{"op":"mcm","clk":"5345904385","pt":1646079078733,"mc":[{"id":"1.195395447","marketDefinition":{"bspMarket":true,"turnInPlayEnabled":false,"persistenceEnabled":false,"marketBaseRate":5.0,"eventId":"31270459","eventTypeId":"4339","numberOfWinners":1,"bettingType":"ODDS","marketType":"WIN","marketTime":"2022-03-01T00:47:00.000Z","suspendTime":"2022-03-01T00:47:00.000Z","bspReconciled":false,"complete":true,"inPlay":false,"crossMatching":false,"runnersVoidable":false,"numberOfActiveRunners":8,"betDelay":0,"status":"OPEN","runners":[{"status":"ACTIVE","sortPriority":1,"id":38541023,"name":"2. Know Beast"},{"status":"ACTIVE","sortPriority":2,"id":43154430,"name":"3. Gandia"},{"status":"ACTIVE","sortPriority":3,"id":42315317,"name":"4. Homebush Villa"},{"status":"ACTIVE","sortPriority":4,"id":40014837,"name":"5. Goldstar Farryn"},{"status":"ACTIVE","sortPriority":5,"id":37535509,"name":"6. King Kong Blonde"},{"status":"ACTIVE","sortPriority":6,"id":37076580,"name":"7. Mitcham Hamish"},{"status":"ACTIVE","sortPriority":7,"id":36899944,"name":"8. Goldstar Willa"},{"status":"ACTIVE","sortPriority":8,"id":40041375,"name":"9. Homebush George"}],"regulators":["MR_INT"],"venue":"Addington","countryCode":"NZ","discountAllowed":false,"timezone":"NZ","openDate":"2022-02-28T23:02:00.000Z","version":4380660679,"name":"R7 295m C1","eventName":"Addington (NZL) 1st Mar"},"rc":[],"con":true,"img":false}]}
{"op":"mcm","clk":"5345904619","pt":1646079080732,"mc":[{"id":"1.195395447","marketDefinition":{"bspMarket":true,"turnInPlayEnabled":false,"persistenceEnabled":false,"marketBaseRate":5.0,"eventId":"31270459","eventTypeId":"4339","numberOfWinners":1,"bettingType":"ODDS","marketType":"WIN","marketTime":"2022-03-01T00:47:00.000Z","suspendTime":"2022-03-01T00:47:00.000Z","bspReconciled":false,"complete":true,"inPlay":false,"crossMatching":false,"runnersVoidable":false,"numberOfActiveRunners":8,"betDelay":0,"status":"OPEN","runners":[{"status":"ACTIVE","sortPriority":1,"id":38541023,"name":"2. Know Beast"},{"status":"ACTIVE","sortPriority":2,"id":43154430,"name":"3. Gandia"},{"status":"ACTIVE","sortPriority":3,"id":42315317,"name":"4. Homebush Villa"},{"status":"ACTIVE","sortPriority":4,"id":40014837,"name":"5. Goldstar Farryn"},{"status":"ACTIVE","sortPriority":5,"id":37535509,"name":"6. King Kong Blonde"},{"status":"ACTIVE","sortPriority":6,"id":37076580,"name":"7. Mitcham Hamish"},{"status":"ACTIVE","sortPriority":7,"id":36899944,"name":"8. Goldstar Willa"},{"status":"ACTIVE","sortPriority":8,"id":40041375,"name":"9. Homebush George"}],"regulators":["MR_INT"],"venue":"Addington","countryCode":"NZ","discountAllowed":true,"timezone":"NZ","openDate":"2022-02-28T23:02:00.000Z","version":4380660679,"name":"R7 295m C1","eventName":"Addington (NZL) 1st Mar"},"rc":[],"con":true,"img":false}]}
{"op":"mcm","clk":"5346126555","pt":1646081524658,"mc":[{"id":"1.195395447","rc":[{"atb":[[18,4.77],[21,2.02],[10.5,17.09],[15.5,8.4]],"id":40014837},{"atl":[[150,0.88],[300,0.66],[200,0.66],[250,0.79]],"id":40014837},{"spn":85.5,"spf":"NaN","id":40014837},{"atb":[[6.4,30.07],[11,4.05],[8.4,16.46],[9.4,9.66]],"id":38541023},{"atl":[[80,1.67],[160,1.25],[55,2.45],[110,1.81]],"id":38541023},{"spn":33.0,"spf":"NaN","id":38541023},{"atb":[[18,4.77],[21,2.02],[10.5,17.09],[15.5,8.4]],"id":37535509},{"atl":[[150,0.88],[300,0.66],[200,0.66],[250,0.79]],"id":37535509},{"spn":85.5,"spf":"NaN","id":37535509},{"atb":[[16.5,5.23],[9.6,18.88],[19,2.25],[14,9.36]],"id":36899944},{"atl":[[140,0.95],[290,0.68],[190,0.69],[240,0.82]],"id":36899944},{"spn":79.5,"spf":"NaN","id":36899944},{"atb":[[2.8,22.55],[2.4,115.99],[2.6,76.12],[2.7,47.76]],"id":42315317},{"atl":[[9.6,23.07],[8.6,26.11],[7.6,20.04],[6.6,23.62]],"id":42315317},{"spn":4.7,"spf":"NaN","id":42315317},{"atb":[[2.3,31.22],[2.2,67.66],[1.95,170.93],[2.1,110.72]],"id":43154430},{"atl":[[8,28.34],[5.5,29.39],[6,26.45],[7,33.07]],"id":43154430},{"spn":3.9,"spf":"NaN","id":43154430},{"atb":[[6.4,30.07],[11,4.05],[8.4,16.46],[9.4,9.66]],"id":40041375},{"atl":[[80,1.67],[160,1.25],[55,2.45],[110,1.81]],"id":40041375},{"spn":33.0,"spf":"NaN","id":40041375},{"atb":[[4.8,10.68],[4.3,24.6],[3.4,67.66],[3.9,41.99]],"id":37076580},{"atl":[[18,7.78],[21,9.92],[26,7.93],[15.5,9.12]],"id":37076580},{"spn":10.15,"spf":"NaN","id":37076580}],"con":true,"img":false}]}
{"op":"mcm","clk":"5346128156","pt":1646081544676,"mc":[{"id":"1.195395447","rc":[{"atb":[[18,0],[21,0],[10.5,0],[15.5,0]],"id":40014837},{"atl":[[150,0],[300,0],[200,0],[250,0]],"id":40014837},{"atb":[[6.4,0],[11,0],[8.4,0],[9.4,0]],"id":38541023},{"atl":[[80,0],[160,0],[55,0],[110,0]],"id":38541023},{"atb":[[18,0],[21,0],[10.5,0],[15.5,0]],"id":37535509},{"atl":[[150,0],[300,0],[200,0],[250,0]],"id":37535509},{"atb":[[16.5,0],[9.6,0],[19,0],[14,0]],"id":36899944},{"atl":[[140,0],[290,0],[190,0],[240,0]],"id":36899944},{"atb":[[2.8,0],[2.4,0],[2.6,0],[2.7,0]],"id":42315317},{"atl":[[9.6,0],[8.6,0],[7.6,0],[6.6,0]],"id":42315317},{"atb":[[2.3,0],[2.2,0],[1.95,0],[2.1,0]],"id":43154430},{"atl":[[8,0],[5.5,0],[6,0],[7,0]],"id":43154430},{"atb":[[6.4,0],[11,0],[8.4,0],[9.4,0]],"id":40041375},{"atl":[[80,0],[160,0],[55,0],[110,0]],"id":40041375},{"atb":[[4.8,0],[4.3,0],[3.4,0],[3.9,0]],"id":37076580},{"atl":[[18,0],[21,0],[26,0],[15.5,0]],"id":37076580}],"con":true,"img":false}]}
{"op":"mcm","clk":"5346129273","pt":1646081558930,"mc":[{"id":"1.195395447","rc":[{"atb":[[18,4.77],[21,2.02],[10.5,17.09],[15.5,8.4]],"id":40014837},{"atl":[[150,0.88],[300,0.66],[200,0.66],[250,0.79]],"id":40014837},{"atb":[[8,17.39],[9,10.14],[10,4.5],[6,32.47]],"id":38541023},{"atl":[[75,1.78],[150,1.33],[50,2.7],[100,2]],"id":38541023},{"atb":[[16.5,5.23],[9.6,18.88],[19,2.25],[14,9.36]],"id":37535509},{"atl":[[140,0.95],[290,0.68],[190,0.69],[240,0.82]],"id":37535509},{"atb":[[16.5,5.23],[9.6,18.88],[19,2.25],[14,9.36]],"id":36899944},{"atl":[[140,0.95],[290,0.68],[190,0.69],[240,0.82]],"id":36899944},{"atb":[[2.8,22.55],[2.4,115.99],[2.6,76.12],[2.7,47.76]],"id":42315317},{"atl":[[9.6,23.07],[8.6,26.11],[7.6,20.04],[6.6,23.62]],"id":42315317},{"atb":[[2.3,31.22],[2.2,67.66],[1.95,170.93],[2.1,110.72]],"id":43154430},{"atl":[[8,28.34],[5.5,29.39],[6,26.45],[7,33.07]],"id":43154430},{"atb":[[8,17.39],[9,10.14],[10,4.5],[6,32.47]],"id":40041375},{"atl":[[75,1.78],[150,1.33],[50,2.7],[100,2]],"id":40041375},{"atb":[[4.8,10.68],[4.3,24.6],[3.4,67.66],[3.9,41.99]],"id":37076580},{"atl":[[18,7.78],[21,9.92],[26,7.93],[15.5,9.12]],"id":37076580}],"con":true,"img":false}]}
{"op":"mcm","clk":"5346130660","pt":1646081577087,"mc":[{"id":"1.195395447","rc":[{"atb":[[18,0],[21,0],[10.5,0],[15.5,0]],"id":40014837},{"atl":[[150,0],[300,0],[200,0],[250,0]],"id":40014837},{"atb":[[8,0],[9,0],[10,0],[6,0]],"id":38541023},{"atl":[[75,0],[150,0],[50,0],[100,0]],"id":38541023},{"atb":[[16.5,0],[9.6,0],[19,0],[14,0]],"id":37535509},{"atl":[[140,0],[290,0],[190,0],[240,0]],"id":37535509},{"atb":[[16.5,0],[9.6,0],[19,0],[14,0]],"id":36899944},{"atl":[[140,0],[290,0],[190,0],[240,0]],"id":36899944},{"atb":[[2.8,0],[2.4,0],[2.6,0],[2.7,0]],"id":42315317},{"atl":[[9.6,0],[8.6,0],[7.6,0],[6.6,0]],"id":42315317},{"atb":[[2.3,0],[2.2,0],[1.95,0],[2.1,0]],"id":43154430},{"atl":[[8,0],[5.5,0],[6,0],[7,0]],"id":43154430},{"atb":[[8,0],[9,0],[10,0],[6,0]],"id":40041375},{"atl":[[75,0],[150,0],[50,0],[100,0]],"id":40041375},{"atb":[[4.8,0],[4.3,0],[3.4,0],[3.9,0]],"id":37076580},{"atl":[[18,0],[21,0],[26,0],[15.5,0]],"id":37076580}],"con":true,"img":false}]}
{"op":"mcm","clk":"5346131645","pt":1646081590850,"mc":[{"id":"1.195395447","rc":[{"atb":[[18,4.77],[21,2.02],[10.5,17.09],[15.5,8.4]],"id":40014837},{"atl":[[150,0.88],[300,0.66],[200,0.66],[250,0.79]],"id":40014837},{"atb":[[8,17.39],[9,10.14],[10,4.5],[6,32.47]],"id":38541023},{"atl":[[75,1.78],[150,1.33],[50,2.7],[100,2]],"id":38541023},{"spn":30.0,"spf":"NaN","id":38541023},{"atb":[[16.5,5.23],[9.6,18.88],[19,2.25],[14,9.36]],"id":37535509},{"atl":[[140,0.95],[290,0.68],[190,0.69],[240,0.82]],"id":37535509},{"spn":79.5,"spf":"NaN","id":37535509},{"atb":[[16.5,5.23],[9.6,18.88],[19,2.25],[14,9.36]],"id":36899944},{"atl":[[140,0.95],[290,0.68],[190,0.69],[240,0.82]],"id":36899944},{"atb":[[2.8,22.55],[2.4,115.99],[2.6,76.12],[2.7,47.76]],"id":42315317},{"atl":[[9.6,23.07],[8.6,26.11],[7.6,20.04],[6.6,23.62]],"id":42315317},{"atb":[[2.3,31.22],[2.2,67.66],[1.95,170.93],[2.1,110.72]],"id":43154430},{"atl":[[8,28.34],[5.5,29.39],[6,26.45],[7,33.07]],"id":43154430},{"atb":[[8,17.39],[9,10.14],[10,4.5],[6,32.47]],"id":40041375},{"atl":[[75,1.78],[150,1.33],[50,2.7],[100,2]],"id":40041375},{"spn":30.0,"spf":"NaN","id":40041375},{"atb":[[4.8,10.68],[4.3,24.6],[3.4,67.66],[3.9,41.99]],"id":37076580},{"atl":[[18,7.78],[21,9.92],[26,7.93],[15.5,9.12]],"id":37076580}],"con":true,"img":false}]}
{"op":"mcm","clk":"5346132673","pt":1646081605211,"mc":[{"id":"1.195395447","rc":[{"atb":[[18,0],[21,0],[10.5,0],[15.5,0]],"id":40014837},{"atl":[[150,0],[300,0],[200,0],[250,0]],"id":40014837},{"atb":[[8,0],[9,0],[10,0],[6,0]],"id":38541023},{"atl":[[75,0],[150,0],[50,0],[100,0]],"id":38541023},{"atb":[[16.5,0],[9.6,0],[19,0],[14,0]],"id":37535509},{"atl":[[140,0],[290,0],[190,0],[240,0]],"id":37535509},{"atb":[[16.5,0],[9.6,0],[19,0],[14,0]],"id":36899944},{"atl":[[140,0],[290,0],[190,0],[240,0]],"id":36899944},{"atb":[[2.8,0],[2.4,0],[2.6,0],[2.7,0]],"id":42315317},{"atl":[[9.6,0],[8.6,0],[7.6,0],[6.6,0]],"id":42315317},{"atb":[[2.3,0],[2.2,0],[1.95,0],[2.1,0]],"id":43154430},{"atl":[[8,0],[5.5,0],[6,0],[7,0]],"id":43154430},{"atb":[[8,0],[9,0],[10,0],[6,0]],"id":40041375},{"atl":[[75,0],[150,0],[50,0],[100,0]],"id":40041375},{"atb":[[4.8,0],[4.3,0],[3.4,0],[3.9,0]],"id":37076580},{"atl":[[18,0],[21,0],[26,0],[15.5,0]],"id":37076580}],"con":true,"img":false}]}
{"op":"mcm","clk":"5346133741","pt":1646081621322,"mc":[{"id":"1.195395447","rc":[{"atb":[[18,4.77],[21,2.02],[10.5,17.09],[15.5,8.4]],"id":40014837},{"atl":[[150,0.88],[300,0.66],[200,0.66],[250,0.79]],"id":40014837},{"atb":[[8,17.39],[9,10.14],[10,4.5],[6,32.47]],"id":38541023},{"atl":[[75,1.78],[150,1.33],[50,2.7],[100,2]],"id":38541023},{"atb":[[16.5,5.23],[9.6,18.88],[19,2.25],[14,9.36]],"id":37535509},{"atl":[[140,0.95],[290,0.68],[190,0.69],[240,0.82]],"id":37535509},{"atb":[[16.5,5.23],[9.6,18.88],[19,2.25],[14,9.36]],"id":36899944},{"atl":[[140,0.95],[290,0.68],[190,0.69],[240,0.82]],"id":36899944},{"atb":[[2.8,22.55],[2.4,115.99],[2.6,76.12],[2.7,47.76]],"id":42315317},{"atl":[[9.6,23.07],[8.6,26.11],[7.6,20.04],[6.6,23.62]],"id":42315317},{"atb":[[2.3,31.22],[2.2,67.66],[1.95,170.93],[2.1,110.72]],"id":43154430},{"atl":[[8,28.34],[5.5,29.39],[6,26.45],[7,33.07]],"id":43154430},{"atb":[[8,17.39],[9,10.14],[10,4.5],[6,32.47]],"id":40041375},{"atl":[[75,1.78],[150,1.33],[50,2.7],[100,2]],"id":40041375},{"atb":[[4.8,10.68],[4.3,24.6],[3.4,67.66],[3.9,41.99]],"id":37076580},{"atl":[[18,7.78],[21,9.92],[26,7.93],[15.5,9.12]],"id":37076580}],"con":true,"img":false}]}
{"op":"mcm","clk":"5346134782","pt":1646081637489,"mc":[{"id":"1.195395447","rc":[{"atb":[[18,0],[21,0],[10.5,0],[15.5,0]],"id":40014837},{"atl":[[150,0],[300,0],[200,0],[250,0]],"id":40014837},{"atb":[[8,0],[9,0],[10,0],[6,0]],"id":38541023},{"atl":[[75,0],[150,0],[50,0],[100,0]],"id":38541023},{"atb":[[16.5,0],[9.6,0],[19,0],[14,0]],"id":37535509},{"atl":[[140,0],[290,0],[190,0],[240,0]],"id":37535509},{"atb":[[16.5,0],[9.6,0],[19,0],[14,0]],"id":36899944},{"atl":[[140,0],[290,0],[190,0],[240,0]],"id":36899944},{"atb":[[2.8,0],[2.4,0],[2.6,0],[2.7,0]],"id":42315317},{"atl":[[9.6,0],[8.6,0],[7.6,0],[6.6,0]],"id":42315317},{"atb":[[2.3,0],[2.2,0],[1.95,0],[2.1,0]],"id":43154430},{"atl":[[8,0],[5.5,0],[6,0],[7,0]],"id":43154430},{"atb":[[8,0],[6,0]],"id":40041375},{"atl":[[50,0],[100,0]],"id":40041375},{"atb":[[4.8,0],[4.3,0],[3.4,0],[3.9,0]],"id":37076580},{"atl":[[18,0],[21,0],[26,0],[15.5,0]],"id":37076580}],"con":true,"img":false}]}
{"op":"mcm","clk":"5346134790","pt":1646081637599,"mc":[{"id":"1.195395447","rc":[{"atb":[[9,0],[10,0]],"id":40041375},{"atl":[[75,0],[150,0]],"id":40041375}],"con":true,"img":false}]}
{"op":"mcm","clk":"5346135981","pt":1646081656756,"mc":[{"id":"1.195395447","rc":[{"atb":[[18,4.77],[21,2.02],[10.5,17.09],[15.5,8.4]],"id":40014837},{"atl":[[150,0.88],[300,0.66],[200,0.66],[250,0.79]],"id":40014837},{"atb":[[8,17.39],[9,10.14],[10,4.5],[6,32.47]],"id":38541023},{"atl":[[75,1.78],[150,1.33],[50,2.7],[100,2]],"id":38541023},{"atb":[[16.5,5.23],[9.6,18.88],[19,2.25],[14,9.36]],"id":37535509},{"atl":[[140,0.95],[290,0.68],[190,0.69],[240,0.82]],"id":37535509},{"atb":[[16.5,5.23],[9.6,18.88],[19,2.25],[14,9.36]],"id":36899944},{"atl":[[140,0.95],[290,0.68],[190,0.69],[240,0.82]],"id":36899944},{"atb":[[2.8,22.55],[2.4,115.99],[2.6,76.12],[2.7,47.76]],"id":42315317},{"atl":[[9.6,23.07],[8.6,26.11],[7.6,20.04],[6.6,23.62]],"id":42315317},{"atb":[[2.3,31.22],[2.2,67.66],[1.95,170.93],[2.1,110.72]],"id":43154430},{"atl":[[8,28.34],[5.5,29.39],[6,26.45],[7,33.07]],"id":43154430},{"atb":[[8,17.39],[9,10.14],[10,4.5],[6,32.47]],"id":40041375},{"atl":[[75,1.78],[150,1.33],[50,2.7],[100,2]],"id":40041375},{"atb":[[4.8,10.68],[4.3,24.6],[3.4,67.66],[3.9,41.99]],"id":37076580},{"atl":[[18,7.78],[21,9.92],[26,7.93],[15.5,9.12]],"id":37076580}],"con":true,"img":false}]}
{"op":"mcm","clk":"5346138690","pt":1646081695488,"mc":[{"id":"1.195395447","rc":[{"atb":[[18,0],[21,0],[10.5,0],[15.5,0]],"id":40014837},{"atl":[[150,0],[300,0],[200,0],[250,0]],"id":40014837},{"atb":[[8,0],[9,0],[10,0],[6,0]],"id":38541023},{"atl":[[75,0],[150,0],[50,0],[100,0]],"id":38541023},{"atb":[[16.5,0],[9.6,0],[19,0],[14,0]],"id":37535509},{"atl":[[140,0],[290,0],[190,0],[240,0]],"id":37535509},{"atb":[[16.5,0],[9.6,0],[19,0],[14,0]],"id":36899944},{"atl":[[140,0],[290,0],[190,0],[240,0]],"id":36899944},{"atb":[[2.8,0],[2.4,0],[2.6,0],[2.7,0]],"id":42315317},{"atl":[[9.6,0],[8.6,0],[7.6,0],[6.6,0]],"id":42315317},{"atb":[[2.3,0],[2.2,0],[1.95,0],[2.1,0]],"id":43154430},{"atl":[[8,0],[5.5,0],[6,0],[7,0]],"id":43154430},{"atb":[[8,0],[9,0],[10,0],[6,0]],"id":40041375},{"atl":[[75,0],[150,0],[50,0],[100,0]],"id":40041375},{"atb":[[4.8,0],[4.3,0],[3.4,0],[3.9,0]],"id":37076580},{"atl":[[18,0],[21,0],[26,0],[15.5,0]],"id":37076580}],"con":true,"img":false}]}
{"op":"mcm","clk":"5346140304","pt":1646081718873,"mc":[{"id":"1.195395447","rc":[{"atb":[[18,4.77],[21,2.02],[10.5,17.09],[15.5,8.4]],"id":40014837},{"atl":[[150,0.88],[300,0.66],[200,0.66],[250,0.79]],"id":40014837},{"atb":[[8,17.39],[9,10.14],[10,4.5],[6,32.47]],"id":38541023},{"atl":[[75,1.78],[150,1.33],[50,2.7],[100,2]],"id":38541023},{"atb":[[16.5,5.23],[9.6,18.88],[19,2.25],[14,9.36]],"id":37535509},{"atl":[[140,0.95],[290,0.68],[190,0.69],[240,0.82]],"id":37535509},{"atb":[[16.5,5.23],[9.6,18.88],[19,2.25],[14,9.36]],"id":36899944},{"atl":[[140,0.95],[290,0.68],[190,0.69],[240,0.82]],"id":36899944},{"atb":[[2.8,22.55],[2.4,115.99],[2.6,76.12],[2.7,47.76]],"id":42315317},{"atl":[[9.6,23.07],[8.6,26.11],[7.6,20.04],[6.6,23.62]],"id":42315317},{"atb":[[2.3,31.22],[2.2,67.66],[1.95,170.93],[2.1,110.72]],"id":43154430},{"atl":[[8,28.34],[5.5,29.39],[6,26.45],[7,33.07]],"id":43154430},{"atb":[[8,17.39],[9,10.14],[10,4.5],[6,32.47]],"id":40041375},{"atl":[[75,1.78],[150,1.33],[50,2.7],[100,2]],"id":40041375},{"atb":[[4.8,10.68],[4.3,24.6],[3.4,67.66],[3.9,41.99]],"id":37076580},{"atl":[[18,7.78],[21,9.92],[26,7.93],[15.5,9.12]],"id":37076580}],"con":true,"img":false}]}
{"op":"mcm","clk":"5346223542","pt":1646082745375,"mc":[{"id":"1.195395447","rc":[{"atb":[[18,0],[21,0],[10.5,0],[15.5,0]],"id":40014837},{"atl":[[150,0],[300,0],[200,0],[250,0]],"id":40014837},{"spn":"NaN","spf":"NaN","id":40014837},{"atb":[[8,0],[9,0],[10,0],[6,0]],"id":38541023},{"atl":[[75,0],[150,0],[50,0],[100,0]],"id":38541023},{"spn":"NaN","spf":"NaN","id":38541023},{"atb":[[16.5,0],[9.6,0],[19,0],[14,0]],"id":37535509},{"atl":[[140,0],[290,0],[190,0],[240,0]],"id":37535509},{"spn":"NaN","spf":"NaN","id":37535509},{"atb":[[16.5,0],[9.6,0],[19,0],[14,0]],"id":36899944},{"atl":[[140,0],[290,0],[190,0],[240,0]],"id":36899944},{"spn":"NaN","spf":"NaN","id":36899944},{"atb":[[2.8,0],[2.4,0],[2.6,0],[2.7,0]],"id":42315317},{"atl":[[9.6,0],[8.6,0],[7.6,0],[6.6,0]],"id":42315317},{"spn":"NaN","spf":"NaN","id":42315317},{"atb":[[2.3,0],[2.2,0],[1.95,0],[2.1,0]],"id":43154430},{"atl":[[8,0],[5.5,0],[6,0],[7,0]],"id":43154430},{"spn":"NaN","spf":"NaN","id":43154430},{"atb":[[8,0],[9,0],[10,0],[6,0]],"id":40041375},{"atl":[[75,0],[150,0],[50,0],[100,0]],"id":40041375},{"spn":"NaN","spf":"NaN","id":40041375},{"atb":[[4.8,0],[4.3,0],[3.4,0],[3.9,0]],"id":37076580},{"atl":[[18,0],[21,0],[26,0],[15.5,0]],"id":37076580},{"spn":"NaN","spf":"NaN","id":37076580}],"con":true,"img":false}]}
{"op":"mcm","clk":"5346225933","pt":1646082773230,"mc":[{"id":"1.195395447","rc":[{"atb":[[18,4.77],[21,2.02],[10.5,17.09],[15.5,8.4]],"id":40014837},{"atl":[[150,0.88],[300,0.66],[200,0.66],[250,0.79]],"id":40014837},{"atb":[[8,17.39],[9,10.14],[10,4.5],[6,32.47]],"id":38541023},{"atl":[[75,1.78],[150,1.33],[50,2.7],[100,2]],"id":38541023},{"atb":[[16.5,5.23],[9.6,18.88],[19,2.25],[14,9.36]],"id":37535509},{"atl":[[140,0.95],[290,0.68],[190,0.69],[240,0.82]],"id":37535509},{"atb":[[16.5,5.23],[9.6,18.88],[19,2.25],[14,9.36]],"id":36899944},{"atl":[[140,0.95],[290,0.68],[190,0.69],[240,0.82]],"id":36899944},{"atb":[[2.8,22.55],[2.4,115.99],[2.6,76.12],[2.7,47.76]],"id":42315317},{"atl":[[9.6,23.07],[8.6,26.11],[7.6,20.04],[6.6,23.62]],"id":42315317},{"atb":[[2.3,31.22],[2.2,67.66],[1.95,170.93],[2.1,110.72]],"id":43154430},{"atl":[[8,28.34],[5.5,29.39],[6,26.45],[7,33.07]],"id":43154430},{"atb":[[8,17.39],[9,10.14],[10,4.5],[6,32.47]],"id":40041375},{"atl":[[75,1.78],[150,1.33],[50,2.7],[100,2]],"id":40041375},{"atb":[[4.8,10.68],[4.3,24.6],[3.4,67.66],[3.9,41.99]],"id":37076580},{"atl":[[18,7.78],[21,9.92],[26,7.93],[15.5,9.12]],"id":37076580}],"con":true,"img":false}]}
{"op":"mcm","clk":"5346253006","pt":1646083002681,"mc":[{"id":"1.195395447","marketDefinition":{"bspMarket":true,"turnInPlayEnabled":false,"persistenceEnabled":false,"marketBaseRate":5.0,"eventId":"31270459","eventTypeId":"4339","numberOfWinners":1,"bettingType":"ODDS","marketType":"WIN","marketTime":"2022-03-01T00:47:00.000Z","suspendTime":"2022-03-01T00:47:00.000Z","bspReconciled":false,"complete":true,"inPlay":false,"crossMatching":false,"runnersVoidable":false,"numberOfActiveRunners":8,"betDelay":0,"status":"OPEN","runners":[{"status":"ACTIVE","sortPriority":1,"id":38541023,"name":"2. Know Beast"},{"status":"ACTIVE","sortPriority":2,"id":43154430,"name":"3. Gandia"},{"status":"ACTIVE","sortPriority":3,"id":42315317,"name":"4. Homebush Villa"},{"status":"ACTIVE","sortPriority":4,"id":40014837,"name":"5. Goldstar Farryn"},{"status":"ACTIVE","sortPriority":5,"id":37535509,"name":"6. King Kong Blonde"},{"status":"ACTIVE","sortPriority":6,"id":37076580,"name":"7. Mitcham Hamish"},{"status":"ACTIVE","sortPriority":7,"id":36899944,"name":"8. Goldstar Willa"},{"status":"ACTIVE","sortPriority":8,"id":40041375,"name":"9. Homebush George"}],"regulators":["MR_INT"],"venue":"Addington","countryCode":"NZ","discountAllowed":true,"timezone":"NZ","openDate":"2022-02-28T23:02:00.000Z","version":4380660679,"name":"R7 295m C1","eventName":"Addington (NZL) 1st Mar"},"rc":[{"atb":[[18,4.77],[21,2.02],[10.5,17.09],[15.5,8.4]],"id":40014837},{"atl":[[150,0.88],[300,0.66],[200,0.66],[250,0.79]],"id":40014837},{"spn":85.5,"spf":"NaN","id":40014837},{"atb":[[8,17.39],[9,10.14],[10,4.5],[6,32.47]],"id":38541023},{"atl":[[75,1.78],[150,1.33],[50,2.7],[100,2]],"id":38541023},{"spn":30.0,"spf":"NaN","id":38541023},{"atb":[[16.5,5.23],[9.6,18.88],[19,2.25],[14,9.36]],"id":37535509},{"atl":[[140,0.95],[290,0.68],[190,0.69],[240,0.82]],"id":37535509},{"spn":79.5,"spf":"NaN","id":37535509},{"atb":[[16.5,5.23],[9.6,18.88],[19,2.25],[14,9.36]],"id":36899944},{"atl":[[140,0.95],[290,0.68],[190,0.69],[240,0.82]],"id":36899944},{"spn":79.5,"spf":"NaN","id":36899944},{"atb":[[2.8,22.55],[2.4,115.99],[2.6,76.12],[2.7,47.76]],"id":42315317},{"atl":[[9.6,23.07],[8.6,26.11],[7.6,20.04],[6.6,23.62]],"id":42315317},{"spn":4.7,"spf":"NaN","id":42315317},{"atb":[[2.3,31.22],[2.2,67.66],[1.95,170.93],[2.1,110.72]],"id":43154430},{"atl":[[8,28.34],[5.5,29.39],[6,26.45],[7,33.07]],"id":43154430},{"spn":3.9,"spf":"NaN","id":43154430},{"atb":[[8,17.39],[9,10.14],[10,4.5],[6,32.47]],"id":40041375},{"atl":[[75,1.78],[150,1.33],[50,2.7],[100,2]],"id":40041375},{"spn":30.0,"spf":"NaN","id":40041375},{"atb":[[4.8,10.68],[4.3,24.6],[3.4,67.66],[3.9,41.99]],"id":37076580},{"atl":[[18,7.78],[21,9.92],[26,7.93],[15.5,9.12]],"id":37076580},{"spn":10.15,"spf":"NaN","id":37076580}],"con":true,"img":true}]}
{"op":"mcm","clk":"5346452047","pt":1646086724221,"mc":[{"id":"1.195395447","rc":[{"atb":[[18,4.77],[21,2.02],[10.5,17.09],[15.5,8.39]],"id":40014837},{"atl":[[150,0.88],[300,0.66],[200,0.66],[250,0.79]],"id":40014837},{"spn":85.5,"spf":"NaN","id":40014837},{"atb":[[8,17.39],[9,10.14],[10,4.5],[6,32.47]],"id":38541023},{"atl":[[75,1.78],[150,1.33],[50,2.7],[100,2]],"id":38541023},{"spn":30.0,"spf":"NaN","id":38541023},{"atb":[[16.5,5.23],[9.6,18.87],[19,2.25],[14,9.36]],"id":37535509},{"atl":[[140,0.95],[290,0.68],[190,0.69],[240,0.82]],"id":37535509},{"spn":79.5,"spf":"NaN","id":37535509},{"atb":[[16.5,5.23],[9.6,18.87],[19,2.25],[14,9.36]],"id":36899944},{"atl":[[140,0.95],[290,0.68],[190,0.69],[240,0.82]],"id":36899944},{"spn":79.5,"spf":"NaN","id":36899944},{"atb":[[2.8,22.55],[2.4,115.97],[2.74,4.28],[2.6,76.11],[2.7,47.75]],"id":42315317},{"atl":[[9.6,23.07],[8.6,26.1],[7.6,20.04],[6.6,23.61]],"id":42315317},{"spn":4.7,"spf":"NaN","id":42315317},{"atb":[[2.3,31.22],[2.2,67.65],[1.95,170.9],[2.1,110.7],[2.34,5.55]],"id":43154430},{"atl":[[8,28.34],[5.5,29.39],[6,26.45],[7,33.06]],"id":43154430},{"spn":3.92,"spf":"NaN","id":43154430},{"atb":[[8,17.39],[9,10.14],[10,4.5],[6,32.47]],"id":40041375},{"atl":[[75,1.78],[150,1.33],[50,2.7],[100,2]],"id":40041375},{"spn":30.0,"spf":"NaN","id":40041375},{"atb":[[4.8,10.68],[4.3,24.59],[1.01,2.23],[3.4,67.65],[3.9,41.99]],"id":37076580},{"atl":[[18,7.78],[21,9.92],[26,7.93],[15.5,9.12]],"id":37076580},{"spn":10.15,"spf":"NaN","id":37076580}],"con":true,"img":false}]}
{"op":"mcm","clk":"5346452055","pt":1646086724425,"mc":[{"id":"1.195395447","rc":[{"atb":[[1.01,2.19]],"id":37076580}],"con":true,"img":false}]}
{"op":"mcm","clk":"5346452063","pt":1646086724630,"mc":[{"id":"1.195395447","rc":[{"atb":[[1.01,0]],"id":37076580}],"con":true,"img":false}]}
{"op":"mcm","clk":"5346452066","pt":1646086724734,"mc":[{"id":"1.195395447","rc":[{"atb":[[4.4,2.19]],"id":37076580}],"con":true,"img":false}]}
{"op":"mcm","clk":"5346453439","pt":1646086761431,"mc":[{"id":"1.195395447","rc":[{"atb":[[2.24,6.73]],"id":43154430}],"con":true,"img":false}]}
{"op":"mcm","clk":"5346453447","pt":1646086761550,"mc":[{"id":"1.195395447","rc":[{"atb":[[2.74,9.09]],"id":42315317}],"con":true,"img":false}]}
{"op":"mcm","clk":"5346453463","pt":1646086761728,"mc":[{"id":"1.195395447","rc":[{"atb":[[4.4,4.64]],"id":37076580}],"con":true,"img":false}]}
{"op":"mcm","clk":"5346490125","pt":1646088172773,"mc":[{"id":"1.195395447","rc":[{"atb":[[18,0],[21,0],[10.5,0],[15.5,0]],"id":40014837},{"atl":[[150,0],[300,0],[200,0],[250,0]],"id":40014837},{"spn":"NaN","spf":"NaN","id":40014837},{"atb":[[16.5,0],[9.6,0],[19,0],[14,0]],"id":37535509},{"atl":[[140,0],[290,0],[190,0],[240,0]],"id":37535509},{"spn":"NaN","spf":"NaN","id":37535509},{"atb":[[2.8,0],[2.4,0],[2.6,0],[2.7,0]],"id":42315317},{"atl":[[9.6,0],[8.6,0],[7.6,0],[6.6,0]],"id":42315317},{"spn":"Infinity","spf":"NaN","id":42315317},{"atb":[[2.3,0],[2.2,0],[1.95,0],[2.1,0]],"id":43154430},{"atl":[[8,0],[5.5,0],[6,0],[7,0]],"id":43154430},{"spn":"Infinity","spf":"NaN","id":43154430},{"atb":[[8,0],[9,0],[10,0],[6,0]],"id":40041375},{"atl":[[75,0],[150,0],[50,0],[100,0]],"id":40041375},{"spn":"NaN","spf":"NaN","id":40041375}],"con":true,"img":false}]}
{"op":"mcm","clk":"5346490248","pt":1646088176475,"mc":[{"id":"1.195395447","rc":[{"atb":[[16.5,7.85],[19,4.5],[23,1.84],[11.5,15.46]],"id":40014837},{"atl":[[260,0.76],[310,0.64],[160,0.83],[210,0.63]],"id":40014837},{"atb":[[16.5,7.85],[19,4.5],[23,1.84],[11.5,15.46]],"id":37535509},{"atl":[[260,0.76],[310,0.64],[160,0.83],[210,0.63]],"id":37535509},{"atb":[[2.8,67.65],[2.9,42.72],[3,20.29],[2.6,101.47]],"id":42315317},{"atl":[[12,18.03],[9.8,22.54],[8.8,16.95],[7.8,19.45]],"id":42315317},{"atb":[[2,121.77],[1.9,180.4],[2.2,33.82],[2.1,73.79]],"id":43154430},{"atl":[[5.8,27.55],[5.3,30.76],[7.6,30.06],[6.6,35.42]],"id":43154430},{"atb":[[12,3.69],[6.8,27.99],[9.8,9.22],[8.8,15.61]],"id":40041375},{"atl":[[70,1.91],[140,1.42],[95,1.4],[190,1.04]],"id":40041375}],"con":true,"img":false}]}
{"op":"mcm","clk":"5346490427","pt":1646088181790,"mc":[{"id":"1.195395447","rc":[{"atb":[[2.74,4.8]],"id":42315317},{"atb":[[2.34,0]],"id":43154430}],"con":true,"img":false}]}
{"op":"mcm","clk":"5346490621","pt":1646088187713,"mc":[{"id":"1.195395447","rc":[{"atb":[[2.74,0]],"id":42315317},{"atb":[[2.24,0]],"id":43154430}],"con":true,"img":false}]}
{"op":"mcm","clk":"5346490707","pt":1646088190699,"mc":[{"id":"1.195395447","rc":[{"atb":[[2.94,4.3]],"id":42315317}],"con":true,"img":false}]}
{"op":"mcm","clk":"5346490710","pt":1646088190801,"mc":[{"id":"1.195395447","rc":[{"atb":[[2.14,7.33]],"id":43154430}],"con":true,"img":false}]}
{"op":"mcm","clk":"5346490917","pt":1646088196797,"mc":[{"id":"1.195395447","rc":[{"atb":[[2.94,8.14]],"id":42315317},{"atb":[[2.24,6]],"id":43154430}],"con":true,"img":false}]}
{"op":"mcm","clk":"5346502901","pt":1646088402669,"mc":[{"id":"1.195395447","marketDefinition":{"bspMarket":true,"turnInPlayEnabled":false,"persistenceEnabled":false,"marketBaseRate":5.0,"eventId":"31270459","eventTypeId":"4339","numberOfWinners":1,"bettingType":"ODDS","marketType":"WIN","marketTime":"2022-03-01T00:47:00.000Z","suspendTime":"2022-03-01T00:47:00.000Z","bspReconciled":false,"complete":true,"inPlay":false,"crossMatching":false,"runnersVoidable":false,"numberOfActiveRunners":8,"betDelay":0,"status":"OPEN","runners":[{"status":"ACTIVE","sortPriority":1,"id":38541023,"name":"2. Know Beast"},{"status":"ACTIVE","sortPriority":2,"id":43154430,"name":"3. Gandia"},{"status":"ACTIVE","sortPriority":3,"id":42315317,"name":"4. Homebush Villa"},{"status":"ACTIVE","sortPriority":4,"id":40014837,"name":"5. Goldstar Farryn"},{"status":"ACTIVE","sortPriority":5,"id":37535509,"name":"6. King Kong Blonde"},{"status":"ACTIVE","sortPriority":6,"id":37076580,"name":"7. Mitcham Hamish"},{"status":"ACTIVE","sortPriority":7,"id":36899944,"name":"8. Goldstar Willa"},{"status":"ACTIVE","sortPriority":8,"id":40041375,"name":"9. Homebush George"}],"regulators":["MR_INT"],"venue":"Addington","countryCode":"NZ","discountAllowed":true,"timezone":"NZ","openDate":"2022-02-28T23:02:00.000Z","version":4380660679,"name":"R7 295m C1","eventName":"Addington (NZL) 1st Mar"},"rc":[{"atb":[[16.5,7.85],[19,4.5],[23,1.84],[11.5,15.46]],"id":40014837},{"atl":[[260,0.76],[310,0.64],[160,0.83],[210,0.63]],"id":40014837},{"spn":91.5,"spf":"NaN","id":40014837},{"atb":[[8,17.39],[9,10.14],[10,4.5],[6,32.47]],"id":38541023},{"atl":[[75,1.78],[150,1.33],[50,2.7],[100,2]],"id":38541023},{"spn":30.0,"spf":"NaN","id":38541023},{"atb":[[16.5,7.85],[19,4.5],[23,1.84],[11.5,15.46]],"id":37535509},{"atl":[[260,0.76],[310,0.64],[160,0.83],[210,0.63]],"id":37535509},{"spn":91.5,"spf":"NaN","id":37535509},{"atb":[[16.5,5.23],[9.6,18.87],[19,2.25],[14,9.36]],"id":36899944},{"atl":[[140,0.95],[290,0.68],[190,0.69],[240,0.82]],"id":36899944},{"spn":79.5,"spf":"NaN","id":36899944},{"atb":[[2.8,67.65],[2.9,42.72],[3,20.29],[2.6,101.47],[2.94,8.14]],"id":42315317},{"atl":[[12,18.03],[9.8,22.54],[8.8,16.95],[7.8,19.45]],"id":42315317},{"spn":5.4,"spf":"NaN","id":42315317},{"atb":[[2.24,6],[2,121.77],[1.9,180.4],[2.2,33.82],[2.14,7.33],[2.1,73.79]],"id":43154430},{"atl":[[5.8,27.55],[5.3,30.76],[7.6,30.06],[6.6,35.42]],"id":43154430},{"spn":3.77,"spf":"NaN","id":43154430},{"atb":[[12,3.69],[6.8,27.99],[9.8,9.22],[8.8,15.61]],"id":40041375},{"atl":[[70,1.91],[140,1.42],[95,1.4],[190,1.04]],"id":40041375},{"spn":41.0,"spf":"NaN","id":40041375},{"atb":[[4.8,10.68],[4.3,24.59],[3.4,67.65],[4.4,4.64],[3.9,41.99]],"id":37076580},{"atl":[[18,7.78],[21,9.92],[26,7.93],[15.5,9.12]],"id":37076580},{"spn":10.15,"spf":"NaN","id":37076580}],"con":true,"img":true}]}
{"op":"mcm","clk":"5346504746","pt":1646088420114,"mc":[{"id":"1.195395447","rc":[{"spn":91.5,"spf":"NaN","id":40014837},{"atb":[[8.8,1.29]],"id":38541023},{"spn":91.5,"spf":"NaN","id":37535509},{"atb":[[17.5,0.62]],"id":36899944},{"atb":[[2.92,2]],"id":42315317},{"spn":5.4,"spf":"NaN","id":42315317},{"atb":[[2.22,2]],"id":43154430},{"spn":3.77,"spf":"NaN","id":43154430},{"atb":[[11.5,0.96]],"id":40041375},{"spn":41.0,"spf":"NaN","id":40041375}],"con":true,"img":false}]}
{"op":"mcm","clk":"5346504752","pt":1646088420166,"mc":[{"id":"1.195395447","rc":[{"atb":[[22,0.49]],"id":40014837},{"atb":[[18.5,0.58]],"id":37535509},{"atb":[[4.5,2]],"id":37076580}],"con":true,"img":false}]}
{"op":"mcm","clk":"5346505459","pt":1646088444248,"mc":[{"id":"1.195395447","rc":[{"atb":[[8.8,0]],"id":38541023},{"atb":[[4.5,0]],"id":37076580}],"con":true,"img":false}]}
{"op":"mcm","clk":"5346505464","pt":1646088444450,"mc":[{"id":"1.195395447","rc":[{"atb":[[8.6,1.33]],"id":38541023},{"atb":[[4.3,26.59]],"id":37076580}],"con":true,"img":false}]}
{"op":"mcm","clk":"5346505571","pt":1646088447455,"mc":[{"id":"1.195395447","marketDefinition":{"bspMarket":true,"turnInPlayEnabled":false,"persistenceEnabled":false,"marketBaseRate":5.0,"eventId":"31270459","eventTypeId":"4339","numberOfWinners":1,"bettingType":"ODDS","marketType":"WIN","marketTime":"2022-03-01T00:47:00.000Z","suspendTime":"2022-03-01T00:47:00.000Z","bspReconciled":false,"complete":true,"inPlay":false,"crossMatching":true,"runnersVoidable":false,"numberOfActiveRunners":8,"betDelay":0,"status":"OPEN","runners":[{"status":"ACTIVE","sortPriority":1,"id":38541023,"name":"2. Know Beast"},{"status":"ACTIVE","sortPriority":2,"id":43154430,"name":"3. Gandia"},{"status":"ACTIVE","sortPriority":3,"id":42315317,"name":"4. Homebush Villa"},{"status":"ACTIVE","sortPriority":4,"id":40014837,"name":"5. Goldstar Farryn"},{"status":"ACTIVE","sortPriority":5,"id":37535509,"name":"6. King Kong Blonde"},{"status":"ACTIVE","sortPriority":6,"id":37076580,"name":"7. Mitcham Hamish"},{"status":"ACTIVE","sortPriority":7,"id":36899944,"name":"8. Goldstar Willa"},{"status":"ACTIVE","sortPriority":8,"id":40041375,"name":"9. Homebush George"}],"regulators":["MR_INT"],"venue":"Addington","countryCode":"NZ","discountAllowed":true,"timezone":"NZ","openDate":"2022-02-28T23:02:00.000Z","version":4380660679,"name":"R7 295m C1","eventName":"Addington (NZL) 1st Mar"},"rc":[],"con":true,"img":false}]}
{"op":"mcm","clk":"5346522898","pt":1646089047392,"mc":[{"id":"1.195395447","rc":[{"atl":[[3.65,4.05]],"id":43154430},{"spn":2.94,"spf":"NaN","id":43154430}],"con":true,"img":false}]}
{"op":"mcm","clk":"5346526777","pt":1646089188572,"mc":[{"id":"1.195395447","rc":[{"spl":[[100,2]],"id":40014837},{"spn":61.5,"spf":1.0,"id":40014837},{"spl":[[100,2]],"id":38541023},{"spn":30.0,"spf":1.0,"id":38541023},{"spl":[[100,2]],"id":37535509},{"spn":61.5,"spf":1.0,"id":37535509},{"spl":[[100,2]],"id":36899944},{"spn":59.5,"spf":1.0,"id":36899944},{"spl":[[100,2]],"id":42315317},{"spn":5.4,"spf":1.0,"id":42315317},{"spl":[[100,2]],"id":43154430},{"spn":2.94,"spf":1.0,"id":43154430},{"spl":[[100,2]],"id":40041375},{"spn":41.0,"spf":1.0,"id":40041375},{"spl":[[100,2]],"id":37076580},{"spn":10.15,"spf":1.0,"id":37076580}],"con":true,"img":false}]}
{"op":"mcm","clk":"5346539707","pt":1646089713657,"mc":[{"id":"1.195395447","rc":[{"atl":[[7.6,2.15]],"id":42315317},{"spn":5.3,"spf":1.0,"id":42315317},{"atl":[[5.2,3.15]],"id":43154430}],"con":true,"img":false}]}
{"op":"mcm","clk":"5346541570","pt":1646089794377,"mc":[{"id":"1.195395447","rc":[{"atl":[[5.2,6.7]],"id":43154430}],"con":true,"img":false}]}
{"op":"mcm","clk":"5346541575","pt":1646089794581,"mc":[{"id":"1.195395447","rc":[{"atl":[[7.6,4.56]],"id":42315317}],"con":true,"img":false}]}
{"op":"mcm","clk":"5346542329","pt":1646089831029,"mc":[{"id":"1.195395447","rc":[{"atl":[[5.2,3.54]],"id":43154430}],"con":true,"img":false}]}
{"op":"mcm","clk":"5346542397","pt":1646089834054,"mc":[{"id":"1.195395447","rc":[{"atl":[[7.6,2.41]],"id":42315317}],"con":true,"img":false}]}
{"op":"mcm","clk":"5346542490","pt":1646089837043,"mc":[{"id":"1.195395447","rc":[{"atl":[[7.6,4.56]],"id":42315317},{"atl":[[5.2,6.7]],"id":43154430}],"con":true,"img":false}]}
{"op":"mcm","clk":"5346542515","pt":1646089838120,"mc":[{"id":"1.195395447","rc":[{"atb":[[17.5,0]],"id":36899944}],"con":true,"img":false}]}
{"op":"mcm","clk":"5346542517","pt":1646089838224,"mc":[{"id":"1.195395447","rc":[{"atb":[[18.5,0.58]],"id":36899944}],"con":true,"img":false}]}
{"op":"mcm","clk":"5346542803","pt":1646089853292,"mc":[{"id":"1.195395447","rc":[{"atb":[[16.5,0],[9.6,0],[19,0],[14,0]],"id":36899944},{"atl":[[140,0],[290,0],[190,0],[240,0]],"id":36899944}],"con":true,"img":false}]}
{"op":"mcm","clk":"5346542876","pt":1646089856467,"mc":[{"id":"1.195395447","rc":[{"atb":[[16.5,5.23],[9.6,18.87],[19,2.25],[14,9.36]],"id":36899944},{"atl":[[140,0.95],[290,0.68],[190,0.69],[240,0.82]],"id":36899944}],"con":true,"img":false}]}
{"op":"mcm","clk":"5346544061","pt":1646089914694,"mc":[{"id":"1.195395447","rc":[{"atl":[[5.2,3.15]],"id":43154430}],"con":true,"img":false}]}
{"op":"mcm","clk":"5346544168","pt":1646089920695,"mc":[{"id":"1.195395447","rc":[{"atl":[[7.6,2.15]],"id":42315317}],"con":true,"img":false}]}
{"op":"mcm","clk":"5346544262","pt":1646089926592,"mc":[{"id":"1.195395447","rc":[{"atl":[[5.2,6.7]],"id":43154430}],"con":true,"img":false}]}
{"op":"mcm","clk":"5346544264","pt":1646089926797,"mc":[{"id":"1.195395447","rc":[{"atl":[[7.6,4.56]],"id":42315317}],"con":true,"img":false}]}
{"op":"mcm","clk":"5346544880","pt":1646089954219,"mc":[{"id":"1.195395447","rc":[{"atl":[[5.2,3.54]],"id":43154430}],"con":true,"img":false}]}
{"op":"mcm","clk":"5346544942","pt":1646089957336,"mc":[{"id":"1.195395447","rc":[{"atl":[[7.6,2.41]],"id":42315317}],"con":true,"img":false}]}
{"op":"mcm","clk":"5346545008","pt":1646089960163,"mc":[{"id":"1.195395447","rc":[{"atl":[[7.6,4.56]],"id":42315317},{"atl":[[5.2,6.7]],"id":43154430}],"con":true,"img":false}]}
{"op":"mcm","clk":"5346547025","pt":1646090046899,"mc":[{"id":"1.195395447","rc":[{"atl":[[5.2,3.15]],"id":43154430}],"con":true,"img":false}]}
{"op":"mcm","clk":"5346547188","pt":1646090052999,"mc":[{"id":"1.195395447","rc":[{"atl":[[7.6,2.15]],"id":42315317}],"con":true,"img":false}]}
{"op":"mcm","clk":"5346547393","pt":1646090059044,"mc":[{"id":"1.195395447","rc":[{"atl":[[7.6,4.56]],"id":42315317},{"atl":[[5.2,6.7]],"id":43154430}],"con":true,"img":false}]}
{"op":"mcm","clk":"5346547868","pt":1646090077486,"mc":[{"id":"1.195395447","rc":[{"atl":[[5.2,3.54]],"id":43154430}],"con":true,"img":false}]}
{"op":"mcm","clk":"5346547926","pt":1646090080550,"mc":[{"id":"1.195395447","rc":[{"atl":[[7.6,2.41]],"id":42315317}],"con":true,"img":false}]}
{"op":"mcm","clk":"5346547980","pt":1646090083467,"mc":[{"id":"1.195395447","rc":[{"atl":[[7.6,4.56]],"id":42315317},{"atl":[[5.2,6.7]],"id":43154430}],"con":true,"img":false}]}
{"op":"mcm","clk":"5346550341","pt":1646090179214,"mc":[{"id":"1.195395447","rc":[{"atl":[[5.2,3.15]],"id":43154430}],"con":true,"img":false}]}
{"op":"mcm","clk":"5346550491","pt":1646090185203,"mc":[{"id":"1.195395447","rc":[{"atl":[[7.6,2.15]],"id":42315317}],"con":true,"img":false}]}
{"op":"mcm","clk":"5346550658","pt":1646090191244,"mc":[{"id":"1.195395447","rc":[{"atl":[[5.2,6.7]],"id":43154430}],"con":true,"img":false}]}
{"op":"mcm","clk":"5346550660","pt":1646090191347,"mc":[{"id":"1.195395447","rc":[{"atl":[[7.6,4.56]],"id":42315317}],"con":true,"img":false}]}
{"op":"mcm","clk":"5346550876","pt":1646090200669,"mc":[{"id":"1.195395447","rc":[{"atl":[[5.2,3.54]],"id":43154430}],"con":true,"img":false}]}
{"op":"mcm","clk":"5346550946","pt":1646090203658,"mc":[{"id":"1.195395447","rc":[{"atl":[[7.6,2.41]],"id":42315317}],"con":true,"img":false}]}
{"op":"mcm","clk":"5346551021","pt":1646090206677,"mc":[{"id":"1.195395447","rc":[{"atl":[[7.6,4.56]],"id":42315317},{"atl":[[5.2,6.7]],"id":43154430}],"con":true,"img":false}]}
{"op":"mcm","clk":"5346551596","pt":1646090230233,"mc":[{"id":"1.195395447","rc":[{"atb":[[5.5,16]],"id":38541023}],"con":true,"img":false}]}
{"op":"mcm","clk":"5346551601","pt":1646090230284,"mc":[{"id":"1.195395447","rc":[{"atb":[[2.62,46.3]],"id":40014837},{"atb":[[2.62,46.3]],"id":38541023},{"atb":[[10,8]],"id":37535509},{"atb":[[2.62,46.3]],"id":36899944},{"atb":[[1.92,78.26]],"id":42315317},{"atl":[[14,8.2]],"id":42315317},{"atb":[[1.57,126.32]],"id":43154430},{"atl":[[6.2,8.2]],"id":43154430},{"atb":[[6.4,13.33]],"id":40041375},{"atb":[[2.9,37.89]],"id":37076580},{"atl":[[36,8.2]],"id":37076580}],"con":true,"img":false}]}
{"op":"mcm","clk":"5346551602","pt":1646090230386,"mc":[{"id":"1.195395447","rc":[{"atb":[[4.2,26.56]],"id":40014837},{"atb":[[2.62,46.3],[4.2,26.56]],"id":37535509},{"atb":[[4.2,26.56]],"id":36899944},{"atl":[[17,8.5]],"id":43154430},{"atb":[[2.62,46.3],[4.2,26.56]],"id":40041375}],"con":true,"img":false}]}
{"op":"mcm","clk":"5346551604","pt":1646090230490,"mc":[{"id":"1.195395447","rc":[{"atl":[[34,13.5]],"id":42315317},{"atl":[[34,13.5]],"id":43154430}],"con":true,"img":false}]}
{"op":"mcm","clk":"5346552230","pt":1646090253350,"mc":[{"id":"1.195395447","rc":[{"atb":[[4.3,24.59]],"id":37076580}],"con":true,"img":false}]}
{"op":"mcm","clk":"5346552232","pt":1646090253446,"mc":[{"id":"1.195395447","rc":[{"atb":[[4.4,6.64]],"id":37076580}],"con":true,"img":false}]}
{"op":"mcm","clk":"5346553676","pt":1646090311535,"mc":[{"id":"1.195395447","rc":[{"atl":[[5.2,3.15]],"id":43154430}],"con":true,"img":false}]}
{"op":"mcm","clk":"5346553795","pt":1646090317400,"mc":[{"id":"1.195395447","rc":[{"atl":[[7.6,2.15]],"id":42315317}],"con":true,"img":false}]}
{"op":"mcm","clk":"5346553949","pt":1646090323439,"mc":[{"id":"1.195395447","rc":[{"atl":[[5.2,6.7]],"id":43154430}],"con":true,"img":false}]}
{"op":"mcm","clk":"5346553954","pt":1646090323654,"mc":[{"id":"1.195395447","rc":[{"atl":[[7.6,4.56]],"id":42315317}],"con":true,"img":false}]}
{"op":"mcm","clk":"5346553961","pt":1646090323950,"mc":[{"id":"1.195395447","rc":[{"atl":[[5.2,3.54]],"id":43154430}],"con":true,"img":false}]}
{"op":"mcm","clk":"5346554059","pt":1646090326926,"mc":[{"id":"1.195395447","rc":[{"atl":[[7.6,2.41]],"id":42315317}],"con":true,"img":false}]}
{"op":"mcm","clk":"5346554156","pt":1646090329846,"mc":[{"id":"1.195395447","rc":[{"atl":[[7.6,4.56]],"id":42315317},{"atl":[[5.2,6.7]],"id":43154430}],"con":true,"img":false}]}
{"op":"mcm","clk":"5346558078","pt":1646090443853,"mc":[{"id":"1.195395447","rc":[{"atl":[[5.2,3.15]],"id":43154430}],"con":true,"img":false}]}
{"op":"mcm","clk":"5346558163","pt":1646090447068,"mc":[{"id":"1.195395447","rc":[{"atl":[[5.2,0]],"id":43154430}],"con":true,"img":false}]}
{"op":"mcm","clk":"5346558236","pt":1646090449781,"mc":[{"id":"1.195395447","rc":[{"atl":[[7.6,2.15]],"id":42315317}],"con":true,"img":false}]}
{"op":"mcm","clk":"5346558248","pt":1646090450190,"mc":[{"id":"1.195395447","rc":[{"atl":[[7.6,0]],"id":42315317}],"con":true,"img":false}]}
{"op":"mcm","clk":"5346558329","pt":1646090453164,"mc":[{"id":"1.195395447","rc":[{"atl":[[7.6,2.15]],"id":42315317},{"atl":[[5.2,3.15]],"id":43154430}],"con":true,"img":false}]}
{"op":"mcm","clk":"5346558389","pt":1646090455667,"mc":[{"id":"1.195395447","rc":[{"atl":[[5.2,6.7]],"id":43154430}],"con":true,"img":false}]}
{"op":"mcm","clk":"5346558392","pt":1646090455771,"mc":[{"id":"1.195395447","rc":[{"atl":[[7.6,4.56]],"id":42315317}],"con":true,"img":false}]}
{"op":"mcm","clk":"5346561046","pt":1646090570349,"mc":[{"id":"1.195395447","rc":[{"atl":[[5.2,3.54]],"id":43154430}],"con":true,"img":false}]}
{"op":"mcm","clk":"5346561115","pt":1646090573467,"mc":[{"id":"1.195395447","rc":[{"atl":[[7.6,2.41]],"id":42315317}],"con":true,"img":false}]}
{"op":"mcm","clk":"5346561158","pt":1646090575986,"mc":[{"id":"1.195395447","rc":[{"atl":[[5.2,0]],"id":43154430}],"con":true,"img":false}]}
{"op":"mcm","clk":"5346561171","pt":1646090576402,"mc":[{"id":"1.195395447","rc":[{"atl":[[7.6,4.56]],"id":42315317},{"atl":[[5.2,3.15]],"id":43154430}],"con":true,"img":false}]}
{"op":"mcm","clk":"5346561297","pt":1646090582092,"mc":[{"id":"1.195395447","rc":[{"atl":[[7.6,2.15]],"id":42315317}],"con":true,"img":false}]}
{"op":"mcm","clk":"5346561444","pt":1646090587889,"mc":[{"id":"1.195395447","rc":[{"atl":[[5.2,6.7]],"id":43154430}],"con":true,"img":false}]}
{"op":"mcm","clk":"5346561446","pt":1646090587992,"mc":[{"id":"1.195395447","rc":[{"atl":[[7.6,4.56]],"id":42315317}],"con":true,"img":false}]}
{"op":"mcm","clk":"5346563705","pt":1646090693654,"mc":[{"id":"1.195395447","rc":[{"atl":[[5.2,3.54]],"id":43154430}],"con":true,"img":false}]}
{"op":"mcm","clk":"5346563843","pt":1646090696781,"mc":[{"id":"1.195395447","rc":[{"atl":[[7.6,2.41]],"id":42315317}],"con":true,"img":false}]}
{"op":"mcm","clk":"5346563898","pt":1646090699552,"mc":[{"id":"1.195395447","rc":[{"atl":[[7.6,4.56]],"id":42315317},{"atl":[[5.2,6.7]],"id":43154430}],"con":true,"img":false}]}
{"op":"mcm","clk":"5346564100","pt":1646090708178,"mc":[{"id":"1.195395447","rc":[{"atl":[[5.2,3.15]],"id":43154430}],"con":true,"img":false}]}
{"op":"mcm","clk":"5346564267","pt":1646090714191,"mc":[{"id":"1.195395447","rc":[{"atl":[[7.6,2.15]],"id":42315317}],"con":true,"img":false}]}
{"op":"mcm","clk":"5346564445","pt":1646090720197,"mc":[{"id":"1.195395447","rc":[{"atl":[[5.2,6.7]],"id":43154430}],"con":true,"img":false}]}
{"op":"mcm","clk":"5346564451","pt":1646090720405,"mc":[{"id":"1.195395447","rc":[{"atl":[[7.6,4.56]],"id":42315317}],"con":true,"img":false}]}
{"op":"mcm","clk":"5346567250","pt":1646090816947,"mc":[{"id":"1.195395447","rc":[{"atl":[[5.2,3.54]],"id":43154430}],"con":true,"img":false}]}
{"op":"mcm","clk":"5346567338","pt":1646090820034,"mc":[{"id":"1.195395447","rc":[{"atl":[[7.6,2.41]],"id":42315317}],"con":true,"img":false}]}
{"op":"mcm","clk":"5346567421","pt":1646090822921,"mc":[{"id":"1.195395447","rc":[{"atl":[[7.6,4.56]],"id":42315317},{"atl":[[5.2,6.7]],"id":43154430}],"con":true,"img":false}]}
{"op":"mcm","clk":"5346567829","pt":1646090837548,"mc":[{"id":"1.195395447","rc":[{"atl":[[5.2,3.15]],"id":43154430}],"con":true,"img":false}]}
{"op":"mcm","clk":"5346568007","pt":1646090843567,"mc":[{"id":"1.195395447","rc":[{"atl":[[7.6,2.15]],"id":42315317}],"con":true,"img":false}]}
{"op":"mcm","clk":"5346568188","pt":1646090849467,"mc":[{"id":"1.195395447","rc":[{"atl":[[5.2,6.7]],"id":43154430}],"con":true,"img":false}]}
{"op":"mcm","clk":"5346568192","pt":1646090849566,"mc":[{"id":"1.195395447","rc":[{"atl":[[7.6,4.56]],"id":42315317}],"con":true,"img":false}]}
{"op":"mcm","clk":"5346570760","pt":1646090940099,"mc":[{"id":"1.195395447","rc":[{"atl":[[5.2,3.54]],"id":43154430}],"con":true,"img":false}]}
{"op":"mcm","clk":"5346570863","pt":1646090943085,"mc":[{"id":"1.195395447","rc":[{"atl":[[7.6,2.41]],"id":42315317}],"con":true,"img":false}]}
{"op":"mcm","clk":"5346570956","pt":1646090946111,"mc":[{"id":"1.195395447","rc":[{"atl":[[7.6,4.56]],"id":42315317},{"atl":[[5.2,6.7]],"id":43154430}],"con":true,"img":false}]}
{"op":"mcm","clk":"5346571697","pt":1646090969823,"mc":[{"id":"1.195395447","rc":[{"atl":[[5.2,3.15]],"id":43154430}],"con":true,"img":false}]}
{"op":"mcm","clk":"5346571918","pt":1646090975739,"mc":[{"id":"1.195395447","rc":[{"atl":[[7.6,2.15]],"id":42315317}],"con":true,"img":false}]}
{"op":"mcm","clk":"5346572052","pt":1646090981644,"mc":[{"id":"1.195395447","rc":[{"atl":[[5.2,6.7]],"id":43154430}],"con":true,"img":false}]}
{"op":"mcm","clk":"5346572060","pt":1646090981848,"mc":[{"id":"1.195395447","rc":[{"atl":[[7.6,4.56]],"id":42315317}],"con":true,"img":false}]}
{"op":"mcm","clk":"5346574541","pt":1646091063268,"mc":[{"id":"1.195395447","rc":[{"atl":[[5.2,3.54]],"id":43154430}],"con":true,"img":false}]}
{"op":"mcm","clk":"5346574630","pt":1646091066361,"mc":[{"id":"1.195395447","rc":[{"atl":[[7.6,2.41]],"id":42315317}],"con":true,"img":false}]}
{"op":"mcm","clk":"5346574716","pt":1646091069253,"mc":[{"id":"1.195395447","rc":[{"atl":[[7.6,4.56]],"id":42315317},{"atl":[[5.2,6.7]],"id":43154430}],"con":true,"img":false}]}
{"op":"mcm","clk":"5346575629","pt":1646091098876,"mc":[{"id":"1.195395447","rc":[{"atl":[[5.2,3.15]],"id":43154430}],"con":true,"img":false}]}
{"op":"mcm","clk":"5346575827","pt":1646091104996,"mc":[{"id":"1.195395447","rc":[{"atl":[[7.6,2.15]],"id":42315317}],"con":true,"img":false}]}
{"op":"mcm","clk":"5346576055","pt":1646091111114,"mc":[{"id":"1.195395447","rc":[{"atl":[[5.2,6.7]],"id":43154430}],"con":true,"img":false}]}
{"op":"mcm","clk":"5346576063","pt":1646091111324,"mc":[{"id":"1.195395447","rc":[{"atl":[[7.6,4.56]],"id":42315317}],"con":true,"img":false}]}
{"op":"mcm","clk":"5346578702","pt":1646091186511,"mc":[{"id":"1.195395447","rc":[{"atl":[[5.2,3.54]],"id":43154430}],"con":true,"img":false}]}
{"op":"mcm","clk":"5346578787","pt":1646091189491,"mc":[{"id":"1.195395447","rc":[{"atl":[[7.6,2.41]],"id":42315317}],"con":true,"img":false}]}
{"op":"mcm","clk":"5346578911","pt":1646091192417,"mc":[{"id":"1.195395447","rc":[{"atl":[[7.6,4.56]],"id":42315317},{"atl":[[5.2,6.7]],"id":43154430}],"con":true,"img":false}]}
{"op":"mcm","clk":"5346580098","pt":1646091231143,"mc":[{"id":"1.195395447","rc":[{"atl":[[5.2,3.15]],"id":43154430}],"con":true,"img":false}]}
{"op":"mcm","clk":"5346580310","pt":1646091237353,"mc":[{"id":"1.195395447","rc":[{"atl":[[7.6,2.15]],"id":42315317}],"con":true,"img":false}]}
{"op":"mcm","clk":"5346580486","pt":1646091243372,"mc":[{"id":"1.195395447","rc":[{"atl":[[7.6,4.56]],"id":42315317}],"con":true,"img":false}]}
{"op":"mcm","clk":"5346580494","pt":1646091243576,"mc":[{"id":"1.195395447","rc":[{"atl":[[5.2,6.7]],"id":43154430}],"con":true,"img":false}]}
{"op":"mcm","clk":"5346582549","pt":1646091309751,"mc":[{"id":"1.195395447","rc":[{"atl":[[5.2,3.54]],"id":43154430}],"con":true,"img":false}]}
{"op":"mcm","clk":"5346582629","pt":1646091312740,"mc":[{"id":"1.195395447","rc":[{"atl":[[7.6,2.41]],"id":42315317}],"con":true,"img":false}]}
{"op":"mcm","clk":"5346582693","pt":1646091315623,"mc":[{"id":"1.195395447","rc":[{"atl":[[7.6,4.56]],"id":42315317},{"atl":[[5.2,6.7]],"id":43154430}],"con":true,"img":false}]}
{"op":"mcm","clk":"5346584027","pt":1646091363594,"mc":[{"id":"1.195395447","rc":[{"atl":[[5.2,3.15]],"id":43154430}],"con":true,"img":false}]}
{"op":"mcm","clk":"5346584171","pt":1646091369587,"mc":[{"id":"1.195395447","rc":[{"atl":[[7.6,2.15]],"id":42315317}],"con":true,"img":false}]}
{"op":"mcm","clk":"5346584334","pt":1646091375407,"mc":[{"id":"1.195395447","rc":[{"atl":[[5.2,6.7]],"id":43154430}],"con":true,"img":false}]}
{"op":"mcm","clk":"5346584337","pt":1646091375603,"mc":[{"id":"1.195395447","rc":[{"atl":[[7.6,4.56]],"id":42315317}],"con":true,"img":false}]}
{"op":"mcm","clk":"5346585921","pt":1646091432878,"mc":[{"id":"1.195395447","rc":[{"atl":[[5.2,3.54]],"id":43154430}],"con":true,"img":false}]}
{"op":"mcm","clk":"5346586020","pt":1646091435875,"mc":[{"id":"1.195395447","rc":[{"atl":[[7.6,2.41]],"id":42315317}],"con":true,"img":false}]}
{"op":"mcm","clk":"5346586104","pt":1646091438901,"mc":[{"id":"1.195395447","rc":[{"atl":[[7.6,4.56]],"id":42315317},{"atl":[[5.2,6.7]],"id":43154430}],"con":true,"img":false}]}
{"op":"mcm","clk":"5346587673","pt":1646091495862,"mc":[{"id":"1.195395447","rc":[{"atl":[[5.2,3.15]],"id":43154430}],"con":true,"img":false}]}
{"op":"mcm","clk":"5346587831","pt":1646091501753,"mc":[{"id":"1.195395447","rc":[{"atl":[[7.6,2.15]],"id":42315317}],"con":true,"img":false}]}
{"op":"mcm","clk":"5346588051","pt":1646091507659,"mc":[{"id":"1.195395447","rc":[{"atl":[[5.2,6.7]],"id":43154430}],"con":true,"img":false}]}
{"op":"mcm","clk":"5346588056","pt":1646091507758,"mc":[{"id":"1.195395447","rc":[{"atl":[[7.6,4.56]],"id":42315317}],"con":true,"img":false}]}
{"op":"mcm","clk":"5346589471","pt":1646091556053,"mc":[{"id":"1.195395447","rc":[{"atl":[[5.2,3.54]],"id":43154430}],"con":true,"img":false}]}
{"op":"mcm","clk":"5346589537","pt":1646091559140,"mc":[{"id":"1.195395447","rc":[{"atl":[[7.6,2.41]],"id":42315317}],"con":true,"img":false}]}
{"op":"mcm","clk":"5346589608","pt":1646091562066,"mc":[{"id":"1.195395447","rc":[{"atl":[[7.6,4.56]],"id":42315317},{"atl":[[5.2,6.7]],"id":43154430}],"con":true,"img":false}]}
{"op":"mcm","clk":"5346591426","pt":1646091627926,"mc":[{"id":"1.195395447","rc":[{"atl":[[5.2,3.15]],"id":43154430}],"con":true,"img":false}]}
{"op":"mcm","clk":"5346591564","pt":1646091634038,"mc":[{"id":"1.195395447","rc":[{"atl":[[7.6,2.15]],"id":42315317}],"con":true,"img":false}]}
{"op":"mcm","clk":"5346591704","pt":1646091639967,"mc":[{"id":"1.195395447","rc":[{"atl":[[5.2,6.7]],"id":43154430}],"con":true,"img":false}]}
{"op":"mcm","clk":"5346591706","pt":1646091640074,"mc":[{"id":"1.195395447","rc":[{"atl":[[7.6,4.56]],"id":42315317}],"con":true,"img":false}]}
{"op":"mcm","clk":"5346592690","pt":1646091679285,"mc":[{"id":"1.195395447","rc":[{"atl":[[5.2,3.54]],"id":43154430}],"con":true,"img":false}]}
{"op":"mcm","clk":"5346592765","pt":1646091682305,"mc":[{"id":"1.195395447","rc":[{"atl":[[7.6,2.41]],"id":42315317}],"con":true,"img":false}]}
{"op":"mcm","clk":"5346592850","pt":1646091685282,"mc":[{"id":"1.195395447","rc":[{"atl":[[7.6,4.56]],"id":42315317},{"atl":[[5.2,6.7]],"id":43154430}],"con":true,"img":false}]}
{"op":"mcm","clk":"5346594677","pt":1646091757286,"mc":[{"id":"1.195395447","rc":[{"atl":[[5.2,3.15]],"id":43154430}],"con":true,"img":false}]}
{"op":"mcm","clk":"5346594818","pt":1646091763296,"mc":[{"id":"1.195395447","rc":[{"atl":[[7.6,2.15]],"id":42315317}],"con":true,"img":false}]}
{"op":"mcm","clk":"5346594950","pt":1646091769209,"mc":[{"id":"1.195395447","rc":[{"atl":[[5.2,6.7]],"id":43154430}],"con":true,"img":false}]}
{"op":"mcm","clk":"5346594955","pt":1646091769310,"mc":[{"id":"1.195395447","rc":[{"atl":[[7.6,4.56]],"id":42315317}],"con":true,"img":false}]}
{"op":"mcm","clk":"5346595433","pt":1646091786843,"mc":[{"id":"1.195395447","rc":[{"atb":[[17,2.7],[12,10.87]],"id":40014837},{"atl":[[100,0.43],[200,2.7]],"id":40014837},{"atb":[[9.2,5.28],[6.2,24.35]],"id":38541023},{"atl":[[80,2.7],[42,2.7]],"id":38541023},{"atb":[[17,2.7],[12,10.06]],"id":37535509},{"atl":[[95,0.46],[190,2.7]],"id":37535509},{"atb":[[9.8,14.61],[14.5,3.2]],"id":36899944},{"atl":[[85,0.51],[170,2.7]],"id":36899944},{"atb":[[2.92,24.55],[1.93,121.04]],"id":42315317},{"atl":[[9.6,13.09],[7.6,11.12]],"id":42315317},{"atb":[[1.58,184.29],[2.12,38.65]],"id":43154430},{"atl":[[6.4,19.79],[5.2,17.01]],"id":43154430},{"atb":[[9,13.53],[10,4.81]],"id":40041375},{"atl":[[100,2.7],[55,0.8]],"id":40041375},{"atb":[[3.45,52.49],[3.95,14.67]],"id":37076580},{"atl":[[17.5,7.57],[15,3.09]],"id":37076580}],"con":true,"img":false}]}
{"op":"mcm","clk":"5346595618","pt":1646091793516,"mc":[{"id":"1.195395447","rc":[{"atb":[[2.94,4.3]],"id":42315317}],"con":true,"img":false}]}
{"op":"mcm","clk":"5346595833","pt":1646091802431,"mc":[{"id":"1.195395447","rc":[{"atb":[[2.96,4.18]],"id":42315317},{"atb":[[2.14,0]],"id":43154430}],"con":true,"img":false}]}
{"op":"mcm","clk":"5346595835","pt":1646091802536,"mc":[{"id":"1.195395447","rc":[{"atl":[[5.2,13.85]],"id":43154430}],"con":true,"img":false}]}
{"op":"mcm","clk":"5346595911","pt":1646091805565,"mc":[{"id":"1.195395447","rc":[{"atl":[[7.6,8.97]],"id":42315317}],"con":true,"img":false}]}
{"op":"mcm","clk":"5346595981","pt":1646091808440,"mc":[{"id":"1.195395447","rc":[{"atl":[[7.6,11.12]],"id":42315317},{"atl":[[5.2,17.01]],"id":43154430}],"con":true,"img":false}]}
{"op":"mcm","clk":"5346596218","pt":1646091816049,"mc":[{"id":"1.195395447","rc":[{"atb":[[2.16,7.92]],"id":43154430}],"con":true,"img":false}]}
{"op":"mcm","clk":"5346597139","pt":1646091845628,"mc":[{"id":"1.195395447","rc":[{"spn":26.0,"spf":1.0,"id":38541023},{"spn":59.0,"spf":1.0,"id":37535509},{"spn":52.0,"spf":1.0,"id":36899944},{"atb":[[2.92,2]],"id":42315317},{"atl":[[5.2,6.7]],"id":43154430},{"spn":33.5,"spf":1.0,"id":40041375},{"spn":9.9,"spf":1.0,"id":37076580}],"con":true,"img":false}]}
{"op":"mcm","clk":"5346597145","pt":1646091845682,"mc":[{"id":"1.195395447","rc":[{"atb":[[2.94,26.85]],"id":42315317},{"atl":[[5.1,10.31]],"id":43154430}],"con":true,"img":false}]}
{"op":"mcm","clk":"5346597352","pt":1646091853637,"mc":[{"id":"1.195395447","rc":[{"atb":[[2.96,0]],"id":42315317}],"con":true,"img":false}]}
{"op":"mcm","clk":"5346597601","pt":1646091862529,"mc":[{"id":"1.195395447","rc":[{"atb":[[2.98,4.14]],"id":42315317}],"con":true,"img":false}]}
{"op":"mcm","clk":"5346597726","pt":1646091866046,"mc":[{"id":"1.195395447","rc":[{"atl":[[200,0]],"id":40014837},{"atl":[[80,0]],"id":38541023},{"atl":[[190,0]],"id":37535509},{"atl":[[170,0]],"id":36899944},{"atl":[[6.4,0]],"id":43154430},{"atl":[[100,0]],"id":40041375}],"con":true,"img":false}]}
{"op":"mcm","clk":"5346597730","pt":1646091866125,"mc":[{"id":"1.195395447","rc":[{"atl":[[150,2.7]],"id":40014837},{"atl":[[48,2.7]],"id":38541023},{"atl":[[150,2.7]],"id":37535509},{"atl":[[130,2.7]],"id":36899944},{"atl":[[6,19.79]],"id":43154430},{"atl":[[65,2.7]],"id":40041375}],"con":true,"img":false}]}
{"op":"mcm","clk":"5346598584","pt":1646091889438,"mc":[{"id":"1.195395447","rc":[{"atl":[[5.2,3.15]],"id":43154430}],"con":true,"img":false}]}
{"op":"mcm","clk":"5346598800","pt":1646091895955,"mc":[{"id":"1.195395447","rc":[{"atl":[[7.6,8.71]],"id":42315317}],"con":true,"img":false}]}
{"op":"mcm","clk":"5346599148","pt":1646091904389,"mc":[{"id":"1.195395447","rc":[{"atl":[[5.2,6.7]],"id":43154430}],"con":true,"img":false}]}
{"op":"mcm","clk":"5346599158","pt":1646091904554,"mc":[{"id":"1.195395447","rc":[{"atl":[[7.6,11.12]],"id":42315317}],"con":true,"img":false}]}
{"op":"mcm","clk":"5346599988","pt":1646091925821,"mc":[{"id":"1.195395447","rc":[{"atl":[[5.2,3.54]],"id":43154430}],"con":true,"img":false}]}
{"op":"mcm","clk":"5346600099","pt":1646091928709,"mc":[{"id":"1.195395447","rc":[{"atl":[[7.6,8.97]],"id":42315317}],"con":true,"img":false}]}
{"op":"mcm","clk":"5346600199","pt":1646091931685,"mc":[{"id":"1.195395447","rc":[{"atl":[[7.6,11.12]],"id":42315317},{"atl":[[5.2,6.7]],"id":43154430}],"con":true,"img":false}]}
{"op":"mcm","clk":"5346603080","pt":1646092024708,"mc":[{"id":"1.195395447","rc":[{"atl":[[5.2,3.15]],"id":43154430}],"con":true,"img":false}]}
{"op":"mcm","clk":"5346603082","pt":1646092024812,"mc":[{"id":"1.195395447","rc":[{"atb":[[2.1,164.7]],"id":43154430},{"atl":[[4.2,10.31]],"id":43154430}],"con":true,"img":false}]}
{"op":"mcm","clk":"5346603085","pt":1646092024915,"mc":[{"id":"1.195395447","rc":[{"atb":[[12,19.96]],"id":40014837},{"atl":[[320,2]],"id":40014837},{"atb":[[4.2,31.25]],"id":38541023},{"atl":[[42,5.14]],"id":38541023},{"atb":[[8,14.29]],"id":37535509},{"atl":[[150,4.7]],"id":37535509},{"atb":[[7.4,15.62]],"id":36899944},{"atl":[[130,4.7]],"id":36899944},{"atb":[[3.05,20.3]],"id":42315317},{"atl":[[10.5,10.53]],"id":42315317},{"atb":[[4.5,28.57]],"id":40041375},{"atl":[[65,4.7]],"id":40041375},{"atb":[[2.84,54.35]],"id":37076580},{"atl":[[14.5,7.41]],"id":37076580}],"con":true,"img":false}]}
{"op":"mcm","clk":"5346603312","pt":1646092030645,"mc":[{"id":"1.195395447","rc":[{"atl":[[7.6,8.71]],"id":42315317}],"con":true,"img":false}]}
{"op":"mcm","clk":"5346603385","pt":1646092033009,"mc":[{"id":"1.195395447","rc":[{"atb":[[2.94,4.3]],"id":42315317}],"con":true,"img":false}]}
{"op":"mcm","clk":"5346603388","pt":1646092033114,"mc":[{"id":"1.195395447","rc":[{"atb":[[2.92,24.55]],"id":42315317}],"con":true,"img":false}]}
{"op":"mcm","clk":"5346603503","pt":1646092036656,"mc":[{"id":"1.195395447","rc":[{"atl":[[5.2,6.7]],"id":43154430}],"con":true,"img":false}]}
{"op":"mcm","clk":"5346603507","pt":1646092036759,"mc":[{"id":"1.195395447","rc":[{"atl":[[7.6,11.12]],"id":42315317}],"con":true,"img":false}]}
{"op":"mcm","clk":"5346603625","pt":1646092040051,"mc":[{"id":"1.195395447","rc":[{"atb":[[2.98,0]],"id":42315317}],"con":true,"img":false}]}
{"op":"mcm","clk":"5346603879","pt":1646092048982,"mc":[{"id":"1.195395447","rc":[{"atb":[[2.96,4.18]],"id":42315317},{"atl":[[5.2,3.54]],"id":43154430}],"con":true,"img":false}]}
{"op":"mcm","clk":"5346603964","pt":1646092051962,"mc":[{"id":"1.195395447","rc":[{"atl":[[7.6,8.97]],"id":42315317}],"con":true,"img":false}]}
{"op":"mcm","clk":"5346604041","pt":1646092054986,"mc":[{"id":"1.195395447","rc":[{"atl":[[7.6,11.12]],"id":42315317},{"atl":[[5.2,6.7]],"id":43154430}],"con":true,"img":false}]}
{"op":"mcm","clk":"5346604301","pt":1646092064597,"mc":[{"id":"1.195395447","rc":[{"atl":[[15,0]],"id":37076580}],"con":true,"img":false}]}
{"op":"mcm","clk":"5346604303","pt":1646092064702,"mc":[{"id":"1.195395447","rc":[{"atl":[[14,3.09],[14.5,0],[15,7.14]],"id":37076580}],"con":true,"img":false}]}
{"op":"mcm","clk":"5346604308","pt":1646092064905,"mc":[{"id":"1.195395447","rc":[{"atl":[[13.5,7.14],[15,0]],"id":37076580}],"con":true,"img":false}]}
{"op":"mcm","clk":"5346604562","pt":1646092074705,"mc":[{"id":"1.195395447","rc":[{"atb":[[2.12,127.94],[2.1,73.79]],"id":43154430}],"con":true,"img":false}]}
{"op":"mcm","clk":"5346604583","pt":1646092075419,"mc":[{"id":"1.195395447","rc":[{"atl":[[48,0]],"id":38541023}],"con":true,"img":false}]}
{"op":"mcm","clk":"5346604586","pt":1646092075477,"mc":[{"id":"1.195395447","rc":[{"atl":[[40,2.7]],"id":38541023}],"con":true,"img":false}]}
{"op":"mcm","clk":"5346605196","pt":1646092094907,"mc":[{"id":"1.195395447","rc":[{"spn":25.0,"spf":1.0,"id":38541023},{"spn":5.32,"spf":1.0,"id":42315317},{"atl":[[6,0]],"id":43154430},{"spn":9.15,"spf":1.0,"id":37076580}],"con":true,"img":false}]}
{"op":"mcm","clk":"5346605197","pt":1646092095008,"mc":[{"id":"1.195395447","rc":[{"atl":[[5.7,19.79]],"id":43154430}],"con":true,"img":false}]}
{"op":"mcm","clk":"5346605855","pt":1646092114715,"mc":[{"id":"1.195395447","rc":[{"atl":[[14,0]],"id":37076580}],"con":true,"img":false}]}
{"op":"mcm","clk":"5346605859","pt":1646092114817,"mc":[{"id":"1.195395447","rc":[{"atl":[[13,3.09],[13.5,0],[15,7.14]],"id":37076580}],"con":true,"img":false}]}
{"op":"mcm","clk":"5346605863","pt":1646092114919,"mc":[{"id":"1.195395447","rc":[{"atl":[[12.5,7.14],[15,0]],"id":37076580}],"con":true,"img":false}]}
{"op":"mcm","clk":"5346606741","pt":1646092141078,"mc":[{"id":"1.195395447","rc":[{"atb":[[4.4,4.64]],"id":37076580}],"con":true,"img":false}]}
{"op":"mcm","clk":"5346606747","pt":1646092141179,"mc":[{"id":"1.195395447","rc":[{"atb":[[4.3,26.59]],"id":37076580}],"con":true,"img":false}]}
{"op":"mcm","clk":"5346607370","pt":1646092157080,"mc":[{"id":"1.195395447","rc":[{"atl":[[5.2,3.15]],"id":43154430},{"spn":8.65,"spf":1.0,"id":37076580}],"con":true,"img":false}]}
{"op":"mcm","clk":"5346607552","pt":1646092163123,"mc":[{"id":"1.195395447","rc":[{"atl":[[7.6,8.71]],"id":42315317}],"con":true,"img":false}]}
{"op":"mcm","clk":"5346607766","pt":1646092168923,"mc":[{"id":"1.195395447","rc":[{"atl":[[5.2,6.7]],"id":43154430}],"con":true,"img":false}]}
{"op":"mcm","clk":"5346607770","pt":1646092169027,"mc":[{"id":"1.195395447","rc":[{"atl":[[7.6,11.12]],"id":42315317}],"con":true,"img":false}]}
{"op":"mcm","clk":"5346607786","pt":1646092169691,"mc":[{"id":"1.195395447","rc":[{"atl":[[13,0]],"id":37076580}],"con":true,"img":false}]}
{"op":"mcm","clk":"5346607791","pt":1646092169796,"mc":[{"id":"1.195395447","rc":[{"atl":[[12.5,3.09],[15,7.14]],"id":37076580}],"con":true,"img":false}]}
{"op":"mcm","clk":"5346607880","pt":1646092172308,"mc":[{"id":"1.195395447","rc":[{"atl":[[5.2,3.54]],"id":43154430}],"con":true,"img":false}]}
{"op":"mcm","clk":"5346607998","pt":1646092175225,"mc":[{"id":"1.195395447","rc":[{"atl":[[7.6,8.97]],"id":42315317}],"con":true,"img":false}]}
{"op":"mcm","clk":"5346608119","pt":1646092178309,"mc":[{"id":"1.195395447","rc":[{"atl":[[7.6,11.12]],"id":42315317},{"atl":[[5.2,6.7]],"id":43154430}],"con":true,"img":false}]}
{"op":"mcm","clk":"5346609083","pt":1646092203670,"mc":[{"id":"1.195395447","rc":[{"atl":[[12.5,0]],"id":37076580}],"con":true,"img":false}]}
{"op":"mcm","clk":"5346609085","pt":1646092203773,"mc":[{"id":"1.195395447","rc":[{"atl":[[14.5,3.09]],"id":37076580}],"con":true,"img":false}]}
{"op":"mcm","clk":"5346609146","pt":1646092205465,"mc":[{"id":"1.195395447","rc":[{"atl":[[14,7.14],[15,0]],"id":37076580}],"con":true,"img":false}]}
{"op":"mcm","clk":"5346611986","pt":1646092271964,"mc":[{"id":"1.195395447","rc":[{"atl":[[14.5,0]],"id":37076580},{"spn":9.4,"spf":1.0,"id":37076580}],"con":true,"img":false}]}
{"op":"mcm","clk":"5346611989","pt":1646092272067,"mc":[{"id":"1.195395447","rc":[{"atl":[[13.5,3.09],[15,7.14]],"id":37076580}],"con":true,"img":false}]}
{"op":"mcm","clk":"5346611993","pt":1646092272170,"mc":[{"id":"1.195395447","rc":[{"atl":[[14,0],[15,0]],"id":37076580}],"con":true,"img":false}]}
{"op":"mcm","clk":"5346611998","pt":1646092272272,"mc":[{"id":"1.195395447","rc":[{"atl":[[13,7.14]],"id":37076580}],"con":true,"img":false}]}
{"op":"mcm","clk":"5346612646","pt":1646092289975,"mc":[{"id":"1.195395447","rc":[{"atl":[[5.2,3.15]],"id":43154430}],"con":true,"img":false}]}
{"op":"mcm","clk":"5346612874","pt":1646092295568,"mc":[{"id":"1.195395447","rc":[{"atl":[[5.2,0]],"id":43154430}],"con":true,"img":false}]}
{"op":"mcm","clk":"5346612885","pt":1646092295874,"mc":[{"id":"1.195395447","rc":[{"atl":[[7.6,8.71]],"id":42315317}],"con":true,"img":false}]}
{"op":"mcm","clk":"5346612986","pt":1646092298599,"mc":[{"id":"1.195395447","rc":[{"atl":[[7.6,6.55]],"id":42315317}],"con":true,"img":false}]}
{"op":"mcm","clk":"5346613089","pt":1646092301481,"mc":[{"id":"1.195395447","rc":[{"atl":[[7.6,8.71]],"id":42315317},{"atl":[[5.2,3.15]],"id":43154430}],"con":true,"img":false}]}
{"op":"mcm","clk":"5346613097","pt":1646092301685,"mc":[{"id":"1.195395447","rc":[{"atl":[[5.2,6.7]],"id":43154430}],"con":true,"img":false}]}
{"op":"mcm","clk":"5346613103","pt":1646092301890,"mc":[{"id":"1.195395447","rc":[{"atl":[[7.6,11.12]],"id":42315317}],"con":true,"img":false}]}
{"op":"mcm","clk":"5346613688","pt":1646092318123,"mc":[{"id":"1.195395447","rc":[{"atb":[[4.3,24.59]],"id":37076580}],"con":true,"img":false}]}
{"op":"mcm","clk":"5346613691","pt":1646092318226,"mc":[{"id":"1.195395447","rc":[{"atb":[[4.4,6.64]],"id":37076580}],"con":true,"img":false}]}
{"op":"mcm","clk":"5346614140","pt":1646092332496,"mc":[{"id":"1.195395447","rc":[{"atl":[[13.5,0]],"id":37076580},{"spn":8.9,"spf":1.0,"id":37076580}],"con":true,"img":false}]}
{"op":"mcm","clk":"5346614145","pt":1646092332598,"mc":[{"id":"1.195395447","rc":[{"atl":[[12.5,3.09],[13,0],[15,7.14]],"id":37076580}],"con":true,"img":false}]}
{"op":"mcm","clk":"5346615305","pt":1646092364762,"mc":[{"id":"1.195395447","rc":[{"atb":[[3,60.89],[3.05,0]],"id":42315317},{"atb":[[2.04,96.15],[2.12,38.65]],"id":43154430},{"atb":[[2.84,0],[2.68,59.52]],"id":37076580}],"con":true,"img":false}]}
{"op":"mcm","clk":"5346615390","pt":1646092366660,"mc":[{"id":"1.195395447","rc":[{"atl":[[12,7.14],[15,0]],"id":37076580}],"con":true,"img":false}]}
{"op":"mcm","clk":"5346615669","pt":1646092373706,"mc":[{"id":"1.195395447","rc":[{"atb":[[2.96,0]],"id":42315317}],"con":true,"img":false}]}
{"op":"mcm","clk":"5346615842","pt":1646092378277,"mc":[{"id":"1.195395447","rc":[{"atb":[[4.4,4.64]],"id":37076580}],"con":true,"img":false}]}
{"op":"mcm","clk":"5346615847","pt":1646092378380,"mc":[{"id":"1.195395447","rc":[{"atb":[[4.3,26.59]],"id":37076580}],"con":true,"img":false}]}
{"op":"mcm","clk":"5346615888","pt":1646092379513,"mc":[{"id":"1.195395447","rc":[{"atl":[[12.5,0]],"id":37076580}],"con":true,"img":false}]}
{"op":"mcm","clk":"5346615893","pt":1646092379564,"mc":[{"id":"1.195395447","rc":[{"atl":[[15,3.09]],"id":37076580}],"con":true,"img":false}]}
{"op":"mcm","clk":"5346615897","pt":1646092379668,"mc":[{"id":"1.195395447","rc":[{"atl":[[12,0],[15,10.23]],"id":37076580}],"con":true,"img":false}]}
{"op":"mcm","clk":"5346616015","pt":1646092382703,"mc":[{"id":"1.195395447","rc":[{"atb":[[3.05,4]],"id":42315317}],"con":true,"img":false}]}
{"op":"mcm","clk":"5346617415","pt":1646092418752,"mc":[{"id":"1.195395447","rc":[{"atl":[[5.2,3.54]],"id":43154430},{"spn":9.9,"spf":1.0,"id":37076580}],"con":true,"img":false}]}
{"op":"mcm","clk":"5346617555","pt":1646092421729,"mc":[{"id":"1.195395447","rc":[{"atl":[[7.6,8.97]],"id":42315317}],"con":true,"img":false}]}
{"op":"mcm","clk":"5346617605","pt":1646092423323,"mc":[{"id":"1.195395447","rc":[{"atb":[[3.1,4.31],[3,20.29]],"id":42315317},{"atb":[[2.04,0],[2.08,92.59]],"id":43154430},{"atb":[[2.9,90.52],[2.68,0]],"id":37076580}],"con":true,"img":false}]}
{"op":"mcm","clk":"5346617644","pt":1646092424657,"mc":[{"id":"1.195395447","rc":[{"atl":[[7.6,11.12]],"id":42315317}],"con":true,"img":false}]}
{"op":"mcm","clk":"5346617648","pt":1646092424759,"mc":[{"id":"1.195395447","rc":[{"atl":[[5.2,6.7]],"id":43154430}],"con":true,"img":false}]}
{"op":"mcm","clk":"5346617838","pt":1646092430756,"mc":[{"id":"1.195395447","rc":[{"atb":[[3.05,0]],"id":42315317}],"con":true,"img":false}]}
{"op":"mcm","clk":"5346617842","pt":1646092430859,"mc":[{"id":"1.195395447","rc":[{"atb":[[3.1,0],[3.05,20.3]],"id":42315317}],"con":true,"img":false}]}
{"op":"mcm","clk":"5346617884","pt":1646092432650,"mc":[{"id":"1.195395447","rc":[{"atl":[[15,7.14]],"id":37076580}],"con":true,"img":false}]}
{"op":"mcm","clk":"5346617886","pt":1646092432753,"mc":[{"id":"1.195395447","rc":[{"atl":[[14.5,3.09]],"id":37076580}],"con":true,"img":false}]}
{"op":"mcm","clk":"5346617890","pt":1646092432857,"mc":[{"id":"1.195395447","rc":[{"atl":[[14,7.14],[15,0]],"id":37076580}],"con":true,"img":false}]}
{"op":"mcm","clk":"5346618138","pt":1646092439777,"mc":[{"id":"1.195395447","rc":[{"atb":[[2.96,4.18]],"id":42315317}],"con":true,"img":false}]}
{"op":"mcm","clk":"5346619673","pt":1646092485999,"mc":[{"id":"1.195395447","rc":[{"atl":[[14.5,0]],"id":37076580},{"spn":9.4,"spf":1.0,"id":37076580}],"con":true,"img":false}]}
{"op":"mcm","clk":"5346619677","pt":1646092486105,"mc":[{"id":"1.195395447","rc":[{"atl":[[13.5,3.09],[14,0],[15,7.14]],"id":37076580}],"con":true,"img":false}]}
{"op":"mcm","clk":"5346619682","pt":1646092486212,"mc":[{"id":"1.195395447","rc":[{"atl":[[13,7.14]],"id":37076580}],"con":true,"img":false}]}
{"op":"mcm","clk":"5346619687","pt":1646092486310,"mc":[{"id":"1.195395447","rc":[{"atl":[[15,0]],"id":37076580}],"con":true,"img":false}]}
{"op":"mcm","clk":"5346620249","pt":1646092506042,"mc":[{"id":"1.195395447","rc":[{"atb":[[9.8,0],[14.5,12.41]],"id":36899944}],"con":true,"img":false}]}
{"op":"mcm","clk":"5346621411","pt":1646092541995,"mc":[{"id":"1.195395447","rc":[{"atl":[[5.2,3.54]],"id":43154430}],"con":true,"img":false}]}
{"op":"mcm","clk":"5346621507","pt":1646092545123,"mc":[{"id":"1.195395447","rc":[{"atl":[[7.6,8.97]],"id":42315317}],"con":true,"img":false}]}
{"op":"mcm","clk":"5346621616","pt":1646092547997,"mc":[{"id":"1.195395447","rc":[{"atl":[[7.6,11.12]],"id":42315317},{"atl":[[5.2,6.7]],"id":43154430},{"spn":8.9,"spf":1.0,"id":37076580}],"con":true,"img":false}]}
{"op":"mcm","clk":"5346621926","pt":1646092557027,"mc":[{"id":"1.195395447","rc":[{"atl":[[13.5,0]],"id":37076580}],"con":true,"img":false}]}
{"op":"mcm","clk":"5346621935","pt":1646092557128,"mc":[{"id":"1.195395447","rc":[{"atl":[[12.5,3.09],[15,7.14]],"id":37076580}],"con":true,"img":false}]}
{"op":"mcm","clk":"5346621941","pt":1646092557229,"mc":[{"id":"1.195395447","rc":[{"atl":[[12,7.14],[13,0],[15,0]],"id":37076580}],"con":true,"img":false}]}
{"op":"mcm","clk":"5346622157","pt":1646092563699,"mc":[{"id":"1.195395447","rc":[{"atl":[[5.2,3.15]],"id":43154430}],"con":true,"img":false}]}
{"op":"mcm","clk":"5346622359","pt":1646092569243,"mc":[{"id":"1.195395447","rc":[{"atl":[[7.6,8.71]],"id":42315317}],"con":true,"img":false}]}
{"op":"mcm","clk":"5346622545","pt":1646092575047,"mc":[{"id":"1.195395447","rc":[{"atl":[[7.6,11.12]],"id":42315317}],"con":true,"img":false}]}
{"op":"mcm","clk":"5346622561","pt":1646092575562,"mc":[{"id":"1.195395447","rc":[{"atl":[[5.2,6.7]],"id":43154430}],"con":true,"img":false}]}
{"op":"mcm","clk":"5346623724","pt":1646092612094,"mc":[{"id":"1.195395447","rc":[{"atl":[[12.5,0]],"id":37076580},{"spn":8.4,"spf":1.0,"id":37076580}],"con":true,"img":false}]}
{"op":"mcm","clk":"5346623727","pt":1646092612196,"mc":[{"id":"1.195395447","rc":[{"atl":[[12,0],[15,10.23]],"id":37076580}],"con":true,"img":false}]}
{"op":"mcm","clk":"5346625389","pt":1646092665150,"mc":[{"id":"1.195395447","rc":[{"atl":[[5.2,3.54]],"id":43154430}],"con":true,"img":false}]}
{"op":"mcm","clk":"5346625480","pt":1646092668273,"mc":[{"id":"1.195395447","rc":[{"atl":[[7.6,8.97]],"id":42315317}],"con":true,"img":false}]}
{"op":"mcm","clk":"5346625570","pt":1646092671206,"mc":[{"id":"1.195395447","rc":[{"atl":[[7.6,11.12]],"id":42315317},{"atl":[[5.2,6.7]],"id":43154430}],"con":true,"img":false}]}
{"op":"mcm","clk":"5346626268","pt":1646092695500,"mc":[{"id":"1.195395447","rc":[{"atl":[[5.2,3.15]],"id":43154430},{"spn":9.9,"spf":1.0,"id":37076580}],"con":true,"img":false}]}
{"op":"mcm","clk":"5346626411","pt":1646092701087,"mc":[{"id":"1.195395447","rc":[{"atl":[[7.6,8.71]],"id":42315317}],"con":true,"img":false}]}
{"op":"mcm","clk":"5346626586","pt":1646092707288,"mc":[{"id":"1.195395447","rc":[{"atl":[[5.2,6.7]],"id":43154430}],"con":true,"img":false}]}
{"op":"mcm","clk":"5346626590","pt":1646092707389,"mc":[{"id":"1.195395447","rc":[{"atl":[[7.6,11.12]],"id":42315317}],"con":true,"img":false}]}
{"op":"mcm","clk":"5346627147","pt":1646092723952,"mc":[{"id":"1.195395447","rc":[{"atb":[[4.3,24.59]],"id":37076580}],"con":true,"img":false}]}
{"op":"mcm","clk":"5346627151","pt":1646092724051,"mc":[{"id":"1.195395447","rc":[{"atb":[[4.4,6.64]],"id":37076580}],"con":true,"img":false}]}
{"op":"mcm","clk":"5346627196","pt":1646092725129,"mc":[{"id":"1.195395447","rc":[{"atb":[[17,0],[12,9.09]],"id":40014837},{"atl":[[150,0],[100,0]],"id":40014837},{"atb":[[9.2,0],[6.2,0]],"id":38541023},{"atl":[[40,0],[42,2.44]],"id":38541023},{"atb":[[17,0],[12,0]],"id":37535509},{"atl":[[150,2],[95,0]],"id":37535509},{"atb":[[14.5,0]],"id":36899944},{"atl":[[130,2],[85,0]],"id":36899944},{"atb":[[2.92,2],[1.93,0]],"id":42315317},{"atl":[[9.6,0],[7.6,4.56]],"id":42315317},{"atb":[[1.58,0],[2.12,0]],"id":43154430},{"atl":[[5.1,0],[5.7,0]],"id":43154430},{"atb":[[9,0],[10,0]],"id":40041375},{"atl":[[65,2],[55,0]],"id":40041375},{"atb":[[3.45,0],[3.95,0]],"id":37076580},{"atl":[[17.5,0],[15,7.14]],"id":37076580}],"con":true,"img":false}]}
{"op":"mcm","clk":"5346627201","pt":1646092725233,"mc":[{"id":"1.195395447","rc":[{"atl":[[42,0],[50,4.74]],"id":38541023},{"atl":[[150,0],[210,2.63]],"id":37535509},{"atl":[[130,0],[190,2.69]],"id":36899944},{"atl":[[65,0],[70,3.91]],"id":40041375}],"con":true,"img":false}]}
{"op":"mcm","clk":"5346627321","pt":1646092729233,"mc":[{"id":"1.195395447","rc":[{"atb":[[17.5,2.7],[12.5,10.4]],"id":40014837},{"atl":[[110,0.39],[220,2.7]],"id":40014837},{"atb":[[9.2,5.28],[6.2,24.35]],"id":38541023},{"atl":[[40,2.7],[48,2.7]],"id":38541023},{"atb":[[17,2.7],[12,10.06]],"id":37535509},{"atl":[[100,0.43],[200,2.7]],"id":37535509},{"atb":[[9.8,14.61],[14.5,3.2]],"id":36899944},{"atl":[[90,0.48],[180,2.7]],"id":36899944},{"atb":[[2.92,24.55],[1.93,121.04]],"id":42315317},{"atl":[[9.6,13.09],[7.6,11.12]],"id":42315317},{"atb":[[1.58,184.29],[2.12,38.65]],"id":43154430},{"atl":[[5.2,17.01],[5.7,22.74]],"id":43154430},{"atb":[[9,13.53],[10,4.81]],"id":40041375},{"atl":[[65,2.7],[55,0.8]],"id":40041375},{"atb":[[3.45,52.49],[3.95,14.67]],"id":37076580},{"atl":[[17.5,7.57],[15,10.23]],"id":37076580}],"con":true,"img":false}]}
{"op":"mcm","clk":"5346627403","pt":1646092732151,"mc":[{"id":"1.195395447","rc":[{"atb":[[2.98,40.6],[3.05,0]],"id":42315317},{"atb":[[2.9,37.89],[2.74,57.47]],"id":37076580}],"con":true,"img":false}]}
{"op":"mcm","clk":"5346627463","pt":1646092734353,"mc":[{"id":"1.195395447","rc":[{"atb":[[2.96,0]],"id":42315317}],"con":true,"img":false}]}
{"op":"mcm","clk":"5346627565","pt":1646092737329,"mc":[{"id":"1.195395447","rc":[{"atb":[[2.94,0]],"id":42315317}],"con":true,"img":false}]}
{"op":"mcm","clk":"5346628018","pt":1646092749171,"mc":[{"id":"1.195395447","rc":[{"atb":[[3,24.89]],"id":42315317}],"con":true,"img":false}]}
{"op":"mcm","clk":"5346628200","pt":1646092755278,"mc":[{"id":"1.195395447","rc":[{"atl":[[40,5.26]],"id":38541023},{"atl":[[190,2]],"id":37535509},{"atl":[[190,0.69]],"id":36899944}],"con":true,"img":false}]}
{"op":"mcm","clk":"5346628205","pt":1646092755380,"mc":[{"id":"1.195395447","rc":[{"atl":[[50,2.7]],"id":38541023},{"atl":[[210,0.63]],"id":37535509},{"atl":[[170,2]],"id":36899944}],"con":true,"img":false}]}
{"op":"mcm","clk":"5346628416","pt":1646092762202,"mc":[{"id":"1.195395447","rc":[{"spn":61.5,"spf":1.0,"id":37535509},{"spn":54.5,"spf":1.0,"id":36899944},{"atb":[[2.98,0],[3.05,24.89]],"id":42315317},{"atb":[[2.9,87.09],[2.74,0]],"id":37076580}],"con":true,"img":false}]}
{"op":"mcm","clk":"5346628782","pt":1646092771805,"mc":[{"id":"1.195395447","rc":[{"atl":[[5.2,6.7]],"id":43154430},{"atl":[[15,7.14]],"id":37076580}],"con":true,"img":false}]}
{"op":"mcm","clk":"5346628785","pt":1646092771910,"mc":[{"id":"1.195395447","rc":[{"atl":[[5.1,10.31]],"id":43154430},{"atl":[[14.5,3.09]],"id":37076580}],"con":true,"img":false}]}
{"op":"mcm","clk":"5346628789","pt":1646092771962,"mc":[{"id":"1.195395447","rc":[{"atl":[[14,7.14]],"id":37076580}],"con":true,"img":false}]}
{"op":"mcm","clk":"5346628792","pt":1646092772065,"mc":[{"id":"1.195395447","rc":[{"atl":[[15,0]],"id":37076580}],"con":true,"img":false}]}
{"op":"mcm","clk":"5346628994","pt":1646092779202,"mc":[{"id":"1.195395447","rc":[{"atb":[[3,20.29]],"id":42315317}],"con":true,"img":false}]}
{"op":"mcm","clk":"5346629079","pt":1646092782379,"mc":[{"id":"1.195395447","rc":[{"atb":[[3.1,3.9]],"id":42315317}],"con":true,"img":false}]}
{"op":"mcm","clk":"5346629080","pt":1646092782479,"mc":[{"id":"1.195395447","rc":[{"atb":[[3.15,20.3],[3.05,0]],"id":42315317}],"con":true,"img":false}]}
{"op":"mcm","clk":"5346629180","pt":1646092785296,"mc":[{"id":"1.195395447","rc":[{"atb":[[2.94,4.73]],"id":42315317}],"con":true,"img":false}]}
{"op":"mcm","clk":"5346629271","pt":1646092788523,"mc":[{"id":"1.195395447","rc":[{"atl":[[5.2,3.54]],"id":43154430}],"con":true,"img":false}]}
{"op":"mcm","clk":"5346629337","pt":1646092791394,"mc":[{"id":"1.195395447","rc":[{"atl":[[7.6,8.97]],"id":42315317}],"con":true,"img":false}]}
{"op":"mcm","clk":"5346629341","pt":1646092791499,"mc":[{"id":"1.195395447","rc":[{"atb":[[3.1,0]],"id":42315317}],"con":true,"img":false}]}
{"op":"mcm","clk":"5346629343","pt":1646092791599,"mc":[{"id":"1.195395447","rc":[{"atb":[[3.15,0],[3.05,40.6]],"id":42315317}],"con":true,"img":false}]}
{"op":"mcm","clk":"5346629422","pt":1646092794426,"mc":[{"id":"1.195395447","rc":[{"atl":[[7.6,11.12]],"id":42315317},{"atl":[[5.2,6.7]],"id":43154430}],"con":true,"img":false}]}
{"op":"mcm","clk":"5346629925","pt":1646092809424,"mc":[{"id":"1.195395447","rc":[{"atb":[[16.5,7.85],[17.5,2.7],[19,4.5],[23,1.84],[11.5,15.45],[12.5,10.39]],"id":40014837},{"atl":[[260,0.76],[310,0.64],[160,0.83],[210,0.63],[110,0.39],[220,2.7]],"id":40014837},{"atb":[[8,17.38],[9,10.14],[10,4.5],[9.2,5.27],[6.2,24.33],[6,32.45]],"id":38541023},{"atl":[[75,1.78],[150,1.33],[40,5.26],[48,2.7],[50,2.69],[100,2]],"id":38541023},{"atb":[[16.5,7.85],[17,2.7],[19,4.5],[23,1.84],[11.5,15.45],[12,10.05]],"id":37535509},{"atl":[[260,0.76],[310,0.64],[160,0.83],[100,0.43],[200,2.7],[210,0.63]],"id":37535509},{"atb":[[16.5,5.23],[9.6,18.86],[19,2.25],[9.8,14.6],[14,9.36],[14.5,3.2]],"id":36899944},{"atl":[[140,0.95],[290,0.68],[90,0.48],[180,2.7],[190,0.69],[240,0.82]],"id":36899944},{"atb":[[2.8,67.6],[2.92,24.53],[2.9,42.7],[3.1,3.9],[3,20.28],[2.6,101.41],[1.93,120.96],[2.94,0]],"id":42315317},{"atl":[[9.6,13.08],[7.6,11.12],[12,18.02],[9.8,22.53],[8.8,16.94],[7.8,19.43]],"id":42315317},{"atb":[[2.24,6],[2,121.69],[1.58,184.17],[2.12,38.63],[1.9,180.28],[2.2,33.8],[2.16,7.92],[2.1,73.75]],"id":43154430},{"atl":[[5.1,10.3],[5.8,27.54],[5.3,30.74],[7.6,30.04],[5.2,6.7],[5.7,22.72],[6.6,35.4],[3.65,4.05]],"id":43154430},{"atb":[[9,13.52],[10,4.8],[12,3.68],[6.8,27.97],[9.8,9.22],[8.8,15.6]],"id":40041375},{"atl":[[65,2.7],[70,3.91],[140,1.42],[95,1.4],[190,1.04],[55,0.8]],"id":40041375},{"atb":[[4.8,10.67],[3.45,52.46],[4.3,24.58],[3.95,14.66],[3.4,67.6],[4.4,6.64],[3.9,41.96]],"id":37076580},{"atl":[[17.5,7.57],[18,7.77],[21,9.91],[26,7.92],[14.5,3.08],[15.5,9.11]],"id":37076580}],"con":true,"img":false}]}
{"op":"mcm","clk":"5346630107","pt":1646092814424,"mc":[{"id":"1.195395447","rc":[{"atl":[[220,0]],"id":40014837},{"atl":[[200,0]],"id":37535509},{"atl":[[180,0]],"id":36899944}],"con":true,"img":false}]}
{"op":"mcm","clk":"5346630111","pt":1646092814528,"mc":[{"id":"1.195395447","rc":[{"atl":[[150,2.7]],"id":40014837},{"atl":[[150,2.7]],"id":37535509},{"atl":[[130,2.7]],"id":36899944}],"con":true,"img":false}]}
{"op":"mcm","clk":"5346630119","pt":1646092814631,"mc":[{"id":"1.195395447","rc":[{"atl":[[150,4.7],[190,0]],"id":37535509},{"atl":[[130,4.7],[170,0]],"id":36899944}],"con":true,"img":false}]}
{"op":"mcm","clk":"5346630147","pt":1646092815659,"mc":[{"id":"1.195395447","rc":[{"atb":[[3.1,8.28]],"id":42315317}],"con":true,"img":false}]}
{"op":"mcm","clk":"5346630345","pt":1646092821033,"mc":[{"id":"1.195395447","rc":[{"atb":[[3.15,20.28],[3.05,0]],"id":42315317}],"con":true,"img":false}]}
{"op":"mcm","clk":"5346630605","pt":1646092827565,"mc":[{"id":"1.195395447","rc":[{"atb":[[3.1,4.37]],"id":42315317},{"spn":5.37,"spf":1.0,"id":42315317},{"spn":9.4,"spf":1.0,"id":37076580}],"con":true,"img":false}]}
{"op":"mcm","clk":"5346630618","pt":1646092827973,"mc":[{"id":"1.195395447","rc":[{"atl":[[5.2,3.15]],"id":43154430}],"con":true,"img":false}]}
{"op":"mcm","clk":"5346630844","pt":1646092833339,"mc":[{"id":"1.195395447","rc":[{"atl":[[7.6,8.7]],"id":42315317}],"con":true,"img":false}]}
{"op":"mcm","clk":"5346630952","pt":1646092836468,"mc":[{"id":"1.195395447","rc":[{"atb":[[2.96,4.17]],"id":42315317}],"con":true,"img":false}]}
{"op":"mcm","clk":"5346630979","pt":1646092837187,"mc":[{"id":"1.195395447","rc":[{"atl":[[48,0]],"id":38541023}],"con":true,"img":false}]}
{"op":"mcm","clk":"5346630982","pt":1646092837290,"mc":[{"id":"1.195395447","rc":[{"atl":[[38,2.7]],"id":38541023}],"con":true,"img":false}]}
{"op":"mcm","clk":"5346631056","pt":1646092839661,"mc":[{"id":"1.195395447","rc":[{"atb":[[3.1,0]],"id":42315317},{"atl":[[5.2,6.7]],"id":43154430}],"con":true,"img":false}]}
{"op":"mcm","clk":"5346631062","pt":1646092839757,"mc":[{"id":"1.195395447","rc":[{"atb":[[3.15,0],[3.05,40.56]],"id":42315317}],"con":true,"img":false}]}
{"op":"mcm","clk":"5346631067","pt":1646092839862,"mc":[{"id":"1.195395447","rc":[{"atl":[[7.6,11.12]],"id":42315317}],"con":true,"img":false}]}
{"op":"mcm","clk":"5346631362","pt":1646092848611,"mc":[{"id":"1.195395447","rc":[{"atb":[[2.96,0]],"id":42315317}],"con":true,"img":false}]}
{"op":"mcm","clk":"5346631669","pt":1646092856396,"mc":[{"id":"1.195395447","rc":[{"atl":[[14.5,0]],"id":37076580}],"con":true,"img":false}]}
{"op":"mcm","clk":"5346631671","pt":1646092856498,"mc":[{"id":"1.195395447","rc":[{"atl":[[13.5,3.08],[15,7.14]],"id":37076580}],"con":true,"img":false}]}
{"op":"mcm","clk":"5346631675","pt":1646092856602,"mc":[{"id":"1.195395447","rc":[{"atl":[[13,7.14],[14,0],[15,0]],"id":37076580}],"con":true,"img":false}]}
{"op":"mcm","clk":"5346631704","pt":1646092857476,"mc":[{"id":"1.195395447","rc":[{"atb":[[3.1,3.9]],"id":42315317}],"con":true,"img":false}]}
{"op":"mcm","clk":"5346631707","pt":1646092857577,"mc":[{"id":"1.195395447","rc":[{"atb":[[3.15,20.28],[3.05,0]],"id":42315317}],"con":true,"img":false}]}
{"op":"mcm","clk":"5346631712","pt":1646092857681,"mc":[{"id":"1.195395447","rc":[{"atb":[[3.1,8.28]],"id":42315317}],"con":true,"img":false}]}
{"op":"mcm","clk":"5346631972","pt":1646092866494,"mc":[{"id":"1.195395447","rc":[{"atb":[[3.1,4.37]],"id":42315317}],"con":true,"img":false}]}
{"op":"mcm","clk":"5346632246","pt":1646092875321,"mc":[{"id":"1.195395447","rc":[{"atl":[[150,2]],"id":37535509},{"atl":[[130,2]],"id":36899944}],"con":true,"img":false}]}
{"op":"mcm","clk":"5346632249","pt":1646092875431,"mc":[{"id":"1.195395447","rc":[{"atl":[[140,2.7],[150,0],[160,2.83]],"id":37535509},{"atl":[[130,0],[140,2.95],[120,2.7]],"id":36899944},{"atb":[[3.1,0]],"id":42315317}],"con":true,"img":false}]}
{"op":"mcm","clk":"5346632257","pt":1646092875635,"mc":[{"id":"1.195395447","rc":[{"atb":[[3.15,0],[2.96,4.17],[3.05,40.56]],"id":42315317}],"con":true,"img":false}]}
{"op":"mcm","clk":"5346632607","pt":1646092884622,"mc":[{"id":"1.195395447","rc":[{"atb":[[2.96,0]],"id":42315317}],"con":true,"img":false}]}
{"op":"mcm","clk":"5346632979","pt":1646092893434,"mc":[{"id":"1.195395447","rc":[{"spn":24.0,"spf":1.0,"id":38541023},{"atb":[[3.1,4.37]],"id":42315317},{"spn":5.35,"spf":1.0,"id":42315317},{"spn":8.9,"spf":1.0,"id":37076580}],"con":true,"img":false}]}
{"op":"mcm","clk":"5346632983","pt":1646092893536,"mc":[{"id":"1.195395447","rc":[{"atb":[[3.1,8.28]],"id":42315317}],"con":true,"img":false}]}
{"op":"mcm","clk":"5346633012","pt":1646092894214,"mc":[{"id":"1.195395447","rc":[{"atl":[[140,0]],"id":37535509},{"atl":[[120,0]],"id":36899944}],"con":true,"img":false}]}
{"op":"mcm","clk":"5346633014","pt":1646092894316,"mc":[{"id":"1.195395447","rc":[{"atl":[[150,2.7],[160,0.83],[210,2.63]],"id":37535509},{"atl":[[130,2.7],[140,0.95],[190,2.69]],"id":36899944}],"con":true,"img":false}]}
{"op":"mcm","clk":"5346633361","pt":1646092903126,"mc":[{"id":"1.195395447","rc":[{"atb":[[4.4,4.64]],"id":37076580}],"con":true,"img":false}]}
{"op":"mcm","clk":"5346633364","pt":1646092903229,"mc":[{"id":"1.195395447","rc":[{"atb":[[4.3,26.58]],"id":37076580}],"con":true,"img":false}]}
{"op":"mcm","clk":"5346633393","pt":1646092904036,"mc":[{"id":"1.195395447","rc":[{"atl":[[150,4.7],[210,0.63]],"id":37535509},{"atl":[[130,4.7],[190,0.69]],"id":36899944}],"con":true,"img":false}]}
{"op":"mcm","clk":"5346633399","pt":1646092904236,"mc":[{"id":"1.195395447","rc":[{"atb":[[3.15,20.28],[3.05,0]],"id":42315317}],"con":true,"img":false}]}
{"op":"mcm","clk":"5346633698","pt":1646092911637,"mc":[{"id":"1.195395447","rc":[{"atb":[[3.1,4.37]],"id":42315317},{"atl":[[5.2,3.54]],"id":43154430}],"con":true,"img":false}]}
{"op":"mcm","clk":"5346633742","pt":1646092912864,"mc":[{"id":"1.195395447","rc":[{"atl":[[13.5,0]],"id":37076580}],"con":true,"img":false}]}
{"op":"mcm","clk":"5346633745","pt":1646092912966,"mc":[{"id":"1.195395447","rc":[{"atl":[[12.5,3.08]],"id":37076580}],"con":true,"img":false}]}
{"op":"mcm","clk":"5346633750","pt":1646092913069,"mc":[{"id":"1.195395447","rc":[{"atl":[[13,0],[15,7.14]],"id":37076580}],"con":true,"img":false}]}
{"op":"mcm","clk":"5346633754","pt":1646092913173,"mc":[{"id":"1.195395447","rc":[{"atl":[[12,7.14],[15,0]],"id":37076580}],"con":true,"img":false}]}
{"op":"mcm","clk":"5346633819","pt":1646092914763,"mc":[{"id":"1.195395447","rc":[{"atl":[[7.6,8.96]],"id":42315317}],"con":true,"img":false}]}
{"op":"mcm","clk":"5346633921","pt":1646092917560,"mc":[{"id":"1.195395447","rc":[{"atb":[[3.1,0]],"id":42315317},{"atl":[[7.6,11.12]],"id":42315317},{"atl":[[5.2,6.7]],"id":43154430}],"con":true,"img":false}]}
{"op":"mcm","clk":"5346633925","pt":1646092917663,"mc":[{"id":"1.195395447","rc":[{"atb":[[3.05,40.56]],"id":42315317}],"con":true,"img":false}]}
{"op":"mcm","clk":"5346633928","pt":1646092917766,"mc":[{"id":"1.195395447","rc":[{"atb":[[3.15,0]],"id":42315317}],"con":true,"img":false}]}
{"op":"mcm","clk":"5346634702","pt":1646092935468,"mc":[{"id":"1.195395447","rc":[{"atb":[[3.1,4.37]],"id":42315317}],"con":true,"img":false}]}
{"op":"mcm","clk":"5346634710","pt":1646092935677,"mc":[{"id":"1.195395447","rc":[{"atb":[[3.1,8.28]],"id":42315317}],"con":true,"img":false}]}
{"op":"mcm","clk":"5346635152","pt":1646092945812,"mc":[{"id":"1.195395447","rc":[{"atb":[[3.15,20.28],[3.05,0]],"id":42315317}],"con":true,"img":false}]}
{"op":"mcm","clk":"5346635288","pt":1646092949819,"mc":[{"id":"1.195395447","rc":[{"atl":[[150,2]],"id":37535509},{"atl":[[130,2]],"id":36899944}],"con":true,"img":false}]}
{"op":"mcm","clk":"5346635291","pt":1646092949921,"mc":[{"id":"1.195395447","rc":[{"atl":[[140,2.7],[160,2.83]],"id":37535509},{"atl":[[130,0],[140,2.95],[120,2.7]],"id":36899944}],"con":true,"img":false}]}
{"op":"mcm","clk":"5346635297","pt":1646092950024,"mc":[{"id":"1.195395447","rc":[{"atl":[[150,0]],"id":37535509}],"con":true,"img":false}]}
{"op":"mcm","clk":"5346635419","pt":1646092953723,"mc":[{"id":"1.195395447","rc":[{"atb":[[3.1,4.37]],"id":42315317},{"spn":5.37,"spf":1.0,"id":42315317},{"spn":8.4,"spf":1.0,"id":37076580}],"con":true,"img":false}]}
{"op":"mcm","clk":"5346635660","pt":1646092959595,"mc":[{"id":"1.195395447","rc":[{"atb":[[3.1,0]],"id":42315317}],"con":true,"img":false}]}
{"op":"mcm","clk":"5346635664","pt":1646092959697,"mc":[{"id":"1.195395447","rc":[{"atb":[[3.15,0],[3.05,40.56]],"id":42315317},{"atl":[[5.2,3.15]],"id":43154430}],"con":true,"img":false}]}
{"op":"mcm","clk":"5346635862","pt":1646092965236,"mc":[{"id":"1.195395447","rc":[{"atl":[[12.5,0]],"id":37076580}],"con":true,"img":false}]}
{"op":"mcm","clk":"5346635865","pt":1646092965340,"mc":[{"id":"1.195395447","rc":[{"atl":[[11.5,3.08],[12,0],[15,7.14]],"id":37076580}],"con":true,"img":false}]}
{"op":"mcm","clk":"5346635890","pt":1646092965908,"mc":[{"id":"1.195395447","rc":[{"atl":[[7.6,8.7]],"id":42315317}],"con":true,"img":false}]}
{"op":"mcm","clk":"5346635974","pt":1646092968010,"mc":[{"id":"1.195395447","rc":[{"atl":[[140,0]],"id":37535509},{"atl":[[120,0]],"id":36899944}],"con":true,"img":false}]}
{"op":"mcm","clk":"5346635978","pt":1646092968110,"mc":[{"id":"1.195395447","rc":[{"atl":[[150,2.7],[160,0.83],[210,2.63]],"id":37535509},{"atl":[[130,2.7],[140,0.95],[190,2.69]],"id":36899944}],"con":true,"img":false}]}
{"op":"mcm","clk":"5346636091","pt":1646092971705,"mc":[{"id":"1.195395447","rc":[{"atl":[[5.2,6.7]],"id":43154430}],"con":true,"img":false}]}
{"op":"mcm","clk":"5346636100","pt":1646092971912,"mc":[{"id":"1.195395447","rc":[{"atl":[[7.6,11.12]],"id":42315317}],"con":true,"img":false}]}
{"op":"mcm","clk":"5346636308","pt":1646092977656,"mc":[{"id":"1.195395447","rc":[{"atb":[[3.1,4.37]],"id":42315317}],"con":true,"img":false}]}
{"op":"mcm","clk":"5346636311","pt":1646092977713,"mc":[{"id":"1.195395447","rc":[{"atb":[[3.1,8.28]],"id":42315317}],"con":true,"img":false}]}
{"op":"mcm","clk":"5346636698","pt":1646092986030,"mc":[{"id":"1.195395447","rc":[{"atl":[[11.5,0]],"id":37076580}],"con":true,"img":false}]}
{"op":"mcm","clk":"5346636702","pt":1646092986138,"mc":[{"id":"1.195395447","rc":[{"atl":[[14.5,3.08]],"id":37076580}],"con":true,"img":false}]}
{"op":"mcm","clk":"5346636757","pt":1646092987425,"mc":[{"id":"1.195395447","rc":[{"atb":[[3.15,20.28]],"id":42315317}],"con":true,"img":false}]}
{"op":"mcm","clk":"5346636760","pt":1646092987528,"mc":[{"id":"1.195395447","rc":[{"atb":[[3.05,0]],"id":42315317}],"con":true,"img":false}]}
{"op":"mcm","clk":"5346636983","pt":1646092993049,"mc":[{"id":"1.195395447","rc":[{"atl":[[14,7.14],[15,0]],"id":37076580}],"con":true,"img":false}]}
{"op":"mcm","clk":"5346637095","pt":1646092995769,"mc":[{"id":"1.195395447","rc":[{"atl":[[150,4.7],[210,0.63]],"id":37535509},{"atl":[[130,4.7],[190,0.69]],"id":36899944},{"atb":[[3.1,4.37]],"id":42315317}],"con":true,"img":false}]}
{"op":"mcm","clk":"5346637373","pt":1646093001845,"mc":[{"id":"1.195395447","rc":[{"atb":[[3.1,0]],"id":42315317}],"con":true,"img":false}]}
{"op":"mcm","clk":"5346637380","pt":1646093001951,"mc":[{"id":"1.195395447","rc":[{"atb":[[3.05,40.56]],"id":42315317}],"con":true,"img":false}]}
{"op":"mcm","clk":"5346637384","pt":1646093002053,"mc":[{"id":"1.195395447","rc":[{"atb":[[3.15,0]],"id":42315317}],"con":true,"img":false}]}
{"op":"mcm","clk":"5346638052","pt":1646093019684,"mc":[{"id":"1.195395447","rc":[{"atb":[[3.1,4.37]],"id":42315317},{"spn":5.35,"spf":1.0,"id":42315317},{"spn":9.4,"spf":1.0,"id":37076580}],"con":true,"img":false}]}
{"op":"mcm","clk":"5346638055","pt":1646093019785,"mc":[{"id":"1.195395447","rc":[{"atb":[[3.15,20.28]],"id":42315317}],"con":true,"img":false}]}
{"op":"mcm","clk":"5346638057","pt":1646093019888,"mc":[{"id":"1.195395447","rc":[{"atb":[[3.1,8.28],[3.05,0]],"id":42315317}],"con":true,"img":false}]}
{"op":"mcm","clk":"5346638368","pt":1646093028980,"mc":[{"id":"1.195395447","rc":[{"atb":[[3.1,4.37]],"id":42315317}],"con":true,"img":false}]}
{"op":"mcm","clk":"5346638623","pt":1646093034989,"mc":[{"id":"1.195395447","rc":[{"atl":[[5.2,3.54]],"id":43154430}],"con":true,"img":false}]}
{"op":"mcm","clk":"5346638713","pt":1646093037712,"mc":[{"id":"1.195395447","rc":[{"atb":[[3.1,0]],"id":42315317}],"con":true,"img":false}]}
{"op":"mcm","clk":"5346638718","pt":1646093037919,"mc":[{"id":"1.195395447","rc":[{"atb":[[3.15,0],[2.96,4.17],[3.05,40.56]],"id":42315317}],"con":true,"img":false}]}
{"op":"mcm","clk":"5346638721","pt":1646093038022,"mc":[{"id":"1.195395447","rc":[{"atl":[[7.6,8.96]],"id":42315317}],"con":true,"img":false}]}
{"op":"mcm","clk":"5346638768","pt":1646093039406,"mc":[{"id":"1.195395447","rc":[{"atl":[[14.5,0]],"id":37076580}],"con":true,"img":false}]}
{"op":"mcm","clk":"5346638771","pt":1646093039508,"mc":[{"id":"1.195395447","rc":[{"atl":[[13.5,3.08]],"id":37076580}],"con":true,"img":false}]}
{"op":"mcm","clk":"5346638776","pt":1646093039611,"mc":[{"id":"1.195395447","rc":[{"atl":[[14,0],[15,7.14]],"id":37076580}],"con":true,"img":false}]}
{"op":"mcm","clk":"5346638778","pt":1646093039714,"mc":[{"id":"1.195395447","rc":[{"atl":[[13,7.14],[15,0]],"id":37076580}],"con":true,"img":false}]}
{"op":"mcm","clk":"5346638825","pt":1646093040895,"mc":[{"id":"1.195395447","rc":[{"atl":[[7.6,11.12]],"id":42315317},{"atl":[[5.2,6.7]],"id":43154430}],"con":true,"img":false}]}
{"op":"mcm","clk":"5346639048","pt":1646093047007,"mc":[{"id":"1.195395447","rc":[{"atb":[[2.96,0]],"id":42315317}],"con":true,"img":false}]}
{"op":"mcm","clk":"5346639361","pt":1646093055745,"mc":[{"id":"1.195395447","rc":[{"atb":[[3.1,4.37]],"id":42315317}],"con":true,"img":false}]}
{"op":"mcm","clk":"5346639370","pt":1646093055908,"mc":[{"id":"1.195395447","rc":[{"atb":[[3.15,20.28],[3.05,0]],"id":42315317}],"con":true,"img":false}]}
{"op":"mcm","clk":"5346639375","pt":1646093056010,"mc":[{"id":"1.195395447","rc":[{"atb":[[3.1,8.28]],"id":42315317}],"con":true,"img":false}]}
{"op":"mcm","clk":"5346639691","pt":1646093065055,"mc":[{"id":"1.195395447","rc":[{"atb":[[3.1,4.37]],"id":42315317}],"con":true,"img":false}]}
{"op":"mcm","clk":"5346639997","pt":1646093073931,"mc":[{"id":"1.195395447","rc":[{"atb":[[3.1,0],[2.96,4.17]],"id":42315317}],"con":true,"img":false}]}
{"op":"mcm","clk":"5346640000","pt":1646093074031,"mc":[{"id":"1.195395447","rc":[{"atb":[[3.15,0],[3.05,40.56]],"id":42315317}],"con":true,"img":false}]}
{"op":"mcm","clk":"5346640328","pt":1646093083081,"mc":[{"id":"1.195395447","rc":[{"atb":[[2.96,0]],"id":42315317},{"spn":5.32,"spf":1.0,"id":42315317},{"spn":8.9,"spf":1.0,"id":37076580}],"con":true,"img":false}]}
{"op":"mcm","clk":"5346640638","pt":1646093091569,"mc":[{"id":"1.195395447","rc":[{"atl":[[13.5,0]],"id":37076580}],"con":true,"img":false}]}
{"op":"mcm","clk":"5346640641","pt":1646093091672,"mc":[{"id":"1.195395447","rc":[{"atl":[[12.5,3.08],[15,7.14]],"id":37076580}],"con":true,"img":false}]}
{"op":"mcm","clk":"5346640646","pt":1646093091772,"mc":[{"id":"1.195395447","rc":[{"atl":[[13,0]],"id":37076580}],"con":true,"img":false}]}
{"op":"mcm","clk":"5346640654","pt":1646093091981,"mc":[{"id":"1.195395447","rc":[{"atb":[[3.1,8.28]],"id":42315317}],"con":true,"img":false}]}
{"op":"mcm","clk":"5346640660","pt":1646093092185,"mc":[{"id":"1.195395447","rc":[{"atl":[[5.2,3.15]],"id":43154430}],"con":true,"img":false}]}
{"op":"mcm","clk":"5346640712","pt":1646093093576,"mc":[{"id":"1.195395447","rc":[{"atl":[[10.5,0],[9.4,11.9]],"id":42315317},{"atb":[[2.14,73.75],[2.08,0]],"id":43154430}],"con":true,"img":false}]}
{"op":"mcm","clk":"5346640893","pt":1646093098491,"mc":[{"id":"1.195395447","rc":[{"atl":[[7.6,8.7]],"id":42315317}],"con":true,"img":false}]}
{"op":"mcm","clk":"5346640952","pt":1646093100695,"mc":[{"id":"1.195395447","rc":[{"atb":[[3.1,28.56],[3.05,0]],"id":42315317}],"con":true,"img":false}]}
{"op":"mcm","clk":"5346640954","pt":1646093100748,"mc":[{"id":"1.195395447","rc":[{"atb":[[3.1,8.28],[3.05,24.54]],"id":42315317}],"con":true,"img":false}]}
{"op":"mcm","clk":"5346641107","pt":1646093103986,"mc":[{"id":"1.195395447","rc":[{"atl":[[5.2,6.7]],"id":43154430}],"con":true,"img":false}]}
{"op":"mcm","clk":"5346641112","pt":1646093104088,"mc":[{"id":"1.195395447","rc":[{"atl":[[7.6,11.12]],"id":42315317}],"con":true,"img":false}]}
{"op":"mcm","clk":"5346641120","pt":1646093104292,"mc":[{"id":"1.195395447","rc":[{"atb":[[3.1,28.56],[3.05,0]],"id":42315317}],"con":true,"img":false}]}
{"op":"mcm","clk":"5346641277","pt":1646093108707,"mc":[{"id":"1.195395447","rc":[{"atl":[[12.5,0]],"id":37076580}],"con":true,"img":false}]}
{"op":"mcm","clk":"5346641281","pt":1646093108810,"mc":[{"id":"1.195395447","rc":[{"atl":[[14.5,3.08]],"id":37076580}],"con":true,"img":false}]}
{"op":"mcm","clk":"5346641334","pt":1646093110202,"mc":[{"id":"1.195395447","rc":[{"atb":[[2.16,0]],"id":43154430}],"con":true,"img":false}]}
{"op":"mcm","clk":"5346641458","pt":1646093113115,"mc":[{"id":"1.195395447","rc":[{"atb":[[3.1,24.65]],"id":42315317}],"con":true,"img":false}]}
{"op":"mcm","clk":"5346641566","pt":1646093115889,"mc":[{"id":"1.195395447","rc":[{"atb":[[3.1,20.28]],"id":42315317},{"atb":[[2.18,7.78]],"id":43154430}],"con":true,"img":false}]}
{"op":"mcm","clk":"5346641570","pt":1646093115992,"mc":[{"id":"1.195395447","rc":[{"atb":[[3.1,0],[3.05,40.56]],"id":42315317}],"con":true,"img":false}]}
{"op":"mcm","clk":"5346641659","pt":1646093118118,"mc":[{"id":"1.195395447","rc":[{"atl":[[14,7.14],[15,0]],"id":37076580}],"con":true,"img":false}]}
{"op":"mcm","clk":"5346642013","pt":1646093125693,"mc":[{"id":"1.195395447","rc":[{"atb":[[2.12,0]],"id":43154430}],"con":true,"img":false}]}
{"op":"mcm","clk":"5346642021","pt":1646093125808,"mc":[{"id":"1.195395447","rc":[{"atb":[[2.16,38.63]],"id":43154430}],"con":true,"img":false}]}
{"op":"mcm","clk":"5346642335","pt":1646093133829,"mc":[{"id":"1.195395447","rc":[{"atb":[[3.1,4.37]],"id":42315317}],"con":true,"img":false}]}
{"op":"mcm","clk":"5346642347","pt":1646093134037,"mc":[{"id":"1.195395447","rc":[{"atb":[[3.1,24.65],[3.05,0]],"id":42315317}],"con":true,"img":false}]}
{"op":"mcm","clk":"5346642352","pt":1646093134091,"mc":[{"id":"1.195395447","rc":[{"atb":[[3.1,8.28],[3.05,24.54]],"id":42315317}],"con":true,"img":false}]}
{"op":"mcm","clk":"5346642608","pt":1646093139856,"mc":[{"id":"1.195395447","rc":[{"atb":[[2.18,0]],"id":43154430}],"con":true,"img":false}]}
{"op":"mcm","clk":"5346642819","pt":1646093145831,"mc":[{"id":"1.195395447","rc":[{"spn":5.35,"spf":1.0,"id":42315317},{"atb":[[2.2,41.45]],"id":43154430},{"spn":9.4,"spf":1.0,"id":37076580}],"con":true,"img":false}]}
{"op":"mcm","clk":"5346643098","pt":1646093152053,"mc":[{"id":"1.195395447","rc":[{"atb":[[3.1,3.9]],"id":42315317}],"con":true,"img":false}]}
{"op":"mcm","clk":"5346643110","pt":1646093152413,"mc":[{"id":"1.195395447","rc":[{"atb":[[2.12,89.29]],"id":43154430}],"con":true,"img":false}]}
{"op":"mcm","clk":"5346643113","pt":1646093152516,"mc":[{"id":"1.195395447","rc":[{"atb":[[2.14,0]],"id":43154430}],"con":true,"img":false}]}
{"op":"mcm","clk":"5346643293","pt":1646093157961,"mc":[{"id":"1.195395447","rc":[{"atb":[[2.94,4.72]],"id":42315317}],"con":true,"img":false}]}
{"op":"mcm","clk":"5346643305","pt":1646093158217,"mc":[{"id":"1.195395447","rc":[{"atl":[[5.2,3.54]],"id":43154430}],"con":true,"img":false}]}
{"op":"mcm","clk":"5346643344","pt":1646093159242,"mc":[{"id":"1.195395447","rc":[{"atb":[[2.16,0]],"id":43154430},{"atl":[[14.5,0]],"id":37076580}],"con":true,"img":false}]}
{"op":"mcm","clk":"5346643350","pt":1646093159345,"mc":[{"id":"1.195395447","rc":[{"atb":[[2.14,38.63]],"id":43154430},{"atl":[[13.5,3.08],[15,7.14]],"id":37076580}],"con":true,"img":false}]}
{"op":"mcm","clk":"5346643355","pt":1646093159448,"mc":[{"id":"1.195395447","rc":[{"atl":[[14,0]],"id":37076580}],"con":true,"img":false}]}
{"op":"mcm","clk":"5346643382","pt":1646093160166,"mc":[{"id":"1.195395447","rc":[{"atb":[[3.1,24.18],[3.05,0]],"id":42315317}],"con":true,"img":false}]}
{"op":"mcm","clk":"5346643386","pt":1646093160218,"mc":[{"id":"1.195395447","rc":[{"atb":[[3.1,3.9],[3.05,20.28]],"id":42315317}],"con":true,"img":false}]}
{"op":"mcm","clk":"5346643423","pt":1646093161142,"mc":[{"id":"1.195395447","rc":[{"atl":[[7.6,8.96]],"id":42315317}],"con":true,"img":false}]}
{"op":"mcm","clk":"5346643533","pt":1646093164120,"mc":[{"id":"1.195395447","rc":[{"atl":[[7.6,11.12]],"id":42315317},{"atl":[[5.2,6.7]],"id":43154430}],"con":true,"img":false}]}
{"op":"mcm","clk":"5346643626","pt":1646093167262,"mc":[{"id":"1.195395447","rc":[{"atb":[[3.1,0]],"id":42315317}],"con":true,"img":false}]}
{"op":"mcm","clk":"5346643894","pt":1646093175948,"mc":[{"id":"1.195395447","rc":[{"atb":[[2.2,33.8]],"id":43154430}],"con":true,"img":false}]}
{"op":"mcm","clk":"5346643901","pt":1646093176153,"mc":[{"id":"1.195395447","rc":[{"atb":[[2.96,4.17]],"id":42315317}],"con":true,"img":false}]}
{"op":"mcm","clk":"5346644115","pt":1646093181855,"mc":[{"id":"1.195395447","rc":[{"atb":[[2.18,7.78]],"id":43154430}],"con":true,"img":false}]}
{"op":"mcm","clk":"5346644214","pt":1646093185098,"mc":[{"id":"1.195395447","rc":[{"atl":[[13,7.14],[15,0]],"id":37076580}],"con":true,"img":false}]}
{"op":"mcm","clk":"5346644496","pt":1646093192364,"mc":[{"id":"1.195395447","rc":[{"atl":[[13.5,0]],"id":37076580}],"con":true,"img":false}]}
{"op":"mcm","clk":"5346644503","pt":1646093192465,"mc":[{"id":"1.195395447","rc":[{"atl":[[13,0],[14.5,3.08],[15,7.14]],"id":37076580}],"con":true,"img":false}]}
{"op":"mcm","clk":"5346644530","pt":1646093192980,"mc":[{"id":"1.195395447","rc":[{"atb":[[4.3,24.58]],"id":37076580}],"con":true,"img":false}]}
{"op":"mcm","clk":"5346644535","pt":1646093193083,"mc":[{"id":"1.195395447","rc":[{"atb":[[4.4,6.64]],"id":37076580}],"con":true,"img":false}]}
{"op":"mcm","clk":"5346645335","pt":1646093217925,"mc":[{"id":"1.195395447","rc":[{"spn":5.32,"spf":1.0,"id":42315317},{"atl":[[14,7.14],[15,0]],"id":37076580}],"con":true,"img":false}]}
{"op":"mcm","clk":"5346645564","pt":1646093224347,"mc":[{"id":"1.195395447","rc":[{"atl":[[5.2,3.15]],"id":43154430}],"con":true,"img":false}]}
{"op":"mcm","clk":"5346645793","pt":1646093230356,"mc":[{"id":"1.195395447","rc":[{"atl":[[7.6,8.7]],"id":42315317}],"con":true,"img":false}]}
{"op":"mcm","clk":"5346646003","pt":1646093236258,"mc":[{"id":"1.195395447","rc":[{"atl":[[5.2,6.7]],"id":43154430}],"con":true,"img":false}]}
{"op":"mcm","clk":"5346646008","pt":1646093236359,"mc":[{"id":"1.195395447","rc":[{"atl":[[7.6,11.12]],"id":42315317}],"con":true,"img":false}]}
{"op":"mcm","clk":"5346646191","pt":1646093241146,"mc":[{"id":"1.195395447","rc":[{"atb":[[14.5,12.4]],"id":36899944}],"con":true,"img":false}]}
{"op":"mcm","clk":"5346646198","pt":1646093241253,"mc":[{"id":"1.195395447","rc":[{"atb":[[9.8,0]],"id":36899944}],"con":true,"img":false}]}
{"op":"mcm","clk":"5346646770","pt":1646093257155,"mc":[{"id":"1.195395447","rc":[{"atl":[[14.5,0]],"id":37076580}],"con":true,"img":false}]}
{"op":"mcm","clk":"5346646773","pt":1646093257260,"mc":[{"id":"1.195395447","rc":[{"atl":[[13.5,3.08],[14,0],[15,7.14]],"id":37076580}],"con":true,"img":false}]}
{"op":"mcm","clk":"5346646776","pt":1646093257362,"mc":[{"id":"1.195395447","rc":[{"atl":[[13,7.14],[15,0]],"id":37076580}],"con":true,"img":false}]}
{"op":"mcm","clk":"5346647712","pt":1646093281387,"mc":[{"id":"1.195395447","rc":[{"atl":[[5.2,3.54]],"id":43154430},{"spn":8.9,"spf":1.0,"id":37076580}],"con":true,"img":false}]}
{"op":"mcm","clk":"5346647821","pt":1646093284379,"mc":[{"id":"1.195395447","rc":[{"atl":[[7.6,8.96]],"id":42315317}],"con":true,"img":false}]}
{"op":"mcm","clk":"5346647942","pt":1646093287411,"mc":[{"id":"1.195395447","rc":[{"atl":[[7.6,11.12]],"id":42315317},{"atl":[[5.2,6.7]],"id":43154430}],"con":true,"img":false}]}
{"op":"mcm","clk":"5346648598","pt":1646093304648,"mc":[{"id":"1.195395447","rc":[{"atl":[[13.5,0]],"id":37076580}],"con":true,"img":false}]}
{"op":"mcm","clk":"5346648628","pt":1646093304752,"mc":[{"id":"1.195395447","rc":[{"atl":[[12.5,3.08]],"id":37076580}],"con":true,"img":false}]}
{"op":"mcm","clk":"5346648640","pt":1646093304855,"mc":[{"id":"1.195395447","rc":[{"atl":[[13,0],[15,7.14]],"id":37076580}],"con":true,"img":false}]}
{"op":"mcm","clk":"5346648646","pt":1646093304906,"mc":[{"id":"1.195395447","rc":[{"atl":[[12,7.14]],"id":37076580}],"con":true,"img":false}]}
{"op":"mcm","clk":"5346648652","pt":1646093305009,"mc":[{"id":"1.195395447","rc":[{"atl":[[15,0]],"id":37076580}],"con":true,"img":false}]}
{"op":"mcm","clk":"5346648916","pt":1646093311129,"mc":[{"id":"1.195395447","rc":[{"atb":[[4.4,4.64]],"id":37076580}],"con":true,"img":false}]}
{"op":"mcm","clk":"5346648919","pt":1646093311233,"mc":[{"id":"1.195395447","rc":[{"atb":[[4.3,26.58]],"id":37076580}],"con":true,"img":false}]}
{"op":"mcm","clk":"5346649392","pt":1646093325159,"mc":[{"id":"1.195395447","rc":[{"atl":[[38,0]],"id":38541023}],"con":true,"img":false}]}
{"op":"mcm","clk":"5346649396","pt":1646093325261,"mc":[{"id":"1.195395447","rc":[{"atl":[[48,2.7]],"id":38541023}],"con":true,"img":false}]}
{"op":"mcm","clk":"5346650258","pt":1646093350992,"mc":[{"id":"1.195395447","rc":[{"spn":25.0,"spf":1.0,"id":38541023},{"atl":[[12.5,0]],"id":37076580},{"spn":8.4,"spf":1.0,"id":37076580}],"con":true,"img":false}]}
{"op":"mcm","clk":"5346650261","pt":1646093351095,"mc":[{"id":"1.195395447","rc":[{"atl":[[11.5,3.08],[12,0],[15,7.14]],"id":37076580}],"con":true,"img":false}]}
{"op":"mcm","clk":"5346650264","pt":1646093351196,"mc":[{"id":"1.195395447","rc":[{"atl":[[11,7.14],[15,0]],"id":37076580}],"con":true,"img":false}]}
{"op":"mcm","clk":"5346650391","pt":1646093356282,"mc":[{"id":"1.195395447","rc":[{"atl":[[5.2,3.15]],"id":43154430}],"con":true,"img":false}]}
{"op":"mcm","clk":"5346650570","pt":1646093362294,"mc":[{"id":"1.195395447","rc":[{"atl":[[7.6,8.7]],"id":42315317}],"con":true,"img":false}]}
{"op":"mcm","clk":"5346650819","pt":1646093368726,"mc":[{"id":"1.195395447","rc":[{"atl":[[5.2,6.7]],"id":43154430}],"con":true,"img":false}]}
{"op":"mcm","clk":"5346650824","pt":1646093368882,"mc":[{"id":"1.195395447","rc":[{"atl":[[7.6,11.12]],"id":42315317}],"con":true,"img":false}]}
{"op":"mcm","clk":"5346651243","pt":1646093381434,"mc":[{"id":"1.195395447","rc":[{"atl":[[11.5,0]],"id":37076580}],"con":true,"img":false}]}
{"op":"mcm","clk":"5346651245","pt":1646093381537,"mc":[{"id":"1.195395447","rc":[{"atl":[[14.5,3.08],[15,7.14]],"id":37076580}],"con":true,"img":false}]}
{"op":"mcm","clk":"5346651247","pt":1646093381640,"mc":[{"id":"1.195395447","rc":[{"atl":[[11,0]],"id":37076580}],"con":true,"img":false}]}
{"op":"mcm","clk":"5346651250","pt":1646093381694,"mc":[{"id":"1.195395447","rc":[{"atl":[[14,7.69]],"id":37076580}],"con":true,"img":false}]}
{"op":"mcm","clk":"5346651253","pt":1646093381796,"mc":[{"id":"1.195395447","rc":[{"atl":[[15,0]],"id":37076580}],"con":true,"img":false}]}
{"op":"mcm","clk":"5346652013","pt":1646093404553,"mc":[{"id":"1.195395447","rc":[{"atl":[[5.2,3.54]],"id":43154430}],"con":true,"img":false}]}
{"op":"mcm","clk":"5346652129","pt":1646093407541,"mc":[{"id":"1.195395447","rc":[{"atl":[[7.6,8.96]],"id":42315317}],"con":true,"img":false}]}
{"op":"mcm","clk":"5346652266","pt":1646093410570,"mc":[{"id":"1.195395447","rc":[{"atl":[[7.6,11.12]],"id":42315317},{"atl":[[5.2,6.7]],"id":43154430}],"con":true,"img":false}]}
{"op":"mcm","clk":"5346652294","pt":1646093411447,"mc":[{"id":"1.195395447","rc":[{"atl":[[14.5,0]],"id":37076580},{"spn":9.4,"spf":1.0,"id":37076580}],"con":true,"img":false}]}
{"op":"mcm","clk":"5346652297","pt":1646093411550,"mc":[{"id":"1.195395447","rc":[{"atl":[[13.5,3.08],[14,0],[15,7.14]],"id":37076580}],"con":true,"img":false}]}
{"op":"mcm","clk":"5346652812","pt":1646093426367,"mc":[{"id":"1.195395447","rc":[{"atl":[[13.5,0]],"id":37076580}],"con":true,"img":false}]}
{"op":"mcm","clk":"5346652816","pt":1646093426471,"mc":[{"id":"1.195395447","rc":[{"atl":[[14.5,3.08]],"id":37076580}],"con":true,"img":false}]}
{"op":"mcm","clk":"5346653122","pt":1646093434777,"mc":[{"id":"1.195395447","rc":[{"atl":[[14,7.14],[15,0]],"id":37076580}],"con":true,"img":false}]}
{"op":"mcm","clk":"5346653574","pt":1646093441306,"mc":[{"id":"1.195395447","rc":[{"atl":[[48,0]],"id":38541023}],"con":true,"img":false}]}
{"op":"mcm","clk":"5346653579","pt":1646093441409,"mc":[{"id":"1.195395447","rc":[{"atl":[[38,2.7]],"id":38541023}],"con":true,"img":false}]}
{"op":"mcm","clk":"5346654378","pt":1646093470539,"mc":[{"id":"1.195395447","rc":[{"atl":[[14.5,0]],"id":37076580}],"con":true,"img":false}]}
{"op":"mcm","clk":"5346654380","pt":1646093470641,"mc":[{"id":"1.195395447","rc":[{"atl":[[13.5,3.08],[14,0],[15,7.14]],"id":37076580}],"con":true,"img":false}]}
{"op":"mcm","clk":"5346654381","pt":1646093470744,"mc":[{"id":"1.195395447","rc":[{"atl":[[13,7.14]],"id":37076580}],"con":true,"img":false}]}
{"op":"mcm","clk":"5346654382","pt":1646093470847,"mc":[{"id":"1.195395447","rc":[{"atl":[[15,0]],"id":37076580}],"con":true,"img":false}]}
{"op":"mcm","clk":"5346654863","pt":1646093488967,"mc":[{"id":"1.195395447","rc":[{"spn":24.0,"spf":1.0,"id":38541023},{"atl":[[5.2,3.15]],"id":43154430},{"spn":8.9,"spf":1.0,"id":37076580}],"con":true,"img":false}]}
{"op":"mcm","clk":"5346655020","pt":1646093494968,"mc":[{"id":"1.195395447","rc":[{"atl":[[7.6,8.7]],"id":42315317}],"con":true,"img":false}]}
{"op":"mcm","clk":"5346655243","pt":1646093500661,"mc":[{"id":"1.195395447","rc":[{"atl":[[5.2,6.7]],"id":43154430}],"con":true,"img":false}]}
{"op":"mcm","clk":"5346655250","pt":1646093500866,"mc":[{"id":"1.195395447","rc":[{"atl":[[7.6,11.12]],"id":42315317}],"con":true,"img":false}]}
{"op":"mcm","clk":"5346655618","pt":1646093513799,"mc":[{"id":"1.195395447","rc":[{"atl":[[13.5,0]],"id":37076580}],"con":true,"img":false}]}
{"op":"mcm","clk":"5346655622","pt":1646093513905,"mc":[{"id":"1.195395447","rc":[{"atl":[[12.5,3.08],[13,0],[15,7.14]],"id":37076580}],"con":true,"img":false}]}
{"op":"mcm","clk":"5346655627","pt":1646093514107,"mc":[{"id":"1.195395447","rc":[{"atl":[[12,7.14],[15,0]],"id":37076580}],"con":true,"img":false}]}
{"op":"mcm","clk":"5346656084","pt":1646093527806,"mc":[{"id":"1.195395447","rc":[{"atl":[[5.2,3.54]],"id":43154430}],"con":true,"img":false}]}
{"op":"mcm","clk":"5346656173","pt":1646093530840,"mc":[{"id":"1.195395447","rc":[{"atl":[[7.6,8.96]],"id":42315317}],"con":true,"img":false}]}
{"op":"mcm","clk":"5346656303","pt":1646093533725,"mc":[{"id":"1.195395447","rc":[{"atl":[[7.6,11.12]],"id":42315317},{"atl":[[5.2,6.7]],"id":43154430}],"con":true,"img":false}]}
{"op":"mcm","clk":"5346656549","pt":1646093542055,"mc":[{"id":"1.195395447","rc":[{"atl":[[38,0]],"id":38541023}],"con":true,"img":false}]}
{"op":"mcm","clk":"5346656551","pt":1646093542157,"mc":[{"id":"1.195395447","rc":[{"atl":[[48,2.7]],"id":38541023}],"con":true,"img":false}]}
{"op":"mcm","clk":"5346656780","pt":1646093550530,"mc":[{"id":"1.195395447","rc":[{"spn":25.0,"spf":1.0,"id":38541023},{"atl":[[12.5,0]],"id":37076580},{"spn":8.4,"spf":1.0,"id":37076580}],"con":true,"img":false}]}
{"op":"mcm","clk":"5346656782","pt":1646093550634,"mc":[{"id":"1.195395447","rc":[{"atl":[[12,0],[15,10.22]],"id":37076580}],"con":true,"img":false}]}
{"op":"mcm","clk":"5346657726","pt":1646093583990,"mc":[{"id":"1.195395447","rc":[{"atl":[[15,7.14]],"id":37076580}],"con":true,"img":false}]}
{"op":"mcm","clk":"5346657731","pt":1646093584094,"mc":[{"id":"1.195395447","rc":[{"atl":[[14.5,3.08]],"id":37076580}],"con":true,"img":false}]}
{"op":"mcm","clk":"5346657738","pt":1646093584302,"mc":[{"id":"1.195395447","rc":[{"atl":[[14,7.14],[15,0]],"id":37076580}],"con":true,"img":false}]}
{"op":"mcm","clk":"5346658156","pt":1646093597912,"mc":[{"id":"1.195395447","rc":[{"atl":[[48,0]],"id":38541023}],"con":true,"img":false}]}
{"op":"mcm","clk":"5346658159","pt":1646093598014,"mc":[{"id":"1.195395447","rc":[{"atl":[[38,2.7]],"id":38541023}],"con":true,"img":false}]}
{"op":"mcm","clk":"5346658820","pt":1646093620954,"mc":[{"id":"1.195395447","rc":[{"spn":24.0,"spf":1.0,"id":38541023},{"atl":[[5.2,3.15]],"id":43154430},{"spn":9.4,"spf":1.0,"id":37076580}],"con":true,"img":false}]}
{"op":"mcm","clk":"5346658947","pt":1646093625009,"mc":[{"id":"1.195395447","rc":[{"atl":[[14.5,0]],"id":37076580}],"con":true,"img":false}]}
{"op":"mcm","clk":"5346658949","pt":1646093625109,"mc":[{"id":"1.195395447","rc":[{"atl":[[13.5,3.08],[14,0],[15,7.14]],"id":37076580}],"con":true,"img":false}]}
{"op":"mcm","clk":"5346658953","pt":1646093625211,"mc":[{"id":"1.195395447","rc":[{"atl":[[13,7.14],[15,0]],"id":37076580}],"con":true,"img":false}]}
{"op":"mcm","clk":"5346659004","pt":1646093627057,"mc":[{"id":"1.195395447","rc":[{"atl":[[7.6,8.7]],"id":42315317}],"con":true,"img":false}]}
{"op":"mcm","clk":"5346659201","pt":1646093632933,"mc":[{"id":"1.195395447","rc":[{"atl":[[5.2,6.7]],"id":43154430}],"con":true,"img":false}]}
{"op":"mcm","clk":"5346659213","pt":1646093633240,"mc":[{"id":"1.195395447","rc":[{"atl":[[7.6,11.12]],"id":42315317}],"con":true,"img":false}]}
{"op":"mcm","clk":"5346659802","pt":1646093651158,"mc":[{"id":"1.195395447","rc":[{"atl":[[5.2,3.54]],"id":43154430}],"con":true,"img":false}]}
{"op":"mcm","clk":"5346659952","pt":1646093654201,"mc":[{"id":"1.195395447","rc":[{"atl":[[7.6,8.96]],"id":42315317}],"con":true,"img":false}]}
{"op":"mcm","clk":"5346660070","pt":1646093657081,"mc":[{"id":"1.195395447","rc":[{"atl":[[7.6,11.33]],"id":42315317},{"atl":[[5.2,7.01]],"id":43154430}],"con":true,"img":false}]}
{"op":"mcm","clk":"5346660686","pt":1646093678814,"mc":[{"id":"1.195395447","rc":[{"atl":[[13.5,0]],"id":37076580}],"con":true,"img":false}]}
{"op":"mcm","clk":"5346660692","pt":1646093678915,"mc":[{"id":"1.195395447","rc":[{"atl":[[12.5,3.08],[13,0],[15,7.14]],"id":37076580}],"con":true,"img":false}]}
{"op":"mcm","clk":"5346660858","pt":1646093683941,"mc":[{"id":"1.195395447","rc":[{"atb":[[2.14,112.38]],"id":43154430},{"spn":8.65,"spf":1.0,"id":37076580}],"con":true,"img":false}]}
{"op":"mcm","clk":"5346660862","pt":1646093684043,"mc":[{"id":"1.195395447","rc":[{"atb":[[2.12,0]],"id":43154430}],"con":true,"img":false}]}
{"op":"mcm","clk":"5346661183","pt":1646093692161,"mc":[{"id":"1.195395447","rc":[{"atl":[[12.5,0]],"id":37076580}],"con":true,"img":false}]}
{"op":"mcm","clk":"5346661188","pt":1646093692214,"mc":[{"id":"1.195395447","rc":[{"atl":[[14.5,3.08]],"id":37076580}],"con":true,"img":false}]}
{"op":"mcm","clk":"5346661480","pt":1646093699463,"mc":[{"id":"1.195395447","rc":[{"atl":[[14,7.14]],"id":37076580}],"con":true,"img":false}]}
{"op":"mcm","clk":"5346661484","pt":1646093699565,"mc":[{"id":"1.195395447","rc":[{"atl":[[15,0]],"id":37076580}],"con":true,"img":false}]}
{"op":"mcm","clk":"5346662069","pt":1646093714578,"mc":[{"id":"1.195395447","rc":[{"atb":[[2.12,89.29],[2.14,38.63]],"id":43154430}],"con":true,"img":false}]}
{"op":"mcm","clk":"5346662074","pt":1646093714679,"mc":[{"id":"1.195395447","rc":[{"atb":[[2.14,126.35]],"id":43154430}],"con":true,"img":false}]}
{"op":"mcm","clk":"5346662078","pt":1646093714783,"mc":[{"id":"1.195395447","rc":[{"atb":[[2.12,0]],"id":43154430}],"con":true,"img":false}]}
{"op":"mcm","clk":"5346662187","pt":1646093718389,"mc":[{"id":"1.195395447","rc":[{"atb":[[9.8,14.6]],"id":36899944}],"con":true,"img":false}]}
{"op":"mcm","clk":"5346662191","pt":1646093718494,"mc":[{"id":"1.195395447","rc":[{"atb":[[14.5,3.2]],"id":36899944}],"con":true,"img":false}]}
{"op":"mcm","clk":"5346663131","pt":1646093744443,"mc":[{"id":"1.195395447","rc":[{"atl":[[14.5,0]],"id":37076580},{"spn":9.4,"spf":1.0,"id":37076580}],"con":true,"img":false}]}
{"op":"mcm","clk":"5346663133","pt":1646093744497,"mc":[{"id":"1.195395447","rc":[{"atl":[[13.5,3.08]],"id":37076580}],"con":true,"img":false}]}
{"op":"mcm","clk":"5346663137","pt":1646093744598,"mc":[{"id":"1.195395447","rc":[{"atl":[[14,0],[15,7.14]],"id":37076580}],"con":true,"img":false}]}
{"op":"mcm","clk":"5346663139","pt":1646093744700,"mc":[{"id":"1.195395447","rc":[{"atl":[[13,7.14]],"id":37076580}],"con":true,"img":false}]}
{"op":"mcm","clk":"5346663141","pt":1646093744802,"mc":[{"id":"1.195395447","rc":[{"atl":[[15,0]],"id":37076580}],"con":true,"img":false}]}
{"op":"mcm","clk":"5346663409","pt":1646093753231,"mc":[{"id":"1.195395447","rc":[{"atl":[[5.2,3.47]],"id":43154430}],"con":true,"img":false}]}
{"op":"mcm","clk":"5346663424","pt":1646093753749,"mc":[{"id":"1.195395447","rc":[{"atb":[[2.12,89.29],[2.14,38.63]],"id":43154430}],"con":true,"img":false}]}
{"op":"mcm","clk":"5346663565","pt":1646093759239,"mc":[{"id":"1.195395447","rc":[{"atl":[[7.6,8.92]],"id":42315317}],"con":true,"img":false}]}
{"op":"mcm","clk":"5346663744","pt":1646093765770,"mc":[{"id":"1.195395447","rc":[{"atl":[[5.2,7.01]],"id":43154430}],"con":true,"img":false}]}
{"op":"mcm","clk":"5346663749","pt":1646093765873,"mc":[{"id":"1.195395447","rc":[{"atl":[[7.6,11.33]],"id":42315317}],"con":true,"img":false}]}
{"op":"mcm","clk":"5346663800","pt":1646093767365,"mc":[{"id":"1.195395447","rc":[{"atl":[[140,8.2]],"id":38541023}],"con":true,"img":false}]}
{"op":"mcm","clk":"5346664032","pt":1646093774360,"mc":[{"id":"1.195395447","rc":[{"atl":[[5.2,3.54]],"id":43154430}],"con":true,"img":false}]}
{"op":"mcm","clk":"5346664109","pt":1646093777391,"mc":[{"id":"1.195395447","rc":[{"atl":[[7.6,8.96]],"id":42315317}],"con":true,"img":false}]}
{"op":"mcm","clk":"5346664200","pt":1646093780363,"mc":[{"id":"1.195395447","rc":[{"atl":[[7.6,11.33]],"id":42315317},{"atl":[[5.2,7.01]],"id":43154430}],"con":true,"img":false}]}
{"op":"mcm","clk":"5346664695","pt":1646093795313,"mc":[{"id":"1.195395447","rc":[{"atl":[[13.5,0]],"id":37076580}],"con":true,"img":false}]}
{"op":"mcm","clk":"5346664698","pt":1646093795416,"mc":[{"id":"1.195395447","rc":[{"atl":[[12.5,3.08],[15,7.14]],"id":37076580}],"con":true,"img":false}]}
{"op":"mcm","clk":"5346664704","pt":1646093795518,"mc":[{"id":"1.195395447","rc":[{"atl":[[12,7.14],[13,0],[15,0]],"id":37076580}],"con":true,"img":false}]}
{"op":"mcm","clk":"5346664920","pt":1646093801518,"mc":[{"id":"1.195395447","rc":[{"atb":[[2.12,0],[2.14,112.38]],"id":43154430}],"con":true,"img":false}]}
{"op":"mcm","clk":"5346672614","pt":1646093807947,"mc":[{"id":"1.195395447","rc":[{"atb":[[9.8,0],[14.5,12.4]],"id":36899944},{"spn":8.4,"spf":1.0,"id":37076580}],"con":true,"img":false}]}
{"op":"mcm","clk":"5346672670","pt":1646093809638,"mc":[{"id":"1.195395447","rc":[{"atl":[[38,0]],"id":38541023}],"con":true,"img":false}]}
{"op":"mcm","clk":"5346672676","pt":1646093809740,"mc":[{"id":"1.195395447","rc":[{"atl":[[48,2.7]],"id":38541023}],"con":true,"img":false}]}
{"op":"mcm","clk":"5346673205","pt":1646093824179,"mc":[{"id":"1.195395447","rc":[{"atb":[[12,20.45],[13,6.25],[14,3.85],[15,1.43]],"id":40014837},{"atl":[[320,3],[340,1],[360,1],[380,1]],"id":40014837},{"atb":[[5.9,25.51],[6.2,38.75],[7,3.33],[6.6,8.93]],"id":38541023},{"atl":[[21,1],[23,2.27],[25,3.12],[27,4.81]],"id":38541023},{"atb":[[10,16.33],[11,5],[12,11.87],[9.6,14.53]],"id":37535509},{"atl":[[260,1.76],[280,1],[220,1],[240,1]],"id":37535509},{"atb":[[10,13.89],[11,7.5],[12,4.55],[13,1.67]],"id":36899944},{"atl":[[260,1],[200,1],[220,1],[240,1.82]],"id":36899944},{"atb":[[2.82,10.99],[2.74,43.1],[2.78,28.09],[2.7,73.53]],"id":42315317},{"atl":[[7.4,19.53],[6.2,3.85],[6.6,8.93],[7,12.5]],"id":42315317},{"atb":[[2.1,91.93],[1.99,126.26],[2.02,73.53],[2.06,47.17]],"id":43154430},{"atl":[[3.6,28.85],[3.55,19.61],[3.5,20],[3.75,45.45],[3.45,8.16],[3.7,46.3],[3.4,8.33],[3.65,32.35]],"id":43154430},{"atb":[[4.8,5.26],[4.4,22.06],[4.6,13.89],[4.2,65.62]],"id":40041375},{"atl":[[24,1],[26,2],[28,2.78],[30,4.31]],"id":40041375},{"atb":[[4.3,32.64],[3.85,43.86],[3.95,40.08],[4.1,16.13]],"id":37076580},{"atl":[[8.6,9.87],[9,15.62],[8.2,6.94],[7.8,2.94]],"id":37076580}],"con":true,"img":false}]}
{"op":"mcm","clk":"5346673210","pt":1646093824232,"mc":[{"id":"1.195395447","rc":[{"atl":[[40,2.7],[25,5.82]],"id":38541023},{"atl":[[70,1.91],[36,2.7]],"id":40041375},{"atl":[[8.6,17.01],[12,0]],"id":37076580}],"con":true,"img":false}]}
{"op":"mcm","clk":"5346673213","pt":1646093824333,"mc":[{"id":"1.195395447","rc":[{"atb":[[2.9,37.89],[3,50]],"id":37076580}],"con":true,"img":false}]}
{"op":"mcm","clk":"5346673217","pt":1646093824436,"mc":[{"id":"1.195395447","rc":[{"atb":[[2.14,38.63],[2.18,92.53]],"id":43154430}],"con":true,"img":false}]}
{"op":"mcm","clk":"5346673305","pt":1646093826232,"mc":[{"id":"1.195395447","rc":[{"atl":[[3.6,0],[3.5,0],[3.7,0],[3.4,0]],"id":43154430}],"con":true,"img":false}]}
{"op":"mcm","clk":"5346673437","pt":1646093829263,"mc":[{"id":"1.195395447","rc":[{"atl":[[150,0]],"id":40014837},{"atb":[[9.2,0]],"id":38541023},{"atl":[[48,0]],"id":38541023},{"atb":[[12.5,11.35],[14.5,3.2]],"id":36899944},{"atb":[[2.14,0]],"id":43154430},{"atl":[[65,0]],"id":40041375}],"con":true,"img":false}]}
{"op":"mcm","clk":"5346673443","pt":1646093829368,"mc":[{"id":"1.195395447","rc":[{"atl":[[220,2.7]],"id":40014837},{"atb":[[8.2,5.27]],"id":38541023},{"atl":[[80,2.7]],"id":38541023},{"atb":[[2.12,38.63]],"id":43154430},{"atl":[[110,2.7]],"id":40041375}],"con":true,"img":false}]}
{"op":"mcm","clk":"5346673784","pt":1646093837762,"mc":[{"id":"1.195395447","rc":[{"atb":[[2.18,84.75]],"id":43154430}],"con":true,"img":false}]}
{"op":"mcm","clk":"5346673836","pt":1646093839249,"mc":[{"id":"1.195395447","rc":[{"atl":[[110,0]],"id":40014837},{"atl":[[100,0]],"id":37535509},{"atl":[[90,0]],"id":36899944},{"atb":[[9,0],[10,0],[7,18.02]],"id":40041375},{"atl":[[12.5,0]],"id":37076580}],"con":true,"img":false}]}
{"op":"mcm","clk":"5346673839","pt":1646093839352,"mc":[{"id":"1.195395447","rc":[{"atl":[[130,0.39]],"id":40014837},{"atl":[[120,0.43]],"id":37535509},{"atl":[[110,0.48]],"id":36899944},{"atb":[[9,4.8]],"id":40041375},{"atl":[[13.5,3.08]],"id":37076580}],"con":true,"img":false}]}
{"op":"mcm","clk":"5346673985","pt":1646093843664,"mc":[{"id":"1.195395447","rc":[{"atb":[[2.22,9.53]],"id":43154430}],"con":true,"img":false}]}
{"op":"mcm","clk":"5346674113","pt":1646093847196,"mc":[{"id":"1.195395447","rc":[{"atl":[[3.45,0],[3.4,8.33]],"id":43154430}],"con":true,"img":false}]}
{"op":"mcm","clk":"5346674193","pt":1646093849293,"mc":[{"id":"1.195395447","rc":[{"atl":[[9.6,0]],"id":42315317},{"atl":[[5.1,0]],"id":43154430},{"atb":[[3.95,25.42]],"id":37076580}],"con":true,"img":false}]}
{"op":"mcm","clk":"5346674196","pt":1646093849398,"mc":[{"id":"1.195395447","rc":[{"atl":[[9.2,13.08]],"id":42315317},{"atl":[[4.9,10.3]],"id":43154430},{"atb":[[4.2,14.66]],"id":37076580}],"con":true,"img":false}]}
{"op":"mcm","clk":"5346674468","pt":1646093857209,"mc":[{"id":"1.195395447","rc":[{"atl":[[3.45,8.16],[3.4,0]],"id":43154430}],"con":true,"img":false}]}
{"op":"mcm","clk":"5346674529","pt":1646093859214,"mc":[{"id":"1.195395447","rc":[{"atl":[[44,2.7],[55,0]],"id":40041375}],"con":true,"img":false}]}
{"op":"mcm","clk":"5346674533","pt":1646093859317,"mc":[{"id":"1.195395447","rc":[{"atb":[[17.5,0]],"id":40014837},{"atl":[[40,0]],"id":38541023},{"atb":[[17,0]],"id":37535509},{"atb":[[14.5,0]],"id":36899944},{"atl":[[7.6,4.78]],"id":42315317}],"con":true,"img":false}]}
{"op":"mcm","clk":"5346674538","pt":1646093859420,"mc":[{"id":"1.195395447","rc":[{"atb":[[20,2.7]],"id":40014837},{"atl":[[34,2.7]],"id":38541023},{"atb":[[18,2.7]],"id":37535509},{"atb":[[16.5,8.44]],"id":36899944},{"atl":[[6.8,6.55]],"id":42315317}],"con":true,"img":false}]}
{"op":"mcm","clk":"5346674563","pt":1646093860497,"mc":[{"id":"1.195395447","rc":[{"atl":[[3.45,0]],"id":43154430}],"con":true,"img":false}]}
{"op":"mcm","clk":"5346674568","pt":1646093860598,"mc":[{"id":"1.195395447","rc":[{"atl":[[3.4,8.33]],"id":43154430}],"con":true,"img":false}]}
{"op":"mcm","clk":"5346674821","pt":1646093869238,"mc":[{"id":"1.195395447","rc":[{"atb":[[17,7.46]],"id":40014837},{"spn":15.5,"spf":1.0,"id":38541023},{"spn":59.5,"spf":1.0,"id":36899944},{"spn":4.62,"spf":1.0,"id":42315317},{"spn":2.82,"spf":1.0,"id":43154430},{"spn":18.0,"spf":1.0,"id":40041375},{"spn":6.3,"spf":1.0,"id":37076580}],"con":true,"img":false}]}
{"op":"mcm","clk":"5346674825","pt":1646093869340,"mc":[{"id":"1.195395447","rc":[{"atb":[[11.5,22.31],[12.5,0]],"id":40014837}],"con":true,"img":false}]}
{"op":"mcm","clk":"5346674836","pt":1646093869498,"mc":[{"id":"1.195395447","rc":[{"atl":[[5.7,0]],"id":43154430}],"con":true,"img":false}]}
{"op":"mcm","clk":"5346674843","pt":1646093869599,"mc":[{"id":"1.195395447","rc":[{"atl":[[5.2,29.74]],"id":43154430}],"con":true,"img":false}]}
{"op":"mcm","clk":"5346674882","pt":1646093870521,"mc":[{"id":"1.195395447","rc":[{"atl":[[3.45,8.16],[3.4,0]],"id":43154430}],"con":true,"img":false}]}
{"op":"mcm","clk":"5346674960","pt":1646093872216,"mc":[{"id":"1.195395447","rc":[{"atl":[[3.45,0],[3.4,8.33]],"id":43154430}],"con":true,"img":false}]}
{"op":"mcm","clk":"5346674984","pt":1646093872940,"mc":[{"id":"1.195395447","rc":[{"atl":[[3.45,8.16],[3.4,0]],"id":43154430}],"con":true,"img":false}]}
{"op":"mcm","clk":"5346675203","pt":1646093879249,"mc":[{"id":"1.195395447","rc":[{"atb":[[12.5,0],[14.5,9.19]],"id":36899944},{"atl":[[17.5,0],[15,9.19]],"id":37076580}],"con":true,"img":false}]}
{"op":"mcm","clk":"5346675245","pt":1646093880539,"mc":[{"id":"1.195395447","rc":[{"atl":[[190,1.69],[200,0]],"id":36899944},{"atl":[[24,0],[26,1]],"id":40041375}],"con":true,"img":false}]}
{"op":"mcm","clk":"5346675409","pt":1646093885162,"mc":[{"id":"1.195395447","rc":[{"atl":[[3.45,0],[3.4,8.33]],"id":43154430}],"con":true,"img":false}]}
{"op":"mcm","clk":"5346675451","pt":1646093885830,"mc":[{"id":"1.195395447","rc":[{"atl":[[5.2,26.19]],"id":43154430}],"con":true,"img":false}]}
{"op":"mcm","clk":"5346675603","pt":1646093890550,"mc":[{"id":"1.195395447","rc":[{"atl":[[30,2.59]],"id":40041375}],"con":true,"img":false}]}
{"op":"mcm","clk":"5346675649","pt":1646093892141,"mc":[{"id":"1.195395447","rc":[{"atl":[[7.6,2.36]],"id":42315317}],"con":true,"img":false}]}
{"op":"mcm","clk":"5346675746","pt":1646093895160,"mc":[{"id":"1.195395447","rc":[{"atl":[[3.45,8.16],[3.4,0]],"id":43154430}],"con":true,"img":false}]}
{"op":"mcm","clk":"5346675832","pt":1646093897546,"mc":[{"id":"1.195395447","rc":[{"atl":[[5.2,22.72]],"id":43154430}],"con":true,"img":false}]}
{"op":"mcm","clk":"5346675836","pt":1646093897649,"mc":[{"id":"1.195395447","rc":[{"atl":[[3.4,8.33]],"id":43154430}],"con":true,"img":false}]}
{"op":"mcm","clk":"5346675839","pt":1646093897750,"mc":[{"id":"1.195395447","rc":[{"atl":[[3.45,0]],"id":43154430}],"con":true,"img":false}]}
{"op":"mcm","clk":"5346675848","pt":1646093897955,"mc":[{"id":"1.195395447","rc":[{"atl":[[3.55,24.78]],"id":43154430}],"con":true,"img":false}]}
{"op":"mcm","clk":"5346675851","pt":1646093898059,"mc":[{"id":"1.195395447","rc":[{"atl":[[6.8,9.25]],"id":42315317}],"con":true,"img":false}]}
{"op":"mcm","clk":"5346675940","pt":1646093900570,"mc":[{"id":"1.195395447","rc":[{"atl":[[7.6,0]],"id":42315317},{"atl":[[34,3.79]],"id":40041375}],"con":true,"img":false}]}
{"op":"mcm","clk":"5346676055","pt":1646093903596,"mc":[{"id":"1.195395447","rc":[{"atl":[[6.8,11.9]],"id":42315317},{"atl":[[3.45,5.22]],"id":43154430}],"con":true,"img":false}]}
{"op":"mcm","clk":"5346676199","pt":1646093907698,"mc":[{"id":"1.195395447","rc":[{"atl":[[3.45,13.38]],"id":43154430}],"con":true,"img":false}]}
{"op":"mcm","clk":"5346676207","pt":1646093907800,"mc":[{"id":"1.195395447","rc":[{"atl":[[3.4,0]],"id":43154430}],"con":true,"img":false}]}
{"op":"mcm","clk":"5346676283","pt":1646093910307,"mc":[{"id":"1.195395447","rc":[{"atl":[[3.45,5.22],[3.4,8.33]],"id":43154430}],"con":true,"img":false}]}
{"op":"mcm","clk":"5346676676","pt":1646093920316,"mc":[{"id":"1.195395447","rc":[{"atl":[[3.45,13.38],[3.4,0]],"id":43154430}],"con":true,"img":false}]}
{"op":"mcm","clk":"5346676809","pt":1646093924219,"mc":[{"id":"1.195395447","rc":[{"atl":[[3.45,5.22],[3.4,8.33]],"id":43154430}],"con":true,"img":false}]}
{"op":"mcm","clk":"5346676816","pt":1646093924424,"mc":[{"id":"1.195395447","rc":[{"atl":[[3.65,28.3]],"id":43154430}],"con":true,"img":false}]}
{"op":"mcm","clk":"5346677135","pt":1646093934229,"mc":[{"id":"1.195395447","rc":[{"atl":[[3.45,13.38],[3.4,0]],"id":43154430},{"spn":2.84,"spf":1.0,"id":43154430},{"spn":19.0,"spf":1.0,"id":40041375}],"con":true,"img":false}]}
{"op":"mcm","clk":"5346677210","pt":1646093936633,"mc":[{"id":"1.195395447","rc":[{"atl":[[3.45,5.22],[3.4,8.33]],"id":43154430}],"con":true,"img":false}]}
{"op":"mcm","clk":"5346677573","pt":1646093946653,"mc":[{"id":"1.195395447","rc":[{"atl":[[3.45,13.38],[3.4,0]],"id":43154430}],"con":true,"img":false}]}
{"op":"mcm","clk":"5346677634","pt":1646093948249,"mc":[{"id":"1.195395447","rc":[{"atl":[[3.45,5.22],[3.4,8.33]],"id":43154430}],"con":true,"img":false}]}
{"op":"mcm","clk":"5346677666","pt":1646093949272,"mc":[{"id":"1.195395447","rc":[{"atl":[[4.9,0]],"id":43154430}],"con":true,"img":false}]}
{"op":"mcm","clk":"5346677670","pt":1646093949325,"mc":[{"id":"1.195395447","rc":[{"atl":[[4.1,10.3]],"id":43154430}],"con":true,"img":false}]}
{"op":"mcm","clk":"5346677674","pt":1646093949428,"mc":[{"id":"1.195395447","rc":[{"atl":[[3.45,13.38]],"id":43154430}],"con":true,"img":false}]}
{"op":"mcm","clk":"5346677680","pt":1646093949529,"mc":[{"id":"1.195395447","rc":[{"atl":[[3.4,0]],"id":43154430}],"con":true,"img":false}]}
{"op":"mcm","clk":"5346678002","pt":1646093959246,"mc":[{"id":"1.195395447","rc":[{"atl":[[4.1,0]],"id":43154430}],"con":true,"img":false}]}
{"op":"mcm","clk":"5346678004","pt":1646093959350,"mc":[{"id":"1.195395447","rc":[{"atl":[[4.9,10.3]],"id":43154430}],"con":true,"img":false}]}
{"op":"mcm","clk":"5346678504","pt":1646093972772,"mc":[{"id":"1.195395447","rc":[{"atl":[[3.45,5.22],[3.4,8.33]],"id":43154430}],"con":true,"img":false}]}
{"op":"mcm","clk":"5346678513","pt":1646093972975,"mc":[{"id":"1.195395447","rc":[{"atl":[[3.45,13.38]],"id":43154430}],"con":true,"img":false}]}
{"op":"mcm","clk":"5346678516","pt":1646093973080,"mc":[{"id":"1.195395447","rc":[{"atl":[[3.4,0]],"id":43154430}],"con":true,"img":false}]}
{"op":"mcm","clk":"5346679037","pt":1646093986395,"mc":[{"id":"1.195395447","rc":[{"atl":[[3.4,8.33]],"id":43154430}],"con":true,"img":false}]}
{"op":"mcm","clk":"5346679041","pt":1646093986497,"mc":[{"id":"1.195395447","rc":[{"atl":[[3.45,5.22]],"id":43154430}],"con":true,"img":false}]}
{"op":"mcm","clk":"5346679443","pt":1646093996520,"mc":[{"id":"1.195395447","rc":[{"atl":[[3.45,13.38],[3.4,0]],"id":43154430}],"con":true,"img":false}]}
{"op":"mcm","clk":"5346679492","pt":1646093997855,"mc":[{"id":"1.195395447","rc":[{"atl":[[3.45,5.22],[3.4,8.33]],"id":43154430}],"con":true,"img":false}]}
{"op":"mcm","clk":"5346679498","pt":1646093998059,"mc":[{"id":"1.195395447","rc":[{"atl":[[3.45,13.38],[3.4,0]],"id":43154430}],"con":true,"img":false}]}
{"op":"mcm","clk":"5346679919","pt":1646094009760,"mc":[{"id":"1.195395447","rc":[{"atl":[[3.45,5.22],[3.4,8.33]],"id":43154430}],"con":true,"img":false}]}
{"op":"mcm","clk":"5346680185","pt":1646094018389,"mc":[{"id":"1.195395447","rc":[{"atl":[[3.55,19.61]],"id":43154430}],"con":true,"img":false}]}
{"op":"mcm","clk":"5346680235","pt":1646094019783,"mc":[{"id":"1.195395447","rc":[{"atl":[[3.45,13.38],[3.4,0]],"id":43154430}],"con":true,"img":false}]}
{"op":"mcm","clk":"5346680270","pt":1646094020861,"mc":[{"id":"1.195395447","rc":[{"atl":[[3.45,8.16]],"id":43154430}],"con":true,"img":false}]}
{"op":"mcm","clk":"5346680347","pt":1646094023482,"mc":[{"id":"1.195395447","rc":[{"atl":[[3.45,0],[3.4,8.33]],"id":43154430}],"con":true,"img":false}]}
{"op":"mcm","clk":"5346680357","pt":1646094023791,"mc":[{"id":"1.195395447","rc":[{"atl":[[6.8,9.25]],"id":42315317}],"con":true,"img":false}]}
{"op":"mcm","clk":"5346680371","pt":1646094024099,"mc":[{"id":"1.195395447","rc":[{"atl":[[6.8,6.55]],"id":42315317}],"con":true,"img":false}]}
{"op":"mcm","clk":"5346680476","pt":1646094026824,"mc":[{"id":"1.195395447","rc":[{"atl":[[6.8,9.2]],"id":42315317},{"atl":[[3.55,24.68]],"id":43154430}],"con":true,"img":false}]}
{"op":"mcm","clk":"5346680587","pt":1646094030211,"mc":[{"id":"1.195395447","rc":[{"atl":[[3.45,5.33]],"id":43154430}],"con":true,"img":false}]}
{"op":"mcm","clk":"5346680598","pt":1646094030417,"mc":[{"id":"1.195395447","rc":[{"atl":[[6.8,11.9]],"id":42315317}],"con":true,"img":false}]}
{"op":"mcm","clk":"5346680705","pt":1646094033496,"mc":[{"id":"1.195395447","rc":[{"atl":[[3.45,13.49],[3.4,0]],"id":43154430}],"con":true,"img":false}]}
{"op":"mcm","clk":"5346680761","pt":1646094035190,"mc":[{"id":"1.195395447","rc":[{"atl":[[3.45,5.33],[3.4,8.33]],"id":43154430}],"con":true,"img":false}]}
{"op":"mcm","clk":"5346680790","pt":1646094035910,"mc":[{"id":"1.195395447","rc":[{"atl":[[3.45,13.49],[3.4,0]],"id":43154430}],"con":true,"img":false}]}
{"op":"mcm","clk":"5346681186","pt":1646094046710,"mc":[{"id":"1.195395447","rc":[{"atl":[[3.45,5.33],[3.4,8.33]],"id":43154430}],"con":true,"img":false}]}
{"op":"mcm","clk":"5346681204","pt":1646094047326,"mc":[{"id":"1.195395447","rc":[{"atl":[[3.45,13.49]],"id":43154430}],"con":true,"img":false}]}
{"op":"mcm","clk":"5346681207","pt":1646094047429,"mc":[{"id":"1.195395447","rc":[{"atl":[[3.4,0]],"id":43154430}],"con":true,"img":false}]}
{"op":"mcm","clk":"5346681626","pt":1646094058538,"mc":[{"id":"1.195395447","rc":[{"atl":[[3.45,5.33],[3.4,8.33]],"id":43154430},{"spn":2.82,"spf":1.0,"id":43154430}],"con":true,"img":false}]}
{"op":"mcm","clk":"5346681687","pt":1646094059721,"mc":[{"id":"1.195395447","rc":[{"atl":[[3.45,13.49],[3.4,0]],"id":43154430}],"con":true,"img":false}]}
{"op":"mcm","clk":"5346682120","pt":1646094070869,"mc":[{"id":"1.195395447","rc":[{"atl":[[3.4,8.33]],"id":43154430}],"con":true,"img":false}]}
{"op":"mcm","clk":"5346682125","pt":1646094070972,"mc":[{"id":"1.195395447","rc":[{"atl":[[3.45,5.33]],"id":43154430}],"con":true,"img":false}]}
{"op":"mcm","clk":"5346682169","pt":1646094071844,"mc":[{"id":"1.195395447","rc":[{"atl":[[3.45,13.49],[3.4,0]],"id":43154430}],"con":true,"img":false}]}
{"op":"mcm","clk":"5346682624","pt":1646094082974,"mc":[{"id":"1.195395447","rc":[{"atl":[[3.4,8.33]],"id":43154430}],"con":true,"img":false}]}
{"op":"mcm","clk":"5346682627","pt":1646094083076,"mc":[{"id":"1.195395447","rc":[{"atl":[[3.45,5.33]],"id":43154430}],"con":true,"img":false}]}
{"op":"mcm","clk":"5346682635","pt":1646094083282,"mc":[{"id":"1.195395447","rc":[{"atl":[[3.4,0]],"id":43154430}],"con":true,"img":false}]}
{"op":"mcm","clk":"5346682935","pt":1646094089279,"mc":[{"id":"1.195395447","rc":[{"atb":[[3.45,0]],"id":37076580}],"con":true,"img":false}]}
{"op":"mcm","clk":"5346682940","pt":1646094089381,"mc":[{"id":"1.195395447","rc":[{"atb":[[3.05,52.46]],"id":37076580}],"con":true,"img":false}]}
{"op":"mcm","clk":"5346683090","pt":1646094092969,"mc":[{"id":"1.195395447","rc":[{"atl":[[3.45,13.49]],"id":43154430}],"con":true,"img":false}]}
{"op":"mcm","clk":"5346683174","pt":1646094095018,"mc":[{"id":"1.195395447","rc":[{"atl":[[3.4,8.33]],"id":43154430}],"con":true,"img":false}]}
{"op":"mcm","clk":"5346683178","pt":1646094095069,"mc":[{"id":"1.195395447","rc":[{"atl":[[3.45,5.33]],"id":43154430}],"con":true,"img":false}]}
{"op":"mcm","clk":"5346683205","pt":1646094095684,"mc":[{"id":"1.195395447","rc":[{"atl":[[3.45,13.49],[3.4,0]],"id":43154430}],"con":true,"img":false}]}
{"op":"mcm","clk":"5346683606","pt":1646094106408,"mc":[{"id":"1.195395447","rc":[{"atl":[[3.45,5.33],[3.4,8.33]],"id":43154430}],"con":true,"img":false}]}
{"op":"mcm","clk":"5346683696","pt":1646094108207,"mc":[{"id":"1.195395447","rc":[{"atl":[[3.45,13.49],[3.4,0]],"id":43154430}],"con":true,"img":false}]}
{"op":"mcm","clk":"5346684121","pt":1646094118732,"mc":[{"id":"1.195395447","rc":[{"atl":[[3.45,5.33],[3.4,8.33]],"id":43154430}],"con":true,"img":false}]}
{"op":"mcm","clk":"5346684191","pt":1646094120323,"mc":[{"id":"1.195395447","rc":[{"atl":[[3.45,13.49],[3.4,0]],"id":43154430}],"con":true,"img":false}]}
{"op":"mcm","clk":"5346684609","pt":1646094130536,"mc":[{"id":"1.195395447","rc":[{"atl":[[3.45,5.33],[3.4,8.33]],"id":43154430}],"con":true,"img":false}]}
{"op":"mcm","clk":"5346684690","pt":1646094132639,"mc":[{"id":"1.195395447","rc":[{"atl":[[3.45,13.49]],"id":43154430}],"con":true,"img":false}]}
{"op":"mcm","clk":"5346684695","pt":1646094132743,"mc":[{"id":"1.195395447","rc":[{"atl":[[3.4,0]],"id":43154430}],"con":true,"img":false}]}
{"op":"mcm","clk":"5346685066","pt":1646094142153,"mc":[{"id":"1.195395447","rc":[{"atl":[[3.45,5.33],[3.4,8.33]],"id":43154430}],"con":true,"img":false}]}
{"op":"mcm","clk":"5346685145","pt":1646094144049,"mc":[{"id":"1.195395447","rc":[{"atl":[[3.55,19.61]],"id":43154430}],"con":true,"img":false}]}
{"op":"mcm","clk":"5346685171","pt":1646094144670,"mc":[{"id":"1.195395447","rc":[{"atl":[[3.45,13.49],[3.4,0]],"id":43154430}],"con":true,"img":false}]}
{"op":"mcm","clk":"5346685274","pt":1646094147087,"mc":[{"id":"1.195395447","rc":[{"atl":[[6.8,9.25]],"id":42315317}],"con":true,"img":false}]}
{"op":"mcm","clk":"5346685364","pt":1646094149292,"mc":[{"id":"1.195395447","rc":[{"atb":[[3.05,0]],"id":37076580}],"con":true,"img":false}]}
{"op":"mcm","clk":"5346685369","pt":1646094149395,"mc":[{"id":"1.195395447","rc":[{"atb":[[3.45,52.46]],"id":37076580}],"con":true,"img":false}]}
{"op":"mcm","clk":"5346685398","pt":1646094150062,"mc":[{"id":"1.195395447","rc":[{"atl":[[6.8,11.9]],"id":42315317},{"atl":[[3.55,24.68]],"id":43154430}],"con":true,"img":false}]}
{"op":"mcm","clk":"5346685407","pt":1646094150267,"mc":[{"id":"1.195395447","rc":[{"atl":[[3.45,8.16]],"id":43154430}],"con":true,"img":false}]}
{"op":"mcm","clk":"5346685681","pt":1646094156392,"mc":[{"id":"1.195395447","rc":[{"atl":[[6.8,9.2]],"id":42315317}],"con":true,"img":false}]}
{"op":"mcm","clk":"5346685905","pt":1646094162516,"mc":[{"id":"1.195395447","rc":[{"atl":[[3.45,13.49]],"id":43154430}],"con":true,"img":false}]}
{"op":"mcm","clk":"5346685908","pt":1646094162619,"mc":[{"id":"1.195395447","rc":[{"atl":[[6.8,11.9]],"id":42315317}],"con":true,"img":false}]}
{"op":"mcm","clk":"5346689619","pt":1646094267252,"mc":[{"id":"1.195395447","rc":[{"atl":[[3.55,19.61]],"id":43154430},{"spn":2.84,"spf":1.0,"id":43154430}],"con":true,"img":false}]}
{"op":"mcm","clk":"5346689711","pt":1646094270281,"mc":[{"id":"1.195395447","rc":[{"atl":[[6.8,9.25]],"id":42315317}],"con":true,"img":false}]}
{"op":"mcm","clk":"5346689781","pt":1646094273198,"mc":[{"id":"1.195395447","rc":[{"atl":[[6.8,11.9]],"id":42315317},{"atl":[[3.55,24.68]],"id":43154430}],"con":true,"img":false}]}
{"op":"mcm","clk":"5346690039","pt":1646094282494,"mc":[{"id":"1.195395447","rc":[{"atl":[[3.45,8.16]],"id":43154430}],"con":true,"img":false}]}
{"op":"mcm","clk":"5346690073","pt":1646094284029,"mc":[{"id":"1.195395447","rc":[{"atl":[[320,2],[330,1]],"id":40014837}],"con":true,"img":false}]}
{"op":"mcm","clk":"5346690076","pt":1646094284081,"mc":[{"id":"1.195395447","rc":[{"atl":[[3.45,0],[3.4,8.33]],"id":43154430}],"con":true,"img":false}]}
{"op":"mcm","clk":"5346690167","pt":1646094288384,"mc":[{"id":"1.195395447","rc":[{"atl":[[6.8,9.2]],"id":42315317}],"con":true,"img":false}]}
{"op":"mcm","clk":"5346690208","pt":1646094289822,"mc":[{"id":"1.195395447","rc":[{"atl":[[3.45,8.16],[3.4,0]],"id":43154430}],"con":true,"img":false}]}
{"op":"mcm","clk":"5346690323","pt":1646094294025,"mc":[{"id":"1.195395447","rc":[{"atl":[[350,1]],"id":40014837}],"con":true,"img":false}]}
{"op":"mcm","clk":"5346690347","pt":1646094294741,"mc":[{"id":"1.195395447","rc":[{"atl":[[3.45,13.49]],"id":43154430}],"con":true,"img":false}]}
{"op":"mcm","clk":"5346690348","pt":1646094294792,"mc":[{"id":"1.195395447","rc":[{"atl":[[6.8,11.9]],"id":42315317}],"con":true,"img":false}]}
{"op":"mcm","clk":"5346690375","pt":1646094295715,"mc":[{"id":"1.195395447","rc":[{"atl":[[340,0],[360,0],[380,0]],"id":40014837},{"atl":[[3.45,5.33],[3.4,8.33]],"id":43154430}],"con":true,"img":false}]}
{"op":"mcm","clk":"5346690614","pt":1646094303258,"mc":[{"id":"1.195395447","rc":[{"atl":[[3.45,13.49]],"id":43154430}],"con":true,"img":false}]}
{"op":"mcm","clk":"5346690618","pt":1646094303362,"mc":[{"id":"1.195395447","rc":[{"atl":[[3.4,0]],"id":43154430}],"con":true,"img":false}]}
{"op":"mcm","clk":"5346690644","pt":1646094304031,"mc":[{"id":"1.195395447","rc":[{"atl":[[370,1]],"id":40014837}],"con":true,"img":false}]}
{"op":"mcm","clk":"5346690746","pt":1646094307053,"mc":[{"id":"1.195395447","rc":[{"atl":[[3.45,5.33],[3.4,8.33]],"id":43154430}],"con":true,"img":false}]}
{"op":"mcm","clk":"5346691039","pt":1646094314053,"mc":[{"id":"1.195395447","rc":[{"atl":[[390,1]],"id":40014837}],"con":true,"img":false}]}
{"op":"mcm","clk":"5346691093","pt":1646094315537,"mc":[{"id":"1.195395447","rc":[{"atl":[[3.45,13.49]],"id":43154430}],"con":true,"img":false}]}
{"op":"mcm","clk":"5346691099","pt":1646094315638,"mc":[{"id":"1.195395447","rc":[{"atl":[[3.4,0]],"id":43154430}],"con":true,"img":false}]}
{"op":"mcm","clk":"5346691230","pt":1646094318880,"mc":[{"id":"1.195395447","rc":[{"atl":[[3.45,5.33],[3.4,8.33]],"id":43154430}],"con":true,"img":false}]}
{"op":"mcm","clk":"5346691247","pt":1646094319285,"mc":[{"id":"1.195395447","rc":[{"atl":[[4.9,0]],"id":43154430}],"con":true,"img":false}]}
{"op":"mcm","clk":"5346691252","pt":1646094319339,"mc":[{"id":"1.195395447","rc":[{"atl":[[4.1,10.3]],"id":43154430}],"con":true,"img":false}]}
{"op":"mcm","clk":"5346691571","pt":1646094327289,"mc":[{"id":"1.195395447","rc":[{"atl":[[3.45,13.49],[3.4,0]],"id":43154430}],"con":true,"img":false}]}
{"op":"mcm","clk":"5346691650","pt":1646094329285,"mc":[{"id":"1.195395447","rc":[{"atl":[[4.1,0]],"id":43154430}],"con":true,"img":false}]}
{"op":"mcm","clk":"5346691654","pt":1646094329387,"mc":[{"id":"1.195395447","rc":[{"atl":[[4.9,10.3]],"id":43154430}],"con":true,"img":false}]}
{"op":"mcm","clk":"5346691716","pt":1646094330874,"mc":[{"id":"1.195395447","rc":[{"atl":[[3.45,5.33],[3.4,8.33]],"id":43154430}],"con":true,"img":false}]}
{"op":"mcm","clk":"5346692075","pt":1646094340177,"mc":[{"id":"1.195395447","rc":[{"atl":[[3.45,13.49]],"id":43154430}],"con":true,"img":false}]}
{"op":"mcm","clk":"5346692077","pt":1646094340279,"mc":[{"id":"1.195395447","rc":[{"atl":[[3.4,0]],"id":43154430}],"con":true,"img":false}]}
{"op":"mcm","clk":"5346692144","pt":1646094342384,"mc":[{"id":"1.195395447","rc":[{"atl":[[3.4,8.33]],"id":43154430}],"con":true,"img":false}]}
{"op":"mcm","clk":"5346692149","pt":1646094342490,"mc":[{"id":"1.195395447","rc":[{"atl":[[3.45,5.33]],"id":43154430}],"con":true,"img":false}]}
{"op":"mcm","clk":"5346692535","pt":1646094352445,"mc":[{"id":"1.195395447","rc":[{"atl":[[3.45,13.49],[3.4,0]],"id":43154430}],"con":true,"img":false}]}
{"op":"mcm","clk":"5346692606","pt":1646094353939,"mc":[{"id":"1.195395447","rc":[{"atl":[[320,0],[330,0],[210,2.63],[220,3.7]],"id":40014837},{"atb":[[8,0],[6.8,17.24]],"id":37535509},{"atl":[[5.9,4.08],[6.2,0]],"id":42315317},{"atb":[[2.22,43.33],[2.18,0]],"id":43154430},{"atl":[[3.45,5.33],[4.2,0],[3.65,7.55]],"id":43154430},{"atl":[[36,0],[42,2.44]],"id":40041375},{"atb":[[4.3,26.58],[4.2,20.91]],"id":37076580}],"con":true,"img":false}]}
{"op":"mcm","clk":"5346692613","pt":1646094354038,"mc":[{"id":"1.195395447","rc":[{"atl":[[9.4,0],[8.8,29.76]],"id":42315317},{"atl":[[4.7,27.03]],"id":43154430}],"con":true,"img":false}]}
{"op":"mcm","clk":"5346692638","pt":1646094354446,"mc":[{"id":"1.195395447","rc":[{"atl":[[3.55,5.07]],"id":43154430},{"atb":[[4.3,32.64],[4.2,14.66]],"id":37076580}],"con":true,"img":false}]}
{"op":"mcm","clk":"5346692646","pt":1646094354650,"mc":[{"id":"1.195395447","rc":[{"atl":[[3.6,4.05]],"id":43154430}],"con":true,"img":false}]}
{"op":"mcm","clk":"5346692770","pt":1646094357839,"mc":[{"id":"1.195395447","rc":[{"atb":[[4.3,26.58],[4.2,20.91]],"id":37076580}],"con":true,"img":false}]}
{"op":"mcm","clk":"5346692833","pt":1646094359227,"mc":[{"id":"1.195395447","rc":[{"atl":[[9.2,0]],"id":42315317},{"atl":[[4.9,0]],"id":43154430}],"con":true,"img":false}]}
{"op":"mcm","clk":"5346692840","pt":1646094359330,"mc":[{"id":"1.195395447","rc":[{"atl":[[9.6,13.08]],"id":42315317},{"atl":[[4.6,10.3]],"id":43154430}],"con":true,"img":false}]}
{"op":"mcm","clk":"5346692894","pt":1646094360353,"mc":[{"id":"1.195395447","rc":[{"atb":[[2.24,0]],"id":43154430}],"con":true,"img":false}]}
{"op":"mcm","clk":"5346693055","pt":1646094363947,"mc":[{"id":"1.195395447","rc":[{"atl":[[240,1]],"id":40014837},{"atl":[[6.2,9.62]],"id":42315317},{"atl":[[3.75,18.18]],"id":43154430}],"con":true,"img":false}]}
{"op":"mcm","clk":"5346693119","pt":1646094365642,"mc":[{"id":"1.195395447","rc":[{"atb":[[9,12.5],[12,11.36],[13,1.67],[15,0]],"id":40014837},{"atl":[[350,0],[370,0],[390,0]],"id":40014837},{"atb":[[7.8,2.94],[7,0]],"id":38541023},{"atb":[[10,10.22],[11,0],[12,10.05]],"id":37535509},{"atb":[[13,0],[14,10.9]],"id":36899944},{"atl":[[7.4,0]],"id":42315317},{"atb":[[4.8,0],[5.7,4.26]],"id":40041375}],"con":true,"img":false}]}
{"op":"mcm","clk":"5346693131","pt":1646094366052,"mc":[{"id":"1.195395447","rc":[{"atb":[[14,0]],"id":40014837},{"atb":[[4.3,32.64]],"id":37076580}],"con":true,"img":false}]}
{"op":"mcm","clk":"5346693134","pt":1646094366154,"mc":[{"id":"1.195395447","rc":[{"atb":[[4.2,14.66]],"id":37076580}],"con":true,"img":false}]}
{"op":"mcm","clk":"5346693154","pt":1646094366673,"mc":[{"id":"1.195395447","rc":[{"atb":[[2.22,35.8]],"id":43154430}],"con":true,"img":false}]}
{"op":"mcm","clk":"5346693250","pt":1646094369338,"mc":[{"id":"1.195395447","rc":[{"atb":[[2.26,7.15]],"id":43154430}],"con":true,"img":false}]}
{"op":"mcm","clk":"5346693350","pt":1646094372778,"mc":[{"id":"1.195395447","rc":[{"atb":[[2.26,14.45]],"id":43154430}],"con":true,"img":false}]}
{"op":"mcm","clk":"5346693382","pt":1646094373965,"mc":[{"id":"1.195395447","rc":[{"atl":[[6.6,13.39]],"id":42315317},{"atl":[[3.85,26.32]],"id":43154430}],"con":true,"img":false}]}
{"op":"mcm","clk":"5346693430","pt":1646094375659,"mc":[{"id":"1.195395447","rc":[{"atb":[[12,4.55]],"id":40014837},{"atl":[[260,1.76]],"id":40014837},{"atb":[[7.4,7.81]],"id":38541023},{"atb":[[9.6,5.81]],"id":37535509},{"atb":[[13,4.17]],"id":36899944},{"atb":[[5.5,11.11]],"id":40041375}],"con":true,"img":false}]}
{"op":"mcm","clk":"5346693440","pt":1646094376072,"mc":[{"id":"1.195395447","rc":[{"atb":[[4.3,26.58],[4.2,20.91]],"id":37076580}],"con":true,"img":false}]}
{"op":"mcm","clk":"5346693512","pt":1646094378585,"mc":[{"id":"1.195395447","rc":[{"atb":[[5.9,0]],"id":38541023},{"atb":[[10,0]],"id":36899944},{"atb":[[4.4,0],[4.6,0],[4.2,26.56]],"id":40041375},{"atb":[[4.3,32.64],[4.2,14.66]],"id":37076580}],"con":true,"img":false}]}
{"op":"mcm","clk":"5346693664","pt":1646094383986,"mc":[{"id":"1.195395447","rc":[{"atl":[[7,20.83]],"id":42315317},{"atl":[[3.95,42.37]],"id":43154430}],"con":true,"img":false}]}
{"op":"mcm","clk":"5346693734","pt":1646094385682,"mc":[{"id":"1.195395447","rc":[{"atb":[[11,7.5]],"id":40014837},{"atl":[[280,1]],"id":40014837},{"atb":[[7,12.5]],"id":38541023},{"atb":[[9.2,9.15]],"id":37535509},{"atb":[[12,6.82]],"id":36899944},{"atb":[[5.3,17.44]],"id":40041375}],"con":true,"img":false}]}
{"op":"mcm","clk":"5346693825","pt":1646094388308,"mc":[{"id":"1.195395447","rc":[{"atb":[[21,3.77]],"id":40014837},{"atb":[[19.5,4.76]],"id":37535509},{"atb":[[15,6.6]],"id":36899944},{"atb":[[3.1,15.21]],"id":42315317},{"spn":4.5,"spf":1.0,"id":42315317},{"atb":[[2.28,10.83]],"id":43154430},{"spn":2.86,"spf":1.0,"id":43154430},{"atb":[[10,7.37]],"id":40041375}],"con":true,"img":false}]}
{"op":"mcm","clk":"5346693836","pt":1646094388511,"mc":[{"id":"1.195395447","rc":[{"atb":[[3.1,35.49],[3.05,0]],"id":42315317}],"con":true,"img":false}]}
{"op":"mcm","clk":"5346693840","pt":1646094388561,"mc":[{"id":"1.195395447","rc":[{"atb":[[4.2,20.91]],"id":37076580}],"con":true,"img":false}]}
{"op":"mcm","clk":"5346693842","pt":1646094388667,"mc":[{"id":"1.195395447","rc":[{"atb":[[4.3,26.58]],"id":37076580}],"con":true,"img":false}]}
{"op":"mcm","clk":"5346693855","pt":1646094389179,"mc":[{"id":"1.195395447","rc":[{"atl":[[220,1]],"id":40014837}],"con":true,"img":false}]}
{"op":"mcm","clk":"5346693858","pt":1646094389282,"mc":[{"id":"1.195395447","rc":[{"atl":[[200,2.7]],"id":40014837}],"con":true,"img":false}]}
{"op":"mcm","clk":"5346693862","pt":1646094389387,"mc":[{"id":"1.195395447","rc":[{"atl":[[190,2],[210,0.63]],"id":40014837}],"con":true,"img":false}]}
{"op":"mcm","clk":"5346693876","pt":1646094389693,"mc":[{"id":"1.195395447","rc":[{"atb":[[6.2,24.33]],"id":38541023},{"atb":[[4.3,32.64],[4.2,14.66]],"id":37076580}],"con":true,"img":false}]}
{"op":"mcm","clk":"5346693903","pt":1646094390411,"mc":[{"id":"1.195395447","rc":[{"atl":[[3.55,0]],"id":43154430}],"con":true,"img":false}]}
{"op":"mcm","clk":"5346693909","pt":1646094390673,"mc":[{"id":"1.195395447","rc":[{"atb":[[4.2,20.91]],"id":37076580}],"con":true,"img":false}]}
{"op":"mcm","clk":"5346693913","pt":1646094390777,"mc":[{"id":"1.195395447","rc":[{"atb":[[4.3,26.58]],"id":37076580}],"con":true,"img":false}]}
{"op":"mcm","clk":"5346694029","pt":1646094393397,"mc":[{"id":"1.195395447","rc":[{"atl":[[6.8,9.25]],"id":42315317}],"con":true,"img":false}]}
{"op":"mcm","clk":"5346694130","pt":1646094395711,"mc":[{"id":"1.195395447","rc":[{"atb":[[10,13.89]],"id":40014837},{"atb":[[6.6,22.32]],"id":38541023},{"atb":[[8.8,16.03]],"id":37535509},{"atb":[[11,12.5]],"id":36899944},{"atb":[[5.1,30.49]],"id":40041375}],"con":true,"img":false}]}
{"op":"mcm","clk":"5346694168","pt":1646094396788,"mc":[{"id":"1.195395447","rc":[{"atb":[[2.96,0]],"id":42315317},{"atl":[[6.4,2.81]],"id":42315317},{"atl":[[3.75,22.98]],"id":43154430}],"con":true,"img":false}]}
{"op":"mcm","clk":"5346694270","pt":1646094399103,"mc":[{"id":"1.195395447","rc":[{"atb":[[3.1,20.28]],"id":42315317}],"con":true,"img":false}]}
{"op":"mcm","clk":"5346694275","pt":1646094399205,"mc":[{"id":"1.195395447","rc":[{"atb":[[3.1,0],[3.05,40.56]],"id":42315317}],"con":true,"img":false}]}
{"op":"mcm","clk":"5346694333","pt":1646094400697,"mc":[{"id":"1.195395447","rc":[{"atb":[[4,16.67]],"id":37076580}],"con":true,"img":false}]}
{"op":"mcm","clk":"5346694339","pt":1646094400903,"mc":[{"id":"1.195395447","rc":[{"atb":[[4.3,32.64],[4.2,14.66]],"id":37076580}],"con":true,"img":false}]}
{"op":"mcm","clk":"5346694343","pt":1646094401006,"mc":[{"id":"1.195395447","rc":[{"atl":[[5.8,4.17],[5.9,0]],"id":42315317}],"con":true,"img":false}]}
{"op":"mcm","clk":"5346694384","pt":1646094402081,"mc":[{"id":"1.195395447","rc":[{"atb":[[4,0]],"id":37076580}],"con":true,"img":false}]}
{"op":"mcm","clk":"5346694410","pt":1646094402897,"mc":[{"id":"1.195395447","rc":[{"atb":[[3.1,30.41],[2.94,0]],"id":42315317}],"con":true,"img":false}]}
{"op":"mcm","clk":"5346694646","pt":1646094409310,"mc":[{"id":"1.195395447","rc":[{"atb":[[8.2,0]],"id":38541023}],"con":true,"img":false}]}
{"op":"mcm","clk":"5346694649","pt":1646094409413,"mc":[{"id":"1.195395447","rc":[{"atb":[[9.2,5.27]],"id":38541023}],"con":true,"img":false}]}
{"op":"mcm","clk":"5346694797","pt":1646094413717,"mc":[{"id":"1.195395447","rc":[{"atb":[[3.1,60.83],[3.05,0]],"id":42315317},{"atl":[[3.6,11.74],[3.65,0]],"id":43154430}],"con":true,"img":false}]}
{"op":"mcm","clk":"5346694799","pt":1646094413817,"mc":[{"id":"1.195395447","rc":[{"atb":[[3.05,48.78]],"id":42315317}],"con":true,"img":false}]}
{"op":"mcm","clk":"5346694802","pt":1646094413921,"mc":[{"id":"1.195395447","rc":[{"atb":[[3.1,30.41]],"id":42315317}],"con":true,"img":false}]}
{"op":"mcm","clk":"5346694832","pt":1646094414845,"mc":[{"id":"1.195395447","rc":[{"atl":[[3.45,0]],"id":43154430}],"con":true,"img":false}]}
{"op":"mcm","clk":"5346694954","pt":1646094417719,"mc":[{"id":"1.195395447","rc":[{"atb":[[6.2,0]],"id":38541023},{"atl":[[9.6,0]],"id":42315317},{"atb":[[9,0]],"id":40041375}],"con":true,"img":false}]}
{"op":"mcm","clk":"5346694960","pt":1646094417821,"mc":[{"id":"1.195395447","rc":[{"atb":[[7.2,24.33]],"id":38541023},{"atl":[[8.6,13.08]],"id":42315317},{"atb":[[10,12.18]],"id":40041375}],"con":true,"img":false}]}
{"op":"mcm","clk":"5346695067","pt":1646094420440,"mc":[{"id":"1.195395447","rc":[{"atb":[[3.15,4.19]],"id":42315317}],"con":true,"img":false}]}
{"op":"mcm","clk":"5346695078","pt":1646094420747,"mc":[{"id":"1.195395447","rc":[{"atb":[[3.15,8.47]],"id":42315317}],"con":true,"img":false}]}
{"op":"mcm","clk":"5346695090","pt":1646094420953,"mc":[{"id":"1.195395447","rc":[{"atl":[[6.8,6.55]],"id":42315317}],"con":true,"img":false}]}
{"op":"mcm","clk":"5346695199","pt":1646094423219,"mc":[{"id":"1.195395447","rc":[{"atb":[[3.1,0]],"id":42315317}],"con":true,"img":false}]}
{"op":"mcm","clk":"5346695228","pt":1646094423732,"mc":[{"id":"1.195395447","rc":[{"atl":[[3.6,4.05],[3.65,7.55]],"id":43154430}],"con":true,"img":false}]}
{"op":"mcm","clk":"5346695290","pt":1646094425023,"mc":[{"id":"1.195395447","rc":[{"atb":[[14.5,0]],"id":36899944}],"con":true,"img":false}]}
{"op":"mcm","clk":"5346695297","pt":1646094425123,"mc":[{"id":"1.195395447","rc":[{"atb":[[15.5,9.19]],"id":36899944}],"con":true,"img":false}]}
{"op":"mcm","clk":"5346695358","pt":1646094426917,"mc":[{"id":"1.195395447","rc":[{"atb":[[3.2,6.35]],"id":42315317}],"con":true,"img":false}]}
{"op":"mcm","clk":"5346695362","pt":1646094427020,"mc":[{"id":"1.195395447","rc":[{"atb":[[3.1,24.54],[3.05,0]],"id":42315317},{"atl":[[3.6,11.74],[3.65,5.03]],"id":43154430}],"con":true,"img":false}]}
{"op":"mcm","clk":"5346695365","pt":1646094427122,"mc":[{"id":"1.195395447","rc":[{"atb":[[3.1,0],[3.05,24.54]],"id":42315317},{"atl":[[6.4,5.68]],"id":42315317}],"con":true,"img":false}]}
{"op":"mcm","clk":"5346695443","pt":1646094428766,"mc":[{"id":"1.195395447","rc":[{"atb":[[15,0]],"id":36899944}],"con":true,"img":false}]}
{"op":"mcm","clk":"5346695461","pt":1646094429229,"mc":[{"id":"1.195395447","rc":[{"atl":[[200,0]],"id":40014837},{"atb":[[15.5,0]],"id":36899944}],"con":true,"img":false}]}
{"op":"mcm","clk":"5346695465","pt":1646094429330,"mc":[{"id":"1.195395447","rc":[{"atl":[[180,2.7]],"id":40014837},{"atb":[[14.5,9.19]],"id":36899944}],"con":true,"img":false}]}
{"op":"mcm","clk":"5346695466","pt":1646094429433,"mc":[{"id":"1.195395447","rc":[{"atl":[[170,2],[190,0]],"id":40014837}],"con":true,"img":false}]}
{"op":"mcm","clk":"5346695604","pt":1646094432461,"mc":[{"id":"1.195395447","rc":[{"atb":[[3.15,4.27]],"id":42315317}],"con":true,"img":false}]}
{"op":"mcm","clk":"5346695616","pt":1646094432667,"mc":[{"id":"1.195395447","rc":[{"atb":[[21,0]],"id":40014837},{"atb":[[15,6.6]],"id":36899944}],"con":true,"img":false}]}
{"op":"mcm","clk":"5346695792","pt":1646094436463,"mc":[{"id":"1.195395447","rc":[{"atb":[[21,3.77]],"id":40014837}],"con":true,"img":false}]}
{"op":"mcm","clk":"5346695817","pt":1646094437079,"mc":[{"id":"1.195395447","rc":[{"atl":[[3.6,4.05],[3.65,12.58]],"id":43154430}],"con":true,"img":false}]}
{"op":"mcm","clk":"5346695877","pt":1646094438772,"mc":[{"id":"1.195395447","rc":[{"atb":[[3.15,0]],"id":42315317}],"con":true,"img":false}]}
{"op":"mcm","clk":"5346695930","pt":1646094439747,"mc":[{"id":"1.195395447","rc":[{"atb":[[3.05,0]],"id":42315317},{"atl":[[3.6,11.74]],"id":43154430}],"con":true,"img":false}]}
{"op":"mcm","clk":"5346695935","pt":1646094439849,"mc":[{"id":"1.195395447","rc":[{"atb":[[3.1,24.54]],"id":42315317},{"atl":[[3.65,5.03]],"id":43154430}],"con":true,"img":false}]}
{"op":"mcm","clk":"5346696033","pt":1646094442074,"mc":[{"id":"1.195395447","rc":[{"atb":[[3.2,0]],"id":42315317}],"con":true,"img":false}]}
{"op":"mcm","clk":"5346696142","pt":1646094444993,"mc":[{"id":"1.195395447","rc":[{"atb":[[3.05,48.78]],"id":42315317}],"con":true,"img":false}]}
{"op":"mcm","clk":"5346696146","pt":1646094445096,"mc":[{"id":"1.195395447","rc":[{"atb":[[3.1,0],[2.94,4.72]],"id":42315317}],"con":true,"img":false}]}
{"op":"mcm","clk":"5346696177","pt":1646094445871,"mc":[{"id":"1.195395447","rc":[{"atb":[[3.15,18.4]],"id":42315317}],"con":true,"img":false}]}
{"op":"mcm","clk":"5346696321","pt":1646094449777,"mc":[{"id":"1.195395447","rc":[{"spn":4.47,"spf":1.0,"id":42315317},{"atl":[[3.65,12.58]],"id":43154430},{"spn":2.94,"spf":1.0,"id":43154430}],"con":true,"img":false}]}
{"op":"mcm","clk":"5346696325","pt":1646094449879,"mc":[{"id":"1.195395447","rc":[{"atl":[[3.6,4.05]],"id":43154430}],"con":true,"img":false}]}
{"op":"mcm","clk":"5346696818","pt":1646094463222,"mc":[{"id":"1.195395447","rc":[{"atb":[[2.94,0]],"id":42315317}],"con":true,"img":false}]}
{"op":"mcm","clk":"5346696850","pt":1646094464097,"mc":[{"id":"1.195395447","rc":[{"atb":[[3.1,36.8],[3.05,0]],"id":42315317},{"atl":[[3.6,11.74],[3.65,5.03]],"id":43154430}],"con":true,"img":false}]}
{"op":"mcm","clk":"5346696853","pt":1646094464199,"mc":[{"id":"1.195395447","rc":[{"atb":[[3.1,0],[3.05,48.78]],"id":42315317}],"con":true,"img":false}]}
{"op":"mcm","clk":"5346696901","pt":1646094465534,"mc":[{"id":"1.195395447","rc":[{"atb":[[3.1,4.29]],"id":42315317}],"con":true,"img":false}]}
{"op":"mcm","clk":"5346697023","pt":1646094469023,"mc":[{"id":"1.195395447","rc":[{"atb":[[3.1,8.66]],"id":42315317}],"con":true,"img":false}]}
{"op":"mcm","clk":"5346697030","pt":1646094469226,"mc":[{"id":"1.195395447","rc":[{"atl":[[110,0]],"id":36899944}],"con":true,"img":false}]}
{"op":"mcm","clk":"5346697032","pt":1646094469330,"mc":[{"id":"1.195395447","rc":[{"atl":[[100,0.48]],"id":36899944}],"con":true,"img":false}]}
{"op":"mcm","clk":"5346697199","pt":1646094474108,"mc":[{"id":"1.195395447","rc":[{"atl":[[3.65,12.58]],"id":43154430}],"con":true,"img":false}]}
{"op":"mcm","clk":"5346697203","pt":1646094474211,"mc":[{"id":"1.195395447","rc":[{"atl":[[3.6,4.05]],"id":43154430}],"con":true,"img":false}]}
{"op":"mcm","clk":"5346697272","pt":1646094476421,"mc":[{"id":"1.195395447","rc":[{"atl":[[3.6,11.74],[3.65,5.03]],"id":43154430}],"con":true,"img":false}]}
{"op":"mcm","clk":"5346697309","pt":1646094477752,"mc":[{"id":"1.195395447","rc":[{"atb":[[3.2,2.94]],"id":42315317}],"con":true,"img":false}]}
{"op":"mcm","clk":"5346697349","pt":1646094479242,"mc":[{"id":"1.195395447","rc":[{"atl":[[180,0]],"id":40014837},{"atl":[[34,0]],"id":38541023},{"atb":[[14.5,0]],"id":36899944}],"con":true,"img":false}]}
{"op":"mcm","clk":"5346697356","pt":1646094479346,"mc":[{"id":"1.195395447","rc":[{"atl":[[160,3.53]],"id":40014837},{"atl":[[26,2.7]],"id":38541023},{"atb":[[15.5,9.19]],"id":36899944}],"con":true,"img":false}]}
{"op":"mcm","clk":"5346697370","pt":1646094479560,"mc":[{"id":"1.195395447","rc":[{"atl":[[160,5.53],[170,0]],"id":40014837}],"con":true,"img":false}]}
{"op":"mcm","clk":"5346697484","pt":1646094482754,"mc":[{"id":"1.195395447","rc":[{"atb":[[21,0]],"id":40014837},{"atb":[[15,0]],"id":36899944}],"con":true,"img":false}]}
{"op":"mcm","clk":"5346697619","pt":1646094486458,"mc":[{"id":"1.195395447","rc":[{"atl":[[3.6,4.05],[3.65,12.58]],"id":43154430}],"con":true,"img":false}]}
{"op":"mcm","clk":"5346697627","pt":1646094486665,"mc":[{"id":"1.195395447","rc":[{"atb":[[21,3.77]],"id":40014837},{"atb":[[17,5.78]],"id":36899944}],"con":true,"img":false}]}
{"op":"mcm","clk":"5346697704","pt":1646094488058,"mc":[{"id":"1.195395447","rc":[{"atb":[[3.1,30],[3.05,0]],"id":42315317},{"atl":[[3.6,11.74],[3.65,5.03]],"id":43154430}],"con":true,"img":false}]}
{"op":"mcm","clk":"5346697714","pt":1646094488367,"mc":[{"id":"1.195395447","rc":[{"atl":[[3.6,4.05],[3.65,12.58]],"id":43154430}],"con":true,"img":false}]}
{"op":"mcm","clk":"5346697749","pt":1646094489238,"mc":[{"id":"1.195395447","rc":[{"atl":[[26,0]],"id":38541023},{"atb":[[15.5,0]],"id":36899944}],"con":true,"img":false}]}
{"op":"mcm","clk":"5346697754","pt":1646094489341,"mc":[{"id":"1.195395447","rc":[{"atl":[[34,2.7]],"id":38541023},{"atb":[[14.5,9.19]],"id":36899944}],"con":true,"img":false}]}
{"op":"mcm","clk":"5346697869","pt":1646094492167,"mc":[{"id":"1.195395447","rc":[{"atb":[[17,0]],"id":36899944}],"con":true,"img":false}]}
{"op":"mcm","clk":"5346697910","pt":1646094493245,"mc":[{"id":"1.195395447","rc":[{"atb":[[3.1,8.66],[3.05,36.8]],"id":42315317}],"con":true,"img":false}]}
{"op":"mcm","clk":"5346698017","pt":1646094495965,"mc":[{"id":"1.195395447","rc":[{"atb":[[15,6.6]],"id":36899944}],"con":true,"img":false}]}
{"op":"mcm","clk":"5346698154","pt":1646094499677,"mc":[{"id":"1.195395447","rc":[{"atl":[[3.6,11.74],[3.65,5.03]],"id":43154430}],"con":true,"img":false}]}
{"op":"mcm","clk":"5346698181","pt":1646094500393,"mc":[{"id":"1.195395447","rc":[{"atl":[[3.6,4.05],[3.65,12.58]],"id":43154430}],"con":true,"img":false}]}
{"op":"mcm","clk":"5346698572","pt":1646094511704,"mc":[{"id":"1.195395447","rc":[{"atb":[[3.1,30]],"id":42315317},{"spn":4.5,"spf":1.0,"id":42315317},{"atl":[[3.6,11.74]],"id":43154430}],"con":true,"img":false}]}
{"op":"mcm","clk":"5346698576","pt":1646094511807,"mc":[{"id":"1.195395447","rc":[{"atb":[[3.05,0]],"id":42315317},{"atl":[[3.65,5.03]],"id":43154430}],"con":true,"img":false}]}
{"op":"mcm","clk":"5346698618","pt":1646094513194,"mc":[{"id":"1.195395447","rc":[{"atl":[[3.65,12.58]],"id":43154430}],"con":true,"img":false}]}
{"op":"mcm","clk":"5346698619","pt":1646094513297,"mc":[{"id":"1.195395447","rc":[{"atl":[[3.6,4.05]],"id":43154430}],"con":true,"img":false}]}
{"op":"mcm","clk":"5346698629","pt":1646094513604,"mc":[{"id":"1.195395447","rc":[{"atb":[[3.1,25.71]],"id":42315317},{"atl":[[3.75,18.18]],"id":43154430}],"con":true,"img":false}]}
{"op":"mcm","clk":"5346698720","pt":1646094516583,"mc":[{"id":"1.195395447","rc":[{"atl":[[6.4,2.86]],"id":42315317}],"con":true,"img":false}]}
{"op":"mcm","clk":"5346698728","pt":1646094516789,"mc":[{"id":"1.195395447","rc":[{"atb":[[3.1,4.37],[3.05,36.8]],"id":42315317}],"con":true,"img":false}]}
{"op":"mcm","clk":"5346698731","pt":1646094516889,"mc":[{"id":"1.195395447","rc":[{"atb":[[3.1,0]],"id":42315317}],"con":true,"img":false}]}
{"op":"mcm","clk":"5346698803","pt":1646094519300,"mc":[{"id":"1.195395447","rc":[{"atl":[[160,2.83]],"id":40014837}],"con":true,"img":false}]}
{"op":"mcm","clk":"5346698808","pt":1646094519402,"mc":[{"id":"1.195395447","rc":[{"atl":[[150,2.7],[160,0.83],[210,2.63]],"id":40014837}],"con":true,"img":false}]}
{"op":"mcm","clk":"5346698810","pt":1646094519505,"mc":[{"id":"1.195395447","rc":[{"atl":[[160,2.83],[210,0.63]],"id":40014837}],"con":true,"img":false}]}
{"op":"mcm","clk":"5346698816","pt":1646094519711,"mc":[{"id":"1.195395447","rc":[{"atl":[[3.75,22.98]],"id":43154430}],"con":true,"img":false}]}
{"op":"mcm","clk":"5346698821","pt":1646094519813,"mc":[{"id":"1.195395447","rc":[{"atl":[[6.4,5.68]],"id":42315317}],"con":true,"img":false}]}
{"op":"mcm","clk":"5346698948","pt":1646094522024,"mc":[{"id":"1.195395447","rc":[{"atb":[[21,0]],"id":40014837}],"con":true,"img":false}]}
{"op":"mcm","clk":"5346699008","pt":1646094523538,"mc":[{"id":"1.195395447","rc":[{"atl":[[3.6,11.74],[3.65,5.03]],"id":43154430}],"con":true,"img":false}]}
{"op":"mcm","clk":"5346699053","pt":1646094525024,"mc":[{"id":"1.195395447","rc":[{"atl":[[3.6,4.05],[3.65,12.58]],"id":43154430}],"con":true,"img":false}]}
{"op":"mcm","clk":"5346699085","pt":1646094525797,"mc":[{"id":"1.195395447","rc":[{"atb":[[21,3.77]],"id":40014837}],"con":true,"img":false}]}
{"op":"mcm","clk":"5346699125","pt":1646094527332,"mc":[{"id":"1.195395447","rc":[{"atb":[[1.2,2.23]],"id":42315317}],"con":true,"img":false}]}
{"op":"mcm","clk":"5346699132","pt":1646094527536,"mc":[{"id":"1.195395447","rc":[{"atb":[[1.2,2.06]],"id":42315317}],"con":true,"img":false}]}
{"op":"mcm","clk":"5346699137","pt":1646094527846,"mc":[{"id":"1.195395447","rc":[{"atb":[[1.2,0]],"id":42315317}],"con":true,"img":false}]}
{"op":"mcm","clk":"5346699140","pt":1646094527948,"mc":[{"id":"1.195395447","rc":[{"atb":[[3.25,2.06]],"id":42315317}],"con":true,"img":false}]}
{"op":"mcm","clk":"5346699151","pt":1646094528207,"mc":[{"id":"1.195395447","rc":[{"atb":[[2.3,7.59]],"id":43154430}],"con":true,"img":false}]}
{"op":"mcm","clk":"5346699190","pt":1646094529028,"mc":[{"id":"1.195395447","rc":[{"atb":[[3.2,0]],"id":42315317}],"con":true,"img":false}]}
{"op":"mcm","clk":"5346699286","pt":1646094531342,"mc":[{"id":"1.195395447","rc":[{"atb":[[2.28,0]],"id":43154430}],"con":true,"img":false}]}
{"op":"mcm","clk":"5346699316","pt":1646094532011,"mc":[{"id":"1.195395447","rc":[{"atb":[[3.25,0]],"id":42315317}],"con":true,"img":false}]}
{"op":"mcm","clk":"5346699389","pt":1646094534213,"mc":[{"id":"1.195395447","rc":[{"atb":[[2.3,0]],"id":43154430}],"con":true,"img":false}]}
{"op":"mcm","clk":"5346699411","pt":1646094534932,"mc":[{"id":"1.195395447","rc":[{"atb":[[3.1,4.37],[3.2,2.93]],"id":42315317}],"con":true,"img":false}]}
{"op":"mcm","clk":"5346699416","pt":1646094535138,"mc":[{"id":"1.195395447","rc":[{"atb":[[2.32,5.69]],"id":43154430}],"con":true,"img":false}]}
{"op":"mcm","clk":"5346699437","pt":1646094535756,"mc":[{"id":"1.195395447","rc":[{"atb":[[3.1,25.7],[3.05,0]],"id":42315317},{"atl":[[3.6,11.74],[3.65,5.03]],"id":43154430}],"con":true,"img":false}]}
{"op":"mcm","clk":"5346699485","pt":1646094536730,"mc":[{"id":"1.195395447","rc":[{"atl":[[3.6,4.05],[3.65,12.58]],"id":43154430}],"con":true,"img":false}]}
{"op":"mcm","clk":"5346699492","pt":1646094536936,"mc":[{"id":"1.195395447","rc":[{"atb":[[3.2,13.2]],"id":42315317}],"con":true,"img":false}]}
{"op":"mcm","clk":"5346699588","pt":1646094539224,"mc":[{"id":"1.195395447","rc":[{"atl":[[150,0]],"id":40014837},{"atb":[[6.8,15.43],[7.2,0]],"id":38541023},{"atl":[[34,0]],"id":38541023},{"atl":[[150,2]],"id":37535509},{"atl":[[130,2]],"id":36899944},{"atl":[[9.6,24.5],[8.6,0]],"id":42315317},{"atb":[[1.58,81.99]],"id":43154430},{"atl":[[5.2,0],[5.7,38.96]],"id":43154430},{"atb":[[3.05,34.62],[3.45,0]],"id":37076580}],"con":true,"img":false}]}
{"op":"mcm","clk":"5346699593","pt":1646094539324,"mc":[{"id":"1.195395447","rc":[{"atl":[[160,0.83],[210,5.33]],"id":40014837},{"atl":[[26,2.7]],"id":38541023},{"atl":[[150,0],[160,2.83],[210,3.33]],"id":37535509},{"atl":[[130,0],[140,2.95],[180,2.7]],"id":36899944}],"con":true,"img":false}]}
{"op":"mcm","clk":"5346699599","pt":1646094539531,"mc":[{"id":"1.195395447","rc":[{"atb":[[2.28,5.69]],"id":43154430}],"con":true,"img":false}]}
{"op":"mcm","clk":"5346699627","pt":1646094540661,"mc":[{"id":"1.195395447","rc":[{"atb":[[3.15,0]],"id":42315317}],"con":true,"img":false}]}
{"op":"mcm","clk":"5346699636","pt":1646094540870,"mc":[{"id":"1.195395447","rc":[{"atb":[[3.1,4.37],[3.05,38.91]],"id":42315317}],"con":true,"img":false}]}
{"op":"mcm","clk":"5346699694","pt":1646094542570,"mc":[{"id":"1.195395447","rc":[{"atb":[[21,0]],"id":40014837}],"con":true,"img":false}]}
{"op":"mcm","clk":"5346699756","pt":1646094544529,"mc":[{"id":"1.195395447","rc":[{"atb":[[3.25,9.9]],"id":42315317}],"con":true,"img":false}]}
{"op":"mcm","clk":"5346699806","pt":1646094546425,"mc":[{"id":"1.195395447","rc":[{"atb":[[21,3.77]],"id":40014837}],"con":true,"img":false}]}
{"op":"mcm","clk":"5346699830","pt":1646094546942,"mc":[{"id":"1.195395447","rc":[{"atb":[[3.2,10.27]],"id":42315317},{"atl":[[3.65,7.55]],"id":43154430}],"con":true,"img":false}]}
{"op":"mcm","clk":"5346699857","pt":1646094547558,"mc":[{"id":"1.195395447","rc":[{"atl":[[3.6,11.74]],"id":43154430}],"con":true,"img":false}]}
{"op":"mcm","clk":"5346699859","pt":1646094547660,"mc":[{"id":"1.195395447","rc":[{"atl":[[3.65,0]],"id":43154430}],"con":true,"img":false}]}
{"op":"mcm","clk":"5346699917","pt":1646094549257,"mc":[{"id":"1.195395447","rc":[{"atb":[[3.2,0]],"id":42315317},{"atl":[[6.8,0]],"id":42315317},{"atl":[[3.6,4.05],[3.65,7.55]],"id":43154430},{"atl":[[15,13.22]],"id":37076580}],"con":true,"img":false}]}
{"op":"mcm","clk":"5346699921","pt":1646094549360,"mc":[{"id":"1.195395447","rc":[{"atl":[[7.6,6.55]],"id":42315317}],"con":true,"img":false}]}
{"op":"mcm","clk":"5346700026","pt":1646094552182,"mc":[{"id":"1.195395447","rc":[{"atb":[[3.25,0]],"id":42315317}],"con":true,"img":false}]}
{"op":"mcm","clk":"5346700050","pt":1646094552976,"mc":[{"id":"1.195395447","rc":[{"atb":[[3.1,7.24]],"id":42315317}],"con":true,"img":false}]}
{"op":"mcm","clk":"5346700053","pt":1646094553077,"mc":[{"id":"1.195395447","rc":[{"atl":[[6.4,2.81]],"id":42315317}],"con":true,"img":false}]}
{"op":"mcm","clk":"5346700099","pt":1646094554463,"mc":[{"id":"1.195395447","rc":[{"atb":[[3.15,9.9]],"id":42315317}],"con":true,"img":false}]}
{"op":"mcm","clk":"5346700152","pt":1646094556000,"mc":[{"id":"1.195395447","rc":[{"atb":[[3.15,15.33]],"id":42315317}],"con":true,"img":false}]}
{"op":"mcm","clk":"5346700274","pt":1646094559193,"mc":[{"id":"1.195395447","rc":[{"atl":[[15,9.19]],"id":37076580}],"con":true,"img":false}]}
{"op":"mcm","clk":"5346700281","pt":1646094559499,"mc":[{"id":"1.195395447","rc":[{"atl":[[3.65,12.58]],"id":43154430}],"con":true,"img":false}]}
{"op":"mcm","clk":"5346700286","pt":1646094559602,"mc":[{"id":"1.195395447","rc":[{"atl":[[6.4,5.68]],"id":42315317}],"con":true,"img":false}]}
{"op":"mcm","clk":"5346700352","pt":1646094561707,"mc":[{"id":"1.195395447","rc":[{"atb":[[3.1,11.53]],"id":42315317}],"con":true,"img":false}]}
{"op":"mcm","clk":"5346700468","pt":1646094564995,"mc":[{"id":"1.195395447","rc":[{"atb":[[3.1,8.66]],"id":42315317}],"con":true,"img":false}]}
{"op":"mcm","clk":"5346700568","pt":1646094568393,"mc":[{"id":"1.195395447","rc":[{"atb":[[3.2,2.9]],"id":42315317}],"con":true,"img":false}]}
{"op":"mcm","clk":"5346700592","pt":1646094569214,"mc":[{"id":"1.195395447","rc":[{"atb":[[1.58,184.17]],"id":43154430}],"con":true,"img":false}]}
{"op":"mcm","clk":"5346700743","pt":1646094573802,"mc":[{"id":"1.195395447","rc":[{"atb":[[3.1,28.94],[3.05,0]],"id":42315317},{"atl":[[3.6,11.74],[3.65,5.03]],"id":43154430},{"spn":2.96,"spf":1.0,"id":43154430}],"con":true,"img":false}]}
{"op":"mcm","clk":"5346700746","pt":1646094573901,"mc":[{"id":"1.195395447","rc":[{"atb":[[3.1,8.66],[3.05,30.68]],"id":42315317}],"con":true,"img":false}]}
{"op":"mcm","clk":"5346700912","pt":1646094579196,"mc":[{"id":"1.195395447","rc":[{"atl":[[7.6,0]],"id":42315317}],"con":true,"img":false}]}
{"op":"mcm","clk":"5346700914","pt":1646094579298,"mc":[{"id":"1.195395447","rc":[{"atl":[[6.8,6.55]],"id":42315317}],"con":true,"img":false}]}
{"op":"mcm","clk":"5346701037","pt":1646094583819,"mc":[{"id":"1.195395447","rc":[{"atl":[[3.6,4.05],[3.65,12.58]],"id":43154430}],"con":true,"img":false}]}
{"op":"mcm","clk":"5346701064","pt":1646094584695,"mc":[{"id":"1.195395447","rc":[{"atl":[[3.6,11.74],[3.65,5.03]],"id":43154430}],"con":true,"img":false}]}
{"op":"mcm","clk":"5346701108","pt":1646094585730,"mc":[{"id":"1.195395447","rc":[{"atl":[[3.6,4.05],[3.65,12.58]],"id":43154430}],"con":true,"img":false}]}
{"op":"mcm","clk":"5346701235","pt":1646094589228,"mc":[{"id":"1.195395447","rc":[{"atl":[[210,2.63]],"id":40014837}],"con":true,"img":false}]}
{"op":"mcm","clk":"5346701238","pt":1646094589330,"mc":[{"id":"1.195395447","rc":[{"atl":[[200,2.7]],"id":40014837}],"con":true,"img":false}]}
{"op":"mcm","clk":"5346701242","pt":1646094589432,"mc":[{"id":"1.195395447","rc":[{"atl":[[190,2],[210,0.63]],"id":40014837}],"con":true,"img":false}]}
{"op":"mcm","clk":"5346701328","pt":1646094591342,"mc":[{"id":"1.195395447","rc":[{"atb":[[21,0]],"id":40014837}],"con":true,"img":false}]}
{"op":"mcm","clk":"5346701468","pt":1646094595244,"mc":[{"id":"1.195395447","rc":[{"atb":[[21,3.77]],"id":40014837}],"con":true,"img":false}]}
{"op":"mcm","clk":"5346701508","pt":1646094596324,"mc":[{"id":"1.195395447","rc":[{"atb":[[3.1,28.94],[3.05,0]],"id":42315317},{"atl":[[3.6,11.74],[3.65,5.03]],"id":43154430}],"con":true,"img":false}]}
{"op":"mcm","clk":"5346701546","pt":1646094597453,"mc":[{"id":"1.195395447","rc":[{"atl":[[3.6,4.05],[3.65,12.58]],"id":43154430}],"con":true,"img":false}]}
{"op":"mcm","clk":"5346701609","pt":1646094599255,"mc":[{"id":"1.195395447","rc":[{"atb":[[6.8,0],[7.2,20.55]],"id":38541023},{"atl":[[210,0.63]],"id":37535509},{"atb":[[14.5,0]],"id":36899944},{"atl":[[180,0]],"id":36899944},{"atl":[[9.6,0],[8.6,14.8]],"id":42315317},{"atl":[[5.2,25.43],[5.7,0]],"id":43154430},{"atb":[[10,7.37]],"id":40041375},{"atb":[[3.05,0],[3.45,52.46]],"id":37076580}],"con":true,"img":false}]}
{"op":"mcm","clk":"5346701611","pt":1646094599358,"mc":[{"id":"1.195395447","rc":[{"atl":[[150,2.7]],"id":37535509},{"atb":[[15.5,9.19]],"id":36899944},{"atl":[[130,2.7]],"id":36899944},{"atb":[[10.5,4.8]],"id":40041375}],"con":true,"img":false}]}
{"op":"mcm","clk":"5346701616","pt":1646094599460,"mc":[{"id":"1.195395447","rc":[{"atl":[[160,0.83],[210,2.63]],"id":37535509},{"atl":[[140,0.95],[190,3.69]],"id":36899944}],"con":true,"img":false}]}
{"op":"mcm","clk":"5346701692","pt":1646094601318,"mc":[{"id":"1.195395447","rc":[{"atb":[[3.1,24.57]],"id":42315317}],"con":true,"img":false}]}
{"op":"mcm","clk":"5346701699","pt":1646094601427,"mc":[{"id":"1.195395447","rc":[{"atb":[[3.1,4.29],[3.05,30.68]],"id":42315317}],"con":true,"img":false}]}
{"op":"mcm","clk":"5346701750","pt":1646094602663,"mc":[{"id":"1.195395447","rc":[{"atb":[[15,0]],"id":36899944},{"atb":[[10,0]],"id":40041375}],"con":true,"img":false}]}
{"op":"mcm","clk":"5346701903","pt":1646094606430,"mc":[{"id":"1.195395447","rc":[{"atb":[[17,5.78]],"id":36899944}],"con":true,"img":false}]}
{"op":"mcm","clk":"5346701997","pt":1646094608749,"mc":[{"id":"1.195395447","rc":[{"atl":[[3.6,11.74],[3.65,5.03]],"id":43154430}],"con":true,"img":false}]}
{"op":"mcm","clk":"5346702019","pt":1646094609266,"mc":[{"id":"1.195395447","rc":[{"atb":[[12,0],[17,6.91]],"id":37535509},{"atl":[[150,0]],"id":37535509},{"atb":[[15.5,0]],"id":36899944},{"atl":[[130,0]],"id":36899944},{"atb":[[10.5,0]],"id":40041375}],"con":true,"img":false}]}
{"op":"mcm","clk":"5346702025","pt":1646094609370,"mc":[{"id":"1.195395447","rc":[{"atl":[[200,2.7]],"id":37535509},{"atb":[[14.5,9.19]],"id":36899944},{"atl":[[180,2.7]],"id":36899944},{"atb":[[10,4.8]],"id":40041375}],"con":true,"img":false}]}
{"op":"mcm","clk":"5346702060","pt":1646094610244,"mc":[{"id":"1.195395447","rc":[{"atl":[[3.6,4.05],[3.65,12.58]],"id":43154430}],"con":true,"img":false}]}
{"op":"mcm","clk":"5346702085","pt":1646094610758,"mc":[{"id":"1.195395447","rc":[{"atl":[[190,2],[210,0.63]],"id":37535509},{"atl":[[170,2],[190,1.69]],"id":36899944}],"con":true,"img":false}]}
{"op":"mcm","clk":"5346702140","pt":1646094611840,"mc":[{"id":"1.195395447","rc":[{"atb":[[17,0]],"id":36899944}],"con":true,"img":false}]}
{"op":"mcm","clk":"5346702281","pt":1646094615484,"mc":[{"id":"1.195395447","rc":[{"atb":[[15,6.6]],"id":36899944}],"con":true,"img":false}]}
{"op":"mcm","clk":"5346702417","pt":1646094619243,"mc":[{"id":"1.195395447","rc":[{"atl":[[44,0]],"id":40041375}],"con":true,"img":false}]}
{"op":"mcm","clk":"5346702421","pt":1646094619400,"mc":[{"id":"1.195395447","rc":[{"atl":[[32,2.7]],"id":40041375}],"con":true,"img":false}]}
{"op":"mcm","clk":"5346702426","pt":1646094619554,"mc":[{"id":"1.195395447","rc":[{"atb":[[3.1,8.66]],"id":42315317}],"con":true,"img":false}]}
{"op":"mcm","clk":"5346702826","pt":1646094629196,"mc":[{"id":"1.195395447","rc":[{"atl":[[200,0]],"id":40014837},{"atl":[[80,0]],"id":38541023}],"con":true,"img":false}]}
{"op":"mcm","clk":"5346702829","pt":1646094629298,"mc":[{"id":"1.195395447","rc":[{"atl":[[180,2.7]],"id":40014837},{"atl":[[48,2.7]],"id":38541023}],"con":true,"img":false}]}
{"op":"mcm","clk":"5346702859","pt":1646094629504,"mc":[{"id":"1.195395447","rc":[{"atl":[[170,2],[190,0]],"id":40014837}],"con":true,"img":false}]}
{"op":"mcm","clk":"5346702939","pt":1646094631672,"mc":[{"id":"1.195395447","rc":[{"atb":[[21,0]],"id":40014837}],"con":true,"img":false}]}
{"op":"mcm","clk":"5346702974","pt":1646094632804,"mc":[{"id":"1.195395447","rc":[{"atb":[[3.1,28.94],[3.05,0]],"id":42315317},{"atl":[[3.6,11.74],[3.65,5.03]],"id":43154430}],"con":true,"img":false}]}
{"op":"mcm","clk":"5346703020","pt":1646094633886,"mc":[{"id":"1.195395447","rc":[{"atb":[[3.1,24.65]],"id":42315317}],"con":true,"img":false}]}
{"op":"mcm","clk":"5346703056","pt":1646094634705,"mc":[{"id":"1.195395447","rc":[{"atl":[[3.6,4.05],[3.65,12.58]],"id":43154430}],"con":true,"img":false}]}
{"op":"mcm","clk":"5346703072","pt":1646094635372,"mc":[{"id":"1.195395447","rc":[{"atb":[[21,3.77]],"id":40014837}],"con":true,"img":false}]}
{"op":"mcm","clk":"5346703112","pt":1646094636807,"mc":[{"id":"1.195395447","rc":[{"atl":[[3.75,18.18]],"id":43154430}],"con":true,"img":false}]}
{"op":"mcm","clk":"5346703158","pt":1646094637888,"mc":[{"id":"1.195395447","rc":[{"atb":[[3.1,4.37],[3.05,30.68]],"id":42315317}],"con":true,"img":false}]}
{"op":"mcm","clk":"5346703223","pt":1646094639889,"mc":[{"id":"1.195395447","rc":[{"atl":[[6.4,2.86]],"id":42315317}],"con":true,"img":false}]}
{"op":"mcm","clk":"5346703348","pt":1646094642811,"mc":[{"id":"1.195395447","rc":[{"atl":[[6.4,5.68]],"id":42315317},{"atl":[[3.75,22.98]],"id":43154430}],"con":true,"img":false}]}
{"op":"mcm","clk":"5346703429","pt":1646094645222,"mc":[{"id":"1.195395447","rc":[{"atb":[[3.1,24.65]],"id":42315317},{"atl":[[3.6,11.74]],"id":43154430}],"con":true,"img":false}]}
{"op":"mcm","clk":"5346703436","pt":1646094645325,"mc":[{"id":"1.195395447","rc":[{"atb":[[3.05,0]],"id":42315317},{"atl":[[3.65,5.03]],"id":43154430}],"con":true,"img":false}]}
{"op":"mcm","clk":"5346703442","pt":1646094645427,"mc":[{"id":"1.195395447","rc":[{"atb":[[3.1,4.37],[3.05,30.68]],"id":42315317}],"con":true,"img":false}]}
{"op":"mcm","clk":"5346703467","pt":1646094645893,"mc":[{"id":"1.195395447","rc":[{"atl":[[3.6,4.05],[3.65,12.58]],"id":43154430}],"con":true,"img":false}]}
{"op":"mcm","clk":"5346703596","pt":1646094649233,"mc":[{"id":"1.195395447","rc":[{"atl":[[200,0]],"id":37535509},{"atl":[[180,0]],"id":36899944}],"con":true,"img":false}]}
{"op":"mcm","clk":"5346703600","pt":1646094649337,"mc":[{"id":"1.195395447","rc":[{"atl":[[180,2.7]],"id":37535509},{"atl":[[160,2.7]],"id":36899944}],"con":true,"img":false}]}
{"op":"mcm","clk":"5346703606","pt":1646094649439,"mc":[{"id":"1.195395447","rc":[{"atl":[[170,2],[190,0]],"id":37535509}],"con":true,"img":false}]}
{"op":"mcm","clk":"5346703611","pt":1646094649542,"mc":[{"id":"1.195395447","rc":[{"atl":[[150,2],[170,0]],"id":36899944}],"con":true,"img":false}]}
{"op":"mcm","clk":"5346703800","pt":1646094654823,"mc":[{"id":"1.195395447","rc":[{"atb":[[3.1,8.66]],"id":42315317}],"con":true,"img":false}]}
{"op":"mcm","clk":"5346703919","pt":1646094658151,"mc":[{"id":"1.195395447","rc":[{"atb":[[3.1,28.94]],"id":42315317},{"atl":[[3.6,11.74]],"id":43154430}],"con":true,"img":false}]}
{"op":"mcm","clk":"5346703925","pt":1646094658254,"mc":[{"id":"1.195395447","rc":[{"atb":[[3.05,0]],"id":42315317},{"atl":[[3.65,5.03]],"id":43154430}],"con":true,"img":false}]}
{"op":"mcm","clk":"5346703966","pt":1646094659229,"mc":[{"id":"1.195395447","rc":[{"atb":[[14.5,0]],"id":36899944}],"con":true,"img":false}]}
{"op":"mcm","clk":"5346703972","pt":1646094659332,"mc":[{"id":"1.195395447","rc":[{"atb":[[15.5,9.19]],"id":36899944}],"con":true,"img":false}]}
{"op":"mcm","clk":"5346704005","pt":1646094660152,"mc":[{"id":"1.195395447","rc":[{"atb":[[2.82,0],[2.76,11.36],[2.78,0]],"id":42315317},{"atb":[[2.1,73.75],[2.06,18.87]],"id":43154430},{"atl":[[3.6,4.05],[3.65,12.58]],"id":43154430},{"atb":[[5.3,4.65],[5.5,0],[5.7,0]],"id":40041375},{"atl":[[8.2,2.78],[7.8,0]],"id":37076580}],"con":true,"img":false}]}
{"op":"mcm","clk":"5346704012","pt":1646094660254,"mc":[{"id":"1.195395447","rc":[{"atl":[[9,28.12]],"id":37076580}],"con":true,"img":false}]}
{"op":"mcm","clk":"5346704016","pt":1646094660356,"mc":[{"id":"1.195395447","rc":[{"atl":[[8.6,9.87]],"id":37076580}],"con":true,"img":false}]}
{"op":"mcm","clk":"5346704060","pt":1646094661537,"mc":[{"id":"1.195395447","rc":[{"atb":[[3.1,24.57]],"id":42315317}],"con":true,"img":false}]}
{"op":"mcm","clk":"5346704095","pt":1646094662361,"mc":[{"id":"1.195395447","rc":[{"atb":[[15,0]],"id":36899944}],"con":true,"img":false}]}
{"op":"mcm","clk":"5346704125","pt":1646094663233,"mc":[{"id":"1.195395447","rc":[{"atb":[[3.05,30.68]],"id":42315317}],"con":true,"img":false}]}
{"op":"mcm","clk":"5346704129","pt":1646094663337,"mc":[{"id":"1.195395447","rc":[{"atb":[[3.1,4.29]],"id":42315317}],"con":true,"img":false}]}
{"op":"mcm","clk":"5346704237","pt":1646094665947,"mc":[{"id":"1.195395447","rc":[{"atb":[[17,5.78]],"id":36899944}],"con":true,"img":false}]}
{"op":"mcm","clk":"5346704348","pt":1646094669285,"mc":[{"id":"1.195395447","rc":[{"atl":[[180,0]],"id":40014837},{"atb":[[15.5,0]],"id":36899944}],"con":true,"img":false}]}
{"op":"mcm","clk":"5346704355","pt":1646094669335,"mc":[{"id":"1.195395447","rc":[{"atl":[[160,3.53]],"id":40014837},{"atb":[[14.5,9.19]],"id":36899944}],"con":true,"img":false}]}
{"op":"mcm","clk":"5346704359","pt":1646094669438,"mc":[{"id":"1.195395447","rc":[{"atl":[[160,5.53],[170,0]],"id":40014837}],"con":true,"img":false}]}
{"op":"mcm","clk":"5346704383","pt":1646094670158,"mc":[{"id":"1.195395447","rc":[{"atb":[[2.72,29.07]],"id":42315317},{"atb":[[2.02,49.02]],"id":43154430},{"atb":[[5.1,12.2]],"id":40041375},{"atl":[[8.6,6.58]],"id":37076580}],"con":true,"img":false}]}
{"op":"mcm","clk":"5346704430","pt":1646094671442,"mc":[{"id":"1.195395447","rc":[{"atb":[[21,0]],"id":40014837},{"atb":[[17,0]],"id":36899944}],"con":true,"img":false}]}
{"op":"mcm","clk":"5346704570","pt":1646094675155,"mc":[{"id":"1.195395447","rc":[{"atb":[[21,3.77]],"id":40014837},{"atb":[[15,6.6]],"id":36899944}],"con":true,"img":false}]}
{"op":"mcm","clk":"5346704724","pt":1646094679155,"mc":[{"id":"1.195395447","rc":[{"atl":[[48,0]],"id":38541023},{"atl":[[32,0]],"id":40041375}],"con":true,"img":false}]}
{"op":"mcm","clk":"5346704728","pt":1646094679256,"mc":[{"id":"1.195395447","rc":[{"atl":[[70,2.7]],"id":38541023},{"atl":[[44,2.7]],"id":40041375}],"con":true,"img":false}]}
{"op":"mcm","clk":"5346704739","pt":1646094679462,"mc":[{"id":"1.195395447","rc":[{"atb":[[3.1,8.66]],"id":42315317}],"con":true,"img":false}]}
{"op":"mcm","clk":"5346704748","pt":1646094679668,"mc":[{"id":"1.195395447","rc":[{"atl":[[3.65,7.55]],"id":43154430}],"con":true,"img":false}]}
{"op":"mcm","clk":"5346704769","pt":1646094680185,"mc":[{"id":"1.195395447","rc":[{"atb":[[2.68,44.64]],"id":42315317},{"atb":[[1.99,75.76]],"id":43154430},{"atb":[[4.9,19.23]],"id":40041375},{"atl":[[9,21.88]],"id":37076580}],"con":true,"img":false}]}
{"op":"mcm","clk":"5346704819","pt":1646094681780,"mc":[{"id":"1.195395447","rc":[{"atb":[[3.1,28.94]],"id":42315317},{"atl":[[3.6,11.74],[3.65,0]],"id":43154430}],"con":true,"img":false}]}
{"op":"mcm","clk":"5346704825","pt":1646094681883,"mc":[{"id":"1.195395447","rc":[{"atb":[[3.05,0],[2.74,0],[2.7,0]],"id":42315317}],"con":true,"img":false}]}
{"op":"mcm","clk":"5346704831","pt":1646094681985,"mc":[{"id":"1.195395447","rc":[{"atb":[[3.1,8.66],[3.05,30.68]],"id":42315317}],"con":true,"img":false}]}
{"op":"mcm","clk":"5346704843","pt":1646094682292,"mc":[{"id":"1.195395447","rc":[{"atl":[[3.6,4.05],[3.65,7.55]],"id":43154430}],"con":true,"img":false}]}
{"op":"mcm","clk":"5346704847","pt":1646094682394,"mc":[{"id":"1.195395447","rc":[{"atl":[[3.6,7.45]],"id":43154430}],"con":true,"img":false}]}
{"op":"mcm","clk":"5346704952","pt":1646094685362,"mc":[{"id":"1.195395447","rc":[{"atl":[[6.4,2.81]],"id":42315317}],"con":true,"img":false}]}
{"op":"mcm","clk":"5346705099","pt":1646094689306,"mc":[{"id":"1.195395447","rc":[{"atl":[[180,0]],"id":37535509},{"atl":[[160,0]],"id":36899944}],"con":true,"img":false}]}
{"op":"mcm","clk":"5346705105","pt":1646094689409,"mc":[{"id":"1.195395447","rc":[{"atl":[[160,3.53]],"id":37535509},{"atl":[[140,3.65]],"id":36899944}],"con":true,"img":false}]}
{"op":"mcm","clk":"5346705113","pt":1646094689562,"mc":[{"id":"1.195395447","rc":[{"atl":[[150,2],[170,0]],"id":37535509},{"atl":[[130,2],[150,0]],"id":36899944}],"con":true,"img":false}]}
{"op":"mcm","clk":"5346705131","pt":1646094690186,"mc":[{"id":"1.195395447","rc":[{"atb":[[2.64,76.22]],"id":42315317},{"atb":[[4.7,33.78]],"id":40041375},{"atl":[[9.4,14.88]],"id":37076580}],"con":true,"img":false}]}
{"op":"mcm","clk":"5346705168","pt":1646094691466,"mc":[{"id":"1.195395447","rc":[{"atl":[[3.65,12.58]],"id":43154430}],"con":true,"img":false}]}
{"op":"mcm","clk":"5346705172","pt":1646094691569,"mc":[{"id":"1.195395447","rc":[{"atl":[[6.4,5.68]],"id":42315317}],"con":true,"img":false}]}
{"op":"mcm","clk":"5346705195","pt":1646094692286,"mc":[{"id":"1.195395447","rc":[{"atb":[[1.97,128.87]],"id":43154430}],"con":true,"img":false}]}
{"op":"mcm","clk":"5346705273","pt":1646094694287,"mc":[{"id":"1.195395447","rc":[{"atl":[[3.6,15.14]],"id":43154430},{"spn":6.5,"spf":1.0,"id":37076580}],"con":true,"img":false}]}
{"op":"mcm","clk":"5346705277","pt":1646094694390,"mc":[{"id":"1.195395447","rc":[{"atl":[[3.65,5.03]],"id":43154430}],"con":true,"img":false}]}
{"op":"mcm","clk":"5346705284","pt":1646094694594,"mc":[{"id":"1.195395447","rc":[{"atl":[[3.6,7.45],[3.65,12.58]],"id":43154430}],"con":true,"img":false}]}
{"op":"mcm","clk":"5346705395","pt":1646094697272,"mc":[{"id":"1.195395447","rc":[{"atb":[[18,0]],"id":37535509},{"atb":[[16.5,5.23]],"id":36899944}],"con":true,"img":false}]}
{"op":"mcm","clk":"5346705403","pt":1646094697372,"mc":[{"id":"1.195395447","rc":[{"atb":[[20,2.7]],"id":37535509},{"atb":[[17,3.2]],"id":36899944}],"con":true,"img":false}]}
{"op":"mcm","clk":"5346705492","pt":1646094699384,"mc":[{"id":"1.195395447","rc":[{"atb":[[2.94,42.7],[3.05,0]],"id":42315317},{"atl":[[5.8,0],[7.8,34.14],[5.4,4.55],[8.8,16.94]],"id":42315317},{"atl":[[3.75,12.07],[3.65,5.03]],"id":43154430}],"con":true,"img":false}]}
{"op":"mcm","clk":"5346705512","pt":1646094700098,"mc":[{"id":"1.195395447","rc":[{"atb":[[3.1,4.37]],"id":42315317}],"con":true,"img":false}]}
{"op":"mcm","clk":"5346705525","pt":1646094700404,"mc":[{"id":"1.195395447","rc":[{"atb":[[19.5,0]],"id":37535509},{"atb":[[15,0]],"id":36899944}],"con":true,"img":false}]}
{"op":"mcm","clk":"5346705528","pt":1646094700516,"mc":[{"id":"1.195395447","rc":[{"atl":[[3.6,4.05]],"id":43154430}],"con":true,"img":false}]}
{"op":"mcm","clk":"5346705684","pt":1646094704103,"mc":[{"id":"1.195395447","rc":[{"atb":[[21,3.41]],"id":37535509},{"atb":[[17.5,4.52]],"id":36899944}],"con":true,"img":false}]}
{"op":"mcm","clk":"5346705818","pt":1646094707432,"mc":[{"id":"1.195395447","rc":[{"atb":[[5.3,0],[4.5,0],[5,25],[5.7,4.26]],"id":40041375}],"con":true,"img":false}]}
{"op":"mcm","clk":"5346705889","pt":1646094709227,"mc":[{"id":"1.195395447","rc":[{"atl":[[160,2.83]],"id":40014837},{"atb":[[6.8,15.43],[7.2,0]],"id":38541023},{"atb":[[14,8.48],[17,0],[20,0]],"id":37535509},{"atl":[[160,0.83]],"id":37535509},{"atl":[[140,0.95]],"id":36899944},{"atl":[[9.6,24.5],[8.6,0]],"id":42315317},{"atb":[[1.58,81.99]],"id":43154430},{"atl":[[5.2,0],[5.7,38.96]],"id":43154430},{"atb":[[3.05,34.62],[3.45,0]],"id":37076580}],"con":true,"img":false}]}
{"op":"mcm","clk":"5346705894","pt":1646094709329,"mc":[{"id":"1.195395447","rc":[{"atl":[[210,5.33]],"id":40014837},{"atb":[[18,2.7]],"id":37535509},{"atl":[[210,3.33]],"id":37535509},{"atl":[[180,2.7]],"id":36899944}],"con":true,"img":false}]}
{"op":"mcm","clk":"5346705896","pt":1646094709433,"mc":[{"id":"1.195395447","rc":[{"atl":[[160,0.83]],"id":40014837},{"atl":[[150,0],[160,2.83]],"id":37535509},{"atl":[[130,0],[140,2.95]],"id":36899944},{"atl":[[5.6,10.87]],"id":42315317},{"atl":[[3.85,17.54]],"id":43154430}],"con":true,"img":false}]}
{"op":"mcm","clk":"5346705955","pt":1646094711329,"mc":[{"id":"1.195395447","rc":[{"atb":[[21,0]],"id":40014837},{"atb":[[21,0]],"id":37535509}],"con":true,"img":false}]}
{"op":"mcm","clk":"5346705963","pt":1646094711535,"mc":[{"id":"1.195395447","rc":[{"atl":[[160,0.83],[200,2]],"id":37535509}],"con":true,"img":false}]}
{"op":"mcm","clk":"5346706080","pt":1646094715020,"mc":[{"id":"1.195395447","rc":[{"atb":[[21,3.77]],"id":40014837},{"atb":[[19.5,4.76]],"id":37535509}],"con":true,"img":false}]}
{"op":"mcm","clk":"5346706096","pt":1646094715528,"mc":[{"id":"1.195395447","rc":[{"atb":[[3.1,0]],"id":42315317}],"con":true,"img":false}]}
{"op":"mcm","clk":"5346706143","pt":1646094717317,"mc":[{"id":"1.195395447","rc":[{"atb":[[5.3,4.65],[5.7,0]],"id":40041375}],"con":true,"img":false}]}
{"op":"mcm","clk":"5346706164","pt":1646094718035,"mc":[{"id":"1.195395447","rc":[{"atb":[[2.98,4.55]],"id":42315317}],"con":true,"img":false}]}
{"op":"mcm","clk":"5346706174","pt":1646094718444,"mc":[{"id":"1.195395447","rc":[{"atl":[[6.2,0],[6.6,0],[7,0]],"id":42315317},{"atb":[[5.3,0],[5.7,4.26]],"id":40041375}],"con":true,"img":false}]}
{"op":"mcm","clk":"5346706178","pt":1646094718650,"mc":[{"id":"1.195395447","rc":[{"atb":[[3.15,9.9]],"id":42315317}],"con":true,"img":false}]}
{"op":"mcm","clk":"5346706202","pt":1646094719319,"mc":[{"id":"1.195395447","rc":[{"atb":[[2.92,2]],"id":42315317},{"atl":[[6.8,0]],"id":42315317}],"con":true,"img":false}]}
{"op":"mcm","clk":"5346706205","pt":1646094719424,"mc":[{"id":"1.195395447","rc":[{"atb":[[12,1.82],[13,0]],"id":40014837},{"atb":[[7.8,0],[7.2,3.23]],"id":38541023},{"atb":[[10,8],[11,2]],"id":37535509},{"atb":[[2.96,22.53]],"id":42315317},{"atl":[[5.8,15.62],[7.6,6.55]],"id":42315317},{"atb":[[2.1,91.93],[2.06,0]],"id":43154430},{"atl":[[3.75,4.8],[4,6.67],[3.95,25.42]],"id":43154430},{"atb":[[6,4],[5.7,0]],"id":40041375}],"con":true,"img":false}]}
{"op":"mcm","clk":"5346706212","pt":1646094719628,"mc":[{"id":"1.195395447","rc":[{"atb":[[3.15,0]],"id":42315317}],"con":true,"img":false}]}
{"op":"mcm","clk":"5346706267","pt":1646094721525,"mc":[{"id":"1.195395447","rc":[{"atb":[[2.98,9.19],[3.2,0]],"id":42315317}],"con":true,"img":false}]}
{"op":"mcm","clk":"5346706292","pt":1646094722347,"mc":[{"id":"1.195395447","rc":[{"atb":[[3.05,17.38]],"id":42315317}],"con":true,"img":false}]}
{"op":"mcm","clk":"5346706351","pt":1646094724353,"mc":[{"id":"1.195395447","rc":[{"atb":[[3.05,28.42]],"id":42315317}],"con":true,"img":false}]}
{"op":"mcm","clk":"5346706355","pt":1646094724455,"mc":[{"id":"1.195395447","rc":[{"atb":[[3.1,2.96]],"id":42315317}],"con":true,"img":false}]}
{"op":"mcm","clk":"5346706364","pt":1646094724761,"mc":[{"id":"1.195395447","rc":[{"atb":[[8.6,0]],"id":38541023},{"atb":[[18.5,0]],"id":37535509}],"con":true,"img":false}]}
{"op":"mcm","clk":"5346706368","pt":1646094724863,"mc":[{"id":"1.195395447","rc":[{"atb":[[8.8,1.29]],"id":38541023},{"atb":[[19,5.07]],"id":37535509}],"con":true,"img":false}]}
{"op":"mcm","clk":"5346706432","pt":1646094726868,"mc":[{"id":"1.195395447","rc":[{"atb":[[7.4,0]],"id":38541023},{"atl":[[3.85,0]],"id":43154430},{"atb":[[6.4,17.03],[6,0]],"id":40041375}],"con":true,"img":false}]}
{"op":"mcm","clk":"5346706457","pt":1646094727638,"mc":[{"id":"1.195395447","rc":[{"atl":[[3.95,0]],"id":43154430},{"atb":[[6.4,13.33],[6,4]],"id":40041375}],"con":true,"img":false}]}
{"op":"mcm","clk":"5346706462","pt":1646094727741,"mc":[{"id":"1.195395447","rc":[{"atb":[[19.5,0]],"id":37535509}],"con":true,"img":false}]}
{"op":"mcm","clk":"5346706484","pt":1646094728968,"mc":[{"id":"1.195395447","rc":[{"atb":[[3.05,17.38]],"id":42315317}],"con":true,"img":false}]}
{"op":"mcm","clk":"5346706491","pt":1646094729276,"mc":[{"id":"1.195395447","rc":[{"atl":[[26,0]],"id":38541023},{"atb":[[1.58,184.17]],"id":43154430}],"con":true,"img":false}]}
{"op":"mcm","clk":"5346706495","pt":1646094729327,"mc":[{"id":"1.195395447","rc":[{"atl":[[34,2.7]],"id":38541023}],"con":true,"img":false}]}
{"op":"mcm","clk":"5346706499","pt":1646094729433,"mc":[{"id":"1.195395447","rc":[{"atb":[[11,5]],"id":40014837},{"atb":[[6.8,24.05]],"id":38541023},{"atb":[[10,13.56]],"id":37535509},{"atl":[[6,25]],"id":42315317},{"atb":[[2.06,47.17]],"id":43154430},{"atl":[[4.2,15.62]],"id":43154430}],"con":true,"img":false}]}
{"op":"mcm","clk":"5346706567","pt":1646094731484,"mc":[{"id":"1.195395447","rc":[{"atb":[[17,5.78]],"id":37535509}],"con":true,"img":false}]}
{"op":"mcm","clk":"5346706635","pt":1646094733947,"mc":[{"id":"1.195395447","rc":[{"atb":[[1.2,2.23]],"id":42315317}],"con":true,"img":false}]}
{"op":"mcm","clk":"5346706646","pt":1646094734255,"mc":[{"id":"1.195395447","rc":[{"atb":[[1.2,2.07]],"id":42315317}],"con":true,"img":false}]}
{"op":"mcm","clk":"5346706664","pt":1646094734563,"mc":[{"id":"1.195395447","rc":[{"atb":[[1.2,0]],"id":42315317}],"con":true,"img":false}]}
{"op":"mcm","clk":"5346706670","pt":1646094734668,"mc":[{"id":"1.195395447","rc":[{"atb":[[3.15,2.07]],"id":42315317}],"con":true,"img":false}]}
{"op":"mcm","clk":"5346706678","pt":1646094734872,"mc":[{"id":"1.195395447","rc":[{"atb":[[8.8,0]],"id":37535509},{"atb":[[1.97,0]],"id":43154430},{"atb":[[6.4,17.03],[6,0]],"id":40041375}],"con":true,"img":false}]}
{"op":"mcm","clk":"5346706707","pt":1646094735642,"mc":[{"id":"1.195395447","rc":[{"atb":[[6.4,13.33],[6,4]],"id":40041375}],"con":true,"img":false}]}
{"op":"mcm","clk":"5346706743","pt":1646094736563,"mc":[{"id":"1.195395447","rc":[{"atb":[[3.1,0]],"id":42315317}],"con":true,"img":false}]}
{"op":"mcm","clk":"5346706755","pt":1646094736972,"mc":[{"id":"1.195395447","rc":[{"atb":[[3.05,0]],"id":42315317}],"con":true,"img":false}]}
{"op":"mcm","clk":"5346706823","pt":1646094739276,"mc":[{"id":"1.195395447","rc":[{"atb":[[18,0]],"id":37535509}],"con":true,"img":false}]}
{"op":"mcm","clk":"5346706829","pt":1646094739379,"mc":[{"id":"1.195395447","rc":[{"atb":[[19.5,2.7]],"id":37535509}],"con":true,"img":false}]}
{"op":"mcm","clk":"5346706833","pt":1646094739479,"mc":[{"id":"1.195395447","rc":[{"atb":[[10,8.33]],"id":40014837},{"atb":[[6.4,13.89]],"id":38541023},{"atb":[[9.6,8.72]],"id":37535509},{"atb":[[2.02,73.53]],"id":43154430},{"atl":[[4.4,22.06]],"id":43154430}],"con":true,"img":false}]}
{"op":"mcm","clk":"5346706875","pt":1646094740555,"mc":[{"id":"1.195395447","rc":[{"atb":[[3.05,16.76]],"id":42315317}],"con":true,"img":false}]}
{"op":"mcm","clk":"5346706898","pt":1646094741173,"mc":[{"id":"1.195395447","rc":[{"atb":[[3.15,0]],"id":42315317}],"con":true,"img":false}]}
{"op":"mcm","clk":"5346706902","pt":1646094741272,"mc":[{"id":"1.195395447","rc":[{"atb":[[2.94,0],[2.92,44.7]],"id":42315317}],"con":true,"img":false}]}
{"op":"mcm","clk":"5346706935","pt":1646094742193,"mc":[{"id":"1.195395447","rc":[{"atb":[[2.98,4.64]],"id":42315317}],"con":true,"img":false}]}
{"op":"mcm","clk":"5346706942","pt":1646094742400,"mc":[{"id":"1.195395447","rc":[{"atb":[[7,0],[6.6,0]],"id":38541023},{"atb":[[17,0]],"id":37535509},{"atb":[[6.4,17.03],[6,0]],"id":40041375}],"con":true,"img":false}]}
{"op":"mcm","clk":"5346706945","pt":1646094742502,"mc":[{"id":"1.195395447","rc":[{"atb":[[3.1,2.88]],"id":42315317}],"con":true,"img":false}]}
{"op":"mcm","clk":"5346706966","pt":1646094743171,"mc":[{"id":"1.195395447","rc":[{"atl":[[140,0.95],[170,2]],"id":36899944}],"con":true,"img":false}]}
{"op":"mcm","clk":"5346706973","pt":1646094743477,"mc":[{"id":"1.195395447","rc":[{"atb":[[6,4]],"id":40041375}],"con":true,"img":false}]}
{"op":"mcm","clk":"5346706979","pt":1646094743581,"mc":[{"id":"1.195395447","rc":[{"atb":[[6.4,13.33]],"id":40041375}],"con":true,"img":false}]}
{"op":"mcm","clk":"5346707066","pt":1646094745884,"mc":[{"id":"1.195395447","rc":[{"atb":[[2.98,0]],"id":42315317}],"con":true,"img":false}]}
{"op":"mcm","clk":"5346707075","pt":1646094746091,"mc":[{"id":"1.195395447","rc":[{"atb":[[20,3.41]],"id":37535509}],"con":true,"img":false}]}
{"op":"mcm","clk":"5346707078","pt":1646094746192,"mc":[{"id":"1.195395447","rc":[{"atb":[[1.2,2.23]],"id":42315317}],"con":true,"img":false}]}
{"op":"mcm","clk":"5346707090","pt":1646094746501,"mc":[{"id":"1.195395447","rc":[{"atb":[[1.2,2.01]],"id":42315317}],"con":true,"img":false}]}
{"op":"mcm","clk":"5346707100","pt":1646094746808,"mc":[{"id":"1.195395447","rc":[{"atb":[[1.2,0]],"id":42315317}],"con":true,"img":false}]}
{"op":"mcm","clk":"5346707103","pt":1646094746860,"mc":[{"id":"1.195395447","rc":[{"atb":[[3.15,2.01]],"id":42315317}],"con":true,"img":false}]}
{"op":"mcm","clk":"5346707165","pt":1646094749171,"mc":[{"id":"1.195395447","rc":[{"atb":[[6.8,30.79]],"id":38541023},{"atl":[[70,0]],"id":38541023},{"atb":[[2.96,0]],"id":42315317},{"atl":[[44,0]],"id":40041375}],"con":true,"img":false}]}
{"op":"mcm","clk":"5346707170","pt":1646094749276,"mc":[{"id":"1.195395447","rc":[{"atb":[[6.6,22.71]],"id":38541023},{"atl":[[48,2.7]],"id":38541023},{"atb":[[2.94,22.53]],"id":42315317},{"atl":[[32,2.7]],"id":40041375}],"con":true,"img":false}]}
{"op":"mcm","clk":"5346707172","pt":1646094749376,"mc":[{"id":"1.195395447","rc":[{"atb":[[6.8,8.62]],"id":38541023},{"atl":[[8.6,14.8]],"id":42315317},{"atl":[[5.2,25.43]],"id":43154430}],"con":true,"img":false}]}
{"op":"mcm","clk":"5346707176","pt":1646094749479,"mc":[{"id":"1.195395447","rc":[{"atb":[[9.6,14.53]],"id":40014837},{"atb":[[6,57.45]],"id":38541023},{"atb":[[9.2,15.24]],"id":37535509},{"atl":[[9.6,0]],"id":42315317},{"atb":[[1.99,126.26]],"id":43154430},{"atl":[[4.6,45.02],[5.7,0]],"id":43154430}],"con":true,"img":false}]}
{"op":"mcm","clk":"5346707190","pt":1646094749785,"mc":[{"id":"1.195395447","rc":[{"atb":[[3.05,0]],"id":42315317}],"con":true,"img":false}]}
{"op":"mcm","clk":"5346707223","pt":1646094750504,"mc":[{"id":"1.195395447","rc":[{"atb":[[6.4,17.03]],"id":40041375}],"con":true,"img":false}]}
{"op":"mcm","clk":"5346707226","pt":1646094750607,"mc":[{"id":"1.195395447","rc":[{"atb":[[6,0]],"id":40041375}],"con":true,"img":false}]}
{"op":"mcm","clk":"5346707233","pt":1646094750709,"mc":[{"id":"1.195395447","rc":[{"atl":[[210,2.63]],"id":40014837},{"atl":[[210,0.63]],"id":37535509},{"atl":[[180,0]],"id":36899944}],"con":true,"img":false}]}
{"op":"mcm","clk":"5346707238","pt":1646094750813,"mc":[{"id":"1.195395447","rc":[{"atl":[[150,2.7]],"id":40014837},{"atl":[[150,2.7]],"id":37535509},{"atl":[[130,2.7]],"id":36899944}],"con":true,"img":false}]}
{"op":"mcm","clk":"5346707247","pt":1646094750967,"mc":[{"id":"1.195395447","rc":[{"atl":[[150,4.7],[210,0.63]],"id":40014837},{"atl":[[150,4.7],[200,0]],"id":37535509},{"atl":[[130,4.7],[170,0]],"id":36899944}],"con":true,"img":false}]}
{"op":"mcm","clk":"5346707252","pt":1646094751073,"mc":[{"id":"1.195395447","rc":[{"atl":[[150,2.7],[160,2.83]],"id":40014837},{"atl":[[150,2.7],[160,2.83]],"id":37535509},{"atl":[[130,2.7],[140,2.95]],"id":36899944}],"con":true,"img":false}]}
{"op":"mcm","clk":"5346707278","pt":1646094751690,"mc":[{"id":"1.195395447","rc":[{"atb":[[6.4,13.33],[6,4]],"id":40041375}],"con":true,"img":false}]}
{"op":"mcm","clk":"5346707347","pt":1646094753487,"mc":[{"id":"1.195395447","rc":[{"atb":[[21,0]],"id":40014837},{"atb":[[20,0]],"id":37535509},{"atb":[[3.15,5.69]],"id":42315317}],"con":true,"img":false}]}
{"op":"mcm","clk":"5346707386","pt":1646094754510,"mc":[{"id":"1.195395447","rc":[{"atb":[[3.1,0]],"id":42315317},{"spn":4.27,"spf":1.0,"id":42315317}],"con":true,"img":false}]}
{"op":"mcm","clk":"5346707476","pt":1646094757132,"mc":[{"id":"1.195395447","rc":[{"atb":[[2.96,4.59]],"id":42315317}],"con":true,"img":false}]}
{"op":"mcm","clk":"5346707480","pt":1646094757182,"mc":[{"id":"1.195395447","rc":[{"atb":[[21,3.77]],"id":40014837},{"atb":[[20,3.41]],"id":37535509}],"con":true,"img":false}]}
{"op":"mcm","clk":"5346707512","pt":1646094758003,"mc":[{"id":"1.195395447","rc":[{"atb":[[3.15,3.67],[2.96,9.28]],"id":42315317}],"con":true,"img":false}]}
{"op":"mcm","clk":"5346707523","pt":1646094758412,"mc":[{"id":"1.195395447","rc":[{"atl":[[70,10.11]],"id":40041375}],"con":true,"img":false}]}
{"op":"mcm","clk":"5346707540","pt":1646094758979,"mc":[{"id":"1.195395447","rc":[{"atb":[[3.15,0]],"id":42315317}],"con":true,"img":false}]}
{"op":"mcm","clk":"5346707546","pt":1646094759183,"mc":[{"id":"1.195395447","rc":[{"atb":[[19.5,0]],"id":37535509},{"atb":[[2.94,65.23],[2.92,2]],"id":42315317},{"atl":[[4.6,34.72]],"id":43154430},{"atb":[[6.4,17.03]],"id":40041375},{"atl":[[110,0]],"id":40041375},{"atb":[[3.05,0],[3.45,52.46]],"id":37076580}],"con":true,"img":false}]}
{"op":"mcm","clk":"5346707549","pt":1646094759287,"mc":[{"id":"1.195395447","rc":[{"atb":[[18,2.7]],"id":37535509},{"atb":[[2.94,22.53],[2.92,44.7]],"id":42315317},{"atl":[[4.3,10.3]],"id":43154430},{"atb":[[6,0]],"id":40041375},{"atl":[[65,2.7]],"id":40041375}],"con":true,"img":false}]}
{"op":"mcm","clk":"5346707563","pt":1646094759901,"mc":[{"id":"1.195395447","rc":[{"atb":[[6.4,13.33],[6,4]],"id":40041375}],"con":true,"img":false}]}
{"op":"mcm","clk":"5346707573","pt":1646094760209,"mc":[{"id":"1.195395447","rc":[{"atl":[[3.75,0]],"id":43154430}],"con":true,"img":false}]}
{"op":"mcm","clk":"5346707588","pt":1646094760516,"mc":[{"id":"1.195395447","rc":[{"atb":[[3.05,2.94]],"id":42315317}],"con":true,"img":false}]}
{"op":"mcm","clk":"5346707667","pt":1646094762693,"mc":[{"id":"1.195395447","rc":[{"atb":[[3.05,20.35]],"id":42315317}],"con":true,"img":false}]}
{"op":"mcm","clk":"5346707674","pt":1646094762896,"mc":[{"id":"1.195395447","rc":[{"atb":[[3.05,31.39]],"id":42315317}],"con":true,"img":false}]}
{"op":"mcm","clk":"5346707683","pt":1646094763205,"mc":[{"id":"1.195395447","rc":[{"atl":[[6.4,2.86]],"id":42315317}],"con":true,"img":false}]}
{"op":"mcm","clk":"5346707781","pt":1646094766125,"mc":[{"id":"1.195395447","rc":[{"atl":[[5.7,3.16]],"id":42315317}],"con":true,"img":false}]}
{"op":"mcm","clk":"5346707787","pt":1646094766226,"mc":[{"id":"1.195395447","rc":[{"atl":[[4.3,14.49]],"id":43154430}],"con":true,"img":false}]}
{"op":"mcm","clk":"5346707871","pt":1646094769053,"mc":[{"id":"1.195395447","rc":[{"atb":[[2.94,65.23],[2.92,2]],"id":42315317},{"atb":[[6.4,17.03],[6,0]],"id":40041375}],"con":true,"img":false}]}
{"op":"mcm","clk":"5346707982","pt":1646094772235,"mc":[{"id":"1.195395447","rc":[{"atb":[[2.96,4.68]],"id":42315317}],"con":true,"img":false}]}
{"op":"mcm","clk":"5346708065","pt":1646094774242,"mc":[{"id":"1.195395447","rc":[{"atb":[[2.92,53.67]],"id":42315317}],"con":true,"img":false}]}
{"op":"mcm","clk":"5346708071","pt":1646094774347,"mc":[{"id":"1.195395447","rc":[{"atb":[[2.94,22.53]],"id":42315317}],"con":true,"img":false}]}
{"op":"mcm","clk":"5346708117","pt":1646094775427,"mc":[{"id":"1.195395447","rc":[{"atb":[[6.4,13.33],[6,4]],"id":40041375}],"con":true,"img":false}]}
{"op":"mcm","clk":"5346708324","pt":1646094781226,"mc":[{"id":"1.195395447","rc":[{"atb":[[3.1,4.29]],"id":42315317}],"con":true,"img":false}]}
{"op":"mcm","clk":"5346708337","pt":1646094781535,"mc":[{"id":"1.195395447","rc":[{"atb":[[2.96,0]],"id":42315317}],"con":true,"img":false}]}
{"op":"mcm","clk":"5346708342","pt":1646094781638,"mc":[{"id":"1.195395447","rc":[{"atb":[[3.05,28.45]],"id":42315317}],"con":true,"img":false}]}
{"op":"mcm","clk":"5346708405","pt":1646094783738,"mc":[{"id":"1.195395447","rc":[{"atb":[[3.05,17.41]],"id":42315317}],"con":true,"img":false}]}
{"op":"mcm","clk":"5346708421","pt":1646094784250,"mc":[{"id":"1.195395447","rc":[{"atb":[[3.05,0]],"id":42315317}],"con":true,"img":false}]}
