{"op":"mcm","clk":"5345985313","pt":1646174444271,"mc":[{"id":"1.195453632","marketDefinition":{"bspMarket":true,"turnInPlayEnabled":false,"persistenceEnabled":false,"marketBaseRate":7.0,"eventId":"31272494","eventTypeId":"4339","numberOfWinners":3,"bettingType":"ODDS","marketType":"PLACE","marketTime":"2022-03-02T12:04:00.000Z","suspendTime":"2022-03-02T12:04:00.000Z","bspReconciled":false,"complete":true,"inPlay":false,"crossMatching":false,"runnersVoidable":false,"numberOfActiveRunners":8,"betDelay":0,"status":"OPEN","runners":[{"status":"ACTIVE","sortPriority":1,"id":36120434,"name":"1. Missys Hand"},{"status":"ACTIVE","sortPriority":2,"id":40637101,"name":"2. Odessa Rock"},{"status":"ACTIVE","sortPriority":3,"id":39183170,"name":"3. Sweet Suzie"},{"status":"ACTIVE","sortPriority":4,"id":35381686,"name":"4. Castle Sween"},{"status":"ACTIVE","sortPriority":5,"id":40917619,"name":"5. Kens Crew"},{"status":"ACTIVE","sortPriority":6,"id":38554545,"name":"6. Call Me Harvey"},{"status":"ACTIVE","sortPriority":7,"id":26349442,"name":"7. Inuka"},{"status":"ACTIVE","sortPriority":8,"id":41398505,"name":"8. Afternoon"}],"regulators":["MR_INT"],"venue":"Traralgon","countryCode":"AU","discountAllowed":true,"timezone":"Australia/Sydney","openDate":"2022-03-02T08:31:00.000Z","version":4382425391,"name":"To Be Placed","eventName":"Traralgon (AUS) 2nd Mar"},"rc":[],"con":true,"img":false}]}
{"op":"mcm","clk":"5346059623","pt":1646175788371,"mc":[{"id":"1.195453632","rc":[{"atb":[[1.2,498.5],[1.25,398.8],[1.3,332.33]],"id":26349442},{"atl":[[2.54,23.54],[2.74,41.67],[2.94,37.37]],"id":26349442},{"spn":1.92,"spf":"NaN","id":26349442},{"atb":[[2.5,66.46],[2.6,62.31],[2.7,58.64]],"id":40637101},{"atl":[[8.6,9.54],[11.5,6.9],[6.6,6.47]],"id":40637101},{"spn":4.65,"spf":"NaN","id":40637101},{"atb":[[2.9,52.47],[3,49.85],[3.25,44.31]],"id":36120434},{"atl":[[16,4.83],[11,7.25],[8.4,4.89]],"id":36120434},{"spn":5.82,"spf":"NaN","id":36120434},{"atb":[[2,99.7],[1.9,110.77],[1.95,104.94]],"id":40917619},{"atl":[[5.1,8.84],[6.2,13.94],[8.2,10.07]],"id":40917619},{"spn":3.55,"spf":"NaN","id":40917619},{"atb":[[1.16,623.13],[1.21,474.76],[1.11,906.36]],"id":41398505},{"atl":[[2.54,47.08],[2.74,41.67],[2.34,27.05]],"id":41398505},{"spn":1.77,"spf":"NaN","id":41398505},{"atb":[[1.2,498.5],[1.25,398.8],[1.3,332.33]],"id":39183170},{"atl":[[2.54,23.54],[2.74,41.67],[2.94,37.37]],"id":39183170},{"spn":1.92,"spf":"NaN","id":39183170},{"atb":[[3.45,40.69],[3.2,45.31],[2.98,50.35]],"id":35381686},{"atl":[[18.5,4.14],[13.5,5.8],[9.4,4.31]],"id":35381686},{"spn":6.42,"spf":"NaN","id":35381686},{"atb":[[2,99.7],[1.95,104.94],[2.1,90.63]],"id":38554545},{"atl":[[8.6,9.54],[5.3,8.43],[6.6,12.95]],"id":38554545},{"spn":3.7,"spf":"NaN","id":38554545}],"con":true,"img":false}]}
{"op":"mcm","clk":"5346061998","pt":1646175839944,"mc":[{"id":"1.195453632","rc":[{"atb":[[1.2,0],[1.25,0],[1.3,0]],"id":26349442},{"atl":[[2.54,0],[2.74,0],[2.94,0]],"id":26349442},{"atb":[[2.5,0],[2.6,0],[2.7,0]],"id":40637101},{"atl":[[8.6,0],[11.5,0],[6.6,0]],"id":40637101},{"atb":[[2.9,0],[3,0],[3.25,0]],"id":36120434},{"atl":[[16,0],[11,0],[8.4,0]],"id":36120434},{"atb":[[2,0],[1.9,0],[1.95,0]],"id":40917619},{"atl":[[5.1,0],[6.2,0],[8.2,0]],"id":40917619},{"atb":[[1.16,0],[1.21,0],[1.11,0]],"id":41398505},{"atl":[[2.54,0],[2.74,0],[2.34,0]],"id":41398505},{"atb":[[1.2,0],[1.25,0],[1.3,0]],"id":39183170},{"atl":[[2.54,0],[2.74,0],[2.94,0]],"id":39183170},{"atb":[[3.45,0],[3.2,0],[2.98,0]],"id":35381686},{"atl":[[18.5,0],[13.5,0],[9.4,0]],"id":35381686},{"atb":[[2,0],[1.95,0],[2.1,0]],"id":38554545},{"atl":[[8.6,0],[5.3,0],[6.6,0]],"id":38554545}],"con":true,"img":false}]}
{"op":"mcm","clk":"5346062228","pt":1646175844782,"mc":[{"id":"1.195453632","rc":[{"atb":[[1.2,498.5],[1.25,398.8],[1.3,332.33]],"id":26349442},{"atl":[[2.54,23.54],[2.74,41.67],[2.94,37.37]],"id":26349442},{"atb":[[2.5,66.46],[2.6,62.31],[2.7,58.64]],"id":40637101},{"atl":[[8.6,9.54],[11.5,6.9],[6.6,6.47]],"id":40637101},{"atb":[[2.9,52.47],[3,49.85],[3.25,44.31]],"id":36120434},{"atl":[[16,4.83],[11,7.25],[8.4,4.89]],"id":36120434},{"atb":[[2,99.7],[1.9,110.77],[1.95,104.94]],"id":40917619},{"atl":[[5.1,8.84],[6.2,13.94],[8.2,10.07]],"id":40917619},{"atb":[[1.16,623.13],[1.21,474.76],[1.11,906.36]],"id":41398505},{"atl":[[2.54,47.08],[2.74,41.67],[2.34,27.05]],"id":41398505},{"atb":[[1.2,498.5],[1.25,398.8],[1.3,332.33]],"id":39183170},{"atl":[[2.54,23.54],[2.74,41.67],[2.94,37.37]],"id":39183170},{"atb":[[3.45,40.69],[3.2,45.31],[2.98,50.35]],"id":35381686},{"atl":[[18.5,4.14],[13.5,5.8],[9.4,4.31]],"id":35381686},{"atb":[[2,99.7],[1.95,104.94],[2.1,90.63]],"id":38554545},{"atl":[[8.6,9.54],[5.3,8.43],[6.6,12.95]],"id":38554545}],"con":true,"img":false}]}
{"op":"mcm","clk":"5346105186","pt":1646176602708,"mc":[{"id":"1.195453632","marketDefinition":{"bspMarket":true,"turnInPlayEnabled":false,"persistenceEnabled":false,"marketBaseRate":7.0,"eventId":"31272494","eventTypeId":"4339","numberOfWinners":3,"bettingType":"ODDS","marketType":"PLACE","marketTime":"2022-03-02T12:04:00.000Z","suspendTime":"2022-03-02T12:04:00.000Z","bspReconciled":false,"complete":true,"inPlay":false,"crossMatching":false,"runnersVoidable":false,"numberOfActiveRunners":8,"betDelay":0,"status":"OPEN","runners":[{"status":"ACTIVE","sortPriority":1,"id":36120434,"name":"1. Missys Hand"},{"status":"ACTIVE","sortPriority":2,"id":40637101,"name":"2. Odessa Rock"},{"status":"ACTIVE","sortPriority":3,"id":39183170,"name":"3. Sweet Suzie"},{"status":"ACTIVE","sortPriority":4,"id":35381686,"name":"4. Castle Sween"},{"status":"ACTIVE","sortPriority":5,"id":40917619,"name":"5. Kens Crew"},{"status":"ACTIVE","sortPriority":6,"id":38554545,"name":"6. Call Me Harvey"},{"status":"ACTIVE","sortPriority":7,"id":26349442,"name":"7. Inuka"},{"status":"ACTIVE","sortPriority":8,"id":41398505,"name":"8. Afternoon"}],"regulators":["MR_INT"],"venue":"Traralgon","countryCode":"AU","discountAllowed":true,"timezone":"Australia/Sydney","openDate":"2022-03-02T08:31:00.000Z","version":4382425391,"name":"To Be Placed","eventName":"Traralgon (AUS) 2nd Mar"},"rc":[{"atb":[[1.2,498.5],[1.25,398.8],[1.3,332.33]],"id":26349442},{"atl":[[2.54,23.54],[2.74,41.67],[2.94,37.37]],"id":26349442},{"spn":1.92,"spf":"NaN","id":26349442},{"atb":[[2.5,66.46],[2.6,62.31],[2.7,58.64]],"id":40637101},{"atl":[[8.6,9.54],[11.5,6.9],[6.6,6.47]],"id":40637101},{"spn":4.65,"spf":"NaN","id":40637101},{"atb":[[2.9,52.47],[3,49.85],[3.25,44.31]],"id":36120434},{"atl":[[16,4.83],[11,7.25],[8.4,4.89]],"id":36120434},{"spn":5.82,"spf":"NaN","id":36120434},{"atb":[[2,99.7],[1.9,110.77],[1.95,104.94]],"id":40917619},{"atl":[[5.1,8.84],[6.2,13.94],[8.2,10.07]],"id":40917619},{"spn":3.55,"spf":"NaN","id":40917619},{"atb":[[1.16,623.13],[1.21,474.76],[1.11,906.36]],"id":41398505},{"atl":[[2.54,47.08],[2.74,41.67],[2.34,27.05]],"id":41398505},{"spn":1.77,"spf":"NaN","id":41398505},{"atb":[[1.2,498.5],[1.25,398.8],[1.3,332.33]],"id":39183170},{"atl":[[2.54,23.54],[2.74,41.67],[2.94,37.37]],"id":39183170},{"spn":1.92,"spf":"NaN","id":39183170},{"atb":[[3.45,40.69],[3.2,45.31],[2.98,50.35]],"id":35381686},{"atl":[[18.5,4.14],[13.5,5.8],[9.4,4.31]],"id":35381686},{"spn":6.42,"spf":"NaN","id":35381686},{"atb":[[2,99.7],[1.95,104.94],[2.1,90.63]],"id":38554545},{"atl":[[8.6,9.54],[5.3,8.43],[6.6,12.95]],"id":38554545},{"spn":3.7,"spf":"NaN","id":38554545}],"con":true,"img":true}]}
{"op":"mcm","clk":"5346220446","pt":1646178833802,"mc":[{"id":"1.195453632","rc":[{"atb":[[2.5,0],[2.6,0],[2.7,0]],"id":40637101},{"atl":[[8.6,0],[11.5,0],[6.6,0]],"id":40637101},{"spn":"NaN","spf":"NaN","id":40637101},{"atb":[[2.9,0],[3,0],[3.25,0]],"id":36120434},{"atl":[[16,0],[11,0],[8.4,0]],"id":36120434},{"spn":"NaN","spf":"NaN","id":36120434},{"atb":[[2,0],[1.9,0],[1.95,0]],"id":40917619},{"atl":[[5.1,0],[6.2,0],[8.2,0]],"id":40917619},{"spn":"NaN","spf":"NaN","id":40917619},{"atb":[[1.16,0],[1.21,0],[1.11,0]],"id":41398505},{"atl":[[2.54,0],[2.74,0],[2.34,0]],"id":41398505},{"spn":"NaN","spf":"NaN","id":41398505},{"atb":[[1.2,0],[1.25,0],[1.3,0]],"id":39183170},{"atl":[[2.54,0],[2.74,0],[2.94,0]],"id":39183170},{"spn":"NaN","spf":"NaN","id":39183170},{"atb":[[3.45,0],[3.2,0],[2.98,0]],"id":35381686},{"atl":[[18.5,0],[13.5,0],[9.4,0]],"id":35381686},{"spn":"NaN","spf":"NaN","id":35381686},{"atb":[[2,0],[1.95,0],[2.1,0]],"id":38554545},{"atl":[[8.6,0],[5.3,0],[6.6,0]],"id":38554545},{"spn":"NaN","spf":"NaN","id":38554545}],"con":true,"img":false}]}
{"op":"mcm","clk":"5346221440","pt":1646178853461,"mc":[{"id":"1.195453632","rc":[{"atb":[[2.8,55.38],[2.9,52.47],[2.7,58.64]],"id":40637101},{"atl":[[9.8,8.24],[7.8,5.32],[14.5,5.37]],"id":40637101},{"atb":[[3.6,38.34],[3.85,34.98],[3.35,42.42]],"id":36120434},{"atl":[[17.5,4.39],[12.5,3.15],[25,3.02]],"id":36120434},{"atb":[[2,99.7],[1.9,110.77],[1.95,104.94]],"id":40917619},{"atl":[[5.1,8.84],[6.2,13.94],[8.2,10.07]],"id":40917619},{"atb":[[1.16,623.13],[1.21,474.76],[1.11,906.36]],"id":41398505},{"atl":[[2.54,47.08],[2.74,41.67],[2.34,27.05]],"id":41398505},{"atb":[[1.2,498.5],[1.25,398.8],[1.3,332.33]],"id":39183170},{"atl":[[2.54,23.54],[2.74,41.67],[2.94,37.37]],"id":39183170},{"atb":[[3.6,38.34],[3.85,34.98],[3.35,42.42]],"id":35381686},{"atl":[[17.5,4.39],[12.5,3.15],[25,3.02]],"id":35381686},{"atb":[[1.85,117.29],[1.9,110.77],[1.95,104.94]],"id":38554545},{"atl":[[5.6,15.76],[7.2,11.69],[4.6,10.07]],"id":38554545}],"con":true,"img":false}]}
{"op":"mcm","clk":"5346401642","pt":1646182002790,"mc":[{"id":"1.195453632","marketDefinition":{"bspMarket":true,"turnInPlayEnabled":false,"persistenceEnabled":false,"marketBaseRate":7.0,"eventId":"31272494","eventTypeId":"4339","numberOfWinners":3,"bettingType":"ODDS","marketType":"PLACE","marketTime":"2022-03-02T12:04:00.000Z","suspendTime":"2022-03-02T12:04:00.000Z","bspReconciled":false,"complete":true,"inPlay":false,"crossMatching":false,"runnersVoidable":false,"numberOfActiveRunners":8,"betDelay":0,"status":"OPEN","runners":[{"status":"ACTIVE","sortPriority":1,"id":36120434,"name":"1. Missys Hand"},{"status":"ACTIVE","sortPriority":2,"id":40637101,"name":"2. Odessa Rock"},{"status":"ACTIVE","sortPriority":3,"id":39183170,"name":"3. Sweet Suzie"},{"status":"ACTIVE","sortPriority":4,"id":35381686,"name":"4. Castle Sween"},{"status":"ACTIVE","sortPriority":5,"id":40917619,"name":"5. Kens Crew"},{"status":"ACTIVE","sortPriority":6,"id":38554545,"name":"6. Call Me Harvey"},{"status":"ACTIVE","sortPriority":7,"id":26349442,"name":"7. Inuka"},{"status":"ACTIVE","sortPriority":8,"id":41398505,"name":"8. Afternoon"}],"regulators":["MR_INT"],"venue":"Traralgon","countryCode":"AU","discountAllowed":true,"timezone":"Australia/Sydney","openDate":"2022-03-02T08:31:00.000Z","version":4382425391,"name":"To Be Placed","eventName":"Traralgon (AUS) 2nd Mar"},"rc":[{"atb":[[1.2,498.55],[1.25,398.84],[1.3,332.37]],"id":26349442},{"atl":[[2.54,23.54],[2.74,41.67],[2.94,37.38]],"id":26349442},{"spn":1.92,"spf":"NaN","id":26349442},{"atb":[[2.8,55.39],[2.9,52.47],[2.7,58.65]],"id":40637101},{"atl":[[9.8,8.24],[7.8,5.32],[14.5,5.37]],"id":40637101},{"spn":5.35,"spf":"NaN","id":40637101},{"atb":[[3.6,38.34],[3.85,34.98],[3.35,42.43]],"id":36120434},{"atl":[[17.5,4.39],[12.5,3.15],[25,3.02]],"id":36120434},{"spn":8.17,"spf":"NaN","id":36120434},{"atb":[[2,99.71],[1.9,110.79],[1.95,104.95]],"id":40917619},{"atl":[[5.1,8.84],[6.2,13.94],[8.2,10.07]],"id":40917619},{"spn":3.55,"spf":"NaN","id":40917619},{"atb":[[1.16,623.19],[1.21,474.81],[1.11,906.46]],"id":41398505},{"atl":[[2.54,47.08],[2.74,41.67],[2.34,27.05]],"id":41398505},{"spn":1.77,"spf":"NaN","id":41398505},{"atb":[[1.2,498.55],[1.25,398.84],[1.3,332.37]],"id":39183170},{"atl":[[2.54,23.54],[2.74,41.67],[2.94,37.38]],"id":39183170},{"spn":1.92,"spf":"NaN","id":39183170},{"atb":[[3.6,38.34],[3.85,34.98],[3.35,42.43]],"id":35381686},{"atl":[[17.5,4.39],[12.5,3.15],[25,3.02]],"id":35381686},{"spn":8.17,"spf":"NaN","id":35381686},{"atb":[[1.85,117.3],[1.9,110.79],[1.95,104.95]],"id":38554545},{"atl":[[5.6,15.76],[7.2,11.69],[4.6,10.07]],"id":38554545},{"spn":3.27,"spf":"NaN","id":38554545}],"con":true,"img":true}]}
{"op":"mcm","clk":"5346767996","pt":1646187402735,"mc":[{"id":"1.195453632","marketDefinition":{"bspMarket":true,"turnInPlayEnabled":false,"persistenceEnabled":false,"marketBaseRate":7.0,"eventId":"31272494","eventTypeId":"4339","numberOfWinners":3,"bettingType":"ODDS","marketType":"PLACE","marketTime":"2022-03-02T12:04:00.000Z","suspendTime":"2022-03-02T12:04:00.000Z","bspReconciled":false,"complete":true,"inPlay":false,"crossMatching":false,"runnersVoidable":false,"numberOfActiveRunners":8,"betDelay":0,"status":"OPEN","runners":[{"status":"ACTIVE","sortPriority":1,"id":36120434,"name":"1. Missys Hand"},{"status":"ACTIVE","sortPriority":2,"id":40637101,"name":"2. Odessa Rock"},{"status":"ACTIVE","sortPriority":3,"id":39183170,"name":"3. Sweet Suzie"},{"status":"ACTIVE","sortPriority":4,"id":35381686,"name":"4. Castle Sween"},{"status":"ACTIVE","sortPriority":5,"id":40917619,"name":"5. Kens Crew"},{"status":"ACTIVE","sortPriority":6,"id":38554545,"name":"6. Call Me Harvey"},{"status":"ACTIVE","sortPriority":7,"id":26349442,"name":"7. Inuka"},{"status":"ACTIVE","sortPriority":8,"id":41398505,"name":"8. Afternoon"}],"regulators":["MR_INT"],"venue":"Traralgon","countryCode":"AU","discountAllowed":true,"timezone":"Australia/Sydney","openDate":"2022-03-02T08:31:00.000Z","version":4382425391,"name":"To Be Placed","eventName":"Traralgon (AUS) 2nd Mar"},"rc":[{"atb":[[1.2,499.34],[1.25,399.47],[1.3,332.89]],"id":26349442},{"atl":[[2.54,23.58],[2.74,41.74],[2.94,37.43]],"id":26349442},{"spn":1.92,"spf":"NaN","id":26349442},{"atb":[[2.8,55.48],[2.9,52.56],[2.7,58.74]],"id":40637101},{"atl":[[9.8,8.25],[7.8,5.33],[14.5,5.38]],"id":40637101},{"spn":5.35,"spf":"NaN","id":40637101},{"atb":[[3.6,38.4],[3.85,35.04],[3.35,42.49]],"id":36120434},{"atl":[[17.5,4.4],[12.5,3.15],[25,3.02]],"id":36120434},{"spn":8.17,"spf":"NaN","id":36120434},{"atb":[[2,99.86],[1.9,110.96],[1.95,105.12]],"id":40917619},{"atl":[[5.1,8.85],[6.2,13.97],[8.2,10.08]],"id":40917619},{"spn":3.55,"spf":"NaN","id":40917619},{"atb":[[1.16,624.18],[1.21,475.56],[1.11,907.9]],"id":41398505},{"atl":[[2.54,47.16],[2.74,41.74],[2.34,27.1]],"id":41398505},{"spn":1.77,"spf":"NaN","id":41398505},{"atb":[[1.2,499.34],[1.25,399.47],[1.3,332.89]],"id":39183170},{"atl":[[2.54,23.58],[2.74,41.74],[2.94,37.43]],"id":39183170},{"spn":1.92,"spf":"NaN","id":39183170},{"atb":[[3.6,38.4],[3.85,35.04],[3.35,42.49]],"id":35381686},{"atl":[[17.5,4.4],[12.5,3.15],[25,3.02]],"id":35381686},{"spn":8.17,"spf":"NaN","id":35381686},{"atb":[[1.85,117.49],[1.9,110.96],[1.95,105.12]],"id":38554545},{"atl":[[5.6,15.79],[7.2,11.71],[4.6,10.08]],"id":38554545},{"spn":3.27,"spf":"NaN","id":38554545}],"con":true,"img":true}]}
{"op":"mcm","clk":"5347092547","pt":1646192802714,"mc":[{"id":"1.195453632","marketDefinition":{"bspMarket":true,"turnInPlayEnabled":false,"persistenceEnabled":false,"marketBaseRate":7.0,"eventId":"31272494","eventTypeId":"4339","numberOfWinners":3,"bettingType":"ODDS","marketType":"PLACE","marketTime":"2022-03-02T12:04:00.000Z","suspendTime":"2022-03-02T12:04:00.000Z","bspReconciled":false,"complete":true,"inPlay":false,"crossMatching":false,"runnersVoidable":false,"numberOfActiveRunners":8,"betDelay":0,"status":"OPEN","runners":[{"status":"ACTIVE","sortPriority":1,"id":36120434,"name":"1. Missys Hand"},{"status":"ACTIVE","sortPriority":2,"id":40637101,"name":"2. Odessa Rock"},{"status":"ACTIVE","sortPriority":3,"id":39183170,"name":"3. Sweet Suzie"},{"status":"ACTIVE","sortPriority":4,"id":35381686,"name":"4. Castle Sween"},{"status":"ACTIVE","sortPriority":5,"id":40917619,"name":"5. Kens Crew"},{"status":"ACTIVE","sortPriority":6,"id":38554545,"name":"6. Call Me Harvey"},{"status":"ACTIVE","sortPriority":7,"id":26349442,"name":"7. Inuka"},{"status":"ACTIVE","sortPriority":8,"id":41398505,"name":"8. Afternoon"}],"regulators":["MR_INT"],"venue":"Traralgon","countryCode":"AU","discountAllowed":true,"timezone":"Australia/Sydney","openDate":"2022-03-02T08:31:00.000Z","version":4382425391,"name":"To Be Placed","eventName":"Traralgon (AUS) 2nd Mar"},"rc":[{"atb":[[1.2,500.19],[1.25,400.15],[1.3,333.46]],"id":26349442},{"atl":[[2.54,23.62],[2.74,41.81],[2.94,37.5]],"id":26349442},{"spn":1.92,"spf":"NaN","id":26349442},{"atb":[[2.8,55.57],[2.9,52.64],[2.7,58.84]],"id":40637101},{"atl":[[9.8,8.26],[7.8,5.34],[14.5,5.39]],"id":40637101},{"spn":5.35,"spf":"NaN","id":40637101},{"atb":[[3.6,38.47],[3.85,35.09],[3.35,42.57]],"id":36120434},{"atl":[[17.5,4.4],[12.5,3.16],[25,3.03]],"id":36120434},{"spn":8.17,"spf":"NaN","id":36120434},{"atb":[[2,100.03],[1.9,111.15],[1.95,105.3]],"id":40917619},{"atl":[[5.1,8.87],[6.2,13.99],[8.2,10.1]],"id":40917619},{"spn":3.55,"spf":"NaN","id":40917619},{"atb":[[1.16,625.24],[1.21,476.37],[1.11,909.43]],"id":41398505},{"atl":[[2.54,47.24],[2.74,41.81],[2.34,27.14]],"id":41398505},{"spn":1.77,"spf":"NaN","id":41398505},{"atb":[[1.2,500.19],[1.25,400.15],[1.3,333.46]],"id":39183170},{"atl":[[2.54,23.62],[2.74,41.81],[2.94,37.5]],"id":39183170},{"spn":1.92,"spf":"NaN","id":39183170},{"atb":[[3.6,38.47],[3.85,35.09],[3.35,42.57]],"id":35381686},{"atl":[[17.5,4.4],[12.5,3.16],[25,3.03]],"id":35381686},{"spn":8.17,"spf":"NaN","id":35381686},{"atb":[[1.85,117.69],[1.9,111.15],[1.95,105.3]],"id":38554545},{"atl":[[5.6,15.81],[7.2,11.73],[4.6,10.1]],"id":38554545},{"spn":3.27,"spf":"NaN","id":38554545}],"con":true,"img":true}]}
{"op":"mcm","clk":"5347381401","pt":1646198202731,"mc":[{"id":"1.195453632","marketDefinition":{"bspMarket":true,"turnInPlayEnabled":false,"persistenceEnabled":false,"marketBaseRate":7.0,"eventId":"31272494","eventTypeId":"4339","numberOfWinners":3,"bettingType":"ODDS","marketType":"PLACE","marketTime":"2022-03-02T12:04:00.000Z","suspendTime":"2022-03-02T12:04:00.000Z","bspReconciled":false,"complete":true,"inPlay":false,"crossMatching":false,"runnersVoidable":false,"numberOfActiveRunners":8,"betDelay":0,"status":"OPEN","runners":[{"status":"ACTIVE","sortPriority":1,"id":36120434,"name":"1. Missys Hand"},{"status":"ACTIVE","sortPriority":2,"id":40637101,"name":"2. Odessa Rock"},{"status":"ACTIVE","sortPriority":3,"id":39183170,"name":"3. Sweet Suzie"},{"status":"ACTIVE","sortPriority":4,"id":35381686,"name":"4. Castle Sween"},{"status":"ACTIVE","sortPriority":5,"id":40917619,"name":"5. Kens Crew"},{"status":"ACTIVE","sortPriority":6,"id":38554545,"name":"6. Call Me Harvey"},{"status":"ACTIVE","sortPriority":7,"id":26349442,"name":"7. Inuka"},{"status":"ACTIVE","sortPriority":8,"id":41398505,"name":"8. Afternoon"}],"regulators":["MR_INT"],"venue":"Traralgon","countryCode":"AU","discountAllowed":true,"timezone":"Australia/Sydney","openDate":"2022-03-02T08:31:00.000Z","version":4382425391,"name":"To Be Placed","eventName":"Traralgon (AUS) 2nd Mar"},"rc":[{"atb":[[1.2,500],[1.25,400],[1.3,333.33]],"id":26349442},{"atl":[[2.54,23.61],[2.74,41.79],[2.94,37.48]],"id":26349442},{"spn":1.92,"spf":"NaN","id":26349442},{"atb":[[2.8,55.55],[2.9,52.62],[2.7,58.82]],"id":40637101},{"atl":[[9.8,8.26],[7.8,5.34],[14.5,5.38]],"id":40637101},{"spn":5.35,"spf":"NaN","id":40637101},{"atb":[[3.6,38.46],[3.85,35.08],[3.35,42.55]],"id":36120434},{"atl":[[17.5,4.4],[12.5,3.16],[25,3.03]],"id":36120434},{"spn":8.17,"spf":"NaN","id":36120434},{"atb":[[2,100],[1.9,111.11],[1.95,105.26]],"id":40917619},{"atl":[[5.1,8.86],[6.2,13.98],[8.2,10.1]],"id":40917619},{"spn":3.55,"spf":"NaN","id":40917619},{"atb":[[1.16,625],[1.21,476.18],[1.11,909.09]],"id":41398505},{"atl":[[2.54,47.22],[2.74,41.79],[2.34,27.13]],"id":41398505},{"spn":1.77,"spf":"NaN","id":41398505},{"atb":[[1.2,500],[1.25,400],[1.3,333.33]],"id":39183170},{"atl":[[2.54,23.61],[2.74,41.79],[2.94,37.48]],"id":39183170},{"spn":1.92,"spf":"NaN","id":39183170},{"atb":[[3.6,38.46],[3.85,35.08],[3.35,42.55]],"id":35381686},{"atl":[[17.5,4.4],[12.5,3.16],[25,3.03]],"id":35381686},{"spn":8.17,"spf":"NaN","id":35381686},{"atb":[[1.85,117.64],[1.9,111.11],[1.95,105.26]],"id":38554545},{"atl":[[5.6,15.81],[7.2,11.72],[4.6,10.1]],"id":38554545},{"spn":3.27,"spf":"NaN","id":38554545}],"con":true,"img":true}]}
{"op":"mcm","clk":"5347849098","pt":1646209002736,"mc":[{"id":"1.195453632","marketDefinition":{"bspMarket":true,"turnInPlayEnabled":false,"persistenceEnabled":false,"marketBaseRate":7.0,"eventId":"31272494","eventTypeId":"4339","numberOfWinners":3,"bettingType":"ODDS","marketType":"PLACE","marketTime":"2022-03-02T12:04:00.000Z","suspendTime":"2022-03-02T12:04:00.000Z","bspReconciled":false,"complete":true,"inPlay":false,"crossMatching":false,"runnersVoidable":false,"numberOfActiveRunners":8,"betDelay":0,"status":"OPEN","runners":[{"status":"ACTIVE","sortPriority":1,"id":36120434,"name":"1. Missys Hand"},{"status":"ACTIVE","sortPriority":2,"id":40637101,"name":"2. Odessa Rock"},{"status":"ACTIVE","sortPriority":3,"id":39183170,"name":"3. Sweet Suzie"},{"status":"ACTIVE","sortPriority":4,"id":35381686,"name":"4. Castle Sween"},{"status":"ACTIVE","sortPriority":5,"id":40917619,"name":"5. Kens Crew"},{"status":"ACTIVE","sortPriority":6,"id":38554545,"name":"6. Call Me Harvey"},{"status":"ACTIVE","sortPriority":7,"id":26349442,"name":"7. Inuka"},{"status":"ACTIVE","sortPriority":8,"id":41398505,"name":"8. Afternoon"}],"regulators":["MR_INT"],"venue":"Traralgon","countryCode":"AU","discountAllowed":true,"timezone":"Australia/Sydney","openDate":"2022-03-02T08:31:00.000Z","version":4382425391,"name":"To Be Placed","eventName":"Traralgon (AUS) 2nd Mar"},"rc":[{"atb":[[1.2,499.86],[1.25,399.89],[1.3,333.24]],"id":26349442},{"atl":[[2.54,23.6],[2.74,41.78],[2.94,37.47]],"id":26349442},{"spn":1.92,"spf":"NaN","id":26349442},{"atb":[[2.8,55.54],[2.9,52.61],[2.7,58.81]],"id":40637101},{"atl":[[9.8,8.26],[7.8,5.34],[14.5,5.38]],"id":40637101},{"spn":5.35,"spf":"NaN","id":40637101},{"atb":[[3.6,38.44],[3.85,35.07],[3.35,42.54]],"id":36120434},{"atl":[[17.5,4.4],[12.5,3.16],[25,3.02]],"id":36120434},{"spn":8.17,"spf":"NaN","id":36120434},{"atb":[[2,99.97],[1.9,111.08],[1.95,105.23]],"id":40917619},{"atl":[[5.1,8.86],[6.2,13.98],[8.2,10.09]],"id":40917619},{"spn":3.55,"spf":"NaN","id":40917619},{"atb":[[1.16,624.83],[1.21,476.05],[1.11,908.84]],"id":41398505},{"atl":[[2.54,47.21],[2.74,41.78],[2.34,27.12]],"id":41398505},{"spn":1.77,"spf":"NaN","id":41398505},{"atb":[[1.2,499.86],[1.25,399.89],[1.3,333.24]],"id":39183170},{"atl":[[2.54,23.6],[2.74,41.78],[2.94,37.47]],"id":39183170},{"spn":1.92,"spf":"NaN","id":39183170},{"atb":[[3.6,38.44],[3.85,35.07],[3.35,42.54]],"id":35381686},{"atl":[[17.5,4.4],[12.5,3.16],[25,3.02]],"id":35381686},{"spn":8.17,"spf":"NaN","id":35381686},{"atb":[[1.85,117.61],[1.9,111.08],[1.95,105.23]],"id":38554545},{"atl":[[5.6,15.8],[7.2,11.72],[4.6,10.09]],"id":38554545},{"spn":3.27,"spf":"NaN","id":38554545}],"con":true,"img":true}]}
{"op":"mcm","clk":"5348133281","pt":1646214402747,"mc":[{"id":"1.195453632","marketDefinition":{"bspMarket":true,"turnInPlayEnabled":false,"persistenceEnabled":false,"marketBaseRate":7.0,"eventId":"31272494","eventTypeId":"4339","numberOfWinners":3,"bettingType":"ODDS","marketType":"PLACE","marketTime":"2022-03-02T12:04:00.000Z","suspendTime":"2022-03-02T12:04:00.000Z","bspReconciled":false,"complete":true,"inPlay":false,"crossMatching":false,"runnersVoidable":false,"numberOfActiveRunners":8,"betDelay":0,"status":"OPEN","runners":[{"status":"ACTIVE","sortPriority":1,"id":36120434,"name":"1. Missys Hand"},{"status":"ACTIVE","sortPriority":2,"id":40637101,"name":"2. Odessa Rock"},{"status":"ACTIVE","sortPriority":3,"id":39183170,"name":"3. Sweet Suzie"},{"status":"ACTIVE","sortPriority":4,"id":35381686,"name":"4. Castle Sween"},{"status":"ACTIVE","sortPriority":5,"id":40917619,"name":"5. Kens Crew"},{"status":"ACTIVE","sortPriority":6,"id":38554545,"name":"6. Call Me Harvey"},{"status":"ACTIVE","sortPriority":7,"id":26349442,"name":"7. Inuka"},{"status":"ACTIVE","sortPriority":8,"id":41398505,"name":"8. Afternoon"}],"regulators":["MR_INT"],"venue":"Traralgon","countryCode":"AU","discountAllowed":true,"timezone":"Australia/Sydney","openDate":"2022-03-02T08:31:00.000Z","version":4382425391,"name":"To Be Placed","eventName":"Traralgon (AUS) 2nd Mar"},"rc":[{"atb":[[1.2,499.07],[1.25,399.25],[1.3,332.71]],"id":26349442},{"atl":[[2.54,23.57],[2.74,41.71],[2.94,37.41]],"id":26349442},{"spn":1.92,"spf":"NaN","id":26349442},{"atb":[[2.8,55.45],[2.9,52.53],[2.7,58.71]],"id":40637101},{"atl":[[9.8,8.25],[7.8,5.33],[14.5,5.37]],"id":40637101},{"spn":5.35,"spf":"NaN","id":40637101},{"atb":[[3.6,38.38],[3.85,35.02],[3.35,42.47]],"id":36120434},{"atl":[[17.5,4.39],[12.5,3.15],[25,3.02]],"id":36120434},{"spn":8.17,"spf":"NaN","id":36120434},{"atb":[[2,99.81],[1.9,110.9],[1.95,105.06]],"id":40917619},{"atl":[[5.1,8.85],[6.2,13.96],[8.2,10.08]],"id":40917619},{"spn":3.55,"spf":"NaN","id":40917619},{"atb":[[1.16,623.84],[1.21,475.3],[1.11,907.4]],"id":41398505},{"atl":[[2.54,47.13],[2.74,41.71],[2.34,27.08]],"id":41398505},{"spn":1.77,"spf":"NaN","id":41398505},{"atb":[[1.2,499.07],[1.25,399.25],[1.3,332.71]],"id":39183170},{"atl":[[2.54,23.57],[2.74,41.71],[2.94,37.41]],"id":39183170},{"spn":1.92,"spf":"NaN","id":39183170},{"atb":[[3.6,38.38],[3.85,35.02],[3.35,42.47]],"id":35381686},{"atl":[[17.5,4.39],[12.5,3.15],[25,3.02]],"id":35381686},{"spn":8.17,"spf":"NaN","id":35381686},{"atb":[[1.85,117.42],[1.9,110.9],[1.95,105.06]],"id":38554545},{"atl":[[5.6,15.78],[7.2,11.7],[4.6,10.08]],"id":38554545},{"spn":3.27,"spf":"NaN","id":38554545}],"con":true,"img":true}]}
{"op":"mcm","clk":"5348401188","pt":1646217308962,"mc":[{"id":"1.195453632","rc":[{"atb":[[1.2,499.07],[1.25,399.25],[1.3,332.71],[1.33,84.77],[1.31,142.24]],"id":26349442},{"atl":[[2.72,25.34],[2.54,23.57],[2.74,41.71],[3.35,18.52],[2.94,37.41]],"id":26349442},{"spn":1.93,"spf":"NaN","id":26349442},{"atb":[[2.8,55.45],[2.72,22.49],[2.9,52.53],[2.84,23.69],[2.7,58.71]],"id":40637101},{"atl":[[9.8,8.25],[12.5,3.79],[7.8,5.33],[14,2.97],[14.5,5.37]],"id":40637101},{"spn":5.35,"spf":"NaN","id":40637101},{"atb":[[3.6,38.38],[3.85,35.02],[3.35,42.47],[3.7,16.14],[3.4,16.65]],"id":36120434},{"atl":[[17.5,4.39],[20,2.72],[22,2.72],[12.5,3.15],[25,3.02]],"id":36120434},{"spn":8.17,"spf":"NaN","id":36120434},{"atb":[[2,99.81],[2.02,42.74],[1.74,50.94],[1.9,110.9],[1.95,105.06]],"id":40917619},{"atl":[[5.1,8.85],[6.2,13.96],[8.2,10.08],[7.4,5.38],[6,8.71]],"id":40917619},{"spn":3.56,"spf":"NaN","id":40917619},{"atb":[[1.16,623.84],[1.21,475.3],[1.11,907.4],[1.22,92.42],[1.17,235.62]],"id":41398505},{"atl":[[2.54,47.13],[2.74,41.71],[2.52,26.35],[2.28,34.06],[2.34,27.08]],"id":41398505},{"spn":1.75,"spf":"NaN","id":41398505},{"atb":[[1.2,499.07],[1.25,399.25],[1.3,332.71],[1.32,140.63],[1.31,130.09]],"id":39183170},{"atl":[[2.72,25.34],[2.92,21],[2.54,23.57],[2.74,41.71],[2.94,37.41]],"id":39183170},{"spn":1.93,"spf":"NaN","id":39183170},{"atb":[[3.6,38.38],[3.85,35.02],[3.35,42.47],[4.4,12.82],[3.75,15.63]],"id":35381686},{"atl":[[17.5,4.39],[22,2.72],[24,2.72],[12.5,3.15],[25,3.02]],"id":35381686},{"spn":8.45,"spf":"NaN","id":35381686},{"atb":[[1.99,45.41],[1.85,117.42],[1.9,110.9],[1.91,43.41],[1.95,105.06]],"id":38554545},{"atl":[[5.6,15.78],[7.2,11.7],[4.6,10.08],[5.5,9.68],[7,6.58]],"id":38554545},{"spn":3.29,"spf":"NaN","id":38554545}],"con":true,"img":false}]}
{"op":"mcm","clk":"5348409071","pt":1646217393050,"mc":[{"id":"1.195453632","rc":[{"atl":[[2.72,0]],"id":26349442},{"atb":[[2.72,0],[2.84,0]],"id":40637101},{"atb":[[3.7,0],[3.4,0]],"id":36120434},{"atl":[[2.52,0]],"id":41398505},{"atl":[[2.72,0]],"id":39183170},{"atb":[[3.75,0]],"id":35381686},{"atb":[[1.91,0]],"id":38554545}],"con":true,"img":false}]}
{"op":"mcm","clk":"5348409076","pt":1646217393154,"mc":[{"id":"1.195453632","rc":[{"atl":[[2.52,25.34]],"id":26349442},{"atb":[[2.82,22.49],[2.92,23.69]],"id":40637101},{"atb":[[3.9,16.14],[3.65,16.65]],"id":36120434},{"atl":[[2.32,26.35]],"id":41398505},{"atl":[[2.52,25.34]],"id":39183170},{"atb":[[3.9,15.63]],"id":35381686},{"atb":[[1.96,43.41]],"id":38554545}],"con":true,"img":false}]}
{"op":"mcm","clk":"5348580928","pt":1646219042311,"mc":[{"id":"1.195453632","rc":[{"atb":[[1.2,499.1],[1.25,399.28],[1.33,84.78],[1.3,332.73],[1.31,142.24]],"id":26349442},{"atl":[[2.54,23.57],[2.74,41.72],[2.52,25.34],[3.35,18.53],[2.94,37.42]],"id":26349442},{"spn":1.92,"spf":"NaN","id":26349442},{"atb":[[2.82,22.49],[2.8,55.45],[2.92,23.69],[2.9,105.06],[2.7,58.72]],"id":40637101},{"atl":[[38,2.7],[9.8,8.25],[12.5,3.79],[7.8,5.33],[14,2.97],[14.5,5.37]],"id":40637101},{"spn":5.36,"spf":"NaN","id":40637101},{"atb":[[3.6,38.39],[3.85,35.02],[3.35,42.47],[3.9,16.14],[3.65,16.65]],"id":36120434},{"atl":[[17.5,4.39],[20,2.72],[22,2.72],[12.5,3.15],[25,3.02]],"id":36120434},{"spn":8.2,"spf":"NaN","id":36120434},{"atb":[[2,99.82],[2.02,42.74],[1.74,50.94],[1.9,110.91],[1.95,105.07]],"id":40917619},{"atl":[[5.1,8.85],[6.2,13.96],[8.2,10.08],[7.4,5.38],[6,8.72]],"id":40917619},{"atb":[[1.16,623.87],[1.21,475.33],[1.11,907.45],[1.22,92.42],[1.17,235.63]],"id":41398505},{"atl":[[2.54,47.13],[2.32,26.35],[2.74,41.72],[2.28,34.06],[2.34,27.08]],"id":41398505},{"atb":[[1.2,499.1],[1.25,399.28],[1.32,140.64],[1.3,332.73],[1.33,140.64],[1.31,130.1]],"id":39183170},{"atl":[[2.92,21],[2.54,23.57],[6.4,18.52],[2.74,41.72],[2.52,25.34],[2.94,37.42]],"id":39183170},{"spn":1.92,"spf":"NaN","id":39183170},{"atb":[[3.6,38.39],[3.85,35.02],[3.35,42.47],[3.7,37.04],[4.4,12.82],[3.9,15.63]],"id":35381686},{"atl":[[17.5,4.39],[22,2.72],[24,2.72],[12.5,3.15],[25,3.02],[28,3.7]],"id":35381686},{"atb":[[1.99,45.41],[1.85,117.43],[1.9,110.91],[1.96,43.42],[1.95,105.07]],"id":38554545},{"atl":[[5.6,15.78],[7.2,11.7],[4.6,10.08],[5.5,9.69],[7,6.58]],"id":38554545}],"con":true,"img":false}]}
{"op":"mcm","clk":"5348580937","pt":1646219042413,"mc":[{"id":"1.195453632","rc":[{"atb":[[1.32,312.5]],"id":26349442},{"atl":[[3.05,48.78]],"id":26349442},{"atb":[[1.41,199.62]],"id":40917619},{"atl":[[5,8.85]],"id":40917619},{"atl":[[3,50]],"id":41398505},{"atb":[[2,45.41]],"id":38554545},{"atl":[[5.4,20.16]],"id":38554545}],"con":true,"img":false}]}
{"op":"mcm","clk":"5348580947","pt":1646219042518,"mc":[{"id":"1.195453632","rc":[{"atb":[[1.8,70.04]],"id":36120434},{"atl":[[12,3.16]],"id":36120434}],"con":true,"img":false}]}
{"op":"mcm","clk":"5348583917","pt":1646219072868,"mc":[{"id":"1.195453632","rc":[{"atl":[[7.4,0],[13,3.13]],"id":40917619},{"atb":[[3.9,0],[2.78,23.27]],"id":35381686},{"atb":[[1.57,69.32],[1.96,0]],"id":38554545}],"con":true,"img":false}]}
{"op":"mcm","clk":"5348583926","pt":1646219072961,"mc":[{"id":"1.195453632","rc":[{"atb":[[1.31,0]],"id":26349442},{"atl":[[12.5,0],[14,0]],"id":40637101},{"atl":[[20,0],[22,0]],"id":36120434},{"atl":[[6,0]],"id":40917619},{"atb":[[1.31,0]],"id":39183170},{"atb":[[4.4,0]],"id":35381686},{"atb":[[1.99,0]],"id":38554545}],"con":true,"img":false}]}
{"op":"mcm","clk":"5348583932","pt":1646219073065,"mc":[{"id":"1.195453632","rc":[{"atb":[[1.26,142.24]],"id":26349442},{"atl":[[21,3.79],[23,2.97]],"id":40637101},{"atl":[[32,2.72],[34,2.72]],"id":36120434},{"atl":[[8,8.72]],"id":40917619},{"atb":[[1.26,130.1]],"id":39183170},{"atb":[[3.9,12.82]],"id":35381686},{"atb":[[1.96,45.41]],"id":38554545}],"con":true,"img":false}]}
{"op":"mcm","clk":"5348583945","pt":1646219073170,"mc":[{"id":"1.195453632","rc":[{"atb":[[2,0],[1.96,149.58]],"id":38554545}],"con":true,"img":false}]}
{"op":"mcm","clk":"5348586733","pt":1646219094867,"mc":[{"id":"1.195453632","rc":[{"atl":[[2.72,25.61],[3.35,0]],"id":26349442},{"atb":[[3.65,0]],"id":36120434},{"atb":[[1.32,0]],"id":39183170},{"atl":[[22,0]],"id":35381686},{"atl":[[5.5,0]],"id":38554545}],"con":true,"img":false}]}
{"op":"mcm","clk":"5348586743","pt":1646219094972,"mc":[{"id":"1.195453632","rc":[{"atb":[[3.4,16.65]],"id":36120434},{"atb":[[1.33,0],[1.31,322.58],[1.34,140.64]],"id":39183170},{"atl":[[15,2.72]],"id":35381686},{"atl":[[5.3,9.69]],"id":38554545}],"con":true,"img":false}]}
{"op":"mcm","clk":"5348588947","pt":1646219113227,"mc":[{"id":"1.195453632","rc":[{"atb":[[2.2,32.24]],"id":40637101},{"spn":7.95,"spf":"NaN","id":36120434},{"atb":[[1.96,39.26]],"id":40917619},{"spn":3.51,"spf":"NaN","id":40917619},{"spn":1.93,"spf":"NaN","id":39183170},{"spn":8.2,"spf":"NaN","id":35381686},{"atl":[[5.5,8.78]],"id":38554545},{"spn":3.28,"spf":"NaN","id":38554545}],"con":true,"img":false}]}
{"op":"mcm","clk":"5348588960","pt":1646219113287,"mc":[{"id":"1.195453632","rc":[{"atl":[[2.72,0],[2.52,0]],"id":26349442},{"atb":[[2.82,0]],"id":40637101},{"atb":[[1.74,0]],"id":40917619},{"atl":[[2.52,0]],"id":39183170},{"atl":[[24,0]],"id":35381686},{"atl":[[7,0]],"id":38554545}],"con":true,"img":false}]}
{"op":"mcm","clk":"5348588977","pt":1646219113387,"mc":[{"id":"1.195453632","rc":[{"atl":[[2.72,25.34],[2.92,25.61]],"id":26349442},{"atl":[[2.72,25.34]],"id":39183170},{"atl":[[17,2.72]],"id":35381686}],"con":true,"img":false}]}
{"op":"mcm","clk":"5348589045","pt":1646219113801,"mc":[{"id":"1.195453632","rc":[{"atl":[[2.32,0]],"id":41398505}],"con":true,"img":false}]}
{"op":"mcm","clk":"5348589059","pt":1646219113907,"mc":[{"id":"1.195453632","rc":[{"atl":[[2.52,26.35]],"id":41398505}],"con":true,"img":false}]}
{"op":"mcm","clk":"5348590974","pt":1646219127624,"mc":[{"id":"1.195453632","rc":[{"atl":[[21,0]],"id":40637101},{"atb":[[1.96,104.17]],"id":38554545}],"con":true,"img":false}]}
{"op":"mcm","clk":"5348590987","pt":1646219127737,"mc":[{"id":"1.195453632","rc":[{"atl":[[11,3.79]],"id":40637101},{"atb":[[1.97,45.41]],"id":38554545}],"con":true,"img":false}]}
{"op":"mcm","clk":"5348591016","pt":1646219127944,"mc":[{"id":"1.195453632","rc":[{"atb":[[1.98,102.04],[1.96,0]],"id":38554545}],"con":true,"img":false}]}
{"op":"mcm","clk":"5348591503","pt":1646219131648,"mc":[{"id":"1.195453632","rc":[{"atb":[[1.31,0],[1.35,285.71]],"id":39183170}],"con":true,"img":false}]}
{"op":"mcm","clk":"5348594064","pt":1646219151153,"mc":[{"id":"1.195453632","rc":[{"atl":[[2.72,0]],"id":26349442},{"atl":[[23,0]],"id":40637101},{"atl":[[32,0]],"id":36120434},{"atl":[[8,0]],"id":40917619},{"atl":[[2.72,0]],"id":39183170},{"atb":[[2.78,0]],"id":35381686}],"con":true,"img":false}]}
{"op":"mcm","clk":"5348594075","pt":1646219151260,"mc":[{"id":"1.195453632","rc":[{"atl":[[2.52,25.34]],"id":26349442},{"atl":[[12.5,2.97]],"id":40637101},{"atl":[[24,2.72]],"id":36120434},{"atl":[[6,8.72]],"id":40917619},{"atl":[[2.52,25.34]],"id":39183170},{"atb":[[3,23.27]],"id":35381686}],"con":true,"img":false}]}
{"op":"mcm","clk":"5348596466","pt":1646219171088,"mc":[{"id":"1.195453632","rc":[{"atl":[[34,0]],"id":36120434},{"atl":[[10.5,3.96],[13,0]],"id":40917619},{"atb":[[1.36,82.91],[1.26,0],[1.34,0]],"id":39183170},{"atb":[[1.97,0],[1.57,0]],"id":38554545}],"con":true,"img":false}]}
{"op":"mcm","clk":"5348596477","pt":1646219171190,"mc":[{"id":"1.195453632","rc":[{"atl":[[24,5.45]],"id":36120434},{"atb":[[1.31,130.1]],"id":39183170},{"atb":[[1.99,45.41],[1.63,69.32]],"id":38554545}],"con":true,"img":false}]}
{"op":"mcm","clk":"5348596491","pt":1646219171294,"mc":[{"id":"1.195453632","rc":[{"atb":[[1.98,0],[1.96,104.17]],"id":38554545}],"con":true,"img":false}]}
{"op":"mcm","clk":"5348598818","pt":1646219191224,"mc":[{"id":"1.195453632","rc":[{"atb":[[2.72,22.49],[2.2,0]],"id":40637101},{"spn":1.94,"spf":"NaN","id":39183170},{"atb":[[1.99,0]],"id":38554545}],"con":true,"img":false}]}
{"op":"mcm","clk":"5348598829","pt":1646219191329,"mc":[{"id":"1.195453632","rc":[{"atb":[[1.97,45.41]],"id":38554545}],"con":true,"img":false}]}
{"op":"mcm","clk":"5348600717","pt":1646219207166,"mc":[{"id":"1.195453632","rc":[{"atb":[[1.98,102.04],[1.96,0]],"id":38554545}],"con":true,"img":false}]}
{"op":"mcm","clk":"5348601314","pt":1646219212343,"mc":[{"id":"1.195453632","rc":[{"atl":[[12.5,0]],"id":40637101}],"con":true,"img":false}]}
{"op":"mcm","clk":"5348601328","pt":1646219212445,"mc":[{"id":"1.195453632","rc":[{"atl":[[13.5,2.97]],"id":40637101}],"con":true,"img":false}]}
{"op":"mcm","clk":"5348604082","pt":1646219235484,"mc":[{"id":"1.195453632","rc":[{"atl":[[11,0]],"id":40637101}],"con":true,"img":false}]}
{"op":"mcm","clk":"5348604092","pt":1646219235589,"mc":[{"id":"1.195453632","rc":[{"atl":[[12.5,3.79]],"id":40637101}],"con":true,"img":false}]}
{"op":"mcm","clk":"5348606459","pt":1646219256337,"mc":[{"id":"1.195453632","rc":[{"atb":[[1.97,0]],"id":38554545},{"spn":3.29,"spf":"NaN","id":38554545}],"con":true,"img":false}]}
{"op":"mcm","clk":"5348606473","pt":1646219256439,"mc":[{"id":"1.195453632","rc":[{"atb":[[1.99,45.41]],"id":38554545}],"con":true,"img":false}]}
{"op":"mcm","clk":"5348606484","pt":1646219256543,"mc":[{"id":"1.195453632","rc":[{"atb":[[1.98,0],[1.96,104.17]],"id":38554545}],"con":true,"img":false}]}
{"op":"mcm","clk":"5348608813","pt":1646219274856,"mc":[{"id":"1.195453632","rc":[{"atl":[[24,2.72]],"id":36120434},{"atb":[[1.99,0]],"id":38554545}],"con":true,"img":false}]}
{"op":"mcm","clk":"5348608825","pt":1646219274962,"mc":[{"id":"1.195453632","rc":[{"atl":[[29,2.72]],"id":36120434},{"atb":[[1.97,45.41]],"id":38554545}],"con":true,"img":false}]}
{"op":"mcm","clk":"5348610932","pt":1646219291476,"mc":[{"id":"1.195453632","rc":[{"atb":[[1.98,102.04]],"id":38554545}],"con":true,"img":false}]}
{"op":"mcm","clk":"5348610948","pt":1646219291579,"mc":[{"id":"1.195453632","rc":[{"atb":[[1.96,0]],"id":38554545}],"con":true,"img":false}]}
{"op":"mcm","clk":"5348615551","pt":1646219329235,"mc":[{"id":"1.195453632","rc":[{"atb":[[1.97,0]],"id":38554545}],"con":true,"img":false}]}
{"op":"mcm","clk":"5348615562","pt":1646219329386,"mc":[{"id":"1.195453632","rc":[{"atb":[[1.99,45.41]],"id":38554545}],"con":true,"img":false}]}
{"op":"mcm","clk":"5348615575","pt":1646219329447,"mc":[{"id":"1.195453632","rc":[{"atb":[[1.98,0],[1.96,104.17]],"id":38554545}],"con":true,"img":false}]}
{"op":"mcm","clk":"5348618520","pt":1646219353391,"mc":[{"id":"1.195453632","rc":[{"atb":[[2.72,0]],"id":40637101},{"atb":[[1.99,0]],"id":38554545}],"con":true,"img":false}]}
{"op":"mcm","clk":"5348618530","pt":1646219353496,"mc":[{"id":"1.195453632","rc":[{"atb":[[2.82,22.49]],"id":40637101},{"atb":[[1.97,45.41]],"id":38554545}],"con":true,"img":false}]}
{"op":"mcm","clk":"5348619712","pt":1646219363685,"mc":[{"id":"1.195453632","rc":[{"atb":[[1.98,102.04],[1.96,0]],"id":38554545}],"con":true,"img":false}]}
{"op":"mcm","clk":"5348620955","pt":1646219374218,"mc":[{"id":"1.195453632","rc":[{"atl":[[13.5,0]],"id":40637101},{"atl":[[29,0]],"id":36120434},{"atb":[[1.31,0]],"id":39183170}],"con":true,"img":false}]}
{"op":"mcm","clk":"5348620965","pt":1646219374317,"mc":[{"id":"1.195453632","rc":[{"atl":[[14,2.97]],"id":40637101},{"atl":[[24,5.45]],"id":36120434},{"atb":[[1.26,130.1]],"id":39183170}],"con":true,"img":false}]}
{"op":"mcm","clk":"5348626100","pt":1646219417788,"mc":[{"id":"1.195453632","rc":[{"atl":[[2.52,0]],"id":41398505},{"atb":[[1.97,0]],"id":38554545}],"con":true,"img":false}]}
{"op":"mcm","clk":"5348626110","pt":1646219417884,"mc":[{"id":"1.195453632","rc":[{"atl":[[2.32,26.35]],"id":41398505},{"atb":[[1.99,45.41]],"id":38554545}],"con":true,"img":false}]}
{"op":"mcm","clk":"5348626120","pt":1646219417999,"mc":[{"id":"1.195453632","rc":[{"atb":[[1.98,0],[1.96,104.17]],"id":38554545}],"con":true,"img":false}]}
{"op":"mcm","clk":"5348629018","pt":1646219441835,"mc":[{"id":"1.195453632","rc":[{"atl":[[10.5,0]],"id":40917619},{"atb":[[1.99,0]],"id":38554545}],"con":true,"img":false}]}
{"op":"mcm","clk":"5348629030","pt":1646219441943,"mc":[{"id":"1.195453632","rc":[{"atl":[[11.5,3.96]],"id":40917619},{"atb":[[1.97,45.41]],"id":38554545}],"con":true,"img":false}]}
{"op":"mcm","clk":"5348630115","pt":1646219451321,"mc":[{"id":"1.195453632","rc":[{"atb":[[1.98,102.04],[1.96,0]],"id":38554545}],"con":true,"img":false}]}
{"op":"mcm","clk":"5348636591","pt":1646219503802,"mc":[{"id":"1.195453632","rc":[{"atb":[[1.97,0]],"id":38554545}],"con":true,"img":false}]}
{"op":"mcm","clk":"5348636604","pt":1646219503911,"mc":[{"id":"1.195453632","rc":[{"atb":[[1.99,45.41]],"id":38554545}],"con":true,"img":false}]}
{"op":"mcm","clk":"5348636610","pt":1646219504008,"mc":[{"id":"1.195453632","rc":[{"atb":[[1.98,0],[1.96,104.17]],"id":38554545}],"con":true,"img":false}]}
{"op":"mcm","clk":"5348638806","pt":1646219521068,"mc":[{"id":"1.195453632","rc":[{"atl":[[12.5,0]],"id":40637101},{"atb":[[1.99,0]],"id":38554545}],"con":true,"img":false}]}
{"op":"mcm","clk":"5348638819","pt":1646219521171,"mc":[{"id":"1.195453632","rc":[{"atl":[[14.5,9.17]],"id":40637101},{"atb":[[1.97,45.41]],"id":38554545}],"con":true,"img":false}]}
{"op":"mcm","clk":"5348640209","pt":1646219531555,"mc":[{"id":"1.195453632","rc":[{"atl":[[2.92,0]],"id":26349442},{"atl":[[14,0]],"id":40637101},{"atl":[[5.5,0]],"id":38554545}],"con":true,"img":false}]}
{"op":"mcm","clk":"5348640222","pt":1646219531654,"mc":[{"id":"1.195453632","rc":[{"atl":[[2.72,25.61]],"id":26349442},{"atl":[[16,2.97]],"id":40637101},{"atl":[[5.3,18.47]],"id":38554545}],"con":true,"img":false}]}
{"op":"mcm","clk":"5348640852","pt":1646219536571,"mc":[{"id":"1.195453632","rc":[{"atb":[[1.98,102.04],[1.96,0]],"id":38554545}],"con":true,"img":false}]}
{"op":"mcm","clk":"5348645441","pt":1646219575720,"mc":[{"id":"1.195453632","rc":[{"atb":[[1.97,0]],"id":38554545}],"con":true,"img":false}]}
{"op":"mcm","clk":"5348645454","pt":1646219575817,"mc":[{"id":"1.195453632","rc":[{"atb":[[1.99,45.41]],"id":38554545}],"con":true,"img":false}]}
{"op":"mcm","clk":"5348645466","pt":1646219575930,"mc":[{"id":"1.195453632","rc":[{"atb":[[1.98,0],[1.96,104.17]],"id":38554545}],"con":true,"img":false}]}
{"op":"mcm","clk":"5348645492","pt":1646219576092,"mc":[{"id":"1.195453632","rc":[{"atb":[[2,100],[1.96,0]],"id":38554545}],"con":true,"img":false}]}
{"op":"mcm","clk":"5348647943","pt":1646219600542,"mc":[{"id":"1.195453632","rc":[{"atl":[[16,0]],"id":40637101},{"atl":[[6,0]],"id":40917619}],"con":true,"img":false}]}
{"op":"mcm","clk":"5348647953","pt":1646219600645,"mc":[{"id":"1.195453632","rc":[{"atl":[[14,2.97]],"id":40637101},{"atl":[[8,8.72]],"id":40917619}],"con":true,"img":false}]}
{"op":"mcm","clk":"5348651753","pt":1646219637240,"mc":[{"id":"1.195453632","rc":[{"atl":[[2.92,0]],"id":39183170},{"atb":[[1.99,0]],"id":38554545},{"spn":3.3,"spf":"NaN","id":38554545}],"con":true,"img":false}]}
{"op":"mcm","clk":"5348651762","pt":1646219637294,"mc":[{"id":"1.195453632","rc":[{"atl":[[2.72,21]],"id":39183170},{"atb":[[2.02,45.41]],"id":38554545}],"con":true,"img":false}]}
{"op":"mcm","clk":"5348651776","pt":1646219637406,"mc":[{"id":"1.195453632","rc":[{"atb":[[2,0],[1.96,104.17]],"id":38554545}],"con":true,"img":false}]}
{"op":"mcm","clk":"5348653806","pt":1646219654959,"mc":[{"id":"1.195453632","rc":[{"atb":[[1.27,370.37],[1.32,0]],"id":26349442},{"atl":[[3.05,0]],"id":26349442},{"atb":[[2.9,52.53],[2.94,23.7]],"id":40637101},{"atb":[[1.41,0],[1.47,199.64]],"id":40917619},{"atl":[[3,0],[2.76,56.82]],"id":41398505},{"atb":[[1.34,294.12],[1.35,0]],"id":39183170},{"atb":[[3.7,0],[3.65,37.74]],"id":35381686}],"con":true,"img":false}]}
{"op":"mcm","clk":"5348653815","pt":1646219655057,"mc":[{"id":"1.195453632","rc":[{"atl":[[2.8,50.97]],"id":26349442}],"con":true,"img":false}]}
{"op":"mcm","clk":"5348653854","pt":1646219655373,"mc":[{"id":"1.195453632","rc":[{"atb":[[1.33,0]],"id":26349442},{"atb":[[1.36,0]],"id":39183170},{"atb":[[2.02,0]],"id":38554545}],"con":true,"img":false}]}
{"op":"mcm","clk":"5348653864","pt":1646219655429,"mc":[{"id":"1.195453632","rc":[{"atb":[[1.31,84.78]],"id":26349442},{"atb":[[1.35,82.91]],"id":39183170},{"atb":[[1.97,45.41]],"id":38554545}],"con":true,"img":false}]}
{"op":"mcm","clk":"5348655284","pt":1646219668599,"mc":[{"id":"1.195453632","rc":[{"atb":[[1.98,102.04],[1.96,0]],"id":38554545}],"con":true,"img":false}]}
{"op":"mcm","clk":"5348655801","pt":1646219673202,"mc":[{"id":"1.195453632","rc":[{"atl":[[2.8,0],[2.92,51.24]],"id":26349442},{"atl":[[2.88,53.19],[2.76,0]],"id":41398505},{"atl":[[5.2,20.16],[5.4,0]],"id":38554545}],"con":true,"img":false}]}
{"op":"mcm","clk":"5348657211","pt":1646219686038,"mc":[{"id":"1.195453632","rc":[{"atb":[[1.27,0],[1.32,312.5]],"id":26349442},{"atb":[[1.36,277.78],[1.34,0]],"id":39183170},{"atb":[[3.95,33.9],[3.65,0]],"id":35381686}],"con":true,"img":false}]}
{"op":"mcm","clk":"5348660091","pt":1646219712427,"mc":[{"id":"1.195453632","rc":[{"atl":[[2.72,0]],"id":26349442},{"spn":1.92,"spf":"NaN","id":26349442},{"spn":5.37,"spf":"NaN","id":40637101},{"atl":[[24,2.72]],"id":36120434},{"atl":[[8,0],[11.5,0]],"id":40917619},{"atl":[[2.72,0]],"id":39183170},{"spn":8.22,"spf":"NaN","id":35381686},{"atl":[[5.3,9.69]],"id":38554545},{"spn":3.29,"spf":"NaN","id":38554545}],"con":true,"img":false}]}
{"op":"mcm","clk":"5348660102","pt":1646219712446,"mc":[{"id":"1.195453632","rc":[{"atl":[[2.9,25.61]],"id":26349442},{"atl":[[30,2.72]],"id":36120434},{"atl":[[10,3.96],[6,8.72]],"id":40917619},{"atl":[[2.92,21]],"id":39183170},{"atl":[[5.5,8.78]],"id":38554545}],"con":true,"img":false}]}
{"op":"mcm","clk":"5348662333","pt":1646219730381,"mc":[{"id":"1.195453632","rc":[{"atl":[[24,0]],"id":36120434}],"con":true,"img":false}]}
{"op":"mcm","clk":"5348662348","pt":1646219730491,"mc":[{"id":"1.195453632","rc":[{"atl":[[28,2.72]],"id":36120434}],"con":true,"img":false}]}
{"op":"mcm","clk":"5348668037","pt":1646219780092,"mc":[{"id":"1.195453632","rc":[{"atb":[[1.31,0]],"id":26349442},{"atl":[[14,0]],"id":40637101},{"atl":[[28,0]],"id":36120434},{"atl":[[2.32,0]],"id":41398505},{"atb":[[1.35,0]],"id":39183170},{"atb":[[3.9,0]],"id":35381686},{"atb":[[1.97,0]],"id":38554545},{"atl":[[5.3,0]],"id":38554545}],"con":true,"img":false}]}
{"op":"mcm","clk":"5348668047","pt":1646219780186,"mc":[{"id":"1.195453632","rc":[{"atb":[[1.33,84.78]],"id":26349442},{"atl":[[17.5,2.97]],"id":40637101},{"atl":[[20,2.72]],"id":36120434},{"atl":[[2.52,26.35]],"id":41398505},{"atb":[[1.37,82.91]],"id":39183170},{"atb":[[4,12.82]],"id":35381686},{"atb":[[1.99,45.41]],"id":38554545},{"atl":[[5.1,9.69]],"id":38554545}],"con":true,"img":false}]}
{"op":"mcm","clk":"5348668062","pt":1646219780246,"mc":[{"id":"1.195453632","rc":[{"atb":[[1.32,0],[1.31,322.58]],"id":26349442},{"atb":[[1.36,0],[1.31,322.58]],"id":39183170},{"atb":[[3.95,0],[3.9,34.48]],"id":35381686},{"atb":[[1.98,0],[1.96,104.17]],"id":38554545}],"con":true,"img":false}]}
{"op":"mcm","clk":"5348668096","pt":1646219780452,"mc":[{"id":"1.195453632","rc":[{"atb":[[1.31,0],[1.34,294.12]],"id":26349442},{"atb":[[1.37,353.18],[1.31,0]],"id":39183170},{"atb":[[3.95,33.9],[3.9,0]],"id":35381686},{"atb":[[2,100],[1.96,0]],"id":38554545}],"con":true,"img":false}]}
{"op":"mcm","clk":"5348668107","pt":1646219780564,"mc":[{"id":"1.195453632","rc":[{"atb":[[1.37,82.91],[1.31,322.58]],"id":39183170}],"con":true,"img":false}]}
{"op":"mcm","clk":"5348668119","pt":1646219780662,"mc":[{"id":"1.195453632","rc":[{"atb":[[1.37,353.18],[1.31,0]],"id":39183170}],"con":true,"img":false}]}
{"op":"mcm","clk":"5348668127","pt":1646219780766,"mc":[{"id":"1.195453632","rc":[{"atb":[[1.37,82.91],[1.31,322.58]],"id":39183170}],"con":true,"img":false}]}
{"op":"mcm","clk":"5348669583","pt":1646219793204,"mc":[{"id":"1.195453632","rc":[{"atb":[[1.32,312.5],[1.34,0]],"id":26349442},{"atb":[[2.9,105.06],[2.94,0]],"id":40637101},{"atb":[[1.41,204.89],[1.47,0]],"id":40917619},{"atl":[[2.88,0],[3,50]],"id":41398505},{"atb":[[3.95,0],[3.7,37.04]],"id":35381686}],"con":true,"img":false}]}
{"op":"mcm","clk":"5348670386","pt":1646219797589,"mc":[{"id":"1.195453632","rc":[{"atl":[[30,0]],"id":36120434},{"atb":[[1.37,0],[1.26,0]],"id":39183170},{"atb":[[4,0]],"id":35381686}],"con":true,"img":false}]}
{"op":"mcm","clk":"5348670399","pt":1646219797688,"mc":[{"id":"1.195453632","rc":[{"atl":[[21,2.72]],"id":36120434},{"atb":[[1.32,82.91],[1.31,452.68]],"id":39183170},{"atb":[[3.9,12.82]],"id":35381686}],"con":true,"img":false}]}
{"op":"mcm","clk":"5348680949","pt":1646219810538,"mc":[{"id":"1.195453632","rc":[{"atb":[[1.33,303.03],[1.31,130.1]],"id":39183170}],"con":true,"img":false}]}
{"op":"mcm","clk":"5348686132","pt":1646219851612,"mc":[{"id":"1.195453632","rc":[{"spn":1.92,"spf":"NaN","id":26349442},{"spn":5.36,"spf":"NaN","id":40637101},{"atb":[[1.32,0]],"id":39183170},{"spn":1.92,"spf":"NaN","id":39183170},{"spn":8.2,"spf":"NaN","id":35381686},{"atb":[[1.99,0]],"id":38554545},{"spn":3.3,"spf":"NaN","id":38554545}],"con":true,"img":false}]}
{"op":"mcm","clk":"5348686149","pt":1646219851718,"mc":[{"id":"1.195453632","rc":[{"atb":[[1.34,82.91]],"id":39183170},{"atb":[[2.02,45.41]],"id":38554545}],"con":true,"img":false}]}
{"op":"mcm","clk":"5348686164","pt":1646219851819,"mc":[{"id":"1.195453632","rc":[{"atb":[[1.33,0],[1.32,312.5]],"id":39183170},{"atb":[[2,0],[1.96,104.17]],"id":38554545}],"con":true,"img":false}]}
{"op":"mcm","clk":"5348686175","pt":1646219851924,"mc":[{"id":"1.195453632","rc":[{"atb":[[1.32,0],[1.35,130.1]],"id":39183170},{"atb":[[2.04,96.15]],"id":38554545}],"con":true,"img":false}]}
{"op":"mcm","clk":"5348686190","pt":1646219852025,"mc":[{"id":"1.195453632","rc":[{"atb":[[1.96,0]],"id":38554545}],"con":true,"img":false}]}
{"op":"mcm","clk":"5348693873","pt":1646219912494,"mc":[{"id":"1.195453632","rc":[{"atb":[[1.31,0],[1.34,0]],"id":39183170},{"spn":1.93,"spf":"NaN","id":39183170},{"atb":[[2.02,0]],"id":38554545},{"spn":3.32,"spf":"NaN","id":38554545}],"con":true,"img":false}]}
{"op":"mcm","clk":"5348693888","pt":1646219912599,"mc":[{"id":"1.195453632","rc":[{"atb":[[1.36,82.91],[1.26,130.1],[1.31,322.58]],"id":39183170},{"atb":[[2.06,45.41],[1.96,104.17]],"id":38554545}],"con":true,"img":false}]}
{"op":"mcm","clk":"5348693904","pt":1646219912705,"mc":[{"id":"1.195453632","rc":[{"atb":[[1.35,0]],"id":39183170},{"atb":[[2.04,0]],"id":38554545}],"con":true,"img":false}]}
{"op":"mcm","clk":"5348693919","pt":1646219912807,"mc":[{"id":"1.195453632","rc":[{"atb":[[1.35,285.71]],"id":39183170},{"atb":[[2.04,96.15]],"id":38554545}],"con":true,"img":false}]}
{"op":"mcm","clk":"5348693927","pt":1646219912911,"mc":[{"id":"1.195453632","rc":[{"atb":[[1.31,0]],"id":39183170},{"atb":[[1.96,0]],"id":38554545}],"con":true,"img":false}]}
{"op":"mcm","clk":"5348700294","pt":1646219963420,"mc":[{"id":"1.195453632","rc":[{"atb":[[2.94,1.66]],"id":40637101},{"atb":[[3.95,1.66]],"id":36120434},{"atb":[[2.04,1.66]],"id":40917619},{"atb":[[3.95,1.66]],"id":35381686},{"atb":[[2.08,1.66]],"id":38554545}],"con":true,"img":false}]}
{"op":"mcm","clk":"5348701281","pt":1646219970754,"mc":[{"id":"1.195453632","rc":[{"atl":[[14.5,5.37]],"id":40637101},{"atl":[[21,0]],"id":36120434}],"con":true,"img":false}]}
{"op":"mcm","clk":"5348701299","pt":1646219970846,"mc":[{"id":"1.195453632","rc":[{"atl":[[16.5,3.79]],"id":40637101},{"atl":[[23,2.72]],"id":36120434}],"con":true,"img":false}]}
{"op":"mcm","clk":"5348704953","pt":1646219998733,"mc":[{"id":"1.195453632","marketDefinition":{"bspMarket":true,"turnInPlayEnabled":false,"persistenceEnabled":false,"marketBaseRate":7.0,"eventId":"31272494","eventTypeId":"4339","numberOfWinners":3,"bettingType":"ODDS","marketType":"PLACE","marketTime":"2022-03-02T12:04:00.000Z","suspendTime":"2022-03-02T12:04:00.000Z","bspReconciled":false,"complete":true,"inPlay":false,"crossMatching":true,"runnersVoidable":false,"numberOfActiveRunners":8,"betDelay":0,"status":"OPEN","runners":[{"status":"ACTIVE","sortPriority":1,"id":36120434,"name":"1. Missys Hand"},{"status":"ACTIVE","sortPriority":2,"id":40637101,"name":"2. Odessa Rock"},{"status":"ACTIVE","sortPriority":3,"id":39183170,"name":"3. Sweet Suzie"},{"status":"ACTIVE","sortPriority":4,"id":35381686,"name":"4. Castle Sween"},{"status":"ACTIVE","sortPriority":5,"id":40917619,"name":"5. Kens Crew"},{"status":"ACTIVE","sortPriority":6,"id":38554545,"name":"6. Call Me Harvey"},{"status":"ACTIVE","sortPriority":7,"id":26349442,"name":"7. Inuka"},{"status":"ACTIVE","sortPriority":8,"id":41398505,"name":"8. Afternoon"}],"regulators":["MR_INT"],"venue":"Traralgon","countryCode":"AU","discountAllowed":true,"timezone":"Australia/Sydney","openDate":"2022-03-02T08:31:00.000Z","version":4382425391,"name":"To Be Placed","eventName":"Traralgon (AUS) 2nd Mar"},"rc":[],"con":true,"img":false}]}
{"op":"mcm","clk":"5348705890","pt":1646220006000,"mc":[{"id":"1.195453632","rc":[{"spn":5.37,"spf":"NaN","id":40637101},{"atb":[[3.4,0]],"id":36120434},{"spn":7.97,"spf":"NaN","id":36120434},{"atl":[[10,0]],"id":40917619},{"spn":3.52,"spf":"NaN","id":40917619},{"spn":1.94,"spf":"NaN","id":39183170},{"spn":8.22,"spf":"NaN","id":35381686},{"spn":3.34,"spf":"NaN","id":38554545}],"con":true,"img":false}]}
{"op":"mcm","clk":"5348705901","pt":1646220006112,"mc":[{"id":"1.195453632","rc":[{"atb":[[3.65,16.65]],"id":36120434},{"atl":[[11,3.96]],"id":40917619}],"con":true,"img":false}]}
{"op":"mcm","clk":"5348719331","pt":1646220112556,"mc":[{"id":"1.195453632","rc":[{"atl":[[23,0]],"id":36120434}],"con":true,"img":false}]}
{"op":"mcm","clk":"5348719343","pt":1646220112659,"mc":[{"id":"1.195453632","rc":[{"atl":[[24,2.72]],"id":36120434}],"con":true,"img":false}]}
{"op":"mcm","clk":"5348721480","pt":1646220129076,"mc":[{"id":"1.195453632","rc":[{"atl":[[20,0]],"id":36120434},{"atl":[[2.52,0]],"id":41398505}],"con":true,"img":false}]}
{"op":"mcm","clk":"5348721493","pt":1646220129184,"mc":[{"id":"1.195453632","rc":[{"atl":[[23,2.72]],"id":36120434},{"atl":[[2.32,26.35]],"id":41398505}],"con":true,"img":false}]}
{"op":"mcm","clk":"5348722042","pt":1646220133479,"mc":[{"id":"1.195453632","rc":[{"atl":[[16.5,10.24],[38,0]],"id":40637101},{"atb":[[1.8,0],[1.98,70.04]],"id":36120434},{"atl":[[2.88,53.19],[3,0]],"id":41398505},{"atl":[[6.4,0],[5.3,23.26]],"id":39183170}],"con":true,"img":false}]}
{"op":"mcm","clk":"5348724749","pt":1646220154939,"mc":[{"id":"1.195453632","rc":[{"atb":[[2.96,3.82]],"id":40637101},{"atb":[[2.06,7.07]],"id":40917619},{"atb":[[1.39,19.24]],"id":39183170},{"atb":[[2.1,6.82]],"id":38554545}],"con":true,"img":false}]}
{"op":"mcm","clk":"5348725817","pt":1646220163520,"mc":[{"id":"1.195453632","rc":[{"atb":[[2.94,0]],"id":40637101},{"atb":[[2.04,0]],"id":40917619},{"atb":[[2.08,0]],"id":38554545}],"con":true,"img":false}]}
{"op":"mcm","clk":"5348725838","pt":1646220163735,"mc":[{"id":"1.195453632","rc":[{"atb":[[2.98,1.66]],"id":40637101},{"atb":[[2.08,1.66]],"id":40917619},{"atb":[[2.12,1.66]],"id":38554545}],"con":true,"img":false}]}
{"op":"mcm","clk":"5348726160","pt":1646220166139,"mc":[{"id":"1.195453632","rc":[{"atb":[[2.28,30.23]],"id":40637101},{"atl":[[11,0],[6,0]],"id":40917619},{"atl":[[2.32,0]],"id":41398505}],"con":true,"img":false}]}
{"op":"mcm","clk":"5348726171","pt":1646220166243,"mc":[{"id":"1.195453632","rc":[{"atb":[[2.82,0]],"id":40637101},{"atl":[[8,8.72],[12,3.96]],"id":40917619},{"atl":[[2.52,26.35]],"id":41398505}],"con":true,"img":false}]}
{"op":"mcm","clk":"5348726778","pt":1646220171225,"mc":[{"id":"1.195453632","rc":[{"atb":[[2.96,8.07]],"id":40637101}],"con":true,"img":false}]}
{"op":"mcm","clk":"5348726791","pt":1646220171324,"mc":[{"id":"1.195453632","rc":[{"atb":[[1.39,40.6]],"id":39183170}],"con":true,"img":false}]}
{"op":"mcm","clk":"5348726905","pt":1646220172161,"mc":[{"id":"1.195453632","rc":[{"atb":[[2.1,14.39]],"id":38554545}],"con":true,"img":false}]}
{"op":"mcm","clk":"5348726946","pt":1646220172429,"mc":[{"id":"1.195453632","rc":[{"atb":[[2.06,14.93]],"id":40917619}],"con":true,"img":false}]}
{"op":"mcm","clk":"5348728057","pt":1646220181676,"mc":[{"id":"1.195453632","rc":[{"atl":[[16.5,6.45]],"id":40637101},{"spn":5.39,"spf":"NaN","id":40637101},{"spn":3.54,"spf":"NaN","id":40917619},{"spn":1.95,"spf":"NaN","id":39183170},{"spn":3.36,"spf":"NaN","id":38554545}],"con":true,"img":false}]}
{"op":"mcm","clk":"5348728072","pt":1646220181777,"mc":[{"id":"1.195453632","rc":[{"atl":[[11,3.79]],"id":40637101}],"con":true,"img":false}]}
{"op":"mcm","clk":"5348730144","pt":1646220199004,"mc":[{"id":"1.195453632","rc":[{"atl":[[17.5,0]],"id":40637101}],"con":true,"img":false}]}
{"op":"mcm","clk":"5348730152","pt":1646220199067,"mc":[{"id":"1.195453632","rc":[{"atl":[[12,2.97]],"id":40637101}],"con":true,"img":false}]}
{"op":"mcm","clk":"5348732005","pt":1646220214423,"mc":[{"id":"1.195453632","rc":[{"atl":[[2.28,0]],"id":41398505},{"atb":[[3,0],[3.4,17.26]],"id":35381686}],"con":true,"img":false}]}
{"op":"mcm","clk":"5348732019","pt":1646220214530,"mc":[{"id":"1.195453632","rc":[{"atl":[[2.32,34.06]],"id":41398505}],"con":true,"img":false}]}
{"op":"mcm","clk":"5348733222","pt":1646220224329,"mc":[{"id":"1.195453632","rc":[{"atb":[[2.16,70.04]],"id":36120434},{"atl":[[2.88,0],[3,50]],"id":41398505}],"con":true,"img":false}]}
{"op":"mcm","clk":"5348733234","pt":1646220224420,"mc":[{"id":"1.195453632","rc":[{"atb":[[1.98,0]],"id":36120434}],"con":true,"img":false}]}
{"op":"mcm","clk":"5348733889","pt":1646220230026,"mc":[{"id":"1.195453632","rc":[{"atl":[[8,0]],"id":40917619},{"atb":[[1.26,0]],"id":39183170}],"con":true,"img":false}]}
{"op":"mcm","clk":"5348733902","pt":1646220230116,"mc":[{"id":"1.195453632","rc":[{"atl":[[6,8.72]],"id":40917619},{"atb":[[1.31,130.1]],"id":39183170}],"con":true,"img":false}]}
{"op":"mcm","clk":"5348736098","pt":1646220248979,"mc":[{"id":"1.195453632","rc":[{"spn":1.77,"spf":"NaN","id":41398505},{"atl":[[5.5,0],[6.6,6.58]],"id":38554545}],"con":true,"img":false}]}
{"op":"mcm","clk":"5348738069","pt":1646220266187,"mc":[{"id":"1.195453632","rc":[{"atb":[[1.26,0]],"id":26349442}],"con":true,"img":false}]}
{"op":"mcm","clk":"5348738085","pt":1646220266362,"mc":[{"id":"1.195453632","rc":[{"atb":[[1.31,142.24]],"id":26349442}],"con":true,"img":false}]}
{"op":"mcm","clk":"5348743268","pt":1646220314948,"mc":[{"id":"1.195453632","rc":[{"atl":[[5.5,8.78]],"id":38554545}],"con":true,"img":false}]}
{"op":"mcm","clk":"5348743275","pt":1646220315053,"mc":[{"id":"1.195453632","rc":[{"atl":[[6.6,0]],"id":38554545}],"con":true,"img":false}]}
{"op":"mcm","clk":"5348744942","pt":1646220331383,"mc":[{"id":"1.195453632","rc":[{"atl":[[12,0]],"id":40917619}],"con":true,"img":false}]}
{"op":"mcm","clk":"5348744946","pt":1646220331489,"mc":[{"id":"1.195453632","rc":[{"atl":[[10.5,3.96]],"id":40917619}],"con":true,"img":false}]}
{"op":"mcm","clk":"5348748609","pt":1646220366518,"mc":[{"id":"1.195453632","rc":[{"atb":[[1.31,0]],"id":26349442}],"con":true,"img":false}]}
{"op":"mcm","clk":"5348748621","pt":1646220366621,"mc":[{"id":"1.195453632","rc":[{"atb":[[1.26,142.24]],"id":26349442}],"con":true,"img":false}]}
{"op":"mcm","clk":"5348752091","pt":1646220398199,"mc":[{"id":"1.195453632","rc":[{"atl":[[23,0],[24,0]],"id":36120434},{"atb":[[1.31,0]],"id":39183170}],"con":true,"img":false}]}
{"op":"mcm","clk":"5348752101","pt":1646220398304,"mc":[{"id":"1.195453632","rc":[{"atl":[[26,2.72],[29,2.72]],"id":36120434},{"atb":[[1.26,130.1]],"id":39183170}],"con":true,"img":false}]}
{"op":"mcm","clk":"5348757423","pt":1646220433290,"mc":[{"id":"1.195453632","rc":[{"atl":[[10.5,0]],"id":40917619}],"con":true,"img":false}]}
{"op":"mcm","clk":"5348757457","pt":1646220433505,"mc":[{"id":"1.195453632","rc":[{"atl":[[11.5,3.96]],"id":40917619}],"con":true,"img":false}]}
{"op":"mcm","clk":"5348765564","pt":1646220486448,"mc":[{"id":"1.195453632","rc":[{"atl":[[29,0]],"id":36120434}],"con":true,"img":false}]}
{"op":"mcm","clk":"5348765573","pt":1646220486503,"mc":[{"id":"1.195453632","rc":[{"atl":[[24,2.72]],"id":36120434}],"con":true,"img":false}]}
{"op":"mcm","clk":"5348770285","pt":1646220535923,"mc":[{"id":"1.195453632","rc":[{"atl":[[6,0]],"id":40917619}],"con":true,"img":false}]}
{"op":"mcm","clk":"5348770294","pt":1646220536027,"mc":[{"id":"1.195453632","rc":[{"atl":[[8,8.72]],"id":40917619}],"con":true,"img":false}]}
{"op":"mcm","clk":"5348776214","pt":1646220599587,"mc":[{"id":"1.195453632","rc":[{"atl":[[8,0]],"id":40917619}],"con":true,"img":false}]}
{"op":"mcm","clk":"5348776224","pt":1646220599697,"mc":[{"id":"1.195453632","rc":[{"atl":[[6,8.72]],"id":40917619}],"con":true,"img":false}]}
{"op":"mcm","clk":"5348778804","pt":1646220623027,"mc":[{"id":"1.195453632","rc":[{"atb":[[1.26,0]],"id":39183170}],"con":true,"img":false}]}
{"op":"mcm","clk":"5348778818","pt":1646220623130,"mc":[{"id":"1.195453632","rc":[{"atb":[[1.31,130.1]],"id":39183170}],"con":true,"img":false}]}
{"op":"mcm","clk":"5348782604","pt":1646220661081,"mc":[{"id":"1.195453632","rc":[{"atl":[[24,0]],"id":36120434}],"con":true,"img":false}]}
{"op":"mcm","clk":"5348782613","pt":1646220661173,"mc":[{"id":"1.195453632","rc":[{"atl":[[30,2.72]],"id":36120434}],"con":true,"img":false}]}
{"op":"mcm","clk":"5348788789","pt":1646220708296,"mc":[{"id":"1.195453632","rc":[{"atb":[[1.26,0]],"id":26349442}],"con":true,"img":false}]}
{"op":"mcm","clk":"5348788800","pt":1646220708400,"mc":[{"id":"1.195453632","rc":[{"atb":[[1.31,142.24]],"id":26349442}],"con":true,"img":false}]}
{"op":"mcm","clk":"5348794347","pt":1646220752164,"mc":[{"id":"1.195453632","rc":[{"atl":[[30,0]],"id":36120434}],"con":true,"img":false}]}
{"op":"mcm","clk":"5348794361","pt":1646220752236,"mc":[{"id":"1.195453632","rc":[{"atl":[[24,2.72]],"id":36120434}],"con":true,"img":false}]}
{"op":"mcm","clk":"5348796087","pt":1646220766431,"mc":[{"id":"1.195453632","rc":[{"atb":[[1.31,0]],"id":26349442}],"con":true,"img":false}]}
{"op":"mcm","clk":"5348796099","pt":1646220766538,"mc":[{"id":"1.195453632","rc":[{"atb":[[1.26,142.24]],"id":26349442}],"con":true,"img":false}]}
{"op":"mcm","clk":"5348804573","pt":1646220837823,"mc":[{"id":"1.195453632","rc":[{"atb":[[1.31,0]],"id":39183170}],"con":true,"img":false}]}
{"op":"mcm","clk":"5348804589","pt":1646220837922,"mc":[{"id":"1.195453632","rc":[{"atb":[[1.26,130.1]],"id":39183170}],"con":true,"img":false}]}
{"op":"mcm","clk":"5348805463","pt":1646220845134,"mc":[{"id":"1.195453632","rc":[{"atb":[[1.33,236.3],[1.29,250],[1.31,241.94],[1.35,57.14]],"id":26349442},{"atl":[[2.72,43.6],[2.64,12.2],[2.68,29.76],[2.76,71.02]],"id":26349442},{"atb":[[2.9,170.85],[2.98,26.91],[2.94,38.66],[3.05,9.76]],"id":40637101},{"atl":[[16,3.33],[17,4.69],[18,7.35],[15,1.43]],"id":40637101},{"atb":[[2.3,15.38],[2.22,61.48],[2.18,105.93],[2.26,39.68]],"id":36120434},{"atl":[[8,2.86],[9.2,15.24],[8.8,9.62],[8.4,6.76]],"id":36120434},{"atb":[[1.83,90.36],[1.81,154.32],[1.85,58.82],[1.87,22.99]],"id":40917619},{"atl":[[3.85,43.86],[3.55,7.84],[3.65,18.87],[3.75,27.27]],"id":40917619},{"atb":[[1.2,250],[1.18,250],[1.16,873.87],[1.22,183.33]],"id":41398505},{"atl":[[2,50],[1.98,20.41],[2.04,72.12],[2.08,115.74]],"id":41398505},{"atb":[[1.33,151.52],[1.29,250],[1.31,241.94],[1.35,342.85]],"id":39183170},{"atl":[[6.2,14.42],[5.7,4.26],[6.6,22.32],[5.9,10.2]],"id":39183170},{"atb":[[4,6.67],[3.7,83.34],[3.8,26.79],[3.9,30.06]],"id":35381686},{"atl":[[11,2],[12,4.55],[13,6.25],[14,9.62]],"id":35381686},{"atb":[[2.04,216.34],[2.12,46.3],[2.16,17.24],[2.08,69.44]],"id":38554545},{"atl":[[3.85,26.32],[3.95,42.37],[3.65,7.55],[3.75,18.18]],"id":38554545}],"con":true,"img":false}]}
{"op":"mcm","clk":"5348805480","pt":1646220845340,"mc":[{"id":"1.195453632","rc":[{"atl":[[8.6,9.62],[12,0]],"id":36120434},{"atl":[[5,0],[3.65,46.14]],"id":40917619}],"con":true,"img":false}]}
{"op":"mcm","clk":"5348805875","pt":1646220848385,"mc":[{"id":"1.195453632","rc":[{"atb":[[2.96,4.24]],"id":40637101},{"atb":[[2.1,7.57]],"id":38554545}],"con":true,"img":false}]}
{"op":"mcm","clk":"5348806131","pt":1646220850429,"mc":[{"id":"1.195453632","rc":[{"atl":[[3.65,18.87],[3.75,63.63]],"id":40917619},{"atl":[[6.6,7.05]],"id":38554545}],"con":true,"img":false}]}
{"op":"mcm","clk":"5348806149","pt":1646220850529,"mc":[{"id":"1.195453632","rc":[{"atl":[[2.52,0]],"id":26349442},{"atb":[[3.65,0]],"id":36120434},{"atl":[[2.52,0]],"id":39183170},{"atb":[[3.4,0]],"id":35381686},{"atl":[[17,0]],"id":35381686},{"atl":[[5.5,0]],"id":38554545}],"con":true,"img":false}]}
{"op":"mcm","clk":"5348806162","pt":1646220850634,"mc":[{"id":"1.195453632","rc":[{"atl":[[2.7,25.34]],"id":26349442},{"atb":[[3.4,16.65]],"id":36120434},{"atl":[[2.72,25.34]],"id":39183170},{"atb":[[3,17.26]],"id":35381686},{"atl":[[18.5,2.72]],"id":35381686}],"con":true,"img":false}]}
{"op":"mcm","clk":"5348806213","pt":1646220850961,"mc":[{"id":"1.195453632","rc":[{"atb":[[1.33,478.24]],"id":26349442},{"atb":[[2.9,118.32],[2.98,53.83]],"id":40637101},{"atb":[[1.36,234.43],[1.35,57.14]],"id":39183170},{"atb":[[3.7,46.3],[3.8,62.5]],"id":35381686},{"atb":[[2.04,120.19],[2.08,138.88]],"id":38554545}],"con":true,"img":false}]}
{"op":"mcm","clk":"5348806230","pt":1646220851163,"mc":[{"id":"1.195453632","rc":[{"atb":[[1.32,0]],"id":26349442}],"con":true,"img":false}]}
{"op":"mcm","clk":"5348806573","pt":1646220853965,"mc":[{"id":"1.195453632","rc":[{"atb":[[1.38,19.75]],"id":26349442},{"atb":[[2.16,23.71]],"id":38554545}],"con":true,"img":false}]}
{"op":"mcm","clk":"5348806588","pt":1646220854070,"mc":[{"id":"1.195453632","rc":[{"atb":[[3.05,13.42]],"id":40637101}],"con":true,"img":false}]}
{"op":"mcm","clk":"5348807078","pt":1646220858068,"mc":[{"id":"1.195453632","rc":[{"atl":[[2.92,0],[2.78,56.18]],"id":26349442},{"atl":[[3,0],[2.76,56.82]],"id":41398505}],"con":true,"img":false}]}
{"op":"mcm","clk":"5348807313","pt":1646220860458,"mc":[{"id":"1.195453632","rc":[{"atl":[[2.9,0]],"id":26349442},{"atl":[[12,0]],"id":40637101},{"atb":[[2.74,22.97],[3.4,0]],"id":36120434},{"atl":[[9,5.45],[26,0]],"id":36120434},{"atb":[[1.96,0],[1.65,57.99]],"id":40917619}],"con":true,"img":false}]}
{"op":"mcm","clk":"5348807327","pt":1646220860562,"mc":[{"id":"1.195453632","rc":[{"atl":[[2.92,25.61]],"id":26349442},{"atl":[[13.5,2.97]],"id":40637101}],"con":true,"img":false}]}
{"op":"mcm","clk":"5348807355","pt":1646220860885,"mc":[{"id":"1.195453632","rc":[{"atl":[[15,0],[15.5,1.38]],"id":40637101},{"atb":[[2.3,0],[1.98,76.78],[2.22,0],[2.26,0],[2.1,18.18],[2.18,0],[2.16,0]],"id":36120434},{"atb":[[1.81,24.69],[1.87,0]],"id":40917619},{"atl":[[5.3,0],[5.7,0],[5.9,24.49]],"id":39183170}],"con":true,"img":false}]}
{"op":"mcm","clk":"5348807603","pt":1646220863091,"mc":[{"id":"1.195453632","rc":[{"atb":[[2.98,52.17]],"id":40637101},{"atb":[[3.95,0]],"id":35381686},{"atb":[[2.12,44.64]],"id":38554545}],"con":true,"img":false}]}
{"op":"mcm","clk":"5348807632","pt":1646220863313,"mc":[{"id":"1.195453632","rc":[{"atb":[[3.1,1.66]],"id":40637101},{"atb":[[4.1,1.66]],"id":35381686},{"atb":[[2.18,1.66]],"id":38554545}],"con":true,"img":false}]}
{"op":"mcm","clk":"5348808061","pt":1646220866553,"mc":[{"id":"1.195453632","rc":[{"atb":[[1.85,0]],"id":40917619}],"con":true,"img":false}]}
{"op":"mcm","clk":"5348808088","pt":1646220866757,"mc":[{"id":"1.195453632","rc":[{"atb":[[1.83,0]],"id":40917619}],"con":true,"img":false}]}
{"op":"mcm","clk":"5348808291","pt":1646220868487,"mc":[{"id":"1.195453632","rc":[{"atb":[[2.96,0]],"id":40637101},{"atb":[[2.1,0]],"id":38554545}],"con":true,"img":false}]}
{"op":"mcm","clk":"5348808541","pt":1646220870480,"mc":[{"id":"1.195453632","rc":[{"atb":[[1.33,393.46]],"id":26349442},{"atb":[[2.06,0]],"id":38554545}],"con":true,"img":false}]}
{"op":"mcm","clk":"5348808555","pt":1646220870589,"mc":[{"id":"1.195453632","rc":[{"atb":[[1.36,84.78]],"id":26349442},{"atb":[[2.1,45.41]],"id":38554545}],"con":true,"img":false}]}
{"op":"mcm","clk":"5348808593","pt":1646220870863,"mc":[{"id":"1.195453632","rc":[{"atl":[[16.5,9.68]],"id":40637101},{"atb":[[2.06,47.17]],"id":36120434},{"atb":[[1.79,63.29]],"id":40917619},{"atl":[[6.2,9.62]],"id":39183170}],"con":true,"img":false}]}
{"op":"mcm","clk":"5348808777","pt":1646220872168,"mc":[{"id":"1.195453632","rc":[{"atb":[[1.38,0]],"id":26349442}],"con":true,"img":false}]}
{"op":"mcm","clk":"5348809504","pt":1646220878190,"mc":[{"id":"1.195453632","rc":[{"atb":[[1.39,19.24]],"id":26349442}],"con":true,"img":false}]}
{"op":"mcm","clk":"5348809760","pt":1646220880500,"mc":[{"id":"1.195453632","rc":[{"atl":[[3.7,16.14],[6,0]],"id":40917619},{"atl":[[5.1,0],[3.8,15.57]],"id":38554545}],"con":true,"img":false}]}
{"op":"mcm","clk":"5348809768","pt":1646220880601,"mc":[{"id":"1.195453632","rc":[{"atb":[[1.26,0]],"id":26349442},{"atb":[[2.92,0]],"id":40637101},{"atb":[[1.17,0]],"id":41398505},{"atl":[[2.32,0]],"id":41398505},{"atb":[[1.26,0]],"id":39183170},{"atl":[[15,0]],"id":35381686}],"con":true,"img":false}]}
{"op":"mcm","clk":"5348809782","pt":1646220880705,"mc":[{"id":"1.195453632","rc":[{"atb":[[1.34,142.24]],"id":26349442},{"atb":[[3,23.69]],"id":40637101},{"atl":[[3.65,37.74],[3.75,27.27]],"id":40917619},{"atb":[[1.19,235.63]],"id":41398505},{"atl":[[1.99,34.06]],"id":41398505},{"atb":[[1.34,130.1]],"id":39183170},{"atl":[[13.5,2.72]],"id":35381686}],"con":true,"img":false}]}
{"op":"mcm","clk":"5348809802","pt":1646220880876,"mc":[{"id":"1.195453632","rc":[{"atl":[[16,0],[17,0],[17.5,4.55],[18,0]],"id":40637101},{"atb":[[2.02,73.53]],"id":36120434},{"atb":[[1.77,97.4]],"id":40917619},{"atl":[[6.6,13.39]],"id":39183170}],"con":true,"img":false}]}
{"op":"mcm","clk":"5348809910","pt":1646220881806,"mc":[{"id":"1.195453632","rc":[{"atb":[[3.05,17.48]],"id":40637101}],"con":true,"img":false}]}
{"op":"mcm","clk":"5348809914","pt":1646220881865,"mc":[{"id":"1.195453632","rc":[{"atb":[[2.16,30.89]],"id":38554545}],"con":true,"img":false}]}
{"op":"mcm","clk":"5348811023","pt":1646220890884,"mc":[{"id":"1.195453632","rc":[{"atl":[[18.5,7.14]],"id":40637101},{"atb":[[1.99,126.26]],"id":36120434},{"atb":[[1.75,166.67]],"id":40917619},{"atl":[[7,20.83]],"id":39183170}],"con":true,"img":false}]}
{"op":"mcm","clk":"5348811826","pt":1646220897398,"mc":[{"id":"1.195453632","rc":[{"atb":[[1.39,40.6]],"id":26349442}],"con":true,"img":false}]}
{"op":"mcm","clk":"5348812180","pt":1646220900513,"mc":[{"id":"1.195453632","rc":[{"spn":1.96,"spf":"NaN","id":26349442},{"atb":[[2.82,21.26],[2.28,0]],"id":40637101},{"spn":5.45,"spf":"NaN","id":40637101},{"atl":[[24,0],[13,3.33]],"id":36120434},{"spn":5.97,"spf":"NaN","id":36120434},{"atl":[[5.5,7.53],[11.5,0]],"id":40917619},{"spn":2.81,"spf":"NaN","id":40917619},{"spn":1.6,"spf":"NaN","id":41398505},{"spn":1.96,"spf":"NaN","id":39183170},{"atb":[[3,0]],"id":35381686},{"atl":[[18.5,0],[13.5,6.03]],"id":35381686},{"spn":7.55,"spf":"NaN","id":35381686},{"atb":[[1.63,0],[1.7,56.44]],"id":38554545},{"atl":[[5.1,9.63],[6.6,0]],"id":38554545},{"spn":2.91,"spf":"NaN","id":38554545}],"con":true,"img":false}]}
{"op":"mcm","clk":"5348812194","pt":1646220900617,"mc":[{"id":"1.195453632","rc":[{"atb":[[3.4,17.26]],"id":35381686}],"con":true,"img":false}]}
{"op":"mcm","clk":"5348813287","pt":1646220910536,"mc":[{"id":"1.195453632","rc":[{"atl":[[2.7,0]],"id":26349442},{"atl":[[9,0]],"id":36120434},{"atl":[[3.7,0]],"id":40917619},{"atb":[[2.1,0]],"id":38554545}],"con":true,"img":false}]}
{"op":"mcm","clk":"5348813304","pt":1646220910635,"mc":[{"id":"1.195453632","rc":[{"atl":[[2.66,25.34]],"id":26349442},{"atl":[[8.4,12.21]],"id":36120434},{"atl":[[3.6,16.14]],"id":40917619},{"atb":[[2.14,45.41]],"id":38554545}],"con":true,"img":false}]}
{"op":"mcm","clk":"5348813318","pt":1646220910746,"mc":[{"id":"1.195453632","rc":[{"atl":[[3.65,18.87],[3.75,63.63]],"id":40917619}],"con":true,"img":false}]}
{"op":"mcm","clk":"5348813325","pt":1646220910810,"mc":[{"id":"1.195453632","rc":[{"atl":[[8.6,0],[8.2,9.62]],"id":36120434}],"con":true,"img":false}]}
{"op":"mcm","clk":"5348813369","pt":1646220911238,"mc":[{"id":"1.195453632","rc":[{"atb":[[2.16,24.41]],"id":38554545}],"con":true,"img":false}]}
{"op":"mcm","clk":"5348814024","pt":1646220917136,"mc":[{"id":"1.195453632","rc":[{"atb":[[2.18,8.02]],"id":38554545}],"con":true,"img":false}]}
{"op":"mcm","clk":"5348814432","pt":1646220920524,"mc":[{"id":"1.195453632","rc":[{"atl":[[2.66,0]],"id":26349442},{"atl":[[8.4,6.76]],"id":36120434},{"atl":[[3.6,0]],"id":40917619}],"con":true,"img":false}]}
{"op":"mcm","clk":"5348814444","pt":1646220920629,"mc":[{"id":"1.195453632","rc":[{"atl":[[2.7,25.34]],"id":26349442},{"atl":[[9,5.45]],"id":36120434},{"atl":[[3.7,16.14]],"id":40917619}],"con":true,"img":false}]}
{"op":"mcm","clk":"5348814454","pt":1646220920739,"mc":[{"id":"1.195453632","rc":[{"atl":[[8.2,0],[8.4,19.24]],"id":36120434}],"con":true,"img":false}]}
{"op":"mcm","clk":"5348815046","pt":1646220925824,"mc":[{"id":"1.195453632","rc":[{"atl":[[8.8,22.44],[8.4,6.76]],"id":36120434}],"con":true,"img":false}]}
{"op":"mcm","clk":"5348815442","pt":1646220929160,"mc":[{"id":"1.195453632","rc":[{"atl":[[3.75,27.27]],"id":40917619}],"con":true,"img":false}]}
{"op":"mcm","clk":"5348815456","pt":1646220929253,"mc":[{"id":"1.195453632","rc":[{"atl":[[3.65,37.74]],"id":40917619}],"con":true,"img":false}]}
{"op":"mcm","clk":"5348815497","pt":1646220929531,"mc":[{"id":"1.195453632","rc":[{"atb":[[2.16,17.24]],"id":38554545}],"con":true,"img":false}]}
{"op":"mcm","clk":"5348815615","pt":1646220930523,"mc":[{"id":"1.195453632","rc":[{"atb":[[1.65,0]],"id":40917619}],"con":true,"img":false}]}
{"op":"mcm","clk":"5348815630","pt":1646220930625,"mc":[{"id":"1.195453632","rc":[{"atb":[[1.78,57.99]],"id":40917619}],"con":true,"img":false}]}
{"op":"mcm","clk":"5348817481","pt":1646220944873,"mc":[{"id":"1.195453632","rc":[{"atb":[[2.18,15.07]],"id":38554545}],"con":true,"img":false}]}
{"op":"mcm","clk":"5348818211","pt":1646220950486,"mc":[{"id":"1.195453632","rc":[{"atl":[[2.7,0]],"id":26349442},{"atl":[[9,0]],"id":36120434},{"atl":[[3.7,0]],"id":40917619}],"con":true,"img":false}]}
{"op":"mcm","clk":"5348818221","pt":1646220950589,"mc":[{"id":"1.195453632","rc":[{"atl":[[2.66,25.34]],"id":26349442},{"atl":[[8.6,5.45]],"id":36120434},{"atl":[[3.6,16.14]],"id":40917619}],"con":true,"img":false}]}
{"op":"mcm","clk":"5348818233","pt":1646220950695,"mc":[{"id":"1.195453632","rc":[{"atl":[[3.65,18.87],[3.75,63.63]],"id":40917619}],"con":true,"img":false}]}
{"op":"mcm","clk":"5348818243","pt":1646220950801,"mc":[{"id":"1.195453632","rc":[{"atl":[[8.8,9.62],[8.4,13.52]],"id":36120434}],"con":true,"img":false}]}
{"op":"mcm","clk":"5348819293","pt":1646220960494,"mc":[{"id":"1.195453632","rc":[{"atl":[[3.6,0]],"id":40917619}],"con":true,"img":false}]}
{"op":"mcm","clk":"5348819306","pt":1646220960598,"mc":[{"id":"1.195453632","rc":[{"atl":[[3.7,16.14]],"id":40917619}],"con":true,"img":false}]}
{"op":"mcm","clk":"5348820258","pt":1646220968695,"mc":[{"id":"1.195453632","rc":[{"atl":[[3.65,37.74],[3.75,27.27]],"id":40917619}],"con":true,"img":false}]}
{"op":"mcm","clk":"5348821701","pt":1646220980529,"mc":[{"id":"1.195453632","rc":[{"atl":[[8.6,0]],"id":36120434}],"con":true,"img":false}]}
{"op":"mcm","clk":"5348821714","pt":1646220980597,"mc":[{"id":"1.195453632","rc":[{"atl":[[8.2,5.45]],"id":36120434}],"con":true,"img":false}]}
{"op":"mcm","clk":"5348821729","pt":1646220980694,"mc":[{"id":"1.195453632","rc":[{"atl":[[8.8,22.44],[8.4,6.76]],"id":36120434}],"con":true,"img":false}]}
{"op":"mcm","clk":"5348822852","pt":1646220990509,"mc":[{"id":"1.195453632","rc":[{"atl":[[8.2,0]],"id":36120434},{"atl":[[3.7,0]],"id":40917619}],"con":true,"img":false}]}
{"op":"mcm","clk":"5348822862","pt":1646220990607,"mc":[{"id":"1.195453632","rc":[{"atl":[[8.6,5.45]],"id":36120434},{"atl":[[3.6,16.14]],"id":40917619}],"con":true,"img":false}]}
{"op":"mcm","clk":"5348822874","pt":1646220990716,"mc":[{"id":"1.195453632","rc":[{"atl":[[3.65,18.87],[3.75,63.63]],"id":40917619}],"con":true,"img":false}]}
{"op":"mcm","clk":"5348822901","pt":1646220990920,"mc":[{"id":"1.195453632","rc":[{"atl":[[3.55,23.99],[3.75,27.27]],"id":40917619}],"con":true,"img":false}]}
{"op":"mcm","clk":"5348823757","pt":1646220998433,"mc":[{"id":"1.195453632","rc":[{"atl":[[8.8,9.62],[8.4,13.52]],"id":36120434}],"con":true,"img":false}]}
{"op":"mcm","clk":"5348826472","pt":1646221020466,"mc":[{"id":"1.195453632","rc":[{"atl":[[8.6,0]],"id":36120434},{"atl":[[3.6,0]],"id":40917619}],"con":true,"img":false}]}
{"op":"mcm","clk":"5348826484","pt":1646221020570,"mc":[{"id":"1.195453632","rc":[{"atl":[[8.2,5.45]],"id":36120434},{"atl":[[3.5,16.14]],"id":40917619}],"con":true,"img":false}]}
{"op":"mcm","clk":"5348826496","pt":1646221020672,"mc":[{"id":"1.195453632","rc":[{"atl":[[8.8,22.44],[8.4,6.76]],"id":36120434},{"atl":[[3.55,7.84],[3.75,63.63]],"id":40917619},{"spn":2.79,"spf":"NaN","id":40917619}],"con":true,"img":false}]}
{"op":"mcm","clk":"5348826510","pt":1646221020779,"mc":[{"id":"1.195453632","rc":[{"atl":[[3.45,18.87]],"id":40917619}],"con":true,"img":false}]}
{"op":"mcm","clk":"5348826522","pt":1646221020882,"mc":[{"id":"1.195453632","rc":[{"atl":[[8,8.31],[8.8,9.62]],"id":36120434},{"atl":[[3.75,27.27]],"id":40917619}],"con":true,"img":false}]}
{"op":"mcm","clk":"5348827619","pt":1646221030478,"mc":[{"id":"1.195453632","rc":[{"atl":[[8.2,0]],"id":36120434},{"atl":[[3.5,0]],"id":40917619}],"con":true,"img":false}]}
{"op":"mcm","clk":"5348827630","pt":1646221030578,"mc":[{"id":"1.195453632","rc":[{"atl":[[8.6,5.45]],"id":36120434},{"atl":[[3.7,16.14]],"id":40917619}],"con":true,"img":false}]}
{"op":"mcm","clk":"5348827641","pt":1646221030683,"mc":[{"id":"1.195453632","rc":[{"atl":[[8,2.86],[8.8,22.44]],"id":36120434},{"atl":[[3.45,0],[3.65,46.14]],"id":40917619}],"con":true,"img":false}]}
{"op":"mcm","clk":"5348828943","pt":1646221040576,"mc":[{"id":"1.195453632","rc":[{"atl":[[2.66,0]],"id":26349442}],"con":true,"img":false}]}
{"op":"mcm","clk":"5348828954","pt":1646221040677,"mc":[{"id":"1.195453632","rc":[{"atl":[[2.7,25.34]],"id":26349442}],"con":true,"img":false}]}
{"op":"mcm","clk":"5348829802","pt":1646221047877,"mc":[{"id":"1.195453632","rc":[{"atl":[[8.4,13.52]],"id":36120434}],"con":true,"img":false}]}
{"op":"mcm","clk":"5348829812","pt":1646221047985,"mc":[{"id":"1.195453632","rc":[{"atl":[[8.8,9.62]],"id":36120434}],"con":true,"img":false}]}
{"op":"mcm","clk":"5348831265","pt":1646221060475,"mc":[{"id":"1.195453632","rc":[{"atl":[[3.7,0]],"id":40917619}],"con":true,"img":false}]}
{"op":"mcm","clk":"5348831278","pt":1646221060582,"mc":[{"id":"1.195453632","rc":[{"atl":[[3.6,16.14],[3.65,18.87],[3.75,63.63]],"id":40917619}],"con":true,"img":false}]}
{"op":"mcm","clk":"5348831290","pt":1646221060690,"mc":[{"id":"1.195453632","rc":[{"atl":[[3.75,27.27]],"id":40917619}],"con":true,"img":false}]}
{"op":"mcm","clk":"5348831304","pt":1646221060799,"mc":[{"id":"1.195453632","rc":[{"atl":[[3.55,23.99]],"id":40917619}],"con":true,"img":false}]}
{"op":"mcm","clk":"5348832393","pt":1646221070504,"mc":[{"id":"1.195453632","rc":[{"atl":[[2.7,0]],"id":26349442},{"atl":[[8.6,0]],"id":36120434}],"con":true,"img":false}]}
{"op":"mcm","clk":"5348832409","pt":1646221070604,"mc":[{"id":"1.195453632","rc":[{"atl":[[2.66,25.34]],"id":26349442},{"atl":[[8.2,5.45]],"id":36120434}],"con":true,"img":false}]}
{"op":"mcm","clk":"5348832419","pt":1646221070706,"mc":[{"id":"1.195453632","rc":[{"atl":[[8.8,22.44],[8.4,6.76]],"id":36120434}],"con":true,"img":false}]}
{"op":"mcm","clk":"5348833656","pt":1646221080498,"mc":[{"id":"1.195453632","rc":[{"atl":[[8.2,0]],"id":36120434}],"con":true,"img":false}]}
{"op":"mcm","clk":"5348833667","pt":1646221080610,"mc":[{"id":"1.195453632","rc":[{"atl":[[8.6,5.45]],"id":36120434}],"con":true,"img":false}]}
{"op":"mcm","clk":"5348834475","pt":1646221087529,"mc":[{"id":"1.195453632","rc":[{"atl":[[8.8,9.62],[8.4,13.52]],"id":36120434},{"spn":2.81,"spf":"NaN","id":40917619}],"con":true,"img":false}]}
{"op":"mcm","clk":"5348834846","pt":1646221090523,"mc":[{"id":"1.195453632","rc":[{"atl":[[3.6,0]],"id":40917619}],"con":true,"img":false}]}
{"op":"mcm","clk":"5348834853","pt":1646221090621,"mc":[{"id":"1.195453632","rc":[{"atl":[[3.5,16.14]],"id":40917619}],"con":true,"img":false}]}
{"op":"mcm","clk":"5348834870","pt":1646221090727,"mc":[{"id":"1.195453632","rc":[{"atl":[[3.55,7.84],[3.75,63.63]],"id":40917619}],"con":true,"img":false}]}
{"op":"mcm","clk":"5348834892","pt":1646221090930,"mc":[{"id":"1.195453632","rc":[{"atl":[[3.45,18.87],[3.75,27.27]],"id":40917619}],"con":true,"img":false}]}
{"op":"mcm","clk":"5348836018","pt":1646221100559,"mc":[{"id":"1.195453632","rc":[{"atl":[[3.5,0]],"id":40917619}],"con":true,"img":false}]}
{"op":"mcm","clk":"5348836033","pt":1646221100662,"mc":[{"id":"1.195453632","rc":[{"atl":[[3.7,16.14]],"id":40917619}],"con":true,"img":false}]}
{"op":"mcm","clk":"5348836047","pt":1646221100765,"mc":[{"id":"1.195453632","rc":[{"atl":[[3.45,0],[3.65,46.14]],"id":40917619}],"con":true,"img":false}]}
{"op":"mcm","clk":"5348837305","pt":1646221110467,"mc":[{"id":"1.195453632","rc":[{"atl":[[8.6,0]],"id":36120434}],"con":true,"img":false}]}
{"op":"mcm","clk":"5348837319","pt":1646221110577,"mc":[{"id":"1.195453632","rc":[{"atl":[[8.2,5.45]],"id":36120434}],"con":true,"img":false}]}
{"op":"mcm","clk":"5348837336","pt":1646221110685,"mc":[{"id":"1.195453632","rc":[{"atl":[[8.8,22.44],[8.4,6.76]],"id":36120434}],"con":true,"img":false}]}
{"op":"mcm","clk":"5348838525","pt":1646221120591,"mc":[{"id":"1.195453632","rc":[{"atl":[[2.66,0]],"id":26349442},{"atl":[[8.2,0]],"id":36120434}],"con":true,"img":false}]}
{"op":"mcm","clk":"5348838537","pt":1646221120646,"mc":[{"id":"1.195453632","rc":[{"atl":[[2.7,25.34]],"id":26349442},{"atl":[[8.6,5.45]],"id":36120434}],"con":true,"img":false}]}
{"op":"mcm","clk":"5348839309","pt":1646221127090,"mc":[{"id":"1.195453632","rc":[{"atl":[[8.8,9.62],[8.4,13.52]],"id":36120434}],"con":true,"img":false}]}
{"op":"mcm","clk":"5348839762","pt":1646221130467,"mc":[{"id":"1.195453632","rc":[{"atl":[[3.7,0]],"id":40917619}],"con":true,"img":false}]}
{"op":"mcm","clk":"5348839775","pt":1646221130598,"mc":[{"id":"1.195453632","rc":[{"atl":[[3.6,16.14]],"id":40917619}],"con":true,"img":false}]}
{"op":"mcm","clk":"5348839788","pt":1646221130677,"mc":[{"id":"1.195453632","rc":[{"atl":[[3.65,18.87],[3.75,63.63]],"id":40917619}],"con":true,"img":false}]}
{"op":"mcm","clk":"5348840900","pt":1646221140617,"mc":[{"id":"1.195453632","rc":[{"atl":[[3.6,0]],"id":40917619}],"con":true,"img":false}]}
{"op":"mcm","clk":"5348840908","pt":1646221140675,"mc":[{"id":"1.195453632","rc":[{"atl":[[3.7,16.14]],"id":40917619}],"con":true,"img":false}]}
{"op":"mcm","clk":"5348841626","pt":1646221146875,"mc":[{"id":"1.195453632","rc":[{"atl":[[3.65,37.74],[3.75,27.27]],"id":40917619}],"con":true,"img":false}]}
{"op":"mcm","clk":"5348841968","pt":1646221150515,"mc":[{"id":"1.195453632","rc":[{"atl":[[2.7,0]],"id":26349442},{"atl":[[8.6,0]],"id":36120434}],"con":true,"img":false}]}
{"op":"mcm","clk":"5348841979","pt":1646221150620,"mc":[{"id":"1.195453632","rc":[{"atl":[[2.66,25.34]],"id":26349442},{"atl":[[8.2,5.45]],"id":36120434}],"con":true,"img":false}]}
{"op":"mcm","clk":"5348841986","pt":1646221150682,"mc":[{"id":"1.195453632","rc":[{"atl":[[8.8,22.44],[8.4,6.76]],"id":36120434}],"con":true,"img":false}]}
{"op":"mcm","clk":"5348842451","pt":1646221154925,"mc":[{"id":"1.195453632","rc":[{"atb":[[1.28,357.14],[1.33,151.52]],"id":26349442},{"atl":[[2.64,59.34],[2.78,0]],"id":26349442},{"atb":[[3.1,19.15],[2.98,25.25]],"id":40637101},{"atb":[[1.41,0],[1.49,204.08]],"id":40917619},{"atl":[[1.92,21.74],[1.98,0],[2.52,92.14],[2.76,0]],"id":41398505},{"atb":[[1.36,82.91],[1.39,97.74]],"id":39183170},{"atb":[[4.1,8.33],[3.8,26.79]],"id":35381686},{"atl":[[22,4.76],[28,0]],"id":35381686},{"atb":[[2.2,17.24],[2.08,69.44]],"id":38554545},{"atl":[[3.65,0],[3.75,7.27]],"id":38554545}],"con":true,"img":false}]}
{"op":"mcm","clk":"5348842548","pt":1646221155814,"mc":[{"id":"1.195453632","rc":[{"atb":[[1.39,78.49]],"id":39183170}],"con":true,"img":false}]}
{"op":"mcm","clk":"5348842814","pt":1646221158224,"mc":[{"id":"1.195453632","rc":[{"atb":[[2.18,13.41]],"id":38554545}],"con":true,"img":false}]}
{"op":"mcm","clk":"5348842823","pt":1646221158284,"mc":[{"id":"1.195453632","rc":[{"atb":[[2.22,1.66]],"id":38554545}],"con":true,"img":false}]}
{"op":"mcm","clk":"5348843056","pt":1646221160523,"mc":[{"id":"1.195453632","rc":[{"atb":[[3,0]],"id":40637101},{"atl":[[8.2,0]],"id":36120434}],"con":true,"img":false}]}
{"op":"mcm","clk":"5348843071","pt":1646221160685,"mc":[{"id":"1.195453632","rc":[{"atb":[[2.96,23.69]],"id":40637101},{"atl":[[8.6,5.45]],"id":36120434}],"con":true,"img":false}]}
{"op":"mcm","clk":"5348843101","pt":1646221160893,"mc":[{"id":"1.195453632","rc":[{"atb":[[1.42,17.87]],"id":39183170}],"con":true,"img":false}]}
{"op":"mcm","clk":"5348843551","pt":1646221164914,"mc":[{"id":"1.195453632","rc":[{"atl":[[1.94,53.19]],"id":41398505},{"atl":[[3.85,17.54]],"id":38554545}],"con":true,"img":false}]}
{"op":"mcm","clk":"5348843730","pt":1646221166687,"mc":[{"id":"1.195453632","rc":[{"atl":[[8.8,9.62],[8.4,13.52]],"id":36120434}],"con":true,"img":false}]}
{"op":"mcm","clk":"5348844112","pt":1646221170512,"mc":[{"id":"1.195453632","rc":[{"atl":[[3.7,0]],"id":40917619},{"atl":[[3.8,0]],"id":38554545}],"con":true,"img":false}]}
{"op":"mcm","clk":"5348844130","pt":1646221170619,"mc":[{"id":"1.195453632","rc":[{"atl":[[3.6,16.14]],"id":40917619},{"atl":[[3.9,15.57]],"id":38554545}],"con":true,"img":false}]}
{"op":"mcm","clk":"5348844138","pt":1646221170709,"mc":[{"id":"1.195453632","rc":[{"atl":[[3.65,18.87],[3.75,63.63]],"id":40917619}],"con":true,"img":false}]}
{"op":"mcm","clk":"5348844160","pt":1646221170918,"mc":[{"id":"1.195453632","rc":[{"atb":[[1.28,0],[1.34,293.76]],"id":26349442}],"con":true,"img":false}]}
{"op":"mcm","clk":"5348844392","pt":1646221173124,"mc":[{"id":"1.195453632","rc":[{"atb":[[2.86,53.76],[3.1,1.66]],"id":40637101},{"atl":[[1.92,0],[1.98,20.41],[2.08,0]],"id":41398505},{"atb":[[2.2,0],[2.08,162.03]],"id":38554545},{"atl":[[5.2,0],[3.65,7.55],[4.7,27.03]],"id":38554545}],"con":true,"img":false}]}
{"op":"mcm","clk":"5348844403","pt":1646221173226,"mc":[{"id":"1.195453632","rc":[{"atb":[[3.05,13.42]],"id":40637101},{"atb":[[1.39,57.14]],"id":39183170}],"con":true,"img":false}]}
{"op":"mcm","clk":"5348844415","pt":1646221173329,"mc":[{"id":"1.195453632","rc":[{"atb":[[2.86,0],[3.1,20.82]],"id":40637101},{"atb":[[2.16,61.88],[2.08,69.44]],"id":38554545}],"con":true,"img":false}]}
{"op":"mcm","clk":"5348844762","pt":1646221177130,"mc":[{"id":"1.195453632","rc":[{"atb":[[2.22,0]],"id":38554545}],"con":true,"img":false}]}
{"op":"mcm","clk":"5348844771","pt":1646221177236,"mc":[{"id":"1.195453632","rc":[{"atb":[[2.2,1.66]],"id":38554545}],"con":true,"img":false}]}
{"op":"mcm","clk":"5348844920","pt":1646221178745,"mc":[{"id":"1.195453632","rc":[{"atb":[[2.18,7.05]],"id":38554545}],"con":true,"img":false}]}
{"op":"mcm","clk":"5348845095","pt":1646221180518,"mc":[{"id":"1.195453632","rc":[{"atl":[[2.66,0]],"id":26349442},{"atl":[[3.6,0]],"id":40917619},{"atb":[[1.36,0]],"id":39183170},{"atl":[[5.1,0]],"id":38554545}],"con":true,"img":false}]}
{"op":"mcm","clk":"5348845106","pt":1646221180618,"mc":[{"id":"1.195453632","rc":[{"atl":[[2.62,25.34]],"id":26349442},{"atl":[[3.7,16.14]],"id":40917619},{"atb":[[1.34,213.01]],"id":39183170},{"atl":[[5.5,9.63]],"id":38554545}],"con":true,"img":false}]}
{"op":"mcm","clk":"5348845344","pt":1646221183155,"mc":[{"id":"1.195453632","rc":[{"atl":[[1.94,0],[2.08,115.74]],"id":41398505},{"atl":[[3.75,18.18]],"id":38554545}],"con":true,"img":false}]}
{"op":"mcm","clk":"5348845545","pt":1646221185242,"mc":[{"id":"1.195453632","rc":[{"atb":[[3,4.16]],"id":40637101}],"con":true,"img":false}]}
{"op":"mcm","clk":"5348845558","pt":1646221185348,"mc":[{"id":"1.195453632","rc":[{"atb":[[1.42,37.7]],"id":39183170},{"atb":[[2.2,7.91]],"id":38554545}],"con":true,"img":false}]}
{"op":"mcm","clk":"5348845673","pt":1646221186542,"mc":[{"id":"1.195453632","rc":[{"atl":[[3.65,37.74]],"id":40917619}],"con":true,"img":false}]}
{"op":"mcm","clk":"5348845686","pt":1646221186657,"mc":[{"id":"1.195453632","rc":[{"atl":[[3.75,27.27]],"id":40917619}],"con":true,"img":false}]}
{"op":"mcm","clk":"5348845697","pt":1646221186758,"mc":[{"id":"1.195453632","rc":[{"atb":[[1.36,169.56],[1.34,142.24]],"id":26349442}],"con":true,"img":false}]}
{"op":"mcm","clk":"5348846076","pt":1646221190562,"mc":[{"id":"1.195453632","rc":[{"atl":[[8.6,0]],"id":36120434}],"con":true,"img":false}]}
{"op":"mcm","clk":"5348846089","pt":1646221190666,"mc":[{"id":"1.195453632","rc":[{"atl":[[8.2,5.45]],"id":36120434}],"con":true,"img":false}]}
{"op":"mcm","clk":"5348846101","pt":1646221190731,"mc":[{"id":"1.195453632","rc":[{"atl":[[8.8,22.44],[8.4,6.76]],"id":36120434}],"con":true,"img":false}]}
{"op":"mcm","clk":"5348846334","pt":1646221193167,"mc":[{"id":"1.195453632","rc":[{"atl":[[3.85,26.32]],"id":38554545}],"con":true,"img":false}]}
{"op":"mcm","clk":"5348846826","pt":1646221198177,"mc":[{"id":"1.195453632","rc":[{"atb":[[2.18,0]],"id":38554545}],"con":true,"img":false}]}
{"op":"mcm","clk":"5348847069","pt":1646221200483,"mc":[{"id":"1.195453632","rc":[{"atb":[[1.86,45.94]],"id":38554545}],"con":true,"img":false}]}
{"op":"mcm","clk":"5348847079","pt":1646221200550,"mc":[{"id":"1.195453632","rc":[{"atl":[[8.2,0]],"id":36120434},{"atb":[[1.7,0],[2.14,0]],"id":38554545}],"con":true,"img":false}]}
{"op":"mcm","clk":"5348847089","pt":1646221200652,"mc":[{"id":"1.195453632","rc":[{"atl":[[8.6,5.45]],"id":36120434},{"atb":[[2.18,45.41]],"id":38554545}],"con":true,"img":false}]}
{"op":"mcm","clk":"5348847146","pt":1646221201275,"mc":[{"id":"1.195453632","rc":[{"atb":[[2.2,1.66]],"id":38554545}],"con":true,"img":false}]}
{"op":"mcm","clk":"5348847669","pt":1646221206370,"mc":[{"id":"1.195453632","rc":[{"atl":[[8.4,13.52]],"id":36120434}],"con":true,"img":false}]}
{"op":"mcm","clk":"5348847681","pt":1646221206465,"mc":[{"id":"1.195453632","rc":[{"atl":[[8.8,9.62]],"id":36120434}],"con":true,"img":false}]}
{"op":"mcm","clk":"5348848062","pt":1646221210465,"mc":[{"id":"1.195453632","rc":[{"atl":[[3.7,0]],"id":40917619}],"con":true,"img":false}]}
{"op":"mcm","clk":"5348848073","pt":1646221210563,"mc":[{"id":"1.195453632","rc":[{"atl":[[3.6,16.14]],"id":40917619},{"spn":1.98,"spf":"NaN","id":39183170},{"spn":2.92,"spf":"NaN","id":38554545}],"con":true,"img":false}]}
{"op":"mcm","clk":"5348848081","pt":1646221210675,"mc":[{"id":"1.195453632","rc":[{"atl":[[3.65,18.87],[3.75,63.63]],"id":40917619}],"con":true,"img":false}]}
{"op":"mcm","clk":"5348848263","pt":1646221212285,"mc":[{"id":"1.195453632","rc":[{"atb":[[2.24,6.05]],"id":38554545}],"con":true,"img":false}]}
{"op":"mcm","clk":"5348848558","pt":1646221215108,"mc":[{"id":"1.195453632","rc":[{"atb":[[2.2,0]],"id":38554545}],"con":true,"img":false}]}
{"op":"mcm","clk":"5348848583","pt":1646221215265,"mc":[{"id":"1.195453632","rc":[{"atb":[[2.26,1.66]],"id":38554545}],"con":true,"img":false}]}
{"op":"mcm","clk":"5348849109","pt":1646221220496,"mc":[{"id":"1.195453632","rc":[{"atl":[[3.6,0]],"id":40917619},{"atl":[[3.9,0]],"id":38554545}],"con":true,"img":false}]}
{"op":"mcm","clk":"5348849118","pt":1646221220596,"mc":[{"id":"1.195453632","rc":[{"atl":[[3.7,16.14]],"id":40917619},{"atl":[[3.8,15.57]],"id":38554545}],"con":true,"img":false}]}
{"op":"mcm","clk":"5348849716","pt":1646221226095,"mc":[{"id":"1.195453632","rc":[{"atl":[[3.65,37.74],[3.75,27.27]],"id":40917619}],"con":true,"img":false}]}
{"op":"mcm","clk":"5348849750","pt":1646221226408,"mc":[{"id":"1.195453632","rc":[{"atb":[[2.24,12.76]],"id":38554545}],"con":true,"img":false}]}
{"op":"mcm","clk":"5348850200","pt":1646221230491,"mc":[{"id":"1.195453632","rc":[{"atl":[[8.6,0]],"id":36120434}],"con":true,"img":false}]}
{"op":"mcm","clk":"5348850209","pt":1646221230592,"mc":[{"id":"1.195453632","rc":[{"atl":[[8.2,5.45]],"id":36120434}],"con":true,"img":false}]}
{"op":"mcm","clk":"5348850219","pt":1646221230694,"mc":[{"id":"1.195453632","rc":[{"atl":[[8.8,22.44],[8.4,6.76]],"id":36120434}],"con":true,"img":false}]}
{"op":"mcm","clk":"5348850225","pt":1646221230797,"mc":[{"id":"1.195453632","rc":[{"atl":[[8,8.31]],"id":36120434}],"con":true,"img":false}]}
{"op":"mcm","clk":"5348850232","pt":1646221230899,"mc":[{"id":"1.195453632","rc":[{"atl":[[8.8,9.62]],"id":36120434}],"con":true,"img":false}]}
{"op":"mcm","clk":"5348851224","pt":1646221240524,"mc":[{"id":"1.195453632","rc":[{"atl":[[8.2,0]],"id":36120434}],"con":true,"img":false}]}
{"op":"mcm","clk":"5348851237","pt":1646221240592,"mc":[{"id":"1.195453632","rc":[{"atl":[[8.6,5.45]],"id":36120434}],"con":true,"img":false}]}
{"op":"mcm","clk":"5348851247","pt":1646221240695,"mc":[{"id":"1.195453632","rc":[{"atl":[[8,2.86],[8.8,22.44]],"id":36120434}],"con":true,"img":false}]}
{"op":"mcm","clk":"5348852310","pt":1646221250506,"mc":[{"id":"1.195453632","rc":[{"atl":[[3.7,0]],"id":40917619}],"con":true,"img":false}]}
{"op":"mcm","clk":"5348852320","pt":1646221250613,"mc":[{"id":"1.195453632","rc":[{"atl":[[3.6,16.14]],"id":40917619}],"con":true,"img":false}]}
{"op":"mcm","clk":"5348852331","pt":1646221250712,"mc":[{"id":"1.195453632","rc":[{"atl":[[3.65,18.87],[3.75,63.63]],"id":40917619}],"con":true,"img":false}]}
{"op":"mcm","clk":"5348852886","pt":1646221255845,"mc":[{"id":"1.195453632","rc":[{"atl":[[8.4,13.52]],"id":36120434}],"con":true,"img":false}]}
{"op":"mcm","clk":"5348852896","pt":1646221255950,"mc":[{"id":"1.195453632","rc":[{"atl":[[8.8,9.62]],"id":36120434}],"con":true,"img":false}]}
{"op":"mcm","clk":"5348853444","pt":1646221260527,"mc":[{"id":"1.195453632","rc":[{"atl":[[3.6,0]],"id":40917619}],"con":true,"img":false}]}
{"op":"mcm","clk":"5348853456","pt":1646221260632,"mc":[{"id":"1.195453632","rc":[{"atl":[[3.7,16.14]],"id":40917619}],"con":true,"img":false}]}
{"op":"mcm","clk":"5348853966","pt":1646221265749,"mc":[{"id":"1.195453632","rc":[{"atl":[[3.65,37.74],[3.75,27.27]],"id":40917619}],"con":true,"img":false}]}
{"op":"mcm","clk":"5348855476","pt":1646221280445,"mc":[{"id":"1.195453632","rc":[{"atl":[[8.6,0]],"id":36120434},{"spn":2.95,"spf":"NaN","id":38554545}],"con":true,"img":false}]}
{"op":"mcm","clk":"5348855487","pt":1646221280550,"mc":[{"id":"1.195453632","rc":[{"atl":[[8.2,5.45],[8.8,22.44]],"id":36120434}],"con":true,"img":false}]}
{"op":"mcm","clk":"5348855497","pt":1646221280649,"mc":[{"id":"1.195453632","rc":[{"atl":[[8.4,6.76]],"id":36120434}],"con":true,"img":false}]}
{"op":"mcm","clk":"5348856573","pt":1646221290560,"mc":[{"id":"1.195453632","rc":[{"atl":[[8.2,0]],"id":36120434},{"atl":[[3.7,0]],"id":40917619}],"con":true,"img":false}]}
{"op":"mcm","clk":"5348856583","pt":1646221290661,"mc":[{"id":"1.195453632","rc":[{"atl":[[8.6,5.45]],"id":36120434},{"atl":[[3.6,16.14]],"id":40917619}],"con":true,"img":false}]}
{"op":"mcm","clk":"5348856594","pt":1646221290765,"mc":[{"id":"1.195453632","rc":[{"atl":[[3.65,18.87],[3.75,63.63]],"id":40917619}],"con":true,"img":false}]}
{"op":"mcm","clk":"5348856615","pt":1646221290983,"mc":[{"id":"1.195453632","rc":[{"atl":[[3.55,23.99],[3.75,27.27]],"id":40917619}],"con":true,"img":false}]}
{"op":"mcm","clk":"5348856865","pt":1646221293171,"mc":[{"id":"1.195453632","rc":[{"atb":[[1.36,84.78],[1.33,393.46]],"id":26349442},{"atl":[[2.64,12.2],[2.78,56.18]],"id":26349442},{"atb":[[3.1,1.66],[2.98,52.09]],"id":40637101},{"atb":[[1.43,160.69],[1.49,0]],"id":40917619},{"atl":[[2.52,26.35],[2.76,56.82]],"id":41398505},{"atb":[[1.36,151.52],[1.39,0]],"id":39183170},{"atb":[[4.1,1.66],[3.8,62.5]],"id":35381686},{"atb":[[2.16,17.24],[2.08,162.03]],"id":38554545}],"con":true,"img":false}]}
{"op":"mcm","clk":"5348857122","pt":1646221295274,"mc":[{"id":"1.195453632","rc":[{"atl":[[8.8,9.62],[8.4,13.52]],"id":36120434}],"con":true,"img":false}]}
{"op":"mcm","clk":"5348857224","pt":1646221296274,"mc":[{"id":"1.195453632","rc":[{"atb":[[1.42,19.83]],"id":39183170}],"con":true,"img":false}]}
{"op":"mcm","clk":"5348857682","pt":1646221300477,"mc":[{"id":"1.195453632","rc":[{"atl":[[2.62,0]],"id":26349442},{"atb":[[2.18,0]],"id":38554545}],"con":true,"img":false}]}
{"op":"mcm","clk":"5348857695","pt":1646221300571,"mc":[{"id":"1.195453632","rc":[{"atl":[[2.66,25.34]],"id":26349442},{"atb":[[2.14,45.41]],"id":38554545}],"con":true,"img":false}]}
{"op":"mcm","clk":"5348857883","pt":1646221302398,"mc":[{"id":"1.195453632","rc":[{"atb":[[1.39,19.24]],"id":39183170},{"atb":[[2.24,6.71]],"id":38554545}],"con":true,"img":false}]}
{"op":"mcm","clk":"5348858537","pt":1646221308185,"mc":[{"id":"1.195453632","rc":[{"atb":[[2.18,6.35]],"id":38554545}],"con":true,"img":false}]}
{"op":"mcm","clk":"5348858587","pt":1646221308694,"mc":[{"id":"1.195453632","rc":[{"atb":[[3,0]],"id":40637101},{"atb":[[1.42,0]],"id":39183170}],"con":true,"img":false}]}
{"op":"mcm","clk":"5348859816","pt":1646221320530,"mc":[{"id":"1.195453632","rc":[{"atb":[[2.96,0]],"id":40637101},{"atl":[[8.6,0]],"id":36120434},{"atl":[[3.6,0]],"id":40917619},{"atb":[[1.34,130.1]],"id":39183170}],"con":true,"img":false}]}
{"op":"mcm","clk":"5348859830","pt":1646221320641,"mc":[{"id":"1.195453632","rc":[{"atb":[[3,23.69]],"id":40637101},{"atl":[[8.2,5.45]],"id":36120434},{"atl":[[3.5,16.14]],"id":40917619},{"atb":[[1.37,82.91]],"id":39183170}],"con":true,"img":false}]}
{"op":"mcm","clk":"5348859838","pt":1646221320697,"mc":[{"id":"1.195453632","rc":[{"atl":[[8.8,22.44],[8.4,6.76]],"id":36120434},{"atl":[[3.55,7.84],[3.75,63.63]],"id":40917619}],"con":true,"img":false}]}
{"op":"mcm","clk":"5348859976","pt":1646221322014,"mc":[{"id":"1.195453632","rc":[{"atb":[[2.24,0]],"id":38554545}],"con":true,"img":false}]}
{"op":"mcm","clk":"5348860000","pt":1646221322224,"mc":[{"id":"1.195453632","rc":[{"atb":[[3.05,17.48]],"id":40637101}],"con":true,"img":false}]}
{"op":"mcm","clk":"5348860010","pt":1646221322328,"mc":[{"id":"1.195453632","rc":[{"atb":[[1.39,40.6]],"id":39183170}],"con":true,"img":false}]}
{"op":"mcm","clk":"5348860129","pt":1646221323481,"mc":[{"id":"1.195453632","rc":[{"atb":[[1.39,21.35]],"id":39183170}],"con":true,"img":false}]}
{"op":"mcm","clk":"5348860327","pt":1646221325423,"mc":[{"id":"1.195453632","rc":[{"atb":[[2.26,0]],"id":38554545}],"con":true,"img":false}]}
{"op":"mcm","clk":"5348860354","pt":1646221325628,"mc":[{"id":"1.195453632","rc":[{"atb":[[2.2,1.66]],"id":38554545}],"con":true,"img":false}]}
{"op":"mcm","clk":"5348860742","pt":1646221329217,"mc":[{"id":"1.195453632","rc":[{"atb":[[1.4,18.76]],"id":39183170}],"con":true,"img":false}]}
{"op":"mcm","clk":"5348860898","pt":1646221330516,"mc":[{"id":"1.195453632","rc":[{"atl":[[8.2,0]],"id":36120434},{"atl":[[3.5,0]],"id":40917619}],"con":true,"img":false}]}
{"op":"mcm","clk":"5348860911","pt":1646221330622,"mc":[{"id":"1.195453632","rc":[{"atl":[[8.6,5.45]],"id":36120434},{"atl":[[3.7,16.14]],"id":40917619}],"con":true,"img":false}]}
{"op":"mcm","clk":"5348861420","pt":1646221335122,"mc":[{"id":"1.195453632","rc":[{"atl":[[8.8,9.62],[8.4,13.52]],"id":36120434},{"atl":[[3.65,37.74],[3.75,27.27]],"id":40917619}],"con":true,"img":false}]}
{"op":"mcm","clk":"5348861493","pt":1646221335707,"mc":[{"id":"1.195453632","rc":[{"atb":[[2.18,13.41]],"id":38554545}],"con":true,"img":false}]}
{"op":"mcm","clk":"5348863052","pt":1646221349599,"mc":[{"id":"1.195453632","rc":[{"atb":[[1.39,0]],"id":39183170},{"spn":1.97,"spf":"NaN","id":39183170},{"spn":2.92,"spf":"NaN","id":38554545}],"con":true,"img":false}]}
{"op":"mcm","clk":"5348864112","pt":1646221359745,"mc":[{"id":"1.195453632","rc":[{"atb":[[1.4,39.59]],"id":39183170}],"con":true,"img":false}]}
{"op":"mcm","clk":"5348864187","pt":1646221360481,"mc":[{"id":"1.195453632","rc":[{"atl":[[8.6,0]],"id":36120434},{"atl":[[3.7,0]],"id":40917619},{"atb":[[1.37,0]],"id":39183170}],"con":true,"img":false}]}
{"op":"mcm","clk":"5348864200","pt":1646221360579,"mc":[{"id":"1.195453632","rc":[{"atl":[[8.2,5.45]],"id":36120434},{"atl":[[3.6,16.14]],"id":40917619},{"atb":[[1.39,82.91]],"id":39183170}],"con":true,"img":false}]}
{"op":"mcm","clk":"5348864210","pt":1646221360684,"mc":[{"id":"1.195453632","rc":[{"atl":[[8.8,22.44],[8.4,6.76]],"id":36120434},{"atl":[[3.65,18.87],[3.75,63.63]],"id":40917619}],"con":true,"img":false}]}
{"op":"mcm","clk":"5348864220","pt":1646221360746,"mc":[{"id":"1.195453632","rc":[{"atl":[[8,8.31],[8.8,9.62]],"id":36120434},{"atl":[[3.55,23.99]],"id":40917619}],"con":true,"img":false}]}
{"op":"mcm","clk":"5348864234","pt":1646221360898,"mc":[{"id":"1.195453632","rc":[{"atl":[[3.75,27.27]],"id":40917619}],"con":true,"img":false}]}
{"op":"mcm","clk":"5348864388","pt":1646221362270,"mc":[{"id":"1.195453632","rc":[{"atb":[[1.4,20.82]],"id":39183170}],"con":true,"img":false}]}
{"op":"mcm","clk":"5348865063","pt":1646221368448,"mc":[{"id":"1.195453632","rc":[{"atb":[[1.42,17.87]],"id":39183170}],"con":true,"img":false}]}
{"op":"mcm","clk":"5348865236","pt":1646221370443,"mc":[{"id":"1.195453632","rc":[{"atl":[[8.2,0]],"id":36120434}],"con":true,"img":false}]}
{"op":"mcm","clk":"5348865248","pt":1646221370592,"mc":[{"id":"1.195453632","rc":[{"atl":[[8.6,5.45]],"id":36120434}],"con":true,"img":false}]}
{"op":"mcm","clk":"5348865260","pt":1646221370648,"mc":[{"id":"1.195453632","rc":[{"atl":[[8,2.86],[8.8,22.44]],"id":36120434}],"con":true,"img":false}]}
{"op":"mcm","clk":"5348865657","pt":1646221374699,"mc":[{"id":"1.195453632","rc":[{"atl":[[8.8,9.62],[8.4,13.52]],"id":36120434}],"con":true,"img":false}]}
{"op":"mcm","clk":"5348866246","pt":1646221380474,"mc":[{"id":"1.195453632","rc":[{"atb":[[1.34,0]],"id":39183170}],"con":true,"img":false}]}
{"op":"mcm","clk":"5348866257","pt":1646221380579,"mc":[{"id":"1.195453632","rc":[{"atb":[[1.37,130.1]],"id":39183170}],"con":true,"img":false}]}
{"op":"mcm","clk":"5348866629","pt":1646221384458,"mc":[{"id":"1.195453632","rc":[{"atb":[[1.4,0]],"id":39183170}],"con":true,"img":false}]}
{"op":"mcm","clk":"5348867191","pt":1646221390484,"mc":[{"id":"1.195453632","rc":[{"atl":[[3.6,0]],"id":40917619}],"con":true,"img":false}]}
{"op":"mcm","clk":"5348867200","pt":1646221390588,"mc":[{"id":"1.195453632","rc":[{"atl":[[3.55,7.84],[3.5,16.14],[3.75,63.63]],"id":40917619}],"con":true,"img":false}]}
{"op":"mcm","clk":"5348867867","pt":1646221397768,"mc":[{"id":"1.195453632","rc":[{"atb":[[1.42,37.7]],"id":39183170}],"con":true,"img":false}]}
{"op":"mcm","clk":"5348868090","pt":1646221400484,"mc":[{"id":"1.195453632","rc":[{"atl":[[8.6,0]],"id":36120434},{"atl":[[3.5,0]],"id":40917619}],"con":true,"img":false}]}
{"op":"mcm","clk":"5348868098","pt":1646221400588,"mc":[{"id":"1.195453632","rc":[{"atl":[[8.2,5.45],[8.8,22.44]],"id":36120434},{"atl":[[3.7,16.14]],"id":40917619}],"con":true,"img":false}]}
{"op":"mcm","clk":"5348868107","pt":1646221400692,"mc":[{"id":"1.195453632","rc":[{"atl":[[8.4,6.76]],"id":36120434}],"con":true,"img":false}]}
{"op":"mcm","clk":"5348868115","pt":1646221400795,"mc":[{"id":"1.195453632","rc":[{"atl":[[8,8.31],[8.8,9.62]],"id":36120434}],"con":true,"img":false}]}
{"op":"mcm","clk":"5348868382","pt":1646221404182,"mc":[{"id":"1.195453632","rc":[{"atl":[[3.65,37.74],[3.75,27.27]],"id":40917619}],"con":true,"img":false}]}
{"op":"mcm","clk":"5348868895","pt":1646221410481,"mc":[{"id":"1.195453632","rc":[{"atl":[[8.2,0]],"id":36120434},{"spn":1.98,"spf":"NaN","id":39183170}],"con":true,"img":false}]}
{"op":"mcm","clk":"5348868902","pt":1646221410584,"mc":[{"id":"1.195453632","rc":[{"atl":[[8,2.86],[8.6,5.45],[8.8,22.44]],"id":36120434}],"con":true,"img":false}]}
{"op":"mcm","clk":"5348868914","pt":1646221410691,"mc":[{"id":"1.195453632","rc":[{"atl":[[8.4,13.52]],"id":36120434}],"con":true,"img":false}]}
{"op":"mcm","clk":"5348868923","pt":1646221410797,"mc":[{"id":"1.195453632","rc":[{"atl":[[8.8,9.62]],"id":36120434}],"con":true,"img":false}]}
{"op":"mcm","clk":"5348870202","pt":1646221426506,"mc":[{"id":"1.195453632","rc":[{"atl":[[2.54,36.56],[2.64,0]],"id":26349442},{"atl":[[16.5,6.45],[17.5,1.21],[15.5,0]],"id":40637101},{"atb":[[1.98,0],[2.3,15.38],[2.1,0],[2.16,57.99]],"id":36120434},{"atb":[[1.87,22.99],[1.81,0]],"id":40917619},{"atb":[[1.2,0],[1.18,0],[1.16,623.87],[1.03,250],[1.22,92.42]],"id":41398505},{"atl":[[2.62,61.73],[2.76,0]],"id":41398505},{"atl":[[4.3,36.36],[5.9,0]],"id":39183170},{"atb":[[2,20],[1.89,90.84],[2.12,0],[2.08,0],[2.16,0]],"id":38554545}],"con":true,"img":false}]}
{"op":"mcm","clk":"5348870592","pt":1646221430517,"mc":[{"id":"1.195453632","rc":[{"atl":[[3.7,0]],"id":40917619},{"atb":[[2.14,0]],"id":38554545}],"con":true,"img":false}]}
{"op":"mcm","clk":"5348870601","pt":1646221430622,"mc":[{"id":"1.195453632","rc":[{"atl":[[3.6,16.14],[3.75,63.63]],"id":40917619},{"atb":[[2.06,45.41]],"id":38554545}],"con":true,"img":false}]}
{"op":"mcm","clk":"5348870611","pt":1646221430724,"mc":[{"id":"1.195453632","rc":[{"atl":[[3.65,18.87]],"id":40917619}],"con":true,"img":false}]}
{"op":"mcm","clk":"5348870770","pt":1646221432449,"mc":[{"id":"1.195453632","rc":[{"atb":[[2.18,7.05]],"id":38554545}],"con":true,"img":false}]}
{"op":"mcm","clk":"5348871159","pt":1646221436556,"mc":[{"id":"1.195453632","rc":[{"atl":[[2.58,31.65]],"id":26349442},{"atl":[[18.5,2.86]],"id":40637101},{"atb":[[2.26,39.68]],"id":36120434},{"atb":[[1.85,58.82]],"id":40917619},{"atl":[[4.5,14.29]],"id":39183170},{"atb":[[1.98,51.02],[2.04,0]],"id":38554545}],"con":true,"img":false}]}
{"op":"mcm","clk":"5348871305","pt":1646221438528,"mc":[{"id":"1.195453632","rc":[{"atb":[[2.1,6.82]],"id":38554545}],"con":true,"img":false}]}
{"op":"mcm","clk":"5348871463","pt":1646221440462,"mc":[{"id":"1.195453632","rc":[{"atl":[[8.6,0]],"id":36120434},{"atl":[[3.6,0]],"id":40917619},{"atb":[[2.06,0]],"id":38554545}],"con":true,"img":false}]}
{"op":"mcm","clk":"5348871471","pt":1646221440566,"mc":[{"id":"1.195453632","rc":[{"atl":[[8.2,5.45]],"id":36120434},{"atl":[[3.7,16.14]],"id":40917619},{"atb":[[1.99,45.41]],"id":38554545}],"con":true,"img":false}]}
{"op":"mcm","clk":"5348871480","pt":1646221440618,"mc":[{"id":"1.195453632","rc":[{"atl":[[8.8,22.44],[8.4,6.76]],"id":36120434}],"con":true,"img":false}]}
{"op":"mcm","clk":"5348871586","pt":1646221441867,"mc":[{"id":"1.195453632","rc":[{"atl":[[2.72,0],[2.68,0],[2.76,0]],"id":26349442},{"atb":[[1.99,0]],"id":36120434},{"atb":[[1.75,0]],"id":40917619},{"atl":[[7,0]],"id":39183170},{"atb":[[2.1,0]],"id":38554545}],"con":true,"img":false}]}
{"op":"mcm","clk":"5348871751","pt":1646221443841,"mc":[{"id":"1.195453632","rc":[{"atl":[[3.65,37.74],[3.75,27.27]],"id":40917619}],"con":true,"img":false}]}
{"op":"mcm","clk":"5348872019","pt":1646221446561,"mc":[{"id":"1.195453632","rc":[{"atl":[[2.62,46.3]],"id":26349442},{"atl":[[19.5,4.05]],"id":40637101},{"atb":[[2.22,61.48]],"id":36120434},{"atb":[[1.83,90.36]],"id":40917619},{"atl":[[4.7,20.27]],"id":39183170},{"atb":[[1.96,78.12]],"id":38554545}],"con":true,"img":false}]}
{"op":"mcm","clk":"5348872146","pt":1646221448173,"mc":[{"id":"1.195453632","rc":[{"atb":[[2.04,7.22]],"id":38554545}],"con":true,"img":false}]}
{"op":"mcm","clk":"5348872355","pt":1646221450573,"mc":[{"id":"1.195453632","rc":[{"atl":[[2.66,0]],"id":26349442},{"atl":[[8.2,0]],"id":36120434}],"con":true,"img":false}]}
{"op":"mcm","clk":"5348872363","pt":1646221450634,"mc":[{"id":"1.195453632","rc":[{"atl":[[2.52,25.34]],"id":26349442},{"atl":[[8.6,5.45]],"id":36120434}],"con":true,"img":false}]}
{"op":"mcm","clk":"5348872400","pt":1646221451041,"mc":[{"id":"1.195453632","rc":[{"atb":[[2.18,0]],"id":38554545}],"con":true,"img":false}]}
{"op":"mcm","clk":"5348872635","pt":1646221453439,"mc":[{"id":"1.195453632","rc":[{"atb":[[2.2,0]],"id":38554545}],"con":true,"img":false}]}
{"op":"mcm","clk":"5348872651","pt":1646221453646,"mc":[{"id":"1.195453632","rc":[{"atb":[[2.06,1.66]],"id":38554545}],"con":true,"img":false}]}
{"op":"mcm","clk":"5348872662","pt":1646221453751,"mc":[{"id":"1.195453632","rc":[{"atl":[[8.8,9.62],[8.4,13.52]],"id":36120434}],"con":true,"img":false}]}
{"op":"mcm","clk":"5348872908","pt":1646221456559,"mc":[{"id":"1.195453632","rc":[{"atl":[[2.66,75.3]],"id":26349442},{"atl":[[21,6.25]],"id":40637101},{"atb":[[2.02,0],[2.18,105.93]],"id":36120434},{"atb":[[1.81,154.32],[1.77,0]],"id":40917619},{"atl":[[4.9,32.05],[6.6,0]],"id":39183170},{"atb":[[1.94,132.98]],"id":38554545}],"con":true,"img":false}]}
{"op":"mcm","clk":"5348873543","pt":1646221463244,"mc":[{"id":"1.195453632","rc":[{"atb":[[2.04,15.23]],"id":38554545}],"con":true,"img":false}]}
{"op":"mcm","clk":"5348873852","pt":1646221466576,"mc":[{"id":"1.195453632","rc":[{"atb":[[2.06,0]],"id":36120434},{"atb":[[1.79,0]],"id":40917619},{"atl":[[6.2,0]],"id":39183170}],"con":true,"img":false}]}
{"op":"mcm","clk":"5348874231","pt":1646221470590,"mc":[{"id":"1.195453632","rc":[{"atl":[[2.92,0]],"id":26349442},{"spn":1.95,"spf":"NaN","id":26349442},{"atb":[[1.78,0]],"id":40917619},{"atl":[[3.7,0]],"id":40917619},{"spn":2.85,"spf":"NaN","id":38554545}],"con":true,"img":false}]}
{"op":"mcm","clk":"5348874243","pt":1646221470696,"mc":[{"id":"1.195453632","rc":[{"atl":[[2.76,25.61]],"id":26349442},{"atb":[[1.66,57.99]],"id":40917619},{"atl":[[3.6,16.14]],"id":40917619}],"con":true,"img":false}]}
{"op":"mcm","clk":"5348874251","pt":1646221470747,"mc":[{"id":"1.195453632","rc":[{"atl":[[3.65,18.87],[3.75,63.63]],"id":40917619}],"con":true,"img":false}]}
{"op":"mcm","clk":"5348875080","pt":1646221480494,"mc":[{"id":"1.195453632","rc":[{"atl":[[8.6,0]],"id":36120434},{"atl":[[3.6,0]],"id":40917619},{"atb":[[3.4,0]],"id":35381686}],"con":true,"img":false}]}
{"op":"mcm","clk":"5348875091","pt":1646221480596,"mc":[{"id":"1.195453632","rc":[{"atl":[[8.2,5.45]],"id":36120434},{"atl":[[3.7,16.14]],"id":40917619},{"atb":[[3.65,17.26]],"id":35381686}],"con":true,"img":false}]}
{"op":"mcm","clk":"5348875100","pt":1646221480699,"mc":[{"id":"1.195453632","rc":[{"atl":[[8.8,22.44],[8.4,6.76]],"id":36120434}],"con":true,"img":false}]}
{"op":"mcm","clk":"5348875121","pt":1646221480907,"mc":[{"id":"1.195453632","rc":[{"atl":[[8,8.31],[8.8,9.62]],"id":36120434}],"con":true,"img":false}]}
{"op":"mcm","clk":"5348875369","pt":1646221483576,"mc":[{"id":"1.195453632","rc":[{"atl":[[3.65,37.74],[3.75,27.27]],"id":40917619}],"con":true,"img":false}]}
{"op":"mcm","clk":"5348876039","pt":1646221490519,"mc":[{"id":"1.195453632","rc":[{"atl":[[8.2,0]],"id":36120434},{"atb":[[1.7,56.44],[1.86,0]],"id":38554545}],"con":true,"img":false}]}
{"op":"mcm","clk":"5348876054","pt":1646221490579,"mc":[{"id":"1.195453632","rc":[{"atl":[[8.6,5.45]],"id":36120434}],"con":true,"img":false}]}
{"op":"mcm","clk":"5348876063","pt":1646221490676,"mc":[{"id":"1.195453632","rc":[{"atl":[[8,2.86],[8.8,22.44]],"id":36120434}],"con":true,"img":false}]}
{"op":"mcm","clk":"5348876071","pt":1646221490781,"mc":[{"id":"1.195453632","rc":[{"atl":[[8.8,9.62],[8.4,20.27]],"id":36120434}],"con":true,"img":false}]}
{"op":"mcm","clk":"5348878044","pt":1646221510513,"mc":[{"id":"1.195453632","rc":[{"atl":[[3.7,0]],"id":40917619}],"con":true,"img":false}]}
{"op":"mcm","clk":"5348878057","pt":1646221510611,"mc":[{"id":"1.195453632","rc":[{"atl":[[3.6,16.14]],"id":40917619}],"con":true,"img":false}]}
{"op":"mcm","clk":"5348878068","pt":1646221510752,"mc":[{"id":"1.195453632","rc":[{"atl":[[3.65,18.87],[3.75,63.63]],"id":40917619}],"con":true,"img":false}]}
{"op":"mcm","clk":"5348879048","pt":1646221520532,"mc":[{"id":"1.195453632","rc":[{"atl":[[8.6,0]],"id":36120434}],"con":true,"img":false}]}
{"op":"mcm","clk":"5348879062","pt":1646221520646,"mc":[{"id":"1.195453632","rc":[{"atl":[[8.2,5.45]],"id":36120434}],"con":true,"img":false}]}
{"op":"mcm","clk":"5348879074","pt":1646221520742,"mc":[{"id":"1.195453632","rc":[{"atl":[[8.8,22.44],[8.4,6.76]],"id":36120434}],"con":true,"img":false}]}
{"op":"mcm","clk":"5348879085","pt":1646221520854,"mc":[{"id":"1.195453632","rc":[{"atl":[[8,8.31],[8.8,9.62]],"id":36120434}],"con":true,"img":false}]}
{"op":"mcm","clk":"5348879337","pt":1646221523146,"mc":[{"id":"1.195453632","rc":[{"atl":[[3.55,23.99],[3.75,27.27]],"id":40917619}],"con":true,"img":false}]}
{"op":"mcm","clk":"5348879539","pt":1646221525056,"mc":[{"id":"1.195453632","rc":[{"atl":[[3.6,0]],"id":40917619}],"con":true,"img":false}]}
{"op":"mcm","clk":"5348879546","pt":1646221525158,"mc":[{"id":"1.195453632","rc":[{"atl":[[3.7,16.14]],"id":40917619}],"con":true,"img":false}]}
{"op":"mcm","clk":"5348879562","pt":1646221525263,"mc":[{"id":"1.195453632","rc":[{"atl":[[3.55,7.84],[3.75,63.63]],"id":40917619}],"con":true,"img":false}]}
{"op":"mcm","clk":"5348880525","pt":1646221534856,"mc":[{"id":"1.195453632","rc":[{"atl":[[8.2,0]],"id":36120434}],"con":true,"img":false}]}
{"op":"mcm","clk":"5348880534","pt":1646221534959,"mc":[{"id":"1.195453632","rc":[{"atl":[[9,5.45]],"id":36120434}],"con":true,"img":false}]}
{"op":"mcm","clk":"5348880543","pt":1646221535064,"mc":[{"id":"1.195453632","rc":[{"atl":[[8,2.86],[8.8,22.44]],"id":36120434}],"con":true,"img":false}]}
{"op":"mcm","clk":"5348880797","pt":1646221537562,"mc":[{"id":"1.195453632","rc":[{"atl":[[3.65,37.74],[3.75,27.27]],"id":40917619}],"con":true,"img":false}]}
{"op":"mcm","clk":"5348881293","pt":1646221542785,"mc":[{"id":"1.195453632","rc":[{"atl":[[3.6,7.69],[3.55,0]],"id":40917619},{"atl":[[3.7,7.41],[3.65,0]],"id":38554545}],"con":true,"img":false}]}
{"op":"mcm","clk":"5348882163","pt":1646221552692,"mc":[{"id":"1.195453632","rc":[{"atl":[[3.8,33.43]],"id":38554545}],"con":true,"img":false}]}
{"op":"mcm","clk":"5348882179","pt":1646221552801,"mc":[{"id":"1.195453632","rc":[{"atl":[[3.7,34.66]],"id":40917619}],"con":true,"img":false}]}
{"op":"mcm","clk":"5348882197","pt":1646221553014,"mc":[{"id":"1.195453632","rc":[{"atl":[[3.7,71.7],[3.65,18.87]],"id":40917619}],"con":true,"img":false}]}
{"op":"mcm","clk":"5348882857","pt":1646221560506,"mc":[{"id":"1.195453632","rc":[{"atl":[[9,0]],"id":36120434}],"con":true,"img":false}]}
{"op":"mcm","clk":"5348882869","pt":1646221560612,"mc":[{"id":"1.195453632","rc":[{"atl":[[8.6,5.45]],"id":36120434}],"con":true,"img":false}]}
{"op":"mcm","clk":"5348882886","pt":1646221560773,"mc":[{"id":"1.195453632","rc":[{"atl":[[8.8,9.62],[8.4,13.52]],"id":36120434}],"con":true,"img":false}]}
{"op":"mcm","clk":"5348883071","pt":1646221562702,"mc":[{"id":"1.195453632","rc":[{"atl":[[3.85,0],[3.8,26.79],[3.65,0],[3.75,0]],"id":40917619},{"atl":[[3.9,25.86]],"id":38554545}],"con":true,"img":false}]}
{"op":"mcm","clk":"5348883083","pt":1646221562807,"mc":[{"id":"1.195453632","rc":[{"atl":[[3.85,0],[3.95,0],[3.75,0]],"id":38554545}],"con":true,"img":false}]}
{"op":"mcm","clk":"5348883842","pt":1646221570503,"mc":[{"id":"1.195453632","rc":[{"atl":[[3.8,17.86]],"id":38554545}],"con":true,"img":false}]}
{"op":"mcm","clk":"5348883852","pt":1646221570609,"mc":[{"id":"1.195453632","rc":[{"atl":[[3.85,15.57]],"id":38554545}],"con":true,"img":false}]}
{"op":"mcm","clk":"5348884064","pt":1646221572790,"mc":[{"id":"1.195453632","rc":[{"atl":[[3.9,43.1]],"id":40917619},{"atl":[[4,41.67]],"id":38554545}],"con":true,"img":false}]}
{"op":"mcm","clk":"5348884114","pt":1646221573308,"mc":[{"id":"1.195453632","rc":[{"atb":[[1.37,0]],"id":39183170},{"atb":[[3.65,0]],"id":35381686}],"con":true,"img":false}]}
{"op":"mcm","clk":"5348884123","pt":1646221573413,"mc":[{"id":"1.195453632","rc":[{"atb":[[1.32,130.1]],"id":39183170},{"atb":[[3.4,17.26]],"id":35381686}],"con":true,"img":false}]}
{"op":"mcm","clk":"5348884836","pt":1646221580515,"mc":[{"id":"1.195453632","rc":[{"atb":[[1.39,0]],"id":39183170}],"con":true,"img":false}]}
{"op":"mcm","clk":"5348884853","pt":1646221580624,"mc":[{"id":"1.195453632","rc":[{"atb":[[1.37,82.91]],"id":39183170}],"con":true,"img":false}]}
{"op":"mcm","clk":"5348884952","pt":1646221581511,"mc":[{"id":"1.195453632","rc":[{"atb":[[1.42,19.83]],"id":39183170}],"con":true,"img":false}]}
{"op":"mcm","clk":"5348885561","pt":1646221587537,"mc":[{"id":"1.195453632","rc":[{"atb":[[1.4,18.76]],"id":39183170}],"con":true,"img":false}]}
{"op":"mcm","clk":"5348885850","pt":1646221590515,"mc":[{"id":"1.195453632","rc":[{"atl":[[8.6,0]],"id":36120434}],"con":true,"img":false}]}
{"op":"mcm","clk":"5348885860","pt":1646221590620,"mc":[{"id":"1.195453632","rc":[{"atl":[[8.2,5.45]],"id":36120434}],"con":true,"img":false}]}
{"op":"mcm","clk":"5348885871","pt":1646221590723,"mc":[{"id":"1.195453632","rc":[{"atl":[[8.8,22.44],[8.4,6.76]],"id":36120434}],"con":true,"img":false}]}
{"op":"mcm","clk":"5348885882","pt":1646221590826,"mc":[{"id":"1.195453632","rc":[{"atl":[[8,8.31],[8.8,9.62]],"id":36120434}],"con":true,"img":false}]}
{"op":"mcm","clk":"5348886853","pt":1646221600560,"mc":[{"id":"1.195453632","rc":[{"atl":[[8.2,0]],"id":36120434},{"spn":2.84,"spf":"NaN","id":40917619},{"spn":2.88,"spf":"NaN","id":38554545}],"con":true,"img":false}]}
{"op":"mcm","clk":"5348886864","pt":1646221600665,"mc":[{"id":"1.195453632","rc":[{"atl":[[9,5.45]],"id":36120434}],"con":true,"img":false}]}
{"op":"mcm","clk":"5348886874","pt":1646221600727,"mc":[{"id":"1.195453632","rc":[{"atl":[[8,2.86],[8.8,22.44]],"id":36120434}],"con":true,"img":false}]}
{"op":"mcm","clk":"5348887117","pt":1646221603257,"mc":[{"id":"1.195453632","rc":[{"atb":[[1.42,0]],"id":39183170}],"con":true,"img":false}]}
{"op":"mcm","clk":"5348888388","pt":1646221616250,"mc":[{"id":"1.195453632","rc":[{"atb":[[1.4,39.59]],"id":39183170}],"con":true,"img":false}]}
{"op":"mcm","clk":"5348889679","pt":1646221630464,"mc":[{"id":"1.195453632","rc":[{"atl":[[9,0]],"id":36120434}],"con":true,"img":false}]}
{"op":"mcm","clk":"5348889695","pt":1646221630568,"mc":[{"id":"1.195453632","rc":[{"atl":[[8.6,5.45]],"id":36120434}],"con":true,"img":false}]}
{"op":"mcm","clk":"5348889718","pt":1646221630774,"mc":[{"id":"1.195453632","rc":[{"atl":[[8.8,9.62],[8.4,13.52]],"id":36120434}],"con":true,"img":false}]}
{"op":"mcm","clk":"5348892690","pt":1646221660529,"mc":[{"id":"1.195453632","rc":[{"atl":[[8.6,0]],"id":36120434}],"con":true,"img":false}]}
{"op":"mcm","clk":"5348892697","pt":1646221660632,"mc":[{"id":"1.195453632","rc":[{"atl":[[8.2,5.45]],"id":36120434},{"spn":1.97,"spf":"NaN","id":39183170}],"con":true,"img":false}]}
{"op":"mcm","clk":"5348892706","pt":1646221660697,"mc":[{"id":"1.195453632","rc":[{"atl":[[8.8,22.44],[8.4,6.76]],"id":36120434}],"con":true,"img":false}]}
{"op":"mcm","clk":"5348892723","pt":1646221660897,"mc":[{"id":"1.195453632","rc":[{"atl":[[8,8.31],[8.8,9.62]],"id":36120434}],"con":true,"img":false}]}
{"op":"mcm","clk":"5348893575","pt":1646221670412,"mc":[{"id":"1.195453632","rc":[{"atl":[[8.2,0]],"id":36120434}],"con":true,"img":false}]}
{"op":"mcm","clk":"5348893585","pt":1646221670506,"mc":[{"id":"1.195453632","rc":[{"atl":[[9,5.45]],"id":36120434}],"con":true,"img":false}]}
{"op":"mcm","clk":"5348893594","pt":1646221670608,"mc":[{"id":"1.195453632","rc":[{"atl":[[8,2.86],[8.8,22.44]],"id":36120434}],"con":true,"img":false}]}
{"op":"mcm","clk":"5348896490","pt":1646221700493,"mc":[{"id":"1.195453632","rc":[{"atl":[[9,0]],"id":36120434}],"con":true,"img":false}]}
{"op":"mcm","clk":"5348896501","pt":1646221700550,"mc":[{"id":"1.195453632","rc":[{"atl":[[8.6,5.45]],"id":36120434}],"con":true,"img":false}]}
{"op":"mcm","clk":"5348896520","pt":1646221700755,"mc":[{"id":"1.195453632","rc":[{"atl":[[8.8,9.62],[8.4,13.52]],"id":36120434}],"con":true,"img":false}]}
{"op":"mcm","clk":"5348898383","pt":1646221720798,"mc":[{"id":"1.195453632","rc":[{"atl":[[2.54,23.57],[2.42,14.08]],"id":26349442},{"spn":1.9,"spf":"NaN","id":26349442},{"atl":[[16.5,0],[17.5,0],[18.5,0],[19.5,6.49]],"id":40637101},{"atb":[[2.3,0],[2.22,0],[2.26,0],[1.71,76.78],[1.81,24.69],[2.18,0],[2.16,0]],"id":36120434},{"atl":[[4.3,0],[3.65,45.29]],"id":39183170},{"atb":[[2,0],[1.89,0],[2.06,16.89],[2.16,17.24]],"id":38554545},{"spn":2.93,"spf":"NaN","id":38554545}],"con":true,"img":false}]}
{"op":"mcm","clk":"5348898671","pt":1646221723815,"mc":[{"id":"1.195453632","rc":[{"atl":[[3.6,0],[3.7,53.18],[3.75,7.27]],"id":40917619},{"atb":[[1.03,0],[1.02,250]],"id":41398505},{"atl":[[3.85,22.59],[3.7,0],[3.8,0]],"id":38554545}],"con":true,"img":false}]}
{"op":"mcm","clk":"5348898880","pt":1646221725592,"mc":[{"id":"1.195453632","rc":[{"atb":[[1.33,302.55],[1.35,0]],"id":26349442},{"atl":[[3.6,7.69]],"id":40917619}],"con":true,"img":false}]}
{"op":"mcm","clk":"5348899049","pt":1646221727405,"mc":[{"id":"1.195453632","rc":[{"atb":[[1.35,57.14]],"id":26349442},{"atb":[[1.03,250]],"id":41398505},{"atl":[[3.7,7.41]],"id":38554545}],"con":true,"img":false}]}
{"op":"mcm","clk":"5348899364","pt":1646221730422,"mc":[{"id":"1.195453632","rc":[{"atb":[[2.06,15.23]],"id":38554545}],"con":true,"img":false}]}
{"op":"mcm","clk":"5348899370","pt":1646221730480,"mc":[{"id":"1.195453632","rc":[{"atl":[[2.52,0]],"id":26349442},{"atl":[[8.6,0]],"id":36120434}],"con":true,"img":false}]}
{"op":"mcm","clk":"5348899379","pt":1646221730583,"mc":[{"id":"1.195453632","rc":[{"atl":[[2.56,25.34]],"id":26349442},{"atl":[[8.2,5.45],[8.8,22.44]],"id":36120434},{"atb":[[2.18,1.66]],"id":38554545}],"con":true,"img":false}]}
{"op":"mcm","clk":"5348899389","pt":1646221730688,"mc":[{"id":"1.195453632","rc":[{"atl":[[21,8.75]],"id":40637101},{"atl":[[8.8,9.62],[8.4,6.76]],"id":36120434},{"atl":[[3.75,18.18]],"id":39183170}],"con":true,"img":false}]}
{"op":"mcm","clk":"5348899398","pt":1646221730789,"mc":[{"id":"1.195453632","rc":[{"atl":[[21,2.5]],"id":40637101},{"atb":[[1.79,63.29]],"id":36120434},{"atl":[[8,8.31]],"id":36120434}],"con":true,"img":false}]}
{"op":"mcm","clk":"5348899423","pt":1646221731101,"mc":[{"id":"1.195453632","rc":[{"atb":[[2.08,18.91],[2.06,0]],"id":38554545}],"con":true,"img":false}]}
{"op":"mcm","clk":"5348899988","pt":1646221737327,"mc":[{"id":"1.195453632","rc":[{"atb":[[1.33,393.46]],"id":26349442},{"atl":[[2.46,34.25]],"id":26349442},{"atb":[[2.12,44.64]],"id":38554545}],"con":true,"img":false}]}
{"op":"mcm","clk":"5348900056","pt":1646221738009,"mc":[{"id":"1.195453632","rc":[{"atb":[[2.04,8.01]],"id":38554545}],"con":true,"img":false}]}
{"op":"mcm","clk":"5348900273","pt":1646221740522,"mc":[{"id":"1.195453632","rc":[{"atl":[[8.2,0]],"id":36120434}],"con":true,"img":false}]}
{"op":"mcm","clk":"5348900281","pt":1646221740633,"mc":[{"id":"1.195453632","rc":[{"atl":[[8.6,5.45]],"id":36120434}],"con":true,"img":false}]}
{"op":"mcm","clk":"5348900289","pt":1646221740736,"mc":[{"id":"1.195453632","rc":[{"atl":[[23,3.41]],"id":40637101},{"atl":[[8,2.86],[8.8,22.44]],"id":36120434},{"atl":[[3.85,26.32],[4.9,0]],"id":39183170}],"con":true,"img":false}]}
{"op":"mcm","clk":"5348900302","pt":1646221740834,"mc":[{"id":"1.195453632","rc":[{"atb":[[1.77,97.4]],"id":36120434}],"con":true,"img":false}]}
{"op":"mcm","clk":"5348900581","pt":1646221744019,"mc":[{"id":"1.195453632","rc":[{"atb":[[2.16,23.71]],"id":38554545}],"con":true,"img":false}]}
{"op":"mcm","clk":"5348900616","pt":1646221744391,"mc":[{"id":"1.195453632","rc":[{"atl":[[2.66,0]],"id":26349442},{"atl":[[3.6,0]],"id":40917619},{"atb":[[1.03,0]],"id":41398505},{"atl":[[4.7,0]],"id":39183170},{"atb":[[1.94,0]],"id":38554545},{"atl":[[3.7,0]],"id":38554545}],"con":true,"img":false}]}
{"op":"mcm","clk":"5348900644","pt":1646221744645,"mc":[{"id":"1.195453632","rc":[{"atl":[[8,0],[8.6,8.08]],"id":36120434},{"atl":[[3.65,7.55]],"id":40917619}],"con":true,"img":false}]}
{"op":"mcm","clk":"5348900811","pt":1646221746319,"mc":[{"id":"1.195453632","rc":[{"atb":[[1.33,302.55],[1.35,0]],"id":26349442},{"atl":[[8.4,0]],"id":36120434},{"atl":[[3.5,8],[3.65,0]],"id":40917619}],"con":true,"img":false}]}
{"op":"mcm","clk":"5348900913","pt":1646221747315,"mc":[{"id":"1.195453632","rc":[{"atb":[[2.08,88.35]],"id":38554545},{"atl":[[3.95,16.95]],"id":38554545}],"con":true,"img":false}]}
{"op":"mcm","clk":"5348901229","pt":1646221750758,"mc":[{"id":"1.195453632","rc":[{"atl":[[25,5.21]],"id":40637101},{"atl":[[3.95,42.37]],"id":39183170}],"con":true,"img":false}]}
{"op":"mcm","clk":"5348901238","pt":1646221750855,"mc":[{"id":"1.195453632","rc":[{"atl":[[8.8,9.62],[8.4,13.51]],"id":36120434}],"con":true,"img":false}]}
{"op":"mcm","clk":"5348901576","pt":1646221754628,"mc":[{"id":"1.195453632","rc":[{"atb":[[1.75,166.67]],"id":36120434},{"atl":[[9,6.25]],"id":36120434}],"con":true,"img":false}]}
{"op":"mcm","clk":"5348901737","pt":1646221756356,"mc":[{"id":"1.195453632","rc":[{"atb":[[1.31,161.29]],"id":26349442},{"atl":[[2.5,50]],"id":26349442},{"atl":[[3.6,19.23]],"id":40917619}],"con":true,"img":false}]}
{"op":"mcm","clk":"5348901838","pt":1646221757350,"mc":[{"id":"1.195453632","rc":[{"atb":[[2.04,128.2],[1.96,0]],"id":38554545},{"atl":[[4.1,24.19]],"id":38554545}],"con":true,"img":false}]}
{"op":"mcm","clk":"5348902156","pt":1646221760530,"mc":[{"id":"1.195453632","rc":[{"atl":[[2.56,0]],"id":26349442}],"con":true,"img":false}]}
{"op":"mcm","clk":"5348902167","pt":1646221760634,"mc":[{"id":"1.195453632","rc":[{"atl":[[2.44,25.34]],"id":26349442}],"con":true,"img":false}]}
{"op":"mcm","clk":"5348902176","pt":1646221760741,"mc":[{"id":"1.195453632","rc":[{"atl":[[4.5,0]],"id":39183170}],"con":true,"img":false}]}
{"op":"mcm","clk":"5348902578","pt":1646221764652,"mc":[{"id":"1.195453632","rc":[{"atl":[[9.4,8.93]],"id":36120434}],"con":true,"img":false}]}
{"op":"mcm","clk":"5348902744","pt":1646221766367,"mc":[{"id":"1.195453632","rc":[{"atb":[[1.27,250]],"id":26349442},{"atl":[[2.54,104.74],[2.62,0]],"id":26349442},{"atl":[[3.7,80.96],[3.75,0]],"id":40917619}],"con":true,"img":false}]}
{"op":"mcm","clk":"5348902854","pt":1646221767463,"mc":[{"id":"1.195453632","rc":[{"atb":[[1.98,0]],"id":38554545},{"atl":[[4,0],[4.3,37.88],[3.9,0]],"id":38554545}],"con":true,"img":false}]}
{"op":"mcm","clk":"5348903162","pt":1646221770487,"mc":[{"id":"1.195453632","rc":[{"atl":[[2.44,0]],"id":26349442},{"atb":[[1.99,0]],"id":38554545},{"atl":[[3.85,7.02]],"id":38554545}],"con":true,"img":false}]}
{"op":"mcm","clk":"5348903170","pt":1646221770539,"mc":[{"id":"1.195453632","rc":[{"atl":[[2.48,25.34]],"id":26349442},{"atb":[[2.14,45.41]],"id":38554545},{"atl":[[4,15.57]],"id":38554545}],"con":true,"img":false}]}
{"op":"mcm","clk":"5348903216","pt":1646221771064,"mc":[{"id":"1.195453632","rc":[{"atb":[[2.16,17.24]],"id":38554545}],"con":true,"img":false}]}
{"op":"mcm","clk":"5348903562","pt":1646221774652,"mc":[{"id":"1.195453632","rc":[{"atl":[[9.2,0],[9.8,14.2],[8.8,0]],"id":36120434}],"con":true,"img":false}]}
{"op":"mcm","clk":"5348903723","pt":1646221776374,"mc":[{"id":"1.195453632","rc":[{"atl":[[2.58,0]],"id":26349442},{"atl":[[3.8,44.64],[3.9,0]],"id":40917619}],"con":true,"img":false}]}
{"op":"mcm","clk":"5348903800","pt":1646221777059,"mc":[{"id":"1.195453632","rc":[{"atb":[[2.18,8.02]],"id":38554545}],"con":true,"img":false}]}
{"op":"mcm","clk":"5348904155","pt":1646221780557,"mc":[{"id":"1.195453632","rc":[{"atl":[[2.76,0]],"id":26349442},{"atl":[[8.6,2.63]],"id":36120434}],"con":true,"img":false}]}
{"op":"mcm","clk":"5348904167","pt":1646221780661,"mc":[{"id":"1.195453632","rc":[{"atl":[[2.72,25.61]],"id":26349442},{"atl":[[9,18.75],[8.2,5.45],[8.4,0]],"id":36120434}],"con":true,"img":false}]}
{"op":"mcm","clk":"5348904178","pt":1646221780775,"mc":[{"id":"1.195453632","rc":[{"atl":[[8.2,10.9]],"id":36120434}],"con":true,"img":false}]}
{"op":"mcm","clk":"5348904190","pt":1646221780872,"mc":[{"id":"1.195453632","rc":[{"atl":[[9,6.25]],"id":36120434},{"spn":6.07,"spf":"NaN","id":36120434},{"spn":2.79,"spf":"NaN","id":40917619},{"spn":3.01,"spf":"NaN","id":38554545}],"con":true,"img":false}]}
{"op":"mcm","clk":"5348904813","pt":1646221786981,"mc":[{"id":"1.195453632","rc":[{"atb":[[2.04,120.19]],"id":38554545}],"con":true,"img":false}]}
{"op":"mcm","clk":"5348905155","pt":1646221790471,"mc":[{"id":"1.195453632","rc":[{"atl":[[8.2,5.45]],"id":36120434},{"atb":[[3.4,0]],"id":35381686},{"atb":[[1.7,0],[1.86,45.94]],"id":38554545}],"con":true,"img":false}]}
{"op":"mcm","clk":"5348905167","pt":1646221790573,"mc":[{"id":"1.195453632","rc":[{"atl":[[9.6,5.45]],"id":36120434},{"atb":[[3.65,17.26]],"id":35381686}],"con":true,"img":false}]}
{"op":"mcm","clk":"5348905173","pt":1646221790678,"mc":[{"id":"1.195453632","rc":[{"atl":[[9,15.18],[8.2,0]],"id":36120434}],"con":true,"img":false}]}
{"op":"mcm","clk":"5348905707","pt":1646221795782,"mc":[{"id":"1.195453632","rc":[{"atl":[[9.4,20.83]],"id":36120434}],"con":true,"img":false}]}
{"op":"mcm","clk":"5348905718","pt":1646221795886,"mc":[{"id":"1.195453632","rc":[{"atl":[[9,6.25]],"id":36120434}],"con":true,"img":false}]}
{"op":"mcm","clk":"5348906094","pt":1646221800482,"mc":[{"id":"1.195453632","rc":[{"atl":[[2.48,0]],"id":26349442}],"con":true,"img":false}]}
{"op":"mcm","clk":"5348906108","pt":1646221800586,"mc":[{"id":"1.195453632","rc":[{"atl":[[2.44,25.34]],"id":26349442}],"con":true,"img":false}]}
{"op":"mcm","clk":"5348906211","pt":1646221801540,"mc":[{"id":"1.195453632","rc":[{"atb":[[1.2,0],[1.25,0],[1.3,0]],"id":26349442},{"atl":[[2.54,81.17],[2.74,0],[2.94,0]],"id":26349442},{"atb":[[2.8,0],[2.9,65.79],[2.7,0]],"id":40637101},{"atl":[[9.8,0],[7.8,0],[14.5,0]],"id":40637101},{"atb":[[3.6,0],[3.85,0],[3.35,0]],"id":36120434},{"atl":[[17.5,0],[12.5,0],[25,0]],"id":36120434},{"atb":[[2,0],[1.9,0],[1.95,0]],"id":40917619},{"atl":[[5.1,0],[6.2,0],[8.2,0]],"id":40917619},{"atb":[[1.16,0],[1.21,0],[1.11,0]],"id":41398505},{"atl":[[2.54,0],[2.74,0],[2.34,0]],"id":41398505},{"atb":[[1.2,0],[1.25,0],[1.3,0]],"id":39183170},{"atl":[[2.54,0],[2.74,0],[2.94,0]],"id":39183170},{"atb":[[3.6,0],[3.85,0],[3.35,0]],"id":35381686},{"atl":[[17.5,0],[12.5,0],[25,0]],"id":35381686},{"atb":[[1.85,0],[1.9,0],[1.95,0]],"id":38554545},{"atl":[[5.6,0],[7.2,0],[4.6,0]],"id":38554545}],"con":true,"img":false}]}
{"op":"mcm","clk":"5348906391","pt":1646221803583,"mc":[{"id":"1.195453632","rc":[{"atb":[[2.18,15.07]],"id":38554545}],"con":true,"img":false}]}
{"op":"mcm","clk":"5348906564","pt":1646221805711,"mc":[{"id":"1.195453632","rc":[{"atb":[[1.2,499.1],[1.25,399.28],[1.3,332.73]],"id":26349442},{"atl":[[2.54,104.74],[2.74,41.72],[2.94,37.42]],"id":26349442},{"atb":[[2.8,55.45],[2.9,118.32],[2.7,58.72]],"id":40637101},{"atl":[[9.8,8.25],[7.8,5.33],[14.5,5.37]],"id":40637101},{"atb":[[3.6,38.39],[3.85,35.02],[3.35,42.47]],"id":36120434},{"atl":[[17.5,4.39],[12.5,3.15],[25,3.02]],"id":36120434},{"atb":[[2,99.82],[1.9,110.91],[1.95,105.07]],"id":40917619},{"atl":[[5.1,8.85],[6.2,13.96],[8.2,10.08]],"id":40917619},{"atb":[[1.16,623.87],[1.21,475.33],[1.11,907.45]],"id":41398505},{"atl":[[2.54,47.13],[2.74,41.72],[2.34,27.08]],"id":41398505},{"atb":[[1.2,499.1],[1.25,399.28],[1.3,332.73]],"id":39183170},{"atl":[[2.54,23.57],[2.74,41.72],[2.94,37.42]],"id":39183170},{"atb":[[3.6,38.39],[3.85,35.02],[3.35,42.47]],"id":35381686},{"atl":[[17.5,4.39],[12.5,3.15],[25,3.02]],"id":35381686},{"atb":[[1.85,117.43],[1.9,110.91],[1.95,105.07]],"id":38554545},{"atl":[[5.6,15.78],[7.2,11.7],[4.6,10.08]],"id":38554545}],"con":true,"img":false}]}
{"op":"mcm","clk":"5348906664","pt":1646221806923,"mc":[{"id":"1.195453632","rc":[{"atb":[[1.33,60.61],[1.35,161.29]],"id":26349442},{"atl":[[2.78,0],[2.62,61.73],[2.16,2]],"id":26349442},{"atb":[[3.1,19.15],[2.98,25.25]],"id":40637101},{"atb":[[1.43,0],[1.87,0],[1.57,160.69],[1.91,21.98]],"id":40917619},{"atl":[[1.98,0],[2.62,0],[1.93,21.51],[2.46,68.49],[1.49,4]],"id":41398505},{"atb":[[1.41,82.91],[1.36,0]],"id":39183170},{"atb":[[1.74,70.04],[3.8,26.79]],"id":35381686},{"atl":[[38,2.7],[11,0],[22,0],[12,0],[13,0],[15,1.43]],"id":35381686},{"atb":[[2.46,3],[2.16,61.88],[2.08,69.44]],"id":38554545},{"atl":[[4.4,29.41],[4.7,0]],"id":38554545}],"con":true,"img":false}]}
{"op":"mcm","clk":"5348906683","pt":1646221807123,"mc":[{"id":"1.195453632","rc":[{"atl":[[14,0]],"id":35381686},{"atb":[[2.48,2]],"id":38554545}],"con":true,"img":false}]}
{"op":"mcm","clk":"5348906692","pt":1646221807175,"mc":[{"id":"1.195453632","rc":[{"atl":[[2.14,4]],"id":26349442},{"atl":[[1.48,2]],"id":41398505}],"con":true,"img":false}]}
{"op":"mcm","clk":"5348906700","pt":1646221807283,"mc":[{"id":"1.195453632","rc":[{"atl":[[1.49,0]],"id":41398505},{"atb":[[2.5,4]],"id":38554545}],"con":true,"img":false}]}
{"op":"mcm","clk":"5348906715","pt":1646221807498,"mc":[{"id":"1.195453632","rc":[{"atl":[[2.12,4]],"id":26349442},{"atl":[[1.41,3],[1.48,0]],"id":41398505},{"atb":[[2.52,2]],"id":38554545}],"con":true,"img":false}]}
{"op":"mcm","clk":"5348906964","pt":1646221810400,"mc":[{"id":"1.195453632","rc":[{"atb":[[1.4,20.82]],"id":39183170},{"atb":[[2.18,8.72]],"id":38554545}],"con":true,"img":false}]}
{"op":"mcm","clk":"5348906967","pt":1646221810504,"mc":[{"id":"1.195453632","rc":[{"atl":[[13.5,2.72],[15.5,2.72]],"id":35381686}],"con":true,"img":false}]}
{"op":"mcm","clk":"5348907136","pt":1646221812488,"mc":[{"id":"1.195453632","rc":[{"atl":[[2.1,3]],"id":26349442},{"atl":[[1.93,0],[1.4,2],[1.92,21.74]],"id":41398505}],"con":true,"img":false}]}
{"op":"mcm","clk":"5348907148","pt":1646221812691,"mc":[{"id":"1.195453632","rc":[{"atl":[[1.39,4]],"id":41398505}],"con":true,"img":false}]}
{"op":"mcm","clk":"5348907491","pt":1646221816404,"mc":[{"id":"1.195453632","rc":[{"atb":[[1.4,84.78],[1.35,0]],"id":26349442},{"atl":[[2.62,0]],"id":26349442},{"atb":[[1.44,17.06]],"id":39183170},{"atb":[[1.74,0],[2.04,70.04]],"id":35381686},{"atb":[[2.2,6.25]],"id":38554545}],"con":true,"img":false}]}
{"op":"mcm","clk":"5348907500","pt":1646221816509,"mc":[{"id":"1.195453632","rc":[{"atl":[[2.42,39.43]],"id":26349442},{"atl":[[2.22,55.8],[2.46,0]],"id":41398505}],"con":true,"img":false}]}
{"op":"mcm","clk":"5348907510","pt":1646221816606,"mc":[{"id":"1.195453632","rc":[{"atb":[[1.45,20.82],[1.41,0]],"id":39183170}],"con":true,"img":false}]}
{"op":"mcm","clk":"5348907542","pt":1646221816816,"mc":[{"id":"1.195453632","rc":[{"atb":[[1.89,56.18]],"id":40917619},{"atl":[[16,3.33]],"id":35381686}],"con":true,"img":false}]}
{"op":"mcm","clk":"5348907599","pt":1646221817288,"mc":[{"id":"1.195453632","rc":[{"atl":[[2.12,0],[2.1,0],[2.14,0],[2.16,0]],"id":26349442},{"atb":[[1.81,0]],"id":40917619}],"con":true,"img":false}]}
{"op":"mcm","clk":"5348907616","pt":1646221817497,"mc":[{"id":"1.195453632","rc":[{"atl":[[1.42,3]],"id":41398505}],"con":true,"img":false}]}
{"op":"mcm","clk":"5348907747","pt":1646221818913,"mc":[{"id":"1.195453632","rc":[{"atb":[[1.45,0]],"id":39183170}],"con":true,"img":false}]}
{"op":"mcm","clk":"5348907757","pt":1646221819007,"mc":[{"id":"1.195453632","rc":[{"atb":[[1.43,57.14]],"id":39183170}],"con":true,"img":false}]}
{"op":"mcm","clk":"5348907768","pt":1646221819114,"mc":[{"id":"1.195453632","rc":[{"atl":[[1.42,0],[1.38,2]],"id":41398505}],"con":true,"img":false}]}
{"op":"mcm","clk":"5348907788","pt":1646221819427,"mc":[{"id":"1.195453632","rc":[{"atb":[[1.39,21.35]],"id":26349442},{"atb":[[1.44,0]],"id":39183170}],"con":true,"img":false}]}
{"op":"mcm","clk":"5348907797","pt":1646221819481,"mc":[{"id":"1.195453632","rc":[{"atb":[[2.18,7.05]],"id":38554545}],"con":true,"img":false}]}
{"op":"mcm","clk":"5348907811","pt":1646221819583,"mc":[{"id":"1.195453632","rc":[{"atb":[[2.54,1.66]],"id":38554545}],"con":true,"img":false}]}
{"op":"mcm","clk":"5348907908","pt":1646221820592,"mc":[{"id":"1.195453632","rc":[{"atb":[[1.34,0]],"id":26349442},{"atl":[[11,0]],"id":40637101},{"atl":[[9.6,0]],"id":36120434},{"atb":[[1.37,0]],"id":39183170}],"con":true,"img":false}]}
{"op":"mcm","clk":"5348907917","pt":1646221820695,"mc":[{"id":"1.195453632","rc":[{"atb":[[1.32,142.24]],"id":26349442},{"atl":[[12.5,3.79]],"id":40637101},{"atl":[[9.2,5.45]],"id":36120434},{"atb":[[1.36,82.91]],"id":39183170}],"con":true,"img":false}]}
{"op":"mcm","clk":"5348907926","pt":1646221820801,"mc":[{"id":"1.195453632","rc":[{"atl":[[9,12.5]],"id":36120434}],"con":true,"img":false}]}
{"op":"mcm","clk":"5348907935","pt":1646221820908,"mc":[{"id":"1.195453632","rc":[{"atl":[[9.4,8.93]],"id":36120434}],"con":true,"img":false}]}
{"op":"mcm","clk":"5348908087","pt":1646221822520,"mc":[{"id":"1.195453632","rc":[{"atl":[[1.94,53.19]],"id":41398505}],"con":true,"img":false}]}
{"op":"mcm","clk":"5348908251","pt":1646221824183,"mc":[{"id":"1.195453632","rc":[{"atb":[[1.41,114.28]],"id":39183170}],"con":true,"img":false}]}
{"op":"mcm","clk":"5348908260","pt":1646221824286,"mc":[{"id":"1.195453632","rc":[{"atb":[[1.43,0]],"id":39183170}],"con":true,"img":false}]}
{"op":"mcm","clk":"5348908270","pt":1646221824392,"mc":[{"id":"1.195453632","rc":[{"atl":[[2.08,0]],"id":41398505}],"con":true,"img":false}]}
{"op":"mcm","clk":"5348908388","pt":1646221825426,"mc":[{"id":"1.195453632","rc":[{"atb":[[1.43,17.46]],"id":26349442}],"con":true,"img":false}]}
{"op":"mcm","clk":"5348908434","pt":1646221825791,"mc":[{"id":"1.195453632","rc":[{"atb":[[1.44,21.36]],"id":26349442}],"con":true,"img":false}]}
{"op":"mcm","clk":"5348908441","pt":1646221825894,"mc":[{"id":"1.195453632","rc":[{"atb":[[1.4,0]],"id":26349442}],"con":true,"img":false}]}
{"op":"mcm","clk":"5348908530","pt":1646221826826,"mc":[{"id":"1.195453632","rc":[{"atb":[[1.87,86.21]],"id":40917619},{"atl":[[17,4.69]],"id":35381686}],"con":true,"img":false}]}
{"op":"mcm","clk":"5348908702","pt":1646221828492,"mc":[{"id":"1.195453632","rc":[{"atb":[[1.43,0]],"id":26349442}],"con":true,"img":false}]}
{"op":"mcm","clk":"5348908711","pt":1646221828599,"mc":[{"id":"1.195453632","rc":[{"atb":[[1.4,60.61]],"id":26349442}],"con":true,"img":false}]}
{"op":"mcm","clk":"5348908720","pt":1646221828707,"mc":[{"id":"1.195453632","rc":[{"atb":[[1.44,0]],"id":26349442}],"con":true,"img":false}]}
{"op":"mcm","clk":"5348908730","pt":1646221828802,"mc":[{"id":"1.195453632","rc":[{"atb":[[1.83,0]],"id":40917619}],"con":true,"img":false}]}
{"op":"mcm","clk":"5348908891","pt":1646221830529,"mc":[{"id":"1.195453632","rc":[{"atb":[[2.14,0]],"id":38554545}],"con":true,"img":false}]}
{"op":"mcm","clk":"5348908904","pt":1646221830631,"mc":[{"id":"1.195453632","rc":[{"atb":[[2.18,52.47]],"id":38554545}],"con":true,"img":false}]}
{"op":"mcm","clk":"5348908962","pt":1646221831415,"mc":[{"id":"1.195453632","rc":[{"atb":[[1.44,17.06]],"id":39183170},{"atb":[[2.2,0]],"id":38554545}],"con":true,"img":false}]}
{"op":"mcm","clk":"5348909001","pt":1646221831933,"mc":[{"id":"1.195453632","rc":[{"atb":[[1.39,0]],"id":26349442},{"atb":[[3.05,13.42]],"id":40637101},{"atb":[[2.18,45.41]],"id":38554545}],"con":true,"img":false}]}
{"op":"mcm","clk":"5348909067","pt":1646221832508,"mc":[{"id":"1.195453632","rc":[{"atl":[[1.96,78.12]],"id":41398505}],"con":true,"img":false}]}
{"op":"mcm","clk":"5348909173","pt":1646221833547,"mc":[{"id":"1.195453632","rc":[{"atb":[[1.45,20.82],[1.41,0]],"id":39183170}],"con":true,"img":false}]}
{"op":"mcm","clk":"5348909188","pt":1646221833706,"mc":[{"id":"1.195453632","rc":[{"atb":[[1.4,0],[1.37,121.22]],"id":26349442}],"con":true,"img":false}]}
{"op":"mcm","clk":"5348909266","pt":1646221834548,"mc":[{"id":"1.195453632","rc":[{"atb":[[1.44,0]],"id":39183170}],"con":true,"img":false}]}
{"op":"mcm","clk":"5348909409","pt":1646221836213,"mc":[{"id":"1.195453632","rc":[{"atl":[[2.04,0]],"id":41398505}],"con":true,"img":false}]}
{"op":"mcm","clk":"5348909471","pt":1646221836833,"mc":[{"id":"1.195453632","rc":[{"atb":[[1.85,147.06]],"id":40917619},{"atl":[[18,7.35]],"id":35381686}],"con":true,"img":false}]}
{"op":"mcm","clk":"5348909542","pt":1646221837513,"mc":[{"id":"1.195453632","rc":[{"atb":[[2.24,6.05]],"id":38554545}],"con":true,"img":false}]}
{"op":"mcm","clk":"5348909651","pt":1646221838652,"mc":[{"id":"1.195453632","rc":[{"atb":[[1.41,57.14],[1.45,0]],"id":39183170}],"con":true,"img":false}]}
{"op":"mcm","clk":"5348909858","pt":1646221840531,"mc":[{"id":"1.195453632","rc":[{"atb":[[1.4,18.76],[1.36,0]],"id":26349442},{"atl":[[2.44,0]],"id":26349442}],"con":true,"img":false}]}
{"op":"mcm","clk":"5348909865","pt":1646221840633,"mc":[{"id":"1.195453632","rc":[{"atb":[[1.38,84.78]],"id":26349442},{"atl":[[2.4,25.34]],"id":26349442}],"con":true,"img":false}]}
{"op":"mcm","clk":"5348909876","pt":1646221840736,"mc":[{"id":"1.195453632","rc":[{"atl":[[2.5,116.67],[2.42,14.08]],"id":26349442}],"con":true,"img":false}]}
{"op":"mcm","clk":"5348909888","pt":1646221840849,"mc":[{"id":"1.195453632","rc":[{"atl":[[2.5,50],[2.42,64.78]],"id":26349442}],"con":true,"img":false}]}
{"op":"mcm","clk":"5348910060","pt":1646221842523,"mc":[{"id":"1.195453632","rc":[{"spn":1.9,"spf":"NaN","id":26349442},{"spn":6.27,"spf":"NaN","id":36120434},{"atl":[[1.98,127.55]],"id":41398505},{"spn":1.3,"spf":"NaN","id":41398505},{"spn":1.97,"spf":"NaN","id":39183170},{"spn":8.3,"spf":"NaN","id":35381686},{"spn":3.19,"spf":"NaN","id":38554545}],"con":true,"img":false}]}
{"op":"mcm","clk":"5348910091","pt":1646221842932,"mc":[{"id":"1.195453632","rc":[{"atb":[[1.41,84.78],[1.37,0]],"id":26349442}],"con":true,"img":false}]}
{"op":"mcm","clk":"5348910137","pt":1646221843512,"mc":[{"id":"1.195453632","rc":[{"atb":[[1.4,0]],"id":26349442}],"con":true,"img":false}]}
{"op":"mcm","clk":"5348910144","pt":1646221843668,"mc":[{"id":"1.195453632","rc":[{"atb":[[1.41,0],[1.39,169.56]],"id":26349442}],"con":true,"img":false}]}
{"op":"mcm","clk":"5348910166","pt":1646221843929,"mc":[{"id":"1.195453632","rc":[{"atb":[[3,27.86]],"id":40637101}],"con":true,"img":false}]}
{"op":"mcm","clk":"5348910179","pt":1646221844137,"mc":[{"id":"1.195453632","rc":[{"atb":[[1.4,0]],"id":39183170},{"atb":[[2.24,12.76]],"id":38554545}],"con":true,"img":false}]}
{"op":"mcm","clk":"5348910196","pt":1646221844345,"mc":[{"id":"1.195453632","rc":[{"atb":[[1.41,0],[1.37,114.28]],"id":39183170}],"con":true,"img":false}]}
{"op":"mcm","clk":"5348910345","pt":1646221846215,"mc":[{"id":"1.195453632","rc":[{"atl":[[2,0]],"id":41398505}],"con":true,"img":false}]}
{"op":"mcm","clk":"5348910724","pt":1646221850425,"mc":[{"id":"1.195453632","rc":[{"atl":[[9.2,0]],"id":36120434},{"atl":[[1.99,0],[2.52,0],[2.2,33.38]],"id":41398505}],"con":true,"img":false}]}
{"op":"mcm","clk":"5348910730","pt":1646221850527,"mc":[{"id":"1.195453632","rc":[{"atl":[[8.8,5.45],[9.4,20.83]],"id":36120434},{"atl":[[1.93,34.06]],"id":41398505}],"con":true,"img":false}]}
{"op":"mcm","clk":"5348910739","pt":1646221850633,"mc":[{"id":"1.195453632","rc":[{"atl":[[9,6.25]],"id":36120434}],"con":true,"img":false}]}
{"op":"mcm","clk":"5348910748","pt":1646221850738,"mc":[{"id":"1.195453632","rc":[{"atl":[[8.6,8.08]],"id":36120434}],"con":true,"img":false}]}
{"op":"mcm","clk":"5348910757","pt":1646221850842,"mc":[{"id":"1.195453632","rc":[{"atl":[[9.4,8.93]],"id":36120434}],"con":true,"img":false}]}
{"op":"mcm","clk":"5348910884","pt":1646221852553,"mc":[{"id":"1.195453632","rc":[{"atb":[[1.42,17.87]],"id":26349442},{"atb":[[1.4,18.76]],"id":39183170}],"con":true,"img":false}]}
{"op":"mcm","clk":"5348910898","pt":1646221852761,"mc":[{"id":"1.195453632","rc":[{"atb":[[1.43,84.78],[1.39,0]],"id":26349442}],"con":true,"img":false}]}
{"op":"mcm","clk":"5348910960","pt":1646221853439,"mc":[{"id":"1.195453632","rc":[{"atb":[[1.41,82.91],[1.37,0]],"id":39183170}],"con":true,"img":false}]}
{"op":"mcm","clk":"5348911138","pt":1646221855673,"mc":[{"id":"1.195453632","rc":[{"atb":[[1.42,0]],"id":26349442},{"atb":[[1.4,0]],"id":39183170}],"con":true,"img":false}]}
{"op":"mcm","clk":"5348911327","pt":1646221857860,"mc":[{"id":"1.195453632","rc":[{"atb":[[1.39,169.56]],"id":26349442}],"con":true,"img":false}]}
{"op":"mcm","clk":"5348911335","pt":1646221857963,"mc":[{"id":"1.195453632","rc":[{"atb":[[1.43,0]],"id":26349442}],"con":true,"img":false}]}
{"op":"mcm","clk":"5348911386","pt":1646221858540,"mc":[{"id":"1.195453632","rc":[{"atb":[[1.41,0],[1.37,165.82]],"id":39183170}],"con":true,"img":false}]}
{"op":"mcm","clk":"5348911599","pt":1646221860554,"mc":[{"id":"1.195453632","rc":[{"atb":[[1.36,0]],"id":39183170}],"con":true,"img":false}]}
{"op":"mcm","clk":"5348911608","pt":1646221860673,"mc":[{"id":"1.195453632","rc":[{"atb":[[1.37,0],[1.33,374.48],[1.39,82.91]],"id":39183170}],"con":true,"img":false}]}
{"op":"mcm","clk":"5348911984","pt":1646221864569,"mc":[{"id":"1.195453632","rc":[{"atb":[[1.42,17.87]],"id":26349442}],"con":true,"img":false}]}
{"op":"mcm","clk":"5348912180","pt":1646221866760,"mc":[{"id":"1.195453632","rc":[{"atb":[[1.43,84.78]],"id":26349442}],"con":true,"img":false}]}
{"op":"mcm","clk":"5348912191","pt":1646221866863,"mc":[{"id":"1.195453632","rc":[{"atb":[[1.39,0]],"id":26349442}],"con":true,"img":false}]}
{"op":"mcm","clk":"5348912267","pt":1646221867652,"mc":[{"id":"1.195453632","rc":[{"atb":[[1.42,0]],"id":26349442},{"atb":[[1.42,17.87]],"id":39183170}],"con":true,"img":false}]}
{"op":"mcm","clk":"5348912410","pt":1646221869586,"mc":[{"id":"1.195453632","rc":[{"atb":[[1.43,57.14],[1.33,151.52]],"id":39183170}],"con":true,"img":false}]}
{"op":"mcm","clk":"5348912515","pt":1646221870559,"mc":[{"id":"1.195453632","rc":[{"atb":[[1.38,0]],"id":26349442},{"atl":[[8.8,0]],"id":36120434},{"atb":[[1.42,0]],"id":39183170}],"con":true,"img":false}]}
{"op":"mcm","clk":"5348912531","pt":1646221870657,"mc":[{"id":"1.195453632","rc":[{"atb":[[1.4,84.78]],"id":26349442},{"atl":[[8.6,2.63],[9.2,5.45],[9.4,20.83]],"id":36120434}],"con":true,"img":false}]}
{"op":"mcm","clk":"5348912649","pt":1646221871907,"mc":[{"id":"1.195453632","rc":[{"atb":[[1.41,169.56]],"id":26349442}],"con":true,"img":false}]}
{"op":"mcm","clk":"5348912659","pt":1646221871953,"mc":[{"id":"1.195453632","rc":[{"atb":[[1.43,0]],"id":26349442}],"con":true,"img":false}]}
{"op":"mcm","clk":"5348912790","pt":1646221873356,"mc":[{"id":"1.195453632","rc":[{"atl":[[2.72,0]],"id":26349442},{"atb":[[1.19,0]],"id":41398505}],"con":true,"img":false}]}
{"op":"mcm","clk":"5348912801","pt":1646221873465,"mc":[{"id":"1.195453632","rc":[{"atl":[[2.92,25.61]],"id":26349442},{"atb":[[1.17,235.63]],"id":41398505}],"con":true,"img":false}]}
{"op":"mcm","clk":"5348912889","pt":1646221874659,"mc":[{"id":"1.195453632","rc":[{"atb":[[1.4,114.28]],"id":39183170}],"con":true,"img":false}]}
{"op":"mcm","clk":"5348912902","pt":1646221874796,"mc":[{"id":"1.195453632","rc":[{"atb":[[1.43,0]],"id":39183170}],"con":true,"img":false}]}
{"op":"mcm","clk":"5348913264","pt":1646221879506,"mc":[{"id":"1.195453632","rc":[{"atl":[[9,12.5],[9.4,8.93]],"id":36120434}],"con":true,"img":false}]}
{"op":"mcm","clk":"5348913272","pt":1646221879560,"mc":[{"id":"1.195453632","rc":[{"atb":[[1.44,17.06]],"id":26349442}],"con":true,"img":false}]}
{"op":"mcm","clk":"5348913356","pt":1646221880599,"mc":[{"id":"1.195453632","rc":[{"atb":[[1.4,0]],"id":26349442},{"atb":[[1.22,0]],"id":41398505}],"con":true,"img":false}]}
{"op":"mcm","clk":"5348913365","pt":1646221880706,"mc":[{"id":"1.195453632","rc":[{"atb":[[1.37,84.78]],"id":26349442},{"atb":[[1.19,92.42]],"id":41398505}],"con":true,"img":false}]}
{"op":"mcm","clk":"5348913378","pt":1646221880760,"mc":[{"id":"1.195453632","rc":[{"atb":[[1.41,0],[1.45,84.78]],"id":26349442}],"con":true,"img":false}]}
{"op":"mcm","clk":"5348913498","pt":1646221882482,"mc":[{"id":"1.195453632","rc":[{"atb":[[1.44,0]],"id":26349442},{"atb":[[1.43,17.46]],"id":39183170}],"con":true,"img":false}]}
{"op":"mcm","clk":"5348913590","pt":1646221883480,"mc":[{"id":"1.195453632","rc":[{"atb":[[1.44,82.91]],"id":39183170}],"con":true,"img":false}]}
{"op":"mcm","clk":"5348913598","pt":1646221883583,"mc":[{"id":"1.195453632","rc":[{"atb":[[1.4,0]],"id":39183170}],"con":true,"img":false}]}
{"op":"mcm","clk":"5348913789","pt":1646221885669,"mc":[{"id":"1.195453632","rc":[{"atb":[[1.43,0]],"id":39183170}],"con":true,"img":false}]}
{"op":"mcm","clk":"5348913804","pt":1646221885878,"mc":[{"id":"1.195453632","rc":[{"atb":[[1.45,0],[1.38,169.56]],"id":26349442}],"con":true,"img":false}]}
{"op":"mcm","clk":"5348914022","pt":1646221888575,"mc":[{"id":"1.195453632","rc":[{"atb":[[1.4,165.82]],"id":39183170}],"con":true,"img":false}]}
{"op":"mcm","clk":"5348914032","pt":1646221888676,"mc":[{"id":"1.195453632","rc":[{"atb":[[1.44,0]],"id":39183170}],"con":true,"img":false}]}
{"op":"mcm","clk":"5348914181","pt":1646221890595,"mc":[{"id":"1.195453632","rc":[{"atb":[[1.32,0],[1.39,0]],"id":39183170}],"con":true,"img":false}]}
{"op":"mcm","clk":"5348914193","pt":1646221890698,"mc":[{"id":"1.195453632","rc":[{"atb":[[1.41,82.91],[1.34,130.1]],"id":39183170}],"con":true,"img":false}]}
{"op":"mcm","clk":"5348914576","pt":1646221894599,"mc":[{"id":"1.195453632","rc":[{"atb":[[1.41,18.31]],"id":26349442}],"con":true,"img":false}]}
{"op":"mcm","clk":"5348914598","pt":1646221894909,"mc":[{"id":"1.195453632","rc":[{"atb":[[1.42,84.78],[1.38,0]],"id":26349442}],"con":true,"img":false}]}
{"op":"mcm","clk":"5348914801","pt":1646221897300,"mc":[{"id":"1.195453632","rc":[{"atb":[[1.4,0],[1.42,82.91]],"id":39183170}],"con":true,"img":false}]}
{"op":"mcm","clk":"5348914833","pt":1646221897709,"mc":[{"id":"1.195453632","rc":[{"atb":[[1.41,0]],"id":26349442}],"con":true,"img":false}]}
{"op":"mcm","clk":"5348914966","pt":1646221899318,"mc":[{"id":"1.195453632","rc":[{"atl":[[1.91,21.98]],"id":41398505}],"con":true,"img":false}]}
{"op":"mcm","clk":"5348914972","pt":1646221899422,"mc":[{"id":"1.195453632","rc":[{"atl":[[1.92,0]],"id":41398505}],"con":true,"img":false}]}
{"op":"mcm","clk":"5348915002","pt":1646221899893,"mc":[{"id":"1.195453632","rc":[{"atb":[[1.33,0],[1.35,57.14]],"id":26349442},{"atl":[[2.54,23.57],[2.5,0],[2.42,50.7],[2.46,0],[2.64,12.2]],"id":26349442},{"atb":[[2.46,3]],"id":40917619},{"atl":[[3.6,0],[3.5,0],[3.65,7.55]],"id":40917619}],"con":true,"img":false}]}
{"op":"mcm","clk":"5348915010","pt":1646221900001,"mc":[{"id":"1.195453632","rc":[{"atb":[[1.42,0],[1.38,169.56]],"id":26349442}],"con":true,"img":false}]}
{"op":"mcm","clk":"5348915019","pt":1646221900102,"mc":[{"id":"1.195453632","rc":[{"atb":[[2.04,0],[1.7,65.08]],"id":35381686}],"con":true,"img":false}]}
{"op":"mcm","clk":"5348915060","pt":1646221900618,"mc":[{"id":"1.195453632","rc":[{"atb":[[1.37,0]],"id":26349442},{"atl":[[9.2,0]],"id":36120434}],"con":true,"img":false}]}
{"op":"mcm","clk":"5348915068","pt":1646221900721,"mc":[{"id":"1.195453632","rc":[{"atb":[[1.39,84.78]],"id":26349442},{"atl":[[8.8,5.45]],"id":36120434}],"con":true,"img":false}]}
{"op":"mcm","clk":"5348915077","pt":1646221900827,"mc":[{"id":"1.195453632","rc":[{"atl":[[9,6.25],[9.4,20.83]],"id":36120434}],"con":true,"img":false}]}
{"op":"mcm","clk":"5348915095","pt":1646221900985,"mc":[{"id":"1.195453632","rc":[{"atl":[[2.64,0]],"id":26349442},{"atb":[[2.48,2]],"id":40917619}],"con":true,"img":false}]}
{"op":"mcm","clk":"5348915143","pt":1646221901606,"mc":[{"id":"1.195453632","rc":[{"atl":[[2.72,43.6],[2.64,12.2],[2.68,29.76],[2.76,71.02]],"id":26349442},{"atb":[[2.5,4]],"id":40917619},{"atl":[[1.92,21.74],[1.91,0]],"id":41398505}],"con":true,"img":false}]}
{"op":"mcm","clk":"5348915158","pt":1646221901812,"mc":[{"id":"1.195453632","rc":[{"atb":[[1.33,60.61],[1.35,0]],"id":26349442},{"atl":[[2.42,64.78],[2.64,0]],"id":26349442},{"atb":[[2.5,0],[2.48,0],[2.46,0]],"id":40917619},{"atl":[[3.5,8]],"id":40917619}],"con":true,"img":false}]}
{"op":"mcm","clk":"5348915301","pt":1646221903526,"mc":[{"id":"1.195453632","rc":[{"spn":1.89,"spf":"NaN","id":26349442},{"spn":1.29,"spf":"NaN","id":41398505},{"atb":[[1.45,16.68]],"id":39183170},{"spn":1.99,"spf":"NaN","id":39183170}],"con":true,"img":false}]}
{"op":"mcm","clk":"5348915309","pt":1646221903630,"mc":[{"id":"1.195453632","rc":[{"atb":[[1.33,0],[1.35,57.14]],"id":26349442},{"atl":[[2.42,50.7],[2.64,12.2]],"id":26349442},{"atb":[[1.03,250]],"id":41398505},{"atl":[[1.39,0],[1.4,0],[1.41,0],[1.38,0]],"id":41398505},{"atb":[[2.5,0],[2.48,0],[2.52,0],[2.46,0]],"id":38554545},{"atl":[[3.85,0],[3.75,7.27]],"id":38554545}],"con":true,"img":false}]}
{"op":"mcm","clk":"5348915317","pt":1646221903687,"mc":[{"id":"1.195453632","rc":[{"atb":[[1.46,82.91],[1.42,0]],"id":39183170}],"con":true,"img":false}]}
{"op":"mcm","clk":"5348915331","pt":1646221903790,"mc":[{"id":"1.195453632","rc":[{"atl":[[2.64,0]],"id":26349442},{"atb":[[2.12,17.86],[2.16,44.64]],"id":38554545},{"atl":[[4.5,28.57],[3.4,3],[4.4,0]],"id":38554545}],"con":true,"img":false}]}
{"op":"mcm","clk":"5348915362","pt":1646221904104,"mc":[{"id":"1.195453632","rc":[{"atl":[[2.72,0],[2.68,0],[2.76,0]],"id":26349442},{"atb":[[1.43,99.59]],"id":39183170},{"atl":[[3.65,37.74],[3.75,0]],"id":39183170}],"con":true,"img":false}]}
{"op":"mcm","clk":"5348915373","pt":1646221904209,"mc":[{"id":"1.195453632","rc":[{"atl":[[2.54,88.51]],"id":26349442},{"atl":[[22,1]],"id":40637101},{"atb":[[1.45,44.44],[1.71,0],[1.35,76.78],[1.79,0],[1.81,0],[1.77,0],[1.75,0]],"id":36120434},{"atl":[[3.75,7.27]],"id":39183170},{"atb":[[2.3,44.64],[2.16,0]],"id":38554545},{"atl":[[2.74,3],[3.4,0]],"id":38554545}],"con":true,"img":false}]}
{"op":"mcm","clk":"5348915383","pt":1646221904314,"mc":[{"id":"1.195453632","rc":[{"atl":[[2.42,0]],"id":26349442},{"atl":[[19.5,5.41]],"id":40637101},{"atb":[[1.46,0]],"id":39183170}],"con":true,"img":false}]}
{"op":"mcm","clk":"5348915479","pt":1646221905208,"mc":[{"id":"1.195453632","rc":[{"atb":[[1.58,65.08]],"id":35381686}],"con":true,"img":false}]}
{"op":"mcm","clk":"5348915490","pt":1646221905316,"mc":[{"id":"1.195453632","rc":[{"atb":[[1.7,0]],"id":35381686}],"con":true,"img":false}]}
{"op":"mcm","clk":"5348915524","pt":1646221905625,"mc":[{"id":"1.195453632","rc":[{"atl":[[2.8,27.78],[2.88,66.49],[2.84,40.76],[2.76,11.36]],"id":26349442},{"atl":[[21,0]],"id":40637101},{"atl":[[2.76,3]],"id":38554545}],"con":true,"img":false}]}
{"op":"mcm","clk":"5348915556","pt":1646221905940,"mc":[{"id":"1.195453632","rc":[{"atl":[[2.76,0]],"id":26349442},{"atl":[[2.78,2]],"id":38554545}],"con":true,"img":false}]}
{"op":"mcm","clk":"5348915620","pt":1646221906619,"mc":[{"id":"1.195453632","rc":[{"atl":[[2.76,11.36]],"id":26349442},{"atb":[[1.45,0]],"id":39183170},{"atb":[[2.24,6.71]],"id":38554545},{"atl":[[2.72,2]],"id":38554545}],"con":true,"img":false}]}
{"op":"mcm","clk":"5348915687","pt":1646221907293,"mc":[{"id":"1.195453632","rc":[{"atl":[[2.54,101.5],[2.76,0]],"id":26349442},{"atl":[[3.75,0],[3.7,7.41]],"id":38554545}],"con":true,"img":false}]}
{"op":"mcm","clk":"5348915707","pt":1646221907499,"mc":[{"id":"1.195453632","rc":[{"atl":[[2.78,0],[2.7,2]],"id":38554545}],"con":true,"img":false}]}
{"op":"mcm","clk":"5348915802","pt":1646221908495,"mc":[{"id":"1.195453632","rc":[{"atb":[[1.4,84.78]],"id":26349442}],"con":true,"img":false}]}
{"op":"mcm","clk":"5348915810","pt":1646221908598,"mc":[{"id":"1.195453632","rc":[{"atb":[[1.38,0]],"id":26349442}],"con":true,"img":false}]}
{"op":"mcm","clk":"5348915833","pt":1646221908810,"mc":[{"id":"1.195453632","rc":[{"atl":[[2.76,0],[2.68,3]],"id":38554545}],"con":true,"img":false}]}
{"op":"mcm","clk":"5348915870","pt":1646221909244,"mc":[{"id":"1.195453632","rc":[{"atb":[[1.43,0],[1.42,199.18]],"id":39183170}],"con":true,"img":false}]}
{"op":"mcm","clk":"5348915888","pt":1646221909436,"mc":[{"id":"1.195453632","rc":[{"atl":[[8.6,8.08],[9.4,8.93]],"id":36120434}],"con":true,"img":false}]}
{"op":"mcm","clk":"5348915973","pt":1646221910525,"mc":[{"id":"1.195453632","rc":[{"atl":[[2.4,0]],"id":26349442},{"atl":[[8.8,0]],"id":36120434},{"atl":[[2.92,0],[3.35,15.51]],"id":39183170},{"atb":[[3.65,0]],"id":35381686}],"con":true,"img":false}]}
{"op":"mcm","clk":"5348915984","pt":1646221910626,"mc":[{"id":"1.195453632","rc":[{"atl":[[2.52,25.34]],"id":26349442},{"atl":[[9.2,5.45]],"id":36120434},{"atb":[[3.75,17.26]],"id":35381686}],"con":true,"img":false}]}
{"op":"mcm","clk":"5348916272","pt":1646221913893,"mc":[{"id":"1.195453632","rc":[{"atl":[[2.54,88.51],[2.76,11.36]],"id":26349442},{"atl":[[1.92,0],[1.93,55.57]],"id":41398505}],"con":true,"img":false}]}
{"op":"mcm","clk":"5348916289","pt":1646221914103,"mc":[{"id":"1.195453632","rc":[{"atl":[[2.76,0]],"id":26349442},{"atl":[[24,2.17]],"id":40637101},{"atb":[[1.43,116.28]],"id":36120434}],"con":true,"img":false}]}
{"op":"mcm","clk":"5348916298","pt":1646221914208,"mc":[{"id":"1.195453632","rc":[{"atl":[[3.85,17.54]],"id":39183170}],"con":true,"img":false}]}
{"op":"mcm","clk":"5348916321","pt":1646221914514,"mc":[{"id":"1.195453632","rc":[{"atl":[[8.6,2.63],[9,18.75]],"id":36120434}],"con":true,"img":false}]}
{"op":"mcm","clk":"5348916414","pt":1646221915606,"mc":[{"id":"1.195453632","rc":[{"atb":[[1.43,17.46]],"id":26349442},{"atb":[[1.45,16.68]],"id":39183170}],"con":true,"img":false}]}
{"op":"mcm","clk":"5348916425","pt":1646221915711,"mc":[{"id":"1.195453632","rc":[{"atb":[[1.4,0],[1.42,84.78]],"id":26349442}],"con":true,"img":false}]}
{"op":"mcm","clk":"5348916558","pt":1646221917322,"mc":[{"id":"1.195453632","rc":[{"atb":[[2.08,46.3]],"id":38554545},{"atl":[[3.8,17.86]],"id":38554545}],"con":true,"img":false}]}
{"op":"mcm","clk":"5348916593","pt":1646221917744,"mc":[{"id":"1.195453632","rc":[{"atb":[[1.43,82.91],[1.42,0]],"id":39183170}],"con":true,"img":false}]}
{"op":"mcm","clk":"5348916685","pt":1646221918827,"mc":[{"id":"1.195453632","rc":[{"atb":[[1.43,0]],"id":26349442},{"atb":[[1.45,0]],"id":39183170}],"con":true,"img":false}]}
{"op":"mcm","clk":"5348916701","pt":1646221919037,"mc":[{"id":"1.195453632","rc":[{"atl":[[2.54,101.5]],"id":26349442},{"atl":[[4.3,0],[3.95,0],[4.1,0]],"id":38554545}],"con":true,"img":false}]}
{"op":"mcm","clk":"5348916830","pt":1646221920506,"mc":[{"id":"1.195453632","rc":[{"atb":[[1.39,0]],"id":26349442},{"atl":[[2.92,0]],"id":26349442},{"atb":[[1.41,0]],"id":39183170},{"atb":[[2.18,0]],"id":38554545},{"atl":[[4,0]],"id":38554545}],"con":true,"img":false}]}
{"op":"mcm","clk":"5348916840","pt":1646221920617,"mc":[{"id":"1.195453632","rc":[{"atb":[[1.43,10],[1.37,84.78],[1.51,2.5],[1.42,191.22],[1.47,5]],"id":26349442},{"atl":[[2.82,25.61],[2.52,77.97]],"id":26349442},{"atb":[[1.43,239.96],[1.55,2.5],[1.51,5],[1.34,278.39],[1.47,10]],"id":39183170},{"atl":[[2.54,75.52],[2.74,123.97],[2.86,2.5],[2.94,42.42]],"id":39183170},{"atb":[[2.54,0],[2.3,48.39],[2.26,5],[2.1,45.41],[2.34,2.5],[2.18,10]],"id":38554545},{"atl":[[4.4,15.57]],"id":38554545}],"con":true,"img":false}]}
{"op":"mcm","clk":"5348916849","pt":1646221920715,"mc":[{"id":"1.195453632","rc":[{"atb":[[1.32,312.98]],"id":26349442},{"atl":[[2.74,123.97]],"id":26349442},{"atb":[[2.12,32.43]],"id":38554545}],"con":true,"img":false}]}
{"op":"mcm","clk":"5348916859","pt":1646221920818,"mc":[{"id":"1.195453632","rc":[{"atb":[[3.1,24.15],[3,60.37],[3.15,16.25],[3.3,2.5]],"id":40637101},{"atl":[[11.5,5],[9.8,10.75],[12.5,21.82],[13.5,12.97],[7.8,17.09]],"id":40637101},{"atb":[[3.6,93.25]],"id":36120434},{"atl":[[9,23.75],[9.2,29.95],[8.2,2.5],[8.4,10.81]],"id":36120434},{"atb":[[1.21,603.24],[1.26,10],[1.3,5],[1.34,2.5],[1.17,428.33]],"id":41398505},{"atl":[[1.96,193.15],[1.93,134.48]],"id":41398505},{"atb":[[3.85,52.27],[4.6,2.5],[4.1,6.08],[3.9,40.06],[4.2,5]],"id":35381686},{"atl":[[12.5,4.03]],"id":35381686},{"atb":[[2.3,3.75],[2.26,55.89]],"id":38554545}],"con":true,"img":false}]}
{"op":"mcm","clk":"5348916873","pt":1646221920924,"mc":[{"id":"1.195453632","rc":[{"atl":[[8.6,8.08],[9,11.25]],"id":36120434},{"atl":[[2.72,0],[2.74,0],[2.66,4]],"id":38554545}],"con":true,"img":false}]}
{"op":"mcm","clk":"5348916926","pt":1646221921646,"mc":[{"id":"1.195453632","rc":[{"atb":[[3.05,9.76]],"id":40637101}],"con":true,"img":false}]}
{"op":"mcm","clk":"5348917144","pt":1646221923927,"mc":[{"id":"1.195453632","rc":[{"atl":[[1.95,52.63]],"id":41398505}],"con":true,"img":false}]}
{"op":"mcm","clk":"5348917168","pt":1646221924132,"mc":[{"id":"1.195453632","rc":[{"atl":[[3.45,11.66],[3.7,142.54]],"id":40917619},{"atl":[[3.95,25.42]],"id":39183170}],"con":true,"img":false}]}
{"op":"mcm","clk":"5348917178","pt":1646221924245,"mc":[{"id":"1.195453632","rc":[{"atl":[[2.54,88.51],[2.76,11.36]],"id":26349442},{"atl":[[26,3]],"id":40637101},{"atb":[[1.41,182.93]],"id":36120434},{"atl":[[1.98,0],[1.96,115.03],[1.94,0]],"id":41398505},{"atl":[[15,0],[15.5,4.1]],"id":35381686},{"atl":[[2.64,3]],"id":38554545}],"con":true,"img":false}]}
{"op":"mcm","clk":"5348917199","pt":1646221924453,"mc":[{"id":"1.195453632","rc":[{"atl":[[2.76,0]],"id":26349442},{"atl":[[23,0],[25,0]],"id":40637101}],"con":true,"img":false}]}
{"op":"mcm","clk":"5348917221","pt":1646221924615,"mc":[{"id":"1.195453632","rc":[{"atb":[[1.45,16.68]],"id":26349442},{"atb":[[1.46,16.32]],"id":39183170}],"con":true,"img":false}]}
{"op":"mcm","clk":"5348917416","pt":1646221926631,"mc":[{"id":"1.195453632","rc":[{"atl":[[2.76,11.36]],"id":26349442},{"atl":[[2.62,2],[2.7,0]],"id":38554545}],"con":true,"img":false}]}
{"op":"mcm","clk":"5348917475","pt":1646221927314,"mc":[{"id":"1.195453632","rc":[{"atb":[[2.04,72.12]],"id":38554545},{"atl":[[3.9,25.86]],"id":38554545}],"con":true,"img":false}]}
{"op":"mcm","clk":"5348917507","pt":1646221927631,"mc":[{"id":"1.195453632","rc":[{"atb":[[3.15,19.74]],"id":40637101}],"con":true,"img":false}]}
{"op":"mcm","clk":"5348917532","pt":1646221927830,"mc":[{"id":"1.195453632","rc":[{"atb":[[3.2,19.74],[3.1,6.66]],"id":40637101}],"con":true,"img":false}]}
{"op":"mcm","clk":"5348917671","pt":1646221929235,"mc":[{"id":"1.195453632","rc":[{"atl":[[2.54,101.5],[2.76,0]],"id":26349442}],"con":true,"img":false}]}
{"op":"mcm","clk":"5348917679","pt":1646221929341,"mc":[{"id":"1.195453632","rc":[{"atl":[[2.62,0],[2.7,3]],"id":38554545}],"con":true,"img":false}]}
{"op":"mcm","clk":"5348917792","pt":1646221930653,"mc":[{"id":"1.195453632","rc":[{"atb":[[3.15,16.25]],"id":40637101},{"atl":[[5.5,0]],"id":38554545}],"con":true,"img":false}]}
{"op":"mcm","clk":"5348917805","pt":1646221930750,"mc":[{"id":"1.195453632","rc":[{"atl":[[5.9,9.63]],"id":38554545}],"con":true,"img":false}]}
{"op":"mcm","clk":"5348917816","pt":1646221930859,"mc":[{"id":"1.195453632","rc":[{"atb":[[3.2,0],[3.15,38.49]],"id":40637101}],"con":true,"img":false}]}
{"op":"mcm","clk":"5348918067","pt":1646221933942,"mc":[{"id":"1.195453632","rc":[{"atl":[[1.97,77.32]],"id":41398505}],"con":true,"img":false}]}
{"op":"mcm","clk":"5348918094","pt":1646221934245,"mc":[{"id":"1.195453632","rc":[{"atl":[[28,4.63]],"id":40637101},{"atb":[[1.39,250]],"id":36120434},{"atl":[[4.1,40.32]],"id":39183170},{"atl":[[16.5,3.23]],"id":35381686}],"con":true,"img":false}]}
{"op":"mcm","clk":"5348918311","pt":1646221936636,"mc":[{"id":"1.195453632","rc":[{"atl":[[2.54,88.51],[2.76,11.36]],"id":26349442},{"atl":[[16,0],[17,0],[18,0]],"id":35381686}],"con":true,"img":false}]}
{"op":"mcm","clk":"5348918326","pt":1646221936845,"mc":[{"id":"1.195453632","rc":[{"atl":[[2.76,0]],"id":26349442}],"con":true,"img":false}]}
{"op":"mcm","clk":"5348918376","pt":1646221937361,"mc":[{"id":"1.195453632","rc":[{"atb":[[2,125]],"id":38554545},{"atl":[[4,41.67]],"id":38554545}],"con":true,"img":false}]}
{"op":"mcm","clk":"5348918417","pt":1646221937629,"mc":[{"id":"1.195453632","rc":[{"atb":[[3.1,5]],"id":40637101},{"atb":[[4.1,4.42]],"id":35381686}],"con":true,"img":false}]}
{"op":"mcm","clk":"5348918429","pt":1646221937731,"mc":[{"id":"1.195453632","rc":[{"atb":[[3.1,45.99],[3.15,16.25]],"id":40637101}],"con":true,"img":false}]}
{"op":"mcm","clk":"5348918438","pt":1646221937834,"mc":[{"id":"1.195453632","rc":[{"atb":[[3.35,1.66]],"id":40637101},{"atb":[[4.7,1.66]],"id":35381686}],"con":true,"img":false}]}
{"op":"mcm","clk":"5348918470","pt":1646221938144,"mc":[{"id":"1.195453632","rc":[{"atb":[[1.51,73.5]],"id":26349442},{"atb":[[1.55,29.01],[1.47,63.03]],"id":39183170},{"atb":[[2.34,7.56]],"id":38554545}],"con":true,"img":false}]}
{"op":"mcm","clk":"5348918479","pt":1646221938250,"mc":[{"id":"1.195453632","rc":[{"atb":[[1.45,158.67],[1.32,142.24]],"id":26349442},{"atb":[[1.34,130.1]],"id":39183170},{"atb":[[2.12,17.86],[2.26,66.01]],"id":38554545}],"con":true,"img":false}]}
{"op":"mcm","clk":"5348918487","pt":1646221938353,"mc":[{"id":"1.195453632","rc":[{"atb":[[1.42,84.78]],"id":26349442},{"atb":[[3.1,86.49],[3.3,14.31]],"id":40637101},{"atl":[[11.5,25.69],[12.5,3.79]],"id":40637101},{"atl":[[8,11.43],[8.6,35.75],[9.2,5.45]],"id":36120434},{"atb":[[1.26,103.94],[1.34,49.47],[1.17,235.63]],"id":41398505},{"atb":[[1.43,165.82]],"id":39183170},{"atb":[[3.85,35.02],[4.1,16.84],[4.7,6.74]],"id":35381686},{"atb":[[2.3,0]],"id":38554545}],"con":true,"img":false}]}
{"op":"mcm","clk":"5348918494","pt":1646221938456,"mc":[{"id":"1.195453632","rc":[{"atb":[[3,27.86]],"id":40637101}],"con":true,"img":false}]}
{"op":"mcm","clk":"5348918505","pt":1646221938558,"mc":[{"id":"1.195453632","rc":[{"atb":[[3.15,0]],"id":40637101},{"atl":[[8.4,0]],"id":36120434},{"atb":[[1.21,475.33]],"id":41398505},{"atb":[[4.1,12.42]],"id":35381686}],"con":true,"img":false}]}
{"op":"mcm","clk":"5348918631","pt":1646221939967,"mc":[{"id":"1.195453632","rc":[{"atb":[[1.45,141.99]],"id":26349442},{"atb":[[1.46,0]],"id":39183170}],"con":true,"img":false}]}
{"op":"mcm","clk":"5348918675","pt":1646221940436,"mc":[{"id":"1.195453632","rc":[{"atb":[[1.28,99.62],[1.32,0]],"id":26349442},{"atl":[[2.82,0],[3.6,50.8]],"id":26349442},{"atb":[[2.82,0],[2.3,49.73]],"id":40637101},{"atl":[[13.5,25.43]],"id":40637101},{"atl":[[13,0],[27,11.46]],"id":36120434},{"atl":[[8,28.04],[5.5,0]],"id":40917619},{"atb":[[1.17,0]],"id":41398505},{"atl":[[2.52,61.72],[2.2,0]],"id":41398505},{"atb":[[1.43,82.91],[1.31,319.23],[1.34,0]],"id":39183170},{"atb":[[3.75,0],[3.65,25.43]],"id":35381686},{"atl":[[32,10.48],[15.5,1.38]],"id":35381686},{"atl":[[5.9,0],[8.4,26.42]],"id":38554545}],"con":true,"img":false}]}
{"op":"mcm","clk":"5348918685","pt":1646221940539,"mc":[{"id":"1.195453632","rc":[{"atb":[[1.12,235.63]],"id":41398505},{"atb":[[1.44,82.91]],"id":39183170}],"con":true,"img":false}]}
{"op":"mcm","clk":"5348918694","pt":1646221940642,"mc":[{"id":"1.195453632","rc":[{"atl":[[16,16.92],[13.5,10]],"id":40637101}],"con":true,"img":false}]}
{"op":"mcm","clk":"5348918710","pt":1646221940847,"mc":[{"id":"1.195453632","rc":[{"atb":[[1.86,0]],"id":38554545}],"con":true,"img":false}]}
{"op":"mcm","clk":"5348918718","pt":1646221940954,"mc":[{"id":"1.195453632","rc":[{"atb":[[1.91,45.94]],"id":38554545}],"con":true,"img":false}]}
{"op":"mcm","clk":"5348918786","pt":1646221941636,"mc":[{"id":"1.195453632","rc":[{"atl":[[3.7,80.96],[3.65,49.94]],"id":40917619}],"con":true,"img":false}]}
{"op":"mcm","clk":"5348918988","pt":1646221943926,"mc":[{"id":"1.195453632","rc":[{"atl":[[1.99,126.26]],"id":41398505}],"con":true,"img":false}]}
{"op":"mcm","clk":"5348919007","pt":1646221944133,"mc":[{"id":"1.195453632","rc":[{"atl":[[2.54,101.5]],"id":26349442}],"con":true,"img":false}]}
{"op":"mcm","clk":"5348919019","pt":1646221944244,"mc":[{"id":"1.195453632","rc":[{"atl":[[17.5,8.94]],"id":35381686}],"con":true,"img":false}]}
{"op":"mcm","clk":"5348919161","pt":1646221945742,"mc":[{"id":"1.195453632","rc":[{"atb":[[1.54,13.9]],"id":26349442},{"atb":[[3.15,3.49]],"id":40637101},{"atb":[[1.5,15.01]],"id":39183170}],"con":true,"img":false}]}
{"op":"mcm","clk":"5348919168","pt":1646221945843,"mc":[{"id":"1.195453632","rc":[{"atb":[[3.1,45.5],[3.35,15.97]],"id":40637101}],"con":true,"img":false}]}
{"op":"mcm","clk":"5348919182","pt":1646221946051,"mc":[{"id":"1.195453632","rc":[{"atb":[[3.35,1.66],[3.2,15.98]],"id":40637101}],"con":true,"img":false}]}
{"op":"mcm","clk":"5348919225","pt":1646221946466,"mc":[{"id":"1.195453632","rc":[{"atb":[[2.24,22.78]],"id":38554545}],"con":true,"img":false}]}
{"op":"mcm","clk":"5348919232","pt":1646221946571,"mc":[{"id":"1.195453632","rc":[{"atb":[[2.26,55.89],[2.24,96.35]],"id":38554545}],"con":true,"img":false}]}
{"op":"mcm","clk":"5348919240","pt":1646221946673,"mc":[{"id":"1.195453632","rc":[{"atb":[[2.26,5]],"id":38554545}],"con":true,"img":false}]}
{"op":"mcm","clk":"5348919491","pt":1646221949957,"mc":[{"id":"1.195453632","rc":[{"atl":[[2.54,88.51],[2.76,11.36]],"id":26349442}],"con":true,"img":false}]}
{"op":"mcm","clk":"5348919512","pt":1646221950261,"mc":[{"id":"1.195453632","rc":[{"atl":[[2.76,0]],"id":26349442}],"con":true,"img":false}]}
{"op":"mcm","clk":"5348919527","pt":1646221950473,"mc":[{"id":"1.195453632","rc":[{"atl":[[8.4,5.52]],"id":40637101},{"atb":[[2.74,44.53]],"id":36120434},{"atb":[[1.66,78.42]],"id":40917619},{"atl":[[3.35,52.35]],"id":39183170}],"con":true,"img":false}]}
{"op":"mcm","clk":"5348919537","pt":1646221950574,"mc":[{"id":"1.195453632","rc":[{"atl":[[12.5,0]],"id":40637101},{"atl":[[2.72,0]],"id":39183170}],"con":true,"img":false}]}
{"op":"mcm","clk":"5348919548","pt":1646221950675,"mc":[{"id":"1.195453632","rc":[{"atl":[[2.52,25.34]],"id":39183170}],"con":true,"img":false}]}
{"op":"mcm","clk":"5348919559","pt":1646221950778,"mc":[{"id":"1.195453632","rc":[{"atl":[[2.74,41.72],[2.86,68.54]],"id":39183170}],"con":true,"img":false}]}
{"op":"mcm","clk":"5348919567","pt":1646221950881,"mc":[{"id":"1.195453632","rc":[{"atl":[[2.52,66.11]],"id":39183170}],"con":true,"img":false}]}
{"op":"mcm","clk":"5348919585","pt":1646221951040,"mc":[{"id":"1.195453632","rc":[{"atl":[[2.54,23.57]],"id":39183170}],"con":true,"img":false}]}
{"op":"mcm","clk":"5348919839","pt":1646221954146,"mc":[{"id":"1.195453632","rc":[{"atb":[[3.35,15.97],[3.2,0]],"id":40637101}],"con":true,"img":false}]}
{"op":"mcm","clk":"5348919849","pt":1646221954247,"mc":[{"id":"1.195453632","rc":[{"atl":[[18.5,7.14]],"id":35381686}],"con":true,"img":false}]}
{"op":"mcm","clk":"5348919924","pt":1646221955379,"mc":[{"id":"1.195453632","rc":[{"atb":[[1.54,120.89]],"id":26349442},{"atb":[[1.5,93.88],[1.47,10]],"id":39183170}],"con":true,"img":false}]}
{"op":"mcm","clk":"5348919933","pt":1646221955490,"mc":[{"id":"1.195453632","rc":[{"atb":[[1.45,0],[1.47,175.21]],"id":26349442}],"con":true,"img":false}]}
{"op":"mcm","clk":"5348919943","pt":1646221955586,"mc":[{"id":"1.195453632","rc":[{"atb":[[1.51,2.5]],"id":26349442},{"atb":[[3.1,5],[3.35,34.77],[3.15,41.08]],"id":40637101},{"atl":[[11.5,5],[9.8,36.28]],"id":40637101},{"atb":[[4.1,0],[4.2,15.15]],"id":35381686}],"con":true,"img":false}]}
{"op":"mcm","clk":"5348919961","pt":1646221955800,"mc":[{"id":"1.195453632","rc":[{"atb":[[3.3,2.5]],"id":40637101}],"con":true,"img":false}]}
{"op":"mcm","clk":"5348919981","pt":1646221955957,"mc":[{"id":"1.195453632","rc":[{"atb":[[1.54,106.99]],"id":26349442},{"atb":[[3.15,37.59]],"id":40637101},{"atb":[[1.5,78.87]],"id":39183170}],"con":true,"img":false}]}
{"op":"mcm","clk":"5348920001","pt":1646221956160,"mc":[{"id":"1.195453632","rc":[{"atb":[[1.54,0]],"id":26349442}],"con":true,"img":false}]}
{"op":"mcm","clk":"5348920011","pt":1646221956264,"mc":[{"id":"1.195453632","rc":[{"atb":[[1.51,132.09]],"id":26349442}],"con":true,"img":false}]}
{"op":"mcm","clk":"5348920047","pt":1646221956674,"mc":[{"id":"1.195453632","rc":[{"atl":[[2.54,101.5],[2.76,11.36]],"id":26349442}],"con":true,"img":false}]}
{"op":"mcm","clk":"5348920066","pt":1646221956882,"mc":[{"id":"1.195453632","rc":[{"atl":[[2.8,0],[2.88,0],[2.84,0],[2.76,0]],"id":26349442}],"con":true,"img":false}]}
{"op":"mcm","clk":"5348920076","pt":1646221956987,"mc":[{"id":"1.195453632","rc":[{"atl":[[2.88,2.5]],"id":26349442}],"con":true,"img":false}]}
{"op":"mcm","clk":"5348920123","pt":1646221957563,"mc":[{"id":"1.195453632","rc":[{"atl":[[9.2,0]],"id":36120434},{"atb":[[3.9,27.24]],"id":35381686},{"atb":[[1.91,0]],"id":38554545},{"atl":[[4.4,0]],"id":38554545}],"con":true,"img":false}]}
{"op":"mcm","clk":"5348920136","pt":1646221957719,"mc":[{"id":"1.195453632","rc":[{"atl":[[8.4,5.45]],"id":36120434},{"atb":[[4.1,12.82]],"id":35381686},{"atb":[[1.86,45.94]],"id":38554545},{"atl":[[3.95,15.57]],"id":38554545}],"con":true,"img":false}]}
{"op":"mcm","clk":"5348920149","pt":1646221957878,"mc":[{"id":"1.195453632","rc":[{"atl":[[8.6,30.3],[8.2,16.39]],"id":36120434}],"con":true,"img":false}]}
{"op":"mcm","clk":"5348920158","pt":1646221957977,"mc":[{"id":"1.195453632","rc":[{"atl":[[8.6,2.63],[8.4,35.44]],"id":36120434}],"con":true,"img":false}]}
{"op":"mcm","clk":"5348920508","pt":1646221961882,"mc":[{"id":"1.195453632","rc":[{"atb":[[3.45,3.06]],"id":40637101},{"atb":[[1.53,14.16]],"id":39183170}],"con":true,"img":false}]}
{"op":"mcm","clk":"5348920533","pt":1646221962186,"mc":[{"id":"1.195453632","rc":[{"atb":[[3.35,20.46],[3.5,3.06]],"id":40637101}],"con":true,"img":false}]}
{"op":"mcm","clk":"5348920654","pt":1646221963484,"mc":[{"id":"1.195453632","rc":[{"atb":[[1.43,188.98]],"id":26349442}],"con":true,"img":false}]}
{"op":"mcm","clk":"5348920662","pt":1646221963588,"mc":[{"id":"1.195453632","rc":[{"atb":[[1.47,5]],"id":26349442},{"spn":2.01,"spf":"NaN","id":26349442},{"spn":5.65,"spf":"NaN","id":40637101},{"spn":5.97,"spf":"NaN","id":36120434},{"spn":2.76,"spf":"NaN","id":40917619},{"spn":1.63,"spf":"NaN","id":41398505},{"spn":2.03,"spf":"NaN","id":39183170},{"spn":8.6,"spf":"NaN","id":35381686},{"spn":2.49,"spf":"NaN","id":38554545}],"con":true,"img":false}]}
{"op":"mcm","clk":"5348920770","pt":1646221964892,"mc":[{"id":"1.195453632","rc":[{"atb":[[1.54,13.9]],"id":26349442},{"atb":[[3.45,0]],"id":40637101}],"con":true,"img":false}]}
{"op":"mcm","clk":"5348920793","pt":1646221965099,"mc":[{"id":"1.195453632","rc":[{"atb":[[3.35,40.93],[3.5,0]],"id":40637101}],"con":true,"img":false}]}
{"op":"mcm","clk":"5348920839","pt":1646221965672,"mc":[{"id":"1.195453632","rc":[{"atl":[[2.54,88.51],[2.76,11.36]],"id":26349442}],"con":true,"img":false}]}
{"op":"mcm","clk":"5348920857","pt":1646221965881,"mc":[{"id":"1.195453632","rc":[{"atl":[[2.76,0]],"id":26349442},{"atl":[[2.62,3],[2.7,0]],"id":38554545}],"con":true,"img":false}]}
{"op":"mcm","clk":"5348920954","pt":1646221966869,"mc":[{"id":"1.195453632","rc":[{"atl":[[2.8,27.78],[2.88,68.99],[2.84,40.76],[2.76,11.36]],"id":26349442}],"con":true,"img":false}]}
{"op":"mcm","clk":"5348921026","pt":1646221967673,"mc":[{"id":"1.195453632","rc":[{"atl":[[2.74,120.59],[2.86,2.5]],"id":39183170}],"con":true,"img":false}]}
{"op":"mcm","clk":"5348921267","pt":1646221970482,"mc":[{"id":"1.195453632","rc":[{"atl":[[3.7,64.82]],"id":40917619},{"atb":[[1.19,0]],"id":41398505},{"atl":[[2.52,40.77]],"id":39183170}],"con":true,"img":false}]}
{"op":"mcm","clk":"5348921279","pt":1646221970588,"mc":[{"id":"1.195453632","rc":[{"atl":[[3.6,16.14]],"id":40917619},{"atb":[[1.22,92.42]],"id":41398505},{"atl":[[2.8,25.34]],"id":39183170}],"con":true,"img":false}]}
{"op":"mcm","clk":"5348921300","pt":1646221970793,"mc":[{"id":"1.195453632","rc":[{"atl":[[3.6,65.26],[3.7,27.78],[3.55,39.22],[3.65,7.55]],"id":40917619}],"con":true,"img":false}]}
{"op":"mcm","clk":"5348921420","pt":1646221972199,"mc":[{"id":"1.195453632","rc":[{"atb":[[1.54,122.7]],"id":26349442},{"atb":[[1.51,83.87]],"id":39183170}],"con":true,"img":false}]}
{"op":"mcm","clk":"5348921429","pt":1646221972300,"mc":[{"id":"1.195453632","rc":[{"atb":[[1.43,10],[1.51,2.5],[1.47,183.41]],"id":26349442},{"atb":[[1.5,0]],"id":39183170}],"con":true,"img":false}]}
{"op":"mcm","clk":"5348921635","pt":1646221974829,"mc":[{"id":"1.195453632","rc":[{"atb":[[1.54,108.8]],"id":26349442},{"atb":[[3.45,3.06]],"id":40637101},{"atb":[[1.53,0]],"id":39183170}],"con":true,"img":false}]}
{"op":"mcm","clk":"5348921655","pt":1646221974979,"mc":[{"id":"1.195453632","rc":[{"atb":[[1.54,0]],"id":26349442},{"atb":[[3.35,20.46],[3.3,36.45],[3.5,3.06],[3.45,20.03],[3.15,0]],"id":40637101}],"con":true,"img":false}]}
{"op":"mcm","clk":"5348921661","pt":1646221975084,"mc":[{"id":"1.195453632","rc":[{"atb":[[1.51,134.56]],"id":26349442}],"con":true,"img":false}]}
{"op":"mcm","clk":"5348921669","pt":1646221975181,"mc":[{"id":"1.195453632","rc":[{"atb":[[3.35,1.66]],"id":40637101}],"con":true,"img":false}]}
{"op":"mcm","clk":"5348921735","pt":1646221976010,"mc":[{"id":"1.195453632","rc":[{"atl":[[2.76,0]],"id":26349442}],"con":true,"img":false}]}
{"op":"mcm","clk":"5348921822","pt":1646221976909,"mc":[{"id":"1.195453632","rc":[{"atb":[[1.33,151.52]],"id":26349442},{"atl":[[2.76,11.36]],"id":26349442}],"con":true,"img":false}]}
{"op":"mcm","clk":"5348922043","pt":1646221979494,"mc":[{"id":"1.195453632","rc":[{"atb":[[1.27,0]],"id":26349442},{"atl":[[2.76,0]],"id":26349442}],"con":true,"img":false}]}
{"op":"mcm","clk":"5348922072","pt":1646221979819,"mc":[{"id":"1.195453632","rc":[{"atl":[[2.76,11.36]],"id":26349442}],"con":true,"img":false}]}
{"op":"mcm","clk":"5348922079","pt":1646221979909,"mc":[{"id":"1.195453632","rc":[{"atb":[[3.45,16.97]],"id":40637101},{"atb":[[1.54,13.9]],"id":39183170}],"con":true,"img":false}]}
{"op":"mcm","clk":"5348922092","pt":1646221980026,"mc":[{"id":"1.195453632","rc":[{"atb":[[1.51,5],[1.47,114.67]],"id":39183170}],"con":true,"img":false}]}
{"op":"mcm","clk":"5348922100","pt":1646221980128,"mc":[{"id":"1.195453632","rc":[{"atb":[[1.43,197.3],[1.47,5]],"id":26349442},{"atb":[[3.4,20.03]],"id":40637101}],"con":true,"img":false}]}
{"op":"mcm","clk":"5348922110","pt":1646221980220,"mc":[{"id":"1.195453632","rc":[{"atb":[[3.5,0]],"id":40637101}],"con":true,"img":false}]}
{"op":"mcm","clk":"5348922140","pt":1646221980585,"mc":[{"id":"1.195453632","rc":[{"atb":[[1.28,0]],"id":26349442},{"atl":[[16,0],[8.4,0]],"id":40637101},{"atl":[[8.4,29.99]],"id":36120434},{"atb":[[4.1,0]],"id":35381686}],"con":true,"img":false}]}
{"op":"mcm","clk":"5348922152","pt":1646221980704,"mc":[{"id":"1.195453632","rc":[{"atb":[[1.26,99.62]],"id":26349442},{"atl":[[8.2,5.52],[13,16.92]],"id":40637101},{"atl":[[8,16.88]],"id":36120434},{"atb":[[4.3,12.82]],"id":35381686}],"con":true,"img":false}]}
{"op":"mcm","clk":"5348922159","pt":1646221980805,"mc":[{"id":"1.195453632","rc":[{"atl":[[11.5,28.32],[9.8,10.75]],"id":40637101},{"atl":[[8.2,2.5],[8.4,43.5]],"id":36120434}],"con":true,"img":false}]}
{"op":"mcm","clk":"5348922169","pt":1646221980907,"mc":[{"id":"1.195453632","rc":[{"atb":[[4.3,22.97],[4.2,5]],"id":35381686}],"con":true,"img":false}]}
{"op":"mcm","clk":"5348922178","pt":1646221981014,"mc":[{"id":"1.195453632","rc":[{"atl":[[11.5,5]],"id":40637101}],"con":true,"img":false}]}
{"op":"mcm","clk":"5348922361","pt":1646221983237,"mc":[{"id":"1.195453632","rc":[{"atb":[[1.54,0]],"id":39183170}],"con":true,"img":false}]}
{"op":"mcm","clk":"5348922412","pt":1646221983704,"mc":[{"id":"1.195453632","rc":[{"atl":[[2.76,0]],"id":26349442}],"con":true,"img":false}]}
{"op":"mcm","clk":"5348922625","pt":1646221986003,"mc":[{"id":"1.195453632","rc":[{"atb":[[1.54,13.9]],"id":26349442},{"atb":[[3.4,23.16]],"id":40637101}],"con":true,"img":false}]}
{"op":"mcm","clk":"5348922642","pt":1646221986215,"mc":[{"id":"1.195453632","rc":[{"atb":[[1.64,3]],"id":26349442}],"con":true,"img":false}]}
{"op":"mcm","clk":"5348922680","pt":1646221986626,"mc":[{"id":"1.195453632","rc":[{"atb":[[1.65,2]],"id":26349442},{"atl":[[2.76,11.36]],"id":26349442}],"con":true,"img":false}]}
{"op":"mcm","clk":"5348922702","pt":1646221986794,"mc":[{"id":"1.195453632","rc":[{"atb":[[1.66,3]],"id":26349442},{"atl":[[2.76,0]],"id":26349442},{"atb":[[4.8,2.5],[4.4,5],[4.6,0],[3.9,17.24],[4.2,0]],"id":35381686}],"con":true,"img":false}]}
{"op":"mcm","clk":"5348922707","pt":1646221986894,"mc":[{"id":"1.195453632","rc":[{"atb":[[4.9,3.92]],"id":35381686}],"con":true,"img":false}]}
{"op":"mcm","clk":"5348922726","pt":1646221987096,"mc":[{"id":"1.195453632","rc":[{"atb":[[4.7,1.66]],"id":35381686}],"con":true,"img":false}]}
{"op":"mcm","clk":"5348922734","pt":1646221987201,"mc":[{"id":"1.195453632","rc":[{"atb":[[1.67,2]],"id":26349442},{"atl":[[2.76,11.36]],"id":26349442}],"con":true,"img":false}]}
{"op":"mcm","clk":"5348922744","pt":1646221987305,"mc":[{"id":"1.195453632","rc":[{"atl":[[3.6,16.14],[3.55,116.11]],"id":40917619}],"con":true,"img":false}]}
{"op":"mcm","clk":"5348922754","pt":1646221987409,"mc":[{"id":"1.195453632","rc":[{"atb":[[1.43,10]],"id":26349442}],"con":true,"img":false}]}
{"op":"mcm","clk":"5348922773","pt":1646221987613,"mc":[{"id":"1.195453632","rc":[{"atb":[[3.35,0]],"id":40637101},{"atb":[[4.7,0]],"id":35381686}],"con":true,"img":false}]}
{"op":"mcm","clk":"5348922791","pt":1646221987830,"mc":[{"id":"1.195453632","rc":[{"atb":[[3.5,1.66]],"id":40637101},{"atb":[[5,1.66]],"id":35381686}],"con":true,"img":false}]}
{"op":"mcm","clk":"5348922806","pt":1646221988034,"mc":[{"id":"1.195453632","rc":[{"atb":[[3.5,18.63],[3.4,3.13]],"id":40637101}],"con":true,"img":false}]}
{"op":"mcm","clk":"5348922823","pt":1646221988192,"mc":[{"id":"1.195453632","rc":[{"atb":[[3.5,1.66],[3.45,40.13]],"id":40637101}],"con":true,"img":false}]}
{"op":"mcm","clk":"5348922854","pt":1646221988502,"mc":[{"id":"1.195453632","rc":[{"atl":[[8.2,16.39],[8.4,29.99]],"id":36120434}],"con":true,"img":false}]}
{"op":"mcm","clk":"5348922858","pt":1646221988604,"mc":[{"id":"1.195453632","rc":[{"atl":[[2.76,0]],"id":26349442}],"con":true,"img":false}]}
{"op":"mcm","clk":"5348922902","pt":1646221989121,"mc":[{"id":"1.195453632","rc":[{"atb":[[3.4,0]],"id":40637101}],"con":true,"img":false}]}
{"op":"mcm","clk":"5348922912","pt":1646221989223,"mc":[{"id":"1.195453632","rc":[{"atb":[[1.5,15.01]],"id":39183170}],"con":true,"img":false}]}
{"op":"mcm","clk":"5348922914","pt":1646221989324,"mc":[{"id":"1.195453632","rc":[{"atb":[[3.1,46.78]],"id":40637101}],"con":true,"img":false}]}
{"op":"mcm","clk":"5348922930","pt":1646221989441,"mc":[{"id":"1.195453632","rc":[{"atb":[[1.64,0],[1.67,0],[1.66,0],[1.65,0]],"id":26349442},{"atl":[[2.54,101.5],[2.76,11.36]],"id":26349442},{"atb":[[3.3,2.5]],"id":40637101},{"atl":[[1.92,21.74],[1.93,112.97]],"id":41398505},{"atb":[[1.5,93.88],[1.47,10]],"id":39183170}],"con":true,"img":false}]}
{"op":"mcm","clk":"5348922935","pt":1646221989533,"mc":[{"id":"1.195453632","rc":[{"atb":[[1.54,74.64]],"id":26349442}],"con":true,"img":false}]}
{"op":"mcm","clk":"5348922953","pt":1646221989638,"mc":[{"id":"1.195453632","rc":[{"atb":[[1.47,191.81]],"id":26349442},{"atl":[[1.92,98.31],[1.96,0],[1.95,193.46]],"id":41398505}],"con":true,"img":false}]}
{"op":"mcm","clk":"5348922957","pt":1646221989697,"mc":[{"id":"1.195453632","rc":[{"atb":[[1.51,2.5]],"id":26349442},{"atl":[[2.8,0],[2.88,2.5],[2.84,0],[2.76,0]],"id":26349442}],"con":true,"img":false}]}
{"op":"mcm","clk":"5348922975","pt":1646221989797,"mc":[{"id":"1.195453632","rc":[{"atl":[[1.93,34.06]],"id":41398505}],"con":true,"img":false}]}
{"op":"mcm","clk":"5348923039","pt":1646221990529,"mc":[{"id":"1.195453632","rc":[{"atl":[[2.8,0]],"id":39183170}],"con":true,"img":false}]}
{"op":"mcm","clk":"5348923048","pt":1646221990625,"mc":[{"id":"1.195453632","rc":[{"atl":[[2.72,25.34]],"id":39183170}],"con":true,"img":false}]}
{"op":"mcm","clk":"5348923070","pt":1646221990832,"mc":[{"id":"1.195453632","rc":[{"atl":[[2.72,106.88],[2.74,41.72]],"id":39183170}],"con":true,"img":false}]}
{"op":"mcm","clk":"5348923156","pt":1646221991931,"mc":[{"id":"1.195453632","rc":[{"atb":[[1.54,60.74]],"id":26349442},{"atb":[[1.5,78.87]],"id":39183170}],"con":true,"img":false}]}
{"op":"mcm","clk":"5348923179","pt":1646221992139,"mc":[{"id":"1.195453632","rc":[{"atb":[[1.54,0]],"id":26349442}],"con":true,"img":false}]}
{"op":"mcm","clk":"5348923191","pt":1646221992236,"mc":[{"id":"1.195453632","rc":[{"atb":[[1.51,137.11]],"id":26349442}],"con":true,"img":false}]}
{"op":"mcm","clk":"5348923419","pt":1646221994830,"mc":[{"id":"1.195453632","rc":[{"atb":[[3.55,2.94]],"id":40637101}],"con":true,"img":false}]}
{"op":"mcm","clk":"5348923435","pt":1646221995040,"mc":[{"id":"1.195453632","rc":[{"atb":[[3.1,5],[3.55,15.15],[3.3,26.92]],"id":40637101}],"con":true,"img":false}]}
{"op":"mcm","clk":"5348923444","pt":1646221995149,"mc":[{"id":"1.195453632","rc":[{"atb":[[3.45,23.16]],"id":40637101}],"con":true,"img":false}]}
{"op":"mcm","clk":"5348923510","pt":1646221995817,"mc":[{"id":"1.195453632","rc":[{"atb":[[3.55,30.3],[3.45,0]],"id":40637101}],"con":true,"img":false}]}
{"op":"mcm","clk":"5348923608","pt":1646221996918,"mc":[{"id":"1.195453632","rc":[{"atb":[[3.1,46.78],[3.3,2.5]],"id":40637101}],"con":true,"img":false}]}
{"op":"mcm","clk":"5348923617","pt":1646221997037,"mc":[{"id":"1.195453632","rc":[{"atl":[[2.88,0],[2.86,2.5]],"id":26349442},{"atb":[[3.1,41.78],[3.35,2.5],[3.3,0],[3.15,5]],"id":40637101}],"con":true,"img":false}]}
{"op":"mcm","clk":"5348923629","pt":1646221997124,"mc":[{"id":"1.195453632","rc":[{"atl":[[9.8,39.31]],"id":40637101}],"con":true,"img":false}]}
{"op":"mcm","clk":"5348923636","pt":1646221997226,"mc":[{"id":"1.195453632","rc":[{"atb":[[4.3,12.82],[4.4,15.15]],"id":35381686}],"con":true,"img":false}]}
{"op":"mcm","clk":"5348923646","pt":1646221997331,"mc":[{"id":"1.195453632","rc":[{"atb":[[1.43,205.86],[1.47,5]],"id":26349442}],"con":true,"img":false}]}
{"op":"mcm","clk":"5348923667","pt":1646221997635,"mc":[{"id":"1.195453632","rc":[{"atb":[[3.55,27.36]],"id":40637101},{"atl":[[8.6,0],[8.4,32.69]],"id":36120434},{"atl":[[3.55,123.95],[3.5,0]],"id":40917619},{"atl":[[3.7,0],[3.65,7.55]],"id":38554545}],"con":true,"img":false}]}
{"op":"mcm","clk":"5348923677","pt":1646221997745,"mc":[{"id":"1.195453632","rc":[{"atb":[[1.53,14.16]],"id":39183170}],"con":true,"img":false}]}
{"op":"mcm","clk":"5348923685","pt":1646221997843,"mc":[{"id":"1.195453632","rc":[{"atl":[[3.6,94.04],[3.55,47.06]],"id":40917619}],"con":true,"img":false}]}
{"op":"mcm","clk":"5348923698","pt":1646221997946,"mc":[{"id":"1.195453632","rc":[{"atl":[[3.45,0],[3.6,132.5],[3.55,7.84]],"id":40917619},{"atb":[[1.51,83.87],[1.5,0]],"id":39183170}],"con":true,"img":false}]}
{"op":"mcm","clk":"5348923707","pt":1646221998048,"mc":[{"id":"1.195453632","rc":[{"atl":[[3.5,32]],"id":40917619}],"con":true,"img":false}]}
{"op":"mcm","clk":"5348923801","pt":1646221999451,"mc":[{"id":"1.195453632","rc":[{"atb":[[1.31,403.23]],"id":26349442},{"atl":[[2.58,31.65]],"id":26349442}],"con":true,"img":false}]}
{"op":"mcm","clk":"5348923809","pt":1646221999504,"mc":[{"id":"1.195453632","rc":[{"atb":[[1.31,241.94]],"id":26349442}],"con":true,"img":false}]}
{"op":"mcm","clk":"5348923814","pt":1646221999607,"mc":[{"id":"1.195453632","rc":[{"atl":[[2.74,41.72],[2.58,140.85]],"id":26349442}],"con":true,"img":false}]}
{"op":"mcm","clk":"5348923927","pt":1646222000950,"mc":[{"id":"1.195453632","rc":[{"atb":[[1.54,13.9]],"id":26349442}],"con":true,"img":false}]}
{"op":"mcm","clk":"5348923938","pt":1646222001019,"mc":[{"id":"1.195453632","rc":[{"atb":[[3.5,41.66]],"id":40637101},{"atb":[[1.53,0]],"id":39183170}],"con":true,"img":false}]}
{"op":"mcm","clk":"5348923944","pt":1646222001115,"mc":[{"id":"1.195453632","rc":[{"atb":[[3.55,12.21]],"id":40637101}],"con":true,"img":false}]}
{"op":"mcm","clk":"5348924000","pt":1646222001845,"mc":[{"id":"1.195453632","rc":[{"atb":[[3.6,38.39]],"id":36120434},{"atb":[[1.57,0],[1.97,20.62],[1.91,0],[1.65,153.85]],"id":40917619},{"atl":[[1.92,76.57],[2.22,0],[1.9,22.22],[2.12,89.29]],"id":41398505},{"atl":[[2.86,0],[2.94,37.42]],"id":39183170},{"atb":[[1.58,0],[2.12,65.08]],"id":35381686},{"atl":[[16,1.33],[15.5,0]],"id":35381686},{"atl":[[3.75,7.27],[3.65,0]],"id":38554545}],"con":true,"img":false}]}
{"op":"mcm","clk":"5348924022","pt":1646222002051,"mc":[{"id":"1.195453632","rc":[{"atb":[[1.64,65.08],[2.12,0]],"id":35381686}],"con":true,"img":false}]}
{"op":"mcm","clk":"5348924029","pt":1646222002148,"mc":[{"id":"1.195453632","rc":[{"atb":[[1.63,4]],"id":26349442},{"atl":[[2.54,88.51],[2.58,109.2],[2.76,11.36]],"id":26349442}],"con":true,"img":false}]}
{"op":"mcm","clk":"5348924049","pt":1646222002309,"mc":[{"id":"1.195453632","rc":[{"atb":[[1.64,4]],"id":26349442},{"atl":[[2.76,0]],"id":26349442}],"con":true,"img":false}]}
{"op":"mcm","clk":"5348924120","pt":1646222003143,"mc":[{"id":"1.195453632","rc":[{"atb":[[5,5.58]],"id":35381686}],"con":true,"img":false}]}
{"op":"mcm","clk":"5348924130","pt":1646222003242,"mc":[{"id":"1.195453632","rc":[{"atb":[[1.65,3]],"id":26349442},{"atl":[[2.8,27.78],[2.88,66.49],[2.84,40.76],[2.76,11.36]],"id":26349442}],"con":true,"img":false}]}
{"op":"mcm","clk":"5348924136","pt":1646222003341,"mc":[{"id":"1.195453632","rc":[{"atb":[[4.9,0]],"id":35381686}],"con":true,"img":false}]}
{"op":"mcm","clk":"5348924144","pt":1646222003447,"mc":[{"id":"1.195453632","rc":[{"atb":[[1.43,10]],"id":26349442}],"con":true,"img":false}]}
{"op":"mcm","clk":"5348924165","pt":1646222003682,"mc":[{"id":"1.195453632","rc":[{"atb":[[3.5,40]],"id":40637101}],"con":true,"img":false}]}
{"op":"mcm","clk":"5348924189","pt":1646222003814,"mc":[{"id":"1.195453632","rc":[{"atb":[[3.6,1.66]],"id":40637101}],"con":true,"img":false}]}
{"op":"mcm","clk":"5348924328","pt":1646222005430,"mc":[{"id":"1.195453632","rc":[{"atb":[[3.1,0],[3.35,48.97]],"id":40637101},{"atb":[[1.51,5],[1.47,114.67]],"id":39183170}],"con":true,"img":false}]}
{"op":"mcm","clk":"5348924356","pt":1646222005744,"mc":[{"id":"1.195453632","rc":[{"atl":[[1.9,84.87],[1.93,159.36],[1.95,52.62]],"id":41398505}],"con":true,"img":false}]}
{"op":"mcm","clk":"5348924374","pt":1646222005944,"mc":[{"id":"1.195453632","rc":[{"atl":[[1.92,0]],"id":41398505}],"con":true,"img":false}]}
{"op":"mcm","clk":"5348924537","pt":1646222007928,"mc":[{"id":"1.195453632","rc":[{"atb":[[1.66,2]],"id":26349442},{"atl":[[2.76,0]],"id":26349442}],"con":true,"img":false}]}
{"op":"mcm","clk":"5348924588","pt":1646222008538,"mc":[{"id":"1.195453632","rc":[{"atb":[[3.6,13.87],[3.5,0]],"id":40637101}],"con":true,"img":false}]}
{"op":"mcm","clk":"5348924750","pt":1646222010463,"mc":[{"id":"1.195453632","rc":[{"atl":[[2.76,11.36]],"id":26349442}],"con":true,"img":false}]}
{"op":"mcm","clk":"5348924760","pt":1646222010563,"mc":[{"id":"1.195453632","rc":[{"atb":[[1.64,0],[1.63,0],[1.66,0],[1.65,0]],"id":26349442},{"atl":[[2.54,101.5]],"id":26349442},{"atl":[[1.93,125.3]],"id":41398505}],"con":true,"img":false}]}
{"op":"mcm","clk":"5348924767","pt":1646222010660,"mc":[{"id":"1.195453632","rc":[{"atb":[[1.54,75.38]],"id":26349442},{"atl":[[1.91,34.06]],"id":41398505}],"con":true,"img":false}]}
{"op":"mcm","clk":"5348924773","pt":1646222010764,"mc":[{"id":"1.195453632","rc":[{"atb":[[1.47,202.08]],"id":26349442},{"atl":[[2.8,0],[2.88,0],[2.84,0],[2.76,0]],"id":26349442}],"con":true,"img":false}]}
{"op":"mcm","clk":"5348924781","pt":1646222010870,"mc":[{"id":"1.195453632","rc":[{"atb":[[1.51,2.5]],"id":26349442}],"con":true,"img":false}]}
{"op":"mcm","clk":"5348924799","pt":1646222011041,"mc":[{"id":"1.195453632","rc":[{"atb":[[3.6,37.11]],"id":40637101}],"con":true,"img":false}]}
{"op":"mcm","clk":"5348924819","pt":1646222011237,"mc":[{"id":"1.195453632","rc":[{"atb":[[3.55,0]],"id":40637101}],"con":true,"img":false}]}
{"op":"mcm","clk":"5348924869","pt":1646222011862,"mc":[{"id":"1.195453632","rc":[{"atb":[[1.95,157.7]],"id":40917619},{"atl":[[3.65,18.87]],"id":40917619},{"atl":[[1.92,54.35]],"id":41398505},{"atl":[[17,3.12]],"id":35381686},{"atl":[[3.85,17.54]],"id":38554545}],"con":true,"img":false}]}
{"op":"mcm","clk":"5348924934","pt":1646222012744,"mc":[{"id":"1.195453632","rc":[{"atb":[[1.54,61.48]],"id":26349442},{"atb":[[1.5,15.01]],"id":39183170}],"con":true,"img":false}]}
{"op":"mcm","clk":"5348924954","pt":1646222012950,"mc":[{"id":"1.195453632","rc":[{"atb":[[1.54,0]],"id":26349442},{"atb":[[3.35,2.5],[3.15,86.33]],"id":40637101},{"atb":[[1.5,93.88],[1.47,10]],"id":39183170}],"con":true,"img":false}]}
{"op":"mcm","clk":"5348924975","pt":1646222013161,"mc":[{"id":"1.195453632","rc":[{"atb":[[1.47,336.69]],"id":26349442}],"con":true,"img":false}]}
{"op":"mcm","clk":"5348925203","pt":1646222016198,"mc":[{"id":"1.195453632","rc":[{"atb":[[1.5,78.87]],"id":39183170}],"con":true,"img":false}]}
{"op":"mcm","clk":"5348925246","pt":1646222016641,"mc":[{"id":"1.195453632","rc":[{"atb":[[1.63,3]],"id":26349442},{"atl":[[2.54,88.51],[2.76,11.36]],"id":26349442},{"atb":[[1.85,0]],"id":40917619},{"atl":[[1.99,0],[1.97,0],[1.95,0]],"id":41398505},{"atl":[[16.5,0],[17.5,4.39],[18.5,0]],"id":35381686},{"atl":[[3.8,0],[4,0],[3.9,0]],"id":38554545}],"con":true,"img":false}]}
{"op":"mcm","clk":"5348925267","pt":1646222016846,"mc":[{"id":"1.195453632","rc":[{"atb":[[1.64,3]],"id":26349442},{"atl":[[2.76,0]],"id":26349442}],"con":true,"img":false}]}
{"op":"mcm","clk":"5348925278","pt":1646222016955,"mc":[{"id":"1.195453632","rc":[{"atb":[[1.51,123.97]],"id":26349442}],"con":true,"img":false}]}
{"op":"mcm","clk":"5348925288","pt":1646222017059,"mc":[{"id":"1.195453632","rc":[{"atb":[[1.47,139.61]],"id":26349442}],"con":true,"img":false}]}
{"op":"mcm","clk":"5348925432","pt":1646222018761,"mc":[{"id":"1.195453632","rc":[{"atb":[[3.7,2.77]],"id":40637101}],"con":true,"img":false}]}
{"op":"mcm","clk":"5348925451","pt":1646222018976,"mc":[{"id":"1.195453632","rc":[{"atb":[[3.6,24.9],[3.7,5.55]],"id":40637101}],"con":true,"img":false}]}
{"op":"mcm","clk":"5348925512","pt":1646222019749,"mc":[{"id":"1.195453632","rc":[{"atb":[[3.6,23.24]],"id":40637101}],"con":true,"img":false}]}
{"op":"mcm","clk":"5348925528","pt":1646222019970,"mc":[{"id":"1.195453632","rc":[{"atb":[[3.75,1.66]],"id":40637101}],"con":true,"img":false}]}
{"op":"mcm","clk":"5348925568","pt":1646222020444,"mc":[{"id":"1.195453632","rc":[{"atl":[[8.2,0]],"id":40637101},{"atl":[[2.72,81.54]],"id":39183170},{"atb":[[4.3,0]],"id":35381686},{"atl":[[3.95,0]],"id":38554545}],"con":true,"img":false}]}
{"op":"mcm","clk":"5348925577","pt":1646222020547,"mc":[{"id":"1.195453632","rc":[{"atl":[[8,5.52]],"id":40637101},{"atl":[[2.7,25.34]],"id":39183170},{"atb":[[4.5,12.82]],"id":35381686},{"atl":[[4.4,15.57]],"id":38554545}],"con":true,"img":false}]}
{"op":"mcm","clk":"5348925589","pt":1646222020651,"mc":[{"id":"1.195453632","rc":[{"atl":[[11.5,30.8],[9.8,10.75]],"id":40637101},{"atl":[[2.72,0],[2.7,106.88]],"id":39183170},{"atb":[[4.4,5],[4.5,22.97]],"id":35381686}],"con":true,"img":false}]}
{"op":"mcm","clk":"5348925615","pt":1646222020856,"mc":[{"id":"1.195453632","rc":[{"atl":[[11.5,5]],"id":40637101}],"con":true,"img":false}]}
{"op":"mcm","clk":"5348925660","pt":1646222021271,"mc":[{"id":"1.195453632","rc":[{"atb":[[3.35,29.47],[3.15,5]],"id":40637101}],"con":true,"img":false}]}
{"op":"mcm","clk":"5348925680","pt":1646222021575,"mc":[{"id":"1.195453632","rc":[{"atl":[[1.92,209.27],[1.93,0]],"id":41398505}],"con":true,"img":false}]}
{"op":"mcm","clk":"5348925700","pt":1646222021872,"mc":[{"id":"1.195453632","rc":[{"atb":[[1.93,80.65]],"id":40917619},{"atl":[[3.75,27.27]],"id":40917619},{"atl":[[1.94,79.79]],"id":41398505},{"atb":[[1.53,14.16]],"id":39183170},{"atl":[[18,4.41]],"id":35381686},{"atl":[[3.95,25.42]],"id":38554545}],"con":true,"img":false}]}
{"op":"mcm","clk":"5348925721","pt":1646222022053,"mc":[{"id":"1.195453632","rc":[{"atb":[[1.51,83.87],[1.5,0]],"id":39183170}],"con":true,"img":false}]}
{"op":"mcm","clk":"5348925730","pt":1646222022149,"mc":[{"id":"1.195453632","rc":[{"atb":[[1.64,0],[1.63,0],[1.65,3]],"id":26349442},{"atl":[[2.8,27.78],[2.54,101.5],[2.58,140.85],[2.84,40.76],[2.62,46.3],[2.76,11.36],[2.88,66.49],[2.66,75.3]],"id":26349442},{"atb":[[1.87,0]],"id":40917619},{"atl":[[3.7,0],[3.8,0]],"id":40917619}],"con":true,"img":false}]}
{"op":"mcm","clk":"5348925753","pt":1646222022356,"mc":[{"id":"1.195453632","rc":[{"atb":[[1.47,342.31]],"id":26349442}],"con":true,"img":false}]}
{"op":"mcm","clk":"5348925763","pt":1646222022460,"mc":[{"id":"1.195453632","rc":[{"atb":[[1.51,2.5],[1.65,0]],"id":26349442},{"atl":[[2.8,0],[2.84,0],[2.76,0],[2.88,0]],"id":26349442}],"con":true,"img":false}]}
{"op":"mcm","clk":"5348925836","pt":1646222023353,"mc":[{"id":"1.195453632","rc":[{"atl":[[3.55,0],[3.65,7.55]],"id":40917619}],"con":true,"img":false}]}
{"op":"mcm","clk":"5348925842","pt":1646222023453,"mc":[{"id":"1.195453632","rc":[{"atl":[[8,34.03],[8.2,2.5],[8.4,29.99]],"id":36120434}],"con":true,"img":false}]}
{"op":"mcm","clk":"5348925851","pt":1646222023555,"mc":[{"id":"1.195453632","rc":[{"atl":[[8,19.74],[8.4,43.5]],"id":36120434},{"atl":[[3.6,54.6],[3.5,0],[3.65,89.42]],"id":40917619}],"con":true,"img":false}]}
{"op":"mcm","clk":"5348925862","pt":1646222023660,"mc":[{"id":"1.195453632","rc":[{"atb":[[3.25,8.89],[3.05,0]],"id":40637101},{"spn":5.77,"spf":"NaN","id":40637101},{"atl":[[8,16.88],[7.2,3.23]],"id":36120434},{"spn":5.57,"spf":"NaN","id":36120434},{"atl":[[3.55,31.37]],"id":40917619},{"spn":2.81,"spf":"NaN","id":40917619},{"spn":1.62,"spf":"NaN","id":41398505},{"spn":8.75,"spf":"NaN","id":35381686},{"spn":2.48,"spf":"NaN","id":38554545}],"con":true,"img":false}]}
{"op":"mcm","clk":"5348925870","pt":1646222023761,"mc":[{"id":"1.195453632","rc":[{"atl":[[7.8,26.47],[8.4,29.99]],"id":36120434},{"atl":[[5.1,13.85],[4.7,2.5]],"id":40917619}],"con":true,"img":false}]}
{"op":"mcm","clk":"5348925876","pt":1646222023868,"mc":[{"id":"1.195453632","rc":[{"atl":[[8.2,38.96],[8.4,0]],"id":36120434}],"con":true,"img":false}]}
{"op":"mcm","clk":"5348925883","pt":1646222023969,"mc":[{"id":"1.195453632","rc":[{"atl":[[8,5.45]],"id":36120434}],"con":true,"img":false}]}
{"op":"mcm","clk":"5348925902","pt":1646222024174,"mc":[{"id":"1.195453632","rc":[{"atl":[[2.86,0]],"id":26349442}],"con":true,"img":false}]}
{"op":"mcm","clk":"5348925921","pt":1646222024340,"mc":[{"id":"1.195453632","rc":[{"atb":[[1.43,219.38],[1.47,139.61]],"id":26349442}],"con":true,"img":false}]}
{"op":"mcm","clk":"5348925961","pt":1646222025066,"mc":[{"id":"1.195453632","rc":[{"atl":[[1.91,0]],"id":41398505},{"atb":[[1.53,0]],"id":39183170}],"con":true,"img":false}]}
{"op":"mcm","clk":"5348925971","pt":1646222025168,"mc":[{"id":"1.195453632","rc":[{"atl":[[1.89,34.06]],"id":41398505}],"con":true,"img":false}]}
{"op":"mcm","clk":"5348925988","pt":1646222025378,"mc":[{"id":"1.195453632","rc":[{"atl":[[1.89,121.15]],"id":41398505}],"con":true,"img":false}]}
{"op":"mcm","clk":"5348926000","pt":1646222025573,"mc":[{"id":"1.195453632","rc":[{"atl":[[1.9,22.22]],"id":41398505}],"con":true,"img":false}]}
{"op":"mcm","clk":"5348926070","pt":1646222026369,"mc":[{"id":"1.195453632","rc":[{"atb":[[1.51,123.93]],"id":26349442}],"con":true,"img":false}]}
{"op":"mcm","clk":"5348926088","pt":1646222026570,"mc":[{"id":"1.195453632","rc":[{"atb":[[1.47,4.99]],"id":26349442}],"con":true,"img":false}]}
{"op":"mcm","clk":"5348926103","pt":1646222026775,"mc":[{"id":"1.195453632","rc":[{"atb":[[3.7,17.78]],"id":40637101}],"con":true,"img":false}]}
{"op":"mcm","clk":"5348926123","pt":1646222026985,"mc":[{"id":"1.195453632","rc":[{"atb":[[3.6,0]],"id":40637101}],"con":true,"img":false}]}
{"op":"mcm","clk":"5348926206","pt":1646222027876,"mc":[{"id":"1.195453632","rc":[{"atb":[[3.7,15.01]],"id":40637101}],"con":true,"img":false}]}
{"op":"mcm","clk":"5348926283","pt":1646222028657,"mc":[{"id":"1.195453632","rc":[{"atb":[[3.35,2.5],[3.25,50.03]],"id":40637101}],"con":true,"img":false}]}
{"op":"mcm","clk":"5348926350","pt":1646222029444,"mc":[{"id":"1.195453632","rc":[{"atb":[[1.51,5],[1.47,114.67]],"id":39183170}],"con":true,"img":false}]}
{"op":"mcm","clk":"5348926379","pt":1646222029768,"mc":[{"id":"1.195453632","rc":[{"atl":[[2.6,3],[2.68,0]],"id":38554545}],"con":true,"img":false}]}
{"op":"mcm","clk":"5348926440","pt":1646222030484,"mc":[{"id":"1.195453632","rc":[{"atl":[[8,0],[13,0]],"id":40637101},{"atb":[[4.5,10.15]],"id":35381686},{"atl":[[4.8,10.75],[4.4,0]],"id":38554545}],"con":true,"img":false}]}
{"op":"mcm","clk":"5348926448","pt":1646222030582,"mc":[{"id":"1.195453632","rc":[{"atl":[[8.8,5.52],[14,16.92]],"id":40637101},{"atb":[[4.2,12.82]],"id":35381686}],"con":true,"img":false}]}
{"op":"mcm","clk":"5348926559","pt":1646222031888,"mc":[{"id":"1.195453632","rc":[{"atl":[[1.96,130.21]],"id":41398505},{"atl":[[19,6.94]],"id":35381686},{"atl":[[4.1,40.32]],"id":38554545}],"con":true,"img":false}]}
{"op":"mcm","clk":"5348926576","pt":1646222032087,"mc":[{"id":"1.195453632","rc":[{"atl":[[13.5,0]],"id":35381686}],"con":true,"img":false}]}
{"op":"mcm","clk":"5348926584","pt":1646222032148,"mc":[{"id":"1.195453632","rc":[{"atl":[[15,2.72]],"id":35381686}],"con":true,"img":false}]}
{"op":"mcm","clk":"5348926595","pt":1646222032255,"mc":[{"id":"1.195453632","rc":[{"atl":[[17,13.86]],"id":35381686}],"con":true,"img":false}]}
{"op":"mcm","clk":"5348926613","pt":1646222032462,"mc":[{"id":"1.195453632","rc":[{"atl":[[17,3.12]],"id":35381686}],"con":true,"img":false}]}
