{"op":"mcm","clk":"5345904395","pt":1646079078742,"mc":[{"id":"1.195395450","marketDefinition":{"bspMarket":false,"turnInPlayEnabled":false,"persistenceEnabled":false,"marketBaseRate":5.0,"eventId":"31270459","eventTypeId":"4339","numberOfWinners":3,"bettingType":"ODDS","marketType":"PLACE","marketTime":"2022-03-01T01:05:00.000Z","suspendTime":"2022-03-01T01:05:00.000Z","bspReconciled":false,"complete":true,"inPlay":false,"crossMatching":false,"runnersVoidable":false,"numberOfActiveRunners":8,"betDelay":0,"status":"OPEN","runners":[{"status":"ACTIVE","sortPriority":1,"id":43066393,"name":"1. Naya Bale"},{"status":"ACTIVE","sortPriority":2,"id":25760990,"name":"2. Darla Bale"},{"status":"ACTIVE","sortPriority":3,"id":37495442,"name":"3. Know Ego"},{"status":"ACTIVE","sortPriority":4,"id":40908100,"name":"4. Not So Simple"},{"status":"ACTIVE","sortPriority":5,"id":40494151,"name":"5. Money Bags"},{"status":"ACTIVE","sortPriority":6,"id":41962160,"name":"6. Opawa Nut"},{"status":"ACTIVE","sortPriority":7,"id":41360966,"name":"7. Sugar Time"},{"status":"ACTIVE","sortPriority":8,"id":40995914,"name":"8. Goldstar Butters"}],"regulators":["MR_INT"],"venue":"Addington","countryCode":"NZ","discountAllowed":false,"timezone":"NZ","openDate":"2022-02-28T23:02:00.000Z","version":4380660689,"name":"To Be Placed","eventName":"Addington (NZL) 1st Mar"},"rc":[],"con":true,"img":false}]}
{"op":"mcm","clk":"5345904630","pt":1646079080741,"mc":[{"id":"1.195395450","marketDefinition":{"bspMarket":false,"turnInPlayEnabled":false,"persistenceEnabled":false,"marketBaseRate":5.0,"eventId":"31270459","eventTypeId":"4339","numberOfWinners":3,"bettingType":"ODDS","marketType":"PLACE","marketTime":"2022-03-01T01:05:00.000Z","suspendTime":"2022-03-01T01:05:00.000Z","bspReconciled":false,"complete":true,"inPlay":false,"crossMatching":false,"runnersVoidable":false,"numberOfActiveRunners":8,"betDelay":0,"status":"OPEN","runners":[{"status":"ACTIVE","sortPriority":1,"id":43066393,"name":"1. Naya Bale"},{"status":"ACTIVE","sortPriority":2,"id":25760990,"name":"2. Darla Bale"},{"status":"ACTIVE","sortPriority":3,"id":37495442,"name":"3. Know Ego"},{"status":"ACTIVE","sortPriority":4,"id":40908100,"name":"4. Not So Simple"},{"status":"ACTIVE","sortPriority":5,"id":40494151,"name":"5. Money Bags"},{"status":"ACTIVE","sortPriority":6,"id":41962160,"name":"6. Opawa Nut"},{"status":"ACTIVE","sortPriority":7,"id":41360966,"name":"7. Sugar Time"},{"status":"ACTIVE","sortPriority":8,"id":40995914,"name":"8. Goldstar Butters"}],"regulators":["MR_INT"],"venue":"Addington","countryCode":"NZ","discountAllowed":true,"timezone":"NZ","openDate":"2022-02-28T23:02:00.000Z","version":4380660689,"name":"To Be Placed","eventName":"Addington (NZL) 1st Mar"},"rc":[],"con":true,"img":false}]}
{"op":"mcm","clk":"5346131645","pt":1646081590850,"mc":[{"id":"1.195395450","rc":[{"atb":[[2.88,63.92],[2.98,30.34],[2.78,67.51]],"id":37495442},{"atl":[[32,1.54],[10.5,1.26],[21,1.2],[8.2,1.66],[15.5,1.65]],"id":37495442},{"atb":[[2.88,63.92],[2.98,30.34],[2.78,67.51]],"id":40995914},{"atl":[[32,1.54],[10.5,1.26],[21,1.2],[8.2,1.66],[15.5,1.65]],"id":40995914},{"atb":[[2.74,69.06],[2.84,65.3],[2.94,30.97]],"id":41360966},{"atl":[[8,1.71],[10,1.33],[20,1.26],[15,1.71],[30,1.65]],"id":41360966},{"atb":[[2.06,56.68],[1.98,122.62],[1.93,129.21]],"id":40494151},{"atl":[[16,3.2],[6.4,2.22],[11,2.4],[5.2,2.86],[8.4,3.24]],"id":40494151},{"atb":[[2.06,56.68],[1.98,122.62],[1.93,129.21]],"id":41962160},{"atl":[[16,3.2],[6.4,2.22],[11,2.4],[5.2,2.86],[8.4,3.24]],"id":41962160},{"atb":[[2.88,63.92],[2.98,30.34],[2.78,67.51]],"id":25760990},{"atl":[[32,1.54],[10.5,1.26],[21,1.2],[8.2,1.66],[15.5,1.65]],"id":25760990},{"atb":[[1.2,600.84],[1.25,240.33],[1.15,801.12]],"id":40908100},{"atl":[[3.6,18.48],[3.1,11.44],[2.44,8.34],[2.64,7.32],[2.84,13.06]],"id":40908100},{"atb":[[1.01,30042.22]],"id":43066393},{"atl":[[2.72,27.94],[2.32,18.2],[2.52,15.81],[2.12,10.72],[1.96,12.52]],"id":43066393}],"con":true,"img":false}]}
{"op":"mcm","clk":"5346132705","pt":1646081605628,"mc":[{"id":"1.195395450","rc":[{"atb":[[2.88,0],[2.98,0],[2.78,0]],"id":37495442},{"atl":[[32,0],[10.5,0],[21,0],[8.2,0],[15.5,0]],"id":37495442},{"atb":[[2.88,0],[2.98,0],[2.78,0]],"id":40995914},{"atl":[[32,0],[10.5,0],[21,0],[8.2,0],[15.5,0]],"id":40995914},{"atb":[[2.74,0],[2.84,0],[2.94,0]],"id":41360966},{"atl":[[8,0],[10,0],[20,0],[15,0],[30,0]],"id":41360966},{"atb":[[2.06,0],[1.98,0],[1.93,0]],"id":40494151},{"atl":[[16,0],[6.4,0],[11,0],[5.2,0],[8.4,0]],"id":40494151},{"atb":[[2.06,0],[1.98,0],[1.93,0]],"id":41962160},{"atl":[[16,0],[6.4,0],[11,0],[5.2,0],[8.4,0]],"id":41962160},{"atb":[[2.88,0],[2.98,0],[2.78,0]],"id":25760990},{"atl":[[32,0],[10.5,0],[21,0],[8.2,0],[15.5,0]],"id":25760990},{"atb":[[1.2,0],[1.25,0],[1.15,0]],"id":40908100},{"atl":[[3.6,0],[3.1,0],[2.44,0],[2.64,0],[2.84,0]],"id":40908100},{"atb":[[1.01,0]],"id":43066393},{"atl":[[2.72,0],[2.32,0],[2.52,0],[2.12,0],[1.96,0]],"id":43066393}],"con":true,"img":false}]}
{"op":"mcm","clk":"5346133741","pt":1646081621322,"mc":[{"id":"1.195395450","rc":[{"atb":[[2.88,63.92],[2.98,30.34],[2.78,67.51]],"id":37495442},{"atl":[[32,1.54],[10.5,1.26],[21,1.2],[8.2,1.66],[15.5,1.65]],"id":37495442},{"atb":[[2.88,63.92],[2.98,30.34],[2.78,67.51]],"id":40995914},{"atl":[[32,1.54],[10.5,1.26],[21,1.2],[8.2,1.66],[15.5,1.65]],"id":40995914},{"atb":[[2.74,69.06],[2.84,65.3],[2.94,30.97]],"id":41360966},{"atl":[[8,1.71],[10,1.33],[20,1.26],[15,1.71],[30,1.65]],"id":41360966},{"atb":[[2.06,56.68],[1.98,122.62],[1.93,129.21]],"id":40494151},{"atl":[[16,3.2],[6.4,2.22],[11,2.4],[5.2,2.86],[8.4,3.24]],"id":40494151},{"atb":[[2.06,56.68],[1.98,122.62],[1.93,129.21]],"id":41962160},{"atl":[[16,3.2],[6.4,2.22],[11,2.4],[5.2,2.86],[8.4,3.24]],"id":41962160},{"atb":[[2.88,63.92],[2.98,30.34],[2.78,67.51]],"id":25760990},{"atl":[[32,1.54],[10.5,1.26],[21,1.2],[8.2,1.66],[15.5,1.65]],"id":25760990},{"atb":[[1.2,600.84],[1.25,240.33],[1.15,801.12]],"id":40908100},{"atl":[[3.6,18.48],[3.1,11.44],[2.44,8.34],[2.64,7.32],[2.84,13.06]],"id":40908100},{"atb":[[1.01,30042.22]],"id":43066393},{"atl":[[2.72,27.94],[2.32,18.2],[2.52,15.81],[2.12,10.72],[1.96,12.52]],"id":43066393}],"con":true,"img":false}]}
{"op":"mcm","clk":"5346134814","pt":1646081637861,"mc":[{"id":"1.195395450","rc":[{"atb":[[2.88,0],[2.98,0],[2.78,0]],"id":37495442},{"atl":[[32,0],[10.5,0],[21,0],[8.2,0],[15.5,0]],"id":37495442},{"atb":[[2.88,0],[2.98,0],[2.78,0]],"id":40995914},{"atl":[[32,0],[10.5,0],[21,0],[8.2,0],[15.5,0]],"id":40995914},{"atb":[[2.74,0],[2.84,0],[2.94,0]],"id":41360966},{"atl":[[8,0],[10,0],[20,0],[15,0],[30,0]],"id":41360966},{"atb":[[2.06,0],[1.98,0],[1.93,0]],"id":40494151},{"atl":[[16,0],[6.4,0],[11,0],[5.2,0],[8.4,0]],"id":40494151},{"atb":[[2.06,0],[1.98,0],[1.93,0]],"id":41962160},{"atl":[[16,0],[6.4,0],[11,0],[5.2,0],[8.4,0]],"id":41962160},{"atb":[[2.88,0],[2.98,0],[2.78,0]],"id":25760990},{"atl":[[32,0],[10.5,0],[21,0],[8.2,0],[15.5,0]],"id":25760990},{"atb":[[1.2,0],[1.25,0],[1.15,0]],"id":40908100},{"atl":[[3.6,0],[3.1,0],[2.44,0],[2.64,0],[2.84,0]],"id":40908100},{"atb":[[1.01,0]],"id":43066393},{"atl":[[2.72,0],[2.32,0],[2.52,0],[2.12,0],[1.96,0]],"id":43066393}],"con":true,"img":false}]}
{"op":"mcm","clk":"5346135981","pt":1646081656756,"mc":[{"id":"1.195395450","rc":[{"atb":[[2.88,63.92],[2.98,30.34],[2.78,67.51]],"id":40995914},{"atl":[[32,1.54],[10.5,1.26],[21,1.2],[8.2,1.66],[15.5,1.65]],"id":40995914},{"atb":[[2.88,63.92],[2.98,30.34],[2.78,67.51]],"id":37495442},{"atl":[[32,1.54],[10.5,1.26],[21,1.2],[8.2,1.66],[15.5,1.65]],"id":37495442},{"atb":[[2.74,69.06],[2.84,65.3],[2.94,30.97]],"id":41360966},{"atl":[[8,1.71],[10,1.33],[20,1.26],[15,1.71],[30,1.65]],"id":41360966},{"atb":[[2.06,56.68],[1.98,122.62],[1.93,129.21]],"id":40494151},{"atl":[[16,3.2],[6.4,2.22],[11,2.4],[5.2,2.86],[8.4,3.24]],"id":40494151},{"atb":[[2.06,56.68],[1.98,122.62],[1.93,129.21]],"id":41962160},{"atl":[[16,3.2],[6.4,2.22],[11,2.4],[5.2,2.86],[8.4,3.24]],"id":41962160},{"atb":[[2.88,63.92],[2.98,30.34],[2.78,67.51]],"id":25760990},{"atl":[[32,1.54],[10.5,1.26],[21,1.2],[8.2,1.66],[15.5,1.65]],"id":25760990},{"atb":[[1.2,600.84],[1.25,240.33],[1.15,801.12]],"id":40908100},{"atl":[[3.6,18.48],[3.1,11.44],[2.44,8.34],[2.64,7.32],[2.84,13.06]],"id":40908100},{"atb":[[1.01,30042.22]],"id":43066393},{"atl":[[2.72,27.94],[2.32,18.2],[2.52,15.81],[2.12,10.72],[1.96,12.52]],"id":43066393}],"con":true,"img":false}]}
{"op":"mcm","clk":"5346138721","pt":1646081695853,"mc":[{"id":"1.195395450","rc":[{"atb":[[2.88,0],[2.98,0],[2.78,0]],"id":40995914},{"atl":[[32,0],[10.5,0],[21,0],[8.2,0],[15.5,0]],"id":40995914},{"atb":[[2.88,0],[2.98,0],[2.78,0]],"id":37495442},{"atl":[[32,0],[10.5,0],[21,0],[8.2,0],[15.5,0]],"id":37495442},{"atb":[[2.74,0],[2.84,0],[2.94,0]],"id":41360966},{"atl":[[8,0],[10,0],[20,0],[15,0],[30,0]],"id":41360966},{"atb":[[2.06,0],[1.98,0],[1.93,0]],"id":40494151},{"atl":[[16,0],[6.4,0],[11,0],[5.2,0],[8.4,0]],"id":40494151},{"atb":[[2.06,0],[1.98,0],[1.93,0]],"id":41962160},{"atl":[[16,0],[6.4,0],[11,0],[5.2,0],[8.4,0]],"id":41962160},{"atb":[[2.88,0],[2.98,0],[2.78,0]],"id":25760990},{"atl":[[32,0],[10.5,0],[21,0],[8.2,0],[15.5,0]],"id":25760990},{"atb":[[1.2,0],[1.25,0],[1.15,0]],"id":40908100},{"atl":[[3.6,0],[3.1,0],[2.44,0],[2.64,0],[2.84,0]],"id":40908100},{"atb":[[1.01,0]],"id":43066393},{"atl":[[2.72,0],[2.32,0],[2.52,0],[2.12,0],[1.96,0]],"id":43066393}],"con":true,"img":false}]}
{"op":"mcm","clk":"5346140304","pt":1646081718873,"mc":[{"id":"1.195395450","rc":[{"atb":[[2.88,63.92],[2.98,30.34],[2.78,67.51]],"id":37495442},{"atl":[[32,1.54],[10.5,1.26],[21,1.2],[8.2,1.66],[15.5,1.65]],"id":37495442},{"atb":[[2.88,63.92],[2.98,30.34],[2.78,67.51]],"id":40995914},{"atl":[[32,1.54],[10.5,1.26],[21,1.2],[8.2,1.66],[15.5,1.65]],"id":40995914},{"atb":[[2.74,69.06],[2.84,65.3],[2.94,30.97]],"id":41360966},{"atl":[[8,1.71],[10,1.33],[20,1.26],[15,1.71],[30,1.65]],"id":41360966},{"atb":[[2.06,56.68],[1.98,122.62],[1.93,129.21]],"id":40494151},{"atl":[[16,3.2],[6.4,2.22],[11,2.4],[5.2,2.86],[8.4,3.24]],"id":40494151},{"atb":[[2.06,56.68],[1.98,122.62],[1.93,129.21]],"id":41962160},{"atl":[[16,3.2],[6.4,2.22],[11,2.4],[5.2,2.86],[8.4,3.24]],"id":41962160},{"atb":[[2.88,63.92],[2.98,30.34],[2.78,67.51]],"id":25760990},{"atl":[[32,1.54],[10.5,1.26],[21,1.2],[8.2,1.66],[15.5,1.65]],"id":25760990},{"atb":[[1.2,600.84],[1.25,240.33],[1.15,801.12]],"id":40908100},{"atl":[[3.6,18.48],[3.1,11.44],[2.44,8.34],[2.64,7.32],[2.84,13.06]],"id":40908100},{"atb":[[1.01,30042.22]],"id":43066393},{"atl":[[2.72,27.94],[2.32,18.2],[2.52,15.81],[2.12,10.72],[1.96,12.52]],"id":43066393}],"con":true,"img":false}]}
{"op":"mcm","clk":"5346223589","pt":1646082745859,"mc":[{"id":"1.195395450","rc":[{"atb":[[2.88,0],[2.98,0],[2.78,0]],"id":40995914},{"atl":[[32,0],[10.5,0],[21,0],[8.2,0],[15.5,0]],"id":40995914},{"atb":[[2.88,0],[2.98,0],[2.78,0]],"id":37495442},{"atl":[[32,0],[10.5,0],[21,0],[8.2,0],[15.5,0]],"id":37495442},{"atb":[[2.74,0],[2.84,0],[2.94,0]],"id":41360966},{"atl":[[8,0],[10,0],[20,0],[15,0],[30,0]],"id":41360966},{"atb":[[2.06,0],[1.98,0],[1.93,0]],"id":40494151},{"atl":[[16,0],[6.4,0],[11,0],[5.2,0],[8.4,0]],"id":40494151},{"atb":[[2.06,0],[1.98,0],[1.93,0]],"id":41962160},{"atl":[[16,0],[6.4,0],[11,0],[5.2,0],[8.4,0]],"id":41962160},{"atb":[[2.88,0],[2.98,0],[2.78,0]],"id":25760990},{"atl":[[32,0],[10.5,0],[21,0],[8.2,0],[15.5,0]],"id":25760990},{"atb":[[1.2,0],[1.25,0],[1.15,0]],"id":40908100},{"atl":[[3.6,0],[3.1,0],[2.44,0],[2.64,0],[2.84,0]],"id":40908100},{"atb":[[1.01,0]],"id":43066393},{"atl":[[2.72,0],[2.32,0],[2.52,0],[2.12,0],[1.96,0]],"id":43066393}],"con":true,"img":false}]}
{"op":"mcm","clk":"5346225933","pt":1646082773230,"mc":[{"id":"1.195395450","rc":[{"atb":[[2.88,63.92],[2.98,30.34],[2.78,67.51]],"id":40995914},{"atl":[[32,1.54],[10.5,1.26],[21,1.2],[8.2,1.66],[15.5,1.65]],"id":40995914},{"atb":[[2.88,63.92],[2.98,30.34],[2.78,67.51]],"id":37495442},{"atl":[[32,1.54],[10.5,1.26],[21,1.2],[8.2,1.66],[15.5,1.65]],"id":37495442},{"atb":[[2.74,69.06],[2.84,65.3],[2.94,30.97]],"id":41360966},{"atl":[[8,1.71],[10,1.33],[20,1.26],[15,1.71],[30,1.65]],"id":41360966},{"atb":[[2.06,56.68],[1.98,122.62],[1.93,129.21]],"id":40494151},{"atl":[[16,3.2],[6.4,2.22],[11,2.4],[5.2,2.86],[8.4,3.24]],"id":40494151},{"atb":[[2.06,56.68],[1.98,122.62],[1.93,129.21]],"id":41962160},{"atl":[[16,3.2],[6.4,2.22],[11,2.4],[5.2,2.86],[8.4,3.24]],"id":41962160},{"atb":[[2.88,63.92],[2.98,30.34],[2.78,67.51]],"id":25760990},{"atl":[[32,1.54],[10.5,1.26],[21,1.2],[8.2,1.66],[15.5,1.65]],"id":25760990},{"atb":[[1.2,600.84],[1.25,240.33],[1.15,801.12]],"id":40908100},{"atl":[[3.6,18.48],[3.1,11.44],[2.44,8.34],[2.64,7.32],[2.84,13.06]],"id":40908100},{"atb":[[1.01,30042.22]],"id":43066393},{"atl":[[2.72,27.94],[2.32,18.2],[2.52,15.81],[2.12,10.72],[1.96,12.52]],"id":43066393}],"con":true,"img":false}]}
{"op":"mcm","clk":"5346426194","pt":1646086073767,"mc":[{"id":"1.195395450","rc":[{"atb":[[2.88,0],[2.98,0],[2.78,0]],"id":37495442},{"atl":[[32,0],[10.5,0],[21,0],[8.2,0],[15.5,0]],"id":37495442},{"atb":[[2.88,0],[2.98,0],[2.78,0]],"id":40995914},{"atl":[[32,0],[10.5,0],[21,0],[8.2,0],[15.5,0]],"id":40995914},{"atb":[[2.74,0],[2.84,0],[2.94,0]],"id":41360966},{"atl":[[8,0],[10,0],[20,0],[15,0],[30,0]],"id":41360966},{"atb":[[2.06,0],[1.98,0],[1.93,0]],"id":40494151},{"atl":[[16,0],[6.4,0],[11,0],[5.2,0],[8.4,0]],"id":40494151},{"atb":[[2.06,0],[1.98,0],[1.93,0]],"id":41962160},{"atl":[[16,0],[6.4,0],[11,0],[5.2,0],[8.4,0]],"id":41962160},{"atb":[[2.88,0],[2.98,0],[2.78,0]],"id":25760990},{"atl":[[32,0],[10.5,0],[21,0],[8.2,0],[15.5,0]],"id":25760990},{"atb":[[1.2,0],[1.25,0],[1.15,0]],"id":40908100},{"atl":[[3.6,0],[3.1,0],[2.44,0],[2.64,0],[2.84,0]],"id":40908100},{"atb":[[1.01,0]],"id":43066393},{"atl":[[2.72,0],[2.32,0],[2.52,0],[2.12,0],[1.96,0]],"id":43066393}],"con":true,"img":false}]}
{"op":"mcm","clk":"5346426617","pt":1646086084569,"mc":[{"id":"1.195395450","rc":[{"atb":[[2.8,33.37],[2.6,75.09],[2.7,70.67]],"id":40995914},{"atl":[[7.2,1.93],[18,1.41],[9.2,1.46],[13,2],[26,1.92]],"id":40995914},{"atb":[[2.8,66.74],[2.9,31.61],[2.7,70.67]],"id":37495442},{"atl":[[19.5,1.29],[9.8,1.36],[7.8,1.76],[14.5,1.78],[29,1.71]],"id":37495442},{"atb":[[2.8,66.74],[2.9,31.61],[2.7,70.67]],"id":41360966},{"atl":[[19.5,1.29],[9.8,1.36],[7.8,1.76],[14.5,1.78],[29,1.71]],"id":41360966},{"atb":[[2,60.07],[1.9,133.5],[1.95,126.47]],"id":40494151},{"atl":[[5.1,2.92],[6.2,2.31],[10.5,2.52],[8.2,3.33],[15.5,3.31]],"id":40494151},{"atb":[[2,60.07],[1.9,133.5],[1.95,126.47]],"id":41962160},{"atl":[[5.1,2.92],[6.2,2.31],[10.5,2.52],[8.2,3.33],[15.5,3.31]],"id":41962160},{"atb":[[2.8,66.74],[2.9,31.61],[2.7,70.67]],"id":25760990},{"atl":[[19.5,1.29],[9.8,1.36],[7.8,1.76],[14.5,1.78],[29,1.71]],"id":25760990},{"atb":[[1.2,600.74],[1.25,480.59],[1.3,200.24]],"id":40908100},{"atl":[[2.54,7.8],[3.85,16.86],[2.74,6.9],[3.35,10.22],[2.94,12.38]],"id":40908100},{"atb":[[1.01,30037.34]],"id":43066393},{"atl":[[2.36,17.67],[2.56,15.4],[1.98,12.25],[2.16,10.35],[2.76,27.3]],"id":43066393}],"con":true,"img":false}]}
{"op":"mcm","clk":"5346429419","pt":1646086162100,"mc":[{"id":"1.195395450","rc":[{"atb":[[2.8,0],[2.9,0],[2.7,0]],"id":41360966},{"atl":[[19.5,0],[9.8,0],[7.8,0],[14.5,0],[29,0]],"id":41360966},{"atb":[[2,0],[1.9,0],[1.95,0]],"id":41962160},{"atl":[[5.1,0],[6.2,0],[10.5,0],[8.2,0],[15.5,0]],"id":41962160},{"atb":[[1.01,0]],"id":43066393},{"atl":[[2.36,0],[2.56,0],[1.98,0],[2.16,0],[2.76,0]],"id":43066393}],"con":true,"img":false}]}
{"op":"mcm","clk":"5346429715","pt":1646086168572,"mc":[{"id":"1.195395450","rc":[{"atb":[[2.8,66.74],[2.9,31.61],[2.7,70.67]],"id":41360966},{"atl":[[19.5,1.29],[9.8,1.36],[7.8,1.76],[14.5,1.78],[29,1.71]],"id":41360966},{"atb":[[2,60.07],[1.9,133.5],[1.95,126.47]],"id":41962160},{"atl":[[5.1,2.92],[6.2,2.31],[10.5,2.52],[8.2,3.33],[15.5,3.31]],"id":41962160},{"atb":[[1.01,30037.34]],"id":43066393},{"atl":[[2.36,17.67],[2.56,15.4],[1.98,12.25],[2.16,10.35],[2.76,27.3]],"id":43066393}],"con":true,"img":false}]}
{"op":"mcm","clk":"5346431801","pt":1646086222846,"mc":[{"id":"1.195395450","rc":[{"atb":[[2.8,0],[2.9,0],[2.7,0]],"id":37495442},{"atl":[[19.5,0],[9.8,0],[7.8,0],[14.5,0],[29,0]],"id":37495442}],"con":true,"img":false}]}
{"op":"mcm","clk":"5346432177","pt":1646086230481,"mc":[{"id":"1.195395450","rc":[{"atb":[[3.1,57.21],[3.35,25.56],[2.94,61.93]],"id":37495442},{"atl":[[17,1.5],[38,1.29],[12,1.09],[24,1.04],[8.8,1.54]],"id":37495442}],"con":true,"img":false}]}
{"op":"mcm","clk":"5346433294","pt":1646086253622,"mc":[{"id":"1.195395450","rc":[{"atb":[[3.1,0],[3.35,0],[2.94,0]],"id":37495442},{"atl":[[17,0],[38,0],[12,0],[24,0],[8.8,0]],"id":37495442}],"con":true,"img":false}]}
{"op":"mcm","clk":"5346433716","pt":1646086264498,"mc":[{"id":"1.195395450","rc":[{"atb":[[2.9,63.23],[3,60.07],[3.25,26.69]],"id":37495442},{"atl":[[16,1.6],[34,1.45],[11,1.2],[22,1.14],[8.4,1.62]],"id":37495442}],"con":true,"img":false}]}
{"op":"mcm","clk":"5346584776","pt":1646091393453,"mc":[{"id":"1.195395450","rc":[{"atb":[[2.82,22.3],[2.58,27.6]],"id":37495442},{"atl":[[12,3.69],[13,3.78]],"id":37495442},{"atb":[[2.38,29.41],[2.2,35.17]],"id":40995914},{"atl":[[9.6,4.87],[8.6,5.34]],"id":40995914},{"atb":[[2.82,22.3],[2.58,27.6]],"id":41360966},{"atl":[[11.5,3.86],[13,3.78]],"id":41360966},{"atb":[[2.28,33.01],[2.48,27.42]],"id":40494151},{"atl":[[10.5,6.79],[11.5,3.78]],"id":40494151},{"atb":[[1.79,54.12],[1.91,40.59]],"id":41962160},{"atl":[[6,8.11],[6.8,7.57]],"id":41962160},{"atb":[[2.64,24.74],[2.44,28.62]],"id":25760990},{"atl":[[11,4.05],[12,3.74]],"id":25760990},{"atb":[[1.26,184.57]],"id":40908100},{"atl":[[2.52,51.32]],"id":40908100},{"atb":[[1.02,1916.79]],"id":43066393},{"atl":[[1.45,83.38],[1.38,40.59]],"id":43066393}],"con":true,"img":false}]}
{"op":"mcm","clk":"5346587188","pt":1646091479663,"mc":[{"id":"1.195395450","rc":[{"atb":[[2.38,0]],"id":40995914},{"atb":[[2.82,0]],"id":37495442},{"atb":[[2.82,0],[2.58,0]],"id":41360966},{"atl":[[10,4.87],[10.5,2.52],[11.5,0]],"id":40494151},{"atb":[[1.79,0],[1.91,0]],"id":41962160},{"atb":[[2.64,0]],"id":25760990}],"con":true,"img":false}]}
{"op":"mcm","clk":"5346587191","pt":1646091479766,"mc":[{"id":"1.195395450","rc":[{"atb":[[2.42,29.41]],"id":40995914},{"atb":[[3.05,22.3]],"id":37495442},{"atb":[[2.82,27.6],[2.92,22.3]],"id":41360966},{"atl":[[8,4.27]],"id":40494151},{"atb":[[2.02,40.59],[1.91,54.12]],"id":41962160},{"atb":[[2.82,24.74]],"id":25760990}],"con":true,"img":false}]}
{"op":"mcm","clk":"5346595082","pt":1646091773717,"mc":[{"id":"1.195395450","rc":[{"atb":[[2.9,0],[3,0],[3.25,0]],"id":37495442},{"atl":[[16,0],[34,0],[11,0],[22,0],[8.4,0]],"id":37495442},{"atb":[[2.8,0],[2.6,0],[2.7,0]],"id":40995914},{"atl":[[7.2,0],[18,0],[9.2,0],[13,0],[26,0]],"id":40995914},{"atb":[[2.8,0],[2.9,0],[2.7,0]],"id":41360966},{"atl":[[19.5,0],[9.8,0],[7.8,0],[14.5,0],[29,0]],"id":41360966},{"atb":[[2,0],[1.9,0],[1.95,0]],"id":40494151},{"atl":[[5.1,0],[6.2,0],[10.5,0],[8.2,0],[15.5,0]],"id":40494151},{"atb":[[2.8,0],[2.9,0],[2.7,0]],"id":25760990},{"atl":[[19.5,0],[9.8,0],[7.8,0],[14.5,0],[29,0]],"id":25760990},{"atb":[[1.01,0]],"id":43066393},{"atl":[[2.36,0],[2.56,0],[1.98,0],[2.16,0],[2.76,0]],"id":43066393}],"con":true,"img":false}]}
{"op":"mcm","clk":"5346595187","pt":1646091778633,"mc":[{"id":"1.195395450","rc":[{"atb":[[2.74,69.05],[2.84,65.29],[2.94,30.96]],"id":37495442},{"atl":[[8,1.71],[10,1.33],[20,1.26],[15,1.71],[30,1.65]],"id":37495442},{"atb":[[2.4,42.91],[2.3,92.42],[2.2,135.3]],"id":40995914},{"atl":[[9.6,7.66],[19,2.66],[5.8,2.5],[7.6,1.81],[14,1.85]],"id":40995914},{"atb":[[2.74,69.05],[2.84,65.29],[2.94,30.96]],"id":41360966},{"atl":[[8,1.71],[10,1.33],[20,1.26],[15,1.71],[30,1.65]],"id":41360966},{"atb":[[2.4,42.91],[2.3,92.42],[2.2,100.12]],"id":40494151},{"atl":[[9.6,2.79],[19,2.66],[5.8,2.5],[7.6,1.81],[14,1.85]],"id":40494151},{"atb":[[2.4,85.82],[2.5,80.09],[2.6,37.54]],"id":25760990},{"atl":[[6.2,2.31],[10.5,2.52],[21,2.4],[8.2,1.66],[15.5,1.65]],"id":25760990},{"atb":[[1.01,30037.34]],"id":43066393},{"atl":[[2.28,18.77],[1.94,12.78],[2.68,28.6],[2.08,11.12],[2.48,16.23]],"id":43066393}],"con":true,"img":false}]}
{"op":"mcm","clk":"5346595442","pt":1646091787152,"mc":[{"id":"1.195395450","rc":[{"atb":[[2.82,0]],"id":41360966},{"atl":[[8,0],[10,0],[11.5,3.78]],"id":40494151}],"con":true,"img":false}]}
{"op":"mcm","clk":"5346595447","pt":1646091787208,"mc":[{"id":"1.195395450","rc":[{"atb":[[2.76,27.6]],"id":41360966},{"atl":[[10.5,4.27]],"id":40494151}],"con":true,"img":false}]}
{"op":"mcm","clk":"5346596119","pt":1646091812760,"mc":[{"id":"1.195395450","rc":[{"atb":[[3.05,0]],"id":37495442},{"atb":[[2.82,0]],"id":25760990}],"con":true,"img":false}]}
{"op":"mcm","clk":"5346596121","pt":1646091812865,"mc":[{"id":"1.195395450","rc":[{"atb":[[2.96,22.3]],"id":37495442},{"atb":[[2.64,24.74]],"id":25760990}],"con":true,"img":false}]}
{"op":"mcm","clk":"5346596839","pt":1646091837100,"mc":[{"id":"1.195395450","rc":[{"atb":[[2.92,0]],"id":41360966}],"con":true,"img":false}]}
{"op":"mcm","clk":"5346596842","pt":1646091837204,"mc":[{"id":"1.195395450","rc":[{"atb":[[2.96,22.3]],"id":41360966}],"con":true,"img":false}]}
{"op":"mcm","clk":"5346597638","pt":1646091863350,"mc":[{"id":"1.195395450","rc":[{"atb":[[2.58,0]],"id":37495442},{"atb":[[2.2,100.12]],"id":40995914},{"atb":[[2.28,0]],"id":40494151},{"atb":[[2.44,0]],"id":25760990}],"con":true,"img":false}]}
{"op":"mcm","clk":"5346597644","pt":1646091863408,"mc":[{"id":"1.195395450","rc":[{"atb":[[2.32,35.17]],"id":40995914},{"atb":[[2.76,27.6]],"id":37495442},{"atb":[[2.32,33.01]],"id":40494151},{"atb":[[2.52,28.62]],"id":25760990}],"con":true,"img":false}]}
{"op":"mcm","clk":"5346598607","pt":1646091890258,"mc":[{"id":"1.195395450","rc":[{"atb":[[1.91,0]],"id":41962160}],"con":true,"img":false}]}
{"op":"mcm","clk":"5346598610","pt":1646091890360,"mc":[{"id":"1.195395450","rc":[{"atb":[[1.79,54.12]],"id":41962160}],"con":true,"img":false}]}
{"op":"mcm","clk":"5346627144","pt":1646092723639,"mc":[{"id":"1.195395450","rc":[{"atl":[[1.11,81.18]],"id":43066393}],"con":true,"img":false}]}
{"op":"mcm","clk":"5346627844","pt":1646092744153,"mc":[{"id":"1.195395450","rc":[{"atb":[[2.32,0]],"id":40995914},{"atb":[[2.26,34.09],[2.76,0]],"id":37495442},{"atb":[[2.24,34.63],[2.76,0]],"id":41360966},{"atb":[[2.32,0],[2.48,0]],"id":40494151},{"atb":[[2.52,0],[2.64,0],[2.18,34.93]],"id":25760990},{"atl":[[2.52,26.7],[3.3,16.27]],"id":40908100},{"atl":[[1.45,0],[1.93,40.34],[1.38,0]],"id":43066393}],"con":true,"img":false}]}
{"op":"mcm","clk":"5346627849","pt":1646092744254,"mc":[{"id":"1.195395450","rc":[{"atb":[[2.04,35.17]],"id":40995914},{"atb":[[2.42,27.42],[2.22,33.01]],"id":40494151},{"atb":[[2.62,24.74]],"id":25760990},{"atl":[[1.82,40.59]],"id":43066393}],"con":true,"img":false}]}
{"op":"mcm","clk":"5346628509","pt":1646092764980,"mc":[{"id":"1.195395450","rc":[{"atl":[[8.6,0]],"id":40995914},{"atl":[[12,0]],"id":37495442},{"atl":[[11.5,0]],"id":41360966},{"atl":[[10.5,0]],"id":40494151},{"atl":[[11,0]],"id":25760990}],"con":true,"img":false}]}
{"op":"mcm","clk":"5346628514","pt":1646092765082,"mc":[{"id":"1.195395450","rc":[{"atl":[[9.4,3.69]],"id":37495442},{"atl":[[8,5.34]],"id":40995914},{"atl":[[9.4,3.86]],"id":41360966},{"atl":[[8.4,4.27]],"id":40494151},{"atl":[[9,4.05]],"id":25760990}],"con":true,"img":false}]}
{"op":"mcm","clk":"5346629186","pt":1646092785499,"mc":[{"id":"1.195395450","rc":[{"atl":[[10,4.57]],"id":25760990}],"con":true,"img":false}]}
{"op":"mcm","clk":"5346629188","pt":1646092785602,"mc":[{"id":"1.195395450","rc":[{"atl":[[9.4,4.87]],"id":40494151},{"atl":[[12,0]],"id":25760990}],"con":true,"img":false}]}
{"op":"mcm","clk":"5346629193","pt":1646092785706,"mc":[{"id":"1.195395450","rc":[{"atl":[[13,0]],"id":37495442},{"atl":[[13,0]],"id":41360966}],"con":true,"img":false}]}
{"op":"mcm","clk":"5346629196","pt":1646092785809,"mc":[{"id":"1.195395450","rc":[{"atl":[[10.5,3.78]],"id":37495442},{"atl":[[10.5,3.78]],"id":41360966},{"atl":[[11.5,0]],"id":40494151}],"con":true,"img":false}]}
{"op":"mcm","clk":"5346630298","pt":1646092819632,"mc":[{"id":"1.195395450","rc":[{"atb":[[2.74,69],[2.84,65.25],[2.26,34.07],[2.96,22.28],[2.94,30.94]],"id":37495442},{"atl":[[8,1.71],[10,1.33],[20,1.26],[10.5,3.78],[15,1.71],[30,1.65],[9.4,3.68]],"id":37495442},{"atb":[[2.4,42.88],[2.3,92.36],[2.42,29.39],[2.04,35.15],[2.2,100.05]],"id":40995914},{"atl":[[8,5.33],[9.6,7.65],[19,2.66],[5.8,2.5],[7.6,1.81],[14,1.84]],"id":40995914},{"atb":[[2.24,34.61],[2.74,69],[2.84,65.25],[2.96,22.28],[2.94,30.94]],"id":41360966},{"atl":[[8,1.71],[10,1.33],[20,1.26],[10.5,3.78],[15,1.71],[30,1.65],[9.4,3.86]],"id":41360966},{"atb":[[2.4,42.88],[2.3,92.36],[2.42,27.41],[2.22,32.99],[2.2,100.05]],"id":40494151},{"atl":[[9.6,2.79],[19,2.66],[5.8,2.5],[7.6,1.81],[14,1.84],[8.4,4.26],[9.4,4.86]],"id":40494151},{"atb":[[2,60.03],[1.79,0],[2.02,40.56],[1.9,133.41],[1.95,126.38]],"id":41962160},{"atl":[[5.1,2.92],[6.2,2.3],[10.5,2.52],[8.2,3.33],[6,8.11],[6.8,7.57],[15.5,3.31]],"id":41962160},{"atb":[[2.4,85.76],[2.5,80.04],[2.6,37.52],[2.18,34.91],[2.62,24.73]],"id":25760990},{"atl":[[9,4.05],[10,4.57],[6.2,2.3],[10.5,2.52],[21,2.4],[8.2,1.66],[15.5,1.65]],"id":25760990},{"atb":[[1.2,600.35],[1.25,480.28],[1.26,184.45],[1.3,200.11]],"id":40908100},{"atl":[[2.54,7.79],[3.85,16.85],[2.74,6.9],[2.52,26.68],[3.35,10.21],[3.3,16.26],[2.94,12.38]],"id":40908100},{"atb":[[1.01,30017.84],[1.02,1915.55]],"id":43066393},{"atl":[[1.82,40.56],[1.11,81.12],[2.28,18.76],[1.94,12.77],[1.93,40.32],[2.68,28.58],[2.08,11.12],[2.48,16.22]],"id":43066393}],"con":true,"img":false}]}
{"op":"mcm","clk":"5346630302","pt":1646092819737,"mc":[{"id":"1.195395450","rc":[{"atb":[[1.91,54.08]],"id":41962160}],"con":true,"img":false}]}
{"op":"mcm","clk":"5346641906","pt":1646093123026,"mc":[{"id":"1.195395450","rc":[{"atb":[[2.6,62.5]],"id":37495442},{"atl":[[29,3.42]],"id":37495442},{"atb":[[2.06,94.34]],"id":40995914},{"atl":[[9,5]],"id":40995914},{"atb":[[2.98,30.95]],"id":41360966},{"atl":[[14,5.5]],"id":41360966},{"atb":[[1.44,85.76]],"id":40494151},{"atl":[[17.5,5.29]],"id":40494151},{"atb":[[1.47,120.08]],"id":41962160},{"atl":[[6,15.68]],"id":41962160},{"atb":[[2.48,67.57]],"id":25760990},{"atl":[[10.5,8.89]],"id":25760990},{"atb":[[1.2,1100.35]],"id":40908100},{"atl":[[2.5,7.8]],"id":40908100}],"con":true,"img":false}]}
{"op":"mcm","clk":"5346642121","pt":1646093127764,"mc":[{"id":"1.195395450","marketDefinition":{"bspMarket":false,"turnInPlayEnabled":false,"persistenceEnabled":false,"marketBaseRate":5.0,"eventId":"31270459","eventTypeId":"4339","numberOfWinners":3,"bettingType":"ODDS","marketType":"PLACE","marketTime":"2022-03-01T01:05:00.000Z","suspendTime":"2022-03-01T01:05:00.000Z","bspReconciled":false,"complete":true,"inPlay":false,"crossMatching":true,"runnersVoidable":false,"numberOfActiveRunners":8,"betDelay":0,"status":"OPEN","runners":[{"status":"ACTIVE","sortPriority":1,"id":43066393,"name":"1. Naya Bale"},{"status":"ACTIVE","sortPriority":2,"id":25760990,"name":"2. Darla Bale"},{"status":"ACTIVE","sortPriority":3,"id":37495442,"name":"3. Know Ego"},{"status":"ACTIVE","sortPriority":4,"id":40908100,"name":"4. Not So Simple"},{"status":"ACTIVE","sortPriority":5,"id":40494151,"name":"5. Money Bags"},{"status":"ACTIVE","sortPriority":6,"id":41962160,"name":"6. Opawa Nut"},{"status":"ACTIVE","sortPriority":7,"id":41360966,"name":"7. Sugar Time"},{"status":"ACTIVE","sortPriority":8,"id":40995914,"name":"8. Goldstar Butters"}],"regulators":["MR_INT"],"venue":"Addington","countryCode":"NZ","discountAllowed":true,"timezone":"NZ","openDate":"2022-02-28T23:02:00.000Z","version":4380660689,"name":"To Be Placed","eventName":"Addington (NZL) 1st Mar"},"rc":[],"con":true,"img":false}]}
{"op":"mcm","clk":"5346643377","pt":1646093159960,"mc":[{"id":"1.195395450","rc":[{"atb":[[2.52,65.79],[2.48,0]],"id":25760990}],"con":true,"img":false}]}
{"op":"mcm","clk":"5346643572","pt":1646093165463,"mc":[{"id":"1.195395450","rc":[{"atb":[[1.91,0]],"id":41962160},{"atl":[[2.52,0]],"id":40908100}],"con":true,"img":false}]}
{"op":"mcm","clk":"5346643576","pt":1646093165566,"mc":[{"id":"1.195395450","rc":[{"atb":[[1.77,54.08]],"id":41962160},{"atl":[[2.72,26.68]],"id":40908100}],"con":true,"img":false}]}
{"op":"mcm","clk":"5346643579","pt":1646093165670,"mc":[{"id":"1.195395450","rc":[{"atl":[[2.5,0],[2.52,15.6]],"id":40908100}],"con":true,"img":false}]}
{"op":"mcm","clk":"5346644270","pt":1646093186593,"mc":[{"id":"1.195395450","rc":[{"atb":[[2.04,0]],"id":40995914},{"atl":[[8,0],[9.6,2.79]],"id":40995914},{"atb":[[2.96,0]],"id":41360966},{"atl":[[9.4,0]],"id":41360966},{"atl":[[9,0]],"id":25760990},{"atl":[[1.82,0]],"id":43066393}],"con":true,"img":false}]}
{"op":"mcm","clk":"5346644272","pt":1646093186696,"mc":[{"id":"1.195395450","rc":[{"atb":[[2.08,35.15]],"id":40995914},{"atl":[[8.2,4.86],[7.4,5.33]],"id":40995914},{"atb":[[3,22.28]],"id":41360966},{"atl":[[9,3.86]],"id":41360966},{"atl":[[8.2,5.72]],"id":25760990},{"atl":[[1.7,40.56]],"id":43066393}],"con":true,"img":false}]}
{"op":"mcm","clk":"5346644275","pt":1646093186798,"mc":[{"id":"1.195395450","rc":[{"atb":[[2.98,0],[2.96,51.02]],"id":41360966}],"con":true,"img":false}]}
{"op":"mcm","clk":"5346644278","pt":1646093186851,"mc":[{"id":"1.195395450","rc":[{"atb":[[2.96,0],[3.05,30.95]],"id":41360966}],"con":true,"img":false}]}
{"op":"mcm","clk":"5346644987","pt":1646093207515,"mc":[{"id":"1.195395450","rc":[{"atl":[[6.8,0]],"id":41962160}],"con":true,"img":false}]}
{"op":"mcm","clk":"5346644990","pt":1646093207620,"mc":[{"id":"1.195395450","rc":[{"atl":[[5.9,7.57]],"id":41962160}],"con":true,"img":false}]}
{"op":"mcm","clk":"5346645709","pt":1646093228353,"mc":[{"id":"1.195395450","rc":[{"atb":[[3,0]],"id":41360966}],"con":true,"img":false}]}
{"op":"mcm","clk":"5346645711","pt":1646093228456,"mc":[{"id":"1.195395450","rc":[{"atb":[[2.96,73.3]],"id":41360966}],"con":true,"img":false}]}
{"op":"mcm","clk":"5346645715","pt":1646093228558,"mc":[{"id":"1.195395450","rc":[{"atb":[[3.05,0]],"id":41360966}],"con":true,"img":false}]}
{"op":"mcm","clk":"5346646456","pt":1646093248867,"mc":[{"id":"1.195395450","rc":[{"atb":[[2.96,0]],"id":37495442}],"con":true,"img":false}]}
{"op":"mcm","clk":"5346646460","pt":1646093248970,"mc":[{"id":"1.195395450","rc":[{"atb":[[2.86,22.28]],"id":37495442}],"con":true,"img":false}]}
{"op":"mcm","clk":"5346647272","pt":1646093269306,"mc":[{"id":"1.195395450","rc":[{"atb":[[2.96,51.02]],"id":41360966}],"con":true,"img":false}]}
{"op":"mcm","clk":"5346647277","pt":1646093269409,"mc":[{"id":"1.195395450","rc":[{"atb":[[2.98,22.28]],"id":41360966}],"con":true,"img":false}]}
{"op":"mcm","clk":"5346647286","pt":1646093269613,"mc":[{"id":"1.195395450","rc":[{"atb":[[3,30.95],[2.96,0]],"id":41360966}],"con":true,"img":false}]}
{"op":"mcm","clk":"5346649559","pt":1646093329568,"mc":[{"id":"1.195395450","rc":[{"atb":[[2.86,0]],"id":37495442},{"atb":[[2.98,0]],"id":41360966}],"con":true,"img":false}]}
{"op":"mcm","clk":"5346649566","pt":1646093329671,"mc":[{"id":"1.195395450","rc":[{"atb":[[2.96,22.28]],"id":37495442},{"atb":[[2.96,51.02],[3.05,22.28]],"id":41360966}],"con":true,"img":false}]}
{"op":"mcm","clk":"5346649572","pt":1646093329773,"mc":[{"id":"1.195395450","rc":[{"atb":[[3,0]],"id":41360966}],"con":true,"img":false}]}
{"op":"mcm","clk":"5346649578","pt":1646093329877,"mc":[{"id":"1.195395450","rc":[{"atb":[[3.1,30.95],[2.96,0]],"id":41360966}],"con":true,"img":false}]}
{"op":"mcm","clk":"5346650824","pt":1646093368882,"mc":[{"id":"1.195395450","rc":[{"atb":[[3.05,0]],"id":41360966}],"con":true,"img":false}]}
{"op":"mcm","clk":"5346650828","pt":1646093368989,"mc":[{"id":"1.195395450","rc":[{"atb":[[3.1,0],[2.96,73.3]],"id":41360966}],"con":true,"img":false}]}
{"op":"mcm","clk":"5346651512","pt":1646093388107,"mc":[{"id":"1.195395450","rc":[{"atb":[[2.96,0]],"id":37495442}],"con":true,"img":false}]}
{"op":"mcm","clk":"5346651518","pt":1646093388208,"mc":[{"id":"1.195395450","rc":[{"atb":[[2.86,22.28]],"id":37495442}],"con":true,"img":false}]}
{"op":"mcm","clk":"5346652123","pt":1646093407336,"mc":[{"id":"1.195395450","rc":[{"atb":[[2.96,51.02]],"id":41360966}],"con":true,"img":false}]}
{"op":"mcm","clk":"5346652126","pt":1646093407438,"mc":[{"id":"1.195395450","rc":[{"atb":[[2.98,22.28]],"id":41360966}],"con":true,"img":false}]}
{"op":"mcm","clk":"5346652129","pt":1646093407541,"mc":[{"id":"1.195395450","rc":[{"atb":[[3,30.95],[2.96,0]],"id":41360966}],"con":true,"img":false}]}
{"op":"mcm","clk":"5346653698","pt":1646093445471,"mc":[{"id":"1.195395450","rc":[{"atl":[[2.72,0]],"id":40908100}],"con":true,"img":false}]}
{"op":"mcm","clk":"5346653703","pt":1646093445574,"mc":[{"id":"1.195395450","rc":[{"atl":[[2.5,26.68]],"id":40908100}],"con":true,"img":false}]}
{"op":"mcm","clk":"5346653706","pt":1646093445678,"mc":[{"id":"1.195395450","rc":[{"atl":[[2.48,15.6]],"id":40908100}],"con":true,"img":false}]}
{"op":"mcm","clk":"5346653707","pt":1646093445781,"mc":[{"id":"1.195395450","rc":[{"atl":[[2.52,0]],"id":40908100}],"con":true,"img":false}]}
{"op":"mcm","clk":"5346654212","pt":1646093464334,"mc":[{"id":"1.195395450","rc":[{"atb":[[2.86,0],[2.26,0]],"id":37495442},{"atb":[[2.98,0]],"id":41360966}],"con":true,"img":false}]}
{"op":"mcm","clk":"5346654215","pt":1646093464437,"mc":[{"id":"1.195395450","rc":[{"atb":[[2.36,34.07],[2.96,22.28]],"id":37495442},{"atb":[[3.05,22.28]],"id":41360966}],"con":true,"img":false}]}
{"op":"mcm","clk":"5346654218","pt":1646093464490,"mc":[{"id":"1.195395450","rc":[{"atb":[[3,0],[2.96,51.02]],"id":41360966}],"con":true,"img":false}]}
{"op":"mcm","clk":"5346654219","pt":1646093464593,"mc":[{"id":"1.195395450","rc":[{"atb":[[3.1,30.95],[2.96,0]],"id":41360966}],"con":true,"img":false}]}
{"op":"mcm","clk":"5346655266","pt":1646093501480,"mc":[{"id":"1.195395450","rc":[{"atb":[[3.05,0]],"id":41360966},{"atl":[[2.5,0]],"id":40908100}],"con":true,"img":false}]}
{"op":"mcm","clk":"5346655269","pt":1646093501583,"mc":[{"id":"1.195395450","rc":[{"atb":[[3.1,0],[2.96,73.3]],"id":41360966},{"atl":[[2.52,31.2],[2.46,26.68]],"id":40908100}],"con":true,"img":false}]}
{"op":"mcm","clk":"5346655274","pt":1646093501684,"mc":[{"id":"1.195395450","rc":[{"atl":[[2.52,0],[2.44,26.69],[2.48,0]],"id":40908100}],"con":true,"img":false}]}
{"op":"mcm","clk":"5346655333","pt":1646093503787,"mc":[{"id":"1.195395450","rc":[{"atb":[[2.56,64.1],[2.52,0]],"id":25760990}],"con":true,"img":false}]}
{"op":"mcm","clk":"5346655837","pt":1646093519715,"mc":[{"id":"1.195395450","rc":[{"atb":[[2.96,0]],"id":37495442},{"atb":[[1.26,143.88]],"id":40908100},{"atl":[[3.3,0]],"id":40908100}],"con":true,"img":false}]}
{"op":"mcm","clk":"5346655840","pt":1646093519819,"mc":[{"id":"1.195395450","rc":[{"atb":[[2.86,22.28]],"id":37495442},{"atb":[[1.27,40.56]],"id":40908100},{"atl":[[2.92,16.26]],"id":40908100}],"con":true,"img":false}]}
{"op":"mcm","clk":"5346656420","pt":1646093538040,"mc":[{"id":"1.195395450","rc":[{"atb":[[2.96,51.02]],"id":41360966},{"atl":[[2.46,0]],"id":40908100}],"con":true,"img":false}]}
{"op":"mcm","clk":"5346656422","pt":1646093538142,"mc":[{"id":"1.195395450","rc":[{"atb":[[2.98,22.28]],"id":41360966},{"atl":[[2.52,80.06]],"id":40908100}],"con":true,"img":false}]}
{"op":"mcm","clk":"5346656424","pt":1646093538246,"mc":[{"id":"1.195395450","rc":[{"atl":[[2.44,0]],"id":40908100}],"con":true,"img":false}]}
{"op":"mcm","clk":"5346656429","pt":1646093538349,"mc":[{"id":"1.195395450","rc":[{"atb":[[3,30.95],[2.96,0]],"id":41360966}],"con":true,"img":false}]}
{"op":"mcm","clk":"5346656940","pt":1646093556135,"mc":[{"id":"1.195395450","rc":[{"atl":[[2.92,0]],"id":40908100}],"con":true,"img":false}]}
{"op":"mcm","clk":"5346656942","pt":1646093556237,"mc":[{"id":"1.195395450","rc":[{"atl":[[3.3,16.26]],"id":40908100}],"con":true,"img":false}]}
{"op":"mcm","clk":"5346657437","pt":1646093574160,"mc":[{"id":"1.195395450","rc":[{"atl":[[2.52,53.38]],"id":40908100}],"con":true,"img":false}]}
{"op":"mcm","clk":"5346657439","pt":1646093574262,"mc":[{"id":"1.195395450","rc":[{"atl":[[2.5,26.68]],"id":40908100}],"con":true,"img":false}]}
{"op":"mcm","clk":"5346657443","pt":1646093574368,"mc":[{"id":"1.195395450","rc":[{"atl":[[2.48,26.69]],"id":40908100}],"con":true,"img":false}]}
{"op":"mcm","clk":"5346657448","pt":1646093574469,"mc":[{"id":"1.195395450","rc":[{"atl":[[2.52,0]],"id":40908100}],"con":true,"img":false}]}
{"op":"mcm","clk":"5346657964","pt":1646093592103,"mc":[{"id":"1.195395450","rc":[{"atb":[[2.86,0]],"id":37495442},{"atb":[[2.98,0]],"id":41360966}],"con":true,"img":false}]}
{"op":"mcm","clk":"5346657967","pt":1646093592206,"mc":[{"id":"1.195395450","rc":[{"atb":[[2.96,22.28]],"id":37495442},{"atb":[[3,0],[2.96,51.02],[3.05,22.28]],"id":41360966}],"con":true,"img":false}]}
{"op":"mcm","clk":"5346658523","pt":1646093609692,"mc":[{"id":"1.195395450","rc":[{"atb":[[3.05,0]],"id":41360966}],"con":true,"img":false}]}
{"op":"mcm","clk":"5346658525","pt":1646093609793,"mc":[{"id":"1.195395450","rc":[{"atb":[[2.98,22.28]],"id":41360966}],"con":true,"img":false}]}
{"op":"mcm","clk":"5346658925","pt":1646093624441,"mc":[{"id":"1.195395450","rc":[{"atb":[[3,30.95]],"id":41360966}],"con":true,"img":false}]}
{"op":"mcm","clk":"5346658928","pt":1646093624545,"mc":[{"id":"1.195395450","rc":[{"atb":[[2.96,0]],"id":41360966}],"con":true,"img":false}]}
{"op":"mcm","clk":"5346659011","pt":1646093627215,"mc":[{"id":"1.195395450","rc":[{"atl":[[2.5,0]],"id":40908100}],"con":true,"img":false}]}
{"op":"mcm","clk":"5346659015","pt":1646093627316,"mc":[{"id":"1.195395450","rc":[{"atl":[[2.52,53.38],[2.46,26.68],[2.48,0]],"id":40908100}],"con":true,"img":false}]}
{"op":"mcm","clk":"5346659570","pt":1646093644738,"mc":[{"id":"1.195395450","rc":[{"atl":[[2.46,0]],"id":40908100}],"con":true,"img":false}]}
{"op":"mcm","clk":"5346659574","pt":1646093644840,"mc":[{"id":"1.195395450","rc":[{"atl":[[2.5,26.68]],"id":40908100}],"con":true,"img":false}]}
{"op":"mcm","clk":"5346660139","pt":1646093659184,"mc":[{"id":"1.195395450","rc":[{"atl":[[2.48,26.69]],"id":40908100}],"con":true,"img":false}]}
{"op":"mcm","clk":"5346660145","pt":1646093659286,"mc":[{"id":"1.195395450","rc":[{"atl":[[2.52,0]],"id":40908100}],"con":true,"img":false}]}
{"op":"mcm","clk":"5346660225","pt":1646093661903,"mc":[{"id":"1.195395450","rc":[{"atb":[[2.98,0]],"id":41360966}],"con":true,"img":false}]}
{"op":"mcm","clk":"5346660229","pt":1646093662006,"mc":[{"id":"1.195395450","rc":[{"atb":[[3,0],[2.96,51.02],[3.05,22.28]],"id":41360966}],"con":true,"img":false}]}
{"op":"mcm","clk":"5346660239","pt":1646093662210,"mc":[{"id":"1.195395450","rc":[{"atb":[[3.1,30.95]],"id":41360966}],"con":true,"img":false}]}
{"op":"mcm","clk":"5346660243","pt":1646093662313,"mc":[{"id":"1.195395450","rc":[{"atb":[[2.96,0]],"id":41360966}],"con":true,"img":false}]}
{"op":"mcm","clk":"5346660726","pt":1646093679841,"mc":[{"id":"1.195395450","rc":[{"atb":[[2.56,0]],"id":25760990}],"con":true,"img":false}]}
{"op":"mcm","clk":"5346660729","pt":1646093679941,"mc":[{"id":"1.195395450","rc":[{"atb":[[2.44,69.44]],"id":25760990}],"con":true,"img":false}]}
{"op":"mcm","clk":"5346661008","pt":1646093687643,"mc":[{"id":"1.195395450","rc":[{"atb":[[1.44,0],[1.53,85.76]],"id":40494151}],"con":true,"img":false}]}
{"op":"mcm","clk":"5346661012","pt":1646093687745,"mc":[{"id":"1.195395450","rc":[{"atb":[[2.6,0],[2.7,58.82]],"id":37495442},{"atl":[[5.1,10.49]],"id":41962160}],"con":true,"img":false}]}
{"op":"mcm","clk":"5346661018","pt":1646093687848,"mc":[{"id":"1.195395450","rc":[{"atl":[[6,8.11]],"id":41962160}],"con":true,"img":false}]}
{"op":"mcm","clk":"5346661098","pt":1646093689647,"mc":[{"id":"1.195395450","rc":[{"atb":[[3.1,0],[2.84,119.6]],"id":41360966},{"atl":[[14,0],[8.4,3.79]],"id":41360966},{"atb":[[1.55,120.08],[1.47,0]],"id":41962160},{"atb":[[1.2,600.35],[1.22,454.55]],"id":40908100}],"con":true,"img":false}]}
{"op":"mcm","clk":"5346661367","pt":1646093696235,"mc":[{"id":"1.195395450","rc":[{"atb":[[2.96,0]],"id":37495442},{"atb":[[3.05,0]],"id":41360966},{"atl":[[5.9,0]],"id":41962160},{"atl":[[2.5,0]],"id":40908100}],"con":true,"img":false}]}
{"op":"mcm","clk":"5346661371","pt":1646093696338,"mc":[{"id":"1.195395450","rc":[{"atb":[[2.86,22.28]],"id":37495442},{"atb":[[2.86,22.28]],"id":41360966},{"atl":[[6.4,7.57]],"id":41962160},{"atl":[[2.52,53.38],[2.46,26.68],[2.48,0]],"id":40908100}],"con":true,"img":false}]}
{"op":"mcm","clk":"5346661944","pt":1646093711272,"mc":[{"id":"1.195395450","rc":[{"atb":[[2.56,64.1],[2.44,0]],"id":25760990}],"con":true,"img":false}]}
{"op":"mcm","clk":"5346662017","pt":1646093713167,"mc":[{"id":"1.195395450","rc":[{"atl":[[2.46,0]],"id":40908100}],"con":true,"img":false}]}
{"op":"mcm","clk":"5346662019","pt":1646093713270,"mc":[{"id":"1.195395450","rc":[{"atl":[[2.5,26.68]],"id":40908100}],"con":true,"img":false}]}
{"op":"mcm","clk":"5346662509","pt":1646093727492,"mc":[{"id":"1.195395450","rc":[{"atl":[[2.52,0],[2.48,26.69]],"id":40908100}],"con":true,"img":false}]}
{"op":"mcm","clk":"5346662610","pt":1646093729915,"mc":[{"id":"1.195395450","rc":[{"atl":[[6,0]],"id":41962160}],"con":true,"img":false}]}
{"op":"mcm","clk":"5346662614","pt":1646093730017,"mc":[{"id":"1.195395450","rc":[{"atl":[[5,8.11]],"id":41962160}],"con":true,"img":false}]}
{"op":"mcm","clk":"5346662618","pt":1646093730070,"mc":[{"id":"1.195395450","rc":[{"atl":[[4.9,8.11]],"id":41962160}],"con":true,"img":false}]}
{"op":"mcm","clk":"5346662623","pt":1646093730173,"mc":[{"id":"1.195395450","rc":[{"atl":[[5.1,2.92]],"id":41962160}],"con":true,"img":false}]}
{"op":"mcm","clk":"5346663665","pt":1646093763347,"mc":[{"id":"1.195395450","rc":[{"atl":[[2.5,0]],"id":40908100}],"con":true,"img":false}]}
{"op":"mcm","clk":"5346663669","pt":1646093763450,"mc":[{"id":"1.195395450","rc":[{"atl":[[2.52,53.38],[2.46,26.68],[2.48,0]],"id":40908100}],"con":true,"img":false}]}
{"op":"mcm","clk":"5346663673","pt":1646093763552,"mc":[{"id":"1.195395450","rc":[{"atl":[[2.44,26.69]],"id":40908100}],"con":true,"img":false}]}
{"op":"mcm","clk":"5346663677","pt":1646093763653,"mc":[{"id":"1.195395450","rc":[{"atl":[[2.52,0]],"id":40908100}],"con":true,"img":false}]}
{"op":"mcm","clk":"5346664177","pt":1646093779698,"mc":[{"id":"1.195395450","rc":[{"atb":[[2.24,0]],"id":41360966},{"atl":[[5,0]],"id":41962160}],"con":true,"img":false}]}
{"op":"mcm","clk":"5346664182","pt":1646093779750,"mc":[{"id":"1.195395450","rc":[{"atb":[[2.36,34.61]],"id":41360966},{"atl":[[4.8,8.11]],"id":41962160}],"con":true,"img":false}]}
{"op":"mcm","clk":"5346664184","pt":1646093779851,"mc":[{"id":"1.195395450","rc":[{"atl":[[5.1,19.14],[4.9,0]],"id":41962160}],"con":true,"img":false}]}
{"op":"mcm","clk":"5346664187","pt":1646093779954,"mc":[{"id":"1.195395450","rc":[{"atl":[[5.1,2.92],[4.9,16.22]],"id":41962160}],"con":true,"img":false}]}
{"op":"mcm","clk":"5346664732","pt":1646093796085,"mc":[{"id":"1.195395450","rc":[{"atl":[[2.46,0]],"id":40908100}],"con":true,"img":false}]}
{"op":"mcm","clk":"5346664736","pt":1646093796189,"mc":[{"id":"1.195395450","rc":[{"atl":[[2.52,80.06]],"id":40908100}],"con":true,"img":false}]}
{"op":"mcm","clk":"5346664740","pt":1646093796290,"mc":[{"id":"1.195395450","rc":[{"atl":[[2.44,0]],"id":40908100}],"con":true,"img":false}]}
{"op":"mcm","clk":"5346673408","pt":1646093828442,"mc":[{"id":"1.195395450","rc":[{"atl":[[2.52,53.38]],"id":40908100}],"con":true,"img":false}]}
{"op":"mcm","clk":"5346673416","pt":1646093828544,"mc":[{"id":"1.195395450","rc":[{"atl":[[2.5,26.68]],"id":40908100}],"con":true,"img":false}]}
{"op":"mcm","clk":"5346673418","pt":1646093828648,"mc":[{"id":"1.195395450","rc":[{"atl":[[2.52,0],[2.48,26.69]],"id":40908100}],"con":true,"img":false}]}
{"op":"mcm","clk":"5346674016","pt":1646093844482,"mc":[{"id":"1.195395450","rc":[{"atl":[[3.3,0]],"id":40908100}],"con":true,"img":false}]}
{"op":"mcm","clk":"5346674021","pt":1646093844583,"mc":[{"id":"1.195395450","rc":[{"atl":[[2.92,16.26]],"id":40908100}],"con":true,"img":false}]}
{"op":"mcm","clk":"5346675117","pt":1646093876431,"mc":[{"id":"1.195395450","rc":[{"atl":[[2.5,0]],"id":40908100}],"con":true,"img":false}]}
{"op":"mcm","clk":"5346675121","pt":1646093876533,"mc":[{"id":"1.195395450","rc":[{"atl":[[2.52,53.38],[2.46,26.68],[2.48,0]],"id":40908100}],"con":true,"img":false}]}
{"op":"mcm","clk":"5346675649","pt":1646093892141,"mc":[{"id":"1.195395450","rc":[{"atl":[[9,0]],"id":41360966},{"atl":[[2.46,0]],"id":40908100}],"con":true,"img":false}]}
{"op":"mcm","clk":"5346675654","pt":1646093892241,"mc":[{"id":"1.195395450","rc":[{"atl":[[9.6,3.86]],"id":41360966},{"atl":[[2.5,26.68]],"id":40908100}],"con":true,"img":false}]}
{"op":"mcm","clk":"5346676132","pt":1646093905902,"mc":[{"id":"1.195395450","rc":[{"atl":[[2.52,0],[2.48,26.69]],"id":40908100}],"con":true,"img":false}]}
{"op":"mcm","clk":"5346677343","pt":1646093940539,"mc":[{"id":"1.195395450","rc":[{"atl":[[2.5,0]],"id":40908100}],"con":true,"img":false}]}
{"op":"mcm","clk":"5346677347","pt":1646093940643,"mc":[{"id":"1.195395450","rc":[{"atl":[[2.52,53.38],[2.46,26.68],[2.48,0]],"id":40908100}],"con":true,"img":false}]}
{"op":"mcm","clk":"5346677910","pt":1646093956062,"mc":[{"id":"1.195395450","rc":[{"atl":[[2.46,0]],"id":40908100}],"con":true,"img":false}]}
{"op":"mcm","clk":"5346677911","pt":1646093956165,"mc":[{"id":"1.195395450","rc":[{"atl":[[2.5,26.68]],"id":40908100}],"con":true,"img":false}]}
{"op":"mcm","clk":"5346678372","pt":1646093969380,"mc":[{"id":"1.195395450","rc":[{"atl":[[2.52,0],[2.48,26.69]],"id":40908100}],"con":true,"img":false}]}
{"op":"mcm","clk":"5346679554","pt":1646093999446,"mc":[{"id":"1.195395450","rc":[{"atl":[[2.5,0]],"id":40908100}],"con":true,"img":false}]}
{"op":"mcm","clk":"5346679558","pt":1646093999550,"mc":[{"id":"1.195395450","rc":[{"atl":[[2.52,53.38],[2.46,26.68]],"id":40908100}],"con":true,"img":false}]}
{"op":"mcm","clk":"5346679561","pt":1646093999652,"mc":[{"id":"1.195395450","rc":[{"atl":[[2.48,0]],"id":40908100}],"con":true,"img":false}]}
{"op":"mcm","clk":"5346680090","pt":1646094015467,"mc":[{"id":"1.195395450","rc":[{"atl":[[2.46,0]],"id":40908100}],"con":true,"img":false}]}
{"op":"mcm","clk":"5346680094","pt":1646094015569,"mc":[{"id":"1.195395450","rc":[{"atl":[[2.5,26.68]],"id":40908100}],"con":true,"img":false}]}
{"op":"mcm","clk":"5346680502","pt":1646094027696,"mc":[{"id":"1.195395450","rc":[{"atl":[[2.52,0],[2.48,26.69]],"id":40908100}],"con":true,"img":false}]}
{"op":"mcm","clk":"5346680691","pt":1646094033085,"mc":[{"id":"1.195395450","rc":[{"atb":[[2.66,5.02]],"id":25760990}],"con":true,"img":false}]}
{"op":"mcm","clk":"5346680698","pt":1646094033291,"mc":[{"id":"1.195395450","rc":[{"atb":[[2.46,5.72]],"id":40995914}],"con":true,"img":false}]}
{"op":"mcm","clk":"5346680705","pt":1646094033496,"mc":[{"id":"1.195395450","rc":[{"atb":[[2.06,7.87]],"id":41962160}],"con":true,"img":false}]}
{"op":"mcm","clk":"5346680708","pt":1646094033597,"mc":[{"id":"1.195395450","rc":[{"atb":[[2.46,5.72]],"id":40494151}],"con":true,"img":false}]}
{"op":"mcm","clk":"5346680712","pt":1646094033803,"mc":[{"id":"1.195395450","rc":[{"atb":[[3,4.17]],"id":41360966}],"con":true,"img":false}]}
{"op":"mcm","clk":"5346680718","pt":1646094034009,"mc":[{"id":"1.195395450","rc":[{"atb":[[3,4.17]],"id":37495442}],"con":true,"img":false}]}
{"op":"mcm","clk":"5346681644","pt":1646094058849,"mc":[{"id":"1.195395450","rc":[{"atl":[[2.5,0]],"id":40908100}],"con":true,"img":false}]}
{"op":"mcm","clk":"5346681650","pt":1646094058951,"mc":[{"id":"1.195395450","rc":[{"atl":[[2.52,53.38],[2.46,26.68],[2.48,0]],"id":40908100}],"con":true,"img":false}]}
{"op":"mcm","clk":"5346681662","pt":1646094059157,"mc":[{"id":"1.195395450","rc":[{"atl":[[2.52,0],[2.44,26.69]],"id":40908100}],"con":true,"img":false}]}
{"op":"mcm","clk":"5346682963","pt":1646094089793,"mc":[{"id":"1.195395450","rc":[{"atb":[[2.86,0]],"id":37495442},{"atb":[[2.86,0]],"id":41360966},{"atl":[[2.46,0]],"id":40908100}],"con":true,"img":false}]}
{"op":"mcm","clk":"5346682969","pt":1646094089895,"mc":[{"id":"1.195395450","rc":[{"atb":[[2.96,22.28]],"id":37495442},{"atb":[[2.96,22.28]],"id":41360966},{"atl":[[2.52,26.68]],"id":40908100}],"con":true,"img":false}]}
{"op":"mcm","clk":"5346682974","pt":1646094089997,"mc":[{"id":"1.195395450","rc":[{"atl":[[2.52,80.06],[2.44,0]],"id":40908100}],"con":true,"img":false}]}
{"op":"mcm","clk":"5346684033","pt":1646094116322,"mc":[{"id":"1.195395450","rc":[{"atl":[[2.52,53.38]],"id":40908100}],"con":true,"img":false}]}
{"op":"mcm","clk":"5346684040","pt":1646094116425,"mc":[{"id":"1.195395450","rc":[{"atl":[[2.5,26.68]],"id":40908100}],"con":true,"img":false}]}
{"op":"mcm","clk":"5346684065","pt":1646094117192,"mc":[{"id":"1.195395450","rc":[{"atl":[[2.48,26.69]],"id":40908100}],"con":true,"img":false}]}
{"op":"mcm","clk":"5346684067","pt":1646094117295,"mc":[{"id":"1.195395450","rc":[{"atl":[[2.52,0]],"id":40908100}],"con":true,"img":false}]}
{"op":"mcm","clk":"5346685952","pt":1646094163909,"mc":[{"id":"1.195395450","rc":[{"atb":[[2.56,0],[2.54,64.94]],"id":25760990}],"con":true,"img":false}]}
{"op":"mcm","clk":"5346686351","pt":1646094172997,"mc":[{"id":"1.195395450","rc":[{"atl":[[2.5,0]],"id":40908100}],"con":true,"img":false}]}
{"op":"mcm","clk":"5346686355","pt":1646094173100,"mc":[{"id":"1.195395450","rc":[{"atl":[[2.52,53.38],[2.46,26.68],[2.48,0]],"id":40908100}],"con":true,"img":false}]}
{"op":"mcm","clk":"5346686412","pt":1646094174229,"mc":[{"id":"1.195395450","rc":[{"atl":[[8.2,3.79]],"id":41360966}],"con":true,"img":false}]}
{"op":"mcm","clk":"5346686415","pt":1646094174333,"mc":[{"id":"1.195395450","rc":[{"atl":[[8.4,0]],"id":41360966}],"con":true,"img":false}]}
{"op":"mcm","clk":"5346686594","pt":1646094179528,"mc":[{"id":"1.195395450","rc":[{"atl":[[8.4,5.5]],"id":41360966}],"con":true,"img":false}]}
{"op":"mcm","clk":"5346686597","pt":1646094179631,"mc":[{"id":"1.195395450","rc":[{"atl":[[8.2,0]],"id":41360966}],"con":true,"img":false}]}
{"op":"mcm","clk":"5346686915","pt":1646094188037,"mc":[{"id":"1.195395450","rc":[{"atl":[[2.46,0]],"id":40908100}],"con":true,"img":false}]}
{"op":"mcm","clk":"5346686918","pt":1646094188139,"mc":[{"id":"1.195395450","rc":[{"atl":[[2.5,26.68]],"id":40908100}],"con":true,"img":false}]}
{"op":"mcm","clk":"5346687391","pt":1646094199568,"mc":[{"id":"1.195395450","rc":[{"atl":[[2.52,0],[2.48,26.69]],"id":40908100}],"con":true,"img":false}]}
{"op":"mcm","clk":"5346687529","pt":1646094203064,"mc":[{"id":"1.195395450","rc":[{"atb":[[2.36,0]],"id":41360966},{"atl":[[2.92,0]],"id":40908100}],"con":true,"img":false}]}
{"op":"mcm","clk":"5346687532","pt":1646094203167,"mc":[{"id":"1.195395450","rc":[{"atb":[[2.22,34.61]],"id":41360966},{"atl":[[3.3,16.26]],"id":40908100}],"con":true,"img":false}]}
{"op":"mcm","clk":"5346688455","pt":1646094228410,"mc":[{"id":"1.195395450","rc":[{"atl":[[9.6,0]],"id":41360966},{"atl":[[2.5,0]],"id":40908100},{"atl":[[1.7,0]],"id":43066393}],"con":true,"img":false}]}
{"op":"mcm","clk":"5346688457","pt":1646094228512,"mc":[{"id":"1.195395450","rc":[{"atl":[[2.52,80.06],[2.48,0]],"id":40908100},{"atl":[[1.67,40.56]],"id":43066393}],"con":true,"img":false}]}
{"op":"mcm","clk":"5346688897","pt":1646094242850,"mc":[{"id":"1.195395450","rc":[{"atb":[[2.22,0]],"id":40494151}],"con":true,"img":false}]}
{"op":"mcm","clk":"5346688900","pt":1646094242953,"mc":[{"id":"1.195395450","rc":[{"atb":[[2.32,32.99]],"id":40494151}],"con":true,"img":false}]}
{"op":"mcm","clk":"5346689355","pt":1646094257451,"mc":[{"id":"1.195395450","rc":[{"atl":[[8.6,5.33]],"id":41360966}],"con":true,"img":false}]}
{"op":"mcm","clk":"5346689360","pt":1646094257556,"mc":[{"id":"1.195395450","rc":[{"atb":[[2.08,0]],"id":40995914},{"atl":[[2.52,53.38]],"id":40908100}],"con":true,"img":false}]}
{"op":"mcm","clk":"5346689362","pt":1646094257655,"mc":[{"id":"1.195395450","rc":[{"atb":[[2.22,35.15]],"id":40995914},{"atl":[[2.5,26.68]],"id":40908100}],"con":true,"img":false}]}
{"op":"mcm","clk":"5346689364","pt":1646094257758,"mc":[{"id":"1.195395450","rc":[{"atl":[[2.52,0],[2.48,26.69]],"id":40908100}],"con":true,"img":false}]}
{"op":"mcm","clk":"5346690350","pt":1646094294946,"mc":[{"id":"1.195395450","rc":[{"atb":[[2.48,5.03]],"id":40995914},{"atb":[[3,7.9]],"id":37495442},{"atb":[[3,7.9]],"id":41360966},{"atb":[[2.46,10.82]],"id":40494151},{"atb":[[2.06,14.9]],"id":41962160},{"atb":[[2.66,9.51]],"id":25760990}],"con":true,"img":false}]}
{"op":"mcm","clk":"5346690446","pt":1646094297411,"mc":[{"id":"1.195395450","rc":[{"atb":[[2.06,0],[2.5,5.72]],"id":40995914},{"atb":[[3.05,22.29],[2.7,0]],"id":37495442},{"atb":[[1.53,0],[2.48,27.41]],"id":40494151},{"atl":[[25,4.17]],"id":25760990},{"atl":[[2.5,0],[2.48,0],[3.75,24.76]],"id":40908100}],"con":true,"img":false}]}
{"op":"mcm","clk":"5346690449","pt":1646094297511,"mc":[{"id":"1.195395450","rc":[{"atl":[[10.5,2.52]],"id":25760990},{"atl":[[2.52,26.68]],"id":40908100}],"con":true,"img":false}]}
{"op":"mcm","clk":"5346691359","pt":1646094322055,"mc":[{"id":"1.195395450","rc":[{"atl":[[8.6,0]],"id":41360966}],"con":true,"img":false}]}
{"op":"mcm","clk":"5346691363","pt":1646094322154,"mc":[{"id":"1.195395450","rc":[{"atl":[[8.2,5.33]],"id":41360966}],"con":true,"img":false}]}
{"op":"mcm","clk":"5346692935","pt":1646094361225,"mc":[{"id":"1.195395450","rc":[{"atl":[[1.93,0]],"id":43066393}],"con":true,"img":false}]}
{"op":"mcm","clk":"5346692939","pt":1646094361325,"mc":[{"id":"1.195395450","rc":[{"atl":[[1.84,40.32]],"id":43066393}],"con":true,"img":false}]}
{"op":"mcm","clk":"5346699853","pt":1646094547454,"mc":[{"id":"1.195395450","rc":[{"atb":[[2.22,0]],"id":40995914},{"atb":[[2.42,29.01],[2.18,0]],"id":25760990}],"con":true,"img":false}]}
{"op":"mcm","clk":"5346699857","pt":1646094547558,"mc":[{"id":"1.195395450","rc":[{"atb":[[2.06,35.15]],"id":40995914}],"con":true,"img":false}]}
{"op":"mcm","clk":"5346701030","pt":1646094583406,"mc":[{"id":"1.195395450","rc":[{"atb":[[2.32,0]],"id":40494151}],"con":true,"img":false}]}
{"op":"mcm","clk":"5346701031","pt":1646094583510,"mc":[{"id":"1.195395450","rc":[{"atb":[[2.22,32.99]],"id":40494151}],"con":true,"img":false}]}
{"op":"mcm","clk":"5346701561","pt":1646094597916,"mc":[{"id":"1.195395450","rc":[{"atb":[[2.84,65.25],[2.68,59.52]],"id":41360966},{"atl":[[8.8,10.68],[8.4,0]],"id":41360966},{"atb":[[2.54,0],[2.42,99.43]],"id":25760990}],"con":true,"img":false}]}
{"op":"mcm","clk":"5346703722","pt":1646094653026,"mc":[{"id":"1.195395450","rc":[{"atl":[[8.6,5.94],[10.5,0]],"id":41360966}],"con":true,"img":false}]}
{"op":"mcm","clk":"5346711089","pt":1646094847427,"mc":[{"id":"1.195395450","rc":[{"atl":[[4.9,0],[4.7,8.11]],"id":41962160}],"con":true,"img":false}]}
{"op":"mcm","clk":"5346712588","pt":1646094887505,"mc":[{"id":"1.195395450","rc":[{"atl":[[4.8,0]],"id":41962160}],"con":true,"img":false}]}
{"op":"mcm","clk":"5346712591","pt":1646094887605,"mc":[{"id":"1.195395450","rc":[{"atl":[[5.1,19.14],[4.6,8.11],[4.7,0]],"id":41962160}],"con":true,"img":false}]}
{"op":"mcm","clk":"5346712595","pt":1646094887824,"mc":[{"id":"1.195395450","rc":[{"atl":[[5.1,2.92],[4.7,16.22]],"id":41962160}],"con":true,"img":false}]}
{"op":"mcm","clk":"5346713138","pt":1646094903371,"mc":[{"id":"1.195395450","rc":[{"atb":[[2.54,12.99],[2.5,39.05],[2.42,117.42],[2.46,57.09]],"id":40995914},{"atl":[[5.6,16.3],[5.8,28.54],[5.2,4.76],[5.4,11.36]],"id":40995914},{"atb":[[2.9,65.79],[2.98,25.25],[2.94,69.6],[3.05,32.05]],"id":37495442},{"atl":[[11,2],[12,4.55],[13,6.25],[14,9.62]],"id":37495442},{"atb":[[2.82,41.21],[2.9,10.53],[2.86,26.88],[2.78,70.22]],"id":41360966},{"atl":[[6.4,13.89],[5.8,4.17],[6,10],[6.8,21.55]],"id":41360966},{"atb":[[2.24,60.48],[2.32,15.15],[2.28,39.06],[2.2,204.22]],"id":40494151},{"atl":[[9.6,17.32],[9.2,9.15],[8.8,6.41],[8.4,6.96]],"id":40494151},{"atb":[[1.92,81.52],[1.9,272.3],[1.96,20.83],[1.94,53.19]],"id":41962160},{"atl":[[5.1,21.21],[5.3,29.07],[4.9,12.82],[4.7,21.63]],"id":41962160},{"atb":[[2.82,41.21],[2.9,10.53],[2.86,26.88],[2.78,70.22]],"id":25760990},{"atl":[[32,4.03],[25,5.17],[27,1.92],[29,2.68]],"id":25760990},{"atb":[[1.2,850.35],[1.26,220.8],[1.22,704.55],[1.24,208.33]],"id":40908100},{"atl":[[3.85,34.39],[3.95,25.42],[4.1,40.32],[3.75,32.03]],"id":40908100}],"con":true,"img":false}]}
{"op":"mcm","clk":"5346713155","pt":1646094903834,"mc":[{"id":"1.195395450","rc":[{"atl":[[23,4.55],[29,0]],"id":37495442},{"atl":[[7.8,14.71],[8.8,0]],"id":41360966}],"con":true,"img":false}]}
{"op":"mcm","clk":"5346713217","pt":1646094905633,"mc":[{"id":"1.195395450","rc":[{"atb":[[3,4.17]],"id":37495442},{"atb":[[2.48,0]],"id":40995914},{"atb":[[2.66,5.02]],"id":25760990}],"con":true,"img":false}]}
{"op":"mcm","clk":"5346713222","pt":1646094905737,"mc":[{"id":"1.195395450","rc":[{"atb":[[2.48,57.09]],"id":40995914}],"con":true,"img":false}]}
{"op":"mcm","clk":"5346713225","pt":1646094905838,"mc":[{"id":"1.195395450","rc":[{"atb":[[2.5,33.33]],"id":40995914}],"con":true,"img":false}]}
{"op":"mcm","clk":"5346713233","pt":1646094906144,"mc":[{"id":"1.195395450","rc":[{"atb":[[1.02,2165.55]],"id":43066393},{"atl":[[1.37,250],[1.33,151.52],[1.31,64.52],[1.35,214.29]],"id":43066393}],"con":true,"img":false}]}
{"op":"mcm","clk":"5346713349","pt":1646094909846,"mc":[{"id":"1.195395450","rc":[{"atl":[[8.6,0],[9.8,4.86]],"id":41360966},{"atl":[[2.52,0]],"id":40908100}],"con":true,"img":false}]}
{"op":"mcm","clk":"5346713351","pt":1646094909950,"mc":[{"id":"1.195395450","rc":[{"atl":[[3,26.68]],"id":40908100}],"con":true,"img":false}]}
{"op":"mcm","clk":"5346713418","pt":1646094911542,"mc":[{"id":"1.195395450","rc":[{"atb":[[2.56,4.77]],"id":40995914},{"atb":[[3.1,3.54]],"id":37495442},{"atb":[[2.92,3.88]],"id":25760990}],"con":true,"img":false}]}
{"op":"mcm","clk":"5346713424","pt":1646094911642,"mc":[{"id":"1.195395450","rc":[{"atb":[[3.15,4.18],[3.05,9.76]],"id":37495442}],"con":true,"img":false}]}
{"op":"mcm","clk":"5346713513","pt":1646094914669,"mc":[{"id":"1.195395450","rc":[{"atb":[[3.1,0]],"id":37495442}],"con":true,"img":false}]}
{"op":"mcm","clk":"5346713575","pt":1646094916777,"mc":[{"id":"1.195395450","rc":[{"atb":[[3.15,0],[3.05,19.52]],"id":37495442}],"con":true,"img":false}]}
{"op":"mcm","clk":"5346713668","pt":1646094919855,"mc":[{"id":"1.195395450","rc":[{"atl":[[10,0],[8.2,1.66]],"id":25760990}],"con":true,"img":false}]}
{"op":"mcm","clk":"5346713672","pt":1646094920007,"mc":[{"id":"1.195395450","rc":[{"atl":[[11,4.57],[9.8,4.05]],"id":25760990}],"con":true,"img":false}]}
{"op":"mcm","clk":"5346713694","pt":1646094920574,"mc":[{"id":"1.195395450","rc":[{"atb":[[3.05,23.15]],"id":37495442}],"con":true,"img":false}]}
{"op":"mcm","clk":"5346713871","pt":1646094924896,"mc":[{"id":"1.195395450","rc":[{"atb":[[2.58,12.99]],"id":40995914}],"con":true,"img":false}]}
{"op":"mcm","clk":"5346713874","pt":1646094924998,"mc":[{"id":"1.195395450","rc":[{"atb":[[2.48,0]],"id":40995914}],"con":true,"img":false}]}
{"op":"mcm","clk":"5346714057","pt":1646094929885,"mc":[{"id":"1.195395450","rc":[{"atl":[[8.4,2.7]],"id":40494151},{"atl":[[1.67,0]],"id":43066393}],"con":true,"img":false}]}
{"op":"mcm","clk":"5346714061","pt":1646094929987,"mc":[{"id":"1.195395450","rc":[{"atl":[[7.8,4.26]],"id":40494151},{"atl":[[1.63,40.56]],"id":43066393}],"con":true,"img":false}]}
{"op":"mcm","clk":"5346714411","pt":1646094939825,"mc":[{"id":"1.195395450","rc":[{"atb":[[2.42,88.03]],"id":40995914},{"atl":[[7.4,0],[5.7,8.63]],"id":40995914},{"atl":[[8.2,0]],"id":41360966},{"atb":[[2.22,0]],"id":40494151},{"atl":[[9.4,0]],"id":40494151},{"atb":[[2.62,0]],"id":25760990}],"con":true,"img":false}]}
{"op":"mcm","clk":"5346714416","pt":1646094939930,"mc":[{"id":"1.195395450","rc":[{"atb":[[2.52,29.39]],"id":40995914},{"atl":[[6.6,5.33]],"id":41360966},{"atb":[[2.26,32.99]],"id":40494151},{"atl":[[8.8,11.27]],"id":40494151},{"atb":[[2.84,24.73]],"id":25760990}],"con":true,"img":false}]}
{"op":"mcm","clk":"5346714558","pt":1646094942705,"mc":[{"id":"1.195395450","rc":[{"atb":[[2.56,0]],"id":40995914}],"con":true,"img":false}]}
{"op":"mcm","clk":"5346714564","pt":1646094942808,"mc":[{"id":"1.195395450","rc":[{"atb":[[2.54,42.39],[2.58,0]],"id":40995914}],"con":true,"img":false}]}
{"op":"mcm","clk":"5346714856","pt":1646094950730,"mc":[{"id":"1.195395450","rc":[{"atb":[[2.6,4.65]],"id":40995914}],"con":true,"img":false}]}
{"op":"mcm","clk":"5346714865","pt":1646094950935,"mc":[{"id":"1.195395450","rc":[{"atb":[[2.42,70.42]],"id":25760990}],"con":true,"img":false}]}
{"op":"mcm","clk":"5346714868","pt":1646094951038,"mc":[{"id":"1.195395450","rc":[{"atb":[[2.52,29.01]],"id":25760990}],"con":true,"img":false}]}
{"op":"mcm","clk":"5346715238","pt":1646094961537,"mc":[{"id":"1.195395450","rc":[{"atb":[[2.54,12.99],[2.62,29.4]],"id":40995914}],"con":true,"img":false}]}
{"op":"mcm","clk":"5346715285","pt":1646094962667,"mc":[{"id":"1.195395450","rc":[{"atb":[[2.6,0]],"id":40995914}],"con":true,"img":false}]}
{"op":"mcm","clk":"5346715288","pt":1646094962771,"mc":[{"id":"1.195395450","rc":[{"atb":[[2.54,71.79],[2.62,0]],"id":40995914}],"con":true,"img":false}]}
{"op":"mcm","clk":"5346715412","pt":1646094966165,"mc":[{"id":"1.195395450","rc":[{"atb":[[2.36,14.71],[2.32,0]],"id":40494151}],"con":true,"img":false}]}
{"op":"mcm","clk":"5346715644","pt":1646094971759,"mc":[{"id":"1.195395450","rc":[{"atb":[[2.6,4.65]],"id":40995914}],"con":true,"img":false}]}
{"op":"mcm","clk":"5346715796","pt":1646094976183,"mc":[{"id":"1.195395450","rc":[{"atb":[[2.32,37.88]],"id":40494151}],"con":true,"img":false}]}
{"op":"mcm","clk":"5346715813","pt":1646094976698,"mc":[{"id":"1.195395450","rc":[{"atb":[[2.2,100.05]],"id":40494151}],"con":true,"img":false}]}
{"op":"mcm","clk":"5346715930","pt":1646094979986,"mc":[{"id":"1.195395450","rc":[{"atb":[[2.52,0]],"id":40995914},{"atl":[[3,0]],"id":40908100}],"con":true,"img":false}]}
{"op":"mcm","clk":"5346715933","pt":1646094980090,"mc":[{"id":"1.195395450","rc":[{"atb":[[2.56,29.39]],"id":40995914},{"atl":[[2.92,26.68]],"id":40908100}],"con":true,"img":false}]}
{"op":"mcm","clk":"5346715955","pt":1646094980679,"mc":[{"id":"1.195395450","rc":[{"atb":[[2.6,0]],"id":40995914}],"con":true,"img":false}]}
{"op":"mcm","clk":"5346715982","pt":1646094981295,"mc":[{"id":"1.195395450","rc":[{"atb":[[2.54,12.99],[2.58,33.33]],"id":40995914}],"con":true,"img":false}]}
{"op":"mcm","clk":"5346716149","pt":1646094986228,"mc":[{"id":"1.195395450","rc":[{"atb":[[2.28,58.59]],"id":40494151}],"con":true,"img":false}]}
{"op":"mcm","clk":"5346716294","pt":1646094989827,"mc":[{"id":"1.195395450","rc":[{"atb":[[2.64,4.54]],"id":40995914}],"con":true,"img":false}]}
{"op":"mcm","clk":"5346716298","pt":1646094989932,"mc":[{"id":"1.195395450","rc":[{"atl":[[8.8,6.41]],"id":40494151}],"con":true,"img":false}]}
{"op":"mcm","clk":"5346716301","pt":1646094990033,"mc":[{"id":"1.195395450","rc":[{"atl":[[8.6,4.86]],"id":40494151}],"con":true,"img":false}]}
{"op":"mcm","clk":"5346716525","pt":1646094996250,"mc":[{"id":"1.195395450","rc":[{"atb":[[2.24,161.29]],"id":40494151}],"con":true,"img":false}]}
{"op":"mcm","clk":"5346716529","pt":1646094996352,"mc":[{"id":"1.195395450","rc":[{"atb":[[2.24,100.81]],"id":40494151}],"con":true,"img":false}]}
{"op":"mcm","clk":"5346716631","pt":1646094999646,"mc":[{"id":"1.195395450","rc":[{"atb":[[2.66,29.4],[2.58,0]],"id":40995914}],"con":true,"img":false}]}
{"op":"mcm","clk":"5346716643","pt":1646094999956,"mc":[{"id":"1.195395450","rc":[{"atb":[[2.56,0]],"id":40995914}],"con":true,"img":false}]}
{"op":"mcm","clk":"5346716645","pt":1646095000059,"mc":[{"id":"1.195395450","rc":[{"atb":[[2.52,29.39]],"id":40995914}],"con":true,"img":false}]}
{"op":"mcm","clk":"5346716703","pt":1646095001751,"mc":[{"id":"1.195395450","rc":[{"atb":[[2.64,0]],"id":40995914}],"con":true,"img":false}]}
{"op":"mcm","clk":"5346716706","pt":1646095001854,"mc":[{"id":"1.195395450","rc":[{"atb":[[2.54,71.79],[2.66,0]],"id":40995914}],"con":true,"img":false}]}
{"op":"mcm","clk":"5346716952","pt":1646095008157,"mc":[{"id":"1.195395450","rc":[{"atb":[[2.46,51.37]],"id":40995914},{"atb":[[2.66,0]],"id":25760990}],"con":true,"img":false}]}
{"op":"mcm","clk":"5346717047","pt":1646095010774,"mc":[{"id":"1.195395450","rc":[{"atb":[[2.6,4.65]],"id":40995914}],"con":true,"img":false}]}
{"op":"mcm","clk":"5346717133","pt":1646095013293,"mc":[{"id":"1.195395450","rc":[{"atb":[[2.88,4.44]],"id":25760990}],"con":true,"img":false}]}
{"op":"mcm","clk":"5346717327","pt":1646095018795,"mc":[{"id":"1.195395450","rc":[{"atb":[[2.6,9.87]],"id":40995914}],"con":true,"img":false}]}
{"op":"mcm","clk":"5346717359","pt":1646095019875,"mc":[{"id":"1.195395450","rc":[{"atb":[[2.52,0]],"id":40995914}],"con":true,"img":false}]}
{"op":"mcm","clk":"5346717364","pt":1646095019981,"mc":[{"id":"1.195395450","rc":[{"atb":[[2.56,29.39],[2.54,12.99],[2.62,29.4]],"id":40995914}],"con":true,"img":false}]}
{"op":"mcm","clk":"5346717499","pt":1646095023892,"mc":[{"id":"1.195395450","rc":[{"atb":[[2.6,5.22]],"id":40995914}],"con":true,"img":false}]}
{"op":"mcm","clk":"5346717703","pt":1646095029835,"mc":[{"id":"1.195395450","rc":[{"atb":[[2.56,0],[2.68,4.43]],"id":40995914}],"con":true,"img":false}]}
{"op":"mcm","clk":"5346717708","pt":1646095029939,"mc":[{"id":"1.195395450","rc":[{"atb":[[2.52,29.39]],"id":40995914}],"con":true,"img":false}]}
{"op":"mcm","clk":"5346717941","pt":1646095036916,"mc":[{"id":"1.195395450","rc":[{"atb":[[2.6,0]],"id":40995914}],"con":true,"img":false}]}
{"op":"mcm","clk":"5346717967","pt":1646095037942,"mc":[{"id":"1.195395450","rc":[{"atb":[[2.7,12.99]],"id":40995914}],"con":true,"img":false}]}
{"op":"mcm","clk":"5346717973","pt":1646095038043,"mc":[{"id":"1.195395450","rc":[{"atb":[[2.62,0]],"id":40995914}],"con":true,"img":false}]}
{"op":"mcm","clk":"5346718053","pt":1646095040813,"mc":[{"id":"1.195395450","rc":[{"atb":[[2.68,0]],"id":40995914}],"con":true,"img":false}]}
{"op":"mcm","clk":"5346718057","pt":1646095040917,"mc":[{"id":"1.195395450","rc":[{"atb":[[2.54,42.39]],"id":40995914}],"con":true,"img":false}]}
{"op":"mcm","clk":"5346718062","pt":1646095041019,"mc":[{"id":"1.195395450","rc":[{"atb":[[2.7,0]],"id":40995914}],"con":true,"img":false}]}
{"op":"mcm","clk":"5346718385","pt":1646095049851,"mc":[{"id":"1.195395450","rc":[{"atb":[[2.6,4.65]],"id":40995914}],"con":true,"img":false}]}
{"op":"mcm","clk":"5346718389","pt":1646095049954,"mc":[{"id":"1.195395450","rc":[{"atb":[[2.62,29.4]],"id":40995914}],"con":true,"img":false}]}
{"op":"mcm","clk":"5346718392","pt":1646095050056,"mc":[{"id":"1.195395450","rc":[{"atb":[[2.54,12.99]],"id":40995914}],"con":true,"img":false}]}
{"op":"mcm","clk":"5346718479","pt":1646095052936,"mc":[{"id":"1.195395450","rc":[{"atb":[[2.6,0]],"id":40995914}],"con":true,"img":false}]}
{"op":"mcm","clk":"5346718482","pt":1646095053038,"mc":[{"id":"1.195395450","rc":[{"atb":[[2.54,71.79]],"id":40995914}],"con":true,"img":false}]}
{"op":"mcm","clk":"5346718485","pt":1646095053142,"mc":[{"id":"1.195395450","rc":[{"atb":[[2.62,0]],"id":40995914}],"con":true,"img":false}]}
{"op":"mcm","clk":"5346718545","pt":1646095054835,"mc":[{"id":"1.195395450","rc":[{"atb":[[2.6,5.22]],"id":40995914}],"con":true,"img":false}]}
{"op":"mcm","clk":"5346718551","pt":1646095054940,"mc":[{"id":"1.195395450","rc":[{"atb":[[2.54,12.99],[2.62,29.4]],"id":40995914}],"con":true,"img":false}]}
{"op":"mcm","clk":"5346718694","pt":1646095058792,"mc":[{"id":"1.195395450","rc":[{"atb":[[2.68,4.43]],"id":40995914}],"con":true,"img":false}]}
{"op":"mcm","clk":"5346719116","pt":1646095069927,"mc":[{"id":"1.195395450","rc":[{"atb":[[2.26,0]],"id":40494151}],"con":true,"img":false}]}
{"op":"mcm","clk":"5346719120","pt":1646095069977,"mc":[{"id":"1.195395450","rc":[{"atb":[[2.3,125.35]],"id":40494151}],"con":true,"img":false}]}
{"op":"mcm","clk":"5346719197","pt":1646095072486,"mc":[{"id":"1.195395450","rc":[{"atb":[[2.62,0],[2.7,5.22]],"id":40995914}],"con":true,"img":false}]}
{"op":"mcm","clk":"5346719239","pt":1646095073870,"mc":[{"id":"1.195395450","rc":[{"atb":[[2.68,0]],"id":40995914}],"con":true,"img":false}]}
{"op":"mcm","clk":"5346719242","pt":1646095073972,"mc":[{"id":"1.195395450","rc":[{"atb":[[2.62,12.99],[2.7,0]],"id":40995914}],"con":true,"img":false}]}
{"op":"mcm","clk":"5346719409","pt":1646095079821,"mc":[{"id":"1.195395450","rc":[{"atb":[[2.58,4.71]],"id":40995914}],"con":true,"img":false}]}
{"op":"mcm","clk":"5346726554","pt":1646095254533,"mc":[{"id":"1.195395450","rc":[{"atl":[[9,0],[6.8,17.24],[5,5],[5.2,0]],"id":40995914},{"atl":[[11,0],[11.5,1.9]],"id":37495442},{"atb":[[2.68,0],[3.05,22.29]],"id":41360966},{"atl":[[6.4,3.7],[5.8,0],[9.8,16.22],[7.8,0]],"id":41360966},{"atl":[[8.2,2.78],[8.4,0],[15,7.14],[17.5,0]],"id":40494151},{"atb":[[2.74,49.46],[2.42,0]],"id":25760990},{"atb":[[1.16,441.62],[1.22,250]],"id":40908100}],"con":true,"img":false}]}
{"op":"mcm","clk":"5346726588","pt":1646095255608,"mc":[{"id":"1.195395450","rc":[{"atl":[[6,0]],"id":41360966}],"con":true,"img":false}]}
{"op":"mcm","clk":"5346726933","pt":1646095264510,"mc":[{"id":"1.195395450","rc":[{"atl":[[5.2,11.9]],"id":40995914},{"atl":[[12.5,4.35]],"id":37495442},{"atl":[[6.8,30.17]],"id":41360966}],"con":true,"img":false}]}
{"op":"mcm","clk":"5346726936","pt":1646095264613,"mc":[{"id":"1.195395450","rc":[{"atl":[[6.8,8.62]],"id":41360966}],"con":true,"img":false}]}
{"op":"mcm","clk":"5346727067","pt":1646095268317,"mc":[{"id":"1.195395450","rc":[{"atl":[[5.8,2.5]],"id":40995914},{"atl":[[12,0],[13,0],[14,0]],"id":37495442}],"con":true,"img":false}]}
{"op":"mcm","clk":"5346727117","pt":1646095269959,"mc":[{"id":"1.195395450","rc":[{"atl":[[5.7,0]],"id":40995914}],"con":true,"img":false}]}
{"op":"mcm","clk":"5346727121","pt":1646095270061,"mc":[{"id":"1.195395450","rc":[{"atl":[[6.6,8.63]],"id":40995914}],"con":true,"img":false}]}
{"op":"mcm","clk":"5346727262","pt":1646095274541,"mc":[{"id":"1.195395450","rc":[{"atl":[[5.4,17.05]],"id":40995914},{"atl":[[13.5,6]],"id":37495442},{"atl":[[7.2,12.1]],"id":41360966}],"con":true,"img":false}]}
{"op":"mcm","clk":"5346727580","pt":1646095284552,"mc":[{"id":"1.195395450","rc":[{"atl":[[5.6,27.17]],"id":40995914},{"atl":[[14.5,9.26]],"id":37495442},{"atl":[[7.6,18.94]],"id":41360966}],"con":true,"img":false}]}
{"op":"mcm","clk":"5346727712","pt":1646095289986,"mc":[{"id":"1.195395450","rc":[{"atl":[[6.6,0]],"id":41360966}],"con":true,"img":false}]}
{"op":"mcm","clk":"5346727716","pt":1646095290088,"mc":[{"id":"1.195395450","rc":[{"atl":[[7,5.33]],"id":41360966}],"con":true,"img":false}]}
{"op":"mcm","clk":"5346727733","pt":1646095290757,"mc":[{"id":"1.195395450","rc":[{"atb":[[2.6,0]],"id":40995914}],"con":true,"img":false}]}
{"op":"mcm","clk":"5346727735","pt":1646095290859,"mc":[{"id":"1.195395450","rc":[{"atb":[[2.6,25.98],[2.62,0]],"id":40995914}],"con":true,"img":false}]}
{"op":"mcm","clk":"5346727929","pt":1646095298299,"mc":[{"id":"1.195395450","rc":[{"atb":[[2.56,5.35]],"id":40995914}],"con":true,"img":false}]}
{"op":"mcm","clk":"5346730186","pt":1646095363828,"mc":[{"id":"1.195395450","rc":[{"atl":[[11,2],[11.5,0]],"id":37495442},{"atl":[[6.4,0],[6.6,3.57]],"id":41360966},{"atb":[[2.62,51.61],[2.74,0]],"id":25760990}],"con":true,"img":false}]}
{"op":"mcm","clk":"5346730553","pt":1646095373863,"mc":[{"id":"1.195395450","rc":[{"atl":[[7,13.66]],"id":41360966}],"con":true,"img":false}]}
{"op":"mcm","clk":"5346730613","pt":1646095375463,"mc":[{"id":"1.195395450","rc":[{"atl":[[7.2,0],[6.8,0],[7.6,0]],"id":41360966}],"con":true,"img":false}]}
{"op":"mcm","clk":"5346730770","pt":1646095379835,"mc":[{"id":"1.195395450","rc":[{"atl":[[7,8.33]],"id":41360966}],"con":true,"img":false}]}
{"op":"mcm","clk":"5346730774","pt":1646095379939,"mc":[{"id":"1.195395450","rc":[{"atl":[[8.6,5.33]],"id":41360966}],"con":true,"img":false}]}
{"op":"mcm","clk":"5346730910","pt":1646095383849,"mc":[{"id":"1.195395450","rc":[{"atl":[[7.4,11.72]],"id":41360966}],"con":true,"img":false}]}
{"op":"mcm","clk":"5346731194","pt":1646095393776,"mc":[{"id":"1.195395450","rc":[{"atl":[[7.8,18.38]],"id":41360966}],"con":true,"img":false}]}
{"op":"mcm","clk":"5346731701","pt":1646095409941,"mc":[{"id":"1.195395450","rc":[{"atl":[[8.6,0]],"id":41360966},{"atb":[[2.52,0]],"id":25760990}],"con":true,"img":false}]}
{"op":"mcm","clk":"5346731706","pt":1646095409992,"mc":[{"id":"1.195395450","rc":[{"atl":[[7.2,5.33]],"id":41360966},{"atb":[[2.64,29.01]],"id":25760990}],"con":true,"img":false}]}
{"op":"mcm","clk":"5346732290","pt":1646095429355,"mc":[{"id":"1.195395450","rc":[{"atl":[[10.5,5.89],[11,0],[19,5.56],[23,0]],"id":37495442},{"atl":[[6.6,0],[7,3.33]],"id":41360966}],"con":true,"img":false}]}
{"op":"mcm","clk":"5346732567","pt":1646095439382,"mc":[{"id":"1.195395450","rc":[{"atl":[[11.5,4.76]],"id":37495442},{"atl":[[7.4,19.53]],"id":41360966}],"con":true,"img":false}]}
{"op":"mcm","clk":"5346732573","pt":1646095439485,"mc":[{"id":"1.195395450","rc":[{"atl":[[7.4,7.81]],"id":41360966}],"con":true,"img":false}]}
{"op":"mcm","clk":"5346732587","pt":1646095439996,"mc":[{"id":"1.195395450","rc":[{"atl":[[7.2,0]],"id":41360966}],"con":true,"img":false}]}
{"op":"mcm","clk":"5346732589","pt":1646095440050,"mc":[{"id":"1.195395450","rc":[{"atl":[[7.6,5.33]],"id":41360966}],"con":true,"img":false}]}
{"op":"mcm","clk":"5346732675","pt":1646095442412,"mc":[{"id":"1.195395450","rc":[{"atl":[[14.5,0]],"id":37495442}],"con":true,"img":false}]}
{"op":"mcm","clk":"5346732928","pt":1646095449409,"mc":[{"id":"1.195395450","rc":[{"atl":[[12.5,6.52]],"id":37495442},{"atl":[[7.8,11.03]],"id":41360966}],"con":true,"img":false}]}
{"op":"mcm","clk":"5346733147","pt":1646095455419,"mc":[{"id":"1.195395450","rc":[{"atl":[[5.4,0],[5.6,0],[5,0],[6.2,3.85],[5.2,0]],"id":40995914},{"atb":[[2.42,65.65],[2.48,0]],"id":40494151},{"atl":[[5,30],[4.7,0]],"id":41962160},{"atl":[[25,0],[15.5,8.09]],"id":25760990},{"atl":[[2.86,27.01],[3.75,0]],"id":40908100}],"con":true,"img":false}]}
{"op":"mcm","clk":"5346733236","pt":1646095457582,"mc":[{"id":"1.195395450","rc":[{"atb":[[2.46,5.72]],"id":40494151}],"con":true,"img":false}]}
{"op":"mcm","clk":"5346733290","pt":1646095459429,"mc":[{"id":"1.195395450","rc":[{"atl":[[13.5,10]],"id":37495442},{"atl":[[8.2,17.36]],"id":41360966}],"con":true,"img":false}]}
{"op":"mcm","clk":"5346733304","pt":1646095459792,"mc":[{"id":"1.195395450","rc":[{"atl":[[4.6,0],[4.9,0]],"id":41962160}],"con":true,"img":false}]}
{"op":"mcm","clk":"5346733308","pt":1646095459895,"mc":[{"id":"1.195395450","rc":[{"atl":[[4.8,8.11]],"id":41962160}],"con":true,"img":false}]}
{"op":"mcm","clk":"5346733418","pt":1646095463696,"mc":[{"id":"1.195395450","rc":[{"atb":[[2.48,5.03]],"id":40494151}],"con":true,"img":false}]}
{"op":"mcm","clk":"5346733471","pt":1646095465397,"mc":[{"id":"1.195395450","rc":[{"atl":[[6.6,17.56]],"id":40995914},{"atl":[[5.2,11.9]],"id":41962160},{"atl":[[16.5,3.23]],"id":25760990},{"atl":[[2.9,26.32]],"id":40908100}],"con":true,"img":false}]}
{"op":"mcm","clk":"5346733498","pt":1646095466220,"mc":[{"id":"1.195395450","rc":[{"atl":[[32,0]],"id":25760990},{"atl":[[4.1,0]],"id":40908100}],"con":true,"img":false}]}
{"op":"mcm","clk":"5346733614","pt":1646095469927,"mc":[{"id":"1.195395450","rc":[{"atl":[[4.8,0]],"id":41962160},{"atb":[[2.64,0]],"id":25760990}],"con":true,"img":false}]}
{"op":"mcm","clk":"5346733617","pt":1646095470031,"mc":[{"id":"1.195395450","rc":[{"atl":[[5.1,45.6],[4.9,8.11]],"id":41962160},{"atb":[[2.52,29.01]],"id":25760990}],"con":true,"img":false}]}
{"op":"mcm","clk":"5346733620","pt":1646095470132,"mc":[{"id":"1.195395450","rc":[{"atl":[[5,5]],"id":41962160}],"con":true,"img":false}]}
{"op":"mcm","clk":"5346733709","pt":1646095472904,"mc":[{"id":"1.195395450","rc":[{"atb":[[2.46,0]],"id":40494151}],"con":true,"img":false}]}
{"op":"mcm","clk":"5346733785","pt":1646095475425,"mc":[{"id":"1.195395450","rc":[{"atl":[[7,12.5]],"id":40995914},{"atl":[[5.4,17.05]],"id":41962160},{"atl":[[17.5,4.55]],"id":25760990},{"atl":[[2.94,51.04]],"id":40908100}],"con":true,"img":false}]}
{"op":"mcm","clk":"5346733901","pt":1646095478762,"mc":[{"id":"1.195395450","rc":[{"atb":[[2.48,10.68]],"id":40494151}],"con":true,"img":false}]}
{"op":"mcm","clk":"5346733932","pt":1646095479740,"mc":[{"id":"1.195395450","rc":[{"atl":[[5.1,27.31],[5.3,0]],"id":41962160},{"atl":[[29,0]],"id":25760990},{"atl":[[3.95,0]],"id":40908100}],"con":true,"img":false}]}
{"op":"mcm","clk":"5346733935","pt":1646095479845,"mc":[{"id":"1.195395450","rc":[{"atl":[[4.9,0]],"id":41962160},{"atl":[[2.92,0]],"id":40908100}],"con":true,"img":false}]}
{"op":"mcm","clk":"5346733943","pt":1646095480156,"mc":[{"id":"1.195395450","rc":[{"atl":[[5,13.11]],"id":41962160},{"atl":[[2.84,26.68]],"id":40908100}],"con":true,"img":false}]}
{"op":"mcm","clk":"5346733961","pt":1646095480724,"mc":[{"id":"1.195395450","rc":[{"atl":[[8.2,0],[8.4,2.7]],"id":40494151},{"atb":[[2.62,0],[2.7,49.46]],"id":25760990}],"con":true,"img":false}]}
{"op":"mcm","clk":"5346734061","pt":1646095483460,"mc":[{"id":"1.195395450","rc":[{"atl":[[5.1,2.92],[5,26.22]],"id":41962160}],"con":true,"img":false}]}
{"op":"mcm","clk":"5346734126","pt":1646095485457,"mc":[{"id":"1.195395450","rc":[{"atl":[[7.4,19.53]],"id":40995914},{"atl":[[5.6,27.17]],"id":41962160},{"atl":[[18.5,7.14]],"id":25760990},{"atl":[[2.98,63.13]],"id":40908100}],"con":true,"img":false}]}
{"op":"mcm","clk":"5346734400","pt":1646095491385,"mc":[{"id":"1.195395450","rc":[{"atl":[[27,0]],"id":25760990},{"atl":[[3.85,16.85]],"id":40908100}],"con":true,"img":false}]}
{"op":"mcm","clk":"5346734519","pt":1646095494172,"mc":[{"id":"1.195395450","rc":[{"atl":[[7.2,3.23],[7,0]],"id":41360966},{"atb":[[2.74,49.46],[2.7,0]],"id":25760990}],"con":true,"img":false}]}
{"op":"mcm","clk":"5346734941","pt":1646095504069,"mc":[{"id":"1.195395450","rc":[{"atl":[[7.6,12.91]],"id":41360966}],"con":true,"img":false}]}
{"op":"mcm","clk":"5346735156","pt":1646095509686,"mc":[{"id":"1.195395450","rc":[{"atl":[[5,18.11]],"id":41962160}],"con":true,"img":false}]}
{"op":"mcm","clk":"5346735161","pt":1646095509790,"mc":[{"id":"1.195395450","rc":[{"atl":[[5.1,27.31],[5,5],[4.9,8.11]],"id":41962160}],"con":true,"img":false}]}
{"op":"mcm","clk":"5346735185","pt":1646095510304,"mc":[{"id":"1.195395450","rc":[{"atl":[[8.2,0],[7.4,0],[7.8,0]],"id":41360966}],"con":true,"img":false}]}
{"op":"mcm","clk":"5346735351","pt":1646095514109,"mc":[{"id":"1.195395450","rc":[{"atl":[[8,12.42]],"id":41360966}],"con":true,"img":false}]}
{"op":"mcm","clk":"5346735738","pt":1646095522840,"mc":[{"id":"1.195395450","rc":[{"atl":[[5.1,2.92],[5,21.22]],"id":41962160}],"con":true,"img":false}]}
{"op":"mcm","clk":"5346735802","pt":1646095524230,"mc":[{"id":"1.195395450","rc":[{"atl":[[8.4,16.89]],"id":41360966}],"con":true,"img":false}]}
{"op":"mcm","clk":"5346736037","pt":1646095529837,"mc":[{"id":"1.195395450","rc":[{"atl":[[7.6,7.58]],"id":41360966},{"atl":[[4.9,0]],"id":41962160}],"con":true,"img":false}]}
{"op":"mcm","clk":"5346736041","pt":1646095529940,"mc":[{"id":"1.195395450","rc":[{"atl":[[7.8,5.33]],"id":41360966},{"atl":[[5.1,27.31],[5,13.11]],"id":41962160}],"con":true,"img":false}]}
{"op":"mcm","clk":"5346736834","pt":1646095549877,"mc":[{"id":"1.195395450","rc":[{"atl":[[9.8,0]],"id":25760990}],"con":true,"img":false}]}
{"op":"mcm","clk":"5346736839","pt":1646095549980,"mc":[{"id":"1.195395450","rc":[{"atl":[[9.4,4.05]],"id":25760990}],"con":true,"img":false}]}
{"op":"mcm","clk":"5346737279","pt":1646095561711,"mc":[{"id":"1.195395450","rc":[{"atb":[[2.5,7.47]],"id":40494151},{"atb":[[2.08,10.43]],"id":41962160},{"atb":[[1.31,72.94]],"id":40908100}],"con":true,"img":false}]}
{"op":"mcm","clk":"5346737289","pt":1646095561914,"mc":[{"id":"1.195395450","rc":[{"atl":[[5.1,2.92],[5,26.22]],"id":41962160}],"con":true,"img":false}]}
{"op":"mcm","clk":"5346738514","pt":1646095589829,"mc":[{"id":"1.195395450","rc":[{"atb":[[2.84,0]],"id":25760990}],"con":true,"img":false}]}
{"op":"mcm","clk":"5346738518","pt":1646095589979,"mc":[{"id":"1.195395450","rc":[{"atb":[[2.88,29.17]],"id":25760990}],"con":true,"img":false}]}
{"op":"mcm","clk":"5346738646","pt":1646095592964,"mc":[{"id":"1.195395450","rc":[{"atb":[[2.92,0]],"id":25760990}],"con":true,"img":false}]}
{"op":"mcm","clk":"5346738909","pt":1646095598876,"mc":[{"id":"1.195395450","rc":[{"atb":[[2.94,3.83]],"id":25760990}],"con":true,"img":false}]}
{"op":"mcm","clk":"5346738957","pt":1646095599910,"mc":[{"id":"1.195395450","rc":[{"atb":[[2.88,4.44]],"id":25760990}],"con":true,"img":false}]}
{"op":"mcm","clk":"5346738962","pt":1646095599963,"mc":[{"id":"1.195395450","rc":[{"atb":[[2.84,24.73]],"id":25760990}],"con":true,"img":false}]}
{"op":"mcm","clk":"5346739100","pt":1646095602898,"mc":[{"id":"1.195395450","rc":[{"atb":[[2.94,0]],"id":25760990}],"con":true,"img":false}]}
{"op":"mcm","clk":"5346739394","pt":1646095609279,"mc":[{"id":"1.195395450","rc":[{"atl":[[9.8,4.86]],"id":41360966}],"con":true,"img":false}]}
{"op":"mcm","clk":"5346739399","pt":1646095609387,"mc":[{"id":"1.195395450","rc":[{"atl":[[11.5,9.52]],"id":41360966}],"con":true,"img":false}]}
{"op":"mcm","clk":"5346739457","pt":1646095610801,"mc":[{"id":"1.195395450","rc":[{"atb":[[2.92,3.88]],"id":25760990}],"con":true,"img":false}]}
{"op":"mcm","clk":"5346739822","pt":1646095619895,"mc":[{"id":"1.195395450","rc":[{"atb":[[1.77,0]],"id":41962160}],"con":true,"img":false}]}
{"op":"mcm","clk":"5346739825","pt":1646095619996,"mc":[{"id":"1.195395450","rc":[{"atb":[[1.91,54.08]],"id":41962160}],"con":true,"img":false}]}
{"op":"mcm","clk":"5346740214","pt":1646095629824,"mc":[{"id":"1.195395450","rc":[{"atb":[[2.06,0]],"id":40995914}],"con":true,"img":false}]}
{"op":"mcm","clk":"5346740217","pt":1646095629928,"mc":[{"id":"1.195395450","rc":[{"atb":[[2.22,35.15]],"id":40995914}],"con":true,"img":false}]}
{"op":"mcm","clk":"5346740630","pt":1646095639862,"mc":[{"id":"1.195395450","rc":[{"atb":[[2.84,0]],"id":25760990}],"con":true,"img":false}]}
{"op":"mcm","clk":"5346740634","pt":1646095639965,"mc":[{"id":"1.195395450","rc":[{"atb":[[2.88,29.17]],"id":25760990}],"con":true,"img":false}]}
{"op":"mcm","clk":"5346740672","pt":1646095640940,"mc":[{"id":"1.195395450","rc":[{"atb":[[2.92,0]],"id":25760990}],"con":true,"img":false}]}
{"op":"mcm","clk":"5346740868","pt":1646095646949,"mc":[{"id":"1.195395450","rc":[{"atb":[[2.94,3.83]],"id":25760990}],"con":true,"img":false}]}
{"op":"mcm","clk":"5346741568","pt":1646095669886,"mc":[{"id":"1.195395450","rc":[{"atb":[[2.3,92.36]],"id":40494151}],"con":true,"img":false}]}
{"op":"mcm","clk":"5346741572","pt":1646095669990,"mc":[{"id":"1.195395450","rc":[{"atb":[[2.26,32.99]],"id":40494151}],"con":true,"img":false}]}
{"op":"mcm","clk":"5346742389","pt":1646095700959,"mc":[{"id":"1.195395450","rc":[{"atl":[[11,2]],"id":37495442},{"atl":[[7.2,0],[7.6,3.03]],"id":41360966},{"atl":[[8,2.86]],"id":40494151}],"con":true,"img":false}]}
{"op":"mcm","clk":"5346742392","pt":1646095701074,"mc":[{"id":"1.195395450","rc":[{"atl":[[10.5,3.78]],"id":37495442},{"atl":[[8.4,0]],"id":40494151}],"con":true,"img":false}]}
{"op":"mcm","clk":"5346742665","pt":1646095710967,"mc":[{"id":"1.195395450","rc":[{"atl":[[12,4.55]],"id":37495442},{"atl":[[8,8.85]],"id":41360966},{"atl":[[8.4,6.76]],"id":40494151}],"con":true,"img":false}]}
{"op":"mcm","clk":"5346742694","pt":1646095711992,"mc":[{"id":"1.195395450","rc":[{"atl":[[11.5,0],[12.5,0],[13.5,0]],"id":37495442},{"atl":[[9.6,2.79]],"id":40494151}],"con":true,"img":false}]}
{"op":"mcm","clk":"5346742915","pt":1646095720971,"mc":[{"id":"1.195395450","rc":[{"atl":[[13,6.25]],"id":37495442},{"atl":[[8.4,10.14]],"id":41360966},{"atl":[[8.8,9.62]],"id":40494151}],"con":true,"img":false}]}
{"op":"mcm","clk":"5346743225","pt":1646095731006,"mc":[{"id":"1.195395450","rc":[{"atl":[[14,9.62]],"id":37495442},{"atl":[[8.8,16.03]],"id":41360966},{"atl":[[9.2,15.24]],"id":40494151}],"con":true,"img":false}]}
{"op":"mcm","clk":"5346743774","pt":1646095749863,"mc":[{"id":"1.195395450","rc":[{"atl":[[8.2,5.94]],"id":40494151}],"con":true,"img":false}]}
{"op":"mcm","clk":"5346743779","pt":1646095749967,"mc":[{"id":"1.195395450","rc":[{"atl":[[8.6,0]],"id":40494151}],"con":true,"img":false}]}
{"op":"mcm","clk":"5346744026","pt":1646095758459,"mc":[{"id":"1.195395450","rc":[{"atl":[[11,0],[15,8.85],[19,0],[8.8,2.56]],"id":37495442},{"atb":[[2.3,169.28],[2.6,0]],"id":40995914},{"atl":[[6.2,21.09],[6.8,0]],"id":40995914},{"atl":[[7.6,0],[7,3.33]],"id":41360966},{"atl":[[8,0],[6.4,3.7],[10.5,8.54],[15,0]],"id":40494151},{"atl":[[5,21.22],[5.2,0],[5.4,0]],"id":41962160},{"atb":[[1.16,0],[1.26,441.61]],"id":40908100}],"con":true,"img":false}]}
{"op":"mcm","clk":"5346744032","pt":1646095758665,"mc":[{"id":"1.195395450","rc":[{"atl":[[5.4,4.55]],"id":41962160}],"con":true,"img":false}]}
{"op":"mcm","clk":"5346744084","pt":1646095759946,"mc":[{"id":"1.195395450","rc":[{"atb":[[2.88,4.44]],"id":25760990}],"con":true,"img":false}]}
{"op":"mcm","clk":"5346744087","pt":1646095760051,"mc":[{"id":"1.195395450","rc":[{"atb":[[2.84,24.73]],"id":25760990}],"con":true,"img":false}]}
{"op":"mcm","clk":"5346744113","pt":1646095761179,"mc":[{"id":"1.195395450","rc":[{"atb":[[2.94,0]],"id":25760990}],"con":true,"img":false}]}
{"op":"mcm","clk":"5346744119","pt":1646095761387,"mc":[{"id":"1.195395450","rc":[{"atl":[[5.4,0]],"id":41962160}],"con":true,"img":false}]}
{"op":"mcm","clk":"5346744143","pt":1646095762260,"mc":[{"id":"1.195395450","rc":[{"atl":[[5.4,4.55]],"id":41962160}],"con":true,"img":false}]}
{"op":"mcm","clk":"5346744149","pt":1646095762467,"mc":[{"id":"1.195395450","rc":[{"atl":[[5.4,0]],"id":41962160}],"con":true,"img":false}]}
{"op":"mcm","clk":"5346744164","pt":1646095763080,"mc":[{"id":"1.195395450","rc":[{"atb":[[2.5,0]],"id":40494151}],"con":true,"img":false}]}
{"op":"mcm","clk":"5346744255","pt":1646095766061,"mc":[{"id":"1.195395450","rc":[{"atl":[[5.4,4.55]],"id":41962160}],"con":true,"img":false}]}
{"op":"mcm","clk":"5346744280","pt":1646095767088,"mc":[{"id":"1.195395450","rc":[{"atb":[[2.92,3.88]],"id":25760990}],"con":true,"img":false}]}
{"op":"mcm","clk":"5346744301","pt":1646095768271,"mc":[{"id":"1.195395450","rc":[{"atb":[[2.5,7.47]],"id":40494151}],"con":true,"img":false}]}
{"op":"mcm","clk":"5346744304","pt":1646095768377,"mc":[{"id":"1.195395450","rc":[{"atl":[[9.2,6.1]],"id":37495442},{"atl":[[7.4,7.81]],"id":41360966},{"atl":[[6.8,8.62]],"id":40494151}],"con":true,"img":false}]}
{"op":"mcm","clk":"5346744321","pt":1646095768913,"mc":[{"id":"1.195395450","rc":[{"atl":[[14,0]],"id":37495442},{"atl":[[8,1.71],[8.8,0],[8.4,0]],"id":41360966},{"atl":[[9.2,0]],"id":40494151},{"atl":[[5.4,0]],"id":41962160}],"con":true,"img":false}]}
{"op":"mcm","clk":"5346744345","pt":1646095769992,"mc":[{"id":"1.195395450","rc":[{"atb":[[2.26,0]],"id":40494151}],"con":true,"img":false}]}
{"op":"mcm","clk":"5346744349","pt":1646095770096,"mc":[{"id":"1.195395450","rc":[{"atb":[[2.22,32.99]],"id":40494151}],"con":true,"img":false}]}
{"op":"mcm","clk":"5346744454","pt":1646095773693,"mc":[{"id":"1.195395450","rc":[{"atl":[[5.4,4.55]],"id":41962160}],"con":true,"img":false}]}
{"op":"mcm","clk":"5346744486","pt":1646095774614,"mc":[{"id":"1.195395450","rc":[{"atl":[[5.4,0]],"id":41962160}],"con":true,"img":false}]}
{"op":"mcm","clk":"5346744541","pt":1646095776417,"mc":[{"id":"1.195395450","rc":[{"atl":[[5.4,4.55]],"id":41962160}],"con":true,"img":false}]}
{"op":"mcm","clk":"5346744556","pt":1646095776891,"mc":[{"id":"1.195395450","rc":[{"atl":[[5.4,0]],"id":41962160}],"con":true,"img":false}]}
{"op":"mcm","clk":"5346744572","pt":1646095777402,"mc":[{"id":"1.195395450","rc":[{"atl":[[5.4,4.55]],"id":41962160}],"con":true,"img":false}]}
{"op":"mcm","clk":"5346744579","pt":1646095777710,"mc":[{"id":"1.195395450","rc":[{"atl":[[6.4,3.7]],"id":41360966},{"atl":[[5.4,0]],"id":41962160}],"con":true,"img":false}]}
{"op":"mcm","clk":"5346744597","pt":1646095778386,"mc":[{"id":"1.195395450","rc":[{"atl":[[9.6,8.72]],"id":37495442},{"atl":[[7.2,12.1]],"id":40494151}],"con":true,"img":false}]}
{"op":"mcm","clk":"5346744606","pt":1646095778589,"mc":[{"id":"1.195395450","rc":[{"atl":[[9,2.5],[13,0]],"id":37495442},{"atl":[[9.2,7.4],[11.5,0]],"id":41360966},{"atl":[[8.8,0]],"id":40494151},{"atl":[[5.4,4.55]],"id":41962160},{"atb":[[1.27,410.93],[1.26,220.8]],"id":40908100}],"con":true,"img":false}]}
{"op":"mcm","clk":"5346744610","pt":1646095778692,"mc":[{"id":"1.195395450","rc":[{"atl":[[9.6,0],[9.2,0],[12,0],[8.8,0]],"id":37495442}],"con":true,"img":false}]}
{"op":"mcm","clk":"5346744658","pt":1646095780593,"mc":[{"id":"1.195395450","rc":[{"atl":[[5.4,0]],"id":41962160}],"con":true,"img":false}]}
{"op":"mcm","clk":"5346744800","pt":1646095786190,"mc":[{"id":"1.195395450","rc":[{"atl":[[5.4,4.55]],"id":41962160}],"con":true,"img":false}]}
{"op":"mcm","clk":"5346744826","pt":1646095787114,"mc":[{"id":"1.195395450","rc":[{"atl":[[5.4,0]],"id":41962160}],"con":true,"img":false}]}
{"op":"mcm","clk":"5346744881","pt":1646095788400,"mc":[{"id":"1.195395450","rc":[{"atl":[[7.6,20.75]],"id":40494151}],"con":true,"img":false}]}
{"op":"mcm","clk":"5346744889","pt":1646095788605,"mc":[{"id":"1.195395450","rc":[{"atl":[[9.4,9.63]],"id":37495442}],"con":true,"img":false}]}
{"op":"mcm","clk":"5346744918","pt":1646095789425,"mc":[{"id":"1.195395450","rc":[{"atl":[[6.4,0],[6.8,3.45],[8.4,0]],"id":40494151},{"atb":[[1.96,0],[1.95,147.43]],"id":41962160},{"atl":[[5.4,4.55]],"id":41962160}],"con":true,"img":false}]}
{"op":"mcm","clk":"5346744931","pt":1646095789938,"mc":[{"id":"1.195395450","rc":[{"atl":[[6.6,8.93]],"id":40995914},{"atl":[[7.8,0]],"id":41360966}],"con":true,"img":false}]}
{"op":"mcm","clk":"5346744936","pt":1646095790043,"mc":[{"id":"1.195395450","rc":[{"atl":[[6,8.63]],"id":40995914},{"atl":[[7.2,5.33]],"id":41360966}],"con":true,"img":false}]}
{"op":"mcm","clk":"5346745012","pt":1646095792411,"mc":[{"id":"1.195395450","rc":[{"atb":[[2.5,0]],"id":40494151}],"con":true,"img":false}]}
{"op":"mcm","clk":"5346745029","pt":1646095793437,"mc":[{"id":"1.195395450","rc":[{"atl":[[5.4,0]],"id":41962160}],"con":true,"img":false}]}
{"op":"mcm","clk":"5346745118","pt":1646095796421,"mc":[{"id":"1.195395450","rc":[{"atl":[[7,6.76]],"id":40494151}],"con":true,"img":false}]}
{"op":"mcm","clk":"5346745123","pt":1646095796525,"mc":[{"id":"1.195395450","rc":[{"atl":[[7.2,0]],"id":41360966},{"atl":[[7.8,0]],"id":40494151}],"con":true,"img":false}]}
{"op":"mcm","clk":"5346745129","pt":1646095796626,"mc":[{"id":"1.195395450","rc":[{"atl":[[8.6,5.33]],"id":41360966}],"con":true,"img":false}]}
{"op":"mcm","clk":"5346745150","pt":1646095797242,"mc":[{"id":"1.195395450","rc":[{"atb":[[2.5,7.47]],"id":40494151}],"con":true,"img":false}]}
{"op":"mcm","clk":"5346745184","pt":1646095798627,"mc":[{"id":"1.195395450","rc":[{"atl":[[9.8,8.52]],"id":37495442}],"con":true,"img":false}]}
{"op":"mcm","clk":"5346745188","pt":1646095798856,"mc":[{"id":"1.195395450","rc":[{"atl":[[5.8,11.13]],"id":40995914},{"atb":[[2.42,27.41]],"id":40494151},{"atl":[[5.4,4.55]],"id":41962160},{"atl":[[2.76,26.69]],"id":40908100}],"con":true,"img":false}]}
{"op":"mcm","clk":"5346745192","pt":1646095798960,"mc":[{"id":"1.195395450","rc":[{"atl":[[5.8,15.3],[6.2,0],[5.9,8.93]],"id":40995914},{"atl":[[5.9,4.08]],"id":41360966},{"atb":[[2.24,181.46]],"id":40494151},{"atl":[[14,1.54],[15.5,6.71]],"id":25760990},{"atl":[[2.86,0],[2.76,38.05]],"id":40908100}],"con":true,"img":false}]}
{"op":"mcm","clk":"5346745197","pt":1646095799064,"mc":[{"id":"1.195395450","rc":[{"atl":[[5.8,6.67]],"id":40995914}],"con":true,"img":false}]}
{"op":"mcm","clk":"5346745213","pt":1646095799425,"mc":[{"id":"1.195395450","rc":[{"atl":[[7.2,8.06]],"id":40494151}],"con":true,"img":false}]}
{"op":"mcm","clk":"5346745243","pt":1646095800245,"mc":[{"id":"1.195395450","rc":[{"atb":[[2.48,5.64]],"id":40494151}],"con":true,"img":false}]}
{"op":"mcm","clk":"5346745299","pt":1646095801735,"mc":[{"id":"1.195395450","rc":[{"atl":[[5.4,0]],"id":41962160}],"con":true,"img":false}]}
{"op":"mcm","clk":"5346745443","pt":1646095806147,"mc":[{"id":"1.195395450","rc":[{"atb":[[2.46,5.1]],"id":40494151}],"con":true,"img":false}]}
{"op":"mcm","clk":"5346745458","pt":1646095806662,"mc":[{"id":"1.195395450","rc":[{"atl":[[5.4,4.55]],"id":41962160}],"con":true,"img":false}]}
{"op":"mcm","clk":"5346745520","pt":1646095808663,"mc":[{"id":"1.195395450","rc":[{"atl":[[10.5,16.94]],"id":37495442}],"con":true,"img":false}]}
{"op":"mcm","clk":"5346745523","pt":1646095808868,"mc":[{"id":"1.195395450","rc":[{"atl":[[6,18.63]],"id":40995914},{"atl":[[15,3.57]],"id":25760990},{"atl":[[2.8,27.78]],"id":40908100}],"con":true,"img":false}]}
{"op":"mcm","clk":"5346745530","pt":1646095808970,"mc":[{"id":"1.195395450","rc":[{"atl":[[6,34.23],[5.9,0]],"id":40995914}],"con":true,"img":false}]}
{"op":"mcm","clk":"5346745553","pt":1646095809487,"mc":[{"id":"1.195395450","rc":[{"atl":[[7.6,13.17]],"id":40494151}],"con":true,"img":false}]}
{"op":"mcm","clk":"5346745568","pt":1646095809947,"mc":[{"id":"1.195395450","rc":[{"atl":[[7,0]],"id":40494151}],"con":true,"img":false}]}
{"op":"mcm","clk":"5346745573","pt":1646095810050,"mc":[{"id":"1.195395450","rc":[{"atl":[[7.4,0],[6.6,0],[7,0]],"id":40995914},{"atl":[[7.4,6.76]],"id":40494151},{"atl":[[5.4,0]],"id":41962160},{"atl":[[16.5,0],[17.5,0],[18.5,0]],"id":25760990},{"atl":[[2.9,0],[2.98,0],[2.94,12.38]],"id":40908100}],"con":true,"img":false}]}
{"op":"mcm","clk":"5346745664","pt":1646095813740,"mc":[{"id":"1.195395450","rc":[{"atb":[[2.48,0]],"id":40494151}],"con":true,"img":false}]}
{"op":"mcm","clk":"5346745700","pt":1646095814763,"mc":[{"id":"1.195395450","rc":[{"atl":[[5.4,4.55]],"id":41962160}],"con":true,"img":false}]}
{"op":"mcm","clk":"5346745754","pt":1646095816557,"mc":[{"id":"1.195395450","rc":[{"atb":[[2.5,0]],"id":40494151}],"con":true,"img":false}]}
{"op":"mcm","clk":"5346745793","pt":1646095817786,"mc":[{"id":"1.195395450","rc":[{"atl":[[5.4,0]],"id":41962160}],"con":true,"img":false}]}
{"op":"mcm","clk":"5346745834","pt":1646095818873,"mc":[{"id":"1.195395450","rc":[{"atl":[[6.4,13.89]],"id":40995914},{"atl":[[16,5]],"id":25760990},{"atl":[[2.84,67.44]],"id":40908100}],"con":true,"img":false}]}
{"op":"mcm","clk":"5346745843","pt":1646095819077,"mc":[{"id":"1.195395450","rc":[{"atl":[[5.8,20.56],[6,18.63]],"id":40995914},{"atb":[[2.46,10.82]],"id":40494151}],"con":true,"img":false}]}
{"op":"mcm","clk":"5346745858","pt":1646095819487,"mc":[{"id":"1.195395450","rc":[{"atl":[[8,17.86]],"id":40494151}],"con":true,"img":false}]}
{"op":"mcm","clk":"5346745871","pt":1646095819898,"mc":[{"id":"1.195395450","rc":[{"atb":[[2.52,0]],"id":40995914},{"atl":[[9.6,4.86]],"id":37495442},{"atl":[[2.84,40.76]],"id":40908100}],"con":true,"img":false}]}
{"op":"mcm","clk":"5346745877","pt":1646095819949,"mc":[{"id":"1.195395450","rc":[{"atl":[[10.5,13.16]],"id":37495442},{"atb":[[2.48,29.39]],"id":40995914},{"atl":[[2.74,33.58]],"id":40908100}],"con":true,"img":false}]}
{"op":"mcm","clk":"5346745913","pt":1646095821279,"mc":[{"id":"1.195395450","rc":[{"atb":[[2.58,0]],"id":40995914},{"atb":[[2.48,3.57]],"id":40494151}],"con":true,"img":false}]}
{"op":"mcm","clk":"5346745942","pt":1646095822405,"mc":[{"id":"1.195395450","rc":[{"atl":[[5.4,4.55]],"id":41962160}],"con":true,"img":false}]}
{"op":"mcm","clk":"5346746038","pt":1646095825890,"mc":[{"id":"1.195395450","rc":[{"atl":[[5.4,0]],"id":41962160}],"con":true,"img":false}]}
{"op":"mcm","clk":"5346746077","pt":1646095827224,"mc":[{"id":"1.195395450","rc":[{"atb":[[2.56,10.13]],"id":40995914}],"con":true,"img":false}]}
{"op":"mcm","clk":"5346746124","pt":1646095828914,"mc":[{"id":"1.195395450","rc":[{"atl":[[6.8,21.55]],"id":40995914},{"atl":[[17,7.81]],"id":25760990},{"atl":[[2.88,66.49]],"id":40908100}],"con":true,"img":false}]}
{"op":"mcm","clk":"5346746149","pt":1646095829885,"mc":[{"id":"1.195395450","rc":[{"atl":[[6,10]],"id":40995914},{"atb":[[2.22,0]],"id":40494151}],"con":true,"img":false}]}
{"op":"mcm","clk":"5346746154","pt":1646095829989,"mc":[{"id":"1.195395450","rc":[{"atl":[[6.2,8.63]],"id":40995914},{"atb":[[2.26,32.99]],"id":40494151}],"con":true,"img":false}]}
{"op":"mcm","clk":"5346746187","pt":1646095830710,"mc":[{"id":"1.195395450","rc":[{"atl":[[5.4,4.55]],"id":41962160}],"con":true,"img":false}]}
{"op":"mcm","clk":"5346746273","pt":1646095833527,"mc":[{"id":"1.195395450","rc":[{"atl":[[5.4,0]],"id":41962160}],"con":true,"img":false}]}
{"op":"mcm","clk":"5346746342","pt":1646095835831,"mc":[{"id":"1.195395450","rc":[{"atl":[[5.4,4.55]],"id":41962160}],"con":true,"img":false}]}
{"op":"mcm","clk":"5346746349","pt":1646095836239,"mc":[{"id":"1.195395450","rc":[{"atl":[[5.4,0]],"id":41962160}],"con":true,"img":false}]}
{"op":"mcm","clk":"5346746411","pt":1646095838912,"mc":[{"id":"1.195395450","rc":[{"atl":[[5.4,4.55]],"id":41962160}],"con":true,"img":false}]}
{"op":"mcm","clk":"5346746595","pt":1646095846141,"mc":[{"id":"1.195395450","rc":[{"atl":[[5.4,0]],"id":41962160}],"con":true,"img":false}]}
{"op":"mcm","clk":"5346746658","pt":1646095848450,"mc":[{"id":"1.195395450","rc":[{"atl":[[5.4,4.55]],"id":41962160}],"con":true,"img":false}]}
{"op":"mcm","clk":"5346746700","pt":1646095849925,"mc":[{"id":"1.195395450","rc":[{"atl":[[8.2,0]],"id":40494151}],"con":true,"img":false}]}
{"op":"mcm","clk":"5346746704","pt":1646095850026,"mc":[{"id":"1.195395450","rc":[{"atl":[[7.8,5.94]],"id":40494151}],"con":true,"img":false}]}
{"op":"mcm","clk":"5346746784","pt":1646095852333,"mc":[{"id":"1.195395450","rc":[{"atb":[[4.5,1.44]],"id":25760990}],"con":true,"img":false}]}
{"op":"mcm","clk":"5346746848","pt":1646095853822,"mc":[{"id":"1.195395450","rc":[{"atl":[[5.4,0]],"id":41962160}],"con":true,"img":false}]}
{"op":"mcm","clk":"5346746874","pt":1646095854644,"mc":[{"id":"1.195395450","rc":[{"atb":[[2.92,0]],"id":25760990}],"con":true,"img":false}]}
{"op":"mcm","clk":"5346746920","pt":1646095856743,"mc":[{"id":"1.195395450","rc":[{"atl":[[5.4,4.55]],"id":41962160}],"con":true,"img":false}]}
{"op":"mcm","clk":"5346747009","pt":1646095860229,"mc":[{"id":"1.195395450","rc":[{"atl":[[5.4,0]],"id":41962160}],"con":true,"img":false}]}
{"op":"mcm","clk":"5346747081","pt":1646095862225,"mc":[{"id":"1.195395450","rc":[{"atl":[[5.4,4.55]],"id":41962160}],"con":true,"img":false}]}
{"op":"mcm","clk":"5346747167","pt":1646095865144,"mc":[{"id":"1.195395450","rc":[{"atl":[[5.4,0]],"id":41962160}],"con":true,"img":false}]}
{"op":"mcm","clk":"5346747179","pt":1646095865552,"mc":[{"id":"1.195395450","rc":[{"atl":[[5.4,4.55]],"id":41962160}],"con":true,"img":false}]}
{"op":"mcm","clk":"5346747200","pt":1646095866167,"mc":[{"id":"1.195395450","rc":[{"atl":[[5.4,0]],"id":41962160}],"con":true,"img":false}]}
{"op":"mcm","clk":"5346747239","pt":1646095867250,"mc":[{"id":"1.195395450","rc":[{"atb":[[2.88,0]],"id":25760990}],"con":true,"img":false}]}
{"op":"mcm","clk":"5346747342","pt":1646095870783,"mc":[{"id":"1.195395450","rc":[{"atl":[[5.4,4.55]],"id":41962160}],"con":true,"img":false}]}
{"op":"mcm","clk":"5346747446","pt":1646095873450,"mc":[{"id":"1.195395450","rc":[{"atl":[[5.4,0]],"id":41962160}],"con":true,"img":false}]}
{"op":"mcm","clk":"5346747495","pt":1646095874682,"mc":[{"id":"1.195395450","rc":[{"atl":[[9,0],[9.2,2.44]],"id":37495442},{"atl":[[5.9,0],[6,4]],"id":41360966},{"atl":[[7.2,3.23],[6.8,0]],"id":40494151},{"atb":[[1.92,21.74],[1.55,0],[1.49,114.13],[1.95,126.38]],"id":41962160},{"atl":[[5.4,4.55]],"id":41962160},{"atb":[[1.27,40.56],[1.24,625]],"id":40908100}],"con":true,"img":false}]}
{"op":"mcm","clk":"5346747552","pt":1646095876275,"mc":[{"id":"1.195395450","rc":[{"atb":[[1.94,0]],"id":41962160},{"atl":[[5.4,0]],"id":41962160}],"con":true,"img":false}]}
{"op":"mcm","clk":"5346747584","pt":1646095876995,"mc":[{"id":"1.195395450","rc":[{"atl":[[5.4,4.55]],"id":41962160}],"con":true,"img":false}]}
{"op":"mcm","clk":"5346747658","pt":1646095878787,"mc":[{"id":"1.195395450","rc":[{"atl":[[5.4,0]],"id":41962160}],"con":true,"img":false}]}
{"op":"mcm","clk":"5346747742","pt":1646095881505,"mc":[{"id":"1.195395450","rc":[{"atl":[[5.4,4.55]],"id":41962160},{"atb":[[1.25,880.28]],"id":40908100}],"con":true,"img":false}]}
{"op":"mcm","clk":"5346747747","pt":1646095881612,"mc":[{"id":"1.195395450","rc":[{"atb":[[1.24,208.33]],"id":40908100}],"con":true,"img":false}]}
{"op":"mcm","clk":"5346747751","pt":1646095881709,"mc":[{"id":"1.195395450","rc":[{"atb":[[2.82,2]],"id":41962160}],"con":true,"img":false}]}
{"op":"mcm","clk":"5346747756","pt":1646095881813,"mc":[{"id":"1.195395450","rc":[{"atb":[[2.74,0],[2.84,0],[2.94,38.66]],"id":37495442},{"atl":[[8,0],[10,0],[20,0],[15,7.14],[30,0]],"id":37495442},{"atb":[[2.4,0],[2.3,0],[2.2,0]],"id":40494151},{"atl":[[9.6,0],[19,0],[5.8,0],[7.6,11.36],[14,0]],"id":40494151},{"atb":[[2.4,0],[2.5,0],[2.6,0]],"id":25760990},{"atl":[[6.2,0],[10.5,0],[21,0],[8.2,0],[15.5,5.06]],"id":25760990},{"atb":[[1.01,0]],"id":43066393},{"atl":[[2.28,0],[1.94,0],[2.68,0],[2.08,0],[2.48,0]],"id":43066393}],"con":true,"img":false}]}
{"op":"mcm","clk":"5346747763","pt":1646095881919,"mc":[{"id":"1.195395450","rc":[{"atb":[[2.84,3]],"id":41962160},{"atl":[[1.11,85.12]],"id":43066393}],"con":true,"img":false}]}
{"op":"mcm","clk":"5346747767","pt":1646095882023,"mc":[{"id":"1.195395450","rc":[{"atl":[[5.4,0]],"id":41962160},{"atl":[[14,9.23],[15.5,0]],"id":25760990}],"con":true,"img":false}]}
{"op":"mcm","clk":"5346747777","pt":1646095882282,"mc":[{"id":"1.195395450","rc":[{"atb":[[2.46,5.72]],"id":40494151},{"atb":[[2.06,7.87]],"id":41962160}],"con":true,"img":false}]}
{"op":"mcm","clk":"5346747796","pt":1646095882693,"mc":[{"id":"1.195395450","rc":[{"atb":[[2.86,2]],"id":41962160},{"atl":[[5.4,4.55]],"id":41962160},{"atl":[[1.1,2]],"id":43066393}],"con":true,"img":false}]}
{"op":"mcm","clk":"5346747804","pt":1646095882897,"mc":[{"id":"1.195395450","rc":[{"atb":[[2.88,4]],"id":41962160},{"atl":[[5.4,0]],"id":41962160},{"atl":[[1.09,2]],"id":43066393}],"con":true,"img":false}]}
{"op":"mcm","clk":"5346747853","pt":1646095884484,"mc":[{"id":"1.195395450","rc":[{"atl":[[5.4,4.55]],"id":41962160}],"con":true,"img":false}]}
{"op":"mcm","clk":"5346747862","pt":1646095884689,"mc":[{"id":"1.195395450","rc":[{"atl":[[9.6,10.67]],"id":37495442},{"atl":[[6.4,9.26]],"id":41360966},{"atl":[[7.6,7.58]],"id":40494151},{"atl":[[5.4,0]],"id":41962160}],"con":true,"img":false}]}
{"op":"mcm","clk":"5346747874","pt":1646095884995,"mc":[{"id":"1.195395450","rc":[{"atb":[[2.08,0]],"id":41962160},{"atl":[[5.4,4.55]],"id":41962160}],"con":true,"img":false}]}
{"op":"mcm","clk":"5346747876","pt":1646095885098,"mc":[{"id":"1.195395450","rc":[{"atl":[[10.5,0],[9.8,0],[9.4,3.68]],"id":37495442}],"con":true,"img":false}]}
{"op":"mcm","clk":"5346747880","pt":1646095885203,"mc":[{"id":"1.195395450","rc":[{"atb":[[2.82,0],[2.88,0],[2.86,0],[2.84,0]],"id":41962160}],"con":true,"img":false}]}
{"op":"mcm","clk":"5346747910","pt":1646095886020,"mc":[{"id":"1.195395450","rc":[{"atl":[[5.4,0]],"id":41962160},{"atl":[[1.08,2]],"id":43066393}],"con":true,"img":false}]}
{"op":"mcm","clk":"5346747928","pt":1646095886382,"mc":[{"id":"1.195395450","rc":[{"atl":[[5.4,4.55]],"id":41962160}],"con":true,"img":false}]}
{"op":"mcm","clk":"5346747935","pt":1646095886584,"mc":[{"id":"1.195395450","rc":[{"atb":[[2.8,66.7],[2.9,97.38],[2.7,70.63]],"id":37495442},{"atl":[[19.5,1.29],[9.8,1.36],[7.8,1.76],[14.5,1.77],[29,1.71]],"id":37495442},{"atb":[[2.4,85.76],[2.5,80.04],[2.6,37.52]],"id":40494151},{"atl":[[10.5,11.06],[6.2,2.3],[21,2.4],[8.2,1.66],[15.5,1.65]],"id":40494151},{"atb":[[2.4,85.76],[2.5,40.02],[2.3,92.36]],"id":25760990},{"atl":[[8,1.71],[10,2.66],[20,2.52],[6,2.4],[15,5.28]],"id":25760990},{"atb":[[1.01,30017.84]],"id":43066393},{"atl":[[2.26,19.05],[1.93,12.91],[2.06,11.32],[2.46,16.44],[2.66,28.93]],"id":43066393}],"con":true,"img":false}]}
{"op":"mcm","clk":"5346747940","pt":1646095886688,"mc":[{"id":"1.195395450","rc":[{"atl":[[9,2.5]],"id":37495442},{"atl":[[5.9,4.08],[6,0]],"id":41360966},{"atl":[[6.8,3.45]],"id":40494151},{"atb":[[1.95,147.43]],"id":41962160},{"atl":[[5.4,0]],"id":41962160}],"con":true,"img":false}]}
{"op":"mcm","clk":"5346747944","pt":1646095886791,"mc":[{"id":"1.195395450","rc":[{"atl":[[1.09,0],[1.1,0],[1.08,0],[1.11,81.12]],"id":43066393}],"con":true,"img":false}]}
{"op":"mcm","clk":"5346747949","pt":1646095886893,"mc":[{"id":"1.195395450","rc":[{"atl":[[5.4,4.55]],"id":41962160}],"con":true,"img":false}]}
{"op":"mcm","clk":"5346748050","pt":1646095889917,"mc":[{"id":"1.195395450","rc":[{"atb":[[2.52,0]],"id":25760990}],"con":true,"img":false}]}
{"op":"mcm","clk":"5346748056","pt":1646095890022,"mc":[{"id":"1.195395450","rc":[{"atb":[[2.42,29.01]],"id":25760990}],"con":true,"img":false}]}
{"op":"mcm","clk":"5346748061","pt":1646095890125,"mc":[{"id":"1.195395450","rc":[{"atl":[[5.4,0]],"id":41962160}],"con":true,"img":false}]}
{"op":"mcm","clk":"5346748073","pt":1646095890431,"mc":[{"id":"1.195395450","rc":[{"atb":[[2.48,0]],"id":40494151},{"atb":[[2.08,5.52]],"id":41962160},{"atl":[[5.4,4.55]],"id":41962160}],"con":true,"img":false}]}
{"op":"mcm","clk":"5346748089","pt":1646095890796,"mc":[{"id":"1.195395450","rc":[{"atb":[[1.27,313.62],[1.25,480.28]],"id":40908100}],"con":true,"img":false}]}
{"op":"mcm","clk":"5346748117","pt":1646095891513,"mc":[{"id":"1.195395450","rc":[{"atb":[[1.01,33767.82],[1.02,290.56]],"id":43066393}],"con":true,"img":false}]}
{"op":"mcm","clk":"5346748122","pt":1646095891715,"mc":[{"id":"1.195395450","rc":[{"atl":[[5.9,0],[6,4]],"id":41360966},{"atl":[[6.8,0]],"id":40494151},{"atb":[[1.95,126.38]],"id":41962160},{"atl":[[5.4,0]],"id":41962160}],"con":true,"img":false}]}
{"op":"mcm","clk":"5346748128","pt":1646095891818,"mc":[{"id":"1.195395450","rc":[{"atl":[[9,0]],"id":37495442}],"con":true,"img":false}]}
{"op":"mcm","clk":"5346748186","pt":1646095893415,"mc":[{"id":"1.195395450","rc":[{"atb":[[2.58,7.09]],"id":40995914}],"con":true,"img":false}]}
{"op":"mcm","clk":"5346748210","pt":1646095894227,"mc":[{"id":"1.195395450","rc":[{"atb":[[2.66,4.48]],"id":40494151},{"atb":[[2.06,14.9]],"id":41962160}],"con":true,"img":false}]}
{"op":"mcm","clk":"5346748226","pt":1646095894739,"mc":[{"id":"1.195395450","rc":[{"atl":[[5.4,4.55]],"id":41962160}],"con":true,"img":false}]}
{"op":"mcm","clk":"5346748245","pt":1646095895303,"mc":[{"id":"1.195395450","rc":[{"atl":[[5.4,0]],"id":41962160}],"con":true,"img":false}]}
{"op":"mcm","clk":"5346748254","pt":1646095895510,"mc":[{"id":"1.195395450","rc":[{"atl":[[5.4,4.55]],"id":41962160}],"con":true,"img":false}]}
{"op":"mcm","clk":"5346748264","pt":1646095895814,"mc":[{"id":"1.195395450","rc":[{"atl":[[5.4,0]],"id":41962160}],"con":true,"img":false}]}
{"op":"mcm","clk":"5346748272","pt":1646095896020,"mc":[{"id":"1.195395450","rc":[{"atl":[[5.4,4.55]],"id":41962160},{"atb":[[1.27,40.56],[1.25,880.28]],"id":40908100}],"con":true,"img":false}]}
{"op":"mcm","clk":"5346748281","pt":1646095896328,"mc":[{"id":"1.195395450","rc":[{"atl":[[5.4,0]],"id":41962160}],"con":true,"img":false}]}
{"op":"mcm","clk":"5346748294","pt":1646095896734,"mc":[{"id":"1.195395450","rc":[{"atl":[[10,8.33]],"id":37495442},{"atl":[[8,10.71]],"id":40494151}],"con":true,"img":false}]}
{"op":"mcm","clk":"5346748318","pt":1646095897299,"mc":[{"id":"1.195395450","rc":[{"atl":[[5.4,4.55]],"id":41962160}],"con":true,"img":false}]}
{"op":"mcm","clk":"5346748324","pt":1646095897505,"mc":[{"id":"1.195395450","rc":[{"atb":[[2.46,0]],"id":40494151}],"con":true,"img":false}]}
{"op":"mcm","clk":"5346748359","pt":1646095898631,"mc":[{"id":"1.195395450","rc":[{"atb":[[1.02,250]],"id":43066393}],"con":true,"img":false}]}
{"op":"mcm","clk":"5346748362","pt":1646095898733,"mc":[{"id":"1.195395450","rc":[{"atl":[[18,5.88],[9.2,0],[9.8,3.63],[15,0]],"id":37495442},{"atb":[[2.3,92.36],[2.38,72.46]],"id":40995914},{"atl":[[5.8,6.67],[6,30]],"id":40995914},{"atb":[[2.88,44.58],[3.05,0]],"id":41360966},{"atl":[[9.2,0],[5.8,4.17],[6,0],[7.6,11.81]],"id":41360966},{"atl":[[7,3.33]],"id":40494151},{"atb":[[1.96,20.83]],"id":41962160},{"atl":[[5.4,0]],"id":41962160},{"atb":[[2.74,0],[2.6,53.76]],"id":25760990},{"atb":[[1.01,33808.38]],"id":43066393},{"atl":[[1.33,60.61],[1.31,0]],"id":43066393}],"con":true,"img":false}]}
{"op":"mcm","clk":"5346748378","pt":1646095899141,"mc":[{"id":"1.195395450","rc":[{"atb":[[3.15,9.3],[3.05,13.39]],"id":37495442},{"atl":[[9.6,4.86]],"id":37495442},{"atb":[[2.4,100.05],[2.36,0]],"id":40494151}],"con":true,"img":false}]}
{"op":"mcm","clk":"5346748383","pt":1646095899243,"mc":[{"id":"1.195395450","rc":[{"atl":[[5.4,4.55]],"id":41962160}],"con":true,"img":false}]}
{"op":"mcm","clk":"5346748409","pt":1646095899912,"mc":[{"id":"1.195395450","rc":[{"atl":[[9.6,0]],"id":37495442},{"atb":[[2.96,0]],"id":41360966},{"atl":[[7.4,0],[7.8,0]],"id":40494151}],"con":true,"img":false}]}
{"op":"mcm","clk":"5346748412","pt":1646095900015,"mc":[{"id":"1.195395450","rc":[{"atl":[[9.8,8.5]],"id":37495442},{"atb":[[2.86,49.16]],"id":41360966},{"atl":[[8,23.42]],"id":40494151}],"con":true,"img":false}]}
{"op":"mcm","clk":"5346748423","pt":1646095900323,"mc":[{"id":"1.195395450","rc":[{"atl":[[7.4,3.12]],"id":40494151},{"atb":[[1.91,76.06],[1.96,0]],"id":41962160},{"atl":[[5.4,0]],"id":41962160}],"con":true,"img":false}]}
{"op":"mcm","clk":"5346748428","pt":1646095900424,"mc":[{"id":"1.195395450","rc":[{"atl":[[7,0]],"id":40494151}],"con":true,"img":false}]}
{"op":"mcm","clk":"5346748476","pt":1646095902014,"mc":[{"id":"1.195395450","rc":[{"atl":[[7.2,0]],"id":40494151},{"atl":[[5.4,4.55]],"id":41962160}],"con":true,"img":false}]}
{"op":"mcm","clk":"5346748480","pt":1646095902114,"mc":[{"id":"1.195395450","rc":[{"atb":[[1.92,0]],"id":41962160}],"con":true,"img":false}]}
{"op":"mcm","clk":"5346748540","pt":1646095903750,"mc":[{"id":"1.195395450","rc":[{"atb":[[2.66,9.51]],"id":40494151}],"con":true,"img":false}]}
{"op":"mcm","clk":"5346748542","pt":1646095903854,"mc":[{"id":"1.195395450","rc":[{"atl":[[6.2,27.86],[6,10]],"id":40995914}],"con":true,"img":false}]}
{"op":"mcm","clk":"5346748553","pt":1646095904163,"mc":[{"id":"1.195395450","rc":[{"atb":[[2.26,0]],"id":40494151}],"con":true,"img":false}]}
{"op":"mcm","clk":"5346748558","pt":1646095904218,"mc":[{"id":"1.195395450","rc":[{"atb":[[2.3,32.99]],"id":40494151}],"con":true,"img":false}]}
{"op":"mcm","clk":"5346748583","pt":1646095905341,"mc":[{"id":"1.195395450","rc":[{"atl":[[10.5,2.52]],"id":40494151},{"atl":[[5.4,0]],"id":41962160}],"con":true,"img":false}]}
{"op":"mcm","clk":"5346748587","pt":1646095905444,"mc":[{"id":"1.195395450","rc":[{"atl":[[13,8.33]],"id":40494151}],"con":true,"img":false}]}
{"op":"mcm","clk":"5346748621","pt":1646095906724,"mc":[{"id":"1.195395450","rc":[{"atl":[[5.4,4.55]],"id":41962160}],"con":true,"img":false}]}
{"op":"mcm","clk":"5346748627","pt":1646095906930,"mc":[{"id":"1.195395450","rc":[{"atl":[[5.4,0]],"id":41962160}],"con":true,"img":false}]}
{"op":"mcm","clk":"5346748630","pt":1646095907033,"mc":[{"id":"1.195395450","rc":[{"atl":[[5.4,4.55]],"id":41962160}],"con":true,"img":false}]}
{"op":"mcm","clk":"5346748684","pt":1646095908728,"mc":[{"id":"1.195395450","rc":[{"atl":[[6,10]],"id":41360966},{"atl":[[1.35,142.86]],"id":43066393}],"con":true,"img":false}]}
{"op":"mcm","clk":"5346748697","pt":1646095909136,"mc":[{"id":"1.195395450","rc":[{"atb":[[3.05,37.78]],"id":37495442},{"atl":[[10.5,5.26]],"id":37495442}],"con":true,"img":false}]}
{"op":"mcm","clk":"5346748709","pt":1646095909447,"mc":[{"id":"1.195395450","rc":[{"atb":[[2.9,31.59]],"id":37495442},{"atl":[[7.4,0],[7,0]],"id":41360966},{"atl":[[5.4,0]],"id":41962160}],"con":true,"img":false}]}
{"op":"mcm","clk":"5346748734","pt":1646095910365,"mc":[{"id":"1.195395450","rc":[{"atb":[[2.36,36.76]],"id":40494151},{"atl":[[7.8,7.35]],"id":40494151}],"con":true,"img":false}]}
{"op":"mcm","clk":"5346748774","pt":1646095911960,"mc":[{"id":"1.195395450","rc":[{"atb":[[2.6,14.18]],"id":40995914},{"atb":[[2.96,15.73]],"id":41360966},{"atb":[[2.52,20.29]],"id":40494151},{"atb":[[2.1,11.04]],"id":41962160},{"atb":[[2.92,16.06]],"id":25760990},{"atb":[[1.28,110.14]],"id":40908100}],"con":true,"img":false}]}
{"op":"mcm","clk":"5346748785","pt":1646095912369,"mc":[{"id":"1.195395450","rc":[{"atb":[[3.05,34.15]],"id":37495442}],"con":true,"img":false}]}
{"op":"mcm","clk":"5346748840","pt":1646095913856,"mc":[{"id":"1.195395450","rc":[{"atb":[[2.42,0]],"id":40494151}],"con":true,"img":false}]}
{"op":"mcm","clk":"5346748843","pt":1646095913966,"mc":[{"id":"1.195395450","rc":[{"atb":[[2.62,27.41]],"id":40494151}],"con":true,"img":false}]}
{"op":"mcm","clk":"5346748863","pt":1646095914674,"mc":[{"id":"1.195395450","rc":[{"atb":[[2.88,0],[2.9,55.11]],"id":41360966},{"atb":[[2.24,80.65]],"id":40494151},{"atl":[[5.4,4.55]],"id":41962160}],"con":true,"img":false}]}
{"op":"mcm","clk":"5346748883","pt":1646095915441,"mc":[{"id":"1.195395450","rc":[{"atb":[[2.58,0]],"id":40995914},{"atb":[[2.08,0]],"id":41962160}],"con":true,"img":false}]}
{"op":"mcm","clk":"5346748888","pt":1646095915645,"mc":[{"id":"1.195395450","rc":[{"atb":[[2.66,5.02]],"id":40494151}],"con":true,"img":false}]}
{"op":"mcm","clk":"5346748900","pt":1646095916160,"mc":[{"id":"1.195395450","rc":[{"atb":[[1.27,0]],"id":40908100}],"con":true,"img":false}]}
{"op":"mcm","clk":"5346748903","pt":1646095916259,"mc":[{"id":"1.195395450","rc":[{"atb":[[1.31,113.5]],"id":40908100}],"con":true,"img":false}]}
{"op":"mcm","clk":"5346748931","pt":1646095917383,"mc":[{"id":"1.195395450","rc":[{"atb":[[2.52,0]],"id":40494151}],"con":true,"img":false}]}
{"op":"mcm","clk":"5346748933","pt":1646095917485,"mc":[{"id":"1.195395450","rc":[{"atl":[[5.4,0]],"id":41962160}],"con":true,"img":false}]}
{"op":"mcm","clk":"5346748945","pt":1646095917744,"mc":[{"id":"1.195395450","rc":[{"atl":[[5.4,4.55]],"id":41962160}],"con":true,"img":false}]}
{"op":"mcm","clk":"5346748957","pt":1646095918002,"mc":[{"id":"1.195395450","rc":[{"atl":[[5.4,0]],"id":41962160}],"con":true,"img":false}]}
{"op":"mcm","clk":"5346748967","pt":1646095918371,"mc":[{"id":"1.195395450","rc":[{"atb":[[3.1,3.54]],"id":37495442}],"con":true,"img":false}]}
{"op":"mcm","clk":"5346748972","pt":1646095918464,"mc":[{"id":"1.195395450","rc":[{"atb":[[3.15,18.6],[3.05,24.39]],"id":37495442}],"con":true,"img":false}]}
{"op":"mcm","clk":"5346748982","pt":1646095918779,"mc":[{"id":"1.195395450","rc":[{"atl":[[6.4,13.89]],"id":41360966},{"atl":[[1.37,202.7]],"id":43066393}],"con":true,"img":false}]}
{"op":"mcm","clk":"5346748989","pt":1646095919180,"mc":[{"id":"1.195395450","rc":[{"atb":[[2.98,37.88]],"id":37495442},{"atl":[[11.5,7.14]],"id":37495442},{"atb":[[2.1,0]],"id":41962160}],"con":true,"img":false}]}
{"op":"mcm","clk":"5346749008","pt":1646095919796,"mc":[{"id":"1.195395450","rc":[{"atb":[[2.88,49.17],[2.9,10.53]],"id":41360966}],"con":true,"img":false}]}
{"op":"mcm","clk":"5346749015","pt":1646095920156,"mc":[{"id":"1.195395450","rc":[{"atb":[[2.86,26.88]],"id":41360966}],"con":true,"img":false}]}
{"op":"mcm","clk":"5346749017","pt":1646095920262,"mc":[{"id":"1.195395450","rc":[{"atb":[[2.96,38.02]],"id":41360966},{"atb":[[2.32,94.7]],"id":40494151},{"atl":[[8.2,12.08]],"id":40494151},{"atb":[[2.12,7.72]],"id":41962160}],"con":true,"img":false}]}
{"op":"mcm","clk":"5346749020","pt":1646095920360,"mc":[{"id":"1.195395450","rc":[{"atb":[[2.32,56.82]],"id":40494151}],"con":true,"img":false}]}
{"op":"mcm","clk":"5346749039","pt":1646095921076,"mc":[{"id":"1.195395450","rc":[{"atb":[[2.68,10.05]],"id":40494151}],"con":true,"img":false}]}
{"op":"mcm","clk":"5346749053","pt":1646095921496,"mc":[{"id":"1.195395450","rc":[{"atb":[[3,4.17]],"id":41360966},{"atb":[[2.68,14.49]],"id":40494151}],"con":true,"img":false}]}
{"op":"mcm","clk":"5346749082","pt":1646095922463,"mc":[{"id":"1.195395450","rc":[{"atl":[[8,12.71],[7.6,0]],"id":40494151},{"atl":[[5.4,4.55]],"id":41962160}],"con":true,"img":false}]}
{"op":"mcm","clk":"5346749099","pt":1646095923080,"mc":[{"id":"1.195395450","rc":[{"atb":[[2.08,21.24]],"id":41962160}],"con":true,"img":false}]}
{"op":"mcm","clk":"5346749151","pt":1646095924976,"mc":[{"id":"1.195395450","rc":[{"atl":[[5.4,0]],"id":41962160}],"con":true,"img":false}]}
{"op":"mcm","clk":"5346749239","pt":1646095927488,"mc":[{"id":"1.195395450","rc":[{"atb":[[3,0]],"id":37495442},{"atb":[[3.05,3.63]],"id":41360966}],"con":true,"img":false}]}
{"op":"mcm","clk":"5346749250","pt":1646095927797,"mc":[{"id":"1.195395450","rc":[{"atl":[[5.4,4.55]],"id":41962160}],"con":true,"img":false}]}
{"op":"mcm","clk":"5346749274","pt":1646095928512,"mc":[{"id":"1.195395450","rc":[{"atl":[[5.4,0]],"id":41962160}],"con":true,"img":false}]}
{"op":"mcm","clk":"5346749283","pt":1646095928821,"mc":[{"id":"1.195395450","rc":[{"atl":[[6.8,21.55]],"id":41360966},{"atl":[[1.39,250]],"id":43066393}],"con":true,"img":false}]}
{"op":"mcm","clk":"5346749299","pt":1646095929179,"mc":[{"id":"1.195395450","rc":[{"atb":[[2.94,64.43]],"id":37495442},{"atl":[[12.5,10.87]],"id":37495442}],"con":true,"img":false}]}
{"op":"mcm","clk":"5346749323","pt":1646095930306,"mc":[{"id":"1.195395450","rc":[{"atb":[[2.28,97.66]],"id":40494151},{"atl":[[8.6,16.45]],"id":40494151}],"con":true,"img":false}]}
{"op":"mcm","clk":"5346749337","pt":1646095930715,"mc":[{"id":"1.195395450","rc":[{"atb":[[2.96,22.28]],"id":41360966}],"con":true,"img":false}]}
{"op":"mcm","clk":"5346749340","pt":1646095930818,"mc":[{"id":"1.195395450","rc":[{"atl":[[5.4,4.55]],"id":41962160}],"con":true,"img":false}]}
{"op":"mcm","clk":"5346749345","pt":1646095930920,"mc":[{"id":"1.195395450","rc":[{"atl":[[10,0]],"id":37495442}],"con":true,"img":false}]}
{"op":"mcm","clk":"5346749382","pt":1646095932203,"mc":[{"id":"1.195395450","rc":[{"atb":[[2.96,0]],"id":37495442},{"atl":[[9.8,3.63]],"id":37495442}],"con":true,"img":false}]}
{"op":"mcm","clk":"5346749387","pt":1646095932309,"mc":[{"id":"1.195395450","rc":[{"atb":[[3,22.28]],"id":37495442},{"atl":[[10.5,10.12]],"id":37495442}],"con":true,"img":false}]}
{"op":"mcm","clk":"5346749401","pt":1646095932720,"mc":[{"id":"1.195395450","rc":[{"atl":[[6.4,22.22],[5.8,2.5],[6.2,8.63],[6,0]],"id":40995914},{"atb":[[2.72,58.14],[2.88,0]],"id":41360966},{"atl":[[8,4.57],[6.4,0],[5.8,0],[6,0],[6.8,0]],"id":41360966},{"atb":[[2.32,0],[1.71,75.06],[2.4,85.76],[2.36,0],[2.24,0],[1.81,24.69],[2.28,0]],"id":40494151},{"atl":[[3.45,8.16]],"id":41962160},{"atl":[[16,0],[17,0],[20,8.83],[14,0],[15,1.71]],"id":25760990}],"con":true,"img":false}]}
{"op":"mcm","clk":"5346749405","pt":1646095932825,"mc":[{"id":"1.195395450","rc":[{"atl":[[8.2,13.89]],"id":41360966}],"con":true,"img":false}]}
{"op":"mcm","clk":"5346749408","pt":1646095932878,"mc":[{"id":"1.195395450","rc":[{"atl":[[7.6,0]],"id":41360966}],"con":true,"img":false}]}
{"op":"mcm","clk":"5346749415","pt":1646095933288,"mc":[{"id":"1.195395450","rc":[{"atb":[[3.05,28.46]],"id":37495442}],"con":true,"img":false}]}
{"op":"mcm","clk":"5346749418","pt":1646095933390,"mc":[{"id":"1.195395450","rc":[{"atb":[[3.05,0]],"id":41360966}],"con":true,"img":false}]}
{"op":"mcm","clk":"5346749439","pt":1646095934211,"mc":[{"id":"1.195395450","rc":[{"atb":[[2.3,0]],"id":40494151}],"con":true,"img":false}]}
{"op":"mcm","clk":"5346749443","pt":1646095934313,"mc":[{"id":"1.195395450","rc":[{"atb":[[2.2,32.99]],"id":40494151}],"con":true,"img":false}]}
{"op":"mcm","clk":"5346749446","pt":1646095934416,"mc":[{"id":"1.195395450","rc":[{"atb":[[3.1,7.27]],"id":41360966}],"con":true,"img":false}]}
{"op":"mcm","clk":"5346749496","pt":1646095936107,"mc":[{"id":"1.195395450","rc":[{"atl":[[8,6.76]],"id":40494151},{"atb":[[1.91,21.98]],"id":41962160}],"con":true,"img":false}]}
{"op":"mcm","clk":"5346749499","pt":1646095936213,"mc":[{"id":"1.195395450","rc":[{"atl":[[8.4,5.94]],"id":40494151},{"atb":[[1.73,54.08]],"id":41962160}],"con":true,"img":false}]}
{"op":"mcm","clk":"5346749545","pt":1646095938212,"mc":[{"id":"1.195395450","rc":[{"atl":[[10,2.22]],"id":37495442}],"con":true,"img":false}]}
{"op":"mcm","clk":"5346749551","pt":1646095938417,"mc":[{"id":"1.195395450","rc":[{"atl":[[9.8,1.36]],"id":37495442}],"con":true,"img":false}]}
{"op":"mcm","clk":"5346749583","pt":1646095939500,"mc":[{"id":"1.195395450","rc":[{"atb":[[3,7.9]],"id":41360966}],"con":true,"img":false}]}
{"op":"mcm","clk":"5346749611","pt":1646095940213,"mc":[{"id":"1.195395450","rc":[{"atb":[[2.48,0]],"id":40995914},{"atl":[[8.6,0]],"id":41360966}],"con":true,"img":false}]}
{"op":"mcm","clk":"5346749614","pt":1646095940316,"mc":[{"id":"1.195395450","rc":[{"atb":[[2.52,29.39]],"id":40995914},{"atl":[[8,9.91]],"id":41360966}],"con":true,"img":false}]}
{"op":"mcm","clk":"5346749663","pt":1646095942419,"mc":[{"id":"1.195395450","rc":[{"atb":[[2.56,5.35]],"id":40995914}],"con":true,"img":false}]}
{"op":"mcm","clk":"5346749667","pt":1646095942728,"mc":[{"id":"1.195395450","rc":[{"atl":[[6.8,8.62]],"id":40995914},{"atl":[[8.4,6.76]],"id":41360966},{"atb":[[1.79,63.29]],"id":40494151},{"atb":[[1.89,56.18]],"id":41962160},{"atl":[[3.55,19.61]],"id":41962160},{"atl":[[22,2.38]],"id":25760990}],"con":true,"img":false}]}
{"op":"mcm","clk":"5346749719","pt":1646095944930,"mc":[{"id":"1.195395450","rc":[{"atl":[[10,0],[9.8,3.63]],"id":37495442}],"con":true,"img":false}]}
{"op":"mcm","clk":"5346749744","pt":1646095945598,"mc":[{"id":"1.195395450","rc":[{"atl":[[10,2.22],[9.8,1.36]],"id":37495442}],"con":true,"img":false}]}
{"op":"mcm","clk":"5346749806","pt":1646095948007,"mc":[{"id":"1.195395450","rc":[{"atl":[[10,0],[9.8,3.63]],"id":37495442}],"con":true,"img":false}]}
{"op":"mcm","clk":"5346749829","pt":1646095948621,"mc":[{"id":"1.195395450","rc":[{"atb":[[2.58,4.71]],"id":40995914}],"con":true,"img":false}]}
{"op":"mcm","clk":"5346749974","pt":1646095952725,"mc":[{"id":"1.195395450","rc":[{"atl":[[7.2,12.1]],"id":40995914},{"atl":[[8.8,9.62]],"id":41360966},{"atb":[[1.77,97.4]],"id":40494151},{"atb":[[1.87,86.21]],"id":41962160},{"atl":[[3.65,28.3]],"id":41962160},{"atl":[[24,3.26]],"id":25760990}],"con":true,"img":false}]}
{"op":"mcm","clk":"5346749977","pt":1646095952827,"mc":[{"id":"1.195395450","rc":[{"atl":[[3.6,27.77],[5,8.11]],"id":41962160}],"con":true,"img":false}]}
{"op":"mcm","clk":"5346749993","pt":1646095953340,"mc":[{"id":"1.195395450","rc":[{"atl":[[10,2.22],[9.8,1.36]],"id":37495442},{"atl":[[5.4,0],[5.6,0]],"id":41962160}],"con":true,"img":false}]}
{"op":"mcm","clk":"5346750018","pt":1646095954259,"mc":[{"id":"1.195395450","rc":[{"atl":[[1.63,0]],"id":43066393}],"con":true,"img":false}]}
{"op":"mcm","clk":"5346750020","pt":1646095954362,"mc":[{"id":"1.195395450","rc":[{"atl":[[1.59,40.56]],"id":43066393}],"con":true,"img":false}]}
{"op":"mcm","clk":"5346750062","pt":1646095955746,"mc":[{"id":"1.195395450","rc":[{"atl":[[10,0],[9.8,3.63]],"id":37495442}],"con":true,"img":false}]}
{"op":"mcm","clk":"5346750081","pt":1646095956268,"mc":[{"id":"1.195395450","rc":[{"atb":[[3,0]],"id":37495442}],"con":true,"img":false}]}
{"op":"mcm","clk":"5346750084","pt":1646095956322,"mc":[{"id":"1.195395450","rc":[{"atb":[[3.1,25.83]],"id":37495442}],"con":true,"img":false}]}
{"op":"mcm","clk":"5346750206","pt":1646095961141,"mc":[{"id":"1.195395450","rc":[{"atl":[[10,2.22],[9.8,1.36]],"id":37495442},{"atl":[[8.2,0],[8.4,20.27]],"id":41360966},{"atb":[[1.92,21.74],[1.91,0]],"id":41962160},{"atl":[[1.33,0],[1.32,62.5]],"id":43066393}],"con":true,"img":false}]}
{"op":"mcm","clk":"5346750224","pt":1646095962062,"mc":[{"id":"1.195395450","rc":[{"atb":[[2.7,49.46]],"id":25760990}],"con":true,"img":false}]}
{"op":"mcm","clk":"5346750228","pt":1646095962165,"mc":[{"id":"1.195395450","rc":[{"atl":[[9.8,3.63]],"id":37495442},{"atl":[[7.4,0],[7.6,3.03]],"id":40494151},{"atb":[[1.92,0],[1.91,21.98]],"id":41962160},{"atb":[[2.6,0]],"id":25760990}],"con":true,"img":false}]}
{"op":"mcm","clk":"5346750231","pt":1646095962270,"mc":[{"id":"1.195395450","rc":[{"atl":[[10,0]],"id":37495442}],"con":true,"img":false}]}
{"op":"mcm","clk":"5346750242","pt":1646095962782,"mc":[{"id":"1.195395450","rc":[{"atl":[[7.6,20.75]],"id":40995914},{"atl":[[9.2,15.24]],"id":41360966},{"atl":[[26,5]],"id":25760990}],"con":true,"img":false}]}
{"op":"mcm","clk":"5346750292","pt":1646095964571,"mc":[{"id":"1.195395450","rc":[{"atb":[[3.1,0]],"id":41360966}],"con":true,"img":false}]}
{"op":"mcm","clk":"5346750297","pt":1646095964673,"mc":[{"id":"1.195395450","rc":[{"atb":[[2.62,9.93]],"id":40995914},{"atb":[[2.8,55.56],[2.72,0]],"id":41360966}],"con":true,"img":false}]}
{"op":"mcm","clk":"5346750344","pt":1646095966258,"mc":[{"id":"1.195395450","rc":[{"atl":[[8.6,13.16],[8.4,6.76]],"id":41360966}],"con":true,"img":false}]}
{"op":"mcm","clk":"5346750401","pt":1646095968158,"mc":[{"id":"1.195395450","rc":[{"atl":[[8,4.57]],"id":41360966}],"con":true,"img":false}]}
{"op":"mcm","clk":"5346750405","pt":1646095968259,"mc":[{"id":"1.195395450","rc":[{"atl":[[8.4,12.09]],"id":41360966}],"con":true,"img":false}]}
{"op":"mcm","clk":"5346750409","pt":1646095968362,"mc":[{"id":"1.195395450","rc":[{"atb":[[2.6,0]],"id":40995914},{"atb":[[3.05,15.04]],"id":41360966}],"con":true,"img":false}]}
{"op":"mcm","clk":"5346750455","pt":1646095970051,"mc":[{"id":"1.195395450","rc":[{"atb":[[3.05,24.39]],"id":37495442}],"con":true,"img":false}]}
{"op":"mcm","clk":"5346750503","pt":1646095972050,"mc":[{"id":"1.195395450","rc":[{"atb":[[1.75,166.67]],"id":40494151},{"atl":[[8,13.9]],"id":40494151},{"atb":[[1.85,147.06]],"id":41962160},{"atl":[[3.75,45.45]],"id":41962160}],"con":true,"img":false}]}
{"op":"mcm","clk":"5346750508","pt":1646095972255,"mc":[{"id":"1.195395450","rc":[{"atb":[[2.64,18.8]],"id":40995914}],"con":true,"img":false}]}
{"op":"mcm","clk":"5346750555","pt":1646095974101,"mc":[{"id":"1.195395450","rc":[{"atb":[[1.26,76.92]],"id":40908100},{"atl":[[1.84,0],[1.74,50.67]],"id":43066393}],"con":true,"img":false}]}
{"op":"mcm","clk":"5346750560","pt":1646095974156,"mc":[{"id":"1.195395450","rc":[{"atb":[[1.29,143.88]],"id":40908100}],"con":true,"img":false}]}
{"op":"mcm","clk":"5346750601","pt":1646095975788,"mc":[{"id":"1.195395450","rc":[{"atb":[[3.15,22.48]],"id":37495442}],"con":true,"img":false}]}
{"op":"mcm","clk":"5346750609","pt":1646095976095,"mc":[{"id":"1.195395450","rc":[{"atb":[[2.36,0]],"id":37495442},{"atb":[[2.22,0]],"id":41360966}],"con":true,"img":false}]}
{"op":"mcm","clk":"5346750612","pt":1646095976197,"mc":[{"id":"1.195395450","rc":[{"atb":[[2.46,34.07]],"id":37495442},{"atb":[[2.32,34.61]],"id":41360966}],"con":true,"img":false}]}
{"op":"mcm","clk":"5346750638","pt":1646095977271,"mc":[{"id":"1.195395450","rc":[{"atb":[[2.62,0]],"id":40995914}],"con":true,"img":false}]}
{"op":"mcm","clk":"5346750642","pt":1646095977476,"mc":[{"id":"1.195395450","rc":[{"atl":[[8.6,0],[8.2,1.66],[7.8,0]],"id":40494151},{"atb":[[1.9,133.41]],"id":41962160}],"con":true,"img":false}]}
{"op":"mcm","clk":"5346750650","pt":1646095977885,"mc":[{"id":"1.195395450","rc":[{"atb":[[1.28,0]],"id":40908100}],"con":true,"img":false}]}
{"op":"mcm","clk":"5346750658","pt":1646095978090,"mc":[{"id":"1.195395450","rc":[{"atb":[[3.1,3.54]],"id":37495442},{"atl":[[8.4,0],[9.4,4.86]],"id":40494151},{"atb":[[1.29,0]],"id":40908100}],"con":true,"img":false}]}
{"op":"mcm","clk":"5346750660","pt":1646095978193,"mc":[{"id":"1.195395450","rc":[{"atb":[[3,22.28]],"id":37495442},{"atb":[[1.26,220.8]],"id":40908100}],"con":true,"img":false}]}
{"op":"mcm","clk":"5346750667","pt":1646095978501,"mc":[{"id":"1.195395450","rc":[{"atb":[[3.1,0]],"id":37495442}],"con":true,"img":false}]}
{"op":"mcm","clk":"5346750696","pt":1646095979682,"mc":[{"id":"1.195395450","rc":[{"atb":[[2.64,0]],"id":40995914}],"con":true,"img":false}]}
{"op":"mcm","clk":"5346750714","pt":1646095980300,"mc":[{"id":"1.195395450","rc":[{"atb":[[2.8,10],[2.54,33.98],[2.58,15.2],[2.88,5],[2.96,2.5]],"id":40995914},{"atl":[[6.4,45.71],[5.7,10.49]],"id":40995914},{"atb":[[3.2,19.48],[3.35,2.5],[3,61.25],[3.15,27.48],[2.98,47.88]],"id":37495442},{"atl":[[7.8,3.24]],"id":37495442},{"atb":[[3.35,2.5],[2.98,10],[3.05,33.98],[3.15,5],[2.96,60.17]],"id":41360966},{"atl":[[8.6,39.33],[7.6,2.5],[7.8,11.76],[8.4,17.09]],"id":41360966},{"atb":[[2.98,5],[2.62,55.81],[2.9,10],[3.15,2.5],[2.7,14.2]],"id":40494151},{"atl":[[8,42.03],[6.2,4.23]],"id":40494151},{"atl":[[3.6,79.53],[3.4,25.88]],"id":41962160},{"atb":[[3.35,2.5],[2.98,10],[2.92,20.9],[2.86,48.76],[3.15,5]],"id":25760990},{"atl":[[8.2,10],[7.4,5],[9.4,25.93],[6,7.24],[6.6,2.5]],"id":25760990},{"atb":[[1.27,10],[1.26,399.45],[1.31,232.17],[1.35,2.5]],"id":40908100},{"atl":[[2.8,37.78],[2.72,5],[2.64,2.5],[2.76,119.6],[2.52,52.63]],"id":40908100},{"atb":[[1.02,464.29],[1.04,2.5]],"id":43066393},{"atl":[[1.11,83.12],[1.35,309.6]],"id":43066393}],"con":true,"img":false}]}
{"op":"mcm","clk":"5346750717","pt":1646095980402,"mc":[{"id":"1.195395450","rc":[{"atb":[[3.35,21.98],[3.15,18.18]],"id":37495442},{"atl":[[3.6,51.76],[3.35,19.61]],"id":41962160},{"atb":[[1.01,34031.37]],"id":43066393}],"con":true,"img":false}]}
{"op":"mcm","clk":"5346750720","pt":1646095980505,"mc":[{"id":"1.195395450","rc":[{"atb":[[3.2,43.87],[3.35,2.5]],"id":37495442},{"atl":[[3.35,0],[3.55,53.65]],"id":41962160}],"con":true,"img":false}]}
{"op":"mcm","clk":"5346750722","pt":1646095980606,"mc":[{"id":"1.195395450","rc":[{"atl":[[3.45,48.98]],"id":41962160}],"con":true,"img":false}]}
{"op":"mcm","clk":"5346750725","pt":1646095980708,"mc":[{"id":"1.195395450","rc":[{"atl":[[3.55,19.61]],"id":41962160}],"con":true,"img":false}]}
{"op":"mcm","clk":"5346750753","pt":1646095981583,"mc":[{"id":"1.195395450","rc":[{"atb":[[2.58,10.49]],"id":40995914},{"atb":[[3,4.17]],"id":41360966}],"con":true,"img":false}]}
{"op":"mcm","clk":"5346750759","pt":1646095981685,"mc":[{"id":"1.195395450","rc":[{"atb":[[1.27,124.22]],"id":40908100}],"con":true,"img":false}]}
{"op":"mcm","clk":"5346750766","pt":1646095981890,"mc":[{"id":"1.195395450","rc":[{"atb":[[3,0]],"id":41360966}],"con":true,"img":false}]}
{"op":"mcm","clk":"5346750772","pt":1646095982097,"mc":[{"id":"1.195395450","rc":[{"atl":[[8.4,10.14]],"id":40494151}],"con":true,"img":false}]}
{"op":"mcm","clk":"5346750796","pt":1646095982710,"mc":[{"id":"1.195395450","rc":[{"atb":[[2.6,3.3]],"id":40995914},{"atb":[[1.31,159.23]],"id":40908100}],"con":true,"img":false}]}
{"op":"mcm","clk":"5346750827","pt":1646095983687,"mc":[{"id":"1.195395450","rc":[{"atb":[[2.82,10.01]],"id":40995914},{"atb":[[3.05,18.94]],"id":41360966},{"atb":[[2.68,4.43]],"id":40494151},{"atb":[[2.92,4.84]],"id":25760990}],"con":true,"img":false}]}
{"op":"mcm","clk":"5346750848","pt":1646095984202,"mc":[{"id":"1.195395450","rc":[{"atl":[[8.2,0]],"id":40995914},{"atl":[[10.5,5.26]],"id":37495442},{"atl":[[8,35.27],[9.4,0]],"id":40494151}],"con":true,"img":false}]}
{"op":"mcm","clk":"5346750851","pt":1646095984304,"mc":[{"id":"1.195395450","rc":[{"atl":[[9,4.86]],"id":40995914},{"atl":[[11,4.86]],"id":37495442},{"atl":[[9,6.76],[10,4.86]],"id":40494151}],"con":true,"img":false}]}
{"op":"mcm","clk":"5346750887","pt":1646095985483,"mc":[{"id":"1.195395450","rc":[{"atb":[[1.27,10]],"id":40908100}],"con":true,"img":false}]}
{"op":"mcm","clk":"5346750890","pt":1646095985586,"mc":[{"id":"1.195395450","rc":[{"atl":[[8.4,30.6]],"id":41360966}],"con":true,"img":false}]}
{"op":"mcm","clk":"5346750894","pt":1646095985688,"mc":[{"id":"1.195395450","rc":[{"atl":[[8.6,26.17]],"id":41360966},{"atl":[[3.55,58.83],[3.45,8.16]],"id":41962160}],"con":true,"img":false}]}
{"op":"mcm","clk":"5346750949","pt":1646095987381,"mc":[{"id":"1.195395450","rc":[{"atb":[[2.6,7.95]],"id":40995914},{"atb":[[3.25,3.3]],"id":37495442}],"con":true,"img":false}]}
{"op":"mcm","clk":"5346750953","pt":1646095987483,"mc":[{"id":"1.195395450","rc":[{"atb":[[3.3,18.19],[3.2,19.48]],"id":37495442}],"con":true,"img":false}]}
{"op":"mcm","clk":"5346750959","pt":1646095987687,"mc":[{"id":"1.195395450","rc":[{"atb":[[3.2,7.5]],"id":41360966},{"atb":[[3,7.5]],"id":40494151},{"atb":[[3.2,11.82]],"id":25760990}],"con":true,"img":false}]}
{"op":"mcm","clk":"5346750963","pt":1646095987789,"mc":[{"id":"1.195395450","rc":[{"atb":[[2.6,4.65]],"id":40995914},{"atb":[[1.32,2.75]],"id":40908100}],"con":true,"img":false}]}
{"op":"mcm","clk":"5346750974","pt":1646095988096,"mc":[{"id":"1.195395450","rc":[{"atl":[[11.5,22.33]],"id":40995914},{"atl":[[12,14.08]],"id":37495442},{"atl":[[14.5,16.36]],"id":41360966},{"atl":[[12.5,18.71]],"id":40494151},{"atl":[[6.4,27.74]],"id":41962160},{"atl":[[13,17.76]],"id":25760990},{"atl":[[3.8,60.69]],"id":40908100},{"atl":[[2.44,105.92]],"id":43066393}],"con":true,"img":false}]}
{"op":"mcm","clk":"5346750978","pt":1646095988199,"mc":[{"id":"1.195395450","rc":[{"atl":[[11,0]],"id":37495442},{"atl":[[9,0]],"id":40995914},{"atl":[[9.8,0]],"id":41360966},{"atl":[[10,0]],"id":40494151},{"atl":[[11,0]],"id":25760990},{"atl":[[3.3,0]],"id":40908100},{"atl":[[1.74,0]],"id":43066393}],"con":true,"img":false}]}
{"op":"mcm","clk":"5346751016","pt":1646095989487,"mc":[{"id":"1.195395450","rc":[{"atb":[[1.32,10.26]],"id":40908100}],"con":true,"img":false}]}
{"op":"mcm","clk":"5346751036","pt":1646095990205,"mc":[{"id":"1.195395450","rc":[{"atl":[[9.4,0]],"id":37495442}],"con":true,"img":false}]}
{"op":"mcm","clk":"5346751040","pt":1646095990309,"mc":[{"id":"1.195395450","rc":[{"atl":[[10.5,19.35]],"id":37495442}],"con":true,"img":false}]}
{"op":"mcm","clk":"5346751045","pt":1646095990410,"mc":[{"id":"1.195395450","rc":[{"atb":[[3.25,0]],"id":37495442},{"atb":[[3.05,22.57]],"id":41360966}],"con":true,"img":false}]}
{"op":"mcm","clk":"5346751050","pt":1646095990513,"mc":[{"id":"1.195395450","rc":[{"atb":[[3.2,40.17],[3.3,0]],"id":37495442}],"con":true,"img":false}]}
{"op":"mcm","clk":"5346751094","pt":1646095992111,"mc":[{"id":"1.195395450","rc":[{"atl":[[8.8,16.03]],"id":40494151}],"con":true,"img":false}]}
{"op":"mcm","clk":"5346751115","pt":1646095992931,"mc":[{"id":"1.195395450","rc":[{"atb":[[2.9,2.75]],"id":40995914}],"con":true,"img":false}]}
{"op":"mcm","clk":"5346751141","pt":1646095994009,"mc":[{"id":"1.195395450","rc":[{"atb":[[2.56,0]],"id":40995914},{"atb":[[3.15,14.3]],"id":37495442},{"atb":[[2.66,0]],"id":40494151}],"con":true,"img":false}]}
{"op":"mcm","clk":"5346751144","pt":1646095994112,"mc":[{"id":"1.195395450","rc":[{"atb":[[3.2,19.48],[3.15,56.97]],"id":37495442},{"atb":[[1.31,118.67]],"id":40908100}],"con":true,"img":false}]}
{"op":"mcm","clk":"5346751147","pt":1646095994215,"mc":[{"id":"1.195395450","rc":[{"atb":[[1.32,50.83]],"id":40908100}],"con":true,"img":false}]}
{"op":"mcm","clk":"5346751179","pt":1646095995293,"mc":[{"id":"1.195395450","rc":[{"atb":[[2.82,0]],"id":40995914}],"con":true,"img":false}]}
{"op":"mcm","clk":"5346751206","pt":1646095996118,"mc":[{"id":"1.195395450","rc":[{"atb":[[2.32,48.58]],"id":41360966}],"con":true,"img":false}]}
{"op":"mcm","clk":"5346751258","pt":1646095997814,"mc":[{"id":"1.195395450","rc":[{"atb":[[2.88,16.64],[2.96,8.32]],"id":40995914},{"atl":[[6.4,24.72],[6.2,20.27]],"id":40995914},{"atb":[[3,22.28],[3.4,17.24],[3.15,91.45]],"id":37495442},{"atb":[[3.35,9.68],[3.15,19.36],[2.96,22.28]],"id":41360966},{"atl":[[8,18.93],[7.4,7.18]],"id":41360966},{"atb":[[2.98,18.86],[2.62,27.41],[3.2,6.93]],"id":40494151},{"atl":[[3.6,0],[3.55,113.05]],"id":41962160},{"atb":[[3.35,8.12],[2.86,26.88],[3.15,20]],"id":25760990},{"atl":[[7.4,20],[9.4,4.05]],"id":25760990},{"atb":[[1.26,220.8],[1.31,206.61],[1.35,46.47]],"id":40908100},{"atl":[[2.64,90.44],[2.76,38.05]],"id":40908100}],"con":true,"img":false}]}
{"op":"mcm","clk":"5346751263","pt":1646095997917,"mc":[{"id":"1.195395450","rc":[{"atb":[[2.54,12.99]],"id":40995914},{"atb":[[3.45,17.24],[3.15,48.78]],"id":37495442},{"atl":[[8.6,0]],"id":41360966}],"con":true,"img":false}]}
{"op":"mcm","clk":"5346751266","pt":1646095998019,"mc":[{"id":"1.195395450","rc":[{"atb":[[3.2,0]],"id":37495442},{"atb":[[2.58,0]],"id":40995914},{"atb":[[3.05,3.63]],"id":41360966},{"atl":[[7.8,0]],"id":41360966},{"atb":[[2.7,0]],"id":40494151},{"atb":[[1.31,92.94]],"id":40908100}],"con":true,"img":false}]}
{"op":"mcm","clk":"5346751271","pt":1646095998124,"mc":[{"id":"1.195395450","rc":[{"atb":[[2.92,0]],"id":25760990}],"con":true,"img":false}]}
{"op":"mcm","clk":"5346751277","pt":1646095998226,"mc":[{"id":"1.195395450","rc":[{"atb":[[2.52,0]],"id":40995914},{"atb":[[2.84,0]],"id":25760990},{"atl":[[9.4,0]],"id":25760990},{"atb":[[1.26,161.12]],"id":40908100},{"atb":[[1.01,31476.42]],"id":43066393}],"con":true,"img":false}]}
{"op":"mcm","clk":"5346751280","pt":1646095998328,"mc":[{"id":"1.195395450","rc":[{"atb":[[2.56,29.39]],"id":40995914},{"atb":[[2.88,24.73]],"id":25760990},{"atl":[[8.8,4.05]],"id":25760990}],"con":true,"img":false}]}
{"op":"mcm","clk":"5346751302","pt":1646095998998,"mc":[{"id":"1.195395450","rc":[{"atb":[[2.98,5]],"id":40995914}],"con":true,"img":false}]}
{"op":"mcm","clk":"5346751312","pt":1646095999412,"mc":[{"id":"1.195395450","rc":[{"atb":[[2.6,0]],"id":40995914},{"atb":[[3.05,0]],"id":41360966}],"con":true,"img":false}]}
{"op":"mcm","clk":"5346751334","pt":1646096000230,"mc":[{"id":"1.195395450","rc":[{"atb":[[3,0]],"id":37495442},{"atl":[[2.74,6.9]],"id":40908100}],"con":true,"img":false}]}
{"op":"mcm","clk":"5346751338","pt":1646096000332,"mc":[{"id":"1.195395450","rc":[{"atb":[[3.1,22.28]],"id":37495442},{"atl":[[2.5,26.68]],"id":40908100}],"con":true,"img":false}]}
{"op":"mcm","clk":"5346751342","pt":1646096000435,"mc":[{"id":"1.195395450","rc":[{"atl":[[2.48,54.05]],"id":40908100}],"con":true,"img":false}]}
{"op":"mcm","clk":"5346751348","pt":1646096000639,"mc":[{"id":"1.195395450","rc":[{"atl":[[2.52,0]],"id":40908100}],"con":true,"img":false}]}
{"op":"mcm","clk":"5346751357","pt":1646096000948,"mc":[{"id":"1.195395450","rc":[{"atb":[[3,0]],"id":40494151}],"con":true,"img":false}]}
{"op":"mcm","clk":"5346751413","pt":1646096002404,"mc":[{"id":"1.195395450","rc":[{"atb":[[3.2,3.38]],"id":37495442}],"con":true,"img":false}]}
{"op":"mcm","clk":"5346751419","pt":1646096002711,"mc":[{"id":"1.195395450","rc":[{"atb":[[2.9,0]],"id":40995914}],"con":true,"img":false}]}
{"op":"mcm","clk":"5346751428","pt":1646096003021,"mc":[{"id":"1.195395450","rc":[{"atb":[[3.35,36.98]],"id":37495442}],"con":true,"img":false}]}
{"op":"mcm","clk":"5346751431","pt":1646096003121,"mc":[{"id":"1.195395450","rc":[{"atb":[[3.45,0]],"id":37495442}],"con":true,"img":false}]}
{"op":"mcm","clk":"5346751459","pt":1646096004255,"mc":[{"id":"1.195395450","rc":[{"atl":[[9,0]],"id":40494151}],"con":true,"img":false}]}
{"op":"mcm","clk":"5346751464","pt":1646096004306,"mc":[{"id":"1.195395450","rc":[{"atl":[[7.8,6.76]],"id":40494151}],"con":true,"img":false}]}
{"op":"mcm","clk":"5346751467","pt":1646096004464,"mc":[{"id":"1.195395450","rc":[{"atl":[[8,7.14],[7.8,23.26]],"id":40494151}],"con":true,"img":false}]}
{"op":"mcm","clk":"5346751480","pt":1646096004820,"mc":[{"id":"1.195395450","rc":[{"atb":[[3.25,13.7]],"id":40494151}],"con":true,"img":false}]}
{"op":"mcm","clk":"5346751497","pt":1646096005436,"mc":[{"id":"1.195395450","rc":[{"atb":[[3.2,0]],"id":37495442},{"atb":[[2.62,4.59]],"id":40995914},{"atb":[[3,3.72]],"id":41360966}],"con":true,"img":false}]}
{"op":"mcm","clk":"5346751526","pt":1646096006256,"mc":[{"id":"1.195395450","rc":[{"atb":[[2.56,0]],"id":40995914},{"atl":[[7.8,16.5]],"id":40494151}],"con":true,"img":false}]}
{"op":"mcm","clk":"5346751532","pt":1646096006308,"mc":[{"id":"1.195395450","rc":[{"atb":[[2.52,29.39]],"id":40995914},{"atl":[[9,6.76]],"id":40494151}],"con":true,"img":false}]}
{"op":"mcm","clk":"5346751552","pt":1646096006723,"mc":[{"id":"1.195395450","rc":[{"atb":[[2.98,0]],"id":40995914}],"con":true,"img":false}]}
{"op":"mcm","clk":"5346751555","pt":1646096006825,"mc":[{"id":"1.195395450","rc":[{"atb":[[2.8,40.74],[2.88,5]],"id":40995914}],"con":true,"img":false}]}
{"op":"mcm","clk":"5346751593","pt":1646096007954,"mc":[{"id":"1.195395450","rc":[{"atb":[[3,3.5]],"id":40995914}],"con":true,"img":false}]}
{"op":"mcm","clk":"5346751601","pt":1646096008155,"mc":[{"id":"1.195395450","rc":[{"atb":[[3.35,2.5],[3.15,95.29]],"id":37495442},{"atl":[[2.5,0]],"id":40908100}],"con":true,"img":false}]}
{"op":"mcm","clk":"5346751605","pt":1646096008257,"mc":[{"id":"1.195395450","rc":[{"atl":[[2.62,26.68]],"id":40908100}],"con":true,"img":false}]}
{"op":"mcm","clk":"5346751609","pt":1646096008359,"mc":[{"id":"1.195395450","rc":[{"atl":[[2.48,0]],"id":40908100}],"con":true,"img":false}]}
{"op":"mcm","clk":"5346751612","pt":1646096008463,"mc":[{"id":"1.195395450","rc":[{"atb":[[2.62,0]],"id":40995914},{"atl":[[2.52,52.63]],"id":40908100}],"con":true,"img":false}]}
{"op":"mcm","clk":"5346751675","pt":1646096010525,"mc":[{"id":"1.195395450","rc":[{"atb":[[2.9,12.25]],"id":40995914}],"con":true,"img":false}]}
{"op":"mcm","clk":"5346751718","pt":1646096012062,"mc":[{"id":"1.195395450","rc":[{"atb":[[3,7.9]],"id":41360966}],"con":true,"img":false}]}
{"op":"mcm","clk":"5346751721","pt":1646096012164,"mc":[{"id":"1.195395450","rc":[{"atb":[[2.66,5.02]],"id":40494151}],"con":true,"img":false}]}
{"op":"mcm","clk":"5346751786","pt":1646096014266,"mc":[{"id":"1.195395450","rc":[{"atl":[[8.4,25.27]],"id":41360966}],"con":true,"img":false}]}
{"op":"mcm","clk":"5346751789","pt":1646096014380,"mc":[{"id":"1.195395450","rc":[{"atl":[[7.8,5.33]],"id":41360966}],"con":true,"img":false}]}
{"op":"mcm","clk":"5346751792","pt":1646096014472,"mc":[{"id":"1.195395450","rc":[{"atb":[[2.86,4]],"id":40995914},{"atb":[[3.2,3.38]],"id":37495442}],"con":true,"img":false}]}
{"op":"mcm","clk":"5346751806","pt":1646096014934,"mc":[{"id":"1.195395450","rc":[{"atb":[[3,0]],"id":40995914}],"con":true,"img":false}]}
{"op":"mcm","clk":"5346751811","pt":1646096015038,"mc":[{"id":"1.195395450","rc":[{"atb":[[2.8,10],[3,14.11],[2.9,40.47]],"id":40995914},{"atb":[[3.2,13.91],[3.15,60.81]],"id":37495442},{"atl":[[8,4.57],[7.8,27.37]],"id":41360966},{"atb":[[3.25,22.08],[3.15,19.26]],"id":40494151},{"atl":[[2.64,2.5],[2.62,122.07]],"id":40908100}],"con":true,"img":false}]}
{"op":"mcm","clk":"5346751814","pt":1646096015138,"mc":[{"id":"1.195395450","rc":[{"atb":[[2.98,5]],"id":40494151}],"con":true,"img":false}]}
{"op":"mcm","clk":"5346751817","pt":1646096015244,"mc":[{"id":"1.195395450","rc":[{"atb":[[3,0],[2.96,2.5]],"id":40995914},{"atb":[[3.2,0]],"id":40494151}],"con":true,"img":false}]}
{"op":"mcm","clk":"5346751825","pt":1646096015448,"mc":[{"id":"1.195395450","rc":[{"atb":[[2.9,50.21]],"id":40995914}],"con":true,"img":false}]}
{"op":"mcm","clk":"5346751842","pt":1646096016164,"mc":[{"id":"1.195395450","rc":[{"atb":[[3.25,22.29],[2.46,0],[3.15,14.3]],"id":37495442},{"atb":[[2.62,0],[2.2,0]],"id":40494151},{"atl":[[7.2,6.54],[8.8,0]],"id":25760990}],"con":true,"img":false}]}
{"op":"mcm","clk":"5346751844","pt":1646096016268,"mc":[{"id":"1.195395450","rc":[{"atb":[[2.72,34.07]],"id":37495442},{"atb":[[2.72,27.41],[2.42,32.99]],"id":40494151},{"atl":[[7.2,31.74]],"id":25760990}],"con":true,"img":false}]}
{"op":"mcm","clk":"5346751849","pt":1646096016370,"mc":[{"id":"1.195395450","rc":[{"atl":[[7.4,5]],"id":25760990}],"con":true,"img":false}]}
{"op":"mcm","clk":"5346751889","pt":1646096018064,"mc":[{"id":"1.195395450","rc":[{"atb":[[3.2,10.53]],"id":37495442},{"atb":[[2.86,0]],"id":40995914},{"atb":[[2.68,0]],"id":40494151}],"con":true,"img":false}]}
{"op":"mcm","clk":"5346751892","pt":1646096018164,"mc":[{"id":"1.195395450","rc":[{"atb":[[3.25,8.38]],"id":40494151}],"con":true,"img":false}]}
{"op":"mcm","clk":"5346751899","pt":1646096018372,"mc":[{"id":"1.195395450","rc":[{"atb":[[3.25,0]],"id":40494151}],"con":true,"img":false}]}
{"op":"mcm","clk":"5346751906","pt":1646096018472,"mc":[{"id":"1.195395450","rc":[{"atb":[[3.2,10.04]],"id":40494151}],"con":true,"img":false}]}
{"op":"mcm","clk":"5346751911","pt":1646096018676,"mc":[{"id":"1.195395450","rc":[{"atl":[[10,2.22],[9.8,1.36]],"id":37495442},{"atl":[[8.4,11.76],[8.6,13.16]],"id":41360966},{"atl":[[7.8,19.44],[7.6,0]],"id":40494151},{"atb":[[1.84,23.81],[1.91,0]],"id":41962160},{"atl":[[1.33,60.61],[1.32,0]],"id":43066393}],"con":true,"img":false}]}
{"op":"mcm","clk":"5346751916","pt":1646096018779,"mc":[{"id":"1.195395450","rc":[{"atl":[[8,32.91]],"id":40494151},{"atb":[[1.04,111.72]],"id":43066393}],"con":true,"img":false}]}
{"op":"mcm","clk":"5346751919","pt":1646096018881,"mc":[{"id":"1.195395450","rc":[{"atl":[[10.5,8.94]],"id":37495442}],"con":true,"img":false}]}
{"op":"mcm","clk":"5346751923","pt":1646096018932,"mc":[{"id":"1.195395450","rc":[{"atl":[[7.8,2.94]],"id":40494151},{"atb":[[1.02,250]],"id":43066393}],"con":true,"img":false}]}
{"op":"mcm","clk":"5346751948","pt":1646096019956,"mc":[{"id":"1.195395450","rc":[{"atl":[[10,0],[10.5,5.79],[7.8,1.76]],"id":37495442},{"atl":[[7.6,3.03]],"id":40494151},{"atb":[[1.89,0],[1.85,23.53]],"id":41962160},{"atl":[[1.33,0],[1.34,58.82]],"id":43066393}],"con":true,"img":false}]}
{"op":"mcm","clk":"5346751951","pt":1646096020061,"mc":[{"id":"1.195395450","rc":[{"atl":[[10.5,18.24]],"id":37495442},{"atl":[[7.8,0]],"id":40494151}],"con":true,"img":false}]}
{"op":"mcm","clk":"5346751966","pt":1646096020573,"mc":[{"id":"1.195395450","rc":[{"atb":[[2.92,2.5]],"id":40995914}],"con":true,"img":false}]}
{"op":"mcm","clk":"5346752012","pt":1646096021957,"mc":[{"id":"1.195395450","rc":[{"atb":[[3.25,13.7]],"id":40494151}],"con":true,"img":false}]}
{"op":"mcm","clk":"5346752037","pt":1646096022978,"mc":[{"id":"1.195395450","rc":[{"atb":[[1.87,0]],"id":41962160}],"con":true,"img":false}]}
{"op":"mcm","clk":"5346752053","pt":1646096023441,"mc":[{"id":"1.195395450","rc":[{"atb":[[2.96,6.29]],"id":40995914},{"atb":[[3.3,3.24]],"id":37495442}],"con":true,"img":false}]}
{"op":"mcm","clk":"5346752065","pt":1646096023863,"mc":[{"id":"1.195395450","rc":[{"atb":[[2.9,37.96]],"id":40995914}],"con":true,"img":false}]}
{"op":"mcm","clk":"5346752072","pt":1646096024161,"mc":[{"id":"1.195395450","rc":[{"atb":[[3.35,36.98]],"id":37495442},{"atl":[[2.62,95.39]],"id":40908100}],"con":true,"img":false}]}
{"op":"mcm","clk":"5346752076","pt":1646096024260,"mc":[{"id":"1.195395450","rc":[{"atb":[[3.25,0]],"id":37495442},{"atl":[[2.5,26.68]],"id":40908100}],"con":true,"img":false}]}
{"op":"mcm","clk":"5346752080","pt":1646096024371,"mc":[{"id":"1.195395450","rc":[{"atl":[[2.48,54.05]],"id":40908100}],"con":true,"img":false}]}
{"op":"mcm","clk":"5346752087","pt":1646096024566,"mc":[{"id":"1.195395450","rc":[{"atl":[[2.52,0]],"id":40908100}],"con":true,"img":false}]}
{"op":"mcm","clk":"5346752140","pt":1646096026462,"mc":[{"id":"1.195395450","rc":[{"atb":[[3.3,0]],"id":37495442},{"atb":[[2.78,4.18]],"id":40494151}],"con":true,"img":false}]}
{"op":"mcm","clk":"5346752167","pt":1646096027690,"mc":[{"id":"1.195395450","rc":[{"atb":[[2.98,12.6]],"id":40995914}],"con":true,"img":false}]}
{"op":"mcm","clk":"5346752172","pt":1646096027791,"mc":[{"id":"1.195395450","rc":[{"atb":[[2.92,27.68]],"id":40995914}],"con":true,"img":false}]}
{"op":"mcm","clk":"5346752178","pt":1646096027901,"mc":[{"id":"1.195395450","rc":[{"atb":[[2.9,9.74]],"id":40995914}],"con":true,"img":false}]}
{"op":"mcm","clk":"5346752185","pt":1646096028199,"mc":[{"id":"1.195395450","rc":[{"atb":[[2.96,0]],"id":41360966}],"con":true,"img":false}]}
{"op":"mcm","clk":"5346752188","pt":1646096028253,"mc":[{"id":"1.195395450","rc":[{"atb":[[3,30.19]],"id":41360966}],"con":true,"img":false}]}
{"op":"mcm","clk":"5346752222","pt":1646096029393,"mc":[{"id":"1.195395450","rc":[{"atb":[[3.2,55.98]],"id":37495442}],"con":true,"img":false}]}
{"op":"mcm","clk":"5346752224","pt":1646096029499,"mc":[{"id":"1.195395450","rc":[{"atb":[[3.35,2.5]],"id":37495442}],"con":true,"img":false}]}
{"op":"mcm","clk":"5346752233","pt":1646096029795,"mc":[{"id":"1.195395450","rc":[{"atb":[[2.96,2.5]],"id":40995914},{"atb":[[3,26.46]],"id":41360966}],"con":true,"img":false}]}
{"op":"mcm","clk":"5346752238","pt":1646096030001,"mc":[{"id":"1.195395450","rc":[{"atl":[[11.5,4.76]],"id":37495442},{"atb":[[1.83,60.24]],"id":41962160},{"atl":[[1.36,138.89]],"id":43066393}],"con":true,"img":false}]}
{"op":"mcm","clk":"5346752244","pt":1646096030260,"mc":[{"id":"1.195395450","rc":[{"atb":[[2.92,25.18]],"id":40995914}],"con":true,"img":false}]}
{"op":"mcm","clk":"5346752285","pt":1646096031903,"mc":[{"id":"1.195395450","rc":[{"atb":[[2.98,29.93]],"id":40995914},{"atb":[[3.25,31.51]],"id":40494151},{"atl":[[2.54,110.93],[2.62,0]],"id":40908100}],"con":true,"img":false}]}
{"op":"mcm","clk":"5346752289","pt":1646096032106,"mc":[{"id":"1.195395450","rc":[{"atb":[[2.9,0]],"id":40995914},{"atl":[[7.8,22.04]],"id":41360966},{"atb":[[3.2,0]],"id":40494151},{"atl":[[2.5,0]],"id":40908100}],"con":true,"img":false}]}
{"op":"mcm","clk":"5346752293","pt":1646096032158,"mc":[{"id":"1.195395450","rc":[{"atl":[[7.6,7.83]],"id":41360966},{"atl":[[2.52,26.68]],"id":40908100}],"con":true,"img":false}]}
{"op":"mcm","clk":"5346752296","pt":1646096032269,"mc":[{"id":"1.195395450","rc":[{"atb":[[2.98,41.39]],"id":40494151},{"atl":[[2.48,0]],"id":40908100}],"con":true,"img":false}]}
{"op":"mcm","clk":"5346752298","pt":1646096032363,"mc":[{"id":"1.195395450","rc":[{"atb":[[3.15,2.5]],"id":40494151},{"atl":[[2.52,79.31]],"id":40908100}],"con":true,"img":false}]}
{"op":"mcm","clk":"5346752305","pt":1646096032668,"mc":[{"id":"1.195395450","rc":[{"atb":[[2.78,0]],"id":40494151}],"con":true,"img":false}]}
{"op":"mcm","clk":"5346752336","pt":1646096034206,"mc":[{"id":"1.195395450","rc":[{"atb":[[3,4.17]],"id":41360966},{"atl":[[7.2,25.2]],"id":25760990}],"con":true,"img":false}]}
{"op":"mcm","clk":"5346752340","pt":1646096034311,"mc":[{"id":"1.195395450","rc":[{"atb":[[2.96,22.28]],"id":41360966},{"atl":[[7,6.54]],"id":25760990}],"con":true,"img":false}]}
{"op":"mcm","clk":"5346752344","pt":1646096034377,"mc":[{"id":"1.195395450","rc":[{"atl":[[7,31.74]],"id":25760990},{"atl":[[1.37,0],[1.39,0],[1.35,166.74]],"id":43066393}],"con":true,"img":false}]}
{"op":"mcm","clk":"5346752347","pt":1646096034476,"mc":[{"id":"1.195395450","rc":[{"atl":[[7.2,0]],"id":25760990}],"con":true,"img":false}]}
{"op":"mcm","clk":"5346752366","pt":1646096035093,"mc":[{"id":"1.195395450","rc":[{"atb":[[2.54,0],[2.5,13.33]],"id":40995914},{"atl":[[6.4,2.5],[5.8,23.33],[4.6,5.56]],"id":40995914},{"atb":[[2.8,0],[3,23.53]],"id":41360966},{"atl":[[8,16],[8.6,0],[6.2,3.85]],"id":41360966},{"atb":[[1.71,0],[1.8,97.4],[1.81,0],[1.9,22.22]],"id":40494151},{"atl":[[16.5,7.74],[20,2.52]],"id":25760990}],"con":true,"img":false}]}
{"op":"mcm","clk":"5346752370","pt":1646096035196,"mc":[{"id":"1.195395450","rc":[{"atl":[[5.8,68.9],[5.6,9.74]],"id":40995914},{"atl":[[7.2,11.51],[7.6,30.85]],"id":41360966},{"atb":[[3.25,17.81]],"id":40494151}],"con":true,"img":false}]}
{"op":"mcm","clk":"5346752374","pt":1646096035300,"mc":[{"id":"1.195395450","rc":[{"atl":[[6.2,8.63]],"id":40995914},{"atl":[[7.8,0]],"id":41360966}],"con":true,"img":false}]}
{"op":"mcm","clk":"5346752379","pt":1646096035389,"mc":[{"id":"1.195395450","rc":[{"atl":[[5.7,0]],"id":40995914},{"atl":[[7.4,0]],"id":41360966},{"atb":[[3.25,0]],"id":40494151}],"con":true,"img":false}]}
{"op":"mcm","clk":"5346752381","pt":1646096035506,"mc":[{"id":"1.195395450","rc":[{"atb":[[3.2,16.54]],"id":40494151}],"con":true,"img":false}]}
{"op":"mcm","clk":"5346752405","pt":1646096036213,"mc":[{"id":"1.195395450","rc":[{"atl":[[10.5,14.56],[12,0]],"id":37495442}],"con":true,"img":false}]}
{"op":"mcm","clk":"5346752408","pt":1646096036315,"mc":[{"id":"1.195395450","rc":[{"atl":[[10,3.68],[14,14.08]],"id":37495442}],"con":true,"img":false}]}
{"op":"mcm","clk":"5346752415","pt":1646096036575,"mc":[{"id":"1.195395450","rc":[{"atl":[[10.5,2.11]],"id":37495442}],"con":true,"img":false}]}
{"op":"mcm","clk":"5346752479","pt":1646096038592,"mc":[{"id":"1.195395450","rc":[{"atb":[[3.25,3.3]],"id":37495442}],"con":true,"img":false}]}
{"op":"mcm","clk":"5346752484","pt":1646096038693,"mc":[{"id":"1.195395450","rc":[{"atb":[[3.25,12.02],[3.3,19.74],[3.2,45.45]],"id":37495442}],"con":true,"img":false}]}
{"op":"mcm","clk":"5346752488","pt":1646096038794,"mc":[{"id":"1.195395450","rc":[{"atb":[[3.2,0]],"id":37495442}],"con":true,"img":false}]}
{"op":"mcm","clk":"5346752497","pt":1646096039106,"mc":[{"id":"1.195395450","rc":[{"atb":[[3.25,13.7]],"id":40494151}],"con":true,"img":false}]}
{"op":"mcm","clk":"5346752517","pt":1646096039708,"mc":[{"id":"1.195395450","rc":[{"atl":[[2.54,7.79],[2.64,103.85]],"id":40908100}],"con":true,"img":false}]}
{"op":"mcm","clk":"5346752526","pt":1646096040019,"mc":[{"id":"1.195395450","rc":[{"atl":[[12.5,6.52]],"id":37495442},{"atb":[[1.81,92.59]],"id":41962160},{"atl":[[1.38,197.37]],"id":43066393}],"con":true,"img":false}]}
{"op":"mcm","clk":"5346752533","pt":1646096040221,"mc":[{"id":"1.195395450","rc":[{"atb":[[2.52,0]],"id":40995914},{"atl":[[9,0]],"id":40494151}],"con":true,"img":false}]}
{"op":"mcm","clk":"5346752536","pt":1646096040324,"mc":[{"id":"1.195395450","rc":[{"atb":[[2.48,29.39]],"id":40995914},{"atl":[[7.8,6.76]],"id":40494151}],"con":true,"img":false}]}
{"op":"mcm","clk":"5346752544","pt":1646096040480,"mc":[{"id":"1.195395450","rc":[{"atl":[[8,7.14],[7.8,23.26]],"id":40494151}],"con":true,"img":false}]}
{"op":"mcm","clk":"5346752587","pt":1646096041610,"mc":[{"id":"1.195395450","rc":[{"atb":[[3.25,8.72]],"id":37495442},{"atb":[[3,27.26]],"id":41360966},{"atb":[[3.05,3.63]],"id":40494151}],"con":true,"img":false}]}
{"op":"mcm","clk":"5346752600","pt":1646096042119,"mc":[{"id":"1.195395450","rc":[{"atl":[[7.8,16.5]],"id":40494151}],"con":true,"img":false}]}
{"op":"mcm","clk":"5346752603","pt":1646096042222,"mc":[{"id":"1.195395450","rc":[{"atl":[[9,6.76]],"id":40494151}],"con":true,"img":false}]}
{"op":"mcm","clk":"5346752626","pt":1646096042893,"mc":[{"id":"1.195395450","rc":[{"atb":[[3.1,22.29]],"id":41360966}],"con":true,"img":false}]}
{"op":"mcm","clk":"5346752629","pt":1646096043019,"mc":[{"id":"1.195395450","rc":[{"atb":[[3,7.9]],"id":41360966}],"con":true,"img":false}]}
{"op":"mcm","clk":"5346752663","pt":1646096044207,"mc":[{"id":"1.195395450","rc":[{"atl":[[6.2,0]],"id":40995914}],"con":true,"img":false}]}
{"op":"mcm","clk":"5346752666","pt":1646096044312,"mc":[{"id":"1.195395450","rc":[{"atl":[[7,8.63]],"id":40995914}],"con":true,"img":false}]}
{"op":"mcm","clk":"5346752685","pt":1646096045129,"mc":[{"id":"1.195395450","rc":[{"atb":[[2.46,34.25]],"id":40995914},{"atl":[[4.8,13.16]],"id":40995914},{"atl":[[6.6,8.93]],"id":41360966},{"atb":[[1.88,56.82]],"id":40494151},{"atl":[[17.5,3.03]],"id":25760990}],"con":true,"img":false}]}
{"op":"mcm","clk":"5346752687","pt":1646096045232,"mc":[{"id":"1.195395450","rc":[{"atl":[[5.6,20.86]],"id":40995914}],"con":true,"img":false}]}
{"op":"mcm","clk":"5346752691","pt":1646096045286,"mc":[{"id":"1.195395450","rc":[{"atl":[[5.8,48.07]],"id":40995914},{"atb":[[1.79,0],[1.77,0],[1.75,0]],"id":40494151},{"atl":[[22,0],[24,0],[26,0]],"id":25760990}],"con":true,"img":false}]}
{"op":"mcm","clk":"5346752695","pt":1646096045390,"mc":[{"id":"1.195395450","rc":[{"atl":[[7.6,1.81]],"id":40995914},{"atl":[[9.2,0],[8.4,5],[8.8,0]],"id":41360966}],"con":true,"img":false}]}
{"op":"mcm","clk":"5346752720","pt":1646096046312,"mc":[{"id":"1.195395450","rc":[{"atb":[[3.35,0],[2.98,37.88],[3.4,19.74],[3.15,9.3]],"id":37495442},{"atb":[[3.35,7.18],[2.98,0],[3.2,12.5],[3.4,2.5],[3.15,14.36]],"id":41360966},{"atb":[[2.98,36.39],[3.2,19.04],[2.9,0],[3.15,0]],"id":40494151},{"atb":[[1.27,0],[1.37,2.5],[1.33,5],[1.31,87.94],[1.35,43.97]],"id":40908100}],"con":true,"img":false}]}
{"op":"mcm","clk":"5346752726","pt":1646096046417,"mc":[{"id":"1.195395450","rc":[{"atb":[[3.3,0]],"id":37495442},{"atb":[[3.15,0]],"id":41360966},{"atb":[[1.37,41.33],[1.33,82.66]],"id":40908100},{"atl":[[2.8,27.78],[2.72,0],[2.5,2.5],[2.64,101.35],[2.58,5],[2.66,10]],"id":40908100}],"con":true,"img":false}]}
{"op":"mcm","clk":"5346752734","pt":1646096046526,"mc":[{"id":"1.195395450","rc":[{"atb":[[3.25,48.2],[3.15,27.92]],"id":37495442},{"atb":[[3.2,36.66],[3.4,14.58]],"id":41360966},{"atb":[[1.31,0],[1.35,0]],"id":40908100},{"atl":[[2.5,12.1]],"id":40908100}],"con":true,"img":false}]}
{"op":"mcm","clk":"5346752740","pt":1646096046625,"mc":[{"id":"1.195395450","rc":[{"atb":[[3.25,39.48],[3.15,56.38]],"id":37495442},{"atb":[[3.35,0]],"id":41360966},{"atl":[[2.52,26.68]],"id":40908100}],"con":true,"img":false}]}
{"op":"mcm","clk":"5346752748","pt":1646096046730,"mc":[{"id":"1.195395450","rc":[{"atb":[[3.25,0]],"id":37495442}],"con":true,"img":false}]}
{"op":"mcm","clk":"5346752783","pt":1646096047621,"mc":[{"id":"1.195395450","rc":[{"atb":[[3,4.17]],"id":41360966}],"con":true,"img":false}]}
{"op":"mcm","clk":"5346752791","pt":1646096047827,"mc":[{"id":"1.195395450","rc":[{"atb":[[2.66,0]],"id":40494151}],"con":true,"img":false}]}
{"op":"mcm","clk":"5346752808","pt":1646096048391,"mc":[{"id":"1.195395450","rc":[{"atb":[[3.25,27.16]],"id":40494151},{"atl":[[2.54,109.82]],"id":40908100}],"con":true,"img":false}]}
{"op":"mcm","clk":"5346752812","pt":1646096048494,"mc":[{"id":"1.195395450","rc":[{"atl":[[2.64,0]],"id":40908100}],"con":true,"img":false}]}
{"op":"mcm","clk":"5346752817","pt":1646096048599,"mc":[{"id":"1.195395450","rc":[{"atb":[[2.98,17.33]],"id":40995914},{"atb":[[3.2,29.16]],"id":41360966},{"atb":[[3.2,2.5],[3.25,13.46]],"id":40494151},{"atb":[[1.32,43.32]],"id":40908100}],"con":true,"img":false}]}
{"op":"mcm","clk":"5346752821","pt":1646096048803,"mc":[{"id":"1.195395450","rc":[{"atb":[[2.98,0],[3.05,15.45]],"id":40494151}],"con":true,"img":false}]}
{"op":"mcm","clk":"5346752843","pt":1646096049621,"mc":[{"id":"1.195395450","rc":[{"atb":[[1.32,40.56]],"id":40908100}],"con":true,"img":false}]}
{"op":"mcm","clk":"5346752853","pt":1646096050036,"mc":[{"id":"1.195395450","rc":[{"atl":[[13.5,10]],"id":37495442},{"atb":[[1.79,158.23]],"id":41962160},{"atl":[[1.4,250]],"id":43066393}],"con":true,"img":false}]}
{"op":"mcm","clk":"5346752859","pt":1646096050238,"mc":[{"id":"1.195395450","rc":[{"atb":[[1.84,0]],"id":41962160},{"atl":[[2.52,0]],"id":40908100}],"con":true,"img":false}]}
{"op":"mcm","clk":"5346752863","pt":1646096050339,"mc":[{"id":"1.195395450","rc":[{"atl":[[2.62,26.68]],"id":40908100}],"con":true,"img":false}]}
{"op":"mcm","clk":"5346752873","pt":1646096050497,"mc":[{"id":"1.195395450","rc":[{"atb":[[3.05,11.82]],"id":40494151}],"con":true,"img":false}]}
{"op":"mcm","clk":"5346752897","pt":1646096051112,"mc":[{"id":"1.195395450","rc":[{"atb":[[2.9,4]],"id":41962160}],"con":true,"img":false}]}
{"op":"mcm","clk":"5346752915","pt":1646096051625,"mc":[{"id":"1.195395450","rc":[{"atl":[[5.8,2.5],[5.6,66.6],[4.6,27.78]],"id":40995914},{"atl":[[7.2,49.84],[6.2,19.23],[7.6,7.83]],"id":41360966}],"con":true,"img":false}]}
{"op":"mcm","clk":"5346752924","pt":1646096051831,"mc":[{"id":"1.195395450","rc":[{"atl":[[5.6,56.86]],"id":40995914},{"atl":[[7.2,38.33]],"id":41360966}],"con":true,"img":false}]}
{"op":"mcm","clk":"5346752937","pt":1646096052137,"mc":[{"id":"1.195395450","rc":[{"atb":[[1.73,0]],"id":41962160},{"atl":[[7,25.2]],"id":25760990}],"con":true,"img":false}]}
{"op":"mcm","clk":"5346752940","pt":1646096052238,"mc":[{"id":"1.195395450","rc":[{"atb":[[1.84,54.08]],"id":41962160},{"atl":[[6.8,6.54]],"id":25760990}],"con":true,"img":false}]}
{"op":"mcm","clk":"5346752950","pt":1646096052447,"mc":[{"id":"1.195395450","rc":[{"atl":[[6.8,31.74],[7,0]],"id":25760990}],"con":true,"img":false}]}
{"op":"mcm","clk":"5346752956","pt":1646096052603,"mc":[{"id":"1.195395450","rc":[{"atb":[[3.2,14.02]],"id":37495442},{"atb":[[3.25,13.7]],"id":41360966},{"atb":[[3.3,13.4]],"id":40494151},{"atb":[[1.34,90.7]],"id":40908100}],"con":true,"img":false}]}
{"op":"mcm","clk":"5346752958","pt":1646096052707,"mc":[{"id":"1.195395450","rc":[{"atb":[[3.3,26.64]],"id":40494151}],"con":true,"img":false}]}
{"op":"mcm","clk":"5346752962","pt":1646096052912,"mc":[{"id":"1.195395450","rc":[{"atb":[[3.25,0]],"id":40494151}],"con":true,"img":false}]}
{"op":"mcm","clk":"5346752979","pt":1646096053627,"mc":[{"id":"1.195395450","rc":[{"atb":[[2.06,7.02]],"id":41962160}],"con":true,"img":false}]}
{"op":"mcm","clk":"5346752998","pt":1646096054250,"mc":[{"id":"1.195395450","rc":[{"atb":[[2.72,0]],"id":40494151}],"con":true,"img":false}]}
{"op":"mcm","clk":"5346753002","pt":1646096054304,"mc":[{"id":"1.195395450","rc":[{"atb":[[3.15,27.92],[3.25,39.48]],"id":37495442},{"atb":[[2.64,27.41]],"id":40494151},{"atb":[[2.08,0]],"id":41962160}],"con":true,"img":false}]}
{"op":"mcm","clk":"5346753006","pt":1646096054510,"mc":[{"id":"1.195395450","rc":[{"atb":[[3.2,17.41]],"id":37495442}],"con":true,"img":false}]}
{"op":"mcm","clk":"5346753010","pt":1646096054616,"mc":[{"id":"1.195395450","rc":[{"atb":[[3.25,17.01]],"id":41360966},{"atb":[[2.06,0]],"id":41962160}],"con":true,"img":false}]}
{"op":"mcm","clk":"5346753021","pt":1646096054924,"mc":[{"id":"1.195395450","rc":[{"atb":[[2.12,0]],"id":41962160},{"atb":[[1.34,136.17]],"id":40908100}],"con":true,"img":false}]}
{"op":"mcm","clk":"5346753025","pt":1646096055029,"mc":[{"id":"1.195395450","rc":[{"atb":[[3.2,49.06],[3.15,9.3]],"id":37495442}],"con":true,"img":false}]}
{"op":"mcm","clk":"5346753028","pt":1646096055129,"mc":[{"id":"1.195395450","rc":[{"atb":[[2.42,52.82]],"id":40995914},{"atl":[[5,18.75]],"id":40995914},{"atl":[[7,12.5]],"id":41360966},{"atb":[[1.86,87.21]],"id":40494151},{"atl":[[18.5,4.29]],"id":25760990}],"con":true,"img":false}]}
{"op":"mcm","clk":"5346753031","pt":1646096055233,"mc":[{"id":"1.195395450","rc":[{"atl":[[5.3,23.26],[5.6,45.74]],"id":40995914}],"con":true,"img":false}]}
{"op":"mcm","clk":"5346753038","pt":1646096055438,"mc":[{"id":"1.195395450","rc":[{"atb":[[2.92,4]],"id":41962160},{"atl":[[1.13,2]],"id":43066393}],"con":true,"img":false}]}
{"op":"mcm","clk":"5346753041","pt":1646096055539,"mc":[{"id":"1.195395450","rc":[{"atl":[[7.2,0]],"id":40995914},{"atb":[[3.1,0],[3.15,34.04]],"id":41360966}],"con":true,"img":false}]}
{"op":"mcm","clk":"5346753043","pt":1646096055639,"mc":[{"id":"1.195395450","rc":[{"atl":[[1.34,266.95]],"id":43066393}],"con":true,"img":false}]}
{"op":"mcm","clk":"5346753046","pt":1646096055743,"mc":[{"id":"1.195395450","rc":[{"atb":[[2.94,4]],"id":41962160},{"atl":[[1.12,3],[1.35,0]],"id":43066393}],"con":true,"img":false}]}
{"op":"mcm","clk":"5346753050","pt":1646096055947,"mc":[{"id":"1.195395450","rc":[{"atl":[[1.34,58.82]],"id":43066393}],"con":true,"img":false}]}
{"op":"mcm","clk":"5346753055","pt":1646096056001,"mc":[{"id":"1.195395450","rc":[{"atl":[[2.54,7.79],[2.58,113.23]],"id":40908100}],"con":true,"img":false}]}
{"op":"mcm","clk":"5346753058","pt":1646096056154,"mc":[{"id":"1.195395450","rc":[{"atl":[[6.4,0],[8.6,30.49]],"id":41962160}],"con":true,"img":false}]}
{"op":"mcm","clk":"5346753073","pt":1646096056720,"mc":[{"id":"1.195395450","rc":[{"atb":[[2.98,21.09]],"id":40995914}],"con":true,"img":false}]}
{"op":"mcm","clk":"5346753077","pt":1646096056822,"mc":[{"id":"1.195395450","rc":[{"atb":[[3.2,45.67]],"id":37495442}],"con":true,"img":false}]}
{"op":"mcm","clk":"5346753106","pt":1646096057641,"mc":[{"id":"1.195395450","rc":[{"atb":[[2.94,0],[2.92,0],[2.9,0]],"id":41962160}],"con":true,"img":false}]}
{"op":"mcm","clk":"5346753126","pt":1646096058152,"mc":[{"id":"1.195395450","rc":[{"atb":[[3.2,31.65]],"id":37495442}],"con":true,"img":false}]}
{"op":"mcm","clk":"5346753130","pt":1646096058210,"mc":[{"id":"1.195395450","rc":[{"atl":[[6.8,25.2]],"id":25760990}],"con":true,"img":false}]}
{"op":"mcm","clk":"5346753137","pt":1646096058311,"mc":[{"id":"1.195395450","rc":[{"atl":[[8.4,6.54]],"id":25760990}],"con":true,"img":false}]}
{"op":"mcm","clk":"5346753147","pt":1646096058517,"mc":[{"id":"1.195395450","rc":[{"atl":[[1.11,86.12]],"id":43066393}],"con":true,"img":false}]}
{"op":"mcm","clk":"5346753178","pt":1646096059442,"mc":[{"id":"1.195395450","rc":[{"atb":[[3.2,77.1],[3.25,0]],"id":37495442}],"con":true,"img":false}]}
{"op":"mcm","clk":"5346753185","pt":1646096059646,"mc":[{"id":"1.195395450","rc":[{"atb":[[3.4,3.1]],"id":40494151}],"con":true,"img":false}]}
{"op":"mcm","clk":"5346753200","pt":1646096059956,"mc":[{"id":"1.195395450","rc":[{"atb":[[3,0]],"id":41360966},{"atb":[[1.96,32.12]],"id":41962160}],"con":true,"img":false}]}
{"op":"mcm","clk":"5346753210","pt":1646096060116,"mc":[{"id":"1.195395450","rc":[{"atl":[[7.6,2.5]],"id":41360966},{"atb":[[3.35,9.62]],"id":40494151},{"atb":[[3.25,9.56]],"id":25760990}],"con":true,"img":false}]}
{"op":"mcm","clk":"5346753213","pt":1646096060217,"mc":[{"id":"1.195395450","rc":[{"atl":[[7.8,5.33]],"id":41360966},{"atb":[[3.2,40.52]],"id":25760990}],"con":true,"img":false}]}
{"op":"mcm","clk":"5346753217","pt":1646096060321,"mc":[{"id":"1.195395450","rc":[{"atb":[[3.15,5]],"id":25760990}],"con":true,"img":false}]}
{"op":"mcm","clk":"5346753233","pt":1646096060940,"mc":[{"id":"1.195395450","rc":[{"atl":[[1.33,60.61],[1.1,4],[1.34,0]],"id":43066393}],"con":true,"img":false}]}
{"op":"mcm","clk":"5346753240","pt":1646096061144,"mc":[{"id":"1.195395450","rc":[{"atl":[[1.1,6]],"id":43066393}],"con":true,"img":false}]}
{"op":"mcm","clk":"5346753245","pt":1646096061352,"mc":[{"id":"1.195395450","rc":[{"atl":[[1.11,84.12]],"id":43066393}],"con":true,"img":false}]}
{"op":"mcm","clk":"5346753264","pt":1646096061866,"mc":[{"id":"1.195395450","rc":[{"atb":[[3.3,13.24]],"id":40494151}],"con":true,"img":false}]}
{"op":"mcm","clk":"5346753273","pt":1646096061972,"mc":[{"id":"1.195395450","rc":[{"atb":[[3.25,13.7]],"id":37495442}],"con":true,"img":false}]}
{"op":"mcm","clk":"5346753284","pt":1646096062132,"mc":[{"id":"1.195395450","rc":[{"atb":[[1.32,0]],"id":40908100}],"con":true,"img":false}]}
{"op":"mcm","clk":"5346753292","pt":1646096062243,"mc":[{"id":"1.195395450","rc":[{"atb":[[1.34,176.74]],"id":40908100}],"con":true,"img":false}]}
{"op":"mcm","clk":"5346753314","pt":1646096062758,"mc":[{"id":"1.195395450","rc":[{"atb":[[3.4,0]],"id":40494151}],"con":true,"img":false}]}
{"op":"mcm","clk":"5346753353","pt":1646096063843,"mc":[{"id":"1.195395450","rc":[{"atb":[[3.2,28.7]],"id":25760990}],"con":true,"img":false}]}
{"op":"mcm","clk":"5346753375","pt":1646096064555,"mc":[{"id":"1.195395450","rc":[{"atb":[[3.35,20.02]],"id":40494151}],"con":true,"img":false}]}
{"op":"mcm","clk":"5346753382","pt":1646096064761,"mc":[{"id":"1.195395450","rc":[{"atb":[[3.3,0]],"id":40494151}],"con":true,"img":false}]}
{"op":"mcm","clk":"5346753391","pt":1646096065024,"mc":[{"id":"1.195395450","rc":[{"atb":[[2.38,163.04]],"id":40995914},{"atl":[[5.2,29.76]],"id":40995914},{"atl":[[7.4,19.53]],"id":41360966}],"con":true,"img":false}]}
{"op":"mcm","clk":"5346753395","pt":1646096065125,"mc":[{"id":"1.195395450","rc":[{"atb":[[1.84,148.81]],"id":40494151},{"atl":[[19.5,6.76]],"id":25760990}],"con":true,"img":false}]}
{"op":"mcm","clk":"5346753401","pt":1646096065329,"mc":[{"id":"1.195395450","rc":[{"atb":[[3.35,10.4]],"id":40494151}],"con":true,"img":false}]}
{"op":"mcm","clk":"5346753406","pt":1646096065583,"mc":[{"id":"1.195395450","rc":[{"atb":[[3.35,0]],"id":40494151},{"atb":[[2.06,7.02]],"id":41962160}],"con":true,"img":false}]}
{"op":"mcm","clk":"5346753409","pt":1646096065637,"mc":[{"id":"1.195395450","rc":[{"atb":[[3.25,10.98]],"id":40494151}],"con":true,"img":false}]}
{"op":"mcm","clk":"5346753412","pt":1646096065741,"mc":[{"id":"1.195395450","rc":[{"atb":[[2.64,51.5],[3.05,0],[3.4,12.85]],"id":40494151}],"con":true,"img":false}]}
{"op":"mcm","clk":"5346753426","pt":1646096066149,"mc":[{"id":"1.195395450","rc":[{"atl":[[2.62,0]],"id":40908100}],"con":true,"img":false}]}
{"op":"mcm","clk":"5346753430","pt":1646096066250,"mc":[{"id":"1.195395450","rc":[{"atl":[[6.8,0]],"id":40995914},{"atb":[[3.25,20.72]],"id":41360966},{"atl":[[2.56,26.68]],"id":40908100}],"con":true,"img":false}]}
{"op":"mcm","clk":"5346753437","pt":1646096066455,"mc":[{"id":"1.195395450","rc":[{"atb":[[2.52,5.49]],"id":40995914},{"atl":[[2.58,5],[2.56,128.71]],"id":40908100}],"con":true,"img":false}]}
{"op":"mcm","clk":"5346753454","pt":1646096066966,"mc":[{"id":"1.195395450","rc":[{"atb":[[3.3,39.48]],"id":37495442}],"con":true,"img":false}]}
{"op":"mcm","clk":"5346753459","pt":1646096067022,"mc":[{"id":"1.195395450","rc":[{"atb":[[3.25,39.8],[3.2,31.65]],"id":37495442}],"con":true,"img":false}]}
{"op":"mcm","clk":"5346753463","pt":1646096067124,"mc":[{"id":"1.195395450","rc":[{"atb":[[3.2,0]],"id":37495442}],"con":true,"img":false}]}
{"op":"mcm","clk":"5346753480","pt":1646096067738,"mc":[{"id":"1.195395450","rc":[{"atl":[[5,76.26]],"id":40995914},{"atl":[[7.2,0],[7,53.57]],"id":41360966}],"con":true,"img":false}]}
{"op":"mcm","clk":"5346753483","pt":1646096067843,"mc":[{"id":"1.195395450","rc":[{"atl":[[5.6,0]],"id":40995914},{"atb":[[1.96,0]],"id":41962160},{"atb":[[3.4,12.85]],"id":25760990}],"con":true,"img":false}]}
{"op":"mcm","clk":"5346753487","pt":1646096067942,"mc":[{"id":"1.195395450","rc":[{"atb":[[3.4,24.37]],"id":25760990}],"con":true,"img":false}]}
{"op":"mcm","clk":"5346753493","pt":1646096068145,"mc":[{"id":"1.195395450","rc":[{"atb":[[3.35,2.5]],"id":25760990}],"con":true,"img":false}]}
{"op":"mcm","clk":"5346753506","pt":1646096068555,"mc":[{"id":"1.195395450","rc":[{"atb":[[2.7,4.38]],"id":40494151}],"con":true,"img":false}]}
{"op":"mcm","clk":"5346753515","pt":1646096068863,"mc":[{"id":"1.195395450","rc":[{"atb":[[3.4,24.27]],"id":40494151}],"con":true,"img":false}]}
{"op":"mcm","clk":"5346753523","pt":1646096069067,"mc":[{"id":"1.195395450","rc":[{"atb":[[3.25,0]],"id":40494151}],"con":true,"img":false}]}
{"op":"mcm","clk":"5346753533","pt":1646096069534,"mc":[{"id":"1.195395450","rc":[{"atb":[[3.25,26.1]],"id":37495442}],"con":true,"img":false}]}
{"op":"mcm","clk":"5346753583","pt":1646096070766,"mc":[{"id":"1.195395450","rc":[{"atb":[[2.08,4.91]],"id":41962160},{"atb":[[3.25,0]],"id":25760990}],"con":true,"img":false}]}
{"op":"mcm","clk":"5346753635","pt":1646096071746,"mc":[{"id":"1.195395450","rc":[{"atb":[[2.7,0]],"id":40494151}],"con":true,"img":false}]}
{"op":"mcm","clk":"5346753646","pt":1646096072052,"mc":[{"id":"1.195395450","rc":[{"atb":[[3.25,70.54]],"id":37495442}],"con":true,"img":false}]}
{"op":"mcm","clk":"5346753649","pt":1646096072155,"mc":[{"id":"1.195395450","rc":[{"atb":[[3.3,0]],"id":37495442}],"con":true,"img":false}]}
{"op":"mcm","clk":"5346753661","pt":1646096072562,"mc":[{"id":"1.195395450","rc":[{"atb":[[2.06,14.9]],"id":41962160}],"con":true,"img":false}]}
{"op":"mcm","clk":"5346753689","pt":1646096073338,"mc":[{"id":"1.195395450","rc":[{"atb":[[3.45,12.59]],"id":37495442},{"atb":[[2.1,9.83]],"id":41962160}],"con":true,"img":false}]}
{"op":"mcm","clk":"5346753692","pt":1646096073443,"mc":[{"id":"1.195395450","rc":[{"atb":[[3.5,12.21]],"id":37495442}],"con":true,"img":false}]}
{"op":"mcm","clk":"5346753695","pt":1646096073543,"mc":[{"id":"1.195395450","rc":[{"atb":[[3.4,43.59]],"id":37495442}],"con":true,"img":false}]}
{"op":"mcm","clk":"5346753697","pt":1646096073643,"mc":[{"id":"1.195395450","rc":[{"atb":[[3.25,44.44],[3.4,26.35]],"id":37495442}],"con":true,"img":false}]}
{"op":"mcm","clk":"5346753714","pt":1646096074255,"mc":[{"id":"1.195395450","rc":[{"atl":[[5.3,0],[5.1,24.39]],"id":40995914}],"con":true,"img":false}]}
{"op":"mcm","clk":"5346753723","pt":1646096074664,"mc":[{"id":"1.195395450","rc":[{"atb":[[3.5,2.97]],"id":25760990}],"con":true,"img":false}]}
{"op":"mcm","clk":"5346753742","pt":1646096075177,"mc":[{"id":"1.195395450","rc":[{"atb":[[3.4,11.42]],"id":40494151}],"con":true,"img":false}]}
{"op":"mcm","clk":"5346753748","pt":1646096075381,"mc":[{"id":"1.195395450","rc":[{"atb":[[3.4,0]],"id":40494151}],"con":true,"img":false}]}
{"op":"mcm","clk":"5346753752","pt":1646096075438,"mc":[{"id":"1.195395450","rc":[{"atb":[[2.64,27.41],[2.6,68.63],[3.25,11.74]],"id":40494151}],"con":true,"img":false}]}
{"op":"mcm","clk":"5346753774","pt":1646096076161,"mc":[{"id":"1.195395450","rc":[{"atb":[[3.35,19.99],[3.2,0]],"id":25760990}],"con":true,"img":false}]}
{"op":"mcm","clk":"5346753783","pt":1646096076363,"mc":[{"id":"1.195395450","rc":[{"atb":[[2.08,0]],"id":41962160},{"atb":[[3.45,9.23]],"id":25760990}],"con":true,"img":false}]}
{"op":"mcm","clk":"5346753809","pt":1646096077083,"mc":[{"id":"1.195395450","rc":[{"atb":[[3.45,0]],"id":37495442},{"atb":[[3.4,11.52]],"id":25760990}],"con":true,"img":false}]}
{"op":"mcm","clk":"5346753820","pt":1646096077290,"mc":[{"id":"1.195395450","rc":[{"atb":[[3.4,2.5],[3.25,68.29],[3.5,0]],"id":37495442}],"con":true,"img":false}]}
{"op":"mcm","clk":"5346753825","pt":1646096077344,"mc":[{"id":"1.195395450","rc":[{"atb":[[3.45,11.92]],"id":37495442}],"con":true,"img":false}]}
{"op":"mcm","clk":"5346753831","pt":1646096077447,"mc":[{"id":"1.195395450","rc":[{"atb":[[3.25,23.85],[3.15,55.81]],"id":37495442}],"con":true,"img":false}]}
{"op":"mcm","clk":"5346753844","pt":1646096077754,"mc":[{"id":"1.195395450","rc":[{"atb":[[3.5,0]],"id":25760990}],"con":true,"img":false}]}
{"op":"mcm","clk":"5346753856","pt":1646096078163,"mc":[{"id":"1.195395450","rc":[{"atl":[[7.8,0]],"id":41360966}],"con":true,"img":false}]}
{"op":"mcm","clk":"5346753860","pt":1646096078266,"mc":[{"id":"1.195395450","rc":[{"atl":[[7.4,24.86]],"id":41360966}],"con":true,"img":false}]}
{"op":"mcm","clk":"5346753881","pt":1646096078981,"mc":[{"id":"1.195395450","rc":[{"atb":[[3.3,13.4]],"id":40494151},{"atb":[[2.1,0]],"id":41962160}],"con":true,"img":false}]}
{"op":"mcm","clk":"5346753895","pt":1646096079446,"mc":[{"id":"1.195395450","rc":[{"atb":[[3.25,47.7]],"id":37495442}],"con":true,"img":false}]}
{"op":"mcm","clk":"5346753897","pt":1646096079546,"mc":[{"id":"1.195395450","rc":[{"atb":[[3.15,9.3]],"id":37495442},{"atb":[[2.12,6.88]],"id":41962160},{"atb":[[3.45,0]],"id":25760990}],"con":true,"img":false}]}
{"op":"mcm","clk":"5346753914","pt":1646096080163,"mc":[{"id":"1.195395450","rc":[{"atl":[[14,0]],"id":37495442}],"con":true,"img":false}]}
{"op":"mcm","clk":"5346753917","pt":1646096080265,"mc":[{"id":"1.195395450","rc":[{"atl":[[13,14.08]],"id":37495442}],"con":true,"img":false}]}
{"op":"mcm","clk":"5346753921","pt":1646096080364,"mc":[{"id":"1.195395450","rc":[{"atb":[[3.3,25.38]],"id":40494151}],"con":true,"img":false}]}
{"op":"mcm","clk":"5346753924","pt":1646096080569,"mc":[{"id":"1.195395450","rc":[{"atb":[[3.25,0]],"id":40494151}],"con":true,"img":false}]}
{"op":"mcm","clk":"5346753935","pt":1646096080877,"mc":[{"id":"1.195395450","rc":[{"atb":[[3.5,12.33]],"id":37495442}],"con":true,"img":false}]}
{"op":"mcm","clk":"5346753941","pt":1646096080979,"mc":[{"id":"1.195395450","rc":[{"atb":[[3.25,23.85],[3.55,11.92]],"id":37495442}],"con":true,"img":false}]}
{"op":"mcm","clk":"5346753969","pt":1646096081596,"mc":[{"id":"1.195395450","rc":[{"atb":[[2.64,58.52],[2.6,37.52]],"id":40494151}],"con":true,"img":false}]}
{"op":"mcm","clk":"5346754029","pt":1646096082882,"mc":[{"id":"1.195395450","rc":[{"atb":[[3.45,35.34]],"id":37495442},{"atb":[[2.08,18.93]],"id":41962160}],"con":true,"img":false}]}
{"op":"mcm","clk":"5346754034","pt":1646096082983,"mc":[{"id":"1.195395450","rc":[{"atb":[[3.25,0]],"id":37495442}],"con":true,"img":false}]}
{"op":"mcm","clk":"5346754060","pt":1646096083599,"mc":[{"id":"1.195395450","rc":[{"atb":[[3.15,35.3]],"id":25760990}],"con":true,"img":false}]}
{"op":"mcm","clk":"5346754066","pt":1646096083659,"mc":[{"id":"1.195395450","rc":[{"atb":[[3.35,2.5]],"id":25760990}],"con":true,"img":false}]}
{"op":"mcm","clk":"5346754088","pt":1646096084173,"mc":[{"id":"1.195395450","rc":[{"atl":[[2.56,102.03]],"id":40908100}],"con":true,"img":false}]}
{"op":"mcm","clk":"5346754092","pt":1646096084278,"mc":[{"id":"1.195395450","rc":[{"atl":[[2.54,34.48]],"id":40908100}],"con":true,"img":false}]}
{"op":"mcm","clk":"5346754101","pt":1646096084584,"mc":[{"id":"1.195395450","rc":[{"atb":[[3.5,0]],"id":37495442}],"con":true,"img":false}]}
{"op":"mcm","clk":"5346754105","pt":1646096084686,"mc":[{"id":"1.195395450","rc":[{"atb":[[3.35,9.62]],"id":40494151}],"con":true,"img":false}]}
{"op":"mcm","clk":"5346754109","pt":1646096084790,"mc":[{"id":"1.195395450","rc":[{"atb":[[3.45,11.92],[3.4,53.45],[3.55,0]],"id":37495442}],"con":true,"img":false}]}
{"op":"mcm","clk":"5346754114","pt":1646096084891,"mc":[{"id":"1.195395450","rc":[{"atb":[[3.35,20.02]],"id":40494151}],"con":true,"img":false}]}
{"op":"mcm","clk":"5346754118","pt":1646096084993,"mc":[{"id":"1.195395450","rc":[{"atb":[[3.3,13.4]],"id":40494151}],"con":true,"img":false}]}
{"op":"mcm","clk":"5346754240","pt":1646096088175,"mc":[{"id":"1.195395450","rc":[{"atl":[[8.6,0]],"id":41962160}],"con":true,"img":false}]}
{"op":"mcm","clk":"5346754247","pt":1646096088279,"mc":[{"id":"1.195395450","rc":[{"atl":[[7,30.49]],"id":41962160}],"con":true,"img":false}]}
{"op":"mcm","clk":"5346754256","pt":1646096088484,"mc":[{"id":"1.195395450","rc":[{"atb":[[3.5,12.33]],"id":37495442},{"atb":[[3.3,0]],"id":40494151}],"con":true,"img":false}]}
{"op":"mcm","clk":"5346754281","pt":1646096089199,"mc":[{"id":"1.195395450","rc":[{"atb":[[3.55,11.71]],"id":37495442}],"con":true,"img":false}]}
{"op":"mcm","clk":"5346754285","pt":1646096089302,"mc":[{"id":"1.195395450","rc":[{"atb":[[3.45,23.1],[3.4,44.17]],"id":37495442}],"con":true,"img":false}]}
{"op":"mcm","clk":"5346754384","pt":1646096092078,"mc":[{"id":"1.195395450","rc":[{"atb":[[3.55,24.05],[3.4,2.5]],"id":37495442},{"atb":[[3.35,10.4]],"id":40494151}],"con":true,"img":false}]}
{"op":"mcm","clk":"5346754388","pt":1646096092180,"mc":[{"id":"1.195395450","rc":[{"atb":[[3.5,0]],"id":37495442},{"atb":[[3.25,13.7]],"id":40494151}],"con":true,"img":false}]}
{"op":"mcm","clk":"5346754391","pt":1646096092283,"mc":[{"id":"1.195395450","rc":[{"atb":[[3.45,0],[3.4,11.78]],"id":37495442},{"atb":[[3.35,0],[2.64,27.41],[3.2,24.46]],"id":40494151}],"con":true,"img":false}]}
{"op":"mcm","clk":"5346754396","pt":1646096092384,"mc":[{"id":"1.195395450","rc":[{"atb":[[3.25,24.68]],"id":40494151}],"con":true,"img":false}]}
{"op":"mcm","clk":"5346754408","pt":1646096092692,"mc":[{"id":"1.195395450","rc":[{"atb":[[3.2,3.38]],"id":25760990}],"con":true,"img":false}]}
{"op":"mcm","clk":"5346754414","pt":1646096092794,"mc":[{"id":"1.195395450","rc":[{"atb":[[3.2,19.32]],"id":25760990}],"con":true,"img":false}]}
{"op":"mcm","clk":"5346754418","pt":1646096092894,"mc":[{"id":"1.195395450","rc":[{"atb":[[3.15,5]],"id":25760990}],"con":true,"img":false}]}
{"op":"mcm","clk":"5346754493","pt":1646096095418,"mc":[{"id":"1.195395450","rc":[{"atb":[[2.8,0],[2.9,0],[2.7,0]],"id":37495442},{"atl":[[19.5,0],[9.8,0],[7.8,0],[14.5,0],[29,0]],"id":37495442},{"atb":[[2.3,0],[2.4,0],[2.2,0]],"id":40995914},{"atl":[[5.8,0],[14,0],[9.6,0],[19,0],[7.6,0]],"id":40995914},{"atb":[[2.84,0],[2.94,0],[2.74,0]],"id":41360966},{"atl":[[8,14.29],[10,0],[20,0],[15,0],[30,0]],"id":41360966},{"atb":[[2.4,0],[2.5,0],[2.6,0]],"id":40494151},{"atl":[[10.5,0],[8.2,0],[15.5,0],[6.2,1.93],[21,0]],"id":40494151},{"atb":[[2,0],[1.95,0],[1.9,0]],"id":41962160},{"atl":[[5.1,0],[6.2,0],[10.5,0],[8.2,0],[15.5,0]],"id":41962160},{"atb":[[2.5,0],[2.3,0],[2.4,0]],"id":25760990},{"atl":[[8,0],[10,0],[15,0],[20,0],[6,4.84]],"id":25760990},{"atb":[[1.2,250],[1.25,400],[1.3,0]],"id":40908100},{"atl":[[2.54,26.68],[3.85,0],[3.35,0],[2.94,0],[2.74,0]],"id":40908100},{"atb":[[1.01,1458.57]],"id":43066393},{"atl":[[2.26,0],[1.93,0],[2.06,0],[2.46,0],[2.66,0]],"id":43066393}],"con":true,"img":false}]}
{"op":"mcm","clk":"5346754499","pt":1646096095624,"mc":[{"id":"1.195395450","rc":[{"atl":[[10,11.44],[11.5,25.85]],"id":37495442},{"atl":[[6.2,0]],"id":40494151},{"atl":[[6,0]],"id":25760990}],"con":true,"img":false}]}
{"op":"mcm","clk":"5346754503","pt":1646096095678,"mc":[{"id":"1.195395450","rc":[{"atl":[[7.6,15.15]],"id":40494151},{"atb":[[3.2,15.94]],"id":25760990},{"atl":[[6.4,5.5]],"id":25760990}],"con":true,"img":false}]}
{"op":"mcm","clk":"5346754506","pt":1646096095779,"mc":[{"id":"1.195395450","rc":[{"atb":[[3.45,12.59]],"id":37495442},{"atl":[[8,45.58],[7.8,0]],"id":40494151},{"atl":[[7.4,31.94],[6.8,0]],"id":25760990}],"con":true,"img":false}]}
{"op":"mcm","clk":"5346754520","pt":1646096096087,"mc":[{"id":"1.195395450","rc":[{"atb":[[2.72,0],[2.42,42.6]],"id":37495442},{"atb":[[2.22,0],[2.04,51.07]],"id":40995914},{"atb":[[2.24,45],[2.42,0]],"id":40494151},{"atb":[[2.24,47.64],[2.42,0]],"id":25760990}],"con":true,"img":false}]}
{"op":"mcm","clk":"5346754524","pt":1646096096189,"mc":[{"id":"1.195395450","rc":[{"atl":[[13,0]],"id":37495442}],"con":true,"img":false}]}
{"op":"mcm","clk":"5346754527","pt":1646096096290,"mc":[{"id":"1.195395450","rc":[{"atl":[[15,14.08]],"id":37495442}],"con":true,"img":false}]}
{"op":"mcm","clk":"5346754559","pt":1646096097211,"mc":[{"id":"1.195395450","rc":[{"atb":[[3.55,11.71],[3.5,40]],"id":37495442}],"con":true,"img":false}]}
{"op":"mcm","clk":"5346754563","pt":1646096097314,"mc":[{"id":"1.195395450","rc":[{"atb":[[3.45,49.04],[3.4,2.5]],"id":37495442}],"con":true,"img":false}]}
{"op":"mcm","clk":"5346754567","pt":1646096097418,"mc":[{"id":"1.195395450","rc":[{"atb":[[2.8,66.7],[3.45,89.86],[2.9,31.59],[2.7,70.63]],"id":37495442},{"atl":[[9.8,0.05],[7.8,0.08],[14.5,0.31]],"id":37495442},{"atb":[[2.3,92.36],[2.4,42.88],[2.2,100.05]],"id":40995914},{"atl":[[9.6,0.5],[5.8,0.11],[7.6,0.08]],"id":40995914},{"atb":[[2.84,65.25],[2.94,30.94],[2.74,69]],"id":41360966},{"atl":[[8,14.36],[10,0.05],[15,0.3]],"id":41360966},{"atb":[[2.4,85.76],[2.5,80.04],[2.6,37.52]],"id":40494151},{"atl":[[6.2,0.1],[10.5,0.45],[8.2,0.07]],"id":40494151},{"atb":[[2,60.03],[1.95,126.38],[1.9,133.41]],"id":41962160},{"atl":[[5.1,0.12],[6.2,0.1],[8.2,0.6]],"id":41962160},{"atb":[[2.5,40.02],[2.3,92.36],[2.4,85.76]],"id":25760990},{"atl":[[8,0.07],[10,0.48],[6,0.1]],"id":25760990},{"atb":[[1.2,850.35],[1.25,880.28],[1.3,200.11]],"id":40908100},{"atl":[[2.54,27.03],[2.74,0.3],[2.94,2.22]],"id":40908100},{"atb":[[1.01,31476.42]],"id":43066393},{"atl":[[2.26,3.43],[1.93,0.58],[2.06,0.5]],"id":43066393}],"con":true,"img":false}]}
{"op":"mcm","clk":"5346754571","pt":1646096097522,"mc":[{"id":"1.195395450","rc":[{"atb":[[3.5,0]],"id":37495442},{"atb":[[3.3,9.83]],"id":40494151}],"con":true,"img":false}]}
{"op":"mcm","clk":"5346754578","pt":1646096097677,"mc":[{"id":"1.195395450","rc":[{"atb":[[3.3,39.54]],"id":40494151}],"con":true,"img":false}]}
{"op":"mcm","clk":"5346754582","pt":1646096097783,"mc":[{"id":"1.195395450","rc":[{"atb":[[3.55,0]],"id":37495442}],"con":true,"img":false}]}
{"op":"mcm","clk":"5346754586","pt":1646096097889,"mc":[{"id":"1.195395450","rc":[{"atb":[[3.5,10.46]],"id":37495442},{"atb":[[3.25,13.7]],"id":40494151}],"con":true,"img":false}]}
{"op":"mcm","clk":"5346754644","pt":1646096099526,"mc":[{"id":"1.195395450","rc":[{"atb":[[3.45,53.41],[3.4,35.58]],"id":37495442}],"con":true,"img":false}]}
{"op":"mcm","clk":"5346754736","pt":1646096101485,"mc":[{"id":"1.195395450","rc":[{"atb":[[1.01,31477.42]],"id":43066393}],"con":true,"img":false}]}
{"op":"mcm","clk":"5346754767","pt":1646096102205,"mc":[{"id":"1.195395450","rc":[{"atb":[[2.64,0]],"id":40494151}],"con":true,"img":false}]}
{"op":"mcm","clk":"5346754772","pt":1646096102304,"mc":[{"id":"1.195395450","rc":[{"atb":[[2.72,27.41]],"id":40494151}],"con":true,"img":false}]}
{"op":"mcm","clk":"5346754798","pt":1646096103022,"mc":[{"id":"1.195395450","rc":[{"atl":[[8,7.14],[8.4,47.36]],"id":40494151}],"con":true,"img":false}]}
{"op":"mcm","clk":"5346754867","pt":1646096104717,"mc":[{"id":"1.195395450","rc":[{"atb":[[3.55,2.92]],"id":37495442},{"atb":[[3.4,3.1]],"id":40494151}],"con":true,"img":false}]}
{"op":"mcm","clk":"5346754873","pt":1646096104819,"mc":[{"id":"1.195395450","rc":[{"atb":[[3.6,10.04],[3.55,13.38],[3.45,45.67],[3.4,2.5]],"id":37495442},{"atb":[[3.25,57.14],[3.2,2.5],[3.4,18.74]],"id":40494151}],"con":true,"img":false}]}
{"op":"mcm","clk":"5346754880","pt":1646096105025,"mc":[{"id":"1.195395450","rc":[{"atb":[[3.5,0]],"id":37495442},{"atb":[[3.3,9.83]],"id":40494151}],"con":true,"img":false}]}
{"op":"mcm","clk":"5346754967","pt":1646096106718,"mc":[{"id":"1.195395450","rc":[{"atb":[[3.45,33.08]],"id":37495442},{"atb":[[3.25,43.44]],"id":40494151}],"con":true,"img":false}]}
{"op":"mcm","clk":"5346755001","pt":1646096107695,"mc":[{"id":"1.195395450","rc":[{"atb":[[3.4,15.64]],"id":40494151}],"con":true,"img":false}]}
{"op":"mcm","clk":"5346755008","pt":1646096107795,"mc":[{"id":"1.195395450","rc":[{"atb":[[3.4,0]],"id":40494151}],"con":true,"img":false}]}
{"op":"mcm","clk":"5346755016","pt":1646096108001,"mc":[{"id":"1.195395450","rc":[{"atb":[[3.25,56.17]],"id":40494151}],"con":true,"img":false}]}
{"op":"mcm","clk":"5346755059","pt":1646096109030,"mc":[{"id":"1.195395450","rc":[{"atb":[[3.25,25.72],[3.45,2.5],[3.2,24.16],[3.4,12.08]],"id":41360966},{"atb":[[3.25,58.67],[2.94,10],[3.05,5],[3.2,0]],"id":40494151}],"con":true,"img":false}]}
{"op":"mcm","clk":"5346755065","pt":1646096109133,"mc":[{"id":"1.195395450","rc":[{"atb":[[3.25,72.68],[3.45,25.98]],"id":41360966},{"atl":[[2.5,9.6],[2.44,2.5],[2.58,0],[2.52,5],[2.66,0]],"id":40908100}],"con":true,"img":false}]}
{"op":"mcm","clk":"5346755070","pt":1646096109235,"mc":[{"id":"1.195395450","rc":[{"atb":[[3.2,0],[3.4,0]],"id":41360966},{"atl":[[2.48,40.07],[2.52,81.4]],"id":40908100}],"con":true,"img":false}]}
{"op":"mcm","clk":"5346755076","pt":1646096109393,"mc":[{"id":"1.195395450","rc":[{"atb":[[3.3,0]],"id":40494151},{"atl":[[2.5,0],[2.56,0]],"id":40908100}],"con":true,"img":false}]}
{"op":"mcm","clk":"5346755105","pt":1646096110212,"mc":[{"id":"1.195395450","rc":[{"atl":[[8.4,0]],"id":25760990}],"con":true,"img":false}]}
{"op":"mcm","clk":"5346755109","pt":1646096110314,"mc":[{"id":"1.195395450","rc":[{"atl":[[7.2,6.54]],"id":25760990}],"con":true,"img":false}]}
{"op":"mcm","clk":"5346755114","pt":1646096110417,"mc":[{"id":"1.195395450","rc":[{"atb":[[3.65,11.63]],"id":37495442},{"atb":[[3.35,13.12]],"id":40494151}],"con":true,"img":false}]}
{"op":"mcm","clk":"5346755119","pt":1646096110520,"mc":[{"id":"1.195395450","rc":[{"atb":[[3.55,48.22],[3.45,0]],"id":37495442}],"con":true,"img":false}]}
{"op":"mcm","clk":"5346755127","pt":1646096110725,"mc":[{"id":"1.195395450","rc":[{"atb":[[3.25,69.37]],"id":41360966}],"con":true,"img":false}]}
{"op":"mcm","clk":"5346755143","pt":1646096111033,"mc":[{"id":"1.195395450","rc":[{"atl":[[7.4,5],[7.2,24.77]],"id":25760990}],"con":true,"img":false}]}
{"op":"mcm","clk":"5346755177","pt":1646096111910,"mc":[{"id":"1.195395450","rc":[{"atb":[[3.55,37.76],[3.7,11.64]],"id":37495442},{"atb":[[3.05,47.57]],"id":40494151}],"con":true,"img":false}]}
{"op":"mcm","clk":"5346755182","pt":1646096112012,"mc":[{"id":"1.195395450","rc":[{"atb":[[3.25,15.23]],"id":40494151}],"con":true,"img":false}]}
{"op":"mcm","clk":"5346755192","pt":1646096112218,"mc":[{"id":"1.195395450","rc":[{"atb":[[3.25,55.66]],"id":41360966},{"atl":[[7.2,18.23]],"id":25760990}],"con":true,"img":false}]}
{"op":"mcm","clk":"5346755199","pt":1646096112321,"mc":[{"id":"1.195395450","rc":[{"atl":[[9,6.54]],"id":25760990}],"con":true,"img":false}]}
{"op":"mcm","clk":"5346755208","pt":1646096112526,"mc":[{"id":"1.195395450","rc":[{"atb":[[3.6,44.88],[3.55,2.92]],"id":37495442}],"con":true,"img":false}]}
{"op":"mcm","clk":"5346755216","pt":1646096112834,"mc":[{"id":"1.195395450","rc":[{"atb":[[3.35,34.33]],"id":40494151}],"con":true,"img":false}]}
{"op":"mcm","clk":"5346755221","pt":1646096113038,"mc":[{"id":"1.195395450","rc":[{"atb":[[3.25,2.5]],"id":40494151}],"con":true,"img":false}]}
{"op":"mcm","clk":"5346755225","pt":1646096113139,"mc":[{"id":"1.195395450","rc":[{"atb":[[3.75,17.32]],"id":37495442}],"con":true,"img":false}]}
{"op":"mcm","clk":"5346755230","pt":1646096113346,"mc":[{"id":"1.195395450","rc":[{"atb":[[3.6,34.84]],"id":37495442}],"con":true,"img":false}]}
{"op":"mcm","clk":"5346755244","pt":1646096113807,"mc":[{"id":"1.195395450","rc":[{"atb":[[3.55,0]],"id":37495442}],"con":true,"img":false}]}
{"op":"mcm","clk":"5346755253","pt":1646096114012,"mc":[{"id":"1.195395450","rc":[{"atb":[[3.65,0]],"id":37495442}],"con":true,"img":false}]}
{"op":"mcm","clk":"5346755257","pt":1646096114115,"mc":[{"id":"1.195395450","rc":[{"atb":[[3.6,63.8],[3.7,0]],"id":37495442}],"con":true,"img":false}]}
{"op":"mcm","clk":"5346755260","pt":1646096114216,"mc":[{"id":"1.195395450","rc":[{"atb":[[3.4,9.18]],"id":40494151}],"con":true,"img":false}]}
{"op":"mcm","clk":"5346755308","pt":1646096115811,"mc":[{"id":"1.195395450","rc":[{"atb":[[3.3,13.4]],"id":41360966}],"con":true,"img":false}]}
{"op":"mcm","clk":"5346755317","pt":1646096116121,"mc":[{"id":"1.195395450","rc":[{"atl":[[9,0]],"id":40494151}],"con":true,"img":false}]}
{"op":"mcm","clk":"5346755321","pt":1646096116224,"mc":[{"id":"1.195395450","rc":[{"atl":[[8.2,6.83]],"id":40494151}],"con":true,"img":false}]}
{"op":"mcm","clk":"5346755325","pt":1646096116326,"mc":[{"id":"1.195395450","rc":[{"atl":[[8.2,31.32],[8.4,10.14]],"id":40494151}],"con":true,"img":false}]}
{"op":"mcm","clk":"5346755337","pt":1646096116739,"mc":[{"id":"1.195395450","rc":[{"atb":[[3.55,2.92]],"id":41360966}],"con":true,"img":false}]}
{"op":"mcm","clk":"5346755367","pt":1646096117507,"mc":[{"id":"1.195395450","rc":[{"atb":[[3.6,28.95],[3.4,45.86]],"id":37495442}],"con":true,"img":false}]}
{"op":"mcm","clk":"5346755373","pt":1646096117608,"mc":[{"id":"1.195395450","rc":[{"atb":[[3.6,0],[3.75,0],[3.45,40.82]],"id":37495442}],"con":true,"img":false}]}
{"op":"mcm","clk":"5346755376","pt":1646096117711,"mc":[{"id":"1.195395450","rc":[{"atb":[[3.45,42.82]],"id":37495442}],"con":true,"img":false}]}
{"op":"mcm","clk":"5346755381","pt":1646096117813,"mc":[{"id":"1.195395450","rc":[{"atb":[[3.65,11.63]],"id":37495442},{"atb":[[3.35,21.21]],"id":40494151}],"con":true,"img":false}]}
{"op":"mcm","clk":"5346755442","pt":1646096119561,"mc":[{"id":"1.195395450","rc":[{"atb":[[3.3,0]],"id":41360966}],"con":true,"img":false}]}
{"op":"mcm","clk":"5346755447","pt":1646096119715,"mc":[{"id":"1.195395450","rc":[{"atb":[[3.45,3.03]],"id":40494151}],"con":true,"img":false}]}
{"op":"mcm","clk":"5346755450","pt":1646096119818,"mc":[{"id":"1.195395450","rc":[{"atb":[[3.7,17.32]],"id":37495442},{"atb":[[3.25,39.16],[3.05,5],[3.4,21.43]],"id":40494151}],"con":true,"img":false}]}
{"op":"mcm","clk":"5346755455","pt":1646096119919,"mc":[{"id":"1.195395450","rc":[{"atb":[[3.45,86.26]],"id":37495442}],"con":true,"img":false}]}
{"op":"mcm","clk":"5346755458","pt":1646096120024,"mc":[{"id":"1.195395450","rc":[{"atb":[[3.45,84.26],[3.4,2.5]],"id":37495442},{"atb":[[3.35,0]],"id":40494151}],"con":true,"img":false}]}
{"op":"mcm","clk":"5346755509","pt":1646096121518,"mc":[{"id":"1.195395450","rc":[{"atb":[[3.65,0]],"id":37495442},{"atb":[[3.45,15.62]],"id":40494151}],"con":true,"img":false}]}
{"op":"mcm","clk":"5346755516","pt":1646096121724,"mc":[{"id":"1.195395450","rc":[{"atb":[[3.7,0]],"id":37495442}],"con":true,"img":false}]}
{"op":"mcm","clk":"5346755520","pt":1646096121827,"mc":[{"id":"1.195395450","rc":[{"atb":[[3.5,10.46]],"id":37495442}],"con":true,"img":false}]}
{"op":"mcm","clk":"5346755538","pt":1646096122341,"mc":[{"id":"1.195395450","rc":[{"atb":[[3.25,51.96]],"id":41360966}],"con":true,"img":false}]}
{"op":"mcm","clk":"5346755553","pt":1646096122752,"mc":[{"id":"1.195395450","rc":[{"atb":[[3.4,44.17]],"id":37495442}],"con":true,"img":false}]}
{"op":"mcm","clk":"5346755558","pt":1646096122856,"mc":[{"id":"1.195395450","rc":[{"atb":[[3.45,43.44]],"id":37495442},{"atb":[[3.45,12.59]],"id":40494151}],"con":true,"img":false}]}
{"op":"mcm","clk":"5346755564","pt":1646096122960,"mc":[{"id":"1.195395450","rc":[{"atb":[[3.45,35.67]],"id":40494151}],"con":true,"img":false}]}
{"op":"mcm","clk":"5346755573","pt":1646096123165,"mc":[{"id":"1.195395450","rc":[{"atb":[[3.4,9.18]],"id":40494151}],"con":true,"img":false}]}
{"op":"mcm","clk":"5346755587","pt":1646096123627,"mc":[{"id":"1.195395450","rc":[{"atb":[[3.4,0]],"id":40494151}],"con":true,"img":false}]}
{"op":"mcm","clk":"5346755594","pt":1646096124037,"mc":[{"id":"1.195395450","rc":[{"atb":[[3.55,34.29]],"id":41360966}],"con":true,"img":false}]}
{"op":"mcm","clk":"5346755597","pt":1646096124140,"mc":[{"id":"1.195395450","rc":[{"atl":[[2.42,56.34]],"id":40908100}],"con":true,"img":false}]}
{"op":"mcm","clk":"5346755605","pt":1646096124243,"mc":[{"id":"1.195395450","rc":[{"atb":[[3.45,2.5]],"id":41360966},{"atl":[[2.52,5],[2.48,132.24]],"id":40908100}],"con":true,"img":false}]}
{"op":"mcm","clk":"5346755616","pt":1646096124550,"mc":[{"id":"1.195395450","rc":[{"atb":[[3.45,0],[3.4,100.33]],"id":37495442}],"con":true,"img":false}]}
{"op":"mcm","clk":"5346755622","pt":1646096124755,"mc":[{"id":"1.195395450","rc":[{"atb":[[3.5,0]],"id":37495442}],"con":true,"img":false}]}
{"op":"mcm","clk":"5346755625","pt":1646096124859,"mc":[{"id":"1.195395450","rc":[{"atb":[[3.45,14.82]],"id":37495442}],"con":true,"img":false}]}
{"op":"mcm","clk":"5346755641","pt":1646096125220,"mc":[{"id":"1.195395450","rc":[{"atb":[[3.55,12.09]],"id":37495442}],"con":true,"img":false}]}
{"op":"mcm","clk":"5346755653","pt":1646096125836,"mc":[{"id":"1.195395450","rc":[{"atb":[[3.55,31.37]],"id":41360966}],"con":true,"img":false}]}
{"op":"mcm","clk":"5346755659","pt":1646096125937,"mc":[{"id":"1.195395450","rc":[{"atb":[[3.55,0]],"id":41360966}],"con":true,"img":false}]}
{"op":"mcm","clk":"5346755662","pt":1646096126040,"mc":[{"id":"1.195395450","rc":[{"atb":[[3.45,35.15],[3.25,5],[3.15,113.94]],"id":41360966}],"con":true,"img":false}]}
{"op":"mcm","clk":"5346755693","pt":1646096126760,"mc":[{"id":"1.195395450","rc":[{"atb":[[3.25,2.5],[3.05,74.87]],"id":40494151}],"con":true,"img":false}]}
{"op":"mcm","clk":"5346755702","pt":1646096126966,"mc":[{"id":"1.195395450","rc":[{"atb":[[3.45,23.08]],"id":40494151}],"con":true,"img":false}]}
{"op":"mcm","clk":"5346755713","pt":1646096127170,"mc":[{"id":"1.195395450","rc":[{"atb":[[3.45,0]],"id":40494151}],"con":true,"img":false}]}
{"op":"mcm","clk":"5346755719","pt":1646096127223,"mc":[{"id":"1.195395450","rc":[{"atb":[[3.25,19.22]],"id":40494151}],"con":true,"img":false}]}
{"op":"mcm","clk":"5346755745","pt":1646096128043,"mc":[{"id":"1.195395450","rc":[{"atb":[[3.6,17.66]],"id":37495442}],"con":true,"img":false}]}
{"op":"mcm","clk":"5346755748","pt":1646096128146,"mc":[{"id":"1.195395450","rc":[{"atb":[[3.45,40.36]],"id":37495442},{"atl":[[15,0]],"id":37495442},{"atb":[[2.24,0],[2.42,37.29]],"id":25760990},{"atl":[[2.54,0.35]],"id":40908100}],"con":true,"img":false}]}
{"op":"mcm","clk":"5346755752","pt":1646096128250,"mc":[{"id":"1.195395450","rc":[{"atb":[[3.4,44.17]],"id":37495442},{"atl":[[11,14.08]],"id":37495442},{"atb":[[2.22,37.6],[2.04,0]],"id":40995914},{"atb":[[3.55,3.27]],"id":41360966},{"atb":[[2.24,0],[2.42,34.8]],"id":40494151},{"atl":[[2.74,26.99]],"id":40908100}],"con":true,"img":false}]}
{"op":"mcm","clk":"5346755755","pt":1646096128352,"mc":[{"id":"1.195395450","rc":[{"atl":[[11,44.15],[11.5,4.76]],"id":37495442}],"con":true,"img":false}]}
{"op":"mcm","clk":"5346755777","pt":1646096128864,"mc":[{"id":"1.195395450","rc":[{"atb":[[3.45,9.07]],"id":25760990}],"con":true,"img":false}]}
{"op":"mcm","clk":"5346755781","pt":1646096128967,"mc":[{"id":"1.195395450","rc":[{"atb":[[3.3,13.4]],"id":41360966}],"con":true,"img":false}]}
{"op":"mcm","clk":"5346755784","pt":1646096129068,"mc":[{"id":"1.195395450","rc":[{"atb":[[3.35,26.68],[3.45,15.07],[3.2,0]],"id":25760990}],"con":true,"img":false}]}
{"op":"mcm","clk":"5346755789","pt":1646096129274,"mc":[{"id":"1.195395450","rc":[{"atb":[[3.4,0]],"id":25760990}],"con":true,"img":false}]}
{"op":"mcm","clk":"5346755800","pt":1646096129633,"mc":[{"id":"1.195395450","rc":[{"atb":[[3.6,35.32],[3.4,2.5]],"id":37495442}],"con":true,"img":false}]}
{"op":"mcm","clk":"5346755820","pt":1646096130148,"mc":[{"id":"1.195395450","rc":[{"atb":[[2.72,29.79]],"id":37495442},{"atl":[[11,30.07]],"id":37495442}],"con":true,"img":false}]}
{"op":"mcm","clk":"5346755826","pt":1646096130250,"mc":[{"id":"1.195395450","rc":[{"atb":[[2.42,0]],"id":37495442},{"atl":[[13,14.08]],"id":37495442}],"con":true,"img":false}]}
{"op":"mcm","clk":"5346755853","pt":1646096130867,"mc":[{"id":"1.195395450","rc":[{"atb":[[3.55,0]],"id":37495442},{"atb":[[3.1,14.68]],"id":40494151}],"con":true,"img":false}]}
{"op":"mcm","clk":"5346755857","pt":1646096130970,"mc":[{"id":"1.195395450","rc":[{"atb":[[3.6,17.66],[3.4,44.17]],"id":37495442}],"con":true,"img":false}]}
{"op":"mcm","clk":"5346755865","pt":1646096131123,"mc":[{"id":"1.195395450","rc":[{"atb":[[3.6,0]],"id":37495442}],"con":true,"img":false}]}
{"op":"mcm","clk":"5346755870","pt":1646096131227,"mc":[{"id":"1.195395450","rc":[{"atb":[[3.5,8.65]],"id":37495442}],"con":true,"img":false}]}
{"op":"mcm","clk":"5346755877","pt":1646096131430,"mc":[{"id":"1.195395450","rc":[{"atb":[[3.4,106.66]],"id":37495442}],"con":true,"img":false}]}
{"op":"mcm","clk":"5346755882","pt":1646096131534,"mc":[{"id":"1.195395450","rc":[{"atb":[[3.45,0]],"id":37495442}],"con":true,"img":false}]}
{"op":"mcm","clk":"5346755933","pt":1646096132774,"mc":[{"id":"1.195395450","rc":[{"atb":[[3.3,0]],"id":41360966}],"con":true,"img":false}]}
{"op":"mcm","clk":"5346755977","pt":1646096134158,"mc":[{"id":"1.195395450","rc":[{"atl":[[8.2,24.56]],"id":40494151}],"con":true,"img":false}]}
{"op":"mcm","clk":"5346755981","pt":1646096134260,"mc":[{"id":"1.195395450","rc":[{"atl":[[8,13.9]],"id":40494151}],"con":true,"img":false}]}
{"op":"mcm","clk":"5346755990","pt":1646096134567,"mc":[{"id":"1.195395450","rc":[{"atb":[[3.55,12.09]],"id":37495442}],"con":true,"img":false}]}
{"op":"mcm","clk":"5346755994","pt":1646096134670,"mc":[{"id":"1.195395450","rc":[{"atb":[[3.6,15.08]],"id":37495442},{"atb":[[3.55,6.19]],"id":41360966},{"atb":[[3.1,18.22]],"id":40494151}],"con":true,"img":false}]}
{"op":"mcm","clk":"5346756000","pt":1646096134876,"mc":[{"id":"1.195395450","rc":[{"atb":[[3.5,35.52],[3.4,44.17]],"id":37495442}],"con":true,"img":false}]}
{"op":"mcm","clk":"5346756024","pt":1646096135954,"mc":[{"id":"1.195395450","rc":[{"atb":[[3.35,2.5],[3.15,38.18]],"id":25760990}],"con":true,"img":false}]}
{"op":"mcm","clk":"5346756088","pt":1646096137658,"mc":[{"id":"1.195395450","rc":[{"atl":[[10,13.66]],"id":37495442},{"atb":[[3.35,0],[2.98,0],[3.2,5],[3.4,2.5],[3.15,33.18]],"id":25760990}],"con":true,"img":false}]}
{"op":"mcm","clk":"5346756092","pt":1646096137760,"mc":[{"id":"1.195395450","rc":[{"atb":[[3.6,30.16],[3.4,2.5]],"id":37495442},{"atl":[[10.5,0]],"id":37495442},{"atl":[[8,0.07],[7.6,17.65]],"id":41360966}],"con":true,"img":false}]}
{"op":"mcm","clk":"5346756097","pt":1646096137863,"mc":[{"id":"1.195395450","rc":[{"atl":[[11,0],[11.5,29.36],[12.5,0],[13.5,0]],"id":37495442}],"con":true,"img":false}]}
{"op":"mcm","clk":"5346756113","pt":1646096138273,"mc":[{"id":"1.195395450","rc":[{"atb":[[3.55,0]],"id":37495442}],"con":true,"img":false}]}
{"op":"mcm","clk":"5346756120","pt":1646096138484,"mc":[{"id":"1.195395450","rc":[{"atb":[[3.4,67.68],[3.5,0]],"id":37495442}],"con":true,"img":false}]}
{"op":"mcm","clk":"5346756131","pt":1646096138638,"mc":[{"id":"1.195395450","rc":[{"atb":[[3.55,27.31]],"id":41360966}],"con":true,"img":false}]}
{"op":"mcm","clk":"5346756139","pt":1646096138844,"mc":[{"id":"1.195395450","rc":[{"atb":[[3.45,2.5]],"id":41360966}],"con":true,"img":false}]}
{"op":"mcm","clk":"5346756142","pt":1646096138948,"mc":[{"id":"1.195395450","rc":[{"atl":[[5.1,0],[5.2,53.57]],"id":40995914},{"atl":[[7.6,12.12],[7.8,2.94]],"id":40494151}],"con":true,"img":false}]}
{"op":"mcm","clk":"5346756147","pt":1646096139050,"mc":[{"id":"1.195395450","rc":[{"atl":[[8,56.21],[8.2,0.07]],"id":40494151},{"atb":[[2.8,49.46],[2.7,0]],"id":25760990}],"con":true,"img":false}]}
{"op":"mcm","clk":"5346756161","pt":1646096139458,"mc":[{"id":"1.195395450","rc":[{"atb":[[1.85,0],[1.86,23.26]],"id":41962160}],"con":true,"img":false}]}
{"op":"mcm","clk":"5346756196","pt":1646096140534,"mc":[{"id":"1.195395450","rc":[{"atb":[[3.1,22.2]],"id":40494151}],"con":true,"img":false}]}
