{"op":"mcm","clk":"5305619445","pt":1646080581435,"mc":[{"id":"1.195395428","marketDefinition":{"bspMarket":true,"turnInPlayEnabled":false,"persistenceEnabled":false,"marketBaseRate":7.0,"eventId":"31270458","eventTypeId":"4339","numberOfWinners":2,"bettingType":"ODDS","marketType":"PLACE","marketTime":"2022-03-01T03:14:00.000Z","suspendTime":"2022-03-01T03:14:00.000Z","bspReconciled":false,"complete":true,"inPlay":false,"crossMatching":false,"runnersVoidable":false,"numberOfActiveRunners":7,"betDelay":0,"status":"OPEN","runners":[{"status":"ACTIVE","sortPriority":1,"id":43154456,"name":"1. Buckle Up Zion"},{"status":"ACTIVE","sortPriority":2,"id":43154457,"name":"2. Rambo Bobbie"},{"status":"ACTIVE","sortPriority":3,"id":39979946,"name":"3. Marshall Giblet"},{"status":"ACTIVE","sortPriority":4,"id":38407646,"name":"4. Hiccup Gus"},{"status":"ACTIVE","sortPriority":5,"id":42130949,"name":"5. Into The Fire"},{"status":"ACTIVE","sortPriority":6,"id":37279191,"name":"7. Shiffrin"},{"status":"ACTIVE","sortPriority":7,"id":36087680,"name":"8. White Poison"}],"regulators":["MR_INT"],"venue":"Devonport","countryCode":"AU","discountAllowed":true,"timezone":"Australia/Sydney","openDate":"2022-03-01T02:00:00.000Z","version":4380714808,"name":"To Be Placed","eventName":"Devonport (AUS) 1st Mar"},"rc":[],"con":true,"img":false}]}
{"op":"mcm","clk":"5305743101","pt":1646082026907,"mc":[{"id":"1.195395428","rc":[{"atb":[[2,120.81],[1.95,127.17],[2.1,54.91]],"id":38407646},{"atl":[[16.5,3.1],[8.6,3.16],[5.3,2.79],[11.5,2.28],[6.6,2.14]],"id":38407646},{"spn":3.7,"spf":"NaN","id":38407646},{"atb":[[2,120.81],[1.95,127.17],[2.1,54.91]],"id":43154456},{"atl":[[16.5,3.1],[8.6,3.16],[5.3,2.79],[11.5,2.28],[6.6,2.14]],"id":43154456},{"spn":3.7,"spf":"NaN","id":43154456},{"atb":[[9.2,14.73],[10.5,6.36],[8.2,16.78]],"id":42130949},{"atl":[[260,0.09],[80,0.15],[160,0.07],[360,0.06],[460,0.1]],"id":42130949},{"spn":45.25,"spf":"NaN","id":42130949},{"atb":[[1.2,604.09],[1.25,241.63],[1.15,805.45]],"id":43154457},{"atl":[[3.6,18.48],[3.1,11.44],[2.44,8.34],[2.64,7.32],[2.84,13.06]],"id":43154457},{"spn":1.84,"spf":"NaN","id":43154457},{"atb":[[9.2,14.73],[10.5,6.36],[8.2,16.78]],"id":39979946},{"atl":[[260,0.09],[80,0.15],[160,0.07],[360,0.06],[460,0.1]],"id":39979946},{"spn":45.25,"spf":"NaN","id":39979946},{"atb":[[5,30.2],[5.5,26.84],[6,12.08]],"id":37279191},{"atl":[[19.5,0.64],[95,0.25],[190,0.25],[48,0.5],[29,0.42]],"id":37279191},{"spn":12.75,"spf":"NaN","id":37279191},{"atb":[[1.2,604.09],[1.25,483.27],[1.3,201.36]],"id":36087680},{"atl":[[2.54,7.8],[3.85,16.86],[2.74,6.9],[3.35,10.22],[2.94,12.39]],"id":36087680},{"spn":1.92,"spf":"NaN","id":36087680}],"con":true,"img":false}]}
{"op":"mcm","clk":"5305747392","pt":1646082083712,"mc":[{"id":"1.195395428","rc":[{"atb":[[2,0],[1.95,0],[2.1,0]],"id":38407646},{"atl":[[16.5,0],[8.6,0],[5.3,0],[11.5,0],[6.6,0]],"id":38407646},{"atb":[[2,0],[1.95,0],[2.1,0]],"id":43154456},{"atl":[[16.5,0],[8.6,0],[5.3,0],[11.5,0],[6.6,0]],"id":43154456},{"atb":[[9.2,0],[10.5,0],[8.2,0]],"id":42130949},{"atl":[[260,0],[80,0],[160,0],[360,0],[460,0]],"id":42130949},{"atb":[[1.2,0],[1.25,0],[1.15,0]],"id":43154457},{"atl":[[3.6,0],[3.1,0],[2.44,0],[2.64,0],[2.84,0]],"id":43154457},{"atb":[[9.2,0],[10.5,0],[8.2,0]],"id":39979946},{"atl":[[260,0],[80,0],[160,0],[360,0],[460,0]],"id":39979946},{"atb":[[5,0],[5.5,0],[6,0]],"id":37279191},{"atl":[[19.5,0],[95,0],[190,0],[48,0],[29,0]],"id":37279191},{"atb":[[1.2,0],[1.25,0],[1.3,0]],"id":36087680},{"atl":[[2.54,0],[3.85,0],[2.74,0],[3.35,0],[2.94,0]],"id":36087680}],"con":true,"img":false}]}
{"op":"mcm","clk":"5305747684","pt":1646082087094,"mc":[{"id":"1.195395428","rc":[{"atb":[[2,120.81],[1.95,127.17],[2.1,54.91]],"id":38407646},{"atl":[[16.5,3.1],[8.6,3.16],[5.3,2.79],[11.5,2.28],[6.6,2.14]],"id":38407646},{"atb":[[2,120.81],[1.95,127.17],[2.1,54.91]],"id":43154456},{"atl":[[16.5,3.1],[8.6,3.16],[5.3,2.79],[11.5,2.28],[6.6,2.14]],"id":43154456},{"atb":[[9.2,14.73],[10.5,6.36],[8.2,16.78]],"id":42130949},{"atl":[[260,0.09],[80,0.15],[160,0.07],[360,0.06],[460,0.1]],"id":42130949},{"atb":[[1.2,604.09],[1.25,241.63],[1.15,805.45]],"id":43154457},{"atl":[[3.6,18.48],[3.1,11.44],[2.44,8.34],[2.64,7.32],[2.84,13.06]],"id":43154457},{"atb":[[9.2,14.73],[10.5,6.36],[8.2,16.78]],"id":39979946},{"atl":[[260,0.09],[80,0.15],[160,0.07],[360,0.06],[460,0.1]],"id":39979946},{"atb":[[5,30.2],[5.5,26.84],[6,12.08]],"id":37279191},{"atl":[[19.5,0.64],[95,0.25],[190,0.25],[48,0.5],[29,0.42]],"id":37279191},{"atb":[[1.2,604.09],[1.25,483.27],[1.3,201.36]],"id":36087680},{"atl":[[2.54,7.8],[3.85,16.86],[2.74,6.9],[3.35,10.22],[2.94,12.39]],"id":36087680}],"con":true,"img":false}]}
{"op":"mcm","clk":"5305928461","pt":1646084873124,"mc":[{"id":"1.195395428","rc":[{"atb":[[9.2,0],[10.5,0],[8.2,0]],"id":42130949},{"atl":[[260,0],[80,0],[160,0],[360,0],[460,0]],"id":42130949},{"spn":"NaN","spf":"NaN","id":42130949},{"atb":[[9.2,0],[10.5,0],[8.2,0]],"id":39979946},{"atl":[[260,0],[80,0],[160,0],[360,0],[460,0]],"id":39979946},{"spn":"NaN","spf":"NaN","id":39979946},{"atb":[[1.2,0],[1.25,0],[1.3,0]],"id":36087680},{"atl":[[2.54,0],[3.85,0],[2.74,0],[3.35,0],[2.94,0]],"id":36087680},{"spn":"NaN","spf":"NaN","id":36087680}],"con":true,"img":false}]}
{"op":"mcm","clk":"5305928630","pt":1646084878445,"mc":[{"id":"1.195395428","rc":[{"atb":[[9.2,14.73],[10.5,6.36],[8.2,16.78]],"id":42130949},{"atl":[[260,0.09],[80,0.15],[160,0.07],[360,0.06],[460,0.1]],"id":42130949},{"atb":[[9.2,14.73],[10.5,6.36],[8.2,16.78]],"id":39979946},{"atl":[[260,0.09],[80,0.15],[160,0.07],[360,0.06],[460,0.1]],"id":39979946},{"atb":[[5,60.4],[5.5,53.69],[6,24.16]],"id":37279191},{"atl":[[19.5,1.29],[95,0.5],[190,0.5],[48,1.01],[29,0.85]],"id":37279191},{"atb":[[1.2,604.09],[1.25,241.63],[1.15,805.45]],"id":36087680},{"atl":[[3.6,18.48],[3.1,11.44],[2.44,8.34],[2.64,7.32],[2.84,13.06]],"id":36087680}],"con":true,"img":false}]}
{"op":"mcm","clk":"5305990536","pt":1646086602700,"mc":[{"id":"1.195395428","marketDefinition":{"bspMarket":true,"turnInPlayEnabled":false,"persistenceEnabled":false,"marketBaseRate":7.0,"eventId":"31270458","eventTypeId":"4339","numberOfWinners":2,"bettingType":"ODDS","marketType":"PLACE","marketTime":"2022-03-01T03:14:00.000Z","suspendTime":"2022-03-01T03:14:00.000Z","bspReconciled":false,"complete":true,"inPlay":false,"crossMatching":false,"runnersVoidable":false,"numberOfActiveRunners":7,"betDelay":0,"status":"OPEN","runners":[{"status":"ACTIVE","sortPriority":1,"id":43154456,"name":"1. Buckle Up Zion"},{"status":"ACTIVE","sortPriority":2,"id":43154457,"name":"2. Rambo Bobbie"},{"status":"ACTIVE","sortPriority":3,"id":39979946,"name":"3. Marshall Giblet"},{"status":"ACTIVE","sortPriority":4,"id":38407646,"name":"4. Hiccup Gus"},{"status":"ACTIVE","sortPriority":5,"id":42130949,"name":"5. Into The Fire"},{"status":"ACTIVE","sortPriority":6,"id":37279191,"name":"7. Shiffrin"},{"status":"ACTIVE","sortPriority":7,"id":36087680,"name":"8. White Poison"}],"regulators":["MR_INT"],"venue":"Devonport","countryCode":"AU","discountAllowed":true,"timezone":"Australia/Sydney","openDate":"2022-03-01T02:00:00.000Z","version":4380714808,"name":"To Be Placed","eventName":"Devonport (AUS) 1st Mar"},"rc":[{"atb":[[2,120.79],[1.95,127.15],[2.1,54.9]],"id":38407646},{"atl":[[16.5,3.1],[8.6,3.16],[5.3,2.79],[11.5,2.28],[6.6,2.14]],"id":38407646},{"spn":3.7,"spf":"NaN","id":38407646},{"atb":[[2,120.79],[1.95,127.15],[2.1,54.9]],"id":43154456},{"atl":[[16.5,3.1],[8.6,3.16],[5.3,2.79],[11.5,2.28],[6.6,2.14]],"id":43154456},{"spn":3.7,"spf":"NaN","id":43154456},{"atb":[[9.2,14.73],[10.5,6.35],[8.2,16.77]],"id":42130949},{"atl":[[260,0.09],[80,0.15],[160,0.07],[360,0.06],[460,0.1]],"id":42130949},{"spn":45.25,"spf":"NaN","id":42130949},{"atb":[[1.2,603.99],[1.25,241.59],[1.15,805.32]],"id":43154457},{"atl":[[3.6,18.48],[3.1,11.44],[2.44,8.34],[2.64,7.32],[2.84,13.05]],"id":43154457},{"spn":1.84,"spf":"NaN","id":43154457},{"atb":[[9.2,14.73],[10.5,6.35],[8.2,16.77]],"id":39979946},{"atl":[[260,0.09],[80,0.15],[160,0.07],[360,0.06],[460,0.1]],"id":39979946},{"spn":45.25,"spf":"NaN","id":39979946},{"atb":[[5,60.39],[5.5,53.68],[6,24.15]],"id":37279191},{"atl":[[19.5,1.29],[95,0.5],[190,0.5],[48,1.01],[29,0.85]],"id":37279191},{"spn":12.75,"spf":"NaN","id":37279191},{"atb":[[1.2,603.99],[1.25,241.59],[1.15,805.32]],"id":36087680},{"atl":[[3.6,18.48],[3.1,11.44],[2.44,8.34],[2.64,7.32],[2.84,13.05]],"id":36087680},{"spn":1.84,"spf":"NaN","id":36087680}],"con":true,"img":true}]}
{"op":"mcm","clk":"5306008484","pt":1646086988740,"mc":[{"id":"1.195395428","marketDefinition":{"bspMarket":true,"turnInPlayEnabled":false,"persistenceEnabled":false,"marketBaseRate":7.0,"eventId":"31270458","eventTypeId":"4339","numberOfWinners":2,"bettingType":"ODDS","marketType":"PLACE","marketTime":"2022-03-01T03:14:00.000Z","suspendTime":"2022-03-01T03:14:00.000Z","bspReconciled":false,"complete":true,"inPlay":false,"crossMatching":false,"runnersVoidable":false,"numberOfActiveRunners":7,"betDelay":0,"status":"SUSPENDED","runners":[{"status":"ACTIVE","sortPriority":1,"id":43154456,"name":"1. Buckle Up Zion"},{"status":"ACTIVE","sortPriority":2,"id":43154457,"name":"2. Rambo Bobbie"},{"status":"ACTIVE","sortPriority":3,"id":39979946,"name":"3. Marshall Giblet"},{"status":"ACTIVE","sortPriority":4,"id":38407646,"name":"4. Hiccup Gus"},{"status":"ACTIVE","sortPriority":5,"id":42130949,"name":"5. Into The Fire"},{"status":"ACTIVE","sortPriority":6,"id":37279191,"name":"7. Shiffrin"},{"status":"ACTIVE","sortPriority":7,"id":36087680,"name":"8. White Poison"}],"regulators":["MR_INT"],"venue":"Devonport","countryCode":"AU","discountAllowed":true,"timezone":"Australia/Sydney","openDate":"2022-03-01T02:00:00.000Z","version":4380876479,"name":"To Be Placed","eventName":"Devonport (AUS) 1st Mar"},"rc":[],"con":true,"img":false}]}
{"op":"mcm","clk":"5306009258","pt":1646087009064,"mc":[{"id":"1.195395428","marketDefinition":{"bspMarket":true,"turnInPlayEnabled":false,"persistenceEnabled":false,"marketBaseRate":7.0,"eventId":"31270458","eventTypeId":"4339","numberOfWinners":2,"bettingType":"ODDS","marketType":"PLACE","marketTime":"2022-03-01T03:14:00.000Z","suspendTime":"2022-03-01T03:14:00.000Z","bspReconciled":false,"complete":true,"inPlay":false,"crossMatching":false,"runnersVoidable":false,"numberOfActiveRunners":6,"betDelay":0,"status":"SUSPENDED","runners":[{"status":"ACTIVE","sortPriority":1,"id":43154456,"name":"1. Buckle Up Zion"},{"status":"ACTIVE","sortPriority":2,"id":43154457,"name":"2. Rambo Bobbie"},{"status":"ACTIVE","sortPriority":3,"id":38407646,"name":"4. Hiccup Gus"},{"status":"ACTIVE","sortPriority":4,"id":42130949,"name":"5. Into The Fire"},{"status":"ACTIVE","sortPriority":5,"id":37279191,"name":"7. Shiffrin"},{"status":"ACTIVE","sortPriority":6,"id":36087680,"name":"8. White Poison"},{"status":"REMOVED","sortPriority":7,"removalDate":"2022-02-28T22:23:28.000Z","id":39979946,"name":"3. Marshall Giblet"}],"regulators":["MR_INT"],"venue":"Devonport","countryCode":"AU","discountAllowed":true,"timezone":"Australia/Sydney","openDate":"2022-03-01T02:00:00.000Z","version":4380876825,"name":"To Be Placed","eventName":"Devonport (AUS) 1st Mar"},"rc":[],"con":true,"img":false}]}
{"op":"mcm","clk":"5306009258","pt":1646087009064,"mc":[{"id":"1.195395428","rc":[{"atb":[[2,0],[1.95,0],[2.1,0]],"id":38407646},{"atl":[[16.5,0],[8.6,0],[5.3,0],[11.5,0],[6.6,0]],"id":38407646},{"atb":[[2,0],[1.95,0],[2.1,0]],"id":43154456},{"atl":[[16.5,0],[8.6,0],[5.3,0],[11.5,0],[6.6,0]],"id":43154456},{"atb":[[9.2,0],[10.5,0],[8.2,0]],"id":42130949},{"atl":[[260,0],[80,0],[160,0],[360,0],[460,0]],"id":42130949},{"atb":[[1.2,0],[1.25,0],[1.15,0]],"id":43154457},{"atl":[[3.6,0],[3.1,0],[2.44,0],[2.64,0],[2.84,0]],"id":43154457},{"atb":[[9.2,0],[10.5,0],[8.2,0]],"id":39979946},{"atl":[[260,0],[80,0],[160,0],[360,0],[460,0]],"id":39979946},{"atb":[[5,0],[5.5,0],[6,0]],"id":37279191},{"atl":[[19.5,0],[95,0],[190,0],[48,0],[29,0]],"id":37279191},{"atb":[[1.2,0],[1.25,0],[1.15,0]],"id":36087680},{"atl":[[3.6,0],[3.1,0],[2.44,0],[2.64,0],[2.84,0]],"id":36087680}],"con":true,"img":false}]}
{"op":"mcm","clk":"5306009521","pt":1646087015788,"mc":[{"id":"1.195395428","marketDefinition":{"bspMarket":true,"turnInPlayEnabled":false,"persistenceEnabled":false,"marketBaseRate":7.0,"eventId":"31270458","eventTypeId":"4339","numberOfWinners":2,"bettingType":"ODDS","marketType":"PLACE","marketTime":"2022-03-01T03:14:00.000Z","suspendTime":"2022-03-01T03:14:00.000Z","bspReconciled":false,"complete":true,"inPlay":false,"crossMatching":false,"runnersVoidable":false,"numberOfActiveRunners":6,"betDelay":0,"status":"OPEN","runners":[{"status":"ACTIVE","sortPriority":1,"id":43154456,"name":"1. Buckle Up Zion"},{"status":"ACTIVE","sortPriority":2,"id":43154457,"name":"2. Rambo Bobbie"},{"status":"ACTIVE","sortPriority":3,"id":38407646,"name":"4. Hiccup Gus"},{"status":"ACTIVE","sortPriority":4,"id":42130949,"name":"5. Into The Fire"},{"status":"ACTIVE","sortPriority":5,"id":37279191,"name":"7. Shiffrin"},{"status":"ACTIVE","sortPriority":6,"id":36087680,"name":"8. White Poison"},{"status":"REMOVED","sortPriority":7,"removalDate":"2022-02-28T22:23:28.000Z","id":39979946,"name":"3. Marshall Giblet"}],"regulators":["MR_INT"],"venue":"Devonport","countryCode":"AU","discountAllowed":true,"timezone":"Australia/Sydney","openDate":"2022-03-01T02:00:00.000Z","version":4380876838,"name":"To Be Placed","eventName":"Devonport (AUS) 1st Mar"},"rc":[],"con":true,"img":false}]}
{"op":"mcm","clk":"5306475716","pt":1646099116225,"mc":[{"id":"1.195395428","rc":[{"atb":[[1.94,46.03],[1.77,76.38]],"id":38407646},{"atl":[[6.8,7.45],[7.6,8.91]],"id":38407646},{"spn":4.37,"spf":"NaN","id":38407646},{"atb":[[1.94,46.03],[1.77,70.59]],"id":43154456},{"atl":[[6.8,7.45],[7.6,8.23]],"id":43154456},{"spn":4.37,"spf":"NaN","id":43154456},{"atb":[[11,5.37],[13,3.6]],"id":42130949},{"atl":[[130,2.7],[120,0.36]],"id":42130949},{"spn":66.5,"spf":"NaN","id":42130949},{"atb":[[1.25,220.67],[1.3,86.07]],"id":43154457},{"atl":[[2.88,23.01],[3.25,24.51]],"id":43154457},{"spn":2.09,"spf":"NaN","id":43154457},{"atb":[[5.1,14.57],[6,8.65]],"id":37279191},{"atl":[[34,2.7],[36,2.7]],"id":37279191},{"spn":20.0,"spf":"NaN","id":37279191},{"atb":[[1.26,234.54],[1.32,84.77]],"id":36087680},{"atl":[[3.35,25.95],[3,21.63]],"id":36087680},{"spn":2.16,"spf":"NaN","id":36087680}],"con":true,"img":false}]}
{"op":"mcm","clk":"5306557164","pt":1646100856442,"mc":[{"id":"1.195395428","rc":[{"atb":[[1.94,46.05],[1.77,76.41],[1.05,122.42]],"id":38407646},{"atl":[[9,12.5],[6.8,7.46],[7.6,8.91]],"id":38407646},{"atb":[[1.94,46.05],[1.77,70.62],[1.05,116.62]],"id":43154456},{"atl":[[9,12.5],[6.8,7.46],[7.6,8.24]],"id":43154456},{"atb":[[11,5.37],[6,8.98],[13,3.6]],"id":42130949},{"atl":[[130,2.7],[120,0.36]],"id":42130949},{"atb":[[1.25,220.76],[1.3,86.11]],"id":43154457},{"atl":[[5.1,24.39],[2.88,23.02],[3.25,24.52]],"id":43154457},{"atb":[[5.1,14.58],[6,8.65],[3.25,23.23]],"id":37279191},{"atl":[[34,2.7],[36,2.7],[40,2.56]],"id":37279191},{"atb":[[1.26,234.64],[1.32,84.81]],"id":36087680},{"atl":[[6.4,18.52],[3.35,25.96],[3,21.64]],"id":36087680}],"con":true,"img":false}]}
{"op":"mcm","clk":"5306559833","pt":1646100908503,"mc":[{"id":"1.195395428","rc":[{"atl":[[120,0]],"id":42130949}],"con":true,"img":false}]}
{"op":"mcm","clk":"5306559836","pt":1646100908606,"mc":[{"id":"1.195395428","rc":[{"atl":[[110,0.36]],"id":42130949}],"con":true,"img":false}]}
{"op":"mcm","clk":"5306566582","pt":1646101056821,"mc":[{"id":"1.195395428","rc":[{"atb":[[1.05,0]],"id":38407646},{"atl":[[9,0]],"id":38407646},{"atb":[[1.05,0]],"id":43154456},{"atl":[[9,0]],"id":43154456},{"atb":[[6,0]],"id":42130949},{"spn":61.5,"spf":"NaN","id":42130949},{"atl":[[5.1,0]],"id":43154457},{"atb":[[3.25,0]],"id":37279191},{"atl":[[40,0]],"id":37279191},{"atl":[[6.4,0]],"id":36087680}],"con":true,"img":false}]}
{"op":"mcm","clk":"5306568711","pt":1646101103173,"mc":[{"id":"1.195395428","rc":[{"atl":[[6.8,0]],"id":38407646},{"atl":[[6.8,0]],"id":43154456},{"atl":[[2.88,0]],"id":43154457},{"atl":[[34,0]],"id":37279191},{"atl":[[3,0]],"id":36087680}],"con":true,"img":false}]}
{"op":"mcm","clk":"5306568715","pt":1646101103277,"mc":[{"id":"1.195395428","rc":[{"atl":[[6.2,7.46]],"id":38407646},{"atl":[[6.2,7.46]],"id":43154456},{"atl":[[2.68,23.02]],"id":43154457},{"atl":[[30,2.7]],"id":37279191},{"atl":[[2.78,21.64]],"id":36087680}],"con":true,"img":false}]}
{"op":"mcm","clk":"5306570693","pt":1646101145347,"mc":[{"id":"1.195395428","marketDefinition":{"bspMarket":true,"turnInPlayEnabled":false,"persistenceEnabled":false,"marketBaseRate":7.0,"eventId":"31270458","eventTypeId":"4339","numberOfWinners":2,"bettingType":"ODDS","marketType":"PLACE","marketTime":"2022-03-01T03:42:00.000Z","suspendTime":"2022-03-01T03:42:00.000Z","bspReconciled":false,"complete":true,"inPlay":false,"crossMatching":false,"runnersVoidable":false,"numberOfActiveRunners":6,"betDelay":0,"status":"OPEN","runners":[{"status":"ACTIVE","sortPriority":1,"id":43154456,"name":"1. Buckle Up Zion"},{"status":"ACTIVE","sortPriority":2,"id":43154457,"name":"2. Rambo Bobbie"},{"status":"ACTIVE","sortPriority":3,"id":38407646,"name":"4. Hiccup Gus"},{"status":"ACTIVE","sortPriority":4,"id":42130949,"name":"5. Into The Fire"},{"status":"ACTIVE","sortPriority":5,"id":37279191,"name":"7. Shiffrin"},{"status":"ACTIVE","sortPriority":6,"id":36087680,"name":"8. White Poison"},{"status":"REMOVED","sortPriority":7,"removalDate":"2022-02-28T22:23:28.000Z","id":39979946,"name":"3. Marshall Giblet"}],"regulators":["MR_INT"],"venue":"Devonport","countryCode":"AU","discountAllowed":true,"timezone":"Australia/Sydney","openDate":"2022-03-01T02:00:00.000Z","version":4381058467,"name":"To Be Placed","eventName":"Devonport (AUS) 1st Mar"},"rc":[],"con":true,"img":false}]}
{"op":"mcm","clk":"5306653034","pt":1646102802687,"mc":[{"id":"1.195395428","marketDefinition":{"bspMarket":true,"turnInPlayEnabled":false,"persistenceEnabled":false,"marketBaseRate":7.0,"eventId":"31270458","eventTypeId":"4339","numberOfWinners":2,"bettingType":"ODDS","marketType":"PLACE","marketTime":"2022-03-01T03:42:00.000Z","suspendTime":"2022-03-01T03:42:00.000Z","bspReconciled":false,"complete":true,"inPlay":false,"crossMatching":false,"runnersVoidable":false,"numberOfActiveRunners":6,"betDelay":0,"status":"OPEN","runners":[{"status":"ACTIVE","sortPriority":1,"id":43154456,"name":"1. Buckle Up Zion"},{"status":"ACTIVE","sortPriority":2,"id":43154457,"name":"2. Rambo Bobbie"},{"status":"ACTIVE","sortPriority":3,"id":38407646,"name":"4. Hiccup Gus"},{"status":"ACTIVE","sortPriority":4,"id":42130949,"name":"5. Into The Fire"},{"status":"ACTIVE","sortPriority":5,"id":37279191,"name":"7. Shiffrin"},{"status":"ACTIVE","sortPriority":6,"id":36087680,"name":"8. White Poison"},{"status":"REMOVED","sortPriority":7,"removalDate":"2022-02-28T22:23:28.000Z","id":39979946,"name":"3. Marshall Giblet"}],"regulators":["MR_INT"],"venue":"Devonport","countryCode":"AU","discountAllowed":true,"timezone":"Australia/Sydney","openDate":"2022-03-01T02:00:00.000Z","version":4381058467,"name":"To Be Placed","eventName":"Devonport (AUS) 1st Mar"},"rc":[{"atb":[[1.94,46.05],[1.77,76.41]],"id":38407646},{"atl":[[6.2,7.46],[7.6,8.91]],"id":38407646},{"spn":4.07,"spf":"NaN","id":38407646},{"atb":[[1.94,46.05],[1.77,70.62]],"id":43154456},{"atl":[[6.2,7.46],[7.6,8.24]],"id":43154456},{"spn":4.07,"spf":"NaN","id":43154456},{"atb":[[11,5.37],[13,3.6]],"id":42130949},{"atl":[[130,2.7],[110,0.36]],"id":42130949},{"spn":61.5,"spf":"NaN","id":42130949},{"atb":[[1.25,220.76],[1.3,86.11]],"id":43154457},{"atl":[[3.25,24.52],[2.68,23.02]],"id":43154457},{"spn":1.99,"spf":"NaN","id":43154457},{"atb":[[5.1,14.58],[6,8.65]],"id":37279191},{"atl":[[36,2.7],[30,2.7]],"id":37279191},{"spn":18.0,"spf":"NaN","id":37279191},{"atb":[[1.26,234.64],[1.32,84.81]],"id":36087680},{"atl":[[3.35,25.96],[2.78,21.64]],"id":36087680},{"spn":2.05,"spf":"NaN","id":36087680}],"con":true,"img":true}]}
{"op":"mcm","clk":"5306678524","pt":1646103383387,"mc":[{"id":"1.195395428","marketDefinition":{"bspMarket":true,"turnInPlayEnabled":false,"persistenceEnabled":false,"marketBaseRate":7.0,"eventId":"31270458","eventTypeId":"4339","numberOfWinners":2,"bettingType":"ODDS","marketType":"PLACE","marketTime":"2022-03-01T04:22:00.000Z","suspendTime":"2022-03-01T04:22:00.000Z","bspReconciled":false,"complete":true,"inPlay":false,"crossMatching":false,"runnersVoidable":false,"numberOfActiveRunners":6,"betDelay":0,"status":"OPEN","runners":[{"status":"ACTIVE","sortPriority":1,"id":43154456,"name":"1. Buckle Up Zion"},{"status":"ACTIVE","sortPriority":2,"id":43154457,"name":"2. Rambo Bobbie"},{"status":"ACTIVE","sortPriority":3,"id":38407646,"name":"4. Hiccup Gus"},{"status":"ACTIVE","sortPriority":4,"id":42130949,"name":"5. Into The Fire"},{"status":"ACTIVE","sortPriority":5,"id":37279191,"name":"7. Shiffrin"},{"status":"ACTIVE","sortPriority":6,"id":36087680,"name":"8. White Poison"},{"status":"REMOVED","sortPriority":7,"removalDate":"2022-02-28T22:23:28.000Z","id":39979946,"name":"3. Marshall Giblet"}],"regulators":["MR_INT"],"venue":"Devonport","countryCode":"AU","discountAllowed":true,"timezone":"Australia/Sydney","openDate":"2022-03-01T02:00:00.000Z","version":4381084013,"name":"To Be Placed","eventName":"Devonport (AUS) 1st Mar"},"rc":[],"con":true,"img":false}]}
{"op":"mcm","clk":"5306693489","pt":1646103822593,"mc":[{"id":"1.195395428","rc":[{"atb":[[2,120.12],[1.95,126.44],[2.1,54.6]],"id":38407646},{"atl":[[8.6,0.56],[5.3,0.12],[6.6,0.09]],"id":38407646},{"spn":3.7,"spf":"NaN","id":38407646},{"atb":[[2,120.12],[1.95,126.44],[2.1,54.6]],"id":43154456},{"atl":[[8.6,0.56],[5.3,0.12],[6.6,0.09]],"id":43154456},{"spn":3.7,"spf":"NaN","id":43154456},{"atb":[[9.2,14.64],[10.5,6.32],[8.2,16.68]],"id":42130949},{"atl":[[260,0.01],[80,0],[160,0]],"id":42130949},{"spn":46.5,"spf":"NaN","id":42130949},{"atb":[[1.2,600.61],[1.25,461.01],[1.15,800.82]],"id":43154457},{"atl":[[2.44,0.37],[2.64,0.33],[2.84,2.35]],"id":43154457},{"spn":1.87,"spf":"NaN","id":43154457},{"atb":[[5,30.03],[5.5,26.69],[6,20.66]],"id":37279191},{"atl":[[19.5,0.02],[48,0.09],[29,0.02]],"id":37279191},{"spn":12.75,"spf":"NaN","id":37279191},{"atb":[[1.2,600.61],[1.25,240.24],[1.15,800.82]],"id":36087680},{"atl":[[2.44,0.37],[2.64,0.33],[2.84,2.35]],"id":36087680},{"spn":1.88,"spf":"NaN","id":36087680}],"con":true,"img":false}]}
{"op":"mcm","clk":"5306693670","pt":1646103827405,"mc":[{"id":"1.195395428","rc":[{"atb":[[1.96,35.35]],"id":43154456},{"atb":[[1.21,146.39]],"id":43154457},{"atb":[[1.27,110.25]],"id":36087680}],"con":true,"img":false}]}
{"op":"mcm","clk":"5306695105","pt":1646103863826,"mc":[{"id":"1.195395428","rc":[{"atb":[[1.94,0]],"id":38407646},{"atb":[[1.94,0]],"id":43154456}],"con":true,"img":false}]}
{"op":"mcm","clk":"5306695112","pt":1646103863929,"mc":[{"id":"1.195395428","rc":[{"atb":[[2.12,46.05]],"id":38407646},{"atb":[[2.12,46.05]],"id":43154456}],"con":true,"img":false}]}
{"op":"mcm","clk":"5306695316","pt":1646103868336,"mc":[{"id":"1.195395428","rc":[{"atb":[[1.96,0]],"id":43154456}],"con":true,"img":false}]}
{"op":"mcm","clk":"5306695507","pt":1646103873350,"mc":[{"id":"1.195395428","rc":[{"atb":[[2.02,33.27]],"id":43154456}],"con":true,"img":false}]}
{"op":"mcm","clk":"5306695704","pt":1646103878775,"mc":[{"id":"1.195395428","rc":[{"atb":[[5.1,0]],"id":37279191},{"atb":[[1.26,0]],"id":36087680}],"con":true,"img":false}]}
{"op":"mcm","clk":"5306695707","pt":1646103878877,"mc":[{"id":"1.195395428","rc":[{"atb":[[5.6,14.58]],"id":37279191},{"atb":[[1.28,234.64]],"id":36087680}],"con":true,"img":false}]}
{"op":"mcm","clk":"5306695866","pt":1646103882887,"mc":[{"id":"1.195395428","rc":[{"spn":3.71,"spf":"NaN","id":38407646},{"spn":3.71,"spf":"NaN","id":43154456},{"atb":[[1.27,0]],"id":36087680}],"con":true,"img":false}]}
{"op":"mcm","clk":"5306696032","pt":1646103887650,"mc":[{"id":"1.195395428","rc":[{"atb":[[1.26,118.73]],"id":36087680}],"con":true,"img":false}]}
{"op":"mcm","clk":"5306710354","pt":1646104259687,"mc":[{"id":"1.195395428","rc":[{"atb":[[13,0]],"id":42130949},{"spn":45.5,"spf":"NaN","id":42130949}],"con":true,"img":false}]}
{"op":"mcm","clk":"5306710357","pt":1646104259788,"mc":[{"id":"1.195395428","rc":[{"atb":[[16,3.6]],"id":42130949}],"con":true,"img":false}]}
{"op":"mcm","clk":"5306711597","pt":1646104289211,"mc":[{"id":"1.195395428","rc":[{"atb":[[11,0],[13.5,4.29]],"id":42130949}],"con":true,"img":false}]}
{"op":"mcm","clk":"5306714122","pt":1646104344197,"mc":[{"id":"1.195395428","rc":[{"atb":[[2.02,0]],"id":43154456},{"spn":48.0,"spf":"NaN","id":42130949},{"atb":[[1.21,0]],"id":43154457},{"atb":[[1.26,0]],"id":36087680}],"con":true,"img":false}]}
{"op":"mcm","clk":"5306718707","pt":1646104427560,"mc":[{"id":"1.195395428","rc":[{"atb":[[2,0],[1.95,0],[2.1,0]],"id":38407646},{"atl":[[8.6,0],[5.3,0],[6.6,0]],"id":38407646},{"spn":4.16,"spf":"NaN","id":38407646},{"atb":[[2,0],[1.95,0],[2.1,0]],"id":43154456},{"atl":[[8.6,0],[5.3,0],[6.6,0]],"id":43154456},{"spn":4.16,"spf":"NaN","id":43154456},{"atb":[[9.2,0],[10.5,0],[8.2,0]],"id":42130949},{"atl":[[260,0],[80,0],[160,0]],"id":42130949},{"spn":63.0,"spf":"NaN","id":42130949},{"atb":[[1.2,0],[1.25,220.76],[1.15,0]],"id":43154457},{"atl":[[2.44,0],[2.64,0],[2.84,0]],"id":43154457},{"spn":1.99,"spf":"NaN","id":43154457},{"atb":[[5,0],[5.5,0],[6,8.65]],"id":37279191},{"atl":[[19.5,0],[48,0],[29,0]],"id":37279191},{"spn":18.0,"spf":"NaN","id":37279191},{"atb":[[1.2,0],[1.25,0],[1.15,0]],"id":36087680},{"atl":[[2.44,0],[2.64,0],[2.84,0]],"id":36087680},{"spn":2.05,"spf":"NaN","id":36087680}],"con":true,"img":false}]}
{"op":"mcm","clk":"5306718858","pt":1646104430734,"mc":[{"id":"1.195395428","rc":[{"atb":[[2,120.12],[1.95,126.44],[2.1,54.6]],"id":38407646},{"atl":[[8.6,0.56],[5.3,0.12],[6.6,0.09]],"id":38407646},{"atb":[[2,120.12],[1.95,126.44],[2.1,54.6]],"id":43154456},{"atl":[[8.6,0.56],[5.3,0.12],[6.6,0.09]],"id":43154456},{"atb":[[9.2,14.64],[10.5,6.32],[8.2,16.68]],"id":42130949},{"atl":[[260,0.01],[80,0],[160,0]],"id":42130949},{"atb":[[1.2,600.61],[1.25,461.01],[1.15,800.82]],"id":43154457},{"atl":[[2.44,0.37],[2.64,0.33],[2.84,2.35]],"id":43154457},{"atb":[[5,30.03],[5.5,26.69],[6,20.66]],"id":37279191},{"atl":[[19.5,0.02],[48,0.09],[29,0.02]],"id":37279191},{"atb":[[1.2,600.61],[1.25,240.24],[1.15,800.82]],"id":36087680},{"atl":[[2.44,0.37],[2.64,0.33],[2.84,2.35]],"id":36087680}],"con":true,"img":false}]}
{"op":"mcm","clk":"5306719033","pt":1646104434938,"mc":[{"id":"1.195395428","rc":[{"atb":[[1.03,2.7]],"id":43154457},{"atb":[[1.03,2.7]],"id":36087680}],"con":true,"img":false}]}
{"op":"mcm","clk":"5306719044","pt":1646104435142,"mc":[{"id":"1.195395428","rc":[{"atb":[[1.03,3.24]],"id":43154457},{"atb":[[1.03,3.24]],"id":36087680}],"con":true,"img":false}]}
{"op":"mcm","clk":"5306719051","pt":1646104435345,"mc":[{"id":"1.195395428","rc":[{"atb":[[1.03,0.54]],"id":43154457},{"atb":[[1.03,0.54]],"id":36087680}],"con":true,"img":false}]}
{"op":"mcm","clk":"5306719063","pt":1646104435649,"mc":[{"id":"1.195395428","rc":[{"atb":[[1.03,0]],"id":43154457},{"atb":[[1.03,0]],"id":36087680}],"con":true,"img":false}]}
{"op":"mcm","clk":"5306719067","pt":1646104435752,"mc":[{"id":"1.195395428","rc":[{"atl":[[2.44,0],[2.64,0.16]],"id":43154457},{"trd":[[2.64,0.33],[2.44,0.74]],"ltp":2.64,"tv":1.07,"id":43154457},{"atl":[[2.44,0],[2.64,0.16]],"id":36087680},{"trd":[[2.64,0.33],[2.44,0.74]],"ltp":2.64,"tv":1.07,"id":36087680}],"con":true,"img":false}]}
{"op":"mcm","clk":"5306719251","pt":1646104440461,"mc":[{"id":"1.195395428","rc":[{"atl":[[2.68,0]],"id":43154457}],"con":true,"img":false}]}
{"op":"mcm","clk":"5306719253","pt":1646104440563,"mc":[{"id":"1.195395428","rc":[{"atl":[[3,23.02]],"id":43154457}],"con":true,"img":false}]}
{"op":"mcm","clk":"5306772552","pt":1646105828695,"mc":[{"id":"1.195395428","rc":[{"atb":[[2.14,1.66]],"id":38407646},{"spn":3.72,"spf":"NaN","id":38407646},{"atb":[[2.14,1.66]],"id":43154456},{"spn":3.72,"spf":"NaN","id":43154456},{"spn":48.0,"spf":"NaN","id":42130949},{"spn":1.97,"spf":"NaN","id":43154457},{"spn":12.75,"spf":"NaN","id":37279191},{"spn":1.98,"spf":"NaN","id":36087680}],"con":true,"img":false}]}
{"op":"mcm","clk":"5306774054","pt":1646105877461,"mc":[{"id":"1.195395428","rc":[{"atb":[[16,0]],"id":42130949}],"con":true,"img":false}]}
{"op":"mcm","clk":"5306774056","pt":1646105877562,"mc":[{"id":"1.195395428","rc":[{"atb":[[16.5,3.6]],"id":42130949}],"con":true,"img":false}]}
{"op":"mcm","clk":"5306777545","pt":1646106000415,"mc":[{"id":"1.195395428","rc":[{"atb":[[2.16,7.19]],"id":43154456},{"spn":3.73,"spf":"NaN","id":43154456},{"spn":48.25,"spf":"NaN","id":42130949},{"atb":[[1.33,25.29]],"id":43154457},{"spn":1.98,"spf":"NaN","id":43154457}],"con":true,"img":false}]}
{"op":"mcm","clk":"5306777550","pt":1646106000621,"mc":[{"id":"1.195395428","rc":[{"atb":[[2.16,7.19]],"id":38407646}],"con":true,"img":false}]}
{"op":"mcm","clk":"5306777556","pt":1646106000825,"mc":[{"id":"1.195395428","rc":[{"atb":[[1.35,23.85]],"id":36087680}],"con":true,"img":false}]}
{"op":"mcm","clk":"5306777581","pt":1646106001492,"mc":[{"id":"1.195395428","rc":[{"atb":[[2.16,13.62]],"id":38407646},{"atb":[[2.16,13.62]],"id":43154456},{"atb":[[1.33,47.88]],"id":43154457},{"atb":[[1.35,45.14]],"id":36087680}],"con":true,"img":false}]}
{"op":"mcm","clk":"5306777614","pt":1646106002720,"mc":[{"id":"1.195395428","rc":[{"atb":[[2.14,0]],"id":38407646},{"atb":[[2.14,0]],"id":43154456}],"con":true,"img":false}]}
{"op":"mcm","clk":"5306777619","pt":1646106002822,"mc":[{"id":"1.195395428","rc":[{"atb":[[2.18,1.66]],"id":38407646},{"atb":[[2.18,1.66]],"id":43154456}],"con":true,"img":false}]}
{"op":"mcm","clk":"5306778551","pt":1646106026969,"mc":[{"id":"1.195395428","marketDefinition":{"bspMarket":true,"turnInPlayEnabled":false,"persistenceEnabled":false,"marketBaseRate":7.0,"eventId":"31270458","eventTypeId":"4339","numberOfWinners":2,"bettingType":"ODDS","marketType":"PLACE","marketTime":"2022-03-01T04:22:00.000Z","suspendTime":"2022-03-01T04:22:00.000Z","bspReconciled":false,"complete":true,"inPlay":false,"crossMatching":true,"runnersVoidable":false,"numberOfActiveRunners":6,"betDelay":0,"status":"OPEN","runners":[{"status":"ACTIVE","sortPriority":1,"id":43154456,"name":"1. Buckle Up Zion"},{"status":"ACTIVE","sortPriority":2,"id":43154457,"name":"2. Rambo Bobbie"},{"status":"ACTIVE","sortPriority":3,"id":38407646,"name":"4. Hiccup Gus"},{"status":"ACTIVE","sortPriority":4,"id":42130949,"name":"5. Into The Fire"},{"status":"ACTIVE","sortPriority":5,"id":37279191,"name":"7. Shiffrin"},{"status":"ACTIVE","sortPriority":6,"id":36087680,"name":"8. White Poison"},{"status":"REMOVED","sortPriority":7,"removalDate":"2022-02-28T22:23:28.000Z","id":39979946,"name":"3. Marshall Giblet"}],"regulators":["MR_INT"],"venue":"Devonport","countryCode":"AU","discountAllowed":true,"timezone":"Australia/Sydney","openDate":"2022-03-01T02:00:00.000Z","version":4381084013,"name":"To Be Placed","eventName":"Devonport (AUS) 1st Mar"},"rc":[],"con":true,"img":false}]}
{"op":"mcm","clk":"5306779204","pt":1646106044783,"mc":[{"id":"1.195395428","rc":[{"atb":[[1.3,0]],"id":43154457},{"atb":[[1.32,0]],"id":36087680}],"con":true,"img":false}]}
{"op":"mcm","clk":"5306779207","pt":1646106044885,"mc":[{"id":"1.195395428","rc":[{"atb":[[1.34,86.11]],"id":43154457},{"atb":[[1.36,84.81]],"id":36087680}],"con":true,"img":false}]}
{"op":"mcm","clk":"5306779267","pt":1646106046571,"mc":[{"id":"1.195395428","rc":[{"atb":[[1.33,25.29]],"id":43154457},{"atb":[[1.35,23.85]],"id":36087680}],"con":true,"img":false}]}
{"op":"mcm","clk":"5306779531","pt":1646106052510,"mc":[{"id":"1.195395428","rc":[{"atb":[[1.37,20.14]],"id":43154457},{"atb":[[1.39,19.11]],"id":36087680}],"con":true,"img":false}]}
{"op":"mcm","clk":"5306779810","pt":1646106059878,"mc":[{"id":"1.195395428","rc":[{"atb":[[1.33,0]],"id":43154457},{"atb":[[1.35,0]],"id":36087680}],"con":true,"img":false}]}
{"op":"mcm","clk":"5306780036","pt":1646106065924,"mc":[{"id":"1.195395428","rc":[{"spn":3.74,"spf":"NaN","id":38407646},{"spn":3.74,"spf":"NaN","id":43154456},{"atb":[[1.37,42.71]],"id":43154457},{"spn":2.0,"spf":"NaN","id":43154457},{"spn":2.01,"spf":"NaN","id":36087680}],"con":true,"img":false}]}
{"op":"mcm","clk":"5306780047","pt":1646106066180,"mc":[{"id":"1.195395428","rc":[{"atb":[[1.39,40.51]],"id":36087680}],"con":true,"img":false}]}
{"op":"mcm","clk":"5306782986","pt":1646106150491,"mc":[{"id":"1.195395428","rc":[{"atb":[[16.5,0]],"id":42130949},{"spn":46.75,"spf":"NaN","id":42130949}],"con":true,"img":false}]}
{"op":"mcm","clk":"5306782989","pt":1646106150594,"mc":[{"id":"1.195395428","rc":[{"atb":[[18,3.6]],"id":42130949}],"con":true,"img":false}]}
{"op":"mcm","clk":"5306784251","pt":1646106185260,"mc":[{"id":"1.195395428","rc":[{"atb":[[13.5,0]],"id":42130949}],"con":true,"img":false}]}
{"op":"mcm","clk":"5306784256","pt":1646106185360,"mc":[{"id":"1.195395428","rc":[{"atb":[[14.5,4.29]],"id":42130949}],"con":true,"img":false}]}
{"op":"mcm","clk":"5306787732","pt":1646106295485,"mc":[{"id":"1.195395428","rc":[{"atb":[[2,0],[1.95,0],[2.1,0]],"id":38407646},{"atl":[[8.6,0],[5.3,0],[6.6,0]],"id":38407646},{"spn":4.19,"spf":"NaN","id":38407646},{"atb":[[2,0],[1.95,0],[2.1,0]],"id":43154456},{"atl":[[8.6,0],[5.3,0],[6.6,0]],"id":43154456},{"spn":4.19,"spf":"NaN","id":43154456},{"atb":[[9.2,0],[10.5,0],[8.2,0]],"id":42130949},{"atl":[[260,0],[80,0],[160,0]],"id":42130949},{"spn":64.0,"spf":"NaN","id":42130949},{"atb":[[1.2,0],[1.25,220.76],[1.15,0]],"id":43154457},{"atl":[[2.64,0],[2.84,0]],"id":43154457},{"spn":2.18,"spf":"NaN","id":43154457},{"atb":[[5,0],[5.5,0],[6,8.65]],"id":37279191},{"atl":[[19.5,0],[48,0],[29,0]],"id":37279191},{"spn":18.0,"spf":"NaN","id":37279191},{"atb":[[1.2,0],[1.25,0],[1.15,0]],"id":36087680},{"atl":[[2.64,0],[2.84,0]],"id":36087680},{"spn":2.08,"spf":"NaN","id":36087680}],"con":true,"img":false}]}
{"op":"mcm","clk":"5306787806","pt":1646106297694,"mc":[{"id":"1.195395428","rc":[{"atb":[[2,120.77],[1.95,127.13],[2.1,54.89]],"id":38407646},{"atl":[[16.5,3.1],[8.6,3.16],[5.3,2.79],[11.5,2.28],[6.6,2.14]],"id":38407646},{"atb":[[2,120.77],[1.95,127.13],[2.1,54.89]],"id":43154456},{"atl":[[16.5,3.1],[8.6,3.16],[5.3,2.79],[11.5,2.28],[6.6,2.14]],"id":43154456},{"atb":[[9.2,14.72],[10.5,6.35],[8.2,16.77]],"id":42130949},{"atl":[[260,0.09],[80,0.15],[160,0.07],[360,0.06],[460,0.1]],"id":42130949},{"atb":[[1.2,605.48],[1.25,462.96],[1.15,807.31]],"id":43154457},{"atl":[[3.6,18.35],[3.1,11.36],[2.44,8.28],[2.64,7.27],[2.84,12.97]],"id":43154457},{"atb":[[5,30.19],[5.5,26.83],[6,20.73]],"id":37279191},{"atl":[[19.5,0.64],[95,0.25],[190,0.25],[48,0.5],[29,0.42]],"id":37279191},{"atb":[[1.2,605.48],[1.25,242.19],[1.15,807.31]],"id":36087680},{"atl":[[3.6,18.35],[3.1,11.36],[2.44,8.28],[2.64,7.27],[2.84,12.97]],"id":36087680}],"con":true,"img":false}]}
{"op":"mcm","clk":"5306788946","pt":1646106336455,"mc":[{"id":"1.195395428","rc":[{"atl":[[3,0]],"id":43154457},{"atl":[[2.78,0]],"id":36087680}],"con":true,"img":false}]}
{"op":"mcm","clk":"5306788951","pt":1646106336558,"mc":[{"id":"1.195395428","rc":[{"atl":[[2.62,23.02]],"id":43154457},{"atl":[[2.62,21.64]],"id":36087680}],"con":true,"img":false}]}
{"op":"mcm","clk":"5306790002","pt":1646106369201,"mc":[{"id":"1.195395428","rc":[{"atb":[[1.96,61.29]],"id":38407646},{"spn":3.74,"spf":"NaN","id":38407646},{"spn":3.74,"spf":"NaN","id":43154456},{"spn":49.0,"spf":"NaN","id":42130949},{"spn":1.9,"spf":"NaN","id":43154457},{"spn":12.75,"spf":"NaN","id":37279191},{"spn":1.91,"spf":"NaN","id":36087680}],"con":true,"img":false}]}
{"op":"mcm","clk":"5306790006","pt":1646106369301,"mc":[{"id":"1.195395428","rc":[{"atb":[[1.77,0]],"id":38407646},{"atl":[[3.25,0]],"id":43154457},{"atl":[[3.35,0]],"id":36087680}],"con":true,"img":false}]}
{"op":"mcm","clk":"5306790009","pt":1646106369407,"mc":[{"id":"1.195395428","rc":[{"atl":[[3.05,24.52]],"id":43154457},{"atl":[[3.05,25.96]],"id":36087680}],"con":true,"img":false}]}
{"op":"mcm","clk":"5306822443","pt":1646107302050,"mc":[{"id":"1.195395428","marketDefinition":{"bspMarket":true,"turnInPlayEnabled":false,"persistenceEnabled":false,"marketBaseRate":7.0,"eventId":"31270458","eventTypeId":"4339","numberOfWinners":2,"bettingType":"ODDS","marketType":"PLACE","marketTime":"2022-03-01T05:17:00.000Z","suspendTime":"2022-03-01T05:17:00.000Z","bspReconciled":false,"complete":true,"inPlay":false,"crossMatching":true,"runnersVoidable":false,"numberOfActiveRunners":6,"betDelay":0,"status":"OPEN","runners":[{"status":"ACTIVE","sortPriority":1,"id":43154456,"name":"1. Buckle Up Zion"},{"status":"ACTIVE","sortPriority":2,"id":43154457,"name":"2. Rambo Bobbie"},{"status":"ACTIVE","sortPriority":3,"id":38407646,"name":"4. Hiccup Gus"},{"status":"ACTIVE","sortPriority":4,"id":42130949,"name":"5. Into The Fire"},{"status":"ACTIVE","sortPriority":5,"id":37279191,"name":"7. Shiffrin"},{"status":"ACTIVE","sortPriority":6,"id":36087680,"name":"8. White Poison"},{"status":"REMOVED","sortPriority":7,"removalDate":"2022-02-28T22:23:28.000Z","id":39979946,"name":"3. Marshall Giblet"}],"regulators":["MR_INT"],"venue":"Devonport","countryCode":"AU","discountAllowed":true,"timezone":"Australia/Sydney","openDate":"2022-03-01T02:00:00.000Z","version":4381118533,"name":"To Be Placed","eventName":"Devonport (AUS) 1st Mar"},"rc":[],"con":true,"img":false}]}
{"op":"mcm","clk":"5306827359","pt":1646107441931,"mc":[{"id":"1.195395428","rc":[{"atb":[[2,120.7],[2.22,2.17],[2.12,46.02],[2.18,1.66],[1.96,61.25],[1.95,127.05],[2.16,13.62],[2.1,54.86]],"id":38407646},{"atl":[[16.5,3.09],[8.6,3.15],[6.2,7.45],[5.3,2.79],[11.5,2.28],[7.6,8.91],[6.6,2.14]],"id":38407646},{"spn":3.76,"spf":"NaN","id":38407646},{"atb":[[2,120.7],[2.22,2.17],[2.12,46.02],[2.18,1.66],[1.77,70.58],[1.95,127.05],[2.16,13.62],[2.1,54.86]],"id":43154456},{"atl":[[16.5,3.09],[8.6,3.15],[6.2,7.45],[5.3,2.79],[11.5,2.28],[7.6,8.23],[6.6,2.14]],"id":43154456},{"spn":3.76,"spf":"NaN","id":43154456},{"atb":[[18,3.6],[9.2,14.71],[10.5,6.35],[8.2,16.76],[14.5,4.29]],"id":42130949},{"atl":[[130,2.7],[110,0.36]],"id":42130949},{"atb":[[1.2,605.12],[1.37,42.72],[1.25,462.68],[1.15,806.83],[1.34,86.06]],"id":43154457},{"atl":[[3.6,18.34],[3.1,11.35],[2.44,8.27],[2.64,7.27],[2.84,12.96],[2.62,23],[3.05,24.51]],"id":43154457},{"trd":[[2.64,0.33],[2.44,0.74]],"ltp":2.64,"tv":1.07,"id":43154457},{"atb":[[5.6,14.57],[5,30.17],[5.5,26.82],[6,20.72]],"id":37279191},{"atl":[[36,2.7],[19.5,0.64],[95,0.25],[190,0.25],[48,0.5],[29,0.42],[30,2.7]],"id":37279191},{"atb":[[1.28,234.5],[1.2,605.12],[1.36,84.76],[1.25,242.05],[1.15,806.83],[1.39,40.53]],"id":36087680},{"atl":[[3.6,18.34],[3.1,11.35],[2.44,8.27],[2.64,7.27],[2.84,12.96],[2.62,21.63],[3.05,25.94]],"id":36087680},{"trd":[[2.64,0.33],[2.44,0.74]],"ltp":2.64,"tv":1.07,"id":36087680}],"con":true,"img":false}]}
{"op":"mcm","clk":"5306827462","pt":1646107444059,"mc":[{"id":"1.195395428","rc":[{"atb":[[2.18,0]],"id":38407646},{"atb":[[2.18,0]],"id":43154456}],"con":true,"img":false}]}
{"op":"mcm","clk":"5306827467","pt":1646107444116,"mc":[{"id":"1.195395428","rc":[{"atb":[[2.24,1.66]],"id":38407646},{"atb":[[2.24,1.66]],"id":43154456}],"con":true,"img":false}]}
{"op":"mcm","clk":"5306828358","pt":1646107467487,"mc":[{"id":"1.195395428","rc":[{"atb":[[1.34,0]],"id":43154457},{"atb":[[1.36,0]],"id":36087680}],"con":true,"img":false}]}
{"op":"mcm","clk":"5306828361","pt":1646107467589,"mc":[{"id":"1.195395428","rc":[{"atb":[[1.38,86.06]],"id":43154457},{"atb":[[1.4,84.76]],"id":36087680}],"con":true,"img":false}]}
{"op":"mcm","clk":"5306828385","pt":1646107468155,"mc":[{"id":"1.195395428","rc":[{"atb":[[1.37,22.56]],"id":43154457},{"atb":[[1.39,21.4]],"id":36087680}],"con":true,"img":false}]}
{"op":"mcm","clk":"5306828592","pt":1646107474094,"mc":[{"id":"1.195395428","rc":[{"atb":[[1.41,18.19]],"id":43154457},{"atb":[[1.43,17.35]],"id":36087680}],"con":true,"img":false}]}
{"op":"mcm","clk":"5306828597","pt":1646107474254,"mc":[{"id":"1.195395428","rc":[{"atb":[[1.44,2.17]],"id":43154457},{"atb":[[1.46,2.17]],"id":36087680}],"con":true,"img":false}]}
{"op":"mcm","clk":"5306828850","pt":1646107482295,"mc":[{"id":"1.195395428","rc":[{"atb":[[1.37,0]],"id":43154457},{"atb":[[1.39,0]],"id":36087680}],"con":true,"img":false}]}
{"op":"mcm","clk":"5306829005","pt":1646107487418,"mc":[{"id":"1.195395428","rc":[{"atb":[[1.38,0]],"id":43154457},{"atb":[[1.4,0]],"id":36087680}],"con":true,"img":false}]}
{"op":"mcm","clk":"5306829009","pt":1646107487521,"mc":[{"id":"1.195395428","rc":[{"atb":[[1.31,86.06]],"id":43154457},{"atb":[[1.33,84.76]],"id":36087680}],"con":true,"img":false}]}
{"op":"mcm","clk":"5306829075","pt":1646107489215,"mc":[{"id":"1.195395428","rc":[{"atb":[[1.41,0]],"id":43154457},{"atb":[[1.43,0]],"id":36087680}],"con":true,"img":false}]}
{"op":"mcm","clk":"5306829285","pt":1646107495103,"mc":[{"id":"1.195395428","rc":[{"atb":[[1.34,21.93]],"id":43154457},{"atb":[[1.36,20.72]],"id":36087680}],"con":true,"img":false}]}
{"op":"mcm","clk":"5306829596","pt":1646107503456,"mc":[{"id":"1.195395428","rc":[{"spn":3.77,"spf":"NaN","id":38407646},{"spn":3.77,"spf":"NaN","id":43154456},{"atb":[[1.34,46.49]],"id":43154457},{"spn":1.94,"spf":"NaN","id":43154457},{"spn":1.95,"spf":"NaN","id":36087680}],"con":true,"img":false}]}
{"op":"mcm","clk":"5306829603","pt":1646107503511,"mc":[{"id":"1.195395428","rc":[{"atb":[[1.36,43.91]],"id":36087680}],"con":true,"img":false}]}
{"op":"mcm","clk":"5306830617","pt":1646107527359,"mc":[{"id":"1.195395428","rc":[{"atb":[[1.31,0]],"id":43154457},{"atb":[[1.33,0]],"id":36087680}],"con":true,"img":false}]}
{"op":"mcm","clk":"5306830620","pt":1646107527458,"mc":[{"id":"1.195395428","rc":[{"atb":[[1.35,86.06]],"id":43154457},{"atb":[[1.37,84.76]],"id":36087680}],"con":true,"img":false}]}
{"op":"mcm","clk":"5306830654","pt":1646107528276,"mc":[{"id":"1.195395428","rc":[{"atb":[[1.34,24.55]],"id":43154457},{"atb":[[1.36,23.19]],"id":36087680}],"con":true,"img":false}]}
{"op":"mcm","clk":"5306830883","pt":1646107534163,"mc":[{"id":"1.195395428","rc":[{"atb":[[1.38,19.63]],"id":43154457},{"atb":[[1.4,18.64]],"id":36087680}],"con":true,"img":false}]}
{"op":"mcm","clk":"5306831564","pt":1646107551207,"mc":[{"id":"1.195395428","rc":[{"atb":[[1.34,0]],"id":43154457},{"atb":[[1.36,0]],"id":36087680}],"con":true,"img":false}]}
{"op":"mcm","clk":"5306831740","pt":1646107555205,"mc":[{"id":"1.195395428","rc":[{"atb":[[1.38,41.6]],"id":43154457}],"con":true,"img":false}]}
{"op":"mcm","clk":"5306831751","pt":1646107555411,"mc":[{"id":"1.195395428","rc":[{"atb":[[1.4,39.51]],"id":36087680}],"con":true,"img":false}]}
{"op":"mcm","clk":"5306832546","pt":1646107577459,"mc":[{"id":"1.195395428","rc":[{"atb":[[1.35,0]],"id":43154457},{"atb":[[1.37,0]],"id":36087680}],"con":true,"img":false}]}
{"op":"mcm","clk":"5306832549","pt":1646107577562,"mc":[{"id":"1.195395428","rc":[{"atb":[[1.39,86.06]],"id":43154457},{"atb":[[1.41,84.76]],"id":36087680}],"con":true,"img":false}]}
{"op":"mcm","clk":"5306832617","pt":1646107579453,"mc":[{"id":"1.195395428","rc":[{"atb":[[1.38,21.97]],"id":43154457},{"atb":[[1.4,20.87]],"id":36087680}],"con":true,"img":false}]}
{"op":"mcm","clk":"5306832787","pt":1646107585360,"mc":[{"id":"1.195395428","rc":[{"atb":[[1.42,17.76]],"id":43154457},{"atb":[[1.44,16.95]],"id":36087680}],"con":true,"img":false}]}
{"op":"mcm","clk":"5306833099","pt":1646107596256,"mc":[{"id":"1.195395428","rc":[{"atb":[[1.38,0]],"id":43154457},{"atb":[[1.4,0]],"id":36087680}],"con":true,"img":false}]}
{"op":"mcm","clk":"5306833131","pt":1646107597378,"mc":[{"id":"1.195395428","rc":[{"atb":[[1.39,0]],"id":43154457},{"atb":[[1.41,0]],"id":36087680}],"con":true,"img":false}]}
{"op":"mcm","clk":"5306833132","pt":1646107597479,"mc":[{"id":"1.195395428","rc":[{"atb":[[1.31,86.06]],"id":43154457},{"atb":[[1.33,84.76]],"id":36087680}],"con":true,"img":false}]}
{"op":"mcm","clk":"5306833197","pt":1646107600496,"mc":[{"id":"1.195395428","rc":[{"atb":[[1.42,0]],"id":43154457},{"atb":[[1.44,0]],"id":36087680}],"con":true,"img":false}]}
{"op":"mcm","clk":"5306833349","pt":1646107606396,"mc":[{"id":"1.195395428","rc":[{"atb":[[1.34,21.93]],"id":43154457},{"atb":[[1.36,20.72]],"id":36087680}],"con":true,"img":false}]}
{"op":"mcm","clk":"5306833582","pt":1646107616718,"mc":[{"id":"1.195395428","rc":[{"atb":[[1.34,46.49]],"id":43154457},{"atb":[[1.36,43.91]],"id":36087680}],"con":true,"img":false}]}
{"op":"mcm","clk":"5306834098","pt":1646107637349,"mc":[{"id":"1.195395428","rc":[{"atb":[[1.31,0]],"id":43154457},{"atb":[[1.33,0]],"id":36087680}],"con":true,"img":false}]}
{"op":"mcm","clk":"5306834101","pt":1646107637451,"mc":[{"id":"1.195395428","rc":[{"atb":[[1.35,86.06]],"id":43154457},{"atb":[[1.37,84.76]],"id":36087680}],"con":true,"img":false}]}
{"op":"mcm","clk":"5306834136","pt":1646107639445,"mc":[{"id":"1.195395428","rc":[{"atb":[[1.34,24.55]],"id":43154457},{"atb":[[1.36,23.19]],"id":36087680}],"con":true,"img":false}]}
{"op":"mcm","clk":"5306834323","pt":1646107645441,"mc":[{"id":"1.195395428","rc":[{"atb":[[1.38,19.63]],"id":43154457},{"atb":[[1.4,18.64]],"id":36087680}],"con":true,"img":false}]}
{"op":"mcm","clk":"5306834544","pt":1646107653564,"mc":[{"id":"1.195395428","rc":[{"atb":[[1.34,0]],"id":43154457},{"atb":[[1.36,0]],"id":36087680}],"con":true,"img":false}]}
{"op":"mcm","clk":"5306834736","pt":1646107659295,"mc":[{"id":"1.195395428","rc":[{"atb":[[1.4,39.51]],"id":36087680}],"con":true,"img":false}]}
{"op":"mcm","clk":"5306834739","pt":1646107659398,"mc":[{"id":"1.195395428","rc":[{"atb":[[1.38,41.6]],"id":43154457}],"con":true,"img":false}]}
{"op":"mcm","clk":"5306835589","pt":1646107687307,"mc":[{"id":"1.195395428","rc":[{"atb":[[1.35,0]],"id":43154457},{"atb":[[1.37,0]],"id":36087680}],"con":true,"img":false}]}
{"op":"mcm","clk":"5306835592","pt":1646107687408,"mc":[{"id":"1.195395428","rc":[{"atb":[[1.39,86.06]],"id":43154457},{"atb":[[1.41,84.76]],"id":36087680}],"con":true,"img":false}]}
{"op":"mcm","clk":"5306835683","pt":1646107690524,"mc":[{"id":"1.195395428","rc":[{"atb":[[1.38,21.97]],"id":43154457},{"atb":[[1.4,20.87]],"id":36087680}],"con":true,"img":false}]}
{"op":"mcm","clk":"5306835884","pt":1646107696605,"mc":[{"id":"1.195395428","rc":[{"atb":[[1.42,17.76]],"id":43154457},{"atb":[[1.44,16.95]],"id":36087680}],"con":true,"img":false}]}
{"op":"mcm","clk":"5306836019","pt":1646107701716,"mc":[{"id":"1.195395428","rc":[{"atb":[[1.38,0]],"id":43154457},{"atb":[[1.4,0]],"id":36087680}],"con":true,"img":false}]}
{"op":"mcm","clk":"5306836203","pt":1646107707441,"mc":[{"id":"1.195395428","rc":[{"atb":[[1.39,0]],"id":43154457},{"atb":[[1.41,0]],"id":36087680}],"con":true,"img":false}]}
{"op":"mcm","clk":"5306836206","pt":1646107707546,"mc":[{"id":"1.195395428","rc":[{"atb":[[1.42,37.63],[1.31,86.06]],"id":43154457},{"atb":[[1.33,84.76]],"id":36087680}],"con":true,"img":false}]}
{"op":"mcm","clk":"5306836208","pt":1646107707647,"mc":[{"id":"1.195395428","rc":[{"atb":[[1.44,35.93]],"id":36087680}],"con":true,"img":false}]}
{"op":"mcm","clk":"5306836248","pt":1646107708519,"mc":[{"id":"1.195395428","rc":[{"atb":[[1.42,19.87]],"id":43154457},{"atb":[[1.44,18.97]],"id":36087680}],"con":true,"img":false}]}
{"op":"mcm","clk":"5306836431","pt":1646107714451,"mc":[{"id":"1.195395428","rc":[{"atb":[[1.34,21.93]],"id":43154457},{"atb":[[1.36,20.72]],"id":36087680}],"con":true,"img":false}]}
{"op":"mcm","clk":"5306836762","pt":1646107725759,"mc":[{"id":"1.195395428","rc":[{"atb":[[1.42,0]],"id":43154457},{"atb":[[1.44,0]],"id":36087680}],"con":true,"img":false}]}
{"op":"mcm","clk":"5306836935","pt":1646107731437,"mc":[{"id":"1.195395428","rc":[{"atb":[[1.34,46.49]],"id":43154457}],"con":true,"img":false}]}
{"op":"mcm","clk":"5306836942","pt":1646107731639,"mc":[{"id":"1.195395428","rc":[{"atb":[[1.36,43.91]],"id":36087680}],"con":true,"img":false}]}
{"op":"mcm","clk":"5306837828","pt":1646107757374,"mc":[{"id":"1.195395428","rc":[{"atb":[[1.31,0]],"id":43154457},{"atb":[[1.33,0]],"id":36087680}],"con":true,"img":false}]}
{"op":"mcm","clk":"5306837834","pt":1646107757477,"mc":[{"id":"1.195395428","rc":[{"atb":[[1.35,86.06]],"id":43154457},{"atb":[[1.37,84.76]],"id":36087680}],"con":true,"img":false}]}
{"op":"mcm","clk":"5306837911","pt":1646107759671,"mc":[{"id":"1.195395428","rc":[{"atb":[[1.34,24.55]],"id":43154457},{"atb":[[1.36,23.19]],"id":36087680}],"con":true,"img":false}]}
{"op":"mcm","clk":"5306838106","pt":1646107765568,"mc":[{"id":"1.195395428","rc":[{"atb":[[1.38,19.63]],"id":43154457},{"atb":[[1.4,18.64]],"id":36087680}],"con":true,"img":false}]}
{"op":"mcm","clk":"5306838416","pt":1646107773963,"mc":[{"id":"1.195395428","rc":[{"atb":[[1.34,0]],"id":43154457},{"atb":[[1.36,0]],"id":36087680}],"con":true,"img":false}]}
{"op":"mcm","clk":"5306838641","pt":1646107779489,"mc":[{"id":"1.195395428","rc":[{"atb":[[1.38,41.6]],"id":43154457}],"con":true,"img":false}]}
{"op":"mcm","clk":"5306838644","pt":1646107779591,"mc":[{"id":"1.195395428","rc":[{"atb":[[1.4,39.51]],"id":36087680}],"con":true,"img":false}]}
{"op":"mcm","clk":"5306839566","pt":1646107807416,"mc":[{"id":"1.195395428","rc":[{"atb":[[1.35,0]],"id":43154457},{"atb":[[1.37,0]],"id":36087680}],"con":true,"img":false}]}
{"op":"mcm","clk":"5306839571","pt":1646107807517,"mc":[{"id":"1.195395428","rc":[{"atb":[[1.39,86.06]],"id":43154457},{"atb":[[1.41,84.76]],"id":36087680}],"con":true,"img":false}]}
{"op":"mcm","clk":"5306839687","pt":1646107810640,"mc":[{"id":"1.195395428","rc":[{"atb":[[1.38,21.97]],"id":43154457},{"atb":[[1.4,20.87]],"id":36087680}],"con":true,"img":false}]}
{"op":"mcm","clk":"5306839885","pt":1646107816733,"mc":[{"id":"1.195395428","rc":[{"atb":[[1.42,17.76]],"id":43154457},{"atb":[[1.44,16.95]],"id":36087680}],"con":true,"img":false}]}
{"op":"mcm","clk":"5306840121","pt":1646107822869,"mc":[{"id":"1.195395428","rc":[{"atb":[[1.38,0]],"id":43154457},{"atb":[[1.4,0]],"id":36087680}],"con":true,"img":false}]}
{"op":"mcm","clk":"5306840295","pt":1646107827380,"mc":[{"id":"1.195395428","rc":[{"atb":[[1.39,0]],"id":43154457},{"atb":[[1.41,0]],"id":36087680}],"con":true,"img":false}]}
{"op":"mcm","clk":"5306840298","pt":1646107827482,"mc":[{"id":"1.195395428","rc":[{"atb":[[1.31,86.06]],"id":43154457},{"atb":[[1.33,84.76]],"id":36087680}],"con":true,"img":false}]}
{"op":"mcm","clk":"5306840336","pt":1646107828663,"mc":[{"id":"1.195395428","rc":[{"atb":[[1.42,0]],"id":43154457},{"atb":[[1.44,0]],"id":36087680}],"con":true,"img":false}]}
{"op":"mcm","clk":"5306840518","pt":1646107834605,"mc":[{"id":"1.195395428","rc":[{"atb":[[1.36,20.72]],"id":36087680}],"con":true,"img":false}]}
{"op":"mcm","clk":"5306840522","pt":1646107834707,"mc":[{"id":"1.195395428","rc":[{"atb":[[1.34,21.93]],"id":43154457}],"con":true,"img":false}]}
{"op":"mcm","clk":"5306840702","pt":1646107840591,"mc":[{"id":"1.195395428","rc":[{"atb":[[1.34,46.49]],"id":43154457},{"atb":[[1.36,43.91]],"id":36087680}],"con":true,"img":false}]}
{"op":"mcm","clk":"5306841507","pt":1646107867325,"mc":[{"id":"1.195395428","rc":[{"atb":[[1.31,0]],"id":43154457},{"atb":[[1.33,0]],"id":36087680}],"con":true,"img":false}]}
{"op":"mcm","clk":"5306841510","pt":1646107867428,"mc":[{"id":"1.195395428","rc":[{"atb":[[1.35,86.06]],"id":43154457},{"atb":[[1.37,84.76]],"id":36087680}],"con":true,"img":false}]}
{"op":"mcm","clk":"5306841521","pt":1646107867731,"mc":[{"id":"1.195395428","rc":[{"atb":[[1.34,24.55]],"id":43154457},{"atb":[[1.36,23.19]],"id":36087680}],"con":true,"img":false}]}
{"op":"mcm","clk":"5306841698","pt":1646107873050,"mc":[{"id":"1.195395428","rc":[{"atb":[[1.4,18.64]],"id":36087680}],"con":true,"img":false}]}
{"op":"mcm","clk":"5306841701","pt":1646107873152,"mc":[{"id":"1.195395428","rc":[{"atb":[[1.38,19.63]],"id":43154457}],"con":true,"img":false}]}
{"op":"mcm","clk":"5306841961","pt":1646107882156,"mc":[{"id":"1.195395428","rc":[{"atb":[[1.34,0]],"id":43154457},{"atb":[[1.36,0]],"id":36087680}],"con":true,"img":false}]}
{"op":"mcm","clk":"5306842195","pt":1646107888752,"mc":[{"id":"1.195395428","rc":[{"atb":[[1.38,41.6]],"id":43154457},{"atb":[[1.4,39.51]],"id":36087680}],"con":true,"img":false}]}
{"op":"mcm","clk":"5306843049","pt":1646107917325,"mc":[{"id":"1.195395428","rc":[{"atb":[[1.35,0]],"id":43154457},{"atb":[[1.37,0]],"id":36087680}],"con":true,"img":false}]}
{"op":"mcm","clk":"5306843051","pt":1646107917375,"mc":[{"id":"1.195395428","rc":[{"atb":[[1.39,86.06]],"id":43154457},{"atb":[[1.41,84.76]],"id":36087680}],"con":true,"img":false}]}
{"op":"mcm","clk":"5306843068","pt":1646107918192,"mc":[{"id":"1.195395428","rc":[{"atb":[[1.38,21.97]],"id":43154457},{"atb":[[1.4,20.87]],"id":36087680}],"con":true,"img":false}]}
{"op":"mcm","clk":"5306843248","pt":1646107924131,"mc":[{"id":"1.195395428","rc":[{"atb":[[1.42,17.76]],"id":43154457},{"atb":[[1.44,16.95]],"id":36087680}],"con":true,"img":false}]}
{"op":"mcm","clk":"5306843370","pt":1646107931026,"mc":[{"id":"1.195395428","rc":[{"atb":[[1.38,0]],"id":43154457},{"atb":[[1.4,0]],"id":36087680}],"con":true,"img":false}]}
{"op":"mcm","clk":"5306843497","pt":1646107936234,"mc":[{"id":"1.195395428","rc":[{"atb":[[1.42,37.63]],"id":43154457},{"atb":[[1.44,35.93]],"id":36087680}],"con":true,"img":false}]}
{"op":"mcm","clk":"5306843946","pt":1646107957445,"mc":[{"id":"1.195395428","rc":[{"atb":[[1.39,0]],"id":43154457},{"atb":[[1.41,0]],"id":36087680}],"con":true,"img":false}]}
{"op":"mcm","clk":"5306843949","pt":1646107957548,"mc":[{"id":"1.195395428","rc":[{"atb":[[1.43,86.06]],"id":43154457},{"atb":[[1.45,84.76]],"id":36087680}],"con":true,"img":false}]}
{"op":"mcm","clk":"5306844000","pt":1646107960252,"mc":[{"id":"1.195395428","rc":[{"atb":[[1.42,19.87]],"id":43154457},{"atb":[[1.44,18.97]],"id":36087680}],"con":true,"img":false}]}
{"op":"mcm","clk":"5306844117","pt":1646107966240,"mc":[{"id":"1.195395428","rc":[{"atb":[[1.46,16.21]],"id":43154457},{"atb":[[1.48,15.53]],"id":36087680}],"con":true,"img":false}]}
{"op":"mcm","clk":"5306844124","pt":1646107966549,"mc":[{"id":"1.195395428","rc":[{"atb":[[1.44,0],[1.49,2.17]],"id":43154457},{"atb":[[1.46,0],[1.51,2.17]],"id":36087680}],"con":true,"img":false}]}
{"op":"mcm","clk":"5306844234","pt":1646107972587,"mc":[{"id":"1.195395428","rc":[{"atb":[[1.42,0]],"id":43154457},{"atb":[[1.44,0]],"id":36087680}],"con":true,"img":false}]}
{"op":"mcm","clk":"5306844336","pt":1646107977500,"mc":[{"id":"1.195395428","rc":[{"atb":[[1.43,0]],"id":43154457},{"atb":[[1.45,0]],"id":36087680}],"con":true,"img":false}]}
{"op":"mcm","clk":"5306844339","pt":1646107977602,"mc":[{"id":"1.195395428","rc":[{"atb":[[1.31,86.06]],"id":43154457},{"atb":[[1.33,84.76]],"id":36087680}],"con":true,"img":false}]}
{"op":"mcm","clk":"5306844347","pt":1646107978270,"mc":[{"id":"1.195395428","rc":[{"atb":[[1.46,0]],"id":43154457},{"atb":[[1.48,0]],"id":36087680}],"con":true,"img":false}]}
{"op":"mcm","clk":"5306844443","pt":1646107984202,"mc":[{"id":"1.195395428","rc":[{"atb":[[1.34,21.93]],"id":43154457},{"atb":[[1.36,20.72]],"id":36087680}],"con":true,"img":false}]}
{"op":"mcm","clk":"5306844559","pt":1646107991204,"mc":[{"id":"1.195395428","rc":[{"atb":[[1.34,46.49]],"id":43154457},{"atb":[[1.36,43.91]],"id":36087680}],"con":true,"img":false}]}
{"op":"mcm","clk":"5306845101","pt":1646108017458,"mc":[{"id":"1.195395428","rc":[{"atb":[[1.31,0]],"id":43154457},{"spn":1.96,"spf":"NaN","id":43154457},{"atb":[[1.33,0]],"id":36087680},{"spn":1.97,"spf":"NaN","id":36087680}],"con":true,"img":false}]}
{"op":"mcm","clk":"5306845104","pt":1646108017560,"mc":[{"id":"1.195395428","rc":[{"atb":[[1.35,86.06]],"id":43154457},{"atb":[[1.37,84.76]],"id":36087680}],"con":true,"img":false}]}
{"op":"mcm","clk":"5306845143","pt":1646108020366,"mc":[{"id":"1.195395428","rc":[{"atb":[[1.34,24.55]],"id":43154457},{"atb":[[1.36,23.19]],"id":36087680}],"con":true,"img":false}]}
{"op":"mcm","clk":"5306845315","pt":1646108026264,"mc":[{"id":"1.195395428","rc":[{"atb":[[1.38,19.63]],"id":43154457},{"atb":[[1.4,18.64]],"id":36087680}],"con":true,"img":false}]}
{"op":"mcm","clk":"5306845336","pt":1646108027286,"mc":[{"id":"1.195395428","rc":[{"atb":[[1.41,2.17],[1.49,0]],"id":43154457},{"atb":[[1.43,2.17],[1.51,0]],"id":36087680}],"con":true,"img":false}]}
{"op":"mcm","clk":"5306845473","pt":1646108035974,"mc":[{"id":"1.195395428","rc":[{"atb":[[1.34,0]],"id":43154457},{"atb":[[1.36,0]],"id":36087680}],"con":true,"img":false}]}
{"op":"mcm","clk":"5306845604","pt":1646108041702,"mc":[{"id":"1.195395428","rc":[{"atb":[[1.38,41.6]],"id":43154457}],"con":true,"img":false}]}
{"op":"mcm","clk":"5306845610","pt":1646108041908,"mc":[{"id":"1.195395428","rc":[{"atb":[[1.4,39.51]],"id":36087680}],"con":true,"img":false}]}
{"op":"mcm","clk":"5306846354","pt":1646108077451,"mc":[{"id":"1.195395428","rc":[{"atb":[[1.35,0]],"id":43154457},{"atb":[[1.37,0]],"id":36087680}],"con":true,"img":false}]}
{"op":"mcm","clk":"5306846356","pt":1646108077554,"mc":[{"id":"1.195395428","rc":[{"atb":[[1.39,86.06]],"id":43154457},{"spn":1.92,"spf":"NaN","id":43154457},{"atb":[[1.41,84.76]],"id":36087680},{"spn":1.93,"spf":"NaN","id":36087680}],"con":true,"img":false}]}
{"op":"mcm","clk":"5306846406","pt":1646108080516,"mc":[{"id":"1.195395428","rc":[{"atb":[[1.38,21.97]],"id":43154457},{"atb":[[1.4,20.87]],"id":36087680}],"con":true,"img":false}]}
{"op":"mcm","clk":"5306846532","pt":1646108086352,"mc":[{"id":"1.195395428","rc":[{"atb":[[1.42,17.76]],"id":43154457},{"atb":[[1.44,16.95]],"id":36087680}],"con":true,"img":false}]}
{"op":"mcm","clk":"5306846558","pt":1646108087171,"mc":[{"id":"1.195395428","rc":[{"atb":[[1.41,0],[1.45,2.17]],"id":43154457},{"atb":[[1.43,0],[1.47,2.17]],"id":36087680}],"con":true,"img":false}]}
{"op":"mcm","clk":"5306846793","pt":1646108098986,"mc":[{"id":"1.195395428","rc":[{"atb":[[1.38,0]],"id":43154457},{"atb":[[1.4,0]],"id":36087680}],"con":true,"img":false}]}
{"op":"mcm","clk":"5306847041","pt":1646108105282,"mc":[{"id":"1.195395428","rc":[{"atb":[[1.42,37.63]],"id":43154457},{"atb":[[1.44,35.93]],"id":36087680}],"con":true,"img":false}]}
{"op":"mcm","clk":"5306847831","pt":1646108137423,"mc":[{"id":"1.195395428","rc":[{"atb":[[1.39,0]],"id":43154457},{"atb":[[1.41,0]],"id":36087680}],"con":true,"img":false}]}
{"op":"mcm","clk":"5306847834","pt":1646108137526,"mc":[{"id":"1.195395428","rc":[{"atb":[[1.43,86.06]],"id":43154457},{"atb":[[1.45,84.76]],"id":36087680}],"con":true,"img":false}]}
{"op":"mcm","clk":"5306847904","pt":1646108140451,"mc":[{"id":"1.195395428","rc":[{"atb":[[1.42,19.87]],"id":43154457},{"spn":1.94,"spf":"NaN","id":43154457},{"atb":[[1.44,18.97]],"id":36087680},{"spn":1.95,"spf":"NaN","id":36087680}],"con":true,"img":false}]}
{"op":"mcm","clk":"5306848027","pt":1646108146452,"mc":[{"id":"1.195395428","rc":[{"atb":[[1.46,16.21]],"id":43154457},{"atb":[[1.48,15.53]],"id":36087680}],"con":true,"img":false}]}
{"op":"mcm","clk":"5306848040","pt":1646108147067,"mc":[{"id":"1.195395428","rc":[{"atb":[[1.45,0],[1.49,2.17]],"id":43154457},{"atb":[[1.51,2.17],[1.47,0]],"id":36087680}],"con":true,"img":false}]}
{"op":"mcm","clk":"5306848212","pt":1646108152562,"mc":[{"id":"1.195395428","rc":[{"atb":[[1.42,0]],"id":43154457},{"atb":[[1.44,0]],"id":36087680}],"con":true,"img":false}]}
{"op":"mcm","clk":"5306848382","pt":1646108157382,"mc":[{"id":"1.195395428","rc":[{"atb":[[1.43,0]],"id":43154457},{"atb":[[1.45,0]],"id":36087680}],"con":true,"img":false}]}
{"op":"mcm","clk":"5306848388","pt":1646108157483,"mc":[{"id":"1.195395428","rc":[{"atb":[[1.31,86.06]],"id":43154457},{"atb":[[1.33,84.76]],"id":36087680}],"con":true,"img":false}]}
{"op":"mcm","clk":"5306848417","pt":1646108158559,"mc":[{"id":"1.195395428","rc":[{"atb":[[1.46,0]],"id":43154457},{"atb":[[1.48,0]],"id":36087680}],"con":true,"img":false}]}
{"op":"mcm","clk":"5306848633","pt":1646108164503,"mc":[{"id":"1.195395428","rc":[{"atb":[[1.34,21.93]],"id":43154457},{"atb":[[1.36,20.72]],"id":36087680}],"con":true,"img":false}]}
{"op":"mcm","clk":"5306848915","pt":1646108173885,"mc":[{"id":"1.195395428","rc":[{"atb":[[1.36,43.91]],"id":36087680}],"con":true,"img":false}]}
{"op":"mcm","clk":"5306848921","pt":1646108173987,"mc":[{"id":"1.195395428","rc":[{"atb":[[1.34,46.49]],"id":43154457}],"con":true,"img":false}]}
{"op":"mcm","clk":"5306856269","pt":1646108202676,"mc":[{"id":"1.195395428","marketDefinition":{"bspMarket":true,"turnInPlayEnabled":false,"persistenceEnabled":false,"marketBaseRate":7.0,"eventId":"31270458","eventTypeId":"4339","numberOfWinners":2,"bettingType":"ODDS","marketType":"PLACE","marketTime":"2022-03-01T05:17:00.000Z","suspendTime":"2022-03-01T05:17:00.000Z","bspReconciled":false,"complete":true,"inPlay":false,"crossMatching":true,"runnersVoidable":false,"numberOfActiveRunners":6,"betDelay":0,"status":"OPEN","runners":[{"status":"ACTIVE","sortPriority":1,"id":43154456,"name":"1. Buckle Up Zion"},{"status":"ACTIVE","sortPriority":2,"id":43154457,"name":"2. Rambo Bobbie"},{"status":"ACTIVE","sortPriority":3,"id":38407646,"name":"4. Hiccup Gus"},{"status":"ACTIVE","sortPriority":4,"id":42130949,"name":"5. Into The Fire"},{"status":"ACTIVE","sortPriority":5,"id":37279191,"name":"7. Shiffrin"},{"status":"ACTIVE","sortPriority":6,"id":36087680,"name":"8. White Poison"},{"status":"REMOVED","sortPriority":7,"removalDate":"2022-02-28T22:23:28.000Z","id":39979946,"name":"3. Marshall Giblet"}],"regulators":["MR_INT"],"venue":"Devonport","countryCode":"AU","discountAllowed":true,"timezone":"Australia/Sydney","openDate":"2022-03-01T02:00:00.000Z","version":4381118533,"name":"To Be Placed","eventName":"Devonport (AUS) 1st Mar"},"rc":[{"atb":[[2.24,1.66],[2,120.7],[2.22,2.17],[2.12,46.02],[1.96,61.25],[1.95,127.05],[2.16,13.62],[2.1,54.86]],"id":38407646},{"atl":[[16.5,3.09],[8.6,3.15],[6.2,7.45],[5.3,2.79],[11.5,2.28],[7.6,8.91],[6.6,2.14]],"id":38407646},{"spn":3.77,"spf":"NaN","id":38407646},{"atb":[[2.24,1.66],[2,120.7],[2.22,2.17],[2.12,46.02],[1.77,70.58],[1.95,127.05],[2.16,13.62],[2.1,54.86]],"id":43154456},{"atl":[[16.5,3.09],[8.6,3.15],[6.2,7.45],[5.3,2.79],[11.5,2.28],[7.6,8.23],[6.6,2.14]],"id":43154456},{"spn":3.77,"spf":"NaN","id":43154456},{"atb":[[18,3.6],[9.2,14.71],[10.5,6.35],[8.2,16.76],[14.5,4.29]],"id":42130949},{"atl":[[130,2.7],[260,0.09],[80,0.15],[160,0.07],[360,0.06],[110,0.36],[460,0.1]],"id":42130949},{"spn":49.0,"spf":"NaN","id":42130949},{"atb":[[1.2,605.12],[1.25,462.68],[1.15,806.83],[1.49,2.17],[1.31,86.06],[1.34,46.49]],"id":43154457},{"atl":[[3.6,18.34],[3.1,11.35],[2.44,8.27],[2.64,7.27],[2.84,12.96],[2.62,23],[3.05,24.51]],"id":43154457},{"trd":[[2.64,0.33],[2.44,0.74]],"ltp":2.64,"tv":1.07,"id":43154457},{"spn":1.96,"spf":"NaN","id":43154457},{"atb":[[5.6,14.57],[5,30.17],[5.5,26.82],[6,20.72]],"id":37279191},{"atl":[[36,2.7],[19.5,0.64],[95,0.25],[190,0.25],[48,0.5],[29,0.42],[30,2.7]],"id":37279191},{"spn":12.75,"spf":"NaN","id":37279191},{"atb":[[1.28,234.5],[1.2,605.12],[1.36,43.91],[1.25,242.05],[1.15,806.83],[1.33,84.76],[1.51,2.17]],"id":36087680},{"atl":[[3.6,18.34],[3.1,11.35],[2.44,8.27],[2.64,7.27],[2.84,12.96],[2.62,21.63],[3.05,25.94]],"id":36087680},{"trd":[[2.64,0.33],[2.44,0.74]],"ltp":2.64,"tv":1.07,"id":36087680},{"spn":1.97,"spf":"NaN","id":36087680}],"con":true,"img":true}]}
{"op":"mcm","clk":"5306857855","pt":1646108207340,"mc":[{"id":"1.195395428","rc":[{"atb":[[1.31,0]],"id":43154457},{"spn":1.96,"spf":"NaN","id":43154457},{"atb":[[1.33,0]],"id":36087680},{"spn":1.97,"spf":"NaN","id":36087680}],"con":true,"img":false}]}
{"op":"mcm","clk":"5306857860","pt":1646108207442,"mc":[{"id":"1.195395428","rc":[{"atb":[[1.35,86.06]],"id":43154457},{"atb":[[1.37,84.76]],"id":36087680}],"con":true,"img":false}]}
{"op":"mcm","clk":"5306857920","pt":1646108209539,"mc":[{"id":"1.195395428","rc":[{"atb":[[1.34,24.55]],"id":43154457},{"atb":[[1.36,23.19]],"id":36087680}],"con":true,"img":false}]}
{"op":"mcm","clk":"5306858112","pt":1646108215630,"mc":[{"id":"1.195395428","rc":[{"atb":[[1.38,19.63]],"id":43154457},{"atb":[[1.4,18.64]],"id":36087680}],"con":true,"img":false}]}
{"op":"mcm","clk":"5306858124","pt":1646108216141,"mc":[{"id":"1.195395428","rc":[{"atb":[[1.41,2.17],[1.49,0]],"id":43154457},{"atb":[[1.43,2.17],[1.51,0]],"id":36087680}],"con":true,"img":false}]}
{"op":"mcm","clk":"5306858226","pt":1646108220287,"mc":[{"id":"1.195395428","rc":[{"atb":[[1.23,250]],"id":38407646},{"atb":[[1.23,250]],"id":43154456},{"atb":[[1.23,250]],"id":42130949},{"atb":[[1.23,250]],"id":37279191}],"con":true,"img":false}]}
{"op":"mcm","clk":"5306858230","pt":1646108220389,"mc":[{"id":"1.195395428","rc":[{"atb":[[4.4,29.41]],"id":37279191},{"atl":[[29,3.12]],"id":37279191}],"con":true,"img":false}]}
{"op":"mcm","clk":"5306858234","pt":1646108220439,"mc":[{"id":"1.195395428","rc":[{"atb":[[1.35,100.89]],"id":38407646},{"atl":[[5.3,5.58]],"id":38407646},{"atb":[[1.54,100.89]],"id":43154456},{"atl":[[9.6,6.32]],"id":43154456},{"atb":[[4.8,12.7]],"id":42130949},{"atl":[[120,2]],"id":42130949}],"con":true,"img":false}]}
{"op":"mcm","clk":"5306858312","pt":1646108222078,"mc":[{"id":"1.195395428","rc":[{"atb":[[1.34,0]],"id":43154457},{"atb":[[1.36,0]],"id":36087680}],"con":true,"img":false}]}
{"op":"mcm","clk":"5306858315","pt":1646108222179,"mc":[{"id":"1.195395428","rc":[{"atl":[[2.62,39.56]],"id":43154457},{"atb":[[1.42,23.19]],"id":36087680},{"atl":[[6.6,17.86]],"id":36087680}],"con":true,"img":false}]}
{"op":"mcm","clk":"5306858475","pt":1646108227348,"mc":[{"id":"1.195395428","rc":[{"atb":[[2.06,94.34],[2.16,35.25],[1.35,0]],"id":38407646},{"atl":[[5.3,21.92]],"id":38407646},{"atb":[[1.63,158.73],[1.54,0],[2.16,33.13]],"id":43154456},{"atl":[[9.6,0],[5.3,21.92]],"id":43154456},{"atl":[[80,1.35]],"id":42130949},{"atb":[[1.35,107.69]],"id":43154457},{"atl":[[2.44,29.91]],"id":43154457},{"atb":[[6,26.74]],"id":37279191},{"atl":[[19.5,4.45]],"id":37279191},{"atb":[[1.37,106.39]],"id":36087680},{"atl":[[5.8,20.83],[2.44,29.91],[2.62,0],[6.6,0]],"id":36087680}],"con":true,"img":false}]}
{"op":"mcm","clk":"5306858477","pt":1646108227450,"mc":[{"id":"1.195395428","rc":[{"atl":[[80,3.35]],"id":42130949},{"atl":[[24,4.35],[29,0.42]],"id":37279191},{"atl":[[2.82,21.63]],"id":36087680}],"con":true,"img":false}]}
{"op":"mcm","clk":"5306858478","pt":1646108227553,"mc":[{"id":"1.195395428","rc":[{"atl":[[120,0]],"id":42130949}],"con":true,"img":false}]}
{"op":"mcm","clk":"5306858491","pt":1646108227962,"mc":[{"id":"1.195395428","rc":[{"atb":[[1.38,41.6]],"id":43154457}],"con":true,"img":false}]}
{"op":"mcm","clk":"5306858492","pt":1646108228064,"mc":[{"id":"1.195395428","rc":[{"atb":[[1.4,39.51]],"id":36087680}],"con":true,"img":false}]}
{"op":"mcm","clk":"5306858523","pt":1646108229853,"mc":[{"id":"1.195395428","rc":[{"atl":[[2.56,59.82],[2.62,23]],"id":43154457}],"con":true,"img":false}]}
{"op":"mcm","clk":"5306858607","pt":1646108232559,"mc":[{"id":"1.195395428","rc":[{"atl":[[24,0],[27,3.85]],"id":37279191}],"con":true,"img":false}]}
{"op":"mcm","clk":"5306858803","pt":1646108237367,"mc":[{"id":"1.195395428","rc":[{"atb":[[1.35,21.63]],"id":43154457},{"atl":[[3.05,0]],"id":43154457},{"atl":[[3.05,0]],"id":36087680}],"con":true,"img":false}]}
{"op":"mcm","clk":"5306858806","pt":1646108237500,"mc":[{"id":"1.195395428","rc":[{"atb":[[1.3,86.06]],"id":43154457},{"atl":[[3.3,24.51]],"id":43154457},{"atl":[[3.3,25.94]],"id":36087680}],"con":true,"img":false}]}
{"op":"mcm","clk":"5306858878","pt":1646108239697,"mc":[{"id":"1.195395428","rc":[{"atb":[[1.38,21.97]],"id":43154457}],"con":true,"img":false}]}
{"op":"mcm","clk":"5306858925","pt":1646108240873,"mc":[{"id":"1.195395428","rc":[{"atb":[[1.35,0]],"id":43154457},{"atb":[[1.37,84.76]],"id":36087680}],"con":true,"img":false}]}
{"op":"mcm","clk":"5306858938","pt":1646108241284,"mc":[{"id":"1.195395428","rc":[{"atb":[[1.38,43.6]],"id":43154457},{"atb":[[1.42,44.82]],"id":36087680}],"con":true,"img":false}]}
{"op":"mcm","clk":"5306859084","pt":1646108245576,"mc":[{"id":"1.195395428","rc":[{"atb":[[1.33,22.6]],"id":43154457}],"con":true,"img":false}]}
{"op":"mcm","clk":"5306859146","pt":1646108247319,"mc":[{"id":"1.195395428","rc":[{"atb":[[18,0],[14.5,0],[9.4,6.39]],"id":42130949},{"atb":[[5.6,0]],"id":37279191}],"con":true,"img":false}]}
{"op":"mcm","clk":"5306859149","pt":1646108247418,"mc":[{"id":"1.195395428","rc":[{"atb":[[11,3.6]],"id":42130949},{"atb":[[5.1,14.57]],"id":37279191}],"con":true,"img":false}]}
{"op":"mcm","clk":"5306859338","pt":1646108252023,"mc":[{"id":"1.195395428","rc":[{"atb":[[1.38,21.63]],"id":43154457}],"con":true,"img":false}]}
{"op":"mcm","clk":"5306859523","pt":1646108257293,"mc":[{"id":"1.195395428","rc":[{"atl":[[110,0],[60,2.7]],"id":42130949},{"atl":[[2.54,32.38],[2.62,0]],"id":43154457},{"atb":[[1.37,0]],"id":36087680}],"con":true,"img":false}]}
{"op":"mcm","clk":"5306859524","pt":1646108257394,"mc":[{"id":"1.195395428","rc":[{"atb":[[1.43,86.93]],"id":36087680}],"con":true,"img":false}]}
{"op":"mcm","clk":"5306859525","pt":1646108257497,"mc":[{"id":"1.195395428","rc":[{"atb":[[1.43,131.75],[1.42,21.63]],"id":36087680}],"con":true,"img":false}]}
{"op":"mcm","clk":"5306859540","pt":1646108257701,"mc":[{"id":"1.195395428","rc":[{"atb":[[1.4,20.87]],"id":36087680}],"con":true,"img":false}]}
{"op":"mcm","clk":"5306859555","pt":1646108258010,"mc":[{"id":"1.195395428","rc":[{"atb":[[1.33,47.89]],"id":43154457}],"con":true,"img":false}]}
{"op":"mcm","clk":"5306859750","pt":1646108263605,"mc":[{"id":"1.195395428","rc":[{"spn":35.5,"spf":"NaN","id":42130949},{"spn":1.92,"spf":"NaN","id":43154457},{"atb":[[1.46,16.21]],"id":36087680},{"spn":1.95,"spf":"NaN","id":36087680}],"con":true,"img":false}]}
{"op":"mcm","clk":"5306859776","pt":1646108264420,"mc":[{"id":"1.195395428","rc":[{"atb":[[1.63,0],[1.71,140.85]],"id":43154456}],"con":true,"img":false}]}
{"op":"mcm","clk":"5306859780","pt":1646108264523,"mc":[{"id":"1.195395428","rc":[{"atl":[[80,1.35],[60,4.7]],"id":42130949}],"con":true,"img":false}]}
{"op":"mcm","clk":"5306859789","pt":1646108264728,"mc":[{"id":"1.195395428","rc":[{"atb":[[1.43,129.58],[1.49,2.17]],"id":36087680}],"con":true,"img":false}]}
{"op":"mcm","clk":"5306859978","pt":1646108270140,"mc":[{"id":"1.195395428","rc":[{"atb":[[1.4,0]],"id":36087680}],"con":true,"img":false}]}
{"op":"mcm","clk":"5306860063","pt":1646108272549,"mc":[{"id":"1.195395428","rc":[{"atl":[[80,0.15]],"id":42130949},{"atb":[[1.42,0]],"id":36087680}],"con":true,"img":false}]}
{"op":"mcm","clk":"5306860075","pt":1646108272907,"mc":[{"id":"1.195395428","rc":[{"atl":[[60,6.3]],"id":42130949},{"atb":[[1.43,151.21]],"id":36087680}],"con":true,"img":false}]}
{"op":"mcm","clk":"5306860184","pt":1646108276032,"mc":[{"id":"1.195395428","rc":[{"atb":[[1.46,34.36]],"id":36087680}],"con":true,"img":false}]}
{"op":"mcm","clk":"5306860289","pt":1646108278440,"mc":[{"id":"1.195395428","rc":[{"atb":[[2.12,0]],"id":38407646},{"atb":[[2.12,0]],"id":43154456},{"atb":[[1.3,0]],"id":43154457},{"atl":[[30,0]],"id":37279191}],"con":true,"img":false}]}
{"op":"mcm","clk":"5306860292","pt":1646108278543,"mc":[{"id":"1.195395428","rc":[{"atb":[[2.18,46.02]],"id":38407646},{"atb":[[2.18,46.02]],"id":43154456},{"atb":[[1.34,86.06]],"id":43154457},{"atl":[[23,2.7]],"id":37279191}],"con":true,"img":false}]}
{"op":"mcm","clk":"5306860387","pt":1646108281721,"mc":[{"id":"1.195395428","rc":[{"atb":[[2.16,28.82]],"id":38407646},{"atb":[[2.16,26.7]],"id":43154456},{"atb":[[1.33,25.29]],"id":43154457}],"con":true,"img":false}]}
{"op":"mcm","clk":"5306860583","pt":1646108287617,"mc":[{"id":"1.195395428","rc":[{"atb":[[2.24,7.68]],"id":38407646},{"atb":[[1.37,20.16]],"id":43154457}],"con":true,"img":false}]}
{"op":"mcm","clk":"5306860586","pt":1646108287718,"mc":[{"id":"1.195395428","rc":[{"atb":[[2.24,7.68]],"id":43154456}],"con":true,"img":false}]}
{"op":"mcm","clk":"5306860669","pt":1646108290121,"mc":[{"id":"1.195395428","rc":[{"atb":[[1.43,129.58]],"id":36087680}],"con":true,"img":false}]}
{"op":"mcm","clk":"5306860690","pt":1646108290735,"mc":[{"id":"1.195395428","rc":[{"atb":[[1.46,55.99]],"id":36087680}],"con":true,"img":false}]}
{"op":"mcm","clk":"5306860818","pt":1646108294221,"mc":[{"id":"1.195395428","rc":[{"atb":[[2.16,21.63]],"id":38407646},{"atb":[[2.16,19.51]],"id":43154456},{"atb":[[1.33,0]],"id":43154457}],"con":true,"img":false}]}
{"op":"mcm","clk":"5306860959","pt":1646108299851,"mc":[{"id":"1.195395428","rc":[{"atb":[[2.18,0]],"id":38407646},{"atb":[[2.18,0]],"id":43154456},{"atl":[[7.6,0]],"id":43154456},{"atl":[[130,0]],"id":42130949},{"atb":[[1.25,242.05]],"id":43154457},{"atl":[[36,0]],"id":37279191}],"con":true,"img":false}]}
{"op":"mcm","clk":"5306860960","pt":1646108299955,"mc":[{"id":"1.195395428","rc":[{"atb":[[2.12,46.02]],"id":38407646},{"atb":[[2.12,46.02]],"id":43154456},{"atl":[[6.6,10.37]],"id":43154456},{"atl":[[55,2.7]],"id":42130949},{"atb":[[1.28,220.63]],"id":43154457},{"atl":[[26,2.7]],"id":37279191}],"con":true,"img":false}]}
{"op":"mcm","clk":"5306860965","pt":1646108300058,"mc":[{"id":"1.195395428","rc":[{"atb":[[2.24,19.74],[2.26,3.01]],"id":38407646},{"atb":[[2.24,14.41]],"id":43154456},{"atl":[[5.3,34.26],[5.2,3.08]],"id":43154456},{"atb":[[1.41,22.14]],"id":43154457},{"atl":[[19.5,10.81]],"id":37279191},{"atb":[[1.49,21.58]],"id":36087680}],"con":true,"img":false}]}
{"op":"mcm","clk":"5306860968","pt":1646108300161,"mc":[{"id":"1.195395428","rc":[{"atl":[[5.1,7.46],[5.3,31.47]],"id":43154456},{"atb":[[1.37,42.72]],"id":43154457}],"con":true,"img":false}]}
{"op":"mcm","clk":"5306860969","pt":1646108300263,"mc":[{"id":"1.195395428","rc":[{"atb":[[2.24,26.47]],"id":38407646}],"con":true,"img":false}]}
{"op":"mcm","clk":"5306860982","pt":1646108300978,"mc":[{"id":"1.195395428","rc":[{"atb":[[2.3,2.17],[2.22,0]],"id":38407646},{"atb":[[2.3,2.17],[2.22,0]],"id":43154456}],"con":true,"img":false}]}
{"op":"mcm","clk":"5306861028","pt":1646108302767,"mc":[{"id":"1.195395428","rc":[{"atb":[[2.24,20.46]],"id":38407646},{"atb":[[2.24,8.39]],"id":43154456}],"con":true,"img":false}]}
{"op":"mcm","clk":"5306861114","pt":1646108305273,"mc":[{"id":"1.195395428","rc":[{"atb":[[2.24,18.79]],"id":38407646},{"atb":[[2.24,6.72]],"id":43154456}],"con":true,"img":false}]}
{"op":"mcm","clk":"5306861120","pt":1646108305479,"mc":[{"id":"1.195395428","rc":[{"atb":[[2.32,1.66]],"id":38407646},{"atb":[[2.32,1.66]],"id":43154456}],"con":true,"img":false}]}
{"op":"mcm","clk":"5306861222","pt":1646108308662,"mc":[{"id":"1.195395428","rc":[{"atb":[[2.16,28.06]],"id":38407646},{"atb":[[2.16,25.94]],"id":43154456}],"con":true,"img":false}]}
{"op":"mcm","clk":"5306861288","pt":1646108311299,"mc":[{"id":"1.195395428","rc":[{"atl":[[5.3,32.75],[5.2,2.7]],"id":38407646},{"atl":[[5,3.08]],"id":43154456},{"atl":[[2.42,5.57]],"id":43154457},{"atb":[[6,34.27]],"id":37279191}],"con":true,"img":false}]}
{"op":"mcm","clk":"5306861293","pt":1646108311476,"mc":[{"id":"1.195395428","rc":[{"atl":[[4.9,3.09]],"id":43154456}],"con":true,"img":false}]}
{"op":"mcm","clk":"5306861295","pt":1646108311578,"mc":[{"id":"1.195395428","rc":[{"atl":[[5.1,0]],"id":43154456}],"con":true,"img":false}]}
{"op":"mcm","clk":"5306861349","pt":1646108313675,"mc":[{"id":"1.195395428","rc":[{"atb":[[2.16,6.42]],"id":38407646},{"atb":[[2.16,6.42]],"id":43154456}],"con":true,"img":false}]}
{"op":"mcm","clk":"5306861359","pt":1646108313981,"mc":[{"id":"1.195395428","rc":[{"atb":[[2.24,40.42]],"id":38407646},{"atb":[[2.24,21.62]],"id":43154456}],"con":true,"img":false}]}
{"op":"mcm","clk":"5306861371","pt":1646108314755,"mc":[{"id":"1.195395428","rc":[{"atb":[[2.16,0]],"id":38407646}],"con":true,"img":false}]}
{"op":"mcm","clk":"5306861472","pt":1646108318174,"mc":[{"id":"1.195395428","rc":[{"atb":[[2.24,33.69]],"id":38407646},{"atb":[[2.24,14.89]],"id":43154456}],"con":true,"img":false}]}
{"op":"mcm","clk":"5306861539","pt":1646108320578,"mc":[{"id":"1.195395428","rc":[{"atl":[[60,3.6]],"id":42130949},{"atb":[[1.43,44.82],[1.32,190.53]],"id":36087680},{"atl":[[2.42,30.46]],"id":36087680}],"con":true,"img":false}]}
{"op":"mcm","clk":"5306861543","pt":1646108320678,"mc":[{"id":"1.195395428","rc":[{"atb":[[2.3,7.9]],"id":38407646},{"atl":[[50,2.7]],"id":42130949},{"atb":[[1.28,0],[1.47,84.76]],"id":36087680},{"atl":[[2.82,0]],"id":36087680}],"con":true,"img":false}]}
{"op":"mcm","clk":"5306861546","pt":1646108320782,"mc":[{"id":"1.195395428","rc":[{"atl":[[50,4.74]],"id":42130949}],"con":true,"img":false}]}
{"op":"mcm","clk":"5306861550","pt":1646108320883,"mc":[{"id":"1.195395428","rc":[{"atl":[[60,1.6]],"id":42130949}],"con":true,"img":false}]}
{"op":"mcm","clk":"5306861630","pt":1646108323802,"mc":[{"id":"1.195395428","rc":[{"spn":3.76,"spf":"NaN","id":38407646},{"spn":3.61,"spf":"NaN","id":43154456},{"spn":30.5,"spf":"NaN","id":42130949},{"spn":1.91,"spf":"NaN","id":43154457},{"atb":[[1.46,39.78]],"id":36087680},{"spn":1.95,"spf":"NaN","id":36087680}],"con":true,"img":false}]}
{"op":"mcm","clk":"5306861631","pt":1646108324106,"mc":[{"id":"1.195395428","rc":[{"atb":[[2.16,13.62]],"id":43154456}],"con":true,"img":false}]}
{"op":"mcm","clk":"5306861633","pt":1646108324209,"mc":[{"id":"1.195395428","rc":[{"atb":[[2.16,7.19]],"id":38407646}],"con":true,"img":false}]}
{"op":"mcm","clk":"5306861784","pt":1646108329680,"mc":[{"id":"1.195395428","rc":[{"atb":[[1.5,14.91]],"id":36087680}],"con":true,"img":false}]}
{"op":"mcm","clk":"5306861791","pt":1646108329886,"mc":[{"id":"1.195395428","rc":[{"atb":[[1.49,19.41],[1.53,2.17]],"id":36087680}],"con":true,"img":false}]}
{"op":"mcm","clk":"5306861812","pt":1646108330499,"mc":[{"id":"1.195395428","rc":[{"atl":[[5.3,16.4]],"id":38407646},{"atl":[[5.3,15.12]],"id":43154456},{"atl":[[60,0]],"id":42130949},{"atb":[[1.38,0]],"id":43154457},{"atb":[[1.46,18.14]],"id":36087680}],"con":true,"img":false}]}
{"op":"mcm","clk":"5306861824","pt":1646108330806,"mc":[{"id":"1.195395428","rc":[{"atl":[[5.2,19.44]],"id":38407646},{"atl":[[4.9,21.11]],"id":43154456},{"atl":[[55,4.45]],"id":42130949},{"atb":[[1.41,43.77]],"id":43154457},{"atb":[[1.49,41.05]],"id":36087680}],"con":true,"img":false}]}
{"op":"mcm","clk":"5306861826","pt":1646108330909,"mc":[{"id":"1.195395428","rc":[{"atl":[[5.1,16.41],[5.3,13.61]],"id":38407646}],"con":true,"img":false}]}
{"op":"mcm","clk":"5306861967","pt":1646108336087,"mc":[{"id":"1.195395428","rc":[{"atb":[[1.46,0]],"id":36087680}],"con":true,"img":false}]}
{"op":"mcm","clk":"5306862042","pt":1646108338798,"mc":[{"id":"1.195395428","rc":[{"atb":[[1.96,0]],"id":38407646},{"atl":[[6.2,0],[7.6,0],[8.8,29.67]],"id":38407646},{"atb":[[1.77,0]],"id":43154456},{"atl":[[6.2,0],[6.6,2.14],[8.4,30.25]],"id":43154456},{"atb":[[8.4,13.48],[9.4,0]],"id":42130949},{"atl":[[50,2.86],[55,1.75]],"id":42130949},{"atb":[[1.28,0],[1.21,145.26],[1.34,0]],"id":43154457},{"atl":[[2.54,0],[4.1,61.74],[3.3,0]],"id":43154457},{"atb":[[5.1,0],[3.75,31.15]],"id":37279191},{"atl":[[40,7.67],[26,0]],"id":37279191},{"atb":[[1.32,0],[1.29,91.99]],"id":36087680},{"atl":[[2.42,0],[3.3,0],[4.2,58.98]],"id":36087680}],"con":true,"img":false}]}
{"op":"mcm","clk":"5306862044","pt":1646108338899,"mc":[{"id":"1.195395428","rc":[{"atb":[[1.72,61.25]],"id":38407646},{"atl":[[5.2,26.89]],"id":38407646},{"atb":[[1.72,70.58]],"id":43154456},{"atl":[[5.2,10.53]],"id":43154456},{"atl":[[170,2.7],[55,3.75]],"id":42130949},{"atb":[[1.39,86.06]],"id":43154457},{"atl":[[2.42,37.96]],"id":43154457},{"atl":[[2.62,30.46]],"id":36087680}],"con":true,"img":false}]}
{"op":"mcm","clk":"5306862046","pt":1646108339000,"mc":[{"id":"1.195395428","rc":[{"atl":[[50,0.82]],"id":42130949}],"con":true,"img":false}]}
{"op":"mcm","clk":"5306862082","pt":1646108340633,"mc":[{"id":"1.195395428","rc":[{"atb":[[2.24,12.06]],"id":38407646},{"atl":[[5.2,10.16]],"id":38407646},{"atl":[[55,2]],"id":42130949},{"atl":[[2.44,8.27]],"id":36087680}],"con":true,"img":false}]}
{"op":"mcm","clk":"5306862087","pt":1646108340735,"mc":[{"id":"1.195395428","rc":[{"atl":[[80,2.15],[55,0]],"id":42130949}],"con":true,"img":false}]}
{"op":"mcm","clk":"5306862090","pt":1646108340889,"mc":[{"id":"1.195395428","rc":[{"atb":[[2.3,29.53]],"id":38407646},{"atl":[[5.1,33.55]],"id":38407646},{"atl":[[50,2.75]],"id":42130949},{"atl":[[2.42,21.63]],"id":36087680}],"con":true,"img":false}]}
{"op":"mcm","clk":"5306862110","pt":1646108341607,"mc":[{"id":"1.195395428","rc":[{"atb":[[2.12,0],[2.26,35.19]],"id":38407646},{"atl":[[50,1.93]],"id":42130949},{"atl":[[23,0]],"id":37279191},{"atb":[[1.26,112.31],[1.29,0]],"id":36087680}],"con":true,"img":false}]}
{"op":"mcm","clk":"5306862113","pt":1646108341709,"mc":[{"id":"1.195395428","rc":[{"atl":[[60,0.82]],"id":42130949},{"atl":[[19,2.7]],"id":37279191}],"con":true,"img":false}]}
{"op":"mcm","clk":"5306862121","pt":1646108341913,"mc":[{"id":"1.195395428","rc":[{"atb":[[2.3,23.8]],"id":38407646},{"atb":[[1.37,22.56]],"id":43154457}],"con":true,"img":false}]}
{"op":"mcm","clk":"5306862126","pt":1646108342116,"mc":[{"id":"1.195395428","rc":[{"atb":[[1.5,31.61]],"id":36087680}],"con":true,"img":false}]}
{"op":"mcm","clk":"5306862257","pt":1646108347735,"mc":[{"id":"1.195395428","rc":[{"atb":[[1.42,17.76]],"id":43154457}],"con":true,"img":false}]}
{"op":"mcm","clk":"5306862265","pt":1646108348502,"mc":[{"id":"1.195395428","rc":[{"atb":[[1.41,41.6],[1.45,2.17]],"id":43154457}],"con":true,"img":false}]}
{"op":"mcm","clk":"5306862306","pt":1646108350748,"mc":[{"id":"1.195395428","rc":[{"atb":[[2.32,7.32]],"id":38407646}],"con":true,"img":false}]}
{"op":"mcm","clk":"5306862391","pt":1646108354736,"mc":[{"id":"1.195395428","rc":[{"atl":[[2.56,0],[2.48,67.57]],"id":43154457}],"con":true,"img":false}]}
{"op":"mcm","clk":"5306862402","pt":1646108355253,"mc":[{"id":"1.195395428","rc":[{"atb":[[1.37,0]],"id":43154457}],"con":true,"img":false}]}
{"op":"mcm","clk":"5306862429","pt":1646108356227,"mc":[{"id":"1.195395428","rc":[{"atl":[[5,2.7]],"id":38407646},{"atl":[[4.8,3.09]],"id":43154456},{"atb":[[1.45,22.11]],"id":43154457},{"atl":[[2.4,5.1],[2.42,35.15]],"id":36087680}],"con":true,"img":false}]}
{"op":"mcm","clk":"5306862430","pt":1646108356327,"mc":[{"id":"1.195395428","rc":[{"atl":[[4.9,18.02],[4.7,3.09]],"id":43154456}],"con":true,"img":false}]}
{"op":"mcm","clk":"5306862439","pt":1646108356839,"mc":[{"id":"1.195395428","rc":[{"atl":[[2.44,8.27]],"id":43154457},{"atl":[[19.5,7.01]],"id":37279191},{"atb":[[1.49,19.41]],"id":36087680}],"con":true,"img":false}]}
{"op":"mcm","clk":"5306862457","pt":1646108357554,"mc":[{"id":"1.195395428","rc":[{"atl":[[2.42,59.59]],"id":43154457},{"atl":[[19,6.6]],"id":37279191},{"atb":[[1.5,53.24]],"id":36087680}],"con":true,"img":false}]}
{"op":"mcm","clk":"5306862480","pt":1646108358424,"mc":[{"id":"1.195395428","rc":[{"atb":[[1.71,0],[1.76,131.58]],"id":43154456},{"atb":[[4.8,0],[5.4,22.73]],"id":42130949},{"atb":[[5,55.17],[4.4,0]],"id":37279191}],"con":true,"img":false}]}
{"op":"mcm","clk":"5306862538","pt":1646108360267,"mc":[{"id":"1.195395428","rc":[{"atb":[[1.42,37.63]],"id":43154457}],"con":true,"img":false}]}
{"op":"mcm","clk":"5306862541","pt":1646108360370,"mc":[{"id":"1.195395428","rc":[{"atb":[[2.16,0]],"id":38407646}],"con":true,"img":false}]}
{"op":"mcm","clk":"5306862599","pt":1646108362364,"mc":[{"id":"1.195395428","rc":[{"atl":[[4.8,13.76],[5.2,3.08]],"id":43154456}],"con":true,"img":false}]}
{"op":"mcm","clk":"5306862603","pt":1646108362466,"mc":[{"id":"1.195395428","rc":[{"atb":[[2.26,3.01]],"id":38407646},{"atl":[[5.2,2.7]],"id":38407646},{"atb":[[1.39,0]],"id":43154457},{"atb":[[1.47,0]],"id":36087680},{"atl":[[2.62,0]],"id":36087680}],"con":true,"img":false}]}
{"op":"mcm","clk":"5306862608","pt":1646108362569,"mc":[{"id":"1.195395428","rc":[{"atb":[[2.32,39.51]],"id":38407646},{"atl":[[5,10.16]],"id":38407646},{"atb":[[1.43,86.06]],"id":43154457},{"atb":[[1.51,84.76]],"id":36087680},{"atl":[[2.4,35.57]],"id":36087680}],"con":true,"img":false}]}
{"op":"mcm","clk":"5306862616","pt":1646108362727,"mc":[{"id":"1.195395428","rc":[{"atb":[[2.32,33.85]],"id":38407646},{"atb":[[1.42,19.87]],"id":43154457},{"atb":[[1.5,38.32]],"id":36087680}],"con":true,"img":false}]}
{"op":"mcm","clk":"5306862625","pt":1646108362932,"mc":[{"id":"1.195395428","rc":[{"atb":[[2.3,21.63],[2.38,2.17]],"id":38407646}],"con":true,"img":false}]}
{"op":"mcm","clk":"5306862692","pt":1646108365232,"mc":[{"id":"1.195395428","rc":[{"atb":[[2.32,32.18]],"id":38407646}],"con":true,"img":false}]}
{"op":"mcm","clk":"5306862697","pt":1646108365435,"mc":[{"id":"1.195395428","rc":[{"atb":[[2.4,1.66]],"id":38407646}],"con":true,"img":false}]}
{"op":"mcm","clk":"5306862750","pt":1646108366970,"mc":[{"id":"1.195395428","rc":[{"atl":[[5.1,17.14],[4.9,10.16]],"id":38407646}],"con":true,"img":false}]}
{"op":"mcm","clk":"5306862764","pt":1646108367540,"mc":[{"id":"1.195395428","rc":[{"atb":[[2.3,0]],"id":38407646},{"atl":[[5.1,0]],"id":38407646},{"atl":[[4.9,0]],"id":43154456},{"atb":[[1.41,19.97]],"id":43154457}],"con":true,"img":false}]}
{"op":"mcm","clk":"5306862776","pt":1646108368354,"mc":[{"id":"1.195395428","rc":[{"atb":[[2.32,53.81]],"id":38407646},{"atl":[[5,27.73]],"id":38407646},{"atl":[[4.7,22.09]],"id":43154456},{"atb":[[1.45,43.75]],"id":43154457}],"con":true,"img":false}]}
{"op":"mcm","clk":"5306862857","pt":1646108371739,"mc":[{"id":"1.195395428","rc":[{"atb":[[2.38,7.57]],"id":38407646},{"atb":[[1.46,16.21]],"id":43154457},{"atb":[[1.54,13.81]],"id":36087680}],"con":true,"img":false}]}
{"op":"mcm","clk":"5306862896","pt":1646108373268,"mc":[{"id":"1.195395428","rc":[{"atb":[[1.49,2.17]],"id":43154457},{"atb":[[1.57,2.17]],"id":36087680}],"con":true,"img":false}]}
{"op":"mcm","clk":"5306862900","pt":1646108373373,"mc":[{"id":"1.195395428","rc":[{"atb":[[1.45,41.58]],"id":43154457},{"atb":[[1.53,0]],"id":36087680}],"con":true,"img":false}]}
{"op":"mcm","clk":"5306862928","pt":1646108374546,"mc":[{"id":"1.195395428","rc":[{"atb":[[2.32,32.18]],"id":38407646},{"atl":[[5,10.16]],"id":38407646},{"atb":[[1.5,16.69]],"id":36087680},{"atl":[[2.42,13.51]],"id":36087680}],"con":true,"img":false}]}
{"op":"mcm","clk":"5306862938","pt":1646108374956,"mc":[{"id":"1.195395428","rc":[{"atb":[[2.38,29.2]],"id":38407646},{"atl":[[4.9,28.18]],"id":38407646},{"atb":[[1.51,106.39]],"id":36087680},{"atl":[[2.4,57.2]],"id":36087680}],"con":true,"img":false}]}
{"op":"mcm","clk":"5306862961","pt":1646108376645,"mc":[{"id":"1.195395428","rc":[{"atl":[[80,0.15],[50,3.93]],"id":42130949}],"con":true,"img":false}]}
{"op":"mcm","clk":"5306862962","pt":1646108376748,"mc":[{"id":"1.195395428","rc":[{"atl":[[80,2.15],[50,1.93]],"id":42130949}],"con":true,"img":false}]}
{"op":"mcm","clk":"5306862965","pt":1646108376851,"mc":[{"id":"1.195395428","rc":[{"atl":[[80,0.15],[50,3.93]],"id":42130949}],"con":true,"img":false}]}
{"op":"mcm","clk":"5306862967","pt":1646108376951,"mc":[{"id":"1.195395428","rc":[{"atl":[[80,2.15]],"id":42130949}],"con":true,"img":false}]}
{"op":"mcm","clk":"5306862970","pt":1646108377054,"mc":[{"id":"1.195395428","rc":[{"atl":[[50,1.93]],"id":42130949}],"con":true,"img":false}]}
{"op":"mcm","clk":"5306862973","pt":1646108377159,"mc":[{"id":"1.195395428","rc":[{"atl":[[80,0.15],[50,3.97]],"id":42130949}],"con":true,"img":false}]}
{"op":"mcm","clk":"5306862977","pt":1646108377260,"mc":[{"id":"1.195395428","rc":[{"atl":[[80,2.15],[50,1.93]],"id":42130949}],"con":true,"img":false}]}
{"op":"mcm","clk":"5306862999","pt":1646108378488,"mc":[{"id":"1.195395428","rc":[{"atb":[[1.42,0]],"id":43154457},{"atb":[[1.5,0]],"id":36087680}],"con":true,"img":false}]}
{"op":"mcm","clk":"5306863122","pt":1646108383450,"mc":[{"id":"1.195395428","rc":[{"atb":[[1.72,0]],"id":43154456},{"atb":[[8.4,0]],"id":42130949},{"atl":[[4.1,0]],"id":43154457},{"atl":[[19,3.9]],"id":37279191},{"atl":[[4.2,0]],"id":36087680}],"con":true,"img":false}]}
{"op":"mcm","clk":"5306863127","pt":1646108383552,"mc":[{"id":"1.195395428","rc":[{"atb":[[1.77,70.58]],"id":43154456},{"atb":[[9.4,13.48]],"id":42130949},{"atl":[[3.55,61.74]],"id":43154457},{"atl":[[18.5,2.7]],"id":37279191},{"atl":[[3.55,58.98]],"id":36087680}],"con":true,"img":false}]}
{"op":"mcm","clk":"5306863147","pt":1646108384267,"mc":[{"id":"1.195395428","rc":[{"spn":3.65,"spf":"NaN","id":38407646},{"spn":3.51,"spf":"NaN","id":43154456},{"atb":[[1.46,34.36]],"id":43154457},{"spn":1.95,"spf":"NaN","id":43154457},{"spn":12.25,"spf":"NaN","id":37279191},{"spn":1.98,"spf":"NaN","id":36087680}],"con":true,"img":false}]}
{"op":"mcm","clk":"5306863151","pt":1646108384472,"mc":[{"id":"1.195395428","rc":[{"atb":[[1.54,29.27]],"id":36087680}],"con":true,"img":false}]}
{"op":"mcm","clk":"5306863292","pt":1646108390301,"mc":[{"id":"1.195395428","rc":[{"atb":[[2.14,7.32]],"id":38407646}],"con":true,"img":false}]}
{"op":"mcm","clk":"5306863296","pt":1646108390709,"mc":[{"id":"1.195395428","rc":[{"atb":[[1.45,19.94]],"id":43154457},{"atl":[[19,0]],"id":37279191},{"atb":[[1.51,84.76]],"id":36087680}],"con":true,"img":false}]}
{"op":"mcm","clk":"5306863310","pt":1646108391067,"mc":[{"id":"1.195395428","rc":[{"atb":[[1.46,55.99]],"id":43154457},{"atl":[[18.5,6.72]],"id":37279191},{"atb":[[1.54,50.9]],"id":36087680}],"con":true,"img":false}]}
{"op":"mcm","clk":"5306863657","pt":1646108403698,"mc":[{"id":"1.195395428","rc":[{"atb":[[2.32,0]],"id":38407646},{"atl":[[4.8,3.09]],"id":43154456},{"atb":[[1.43,0]],"id":43154457},{"atb":[[1.51,0]],"id":36087680},{"atl":[[2.4,26.73]],"id":36087680}],"con":true,"img":false}]}
{"op":"mcm","clk":"5306863660","pt":1646108403802,"mc":[{"id":"1.195395428","rc":[{"atb":[[2.4,33.85]],"id":38407646},{"atl":[[4.8,10.67],[5,2.7]],"id":38407646},{"atl":[[4.6,10.67]],"id":43154456},{"atb":[[1.47,86.06]],"id":43154457},{"atb":[[1.55,84.76]],"id":36087680},{"atl":[[2.38,30.46]],"id":36087680}],"con":true,"img":false}]}
{"op":"mcm","clk":"5306863662","pt":1646108403901,"mc":[{"id":"1.195395428","rc":[{"atl":[[4.7,10.67]],"id":38407646},{"atl":[[4.5,10.67],[4.7,19]],"id":43154456}],"con":true,"img":false}]}
{"op":"mcm","clk":"5306863664","pt":1646108404003,"mc":[{"id":"1.195395428","rc":[{"atl":[[4.9,18.02]],"id":38407646}],"con":true,"img":false}]}
{"op":"mcm","clk":"5306863670","pt":1646108404311,"mc":[{"id":"1.195395428","rc":[{"atb":[[2.38,27.03],[2.46,2.17]],"id":38407646}],"con":true,"img":false}]}
{"op":"mcm","clk":"5306863691","pt":1646108404925,"mc":[{"id":"1.195395428","rc":[{"atb":[[2.38,21.63]],"id":38407646},{"atb":[[1.46,39.78]],"id":43154457},{"atb":[[1.54,37.09]],"id":36087680}],"con":true,"img":false}]}
{"op":"mcm","clk":"5306863705","pt":1646108405288,"mc":[{"id":"1.195395428","rc":[{"atb":[[2.4,32.18]],"id":38407646}],"con":true,"img":false}]}
{"op":"mcm","clk":"5306863710","pt":1646108405391,"mc":[{"id":"1.195395428","rc":[{"atb":[[2.48,1.66]],"id":38407646}],"con":true,"img":false}]}
{"op":"mcm","clk":"5306863842","pt":1646108410815,"mc":[{"id":"1.195395428","rc":[{"atb":[[2.46,7.28]],"id":38407646},{"atb":[[1.5,14.91]],"id":43154457},{"atb":[[1.59,12.64]],"id":36087680}],"con":true,"img":false}]}
{"op":"mcm","clk":"5306863896","pt":1646108412302,"mc":[{"id":"1.195395428","rc":[{"atb":[[2.38,0]],"id":38407646},{"atl":[[4.9,0]],"id":38407646},{"atl":[[4.7,0]],"id":43154456},{"atb":[[1.46,18.14]],"id":43154457},{"atb":[[1.54,15.46]],"id":36087680},{"atl":[[2.4,5.1]],"id":36087680}],"con":true,"img":false}]}
{"op":"mcm","clk":"5306863897","pt":1646108412404,"mc":[{"id":"1.195395428","rc":[{"atb":[[2.46,28.91]],"id":38407646},{"atl":[[4.7,27.43]],"id":38407646},{"atl":[[4.5,30.75]],"id":43154456},{"atb":[[1.47,107.69]],"id":43154457},{"atb":[[1.55,106.39]],"id":36087680},{"atl":[[2.38,52.09]],"id":36087680}],"con":true,"img":false}]}
{"op":"mcm","clk":"5306863905","pt":1646108412816,"mc":[{"id":"1.195395428","rc":[{"atl":[[80,0.15],[50,3.93]],"id":42130949}],"con":true,"img":false}]}
{"op":"mcm","clk":"5306863955","pt":1646108414710,"mc":[{"id":"1.195395428","rc":[{"atb":[[1.49,0],[1.53,2.17]],"id":43154457},{"atb":[[1.57,0],[1.62,2.17]],"id":36087680}],"con":true,"img":false}]}
{"op":"mcm","clk":"5306864013","pt":1646108416605,"mc":[{"id":"1.195395428","rc":[{"atl":[[2.42,119.18],[2.48,0]],"id":43154457},{"atl":[[25,4.17],[27,0]],"id":37279191}],"con":true,"img":false}]}
{"op":"mcm","clk":"5306864102","pt":1646108420393,"mc":[{"id":"1.195395428","rc":[{"atb":[[1.46,0]],"id":43154457},{"atb":[[1.54,0]],"id":36087680}],"con":true,"img":false}]}
{"op":"mcm","clk":"5306864225","pt":1646108424133,"mc":[{"id":"1.195395428","rc":[{"atl":[[18.5,4.01]],"id":37279191}],"con":true,"img":false}]}
{"op":"mcm","clk":"5306864228","pt":1646108424236,"mc":[{"id":"1.195395428","rc":[{"atl":[[18,2.7]],"id":37279191}],"con":true,"img":false}]}
{"op":"mcm","clk":"5306864262","pt":1646108425211,"mc":[{"id":"1.195395428","rc":[{"atb":[[2.48,0]],"id":38407646},{"atb":[[2.32,0]],"id":43154456}],"con":true,"img":false}]}
{"op":"mcm","clk":"5306864300","pt":1646108426337,"mc":[{"id":"1.195395428","rc":[{"atl":[[18.5,0]],"id":37279191}],"con":true,"img":false}]}
{"op":"mcm","clk":"5306864302","pt":1646108426440,"mc":[{"id":"1.195395428","rc":[{"atb":[[1.5,31.61]],"id":43154457}],"con":true,"img":false}]}
{"op":"mcm","clk":"5306864305","pt":1646108426541,"mc":[{"id":"1.195395428","rc":[{"atl":[[18,6.84]],"id":37279191}],"con":true,"img":false}]}
{"op":"mcm","clk":"5306864309","pt":1646108426596,"mc":[{"id":"1.195395428","rc":[{"atb":[[1.59,26.79]],"id":36087680}],"con":true,"img":false}]}
{"op":"mcm","clk":"5306864430","pt":1646108431202,"mc":[{"id":"1.195395428","rc":[{"atb":[[1.47,86.06]],"id":43154457},{"atb":[[1.55,84.76]],"id":36087680}],"con":true,"img":false}]}
{"op":"mcm","clk":"5306864436","pt":1646108431410,"mc":[{"id":"1.195395428","rc":[{"atb":[[1.5,53.24]],"id":43154457},{"atb":[[1.59,48.42]],"id":36087680}],"con":true,"img":false}]}
{"op":"mcm","clk":"5306864825","pt":1646108445029,"mc":[{"id":"1.195395428","rc":[{"atb":[[2.4,0]],"id":38407646},{"atl":[[4.8,0]],"id":38407646},{"spn":3.58,"spf":"NaN","id":38407646},{"atl":[[4.6,0]],"id":43154456},{"spn":3.4,"spf":"NaN","id":43154456},{"atl":[[60,0]],"id":42130949},{"atb":[[1.47,0]],"id":43154457},{"spn":1.97,"spf":"NaN","id":43154457},{"spn":12.0,"spf":"NaN","id":37279191},{"atb":[[1.55,0]],"id":36087680},{"spn":2.0,"spf":"NaN","id":36087680}],"con":true,"img":false}]}
{"op":"mcm","clk":"5306864828","pt":1646108445131,"mc":[{"id":"1.195395428","rc":[{"atb":[[2.48,32.18]],"id":38407646},{"atl":[[4.6,10.67]],"id":38407646},{"atl":[[4.4,10.67]],"id":43154456},{"atl":[[48,0.82]],"id":42130949},{"atb":[[1.51,86.06]],"id":43154457},{"atb":[[1.6,84.76]],"id":36087680}],"con":true,"img":false}]}
{"op":"mcm","clk":"5306864832","pt":1646108445336,"mc":[{"id":"1.195395428","rc":[{"atl":[[4.5,10.67],[4.7,16.76]],"id":38407646},{"atl":[[4.5,20.08],[4.3,10.67]],"id":43154456}],"con":true,"img":false}]}
{"op":"mcm","clk":"5306864886","pt":1646108446973,"mc":[{"id":"1.195395428","rc":[{"atb":[[2.46,23.8]],"id":38407646},{"atb":[[1.5,38.32]],"id":43154457},{"atb":[[1.59,35.78]],"id":36087680}],"con":true,"img":false}]}
{"op":"mcm","clk":"5306864951","pt":1646108449175,"mc":[{"id":"1.195395428","rc":[{"atb":[[2.46,2.17]],"id":38407646},{"atl":[[4.7,0]],"id":38407646},{"atl":[[4.5,0]],"id":43154456},{"atl":[[50,2]],"id":42130949},{"atb":[[1.5,16.69]],"id":43154457},{"atb":[[1.59,14.15]],"id":36087680}],"con":true,"img":false}]}
{"op":"mcm","clk":"5306864953","pt":1646108449277,"mc":[{"id":"1.195395428","rc":[{"atl":[[80,2.15]],"id":42130949}],"con":true,"img":false}]}
{"op":"mcm","clk":"5306864957","pt":1646108449379,"mc":[{"id":"1.195395428","rc":[{"atb":[[2.48,53.22]],"id":38407646},{"atl":[[4.5,25.99]],"id":38407646},{"atl":[[4.3,31.97]],"id":43154456},{"atl":[[48,2.83],[50,0]],"id":42130949},{"atb":[[1.51,107.69]],"id":43154457},{"atb":[[1.6,106.39]],"id":36087680}],"con":true,"img":false}]}
{"op":"mcm","clk":"5306864963","pt":1646108449536,"mc":[{"id":"1.195395428","rc":[{"atl":[[80,0.15],[48,4.96]],"id":42130949}],"con":true,"img":false}]}
{"op":"mcm","clk":"5306864966","pt":1646108449637,"mc":[{"id":"1.195395428","rc":[{"atl":[[160,2.07],[48,2.83]],"id":42130949}],"con":true,"img":false}]}
{"op":"mcm","clk":"5306865056","pt":1646108453072,"mc":[{"id":"1.195395428","rc":[{"atb":[[2.54,4.84]],"id":38407646},{"atb":[[1.54,13.81]],"id":43154457},{"atb":[[1.64,11.65]],"id":36087680}],"con":true,"img":false}]}
{"op":"mcm","clk":"5306865081","pt":1646108453786,"mc":[{"id":"1.195395428","rc":[{"atb":[[1.57,2.17],[1.53,0]],"id":43154457},{"atb":[[1.67,2.17],[1.62,0]],"id":36087680}],"con":true,"img":false}]}
{"op":"mcm","clk":"5306865338","pt":1646108462488,"mc":[{"id":"1.195395428","rc":[{"atb":[[2.14,0]],"id":38407646},{"atb":[[1.5,0]],"id":43154457},{"atb":[[1.59,0]],"id":36087680}],"con":true,"img":false}]}
{"op":"mcm","clk":"5306865406","pt":1646108464900,"mc":[{"id":"1.195395428","rc":[{"atb":[[11,0]],"id":42130949},{"atl":[[48,2.01]],"id":42130949},{"atb":[[3.75,0]],"id":37279191},{"atl":[[18,4.13]],"id":37279191}],"con":true,"img":false}]}
{"op":"mcm","clk":"5306865408","pt":1646108465001,"mc":[{"id":"1.195395428","rc":[{"atb":[[12,3.6]],"id":42130949},{"atl":[[160,0.07],[48,4.02],[55,0.82]],"id":42130949},{"atb":[[4,31.15]],"id":37279191},{"atl":[[17.5,2.7]],"id":37279191}],"con":true,"img":false}]}
{"op":"mcm","clk":"5306865410","pt":1646108465104,"mc":[{"id":"1.195395428","rc":[{"atl":[[160,2.07]],"id":42130949}],"con":true,"img":false}]}
{"op":"mcm","clk":"5306865414","pt":1646108465159,"mc":[{"id":"1.195395428","rc":[{"atl":[[48,2.01]],"id":42130949}],"con":true,"img":false}]}
{"op":"mcm","clk":"5306865417","pt":1646108465262,"mc":[{"id":"1.195395428","rc":[{"atl":[[80,2.15],[160,0.07]],"id":42130949}],"con":true,"img":false}]}
{"op":"mcm","clk":"5306865420","pt":1646108465361,"mc":[{"id":"1.195395428","rc":[{"atl":[[80,0.15],[48,4.02]],"id":42130949}],"con":true,"img":false}]}
{"op":"mcm","clk":"5306865522","pt":1646108468790,"mc":[{"id":"1.195395428","rc":[{"atl":[[18,0]],"id":37279191}],"con":true,"img":false}]}
{"op":"mcm","clk":"5306865525","pt":1646108468893,"mc":[{"id":"1.195395428","rc":[{"atl":[[17.5,6.96]],"id":37279191}],"con":true,"img":false}]}
{"op":"mcm","clk":"5306865954","pt":1646108484226,"mc":[{"id":"1.195395428","rc":[{"atb":[[2.48,21.03]],"id":38407646},{"atl":[[4.6,0]],"id":38407646},{"atl":[[4.4,0]],"id":43154456},{"atl":[[55,0]],"id":42130949},{"atb":[[1.51,21.63]],"id":43154457},{"atb":[[1.6,21.63]],"id":36087680}],"con":true,"img":false}]}
{"op":"mcm","clk":"5306865958","pt":1646108484326,"mc":[{"id":"1.195395428","rc":[{"atb":[[2.5,32.18]],"id":38407646},{"atl":[[4.4,10.67]],"id":38407646},{"atl":[[4.2,10.67]],"id":43154456},{"atl":[[48,4.84]],"id":42130949},{"atb":[[1.52,86.06]],"id":43154457},{"atb":[[1.61,84.76]],"id":36087680}],"con":true,"img":false}]}
{"op":"mcm","clk":"5306865961","pt":1646108484429,"mc":[{"id":"1.195395428","rc":[{"atl":[[4.3,10.67]],"id":38407646},{"atl":[[4.1,10.67]],"id":43154456}],"con":true,"img":false}]}
{"op":"mcm","clk":"5306865964","pt":1646108484531,"mc":[{"id":"1.195395428","rc":[{"atl":[[4.5,15.32]],"id":38407646},{"atl":[[4.3,21.3]],"id":43154456}],"con":true,"img":false}]}
{"op":"mcm","clk":"5306866021","pt":1646108486530,"mc":[{"id":"1.195395428","rc":[{"atb":[[2.54,0]],"id":38407646},{"atb":[[1.54,0]],"id":43154457},{"atb":[[1.64,0]],"id":36087680}],"con":true,"img":false}]}
{"op":"mcm","clk":"5306866134","pt":1646108490322,"mc":[{"id":"1.195395428","rc":[{"atb":[[2.14,2]],"id":38407646},{"atl":[[6.2,2]],"id":38407646},{"atb":[[1.92,2]],"id":43154456},{"atl":[[5.9,2]],"id":43154456},{"atb":[[6.2,2]],"id":42130949},{"atl":[[960,2]],"id":42130949},{"atb":[[1.35,2]],"id":43154457},{"atl":[[2.96,2]],"id":43154457},{"atb":[[3.7,2]],"id":37279191},{"atl":[[75,2]],"id":37279191},{"atb":[[1.44,2]],"id":36087680},{"atl":[[2.74,2]],"id":36087680}],"con":true,"img":false}]}
{"op":"mcm","clk":"5306866217","pt":1646108493710,"mc":[{"id":"1.195395428","rc":[{"atb":[[2.48,0]],"id":38407646},{"atl":[[4.5,0]],"id":38407646},{"atl":[[4.3,0]],"id":43154456},{"atb":[[1.51,0]],"id":43154457},{"atb":[[1.6,0]],"id":36087680}],"con":true,"img":false}]}
{"op":"mcm","clk":"5306866225","pt":1646108494020,"mc":[{"id":"1.195395428","rc":[{"atb":[[2.5,52.37]],"id":38407646},{"atl":[[4.3,24.37]],"id":38407646},{"atl":[[4.1,32.3]],"id":43154456},{"atb":[[1.52,107.69]],"id":43154457},{"atb":[[1.61,106.39]],"id":36087680}],"con":true,"img":false}]}
{"op":"mcm","clk":"5306866547","pt":1646108504821,"mc":[{"id":"1.195395428","rc":[{"atl":[[48,4.02]],"id":42130949},{"atb":[[1.52,21.63]],"id":43154457},{"atl":[[17.5,4.26]],"id":37279191},{"atl":[[2.38,21.63]],"id":36087680}],"con":true,"img":false}]}
{"op":"mcm","clk":"5306866551","pt":1646108504923,"mc":[{"id":"1.195395428","rc":[{"atl":[[46,0.82]],"id":42130949},{"atb":[[1.46,86.06]],"id":43154457},{"atl":[[17,2.7]],"id":37279191},{"atl":[[2.4,35.57]],"id":36087680}],"con":true,"img":false}]}
{"op":"mcm","clk":"5306866563","pt":1646108505434,"mc":[{"id":"1.195395428","rc":[{"atb":[[1.97,2],[2.14,0]],"id":38407646},{"atl":[[7.2,2],[6.2,0]],"id":38407646},{"spn":3.4,"spf":"NaN","id":38407646},{"atl":[[6.8,2],[5.9,0]],"id":43154456},{"spn":3.2,"spf":"NaN","id":43154456},{"atl":[[960,0]],"id":42130949},{"spn":29.0,"spf":"NaN","id":42130949},{"atb":[[1.34,2],[1.35,0]],"id":43154457},{"spn":1.99,"spf":"NaN","id":43154457},{"atl":[[75,0],[40,9.67]],"id":37279191},{"spn":11.5,"spf":"NaN","id":37279191},{"atb":[[1.44,0],[1.37,2]],"id":36087680},{"spn":2.02,"spf":"NaN","id":36087680}],"con":true,"img":false}]}
{"op":"mcm","clk":"5306866809","pt":1646108513428,"mc":[{"id":"1.195395428","rc":[{"atl":[[48,2.01]],"id":42130949},{"atl":[[17.5,0]],"id":37279191}],"con":true,"img":false}]}
{"op":"mcm","clk":"5306866812","pt":1646108513532,"mc":[{"id":"1.195395428","rc":[{"atl":[[80,2.15],[48,0]],"id":42130949}],"con":true,"img":false}]}
{"op":"mcm","clk":"5306866815","pt":1646108513632,"mc":[{"id":"1.195395428","rc":[{"atl":[[80,0.15],[160,2.07]],"id":42130949}],"con":true,"img":false}]}
{"op":"mcm","clk":"5306866819","pt":1646108513732,"mc":[{"id":"1.195395428","rc":[{"atl":[[46,2.93]],"id":42130949},{"atl":[[17,7.09]],"id":37279191}],"con":true,"img":false}]}
{"op":"mcm","clk":"5306866830","pt":1646108513941,"mc":[{"id":"1.195395428","rc":[{"atl":[[4.3,35.24],[4.2,2.71]],"id":38407646},{"atl":[[4,3.1],[4.1,44.72]],"id":43154456},{"atb":[[1.57,8.53],[1.53,13.51]],"id":43154457},{"atl":[[2.36,5.11]],"id":36087680}],"con":true,"img":false}]}
{"op":"mcm","clk":"5306866835","pt":1646108514040,"mc":[{"id":"1.195395428","rc":[{"atl":[[2.42,59.59],[2.44,77.71]],"id":43154457}],"con":true,"img":false}]}
{"op":"mcm","clk":"5306866849","pt":1646108514350,"mc":[{"id":"1.195395428","rc":[{"atb":[[1.57,2.17]],"id":43154457},{"atl":[[2.4,5.58]],"id":43154457},{"atl":[[17,13.47]],"id":37279191},{"atb":[[1.67,7.71]],"id":36087680}],"con":true,"img":false}]}
{"op":"mcm","clk":"5306866977","pt":1646108518850,"mc":[{"id":"1.195395428","rc":[{"atl":[[3.95,10.67]],"id":43154456}],"con":true,"img":false}]}
{"op":"mcm","clk":"5306866979","pt":1646108518953,"mc":[{"id":"1.195395428","rc":[{"atl":[[4.1,34.05]],"id":43154456}],"con":true,"img":false}]}
{"op":"mcm","clk":"5306867021","pt":1646108520587,"mc":[{"id":"1.195395428","rc":[{"atl":[[7.2,0],[6,2]],"id":38407646},{"atl":[[6.8,0],[5.7,2]],"id":43154456},{"atl":[[370,2]],"id":42130949},{"atb":[[1.36,2],[1.34,0]],"id":43154457},{"atl":[[2.96,0],[2.76,2]],"id":43154457},{"atl":[[75,2],[40,7.67]],"id":37279191},{"atl":[[2.72,2],[2.74,0]],"id":36087680}],"con":true,"img":false}]}
{"op":"mcm","clk":"5306867126","pt":1646108524068,"mc":[{"id":"1.195395428","rc":[{"atb":[[1.72,0],[2.5,20.19],[1.96,42.67]],"id":38407646},{"atl":[[4.4,0]],"id":38407646},{"atl":[[4.2,0]],"id":43154456},{"atb":[[1.61,21.63]],"id":36087680}],"con":true,"img":false}]}
{"op":"mcm","clk":"5306867128","pt":1646108524169,"mc":[{"id":"1.195395428","rc":[{"atb":[[2.52,32.18]],"id":38407646},{"atl":[[4.2,13.38]],"id":38407646},{"atl":[[4,13.77]],"id":43154456},{"atb":[[1.62,84.76]],"id":36087680}],"con":true,"img":false}]}
{"op":"mcm","clk":"5306867130","pt":1646108524271,"mc":[{"id":"1.195395428","rc":[{"atl":[[4.1,13.39]],"id":38407646}],"con":true,"img":false}]}
{"op":"mcm","clk":"5306867135","pt":1646108524374,"mc":[{"id":"1.195395428","rc":[{"atl":[[4.3,24.57]],"id":38407646}],"con":true,"img":false}]}
{"op":"mcm","clk":"5306867147","pt":1646108524681,"mc":[{"id":"1.195395428","rc":[{"atl":[[2.42,119.18]],"id":43154457}],"con":true,"img":false}]}
{"op":"mcm","clk":"5306867150","pt":1646108524784,"mc":[{"id":"1.195395428","rc":[{"atl":[[2.44,8.27]],"id":43154457}],"con":true,"img":false}]}
{"op":"mcm","clk":"5306867159","pt":1646108525145,"mc":[{"id":"1.195395428","rc":[{"atl":[[3.55,0]],"id":43154457},{"atl":[[3.55,0]],"id":36087680}],"con":true,"img":false}]}
{"op":"mcm","clk":"5306867161","pt":1646108525248,"mc":[{"id":"1.195395428","rc":[{"atl":[[4.1,61.74]],"id":43154457},{"atl":[[4,58.98]],"id":36087680}],"con":true,"img":false}]}
{"op":"mcm","clk":"5306867352","pt":1646108532157,"mc":[{"id":"1.195395428","rc":[{"atl":[[4.3,10.86]],"id":38407646},{"atl":[[4.1,12.42]],"id":43154456}],"con":true,"img":false}]}
{"op":"mcm","clk":"5306867383","pt":1646108533076,"mc":[{"id":"1.195395428","rc":[{"atl":[[4,3.1]],"id":43154456}],"con":true,"img":false}]}
{"op":"mcm","clk":"5306867385","pt":1646108533177,"mc":[{"id":"1.195395428","rc":[{"atl":[[4.2,26.21]],"id":38407646},{"atl":[[4.8,13.76],[4,24.73]],"id":43154456}],"con":true,"img":false}]}
{"op":"mcm","clk":"5306867470","pt":1646108535584,"mc":[{"id":"1.195395428","rc":[{"atb":[[2.14,2],[1.97,0]],"id":38407646},{"atl":[[5.9,2],[6,0]],"id":38407646},{"atb":[[1.37,0],[1.45,2]],"id":36087680}],"con":true,"img":false}]}
{"op":"mcm","clk":"5306867594","pt":1646108539673,"mc":[{"id":"1.195395428","rc":[{"atl":[[4.2,15.54]],"id":38407646},{"atl":[[170,0]],"id":42130949}],"con":true,"img":false}]}
{"op":"mcm","clk":"5306867597","pt":1646108539776,"mc":[{"id":"1.195395428","rc":[{"atl":[[5.2,13.37]],"id":38407646},{"atl":[[150,2.7]],"id":42130949}],"con":true,"img":false}]}
{"op":"mcm","clk":"5306867647","pt":1646108541874,"mc":[{"id":"1.195395428","rc":[{"atl":[[8.8,0]],"id":38407646},{"atl":[[2.4,5.1]],"id":36087680}],"con":true,"img":false}]}
{"op":"mcm","clk":"5306867651","pt":1646108541976,"mc":[{"id":"1.195395428","rc":[{"atl":[[7.4,29.67]],"id":38407646},{"atl":[[2.38,52.09]],"id":36087680}],"con":true,"img":false}]}
{"op":"mcm","clk":"5306867703","pt":1646108543612,"mc":[{"id":"1.195395428","rc":[{"atl":[[46,2.1]],"id":42130949},{"atb":[[1.46,0]],"id":43154457},{"atl":[[17,10.76]],"id":37279191}],"con":true,"img":false}]}
{"op":"mcm","clk":"5306867706","pt":1646108543713,"mc":[{"id":"1.195395428","rc":[{"atl":[[50,0.82]],"id":42130949},{"atb":[[1.53,99.58]],"id":43154457},{"atl":[[16.5,2.7]],"id":37279191}],"con":true,"img":false}]}
{"op":"mcm","clk":"5306867824","pt":1646108547913,"mc":[{"id":"1.195395428","rc":[{"atl":[[160,0.07],[46,4.1]],"id":42130949}],"con":true,"img":false}]}
{"op":"mcm","clk":"5306867828","pt":1646108548015,"mc":[{"id":"1.195395428","rc":[{"atl":[[80,2.15],[46,2.1]],"id":42130949}],"con":true,"img":false}]}
{"op":"mcm","clk":"5306867829","pt":1646108548116,"mc":[{"id":"1.195395428","rc":[{"atl":[[46,4.1]],"id":42130949}],"con":true,"img":false}]}
{"op":"mcm","clk":"5306867831","pt":1646108548219,"mc":[{"id":"1.195395428","rc":[{"atl":[[80,0.15]],"id":42130949}],"con":true,"img":false}]}
{"op":"mcm","clk":"5306867877","pt":1646108550009,"mc":[{"id":"1.195395428","rc":[{"spb":[[3.05,29.45]],"id":38407646},{"spb":[[2.46,15.34]],"id":43154456},{"spl":[[11.5,1.76]],"id":42130949},{"spb":[[1.77,21.62]],"id":43154457},{"spb":[[7.2,30.09]],"id":37279191},{"spb":[[1.75,12.32]],"id":36087680}],"con":true,"img":false}]}
{"op":"mcm","clk":"5306867890","pt":1646108550624,"mc":[{"id":"1.195395428","rc":[{"atl":[[370,0],[870,2]],"id":42130949},{"atl":[[75,0],[40,9.67]],"id":37279191}],"con":true,"img":false}]}
{"op":"mcm","clk":"5306868053","pt":1646108557020,"mc":[{"id":"1.195395428","rc":[{"atl":[[4.8,3.09]],"id":43154456}],"con":true,"img":false}]}
{"op":"mcm","clk":"5306868058","pt":1646108557120,"mc":[{"id":"1.195395428","rc":[{"atl":[[3.95,21.34]],"id":43154456}],"con":true,"img":false}]}
{"op":"mcm","clk":"5306868305","pt":1646108565413,"mc":[{"id":"1.195395428","rc":[{"atb":[[1.78,63.79],[1.96,0]],"id":38407646}],"con":true,"img":false}]}
{"op":"mcm","clk":"5306868308","pt":1646108565623,"mc":[{"id":"1.195395428","rc":[{"spn":3.57,"spf":"Infinity","id":38407646},{"spn":3.2,"spf":"Infinity","id":43154456},{"atl":[[870,0]],"id":42130949},{"spn":12.0,"spf":1.0,"id":42130949},{"spn":2.08,"spf":"Infinity","id":43154457},{"spn":11.85,"spf":"Infinity","id":37279191},{"spn":2.05,"spf":"Infinity","id":36087680}],"con":true,"img":false}]}
{"op":"mcm","clk":"5306868332","pt":1646108566544,"mc":[{"id":"1.195395428","rc":[{"atl":[[50,0]],"id":42130949}],"con":true,"img":false}]}
{"op":"mcm","clk":"5306868335","pt":1646108566645,"mc":[{"id":"1.195395428","rc":[{"atl":[[44,0.82]],"id":42130949}],"con":true,"img":false}]}
{"op":"mcm","clk":"5306868409","pt":1646108569051,"mc":[{"id":"1.195395428","rc":[{"atl":[[4.1,0]],"id":43154457},{"atl":[[4,0]],"id":36087680}],"con":true,"img":false}]}
{"op":"mcm","clk":"5306868413","pt":1646108569151,"mc":[{"id":"1.195395428","rc":[{"atl":[[3.55,61.74]],"id":43154457},{"atl":[[3.55,58.98]],"id":36087680}],"con":true,"img":false}]}
{"op":"mcm","clk":"5306868755","pt":1646108580770,"mc":[{"id":"1.195395428","rc":[{"atl":[[960,2]],"id":42130949}],"con":true,"img":false}]}
{"op":"mcm","clk":"5306869182","pt":1646108595920,"mc":[{"id":"1.195395428","rc":[{"atl":[[960,0]],"id":42130949}],"con":true,"img":false}]}
{"op":"mcm","clk":"5306869712","pt":1646108610863,"mc":[{"id":"1.195395428","rc":[{"atl":[[960,2]],"id":42130949}],"con":true,"img":false}]}
{"op":"mcm","clk":"5306870127","pt":1646108625961,"mc":[{"id":"1.195395428","rc":[{"atl":[[960,0]],"id":42130949}],"con":true,"img":false}]}
{"op":"mcm","clk":"5306870545","pt":1646108640974,"mc":[{"id":"1.195395428","rc":[{"atl":[[960,2]],"id":42130949}],"con":true,"img":false}]}
{"op":"mcm","clk":"5306870950","pt":1646108656026,"mc":[{"id":"1.195395428","rc":[{"atl":[[960,0]],"id":42130949}],"con":true,"img":false}]}
{"op":"mcm","clk":"5306871325","pt":1646108671117,"mc":[{"id":"1.195395428","rc":[{"atl":[[960,2]],"id":42130949}],"con":true,"img":false}]}
{"op":"mcm","clk":"5306871665","pt":1646108686250,"mc":[{"id":"1.195395428","rc":[{"atl":[[960,0]],"id":42130949}],"con":true,"img":false}]}
{"op":"mcm","clk":"5306872052","pt":1646108701278,"mc":[{"id":"1.195395428","rc":[{"atl":[[960,2]],"id":42130949}],"con":true,"img":false}]}
{"op":"mcm","clk":"5306872436","pt":1646108716405,"mc":[{"id":"1.195395428","rc":[{"atl":[[960,0]],"id":42130949}],"con":true,"img":false}]}
{"op":"mcm","clk":"5306872818","pt":1646108731528,"mc":[{"id":"1.195395428","rc":[{"atl":[[960,2]],"id":42130949}],"con":true,"img":false}]}
{"op":"mcm","clk":"5306873140","pt":1646108746619,"mc":[{"id":"1.195395428","rc":[{"atl":[[960,0]],"id":42130949}],"con":true,"img":false}]}
{"op":"mcm","clk":"5306873482","pt":1646108761555,"mc":[{"id":"1.195395428","rc":[{"atl":[[960,2]],"id":42130949}],"con":true,"img":false}]}
{"op":"mcm","clk":"5306873846","pt":1646108776685,"mc":[{"id":"1.195395428","rc":[{"atl":[[960,0]],"id":42130949}],"con":true,"img":false}]}
{"op":"mcm","clk":"5306874219","pt":1646108791778,"mc":[{"id":"1.195395428","rc":[{"atl":[[960,2]],"id":42130949}],"con":true,"img":false}]}
{"op":"mcm","clk":"5306874389","pt":1646108798689,"mc":[{"id":"1.195395428","rc":[{"atb":[[1.65,153.85],[1.76,0]],"id":43154456}],"con":true,"img":false}]}
{"op":"mcm","clk":"5306874408","pt":1646108799405,"mc":[{"id":"1.195395428","rc":[{"atb":[[1.77,0]],"id":43154456}],"con":true,"img":false}]}
{"op":"mcm","clk":"5306874412","pt":1646108799508,"mc":[{"id":"1.195395428","rc":[{"atb":[[1.67,70.58]],"id":43154456}],"con":true,"img":false}]}
{"op":"mcm","clk":"5306874562","pt":1646108806916,"mc":[{"id":"1.195395428","rc":[{"atl":[[960,0]],"id":42130949}],"con":true,"img":false}]}
{"op":"mcm","clk":"5306874872","pt":1646108821942,"mc":[{"id":"1.195395428","rc":[{"atl":[[960,2]],"id":42130949}],"con":true,"img":false}]}
{"op":"mcm","clk":"5306875211","pt":1646108836965,"mc":[{"id":"1.195395428","rc":[{"atl":[[960,0]],"id":42130949}],"con":true,"img":false}]}
{"op":"mcm","clk":"5306875511","pt":1646108851965,"mc":[{"id":"1.195395428","rc":[{"atl":[[960,2]],"id":42130949}],"con":true,"img":false}]}
{"op":"mcm","clk":"5306875812","pt":1646108867108,"mc":[{"id":"1.195395428","rc":[{"atl":[[960,0]],"id":42130949}],"con":true,"img":false}]}
{"op":"mcm","clk":"5306876254","pt":1646108882211,"mc":[{"id":"1.195395428","rc":[{"atl":[[960,2]],"id":42130949}],"con":true,"img":false}]}
{"op":"mcm","clk":"5306876719","pt":1646108897366,"mc":[{"id":"1.195395428","rc":[{"atl":[[960,0]],"id":42130949}],"con":true,"img":false}]}
{"op":"mcm","clk":"5306877102","pt":1646108912374,"mc":[{"id":"1.195395428","rc":[{"atl":[[960,2]],"id":42130949}],"con":true,"img":false}]}
{"op":"mcm","clk":"5306877210","pt":1646108916676,"mc":[{"id":"1.195395428","rc":[{"atl":[[2.42,59.59],[2.44,77.71]],"id":43154457},{"atl":[[23,4.55],[25,0]],"id":37279191}],"con":true,"img":false}]}
{"op":"mcm","clk":"5306877514","pt":1646108927385,"mc":[{"id":"1.195395428","rc":[{"atl":[[960,0]],"id":42130949}],"con":true,"img":false}]}
{"op":"mcm","clk":"5306877867","pt":1646108940367,"mc":[{"id":"1.195395428","rc":[{"atb":[[2.06,0]],"id":38407646},{"atl":[[4.1,0]],"id":38407646},{"atb":[[1.65,0]],"id":43154456},{"atl":[[3.95,10.67]],"id":43154456},{"atb":[[5.4,0]],"id":42130949},{"atl":[[46,2.1]],"id":42130949},{"atl":[[2.44,8.27]],"id":43154457},{"atb":[[5,30.17]],"id":37279191},{"atl":[[23,0]],"id":37279191},{"atb":[[1.43,0]],"id":36087680},{"atl":[[5.8,0]],"id":36087680}],"con":true,"img":false}]}
{"op":"mcm","clk":"5306877946","pt":1646108942524,"mc":[{"id":"1.195395428","rc":[{"atl":[[7.2,2],[5.9,0]],"id":38407646},{"atl":[[960,2]],"id":42130949}],"con":true,"img":false}]}
{"op":"mcm","clk":"5306878216","pt":1646108951833,"mc":[{"id":"1.195395428","rc":[{"atl":[[3.55,21.63]],"id":43154457},{"atl":[[3.55,23.91]],"id":36087680}],"con":true,"img":false}]}
{"op":"mcm","clk":"5306878371","pt":1646108957669,"mc":[{"id":"1.195395428","rc":[{"atl":[[960,0]],"id":42130949}],"con":true,"img":false}]}
{"op":"mcm","clk":"5306878635","pt":1646108965676,"mc":[{"id":"1.195395428","rc":[{"atl":[[44,2.7]],"id":42130949}],"con":true,"img":false}]}
{"op":"mcm","clk":"5306878763","pt":1646108969074,"mc":[{"id":"1.195395428","rc":[{"atl":[[2.38,21.63]],"id":36087680}],"con":true,"img":false}]}
{"op":"mcm","clk":"5306878767","pt":1646108969177,"mc":[{"id":"1.195395428","rc":[{"atl":[[2.36,35.58]],"id":36087680}],"con":true,"img":false}]}
{"op":"mcm","clk":"5306878867","pt":1646108972662,"mc":[{"id":"1.195395428","rc":[{"atl":[[350,2]],"id":42130949}],"con":true,"img":false}]}
{"op":"mcm","clk":"5306878878","pt":1646108972967,"mc":[{"id":"1.195395428","rc":[{"atl":[[5.2,2.7]],"id":38407646}],"con":true,"img":false}]}
{"op":"mcm","clk":"5306878882","pt":1646108973073,"mc":[{"id":"1.195395428","rc":[{"atl":[[4.1,10.67]],"id":38407646}],"con":true,"img":false}]}
{"op":"mcm","clk":"5306879229","pt":1646108983488,"mc":[{"id":"1.195395428","rc":[{"atb":[[1.62,0]],"id":36087680}],"con":true,"img":false}]}
{"op":"mcm","clk":"5306879233","pt":1646108983591,"mc":[{"id":"1.195395428","rc":[{"atb":[[1.44,84.76]],"id":36087680}],"con":true,"img":false}]}
{"op":"mcm","clk":"5306879342","pt":1646108987807,"mc":[{"id":"1.195395428","rc":[{"atl":[[5.9,2],[7.2,0]],"id":38407646},{"atb":[[1.45,0],[1.37,2]],"id":36087680}],"con":true,"img":false}]}
{"op":"mcm","clk":"5306879567","pt":1646108995605,"mc":[{"id":"1.195395428","rc":[{"atb":[[1.67,0]],"id":43154456},{"atb":[[1.26,0],[1.33,184.76]],"id":36087680}],"con":true,"img":false}]}
{"op":"mcm","clk":"5306879569","pt":1646108995708,"mc":[{"id":"1.195395428","rc":[{"atb":[[1.75,70.58]],"id":43154456}],"con":true,"img":false}]}
{"op":"mcm","clk":"5306879588","pt":1646108996530,"mc":[{"id":"1.195395428","rc":[{"atb":[[1.78,0]],"id":38407646},{"atl":[[5.2,16.7]],"id":38407646},{"atb":[[1.21,0]],"id":43154457}],"con":true,"img":false}]}
{"op":"mcm","clk":"5306879590","pt":1646108996630,"mc":[{"id":"1.195395428","rc":[{"atb":[[1.96,63.79]],"id":38407646},{"atl":[[7.4,0]],"id":38407646},{"atb":[[1.32,145.26]],"id":43154457}],"con":true,"img":false}]}
{"op":"mcm","clk":"5306879615","pt":1646108997503,"mc":[{"id":"1.195395428","rc":[{"atl":[[8.4,0],[5.2,16.02]],"id":43154456},{"atl":[[150,0]],"id":42130949},{"atl":[[19,3.32],[40,2]],"id":37279191}],"con":true,"img":false}]}
{"op":"mcm","clk":"5306879616","pt":1646108997605,"mc":[{"id":"1.195395428","rc":[{"atl":[[60,2.7]],"id":42130949}],"con":true,"img":false}]}
{"op":"mcm","clk":"5306879661","pt":1646108999506,"mc":[{"id":"1.195395428","rc":[{"atb":[[11,5.36],[9.4,0]],"id":42130949}],"con":true,"img":false}]}
{"op":"mcm","clk":"5306879688","pt":1646109000533,"mc":[{"id":"1.195395428","rc":[{"atb":[[4,0],[5.1,14.57]],"id":37279191}],"con":true,"img":false}]}
{"op":"mcm","clk":"5306879747","pt":1646109002904,"mc":[{"id":"1.195395428","rc":[{"atb":[[6.2,0],[7,2]],"id":42130949},{"atl":[[350,0],[220,2]],"id":42130949},{"atb":[[3.7,0],[3.75,2]],"id":37279191},{"atl":[[38,2],[40,0]],"id":37279191}],"con":true,"img":false}]}
{"op":"mcm","clk":"5306880214","pt":1646109018822,"mc":[{"id":"1.195395428","rc":[{"atl":[[60,0]],"id":42130949}],"con":true,"img":false}]}
{"op":"mcm","clk":"5306880215","pt":1646109018925,"mc":[{"id":"1.195395428","rc":[{"atl":[[65,2.7]],"id":42130949}],"con":true,"img":false}]}
{"op":"mcm","clk":"5306880596","pt":1646109031158,"mc":[{"id":"1.195395428","rc":[{"atb":[[2.12,0]],"id":43154456}],"con":true,"img":false}]}
{"op":"mcm","clk":"5306880598","pt":1646109031260,"mc":[{"id":"1.195395428","rc":[{"atb":[[2.26,46.02]],"id":43154456}],"con":true,"img":false}]}
{"op":"mcm","clk":"5306880657","pt":1646109033056,"mc":[{"id":"1.195395428","rc":[{"atb":[[1.92,0],[1.96,2]],"id":43154456},{"atl":[[220,0],[230,2]],"id":42130949}],"con":true,"img":false}]}
{"op":"mcm","clk":"5306880676","pt":1646109033466,"mc":[{"id":"1.195395428","rc":[{"atb":[[2.16,7.19]],"id":43154456}],"con":true,"img":false}]}
{"op":"mcm","clk":"5306881054","pt":1646109046660,"mc":[{"id":"1.195395428","rc":[{"atb":[[2.16,0]],"id":43154456}],"con":true,"img":false}]}
{"op":"mcm","clk":"5306881224","pt":1646109053805,"mc":[{"id":"1.195395428","rc":[{"atb":[[4.3,18.1]],"id":37279191}],"con":true,"img":false}]}
{"op":"mcm","clk":"5306881232","pt":1646109053908,"mc":[{"id":"1.195395428","rc":[{"atb":[[5.1,0]],"id":37279191}],"con":true,"img":false}]}
{"op":"mcm","clk":"5306881316","pt":1646109057287,"mc":[{"id":"1.195395428","rc":[{"atb":[[2.26,0]],"id":43154456}],"con":true,"img":false}]}
{"op":"mcm","clk":"5306881318","pt":1646109057389,"mc":[{"id":"1.195395428","rc":[{"atb":[[2.12,46.02]],"id":43154456}],"con":true,"img":false}]}
{"op":"mcm","clk":"5306881494","pt":1646109063227,"mc":[{"id":"1.195395428","rc":[{"atb":[[1.9,2],[1.96,0]],"id":43154456},{"atb":[[3.7,2],[3.75,0]],"id":37279191}],"con":true,"img":false}]}
{"op":"mcm","clk":"5306881822","pt":1646109075508,"mc":[{"id":"1.195395428","rc":[{"atl":[[65,0]],"id":42130949}],"con":true,"img":false}]}
{"op":"mcm","clk":"5306881827","pt":1646109075608,"mc":[{"id":"1.195395428","rc":[{"atl":[[70,2.7]],"id":42130949}],"con":true,"img":false}]}
{"op":"mcm","clk":"5306881894","pt":1646109078318,"mc":[{"id":"1.195395428","rc":[{"atl":[[230,0],[240,2]],"id":42130949}],"con":true,"img":false}]}
{"op":"mcm","clk":"5306882027","pt":1646109083758,"mc":[{"id":"1.195395428","rc":[{"atb":[[12,0]],"id":42130949}],"con":true,"img":false}]}
{"op":"mcm","clk":"5306882030","pt":1646109083807,"mc":[{"id":"1.195395428","rc":[{"atb":[[13.5,3.6]],"id":42130949}],"con":true,"img":false}]}
{"op":"mcm","clk":"5306883124","pt":1646109123596,"mc":[{"id":"1.195395428","rc":[{"atb":[[2.14,0]],"id":38407646},{"atl":[[5.9,0]],"id":38407646},{"atb":[[1.9,0]],"id":43154456},{"atl":[[5.7,0]],"id":43154456},{"atb":[[7,0]],"id":42130949},{"atl":[[240,0]],"id":42130949},{"spn":13.5,"spf":1.0,"id":42130949},{"atb":[[1.36,0]],"id":43154457},{"atl":[[2.76,0]],"id":43154457},{"atb":[[3.7,0]],"id":37279191},{"atl":[[38,0]],"id":37279191},{"atb":[[1.37,0]],"id":36087680},{"atl":[[2.72,0]],"id":36087680}],"con":true,"img":false}]}
{"op":"mcm","clk":"5306883129","pt":1646109123698,"mc":[{"id":"1.195395428","rc":[{"atb":[[2.06,94.34]],"id":38407646},{"atl":[[4.1,21.53]],"id":38407646},{"atb":[[1.59,169.49]],"id":43154456},{"atl":[[3.95,23.1]],"id":43154456},{"atb":[[4.8,26.32]],"id":42130949},{"atl":[[46,4.32]],"id":42130949},{"atl":[[2.58,16.56]],"id":43154457},{"atb":[[4.4,29.41]],"id":37279191},{"atl":[[26,4]],"id":37279191},{"atb":[[1.43,184.77]],"id":36087680},{"atl":[[5.8,20.83]],"id":36087680}],"con":true,"img":false}]}
{"op":"mcm","clk":"5306883160","pt":1646109124820,"mc":[{"id":"1.195395428","rc":[{"atb":[[1.96,0]],"id":38407646},{"atl":[[7.6,27.72],[5.2,2.7]],"id":38407646},{"atb":[[1.75,0],[1.65,93.46]],"id":43154456},{"atl":[[7.4,28.53],[5.2,3.08]],"id":43154456},{"atl":[[70,0]],"id":42130949},{"atb":[[1.32,0]],"id":43154457},{"atl":[[19,0],[40,7.66]],"id":37279191},{"atb":[[1.26,113.03],[1.33,0]],"id":36087680}],"con":true,"img":false}]}
{"op":"mcm","clk":"5306883163","pt":1646109124871,"mc":[{"id":"1.195395428","rc":[{"atb":[[1.73,63.79]],"id":38407646},{"atl":[[180,2.7]],"id":42130949},{"atb":[[1.21,145.26]],"id":43154457}],"con":true,"img":false}]}
{"op":"mcm","clk":"5306883187","pt":1646109125688,"mc":[{"id":"1.195395428","rc":[{"atb":[[11,0],[9.4,11.42]],"id":42130949}],"con":true,"img":false}]}
{"op":"mcm","clk":"5306883338","pt":1646109131306,"mc":[{"id":"1.195395428","rc":[{"atb":[[2.54,1.66]],"id":38407646},{"atb":[[2.32,1.66]],"id":43154456},{"atl":[[44,0.94]],"id":42130949}],"con":true,"img":false}]}
{"op":"mcm","clk":"5306883354","pt":1646109132325,"mc":[{"id":"1.195395428","rc":[{"atb":[[13.5,0]],"id":42130949}],"con":true,"img":false}]}
{"op":"mcm","clk":"5306883357","pt":1646109132428,"mc":[{"id":"1.195395428","rc":[{"atb":[[11,3.6]],"id":42130949}],"con":true,"img":false}]}
{"op":"mcm","clk":"5306883510","pt":1646109138606,"mc":[{"id":"1.195395428","rc":[{"atb":[[2.18,2]],"id":38407646},{"atl":[[5.9,2]],"id":38407646},{"atb":[[1.96,2]],"id":43154456},{"atl":[[5.7,2]],"id":43154456},{"atb":[[6.2,2]],"id":42130949},{"atl":[[960,2]],"id":42130949},{"atb":[[1.36,2]],"id":43154457},{"atl":[[2.76,2]],"id":43154457},{"atb":[[3.7,2]],"id":37279191},{"atl":[[40,9.66]],"id":37279191},{"atb":[[1.37,2]],"id":36087680},{"atl":[[2.72,2]],"id":36087680}],"con":true,"img":false}]}
{"op":"mcm","clk":"5306883561","pt":1646109140348,"mc":[{"id":"1.195395428","rc":[{"atl":[[3.55,57.58]],"id":43154457},{"atl":[[3.55,54.14]],"id":36087680}],"con":true,"img":false}]}
{"op":"mcm","clk":"5306883679","pt":1646109144907,"mc":[{"id":"1.195395428","rc":[{"atb":[[1.44,0]],"id":36087680}],"con":true,"img":false}]}
{"op":"mcm","clk":"5306883682","pt":1646109145011,"mc":[{"id":"1.195395428","rc":[{"atb":[[1.62,84.76]],"id":36087680}],"con":true,"img":false}]}
{"op":"mcm","clk":"5306883915","pt":1646109153759,"mc":[{"id":"1.195395428","rc":[{"atb":[[1.45,2]],"id":36087680}],"con":true,"img":false}]}
{"op":"mcm","clk":"5306883918","pt":1646109153860,"mc":[{"id":"1.195395428","rc":[{"atl":[[960,0]],"id":42130949},{"atb":[[1.37,0]],"id":36087680}],"con":true,"img":false}]}
{"op":"mcm","clk":"5306884076","pt":1646109161079,"mc":[{"id":"1.195395428","rc":[{"atb":[[4.3,0]],"id":37279191}],"con":true,"img":false}]}
{"op":"mcm","clk":"5306884078","pt":1646109161129,"mc":[{"id":"1.195395428","rc":[{"atb":[[4.5,18.1]],"id":37279191}],"con":true,"img":false}]}
{"op":"mcm","clk":"5306884269","pt":1646109168893,"mc":[{"id":"1.195395428","rc":[{"atl":[[960,2]],"id":42130949}],"con":true,"img":false}]}
{"op":"mcm","clk":"5306884701","pt":1646109183861,"mc":[{"id":"1.195395428","rc":[{"atl":[[960,0]],"id":42130949},{"spn":11.25,"spf":1.0,"id":42130949}],"con":true,"img":false}]}
{"op":"mcm","clk":"5306885093","pt":1646109198887,"mc":[{"id":"1.195395428","rc":[{"atl":[[960,2]],"id":42130949}],"con":true,"img":false}]}
{"op":"mcm","clk":"5306885202","pt":1646109202451,"mc":[{"id":"1.195395428","marketDefinition":{"bspMarket":true,"turnInPlayEnabled":false,"persistenceEnabled":false,"marketBaseRate":7.0,"eventId":"31270458","eventTypeId":"4339","numberOfWinners":2,"bettingType":"ODDS","marketType":"PLACE","marketTime":"2022-03-01T05:32:00.000Z","suspendTime":"2022-03-01T05:32:00.000Z","bspReconciled":false,"complete":true,"inPlay":false,"crossMatching":true,"runnersVoidable":false,"numberOfActiveRunners":6,"betDelay":0,"status":"OPEN","runners":[{"status":"ACTIVE","sortPriority":1,"id":43154456,"name":"1. Buckle Up Zion"},{"status":"ACTIVE","sortPriority":2,"id":43154457,"name":"2. Rambo Bobbie"},{"status":"ACTIVE","sortPriority":3,"id":38407646,"name":"4. Hiccup Gus"},{"status":"ACTIVE","sortPriority":4,"id":42130949,"name":"5. Into The Fire"},{"status":"ACTIVE","sortPriority":5,"id":37279191,"name":"7. Shiffrin"},{"status":"ACTIVE","sortPriority":6,"id":36087680,"name":"8. White Poison"},{"status":"REMOVED","sortPriority":7,"removalDate":"2022-02-28T22:23:28.000Z","id":39979946,"name":"3. Marshall Giblet"}],"regulators":["MR_INT"],"venue":"Devonport","countryCode":"AU","discountAllowed":true,"timezone":"Australia/Sydney","openDate":"2022-03-01T02:00:00.000Z","version":4381128850,"name":"To Be Placed","eventName":"Devonport (AUS) 1st Mar"},"rc":[],"con":true,"img":false}]}
{"op":"mcm","clk":"5306885559","pt":1646109214001,"mc":[{"id":"1.195395428","rc":[{"atl":[[960,0]],"id":42130949}],"con":true,"img":false}]}
{"op":"mcm","clk":"5306886001","pt":1646109229145,"mc":[{"id":"1.195395428","rc":[{"atl":[[960,2]],"id":42130949}],"con":true,"img":false}]}
{"op":"mcm","clk":"5306886511","pt":1646109244189,"mc":[{"id":"1.195395428","rc":[{"atl":[[960,0]],"id":42130949}],"con":true,"img":false}]}
{"op":"mcm","clk":"5306886910","pt":1646109259270,"mc":[{"id":"1.195395428","rc":[{"atl":[[960,2]],"id":42130949}],"con":true,"img":false}]}
{"op":"mcm","clk":"5306887318","pt":1646109274403,"mc":[{"id":"1.195395428","rc":[{"atl":[[960,0]],"id":42130949}],"con":true,"img":false}]}
{"op":"mcm","clk":"5306887719","pt":1646109289397,"mc":[{"id":"1.195395428","rc":[{"atl":[[960,2]],"id":42130949}],"con":true,"img":false}]}
{"op":"mcm","clk":"5306888200","pt":1646109304542,"mc":[{"id":"1.195395428","rc":[{"atl":[[960,0]],"id":42130949}],"con":true,"img":false}]}
{"op":"mcm","clk":"5306888637","pt":1646109319657,"mc":[{"id":"1.195395428","rc":[{"atl":[[960,2]],"id":42130949}],"con":true,"img":false}]}
{"op":"mcm","clk":"5306889105","pt":1646109334688,"mc":[{"id":"1.195395428","rc":[{"atl":[[960,0]],"id":42130949}],"con":true,"img":false}]}
{"op":"mcm","clk":"5306889587","pt":1646109349783,"mc":[{"id":"1.195395428","rc":[{"atl":[[960,2]],"id":42130949}],"con":true,"img":false}]}
{"op":"mcm","clk":"5306889984","pt":1646109364840,"mc":[{"id":"1.195395428","rc":[{"atl":[[960,0]],"id":42130949}],"con":true,"img":false}]}
{"op":"mcm","clk":"5306890454","pt":1646109379954,"mc":[{"id":"1.195395428","rc":[{"atl":[[960,2]],"id":42130949}],"con":true,"img":false}]}
{"op":"mcm","clk":"5306890911","pt":1646109395030,"mc":[{"id":"1.195395428","rc":[{"atl":[[960,0]],"id":42130949}],"con":true,"img":false}]}
{"op":"mcm","clk":"5306891308","pt":1646109409947,"mc":[{"id":"1.195395428","rc":[{"atl":[[960,2]],"id":42130949}],"con":true,"img":false}]}
{"op":"mcm","clk":"5306891760","pt":1646109425187,"mc":[{"id":"1.195395428","rc":[{"atl":[[960,0]],"id":42130949}],"con":true,"img":false}]}
{"op":"mcm","clk":"5306892132","pt":1646109440124,"mc":[{"id":"1.195395428","rc":[{"atl":[[960,2]],"id":42130949}],"con":true,"img":false}]}
{"op":"mcm","clk":"5306892557","pt":1646109455327,"mc":[{"id":"1.195395428","rc":[{"atl":[[960,0]],"id":42130949}],"con":true,"img":false}]}
{"op":"mcm","clk":"5306892972","pt":1646109470339,"mc":[{"id":"1.195395428","rc":[{"atl":[[960,2]],"id":42130949}],"con":true,"img":false}]}
{"op":"mcm","clk":"5306893449","pt":1646109485382,"mc":[{"id":"1.195395428","rc":[{"atl":[[960,0]],"id":42130949}],"con":true,"img":false}]}
{"op":"mcm","clk":"5306893953","pt":1646109500485,"mc":[{"id":"1.195395428","rc":[{"atl":[[960,2]],"id":42130949}],"con":true,"img":false}]}
{"op":"mcm","clk":"5306894436","pt":1646109515519,"mc":[{"id":"1.195395428","rc":[{"atl":[[960,0]],"id":42130949}],"con":true,"img":false}]}
{"op":"mcm","clk":"5306894942","pt":1646109530603,"mc":[{"id":"1.195395428","rc":[{"atl":[[960,2]],"id":42130949}],"con":true,"img":false}]}
{"op":"mcm","clk":"5306895481","pt":1646109545634,"mc":[{"id":"1.195395428","rc":[{"atl":[[960,0]],"id":42130949}],"con":true,"img":false}]}
{"op":"mcm","clk":"5306895936","pt":1646109560771,"mc":[{"id":"1.195395428","rc":[{"atl":[[960,2]],"id":42130949}],"con":true,"img":false}]}
{"op":"mcm","clk":"5306896408","pt":1646109575765,"mc":[{"id":"1.195395428","rc":[{"atl":[[960,0]],"id":42130949}],"con":true,"img":false}]}
{"op":"mcm","clk":"5306896881","pt":1646109590768,"mc":[{"id":"1.195395428","rc":[{"atl":[[960,2]],"id":42130949}],"con":true,"img":false}]}
{"op":"mcm","clk":"5306897492","pt":1646109605779,"mc":[{"id":"1.195395428","rc":[{"atl":[[960,0]],"id":42130949}],"con":true,"img":false}]}
{"op":"mcm","clk":"5306898025","pt":1646109620949,"mc":[{"id":"1.195395428","rc":[{"atl":[[960,2]],"id":42130949}],"con":true,"img":false}]}
{"op":"mcm","clk":"5306898031","pt":1646109621101,"mc":[{"id":"1.195395428","rc":[{"atb":[[1.67,149.25]],"id":43154456},{"atb":[[4.8,0],[5.4,22.73]],"id":42130949},{"atl":[[2.44,73.45],[2.58,0]],"id":43154457},{"atl":[[23,4.55],[26,0]],"id":37279191}],"con":true,"img":false}]}
{"op":"mcm","clk":"5306898033","pt":1646109621204,"mc":[{"id":"1.195395428","rc":[{"atb":[[1.59,0]],"id":43154456}],"con":true,"img":false}]}
{"op":"mcm","clk":"5306898306","pt":1646109629016,"mc":[{"id":"1.195395428","rc":[{"atl":[[4.1,10.86]],"id":38407646},{"atl":[[2.36,5.11]],"id":36087680}],"con":true,"img":false}]}
{"op":"mcm","clk":"5306898308","pt":1646109629118,"mc":[{"id":"1.195395428","rc":[{"atl":[[5.2,13.37]],"id":38407646},{"atl":[[2.38,52.09]],"id":36087680}],"con":true,"img":false}]}
{"op":"mcm","clk":"5306898534","pt":1646109636054,"mc":[{"id":"1.195395428","rc":[{"atl":[[960,0]],"id":42130949}],"con":true,"img":false}]}
{"op":"mcm","clk":"5306899062","pt":1646109651072,"mc":[{"id":"1.195395428","rc":[{"atl":[[960,2]],"id":42130949}],"con":true,"img":false}]}
{"op":"mcm","clk":"5306899283","pt":1646109656770,"mc":[{"id":"1.195395428","rc":[{"atb":[[1.68,76.57],[1.65,0]],"id":43154456}],"con":true,"img":false}]}
{"op":"mcm","clk":"5306899657","pt":1646109666175,"mc":[{"id":"1.195395428","rc":[{"atl":[[960,0]],"id":42130949}],"con":true,"img":false}]}
{"op":"mcm","clk":"5306900246","pt":1646109681204,"mc":[{"id":"1.195395428","rc":[{"atl":[[960,2]],"id":42130949}],"con":true,"img":false}]}
{"op":"mcm","clk":"5306900788","pt":1646109696328,"mc":[{"id":"1.195395428","rc":[{"atl":[[960,0]],"id":42130949}],"con":true,"img":false}]}
{"op":"mcm","clk":"5306901184","pt":1646109711330,"mc":[{"id":"1.195395428","rc":[{"atl":[[960,2]],"id":42130949}],"con":true,"img":false}]}
{"op":"mcm","clk":"5306901640","pt":1646109726463,"mc":[{"id":"1.195395428","rc":[{"atl":[[960,0]],"id":42130949}],"con":true,"img":false}]}
{"op":"mcm","clk":"5306902046","pt":1646109741554,"mc":[{"id":"1.195395428","rc":[{"atl":[[960,2]],"id":42130949}],"con":true,"img":false}]}
{"op":"mcm","clk":"5306902377","pt":1646109756183,"mc":[{"id":"1.195395428","rc":[{"atb":[[1.6,166.67],[1.67,0]],"id":43154456},{"atb":[[4.8,26.32],[5.4,0]],"id":42130949},{"atl":[[2.44,8.27],[2.58,63.29]],"id":43154457}],"con":true,"img":false}]}
{"op":"mcm","clk":"5306902386","pt":1646109756593,"mc":[{"id":"1.195395428","rc":[{"atl":[[960,0]],"id":42130949}],"con":true,"img":false}]}
{"op":"mcm","clk":"5306902733","pt":1646109771717,"mc":[{"id":"1.195395428","rc":[{"atl":[[960,2]],"id":42130949}],"con":true,"img":false}]}
{"op":"mcm","clk":"5306902961","pt":1646109779208,"mc":[{"id":"1.195395428","rc":[{"atl":[[5.2,2.7]],"id":38407646}],"con":true,"img":false}]}
{"op":"mcm","clk":"5306902962","pt":1646109779312,"mc":[{"id":"1.195395428","rc":[{"atl":[[4.1,21.53]],"id":38407646}],"con":true,"img":false}]}
{"op":"mcm","clk":"5306903203","pt":1646109786701,"mc":[{"id":"1.195395428","rc":[{"atl":[[960,0]],"id":42130949}],"con":true,"img":false}]}
{"op":"mcm","clk":"5306903207","pt":1646109786903,"mc":[{"id":"1.195395428","rc":[{"atl":[[2.58,0]],"id":43154457}],"con":true,"img":false}]}
{"op":"mcm","clk":"5306903210","pt":1646109787007,"mc":[{"id":"1.195395428","rc":[{"atb":[[1.6,0],[1.68,223.63]],"id":43154456},{"atb":[[4.8,0],[5.4,22.73]],"id":42130949},{"atl":[[2.44,73.45]],"id":43154457}],"con":true,"img":false}]}
{"op":"mcm","clk":"5306903382","pt":1646109794028,"mc":[{"id":"1.195395428","rc":[{"atl":[[4.1,10.86]],"id":38407646}],"con":true,"img":false}]}
{"op":"mcm","clk":"5306903385","pt":1646109794131,"mc":[{"id":"1.195395428","rc":[{"atl":[[5.2,13.37]],"id":38407646}],"con":true,"img":false}]}
{"op":"mcm","clk":"5306903549","pt":1646109801866,"mc":[{"id":"1.195395428","rc":[{"atl":[[960,2]],"id":42130949}],"con":true,"img":false}]}
{"op":"mcm","clk":"5306903901","pt":1646109816967,"mc":[{"id":"1.195395428","rc":[{"atl":[[960,0]],"id":42130949}],"con":true,"img":false}]}
{"op":"mcm","clk":"5306903982","pt":1646109820965,"mc":[{"id":"1.195395428","rc":[{"atl":[[2.48,67.57]],"id":43154457}],"con":true,"img":false}]}
{"op":"mcm","clk":"5306903984","pt":1646109821070,"mc":[{"id":"1.195395428","rc":[{"atl":[[2.44,8.27]],"id":43154457}],"con":true,"img":false}]}
{"op":"mcm","clk":"5306904222","pt":1646109831988,"mc":[{"id":"1.195395428","rc":[{"atl":[[960,2]],"id":42130949}],"con":true,"img":false}]}
{"op":"mcm","clk":"5306904497","pt":1646109842183,"mc":[{"id":"1.195395428","rc":[{"atb":[[5,55.17],[4.4,0]],"id":37279191}],"con":true,"img":false}]}
{"op":"mcm","clk":"5306904541","pt":1646109843677,"mc":[{"id":"1.195395428","rc":[{"atl":[[5.2,2.7]],"id":38407646}],"con":true,"img":false}]}
{"op":"mcm","clk":"5306904546","pt":1646109843778,"mc":[{"id":"1.195395428","rc":[{"atl":[[4.1,21.53]],"id":38407646}],"con":true,"img":false}]}
{"op":"mcm","clk":"5306904619","pt":1646109847106,"mc":[{"id":"1.195395428","rc":[{"atl":[[960,0]],"id":42130949}],"con":true,"img":false}]}
{"op":"mcm","clk":"5306904871","pt":1646109858783,"mc":[{"id":"1.195395428","rc":[{"atb":[[4.5,26.16]],"id":37279191}],"con":true,"img":false}]}
{"op":"mcm","clk":"5306904946","pt":1646109862111,"mc":[{"id":"1.195395428","rc":[{"atl":[[960,2]],"id":42130949}],"con":true,"img":false}]}
{"op":"mcm","clk":"5306905294","pt":1646109877227,"mc":[{"id":"1.195395428","rc":[{"atl":[[960,0]],"id":42130949}],"con":true,"img":false}]}
{"op":"mcm","clk":"5306905633","pt":1646109892307,"mc":[{"id":"1.195395428","rc":[{"atl":[[960,2]],"id":42130949}],"con":true,"img":false}]}
{"op":"mcm","clk":"5306906030","pt":1646109907374,"mc":[{"id":"1.195395428","rc":[{"atl":[[960,0]],"id":42130949}],"con":true,"img":false}]}
{"op":"mcm","clk":"5306906463","pt":1646109922469,"mc":[{"id":"1.195395428","rc":[{"atl":[[960,2]],"id":42130949}],"con":true,"img":false}]}
{"op":"mcm","clk":"5306906876","pt":1646109937525,"mc":[{"id":"1.195395428","rc":[{"atl":[[960,0]],"id":42130949}],"con":true,"img":false}]}
{"op":"mcm","clk":"5306907153","pt":1646109952612,"mc":[{"id":"1.195395428","rc":[{"atl":[[960,2]],"id":42130949}],"con":true,"img":false}]}
{"op":"mcm","clk":"5306907452","pt":1646109967632,"mc":[{"id":"1.195395428","rc":[{"atl":[[960,0]],"id":42130949}],"con":true,"img":false}]}
{"op":"mcm","clk":"5306907726","pt":1646109980871,"mc":[{"id":"1.195395428","rc":[{"atl":[[85,5]],"id":43154457},{"atl":[[85,5]],"id":36087680}],"con":true,"img":false}]}
{"op":"mcm","clk":"5306907761","pt":1646109982656,"mc":[{"id":"1.195395428","rc":[{"atl":[[960,2]],"id":42130949}],"con":true,"img":false}]}
{"op":"mcm","clk":"5306907990","pt":1646109997919,"mc":[{"id":"1.195395428","rc":[{"atl":[[960,0]],"id":42130949}],"con":true,"img":false}]}
{"op":"mcm","clk":"5306908328","pt":1646110012802,"mc":[{"id":"1.195395428","rc":[{"atl":[[960,2]],"id":42130949}],"con":true,"img":false}]}
{"op":"mcm","clk":"5306908733","pt":1646110027640,"mc":[{"id":"1.195395428","rc":[{"atb":[[1.59,169.49],[1.68,76.57]],"id":43154456},{"atb":[[4.8,26.32],[5.4,0]],"id":42130949},{"atl":[[2.62,61.73]],"id":43154457},{"atb":[[5,30.17],[4.4,29.41]],"id":37279191}],"con":true,"img":false}]}
{"op":"mcm","clk":"5306908736","pt":1646110027740,"mc":[{"id":"1.195395428","rc":[{"atl":[[2.48,0]],"id":43154457}],"con":true,"img":false}]}
{"op":"mcm","clk":"5306908743","pt":1646110027945,"mc":[{"id":"1.195395428","rc":[{"atl":[[960,0]],"id":42130949}],"con":true,"img":false}]}
{"op":"mcm","clk":"5306909128","pt":1646110042973,"mc":[{"id":"1.195395428","rc":[{"atl":[[960,2]],"id":42130949}],"con":true,"img":false}]}
{"op":"mcm","clk":"5306909546","pt":1646110058061,"mc":[{"id":"1.195395428","rc":[{"atl":[[960,0]],"id":42130949}],"con":true,"img":false}]}
{"op":"mcm","clk":"5306909929","pt":1646110073095,"mc":[{"id":"1.195395428","rc":[{"atl":[[960,2]],"id":42130949}],"con":true,"img":false}]}
{"op":"mcm","clk":"5306910305","pt":1646110088141,"mc":[{"id":"1.195395428","rc":[{"atl":[[960,0]],"id":42130949}],"con":true,"img":false}]}
{"op":"mcm","clk":"5306911105","pt":1646110103280,"mc":[{"id":"1.195395428","rc":[{"atl":[[960,2]],"id":42130949}],"con":true,"img":false}]}
{"op":"mcm","clk":"5306911982","pt":1646110118362,"mc":[{"id":"1.195395428","rc":[{"atl":[[960,0]],"id":42130949}],"con":true,"img":false}]}
{"op":"mcm","clk":"5306912547","pt":1646110133091,"mc":[{"id":"1.195395428","rc":[{"atb":[[1.59,0],[1.67,149.25]],"id":43154456},{"atb":[[4.8,0],[5.3,23.26]],"id":42130949},{"atl":[[2.62,0],[2.48,16.56]],"id":43154457}],"con":true,"img":false}]}
{"op":"mcm","clk":"5306912560","pt":1646110133400,"mc":[{"id":"1.195395428","rc":[{"atl":[[960,2]],"id":42130949}],"con":true,"img":false}]}
{"op":"mcm","clk":"5306913097","pt":1646110148505,"mc":[{"id":"1.195395428","rc":[{"atl":[[960,0]],"id":42130949},{"atl":[[2.38,21.63]],"id":36087680}],"con":true,"img":false}]}
{"op":"mcm","clk":"5306913103","pt":1646110148605,"mc":[{"id":"1.195395428","rc":[{"atl":[[2.36,35.58]],"id":36087680}],"con":true,"img":false}]}
{"op":"mcm","clk":"5306913607","pt":1646110163630,"mc":[{"id":"1.195395428","rc":[{"atl":[[960,2]],"id":42130949}],"con":true,"img":false}]}
{"op":"mcm","clk":"5306914106","pt":1646110178738,"mc":[{"id":"1.195395428","rc":[{"atl":[[960,0]],"id":42130949}],"con":true,"img":false}]}
{"op":"mcm","clk":"5306914241","pt":1646110182452,"mc":[{"id":"1.195395428","rc":[{"atb":[[1.23,0]],"id":38407646},{"atb":[[1.23,0]],"id":43154456},{"atb":[[1.23,0]],"id":42130949},{"atb":[[1.23,0]],"id":37279191}],"con":true,"img":false}]}
{"op":"mcm","clk":"5306914561","pt":1646110193761,"mc":[{"id":"1.195395428","rc":[{"atl":[[960,2]],"id":42130949}],"con":true,"img":false}]}
{"op":"mcm","clk":"5306914656","pt":1646110196878,"mc":[{"id":"1.195395428","rc":[{"atb":[[1.23,250]],"id":38407646},{"atb":[[1.23,250]],"id":43154456},{"atb":[[1.23,250]],"id":42130949},{"atb":[[1.23,250]],"id":37279191}],"con":true,"img":false}]}
{"op":"mcm","clk":"5306915071","pt":1646110208792,"mc":[{"id":"1.195395428","rc":[{"atl":[[960,0]],"id":42130949}],"con":true,"img":false}]}
{"op":"mcm","clk":"5306915516","pt":1646110223803,"mc":[{"id":"1.195395428","rc":[{"atl":[[960,2]],"id":42130949}],"con":true,"img":false}]}
{"op":"mcm","clk":"5306915991","pt":1646110238850,"mc":[{"id":"1.195395428","rc":[{"atl":[[960,0]],"id":42130949}],"con":true,"img":false}]}
{"op":"mcm","clk":"5306916506","pt":1646110253843,"mc":[{"id":"1.195395428","rc":[{"atl":[[960,2]],"id":42130949}],"con":true,"img":false}]}
{"op":"mcm","clk":"5306916862","pt":1646110266573,"mc":[{"id":"1.195395428","rc":[{"atb":[[2.18,0]],"id":38407646},{"atl":[[5.9,0]],"id":38407646},{"atb":[[1.96,0]],"id":43154456},{"atl":[[5.7,0]],"id":43154456},{"atb":[[6.2,0]],"id":42130949},{"atl":[[960,0]],"id":42130949},{"atb":[[1.36,0]],"id":43154457},{"atl":[[2.76,0]],"id":43154457},{"atb":[[3.7,0]],"id":37279191},{"atl":[[40,7.66]],"id":37279191},{"atb":[[1.45,0]],"id":36087680},{"atl":[[2.72,0]],"id":36087680}],"con":true,"img":false}]}
{"op":"mcm","clk":"5306917289","pt":1646110281822,"mc":[{"id":"1.195395428","rc":[{"atb":[[2.18,2]],"id":38407646},{"atl":[[5.9,2]],"id":38407646},{"atb":[[1.96,2]],"id":43154456},{"atl":[[5.7,2]],"id":43154456},{"atb":[[6.2,2]],"id":42130949},{"atl":[[960,2]],"id":42130949},{"atb":[[1.36,2]],"id":43154457},{"atl":[[2.76,2]],"id":43154457},{"atb":[[3.7,2]],"id":37279191},{"atl":[[40,9.66]],"id":37279191},{"atb":[[1.45,2]],"id":36087680},{"atl":[[2.72,2]],"id":36087680}],"con":true,"img":false}]}
{"op":"mcm","clk":"5306917688","pt":1646110296922,"mc":[{"id":"1.195395428","rc":[{"atl":[[960,0]],"id":42130949}],"con":true,"img":false}]}
{"op":"mcm","clk":"5306918103","pt":1646110311835,"mc":[{"id":"1.195395428","rc":[{"atl":[[960,2]],"id":42130949}],"con":true,"img":false}]}
{"op":"mcm","clk":"5306918520","pt":1646110327046,"mc":[{"id":"1.195395428","rc":[{"atl":[[960,0]],"id":42130949}],"con":true,"img":false}]}
{"op":"mcm","clk":"5306919008","pt":1646110341992,"mc":[{"id":"1.195395428","rc":[{"atl":[[960,2]],"id":42130949}],"con":true,"img":false}]}
{"op":"mcm","clk":"5306919435","pt":1646110355511,"mc":[{"id":"1.195395428","rc":[{"atb":[[1.59,169.49]],"id":43154456},{"atl":[[2.64,32.11],[2.48,0]],"id":43154457}],"con":true,"img":false}]}
{"op":"mcm","clk":"5306919438","pt":1646110355612,"mc":[{"id":"1.195395428","rc":[{"atb":[[1.67,0]],"id":43154456}],"con":true,"img":false}]}
{"op":"mcm","clk":"5306919477","pt":1646110357101,"mc":[{"id":"1.195395428","rc":[{"atl":[[960,0]],"id":42130949}],"con":true,"img":false}]}
{"op":"mcm","clk":"5306920013","pt":1646110372028,"mc":[{"id":"1.195395428","rc":[{"atl":[[960,2]],"id":42130949}],"con":true,"img":false}]}
{"op":"mcm","clk":"5306920486","pt":1646110387291,"mc":[{"id":"1.195395428","rc":[{"atl":[[960,0]],"id":42130949}],"con":true,"img":false}]}
{"op":"mcm","clk":"5306920957","pt":1646110402302,"mc":[{"id":"1.195395428","rc":[{"atl":[[960,2]],"id":42130949}],"con":true,"img":false}]}
{"op":"mcm","clk":"5306921324","pt":1646110417409,"mc":[{"id":"1.195395428","rc":[{"atl":[[960,0]],"id":42130949}],"con":true,"img":false}]}
{"op":"mcm","clk":"5306921736","pt":1646110432354,"mc":[{"id":"1.195395428","rc":[{"atl":[[960,2]],"id":42130949}],"con":true,"img":false}]}
{"op":"mcm","clk":"5306922172","pt":1646110447562,"mc":[{"id":"1.195395428","rc":[{"atl":[[960,0]],"id":42130949}],"con":true,"img":false}]}
{"op":"mcm","clk":"5306922546","pt":1646110462569,"mc":[{"id":"1.195395428","rc":[{"atl":[[960,2]],"id":42130949}],"con":true,"img":false}]}
{"op":"mcm","clk":"5306922932","pt":1646110477620,"mc":[{"id":"1.195395428","rc":[{"atl":[[960,0]],"id":42130949}],"con":true,"img":false}]}
{"op":"mcm","clk":"5306923322","pt":1646110492635,"mc":[{"id":"1.195395428","rc":[{"atl":[[960,2]],"id":42130949}],"con":true,"img":false}]}
{"op":"mcm","clk":"5306923695","pt":1646110507775,"mc":[{"id":"1.195395428","rc":[{"atl":[[960,0]],"id":42130949}],"con":true,"img":false}]}
{"op":"mcm","clk":"5306924064","pt":1646110522676,"mc":[{"id":"1.195395428","rc":[{"atl":[[960,2]],"id":42130949}],"con":true,"img":false}]}
{"op":"mcm","clk":"5306924409","pt":1646110537927,"mc":[{"id":"1.195395428","rc":[{"atl":[[960,0]],"id":42130949}],"con":true,"img":false}]}
{"op":"mcm","clk":"5306924524","pt":1646110543732,"mc":[{"id":"1.195395428","marketDefinition":{"bspMarket":true,"turnInPlayEnabled":false,"persistenceEnabled":false,"marketBaseRate":7.0,"eventId":"31270458","eventTypeId":"4339","numberOfWinners":2,"bettingType":"ODDS","marketType":"PLACE","marketTime":"2022-03-01T05:32:00.000Z","suspendTime":"2022-03-01T05:32:00.000Z","bspReconciled":false,"complete":true,"inPlay":false,"crossMatching":true,"runnersVoidable":false,"numberOfActiveRunners":6,"betDelay":0,"status":"SUSPENDED","runners":[{"status":"ACTIVE","sortPriority":1,"id":43154456,"name":"1. Buckle Up Zion"},{"status":"ACTIVE","sortPriority":2,"id":43154457,"name":"2. Rambo Bobbie"},{"status":"ACTIVE","sortPriority":3,"id":38407646,"name":"4. Hiccup Gus"},{"status":"ACTIVE","sortPriority":4,"id":42130949,"name":"5. Into The Fire"},{"status":"ACTIVE","sortPriority":5,"id":37279191,"name":"7. Shiffrin"},{"status":"ACTIVE","sortPriority":6,"id":36087680,"name":"8. White Poison"},{"status":"REMOVED","sortPriority":7,"removalDate":"2022-02-28T22:23:28.000Z","id":39979946,"name":"3. Marshall Giblet"}],"regulators":["MR_INT"],"venue":"Devonport","countryCode":"AU","discountAllowed":true,"timezone":"Australia/Sydney","openDate":"2022-03-01T02:00:00.000Z","version":4381133003,"name":"To Be Placed","eventName":"Devonport (AUS) 1st Mar"},"rc":[],"con":true,"img":false}]}
{"op":"mcm","clk":"5306924754","pt":1646110555445,"mc":[{"id":"1.195395428","rc":[{"atb":[[1.23,0]],"id":38407646},{"atb":[[1.23,0]],"id":43154456},{"atb":[[1.23,0]],"id":42130949},{"atb":[[1.23,0]],"id":37279191}],"con":true,"img":false}]}
{"op":"mcm","clk":"5306927295","pt":1646110689089,"mc":[{"id":"1.195395428","marketDefinition":{"bspMarket":true,"turnInPlayEnabled":false,"persistenceEnabled":false,"marketBaseRate":7.0,"eventId":"31270458","eventTypeId":"4339","numberOfWinners":2,"bettingType":"ODDS","marketType":"PLACE","marketTime":"2022-03-01T05:32:00.000Z","suspendTime":"2022-03-01T05:32:00.000Z","bspReconciled":false,"complete":true,"inPlay":false,"crossMatching":false,"runnersVoidable":false,"numberOfActiveRunners":6,"betDelay":0,"status":"SUSPENDED","runners":[{"status":"ACTIVE","sortPriority":1,"id":43154456,"name":"1. Buckle Up Zion"},{"status":"ACTIVE","sortPriority":2,"id":43154457,"name":"2. Rambo Bobbie"},{"status":"ACTIVE","sortPriority":3,"id":38407646,"name":"4. Hiccup Gus"},{"status":"ACTIVE","sortPriority":4,"id":42130949,"name":"5. Into The Fire"},{"status":"ACTIVE","sortPriority":5,"id":37279191,"name":"7. Shiffrin"},{"status":"ACTIVE","sortPriority":6,"id":36087680,"name":"8. White Poison"},{"status":"REMOVED","sortPriority":7,"removalDate":"2022-02-28T22:23:28.000Z","id":39979946,"name":"3. Marshall Giblet"}],"regulators":["MR_INT"],"venue":"Devonport","countryCode":"AU","discountAllowed":true,"timezone":"Australia/Sydney","openDate":"2022-03-01T02:00:00.000Z","version":4381133801,"name":"To Be Placed","eventName":"Devonport (AUS) 1st Mar"},"rc":[],"con":true,"img":false}]}
{"op":"mcm","clk":"5306927295","pt":1646110689089,"mc":[{"id":"1.195395428","rc":[{"atb":[[2.24,0],[2,0],[1.73,0],[2.54,0],[2.5,0],[2.06,0],[2.52,0],[2.46,0],[2.18,0],[2.26,0],[1.95,0],[2.1,0]],"id":38407646},{"atl":[[16.5,0],[4.3,0],[8.6,0],[5,0],[4.1,0],[5.3,0],[11.5,0],[7.6,0],[5.2,0],[6.6,0],[4.2,0],[5.9,0]],"id":38407646},{"spb":[[3.05,0]],"id":38407646},{"atb":[[2.24,0],[2,0],[1.59,0],[2.32,0],[2.3,0],[2.12,0],[1.68,0],[1.96,0],[1.95,0],[2.1,0]],"id":43154456},{"atl":[[4.8,0],[5.3,0],[7.4,0],[11.5,0],[4,0],[16.5,0],[8.6,0],[5,0],[3.95,0],[4.1,0],[5.2,0],[5.7,0],[6.6,0]],"id":43154456},{"spb":[[2.46,0]],"id":43154456},{"atb":[[9.2,0],[10.5,0],[6.2,0],[11,0],[8.2,0],[5.3,0],[9.4,0]],"id":42130949},{"spl":[[11.5,0]],"id":42130949},{"atl":[[260,0],[80,0],[160,0],[44,0],[180,0],[360,0],[46,0],[460,0]],"id":42130949},{"atb":[[1.41,0],[1.2,0],[1.36,0],[1.45,0],[1.25,0],[1.15,0],[1.57,0],[1.21,0],[1.53,0],[1.52,0]],"id":43154457},{"atl":[[2.4,0],[3.6,0],[2.42,0],[3.1,0],[85,0],[2.44,0],[2.64,0],[2.84,0],[3.55,0],[2.76,0]],"id":43154457},{"spb":[[1.77,0]],"id":43154457},{"trd":[[2.44,0],[2.64,0]],"ltp":2.44,"tv":0.0,"id":43154457},{"atb":[[4.5,0],[5,0],[5.5,0],[3.7,0],[6,0],[4.4,0]],"id":37279191},{"atl":[[16.5,0],[17,0],[19.5,0],[40,0],[23,0],[95,0],[190,0],[48,0],[29,0]],"id":37279191},{"spb":[[7.2,0]],"id":37279191},{"atb":[[1.2,0],[1.45,0],[1.43,0],[1.25,0],[1.15,0],[1.67,0],[1.26,0],[1.62,0],[1.49,0],[1.61,0]],"id":36087680},{"atl":[[2.72,0],[3.6,0],[5.8,0],[3.1,0],[2.44,0],[2.64,0],[2.84,0],[3.55,0],[2.36,0],[2.4,0],[2.42,0],[85,0],[2.38,0]],"id":36087680},{"spb":[[1.75,0]],"id":36087680},{"trd":[[2.44,0],[2.64,0]],"ltp":2.44,"tv":0.0,"id":36087680}],"con":true,"img":false}]}
{"op":"mcm","clk":"5306927309","pt":1646110689940,"mc":[{"id":"1.195395428","marketDefinition":{"bspMarket":true,"turnInPlayEnabled":false,"persistenceEnabled":false,"marketBaseRate":7.0,"eventId":"31270458","eventTypeId":"4339","numberOfWinners":2,"bettingType":"ODDS","marketType":"PLACE","marketTime":"2022-03-01T05:32:00.000Z","suspendTime":"2022-03-01T05:32:00.000Z","bspReconciled":false,"complete":true,"inPlay":false,"crossMatching":false,"runnersVoidable":false,"numberOfActiveRunners":0,"betDelay":0,"status":"CLOSED","settledTime":"2022-03-01T04:58:08.000Z","runners":[{"status":"REMOVED","sortPriority":1,"removalDate":"2022-02-28T22:23:28.000Z","id":39979946,"name":"3. Marshall Giblet"},{"status":"REMOVED","sortPriority":2,"removalDate":"2022-03-01T04:58:08.000Z","id":43154456,"name":"1. Buckle Up Zion"},{"status":"REMOVED","sortPriority":3,"removalDate":"2022-03-01T04:58:08.000Z","id":43154457,"name":"2. Rambo Bobbie"},{"status":"REMOVED","sortPriority":4,"removalDate":"2022-03-01T04:58:08.000Z","id":38407646,"name":"4. Hiccup Gus"},{"status":"REMOVED","sortPriority":5,"removalDate":"2022-03-01T04:58:08.000Z","id":42130949,"name":"5. Into The Fire"},{"status":"REMOVED","sortPriority":6,"removalDate":"2022-03-01T04:58:08.000Z","id":37279191,"name":"7. Shiffrin"},{"status":"REMOVED","sortPriority":7,"removalDate":"2022-03-01T04:58:08.000Z","id":36087680,"name":"8. White Poison"}],"regulators":["MR_INT"],"venue":"Devonport","countryCode":"AU","discountAllowed":true,"timezone":"Australia/Sydney","openDate":"2022-03-01T02:00:00.000Z","version":4381133819,"name":"To Be Placed","eventName":"Devonport (AUS) 1st Mar"},"rc":[],"con":true,"img":false}]}
