{"op":"mcm","clk":"5351767864","pt":1646175389027,"mc":[{"id":"1.195453777","marketDefinition":{"bspMarket":true,"turnInPlayEnabled":false,"persistenceEnabled":false,"marketBaseRate":7.0,"eventId":"31272499","eventTypeId":"4339","numberOfWinners":2,"bettingType":"ODDS","marketType":"PLACE","marketTime":"2022-03-02T10:54:00.000Z","suspendTime":"2022-03-02T10:54:00.000Z","bspReconciled":false,"complete":true,"inPlay":false,"crossMatching":false,"runnersVoidable":false,"numberOfActiveRunners":7,"betDelay":0,"status":"OPEN","runners":[{"status":"ACTIVE","sortPriority":1,"id":38440014,"name":"1. Wenatchee"},{"status":"ACTIVE","sortPriority":2,"id":36201034,"name":"2. Loco Dinero"},{"status":"ACTIVE","sortPriority":3,"id":38276037,"name":"3. Deadly Choice"},{"status":"ACTIVE","sortPriority":4,"id":40659166,"name":"4. Unique Speed"},{"status":"ACTIVE","sortPriority":5,"id":39594662,"name":"6. Scriven"},{"status":"ACTIVE","sortPriority":6,"id":39849129,"name":"7. Prosecutor"},{"status":"ACTIVE","sortPriority":7,"id":32633412,"name":"8. Off Break"}],"regulators":["MR_INT"],"venue":"Rockhampton","countryCode":"AU","discountAllowed":true,"timezone":"Australia/Queensland","openDate":"2022-03-02T08:34:00.000Z","version":4382437875,"name":"To Be Placed","eventName":"Rockhampton (AUS) 2nd Mar"},"rc":[],"con":true,"img":false}]}
{"op":"mcm","clk":"5351835883","pt":1646176787551,"mc":[{"id":"1.195453777","rc":[{"atb":[[2.9,63.6],[3,60.42],[3.25,26.85]],"id":32633412},{"atl":[[16,1.61],[34,1.46],[11,1.2],[22,1.14],[8.4,1.63]],"id":32633412},{"spn":5.82,"spf":"NaN","id":32633412},{"atb":[[2.06,57],[1.98,123.31],[1.93,129.94]],"id":39594662},{"atl":[[16,3.22],[6.4,2.23],[11,2.41],[5.2,2.87],[8.4,3.26]],"id":39594662},{"spn":3.63,"spf":"NaN","id":39594662},{"atb":[[1.2,604.24],[1.25,483.39],[1.3,201.41]],"id":40659166},{"atl":[[2.54,7.84],[3.85,16.96],[2.74,6.94],[3.35,10.28],[2.94,12.46]],"id":40659166},{"spn":1.92,"spf":"NaN","id":40659166},{"atb":[[9.8,6.86],[8.8,15.49],[7.8,17.77]],"id":38440014},{"atl":[[70,0.17],[140,0.08],[340,0.07],[440,0.1],[240,0.1]],"id":38440014},{"spn":39.9,"spf":"NaN","id":38440014},{"atb":[[3.45,49.32],[3.95,20.48],[3.7,44.75]],"id":36201034},{"atl":[[18.5,0.69],[85,0.57],[44,0.56],[13.5,0.96],[27,0.93]],"id":36201034},{"spn":8.72,"spf":"NaN","id":36201034},{"atb":[[1.2,604.24],[1.25,241.69],[1.15,805.66]],"id":38276037},{"atl":[[3.6,18.59],[3.1,11.5],[2.44,8.39],[2.64,7.37],[2.84,13.13]],"id":38276037},{"spn":1.84,"spf":"NaN","id":38276037},{"atb":[[2.74,69.45],[2.84,65.67],[2.94,31.14]],"id":39849129},{"atl":[[8,1.72],[10,1.34],[20,1.27],[15,1.72],[30,1.66]],"id":39849129},{"spn":5.47,"spf":"NaN","id":39849129}],"con":true,"img":false}]}
{"op":"mcm","clk":"5351869735","pt":1646177573353,"mc":[{"id":"1.195453777","rc":[{"atb":[[2.9,0],[3,0],[3.25,0]],"id":32633412},{"atl":[[16,0],[34,0],[11,0],[22,0],[8.4,0]],"id":32633412},{"spn":"NaN","spf":"NaN","id":32633412},{"atb":[[1.2,0],[1.25,0],[1.3,0]],"id":40659166},{"atl":[[2.54,0],[3.85,0],[2.74,0],[3.35,0],[2.94,0]],"id":40659166},{"spn":"NaN","spf":"NaN","id":40659166},{"atb":[[9.8,0],[8.8,0],[7.8,0]],"id":38440014},{"atl":[[70,0],[140,0],[340,0],[440,0],[240,0]],"id":38440014},{"spn":"NaN","spf":"NaN","id":38440014},{"atb":[[3.45,0],[3.95,0],[3.7,0]],"id":36201034},{"atl":[[18.5,0],[85,0],[44,0],[13.5,0],[27,0]],"id":36201034},{"spn":"NaN","spf":"NaN","id":36201034},{"atb":[[1.2,0],[1.25,0],[1.15,0]],"id":38276037},{"atl":[[3.6,0],[3.1,0],[2.44,0],[2.64,0],[2.84,0]],"id":38276037},{"spn":"NaN","spf":"NaN","id":38276037}],"con":true,"img":false}]}
{"op":"mcm","clk":"5351870292","pt":1646177583506,"mc":[{"id":"1.195453777","rc":[{"atb":[[3.6,46.47],[3.85,21.2],[3.35,51.42]],"id":32633412},{"atl":[[17.5,0.73],[75,0.65],[40,0.62],[12.5,1.05],[25,1]],"id":32633412},{"atb":[[1.25,483.39],[1.3,402.83],[1.35,172.64]],"id":40659166},{"atl":[[2.8,6.71],[4,16.11],[3,12.08],[2.6,7.55],[3.5,9.66]],"id":40659166},{"atb":[[9.8,6.86],[8.8,15.49],[7.8,17.77]],"id":38440014},{"atl":[[70,0.17],[140,0.08],[340,0.07],[440,0.1],[240,0.1]],"id":38440014},{"atb":[[3.45,49.32],[3.95,20.48],[3.7,44.75]],"id":36201034},{"atl":[[18.5,0.69],[85,0.57],[44,0.56],[13.5,0.96],[27,0.93]],"id":36201034},{"atb":[[1.2,604.24],[1.25,241.69],[1.15,805.66]],"id":38276037},{"atl":[[3.6,18.59],[3.1,11.5],[2.44,8.39],[2.64,7.37],[2.84,13.13]],"id":38276037}],"con":true,"img":false}]}
{"op":"mcm","clk":"5352003865","pt":1646180202622,"mc":[{"id":"1.195453777","marketDefinition":{"bspMarket":true,"turnInPlayEnabled":false,"persistenceEnabled":false,"marketBaseRate":7.0,"eventId":"31272499","eventTypeId":"4339","numberOfWinners":2,"bettingType":"ODDS","marketType":"PLACE","marketTime":"2022-03-02T10:54:00.000Z","suspendTime":"2022-03-02T10:54:00.000Z","bspReconciled":false,"complete":true,"inPlay":false,"crossMatching":false,"runnersVoidable":false,"numberOfActiveRunners":7,"betDelay":0,"status":"OPEN","runners":[{"status":"ACTIVE","sortPriority":1,"id":38440014,"name":"1. Wenatchee"},{"status":"ACTIVE","sortPriority":2,"id":36201034,"name":"2. Loco Dinero"},{"status":"ACTIVE","sortPriority":3,"id":38276037,"name":"3. Deadly Choice"},{"status":"ACTIVE","sortPriority":4,"id":40659166,"name":"4. Unique Speed"},{"status":"ACTIVE","sortPriority":5,"id":39594662,"name":"6. Scriven"},{"status":"ACTIVE","sortPriority":6,"id":39849129,"name":"7. Prosecutor"},{"status":"ACTIVE","sortPriority":7,"id":32633412,"name":"8. Off Break"}],"regulators":["MR_INT"],"venue":"Rockhampton","countryCode":"AU","discountAllowed":true,"timezone":"Australia/Queensland","openDate":"2022-03-02T08:34:00.000Z","version":4382437875,"name":"To Be Placed","eventName":"Rockhampton (AUS) 2nd Mar"},"rc":[{"atb":[[3.6,46.48],[3.85,21.2],[3.35,51.43]],"id":32633412},{"atl":[[17.5,0.73],[75,0.65],[40,0.62],[12.5,1.05],[25,1]],"id":32633412},{"spn":8.17,"spf":"NaN","id":32633412},{"atb":[[2.06,57.01],[1.98,123.32],[1.93,129.95]],"id":39594662},{"atl":[[16,3.22],[6.4,2.23],[11,2.41],[5.2,2.88],[8.4,3.26]],"id":39594662},{"spn":3.63,"spf":"NaN","id":39594662},{"atb":[[1.25,483.44],[1.3,402.87],[1.35,172.65]],"id":40659166},{"atl":[[2.8,6.71],[4,16.11],[3,12.08],[2.6,7.55],[3.5,9.66]],"id":40659166},{"spn":1.97,"spf":"NaN","id":40659166},{"atb":[[9.8,6.86],[8.8,15.49],[7.8,17.77]],"id":38440014},{"atl":[[70,0.17],[140,0.08],[340,0.07],[440,0.1],[240,0.1]],"id":38440014},{"spn":39.9,"spf":"NaN","id":38440014},{"atb":[[3.45,49.33],[3.95,20.48],[3.7,44.76]],"id":36201034},{"atl":[[18.5,0.69],[85,0.57],[44,0.56],[13.5,0.96],[27,0.93]],"id":36201034},{"spn":8.72,"spf":"NaN","id":36201034},{"atb":[[1.2,604.31],[1.25,241.72],[1.15,805.74]],"id":38276037},{"atl":[[3.6,18.59],[3.1,11.5],[2.44,8.39],[2.64,7.37],[2.84,13.13]],"id":38276037},{"spn":1.84,"spf":"NaN","id":38276037},{"atb":[[2.74,69.46],[2.84,65.68],[2.94,31.15]],"id":39849129},{"atl":[[8,1.72],[10,1.34],[20,1.27],[15,1.72],[30,1.66]],"id":39849129},{"spn":5.47,"spf":"NaN","id":39849129}],"con":true,"img":true}]}
{"op":"mcm","clk":"5352146210","pt":1646183572662,"mc":[{"id":"1.195453777","marketDefinition":{"bspMarket":true,"turnInPlayEnabled":false,"persistenceEnabled":false,"marketBaseRate":7.0,"eventId":"31272499","eventTypeId":"4339","numberOfWinners":2,"bettingType":"ODDS","marketType":"PLACE","marketTime":"2022-03-02T10:54:00.000Z","suspendTime":"2022-03-02T10:54:00.000Z","bspReconciled":false,"complete":true,"inPlay":false,"crossMatching":false,"runnersVoidable":false,"numberOfActiveRunners":7,"betDelay":0,"status":"OPEN","runners":[{"status":"ACTIVE","sortPriority":1,"id":38440014,"name":"1. Wenatchee"},{"status":"ACTIVE","sortPriority":2,"id":36201034,"name":"2. Loco Dinero"},{"status":"ACTIVE","sortPriority":3,"id":38276037,"name":"3. Deadly Choice"},{"status":"ACTIVE","sortPriority":4,"id":40659166,"name":"4. Unique Speed"},{"status":"ACTIVE","sortPriority":5,"id":39594662,"name":"6. Scriven"},{"status":"ACTIVE","sortPriority":6,"id":39849129,"name":"7. Prosecutor"},{"status":"ACTIVE","sortPriority":7,"id":32633412,"name":"8. Off Break"}],"regulators":["MR_INT"],"venue":"Rockhampton","countryCode":"AU","discountAllowed":true,"timezone":"Australia/Queensland","openDate":"2022-03-02T08:28:00.000Z","version":4382597846,"name":"To Be Placed","eventName":"Rockhampton (AUS) 2nd Mar"},"rc":[],"con":true,"img":false}]}
{"op":"mcm","clk":"5352162840","pt":1646184014581,"mc":[{"id":"1.195453777","marketDefinition":{"bspMarket":true,"turnInPlayEnabled":false,"persistenceEnabled":false,"marketBaseRate":7.0,"eventId":"31272499","eventTypeId":"4339","numberOfWinners":2,"bettingType":"ODDS","marketType":"PLACE","marketTime":"2022-03-02T10:48:00.000Z","suspendTime":"2022-03-02T10:48:00.000Z","bspReconciled":false,"complete":true,"inPlay":false,"crossMatching":false,"runnersVoidable":false,"numberOfActiveRunners":7,"betDelay":0,"status":"OPEN","runners":[{"status":"ACTIVE","sortPriority":1,"id":38440014,"name":"1. Wenatchee"},{"status":"ACTIVE","sortPriority":2,"id":36201034,"name":"2. Loco Dinero"},{"status":"ACTIVE","sortPriority":3,"id":38276037,"name":"3. Deadly Choice"},{"status":"ACTIVE","sortPriority":4,"id":40659166,"name":"4. Unique Speed"},{"status":"ACTIVE","sortPriority":5,"id":39594662,"name":"6. Scriven"},{"status":"ACTIVE","sortPriority":6,"id":39849129,"name":"7. Prosecutor"},{"status":"ACTIVE","sortPriority":7,"id":32633412,"name":"8. Off Break"}],"regulators":["MR_INT"],"venue":"Rockhampton","countryCode":"AU","discountAllowed":true,"timezone":"Australia/Queensland","openDate":"2022-03-02T08:28:00.000Z","version":4382605933,"name":"To Be Placed","eventName":"Rockhampton (AUS) 2nd Mar"},"rc":[],"con":true,"img":false}]}
{"op":"mcm","clk":"5352237985","pt":1646185602656,"mc":[{"id":"1.195453777","marketDefinition":{"bspMarket":true,"turnInPlayEnabled":false,"persistenceEnabled":false,"marketBaseRate":7.0,"eventId":"31272499","eventTypeId":"4339","numberOfWinners":2,"bettingType":"ODDS","marketType":"PLACE","marketTime":"2022-03-02T10:48:00.000Z","suspendTime":"2022-03-02T10:48:00.000Z","bspReconciled":false,"complete":true,"inPlay":false,"crossMatching":false,"runnersVoidable":false,"numberOfActiveRunners":7,"betDelay":0,"status":"OPEN","runners":[{"status":"ACTIVE","sortPriority":1,"id":38440014,"name":"1. Wenatchee"},{"status":"ACTIVE","sortPriority":2,"id":36201034,"name":"2. Loco Dinero"},{"status":"ACTIVE","sortPriority":3,"id":38276037,"name":"3. Deadly Choice"},{"status":"ACTIVE","sortPriority":4,"id":40659166,"name":"4. Unique Speed"},{"status":"ACTIVE","sortPriority":5,"id":39594662,"name":"6. Scriven"},{"status":"ACTIVE","sortPriority":6,"id":39849129,"name":"7. Prosecutor"},{"status":"ACTIVE","sortPriority":7,"id":32633412,"name":"8. Off Break"}],"regulators":["MR_INT"],"venue":"Rockhampton","countryCode":"AU","discountAllowed":true,"timezone":"Australia/Queensland","openDate":"2022-03-02T08:28:00.000Z","version":4382605933,"name":"To Be Placed","eventName":"Rockhampton (AUS) 2nd Mar"},"rc":[{"atb":[[3.6,46.55],[3.85,21.23],[3.35,51.51]],"id":32633412},{"atl":[[17.5,0.73],[75,0.65],[40,0.62],[12.5,1.05],[25,1]],"id":32633412},{"spn":8.17,"spf":"NaN","id":32633412},{"atb":[[2.06,57.1],[1.98,123.52],[1.93,130.16]],"id":39594662},{"atl":[[16,3.22],[6.4,2.24],[11,2.42],[5.2,2.88],[8.4,3.27]],"id":39594662},{"spn":3.63,"spf":"NaN","id":39594662},{"atb":[[1.25,484.21],[1.3,403.51],[1.35,172.93]],"id":40659166},{"atl":[[2.8,6.72],[4,16.14],[3,12.1],[2.6,7.56],[3.5,9.68]],"id":40659166},{"spn":1.97,"spf":"NaN","id":40659166},{"atb":[[9.8,6.87],[8.8,15.51],[7.8,17.8]],"id":38440014},{"atl":[[70,0.17],[140,0.08],[340,0.07],[440,0.1],[240,0.1]],"id":38440014},{"spn":39.9,"spf":"NaN","id":38440014},{"atb":[[3.45,49.4],[3.95,20.51],[3.7,44.83]],"id":36201034},{"atl":[[18.5,0.69],[85,0.57],[44,0.56],[13.5,0.97],[27,0.93]],"id":36201034},{"spn":8.72,"spf":"NaN","id":36201034},{"atb":[[1.2,605.26],[1.25,242.1],[1.15,807.02]],"id":38276037},{"atl":[[3.6,18.62],[3.1,11.52],[2.44,8.4],[2.64,7.38],[2.84,13.15]],"id":38276037},{"spn":1.84,"spf":"NaN","id":38276037},{"atb":[[2.74,69.57],[2.84,65.78],[2.94,31.2]],"id":39849129},{"atl":[[8,1.72],[10,1.34],[20,1.27],[15,1.72],[30,1.66]],"id":39849129},{"spn":5.47,"spf":"NaN","id":39849129}],"con":true,"img":true}]}
{"op":"mcm","clk":"5352465282","pt":1646191002605,"mc":[{"id":"1.195453777","marketDefinition":{"bspMarket":true,"turnInPlayEnabled":false,"persistenceEnabled":false,"marketBaseRate":7.0,"eventId":"31272499","eventTypeId":"4339","numberOfWinners":2,"bettingType":"ODDS","marketType":"PLACE","marketTime":"2022-03-02T10:48:00.000Z","suspendTime":"2022-03-02T10:48:00.000Z","bspReconciled":false,"complete":true,"inPlay":false,"crossMatching":false,"runnersVoidable":false,"numberOfActiveRunners":7,"betDelay":0,"status":"OPEN","runners":[{"status":"ACTIVE","sortPriority":1,"id":38440014,"name":"1. Wenatchee"},{"status":"ACTIVE","sortPriority":2,"id":36201034,"name":"2. Loco Dinero"},{"status":"ACTIVE","sortPriority":3,"id":38276037,"name":"3. Deadly Choice"},{"status":"ACTIVE","sortPriority":4,"id":40659166,"name":"4. Unique Speed"},{"status":"ACTIVE","sortPriority":5,"id":39594662,"name":"6. Scriven"},{"status":"ACTIVE","sortPriority":6,"id":39849129,"name":"7. Prosecutor"},{"status":"ACTIVE","sortPriority":7,"id":32633412,"name":"8. Off Break"}],"regulators":["MR_INT"],"venue":"Rockhampton","countryCode":"AU","discountAllowed":true,"timezone":"Australia/Queensland","openDate":"2022-03-02T08:28:00.000Z","version":4382605933,"name":"To Be Placed","eventName":"Rockhampton (AUS) 2nd Mar"},"rc":[{"atb":[[3.6,46.63],[3.85,21.27],[3.35,51.6]],"id":32633412},{"atl":[[17.5,0.73],[75,0.65],[40,0.62],[12.5,1.05],[25,1.01]],"id":32633412},{"spn":8.17,"spf":"NaN","id":32633412},{"atb":[[2.06,57.19],[1.98,123.73],[1.93,130.38]],"id":39594662},{"atl":[[16,3.23],[6.4,2.24],[11,2.42],[5.2,2.88],[8.4,3.27]],"id":39594662},{"spn":3.63,"spf":"NaN","id":39594662},{"atb":[[1.25,485.03],[1.3,404.19],[1.35,173.22]],"id":40659166},{"atl":[[2.8,6.73],[4,16.16],[3,12.12],[2.6,7.58],[3.5,9.7]],"id":40659166},{"spn":1.97,"spf":"NaN","id":40659166},{"atb":[[9.8,6.88],[8.8,15.54],[7.8,17.83]],"id":38440014},{"atl":[[70,0.17],[140,0.08],[340,0.07],[440,0.1],[240,0.1]],"id":38440014},{"spn":39.9,"spf":"NaN","id":38440014},{"atb":[[3.45,49.49],[3.95,20.55],[3.7,44.9]],"id":36201034},{"atl":[[18.5,0.69],[85,0.57],[44,0.56],[13.5,0.97],[27,0.93]],"id":36201034},{"spn":8.72,"spf":"NaN","id":36201034},{"atb":[[1.2,606.29],[1.25,242.51],[1.15,808.38]],"id":38276037},{"atl":[[3.6,18.65],[3.1,11.54],[2.44,8.42],[2.64,7.39],[2.84,13.18]],"id":38276037},{"spn":1.84,"spf":"NaN","id":38276037},{"atb":[[2.74,69.69],[2.84,65.9],[2.94,31.25]],"id":39849129},{"atl":[[8,1.73],[10,1.34],[20,1.27],[15,1.73],[30,1.67]],"id":39849129},{"spn":5.47,"spf":"NaN","id":39849129}],"con":true,"img":true}]}
{"op":"mcm","clk":"5352822076","pt":1646201802637,"mc":[{"id":"1.195453777","marketDefinition":{"bspMarket":true,"turnInPlayEnabled":false,"persistenceEnabled":false,"marketBaseRate":7.0,"eventId":"31272499","eventTypeId":"4339","numberOfWinners":2,"bettingType":"ODDS","marketType":"PLACE","marketTime":"2022-03-02T10:48:00.000Z","suspendTime":"2022-03-02T10:48:00.000Z","bspReconciled":false,"complete":true,"inPlay":false,"crossMatching":false,"runnersVoidable":false,"numberOfActiveRunners":7,"betDelay":0,"status":"OPEN","runners":[{"status":"ACTIVE","sortPriority":1,"id":38440014,"name":"1. Wenatchee"},{"status":"ACTIVE","sortPriority":2,"id":36201034,"name":"2. Loco Dinero"},{"status":"ACTIVE","sortPriority":3,"id":38276037,"name":"3. Deadly Choice"},{"status":"ACTIVE","sortPriority":4,"id":40659166,"name":"4. Unique Speed"},{"status":"ACTIVE","sortPriority":5,"id":39594662,"name":"6. Scriven"},{"status":"ACTIVE","sortPriority":6,"id":39849129,"name":"7. Prosecutor"},{"status":"ACTIVE","sortPriority":7,"id":32633412,"name":"8. Off Break"}],"regulators":["MR_INT"],"venue":"Rockhampton","countryCode":"AU","discountAllowed":true,"timezone":"Australia/Queensland","openDate":"2022-03-02T08:28:00.000Z","version":4382605933,"name":"To Be Placed","eventName":"Rockhampton (AUS) 2nd Mar"},"rc":[{"atb":[[3.6,46.61],[3.85,21.26],[3.35,51.58]],"id":32633412},{"atl":[[17.5,0.73],[75,0.65],[40,0.62],[12.5,1.05],[25,1.01]],"id":32633412},{"spn":8.17,"spf":"NaN","id":32633412},{"atb":[[2.06,57.17],[1.98,123.68],[1.93,130.33]],"id":39594662},{"atl":[[16,3.23],[6.4,2.24],[11,2.42],[5.2,2.88],[8.4,3.27]],"id":39594662},{"spn":3.63,"spf":"NaN","id":39594662},{"atb":[[1.25,484.84],[1.3,404.04],[1.35,173.15]],"id":40659166},{"atl":[[2.8,6.73],[4,16.16],[3,12.12],[2.6,7.57],[3.5,9.69]],"id":40659166},{"spn":1.97,"spf":"NaN","id":40659166},{"atb":[[9.8,6.88],[8.8,15.53],[7.8,17.82]],"id":38440014},{"atl":[[70,0.17],[140,0.08],[340,0.07],[440,0.1],[240,0.1]],"id":38440014},{"spn":39.9,"spf":"NaN","id":38440014},{"atb":[[3.45,49.47],[3.95,20.54],[3.7,44.89]],"id":36201034},{"atl":[[18.5,0.69],[85,0.57],[44,0.56],[13.5,0.97],[27,0.93]],"id":36201034},{"spn":8.72,"spf":"NaN","id":36201034},{"atb":[[1.2,606.06],[1.25,242.42],[1.15,808.08]],"id":38276037},{"atl":[[3.6,18.64],[3.1,11.54],[2.44,8.41],[2.64,7.39],[2.84,13.17]],"id":38276037},{"spn":1.84,"spf":"NaN","id":38276037},{"atb":[[2.74,69.66],[2.84,65.87],[2.94,31.24]],"id":39849129},{"atl":[[8,1.73],[10,1.34],[20,1.27],[15,1.73],[30,1.67]],"id":39849129},{"spn":5.47,"spf":"NaN","id":39849129}],"con":true,"img":true}]}
{"op":"mcm","clk":"5352844506","pt":1646202475791,"mc":[{"id":"1.195453777","rc":[{"atb":[[3.6,0],[3.85,0],[3.35,0]],"id":32633412},{"atl":[[17.5,0],[75,0],[40,0],[12.5,0],[25,0]],"id":32633412},{"atb":[[2.06,57.17],[1.98,123.68],[1.93,130.33]],"id":39594662},{"atl":[[16,3.23],[6.4,2.24],[11,2.42],[5.2,2.88],[8.4,3.27]],"id":39594662},{"atb":[[1.25,484.84],[1.3,404.04],[1.35,173.15]],"id":40659166},{"atl":[[2.8,6.73],[4,16.16],[3,12.12],[2.6,7.57],[3.5,9.69]],"id":40659166},{"spn":1.97,"spf":"NaN","id":40659166},{"atb":[[9.8,6.88],[8.8,15.53],[7.8,17.82]],"id":38440014},{"atl":[[70,0.17],[140,0.08],[340,0.07],[440,0.1],[240,0.1]],"id":38440014},{"spn":39.9,"spf":"NaN","id":38440014},{"atb":[[3.45,0],[3.95,0],[3.7,0]],"id":36201034},{"atl":[[18.5,0],[85,0],[44,0],[13.5,0],[27,0]],"id":36201034},{"atb":[[1.2,606.06],[1.25,242.42],[1.15,808.08]],"id":38276037},{"atl":[[3.6,18.64],[3.1,11.54],[2.44,8.41],[2.64,7.39],[2.84,13.17]],"id":38276037},{"spn":1.84,"spf":"NaN","id":38276037},{"atb":[[2.74,69.66],[2.84,65.87],[2.94,31.24]],"id":39849129},{"atl":[[8,1.73],[10,1.34],[20,1.27],[15,1.73],[30,1.67]],"id":39849129}],"con":true,"img":false}]}
{"op":"mcm","clk":"5352845214","pt":1646202497533,"mc":[{"id":"1.195453777","rc":[{"atb":[[3.6,46.61],[3.85,21.26],[3.35,51.58]],"id":32633412},{"atl":[[17.5,0.73],[75,0.65],[40,0.62],[12.5,1.05],[25,1.01]],"id":32633412},{"atb":[[2.74,69.66],[2.84,65.87],[2.94,31.24]],"id":36201034},{"atl":[[8,1.73],[10,1.34],[20,1.27],[15,1.73],[30,1.67]],"id":36201034}],"con":true,"img":false}]}
{"op":"mcm","clk":"5353027451","pt":1646207202672,"mc":[{"id":"1.195453777","marketDefinition":{"bspMarket":true,"turnInPlayEnabled":false,"persistenceEnabled":false,"marketBaseRate":7.0,"eventId":"31272499","eventTypeId":"4339","numberOfWinners":2,"bettingType":"ODDS","marketType":"PLACE","marketTime":"2022-03-02T10:48:00.000Z","suspendTime":"2022-03-02T10:48:00.000Z","bspReconciled":false,"complete":true,"inPlay":false,"crossMatching":false,"runnersVoidable":false,"numberOfActiveRunners":7,"betDelay":0,"status":"OPEN","runners":[{"status":"ACTIVE","sortPriority":1,"id":38440014,"name":"1. Wenatchee"},{"status":"ACTIVE","sortPriority":2,"id":36201034,"name":"2. Loco Dinero"},{"status":"ACTIVE","sortPriority":3,"id":38276037,"name":"3. Deadly Choice"},{"status":"ACTIVE","sortPriority":4,"id":40659166,"name":"4. Unique Speed"},{"status":"ACTIVE","sortPriority":5,"id":39594662,"name":"6. Scriven"},{"status":"ACTIVE","sortPriority":6,"id":39849129,"name":"7. Prosecutor"},{"status":"ACTIVE","sortPriority":7,"id":32633412,"name":"8. Off Break"}],"regulators":["MR_INT"],"venue":"Rockhampton","countryCode":"AU","discountAllowed":true,"timezone":"Australia/Queensland","openDate":"2022-03-02T08:28:00.000Z","version":4382605933,"name":"To Be Placed","eventName":"Rockhampton (AUS) 2nd Mar"},"rc":[{"atb":[[3.6,46.6],[3.85,21.26],[3.35,51.56]],"id":32633412},{"atl":[[17.5,0.73],[75,0.65],[40,0.62],[12.5,1.05],[25,1]],"id":32633412},{"spn":8.17,"spf":"NaN","id":32633412},{"atb":[[2.06,57.16],[1.98,123.65],[1.93,130.3]],"id":39594662},{"atl":[[16,3.23],[6.4,2.24],[11,2.42],[5.2,2.88],[8.4,3.27]],"id":39594662},{"spn":3.63,"spf":"NaN","id":39594662},{"atb":[[1.25,484.71],[1.3,403.93],[1.35,173.11]],"id":40659166},{"atl":[[2.8,6.73],[4,16.15],[3,12.11],[2.6,7.57],[3.5,9.69]],"id":40659166},{"spn":1.97,"spf":"NaN","id":40659166},{"atb":[[9.8,6.88],[8.8,15.53],[7.8,17.82]],"id":38440014},{"atl":[[70,0.17],[140,0.08],[340,0.07],[440,0.1],[240,0.1]],"id":38440014},{"spn":39.9,"spf":"NaN","id":38440014},{"atb":[[2.74,69.64],[2.84,65.85],[2.94,31.23]],"id":36201034},{"atl":[[8,1.73],[10,1.34],[20,1.27],[15,1.73],[30,1.67]],"id":36201034},{"spn":5.47,"spf":"NaN","id":36201034},{"atb":[[1.2,605.89],[1.25,242.35],[1.15,807.86]],"id":38276037},{"atl":[[3.6,18.64],[3.1,11.53],[2.44,8.41],[2.64,7.39],[2.84,13.17]],"id":38276037},{"spn":1.84,"spf":"NaN","id":38276037},{"atb":[[2.74,69.64],[2.84,65.85],[2.94,31.23]],"id":39849129},{"atl":[[8,1.73],[10,1.34],[20,1.27],[15,1.73],[30,1.67]],"id":39849129},{"spn":5.47,"spf":"NaN","id":39849129}],"con":true,"img":true}]}
{"op":"mcm","clk":"5353298804","pt":1646212602692,"mc":[{"id":"1.195453777","marketDefinition":{"bspMarket":true,"turnInPlayEnabled":false,"persistenceEnabled":false,"marketBaseRate":7.0,"eventId":"31272499","eventTypeId":"4339","numberOfWinners":2,"bettingType":"ODDS","marketType":"PLACE","marketTime":"2022-03-02T10:48:00.000Z","suspendTime":"2022-03-02T10:48:00.000Z","bspReconciled":false,"complete":true,"inPlay":false,"crossMatching":false,"runnersVoidable":false,"numberOfActiveRunners":7,"betDelay":0,"status":"OPEN","runners":[{"status":"ACTIVE","sortPriority":1,"id":38440014,"name":"1. Wenatchee"},{"status":"ACTIVE","sortPriority":2,"id":36201034,"name":"2. Loco Dinero"},{"status":"ACTIVE","sortPriority":3,"id":38276037,"name":"3. Deadly Choice"},{"status":"ACTIVE","sortPriority":4,"id":40659166,"name":"4. Unique Speed"},{"status":"ACTIVE","sortPriority":5,"id":39594662,"name":"6. Scriven"},{"status":"ACTIVE","sortPriority":6,"id":39849129,"name":"7. Prosecutor"},{"status":"ACTIVE","sortPriority":7,"id":32633412,"name":"8. Off Break"}],"regulators":["MR_INT"],"venue":"Rockhampton","countryCode":"AU","discountAllowed":true,"timezone":"Australia/Queensland","openDate":"2022-03-02T08:28:00.000Z","version":4382605933,"name":"To Be Placed","eventName":"Rockhampton (AUS) 2nd Mar"},"rc":[{"atb":[[3.6,46.53],[3.85,21.22],[3.35,51.48]],"id":32633412},{"atl":[[17.5,0.73],[75,0.65],[40,0.62],[12.5,1.05],[25,1]],"id":32633412},{"spn":8.17,"spf":"NaN","id":32633412},{"atb":[[2.06,57.07],[1.98,123.45],[1.93,130.09]],"id":39594662},{"atl":[[16,3.22],[6.4,2.23],[11,2.41],[5.2,2.88],[8.4,3.26]],"id":39594662},{"spn":3.63,"spf":"NaN","id":39594662},{"atb":[[1.25,483.95],[1.3,403.29],[1.35,172.83]],"id":40659166},{"atl":[[2.8,6.71],[4,16.13],[3,12.09],[2.6,7.56],[3.5,9.67]],"id":40659166},{"spn":1.97,"spf":"NaN","id":40659166},{"atb":[[9.8,6.87],[8.8,15.51],[7.8,17.79]],"id":38440014},{"atl":[[70,0.17],[140,0.08],[340,0.07],[440,0.1],[240,0.1]],"id":38440014},{"spn":39.9,"spf":"NaN","id":38440014},{"atb":[[2.74,69.53],[2.84,65.75],[2.94,31.18]],"id":36201034},{"atl":[[8,1.72],[10,1.34],[20,1.27],[15,1.72],[30,1.66]],"id":36201034},{"spn":5.47,"spf":"NaN","id":36201034},{"atb":[[1.2,604.93],[1.25,241.97],[1.15,806.58]],"id":38276037},{"atl":[[3.6,18.61],[3.1,11.52],[2.44,8.4],[2.64,7.37],[2.84,13.15]],"id":38276037},{"spn":1.84,"spf":"NaN","id":38276037},{"atb":[[2.74,69.53],[2.84,65.75],[2.94,31.18]],"id":39849129},{"atl":[[8,1.72],[10,1.34],[20,1.27],[15,1.72],[30,1.66]],"id":39849129},{"spn":5.47,"spf":"NaN","id":39849129}],"con":true,"img":true}]}
{"op":"mcm","clk":"5353310289","pt":1646212762723,"mc":[{"id":"1.195453777","rc":[{"atb":[[3.6,46.53],[3.85,21.22],[3.35,51.48],[3.4,23.44],[3.75,15.85]],"id":32633412},{"atl":[[17.5,0.73],[75,0.65],[18.5,2.72],[40,0.62],[20,2.95],[12.5,1.05],[25,1]],"id":32633412},{"spn":8.17,"spf":"NaN","id":32633412},{"atb":[[1.99,44.04],[2.06,57.07],[1.98,123.45],[1.67,94.82],[1.93,130.09]],"id":39594662},{"atl":[[16,3.22],[6.4,2.23],[11,2.41],[5.2,2.88],[6.6,11.44],[8.4,3.26],[5.9,8.89]],"id":39594662},{"atb":[[1.25,483.95],[1.45,96.88],[1.37,176.57],[1.3,403.29],[1.35,172.83]],"id":40659166},{"atl":[[2.8,6.71],[4,16.13],[3.95,21.25],[3,12.09],[2.6,7.56],[3.5,9.67],[3.65,16.45]],"id":40659166},{"spn":2.02,"spf":"NaN","id":40659166},{"atb":[[17.5,3.75],[21,2.72],[9.8,6.87],[8.8,15.51],[7.8,17.79]],"id":38440014},{"atl":[[270,2.72],[70,0.17],[140,0.08],[340,0.07],[440,0.1],[240,0.28]],"id":38440014},{"spn":45.5,"spf":"NaN","id":38440014},{"atb":[[2.74,69.53],[2.86,23.43],[2.84,65.75],[2.94,31.18],[2.76,36.51]],"id":36201034},{"atl":[[8,1.72],[10,1.34],[20,1.27],[11.5,4.15],[12.5,5.44],[15,1.72],[30,1.66]],"id":36201034},{"spn":5.47,"spf":"NaN","id":36201034},{"atb":[[1.2,604.93],[1.27,228.99],[1.25,241.97],[1.15,806.58],[1.32,108.81]],"id":38276037},{"atl":[[3.6,18.61],[2.88,23.18],[3.1,11.52],[2.44,8.4],[2.64,7.37],[2.84,13.15],[3.05,29.04]],"id":38276037},{"spn":1.88,"spf":"NaN","id":38276037},{"atb":[[2.74,69.53],[3.35,18.55],[2.84,65.75],[2.94,61.21]],"id":39849129},{"atl":[[8,1.72],[17,3.49],[10,1.34],[20,1.27],[15,4.83],[30,1.66]],"id":39849129},{"spn":5.67,"spf":"NaN","id":39849129}],"con":true,"img":false}]}
{"op":"mcm","clk":"5353314642","pt":1646212843104,"mc":[{"id":"1.195453777","rc":[{"atb":[[3.4,0],[3.75,0]],"id":32633412},{"atb":[[1.99,0]],"id":39594662},{"atb":[[2.86,0]],"id":36201034},{"atl":[[3.05,0]],"id":38276037},{"atb":[[2.94,31.18]],"id":39849129}],"con":true,"img":false}]}
{"op":"mcm","clk":"5353314646","pt":1646212843206,"mc":[{"id":"1.195453777","rc":[{"atb":[[3.9,15.85],[3.65,23.44]],"id":32633412},{"atb":[[2.08,44.04]],"id":39594662},{"atb":[[2.96,23.43]],"id":36201034},{"atl":[[2.82,29.04]],"id":38276037},{"atb":[[2.96,30.03]],"id":39849129}],"con":true,"img":false}]}
{"op":"mcm","clk":"5353340371","pt":1646213282335,"mc":[{"id":"1.195453777","rc":[{"spn":8.2,"spf":"NaN","id":32633412},{"spn":3.64,"spf":"NaN","id":39594662},{"spn":5.48,"spf":"NaN","id":36201034},{"atl":[[2.82,0],[3.35,23.34]],"id":38276037}],"con":true,"img":false}]}
{"op":"mcm","clk":"5353341804","pt":1646213310565,"mc":[{"id":"1.195453777","rc":[{"atb":[[2.08,0]],"id":39594662}],"con":true,"img":false}]}
{"op":"mcm","clk":"5353341810","pt":1646213310668,"mc":[{"id":"1.195453777","rc":[{"atb":[[1.79,44.04]],"id":39594662}],"con":true,"img":false}]}
{"op":"mcm","clk":"5353414903","pt":1646214510172,"mc":[{"id":"1.195453777","rc":[{"atb":[[3.05,46.9]],"id":32633412},{"atl":[[14.5,2.72]],"id":32633412},{"atb":[[2.08,92.59]],"id":39594662},{"atl":[[8.6,6.54]],"id":39594662},{"atb":[[1.46,172.84]],"id":40659166},{"atl":[[3.6,17.24]],"id":40659166},{"spn":2.03,"spf":"NaN","id":40659166},{"atl":[[390,2]],"id":38440014},{"atl":[[8.4,4.15]],"id":36201034},{"atb":[[1.28,241.98]],"id":38276037},{"atl":[[4.9,25.64]],"id":38276037},{"atb":[[1.53,62.36]],"id":39849129},{"atl":[[8.2,3.49]],"id":39849129}],"con":true,"img":false}]}
{"op":"mcm","clk":"5353415822","pt":1646214529297,"mc":[{"id":"1.195453777","rc":[{"atb":[[21,0]],"id":38440014}],"con":true,"img":false}]}
{"op":"mcm","clk":"5353415831","pt":1646214529400,"mc":[{"id":"1.195453777","rc":[{"atb":[[22,2.72]],"id":38440014}],"con":true,"img":false}]}
{"op":"mcm","clk":"5353416842","pt":1646214548357,"mc":[{"id":"1.195453777","rc":[{"atb":[[2.42,45.77],[2.76,0]],"id":36201034}],"con":true,"img":false}]}
{"op":"mcm","clk":"5353416847","pt":1646214548409,"mc":[{"id":"1.195453777","rc":[{"atl":[[20,0]],"id":32633412}],"con":true,"img":false}]}
{"op":"mcm","clk":"5353416852","pt":1646214548511,"mc":[{"id":"1.195453777","rc":[{"atl":[[22,2.95]],"id":32633412}],"con":true,"img":false}]}
{"op":"mcm","clk":"5353417760","pt":1646214564646,"mc":[{"id":"1.195453777","rc":[{"atb":[[1.45,0]],"id":40659166},{"atl":[[3.65,0]],"id":40659166},{"atb":[[1.27,0]],"id":38276037},{"atl":[[2.88,0]],"id":38276037}],"con":true,"img":false}]}
{"op":"mcm","clk":"5353417769","pt":1646214564750,"mc":[{"id":"1.195453777","rc":[{"atb":[[1.46,0],[1.47,96.88],[1.38,263.16]],"id":40659166},{"atl":[[3.55,16.45]],"id":40659166},{"atb":[[1.29,228.99]],"id":38276037},{"atl":[[2.82,23.18]],"id":38276037}],"con":true,"img":false}]}
{"op":"mcm","clk":"5353417802","pt":1646214565372,"mc":[{"id":"1.195453777","rc":[{"atb":[[3.9,0]],"id":32633412}],"con":true,"img":false}]}
{"op":"mcm","clk":"5353417807","pt":1646214565475,"mc":[{"id":"1.195453777","rc":[{"atb":[[3.75,15.85]],"id":32633412}],"con":true,"img":false}]}
{"op":"mcm","clk":"5353418603","pt":1646214580712,"mc":[{"id":"1.195453777","rc":[{"atl":[[14.5,0],[15.5,3.77]],"id":32633412},{"spn":8.17,"spf":"NaN","id":32633412},{"spn":2.03,"spf":"NaN","id":40659166},{"spn":46.0,"spf":"NaN","id":38440014},{"atl":[[8.8,5.88],[8.4,0]],"id":36201034},{"atb":[[1.28,0],[1.26,384.62]],"id":38276037},{"atl":[[8.6,5.22],[8.2,0]],"id":39849129}],"con":true,"img":false}]}
{"op":"mcm","clk":"5353419151","pt":1646214590403,"mc":[{"id":"1.195453777","rc":[{"atb":[[22,0]],"id":38440014}],"con":true,"img":false}]}
{"op":"mcm","clk":"5353419155","pt":1646214590506,"mc":[{"id":"1.195453777","rc":[{"atb":[[25,2.72]],"id":38440014}],"con":true,"img":false}]}
{"op":"mcm","clk":"5353419678","pt":1646214601141,"mc":[{"id":"1.195453777","rc":[{"atb":[[1.47,273.46],[1.38,0]],"id":40659166}],"con":true,"img":false}]}
{"op":"mcm","clk":"5353419683","pt":1646214601195,"mc":[{"id":"1.195453777","rc":[{"atb":[[1.38,193.78]],"id":40659166}],"con":true,"img":false}]}
{"op":"mcm","clk":"5353419687","pt":1646214601297,"mc":[{"id":"1.195453777","rc":[{"atb":[[1.47,96.88]],"id":40659166}],"con":true,"img":false}]}
{"op":"mcm","clk":"5353420194","pt":1646214611642,"mc":[{"id":"1.195453777","rc":[{"atb":[[17.5,0]],"id":38440014}],"con":true,"img":false}]}
{"op":"mcm","clk":"5353420198","pt":1646214611745,"mc":[{"id":"1.195453777","rc":[{"atb":[[20,3.75]],"id":38440014}],"con":true,"img":false}]}
{"op":"mcm","clk":"5353421227","pt":1646214632383,"mc":[{"id":"1.195453777","rc":[{"atl":[[18.5,0]],"id":32633412},{"atb":[[1.37,0]],"id":40659166},{"atl":[[11.5,0]],"id":36201034}],"con":true,"img":false}]}
{"op":"mcm","clk":"5353421237","pt":1646214632486,"mc":[{"id":"1.195453777","rc":[{"atl":[[15,2.72]],"id":32633412},{"atb":[[1.39,176.57]],"id":40659166},{"atl":[[8.6,4.15]],"id":36201034}],"con":true,"img":false}]}
{"op":"mcm","clk":"5353421477","pt":1646214637176,"mc":[{"id":"1.195453777","rc":[{"atb":[[1.47,273.46]],"id":40659166}],"con":true,"img":false}]}
{"op":"mcm","clk":"5353421482","pt":1646214637280,"mc":[{"id":"1.195453777","rc":[{"atb":[[1.38,0]],"id":40659166}],"con":true,"img":false}]}
{"op":"mcm","clk":"5353424036","pt":1646214694399,"mc":[{"id":"1.195453777","rc":[{"atl":[[3.55,0]],"id":40659166},{"spn":47.5,"spf":"NaN","id":38440014},{"atl":[[15,1.72]],"id":39849129}],"con":true,"img":false}]}
{"op":"mcm","clk":"5353424042","pt":1646214694500,"mc":[{"id":"1.195453777","rc":[{"atl":[[2.98,16.45]],"id":40659166},{"atl":[[14,3.11]],"id":39849129}],"con":true,"img":false}]}
{"op":"mcm","clk":"5353425090","pt":1646214714711,"mc":[{"id":"1.195453777","rc":[{"atl":[[3.35,0],[3.05,29.04]],"id":38276037}],"con":true,"img":false}]}
{"op":"mcm","clk":"5353452868","pt":1646215210151,"mc":[{"id":"1.195453777","rc":[{"atl":[[8,5.87],[8.8,0]],"id":36201034},{"atb":[[1.26,0],[1.29,470.97]],"id":38276037},{"atl":[[8.6,0],[9,6.95]],"id":39849129}],"con":true,"img":false}]}
{"op":"mcm","clk":"5353453317","pt":1646215215324,"mc":[{"id":"1.195453777","rc":[{"atl":[[9,0],[9.2,8.68]],"id":39849129}],"con":true,"img":false}]}
{"op":"mcm","clk":"5353453739","pt":1646215220663,"mc":[{"id":"1.195453777","rc":[{"atl":[[8.6,0]],"id":36201034}],"con":true,"img":false}]}
{"op":"mcm","clk":"5353453749","pt":1646215220732,"mc":[{"id":"1.195453777","rc":[{"atl":[[12,4.15]],"id":36201034}],"con":true,"img":false}]}
{"op":"mcm","clk":"5353454612","pt":1646215233061,"mc":[{"id":"1.195453777","rc":[{"atl":[[15,5.44],[15.5,0]],"id":32633412},{"atl":[[8,1.72],[8.4,11.76]],"id":36201034},{"atb":[[1.28,357.14],[1.29,228.99]],"id":38276037}],"con":true,"img":false}]}
{"op":"mcm","clk":"5353454629","pt":1646215233266,"mc":[{"id":"1.195453777","rc":[{"atl":[[14.5,2.96],[15,2.72]],"id":32633412},{"atl":[[9.8,11.36],[8.4,0]],"id":36201034}],"con":true,"img":false}]}
{"op":"mcm","clk":"5353455206","pt":1646215239959,"mc":[{"id":"1.195453777","rc":[{"atl":[[8.2,3.46]],"id":39849129}],"con":true,"img":false}]}
{"op":"mcm","clk":"5353455210","pt":1646215240064,"mc":[{"id":"1.195453777","rc":[{"atl":[[9.2,0]],"id":39849129}],"con":true,"img":false}]}
{"op":"mcm","clk":"5353455392","pt":1646215242672,"mc":[{"id":"1.195453777","rc":[{"atl":[[14,0]],"id":39849129}],"con":true,"img":false}]}
{"op":"mcm","clk":"5353455401","pt":1646215242781,"mc":[{"id":"1.195453777","rc":[{"atl":[[16,3.11]],"id":39849129}],"con":true,"img":false}]}
{"op":"mcm","clk":"5353456528","pt":1646215259684,"mc":[{"id":"1.195453777","rc":[{"atl":[[12.5,0]],"id":36201034}],"con":true,"img":false}]}
{"op":"mcm","clk":"5353456536","pt":1646215259790,"mc":[{"id":"1.195453777","rc":[{"atl":[[13.5,5.44]],"id":36201034}],"con":true,"img":false}]}
{"op":"mcm","clk":"5353456753","pt":1646215262909,"mc":[{"id":"1.195453777","rc":[{"atl":[[9.8,0],[8.4,4.15]],"id":36201034}],"con":true,"img":false}]}
{"op":"mcm","clk":"5353458401","pt":1646215283926,"mc":[{"id":"1.195453777","rc":[{"atl":[[15,0]],"id":32633412}],"con":true,"img":false}]}
{"op":"mcm","clk":"5353458408","pt":1646215284025,"mc":[{"id":"1.195453777","rc":[{"atl":[[14,2.72]],"id":32633412}],"con":true,"img":false}]}
{"op":"mcm","clk":"5353459545","pt":1646215300257,"mc":[{"id":"1.195453777","rc":[{"atb":[[2.42,0],[2.76,36.51]],"id":36201034}],"con":true,"img":false}]}
{"op":"mcm","clk":"5353463229","pt":1646215351869,"mc":[{"id":"1.195453777","rc":[{"atb":[[3.75,0]],"id":32633412}],"con":true,"img":false}]}
{"op":"mcm","clk":"5353463236","pt":1646215351973,"mc":[{"id":"1.195453777","rc":[{"atb":[[3.9,15.85]],"id":32633412}],"con":true,"img":false}]}
{"op":"mcm","clk":"5353463304","pt":1646215353114,"mc":[{"id":"1.195453777","rc":[{"atl":[[15.5,5.44]],"id":32633412},{"atl":[[8.4,0]],"id":36201034},{"atb":[[1.28,0]],"id":38276037}],"con":true,"img":false}]}
{"op":"mcm","clk":"5353463311","pt":1646215353212,"mc":[{"id":"1.195453777","rc":[{"atl":[[14.5,0]],"id":32633412},{"atl":[[8.8,5.88]],"id":36201034},{"atb":[[1.26,384.62]],"id":38276037},{"atl":[[8.6,5.19],[8.2,0]],"id":39849129}],"con":true,"img":false}]}
{"op":"mcm","clk":"5353464251","pt":1646215367006,"mc":[{"id":"1.195453777","rc":[{"atb":[[3.9,0]],"id":32633412}],"con":true,"img":false}]}
{"op":"mcm","clk":"5353464261","pt":1646215367111,"mc":[{"id":"1.195453777","rc":[{"atb":[[3.75,15.85]],"id":32633412}],"con":true,"img":false}]}
{"op":"mcm","clk":"5353465987","pt":1646215391614,"mc":[{"id":"1.195453777","rc":[{"atb":[[3.9,1.66]],"id":32633412},{"atb":[[2.1,1.66]],"id":39594662},{"atb":[[2.98,1.66]],"id":36201034},{"atb":[[3.4,1.66]],"id":39849129}],"con":true,"img":false}]}
{"op":"mcm","clk":"5353467013","pt":1646215403653,"mc":[{"id":"1.195453777","rc":[{"atb":[[3.75,0]],"id":32633412},{"atl":[[14,0]],"id":32633412},{"atl":[[12,0]],"id":36201034},{"atl":[[16,0]],"id":39849129}],"con":true,"img":false}]}
{"op":"mcm","clk":"5353467024","pt":1646215403754,"mc":[{"id":"1.195453777","rc":[{"atb":[[3.9,17.52]],"id":32633412},{"atl":[[15,2.72]],"id":32633412},{"atl":[[8.6,4.15]],"id":36201034},{"atl":[[14,3.11]],"id":39849129}],"con":true,"img":false}]}
{"op":"mcm","clk":"5353467671","pt":1646215411795,"mc":[{"id":"1.195453777","marketDefinition":{"bspMarket":true,"turnInPlayEnabled":false,"persistenceEnabled":false,"marketBaseRate":7.0,"eventId":"31272499","eventTypeId":"4339","numberOfWinners":2,"bettingType":"ODDS","marketType":"PLACE","marketTime":"2022-03-02T10:48:00.000Z","suspendTime":"2022-03-02T10:48:00.000Z","bspReconciled":false,"complete":true,"inPlay":false,"crossMatching":true,"runnersVoidable":false,"numberOfActiveRunners":7,"betDelay":0,"status":"OPEN","runners":[{"status":"ACTIVE","sortPriority":1,"id":38440014,"name":"1. Wenatchee"},{"status":"ACTIVE","sortPriority":2,"id":36201034,"name":"2. Loco Dinero"},{"status":"ACTIVE","sortPriority":3,"id":38276037,"name":"3. Deadly Choice"},{"status":"ACTIVE","sortPriority":4,"id":40659166,"name":"4. Unique Speed"},{"status":"ACTIVE","sortPriority":5,"id":39594662,"name":"6. Scriven"},{"status":"ACTIVE","sortPriority":6,"id":39849129,"name":"7. Prosecutor"},{"status":"ACTIVE","sortPriority":7,"id":32633412,"name":"8. Off Break"}],"regulators":["MR_INT"],"venue":"Rockhampton","countryCode":"AU","discountAllowed":true,"timezone":"Australia/Queensland","openDate":"2022-03-02T08:28:00.000Z","version":4382605933,"name":"To Be Placed","eventName":"Rockhampton (AUS) 2nd Mar"},"rc":[],"con":true,"img":false}]}
{"op":"mcm","clk":"5353485361","pt":1646215618879,"mc":[{"id":"1.195453777","rc":[{"spn":8.2,"spf":"NaN","id":32633412},{"spn":3.65,"spf":"NaN","id":39594662},{"atb":[[3,4.16]],"id":36201034},{"spn":5.5,"spf":"NaN","id":36201034},{"spn":5.7,"spf":"NaN","id":39849129}],"con":true,"img":false}]}
{"op":"mcm","clk":"5353485371","pt":1646215618983,"mc":[{"id":"1.195453777","rc":[{"atb":[[1.35,23.81]],"id":38276037}],"con":true,"img":false}]}
{"op":"mcm","clk":"5353485403","pt":1646215619292,"mc":[{"id":"1.195453777","rc":[{"atb":[[2.12,7.44]],"id":39594662}],"con":true,"img":false}]}
{"op":"mcm","clk":"5353485417","pt":1646215619499,"mc":[{"id":"1.195453777","rc":[{"atb":[[2.14,7.44],[2.08,0]],"id":39594662}],"con":true,"img":false}]}
{"op":"mcm","clk":"5353485430","pt":1646215619608,"mc":[{"id":"1.195453777","rc":[{"atb":[[3.05,4.06]],"id":39849129}],"con":true,"img":false}]}
{"op":"mcm","clk":"5353485483","pt":1646215620181,"mc":[{"id":"1.195453777","rc":[{"atb":[[1.5,16.67]],"id":40659166}],"con":true,"img":false}]}
{"op":"mcm","clk":"5353485666","pt":1646215622368,"mc":[{"id":"1.195453777","rc":[{"atb":[[2.1,0]],"id":39594662},{"atb":[[2.98,0]],"id":36201034}],"con":true,"img":false}]}
{"op":"mcm","clk":"5353485680","pt":1646215622574,"mc":[{"id":"1.195453777","rc":[{"atb":[[2.16,1.66]],"id":39594662},{"atb":[[3.05,1.66]],"id":36201034}],"con":true,"img":false}]}
{"op":"mcm","clk":"5353488184","pt":1646215650525,"mc":[{"id":"1.195453777","rc":[{"atb":[[2.12,0]],"id":39594662}],"con":true,"img":false}]}
{"op":"mcm","clk":"5353489326","pt":1646215662235,"mc":[{"id":"1.195453777","rc":[{"atb":[[2.1,7.57]],"id":39594662}],"con":true,"img":false}]}
{"op":"mcm","clk":"5353489479","pt":1646215663856,"mc":[{"id":"1.195453777","rc":[{"atb":[[2.1,14.41]],"id":39594662},{"atb":[[1.5,31.7]],"id":40659166},{"atb":[[3,7.92]],"id":36201034},{"atb":[[1.35,45.29]],"id":38276037},{"atb":[[3.05,7.73]],"id":39849129}],"con":true,"img":false}]}
{"op":"mcm","clk":"5353493705","pt":1646215711477,"mc":[{"id":"1.195453777","rc":[{"spn":3.68,"spf":"NaN","id":39594662},{"spn":2.05,"spf":"NaN","id":40659166},{"spn":5.52,"spf":"NaN","id":36201034},{"atb":[[1.32,0]],"id":38276037},{"spn":1.89,"spf":"NaN","id":38276037}],"con":true,"img":false}]}
{"op":"mcm","clk":"5353493718","pt":1646215711580,"mc":[{"id":"1.195453777","rc":[{"atb":[[1.36,108.81]],"id":38276037}],"con":true,"img":false}]}
{"op":"mcm","clk":"5353493748","pt":1646215711892,"mc":[{"id":"1.195453777","rc":[{"atb":[[1.35,23.81]],"id":38276037}],"con":true,"img":false}]}
{"op":"mcm","clk":"5353494268","pt":1646215717867,"mc":[{"id":"1.195453777","rc":[{"atb":[[1.39,19.27]],"id":38276037}],"con":true,"img":false}]}
{"op":"mcm","clk":"5353495198","pt":1646215730300,"mc":[{"id":"1.195453777","rc":[{"atb":[[2.44,44.68]],"id":36201034}],"con":true,"img":false}]}
{"op":"mcm","clk":"5353495205","pt":1646215730410,"mc":[{"id":"1.195453777","rc":[{"atb":[[2.76,0]],"id":36201034},{"atb":[[1.36,0]],"id":38276037}],"con":true,"img":false}]}
{"op":"mcm","clk":"5353495211","pt":1646215730514,"mc":[{"id":"1.195453777","rc":[{"atb":[[1.33,108.81]],"id":38276037}],"con":true,"img":false}]}
{"op":"mcm","clk":"5353495220","pt":1646215730570,"mc":[{"id":"1.195453777","rc":[{"atb":[[1.35,0]],"id":38276037}],"con":true,"img":false}]}
{"op":"mcm","clk":"5353495399","pt":1646215733006,"mc":[{"id":"1.195453777","rc":[{"atb":[[1.39,0]],"id":38276037}],"con":true,"img":false}]}
{"op":"mcm","clk":"5353495927","pt":1646215739799,"mc":[{"id":"1.195453777","rc":[{"atb":[[1.36,20.88]],"id":38276037}],"con":true,"img":false}]}
{"op":"mcm","clk":"5353497422","pt":1646215757029,"mc":[{"id":"1.195453777","rc":[{"atb":[[1.36,44.04]],"id":38276037}],"con":true,"img":false}]}
{"op":"mcm","clk":"5353500737","pt":1646215797968,"mc":[{"id":"1.195453777","rc":[{"atb":[[1.33,0]],"id":38276037},{"spn":1.9,"spf":"NaN","id":38276037}],"con":true,"img":false}]}
{"op":"mcm","clk":"5353500748","pt":1646215798067,"mc":[{"id":"1.195453777","rc":[{"atb":[[1.37,108.81]],"id":38276037}],"con":true,"img":false}]}
{"op":"mcm","clk":"5353500773","pt":1646215798375,"mc":[{"id":"1.195453777","rc":[{"atb":[[1.36,23.15]],"id":38276037}],"con":true,"img":false}]}
{"op":"mcm","clk":"5353501492","pt":1646215807363,"mc":[{"id":"1.195453777","rc":[{"atb":[[1.4,18.79]],"id":38276037}],"con":true,"img":false}]}
{"op":"mcm","clk":"5353501980","pt":1646215814101,"mc":[{"id":"1.195453777","rc":[{"atb":[[1.36,0]],"id":38276037}],"con":true,"img":false}]}
{"op":"mcm","clk":"5353502249","pt":1646215817673,"mc":[{"id":"1.195453777","rc":[{"atb":[[1.37,0]],"id":38276037}],"con":true,"img":false}]}
{"op":"mcm","clk":"5353502262","pt":1646215817776,"mc":[{"id":"1.195453777","rc":[{"atb":[[1.33,108.81]],"id":38276037}],"con":true,"img":false}]}
{"op":"mcm","clk":"5353502376","pt":1646215819407,"mc":[{"id":"1.195453777","rc":[{"atb":[[1.4,0]],"id":38276037}],"con":true,"img":false}]}
{"op":"mcm","clk":"5353502818","pt":1646215825385,"mc":[{"id":"1.195453777","rc":[{"atb":[[1.36,20.88]],"id":38276037}],"con":true,"img":false}]}
{"op":"mcm","clk":"5353504481","pt":1646215845915,"mc":[{"id":"1.195453777","rc":[{"atb":[[1.36,44.04]],"id":38276037}],"con":true,"img":false}]}
{"op":"mcm","clk":"5353508671","pt":1646215893750,"mc":[{"id":"1.195453777","rc":[{"atb":[[1.33,0]],"id":38276037}],"con":true,"img":false}]}
{"op":"mcm","clk":"5353508683","pt":1646215893856,"mc":[{"id":"1.195453777","rc":[{"atb":[[1.37,108.81]],"id":38276037}],"con":true,"img":false}]}
{"op":"mcm","clk":"5353508815","pt":1646215895580,"mc":[{"id":"1.195453777","rc":[{"atb":[[1.36,23.15]],"id":38276037}],"con":true,"img":false}]}
{"op":"mcm","clk":"5353509546","pt":1646215903495,"mc":[{"id":"1.195453777","rc":[{"atb":[[1.4,18.79]],"id":38276037}],"con":true,"img":false}]}
{"op":"mcm","clk":"5353510112","pt":1646215909697,"mc":[{"id":"1.195453777","rc":[{"atb":[[1.37,0]],"id":38276037}],"con":true,"img":false}]}
{"op":"mcm","clk":"5353510120","pt":1646215909802,"mc":[{"id":"1.195453777","rc":[{"atb":[[1.33,108.81]],"id":38276037}],"con":true,"img":false}]}
{"op":"mcm","clk":"5353510346","pt":1646215912653,"mc":[{"id":"1.195453777","rc":[{"atb":[[1.4,0]],"id":38276037}],"con":true,"img":false}]}
{"op":"mcm","clk":"5353510891","pt":1646215918624,"mc":[{"id":"1.195453777","rc":[{"atb":[[1.36,44.04]],"id":38276037}],"con":true,"img":false}]}
{"op":"mcm","clk":"5353514573","pt":1646215955973,"mc":[{"id":"1.195453777","rc":[{"atb":[[1.33,0]],"id":38276037}],"con":true,"img":false}]}
{"op":"mcm","clk":"5353514588","pt":1646215956078,"mc":[{"id":"1.195453777","rc":[{"atb":[[1.37,108.81]],"id":38276037}],"con":true,"img":false}]}
{"op":"mcm","clk":"5353514739","pt":1646215957787,"mc":[{"id":"1.195453777","rc":[{"atb":[[1.36,23.15]],"id":38276037}],"con":true,"img":false}]}
{"op":"mcm","clk":"5353514889","pt":1646215959354,"mc":[{"id":"1.195453777","rc":[{"atb":[[1.36,0]],"id":38276037}],"con":true,"img":false}]}
{"op":"mcm","clk":"5353515344","pt":1646215963773,"mc":[{"id":"1.195453777","rc":[{"atb":[[1.4,18.79]],"id":38276037}],"con":true,"img":false}]}
{"op":"mcm","clk":"5353516127","pt":1646215971168,"mc":[{"id":"1.195453777","rc":[{"atb":[[1.37,0]],"id":38276037}],"con":true,"img":false}]}
{"op":"mcm","clk":"5353516139","pt":1646215971269,"mc":[{"id":"1.195453777","rc":[{"atb":[[1.33,108.81]],"id":38276037}],"con":true,"img":false}]}
{"op":"mcm","clk":"5353516314","pt":1646215972686,"mc":[{"id":"1.195453777","rc":[{"atb":[[1.4,39.63]],"id":38276037}],"con":true,"img":false}]}
{"op":"mcm","clk":"5353516339","pt":1646215972897,"mc":[{"id":"1.195453777","rc":[{"atb":[[1.4,20.84]],"id":38276037}],"con":true,"img":false}]}
{"op":"mcm","clk":"5353517054","pt":1646215978766,"mc":[{"id":"1.195453777","rc":[{"atb":[[1.36,20.88]],"id":38276037}],"con":true,"img":false}]}
{"op":"mcm","clk":"5353518831","pt":1646215999041,"mc":[{"id":"1.195453777","rc":[{"atb":[[1.4,0]],"id":38276037}],"con":true,"img":false}]}
{"op":"mcm","clk":"5353520359","pt":1646216015054,"mc":[{"id":"1.195453777","rc":[{"atb":[[1.36,44.04]],"id":38276037}],"con":true,"img":false}]}
{"op":"mcm","clk":"5353524054","pt":1646216054589,"mc":[{"id":"1.195453777","rc":[{"atb":[[1.33,0]],"id":38276037}],"con":true,"img":false}]}
{"op":"mcm","clk":"5353524066","pt":1646216054693,"mc":[{"id":"1.195453777","rc":[{"atb":[[1.37,108.81]],"id":38276037}],"con":true,"img":false}]}
{"op":"mcm","clk":"5353526412","pt":1646216071426,"mc":[{"id":"1.195453777","rc":[{"atb":[[1.36,23.15]],"id":38276037}],"con":true,"img":false}]}
{"op":"mcm","clk":"5353527424","pt":1646216078056,"mc":[{"id":"1.195453777","rc":[{"atb":[[1.4,18.79]],"id":38276037}],"con":true,"img":false}]}
{"op":"mcm","clk":"5353529528","pt":1646216086714,"mc":[{"id":"1.195453777","rc":[{"atb":[[1.37,0]],"id":38276037}],"con":true,"img":false}]}
{"op":"mcm","clk":"5353529558","pt":1646216086824,"mc":[{"id":"1.195453777","rc":[{"atb":[[1.33,108.81]],"id":38276037}],"con":true,"img":false}]}
{"op":"mcm","clk":"5353530394","pt":1646216090009,"mc":[{"id":"1.195453777","rc":[{"atb":[[1.4,0]],"id":38276037}],"con":true,"img":false}]}
{"op":"mcm","clk":"5353532048","pt":1646216096022,"mc":[{"id":"1.195453777","rc":[{"atb":[[1.36,44.04]],"id":38276037}],"con":true,"img":false}]}
{"op":"mcm","clk":"5353541266","pt":1646216133839,"mc":[{"id":"1.195453777","rc":[{"atb":[[1.33,0]],"id":38276037}],"con":true,"img":false}]}
{"op":"mcm","clk":"5353541284","pt":1646216133949,"mc":[{"id":"1.195453777","rc":[{"atb":[[1.37,108.81]],"id":38276037}],"con":true,"img":false}]}
{"op":"mcm","clk":"5353541458","pt":1646216135113,"mc":[{"id":"1.195453777","rc":[{"atb":[[1.36,23.15]],"id":38276037}],"con":true,"img":false}]}
{"op":"mcm","clk":"5353542255","pt":1646216141156,"mc":[{"id":"1.195453777","rc":[{"atb":[[1.4,18.79]],"id":38276037}],"con":true,"img":false}]}
{"op":"mcm","clk":"5353543190","pt":1646216148855,"mc":[{"id":"1.195453777","rc":[{"atb":[[1.37,0]],"id":38276037}],"con":true,"img":false}]}
{"op":"mcm","clk":"5353543201","pt":1646216148960,"mc":[{"id":"1.195453777","rc":[{"atb":[[1.33,108.81]],"id":38276037}],"con":true,"img":false}]}
{"op":"mcm","clk":"5353543324","pt":1646216150160,"mc":[{"id":"1.195453777","rc":[{"atb":[[1.4,0]],"id":38276037}],"con":true,"img":false}]}
{"op":"mcm","clk":"5353544057","pt":1646216156271,"mc":[{"id":"1.195453777","rc":[{"atb":[[1.36,44.04]],"id":38276037}],"con":true,"img":false}]}
{"op":"mcm","clk":"5353550648","pt":1646216204687,"mc":[{"id":"1.195453777","rc":[{"atb":[[1.33,0]],"id":38276037}],"con":true,"img":false}]}
{"op":"mcm","clk":"5353550655","pt":1646216204797,"mc":[{"id":"1.195453777","rc":[{"atb":[[1.37,108.81]],"id":38276037}],"con":true,"img":false}]}
{"op":"mcm","clk":"5353550960","pt":1646216207414,"mc":[{"id":"1.195453777","rc":[{"atb":[[1.36,23.15]],"id":38276037}],"con":true,"img":false}]}
{"op":"mcm","clk":"5353551232","pt":1646216209720,"mc":[{"id":"1.195453777","rc":[{"atb":[[1.36,0]],"id":38276037}],"con":true,"img":false}]}
{"op":"mcm","clk":"5353551650","pt":1646216213448,"mc":[{"id":"1.195453777","rc":[{"atb":[[1.4,18.79]],"id":38276037}],"con":true,"img":false}]}
{"op":"mcm","clk":"5353552232","pt":1646216217447,"mc":[{"id":"1.195453777","rc":[{"atb":[[1.37,0]],"id":38276037}],"con":true,"img":false}]}
{"op":"mcm","clk":"5353552248","pt":1646216217550,"mc":[{"id":"1.195453777","rc":[{"atb":[[1.33,108.81]],"id":38276037}],"con":true,"img":false}]}
{"op":"mcm","clk":"5353552468","pt":1646216219335,"mc":[{"id":"1.195453777","rc":[{"atb":[[1.4,0]],"id":38276037}],"con":true,"img":false}]}
{"op":"mcm","clk":"5353553262","pt":1646216225651,"mc":[{"id":"1.195453777","rc":[{"atb":[[1.36,20.88]],"id":38276037}],"con":true,"img":false}]}
{"op":"mcm","clk":"5353554963","pt":1646216239741,"mc":[{"id":"1.195453777","rc":[{"atb":[[1.36,44.04]],"id":38276037}],"con":true,"img":false}]}
{"op":"mcm","clk":"5353559365","pt":1646216276185,"mc":[{"id":"1.195453777","rc":[{"atb":[[1.33,0]],"id":38276037}],"con":true,"img":false}]}
{"op":"mcm","clk":"5353559375","pt":1646216276282,"mc":[{"id":"1.195453777","rc":[{"atb":[[1.37,108.81]],"id":38276037}],"con":true,"img":false}]}
{"op":"mcm","clk":"5353559733","pt":1646216279500,"mc":[{"id":"1.195453777","rc":[{"atb":[[1.36,23.15]],"id":38276037}],"con":true,"img":false}]}
{"op":"mcm","clk":"5353560319","pt":1646216284713,"mc":[{"id":"1.195453777","rc":[{"atb":[[1.37,0]],"id":38276037}],"con":true,"img":false}]}
{"op":"mcm","clk":"5353560327","pt":1646216284767,"mc":[{"id":"1.195453777","rc":[{"atb":[[1.33,108.81]],"id":38276037}],"con":true,"img":false}]}
{"op":"mcm","clk":"5353560476","pt":1646216286198,"mc":[{"id":"1.195453777","rc":[{"atb":[[4,6.67],[3.7,46.3],[3.8,26.79],[3.9,34.76]],"id":32633412},{"atl":[[9.6,14.53],[9.2,9.15],[8.8,6.41],[8.4,2.7]],"id":32633412},{"atb":[[1.92,81.52],[1.9,138.89],[1.96,20.83],[1.94,53.19]],"id":39594662},{"atl":[[4.8,13.16],[4.6,5.56],[5,18.75],[5.2,32.64]],"id":39594662},{"atb":[[1.46,250],[1.5,131.7],[1.48,156.25],[1.52,38.46]],"id":40659166},{"atl":[[2.56,80.13],[2.52,49.34],[2.44,13.89],[2.48,33.78]],"id":40659166},{"atb":[[3.2,22.73],[3.1,35.71],[3,62.5],[3.3,8.7]],"id":38440014},{"atl":[[390,3],[410,1],[430,1],[450,1]],"id":38440014},{"atb":[[1.03,250],[1.09,222.22],[1.07,250],[1.05,250]],"id":36201034},{"atl":[[6.2,14.42],[5.7,4.26],[6.6,22.32],[5.9,10.2]],"id":36201034},{"atb":[[1.37,135.14],[1.33,358.81],[1.39,51.28],[1.35,214.29]],"id":38276037},{"atl":[[5.1,12.2],[5.3,17.44],[5.5,27.78],[4.9,30.77]],"id":38276037},{"atb":[[1.59,127.12],[1.63,31.75],[1.57,219.3],[1.61,81.97]],"id":39849129},{"atl":[[8.6,21.64],[8.2,10.42],[7.4,3.12],[7.8,7.35]],"id":39849129}],"con":true,"img":false}]}
{"op":"mcm","clk":"5353560736","pt":1646216288596,"mc":[{"id":"1.195453777","rc":[{"atb":[[1.5,116.67]],"id":40659166}],"con":true,"img":false}]}
{"op":"mcm","clk":"5353560867","pt":1646216289901,"mc":[{"id":"1.195453777","rc":[{"atb":[[3.9,33.09]],"id":32633412}],"con":true,"img":false}]}
{"op":"mcm","clk":"5353560890","pt":1646216290105,"mc":[{"id":"1.195453777","rc":[{"atb":[[4.1,1.66]],"id":32633412}],"con":true,"img":false}]}
{"op":"mcm","clk":"5353561347","pt":1646216293698,"mc":[{"id":"1.195453777","rc":[{"atl":[[3.05,0]],"id":38276037}],"con":true,"img":false}]}
{"op":"mcm","clk":"5353561367","pt":1646216293898,"mc":[{"id":"1.195453777","rc":[{"atl":[[3.95,0]],"id":40659166}],"con":true,"img":false}]}
{"op":"mcm","clk":"5353561381","pt":1646216293999,"mc":[{"id":"1.195453777","rc":[{"atl":[[4.2,21.25]],"id":40659166}],"con":true,"img":false}]}
{"op":"mcm","clk":"5353561458","pt":1646216294582,"mc":[{"id":"1.195453777","rc":[{"atb":[[1.53,14.18]],"id":40659166},{"atb":[[1.4,18.79]],"id":38276037}],"con":true,"img":false}]}
{"op":"mcm","clk":"5353561986","pt":1646216299196,"mc":[{"id":"1.195453777","rc":[{"atb":[[1.36,0]],"id":38276037}],"con":true,"img":false}]}
{"op":"mcm","clk":"5353562452","pt":1646216303622,"mc":[{"id":"1.195453777","rc":[{"atb":[[3.65,0]],"id":32633412},{"atb":[[2.44,0],[2.18,55.04]],"id":36201034},{"atl":[[2.82,0]],"id":38276037},{"atb":[[3.35,0],[2.96,0]],"id":39849129}],"con":true,"img":false}]}
{"op":"mcm","clk":"5353562460","pt":1646216303727,"mc":[{"id":"1.195453777","rc":[{"atb":[[3.1,23.44]],"id":32633412},{"atl":[[3.35,23.18]],"id":38276037},{"atb":[[2.86,30.03],[2.96,18.55]],"id":39849129}],"con":true,"img":false}]}
{"op":"mcm","clk":"5353562772","pt":1646216306586,"mc":[{"id":"1.195453777","rc":[{"atb":[[3.05,4.06]],"id":39849129}],"con":true,"img":false}]}
{"op":"mcm","clk":"5353563355","pt":1646216311898,"mc":[{"id":"1.195453777","rc":[{"atb":[[3.4,0]],"id":39849129}],"con":true,"img":false}]}
{"op":"mcm","clk":"5353563383","pt":1646216312108,"mc":[{"id":"1.195453777","rc":[{"atb":[[3.1,1.66]],"id":39849129}],"con":true,"img":false}]}
{"op":"mcm","clk":"5353563447","pt":1646216312625,"mc":[{"id":"1.195453777","rc":[{"atb":[[3,3.75]],"id":39849129}],"con":true,"img":false}]}
{"op":"mcm","clk":"5353563494","pt":1646216313073,"mc":[{"id":"1.195453777","rc":[{"atb":[[2.8,55.56],[3.05,0]],"id":32633412},{"atl":[[4.6,0],[4.7,5.41]],"id":39594662},{"atb":[[1.5,272.92],[1.47,96.88]],"id":40659166},{"atl":[[2.5,13.33],[2.44,0]],"id":40659166},{"atl":[[6.8,17.24],[8.8,0]],"id":36201034},{"atb":[[1.26,0],[1.29,499.27]],"id":38276037}],"con":true,"img":false}]}
{"op":"mcm","clk":"5353563521","pt":1646216313200,"mc":[{"id":"1.195453777","rc":[{"atb":[[2.8,0],[3.15,46.51]],"id":32633412},{"atb":[[1.54,38.46],[1.5,116.67]],"id":40659166},{"atl":[[6.8,0],[6.6,40.18]],"id":36201034}],"con":true,"img":false}]}
{"op":"mcm","clk":"5353563537","pt":1646216313307,"mc":[{"id":"1.195453777","rc":[{"atl":[[2.48,0]],"id":40659166}],"con":true,"img":false}]}
{"op":"mcm","clk":"5353563579","pt":1646216313623,"mc":[{"id":"1.195453777","rc":[{"atb":[[2.8,31.26],[3.1,0]],"id":32633412},{"atb":[[1.79,0]],"id":39594662},{"atl":[[3.85,20.88]],"id":38276037}],"con":true,"img":false}]}
{"op":"mcm","clk":"5353563589","pt":1646216313718,"mc":[{"id":"1.195453777","rc":[{"atb":[[1.93,174.13]],"id":39594662}],"con":true,"img":false}]}
{"op":"mcm","clk":"5353563609","pt":1646216313836,"mc":[{"id":"1.195453777","rc":[{"atb":[[1.47,0]],"id":40659166}],"con":true,"img":false}]}
{"op":"mcm","clk":"5353563617","pt":1646216313927,"mc":[{"id":"1.195453777","rc":[{"atb":[[1.51,96.88]],"id":40659166}],"con":true,"img":false}]}
{"op":"mcm","clk":"5353563825","pt":1646216315614,"mc":[{"id":"1.195453777","rc":[{"atb":[[1.53,0]],"id":40659166}],"con":true,"img":false}]}
{"op":"mcm","clk":"5353564137","pt":1646216318327,"mc":[{"id":"1.195453777","rc":[{"atb":[[1.54,0],[1.52,135.35]],"id":40659166}],"con":true,"img":false}]}
{"op":"mcm","clk":"5353564677","pt":1646216323030,"mc":[{"id":"1.195453777","rc":[{"atl":[[4.9,12.82]],"id":39594662},{"atl":[[2.54,32.47]],"id":40659166}],"con":true,"img":false}]}
{"op":"mcm","clk":"5353564738","pt":1646216323607,"mc":[{"id":"1.195453777","rc":[{"atl":[[9,5.44],[15,0]],"id":32633412},{"atl":[[5.9,0]],"id":39594662},{"atl":[[2.5,42.39],[2.98,0]],"id":40659166},{"atb":[[25,0]],"id":38440014},{"atl":[[170,0.25],[240,0.1]],"id":38440014},{"atl":[[8.6,0],[6,8.71]],"id":36201034},{"atb":[[1.33,250]],"id":38276037},{"atl":[[8,7.95],[14,0]],"id":39849129}],"con":true,"img":false}]}
{"op":"mcm","clk":"5353564751","pt":1646216323714,"mc":[{"id":"1.195453777","rc":[{"atl":[[4.9,21.71]],"id":39594662},{"atb":[[28,2.72]],"id":38440014},{"atb":[[1.38,108.81]],"id":38276037}],"con":true,"img":false}]}
{"op":"mcm","clk":"5353564860","pt":1646216324707,"mc":[{"id":"1.195453777","rc":[{"atb":[[1.4,0]],"id":38276037}],"con":true,"img":false}]}
{"op":"mcm","clk":"5353565204","pt":1646216327853,"mc":[{"id":"1.195453777","rc":[{"atb":[[1.55,13.66]],"id":40659166}],"con":true,"img":false}]}
{"op":"mcm","clk":"5353565555","pt":1646216330721,"mc":[{"id":"1.195453777","rc":[{"atb":[[1.41,18.33]],"id":38276037}],"con":true,"img":false}]}
{"op":"mcm","clk":"5353565779","pt":1646216333019,"mc":[{"id":"1.195453777","rc":[{"atl":[[4.8,0],[5.1,18.29],[5,0],[5.2,2.88]],"id":39594662},{"atl":[[2.58,47.47]],"id":40659166}],"con":true,"img":false}]}
{"op":"mcm","clk":"5353565833","pt":1646216333642,"mc":[{"id":"1.195453777","rc":[{"atl":[[4.9,12.82]],"id":39594662}],"con":true,"img":false}]}
{"op":"mcm","clk":"5353565843","pt":1646216333748,"mc":[{"id":"1.195453777","rc":[{"atl":[[5,8.89]],"id":39594662}],"con":true,"img":false}]}
{"op":"mcm","clk":"5353566254","pt":1646216337022,"mc":[{"id":"1.195453777","rc":[{"spn":6.25,"spf":"NaN","id":32633412},{"spn":3.43,"spf":"NaN","id":39594662},{"atb":[[1.54,116.67],[1.52,38.46]],"id":40659166},{"spn":2.02,"spf":"NaN","id":40659166},{"spn":49.0,"spf":"NaN","id":38440014},{"spn":4.37,"spf":"NaN","id":36201034},{"spn":1.92,"spf":"NaN","id":38276037},{"spn":5.25,"spf":"NaN","id":39849129}],"con":true,"img":false}]}
{"op":"mcm","clk":"5353566658","pt":1646216340821,"mc":[{"id":"1.195453777","rc":[{"atb":[[1.55,0]],"id":40659166}],"con":true,"img":false}]}
{"op":"mcm","clk":"5353566798","pt":1646216342239,"mc":[{"id":"1.195453777","rc":[{"atb":[[1.54,0],[1.52,230.77]],"id":40659166}],"con":true,"img":false}]}
{"op":"mcm","clk":"5353566897","pt":1646216343021,"mc":[{"id":"1.195453777","rc":[{"atl":[[5.3,29.07]],"id":39594662},{"atl":[[2.62,77.16]],"id":40659166}],"con":true,"img":false}]}
{"op":"mcm","clk":"5353566911","pt":1646216343136,"mc":[{"id":"1.195453777","rc":[{"atl":[[2.56,0],[2.52,0]],"id":40659166}],"con":true,"img":false}]}
{"op":"mcm","clk":"5353566976","pt":1646216343651,"mc":[{"id":"1.195453777","rc":[{"atl":[[14.5,4.02],[22,0]],"id":32633412},{"atb":[[1.51,0]],"id":40659166},{"atl":[[2.5,13.33],[4.2,0]],"id":40659166},{"atb":[[20,0],[23,2.81]],"id":38440014},{"atl":[[270,0]],"id":38440014},{"atl":[[9.8,7.08],[13.5,0]],"id":36201034},{"atb":[[1.29,270.28],[1.34,175.11]],"id":38276037},{"atl":[[17,0],[12.5,4.85]],"id":39849129}],"con":true,"img":false}]}
{"op":"mcm","clk":"5353566987","pt":1646216343756,"mc":[{"id":"1.195453777","rc":[{"atb":[[1.53,96.88]],"id":40659166},{"atl":[[2.52,29.06],[3.55,21.25]],"id":40659166},{"atl":[[190,2.72]],"id":38440014}],"con":true,"img":false}]}
{"op":"mcm","clk":"5353566993","pt":1646216343856,"mc":[{"id":"1.195453777","rc":[{"atb":[[1.51,196.08],[1.52,38.46]],"id":40659166}],"con":true,"img":false}]}
{"op":"mcm","clk":"5353567813","pt":1646216351774,"mc":[{"id":"1.195453777","rc":[{"atb":[[1.57,13.18]],"id":40659166}],"con":true,"img":false}]}
{"op":"mcm","clk":"5353568028","pt":1646216353758,"mc":[{"id":"1.195453777","rc":[{"atb":[[1.53,0]],"id":40659166}],"con":true,"img":false}]}
{"op":"mcm","clk":"5353568040","pt":1646216353865,"mc":[{"id":"1.195453777","rc":[{"atb":[[1.52,135.34]],"id":40659166}],"con":true,"img":false}]}
{"op":"mcm","clk":"5353568148","pt":1646216354862,"mc":[{"id":"1.195453777","rc":[{"atb":[[1.57,0]],"id":40659166}],"con":true,"img":false}]}
{"op":"mcm","clk":"5353568852","pt":1646216361855,"mc":[{"id":"1.195453777","rc":[{"atb":[[1.55,13.66]],"id":40659166}],"con":true,"img":false}]}
{"op":"mcm","clk":"5353568909","pt":1646216362374,"mc":[{"id":"1.195453777","rc":[{"atb":[[1.54,135.35],[1.51,0]],"id":40659166}],"con":true,"img":false}]}
{"op":"mcm","clk":"5353569077","pt":1646216363894,"mc":[{"id":"1.195453777","rc":[{"atb":[[1.55,0]],"id":40659166}],"con":true,"img":false}]}
{"op":"mcm","clk":"5353569449","pt":1646216367558,"mc":[{"id":"1.195453777","rc":[{"atb":[[1.54,0],[1.53,188.68]],"id":40659166}],"con":true,"img":false}]}
{"op":"mcm","clk":"5353570325","pt":1646216375813,"mc":[{"id":"1.195453777","rc":[{"atb":[[1.57,13.18]],"id":40659166}],"con":true,"img":false}]}
{"op":"mcm","clk":"5353571088","pt":1646216383592,"mc":[{"id":"1.195453777","rc":[{"atb":[[1.52,38.46]],"id":40659166}],"con":true,"img":false}]}
{"op":"mcm","clk":"5353571099","pt":1646216383700,"mc":[{"id":"1.195453777","rc":[{"atb":[[1.54,96.88]],"id":40659166}],"con":true,"img":false}]}
{"op":"mcm","clk":"5353571257","pt":1646216385117,"mc":[{"id":"1.195453777","rc":[{"atb":[[1.57,0]],"id":40659166}],"con":true,"img":false}]}
{"op":"mcm","clk":"5353571338","pt":1646216385899,"mc":[{"id":"1.195453777","rc":[{"atb":[[1.54,193.77],[1.53,0]],"id":40659166}],"con":true,"img":false}]}
{"op":"mcm","clk":"5353571914","pt":1646216390892,"mc":[{"id":"1.195453777","rc":[{"atb":[[1.58,12.96]],"id":40659166}],"con":true,"img":false}]}
{"op":"mcm","clk":"5353572185","pt":1646216393629,"mc":[{"id":"1.195453777","rc":[{"atl":[[3.85,0]],"id":38276037}],"con":true,"img":false}]}
{"op":"mcm","clk":"5353572192","pt":1646216393689,"mc":[{"id":"1.195453777","rc":[{"atl":[[3.55,20.88]],"id":38276037}],"con":true,"img":false}]}
{"op":"mcm","clk":"5353573280","pt":1646216403612,"mc":[{"id":"1.195453777","rc":[{"atb":[[1.54,96.89]],"id":40659166},{"spn":2.04,"spf":"NaN","id":40659166}],"con":true,"img":false}]}
{"op":"mcm","clk":"5353573291","pt":1646216403715,"mc":[{"id":"1.195453777","rc":[{"atb":[[1.51,96.88]],"id":40659166}],"con":true,"img":false}]}
{"op":"mcm","clk":"5353573644","pt":1646216406923,"mc":[{"id":"1.195453777","rc":[{"atb":[[1.5,100]],"id":40659166}],"con":true,"img":false}]}
{"op":"mcm","clk":"5353574294","pt":1646216413597,"mc":[{"id":"1.195453777","rc":[{"atb":[[1.38,0]],"id":38276037}],"con":true,"img":false}]}
{"op":"mcm","clk":"5353574303","pt":1646216413716,"mc":[{"id":"1.195453777","rc":[{"atb":[[1.4,108.81]],"id":38276037}],"con":true,"img":false}]}
{"op":"mcm","clk":"5353574420","pt":1646216414813,"mc":[{"id":"1.195453777","rc":[{"atb":[[1.41,0]],"id":38276037}],"con":true,"img":false}]}
{"op":"mcm","clk":"5353574965","pt":1646216420708,"mc":[{"id":"1.195453777","rc":[{"atb":[[1.43,17.48]],"id":38276037}],"con":true,"img":false}]}
{"op":"mcm","clk":"5353575446","pt":1646216425429,"mc":[{"id":"1.195453777","rc":[{"atb":[[1.58,27.33]],"id":40659166}],"con":true,"img":false}]}
{"op":"mcm","clk":"5353575465","pt":1646216425636,"mc":[{"id":"1.195453777","rc":[{"atb":[[3.05,0]],"id":39849129}],"con":true,"img":false}]}
{"op":"mcm","clk":"5353576182","pt":1646216432980,"mc":[{"id":"1.195453777","rc":[{"atb":[[3.1,0]],"id":39849129}],"con":true,"img":false}]}
{"op":"mcm","clk":"5353576194","pt":1646216433084,"mc":[{"id":"1.195453777","rc":[{"atb":[[1.54,0],[1.5,256.25]],"id":40659166},{"atl":[[8.6,16.45],[9.4,11.9]],"id":39849129}],"con":true,"img":false}]}
{"op":"mcm","clk":"5353576201","pt":1646216433179,"mc":[{"id":"1.195453777","rc":[{"atb":[[3.05,1.66]],"id":39849129}],"con":true,"img":false}]}
{"op":"mcm","clk":"5353576533","pt":1646216436064,"mc":[{"id":"1.195453777","rc":[{"atb":[[1.58,14.37]],"id":40659166}],"con":true,"img":false}]}
{"op":"mcm","clk":"5353576883","pt":1646216439057,"mc":[{"id":"1.195453777","rc":[{"atb":[[1.43,36.87]],"id":38276037}],"con":true,"img":false}]}
{"op":"mcm","clk":"5353576921","pt":1646216439363,"mc":[{"id":"1.195453777","rc":[{"atb":[[3,7.92]],"id":39849129}],"con":true,"img":false}]}
{"op":"mcm","clk":"5353577221","pt":1646216441945,"mc":[{"id":"1.195453777","rc":[{"atb":[[1.54,13.92]],"id":40659166}],"con":true,"img":false}]}
{"op":"mcm","clk":"5353578236","pt":1646216453370,"mc":[{"id":"1.195453777","rc":[{"atb":[[1.58,0]],"id":40659166}],"con":true,"img":false}]}
{"op":"mcm","clk":"5353578262","pt":1646216453685,"mc":[{"id":"1.195453777","rc":[{"atb":[[1.4,0]],"id":38276037}],"con":true,"img":false}]}
{"op":"mcm","clk":"5353578271","pt":1646216453787,"mc":[{"id":"1.195453777","rc":[{"atb":[[1.38,108.81]],"id":38276037}],"con":true,"img":false}]}
{"op":"mcm","clk":"5353578463","pt":1646216456386,"mc":[{"id":"1.195453777","rc":[{"atb":[[1.43,19.38]],"id":38276037}],"con":true,"img":false}]}
{"op":"mcm","clk":"5353579093","pt":1646216463377,"mc":[{"id":"1.195453777","rc":[{"atb":[[1.41,18.33]],"id":38276037}],"con":true,"img":false}]}
{"op":"mcm","clk":"5353579317","pt":1646216465704,"mc":[{"id":"1.195453777","rc":[{"atb":[[1.54,29.36]],"id":40659166},{"spn":2.02,"spf":"NaN","id":40659166},{"spn":1.93,"spf":"NaN","id":38276037},{"spn":5.22,"spf":"NaN","id":39849129}],"con":true,"img":false}]}
{"op":"mcm","clk":"5353595643","pt":1646216600544,"mc":[{"id":"1.195453777","rc":[{"atb":[[1.43,0]],"id":38276037},{"spn":1.92,"spf":"NaN","id":38276037}],"con":true,"img":false}]}
{"op":"mcm","clk":"5353597524","pt":1646216619370,"mc":[{"id":"1.195453777","rc":[{"atb":[[1.41,38.67]],"id":38276037}],"con":true,"img":false}]}
{"op":"mcm","clk":"5353600860","pt":1646216654846,"mc":[{"id":"1.195453777","rc":[{"atl":[[4.6,5.56],[4.7,0]],"id":39594662},{"atb":[[1.5,100],[1.51,253.13]],"id":40659166},{"atl":[[2.5,0],[2.52,42.22]],"id":40659166},{"atl":[[6.2,31.86],[6.6,22.32]],"id":36201034}],"con":true,"img":false}]}
{"op":"mcm","clk":"5353601939","pt":1646216664850,"mc":[{"id":"1.195453777","rc":[{"spn":3.38,"spf":"NaN","id":39594662},{"atl":[[2.56,32.05]],"id":40659166},{"spn":2.03,"spf":"NaN","id":40659166}],"con":true,"img":false}]}
{"op":"mcm","clk":"5353602456","pt":1646216670250,"mc":[{"id":"1.195453777","rc":[{"atb":[[1.55,38.46],[1.51,96.88]],"id":40659166}],"con":true,"img":false}]}
{"op":"mcm","clk":"5353602719","pt":1646216673040,"mc":[{"id":"1.195453777","rc":[{"atl":[[4.6,0],[4.7,5.41]],"id":39594662},{"atb":[[1.55,0],[1.54,106.28]],"id":40659166},{"atl":[[2.5,13.33],[2.56,0],[2.52,29.06]],"id":40659166},{"atl":[[6.2,14.41],[6.6,40.18]],"id":36201034},{"atl":[[9,12.5],[9.4,0]],"id":39849129}],"con":true,"img":false}]}
{"op":"mcm","clk":"5353602891","pt":1646216674826,"mc":[{"id":"1.195453777","rc":[{"atb":[[1.54,92.35]],"id":40659166}],"con":true,"img":false}]}
{"op":"mcm","clk":"5353603715","pt":1646216682971,"mc":[{"id":"1.195453777","rc":[{"atb":[[1.58,12.96]],"id":40659166}],"con":true,"img":false}]}
{"op":"mcm","clk":"5353604914","pt":1646216696017,"mc":[{"id":"1.195453777","rc":[{"atb":[[1.54,76.92]],"id":40659166}],"con":true,"img":false}]}
{"op":"mcm","clk":"5353605592","pt":1646216703703,"mc":[{"id":"1.195453777","rc":[{"atb":[[1.38,0]],"id":38276037}],"con":true,"img":false}]}
{"op":"mcm","clk":"5353605605","pt":1646216703811,"mc":[{"id":"1.195453777","rc":[{"atb":[[1.4,108.81]],"id":38276037}],"con":true,"img":false}]}
{"op":"mcm","clk":"5353605883","pt":1646216707124,"mc":[{"id":"1.195453777","rc":[{"atb":[[1.41,20.33]],"id":38276037}],"con":true,"img":false}]}
{"op":"mcm","clk":"5353606417","pt":1646216712932,"mc":[{"id":"1.195453777","rc":[{"atb":[[1.43,17.48]],"id":38276037}],"con":true,"img":false}]}
{"op":"mcm","clk":"5353606597","pt":1646216714925,"mc":[{"id":"1.195453777","rc":[{"atb":[[1.58,27.33]],"id":40659166}],"con":true,"img":false}]}
{"op":"mcm","clk":"5353607693","pt":1646216728435,"mc":[{"id":"1.195453777","rc":[{"spn":3.43,"spf":"NaN","id":39594662},{"spn":2.04,"spf":"NaN","id":40659166},{"atb":[[1.41,0]],"id":38276037},{"spn":1.93,"spf":"NaN","id":38276037}],"con":true,"img":false}]}
{"op":"mcm","clk":"5353608754","pt":1646216741962,"mc":[{"id":"1.195453777","rc":[{"atb":[[1.43,36.87]],"id":38276037}],"con":true,"img":false}]}
{"op":"mcm","clk":"5353613519","pt":1646216793044,"mc":[{"id":"1.195453777","rc":[{"atb":[[1.54,0],[1.5,256.25]],"id":40659166}],"con":true,"img":false}]}
{"op":"mcm","clk":"5353613659","pt":1646216794142,"mc":[{"id":"1.195453777","rc":[{"atb":[[1.58,14.37]],"id":40659166}],"con":true,"img":false}]}
{"op":"mcm","clk":"5353614289","pt":1646216800167,"mc":[{"id":"1.195453777","rc":[{"atb":[[1.54,13.92]],"id":40659166}],"con":true,"img":false}]}
{"op":"mcm","clk":"5353616180","pt":1646216816598,"mc":[{"id":"1.195453777","rc":[{"atb":[[1.58,0]],"id":40659166}],"con":true,"img":false}]}
{"op":"mcm","clk":"5353616895","pt":1646216823590,"mc":[{"id":"1.195453777","rc":[{"atb":[[1.4,0]],"id":38276037}],"con":true,"img":false}]}
{"op":"mcm","clk":"5353616907","pt":1646216823698,"mc":[{"id":"1.195453777","rc":[{"atb":[[1.38,108.81]],"id":38276037}],"con":true,"img":false}]}
{"op":"mcm","clk":"5353616959","pt":1646216824217,"mc":[{"id":"1.195453777","rc":[{"atb":[[1.43,19.38]],"id":38276037}],"con":true,"img":false}]}
{"op":"mcm","clk":"5353617613","pt":1646216830200,"mc":[{"id":"1.195453777","rc":[{"atb":[[1.41,18.33]],"id":38276037}],"con":true,"img":false}]}
{"op":"mcm","clk":"5353617803","pt":1646216831989,"mc":[{"id":"1.195453777","rc":[{"atb":[[1.54,29.36]],"id":40659166}],"con":true,"img":false}]}
{"op":"mcm","clk":"5353619128","pt":1646216846127,"mc":[{"id":"1.195453777","rc":[{"atb":[[1.43,0]],"id":38276037}],"con":true,"img":false}]}
{"op":"mcm","clk":"5353620760","pt":1646216860757,"mc":[{"id":"1.195453777","rc":[{"spn":2.02,"spf":"NaN","id":40659166},{"atb":[[1.41,38.67]],"id":38276037},{"spn":1.92,"spf":"NaN","id":38276037}],"con":true,"img":false}]}
{"op":"mcm","clk":"5353634171","pt":1646217001835,"mc":[{"id":"1.195453777","rc":[{"atb":[[2.16,3.83]],"id":39594662},{"atb":[[1.57,2.16]],"id":40659166},{"spn":2.03,"spf":"NaN","id":40659166},{"atb":[[1.44,2.16]],"id":38276037},{"spn":1.94,"spf":"NaN","id":38276037}],"con":true,"img":false}]}
{"op":"mcm","clk":"5353634193","pt":1646217002044,"mc":[{"id":"1.195453777","rc":[{"atb":[[2.18,7.44],[2.14,0]],"id":39594662}],"con":true,"img":false}]}
{"op":"mcm","clk":"5353634716","pt":1646217007023,"mc":[{"id":"1.195453777","rc":[{"atb":[[2.16,2.16]],"id":39594662}],"con":true,"img":false}]}
{"op":"mcm","clk":"5353634727","pt":1646217007123,"mc":[{"id":"1.195453777","rc":[{"atb":[[2.18,0],[2.16,17.04]],"id":39594662}],"con":true,"img":false}]}
{"op":"mcm","clk":"5353634739","pt":1646217007232,"mc":[{"id":"1.195453777","rc":[{"atb":[[2.2,1.66]],"id":39594662}],"con":true,"img":false}]}
{"op":"mcm","clk":"5353634756","pt":1646217007443,"mc":[{"id":"1.195453777","rc":[{"atb":[[2.2,16.07],[2.16,2.16]],"id":39594662}],"con":true,"img":false}]}
{"op":"mcm","clk":"5353635269","pt":1646217012526,"mc":[{"id":"1.195453777","rc":[{"atb":[[2.26,2.16],[2.16,0]],"id":39594662}],"con":true,"img":false}]}
{"op":"mcm","clk":"5353635279","pt":1646217012631,"mc":[{"id":"1.195453777","rc":[{"atb":[[2.26,16.57]],"id":39594662}],"con":true,"img":false}]}
{"op":"mcm","clk":"5353635287","pt":1646217012735,"mc":[{"id":"1.195453777","rc":[{"atb":[[2.2,1.66]],"id":39594662}],"con":true,"img":false}]}
{"op":"mcm","clk":"5353636008","pt":1646217020059,"mc":[{"id":"1.195453777","rc":[{"atb":[[2.2,0]],"id":39594662}],"con":true,"img":false}]}
{"op":"mcm","clk":"5353636030","pt":1646217020270,"mc":[{"id":"1.195453777","rc":[{"atb":[[2.28,1.66]],"id":39594662}],"con":true,"img":false}]}
{"op":"mcm","clk":"5353636413","pt":1646217023636,"mc":[{"id":"1.195453777","rc":[{"atb":[[1.38,0]],"id":38276037}],"con":true,"img":false}]}
{"op":"mcm","clk":"5353636423","pt":1646217023745,"mc":[{"id":"1.195453777","rc":[{"atb":[[1.4,108.81]],"id":38276037}],"con":true,"img":false}]}
{"op":"mcm","clk":"5353636547","pt":1646217025054,"mc":[{"id":"1.195453777","rc":[{"atb":[[1.41,20.33]],"id":38276037}],"con":true,"img":false}]}
{"op":"mcm","clk":"5353637068","pt":1646217030878,"mc":[{"id":"1.195453777","rc":[{"atb":[[1.43,17.48]],"id":38276037}],"con":true,"img":false}]}
{"op":"mcm","clk":"5353638929","pt":1646217049773,"mc":[{"id":"1.195453777","rc":[{"atb":[[1.41,0]],"id":38276037}],"con":true,"img":false}]}
{"op":"mcm","clk":"5353640255","pt":1646217065283,"mc":[{"id":"1.195453777","rc":[{"spn":3.49,"spf":"NaN","id":39594662},{"atb":[[1.43,36.87]],"id":38276037}],"con":true,"img":false}]}
{"op":"mcm","clk":"5353645323","pt":1646217120151,"mc":[{"id":"1.195453777","rc":[{"atb":[[1.09,0],[1.08,250]],"id":36201034},{"atb":[[1.59,0],[1.58,34.48],[1.63,0],[1.61,0]],"id":39849129}],"con":true,"img":false}]}
{"op":"mcm","clk":"5353646183","pt":1646217130197,"mc":[{"id":"1.195453777","rc":[{"atb":[[1.06,250]],"id":36201034},{"atb":[[1.56,89.29]],"id":39849129}],"con":true,"img":false}]}
{"op":"mcm","clk":"5353647066","pt":1646217140218,"mc":[{"id":"1.195453777","rc":[{"atb":[[1.03,0],[1.07,0],[1.05,0],[1.04,250]],"id":36201034},{"atb":[[1.54,138.89]],"id":39849129}],"con":true,"img":false}]}
{"op":"mcm","clk":"5353647932","pt":1646217149723,"mc":[{"id":"1.195453777","rc":[{"atb":[[2.12,7.09]],"id":39594662},{"atb":[[1.55,5.95]],"id":40659166},{"atb":[[3.1,3.33]],"id":36201034},{"atb":[[1.41,6.49]],"id":38276037},{"atb":[[3.1,3.33]],"id":39849129}],"con":true,"img":false}]}
{"op":"mcm","clk":"5353647974","pt":1646217150209,"mc":[{"id":"1.195453777","rc":[{"atb":[[1.02,250]],"id":36201034},{"atb":[[1.52,240.38]],"id":39849129}],"con":true,"img":false}]}
{"op":"mcm","clk":"5353648183","pt":1646217152452,"mc":[{"id":"1.195453777","rc":[{"atl":[[6.4,18.52],[6.6,22.32]],"id":36201034},{"atl":[[9,0],[8.4,13.51]],"id":39849129}],"con":true,"img":false}]}
{"op":"mcm","clk":"5353648511","pt":1646217156017,"mc":[{"id":"1.195453777","rc":[{"atb":[[3.05,0]],"id":36201034},{"atb":[[3.05,0]],"id":39849129}],"con":true,"img":false}]}
{"op":"mcm","clk":"5353648532","pt":1646217156219,"mc":[{"id":"1.195453777","rc":[{"atb":[[3.15,1.66]],"id":36201034},{"atb":[[3.15,1.66]],"id":39849129}],"con":true,"img":false}]}
{"op":"mcm","clk":"5353648747","pt":1646217158726,"mc":[{"id":"1.195453777","rc":[{"atb":[[3.1,0]],"id":36201034},{"atb":[[3.1,0]],"id":39849129}],"con":true,"img":false}]}
{"op":"mcm","clk":"5353648869","pt":1646217160241,"mc":[{"id":"1.195453777","rc":[{"atb":[[1.57,0]],"id":39849129}],"con":true,"img":false}]}
{"op":"mcm","clk":"5353649090","pt":1646217162451,"mc":[{"id":"1.195453777","rc":[{"atb":[[3.05,4.59]],"id":36201034},{"atb":[[3.05,4.59]],"id":39849129}],"con":true,"img":false}]}
{"op":"mcm","clk":"5353649234","pt":1646217164334,"mc":[{"id":"1.195453777","rc":[{"atb":[[3.15,0],[2.84,54.35]],"id":32633412},{"atl":[[11.5,9.52],[15.5,0]],"id":32633412},{"atl":[[8.6,0],[4.5,5.71],[7.6,15.15],[4.7,0]],"id":39594662},{"atb":[[1.53,96.89],[1.5,40],[1.52,0]],"id":40659166},{"atl":[[3.6,0],[2.5,0],[3,62.09],[2.6,20.06]],"id":40659166},{"atb":[[1.61,31.02]],"id":38440014},{"atl":[[390,1],[200,2]],"id":38440014},{"atb":[[1.09,222.22],[1.08,0]],"id":36201034},{"atl":[[6.4,0],[7.2,16.13]],"id":36201034},{"atl":[[5.1,0],[5.3,4.65],[4.9,25.64]],"id":38276037},{"atl":[[7.8,15.31],[8.4,0]],"id":39849129}],"con":true,"img":false}]}
{"op":"mcm","clk":"5353649258","pt":1646217164642,"mc":[{"id":"1.195453777","rc":[{"atl":[[2.54,0]],"id":40659166}],"con":true,"img":false}]}
{"op":"mcm","clk":"5353649418","pt":1646217166317,"mc":[{"id":"1.195453777","rc":[{"atb":[[1.54,15.43]],"id":40659166}],"con":true,"img":false}]}
{"op":"mcm","clk":"5353649475","pt":1646217166834,"mc":[{"id":"1.195453777","rc":[{"atb":[[1.52,38.46]],"id":40659166},{"atl":[[2.58,0]],"id":40659166},{"atl":[[4.9,30.77]],"id":38276037},{"atb":[[1.58,0],[1.63,31.75]],"id":39849129}],"con":true,"img":false}]}
{"op":"mcm","clk":"5353649484","pt":1646217166937,"mc":[{"id":"1.195453777","rc":[{"atl":[[2.56,12.82]],"id":40659166},{"atb":[[1.09,0],[1.08,250]],"id":36201034}],"con":true,"img":false}]}
{"op":"mcm","clk":"5353649601","pt":1646217168146,"mc":[{"id":"1.195453777","rc":[{"atb":[[2.12,0]],"id":39594662}],"con":true,"img":false}]}
{"op":"mcm","clk":"5353649696","pt":1646217169239,"mc":[{"id":"1.195453777","rc":[{"atl":[[8.4,0],[8.6,2.63]],"id":32633412},{"atb":[[1.37,54.05],[1.39,0]],"id":38276037},{"atl":[[7.4,0],[7.6,3.03]],"id":39849129}],"con":true,"img":false}]}
{"op":"mcm","clk":"5353649764","pt":1646217170025,"mc":[{"id":"1.195453777","rc":[{"atb":[[3.15,0]],"id":36201034},{"atb":[[3.15,0]],"id":39849129}],"con":true,"img":false}]}
{"op":"mcm","clk":"5353649771","pt":1646217170129,"mc":[{"id":"1.195453777","rc":[{"atb":[[1.52,0]],"id":40659166},{"atb":[[1.09,222.22],[1.08,0]],"id":36201034},{"atb":[[1.58,34.48],[1.63,0]],"id":39849129},{"atl":[[7.4,3.12],[7.6,0]],"id":39849129}],"con":true,"img":false}]}
{"op":"mcm","clk":"5353649781","pt":1646217170226,"mc":[{"id":"1.195453777","rc":[{"atb":[[3.1,1.66]],"id":36201034},{"atb":[[3.1,1.66]],"id":39849129}],"con":true,"img":false}]}
{"op":"mcm","clk":"5353649799","pt":1646217170466,"mc":[{"id":"1.195453777","rc":[{"atl":[[10.5,12.64],[5.3,0],[4.9,0],[4.5,0],[5.1,0],[7.6,0]],"id":39594662},{"atb":[[3.5,8]],"id":38440014},{"atb":[[1.18,111.11],[1.09,0],[1.08,250]],"id":36201034},{"atl":[[5.1,4.88],[4.9,25.64]],"id":38276037},{"atb":[[1.62,89.29],[1.66,30.3]],"id":39849129}],"con":true,"img":false}]}
{"op":"mcm","clk":"5353649805","pt":1646217170524,"mc":[{"id":"1.195453777","rc":[{"atb":[[3.3,0]],"id":38440014},{"atb":[[1.58,0],[1.53,0]],"id":39849129}],"con":true,"img":false}]}
{"op":"mcm","clk":"5353649918","pt":1646217171838,"mc":[{"id":"1.195453777","rc":[{"atb":[[2.12,7.09]],"id":39594662}],"con":true,"img":false}]}
{"op":"mcm","clk":"5353649958","pt":1646217172319,"mc":[{"id":"1.195453777","rc":[{"atb":[[1.57,15.35]],"id":40659166}],"con":true,"img":false}]}
{"op":"mcm","clk":"5353650061","pt":1646217173731,"mc":[{"id":"1.195453777","rc":[{"atl":[[5,0]],"id":39594662},{"atb":[[1.51,0]],"id":40659166},{"atl":[[2.52,0],[3.55,0]],"id":40659166}],"con":true,"img":false}]}
{"op":"mcm","clk":"5353650073","pt":1646217173831,"mc":[{"id":"1.195453777","rc":[{"atl":[[5.9,8.89]],"id":39594662},{"atb":[[1.53,193.77]],"id":40659166},{"atl":[[3.8,21.25],[2.6,49.12]],"id":40659166}],"con":true,"img":false}]}
{"op":"mcm","clk":"5353650150","pt":1646217174663,"mc":[{"id":"1.195453777","rc":[{"atb":[[3,50],[2.84,0]],"id":32633412},{"atl":[[9.6,26.16],[11.5,0]],"id":32633412},{"atb":[[1.58,15.36],[1.53,96.88]],"id":40659166},{"atb":[[1.61,0],[2.68,31.02]],"id":38440014}],"con":true,"img":false}]}
{"op":"mcm","clk":"5353650164","pt":1646217174769,"mc":[{"id":"1.195453777","rc":[{"atl":[[6.4,18.52],[7.2,0]],"id":36201034}],"con":true,"img":false}]}
{"op":"mcm","clk":"5353650255","pt":1646217175759,"mc":[{"id":"1.195453777","rc":[{"atb":[[1.57,13.18],[1.61,2.16]],"id":40659166}],"con":true,"img":false}]}
{"op":"mcm","clk":"5353650356","pt":1646217176962,"mc":[{"id":"1.195453777","rc":[{"atb":[[1.48,104.17]],"id":40659166},{"atl":[[2.6,67.87]],"id":40659166}],"con":true,"img":false}]}
{"op":"mcm","clk":"5353650400","pt":1646217177536,"mc":[{"id":"1.195453777","rc":[{"atb":[[2.12,0]],"id":39594662},{"atb":[[1.55,0]],"id":40659166}],"con":true,"img":false}]}
{"op":"mcm","clk":"5353650550","pt":1646217179252,"mc":[{"id":"1.195453777","rc":[{"atl":[[9,11.69]],"id":32633412}],"con":true,"img":false}]}
{"op":"mcm","clk":"5353650664","pt":1646217180450,"mc":[{"id":"1.195453777","rc":[{"atb":[[6,4]],"id":32633412},{"atl":[[9.6,11.63],[9.2,0],[8.8,0]],"id":32633412},{"atl":[[11.5,4.76]],"id":39594662},{"atl":[[2.26,2]],"id":40659166},{"atb":[[3.4,20.83]],"id":38440014},{"atb":[[1.16,250]],"id":36201034},{"atb":[[1.35,142.86]],"id":38276037},{"atl":[[5.3,11.63],[4.9,27.64]],"id":38276037},{"atb":[[1.64,78.13]],"id":39849129},{"atl":[[4.8,2]],"id":39849129}],"con":true,"img":false}]}
{"op":"mcm","clk":"5353650719","pt":1646217181146,"mc":[{"id":"1.195453777","rc":[{"atb":[[2.12,7.09]],"id":39594662},{"atb":[[1.62,4.33]],"id":40659166}],"con":true,"img":false}]}
{"op":"mcm","clk":"5353650967","pt":1646217183653,"mc":[{"id":"1.195453777","rc":[{"atl":[[9,6.25]],"id":32633412},{"atb":[[1.53,0]],"id":40659166},{"atb":[[18,3.64],[23,0],[28,0]],"id":38440014},{"atb":[[1.4,0]],"id":38276037},{"atb":[[2.86,0]],"id":39849129}],"con":true,"img":false}]}
{"op":"mcm","clk":"5353650977","pt":1646217183758,"mc":[{"id":"1.195453777","rc":[{"atl":[[9.4,5.44]],"id":32633412},{"atb":[[1.51,96.88]],"id":40659166},{"atb":[[22,2.72]],"id":38440014},{"atb":[[1.38,108.81]],"id":38276037},{"atb":[[2.76,30.03]],"id":39849129}],"con":true,"img":false}]}
{"op":"mcm","clk":"5353651007","pt":1646217184074,"mc":[{"id":"1.195453777","rc":[{"atb":[[4.1,0]],"id":32633412}],"con":true,"img":false}]}
{"op":"mcm","clk":"5353651024","pt":1646217184281,"mc":[{"id":"1.195453777","rc":[{"atb":[[1.57,0]],"id":40659166},{"atb":[[1.43,19.38]],"id":38276037}],"con":true,"img":false}]}
{"op":"mcm","clk":"5353651042","pt":1646217184443,"mc":[{"id":"1.195453777","rc":[{"atb":[[6.2,3]],"id":32633412},{"atl":[[2.24,3]],"id":40659166},{"atb":[[3,0]],"id":38440014},{"atb":[[1.02,0]],"id":36201034},{"atl":[[4.8,3]],"id":38276037},{"atb":[[1.52,0]],"id":39849129},{"atl":[[4.7,3]],"id":39849129}],"con":true,"img":false}]}
{"op":"mcm","clk":"5353651084","pt":1646217184861,"mc":[{"id":"1.195453777","rc":[{"atb":[[1.58,0],[1.63,4.33]],"id":40659166}],"con":true,"img":false}]}
{"op":"mcm","clk":"5353651193","pt":1646217186380,"mc":[{"id":"1.195453777","rc":[{"atb":[[1.62,0]],"id":40659166},{"atb":[[3.05,0]],"id":39849129}],"con":true,"img":false}]}
{"op":"mcm","clk":"5353651235","pt":1646217186855,"mc":[{"id":"1.195453777","rc":[{"atb":[[1.46,413.04]],"id":40659166},{"atl":[[2.64,45.73]],"id":40659166}],"con":true,"img":false}]}
{"op":"mcm","clk":"5353651248","pt":1646217186956,"mc":[{"id":"1.195453777","rc":[{"atb":[[1.46,163.04]],"id":40659166}],"con":true,"img":false}]}
{"op":"mcm","clk":"5353651260","pt":1646217187061,"mc":[{"id":"1.195453777","rc":[{"atb":[[6.4,4]],"id":32633412},{"atl":[[4.7,4]],"id":38276037},{"atl":[[4.6,4]],"id":39849129}],"con":true,"img":false}]}
{"op":"mcm","clk":"5353651268","pt":1646217187163,"mc":[{"id":"1.195453777","rc":[{"atl":[[2.22,4]],"id":40659166}],"con":true,"img":false}]}
{"op":"mcm","clk":"5353651276","pt":1646217187267,"mc":[{"id":"1.195453777","rc":[{"atb":[[6.6,4]],"id":32633412},{"atl":[[4.6,3]],"id":38276037},{"atl":[[4.5,3]],"id":39849129}],"con":true,"img":false}]}
{"op":"mcm","clk":"5353651285","pt":1646217187372,"mc":[{"id":"1.195453777","rc":[{"atb":[[1.57,2.16],[1.61,0]],"id":40659166}],"con":true,"img":false}]}
{"op":"mcm","clk":"5353651450","pt":1646217189251,"mc":[{"id":"1.195453777","rc":[{"atl":[[9.4,14.37]],"id":32633412}],"con":true,"img":false}]}
{"op":"mcm","clk":"5353651521","pt":1646217189986,"mc":[{"id":"1.195453777","rc":[{"atb":[[1.57,17.6],[1.55,18.4]],"id":40659166}],"con":true,"img":false}]}
{"op":"mcm","clk":"5353651532","pt":1646217190048,"mc":[{"id":"1.195453777","rc":[{"atb":[[1.63,0]],"id":40659166}],"con":true,"img":false}]}
{"op":"mcm","clk":"5353651553","pt":1646217190260,"mc":[{"id":"1.195453777","rc":[{"spn":7.6,"spf":"NaN","id":32633412},{"spn":3.74,"spf":"NaN","id":39594662},{"atb":[[1.54,29.36]],"id":40659166},{"spn":1.89,"spf":"NaN","id":40659166},{"spn":46.0,"spf":"NaN","id":38440014},{"spn":4.4,"spf":"NaN","id":36201034},{"atb":[[1.41,24.83]],"id":38276037},{"spn":3.8,"spf":"NaN","id":39849129}],"con":true,"img":false}]}
{"op":"mcm","clk":"5353651568","pt":1646217190461,"mc":[{"id":"1.195453777","rc":[{"atl":[[12.5,6.52]],"id":39594662},{"atb":[[3.3,32.61]],"id":38440014},{"atb":[[1.14,250]],"id":36201034},{"atb":[[1.33,227.27]],"id":38276037},{"atl":[[5.5,16.67]],"id":38276037},{"atb":[[1.62,210.26]],"id":39849129}],"con":true,"img":false}]}
{"op":"mcm","clk":"5353651862","pt":1646217193670,"mc":[{"id":"1.195453777","rc":[{"atl":[[8,1.72]],"id":39849129}],"con":true,"img":false}]}
{"op":"mcm","clk":"5353651867","pt":1646217193772,"mc":[{"id":"1.195453777","rc":[{"atl":[[7.6,6.22]],"id":39849129}],"con":true,"img":false}]}
{"op":"mcm","clk":"5353652153","pt":1646217196867,"mc":[{"id":"1.195453777","rc":[{"atb":[[1.44,250]],"id":40659166},{"atl":[[2.68,74.4]],"id":40659166}],"con":true,"img":false}]}
{"op":"mcm","clk":"5353652171","pt":1646217197077,"mc":[{"id":"1.195453777","rc":[{"atl":[[2.2,2]],"id":40659166},{"atb":[[3.1,0]],"id":38440014},{"atb":[[1.04,0]],"id":36201034},{"atb":[[1.54,0]],"id":39849129}],"con":true,"img":false}]}
{"op":"mcm","clk":"5353652185","pt":1646217197178,"mc":[{"id":"1.195453777","rc":[{"atl":[[2.62,0]],"id":40659166}],"con":true,"img":false}]}
{"op":"mcm","clk":"5353652192","pt":1646217197282,"mc":[{"id":"1.195453777","rc":[{"atl":[[4.4,4]],"id":39849129}],"con":true,"img":false}]}
{"op":"mcm","clk":"5353652200","pt":1646217197388,"mc":[{"id":"1.195453777","rc":[{"atl":[[4.8,0]],"id":39849129}],"con":true,"img":false}]}
{"op":"mcm","clk":"5353652254","pt":1646217198064,"mc":[{"id":"1.195453777","rc":[{"atb":[[3.1,0]],"id":39849129}],"con":true,"img":false}]}
{"op":"mcm","clk":"5353652272","pt":1646217198272,"mc":[{"id":"1.195453777","rc":[{"atb":[[3.05,1.66]],"id":39849129}],"con":true,"img":false}]}
{"op":"mcm","clk":"5353652359","pt":1646217199269,"mc":[{"id":"1.195453777","rc":[{"atl":[[9.8,14.2]],"id":32633412}],"con":true,"img":false}]}
{"op":"mcm","clk":"5353652475","pt":1646217200480,"mc":[{"id":"1.195453777","rc":[{"atl":[[13.5,10]],"id":39594662},{"atb":[[3.2,56.82]],"id":38440014},{"atb":[[1.12,250]],"id":36201034},{"atb":[[1.31,250]],"id":38276037},{"atl":[[5.7,26.6]],"id":38276037},{"atb":[[1.6,208.33]],"id":39849129}],"con":true,"img":false}]}
{"op":"mcm","clk":"5353652626","pt":1646217202056,"mc":[{"id":"1.195453777","rc":[{"atb":[[1.06,0]],"id":36201034},{"atb":[[1.56,0]],"id":39849129}],"con":true,"img":false}]}
{"op":"mcm","clk":"5353652770","pt":1646217203685,"mc":[{"id":"1.195453777","rc":[{"atl":[[2.6,38.81]],"id":40659166},{"atl":[[170,0]],"id":38440014},{"atl":[[6,0]],"id":36201034}],"con":true,"img":false}]}
{"op":"mcm","clk":"5353652783","pt":1646217203787,"mc":[{"id":"1.195453777","rc":[{"atl":[[2.58,29.06]],"id":40659166},{"atl":[[130,0.25]],"id":38440014},{"atl":[[5.8,8.71]],"id":36201034}],"con":true,"img":false}]}
{"op":"mcm","clk":"5353652803","pt":1646217203995,"mc":[{"id":"1.195453777","rc":[{"atl":[[150,2],[200,0]],"id":38440014}],"con":true,"img":false}]}
{"op":"mcm","clk":"5353653181","pt":1646217208171,"mc":[{"id":"1.195453777","rc":[{"atb":[[1.43,0]],"id":38276037}],"con":true,"img":false}]}
{"op":"mcm","clk":"5353653404","pt":1646217211098,"mc":[{"id":"1.195453777","rc":[{"atb":[[1.41,18.33]],"id":38276037}],"con":true,"img":false}]}
{"op":"mcm","clk":"5353653664","pt":1646217213603,"mc":[{"id":"1.195453777","rc":[{"atb":[[2.8,0]],"id":32633412}],"con":true,"img":false}]}
{"op":"mcm","clk":"5353653672","pt":1646217213706,"mc":[{"id":"1.195453777","rc":[{"atb":[[3.05,31.26]],"id":32633412}],"con":true,"img":false}]}
{"op":"mcm","clk":"5353653740","pt":1646217214386,"mc":[{"id":"1.195453777","rc":[{"atb":[[1.39,7.57]],"id":38276037}],"con":true,"img":false}]}
{"op":"mcm","clk":"5353654649","pt":1646217223599,"mc":[{"id":"1.195453777","rc":[{"atl":[[9.4,8.93]],"id":32633412},{"atb":[[18,0],[22,0]],"id":38440014},{"atl":[[190,0]],"id":38440014}],"con":true,"img":false}]}
{"op":"mcm","clk":"5353654661","pt":1646217223705,"mc":[{"id":"1.195453777","rc":[{"atl":[[8.8,5.44]],"id":32633412},{"atb":[[19.5,2.72],[15.5,3.64]],"id":38440014},{"atl":[[130,2.98]],"id":38440014}],"con":true,"img":false}]}
{"op":"mcm","clk":"5353654860","pt":1646217225495,"mc":[{"id":"1.195453777","rc":[{"atb":[[1.41,38.67]],"id":38276037}],"con":true,"img":false}]}
{"op":"mcm","clk":"5353656003","pt":1646217237443,"mc":[{"id":"1.195453777","rc":[{"atb":[[3.6,0],[3.85,0],[3.35,0]],"id":32633412},{"atl":[[17.5,0],[75,0],[40,0],[12.5,0],[25,0]],"id":32633412},{"atb":[[2.06,0],[1.98,0],[1.93,44.04]],"id":39594662},{"atl":[[16,0],[6.4,0],[11,0],[5.2,0],[8.4,0]],"id":39594662},{"atb":[[1.25,0],[1.3,0],[1.35,0]],"id":40659166},{"atl":[[2.8,0],[3,50],[2.6,31.25],[3.5,0],[4,0]],"id":40659166},{"atb":[[9.8,0],[8.8,0],[7.8,0]],"id":38440014},{"atl":[[70,0],[140,0],[340,0],[440,0],[240,0]],"id":38440014},{"atb":[[2.84,0],[2.94,0],[2.74,0]],"id":36201034},{"atl":[[8,0],[10,0],[20,0],[15,0],[30,0]],"id":36201034},{"atb":[[1.2,0],[1.25,0],[1.15,0]],"id":38276037},{"atl":[[3.6,0],[3.1,0],[2.44,0],[2.64,0],[2.84,0]],"id":38276037},{"atb":[[2.74,0],[2.84,0],[2.94,0]],"id":39849129},{"atl":[[8,0],[10,0],[15,0],[20,0],[30,0]],"id":39849129}],"con":true,"img":false}]}
{"op":"mcm","clk":"5353656040","pt":1646217237712,"mc":[{"id":"1.195453777","rc":[{"atb":[[2.54,41.66],[2.68,0]],"id":38440014}],"con":true,"img":false}]}
{"op":"mcm","clk":"5353656101","pt":1646217238435,"mc":[{"id":"1.195453777","rc":[{"atb":[[2.1,7.57]],"id":39594662},{"atb":[[3,4.16]],"id":36201034},{"atb":[[3,4.16]],"id":39849129}],"con":true,"img":false}]}
{"op":"mcm","clk":"5353656115","pt":1646217238539,"mc":[{"id":"1.195453777","rc":[{"atb":[[1.45,141.15]],"id":40659166},{"atl":[[110,0.39]],"id":38440014}],"con":true,"img":false}]}
{"op":"mcm","clk":"5353656127","pt":1646217238645,"mc":[{"id":"1.195453777","rc":[{"atb":[[1.39,0]],"id":40659166},{"atl":[[130,2.72]],"id":38440014}],"con":true,"img":false}]}
{"op":"mcm","clk":"5353656262","pt":1646217240222,"mc":[{"id":"1.195453777","rc":[{"atb":[[2.12,0]],"id":39594662},{"atb":[[1.39,0]],"id":38276037}],"con":true,"img":false}]}
{"op":"mcm","clk":"5353656361","pt":1646217241230,"mc":[{"id":"1.195453777","rc":[{"atb":[[3.6,46.53],[3.85,21.22],[3.35,51.48]],"id":32633412},{"atl":[[17.5,0.73],[75,0.65],[40,0.62],[12.5,1.05],[25,1]],"id":32633412},{"atb":[[2.06,57.07],[1.98,123.45],[1.93,174.13]],"id":39594662},{"atl":[[16,3.22],[6.4,2.23],[11,2.41],[5.2,2.88],[8.4,3.26]],"id":39594662},{"atb":[[1.25,483.95],[1.3,403.29],[1.35,172.83]],"id":40659166},{"atl":[[2.8,6.71],[3,62.09],[2.6,38.81],[3.5,9.67],[4,16.13]],"id":40659166},{"atb":[[9.8,6.87],[8.8,15.51],[7.8,17.79]],"id":38440014},{"atl":[[70,0.17],[140,0.08],[340,0.07],[440,0.1],[240,0.1]],"id":38440014},{"atb":[[2.84,65.75],[2.94,31.18],[2.74,69.53]],"id":36201034},{"atl":[[8,1.72],[10,1.34],[20,1.27],[15,1.72],[30,1.66]],"id":36201034},{"atb":[[1.2,604.93],[1.25,241.97],[1.15,806.58]],"id":38276037},{"atl":[[3.6,18.61],[3.1,11.52],[2.44,8.4],[2.64,7.37],[2.84,13.15]],"id":38276037},{"atb":[[2.74,69.53],[2.84,65.75],[2.94,31.18]],"id":39849129},{"atl":[[8,1.72],[10,1.34],[15,1.72],[20,1.27],[30,1.66]],"id":39849129}],"con":true,"img":false}]}
{"op":"mcm","clk":"5353656406","pt":1646217241647,"mc":[{"id":"1.195453777","rc":[{"atb":[[5.9,2],[6.6,0]],"id":32633412}],"con":true,"img":false}]}
{"op":"mcm","clk":"5353656605","pt":1646217243615,"mc":[{"id":"1.195453777","rc":[{"atb":[[2.96,0]],"id":39849129},{"atl":[[7.6,0]],"id":39849129}],"con":true,"img":false}]}
{"op":"mcm","clk":"5353656614","pt":1646217243721,"mc":[{"id":"1.195453777","rc":[{"atb":[[2.12,7.09]],"id":39594662},{"atb":[[1.39,7.57]],"id":38276037},{"atb":[[2.86,18.55]],"id":39849129},{"atl":[[8.4,6.22]],"id":39849129}],"con":true,"img":false}]}
{"op":"mcm","clk":"5353656966","pt":1646217247230,"mc":[{"id":"1.195453777","rc":[{"atb":[[2.76,41.66]],"id":38440014}],"con":true,"img":false}]}
{"op":"mcm","clk":"5353656977","pt":1646217247334,"mc":[{"id":"1.195453777","rc":[{"atb":[[2.54,0]],"id":38440014}],"con":true,"img":false}]}
{"op":"mcm","clk":"5353657092","pt":1646217248442,"mc":[{"id":"1.195453777","rc":[{"atb":[[5.9,0],[6.6,3]],"id":32633412},{"atl":[[4.3,2],[4.7,0]],"id":39849129}],"con":true,"img":false}]}
{"op":"mcm","clk":"5353657169","pt":1646217249024,"mc":[{"id":"1.195453777","rc":[{"atb":[[5.9,2],[6.6,0]],"id":32633412}],"con":true,"img":false}]}
{"op":"mcm","clk":"5353657313","pt":1646217250430,"mc":[{"id":"1.195453777","rc":[{"spn":7.5,"spf":"NaN","id":32633412},{"atb":[[2.1,14.41]],"id":39594662},{"spn":1.88,"spf":"NaN","id":40659166},{"spn":44.75,"spf":"NaN","id":38440014},{"atb":[[3,7.92]],"id":36201034},{"spn":3.67,"spf":"NaN","id":39849129}],"con":true,"img":false}]}
{"op":"mcm","clk":"5353657489","pt":1646217252357,"mc":[{"id":"1.195453777","rc":[{"atb":[[2.48,33.3],[2.76,0]],"id":38440014}],"con":true,"img":false}]}
{"op":"mcm","clk":"5353658503","pt":1646217263695,"mc":[{"id":"1.195453777","rc":[{"atl":[[6.6,0]],"id":39594662},{"atb":[[1.38,0]],"id":38276037}],"con":true,"img":false}]}
{"op":"mcm","clk":"5353658516","pt":1646217263749,"mc":[{"id":"1.195453777","rc":[{"atl":[[7.2,11.44]],"id":39594662},{"atb":[[1.46,108.81]],"id":38276037}],"con":true,"img":false}]}
{"op":"mcm","clk":"5353658584","pt":1646217264477,"mc":[{"id":"1.195453777","rc":[{"atb":[[1.44,0],[1.49,2.16]],"id":38276037}],"con":true,"img":false}]}
{"op":"mcm","clk":"5353658687","pt":1646217265472,"mc":[{"id":"1.195453777","rc":[{"atb":[[1.41,20.33]],"id":38276037}],"con":true,"img":false}]}
{"op":"mcm","clk":"5353658760","pt":1646217266363,"mc":[{"id":"1.195453777","rc":[{"atb":[[1.39,0]],"id":38276037}],"con":true,"img":false}]}
{"op":"mcm","clk":"5353658806","pt":1646217266756,"mc":[{"id":"1.195453777","rc":[{"atb":[[2.26,33.3]],"id":38440014}],"con":true,"img":false}]}
{"op":"mcm","clk":"5353658815","pt":1646217266859,"mc":[{"id":"1.195453777","rc":[{"atb":[[2.48,0]],"id":38440014}],"con":true,"img":false}]}
{"op":"mcm","clk":"5353659079","pt":1646217269858,"mc":[{"id":"1.195453777","rc":[{"atb":[[1.42,8.66]],"id":38276037}],"con":true,"img":false}]}
{"op":"mcm","clk":"5353659220","pt":1646217271470,"mc":[{"id":"1.195453777","rc":[{"atb":[[1.49,17.51]],"id":38276037}],"con":true,"img":false}]}
{"op":"mcm","clk":"5353659273","pt":1646217272092,"mc":[{"id":"1.195453777","rc":[{"atb":[[5.9,0],[6.6,2]],"id":32633412},{"atl":[[4.3,0],[4.7,2]],"id":39849129}],"con":true,"img":false}]}
{"op":"mcm","clk":"5353659282","pt":1646217272197,"mc":[{"id":"1.195453777","rc":[{"atb":[[2.26,0],[2.48,33.3]],"id":38440014}],"con":true,"img":false}]}
{"op":"mcm","clk":"5353659399","pt":1646217273562,"mc":[{"id":"1.195453777","rc":[{"atb":[[1.34,0]],"id":38276037}],"con":true,"img":false}]}
{"op":"mcm","clk":"5353659408","pt":1646217273657,"mc":[{"id":"1.195453777","rc":[{"atb":[[1.38,175.11]],"id":38276037}],"con":true,"img":false}]}
{"op":"mcm","clk":"5353659477","pt":1646217274488,"mc":[{"id":"1.195453777","rc":[{"atl":[[4.8,0],[4.9,25.64],[4.6,0],[4.7,0]],"id":38276037}],"con":true,"img":false}]}
{"op":"mcm","clk":"5353659484","pt":1646217274590,"mc":[{"id":"1.195453777","rc":[{"atb":[[5.9,3],[6.6,0]],"id":32633412}],"con":true,"img":false}]}
{"op":"mcm","clk":"5353659503","pt":1646217274797,"mc":[{"id":"1.195453777","rc":[{"atl":[[4.3,3],[4.7,0]],"id":39849129}],"con":true,"img":false}]}
{"op":"mcm","clk":"5353659515","pt":1646217274960,"mc":[{"id":"1.195453777","rc":[{"atl":[[4.3,0],[4.7,2]],"id":39849129}],"con":true,"img":false}]}
{"op":"mcm","clk":"5353659704","pt":1646217277203,"mc":[{"id":"1.195453777","rc":[{"atb":[[2.32,33.3],[2.48,0]],"id":38440014},{"atb":[[1.18,0],[1.16,125]],"id":36201034},{"atl":[[5.1,3]],"id":36201034},{"atl":[[4.3,4],[4.7,0]],"id":39849129}],"con":true,"img":false}]}
{"op":"mcm","clk":"5353659726","pt":1646217277372,"mc":[{"id":"1.195453777","rc":[{"atb":[[5.9,0],[6.6,3]],"id":32633412},{"atl":[[4.5,2]],"id":36201034},{"atl":[[4.3,0],[4.7,4]],"id":39849129}],"con":true,"img":false}]}
{"op":"mcm","clk":"5353659731","pt":1646217277466,"mc":[{"id":"1.195453777","rc":[{"atl":[[5.1,0]],"id":36201034}],"con":true,"img":false}]}
{"op":"mcm","clk":"5353659974","pt":1646217279487,"mc":[{"id":"1.195453777","rc":[{"atl":[[4.4,3]],"id":36201034}],"con":true,"img":false}]}
{"op":"mcm","clk":"5353660170","pt":1646217281592,"mc":[{"id":"1.195453777","rc":[{"atb":[[3.05,0]],"id":36201034}],"con":true,"img":false}]}
{"op":"mcm","clk":"5353660243","pt":1646217282283,"mc":[{"id":"1.195453777","rc":[{"atl":[[2.58,41.72],[2.56,0]],"id":40659166},{"atb":[[1.18,111.11]],"id":36201034},{"atl":[[4.3,3],[4.4,0],[4.5,0]],"id":36201034}],"con":true,"img":false}]}
{"op":"mcm","clk":"5353660256","pt":1646217282382,"mc":[{"id":"1.195453777","rc":[{"atl":[[6.4,0],[6.2,32.94]],"id":36201034}],"con":true,"img":false}]}
{"op":"mcm","clk":"5353660266","pt":1646217282487,"mc":[{"id":"1.195453777","rc":[{"atl":[[4.3,0]],"id":36201034}],"con":true,"img":false}]}
{"op":"mcm","clk":"5353660345","pt":1646217283176,"mc":[{"id":"1.195453777","rc":[{"atb":[[1.41,0]],"id":38276037}],"con":true,"img":false}]}
{"op":"mcm","clk":"5353660420","pt":1646217284012,"mc":[{"id":"1.195453777","rc":[{"atb":[[3.1,0]],"id":36201034}],"con":true,"img":false}]}
{"op":"mcm","clk":"5353660437","pt":1646217284219,"mc":[{"id":"1.195453777","rc":[{"atb":[[3.05,1.66]],"id":36201034}],"con":true,"img":false}]}
{"op":"mcm","clk":"5353660514","pt":1646217284999,"mc":[{"id":"1.195453777","rc":[{"atb":[[3.15,3.33]],"id":36201034}],"con":true,"img":false}]}
{"op":"mcm","clk":"5353660618","pt":1646217286398,"mc":[{"id":"1.195453777","rc":[{"atb":[[2.32,0],[3,33.3]],"id":38440014}],"con":true,"img":false}]}
{"op":"mcm","clk":"5353660721","pt":1646217287500,"mc":[{"id":"1.195453777","rc":[{"atb":[[3,0]],"id":38440014}],"con":true,"img":false}]}
{"op":"mcm","clk":"5353660743","pt":1646217287710,"mc":[{"id":"1.195453777","rc":[{"atb":[[5.9,4],[6.6,0]],"id":32633412},{"atb":[[2.08,33.3]],"id":38440014},{"atl":[[4.3,2],[4.7,0]],"id":39849129}],"con":true,"img":false}]}
{"op":"mcm","clk":"5353661191","pt":1646217292309,"mc":[{"id":"1.195453777","rc":[{"atl":[[2.62,30.86]],"id":40659166},{"atb":[[1.16,250]],"id":36201034}],"con":true,"img":false}]}
{"op":"mcm","clk":"5353661270","pt":1646217293211,"mc":[{"id":"1.195453777","rc":[{"atl":[[2.58,29.06],[2.62,0],[2.56,12.82]],"id":40659166},{"atb":[[1.18,0],[1.16,125]],"id":36201034},{"atl":[[6.4,18.52],[5,2],[6.2,14.42]],"id":36201034}],"con":true,"img":false}]}
{"op":"mcm","clk":"5353661291","pt":1646217293420,"mc":[{"id":"1.195453777","rc":[{"atb":[[5.9,0],[6.6,3]],"id":32633412},{"atl":[[4.5,2],[5,0]],"id":36201034},{"atl":[[4.3,0],[4.7,4]],"id":39849129}],"con":true,"img":false}]}
{"op":"mcm","clk":"5353661305","pt":1646217293582,"mc":[{"id":"1.195453777","rc":[{"atb":[[2.86,0]],"id":39849129},{"atl":[[8.4,0]],"id":39849129}],"con":true,"img":false}]}
{"op":"mcm","clk":"5353661316","pt":1646217293685,"mc":[{"id":"1.195453777","rc":[{"atb":[[2.96,18.55]],"id":39849129},{"atl":[[7.6,6.22]],"id":39849129}],"con":true,"img":false}]}
{"op":"mcm","clk":"5353661472","pt":1646217295518,"mc":[{"id":"1.195453777","rc":[{"atb":[[3,33.3],[2.08,0]],"id":38440014}],"con":true,"img":false}]}
{"op":"mcm","clk":"5353661484","pt":1646217295621,"mc":[{"id":"1.195453777","rc":[{"atb":[[1.49,34.52]],"id":38276037}],"con":true,"img":false}]}
{"op":"mcm","clk":"5353661849","pt":1646217299018,"mc":[{"id":"1.195453777","rc":[{"atb":[[3.05,0]],"id":36201034}],"con":true,"img":false}]}
{"op":"mcm","clk":"5353661870","pt":1646217299226,"mc":[{"id":"1.195453777","rc":[{"atb":[[3.2,1.66]],"id":36201034}],"con":true,"img":false}]}
{"op":"mcm","clk":"5353661899","pt":1646217299492,"mc":[{"id":"1.195453777","rc":[{"atl":[[2.58,41.72],[2.56,0]],"id":40659166},{"atb":[[1.18,111.11]],"id":36201034},{"atl":[[4.4,3],[4.5,0]],"id":36201034}],"con":true,"img":false}]}
{"op":"mcm","clk":"5353661918","pt":1646217299695,"mc":[{"id":"1.195453777","rc":[{"atl":[[4.4,0]],"id":36201034}],"con":true,"img":false}]}
{"op":"mcm","clk":"5353661984","pt":1646217300323,"mc":[{"id":"1.195453777","rc":[{"atb":[[3,0],[2.08,33.3]],"id":38440014}],"con":true,"img":false}]}
{"op":"mcm","clk":"5353662091","pt":1646217301524,"mc":[{"id":"1.195453777","rc":[{"atb":[[3.15,0]],"id":36201034}],"con":true,"img":false}]}
{"op":"mcm","clk":"5353662160","pt":1646217302216,"mc":[{"id":"1.195453777","rc":[{"atl":[[6.4,0],[6.2,32.94]],"id":36201034}],"con":true,"img":false}]}
{"op":"mcm","clk":"5353662407","pt":1646217304835,"mc":[{"id":"1.195453777","rc":[{"atb":[[3.05,5]],"id":36201034}],"con":true,"img":false}]}
{"op":"mcm","clk":"5353662489","pt":1646217305626,"mc":[{"id":"1.195453777","rc":[{"atb":[[5.9,3],[6.6,0]],"id":32633412},{"atl":[[4.3,4],[4.7,0]],"id":39849129}],"con":true,"img":false}]}
{"op":"mcm","clk":"5353662838","pt":1646217309533,"mc":[{"id":"1.195453777","rc":[{"atl":[[2.62,30.86]],"id":40659166},{"atb":[[1.16,375]],"id":36201034}],"con":true,"img":false}]}
{"op":"mcm","clk":"5353662845","pt":1646217309637,"mc":[{"id":"1.195453777","rc":[{"atb":[[1.16,250]],"id":36201034}],"con":true,"img":false}]}
{"op":"mcm","clk":"5353663028","pt":1646217311421,"mc":[{"id":"1.195453777","rc":[{"atl":[[2.58,29.06],[2.62,0],[2.56,12.82]],"id":40659166},{"atl":[[6.4,18.52],[6.2,14.42]],"id":36201034},{"spn":4.45,"spf":"NaN","id":36201034},{"spn":1.96,"spf":"NaN","id":38276037}],"con":true,"img":false}]}
{"op":"mcm","clk":"5353663257","pt":1646217314031,"mc":[{"id":"1.195453777","rc":[{"atb":[[3.2,0]],"id":36201034}],"con":true,"img":false}]}
{"op":"mcm","clk":"5353663273","pt":1646217314237,"mc":[{"id":"1.195453777","rc":[{"atb":[[3.1,1.66]],"id":36201034}],"con":true,"img":false}]}
{"op":"mcm","clk":"5353664179","pt":1646217323626,"mc":[{"id":"1.195453777","rc":[{"atl":[[5.9,0]],"id":39594662},{"atb":[[1.46,0],[1.5,75.17]],"id":38276037}],"con":true,"img":false}]}
{"op":"mcm","clk":"5353664187","pt":1646217323733,"mc":[{"id":"1.195453777","rc":[{"atl":[[6.6,8.89]],"id":39594662}],"con":true,"img":false}]}
{"op":"mcm","clk":"5353664333","pt":1646217325641,"mc":[{"id":"1.195453777","rc":[{"atb":[[1.49,19.18]],"id":38276037}],"con":true,"img":false}]}
{"op":"mcm","clk":"5353664350","pt":1646217325836,"mc":[{"id":"1.195453777","rc":[{"atb":[[2.12,0]],"id":39594662},{"atb":[[1.42,0]],"id":38276037}],"con":true,"img":false}]}
{"op":"mcm","clk":"5353664605","pt":1646217328662,"mc":[{"id":"1.195453777","rc":[{"atb":[[1.18,0],[1.16,0]],"id":36201034},{"atl":[[5,4]],"id":36201034}],"con":true,"img":false}]}
{"op":"mcm","clk":"5353664616","pt":1646217328767,"mc":[{"id":"1.195453777","rc":[{"atb":[[1.16,125]],"id":36201034}],"con":true,"img":false}]}
{"op":"mcm","clk":"5353664629","pt":1646217328828,"mc":[{"id":"1.195453777","rc":[{"atb":[[5.9,0],[6.6,3]],"id":32633412},{"atl":[[4.4,2],[5,0]],"id":36201034},{"atl":[[4.3,0],[4.7,3]],"id":39849129}],"con":true,"img":false}]}
{"op":"mcm","clk":"5353664713","pt":1646217329663,"mc":[{"id":"1.195453777","rc":[{"atb":[[2.12,7.09]],"id":39594662},{"atb":[[1.39,121.54]],"id":38276037}],"con":true,"img":false}]}
{"op":"mcm","clk":"5353664890","pt":1646217331636,"mc":[{"id":"1.195453777","rc":[{"atb":[[1.53,14.18]],"id":38276037}],"con":true,"img":false}]}
{"op":"mcm","clk":"5353664953","pt":1646217332268,"mc":[{"id":"1.195453777","rc":[{"atb":[[1.56,2.16],[1.49,17.01]],"id":38276037}],"con":true,"img":false}]}
{"op":"mcm","clk":"5353665098","pt":1646217333626,"mc":[{"id":"1.195453777","rc":[{"atb":[[2.96,0]],"id":36201034},{"atl":[[5.8,0]],"id":36201034}],"con":true,"img":false}]}
{"op":"mcm","clk":"5353665110","pt":1646217333731,"mc":[{"id":"1.195453777","rc":[{"atb":[[2.86,23.43]],"id":36201034},{"atl":[[6,8.71]],"id":36201034}],"con":true,"img":false}]}
{"op":"mcm","clk":"5353665121","pt":1646217333833,"mc":[{"id":"1.195453777","rc":[{"atl":[[2.58,41.72],[2.56,0]],"id":40659166},{"atb":[[3,33.3],[2.08,0]],"id":38440014},{"atb":[[1.18,111.11]],"id":36201034},{"atl":[[4.3,4],[4.4,0]],"id":36201034}],"con":true,"img":false}]}
{"op":"mcm","clk":"5353665130","pt":1646217333938,"mc":[{"id":"1.195453777","rc":[{"atl":[[6.4,0],[6.2,32.94]],"id":36201034}],"con":true,"img":false}]}
{"op":"mcm","clk":"5353665149","pt":1646217334144,"mc":[{"id":"1.195453777","rc":[{"atl":[[4.3,0]],"id":36201034}],"con":true,"img":false}]}
{"op":"mcm","clk":"5353665193","pt":1646217334662,"mc":[{"id":"1.195453777","rc":[{"atb":[[1.39,0]],"id":38276037}],"con":true,"img":false}]}
{"op":"mcm","clk":"5353665308","pt":1646217335933,"mc":[{"id":"1.195453777","rc":[{"atb":[[3,0],[2.08,33.3]],"id":38440014}],"con":true,"img":false}]}
{"op":"mcm","clk":"5353665529","pt":1646217338236,"mc":[{"id":"1.195453777","rc":[{"atb":[[1.51,7.57]],"id":38276037}],"con":true,"img":false}]}
{"op":"mcm","clk":"5353665832","pt":1646217341281,"mc":[{"id":"1.195453777","rc":[{"atb":[[5.9,2],[6.6,0]],"id":32633412},{"atl":[[4.3,3],[4.7,0]],"id":39849129}],"con":true,"img":false}]}
{"op":"mcm","clk":"5353665844","pt":1646217341339,"mc":[{"id":"1.195453777","rc":[{"atb":[[1.5,0],[1.52,38.46]],"id":40659166},{"atl":[[2.22,0],[2.26,0],[2.24,0],[2.2,0]],"id":40659166},{"atb":[[1.18,0]],"id":36201034},{"atl":[[5,3]],"id":36201034},{"atb":[[1.49,0]],"id":38276037},{"atb":[[1.72,27.78],[1.66,0]],"id":39849129},{"atl":[[4.4,0],[4.5,0],[4.6,0]],"id":39849129}],"con":true,"img":false}]}
{"op":"mcm","clk":"5353665854","pt":1646217341440,"mc":[{"id":"1.195453777","rc":[{"atb":[[1.77,3]],"id":39849129},{"atl":[[4.3,0]],"id":39849129}],"con":true,"img":false}]}
{"op":"mcm","clk":"5353665865","pt":1646217341545,"mc":[{"id":"1.195453777","rc":[{"atl":[[7.4,6.23],[7.6,9.25]],"id":39849129}],"con":true,"img":false}]}
{"op":"mcm","clk":"5353665876","pt":1646217341645,"mc":[{"id":"1.195453777","rc":[{"atl":[[4.4,3]],"id":36201034},{"atl":[[7.8,7.35]],"id":39849129}],"con":true,"img":false}]}
{"op":"mcm","clk":"5353665884","pt":1646217341750,"mc":[{"id":"1.195453777","rc":[{"atl":[[5,0]],"id":36201034}],"con":true,"img":false}]}
{"op":"mcm","clk":"5353665936","pt":1646217342379,"mc":[{"id":"1.195453777","rc":[{"atb":[[1.5,40],[1.52,0]],"id":40659166},{"atl":[[2.26,4]],"id":40659166},{"atb":[[1.18,111.11]],"id":36201034},{"atl":[[4.4,0]],"id":36201034},{"atb":[[1.72,0],[1.77,0],[1.66,30.3]],"id":39849129},{"atl":[[5.6,2],[7.4,9.35],[7.6,6.22]],"id":39849129}],"con":true,"img":false}]}
{"op":"mcm","clk":"5353665957","pt":1646217342543,"mc":[{"id":"1.195453777","rc":[{"atl":[[2.24,3]],"id":40659166},{"atl":[[4.8,2],[5.6,0]],"id":39849129}],"con":true,"img":false}]}
{"op":"mcm","clk":"5353665964","pt":1646217342646,"mc":[{"id":"1.195453777","rc":[{"atl":[[2.26,0]],"id":40659166},{"atb":[[3.55,7.84],[3.5,0]],"id":38440014},{"atl":[[5.1,0],[5.2,4.76]],"id":38276037},{"atb":[[1.62,120.97],[1.71,78.13],[1.66,0],[1.75,26.67]],"id":39849129}],"con":true,"img":false}]}
{"op":"mcm","clk":"5353665976","pt":1646217342747,"mc":[{"id":"1.195453777","rc":[{"atl":[[2.24,0],[2.06,4]],"id":40659166},{"atl":[[4.7,2]],"id":39849129}],"con":true,"img":false}]}
{"op":"mcm","clk":"5353665995","pt":1646217342957,"mc":[{"id":"1.195453777","rc":[{"atb":[[6.4,0],[5.9,0],[6.2,0],[6,0]],"id":32633412},{"atl":[[8.4,2.7],[8.6,0]],"id":32633412},{"atb":[[1.5,0],[1.52,38.46]],"id":40659166},{"atl":[[2.06,0]],"id":40659166},{"atb":[[1.18,0]],"id":36201034},{"atl":[[4.7,3]],"id":36201034},{"atb":[[1.37,0],[1.39,51.28]],"id":38276037},{"atb":[[1.81,24.69],[1.75,0]],"id":39849129},{"atl":[[4.8,0],[4.7,0]],"id":39849129}],"con":true,"img":false}]}
{"op":"mcm","clk":"5353666007","pt":1646217343061,"mc":[{"id":"1.195453777","rc":[{"atl":[[2.6,20.06],[2.58,29.06]],"id":40659166}],"con":true,"img":false}]}
{"op":"mcm","clk":"5353666018","pt":1646217343164,"mc":[{"id":"1.195453777","rc":[{"atl":[[4.1,3],[4.7,0]],"id":36201034}],"con":true,"img":false}]}
{"op":"mcm","clk":"5353666061","pt":1646217343578,"mc":[{"id":"1.195453777","rc":[{"atl":[[4,4]],"id":36201034}],"con":true,"img":false}]}
{"op":"mcm","clk":"5353666073","pt":1646217343634,"mc":[{"id":"1.195453777","rc":[{"atl":[[8.8,0]],"id":32633412},{"atb":[[1.93,130.09]],"id":39594662},{"atl":[[2.58,0]],"id":40659166}],"con":true,"img":false}]}
{"op":"mcm","clk":"5353666077","pt":1646217343740,"mc":[{"id":"1.195453777","rc":[{"atl":[[9.2,5.44]],"id":32633412},{"atb":[[1.95,44.04]],"id":39594662},{"atl":[[2.62,29.06]],"id":40659166},{"atl":[[3.95,3]],"id":36201034}],"con":true,"img":false}]}
{"op":"mcm","clk":"5353666107","pt":1646217344048,"mc":[{"id":"1.195453777","rc":[{"atb":[[4.1,1.66]],"id":32633412},{"atb":[[3,4.16]],"id":36201034}],"con":true,"img":false}]}
{"op":"mcm","clk":"5353666163","pt":1646217344773,"mc":[{"id":"1.195453777","rc":[{"atb":[[3.1,3.33]],"id":39849129}],"con":true,"img":false}]}
{"op":"mcm","clk":"5353666339","pt":1646217346576,"mc":[{"id":"1.195453777","rc":[{"atb":[[3.05,0]],"id":36201034}],"con":true,"img":false}]}
{"op":"mcm","clk":"5353666366","pt":1646217346865,"mc":[{"id":"1.195453777","rc":[{"atl":[[3.9,2]],"id":36201034}],"con":true,"img":false}]}
{"op":"mcm","clk":"5353666385","pt":1646217347075,"mc":[{"id":"1.195453777","rc":[{"atl":[[3.85,3],[4,0],[4.1,0]],"id":36201034}],"con":true,"img":false}]}
{"op":"mcm","clk":"5353666593","pt":1646217349653,"mc":[{"id":"1.195453777","rc":[{"atb":[[3,7.92]],"id":39849129}],"con":true,"img":false}]}
{"op":"mcm","clk":"5353666813","pt":1646217352059,"mc":[{"id":"1.195453777","rc":[{"atl":[[3.8,4]],"id":36201034}],"con":true,"img":false}]}
{"op":"mcm","clk":"5353666840","pt":1646217352261,"mc":[{"id":"1.195453777","rc":[{"atl":[[3.75,2]],"id":36201034}],"con":true,"img":false}]}
{"op":"mcm","clk":"5353666850","pt":1646217352365,"mc":[{"id":"1.195453777","rc":[{"atb":[[1.1,250]],"id":36201034},{"atl":[[3.95,0]],"id":36201034}],"con":true,"img":false}]}
{"op":"mcm","clk":"5353666916","pt":1646217352993,"mc":[{"id":"1.195453777","rc":[{"atl":[[2.64,0]],"id":40659166},{"atb":[[1.37,135.14]],"id":38276037},{"atl":[[5.4,11.36]],"id":38276037},{"atb":[[1.79,63.29]],"id":39849129}],"con":true,"img":false}]}
{"op":"mcm","clk":"5353666923","pt":1646217353051,"mc":[{"id":"1.195453777","rc":[{"atb":[[1.5,100]],"id":40659166},{"atl":[[2.64,30.49]],"id":40659166}],"con":true,"img":false}]}
{"op":"mcm","clk":"5353666972","pt":1646217353572,"mc":[{"id":"1.195453777","rc":[{"atb":[[1.51,0]],"id":40659166}],"con":true,"img":false}]}
{"op":"mcm","clk":"5353666983","pt":1646217353679,"mc":[{"id":"1.195453777","rc":[{"atb":[[1.53,96.88]],"id":40659166}],"con":true,"img":false}]}
{"op":"mcm","clk":"5353667153","pt":1646217355773,"mc":[{"id":"1.195453777","rc":[{"atb":[[1.54,15.43]],"id":40659166}],"con":true,"img":false}]}
{"op":"mcm","clk":"5353667205","pt":1646217356297,"mc":[{"id":"1.195453777","rc":[{"atb":[[1.53,29.91]],"id":38276037}],"con":true,"img":false}]}
{"op":"mcm","clk":"5353667236","pt":1646217356577,"mc":[{"id":"1.195453777","rc":[{"atb":[[1.54,0]],"id":40659166},{"atb":[[3,0]],"id":36201034}],"con":true,"img":false}]}
{"op":"mcm","clk":"5353667336","pt":1646217357514,"mc":[{"id":"1.195453777","rc":[{"atb":[[1.44,0]],"id":40659166},{"atb":[[1.31,0]],"id":38276037},{"atl":[[5.3,0],[5.5,0],[5.7,0]],"id":38276037},{"atb":[[1.64,0],[1.6,0],[1.62,0]],"id":39849129}],"con":true,"img":false}]}
{"op":"mcm","clk":"5353667493","pt":1646217359135,"mc":[{"id":"1.195453777","rc":[{"atb":[[3.1,0]],"id":36201034},{"atb":[[3.05,0]],"id":39849129}],"con":true,"img":false}]}
{"op":"mcm","clk":"5353667508","pt":1646217359289,"mc":[{"id":"1.195453777","rc":[{"atb":[[2.96,1.66]],"id":36201034},{"atb":[[3.15,1.66]],"id":39849129}],"con":true,"img":false}]}
{"op":"mcm","clk":"5353667560","pt":1646217359888,"mc":[{"id":"1.195453777","rc":[{"atb":[[1.55,0]],"id":40659166}],"con":true,"img":false}]}
{"op":"mcm","clk":"5353667716","pt":1646217361414,"mc":[{"id":"1.195453777","rc":[{"atb":[[3.1,0]],"id":39849129}],"con":true,"img":false}]}
{"op":"mcm","clk":"5353667742","pt":1646217361626,"mc":[{"id":"1.195453777","rc":[{"atb":[[3,19.38],[2.94,64.6],[3.05,2.5]],"id":39849129},{"atl":[[7.2,11.46],[7.8,35.77]],"id":39849129}],"con":true,"img":false}]}
{"op":"mcm","clk":"5353667756","pt":1646217361683,"mc":[{"id":"1.195453777","rc":[{"atb":[[1.57,30.79]],"id":40659166}],"con":true,"img":false}]}
{"op":"mcm","clk":"5353667765","pt":1646217361787,"mc":[{"id":"1.195453777","rc":[{"atb":[[4,15.44],[3.85,43.1]],"id":32633412},{"atl":[[9.2,27.32],[8.2,8.77],[9.4,11.43]],"id":32633412},{"atb":[[2.32,10],[2.26,24.05],[2.1,38.41],[2.48,2.5],[2.4,5]],"id":39594662},{"atl":[[6.2,5],[5.2,10.36],[5.7,2.5],[6.6,32.89],[7,10]],"id":39594662},{"atb":[[1.64,10],[1.68,5],[1.72,2.5],[1.57,75.45],[1.52,127.78]],"id":40659166},{"atl":[[2.6,64.72],[2.64,116.16]],"id":40659166},{"atb":[[10,10],[12,5],[14,2.5],[19.5,6.8],[9.8,15.03]],"id":38440014},{"atl":[[130,4.45],[65,1.25],[75,2.5]],"id":38440014},{"atb":[[2.86,33.43],[2.84,106.91],[2.94,36.18],[3.05,2.5]],"id":36201034},{"atb":[[1.51,31.54],[1.53,32.41],[1.56,14.14]],"id":38276037},{"atl":[[2.44,20.38],[2.84,47.12],[2.68,2.5],[2.76,5]],"id":38276037}],"con":true,"img":false}]}
{"op":"mcm","clk":"5353667789","pt":1646217362002,"mc":[{"id":"1.195453777","rc":[{"atb":[[2.44,5],[2.26,9.64]],"id":39594662},{"atb":[[1.57,60.01],[1.66,75.46]],"id":40659166}],"con":true,"img":false}]}
{"op":"mcm","clk":"5353667888","pt":1646217363002,"mc":[{"id":"1.195453777","rc":[{"atb":[[1.35,214.29]],"id":38276037},{"atl":[[5.6,16.3]],"id":38276037},{"atb":[[1.77,97.4]],"id":39849129}],"con":true,"img":false}]}
{"op":"mcm","clk":"5353667899","pt":1646217363108,"mc":[{"id":"1.195453777","rc":[{"atb":[[1.48,156.25],[1.54,52.82]],"id":40659166},{"atl":[[2.68,44.64]],"id":40659166}],"con":true,"img":false}]}
{"op":"mcm","clk":"5353667949","pt":1646217363620,"mc":[{"id":"1.195453777","rc":[{"atb":[[1.45,0],[1.38,176.57]],"id":40659166},{"atl":[[3.55,0]],"id":38276037},{"atl":[[7.6,0]],"id":39849129}],"con":true,"img":false}]}
{"op":"mcm","clk":"5353667960","pt":1646217363678,"mc":[{"id":"1.195453777","rc":[{"atl":[[3.9,20.88]],"id":38276037},{"atl":[[7.2,17.68]],"id":39849129}],"con":true,"img":false}]}
{"op":"mcm","clk":"5353667973","pt":1646217363788,"mc":[{"id":"1.195453777","rc":[{"atl":[[7.4,3.12],[7.8,50.48]],"id":39849129}],"con":true,"img":false}]}
{"op":"mcm","clk":"5353668079","pt":1646217364774,"mc":[{"id":"1.195453777","rc":[{"atb":[[2.12,0]],"id":39594662},{"atb":[[3.2,3.33]],"id":39849129}],"con":true,"img":false}]}
{"op":"mcm","clk":"5353668091","pt":1646217364880,"mc":[{"id":"1.195453777","rc":[{"atb":[[1.57,46.82]],"id":40659166}],"con":true,"img":false}]}
{"op":"mcm","clk":"5353668292","pt":1646217366706,"mc":[{"id":"1.195453777","rc":[{"atb":[[1.54,0]],"id":40659166}],"con":true,"img":false}]}
{"op":"mcm","clk":"5353668338","pt":1646217367078,"mc":[{"id":"1.195453777","rc":[{"atb":[[2.44,0],[2.4,12.5]],"id":39594662}],"con":true,"img":false}]}
{"op":"mcm","clk":"5353668366","pt":1646217367284,"mc":[{"id":"1.195453777","rc":[{"atb":[[2.32,25],[2.4,5]],"id":39594662}],"con":true,"img":false}]}
{"op":"mcm","clk":"5353668467","pt":1646217368216,"mc":[{"id":"1.195453777","rc":[{"atb":[[2.5,5]],"id":39594662}],"con":true,"img":false}]}
{"op":"mcm","clk":"5353668519","pt":1646217368586,"mc":[{"id":"1.195453777","rc":[{"atl":[[14.5,0],[23,11.07]],"id":32633412},{"atl":[[8.2,34.96],[7.2,0]],"id":39594662},{"atl":[[4.8,45.16],[3.8,0]],"id":40659166},{"atb":[[12.5,9.6],[15.5,0],[19.5,4.08]],"id":38440014},{"atl":[[130,1.73]],"id":38440014},{"atl":[[13.5,17.3],[9.8,0]],"id":36201034},{"atb":[[1.34,77.66],[1.38,0]],"id":38276037},{"atb":[[2.76,0],[2.42,49.73]],"id":39849129},{"atl":[[16,13.39],[12.5,0]],"id":39849129}],"con":true,"img":false}]}
{"op":"mcm","clk":"5353668531","pt":1646217368688,"mc":[{"id":"1.195453777","rc":[{"atb":[[16,2.72],[19.5,0]],"id":38440014},{"atl":[[380,2.72]],"id":38440014}],"con":true,"img":false}]}
{"op":"mcm","clk":"5353668541","pt":1646217368792,"mc":[{"id":"1.195453777","rc":[{"atb":[[2.26,7.48]],"id":39594662},{"atb":[[14.5,3.75]],"id":38440014}],"con":true,"img":false}]}
{"op":"mcm","clk":"5353668556","pt":1646217368896,"mc":[{"id":"1.195453777","rc":[{"atb":[[2.46,2.16]],"id":39594662}],"con":true,"img":false}]}
{"op":"mcm","clk":"5353668679","pt":1646217369988,"mc":[{"id":"1.195453777","rc":[{"atb":[[1.69,7.51]],"id":40659166}],"con":true,"img":false}]}
{"op":"mcm","clk":"5353668751","pt":1646217370681,"mc":[{"id":"1.195453777","rc":[{"atb":[[1.7,10.74]],"id":40659166}],"con":true,"img":false}]}
{"op":"mcm","clk":"5353668871","pt":1646217372081,"mc":[{"id":"1.195453777","rc":[{"spn":6.15,"spf":"NaN","id":32633412},{"spn":3.85,"spf":"NaN","id":39594662},{"spn":2.16,"spf":"NaN","id":40659166},{"spn":40.5,"spf":"NaN","id":38440014},{"spn":3.4,"spf":"NaN","id":36201034},{"spn":2.0,"spf":"NaN","id":38276037},{"atl":[[7.8,35.77],[7,16.67]],"id":39849129},{"spn":5.1,"spf":"NaN","id":39849129}],"con":true,"img":false}]}
{"op":"mcm","clk":"5353668947","pt":1646217373015,"mc":[{"id":"1.195453777","rc":[{"atb":[[1.33,250]],"id":38276037},{"atl":[[5.8,26.04]],"id":38276037},{"atb":[[1.75,166.67]],"id":39849129}],"con":true,"img":false}]}
{"op":"mcm","clk":"5353668959","pt":1646217373083,"mc":[{"id":"1.195453777","rc":[{"atb":[[1.46,250]],"id":40659166},{"atl":[[2.72,72.67]],"id":40659166}],"con":true,"img":false}]}
{"op":"mcm","clk":"5353669018","pt":1646217373596,"mc":[{"id":"1.195453777","rc":[{"atb":[[1.69,0]],"id":40659166},{"atb":[[1.5,0]],"id":38276037},{"atl":[[4.5,54.74],[3.9,0]],"id":38276037},{"atl":[[7.2,11.46]],"id":39849129}],"con":true,"img":false}]}
{"op":"mcm","clk":"5353669028","pt":1646217373697,"mc":[{"id":"1.195453777","rc":[{"atb":[[1.42,75.17]],"id":38276037},{"atl":[[7.6,6.22]],"id":39849129}],"con":true,"img":false}]}
{"op":"mcm","clk":"5353669065","pt":1646217374116,"mc":[{"id":"1.195453777","rc":[{"atb":[[2.28,0]],"id":39594662},{"atb":[[2.96,0]],"id":36201034},{"atb":[[3.15,0]],"id":39849129}],"con":true,"img":false}]}
{"op":"mcm","clk":"5353669083","pt":1646217374275,"mc":[{"id":"1.195453777","rc":[{"atb":[[2.52,1.66]],"id":39594662},{"atb":[[3.1,1.66]],"id":36201034},{"atb":[[3.25,1.66]],"id":39849129}],"con":true,"img":false}]}
{"op":"mcm","clk":"5353669223","pt":1646217375590,"mc":[{"id":"1.195453777","rc":[{"atb":[[2.32,10],[2.44,7.48]],"id":39594662}],"con":true,"img":false}]}
{"op":"mcm","clk":"5353669351","pt":1646217376691,"mc":[{"id":"1.195453777","rc":[{"atb":[[1.53,18.23]],"id":38276037}],"con":true,"img":false}]}
{"op":"mcm","clk":"5353669403","pt":1646217377100,"mc":[{"id":"1.195453777","rc":[{"atb":[[2.5,0]],"id":39594662},{"atb":[[1.73,5]],"id":40659166},{"atb":[[3.2,0]],"id":39849129}],"con":true,"img":false}]}
{"op":"mcm","clk":"5353669416","pt":1646217377206,"mc":[{"id":"1.195453777","rc":[{"atl":[[7.4,18.74],[7,0]],"id":39849129}],"con":true,"img":false}]}
{"op":"mcm","clk":"5353669617","pt":1646217379138,"mc":[{"id":"1.195453777","rc":[{"atb":[[2.94,36.18],[3.05,15.77],[2.96,63.57]],"id":39849129},{"atl":[[7.6,37.6],[7.8,7.35]],"id":39849129}],"con":true,"img":false}]}
{"op":"mcm","clk":"5353669643","pt":1646217379298,"mc":[{"id":"1.195453777","rc":[{"atl":[[9,32.76],[9.2,5.44]],"id":32633412},{"atb":[[2.44,21.24],[2.1,14.41],[2.48,6.25]],"id":39594662},{"atl":[[6.2,18.76],[6.6,8.89]],"id":39594662},{"atb":[[1.73,34.85],[1.7,70.44],[1.52,38.46]],"id":40659166},{"atb":[[14,10],[16.5,3.75],[9.8,6.87]],"id":38440014},{"atl":[[130,0],[75,5.67]],"id":38440014},{"atb":[[2.86,45.69],[2.84,65.75]],"id":36201034},{"atl":[[2.84,23.15],[2.68,51.07]],"id":38276037},{"atb":[[3,7.92]],"id":39849129}],"con":true,"img":false}]}
{"op":"mcm","clk":"5353669659","pt":1646217379507,"mc":[{"id":"1.195453777","rc":[{"atb":[[2.26,0]],"id":39594662},{"atb":[[1.57,2.16]],"id":40659166},{"atb":[[14.5,0]],"id":38440014}],"con":true,"img":false}]}
{"op":"mcm","clk":"5353669681","pt":1646217379715,"mc":[{"id":"1.195453777","rc":[{"atb":[[1.7,59.7]],"id":40659166},{"atb":[[3,4.16]],"id":39849129}],"con":true,"img":false}]}
{"op":"mcm","clk":"5353669744","pt":1646217380291,"mc":[{"id":"1.195453777","rc":[{"atb":[[2.54,3.33]],"id":39594662},{"atb":[[1.76,2.16],[1.57,0]],"id":40659166},{"atb":[[3.1,5]],"id":39849129}],"con":true,"img":false}]}
{"op":"mcm","clk":"5353669770","pt":1646217380601,"mc":[{"id":"1.195453777","rc":[{"atb":[[3.9,17.24]],"id":32633412},{"atb":[[1.67,70]],"id":39594662},{"atl":[[8.2,0]],"id":39594662},{"atb":[[1.53,0]],"id":40659166},{"atl":[[2.62,0]],"id":40659166},{"atl":[[110,0]],"id":38440014},{"atl":[[3.35,0]],"id":38276037}],"con":true,"img":false}]}
{"op":"mcm","clk":"5353669780","pt":1646217380707,"mc":[{"id":"1.195453777","rc":[{"atb":[[4.1,17.52]],"id":32633412},{"atl":[[9.4,34.96]],"id":39594662},{"atb":[[1.58,96.88]],"id":40659166},{"atl":[[2.64,30.49],[2.58,29.06],[2.68,134.08]],"id":40659166},{"atl":[[85,0.39]],"id":38440014},{"atl":[[2.82,23.18]],"id":38276037}],"con":true,"img":false}]}
{"op":"mcm","clk":"5353669798","pt":1646217380913,"mc":[{"id":"1.195453777","rc":[{"atb":[[3.85,21.22],[4.1,39.03],[3.9,66.26]],"id":32633412},{"atl":[[2.58,73.72],[2.68,44.64]],"id":40659166}],"con":true,"img":false}]}
{"op":"mcm","clk":"5353669808","pt":1646217381019,"mc":[{"id":"1.195453777","rc":[{"atb":[[4,6.67]],"id":32633412},{"atl":[[2.6,20.06]],"id":40659166}],"con":true,"img":false}]}
{"op":"mcm","clk":"5353670035","pt":1646217383324,"mc":[{"id":"1.195453777","rc":[{"atb":[[1.45,16.7]],"id":38276037}],"con":true,"img":false}]}
{"op":"mcm","clk":"5353670125","pt":1646217384006,"mc":[{"id":"1.195453777","rc":[{"atb":[[1.73,29.85]],"id":40659166}],"con":true,"img":false}]}
{"op":"mcm","clk":"5353670310","pt":1646217385724,"mc":[{"id":"1.195453777","rc":[{"atb":[[1.74,10.15]],"id":40659166},{"atb":[[3.05,19.43]],"id":39849129}],"con":true,"img":false}]}
{"op":"mcm","clk":"5353670506","pt":1646217387518,"mc":[{"id":"1.195453777","rc":[{"atb":[[1.77,4.33]],"id":40659166}],"con":true,"img":false}]}
{"op":"mcm","clk":"5353670660","pt":1646217389024,"mc":[{"id":"1.195453777","rc":[{"atb":[[2.52,0]],"id":39594662},{"atb":[[3.25,0]],"id":39849129}],"con":true,"img":false}]}
{"op":"mcm","clk":"5353670683","pt":1646217389235,"mc":[{"id":"1.195453777","rc":[{"atb":[[2.56,1.66]],"id":39594662},{"atb":[[3.15,1.66]],"id":39849129}],"con":true,"img":false}]}
{"op":"mcm","clk":"5353670837","pt":1646217390907,"mc":[{"id":"1.195453777","rc":[{"atb":[[2.54,5.5],[2.46,0]],"id":39594662}],"con":true,"img":false}]}
{"op":"mcm","clk":"5353670999","pt":1646217392425,"mc":[{"id":"1.195453777","rc":[{"atb":[[1.58,0]],"id":40659166},{"atb":[[2.86,22.26]],"id":36201034},{"atl":[[7.6,31.38]],"id":39849129}],"con":true,"img":false}]}
{"op":"mcm","clk":"5353671010","pt":1646217392529,"mc":[{"id":"1.195453777","rc":[{"atb":[[2.54,2.16]],"id":39594662},{"atb":[[1.54,96.88]],"id":40659166},{"atb":[[2.58,23.43]],"id":36201034},{"atl":[[7.2,17.68]],"id":39849129}],"con":true,"img":false}]}
{"op":"mcm","clk":"5353671022","pt":1646217392634,"mc":[{"id":"1.195453777","rc":[{"atl":[[7.4,3.12],[7.6,46.53]],"id":39849129}],"con":true,"img":false}]}
{"op":"mcm","clk":"5353671367","pt":1646217395915,"mc":[{"id":"1.195453777","rc":[{"atb":[[2.5,5]],"id":39594662}],"con":true,"img":false}]}
{"op":"mcm","clk":"5353671408","pt":1646217396326,"mc":[{"id":"1.195453777","rc":[{"atb":[[3.1,22.03],[3,40.72],[2.96,18.55]],"id":39849129}],"con":true,"img":false}]}
{"op":"mcm","clk":"5353671420","pt":1646217396536,"mc":[{"id":"1.195453777","rc":[{"atb":[[2.54,7.79],[2.44,7.48],[2.48,23.14]],"id":39594662},{"atb":[[1.7,0],[1.74,55.48],[1.77,26.99]],"id":40659166},{"atb":[[3.05,6.16]],"id":39849129}],"con":true,"img":false}]}
{"op":"mcm","clk":"5353671442","pt":1646217396747,"mc":[{"id":"1.195453777","rc":[{"atb":[[2.48,19.39]],"id":39594662},{"atb":[[1.73,0]],"id":40659166}],"con":true,"img":false}]}
{"op":"mcm","clk":"5353671530","pt":1646217397838,"mc":[{"id":"1.195453777","rc":[{"atb":[[1.74,45.33]],"id":40659166}],"con":true,"img":false}]}
{"op":"mcm","clk":"5353671537","pt":1646217397945,"mc":[{"id":"1.195453777","rc":[{"atl":[[2.64,116.71]],"id":40659166}],"con":true,"img":false}]}
{"op":"mcm","clk":"5353671795","pt":1646217400649,"mc":[{"id":"1.195453777","rc":[{"atl":[[7.6,31.38],[7,16.67]],"id":39849129}],"con":true,"img":false}]}
{"op":"mcm","clk":"5353671811","pt":1646217400755,"mc":[{"id":"1.195453777","rc":[{"atl":[[7,23.64]],"id":39849129}],"con":true,"img":false}]}
{"op":"mcm","clk":"5353671821","pt":1646217400863,"mc":[{"id":"1.195453777","rc":[{"atl":[[7.4,37.44],[7.6,0]],"id":39849129}],"con":true,"img":false}]}
{"op":"mcm","clk":"5353671829","pt":1646217400923,"mc":[{"id":"1.195453777","rc":[{"atl":[[7.2,6.22]],"id":39849129}],"con":true,"img":false}]}
{"op":"mcm","clk":"5353671935","pt":1646217402012,"mc":[{"id":"1.195453777","rc":[{"atb":[[1.53,2.5]],"id":38276037},{"atb":[[3,36.56]],"id":39849129}],"con":true,"img":false}]}
{"op":"mcm","clk":"5353672102","pt":1646217403634,"mc":[{"id":"1.195453777","rc":[{"atb":[[4.1,23.17]],"id":32633412},{"atl":[[9.2,0]],"id":32633412},{"atl":[[6.6,0]],"id":39594662},{"atb":[[1.47,56.1],[1.38,0]],"id":40659166},{"atl":[[2.58,44.66]],"id":40659166},{"atb":[[16,0]],"id":38440014},{"atl":[[2.82,0]],"id":38276037},{"atl":[[7.2,0]],"id":39849129}],"con":true,"img":false}]}
{"op":"mcm","clk":"5353672111","pt":1646217403737,"mc":[{"id":"1.195453777","rc":[{"atb":[[4.2,15.85]],"id":32633412},{"atl":[[8.8,5.44]],"id":32633412},{"atl":[[6,8.89]],"id":39594662},{"atb":[[1.78,9.63]],"id":40659166},{"atl":[[2.56,29.06]],"id":40659166},{"atb":[[17,2.72]],"id":38440014},{"atl":[[2.66,23.18]],"id":38276037},{"atl":[[7.4,43.66]],"id":39849129}],"con":true,"img":false}]}
{"op":"mcm","clk":"5353672123","pt":1646217403842,"mc":[{"id":"1.195453777","rc":[{"atb":[[12.5,23.73],[14,2.5],[16.5,0]],"id":38440014}],"con":true,"img":false}]}
{"op":"mcm","clk":"5353672135","pt":1646217403946,"mc":[{"id":"1.195453777","rc":[{"atb":[[4,29.83],[3.9,17.24],[4.2,27.43]],"id":32633412},{"atl":[[9,6.25],[8.8,28.6]],"id":32633412},{"atl":[[6.2,5],[6,36.44]],"id":39594662},{"atl":[[2.56,64.35]],"id":40659166},{"atb":[[17.5,4.85]],"id":38440014},{"atl":[[2.66,74.98],[2.68,2.5]],"id":38276037}],"con":true,"img":false}]}
{"op":"mcm","clk":"5353672146","pt":1646217404051,"mc":[{"id":"1.195453777","rc":[{"atb":[[12.5,9.6]],"id":38440014}],"con":true,"img":false}]}
{"op":"mcm","clk":"5353672163","pt":1646217404116,"mc":[{"id":"1.195453777","rc":[{"atb":[[4.1,1.66]],"id":32633412},{"atl":[[2.58,0]],"id":40659166}],"con":true,"img":false}]}
{"op":"mcm","clk":"5353672338","pt":1646217405730,"mc":[{"id":"1.195453777","rc":[{"atl":[[7.2,16.13]],"id":39849129}],"con":true,"img":false}]}
{"op":"mcm","clk":"5353672351","pt":1646217405834,"mc":[{"id":"1.195453777","rc":[{"atl":[[7,6.96]],"id":39849129}],"con":true,"img":false}]}
{"op":"mcm","clk":"5353672414","pt":1646217406356,"mc":[{"id":"1.195453777","rc":[{"atb":[[1.77,22.66]],"id":40659166}],"con":true,"img":false}]}
{"op":"mcm","clk":"5353672960","pt":1646217411328,"mc":[{"id":"1.195453777","rc":[{"atb":[[1.79,19.27]],"id":40659166}],"con":true,"img":false}]}
{"op":"mcm","clk":"5353673010","pt":1646217411842,"mc":[{"id":"1.195453777","rc":[{"atb":[[3.9,84.24]],"id":32633412}],"con":true,"img":false}]}
{"op":"mcm","clk":"5353673027","pt":1646217411949,"mc":[{"id":"1.195453777","rc":[{"atb":[[4,6.67]],"id":32633412}],"con":true,"img":false}]}
{"op":"mcm","clk":"5353673052","pt":1646217412163,"mc":[{"id":"1.195453777","rc":[{"atb":[[1.76,0],[1.82,2.16]],"id":40659166}],"con":true,"img":false}]}
{"op":"mcm","clk":"5353673183","pt":1646217413330,"mc":[{"id":"1.195453777","rc":[{"atb":[[1.78,68.64],[1.82,31.67],[1.74,0]],"id":40659166}],"con":true,"img":false}]}
{"op":"mcm","clk":"5353673214","pt":1646217413639,"mc":[{"id":"1.195453777","rc":[{"atb":[[1.77,0]],"id":40659166}],"con":true,"img":false}]}
{"op":"mcm","clk":"5353673223","pt":1646217413744,"mc":[{"id":"1.195453777","rc":[{"atb":[[4.2,11.58]],"id":32633412},{"atb":[[2.96,0]],"id":39849129}],"con":true,"img":false}]}
{"op":"mcm","clk":"5353673234","pt":1646217413844,"mc":[{"id":"1.195453777","rc":[{"atb":[[3.95,15.85]],"id":32633412},{"atb":[[3.15,20.21]],"id":39849129}],"con":true,"img":false}]}
{"op":"mcm","clk":"5353673244","pt":1646217413949,"mc":[{"id":"1.195453777","rc":[{"atb":[[3.05,60.68],[3.15,47.47]],"id":39849129}],"con":true,"img":false}]}
{"op":"mcm","clk":"5353673256","pt":1646217414057,"mc":[{"id":"1.195453777","rc":[{"atb":[[3.1,5],[3,0]],"id":39849129}],"con":true,"img":false}]}
{"op":"mcm","clk":"5353673353","pt":1646217415046,"mc":[{"id":"1.195453777","rc":[{"atb":[[1.79,0]],"id":40659166}],"con":true,"img":false}]}
{"op":"mcm","clk":"5353673422","pt":1646217415723,"mc":[{"id":"1.195453777","rc":[{"atb":[[1.78,59.01]],"id":40659166},{"atb":[[3.05,57.02]],"id":39849129}],"con":true,"img":false}]}
{"op":"mcm","clk":"5353673614","pt":1646217417457,"mc":[{"id":"1.195453777","rc":[{"atb":[[1.45,35.22]],"id":38276037}],"con":true,"img":false}]}
{"op":"mcm","clk":"5353673748","pt":1646217418467,"mc":[{"id":"1.195453777","rc":[{"atb":[[1.73,64.93]],"id":40659166}],"con":true,"img":false}]}
{"op":"mcm","clk":"5353673815","pt":1646217419054,"mc":[{"id":"1.195453777","rc":[{"atb":[[4.1,0]],"id":32633412}],"con":true,"img":false}]}
{"op":"mcm","clk":"5353673840","pt":1646217419267,"mc":[{"id":"1.195453777","rc":[{"atb":[[4.3,1.66]],"id":32633412}],"con":true,"img":false}]}
{"op":"mcm","clk":"5353673867","pt":1646217419431,"mc":[{"id":"1.195453777","rc":[{"atb":[[4.2,0]],"id":32633412}],"con":true,"img":false}]}
{"op":"mcm","clk":"5353673887","pt":1646217419631,"mc":[{"id":"1.195453777","rc":[{"atb":[[4.2,11.58]],"id":32633412}],"con":true,"img":false}]}
{"op":"mcm","clk":"5353673960","pt":1646217420469,"mc":[{"id":"1.195453777","rc":[{"atb":[[14,10.33]],"id":38440014}],"con":true,"img":false}]}
{"op":"mcm","clk":"5353673979","pt":1646217420637,"mc":[{"id":"1.195453777","rc":[{"atb":[[3.95,48.88],[3.9,17.24]],"id":32633412}],"con":true,"img":false}]}
{"op":"mcm","clk":"5353674022","pt":1646217421157,"mc":[{"id":"1.195453777","rc":[{"atb":[[1.73,220.18],[1.78,0]],"id":40659166}],"con":true,"img":false}]}
{"op":"mcm","clk":"5353674094","pt":1646217421844,"mc":[{"id":"1.195453777","rc":[{"atb":[[3.2,3.42]],"id":39849129}],"con":true,"img":false}]}
{"op":"mcm","clk":"5353674260","pt":1646217423634,"mc":[{"id":"1.195453777","rc":[{"atl":[[7.4,37.44]],"id":39849129}],"con":true,"img":false}]}
{"op":"mcm","clk":"5353674269","pt":1646217423742,"mc":[{"id":"1.195453777","rc":[{"atl":[[7.2,0],[7.4,53.06],[7,13.19]],"id":39849129}],"con":true,"img":false}]}
{"op":"mcm","clk":"5353674279","pt":1646217423850,"mc":[{"id":"1.195453777","rc":[{"atl":[[7,26.39]],"id":39849129}],"con":true,"img":false}]}
{"op":"mcm","clk":"5353674287","pt":1646217423949,"mc":[{"id":"1.195453777","rc":[{"atl":[[7.4,3.12],[7.8,38.17]],"id":39849129}],"con":true,"img":false}]}
{"op":"mcm","clk":"5353674381","pt":1646217424965,"mc":[{"id":"1.195453777","rc":[{"atb":[[3.1,0]],"id":39849129}],"con":true,"img":false}]}
{"op":"mcm","clk":"5353674481","pt":1646217425957,"mc":[{"id":"1.195453777","rc":[{"atb":[[2.18,33.3]],"id":38440014}],"con":true,"img":false}]}
{"op":"mcm","clk":"5353674491","pt":1646217426074,"mc":[{"id":"1.195453777","rc":[{"atb":[[2.08,0]],"id":38440014}],"con":true,"img":false}]}
{"op":"mcm","clk":"5353674661","pt":1646217427781,"mc":[{"id":"1.195453777","rc":[{"atl":[[9.4,8.93]],"id":32633412},{"atb":[[2.32,0],[2.48,16.89],[2.4,0],[2.52,2.5]],"id":39594662},{"atl":[[2.84,13.15],[2.76,0],[2.66,77.48],[2.68,0]],"id":38276037}],"con":true,"img":false}]}
{"op":"mcm","clk":"5353674671","pt":1646217427843,"mc":[{"id":"1.195453777","rc":[{"atb":[[1.77,9.76]],"id":40659166}],"con":true,"img":false}]}
{"op":"mcm","clk":"5353674683","pt":1646217427947,"mc":[{"id":"1.195453777","rc":[{"atb":[[2.5,26.72],[2.48,0]],"id":39594662}],"con":true,"img":false}]}
{"op":"mcm","clk":"5353674779","pt":1646217428744,"mc":[{"id":"1.195453777","rc":[{"atb":[[3.25,6.84]],"id":39849129}],"con":true,"img":false}]}
{"op":"mcm","clk":"5353674946","pt":1646217430357,"mc":[{"id":"1.195453777","rc":[{"atb":[[3.25,31.77],[3.05,2.5],[3.15,97.33]],"id":39849129}],"con":true,"img":false}]}
{"op":"mcm","clk":"5353674955","pt":1646217430461,"mc":[{"id":"1.195453777","rc":[{"atb":[[3.15,70.07]],"id":39849129}],"con":true,"img":false}]}
{"op":"mcm","clk":"5353674989","pt":1646217430663,"mc":[{"id":"1.195453777","rc":[{"atb":[[2.5,21.72]],"id":39594662},{"atb":[[1.73,155.25]],"id":40659166}],"con":true,"img":false}]}
{"op":"mcm","clk":"5353675014","pt":1646217430873,"mc":[{"id":"1.195453777","rc":[{"atb":[[3.2,0]],"id":39849129}],"con":true,"img":false}]}
{"op":"mcm","clk":"5353675024","pt":1646217430977,"mc":[{"id":"1.195453777","rc":[{"atb":[[3.2,3.79]],"id":39849129}],"con":true,"img":false}]}
{"op":"mcm","clk":"5353675221","pt":1646217433063,"mc":[{"id":"1.195453777","rc":[{"spn":6.25,"spf":"NaN","id":32633412},{"spn":3.88,"spf":"NaN","id":39594662},{"spn":2.19,"spf":"NaN","id":40659166},{"spn":41.25,"spf":"NaN","id":38440014},{"spn":3.42,"spf":"NaN","id":36201034},{"atb":[[3.15,68.41]],"id":39849129},{"spn":5.12,"spf":"NaN","id":39849129}],"con":true,"img":false}]}
{"op":"mcm","clk":"5353675240","pt":1646217433275,"mc":[{"id":"1.195453777","rc":[{"atb":[[3.3,1.66]],"id":39849129}],"con":true,"img":false}]}
{"op":"mcm","clk":"5353675286","pt":1646217433689,"mc":[{"id":"1.195453777","rc":[{"atl":[[8.8,23.16]],"id":32633412},{"atl":[[6,27.55]],"id":39594662},{"atl":[[2.56,35.29]],"id":40659166},{"atb":[[17,0]],"id":38440014},{"atl":[[2.66,54.3]],"id":38276037}],"con":true,"img":false}]}
{"op":"mcm","clk":"5353675297","pt":1646217433755,"mc":[{"id":"1.195453777","rc":[{"atl":[[8.6,5.44]],"id":32633412},{"atl":[[5.9,8.89]],"id":39594662},{"atl":[[2.62,29.06]],"id":40659166},{"atb":[[18,2.72]],"id":38440014},{"atl":[[2.64,30.56]],"id":38276037}],"con":true,"img":false}]}
{"op":"mcm","clk":"5353675310","pt":1646217433863,"mc":[{"id":"1.195453777","rc":[{"atl":[[2.56,0]],"id":40659166},{"atb":[[12.5,25.38],[14,2.5],[17.5,0],[18.5,4.57]],"id":38440014}],"con":true,"img":false}]}
{"op":"mcm","clk":"5353675320","pt":1646217433991,"mc":[{"id":"1.195453777","rc":[{"atl":[[8.6,28.6],[8.8,0]],"id":32633412},{"atl":[[5.9,36.44],[6,0]],"id":39594662},{"atl":[[2.64,30.49],[2.62,120.17]],"id":40659166}],"con":true,"img":false}]}
{"op":"mcm","clk":"5353675329","pt":1646217434065,"mc":[{"id":"1.195453777","rc":[{"atl":[[2.62,157.01]],"id":40659166},{"atb":[[12.5,9.6]],"id":38440014}],"con":true,"img":false}]}
{"op":"mcm","clk":"5353675397","pt":1646217434685,"mc":[{"id":"1.195453777","rc":[{"atb":[[2.58,3.33]],"id":39594662},{"atb":[[1.74,64.06]],"id":40659166}],"con":true,"img":false}]}
{"op":"mcm","clk":"5353675416","pt":1646217434892,"mc":[{"id":"1.195453777","rc":[{"atb":[[2.58,11.69]],"id":39594662},{"atb":[[1.73,0],[1.74,157.32]],"id":40659166}],"con":true,"img":false}]}
{"op":"mcm","clk":"5353675436","pt":1646217435057,"mc":[{"id":"1.195453777","rc":[{"atb":[[2.54,2.16]],"id":39594662}],"con":true,"img":false}]}
{"op":"mcm","clk":"5353675555","pt":1646217436199,"mc":[{"id":"1.195453777","rc":[{"atb":[[3.25,24.93]],"id":39849129}],"con":true,"img":false}]}
{"op":"mcm","clk":"5353675628","pt":1646217436775,"mc":[{"id":"1.195453777","rc":[{"atb":[[1.77,0]],"id":40659166},{"atb":[[14,10.33]],"id":38440014},{"atb":[[3.3,4.93]],"id":39849129}],"con":true,"img":false}]}
{"op":"mcm","clk":"5353675809","pt":1646217438666,"mc":[{"id":"1.195453777","rc":[{"atl":[[9.2,12.2],[9.6,0]],"id":32633412}],"con":true,"img":false}]}
{"op":"mcm","clk":"5353675870","pt":1646217439394,"mc":[{"id":"1.195453777","rc":[{"atb":[[1.74,93.26]],"id":40659166},{"atb":[[3.35,9.87]],"id":39849129}],"con":true,"img":false}]}
{"op":"mcm","clk":"5353676107","pt":1646217441592,"mc":[{"id":"1.195453777","rc":[{"atl":[[2.64,123.75]],"id":40659166}],"con":true,"img":false}]}
{"op":"mcm","clk":"5353676115","pt":1646217441697,"mc":[{"id":"1.195453777","rc":[{"atl":[[2.62,65.9]],"id":40659166}],"con":true,"img":false}]}
{"op":"mcm","clk":"5353676188","pt":1646217442487,"mc":[{"id":"1.195453777","rc":[{"atb":[[1.72,148.87],[1.74,0]],"id":40659166}],"con":true,"img":false}]}
{"op":"mcm","clk":"5353676221","pt":1646217442902,"mc":[{"id":"1.195453777","rc":[{"atb":[[1.75,63.2]],"id":40659166}],"con":true,"img":false}]}
{"op":"mcm","clk":"5353676307","pt":1646217443699,"mc":[{"id":"1.195453777","rc":[{"atb":[[3.95,33.03]],"id":32633412},{"atl":[[4.5,0]],"id":38276037},{"atb":[[3.15,49.86]],"id":39849129}],"con":true,"img":false}]}
{"op":"mcm","clk":"5353676320","pt":1646217443802,"mc":[{"id":"1.195453777","rc":[{"atb":[[4,22.52]],"id":32633412},{"atl":[[3.95,54.74]],"id":38276037},{"atb":[[3.3,23.48]],"id":39849129}],"con":true,"img":false}]}
{"op":"mcm","clk":"5353676361","pt":1646217444174,"mc":[{"id":"1.195453777","rc":[{"atb":[[2.5,0],[2.52,23.8]],"id":39594662}],"con":true,"img":false}]}
{"op":"mcm","clk":"5353676590","pt":1646217446480,"mc":[{"id":"1.195453777","rc":[{"atb":[[3.35,43.91],[3.25,97.56],[3.15,0]],"id":39849129}],"con":true,"img":false}]}
{"op":"mcm","clk":"5353676608","pt":1646217446679,"mc":[{"id":"1.195453777","rc":[{"atb":[[3.25,72.63]],"id":39849129}],"con":true,"img":false}]}
{"op":"mcm","clk":"5353676736","pt":1646217448190,"mc":[{"id":"1.195453777","rc":[{"atb":[[2.56,0]],"id":39594662},{"atb":[[3.3,21.82]],"id":39849129}],"con":true,"img":false}]}
{"op":"mcm","clk":"5353676750","pt":1646217448397,"mc":[{"id":"1.195453777","rc":[{"atb":[[2.6,1.66]],"id":39594662},{"atb":[[3.4,1.66]],"id":39849129}],"con":true,"img":false}]}
{"op":"mcm","clk":"5353676798","pt":1646217448876,"mc":[{"id":"1.195453777","rc":[{"atb":[[3.3,18.55]],"id":39849129}],"con":true,"img":false}]}
{"op":"mcm","clk":"5353676896","pt":1646217449981,"mc":[{"id":"1.195453777","rc":[{"atb":[[2.58,8.36]],"id":39594662},{"atb":[[3.35,34.04]],"id":39849129}],"con":true,"img":false}]}
{"op":"mcm","clk":"5353676912","pt":1646217450190,"mc":[{"id":"1.195453777","rc":[{"atl":[[2.6,70.06]],"id":40659166}],"con":true,"img":false}]}
{"op":"mcm","clk":"5353676929","pt":1646217450396,"mc":[{"id":"1.195453777","rc":[{"atl":[[2.62,29.06]],"id":40659166}],"con":true,"img":false}]}
{"op":"mcm","clk":"5353677079","pt":1646217452010,"mc":[{"id":"1.195453777","rc":[{"atb":[[1.79,9.51]],"id":40659166}],"con":true,"img":false}]}
{"op":"mcm","clk":"5353677096","pt":1646217452219,"mc":[{"id":"1.195453777","rc":[{"atb":[[1.72,2.5],[1.75,205.52]],"id":40659166}],"con":true,"img":false}]}
{"op":"mcm","clk":"5353677234","pt":1646217453589,"mc":[{"id":"1.195453777","rc":[{"atb":[[12.5,0],[14.5,7.85]],"id":38440014}],"con":true,"img":false}]}
{"op":"mcm","clk":"5353677242","pt":1646217453683,"mc":[{"id":"1.195453777","rc":[{"atb":[[14.5,18.79]],"id":38440014},{"atl":[[7,20.16]],"id":39849129}],"con":true,"img":false}]}
{"op":"mcm","clk":"5353677249","pt":1646217453794,"mc":[{"id":"1.195453777","rc":[{"atb":[[14,2.5]],"id":38440014},{"atl":[[6.8,6.22],[7,6.96],[7.8,52.88]],"id":39849129}],"con":true,"img":false}]}
{"op":"mcm","clk":"5353677265","pt":1646217453996,"mc":[{"id":"1.195453777","rc":[{"atl":[[7.4,41.4],[7.8,22.06],[6.6,9.9]],"id":39849129}],"con":true,"img":false}]}
{"op":"mcm","clk":"5353677273","pt":1646217454101,"mc":[{"id":"1.195453777","rc":[{"atl":[[7,0]],"id":39849129}],"con":true,"img":false}]}
{"op":"mcm","clk":"5353677304","pt":1646217454410,"mc":[{"id":"1.195453777","rc":[{"atb":[[1.75,142.32]],"id":40659166}],"con":true,"img":false}]}
{"op":"mcm","clk":"5353677314","pt":1646217454515,"mc":[{"id":"1.195453777","rc":[{"atb":[[2.62,3.33]],"id":39594662},{"atb":[[3.45,3.33]],"id":39849129}],"con":true,"img":false}]}
{"op":"mcm","clk":"5353677336","pt":1646217454679,"mc":[{"id":"1.195453777","rc":[{"atb":[[2.62,12.1]],"id":39594662}],"con":true,"img":false}]}
{"op":"mcm","clk":"5353677348","pt":1646217454785,"mc":[{"id":"1.195453777","rc":[{"atb":[[2.58,0]],"id":39594662}],"con":true,"img":false}]}
{"op":"mcm","clk":"5353677369","pt":1646217454991,"mc":[{"id":"1.195453777","rc":[{"atb":[[3.45,6.4]],"id":39849129}],"con":true,"img":false}]}
{"op":"mcm","clk":"5353677406","pt":1646217455407,"mc":[{"id":"1.195453777","rc":[{"atb":[[3.2,0]],"id":39849129}],"con":true,"img":false}]}
{"op":"mcm","clk":"5353677494","pt":1646217456296,"mc":[{"id":"1.195453777","rc":[{"atb":[[1.76,62.37]],"id":40659166}],"con":true,"img":false}]}
{"op":"mcm","clk":"5353677684","pt":1646217458020,"mc":[{"id":"1.195453777","rc":[{"atb":[[1.79,0]],"id":40659166}],"con":true,"img":false}]}
{"op":"mcm","clk":"5353677987","pt":1646217461212,"mc":[{"id":"1.195453777","rc":[{"atl":[[7.8,7.35],[7,16.67]],"id":39849129}],"con":true,"img":false}]}
{"op":"mcm","clk":"5353678104","pt":1646217462308,"mc":[{"id":"1.195453777","rc":[{"atb":[[3.25,0],[3.3,58.41],[3.45,18.63]],"id":39849129}],"con":true,"img":false}]}
{"op":"mcm","clk":"5353678124","pt":1646217462517,"mc":[{"id":"1.195453777","rc":[{"atb":[[3.35,0]],"id":39849129}],"con":true,"img":false}]}
{"op":"mcm","clk":"5353678181","pt":1646217463102,"mc":[{"id":"1.195453777","rc":[{"atb":[[2.6,0]],"id":39594662},{"atb":[[3.4,0]],"id":39849129}],"con":true,"img":false}]}
{"op":"mcm","clk":"5353678199","pt":1646217463305,"mc":[{"id":"1.195453777","rc":[{"atb":[[2.64,1.66]],"id":39594662},{"atb":[[3.5,1.66]],"id":39849129}],"con":true,"img":false}]}
{"op":"mcm","clk":"5353678231","pt":1646217463624,"mc":[{"id":"1.195453777","rc":[{"atl":[[8.6,23.16]],"id":32633412},{"atl":[[5.9,27.55]],"id":39594662},{"atl":[[2.62,0]],"id":40659166},{"atb":[[18,0]],"id":38440014}],"con":true,"img":false}]}
{"op":"mcm","clk":"5353678240","pt":1646217463721,"mc":[{"id":"1.195453777","rc":[{"atl":[[8.4,8.14]],"id":32633412},{"atl":[[5.8,8.89]],"id":39594662},{"atl":[[2.58,29.06]],"id":40659166},{"atb":[[18.5,7.29]],"id":38440014}],"con":true,"img":false}]}
{"op":"mcm","clk":"5353678248","pt":1646217463824,"mc":[{"id":"1.195453777","rc":[{"atl":[[2.68,156.21]],"id":40659166},{"atb":[[14,13.1],[14.5,7.85],[18.5,2.72]],"id":38440014}],"con":true,"img":false}]}
{"op":"mcm","clk":"5353678257","pt":1646217463929,"mc":[{"id":"1.195453777","rc":[{"atl":[[5.8,37.78],[5.9,0]],"id":39594662},{"atl":[[2.64,30.49],[2.68,44.64]],"id":40659166},{"atb":[[19,4.44]],"id":38440014}],"con":true,"img":false}]}
{"op":"mcm","clk":"5353678264","pt":1646217463988,"mc":[{"id":"1.195453777","rc":[{"atb":[[1.8,9.39]],"id":40659166},{"atb":[[3.45,15.56]],"id":39849129}],"con":true,"img":false}]}
{"op":"mcm","clk":"5353678272","pt":1646217464097,"mc":[{"id":"1.195453777","rc":[{"atb":[[1.76,155.63],[1.75,0]],"id":40659166}],"con":true,"img":false}]}
{"op":"mcm","clk":"5353678441","pt":1646217465735,"mc":[{"id":"1.195453777","rc":[{"atb":[[2.62,8.77]],"id":39594662},{"atb":[[3.45,12.23]],"id":39849129}],"con":true,"img":false}]}
{"op":"mcm","clk":"5353678463","pt":1646217465903,"mc":[{"id":"1.195453777","rc":[{"atl":[[2.58,75.69]],"id":40659166}],"con":true,"img":false}]}
{"op":"mcm","clk":"5353678478","pt":1646217466101,"mc":[{"id":"1.195453777","rc":[{"atl":[[2.6,20.06]],"id":40659166}],"con":true,"img":false}]}
{"op":"mcm","clk":"5353678616","pt":1646217467526,"mc":[{"id":"1.195453777","rc":[{"atb":[[1.76,93.26]],"id":40659166}],"con":true,"img":false}]}
{"op":"mcm","clk":"5353678774","pt":1646217469209,"mc":[{"id":"1.195453777","rc":[{"atb":[[2.56,5.42]],"id":39594662}],"con":true,"img":false}]}
{"op":"mcm","clk":"5353678782","pt":1646217469310,"mc":[{"id":"1.195453777","rc":[{"atb":[[14,2.5],[14.5,18.59]],"id":38440014}],"con":true,"img":false}]}
{"op":"mcm","clk":"5353678792","pt":1646217469412,"mc":[{"id":"1.195453777","rc":[{"atb":[[2.54,25.84],[2.52,2.5]],"id":39594662}],"con":true,"img":false}]}
{"op":"mcm","clk":"5353678809","pt":1646217469624,"mc":[{"id":"1.195453777","rc":[{"atb":[[3.3,18.55],[3.05,38.2]],"id":39849129},{"atl":[[7.4,3.12],[7,52.37]],"id":39849129}],"con":true,"img":false}]}
{"op":"mcm","clk":"5353678922","pt":1646217470727,"mc":[{"id":"1.195453777","rc":[{"atb":[[1.77,61.56]],"id":40659166}],"con":true,"img":false}]}
{"op":"mcm","clk":"5353678960","pt":1646217471042,"mc":[{"id":"1.195453777","rc":[{"atb":[[1.76,0],[1.77,154.82]],"id":40659166}],"con":true,"img":false}]}
{"op":"mcm","clk":"5353679167","pt":1646217473138,"mc":[{"id":"1.195453777","rc":[{"atb":[[1.8,0]],"id":40659166}],"con":true,"img":false}]}
{"op":"mcm","clk":"5353679190","pt":1646217473348,"mc":[{"id":"1.195453777","rc":[{"atb":[[1.72,95.76],[1.77,61.56]],"id":40659166}],"con":true,"img":false}]}
{"op":"mcm","clk":"5353679219","pt":1646217473620,"mc":[{"id":"1.195453777","rc":[{"atb":[[3.3,0]],"id":39849129}],"con":true,"img":false}]}
{"op":"mcm","clk":"5353679230","pt":1646217473724,"mc":[{"id":"1.195453777","rc":[{"atb":[[3.1,18.55]],"id":39849129}],"con":true,"img":false}]}
{"op":"mcm","clk":"5353679405","pt":1646217475444,"mc":[{"id":"1.195453777","rc":[{"atb":[[1.77,0]],"id":40659166}],"con":true,"img":false}]}
{"op":"mcm","clk":"5353679465","pt":1646217476135,"mc":[{"id":"1.195453777","rc":[{"atb":[[3.1,22.13]],"id":39849129}],"con":true,"img":false}]}
{"op":"mcm","clk":"5353679603","pt":1646217477664,"mc":[{"id":"1.195453777","rc":[{"atb":[[3.6,0],[3.85,0],[3.35,0]],"id":32633412},{"atl":[[40,0],[12.5,0],[17.5,0],[75,0],[25,0]],"id":32633412},{"atb":[[1.98,0],[1.93,0],[2.06,0]],"id":39594662},{"atl":[[6.4,0],[11,0],[8.4,0],[16,0],[5.2,7.48]],"id":39594662},{"atb":[[1.35,0],[1.25,0],[1.3,0]],"id":40659166},{"atl":[[2.8,0],[4,0],[3,50],[2.6,12.5],[3.5,0]],"id":40659166},{"atb":[[7.8,0],[9.8,0],[8.8,0]],"id":38440014},{"atl":[[140,0],[240,0],[70,0],[340,0],[440,0]],"id":38440014},{"atb":[[2.84,0],[2.94,5],[2.74,0]],"id":36201034},{"atl":[[8,0],[10,0],[15,0],[20,0],[30,0]],"id":36201034},{"atb":[[1.2,0],[1.25,0],[1.15,0]],"id":38276037},{"atl":[[3.6,0],[3.1,0],[2.44,11.98],[2.64,23.18],[2.84,0]],"id":38276037},{"atb":[[2.84,0],[2.94,5],[2.74,0]],"id":39849129},{"atl":[[8,0],[10,0],[15,0],[20,0],[30,0]],"id":39849129}],"con":true,"img":false}]}
{"op":"mcm","clk":"5353679632","pt":1646217477931,"mc":[{"id":"1.195453777","rc":[{"atb":[[14.5,21.09]],"id":38440014}],"con":true,"img":false}]}
{"op":"mcm","clk":"5353679637","pt":1646217478034,"mc":[{"id":"1.195453777","rc":[{"atl":[[5.2,0]],"id":39594662},{"atb":[[10,0],[12,0],[14,0]],"id":38440014},{"atl":[[75,2.5],[85,4.02]],"id":38440014},{"atl":[[2.44,0]],"id":38276037}],"con":true,"img":false}]}
{"op":"mcm","clk":"5353679645","pt":1646217478147,"mc":[{"id":"1.195453777","rc":[{"atl":[[5.7,12.18]],"id":39594662},{"atl":[[65,0]],"id":38440014},{"atl":[[2.64,51.19]],"id":38276037}],"con":true,"img":false}]}
{"op":"mcm","clk":"5353679655","pt":1646217478244,"mc":[{"id":"1.195453777","rc":[{"atl":[[5.8,8.89],[6.2,28.8]],"id":39594662},{"atb":[[1.72,2.5],[1.68,98.26]],"id":40659166},{"atl":[[3.95,133.05]],"id":38276037}],"con":true,"img":false}]}
{"op":"mcm","clk":"5353679663","pt":1646217478348,"mc":[{"id":"1.195453777","rc":[{"atl":[[70,1.16]],"id":38440014},{"atl":[[2.66,2.5]],"id":38276037}],"con":true,"img":false}]}
{"op":"mcm","clk":"5353679687","pt":1646217478520,"mc":[{"id":"1.195453777","rc":[{"atb":[[1.69,68.69]],"id":40659166}],"con":true,"img":false}]}
{"op":"mcm","clk":"5353679747","pt":1646217479143,"mc":[{"id":"1.195453777","rc":[{"atb":[[2.1,7.57]],"id":39594662}],"con":true,"img":false}]}
{"op":"mcm","clk":"5353679771","pt":1646217479354,"mc":[{"id":"1.195453777","rc":[{"atl":[[2.64,123.75]],"id":40659166}],"con":true,"img":false}]}
{"op":"mcm","clk":"5353679800","pt":1646217479624,"mc":[{"id":"1.195453777","rc":[{"atb":[[1.68,5],[1.69,219.26]],"id":40659166}],"con":true,"img":false}]}
{"op":"mcm","clk":"5353679857","pt":1646217480247,"mc":[{"id":"1.195453777","rc":[{"atb":[[2.56,0]],"id":39594662},{"atb":[[1.51,23.97]],"id":38276037}],"con":true,"img":false}]}
{"op":"mcm","clk":"5353679881","pt":1646217480414,"mc":[{"id":"1.195453777","rc":[{"atb":[[2.54,2.16],[2.52,36.43]],"id":39594662}],"con":true,"img":false}]}
{"op":"mcm","clk":"5353679893","pt":1646217480522,"mc":[{"id":"1.195453777","rc":[{"atl":[[5.8,16.58]],"id":39594662},{"atl":[[2.62,6.21]],"id":38276037}],"con":true,"img":false}]}
{"op":"mcm","clk":"5353679970","pt":1646217481454,"mc":[{"id":"1.195453777","rc":[{"atb":[[3.6,46.53],[3.85,21.22],[3.35,51.48]],"id":32633412},{"atl":[[17.5,0.03],[12.5,0.04],[25,0.17]],"id":32633412},{"atb":[[1.98,123.45],[1.93,130.09],[2.06,57.07]],"id":39594662},{"atl":[[6.4,0.1],[5.2,0.13],[8.4,0.58]],"id":39594662},{"atb":[[1.35,172.83],[1.25,483.95],[1.3,403.29]],"id":40659166},{"atl":[[2.8,0.3],[3,52.17],[2.6,12.84]],"id":40659166},{"atb":[[9.8,6.87],[8.8,15.51],[7.8,17.79]],"id":38440014},{"atl":[[70,1.16],[140,0],[240,0.01]],"id":38440014},{"atb":[[2.84,65.75],[2.94,36.18],[2.74,69.53]],"id":36201034},{"atl":[[8,0.07],[10,0.05],[15,0.31]],"id":36201034},{"atb":[[1.2,604.93],[1.25,241.97],[1.15,806.58]],"id":38276037},{"atl":[[2.64,51.53],[2.44,0.37],[2.84,2.37],[2.62,0]],"id":38276037},{"atb":[[2.84,65.75],[2.94,36.18],[2.74,69.53]],"id":39849129},{"atl":[[8,0.07],[10,0.05],[15,0.31]],"id":39849129}],"con":true,"img":false}]}
{"op":"mcm","clk":"5353679983","pt":1646217481614,"mc":[{"id":"1.195453777","rc":[{"atl":[[5.8,8.89]],"id":39594662}],"con":true,"img":false}]}
{"op":"mcm","clk":"5353680015","pt":1646217482032,"mc":[{"id":"1.195453777","rc":[{"atb":[[1.68,41.93],[2.18,0]],"id":38440014}],"con":true,"img":false}]}
{"op":"mcm","clk":"5353680046","pt":1646217482350,"mc":[{"id":"1.195453777","rc":[{"atl":[[3.7,3],[3.9,0]],"id":36201034}],"con":true,"img":false}]}
{"op":"mcm","clk":"5353680192","pt":1646217483628,"mc":[{"id":"1.195453777","rc":[{"atl":[[5.8,0]],"id":39594662},{"atb":[[18.5,0],[12,10.11],[14.5,13.24]],"id":38440014},{"atl":[[2.64,28.34]],"id":38276037}],"con":true,"img":false}]}
{"op":"mcm","clk":"5353680201","pt":1646217483730,"mc":[{"id":"1.195453777","rc":[{"atb":[[2.56,5.42]],"id":39594662},{"atl":[[6,8.89]],"id":39594662},{"atb":[[19,7.16]],"id":38440014},{"atb":[[1.54,38.91]],"id":38276037},{"atl":[[3.05,23.18]],"id":38276037}],"con":true,"img":false}]}
{"op":"mcm","clk":"5353680210","pt":1646217483854,"mc":[{"id":"1.195453777","rc":[{"atb":[[12,22.82]],"id":38440014}],"con":true,"img":false}]}
{"op":"mcm","clk":"5353680225","pt":1646217483959,"mc":[{"id":"1.195453777","rc":[{"atb":[[19,2.72],[14.5,2.5]],"id":38440014},{"atb":[[1.51,0],[1.53,27.48]],"id":38276037}],"con":true,"img":false}]}
{"op":"mcm","clk":"5353680247","pt":1646217484130,"mc":[{"id":"1.195453777","rc":[{"atb":[[15,3.92]],"id":38440014}],"con":true,"img":false}]}
{"op":"mcm","clk":"5353680296","pt":1646217484649,"mc":[{"id":"1.195453777","rc":[{"atb":[[14.5,10.33]],"id":38440014}],"con":true,"img":false}]}
{"op":"mcm","clk":"5353680307","pt":1646217484754,"mc":[{"id":"1.195453777","rc":[{"atb":[[2.54,31.17]],"id":39594662},{"atb":[[12,10.11]],"id":38440014}],"con":true,"img":false}]}
{"op":"mcm","clk":"5353680317","pt":1646217484859,"mc":[{"id":"1.195453777","rc":[{"atb":[[2.52,2.5]],"id":39594662}],"con":true,"img":false}]}
{"op":"mcm","clk":"5353680416","pt":1646217485752,"mc":[{"id":"1.195453777","rc":[{"atb":[[1.64,0],[1.73,2.5],[1.68,0],[1.69,224.26],[1.72,0]],"id":40659166}],"con":true,"img":false}]}
{"op":"mcm","clk":"5353680448","pt":1646217486069,"mc":[{"id":"1.195453777","rc":[{"atb":[[3.1,26.09]],"id":39849129}],"con":true,"img":false}]}
{"op":"mcm","clk":"5353680457","pt":1646217486125,"mc":[{"id":"1.195453777","rc":[{"atb":[[1.73,12.8]],"id":40659166}],"con":true,"img":false}]}
{"op":"mcm","clk":"5353680677","pt":1646217488574,"mc":[{"id":"1.195453777","rc":[{"atb":[[1.69,155.57]],"id":40659166}],"con":true,"img":false}]}
{"op":"mcm","clk":"5353680725","pt":1646217489162,"mc":[{"id":"1.195453777","rc":[{"atb":[[1.68,0],[2.16,41.93]],"id":38440014}],"con":true,"img":false}]}
{"op":"mcm","clk":"5353680842","pt":1646217490363,"mc":[{"id":"1.195453777","rc":[{"atb":[[2.54,33.67],[2.52,0]],"id":39594662}],"con":true,"img":false}]}
{"op":"mcm","clk":"5353681011","pt":1646217492049,"mc":[{"id":"1.195453777","rc":[{"atb":[[1.7,67.72]],"id":40659166}],"con":true,"img":false}]}
{"op":"mcm","clk":"5353681030","pt":1646217492257,"mc":[{"id":"1.195453777","rc":[{"atb":[[1.7,216.82],[1.69,5]],"id":40659166}],"con":true,"img":false}]}
{"op":"mcm","clk":"5353681097","pt":1646217493048,"mc":[{"id":"1.195453777","rc":[{"atb":[[3.1,0]],"id":36201034}],"con":true,"img":false}]}
{"op":"mcm","clk":"5353681148","pt":1646217493463,"mc":[{"id":"1.195453777","rc":[{"spn":3.92,"spf":"NaN","id":39594662},{"spn":2.2,"spf":"NaN","id":40659166},{"spn":44.5,"spf":"NaN","id":38440014},{"spn":3.37,"spf":"NaN","id":36201034},{"atl":[[3.95,54.74],[2.84,64.82]],"id":38276037},{"spn":5.05,"spf":"NaN","id":39849129}],"con":true,"img":false}]}
{"op":"mcm","clk":"5353681165","pt":1646217493668,"mc":[{"id":"1.195453777","rc":[{"atl":[[2.58,46.63]],"id":40659166},{"atb":[[19,0]],"id":38440014}],"con":true,"img":false}]}
{"op":"mcm","clk":"5353681174","pt":1646217493772,"mc":[{"id":"1.195453777","rc":[{"atl":[[2.56,29.06]],"id":40659166},{"atb":[[16.5,2.72]],"id":38440014}],"con":true,"img":false}]}
{"op":"mcm","clk":"5353681185","pt":1646217493842,"mc":[{"id":"1.195453777","rc":[{"atb":[[12,22.03],[14.5,2.5]],"id":38440014}],"con":true,"img":false}]}
{"op":"mcm","clk":"5353681193","pt":1646217493942,"mc":[{"id":"1.195453777","rc":[{"atl":[[2.56,74.61]],"id":40659166},{"atb":[[12,10.11]],"id":38440014}],"con":true,"img":false}]}
{"op":"mcm","clk":"5353681201","pt":1646217494042,"mc":[{"id":"1.195453777","rc":[{"atb":[[2.6,4.69]],"id":39594662},{"atb":[[1.73,2.5]],"id":40659166}],"con":true,"img":false}]}
{"op":"mcm","clk":"5353681212","pt":1646217494150,"mc":[{"id":"1.195453777","rc":[{"atl":[[2.58,0]],"id":40659166}],"con":true,"img":false}]}
{"op":"mcm","clk":"5353681362","pt":1646217495569,"mc":[{"id":"1.195453777","rc":[{"atb":[[2.54,4.66],[2.56,34.43]],"id":39594662}],"con":true,"img":false}]}
{"op":"mcm","clk":"5353681451","pt":1646217496570,"mc":[{"id":"1.195453777","rc":[{"atb":[[2.56,29.01]],"id":39594662},{"atb":[[1.7,149.1]],"id":40659166}],"con":true,"img":false}]}
{"op":"mcm","clk":"5353681504","pt":1646217497040,"mc":[{"id":"1.195453777","rc":[{"atb":[[2.6,0]],"id":39594662}],"con":true,"img":false}]}
{"op":"mcm","clk":"5353681719","pt":1646217498976,"mc":[{"id":"1.195453777","rc":[{"atb":[[14.5,10.33]],"id":38440014}],"con":true,"img":false}]}
{"op":"mcm","clk":"5353681747","pt":1646217499286,"mc":[{"id":"1.195453777","rc":[{"atb":[[17,4.98]],"id":38440014}],"con":true,"img":false}]}
{"op":"mcm","clk":"5353681766","pt":1646217499450,"mc":[{"id":"1.195453777","rc":[{"atb":[[15,0]],"id":38440014}],"con":true,"img":false}]}
{"op":"mcm","clk":"5353681816","pt":1646217499969,"mc":[{"id":"1.195453777","rc":[{"atb":[[2.58,5]],"id":39594662},{"atb":[[1.71,66.76]],"id":40659166}],"con":true,"img":false}]}
{"op":"mcm","clk":"5353681836","pt":1646217500176,"mc":[{"id":"1.195453777","rc":[{"atb":[[1.7,0],[1.71,214.43],[1.74,10.15]],"id":40659166}],"con":true,"img":false}]}
{"op":"mcm","clk":"5353682121","pt":1646217502958,"mc":[{"id":"1.195453777","rc":[{"atb":[[2.62,13.4]],"id":39594662}],"con":true,"img":false}]}
{"op":"mcm","clk":"5353682134","pt":1646217503071,"mc":[{"id":"1.195453777","rc":[{"atb":[[1.74,0]],"id":40659166}],"con":true,"img":false}]}
{"op":"mcm","clk":"5353682153","pt":1646217503273,"mc":[{"id":"1.195453777","rc":[{"atb":[[1.71,147.67]],"id":40659166}],"con":true,"img":false}]}
{"op":"mcm","clk":"5353682482","pt":1646217506268,"mc":[{"id":"1.195453777","rc":[{"atb":[[1.74,64.06]],"id":40659166}],"con":true,"img":false}]}
{"op":"mcm","clk":"5353682579","pt":1646217507187,"mc":[{"id":"1.195453777","rc":[{"atb":[[1.73,146.11],[1.71,0]],"id":40659166}],"con":true,"img":false}]}
{"op":"mcm","clk":"5353683321","pt":1646217513679,"mc":[{"id":"1.195453777","rc":[{"atb":[[1.42,0]],"id":38276037}],"con":true,"img":false}]}
{"op":"mcm","clk":"5353683330","pt":1646217513780,"mc":[{"id":"1.195453777","rc":[{"atb":[[1.55,75.17]],"id":38276037}],"con":true,"img":false}]}
{"op":"mcm","clk":"5353683349","pt":1646217513993,"mc":[{"id":"1.195453777","rc":[{"atb":[[1.53,2.5],[1.54,140.37]],"id":38276037}],"con":true,"img":false}]}
{"op":"mcm","clk":"5353683460","pt":1646217515190,"mc":[{"id":"1.195453777","rc":[{"atb":[[1.78,9.63]],"id":40659166},{"atb":[[1.45,18.52]],"id":38276037}],"con":true,"img":false}]}
{"op":"mcm","clk":"5353683478","pt":1646217515402,"mc":[{"id":"1.195453777","rc":[{"atb":[[1.73,2.5],[1.74,207.67]],"id":40659166}],"con":true,"img":false}]}
{"op":"mcm","clk":"5353683584","pt":1646217516316,"mc":[{"id":"1.195453777","rc":[{"atb":[[1.54,101.46]],"id":38276037}],"con":true,"img":false}]}
{"op":"mcm","clk":"5353683654","pt":1646217516998,"mc":[{"id":"1.195453777","rc":[{"atb":[[2.16,0]],"id":38440014}],"con":true,"img":false}]}
{"op":"mcm","clk":"5353683742","pt":1646217517790,"mc":[{"id":"1.195453777","rc":[{"atb":[[1.74,143.61]],"id":40659166}],"con":true,"img":false}]}
{"op":"mcm","clk":"5353683877","pt":1646217518892,"mc":[{"id":"1.195453777","rc":[{"atb":[[5.9,3]],"id":32633412},{"atl":[[8.6,25.79],[8.4,5.44]],"id":32633412},{"atl":[[3.85,0],[3.8,0],[3.75,0],[4.1,3],[3.7,0]],"id":36201034},{"atb":[[1.37,54.05],[1.39,0]],"id":38276037},{"atl":[[4.8,3]],"id":38276037},{"atl":[[7.4,0],[7.6,3.03]],"id":39849129}],"con":true,"img":false}]}
{"op":"mcm","clk":"5353683891","pt":1646217518993,"mc":[{"id":"1.195453777","rc":[{"atl":[[5.7,9.51]],"id":36201034},{"atb":[[1.87,3]],"id":39849129}],"con":true,"img":false}]}
{"op":"mcm","clk":"5353683901","pt":1646217519097,"mc":[{"id":"1.195453777","rc":[{"atb":[[5.9,0],[4,55.55],[3.95,0],[6,4]],"id":32633412},{"atl":[[4,2],[5.9,31.89]],"id":36201034},{"atl":[[2.8,10],[2.72,5],[2.64,30.84],[2.66,0],[4.7,4]],"id":38276037}],"con":true,"img":false}]}
{"op":"mcm","clk":"5353683914","pt":1646217519201,"mc":[{"id":"1.195453777","rc":[{"atb":[[1.88,2]],"id":39849129}],"con":true,"img":false}]}
{"op":"mcm","clk":"5353683923","pt":1646217519310,"mc":[{"id":"1.195453777","rc":[{"atb":[[5.9,4]],"id":32633412},{"atl":[[3.95,2]],"id":36201034},{"atb":[[1.57,28.3]],"id":38276037},{"atl":[[2.8,78.05],[2.84,2.37],[4.6,4]],"id":38276037}],"con":true,"img":false}]}
{"op":"mcm","clk":"5353683942","pt":1646217519510,"mc":[{"id":"1.195453777","rc":[{"atl":[[5.9,10.2]],"id":36201034},{"atb":[[1.57,60.14]],"id":38276037}],"con":true,"img":false}]}
{"op":"mcm","clk":"5353683952","pt":1646217519617,"mc":[{"id":"1.195453777","rc":[{"atb":[[6.2,4]],"id":32633412},{"atl":[[4.5,4]],"id":38276037},{"atb":[[1.89,4]],"id":39849129}],"con":true,"img":false}]}
{"op":"mcm","clk":"5353683965","pt":1646217519681,"mc":[{"id":"1.195453777","rc":[{"atl":[[8.4,8.14]],"id":32633412},{"atb":[[1.56,2.16]],"id":38276037}],"con":true,"img":false}]}
{"op":"mcm","clk":"5353683974","pt":1646217519817,"mc":[{"id":"1.195453777","rc":[{"atb":[[6.4,3],[5.9,0],[4,22.52],[6.2,0],[6,0]],"id":32633412},{"atl":[[8.6,23.16],[9.2,0],[8.8,12.82]],"id":32633412},{"atb":[[1.96,0],[1.94,0],[1.92,21.74]],"id":39594662},{"atl":[[10.5,15.64],[5.6,10.43]],"id":39594662},{"atb":[[1.5,40],[1.52,0]],"id":40659166},{"atl":[[3,2.17],[2.6,0.34],[2.66,12.05],[2.84,54.35],[2.08,4]],"id":40659166},{"atb":[[2.6,20.66]],"id":38440014},{"atl":[[130,2],[150,0]],"id":38440014},{"atb":[[1.18,111.11],[1.16,0]],"id":36201034},{"atl":[[4,0],[3.95,0],[4.1,0]],"id":36201034},{"atb":[[1.39,51.28]],"id":38276037},{"atl":[[4.8,0],[2.62,33.74],[4.5,0],[4.6,0],[5,3],[4.7,0]],"id":38276037},{"atb":[[1.89,0],[1.96,3],[1.87,0],[1.79,0],[1.81,0],[1.88,0],[1.77,0],[1.75,26.67]],"id":39849129},{"atl":[[7.4,3.12],[7.6,0]],"id":39849129}],"con":true,"img":false}]}
{"op":"mcm","clk":"5353683983","pt":1646217519891,"mc":[{"id":"1.195453777","rc":[{"atl":[[8.4,5.44]],"id":32633412}],"con":true,"img":false}]}
{"op":"mcm","clk":"5353683995","pt":1646217519997,"mc":[{"id":"1.195453777","rc":[{"atb":[[6.4,0],[5.8,2]],"id":32633412},{"atl":[[8.6,25.79]],"id":32633412},{"atl":[[10,3],[10.5,13.53],[11,2],[6.2,5],[6,43],[5.7,2.5]],"id":39594662},{"atb":[[1.52,38.46]],"id":40659166},{"atl":[[2.64,93.26],[2.08,0]],"id":40659166},{"atb":[[3.55,0],[3.75,7.27]],"id":38440014},{"atb":[[1.18,0],[1.08,0],[1.27,74.07],[1.17,250]],"id":36201034},{"atl":[[5.8,10.2],[6.2,16.92]],"id":36201034},{"atl":[[2.64,2.83],[4.9,0],[5,0],[5.5,26.66],[5.2,0]],"id":38276037},{"atb":[[1.96,0],[1.71,0],[1.8,72.36],[1.9,22.22]],"id":39849129}],"con":true,"img":false}]}
{"op":"mcm","clk":"5353684020","pt":1646217520217,"mc":[{"id":"1.195453777","rc":[{"atl":[[2.64,0],[2.66,139.6]],"id":40659166}],"con":true,"img":false}]}
{"op":"mcm","clk":"5353684035","pt":1646217520418,"mc":[{"id":"1.195453777","rc":[{"atb":[[5.9,4]],"id":32633412},{"atl":[[8.8,15.32]],"id":32633412},{"atl":[[9.8,2]],"id":39594662},{"atb":[[3.1,2.5],[2.94,31.18],[3.05,0],[1.27,77.07],[2.88,10],[2.86,12.26],[2.96,5]],"id":36201034},{"atl":[[5.7,5.25],[5.9,4.08]],"id":36201034},{"atl":[[5.4,0]],"id":38276037}],"con":true,"img":false}]}
{"op":"mcm","clk":"5353684048","pt":1646217520482,"mc":[{"id":"1.195453777","rc":[{"atb":[[1.6,2.16],[1.56,0]],"id":38276037}],"con":true,"img":false}]}
{"op":"mcm","clk":"5353684061","pt":1646217520590,"mc":[{"id":"1.195453777","rc":[{"atb":[[5.7,3]],"id":32633412},{"atl":[[9.6,2]],"id":39594662},{"atb":[[1.28,2],[2.86,0]],"id":36201034}],"con":true,"img":false}]}
{"op":"mcm","clk":"5353684083","pt":1646217520797,"mc":[{"id":"1.195453777","rc":[{"atb":[[6,4]],"id":32633412},{"atl":[[5.6,12.93],[6.2,0],[6,48],[5.7,0],[7,0]],"id":39594662},{"atb":[[1.28,0],[1.27,0],[1.29,3],[1.24,83.33]],"id":36201034},{"atl":[[5.7,9.51]],"id":36201034}],"con":true,"img":false}]}
{"op":"mcm","clk":"5353684110","pt":1646217521011,"mc":[{"id":"1.195453777","rc":[{"atb":[[1.27,74.07],[1.29,0],[1.24,0]],"id":36201034}],"con":true,"img":false}]}
{"op":"mcm","clk":"5353684115","pt":1646217521108,"mc":[{"id":"1.195453777","rc":[{"atb":[[1.75,63.2]],"id":40659166}],"con":true,"img":false}]}
{"op":"mcm","clk":"5353684200","pt":1646217521802,"mc":[{"id":"1.195453777","rc":[{"atb":[[1.74,0],[1.75,224.96]],"id":40659166}],"con":true,"img":false}]}
{"op":"mcm","clk":"5353684299","pt":1646217522595,"mc":[{"id":"1.195453777","rc":[{"atb":[[1.96,20.83]],"id":39594662},{"atl":[[10,0],[10.5,10.53],[9.6,0],[9.8,0]],"id":39594662}],"con":true,"img":false}]}
{"op":"mcm","clk":"5353684319","pt":1646217522803,"mc":[{"id":"1.195453777","rc":[{"atb":[[6.2,3],[5.7,0]],"id":32633412},{"atb":[[1.27,0],[1.24,83.33]],"id":36201034},{"atl":[[5.2,2]],"id":36201034}],"con":true,"img":false}]}
{"op":"mcm","clk":"5353684344","pt":1646217523015,"mc":[{"id":"1.195453777","rc":[{"atb":[[2.58,0]],"id":39594662},{"atb":[[2.98,7.51]],"id":36201034},{"atl":[[4.6,4],[5.2,0]],"id":36201034},{"atb":[[1.57,31.84]],"id":38276037}],"con":true,"img":false}]}
{"op":"mcm","clk":"5353684361","pt":1646217523216,"mc":[{"id":"1.195453777","rc":[{"atb":[[4.3,0]],"id":32633412},{"atb":[[2.54,70.8],[2.56,0]],"id":39594662}],"con":true,"img":false}]}
{"op":"mcm","clk":"5353684384","pt":1646217523384,"mc":[{"id":"1.195453777","rc":[{"atb":[[3.15,1.66]],"id":36201034}],"con":true,"img":false}]}
{"op":"mcm","clk":"5353684403","pt":1646217523588,"mc":[{"id":"1.195453777","rc":[{"atb":[[4,6.67]],"id":32633412},{"atb":[[1.95,0]],"id":39594662},{"atl":[[2.56,45.55]],"id":40659166},{"atb":[[16.5,0]],"id":38440014},{"atl":[[6,0]],"id":36201034},{"atl":[[3.05,0]],"id":38276037}],"con":true,"img":false}]}
{"op":"mcm","clk":"5353684412","pt":1646217523697,"mc":[{"id":"1.195453777","rc":[{"atb":[[3.95,15.85]],"id":32633412},{"atb":[[1.94,44.04]],"id":39594662},{"atl":[[2.56,0],[2.54,29.06]],"id":40659166},{"atb":[[17.5,2.72],[14.5,2.5]],"id":38440014},{"atl":[[6.4,8.71]],"id":36201034},{"atl":[[2.82,23.18]],"id":38276037}],"con":true,"img":false}]}
{"op":"mcm","clk":"5353684423","pt":1646217523800,"mc":[{"id":"1.195453777","rc":[{"atl":[[2.66,187.79]],"id":40659166},{"atb":[[17,0],[12,23.63]],"id":38440014}],"con":true,"img":false}]}
{"op":"mcm","clk":"5353684435","pt":1646217523898,"mc":[{"id":"1.195453777","rc":[{"atb":[[18,3.92]],"id":38440014}],"con":true,"img":false}]}
{"op":"mcm","clk":"5353684457","pt":1646217524113,"mc":[{"id":"1.195453777","rc":[{"atl":[[4.5,4],[4.6,0]],"id":36201034}],"con":true,"img":false}]}
{"op":"mcm","clk":"5353684470","pt":1646217524213,"mc":[{"id":"1.195453777","rc":[{"atb":[[2.62,8.77]],"id":39594662},{"atb":[[1.78,0]],"id":40659166}],"con":true,"img":false}]}
{"op":"mcm","clk":"5353684486","pt":1646217524420,"mc":[{"id":"1.195453777","rc":[{"atb":[[1.73,116.98],[1.75,63.2]],"id":40659166}],"con":true,"img":false}]}
{"op":"mcm","clk":"5353684509","pt":1646217524625,"mc":[{"id":"1.195453777","rc":[{"atl":[[4.4,2]],"id":36201034}],"con":true,"img":false}]}
{"op":"mcm","clk":"5353684519","pt":1646217524730,"mc":[{"id":"1.195453777","rc":[{"atb":[[6.4,3],[5.8,0]],"id":32633412},{"atl":[[4.3,4]],"id":36201034}],"con":true,"img":false}]}
{"op":"mcm","clk":"5353684552","pt":1646217524993,"mc":[{"id":"1.195453777","rc":[{"atl":[[9,18.75],[8.8,2.5]],"id":32633412}],"con":true,"img":false}]}
{"op":"mcm","clk":"5353684561","pt":1646217525100,"mc":[{"id":"1.195453777","rc":[{"atb":[[6.4,0],[5.8,2]],"id":32633412},{"atl":[[4.2,2]],"id":36201034}],"con":true,"img":false}]}
{"op":"mcm","clk":"5353684590","pt":1646217525411,"mc":[{"id":"1.195453777","rc":[{"atb":[[6.4,4],[5.8,0]],"id":32633412}],"con":true,"img":false}]}
{"op":"mcm","clk":"5353684655","pt":1646217525884,"mc":[{"id":"1.195453777","rc":[{"atb":[[1.97,3]],"id":39849129},{"atl":[[7.4,0],[7.6,3.03]],"id":39849129}],"con":true,"img":false}]}
{"op":"mcm","clk":"5353684680","pt":1646217526094,"mc":[{"id":"1.195453777","rc":[{"atb":[[6.4,0],[6.2,0],[5.7,3]],"id":32633412},{"atl":[[4.5,0],[4.1,2]],"id":36201034},{"atb":[[1.98,4]],"id":39849129}],"con":true,"img":false}]}
{"op":"mcm","clk":"5353684764","pt":1646217526816,"mc":[{"id":"1.195453777","rc":[{"atl":[[6,13.89],[9.4,71.55]],"id":39594662}],"con":true,"img":false}]}
{"op":"mcm","clk":"5353684776","pt":1646217526924,"mc":[{"id":"1.195453777","rc":[{"atb":[[2.56,5.42]],"id":39594662},{"atb":[[1.75,0]],"id":40659166},{"atb":[[2.98,0]],"id":36201034},{"atb":[[1.58,5.95]],"id":38276037}],"con":true,"img":false}]}
{"op":"mcm","clk":"5353684784","pt":1646217527021,"mc":[{"id":"1.195453777","rc":[{"atl":[[2.66,60.24],[2.68,173.06]],"id":40659166}],"con":true,"img":false}]}
{"op":"mcm","clk":"5353684968","pt":1646217528488,"mc":[{"id":"1.195453777","rc":[{"atb":[[1.73,2.5],[1.69,143.39]],"id":40659166},{"atb":[[1.57,48.26],[1.54,0]],"id":38276037}],"con":true,"img":false}]}
{"op":"mcm","clk":"5353685137","pt":1646217530097,"mc":[{"id":"1.195453777","rc":[{"atb":[[2.6,4.69]],"id":39594662}],"con":true,"img":false}]}
{"op":"mcm","clk":"5353685159","pt":1646217530308,"mc":[{"id":"1.195453777","rc":[{"atb":[[5.8,3]],"id":32633412},{"atb":[[1.7,67.72],[1.5,140]],"id":40659166},{"atl":[[2.7,29.41]],"id":40659166},{"atb":[[3.65,18.87]],"id":38440014},{"atb":[[1.37,135.14]],"id":38276037},{"atl":[[5.7,10.64]],"id":38276037}],"con":true,"img":false}]}
{"op":"mcm","clk":"5353685170","pt":1646217530408,"mc":[{"id":"1.195453777","rc":[{"atb":[[1.5,100]],"id":40659166}],"con":true,"img":false}]}
{"op":"mcm","clk":"5353685180","pt":1646217530512,"mc":[{"id":"1.195453777","rc":[{"atb":[[1.7,206.11],[1.69,5]],"id":40659166}],"con":true,"img":false}]}
{"op":"mcm","clk":"5353685223","pt":1646217531030,"mc":[{"id":"1.195453777","rc":[{"atb":[[3.3,0],[3.2,0],[3.4,0]],"id":38440014},{"atb":[[1.99,3]],"id":39849129}],"con":true,"img":false}]}
{"op":"mcm","clk":"5353685241","pt":1646217531191,"mc":[{"id":"1.195453777","rc":[{"atb":[[2,3]],"id":39849129}],"con":true,"img":false}]}
{"op":"mcm","clk":"5353685292","pt":1646217531614,"mc":[{"id":"1.195453777","rc":[{"atl":[[4.4,0],[4,3]],"id":36201034}],"con":true,"img":false}]}
{"op":"mcm","clk":"5353685327","pt":1646217531920,"mc":[{"id":"1.195453777","rc":[{"atb":[[2.56,0]],"id":39594662}],"con":true,"img":false}]}
{"op":"mcm","clk":"5353685440","pt":1646217532910,"mc":[{"id":"1.195453777","rc":[{"atb":[[1.94,97.23]],"id":39594662},{"atl":[[12,4.55]],"id":39594662}],"con":true,"img":false}]}
{"op":"mcm","clk":"5353685452","pt":1646217533016,"mc":[{"id":"1.195453777","rc":[{"atb":[[1.22,227.27]],"id":36201034},{"atl":[[5.9,10.2]],"id":36201034}],"con":true,"img":false}]}
{"op":"mcm","clk":"5353685517","pt":1646217533541,"mc":[{"id":"1.195453777","rc":[{"atb":[[2.1,0]],"id":39594662},{"atb":[[1.45,0]],"id":38276037}],"con":true,"img":false}]}
{"op":"mcm","clk":"5353685533","pt":1646217533647,"mc":[{"id":"1.195453777","rc":[{"atl":[[6,5]],"id":39594662},{"atl":[[2.54,0]],"id":40659166}],"con":true,"img":false}]}
{"op":"mcm","clk":"5353685543","pt":1646217533704,"mc":[{"id":"1.195453777","rc":[{"atl":[[6.6,8.89]],"id":39594662},{"atl":[[2.64,29.06]],"id":40659166},{"atl":[[2.8,10],[2.72,21.42]],"id":38276037}],"con":true,"img":false}]}
{"op":"mcm","clk":"5353685555","pt":1646217533816,"mc":[{"id":"1.195453777","rc":[{"atl":[[2.68,44.64],[2.7,158.68]],"id":40659166}],"con":true,"img":false}]}
{"op":"mcm","clk":"5353685574","pt":1646217534020,"mc":[{"id":"1.195453777","rc":[{"atl":[[2.7,29.41]],"id":40659166}],"con":true,"img":false}]}
{"op":"mcm","clk":"5353685623","pt":1646217534438,"mc":[{"id":"1.195453777","rc":[{"atl":[[9.4,34.96],[6.6,38.05]],"id":39594662}],"con":true,"img":false}]}
{"op":"mcm","clk":"5353685649","pt":1646217534604,"mc":[{"id":"1.195453777","rc":[{"atl":[[2.68,159.12]],"id":40659166}],"con":true,"img":false}]}
{"op":"mcm","clk":"5353685676","pt":1646217534812,"mc":[{"id":"1.195453777","rc":[{"atb":[[2.66,3.33]],"id":39594662}],"con":true,"img":false}]}
{"op":"mcm","clk":"5353685699","pt":1646217535019,"mc":[{"id":"1.195453777","rc":[{"atb":[[2.66,9.59]],"id":39594662}],"con":true,"img":false}]}
{"op":"mcm","clk":"5353685717","pt":1646217535180,"mc":[{"id":"1.195453777","rc":[{"atb":[[2.62,0]],"id":39594662}],"con":true,"img":false}]}
{"op":"mcm","clk":"5353685852","pt":1646217536121,"mc":[{"id":"1.195453777","rc":[{"atb":[[1.61,12.32]],"id":38276037},{"atb":[[1.88,56.82]],"id":39849129},{"atl":[[8,7.21]],"id":39849129}],"con":true,"img":false}]}
{"op":"mcm","clk":"5353685879","pt":1646217536330,"mc":[{"id":"1.195453777","rc":[{"atb":[[1.1,0]],"id":36201034},{"atl":[[8.6,0],[8.2,0],[7.8,0]],"id":39849129}],"con":true,"img":false}]}
{"op":"mcm","clk":"5353685890","pt":1646217536433,"mc":[{"id":"1.195453777","rc":[{"atl":[[11.5,0],[12.5,0],[13.5,0]],"id":39594662}],"con":true,"img":false}]}
{"op":"mcm","clk":"5353685921","pt":1646217536640,"mc":[{"id":"1.195453777","rc":[{"atb":[[1.7,138.39]],"id":40659166}],"con":true,"img":false}]}
{"op":"mcm","clk":"5353686017","pt":1646217537425,"mc":[{"id":"1.195453777","rc":[{"atb":[[1.6,0]],"id":38276037}],"con":true,"img":false}]}
{"op":"mcm","clk":"5353686031","pt":1646217537530,"mc":[{"id":"1.195453777","rc":[{"atb":[[1.64,2.16]],"id":38276037}],"con":true,"img":false}]}
{"op":"mcm","clk":"5353686065","pt":1646217537840,"mc":[{"id":"1.195453777","rc":[{"atl":[[4.3,0],[3.95,4]],"id":36201034}],"con":true,"img":false}]}
{"op":"mcm","clk":"5353686095","pt":1646217538106,"mc":[{"id":"1.195453777","rc":[{"atl":[[2.64,74.61]],"id":40659166},{"atb":[[12,10.11],[14.5,10.33]],"id":38440014},{"atb":[[1.58,0]],"id":38276037}],"con":true,"img":false}]}
{"op":"mcm","clk":"5353686104","pt":1646217538210,"mc":[{"id":"1.195453777","rc":[{"atb":[[2.64,0]],"id":39594662}],"con":true,"img":false}]}
{"op":"mcm","clk":"5353686117","pt":1646217538321,"mc":[{"id":"1.195453777","rc":[{"atl":[[2.66,12.05]],"id":40659166}],"con":true,"img":false}]}
{"op":"mcm","clk":"5353686127","pt":1646217538421,"mc":[{"id":"1.195453777","rc":[{"atb":[[2.68,1.66]],"id":39594662},{"atb":[[18.5,1.66]],"id":38440014}],"con":true,"img":false}]}
{"op":"mcm","clk":"5353686147","pt":1646217538629,"mc":[{"id":"1.195453777","rc":[{"atb":[[19,3.92]],"id":38440014}],"con":true,"img":false}]}
{"op":"mcm","clk":"5353686158","pt":1646217538735,"mc":[{"id":"1.195453777","rc":[{"atb":[[18,0]],"id":38440014}],"con":true,"img":false}]}
{"op":"mcm","clk":"5353686279","pt":1646217539940,"mc":[{"id":"1.195453777","rc":[{"atb":[[1.71,66.76]],"id":40659166}],"con":true,"img":false}]}
{"op":"mcm","clk":"5353686299","pt":1646217540150,"mc":[{"id":"1.195453777","rc":[{"atb":[[1.7,0],[1.71,214.43]],"id":40659166}],"con":true,"img":false}]}
{"op":"mcm","clk":"5353686342","pt":1646217540520,"mc":[{"id":"1.195453777","rc":[{"atl":[[2.74,43.1]],"id":40659166},{"atb":[[3.55,29.41]],"id":38440014},{"atl":[[5.9,15.31]],"id":38276037}],"con":true,"img":false}]}
{"op":"mcm","clk":"5353686446","pt":1646217541524,"mc":[{"id":"1.195453777","rc":[{"atb":[[2.66,6.26]],"id":39594662},{"atb":[[1.58,8.12]],"id":38276037}],"con":true,"img":false}]}
{"op":"mcm","clk":"5353686505","pt":1646217542054,"mc":[{"id":"1.195453777","rc":[{"atl":[[5.8,0],[5.6,0]],"id":38276037}],"con":true,"img":false}]}
{"op":"mcm","clk":"5353686512","pt":1646217542148,"mc":[{"id":"1.195453777","rc":[{"atl":[[2.72,0],[2.68,114.48]],"id":40659166}],"con":true,"img":false}]}
{"op":"mcm","clk":"5353686522","pt":1646217542251,"mc":[{"id":"1.195453777","rc":[{"atl":[[6.6,0]],"id":39849129}],"con":true,"img":false}]}
{"op":"mcm","clk":"5353686542","pt":1646217542418,"mc":[{"id":"1.195453777","rc":[{"atl":[[6.8,20.01],[7.6,49.76],[7,16.67]],"id":39849129}],"con":true,"img":false}]}
{"op":"mcm","clk":"5353686577","pt":1646217542733,"mc":[{"id":"1.195453777","rc":[{"atb":[[1.58,38.78],[1.57,31.84]],"id":38276037}],"con":true,"img":false}]}
{"op":"mcm","clk":"5353686613","pt":1646217543051,"mc":[{"id":"1.195453777","rc":[{"atb":[[1.92,81.52]],"id":39594662},{"atl":[[13,6.25]],"id":39594662}],"con":true,"img":false}]}
{"op":"mcm","clk":"5353686634","pt":1646217543215,"mc":[{"id":"1.195453777","rc":[{"atb":[[1.2,250]],"id":36201034}],"con":true,"img":false}]}
{"op":"mcm","clk":"5353686652","pt":1646217543420,"mc":[{"id":"1.195453777","rc":[{"atb":[[1.12,0]],"id":36201034}],"con":true,"img":false}]}
{"op":"mcm","clk":"5353686674","pt":1646217543628,"mc":[{"id":"1.195453777","rc":[{"atb":[[1.94,53.19]],"id":39594662},{"atb":[[1.55,0]],"id":38276037}],"con":true,"img":false}]}
{"op":"mcm","clk":"5353686684","pt":1646217543738,"mc":[{"id":"1.195453777","rc":[{"atb":[[1.95,44.04]],"id":39594662},{"atb":[[1.58,113.95]],"id":38276037}],"con":true,"img":false}]}
{"op":"mcm","clk":"5353686753","pt":1646217544418,"mc":[{"id":"1.195453777","rc":[{"atb":[[5.6,4],[6,0]],"id":32633412}],"con":true,"img":false}]}
{"op":"mcm","clk":"5353686832","pt":1646217545148,"mc":[{"id":"1.195453777","rc":[{"atb":[[2.62,5]],"id":39594662}],"con":true,"img":false}]}
{"op":"mcm","clk":"5353686853","pt":1646217545321,"mc":[{"id":"1.195453777","rc":[{"atb":[[2.54,4.66],[2.6,24.1]],"id":39594662}],"con":true,"img":false}]}
{"op":"mcm","clk":"5353686859","pt":1646217545412,"mc":[{"id":"1.195453777","rc":[{"atb":[[1.61,0]],"id":38276037}],"con":true,"img":false}]}
{"op":"mcm","clk":"5353686950","pt":1646217546248,"mc":[{"id":"1.195453777","rc":[{"atb":[[1.86,87.21]],"id":39849129},{"atl":[[8.4,10.14]],"id":39849129}],"con":true,"img":false}]}
{"op":"mcm","clk":"5353687016","pt":1646217546731,"mc":[{"id":"1.195453777","rc":[{"atb":[[5.6,0],[6,4]],"id":32633412},{"atl":[[4.3,2],[3.95,0]],"id":36201034}],"con":true,"img":false}]}
{"op":"mcm","clk":"5353687099","pt":1646217547460,"mc":[{"id":"1.195453777","rc":[{"atb":[[2,0],[1.98,0],[1.99,0],[1.97,0]],"id":39849129},{"atl":[[7.4,3.12]],"id":39849129}],"con":true,"img":false}]}
{"op":"mcm","clk":"5353687126","pt":1646217547622,"mc":[{"id":"1.195453777","rc":[{"atb":[[5.8,0],[6.2,2],[5.7,0]],"id":32633412},{"atl":[[4.4,3],[4,0]],"id":36201034}],"con":true,"img":false}]}
{"op":"mcm","clk":"5353687174","pt":1646217547935,"mc":[{"id":"1.195453777","rc":[{"atb":[[6.4,3]],"id":32633412}],"con":true,"img":false}]}
{"op":"mcm","clk":"5353687198","pt":1646217548142,"mc":[{"id":"1.195453777","rc":[{"atb":[[2.6,19.41]],"id":39594662}],"con":true,"img":false}]}
{"op":"mcm","clk":"5353687207","pt":1646217548245,"mc":[{"id":"1.195453777","rc":[{"atb":[[6.4,0],[5.8,4]],"id":32633412}],"con":true,"img":false}]}
{"op":"mcm","clk":"5353687232","pt":1646217548458,"mc":[{"id":"1.195453777","rc":[{"atl":[[5.8,7.69]],"id":39594662}],"con":true,"img":false}]}
{"op":"mcm","clk":"5353687257","pt":1646217548629,"mc":[{"id":"1.195453777","rc":[{"atl":[[6,28.43],[6.6,8.89]],"id":39594662}],"con":true,"img":false}]}
{"op":"mcm","clk":"5353687339","pt":1646217549248,"mc":[{"id":"1.195453777","rc":[{"atb":[[1.58,83.29],[1.57,111.73]],"id":38276037}],"con":true,"img":false}]}
{"op":"mcm","clk":"5353687377","pt":1646217549517,"mc":[{"id":"1.195453777","rc":[{"atl":[[5.8,0]],"id":39594662}],"con":true,"img":false}]}
{"op":"mcm","clk":"5353687421","pt":1646217549827,"mc":[{"id":"1.195453777","rc":[{"atb":[[2.54,2.16],[2.64,2.5]],"id":39594662}],"con":true,"img":false}]}
{"op":"mcm","clk":"5353687512","pt":1646217550560,"mc":[{"id":"1.195453777","rc":[{"atl":[[2.78,70.22]],"id":40659166},{"atb":[[3.45,51.02]],"id":38440014},{"atl":[[6.2,24.04]],"id":38276037}],"con":true,"img":false}]}
{"op":"mcm","clk":"5353687557","pt":1646217550927,"mc":[{"id":"1.195453777","rc":[{"atb":[[6.4,2],[5.8,0]],"id":32633412},{"atl":[[4.5,2],[4.1,0]],"id":36201034}],"con":true,"img":false}]}
{"op":"mcm","clk":"5353687568","pt":1646217551030,"mc":[{"id":"1.195453777","rc":[{"atl":[[4.4,13.76]],"id":36201034}],"con":true,"img":false}]}
{"op":"mcm","clk":"5353687598","pt":1646217551341,"mc":[{"id":"1.195453777","rc":[{"atl":[[5.8,7.88]],"id":39594662}],"con":true,"img":false}]}
{"op":"mcm","clk":"5353687639","pt":1646217551757,"mc":[{"id":"1.195453777","rc":[{"atl":[[5.8,0]],"id":39594662}],"con":true,"img":false}]}
{"op":"mcm","clk":"5353687652","pt":1646217551813,"mc":[{"id":"1.195453777","rc":[{"atb":[[2.62,0]],"id":39594662}],"con":true,"img":false}]}
{"op":"mcm","clk":"5353687678","pt":1646217552027,"mc":[{"id":"1.195453777","rc":[{"atl":[[5.7,2.19]],"id":39594662}],"con":true,"img":false}]}
{"op":"mcm","clk":"5353687689","pt":1646217552134,"mc":[{"id":"1.195453777","rc":[{"atb":[[14.5,2.5],[17.5,10.55]],"id":38440014}],"con":true,"img":false}]}
{"op":"mcm","clk":"5353687723","pt":1646217552445,"mc":[{"id":"1.195453777","rc":[{"atb":[[6.4,0],[5.8,2]],"id":32633412},{"atl":[[5.5,3.52]],"id":39594662},{"atl":[[2.66,0],[2.7,11.76]],"id":40659166},{"atb":[[2.3,21.1],[2.6,0]],"id":38440014},{"atl":[[4.4,3],[4.5,0],[4.1,3],[4.2,0]],"id":36201034},{"atb":[[1.37,54.05],[1.39,0]],"id":38276037},{"atl":[[5.1,2]],"id":38276037},{"atb":[[1.97,4]],"id":39849129},{"atl":[[7.4,0]],"id":39849129}],"con":true,"img":false}]}
{"op":"mcm","clk":"5353687743","pt":1646217552654,"mc":[{"id":"1.195453777","rc":[{"atb":[[6.2,0],[5.7,4]],"id":32633412},{"atl":[[5.6,2.5]],"id":39594662},{"atl":[[2.68,0],[2.7,146.01]],"id":40659166},{"atl":[[4.5,2],[4.1,0]],"id":36201034},{"atl":[[5,3]],"id":38276037},{"atb":[[1.98,2]],"id":39849129}],"con":true,"img":false}]}
{"op":"mcm","clk":"5353687771","pt":1646217552862,"mc":[{"id":"1.195453777","rc":[{"atl":[[4.6,3]],"id":36201034},{"atl":[[4.9,3]],"id":38276037},{"atb":[[1.99,4]],"id":39849129}],"con":true,"img":false}]}
{"op":"mcm","clk":"5353687782","pt":1646217552966,"mc":[{"id":"1.195453777","rc":[{"atl":[[14,9.62]],"id":39594662}],"con":true,"img":false}]}
{"op":"mcm","clk":"5353687802","pt":1646217553125,"mc":[{"id":"1.195453777","rc":[{"atb":[[1.18,250]],"id":36201034},{"atl":[[4.4,0],[4.5,0],[4.6,0],[4.2,2]],"id":36201034},{"atb":[[1.39,51.28]],"id":38276037},{"atl":[[4.9,0],[5.1,0],[5,0]],"id":38276037},{"atb":[[2,3]],"id":39849129}],"con":true,"img":false}]}
{"op":"mcm","clk":"5353687812","pt":1646217553229,"mc":[{"id":"1.195453777","rc":[{"atb":[[18.5,0]],"id":38440014}],"con":true,"img":false}]}
{"op":"mcm","clk":"5353687823","pt":1646217553341,"mc":[{"id":"1.195453777","rc":[{"atb":[[1.14,0]],"id":36201034},{"atl":[[4.1,2]],"id":36201034}],"con":true,"img":false}]}
{"op":"mcm","clk":"5353687833","pt":1646217553436,"mc":[{"id":"1.195453777","rc":[{"atb":[[19,0],[19.5,1.66]],"id":38440014}],"con":true,"img":false}]}
{"op":"mcm","clk":"5353687849","pt":1646217553542,"mc":[{"id":"1.195453777","rc":[{"atb":[[5.6,2],[6,0]],"id":32633412},{"spn":7.05,"spf":"NaN","id":32633412},{"spn":3.94,"spf":"NaN","id":39594662},{"spn":2.21,"spf":"NaN","id":40659166},{"spn":44.75,"spf":"NaN","id":38440014},{"atl":[[4.3,0],[4,4]],"id":36201034},{"spn":3.57,"spf":"NaN","id":36201034},{"spn":2.04,"spf":"NaN","id":38276037},{"spn":5.15,"spf":"NaN","id":39849129}],"con":true,"img":false}]}
{"op":"mcm","clk":"5353687856","pt":1646217553646,"mc":[{"id":"1.195453777","rc":[{"atb":[[20,3.13]],"id":38440014}],"con":true,"img":false}]}
{"op":"mcm","clk":"5353687871","pt":1646217553752,"mc":[{"id":"1.195453777","rc":[{"atl":[[6.4,0]],"id":36201034},{"atl":[[2.82,0]],"id":38276037}],"con":true,"img":false}]}
{"op":"mcm","clk":"5353687880","pt":1646217553853,"mc":[{"id":"1.195453777","rc":[{"atl":[[6,8.71]],"id":36201034},{"atl":[[3.05,23.18]],"id":38276037}],"con":true,"img":false}]}
{"op":"mcm","clk":"5353687910","pt":1646217554167,"mc":[{"id":"1.195453777","rc":[{"atb":[[5.6,0],[6,2]],"id":32633412},{"atl":[[4.4,2],[4,0]],"id":36201034}],"con":true,"img":false}]}
{"op":"mcm","clk":"5353687935","pt":1646217554333,"mc":[{"id":"1.195453777","rc":[{"atl":[[5.7,0]],"id":39594662}],"con":true,"img":false}]}
{"op":"mcm","clk":"5353687969","pt":1646217554645,"mc":[{"id":"1.195453777","rc":[{"atb":[[5.6,2],[6,0]],"id":32633412},{"atl":[[5.7,1.87]],"id":39594662},{"atl":[[4.4,0],[4,2]],"id":36201034}],"con":true,"img":false}]}
{"op":"mcm","clk":"5353688018","pt":1646217555060,"mc":[{"id":"1.195453777","rc":[{"atl":[[5.7,0]],"id":39594662}],"con":true,"img":false}]}
{"op":"mcm","clk":"5353688045","pt":1646217555271,"mc":[{"id":"1.195453777","rc":[{"atb":[[2.7,3.33]],"id":39594662}],"con":true,"img":false}]}
{"op":"mcm","clk":"5353688058","pt":1646217555367,"mc":[{"id":"1.195453777","rc":[{"atl":[[5.7,2.19]],"id":39594662}],"con":true,"img":false}]}
{"op":"mcm","clk":"5353688071","pt":1646217555426,"mc":[{"id":"1.195453777","rc":[{"atb":[[2.7,7.71]],"id":39594662}],"con":true,"img":false}]}
{"op":"mcm","clk":"5353688093","pt":1646217555626,"mc":[{"id":"1.195453777","rc":[{"atb":[[2.66,0]],"id":39594662}],"con":true,"img":false}]}
{"op":"mcm","clk":"5353688143","pt":1646217556156,"mc":[{"id":"1.195453777","rc":[{"atl":[[3.95,3]],"id":36201034}],"con":true,"img":false}]}
{"op":"mcm","clk":"5353688237","pt":1646217556940,"mc":[{"id":"1.195453777","rc":[{"atb":[[5.6,0],[6,4]],"id":32633412},{"atl":[[4.4,4],[4,0],[3.95,0]],"id":36201034}],"con":true,"img":false}]}
{"op":"mcm","clk":"5353688275","pt":1646217557251,"mc":[{"id":"1.195453777","rc":[{"atl":[[5.7,0]],"id":39594662}],"con":true,"img":false}]}
{"op":"mcm","clk":"5353688286","pt":1646217557353,"mc":[{"id":"1.195453777","rc":[{"atb":[[1.84,148.81]],"id":39849129},{"atl":[[8.8,16.03]],"id":39849129}],"con":true,"img":false}]}
{"op":"mcm","clk":"5353688302","pt":1646217557564,"mc":[{"id":"1.195453777","rc":[{"atb":[[2.52,3]],"id":39594662},{"atl":[[11,0],[12,0]],"id":39594662},{"atl":[[2.68,11.9]],"id":40659166},{"atl":[[4.3,4]],"id":36201034},{"atb":[[2,0],[1.98,0],[1.99,0],[1.97,0],[1.75,0]],"id":39849129},{"atl":[[7.4,3.12],[7.6,46.73]],"id":39849129}],"con":true,"img":false}]}
{"op":"mcm","clk":"5353688334","pt":1646217557771,"mc":[{"id":"1.195453777","rc":[{"atl":[[4.4,0],[4,4]],"id":36201034},{"atl":[[7.4,52.59],[7.6,0]],"id":39849129}],"con":true,"img":false}]}
{"op":"mcm","clk":"5353688406","pt":1646217558275,"mc":[{"id":"1.195453777","rc":[{"atb":[[2.54,5.16]],"id":39594662},{"atl":[[12,1.82]],"id":39594662},{"atl":[[4.3,0],[3.95,2]],"id":36201034}],"con":true,"img":false}]}
{"op":"mcm","clk":"5353688458","pt":1646217558760,"mc":[{"id":"1.195453777","rc":[{"atb":[[2.56,4]],"id":39594662},{"atl":[[12,0]],"id":39594662},{"atl":[[3.9,2],[4.2,0]],"id":36201034}],"con":true,"img":false}]}
{"op":"mcm","clk":"5353688466","pt":1646217558865,"mc":[{"id":"1.195453777","rc":[{"atl":[[5.8,7.88]],"id":39594662}],"con":true,"img":false}]}
{"op":"mcm","clk":"5353688527","pt":1646217559243,"mc":[{"id":"1.195453777","rc":[{"atb":[[1.95,0]],"id":39594662},{"atl":[[6.6,0]],"id":39594662},{"atl":[[2.64,45.55]],"id":40659166},{"atb":[[1.58,8.12],[1.34,0]],"id":38276037},{"atb":[[2.76,37.91],[2.42,0]],"id":39849129},{"atl":[[16,0]],"id":39849129}],"con":true,"img":false}]}
{"op":"mcm","clk":"5353688540","pt":1646217559345,"mc":[{"id":"1.195453777","rc":[{"atb":[[1.91,44.04]],"id":39594662},{"atl":[[5.9,8.89]],"id":39594662},{"atl":[[2.62,29.06]],"id":40659166},{"atb":[[1.3,77.66],[1.38,75.17]],"id":38276037},{"atl":[[19,13.39]],"id":39849129}],"con":true,"img":false}]}
{"op":"mcm","clk":"5353688557","pt":1646217559556,"mc":[{"id":"1.195453777","rc":[{"atl":[[2.62,70.67]],"id":40659166}],"con":true,"img":false}]}
{"op":"mcm","clk":"5353688581","pt":1646217559757,"mc":[{"id":"1.195453777","rc":[{"atb":[[5.6,4],[6,0]],"id":32633412},{"atb":[[2.58,2]],"id":39594662},{"atl":[[12,1.82]],"id":39594662},{"atl":[[2.64,0]],"id":40659166}],"con":true,"img":false}]}
{"op":"mcm","clk":"5353688608","pt":1646217560072,"mc":[{"id":"1.195453777","rc":[{"atl":[[12,0]],"id":39594662}],"con":true,"img":false}]}
{"op":"mcm","clk":"5353688658","pt":1646217560445,"mc":[{"id":"1.195453777","rc":[{"atl":[[12,1.82]],"id":39594662}],"con":true,"img":false}]}
{"op":"mcm","clk":"5353688677","pt":1646217560651,"mc":[{"id":"1.195453777","rc":[{"atl":[[5.8,0]],"id":39594662}],"con":true,"img":false}]}
{"op":"mcm","clk":"5353688708","pt":1646217560964,"mc":[{"id":"1.195453777","rc":[{"atb":[[5.6,0],[6,4]],"id":32633412},{"atl":[[12,0]],"id":39594662},{"atl":[[3.9,0],[4.2,4]],"id":36201034}],"con":true,"img":false}]}
{"op":"mcm","clk":"5353688750","pt":1646217561328,"mc":[{"id":"1.195453777","rc":[{"atl":[[12,1.82]],"id":39594662}],"con":true,"img":false}]}
{"op":"mcm","clk":"5353688760","pt":1646217561432,"mc":[{"id":"1.195453777","rc":[{"atb":[[1.71,147.67]],"id":40659166}],"con":true,"img":false}]}
{"op":"mcm","clk":"5353688856","pt":1646217562469,"mc":[{"id":"1.195453777","rc":[{"atl":[[6,5],[5.9,26.73]],"id":39594662}],"con":true,"img":false}]}
{"op":"mcm","clk":"5353688865","pt":1646217562571,"mc":[{"id":"1.195453777","rc":[{"atl":[[12,0]],"id":39594662}],"con":true,"img":false}]}
{"op":"mcm","clk":"5353688882","pt":1646217562780,"mc":[{"id":"1.195453777","rc":[{"atb":[[6.2,4],[5.7,0]],"id":32633412},{"atl":[[12,1.82]],"id":39594662},{"atl":[[4.3,3],[3.95,0]],"id":36201034},{"atl":[[8,9.71]],"id":39849129}],"con":true,"img":false}]}
{"op":"mcm","clk":"5353688901","pt":1646217562946,"mc":[{"id":"1.195453777","rc":[{"atl":[[5.6,4.61]],"id":39594662},{"atb":[[1.37,135.14]],"id":38276037}],"con":true,"img":false}]}
{"op":"mcm","clk":"5353688959","pt":1646217563460,"mc":[{"id":"1.195453777","rc":[{"atl":[[12,0]],"id":39594662}],"con":true,"img":false}]}
{"op":"mcm","clk":"5353688973","pt":1646217563571,"mc":[{"id":"1.195453777","rc":[{"atl":[[5.6,2.5]],"id":39594662}],"con":true,"img":false}]}
{"op":"mcm","clk":"5353689072","pt":1646217564353,"mc":[{"id":"1.195453777","rc":[{"atl":[[12,1.82]],"id":39594662}],"con":true,"img":false}]}
{"op":"mcm","clk":"5353689093","pt":1646217564559,"mc":[{"id":"1.195453777","rc":[{"atb":[[1.74,64.06]],"id":40659166}],"con":true,"img":false}]}
{"op":"mcm","clk":"5353689100","pt":1646217564660,"mc":[{"id":"1.195453777","rc":[{"atl":[[12,0]],"id":39594662}],"con":true,"img":false}]}
{"op":"mcm","clk":"5353689111","pt":1646217564770,"mc":[{"id":"1.195453777","rc":[{"atb":[[1.73,146.11],[1.71,0]],"id":40659166}],"con":true,"img":false}]}
{"op":"mcm","clk":"5353689179","pt":1646217565345,"mc":[{"id":"1.195453777","rc":[{"atl":[[12,1.82]],"id":39594662}],"con":true,"img":false}]}
{"op":"mcm","clk":"5353689258","pt":1646217566183,"mc":[{"id":"1.195453777","rc":[{"atl":[[5.4,3.75]],"id":39594662}],"con":true,"img":false}]}
{"op":"mcm","clk":"5353689281","pt":1646217566385,"mc":[{"id":"1.195453777","rc":[{"atl":[[12,0],[5.5,0]],"id":39594662}],"con":true,"img":false}]}
{"op":"mcm","clk":"5353689301","pt":1646217566550,"mc":[{"id":"1.195453777","rc":[{"atl":[[5.6,5.02]],"id":39594662}],"con":true,"img":false}]}
{"op":"mcm","clk":"5353689350","pt":1646217566960,"mc":[{"id":"1.195453777","rc":[{"atb":[[12,0]],"id":38440014}],"con":true,"img":false}]}
{"op":"mcm","clk":"5353689360","pt":1646217567067,"mc":[{"id":"1.195453777","rc":[{"atb":[[13,10.11]],"id":38440014}],"con":true,"img":false}]}
{"op":"mcm","clk":"5353689381","pt":1646217567272,"mc":[{"id":"1.195453777","rc":[{"atl":[[2.72,29.07]],"id":40659166}],"con":true,"img":false}]}
{"op":"mcm","clk":"5353689411","pt":1646217567479,"mc":[{"id":"1.195453777","rc":[{"atb":[[2.54,2.16],[2.58,0],[2.56,0],[2.52,0]],"id":39594662},{"atl":[[12,1.82]],"id":39594662},{"atl":[[2.72,0],[2.68,0]],"id":40659166},{"atb":[[1.97,3]],"id":39849129},{"atl":[[7.4,49.47],[7.6,3.03]],"id":39849129}],"con":true,"img":false}]}
{"op":"mcm","clk":"5353689423","pt":1646217567580,"mc":[{"id":"1.195453777","rc":[{"atl":[[11,2]],"id":39594662}],"con":true,"img":false}]}
{"op":"mcm","clk":"5353689430","pt":1646217567685,"mc":[{"id":"1.195453777","rc":[{"atb":[[5.6,3],[6.2,0],[6,0]],"id":32633412},{"atl":[[5.6,2.5]],"id":39594662},{"atl":[[2.74,179.3],[2.7,11.76]],"id":40659166},{"atl":[[4.3,0],[3.95,2],[4.2,0]],"id":36201034},{"atb":[[1.98,2]],"id":39849129}],"con":true,"img":false}]}
{"op":"mcm","clk":"5353689468","pt":1646217567954,"mc":[{"id":"1.195453777","rc":[{"atl":[[5.4,5.96]],"id":39594662}],"con":true,"img":false}]}
{"op":"mcm","clk":"5353689545","pt":1646217568576,"mc":[{"id":"1.195453777","rc":[{"atb":[[5.6,0],[5.7,3]],"id":32633412},{"atl":[[4.2,3]],"id":36201034},{"atb":[[1.99,3]],"id":39849129}],"con":true,"img":false}]}
{"op":"mcm","clk":"5353689574","pt":1646217568845,"mc":[{"id":"1.195453777","rc":[{"atl":[[5.4,3.75]],"id":39594662}],"con":true,"img":false}]}
{"op":"mcm","clk":"5353689626","pt":1646217569265,"mc":[{"id":"1.195453777","rc":[{"atb":[[2.68,0]],"id":39594662},{"atb":[[19.5,0]],"id":38440014}],"con":true,"img":false}]}
{"op":"mcm","clk":"5353689639","pt":1646217569366,"mc":[{"id":"1.195453777","rc":[{"atb":[[2.72,1.66]],"id":39594662}],"con":true,"img":false}]}
{"op":"mcm","clk":"5353689647","pt":1646217569470,"mc":[{"id":"1.195453777","rc":[{"atb":[[17.5,2.72],[20,0],[14.5,10.94]],"id":38440014}],"con":true,"img":false}]}
{"op":"mcm","clk":"5353689657","pt":1646217569576,"mc":[{"id":"1.195453777","rc":[{"atb":[[6,3]],"id":32633412},{"atb":[[18,4.22]],"id":38440014},{"atb":[[2,4]],"id":39849129}],"con":true,"img":false}]}
{"op":"mcm","clk":"5353689695","pt":1646217569987,"mc":[{"id":"1.195453777","rc":[{"atb":[[5.6,2],[6,0]],"id":32633412},{"atl":[[3.9,4],[4.2,0]],"id":36201034}],"con":true,"img":false}]}
{"op":"mcm","clk":"5353689794","pt":1646217570880,"mc":[{"id":"1.195453777","rc":[{"atb":[[2.7,4.38]],"id":39594662}],"con":true,"img":false}]}
{"op":"mcm","clk":"5353689807","pt":1646217570982,"mc":[{"id":"1.195453777","rc":[{"atl":[[5.7,1.6]],"id":39594662}],"con":true,"img":false}]}
{"op":"mcm","clk":"5353689912","pt":1646217571885,"mc":[{"id":"1.195453777","rc":[{"atb":[[2.58,0]],"id":36201034}],"con":true,"img":false}]}
{"op":"mcm","clk":"5353689920","pt":1646217571981,"mc":[{"id":"1.195453777","rc":[{"atb":[[2.96,28.43]],"id":36201034}],"con":true,"img":false}]}
{"op":"mcm","clk":"5353689992","pt":1646217572563,"mc":[{"id":"1.195453777","rc":[{"atb":[[2.52,4]],"id":39594662},{"atl":[[11,0],[12,0]],"id":39594662},{"atl":[[2.68,11.9]],"id":40659166},{"atb":[[2,0],[1.98,0],[1.99,0],[1.97,0]],"id":39849129},{"atl":[[7.4,52.59],[7.6,0]],"id":39849129}],"con":true,"img":false}]}
{"op":"mcm","clk":"5353690019","pt":1646217572775,"mc":[{"id":"1.195453777","rc":[{"atb":[[2.54,4.16]],"id":39594662},{"atl":[[12,1.82]],"id":39594662}],"con":true,"img":false}]}
{"op":"mcm","clk":"5353690044","pt":1646217572981,"mc":[{"id":"1.195453777","rc":[{"atb":[[5.6,0],[6,2]],"id":32633412},{"atb":[[2.54,2.16],[2.52,0]],"id":39594662},{"atl":[[11,2]],"id":39594662},{"atl":[[3.9,0],[4.2,2]],"id":36201034}],"con":true,"img":false}]}
{"op":"mcm","clk":"5353690053","pt":1646217573084,"mc":[{"id":"1.195453777","rc":[{"atb":[[2.56,2]],"id":39594662},{"atl":[[12,0],[5.7,0]],"id":39594662}],"con":true,"img":false}]}
{"op":"mcm","clk":"5353690065","pt":1646217573187,"mc":[{"id":"1.195453777","rc":[{"atb":[[6.2,2],[5.7,0]],"id":32633412},{"atl":[[11,0]],"id":39594662},{"atl":[[4.3,4],[3.95,0]],"id":36201034}],"con":true,"img":false}]}
{"op":"mcm","clk":"5353690078","pt":1646217573292,"mc":[{"id":"1.195453777","rc":[{"atb":[[1.37,96.68],[1.47,0]],"id":40659166}],"con":true,"img":false}]}
{"op":"mcm","clk":"5353690105","pt":1646217573498,"mc":[{"id":"1.195453777","rc":[{"atb":[[2.52,3]],"id":39594662},{"atl":[[12,1.82]],"id":39594662}],"con":true,"img":false}]}
{"op":"mcm","clk":"5353690125","pt":1646217573662,"mc":[{"id":"1.195453777","rc":[{"atl":[[5.7,1.6]],"id":39594662}],"con":true,"img":false}]}
{"op":"mcm","clk":"5353690136","pt":1646217573759,"mc":[{"id":"1.195453777","rc":[{"atb":[[2.54,6.16]],"id":39594662},{"atl":[[12,0]],"id":39594662}],"con":true,"img":false}]}
{"op":"mcm","clk":"5353690145","pt":1646217573869,"mc":[{"id":"1.195453777","rc":[{"atb":[[6.2,0],[5.7,4]],"id":32633412}],"con":true,"img":false}]}
{"op":"mcm","clk":"5353690183","pt":1646217574179,"mc":[{"id":"1.195453777","rc":[{"atb":[[2.66,5]],"id":39594662}],"con":true,"img":false}]}
{"op":"mcm","clk":"5353690209","pt":1646217574387,"mc":[{"id":"1.195453777","rc":[{"atb":[[2.64,15.84],[2.6,0]],"id":39594662}],"con":true,"img":false}]}
{"op":"mcm","clk":"5353690218","pt":1646217574490,"mc":[{"id":"1.195453777","rc":[{"atb":[[2.58,3]],"id":39594662},{"atl":[[12,1.82]],"id":39594662}],"con":true,"img":false}]}
{"op":"mcm","clk":"5353690279","pt":1646217575065,"mc":[{"id":"1.195453777","rc":[{"atb":[[2.54,2.16],[2.58,0],[2.56,0],[2.52,0]],"id":39594662},{"atl":[[11,2]],"id":39594662}],"con":true,"img":false}]}
{"op":"mcm","clk":"5353690288","pt":1646217575169,"mc":[{"id":"1.195453777","rc":[{"atb":[[6.2,4],[5.7,0]],"id":32633412},{"atl":[[4.4,4],[4,0]],"id":36201034}],"con":true,"img":false}]}
{"op":"mcm","clk":"5353690300","pt":1646217575277,"mc":[{"id":"1.195453777","rc":[{"atb":[[2.52,2]],"id":39594662},{"atl":[[11,0],[12,0],[5.7,0]],"id":39594662}],"con":true,"img":false}]}
{"op":"mcm","clk":"5353690336","pt":1646217575586,"mc":[{"id":"1.195453777","rc":[{"atl":[[5.7,1.6]],"id":39594662}],"con":true,"img":false}]}
{"op":"mcm","clk":"5353690377","pt":1646217575905,"mc":[{"id":"1.195453777","rc":[{"atb":[[6.2,0],[5.7,4]],"id":32633412},{"atl":[[9,6.25],[9.2,12.2]],"id":32633412},{"atb":[[2.54,6.16],[2.52,0]],"id":39594662},{"atl":[[11,2],[12,1.82]],"id":39594662},{"atl":[[2.66,12.05],[2.68,0]],"id":40659166},{"atb":[[2.3,0]],"id":38440014},{"atl":[[5.8,0],[4.4,0],[4,4]],"id":36201034},{"atl":[[2.6,8.21]],"id":38276037}],"con":true,"img":false}]}
{"op":"mcm","clk":"5353690399","pt":1646217576062,"mc":[{"id":"1.195453777","rc":[{"atl":[[6.6,39.76]],"id":36201034},{"atl":[[2.72,4.99],[2.64,27.89],[2.62,0]],"id":38276037}],"con":true,"img":false}]}
{"op":"mcm","clk":"5353690637","pt":1646217578158,"mc":[{"id":"1.195453777","rc":[{"atb":[[2.54,2.16]],"id":39594662},{"atl":[[2.66,0],[2.68,11.9]],"id":40659166},{"atb":[[1.97,4]],"id":39849129},{"atl":[[7.4,49.47],[7.6,3.03]],"id":39849129}],"con":true,"img":false}]}
{"op":"mcm","clk":"5353690657","pt":1646217578366,"mc":[{"id":"1.195453777","rc":[{"atb":[[5.9,0],[5.5,4],[6,0]],"id":32633412},{"atl":[[8.8,0],[8.4,7.94]],"id":32633412},{"atb":[[3.1,0],[2.98,5],[2.88,0],[3.15,4.16],[2.96,23.43]],"id":36201034},{"atl":[[4.3,0],[3.95,2],[4.2,0]],"id":36201034},{"atl":[[2.8,0],[2.72,0],[2.64,25.39],[2.62,2.5],[2.7,5]],"id":38276037},{"atb":[[1.98,3]],"id":39849129}],"con":true,"img":false}]}
{"op":"mcm","clk":"5353690689","pt":1646217578680,"mc":[{"id":"1.195453777","rc":[{"atl":[[5.4,6.25]],"id":39594662}],"con":true,"img":false}]}
{"op":"mcm","clk":"5353690705","pt":1646217578781,"mc":[{"id":"1.195453777","rc":[{"atb":[[5.6,2],[5.5,0]],"id":32633412},{"atl":[[5.6,0],[6,0]],"id":39594662},{"atl":[[4.2,2]],"id":36201034},{"atb":[[1.99,3]],"id":39849129}],"con":true,"img":false}]}
{"op":"mcm","clk":"5353690719","pt":1646217578884,"mc":[{"id":"1.195453777","rc":[{"atl":[[5.9,17.84]],"id":39594662},{"atb":[[1.54,0]],"id":40659166},{"atl":[[2.62,41.61]],"id":40659166}],"con":true,"img":false}]}
{"op":"mcm","clk":"5353690729","pt":1646217578993,"mc":[{"id":"1.195453777","rc":[{"atl":[[5.8,8.89],[5.9,0],[9.4,68.29]],"id":39594662},{"atb":[[1.53,96.88]],"id":40659166},{"atl":[[2.6,29.4]],"id":40659166}],"con":true,"img":false}]}
{"op":"mcm","clk":"5353690751","pt":1646217579198,"mc":[{"id":"1.195453777","rc":[{"atl":[[2.6,70.63]],"id":40659166}],"con":true,"img":false}]}
{"op":"mcm","clk":"5353690776","pt":1646217579366,"mc":[{"id":"1.195453777","rc":[{"atl":[[2.62,0]],"id":40659166}],"con":true,"img":false}]}
{"op":"mcm","clk":"5353690888","pt":1646217580503,"mc":[{"id":"1.195453777","rc":[{"atb":[[5.5,3]],"id":32633412},{"atl":[[3.9,4],[4.2,0]],"id":36201034},{"atb":[[2,3]],"id":39849129}],"con":true,"img":false}]}
{"op":"mcm","clk":"5353690926","pt":1646217580874,"mc":[{"id":"1.195453777","rc":[{"atl":[[5.8,0]],"id":39594662}],"con":true,"img":false}]}
{"op":"mcm","clk":"5353690935","pt":1646217580982,"mc":[{"id":"1.195453777","rc":[{"atl":[[6.4,9]],"id":39594662}],"con":true,"img":false}]}
{"op":"mcm","clk":"5353690945","pt":1646217581082,"mc":[{"id":"1.195453777","rc":[{"atl":[[2.74,43.1],[2.7,153.53]],"id":40659166}],"con":true,"img":false}]}
{"op":"mcm","clk":"5353690977","pt":1646217581394,"mc":[{"id":"1.195453777","rc":[{"atb":[[5.9,3],[5.5,0]],"id":32633412},{"atl":[[3.9,0],[4.2,2]],"id":36201034}],"con":true,"img":false}]}
{"op":"mcm","clk":"5353690987","pt":1646217581502,"mc":[{"id":"1.195453777","rc":[{"atl":[[5.7,0]],"id":39594662}],"con":true,"img":false}]}
{"op":"mcm","clk":"5353691104","pt":1646217582806,"mc":[{"id":"1.195453777","rc":[{"atb":[[5.5,3]],"id":32633412},{"atl":[[3.9,3]],"id":36201034}],"con":true,"img":false}]}
{"op":"mcm","clk":"5353691116","pt":1646217582907,"mc":[{"id":"1.195453777","rc":[{"atb":[[5.9,0]],"id":32633412},{"atb":[[17.5,0]],"id":38440014},{"atl":[[4.2,0]],"id":36201034}],"con":true,"img":false}]}
{"op":"mcm","clk":"5353691128","pt":1646217583017,"mc":[{"id":"1.195453777","rc":[{"atb":[[18.5,2.72]],"id":38440014}],"con":true,"img":false}]}
{"op":"mcm","clk":"5353691138","pt":1646217583073,"mc":[{"id":"1.195453777","rc":[{"atb":[[18,0],[13,22.49],[14.5,2.5]],"id":38440014}],"con":true,"img":false}]}
{"op":"mcm","clk":"5353691152","pt":1646217583205,"mc":[{"id":"1.195453777","rc":[{"atb":[[19,4.44]],"id":38440014}],"con":true,"img":false}]}
{"op":"mcm","clk":"5353691165","pt":1646217583278,"mc":[{"id":"1.195453777","rc":[{"atl":[[2.66,12.05],[2.68,0]],"id":40659166},{"atb":[[2,0],[1.98,0],[1.99,0],[1.97,0]],"id":39849129},{"atl":[[7.4,52.59],[7.6,0]],"id":39849129}],"con":true,"img":false}]}
{"op":"mcm","clk":"5353691243","pt":1646217584171,"mc":[{"id":"1.195453777","rc":[{"atb":[[5.9,2]],"id":32633412},{"atl":[[3.9,0],[4.2,4]],"id":36201034}],"con":true,"img":false}]}
{"op":"mcm","clk":"5353691252","pt":1646217584278,"mc":[{"id":"1.195453777","rc":[{"atb":[[5.6,0],[5.5,0]],"id":32633412}],"con":true,"img":false}]}
{"op":"mcm","clk":"5353691262","pt":1646217584380,"mc":[{"id":"1.195453777","rc":[{"atb":[[5.9,0]],"id":32633412},{"atl":[[3.9,2],[4.2,0]],"id":36201034}],"con":true,"img":false}]}
{"op":"mcm","clk":"5353691272","pt":1646217584486,"mc":[{"id":"1.195453777","rc":[{"atb":[[4.2,36.66]],"id":32633412}],"con":true,"img":false}]}
{"op":"mcm","clk":"5353691356","pt":1646217585188,"mc":[{"id":"1.195453777","rc":[{"atb":[[19.5,1.66]],"id":38440014}],"con":true,"img":false}]}
{"op":"mcm","clk":"5353691368","pt":1646217585270,"mc":[{"id":"1.195453777","rc":[{"atl":[[12,4.55]],"id":39594662}],"con":true,"img":false}]}
{"op":"mcm","clk":"5353691442","pt":1646217586000,"mc":[{"id":"1.195453777","rc":[{"atb":[[5.9,4]],"id":32633412},{"atl":[[3.9,0],[4.2,2]],"id":36201034}],"con":true,"img":false}]}
{"op":"mcm","clk":"5353691465","pt":1646217586204,"mc":[{"id":"1.195453777","rc":[{"atb":[[4.2,11.58]],"id":32633412}],"con":true,"img":false}]}
{"op":"mcm","clk":"5353691764","pt":1646217588613,"mc":[{"id":"1.195453777","rc":[{"atb":[[5.9,0],[5.5,2]],"id":32633412},{"atl":[[5.3,7.04]],"id":39594662},{"atl":[[3.9,2],[4.2,0]],"id":36201034}],"con":true,"img":false}]}
{"op":"mcm","clk":"5353691787","pt":1646217588819,"mc":[{"id":"1.195453777","rc":[{"atb":[[5.9,3],[5.5,0]],"id":32633412},{"atl":[[5.4,2.5]],"id":39594662},{"atl":[[4.3,4],[3.95,0],[3.9,0]],"id":36201034}],"con":true,"img":false}]}
{"op":"mcm","clk":"5353691845","pt":1646217589405,"mc":[{"id":"1.195453777","rc":[{"atb":[[6,4]],"id":32633412},{"atl":[[4.2,4]],"id":36201034}],"con":true,"img":false}]}
{"op":"mcm","clk":"5353691960","pt":1646217590396,"mc":[{"id":"1.195453777","rc":[{"atl":[[4.4,4],[4,0]],"id":36201034}],"con":true,"img":false}]}
