{"op":"mcm","clk":"5346220767","pt":1646178839799,"mc":[{"id":"1.195453675","marketDefinition":{"bspMarket":false,"turnInPlayEnabled":false,"persistenceEnabled":false,"marketBaseRate":7.0,"eventId":"31272494","eventTypeId":"4339","numberOfWinners":1,"bettingType":"ODDS","marketType":"MATCH_BET","marketTime":"2022-03-02T10:27:00.000Z","suspendTime":"2022-03-02T10:27:00.000Z","bspReconciled":false,"complete":true,"inPlay":false,"crossMatching":true,"runnersVoidable":false,"numberOfActiveRunners":2,"betDelay":0,"status":"OPEN","runners":[{"status":"ACTIVE","sortPriority":1,"id":40250501,"name":"1. Dwarshuis"},{"status":"ACTIVE","sortPriority":2,"id":6780934,"name":"2. Peacock"}],"regulators":["MR_INT"],"venue":"Traralgon","countryCode":"AU","discountAllowed":true,"timezone":"Australia/Sydney","openDate":"2022-03-02T08:31:00.000Z","version":4382489947,"name":"Dwarshuis v Peacock","eventName":"Traralgon (AUS) 2nd Mar"},"rc":[],"con":true,"img":false}]}
{"op":"mcm","clk":"5346224660","pt":1646178919306,"mc":[{"id":"1.195453675","rc":[{"atb":[[1.85,6.34],[1.95,5.67],[2.1,4.89]],"id":40250501},{"atb":[[1.27,19.96],[1.37,14.56],[1.47,11.46]],"id":6780934}],"con":true,"img":false}]}
{"op":"mcm","clk":"5346401492","pt":1646182002783,"mc":[{"id":"1.195453675","marketDefinition":{"bspMarket":false,"turnInPlayEnabled":false,"persistenceEnabled":false,"marketBaseRate":7.0,"eventId":"31272494","eventTypeId":"4339","numberOfWinners":1,"bettingType":"ODDS","marketType":"MATCH_BET","marketTime":"2022-03-02T10:27:00.000Z","suspendTime":"2022-03-02T10:27:00.000Z","bspReconciled":false,"complete":true,"inPlay":false,"crossMatching":true,"runnersVoidable":false,"numberOfActiveRunners":2,"betDelay":0,"status":"OPEN","runners":[{"status":"ACTIVE","sortPriority":1,"id":40250501,"name":"1. Dwarshuis"},{"status":"ACTIVE","sortPriority":2,"id":6780934,"name":"2. Peacock"}],"regulators":["MR_INT"],"venue":"Traralgon","countryCode":"AU","discountAllowed":true,"timezone":"Australia/Sydney","openDate":"2022-03-02T08:31:00.000Z","version":4382489947,"name":"Dwarshuis v Peacock","eventName":"Traralgon (AUS) 2nd Mar"},"rc":[{"atb":[[1.85,6.34],[1.95,5.67],[2.1,4.89]],"id":40250501},{"atb":[[1.27,19.96],[1.37,14.56],[1.47,11.46]],"id":6780934}],"con":true,"img":true}]}
{"op":"mcm","clk":"5346767847","pt":1646187402728,"mc":[{"id":"1.195453675","marketDefinition":{"bspMarket":false,"turnInPlayEnabled":false,"persistenceEnabled":false,"marketBaseRate":7.0,"eventId":"31272494","eventTypeId":"4339","numberOfWinners":1,"bettingType":"ODDS","marketType":"MATCH_BET","marketTime":"2022-03-02T10:27:00.000Z","suspendTime":"2022-03-02T10:27:00.000Z","bspReconciled":false,"complete":true,"inPlay":false,"crossMatching":true,"runnersVoidable":false,"numberOfActiveRunners":2,"betDelay":0,"status":"OPEN","runners":[{"status":"ACTIVE","sortPriority":1,"id":40250501,"name":"1. Dwarshuis"},{"status":"ACTIVE","sortPriority":2,"id":6780934,"name":"2. Peacock"}],"regulators":["MR_INT"],"venue":"Traralgon","countryCode":"AU","discountAllowed":true,"timezone":"Australia/Sydney","openDate":"2022-03-02T08:31:00.000Z","version":4382489947,"name":"Dwarshuis v Peacock","eventName":"Traralgon (AUS) 2nd Mar"},"rc":[{"atb":[[1.85,6.35],[1.95,5.68],[2.1,4.9]],"id":40250501},{"atb":[[1.27,19.99],[1.37,14.59],[1.47,11.48]],"id":6780934}],"con":true,"img":true}]}
{"op":"mcm","clk":"5347092398","pt":1646192802708,"mc":[{"id":"1.195453675","marketDefinition":{"bspMarket":false,"turnInPlayEnabled":false,"persistenceEnabled":false,"marketBaseRate":7.0,"eventId":"31272494","eventTypeId":"4339","numberOfWinners":1,"bettingType":"ODDS","marketType":"MATCH_BET","marketTime":"2022-03-02T10:27:00.000Z","suspendTime":"2022-03-02T10:27:00.000Z","bspReconciled":false,"complete":true,"inPlay":false,"crossMatching":true,"runnersVoidable":false,"numberOfActiveRunners":2,"betDelay":0,"status":"OPEN","runners":[{"status":"ACTIVE","sortPriority":1,"id":40250501,"name":"1. Dwarshuis"},{"status":"ACTIVE","sortPriority":2,"id":6780934,"name":"2. Peacock"}],"regulators":["MR_INT"],"venue":"Traralgon","countryCode":"AU","discountAllowed":true,"timezone":"Australia/Sydney","openDate":"2022-03-02T08:31:00.000Z","version":4382489947,"name":"Dwarshuis v Peacock","eventName":"Traralgon (AUS) 2nd Mar"},"rc":[{"atb":[[1.85,6.36],[1.95,5.69],[2.1,4.91]],"id":40250501},{"atb":[[1.27,20.02],[1.37,14.61],[1.47,11.5]],"id":6780934}],"con":true,"img":true}]}
{"op":"mcm","clk":"5347381259","pt":1646198202726,"mc":[{"id":"1.195453675","marketDefinition":{"bspMarket":false,"turnInPlayEnabled":false,"persistenceEnabled":false,"marketBaseRate":7.0,"eventId":"31272494","eventTypeId":"4339","numberOfWinners":1,"bettingType":"ODDS","marketType":"MATCH_BET","marketTime":"2022-03-02T10:27:00.000Z","suspendTime":"2022-03-02T10:27:00.000Z","bspReconciled":false,"complete":true,"inPlay":false,"crossMatching":true,"runnersVoidable":false,"numberOfActiveRunners":2,"betDelay":0,"status":"OPEN","runners":[{"status":"ACTIVE","sortPriority":1,"id":40250501,"name":"1. Dwarshuis"},{"status":"ACTIVE","sortPriority":2,"id":6780934,"name":"2. Peacock"}],"regulators":["MR_INT"],"venue":"Traralgon","countryCode":"AU","discountAllowed":true,"timezone":"Australia/Sydney","openDate":"2022-03-02T08:31:00.000Z","version":4382489947,"name":"Dwarshuis v Peacock","eventName":"Traralgon (AUS) 2nd Mar"},"rc":[{"atb":[[1.85,6.36],[1.95,5.68],[2.1,4.91]],"id":40250501},{"atb":[[1.27,20.02],[1.37,14.61],[1.47,11.49]],"id":6780934}],"con":true,"img":true}]}
{"op":"mcm","clk":"5347848931","pt":1646209002729,"mc":[{"id":"1.195453675","marketDefinition":{"bspMarket":false,"turnInPlayEnabled":false,"persistenceEnabled":false,"marketBaseRate":7.0,"eventId":"31272494","eventTypeId":"4339","numberOfWinners":1,"bettingType":"ODDS","marketType":"MATCH_BET","marketTime":"2022-03-02T10:27:00.000Z","suspendTime":"2022-03-02T10:27:00.000Z","bspReconciled":false,"complete":true,"inPlay":false,"crossMatching":true,"runnersVoidable":false,"numberOfActiveRunners":2,"betDelay":0,"status":"OPEN","runners":[{"status":"ACTIVE","sortPriority":1,"id":40250501,"name":"1. Dwarshuis"},{"status":"ACTIVE","sortPriority":2,"id":6780934,"name":"2. Peacock"}],"regulators":["MR_INT"],"venue":"Traralgon","countryCode":"AU","discountAllowed":true,"timezone":"Australia/Sydney","openDate":"2022-03-02T08:31:00.000Z","version":4382489947,"name":"Dwarshuis v Peacock","eventName":"Traralgon (AUS) 2nd Mar"},"rc":[{"atb":[[1.85,6.35],[1.95,5.68],[2.1,4.91]],"id":40250501},{"atb":[[1.27,20.01],[1.37,14.6],[1.47,11.49]],"id":6780934}],"con":true,"img":true}]}
{"op":"mcm","clk":"5348133114","pt":1646214402739,"mc":[{"id":"1.195453675","marketDefinition":{"bspMarket":false,"turnInPlayEnabled":false,"persistenceEnabled":false,"marketBaseRate":7.0,"eventId":"31272494","eventTypeId":"4339","numberOfWinners":1,"bettingType":"ODDS","marketType":"MATCH_BET","marketTime":"2022-03-02T10:27:00.000Z","suspendTime":"2022-03-02T10:27:00.000Z","bspReconciled":false,"complete":true,"inPlay":false,"crossMatching":true,"runnersVoidable":false,"numberOfActiveRunners":2,"betDelay":0,"status":"OPEN","runners":[{"status":"ACTIVE","sortPriority":1,"id":40250501,"name":"1. Dwarshuis"},{"status":"ACTIVE","sortPriority":2,"id":6780934,"name":"2. Peacock"}],"regulators":["MR_INT"],"venue":"Traralgon","countryCode":"AU","discountAllowed":true,"timezone":"Australia/Sydney","openDate":"2022-03-02T08:31:00.000Z","version":4382489947,"name":"Dwarshuis v Peacock","eventName":"Traralgon (AUS) 2nd Mar"},"rc":[{"atb":[[1.85,6.34],[1.95,5.67],[2.1,4.9]],"id":40250501},{"atb":[[1.27,19.98],[1.37,14.58],[1.47,11.47]],"id":6780934}],"con":true,"img":true}]}
{"op":"mcm","clk":"5348222165","pt":1646215623424,"mc":[{"id":"1.195453675","rc":[{"atb":[[1.81,2],[1.85,6.34],[1.95,5.67],[2.1,4.9]],"id":40250501},{"atl":[[2.58,2]],"id":40250501},{"atb":[[1.59,2],[1.27,19.98],[1.37,14.58],[1.47,11.47]],"id":6780934},{"atl":[[2.22,2]],"id":6780934}],"con":true,"img":false}]}
{"op":"mcm","clk":"5348222588","pt":1646215628809,"mc":[{"id":"1.195453675","rc":[{"atb":[[1.59,0],[1.55,2]],"id":6780934}],"con":true,"img":false}]}
{"op":"mcm","clk":"5348222595","pt":1646215628911,"mc":[{"id":"1.195453675","rc":[{"atb":[[1.54,2]],"id":6780934}],"con":true,"img":false}]}
{"op":"mcm","clk":"5348222601","pt":1646215629017,"mc":[{"id":"1.195453675","rc":[{"atb":[[1.55,0]],"id":6780934}],"con":true,"img":false}]}
{"op":"mcm","clk":"5348222611","pt":1646215629126,"mc":[{"id":"1.195453675","rc":[{"atb":[[1.55,2],[1.54,0]],"id":6780934}],"con":true,"img":false}]}
{"op":"mcm","clk":"5348223662","pt":1646215642044,"mc":[{"id":"1.195453675","rc":[{"atb":[[1.56,2],[1.55,0]],"id":6780934}],"con":true,"img":false}]}
{"op":"mcm","clk":"5348223892","pt":1646215644967,"mc":[{"id":"1.195453675","rc":[{"atb":[[1.56,0],[1.57,2]],"id":6780934}],"con":true,"img":false}]}
{"op":"mcm","clk":"5348224319","pt":1646215650056,"mc":[{"id":"1.195453675","rc":[{"atb":[[1.58,2]],"id":6780934}],"con":true,"img":false}]}
{"op":"mcm","clk":"5348224325","pt":1646215650160,"mc":[{"id":"1.195453675","rc":[{"atb":[[1.57,0]],"id":6780934}],"con":true,"img":false}]}
{"op":"mcm","clk":"5348225549","pt":1646215663967,"mc":[{"id":"1.195453675","rc":[{"atl":[[2.56,2],[2.58,0]],"id":40250501},{"atb":[[1.59,2],[1.58,0]],"id":6780934}],"con":true,"img":false}]}
{"op":"mcm","clk":"5348226030","pt":1646215669083,"mc":[{"id":"1.195453675","rc":[{"atl":[[2.56,0],[2.54,2]],"id":40250501}],"con":true,"img":false}]}
{"op":"mcm","clk":"5348226040","pt":1646215669189,"mc":[{"id":"1.195453675","rc":[{"atb":[[1.59,0],[1.6,2]],"id":6780934}],"con":true,"img":false}]}
{"op":"mcm","clk":"5348227564","pt":1646215686005,"mc":[{"id":"1.195453675","rc":[{"atl":[[2.54,0],[2.5,2]],"id":40250501},{"atb":[[1.6,0],[1.62,2]],"id":6780934}],"con":true,"img":false}]}
{"op":"mcm","clk":"5348228026","pt":1646215691187,"mc":[{"id":"1.195453675","rc":[{"atl":[[2.5,0],[2.44,2]],"id":40250501},{"atb":[[1.62,0],[1.66,2]],"id":6780934}],"con":true,"img":false}]}
{"op":"mcm","clk":"5348228501","pt":1646215696412,"mc":[{"id":"1.195453675","rc":[{"atl":[[2.42,2],[2.44,0]],"id":40250501}],"con":true,"img":false}]}
{"op":"mcm","clk":"5348229875","pt":1646215712006,"mc":[{"id":"1.195453675","rc":[{"atl":[[2.4,2],[2.42,0]],"id":40250501},{"atb":[[1.68,2],[1.66,0]],"id":6780934}],"con":true,"img":false}]}
{"op":"mcm","clk":"5348230651","pt":1646215720537,"mc":[{"id":"1.195453675","rc":[{"atb":[[1.67,2],[1.68,0]],"id":6780934}],"con":true,"img":false}]}
{"op":"mcm","clk":"5348232987","pt":1646215746137,"mc":[{"id":"1.195453675","rc":[{"atb":[[1.6,2],[1.67,0]],"id":6780934},{"atl":[[2.22,0],[2.2,2]],"id":6780934}],"con":true,"img":false}]}
{"op":"mcm","clk":"5348233142","pt":1646215747963,"mc":[{"id":"1.195453675","rc":[{"atb":[[1.6,0],[1.61,2]],"id":6780934}],"con":true,"img":false}]}
{"op":"mcm","clk":"5348233873","pt":1646215756034,"mc":[{"id":"1.195453675","rc":[{"atb":[[1.6,2],[1.61,0]],"id":6780934}],"con":true,"img":false}]}
{"op":"mcm","clk":"5348235145","pt":1646215769980,"mc":[{"id":"1.195453675","rc":[{"atb":[[1.6,0],[1.62,2]],"id":6780934}],"con":true,"img":false}]}
{"op":"mcm","clk":"5348235165","pt":1646215770138,"mc":[{"id":"1.195453675","rc":[{"atb":[[1.64,2],[1.62,0]],"id":6780934}],"con":true,"img":false}]}
{"op":"mcm","clk":"5348237004","pt":1646215789891,"mc":[{"id":"1.195453675","rc":[{"atb":[[1.64,0],[1.63,2]],"id":6780934}],"con":true,"img":false}]}
{"op":"mcm","clk":"5348237530","pt":1646215795098,"mc":[{"id":"1.195453675","rc":[{"atb":[[1.63,0],[1.62,2]],"id":6780934}],"con":true,"img":false}]}
{"op":"mcm","clk":"5348246656","pt":1646215892067,"mc":[{"id":"1.195453675","rc":[{"atb":[[1.81,0]],"id":40250501},{"atl":[[2.4,0]],"id":40250501},{"atb":[[1.62,0]],"id":6780934},{"atl":[[2.2,0]],"id":6780934}],"con":true,"img":false}]}
{"op":"mcm","clk":"5348248473","pt":1646215910787,"mc":[{"id":"1.195453675","rc":[{"atb":[[1.81,2]],"id":40250501},{"atl":[[2.5,2]],"id":40250501},{"atb":[[1.62,2]],"id":6780934},{"atl":[[2.34,2]],"id":6780934}],"con":true,"img":false}]}
{"op":"mcm","clk":"5348249476","pt":1646215922586,"mc":[{"id":"1.195453675","rc":[{"atl":[[2.32,2],[2.34,0]],"id":6780934}],"con":true,"img":false}]}
{"op":"mcm","clk":"5348250049","pt":1646215929506,"mc":[{"id":"1.195453675","rc":[{"atb":[[1.63,2],[1.62,0]],"id":6780934}],"con":true,"img":false}]}
{"op":"mcm","clk":"5348250060","pt":1646215929610,"mc":[{"id":"1.195453675","rc":[{"atb":[[1.63,0],[1.62,2]],"id":6780934}],"con":true,"img":false}]}
{"op":"mcm","clk":"5348250244","pt":1646215932066,"mc":[{"id":"1.195453675","rc":[{"atb":[[1.63,2],[1.62,0]],"id":6780934}],"con":true,"img":false}]}
{"op":"mcm","clk":"5348251188","pt":1646215942025,"mc":[{"id":"1.195453675","rc":[{"atb":[[1.63,0],[1.62,2]],"id":6780934}],"con":true,"img":false}]}
{"op":"mcm","clk":"5348251712","pt":1646215947036,"mc":[{"id":"1.195453675","rc":[{"atb":[[1.63,2],[1.62,0]],"id":6780934}],"con":true,"img":false}]}
{"op":"mcm","clk":"5348253156","pt":1646215961767,"mc":[{"id":"1.195453675","rc":[{"atl":[[2.5,0],[2.46,2]],"id":40250501},{"atb":[[1.64,2],[1.63,0]],"id":6780934}],"con":true,"img":false}]}
{"op":"mcm","clk":"5348254767","pt":1646215977636,"mc":[{"id":"1.195453675","rc":[{"atb":[[1.85,0],[1.95,0],[2.1,0]],"id":40250501},{"atb":[[1.27,0],[1.37,0],[1.47,0]],"id":6780934}],"con":true,"img":false}]}
{"op":"mcm","clk":"5348255266","pt":1646215981301,"mc":[{"id":"1.195453675","rc":[{"atb":[[1.85,6.34],[1.95,5.67],[2.1,4.9]],"id":40250501},{"atb":[[1.27,19.98],[1.37,14.58],[1.47,11.47]],"id":6780934}],"con":true,"img":false}]}
{"op":"mcm","clk":"5348255290","pt":1646215981511,"mc":[{"id":"1.195453675","rc":[{"atb":[[1.64,0],[1.59,2]],"id":6780934}],"con":true,"img":false}]}
{"op":"mcm","clk":"5348255829","pt":1646215986605,"mc":[{"id":"1.195453675","rc":[{"atb":[[1.59,0],[1.58,2]],"id":6780934}],"con":true,"img":false}]}
{"op":"mcm","clk":"5348257898","pt":1646216008723,"mc":[{"id":"1.195453675","rc":[{"atb":[[1.58,0],[1.62,2]],"id":6780934}],"con":true,"img":false}]}
{"op":"mcm","clk":"5348272405","pt":1646216102106,"mc":[{"id":"1.195453675","rc":[{"atb":[[1.62,0],[1.61,2]],"id":6780934}],"con":true,"img":false}]}
{"op":"mcm","clk":"5348272437","pt":1646216102275,"mc":[{"id":"1.195453675","rc":[{"atl":[[2.36,2],[2.46,0]],"id":40250501}],"con":true,"img":false}]}
{"op":"mcm","clk":"5348273693","pt":1646216107193,"mc":[{"id":"1.195453675","rc":[{"atb":[[1.7,2],[1.61,0]],"id":6780934}],"con":true,"img":false}]}
{"op":"mcm","clk":"5348279504","pt":1646216131688,"mc":[{"id":"1.195453675","rc":[{"atb":[[1.69,2]],"id":6780934}],"con":true,"img":false}]}
{"op":"mcm","clk":"5348279521","pt":1646216131791,"mc":[{"id":"1.195453675","rc":[{"atb":[[1.7,0]],"id":6780934}],"con":true,"img":false}]}
{"op":"mcm","clk":"5348280728","pt":1646216139308,"mc":[{"id":"1.195453675","rc":[{"atb":[[1.68,2],[1.69,0]],"id":6780934}],"con":true,"img":false}]}
{"op":"mcm","clk":"5348286391","pt":1646216179759,"mc":[{"id":"1.195453675","rc":[{"atb":[[1.68,0],[1.7,2]],"id":6780934}],"con":true,"img":false}]}
{"op":"mcm","clk":"5348298988","pt":1646216271853,"mc":[{"id":"1.195453675","rc":[{"atb":[[1.7,0],[1.69,2]],"id":6780934}],"con":true,"img":false}]}
{"op":"mcm","clk":"5348299690","pt":1646216277029,"mc":[{"id":"1.195453675","rc":[{"atb":[[1.67,2],[1.69,0]],"id":6780934}],"con":true,"img":false}]}
{"op":"mcm","clk":"5348306538","pt":1646216335815,"mc":[{"id":"1.195453675","rc":[{"atb":[[1.67,0],[1.66,2]],"id":6780934}],"con":true,"img":false}]}
{"op":"mcm","clk":"5348310358","pt":1646216371417,"mc":[{"id":"1.195453675","rc":[{"atb":[[1.66,0],[1.65,2]],"id":6780934}],"con":true,"img":false}]}
{"op":"mcm","clk":"5348311081","pt":1646216377646,"mc":[{"id":"1.195453675","rc":[{"atb":[[1.65,0],[1.66,2]],"id":6780934}],"con":true,"img":false}]}
{"op":"mcm","clk":"5348311457","pt":1646216380928,"mc":[{"id":"1.195453675","rc":[{"atl":[[2.32,0],[2.3,2]],"id":6780934}],"con":true,"img":false}]}
{"op":"mcm","clk":"5348313869","pt":1646216403090,"mc":[{"id":"1.195453675","rc":[{"atl":[[2.3,0],[2.32,2]],"id":6780934}],"con":true,"img":false}]}
{"op":"mcm","clk":"5348316621","pt":1646216429887,"mc":[{"id":"1.195453675","rc":[{"atl":[[2.22,2]],"id":6780934}],"con":true,"img":false}]}
{"op":"mcm","clk":"5348316631","pt":1646216429993,"mc":[{"id":"1.195453675","rc":[{"atl":[[2.32,0]],"id":6780934}],"con":true,"img":false}]}
{"op":"mcm","clk":"5348317313","pt":1646216436630,"mc":[{"id":"1.195453675","rc":[{"atb":[[1.64,2],[1.66,0]],"id":6780934}],"con":true,"img":false}]}
{"op":"mcm","clk":"5348317950","pt":1646216441729,"mc":[{"id":"1.195453675","rc":[{"atb":[[1.64,0],[1.65,2]],"id":6780934}],"con":true,"img":false}]}
{"op":"mcm","clk":"5348322275","pt":1646216487596,"mc":[{"id":"1.195453675","rc":[{"atb":[[1.65,0],[1.66,2]],"id":6780934}],"con":true,"img":false}]}
{"op":"mcm","clk":"5348322293","pt":1646216487758,"mc":[{"id":"1.195453675","rc":[{"atb":[[1.96,9.04]],"id":40250501},{"atl":[[2.36,10.85]],"id":40250501},{"atb":[[1.66,11.59]],"id":6780934},{"atl":[[2.22,11.18]],"id":6780934}],"con":true,"img":false}]}
{"op":"mcm","clk":"5348326097","pt":1646216519701,"mc":[{"id":"1.195453675","rc":[{"atb":[[1.73,2],[1.7,50],[1.68,2],[1.71,2],[1.76,2],[1.79,15],[1.74,33],[1.67,2],[1.77,22],[1.75,2],[1.65,75]],"id":40250501}],"con":true,"img":false}]}
{"op":"mcm","clk":"5348326312","pt":1646216521716,"mc":[{"id":"1.195453675","rc":[{"atl":[[2.36,24.85],[2.4,2],[2.56,2],[2.54,2],[2.32,9],[2.5,32],[2.42,21],[2.38,2],[2.44,2],[2.6,48],[2.48,2]],"id":40250501}],"con":true,"img":false}]}
{"op":"mcm","clk":"5348326336","pt":1646216521925,"mc":[{"id":"1.195453675","rc":[{"atl":[[2.36,22.85],[2.38,4]],"id":40250501}],"con":true,"img":false}]}
{"op":"mcm","clk":"5348327073","pt":1646216527015,"mc":[{"id":"1.195453675","rc":[{"atl":[[2.38,2],[2.34,2]],"id":40250501}],"con":true,"img":false}]}
{"op":"mcm","clk":"5348329686","pt":1646216542032,"mc":[{"id":"1.195453675","rc":[{"atb":[[1.85,0],[1.95,0],[2.1,0]],"id":40250501},{"atb":[[1.27,0],[1.37,0],[1.47,0]],"id":6780934}],"con":true,"img":false}]}
{"op":"mcm","clk":"5348330867","pt":1646216550931,"mc":[{"id":"1.195453675","rc":[{"atb":[[1.83,6.5],[1.93,5.8],[2.06,5.09]],"id":40250501},{"atb":[[1.4,13.48],[1.5,10.79],[1.3,17.98]],"id":6780934}],"con":true,"img":false}]}
{"op":"mcm","clk":"5348331269","pt":1646216554637,"mc":[{"id":"1.195453675","rc":[{"atl":[[2.3,8.65]],"id":40250501}],"con":true,"img":false}]}
{"op":"mcm","clk":"5348331285","pt":1646216554740,"mc":[{"id":"1.195453675","rc":[{"atl":[[2.34,0],[2.28,17.65]],"id":40250501}],"con":true,"img":false}]}
{"op":"mcm","clk":"5348331923","pt":1646216560484,"mc":[{"id":"1.195453675","rc":[{"atl":[[2.26,8.66]],"id":40250501}],"con":true,"img":false}]}
{"op":"mcm","clk":"5348331948","pt":1646216560646,"mc":[{"id":"1.195453675","rc":[{"atl":[[2.24,17.32],[2.28,0]],"id":40250501}],"con":true,"img":false}]}
{"op":"mcm","clk":"5348333126","pt":1646216571468,"mc":[{"id":"1.195453675","rc":[{"atl":[[2.22,9.18],[2.2,2]],"id":6780934}],"con":true,"img":false}]}
{"op":"mcm","clk":"5348333235","pt":1646216572465,"mc":[{"id":"1.195453675","rc":[{"atl":[[2.2,11.59]],"id":6780934}],"con":true,"img":false}]}
{"op":"mcm","clk":"5348333891","pt":1646216578400,"mc":[{"id":"1.195453675","rc":[{"atl":[[2.22,8.59]],"id":40250501}],"con":true,"img":false}]}
{"op":"mcm","clk":"5348333913","pt":1646216578606,"mc":[{"id":"1.195453675","rc":[{"atl":[[2.24,0],[2.2,2]],"id":40250501}],"con":true,"img":false}]}
{"op":"mcm","clk":"5348334486","pt":1646216583696,"mc":[{"id":"1.195453675","rc":[{"atl":[[2.36,14],[2.2,10.6]],"id":40250501}],"con":true,"img":false}]}
{"op":"mcm","clk":"5348336682","pt":1646216602735,"mc":[{"id":"1.195453675","rc":[{"atb":[[1.83,0],[1.93,0],[2.06,0]],"id":40250501},{"atb":[[1.4,0],[1.5,0],[1.3,0]],"id":6780934}],"con":true,"img":false}]}
{"op":"mcm","clk":"5348337860","pt":1646216614374,"mc":[{"id":"1.195453675","rc":[{"atb":[[1.94,5.73],[2.08,4.99]],"id":40250501},{"atl":[[2.2,6.39]],"id":40250501},{"trd":[[2.2,8.42]],"ltp":2.2,"tv":8.42,"id":40250501},{"atb":[[1.4,13.48],[1.2,26.97],[1.3,17.98]],"id":6780934}],"con":true,"img":false}]}
{"op":"mcm","clk":"5348337875","pt":1646216614528,"mc":[{"id":"1.195453675","rc":[{"atb":[[2.08,0]],"id":40250501},{"trd":[[2.08,9.99]],"ltp":2.08,"tv":9.99,"id":40250501}],"con":true,"img":false}]}
{"op":"mcm","clk":"5348337882","pt":1646216614636,"mc":[{"id":"1.195453675","rc":[{"atb":[[2.08,8.65]],"id":40250501}],"con":true,"img":false}]}
{"op":"mcm","clk":"5348339393","pt":1646216632687,"mc":[{"id":"1.195453675","rc":[{"atb":[[1.94,0]],"id":40250501},{"atb":[[1.4,0],[1.2,0],[1.3,0]],"id":6780934}],"con":true,"img":false}]}
{"op":"mcm","clk":"5348340103","pt":1646216641188,"mc":[{"id":"1.195453675","rc":[{"atb":[[1.98,5.5],[1.88,6.13],[2.16,4.64]],"id":40250501},{"atb":[[1.45,11.98],[1.25,21.58],[1.35,15.41]],"id":6780934}],"con":true,"img":false}]}
{"op":"mcm","clk":"5348340117","pt":1646216641392,"mc":[{"id":"1.195453675","rc":[{"atb":[[2.16,0]],"id":40250501},{"trd":[[2.16,9.29]],"ltp":2.16,"tv":9.29,"id":40250501}],"con":true,"img":false}]}
{"op":"mcm","clk":"5348340135","pt":1646216641551,"mc":[{"id":"1.195453675","rc":[{"atl":[[2.2,8.39]],"id":40250501}],"con":true,"img":false}]}
{"op":"mcm","clk":"5348340574","pt":1646216646268,"mc":[{"id":"1.195453675","rc":[{"atb":[[1.68,2],[1.66,9.59]],"id":6780934}],"con":true,"img":false}]}
{"op":"mcm","clk":"5348340841","pt":1646216649569,"mc":[{"id":"1.195453675","rc":[{"atl":[[1.92,21.79]],"id":6780934}],"con":true,"img":false}]}
{"op":"mcm","clk":"5348340910","pt":1646216650402,"mc":[{"id":"1.195453675","rc":[{"atb":[[2.08,0]],"id":40250501},{"atb":[[1.68,11.76]],"id":6780934}],"con":true,"img":false}]}
{"op":"mcm","clk":"5348340923","pt":1646216650613,"mc":[{"id":"1.195453675","rc":[{"atb":[[2.08,8.71],[1.99,8.71]],"id":40250501}],"con":true,"img":false}]}
{"op":"mcm","clk":"5348340974","pt":1646216651297,"mc":[{"id":"1.195453675","rc":[{"atl":[[1.91,9.76]],"id":6780934}],"con":true,"img":false}]}
{"op":"mcm","clk":"5348341092","pt":1646216652498,"mc":[{"id":"1.195453675","rc":[{"atl":[[2.2,2]],"id":40250501}],"con":true,"img":false}]}
{"op":"mcm","clk":"5348341103","pt":1646216652601,"mc":[{"id":"1.195453675","rc":[{"atl":[[2.22,0]],"id":40250501}],"con":true,"img":false}]}
{"op":"mcm","clk":"5348341117","pt":1646216652809,"mc":[{"id":"1.195453675","rc":[{"atl":[[2.24,2],[2.2,0]],"id":40250501}],"con":true,"img":false}]}
{"op":"mcm","clk":"5348341235","pt":1646216654115,"mc":[{"id":"1.195453675","rc":[{"atl":[[2.24,10.34]],"id":40250501}],"con":true,"img":false}]}
{"op":"mcm","clk":"5348341642","pt":1646216657593,"mc":[{"id":"1.195453675","rc":[{"atl":[[1.92,0]],"id":6780934}],"con":true,"img":false}]}
{"op":"mcm","clk":"5348341655","pt":1646216657699,"mc":[{"id":"1.195453675","rc":[{"atl":[[1.9,21.79]],"id":6780934}],"con":true,"img":false}]}
{"op":"mcm","clk":"5348341761","pt":1646216658698,"mc":[{"id":"1.195453675","rc":[{"atl":[[1.83,24.75],[1.91,0]],"id":6780934}],"con":true,"img":false}]}
{"op":"mcm","clk":"5348341770","pt":1646216658801,"mc":[{"id":"1.195453675","rc":[{"atl":[[1.83,6.37]],"id":6780934},{"trd":[[1.83,36.76]],"ltp":1.83,"tv":36.76,"id":6780934}],"con":true,"img":false}]}
{"op":"mcm","clk":"5348341790","pt":1646216659012,"mc":[{"id":"1.195453675","rc":[{"trd":[[2.2,12.01]],"ltp":2.2,"tv":12.01,"id":40250501},{"atl":[[1.83,2.06]],"id":6780934},{"trd":[[1.83,41.07]],"ltp":1.83,"tv":41.07,"id":6780934}],"con":true,"img":false}]}
{"op":"mcm","clk":"5348341810","pt":1646216659223,"mc":[{"id":"1.195453675","rc":[{"trd":[[2.2,13.73]],"ltp":2.2,"tv":13.73,"id":40250501},{"atl":[[1.83,0]],"id":6780934},{"trd":[[1.83,43.14]],"ltp":1.83,"tv":43.14,"id":6780934}],"con":true,"img":false}]}
{"op":"mcm","clk":"5348341986","pt":1646216661427,"mc":[{"id":"1.195453675","rc":[{"atb":[[2.08,0]],"id":40250501}],"con":true,"img":false}]}
{"op":"mcm","clk":"5348342848","pt":1646216670514,"mc":[{"id":"1.195453675","rc":[{"atb":[[2,29.17]],"id":40250501},{"atb":[[1.76,38.38]],"id":6780934}],"con":true,"img":false}]}
{"op":"mcm","clk":"5348342871","pt":1646216670723,"mc":[{"id":"1.195453675","rc":[{"atb":[[1.68,9.76],[1.77,2]],"id":6780934}],"con":true,"img":false}]}
{"op":"mcm","clk":"5348343074","pt":1646216672826,"mc":[{"id":"1.195453675","rc":[{"atb":[[2,38.51]],"id":40250501},{"atb":[[1.77,6]],"id":6780934}],"con":true,"img":false}]}
{"op":"mcm","clk":"5348343103","pt":1646216673142,"mc":[{"id":"1.195453675","rc":[{"atb":[[1.77,2]],"id":6780934}],"con":true,"img":false}]}
{"op":"mcm","clk":"5348343118","pt":1646216673300,"mc":[{"id":"1.195453675","rc":[{"atb":[[2.02,8.89]],"id":40250501}],"con":true,"img":false}]}
{"op":"mcm","clk":"5348343135","pt":1646216673512,"mc":[{"id":"1.195453675","rc":[{"atb":[[1.77,6]],"id":6780934}],"con":true,"img":false}]}
{"op":"mcm","clk":"5348343157","pt":1646216673721,"mc":[{"id":"1.195453675","rc":[{"atb":[[2,29.17]],"id":40250501}],"con":true,"img":false}]}
{"op":"mcm","clk":"5348343168","pt":1646216673828,"mc":[{"id":"1.195453675","rc":[{"atb":[[2.02,18.23]],"id":40250501}],"con":true,"img":false}]}
{"op":"mcm","clk":"5348343177","pt":1646216673930,"mc":[{"id":"1.195453675","rc":[{"atb":[[1.77,2]],"id":6780934}],"con":true,"img":false}]}
{"op":"mcm","clk":"5348343251","pt":1646216674510,"mc":[{"id":"1.195453675","rc":[{"atb":[[2.04,28.05]],"id":40250501}],"con":true,"img":false}]}
{"op":"mcm","clk":"5348343286","pt":1646216674823,"mc":[{"id":"1.195453675","rc":[{"atb":[[2.02,8.89]],"id":40250501}],"con":true,"img":false}]}
{"op":"mcm","clk":"5348343298","pt":1646216674929,"mc":[{"id":"1.195453675","rc":[{"atb":[[2.04,37.39]],"id":40250501}],"con":true,"img":false}]}
{"op":"mcm","clk":"5348343368","pt":1646216675608,"mc":[{"id":"1.195453675","rc":[{"atl":[[1.9,29.62]],"id":6780934}],"con":true,"img":false}]}
{"op":"mcm","clk":"5348344089","pt":1646216682656,"mc":[{"id":"1.195453675","rc":[{"atb":[[1.99,0]],"id":40250501}],"con":true,"img":false}]}
{"op":"mcm","clk":"5348344109","pt":1646216682870,"mc":[{"id":"1.195453675","rc":[{"atb":[[2.02,0]],"id":40250501}],"con":true,"img":false}]}
{"op":"mcm","clk":"5348344185","pt":1646216683545,"mc":[{"id":"1.195453675","rc":[{"atl":[[2.24,0]],"id":40250501},{"trd":[[2.24,10.34]],"ltp":2.24,"tv":10.34,"id":40250501},{"atl":[[1.8,96.11]],"id":6780934},{"trd":[[1.8,12.87]],"ltp":1.8,"tv":12.87,"id":6780934}],"con":true,"img":false}]}
{"op":"mcm","clk":"5348344198","pt":1646216683650,"mc":[{"id":"1.195453675","rc":[{"atb":[[1.99,9.06]],"id":40250501}],"con":true,"img":false}]}
{"op":"mcm","clk":"5348344239","pt":1646216683963,"mc":[{"id":"1.195453675","rc":[{"atb":[[2.16,25.15]],"id":40250501},{"atb":[[1.73,39.97],[1.76,0]],"id":6780934}],"con":true,"img":false}]}
{"op":"mcm","clk":"5348344264","pt":1646216684122,"mc":[{"id":"1.195453675","rc":[{"atb":[[2.02,9]],"id":40250501},{"atb":[[1.74,2],[1.77,0]],"id":6780934}],"con":true,"img":false}]}
{"op":"mcm","clk":"5348344351","pt":1646216684850,"mc":[{"id":"1.195453675","rc":[{"atl":[[2.26,0]],"id":40250501},{"trd":[[2.26,8.66]],"ltp":2.26,"tv":8.66,"id":40250501},{"trd":[[1.79,10.95]],"ltp":1.79,"tv":10.95,"id":6780934}],"con":true,"img":false}]}
{"op":"mcm","clk":"5348344378","pt":1646216685059,"mc":[{"id":"1.195453675","rc":[{"trd":[[2.24,12.34]],"ltp":2.24,"tv":12.34,"id":40250501},{"atl":[[1.8,93.63]],"id":6780934},{"trd":[[1.8,15.36]],"ltp":1.8,"tv":15.36,"id":6780934}],"con":true,"img":false}]}
{"op":"mcm","clk":"5348344399","pt":1646216685224,"mc":[{"id":"1.195453675","rc":[{"atl":[[1.8,66.89]],"id":6780934},{"trd":[[1.8,68.86]],"ltp":1.8,"tv":68.86,"id":6780934}],"con":true,"img":false}]}
{"op":"mcm","clk":"5348344407","pt":1646216685321,"mc":[{"id":"1.195453675","rc":[{"atb":[[2.02,0]],"id":40250501}],"con":true,"img":false}]}
{"op":"mcm","clk":"5348344418","pt":1646216685427,"mc":[{"id":"1.195453675","rc":[{"atb":[[2,0]],"id":40250501}],"con":true,"img":false}]}
{"op":"mcm","clk":"5348344695","pt":1646216688243,"mc":[{"id":"1.195453675","rc":[{"atl":[[1.8,11.92]],"id":6780934},{"trd":[[1.8,178.82]],"ltp":1.8,"tv":178.82,"id":6780934}],"con":true,"img":false}]}
{"op":"mcm","clk":"5348344723","pt":1646216688455,"mc":[{"id":"1.195453675","rc":[{"atb":[[2.16,0]],"id":40250501},{"atb":[[1.73,0]],"id":6780934},{"atl":[[1.8,10.24]],"id":6780934},{"trd":[[1.8,182.2]],"ltp":1.8,"tv":182.2,"id":6780934}],"con":true,"img":false}]}
{"op":"mcm","clk":"5348344733","pt":1646216688560,"mc":[{"id":"1.195453675","rc":[{"atb":[[2.12,26.05]],"id":40250501},{"atb":[[1.72,40.52]],"id":6780934}],"con":true,"img":false}]}
{"op":"mcm","clk":"5348344785","pt":1646216689033,"mc":[{"id":"1.195453675","rc":[{"atb":[[1.96,0]],"id":40250501}],"con":true,"img":false}]}
{"op":"mcm","clk":"5348344820","pt":1646216689356,"mc":[{"id":"1.195453675","rc":[{"atb":[[1.99,0]],"id":40250501},{"atb":[[1.73,2],[1.74,0]],"id":6780934}],"con":true,"img":false}]}
{"op":"mcm","clk":"5348344979","pt":1646216691025,"mc":[{"id":"1.195453675","rc":[{"atb":[[1.8,4.75]],"id":6780934},{"atl":[[1.8,0]],"id":6780934},{"trd":[[1.8,202.69]],"ltp":1.8,"tv":202.69,"id":6780934}],"con":true,"img":false}]}
{"op":"mcm","clk":"5348345017","pt":1646216691457,"mc":[{"id":"1.195453675","rc":[{"atb":[[2.04,28.05]],"id":40250501},{"atb":[[1.74,39.42]],"id":6780934}],"con":true,"img":false}]}
{"op":"mcm","clk":"5348345044","pt":1646216691760,"mc":[{"id":"1.195453675","rc":[{"atb":[[2.12,44.86]],"id":40250501}],"con":true,"img":false}]}
{"op":"mcm","clk":"5348345102","pt":1646216692235,"mc":[{"id":"1.195453675","rc":[{"atb":[[1.8,19.75]],"id":6780934}],"con":true,"img":false}]}
{"op":"mcm","clk":"5348345119","pt":1646216692445,"mc":[{"id":"1.195453675","rc":[{"atb":[[1.76,38.38]],"id":6780934}],"con":true,"img":false}]}
{"op":"mcm","clk":"5348345153","pt":1646216692860,"mc":[{"id":"1.195453675","rc":[{"atl":[[2.56,4],[2.54,4],[2.6,4],[2.64,4],[2.66,4],[2.58,4],[2.62,4]],"id":6780934}],"con":true,"img":false}]}
{"op":"mcm","clk":"5348345214","pt":1646216693448,"mc":[{"id":"1.195453675","rc":[{"atb":[[1.98,0],[1.88,0]],"id":40250501},{"atb":[[1.45,0],[1.25,0],[1.35,0]],"id":6780934}],"con":true,"img":false}]}
{"op":"mcm","clk":"5348345244","pt":1646216693759,"mc":[{"id":"1.195453675","rc":[{"atb":[[1.8,34.75]],"id":6780934}],"con":true,"img":false}]}
{"op":"mcm","clk":"5348345303","pt":1646216694547,"mc":[{"id":"1.195453675","rc":[{"atb":[[1.73,0],[1.77,2]],"id":6780934}],"con":true,"img":false}]}
{"op":"mcm","clk":"5348345340","pt":1646216694963,"mc":[{"id":"1.195453675","rc":[{"atb":[[1.72,0]],"id":6780934}],"con":true,"img":false}]}
{"op":"mcm","clk":"5348345727","pt":1646216699677,"mc":[{"id":"1.195453675","rc":[{"atb":[[1.82,2],[1.77,0]],"id":6780934}],"con":true,"img":false}]}
{"op":"mcm","clk":"5348345762","pt":1646216699938,"mc":[{"id":"1.195453675","rc":[{"atb":[[2.12,18.81],[2.1,26.52]],"id":40250501},{"atb":[[1.8,71.22]],"id":6780934}],"con":true,"img":false}]}
{"op":"mcm","clk":"5348345786","pt":1646216700253,"mc":[{"id":"1.195453675","rc":[{"atb":[[2.12,0]],"id":40250501}],"con":true,"img":false}]}
{"op":"mcm","clk":"5348345796","pt":1646216700360,"mc":[{"id":"1.195453675","rc":[{"atb":[[2.1,45.33]],"id":40250501}],"con":true,"img":false}]}
{"op":"mcm","clk":"5348345810","pt":1646216700567,"mc":[{"id":"1.195453675","rc":[{"atb":[[1.81,11.7]],"id":40250501}],"con":true,"img":false}]}
{"op":"mcm","clk":"5348346213","pt":1646216704751,"mc":[{"id":"1.195453675","rc":[{"atb":[[1.82,0],[1.81,2]],"id":6780934}],"con":true,"img":false}]}
{"op":"mcm","clk":"5348346241","pt":1646216705069,"mc":[{"id":"1.195453675","rc":[{"atb":[[2,5.39],[2.2,4.49]],"id":40250501},{"trd":[[2.26,10.9],[2.24,13.96]],"ltp":2.26,"tv":24.86,"id":40250501},{"atb":[[1.8,68.41],[1.36,14.98],[1.81,0],[1.16,33.72],[1.26,20.75]],"id":6780934},{"trd":[[1.8,205.5],[1.81,2]],"ltp":1.8,"tv":207.5,"id":6780934}],"con":true,"img":false}]}
{"op":"mcm","clk":"5348346260","pt":1646216705277,"mc":[{"id":"1.195453675","rc":[{"atl":[[2.22,2]],"id":40250501}],"con":true,"img":false}]}
{"op":"mcm","clk":"5348346279","pt":1646216705488,"mc":[{"id":"1.195453675","rc":[{"atb":[[2.2,0]],"id":40250501},{"trd":[[2.2,22.73]],"ltp":2.2,"tv":22.73,"id":40250501},{"atb":[[1.8,31.94]],"id":6780934}],"con":true,"img":false}]}
{"op":"mcm","clk":"5348346743","pt":1646216710471,"mc":[{"id":"1.195453675","rc":[{"atl":[[2.22,0],[2.28,2]],"id":40250501}],"con":true,"img":false}]}
{"op":"mcm","clk":"5348347589","pt":1646216720206,"mc":[{"id":"1.195453675","rc":[{"atb":[[1.77,2]],"id":6780934}],"con":true,"img":false}]}
{"op":"mcm","clk":"5348348376","pt":1646216729578,"mc":[{"id":"1.195453675","rc":[{"atb":[[2.1,34.41]],"id":40250501},{"trd":[[2.1,21.82]],"ltp":2.1,"tv":21.82,"id":40250501}],"con":true,"img":false}]}
{"op":"mcm","clk":"5348349692","pt":1646216743996,"mc":[{"id":"1.195453675","rc":[{"atl":[[2.2,16.34]],"id":40250501}],"con":true,"img":false}]}
{"op":"mcm","clk":"5348349701","pt":1646216744102,"mc":[{"id":"1.195453675","rc":[{"atl":[[2.28,0],[2.18,2]],"id":40250501}],"con":true,"img":false}]}
{"op":"mcm","clk":"5348349738","pt":1646216744519,"mc":[{"id":"1.195453675","rc":[{"atb":[[1.8,68.41]],"id":6780934}],"con":true,"img":false}]}
{"op":"mcm","clk":"5348349750","pt":1646216744625,"mc":[{"id":"1.195453675","rc":[{"atb":[[1.81,2],[1.77,0]],"id":6780934}],"con":true,"img":false}]}
{"op":"mcm","clk":"5348350062","pt":1646216747965,"mc":[{"id":"1.195453675","rc":[{"atl":[[1.9,7.83]],"id":6780934}],"con":true,"img":false}]}
{"op":"mcm","clk":"5348350066","pt":1646216748015,"mc":[{"id":"1.195453675","rc":[{"atl":[[2.18,0],[2.2,0.19]],"id":40250501},{"trd":[[2.2,38.89],[2.18,2]],"ltp":2.2,"tv":40.89,"id":40250501},{"trd":[[1.83,62.57],[1.84,2.37]],"ltp":1.83,"tv":64.94,"id":6780934}],"con":true,"img":false}]}
{"op":"mcm","clk":"5348350078","pt":1646216748225,"mc":[{"id":"1.195453675","rc":[{"atb":[[2.1,36.52]],"id":40250501}],"con":true,"img":false}]}
{"op":"mcm","clk":"5348350085","pt":1646216748329,"mc":[{"id":"1.195453675","rc":[{"atl":[[1.9,0]],"id":6780934}],"con":true,"img":false}]}
{"op":"mcm","clk":"5348350103","pt":1646216748537,"mc":[{"id":"1.195453675","rc":[{"atb":[[2.04,0],[2.1,20.92]],"id":40250501},{"atb":[[1.8,31.94]],"id":6780934},{"atl":[[2.22,11.18],[2.2,9.59]],"id":6780934}],"con":true,"img":false}]}
{"op":"mcm","clk":"5348350112","pt":1646216748642,"mc":[{"id":"1.195453675","rc":[{"atl":[[2.2,32.77]],"id":6780934}],"con":true,"img":false}]}
{"op":"mcm","clk":"5348350129","pt":1646216748848,"mc":[{"id":"1.195453675","rc":[{"atb":[[2.1,6.33]],"id":40250501}],"con":true,"img":false}]}
{"op":"mcm","clk":"5348350226","pt":1646216749837,"mc":[{"id":"1.195453675","rc":[{"atb":[[1.81,0],[1.77,2]],"id":6780934}],"con":true,"img":false}]}
{"op":"mcm","clk":"5348350374","pt":1646216751611,"mc":[{"id":"1.195453675","rc":[{"atl":[[2.18,17.55]],"id":6780934}],"con":true,"img":false}]}
{"op":"mcm","clk":"5348350404","pt":1646216752026,"mc":[{"id":"1.195453675","rc":[{"atl":[[2.2,9.59]],"id":6780934}],"con":true,"img":false}]}
{"op":"mcm","clk":"5348350426","pt":1646216752339,"mc":[{"id":"1.195453675","rc":[{"atl":[[2.18,52.67]],"id":6780934}],"con":true,"img":false}]}
{"op":"mcm","clk":"5348350436","pt":1646216752443,"mc":[{"id":"1.195453675","rc":[{"atl":[[2.16,17.75]],"id":6780934}],"con":true,"img":false}]}
{"op":"mcm","clk":"5348350472","pt":1646216752765,"mc":[{"id":"1.195453675","rc":[{"atl":[[2.18,17.55]],"id":6780934}],"con":true,"img":false}]}
{"op":"mcm","clk":"5348350474","pt":1646216752863,"mc":[{"id":"1.195453675","rc":[{"atb":[[2,0]],"id":40250501},{"atb":[[1.36,0],[1.16,0],[1.26,0]],"id":6780934}],"con":true,"img":false}]}
{"op":"mcm","clk":"5348350498","pt":1646216753058,"mc":[{"id":"1.195453675","rc":[{"atb":[[1.87,33.53]],"id":40250501},{"atl":[[2.16,53.27]],"id":6780934}],"con":true,"img":false}]}
{"op":"mcm","clk":"5348350511","pt":1646216753269,"mc":[{"id":"1.195453675","rc":[{"atb":[[1.8,33.94],[1.77,0]],"id":6780934}],"con":true,"img":false}]}
{"op":"mcm","clk":"5348350534","pt":1646216753427,"mc":[{"id":"1.195453675","rc":[{"atb":[[1.88,18.82]],"id":40250501},{"atl":[[2.22,2],[2.14,17.79]],"id":6780934}],"con":true,"img":false}]}
{"op":"mcm","clk":"5348350554","pt":1646216753636,"mc":[{"id":"1.195453675","rc":[{"atb":[[1.8,31.94],[1.81,2]],"id":6780934}],"con":true,"img":false}]}
{"op":"mcm","clk":"5348350576","pt":1646216753846,"mc":[{"id":"1.195453675","rc":[{"atl":[[2.16,17.75]],"id":6780934}],"con":true,"img":false}]}
{"op":"mcm","clk":"5348350595","pt":1646216754054,"mc":[{"id":"1.195453675","rc":[{"atb":[[1.87,0],[1.88,51.97]],"id":40250501}],"con":true,"img":false}]}
{"op":"mcm","clk":"5348350623","pt":1646216754365,"mc":[{"id":"1.195453675","rc":[{"atb":[[1.89,9.35]],"id":40250501},{"atl":[[2.14,53.39]],"id":6780934}],"con":true,"img":false}]}
{"op":"mcm","clk":"5348350652","pt":1646216754626,"mc":[{"id":"1.195453675","rc":[{"atl":[[2.12,17.6]],"id":6780934}],"con":true,"img":false}]}
{"op":"mcm","clk":"5348350661","pt":1646216754731,"mc":[{"id":"1.195453675","rc":[{"atl":[[2.2,0]],"id":6780934}],"con":true,"img":false}]}
{"op":"mcm","clk":"5348350676","pt":1646216754940,"mc":[{"id":"1.195453675","rc":[{"atl":[[2.14,17.79]],"id":6780934}],"con":true,"img":false}]}
{"op":"mcm","clk":"5348350683","pt":1646216755045,"mc":[{"id":"1.195453675","rc":[{"atb":[[1.9,32.41]],"id":40250501},{"atl":[[2.12,53.2]],"id":6780934}],"con":true,"img":false}]}
{"op":"mcm","clk":"5348350719","pt":1646216755568,"mc":[{"id":"1.195453675","rc":[{"atb":[[1.88,18.82]],"id":40250501}],"con":true,"img":false}]}
{"op":"mcm","clk":"5348350773","pt":1646216756145,"mc":[{"id":"1.195453675","rc":[{"atl":[[2.1,8.87]],"id":6780934}],"con":true,"img":false}]}
{"op":"mcm","clk":"5348350786","pt":1646216756250,"mc":[{"id":"1.195453675","rc":[{"atb":[[1.91,9.46]],"id":40250501},{"atl":[[2.18,8.77]],"id":6780934}],"con":true,"img":false}]}
{"op":"mcm","clk":"5348350814","pt":1646216756669,"mc":[{"id":"1.195453675","rc":[{"atl":[[2.12,17.6]],"id":6780934}],"con":true,"img":false}]}
{"op":"mcm","clk":"5348350830","pt":1646216756776,"mc":[{"id":"1.195453675","rc":[{"atl":[[2.1,44.47]],"id":6780934}],"con":true,"img":false}]}
{"op":"mcm","clk":"5348350861","pt":1646216757144,"mc":[{"id":"1.195453675","rc":[{"atl":[[2.1,26.63]],"id":6780934}],"con":true,"img":false}]}
{"op":"mcm","clk":"5348350909","pt":1646216757626,"mc":[{"id":"1.195453675","rc":[{"atl":[[2.3,15.77]],"id":40250501}],"con":true,"img":false}]}
{"op":"mcm","clk":"5348350919","pt":1646216757729,"mc":[{"id":"1.195453675","rc":[{"atb":[[2.1,2.11]],"id":40250501}],"con":true,"img":false}]}
{"op":"mcm","clk":"5348350930","pt":1646216757838,"mc":[{"id":"1.195453675","rc":[{"atl":[[2.08,8.95]],"id":6780934}],"con":true,"img":false}]}
{"op":"mcm","clk":"5348350951","pt":1646216758047,"mc":[{"id":"1.195453675","rc":[{"atb":[[2.1,0]],"id":40250501},{"atl":[[2.18,0]],"id":6780934}],"con":true,"img":false}]}
{"op":"mcm","clk":"5348350967","pt":1646216758257,"mc":[{"id":"1.195453675","rc":[{"atb":[[1.92,9.23]],"id":40250501},{"atl":[[2.1,8.87]],"id":6780934}],"con":true,"img":false}]}
{"op":"mcm","clk":"5348350975","pt":1646216758361,"mc":[{"id":"1.195453675","rc":[{"atb":[[1.91,24.22]],"id":40250501},{"atl":[[2.08,26.71]],"id":6780934}],"con":true,"img":false}]}
{"op":"mcm","clk":"5348350999","pt":1646216758582,"mc":[{"id":"1.195453675","rc":[{"atb":[[1.74,0]],"id":6780934}],"con":true,"img":false}]}
{"op":"mcm","clk":"5348351004","pt":1646216758677,"mc":[{"id":"1.195453675","rc":[{"atb":[[1.91,9.46]],"id":40250501},{"atl":[[2.08,8.95]],"id":6780934}],"con":true,"img":false}]}
{"op":"mcm","clk":"5348351020","pt":1646216758784,"mc":[{"id":"1.195453675","rc":[{"atb":[[1.92,23.99]],"id":40250501},{"atb":[[1.83,2]],"id":6780934},{"atl":[[2.1,26.63]],"id":6780934}],"con":true,"img":false}]}
{"op":"mcm","clk":"5348351027","pt":1646216758836,"mc":[{"id":"1.195453675","rc":[{"atb":[[1.81,0]],"id":6780934}],"con":true,"img":false}]}
{"op":"mcm","clk":"5348351036","pt":1646216758944,"mc":[{"id":"1.195453675","rc":[{"atb":[[1.93,9.13]],"id":40250501}],"con":true,"img":false}]}
{"op":"mcm","clk":"5348351058","pt":1646216759155,"mc":[{"id":"1.195453675","rc":[{"atl":[[2.1,8.87]],"id":6780934}],"con":true,"img":false}]}
{"op":"mcm","clk":"5348351070","pt":1646216759258,"mc":[{"id":"1.195453675","rc":[{"atb":[[1.92,9.23]],"id":40250501},{"atl":[[2.08,26.71]],"id":6780934}],"con":true,"img":false}]}
{"op":"mcm","clk":"5348351084","pt":1646216759368,"mc":[{"id":"1.195453675","rc":[{"atb":[[1.93,23.89]],"id":40250501}],"con":true,"img":false}]}
{"op":"mcm","clk":"5348351101","pt":1646216759581,"mc":[{"id":"1.195453675","rc":[{"atb":[[1.94,9.11],[1.93,55.26],[1.88,9.41]],"id":40250501},{"atl":[[1.89,7.62],[2.08,8.95],[2.06,9.21],[2.16,8.87]],"id":6780934}],"con":true,"img":false}]}
{"op":"mcm","clk":"5348351108","pt":1646216759636,"mc":[{"id":"1.195453675","rc":[{"atb":[[1.93,40.5]],"id":40250501},{"atl":[[2.1,26.63]],"id":6780934}],"con":true,"img":false}]}
{"op":"mcm","clk":"5348351121","pt":1646216759738,"mc":[{"id":"1.195453675","rc":[{"atb":[[1.92,23.99]],"id":40250501}],"con":true,"img":false}]}
{"op":"mcm","clk":"5348351154","pt":1646216760052,"mc":[{"id":"1.195453675","rc":[{"atb":[[1.92,9.23]],"id":40250501}],"con":true,"img":false}]}
{"op":"mcm","clk":"5348351160","pt":1646216760155,"mc":[{"id":"1.195453675","rc":[{"atb":[[1.94,23.87]],"id":40250501}],"con":true,"img":false}]}
{"op":"mcm","clk":"5348351193","pt":1646216760583,"mc":[{"id":"1.195453675","rc":[{"atb":[[1.9,0]],"id":40250501}],"con":true,"img":false}]}
{"op":"mcm","clk":"5348351239","pt":1646216761052,"mc":[{"id":"1.195453675","rc":[{"atb":[[1.95,17.96]],"id":40250501}],"con":true,"img":false}]}
{"op":"mcm","clk":"5348351247","pt":1646216761155,"mc":[{"id":"1.195453675","rc":[{"atb":[[1.89,0]],"id":40250501}],"con":true,"img":false}]}
{"op":"mcm","clk":"5348351266","pt":1646216761363,"mc":[{"id":"1.195453675","rc":[{"atb":[[1.94,9.11]],"id":40250501}],"con":true,"img":false}]}
{"op":"mcm","clk":"5348351280","pt":1646216761468,"mc":[{"id":"1.195453675","rc":[{"atb":[[1.95,32.72]],"id":40250501}],"con":true,"img":false}]}
{"op":"mcm","clk":"5348351282","pt":1646216761569,"mc":[{"id":"1.195453675","rc":[{"atb":[[1.95,63.43]],"id":40250501}],"con":true,"img":false}]}
{"op":"mcm","clk":"5348351302","pt":1646216761780,"mc":[{"id":"1.195453675","rc":[{"atb":[[1.95,55.07]],"id":40250501}],"con":true,"img":false}]}
{"op":"mcm","clk":"5348351333","pt":1646216762044,"mc":[{"id":"1.195453675","rc":[{"atb":[[1.95,24.36]],"id":40250501}],"con":true,"img":false}]}
{"op":"mcm","clk":"5348351353","pt":1646216762253,"mc":[{"id":"1.195453675","rc":[{"atb":[[1.96,8.81]],"id":40250501}],"con":true,"img":false}]}
{"op":"mcm","clk":"5348351361","pt":1646216762358,"mc":[{"id":"1.195453675","rc":[{"atb":[[1.96,17.63],[1.87,6.2],[1.97,5.56],[1.91,0],[1.77,29]],"id":40250501},{"atb":[[1.45,11.98],[1.55,9.8],[1.35,15.41]],"id":6780934}],"con":true,"img":false}]}
{"op":"mcm","clk":"5348351371","pt":1646216762478,"mc":[{"id":"1.195453675","rc":[{"atb":[[1.96,48.02],[1.92,0],[1.97,14.55]],"id":40250501}],"con":true,"img":false}]}
{"op":"mcm","clk":"5348351385","pt":1646216762677,"mc":[{"id":"1.195453675","rc":[{"atb":[[1.95,17.96]],"id":40250501}],"con":true,"img":false}]}
{"op":"mcm","clk":"5348351410","pt":1646216762890,"mc":[{"id":"1.195453675","rc":[{"atb":[[1.83,6]],"id":6780934}],"con":true,"img":false}]}
{"op":"mcm","clk":"5348351438","pt":1646216763158,"mc":[{"id":"1.195453675","rc":[{"atl":[[2.28,2]],"id":40250501}],"con":true,"img":false}]}
{"op":"mcm","clk":"5348351471","pt":1646216763477,"mc":[{"id":"1.195453675","rc":[{"atl":[[2.3,8.65]],"id":40250501},{"atb":[[1.78,37.4]],"id":6780934}],"con":true,"img":false}]}
{"op":"mcm","clk":"5348351475","pt":1646216763571,"mc":[{"id":"1.195453675","rc":[{"atl":[[2.28,9.12]],"id":40250501}],"con":true,"img":false}]}
{"op":"mcm","clk":"5348351778","pt":1646216766559,"mc":[{"id":"1.195453675","rc":[{"atb":[[1.98,17.69]],"id":40250501}],"con":true,"img":false}]}
{"op":"mcm","clk":"5348351789","pt":1646216766665,"mc":[{"id":"1.195453675","rc":[{"atb":[[1.93,31.36],[1.81,2]],"id":40250501}],"con":true,"img":false}]}
{"op":"mcm","clk":"5348351827","pt":1646216767081,"mc":[{"id":"1.195453675","rc":[{"atb":[[1.98,19.93],[1.93,0]],"id":40250501}],"con":true,"img":false}]}
{"op":"mcm","clk":"5348351835","pt":1646216767185,"mc":[{"id":"1.195453675","rc":[{"atb":[[1.97,5.56]],"id":40250501}],"con":true,"img":false}]}
{"op":"mcm","clk":"5348351929","pt":1646216768081,"mc":[{"id":"1.195453675","rc":[{"atb":[[1.94,0],[1.99,8.85]],"id":40250501}],"con":true,"img":false}]}
{"op":"mcm","clk":"5348351957","pt":1646216768390,"mc":[{"id":"1.195453675","rc":[{"atb":[[1.98,17.69],[1.99,11.08]],"id":40250501},{"atl":[[2.26,2],[2.28,7.12]],"id":40250501}],"con":true,"img":false}]}
{"op":"mcm","clk":"5348351973","pt":1646216768548,"mc":[{"id":"1.195453675","rc":[{"atb":[[1.99,40.55]],"id":40250501}],"con":true,"img":false}]}
{"op":"mcm","clk":"5348352010","pt":1646216768875,"mc":[{"id":"1.195453675","rc":[{"atl":[[2.28,0]],"id":40250501}],"con":true,"img":false}]}
{"op":"mcm","clk":"5348352020","pt":1646216768967,"mc":[{"id":"1.195453675","rc":[{"atl":[[2.26,9.12]],"id":40250501},{"atl":[[1.89,0]],"id":6780934}],"con":true,"img":false}]}
{"op":"mcm","clk":"5348352027","pt":1646216769070,"mc":[{"id":"1.195453675","rc":[{"atl":[[2,7.62]],"id":6780934}],"con":true,"img":false}]}
{"op":"mcm","clk":"5348352035","pt":1646216769174,"mc":[{"id":"1.195453675","rc":[{"atb":[[2,17.57],[1.95,8.98],[1.88,0]],"id":40250501}],"con":true,"img":false}]}
{"op":"mcm","clk":"5348352072","pt":1646216769484,"mc":[{"id":"1.195453675","rc":[{"atb":[[1.81,36.02]],"id":6780934}],"con":true,"img":false}]}
{"op":"mcm","clk":"5348352179","pt":1646216770788,"mc":[{"id":"1.195453675","rc":[{"atl":[[1.99,9.56]],"id":6780934}],"con":true,"img":false}]}
{"op":"mcm","clk":"5348352183","pt":1646216770842,"mc":[{"id":"1.195453675","rc":[{"atl":[[2.14,8.89]],"id":6780934}],"con":true,"img":false}]}
{"op":"mcm","clk":"5348352198","pt":1646216770950,"mc":[{"id":"1.195453675","rc":[{"atb":[[2,19.79],[1.96,17.63],[1.99,38.32]],"id":40250501}],"con":true,"img":false}]}
{"op":"mcm","clk":"5348352630","pt":1646216775391,"mc":[{"id":"1.195453675","rc":[{"atb":[[1.95,0],[2.02,8.79]],"id":40250501}],"con":true,"img":false}]}
{"op":"mcm","clk":"5348352685","pt":1646216775964,"mc":[{"id":"1.195453675","rc":[{"atb":[[2.02,37.39]],"id":40250501}],"con":true,"img":false}]}
{"op":"mcm","clk":"5348352700","pt":1646216776172,"mc":[{"id":"1.195453675","rc":[{"atl":[[2.26,7.12],[2.24,2]],"id":40250501}],"con":true,"img":false}]}
{"op":"mcm","clk":"5348352735","pt":1646216776592,"mc":[{"id":"1.195453675","rc":[{"atl":[[2.26,0]],"id":40250501}],"con":true,"img":false}]}
{"op":"mcm","clk":"5348352742","pt":1646216776694,"mc":[{"id":"1.195453675","rc":[{"atl":[[2.24,9.12]],"id":40250501}],"con":true,"img":false}]}
{"op":"mcm","clk":"5348352765","pt":1646216776953,"mc":[{"id":"1.195453675","rc":[{"atl":[[2,0]],"id":6780934}],"con":true,"img":false}]}
{"op":"mcm","clk":"5348352773","pt":1646216777055,"mc":[{"id":"1.195453675","rc":[{"atl":[[2.24,2]],"id":40250501},{"atl":[[1.98,7.62],[1.99,0]],"id":6780934}],"con":true,"img":false}]}
{"op":"mcm","clk":"5348352781","pt":1646216777160,"mc":[{"id":"1.195453675","rc":[{"atl":[[1.97,9.42]],"id":6780934}],"con":true,"img":false}]}
{"op":"mcm","clk":"5348352802","pt":1646216777370,"mc":[{"id":"1.195453675","rc":[{"atb":[[2.04,8.9],[1.96,8.81]],"id":40250501},{"atl":[[2.24,6.38]],"id":40250501},{"atl":[[2.16,0]],"id":6780934}],"con":true,"img":false}]}
{"op":"mcm","clk":"5348352822","pt":1646216777581,"mc":[{"id":"1.195453675","rc":[{"atb":[[2,11],[2.04,0],[1.99,29.46]],"id":40250501},{"atl":[[1.97,0]],"id":6780934}],"con":true,"img":false}]}
{"op":"mcm","clk":"5348352867","pt":1646216777949,"mc":[{"id":"1.195453675","rc":[{"atl":[[1.98,16.98]],"id":6780934}],"con":true,"img":false}]}
{"op":"mcm","clk":"5348352874","pt":1646216778052,"mc":[{"id":"1.195453675","rc":[{"atb":[[2.02,8.79]],"id":40250501},{"atl":[[1.97,9.37]],"id":6780934}],"con":true,"img":false}]}
{"op":"mcm","clk":"5348352884","pt":1646216778156,"mc":[{"id":"1.195453675","rc":[{"atl":[[2.14,0]],"id":6780934}],"con":true,"img":false}]}
{"op":"mcm","clk":"5348352903","pt":1646216778366,"mc":[{"id":"1.195453675","rc":[{"atb":[[2,8.78],[2.02,10.98]],"id":40250501}],"con":true,"img":false}]}
{"op":"mcm","clk":"5348352942","pt":1646216778783,"mc":[{"id":"1.195453675","rc":[{"atl":[[1.97,0]],"id":6780934}],"con":true,"img":false}]}
{"op":"mcm","clk":"5348352955","pt":1646216778889,"mc":[{"id":"1.195453675","rc":[{"atl":[[1.93,1]],"id":6780934}],"con":true,"img":false}]}
{"op":"mcm","clk":"5348352963","pt":1646216778995,"mc":[{"id":"1.195453675","rc":[{"atb":[[2.02,39.58]],"id":40250501}],"con":true,"img":false}]}
{"op":"mcm","clk":"5348352997","pt":1646216779256,"mc":[{"id":"1.195453675","rc":[{"atl":[[1.97,9.37]],"id":6780934}],"con":true,"img":false}]}
{"op":"mcm","clk":"5348353105","pt":1646216780197,"mc":[{"id":"1.195453675","rc":[{"atl":[[1.97,0]],"id":6780934}],"con":true,"img":false}]}
{"op":"mcm","clk":"5348353174","pt":1646216780776,"mc":[{"id":"1.195453675","rc":[{"atb":[[2.04,8.9]],"id":40250501},{"atl":[[1.97,9.43]],"id":6780934}],"con":true,"img":false}]}
{"op":"mcm","clk":"5348353201","pt":1646216781090,"mc":[{"id":"1.195453675","rc":[{"atl":[[1.98,9.35]],"id":6780934}],"con":true,"img":false}]}
{"op":"mcm","clk":"5348353213","pt":1646216781196,"mc":[{"id":"1.195453675","rc":[{"atl":[[1.96,7.62]],"id":6780934}],"con":true,"img":false}]}
{"op":"mcm","clk":"5348353244","pt":1646216781559,"mc":[{"id":"1.195453675","rc":[{"atl":[[2.12,8.8],[1.96,17.1]],"id":6780934}],"con":true,"img":false}]}
{"op":"mcm","clk":"5348353287","pt":1646216782085,"mc":[{"id":"1.195453675","rc":[{"atb":[[1.87,0],[1.97,0],[1.77,22]],"id":40250501},{"atb":[[1.45,0],[1.55,0],[1.35,0]],"id":6780934}],"con":true,"img":false}]}
{"op":"mcm","clk":"5348353319","pt":1646216782398,"mc":[{"id":"1.195453675","rc":[{"atb":[[2.04,0]],"id":40250501},{"atl":[[1.96,7.62],[1.97,0]],"id":6780934}],"con":true,"img":false}]}
{"op":"mcm","clk":"5348353369","pt":1646216782869,"mc":[{"id":"1.195453675","rc":[{"atl":[[2.24,4.38],[2.18,2]],"id":40250501},{"atb":[[1.83,4],[1.84,2]],"id":6780934}],"con":true,"img":false}]}
{"op":"mcm","clk":"5348353412","pt":1646216783288,"mc":[{"id":"1.195453675","rc":[{"atl":[[2.24,0]],"id":40250501},{"atb":[[1.83,0]],"id":6780934}],"con":true,"img":false}]}
{"op":"mcm","clk":"5348353420","pt":1646216783391,"mc":[{"id":"1.195453675","rc":[{"atl":[[2.18,6.38]],"id":40250501},{"atb":[[1.84,6]],"id":6780934}],"con":true,"img":false}]}
{"op":"mcm","clk":"5348353493","pt":1646216784178,"mc":[{"id":"1.195453675","rc":[{"atl":[[2.18,2]],"id":40250501},{"atb":[[1.84,2]],"id":6780934},{"atl":[[2.1,8.87]],"id":6780934}],"con":true,"img":false}]}
{"op":"mcm","clk":"5348353526","pt":1646216784597,"mc":[{"id":"1.195453675","rc":[{"atb":[[1.84,0],[1.85,2]],"id":6780934}],"con":true,"img":false}]}
{"op":"mcm","clk":"5348353539","pt":1646216784704,"mc":[{"id":"1.195453675","rc":[{"atl":[[2.24,2],[2.18,0]],"id":40250501}],"con":true,"img":false}]}
{"op":"mcm","clk":"5348353589","pt":1646216785174,"mc":[{"id":"1.195453675","rc":[{"atl":[[2.24,6.38]],"id":40250501},{"atb":[[1.85,6]],"id":6780934}],"con":true,"img":false}]}
{"op":"mcm","clk":"5348353605","pt":1646216785385,"mc":[{"id":"1.195453675","rc":[{"atl":[[1.93,0]],"id":6780934}],"con":true,"img":false}]}
{"op":"mcm","clk":"5348353614","pt":1646216785489,"mc":[{"id":"1.195453675","rc":[{"atl":[[1.91,1]],"id":6780934}],"con":true,"img":false}]}
{"op":"mcm","clk":"5348353690","pt":1646216786279,"mc":[{"id":"1.195453675","rc":[{"atb":[[2.04,8.85]],"id":40250501},{"atl":[[1.95,9.49]],"id":6780934}],"con":true,"img":false}]}
{"op":"mcm","clk":"5348353715","pt":1646216786695,"mc":[{"id":"1.195453675","rc":[{"atb":[[2.04,11.02],[2.02,37.39]],"id":40250501}],"con":true,"img":false}]}
{"op":"mcm","clk":"5348353725","pt":1646216786800,"mc":[{"id":"1.195453675","rc":[{"atb":[[2.04,2.17]],"id":40250501},{"atl":[[1.95,0]],"id":6780934}],"con":true,"img":false}]}
{"op":"mcm","clk":"5348353810","pt":1646216787691,"mc":[{"id":"1.195453675","rc":[{"atb":[[2.04,11.04]],"id":40250501},{"atl":[[1.96,17.1]],"id":6780934}],"con":true,"img":false}]}
{"op":"mcm","clk":"5348353826","pt":1646216787897,"mc":[{"id":"1.195453675","rc":[{"atl":[[1.95,9.49]],"id":6780934}],"con":true,"img":false}]}
{"op":"mcm","clk":"5348353839","pt":1646216788000,"mc":[{"id":"1.195453675","rc":[{"atb":[[1.99,0]],"id":40250501}],"con":true,"img":false}]}
{"op":"mcm","clk":"5348353917","pt":1646216788993,"mc":[{"id":"1.195453675","rc":[{"atl":[[1.91,0]],"id":6780934}],"con":true,"img":false}]}
{"op":"mcm","clk":"5348353922","pt":1646216789098,"mc":[{"id":"1.195453675","rc":[{"atl":[[1.89,1]],"id":6780934}],"con":true,"img":false}]}
{"op":"mcm","clk":"5348353952","pt":1646216789462,"mc":[{"id":"1.195453675","rc":[{"atb":[[2.06,27.52]],"id":40250501}],"con":true,"img":false}]}
{"op":"mcm","clk":"5348353973","pt":1646216789671,"mc":[{"id":"1.195453675","rc":[{"atl":[[2.2,0]],"id":40250501},{"trd":[[2.2,39.08]],"ltp":2.2,"tv":39.08,"id":40250501},{"atb":[[1.81,25.24],[1.85,0]],"id":6780934},{"trd":[[1.81,23.54],[1.83,62.8],[1.85,12]],"ltp":1.81,"tv":98.34,"id":6780934}],"con":true,"img":false}]}
{"op":"mcm","clk":"5348353988","pt":1646216789777,"mc":[{"id":"1.195453675","rc":[{"atb":[[2.08,8.64]],"id":40250501},{"atl":[[2.24,4.38]],"id":40250501}],"con":true,"img":false}]}
{"op":"mcm","clk":"5348353997","pt":1646216789880,"mc":[{"id":"1.195453675","rc":[{"atl":[[2.2,2]],"id":40250501},{"atb":[[1.82,2]],"id":6780934}],"con":true,"img":false}]}
{"op":"mcm","clk":"5348354005","pt":1646216789985,"mc":[{"id":"1.195453675","rc":[{"atb":[[1.98,8.84]],"id":40250501},{"atl":[[2.22,2],[2.2,0]],"id":40250501}],"con":true,"img":false}]}
{"op":"mcm","clk":"5348354013","pt":1646216790088,"mc":[{"id":"1.195453675","rc":[{"atl":[[2.24,0]],"id":40250501},{"atb":[[1.81,0],[1.78,0]],"id":6780934},{"atl":[[1.89,11.22]],"id":6780934}],"con":true,"img":false}]}
{"op":"mcm","clk":"5348354028","pt":1646216790301,"mc":[{"id":"1.195453675","rc":[{"atl":[[2.22,0],[2.28,2]],"id":40250501}],"con":true,"img":false}]}
{"op":"mcm","clk":"5348354051","pt":1646216790510,"mc":[{"id":"1.195453675","rc":[{"atb":[[2.08,10.77]],"id":40250501},{"atl":[[2.22,4]],"id":40250501}],"con":true,"img":false}]}
{"op":"mcm","clk":"5348354060","pt":1646216790615,"mc":[{"id":"1.195453675","rc":[{"atb":[[2.04,8.87]],"id":40250501}],"con":true,"img":false}]}
{"op":"mcm","clk":"5348354080","pt":1646216790773,"mc":[{"id":"1.195453675","rc":[{"atl":[[2.22,0]],"id":40250501}],"con":true,"img":false}]}
{"op":"mcm","clk":"5348354094","pt":1646216790984,"mc":[{"id":"1.195453675","rc":[{"atb":[[1.64,8.43],[1.84,6.42],[1.74,40.29]],"id":40250501},{"atb":[[1.64,8.43],[1.82,6],[1.74,7.29],[1.54,9.98]],"id":6780934}],"con":true,"img":false}]}
{"op":"mcm","clk":"5348354100","pt":1646216791091,"mc":[{"id":"1.195453675","rc":[{"atl":[[2.28,6]],"id":40250501}],"con":true,"img":false}]}
{"op":"mcm","clk":"5348354115","pt":1646216791297,"mc":[{"id":"1.195453675","rc":[{"atl":[[1.96,9.47]],"id":6780934}],"con":true,"img":false}]}
{"op":"mcm","clk":"5348354122","pt":1646216791401,"mc":[{"id":"1.195453675","rc":[{"atl":[[1.97,7.62]],"id":6780934}],"con":true,"img":false}]}
{"op":"mcm","clk":"5348354186","pt":1646216792097,"mc":[{"id":"1.195453675","rc":[{"atl":[[1.89,9.62]],"id":6780934},{"trd":[[1.89,3.2]],"ltp":1.89,"tv":3.2,"id":6780934}],"con":true,"img":false}]}
{"op":"mcm","clk":"5348354232","pt":1646216792668,"mc":[{"id":"1.195453675","rc":[{"atl":[[1.85,4.34]],"id":6780934}],"con":true,"img":false}]}
{"op":"mcm","clk":"5348354239","pt":1646216792774,"mc":[{"id":"1.195453675","rc":[{"atl":[[1.89,0]],"id":6780934}],"con":true,"img":false}]}
{"op":"mcm","clk":"5348354247","pt":1646216792878,"mc":[{"id":"1.195453675","rc":[{"atl":[[2.08,0],[1.88,10.14]],"id":6780934}],"con":true,"img":false}]}
{"op":"mcm","clk":"5348354292","pt":1646216793523,"mc":[{"id":"1.195453675","rc":[{"atb":[[1.77,37.88]],"id":6780934}],"con":true,"img":false}]}
{"op":"mcm","clk":"5348354551","pt":1646216796508,"mc":[{"id":"1.195453675","rc":[{"atl":[[1.98,0],[1.85,14.54]],"id":6780934}],"con":true,"img":false}]}
{"op":"mcm","clk":"5348354595","pt":1646216796986,"mc":[{"id":"1.195453675","rc":[{"atb":[[2.08,37.79]],"id":40250501}],"con":true,"img":false}]}
{"op":"mcm","clk":"5348354650","pt":1646216797611,"mc":[{"id":"1.195453675","rc":[{"atl":[[1.85,4.34]],"id":6780934}],"con":true,"img":false}]}
{"op":"mcm","clk":"5348354688","pt":1646216798031,"mc":[{"id":"1.195453675","rc":[{"atb":[[2.08,10.77]],"id":40250501}],"con":true,"img":false}]}
{"op":"mcm","clk":"5348354825","pt":1646216799198,"mc":[{"id":"1.195453675","rc":[{"atl":[[2.26,2],[2.28,4]],"id":40250501}],"con":true,"img":false}]}
{"op":"mcm","clk":"5348354851","pt":1646216799492,"mc":[{"id":"1.195453675","rc":[{"atl":[[2.28,0]],"id":40250501},{"atl":[[1.85,0]],"id":6780934}],"con":true,"img":false}]}
{"op":"mcm","clk":"5348354858","pt":1646216799597,"mc":[{"id":"1.195453675","rc":[{"atl":[[2.26,6]],"id":40250501},{"atb":[[1.82,1.66]],"id":6780934},{"trd":[[1.82,8.68]],"ltp":1.82,"tv":8.68,"id":6780934}],"con":true,"img":false}]}
{"op":"mcm","clk":"5348354871","pt":1646216799701,"mc":[{"id":"1.195453675","rc":[{"atb":[[1.78,2]],"id":6780934}],"con":true,"img":false}]}
{"op":"mcm","clk":"5348354892","pt":1646216799909,"mc":[{"id":"1.195453675","rc":[{"atb":[[1.82,0]],"id":6780934}],"con":true,"img":false}]}
{"op":"mcm","clk":"5348354952","pt":1646216800536,"mc":[{"id":"1.195453675","rc":[{"atb":[[1.8,68.41]],"id":6780934}],"con":true,"img":false}]}
{"op":"mcm","clk":"5348355007","pt":1646216801115,"mc":[{"id":"1.195453675","rc":[{"atb":[[1.8,89.63]],"id":6780934}],"con":true,"img":false}]}
{"op":"mcm","clk":"5348355073","pt":1646216801799,"mc":[{"id":"1.195453675","rc":[{"atl":[[1.97,0]],"id":6780934}],"con":true,"img":false}]}
{"op":"mcm","clk":"5348355085","pt":1646216801905,"mc":[{"id":"1.195453675","rc":[{"atl":[[1.83,7.62]],"id":6780934}],"con":true,"img":false}]}
{"op":"mcm","clk":"5348355107","pt":1646216802118,"mc":[{"id":"1.195453675","rc":[{"trd":[[2.2,45.44]],"ltp":2.2,"tv":45.44,"id":40250501},{"atl":[[1.83,0]],"id":6780934},{"trd":[[1.83,70.43]],"ltp":1.83,"tv":70.43,"id":6780934}],"con":true,"img":false}]}
{"op":"mcm","clk":"5348355192","pt":1646216802797,"mc":[{"id":"1.195453675","rc":[{"atl":[[2.16,8.74]],"id":40250501}],"con":true,"img":false}]}
{"op":"mcm","clk":"5348355213","pt":1646216803006,"mc":[{"id":"1.195453675","rc":[{"trd":[[2.12,1.9]],"ltp":2.12,"tv":1.9,"id":40250501},{"atl":[[1.88,8]],"id":6780934},{"trd":[[1.88,2.14]],"ltp":1.88,"tv":2.14,"id":6780934}],"con":true,"img":false}]}
{"op":"mcm","clk":"5348355232","pt":1646216803215,"mc":[{"id":"1.195453675","rc":[{"atb":[[1.81,2],[1.78,0]],"id":6780934},{"atl":[[1.88,0]],"id":6780934},{"trd":[[1.88,18.15]],"ltp":1.88,"tv":18.15,"id":6780934}],"con":true,"img":false}]}
{"op":"mcm","clk":"5348355272","pt":1646216803634,"mc":[{"id":"1.195453675","rc":[{"atb":[[1.8,68.41]],"id":6780934}],"con":true,"img":false}]}
{"op":"mcm","clk":"5348355283","pt":1646216803687,"mc":[{"id":"1.195453675","rc":[{"atb":[[1.81,23.22]],"id":6780934}],"con":true,"img":false}]}
{"op":"mcm","clk":"5348355305","pt":1646216804004,"mc":[{"id":"1.195453675","rc":[{"atb":[[1.81,6]],"id":6780934}],"con":true,"img":false}]}
{"op":"mcm","clk":"5348355334","pt":1646216804422,"mc":[{"id":"1.195453675","rc":[{"atl":[[2.26,4],[2.14,2]],"id":40250501}],"con":true,"img":false}]}
{"op":"mcm","clk":"5348355378","pt":1646216805037,"mc":[{"id":"1.195453675","rc":[{"atb":[[2.04,0],[2.08,0],[2.06,0]],"id":40250501},{"trd":[[2.04,20.59],[2.06,55.02],[2.08,31.55]],"ltp":2.04,"tv":107.16,"id":40250501},{"atl":[[1.95,6.52]],"id":6780934},{"trd":[[1.95,2.97]],"ltp":1.95,"tv":2.97,"id":6780934}],"con":true,"img":false}]}
{"op":"mcm","clk":"5348355394","pt":1646216805200,"mc":[{"id":"1.195453675","rc":[{"atl":[[2.24,8.38]],"id":40250501},{"atb":[[1.82,10.03]],"id":6780934}],"con":true,"img":false}]}
{"op":"mcm","clk":"5348355436","pt":1646216805625,"mc":[{"id":"1.195453675","rc":[{"atb":[[1.81,2]],"id":6780934}],"con":true,"img":false}]}
{"op":"mcm","clk":"5348355465","pt":1646216805888,"mc":[{"id":"1.195453675","rc":[{"atl":[[1000,0.07]],"id":40250501}],"con":true,"img":false}]}
{"op":"mcm","clk":"5348355475","pt":1646216805999,"mc":[{"id":"1.195453675","rc":[{"atb":[[1.82,30.11]],"id":6780934}],"con":true,"img":false}]}
{"op":"mcm","clk":"5348355483","pt":1646216806100,"mc":[{"id":"1.195453675","rc":[{"atb":[[2.04,8.62]],"id":40250501},{"atl":[[1000,0]],"id":40250501}],"con":true,"img":false}]}
{"op":"mcm","clk":"5348355499","pt":1646216806313,"mc":[{"id":"1.195453675","rc":[{"atb":[[2.04,8.55]],"id":40250501},{"trd":[[2.04,20.73]],"ltp":2.04,"tv":20.73,"id":40250501}],"con":true,"img":false}]}
{"op":"mcm","clk":"5348355689","pt":1646216808314,"mc":[{"id":"1.195453675","rc":[{"atb":[[1.83,2],[1.81,0]],"id":6780934}],"con":true,"img":false}]}
{"op":"mcm","clk":"5348355709","pt":1646216808523,"mc":[{"id":"1.195453675","rc":[{"atb":[[1.83,37.15]],"id":6780934}],"con":true,"img":false}]}
{"op":"mcm","clk":"5348355727","pt":1646216808733,"mc":[{"id":"1.195453675","rc":[{"atb":[[1.82,10.03]],"id":6780934}],"con":true,"img":false}]}
{"op":"mcm","clk":"5348355736","pt":1646216808849,"mc":[{"id":"1.195453675","rc":[{"atb":[[1.83,57.23]],"id":6780934}],"con":true,"img":false}]}
{"op":"mcm","clk":"5348355764","pt":1646216809003,"mc":[{"id":"1.195453675","rc":[{"atb":[[1.83,22.08]],"id":6780934}],"con":true,"img":false}]}
{"op":"mcm","clk":"5348355796","pt":1646216809314,"mc":[{"id":"1.195453675","rc":[{"atb":[[1.83,6]],"id":6780934}],"con":true,"img":false}]}
{"op":"mcm","clk":"5348355968","pt":1646216810899,"mc":[{"id":"1.195453675","rc":[{"atb":[[1.83,16.93]],"id":6780934}],"con":true,"img":false}]}
{"op":"mcm","clk":"5348355976","pt":1646216811005,"mc":[{"id":"1.195453675","rc":[{"atl":[[2.16,17.32]],"id":40250501},{"atb":[[1.84,9.79]],"id":6780934}],"con":true,"img":false}]}
{"op":"mcm","clk":"5348355985","pt":1646216811105,"mc":[{"id":"1.195453675","rc":[{"atb":[[1.83,14.93],[1.85,2]],"id":6780934}],"con":true,"img":false}]}
{"op":"mcm","clk":"5348356003","pt":1646216811319,"mc":[{"id":"1.195453675","rc":[{"atb":[[1.83,10.93]],"id":6780934}],"con":true,"img":false}]}
{"op":"mcm","clk":"5348356020","pt":1646216811526,"mc":[{"id":"1.195453675","rc":[{"atb":[[1.84,44.53]],"id":6780934}],"con":true,"img":false}]}
{"op":"mcm","clk":"5348356043","pt":1646216811741,"mc":[{"id":"1.195453675","rc":[{"atl":[[2.16,8.58]],"id":40250501},{"atb":[[1.85,6]],"id":6780934}],"con":true,"img":false}]}
{"op":"mcm","clk":"5348356070","pt":1646216811949,"mc":[{"id":"1.195453675","rc":[{"atl":[[2.26,0]],"id":40250501}],"con":true,"img":false}]}
{"op":"mcm","clk":"5348356081","pt":1646216812006,"mc":[{"id":"1.195453675","rc":[{"atl":[[2.14,6],[2.16,0]],"id":40250501}],"con":true,"img":false}]}
{"op":"mcm","clk":"5348356130","pt":1646216812535,"mc":[{"id":"1.195453675","rc":[{"atb":[[1.83,46.08],[1.84,9.79]],"id":6780934}],"con":true,"img":false}]}
{"op":"mcm","clk":"5348356213","pt":1646216813322,"mc":[{"id":"1.195453675","rc":[{"atb":[[1.64,0],[1.84,0],[1.74,33]],"id":40250501},{"atb":[[1.64,0],[1.74,0],[1.54,0]],"id":6780934}],"con":true,"img":false}]}
{"op":"mcm","clk":"5348356341","pt":1646216814427,"mc":[{"id":"1.195453675","rc":[{"atb":[[1.84,0]],"id":6780934}],"con":true,"img":false}]}
{"op":"mcm","clk":"5348356410","pt":1646216815014,"mc":[{"id":"1.195453675","rc":[{"atb":[[1.83,10.93]],"id":6780934}],"con":true,"img":false}]}
{"op":"mcm","clk":"5348356498","pt":1646216815981,"mc":[{"id":"1.195453675","rc":[{"atb":[[1.85,4],[1.86,2]],"id":6780934}],"con":true,"img":false}]}
{"op":"mcm","clk":"5348356513","pt":1646216816136,"mc":[{"id":"1.195453675","rc":[{"atb":[[1.83,20.98]],"id":6780934}],"con":true,"img":false}]}
{"op":"mcm","clk":"5348356536","pt":1646216816358,"mc":[{"id":"1.195453675","rc":[{"atb":[[1.85,0]],"id":6780934}],"con":true,"img":false}]}
{"op":"mcm","clk":"5348356547","pt":1646216816454,"mc":[{"id":"1.195453675","rc":[{"atb":[[1.85,9.86],[1.86,6]],"id":6780934}],"con":true,"img":false}]}
{"op":"mcm","clk":"5348356556","pt":1646216816556,"mc":[{"id":"1.195453675","rc":[{"atb":[[1.83,56.13],[1.66,0]],"id":6780934}],"con":true,"img":false}]}
{"op":"mcm","clk":"5348356701","pt":1646216817921,"mc":[{"id":"1.195453675","rc":[{"atb":[[1.84,10.87]],"id":6780934}],"con":true,"img":false}]}
{"op":"mcm","clk":"5348356726","pt":1646216818227,"mc":[{"id":"1.195453675","rc":[{"atl":[[2.14,14.66]],"id":40250501},{"atb":[[1.68,0],[1.87,9.72]],"id":6780934}],"con":true,"img":false}]}
{"op":"mcm","clk":"5348356757","pt":1646216818553,"mc":[{"id":"1.195453675","rc":[{"atb":[[1.76,0]],"id":6780934}],"con":true,"img":false}]}
{"op":"mcm","clk":"5348356763","pt":1646216818650,"mc":[{"id":"1.195453675","rc":[{"atb":[[1.86,2]],"id":6780934}],"con":true,"img":false}]}
{"op":"mcm","clk":"5348356788","pt":1646216818916,"mc":[{"id":"1.195453675","rc":[{"atb":[[1.87,29.18]],"id":6780934}],"con":true,"img":false}]}
{"op":"mcm","clk":"5348356815","pt":1646216819236,"mc":[{"id":"1.195453675","rc":[{"atb":[[1.88,9.66]],"id":6780934}],"con":true,"img":false}]}
{"op":"mcm","clk":"5348356839","pt":1646216819469,"mc":[{"id":"1.195453675","rc":[{"atb":[[1.82,0]],"id":6780934}],"con":true,"img":false}]}
{"op":"mcm","clk":"5348356848","pt":1646216819551,"mc":[{"id":"1.195453675","rc":[{"atb":[[1.87,43.26]],"id":6780934}],"con":true,"img":false}]}
{"op":"mcm","clk":"5348356863","pt":1646216819655,"mc":[{"id":"1.195453675","rc":[{"atb":[[2.04,0]],"id":40250501},{"atb":[[1.88,29.12]],"id":6780934}],"con":true,"img":false}]}
{"op":"mcm","clk":"5348356884","pt":1646216819817,"mc":[{"id":"1.195453675","rc":[{"atb":[[2.06,8.68]],"id":40250501},{"atl":[[2.14,6]],"id":40250501},{"atb":[[1.88,19.46]],"id":6780934}],"con":true,"img":false}]}
{"op":"mcm","clk":"5348356898","pt":1646216819919,"mc":[{"id":"1.195453675","rc":[{"atb":[[2.04,8.67]],"id":40250501}],"con":true,"img":false}]}
{"op":"mcm","clk":"5348356906","pt":1646216820022,"mc":[{"id":"1.195453675","rc":[{"atb":[[2.02,8.79]],"id":40250501}],"con":true,"img":false}]}
{"op":"mcm","clk":"5348356915","pt":1646216820125,"mc":[{"id":"1.195453675","rc":[{"atb":[[1.88,0]],"id":6780934}],"con":true,"img":false}]}
{"op":"mcm","clk":"5348356925","pt":1646216820229,"mc":[{"id":"1.195453675","rc":[{"atb":[[1.87,62.72]],"id":6780934}],"con":true,"img":false}]}
{"op":"mcm","clk":"5348356937","pt":1646216820344,"mc":[{"id":"1.195453675","rc":[{"atl":[[2.14,14.7]],"id":40250501}],"con":true,"img":false}]}
{"op":"mcm","clk":"5348356944","pt":1646216820446,"mc":[{"id":"1.195453675","rc":[{"atb":[[2.04,0]],"id":40250501},{"atb":[[1.88,9.66]],"id":6780934}],"con":true,"img":false}]}
{"op":"mcm","clk":"5348356950","pt":1646216820546,"mc":[{"id":"1.195453675","rc":[{"atb":[[2.02,37.39]],"id":40250501},{"atb":[[1.86,35.92],[1.87,29.18]],"id":6780934}],"con":true,"img":false}]}
{"op":"mcm","clk":"5348356982","pt":1646216820812,"mc":[{"id":"1.195453675","rc":[{"atb":[[1.87,9.72]],"id":6780934}],"con":true,"img":false}]}
{"op":"mcm","clk":"5348356996","pt":1646216820918,"mc":[{"id":"1.195453675","rc":[{"atb":[[1.88,29.12]],"id":6780934}],"con":true,"img":false}]}
{"op":"mcm","clk":"5348357011","pt":1646216821028,"mc":[{"id":"1.195453675","rc":[{"atb":[[1.77,0]],"id":6780934}],"con":true,"img":false}]}
{"op":"mcm","clk":"5348357021","pt":1646216821129,"mc":[{"id":"1.195453675","rc":[{"atb":[[1.86,33.92],[1.87,11.72]],"id":6780934}],"con":true,"img":false}]}
{"op":"mcm","clk":"5348357033","pt":1646216821237,"mc":[{"id":"1.195453675","rc":[{"atb":[[2.06,0],[1.55,9.8],[1.75,9.19],[1.65,83.3]],"id":40250501},{"trd":[[2.04,20.78],[2.06,72.4]],"ltp":2.04,"tv":93.18,"id":40250501},{"atb":[[1.64,8.43],[1.84,17.29],[1.74,7.29]],"id":6780934},{"atl":[[1.95,6.47]],"id":6780934},{"trd":[[1.95,3.01]],"ltp":1.95,"tv":3.01,"id":6780934}],"con":true,"img":false}]}
{"op":"mcm","clk":"5348357055","pt":1646216821443,"mc":[{"id":"1.195453675","rc":[{"atl":[[2.12,17.51]],"id":40250501},{"atb":[[1.83,46.08],[1.89,19.21]],"id":6780934}],"con":true,"img":false}]}
{"op":"mcm","clk":"5348357068","pt":1646216821547,"mc":[{"id":"1.195453675","rc":[{"atb":[[2,37.96],[2.02,8.79]],"id":40250501},{"atb":[[1.88,62.28]],"id":6780934}],"con":true,"img":false}]}
{"op":"mcm","clk":"5348357087","pt":1646216821758,"mc":[{"id":"1.195453675","rc":[{"atl":[[2.12,8.75]],"id":40250501}],"con":true,"img":false}]}
{"op":"mcm","clk":"5348357100","pt":1646216821815,"mc":[{"id":"1.195453675","rc":[{"atl":[[2.14,10.7]],"id":40250501},{"atb":[[1.88,42.82]],"id":6780934}],"con":true,"img":false}]}
{"op":"mcm","clk":"5348357133","pt":1646216822129,"mc":[{"id":"1.195453675","rc":[{"atl":[[2.12,26.27]],"id":40250501},{"atb":[[1.89,42.48]],"id":6780934}],"con":true,"img":false}]}
{"op":"mcm","clk":"5348357175","pt":1646216822548,"mc":[{"id":"1.195453675","rc":[{"atb":[[1.8,31.94]],"id":6780934}],"con":true,"img":false}]}
{"op":"mcm","clk":"5348357281","pt":1646216823548,"mc":[{"id":"1.195453675","rc":[{"atl":[[2.1,8.75]],"id":40250501},{"atb":[[1.9,9.6]],"id":6780934}],"con":true,"img":false}]}
{"op":"mcm","clk":"5348357298","pt":1646216823749,"mc":[{"id":"1.195453675","rc":[{"atb":[[1.86,35.92],[1.87,9.72]],"id":6780934}],"con":true,"img":false}]}
{"op":"mcm","clk":"5348357319","pt":1646216823962,"mc":[{"id":"1.195453675","rc":[{"atl":[[2.12,8.75]],"id":40250501},{"atb":[[1.89,19.21]],"id":6780934}],"con":true,"img":false}]}
{"op":"mcm","clk":"5348357326","pt":1646216824018,"mc":[{"id":"1.195453675","rc":[{"atl":[[2.1,26.27]],"id":40250501},{"atb":[[1.89,52],[1.9,32.87]],"id":6780934}],"con":true,"img":false}]}
{"op":"mcm","clk":"5348357345","pt":1646216824223,"mc":[{"id":"1.195453675","rc":[{"atl":[[1.95,0]],"id":6780934},{"trd":[[1.95,15.96]],"ltp":1.95,"tv":15.96,"id":6780934}],"con":true,"img":false}]}
{"op":"mcm","clk":"5348357359","pt":1646216824331,"mc":[{"id":"1.195453675","rc":[{"atl":[[2.08,8.76]],"id":40250501},{"atb":[[1.91,9.6]],"id":6780934}],"con":true,"img":false}]}
{"op":"mcm","clk":"5348357379","pt":1646216824543,"mc":[{"id":"1.195453675","rc":[{"atb":[[2,8.78]],"id":40250501},{"trd":[[2.04,29.9]],"ltp":2.04,"tv":29.9,"id":40250501},{"atb":[[1.83,10.93]],"id":6780934},{"atl":[[1.96,0],[1.95,0]],"id":6780934},{"trd":[[1.96,9.47],[1.95,15.97]],"ltp":1.96,"tv":25.44,"id":6780934}],"con":true,"img":false}]}
{"op":"mcm","clk":"5348357408","pt":1646216824852,"mc":[{"id":"1.195453675","rc":[{"atl":[[2.1,8.75]],"id":40250501},{"atb":[[1.9,9.6]],"id":6780934}],"con":true,"img":false}]}
{"op":"mcm","clk":"5348357419","pt":1646216824957,"mc":[{"id":"1.195453675","rc":[{"atl":[[2.08,26.28]],"id":40250501},{"atb":[[1.91,32.87]],"id":6780934}],"con":true,"img":false}]}
{"op":"mcm","clk":"5348357430","pt":1646216825016,"mc":[{"id":"1.195453675","rc":[{"atb":[[1.97,30.07]],"id":40250501},{"atb":[[1.91,64.93]],"id":6780934}],"con":true,"img":false}]}
{"op":"mcm","clk":"5348357441","pt":1646216825118,"mc":[{"id":"1.195453675","rc":[{"atb":[[1.92,9.54]],"id":6780934}],"con":true,"img":false}]}
{"op":"mcm","clk":"5348357468","pt":1646216825440,"mc":[{"id":"1.195453675","rc":[{"atb":[[1.91,41.66]],"id":6780934}],"con":true,"img":false}]}
{"op":"mcm","clk":"5348357478","pt":1646216825537,"mc":[{"id":"1.195453675","rc":[{"atb":[[1.92,32.81],[1.86,2]],"id":6780934}],"con":true,"img":false}]}
{"op":"mcm","clk":"5348357522","pt":1646216826062,"mc":[{"id":"1.195453675","rc":[{"atb":[[1.84,6.42],[1.92,64.52]],"id":6780934}],"con":true,"img":false}]}
{"op":"mcm","clk":"5348357567","pt":1646216826437,"mc":[{"id":"1.195453675","rc":[{"atl":[[2.12,0],[2.1,0],[2.14,2],[2.08,17.52]],"id":40250501},{"atb":[[1.89,32.78],[1.87,0],[1.92,54.98],[1.88,33.15],[1.91,32.06],[1.9,0]],"id":6780934}],"con":true,"img":false}]}
{"op":"mcm","clk":"5348357586","pt":1646216826643,"mc":[{"id":"1.195453675","rc":[{"atb":[[1.85,0]],"id":6780934}],"con":true,"img":false}]}
{"op":"mcm","clk":"5348357594","pt":1646216826746,"mc":[{"id":"1.195453675","rc":[{"atl":[[2.08,0]],"id":40250501}],"con":true,"img":false}]}
{"op":"mcm","clk":"5348357612","pt":1646216826848,"mc":[{"id":"1.195453675","rc":[{"atl":[[2.14,19.52]],"id":40250501}],"con":true,"img":false}]}
{"op":"mcm","clk":"5348357629","pt":1646216826958,"mc":[{"id":"1.195453675","rc":[{"atl":[[2.22,2],[2.14,17.52]],"id":40250501}],"con":true,"img":false}]}
{"op":"mcm","clk":"5348357636","pt":1646216827060,"mc":[{"id":"1.195453675","rc":[{"atb":[[1.92,23.27],[1.89,0],[1.88,0],[1.85,34.32],[1.91,0]],"id":6780934}],"con":true,"img":false}]}
{"op":"mcm","clk":"5348357656","pt":1646216827228,"mc":[{"id":"1.195453675","rc":[{"atl":[[2.22,10.42],[2.14,0]],"id":40250501}],"con":true,"img":false}]}
{"op":"mcm","clk":"5348357665","pt":1646216827332,"mc":[{"id":"1.195453675","rc":[{"atl":[[2.22,27.94]],"id":40250501}],"con":true,"img":false}]}
{"op":"mcm","clk":"5348357682","pt":1646216827432,"mc":[{"id":"1.195453675","rc":[{"atb":[[1.92,0]],"id":6780934}],"con":true,"img":false}]}
{"op":"mcm","clk":"5348357693","pt":1646216827535,"mc":[{"id":"1.195453675","rc":[{"atb":[[1.85,0],[1.86,25.27]],"id":6780934}],"con":true,"img":false}]}
{"op":"mcm","clk":"5348357699","pt":1646216827638,"mc":[{"id":"1.195453675","rc":[{"atb":[[1.02,3.22]],"id":40250501},{"atl":[[2.22,10.42]],"id":40250501}],"con":true,"img":false}]}
{"op":"mcm","clk":"5348357716","pt":1646216827749,"mc":[{"id":"1.195453675","rc":[{"atl":[[2.2,8.42]],"id":40250501},{"atb":[[1.85,10.01]],"id":6780934}],"con":true,"img":false}]}
{"op":"mcm","clk":"5348357730","pt":1646216827853,"mc":[{"id":"1.195453675","rc":[{"atb":[[1.02,0.5]],"id":40250501},{"atb":[[1.86,2]],"id":6780934}],"con":true,"img":false}]}
{"op":"mcm","clk":"5348357740","pt":1646216827954,"mc":[{"id":"1.195453675","rc":[{"atb":[[1.85,33.28]],"id":6780934}],"con":true,"img":false}]}
{"op":"mcm","clk":"5348357754","pt":1646216828063,"mc":[{"id":"1.195453675","rc":[{"atb":[[1.02,0]],"id":40250501},{"atb":[[1.84,41.16]],"id":6780934}],"con":true,"img":false}]}
{"op":"mcm","clk":"5348357767","pt":1646216828163,"mc":[{"id":"1.195453675","rc":[{"atb":[[2.1,0.5]],"id":40250501},{"atl":[[2.22,29.38]],"id":40250501}],"con":true,"img":false}]}
{"op":"mcm","clk":"5348357794","pt":1646216828372,"mc":[{"id":"1.195453675","rc":[{"atl":[[2.22,20.96],[2.24,0],[2.2,0]],"id":40250501},{"atb":[[1.85,0]],"id":6780934}],"con":true,"img":false}]}
{"op":"mcm","clk":"5348357806","pt":1646216828442,"mc":[{"id":"1.195453675","rc":[{"atl":[[2.22,2]],"id":40250501},{"atb":[[1.83,21.86],[1.86,25.27]],"id":6780934}],"con":true,"img":false}]}
{"op":"mcm","clk":"5348357815","pt":1646216828592,"mc":[{"id":"1.195453675","rc":[{"atl":[[2.2,18.96]],"id":40250501},{"atb":[[1.84,6.42],[1.85,2],[1.86,23.27]],"id":6780934}],"con":true,"img":false}]}
{"op":"mcm","clk":"5348357831","pt":1646216828647,"mc":[{"id":"1.195453675","rc":[{"atl":[[2.22,10.18]],"id":40250501},{"atb":[[1.81,10.31]],"id":6780934}],"con":true,"img":false}]}
{"op":"mcm","clk":"5348357851","pt":1646216828847,"mc":[{"id":"1.195453675","rc":[{"atb":[[1.86,4]],"id":6780934}],"con":true,"img":false}]}
{"op":"mcm","clk":"5348357860","pt":1646216828952,"mc":[{"id":"1.195453675","rc":[{"atl":[[2.2,0]],"id":40250501},{"atl":[[2.04,5.37]],"id":6780934}],"con":true,"img":false}]}
{"op":"mcm","clk":"5348357871","pt":1646216829074,"mc":[{"id":"1.195453675","rc":[{"atl":[[2.22,20.96]],"id":40250501},{"atb":[[1.84,41.16]],"id":6780934}],"con":true,"img":false}]}
{"op":"mcm","clk":"5348357894","pt":1646216829270,"mc":[{"id":"1.195453675","rc":[{"atb":[[1.81,0]],"id":6780934}],"con":true,"img":false}]}
{"op":"mcm","clk":"5348357898","pt":1646216829329,"mc":[{"id":"1.195453675","rc":[{"atb":[[1.86,0]],"id":6780934}],"con":true,"img":false}]}
{"op":"mcm","clk":"5348357902","pt":1646216829423,"mc":[{"id":"1.195453675","rc":[{"atl":[[2.22,6]],"id":40250501},{"atb":[[1.82,10.34]],"id":6780934}],"con":true,"img":false}]}
{"op":"mcm","clk":"5348357911","pt":1646216829528,"mc":[{"id":"1.195453675","rc":[{"atb":[[1.84,6.42],[1.9,5.99]],"id":6780934}],"con":true,"img":false}]}
{"op":"mcm","clk":"5348357920","pt":1646216829641,"mc":[{"id":"1.195453675","rc":[{"atl":[[2.22,14.19]],"id":40250501}],"con":true,"img":false}]}
{"op":"mcm","clk":"5348357931","pt":1646216829756,"mc":[{"id":"1.195453675","rc":[{"atb":[[1.85,6]],"id":6780934}],"con":true,"img":false}]}
{"op":"mcm","clk":"5348357961","pt":1646216830064,"mc":[{"id":"1.195453675","rc":[{"atb":[[1.84,41.16]],"id":6780934}],"con":true,"img":false}]}
{"op":"mcm","clk":"5348358022","pt":1646216830729,"mc":[{"id":"1.195453675","rc":[{"atl":[[2.22,6]],"id":40250501},{"atb":[[1.82,0]],"id":6780934}],"con":true,"img":false}]}
{"op":"mcm","clk":"5348358124","pt":1646216831774,"mc":[{"id":"1.195453675","rc":[{"atl":[[2.22,14.15]],"id":40250501}],"con":true,"img":false}]}
{"op":"mcm","clk":"5348358314","pt":1646216833570,"mc":[{"id":"1.195453675","rc":[{"atl":[[2.22,6]],"id":40250501}],"con":true,"img":false}]}
{"op":"mcm","clk":"5348358323","pt":1646216833670,"mc":[{"id":"1.195453675","rc":[{"atb":[[1.03,2.87]],"id":6780934}],"con":true,"img":false}]}
{"op":"mcm","clk":"5348358335","pt":1646216833779,"mc":[{"id":"1.195453675","rc":[{"atl":[[2.22,14.14]],"id":40250501},{"atb":[[1.85,4],[1.86,2]],"id":6780934}],"con":true,"img":false}]}
{"op":"mcm","clk":"5348358345","pt":1646216833835,"mc":[{"id":"1.195453675","rc":[{"atb":[[1.03,0.14]],"id":6780934}],"con":true,"img":false}]}
{"op":"mcm","clk":"5348358363","pt":1646216834093,"mc":[{"id":"1.195453675","rc":[{"atb":[[1.03,0]],"id":6780934}],"con":true,"img":false}]}
{"op":"mcm","clk":"5348358373","pt":1646216834151,"mc":[{"id":"1.195453675","rc":[{"atb":[[2.1,0.36]],"id":40250501},{"trd":[[2.1,21.95]],"ltp":2.1,"tv":21.95,"id":40250501},{"trd":[[1.91,0.14]],"ltp":1.91,"tv":0.14,"id":6780934}],"con":true,"img":false}]}
{"op":"mcm","clk":"5348358385","pt":1646216834261,"mc":[{"id":"1.195453675","rc":[{"atb":[[2.1,0]],"id":40250501},{"trd":[[2.1,22.69]],"ltp":2.1,"tv":22.69,"id":40250501}],"con":true,"img":false}]}
{"op":"mcm","clk":"5348358533","pt":1646216835935,"mc":[{"id":"1.195453675","rc":[{"atb":[[1.9,0]],"id":6780934}],"con":true,"img":false}]}
{"op":"mcm","clk":"5348358543","pt":1646216836043,"mc":[{"id":"1.195453675","rc":[{"atb":[[1.85,9.99]],"id":6780934}],"con":true,"img":false}]}
{"op":"mcm","clk":"5348358569","pt":1646216836359,"mc":[{"id":"1.195453675","rc":[{"atb":[[1.85,5.99]],"id":6780934}],"con":true,"img":false}]}
{"op":"mcm","clk":"5348358578","pt":1646216836462,"mc":[{"id":"1.195453675","rc":[{"atb":[[1.86,6]],"id":6780934}],"con":true,"img":false}]}
{"op":"mcm","clk":"5348358583","pt":1646216836566,"mc":[{"id":"1.195453675","rc":[{"atb":[[1.81,10.38]],"id":6780934}],"con":true,"img":false}]}
{"op":"mcm","clk":"5348358606","pt":1646216836772,"mc":[{"id":"1.195453675","rc":[{"atl":[[2.22,6]],"id":40250501}],"con":true,"img":false}]}
{"op":"mcm","clk":"5348358818","pt":1646216838981,"mc":[{"id":"1.195453675","rc":[{"atb":[[1.85,7.99],[1.86,4]],"id":6780934}],"con":true,"img":false}]}
{"op":"mcm","clk":"5348358836","pt":1646216839156,"mc":[{"id":"1.195453675","rc":[{"atl":[[2.22,14.14]],"id":40250501}],"con":true,"img":false}]}
{"op":"mcm","clk":"5348358852","pt":1646216839352,"mc":[{"id":"1.195453675","rc":[{"atb":[[1.86,0]],"id":6780934}],"con":true,"img":false}]}
{"op":"mcm","clk":"5348358872","pt":1646216839671,"mc":[{"id":"1.195453675","rc":[{"atb":[[1.85,23.97]],"id":6780934}],"con":true,"img":false}]}
{"op":"mcm","clk":"5348359065","pt":1646216841890,"mc":[{"id":"1.195453675","rc":[{"atb":[[1.55,0],[1.75,2],[1.65,75]],"id":40250501},{"atb":[[1.64,0],[1.84,34.73],[1.74,0]],"id":6780934}],"con":true,"img":false}]}
{"op":"mcm","clk":"5348359091","pt":1646216842194,"mc":[{"id":"1.195453675","rc":[{"atl":[[2.2,17.12]],"id":40250501},{"atb":[[1.86,9.82]],"id":6780934}],"con":true,"img":false}]}
{"op":"mcm","clk":"5348359115","pt":1646216842368,"mc":[{"id":"1.195453675","rc":[{"atl":[[2.22,12.14],[2.18,2]],"id":40250501}],"con":true,"img":false}]}
{"op":"mcm","clk":"5348359143","pt":1646216842669,"mc":[{"id":"1.195453675","rc":[{"atl":[[2.22,8.14]],"id":40250501},{"atb":[[1.85,7.99]],"id":6780934}],"con":true,"img":false}]}
{"op":"mcm","clk":"5348359179","pt":1646216842983,"mc":[{"id":"1.195453675","rc":[{"atl":[[2.18,10.53]],"id":40250501}],"con":true,"img":false}]}
{"op":"mcm","clk":"5348359189","pt":1646216843087,"mc":[{"id":"1.195453675","rc":[{"atl":[[2.18,14.53]],"id":40250501},{"atb":[[1.86,29.48]],"id":6780934}],"con":true,"img":false}]}
{"op":"mcm","clk":"5348359219","pt":1646216843350,"mc":[{"id":"1.195453675","rc":[{"atl":[[2.18,6]],"id":40250501}],"con":true,"img":false}]}
{"op":"mcm","clk":"5348359240","pt":1646216843557,"mc":[{"id":"1.195453675","rc":[{"atb":[[1.86,63.41]],"id":6780934}],"con":true,"img":false}]}
{"op":"mcm","clk":"5348359319","pt":1646216844554,"mc":[{"id":"1.195453675","rc":[{"atb":[[2.02,15.37]],"id":40250501},{"atb":[[1.84,36.73],[1.85,5.99],[1.87,9.92]],"id":6780934}],"con":true,"img":false}]}
{"op":"mcm","clk":"5348359338","pt":1646216844761,"mc":[{"id":"1.195453675","rc":[{"atl":[[2.18,14.48],[2.16,8.48]],"id":40250501}],"con":true,"img":false}]}
{"op":"mcm","clk":"5348359357","pt":1646216844974,"mc":[{"id":"1.195453675","rc":[{"atb":[[1.86,43.75]],"id":6780934}],"con":true,"img":false}]}
{"op":"mcm","clk":"5348359368","pt":1646216845074,"mc":[{"id":"1.195453675","rc":[{"atb":[[1.99,29.46]],"id":40250501},{"atl":[[2.18,10.48]],"id":40250501}],"con":true,"img":false}]}
{"op":"mcm","clk":"5348359376","pt":1646216845184,"mc":[{"id":"1.195453675","rc":[{"atl":[[2.18,2]],"id":40250501}],"con":true,"img":false}]}
{"op":"mcm","clk":"5348359421","pt":1646216845556,"mc":[{"id":"1.195453675","rc":[{"atl":[[2.16,25.46]],"id":40250501},{"atb":[[1.87,29.78]],"id":6780934}],"con":true,"img":false}]}
{"op":"mcm","clk":"5348359439","pt":1646216845761,"mc":[{"id":"1.195453675","rc":[{"atl":[[2.14,8.48]],"id":40250501}],"con":true,"img":false}]}
{"op":"mcm","clk":"5348359447","pt":1646216845871,"mc":[{"id":"1.195453675","rc":[{"atb":[[1.88,9.9]],"id":6780934}],"con":true,"img":false}]}
{"op":"mcm","clk":"5348359464","pt":1646216846084,"mc":[{"id":"1.195453675","rc":[{"atb":[[1.88,43.05]],"id":6780934}],"con":true,"img":false}]}
{"op":"mcm","clk":"5348359494","pt":1646216846303,"mc":[{"id":"1.195453675","rc":[{"atl":[[2.16,8.48]],"id":40250501},{"atb":[[1.87,9.92]],"id":6780934}],"con":true,"img":false}]}
{"op":"mcm","clk":"5348359501","pt":1646216846346,"mc":[{"id":"1.195453675","rc":[{"atl":[[2.14,25.46]],"id":40250501},{"atb":[[1.88,62.91]],"id":6780934}],"con":true,"img":false}]}
{"op":"mcm","clk":"5348359595","pt":1646216847561,"mc":[{"id":"1.195453675","rc":[{"atl":[[2.18,0],[2.16,10.48]],"id":40250501}],"con":true,"img":false}]}
{"op":"mcm","clk":"5348359674","pt":1646216848554,"mc":[{"id":"1.195453675","rc":[{"atl":[[2.12,8.71]],"id":40250501},{"atb":[[1.89,9.64]],"id":6780934}],"con":true,"img":false}]}
{"op":"mcm","clk":"5348359679","pt":1646216848663,"mc":[{"id":"1.195453675","rc":[{"atl":[[2.22,0]],"id":40250501},{"atb":[[1.81,0]],"id":6780934}],"con":true,"img":false}]}
{"op":"mcm","clk":"5348359702","pt":1646216848976,"mc":[{"id":"1.195453675","rc":[{"atl":[[2.14,8.48]],"id":40250501},{"atb":[[1.88,43.05]],"id":6780934}],"con":true,"img":false}]}
{"op":"mcm","clk":"5348359712","pt":1646216849081,"mc":[{"id":"1.195453675","rc":[{"atb":[[1.89,29.5]],"id":6780934}],"con":true,"img":false}]}
{"op":"mcm","clk":"5348359741","pt":1646216849398,"mc":[{"id":"1.195453675","rc":[{"atl":[[2.12,26.15]],"id":40250501}],"con":true,"img":false}]}
{"op":"mcm","clk":"5348359817","pt":1646216850083,"mc":[{"id":"1.195453675","rc":[{"atb":[[1.9,32.41]],"id":6780934}],"con":true,"img":false}]}
{"op":"mcm","clk":"5348359847","pt":1646216850503,"mc":[{"id":"1.195453675","rc":[{"atb":[[1.89,9.64]],"id":6780934}],"con":true,"img":false}]}
{"op":"mcm","clk":"5348359859","pt":1646216850566,"mc":[{"id":"1.195453675","rc":[{"atb":[[1.9,52.27]],"id":6780934}],"con":true,"img":false}]}
{"op":"mcm","clk":"5348359868","pt":1646216850668,"mc":[{"id":"1.195453675","rc":[{"atl":[[2.12,17.44],[2.14,0],[2.2,0],[2.16,2]],"id":40250501},{"atb":[[1.89,0],[1.88,33.15],[1.86,33.92],[1.87,0]],"id":6780934}],"con":true,"img":false}]}
{"op":"mcm","clk":"5348359916","pt":1646216851092,"mc":[{"id":"1.195453675","rc":[{"atb":[[1.7,57.7],[1.8,6.74],[1.9,5.99]],"id":40250501},{"atb":[[1.64,8.43],[1.44,12.26],[1.54,9.98]],"id":6780934}],"con":true,"img":false}]}
{"op":"mcm","clk":"5348359926","pt":1646216851195,"mc":[{"id":"1.195453675","rc":[{"atl":[[2.12,0]],"id":40250501}],"con":true,"img":false}]}
{"op":"mcm","clk":"5348359934","pt":1646216851295,"mc":[{"id":"1.195453675","rc":[{"atl":[[2.16,19.44]],"id":40250501}],"con":true,"img":false}]}
{"op":"mcm","clk":"5348359965","pt":1646216851562,"mc":[{"id":"1.195453675","rc":[{"atb":[[1.88,0],[1.9,19.86]],"id":6780934}],"con":true,"img":false}]}
{"op":"mcm","clk":"5348359972","pt":1646216851669,"mc":[{"id":"1.195453675","rc":[{"atl":[[2.16,6]],"id":40250501}],"con":true,"img":false}]}
{"op":"mcm","clk":"5348359992","pt":1646216851872,"mc":[{"id":"1.195453675","rc":[{"atb":[[1.9,0]],"id":6780934}],"con":true,"img":false}]}
{"op":"mcm","clk":"5348360006","pt":1646216851985,"mc":[{"id":"1.195453675","rc":[{"atb":[[1.85,16.12]],"id":6780934}],"con":true,"img":false}]}
{"op":"mcm","clk":"5348360013","pt":1646216852081,"mc":[{"id":"1.195453675","rc":[{"atb":[[1.86,0]],"id":6780934}],"con":true,"img":false}]}
{"op":"mcm","clk":"5348360031","pt":1646216852294,"mc":[{"id":"1.195453675","rc":[{"atb":[[1.86,20.02]],"id":6780934}],"con":true,"img":false}]}
{"op":"mcm","clk":"5348360067","pt":1646216852659,"mc":[{"id":"1.195453675","rc":[{"atb":[[1.86,0]],"id":6780934}],"con":true,"img":false}]}
{"op":"mcm","clk":"5348360090","pt":1646216853073,"mc":[{"id":"1.195453675","rc":[{"atb":[[1.04,1.45]],"id":40250501}],"con":true,"img":false}]}
{"op":"mcm","clk":"5348360101","pt":1646216853186,"mc":[{"id":"1.195453675","rc":[{"atb":[[1.04,0.72]],"id":40250501}],"con":true,"img":false}]}
{"op":"mcm","clk":"5348360109","pt":1646216853285,"mc":[{"id":"1.195453675","rc":[{"atb":[[1.85,37.04]],"id":6780934}],"con":true,"img":false}]}
{"op":"mcm","clk":"5348360117","pt":1646216853389,"mc":[{"id":"1.195453675","rc":[{"atb":[[1.04,0]],"id":40250501}],"con":true,"img":false}]}
{"op":"mcm","clk":"5348360124","pt":1646216853493,"mc":[{"id":"1.195453675","rc":[{"atl":[[2.16,5.28]],"id":40250501},{"trd":[[2.16,10.73]],"ltp":2.16,"tv":10.73,"id":40250501}],"con":true,"img":false}]}
{"op":"mcm","clk":"5348360131","pt":1646216853600,"mc":[{"id":"1.195453675","rc":[{"atb":[[1.86,33.92]],"id":6780934}],"con":true,"img":false}]}
{"op":"mcm","clk":"5348360148","pt":1646216853762,"mc":[{"id":"1.195453675","rc":[{"atl":[[2.16,13.67]],"id":40250501}],"con":true,"img":false}]}
{"op":"mcm","clk":"5348360180","pt":1646216854084,"mc":[{"id":"1.195453675","rc":[{"atb":[[1.85,16.12]],"id":6780934}],"con":true,"img":false}]}
{"op":"mcm","clk":"5348360230","pt":1646216854548,"mc":[{"id":"1.195453675","rc":[{"atb":[[1.86,0]],"id":6780934}],"con":true,"img":false}]}
{"op":"mcm","clk":"5348360266","pt":1646216854981,"mc":[{"id":"1.195453675","rc":[{"atb":[[1.85,48.38]],"id":6780934}],"con":true,"img":false}]}
{"op":"mcm","clk":"5348360335","pt":1646216855602,"mc":[{"id":"1.195453675","rc":[{"atb":[[1.86,33.92]],"id":6780934}],"con":true,"img":false}]}
{"op":"mcm","clk":"5348360366","pt":1646216855878,"mc":[{"id":"1.195453675","rc":[{"atb":[[2.02,11.56]],"id":40250501},{"trd":[[2.02,7.62]],"ltp":2.02,"tv":7.62,"id":40250501}],"con":true,"img":false}]}
{"op":"mcm","clk":"5348360375","pt":1646216855980,"mc":[{"id":"1.195453675","rc":[{"atb":[[1.85,16.12]],"id":6780934}],"con":true,"img":false}]}
{"op":"mcm","clk":"5348360406","pt":1646216856399,"mc":[{"id":"1.195453675","rc":[{"atb":[[1.86,66.92]],"id":6780934}],"con":true,"img":false}]}
{"op":"mcm","clk":"5348360427","pt":1646216856560,"mc":[{"id":"1.195453675","rc":[{"atb":[[1.99,0]],"id":40250501},{"atb":[[1.86,33]],"id":6780934}],"con":true,"img":false}]}
{"op":"mcm","clk":"5348360460","pt":1646216856977,"mc":[{"id":"1.195453675","rc":[{"atb":[[1.86,0]],"id":6780934}],"con":true,"img":false}]}
{"op":"mcm","clk":"5348360493","pt":1646216857398,"mc":[{"id":"1.195453675","rc":[{"atb":[[1.85,29.82]],"id":6780934}],"con":true,"img":false}]}
{"op":"mcm","clk":"5348360583","pt":1646216858501,"mc":[{"id":"1.195453675","rc":[{"atl":[[2.2,2],[2.16,12.39]],"id":40250501},{"atb":[[1.82,2],[1.84,34.73]],"id":6780934}],"con":true,"img":false}]}
{"op":"mcm","clk":"5348360632","pt":1646216859079,"mc":[{"id":"1.195453675","rc":[{"atb":[[1.86,33.92]],"id":6780934}],"con":true,"img":false}]}
{"op":"mcm","clk":"5348360677","pt":1646216859659,"mc":[{"id":"1.195453675","rc":[{"atb":[[1.85,16.12]],"id":6780934}],"con":true,"img":false}]}
{"op":"mcm","clk":"5348360687","pt":1646216859764,"mc":[{"id":"1.195453675","rc":[{"atb":[[1.86,47.62]],"id":6780934}],"con":true,"img":false}]}
{"op":"mcm","clk":"5348360716","pt":1646216860184,"mc":[{"id":"1.195453675","rc":[{"atl":[[2.18,2],[2.2,0]],"id":40250501},{"atb":[[1.83,23.86],[1.82,0]],"id":6780934}],"con":true,"img":false}]}
{"op":"mcm","clk":"5348361246","pt":1646216865702,"mc":[{"id":"1.195453675","rc":[{"atl":[[2.16,4]],"id":40250501}],"con":true,"img":false}]}
{"op":"mcm","clk":"5348361282","pt":1646216866075,"mc":[{"id":"1.195453675","rc":[{"atl":[[2.16,0]],"id":40250501}],"con":true,"img":false}]}
{"op":"mcm","clk":"5348361295","pt":1646216866185,"mc":[{"id":"1.195453675","rc":[{"atl":[[2.28,2]],"id":40250501}],"con":true,"img":false}]}
{"op":"mcm","clk":"5348361308","pt":1646216866286,"mc":[{"id":"1.195453675","rc":[{"atl":[[2.18,0]],"id":40250501}],"con":true,"img":false}]}
{"op":"mcm","clk":"5348361313","pt":1646216866387,"mc":[{"id":"1.195453675","rc":[{"atl":[[2.18,4]],"id":40250501}],"con":true,"img":false}]}
{"op":"mcm","clk":"5348361325","pt":1646216866598,"mc":[{"id":"1.195453675","rc":[{"atl":[[2.18,12.34]],"id":40250501},{"atb":[[1.86,13.7]],"id":6780934}],"con":true,"img":false}]}
{"op":"mcm","clk":"5348361333","pt":1646216866707,"mc":[{"id":"1.195453675","rc":[{"atl":[[2.18,8.34]],"id":40250501}],"con":true,"img":false}]}
{"op":"mcm","clk":"5348361365","pt":1646216867117,"mc":[{"id":"1.195453675","rc":[{"atl":[[2.18,21.92]],"id":40250501},{"atb":[[1.86,0]],"id":6780934}],"con":true,"img":false}]}
{"op":"mcm","clk":"5348361391","pt":1646216867484,"mc":[{"id":"1.195453675","rc":[{"atb":[[1.85,31.97]],"id":6780934}],"con":true,"img":false}]}
{"op":"mcm","clk":"5348361401","pt":1646216867590,"mc":[{"id":"1.195453675","rc":[{"atb":[[1.85,21.84]],"id":6780934}],"con":true,"img":false}]}
{"op":"mcm","clk":"5348361426","pt":1646216867805,"mc":[{"id":"1.195453675","rc":[{"atb":[[1.81,10.1]],"id":6780934}],"con":true,"img":false}]}
{"op":"mcm","clk":"5348361765","pt":1646216871364,"mc":[{"id":"1.195453675","rc":[{"atl":[[2.28,0],[2.18,23.92]],"id":40250501}],"con":true,"img":false}]}
{"op":"mcm","clk":"5348361810","pt":1646216871889,"mc":[{"id":"1.195453675","rc":[{"atl":[[2.18,15.58]],"id":40250501}],"con":true,"img":false}]}
{"op":"mcm","clk":"5348361849","pt":1646216872305,"mc":[{"id":"1.195453675","rc":[{"atl":[[2.18,6]],"id":40250501}],"con":true,"img":false}]}
{"op":"mcm","clk":"5348361889","pt":1646216872825,"mc":[{"id":"1.195453675","rc":[{"atb":[[1.7,50],[1.8,0],[1.9,0]],"id":40250501},{"atb":[[1.64,0],[1.44,0],[1.54,0]],"id":6780934}],"con":true,"img":false}]}
{"op":"mcm","clk":"5348361906","pt":1646216872986,"mc":[{"id":"1.195453675","rc":[{"atb":[[1.81,0]],"id":6780934}],"con":true,"img":false}]}
{"op":"mcm","clk":"5348361952","pt":1646216873621,"mc":[{"id":"1.195453675","rc":[{"atb":[[1.81,10.26]],"id":6780934}],"con":true,"img":false}]}
{"op":"mcm","clk":"5348362123","pt":1646216875509,"mc":[{"id":"1.195453675","marketDefinition":{"bspMarket":false,"turnInPlayEnabled":false,"persistenceEnabled":false,"marketBaseRate":7.0,"eventId":"31272494","eventTypeId":"4339","numberOfWinners":1,"bettingType":"ODDS","marketType":"MATCH_BET","marketTime":"2022-03-02T10:27:00.000Z","suspendTime":"2022-03-02T10:27:00.000Z","bspReconciled":false,"complete":true,"inPlay":false,"crossMatching":true,"runnersVoidable":false,"numberOfActiveRunners":2,"betDelay":0,"status":"SUSPENDED","runners":[{"status":"ACTIVE","sortPriority":1,"id":40250501,"name":"1. Dwarshuis"},{"status":"ACTIVE","sortPriority":2,"id":6780934,"name":"2. Peacock"}],"regulators":["MR_INT"],"venue":"Traralgon","countryCode":"AU","discountAllowed":true,"timezone":"Australia/Sydney","openDate":"2022-03-02T08:31:00.000Z","version":4382946624,"name":"Dwarshuis v Peacock","eventName":"Traralgon (AUS) 2nd Mar"},"rc":[],"con":true,"img":false}]}
{"op":"mcm","clk":"5348362123","pt":1646216875509,"mc":[{"id":"1.195453675","rc":[{"atb":[[2,0],[1.73,0],[1.98,0],[1.7,0],[1.68,0],[1.96,0],[1.71,0],[1.76,0],[1.79,0],[2.02,0],[1.81,0],[1.97,0],[1.74,0],[1.67,0],[1.77,0],[1.75,0],[1.65,0]],"id":40250501},{"atl":[[2.54,0],[2.3,0],[2.32,0],[2.5,0],[2.44,0],[2.6,0],[2.48,0],[2.36,0],[2.4,0],[2.56,0],[2.42,0],[2.38,0],[2.18,0]],"id":40250501},{"atb":[[1.83,0],[1.8,0],[1.81,0],[1.84,0],[1.85,0]],"id":6780934},{"atl":[[2.56,0],[2.54,0],[2.06,0],[2.22,0],[2.04,0],[2.12,0],[2.6,0],[2.64,0],[2.66,0],[2.58,0],[2.62,0],[2.1,0]],"id":6780934}],"con":true,"img":false}]}
{"op":"mcm","clk":"5348367077","pt":1646216931405,"mc":[{"id":"1.195453675","rc":[{"trd":[[2.24,0],[2.02,0],[2.06,0],[2.04,0],[2.12,0],[2.18,0],[2.2,0],[2.26,0],[2.1,0],[2.16,0],[2.08,0]],"ltp":2.24,"tv":0.0,"id":40250501},{"trd":[[1.8,0],[1.82,0],[1.83,0],[1.79,0],[1.81,0],[1.89,0],[1.84,0],[1.85,0],[1.88,0],[1.91,0],[1.96,0],[1.95,0]],"ltp":1.8,"tv":0.0,"id":6780934}],"con":true,"img":false}]}
{"op":"mcm","clk":"5348367152","pt":1646216932117,"mc":[{"id":"1.195453675","marketDefinition":{"bspMarket":false,"turnInPlayEnabled":false,"persistenceEnabled":false,"marketBaseRate":7.0,"eventId":"31272494","eventTypeId":"4339","numberOfWinners":1,"bettingType":"ODDS","marketType":"MATCH_BET","marketTime":"2022-03-02T10:27:00.000Z","suspendTime":"2022-03-02T10:27:00.000Z","bspReconciled":false,"complete":true,"inPlay":false,"crossMatching":false,"runnersVoidable":false,"numberOfActiveRunners":0,"betDelay":0,"status":"CLOSED","settledTime":"2022-03-02T10:28:50.000Z","runners":[{"status":"WINNER","sortPriority":1,"id":40250501,"name":"1. Dwarshuis"},{"status":"LOSER","sortPriority":2,"id":6780934,"name":"2. Peacock"}],"regulators":["MR_INT"],"venue":"Traralgon","countryCode":"AU","discountAllowed":true,"timezone":"Australia/Sydney","openDate":"2022-03-02T08:31:00.000Z","version":4382947677,"name":"Dwarshuis v Peacock","eventName":"Traralgon (AUS) 2nd Mar"},"rc":[],"con":true,"img":false}]}
