{"op":"mcm","clk":"5351767844","pt":1646175389002,"mc":[{"id":"1.195453765","marketDefinition":{"bspMarket":true,"turnInPlayEnabled":false,"persistenceEnabled":false,"marketBaseRate":7.0,"eventId":"31272499","eventTypeId":"4339","numberOfWinners":2,"bettingType":"ODDS","marketType":"PLACE","marketTime":"2022-03-02T08:54:00.000Z","suspendTime":"2022-03-02T08:54:00.000Z","bspReconciled":false,"complete":true,"inPlay":false,"crossMatching":false,"runnersVoidable":false,"numberOfActiveRunners":7,"betDelay":0,"status":"OPEN","runners":[{"status":"ACTIVE","sortPriority":1,"id":41207262,"name":"1. Kooky Loopy"},{"status":"ACTIVE","sortPriority":2,"id":43167130,"name":"2. Suited It"},{"status":"ACTIVE","sortPriority":3,"id":43167131,"name":"3. Pucovski"},{"status":"ACTIVE","sortPriority":4,"id":36386524,"name":"4. Scandalise"},{"status":"ACTIVE","sortPriority":5,"id":40209251,"name":"5. Cyclone Jenny"},{"status":"ACTIVE","sortPriority":6,"id":42401236,"name":"7. Nomad Road"},{"status":"ACTIVE","sortPriority":7,"id":36010178,"name":"9. So You Sing"}],"regulators":["MR_INT"],"venue":"Rockhampton","countryCode":"AU","discountAllowed":true,"timezone":"Australia/Queensland","openDate":"2022-03-02T08:34:00.000Z","version":4382437832,"name":"To Be Placed","eventName":"Rockhampton (AUS) 2nd Mar"},"rc":[],"con":true,"img":false}]}
{"op":"mcm","clk":"5351829775","pt":1646176640937,"mc":[{"id":"1.195453765","rc":[{"atb":[[2.06,114],[2.26,47.95],[2.16,104.18]],"id":41207262},{"atl":[[5.6,2.62],[7.2,1.94],[18,2.84],[9.2,2.94],[13,2.01]],"id":41207262},{"spn":3.93,"spf":"NaN","id":41207262},{"atb":[[2.06,57],[1.98,123.31],[1.93,129.94]],"id":43167130},{"atl":[[16,3.22],[6.4,2.23],[11,2.41],[5.2,2.87],[8.4,3.26]],"id":43167130},{"spn":3.63,"spf":"NaN","id":43167130},{"atb":[[1.19,318.02],[1.14,863.2],[1.09,1342.77]],"id":42401236},{"atl":[[2.88,12.85],[3.2,21.97],[2.28,9.43],[2.68,14.38],[2.48,8.16]],"id":42401236},{"spn":1.73,"spf":"NaN","id":42401236},{"atb":[[3.6,46.47],[3.85,21.2],[3.35,51.42]],"id":43167131},{"atl":[[17.5,0.73],[75,0.65],[40,0.62],[12.5,1.05],[25,1]],"id":43167131},{"spn":8.17,"spf":"NaN","id":43167131},{"atb":[[1.8,151.06],[1.85,142.17],[1.9,67.13]],"id":40209251},{"atl":[[4,4.02],[8,3.45],[5,3.02],[10,5.37],[6,4.83]],"id":40209251},{"spn":2.95,"spf":"NaN","id":40209251},{"atb":[[8.6,7.95],[7.6,18.31],[6.6,21.57]],"id":36010178},{"atl":[[280,0.08],[90,0.13],[180,0.13],[46,0.26],[380,0.12]],"id":36010178},{"spn":27.3,"spf":"NaN","id":36010178},{"atb":[[2.86,64.97],[3.15,28.1],[2.96,61.66]],"id":36386524},{"atl":[[16,1.61],[34,1.46],[11,1.2],[22,1.14],[8.4,1.63]],"id":36386524},{"spn":5.77,"spf":"NaN","id":36386524}],"con":true,"img":false}]}
{"op":"mcm","clk":"5351831296","pt":1646176677975,"mc":[{"id":"1.195453765","rc":[{"atb":[[2.06,0],[2.26,0],[2.16,0]],"id":41207262},{"atl":[[5.6,0],[7.2,0],[18,0],[9.2,0],[13,0]],"id":41207262},{"atb":[[2.06,0],[1.98,0],[1.93,0]],"id":43167130},{"atl":[[16,0],[6.4,0],[11,0],[5.2,0],[8.4,0]],"id":43167130},{"atb":[[1.19,0],[1.14,0],[1.09,0]],"id":42401236},{"atl":[[2.88,0],[3.2,0],[2.28,0],[2.68,0],[2.48,0]],"id":42401236},{"atb":[[3.6,0],[3.85,0],[3.35,0]],"id":43167131},{"atl":[[17.5,0],[75,0],[40,0],[12.5,0],[25,0]],"id":43167131},{"atb":[[1.8,0],[1.85,0],[1.9,0]],"id":40209251},{"atl":[[4,0],[8,0],[5,0],[10,0],[6,0]],"id":40209251},{"atb":[[8.6,0],[7.6,0],[6.6,0]],"id":36010178},{"atl":[[280,0],[90,0],[180,0],[46,0],[380,0]],"id":36010178},{"atb":[[2.86,0],[3.15,0],[2.96,0]],"id":36386524},{"atl":[[16,0],[34,0],[11,0],[22,0],[8.4,0]],"id":36386524}],"con":true,"img":false}]}
{"op":"mcm","clk":"5351832829","pt":1646176717820,"mc":[{"id":"1.195453765","rc":[{"atb":[[2,120.84],[2.2,50.35],[2.1,109.86]],"id":41207262},{"atl":[[17.5,2.92],[9,3.02],[5.5,2.68],[12.5,2.1],[7,2.01]],"id":41207262},{"spn":3.85,"spf":"NaN","id":41207262},{"atb":[[2,60.42],[1.9,134.27],[1.95,127.2]],"id":43167130},{"atl":[[5.1,2.94],[6.2,2.32],[10.5,2.54],[8.2,3.35],[15.5,3.33]],"id":43167130},{"spn":3.55,"spf":"NaN","id":43167130},{"atb":[[1.18,671.38],[1.23,262.71],[1.13,929.6]],"id":42401236},{"atl":[[3.45,19.72],[2.38,8.75],[2.58,7.64],[2.98,12.2],[2.78,13.57]],"id":42401236},{"spn":1.8,"spf":"NaN","id":42401236},{"atb":[[1.8,151.06],[1.85,142.17],[1.9,67.13]],"id":40209251},{"atl":[[4,4.02],[8,3.45],[5,3.02],[10,5.37],[6,4.83]],"id":40209251},{"atb":[[3.6,46.47],[3.85,21.2],[3.35,51.42]],"id":43167131},{"atl":[[17.5,0.73],[75,0.65],[40,0.62],[12.5,1.05],[25,1]],"id":43167131},{"atb":[[8.6,7.95],[7.6,18.31],[6.6,21.57]],"id":36010178},{"atl":[[280,0.08],[90,0.13],[180,0.13],[46,0.26],[380,0.12]],"id":36010178},{"atb":[[2.88,64.28],[2.98,30.51],[2.78,67.89]],"id":36386524},{"atl":[[32,1.55],[10.5,1.27],[21,1.2],[8.2,1.67],[15.5,1.66]],"id":36386524},{"spn":5.59,"spf":"NaN","id":36386524}],"con":true,"img":false}]}
{"op":"mcm","clk":"5351834994","pt":1646176767670,"mc":[{"id":"1.195453765","rc":[{"atb":[[2,0],[2.2,0],[2.1,0]],"id":41207262},{"atl":[[17.5,0],[9,0],[5.5,0],[12.5,0],[7,0]],"id":41207262},{"atb":[[2,0],[1.9,0],[1.95,0]],"id":43167130},{"atl":[[5.1,0],[6.2,0],[10.5,0],[8.2,0],[15.5,0]],"id":43167130},{"atb":[[1.18,0],[1.23,0],[1.13,0]],"id":42401236},{"atl":[[3.45,0],[2.38,0],[2.58,0],[2.98,0],[2.78,0]],"id":42401236},{"atb":[[3.6,0],[3.85,0],[3.35,0]],"id":43167131},{"atl":[[17.5,0],[75,0],[40,0],[12.5,0],[25,0]],"id":43167131},{"atb":[[1.8,0],[1.85,0],[1.9,0]],"id":40209251},{"atl":[[4,0],[8,0],[5,0],[10,0],[6,0]],"id":40209251},{"atb":[[8.6,0],[7.6,0],[6.6,0]],"id":36010178},{"atl":[[280,0],[90,0],[180,0],[46,0],[380,0]],"id":36010178},{"atb":[[2.88,0],[2.98,0],[2.78,0]],"id":36386524},{"atl":[[32,0],[10.5,0],[21,0],[8.2,0],[15.5,0]],"id":36386524}],"con":true,"img":false}]}
{"op":"mcm","clk":"5351835810","pt":1646176785738,"mc":[{"id":"1.195453765","rc":[{"atb":[[2.06,57],[1.98,123.31],[1.93,129.94]],"id":41207262},{"atl":[[16,3.22],[6.4,2.23],[11,2.41],[5.2,2.87],[8.4,3.26]],"id":41207262},{"spn":3.63,"spf":"NaN","id":41207262},{"atb":[[2,60.42],[1.9,134.27],[1.95,127.2]],"id":43167130},{"atl":[[5.1,2.94],[6.2,2.32],[10.5,2.54],[8.2,3.35],[15.5,3.33]],"id":43167130},{"atb":[[1.18,671.38],[1.23,262.71],[1.13,929.6]],"id":42401236},{"atl":[[3.45,19.72],[2.38,8.75],[2.58,7.64],[2.98,12.2],[2.78,13.57]],"id":42401236},{"atb":[[3.6,46.47],[3.85,21.2],[3.35,51.42]],"id":43167131},{"atl":[[17.5,0.73],[75,0.65],[40,0.62],[12.5,1.05],[25,1]],"id":43167131},{"atb":[[2.06,57],[1.98,123.31],[1.93,129.94]],"id":40209251},{"atl":[[16,3.22],[6.4,2.23],[11,2.41],[5.2,2.87],[8.4,3.26]],"id":40209251},{"spn":3.63,"spf":"NaN","id":40209251},{"atb":[[8.6,7.95],[7.6,18.31],[6.6,21.57]],"id":36010178},{"atl":[[280,0.08],[90,0.13],[180,0.13],[46,0.26],[380,0.12]],"id":36010178},{"atb":[[2.88,64.28],[2.98,30.51],[2.78,67.89]],"id":36386524},{"atl":[[32,1.55],[10.5,1.27],[21,1.2],[8.2,1.67],[15.5,1.66]],"id":36386524}],"con":true,"img":false}]}
{"op":"mcm","clk":"5352004159","pt":1646180202639,"mc":[{"id":"1.195453765","marketDefinition":{"bspMarket":true,"turnInPlayEnabled":false,"persistenceEnabled":false,"marketBaseRate":7.0,"eventId":"31272499","eventTypeId":"4339","numberOfWinners":2,"bettingType":"ODDS","marketType":"PLACE","marketTime":"2022-03-02T08:54:00.000Z","suspendTime":"2022-03-02T08:54:00.000Z","bspReconciled":false,"complete":true,"inPlay":false,"crossMatching":false,"runnersVoidable":false,"numberOfActiveRunners":7,"betDelay":0,"status":"OPEN","runners":[{"status":"ACTIVE","sortPriority":1,"id":41207262,"name":"1. Kooky Loopy"},{"status":"ACTIVE","sortPriority":2,"id":43167130,"name":"2. Suited It"},{"status":"ACTIVE","sortPriority":3,"id":43167131,"name":"3. Pucovski"},{"status":"ACTIVE","sortPriority":4,"id":36386524,"name":"4. Scandalise"},{"status":"ACTIVE","sortPriority":5,"id":40209251,"name":"5. Cyclone Jenny"},{"status":"ACTIVE","sortPriority":6,"id":42401236,"name":"7. Nomad Road"},{"status":"ACTIVE","sortPriority":7,"id":36010178,"name":"9. So You Sing"}],"regulators":["MR_INT"],"venue":"Rockhampton","countryCode":"AU","discountAllowed":true,"timezone":"Australia/Queensland","openDate":"2022-03-02T08:34:00.000Z","version":4382437832,"name":"To Be Placed","eventName":"Rockhampton (AUS) 2nd Mar"},"rc":[{"atb":[[2.06,57.01],[1.98,123.32],[1.93,129.95]],"id":41207262},{"atl":[[16,3.22],[6.4,2.23],[11,2.41],[5.2,2.88],[8.4,3.26]],"id":41207262},{"spn":3.63,"spf":"NaN","id":41207262},{"atb":[[2,60.43],[1.9,134.29],[1.95,127.22]],"id":43167130},{"atl":[[5.1,2.94],[6.2,2.32],[10.5,2.54],[8.2,3.35],[15.5,3.33]],"id":43167130},{"spn":3.55,"spf":"NaN","id":43167130},{"atb":[[1.18,671.45],[1.23,262.74],[1.13,929.7]],"id":42401236},{"atl":[[3.45,19.72],[2.38,8.75],[2.58,7.64],[2.98,12.2],[2.78,13.57]],"id":42401236},{"spn":1.8,"spf":"NaN","id":42401236},{"atb":[[3.6,46.48],[3.85,21.2],[3.35,51.43]],"id":43167131},{"atl":[[17.5,0.73],[75,0.65],[40,0.62],[12.5,1.05],[25,1]],"id":43167131},{"spn":8.17,"spf":"NaN","id":43167131},{"atb":[[2.06,57.01],[1.98,123.32],[1.93,129.95]],"id":40209251},{"atl":[[16,3.22],[6.4,2.23],[11,2.41],[5.2,2.88],[8.4,3.26]],"id":40209251},{"spn":3.63,"spf":"NaN","id":40209251},{"atb":[[8.6,7.95],[7.6,18.31],[6.6,21.58]],"id":36010178},{"atl":[[280,0.08],[90,0.13],[180,0.13],[46,0.26],[380,0.12]],"id":36010178},{"spn":27.3,"spf":"NaN","id":36010178},{"atb":[[2.88,64.29],[2.98,30.52],[2.78,67.9]],"id":36386524},{"atl":[[32,1.55],[10.5,1.27],[21,1.2],[8.2,1.67],[15.5,1.66]],"id":36386524},{"spn":5.59,"spf":"NaN","id":36386524}],"con":true,"img":true}]}
{"op":"mcm","clk":"5352146197","pt":1646183572653,"mc":[{"id":"1.195453765","marketDefinition":{"bspMarket":true,"turnInPlayEnabled":false,"persistenceEnabled":false,"marketBaseRate":7.0,"eventId":"31272499","eventTypeId":"4339","numberOfWinners":2,"bettingType":"ODDS","marketType":"PLACE","marketTime":"2022-03-02T08:54:00.000Z","suspendTime":"2022-03-02T08:54:00.000Z","bspReconciled":false,"complete":true,"inPlay":false,"crossMatching":false,"runnersVoidable":false,"numberOfActiveRunners":7,"betDelay":0,"status":"OPEN","runners":[{"status":"ACTIVE","sortPriority":1,"id":41207262,"name":"1. Kooky Loopy"},{"status":"ACTIVE","sortPriority":2,"id":43167130,"name":"2. Suited It"},{"status":"ACTIVE","sortPriority":3,"id":43167131,"name":"3. Pucovski"},{"status":"ACTIVE","sortPriority":4,"id":36386524,"name":"4. Scandalise"},{"status":"ACTIVE","sortPriority":5,"id":40209251,"name":"5. Cyclone Jenny"},{"status":"ACTIVE","sortPriority":6,"id":42401236,"name":"7. Nomad Road"},{"status":"ACTIVE","sortPriority":7,"id":36010178,"name":"9. So You Sing"}],"regulators":["MR_INT"],"venue":"Rockhampton","countryCode":"AU","discountAllowed":true,"timezone":"Australia/Queensland","openDate":"2022-03-02T08:28:00.000Z","version":4382597822,"name":"To Be Placed","eventName":"Rockhampton (AUS) 2nd Mar"},"rc":[],"con":true,"img":false}]}
{"op":"mcm","clk":"5352150455","pt":1646183689912,"mc":[{"id":"1.195453765","marketDefinition":{"bspMarket":true,"turnInPlayEnabled":false,"persistenceEnabled":false,"marketBaseRate":7.0,"eventId":"31272499","eventTypeId":"4339","numberOfWinners":2,"bettingType":"ODDS","marketType":"PLACE","marketTime":"2022-03-02T08:48:00.000Z","suspendTime":"2022-03-02T08:48:00.000Z","bspReconciled":false,"complete":true,"inPlay":false,"crossMatching":false,"runnersVoidable":false,"numberOfActiveRunners":7,"betDelay":0,"status":"OPEN","runners":[{"status":"ACTIVE","sortPriority":1,"id":41207262,"name":"1. Kooky Loopy"},{"status":"ACTIVE","sortPriority":2,"id":43167130,"name":"2. Suited It"},{"status":"ACTIVE","sortPriority":3,"id":43167131,"name":"3. Pucovski"},{"status":"ACTIVE","sortPriority":4,"id":36386524,"name":"4. Scandalise"},{"status":"ACTIVE","sortPriority":5,"id":40209251,"name":"5. Cyclone Jenny"},{"status":"ACTIVE","sortPriority":6,"id":42401236,"name":"7. Nomad Road"},{"status":"ACTIVE","sortPriority":7,"id":36010178,"name":"9. So You Sing"}],"regulators":["MR_INT"],"venue":"Rockhampton","countryCode":"AU","discountAllowed":true,"timezone":"Australia/Queensland","openDate":"2022-03-02T08:28:00.000Z","version":4382599266,"name":"To Be Placed","eventName":"Rockhampton (AUS) 2nd Mar"},"rc":[],"con":true,"img":false}]}
{"op":"mcm","clk":"5352238284","pt":1646185602675,"mc":[{"id":"1.195453765","marketDefinition":{"bspMarket":true,"turnInPlayEnabled":false,"persistenceEnabled":false,"marketBaseRate":7.0,"eventId":"31272499","eventTypeId":"4339","numberOfWinners":2,"bettingType":"ODDS","marketType":"PLACE","marketTime":"2022-03-02T08:48:00.000Z","suspendTime":"2022-03-02T08:48:00.000Z","bspReconciled":false,"complete":true,"inPlay":false,"crossMatching":false,"runnersVoidable":false,"numberOfActiveRunners":7,"betDelay":0,"status":"OPEN","runners":[{"status":"ACTIVE","sortPriority":1,"id":41207262,"name":"1. Kooky Loopy"},{"status":"ACTIVE","sortPriority":2,"id":43167130,"name":"2. Suited It"},{"status":"ACTIVE","sortPriority":3,"id":43167131,"name":"3. Pucovski"},{"status":"ACTIVE","sortPriority":4,"id":36386524,"name":"4. Scandalise"},{"status":"ACTIVE","sortPriority":5,"id":40209251,"name":"5. Cyclone Jenny"},{"status":"ACTIVE","sortPriority":6,"id":42401236,"name":"7. Nomad Road"},{"status":"ACTIVE","sortPriority":7,"id":36010178,"name":"9. So You Sing"}],"regulators":["MR_INT"],"venue":"Rockhampton","countryCode":"AU","discountAllowed":true,"timezone":"Australia/Queensland","openDate":"2022-03-02T08:28:00.000Z","version":4382599266,"name":"To Be Placed","eventName":"Rockhampton (AUS) 2nd Mar"},"rc":[{"atb":[[2.06,57.1],[1.98,123.52],[1.93,130.16]],"id":41207262},{"atl":[[16,3.22],[6.4,2.24],[11,2.42],[5.2,2.88],[8.4,3.27]],"id":41207262},{"spn":3.63,"spf":"NaN","id":41207262},{"atb":[[2,60.52],[1.9,134.5],[1.95,127.42]],"id":43167130},{"atl":[[5.1,2.94],[6.2,2.32],[10.5,2.54],[8.2,3.36],[15.5,3.33]],"id":43167130},{"spn":3.55,"spf":"NaN","id":43167130},{"atb":[[1.18,672.51],[1.23,263.16],[1.13,931.17]],"id":42401236},{"atl":[[3.45,19.76],[2.38,8.77],[2.58,7.66],[2.98,12.22],[2.78,13.59]],"id":42401236},{"spn":1.8,"spf":"NaN","id":42401236},{"atb":[[3.6,46.55],[3.85,21.23],[3.35,51.51]],"id":43167131},{"atl":[[17.5,0.73],[75,0.65],[40,0.62],[12.5,1.05],[25,1]],"id":43167131},{"spn":8.17,"spf":"NaN","id":43167131},{"atb":[[2.06,57.1],[1.98,123.52],[1.93,130.16]],"id":40209251},{"atl":[[16,3.22],[6.4,2.24],[11,2.42],[5.2,2.88],[8.4,3.27]],"id":40209251},{"spn":3.63,"spf":"NaN","id":40209251},{"atb":[[8.6,7.96],[7.6,18.34],[6.6,21.61]],"id":36010178},{"atl":[[280,0.08],[90,0.13],[180,0.13],[46,0.26],[380,0.12]],"id":36010178},{"spn":27.3,"spf":"NaN","id":36010178},{"atb":[[2.88,64.39],[2.98,30.56],[2.78,68]],"id":36386524},{"atl":[[32,1.55],[10.5,1.27],[21,1.21],[8.2,1.67],[15.5,1.66]],"id":36386524},{"spn":5.59,"spf":"NaN","id":36386524}],"con":true,"img":true}]}
{"op":"mcm","clk":"5352465581","pt":1646191002622,"mc":[{"id":"1.195453765","marketDefinition":{"bspMarket":true,"turnInPlayEnabled":false,"persistenceEnabled":false,"marketBaseRate":7.0,"eventId":"31272499","eventTypeId":"4339","numberOfWinners":2,"bettingType":"ODDS","marketType":"PLACE","marketTime":"2022-03-02T08:48:00.000Z","suspendTime":"2022-03-02T08:48:00.000Z","bspReconciled":false,"complete":true,"inPlay":false,"crossMatching":false,"runnersVoidable":false,"numberOfActiveRunners":7,"betDelay":0,"status":"OPEN","runners":[{"status":"ACTIVE","sortPriority":1,"id":41207262,"name":"1. Kooky Loopy"},{"status":"ACTIVE","sortPriority":2,"id":43167130,"name":"2. Suited It"},{"status":"ACTIVE","sortPriority":3,"id":43167131,"name":"3. Pucovski"},{"status":"ACTIVE","sortPriority":4,"id":36386524,"name":"4. Scandalise"},{"status":"ACTIVE","sortPriority":5,"id":40209251,"name":"5. Cyclone Jenny"},{"status":"ACTIVE","sortPriority":6,"id":42401236,"name":"7. Nomad Road"},{"status":"ACTIVE","sortPriority":7,"id":36010178,"name":"9. So You Sing"}],"regulators":["MR_INT"],"venue":"Rockhampton","countryCode":"AU","discountAllowed":true,"timezone":"Australia/Queensland","openDate":"2022-03-02T08:28:00.000Z","version":4382599266,"name":"To Be Placed","eventName":"Rockhampton (AUS) 2nd Mar"},"rc":[{"atb":[[2.06,57.19],[1.98,123.73],[1.93,130.38]],"id":41207262},{"atl":[[16,3.23],[6.4,2.24],[11,2.42],[5.2,2.88],[8.4,3.27]],"id":41207262},{"spn":3.63,"spf":"NaN","id":41207262},{"atb":[[2,60.62],[1.9,134.73],[1.95,127.63]],"id":43167130},{"atl":[[5.1,2.95],[6.2,2.33],[10.5,2.55],[8.2,3.37],[15.5,3.34]],"id":43167130},{"spn":3.55,"spf":"NaN","id":43167130},{"atb":[[1.18,673.65],[1.23,263.6],[1.13,932.75]],"id":42401236},{"atl":[[3.45,19.79],[2.38,8.78],[2.58,7.67],[2.98,12.24],[2.78,13.62]],"id":42401236},{"spn":1.8,"spf":"NaN","id":42401236},{"atb":[[3.6,46.63],[3.85,21.27],[3.35,51.6]],"id":43167131},{"atl":[[17.5,0.73],[75,0.65],[40,0.62],[12.5,1.05],[25,1.01]],"id":43167131},{"spn":8.17,"spf":"NaN","id":43167131},{"atb":[[2.06,57.19],[1.98,123.73],[1.93,130.38]],"id":40209251},{"atl":[[16,3.23],[6.4,2.24],[11,2.42],[5.2,2.88],[8.4,3.27]],"id":40209251},{"spn":3.63,"spf":"NaN","id":40209251},{"atb":[[8.6,7.98],[7.6,18.37],[6.6,21.65]],"id":36010178},{"atl":[[280,0.08],[90,0.13],[180,0.13],[46,0.26],[380,0.12]],"id":36010178},{"spn":27.3,"spf":"NaN","id":36010178},{"atb":[[2.88,64.5],[2.98,30.62],[2.78,68.12]],"id":36386524},{"atl":[[32,1.56],[10.5,1.27],[21,1.21],[8.2,1.68],[15.5,1.67]],"id":36386524},{"spn":5.59,"spf":"NaN","id":36386524}],"con":true,"img":true}]}
{"op":"mcm","clk":"5352586038","pt":1646194223450,"mc":[{"id":"1.195453765","rc":[{"atb":[[2.06,0],[1.98,0],[1.93,0]],"id":41207262},{"atl":[[16,0],[6.4,0],[11,0],[5.2,0],[8.4,0]],"id":41207262},{"spn":"NaN","spf":"NaN","id":41207262},{"atb":[[2,0],[1.9,0],[1.95,0]],"id":43167130},{"atl":[[5.1,0],[6.2,0],[10.5,0],[8.2,0],[15.5,0]],"id":43167130},{"spn":"NaN","spf":"NaN","id":43167130},{"atb":[[1.18,0],[1.23,0],[1.13,0]],"id":42401236},{"atl":[[3.45,0],[2.38,0],[2.58,0],[2.98,0],[2.78,0]],"id":42401236},{"spn":"NaN","spf":"NaN","id":42401236},{"atb":[[3.6,0],[3.85,0],[3.35,0]],"id":43167131},{"atl":[[17.5,0],[75,0],[40,0],[12.5,0],[25,0]],"id":43167131},{"spn":"NaN","spf":"NaN","id":43167131},{"atb":[[2.06,0],[1.98,0],[1.93,0]],"id":40209251},{"atl":[[16,0],[6.4,0],[11,0],[5.2,0],[8.4,0]],"id":40209251},{"spn":"NaN","spf":"NaN","id":40209251},{"atb":[[8.6,0],[7.6,0],[6.6,0]],"id":36010178},{"atl":[[280,0],[90,0],[180,0],[46,0],[380,0]],"id":36010178},{"spn":"NaN","spf":"NaN","id":36010178},{"atb":[[2.88,0],[2.98,0],[2.78,0]],"id":36386524},{"atl":[[32,0],[10.5,0],[21,0],[8.2,0],[15.5,0]],"id":36386524},{"spn":"NaN","spf":"NaN","id":36386524}],"con":true,"img":false}]}
{"op":"mcm","clk":"5352586491","pt":1646194236690,"mc":[{"id":"1.195453765","rc":[{"atb":[[2.06,57.19],[1.98,123.73],[1.93,130.38]],"id":41207262},{"atl":[[16,3.23],[6.4,2.24],[11,2.42],[5.2,2.88],[8.4,3.27]],"id":41207262},{"atb":[[2,60.62],[1.9,134.73],[1.95,127.63]],"id":43167130},{"atl":[[5.1,2.95],[6.2,2.33],[10.5,2.55],[8.2,3.37],[15.5,3.34]],"id":43167130},{"atb":[[1.18,673.65],[1.23,263.6],[1.13,932.75]],"id":42401236},{"atl":[[3.45,19.79],[2.38,8.78],[2.58,7.67],[2.98,12.24],[2.78,13.62]],"id":42401236},{"atb":[[2,121.25],[2.2,50.52],[2.1,110.23]],"id":40209251},{"atl":[[17.5,2.93],[9,3.03],[5.5,2.69],[12.5,2.1],[7,2.02]],"id":40209251},{"atb":[[3.6,46.63],[3.85,21.27],[3.35,51.6]],"id":43167131},{"atl":[[17.5,0.73],[75,0.65],[40,0.62],[12.5,1.05],[25,1.01]],"id":43167131},{"atb":[[8.6,7.98],[7.6,18.37],[6.6,21.65]],"id":36010178},{"atl":[[280,0.08],[90,0.13],[180,0.13],[46,0.26],[380,0.12]],"id":36010178},{"atb":[[2.82,66.62],[2.92,63.15],[3.05,29.57]],"id":36386524},{"atl":[[32,1.56],[10.5,1.27],[21,1.21],[8.2,1.68],[15.5,1.67]],"id":36386524}],"con":true,"img":false}]}
{"op":"mcm","clk":"5352597941","pt":1646194615613,"mc":[{"id":"1.195453765","rc":[{"atb":[[2.06,0],[1.98,0],[1.93,0]],"id":41207262},{"atl":[[16,0],[6.4,0],[11,0],[5.2,0],[8.4,0]],"id":41207262},{"atb":[[2,0],[1.9,0],[1.95,0]],"id":43167130},{"atl":[[5.1,0],[6.2,0],[10.5,0],[8.2,0],[15.5,0]],"id":43167130},{"atb":[[1.18,0],[1.23,0],[1.13,0]],"id":42401236},{"atl":[[3.45,0],[2.38,0],[2.58,0],[2.98,0],[2.78,0]],"id":42401236},{"atb":[[3.6,0],[3.85,0],[3.35,0]],"id":43167131},{"atl":[[17.5,0],[75,0],[40,0],[12.5,0],[25,0]],"id":43167131},{"atb":[[2,0],[2.2,0],[2.1,0]],"id":40209251},{"atl":[[17.5,0],[9,0],[5.5,0],[12.5,0],[7,0]],"id":40209251},{"spn":27.3,"spf":"NaN","id":36010178},{"atb":[[2.82,0],[2.92,0],[3.05,0]],"id":36386524},{"atl":[[32,0],[10.5,0],[21,0],[8.2,0],[15.5,0]],"id":36386524}],"con":true,"img":false}]}
{"op":"mcm","clk":"5352598363","pt":1646194631252,"mc":[{"id":"1.195453765","rc":[{"atb":[[2.06,57.19],[1.98,123.73],[1.93,130.38]],"id":41207262},{"atl":[[16,3.23],[6.4,2.24],[11,2.42],[5.2,2.88],[8.4,3.27]],"id":41207262},{"atb":[[2,121.25],[2.2,50.52],[2.1,110.23]],"id":43167130},{"atl":[[17.5,2.93],[9,3.03],[5.5,2.69],[12.5,2.1],[7,2.02]],"id":43167130},{"atb":[[1.19,319.1],[1.14,866.12],[1.09,1347.31]],"id":42401236},{"atl":[[2.88,12.9],[3.2,22.04],[2.28,9.47],[2.68,14.43],[2.48,8.19]],"id":42401236},{"atb":[[4.3,18.37],[3.9,41.81],[3.65,45.75]],"id":43167131},{"atl":[[32,0.78],[21,0.6],[55,0.44],[110,0.44],[15.5,0.83]],"id":43167131},{"atb":[[2,121.25],[2.2,50.52],[2.1,110.23]],"id":40209251},{"atl":[[17.5,2.93],[9,3.03],[5.5,2.69],[12.5,2.1],[7,2.02]],"id":40209251},{"atb":[[2.74,69.69],[2.84,65.9],[2.94,31.25]],"id":36386524},{"atl":[[8,1.73],[10,1.34],[20,1.27],[15,1.73],[30,1.67]],"id":36386524}],"con":true,"img":false}]}
{"op":"mcm","clk":"5352601723","pt":1646194734153,"mc":[{"id":"1.195453765","rc":[{"atb":[[2.06,0],[1.98,0],[1.93,0]],"id":41207262},{"atl":[[16,0],[6.4,0],[11,0],[5.2,0],[8.4,0]],"id":41207262},{"atb":[[2,0],[2.2,0],[2.1,0]],"id":43167130},{"atl":[[17.5,0],[9,0],[5.5,0],[12.5,0],[7,0]],"id":43167130},{"spn":1.73,"spf":"NaN","id":42401236},{"spn":9.9,"spf":"NaN","id":43167131},{"atb":[[2,0],[2.2,0],[2.1,0]],"id":40209251},{"atl":[[17.5,0],[9,0],[5.5,0],[12.5,0],[7,0]],"id":40209251},{"atb":[[2.74,0],[2.84,0],[2.94,0]],"id":36386524},{"atl":[[8,0],[10,0],[20,0],[15,0],[30,0]],"id":36386524}],"con":true,"img":false}]}
{"op":"mcm","clk":"5352602393","pt":1646194751778,"mc":[{"id":"1.195453765","rc":[{"atb":[[2.06,57.19],[1.98,123.73],[1.93,130.38]],"id":41207262},{"atl":[[16,3.23],[6.4,2.24],[11,2.42],[5.2,2.88],[8.4,3.27]],"id":41207262},{"atb":[[2.06,114.39],[2.26,48.12],[2.16,104.53]],"id":43167130},{"atl":[[5.6,2.63],[7.2,1.95],[18,2.85],[9.2,2.95],[13,2.02]],"id":43167130},{"atb":[[2.06,114.39],[2.26,48.12],[2.16,104.53]],"id":40209251},{"atl":[[5.6,2.63],[7.2,1.95],[18,2.85],[9.2,2.95],[13,2.02]],"id":40209251},{"atb":[[2.86,65.19],[3.15,28.2],[2.96,61.86]],"id":36386524},{"atl":[[16,1.61],[34,1.46],[11,1.21],[22,1.15],[8.4,1.63]],"id":36386524}],"con":true,"img":false}]}
{"op":"mcm","clk":"5352664923","pt":1646196402641,"mc":[{"id":"1.195453765","marketDefinition":{"bspMarket":true,"turnInPlayEnabled":false,"persistenceEnabled":false,"marketBaseRate":7.0,"eventId":"31272499","eventTypeId":"4339","numberOfWinners":2,"bettingType":"ODDS","marketType":"PLACE","marketTime":"2022-03-02T08:48:00.000Z","suspendTime":"2022-03-02T08:48:00.000Z","bspReconciled":false,"complete":true,"inPlay":false,"crossMatching":false,"runnersVoidable":false,"numberOfActiveRunners":7,"betDelay":0,"status":"OPEN","runners":[{"status":"ACTIVE","sortPriority":1,"id":41207262,"name":"1. Kooky Loopy"},{"status":"ACTIVE","sortPriority":2,"id":43167130,"name":"2. Suited It"},{"status":"ACTIVE","sortPriority":3,"id":43167131,"name":"3. Pucovski"},{"status":"ACTIVE","sortPriority":4,"id":36386524,"name":"4. Scandalise"},{"status":"ACTIVE","sortPriority":5,"id":40209251,"name":"5. Cyclone Jenny"},{"status":"ACTIVE","sortPriority":6,"id":42401236,"name":"7. Nomad Road"},{"status":"ACTIVE","sortPriority":7,"id":36010178,"name":"9. So You Sing"}],"regulators":["MR_INT"],"venue":"Rockhampton","countryCode":"AU","discountAllowed":true,"timezone":"Australia/Queensland","openDate":"2022-03-02T08:28:00.000Z","version":4382599266,"name":"To Be Placed","eventName":"Rockhampton (AUS) 2nd Mar"},"rc":[{"atb":[[2.06,57.19],[1.98,123.73],[1.93,130.38]],"id":41207262},{"atl":[[16,3.23],[6.4,2.24],[11,2.42],[5.2,2.88],[8.4,3.27]],"id":41207262},{"spn":3.63,"spf":"NaN","id":41207262},{"atb":[[2.06,114.39],[2.26,48.12],[2.16,104.53]],"id":43167130},{"atl":[[5.6,2.63],[7.2,1.95],[18,2.85],[9.2,2.95],[13,2.02]],"id":43167130},{"spn":3.93,"spf":"NaN","id":43167130},{"atb":[[1.19,319.1],[1.14,866.12],[1.09,1347.31]],"id":42401236},{"atl":[[2.88,12.9],[3.2,22.04],[2.28,9.47],[2.68,14.43],[2.48,8.19]],"id":42401236},{"spn":1.73,"spf":"NaN","id":42401236},{"atb":[[2.06,114.39],[2.26,48.12],[2.16,104.53]],"id":40209251},{"atl":[[5.6,2.63],[7.2,1.95],[18,2.85],[9.2,2.95],[13,2.02]],"id":40209251},{"spn":3.93,"spf":"NaN","id":40209251},{"atb":[[4.3,18.37],[3.9,41.81],[3.65,45.75]],"id":43167131},{"atl":[[32,0.78],[21,0.6],[55,0.44],[110,0.44],[15.5,0.83]],"id":43167131},{"spn":9.9,"spf":"NaN","id":43167131},{"atb":[[8.6,7.98],[7.6,18.37],[6.6,21.65]],"id":36010178},{"atl":[[280,0.08],[90,0.13],[180,0.13],[46,0.26],[380,0.12]],"id":36010178},{"spn":27.3,"spf":"NaN","id":36010178},{"atb":[[2.86,65.19],[3.15,28.2],[2.96,61.86]],"id":36386524},{"atl":[[16,1.61],[34,1.46],[11,1.21],[22,1.15],[8.4,1.63]],"id":36386524},{"spn":5.77,"spf":"NaN","id":36386524}],"con":true,"img":true}]}
{"op":"mcm","clk":"5352822390","pt":1646201802667,"mc":[{"id":"1.195453765","marketDefinition":{"bspMarket":true,"turnInPlayEnabled":false,"persistenceEnabled":false,"marketBaseRate":7.0,"eventId":"31272499","eventTypeId":"4339","numberOfWinners":2,"bettingType":"ODDS","marketType":"PLACE","marketTime":"2022-03-02T08:48:00.000Z","suspendTime":"2022-03-02T08:48:00.000Z","bspReconciled":false,"complete":true,"inPlay":false,"crossMatching":false,"runnersVoidable":false,"numberOfActiveRunners":7,"betDelay":0,"status":"OPEN","runners":[{"status":"ACTIVE","sortPriority":1,"id":41207262,"name":"1. Kooky Loopy"},{"status":"ACTIVE","sortPriority":2,"id":43167130,"name":"2. Suited It"},{"status":"ACTIVE","sortPriority":3,"id":43167131,"name":"3. Pucovski"},{"status":"ACTIVE","sortPriority":4,"id":36386524,"name":"4. Scandalise"},{"status":"ACTIVE","sortPriority":5,"id":40209251,"name":"5. Cyclone Jenny"},{"status":"ACTIVE","sortPriority":6,"id":42401236,"name":"7. Nomad Road"},{"status":"ACTIVE","sortPriority":7,"id":36010178,"name":"9. So You Sing"}],"regulators":["MR_INT"],"venue":"Rockhampton","countryCode":"AU","discountAllowed":true,"timezone":"Australia/Queensland","openDate":"2022-03-02T08:28:00.000Z","version":4382599266,"name":"To Be Placed","eventName":"Rockhampton (AUS) 2nd Mar"},"rc":[{"atb":[[2.06,57.17],[1.98,123.68],[1.93,130.33]],"id":41207262},{"atl":[[16,3.23],[6.4,2.24],[11,2.42],[5.2,2.88],[8.4,3.27]],"id":41207262},{"spn":3.63,"spf":"NaN","id":41207262},{"atb":[[2.06,114.34],[2.26,48.1],[2.16,104.49]],"id":43167130},{"atl":[[5.6,2.63],[7.2,1.95],[18,2.85],[9.2,2.95],[13,2.02]],"id":43167130},{"spn":3.93,"spf":"NaN","id":43167130},{"atb":[[1.19,318.97],[1.14,865.79],[1.09,1346.8]],"id":42401236},{"atl":[[2.88,12.89],[3.2,22.03],[2.28,9.46],[2.68,14.43],[2.48,8.19]],"id":42401236},{"spn":1.73,"spf":"NaN","id":42401236},{"atb":[[2.06,114.34],[2.26,48.1],[2.16,104.49]],"id":40209251},{"atl":[[5.6,2.63],[7.2,1.95],[18,2.85],[9.2,2.95],[13,2.02]],"id":40209251},{"spn":3.93,"spf":"NaN","id":40209251},{"atb":[[4.3,18.36],[3.9,41.79],[3.65,45.73]],"id":43167131},{"atl":[[32,0.78],[21,0.6],[55,0.44],[110,0.44],[15.5,0.83]],"id":43167131},{"spn":9.9,"spf":"NaN","id":43167131},{"atb":[[8.6,7.97],[7.6,18.36],[6.6,21.64]],"id":36010178},{"atl":[[280,0.08],[90,0.13],[180,0.13],[46,0.26],[380,0.12]],"id":36010178},{"spn":27.3,"spf":"NaN","id":36010178},{"atb":[[2.86,65.16],[3.15,28.19],[2.96,61.84]],"id":36386524},{"atl":[[16,1.61],[34,1.46],[11,1.21],[22,1.15],[8.4,1.63]],"id":36386524},{"spn":5.77,"spf":"NaN","id":36386524}],"con":true,"img":true}]}
{"op":"mcm","clk":"5352954920","pt":1646205560683,"mc":[{"id":"1.195453765","rc":[{"atb":[[1.99,44.11],[2.06,57.16],[1.98,123.65],[1.93,130.3],[1.69,94.97]],"id":41207262},{"atl":[[16,3.23],[6.4,2.24],[6.2,8.39],[11,2.42],[6.8,11.46],[5.2,2.88],[8.4,3.27]],"id":41207262},{"spn":3.63,"spf":"NaN","id":41207262},{"atb":[[1.83,79.14],[2.06,114.31],[2.18,37],[2.26,48.08],[2.16,104.46]],"id":43167130},{"atl":[[5.6,2.63],[8,9.27],[7.2,8.99],[18,2.84],[9.2,2.95],[13,2.01]],"id":43167130},{"spn":3.93,"spf":"NaN","id":43167130},{"atb":[[1.2,94.11],[1.15,386.64],[1.19,318.89],[1.14,865.56],[1.09,1346.43]],"id":42401236},{"atl":[[2.88,12.89],[3.2,22.03],[2.28,9.46],[2.12,38.99],[2.68,14.42],[2.48,8.18],[2.34,39.72]],"id":42401236},{"spn":1.66,"spf":"NaN","id":42401236},{"atb":[[2.06,114.31],[2.18,37],[2.26,48.08],[2.16,104.46],[2.08,60.04]],"id":40209251},{"atl":[[5.6,2.63],[7.2,1.95],[18,2.84],[8.6,8.73],[9.2,2.95],[13,2.01],[7.8,6.41]],"id":40209251},{"spn":3.93,"spf":"NaN","id":40209251},{"atb":[[4.3,18.36],[5.2,10.39],[4.4,16.49],[3.9,41.78],[3.65,45.72]],"id":43167131},{"atl":[[32,0.78],[21,0.6],[55,0.44],[110,0.44],[27,2.72],[30,2.72],[15.5,0.83]],"id":43167131},{"spn":10.35,"spf":"NaN","id":43167131},{"atb":[[8.6,7.97],[19,2.72],[7.6,18.36],[6.6,21.63],[15.5,3.97]],"id":36010178},{"atl":[[150,0.29],[160,2.72],[46,0.26]],"id":36010178},{"spn":32.5,"spf":"NaN","id":36010178},{"atb":[[2.88,29.32],[2.86,65.14],[3.15,28.18],[2.98,22.05],[2.96,61.82]],"id":36386524},{"atl":[[16,1.61],[34,1.46],[11,1.21],[22,1.15],[13,3.64],[8.4,1.63],[14.5,4.08]],"id":36386524},{"spn":5.77,"spf":"NaN","id":36386524}],"con":true,"img":false}]}
{"op":"mcm","clk":"5352957677","pt":1646205647163,"mc":[{"id":"1.195453765","rc":[{"atb":[[5.2,0]],"id":43167131},{"spn":9.95,"spf":"NaN","id":43167131}],"con":true,"img":false}]}
{"op":"mcm","clk":"5352957680","pt":1646205647265,"mc":[{"id":"1.195453765","rc":[{"atb":[[4.7,10.39]],"id":43167131}],"con":true,"img":false}]}
{"op":"mcm","clk":"5353027765","pt":1646207202702,"mc":[{"id":"1.195453765","marketDefinition":{"bspMarket":true,"turnInPlayEnabled":false,"persistenceEnabled":false,"marketBaseRate":7.0,"eventId":"31272499","eventTypeId":"4339","numberOfWinners":2,"bettingType":"ODDS","marketType":"PLACE","marketTime":"2022-03-02T08:48:00.000Z","suspendTime":"2022-03-02T08:48:00.000Z","bspReconciled":false,"complete":true,"inPlay":false,"crossMatching":false,"runnersVoidable":false,"numberOfActiveRunners":7,"betDelay":0,"status":"OPEN","runners":[{"status":"ACTIVE","sortPriority":1,"id":41207262,"name":"1. Kooky Loopy"},{"status":"ACTIVE","sortPriority":2,"id":43167130,"name":"2. Suited It"},{"status":"ACTIVE","sortPriority":3,"id":43167131,"name":"3. Pucovski"},{"status":"ACTIVE","sortPriority":4,"id":36386524,"name":"4. Scandalise"},{"status":"ACTIVE","sortPriority":5,"id":40209251,"name":"5. Cyclone Jenny"},{"status":"ACTIVE","sortPriority":6,"id":42401236,"name":"7. Nomad Road"},{"status":"ACTIVE","sortPriority":7,"id":36010178,"name":"9. So You Sing"}],"regulators":["MR_INT"],"venue":"Rockhampton","countryCode":"AU","discountAllowed":true,"timezone":"Australia/Queensland","openDate":"2022-03-02T08:28:00.000Z","version":4382599266,"name":"To Be Placed","eventName":"Rockhampton (AUS) 2nd Mar"},"rc":[{"atb":[[1.99,44.11],[2.06,57.16],[1.98,123.65],[1.93,130.3],[1.69,94.97]],"id":41207262},{"atl":[[16,3.23],[6.4,2.24],[6.2,8.39],[11,2.42],[6.8,11.46],[5.2,2.88],[8.4,3.27]],"id":41207262},{"spn":3.63,"spf":"NaN","id":41207262},{"atb":[[1.83,79.14],[2.06,114.31],[2.18,37],[2.26,48.08],[2.16,104.46]],"id":43167130},{"atl":[[5.6,2.63],[8,9.27],[7.2,8.99],[18,2.84],[9.2,2.95],[13,2.01]],"id":43167130},{"spn":3.93,"spf":"NaN","id":43167130},{"atb":[[1.2,94.11],[1.15,386.64],[1.19,318.89],[1.14,865.56],[1.09,1346.43]],"id":42401236},{"atl":[[2.88,12.89],[3.2,22.03],[2.12,38.99],[2.28,9.46],[2.68,14.42],[2.34,39.72],[2.48,8.18]],"id":42401236},{"spn":1.66,"spf":"NaN","id":42401236},{"atb":[[4.3,18.36],[4.4,16.49],[3.9,41.78],[3.65,45.72],[4.7,10.39]],"id":43167131},{"atl":[[32,0.78],[21,0.6],[27,2.72],[55,0.44],[110,0.44],[30,2.72],[15.5,0.83]],"id":43167131},{"spn":10.1,"spf":"NaN","id":43167131},{"atb":[[2.06,114.31],[2.18,37],[2.26,48.08],[2.16,104.46],[2.08,60.04]],"id":40209251},{"atl":[[5.6,2.63],[7.2,1.95],[8.6,8.73],[18,2.84],[9.2,2.95],[13,2.01],[7.8,6.41]],"id":40209251},{"spn":3.93,"spf":"NaN","id":40209251},{"atb":[[8.6,7.97],[19,2.72],[7.6,18.36],[6.6,21.63],[15.5,3.97]],"id":36010178},{"atl":[[280,0.08],[150,0.29],[160,2.72],[90,0.13],[180,0.13],[46,0.26],[380,0.12]],"id":36010178},{"spn":32.5,"spf":"NaN","id":36010178},{"atb":[[2.88,29.32],[2.86,65.14],[3.15,28.18],[2.98,22.05],[2.96,61.82]],"id":36386524},{"atl":[[16,1.61],[34,1.46],[11,1.21],[22,1.15],[13,3.64],[8.4,1.63],[14.5,4.08]],"id":36386524},{"spn":5.77,"spf":"NaN","id":36386524}],"con":true,"img":true}]}
{"op":"mcm","clk":"5353034792","pt":1646207298845,"mc":[{"id":"1.195453765","rc":[{"atl":[[9,6.56]],"id":41207262},{"atb":[[1.07,158.3]],"id":43167130},{"atl":[[9.4,11.9]],"id":43167130},{"atl":[[4.3,28.86]],"id":42401236},{"atb":[[2.4,36.72]],"id":43167131},{"atl":[[27,5.45]],"id":43167131},{"spn":10.1,"spf":"NaN","id":43167131},{"atb":[[1.1,120.08]],"id":40209251},{"atl":[[9.8,5.9]],"id":40209251},{"atb":[[2.16,15.94]],"id":36010178},{"atb":[[1.26,58.64]],"id":36386524},{"atl":[[17,3.28]],"id":36386524}],"con":true,"img":false}]}
{"op":"mcm","clk":"5353037408","pt":1646207356931,"mc":[{"id":"1.195453765","rc":[{"atl":[[30,0]],"id":43167131}],"con":true,"img":false}]}
{"op":"mcm","clk":"5353037416","pt":1646207357025,"mc":[{"id":"1.195453765","rc":[{"atl":[[26,2.72]],"id":43167131}],"con":true,"img":false}]}
{"op":"mcm","clk":"5353045019","pt":1646207552711,"mc":[{"id":"1.195453765","rc":[{"atb":[[2.5,36.75]],"id":36386524}],"con":true,"img":false}]}
{"op":"mcm","clk":"5353045024","pt":1646207552814,"mc":[{"id":"1.195453765","rc":[{"atb":[[2.88,0]],"id":36386524}],"con":true,"img":false}]}
{"op":"mcm","clk":"5353045899","pt":1646207577376,"mc":[{"id":"1.195453765","rc":[{"atb":[[2.18,0]],"id":40209251}],"con":true,"img":false}]}
{"op":"mcm","clk":"5353045905","pt":1646207577427,"mc":[{"id":"1.195453765","rc":[{"atb":[[2.28,37]],"id":40209251}],"con":true,"img":false}]}
{"op":"mcm","clk":"5353070410","pt":1646208188031,"mc":[{"id":"1.195453765","rc":[{"atb":[[2.08,1.67]],"id":41207262},{"spn":3.64,"spf":"NaN","id":41207262},{"atb":[[2.28,1.67]],"id":43167130},{"spn":3.94,"spf":"NaN","id":43167130},{"atb":[[2.3,1.67]],"id":40209251},{"spn":3.95,"spf":"NaN","id":40209251},{"atb":[[4.8,1.67]],"id":43167131},{"spn":10.15,"spf":"NaN","id":43167131},{"atb":[[3.2,1.67]],"id":36386524},{"spn":5.8,"spf":"NaN","id":36386524}],"con":true,"img":false}]}
{"op":"mcm","clk":"5353071388","pt":1646208209279,"mc":[{"id":"1.195453765","marketDefinition":{"bspMarket":true,"turnInPlayEnabled":false,"persistenceEnabled":false,"marketBaseRate":7.0,"eventId":"31272499","eventTypeId":"4339","numberOfWinners":2,"bettingType":"ODDS","marketType":"PLACE","marketTime":"2022-03-02T08:48:00.000Z","suspendTime":"2022-03-02T08:48:00.000Z","bspReconciled":false,"complete":true,"inPlay":false,"crossMatching":true,"runnersVoidable":false,"numberOfActiveRunners":7,"betDelay":0,"status":"OPEN","runners":[{"status":"ACTIVE","sortPriority":1,"id":41207262,"name":"1. Kooky Loopy"},{"status":"ACTIVE","sortPriority":2,"id":43167130,"name":"2. Suited It"},{"status":"ACTIVE","sortPriority":3,"id":43167131,"name":"3. Pucovski"},{"status":"ACTIVE","sortPriority":4,"id":36386524,"name":"4. Scandalise"},{"status":"ACTIVE","sortPriority":5,"id":40209251,"name":"5. Cyclone Jenny"},{"status":"ACTIVE","sortPriority":6,"id":42401236,"name":"7. Nomad Road"},{"status":"ACTIVE","sortPriority":7,"id":36010178,"name":"9. So You Sing"}],"regulators":["MR_INT"],"venue":"Rockhampton","countryCode":"AU","discountAllowed":true,"timezone":"Australia/Queensland","openDate":"2022-03-02T08:28:00.000Z","version":4382599266,"name":"To Be Placed","eventName":"Rockhampton (AUS) 2nd Mar"},"rc":[],"con":true,"img":false}]}
{"op":"mcm","clk":"5353083382","pt":1646208461475,"mc":[{"id":"1.195453765","rc":[{"atb":[[2.1,6.84]],"id":41207262},{"spn":3.65,"spf":"NaN","id":41207262},{"atb":[[2.32,5.7]],"id":43167130},{"spn":3.96,"spf":"NaN","id":43167130},{"atb":[[2.34,5.61]],"id":40209251},{"spn":3.97,"spf":"NaN","id":40209251},{"atb":[[3.2,5.09]],"id":36386524}],"con":true,"img":false}]}
{"op":"mcm","clk":"5353083513","pt":1646208464104,"mc":[{"id":"1.195453765","rc":[{"atb":[[2.08,0]],"id":41207262},{"atb":[[2.28,0]],"id":43167130},{"atb":[[2.3,0]],"id":40209251}],"con":true,"img":false}]}
{"op":"mcm","clk":"5353083523","pt":1646208464310,"mc":[{"id":"1.195453765","rc":[{"atb":[[2.12,1.67]],"id":41207262},{"atb":[[2.34,1.67]],"id":43167130},{"atb":[[2.36,1.67]],"id":40209251}],"con":true,"img":false}]}
{"op":"mcm","clk":"5353084259","pt":1646208481003,"mc":[{"id":"1.195453765","rc":[{"atl":[[4.3,0],[8.6,13.16]],"id":42401236},{"atb":[[4.6,15.94]],"id":36010178},{"atb":[[1.26,0]],"id":36386524}],"con":true,"img":false}]}
{"op":"mcm","clk":"5353084263","pt":1646208481106,"mc":[{"id":"1.195453765","rc":[{"atb":[[2.16,0]],"id":36010178}],"con":true,"img":false}]}
{"op":"mcm","clk":"5353087449","pt":1646208558295,"mc":[{"id":"1.195453765","rc":[{"atb":[[2.1,14.43]],"id":41207262},{"spn":3.66,"spf":"NaN","id":41207262},{"spn":3.97,"spf":"NaN","id":43167130},{"spn":3.98,"spf":"NaN","id":40209251}],"con":true,"img":false}]}
{"op":"mcm","clk":"5353087457","pt":1646208558502,"mc":[{"id":"1.195453765","rc":[{"atb":[[2.32,12.03]],"id":43167130}],"con":true,"img":false}]}
{"op":"mcm","clk":"5353087471","pt":1646208558811,"mc":[{"id":"1.195453765","rc":[{"atb":[[2.34,11.84]],"id":40209251}],"con":true,"img":false}]}
{"op":"mcm","clk":"5353087482","pt":1646208559118,"mc":[{"id":"1.195453765","rc":[{"atb":[[3.2,8.89]],"id":36386524}],"con":true,"img":false}]}
{"op":"mcm","clk":"5353111289","pt":1646209081688,"mc":[{"id":"1.195453765","rc":[{"atb":[[1.99,119.87],[2.02,49.02],[2.06,76.03],[1.97,128.87]],"id":41207262},{"atl":[[3.6,28.85],[3.7,46.3],[3.4,8.33],[3.5,20]],"id":41207262},{"spn":2.76,"spf":"NaN","id":41207262},{"atb":[[2.04,120.19],[2.12,44.64],[2.16,121.7],[2.08,69.44]],"id":43167130},{"atl":[[3.6,7.69],[3.7,18.52],[3.8,26.79],[3.9,43.1]],"id":43167130},{"spn":2.97,"spf":"NaN","id":43167130},{"atb":[[1.2,344.11],[1.18,250],[1.16,250],[1.22,90.91]],"id":42401236},{"atl":[[8.6,15.79],[9,6.25],[9.8,14.2],[9.4,8.93]],"id":42401236},{"spn":1.67,"spf":"NaN","id":42401236},{"atb":[[2.22,16.39],[2.18,42.37],[2.14,65.79],[2.1,113.64]],"id":40209251},{"atl":[[3.85,17.54],[3.95,25.42],[4.1,40.32],[3.75,7.27]],"id":40209251},{"spn":3.05,"spf":"NaN","id":40209251},{"atb":[[2.4,0],[4.3,33.51],[4.5,5.71],[2.5,36.72],[3.95,42.37],[4.1,24.19]],"id":43167131},{"atl":[[17.5,1.21],[18.5,2.86],[19.5,4.05],[21,6.85]],"id":43167131},{"atb":[[4.8,5.26],[4.6,29.83],[4.4,22.06],[4.2,39.06]],"id":36010178},{"atl":[[270,1],[210,1],[230,1],[250,1]],"id":36010178},{"atb":[[2.56,48.08],[2.52,82.24],[2.64,12.2],[2.6,31.25]],"id":36386524},{"atl":[[7.4,11.72],[6.6,3.57],[7,8.33],[7.8,18.38]],"id":36386524},{"spn":4.9,"spf":"NaN","id":36386524}],"con":true,"img":false}]}
{"op":"mcm","clk":"5353111348","pt":1646209083102,"mc":[{"id":"1.195453765","rc":[{"atb":[[2.46,13.7],[2.64,0],[2.6,0]],"id":36386524}],"con":true,"img":false}]}
{"op":"mcm","clk":"5353111386","pt":1646209083780,"mc":[{"id":"1.195453765","rc":[{"atb":[[2.56,0]],"id":36386524}],"con":true,"img":false}]}
{"op":"mcm","clk":"5353111430","pt":1646209084601,"mc":[{"id":"1.195453765","rc":[{"atl":[[26,0]],"id":43167131}],"con":true,"img":false}]}
{"op":"mcm","clk":"5353111435","pt":1646209084705,"mc":[{"id":"1.195453765","rc":[{"atl":[[29,2.72]],"id":43167131}],"con":true,"img":false}]}
{"op":"mcm","clk":"5353111494","pt":1646209086114,"mc":[{"id":"1.195453765","rc":[{"atb":[[2.52,0]],"id":36386524}],"con":true,"img":false}]}
{"op":"mcm","clk":"5353111501","pt":1646209086269,"mc":[{"id":"1.195453765","rc":[{"atl":[[3.75,0],[3.7,7.41]],"id":40209251}],"con":true,"img":false}]}
{"op":"mcm","clk":"5353111555","pt":1646209087413,"mc":[{"id":"1.195453765","rc":[{"atl":[[8.6,0],[5,30]],"id":42401236},{"atl":[[17.5,0],[18.5,0],[21,1.6]],"id":43167131},{"atb":[[4.8,0],[3.2,36.72],[4.6,0],[3.4,8.33],[4.4,0],[4.2,0]],"id":36010178}],"con":true,"img":false}]}
{"op":"mcm","clk":"5353111611","pt":1646209089487,"mc":[{"id":"1.195453765","rc":[{"atb":[[1.83,0]],"id":43167130},{"atl":[[2.12,0],[2.6,27.29],[2.34,0],[2.86,31.17]],"id":42401236},{"atb":[[2.08,0],[1.76,85.69]],"id":40209251}],"con":true,"img":false}]}
{"op":"mcm","clk":"5353111615","pt":1646209089599,"mc":[{"id":"1.195453765","rc":[{"atb":[[1.74,79.14]],"id":43167130}],"con":true,"img":false}]}
{"op":"mcm","clk":"5353111762","pt":1646209093121,"mc":[{"id":"1.195453765","rc":[{"atb":[[2.42,35.21]],"id":36386524}],"con":true,"img":false}]}
{"op":"mcm","clk":"5353111922","pt":1646209097416,"mc":[{"id":"1.195453765","rc":[{"atl":[[5.2,11.9]],"id":42401236},{"atl":[[19.5,0],[23,2.27]],"id":43167131},{"atb":[[3.3,21.74]],"id":36010178}],"con":true,"img":false}]}
{"op":"mcm","clk":"5353112002","pt":1646209099592,"mc":[{"id":"1.195453765","rc":[{"atb":[[1.99,75.76]],"id":41207262}],"con":true,"img":false}]}
{"op":"mcm","clk":"5353112008","pt":1646209099698,"mc":[{"id":"1.195453765","rc":[{"atb":[[2.04,44.11]],"id":41207262}],"con":true,"img":false}]}
{"op":"mcm","clk":"5353112141","pt":1646209103094,"mc":[{"id":"1.195453765","rc":[{"atb":[[2.38,54.35]],"id":36386524}],"con":true,"img":false}]}
{"op":"mcm","clk":"5353112201","pt":1646209104643,"mc":[{"id":"1.195453765","rc":[{"atb":[[1.2,250]],"id":42401236}],"con":true,"img":false}]}
{"op":"mcm","clk":"5353112205","pt":1646209104697,"mc":[{"id":"1.195453765","rc":[{"atb":[[1.23,94.11]],"id":42401236}],"con":true,"img":false}]}
{"op":"mcm","clk":"5353112312","pt":1646209107436,"mc":[{"id":"1.195453765","rc":[{"atl":[[5.4,17.05]],"id":42401236},{"atl":[[25,3.12]],"id":43167131},{"atb":[[3.2,70.81]],"id":36010178}],"con":true,"img":false}]}
{"op":"mcm","clk":"5353112319","pt":1646209107538,"mc":[{"id":"1.195453765","rc":[{"atl":[[9,0],[9.4,0],[9.8,0]],"id":42401236}],"con":true,"img":false}]}
{"op":"mcm","clk":"5353112392","pt":1646209109500,"mc":[{"id":"1.195453765","rc":[{"atl":[[3.55,17.12],[6.2,0]],"id":41207262},{"atl":[[7.2,1.95],[3.75,15.87]],"id":43167130},{"atl":[[27,2.73]],"id":43167131},{"atl":[[7.8,0],[3.9,15.06]],"id":40209251},{"atb":[[19,0]],"id":36010178},{"atl":[[150,0]],"id":36010178},{"atl":[[13,0],[7.2,7.04]],"id":36386524}],"con":true,"img":false}]}
{"op":"mcm","clk":"5353112397","pt":1646209109603,"mc":[{"id":"1.195453765","rc":[{"atl":[[22,2.72]],"id":43167131},{"atb":[[19.5,2.72]],"id":36010178},{"atl":[[110,0.29]],"id":36010178}],"con":true,"img":false}]}
{"op":"mcm","clk":"5353112529","pt":1646209113113,"mc":[{"id":"1.195453765","rc":[{"atb":[[2.34,93.28]],"id":36386524}],"con":true,"img":false}]}
{"op":"mcm","clk":"5353112693","pt":1646209117443,"mc":[{"id":"1.195453765","rc":[{"atl":[[5.6,27.17]],"id":42401236},{"atl":[[27,7.54]],"id":43167131},{"atb":[[3.1,59.52]],"id":36010178}],"con":true,"img":false}]}
{"op":"mcm","clk":"5353113039","pt":1646209124528,"mc":[{"id":"1.195453765","rc":[{"atb":[[1.15,0],[1.21,276.17]],"id":42401236}],"con":true,"img":false}]}
{"op":"mcm","clk":"5353113248","pt":1646209129520,"mc":[{"id":"1.195453765","rc":[{"atl":[[6.8,0],[5.6,14.19]],"id":41207262},{"atl":[[8,0],[6.2,12.55]],"id":43167130},{"atl":[[29,0]],"id":43167131},{"atl":[[8.6,0],[6.2,12.55]],"id":40209251},{"atl":[[160,0]],"id":36010178},{"atl":[[10.5,5.8],[14.5,0]],"id":36386524}],"con":true,"img":false}]}
{"op":"mcm","clk":"5353113254","pt":1646209129622,"mc":[{"id":"1.195453765","rc":[{"atl":[[22,5.45]],"id":43167131},{"atl":[[120,2.72]],"id":36010178}],"con":true,"img":false}]}
{"op":"mcm","clk":"5353113456","pt":1646209134591,"mc":[{"id":"1.195453765","rc":[{"atl":[[3.55,0]],"id":41207262}],"con":true,"img":false}]}
{"op":"mcm","clk":"5353113458","pt":1646209134651,"mc":[{"id":"1.195453765","rc":[{"atl":[[3.45,17.12]],"id":41207262}],"con":true,"img":false}]}
{"op":"mcm","clk":"5353114296","pt":1646209154482,"mc":[{"id":"1.195453765","rc":[{"atb":[[2.06,57.16],[1.98,144.06]],"id":41207262},{"spn":1.75,"spf":"NaN","id":42401236},{"spn":3.03,"spf":"NaN","id":40209251},{"spn":32.75,"spf":"NaN","id":36010178},{"atb":[[2.74,11.49],[2.46,0]],"id":36386524}],"con":true,"img":false}]}
{"op":"mcm","clk":"5353114399","pt":1646209156964,"mc":[{"id":"1.195453765","rc":[{"atb":[[19.5,0]],"id":36010178},{"trd":[[19.5,5.45]],"ltp":19.5,"tv":5.45,"id":36010178}],"con":true,"img":false}]}
{"op":"mcm","clk":"5353114493","pt":1646209159492,"mc":[{"id":"1.195453765","rc":[{"atl":[[7.2,12.32]],"id":40209251},{"atb":[[11.5,3.09]],"id":36010178},{"atl":[[12.5,4.79]],"id":36386524}],"con":true,"img":false}]}
{"op":"mcm","clk":"5353114496","pt":1646209159596,"mc":[{"id":"1.195453765","rc":[{"atl":[[5.6,0]],"id":41207262},{"atl":[[6.2,0]],"id":43167130},{"atl":[[2.86,0],[2.6,0]],"id":42401236},{"atl":[[6.2,0]],"id":40209251},{"atl":[[22,2.72]],"id":43167131},{"atb":[[15.5,0]],"id":36010178},{"atl":[[10.5,0]],"id":36386524}],"con":true,"img":false}]}
{"op":"mcm","clk":"5353114503","pt":1646209159698,"mc":[{"id":"1.195453765","rc":[{"atl":[[6.4,16.43]],"id":41207262},{"atl":[[7,12.55]],"id":43167130},{"atl":[[2.86,27.29],[3.15,31.17]],"id":42401236},{"atl":[[24,2.72]],"id":43167131}],"con":true,"img":false}]}
{"op":"mcm","clk":"5353114695","pt":1646209164500,"mc":[{"id":"1.195453765","rc":[{"atb":[[2.02,0],[1.96,52.08]],"id":41207262},{"atl":[[3.45,0],[5.2,13.28]],"id":41207262},{"atl":[[3.75,0],[5.7,9.29]],"id":43167130},{"atl":[[5.8,9.09],[3.9,0]],"id":40209251},{"atb":[[2.7,29.41]],"id":36386524}],"con":true,"img":false}]}
{"op":"mcm","clk":"5353114701","pt":1646209164705,"mc":[{"id":"1.195453765","rc":[{"atl":[[24,0]],"id":43167131}],"con":true,"img":false}]}
{"op":"mcm","clk":"5353114704","pt":1646209164808,"mc":[{"id":"1.195453765","rc":[{"atl":[[26,2.72]],"id":43167131}],"con":true,"img":false}]}
{"op":"mcm","clk":"5353114908","pt":1646209170394,"mc":[{"id":"1.195453765","rc":[{"atb":[[17,2.72]],"id":36010178}],"con":true,"img":false}]}
{"op":"mcm","clk":"5353115059","pt":1646209174520,"mc":[{"id":"1.195453765","rc":[{"atb":[[1.99,0],[2.04,0],[1.94,79.79]],"id":41207262},{"atl":[[110,0]],"id":36010178},{"atb":[[2.66,45.18],[2.34,0]],"id":36386524}],"con":true,"img":false}]}
{"op":"mcm","clk":"5353115062","pt":1646209174622,"mc":[{"id":"1.195453765","rc":[{"atb":[[2,44.11]],"id":41207262},{"atl":[[95,0.29]],"id":36010178}],"con":true,"img":false}]}
{"op":"mcm","clk":"5353115511","pt":1646209184516,"mc":[{"id":"1.195453765","rc":[{"atb":[[2,0],[1.92,135.87]],"id":41207262},{"atb":[[2.38,0],[2.62,77.16]],"id":36386524}],"con":true,"img":false}]}
{"op":"mcm","clk":"5353115515","pt":1646209184617,"mc":[{"id":"1.195453765","rc":[{"atb":[[1.99,44.11]],"id":41207262}],"con":true,"img":false}]}
{"op":"mcm","clk":"5353115943","pt":1646209194548,"mc":[{"id":"1.195453765","rc":[{"atb":[[1.97,0]],"id":41207262},{"atb":[[2.42,0]],"id":36386524}],"con":true,"img":false}]}
{"op":"mcm","clk":"5353116142","pt":1646209199574,"mc":[{"id":"1.195453765","rc":[{"atb":[[1.93,200.71],[1.69,0]],"id":41207262},{"atb":[[2.06,175.99],[1.74,0]],"id":43167130},{"atb":[[2.08,60.04],[1.76,0]],"id":40209251},{"atl":[[120,0]],"id":36010178}],"con":true,"img":false}]}
{"op":"mcm","clk":"5353116151","pt":1646209199736,"mc":[{"id":"1.195453765","rc":[{"atl":[[100,2.72]],"id":36010178}],"con":true,"img":false}]}
{"op":"mcm","clk":"5353116597","pt":1646209208168,"mc":[{"id":"1.195453765","rc":[{"atb":[[2.5,0]],"id":36386524}],"con":true,"img":false}]}
{"op":"mcm","clk":"5353116605","pt":1646209208271,"mc":[{"id":"1.195453765","rc":[{"atb":[[2.72,36.75]],"id":36386524}],"con":true,"img":false}]}
{"op":"mcm","clk":"5353120588","pt":1646209298410,"mc":[{"id":"1.195453765","rc":[{"atl":[[3.4,0],[3.5,8]],"id":41207262},{"spn":2.81,"spf":"NaN","id":41207262},{"spn":31.5,"spf":"NaN","id":36010178}],"con":true,"img":false}]}
{"op":"mcm","clk":"5353120596","pt":1646209298613,"mc":[{"id":"1.195453765","rc":[{"atl":[[3.4,8.33]],"id":41207262}],"con":true,"img":false}]}
{"op":"mcm","clk":"5353121041","pt":1646209308632,"mc":[{"id":"1.195453765","rc":[{"atl":[[3.5,20]],"id":41207262}],"con":true,"img":false}]}
{"op":"mcm","clk":"5353122689","pt":1646209344665,"mc":[{"id":"1.195453765","rc":[{"atl":[[26,0]],"id":43167131}],"con":true,"img":false}]}
{"op":"mcm","clk":"5353122694","pt":1646209344771,"mc":[{"id":"1.195453765","rc":[{"atl":[[24,2.72]],"id":43167131}],"con":true,"img":false}]}
{"op":"mcm","clk":"5353131759","pt":1646209514572,"mc":[{"id":"1.195453765","rc":[{"spn":2.76,"spf":"NaN","id":41207262},{"atl":[[24,0]],"id":43167131}],"con":true,"img":false}]}
{"op":"mcm","clk":"5353131763","pt":1646209514676,"mc":[{"id":"1.195453765","rc":[{"atl":[[26,2.72]],"id":43167131}],"con":true,"img":false}]}
{"op":"mcm","clk":"5353131838","pt":1646209515932,"mc":[{"id":"1.195453765","rc":[{"atb":[[1.98,123.65],[1.96,20.83]],"id":41207262},{"atb":[[2.86,75.89],[2.74,0]],"id":36386524}],"con":true,"img":false}]}
{"op":"mcm","clk":"5353132066","pt":1646209519517,"mc":[{"id":"1.195453765","rc":[{"atb":[[2.72,0]],"id":36386524}],"con":true,"img":false}]}
{"op":"mcm","clk":"5353132071","pt":1646209519570,"mc":[{"id":"1.195453765","rc":[{"atb":[[2.68,36.75]],"id":36386524}],"con":true,"img":false}]}
{"op":"mcm","clk":"5353132459","pt":1646209525900,"mc":[{"id":"1.195453765","rc":[{"atb":[[1.94,132.98]],"id":41207262},{"atb":[[2.82,27.47]],"id":36386524}],"con":true,"img":false}]}
{"op":"mcm","clk":"5353132463","pt":1646209526002,"mc":[{"id":"1.195453765","rc":[{"atb":[[1.94,53.18]],"id":41207262}],"con":true,"img":false}]}
{"op":"mcm","clk":"5353132768","pt":1646209531022,"mc":[{"id":"1.195453765","rc":[{"atb":[[2,20]],"id":41207262},{"atb":[[2.8,11.11],[2.86,65.14]],"id":36386524}],"con":true,"img":false}]}
{"op":"mcm","clk":"5353133326","pt":1646209541007,"mc":[{"id":"1.195453765","rc":[{"atb":[[1.98,174.67]],"id":41207262},{"atb":[[2.82,0],[2.76,28.41]],"id":36386524}],"con":true,"img":false}]}
{"op":"mcm","clk":"5353133884","pt":1646209551022,"mc":[{"id":"1.195453765","rc":[{"atb":[[1.92,0],[1.96,78.12]],"id":41207262},{"atb":[[2.72,43.6],[2.66,0],[2.62,0],[2.7,0]],"id":36386524}],"con":true,"img":false}]}
{"op":"mcm","clk":"5353134069","pt":1646209554524,"mc":[{"id":"1.195453765","rc":[{"atb":[[1.93,130.3]],"id":41207262}],"con":true,"img":false}]}
{"op":"mcm","clk":"5353134390","pt":1646209561038,"mc":[{"id":"1.195453765","rc":[{"atb":[[1.94,132.97]],"id":41207262},{"atb":[[2.68,111.15]],"id":36386524}],"con":true,"img":false}]}
{"op":"mcm","clk":"5353134863","pt":1646209569529,"mc":[{"id":"1.195453765","rc":[{"atb":[[2.68,74.4]],"id":36386524}],"con":true,"img":false}]}
{"op":"mcm","clk":"5353134869","pt":1646209569631,"mc":[{"id":"1.195453765","rc":[{"atb":[[2.78,36.75]],"id":36386524}],"con":true,"img":false}]}
{"op":"mcm","clk":"5353135168","pt":1646209574531,"mc":[{"id":"1.195453765","rc":[{"atb":[[1.76,86.24]],"id":41207262}],"con":true,"img":false}]}
{"op":"mcm","clk":"5353140195","pt":1646209664550,"mc":[{"id":"1.195453765","rc":[{"atb":[[2,20],[2.12,0],[2.16,104.46],[2.08,0]],"id":43167130},{"atl":[[5,25],[5.4,4.55]],"id":42401236},{"atl":[[21,0.6],[22,3.72]],"id":43167131},{"atb":[[3.2,34.09],[3.4,0],[3.5,21.74],[3.65,7.55]],"id":36010178}],"con":true,"img":false}]}
{"op":"mcm","clk":"5353140222","pt":1646209665062,"mc":[{"id":"1.195453765","rc":[{"atl":[[3.45,8.16],[3.4,0]],"id":41207262},{"atb":[[2.04,0]],"id":43167130},{"atl":[[5.2,0]],"id":42401236}],"con":true,"img":false}]}
{"op":"mcm","clk":"5353140470","pt":1646209669550,"mc":[{"id":"1.195453765","rc":[{"atb":[[2.06,114.31],[1.87,75.32]],"id":43167130}],"con":true,"img":false}]}
{"op":"mcm","clk":"5353140748","pt":1646209674562,"mc":[{"id":"1.195453765","rc":[{"atl":[[5.6,10.87]],"id":42401236},{"atl":[[24,2.17]],"id":43167131},{"atb":[[3.55,19.61]],"id":36010178}],"con":true,"img":false}]}
{"op":"mcm","clk":"5353140754","pt":1646209674668,"mc":[{"id":"1.195453765","rc":[{"atb":[[1.98,51.02]],"id":43167130}],"con":true,"img":false}]}
{"op":"mcm","clk":"5353140773","pt":1646209674975,"mc":[{"id":"1.195453765","rc":[{"atl":[[3.55,19.61]],"id":41207262}],"con":true,"img":false}]}
{"op":"mcm","clk":"5353141300","pt":1646209684599,"mc":[{"id":"1.195453765","rc":[{"atb":[[1.96,78.12]],"id":43167130},{"atl":[[5.8,15.62]],"id":42401236},{"atl":[[23,0],[25,0],[26,5.72],[27,2.73]],"id":43167131},{"atb":[[3.45,30.61],[3.2,0],[3.1,0],[3.3,0]],"id":36010178}],"con":true,"img":false}]}
{"op":"mcm","clk":"5353141331","pt":1646209685064,"mc":[{"id":"1.195453765","rc":[{"atl":[[3.6,0],[3.7,0],[3.5,0],[3.65,28.3]],"id":41207262}],"con":true,"img":false}]}
{"op":"mcm","clk":"5353141979","pt":1646209694603,"mc":[{"id":"1.195453765","rc":[{"atb":[[1.94,132.98]],"id":43167130},{"atl":[[6,25]],"id":42401236},{"atl":[[28,4.63]],"id":43167131},{"atb":[[3.35,53.19]],"id":36010178}],"con":true,"img":false}]}
{"op":"mcm","clk":"5353142007","pt":1646209695020,"mc":[{"id":"1.195453765","rc":[{"atl":[[3.75,45.45]],"id":41207262}],"con":true,"img":false}]}
{"op":"mcm","clk":"5353142381","pt":1646209701184,"mc":[{"id":"1.195453765","rc":[{"atb":[[2.8,0],[2.78,47.99]],"id":36386524}],"con":true,"img":false}]}
{"op":"mcm","clk":"5353142945","pt":1646209711195,"mc":[{"id":"1.195453765","rc":[{"atb":[[2.74,28.74]],"id":36386524}],"con":true,"img":false}]}
{"op":"mcm","clk":"5353143396","pt":1646209719585,"mc":[{"id":"1.195453765","rc":[{"atb":[[1.87,0]],"id":43167130}],"con":true,"img":false}]}
{"op":"mcm","clk":"5353143399","pt":1646209719687,"mc":[{"id":"1.195453765","rc":[{"atb":[[1.99,75.32]],"id":43167130}],"con":true,"img":false}]}
{"op":"mcm","clk":"5353143479","pt":1646209721233,"mc":[{"id":"1.195453765","rc":[{"atb":[[2.72,0],[2.68,0],[2.76,0],[2.7,44.12]],"id":36386524}],"con":true,"img":false}]}
{"op":"mcm","clk":"5353143643","pt":1646209724635,"mc":[{"id":"1.195453765","rc":[{"spn":2.78,"spf":"NaN","id":41207262},{"atb":[[2.78,11.24]],"id":36386524}],"con":true,"img":false}]}
{"op":"mcm","clk":"5353143648","pt":1646209724734,"mc":[{"id":"1.195453765","rc":[{"atb":[[2.76,36.75]],"id":36386524}],"con":true,"img":false}]}
{"op":"mcm","clk":"5353143987","pt":1646209731254,"mc":[{"id":"1.195453765","rc":[{"atb":[[2.66,75.3]],"id":36386524}],"con":true,"img":false}]}
{"op":"mcm","clk":"5353143992","pt":1646209731360,"mc":[{"id":"1.195453765","rc":[{"atb":[[2,0],[1.98,144.06]],"id":41207262},{"atb":[[3,10]],"id":36386524}],"con":true,"img":false}]}
{"op":"mcm","clk":"5353144520","pt":1646209741364,"mc":[{"id":"1.195453765","rc":[{"atb":[[1.96,52.08]],"id":41207262},{"atb":[[2.74,0],[2.66,0],[2.96,87.33],[2.78,0],[2.7,0]],"id":36386524}],"con":true,"img":false}]}
{"op":"mcm","clk":"5353144699","pt":1646209744630,"mc":[{"id":"1.195453765","rc":[{"atb":[[2.76,0]],"id":36386524}],"con":true,"img":false}]}
{"op":"mcm","clk":"5353144704","pt":1646209744740,"mc":[{"id":"1.195453765","rc":[{"atb":[[2.5,36.75]],"id":36386524}],"con":true,"img":false}]}
{"op":"mcm","clk":"5353145036","pt":1646209751343,"mc":[{"id":"1.195453765","rc":[{"atb":[[1.94,79.78]],"id":41207262},{"atb":[[2.92,39.06]],"id":36386524}],"con":true,"img":false}]}
{"op":"mcm","clk":"5353145217","pt":1646209754985,"mc":[{"id":"1.195453765","rc":[{"atb":[[1.98,123.65],[1.94,21.27]],"id":41207262},{"atb":[[3.2,17.98]],"id":36386524}],"con":true,"img":false}]}
{"op":"mcm","clk":"5353145690","pt":1646209764996,"mc":[{"id":"1.195453765","rc":[{"atb":[[1.92,54.35],[1.96,0]],"id":41207262},{"atb":[[3.1,23.81]],"id":36386524}],"con":true,"img":false}]}
{"op":"mcm","clk":"5353146109","pt":1646209772996,"mc":[{"id":"1.195453765","rc":[{"atb":[[1.98,144.06]],"id":41207262},{"atb":[[3.2,8.89]],"id":36386524}],"con":true,"img":false}]}
{"op":"mcm","clk":"5353146220","pt":1646209775002,"mc":[{"id":"1.195453765","rc":[{"atb":[[2.88,66.49],[3.1,0]],"id":36386524}],"con":true,"img":false}]}
{"op":"mcm","clk":"5353146583","pt":1646209783033,"mc":[{"id":"1.195453765","rc":[{"atb":[[1.96,52.08]],"id":41207262}],"con":true,"img":false}]}
{"op":"mcm","clk":"5353147131","pt":1646209793028,"mc":[{"id":"1.195453765","rc":[{"atb":[[1.94,79.78]],"id":41207262}],"con":true,"img":false}]}
{"op":"mcm","clk":"5353147323","pt":1646209796737,"mc":[{"id":"1.195453765","rc":[{"atb":[[2,20],[1.98,123.65]],"id":41207262},{"atb":[[2.9,10.53],[3,0]],"id":36386524}],"con":true,"img":false}]}
{"op":"mcm","clk":"5353147597","pt":1646209801765,"mc":[{"id":"1.195453765","rc":[{"atb":[[2.16,2.17]],"id":41207262},{"atb":[[2.38,2.17]],"id":43167130},{"atb":[[2.4,2.17]],"id":40209251}],"con":true,"img":false}]}
{"op":"mcm","clk":"5353147604","pt":1646209801869,"mc":[{"id":"1.195453765","rc":[{"atb":[[2.02,19.32]],"id":41207262},{"atb":[[2.2,19.18]],"id":43167130},{"atb":[[1.24,65.87]],"id":42401236}],"con":true,"img":false}]}
{"op":"mcm","clk":"5353147633","pt":1646209802339,"mc":[{"id":"1.195453765","rc":[{"atb":[[2.12,0]],"id":41207262},{"atb":[[2.34,0]],"id":43167130},{"atb":[[2.36,0]],"id":40209251}],"con":true,"img":false}]}
{"op":"mcm","clk":"5353147650","pt":1646209802543,"mc":[{"id":"1.195453765","rc":[{"atb":[[2.18,1.67]],"id":41207262},{"atb":[[2.4,1.67]],"id":43167130},{"atb":[[2.42,1.67]],"id":40209251}],"con":true,"img":false}]}
{"op":"mcm","clk":"5353147892","pt":1646209806346,"mc":[{"id":"1.195453765","rc":[{"atb":[[2.02,0]],"id":41207262},{"atb":[[2.2,0]],"id":43167130}],"con":true,"img":false}]}
{"op":"mcm","clk":"5353147905","pt":1646209806758,"mc":[{"id":"1.195453765","rc":[{"atb":[[1.98,174.67]],"id":41207262},{"atb":[[2.86,92.02],[2.96,61.82]],"id":36386524}],"con":true,"img":false}]}
{"op":"mcm","clk":"5353148035","pt":1646209809560,"mc":[{"id":"1.195453765","rc":[{"atb":[[1.93,200.71],[1.76,0]],"id":41207262}],"con":true,"img":false}]}
{"op":"mcm","clk":"5353148132","pt":1646209811464,"mc":[{"id":"1.195453765","rc":[{"atb":[[2.12,3.84]],"id":41207262},{"atb":[[2.28,4.99]],"id":43167130}],"con":true,"img":false}]}
{"op":"mcm","clk":"5353148426","pt":1646209816783,"mc":[{"id":"1.195453765","rc":[{"atb":[[1.96,130.2]],"id":41207262},{"atb":[[2.82,41.21],[2.92,0]],"id":36386524}],"con":true,"img":false}]}
{"op":"mcm","clk":"5353148431","pt":1646209816887,"mc":[{"id":"1.195453765","rc":[{"atb":[[1.92,0],[1.96,78.12]],"id":41207262}],"con":true,"img":false}]}
{"op":"mcm","clk":"5353148559","pt":1646209819568,"mc":[{"id":"1.195453765","rc":[{"atb":[[1.93,130.3],[1.76,86.24]],"id":41207262}],"con":true,"img":false}]}
{"op":"mcm","clk":"5353148943","pt":1646209826788,"mc":[{"id":"1.195453765","rc":[{"atb":[[1.94,212.76]],"id":41207262},{"atb":[[2.78,70.22]],"id":36386524}],"con":true,"img":false}]}
{"op":"mcm","clk":"5353148946","pt":1646209826890,"mc":[{"id":"1.195453765","rc":[{"atb":[[1.94,132.97]],"id":41207262}],"con":true,"img":false}]}
{"op":"mcm","clk":"5353149466","pt":1646209836896,"mc":[{"id":"1.195453765","rc":[{"atb":[[2.88,0]],"id":36386524}],"con":true,"img":false}]}
{"op":"mcm","clk":"5353150677","pt":1646209859523,"mc":[{"id":"1.195453765","rc":[{"spn":2.81,"spf":"NaN","id":41207262},{"spn":3.0,"spf":"NaN","id":43167130},{"spn":1.76,"spf":"NaN","id":42401236},{"spn":3.06,"spf":"NaN","id":40209251},{"atb":[[2.5,0],[2.84,29.96]],"id":36386524}],"con":true,"img":false}]}
{"op":"mcm","clk":"5353153936","pt":1646209922996,"mc":[{"id":"1.195453765","rc":[{"atb":[[2,0]],"id":41207262},{"atl":[[3.6,0],[3.8,7.14]],"id":43167130},{"spn":3.05,"spf":"NaN","id":43167130},{"atb":[[3.3,8.7]],"id":36386524},{"spn":4.95,"spf":"NaN","id":36386524}],"con":true,"img":false}]}
{"op":"mcm","clk":"5353153943","pt":1646209923143,"mc":[{"id":"1.195453765","rc":[{"atb":[[2.06,76.03],[1.91,88.22]],"id":41207262},{"atl":[[3.45,0],[9,0],[4.1,32.26],[3.8,7.14],[3.55,0],[3.65,0],[3.75,0]],"id":41207262},{"atb":[[1.89,112.36],[1.07,0]],"id":43167130},{"atl":[[5.1,24.39],[3.7,0],[9.4,0]],"id":43167130},{"atb":[[1.25,90.91]],"id":42401236},{"atb":[[1.1,0],[2.1,204.55]],"id":40209251},{"atl":[[5.1,24.39],[3.85,7.02],[3.7,0],[9.8,0]],"id":40209251},{"atb":[[2.5,0],[4.2,31.25]],"id":43167131},{"atl":[[95,2.29]],"id":36010178},{"atb":[[2.9,0],[3.25,8.89]],"id":36386524},{"atl":[[17,0],[7,16.66]],"id":36386524}],"con":true,"img":false}]}
{"op":"mcm","clk":"5353153952","pt":1646209923202,"mc":[{"id":"1.195453765","rc":[{"atb":[[3.3,0]],"id":36386524}],"con":true,"img":false}]}
{"op":"mcm","clk":"5353153959","pt":1646209923304,"mc":[{"id":"1.195453765","rc":[{"atl":[[3.75,7.27]],"id":41207262}],"con":true,"img":false}]}
{"op":"mcm","clk":"5353154104","pt":1646209926029,"mc":[{"id":"1.195453765","rc":[{"atb":[[2.28,0]],"id":43167130},{"atb":[[1.24,0]],"id":42401236}],"con":true,"img":false}]}
{"op":"mcm","clk":"5353154218","pt":1646209928304,"mc":[{"id":"1.195453765","rc":[{"atb":[[1.25,0],[1.24,181.82]],"id":42401236}],"con":true,"img":false}]}
{"op":"mcm","clk":"5353154221","pt":1646209928405,"mc":[{"id":"1.195453765","rc":[{"atb":[[3.2,7.22]],"id":36386524}],"con":true,"img":false}]}
{"op":"mcm","clk":"5353154230","pt":1646209928607,"mc":[{"id":"1.195453765","rc":[{"atb":[[3.3,1.67]],"id":36386524}],"con":true,"img":false}]}
{"op":"mcm","clk":"5353154287","pt":1646209929634,"mc":[{"id":"1.195453765","rc":[{"atb":[[17,0]],"id":36010178}],"con":true,"img":false}]}
{"op":"mcm","clk":"5353154294","pt":1646209929692,"mc":[{"id":"1.195453765","rc":[{"atb":[[13,2.72]],"id":36010178}],"con":true,"img":false}]}
{"op":"mcm","clk":"5353154352","pt":1646209930722,"mc":[{"id":"1.195453765","rc":[{"atb":[[2.28,4.99]],"id":43167130},{"atb":[[1.26,63.63]],"id":42401236}],"con":true,"img":false}]}
{"op":"mcm","clk":"5353154471","pt":1646209933036,"mc":[{"id":"1.195453765","rc":[{"atl":[[3.9,17.24]],"id":43167130},{"atl":[[3.95,16.95]],"id":40209251},{"atb":[[3.15,51.44]],"id":36386524}],"con":true,"img":false}]}
{"op":"mcm","clk":"5353154484","pt":1646209933298,"mc":[{"id":"1.195453765","rc":[{"atb":[[2.02,49.02]],"id":41207262},{"atl":[[3.85,17.54]],"id":41207262}],"con":true,"img":false}]}
{"op":"mcm","clk":"5353154504","pt":1646209933811,"mc":[{"id":"1.195453765","rc":[{"atb":[[1.24,0]],"id":42401236}],"con":true,"img":false}]}
{"op":"mcm","clk":"5353154510","pt":1646209933912,"mc":[{"id":"1.195453765","rc":[{"atb":[[1.26,157.74]],"id":42401236}],"con":true,"img":false}]}
{"op":"mcm","clk":"5353154558","pt":1646209934835,"mc":[{"id":"1.195453765","rc":[{"atb":[[1.98,123.65],[1.96,0],[1.94,0]],"id":41207262},{"atb":[[2.78,0]],"id":36386524}],"con":true,"img":false}]}
{"op":"mcm","clk":"5353154731","pt":1646209937936,"mc":[{"id":"1.195453765","rc":[{"atb":[[1.26,94.11]],"id":42401236}],"con":true,"img":false}]}
{"op":"mcm","clk":"5353154740","pt":1646209938130,"mc":[{"id":"1.195453765","rc":[{"atb":[[1.29,25.94]],"id":42401236}],"con":true,"img":false}]}
{"op":"mcm","clk":"5353154978","pt":1646209942728,"mc":[{"id":"1.195453765","rc":[{"atb":[[1.24,33.72]],"id":42401236}],"con":true,"img":false}]}
{"op":"mcm","clk":"5353154996","pt":1646209943044,"mc":[{"id":"1.195453765","rc":[{"atl":[[4,25]],"id":43167130},{"atl":[[4.1,24.19]],"id":40209251},{"atb":[[3.05,36.59]],"id":36386524}],"con":true,"img":false}]}
{"op":"mcm","clk":"5353155014","pt":1646209943351,"mc":[{"id":"1.195453765","rc":[{"atb":[[1.99,119.87]],"id":41207262},{"atl":[[3.95,25.42]],"id":41207262}],"con":true,"img":false}]}
{"op":"mcm","clk":"5353155078","pt":1646209944543,"mc":[{"id":"1.195453765","rc":[{"atl":[[5.2,2.88],[3.9,15.06]],"id":41207262},{"atl":[[5.7,0]],"id":43167130},{"atl":[[5.8,0]],"id":40209251},{"atl":[[70,0.46],[95,2]],"id":36010178},{"atl":[[7.2,0]],"id":36386524}],"con":true,"img":false}]}
{"op":"mcm","clk":"5353155084","pt":1646209944643,"mc":[{"id":"1.195453765","rc":[{"atl":[[5,9.29]],"id":43167130},{"atl":[[5,9.09]],"id":40209251},{"atl":[[7.4,27.34],[6.8,7.04]],"id":36386524}],"con":true,"img":false}]}
{"op":"mcm","clk":"5353155093","pt":1646209944746,"mc":[{"id":"1.195453765","rc":[{"atl":[[7,8.33]],"id":36386524}],"con":true,"img":false}]}
{"op":"mcm","clk":"5353155315","pt":1646209949534,"mc":[{"id":"1.195453765","rc":[{"atb":[[1.99,75.76]],"id":41207262}],"con":true,"img":false}]}
{"op":"mcm","clk":"5353155322","pt":1646209949639,"mc":[{"id":"1.195453765","rc":[{"atb":[[2.04,44.11]],"id":41207262}],"con":true,"img":false}]}
{"op":"mcm","clk":"5353155485","pt":1646209952468,"mc":[{"id":"1.195453765","rc":[{"atb":[[1.29,54.74]],"id":42401236}],"con":true,"img":false}]}
{"op":"mcm","clk":"5353155526","pt":1646209953041,"mc":[{"id":"1.195453765","rc":[{"atl":[[4.2,39.06]],"id":43167130},{"atl":[[4.3,37.88]],"id":40209251},{"atb":[[2.82,0],[2.98,85.18]],"id":36386524}],"con":true,"img":false}]}
{"op":"mcm","clk":"5353155545","pt":1646209953354,"mc":[{"id":"1.195453765","rc":[{"atb":[[1.97,128.87]],"id":41207262},{"atl":[[4.1,72.58]],"id":41207262}],"con":true,"img":false}]}
{"op":"mcm","clk":"5353155611","pt":1646209954577,"mc":[{"id":"1.195453765","rc":[{"atl":[[3.4,24.16],[3.15,0]],"id":42401236},{"atb":[[2.5,36.75],[2.84,0]],"id":36386524},{"atl":[[6.8,0]],"id":36386524}],"con":true,"img":false}]}
{"op":"mcm","clk":"5353155618","pt":1646209954681,"mc":[{"id":"1.195453765","rc":[{"atl":[[7.2,7.04]],"id":36386524}],"con":true,"img":false}]}
{"op":"mcm","clk":"5353155646","pt":1646209955151,"mc":[{"id":"1.195453765","rc":[{"atl":[[7.4,11.72],[7,16.66]],"id":36386524}],"con":true,"img":false}]}
{"op":"mcm","clk":"5353155801","pt":1646209958790,"mc":[{"id":"1.195453765","rc":[{"atl":[[3.8,0]],"id":41207262},{"atb":[[2,0],[1.98,0],[1.96,0],[1.94,0],[1.92,21.74]],"id":43167130},{"atb":[[3.25,0],[3.3,10.37]],"id":36386524},{"atl":[[6.8,3.45],[6.6,0]],"id":36386524}],"con":true,"img":false}]}
{"op":"mcm","clk":"5353155816","pt":1646209958955,"mc":[{"id":"1.195453765","rc":[{"atl":[[3.85,0],[3.9,6.9]],"id":40209251},{"atb":[[2.86,65.14],[3.15,28.18],[2.98,22.05],[3.05,0]],"id":36386524}],"con":true,"img":false}]}
{"op":"mcm","clk":"5353155849","pt":1646209959568,"mc":[{"id":"1.195453765","rc":[{"atb":[[1.99,0]],"id":43167130}],"con":true,"img":false}]}
{"op":"mcm","clk":"5353155856","pt":1646209959671,"mc":[{"id":"1.195453765","rc":[{"atb":[[1.9,75.32]],"id":43167130}],"con":true,"img":false}]}
{"op":"mcm","clk":"5353155866","pt":1646209959871,"mc":[{"id":"1.195453765","rc":[{"atl":[[4.3,0],[3.95,0],[4.1,0],[3.9,0]],"id":40209251}],"con":true,"img":false}]}
{"op":"mcm","clk":"5353155874","pt":1646209959975,"mc":[{"id":"1.195453765","rc":[{"atb":[[1.79,124.78],[1.91,0]],"id":41207262},{"atl":[[3.45,8.16],[3.85,35.08],[4.1,40.32],[3.75,0]],"id":41207262},{"atb":[[2,20]],"id":43167130},{"atl":[[3.6,7.69],[3.8,0],[4.4,29.41],[3.75,7.27],[5.1,0]],"id":43167130},{"atb":[[1.21,371.41],[1.26,0],[1.22,250]],"id":42401236},{"atb":[[1.46,90.46],[2.1,113.64]],"id":40209251},{"atl":[[5.1,0],[4.9,5.13],[7.8,14.71]],"id":40209251},{"atb":[[4.8,7.38],[4.2,0]],"id":43167131},{"atl":[[38,2.7],[27,0]],"id":43167131},{"atl":[[6.6,3.57]],"id":36386524}],"con":true,"img":false}]}
{"op":"mcm","clk":"5353155878","pt":1646209960078,"mc":[{"id":"1.195453765","rc":[{"atl":[[5.1,12.2],[5.3,17.44],[5.5,27.78]],"id":40209251},{"atl":[[6.8,0]],"id":36386524}],"con":true,"img":false}]}
{"op":"mcm","clk":"5353155902","pt":1646209960490,"mc":[{"id":"1.195453765","rc":[{"atl":[[3.6,0]],"id":43167130}],"con":true,"img":false}]}
{"op":"mcm","clk":"5353155921","pt":1646209960856,"mc":[{"id":"1.195453765","rc":[{"atl":[[100,0]],"id":36010178}],"con":true,"img":false}]}
{"op":"mcm","clk":"5353155927","pt":1646209960957,"mc":[{"id":"1.195453765","rc":[{"atl":[[75,2.72]],"id":36010178}],"con":true,"img":false}]}
{"op":"mcm","clk":"5353155931","pt":1646209961060,"mc":[{"id":"1.195453765","rc":[{"atl":[[70,2.46]],"id":36010178}],"con":true,"img":false}]}
{"op":"mcm","clk":"5353155936","pt":1646209961167,"mc":[{"id":"1.195453765","rc":[{"atl":[[95,0]],"id":36010178}],"con":true,"img":false}]}
{"op":"mcm","clk":"5353155994","pt":1646209962496,"mc":[{"id":"1.195453765","rc":[{"atb":[[1.29,28.79]],"id":42401236}],"con":true,"img":false}]}
{"op":"mcm","clk":"5353156050","pt":1646209963272,"mc":[{"id":"1.195453765","rc":[{"atb":[[2.28,0]],"id":43167130}],"con":true,"img":false}]}
{"op":"mcm","clk":"5353156119","pt":1646209964564,"mc":[{"id":"1.195453765","rc":[{"atb":[[1.76,0]],"id":41207262}],"con":true,"img":false}]}
{"op":"mcm","clk":"5353156125","pt":1646209964666,"mc":[{"id":"1.195453765","rc":[{"atb":[[1.8,86.24]],"id":41207262}],"con":true,"img":false}]}
{"op":"mcm","clk":"5353156287","pt":1646209968057,"mc":[{"id":"1.195453765","rc":[{"atb":[[2.28,4.99]],"id":43167130}],"con":true,"img":false}]}
{"op":"mcm","clk":"5353156378","pt":1646209969595,"mc":[{"id":"1.195453765","rc":[{"atl":[[5,0]],"id":40209251},{"atb":[[11.5,4.15],[13,0],[9.4,3.86]],"id":36010178}],"con":true,"img":false}]}
{"op":"mcm","clk":"5353156384","pt":1646209969698,"mc":[{"id":"1.195453765","rc":[{"atl":[[5.2,9.09]],"id":40209251}],"con":true,"img":false}]}
{"op":"mcm","clk":"5353156392","pt":1646209969861,"mc":[{"id":"1.195453765","rc":[{"atl":[[3.55,19.61]],"id":41207262}],"con":true,"img":false}]}
{"op":"mcm","clk":"5353156402","pt":1646209969965,"mc":[{"id":"1.195453765","rc":[{"atb":[[1.98,51.02]],"id":43167130},{"atb":[[1.19,568.89]],"id":42401236},{"atb":[[3.2,29.95]],"id":36386524}],"con":true,"img":false}]}
{"op":"mcm","clk":"5353156415","pt":1646209970168,"mc":[{"id":"1.195453765","rc":[{"atb":[[1.2,0],[1.18,0],[1.16,0]],"id":42401236}],"con":true,"img":false}]}
{"op":"mcm","clk":"5353156431","pt":1646209970376,"mc":[{"id":"1.195453765","rc":[{"atb":[[1.22,340.91]],"id":42401236},{"atb":[[1.46,0],[1.74,90.46]],"id":40209251},{"atl":[[6.8,17.24],[7.8,0]],"id":40209251}],"con":true,"img":false}]}
{"op":"mcm","clk":"5353156438","pt":1646209970479,"mc":[{"id":"1.195453765","rc":[{"atl":[[4.1,0]],"id":41207262}],"con":true,"img":false}]}
{"op":"mcm","clk":"5353156472","pt":1646209971301,"mc":[{"id":"1.195453765","rc":[{"atb":[[3.2,26.53]],"id":36386524}],"con":true,"img":false}]}
{"op":"mcm","clk":"5353156775","pt":1646209977086,"mc":[{"id":"1.195453765","rc":[{"atb":[[3.25,3.34]],"id":36386524}],"con":true,"img":false}]}
{"op":"mcm","clk":"5353156813","pt":1646209977808,"mc":[{"id":"1.195453765","rc":[{"atb":[[1.29,0]],"id":42401236}],"con":true,"img":false}]}
{"op":"mcm","clk":"5353156923","pt":1646209979876,"mc":[{"id":"1.195453765","rc":[{"atl":[[3.65,28.3]],"id":41207262}],"con":true,"img":false}]}
{"op":"mcm","clk":"5353156927","pt":1646209979978,"mc":[{"id":"1.195453765","rc":[{"atl":[[3.85,17.54],[3.65,56.07]],"id":41207262},{"atb":[[1.96,78.12]],"id":43167130},{"atb":[[3.1,35.71]],"id":36386524}],"con":true,"img":false}]}
{"op":"mcm","clk":"5353156935","pt":1646209980082,"mc":[{"id":"1.195453765","rc":[{"atl":[[3.45,0],[3.85,0],[3.95,0],[3.4,8.33],[3.55,0],[3.65,27.77]],"id":41207262}],"con":true,"img":false}]}
{"op":"mcm","clk":"5353156941","pt":1646209980186,"mc":[{"id":"1.195453765","rc":[{"atl":[[3.45,16.66]],"id":41207262},{"atb":[[3,4]],"id":40209251}],"con":true,"img":false}]}
{"op":"mcm","clk":"5353156949","pt":1646209980288,"mc":[{"id":"1.195453765","rc":[{"atl":[[3.65,0]],"id":41207262},{"atb":[[2.04,3]],"id":43167130}],"con":true,"img":false}]}
{"op":"mcm","clk":"5353156953","pt":1646209980392,"mc":[{"id":"1.195453765","rc":[{"atb":[[1.2,250]],"id":42401236},{"atb":[[3.05,4]],"id":40209251}],"con":true,"img":false}]}
{"op":"mcm","clk":"5353157023","pt":1646209981473,"mc":[{"id":"1.195453765","rc":[{"atb":[[1.24,0]],"id":42401236}],"con":true,"img":false}]}
{"op":"mcm","clk":"5353157067","pt":1646209982301,"mc":[{"id":"1.195453765","rc":[{"atb":[[2.06,118.31]],"id":43167130}],"con":true,"img":false}]}
{"op":"mcm","clk":"5353157079","pt":1646209982508,"mc":[{"id":"1.195453765","rc":[{"atb":[[2.08,4]],"id":43167130},{"atb":[[3.1,3]],"id":40209251}],"con":true,"img":false}]}
{"op":"mcm","clk":"5353157131","pt":1646209983188,"mc":[{"id":"1.195453765","rc":[{"spn":2.79,"spf":"NaN","id":41207262},{"spn":3.07,"spf":"NaN","id":43167130},{"spn":1.75,"spf":"NaN","id":42401236},{"atb":[[2.34,6.23]],"id":40209251},{"spn":4.0,"spf":"NaN","id":40209251},{"spn":28.75,"spf":"NaN","id":36010178}],"con":true,"img":false}]}
{"op":"mcm","clk":"5353157200","pt":1646209984372,"mc":[{"id":"1.195453765","rc":[{"atb":[[2.42,0]],"id":40209251}],"con":true,"img":false}]}
{"op":"mcm","clk":"5353157206","pt":1646209984477,"mc":[{"id":"1.195453765","rc":[{"atl":[[5.8,9.09],[3.9,0]],"id":41207262},{"atl":[[4.3,13.23],[5,0]],"id":43167130},{"atl":[[70,2]],"id":36010178}],"con":true,"img":false}]}
{"op":"mcm","clk":"5353157210","pt":1646209984579,"mc":[{"id":"1.195453765","rc":[{"atl":[[60,0.46]],"id":36010178}],"con":true,"img":false}]}
{"op":"mcm","clk":"5353157250","pt":1646209985300,"mc":[{"id":"1.195453765","rc":[{"atl":[[3.45,0],[5.1,24.39]],"id":41207262}],"con":true,"img":false}]}
{"op":"mcm","clk":"5353157313","pt":1646209986537,"mc":[{"id":"1.195453765","rc":[{"atb":[[1.24,65.87]],"id":42401236}],"con":true,"img":false}]}
{"op":"mcm","clk":"5353157483","pt":1646209990006,"mc":[{"id":"1.195453765","rc":[{"atb":[[1.94,132.98]],"id":43167130},{"atb":[[3,62.5]],"id":36386524}],"con":true,"img":false}]}
{"op":"mcm","clk":"5353157487","pt":1646209990106,"mc":[{"id":"1.195453765","rc":[{"atl":[[3.5,20]],"id":41207262}],"con":true,"img":false}]}
{"op":"mcm","clk":"5353157492","pt":1646209990211,"mc":[{"id":"1.195453765","rc":[{"atb":[[1.92,0]],"id":43167130},{"atb":[[3.15,4]],"id":40209251}],"con":true,"img":false}]}
{"op":"mcm","clk":"5353157498","pt":1646209990313,"mc":[{"id":"1.195453765","rc":[{"atb":[[2.1,2]],"id":43167130}],"con":true,"img":false}]}
{"op":"mcm","clk":"5353157504","pt":1646209990415,"mc":[{"id":"1.195453765","rc":[{"atb":[[1.18,250]],"id":42401236}],"con":true,"img":false}]}
{"op":"mcm","clk":"5353157908","pt":1646209997324,"mc":[{"id":"1.195453765","rc":[{"atb":[[1.21,276.17],[1.19,318.89]],"id":42401236}],"con":true,"img":false}]}
{"op":"mcm","clk":"5353158067","pt":1646210000114,"mc":[{"id":"1.195453765","rc":[{"atl":[[3.6,28.85]],"id":41207262}],"con":true,"img":false}]}
{"op":"mcm","clk":"5353158073","pt":1646210000216,"mc":[{"id":"1.195453765","rc":[{"atl":[[3.6,57.18],[5.1,0]],"id":41207262}],"con":true,"img":false}]}
{"op":"mcm","clk":"5353158081","pt":1646210000420,"mc":[{"id":"1.195453765","rc":[{"atb":[[1.16,250]],"id":42401236}],"con":true,"img":false}]}
{"op":"mcm","clk":"5353158179","pt":1646210001711,"mc":[{"id":"1.195453765","rc":[{"atb":[[3,0],[3.2,3]],"id":40209251},{"atb":[[3.25,12.23],[3.3,1.67]],"id":36386524},{"atl":[[6.4,3.7],[6.6,0]],"id":36386524}],"con":true,"img":false}]}
{"op":"mcm","clk":"5353158205","pt":1646210002121,"mc":[{"id":"1.195453765","rc":[{"atb":[[2.34,0]],"id":40209251}],"con":true,"img":false}]}
{"op":"mcm","clk":"5353158315","pt":1646210004543,"mc":[{"id":"1.195453765","rc":[{"atb":[[1.9,0]],"id":43167130},{"atl":[[3.4,0]],"id":42401236},{"atb":[[3.1,0],[3.05,0],[3.2,0],[3.15,0]],"id":40209251},{"atl":[[75,0]],"id":36010178}],"con":true,"img":false}]}
{"op":"mcm","clk":"5353158321","pt":1646210004646,"mc":[{"id":"1.195453765","rc":[{"atb":[[1.84,105.51],[1.79,0]],"id":41207262},{"atl":[[3.45,8.16],[3.4,0]],"id":41207262},{"atb":[[2.04,0],[2.1,0],[2.08,0],[1.99,75.32],[2.06,114.31]],"id":43167130},{"atb":[[1.21,552.34],[1.22,90.91]],"id":42401236},{"atl":[[3.15,24.16]],"id":42401236},{"atb":[[1.74,0],[1.66,84.74]],"id":40209251},{"atl":[[5.1,4.88],[4.9,0]],"id":40209251},{"atl":[[65,2.72]],"id":36010178}],"con":true,"img":false}]}
{"op":"mcm","clk":"5353158331","pt":1646210004803,"mc":[{"id":"1.195453765","rc":[{"atl":[[60,2.46]],"id":36010178}],"con":true,"img":false}]}
{"op":"mcm","clk":"5353158339","pt":1646210004904,"mc":[{"id":"1.195453765","rc":[{"atl":[[70,0]],"id":36010178}],"con":true,"img":false}]}
{"op":"mcm","clk":"5353158366","pt":1646210005317,"mc":[{"id":"1.195453765","rc":[{"atb":[[2.42,1.67]],"id":40209251}],"con":true,"img":false}]}
{"op":"mcm","clk":"5353158592","pt":1646210010040,"mc":[{"id":"1.195453765","rc":[{"atl":[[7.2,1.95]],"id":40209251},{"atb":[[2.98,0]],"id":36386524}],"con":true,"img":false}]}
{"op":"mcm","clk":"5353158594","pt":1646210010142,"mc":[{"id":"1.195453765","rc":[{"atl":[[3.5,40]],"id":41207262},{"atl":[[6.6,10.37]],"id":40209251},{"atb":[[3.05,22.05]],"id":36386524}],"con":true,"img":false}]}
{"op":"mcm","clk":"5353158598","pt":1646210010245,"mc":[{"id":"1.195453765","rc":[{"atl":[[3.6,28.85]],"id":41207262}],"con":true,"img":false}]}
{"op":"mcm","clk":"5353158684","pt":1646210011742,"mc":[{"id":"1.195453765","rc":[{"atb":[[3.15,51.44]],"id":36386524}],"con":true,"img":false}]}
{"op":"mcm","clk":"5353158706","pt":1646210012051,"mc":[{"id":"1.195453765","rc":[{"atb":[[3.2,3.8],[3.1,0],[3,0]],"id":36386524}],"con":true,"img":false}]}
{"op":"mcm","clk":"5353158734","pt":1646210012418,"mc":[{"id":"1.195453765","rc":[{"atb":[[2.34,5.61]],"id":40209251},{"atb":[[3.25,8.89]],"id":36386524}],"con":true,"img":false}]}
{"op":"mcm","clk":"5353158877","pt":1646210014630,"mc":[{"id":"1.195453765","rc":[{"atl":[[3.55,19.61]],"id":41207262},{"atl":[[5.3,11.63]],"id":40209251}],"con":true,"img":false}]}
{"op":"mcm","clk":"5353158897","pt":1646210015243,"mc":[{"id":"1.195453765","rc":[{"atl":[[3.55,58.83],[3.5,20]],"id":41207262}],"con":true,"img":false}]}
{"op":"mcm","clk":"5353158933","pt":1646210016015,"mc":[{"id":"1.195453765","rc":[{"atl":[[5.8,0]],"id":41207262}],"con":true,"img":false}]}
{"op":"mcm","clk":"5353158938","pt":1646210016117,"mc":[{"id":"1.195453765","rc":[{"atl":[[5.3,9.09]],"id":41207262}],"con":true,"img":false}]}
{"op":"mcm","clk":"5353158947","pt":1646210016220,"mc":[{"id":"1.195453765","rc":[{"atl":[[3.45,0],[3.4,8.33]],"id":41207262}],"con":true,"img":false}]}
{"op":"mcm","clk":"5353158964","pt":1646210016530,"mc":[{"id":"1.195453765","rc":[{"atl":[[3.7,7.41]],"id":43167130},{"atb":[[2.32,15.15],[2.22,0]],"id":40209251},{"atb":[[4.5,0]],"id":43167131},{"atl":[[200,1],[210,0]],"id":36010178},{"atl":[[6.4,0],[6.2,3.85]],"id":36386524}],"con":true,"img":false}]}
{"op":"mcm","clk":"5353158969","pt":1646210016631,"mc":[{"id":"1.195453765","rc":[{"atl":[[3.75,0]],"id":43167130},{"atb":[[4.9,5.13]],"id":43167131}],"con":true,"img":false}]}
{"op":"mcm","clk":"5353159070","pt":1646210018227,"mc":[{"id":"1.195453765","rc":[{"atl":[[3.45,8.16],[3.4,0]],"id":41207262}],"con":true,"img":false}]}
{"op":"mcm","clk":"5353159090","pt":1646210018535,"mc":[{"id":"1.195453765","rc":[{"atb":[[3.2,7.22]],"id":36386524}],"con":true,"img":false}]}
{"op":"mcm","clk":"5353159138","pt":1646210019413,"mc":[{"id":"1.195453765","rc":[{"atb":[[4.8,5.71]],"id":43167131}],"con":true,"img":false}]}
{"op":"mcm","clk":"5353159153","pt":1646210019645,"mc":[{"id":"1.195453765","rc":[{"atb":[[5,1.67]],"id":43167131}],"con":true,"img":false}]}
{"op":"mcm","clk":"5353159162","pt":1646210019822,"mc":[{"id":"1.195453765","rc":[{"atb":[[4.8,0],[5,6.8]],"id":43167131}],"con":true,"img":false}]}
{"op":"mcm","clk":"5353159168","pt":1646210019924,"mc":[{"id":"1.195453765","rc":[{"atb":[[4.8,10.4]],"id":43167131},{"atb":[[3.05,0]],"id":36386524}],"con":true,"img":false}]}
{"op":"mcm","clk":"5353159172","pt":1646210020028,"mc":[{"id":"1.195453765","rc":[{"atb":[[2.28,0]],"id":43167130},{"atb":[[5,1.67]],"id":43167131},{"atb":[[2.98,22.05]],"id":36386524}],"con":true,"img":false}]}
{"op":"mcm","clk":"5353159177","pt":1646210020131,"mc":[{"id":"1.195453765","rc":[{"atb":[[4.8,0],[5,8.47]],"id":43167131}],"con":true,"img":false}]}
{"op":"mcm","clk":"5353159260","pt":1646210022037,"mc":[{"id":"1.195453765","rc":[{"atl":[[5.2,0]],"id":40209251}],"con":true,"img":false}]}
{"op":"mcm","clk":"5353159266","pt":1646210022140,"mc":[{"id":"1.195453765","rc":[{"atl":[[5.4,9.09]],"id":40209251}],"con":true,"img":false}]}
{"op":"mcm","clk":"5353159294","pt":1646210022653,"mc":[{"id":"1.195453765","rc":[{"atb":[[2.28,4.99]],"id":43167130}],"con":true,"img":false}]}
{"op":"mcm","clk":"5353159436","pt":1646210026046,"mc":[{"id":"1.195453765","rc":[{"atb":[[2.08,0]],"id":40209251},{"atl":[[7.2,0]],"id":36386524}],"con":true,"img":false}]}
{"op":"mcm","clk":"5353159441","pt":1646210026148,"mc":[{"id":"1.195453765","rc":[{"atb":[[2.12,60.04]],"id":40209251},{"atl":[[6.8,7.04]],"id":36386524}],"con":true,"img":false}]}
{"op":"mcm","clk":"5353159446","pt":1646210026252,"mc":[{"id":"1.195453765","rc":[{"atl":[[7.4,27.34],[7,8.33]],"id":36386524}],"con":true,"img":false}]}
{"op":"mcm","clk":"5353159452","pt":1646210026358,"mc":[{"id":"1.195453765","rc":[{"atl":[[6.6,8.33]],"id":36386524}],"con":true,"img":false}]}
{"op":"mcm","clk":"5353159459","pt":1646210026458,"mc":[{"id":"1.195453765","rc":[{"atl":[[7.4,11.72]],"id":36386524}],"con":true,"img":false}]}
{"op":"mcm","clk":"5353159463","pt":1646210026564,"mc":[{"id":"1.195453765","rc":[{"atl":[[3.8,17.86]],"id":43167130},{"atb":[[2.28,76.06]],"id":40209251},{"atl":[[5.5,16.67]],"id":40209251},{"atb":[[4.7,23.9]],"id":43167131},{"atb":[[3.05,36.59]],"id":36386524},{"atl":[[6.6,17.26]],"id":36386524}],"con":true,"img":false}]}
{"op":"mcm","clk":"5353159540","pt":1646210027956,"mc":[{"id":"1.195453765","rc":[{"atl":[[55,0.59],[60,2]],"id":36010178}],"con":true,"img":false}]}
{"op":"mcm","clk":"5353159556","pt":1646210028262,"mc":[{"id":"1.195453765","rc":[{"atl":[[3.65,28.3]],"id":41207262}],"con":true,"img":false}]}
{"op":"mcm","clk":"5353159644","pt":1646210029559,"mc":[{"id":"1.195453765","rc":[{"atb":[[2.28,0]],"id":43167130},{"atb":[[2.34,11.84]],"id":40209251}],"con":true,"img":false}]}
{"op":"mcm","clk":"5353159945","pt":1646210034358,"mc":[{"id":"1.195453765","rc":[{"atb":[[2.28,4.99]],"id":43167130}],"con":true,"img":false}]}
{"op":"mcm","clk":"5353160029","pt":1646210036061,"mc":[{"id":"1.195453765","rc":[{"atl":[[6.8,0]],"id":36386524}],"con":true,"img":false}]}
{"op":"mcm","clk":"5353160036","pt":1646210036162,"mc":[{"id":"1.195453765","rc":[{"atl":[[7.2,7.04]],"id":36386524}],"con":true,"img":false}]}
{"op":"mcm","clk":"5353160040","pt":1646210036265,"mc":[{"id":"1.195453765","rc":[{"atl":[[7,25]],"id":36386524}],"con":true,"img":false}]}
{"op":"mcm","clk":"5353160045","pt":1646210036367,"mc":[{"id":"1.195453765","rc":[{"atl":[[6.6,8.93]],"id":36386524}],"con":true,"img":false}]}
{"op":"mcm","clk":"5353160058","pt":1646210036573,"mc":[{"id":"1.195453765","rc":[{"atb":[[2.14,0],[2.1,0],[2.24,60.48],[2.18,0]],"id":40209251},{"atl":[[5.7,26.6]],"id":40209251},{"atb":[[4.5,21.43],[3.95,0]],"id":43167131}],"con":true,"img":false}]}
{"op":"mcm","clk":"5353160067","pt":1646210036674,"mc":[{"id":"1.195453765","rc":[{"atl":[[3.9,25.86],[4.2,0]],"id":43167130},{"atb":[[2.98,85.18]],"id":36386524},{"atl":[[7,29.17],[7.8,0]],"id":36386524}],"con":true,"img":false}]}
{"op":"mcm","clk":"5353160135","pt":1646210037962,"mc":[{"id":"1.195453765","rc":[{"atb":[[2.12,0]],"id":40209251}],"con":true,"img":false}]}
{"op":"mcm","clk":"5353160139","pt":1646210038063,"mc":[{"id":"1.195453765","rc":[{"atb":[[2.08,60.04]],"id":40209251}],"con":true,"img":false}]}
{"op":"mcm","clk":"5353160149","pt":1646210038267,"mc":[{"id":"1.195453765","rc":[{"atl":[[3.6,0],[3.5,0],[3.75,45.45]],"id":41207262}],"con":true,"img":false}]}
{"op":"mcm","clk":"5353160173","pt":1646210038637,"mc":[{"id":"1.195453765","rc":[{"atl":[[3.65,66.04]],"id":41207262}],"con":true,"img":false}]}
{"op":"mcm","clk":"5353160179","pt":1646210038732,"mc":[{"id":"1.195453765","rc":[{"atl":[[3.55,19.61]],"id":41207262}],"con":true,"img":false}]}
{"op":"mcm","clk":"5353160190","pt":1646210038966,"mc":[{"id":"1.195453765","rc":[{"atb":[[2.28,0]],"id":43167130}],"con":true,"img":false}]}
{"op":"mcm","clk":"5353160242","pt":1646210039942,"mc":[{"id":"1.195453765","rc":[{"atl":[[6.6,0]],"id":40209251}],"con":true,"img":false}]}
{"op":"mcm","clk":"5353160248","pt":1646210040053,"mc":[{"id":"1.195453765","rc":[{"atl":[[7.8,10.37]],"id":40209251}],"con":true,"img":false}]}
{"op":"mcm","clk":"5353160323","pt":1646210041694,"mc":[{"id":"1.195453765","rc":[{"atb":[[1.98,0],[1.93,0],[2.06,18.87]],"id":41207262},{"atl":[[16,0],[6.4,14.19],[11,0],[5.2,0],[8.4,0]],"id":41207262},{"atb":[[2.26,0],[2.06,0],[2.16,0]],"id":43167130},{"atl":[[5.6,0],[7.2,0],[18,0],[9.2,0],[13,0]],"id":43167130},{"atb":[[1.19,0],[1.14,0],[1.09,0]],"id":42401236},{"atl":[[2.88,0],[3.2,0],[2.28,0],[2.68,0],[2.48,0]],"id":42401236},{"atb":[[2.06,0],[2.26,0],[2.16,0]],"id":40209251},{"atl":[[5.6,0],[7.2,0],[18,0],[9.2,0],[13,0]],"id":40209251},{"atb":[[4.3,15.15],[3.9,0],[3.65,0]],"id":43167131},{"atl":[[32,0],[21,0],[55,0],[110,0],[15.5,0]],"id":43167131},{"atb":[[8.6,0],[7.6,0],[6.6,0]],"id":36010178},{"atl":[[280,0],[90,0],[180,0],[46,0],[380,0]],"id":36010178},{"atb":[[2.86,0],[3.15,23.26],[2.96,0]],"id":36386524},{"atl":[[16,0],[34,0],[11,0],[22,0],[8.4,0]],"id":36386524}],"con":true,"img":false}]}
{"op":"mcm","clk":"5353160333","pt":1646210041851,"mc":[{"id":"1.195453765","rc":[{"atl":[[32,3.23],[38,0]],"id":43167131}],"con":true,"img":false}]}
{"op":"mcm","clk":"5353160336","pt":1646210041955,"mc":[{"id":"1.195453765","rc":[{"atb":[[2.18,0]],"id":43167130},{"atb":[[4.1,0]],"id":43167131},{"atb":[[2.08,0]],"id":40209251}],"con":true,"img":false}]}
{"op":"mcm","clk":"5353160339","pt":1646210042058,"mc":[{"id":"1.195453765","rc":[{"atb":[[2.06,37]],"id":43167130},{"atb":[[1.96,60.04]],"id":40209251}],"con":true,"img":false}]}
{"op":"mcm","clk":"5353160347","pt":1646210042161,"mc":[{"id":"1.195453765","rc":[{"atl":[[3.4,8.33]],"id":41207262}],"con":true,"img":false}]}
{"op":"mcm","clk":"5353160353","pt":1646210042264,"mc":[{"id":"1.195453765","rc":[{"atl":[[3.45,0],[3.55,58.83],[3.65,28.3]],"id":41207262}],"con":true,"img":false}]}
{"op":"mcm","clk":"5353160363","pt":1646210042366,"mc":[{"id":"1.195453765","rc":[{"atl":[[3.55,19.61],[3.65,66.04]],"id":41207262}],"con":true,"img":false}]}
{"op":"mcm","clk":"5353160371","pt":1646210042469,"mc":[{"id":"1.195453765","rc":[{"atb":[[2.1,7.59]],"id":41207262},{"atb":[[2.32,6.33]],"id":43167130}],"con":true,"img":false}]}
{"op":"mcm","clk":"5353160455","pt":1646210044063,"mc":[{"id":"1.195453765","rc":[{"atb":[[2.28,4.99]],"id":43167130},{"spn":3.05,"spf":"NaN","id":43167130},{"spn":2.05,"spf":"NaN","id":42401236},{"spn":3.76,"spf":"NaN","id":40209251},{"spn":13.5,"spf":"NaN","id":43167131},{"spn":33.25,"spf":"NaN","id":36010178},{"spn":4.75,"spf":"NaN","id":36386524}],"con":true,"img":false}]}
{"op":"mcm","clk":"5353160521","pt":1646210045040,"mc":[{"id":"1.195453765","rc":[{"atb":[[1.8,0]],"id":41207262}],"con":true,"img":false}]}
{"op":"mcm","clk":"5353160527","pt":1646210045144,"mc":[{"id":"1.195453765","rc":[{"atb":[[1.85,86.24]],"id":41207262}],"con":true,"img":false}]}
{"op":"mcm","clk":"5353160552","pt":1646210045867,"mc":[{"id":"1.195453765","rc":[{"atb":[[1.98,123.65],[1.93,130.3],[2.06,76.03]],"id":41207262},{"atl":[[16,3.23],[6.4,16.43],[11,2.42],[5.2,2.88],[8.4,3.27]],"id":41207262},{"atb":[[2.26,48.08],[2.06,151.32],[2.16,104.46]],"id":43167130},{"atl":[[5.6,2.63],[7.2,1.95],[18,2.84],[9.2,2.95],[13,2.01]],"id":43167130},{"atb":[[1.19,318.89],[1.14,865.56],[1.09,1346.43]],"id":42401236},{"atl":[[2.88,12.89],[3.2,22.03],[2.28,9.46],[2.68,14.42],[2.48,8.18]],"id":42401236},{"atb":[[2.06,114.31],[2.26,48.08],[2.16,104.46]],"id":40209251},{"atl":[[5.6,2.63],[7.2,1.95],[18,2.84],[9.2,2.95],[13,2.01]],"id":40209251},{"atb":[[4.3,33.51],[3.9,41.78],[3.65,45.72]],"id":43167131},{"atl":[[32,4.01],[21,0.6],[55,0.44],[110,0.44],[15.5,0.83]],"id":43167131},{"atb":[[8.6,7.97],[7.6,18.36],[6.6,21.63]],"id":36010178},{"atl":[[280,0.08],[90,0.13],[180,0.13],[46,0.26],[380,0.12]],"id":36010178},{"atb":[[2.86,65.14],[3.15,51.44],[2.96,61.82]],"id":36386524},{"atl":[[16,1.61],[34,1.46],[11,1.21],[22,1.15],[8.4,1.63]],"id":36386524}],"con":true,"img":false}]}
{"op":"mcm","clk":"5353160580","pt":1646210046585,"mc":[{"id":"1.195453765","rc":[{"atb":[[4.3,56.24]],"id":43167131},{"atb":[[2.2,104.17]],"id":40209251}],"con":true,"img":false}]}
{"op":"mcm","clk":"5353160588","pt":1646210046640,"mc":[{"id":"1.195453765","rc":[{"atl":[[4,41.67]],"id":43167130},{"atl":[[7.4,19.53]],"id":36386524}],"con":true,"img":false}]}
{"op":"mcm","clk":"5353160863","pt":1646210052040,"mc":[{"id":"1.195453765","rc":[{"atl":[[65,0]],"id":36010178}],"con":true,"img":false}]}
{"op":"mcm","clk":"5353160868","pt":1646210052143,"mc":[{"id":"1.195453765","rc":[{"atl":[[55,3.32]],"id":36010178}],"con":true,"img":false}]}
{"op":"mcm","clk":"5353160873","pt":1646210052247,"mc":[{"id":"1.195453765","rc":[{"atl":[[50,2],[60,0]],"id":36010178}],"con":true,"img":false}]}
{"op":"mcm","clk":"5353160978","pt":1646210053992,"mc":[{"id":"1.195453765","rc":[{"atb":[[8,4.77],[11.5,0],[9.4,0]],"id":36010178},{"atl":[[55,0.59]],"id":36010178}],"con":true,"img":false}]}
{"op":"mcm","clk":"5353160984","pt":1646210054045,"mc":[{"id":"1.195453765","rc":[{"atb":[[9.8,4.15]],"id":36010178},{"atl":[[65,2.72]],"id":36010178}],"con":true,"img":false}]}
{"op":"mcm","clk":"5353160997","pt":1646210054359,"mc":[{"id":"1.195453765","rc":[{"atb":[[10,1.67]],"id":36010178}],"con":true,"img":false}]}
{"op":"mcm","clk":"5353161012","pt":1646210054558,"mc":[{"id":"1.195453765","rc":[{"atb":[[2.1,14.43]],"id":41207262},{"atb":[[2.32,12.03]],"id":43167130}],"con":true,"img":false}]}
{"op":"mcm","clk":"5353161059","pt":1646210055277,"mc":[{"id":"1.195453765","rc":[{"atl":[[3.45,8.16],[3.4,0]],"id":41207262}],"con":true,"img":false}]}
{"op":"mcm","clk":"5353161064","pt":1646210055380,"mc":[{"id":"1.195453765","rc":[{"atl":[[3.55,58.83],[3.65,28.3]],"id":41207262}],"con":true,"img":false}]}
{"op":"mcm","clk":"5353161071","pt":1646210055488,"mc":[{"id":"1.195453765","rc":[{"atl":[[3.55,19.61],[3.65,66.04]],"id":41207262}],"con":true,"img":false}]}
{"op":"mcm","clk":"5353161101","pt":1646210055851,"mc":[{"id":"1.195453765","rc":[{"atl":[[7.2,0]],"id":36386524}],"con":true,"img":false}]}
{"op":"mcm","clk":"5353161107","pt":1646210055952,"mc":[{"id":"1.195453765","rc":[{"atl":[[6.8,7.04]],"id":36386524}],"con":true,"img":false}]}
{"op":"mcm","clk":"5353161113","pt":1646210056047,"mc":[{"id":"1.195453765","rc":[{"atl":[[6.6,17.86],[7,12.49]],"id":36386524}],"con":true,"img":false}]}
{"op":"mcm","clk":"5353161184","pt":1646210057388,"mc":[{"id":"1.195453765","rc":[{"atl":[[55,2.59]],"id":36010178}],"con":true,"img":false}]}
{"op":"mcm","clk":"5353161187","pt":1646210057492,"mc":[{"id":"1.195453765","rc":[{"atl":[[50,0]],"id":36010178}],"con":true,"img":false}]}
{"op":"mcm","clk":"5353161192","pt":1646210057649,"mc":[{"id":"1.195453765","rc":[{"atl":[[55,0.59],[60,2]],"id":36010178}],"con":true,"img":false}]}
{"op":"mcm","clk":"5353161462","pt":1646210062892,"mc":[{"id":"1.195453765","rc":[{"atl":[[3.45,0],[3.4,8.33]],"id":41207262}],"con":true,"img":false}]}
{"op":"mcm","clk":"5353161467","pt":1646210062944,"mc":[{"id":"1.195453765","rc":[{"atl":[[3.55,58.83]],"id":41207262}],"con":true,"img":false}]}
{"op":"mcm","clk":"5353161475","pt":1646210063052,"mc":[{"id":"1.195453765","rc":[{"atl":[[3.65,28.3]],"id":41207262}],"con":true,"img":false}]}
{"op":"mcm","clk":"5353161535","pt":1646210064384,"mc":[{"id":"1.195453765","rc":[{"atl":[[3.45,8.16],[3.4,0]],"id":41207262}],"con":true,"img":false}]}
{"op":"mcm","clk":"5353161714","pt":1646210067778,"mc":[{"id":"1.195453765","rc":[{"atl":[[3.45,0],[3.4,8.33]],"id":41207262}],"con":true,"img":false}]}
{"op":"mcm","clk":"5353161896","pt":1646210071194,"mc":[{"id":"1.195453765","rc":[{"atl":[[3.45,8.16],[3.4,0]],"id":41207262}],"con":true,"img":false}]}
{"op":"mcm","clk":"5353161906","pt":1646210071397,"mc":[{"id":"1.195453765","rc":[{"atl":[[3.55,19.61],[3.65,66.04]],"id":41207262}],"con":true,"img":false}]}
{"op":"mcm","clk":"5353161942","pt":1646210071959,"mc":[{"id":"1.195453765","rc":[{"atb":[[2.06,114.31]],"id":43167130}],"con":true,"img":false}]}
{"op":"mcm","clk":"5353161946","pt":1646210072062,"mc":[{"id":"1.195453765","rc":[{"atb":[[2.18,37]],"id":43167130}],"con":true,"img":false}]}
{"op":"mcm","clk":"5353162056","pt":1646210074587,"mc":[{"id":"1.195453765","rc":[{"atl":[[3.45,0],[3.4,8.33]],"id":41207262}],"con":true,"img":false}]}
{"op":"mcm","clk":"5353162147","pt":1646210076482,"mc":[{"id":"1.195453765","rc":[{"atl":[[3.45,8.16],[3.4,0]],"id":41207262}],"con":true,"img":false}]}
{"op":"mcm","clk":"5353162281","pt":1646210078586,"mc":[{"id":"1.195453765","rc":[{"atl":[[3.45,0],[3.5,8]],"id":41207262}],"con":true,"img":false}]}
{"op":"mcm","clk":"5353162359","pt":1646210079977,"mc":[{"id":"1.195453765","rc":[{"atb":[[4.4,0]],"id":43167131},{"atb":[[9.8,0]],"id":36010178}],"con":true,"img":false}]}
{"op":"mcm","clk":"5353162366","pt":1646210080074,"mc":[{"id":"1.195453765","rc":[{"atb":[[4.8,16.49]],"id":43167131},{"atb":[[11,4.15]],"id":36010178}],"con":true,"img":false}]}
{"op":"mcm","clk":"5353162480","pt":1646210082394,"mc":[{"id":"1.195453765","rc":[{"atb":[[10,0]],"id":36010178}],"con":true,"img":false}]}
{"op":"mcm","clk":"5353162662","pt":1646210086002,"mc":[{"id":"1.195453765","rc":[{"atb":[[4.7,13.51]],"id":43167131}],"con":true,"img":false}]}
{"op":"mcm","clk":"5353162668","pt":1646210086106,"mc":[{"id":"1.195453765","rc":[{"atb":[[5,18.86]],"id":43167131}],"con":true,"img":false}]}
{"op":"mcm","clk":"5353162802","pt":1646210088616,"mc":[{"id":"1.195453765","rc":[{"atl":[[3.6,19.23]],"id":41207262}],"con":true,"img":false}]}
{"op":"mcm","clk":"5353162864","pt":1646210089904,"mc":[{"id":"1.195453765","rc":[{"atb":[[1.96,0]],"id":40209251}],"con":true,"img":false}]}
{"op":"mcm","clk":"5353162870","pt":1646210090011,"mc":[{"id":"1.195453765","rc":[{"atb":[[2.22,60.04]],"id":40209251}],"con":true,"img":false}]}
{"op":"mcm","clk":"5353163293","pt":1646210097909,"mc":[{"id":"1.195453765","rc":[{"atl":[[65,0]],"id":36010178}],"con":true,"img":false}]}
{"op":"mcm","clk":"5353163295","pt":1646210098006,"mc":[{"id":"1.195453765","rc":[{"atl":[[55,3.32]],"id":36010178}],"con":true,"img":false}]}
{"op":"mcm","clk":"5353163302","pt":1646210098113,"mc":[{"id":"1.195453765","rc":[{"atl":[[3.55,0],[3.65,37.74],[3.75,0]],"id":41207262},{"atl":[[50,2],[60,0]],"id":36010178}],"con":true,"img":false}]}
{"op":"mcm","clk":"5353163329","pt":1646210098625,"mc":[{"id":"1.195453765","rc":[{"atl":[[3.7,27.78]],"id":41207262}],"con":true,"img":false}]}
{"op":"mcm","clk":"5353163377","pt":1646210099903,"mc":[{"id":"1.195453765","rc":[{"atl":[[55,0.59]],"id":36010178}],"con":true,"img":false}]}
{"op":"mcm","clk":"5353163380","pt":1646210100004,"mc":[{"id":"1.195453765","rc":[{"atl":[[60,2.72]],"id":36010178}],"con":true,"img":false}]}
{"op":"mcm","clk":"5353163552","pt":1646210103193,"mc":[{"id":"1.195453765","rc":[{"atl":[[50,0],[55,2.59]],"id":36010178}],"con":true,"img":false}]}
{"op":"mcm","clk":"5353163777","pt":1646210107200,"mc":[{"id":"1.195453765","rc":[{"spn":2.84,"spf":"NaN","id":41207262},{"atb":[[1.21,276.17],[1.22,340.91]],"id":42401236},{"spn":1.76,"spf":"NaN","id":42401236},{"spn":10.25,"spf":"NaN","id":43167131},{"spn":28.5,"spf":"NaN","id":36010178}],"con":true,"img":false}]}
{"op":"mcm","clk":"5353163834","pt":1646210108640,"mc":[{"id":"1.195453765","rc":[{"atl":[[3.8,44.64]],"id":41207262}],"con":true,"img":false}]}
{"op":"mcm","clk":"5353164101","pt":1646210113430,"mc":[{"id":"1.195453765","rc":[{"atb":[[1.21,552.34],[1.22,90.91]],"id":42401236}],"con":true,"img":false}]}
{"op":"mcm","clk":"5353164364","pt":1646210118053,"mc":[{"id":"1.195453765","rc":[{"atl":[[55,2]],"id":36010178}],"con":true,"img":false}]}
{"op":"mcm","clk":"5353164370","pt":1646210118109,"mc":[{"id":"1.195453765","rc":[{"atl":[[50,0.59]],"id":36010178}],"con":true,"img":false}]}
{"op":"mcm","clk":"5353165203","pt":1646210134342,"mc":[{"id":"1.195453765","rc":[{"atl":[[3.45,8.16],[3.5,0]],"id":41207262}],"con":true,"img":false}]}
{"op":"mcm","clk":"5353165583","pt":1646210141555,"mc":[{"id":"1.195453765","rc":[{"atl":[[3.45,0],[3.5,8]],"id":41207262}],"con":true,"img":false}]}
{"op":"mcm","clk":"5353165590","pt":1646210141648,"mc":[{"id":"1.195453765","rc":[{"atl":[[3.45,19.23],[3.65,0]],"id":41207262}],"con":true,"img":false}]}
{"op":"mcm","clk":"5353165646","pt":1646210142479,"mc":[{"id":"1.195453765","rc":[{"atl":[[3.45,27.39],[3.5,0]],"id":41207262},{"atl":[[3.55,7.84],[3.7,0]],"id":43167130},{"atb":[[2.28,91.69]],"id":40209251}],"con":true,"img":false}]}
{"op":"mcm","clk":"5353165650","pt":1646210142580,"mc":[{"id":"1.195453765","rc":[{"atb":[[2.32,0],[2.28,52.63]],"id":40209251}],"con":true,"img":false}]}
{"op":"mcm","clk":"5353165665","pt":1646210142784,"mc":[{"id":"1.195453765","rc":[{"atl":[[3.55,0],[3.7,7.41]],"id":43167130},{"atb":[[2.32,15.15]],"id":40209251}],"con":true,"img":false}]}
{"op":"mcm","clk":"5353165672","pt":1646210142891,"mc":[{"id":"1.195453765","rc":[{"atb":[[1.84,0],[1.92,98.04]],"id":41207262},{"atb":[[1.24,156.78]],"id":42401236},{"atb":[[2,100]],"id":40209251},{"atl":[[4.3,6.06],[5.1,0],[5.7,44.8]],"id":40209251}],"con":true,"img":false}]}
{"op":"mcm","clk":"5353165676","pt":1646210142942,"mc":[{"id":"1.195453765","rc":[{"atb":[[1.21,276.17]],"id":42401236},{"atb":[[1.66,0]],"id":40209251},{"atl":[[6.8,0]],"id":40209251}],"con":true,"img":false}]}
{"op":"mcm","clk":"5353165715","pt":1646210143558,"mc":[{"id":"1.195453765","rc":[{"atb":[[1.22,0]],"id":42401236}],"con":true,"img":false}]}
{"op":"mcm","clk":"5353165722","pt":1646210143659,"mc":[{"id":"1.195453765","rc":[{"atb":[[1.21,371.41]],"id":42401236},{"atl":[[2.46,4]],"id":42401236}],"con":true,"img":false}]}
{"op":"mcm","clk":"5353165743","pt":1646210143968,"mc":[{"id":"1.195453765","rc":[{"atl":[[60,0]],"id":36010178}],"con":true,"img":false}]}
{"op":"mcm","clk":"5353165749","pt":1646210144070,"mc":[{"id":"1.195453765","rc":[{"atl":[[50,3.32]],"id":36010178}],"con":true,"img":false}]}
{"op":"mcm","clk":"5353165755","pt":1646210144174,"mc":[{"id":"1.195453765","rc":[{"atl":[[48,2],[55,0]],"id":36010178}],"con":true,"img":false}]}
{"op":"mcm","clk":"5353165814","pt":1646210145262,"mc":[{"id":"1.195453765","rc":[{"atb":[[2.28,0]],"id":43167130}],"con":true,"img":false}]}
{"op":"mcm","clk":"5353165840","pt":1646210145879,"mc":[{"id":"1.195453765","rc":[{"atl":[[50,0.59]],"id":36010178}],"con":true,"img":false}]}
{"op":"mcm","clk":"5353165844","pt":1646210145981,"mc":[{"id":"1.195453765","rc":[{"atl":[[48,0],[50,2.63],[60,2.72]],"id":36010178}],"con":true,"img":false}]}
{"op":"mcm","clk":"5353165888","pt":1646210146759,"mc":[{"id":"1.195453765","rc":[{"atl":[[2.44,2]],"id":42401236},{"atl":[[4.3,0],[4.4,5.88]],"id":40209251}],"con":true,"img":false}]}
{"op":"mcm","clk":"5353165894","pt":1646210146861,"mc":[{"id":"1.195453765","rc":[{"atl":[[3.45,8.16],[3.7,64.82]],"id":41207262},{"atl":[[5.8,20.73]],"id":40209251}],"con":true,"img":false}]}
{"op":"mcm","clk":"5353165901","pt":1646210146973,"mc":[{"id":"1.195453765","rc":[{"atl":[[5.7,26.6]],"id":40209251}],"con":true,"img":false}]}
{"op":"mcm","clk":"5353166037","pt":1646210149493,"mc":[{"id":"1.195453765","rc":[{"atl":[[3.45,0],[3.5,8]],"id":41207262},{"atl":[[2.42,3]],"id":42401236},{"atb":[[2.32,0]],"id":40209251}],"con":true,"img":false}]}
{"op":"mcm","clk":"5353166063","pt":1646210149959,"mc":[{"id":"1.195453765","rc":[{"atb":[[1.23,0]],"id":42401236}],"con":true,"img":false}]}
{"op":"mcm","clk":"5353166067","pt":1646210150063,"mc":[{"id":"1.195453765","rc":[{"atb":[[2.28,4.99]],"id":43167130},{"atb":[[1.22,94.11]],"id":42401236},{"atl":[[2.4,3]],"id":42401236},{"atb":[[2.32,15.15]],"id":40209251}],"con":true,"img":false}]}
{"op":"mcm","clk":"5353166072","pt":1646210150170,"mc":[{"id":"1.195453765","rc":[{"atl":[[3.45,8.16]],"id":41207262}],"con":true,"img":false}]}
{"op":"mcm","clk":"5353166078","pt":1646210150268,"mc":[{"id":"1.195453765","rc":[{"atl":[[3.5,0]],"id":41207262}],"con":true,"img":false}]}
{"op":"mcm","clk":"5353166112","pt":1646210151094,"mc":[{"id":"1.195453765","rc":[{"atl":[[55,2]],"id":36010178}],"con":true,"img":false}]}
{"op":"mcm","clk":"5353166114","pt":1646210151190,"mc":[{"id":"1.195453765","rc":[{"atl":[[50,0.59]],"id":36010178}],"con":true,"img":false}]}
{"op":"mcm","clk":"5353166185","pt":1646210152275,"mc":[{"id":"1.195453765","rc":[{"atb":[[1.24,90.91]],"id":42401236}],"con":true,"img":false}]}
{"op":"mcm","clk":"5353166204","pt":1646210152483,"mc":[{"id":"1.195453765","rc":[{"atb":[[1.23,250],[1.24,0]],"id":42401236}],"con":true,"img":false}]}
{"op":"mcm","clk":"5353166278","pt":1646210153578,"mc":[{"id":"1.195453765","rc":[{"atb":[[1.19,568.89]],"id":42401236}],"con":true,"img":false}]}
{"op":"mcm","clk":"5353166451","pt":1646210156883,"mc":[{"id":"1.195453765","rc":[{"atb":[[1.2,0],[1.18,0],[1.16,0],[1.24,148.17]],"id":42401236},{"atl":[[4.3,6.06],[4.4,0]],"id":40209251}],"con":true,"img":false}]}
{"op":"mcm","clk":"5353166454","pt":1646210156986,"mc":[{"id":"1.195453765","rc":[{"atl":[[5.7,47.33]],"id":40209251}],"con":true,"img":false}]}
{"op":"mcm","clk":"5353166460","pt":1646210157088,"mc":[{"id":"1.195453765","rc":[{"atl":[[5.8,0]],"id":40209251}],"con":true,"img":false}]}
{"op":"mcm","clk":"5353166497","pt":1646210157806,"mc":[{"id":"1.195453765","rc":[{"atl":[[3.45,0],[3.5,8]],"id":41207262},{"atb":[[2.32,0]],"id":40209251}],"con":true,"img":false}]}
{"op":"mcm","clk":"5353166502","pt":1646210157882,"mc":[{"id":"1.195453765","rc":[{"atl":[[3.6,57.69],[3.7,27.78]],"id":41207262}],"con":true,"img":false}]}
{"op":"mcm","clk":"5353166655","pt":1646210160896,"mc":[{"id":"1.195453765","rc":[{"atb":[[1.23,0],[1.22,249.48],[1.24,374.02]],"id":42401236},{"atl":[[2.42,96.2],[2.28,71.96]],"id":42401236}],"con":true,"img":false}]}
{"op":"mcm","clk":"5353166660","pt":1646210161000,"mc":[{"id":"1.195453765","rc":[{"atb":[[1.27,10],[1.31,5],[1.35,2.5]],"id":42401236}],"con":true,"img":false}]}
{"op":"mcm","clk":"5353166672","pt":1646210161206,"mc":[{"id":"1.195453765","rc":[{"atb":[[2.1,50.57],[2.16,11.06]],"id":41207262},{"atl":[[3.7,61.42],[3.5,16.89]],"id":41207262},{"atb":[[2.44,2.5],[2.36,5],[2.38,16.76],[2.28,44.16]],"id":43167130},{"atl":[[3.7,22],[3.9,55.03]],"id":43167130},{"atb":[[2.6,2.5],[2.44,10],[2.4,13.54],[2.52,5],[2.28,83.73]],"id":40209251},{"atl":[[4.3,17.43],[5.4,40.19]],"id":40209251},{"atb":[[4.8,34.78],[5.1,6.64],[5.2,2.5]],"id":43167131},{"atl":[[19.5,2.5],[22,13.97],[23,5],[15.5,6.35]],"id":43167131},{"atb":[[8,14.01],[7.6,20.86]],"id":36010178},{"atl":[[38,2.5],[44,1.86],[55,6.09]],"id":36010178},{"atb":[[3.25,19.59],[3.15,78.11]],"id":36386524},{"atl":[[6.2,6.35],[6.8,33.71],[6,10.7],[7,17.49]],"id":36386524}],"con":true,"img":false}]}
{"op":"mcm","clk":"5353166687","pt":1646210161374,"mc":[{"id":"1.195453765","rc":[{"atl":[[48,2],[55,4.09]],"id":36010178}],"con":true,"img":false}]}
{"op":"mcm","clk":"5353166700","pt":1646210161674,"mc":[{"id":"1.195453765","rc":[{"atl":[[3.65,7.55]],"id":41207262}],"con":true,"img":false}]}
{"op":"mcm","clk":"5353166708","pt":1646210161775,"mc":[{"id":"1.195453765","rc":[{"atl":[[3.5,8.89]],"id":41207262}],"con":true,"img":false}]}
{"op":"mcm","clk":"5353166719","pt":1646210161985,"mc":[{"id":"1.195453765","rc":[{"atl":[[3.5,0]],"id":41207262}],"con":true,"img":false}]}
{"op":"mcm","clk":"5353166725","pt":1646210162086,"mc":[{"id":"1.195453765","rc":[{"atl":[[3.6,70.02]],"id":41207262},{"atb":[[2.5,2.17],[2.4,11.37]],"id":40209251}],"con":true,"img":false}]}
{"op":"mcm","clk":"5353166759","pt":1646210162808,"mc":[{"id":"1.195453765","rc":[{"atb":[[2.1,43.73]],"id":41207262},{"atb":[[2.32,6.33]],"id":43167130}],"con":true,"img":false}]}
{"op":"mcm","clk":"5353166772","pt":1646210163013,"mc":[{"id":"1.195453765","rc":[{"atl":[[3.6,31.56],[3.7,98.46]],"id":41207262}],"con":true,"img":false}]}
{"op":"mcm","clk":"5353166798","pt":1646210163388,"mc":[{"id":"1.195453765","rc":[{"atl":[[3.6,12.33]],"id":41207262},{"atl":[[2.44,0],[2.4,0],[5,27],[2.42,93.2],[2.46,0]],"id":42401236},{"atb":[[2.32,15.15]],"id":40209251},{"atl":[[4.3,11.37],[5.7,26.6],[4.2,6.25],[5.4,62.92]],"id":40209251},{"atb":[[3.25,10.7],[3.15,64.15]],"id":36386524},{"atl":[[4.5,4]],"id":36386524}],"con":true,"img":false}]}
{"op":"mcm","clk":"5353166807","pt":1646210163585,"mc":[{"id":"1.195453765","rc":[{"atl":[[3.7,78.09],[3.65,0]],"id":41207262},{"atb":[[1.17,250]],"id":42401236},{"atl":[[4.9,2]],"id":42401236},{"atl":[[4.4,4],[4.5,0],[6.2,25.58],[6.6,8.93]],"id":36386524}],"con":true,"img":false}]}
{"op":"mcm","clk":"5353166842","pt":1646210164302,"mc":[{"id":"1.195453765","rc":[{"atb":[[2.28,39.17]],"id":43167130},{"atb":[[1.24,225.85]],"id":42401236},{"atl":[[4.3,3]],"id":36386524}],"con":true,"img":false}]}
{"op":"mcm","clk":"5353166853","pt":1646210164509,"mc":[{"id":"1.195453765","rc":[{"atl":[[4.2,3]],"id":36386524}],"con":true,"img":false}]}
{"op":"mcm","clk":"5353166932","pt":1646210165897,"mc":[{"id":"1.195453765","rc":[{"atl":[[4.1,3]],"id":36386524}],"con":true,"img":false}]}
{"op":"mcm","clk":"5353166955","pt":1646210166411,"mc":[{"id":"1.195453765","rc":[{"atb":[[2.4,0]],"id":43167130},{"atb":[[2.42,0]],"id":40209251},{"atb":[[5,17.19]],"id":43167131}],"con":true,"img":false}]}
{"op":"mcm","clk":"5353166963","pt":1646210166618,"mc":[{"id":"1.195453765","rc":[{"atb":[[2.46,1.67]],"id":43167130},{"atb":[[2.62,1.67]],"id":40209251},{"atb":[[5.3,1.67]],"id":43167131}],"con":true,"img":false}]}
{"op":"mcm","clk":"5353166974","pt":1646210166825,"mc":[{"id":"1.195453765","rc":[{"atb":[[5,10.39],[5.2,9.14]],"id":43167131}],"con":true,"img":false}]}
{"op":"mcm","clk":"5353167005","pt":1646210167291,"mc":[{"id":"1.195453765","rc":[{"spn":2.89,"spf":"NaN","id":41207262},{"atb":[[1.2,2.25]],"id":43167130},{"spn":3.08,"spf":"NaN","id":43167130},{"spn":1.81,"spf":"NaN","id":42401236},{"spn":10.4,"spf":"NaN","id":43167131},{"spn":3.41,"spf":"NaN","id":40209251},{"spn":24.5,"spf":"NaN","id":36010178},{"spn":3.7,"spf":"NaN","id":36386524}],"con":true,"img":false}]}
{"op":"mcm","clk":"5353167016","pt":1646210167599,"mc":[{"id":"1.195453765","rc":[{"atb":[[1.2,1.74]],"id":43167130}],"con":true,"img":false}]}
{"op":"mcm","clk":"5353167032","pt":1646210167931,"mc":[{"id":"1.195453765","rc":[{"atb":[[1.2,0]],"id":43167130}],"con":true,"img":false}]}
{"op":"mcm","clk":"5353167037","pt":1646210167983,"mc":[{"id":"1.195453765","rc":[{"atb":[[2.46,3.41]],"id":43167130}],"con":true,"img":false}]}
{"op":"mcm","clk":"5353167045","pt":1646210168188,"mc":[{"id":"1.195453765","rc":[{"atb":[[1.28,3.74]],"id":42401236}],"con":true,"img":false}]}
{"op":"mcm","clk":"5353167057","pt":1646210168395,"mc":[{"id":"1.195453765","rc":[{"atl":[[4.8,4]],"id":42401236},{"atb":[[3.25,19.59]],"id":36386524}],"con":true,"img":false}]}
{"op":"mcm","clk":"5353167064","pt":1646210168499,"mc":[{"id":"1.195453765","rc":[{"atl":[[4.3,0],[4.4,0],[4.1,0],[4.2,0]],"id":36386524}],"con":true,"img":false}]}
{"op":"mcm","clk":"5353167072","pt":1646210168602,"mc":[{"id":"1.195453765","rc":[{"atl":[[4.7,2]],"id":42401236},{"atl":[[5.9,10.7],[6.2,6.35]],"id":36386524}],"con":true,"img":false}]}
{"op":"mcm","clk":"5353167081","pt":1646210168711,"mc":[{"id":"1.195453765","rc":[{"atl":[[5.9,0],[6.6,26.79]],"id":36386524}],"con":true,"img":false}]}
{"op":"mcm","clk":"5353167085","pt":1646210168808,"mc":[{"id":"1.195453765","rc":[{"atb":[[2.14,6.59]],"id":41207262},{"atb":[[2.34,5.61]],"id":43167130},{"atl":[[6.2,25.58],[6.6,8.93]],"id":36386524}],"con":true,"img":false}]}
{"op":"mcm","clk":"5353167091","pt":1646210168912,"mc":[{"id":"1.195453765","rc":[{"atl":[[6.2,6.35],[6.6,26.79]],"id":36386524}],"con":true,"img":false}]}
{"op":"mcm","clk":"5353167096","pt":1646210169016,"mc":[{"id":"1.195453765","rc":[{"atl":[[3.6,0],[3.7,41.05],[3.8,80.35]],"id":41207262}],"con":true,"img":false}]}
{"op":"mcm","clk":"5353167104","pt":1646210169119,"mc":[{"id":"1.195453765","rc":[{"atl":[[3.7,58.59]],"id":41207262}],"con":true,"img":false}]}
{"op":"mcm","clk":"5353167109","pt":1646210169222,"mc":[{"id":"1.195453765","rc":[{"atl":[[5.1,24.39],[3.7,51.18],[3.8,44.64],[3.75,7.27]],"id":41207262},{"atl":[[2.48,27.96],[2.42,0]],"id":42401236}],"con":true,"img":false}]}
{"op":"mcm","clk":"5353167120","pt":1646210169379,"mc":[{"id":"1.195453765","rc":[{"atl":[[2.8,2.5]],"id":42401236}],"con":true,"img":false}]}
{"op":"mcm","clk":"5353167125","pt":1646210169481,"mc":[{"id":"1.195453765","rc":[{"atl":[[3.8,74.64]],"id":41207262}],"con":true,"img":false}]}
{"op":"mcm","clk":"5353167132","pt":1646210169587,"mc":[{"id":"1.195453765","rc":[{"atl":[[3.7,17.54]],"id":41207262}],"con":true,"img":false}]}
{"op":"mcm","clk":"5353167240","pt":1646210171699,"mc":[{"id":"1.195453765","rc":[{"atb":[[2.12,0]],"id":41207262}],"con":true,"img":false}]}
{"op":"mcm","clk":"5353167319","pt":1646210173400,"mc":[{"id":"1.195453765","rc":[{"atb":[[2.28,107.16]],"id":40209251},{"atl":[[4.4,14.71]],"id":40209251}],"con":true,"img":false}]}
{"op":"mcm","clk":"5353167336","pt":1646210173711,"mc":[{"id":"1.195453765","rc":[{"atb":[[1.15,250]],"id":42401236}],"con":true,"img":false}]}
{"op":"mcm","clk":"5353167341","pt":1646210173815,"mc":[{"id":"1.195453765","rc":[{"atl":[[5.3,0],[5.5,0],[5.7,0]],"id":40209251}],"con":true,"img":false}]}
{"op":"mcm","clk":"5353167351","pt":1646210173925,"mc":[{"id":"1.195453765","rc":[{"atl":[[36,0.91]],"id":36010178}],"con":true,"img":false}]}
{"op":"mcm","clk":"5353167356","pt":1646210174022,"mc":[{"id":"1.195453765","rc":[{"atl":[[3.7,24.95]],"id":41207262},{"atl":[[50,0]],"id":36010178}],"con":true,"img":false}]}
{"op":"mcm","clk":"5353167548","pt":1646210176899,"mc":[{"id":"1.195453765","rc":[{"atb":[[2.18,10.58]],"id":41207262}],"con":true,"img":false}]}
{"op":"mcm","clk":"5353167574","pt":1646210177410,"mc":[{"id":"1.195453765","rc":[{"atl":[[3.8,106.86]],"id":41207262},{"atl":[[2.48,8.18],[2.68,43.56]],"id":42401236}],"con":true,"img":false}]}
{"op":"mcm","clk":"5353167584","pt":1646210177517,"mc":[{"id":"1.195453765","rc":[{"atl":[[5.1,0]],"id":41207262}],"con":true,"img":false}]}
{"op":"mcm","clk":"5353167593","pt":1646210177620,"mc":[{"id":"1.195453765","rc":[{"atb":[[2.32,0]],"id":43167130}],"con":true,"img":false}]}
{"op":"mcm","clk":"5353167610","pt":1646210177824,"mc":[{"id":"1.195453765","rc":[{"atb":[[2.24,2.17],[2.16,8.89]],"id":41207262}],"con":true,"img":false}]}
{"op":"mcm","clk":"5353167640","pt":1646210178394,"mc":[{"id":"1.195453765","rc":[{"atb":[[1.28,23.52],[1.22,94.11],[1.35,12.39]],"id":42401236},{"atb":[[3.15,78.11]],"id":36386524}],"con":true,"img":false}]}
{"op":"mcm","clk":"5353167653","pt":1646210178600,"mc":[{"id":"1.195453765","rc":[{"atb":[[1.24,148.17]],"id":42401236}],"con":true,"img":false}]}
{"op":"mcm","clk":"5353167658","pt":1646210178705,"mc":[{"id":"1.195453765","rc":[{"atb":[[2.1,10.09],[2.24,16.77],[2.16,38.09]],"id":41207262},{"atb":[[2.38,68.69],[2.46,29.38],[2.28,10]],"id":43167130},{"atb":[[2.5,19.05],[2.6,10.94],[2.28,76.06]],"id":40209251},{"atl":[[4.4,31.59],[4.2,14.69],[5.4,31.82]],"id":40209251},{"atb":[[4.8,21.49],[5,29.89],[5.3,8.31]],"id":43167131},{"atl":[[21,11.94],[22,3.72]],"id":43167131},{"atl":[[34,2.42],[44,7.27],[55,0]],"id":36010178},{"atl":[[6.6,62.89]],"id":36386524}],"con":true,"img":false}]}
{"op":"mcm","clk":"5353167664","pt":1646210178807,"mc":[{"id":"1.195453765","rc":[{"atb":[[2.16,29.2]],"id":41207262},{"atb":[[2.38,54.1]],"id":43167130},{"atb":[[1.38,2.17]],"id":42401236},{"atb":[[5.1,10.81],[5.2,2.5]],"id":43167131},{"atb":[[2.4,0]],"id":40209251},{"atl":[[4.3,0]],"id":40209251},{"atl":[[44,5.41]],"id":36010178},{"atl":[[6.8,7.04]],"id":36386524}],"con":true,"img":false}]}
{"op":"mcm","clk":"5353167669","pt":1646210178910,"mc":[{"id":"1.195453765","rc":[{"atb":[[5.1,0],[5.2,19.12]],"id":43167131}],"con":true,"img":false}]}
{"op":"mcm","clk":"5353167689","pt":1646210179523,"mc":[{"id":"1.195453765","rc":[{"atb":[[3.15,87.41]],"id":36386524},{"atl":[[4.6,3]],"id":36386524}],"con":true,"img":false}]}
{"op":"mcm","clk":"5353167692","pt":1646210179626,"mc":[{"id":"1.195453765","rc":[{"atb":[[3.25,10.7],[3.15,64.15]],"id":36386524},{"atl":[[5.9,10.18],[6.2,25.58],[6.6,45.03]],"id":36386524}],"con":true,"img":false}]}
{"op":"mcm","clk":"5353167696","pt":1646210179682,"mc":[{"id":"1.195453765","rc":[{"atl":[[3.7,17.54]],"id":41207262},{"atl":[[4.4,3],[4.6,0]],"id":36386524}],"con":true,"img":false}]}
{"op":"mcm","clk":"5353167701","pt":1646210179784,"mc":[{"id":"1.195453765","rc":[{"atl":[[6,0]],"id":36386524}],"con":true,"img":false}]}
{"op":"mcm","clk":"5353167717","pt":1646210180402,"mc":[{"id":"1.195453765","rc":[{"atb":[[2.18,8.91]],"id":41207262}],"con":true,"img":false}]}
{"op":"mcm","clk":"5353167722","pt":1646210180606,"mc":[{"id":"1.195453765","rc":[{"atb":[[2.26,1.67]],"id":41207262}],"con":true,"img":false}]}
{"op":"mcm","clk":"5353167731","pt":1646210180813,"mc":[{"id":"1.195453765","rc":[{"atb":[[2.14,0]],"id":41207262},{"atb":[[2.34,0]],"id":43167130}],"con":true,"img":false}]}
{"op":"mcm","clk":"5353167741","pt":1646210181025,"mc":[{"id":"1.195453765","rc":[{"atl":[[4.3,4]],"id":36386524}],"con":true,"img":false}]}
{"op":"mcm","clk":"5353167763","pt":1646210181383,"mc":[{"id":"1.195453765","rc":[{"atb":[[2.18,0]],"id":41207262}],"con":true,"img":false}]}
{"op":"mcm","clk":"5353167784","pt":1646210181899,"mc":[{"id":"1.195453765","rc":[{"atl":[[5.3,0]],"id":41207262}],"con":true,"img":false}]}
{"op":"mcm","clk":"5353167788","pt":1646210182004,"mc":[{"id":"1.195453765","rc":[{"atl":[[5.1,9.09]],"id":41207262}],"con":true,"img":false}]}
{"op":"mcm","clk":"5353167869","pt":1646210183399,"mc":[{"id":"1.195453765","rc":[{"atl":[[4.6,20.83]],"id":40209251}],"con":true,"img":false}]}
{"op":"mcm","clk":"5353167895","pt":1646210183915,"mc":[{"id":"1.195453765","rc":[{"atb":[[1.93,200.71]],"id":41207262}],"con":true,"img":false}]}
{"op":"mcm","clk":"5353167900","pt":1646210184018,"mc":[{"id":"1.195453765","rc":[{"atb":[[1.85,0]],"id":41207262},{"atl":[[3.85,17.54]],"id":41207262},{"atl":[[2.86,0]],"id":42401236}],"con":true,"img":false}]}
{"op":"mcm","clk":"5353167904","pt":1646210184118,"mc":[{"id":"1.195453765","rc":[{"atl":[[2.26,27.29]],"id":42401236}],"con":true,"img":false}]}
{"op":"mcm","clk":"5353167914","pt":1646210184325,"mc":[{"id":"1.195453765","rc":[{"atl":[[2.26,42.72],[2.48,39.05],[2.68,14.42]],"id":42401236}],"con":true,"img":false}]}
{"op":"mcm","clk":"5353167924","pt":1646210184486,"mc":[{"id":"1.195453765","rc":[{"atl":[[2.28,9.46]],"id":42401236}],"con":true,"img":false}]}
{"op":"mcm","clk":"5353167934","pt":1646210184691,"mc":[{"id":"1.195453765","rc":[{"atb":[[2.14,3]],"id":43167130},{"atb":[[3.25,19.59]],"id":36386524},{"atl":[[4.3,0],[4.4,0],[4.2,2]],"id":36386524}],"con":true,"img":false}]}
{"op":"mcm","clk":"5353167938","pt":1646210184794,"mc":[{"id":"1.195453765","rc":[{"atb":[[2.16,108.46]],"id":43167130}],"con":true,"img":false}]}
{"op":"mcm","clk":"5353167942","pt":1646210184898,"mc":[{"id":"1.195453765","rc":[{"atl":[[3.7,24.95]],"id":41207262},{"atl":[[4.2,0]],"id":36386524}],"con":true,"img":false}]}
{"op":"mcm","clk":"5353167997","pt":1646210186028,"mc":[{"id":"1.195453765","rc":[{"atl":[[2.26,15.43]],"id":42401236}],"con":true,"img":false}]}
{"op":"mcm","clk":"5353168005","pt":1646210186136,"mc":[{"id":"1.195453765","rc":[{"atb":[[2.12,25.82]],"id":41207262},{"atl":[[2.58,27.29]],"id":42401236}],"con":true,"img":false}]}
{"op":"mcm","clk":"5353168029","pt":1646210186808,"mc":[{"id":"1.195453765","rc":[{"atb":[[2.12,101.98],[2.1,16.93],[2.16,0]],"id":41207262},{"atb":[[2.52,4.95]],"id":43167130},{"atl":[[4.6,71.44]],"id":40209251}],"con":true,"img":false}]}
{"op":"mcm","clk":"5353168037","pt":1646210186913,"mc":[{"id":"1.195453765","rc":[{"atl":[[4.4,14.71]],"id":40209251}],"con":true,"img":false}]}
{"op":"mcm","clk":"5353168057","pt":1646210187325,"mc":[{"id":"1.195453765","rc":[{"atb":[[2.46,27.71]],"id":43167130}],"con":true,"img":false}]}
{"op":"mcm","clk":"5353168068","pt":1646210187532,"mc":[{"id":"1.195453765","rc":[{"atb":[[2.54,1.67]],"id":43167130}],"con":true,"img":false}]}
{"op":"mcm","clk":"5353168099","pt":1646210187998,"mc":[{"id":"1.195453765","rc":[{"atl":[[4.3,0]],"id":43167130}],"con":true,"img":false}]}
{"op":"mcm","clk":"5353168101","pt":1646210188100,"mc":[{"id":"1.195453765","rc":[{"atl":[[5.6,15.86]],"id":43167130}],"con":true,"img":false}]}
{"op":"mcm","clk":"5353168123","pt":1646210188408,"mc":[{"id":"1.195453765","rc":[{"atb":[[2.52,7.12],[2.38,51.93]],"id":43167130}],"con":true,"img":false}]}
{"op":"mcm","clk":"5353168146","pt":1646210188716,"mc":[{"id":"1.195453765","rc":[{"atb":[[1.28,19.78]],"id":42401236}],"con":true,"img":false}]}
{"op":"mcm","clk":"5353168205","pt":1646210189692,"mc":[{"id":"1.195453765","rc":[{"atb":[[2.1,10.09]],"id":41207262},{"atb":[[2.52,2.17]],"id":43167130}],"con":true,"img":false}]}
{"op":"mcm","clk":"5353168226","pt":1646210190206,"mc":[{"id":"1.195453765","rc":[{"atb":[[2.18,39]],"id":43167130}],"con":true,"img":false}]}
{"op":"mcm","clk":"5353168236","pt":1646210190413,"mc":[{"id":"1.195453765","rc":[{"atl":[[3.7,17.54],[3.65,7.55]],"id":41207262},{"atb":[[2.2,3]],"id":43167130}],"con":true,"img":false}]}
{"op":"mcm","clk":"5353168242","pt":1646210190515,"mc":[{"id":"1.195453765","rc":[{"atl":[[3.8,76.86],[3.65,25.79],[3.75,48.71]],"id":41207262}],"con":true,"img":false}]}
{"op":"mcm","clk":"5353168249","pt":1646210190728,"mc":[{"id":"1.195453765","rc":[{"atl":[[3.7,0]],"id":41207262}],"con":true,"img":false}]}
{"op":"mcm","clk":"5353168267","pt":1646210191132,"mc":[{"id":"1.195453765","rc":[{"atb":[[2.46,25.97]],"id":43167130}],"con":true,"img":false}]}
{"op":"mcm","clk":"5353168365","pt":1646210193395,"mc":[{"id":"1.195453765","rc":[{"atl":[[4.8,32.89]],"id":40209251}],"con":true,"img":false}]}
{"op":"mcm","clk":"5353168374","pt":1646210193600,"mc":[{"id":"1.195453765","rc":[{"atb":[[1.29,20.38]],"id":42401236}],"con":true,"img":false}]}
{"op":"mcm","clk":"5353168388","pt":1646210193909,"mc":[{"id":"1.195453765","rc":[{"atb":[[8,9.24]],"id":36010178}],"con":true,"img":false}]}
{"op":"mcm","clk":"5353168393","pt":1646210194011,"mc":[{"id":"1.195453765","rc":[{"atb":[[8.8,4.77]],"id":36010178}],"con":true,"img":false}]}
{"op":"mcm","clk":"5353168396","pt":1646210194112,"mc":[{"id":"1.195453765","rc":[{"atb":[[8,0],[8.6,17.96]],"id":36010178}],"con":true,"img":false}]}
{"op":"mcm","clk":"5353168426","pt":1646210194729,"mc":[{"id":"1.195453765","rc":[{"atb":[[3.15,78.11]],"id":36386524}],"con":true,"img":false}]}
{"op":"mcm","clk":"5353168432","pt":1646210194830,"mc":[{"id":"1.195453765","rc":[{"atl":[[6.2,6.35],[6.6,62.89],[5.9,0]],"id":36386524}],"con":true,"img":false}]}
{"op":"mcm","clk":"5353168439","pt":1646210194934,"mc":[{"id":"1.195453765","rc":[{"atb":[[2.12,25.82],[2.1,121.84]],"id":41207262},{"atl":[[6,16]],"id":36386524}],"con":true,"img":false}]}
{"op":"mcm","clk":"5353168444","pt":1646210195036,"mc":[{"id":"1.195453765","rc":[{"atl":[[6.8,43.78]],"id":36386524}],"con":true,"img":false}]}
{"op":"mcm","clk":"5353168449","pt":1646210195140,"mc":[{"id":"1.195453765","rc":[{"atl":[[6.8,7.04],[6.6,26.79]],"id":36386524}],"con":true,"img":false}]}
{"op":"mcm","clk":"5353168469","pt":1646210195501,"mc":[{"id":"1.195453765","rc":[{"atb":[[1.28,0],[1.31,37.79],[1.38,18.57]],"id":42401236}],"con":true,"img":false}]}
{"op":"mcm","clk":"5353168481","pt":1646210195707,"mc":[{"id":"1.195453765","rc":[{"atb":[[1.35,2.5]],"id":42401236}],"con":true,"img":false}]}
{"op":"mcm","clk":"5353168489","pt":1646210195810,"mc":[{"id":"1.195453765","rc":[{"atb":[[2.44,67.51],[2.52,32.07],[2.38,0]],"id":43167130},{"atl":[[38,9.08]],"id":36010178},{"atl":[[6.6,64.74]],"id":36386524}],"con":true,"img":false}]}
{"op":"mcm","clk":"5353168493","pt":1646210195912,"mc":[{"id":"1.195453765","rc":[{"atl":[[44,0]],"id":36010178}],"con":true,"img":false}]}
{"op":"mcm","clk":"5353168498","pt":1646210196015,"mc":[{"id":"1.195453765","rc":[{"atb":[[2.46,0]],"id":43167130}],"con":true,"img":false}]}
{"op":"mcm","clk":"5353168511","pt":1646210196220,"mc":[{"id":"1.195453765","rc":[{"atb":[[2.54,4.36]],"id":43167130}],"con":true,"img":false}]}
{"op":"mcm","clk":"5353168571","pt":1646210197406,"mc":[{"id":"1.195453765","rc":[{"atb":[[3.25,10.7],[3.15,64.15]],"id":36386524},{"atl":[[4.6,2]],"id":36386524}],"con":true,"img":false}]}
{"op":"mcm","clk":"5353168577","pt":1646210197507,"mc":[{"id":"1.195453765","rc":[{"atl":[[4.6,12.18]],"id":36386524}],"con":true,"img":false}]}
{"op":"mcm","clk":"5353168583","pt":1646210197713,"mc":[{"id":"1.195453765","rc":[{"atl":[[6,0]],"id":36386524}],"con":true,"img":false}]}
{"op":"mcm","clk":"5353168611","pt":1646210198434,"mc":[{"id":"1.195453765","rc":[{"atb":[[1.29,0]],"id":42401236}],"con":true,"img":false}]}
{"op":"mcm","clk":"5353168619","pt":1646210198539,"mc":[{"id":"1.195453765","rc":[{"atl":[[3.8,143.29]],"id":41207262}],"con":true,"img":false}]}
{"op":"mcm","clk":"5353168632","pt":1646210198643,"mc":[{"id":"1.195453765","rc":[{"atl":[[3.75,7.27]],"id":41207262}],"con":true,"img":false}]}
{"op":"mcm","clk":"5353168747","pt":1646210198906,"mc":[{"id":"1.195453765","rc":[{"atb":[[2.44,62.29]],"id":43167130}],"con":true,"img":false}]}
{"op":"mcm","clk":"5353168807","pt":1646210200036,"mc":[{"id":"1.195453765","rc":[{"atl":[[22,1]],"id":43167131},{"atl":[[36,0]],"id":36010178}],"con":true,"img":false}]}
{"op":"mcm","clk":"5353168811","pt":1646210200140,"mc":[{"id":"1.195453765","rc":[{"atl":[[20,2.72]],"id":43167131},{"atl":[[32,0.91]],"id":36010178}],"con":true,"img":false}]}
{"op":"mcm","clk":"5353168817","pt":1646210200241,"mc":[{"id":"1.195453765","rc":[{"atl":[[34,0]],"id":36010178}],"con":true,"img":false}]}
{"op":"mcm","clk":"5353168823","pt":1646210200343,"mc":[{"id":"1.195453765","rc":[{"atl":[[3.75,25.45]],"id":41207262},{"atl":[[20,15.39],[21,0.6]],"id":43167131},{"atl":[[30,2.76]],"id":36010178}],"con":true,"img":false}]}
{"op":"mcm","clk":"5353168827","pt":1646210200446,"mc":[{"id":"1.195453765","rc":[{"atl":[[3.75,18.18]],"id":41207262}],"con":true,"img":false}]}
{"op":"mcm","clk":"5353168893","pt":1646210201844,"mc":[{"id":"1.195453765","rc":[{"atb":[[2.14,6.59]],"id":41207262}],"con":true,"img":false}]}
{"op":"mcm","clk":"5353168901","pt":1646210202003,"mc":[{"id":"1.195453765","rc":[{"atb":[[2.12,92.16],[2.1,10.09]],"id":41207262}],"con":true,"img":false}]}
{"op":"mcm","clk":"5353168905","pt":1646210202108,"mc":[{"id":"1.195453765","rc":[{"atb":[[2.1,2.5]],"id":41207262}],"con":true,"img":false}]}
{"op":"mcm","clk":"5353168960","pt":1646210203340,"mc":[{"id":"1.195453765","rc":[{"atb":[[1.32,26]],"id":42401236}],"con":true,"img":false}]}
{"op":"mcm","clk":"5353168993","pt":1646210203905,"mc":[{"id":"1.195453765","rc":[{"atl":[[26,3]],"id":43167131},{"atl":[[6.8,0],[4.4,3]],"id":36386524}],"con":true,"img":false}]}
{"op":"mcm","clk":"5353168997","pt":1646210204009,"mc":[{"id":"1.195453765","rc":[{"atl":[[22,3.72]],"id":43167131},{"atb":[[3.25,19.59]],"id":36386524},{"atl":[[7.2,7.04],[4.6,10.18]],"id":36386524}],"con":true,"img":false}]}
{"op":"mcm","clk":"5353169002","pt":1646210204117,"mc":[{"id":"1.195453765","rc":[{"atl":[[3.7,7.41],[3.65,18.24]],"id":41207262},{"atl":[[3.7,7.41]],"id":43167130}],"con":true,"img":false}]}
{"op":"mcm","clk":"5353169005","pt":1646210204213,"mc":[{"id":"1.195453765","rc":[{"atl":[[4.4,0]],"id":36386524}],"con":true,"img":false}]}
{"op":"mcm","clk":"5353169014","pt":1646210204417,"mc":[{"id":"1.195453765","rc":[{"atl":[[4.6,0]],"id":36386524}],"con":true,"img":false}]}
{"op":"mcm","clk":"5353169018","pt":1646210204520,"mc":[{"id":"1.195453765","rc":[{"atl":[[6,13.05],[6.6,8.93],[7,70.84]],"id":36386524}],"con":true,"img":false}]}
{"op":"mcm","clk":"5353169021","pt":1646210204623,"mc":[{"id":"1.195453765","rc":[{"atl":[[6.6,26.43]],"id":36386524}],"con":true,"img":false}]}
{"op":"mcm","clk":"5353169025","pt":1646210204725,"mc":[{"id":"1.195453765","rc":[{"atl":[[7,54.17]],"id":36386524}],"con":true,"img":false}]}
{"op":"mcm","clk":"5353169035","pt":1646210205033,"mc":[{"id":"1.195453765","rc":[{"atb":[[2.14,0]],"id":41207262},{"atb":[[2.58,4.76]],"id":43167130}],"con":true,"img":false}]}
{"op":"mcm","clk":"5353169040","pt":1646210205137,"mc":[{"id":"1.195453765","rc":[{"atb":[[2.1,57.13]],"id":41207262}],"con":true,"img":false}]}
{"op":"mcm","clk":"5353169049","pt":1646210205342,"mc":[{"id":"1.195453765","rc":[{"atb":[[2.12,25.82]],"id":41207262}],"con":true,"img":false}]}
{"op":"mcm","clk":"5353169079","pt":1646210205908,"mc":[{"id":"1.195453765","rc":[{"atb":[[2.12,0]],"id":41207262},{"atb":[[5,19.5]],"id":43167131}],"con":true,"img":false}]}
{"op":"mcm","clk":"5353169086","pt":1646210206060,"mc":[{"id":"1.195453765","rc":[{"atb":[[5.3,18.7]],"id":43167131}],"con":true,"img":false}]}
{"op":"mcm","clk":"5353169156","pt":1646210207455,"mc":[{"id":"1.195453765","rc":[{"atl":[[3.8,76.85],[3.75,73.2]],"id":41207262}],"con":true,"img":false}]}
{"op":"mcm","clk":"5353169205","pt":1646210208434,"mc":[{"id":"1.195453765","rc":[{"atb":[[2.54,0]],"id":43167130}],"con":true,"img":false}]}
{"op":"mcm","clk":"5353169209","pt":1646210208540,"mc":[{"id":"1.195453765","rc":[{"atb":[[2.6,1.67]],"id":43167130}],"con":true,"img":false}]}
{"op":"mcm","clk":"5353169280","pt":1646210209938,"mc":[{"id":"1.195453765","rc":[{"atb":[[2.06,189.38]],"id":41207262}],"con":true,"img":false}]}
{"op":"mcm","clk":"5353169285","pt":1646210210040,"mc":[{"id":"1.195453765","rc":[{"atb":[[2.1,2.5]],"id":41207262}],"con":true,"img":false}]}
{"op":"mcm","clk":"5353169325","pt":1646210210810,"mc":[{"id":"1.195453765","rc":[{"atb":[[2.12,25.82]],"id":41207262}],"con":true,"img":false}]}
{"op":"mcm","clk":"5353169359","pt":1646210211738,"mc":[{"id":"1.195453765","rc":[{"atb":[[2.06,76.03],[2.1,57.52]],"id":41207262}],"con":true,"img":false}]}
{"op":"mcm","clk":"5353169365","pt":1646210211842,"mc":[{"id":"1.195453765","rc":[{"atl":[[6.6,66.11],[7,17.5]],"id":36386524}],"con":true,"img":false}]}
{"op":"mcm","clk":"5353169389","pt":1646210212309,"mc":[{"id":"1.195453765","rc":[{"atb":[[1.32,77],[1.31,5]],"id":42401236}],"con":true,"img":false}]}
{"op":"mcm","clk":"5353169395","pt":1646210212415,"mc":[{"id":"1.195453765","rc":[{"atl":[[3.7,0],[3.65,25.79]],"id":41207262},{"atl":[[3.7,26.36]],"id":43167130}],"con":true,"img":false}]}
{"op":"mcm","clk":"5353169401","pt":1646210212516,"mc":[{"id":"1.195453765","rc":[{"atl":[[3.6,38.46]],"id":41207262}],"con":true,"img":false}]}
{"op":"mcm","clk":"5353169404","pt":1646210212620,"mc":[{"id":"1.195453765","rc":[{"atl":[[3.6,69.23],[3.8,44.63]],"id":41207262},{"atb":[[2.58,37.92]],"id":43167130}],"con":true,"img":false}]}
{"op":"mcm","clk":"5353169411","pt":1646210212722,"mc":[{"id":"1.195453765","rc":[{"atl":[[3.65,7.55]],"id":41207262},{"atb":[[2.52,2.17]],"id":43167130}],"con":true,"img":false}]}
{"op":"mcm","clk":"5353169452","pt":1646210213448,"mc":[{"id":"1.195453765","rc":[{"atb":[[2.54,6.43]],"id":43167130}],"con":true,"img":false}]}
{"op":"mcm","clk":"5353169459","pt":1646210213551,"mc":[{"id":"1.195453765","rc":[{"atb":[[2.52,68.5]],"id":43167130}],"con":true,"img":false}]}
{"op":"mcm","clk":"5353169469","pt":1646210213655,"mc":[{"id":"1.195453765","rc":[{"atb":[[2.44,2.5]],"id":43167130}],"con":true,"img":false}]}
{"op":"mcm","clk":"5353169482","pt":1646210213860,"mc":[{"id":"1.195453765","rc":[{"atb":[[2.14,7.32]],"id":41207262},{"atb":[[2.58,33.16]],"id":43167130}],"con":true,"img":false}]}
{"op":"mcm","clk":"5353169489","pt":1646210213960,"mc":[{"id":"1.195453765","rc":[{"atb":[[2.64,2.17],[2.52,66.33]],"id":43167130}],"con":true,"img":false}]}
{"op":"mcm","clk":"5353169493","pt":1646210214064,"mc":[{"id":"1.195453765","rc":[{"atl":[[3.6,76.92],[3.65,0]],"id":41207262},{"atl":[[3.7,7.41]],"id":43167130},{"atb":[[3.15,78.11]],"id":36386524}],"con":true,"img":false}]}
{"op":"mcm","clk":"5353169546","pt":1646210214942,"mc":[{"id":"1.195453765","rc":[{"atl":[[3.65,7.55]],"id":41207262},{"atl":[[3.7,26.36]],"id":43167130}],"con":true,"img":false}]}
{"op":"mcm","clk":"5353169554","pt":1646210215046,"mc":[{"id":"1.195453765","rc":[{"atl":[[3.6,69.23]],"id":41207262}],"con":true,"img":false}]}
{"op":"mcm","clk":"5353169571","pt":1646210215250,"mc":[{"id":"1.195453765","rc":[{"atl":[[3.65,0],[3.75,62.29]],"id":41207262},{"atb":[[2.14,0],[2.18,37],[2.2,0],[2.16,104.46]],"id":43167130}],"con":true,"img":false}]}
{"op":"mcm","clk":"5353169578","pt":1646210215455,"mc":[{"id":"1.195453765","rc":[{"atl":[[3.8,114.23]],"id":41207262},{"atb":[[2.6,0]],"id":43167130}],"con":true,"img":false}]}
{"op":"mcm","clk":"5353169583","pt":1646210215558,"mc":[{"id":"1.195453765","rc":[{"atl":[[3.75,7.27]],"id":41207262}],"con":true,"img":false}]}
{"op":"mcm","clk":"5353169590","pt":1646210215659,"mc":[{"id":"1.195453765","rc":[{"atb":[[2.66,1.67]],"id":43167130}],"con":true,"img":false}]}
{"op":"mcm","clk":"5353169702","pt":1646210217618,"mc":[{"id":"1.195453765","rc":[{"atl":[[3.8,149.94]],"id":41207262}],"con":true,"img":false}]}
{"op":"mcm","clk":"5353169706","pt":1646210217719,"mc":[{"id":"1.195453765","rc":[{"atl":[[3.6,30.77]],"id":41207262}],"con":true,"img":false}]}
{"op":"mcm","clk":"5353169711","pt":1646210217823,"mc":[{"id":"1.195453765","rc":[{"atl":[[3.6,0]],"id":41207262}],"con":true,"img":false}]}
{"op":"mcm","clk":"5353169719","pt":1646210217927,"mc":[{"id":"1.195453765","rc":[{"atb":[[2.12,0]],"id":41207262},{"atl":[[3.75,18.21]],"id":41207262}],"con":true,"img":false}]}
{"op":"mcm","clk":"5353169784","pt":1646210219361,"mc":[{"id":"1.195453765","rc":[{"atb":[[3.25,10.7],[3.15,64.15]],"id":36386524},{"atl":[[4.6,3]],"id":36386524}],"con":true,"img":false}]}
{"op":"mcm","clk":"5353169788","pt":1646210219462,"mc":[{"id":"1.195453765","rc":[{"atl":[[5.9,10.18],[6.2,25.58],[6.6,48.61]],"id":36386524}],"con":true,"img":false}]}
{"op":"mcm","clk":"5353169794","pt":1646210219566,"mc":[{"id":"1.195453765","rc":[{"atl":[[3.8,157.08]],"id":41207262},{"atl":[[4.4,2],[6.2,54.96],[6.6,8.93]],"id":36386524}],"con":true,"img":false}]}
{"op":"mcm","clk":"5353169800","pt":1646210219668,"mc":[{"id":"1.195453765","rc":[{"atl":[[3.8,112.44],[3.75,10.94]],"id":41207262},{"atl":[[4.6,0],[6,0]],"id":36386524}],"con":true,"img":false}]}
{"op":"mcm","clk":"5353169806","pt":1646210219824,"mc":[{"id":"1.195453765","rc":[{"atb":[[2.14,13.92]],"id":41207262},{"atb":[[2.64,6.76]],"id":43167130},{"atb":[[1.35,24]],"id":42401236}],"con":true,"img":false}]}
{"op":"mcm","clk":"5353169826","pt":1646210220239,"mc":[{"id":"1.195453765","rc":[{"atb":[[2.54,0]],"id":43167130}],"con":true,"img":false}]}
{"op":"mcm","clk":"5353169848","pt":1646210220754,"mc":[{"id":"1.195453765","rc":[{"atl":[[4.3,3]],"id":36386524}],"con":true,"img":false}]}
{"op":"mcm","clk":"5353169864","pt":1646210221163,"mc":[{"id":"1.195453765","rc":[{"atl":[[4.3,10.66],[5.9,36.28],[6.2,25.58]],"id":36386524}],"con":true,"img":false}]}
{"op":"mcm","clk":"5353169878","pt":1646210221473,"mc":[{"id":"1.195453765","rc":[{"atl":[[5.9,26.1]],"id":36386524}],"con":true,"img":false}]}
{"op":"mcm","clk":"5353169902","pt":1646210221939,"mc":[{"id":"1.195453765","rc":[{"atl":[[32,0],[29,1.12]],"id":36010178}],"con":true,"img":false}]}
{"op":"mcm","clk":"5353169907","pt":1646210222046,"mc":[{"id":"1.195453765","rc":[{"atl":[[20,12.67]],"id":43167131}],"con":true,"img":false}]}
{"op":"mcm","clk":"5353169912","pt":1646210222145,"mc":[{"id":"1.195453765","rc":[{"atl":[[19.5,5.22]],"id":43167131}],"con":true,"img":false}]}
{"op":"mcm","clk":"5353169950","pt":1646210222764,"mc":[{"id":"1.195453765","rc":[{"atl":[[3.85,52.63],[3.8,76.73]],"id":41207262}],"con":true,"img":false}]}
{"op":"mcm","clk":"5353169956","pt":1646210222867,"mc":[{"id":"1.195453765","rc":[{"atb":[[2.16,22.13]],"id":41207262}],"con":true,"img":false}]}
{"op":"mcm","clk":"5353169969","pt":1646210223074,"mc":[{"id":"1.195453765","rc":[{"atb":[[2.14,74.77],[2.1,2.5]],"id":41207262}],"con":true,"img":false}]}
{"op":"mcm","clk":"5353169980","pt":1646210223227,"mc":[{"id":"1.195453765","rc":[{"atl":[[3.85,122.77],[3.8,7.14]],"id":41207262}],"con":true,"img":false}]}
{"op":"mcm","clk":"5353169984","pt":1646210223331,"mc":[{"id":"1.195453765","rc":[{"atl":[[3.85,112.25],[3.8,0]],"id":41207262}],"con":true,"img":false}]}
{"op":"mcm","clk":"5353169986","pt":1646210223430,"mc":[{"id":"1.195453765","rc":[{"atl":[[4.2,4]],"id":36386524}],"con":true,"img":false}]}
{"op":"mcm","clk":"5353169993","pt":1646210223533,"mc":[{"id":"1.195453765","rc":[{"atl":[[3.75,0]],"id":41207262}],"con":true,"img":false}]}
{"op":"mcm","clk":"5353169997","pt":1646210223637,"mc":[{"id":"1.195453765","rc":[{"atl":[[5.5,2.5],[3.8,19.4],[5.9,5]],"id":41207262}],"con":true,"img":false}]}
{"op":"mcm","clk":"5353170012","pt":1646210223948,"mc":[{"id":"1.195453765","rc":[{"atl":[[7.2,0]],"id":36386524}],"con":true,"img":false}]}
{"op":"mcm","clk":"5353170019","pt":1646210224052,"mc":[{"id":"1.195453765","rc":[{"atl":[[6.8,7.04]],"id":36386524}],"con":true,"img":false}]}
{"op":"mcm","clk":"5353170099","pt":1646210225649,"mc":[{"id":"1.195453765","rc":[{"atb":[[2.54,13.87]],"id":40209251}],"con":true,"img":false}]}
{"op":"mcm","clk":"5353170103","pt":1646210225779,"mc":[{"id":"1.195453765","rc":[{"atb":[[2.5,2.17],[2.52,47.86]],"id":40209251}],"con":true,"img":false}]}
{"op":"mcm","clk":"5353170109","pt":1646210225957,"mc":[{"id":"1.195453765","rc":[{"atl":[[5.4,22.73]],"id":40209251},{"atb":[[2.98,63.13]],"id":36386524}],"con":true,"img":false}]}
{"op":"mcm","clk":"5353170113","pt":1646210226062,"mc":[{"id":"1.195453765","rc":[{"atl":[[4.7,9.09]],"id":40209251},{"atb":[[2.88,22.05]],"id":36386524}],"con":true,"img":false}]}
{"op":"mcm","clk":"5353170154","pt":1646210226937,"mc":[{"id":"1.195453765","rc":[{"atb":[[2.14,68.17]],"id":41207262},{"atb":[[1.35,21.5],[1.36,2.5],[1.27,0],[1.32,82],[1.31,0]],"id":42401236},{"atb":[[2.34,6.23]],"id":40209251}],"con":true,"img":false}]}
{"op":"mcm","clk":"5353170158","pt":1646210227037,"mc":[{"id":"1.195453765","rc":[{"atb":[[2.64,11.85]],"id":43167130}],"con":true,"img":false}]}
{"op":"mcm","clk":"5353170161","pt":1646210227141,"mc":[{"id":"1.195453765","rc":[{"atb":[[2.1,0]],"id":41207262},{"atb":[[5.6,2.5]],"id":43167131},{"atl":[[6.2,23.08],[7,12.5]],"id":36386524}],"con":true,"img":false}]}
{"op":"mcm","clk":"5353170166","pt":1646210227245,"mc":[{"id":"1.195453765","rc":[{"atb":[[1.35,45.36]],"id":42401236},{"atb":[[5,0],[5.2,47.66],[5.4,14.27]],"id":43167131}],"con":true,"img":false}]}
{"op":"mcm","clk":"5353170177","pt":1646210227453,"mc":[{"id":"1.195453765","rc":[{"spn":3.03,"spf":"NaN","id":41207262},{"spn":3.18,"spf":"NaN","id":43167130},{"spn":1.82,"spf":"NaN","id":42401236},{"atb":[[5.3,12.06]],"id":43167131},{"spn":10.55,"spf":"NaN","id":43167131},{"spn":20.0,"spf":"NaN","id":36010178},{"spn":3.75,"spf":"NaN","id":36386524}],"con":true,"img":false}]}
{"op":"mcm","clk":"5353170198","pt":1646210227865,"mc":[{"id":"1.195453765","rc":[{"atl":[[3.85,77.16],[5,25]],"id":41207262}],"con":true,"img":false}]}
{"op":"mcm","clk":"5353170202","pt":1646210227965,"mc":[{"id":"1.195453765","rc":[{"atb":[[2.02,19.61],[2.06,57.16],[1.93,130.3]],"id":41207262},{"atl":[[6.4,2.24],[7.6,29.54],[3.65,3]],"id":41207262},{"atl":[[8.6,26.09],[7,0]],"id":43167130},{"atb":[[1.18,93.88],[1.21,95.24]],"id":42401236},{"atb":[[4.8,5]],"id":43167131},{"atl":[[22,1],[25,7.6]],"id":43167131},{"atb":[[2.22,0],[2.18,34.17]],"id":40209251},{"atl":[[7.8,0],[9.4,23.47]],"id":40209251},{"atb":[[1.01,2.53]],"id":36010178},{"atl":[[60,0]],"id":36010178},{"atb":[[2.5,0],[2.3,51.58]],"id":36386524},{"atl":[[4.3,7.66],[12.5,14.9],[4.4,0],[4.1,4],[4.2,0]],"id":36386524}],"con":true,"img":false}]}
{"op":"mcm","clk":"5353170209","pt":1646210228072,"mc":[{"id":"1.195453765","rc":[{"atb":[[1.74,70.41]],"id":41207262},{"atb":[[4.4,16.49]],"id":43167131},{"atl":[[190,2.72]],"id":36010178},{"atb":[[3.25,19.59]],"id":36386524},{"atl":[[6,2.5]],"id":36386524}],"con":true,"img":false}]}
{"op":"mcm","clk":"5353170214","pt":1646210228170,"mc":[{"id":"1.195453765","rc":[{"atl":[[3.6,3]],"id":41207262},{"atb":[[1.01,1.69]],"id":36010178},{"atl":[[4.1,0]],"id":36386524}],"con":true,"img":false}]}
{"op":"mcm","clk":"5353170225","pt":1646210228378,"mc":[{"id":"1.195453765","rc":[{"atl":[[3.85,7.02],[3.8,76.16]],"id":41207262},{"atb":[[1.01,0]],"id":36010178},{"atl":[[5.9,0],[6,45.88]],"id":36386524}],"con":true,"img":false}]}
{"op":"mcm","clk":"5353170231","pt":1646210228476,"mc":[{"id":"1.195453765","rc":[{"atb":[[11.5,1.69]],"id":36010178},{"atl":[[4.3,0]],"id":36386524}],"con":true,"img":false}]}
{"op":"mcm","clk":"5353170238","pt":1646210228581,"mc":[{"id":"1.195453765","rc":[{"atl":[[5.9,16.33]],"id":36386524}],"con":true,"img":false}]}
{"op":"mcm","clk":"5353170243","pt":1646210228638,"mc":[{"id":"1.195453765","rc":[{"atb":[[8.8,15.15]],"id":36010178},{"atl":[[6.6,26.79]],"id":36386524}],"con":true,"img":false}]}
{"op":"mcm","clk":"5353170249","pt":1646210228744,"mc":[{"id":"1.195453765","rc":[{"atb":[[8.6,7.97]],"id":36010178},{"atl":[[6.2,3.85]],"id":36386524}],"con":true,"img":false}]}
{"op":"mcm","clk":"5353170254","pt":1646210228840,"mc":[{"id":"1.195453765","rc":[{"atb":[[1.35,96.36],[1.32,31]],"id":42401236},{"atl":[[14.5,14.66],[6.2,48.05]],"id":36386524}],"con":true,"img":false}]}
{"op":"mcm","clk":"5353170262","pt":1646210228947,"mc":[{"id":"1.195453765","rc":[{"atb":[[2.18,0]],"id":40209251},{"atl":[[12.5,0],[6,2.5]],"id":36386524}],"con":true,"img":false}]}
{"op":"mcm","clk":"5353170268","pt":1646210229050,"mc":[{"id":"1.195453765","rc":[{"atb":[[2.64,43.26]],"id":43167130},{"atb":[[2.08,34.17]],"id":40209251}],"con":true,"img":false}]}
{"op":"mcm","clk":"5353170273","pt":1646210229157,"mc":[{"id":"1.195453765","rc":[{"atl":[[3.6,17.83]],"id":41207262}],"con":true,"img":false}]}
{"op":"mcm","clk":"5353170279","pt":1646210229256,"mc":[{"id":"1.195453765","rc":[{"atb":[[2.58,0]],"id":43167130}],"con":true,"img":false}]}
{"op":"mcm","clk":"5353170283","pt":1646210229361,"mc":[{"id":"1.195453765","rc":[{"atl":[[3.8,56.76]],"id":41207262}],"con":true,"img":false}]}
{"op":"mcm","clk":"5353170287","pt":1646210229465,"mc":[{"id":"1.195453765","rc":[{"atb":[[2.44,109.45],[2.52,0]],"id":43167130}],"con":true,"img":false}]}
{"op":"mcm","clk":"5353170329","pt":1646210230335,"mc":[{"id":"1.195453765","rc":[{"atb":[[1.32,5]],"id":42401236}],"con":true,"img":false}]}
{"op":"mcm","clk":"5353170333","pt":1646210230486,"mc":[{"id":"1.195453765","rc":[{"atl":[[3.8,81.76],[5,0]],"id":41207262}],"con":true,"img":false}]}
{"op":"mcm","clk":"5353170371","pt":1646210231162,"mc":[{"id":"1.195453765","rc":[{"atl":[[3.55,3]],"id":41207262}],"con":true,"img":false}]}
{"op":"mcm","clk":"5353170380","pt":1646210231268,"mc":[{"id":"1.195453765","rc":[{"atl":[[3.65,38.66]],"id":41207262}],"con":true,"img":false}]}
{"op":"mcm","clk":"5353170390","pt":1646210231371,"mc":[{"id":"1.195453765","rc":[{"atl":[[3.8,56.76]],"id":41207262}],"con":true,"img":false}]}
{"op":"mcm","clk":"5353170416","pt":1646210231880,"mc":[{"id":"1.195453765","rc":[{"atl":[[3.8,0],[3.65,99.51]],"id":41207262},{"atb":[[2.64,38.67]],"id":43167130},{"atb":[[1.35,74.86]],"id":42401236}],"con":true,"img":false}]}
{"op":"mcm","clk":"5353170419","pt":1646210231981,"mc":[{"id":"1.195453765","rc":[{"atl":[[5.1,0]],"id":41207262},{"atb":[[1.99,41.37]],"id":43167130},{"atl":[[5.6,2.63]],"id":43167130},{"atl":[[2.58,0]],"id":42401236},{"atl":[[4.7,0]],"id":40209251},{"atl":[[19.5,2.5]],"id":43167131},{"atb":[[11,0]],"id":36010178}],"con":true,"img":false}]}
{"op":"mcm","clk":"5353170506","pt":1646210233475,"mc":[{"id":"1.195453765","rc":[{"atb":[[5.3,10.39]],"id":43167131}],"con":true,"img":false}]}
{"op":"mcm","clk":"5353170511","pt":1646210233580,"mc":[{"id":"1.195453765","rc":[{"atb":[[5.7,1.67]],"id":43167131}],"con":true,"img":false}]}
{"op":"mcm","clk":"5353170546","pt":1646210234350,"mc":[{"id":"1.195453765","rc":[{"atl":[[3.55,28.95]],"id":41207262}],"con":true,"img":false}]}
{"op":"mcm","clk":"5353170554","pt":1646210234457,"mc":[{"id":"1.195453765","rc":[{"atl":[[3.6,3]],"id":41207262}],"con":true,"img":false}]}
{"op":"mcm","clk":"5353170560","pt":1646210234663,"mc":[{"id":"1.195453765","rc":[{"atl":[[3.5,2]],"id":41207262}],"con":true,"img":false}]}
{"op":"mcm","clk":"5353170568","pt":1646210234870,"mc":[{"id":"1.195453765","rc":[{"atb":[[2.18,6.37]],"id":41207262},{"atl":[[3.8,7.14],[3.45,3],[3.65,96.51]],"id":41207262},{"atb":[[2.58,4.76]],"id":40209251}],"con":true,"img":false}]}
{"op":"mcm","clk":"5353170574","pt":1646210234971,"mc":[{"id":"1.195453765","rc":[{"atl":[[3.55,57.9]],"id":41207262},{"atb":[[1.39,13]],"id":42401236}],"con":true,"img":false}]}
{"op":"mcm","clk":"5353170580","pt":1646210235083,"mc":[{"id":"1.195453765","rc":[{"atb":[[2.14,7.32],[2.16,59.34]],"id":41207262},{"atl":[[3.65,60.85]],"id":41207262}],"con":true,"img":false}]}
{"op":"mcm","clk":"5353170585","pt":1646210235177,"mc":[{"id":"1.195453765","rc":[{"atb":[[1.39,34.32]],"id":42401236}],"con":true,"img":false}]}
{"op":"mcm","clk":"5353170599","pt":1646210235381,"mc":[{"id":"1.195453765","rc":[{"atb":[[1.38,2.17]],"id":42401236}],"con":true,"img":false}]}
{"op":"mcm","clk":"5353170629","pt":1646210235950,"mc":[{"id":"1.195453765","rc":[{"atb":[[2.04,0]],"id":41207262}],"con":true,"img":false}]}
{"op":"mcm","clk":"5353170638","pt":1646210236052,"mc":[{"id":"1.195453765","rc":[{"atb":[[2,44.11]],"id":41207262},{"atb":[[11.5,0]],"id":36010178}],"con":true,"img":false}]}
{"op":"mcm","clk":"5353170647","pt":1646210236155,"mc":[{"id":"1.195453765","rc":[{"atb":[[8.8,25.41]],"id":36010178},{"atl":[[28,2.96]],"id":36010178}],"con":true,"img":false}]}
{"op":"mcm","clk":"5353170659","pt":1646210236256,"mc":[{"id":"1.195453765","rc":[{"atl":[[38,2.5],[30,9.3]],"id":36010178}],"con":true,"img":false}]}
{"op":"mcm","clk":"5353170670","pt":1646210236361,"mc":[{"id":"1.195453765","rc":[{"atb":[[7.6,37.26],[8.8,15.03]],"id":36010178},{"atl":[[6.2,67.28],[6.6,8.93]],"id":36386524}],"con":true,"img":false}]}
{"op":"mcm","clk":"5353170676","pt":1646210236463,"mc":[{"id":"1.195453765","rc":[{"atb":[[1.01,2.53]],"id":36010178}],"con":true,"img":false}]}
{"op":"mcm","clk":"5353170688","pt":1646210236666,"mc":[{"id":"1.195453765","rc":[{"atb":[[1.01,1.69]],"id":36010178}],"con":true,"img":false}]}
{"op":"mcm","clk":"5353170697","pt":1646210236872,"mc":[{"id":"1.195453765","rc":[{"atb":[[1.01,0]],"id":36010178}],"con":true,"img":false}]}
{"op":"mcm","clk":"5353170700","pt":1646210236973,"mc":[{"id":"1.195453765","rc":[{"atb":[[12,1.69]],"id":36010178}],"con":true,"img":false}]}
{"op":"mcm","clk":"5353170706","pt":1646210237075,"mc":[{"id":"1.195453765","rc":[{"atb":[[2.36,105.07]],"id":43167130}],"con":true,"img":false}]}
{"op":"mcm","clk":"5353170712","pt":1646210237179,"mc":[{"id":"1.195453765","rc":[{"atb":[[2.44,2.5]],"id":43167130},{"atl":[[28,0]],"id":36010178}],"con":true,"img":false}]}
{"op":"mcm","clk":"5353170730","pt":1646210237486,"mc":[{"id":"1.195453765","rc":[{"atb":[[2.16,37.21]],"id":41207262},{"atb":[[2.54,0]],"id":40209251}],"con":true,"img":false}]}
{"op":"mcm","clk":"5353170765","pt":1646210237951,"mc":[{"id":"1.195453765","rc":[{"atb":[[2.18,0]],"id":41207262},{"atb":[[2.7,4.42]],"id":43167130},{"atb":[[1.38,21.97]],"id":42401236},{"atb":[[3.15,78.11]],"id":36386524},{"atl":[[6.8,0]],"id":36386524}],"con":true,"img":false}]}
{"op":"mcm","clk":"5353170774","pt":1646210238156,"mc":[{"id":"1.195453765","rc":[{"atb":[[1.42,2.17],[1.38,19.8]],"id":42401236}],"con":true,"img":false}]}
{"op":"mcm","clk":"5353170843","pt":1646210239387,"mc":[{"id":"1.195453765","rc":[{"atb":[[2.66,0]],"id":43167130}],"con":true,"img":false}]}
{"op":"mcm","clk":"5353170857","pt":1646210239592,"mc":[{"id":"1.195453765","rc":[{"atl":[[3.55,96.54],[3.65,0]],"id":41207262},{"atb":[[2.72,1.67]],"id":43167130}],"con":true,"img":false}]}
{"op":"mcm","clk":"5353170870","pt":1646210239758,"mc":[{"id":"1.195453765","rc":[{"atb":[[3.25,10.7],[3.15,64.15]],"id":36386524},{"atl":[[4.6,2]],"id":36386524}],"con":true,"img":false}]}
{"op":"mcm","clk":"5353170875","pt":1646210239862,"mc":[{"id":"1.195453765","rc":[{"atl":[[3.8,0],[3.65,3]],"id":41207262},{"atl":[[3.15,72.45]],"id":42401236},{"atb":[[8.8,23.6]],"id":36010178},{"atl":[[29,3.98]],"id":36010178},{"atl":[[5.8,7.29],[4.4,2],[4.6,0],[6.2,23.08],[6,31.88]],"id":36386524}],"con":true,"img":false}]}
{"op":"mcm","clk":"5353170879","pt":1646210239955,"mc":[{"id":"1.195453765","rc":[{"atl":[[3.45,0]],"id":41207262}],"con":true,"img":false}]}
{"op":"mcm","clk":"5353170885","pt":1646210240060,"mc":[{"id":"1.195453765","rc":[{"atl":[[3.6,41.46],[3.55,67.59]],"id":41207262},{"atl":[[5.9,0]],"id":36386524}],"con":true,"img":false}]}
{"op":"mcm","clk":"5353170892","pt":1646210240163,"mc":[{"id":"1.195453765","rc":[{"atl":[[3.5,16.83]],"id":41207262}],"con":true,"img":false}]}
{"op":"mcm","clk":"5353170897","pt":1646210240367,"mc":[{"id":"1.195453765","rc":[{"atl":[[3.55,41.64]],"id":41207262}],"con":true,"img":false}]}
{"op":"mcm","clk":"5353170963","pt":1646210241855,"mc":[{"id":"1.195453765","rc":[{"atb":[[7.8,15.76]],"id":36010178}],"con":true,"img":false}]}
{"op":"mcm","clk":"5353170968","pt":1646210241960,"mc":[{"id":"1.195453765","rc":[{"atb":[[8.8,10.26]],"id":36010178}],"con":true,"img":false}]}
{"op":"mcm","clk":"5353171000","pt":1646210242678,"mc":[{"id":"1.195453765","rc":[{"atb":[[2.14,90.8]],"id":41207262}],"con":true,"img":false}]}
{"op":"mcm","clk":"5353171002","pt":1646210242779,"mc":[{"id":"1.195453765","rc":[{"atb":[[2.16,0]],"id":41207262}],"con":true,"img":false}]}
{"op":"mcm","clk":"5353171005","pt":1646210242883,"mc":[{"id":"1.195453765","rc":[{"atb":[[2.12,2.5],[2.18,20.28]],"id":41207262},{"atb":[[2.62,10.49]],"id":40209251}],"con":true,"img":false}]}
{"op":"mcm","clk":"5353171019","pt":1646210243090,"mc":[{"id":"1.195453765","rc":[{"atb":[[2.58,43.2],[2.62,29.71],[2.52,5]],"id":40209251}],"con":true,"img":false}]}
{"op":"mcm","clk":"5353171034","pt":1646210243296,"mc":[{"id":"1.195453765","rc":[{"atb":[[2.6,2.5]],"id":40209251}],"con":true,"img":false}]}
{"op":"mcm","clk":"5353171043","pt":1646210243499,"mc":[{"id":"1.195453765","rc":[{"atb":[[5.3,35.53],[5.2,19.12],[5.7,8.31]],"id":43167131}],"con":true,"img":false}]}
{"op":"mcm","clk":"5353171056","pt":1646210243660,"mc":[{"id":"1.195453765","rc":[{"atb":[[5.4,0]],"id":43167131}],"con":true,"img":false}]}
{"op":"mcm","clk":"5353171070","pt":1646210243864,"mc":[{"id":"1.195453765","rc":[{"atb":[[2.58,38.44]],"id":40209251},{"atb":[[12,0]],"id":36010178},{"atl":[[38,9.99],[30,0]],"id":36010178},{"atb":[[2.88,0]],"id":36386524}],"con":true,"img":false}]}
{"op":"mcm","clk":"5353171076","pt":1646210243970,"mc":[{"id":"1.195453765","rc":[{"atb":[[2.62,22.05]],"id":36386524}],"con":true,"img":false}]}
{"op":"mcm","clk":"5353171114","pt":1646210244785,"mc":[{"id":"1.195453765","rc":[{"atb":[[7.6,20.86],[7.8,42.7]],"id":36010178},{"atl":[[4.4,12.88]],"id":36386524}],"con":true,"img":false}]}
{"op":"mcm","clk":"5353171118","pt":1646210244891,"mc":[{"id":"1.195453765","rc":[{"atb":[[1.99,50.51]],"id":41207262},{"atl":[[3.95,16.95]],"id":41207262}],"con":true,"img":false}]}
{"op":"mcm","clk":"5353171121","pt":1646210244990,"mc":[{"id":"1.195453765","rc":[{"atb":[[1.35,23.86],[1.38,72.66]],"id":42401236},{"atl":[[5.8,0]],"id":36386524}],"con":true,"img":false}]}
{"op":"mcm","clk":"5353171126","pt":1646210245093,"mc":[{"id":"1.195453765","rc":[{"atb":[[1.01,2.53]],"id":36010178}],"con":true,"img":false}]}
{"op":"mcm","clk":"5353171135","pt":1646210245296,"mc":[{"id":"1.195453765","rc":[{"atb":[[2.7,29.09]],"id":43167130}],"con":true,"img":false}]}
{"op":"mcm","clk":"5353171144","pt":1646210245401,"mc":[{"id":"1.195453765","rc":[{"atb":[[2.64,7.26]],"id":43167130},{"atb":[[9,1.67],[1.01,1.69]],"id":36010178}],"con":true,"img":false}]}
{"op":"mcm","clk":"5353171154","pt":1646210245560,"mc":[{"id":"1.195453765","rc":[{"atb":[[1.01,0]],"id":36010178}],"con":true,"img":false}]}
{"op":"mcm","clk":"5353171160","pt":1646210245664,"mc":[{"id":"1.195453765","rc":[{"atb":[[2.44,68.83],[2.36,5]],"id":43167130},{"atb":[[9,3.36]],"id":36010178}],"con":true,"img":false}]}
{"op":"mcm","clk":"5353171167","pt":1646210245767,"mc":[{"id":"1.195453765","rc":[{"atb":[[2.14,83.48]],"id":41207262},{"atb":[[2.34,0]],"id":40209251}],"con":true,"img":false}]}
{"op":"mcm","clk":"5353171211","pt":1646210246484,"mc":[{"id":"1.195453765","rc":[{"atb":[[2.2,39.53]],"id":41207262},{"atb":[[1.4,72.99]],"id":42401236},{"atb":[[2.64,20.99]],"id":40209251},{"atb":[[5.7,16.64]],"id":43167131}],"con":true,"img":false}]}
{"op":"mcm","clk":"5353171234","pt":1646210246999,"mc":[{"id":"1.195453765","rc":[{"atb":[[2.7,24.67]],"id":43167130},{"atb":[[1.38,52.86]],"id":42401236}],"con":true,"img":false}]}
{"op":"mcm","clk":"5353171238","pt":1646210247102,"mc":[{"id":"1.195453765","rc":[{"atl":[[3.6,121.21],[3.55,3]],"id":41207262}],"con":true,"img":false}]}
{"op":"mcm","clk":"5353171246","pt":1646210247202,"mc":[{"id":"1.195453765","rc":[{"atb":[[3.25,19.59]],"id":36386524},{"atl":[[4.3,4],[4.4,10.88]],"id":36386524}],"con":true,"img":false}]}
{"op":"mcm","clk":"5353171256","pt":1646210247365,"mc":[{"id":"1.195453765","rc":[{"atl":[[4.3,0]],"id":36386524}],"con":true,"img":false}]}
{"op":"mcm","clk":"5353171259","pt":1646210247464,"mc":[{"id":"1.195453765","rc":[{"atl":[[6.2,69.43],[6,2.5]],"id":36386524}],"con":true,"img":false}]}
{"op":"mcm","clk":"5353171267","pt":1646210247672,"mc":[{"id":"1.195453765","rc":[{"atl":[[4.4,0]],"id":36386524}],"con":true,"img":false}]}
{"op":"mcm","clk":"5353171272","pt":1646210247776,"mc":[{"id":"1.195453765","rc":[{"atl":[[6.2,50.2],[6,16.08],[6.6,26.79]],"id":36386524}],"con":true,"img":false}]}
{"op":"mcm","clk":"5353171275","pt":1646210247873,"mc":[{"id":"1.195453765","rc":[{"atl":[[3.7,77.11]],"id":42401236}],"con":true,"img":false}]}
{"op":"mcm","clk":"5353171281","pt":1646210247982,"mc":[{"id":"1.195453765","rc":[{"atl":[[3.15,0]],"id":42401236}],"con":true,"img":false}]}
{"op":"mcm","clk":"5353171378","pt":1646210249888,"mc":[{"id":"1.195453765","rc":[{"atb":[[2.68,4.47]],"id":40209251}],"con":true,"img":false}]}
{"op":"mcm","clk":"5353171386","pt":1646210250092,"mc":[{"id":"1.195453765","rc":[{"atb":[[2.18,0]],"id":41207262},{"atb":[[1.39,21.32]],"id":42401236},{"atb":[[2.62,20.89]],"id":40209251}],"con":true,"img":false}]}
{"op":"mcm","clk":"5353171392","pt":1646210250193,"mc":[{"id":"1.195453765","rc":[{"atb":[[3.3,22.29]],"id":36386524}],"con":true,"img":false}]}
{"op":"mcm","clk":"5353171410","pt":1646210250401,"mc":[{"id":"1.195453765","rc":[{"atb":[[3.2,70.06],[3.15,37.48],[3.3,52.96]],"id":36386524}],"con":true,"img":false}]}
{"op":"mcm","clk":"5353171422","pt":1646210250604,"mc":[{"id":"1.195453765","rc":[{"atb":[[3.25,8.89]],"id":36386524}],"con":true,"img":false}]}
{"op":"mcm","clk":"5353171452","pt":1646210251175,"mc":[{"id":"1.195453765","rc":[{"atb":[[1.42,29.73]],"id":42401236}],"con":true,"img":false}]}
{"op":"mcm","clk":"5353171459","pt":1646210251376,"mc":[{"id":"1.195453765","rc":[{"atb":[[1.39,0]],"id":42401236},{"atb":[[2.62,19.22]],"id":40209251},{"atl":[[38,2.5],[46,6.56]],"id":36010178}],"con":true,"img":false}]}
{"op":"mcm","clk":"5353171462","pt":1646210251480,"mc":[{"id":"1.195453765","rc":[{"atb":[[2.7,1.67]],"id":40209251}],"con":true,"img":false}]}
{"op":"mcm","clk":"5353171500","pt":1646210252201,"mc":[{"id":"1.195453765","rc":[{"atb":[[9,11.28]],"id":36010178}],"con":true,"img":false}]}
{"op":"mcm","clk":"5353171510","pt":1646210252405,"mc":[{"id":"1.195453765","rc":[{"atb":[[8.6,29.78],[8.8,0],[7.8,15.76]],"id":36010178}],"con":true,"img":false}]}
{"op":"mcm","clk":"5353171529","pt":1646210252768,"mc":[{"id":"1.195453765","rc":[{"atl":[[3.8,7.14],[3.45,2],[3.65,0]],"id":41207262},{"atb":[[2.64,0]],"id":40209251}],"con":true,"img":false}]}
{"op":"mcm","clk":"5353171534","pt":1646210252872,"mc":[{"id":"1.195453765","rc":[{"atl":[[3.6,41.46],[3.55,55.9],[3.45,16.83]],"id":41207262}],"con":true,"img":false}]}
{"op":"mcm","clk":"5353171537","pt":1646210252972,"mc":[{"id":"1.195453765","rc":[{"atb":[[2.26,7.64]],"id":41207262},{"atb":[[2.5,5.01]],"id":43167130},{"atb":[[1.43,17.5]],"id":42401236},{"atb":[[2.68,0]],"id":40209251},{"atb":[[3.2,66.64]],"id":36386524}],"con":true,"img":false}]}
{"op":"mcm","clk":"5353171541","pt":1646210253075,"mc":[{"id":"1.195453765","rc":[{"atb":[[2.26,32.88],[2.14,0],[2.2,90.02]],"id":41207262},{"atl":[[3.5,2]],"id":41207262},{"atb":[[2.5,71.31],[2.44,2.5]],"id":43167130}],"con":true,"img":false}]}
{"op":"mcm","clk":"5353171553","pt":1646210253281,"mc":[{"id":"1.195453765","rc":[{"atb":[[2.24,2.17]],"id":41207262}],"con":true,"img":false}]}
{"op":"mcm","clk":"5353171579","pt":1646210254104,"mc":[{"id":"1.195453765","rc":[{"atb":[[2.32,2.17],[2.24,0]],"id":41207262},{"atb":[[1.46,2.17],[1.42,27.56]],"id":42401236}],"con":true,"img":false}]}
{"op":"mcm","clk":"5353171631","pt":1646210254989,"mc":[{"id":"1.195453765","rc":[{"atb":[[9,9.59]],"id":36010178},{"atl":[[6.2,3.85],[6.6,71.14]],"id":36386524}],"con":true,"img":false}]}
{"op":"mcm","clk":"5353171634","pt":1646210255084,"mc":[{"id":"1.195453765","rc":[{"atb":[[2.16,22.13]],"id":41207262},{"atb":[[1.43,38.32]],"id":42401236},{"atb":[[2.7,5.97]],"id":40209251}],"con":true,"img":false}]}
{"op":"mcm","clk":"5353171640","pt":1646210255189,"mc":[{"id":"1.195453765","rc":[{"atb":[[2.64,2.17]],"id":43167130},{"atb":[[1.35,0]],"id":42401236}],"con":true,"img":false}]}
{"op":"mcm","clk":"5353171643","pt":1646210255288,"mc":[{"id":"1.195453765","rc":[{"atb":[[1.4,0]],"id":42401236}],"con":true,"img":false}]}
{"op":"mcm","clk":"5353171653","pt":1646210255502,"mc":[{"id":"1.195453765","rc":[{"atb":[[1.01,2.53]],"id":36010178}],"con":true,"img":false}]}
{"op":"mcm","clk":"5353171659","pt":1646210255597,"mc":[{"id":"1.195453765","rc":[{"atb":[[1.01,1.69]],"id":36010178}],"con":true,"img":false}]}
{"op":"mcm","clk":"5353171667","pt":1646210255806,"mc":[{"id":"1.195453765","rc":[{"atb":[[1.01,0]],"id":36010178}],"con":true,"img":false}]}
{"op":"mcm","clk":"5353171673","pt":1646210255907,"mc":[{"id":"1.195453765","rc":[{"atb":[[9.2,1.69]],"id":36010178}],"con":true,"img":false}]}
{"op":"mcm","clk":"5353171679","pt":1646210256010,"mc":[{"id":"1.195453765","rc":[{"atb":[[2.5,66.3]],"id":43167130},{"atb":[[1.43,20.81]],"id":42401236}],"con":true,"img":false}]}
{"op":"mcm","clk":"5353171738","pt":1646210257199,"mc":[{"id":"1.195453765","rc":[{"atb":[[3.15,51.44]],"id":36386524}],"con":true,"img":false}]}
{"op":"mcm","clk":"5353171746","pt":1646210257404,"mc":[{"id":"1.195453765","rc":[{"atb":[[2.26,31.21]],"id":41207262},{"atb":[[9,7.92]],"id":36010178},{"atb":[[3.25,0],[3.15,37.48]],"id":36386524},{"atl":[[4.6,4]],"id":36386524}],"con":true,"img":false}]}
{"op":"mcm","clk":"5353171752","pt":1646210257506,"mc":[{"id":"1.195453765","rc":[{"atl":[[5.9,16.33],[6.2,23.08]],"id":36386524}],"con":true,"img":false}]}
{"op":"mcm","clk":"5353171759","pt":1646210257606,"mc":[{"id":"1.195453765","rc":[{"atb":[[2.34,1.67]],"id":41207262},{"atl":[[3.8,0],[3.45,0],[3.65,3]],"id":41207262},{"atb":[[9.4,1.67]],"id":36010178},{"atl":[[4.4,2],[4.6,0],[6.2,70.59],[6.6,8.93]],"id":36386524}],"con":true,"img":false}]}
{"op":"mcm","clk":"5353171765","pt":1646210257710,"mc":[{"id":"1.195453765","rc":[{"atl":[[3.5,34]],"id":41207262},{"atl":[[5.9,32.66],[6.2,51.36],[6,2.5]],"id":36386524}],"con":true,"img":false}]}
{"op":"mcm","clk":"5353171773","pt":1646210257812,"mc":[{"id":"1.195453765","rc":[{"atl":[[3.6,123.32],[3.55,3]],"id":41207262},{"atb":[[3.2,3.8],[3.15,118.19]],"id":36386524}],"con":true,"img":false}]}
{"op":"mcm","clk":"5353171780","pt":1646210257868,"mc":[{"id":"1.195453765","rc":[{"atb":[[2.2,50.49]],"id":41207262},{"atb":[[2.52,25.13],[2.18,0]],"id":43167130},{"atb":[[2.64,17.92]],"id":40209251},{"atl":[[4.3,3]],"id":36386524}],"con":true,"img":false}]}
{"op":"mcm","clk":"5353171851","pt":1646210258894,"mc":[{"id":"1.195453765","rc":[{"atb":[[2.64,22.51]],"id":40209251}],"con":true,"img":false}]}
{"op":"mcm","clk":"5353171855","pt":1646210258996,"mc":[{"id":"1.195453765","rc":[{"atb":[[2.62,68.18]],"id":40209251}],"con":true,"img":false}]}
{"op":"mcm","clk":"5353171861","pt":1646210259100,"mc":[{"id":"1.195453765","rc":[{"atb":[[2.58,0]],"id":40209251}],"con":true,"img":false}]}
{"op":"mcm","clk":"5353171970","pt":1646210260592,"mc":[{"id":"1.195453765","rc":[{"atb":[[9,17.66],[8.6,7.97]],"id":36010178},{"atl":[[4.3,22.89]],"id":36386524}],"con":true,"img":false}]}
{"op":"mcm","clk":"5353171982","pt":1646210260798,"mc":[{"id":"1.195453765","rc":[{"atb":[[1.42,81.94]],"id":42401236},{"atl":[[5.9,16.33]],"id":36386524}],"con":true,"img":false}]}
{"op":"mcm","clk":"5353171988","pt":1646210260902,"mc":[{"id":"1.195453765","rc":[{"atb":[[2.54,30.8]],"id":43167130},{"atb":[[1.39,74.72],[1.38,0]],"id":42401236}],"con":true,"img":false}]}
{"op":"mcm","clk":"5353172029","pt":1646210261515,"mc":[{"id":"1.195453765","rc":[{"atb":[[2.54,109.85]],"id":43167130}],"con":true,"img":false}]}
{"op":"mcm","clk":"5353172034","pt":1646210261617,"mc":[{"id":"1.195453765","rc":[{"atb":[[2.16,0]],"id":41207262},{"atb":[[2.5,0]],"id":43167130},{"atb":[[2.7,1.67]],"id":40209251}],"con":true,"img":false}]}
{"op":"mcm","clk":"5353172043","pt":1646210261775,"mc":[{"id":"1.195453765","rc":[{"atb":[[2.64,50.43]],"id":40209251}],"con":true,"img":false}]}
{"op":"mcm","clk":"5353172051","pt":1646210261982,"mc":[{"id":"1.195453765","rc":[{"atb":[[2.62,48.96]],"id":40209251}],"con":true,"img":false}]}
{"op":"mcm","clk":"5353172066","pt":1646210262392,"mc":[{"id":"1.195453765","rc":[{"atb":[[9.2,0]],"id":36010178}],"con":true,"img":false}]}
{"op":"mcm","clk":"5353172083","pt":1646210262802,"mc":[{"id":"1.195453765","rc":[{"atb":[[1.97,77.32]],"id":41207262},{"atl":[[4.1,24.19]],"id":41207262}],"con":true,"img":false}]}
{"op":"mcm","clk":"5353172094","pt":1646210263112,"mc":[{"id":"1.195453765","rc":[{"atb":[[2.64,45.84]],"id":40209251}],"con":true,"img":false}]}
{"op":"mcm","clk":"5353172104","pt":1646210263320,"mc":[{"id":"1.195453765","rc":[{"atl":[[5.9,66.95],[6.2,3.85]],"id":36386524}],"con":true,"img":false}]}
{"op":"mcm","clk":"5353172110","pt":1646210263519,"mc":[{"id":"1.195453765","rc":[{"atb":[[2.7,0]],"id":40209251},{"atb":[[9.4,0]],"id":36010178}],"con":true,"img":false}]}
{"op":"mcm","clk":"5353172120","pt":1646210263680,"mc":[{"id":"1.195453765","rc":[{"atb":[[2.22,13.46]],"id":41207262},{"atb":[[2.66,1.67]],"id":40209251},{"atb":[[9.2,1.67]],"id":36010178}],"con":true,"img":false}]}
{"op":"mcm","clk":"5353172127","pt":1646210263786,"mc":[{"id":"1.195453765","rc":[{"atb":[[2.22,80.48],[2.2,0]],"id":41207262}],"con":true,"img":false}]}
{"op":"mcm","clk":"5353172136","pt":1646210263989,"mc":[{"id":"1.195453765","rc":[{"atb":[[1.43,0]],"id":42401236}],"con":true,"img":false}]}
{"op":"mcm","clk":"5353172155","pt":1646210264300,"mc":[{"id":"1.195453765","rc":[{"atb":[[3.25,8.89]],"id":36386524},{"atl":[[4.2,2]],"id":36386524}],"con":true,"img":false}]}
{"op":"mcm","clk":"5353172159","pt":1646210264400,"mc":[{"id":"1.195453765","rc":[{"atl":[[4.3,19.89],[4.4,0]],"id":36386524}],"con":true,"img":false}]}
{"op":"mcm","clk":"5353172164","pt":1646210264503,"mc":[{"id":"1.195453765","rc":[{"atl":[[4.2,11.52]],"id":36386524}],"con":true,"img":false}]}
{"op":"mcm","clk":"5353172171","pt":1646210264605,"mc":[{"id":"1.195453765","rc":[{"atl":[[4.2,9.52]],"id":36386524}],"con":true,"img":false}]}
{"op":"mcm","clk":"5353172176","pt":1646210264709,"mc":[{"id":"1.195453765","rc":[{"atl":[[4.3,0]],"id":36386524}],"con":true,"img":false}]}
{"op":"mcm","clk":"5353172183","pt":1646210264913,"mc":[{"id":"1.195453765","rc":[{"atl":[[4.2,0]],"id":36386524}],"con":true,"img":false}]}
{"op":"mcm","clk":"5353172190","pt":1646210265015,"mc":[{"id":"1.195453765","rc":[{"atb":[[2.26,25.24]],"id":41207262},{"atl":[[5.8,13.81],[5.9,0],[6,50.12]],"id":36386524}],"con":true,"img":false}]}
{"op":"mcm","clk":"5353172203","pt":1646210265220,"mc":[{"id":"1.195453765","rc":[{"atl":[[5.8,0]],"id":36386524}],"con":true,"img":false}]}
{"op":"mcm","clk":"5353172215","pt":1646210265404,"mc":[{"id":"1.195453765","rc":[{"atl":[[5.9,16.33]],"id":36386524}],"con":true,"img":false}]}
{"op":"mcm","clk":"5353172252","pt":1646210266096,"mc":[{"id":"1.195453765","rc":[{"atb":[[3.2,41.63],[3.15,37.48]],"id":36386524}],"con":true,"img":false}]}
{"op":"mcm","clk":"5353172268","pt":1646210266403,"mc":[{"id":"1.195453765","rc":[{"atb":[[2.6,95.84]],"id":40209251}],"con":true,"img":false}]}
{"op":"mcm","clk":"5353172272","pt":1646210266509,"mc":[{"id":"1.195453765","rc":[{"atb":[[2.28,3.84]],"id":41207262},{"atb":[[2.62,0],[2.66,23.09]],"id":40209251}],"con":true,"img":false}]}
{"op":"mcm","clk":"5353172292","pt":1646210266916,"mc":[{"id":"1.195453765","rc":[{"atb":[[1.46,43.04]],"id":42401236}],"con":true,"img":false}]}
{"op":"mcm","clk":"5353172300","pt":1646210267118,"mc":[{"id":"1.195453765","rc":[{"atb":[[1.42,54.38]],"id":42401236}],"con":true,"img":false}]}
{"op":"mcm","clk":"5353172330","pt":1646210267893,"mc":[{"id":"1.195453765","rc":[{"atb":[[9,7.92],[8.6,23.81],[9.2,9.59]],"id":36010178}],"con":true,"img":false}]}
{"op":"mcm","clk":"5353172333","pt":1646210267998,"mc":[{"id":"1.195453765","rc":[{"atb":[[2.6,4.7]],"id":43167130},{"atb":[[1.45,16.72]],"id":42401236},{"atb":[[2.7,4.42]],"id":40209251}],"con":true,"img":false}]}
{"op":"mcm","clk":"5353172337","pt":1646210268102,"mc":[{"id":"1.195453765","rc":[{"atb":[[1.39,197.87]],"id":42401236},{"atb":[[9,0]],"id":36010178}],"con":true,"img":false}]}
{"op":"mcm","clk":"5353172342","pt":1646210268204,"mc":[{"id":"1.195453765","rc":[{"atb":[[1.42,0]],"id":42401236}],"con":true,"img":false}]}
{"op":"mcm","clk":"5353172349","pt":1646210268408,"mc":[{"id":"1.195453765","rc":[{"atb":[[1.39,74.72]],"id":42401236}],"con":true,"img":false}]}
{"op":"mcm","clk":"5353172357","pt":1646210268614,"mc":[{"id":"1.195453765","rc":[{"atb":[[1.01,2.53]],"id":36010178}],"con":true,"img":false}]}
{"op":"mcm","clk":"5353172365","pt":1646210268720,"mc":[{"id":"1.195453765","rc":[{"atb":[[1.39,0]],"id":42401236}],"con":true,"img":false}]}
{"op":"mcm","clk":"5353172374","pt":1646210268826,"mc":[{"id":"1.195453765","rc":[{"atb":[[2.32,7.31],[2.22,13.46],[2.26,68.88]],"id":41207262},{"atb":[[2.54,30.8],[2.6,71]],"id":43167130},{"atb":[[1.01,1.69]],"id":36010178}],"con":true,"img":false}]}
{"op":"mcm","clk":"5353172387","pt":1646210269035,"mc":[{"id":"1.195453765","rc":[{"atb":[[2.26,43.64]],"id":41207262},{"atb":[[1.01,0]],"id":36010178}],"con":true,"img":false}]}
{"op":"mcm","clk":"5353172394","pt":1646210269137,"mc":[{"id":"1.195453765","rc":[{"atb":[[9.4,1.69]],"id":36010178}],"con":true,"img":false}]}
{"op":"mcm","clk":"5353172401","pt":1646210269294,"mc":[{"id":"1.195453765","rc":[{"atb":[[1.37,96.1]],"id":42401236}],"con":true,"img":false}]}
{"op":"mcm","clk":"5353172412","pt":1646210269500,"mc":[{"id":"1.195453765","rc":[{"atb":[[2.66,21.42]],"id":40209251},{"atb":[[9.2,7.92]],"id":36010178}],"con":true,"img":false}]}
{"op":"mcm","clk":"5353172418","pt":1646210269608,"mc":[{"id":"1.195453765","rc":[{"atb":[[2.72,1.67]],"id":40209251},{"atb":[[9.6,1.67]],"id":36010178}],"con":true,"img":false}]}
{"op":"mcm","clk":"5353172425","pt":1646210269712,"mc":[{"id":"1.195453765","rc":[{"atb":[[9.2,17.66]],"id":36010178}],"con":true,"img":false}]}
{"op":"mcm","clk":"5353172430","pt":1646210269813,"mc":[{"id":"1.195453765","rc":[{"atb":[[8.6,7.97]],"id":36010178}],"con":true,"img":false}]}
{"op":"mcm","clk":"5353172435","pt":1646210269915,"mc":[{"id":"1.195453765","rc":[{"atl":[[3.8,7.14],[3.45,2],[3.65,0]],"id":41207262}],"con":true,"img":false}]}
{"op":"mcm","clk":"5353172439","pt":1646210270015,"mc":[{"id":"1.195453765","rc":[{"atb":[[2.52,0]],"id":43167130}],"con":true,"img":false}]}
{"op":"mcm","clk":"5353172447","pt":1646210270122,"mc":[{"id":"1.195453765","rc":[{"atl":[[3.6,41.46],[3.55,22.24],[3.45,7.14]],"id":41207262},{"atb":[[2.18,25.13]],"id":43167130}],"con":true,"img":false}]}
{"op":"mcm","clk":"5353172453","pt":1646210270229,"mc":[{"id":"1.195453765","rc":[{"atl":[[3.5,2]],"id":41207262},{"atl":[[6.2,23.08],[6,30.12]],"id":36386524}],"con":true,"img":false}]}
{"op":"mcm","clk":"5353172473","pt":1646210270589,"mc":[{"id":"1.195453765","rc":[{"atl":[[6.2,72.09],[6,2.5]],"id":36386524}],"con":true,"img":false}]}
{"op":"mcm","clk":"5353172498","pt":1646210271003,"mc":[{"id":"1.195453765","rc":[{"atb":[[2.6,66.3]],"id":43167130},{"atb":[[1.45,0]],"id":42401236}],"con":true,"img":false}]}
{"op":"mcm","clk":"5353172517","pt":1646210271312,"mc":[{"id":"1.195453765","rc":[{"atb":[[2.22,0]],"id":41207262},{"atb":[[2.54,0]],"id":43167130},{"atb":[[2.64,27.92]],"id":40209251}],"con":true,"img":false}]}
{"op":"mcm","clk":"5353172541","pt":1646210271824,"mc":[{"id":"1.195453765","rc":[{"atb":[[2.66,0]],"id":40209251}],"con":true,"img":false}]}
{"op":"mcm","clk":"5353172646","pt":1646210273900,"mc":[{"id":"1.195453765","rc":[{"atb":[[3.4,3.13]],"id":36386524}],"con":true,"img":false}]}
{"op":"mcm","clk":"5353172650","pt":1646210274001,"mc":[{"id":"1.195453765","rc":[{"atb":[[1.38,124.85]],"id":42401236}],"con":true,"img":false}]}
{"op":"mcm","clk":"5353172658","pt":1646210274104,"mc":[{"id":"1.195453765","rc":[{"atb":[[3.2,3.8],[3.4,22.05],[3.25,46.72]],"id":36386524}],"con":true,"img":false}]}
{"op":"mcm","clk":"5353172669","pt":1646210274310,"mc":[{"id":"1.195453765","rc":[{"atb":[[3.15,60.74],[3.3,22.29]],"id":36386524}],"con":true,"img":false}]}
{"op":"mcm","clk":"5353172675","pt":1646210274414,"mc":[{"id":"1.195453765","rc":[{"atb":[[3.15,51.44]],"id":36386524}],"con":true,"img":false}]}
{"op":"mcm","clk":"5353172709","pt":1646210275030,"mc":[{"id":"1.195453765","rc":[{"atb":[[3.25,37.83],[3.15,37.48]],"id":36386524},{"atl":[[4.6,2]],"id":36386524}],"con":true,"img":false}]}
{"op":"mcm","clk":"5353172713","pt":1646210275084,"mc":[{"id":"1.195453765","rc":[{"atl":[[5.8,16.67]],"id":36386524}],"con":true,"img":false}]}
{"op":"mcm","clk":"5353172721","pt":1646210275189,"mc":[{"id":"1.195453765","rc":[{"atl":[[3.8,0],[3.45,0],[3.65,3]],"id":41207262},{"atl":[[4.4,4],[4.6,0],[6.2,23.08],[6,53.69]],"id":36386524}],"con":true,"img":false}]}
{"op":"mcm","clk":"5353172729","pt":1646210275292,"mc":[{"id":"1.195453765","rc":[{"atl":[[5.9,0]],"id":36386524}],"con":true,"img":false}]}
{"op":"mcm","clk":"5353172734","pt":1646210275396,"mc":[{"id":"1.195453765","rc":[{"atl":[[3.55,26.63]],"id":41207262}],"con":true,"img":false}]}
{"op":"mcm","clk":"5353172740","pt":1646210275499,"mc":[{"id":"1.195453765","rc":[{"atl":[[3.6,3],[3.5,28.63]],"id":41207262},{"atb":[[3.3,20.62]],"id":36386524}],"con":true,"img":false}]}
{"op":"mcm","clk":"5353172750","pt":1646210275708,"mc":[{"id":"1.195453765","rc":[{"atl":[[3.6,41.46],[3.5,2]],"id":41207262},{"atb":[[3.45,1.67]],"id":36386524}],"con":true,"img":false}]}
{"op":"mcm","clk":"5353172773","pt":1646210276118,"mc":[{"id":"1.195453765","rc":[{"atl":[[4.4,27.38]],"id":36386524}],"con":true,"img":false}]}
{"op":"mcm","clk":"5353172778","pt":1646210276221,"mc":[{"id":"1.195453765","rc":[{"atl":[[5.8,0]],"id":36386524}],"con":true,"img":false}]}
{"op":"mcm","clk":"5353172782","pt":1646210276332,"mc":[{"id":"1.195453765","rc":[{"atb":[[1.37,219.25]],"id":42401236}],"con":true,"img":false}]}
{"op":"mcm","clk":"5353172790","pt":1646210276532,"mc":[{"id":"1.195453765","rc":[{"atb":[[2.62,21.95]],"id":43167130}],"con":true,"img":false}]}
{"op":"mcm","clk":"5353172808","pt":1646210277001,"mc":[{"id":"1.195453765","rc":[{"atb":[[2.32,13.01]],"id":41207262},{"atb":[[2.62,94.39],[2.66,4.53]],"id":43167130},{"atb":[[3.4,18.92]],"id":36386524}],"con":true,"img":false}]}
{"op":"mcm","clk":"5353172816","pt":1646210277108,"mc":[{"id":"1.195453765","rc":[{"atb":[[2.6,0]],"id":43167130},{"atb":[[9.4,0]],"id":36010178}],"con":true,"img":false}]}
{"op":"mcm","clk":"5353172821","pt":1646210277210,"mc":[{"id":"1.195453765","rc":[{"atb":[[8.6,23.81]],"id":36010178},{"atb":[[3.3,0]],"id":36386524}],"con":true,"img":false}]}
{"op":"mcm","clk":"5353172826","pt":1646210277313,"mc":[{"id":"1.195453765","rc":[{"atb":[[2.34,19.64]],"id":41207262},{"atl":[[3.6,103.44],[3.55,7.39]],"id":41207262},{"atb":[[2.66,16.75]],"id":40209251},{"atb":[[9.2,7.92]],"id":36010178}],"con":true,"img":false}]}
{"op":"mcm","clk":"5353172832","pt":1646210277417,"mc":[{"id":"1.195453765","rc":[{"atb":[[2.64,75.13]],"id":40209251}],"con":true,"img":false}]}
{"op":"mcm","clk":"5353172838","pt":1646210277522,"mc":[{"id":"1.195453765","rc":[{"atb":[[2.6,2.5]],"id":40209251}],"con":true,"img":false}]}
{"op":"mcm","clk":"5353172855","pt":1646210277827,"mc":[{"id":"1.195453765","rc":[{"atl":[[6.2,72.92]],"id":36386524}],"con":true,"img":false}]}
{"op":"mcm","clk":"5353172860","pt":1646210277931,"mc":[{"id":"1.195453765","rc":[{"atl":[[6,2.5]],"id":36386524}],"con":true,"img":false}]}
{"op":"mcm","clk":"5353172870","pt":1646210278087,"mc":[{"id":"1.195453765","rc":[{"atb":[[3.2,0]],"id":36386524}],"con":true,"img":false}]}
{"op":"mcm","clk":"5353172893","pt":1646210278500,"mc":[{"id":"1.195453765","rc":[{"atb":[[2.32,10.84],[2.4,2.17]],"id":41207262}],"con":true,"img":false}]}
{"op":"mcm","clk":"5353172907","pt":1646210278707,"mc":[{"id":"1.195453765","rc":[{"atb":[[1.37,123.15]],"id":42401236}],"con":true,"img":false}]}
{"op":"mcm","clk":"5353172937","pt":1646210279330,"mc":[{"id":"1.195453765","rc":[{"atb":[[2.32,38.18],[2.26,0]],"id":41207262}],"con":true,"img":false}]}
{"op":"mcm","clk":"5353172952","pt":1646210279539,"mc":[{"id":"1.195453765","rc":[{"atb":[[1.98,0],[1.93,0],[2.06,0]],"id":41207262},{"atl":[[6.4,0],[11,0],[8.4,0],[16,0],[5.2,0]],"id":41207262},{"atb":[[2.26,0],[2.06,0],[2.16,0]],"id":43167130},{"atl":[[5.6,0],[7.2,0],[18,0],[9.2,0],[13,0]],"id":43167130},{"atb":[[1.19,250],[1.14,0],[1.09,0]],"id":42401236},{"atl":[[2.48,30.87],[2.88,0],[3.2,0],[2.28,0],[2.68,0]],"id":42401236},{"atb":[[2.26,0],[2.06,0],[2.16,0]],"id":40209251},{"atl":[[5.6,0],[7.2,0],[18,0],[9.2,0],[13,0]],"id":40209251},{"atb":[[4.3,37.88],[3.9,0],[3.65,0]],"id":43167131},{"atl":[[32,3.23],[55,0],[15.5,5.52],[21,0],[110,0]],"id":43167131},{"atb":[[8.6,15.84],[7.6,2.5],[6.6,0]],"id":36010178},{"atl":[[180,0],[46,6.3],[280,0],[90,0],[380,0]],"id":36010178},{"atb":[[2.86,0],[3.15,9.3],[2.96,0]],"id":36386524},{"atl":[[16,0],[34,0],[11,0],[22,0],[8.4,0]],"id":36386524}],"con":true,"img":false}]}
{"op":"mcm","clk":"5353172966","pt":1646210279695,"mc":[{"id":"1.195453765","rc":[{"atl":[[2.8,113.35],[2.26,0],[2.48,0]],"id":42401236},{"atl":[[15.5,0]],"id":43167131},{"atl":[[4.3,3]],"id":36386524}],"con":true,"img":false}]}
{"op":"mcm","clk":"5353172971","pt":1646210279796,"mc":[{"id":"1.195453765","rc":[{"atl":[[19.5,6.82],[20,0],[22,15.1]],"id":43167131},{"atl":[[6.2,23.08],[6,47.34]],"id":36386524}],"con":true,"img":false}]}
{"op":"mcm","clk":"5353172976","pt":1646210279902,"mc":[{"id":"1.195453765","rc":[{"atb":[[1.95,131.58]],"id":41207262},{"atl":[[4.3,37.88],[3.85,0],[3.5,0],[3.7,4],[3.9,6.9]],"id":41207262},{"atl":[[2.78,44.94]],"id":42401236},{"atb":[[2.64,0],[2.08,0],[2.02,45.42]],"id":40209251},{"atb":[[7.8,0],[9.4,12.13]],"id":36010178},{"atl":[[29,1.12]],"id":36010178},{"atl":[[4.3,23.31],[4.2,4]],"id":36386524}],"con":true,"img":false}]}
{"op":"mcm","clk":"5353172983","pt":1646210280053,"mc":[{"id":"1.195453765","rc":[{"atb":[[2.32,32.48]],"id":41207262},{"atl":[[3.6,100.44],[3.55,4.39],[3.65,0]],"id":41207262},{"atb":[[2.66,0]],"id":43167130},{"atl":[[2.8,110.85],[4.8,0],[3,3],[4.9,0],[2.94,10],[5,25],[2.86,5],[2.78,47.44],[4.7,0]],"id":42401236}],"con":true,"img":false}]}
{"op":"mcm","clk":"5353172989","pt":1646210280105,"mc":[{"id":"1.195453765","rc":[{"atl":[[36,2.29]],"id":36010178},{"atl":[[4.4,4]],"id":36386524}],"con":true,"img":false}]}
{"op":"mcm","clk":"5353172997","pt":1646210280212,"mc":[{"id":"1.195453765","rc":[{"atl":[[3.6,61.98],[3.7,37.04],[3.5,4]],"id":41207262},{"atl":[[3,0],[2.98,3]],"id":42401236},{"atl":[[38,9.68],[46,0]],"id":36010178},{"atl":[[4.1,3],[4.4,0]],"id":36386524}],"con":true,"img":false}]}
{"op":"mcm","clk":"5353173008","pt":1646210280417,"mc":[{"id":"1.195453765","rc":[{"atl":[[4.3,68.15],[6,2.5]],"id":36386524}],"con":true,"img":false}]}
{"op":"mcm","clk":"5353173039","pt":1646210280938,"mc":[{"id":"1.195453765","rc":[{"atl":[[3.55,6.39]],"id":41207262},{"atl":[[4,2],[4.3,65.15]],"id":36386524}],"con":true,"img":false}]}
{"op":"mcm","clk":"5353173046","pt":1646210281036,"mc":[{"id":"1.195453765","rc":[{"atb":[[1.22,0]],"id":42401236}],"con":true,"img":false}]}
{"op":"mcm","clk":"5353173055","pt":1646210281139,"mc":[{"id":"1.195453765","rc":[{"atb":[[1.25,94.11]],"id":42401236},{"atb":[[1.01,2.53]],"id":36010178}],"con":true,"img":false}]}
{"op":"mcm","clk":"5353173067","pt":1646210281349,"mc":[{"id":"1.195453765","rc":[{"atb":[[1.01,1.69]],"id":36010178},{"atb":[[3.15,29.25]],"id":36386524}],"con":true,"img":false}]}
{"op":"mcm","clk":"5353173070","pt":1646210281404,"mc":[{"id":"1.195453765","rc":[{"atb":[[2.28,0]],"id":41207262},{"atb":[[2.62,72.44]],"id":43167130},{"atb":[[3.25,0]],"id":36386524}],"con":true,"img":false}]}
{"op":"mcm","clk":"5353173077","pt":1646210281507,"mc":[{"id":"1.195453765","rc":[{"atb":[[2.34,17.97]],"id":41207262},{"atb":[[1.01,0]],"id":36010178},{"atb":[[3.45,0]],"id":36386524}],"con":true,"img":false}]}
{"op":"mcm","clk":"5353173083","pt":1646210281610,"mc":[{"id":"1.195453765","rc":[{"atb":[[2.42,1.67]],"id":41207262},{"atl":[[3.45,3]],"id":41207262},{"atb":[[9.8,1.69]],"id":36010178},{"atb":[[3.4,0]],"id":36386524},{"atl":[[4,11.38]],"id":36386524}],"con":true,"img":false}]}
{"op":"mcm","clk":"5353173089","pt":1646210281711,"mc":[{"id":"1.195453765","rc":[{"atb":[[3.15,46.44]],"id":36386524},{"atl":[[4.3,44.84]],"id":36386524}],"con":true,"img":false}]}
{"op":"mcm","clk":"5353173098","pt":1646210281816,"mc":[{"id":"1.195453765","rc":[{"atb":[[2.6,46.6]],"id":40209251},{"atb":[[2.86,5],[2.78,10],[2.94,2.5]],"id":36386524}],"con":true,"img":false}]}
{"op":"mcm","clk":"5353173111","pt":1646210282025,"mc":[{"id":"1.195453765","rc":[{"atl":[[3.4,2]],"id":41207262}],"con":true,"img":false}]}
{"op":"mcm","clk":"5353173126","pt":1646210282232,"mc":[{"id":"1.195453765","rc":[{"atl":[[3.6,0]],"id":41207262}],"con":true,"img":false}]}
{"op":"mcm","clk":"5353173165","pt":1646210282849,"mc":[{"id":"1.195453765","rc":[{"atl":[[2.96,3]],"id":42401236},{"atl":[[3.95,4]],"id":36386524}],"con":true,"img":false}]}
{"op":"mcm","clk":"5353173171","pt":1646210282948,"mc":[{"id":"1.195453765","rc":[{"atb":[[1.41,18.35]],"id":42401236},{"atb":[[2.7,0]],"id":40209251}],"con":true,"img":false}]}
{"op":"mcm","clk":"5353173176","pt":1646210283053,"mc":[{"id":"1.195453765","rc":[{"atl":[[4.3,0]],"id":36386524}],"con":true,"img":false}]}
{"op":"mcm","clk":"5353173184","pt":1646210283112,"mc":[{"id":"1.195453765","rc":[{"atl":[[2.94,14]],"id":42401236}],"con":true,"img":false}]}
{"op":"mcm","clk":"5353173198","pt":1646210283315,"mc":[{"id":"1.195453765","rc":[{"atb":[[8.6,0],[9.8,4.67],[9.4,18.1]],"id":36010178}],"con":true,"img":false}]}
{"op":"mcm","clk":"5353173211","pt":1646210283526,"mc":[{"id":"1.195453765","rc":[{"atb":[[1.37,0],[1.38,260.57]],"id":42401236},{"atb":[[9.2,0]],"id":36010178}],"con":true,"img":false}]}
{"op":"mcm","clk":"5353173226","pt":1646210283834,"mc":[{"id":"1.195453765","rc":[{"atb":[[1.98,123.65],[1.93,130.3],[2.06,57.16]],"id":41207262},{"atl":[[6.4,0.1],[8.4,0.58],[5.2,0.13]],"id":41207262},{"atb":[[2.26,48.08],[2.06,114.31],[2.16,104.46]],"id":43167130},{"atl":[[5.6,0.12],[7.2,0.08],[9.2,0.53]],"id":43167130},{"atb":[[1.19,568.89],[1.14,865.56],[1.09,1346.43]],"id":42401236},{"atl":[[2.48,0.37],[2.28,0.42],[2.68,2.59]],"id":42401236},{"atb":[[2.26,48.08],[2.06,114.31],[2.16,104.46]],"id":40209251},{"atl":[[5.6,0.12],[7.2,0.08],[9.2,0.53]],"id":40209251},{"atb":[[4.3,56.24],[3.9,41.78],[3.65,45.72]],"id":43167131},{"atl":[[32,3.37],[21,0.02],[15.5,0.03]],"id":43167131},{"atb":[[8.6,7.97],[7.6,20.86],[6.6,21.63]],"id":36010178},{"atl":[[90,0],[180,0.02],[46,0.01]],"id":36010178},{"atb":[[2.86,70.14],[3.15,74.62],[2.96,61.82]],"id":36386524},{"atl":[[11,0.05],[8.4,0.07],[16,0.28]],"id":36386524}],"con":true,"img":false}]}
{"op":"mcm","clk":"5353173231","pt":1646210283935,"mc":[{"id":"1.195453765","rc":[{"atb":[[1.39,64.56]],"id":42401236}],"con":true,"img":false}]}
{"op":"mcm","clk":"5353173235","pt":1646210284037,"mc":[{"id":"1.195453765","rc":[{"atb":[[2.66,40.35]],"id":40209251}],"con":true,"img":false}]}
{"op":"mcm","clk":"5353173249","pt":1646210284244,"mc":[{"id":"1.195453765","rc":[{"atb":[[2.34,0]],"id":41207262},{"atl":[[3.55,2],[3.95,6.78],[3.9,0]],"id":41207262},{"atb":[[2.66,23.6]],"id":40209251},{"atb":[[5.7,8.31]],"id":43167131}],"con":true,"img":false}]}
{"op":"mcm","clk":"5353173263","pt":1646210284549,"mc":[{"id":"1.195453765","rc":[{"atl":[[2.98,0],[2.94,10],[2.46,4],[2.96,0]],"id":42401236},{"atb":[[2.6,2.5],[2.52,64.97]],"id":40209251},{"atl":[[4.3,4],[3.95,0]],"id":36386524}],"con":true,"img":false}]}
{"op":"mcm","clk":"5353173291","pt":1646210285070,"mc":[{"id":"1.195453765","rc":[{"atl":[[3.85,7.02],[3.35,3],[3.55,0],[3.5,0]],"id":41207262},{"atl":[[2.44,3]],"id":42401236},{"atb":[[3.05,24.39]],"id":36386524}],"con":true,"img":false}]}
{"op":"mcm","clk":"5353173305","pt":1646210285230,"mc":[{"id":"1.195453765","rc":[{"atl":[[3.5,2]],"id":41207262},{"atl":[[2.42,4]],"id":42401236},{"atl":[[4.3,0],[3.95,2],[4.2,0]],"id":36386524}],"con":true,"img":false}]}
{"op":"mcm","clk":"5353173343","pt":1646210285848,"mc":[{"id":"1.195453765","rc":[{"atl":[[3.5,0],[3.3,4]],"id":41207262},{"atl":[[2.4,4]],"id":42401236},{"atl":[[3.9,4]],"id":36386524}],"con":true,"img":false}]}
{"op":"mcm","clk":"5353173351","pt":1646210285955,"mc":[{"id":"1.195453765","rc":[{"atb":[[9.4,5.97]],"id":36010178},{"atl":[[34,0.96],[29,0]],"id":36010178}],"con":true,"img":false}]}
{"op":"mcm","clk":"5353173357","pt":1646210286050,"mc":[{"id":"1.195453765","rc":[{"atb":[[8.8,12.13]],"id":36010178}],"con":true,"img":false}]}
{"op":"mcm","clk":"5353173370","pt":1646210286256,"mc":[{"id":"1.195453765","rc":[{"atb":[[1.38,135.72]],"id":42401236}],"con":true,"img":false}]}
{"op":"mcm","clk":"5353173382","pt":1646210286417,"mc":[{"id":"1.195453765","rc":[{"atb":[[2.32,5.14],[2.12,12.76]],"id":41207262}],"con":true,"img":false}]}
{"op":"mcm","clk":"5353173387","pt":1646210286517,"mc":[{"id":"1.195453765","rc":[{"atb":[[2.42,4.36]],"id":41207262},{"atb":[[2.62,18.43]],"id":40209251}],"con":true,"img":false}]}
{"op":"mcm","clk":"5353173408","pt":1646210286929,"mc":[{"id":"1.195453765","rc":[{"atl":[[23,18.71]],"id":43167131}],"con":true,"img":false}]}
{"op":"mcm","clk":"5353173411","pt":1646210287030,"mc":[{"id":"1.195453765","rc":[{"atb":[[2.68,4.47]],"id":43167130},{"atb":[[1.41,0]],"id":42401236},{"atl":[[22,1]],"id":43167131}],"con":true,"img":false}]}
{"op":"mcm","clk":"5353173417","pt":1646210287134,"mc":[{"id":"1.195453765","rc":[{"atl":[[3.85,0],[3.8,7.14]],"id":41207262}],"con":true,"img":false}]}
{"op":"mcm","clk":"5353173422","pt":1646210287236,"mc":[{"id":"1.195453765","rc":[{"atb":[[2.64,68.47],[2.62,0]],"id":43167130}],"con":true,"img":false}]}
{"op":"mcm","clk":"5353173429","pt":1646210287340,"mc":[{"id":"1.195453765","rc":[{"atl":[[3.4,9]],"id":41207262}],"con":true,"img":false}]}
{"op":"mcm","clk":"5353173434","pt":1646210287444,"mc":[{"id":"1.195453765","rc":[{"atl":[[3.7,0]],"id":41207262}],"con":true,"img":false}]}
{"op":"mcm","clk":"5353173441","pt":1646210287547,"mc":[{"id":"1.195453765","rc":[{"spn":2.86,"spf":"NaN","id":41207262},{"spn":3.21,"spf":"NaN","id":43167130},{"spn":1.87,"spf":"NaN","id":42401236},{"spn":10.6,"spf":"NaN","id":43167131},{"atb":[[2.72,0]],"id":40209251},{"spn":3.43,"spf":"NaN","id":40209251},{"atb":[[9.6,0]],"id":36010178},{"spn":21.9,"spf":"NaN","id":36010178},{"spn":3.52,"spf":"NaN","id":36386524}],"con":true,"img":false}]}
{"op":"mcm","clk":"5353173446","pt":1646210287649,"mc":[{"id":"1.195453765","rc":[{"atb":[[2.68,1.67]],"id":40209251},{"atb":[[10,1.67]],"id":36010178},{"atb":[[3.2,1.67]],"id":36386524}],"con":true,"img":false}]}
{"op":"mcm","clk":"5353173453","pt":1646210287752,"mc":[{"id":"1.195453765","rc":[{"atb":[[2.66,0]],"id":40209251},{"atb":[[8.8,28.09],[9.4,0]],"id":36010178}],"con":true,"img":false}]}
{"op":"mcm","clk":"5353173460","pt":1646210287858,"mc":[{"id":"1.195453765","rc":[{"atb":[[2.66,24.86]],"id":40209251}],"con":true,"img":false}]}
{"op":"mcm","clk":"5353173465","pt":1646210287958,"mc":[{"id":"1.195453765","rc":[{"atb":[[8.8,12.13]],"id":36010178}],"con":true,"img":false}]}
{"op":"mcm","clk":"5353173493","pt":1646210288426,"mc":[{"id":"1.195453765","rc":[{"atb":[[3.15,54.67],[2.98,116.79]],"id":36386524}],"con":true,"img":false}]}
{"op":"mcm","clk":"5353173505","pt":1646210288632,"mc":[{"id":"1.195453765","rc":[{"atb":[[1.39,0]],"id":42401236}],"con":true,"img":false}]}
{"op":"mcm","clk":"5353173510","pt":1646210288731,"mc":[{"id":"1.195453765","rc":[{"atl":[[3.85,7.02],[3.8,0]],"id":41207262},{"atb":[[9.8,2.98]],"id":36010178}],"con":true,"img":false}]}
{"op":"mcm","clk":"5353173524","pt":1646210289045,"mc":[{"id":"1.195453765","rc":[{"atb":[[1.99,127.83],[1.92,0]],"id":41207262},{"atb":[[2.68,0]],"id":43167130},{"atb":[[2,0],[2.14,87.72]],"id":40209251},{"atb":[[5.5,19.12],[5.2,2.5]],"id":43167131}],"con":true,"img":false}]}
{"op":"mcm","clk":"5353173533","pt":1646210289248,"mc":[{"id":"1.195453765","rc":[{"atl":[[3.3,0],[3.5,2]],"id":41207262},{"atb":[[5.3,10.39],[5.5,41.88]],"id":43167131}],"con":true,"img":false}]}
{"op":"mcm","clk":"5353173542","pt":1646210289452,"mc":[{"id":"1.195453765","rc":[{"atl":[[3.45,15],[3.4,2]],"id":41207262}],"con":true,"img":false}]}
{"op":"mcm","clk":"5353173554","pt":1646210289660,"mc":[{"id":"1.195453765","rc":[{"atb":[[2.14,21.14]],"id":41207262},{"atb":[[5.8,9.88]],"id":43167131},{"atb":[[2.54,30.8]],"id":40209251}],"con":true,"img":false}]}
{"op":"mcm","clk":"5353173562","pt":1646210289860,"mc":[{"id":"1.195453765","rc":[{"atb":[[5.9,6.99]],"id":43167131}],"con":true,"img":false}]}
{"op":"mcm","clk":"5353173570","pt":1646210290020,"mc":[{"id":"1.195453765","rc":[{"atb":[[5.7,1.67]],"id":43167131}],"con":true,"img":false}]}
{"op":"mcm","clk":"5353173575","pt":1646210290122,"mc":[{"id":"1.195453765","rc":[{"atb":[[1.41,20.37]],"id":42401236}],"con":true,"img":false}]}
{"op":"mcm","clk":"5353173580","pt":1646210290329,"mc":[{"id":"1.195453765","rc":[{"atl":[[3.9,8.33]],"id":36386524}],"con":true,"img":false}]}
{"op":"mcm","clk":"5353173587","pt":1646210290433,"mc":[{"id":"1.195453765","rc":[{"atl":[[4,1.99]],"id":36386524}],"con":true,"img":false}]}
{"op":"mcm","clk":"5353173605","pt":1646210290844,"mc":[{"id":"1.195453765","rc":[{"atl":[[6,0]],"id":36386524}],"con":true,"img":false}]}
{"op":"mcm","clk":"5353173666","pt":1646210291924,"mc":[{"id":"1.195453765","rc":[{"atb":[[1.39,121.65]],"id":42401236}],"con":true,"img":false}]}
{"op":"mcm","clk":"5353173671","pt":1646210292025,"mc":[{"id":"1.195453765","rc":[{"atl":[[3.3,4]],"id":41207262},{"atb":[[1.39,158.85],[1.38,0]],"id":42401236}],"con":true,"img":false}]}
{"op":"mcm","clk":"5353173679","pt":1646210292130,"mc":[{"id":"1.195453765","rc":[{"atl":[[3.85,0],[3.8,7.14],[3.5,0],[3.45,26.04]],"id":41207262}],"con":true,"img":false}]}
{"op":"mcm","clk":"5353173690","pt":1646210292333,"mc":[{"id":"1.195453765","rc":[{"atl":[[3.45,15]],"id":41207262}],"con":true,"img":false}]}
{"op":"mcm","clk":"5353173695","pt":1646210292431,"mc":[{"id":"1.195453765","rc":[{"atb":[[8.8,20.03]],"id":36010178}],"con":true,"img":false}]}
{"op":"mcm","clk":"5353173710","pt":1646210292639,"mc":[{"id":"1.195453765","rc":[{"atb":[[2.6,52.21],[2.52,5]],"id":40209251}],"con":true,"img":false}]}
{"op":"mcm","clk":"5353173739","pt":1646210293461,"mc":[{"id":"1.195453765","rc":[{"atb":[[2.42,1.67]],"id":41207262},{"atb":[[1.39,223.42]],"id":42401236}],"con":true,"img":false}]}
{"op":"mcm","clk":"5353173745","pt":1646210293564,"mc":[{"id":"1.195453765","rc":[{"atb":[[5.7,0]],"id":43167131}],"con":true,"img":false}]}
{"op":"mcm","clk":"5353173749","pt":1646210293621,"mc":[{"id":"1.195453765","rc":[{"atb":[[6,1.67]],"id":43167131}],"con":true,"img":false}]}
{"op":"mcm","clk":"5353173784","pt":1646210294342,"mc":[{"id":"1.195453765","rc":[{"atb":[[2.64,2.17],[2.44,81.55]],"id":43167130}],"con":true,"img":false}]}
{"op":"mcm","clk":"5353173789","pt":1646210294451,"mc":[{"id":"1.195453765","rc":[{"atb":[[2.12,2.5],[2.14,32.9],[2.4,0],[2.2,2.17]],"id":41207262},{"atb":[[5.8,0]],"id":43167131},{"atb":[[2.54,0]],"id":40209251}],"con":true,"img":false}]}
{"op":"mcm","clk":"5353173807","pt":1646210294857,"mc":[{"id":"1.195453765","rc":[{"atl":[[2.8,0],[2.44,40.2]],"id":42401236}],"con":true,"img":false}]}
{"op":"mcm","clk":"5353173811","pt":1646210294955,"mc":[{"id":"1.195453765","rc":[{"atl":[[19,3.13]],"id":43167131}],"con":true,"img":false}]}
{"op":"mcm","clk":"5353173819","pt":1646210295064,"mc":[{"id":"1.195453765","rc":[{"atb":[[2.1,6.84]],"id":41207262},{"atl":[[2.4,22.28]],"id":42401236},{"atl":[[19.5,2.5],[22,15.6]],"id":43167131}],"con":true,"img":false}]}
{"op":"mcm","clk":"5353173823","pt":1646210295165,"mc":[{"id":"1.195453765","rc":[{"atl":[[23,5]],"id":43167131}],"con":true,"img":false}]}
{"op":"mcm","clk":"5353173828","pt":1646210295265,"mc":[{"id":"1.195453765","rc":[{"atl":[[2.78,2.5]],"id":42401236},{"atl":[[32,2.58]],"id":36010178}],"con":true,"img":false}]}
{"op":"mcm","clk":"5353173838","pt":1646210295426,"mc":[{"id":"1.195453765","rc":[{"atl":[[36,7.3],[38,2.5]],"id":36010178}],"con":true,"img":false}]}
{"op":"mcm","clk":"5353173863","pt":1646210295939,"mc":[{"id":"1.195453765","rc":[{"atb":[[2.98,91.54]],"id":36386524}],"con":true,"img":false}]}
{"op":"mcm","clk":"5353173910","pt":1646210296658,"mc":[{"id":"1.195453765","rc":[{"atb":[[2.14,11.76]],"id":41207262},{"atb":[[1.39,101.76]],"id":42401236}],"con":true,"img":false}]}
{"op":"mcm","clk":"5353173979","pt":1646210298059,"mc":[{"id":"1.195453765","rc":[{"atb":[[5.3,0]],"id":43167131},{"atb":[[2.62,0]],"id":36386524}],"con":true,"img":false}]}
{"op":"mcm","clk":"5353173988","pt":1646210298164,"mc":[{"id":"1.195453765","rc":[{"atb":[[2.16,10.89]],"id":41207262},{"atb":[[5.1,10.39]],"id":43167131},{"atb":[[2.88,22.05]],"id":36386524}],"con":true,"img":false}]}
{"op":"mcm","clk":"5353173995","pt":1646210298371,"mc":[{"id":"1.195453765","rc":[{"atl":[[3.85,7.02],[3.8,0]],"id":41207262},{"atb":[[4.8,0],[5.6,0],[5.2,0],[5.7,2.5]],"id":43167131},{"atl":[[3.85,2],[4.1,0]],"id":36386524}],"con":true,"img":false}]}
{"op":"mcm","clk":"5353173998","pt":1646210298468,"mc":[{"id":"1.195453765","rc":[{"atb":[[10,5.84]],"id":36010178}],"con":true,"img":false}]}
{"op":"mcm","clk":"5353174002","pt":1646210298524,"mc":[{"id":"1.195453765","rc":[{"atl":[[3.85,4.44]],"id":36386524}],"con":true,"img":false}]}
{"op":"mcm","clk":"5353174008","pt":1646210298630,"mc":[{"id":"1.195453765","rc":[{"atb":[[9.8,0]],"id":36010178}],"con":true,"img":false}]}
{"op":"mcm","clk":"5353174014","pt":1646210298731,"mc":[{"id":"1.195453765","rc":[{"atb":[[8.6,27.68],[8.8,12.13]],"id":36010178},{"atl":[[3.9,4]],"id":36386524}],"con":true,"img":false}]}
{"op":"mcm","clk":"5353174048","pt":1646210299557,"mc":[{"id":"1.195453765","rc":[{"atb":[[2.42,0]],"id":41207262},{"atb":[[3.2,0]],"id":36386524}],"con":true,"img":false}]}
{"op":"mcm","clk":"5353174056","pt":1646210299660,"mc":[{"id":"1.195453765","rc":[{"atb":[[2.34,1.67]],"id":41207262}],"con":true,"img":false}]}
{"op":"mcm","clk":"5353174063","pt":1646210299769,"mc":[{"id":"1.195453765","rc":[{"atb":[[2.32,0]],"id":41207262}],"con":true,"img":false}]}
{"op":"mcm","clk":"5353174068","pt":1646210299866,"mc":[{"id":"1.195453765","rc":[{"atb":[[2.32,3.88]],"id":41207262}],"con":true,"img":false}]}
{"op":"mcm","clk":"5353174072","pt":1646210299971,"mc":[{"id":"1.195453765","rc":[{"atb":[[2.38,34.38]],"id":43167130},{"atb":[[5.7,12.59]],"id":43167131},{"atb":[[2.68,29.91]],"id":40209251}],"con":true,"img":false}]}
{"op":"mcm","clk":"5353174076","pt":1646210300022,"mc":[{"id":"1.195453765","rc":[{"atb":[[1.01,2.53]],"id":36010178}],"con":true,"img":false}]}
{"op":"mcm","clk":"5353174079","pt":1646210300125,"mc":[{"id":"1.195453765","rc":[{"atb":[[2.6,2.5],[2.62,83.37],[2.68,62.38]],"id":40209251}],"con":true,"img":false}]}
{"op":"mcm","clk":"5353174085","pt":1646210300229,"mc":[{"id":"1.195453765","rc":[{"atb":[[2.66,0]],"id":40209251},{"atb":[[1.01,1.69]],"id":36010178}],"con":true,"img":false}]}
{"op":"mcm","clk":"5353174096","pt":1646210300436,"mc":[{"id":"1.195453765","rc":[{"atl":[[3.85,0],[3.8,7.14]],"id":41207262},{"atb":[[1.01,0]],"id":36010178},{"atl":[[3.85,0],[4.1,4]],"id":36386524}],"con":true,"img":false}]}
{"op":"mcm","clk":"5353174102","pt":1646210300541,"mc":[{"id":"1.195453765","rc":[{"atb":[[10.5,1.69]],"id":36010178},{"atl":[[3.9,8.65]],"id":36386524}],"con":true,"img":false}]}
{"op":"mcm","clk":"5353174108","pt":1646210300643,"mc":[{"id":"1.195453765","rc":[{"atl":[[3.85,7.02],[3.8,0]],"id":41207262},{"atl":[[3.85,2],[4.1,0]],"id":36386524}],"con":true,"img":false}]}
{"op":"mcm","clk":"5353174125","pt":1646210300954,"mc":[{"id":"1.195453765","rc":[{"atb":[[2.5,5.01]],"id":43167130},{"atb":[[1.42,17.91]],"id":42401236}],"con":true,"img":false}]}
{"op":"mcm","clk":"5353174131","pt":1646210301156,"mc":[{"id":"1.195453765","rc":[{"atb":[[1.41,84.99]],"id":42401236}],"con":true,"img":false}]}
{"op":"mcm","clk":"5353174137","pt":1646210301263,"mc":[{"id":"1.195453765","rc":[{"atb":[[1.39,64.56]],"id":42401236}],"con":true,"img":false}]}
{"op":"mcm","clk":"5353174150","pt":1646210301533,"mc":[{"id":"1.195453765","rc":[{"atb":[[2.14,0],[2.16,21.39]],"id":41207262}],"con":true,"img":false}]}
{"op":"mcm","clk":"5353174216","pt":1646210302263,"mc":[{"id":"1.195453765","rc":[{"atb":[[2.5,71.31],[2.44,2.5]],"id":43167130}],"con":true,"img":false}]}
{"op":"mcm","clk":"5353174243","pt":1646210302729,"mc":[{"id":"1.195453765","rc":[{"atb":[[8.6,7.97],[8.8,24.76]],"id":36010178}],"con":true,"img":false}]}
{"op":"mcm","clk":"5353174250","pt":1646210302833,"mc":[{"id":"1.195453765","rc":[{"atb":[[2.18,22.21]],"id":41207262},{"atb":[[1.42,130.88]],"id":42401236}],"con":true,"img":false}]}
{"op":"mcm","clk":"5353174263","pt":1646210303041,"mc":[{"id":"1.195453765","rc":[{"atb":[[2.1,14.43]],"id":41207262}],"con":true,"img":false}]}
{"op":"mcm","clk":"5353174325","pt":1646210304076,"mc":[{"id":"1.195453765","rc":[{"atb":[[2.5,66.3]],"id":43167130},{"atb":[[1.42,112.96]],"id":42401236}],"con":true,"img":false}]}
{"op":"mcm","clk":"5353174354","pt":1646210304447,"mc":[{"id":"1.195453765","rc":[{"atb":[[2.02,0],[2.06,76.03]],"id":41207262},{"atl":[[3.35,0],[3.3,0],[3.45,12],[3.4,0]],"id":41207262},{"atb":[[2,0],[1.98,0],[1.96,0],[1.94,0],[1.92,21.74]],"id":43167130},{"atl":[[3.7,18.95],[3.55,7.84]],"id":43167130},{"atb":[[1.21,0],[1.22,90.91]],"id":42401236},{"atl":[[2.44,37.2],[2.4,18.28],[2.42,0],[2.46,0]],"id":42401236},{"atb":[[3.25,8.89]],"id":36386524},{"atl":[[4,0],[3.85,0],[3.95,0],[3.9,4.65]],"id":36386524}],"con":true,"img":false}]}
{"op":"mcm","clk":"5353174364","pt":1646210304545,"mc":[{"id":"1.195453765","rc":[{"atl":[[3.85,0],[3.95,27.48]],"id":41207262},{"atl":[[4.4,0],[3.9,25.86],[4.2,31.25]],"id":43167130},{"atl":[[2.68,122.95]],"id":42401236},{"atl":[[4.3,6.06],[4.2,8.44]],"id":40209251},{"atb":[[2.98,37.88],[3.05,72.41]],"id":36386524},{"atl":[[4.3,2],[6,2.5],[6.8,5],[6.6,56.95]],"id":36386524}],"con":true,"img":false}]}
{"op":"mcm","clk":"5353174371","pt":1646210304648,"mc":[{"id":"1.195453765","rc":[{"atl":[[3.8,9.14],[3.9,27.48]],"id":41207262},{"atl":[[3.8,73.08],[3.55,27.11]],"id":43167130},{"atl":[[2.44,0]],"id":42401236},{"atl":[[4.4,49.43]],"id":40209251},{"atb":[[3.25,19.05]],"id":36386524},{"atl":[[3.9,0]],"id":36386524}],"con":true,"img":false}]}
{"op":"mcm","clk":"5353174380","pt":1646210304753,"mc":[{"id":"1.195453765","rc":[{"atl":[[3.45,0]],"id":41207262},{"atl":[[3.7,0]],"id":43167130},{"atl":[[4.6,20.83]],"id":40209251},{"atb":[[3.25,10.16],[3.15,37.48]],"id":36386524},{"atl":[[4.3,12.16]],"id":36386524}],"con":true,"img":false}]}
{"op":"mcm","clk":"5353174383","pt":1646210304853,"mc":[{"id":"1.195453765","rc":[{"atb":[[6,5.89]],"id":43167131}],"con":true,"img":false}]}
{"op":"mcm","clk":"5353174388","pt":1646210304956,"mc":[{"id":"1.195453765","rc":[{"atb":[[3.25,0]],"id":36386524},{"atl":[[4.4,3]],"id":36386524}],"con":true,"img":false}]}
{"op":"mcm","clk":"5353174394","pt":1646210305061,"mc":[{"id":"1.195453765","rc":[{"atb":[[5.5,19.12],[5.7,31.91],[5.9,0]],"id":43167131},{"atb":[[3.15,54.22]],"id":36386524}],"con":true,"img":false}]}
{"op":"mcm","clk":"5353174402","pt":1646210305264,"mc":[{"id":"1.195453765","rc":[{"atb":[[2.38,0]],"id":43167130}],"con":true,"img":false}]}
{"op":"mcm","clk":"5353174416","pt":1646210305475,"mc":[{"id":"1.195453765","rc":[{"atb":[[2.16,10.5]],"id":41207262},{"atb":[[1.39,0]],"id":42401236},{"atb":[[10,4.17]],"id":36010178}],"con":true,"img":false}]}
{"op":"mcm","clk":"5353174420","pt":1646210305574,"mc":[{"id":"1.195453765","rc":[{"atb":[[1.99,50.51],[1.9,70.41]],"id":41207262},{"atb":[[5.5,0],[5.2,23.81]],"id":43167131},{"atb":[[3.1,9.52],[3.15,44.92]],"id":36386524},{"atl":[[6,6.5],[4.2,3]],"id":36386524}],"con":true,"img":false}]}
{"op":"mcm","clk":"5353174426","pt":1646210305679,"mc":[{"id":"1.195453765","rc":[{"atl":[[3.85,7.02],[3.8,2]],"id":41207262},{"atb":[[11,1.67]],"id":36010178},{"atb":[[3.2,1.67]],"id":36386524},{"atl":[[7.4,0],[4.4,0],[6.2,19.23],[4.1,4],[6.6,48.02],[7,0]],"id":36386524}],"con":true,"img":false}]}
{"op":"mcm","clk":"5353174429","pt":1646210305729,"mc":[{"id":"1.195453765","rc":[{"atl":[[4.2,11.02]],"id":36386524}],"con":true,"img":false}]}
{"op":"mcm","clk":"5353174438","pt":1646210305882,"mc":[{"id":"1.195453765","rc":[{"atb":[[1.99,0],[1.9,50.88]],"id":43167130},{"atl":[[4,2],[4.3,0],[6.6,0],[4.2,8.02]],"id":36386524}],"con":true,"img":false}]}
{"op":"mcm","clk":"5353174450","pt":1646210306038,"mc":[{"id":"1.195453765","rc":[{"atl":[[3.95,2]],"id":36386524}],"con":true,"img":false}]}
{"op":"mcm","clk":"5353174477","pt":1646210306559,"mc":[{"id":"1.195453765","rc":[{"atb":[[2.02,19.61],[2.06,57.16]],"id":41207262},{"atl":[[3.5,2]],"id":41207262},{"atb":[[2,20]],"id":43167130},{"atl":[[3.55,19.27],[3.75,7.27]],"id":43167130},{"atb":[[1.21,95.24],[1.22,0]],"id":42401236},{"atl":[[2.46,3]],"id":42401236},{"atl":[[3.9,4]],"id":36386524}],"con":true,"img":false}]}
{"op":"mcm","clk":"5353174487","pt":1646210306764,"mc":[{"id":"1.195453765","rc":[{"atl":[[3.45,2]],"id":41207262},{"atl":[[3.55,0]],"id":43167130},{"atl":[[3.85,3],[4.1,0]],"id":36386524}],"con":true,"img":false}]}
{"op":"mcm","clk":"5353174494","pt":1646210306862,"mc":[{"id":"1.195453765","rc":[{"atl":[[3.75,27.17]],"id":43167130}],"con":true,"img":false}]}
{"op":"mcm","clk":"5353174506","pt":1646210307070,"mc":[{"id":"1.195453765","rc":[{"atl":[[3.8,8.26],[3.95,6.78]],"id":41207262},{"atb":[[2.6,89.3],[2.62,18.43],[2.74,4.32]],"id":40209251}],"con":true,"img":false}]}
{"op":"mcm","clk":"5353174508","pt":1646210307169,"mc":[{"id":"1.195453765","rc":[{"atb":[[10.5,0]],"id":36010178}],"con":true,"img":false}]}
{"op":"mcm","clk":"5353174515","pt":1646210307272,"mc":[{"id":"1.195453765","rc":[{"atb":[[2.74,24.47]],"id":40209251}],"con":true,"img":false}]}
{"op":"mcm","clk":"5353174528","pt":1646210307480,"mc":[{"id":"1.195453765","rc":[{"atb":[[2.68,29.91]],"id":40209251},{"atl":[[1000,2.53]],"id":36010178}],"con":true,"img":false}]}
{"op":"mcm","clk":"5353174537","pt":1646210307582,"mc":[{"id":"1.195453765","rc":[{"atb":[[2.6,2.5],[2.62,82.79]],"id":40209251}],"con":true,"img":false}]}
{"op":"mcm","clk":"5353174542","pt":1646210307634,"mc":[{"id":"1.195453765","rc":[{"atl":[[1000,1.69]],"id":36010178}],"con":true,"img":false}]}
{"op":"mcm","clk":"5353174551","pt":1646210307842,"mc":[{"id":"1.195453765","rc":[{"atb":[[2.68,1.67]],"id":40209251},{"atb":[[5.7,21.82]],"id":43167131},{"atl":[[1000,0]],"id":36010178}],"con":true,"img":false}]}
{"op":"mcm","clk":"5353174558","pt":1646210307944,"mc":[{"id":"1.195453765","rc":[{"atl":[[30,1.69]],"id":36010178}],"con":true,"img":false}]}
{"op":"mcm","clk":"5353174614","pt":1646210309071,"mc":[{"id":"1.195453765","rc":[{"atl":[[3.4,3]],"id":41207262},{"atl":[[2.44,3]],"id":42401236}],"con":true,"img":false}]}
{"op":"mcm","clk":"5353174624","pt":1646210309279,"mc":[{"id":"1.195453765","rc":[{"atb":[[2.02,0],[2.06,76.03],[2.18,29.97],[2.16,0]],"id":41207262},{"atl":[[3.5,0],[3.45,0],[3.4,0]],"id":41207262},{"atb":[[1.21,0],[1.22,90.91]],"id":42401236},{"atl":[[2.44,0],[2.42,2],[2.46,0]],"id":42401236},{"atb":[[2.98,2]],"id":40209251},{"atl":[[3.85,0],[3.8,2],[4,0],[3.95,0],[3.9,0]],"id":36386524}],"con":true,"img":false}]}
{"op":"mcm","clk":"5353174628","pt":1646210309330,"mc":[{"id":"1.195453765","rc":[{"atl":[[3.9,34.38]],"id":41207262}],"con":true,"img":false}]}
{"op":"mcm","clk":"5353174634","pt":1646210309433,"mc":[{"id":"1.195453765","rc":[{"atl":[[3.85,0],[3.8,2]],"id":41207262},{"atl":[[2.42,0]],"id":42401236},{"atb":[[3,4],[2.98,0]],"id":40209251},{"atl":[[3.75,3]],"id":36386524}],"con":true,"img":false}]}
{"op":"mcm","clk":"5353174645","pt":1646210309642,"mc":[{"id":"1.195453765","rc":[{"atl":[[3.85,7.02],[3.9,27.48]],"id":41207262},{"atb":[[3,0],[3.05,3]],"id":40209251},{"atl":[[3.7,2]],"id":36386524}],"con":true,"img":false}]}
{"op":"mcm","clk":"5353174662","pt":1646210310056,"mc":[{"id":"1.195453765","rc":[{"atb":[[2.56,4.82]],"id":43167130},{"atb":[[1.45,16.72]],"id":42401236},{"atb":[[2.74,20.15]],"id":40209251},{"atl":[[30,4.45]],"id":36010178}],"con":true,"img":false}]}
{"op":"mcm","clk":"5353174669","pt":1646210310156,"mc":[{"id":"1.195453765","rc":[{"atb":[[2.5,0]],"id":43167130},{"atb":[[1.41,20.37],[1.42,205.58]],"id":42401236},{"atl":[[32,0]],"id":36010178}],"con":true,"img":false}]}
{"op":"mcm","clk":"5353174675","pt":1646210310259,"mc":[{"id":"1.195453765","rc":[{"atb":[[2.56,83.12]],"id":43167130},{"atl":[[34,10.72],[36,0]],"id":36010178}],"con":true,"img":false}]}
{"op":"mcm","clk":"5353174679","pt":1646210310363,"mc":[{"id":"1.195453765","rc":[{"atb":[[2.46,32.49]],"id":43167130},{"atb":[[3.1,3]],"id":40209251},{"atl":[[3.65,3]],"id":36386524}],"con":true,"img":false}]}
{"op":"mcm","clk":"5353174713","pt":1646210310878,"mc":[{"id":"1.195453765","rc":[{"atb":[[3.15,4]],"id":40209251},{"atl":[[5.4,0]],"id":40209251}],"con":true,"img":false}]}
{"op":"mcm","clk":"5353174719","pt":1646210310981,"mc":[{"id":"1.195453765","rc":[{"atb":[[2.2,9.94]],"id":41207262},{"atb":[[1.43,47.34]],"id":42401236},{"atl":[[5.2,23.81]],"id":40209251},{"atl":[[18.5,4.57]],"id":43167131}],"con":true,"img":false}]}
{"op":"mcm","clk":"5353174721","pt":1646210311035,"mc":[{"id":"1.195453765","rc":[{"atb":[[2.62,18.43]],"id":40209251}],"con":true,"img":false}]}
{"op":"mcm","clk":"5353174728","pt":1646210311138,"mc":[{"id":"1.195453765","rc":[{"atl":[[19,0],[19.5,18.25],[22,1]],"id":43167131}],"con":true,"img":false}]}
{"op":"mcm","clk":"5353174750","pt":1646210311449,"mc":[{"id":"1.195453765","rc":[{"atl":[[4.1,32.26],[4.2,0]],"id":43167130},{"atl":[[2.78,95.12],[2.68,2.59]],"id":42401236},{"atb":[[2.68,0]],"id":40209251},{"atb":[[11,0]],"id":36010178},{"atb":[[3.2,0]],"id":36386524}],"con":true,"img":false}]}
{"op":"mcm","clk":"5353174757","pt":1646210311551,"mc":[{"id":"1.195453765","rc":[{"atl":[[3.8,17.86],[3.9,106.13]],"id":43167130},{"atb":[[8.6,26.6],[8.8,12.13]],"id":36010178}],"con":true,"img":false}]}
{"op":"mcm","clk":"5353174762","pt":1646210311656,"mc":[{"id":"1.195453765","rc":[{"atb":[[10,0],[10.5,1.67]],"id":36010178}],"con":true,"img":false}]}
{"op":"mcm","clk":"5353174766","pt":1646210311759,"mc":[{"id":"1.195453765","rc":[{"atb":[[8.8,22.39]],"id":36010178}],"con":true,"img":false}]}
{"op":"mcm","clk":"5353174777","pt":1646210311963,"mc":[{"id":"1.195453765","rc":[{"atb":[[5.2,60.02],[5.7,2.5]],"id":43167131},{"atl":[[34,9.76]],"id":36010178}],"con":true,"img":false}]}
{"op":"mcm","clk":"5353174783","pt":1646210312067,"mc":[{"id":"1.195453765","rc":[{"atl":[[30,5.41]],"id":36010178}],"con":true,"img":false}]}
