{"op":"mcm","clk":"5317728435","pt":1646251399784,"mc":[{"id":"1.195532854","marketDefinition":{"bspMarket":true,"turnInPlayEnabled":false,"persistenceEnabled":false,"marketBaseRate":5.0,"eventId":"31275720","eventTypeId":"4339","numberOfWinners":1,"bettingType":"ODDS","marketType":"WIN","marketTime":"2022-03-03T14:12:00.000Z","suspendTime":"2022-03-03T14:12:00.000Z","bspReconciled":false,"complete":true,"inPlay":false,"crossMatching":false,"runnersVoidable":false,"numberOfActiveRunners":6,"betDelay":0,"status":"OPEN","runners":[{"status":"ACTIVE","sortPriority":1,"id":36042605,"name":"1. Droopys Icing"},{"status":"ACTIVE","sortPriority":2,"id":42190933,"name":"2. Patagonia"},{"status":"ACTIVE","sortPriority":3,"id":42609833,"name":"3. Tip Top Saka"},{"status":"ACTIVE","sortPriority":4,"id":41064149,"name":"4. Bang On Esmae"},{"status":"ACTIVE","sortPriority":5,"id":38833999,"name":"5. Adorable Emma"},{"status":"ACTIVE","sortPriority":6,"id":28603686,"name":"6. Trapstyle Flash"}],"regulators":["MR_INT"],"venue":"Romford","countryCode":"GB","discountAllowed":false,"timezone":"Europe/London","openDate":"2022-03-03T13:57:00.000Z","version":4384107284,"name":"A8 400m","eventName":"Romford 3rd Mar"},"rc":[],"con":true,"img":false}]}
{"op":"mcm","clk":"5317728692","pt":1646251400815,"mc":[{"id":"1.195532854","marketDefinition":{"bspMarket":true,"turnInPlayEnabled":false,"persistenceEnabled":false,"marketBaseRate":5.0,"eventId":"31275720","eventTypeId":"4339","numberOfWinners":1,"bettingType":"ODDS","marketType":"WIN","marketTime":"2022-03-03T14:12:00.000Z","suspendTime":"2022-03-03T14:12:00.000Z","bspReconciled":false,"complete":true,"inPlay":false,"crossMatching":false,"runnersVoidable":false,"numberOfActiveRunners":6,"betDelay":0,"status":"OPEN","runners":[{"status":"ACTIVE","sortPriority":1,"id":36042605,"name":"1. Droopys Icing"},{"status":"ACTIVE","sortPriority":2,"id":42190933,"name":"2. Patagonia"},{"status":"ACTIVE","sortPriority":3,"id":42609833,"name":"3. Tip Top Saka"},{"status":"ACTIVE","sortPriority":4,"id":41064149,"name":"4. Bang On Esmae"},{"status":"ACTIVE","sortPriority":5,"id":38833999,"name":"5. Adorable Emma"},{"status":"ACTIVE","sortPriority":6,"id":28603686,"name":"6. Trapstyle Flash"}],"regulators":["MR_INT"],"venue":"Romford","countryCode":"GB","discountAllowed":true,"timezone":"Europe/London","openDate":"2022-03-03T13:57:00.000Z","version":4384107284,"name":"A8 400m","eventName":"Romford 3rd Mar"},"rc":[],"con":true,"img":false}]}
{"op":"mcm","clk":"5318488884","pt":1646259138605,"mc":[{"id":"1.195532854","rc":[{"atl":[[560,3]],"id":38833999},{"spn":1.0,"spf":"NaN","id":38833999},{"atl":[[550,3]],"id":42609833},{"spn":1.0,"spf":"NaN","id":42609833},{"atl":[[390,3]],"id":42190933},{"spn":1.0,"spf":"NaN","id":42190933},{"atl":[[370,3]],"id":36042605},{"spn":1.0,"spf":"NaN","id":36042605},{"atl":[[270,3]],"id":41064149},{"spn":1.0,"spf":"NaN","id":41064149}],"con":true,"img":false}]}
{"op":"mcm","clk":"5318488894","pt":1646259138707,"mc":[{"id":"1.195532854","rc":[{"atb":[[1.14,30]],"id":28603686},{"atl":[[500,3]],"id":28603686},{"atb":[[1.12,30]],"id":38833999},{"atb":[[1.12,30]],"id":42609833},{"atb":[[1.12,30]],"id":42190933},{"atb":[[1.12,30]],"id":36042605},{"atb":[[1.12,30]],"id":41064149}],"con":true,"img":false}]}
{"op":"mcm","clk":"5318509044","pt":1646259402464,"mc":[{"id":"1.195532854","marketDefinition":{"bspMarket":true,"turnInPlayEnabled":false,"persistenceEnabled":false,"marketBaseRate":5.0,"eventId":"31275720","eventTypeId":"4339","numberOfWinners":1,"bettingType":"ODDS","marketType":"WIN","marketTime":"2022-03-03T14:12:00.000Z","suspendTime":"2022-03-03T14:12:00.000Z","bspReconciled":false,"complete":true,"inPlay":false,"crossMatching":false,"runnersVoidable":false,"numberOfActiveRunners":6,"betDelay":0,"status":"OPEN","runners":[{"status":"ACTIVE","sortPriority":1,"id":36042605,"name":"1. Droopys Icing"},{"status":"ACTIVE","sortPriority":2,"id":42190933,"name":"2. Patagonia"},{"status":"ACTIVE","sortPriority":3,"id":42609833,"name":"3. Tip Top Saka"},{"status":"ACTIVE","sortPriority":4,"id":41064149,"name":"4. Bang On Esmae"},{"status":"ACTIVE","sortPriority":5,"id":38833999,"name":"5. Adorable Emma"},{"status":"ACTIVE","sortPriority":6,"id":28603686,"name":"6. Trapstyle Flash"}],"regulators":["MR_INT"],"venue":"Romford","countryCode":"GB","discountAllowed":true,"timezone":"Europe/London","openDate":"2022-03-03T13:57:00.000Z","version":4384107284,"name":"A8 400m","eventName":"Romford 3rd Mar"},"rc":[{"atb":[[1.14,30]],"id":28603686},{"atl":[[500,3]],"id":28603686},{"spn":250.57,"spf":"NaN","id":28603686},{"atb":[[1.12,30]],"id":38833999},{"atl":[[560,3]],"id":38833999},{"spn":280.56,"spf":"NaN","id":38833999},{"atb":[[1.12,30]],"id":42609833},{"atl":[[550,3]],"id":42609833},{"spn":275.56,"spf":"NaN","id":42609833},{"atb":[[1.12,30]],"id":42190933},{"atl":[[390,3]],"id":42190933},{"spn":195.56,"spf":"NaN","id":42190933},{"atb":[[1.12,30]],"id":36042605},{"atl":[[370,3]],"id":36042605},{"spn":185.56,"spf":"NaN","id":36042605},{"atb":[[1.12,30]],"id":41064149},{"atl":[[270,3]],"id":41064149},{"spn":135.56,"spf":"NaN","id":41064149}],"con":true,"img":true}]}
{"op":"mcm","clk":"5320139799","pt":1646287408958,"mc":[{"id":"1.195532854","rc":[{"atb":[[2.06,8.61]],"id":28603686},{"spn":251.03,"spf":"NaN","id":28603686},{"atb":[[2.04,11.94]],"id":38833999},{"spn":281.02,"spf":"NaN","id":38833999},{"atb":[[2.06,12.05]],"id":42609833},{"spn":276.03,"spf":"NaN","id":42609833},{"atb":[[2.02,10.98]],"id":42190933},{"spn":196.01,"spf":"NaN","id":42190933},{"atb":[[2.1,11.41]],"id":36042605},{"spn":186.05,"spf":"NaN","id":36042605},{"atb":[[2,10.03]],"id":41064149},{"spn":136.0,"spf":"NaN","id":41064149}],"con":true,"img":false}]}
{"op":"mcm","clk":"5320249792","pt":1646291099904,"mc":[{"id":"1.195532854","rc":[{"spl":[[1.01,10]],"id":42609833},{"spn":2.06,"spf":1.0,"id":42609833}],"con":true,"img":false}]}
{"op":"mcm","clk":"5320453234","pt":1646295823143,"mc":[{"id":"1.195532854","rc":[{"atb":[[2.06,8.61]],"id":28603686},{"spl":[[8.6,10]],"id":28603686},{"spn":5.33,"spf":1.0,"id":28603686},{"atb":[[2.04,11.94]],"id":38833999},{"spl":[[10,10]],"id":38833999},{"spn":6.02,"spf":1.0,"id":38833999},{"atb":[[2.06,12.06]],"id":42609833},{"spl":[[27,10]],"id":42609833},{"atb":[[2.02,10.98]],"id":42190933},{"spl":[[75,10]],"id":42190933},{"spn":38.51,"spf":1.0,"id":42190933},{"atb":[[2.1,11.41]],"id":36042605},{"spl":[[9.8,10]],"id":36042605},{"spn":5.95,"spf":1.0,"id":36042605},{"atb":[[2,10.04]],"id":41064149},{"spl":[[6.2,10]],"id":41064149},{"spn":4.1,"spf":1.0,"id":41064149}],"con":true,"img":false}]}
{"op":"mcm","clk":"5320551652","pt":1646297355683,"mc":[{"id":"1.195532854","rc":[{"spl":[[21,1]],"id":28603686},{"spl":[[21,1]],"id":38833999},{"spl":[[21,1]],"id":42609833},{"spl":[[21,1]],"id":42190933},{"spn":11.51,"spf":1.0,"id":42190933},{"spl":[[21,1]],"id":36042605},{"spl":[[21,1]],"id":41064149}],"con":true,"img":false}]}
{"op":"mcm","clk":"5320830273","pt":1646302602588,"mc":[{"id":"1.195532854","marketDefinition":{"bspMarket":true,"turnInPlayEnabled":false,"persistenceEnabled":false,"marketBaseRate":5.0,"eventId":"31275720","eventTypeId":"4339","numberOfWinners":1,"bettingType":"ODDS","marketType":"WIN","marketTime":"2022-03-03T14:12:00.000Z","suspendTime":"2022-03-03T14:12:00.000Z","bspReconciled":false,"complete":true,"inPlay":false,"crossMatching":false,"runnersVoidable":false,"numberOfActiveRunners":6,"betDelay":0,"status":"OPEN","runners":[{"status":"ACTIVE","sortPriority":1,"id":36042605,"name":"1. Droopys Icing"},{"status":"ACTIVE","sortPriority":2,"id":42190933,"name":"2. Patagonia"},{"status":"ACTIVE","sortPriority":3,"id":42609833,"name":"3. Tip Top Saka"},{"status":"ACTIVE","sortPriority":4,"id":41064149,"name":"4. Bang On Esmae"},{"status":"ACTIVE","sortPriority":5,"id":38833999,"name":"5. Adorable Emma"},{"status":"ACTIVE","sortPriority":6,"id":28603686,"name":"6. Trapstyle Flash"}],"regulators":["MR_INT"],"venue":"Romford","countryCode":"GB","discountAllowed":true,"timezone":"Europe/London","openDate":"2022-03-03T13:57:00.000Z","version":4384107284,"name":"A8 400m","eventName":"Romford 3rd Mar"},"rc":[{"atb":[[2.06,8.61],[1.14,30]],"id":28603686},{"spl":[[8.6,10],[21,1]],"id":28603686},{"atl":[[500,3]],"id":28603686},{"spn":5.33,"spf":1.0,"id":28603686},{"atb":[[1.12,30],[2.04,11.94]],"id":38833999},{"spl":[[10,10],[21,1]],"id":38833999},{"atl":[[560,3]],"id":38833999},{"spn":6.02,"spf":1.0,"id":38833999},{"atb":[[1.12,30],[2.06,12.05]],"id":42609833},{"spl":[[1.01,10],[21,1],[27,10]],"id":42609833},{"atl":[[550,3]],"id":42609833},{"spn":2.06,"spf":1.0,"id":42609833},{"atb":[[1.12,30],[2.02,10.98]],"id":42190933},{"spl":[[75,10],[21,1]],"id":42190933},{"atl":[[390,3]],"id":42190933},{"spn":11.51,"spf":1.0,"id":42190933},{"atb":[[1.12,30],[2.1,11.41]],"id":36042605},{"spl":[[21,1],[9.8,10]],"id":36042605},{"atl":[[370,3]],"id":36042605},{"spn":5.95,"spf":1.0,"id":36042605},{"atb":[[2,10.03],[1.12,30]],"id":41064149},{"spl":[[6.2,10],[21,1]],"id":41064149},{"atl":[[270,3]],"id":41064149},{"spn":4.1,"spf":1.0,"id":41064149}],"con":true,"img":true}]}
{"op":"mcm","clk":"5320956211","pt":1646304331199,"mc":[{"id":"1.195532854","rc":[{"atb":[[2.06,8.61]],"id":28603686},{"atl":[[1000,2.5]],"id":28603686},{"atb":[[2.04,11.94]],"id":38833999},{"atl":[[1000,2.5]],"id":38833999},{"atb":[[2.06,12.05]],"id":42609833},{"atl":[[1000,2.5]],"id":42609833},{"atb":[[2.02,10.98]],"id":42190933},{"atl":[[1000,2.5]],"id":42190933},{"atb":[[2.1,11.41]],"id":36042605},{"atl":[[1000,2.5]],"id":36042605},{"atb":[[2,10.03]],"id":41064149},{"atl":[[1000,2.5]],"id":41064149}],"con":true,"img":false}]}
{"op":"mcm","clk":"5320956233","pt":1646304331717,"mc":[{"id":"1.195532854","rc":[{"atl":[[1000,12.5]],"id":28603686},{"atl":[[1000,12.5]],"id":38833999},{"atl":[[1000,12.5]],"id":42609833},{"atl":[[1000,12.5]],"id":42190933},{"atl":[[1000,12.5]],"id":41064149},{"atl":[[1000,12.5]],"id":36042605}],"con":true,"img":false}]}
{"op":"mcm","clk":"5320956256","pt":1646304332187,"mc":[{"id":"1.195532854","rc":[{"atb":[[1.01,1000]],"id":28603686},{"atb":[[1.01,1000]],"id":38833999},{"atb":[[1.01,1000]],"id":42609833},{"atb":[[1.01,1000]],"id":42190933},{"atb":[[1.01,1000]],"id":41064149},{"atb":[[1.01,1000]],"id":36042605}],"con":true,"img":false}]}
{"op":"mcm","clk":"5320956266","pt":1646304332396,"mc":[{"id":"1.195532854","rc":[{"atb":[[1.01,11000]],"id":28603686},{"atb":[[1.01,11000]],"id":38833999},{"atb":[[1.01,11000]],"id":42609833},{"atb":[[1.01,11000]],"id":42190933},{"atb":[[1.01,11000]],"id":41064149},{"atb":[[1.01,11000]],"id":36042605}],"con":true,"img":false}]}
{"op":"mcm","clk":"5320961051","pt":1646304411248,"mc":[{"id":"1.195532854","rc":[{"spb":[[1000,11.06]],"id":42609833},{"spn":2.1,"spf":2.1,"id":42609833}],"con":true,"img":false}]}
{"op":"mcm","clk":"5321025560","pt":1646305286949,"mc":[{"id":"1.195532854","rc":[{"atb":[[2.06,8.61],[6,2]],"id":28603686},{"spn":7.3,"spf":1.0,"id":28603686},{"atb":[[5.1,2],[2.04,11.94]],"id":38833999},{"spn":7.55,"spf":1.0,"id":38833999},{"atb":[[2.06,12.06],[10,2]],"id":42609833},{"spn":4.41,"spf":2.1,"id":42609833},{"atb":[[2.02,10.98],[6,2]],"id":42190933},{"spn":13.5,"spf":1.0,"id":42190933},{"atb":[[2,10.04],[2.74,2]],"id":41064149},{"spn":4.47,"spf":1.0,"id":41064149},{"atb":[[8,2],[2.1,11.41]],"id":36042605},{"spn":8.9,"spf":1.0,"id":36042605}],"con":true,"img":false}]}
{"op":"mcm","clk":"5321028072","pt":1646305320234,"mc":[{"id":"1.195532854","marketDefinition":{"bspMarket":true,"turnInPlayEnabled":false,"persistenceEnabled":false,"marketBaseRate":5.0,"eventId":"31275720","eventTypeId":"4339","numberOfWinners":1,"bettingType":"ODDS","marketType":"WIN","marketTime":"2022-03-03T14:12:00.000Z","suspendTime":"2022-03-03T14:12:00.000Z","bspReconciled":false,"complete":true,"inPlay":false,"crossMatching":true,"runnersVoidable":false,"numberOfActiveRunners":6,"betDelay":0,"status":"OPEN","runners":[{"status":"ACTIVE","sortPriority":1,"id":36042605,"name":"1. Droopys Icing"},{"status":"ACTIVE","sortPriority":2,"id":42190933,"name":"2. Patagonia"},{"status":"ACTIVE","sortPriority":3,"id":42609833,"name":"3. Tip Top Saka"},{"status":"ACTIVE","sortPriority":4,"id":41064149,"name":"4. Bang On Esmae"},{"status":"ACTIVE","sortPriority":5,"id":38833999,"name":"5. Adorable Emma"},{"status":"ACTIVE","sortPriority":6,"id":28603686,"name":"6. Trapstyle Flash"}],"regulators":["MR_INT"],"venue":"Romford","countryCode":"GB","discountAllowed":true,"timezone":"Europe/London","openDate":"2022-03-03T13:57:00.000Z","version":4384107284,"name":"A8 400m","eventName":"Romford 3rd Mar"},"rc":[],"con":true,"img":false}]}
{"op":"mcm","clk":"5321074410","pt":1646305849451,"mc":[{"id":"1.195532854","rc":[{"atb":[[10,5]],"id":42609833},{"spn":6.93,"spf":2.1,"id":42609833}],"con":true,"img":false}]}
{"op":"mcm","clk":"5321074481","pt":1646305850240,"mc":[{"id":"1.195532854","rc":[{"atb":[[10,3]],"id":42609833}],"con":true,"img":false}]}
{"op":"mcm","clk":"5321097193","pt":1646306132942,"mc":[{"id":"1.195532854","rc":[{"atb":[[5.1,2]],"id":28603686},{"atl":[[11,1.01]],"id":28603686},{"atb":[[4.3,2]],"id":38833999},{"atl":[[8.6,1.33]],"id":38833999},{"spn":6.85,"spf":1.0,"id":38833999},{"atb":[[8.2,1.4]],"id":42609833},{"atl":[[24,0.44]],"id":42609833},{"spn":6.18,"spf":2.1,"id":42609833},{"atb":[[5.1,2]],"id":42190933},{"atl":[[11,1.01]],"id":42190933},{"spn":8.5,"spf":1.0,"id":42190933},{"atb":[[6.2,1.93]],"id":36042605},{"atl":[[14,0.78]],"id":36042605},{"atb":[[2.52,2]],"id":41064149},{"atl":[[4,2]],"id":41064149},{"spn":3.37,"spf":1.0,"id":41064149}],"con":true,"img":false}]}
{"op":"mcm","clk":"5321151024","pt":1646306606917,"mc":[{"id":"1.195532854","rc":[{"atb":[[5.1,1]],"id":38833999},{"trd":[[5.1,2]],"ltp":5.1,"tv":2.0,"id":38833999}],"con":true,"img":false}]}
{"op":"mcm","clk":"5321151066","pt":1646306607328,"mc":[{"id":"1.195532854","rc":[{"atb":[[2.66,6.75]],"id":42609833},{"atb":[[2.46,7.67]],"id":36042605}],"con":true,"img":false}]}
{"op":"mcm","clk":"5321151075","pt":1646306607432,"mc":[{"id":"1.195532854","rc":[{"atb":[[2.36,8.24]],"id":28603686},{"atb":[[2.36,8.24]],"id":42190933}],"con":true,"img":false}]}
{"op":"mcm","clk":"5321151092","pt":1646306607540,"mc":[{"id":"1.195532854","rc":[{"atb":[[2.04,10.77]],"id":41064149}],"con":true,"img":false}]}
{"op":"mcm","clk":"5321151117","pt":1646306607706,"mc":[{"id":"1.195532854","rc":[{"atb":[[2.22,9.19]],"id":38833999}],"con":true,"img":false}]}
{"op":"mcm","clk":"5321151302","pt":1646306609424,"mc":[{"id":"1.195532854","rc":[{"atb":[[5.1,2]],"id":38833999}],"con":true,"img":false}]}
{"op":"mcm","clk":"5321152395","pt":1646306619057,"mc":[{"id":"1.195532854","rc":[{"atb":[[2.5,8.28]],"id":36042605}],"con":true,"img":false}]}
{"op":"mcm","clk":"5321152437","pt":1646306619318,"mc":[{"id":"1.195532854","rc":[{"atb":[[2.4,8.87]],"id":42190933}],"con":true,"img":false}]}
{"op":"mcm","clk":"5321152475","pt":1646306619630,"mc":[{"id":"1.195532854","rc":[{"atb":[[2.08,11.5]],"id":41064149}],"con":true,"img":false}]}
{"op":"mcm","clk":"5321152529","pt":1646306620143,"mc":[{"id":"1.195532854","rc":[{"atb":[[2.7,7.3]],"id":42609833}],"con":true,"img":false}]}
{"op":"mcm","clk":"5321152567","pt":1646306620454,"mc":[{"id":"1.195532854","rc":[{"atb":[[2.26,9.85]],"id":38833999}],"con":true,"img":false}]}
{"op":"mcm","clk":"5321152611","pt":1646306620877,"mc":[{"id":"1.195532854","rc":[{"atb":[[2.4,8.87]],"id":28603686}],"con":true,"img":false}]}
{"op":"mcm","clk":"5321172430","pt":1646306808644,"mc":[{"id":"1.195532854","rc":[{"atb":[[10,0]],"id":42609833},{"trd":[[10,6]],"ltp":10.0,"tv":6.0,"id":42609833},{"spn":3.93,"spf":2.1,"id":42609833}],"con":true,"img":false}]}
{"op":"mcm","clk":"5321172594","pt":1646306810515,"mc":[{"id":"1.195532854","rc":[{"atb":[[10,2]],"id":42609833}],"con":true,"img":false}]}
{"op":"mcm","clk":"5321176205","pt":1646306854201,"mc":[{"id":"1.195532854","rc":[{"atb":[[2.36,0]],"id":28603686},{"atb":[[2.22,0]],"id":38833999},{"atb":[[2.66,0]],"id":42609833},{"atb":[[2.36,0]],"id":42190933},{"atb":[[2.04,0]],"id":41064149},{"atb":[[2.46,0]],"id":36042605}],"con":true,"img":false}]}
{"op":"mcm","clk":"5321176448","pt":1646306857377,"mc":[{"id":"1.195532854","rc":[{"atb":[[2.54,7.27]],"id":36042605}],"con":true,"img":false}]}
{"op":"mcm","clk":"5321176458","pt":1646306857487,"mc":[{"id":"1.195532854","rc":[{"atb":[[2.3,8.62]],"id":38833999},{"atb":[[2.44,7.78]],"id":42190933}],"con":true,"img":false}]}
{"op":"mcm","clk":"5321176464","pt":1646306857582,"mc":[{"id":"1.195532854","rc":[{"atb":[[2.12,10]],"id":41064149}],"con":true,"img":false}]}
{"op":"mcm","clk":"5321176471","pt":1646306857717,"mc":[{"id":"1.195532854","rc":[{"atb":[[2.44,7.78]],"id":28603686},{"atb":[[2.74,6.44]],"id":42609833}],"con":true,"img":false}]}
{"op":"mcm","clk":"5321180095","pt":1646306901978,"mc":[{"id":"1.195532854","rc":[{"atb":[[2.04,0]],"id":38833999},{"spn":5.64,"spf":2.1,"id":42609833},{"atb":[[2,0]],"id":41064149}],"con":true,"img":false}]}
{"op":"mcm","clk":"5321180106","pt":1646306902031,"mc":[{"id":"1.195532854","rc":[{"atb":[[2.32,11.94]],"id":38833999},{"atb":[[2.14,10.04]],"id":41064149}],"con":true,"img":false}]}
{"op":"mcm","clk":"5321199475","pt":1646307115994,"mc":[{"id":"1.195532854","rc":[{"atb":[[2.4,0]],"id":28603686},{"atb":[[2.26,0]],"id":38833999},{"atb":[[2.7,0]],"id":42609833},{"atb":[[2.4,0]],"id":42190933},{"atb":[[2.08,0]],"id":41064149},{"atb":[[2.5,0]],"id":36042605}],"con":true,"img":false}]}
{"op":"mcm","clk":"5321200984","pt":1646307132629,"mc":[{"id":"1.195532854","rc":[{"atb":[[2.78,6.98]],"id":42609833}],"con":true,"img":false}]}
{"op":"mcm","clk":"5321200996","pt":1646307132735,"mc":[{"id":"1.195532854","rc":[{"atb":[[2.58,7.86]],"id":36042605}],"con":true,"img":false}]}
{"op":"mcm","clk":"5321201010","pt":1646307132938,"mc":[{"id":"1.195532854","rc":[{"atb":[[2.48,8.4]],"id":28603686},{"atb":[[2.18,10.52]],"id":41064149}],"con":true,"img":false}]}
{"op":"mcm","clk":"5321201033","pt":1646307133202,"mc":[{"id":"1.195532854","rc":[{"atb":[[2.36,9.13]],"id":38833999},{"atb":[[2.48,8.4]],"id":42190933}],"con":true,"img":false}]}
{"op":"mcm","clk":"5321201528","pt":1646307139248,"mc":[{"id":"1.195532854","rc":[{"atb":[[2.3,0]],"id":38833999},{"atb":[[2.12,0]],"id":41064149}],"con":true,"img":false}]}
{"op":"mcm","clk":"5321201806","pt":1646307142558,"mc":[{"id":"1.195532854","rc":[{"atb":[[2.4,8]],"id":38833999}],"con":true,"img":false}]}
{"op":"mcm","clk":"5321201829","pt":1646307142718,"mc":[{"id":"1.195532854","rc":[{"atb":[[2.22,9.19]],"id":41064149}],"con":true,"img":false}]}
{"op":"mcm","clk":"5321207603","pt":1646307200872,"mc":[{"id":"1.195532854","rc":[{"spn":5.66,"spf":2.1,"id":42609833},{"atb":[[2.14,0]],"id":41064149}],"con":true,"img":false}]}
{"op":"mcm","clk":"5321207614","pt":1646307200931,"mc":[{"id":"1.195532854","rc":[{"atb":[[2.24,10.04]],"id":41064149}],"con":true,"img":false}]}
{"op":"mcm","clk":"5321215289","pt":1646307282900,"mc":[{"id":"1.195532854","rc":[{"atb":[[5.1,0],[5.7,2]],"id":38833999},{"spn":7.15,"spf":1.0,"id":38833999},{"atb":[[10,0],[6.8,2]],"id":42609833},{"spn":4.95,"spf":2.1,"id":42609833},{"atb":[[2.74,0],[2.96,2]],"id":41064149},{"spn":3.48,"spf":1.0,"id":41064149},{"atb":[[8,0],[7.8,2]],"id":36042605},{"spn":8.8,"spf":1.0,"id":36042605}],"con":true,"img":false}]}
{"op":"mcm","clk":"5321222581","pt":1646307349693,"mc":[{"id":"1.195532854","rc":[{"atb":[[2.44,0]],"id":28603686},{"atb":[[2.74,0]],"id":42609833},{"atb":[[2.44,0]],"id":42190933},{"atb":[[2.54,0]],"id":36042605}],"con":true,"img":false}]}
{"op":"mcm","clk":"5321226705","pt":1646307387384,"mc":[{"id":"1.195532854","rc":[{"atb":[[2.36,0]],"id":38833999},{"atb":[[2.18,0]],"id":41064149}],"con":true,"img":false}]}
{"op":"mcm","clk":"5321231712","pt":1646307437629,"mc":[{"id":"1.195532854","rc":[{"atb":[[2.22,0]],"id":41064149}],"con":true,"img":false}]}
{"op":"mcm","clk":"5321247341","pt":1646307594239,"mc":[{"id":"1.195532854","rc":[{"atb":[[2.48,0]],"id":28603686},{"atb":[[2.78,0]],"id":42609833},{"spn":4.65,"spf":2.1,"id":42609833},{"atb":[[2.48,0]],"id":42190933},{"atb":[[2.58,0]],"id":36042605}],"con":true,"img":false}]}
{"op":"mcm","clk":"5321249431","pt":1646307624126,"mc":[{"id":"1.195532854","rc":[{"atb":[[2.4,0]],"id":38833999}],"con":true,"img":false}]}
{"op":"mcm","clk":"5321274945","pt":1646307931694,"mc":[{"id":"1.195532854","rc":[{"atl":[[11,0]],"id":28603686},{"atb":[[8.2,0]],"id":42609833},{"spn":3.67,"spf":2.1,"id":42609833},{"atl":[[11,0]],"id":42190933},{"spn":13.5,"spf":1.0,"id":42190933},{"atl":[[14,0]],"id":36042605}],"con":true,"img":false}]}
{"op":"mcm","clk":"5321274957","pt":1646307931796,"mc":[{"id":"1.195532854","rc":[{"atl":[[10.5,1.06]],"id":28603686},{"atb":[[5.3,2]],"id":42609833},{"atl":[[10.5,1.06]],"id":42190933},{"atl":[[13,0.84]],"id":36042605}],"con":true,"img":false}]}
{"op":"mcm","clk":"5321275100","pt":1646307933308,"mc":[{"id":"1.195532854","rc":[{"atb":[[2.52,7.37]],"id":36042605}],"con":true,"img":false}]}
{"op":"mcm","clk":"5321275124","pt":1646307933522,"mc":[{"id":"1.195532854","rc":[{"atb":[[2.42,7.89]],"id":42190933}],"con":true,"img":false}]}
{"op":"mcm","clk":"5321275131","pt":1646307933619,"mc":[{"id":"1.195532854","rc":[{"atb":[[2.76,6.36]],"id":42609833}],"con":true,"img":false}]}
{"op":"mcm","clk":"5321275141","pt":1646307933724,"mc":[{"id":"1.195532854","rc":[{"atb":[[2.42,7.89]],"id":28603686},{"atb":[[2.56,7.18]],"id":41064149}],"con":true,"img":false}]}
{"op":"mcm","clk":"5321275151","pt":1646307933826,"mc":[{"id":"1.195532854","rc":[{"atb":[[2.36,8.24]],"id":38833999}],"con":true,"img":false}]}
{"op":"mcm","clk":"5321276405","pt":1646307948021,"mc":[{"id":"1.195532854","rc":[{"atb":[[2.4,8.87]],"id":38833999},{"atb":[[2.56,15.15]],"id":41064149}],"con":true,"img":false}]}
{"op":"mcm","clk":"5321276420","pt":1646307948226,"mc":[{"id":"1.195532854","rc":[{"atb":[[2.8,6.9]],"id":42609833},{"atb":[[2.56,7.96]],"id":36042605}],"con":true,"img":false}]}
{"op":"mcm","clk":"5321276450","pt":1646307948537,"mc":[{"id":"1.195532854","rc":[{"atb":[[2.46,8.5]],"id":28603686},{"atb":[[2.46,8.5]],"id":42190933}],"con":true,"img":false}]}
{"op":"mcm","clk":"5321276882","pt":1646307953770,"mc":[{"id":"1.195532854","rc":[{"atb":[[5.3,0]],"id":42609833},{"atl":[[24,0]],"id":42609833},{"atb":[[2.52,0]],"id":41064149},{"atl":[[4,0]],"id":41064149}],"con":true,"img":false}]}
{"op":"mcm","clk":"5321276893","pt":1646307953819,"mc":[{"id":"1.195532854","rc":[{"atb":[[3.65,2]],"id":42609833},{"atl":[[13.5,0.81]],"id":42609833},{"atb":[[2.76,2]],"id":41064149},{"atl":[[4.8,2]],"id":41064149}],"con":true,"img":false}]}
{"op":"mcm","clk":"5321282948","pt":1646308002563,"mc":[{"id":"1.195532854","marketDefinition":{"bspMarket":true,"turnInPlayEnabled":false,"persistenceEnabled":false,"marketBaseRate":5.0,"eventId":"31275720","eventTypeId":"4339","numberOfWinners":1,"bettingType":"ODDS","marketType":"WIN","marketTime":"2022-03-03T14:12:00.000Z","suspendTime":"2022-03-03T14:12:00.000Z","bspReconciled":false,"complete":true,"inPlay":false,"crossMatching":true,"runnersVoidable":false,"numberOfActiveRunners":6,"betDelay":0,"status":"OPEN","runners":[{"status":"ACTIVE","sortPriority":1,"id":36042605,"name":"1. Droopys Icing"},{"status":"ACTIVE","sortPriority":2,"id":42190933,"name":"2. Patagonia"},{"status":"ACTIVE","sortPriority":3,"id":42609833,"name":"3. Tip Top Saka"},{"status":"ACTIVE","sortPriority":4,"id":41064149,"name":"4. Bang On Esmae"},{"status":"ACTIVE","sortPriority":5,"id":38833999,"name":"5. Adorable Emma"},{"status":"ACTIVE","sortPriority":6,"id":28603686,"name":"6. Trapstyle Flash"}],"regulators":["MR_INT"],"venue":"Romford","countryCode":"GB","discountAllowed":true,"timezone":"Europe/London","openDate":"2022-03-03T13:57:00.000Z","version":4384107284,"name":"A8 400m","eventName":"Romford 3rd Mar"},"rc":[{"atb":[[5.1,2],[1.01,11000],[2.06,8.61],[2.42,7.89],[6,2],[2.46,8.5],[1.14,30]],"id":28603686},{"spl":[[8.6,10],[21,1]],"id":28603686},{"atl":[[10.5,1.06],[500,3],[1000,12.5]],"id":28603686},{"spn":7.3,"spf":1.0,"id":28603686},{"atb":[[2.4,8.87],[2.36,8.24],[1.12,30],[4.3,2],[1.01,11000],[2.32,11.94],[5.7,2]],"id":38833999},{"spl":[[10,10],[21,1]],"id":38833999},{"atl":[[560,3],[8.6,1.33],[1000,12.5]],"id":38833999},{"trd":[[5.1,2]],"ltp":5.1,"tv":2.0,"id":38833999},{"spn":7.15,"spf":1.0,"id":38833999},{"atb":[[2.8,6.9],[1.12,30],[1.01,11000],[2.06,12.06],[6.8,2],[3.65,2],[2.76,6.36]],"id":42609833},{"spl":[[1.01,10],[21,1],[27,10]],"id":42609833},{"atl":[[550,3],[13.5,0.81],[1000,12.5]],"id":42609833},{"spb":[[1000,11.06]],"id":42609833},{"trd":[[10,6]],"ltp":10.0,"tv":6.0,"id":42609833},{"spn":4.26,"spf":2.1,"id":42609833},{"atb":[[1.12,30],[5.1,2],[2.02,10.98],[1.01,11000],[2.42,7.89],[6,2],[2.46,8.5]],"id":42190933},{"spl":[[75,10],[21,1]],"id":42190933},{"atl":[[10.5,1.06],[390,3],[1000,12.5]],"id":42190933},{"spn":8.25,"spf":1.0,"id":42190933},{"atb":[[2.56,15.15],[2.24,10.04],[1.12,30],[1.01,11000],[2.96,2],[2.76,2]],"id":41064149},{"spl":[[6.2,10],[21,1]],"id":41064149},{"atl":[[4.8,2],[270,3],[1000,12.5]],"id":41064149},{"spn":3.88,"spf":1.0,"id":41064149},{"atb":[[2.56,7.96],[1.12,30],[1.01,11000],[6.2,1.93],[2.52,7.37],[7.8,2],[2.1,11.41]],"id":36042605},{"spl":[[21,1],[9.8,10]],"id":36042605},{"atl":[[370,3],[13,0.84],[1000,12.5]],"id":36042605},{"spn":8.8,"spf":1.0,"id":36042605}],"con":true,"img":true}]}
{"op":"mcm","clk":"5321304138","pt":1646308183403,"mc":[{"id":"1.195532854","rc":[{"atb":[[2.42,0]],"id":28603686},{"atb":[[2.36,0]],"id":38833999},{"atb":[[2.76,0]],"id":42609833},{"spn":4.26,"spf":2.1,"id":42609833},{"atb":[[2.42,0]],"id":42190933},{"spn":8.25,"spf":1.0,"id":42190933},{"spn":3.88,"spf":1.0,"id":41064149},{"atb":[[2.52,0]],"id":36042605}],"con":true,"img":false}]}
{"op":"mcm","clk":"5321304745","pt":1646308189813,"mc":[{"id":"1.195532854","rc":[{"atb":[[2.56,7.96]],"id":41064149}],"con":true,"img":false}]}
{"op":"mcm","clk":"5321304757","pt":1646308189918,"mc":[{"id":"1.195532854","rc":[{"atb":[[2.6,7]],"id":36042605}],"con":true,"img":false}]}
{"op":"mcm","clk":"5321304766","pt":1646308190023,"mc":[{"id":"1.195532854","rc":[{"atb":[[3.75,4.07]],"id":42609833},{"atb":[[2.5,7.47]],"id":42190933}],"con":true,"img":false}]}
{"op":"mcm","clk":"5321304784","pt":1646308190127,"mc":[{"id":"1.195532854","rc":[{"atb":[[2.44,7.78]],"id":38833999}],"con":true,"img":false}]}
{"op":"mcm","clk":"5321304806","pt":1646308190334,"mc":[{"id":"1.195532854","rc":[{"atb":[[2.5,7.47]],"id":28603686}],"con":true,"img":false}]}
{"op":"mcm","clk":"5321305207","pt":1646308194699,"mc":[{"id":"1.195532854","rc":[{"atb":[[2.28,8.75]],"id":41064149}],"con":true,"img":false}]}
{"op":"mcm","clk":"5321305366","pt":1646308196514,"mc":[{"id":"1.195532854","rc":[{"atb":[[2.8,0]],"id":42609833},{"atb":[[2.56,0]],"id":41064149}],"con":true,"img":false}]}
{"op":"mcm","clk":"5321306680","pt":1646308211245,"mc":[{"id":"1.195532854","rc":[{"atb":[[3.85,4.35]],"id":42609833}],"con":true,"img":false}]}
{"op":"mcm","clk":"5321306689","pt":1646308211352,"mc":[{"id":"1.195532854","rc":[{"atb":[[2.32,9.41]],"id":41064149}],"con":true,"img":false}]}
{"op":"mcm","clk":"5321320795","pt":1646308368433,"mc":[{"id":"1.195532854","rc":[{"atb":[[3.85,0.1],[6.8,0]],"id":42609833},{"trd":[[3.85,8.49],[6.8,4]],"ltp":3.85,"tv":12.49,"id":42609833},{"spn":3.72,"spf":2.1,"id":42609833}],"con":true,"img":false}]}
{"op":"mcm","clk":"5321323864","pt":1646308401389,"mc":[{"id":"1.195532854","rc":[{"atb":[[2.24,0]],"id":41064149}],"con":true,"img":false}]}
{"op":"mcm","clk":"5321323876","pt":1646308401491,"mc":[{"id":"1.195532854","rc":[{"atb":[[2.34,10.04]],"id":41064149}],"con":true,"img":false}]}
{"op":"mcm","clk":"5321327261","pt":1646308436854,"mc":[{"id":"1.195532854","rc":[{"atb":[[2.46,0]],"id":28603686},{"atb":[[2.4,0]],"id":38833999},{"atb":[[2.46,0]],"id":42190933},{"atb":[[2.56,0]],"id":36042605}],"con":true,"img":false}]}
{"op":"mcm","clk":"5321328317","pt":1646308444085,"mc":[{"id":"1.195532854","rc":[{"atb":[[3.75,0]],"id":42609833},{"atb":[[2.28,0]],"id":41064149}],"con":true,"img":false}]}
{"op":"mcm","clk":"5321328663","pt":1646308447265,"mc":[{"id":"1.195532854","rc":[{"atb":[[2.48,7.57]],"id":42609833},{"atb":[[2.38,8.12]],"id":41064149}],"con":true,"img":false}]}
{"op":"mcm","clk":"5321329159","pt":1646308451997,"mc":[{"id":"1.195532854","rc":[{"atb":[[2.54,8.06]],"id":28603686}],"con":true,"img":false}]}
{"op":"mcm","clk":"5321329169","pt":1646308452056,"mc":[{"id":"1.195532854","rc":[{"atb":[[2.64,7.58]],"id":36042605}],"con":true,"img":false}]}
{"op":"mcm","clk":"5321329188","pt":1646308452269,"mc":[{"id":"1.195532854","rc":[{"atb":[[2.48,8.4]],"id":38833999}],"con":true,"img":false}]}
{"op":"mcm","clk":"5321329200","pt":1646308452366,"mc":[{"id":"1.195532854","rc":[{"atb":[[2.54,8.06]],"id":42190933}],"con":true,"img":false}]}
{"op":"mcm","clk":"5321345868","pt":1646308605598,"mc":[{"id":"1.195532854","rc":[{"atb":[[3.85,0]],"id":42609833},{"spn":3.0,"spf":2.1,"id":42609833}],"con":true,"img":false}]}
{"op":"mcm","clk":"5321347323","pt":1646308623034,"mc":[{"id":"1.195532854","rc":[{"atl":[[5,3.27]],"id":42609833}],"con":true,"img":false}]}
{"op":"mcm","clk":"5321347334","pt":1646308623137,"mc":[{"id":"1.195532854","rc":[{"atl":[[5,1.27]],"id":42609833},{"trd":[[5,3.99]],"ltp":5.0,"tv":3.99,"id":42609833}],"con":true,"img":false}]}
{"op":"mcm","clk":"5321347350","pt":1646308623244,"mc":[{"id":"1.195532854","rc":[{"atb":[[2.74,14.27]],"id":42609833}],"con":true,"img":false}]}
{"op":"mcm","clk":"5321347360","pt":1646308623354,"mc":[{"id":"1.195532854","rc":[{"atb":[[3.7,2]],"id":42609833}],"con":true,"img":false}]}
{"op":"mcm","clk":"5321347630","pt":1646308626154,"mc":[{"id":"1.195532854","rc":[{"atb":[[5.8,2],[5.7,0]],"id":38833999},{"atb":[[8,2],[7.8,0]],"id":36042605},{"atb":[[2.98,2],[2.96,0]],"id":41064149}],"con":true,"img":false}]}
{"op":"mcm","clk":"5321347652","pt":1646308626366,"mc":[{"id":"1.195532854","rc":[{"atl":[[8.6,0]],"id":38833999},{"atb":[[3.65,0]],"id":42609833}],"con":true,"img":false}]}
{"op":"mcm","clk":"5321347674","pt":1646308626573,"mc":[{"id":"1.195532854","rc":[{"atl":[[12,0.92]],"id":38833999},{"atb":[[2.18,2]],"id":42609833}],"con":true,"img":false}]}
{"op":"mcm","clk":"5321348924","pt":1646308641248,"mc":[{"id":"1.195532854","rc":[{"atb":[[2.32,0]],"id":41064149}],"con":true,"img":false}]}
{"op":"mcm","clk":"5321350372","pt":1646308659082,"mc":[{"id":"1.195532854","rc":[{"atb":[[2.42,8.74]],"id":41064149}],"con":true,"img":false}]}
{"op":"mcm","clk":"5321351350","pt":1646308669883,"mc":[{"id":"1.195532854","rc":[{"atb":[[2.5,0]],"id":28603686},{"atb":[[2.44,0]],"id":38833999},{"spn":7.9,"spf":1.0,"id":38833999},{"spn":3.13,"spf":2.1,"id":42609833},{"atb":[[2.5,0]],"id":42190933},{"spn":3.89,"spf":1.0,"id":41064149},{"atb":[[2.6,0]],"id":36042605},{"spn":8.9,"spf":1.0,"id":36042605}],"con":true,"img":false}]}
{"op":"mcm","clk":"5321351620","pt":1646308672630,"mc":[{"id":"1.195532854","rc":[{"atb":[[3.2,5.09]],"id":36042605}],"con":true,"img":false}]}
{"op":"mcm","clk":"5321351629","pt":1646308672736,"mc":[{"id":"1.195532854","rc":[{"atb":[[3,5.6]],"id":28603686},{"atb":[[3.15,5.21]],"id":38833999}],"con":true,"img":false}]}
{"op":"mcm","clk":"5321351638","pt":1646308672792,"mc":[{"id":"1.195532854","rc":[{"atb":[[3,5.6]],"id":42190933}],"con":true,"img":false}]}
{"op":"mcm","clk":"5321359947","pt":1646308767433,"mc":[{"id":"1.195532854","rc":[{"atl":[[5,0]],"id":42609833}],"con":true,"img":false}]}
{"op":"mcm","clk":"5321359981","pt":1646308767746,"mc":[{"id":"1.195532854","rc":[{"atb":[[3.7,0]],"id":42609833},{"atl":[[1000,14.15]],"id":42609833}],"con":true,"img":false}]}
{"op":"mcm","clk":"5321360054","pt":1646308768568,"mc":[{"id":"1.195532854","rc":[{"atl":[[1000,12.51]],"id":42609833}],"con":true,"img":false}]}
{"op":"mcm","clk":"5321360094","pt":1646308768979,"mc":[{"id":"1.195532854","rc":[{"atl":[[1000,12.5]],"id":42609833}],"con":true,"img":false}]}
{"op":"mcm","clk":"5321360105","pt":1646308769032,"mc":[{"id":"1.195532854","rc":[{"atl":[[510,0.01]],"id":42609833}],"con":true,"img":false}]}
{"op":"mcm","clk":"5321361304","pt":1646308782409,"mc":[{"id":"1.195532854","rc":[{"atb":[[2.76,4.24]],"id":42609833}],"con":true,"img":false}]}
{"op":"mcm","clk":"5321362000","pt":1646308789898,"mc":[{"id":"1.195532854","rc":[{"atb":[[2.44,5.18]],"id":38833999},{"atb":[[2.2,6.22]],"id":36042605}],"con":true,"img":false}]}
{"op":"mcm","clk":"5321362009","pt":1646308790005,"mc":[{"id":"1.195532854","rc":[{"atb":[[2.46,5.11]],"id":41064149}],"con":true,"img":false}]}
{"op":"mcm","clk":"5321362047","pt":1646308790418,"mc":[{"id":"1.195532854","rc":[{"atb":[[2.88,3.97]],"id":42609833}],"con":true,"img":false}]}
{"op":"mcm","clk":"5321362823","pt":1646308799218,"mc":[{"id":"1.195532854","rc":[{"atb":[[2.46,9.72]],"id":41064149}],"con":true,"img":false}]}
{"op":"mcm","clk":"5321362923","pt":1646308800454,"mc":[{"id":"1.195532854","rc":[{"atb":[[2.44,12.84]],"id":38833999}],"con":true,"img":false}]}
{"op":"mcm","clk":"5321362943","pt":1646308800625,"mc":[{"id":"1.195532854","rc":[{"atb":[[2.76,0]],"id":42609833}],"con":true,"img":false}]}
{"op":"mcm","clk":"5321362967","pt":1646308800937,"mc":[{"id":"1.195532854","rc":[{"atb":[[2.9,4.24]],"id":42609833}],"con":true,"img":false}]}
{"op":"mcm","clk":"5321365769","pt":1646308830469,"mc":[{"id":"1.195532854","rc":[{"atb":[[2.94,5.11]],"id":42609833},{"spn":2.94,"spf":2.1,"id":42609833}],"con":true,"img":false}]}
{"op":"mcm","clk":"5321365797","pt":1646308830777,"mc":[{"id":"1.195532854","rc":[{"atb":[[2.5,6.61]],"id":41064149}],"con":true,"img":false}]}
{"op":"mcm","clk":"5321366284","pt":1646308835614,"mc":[{"id":"1.195532854","rc":[{"atl":[[13.5,0]],"id":42609833},{"atl":[[4.8,0]],"id":41064149}],"con":true,"img":false}]}
{"op":"mcm","clk":"5321366295","pt":1646308835707,"mc":[{"id":"1.195532854","rc":[{"atl":[[12.5,0.88]],"id":42609833},{"atl":[[4.7,2]],"id":41064149}],"con":true,"img":false}]}
{"op":"mcm","clk":"5321366489","pt":1646308837994,"mc":[{"id":"1.195532854","rc":[{"atb":[[2.46,5.11]],"id":41064149}],"con":true,"img":false}]}
{"op":"mcm","clk":"5321367237","pt":1646308846615,"mc":[{"id":"1.195532854","rc":[{"atb":[[2.9,0]],"id":42609833}],"con":true,"img":false}]}
{"op":"mcm","clk":"5321367261","pt":1646308846956,"mc":[{"id":"1.195532854","rc":[{"atb":[[2.96,4.24]],"id":42609833}],"con":true,"img":false}]}
{"op":"mcm","clk":"5321368132","pt":1646308856523,"mc":[{"id":"1.195532854","rc":[{"atb":[[2.48,0]],"id":42609833},{"atb":[[2.38,0]],"id":41064149}],"con":true,"img":false}]}
{"op":"mcm","clk":"5321368665","pt":1646308863334,"mc":[{"id":"1.195532854","rc":[{"atb":[[2.32,8.48]],"id":42609833}],"con":true,"img":false}]}
{"op":"mcm","clk":"5321368673","pt":1646308863437,"mc":[{"id":"1.195532854","rc":[{"atb":[[2.56,4.31]],"id":41064149}],"con":true,"img":false}]}
{"op":"mcm","clk":"5321368686","pt":1646308863542,"mc":[{"id":"1.195532854","rc":[{"atb":[[2.54,7.27]],"id":41064149}],"con":true,"img":false}]}
{"op":"mcm","clk":"5321369840","pt":1646308877405,"mc":[{"id":"1.195532854","rc":[{"atb":[[3,3.36]],"id":42609833}],"con":true,"img":false}]}
{"op":"mcm","clk":"5321370201","pt":1646308881599,"mc":[{"id":"1.195532854","rc":[{"atb":[[2.96,0]],"id":42609833}],"con":true,"img":false}]}
{"op":"mcm","clk":"5321370218","pt":1646308881807,"mc":[{"id":"1.195532854","rc":[{"atb":[[2.54,0]],"id":28603686},{"atb":[[2.48,0]],"id":38833999},{"atb":[[2.54,0]],"id":42190933},{"atb":[[2.64,0]],"id":36042605}],"con":true,"img":false}]}
{"op":"mcm","clk":"5321370227","pt":1646308881907,"mc":[{"id":"1.195532854","rc":[{"atb":[[3.05,4.24]],"id":42609833}],"con":true,"img":false}]}
{"op":"mcm","clk":"5321370907","pt":1646308889740,"mc":[{"id":"1.195532854","rc":[{"atb":[[3,0]],"id":42609833}],"con":true,"img":false}]}
{"op":"mcm","clk":"5321371429","pt":1646308896310,"mc":[{"id":"1.195532854","rc":[{"spn":3.04,"spf":2.1,"id":42609833},{"atb":[[2.5,0]],"id":41064149},{"spn":3.84,"spf":1.0,"id":41064149}],"con":true,"img":false}]}
{"op":"mcm","clk":"5321371437","pt":1646308896413,"mc":[{"id":"1.195532854","rc":[{"atb":[[3.3,5.4]],"id":36042605}],"con":true,"img":false}]}
{"op":"mcm","clk":"5321371451","pt":1646308896619,"mc":[{"id":"1.195532854","rc":[{"atb":[[3.1,5.91]],"id":28603686}],"con":true,"img":false}]}
{"op":"mcm","clk":"5321371471","pt":1646308896925,"mc":[{"id":"1.195532854","rc":[{"atb":[[3.25,5.52]],"id":38833999}],"con":true,"img":false}]}
{"op":"mcm","clk":"5321371477","pt":1646308897030,"mc":[{"id":"1.195532854","rc":[{"atb":[[3.1,5.91]],"id":42190933}],"con":true,"img":false}]}
{"op":"mcm","clk":"5321372191","pt":1646308904444,"mc":[{"id":"1.195532854","rc":[{"atb":[[2.56,0]],"id":41064149}],"con":true,"img":false}]}
{"op":"mcm","clk":"5321372622","pt":1646308910427,"mc":[{"id":"1.195532854","rc":[{"atb":[[3.1,3.2]],"id":42609833}],"con":true,"img":false}]}
{"op":"mcm","clk":"5321373993","pt":1646308926501,"mc":[{"id":"1.195532854","rc":[{"atb":[[2.46,9.72]],"id":41064149}],"con":true,"img":false}]}
{"op":"mcm","clk":"5321380056","pt":1646309000755,"mc":[{"id":"1.195532854","rc":[{"atb":[[2.06,0]],"id":42609833},{"spn":3.08,"spf":2.1,"id":42609833},{"atb":[[2.1,0]],"id":36042605}],"con":true,"img":false}]}
{"op":"mcm","clk":"5321380065","pt":1646309000855,"mc":[{"id":"1.195532854","rc":[{"atb":[[2.34,12.06]],"id":42609833},{"atb":[[2.22,11.41]],"id":36042605}],"con":true,"img":false}]}
{"op":"mcm","clk":"5321380279","pt":1646309003326,"mc":[{"id":"1.195532854","rc":[{"atb":[[2.2,0]],"id":36042605}],"con":true,"img":false}]}
{"op":"mcm","clk":"5321380286","pt":1646309003429,"mc":[{"id":"1.195532854","rc":[{"atb":[[3,0]],"id":28603686},{"atb":[[3.15,0]],"id":38833999},{"atb":[[3,0]],"id":42190933},{"atb":[[3.2,0]],"id":36042605}],"con":true,"img":false}]}
{"op":"mcm","clk":"5321380389","pt":1646309004930,"mc":[{"id":"1.195532854","rc":[{"atb":[[3.05,0]],"id":42609833}],"con":true,"img":false}]}
{"op":"mcm","clk":"5321380402","pt":1646309005138,"mc":[{"id":"1.195532854","rc":[{"atl":[[510,0]],"id":42609833}],"con":true,"img":false}]}
{"op":"mcm","clk":"5321380435","pt":1646309005554,"mc":[{"id":"1.195532854","rc":[{"atb":[[3.15,4.24]],"id":42609833},{"atl":[[1000,14.15]],"id":42609833}],"con":true,"img":false}]}
{"op":"mcm","clk":"5321380453","pt":1646309005816,"mc":[{"id":"1.195532854","rc":[{"atl":[[1000,12.51]],"id":42609833}],"con":true,"img":false}]}
{"op":"mcm","clk":"5321380492","pt":1646309006337,"mc":[{"id":"1.195532854","rc":[{"atb":[[3.35,4.76]],"id":38833999},{"atb":[[3.4,4.67]],"id":36042605}],"con":true,"img":false}]}
{"op":"mcm","clk":"5321380499","pt":1646309006438,"mc":[{"id":"1.195532854","rc":[{"atb":[[3.2,5.09]],"id":42190933}],"con":true,"img":false}]}
{"op":"mcm","clk":"5321380508","pt":1646309006542,"mc":[{"id":"1.195532854","rc":[{"atb":[[3.2,5.09]],"id":28603686}],"con":true,"img":false}]}
{"op":"mcm","clk":"5321380526","pt":1646309006748,"mc":[{"id":"1.195532854","rc":[{"atl":[[1000,12.5]],"id":42609833}],"con":true,"img":false}]}
{"op":"mcm","clk":"5321380534","pt":1646309006852,"mc":[{"id":"1.195532854","rc":[{"atl":[[540,0.01]],"id":42609833}],"con":true,"img":false}]}
{"op":"mcm","clk":"5321381077","pt":1646309012931,"mc":[{"id":"1.195532854","rc":[{"atb":[[3.1,0]],"id":42609833}],"con":true,"img":false}]}
{"op":"mcm","clk":"5321381589","pt":1646309019248,"mc":[{"id":"1.195532854","rc":[{"atb":[[2.34,5.57]],"id":36042605}],"con":true,"img":false}]}
{"op":"mcm","clk":"5321382192","pt":1646309026099,"mc":[{"id":"1.195532854","rc":[{"atb":[[2.34,13.8]],"id":36042605}],"con":true,"img":false}]}
{"op":"mcm","clk":"5321382201","pt":1646309026152,"mc":[{"id":"1.195532854","rc":[{"atb":[[2.46,7.55]],"id":42609833}],"con":true,"img":false}]}
{"op":"mcm","clk":"5321382782","pt":1646309033091,"mc":[{"id":"1.195532854","rc":[{"atb":[[3.2,3.05]],"id":42609833}],"con":true,"img":false}]}
{"op":"mcm","clk":"5321383615","pt":1646309043502,"mc":[{"id":"1.195532854","rc":[{"atb":[[3.15,0]],"id":42609833}],"con":true,"img":false}]}
{"op":"mcm","clk":"5321383640","pt":1646309043811,"mc":[{"id":"1.195532854","rc":[{"atb":[[2.42,0]],"id":41064149}],"con":true,"img":false}]}
{"op":"mcm","clk":"5321383708","pt":1646309044382,"mc":[{"id":"1.195532854","rc":[{"atb":[[3.25,4.24]],"id":42609833}],"con":true,"img":false}]}
{"op":"mcm","clk":"5321384439","pt":1646309054244,"mc":[{"id":"1.195532854","rc":[{"atb":[[3.2,0]],"id":42609833},{"atb":[[2.46,5.11]],"id":41064149}],"con":true,"img":false}]}
{"op":"mcm","clk":"5321384782","pt":1646309058505,"mc":[{"id":"1.195532854","rc":[{"atb":[[2.58,7.86]],"id":41064149}],"con":true,"img":false}]}
{"op":"mcm","clk":"5321390568","pt":1646309130292,"mc":[{"id":"1.195532854","rc":[{"spn":3.2,"spf":2.1,"id":42609833},{"atb":[[2.54,0]],"id":41064149}],"con":true,"img":false}]}
{"op":"mcm","clk":"5321390996","pt":1646309135286,"mc":[{"id":"1.195532854","rc":[{"atb":[[2.38,8.12]],"id":41064149}],"con":true,"img":false}]}
{"op":"mcm","clk":"5321399650","pt":1646309235225,"mc":[{"id":"1.195532854","rc":[{"atb":[[2.32,0]],"id":42609833}],"con":true,"img":false}]}
{"op":"mcm","clk":"5321400190","pt":1646309242209,"mc":[{"id":"1.195532854","rc":[{"atb":[[2.5,7.47]],"id":42609833}],"con":true,"img":false}]}
{"op":"mcm","clk":"5321400463","pt":1646309245735,"mc":[{"id":"1.195532854","rc":[{"atb":[[3.1,0]],"id":28603686},{"atb":[[3.25,0]],"id":38833999},{"atb":[[3.1,0]],"id":42190933},{"atb":[[3.3,0]],"id":36042605}],"con":true,"img":false}]}
{"op":"mcm","clk":"5321402503","pt":1646309269877,"mc":[{"id":"1.195532854","rc":[{"atb":[[3.3,5.4]],"id":42190933}],"con":true,"img":false}]}
{"op":"mcm","clk":"5321402529","pt":1646309270191,"mc":[{"id":"1.195532854","rc":[{"atb":[[3.3,5.4]],"id":28603686}],"con":true,"img":false}]}
{"op":"mcm","clk":"5321402547","pt":1646309270393,"mc":[{"id":"1.195532854","rc":[{"atb":[[3.5,4.97]],"id":36042605}],"con":true,"img":false}]}
{"op":"mcm","clk":"5321402581","pt":1646309270700,"mc":[{"id":"1.195532854","rc":[{"atb":[[3.45,5.07]],"id":38833999}],"con":true,"img":false}]}
{"op":"mcm","clk":"5321405100","pt":1646309300721,"mc":[{"id":"1.195532854","rc":[{"atb":[[2.22,0]],"id":36042605}],"con":true,"img":false}]}
{"op":"mcm","clk":"5321405111","pt":1646309300819,"mc":[{"id":"1.195532854","rc":[{"atb":[[2.36,11.41]],"id":36042605}],"con":true,"img":false}]}
{"op":"mcm","clk":"5321405410","pt":1646309303861,"mc":[{"id":"1.195532854","rc":[{"atb":[[2.34,8.22]],"id":36042605}],"con":true,"img":false}]}
{"op":"mcm","clk":"5321406557","pt":1646309317753,"mc":[{"id":"1.195532854","rc":[{"atb":[[2.34,0]],"id":36042605}],"con":true,"img":false}]}
{"op":"mcm","clk":"5321415662","pt":1646309441233,"mc":[{"id":"1.195532854","rc":[{"atb":[[2.18,0]],"id":42609833}],"con":true,"img":false}]}
{"op":"mcm","clk":"5321415671","pt":1646309441333,"mc":[{"id":"1.195532854","rc":[{"atb":[[2.68,2]],"id":42609833}],"con":true,"img":false}]}
{"op":"mcm","clk":"5321418273","pt":1646309476912,"mc":[{"id":"1.195532854","rc":[{"atb":[[2.58,0]],"id":41064149}],"con":true,"img":false}]}
{"op":"mcm","clk":"5321418520","pt":1646309480033,"mc":[{"id":"1.195532854","rc":[{"atb":[[3.2,0]],"id":28603686},{"atb":[[3.35,0]],"id":38833999},{"atb":[[3.2,0]],"id":42190933},{"atb":[[3.4,0]],"id":36042605}],"con":true,"img":false}]}
{"op":"mcm","clk":"5321418985","pt":1646309485533,"mc":[{"id":"1.195532854","rc":[{"atb":[[3.4,4.67]],"id":28603686}],"con":true,"img":false}]}
{"op":"mcm","clk":"5321419073","pt":1646309486770,"mc":[{"id":"1.195532854","rc":[{"atb":[[3.6,4.31]],"id":36042605}],"con":true,"img":false}]}
{"op":"mcm","clk":"5321419168","pt":1646309487760,"mc":[{"id":"1.195532854","rc":[{"atb":[[3.55,4.39]],"id":38833999}],"con":true,"img":false}]}
{"op":"mcm","clk":"5321419179","pt":1646309487865,"mc":[{"id":"1.195532854","rc":[{"atb":[[3.4,4.67]],"id":42190933}],"con":true,"img":false}]}
{"op":"mcm","clk":"5321419987","pt":1646309498485,"mc":[{"id":"1.195532854","rc":[{"atb":[[2.5,8.28]],"id":41064149}],"con":true,"img":false}]}
{"op":"mcm","clk":"5321421770","pt":1646309521192,"mc":[{"id":"1.195532854","rc":[{"atl":[[12.5,0]],"id":42609833}],"con":true,"img":false}]}
{"op":"mcm","clk":"5321421782","pt":1646309521403,"mc":[{"id":"1.195532854","rc":[{"atl":[[11,1.01]],"id":42609833}],"con":true,"img":false}]}
{"op":"mcm","clk":"5321422390","pt":1646309529534,"mc":[{"id":"1.195532854","rc":[{"atb":[[1.67,152.24],[1.9,102.22]],"id":42609833},{"atb":[[2.62,64.81]],"id":42190933},{"atb":[[2.62,64.81]],"id":36042605}],"con":true,"img":false}]}
{"op":"mcm","clk":"5321422395","pt":1646309529633,"mc":[{"id":"1.195532854","rc":[{"atb":[[2.62,64.81]],"id":28603686},{"atl":[[34,15.5]],"id":28603686},{"atb":[[2.62,64.81]],"id":38833999},{"atl":[[34,15.5]],"id":42190933},{"atl":[[17,9.5],[34,15.5]],"id":41064149}],"con":true,"img":false}]}
{"op":"mcm","clk":"5321422784","pt":1646309535446,"mc":[{"id":"1.195532854","rc":[{"atb":[[2.44,5.18]],"id":38833999}],"con":true,"img":false}]}
{"op":"mcm","clk":"5321422912","pt":1646309536946,"mc":[{"id":"1.195532854","rc":[{"atb":[[2.44,0]],"id":38833999}],"con":true,"img":false}]}
{"op":"mcm","clk":"5321423513","pt":1646309543425,"mc":[{"id":"1.195532854","rc":[{"atb":[[3.3,1.65]],"id":42609833}],"con":true,"img":false}]}
{"op":"mcm","clk":"5321424566","pt":1646309555647,"mc":[{"id":"1.195532854","rc":[{"atb":[[3.25,0]],"id":42609833}],"con":true,"img":false}]}
{"op":"mcm","clk":"5321424610","pt":1646309556226,"mc":[{"id":"1.195532854","rc":[{"atb":[[3.35,4.24]],"id":42609833}],"con":true,"img":false}]}
{"op":"mcm","clk":"5321426778","pt":1646309585581,"mc":[{"id":"1.195532854","rc":[{"atb":[[3.3,0]],"id":42609833},{"spn":3.27,"spf":2.1,"id":42609833}],"con":true,"img":false}]}
{"op":"mcm","clk":"5321426810","pt":1646309585995,"mc":[{"id":"1.195532854","rc":[{"atb":[[3.4,1.65]],"id":42609833}],"con":true,"img":false}]}
{"op":"mcm","clk":"5321427592","pt":1646309597510,"mc":[{"id":"1.195532854","rc":[{"atb":[[3.35,0]],"id":42609833}],"con":true,"img":false}]}
{"op":"mcm","clk":"5321427615","pt":1646309597821,"mc":[{"id":"1.195532854","rc":[{"atb":[[3.45,4.24]],"id":42609833}],"con":true,"img":false}]}
{"op":"mcm","clk":"5321431795","pt":1646309649886,"mc":[{"id":"1.195532854","rc":[{"atb":[[3.4,0]],"id":42609833},{"spn":3.34,"spf":2.1,"id":42609833}],"con":true,"img":false}]}
{"op":"mcm","clk":"5321431841","pt":1646309650301,"mc":[{"id":"1.195532854","rc":[{"atb":[[3.5,1.65]],"id":42609833}],"con":true,"img":false}]}
{"op":"mcm","clk":"5321433181","pt":1646309661407,"mc":[{"id":"1.195532854","rc":[{"atb":[[3.45,0]],"id":42609833}],"con":true,"img":false}]}
{"op":"mcm","clk":"5321433219","pt":1646309661722,"mc":[{"id":"1.195532854","rc":[{"atb":[[3.55,4.24]],"id":42609833}],"con":true,"img":false}]}
{"op":"mcm","clk":"5321438109","pt":1646309712495,"mc":[{"id":"1.195532854","rc":[{"atb":[[3.5,0]],"id":42609833},{"spn":3.41,"spf":2.1,"id":42609833}],"con":true,"img":false}]}
{"op":"mcm","clk":"5321438145","pt":1646309712862,"mc":[{"id":"1.195532854","rc":[{"atb":[[3.6,1.65]],"id":42609833}],"con":true,"img":false}]}
{"op":"mcm","clk":"5321438580","pt":1646309717384,"mc":[{"id":"1.195532854","rc":[{"atb":[[3.55,0]],"id":42609833}],"con":true,"img":false}]}
{"op":"mcm","clk":"5321438601","pt":1646309717698,"mc":[{"id":"1.195532854","rc":[{"atb":[[3.65,4.24]],"id":42609833}],"con":true,"img":false}]}
{"op":"mcm","clk":"5321440058","pt":1646309731557,"mc":[{"id":"1.195532854","rc":[{"atb":[[2.38,0]],"id":41064149}],"con":true,"img":false}]}
{"op":"mcm","clk":"5321440666","pt":1646309736953,"mc":[{"id":"1.195532854","rc":[{"atb":[[3.3,0]],"id":28603686},{"atb":[[3.45,0]],"id":38833999},{"atb":[[3.3,0]],"id":42190933},{"atb":[[3.5,0]],"id":36042605}],"con":true,"img":false}]}
{"op":"mcm","clk":"5321440690","pt":1646309737161,"mc":[{"id":"1.195532854","rc":[{"atb":[[2.54,7.27]],"id":41064149}],"con":true,"img":false}]}
{"op":"mcm","clk":"5321443063","pt":1646309758074,"mc":[{"id":"1.195532854","rc":[{"atb":[[3.65,4.68]],"id":38833999}],"con":true,"img":false}]}
{"op":"mcm","clk":"5321443072","pt":1646309758181,"mc":[{"id":"1.195532854","rc":[{"atb":[[3.5,4.97]],"id":42190933}],"con":true,"img":false}]}
{"op":"mcm","clk":"5321443110","pt":1646309758590,"mc":[{"id":"1.195532854","rc":[{"atb":[[3.5,4.97]],"id":28603686}],"con":true,"img":false}]}
{"op":"mcm","clk":"5321443141","pt":1646309758899,"mc":[{"id":"1.195532854","rc":[{"atb":[[3.7,4.6]],"id":36042605}],"con":true,"img":false}]}
{"op":"mcm","clk":"5321445013","pt":1646309776413,"mc":[{"id":"1.195532854","rc":[{"atb":[[3.6,0]],"id":42609833},{"spn":3.48,"spf":2.1,"id":42609833}],"con":true,"img":false}]}
{"op":"mcm","clk":"5321445057","pt":1646309776828,"mc":[{"id":"1.195532854","rc":[{"atb":[[3.7,1.65]],"id":42609833}],"con":true,"img":false}]}
{"op":"mcm","clk":"5321445414","pt":1646309780124,"mc":[{"id":"1.195532854","rc":[{"atb":[[2.5,0]],"id":42609833}],"con":true,"img":false}]}
{"op":"mcm","clk":"5321445467","pt":1646309780747,"mc":[{"id":"1.195532854","rc":[{"atb":[[3.65,0]],"id":42609833}],"con":true,"img":false}]}
{"op":"mcm","clk":"5321445493","pt":1646309781012,"mc":[{"id":"1.195532854","rc":[{"atb":[[3.75,4.24]],"id":42609833}],"con":true,"img":false}]}
{"op":"mcm","clk":"5321445907","pt":1646309785430,"mc":[{"id":"1.195532854","rc":[{"atb":[[2.78,6.29]],"id":42609833}],"con":true,"img":false}]}
{"op":"mcm","clk":"5321450649","pt":1646309830422,"mc":[{"id":"1.195532854","rc":[{"atl":[[1000,14.5]],"id":36042605}],"con":true,"img":false}]}
{"op":"mcm","clk":"5321450779","pt":1646309831618,"mc":[{"id":"1.195532854","rc":[{"atl":[[1000,14.7]],"id":36042605}],"con":true,"img":false}]}
{"op":"mcm","clk":"5321450910","pt":1646309832927,"mc":[{"id":"1.195532854","rc":[{"atl":[[1000,14.5]],"id":36042605}],"con":true,"img":false}]}
{"op":"mcm","clk":"5321450921","pt":1646309833031,"mc":[{"id":"1.195532854","rc":[{"atl":[[18,0.2]],"id":36042605}],"con":true,"img":false}]}
{"op":"mcm","clk":"5321451103","pt":1646309834335,"mc":[{"id":"1.195532854","rc":[{"atl":[[1000,14.5]],"id":42190933}],"con":true,"img":false}]}
{"op":"mcm","clk":"5321451259","pt":1646309835642,"mc":[{"id":"1.195532854","rc":[{"atl":[[1000,14.7]],"id":42190933}],"con":true,"img":false}]}
{"op":"mcm","clk":"5321451444","pt":1646309837054,"mc":[{"id":"1.195532854","rc":[{"spn":3.73,"spf":2.1,"id":42609833},{"atl":[[1000,14.5]],"id":42190933}],"con":true,"img":false}]}
{"op":"mcm","clk":"5321451458","pt":1646309837156,"mc":[{"id":"1.195532854","rc":[{"atl":[[13.5,0.2]],"id":42190933}],"con":true,"img":false}]}
{"op":"mcm","clk":"5321451613","pt":1646309838463,"mc":[{"id":"1.195532854","rc":[{"atl":[[1000,14.5]],"id":42609833}],"con":true,"img":false}]}
{"op":"mcm","clk":"5321451735","pt":1646309839762,"mc":[{"id":"1.195532854","rc":[{"atl":[[1000,14.7]],"id":42609833}],"con":true,"img":false}]}
{"op":"mcm","clk":"5321451827","pt":1646309840656,"mc":[{"id":"1.195532854","rc":[{"atb":[[3.7,0]],"id":42609833}],"con":true,"img":false}]}
{"op":"mcm","clk":"5321451872","pt":1646309841073,"mc":[{"id":"1.195532854","rc":[{"atl":[[1000,14.5]],"id":42609833}],"con":true,"img":false}]}
{"op":"mcm","clk":"5321451883","pt":1646309841177,"mc":[{"id":"1.195532854","rc":[{"atb":[[3.8,1.65]],"id":42609833},{"atl":[[13.5,0.2]],"id":42609833}],"con":true,"img":false}]}
{"op":"mcm","clk":"5321451995","pt":1646309844426,"mc":[{"id":"1.195532854","rc":[{"atl":[[1000,14.5]],"id":41064149}],"con":true,"img":false}]}
{"op":"mcm","clk":"5321452098","pt":1646309844534,"mc":[{"id":"1.195532854","rc":[{"atl":[[1000,14.7]],"id":41064149}],"con":true,"img":false}]}
{"op":"mcm","clk":"5321452480","pt":1646309847968,"mc":[{"id":"1.195532854","rc":[{"atl":[[1000,14.5]],"id":41064149}],"con":true,"img":false}]}
{"op":"mcm","clk":"5321452487","pt":1646309848067,"mc":[{"id":"1.195532854","rc":[{"atl":[[7.2,0.2]],"id":41064149}],"con":true,"img":false}]}
{"op":"mcm","clk":"5321452609","pt":1646309849369,"mc":[{"id":"1.195532854","rc":[{"atl":[[1000,14.5]],"id":38833999}],"con":true,"img":false}]}
{"op":"mcm","clk":"5321453266","pt":1646309856665,"mc":[{"id":"1.195532854","rc":[{"atb":[[3.75,0]],"id":42609833}],"con":true,"img":false}]}
{"op":"mcm","clk":"5321453294","pt":1646309856971,"mc":[{"id":"1.195532854","rc":[{"atb":[[3.85,4.24]],"id":42609833}],"con":true,"img":false}]}
{"op":"mcm","clk":"5321454273","pt":1646309866612,"mc":[{"id":"1.195532854","rc":[{"atl":[[1000,14.7]],"id":38833999}],"con":true,"img":false}]}
{"op":"mcm","clk":"5321454378","pt":1646309867906,"mc":[{"id":"1.195532854","rc":[{"atl":[[1000,14.5]],"id":38833999}],"con":true,"img":false}]}
{"op":"mcm","clk":"5321454384","pt":1646309868008,"mc":[{"id":"1.195532854","rc":[{"atl":[[12.5,0.2]],"id":38833999}],"con":true,"img":false}]}
{"op":"mcm","clk":"5321454428","pt":1646309868621,"mc":[{"id":"1.195532854","rc":[{"atl":[[12,2.57]],"id":38833999}],"con":true,"img":false}]}
{"op":"mcm","clk":"5321454478","pt":1646309869300,"mc":[{"id":"1.195532854","rc":[{"atl":[[1000,14.5]],"id":28603686}],"con":true,"img":false}]}
{"op":"mcm","clk":"5321457380","pt":1646309904851,"mc":[{"id":"1.195532854","rc":[{"atb":[[3.8,0]],"id":42609833},{"spn":3.61,"spf":2.1,"id":42609833}],"con":true,"img":false}]}
{"op":"mcm","clk":"5321457416","pt":1646309905465,"mc":[{"id":"1.195532854","rc":[{"atb":[[3.9,1.65]],"id":42609833}],"con":true,"img":false}]}
{"op":"mcm","clk":"5321459661","pt":1646309929588,"mc":[{"id":"1.195532854","rc":[{"atl":[[1000,14.7]],"id":28603686}],"con":true,"img":false}]}
{"op":"mcm","clk":"5321459797","pt":1646309930881,"mc":[{"id":"1.195532854","rc":[{"atl":[[1000,14.5]],"id":28603686}],"con":true,"img":false}]}
{"op":"mcm","clk":"5321459802","pt":1646309930988,"mc":[{"id":"1.195532854","rc":[{"atl":[[13.5,0.2]],"id":28603686}],"con":true,"img":false}]}
{"op":"mcm","clk":"5321463639","pt":1646309972147,"mc":[{"id":"1.195532854","rc":[{"atb":[[3.4,0]],"id":28603686},{"atb":[[3.55,0]],"id":38833999},{"spn":3.83,"spf":2.1,"id":42609833},{"atb":[[3.4,0]],"id":42190933},{"atb":[[3.6,0]],"id":36042605}],"con":true,"img":false}]}
{"op":"mcm","clk":"5321464072","pt":1646309977477,"mc":[{"id":"1.195532854","rc":[{"atb":[[3.8,4]],"id":36042605}],"con":true,"img":false}]}
{"op":"mcm","clk":"5321464079","pt":1646309977578,"mc":[{"id":"1.195532854","rc":[{"atb":[[3.6,4.31]],"id":42190933}],"con":true,"img":false}]}
{"op":"mcm","clk":"5321464114","pt":1646309978045,"mc":[{"id":"1.195532854","rc":[{"atb":[[3.6,4.31]],"id":28603686}],"con":true,"img":false}]}
{"op":"mcm","clk":"5321464124","pt":1646309978149,"mc":[{"id":"1.195532854","rc":[{"atb":[[3.75,4.07]],"id":38833999}],"con":true,"img":false}]}
{"op":"mcm","clk":"5321465476","pt":1646309991385,"mc":[{"id":"1.195532854","rc":[{"atb":[[2.5,0]],"id":41064149}],"con":true,"img":false}]}
{"op":"mcm","clk":"5321466940","pt":1646310006403,"mc":[{"id":"1.195532854","rc":[{"atb":[[2.58,7.86]],"id":41064149}],"con":true,"img":false}]}
{"op":"mcm","clk":"5321482441","pt":1646310152998,"mc":[{"id":"1.195532854","rc":[{"atb":[[1.67,0]],"id":42609833}],"con":true,"img":false}]}
{"op":"mcm","clk":"5321484391","pt":1646310174334,"mc":[{"id":"1.195532854","rc":[{"atb":[[2.68,0]],"id":42609833}],"con":true,"img":false}]}
{"op":"mcm","clk":"5321484418","pt":1646310174539,"mc":[{"id":"1.195532854","rc":[{"atb":[[2.92,2]],"id":42609833}],"con":true,"img":false}]}
{"op":"mcm","clk":"5321485005","pt":1646310180338,"mc":[{"id":"1.195532854","rc":[{"atl":[[34,15.5]],"id":42609833}],"con":true,"img":false}]}
{"op":"mcm","clk":"5321485998","pt":1646310190346,"mc":[{"id":"1.195532854","rc":[{"atl":[[540,0]],"id":42609833}],"con":true,"img":false}]}
{"op":"mcm","clk":"5321486017","pt":1646310190656,"mc":[{"id":"1.195532854","rc":[{"atl":[[1000,16.15]],"id":42609833}],"con":true,"img":false}]}
{"op":"mcm","clk":"5321486038","pt":1646310190960,"mc":[{"id":"1.195532854","rc":[{"atl":[[1000,14.78]],"id":42609833}],"con":true,"img":false}]}
{"op":"mcm","clk":"5321486065","pt":1646310191273,"mc":[{"id":"1.195532854","rc":[{"atl":[[1000,14.5]],"id":42609833}],"con":true,"img":false}]}
{"op":"mcm","clk":"5321486078","pt":1646310191377,"mc":[{"id":"1.195532854","rc":[{"atl":[[32,0.28]],"id":42609833}],"con":true,"img":false}]}
{"op":"mcm","clk":"5321487538","pt":1646310205527,"mc":[{"id":"1.195532854","rc":[{"atb":[[3.5,0]],"id":28603686},{"atb":[[3.65,0]],"id":38833999},{"atb":[[3.5,0]],"id":42190933},{"atb":[[3.7,0]],"id":36042605}],"con":true,"img":false}]}
{"op":"mcm","clk":"5321489475","pt":1646310224253,"mc":[{"id":"1.195532854","rc":[{"atb":[[2.54,0]],"id":41064149}],"con":true,"img":false}]}
{"op":"mcm","clk":"5321490070","pt":1646310230247,"mc":[{"id":"1.195532854","rc":[{"atb":[[3.7,4.6]],"id":42190933}],"con":true,"img":false}]}
{"op":"mcm","clk":"5321490083","pt":1646310230352,"mc":[{"id":"1.195532854","rc":[{"atb":[[3.85,4.35]],"id":38833999},{"atb":[[2.38,8.12]],"id":41064149}],"con":true,"img":false}]}
{"op":"mcm","clk":"5321490127","pt":1646310230823,"mc":[{"id":"1.195532854","rc":[{"atb":[[3.7,4.6]],"id":28603686}],"con":true,"img":false}]}
{"op":"mcm","clk":"5321490153","pt":1646310231037,"mc":[{"id":"1.195532854","rc":[{"atb":[[3.9,4.28]],"id":36042605}],"con":true,"img":false}]}
{"op":"mcm","clk":"5321505133","pt":1646310407359,"mc":[{"id":"1.195532854","rc":[{"atb":[[2.78,0]],"id":42609833}],"con":true,"img":false}]}
{"op":"mcm","clk":"5321507627","pt":1646310438204,"mc":[{"id":"1.195532854","rc":[{"atb":[[3.6,0]],"id":28603686},{"atb":[[3.75,0]],"id":38833999},{"atb":[[3.6,0]],"id":42190933},{"atb":[[3.8,0]],"id":36042605}],"con":true,"img":false}]}
{"op":"mcm","clk":"5321509533","pt":1646310463744,"mc":[{"id":"1.195532854","rc":[{"atb":[[2.58,0]],"id":41064149}],"con":true,"img":false}]}
{"op":"mcm","clk":"5321510822","pt":1646310478679,"mc":[{"id":"1.195532854","rc":[{"atb":[[2.5,8.28]],"id":41064149}],"con":true,"img":false}]}
{"op":"mcm","clk":"5321511902","pt":1646310493640,"mc":[{"id":"1.195532854","rc":[{"atl":[[34,15.5]],"id":38833999}],"con":true,"img":false}]}
{"op":"mcm","clk":"5321521314","pt":1646310610560,"mc":[{"id":"1.195532854","rc":[{"atb":[[2.66,6.75]],"id":38833999}],"con":true,"img":false}]}
{"op":"mcm","clk":"5321521405","pt":1646310611334,"mc":[{"id":"1.195532854","rc":[{"atb":[[2.96,5.71]],"id":42609833}],"con":true,"img":false}]}
{"op":"mcm","clk":"5321521482","pt":1646310611955,"mc":[{"id":"1.195532854","rc":[{"atb":[[3.8,4]],"id":42190933}],"con":true,"img":false}]}
{"op":"mcm","clk":"5321521579","pt":1646310612632,"mc":[{"id":"1.195532854","rc":[{"atb":[[3.8,4]],"id":28603686}],"con":true,"img":false}]}
{"op":"mcm","clk":"5321521602","pt":1646310612844,"mc":[{"id":"1.195532854","rc":[{"atb":[[4,3.73]],"id":36042605}],"con":true,"img":false}]}
{"op":"mcm","clk":"5321522230","pt":1646310619744,"mc":[{"id":"1.195532854","rc":[{"atb":[[2.94,0]],"id":42609833}],"con":true,"img":false}]}
{"op":"mcm","clk":"5321529732","pt":1646310686682,"mc":[{"id":"1.195532854","rc":[{"atb":[[3.7,0]],"id":28603686},{"atb":[[3.85,0]],"id":38833999},{"spn":3.83,"spf":2.1,"id":42609833},{"atb":[[3.7,0]],"id":42190933},{"atb":[[3.9,0]],"id":36042605}],"con":true,"img":false}]}
{"op":"mcm","clk":"5321531925","pt":1646310704793,"mc":[{"id":"1.195532854","rc":[{"atb":[[4.2,3.88]],"id":36042605}],"con":true,"img":false}]}
{"op":"mcm","clk":"5321531961","pt":1646310705098,"mc":[{"id":"1.195532854","rc":[{"atb":[[3.9,4.28]],"id":42190933}],"con":true,"img":false}]}
{"op":"mcm","clk":"5321531971","pt":1646310705203,"mc":[{"id":"1.195532854","rc":[{"atb":[[2.7,7.3]],"id":38833999}],"con":true,"img":false}]}
{"op":"mcm","clk":"5321531995","pt":1646310705416,"mc":[{"id":"1.195532854","rc":[{"atb":[[3.9,4.28]],"id":28603686}],"con":true,"img":false}]}
{"op":"mcm","clk":"5321532600","pt":1646310711296,"mc":[{"id":"1.195532854","rc":[{"atb":[[2.38,0]],"id":41064149}],"con":true,"img":false}]}
{"op":"mcm","clk":"5321532837","pt":1646310713799,"mc":[{"id":"1.195532854","rc":[{"atb":[[2.54,7.27]],"id":41064149}],"con":true,"img":false}]}
{"op":"mcm","clk":"5321541744","pt":1646310802726,"mc":[{"id":"1.195532854","rc":[{"atl":[[22,9.2],[29,15.2]],"id":38833999}],"con":true,"img":false}]}
{"op":"mcm","clk":"5321555159","pt":1646310921493,"mc":[{"id":"1.195532854","rc":[{"atb":[[3.8,0]],"id":28603686},{"atb":[[3.8,0]],"id":42190933},{"atb":[[4,0]],"id":36042605}],"con":true,"img":false}]}
{"op":"mcm","clk":"5321555505","pt":1646310924877,"mc":[{"id":"1.195532854","rc":[{"atb":[[4,3.73]],"id":42190933}],"con":true,"img":false}]}
{"op":"mcm","clk":"5321555556","pt":1646310925499,"mc":[{"id":"1.195532854","rc":[{"atb":[[4,3.73]],"id":28603686},{"atb":[[4.4,3.29]],"id":36042605}],"con":true,"img":false}]}
{"op":"mcm","clk":"5321556837","pt":1646310939107,"mc":[{"id":"1.195532854","rc":[{"atb":[[2.66,0]],"id":38833999}],"con":true,"img":false}]}
{"op":"mcm","clk":"5321557197","pt":1646310943035,"mc":[{"id":"1.195532854","rc":[{"atb":[[2.74,6.44]],"id":38833999}],"con":true,"img":false}]}
{"op":"mcm","clk":"5321558399","pt":1646310955244,"mc":[{"id":"1.195532854","rc":[{"atb":[[2.5,0]],"id":41064149}],"con":true,"img":false}]}
{"op":"mcm","clk":"5321559692","pt":1646310969670,"mc":[{"id":"1.195532854","rc":[{"atb":[[2.58,7.86]],"id":41064149}],"con":true,"img":false}]}
{"op":"mcm","clk":"5321565890","pt":1646311021440,"mc":[{"id":"1.195532854","rc":[{"atl":[[18,0.04],[13,0]],"id":36042605},{"trd":[[18,0.32],[13,1.68]],"ltp":18.0,"tv":2.0,"id":36042605}],"con":true,"img":false}]}
{"op":"mcm","clk":"5321565918","pt":1646311021646,"mc":[{"id":"1.195532854","rc":[{"atb":[[8.2,1.22]],"id":36042605}],"con":true,"img":false}]}
{"op":"mcm","clk":"5321567797","pt":1646311041990,"mc":[{"id":"1.195532854","rc":[{"atb":[[3.85,32.28],[3.15,47.44]],"id":36042605}],"con":true,"img":false}]}
{"op":"mcm","clk":"5321571377","pt":1646311083574,"mc":[{"id":"1.195532854","rc":[{"atl":[[17,0.64]],"id":36042605},{"spn":9.0,"spf":1.0,"id":36042605}],"con":true,"img":false}]}
{"op":"mcm","clk":"5321578913","pt":1646311164630,"mc":[{"id":"1.195532854","rc":[{"atb":[[3.9,0]],"id":28603686},{"atb":[[3.9,0]],"id":42190933},{"atb":[[4.2,0]],"id":36042605}],"con":true,"img":false}]}
{"op":"mcm","clk":"5321581191","pt":1646311182671,"mc":[{"id":"1.195532854","rc":[{"atb":[[2.66,7.48]],"id":42190933},{"atb":[[4.6,3.45]],"id":36042605}],"con":true,"img":false}]}
{"op":"mcm","clk":"5321581251","pt":1646311183196,"mc":[{"id":"1.195532854","rc":[{"atb":[[2.66,7.48]],"id":28603686}],"con":true,"img":false}]}
{"op":"mcm","clk":"5321582016","pt":1646311189509,"mc":[{"id":"1.195532854","rc":[{"atb":[[2.54,0]],"id":41064149}],"con":true,"img":false}]}
{"op":"mcm","clk":"5321582490","pt":1646311192102,"mc":[{"id":"1.195532854","rc":[{"atb":[[2.38,8.12]],"id":41064149}],"con":true,"img":false}]}
{"op":"mcm","clk":"5321583323","pt":1646311198698,"mc":[{"id":"1.195532854","rc":[{"atb":[[2.7,0]],"id":38833999}],"con":true,"img":false}]}
{"op":"mcm","clk":"5321584058","pt":1646311209952,"mc":[{"id":"1.195532854","rc":[{"atb":[[2.78,6.98]],"id":38833999}],"con":true,"img":false}]}
{"op":"mcm","clk":"5321600306","pt":1646311400905,"mc":[{"id":"1.195532854","rc":[{"atb":[[4,0]],"id":28603686},{"atb":[[4,0]],"id":42190933},{"atb":[[4.4,0]],"id":36042605}],"con":true,"img":false}]}
{"op":"mcm","clk":"5321600685","pt":1646311405714,"mc":[{"id":"1.195532854","rc":[{"atb":[[2.7,6.59]],"id":28603686},{"atb":[[2.7,6.59]],"id":42190933}],"con":true,"img":false}]}
{"op":"mcm","clk":"5321600697","pt":1646311405818,"mc":[{"id":"1.195532854","rc":[{"atb":[[4.8,2.95]],"id":36042605}],"con":true,"img":false}]}
{"op":"mcm","clk":"5321602860","pt":1646311432477,"mc":[{"id":"1.195532854","rc":[{"atb":[[2.74,0]],"id":38833999}],"con":true,"img":false}]}
{"op":"mcm","clk":"5321603147","pt":1646311435953,"mc":[{"id":"1.195532854","rc":[{"atb":[[2.82,6.15]],"id":38833999}],"con":true,"img":false}]}
{"op":"mcm","clk":"5321603189","pt":1646311436467,"mc":[{"id":"1.195532854","rc":[{"atb":[[2.58,0]],"id":41064149}],"con":true,"img":false}]}
{"op":"mcm","clk":"5321604437","pt":1646311451200,"mc":[{"id":"1.195532854","rc":[{"atb":[[2.5,8.28]],"id":41064149}],"con":true,"img":false}]}
{"op":"mcm","clk":"5321622453","pt":1646311637459,"mc":[{"id":"1.195532854","rc":[{"atb":[[4.6,0]],"id":36042605}],"con":true,"img":false}]}
{"op":"mcm","clk":"5321623918","pt":1646311651666,"mc":[{"id":"1.195532854","rc":[{"atb":[[2.66,0]],"id":28603686},{"atb":[[2.66,0]],"id":42190933}],"con":true,"img":false}]}
{"op":"mcm","clk":"5321627304","pt":1646311685512,"mc":[{"id":"1.195532854","rc":[{"atb":[[2.38,0]],"id":41064149}],"con":true,"img":false}]}
{"op":"mcm","clk":"5321627571","pt":1646311688312,"mc":[{"id":"1.195532854","rc":[{"atb":[[2.54,7.27]],"id":41064149}],"con":true,"img":false}]}
{"op":"mcm","clk":"5321634551","pt":1646311761326,"mc":[{"id":"1.195532854","rc":[{"atl":[[34,25.5]],"id":42609833}],"con":true,"img":false}]}
{"op":"mcm","clk":"5321638750","pt":1646311805865,"mc":[{"id":"1.195532854","rc":[{"atb":[[2.78,0]],"id":38833999}],"con":true,"img":false}]}
{"op":"mcm","clk":"5321638785","pt":1646311806177,"mc":[{"id":"1.195532854","rc":[{"atb":[[2.74,7.14]],"id":28603686}],"con":true,"img":false}]}
{"op":"mcm","clk":"5321638931","pt":1646311807678,"mc":[{"id":"1.195532854","rc":[{"atb":[[2.74,7.14]],"id":42190933}],"con":true,"img":false}]}
{"op":"mcm","clk":"5321644003","pt":1646311839328,"mc":[{"id":"1.195532854","rc":[{"atb":[[2.86,6.67]],"id":38833999}],"con":true,"img":false}]}
{"op":"mcm","clk":"5321648349","pt":1646311875189,"mc":[{"id":"1.195532854","rc":[{"atb":[[4.8,0]],"id":36042605}],"con":true,"img":false}]}
{"op":"mcm","clk":"5321648578","pt":1646311877568,"mc":[{"id":"1.195532854","rc":[{"atb":[[3.95,4.2]],"id":36042605}],"con":true,"img":false}]}
{"op":"mcm","clk":"5321648984","pt":1646311881277,"mc":[{"id":"1.195532854","rc":[{"atb":[[4.1,3.61]],"id":36042605}],"con":true,"img":false}]}
{"op":"mcm","clk":"5321649962","pt":1646311887902,"mc":[{"id":"1.195532854","rc":[{"atb":[[2.7,0]],"id":28603686},{"atb":[[2.7,0]],"id":42190933}],"con":true,"img":false}]}
{"op":"mcm","clk":"5321650463","pt":1646311892516,"mc":[{"id":"1.195532854","rc":[{"atb":[[2.78,6.29]],"id":28603686}],"con":true,"img":false}]}
{"op":"mcm","clk":"5321650479","pt":1646311892721,"mc":[{"id":"1.195532854","rc":[{"atb":[[2.78,6.29]],"id":42190933}],"con":true,"img":false}]}
{"op":"mcm","clk":"5321667759","pt":1646312040460,"mc":[{"id":"1.195532854","rc":[{"atb":[[2.82,0]],"id":38833999}],"con":true,"img":false}]}
{"op":"mcm","clk":"5321668001","pt":1646312042870,"mc":[{"id":"1.195532854","rc":[{"atb":[[2.9,5.89]],"id":38833999}],"con":true,"img":false}]}
{"op":"mcm","clk":"5321668735","pt":1646312048779,"mc":[{"id":"1.195532854","rc":[{"atb":[[2.5,0]],"id":41064149}],"con":true,"img":false}]}
{"op":"mcm","clk":"5321670499","pt":1646312064511,"mc":[{"id":"1.195532854","rc":[{"atb":[[2.58,7.86]],"id":41064149}],"con":true,"img":false}]}
{"op":"mcm","clk":"5321677603","pt":1646312139947,"mc":[{"id":"1.195532854","rc":[{"atb":[[2.74,0]],"id":28603686},{"atb":[[2.74,0]],"id":42190933},{"atb":[[3.95,0]],"id":36042605}],"con":true,"img":false}]}
{"op":"mcm","clk":"5321678990","pt":1646312156866,"mc":[{"id":"1.195532854","rc":[{"atb":[[4.3,3.76]],"id":36042605}],"con":true,"img":false}]}
{"op":"mcm","clk":"5321679032","pt":1646312157281,"mc":[{"id":"1.195532854","rc":[{"atb":[[2.82,6.82]],"id":28603686}],"con":true,"img":false}]}
{"op":"mcm","clk":"5321679062","pt":1646312157593,"mc":[{"id":"1.195532854","rc":[{"atb":[[2.82,6.82]],"id":42190933}],"con":true,"img":false}]}
{"op":"mcm","clk":"5321689806","pt":1646312284299,"mc":[{"id":"1.195532854","rc":[{"atb":[[2.54,0]],"id":41064149}],"con":true,"img":false}]}
{"op":"mcm","clk":"5321690192","pt":1646312289347,"mc":[{"id":"1.195532854","rc":[{"atb":[[2.38,8.12]],"id":41064149}],"con":true,"img":false}]}
{"op":"mcm","clk":"5321690411","pt":1646312291708,"mc":[{"id":"1.195532854","rc":[{"atb":[[2.86,0]],"id":38833999}],"con":true,"img":false}]}
{"op":"mcm","clk":"5321691479","pt":1646312305222,"mc":[{"id":"1.195532854","rc":[{"atb":[[2.94,6.4]],"id":38833999}],"con":true,"img":false}]}
{"op":"mcm","clk":"5321697447","pt":1646312373589,"mc":[{"id":"1.195532854","rc":[{"atb":[[2.78,0]],"id":28603686},{"atb":[[2.78,0]],"id":42190933},{"atb":[[4.1,0]],"id":36042605}],"con":true,"img":false}]}
{"op":"mcm","clk":"5321700449","pt":1646312402469,"mc":[{"id":"1.195532854","rc":[{"atb":[[4.5,3.2]],"id":36042605}],"con":true,"img":false}]}
{"op":"mcm","clk":"5321700496","pt":1646312402731,"mc":[{"id":"1.195532854","rc":[{"atb":[[2.86,6.02]],"id":42190933}],"con":true,"img":false}]}
{"op":"mcm","clk":"5321700544","pt":1646312403157,"mc":[{"id":"1.195532854","rc":[{"atb":[[2.86,6.02]],"id":28603686}],"con":true,"img":false}]}
{"op":"mcm","clk":"5321711937","pt":1646312526742,"mc":[{"id":"1.195532854","rc":[{"atb":[[2.82,6.82],[2.86,6.02],[2.06,8.61]],"id":28603686},{"atb":[[2.9,0],[2.32,11.93],[2.94,6.4]],"id":38833999},{"atl":[[12,2.57]],"id":38833999},{"atb":[[3.85,4.24],[2.88,3.97],[2.74,14.26],[2.46,7.55],[3.9,1.65],[2.96,5.71],[2.34,12.05]],"id":42609833},{"atl":[[32,0.28]],"id":42609833},{"trd":[[5,3.99],[3.85,8.49]],"ltp":5.0,"tv":12.48,"id":42609833},{"spn":3.83,"spf":2.1,"id":42609833},{"atb":[[2.82,6.82],[2.02,10.97],[2.86,6.02]],"id":42190933},{"atb":[[2.36,11.4],[4.5,3.2],[4.3,3.76]],"id":36042605},{"atb":[[2.38,8.12],[2.46,5.12],[2.58,7.85],[2.34,10.03]],"id":41064149}],"con":true,"img":false}]}
{"op":"mcm","clk":"5321711975","pt":1646312527157,"mc":[{"id":"1.195532854","rc":[{"atb":[[2.58,0]],"id":41064149}],"con":true,"img":false}]}
{"op":"mcm","clk":"5321712293","pt":1646312530269,"mc":[{"id":"1.195532854","rc":[{"atb":[[2.98,5.66]],"id":38833999}],"con":true,"img":false}]}
{"op":"mcm","clk":"5321712943","pt":1646312536852,"mc":[{"id":"1.195532854","rc":[{"atb":[[1.87,117.24]],"id":42609833}],"con":true,"img":false}]}
{"op":"mcm","clk":"5321713552","pt":1646312543063,"mc":[{"id":"1.195532854","rc":[{"atb":[[2.5,8.27]],"id":41064149}],"con":true,"img":false}]}
{"op":"mcm","clk":"5321719878","pt":1646312614853,"mc":[{"id":"1.195532854","rc":[{"atb":[[2.82,0]],"id":28603686},{"atb":[[2.82,0]],"id":42190933},{"atb":[[4.3,0]],"id":36042605}],"con":true,"img":false}]}
{"op":"mcm","clk":"5321721595","pt":1646312633361,"mc":[{"id":"1.195532854","rc":[{"atb":[[2.9,6.53]],"id":42190933}],"con":true,"img":false}]}
{"op":"mcm","clk":"5321721659","pt":1646312633886,"mc":[{"id":"1.195532854","rc":[{"atb":[[4.7,3.35]],"id":36042605}],"con":true,"img":false}]}
{"op":"mcm","clk":"5321721703","pt":1646312634300,"mc":[{"id":"1.195532854","rc":[{"atb":[[2.9,6.53]],"id":28603686}],"con":true,"img":false}]}
{"op":"mcm","clk":"5321736926","pt":1646312777317,"mc":[{"id":"1.195532854","rc":[{"atb":[[2.38,0]],"id":41064149}],"con":true,"img":false}]}
{"op":"mcm","clk":"5321737149","pt":1646312779512,"mc":[{"id":"1.195532854","rc":[{"atb":[[2.94,0]],"id":38833999}],"con":true,"img":false}]}
{"op":"mcm","clk":"5321737450","pt":1646312782541,"mc":[{"id":"1.195532854","rc":[{"atb":[[2.54,7.28]],"id":41064149}],"con":true,"img":false}]}
{"op":"mcm","clk":"5321738806","pt":1646312795342,"mc":[{"id":"1.195532854","rc":[{"atb":[[3.05,6.06]],"id":38833999}],"con":true,"img":false}]}
{"op":"mcm","clk":"5321745105","pt":1646312848738,"mc":[{"id":"1.195532854","rc":[{"atb":[[2.86,0]],"id":28603686},{"atb":[[2.86,0]],"id":42190933},{"atb":[[4.5,0]],"id":36042605}],"con":true,"img":false}]}
{"op":"mcm","clk":"5321745474","pt":1646312851748,"mc":[{"id":"1.195532854","rc":[{"atb":[[2.94,5.77]],"id":28603686},{"atb":[[2.94,5.77]],"id":42190933}],"con":true,"img":false}]}
{"op":"mcm","clk":"5321765697","pt":1646313017851,"mc":[{"id":"1.195532854","rc":[{"atb":[[2.98,0]],"id":38833999}],"con":true,"img":false}]}
{"op":"mcm","clk":"5321766392","pt":1646313024082,"mc":[{"id":"1.195532854","rc":[{"atb":[[3.15,5.21]],"id":38833999}],"con":true,"img":false}]}
{"op":"mcm","clk":"5321767937","pt":1646313036568,"mc":[{"id":"1.195532854","rc":[{"atb":[[2.5,0]],"id":41064149}],"con":true,"img":false}]}
{"op":"mcm","clk":"5321769526","pt":1646313050712,"mc":[{"id":"1.195532854","rc":[{"atb":[[2.58,7.85]],"id":41064149}],"con":true,"img":false}]}
{"op":"mcm","clk":"5321773238","pt":1646313083927,"mc":[{"id":"1.195532854","rc":[{"atb":[[2.9,0]],"id":28603686},{"atb":[[2.9,0]],"id":42190933},{"atb":[[4.7,0]],"id":36042605}],"con":true,"img":false}]}
{"op":"mcm","clk":"5321773452","pt":1646313086426,"mc":[{"id":"1.195532854","rc":[{"atb":[[3.95,3.79]],"id":36042605}],"con":true,"img":false}]}
{"op":"mcm","clk":"5321774773","pt":1646313099965,"mc":[{"id":"1.195532854","rc":[{"atb":[[2.98,6.27]],"id":28603686}],"con":true,"img":false}]}
{"op":"mcm","clk":"5321774808","pt":1646313100284,"mc":[{"id":"1.195532854","rc":[{"atb":[[4.1,4]],"id":36042605}],"con":true,"img":false}]}
{"op":"mcm","clk":"5321774821","pt":1646313100386,"mc":[{"id":"1.195532854","rc":[{"atb":[[2.98,6.27]],"id":42190933}],"con":true,"img":false}]}
{"op":"mcm","clk":"5321792482","pt":1646313255044,"mc":[{"id":"1.195532854","rc":[{"atb":[[3.05,0]],"id":38833999}],"con":true,"img":false}]}
{"op":"mcm","clk":"5321794025","pt":1646313269943,"mc":[{"id":"1.195532854","rc":[{"atb":[[2.54,0]],"id":41064149}],"con":true,"img":false}]}
{"op":"mcm","clk":"5321794156","pt":1646313271030,"mc":[{"id":"1.195532854","rc":[{"atb":[[3.25,5.52]],"id":38833999}],"con":true,"img":false}]}
{"op":"mcm","clk":"5321794316","pt":1646313273049,"mc":[{"id":"1.195532854","rc":[{"atb":[[2.38,8.12]],"id":41064149}],"con":true,"img":false}]}
{"op":"mcm","clk":"5321796625","pt":1646313297989,"mc":[{"id":"1.195532854","rc":[{"atl":[[1000,16.74]],"id":42609833}],"con":true,"img":false}]}
{"op":"mcm","clk":"5321796647","pt":1646313298197,"mc":[{"id":"1.195532854","rc":[{"atl":[[1000,14.85]],"id":42609833}],"con":true,"img":false}]}
{"op":"mcm","clk":"5321796663","pt":1646313298355,"mc":[{"id":"1.195532854","rc":[{"atl":[[1000,14.5]],"id":42609833}],"con":true,"img":false}]}
{"op":"mcm","clk":"5321796675","pt":1646313298459,"mc":[{"id":"1.195532854","rc":[{"atl":[[10.5,0.35]],"id":42609833}],"con":true,"img":false}]}
{"op":"mcm","clk":"5321798868","pt":1646313321222,"mc":[{"id":"1.195532854","rc":[{"atb":[[2.94,0]],"id":28603686},{"atb":[[2.94,0]],"id":42190933}],"con":true,"img":false}]}
{"op":"mcm","clk":"5321799175","pt":1646313324331,"mc":[{"id":"1.195532854","rc":[{"atb":[[3.05,5.47]],"id":42190933}],"con":true,"img":false}]}
{"op":"mcm","clk":"5321799187","pt":1646313324440,"mc":[{"id":"1.195532854","rc":[{"atb":[[3.05,5.47]],"id":28603686}],"con":true,"img":false}]}
{"op":"mcm","clk":"5321799990","pt":1646313332833,"mc":[{"id":"1.195532854","rc":[{"atb":[[3.95,0]],"id":36042605}],"con":true,"img":false}]}
{"op":"mcm","clk":"5321800250","pt":1646313335949,"mc":[{"id":"1.195532854","rc":[{"atb":[[4.3,3.4]],"id":36042605}],"con":true,"img":false}]}
{"op":"mcm","clk":"5321823750","pt":1646313489512,"mc":[{"id":"1.195532854","rc":[{"atb":[[3.15,0]],"id":38833999}],"con":true,"img":false}]}
{"op":"mcm","clk":"5321824029","pt":1646313492311,"mc":[{"id":"1.195532854","rc":[{"atb":[[3.35,4.76]],"id":38833999}],"con":true,"img":false}]}
{"op":"mcm","clk":"5321826652","pt":1646313520791,"mc":[{"id":"1.195532854","rc":[{"atb":[[2.58,0]],"id":41064149}],"con":true,"img":false}]}
{"op":"mcm","clk":"5321828303","pt":1646313539096,"mc":[{"id":"1.195532854","rc":[{"atb":[[2.5,8.27]],"id":41064149}],"con":true,"img":false}]}
{"op":"mcm","clk":"5321831741","pt":1646313572048,"mc":[{"id":"1.195532854","rc":[{"atb":[[2.98,0]],"id":28603686},{"atb":[[2.98,0]],"id":42190933}],"con":true,"img":false}]}
{"op":"mcm","clk":"5321833250","pt":1646313586156,"mc":[{"id":"1.195532854","rc":[{"atb":[[4.1,0]],"id":36042605}],"con":true,"img":false}]}
{"op":"mcm","clk":"5321833279","pt":1646313586468,"mc":[{"id":"1.195532854","rc":[{"atb":[[3.15,5.77]],"id":42190933}],"con":true,"img":false}]}
{"op":"mcm","clk":"5321833316","pt":1646313586780,"mc":[{"id":"1.195532854","rc":[{"atb":[[3.15,5.77]],"id":28603686}],"con":true,"img":false}]}
{"op":"mcm","clk":"5321834853","pt":1646313600798,"mc":[{"id":"1.195532854","rc":[{"atb":[[4.5,3.55]],"id":36042605}],"con":true,"img":false}]}
{"op":"mcm","clk":"5321842883","pt":1646313672831,"mc":[{"id":"1.195532854","rc":[{"atl":[[1000,14.8]],"id":41064149}],"con":true,"img":false}]}
{"op":"mcm","clk":"5321842908","pt":1646313673029,"mc":[{"id":"1.195532854","rc":[{"atl":[[1000,14.5]],"id":41064149}],"con":true,"img":false}]}
{"op":"mcm","clk":"5321842918","pt":1646313673141,"mc":[{"id":"1.195532854","rc":[{"atb":[[2.98,1.7]],"id":41064149},{"trd":[[2.98,0.6]],"ltp":2.98,"tv":0.6,"id":41064149}],"con":true,"img":false}]}
{"op":"mcm","clk":"5321842934","pt":1646313673345,"mc":[{"id":"1.195532854","rc":[{"atb":[[1.01,11002.24]],"id":38833999},{"atb":[[1.02,2.24]],"id":36042605}],"con":true,"img":false}]}
{"op":"mcm","clk":"5321842953","pt":1646313673555,"mc":[{"id":"1.195532854","rc":[{"atb":[[1.01,11000.63]],"id":38833999},{"atb":[[1.02,0.44]],"id":36042605}],"con":true,"img":false}]}
{"op":"mcm","clk":"5321842963","pt":1646313673652,"mc":[{"id":"1.195532854","rc":[{"atb":[[1.02,0]],"id":36042605}],"con":true,"img":false}]}
{"op":"mcm","clk":"5321842979","pt":1646313673758,"mc":[{"id":"1.195532854","rc":[{"atb":[[8.4,0.44]],"id":36042605}],"con":true,"img":false}]}
{"op":"mcm","clk":"5321843002","pt":1646313673926,"mc":[{"id":"1.195532854","rc":[{"atb":[[1.01,11000]],"id":38833999}],"con":true,"img":false}]}
{"op":"mcm","clk":"5321843016","pt":1646313674029,"mc":[{"id":"1.195532854","rc":[{"atb":[[5.9,0.63]],"id":38833999}],"con":true,"img":false}]}
{"op":"mcm","clk":"5321843217","pt":1646313676256,"mc":[{"id":"1.195532854","rc":[{"atb":[[2.98,2]],"id":41064149}],"con":true,"img":false}]}
{"op":"mcm","clk":"5321844544","pt":1646313689654,"mc":[{"id":"1.195532854","rc":[{"atb":[[2.92,47.92],[2.44,70.83]],"id":38833999}],"con":true,"img":false}]}
{"op":"mcm","clk":"5321850314","pt":1646313746131,"mc":[{"id":"1.195532854","rc":[{"atb":[[3.25,0]],"id":38833999},{"spn":7.95,"spf":1.0,"id":38833999},{"spn":9.1,"spf":1.0,"id":36042605}],"con":true,"img":false}]}
{"op":"mcm","clk":"5321852381","pt":1646313766705,"mc":[{"id":"1.195532854","rc":[{"atb":[[3.45,5.06]],"id":38833999}],"con":true,"img":false}]}
{"op":"mcm","clk":"5321852859","pt":1646313772182,"mc":[{"id":"1.195532854","rc":[{"atb":[[2.38,0]],"id":41064149}],"con":true,"img":false}]}
{"op":"mcm","clk":"5321853235","pt":1646313775705,"mc":[{"id":"1.195532854","rc":[{"atb":[[2.54,7.28]],"id":41064149}],"con":true,"img":false}]}
{"op":"mcm","clk":"5321856021","pt":1646313804917,"mc":[{"id":"1.195532854","rc":[{"atb":[[3.05,0]],"id":28603686},{"atb":[[3.05,0]],"id":42190933}],"con":true,"img":false}]}
{"op":"mcm","clk":"5321856379","pt":1646313808043,"mc":[{"id":"1.195532854","rc":[{"atb":[[3.25,4.98]],"id":42190933}],"con":true,"img":false}]}
{"op":"mcm","clk":"5321856390","pt":1646313808145,"mc":[{"id":"1.195532854","rc":[{"atb":[[3.25,4.98]],"id":28603686}],"con":true,"img":false}]}
{"op":"mcm","clk":"5321858103","pt":1646313823075,"mc":[{"id":"1.195532854","rc":[{"atb":[[4.3,0]],"id":36042605}],"con":true,"img":false}]}
{"op":"mcm","clk":"5321858494","pt":1646313825952,"mc":[{"id":"1.195532854","rc":[{"atb":[[4.7,3.02]],"id":36042605}],"con":true,"img":false}]}
{"op":"mcm","clk":"5321872207","pt":1646313983422,"mc":[{"id":"1.195532854","rc":[{"atb":[[3.35,0]],"id":38833999}],"con":true,"img":false}]}
{"op":"mcm","clk":"5321872597","pt":1646313988716,"mc":[{"id":"1.195532854","rc":[{"atb":[[3.55,4.39]],"id":38833999}],"con":true,"img":false}]}
{"op":"mcm","clk":"5321874834","pt":1646314017940,"mc":[{"id":"1.195532854","rc":[{"atb":[[2.5,0]],"id":41064149}],"con":true,"img":false}]}
{"op":"mcm","clk":"5321876534","pt":1646314039183,"mc":[{"id":"1.195532854","rc":[{"atb":[[2.58,7.85]],"id":41064149}],"con":true,"img":false}]}
{"op":"mcm","clk":"5321878224","pt":1646314061114,"mc":[{"id":"1.195532854","rc":[{"atb":[[3.15,0]],"id":28603686},{"atb":[[3.15,0]],"id":42190933},{"atb":[[4.5,0]],"id":36042605}],"con":true,"img":false}]}
{"op":"mcm","clk":"5321879913","pt":1646314080742,"mc":[{"id":"1.195532854","rc":[{"atb":[[3.35,5.28]],"id":42190933}],"con":true,"img":false}]}
{"op":"mcm","clk":"5321879939","pt":1646314081006,"mc":[{"id":"1.195532854","rc":[{"atb":[[3.35,5.28]],"id":28603686}],"con":true,"img":false}]}
{"op":"mcm","clk":"5321891703","pt":1646314222431,"mc":[{"id":"1.195532854","rc":[{"atl":[[10.5,0]],"id":28603686},{"atl":[[10.5,0]],"id":42190933},{"spn":9.75,"spf":1.0,"id":42190933}],"con":true,"img":false}]}
{"op":"mcm","clk":"5321891714","pt":1646314222536,"mc":[{"id":"1.195532854","rc":[{"atl":[[9.8,1.15]],"id":28603686},{"atl":[[9.8,1.15]],"id":42190933}],"con":true,"img":false}]}
{"op":"mcm","clk":"5321892654","pt":1646314232669,"mc":[{"id":"1.195532854","rc":[{"atb":[[3.45,0]],"id":38833999}],"con":true,"img":false}]}
{"op":"mcm","clk":"5321893977","pt":1646314247300,"mc":[{"id":"1.195532854","rc":[{"atb":[[3.65,4.68]],"id":38833999}],"con":true,"img":false}]}
{"op":"mcm","clk":"5321894299","pt":1646314250879,"mc":[{"id":"1.195532854","rc":[{"atb":[[2.54,0]],"id":41064149}],"con":true,"img":false}]}
{"op":"mcm","clk":"5321894547","pt":1646314253714,"mc":[{"id":"1.195532854","rc":[{"atb":[[2.38,8.12]],"id":41064149}],"con":true,"img":false}]}
{"op":"mcm","clk":"5321897643","pt":1646314295889,"mc":[{"id":"1.195532854","rc":[{"atb":[[3.25,0]],"id":28603686},{"atb":[[3.25,0]],"id":42190933},{"spn":7.9,"spf":1.0,"id":42190933},{"atb":[[4.7,0]],"id":36042605}],"con":true,"img":false}]}
{"op":"mcm","clk":"5321897823","pt":1646314298574,"mc":[{"id":"1.195532854","rc":[{"atb":[[3.95,3.79]],"id":36042605}],"con":true,"img":false}]}
{"op":"mcm","clk":"5321897832","pt":1646314298677,"mc":[{"id":"1.195532854","rc":[{"atb":[[3.45,4.57]],"id":28603686},{"atb":[[3.45,4.57]],"id":42190933}],"con":true,"img":false}]}
{"op":"mcm","clk":"5321907228","pt":1646314412584,"mc":[{"id":"1.195532854","rc":[{"atb":[[4.1,4]],"id":36042605}],"con":true,"img":false}]}
{"op":"mcm","clk":"5321912012","pt":1646314467950,"mc":[{"id":"1.195532854","rc":[{"atb":[[3.55,0]],"id":38833999}],"con":true,"img":false}]}
{"op":"mcm","clk":"5321912256","pt":1646314471167,"mc":[{"id":"1.195532854","rc":[{"atb":[[3.75,4.07]],"id":38833999}],"con":true,"img":false}]}
{"op":"mcm","clk":"5321931061","pt":1646314647348,"mc":[{"id":"1.195532854","rc":[{"atb":[[3.95,0]],"id":36042605}],"con":true,"img":false}]}
{"op":"mcm","clk":"5321931554","pt":1646314651929,"mc":[{"id":"1.195532854","rc":[{"atb":[[4.3,3.4]],"id":36042605}],"con":true,"img":false}]}
{"op":"mcm","clk":"5321932602","pt":1646314661563,"mc":[{"id":"1.195532854","rc":[{"atb":[[3.35,0]],"id":28603686},{"atb":[[3.35,0]],"id":42190933},{"atb":[[2.58,0]],"id":41064149}],"con":true,"img":false}]}
{"op":"mcm","clk":"5321934328","pt":1646314676253,"mc":[{"id":"1.195532854","rc":[{"atb":[[3.55,4.86]],"id":42190933}],"con":true,"img":false}]}
{"op":"mcm","clk":"5321934388","pt":1646314676670,"mc":[{"id":"1.195532854","rc":[{"atb":[[3.55,4.86]],"id":28603686}],"con":true,"img":false}]}
{"op":"mcm","clk":"5321934441","pt":1646314677080,"mc":[{"id":"1.195532854","rc":[{"atb":[[2.5,8.27]],"id":41064149}],"con":true,"img":false}]}
{"op":"mcm","clk":"5321938519","pt":1646314711865,"mc":[{"id":"1.195532854","rc":[{"atb":[[3.65,0]],"id":38833999}],"con":true,"img":false}]}
{"op":"mcm","clk":"5321940430","pt":1646314729500,"mc":[{"id":"1.195532854","rc":[{"atb":[[3.85,4.35]],"id":38833999}],"con":true,"img":false}]}
{"op":"mcm","clk":"5321958476","pt":1646314894407,"mc":[{"id":"1.195532854","rc":[{"atb":[[3.45,0]],"id":28603686},{"atb":[[3.45,0]],"id":42190933}],"con":true,"img":false}]}
{"op":"mcm","clk":"5321958748","pt":1646314897822,"mc":[{"id":"1.195532854","rc":[{"atb":[[3.65,4.23]],"id":28603686}],"con":true,"img":false}]}
{"op":"mcm","clk":"5321958773","pt":1646314898130,"mc":[{"id":"1.195532854","rc":[{"atb":[[3.65,4.23]],"id":42190933}],"con":true,"img":false}]}
{"op":"mcm","clk":"5321958837","pt":1646314898959,"mc":[{"id":"1.195532854","rc":[{"atb":[[4.1,0]],"id":36042605}],"con":true,"img":false}]}
{"op":"mcm","clk":"5321959881","pt":1646314910044,"mc":[{"id":"1.195532854","rc":[{"atb":[[2.38,0]],"id":41064149}],"con":true,"img":false}]}
{"op":"mcm","clk":"5321960080","pt":1646314912626,"mc":[{"id":"1.195532854","rc":[{"atb":[[2.54,7.28]],"id":41064149}],"con":true,"img":false}]}
{"op":"mcm","clk":"5321960826","pt":1646314920659,"mc":[{"id":"1.195532854","rc":[{"atb":[[4.5,3.55]],"id":36042605}],"con":true,"img":false}]}
{"op":"mcm","clk":"5321960912","pt":1646314921689,"mc":[{"id":"1.195532854","rc":[{"atb":[[4.3,12.12],[3.85,87.72],[3.95,50.85],[4.1,32.26]],"id":28603686},{"atl":[[10.5,4.21],[11.5,9.52],[12.5,13.04],[13.5,20.2]],"id":28603686},{"atb":[[3.6,56.94],[3.8,14.1],[3.5,98.7],[3.7,36.56]],"id":42609833},{"atl":[[11.5,3.81],[12.5,8.7],[13.5,12.2],[14.5,18.52]],"id":42609833},{"atb":[[4.3,12.12],[3.85,87.72],[3.95,50.85],[4.1,32.26]],"id":42190933},{"atl":[[10.5,4.21],[11.5,9.52],[12.5,13.04],[13.5,20.2]],"id":42190933},{"atb":[[5.3,23.26],[4.9,64.1],[5.1,36.59],[5.5,8.89]],"id":36042605},{"atl":[[18,2.36],[19,5.48],[20,7.78],[22,11.74]],"id":36042605},{"atb":[[2.56,96.15],[2.52,164.47],[2.64,24.39],[2.6,62.5]],"id":41064149},{"atl":[[5.1,24.39],[5.3,34.88],[5.5,55.56],[4.9,10.26]],"id":41064149}],"con":true,"img":false}]}
{"op":"mcm","clk":"5321960920","pt":1646314921790,"mc":[{"id":"1.195532854","rc":[{"atb":[[3.8,89.29],[4,33.33],[3.9,51.72],[4.2,12.5]],"id":38833999},{"atl":[[16,16.67],[13,3.33],[14,7.69],[15,10.71]],"id":38833999}],"con":true,"img":false}]}
{"op":"mcm","clk":"5321960928","pt":1646314921846,"mc":[{"id":"1.195532854","rc":[{"atl":[[10.5,0],[1000,16.74]],"id":42609833}],"con":true,"img":false}]}
{"op":"mcm","clk":"5321960945","pt":1646314922058,"mc":[{"id":"1.195532854","rc":[{"atl":[[1000,14.85]],"id":42609833}],"con":true,"img":false}]}
{"op":"mcm","clk":"5321960970","pt":1646314922264,"mc":[{"id":"1.195532854","rc":[{"atl":[[1000,14.5]],"id":42609833}],"con":true,"img":false}]}
{"op":"mcm","clk":"5321960981","pt":1646314922373,"mc":[{"id":"1.195532854","rc":[{"atl":[[11,1.36]],"id":42609833}],"con":true,"img":false}]}
{"op":"mcm","clk":"5321961007","pt":1646314922684,"mc":[{"id":"1.195532854","rc":[{"atl":[[10,0.82]],"id":28603686},{"atl":[[12,3.4]],"id":38833999},{"atl":[[11,2.19]],"id":42609833},{"atl":[[10,0.82]],"id":42190933},{"atl":[[4.8,0.82]],"id":41064149},{"atl":[[17.5,0.82]],"id":36042605}],"con":true,"img":false}]}
{"op":"mcm","clk":"5321961093","pt":1646314923681,"mc":[{"id":"1.195532854","rc":[{"atl":[[10,0.48]],"id":28603686},{"atl":[[12,3.02]],"id":38833999},{"atl":[[11,1.8]],"id":42609833},{"atl":[[10,0.44]],"id":42190933},{"atl":[[17.5,0.47]],"id":36042605},{"atl":[[4.8,0.43]],"id":41064149}],"con":true,"img":false}]}
{"op":"mcm","clk":"5321961158","pt":1646314924260,"mc":[{"id":"1.195532854","rc":[{"atb":[[2.88,0]],"id":42609833},{"atl":[[18,9.2]],"id":42190933},{"atb":[[2.46,0]],"id":41064149}],"con":true,"img":false}]}
{"op":"mcm","clk":"5321961176","pt":1646314924372,"mc":[{"id":"1.195532854","rc":[{"atl":[[18,9.2],[23,15.2]],"id":28603686},{"atl":[[20,9.2],[26,15.2]],"id":42609833},{"atl":[[23,15.2]],"id":42190933},{"atl":[[10.5,15.2],[8.2,9.2]],"id":41064149}],"con":true,"img":false}]}
{"op":"mcm","clk":"5321961302","pt":1646314925679,"mc":[{"id":"1.195532854","rc":[{"atl":[[11.5,0],[12,3.64]],"id":42609833}],"con":true,"img":false}]}
{"op":"mcm","clk":"5321961396","pt":1646314926672,"mc":[{"id":"1.195532854","rc":[{"atl":[[11,1.36]],"id":42609833}],"con":true,"img":false}]}
{"op":"mcm","clk":"5321961405","pt":1646314926765,"mc":[{"id":"1.195532854","rc":[{"atl":[[11.5,0.43]],"id":42609833}],"con":true,"img":false}]}
{"op":"mcm","clk":"5321962287","pt":1646314935700,"mc":[{"id":"1.195532854","rc":[{"atl":[[13,8.33]],"id":42609833}],"con":true,"img":false}]}
{"op":"mcm","clk":"5321962665","pt":1646314939079,"mc":[{"id":"1.195532854","rc":[{"atb":[[2.46,0]],"id":42609833}],"con":true,"img":false}]}
{"op":"mcm","clk":"5321962705","pt":1646314939395,"mc":[{"id":"1.195532854","rc":[{"atl":[[32,0]],"id":42609833}],"con":true,"img":false}]}
{"op":"mcm","clk":"5321962723","pt":1646314939702,"mc":[{"id":"1.195532854","rc":[{"atl":[[1000,16.15]],"id":42609833}],"con":true,"img":false}]}
{"op":"mcm","clk":"5321962796","pt":1646314940280,"mc":[{"id":"1.195532854","rc":[{"atl":[[1000,15.28]],"id":42609833}],"con":true,"img":false}]}
{"op":"mcm","clk":"5321962835","pt":1646314940592,"mc":[{"id":"1.195532854","rc":[{"atl":[[1000,14.5]],"id":42609833}],"con":true,"img":false}]}
{"op":"mcm","clk":"5321962840","pt":1646314940695,"mc":[{"id":"1.195532854","rc":[{"atl":[[11.5,1.22]],"id":42609833}],"con":true,"img":false}]}
{"op":"mcm","clk":"5321963309","pt":1646314945603,"mc":[{"id":"1.195532854","rc":[{"atb":[[3.75,0]],"id":38833999}],"con":true,"img":false}]}
{"op":"mcm","clk":"5321963321","pt":1646314945685,"mc":[{"id":"1.195532854","rc":[{"atl":[[12.5,0],[13.5,0.2],[14,11.54],[14.5,0]],"id":42609833}],"con":true,"img":false}]}
{"op":"mcm","clk":"5321963572","pt":1646314948425,"mc":[{"id":"1.195532854","rc":[{"atb":[[3.95,3.79]],"id":38833999}],"con":true,"img":false}]}
{"op":"mcm","clk":"5321964317","pt":1646314955724,"mc":[{"id":"1.195532854","rc":[{"atl":[[15,17.86]],"id":42609833},{"spn":3.86,"spf":2.1,"id":42609833}],"con":true,"img":false}]}
{"op":"mcm","clk":"5321969490","pt":1646315005799,"mc":[{"id":"1.195532854","rc":[{"atb":[[3.75,6.62]],"id":42609833}],"con":true,"img":false}]}
{"op":"mcm","clk":"5321969513","pt":1646315005961,"mc":[{"id":"1.195532854","rc":[{"atb":[[3.75,0]],"id":42609833}],"con":true,"img":false}]}
{"op":"mcm","clk":"5321970801","pt":1646315021803,"mc":[{"id":"1.195532854","rc":[{"atl":[[9.8,0]],"id":42190933},{"trd":[[9.8,2.29]],"ltp":9.8,"tv":2.29,"id":42190933},{"spn":8.0,"spf":1.0,"id":42190933}],"con":true,"img":false}]}
{"op":"mcm","clk":"5321970820","pt":1646315022013,"mc":[{"id":"1.195532854","rc":[{"atb":[[1.01,11002.24]],"id":42190933}],"con":true,"img":false}]}
{"op":"mcm","clk":"5321970828","pt":1646315022113,"mc":[{"id":"1.195532854","rc":[{"atb":[[1.01,11000.6]],"id":42190933}],"con":true,"img":false}]}
{"op":"mcm","clk":"5321970841","pt":1646315022319,"mc":[{"id":"1.195532854","rc":[{"atb":[[1.01,11000]],"id":42190933}],"con":true,"img":false}]}
{"op":"mcm","clk":"5321970853","pt":1646315022423,"mc":[{"id":"1.195532854","rc":[{"atb":[[6.2,0.6]],"id":42190933}],"con":true,"img":false}]}
{"op":"mcm","clk":"5321971371","pt":1646315027800,"mc":[{"id":"1.195532854","rc":[{"atb":[[2.5,68],[3,46]],"id":42190933}],"con":true,"img":false}]}
{"op":"mcm","clk":"5321972967","pt":1646315043951,"mc":[{"id":"1.195532854","rc":[{"atl":[[12,0.92]],"id":42190933}],"con":true,"img":false}]}
{"op":"mcm","clk":"5321974862","pt":1646315061445,"mc":[{"id":"1.195532854","rc":[{"spl":[[1.01,10]],"id":41064149}],"con":true,"img":false}]}
{"op":"mcm","clk":"5321982345","pt":1646315130687,"mc":[{"id":"1.195532854","rc":[{"spn":8.1,"spf":1.0,"id":42190933},{"spn":2.73,"spf":1.0,"id":41064149},{"atb":[[4.3,0]],"id":36042605}],"con":true,"img":false}]}
{"op":"mcm","clk":"5321983006","pt":1646315136222,"mc":[{"id":"1.195532854","rc":[{"atb":[[3.55,0]],"id":28603686},{"atb":[[3.55,0]],"id":42190933}],"con":true,"img":false}]}
{"op":"mcm","clk":"5321984378","pt":1646315149689,"mc":[{"id":"1.195532854","rc":[{"atb":[[4.1,36.26]],"id":42190933}],"con":true,"img":false}]}
{"op":"mcm","clk":"5321984420","pt":1646315150105,"mc":[{"id":"1.195532854","rc":[{"atb":[[3.95,55.05]],"id":28603686}],"con":true,"img":false}]}
{"op":"mcm","clk":"5321985095","pt":1646315156114,"mc":[{"id":"1.195532854","rc":[{"atb":[[3.65,0]],"id":28603686},{"atb":[[3.65,0]],"id":42190933},{"atb":[[2.54,0]],"id":41064149}],"con":true,"img":false}]}
{"op":"mcm","clk":"5321985362","pt":1646315159212,"mc":[{"id":"1.195532854","rc":[{"atb":[[3.95,58.85]],"id":28603686},{"atb":[[4.1,39.88]],"id":42190933}],"con":true,"img":false}]}
{"op":"mcm","clk":"5321985373","pt":1646315159318,"mc":[{"id":"1.195532854","rc":[{"atb":[[2.56,103.34]],"id":41064149}],"con":true,"img":false}]}
{"op":"mcm","clk":"5321986081","pt":1646315166132,"mc":[{"id":"1.195532854","rc":[{"atb":[[2.5,0]],"id":41064149}],"con":true,"img":false}]}
{"op":"mcm","clk":"5321987908","pt":1646315180183,"mc":[{"id":"1.195532854","rc":[{"atb":[[3.85,0]],"id":38833999},{"atb":[[4.5,0]],"id":36042605}],"con":true,"img":false}]}
{"op":"mcm","clk":"5321987933","pt":1646315180344,"mc":[{"id":"1.195532854","rc":[{"atb":[[2.56,111.3]],"id":41064149}],"con":true,"img":false}]}
{"op":"mcm","clk":"5321989618","pt":1646315198300,"mc":[{"id":"1.195532854","rc":[{"atb":[[3.9,56]],"id":38833999}],"con":true,"img":false}]}
{"op":"mcm","clk":"5321991654","pt":1646315221710,"mc":[{"id":"1.195532854","rc":[{"atb":[[4.3,0],[4.6,11.11]],"id":28603686},{"atb":[[4.3,0],[4.4,11.76],[4.2,0]],"id":38833999},{"atb":[[4.3,0],[4.6,11.11]],"id":42190933},{"atl":[[10.5,0],[11,3.94]],"id":42190933}],"con":true,"img":false}]}
{"op":"mcm","clk":"5321991662","pt":1646315221815,"mc":[{"id":"1.195532854","rc":[{"atb":[[4.5,2]],"id":38833999},{"atb":[[4,4.03]],"id":42609833}],"con":true,"img":false}]}
{"op":"mcm","clk":"5321991673","pt":1646315221918,"mc":[{"id":"1.195532854","rc":[{"atb":[[1.01,11002.24],[5.9,0]],"id":38833999}],"con":true,"img":false}]}
{"op":"mcm","clk":"5321991687","pt":1646315222021,"mc":[{"id":"1.195532854","rc":[{"atb":[[1.01,11000.63]],"id":38833999},{"atb":[[4,0]],"id":42609833}],"con":true,"img":false}]}
{"op":"mcm","clk":"5321991712","pt":1646315222226,"mc":[{"id":"1.195532854","rc":[{"atb":[[1.01,11000]],"id":38833999}],"con":true,"img":false}]}
{"op":"mcm","clk":"5321991722","pt":1646315222326,"mc":[{"id":"1.195532854","rc":[{"atb":[[4.5,2.63]],"id":38833999}],"con":true,"img":false}]}
{"op":"mcm","clk":"5321991786","pt":1646315222807,"mc":[{"id":"1.195532854","rc":[{"atl":[[10,0]],"id":42190933}],"con":true,"img":false}]}
{"op":"mcm","clk":"5321991794","pt":1646315222908,"mc":[{"id":"1.195532854","rc":[{"atl":[[10.5,0.44]],"id":42190933}],"con":true,"img":false}]}
{"op":"mcm","clk":"5321992634","pt":1646315231748,"mc":[{"id":"1.195532854","rc":[{"atb":[[4.4,29.41]],"id":28603686},{"atb":[[4.2,31.25]],"id":38833999},{"atb":[[4.4,29.41]],"id":42190933},{"atl":[[11,0],[11.5,3.75]],"id":42190933}],"con":true,"img":false}]}
{"op":"mcm","clk":"5321992734","pt":1646315232935,"mc":[{"id":"1.195532854","rc":[{"atl":[[10.5,0]],"id":42190933}],"con":true,"img":false}]}
{"op":"mcm","clk":"5321992744","pt":1646315233040,"mc":[{"id":"1.195532854","rc":[{"atl":[[11,0.44]],"id":42190933}],"con":true,"img":false}]}
{"op":"mcm","clk":"5321993589","pt":1646315241711,"mc":[{"id":"1.195532854","rc":[{"atb":[[3.85,0],[3.95,8],[4.1,0],[4.2,46.88]],"id":28603686},{"atb":[[3.8,0],[4,50]],"id":38833999},{"atb":[[3.85,0],[3.95,0],[4.1,7.62],[4.2,46.88]],"id":42190933},{"atl":[[11.5,0],[12,4.5]],"id":42190933}],"con":true,"img":false}]}
{"op":"mcm","clk":"5321993616","pt":1646315241950,"mc":[{"id":"1.195532854","rc":[{"atl":[[11,0]],"id":42190933}],"con":true,"img":false}]}
{"op":"mcm","clk":"5321993631","pt":1646315242054,"mc":[{"id":"1.195532854","rc":[{"atl":[[11.5,0.44]],"id":42190933}],"con":true,"img":false}]}
{"op":"mcm","clk":"5321994996","pt":1646315251801,"mc":[{"id":"1.195532854","rc":[{"atb":[[4,83.33]],"id":28603686},{"atb":[[3.9,90.49]],"id":38833999},{"atb":[[4,83.33]],"id":42190933},{"atl":[[12,0.92],[12.5,3.43]],"id":42190933}],"con":true,"img":false}]}
{"op":"mcm","clk":"5321995138","pt":1646315252997,"mc":[{"id":"1.195532854","rc":[{"atl":[[11.5,0]],"id":42190933}],"con":true,"img":false}]}
{"op":"mcm","clk":"5321995151","pt":1646315253098,"mc":[{"id":"1.195532854","rc":[{"atl":[[12,1.36]],"id":42190933}],"con":true,"img":false}]}
{"op":"mcm","clk":"5321996218","pt":1646315261688,"mc":[{"id":"1.195532854","rc":[{"spn":7.9,"spf":1.0,"id":38833999},{"atl":[[13,3.28]],"id":42190933},{"spn":9.1,"spf":1.0,"id":42190933}],"con":true,"img":false}]}
{"op":"mcm","clk":"5321996229","pt":1646315261843,"mc":[{"id":"1.195532854","rc":[{"atl":[[12.5,0]],"id":42190933}],"con":true,"img":false}]}
{"op":"mcm","clk":"5321996369","pt":1646315262997,"mc":[{"id":"1.195532854","rc":[{"atl":[[12,0.92]],"id":42190933}],"con":true,"img":false}]}
{"op":"mcm","clk":"5321996377","pt":1646315263092,"mc":[{"id":"1.195532854","rc":[{"atl":[[12.5,0.44]],"id":42190933}],"con":true,"img":false}]}
{"op":"mcm","clk":"5321997402","pt":1646315271847,"mc":[{"id":"1.195532854","rc":[{"atl":[[14,7.58]],"id":42190933}],"con":true,"img":false}]}
{"op":"mcm","clk":"5321998211","pt":1646315278319,"mc":[{"id":"1.195532854","rc":[{"atl":[[18,0]],"id":42190933}],"con":true,"img":false}]}
{"op":"mcm","clk":"5321998620","pt":1646315281735,"mc":[{"id":"1.195532854","rc":[{"atl":[[15,10.56]],"id":42190933}],"con":true,"img":false}]}
{"op":"mcm","clk":"5321999884","pt":1646315291762,"mc":[{"id":"1.195532854","rc":[{"atl":[[16,16.42]],"id":42190933}],"con":true,"img":false}]}
{"op":"mcm","clk":"5322000224","pt":1646315294435,"mc":[{"id":"1.195532854","rc":[{"atb":[[1.01,11002]],"id":36042605}],"con":true,"img":false}]}
{"op":"mcm","clk":"5322000252","pt":1646315294647,"mc":[{"id":"1.195532854","rc":[{"atb":[[1.01,11003.99]],"id":36042605}],"con":true,"img":false}]}
{"op":"mcm","clk":"5322000276","pt":1646315294882,"mc":[{"id":"1.195532854","rc":[{"atb":[[1.01,11002]],"id":36042605}],"con":true,"img":false}]}
{"op":"mcm","clk":"5322000287","pt":1646315294956,"mc":[{"id":"1.195532854","rc":[{"atb":[[1.02,1.99]],"id":36042605}],"con":true,"img":false}]}
{"op":"mcm","clk":"5322000303","pt":1646315295060,"mc":[{"id":"1.195532854","rc":[{"atb":[[1.01,11002]],"id":42190933}],"con":true,"img":false}]}
{"op":"mcm","clk":"5322000315","pt":1646315295166,"mc":[{"id":"1.195532854","rc":[{"atb":[[1.01,11003.99]],"id":42190933}],"con":true,"img":false}]}
{"op":"mcm","clk":"5322000336","pt":1646315295373,"mc":[{"id":"1.195532854","rc":[{"atb":[[1.01,11002]],"id":42190933}],"con":true,"img":false}]}
{"op":"mcm","clk":"5322000348","pt":1646315295431,"mc":[{"id":"1.195532854","rc":[{"atb":[[6.2,2.59]],"id":42190933}],"con":true,"img":false}]}
{"op":"mcm","clk":"5322000371","pt":1646315295638,"mc":[{"id":"1.195532854","rc":[{"atb":[[1.01,11002]],"id":42609833}],"con":true,"img":false}]}
{"op":"mcm","clk":"5322000399","pt":1646315295848,"mc":[{"id":"1.195532854","rc":[{"atb":[[1.01,11003.99]],"id":42609833}],"con":true,"img":false}]}
{"op":"mcm","clk":"5322000412","pt":1646315295946,"mc":[{"id":"1.195532854","rc":[{"atb":[[1.01,11002]],"id":42609833}],"con":true,"img":false}]}
{"op":"mcm","clk":"5322000430","pt":1646315296051,"mc":[{"id":"1.195532854","rc":[{"atb":[[3.9,3.64]],"id":42609833}],"con":true,"img":false}]}
{"op":"mcm","clk":"5322000446","pt":1646315296155,"mc":[{"id":"1.195532854","rc":[{"atb":[[1.01,11002]],"id":41064149}],"con":true,"img":false}]}
{"op":"mcm","clk":"5322000469","pt":1646315296366,"mc":[{"id":"1.195532854","rc":[{"atb":[[1.01,11003.99]],"id":41064149}],"con":true,"img":false}]}
{"op":"mcm","clk":"5322000493","pt":1646315296575,"mc":[{"id":"1.195532854","rc":[{"atb":[[1.01,11002]],"id":41064149}],"con":true,"img":false}]}
{"op":"mcm","clk":"5322000505","pt":1646315296634,"mc":[{"id":"1.195532854","rc":[{"atb":[[3,1.99]],"id":41064149}],"con":true,"img":false}]}
{"op":"mcm","clk":"5322000534","pt":1646315296843,"mc":[{"id":"1.195532854","rc":[{"atb":[[1.01,11002]],"id":38833999},{"atb":[[2.62,5]],"id":41064149}],"con":true,"img":false}]}
{"op":"mcm","clk":"5322000564","pt":1646315297046,"mc":[{"id":"1.195532854","rc":[{"atb":[[1.01,11003.99]],"id":38833999}],"con":true,"img":false}]}
{"op":"mcm","clk":"5322000579","pt":1646315297150,"mc":[{"id":"1.195532854","rc":[{"atb":[[1.01,11002]],"id":38833999}],"con":true,"img":false}]}
{"op":"mcm","clk":"5322000595","pt":1646315297257,"mc":[{"id":"1.195532854","rc":[{"atb":[[1.02,1.99]],"id":38833999}],"con":true,"img":false}]}
{"op":"mcm","clk":"5322000615","pt":1646315297466,"mc":[{"id":"1.195532854","rc":[{"atb":[[1.01,11002]],"id":28603686}],"con":true,"img":false}]}
{"op":"mcm","clk":"5322000643","pt":1646315297674,"mc":[{"id":"1.195532854","rc":[{"atb":[[1.01,11003.99]],"id":28603686}],"con":true,"img":false}]}
{"op":"mcm","clk":"5322000666","pt":1646315297834,"mc":[{"id":"1.195532854","rc":[{"atb":[[1.01,11002]],"id":28603686}],"con":true,"img":false}]}
{"op":"mcm","clk":"5322000677","pt":1646315297942,"mc":[{"id":"1.195532854","rc":[{"atb":[[1.02,1.99]],"id":28603686}],"con":true,"img":false}]}
{"op":"mcm","clk":"5322000892","pt":1646315299657,"mc":[{"id":"1.195532854","rc":[{"atb":[[1.73,126.03],[1.55,185.45]],"id":41064149}],"con":true,"img":false}]}
{"op":"mcm","clk":"5322001146","pt":1646315301748,"mc":[{"id":"1.195532854","rc":[{"atl":[[13.5,0.2]],"id":42190933}],"con":true,"img":false}]}
{"op":"mcm","clk":"5322001168","pt":1646315301852,"mc":[{"id":"1.195532854","rc":[{"atl":[[14,12.58]],"id":42190933}],"con":true,"img":false}]}
{"op":"mcm","clk":"5322001717","pt":1646315306849,"mc":[{"id":"1.195532854","rc":[{"atl":[[14,7.58]],"id":42190933},{"atb":[[2.62,0]],"id":41064149}],"con":true,"img":false}]}
{"op":"mcm","clk":"5322013336","pt":1646315415507,"mc":[{"id":"1.195532854","rc":[{"atb":[[3.95,0]],"id":38833999},{"spn":3.87,"spf":2.1,"id":42609833},{"spn":2.8,"spf":1.0,"id":41064149}],"con":true,"img":false}]}
{"op":"mcm","clk":"5322013679","pt":1646315417902,"mc":[{"id":"1.195532854","rc":[{"atb":[[2.96,5.71]],"id":38833999}],"con":true,"img":false}]}
{"op":"mcm","clk":"5322020146","pt":1646315475789,"mc":[{"id":"1.195532854","rc":[{"atb":[[3.95,4.2]],"id":28603686},{"atb":[[4.1,4]],"id":42190933}],"con":true,"img":false}]}
{"op":"mcm","clk":"5322020325","pt":1646315478020,"mc":[{"id":"1.195532854","rc":[{"atb":[[3.1,5.33]],"id":42190933}],"con":true,"img":false}]}
{"op":"mcm","clk":"5322020334","pt":1646315478129,"mc":[{"id":"1.195532854","rc":[{"atb":[[2.66,6.75]],"id":28603686}],"con":true,"img":false}]}
{"op":"mcm","clk":"5322021345","pt":1646315490845,"mc":[{"id":"1.195532854","rc":[{"atb":[[3.95,0]],"id":28603686},{"atb":[[3.9,86.21]],"id":38833999},{"atb":[[4.1,0]],"id":42190933}],"con":true,"img":false}]}
{"op":"mcm","clk":"5322021551","pt":1646315493610,"mc":[{"id":"1.195532854","rc":[{"atb":[[4,29.45]],"id":42609833}],"con":true,"img":false}]}
{"op":"mcm","clk":"5322021564","pt":1646315493812,"mc":[{"id":"1.195532854","rc":[{"atb":[[3.75,6.3]],"id":42609833}],"con":true,"img":false}]}
{"op":"mcm","clk":"5322021640","pt":1646315494644,"mc":[{"id":"1.195532854","rc":[{"atb":[[3.9,1.65]],"id":42609833}],"con":true,"img":false}]}
{"op":"mcm","clk":"5322021646","pt":1646315494749,"mc":[{"id":"1.195532854","rc":[{"atb":[[3.75,0],[4.1,1.99]],"id":42609833}],"con":true,"img":false}]}
{"op":"mcm","clk":"5322021664","pt":1646315494907,"mc":[{"id":"1.195532854","rc":[{"atb":[[2.92,0]],"id":42609833}],"con":true,"img":false}]}
{"op":"mcm","clk":"5322021740","pt":1646315496149,"mc":[{"id":"1.195532854","rc":[{"atb":[[4.1,4.89]],"id":42609833}],"con":true,"img":false}]}
{"op":"mcm","clk":"5322022402","pt":1646315504343,"mc":[{"id":"1.195532854","rc":[{"atb":[[3.2,5.64]],"id":42190933}],"con":true,"img":false}]}
{"op":"mcm","clk":"5322022421","pt":1646315504551,"mc":[{"id":"1.195532854","rc":[{"atb":[[3,6.2]],"id":38833999}],"con":true,"img":false}]}
{"op":"mcm","clk":"5322022427","pt":1646315504656,"mc":[{"id":"1.195532854","rc":[{"atb":[[2.7,7.3]],"id":28603686}],"con":true,"img":false}]}
{"op":"mcm","clk":"5322022460","pt":1646315505125,"mc":[{"id":"1.195532854","rc":[{"atb":[[3.9,0]],"id":42609833}],"con":true,"img":false}]}
{"op":"mcm","clk":"5322022481","pt":1646315505434,"mc":[{"id":"1.195532854","rc":[{"atb":[[4.2,1.65]],"id":42609833}],"con":true,"img":false}]}
{"op":"mcm","clk":"5322022678","pt":1646315508138,"mc":[{"id":"1.195532854","rc":[{"atb":[[4.1,1.99]],"id":42609833}],"con":true,"img":false}]}
{"op":"mcm","clk":"5322024421","pt":1646315527589,"mc":[{"id":"1.195532854","rc":[{"atb":[[1.01,11004.52]],"id":42609833}],"con":true,"img":false}]}
{"op":"mcm","clk":"5322024429","pt":1646315527692,"mc":[{"id":"1.195532854","rc":[{"atb":[[1.01,11003.68]],"id":42609833},{"atl":[[4.6,2.52]],"id":41064149}],"con":true,"img":false}]}
{"op":"mcm","clk":"5322024447","pt":1646315527852,"mc":[{"id":"1.195532854","rc":[{"atb":[[1.01,11002]],"id":42609833}],"con":true,"img":false}]}
{"op":"mcm","clk":"5322024457","pt":1646315527952,"mc":[{"id":"1.195532854","rc":[{"atb":[[4.3,1.68]],"id":42609833}],"con":true,"img":false}]}
{"op":"mcm","clk":"5322024486","pt":1646315528265,"mc":[{"id":"1.195532854","rc":[{"atl":[[4.6,0]],"id":41064149}],"con":true,"img":false}]}
{"op":"mcm","clk":"5322024507","pt":1646315528475,"mc":[{"id":"1.195532854","rc":[{"atl":[[4.8,0]],"id":41064149}],"con":true,"img":false}]}
{"op":"mcm","clk":"5322024518","pt":1646315528579,"mc":[{"id":"1.195532854","rc":[{"atl":[[4.6,0.43]],"id":41064149}],"con":true,"img":false}]}
{"op":"mcm","clk":"5322024581","pt":1646315529154,"mc":[{"id":"1.195532854","rc":[{"atb":[[4.1,0]],"id":42609833}],"con":true,"img":false}]}
{"op":"mcm","clk":"5322024597","pt":1646315529253,"mc":[{"id":"1.195532854","rc":[{"atb":[[4.3,3.67]],"id":42609833}],"con":true,"img":false}]}
{"op":"mcm","clk":"5322024758","pt":1646315530761,"mc":[{"id":"1.195532854","rc":[{"atb":[[4.3,1.68]],"id":42609833}],"con":true,"img":false}]}
{"op":"mcm","clk":"5322024772","pt":1646315530864,"mc":[{"id":"1.195532854","rc":[{"atb":[[4.1,1.99]],"id":42609833}],"con":true,"img":false}]}
{"op":"mcm","clk":"5322024934","pt":1646315532212,"mc":[{"id":"1.195532854","rc":[{"atb":[[4.1,0]],"id":42609833},{"atb":[[2.56,104.11]],"id":41064149}],"con":true,"img":false}]}
{"op":"mcm","clk":"5322024949","pt":1646315532318,"mc":[{"id":"1.195532854","rc":[{"atb":[[4.3,3.67]],"id":42609833}],"con":true,"img":false}]}
{"op":"mcm","clk":"5322025103","pt":1646315534229,"mc":[{"id":"1.195532854","rc":[{"atl":[[4.6,2.96]],"id":41064149}],"con":true,"img":false}]}
{"op":"mcm","clk":"5322025121","pt":1646315534436,"mc":[{"id":"1.195532854","rc":[{"atb":[[4.3,1.68]],"id":42609833}],"con":true,"img":false}]}
{"op":"mcm","clk":"5322025131","pt":1646315534538,"mc":[{"id":"1.195532854","rc":[{"atb":[[4.1,1.99]],"id":42609833}],"con":true,"img":false}]}
{"op":"mcm","clk":"5322025140","pt":1646315534643,"mc":[{"id":"1.195532854","rc":[{"atl":[[4.6,0.43]],"id":41064149}],"con":true,"img":false}]}
{"op":"mcm","clk":"5322025193","pt":1646315535216,"mc":[{"id":"1.195532854","rc":[{"atb":[[2.6,69.51]],"id":41064149}],"con":true,"img":false}]}
{"op":"mcm","clk":"5322025281","pt":1646315536201,"mc":[{"id":"1.195532854","rc":[{"atb":[[4.1,0]],"id":42609833},{"spn":4.12,"spf":2.1,"id":42609833}],"con":true,"img":false}]}
{"op":"mcm","clk":"5322025288","pt":1646315536318,"mc":[{"id":"1.195532854","rc":[{"atb":[[4.3,3.67]],"id":42609833}],"con":true,"img":false}]}
{"op":"mcm","clk":"5322025435","pt":1646315537812,"mc":[{"id":"1.195532854","rc":[{"atb":[[4.3,1.68]],"id":42609833}],"con":true,"img":false}]}
{"op":"mcm","clk":"5322025449","pt":1646315537913,"mc":[{"id":"1.195532854","rc":[{"atb":[[4.1,1.99]],"id":42609833}],"con":true,"img":false}]}
{"op":"mcm","clk":"5322025566","pt":1646315539257,"mc":[{"id":"1.195532854","rc":[{"atb":[[4.1,0]],"id":42609833}],"con":true,"img":false}]}
{"op":"mcm","clk":"5322025578","pt":1646315539361,"mc":[{"id":"1.195532854","rc":[{"atb":[[4.3,3.67]],"id":42609833}],"con":true,"img":false}]}
{"op":"mcm","clk":"5322025695","pt":1646315540755,"mc":[{"id":"1.195532854","rc":[{"atb":[[4.3,1.68]],"id":42609833},{"atl":[[4.6,2.96]],"id":41064149}],"con":true,"img":false}]}
{"op":"mcm","clk":"5322025706","pt":1646315540858,"mc":[{"id":"1.195532854","rc":[{"atb":[[4.1,1.99]],"id":42609833}],"con":true,"img":false}]}
{"op":"mcm","clk":"5322025731","pt":1646315541121,"mc":[{"id":"1.195532854","rc":[{"atl":[[4.6,0.43]],"id":41064149}],"con":true,"img":false}]}
{"op":"mcm","clk":"5322025875","pt":1646315542736,"mc":[{"id":"1.195532854","rc":[{"atb":[[4.1,0]],"id":42609833}],"con":true,"img":false}]}
{"op":"mcm","clk":"5322025885","pt":1646315542841,"mc":[{"id":"1.195532854","rc":[{"atb":[[4.3,3.67]],"id":42609833}],"con":true,"img":false}]}
{"op":"mcm","clk":"5322026031","pt":1646315544340,"mc":[{"id":"1.195532854","rc":[{"atb":[[4.3,1.68]],"id":42609833}],"con":true,"img":false}]}
{"op":"mcm","clk":"5322026041","pt":1646315544448,"mc":[{"id":"1.195532854","rc":[{"atb":[[4.1,1.99]],"id":42609833}],"con":true,"img":false}]}
{"op":"mcm","clk":"5322026190","pt":1646315546050,"mc":[{"id":"1.195532854","rc":[{"atb":[[4.1,0]],"id":42609833}],"con":true,"img":false}]}
{"op":"mcm","clk":"5322026197","pt":1646315546151,"mc":[{"id":"1.195532854","rc":[{"atb":[[4.3,3.67]],"id":42609833}],"con":true,"img":false}]}
{"op":"mcm","clk":"5322026264","pt":1646315547032,"mc":[{"id":"1.195532854","rc":[{"atl":[[4.6,2.96]],"id":41064149}],"con":true,"img":false}]}
{"op":"mcm","clk":"5322026304","pt":1646315547553,"mc":[{"id":"1.195532854","rc":[{"atl":[[4.6,0.43]],"id":41064149}],"con":true,"img":false}]}
{"op":"mcm","clk":"5322026311","pt":1646315547656,"mc":[{"id":"1.195532854","rc":[{"atb":[[4.3,1.68]],"id":42609833},{"atb":[[2.56,96.15]],"id":41064149}],"con":true,"img":false}]}
{"op":"mcm","clk":"5322026314","pt":1646315547757,"mc":[{"id":"1.195532854","rc":[{"atb":[[4.1,1.99]],"id":42609833}],"con":true,"img":false}]}
{"op":"mcm","clk":"5322026412","pt":1646315549061,"mc":[{"id":"1.195532854","rc":[{"atb":[[4.1,0]],"id":42609833}],"con":true,"img":false}]}
{"op":"mcm","clk":"5322026423","pt":1646315549164,"mc":[{"id":"1.195532854","rc":[{"atb":[[4.3,3.67]],"id":42609833}],"con":true,"img":false}]}
{"op":"mcm","clk":"5322026652","pt":1646315551960,"mc":[{"id":"1.195532854","rc":[{"atb":[[4.3,1.68]],"id":42609833}],"con":true,"img":false}]}
{"op":"mcm","clk":"5322026661","pt":1646315552065,"mc":[{"id":"1.195532854","rc":[{"atb":[[4.1,1.99]],"id":42609833}],"con":true,"img":false}]}
{"op":"mcm","clk":"5322026728","pt":1646315552842,"mc":[{"id":"1.195532854","rc":[{"atb":[[3.95,4.18]],"id":42609833}],"con":true,"img":false}]}
{"op":"mcm","clk":"5322026758","pt":1646315553254,"mc":[{"id":"1.195532854","rc":[{"atb":[[3.95,0]],"id":42609833}],"con":true,"img":false}]}
{"op":"mcm","clk":"5322026763","pt":1646315553357,"mc":[{"id":"1.195532854","rc":[{"atl":[[4.6,2.96]],"id":41064149}],"con":true,"img":false}]}
{"op":"mcm","clk":"5322026800","pt":1646315553872,"mc":[{"id":"1.195532854","rc":[{"atb":[[4.1,0]],"id":42609833},{"atl":[[4.6,0.43]],"id":41064149}],"con":true,"img":false}]}
{"op":"mcm","clk":"5322026812","pt":1646315553977,"mc":[{"id":"1.195532854","rc":[{"atb":[[4.3,3.67]],"id":42609833}],"con":true,"img":false}]}
{"op":"mcm","clk":"5322026917","pt":1646315555277,"mc":[{"id":"1.195532854","rc":[{"atb":[[4.3,1.68]],"id":42609833}],"con":true,"img":false}]}
{"op":"mcm","clk":"5322026929","pt":1646315555382,"mc":[{"id":"1.195532854","rc":[{"atb":[[4.1,1.99]],"id":42609833}],"con":true,"img":false}]}
{"op":"mcm","clk":"5322027042","pt":1646315556575,"mc":[{"id":"1.195532854","rc":[{"atb":[[4.1,0]],"id":42609833}],"con":true,"img":false}]}
{"op":"mcm","clk":"5322027050","pt":1646315556676,"mc":[{"id":"1.195532854","rc":[{"atb":[[4.3,3.67]],"id":42609833}],"con":true,"img":false}]}
{"op":"mcm","clk":"5322027183","pt":1646315558237,"mc":[{"id":"1.195532854","rc":[{"atb":[[4.3,1.68]],"id":42609833}],"con":true,"img":false}]}
{"op":"mcm","clk":"5322027199","pt":1646315558348,"mc":[{"id":"1.195532854","rc":[{"atb":[[4.1,1.99]],"id":42609833}],"con":true,"img":false}]}
{"op":"mcm","clk":"5322027230","pt":1646315558652,"mc":[{"id":"1.195532854","rc":[{"atb":[[2.6,77.27]],"id":41064149}],"con":true,"img":false}]}
{"op":"mcm","clk":"5322027319","pt":1646315559859,"mc":[{"id":"1.195532854","rc":[{"atl":[[4.6,2.96]],"id":41064149}],"con":true,"img":false}]}
{"op":"mcm","clk":"5322027336","pt":1646315560056,"mc":[{"id":"1.195532854","rc":[{"atb":[[4.1,0]],"id":42609833}],"con":true,"img":false}]}
{"op":"mcm","clk":"5322027343","pt":1646315560163,"mc":[{"id":"1.195532854","rc":[{"atb":[[4.3,3.67]],"id":42609833}],"con":true,"img":false}]}
{"op":"mcm","clk":"5322027351","pt":1646315560270,"mc":[{"id":"1.195532854","rc":[{"atl":[[4.6,0.43]],"id":41064149}],"con":true,"img":false}]}
{"op":"mcm","clk":"5322027440","pt":1646315561362,"mc":[{"id":"1.195532854","rc":[{"atb":[[4.3,1.68]],"id":42609833}],"con":true,"img":false}]}
{"op":"mcm","clk":"5322027448","pt":1646315561463,"mc":[{"id":"1.195532854","rc":[{"atb":[[4.1,1.99]],"id":42609833}],"con":true,"img":false}]}
{"op":"mcm","clk":"5322027607","pt":1646315563641,"mc":[{"id":"1.195532854","rc":[{"atb":[[4.1,0]],"id":42609833}],"con":true,"img":false}]}
{"op":"mcm","clk":"5322027614","pt":1646315563745,"mc":[{"id":"1.195532854","rc":[{"atb":[[4.3,3.67]],"id":42609833}],"con":true,"img":false}]}
{"op":"mcm","clk":"5322027711","pt":1646315565149,"mc":[{"id":"1.195532854","rc":[{"atb":[[4.3,1.68]],"id":42609833}],"con":true,"img":false}]}
{"op":"mcm","clk":"5322027715","pt":1646315565252,"mc":[{"id":"1.195532854","rc":[{"atb":[[4.1,1.99]],"id":42609833}],"con":true,"img":false}]}
{"op":"mcm","clk":"5322027757","pt":1646315565771,"mc":[{"id":"1.195532854","rc":[{"atl":[[4.6,2.96]],"id":41064149}],"con":true,"img":false}]}
{"op":"mcm","clk":"5322027777","pt":1646315566083,"mc":[{"id":"1.195532854","rc":[{"atb":[[4.1,0]],"id":42609833}],"con":true,"img":false}]}
{"op":"mcm","clk":"5322027787","pt":1646315566137,"mc":[{"id":"1.195532854","rc":[{"atb":[[4.3,3.67]],"id":42609833},{"atl":[[4.6,0.43]],"id":41064149}],"con":true,"img":false}]}
{"op":"mcm","clk":"5322027961","pt":1646315568079,"mc":[{"id":"1.195532854","rc":[{"atb":[[4.3,1.68]],"id":42609833}],"con":true,"img":false}]}
{"op":"mcm","clk":"5322027966","pt":1646315568182,"mc":[{"id":"1.195532854","rc":[{"atb":[[4.1,1.99]],"id":42609833}],"con":true,"img":false}]}
{"op":"mcm","clk":"5322028039","pt":1646315569165,"mc":[{"id":"1.195532854","rc":[{"atb":[[4.1,0]],"id":42609833}],"con":true,"img":false}]}
{"op":"mcm","clk":"5322028045","pt":1646315569269,"mc":[{"id":"1.195532854","rc":[{"atb":[[4.3,3.67]],"id":42609833}],"con":true,"img":false}]}
{"op":"mcm","clk":"5322028123","pt":1646315570360,"mc":[{"id":"1.195532854","rc":[{"atb":[[4.2,0]],"id":42609833}],"con":true,"img":false}]}
{"op":"mcm","clk":"5322028141","pt":1646315570662,"mc":[{"id":"1.195532854","rc":[{"atb":[[4.4,1.65]],"id":42609833}],"con":true,"img":false}]}
{"op":"mcm","clk":"5322028157","pt":1646315570974,"mc":[{"id":"1.195532854","rc":[{"atb":[[4.3,1.68]],"id":42609833}],"con":true,"img":false}]}
{"op":"mcm","clk":"5322028167","pt":1646315571074,"mc":[{"id":"1.195532854","rc":[{"atb":[[4.1,1.99]],"id":42609833}],"con":true,"img":false}]}
{"op":"mcm","clk":"5322028204","pt":1646315571748,"mc":[{"id":"1.195532854","rc":[{"atb":[[4.3,0]],"id":42609833},{"atl":[[4.6,2.96]],"id":41064149}],"con":true,"img":false}]}
{"op":"mcm","clk":"5322028226","pt":1646315572056,"mc":[{"id":"1.195532854","rc":[{"atl":[[4.6,0.43]],"id":41064149}],"con":true,"img":false}]}
{"op":"mcm","clk":"5322028360","pt":1646315573659,"mc":[{"id":"1.195532854","rc":[{"atb":[[1.01,11004.52]],"id":42609833}],"con":true,"img":false}]}
{"op":"mcm","clk":"5322028368","pt":1646315573760,"mc":[{"id":"1.195532854","rc":[{"atb":[[1.01,11003.68]],"id":42609833}],"con":true,"img":false}]}
{"op":"mcm","clk":"5322028390","pt":1646315573967,"mc":[{"id":"1.195532854","rc":[{"atb":[[1.01,11002]],"id":42609833}],"con":true,"img":false}]}
{"op":"mcm","clk":"5322028399","pt":1646315574070,"mc":[{"id":"1.195532854","rc":[{"atb":[[4.5,1.68]],"id":42609833}],"con":true,"img":false}]}
{"op":"mcm","clk":"5322028416","pt":1646315574275,"mc":[{"id":"1.195532854","rc":[{"atl":[[12,2.1]],"id":38833999},{"atb":[[3.95,4.18]],"id":42609833}],"con":true,"img":false}]}
{"op":"mcm","clk":"5322028435","pt":1646315574482,"mc":[{"id":"1.195532854","rc":[{"atl":[[11.5,0.96]],"id":38833999}],"con":true,"img":false}]}
{"op":"mcm","clk":"5322028453","pt":1646315574690,"mc":[{"id":"1.195532854","rc":[{"atl":[[12,1.65]],"id":38833999}],"con":true,"img":false}]}
{"op":"mcm","clk":"5322028463","pt":1646315574793,"mc":[{"id":"1.195532854","rc":[{"atl":[[12.5,0.64]],"id":38833999}],"con":true,"img":false}]}
{"op":"mcm","clk":"5322028479","pt":1646315575000,"mc":[{"id":"1.195532854","rc":[{"atb":[[4.1,0]],"id":42609833}],"con":true,"img":false}]}
{"op":"mcm","clk":"5322028486","pt":1646315575058,"mc":[{"id":"1.195532854","rc":[{"atb":[[4.5,3.67]],"id":42609833}],"con":true,"img":false}]}
{"op":"mcm","clk":"5322028497","pt":1646315575159,"mc":[{"id":"1.195532854","rc":[{"atb":[[3.95,0]],"id":42609833}],"con":true,"img":false}]}
{"op":"mcm","clk":"5322028534","pt":1646315575673,"mc":[{"id":"1.195532854","rc":[{"atl":[[12.5,0.2]],"id":38833999}],"con":true,"img":false}]}
{"op":"mcm","clk":"5322028543","pt":1646315575782,"mc":[{"id":"1.195532854","rc":[{"atl":[[12,2.1]],"id":38833999}],"con":true,"img":false}]}
{"op":"mcm","clk":"5322028605","pt":1646315576456,"mc":[{"id":"1.195532854","rc":[{"atb":[[4.5,1.68]],"id":42609833}],"con":true,"img":false}]}
{"op":"mcm","clk":"5322028615","pt":1646315576568,"mc":[{"id":"1.195532854","rc":[{"atb":[[4.1,1.99]],"id":42609833}],"con":true,"img":false}]}
{"op":"mcm","clk":"5322028723","pt":1646315577902,"mc":[{"id":"1.195532854","rc":[{"atb":[[4.1,0]],"id":42609833}],"con":true,"img":false}]}
{"op":"mcm","clk":"5322028731","pt":1646315578006,"mc":[{"id":"1.195532854","rc":[{"atb":[[4.5,3.67]],"id":42609833},{"atl":[[4.6,2.96]],"id":41064149}],"con":true,"img":false}]}
{"op":"mcm","clk":"5322028773","pt":1646315578475,"mc":[{"id":"1.195532854","rc":[{"atl":[[4.6,0.43]],"id":41064149}],"con":true,"img":false}]}
{"op":"mcm","clk":"5322028822","pt":1646315578991,"mc":[{"id":"1.195532854","rc":[{"atb":[[4.5,1.68]],"id":42609833}],"con":true,"img":false}]}
{"op":"mcm","clk":"5322028829","pt":1646315579094,"mc":[{"id":"1.195532854","rc":[{"atb":[[4.1,1.99]],"id":42609833}],"con":true,"img":false}]}
{"op":"mcm","clk":"5322029013","pt":1646315581495,"mc":[{"id":"1.195532854","rc":[{"atb":[[4.1,0]],"id":42609833}],"con":true,"img":false}]}
{"op":"mcm","clk":"5322029022","pt":1646315581593,"mc":[{"id":"1.195532854","rc":[{"atb":[[4.5,3.67]],"id":42609833}],"con":true,"img":false}]}
{"op":"mcm","clk":"5322029084","pt":1646315582370,"mc":[{"id":"1.195532854","rc":[{"atb":[[4.5,1.68]],"id":42609833}],"con":true,"img":false}]}
{"op":"mcm","clk":"5322029097","pt":1646315582476,"mc":[{"id":"1.195532854","rc":[{"atb":[[4.1,1.99]],"id":42609833}],"con":true,"img":false}]}
{"op":"mcm","clk":"5322029252","pt":1646315584192,"mc":[{"id":"1.195532854","rc":[{"atl":[[4.6,2.96]],"id":41064149}],"con":true,"img":false}]}
{"op":"mcm","clk":"5322029269","pt":1646315584506,"mc":[{"id":"1.195532854","rc":[{"atb":[[4.1,0]],"id":42609833}],"con":true,"img":false}]}
{"op":"mcm","clk":"5322029278","pt":1646315584632,"mc":[{"id":"1.195532854","rc":[{"atb":[[4.5,3.67]],"id":42609833},{"atl":[[4.6,0.43]],"id":41064149}],"con":true,"img":false}]}
{"op":"mcm","clk":"5322029364","pt":1646315585502,"mc":[{"id":"1.195532854","rc":[{"atb":[[4.5,1.68]],"id":42609833}],"con":true,"img":false}]}
{"op":"mcm","clk":"5322029373","pt":1646315585606,"mc":[{"id":"1.195532854","rc":[{"atb":[[4.1,1.99]],"id":42609833}],"con":true,"img":false}]}
{"op":"mcm","clk":"5322029534","pt":1646315587894,"mc":[{"id":"1.195532854","rc":[{"atb":[[4.1,0]],"id":42609833}],"con":true,"img":false}]}
{"op":"mcm","clk":"5322029539","pt":1646315587983,"mc":[{"id":"1.195532854","rc":[{"atb":[[4.5,3.67]],"id":42609833}],"con":true,"img":false}]}
{"op":"mcm","clk":"5322029754","pt":1646315590200,"mc":[{"id":"1.195532854","rc":[{"atb":[[4.5,1.68]],"id":42609833}],"con":true,"img":false}]}
{"op":"mcm","clk":"5322029769","pt":1646315590314,"mc":[{"id":"1.195532854","rc":[{"atb":[[4.1,1.99]],"id":42609833}],"con":true,"img":false}]}
{"op":"mcm","clk":"5322029775","pt":1646315590403,"mc":[{"id":"1.195532854","rc":[{"atl":[[4.6,2.96]],"id":41064149}],"con":true,"img":false}]}
{"op":"mcm","clk":"5322029814","pt":1646315590790,"mc":[{"id":"1.195532854","rc":[{"atl":[[4.6,0.43]],"id":41064149}],"con":true,"img":false}]}
{"op":"mcm","clk":"5322029891","pt":1646315591707,"mc":[{"id":"1.195532854","rc":[{"atb":[[4.1,0]],"id":42609833}],"con":true,"img":false}]}
{"op":"mcm","clk":"5322029900","pt":1646315591825,"mc":[{"id":"1.195532854","rc":[{"atb":[[4.5,3.67]],"id":42609833}],"con":true,"img":false}]}
{"op":"mcm","clk":"5322030029","pt":1646315593520,"mc":[{"id":"1.195532854","rc":[{"atb":[[4.5,1.68]],"id":42609833}],"con":true,"img":false}]}
{"op":"mcm","clk":"5322030033","pt":1646315593618,"mc":[{"id":"1.195532854","rc":[{"atb":[[4.1,1.99]],"id":42609833}],"con":true,"img":false}]}
{"op":"mcm","clk":"5322030138","pt":1646315594713,"mc":[{"id":"1.195532854","rc":[{"atb":[[4.1,0]],"id":42609833}],"con":true,"img":false}]}
{"op":"mcm","clk":"5322030152","pt":1646315594817,"mc":[{"id":"1.195532854","rc":[{"atb":[[4.5,3.67]],"id":42609833}],"con":true,"img":false}]}
{"op":"mcm","clk":"5322030283","pt":1646315596823,"mc":[{"id":"1.195532854","rc":[{"atb":[[4.5,1.68]],"id":42609833},{"spn":4.22,"spf":2.1,"id":42609833}],"con":true,"img":false}]}
{"op":"mcm","clk":"5322030291","pt":1646315596928,"mc":[{"id":"1.195532854","rc":[{"atb":[[4.1,1.99]],"id":42609833}],"con":true,"img":false}]}
{"op":"mcm","clk":"5322030305","pt":1646315596989,"mc":[{"id":"1.195532854","rc":[{"atl":[[4.6,2.96]],"id":41064149}],"con":true,"img":false}]}
{"op":"mcm","clk":"5322030346","pt":1646315597400,"mc":[{"id":"1.195532854","rc":[{"atl":[[4.6,0.43]],"id":41064149}],"con":true,"img":false}]}
{"op":"mcm","clk":"5322030524","pt":1646315599319,"mc":[{"id":"1.195532854","rc":[{"atb":[[4.1,0]],"id":42609833}],"con":true,"img":false}]}
{"op":"mcm","clk":"5322030530","pt":1646315599417,"mc":[{"id":"1.195532854","rc":[{"atb":[[4.5,3.67]],"id":42609833}],"con":true,"img":false}]}
{"op":"mcm","clk":"5322030553","pt":1646315599831,"mc":[{"id":"1.195532854","rc":[{"atb":[[4.5,1.68]],"id":42609833}],"con":true,"img":false}]}
{"op":"mcm","clk":"5322030560","pt":1646315599888,"mc":[{"id":"1.195532854","rc":[{"atb":[[4.1,1.99]],"id":42609833}],"con":true,"img":false}]}
{"op":"mcm","clk":"5322030660","pt":1646315601225,"mc":[{"id":"1.195532854","rc":[{"atb":[[4.1,0]],"id":42609833}],"con":true,"img":false}]}
{"op":"mcm","clk":"5322030666","pt":1646315601328,"mc":[{"id":"1.195532854","rc":[{"atb":[[4.5,3.67]],"id":42609833}],"con":true,"img":false}]}
{"op":"mcm","clk":"5322030813","pt":1646315603194,"mc":[{"id":"1.195532854","rc":[{"atb":[[4.5,1.68]],"id":42609833}],"con":true,"img":false}]}
{"op":"mcm","clk":"5322030822","pt":1646315603299,"mc":[{"id":"1.195532854","rc":[{"atb":[[4.1,1.99]],"id":42609833}],"con":true,"img":false}]}
{"op":"mcm","clk":"5322030828","pt":1646315603402,"mc":[{"id":"1.195532854","rc":[{"atl":[[4.6,2.96]],"id":41064149}],"con":true,"img":false}]}
{"op":"mcm","clk":"5322030857","pt":1646315603823,"mc":[{"id":"1.195532854","rc":[{"atl":[[4.6,0.43]],"id":41064149}],"con":true,"img":false}]}
{"op":"mcm","clk":"5322031089","pt":1646315606430,"mc":[{"id":"1.195532854","rc":[{"atb":[[4.1,0]],"id":42609833}],"con":true,"img":false}]}
{"op":"mcm","clk":"5322031101","pt":1646315606545,"mc":[{"id":"1.195532854","rc":[{"atb":[[4.5,3.67]],"id":42609833}],"con":true,"img":false}]}
{"op":"mcm","clk":"5322031305","pt":1646315608939,"mc":[{"id":"1.195532854","rc":[{"atb":[[4.5,1.68]],"id":42609833}],"con":true,"img":false}]}
{"op":"mcm","clk":"5322031315","pt":1646315609040,"mc":[{"id":"1.195532854","rc":[{"atb":[[4.1,1.99]],"id":42609833}],"con":true,"img":false}]}
{"op":"mcm","clk":"5322031350","pt":1646315609415,"mc":[{"id":"1.195532854","rc":[{"atl":[[4.6,2.96]],"id":41064149}],"con":true,"img":false}]}
{"op":"mcm","clk":"5322031384","pt":1646315609821,"mc":[{"id":"1.195532854","rc":[{"atl":[[4.6,0.43]],"id":41064149}],"con":true,"img":false}]}
{"op":"mcm","clk":"5322031417","pt":1646315610340,"mc":[{"id":"1.195532854","rc":[{"atb":[[4.1,0]],"id":42609833}],"con":true,"img":false}]}
{"op":"mcm","clk":"5322031422","pt":1646315610440,"mc":[{"id":"1.195532854","rc":[{"atb":[[4.5,3.67]],"id":42609833}],"con":true,"img":false}]}
{"op":"mcm","clk":"5322031563","pt":1646315612218,"mc":[{"id":"1.195532854","rc":[{"atb":[[4.5,1.68]],"id":42609833}],"con":true,"img":false}]}
{"op":"mcm","clk":"5322031568","pt":1646315612321,"mc":[{"id":"1.195532854","rc":[{"atb":[[4.1,1.99]],"id":42609833}],"con":true,"img":false}]}
{"op":"mcm","clk":"5322031584","pt":1646315612523,"mc":[{"id":"1.195532854","rc":[{"atb":[[3.95,4.18]],"id":42609833}],"con":true,"img":false}]}
{"op":"mcm","clk":"5322031665","pt":1646315613818,"mc":[{"id":"1.195532854","rc":[{"atb":[[4.1,0]],"id":42609833}],"con":true,"img":false}]}
{"op":"mcm","clk":"5322031672","pt":1646315613920,"mc":[{"id":"1.195532854","rc":[{"atb":[[4.5,3.67],[3.95,0]],"id":42609833}],"con":true,"img":false}]}
{"op":"mcm","clk":"5322031747","pt":1646315615020,"mc":[{"id":"1.195532854","rc":[{"atb":[[4.5,1.68]],"id":42609833}],"con":true,"img":false}]}
{"op":"mcm","clk":"5322031755","pt":1646315615118,"mc":[{"id":"1.195532854","rc":[{"atb":[[4.1,1.99]],"id":42609833}],"con":true,"img":false}]}
{"op":"mcm","clk":"5322031796","pt":1646315615634,"mc":[{"id":"1.195532854","rc":[{"atb":[[4.1,0]],"id":42609833}],"con":true,"img":false}]}
{"op":"mcm","clk":"5322031805","pt":1646315615736,"mc":[{"id":"1.195532854","rc":[{"atb":[[4.5,3.67]],"id":42609833}],"con":true,"img":false}]}
{"op":"mcm","clk":"5322031828","pt":1646315616000,"mc":[{"id":"1.195532854","rc":[{"atl":[[4.6,2.96]],"id":41064149}],"con":true,"img":false}]}
{"op":"mcm","clk":"5322031863","pt":1646315616412,"mc":[{"id":"1.195532854","rc":[{"atl":[[4.6,0.43]],"id":41064149}],"con":true,"img":false}]}
{"op":"mcm","clk":"5322031949","pt":1646315617504,"mc":[{"id":"1.195532854","rc":[{"atb":[[4.5,1.68]],"id":42609833}],"con":true,"img":false}]}
{"op":"mcm","clk":"5322031958","pt":1646315617608,"mc":[{"id":"1.195532854","rc":[{"atb":[[4.1,1.99]],"id":42609833}],"con":true,"img":false}]}
{"op":"mcm","clk":"5322032073","pt":1646315618909,"mc":[{"id":"1.195532854","rc":[{"atb":[[4.1,0]],"id":42609833}],"con":true,"img":false}]}
{"op":"mcm","clk":"5322032080","pt":1646315619015,"mc":[{"id":"1.195532854","rc":[{"atb":[[4.5,3.67]],"id":42609833}],"con":true,"img":false}]}
{"op":"mcm","clk":"5322032113","pt":1646315619430,"mc":[{"id":"1.195532854","rc":[{"atb":[[4.5,1.68]],"id":42609833}],"con":true,"img":false}]}
{"op":"mcm","clk":"5322032119","pt":1646315619528,"mc":[{"id":"1.195532854","rc":[{"atb":[[4.1,1.99]],"id":42609833}],"con":true,"img":false}]}
{"op":"mcm","clk":"5322032203","pt":1646315620524,"mc":[{"id":"1.195532854","rc":[{"atb":[[4.1,0]],"id":42609833}],"con":true,"img":false}]}
{"op":"mcm","clk":"5322032213","pt":1646315620624,"mc":[{"id":"1.195532854","rc":[{"atb":[[4.5,3.67]],"id":42609833}],"con":true,"img":false}]}
{"op":"mcm","clk":"5322032343","pt":1646315622632,"mc":[{"id":"1.195532854","rc":[{"atb":[[4.5,1.68]],"id":42609833}],"con":true,"img":false}]}
{"op":"mcm","clk":"5322032349","pt":1646315622706,"mc":[{"id":"1.195532854","rc":[{"atb":[[4.1,1.99]],"id":42609833}],"con":true,"img":false}]}
{"op":"mcm","clk":"5322032355","pt":1646315622806,"mc":[{"id":"1.195532854","rc":[{"atl":[[4.6,2.96]],"id":41064149}],"con":true,"img":false}]}
{"op":"mcm","clk":"5322032396","pt":1646315623427,"mc":[{"id":"1.195532854","rc":[{"atl":[[4.6,0.43]],"id":41064149}],"con":true,"img":false}]}
{"op":"mcm","clk":"5322032470","pt":1646315624307,"mc":[{"id":"1.195532854","rc":[{"atb":[[4.1,0]],"id":42609833}],"con":true,"img":false}]}
{"op":"mcm","clk":"5322032476","pt":1646315624410,"mc":[{"id":"1.195532854","rc":[{"atb":[[4.5,3.67]],"id":42609833}],"con":true,"img":false}]}
{"op":"mcm","clk":"5322032586","pt":1646315625707,"mc":[{"id":"1.195532854","rc":[{"atb":[[4.5,1.68]],"id":42609833}],"con":true,"img":false}]}
{"op":"mcm","clk":"5322032594","pt":1646315625812,"mc":[{"id":"1.195532854","rc":[{"atb":[[4.1,1.99]],"id":42609833}],"con":true,"img":false}]}
{"op":"mcm","clk":"5322032732","pt":1646315627114,"mc":[{"id":"1.195532854","rc":[{"atb":[[4.1,0]],"id":42609833}],"con":true,"img":false}]}
{"op":"mcm","clk":"5322032745","pt":1646315627250,"mc":[{"id":"1.195532854","rc":[{"atb":[[4.5,3.67]],"id":42609833}],"con":true,"img":false}]}
{"op":"mcm","clk":"5322032879","pt":1646315628732,"mc":[{"id":"1.195532854","rc":[{"atb":[[4.5,1.68]],"id":42609833}],"con":true,"img":false}]}
{"op":"mcm","clk":"5322032885","pt":1646315628833,"mc":[{"id":"1.195532854","rc":[{"atb":[[4.1,1.99]],"id":42609833}],"con":true,"img":false}]}
{"op":"mcm","clk":"5322032921","pt":1646315629308,"mc":[{"id":"1.195532854","rc":[{"atl":[[4.6,2.96]],"id":41064149}],"con":true,"img":false}]}
{"op":"mcm","clk":"5322032967","pt":1646315629841,"mc":[{"id":"1.195532854","rc":[{"atl":[[4.6,0.43]],"id":41064149}],"con":true,"img":false}]}
{"op":"mcm","clk":"5322032999","pt":1646315630240,"mc":[{"id":"1.195532854","rc":[{"atb":[[4.1,0]],"id":42609833}],"con":true,"img":false}]}
{"op":"mcm","clk":"5322033005","pt":1646315630297,"mc":[{"id":"1.195532854","rc":[{"atb":[[4.5,3.67]],"id":42609833}],"con":true,"img":false}]}
{"op":"mcm","clk":"5322033109","pt":1646315631743,"mc":[{"id":"1.195532854","rc":[{"atb":[[4.5,1.68]],"id":42609833}],"con":true,"img":false}]}
{"op":"mcm","clk":"5322033122","pt":1646315631850,"mc":[{"id":"1.195532854","rc":[{"atb":[[4.1,1.99]],"id":42609833}],"con":true,"img":false}]}
{"op":"mcm","clk":"5322033363","pt":1646315635203,"mc":[{"id":"1.195532854","rc":[{"atl":[[4.6,2.96]],"id":41064149}],"con":true,"img":false}]}
{"op":"mcm","clk":"5322033381","pt":1646315635514,"mc":[{"id":"1.195532854","rc":[{"atb":[[4.1,0]],"id":42609833}],"con":true,"img":false}]}
{"op":"mcm","clk":"5322033387","pt":1646315635614,"mc":[{"id":"1.195532854","rc":[{"atb":[[4.5,3.67]],"id":42609833}],"con":true,"img":false}]}
{"op":"mcm","clk":"5322033397","pt":1646315635724,"mc":[{"id":"1.195532854","rc":[{"atl":[[4.6,0.43]],"id":41064149}],"con":true,"img":false}]}
{"op":"mcm","clk":"5322033410","pt":1646315635926,"mc":[{"id":"1.195532854","rc":[{"atb":[[4.4,0]],"id":42609833}],"con":true,"img":false}]}
{"op":"mcm","clk":"5322033429","pt":1646315636234,"mc":[{"id":"1.195532854","rc":[{"atb":[[4.6,1.65]],"id":42609833}],"con":true,"img":false}]}
{"op":"mcm","clk":"5322033437","pt":1646315636339,"mc":[{"id":"1.195532854","rc":[{"atb":[[4.5,1.68]],"id":42609833}],"con":true,"img":false}]}
{"op":"mcm","clk":"5322033443","pt":1646315636440,"mc":[{"id":"1.195532854","rc":[{"atb":[[4.1,1.99]],"id":42609833}],"con":true,"img":false}]}
{"op":"mcm","clk":"5322033456","pt":1646315636650,"mc":[{"id":"1.195532854","rc":[{"atb":[[3.95,4.18]],"id":42609833}],"con":true,"img":false}]}
{"op":"mcm","clk":"5322033486","pt":1646315636909,"mc":[{"id":"1.195532854","rc":[{"atb":[[4.5,0]],"id":42609833}],"con":true,"img":false}]}
{"op":"mcm","clk":"5322033577","pt":1646315638101,"mc":[{"id":"1.195532854","rc":[{"atb":[[3.95,0]],"id":42609833}],"con":true,"img":false}]}
{"op":"mcm","clk":"5322033757","pt":1646315640330,"mc":[{"id":"1.195532854","rc":[{"atl":[[4.6,2.96]],"id":41064149}],"con":true,"img":false}]}
{"op":"mcm","clk":"5322033784","pt":1646315640642,"mc":[{"id":"1.195532854","rc":[{"atl":[[4.6,0.43]],"id":41064149}],"con":true,"img":false}]}
{"op":"mcm","clk":"5322034204","pt":1646315646216,"mc":[{"id":"1.195532854","rc":[{"atl":[[4.6,2.96]],"id":41064149}],"con":true,"img":false}]}
{"op":"mcm","clk":"5322034230","pt":1646315646530,"mc":[{"id":"1.195532854","rc":[{"atl":[[4.6,0.43]],"id":41064149}],"con":true,"img":false}]}
{"op":"mcm","clk":"5322034669","pt":1646315651726,"mc":[{"id":"1.195532854","rc":[{"atl":[[4.6,2.96]],"id":41064149}],"con":true,"img":false}]}
{"op":"mcm","clk":"5322034700","pt":1646315652139,"mc":[{"id":"1.195532854","rc":[{"atl":[[4.6,0.43]],"id":41064149}],"con":true,"img":false}]}
{"op":"mcm","clk":"5322035097","pt":1646315657158,"mc":[{"id":"1.195532854","rc":[{"spn":4.18,"spf":2.1,"id":42609833},{"atl":[[4.6,2.96]],"id":41064149}],"con":true,"img":false}]}
{"op":"mcm","clk":"5322035130","pt":1646315657572,"mc":[{"id":"1.195532854","rc":[{"atl":[[4.6,0.43]],"id":41064149}],"con":true,"img":false}]}
{"op":"mcm","clk":"5322035622","pt":1646315663037,"mc":[{"id":"1.195532854","rc":[{"atl":[[4.6,2.96]],"id":41064149}],"con":true,"img":false}]}
{"op":"mcm","clk":"5322035651","pt":1646315663349,"mc":[{"id":"1.195532854","rc":[{"atl":[[4.6,0.43]],"id":41064149}],"con":true,"img":false}]}
{"op":"mcm","clk":"5322036126","pt":1646315668756,"mc":[{"id":"1.195532854","rc":[{"atl":[[4.6,2.96]],"id":41064149}],"con":true,"img":false}]}
{"op":"mcm","clk":"5322036153","pt":1646315669065,"mc":[{"id":"1.195532854","rc":[{"atl":[[4.6,0.43]],"id":41064149}],"con":true,"img":false}]}
{"op":"mcm","clk":"5322036243","pt":1646315670056,"mc":[{"id":"1.195532854","rc":[{"atb":[[2.66,24.95]],"id":41064149},{"atb":[[5.6,20.32]],"id":36042605}],"con":true,"img":false}]}
{"op":"mcm","clk":"5322036623","pt":1646315674176,"mc":[{"id":"1.195532854","rc":[{"atl":[[4.6,2.96]],"id":41064149}],"con":true,"img":false}]}
{"op":"mcm","clk":"5322036656","pt":1646315674550,"mc":[{"id":"1.195532854","rc":[{"atl":[[4.6,0.43]],"id":41064149}],"con":true,"img":false}]}
{"op":"mcm","clk":"5322037043","pt":1646315679694,"mc":[{"id":"1.195532854","rc":[{"atl":[[4.6,2.96]],"id":41064149}],"con":true,"img":false}]}
{"op":"mcm","clk":"5322037068","pt":1646315679957,"mc":[{"id":"1.195532854","rc":[{"atl":[[4.6,0.43]],"id":41064149}],"con":true,"img":false}]}
{"op":"mcm","clk":"5322037469","pt":1646315685498,"mc":[{"id":"1.195532854","rc":[{"atl":[[4.6,2.96]],"id":41064149}],"con":true,"img":false}]}
{"op":"mcm","clk":"5322037492","pt":1646315685759,"mc":[{"id":"1.195532854","rc":[{"atl":[[4.6,0.43]],"id":41064149}],"con":true,"img":false}]}
{"op":"mcm","clk":"5322037910","pt":1646315690795,"mc":[{"id":"1.195532854","rc":[{"atl":[[4.6,2.96]],"id":41064149}],"con":true,"img":false}]}
{"op":"mcm","clk":"5322037947","pt":1646315691168,"mc":[{"id":"1.195532854","rc":[{"atl":[[4.6,0.43]],"id":41064149}],"con":true,"img":false}]}
{"op":"mcm","clk":"5322038291","pt":1646315696206,"mc":[{"id":"1.195532854","rc":[{"atl":[[4.6,2.96]],"id":41064149}],"con":true,"img":false}]}
{"op":"mcm","clk":"5322038312","pt":1646315696584,"mc":[{"id":"1.195532854","rc":[{"atl":[[4.6,0.43]],"id":41064149}],"con":true,"img":false}]}
{"op":"mcm","clk":"5322038714","pt":1646315701692,"mc":[{"id":"1.195532854","rc":[{"atl":[[4.6,2.96]],"id":41064149}],"con":true,"img":false}]}
{"op":"mcm","clk":"5322038742","pt":1646315702005,"mc":[{"id":"1.195532854","rc":[{"atl":[[4.6,0.43]],"id":41064149}],"con":true,"img":false}]}
{"op":"mcm","clk":"5322039243","pt":1646315707176,"mc":[{"id":"1.195532854","rc":[{"atl":[[4.6,2.96]],"id":41064149}],"con":true,"img":false}]}
{"op":"mcm","clk":"5322039282","pt":1646315707546,"mc":[{"id":"1.195532854","rc":[{"atl":[[4.6,0.43]],"id":41064149}],"con":true,"img":false}]}
{"op":"mcm","clk":"5322039744","pt":1646315712579,"mc":[{"id":"1.195532854","rc":[{"atl":[[4.6,2.96]],"id":41064149}],"con":true,"img":false}]}
{"op":"mcm","clk":"5322039783","pt":1646315712993,"mc":[{"id":"1.195532854","rc":[{"atl":[[4.6,0.43]],"id":41064149}],"con":true,"img":false}]}
{"op":"mcm","clk":"5322040384","pt":1646315718986,"mc":[{"id":"1.195532854","rc":[{"atl":[[4.6,2.96]],"id":41064149},{"spn":2.81,"spf":1.0,"id":41064149}],"con":true,"img":false}]}
{"op":"mcm","clk":"5322040416","pt":1646315719303,"mc":[{"id":"1.195532854","rc":[{"atl":[[4.6,0.43]],"id":41064149}],"con":true,"img":false}]}
{"op":"mcm","clk":"5322041005","pt":1646315724688,"mc":[{"id":"1.195532854","rc":[{"atl":[[4.6,2.96]],"id":41064149}],"con":true,"img":false}]}
{"op":"mcm","clk":"5322041039","pt":1646315725106,"mc":[{"id":"1.195532854","rc":[{"atl":[[4.6,0.43]],"id":41064149}],"con":true,"img":false}]}
{"op":"mcm","clk":"5322041292","pt":1646315727398,"mc":[{"id":"1.195532854","rc":[{"atb":[[2.96,0]],"id":42609833}],"con":true,"img":false}]}
{"op":"mcm","clk":"5322041541","pt":1646315730491,"mc":[{"id":"1.195532854","rc":[{"atl":[[4.6,2.96]],"id":41064149}],"con":true,"img":false}]}
{"op":"mcm","clk":"5322041550","pt":1646315730590,"mc":[{"id":"1.195532854","rc":[{"atb":[[2.78,6.3]],"id":42609833}],"con":true,"img":false}]}
{"op":"mcm","clk":"5322041585","pt":1646315731006,"mc":[{"id":"1.195532854","rc":[{"atl":[[4.6,0.43]],"id":41064149}],"con":true,"img":false}]}
{"op":"mcm","clk":"5322042150","pt":1646315736626,"mc":[{"id":"1.195532854","rc":[{"atb":[[3.1,0]],"id":42190933}],"con":true,"img":false}]}
{"op":"mcm","clk":"5322042184","pt":1646315737002,"mc":[{"id":"1.195532854","rc":[{"atl":[[4.6,2.96]],"id":41064149}],"con":true,"img":false}]}
{"op":"mcm","clk":"5322042223","pt":1646315737414,"mc":[{"id":"1.195532854","rc":[{"atl":[[4.6,0.43]],"id":41064149}],"con":true,"img":false}]}
{"op":"mcm","clk":"5322042417","pt":1646315739621,"mc":[{"id":"1.195532854","rc":[{"atb":[[2.66,0]],"id":28603686},{"atb":[[2.96,0]],"id":38833999}],"con":true,"img":false}]}
{"op":"mcm","clk":"5322042432","pt":1646315739823,"mc":[{"id":"1.195532854","rc":[{"atb":[[3.3,4.87]],"id":42190933}],"con":true,"img":false}]}
{"op":"mcm","clk":"5322042676","pt":1646315742725,"mc":[{"id":"1.195532854","rc":[{"atb":[[3.1,5.33]],"id":38833999}],"con":true,"img":false}]}
{"op":"mcm","clk":"5322042684","pt":1646315742823,"mc":[{"id":"1.195532854","rc":[{"atl":[[4.6,2.96]],"id":41064149}],"con":true,"img":false}]}
{"op":"mcm","clk":"5322042696","pt":1646315742929,"mc":[{"id":"1.195532854","rc":[{"atb":[[2.74,6.44]],"id":28603686}],"con":true,"img":false}]}
{"op":"mcm","clk":"5322042719","pt":1646315743233,"mc":[{"id":"1.195532854","rc":[{"atl":[[4.6,0.43]],"id":41064149}],"con":true,"img":false}]}
{"op":"mcm","clk":"5322043178","pt":1646315748830,"mc":[{"id":"1.195532854","rc":[{"atl":[[4.6,2.96]],"id":41064149}],"con":true,"img":false}]}
{"op":"mcm","clk":"5322043221","pt":1646315749405,"mc":[{"id":"1.195532854","rc":[{"atl":[[4.6,0.43]],"id":41064149}],"con":true,"img":false}]}
{"op":"mcm","clk":"5322043699","pt":1646315755042,"mc":[{"id":"1.195532854","rc":[{"atl":[[4.6,2.96]],"id":41064149}],"con":true,"img":false}]}
{"op":"mcm","clk":"5322043723","pt":1646315755408,"mc":[{"id":"1.195532854","rc":[{"atl":[[4.6,0.43]],"id":41064149}],"con":true,"img":false}]}
{"op":"mcm","clk":"5322044114","pt":1646315760433,"mc":[{"id":"1.195532854","rc":[{"atl":[[4.6,2.96]],"id":41064149}],"con":true,"img":false}]}
{"op":"mcm","clk":"5322044155","pt":1646315760849,"mc":[{"id":"1.195532854","rc":[{"atl":[[4.6,0.43]],"id":41064149}],"con":true,"img":false}]}
{"op":"mcm","clk":"5322044607","pt":1646315765922,"mc":[{"id":"1.195532854","rc":[{"atl":[[4.6,2.96]],"id":41064149}],"con":true,"img":false}]}
{"op":"mcm","clk":"5322044628","pt":1646315766227,"mc":[{"id":"1.195532854","rc":[{"atl":[[4.6,0.43]],"id":41064149}],"con":true,"img":false}]}
{"op":"mcm","clk":"5322045058","pt":1646315771235,"mc":[{"id":"1.195532854","rc":[{"atl":[[4.6,2.96]],"id":41064149}],"con":true,"img":false}]}
{"op":"mcm","clk":"5322045089","pt":1646315771550,"mc":[{"id":"1.195532854","rc":[{"atl":[[4.6,0.43]],"id":41064149}],"con":true,"img":false}]}
{"op":"mcm","clk":"5322045560","pt":1646315776885,"mc":[{"id":"1.195532854","rc":[{"atl":[[4.6,2.96]],"id":41064149}],"con":true,"img":false}]}
{"op":"mcm","clk":"5322045610","pt":1646315777366,"mc":[{"id":"1.195532854","rc":[{"atl":[[4.6,0.43]],"id":41064149}],"con":true,"img":false}]}
{"op":"mcm","clk":"5322046037","pt":1646315782190,"mc":[{"id":"1.195532854","rc":[{"atl":[[4.6,2.96]],"id":41064149}],"con":true,"img":false}]}
{"op":"mcm","clk":"5322046066","pt":1646315782563,"mc":[{"id":"1.195532854","rc":[{"atl":[[4.6,0.43]],"id":41064149}],"con":true,"img":false}]}
{"op":"mcm","clk":"5322046475","pt":1646315787472,"mc":[{"id":"1.195532854","rc":[{"atl":[[4.6,2.96]],"id":41064149}],"con":true,"img":false}]}
{"op":"mcm","clk":"5322046512","pt":1646315787987,"mc":[{"id":"1.195532854","rc":[{"atl":[[4.6,0.43]],"id":41064149}],"con":true,"img":false}]}
{"op":"mcm","clk":"5322046913","pt":1646315793002,"mc":[{"id":"1.195532854","rc":[{"atl":[[4.6,2.96]],"id":41064149}],"con":true,"img":false}]}
{"op":"mcm","clk":"5322046932","pt":1646315793298,"mc":[{"id":"1.195532854","rc":[{"atl":[[4.6,0.43]],"id":41064149}],"con":true,"img":false}]}
{"op":"mcm","clk":"5322047359","pt":1646315798399,"mc":[{"id":"1.195532854","rc":[{"atl":[[4.6,2.96]],"id":41064149}],"con":true,"img":false}]}
{"op":"mcm","clk":"5322047397","pt":1646315798811,"mc":[{"id":"1.195532854","rc":[{"atl":[[4.6,0.43]],"id":41064149}],"con":true,"img":false}]}
{"op":"mcm","clk":"5322047892","pt":1646315804300,"mc":[{"id":"1.195532854","rc":[{"atl":[[4.6,2.96]],"id":41064149}],"con":true,"img":false}]}
{"op":"mcm","clk":"5322047915","pt":1646315804604,"mc":[{"id":"1.195532854","rc":[{"atl":[[4.6,0.43]],"id":41064149}],"con":true,"img":false}]}
{"op":"mcm","clk":"5322048380","pt":1646315810009,"mc":[{"id":"1.195532854","rc":[{"atl":[[4.6,2.96]],"id":41064149}],"con":true,"img":false}]}
{"op":"mcm","clk":"5322048409","pt":1646315810416,"mc":[{"id":"1.195532854","rc":[{"atl":[[4.6,0.43]],"id":41064149}],"con":true,"img":false}]}
{"op":"mcm","clk":"5322048837","pt":1646315815330,"mc":[{"id":"1.195532854","rc":[{"atl":[[4.6,2.96]],"id":41064149}],"con":true,"img":false}]}
{"op":"mcm","clk":"5322048873","pt":1646315815689,"mc":[{"id":"1.195532854","rc":[{"atl":[[4.6,0.43]],"id":41064149}],"con":true,"img":false}]}
{"op":"mcm","clk":"5322049412","pt":1646315821614,"mc":[{"id":"1.195532854","rc":[{"atl":[[4.6,2.96]],"id":41064149}],"con":true,"img":false}]}
{"op":"mcm","clk":"5322049441","pt":1646315821819,"mc":[{"id":"1.195532854","rc":[{"atb":[[2.52,230.26]],"id":41064149},{"atl":[[4.9,34.65]],"id":41064149}],"con":true,"img":false}]}
{"op":"mcm","clk":"5322049464","pt":1646315822031,"mc":[{"id":"1.195532854","rc":[{"atl":[[4.6,0.43]],"id":41064149}],"con":true,"img":false}]}
{"op":"mcm","clk":"5322049666","pt":1646315823824,"mc":[{"id":"1.195532854","rc":[{"atl":[[4.7,4.94]],"id":41064149}],"con":true,"img":false}]}
{"op":"mcm","clk":"5322049965","pt":1646315827323,"mc":[{"id":"1.195532854","rc":[{"atl":[[4.6,2.96]],"id":41064149}],"con":true,"img":false}]}
{"op":"mcm","clk":"5322049992","pt":1646315827632,"mc":[{"id":"1.195532854","rc":[{"atl":[[4.6,0.43]],"id":41064149}],"con":true,"img":false}]}
{"op":"mcm","clk":"5322050480","pt":1646315833145,"mc":[{"id":"1.195532854","rc":[{"atl":[[4.6,2.96]],"id":41064149}],"con":true,"img":false}]}
{"op":"mcm","clk":"5322050528","pt":1646315833659,"mc":[{"id":"1.195532854","rc":[{"atl":[[4.6,0.43]],"id":41064149}],"con":true,"img":false}]}
{"op":"mcm","clk":"5322050976","pt":1646315838558,"mc":[{"id":"1.195532854","rc":[{"atl":[[4.6,2.96]],"id":41064149}],"con":true,"img":false}]}
{"op":"mcm","clk":"5322051003","pt":1646315838866,"mc":[{"id":"1.195532854","rc":[{"atl":[[4.6,0.43]],"id":41064149}],"con":true,"img":false}]}
{"op":"mcm","clk":"5322051011","pt":1646315838964,"mc":[{"id":"1.195532854","rc":[{"atl":[[4.7,2]],"id":41064149}],"con":true,"img":false}]}
{"op":"mcm","clk":"5322051290","pt":1646315842221,"mc":[{"id":"1.195532854","rc":[{"atl":[[4.7,4.88]],"id":41064149}],"con":true,"img":false}]}
{"op":"mcm","clk":"5322051344","pt":1646315842831,"mc":[{"id":"1.195532854","rc":[{"atb":[[4,0]],"id":42609833}],"con":true,"img":false}]}
{"op":"mcm","clk":"5322051352","pt":1646315842936,"mc":[{"id":"1.195532854","rc":[{"atb":[[3.5,126.9],[6.2,29.45]],"id":42609833},{"atl":[[11.5,4.86]],"id":42609833}],"con":true,"img":false}]}
{"op":"mcm","clk":"5322051359","pt":1646315843042,"mc":[{"id":"1.195532854","rc":[{"atb":[[3.9,34.48]],"id":28603686},{"atl":[[12,9.09]],"id":28603686},{"atb":[[3.9,109.73]],"id":38833999},{"atl":[[12,4.2]],"id":38833999},{"atb":[[3.95,4.52]],"id":42609833},{"atb":[[4,97.04]],"id":42190933},{"atl":[[13,6.56]],"id":42190933},{"atb":[[4.4,29.41]],"id":36042605},{"atl":[[18,7.84]],"id":36042605}],"con":true,"img":false}]}
{"op":"mcm","clk":"5322051368","pt":1646315843150,"mc":[{"id":"1.195532854","rc":[{"atl":[[17,0]],"id":36042605}],"con":true,"img":false}]}
{"op":"mcm","clk":"5322051387","pt":1646315843349,"mc":[{"id":"1.195532854","rc":[{"atl":[[16,0.68],[18,2.36],[19,11.04]],"id":36042605}],"con":true,"img":false}]}
{"op":"mcm","clk":"5322051407","pt":1646315843581,"mc":[{"id":"1.195532854","rc":[{"atb":[[6.2,0.6]],"id":42190933}],"con":true,"img":false}]}
{"op":"mcm","clk":"5322051419","pt":1646315843670,"mc":[{"id":"1.195532854","rc":[{"atb":[[1.02,1.99]],"id":42190933}],"con":true,"img":false}]}
{"op":"mcm","clk":"5322051428","pt":1646315843764,"mc":[{"id":"1.195532854","rc":[{"atl":[[4.5,2.52]],"id":41064149}],"con":true,"img":false}]}
{"op":"mcm","clk":"5322051438","pt":1646315843866,"mc":[{"id":"1.195532854","rc":[{"atb":[[1.02,4.94]],"id":28603686},{"atb":[[1.02,4.95]],"id":38833999},{"atb":[[1.03,2.89],[4.1,0]],"id":42609833},{"atb":[[1.02,4.94]],"id":42190933},{"atb":[[1.03,3.1]],"id":41064149},{"atb":[[1.03,2.9]],"id":36042605}],"con":true,"img":false}]}
{"op":"mcm","clk":"5322051448","pt":1646315843983,"mc":[{"id":"1.195532854","rc":[{"atb":[[1.02,1.99]],"id":42609833},{"atl":[[5,4.51]],"id":41064149}],"con":true,"img":false}]}
{"op":"mcm","clk":"5322051467","pt":1646315844181,"mc":[{"id":"1.195532854","rc":[{"atb":[[3,0]],"id":41064149}],"con":true,"img":false}]}
{"op":"mcm","clk":"5322051477","pt":1646315844271,"mc":[{"id":"1.195532854","rc":[{"atb":[[1.02,2.21]],"id":28603686},{"atb":[[1.03,0.15]],"id":42609833},{"atb":[[1.02,1.99]],"id":41064149},{"atb":[[1.03,0.17]],"id":36042605}],"con":true,"img":false}]}
{"op":"mcm","clk":"5322051486","pt":1646315844338,"mc":[{"id":"1.195532854","rc":[{"atb":[[1.02,2.22]],"id":38833999},{"atb":[[1.02,2.21]],"id":42190933},{"atb":[[1.03,0.37]],"id":41064149}],"con":true,"img":false}]}
{"op":"mcm","clk":"5322051518","pt":1646315844651,"mc":[{"id":"1.195532854","rc":[{"atb":[[1.02,1.99]],"id":28603686},{"atb":[[1.03,0]],"id":42609833}],"con":true,"img":false}]}
{"op":"mcm","clk":"5322051525","pt":1646315844756,"mc":[{"id":"1.195532854","rc":[{"atb":[[4.9,0.22]],"id":28603686},{"atb":[[7,0.15]],"id":42609833},{"atb":[[1.03,0]],"id":36042605}],"con":true,"img":false}]}
{"op":"mcm","clk":"5322051532","pt":1646315844865,"mc":[{"id":"1.195532854","rc":[{"atb":[[1.02,1.99]],"id":38833999},{"atb":[[1.02,1.99]],"id":42190933},{"atb":[[6.2,2.1]],"id":36042605},{"atb":[[1.03,0]],"id":41064149},{"atl":[[4.6,0]],"id":41064149}],"con":true,"img":false}]}
{"op":"mcm","clk":"5322051538","pt":1646315844960,"mc":[{"id":"1.195532854","rc":[{"atb":[[4.6,0.23]],"id":38833999},{"atb":[[4.9,0.22]],"id":42190933},{"atb":[[2.9,0.37]],"id":41064149},{"atl":[[4.5,2.96]],"id":41064149}],"con":true,"img":false}]}
{"op":"mcm","clk":"5322051545","pt":1646315845070,"mc":[{"id":"1.195532854","rc":[{"atb":[[3.95,0]],"id":42609833},{"atl":[[5,0]],"id":41064149}],"con":true,"img":false}]}
{"op":"mcm","clk":"5322051553","pt":1646315845169,"mc":[{"id":"1.195532854","rc":[{"atb":[[4.3,3.7]],"id":38833999},{"atl":[[4.7,2]],"id":41064149}],"con":true,"img":false}]}
{"op":"mcm","clk":"5322051718","pt":1646315847082,"mc":[{"id":"1.195532854","rc":[{"atb":[[4.3,0]],"id":38833999}],"con":true,"img":false}]}
{"op":"mcm","clk":"5322051788","pt":1646315847868,"mc":[{"id":"1.195532854","rc":[{"atb":[[3.9,32.24]],"id":42609833},{"atb":[[4.7,14.34]],"id":42190933}],"con":true,"img":false}]}
{"op":"mcm","clk":"5322051994","pt":1646315850971,"mc":[{"id":"1.195532854","rc":[{"atl":[[4.5,0.43]],"id":41064149}],"con":true,"img":false}]}
{"op":"mcm","clk":"5322052060","pt":1646315851865,"mc":[{"id":"1.195532854","rc":[{"atl":[[4.5,0]],"id":41064149}],"con":true,"img":false}]}
{"op":"mcm","clk":"5322052066","pt":1646315851962,"mc":[{"id":"1.195532854","rc":[{"atl":[[4.7,2.43]],"id":41064149}],"con":true,"img":false}]}
{"op":"mcm","clk":"5322052073","pt":1646315852062,"mc":[{"id":"1.195532854","rc":[{"atl":[[5.1,48.78],[4.9,10.26]],"id":41064149}],"con":true,"img":false}]}
{"op":"mcm","clk":"5322052131","pt":1646315852843,"mc":[{"id":"1.195532854","rc":[{"atl":[[4.7,2]],"id":41064149}],"con":true,"img":false}]}
{"op":"mcm","clk":"5322052137","pt":1646315852955,"mc":[{"id":"1.195532854","rc":[{"atl":[[4.8,0.43]],"id":41064149}],"con":true,"img":false}]}
{"op":"mcm","clk":"5322052146","pt":1646315853054,"mc":[{"id":"1.195532854","rc":[{"atl":[[4.9,35.9]],"id":41064149}],"con":true,"img":false}]}
{"op":"mcm","clk":"5322052160","pt":1646315853162,"mc":[{"id":"1.195532854","rc":[{"atl":[[5.1,24.39]],"id":41064149}],"con":true,"img":false}]}
{"op":"mcm","clk":"5322052166","pt":1646315853261,"mc":[{"id":"1.195532854","rc":[{"atl":[[18,8.24],[19,5.48]],"id":36042605}],"con":true,"img":false}]}
{"op":"mcm","clk":"5322052238","pt":1646315853979,"mc":[{"id":"1.195532854","rc":[{"atl":[[4.7,4.86]],"id":41064149}],"con":true,"img":false}]}
{"op":"mcm","clk":"5322052304","pt":1646315854864,"mc":[{"id":"1.195532854","rc":[{"atl":[[4.8,0]],"id":41064149}],"con":true,"img":false}]}
{"op":"mcm","clk":"5322052310","pt":1646315854967,"mc":[{"id":"1.195532854","rc":[{"atl":[[4.6,0.43]],"id":41064149}],"con":true,"img":false}]}
{"op":"mcm","clk":"5322052376","pt":1646315855744,"mc":[{"id":"1.195532854","rc":[{"atl":[[11.5,4.07]],"id":42609833}],"con":true,"img":false}]}
{"op":"mcm","clk":"5322052386","pt":1646315855847,"mc":[{"id":"1.195532854","rc":[{"atl":[[12,9.09]],"id":42609833}],"con":true,"img":false}]}
{"op":"mcm","clk":"5322052394","pt":1646315855947,"mc":[{"id":"1.195532854","rc":[{"atl":[[11.5,0.43]],"id":42609833}],"con":true,"img":false}]}
{"op":"mcm","clk":"5322052399","pt":1646315856054,"mc":[{"id":"1.195532854","rc":[{"atl":[[1000,16.15]],"id":42609833}],"con":true,"img":false}]}
{"op":"mcm","clk":"5322052433","pt":1646315856573,"mc":[{"id":"1.195532854","rc":[{"atl":[[1000,15.31]],"id":42609833}],"con":true,"img":false}]}
{"op":"mcm","clk":"5322052459","pt":1646315856836,"mc":[{"id":"1.195532854","rc":[{"atl":[[1000,14.5]],"id":42609833}],"con":true,"img":false}]}
{"op":"mcm","clk":"5322052470","pt":1646315856939,"mc":[{"id":"1.195532854","rc":[{"atl":[[11,2.18]],"id":42609833}],"con":true,"img":false}]}
{"op":"mcm","clk":"5322052480","pt":1646315857051,"mc":[{"id":"1.195532854","rc":[{"atl":[[11,4.37],[12,3.64]],"id":42609833}],"con":true,"img":false}]}
{"op":"mcm","clk":"5322052521","pt":1646315857781,"mc":[{"id":"1.195532854","rc":[{"atl":[[11.5,0]],"id":42609833}],"con":true,"img":false}]}
{"op":"mcm","clk":"5322052530","pt":1646315857878,"mc":[{"id":"1.195532854","rc":[{"atl":[[10.5,0.43]],"id":42609833}],"con":true,"img":false}]}
{"op":"mcm","clk":"5322053692","pt":1646315873371,"mc":[{"id":"1.195532854","rc":[{"atl":[[11,3.55]],"id":42609833}],"con":true,"img":false}]}
{"op":"mcm","clk":"5322053700","pt":1646315873470,"mc":[{"id":"1.195532854","rc":[{"atl":[[12,7.64]],"id":42609833}],"con":true,"img":false}]}
{"op":"mcm","clk":"5322053706","pt":1646315873577,"mc":[{"id":"1.195532854","rc":[{"atl":[[11,1.36]],"id":42609833}],"con":true,"img":false}]}
{"op":"mcm","clk":"5322053729","pt":1646315873885,"mc":[{"id":"1.195532854","rc":[{"atl":[[10.5,0],[1000,16.15]],"id":42609833}],"con":true,"img":false}]}
{"op":"mcm","clk":"5322053740","pt":1646315873989,"mc":[{"id":"1.195532854","rc":[{"atl":[[11.5,0.43]],"id":42609833}],"con":true,"img":false}]}
{"op":"mcm","clk":"5322053780","pt":1646315874499,"mc":[{"id":"1.195532854","rc":[{"atl":[[1000,15.36]],"id":42609833}],"con":true,"img":false}]}
{"op":"mcm","clk":"5322053804","pt":1646315874764,"mc":[{"id":"1.195532854","rc":[{"atl":[[1000,14.5]],"id":42609833}],"con":true,"img":false}]}
{"op":"mcm","clk":"5322053815","pt":1646315874867,"mc":[{"id":"1.195532854","rc":[{"atl":[[10.5,0.86]],"id":42609833}],"con":true,"img":false}]}
{"op":"mcm","clk":"5322054397","pt":1646315882074,"mc":[{"id":"1.195532854","rc":[{"atb":[[1.04,2.85]],"id":28603686},{"atb":[[1.04,2.85]],"id":38833999},{"atb":[[1.04,2.84]],"id":42190933},{"atb":[[1.03,2.92]],"id":41064149}],"con":true,"img":false}]}
{"op":"mcm","clk":"5322054431","pt":1646315882601,"mc":[{"id":"1.195532854","rc":[{"atb":[[1.04,0.12]],"id":28603686},{"atb":[[1.04,0.12]],"id":38833999},{"atb":[[1.04,0.1]],"id":42190933},{"atb":[[1.03,0.19]],"id":41064149}],"con":true,"img":false}]}
{"op":"mcm","clk":"5322054475","pt":1646315883067,"mc":[{"id":"1.195532854","rc":[{"atb":[[1.04,0]],"id":28603686},{"atb":[[1.04,0]],"id":38833999},{"atb":[[1.04,0]],"id":42190933},{"atb":[[1.03,0]],"id":41064149}],"con":true,"img":false}]}
{"op":"mcm","clk":"5322054484","pt":1646315883178,"mc":[{"id":"1.195532854","rc":[{"atb":[[4.5,0.12]],"id":28603686},{"atb":[[4.3,0.12]],"id":38833999},{"atb":[[4.9,0.33]],"id":42190933},{"atb":[[2.74,0.19]],"id":41064149}],"con":true,"img":false}]}
{"op":"mcm","clk":"5322054801","pt":1646315887499,"mc":[{"id":"1.195532854","rc":[{"atb":[[4.7,0]],"id":42190933}],"con":true,"img":false}]}
{"op":"mcm","clk":"5322055196","pt":1646315892498,"mc":[{"id":"1.195532854","rc":[{"atb":[[4.6,0]],"id":42609833}],"con":true,"img":false}]}
{"op":"mcm","clk":"5322055599","pt":1646315897510,"mc":[{"id":"1.195532854","rc":[{"atl":[[1000,16.15]],"id":36042605}],"con":true,"img":false}]}
{"op":"mcm","clk":"5322055608","pt":1646315897613,"mc":[{"id":"1.195532854","rc":[{"atb":[[1.03,1.65]],"id":42190933}],"con":true,"img":false}]}
{"op":"mcm","clk":"5322055618","pt":1646315897718,"mc":[{"id":"1.195532854","rc":[{"atl":[[1000,16.15]],"id":42609833}],"con":true,"img":false}]}
{"op":"mcm","clk":"5322055629","pt":1646315897822,"mc":[{"id":"1.195532854","rc":[{"atl":[[1000,16.15]],"id":42190933}],"con":true,"img":false}]}
{"op":"mcm","clk":"5322055639","pt":1646315897925,"mc":[{"id":"1.195532854","rc":[{"atl":[[1000,16.15]],"id":38833999},{"atl":[[1000,16.15]],"id":41064149}],"con":true,"img":false}]}
{"op":"mcm","clk":"5322055648","pt":1646315897980,"mc":[{"id":"1.195532854","rc":[{"atl":[[1000,16.15]],"id":28603686}],"con":true,"img":false}]}
{"op":"mcm","clk":"5322055675","pt":1646315898187,"mc":[{"id":"1.195532854","rc":[{"atb":[[1.03,0.64]],"id":42190933}],"con":true,"img":false}]}
{"op":"mcm","clk":"5322055692","pt":1646315898397,"mc":[{"id":"1.195532854","rc":[{"atl":[[1000,14.76]],"id":36042605}],"con":true,"img":false}]}
{"op":"mcm","clk":"5322055702","pt":1646315898500,"mc":[{"id":"1.195532854","rc":[{"atl":[[1000,14.91]],"id":42609833}],"con":true,"img":false}]}
{"op":"mcm","clk":"5322055706","pt":1646315898605,"mc":[{"id":"1.195532854","rc":[{"atl":[[1000,15.48]],"id":41064149}],"con":true,"img":false}]}
{"op":"mcm","clk":"5322055713","pt":1646315898710,"mc":[{"id":"1.195532854","rc":[{"atl":[[1000,14.87]],"id":38833999}],"con":true,"img":false}]}
{"op":"mcm","clk":"5322055724","pt":1646315898813,"mc":[{"id":"1.195532854","rc":[{"atl":[[1000,14.93]],"id":28603686}],"con":true,"img":false}]}
{"op":"mcm","clk":"5322055730","pt":1646315898921,"mc":[{"id":"1.195532854","rc":[{"atl":[[1000,14.85]],"id":42190933}],"con":true,"img":false}]}
{"op":"mcm","clk":"5322055769","pt":1646315899397,"mc":[{"id":"1.195532854","rc":[{"atb":[[1.03,0]],"id":42190933}],"con":true,"img":false}]}
{"op":"mcm","clk":"5322055773","pt":1646315899501,"mc":[{"id":"1.195532854","rc":[{"atb":[[6.4,0.64]],"id":42190933}],"con":true,"img":false}]}
{"op":"mcm","clk":"5322055818","pt":1646315900024,"mc":[{"id":"1.195532854","rc":[{"atl":[[1000,14.5]],"id":36042605}],"con":true,"img":false}]}
{"op":"mcm","clk":"5322055826","pt":1646315900128,"mc":[{"id":"1.195532854","rc":[{"atl":[[15.5,0.26]],"id":36042605}],"con":true,"img":false}]}
{"op":"mcm","clk":"5322055846","pt":1646315900288,"mc":[{"id":"1.195532854","rc":[{"atl":[[1000,14.5]],"id":42609833}],"con":true,"img":false}]}
{"op":"mcm","clk":"5322055856","pt":1646315900392,"mc":[{"id":"1.195532854","rc":[{"atl":[[10,0.41]],"id":42609833}],"con":true,"img":false}]}
{"op":"mcm","clk":"5322055869","pt":1646315900498,"mc":[{"id":"1.195532854","rc":[{"atl":[[11,3.36],[12,3.64]],"id":42609833}],"con":true,"img":false}]}
{"op":"mcm","clk":"5322055880","pt":1646315900601,"mc":[{"id":"1.195532854","rc":[{"atl":[[1000,14.5]],"id":41064149}],"con":true,"img":false}]}
{"op":"mcm","clk":"5322055889","pt":1646315900705,"mc":[{"id":"1.195532854","rc":[{"atl":[[4.2,0.98]],"id":41064149}],"con":true,"img":false}]}
{"op":"mcm","clk":"5322055899","pt":1646315900819,"mc":[{"id":"1.195532854","rc":[{"atl":[[1000,17.37]],"id":42190933}],"con":true,"img":false}]}
{"op":"mcm","clk":"5322055910","pt":1646315900912,"mc":[{"id":"1.195532854","rc":[{"atl":[[1000,14.5]],"id":38833999},{"atl":[[11.5,0]],"id":42609833},{"atl":[[5.4,3.74],[5,3.74]],"id":41064149}],"con":true,"img":false}]}
{"op":"mcm","clk":"5322055914","pt":1646315901015,"mc":[{"id":"1.195532854","rc":[{"atl":[[11,0.37]],"id":38833999},{"atl":[[10.5,1.29]],"id":42609833},{"atl":[[1000,16.53]],"id":42190933}],"con":true,"img":false}]}
{"op":"mcm","clk":"5322055930","pt":1646315901225,"mc":[{"id":"1.195532854","rc":[{"atl":[[1000,14.5]],"id":28603686}],"con":true,"img":false}]}
{"op":"mcm","clk":"5322055940","pt":1646315901329,"mc":[{"id":"1.195532854","rc":[{"atl":[[9.6,0.43]],"id":28603686}],"con":true,"img":false}]}
{"op":"mcm","clk":"5322055948","pt":1646315901382,"mc":[{"id":"1.195532854","rc":[{"atl":[[1000,14.85]],"id":42190933},{"atl":[[5.4,0]],"id":41064149}],"con":true,"img":false}]}
{"op":"mcm","clk":"5322055962","pt":1646315901487,"mc":[{"id":"1.195532854","rc":[{"atl":[[12,2.6],[1000,14.5]],"id":42190933}],"con":true,"img":false}]}
{"op":"mcm","clk":"5322055972","pt":1646315901593,"mc":[{"id":"1.195532854","rc":[{"atl":[[11.5,0.35],[12.5,5.64]],"id":42190933}],"con":true,"img":false}]}
{"op":"mcm","clk":"5322055981","pt":1646315901697,"mc":[{"id":"1.195532854","rc":[{"atl":[[13,3.28]],"id":42190933}],"con":true,"img":false}]}
{"op":"mcm","clk":"5322055993","pt":1646315901905,"mc":[{"id":"1.195532854","rc":[{"atl":[[5,0]],"id":41064149}],"con":true,"img":false}]}
{"op":"mcm","clk":"5322056009","pt":1646315902219,"mc":[{"id":"1.195532854","rc":[{"atl":[[4.7,2]],"id":41064149}],"con":true,"img":false}]}
{"op":"mcm","clk":"5322056063","pt":1646315903004,"mc":[{"id":"1.195532854","rc":[{"spn":6.21,"spf":2.1,"id":42609833},{"atl":[[12.5,5.2]],"id":42190933},{"spn":8.95,"spf":1.0,"id":42190933},{"atl":[[4.6,0]],"id":41064149},{"spn":2.75,"spf":1.0,"id":41064149}],"con":true,"img":false}]}
{"op":"mcm","clk":"5322056072","pt":1646315903111,"mc":[{"id":"1.195532854","rc":[{"atl":[[11.5,0.8]],"id":42190933},{"atl":[[4.8,0.43]],"id":41064149}],"con":true,"img":false}]}
{"op":"mcm","clk":"5322056211","pt":1646315905195,"mc":[{"id":"1.195532854","rc":[{"atl":[[4.7,4.95]],"id":41064149}],"con":true,"img":false}]}
{"op":"mcm","clk":"5322056462","pt":1646315908731,"mc":[{"id":"1.195532854","rc":[{"atb":[[1.87,0]],"id":42609833}],"con":true,"img":false}]}
{"op":"mcm","clk":"5322057517","pt":1646315923695,"mc":[{"id":"1.195532854","rc":[{"atb":[[6.2,18.61],[7,0]],"id":42609833},{"trd":[[6.2,21.68],[7,0.31]],"ltp":6.2,"tv":21.99,"id":42609833}],"con":true,"img":false}]}
{"op":"mcm","clk":"5322057532","pt":1646315923856,"mc":[{"id":"1.195532854","rc":[{"atb":[[1.02,3.64]],"id":36042605}],"con":true,"img":false}]}
{"op":"mcm","clk":"5322057538","pt":1646315923963,"mc":[{"id":"1.195532854","rc":[{"atb":[[3.85,9.62]],"id":42609833}],"con":true,"img":false}]}
{"op":"mcm","clk":"5322057548","pt":1646315924065,"mc":[{"id":"1.195532854","rc":[{"atb":[[1.02,2.47]],"id":36042605}],"con":true,"img":false}]}
{"op":"mcm","clk":"5322057561","pt":1646315924275,"mc":[{"id":"1.195532854","rc":[{"atb":[[3.85,4.24]],"id":42609833},{"atb":[[1.02,1.99]],"id":36042605}],"con":true,"img":false}]}
{"op":"mcm","clk":"5322057572","pt":1646315924379,"mc":[{"id":"1.195532854","rc":[{"atb":[[8.6,0.48]],"id":36042605}],"con":true,"img":false}]}
{"op":"mcm","clk":"5322057597","pt":1646315924724,"mc":[{"id":"1.195532854","rc":[{"atb":[[8.2,0]],"id":36042605}],"con":true,"img":false}]}
{"op":"mcm","clk":"5322057616","pt":1646315924895,"mc":[{"id":"1.195532854","rc":[{"atb":[[8.8,1.14]],"id":36042605}],"con":true,"img":false}]}
{"op":"mcm","clk":"5322057634","pt":1646315925057,"mc":[{"id":"1.195532854","rc":[{"atb":[[8.6,0],[1.02,3.64]],"id":36042605}],"con":true,"img":false}]}
{"op":"mcm","clk":"5322057654","pt":1646315925269,"mc":[{"id":"1.195532854","rc":[{"atb":[[1.02,2.47]],"id":36042605}],"con":true,"img":false}]}
{"op":"mcm","clk":"5322057668","pt":1646315925477,"mc":[{"id":"1.195532854","rc":[{"atb":[[1.02,1.99]],"id":36042605}],"con":true,"img":false}]}
{"op":"mcm","clk":"5322057673","pt":1646315925583,"mc":[{"id":"1.195532854","rc":[{"atb":[[8.2,0.48]],"id":36042605}],"con":true,"img":false}]}
{"op":"mcm","clk":"5322057801","pt":1646315927458,"mc":[{"id":"1.195532854","rc":[{"atl":[[1000,16.15],[4.2,0]],"id":41064149}],"con":true,"img":false}]}
{"op":"mcm","clk":"5322057826","pt":1646315927768,"mc":[{"id":"1.195532854","rc":[{"atl":[[1000,15.48]],"id":41064149}],"con":true,"img":false}]}
{"op":"mcm","clk":"5322057835","pt":1646315927871,"mc":[{"id":"1.195532854","rc":[{"atl":[[1000,14.5]],"id":41064149}],"con":true,"img":false}]}
{"op":"mcm","clk":"5322057843","pt":1646315927976,"mc":[{"id":"1.195532854","rc":[{"atl":[[4.3,0.98]],"id":41064149}],"con":true,"img":false}]}
{"op":"mcm","clk":"5322057952","pt":1646315929281,"mc":[{"id":"1.195532854","rc":[{"atl":[[9,10]],"id":42609833}],"con":true,"img":false}]}
{"op":"mcm","clk":"5322057965","pt":1646315929490,"mc":[{"id":"1.195532854","rc":[{"atl":[[9.2,12.2],[11,1.36]],"id":42609833}],"con":true,"img":false}]}
{"op":"mcm","clk":"5322058011","pt":1646315930071,"mc":[{"id":"1.195532854","rc":[{"atl":[[10.5,0.86]],"id":42609833}],"con":true,"img":false}]}
{"op":"mcm","clk":"5322058019","pt":1646315930171,"mc":[{"id":"1.195532854","rc":[{"atl":[[8.8,0.43]],"id":42609833}],"con":true,"img":false}]}
{"op":"mcm","clk":"5322058148","pt":1646315932099,"mc":[{"id":"1.195532854","rc":[{"atl":[[10.5,0]],"id":42609833}],"con":true,"img":false}]}
{"op":"mcm","clk":"5322058179","pt":1646315932472,"mc":[{"id":"1.195532854","rc":[{"atl":[[1000,16.15]],"id":42609833}],"con":true,"img":false}]}
{"op":"mcm","clk":"5322058211","pt":1646315932787,"mc":[{"id":"1.195532854","rc":[{"atl":[[1000,15.52]],"id":42609833}],"con":true,"img":false}]}
{"op":"mcm","clk":"5322058243","pt":1646315933199,"mc":[{"id":"1.195532854","rc":[{"atl":[[1000,14.5]],"id":42609833}],"con":true,"img":false}]}
{"op":"mcm","clk":"5322058252","pt":1646315933309,"mc":[{"id":"1.195532854","rc":[{"atl":[[8.8,1.46]],"id":42609833}],"con":true,"img":false}]}
{"op":"mcm","clk":"5322058312","pt":1646315934195,"mc":[{"id":"1.195532854","rc":[{"atb":[[4.7,1.73]],"id":28603686},{"atb":[[4.5,4.24]],"id":38833999},{"atb":[[4.7,1.7]],"id":42190933},{"atb":[[2.68,1.54]],"id":41064149},{"atb":[[5.7,1.64]],"id":36042605}],"con":true,"img":false}]}
{"op":"mcm","clk":"5322058332","pt":1646315934533,"mc":[{"id":"1.195532854","rc":[{"atb":[[3.9,0]],"id":42609833}],"con":true,"img":false}]}
{"op":"mcm","clk":"5322058348","pt":1646315934696,"mc":[{"id":"1.195532854","rc":[{"atb":[[6.2,0]],"id":42609833},{"atl":[[6.2,1.39]],"id":42609833},{"trd":[[6.2,58.9]],"ltp":6.2,"tv":58.9,"id":42609833}],"con":true,"img":false}]}
{"op":"mcm","clk":"5322058354","pt":1646315934795,"mc":[{"id":"1.195532854","rc":[{"atb":[[3.2,2]],"id":42609833}],"con":true,"img":false}]}
{"op":"mcm","clk":"5322058362","pt":1646315934900,"mc":[{"id":"1.195532854","rc":[{"atb":[[1.01,11003.65]],"id":38833999},{"atb":[[3.9,2]],"id":42609833}],"con":true,"img":false}]}
{"op":"mcm","clk":"5322058367","pt":1646315934960,"mc":[{"id":"1.195532854","rc":[{"atb":[[1.01,11002.7]],"id":38833999}],"con":true,"img":false}]}
{"op":"mcm","clk":"5322058379","pt":1646315935166,"mc":[{"id":"1.195532854","rc":[{"atb":[[1.01,11002]],"id":38833999},{"atb":[[3.9,3.72]],"id":42609833}],"con":true,"img":false}]}
{"op":"mcm","clk":"5322058387","pt":1646315935269,"mc":[{"id":"1.195532854","rc":[{"atb":[[5.9,0.7]],"id":38833999}],"con":true,"img":false}]}
{"op":"mcm","clk":"5322058454","pt":1646315936270,"mc":[{"id":"1.195532854","rc":[{"atb":[[1.01,11004.52]],"id":42609833},{"atl":[[4.6,2.52]],"id":41064149}],"con":true,"img":false}]}
{"op":"mcm","clk":"5322058468","pt":1646315936478,"mc":[{"id":"1.195532854","rc":[{"atb":[[1.01,11004.1]],"id":42609833},{"atb":[[2.66,0]],"id":41064149},{"atb":[[5.6,0]],"id":36042605}],"con":true,"img":false}]}
{"op":"mcm","clk":"5322058482","pt":1646315936684,"mc":[{"id":"1.195532854","rc":[{"atb":[[1.01,11002]],"id":42609833}],"con":true,"img":false}]}
{"op":"mcm","clk":"5322058490","pt":1646315936791,"mc":[{"id":"1.195532854","rc":[{"atb":[[3.95,2.1]],"id":42609833}],"con":true,"img":false}]}
{"op":"mcm","clk":"5322058497","pt":1646315936890,"mc":[{"id":"1.195532854","rc":[{"atb":[[3.95,3.75]],"id":42609833}],"con":true,"img":false}]}
{"op":"mcm","clk":"5322058504","pt":1646315936995,"mc":[{"id":"1.195532854","rc":[{"atb":[[1.02,0]],"id":42190933},{"atl":[[4.8,0]],"id":41064149}],"con":true,"img":false}]}
{"op":"mcm","clk":"5322058512","pt":1646315937100,"mc":[{"id":"1.195532854","rc":[{"atb":[[6.2,2.59]],"id":42190933},{"atl":[[4.5,0.43]],"id":41064149}],"con":true,"img":false}]}
{"op":"mcm","clk":"5322058520","pt":1646315937200,"mc":[{"id":"1.195532854","rc":[{"atb":[[3.9,2]],"id":42609833},{"atb":[[2.68,0]],"id":41064149},{"atb":[[5.7,0]],"id":36042605}],"con":true,"img":false}]}
{"op":"mcm","clk":"5322058527","pt":1646315937304,"mc":[{"id":"1.195532854","rc":[{"atb":[[4,1.72],[1.02,0]],"id":42609833},{"atb":[[5.6,1.64]],"id":36042605},{"atb":[[2.66,1.54]],"id":41064149}],"con":true,"img":false}]}
{"op":"mcm","clk":"5322058533","pt":1646315937408,"mc":[{"id":"1.195532854","rc":[{"atb":[[3.95,5.74]],"id":42609833}],"con":true,"img":false}]}
{"op":"mcm","clk":"5322058547","pt":1646315937575,"mc":[{"id":"1.195532854","rc":[{"atb":[[1.02,0]],"id":41064149}],"con":true,"img":false}]}
{"op":"mcm","clk":"5322058554","pt":1646315937675,"mc":[{"id":"1.195532854","rc":[{"atb":[[3,1.99]],"id":41064149}],"con":true,"img":false}]}
{"op":"mcm","clk":"5322058579","pt":1646315937986,"mc":[{"id":"1.195532854","rc":[{"atl":[[9,10]],"id":38833999}],"con":true,"img":false}]}
{"op":"mcm","clk":"5322058598","pt":1646315938195,"mc":[{"id":"1.195532854","rc":[{"atb":[[3.9,0]],"id":42609833}],"con":true,"img":false}]}
{"op":"mcm","clk":"5322058616","pt":1646315938404,"mc":[{"id":"1.195532854","rc":[{"atb":[[4.1,7.29]],"id":42609833},{"atl":[[4.7,2]],"id":41064149}],"con":true,"img":false}]}
{"op":"mcm","clk":"5322058672","pt":1646315939290,"mc":[{"id":"1.195532854","rc":[{"atb":[[4,0]],"id":42609833}],"con":true,"img":false}]}
{"op":"mcm","clk":"5322058684","pt":1646315939394,"mc":[{"id":"1.195532854","rc":[{"atb":[[4.2,1.72]],"id":42609833}],"con":true,"img":false}]}
{"op":"mcm","clk":"5322058707","pt":1646315939702,"mc":[{"id":"1.195532854","rc":[{"atb":[[3.95,3.75]],"id":42609833}],"con":true,"img":false}]}
{"op":"mcm","clk":"5322058715","pt":1646315939807,"mc":[{"id":"1.195532854","rc":[{"atb":[[4.2,3.71]],"id":42609833}],"con":true,"img":false}]}
{"op":"mcm","clk":"5322058728","pt":1646315939913,"mc":[{"id":"1.195532854","rc":[{"atb":[[4.5,28.69],[3.9,0]],"id":28603686},{"atl":[[10,4.92],[10.5,0],[11,9.52],[12,0]],"id":28603686},{"atb":[[4.3,30.42],[3.9,86.21]],"id":38833999},{"atl":[[10.5,10.53],[12,2.1],[13,0],[9.4,4.76]],"id":38833999},{"atb":[[3.8,0],[3.5,98.7],[4,13.16]],"id":42609833},{"atl":[[9.2,0],[12,0],[8.6,5.26],[7.6,10]],"id":42609833},{"atb":[[4,83.33],[4.6,38.89]],"id":42190933},{"atl":[[12.5,8.63],[13,0]],"id":42190933},{"atb":[[2.72,24.39],[2.52,164.47]],"id":41064149},{"atl":[[4.9,0],[4.5,13.86]],"id":41064149},{"atb":[[4.4,0],[3.3,43.48]],"id":36042605},{"atl":[[16.5,2.54],[18,0.04],[18.5,5.71]],"id":36042605}],"con":true,"img":false}]}
{"op":"mcm","clk":"5322058742","pt":1646315940028,"mc":[{"id":"1.195532854","rc":[{"atl":[[10,9.13],[11,0]],"id":28603686},{"atb":[[3.85,2.07]],"id":38833999},{"atb":[[3.35,21.39],[3.45,6.85]],"id":42609833},{"atb":[[3.95,5.75]],"id":42190933}],"con":true,"img":false}]}
{"op":"mcm","clk":"5322058748","pt":1646315940080,"mc":[{"id":"1.195532854","rc":[{"atl":[[9.6,0],[1000,16.15]],"id":28603686},{"atl":[[10.5,0],[9.6,11.63]],"id":38833999},{"atl":[[13.5,3.73]],"id":42190933},{"atb":[[3.3,0],[3.75,36.36]],"id":36042605},{"atl":[[17.5,5.95],[18.5,0]],"id":36042605},{"atb":[[2.82,3.98],[2.72,0]],"id":41064149}],"con":true,"img":false}]}
{"op":"mcm","clk":"5322058756","pt":1646315940184,"mc":[{"id":"1.195532854","rc":[{"atb":[[2.66,0]],"id":41064149}],"con":true,"img":false}]}
{"op":"mcm","clk":"5322058773","pt":1646315940291,"mc":[{"id":"1.195532854","rc":[{"atl":[[1000,14.93]],"id":28603686},{"atb":[[3.85,0]],"id":38833999},{"atb":[[3.45,0]],"id":42609833},{"atb":[[3.95,0]],"id":42190933},{"atb":[[2.74,1.74]],"id":41064149}],"con":true,"img":false}]}
{"op":"mcm","clk":"5322058790","pt":1646315940396,"mc":[{"id":"1.195532854","rc":[{"atl":[[1000,14.5]],"id":28603686},{"atl":[[13.5,0.2]],"id":42190933}],"con":true,"img":false}]}
{"op":"mcm","clk":"5322058799","pt":1646315940504,"mc":[{"id":"1.195532854","rc":[{"atl":[[9.8,1.58]],"id":28603686}],"con":true,"img":false}]}
{"op":"mcm","clk":"5322058811","pt":1646315940599,"mc":[{"id":"1.195532854","rc":[{"atb":[[5.7,19.89]],"id":36042605}],"con":true,"img":false}]}
{"op":"mcm","clk":"5322058835","pt":1646315940809,"mc":[{"id":"1.195532854","rc":[{"atl":[[1000,17.02]],"id":38833999}],"con":true,"img":false}]}
{"op":"mcm","clk":"5322058859","pt":1646315940972,"mc":[{"id":"1.195532854","rc":[{"atl":[[12,1.65],[1000,16.6]],"id":38833999},{"atl":[[8.8,1.02]],"id":42609833},{"atl":[[17.5,5.48]],"id":36042605}],"con":true,"img":false}]}
{"op":"mcm","clk":"5322058866","pt":1646315941083,"mc":[{"id":"1.195532854","rc":[{"atl":[[8.8,0.44]],"id":38833999},{"atl":[[7.4,0.43]],"id":42609833},{"atl":[[16,1.15]],"id":36042605}],"con":true,"img":false}]}
{"op":"mcm","clk":"5322058880","pt":1646315941186,"mc":[{"id":"1.195532854","rc":[{"atl":[[1000,14.5]],"id":38833999},{"atb":[[5.6,0]],"id":36042605},{"atb":[[2.74,0.19]],"id":41064149}],"con":true,"img":false}]}
{"op":"mcm","clk":"5322058888","pt":1646315941291,"mc":[{"id":"1.195532854","rc":[{"atl":[[8.8,2.54]],"id":38833999},{"atb":[[1.01,11003.54]],"id":41064149},{"atb":[[5.8,1.64]],"id":36042605}],"con":true,"img":false}]}
{"op":"mcm","clk":"5322059141","pt":1646315944273,"mc":[{"id":"1.195532854","rc":[{"atb":[[5.7,0]],"id":36042605}],"con":true,"img":false}]}
{"op":"mcm","clk":"5322059191","pt":1646315944903,"mc":[{"id":"1.195532854","rc":[{"atb":[[3.95,1.65]],"id":42609833},{"atl":[[4.6,0]],"id":41064149}],"con":true,"img":false}]}
{"op":"mcm","clk":"5322059204","pt":1646315945008,"mc":[{"id":"1.195532854","rc":[{"atl":[[4.7,26.39]],"id":41064149}],"con":true,"img":false}]}
{"op":"mcm","clk":"5322059215","pt":1646315945105,"mc":[{"id":"1.195532854","rc":[{"atl":[[10,4.69],[10.5,4.21]],"id":28603686},{"atl":[[9.2,4.88],[9.4,0]],"id":38833999},{"atl":[[4.5,11.86]],"id":41064149}],"con":true,"img":false}]}
{"op":"mcm","clk":"5322059223","pt":1646315945209,"mc":[{"id":"1.195532854","rc":[{"atl":[[11.5,19.04]],"id":28603686}],"con":true,"img":false}]}
{"op":"mcm","clk":"5322059236","pt":1646315945315,"mc":[{"id":"1.195532854","rc":[{"atl":[[10,0.48]],"id":28603686},{"atb":[[5.8,0]],"id":36042605}],"con":true,"img":false}]}
{"op":"mcm","clk":"5322059246","pt":1646315945417,"mc":[{"id":"1.195532854","rc":[{"atb":[[5.6,1.64]],"id":36042605},{"atl":[[4.4,2.52]],"id":41064149}],"con":true,"img":false}]}
{"op":"mcm","clk":"5322059310","pt":1646315946100,"mc":[{"id":"1.195532854","rc":[{"atl":[[4.5,11.43]],"id":41064149}],"con":true,"img":false}]}
{"op":"mcm","clk":"5322059319","pt":1646315946208,"mc":[{"id":"1.195532854","rc":[{"atl":[[4.3,1.42]],"id":41064149}],"con":true,"img":false}]}
{"op":"mcm","clk":"5322059496","pt":1646315948405,"mc":[{"id":"1.195532854","rc":[{"atl":[[8.8,0]],"id":42609833}],"con":true,"img":false}]}
{"op":"mcm","clk":"5322059542","pt":1646315948922,"mc":[{"id":"1.195532854","rc":[{"atl":[[1000,16.15]],"id":42609833}],"con":true,"img":false}]}
{"op":"mcm","clk":"5322059554","pt":1646315949033,"mc":[{"id":"1.195532854","rc":[{"atl":[[10.5,14.74],[11.5,9.52]],"id":28603686}],"con":true,"img":false}]}
{"op":"mcm","clk":"5322059581","pt":1646315949299,"mc":[{"id":"1.195532854","rc":[{"atb":[[1.9,0]],"id":42609833}],"con":true,"img":false}]}
{"op":"mcm","clk":"5322059594","pt":1646315949408,"mc":[{"id":"1.195532854","rc":[{"atl":[[1000,15.71]],"id":42609833}],"con":true,"img":false}]}
{"op":"mcm","clk":"5322059619","pt":1646315949710,"mc":[{"id":"1.195532854","rc":[{"atl":[[1000,14.5]],"id":42609833}],"con":true,"img":false}]}
{"op":"mcm","clk":"5322059626","pt":1646315949818,"mc":[{"id":"1.195532854","rc":[{"atl":[[7.4,1.65]],"id":42609833}],"con":true,"img":false}]}
{"op":"mcm","clk":"5322059636","pt":1646315949923,"mc":[{"id":"1.195532854","rc":[{"atb":[[3.9,34.04]],"id":42609833},{"atl":[[9,22.5]],"id":42609833},{"atl":[[4.7,53.42]],"id":41064149},{"atl":[[17.5,11.45]],"id":36042605}],"con":true,"img":false}]}
{"op":"mcm","clk":"5322059715","pt":1646315950601,"mc":[{"id":"1.195532854","rc":[{"atb":[[4.1,2]],"id":42609833}],"con":true,"img":false}]}
{"op":"mcm","clk":"5322059786","pt":1646315951225,"mc":[{"id":"1.195532854","rc":[{"atb":[[4.2,1.99]],"id":42609833}],"con":true,"img":false}]}
{"op":"mcm","clk":"5322059791","pt":1646315951279,"mc":[{"id":"1.195532854","rc":[{"atb":[[4.1,3.72]],"id":42609833}],"con":true,"img":false}]}
{"op":"mcm","clk":"5322059941","pt":1646315953213,"mc":[{"id":"1.195532854","rc":[{"atl":[[4.4,0]],"id":41064149}],"con":true,"img":false}]}
{"op":"mcm","clk":"5322059997","pt":1646315953899,"mc":[{"id":"1.195532854","rc":[{"atl":[[4.3,12.85],[4.7,29.03]],"id":41064149}],"con":true,"img":false}]}
{"op":"mcm","clk":"5322060004","pt":1646315954005,"mc":[{"id":"1.195532854","rc":[{"atl":[[4.3,12.41],[5.2,6.1]],"id":41064149}],"con":true,"img":false}]}
{"op":"mcm","clk":"5322060012","pt":1646315954110,"mc":[{"id":"1.195532854","rc":[{"atl":[[4.3,0.98],[4.4,0.43],[4.7,53.42]],"id":41064149}],"con":true,"img":false}]}
{"op":"mcm","clk":"5322060030","pt":1646315954316,"mc":[{"id":"1.195532854","rc":[{"atl":[[4.5,35.82],[4.7,29.03]],"id":41064149}],"con":true,"img":false}]}
{"op":"mcm","clk":"5322060047","pt":1646315954528,"mc":[{"id":"1.195532854","rc":[{"atl":[[5.2,0]],"id":41064149}],"con":true,"img":false}]}
{"op":"mcm","clk":"5322060108","pt":1646315955115,"mc":[{"id":"1.195532854","rc":[{"atl":[[9.6,23.26]],"id":38833999}],"con":true,"img":false}]}
{"op":"mcm","clk":"5322060165","pt":1646315955631,"mc":[{"id":"1.195532854","rc":[{"atl":[[4.3,3.5]],"id":41064149}],"con":true,"img":false}]}
{"op":"mcm","clk":"5322060180","pt":1646315955791,"mc":[{"id":"1.195532854","rc":[{"atl":[[4.3,7.01],[4.5,11.43]],"id":41064149}],"con":true,"img":false}]}
{"op":"mcm","clk":"5322060199","pt":1646315955999,"mc":[{"id":"1.195532854","rc":[{"atl":[[12,0]],"id":38833999},{"atb":[[3.95,0]],"id":42609833},{"atl":[[4.4,0]],"id":41064149}],"con":true,"img":false}]}
{"op":"mcm","clk":"5322060206","pt":1646315956106,"mc":[{"id":"1.195532854","rc":[{"atl":[[4.2,0.43]],"id":41064149}],"con":true,"img":false}]}
{"op":"mcm","clk":"5322060237","pt":1646315956522,"mc":[{"id":"1.195532854","rc":[{"atb":[[4.3,1.65]],"id":42609833}],"con":true,"img":false}]}
{"op":"mcm","clk":"5322060271","pt":1646315956898,"mc":[{"id":"1.195532854","rc":[{"atb":[[4.1,1.72]],"id":42609833}],"con":true,"img":false}]}
{"op":"mcm","clk":"5322060335","pt":1646315957632,"mc":[{"id":"1.195532854","rc":[{"atb":[[4.2,0]],"id":42609833}],"con":true,"img":false}]}
{"op":"mcm","clk":"5322060347","pt":1646315957738,"mc":[{"id":"1.195532854","rc":[{"atb":[[4.1,3.71]],"id":42609833}],"con":true,"img":false}]}
{"op":"mcm","clk":"5322060351","pt":1646315957798,"mc":[{"id":"1.195532854","rc":[{"atb":[[4.4,2]],"id":42609833}],"con":true,"img":false}]}
{"op":"mcm","clk":"5322060450","pt":1646315958705,"mc":[{"id":"1.195532854","rc":[{"atb":[[4.1,1.72]],"id":42609833}],"con":true,"img":false}]}
{"op":"mcm","clk":"5322060456","pt":1646315958810,"mc":[{"id":"1.195532854","rc":[{"atb":[[4.5,1.99]],"id":42609833}],"con":true,"img":false}]}
{"op":"mcm","clk":"5322060575","pt":1646315959920,"mc":[{"id":"1.195532854","rc":[{"atb":[[4,0],[4.1,14.46]],"id":42609833},{"atl":[[13,0],[14,0],[15,0],[9.4,17.86]],"id":42609833},{"atl":[[5.3,0],[4.4,11.76],[4.5,0],[5.1,0],[4.6,4.99],[5.5,0],[4.7,2]],"id":41064149},{"atl":[[18.5,8.45],[19,0],[20,0],[22,0]],"id":36042605}],"con":true,"img":false}]}
{"op":"mcm","clk":"5322060651","pt":1646315960809,"mc":[{"id":"1.195532854","rc":[{"atl":[[4.6,0]],"id":41064149}],"con":true,"img":false}]}
{"op":"mcm","clk":"5322061034","pt":1646315965137,"mc":[{"id":"1.195532854","rc":[{"atl":[[10,16.67],[16,0]],"id":38833999},{"spn":7.35,"spf":1.0,"id":38833999},{"spn":4.35,"spf":2.1,"id":42609833},{"spn":2.88,"spf":1.0,"id":41064149},{"spn":9.3,"spf":1.0,"id":36042605}],"con":true,"img":false}]}
{"op":"mcm","clk":"5322061053","pt":1646315965344,"mc":[{"id":"1.195532854","rc":[{"atb":[[4.2,12.34]],"id":42609833},{"atl":[[17.5,5.97],[17,6.25]],"id":36042605}],"con":true,"img":false}]}
{"op":"mcm","clk":"5322061064","pt":1646315965404,"mc":[{"id":"1.195532854","rc":[{"atl":[[15,0]],"id":38833999},{"atb":[[4,4.56],[4.1,1.72]],"id":42609833}],"con":true,"img":false}]}
{"op":"mcm","clk":"5322061129","pt":1646315966339,"mc":[{"id":"1.195532854","rc":[{"atb":[[4.1,0]],"id":42609833}],"con":true,"img":false}]}
{"op":"mcm","clk":"5322061138","pt":1646315966442,"mc":[{"id":"1.195532854","rc":[{"atb":[[4.3,3.37]],"id":42609833}],"con":true,"img":false}]}
{"op":"mcm","clk":"5322061173","pt":1646315966815,"mc":[{"id":"1.195532854","rc":[{"atb":[[4,0]],"id":42609833}],"con":true,"img":false}]}
{"op":"mcm","clk":"5322061429","pt":1646315969905,"mc":[{"id":"1.195532854","rc":[{"atl":[[19.5,13.32]],"id":36042605},{"atl":[[4.6,27.78]],"id":41064149}],"con":true,"img":false}]}
{"op":"mcm","clk":"5322061785","pt":1646315975138,"mc":[{"id":"1.195532854","rc":[{"atl":[[11,25.37]],"id":38833999}],"con":true,"img":false}]}
{"op":"mcm","clk":"5322061807","pt":1646315975351,"mc":[{"id":"1.195532854","rc":[{"atb":[[3.5,0],[4,32.9]],"id":42609833},{"atl":[[9.8,28.41]],"id":42609833}],"con":true,"img":false}]}
{"op":"mcm","clk":"5322062176","pt":1646315979931,"mc":[{"id":"1.195532854","rc":[{"atl":[[4.8,39.47]],"id":41064149}],"con":true,"img":false}]}
{"op":"mcm","clk":"5322062642","pt":1646315985268,"mc":[{"id":"1.195532854","rc":[{"atl":[[14,0]],"id":38833999}],"con":true,"img":false}]}
{"op":"mcm","clk":"5322062653","pt":1646315985370,"mc":[{"id":"1.195532854","rc":[{"atb":[[3.6,0],[3.85,8.44],[3.9,51.05]],"id":42609833}],"con":true,"img":false}]}
{"op":"mcm","clk":"5322062665","pt":1646315985474,"mc":[{"id":"1.195532854","rc":[{"atb":[[3.85,4.24]],"id":42609833}],"con":true,"img":false}]}
{"op":"mcm","clk":"5322063058","pt":1646315989967,"mc":[{"id":"1.195532854","rc":[{"atb":[[2.7,0]],"id":28603686},{"atb":[[3,0]],"id":38833999},{"atb":[[3.2,0]],"id":42190933},{"atl":[[5,62.5]],"id":41064149}],"con":true,"img":false}]}
{"op":"mcm","clk":"5322063956","pt":1646315995381,"mc":[{"id":"1.195532854","rc":[{"atb":[[3.8,88.13]],"id":42609833}],"con":true,"img":false}]}
{"op":"mcm","clk":"5322064796","pt":1646316001979,"mc":[{"id":"1.195532854","rc":[{"atb":[[4.2,50.76]],"id":42190933}],"con":true,"img":false}]}
{"op":"mcm","clk":"5322064821","pt":1646316002189,"mc":[{"id":"1.195532854","rc":[{"atb":[[2.94,6.4]],"id":28603686}],"con":true,"img":false}]}
{"op":"mcm","clk":"5322064828","pt":1646316002304,"mc":[{"id":"1.195532854","rc":[{"atb":[[3.2,5.64]],"id":38833999}],"con":true,"img":false}]}
{"op":"mcm","clk":"5322064881","pt":1646316002600,"mc":[{"id":"1.195532854","rc":[{"atb":[[2.58,4.99]],"id":41064149}],"con":true,"img":false}]}
{"op":"mcm","clk":"5322064946","pt":1646316003096,"mc":[{"id":"1.195532854","rc":[{"atb":[[2.58,0]],"id":41064149}],"con":true,"img":false}]}
{"op":"mcm","clk":"5322064988","pt":1646316003363,"mc":[{"id":"1.195532854","rc":[{"atb":[[3,12.99]],"id":41064149}],"con":true,"img":false}]}
{"op":"mcm","clk":"5322065018","pt":1646316003562,"mc":[{"id":"1.195532854","rc":[{"atb":[[4.7,3.05]],"id":28603686},{"atb":[[4.5,5.64]],"id":38833999},{"atb":[[4.3,4.75]],"id":42609833},{"atb":[[4.7,3.09]],"id":42190933},{"atb":[[2.66,1.3]],"id":41064149},{"atb":[[5.6,2.93]],"id":36042605}],"con":true,"img":false}]}
{"op":"mcm","clk":"5322065248","pt":1646316005401,"mc":[{"id":"1.195532854","rc":[{"atb":[[3.7,0]],"id":42609833}],"con":true,"img":false}]}
{"op":"mcm","clk":"5322065253","pt":1646316005496,"mc":[{"id":"1.195532854","rc":[{"atb":[[2.98,0]],"id":41064149}],"con":true,"img":false}]}
{"op":"mcm","clk":"5322065339","pt":1646316006289,"mc":[{"id":"1.195532854","rc":[{"atl":[[15.5,11.26]],"id":36042605}],"con":true,"img":false}]}
{"op":"mcm","clk":"5322065362","pt":1646316006500,"mc":[{"id":"1.195532854","rc":[{"atb":[[1.01,11002]],"id":41064149}],"con":true,"img":false}]}
{"op":"mcm","clk":"5322065371","pt":1646316006604,"mc":[{"id":"1.195532854","rc":[{"atb":[[3.05,1.54]],"id":41064149}],"con":true,"img":false}]}
{"op":"mcm","clk":"5322065487","pt":1646316007699,"mc":[{"id":"1.195532854","rc":[{"atb":[[3.95,5.69]],"id":38833999}],"con":true,"img":false}]}
{"op":"mcm","clk":"5322065511","pt":1646316007867,"mc":[{"id":"1.195532854","rc":[{"atl":[[9.4,11.9]],"id":38833999}],"con":true,"img":false}]}
{"op":"mcm","clk":"5322065522","pt":1646316007980,"mc":[{"id":"1.195532854","rc":[{"atl":[[9.6,11.63]],"id":38833999}],"con":true,"img":false}]}
{"op":"mcm","clk":"5322065540","pt":1646316008180,"mc":[{"id":"1.195532854","rc":[{"atb":[[3.95,0]],"id":38833999}],"con":true,"img":false}]}
{"op":"mcm","clk":"5322066589","pt":1646316019413,"mc":[{"id":"1.195532854","rc":[{"atb":[[4.3,3.09]],"id":42609833}],"con":true,"img":false}]}
{"op":"mcm","clk":"5322066640","pt":1646316019786,"mc":[{"id":"1.195532854","rc":[{"atb":[[4.6,1.65]],"id":42609833}],"con":true,"img":false}]}
{"op":"mcm","clk":"5322066670","pt":1646316020090,"mc":[{"id":"1.195532854","rc":[{"atb":[[4.4,0]],"id":42609833}],"con":true,"img":false}]}
{"op":"mcm","clk":"5322066773","pt":1646316021083,"mc":[{"id":"1.195532854","rc":[{"atb":[[4.5,0]],"id":42609833}],"con":true,"img":false}]}
{"op":"mcm","clk":"5322066785","pt":1646316021191,"mc":[{"id":"1.195532854","rc":[{"atb":[[4.4,1.99]],"id":42609833}],"con":true,"img":false}]}
{"op":"mcm","clk":"5322066799","pt":1646316021293,"mc":[{"id":"1.195532854","rc":[{"atb":[[4.7,2]],"id":42609833}],"con":true,"img":false}]}
{"op":"mcm","clk":"5322066814","pt":1646316021500,"mc":[{"id":"1.195532854","rc":[{"atb":[[4.2,15.67]],"id":42609833}],"con":true,"img":false}]}
{"op":"mcm","clk":"5322066822","pt":1646316021606,"mc":[{"id":"1.195532854","rc":[{"atb":[[4.2,12.34]],"id":42609833}],"con":true,"img":false}]}
{"op":"mcm","clk":"5322066970","pt":1646316023270,"mc":[{"id":"1.195532854","rc":[{"atb":[[4.4,0]],"id":42609833}],"con":true,"img":false}]}
{"op":"mcm","clk":"5322066981","pt":1646316023384,"mc":[{"id":"1.195532854","rc":[{"atb":[[4.8,1.99]],"id":42609833}],"con":true,"img":false}]}
{"op":"mcm","clk":"5322067088","pt":1646316024588,"mc":[{"id":"1.195532854","rc":[{"atb":[[4.7,0]],"id":42609833}],"con":true,"img":false}]}
{"op":"mcm","clk":"5322067188","pt":1646316025717,"mc":[{"id":"1.195532854","rc":[{"atb":[[4.8,0]],"id":42609833},{"spn":4.34,"spf":2.1,"id":42609833},{"spn":3.0,"spf":1.0,"id":41064149}],"con":true,"img":false}]}
{"op":"mcm","clk":"5322067199","pt":1646316025785,"mc":[{"id":"1.195532854","rc":[{"atb":[[4.7,1.99]],"id":42609833}],"con":true,"img":false}]}
{"op":"mcm","clk":"5322067215","pt":1646316025887,"mc":[{"id":"1.195532854","rc":[{"atb":[[4.3,15.05],[4.2,0],[4.7,3.99]],"id":42609833}],"con":true,"img":false}]}
{"op":"mcm","clk":"5322067232","pt":1646316026093,"mc":[{"id":"1.195532854","rc":[{"atb":[[4.1,3.02]],"id":42609833}],"con":true,"img":false}]}
{"op":"mcm","clk":"5322067248","pt":1646316026296,"mc":[{"id":"1.195532854","rc":[{"atb":[[4.1,0]],"id":42609833}],"con":true,"img":false}]}
{"op":"mcm","clk":"5322067298","pt":1646316026814,"mc":[{"id":"1.195532854","rc":[{"atb":[[1.01,11004.52]],"id":42609833}],"con":true,"img":false}]}
{"op":"mcm","clk":"5322067319","pt":1646316027025,"mc":[{"id":"1.195532854","rc":[{"atb":[[1.01,11004.1]],"id":42609833}],"con":true,"img":false}]}
{"op":"mcm","clk":"5322067340","pt":1646316027181,"mc":[{"id":"1.195532854","rc":[{"atb":[[1.01,11002]],"id":42609833}],"con":true,"img":false}]}
{"op":"mcm","clk":"5322067353","pt":1646316027314,"mc":[{"id":"1.195532854","rc":[{"atb":[[4.8,2.1]],"id":42609833}],"con":true,"img":false}]}
{"op":"mcm","clk":"5322067442","pt":1646316028220,"mc":[{"id":"1.195532854","rc":[{"atb":[[4.7,2]],"id":42609833}],"con":true,"img":false}]}
{"op":"mcm","clk":"5322067455","pt":1646316028324,"mc":[{"id":"1.195532854","rc":[{"atb":[[4.9,1.99]],"id":42609833}],"con":true,"img":false}]}
{"op":"mcm","clk":"5322067543","pt":1646316029425,"mc":[{"id":"1.195532854","rc":[{"atb":[[4.7,0]],"id":42609833}],"con":true,"img":false}]}
{"op":"mcm","clk":"5322067823","pt":1646316032800,"mc":[{"id":"1.195532854","rc":[{"atb":[[3,1.99]],"id":41064149}],"con":true,"img":false}]}
{"op":"mcm","clk":"5322067831","pt":1646316032907,"mc":[{"id":"1.195532854","rc":[{"atb":[[3.05,12.54]],"id":41064149}],"con":true,"img":false}]}
{"op":"mcm","clk":"5322067845","pt":1646316033019,"mc":[{"id":"1.195532854","rc":[{"atb":[[3.6,19.31],[4.3,3.09],[3.35,0],[4.4,11.61]],"id":42609833}],"con":true,"img":false}]}
{"op":"mcm","clk":"5322067902","pt":1646316033524,"mc":[{"id":"1.195532854","rc":[{"atb":[[3,0]],"id":41064149}],"con":true,"img":false}]}
{"op":"mcm","clk":"5322067913","pt":1646316033629,"mc":[{"id":"1.195532854","rc":[{"atb":[[3.1,1.99]],"id":41064149}],"con":true,"img":false}]}
{"op":"mcm","clk":"5322067924","pt":1646316033690,"mc":[{"id":"1.195532854","rc":[{"atb":[[4.1,5.75]],"id":42190933}],"con":true,"img":false}]}
{"op":"mcm","clk":"5322067935","pt":1646316033799,"mc":[{"id":"1.195532854","rc":[{"atb":[[2.8,3.99]],"id":41064149}],"con":true,"img":false}]}
{"op":"mcm","clk":"5322067947","pt":1646316033900,"mc":[{"id":"1.195532854","rc":[{"atb":[[4.1,4.47]],"id":28603686},{"atb":[[4.1,0]],"id":42190933}],"con":true,"img":false}]}
{"op":"mcm","clk":"5322067998","pt":1646316034415,"mc":[{"id":"1.195532854","rc":[{"atb":[[4.1,0]],"id":28603686},{"atb":[[4.8,0]],"id":42609833}],"con":true,"img":false}]}
{"op":"mcm","clk":"5322068062","pt":1646316035190,"mc":[{"id":"1.195532854","rc":[{"atb":[[4.9,0]],"id":42609833},{"atl":[[16,0.68]],"id":36042605}],"con":true,"img":false}]}
{"op":"mcm","clk":"5322068072","pt":1646316035295,"mc":[{"id":"1.195532854","rc":[{"atb":[[4.7,1.99]],"id":42609833},{"atl":[[15,0.47]],"id":36042605}],"con":true,"img":false}]}
{"op":"mcm","clk":"5322068084","pt":1646316035402,"mc":[{"id":"1.195532854","rc":[{"atb":[[4.7,3.99]],"id":42609833},{"atl":[[16.5,8.51],[17,0]],"id":36042605}],"con":true,"img":false}]}
{"op":"mcm","clk":"5322068098","pt":1646316035605,"mc":[{"id":"1.195532854","rc":[{"atb":[[8.8,0]],"id":36042605}],"con":true,"img":false}]}
{"op":"mcm","clk":"5322068111","pt":1646316035807,"mc":[{"id":"1.195532854","rc":[{"atb":[[8.6,1.17]],"id":36042605},{"atb":[[2.8,0]],"id":41064149}],"con":true,"img":false}]}
{"op":"mcm","clk":"5322068118","pt":1646316035915,"mc":[{"id":"1.195532854","rc":[{"atl":[[16,3.31],[16.5,5.97]],"id":36042605}],"con":true,"img":false}]}
{"op":"mcm","clk":"5322068190","pt":1646316036799,"mc":[{"id":"1.195532854","rc":[{"atb":[[8.6,12.17]],"id":36042605}],"con":true,"img":false}]}
{"op":"mcm","clk":"5322068366","pt":1646316038887,"mc":[{"id":"1.195532854","rc":[{"atb":[[4.7,1.99]],"id":42609833},{"atb":[[2.74,7.91]],"id":41064149}],"con":true,"img":false}]}
{"op":"mcm","clk":"5322068389","pt":1646316039098,"mc":[{"id":"1.195532854","rc":[{"atb":[[4.3,15.05],[4.4,0]],"id":42609833},{"atb":[[2.74,0.19]],"id":41064149},{"atb":[[3.75,0],[4.1,32.26]],"id":36042605}],"con":true,"img":false}]}
{"op":"mcm","clk":"5322068501","pt":1646316040394,"mc":[{"id":"1.195532854","rc":[{"atb":[[4.7,4.54]],"id":42609833}],"con":true,"img":false}]}
{"op":"mcm","clk":"5322068517","pt":1646316040605,"mc":[{"id":"1.195532854","rc":[{"atb":[[8,0]],"id":36042605}],"con":true,"img":false}]}
{"op":"mcm","clk":"5322068660","pt":1646316042324,"mc":[{"id":"1.195532854","rc":[{"atb":[[1.01,11004.52]],"id":42609833}],"con":true,"img":false}]}
{"op":"mcm","clk":"5322068675","pt":1646316042535,"mc":[{"id":"1.195532854","rc":[{"atb":[[1.01,11004.1]],"id":42609833}],"con":true,"img":false}]}
{"op":"mcm","clk":"5322068692","pt":1646316042732,"mc":[{"id":"1.195532854","rc":[{"atb":[[1.01,11002]],"id":42609833}],"con":true,"img":false}]}
{"op":"mcm","clk":"5322068698","pt":1646316042837,"mc":[{"id":"1.195532854","rc":[{"atb":[[4.8,2.1]],"id":42609833}],"con":true,"img":false}]}
{"op":"mcm","clk":"5322068770","pt":1646316043932,"mc":[{"id":"1.195532854","rc":[{"atb":[[4.7,2.55]],"id":42609833}],"con":true,"img":false}]}
{"op":"mcm","clk":"5322068785","pt":1646316044053,"mc":[{"id":"1.195532854","rc":[{"atb":[[4.9,1.99]],"id":42609833}],"con":true,"img":false}]}
{"op":"mcm","clk":"5322068794","pt":1646316044094,"mc":[{"id":"1.195532854","rc":[{"atb":[[4.3,3.09],[4.4,11.61]],"id":42609833}],"con":true,"img":false}]}
{"op":"mcm","clk":"5322068936","pt":1646316045865,"mc":[{"id":"1.195532854","rc":[{"atb":[[4.8,0]],"id":42609833}],"con":true,"img":false}]}
{"op":"mcm","clk":"5322068989","pt":1646316046603,"mc":[{"id":"1.195532854","rc":[{"atb":[[4.9,0]],"id":42609833}],"con":true,"img":false}]}
{"op":"mcm","clk":"5322069000","pt":1646316046707,"mc":[{"id":"1.195532854","rc":[{"atb":[[4.8,1.99]],"id":42609833}],"con":true,"img":false}]}
{"op":"mcm","clk":"5322069092","pt":1646316047789,"mc":[{"id":"1.195532854","rc":[{"atl":[[15.5,11],[1000,16.15]],"id":36042605}],"con":true,"img":false}]}
{"op":"mcm","clk":"5322069116","pt":1646316048101,"mc":[{"id":"1.195532854","rc":[{"atl":[[1000,14.78]],"id":36042605}],"con":true,"img":false}]}
{"op":"mcm","clk":"5322069126","pt":1646316048207,"mc":[{"id":"1.195532854","rc":[{"atl":[[1000,14.5]],"id":36042605}],"con":true,"img":false}]}
{"op":"mcm","clk":"5322069139","pt":1646316048319,"mc":[{"id":"1.195532854","rc":[{"atl":[[14.5,0.28]],"id":36042605}],"con":true,"img":false}]}
{"op":"mcm","clk":"5322069175","pt":1646316048574,"mc":[{"id":"1.195532854","rc":[{"atb":[[8.6,11]],"id":36042605}],"con":true,"img":false}]}
{"op":"mcm","clk":"5322069618","pt":1646316054103,"mc":[{"id":"1.195532854","rc":[{"atb":[[4.2,30.84]],"id":42609833}],"con":true,"img":false}]}
{"op":"mcm","clk":"5322069635","pt":1646316054314,"mc":[{"id":"1.195532854","rc":[{"atb":[[3.8,0]],"id":42609833},{"atl":[[16,6.65],[16.5,0],[15.5,13.72]],"id":36042605}],"con":true,"img":false}]}
{"op":"mcm","clk":"5322070302","pt":1646316062192,"mc":[{"id":"1.195532854","rc":[{"atl":[[15.5,2.72]],"id":36042605}],"con":true,"img":false}]}
{"op":"mcm","clk":"5322070313","pt":1646316062297,"mc":[{"id":"1.195532854","rc":[{"atl":[[14.5,11.28]],"id":36042605}],"con":true,"img":false}]}
{"op":"mcm","clk":"5322070333","pt":1646316062615,"mc":[{"id":"1.195532854","rc":[{"atl":[[15,0]],"id":36042605}],"con":true,"img":false}]}
{"op":"mcm","clk":"5322070340","pt":1646316062718,"mc":[{"id":"1.195532854","rc":[{"atl":[[14,0.47]],"id":36042605}],"con":true,"img":false}]}
{"op":"mcm","clk":"5322070468","pt":1646316064127,"mc":[{"id":"1.195532854","rc":[{"atb":[[4,49.35]],"id":42609833}],"con":true,"img":false}]}
{"op":"mcm","clk":"5322070475","pt":1646316064234,"mc":[{"id":"1.195532854","rc":[{"atb":[[3.95,4.06]],"id":42609833}],"con":true,"img":false}]}
{"op":"mcm","clk":"5322070479","pt":1646316064325,"mc":[{"id":"1.195532854","rc":[{"atl":[[15,2.82],[15.5,0]],"id":36042605}],"con":true,"img":false}]}
{"op":"mcm","clk":"5322070491","pt":1646316064440,"mc":[{"id":"1.195532854","rc":[{"atb":[[3.95,0]],"id":42609833}],"con":true,"img":false}]}
{"op":"mcm","clk":"5322070584","pt":1646316065523,"mc":[{"id":"1.195532854","rc":[{"atb":[[3.05,1.54]],"id":41064149}],"con":true,"img":false}]}
{"op":"mcm","clk":"5322070590","pt":1646316065631,"mc":[{"id":"1.195532854","rc":[{"atb":[[3.1,12.99]],"id":41064149}],"con":true,"img":false}]}
{"op":"mcm","clk":"5322070607","pt":1646316065832,"mc":[{"id":"1.195532854","rc":[{"atb":[[3.05,0]],"id":41064149}],"con":true,"img":false}]}
{"op":"mcm","clk":"5322070612","pt":1646316065937,"mc":[{"id":"1.195532854","rc":[{"atb":[[1.01,11003.54]],"id":41064149}],"con":true,"img":false}]}
{"op":"mcm","clk":"5322071237","pt":1646316074149,"mc":[{"id":"1.195532854","rc":[{"atb":[[3.9,136.14]],"id":42609833}],"con":true,"img":false}]}
{"op":"mcm","clk":"5322071248","pt":1646316074200,"mc":[{"id":"1.195532854","rc":[{"atb":[[3.9,85.09]],"id":42609833}],"con":true,"img":false}]}
{"op":"mcm","clk":"5322071256","pt":1646316074306,"mc":[{"id":"1.195532854","rc":[{"atl":[[16,13.22]],"id":36042605}],"con":true,"img":false}]}
{"op":"mcm","clk":"5322071297","pt":1646316074926,"mc":[{"id":"1.195532854","rc":[{"atb":[[4.3,1.37]],"id":42609833},{"atb":[[1.01,11002]],"id":41064149}],"con":true,"img":false}]}
{"op":"mcm","clk":"5322071301","pt":1646316075030,"mc":[{"id":"1.195532854","rc":[{"atb":[[4.5,1.72]],"id":42609833},{"atb":[[3.15,1.54]],"id":41064149}],"con":true,"img":false}]}
{"op":"mcm","clk":"5322071682","pt":1646316079703,"mc":[{"id":"1.195532854","rc":[{"atb":[[2.74,0]],"id":28603686},{"atb":[[2.78,0]],"id":42609833},{"atb":[[2.6,70.26]],"id":41064149}],"con":true,"img":false}]}
{"op":"mcm","clk":"5322071697","pt":1646316079912,"mc":[{"id":"1.195532854","rc":[{"atl":[[17.5,0],[18.5,0],[19.5,0]],"id":36042605}],"con":true,"img":false}]}
{"op":"mcm","clk":"5322071779","pt":1646316080746,"mc":[{"id":"1.195532854","rc":[{"atb":[[4.6,0]],"id":42609833}],"con":true,"img":false}]}
{"op":"mcm","clk":"5322071818","pt":1646316081114,"mc":[{"id":"1.195532854","rc":[{"atb":[[4.9,1.65]],"id":42609833}],"con":true,"img":false}]}
{"op":"mcm","clk":"5322071880","pt":1646316081634,"mc":[{"id":"1.195532854","rc":[{"atb":[[6.2,0.6]],"id":42190933}],"con":true,"img":false}]}
{"op":"mcm","clk":"5322071892","pt":1646316081740,"mc":[{"id":"1.195532854","rc":[{"atb":[[1.02,1.99]],"id":42190933}],"con":true,"img":false}]}
{"op":"mcm","clk":"5322071921","pt":1646316082050,"mc":[{"id":"1.195532854","rc":[{"atb":[[4.8,0]],"id":42609833}],"con":true,"img":false}]}
{"op":"mcm","clk":"5322071931","pt":1646316082154,"mc":[{"id":"1.195532854","rc":[{"atb":[[1.02,1.99]],"id":42609833}],"con":true,"img":false}]}
{"op":"mcm","clk":"5322071945","pt":1646316082311,"mc":[{"id":"1.195532854","rc":[{"atb":[[3.1,11]],"id":41064149}],"con":true,"img":false}]}
{"op":"mcm","clk":"5322071952","pt":1646316082416,"mc":[{"id":"1.195532854","rc":[{"atb":[[1.02,1.99]],"id":41064149}],"con":true,"img":false}]}
{"op":"mcm","clk":"5322071999","pt":1646316083057,"mc":[{"id":"1.195532854","rc":[{"atb":[[3.05,5.47]],"id":28603686},{"atb":[[3.3,4.87]],"id":42609833}],"con":true,"img":false}]}
{"op":"mcm","clk":"5322072012","pt":1646316083153,"mc":[{"id":"1.195532854","rc":[{"atb":[[2.64,31.23]],"id":41064149}],"con":true,"img":false}]}
{"op":"mcm","clk":"5322072054","pt":1646316083834,"mc":[{"id":"1.195532854","rc":[{"atb":[[1.02,0]],"id":42190933}],"con":true,"img":false}]}
{"op":"mcm","clk":"5322072062","pt":1646316083934,"mc":[{"id":"1.195532854","rc":[{"atb":[[6.2,2.59]],"id":42190933}],"con":true,"img":false}]}
{"op":"mcm","clk":"5322072087","pt":1646316084245,"mc":[{"id":"1.195532854","rc":[{"atb":[[1.02,0]],"id":42609833}],"con":true,"img":false}]}
{"op":"mcm","clk":"5322072093","pt":1646316084349,"mc":[{"id":"1.195532854","rc":[{"atb":[[4.8,1.99]],"id":42609833},{"atl":[[17,9.24]],"id":36042605}],"con":true,"img":false}]}
{"op":"mcm","clk":"5322072264","pt":1646316086440,"mc":[{"id":"1.195532854","rc":[{"spn":4.75,"spf":2.1,"id":42609833},{"atb":[[6.2,0.6]],"id":42190933},{"spn":9.2,"spf":1.0,"id":36042605},{"spn":3.1,"spf":1.0,"id":41064149}],"con":true,"img":false}]}
{"op":"mcm","clk":"5322072272","pt":1646316086546,"mc":[{"id":"1.195532854","rc":[{"atb":[[1.02,1.99]],"id":42190933}],"con":true,"img":false}]}
{"op":"mcm","clk":"5322072302","pt":1646316086805,"mc":[{"id":"1.195532854","rc":[{"atb":[[4.8,0]],"id":42609833}],"con":true,"img":false}]}
{"op":"mcm","clk":"5322072310","pt":1646316086911,"mc":[{"id":"1.195532854","rc":[{"atb":[[1.02,1.99]],"id":42609833}],"con":true,"img":false}]}
{"op":"mcm","clk":"5322072395","pt":1646316088055,"mc":[{"id":"1.195532854","rc":[{"atb":[[1.02,0]],"id":42190933}],"con":true,"img":false}]}
{"op":"mcm","clk":"5322072404","pt":1646316088159,"mc":[{"id":"1.195532854","rc":[{"atb":[[6.2,2.59]],"id":42190933}],"con":true,"img":false}]}
{"op":"mcm","clk":"5322072425","pt":1646316088422,"mc":[{"id":"1.195532854","rc":[{"atb":[[1.02,0]],"id":42609833}],"con":true,"img":false}]}
{"op":"mcm","clk":"5322072430","pt":1646316088525,"mc":[{"id":"1.195532854","rc":[{"atb":[[4.8,1.99]],"id":42609833}],"con":true,"img":false}]}
{"op":"mcm","clk":"5322072545","pt":1646316090142,"mc":[{"id":"1.195532854","rc":[{"atb":[[6.2,0.6]],"id":42190933}],"con":true,"img":false}]}
{"op":"mcm","clk":"5322072555","pt":1646316090244,"mc":[{"id":"1.195532854","rc":[{"atb":[[1.02,1.99]],"id":42190933}],"con":true,"img":false}]}
{"op":"mcm","clk":"5322072580","pt":1646316090558,"mc":[{"id":"1.195532854","rc":[{"atb":[[4.8,0]],"id":42609833}],"con":true,"img":false}]}
{"op":"mcm","clk":"5322072591","pt":1646316090666,"mc":[{"id":"1.195532854","rc":[{"atb":[[1.02,1.99]],"id":42609833}],"con":true,"img":false}]}
{"op":"mcm","clk":"5322072766","pt":1646316092338,"mc":[{"id":"1.195532854","rc":[{"atb":[[1.02,0]],"id":42190933}],"con":true,"img":false}]}
{"op":"mcm","clk":"5322072778","pt":1646316092440,"mc":[{"id":"1.195532854","rc":[{"atb":[[6.2,2.59]],"id":42190933}],"con":true,"img":false}]}
{"op":"mcm","clk":"5322072808","pt":1646316092752,"mc":[{"id":"1.195532854","rc":[{"atb":[[1.02,0]],"id":42609833}],"con":true,"img":false}]}
{"op":"mcm","clk":"5322072817","pt":1646316092855,"mc":[{"id":"1.195532854","rc":[{"atb":[[4.8,1.99]],"id":42609833}],"con":true,"img":false}]}
{"op":"mcm","clk":"5322072926","pt":1646316094268,"mc":[{"id":"1.195532854","rc":[{"atb":[[6.2,0.6]],"id":42190933}],"con":true,"img":false}]}
{"op":"mcm","clk":"5322072934","pt":1646316094364,"mc":[{"id":"1.195532854","rc":[{"atb":[[1.02,1.99]],"id":42190933},{"atl":[[18,14.54]],"id":36042605}],"con":true,"img":false}]}
{"op":"mcm","clk":"5322072954","pt":1646316094569,"mc":[{"id":"1.195532854","rc":[{"atb":[[4.8,0]],"id":42609833}],"con":true,"img":false}]}
{"op":"mcm","clk":"5322072965","pt":1646316094688,"mc":[{"id":"1.195532854","rc":[{"atb":[[1.02,1.99]],"id":42609833}],"con":true,"img":false}]}
{"op":"mcm","clk":"5322072996","pt":1646316095034,"mc":[{"id":"1.195532854","rc":[{"atb":[[2.6,62.5]],"id":41064149}],"con":true,"img":false}]}
{"op":"mcm","clk":"5322073109","pt":1646316095866,"mc":[{"id":"1.195532854","rc":[{"atb":[[1.02,0]],"id":42190933}],"con":true,"img":false}]}
{"op":"mcm","clk":"5322073119","pt":1646316095989,"mc":[{"id":"1.195532854","rc":[{"atb":[[6.2,2.59]],"id":42190933}],"con":true,"img":false}]}
