{"op":"mcm","clk":"5352092081","pt":1646182319001,"mc":[{"id":"1.195503871","marketDefinition":{"bspMarket":false,"turnInPlayEnabled":false,"persistenceEnabled":false,"marketBaseRate":7.0,"eventId":"31272499","eventTypeId":"4339","numberOfWinners":1,"bettingType":"ODDS","marketType":"EXACTA","marketTime":"2022-03-02T12:10:00.000Z","suspendTime":"2022-03-02T12:10:00.000Z","bspReconciled":false,"complete":true,"inPlay":false,"crossMatching":false,"runnersVoidable":false,"numberOfActiveRunners":56,"betDelay":0,"status":"OPEN","runners":[{"status":"ACTIVE","sortPriority":1,"id":41419585,"name":"1 - 2"},{"status":"ACTIVE","sortPriority":2,"id":41419586,"name":"1 - 3"},{"status":"ACTIVE","sortPriority":3,"id":41419587,"name":"1 - 4"},{"status":"ACTIVE","sortPriority":4,"id":41419589,"name":"1 - 6"},{"status":"ACTIVE","sortPriority":5,"id":41419590,"name":"1 - 7"},{"status":"ACTIVE","sortPriority":6,"id":41419591,"name":"1 - 8"},{"status":"ACTIVE","sortPriority":7,"id":28546943,"name":"1 - 9"},{"status":"ACTIVE","sortPriority":8,"id":41419592,"name":"2 - 1"},{"status":"ACTIVE","sortPriority":9,"id":41419593,"name":"2 - 3"},{"status":"ACTIVE","sortPriority":10,"id":41419594,"name":"2 - 4"},{"status":"ACTIVE","sortPriority":11,"id":41419596,"name":"2 - 6"},{"status":"ACTIVE","sortPriority":12,"id":41419597,"name":"2 - 7"},{"status":"ACTIVE","sortPriority":13,"id":41419598,"name":"2 - 8"},{"status":"ACTIVE","sortPriority":14,"id":41419651,"name":"2 - 9"},{"status":"ACTIVE","sortPriority":15,"id":41419599,"name":"3 - 1"},{"status":"ACTIVE","sortPriority":16,"id":41419600,"name":"3 - 2"},{"status":"ACTIVE","sortPriority":17,"id":41419601,"name":"3 - 4"},{"status":"ACTIVE","sortPriority":18,"id":41419603,"name":"3 - 6"},{"status":"ACTIVE","sortPriority":19,"id":41419604,"name":"3 - 7"},{"status":"ACTIVE","sortPriority":20,"id":41419605,"name":"3 - 8"},{"status":"ACTIVE","sortPriority":21,"id":41419652,"name":"3 - 9"},{"status":"ACTIVE","sortPriority":22,"id":41419606,"name":"4 - 1"},{"status":"ACTIVE","sortPriority":23,"id":41419607,"name":"4 - 2"},{"status":"ACTIVE","sortPriority":24,"id":41419608,"name":"4 - 3"},{"status":"ACTIVE","sortPriority":25,"id":41419610,"name":"4 - 6"},{"status":"ACTIVE","sortPriority":26,"id":41419611,"name":"4 - 7"},{"status":"ACTIVE","sortPriority":27,"id":41419612,"name":"4 - 8"},{"status":"ACTIVE","sortPriority":28,"id":41435525,"name":"4 - 9"},{"status":"ACTIVE","sortPriority":29,"id":41419620,"name":"6 - 1"},{"status":"ACTIVE","sortPriority":30,"id":41419621,"name":"6 - 2"},{"status":"ACTIVE","sortPriority":31,"id":41419622,"name":"6 - 3"},{"status":"ACTIVE","sortPriority":32,"id":41419623,"name":"6 - 4"},{"status":"ACTIVE","sortPriority":33,"id":41419625,"name":"6 - 7"},{"status":"ACTIVE","sortPriority":34,"id":41419626,"name":"6 - 8"},{"status":"ACTIVE","sortPriority":35,"id":41435526,"name":"6 - 9"},{"status":"ACTIVE","sortPriority":36,"id":41419627,"name":"7 - 1"},{"status":"ACTIVE","sortPriority":37,"id":41419628,"name":"7 - 2"},{"status":"ACTIVE","sortPriority":38,"id":41419629,"name":"7 - 3"},{"status":"ACTIVE","sortPriority":39,"id":41419630,"name":"7 - 4"},{"status":"ACTIVE","sortPriority":40,"id":41419632,"name":"7 - 6"},{"status":"ACTIVE","sortPriority":41,"id":41419633,"name":"7 - 8"},{"status":"ACTIVE","sortPriority":42,"id":41419654,"name":"7 - 9"},{"status":"ACTIVE","sortPriority":43,"id":41419634,"name":"8 - 1"},{"status":"ACTIVE","sortPriority":44,"id":41419635,"name":"8 - 2"},{"status":"ACTIVE","sortPriority":45,"id":41419636,"name":"8 - 3"},{"status":"ACTIVE","sortPriority":46,"id":41419637,"name":"8 - 4"},{"status":"ACTIVE","sortPriority":47,"id":41419639,"name":"8 - 6"},{"status":"ACTIVE","sortPriority":48,"id":41419640,"name":"8 - 7"},{"status":"ACTIVE","sortPriority":49,"id":41419655,"name":"8 - 9"},{"status":"ACTIVE","sortPriority":50,"id":28546950,"name":"9 - 1"},{"status":"ACTIVE","sortPriority":51,"id":41419656,"name":"9 - 2"},{"status":"ACTIVE","sortPriority":52,"id":41419657,"name":"9 - 3"},{"status":"ACTIVE","sortPriority":53,"id":41435527,"name":"9 - 4"},{"status":"ACTIVE","sortPriority":54,"id":41435528,"name":"9 - 6"},{"status":"ACTIVE","sortPriority":55,"id":41419659,"name":"9 - 7"},{"status":"ACTIVE","sortPriority":56,"id":41419660,"name":"9 - 8"}],"regulators":["MR_INT"],"venue":"Rockhampton","countryCode":"AU","discountAllowed":true,"timezone":"Australia/Queensland","openDate":"2022-03-02T08:34:00.000Z","version":4382565148,"name":"Exacta","eventName":"Rockhampton (AUS) 2nd Mar"},"rc":[],"con":true,"img":false}]}
{"op":"mcm","clk":"5352095665","pt":1646182412891,"mc":[{"id":"1.195503871","rc":[{"atb":[[18.5,15.2],[27,7.67],[60,3.38]],"id":41419607},{"atb":[[360,0.55],[210,0.95],[110,2.43]],"id":41419605},{"atb":[[600,0.44],[700,0.28],[850,0.23]],"id":41419603},{"atb":[[42,4.86],[26,10.64],[110,1.82]],"id":41419611},{"atb":[[85,2.37],[44,6.19],[220,0.9]],"id":41419593},{"atb":[[8,28.51],[6,53.22],[12.5,17.35]],"id":41419591},{"atb":[[18,15.65],[26,7.98],[55,3.69]],"id":41435525},{"atb":[[22,9.5],[13.5,15.96],[9.4,31.68]],"id":41419589},{"atb":[[38,5.39],[19.5,10.79],[14.5,19.71]],"id":41419587},{"atb":[[9,24.94],[7,44.35],[15,14.25]],"id":41419651},{"atb":[[600,0.44],[700,0.28],[850,0.23]],"id":41419601},{"atb":[[34,8.06],[170,1.18],[60,3.38]],"id":41419599},{"atb":[[9,33.26],[20,10.5],[12.5,17.35]],"id":41419597},{"atb":[[9.6,23.2],[5.3,61.88],[6.6,35.63]],"id":28546943},{"atb":[[600,0.44],[700,0.28],[850,0.23]],"id":41419608},{"atb":[[16,17.74],[44,4.64],[22,9.5]],"id":41419606},{"atb":[[530,0.37],[280,0.95],[380,0.52]],"id":41419604},{"atb":[[6.8,34.41],[9.8,22.68],[5.4,60.48]],"id":41419585},{"atb":[[70,2.89],[19.5,14.38],[29,7.12]],"id":41419612},{"atb":[[130,1.54],[65,4.15],[280,0.71]],"id":41419610},{"atb":[[5.8,55.43],[11.5,19],[7.6,30.24]],"id":41419592},{"atb":[[16,13.3],[7.4,41.58],[9.4,23.75]],"id":41419590},{"atb":[[270,0.74],[120,1.67],[60,4.5]],"id":41419652},{"atb":[[38,5.39],[95,2.12],[24,11.56]],"id":41419586},{"atb":[[140,1.43],[70,3.85],[290,0.69]],"id":41419600},{"atb":[[8,38.01],[17.5,12.09],[10,22.17]],"id":41419598},{"atb":[[17,12.47],[12,24.19],[29,7.12]],"id":41419596},{"atb":[[17,16.63],[48,4.24],[24,8.67]],"id":41419594}],"con":true,"img":false}]}
{"op":"mcm","clk":"5352095669","pt":1646182412947,"mc":[{"id":"1.195503871","rc":[{"atb":[[8.6,26.26],[14,15.35],[6.6,47.52]],"id":41419634},{"atb":[[8,38.01],[17.5,12.09],[10,22.17]],"id":41419655},{"atb":[[600,0.44],[700,0.28],[850,0.23]],"id":41419622},{"atb":[[17,16.63],[48,4.24],[24,8.67]],"id":41435527},{"atb":[[38,5.39],[95,2.12],[24,11.56]],"id":41419630},{"atb":[[19.5,10.79],[12,18.14],[8.8,34.11]],"id":41419659},{"atb":[[36,5.7],[19,11.08],[14,20.47]],"id":41419626},{"atb":[[32,6.44],[18,11.73],[13,22.17]],"id":41419639},{"atb":[[18,11.73],[10.5,21],[8.2,36.96]],"id":41419635},{"atb":[[9,24.94],[7,44.35],[15,14.25]],"id":41419656},{"atb":[[260,0.77],[110,1.82],[55,4.92]],"id":41419623},{"atb":[[16.5,12.87],[11.5,25.34],[28,7.39]],"id":41435528},{"atb":[[16.5,12.87],[9.6,23.2],[7.6,40.32]],"id":41419660},{"atb":[[18,11.73],[10.5,21],[8.2,36.96]],"id":41419627},{"atb":[[24,8.67],[9.8,30.24],[14.5,14.78]],"id":41419640},{"atb":[[10,22.17],[5.5,59.13],[7,33.26]],"id":28546950},{"atb":[[140,1.43],[70,3.85],[290,0.69]],"id":41419636},{"atb":[[75,2.69],[40,6.82],[200,1]],"id":41419657},{"atb":[[10.5,28.01],[26,7.98],[15.5,13.76]],"id":41419620},{"atb":[[42,4.86],[21,9.97],[15.5,18.35]],"id":41419632},{"atb":[[22,9.5],[13.5,15.96],[9.4,31.68]],"id":41419628},{"atb":[[18.5,15.2],[27,7.67],[60,3.38]],"id":41419637},{"atb":[[16,17.74],[44,4.64],[22,9.5]],"id":41419625},{"atb":[[9.2,32.45],[21,9.97],[13,16.63]],"id":41419654},{"atb":[[17.5,12.09],[12.5,23.13],[30,6.88]],"id":41435526},{"atb":[[32,6.44],[18,11.73],[13,22.17]],"id":41419621},{"atb":[[10,29.56],[25,8.31],[15,14.25]],"id":41419633},{"atb":[[310,0.64],[210,1.27],[460,0.43]],"id":41419629}],"con":true,"img":false}]}
{"op":"mcm","clk":"5352104616","pt":1646182613235,"mc":[{"id":"1.195503871","rc":[{"atb":[[360,0],[210,0],[110,0]],"id":41419605},{"atb":[[85,0],[44,0],[220,0]],"id":41419593},{"atb":[[22,0],[13.5,0],[9.4,0]],"id":41419589},{"atb":[[600,0],[700,0],[850,0]],"id":41419601},{"atb":[[9,0],[20,0],[12.5,0]],"id":41419597},{"atb":[[9.6,0],[5.3,0],[6.6,0]],"id":28546943},{"atb":[[6.8,0],[9.8,0],[5.4,0]],"id":41419585},{"atb":[[16,0],[7.4,0],[9.4,0]],"id":41419590},{"atb":[[38,0],[95,0],[24,0]],"id":41419586},{"atb":[[8,0],[17.5,0],[10,0]],"id":41419598},{"atb":[[17,0],[48,0],[24,0]],"id":41419594},{"atb":[[10,0],[5.5,0],[7,0]],"id":28546950},{"atb":[[600,0],[700,0],[850,0]],"id":41419603},{"atb":[[8,0],[6,0],[12.5,0]],"id":41419591},{"atb":[[38,0],[19.5,0],[14.5,0]],"id":41419587},{"atb":[[34,0],[170,0],[60,0]],"id":41419599},{"atb":[[530,0],[280,0],[380,0]],"id":41419604},{"atb":[[5.8,0],[11.5,0],[7.6,0]],"id":41419592},{"atb":[[140,0],[70,0],[290,0]],"id":41419600},{"atb":[[17,0],[12,0],[29,0]],"id":41419596}],"con":true,"img":false}]}
{"op":"mcm","clk":"5352104624","pt":1646182613395,"mc":[{"id":"1.195503871","rc":[{"atb":[[8.6,0],[14,0],[6.6,0]],"id":41419634},{"atb":[[600,0],[700,0],[850,0]],"id":41419622},{"atb":[[38,0],[95,0],[24,0]],"id":41419630},{"atb":[[36,0],[19,0],[14,0]],"id":41419626},{"atb":[[16,0],[44,0],[22,0]],"id":41419606},{"atb":[[18,0],[10.5,0],[8.2,0]],"id":41419635},{"atb":[[130,0],[65,0],[280,0]],"id":41419610},{"atb":[[260,0],[110,0],[55,0]],"id":41419623},{"atb":[[18,0],[10.5,0],[8.2,0]],"id":41419627},{"atb":[[18.5,0],[27,0],[60,0]],"id":41419607},{"atb":[[42,0],[26,0],[110,0]],"id":41419611},{"atb":[[10.5,0],[26,0],[15.5,0]],"id":41419620},{"atb":[[42,0],[21,0],[15.5,0]],"id":41419632},{"atb":[[22,0],[13.5,0],[9.4,0]],"id":41419628},{"atb":[[600,0],[700,0],[850,0]],"id":41419608},{"atb":[[70,0],[19.5,0],[29,0]],"id":41419612},{"atb":[[16,0],[44,0],[22,0]],"id":41419625},{"atb":[[32,0],[18,0],[13,0]],"id":41419621},{"atb":[[10,0],[25,0],[15,0]],"id":41419633},{"atb":[[310,0],[210,0],[460,0]],"id":41419629}],"con":true,"img":false}]}
{"op":"mcm","clk":"5352104630","pt":1646182613500,"mc":[{"id":"1.195503871","rc":[{"atb":[[8,0],[17.5,0],[10,0]],"id":41419655},{"atb":[[17,0],[48,0],[24,0]],"id":41435527},{"atb":[[9,0],[7,0],[15,0]],"id":41419651},{"atb":[[19.5,0],[12,0],[8.8,0]],"id":41419659},{"atb":[[32,0],[18,0],[13,0]],"id":41419639},{"atb":[[9,0],[7,0],[15,0]],"id":41419656},{"atb":[[270,0],[120,0],[60,0]],"id":41419652},{"atb":[[16.5,0],[11.5,0],[28,0]],"id":41435528},{"atb":[[16.5,0],[9.6,0],[7.6,0]],"id":41419660},{"atb":[[24,0],[9.8,0],[14.5,0]],"id":41419640},{"atb":[[140,0],[70,0],[290,0]],"id":41419636},{"atb":[[75,0],[40,0],[200,0]],"id":41419657},{"atb":[[18,0],[26,0],[55,0]],"id":41435525},{"atb":[[18.5,0],[27,0],[60,0]],"id":41419637},{"atb":[[9.2,0],[21,0],[13,0]],"id":41419654},{"atb":[[17.5,0],[12.5,0],[30,0]],"id":41435526}],"con":true,"img":false}]}
{"op":"mcm","clk":"5352105194","pt":1646182624024,"mc":[{"id":"1.195503871","rc":[{"atb":[[130,2.06],[380,0.52],[230,0.87]],"id":41419605},{"atb":[[6.8,45.88],[8.8,25.58],[14.5,14.78]],"id":41419634},{"atb":[[80,2.52],[42,6.48],[210,0.95]],"id":41419593},{"atb":[[18,11.73],[10.5,21],[8.2,36.96]],"id":41419655},{"atb":[[600,0.44],[700,0.28],[850,0.23]],"id":41419622},{"atb":[[22,9.5],[13.5,15.96],[9.4,31.68]],"id":41419589},{"atb":[[16.5,17.17],[46,4.43],[23,9.07]],"id":41435527},{"atb":[[9,24.94],[7,44.35],[15,14.25]],"id":41419651},{"atb":[[600,0.44],[700,0.28],[850,0.23]],"id":41419601},{"atb":[[36,5.7],[90,2.24],[23,12.09]],"id":41419630},{"atb":[[9,33.26],[20,10.5],[12.5,17.35]],"id":41419597},{"atb":[[6.4,36.96],[5.2,63.36],[9.4,23.75]],"id":28546943},{"atb":[[19.5,10.79],[12,18.14],[8.8,34.11]],"id":41419659},{"atb":[[38,5.39],[19.5,10.79],[14.5,19.71]],"id":41419626},{"atb":[[34,6.04],[18.5,11.4],[13.5,21.28]],"id":41419639},{"atb":[[16,17.74],[44,4.64],[22,9.5]],"id":41419606},{"atb":[[18.5,11.4],[11,19.95],[8.4,35.95]],"id":41419635},{"atb":[[6.8,34.41],[9.8,22.68],[5.4,60.48]],"id":41419585},{"atb":[[270,0.74],[120,1.67],[60,4.5]],"id":41419610},{"atb":[[6.8,45.88],[8.8,25.58],[14.5,14.78]],"id":41419656},{"atb":[[100,2.01],[50,5.43],[250,0.8]],"id":41419623},{"atb":[[7.2,42.92],[9.2,24.34],[15.5,13.76]],"id":41419590},{"atb":[[260,0.77],[110,1.82],[55,4.92]],"id":41419652},{"atb":[[16.5,12.87],[11.5,25.34],[28,7.39]],"id":41435528},{"atb":[[38,5.39],[95,2.12],[24,11.56]],"id":41419586},{"atb":[[18,11.73],[10.5,21],[8.2,36.96]],"id":41419598},{"atb":[[8,38.01],[17.5,12.09],[10,22.17]],"id":41419660},{"atb":[[18,11.73],[10.5,21],[8.2,36.96]],"id":41419627},{"atb":[[17,16.63],[48,4.24],[24,8.67]],"id":41419594},{"atb":[[10,29.56],[25,8.31],[15,14.25]],"id":41419640},{"atb":[[18.5,15.2],[27,7.67],[60,3.38]],"id":41419607},{"atb":[[10,22.17],[5.5,59.13],[7,33.26]],"id":28546950},{"atb":[[310,0.64],[160,1.25],[80,3.36]],"id":41419636},{"atb":[[600,0.44],[700,0.28],[850,0.23]],"id":41419603},{"atb":[[40,5.11],[100,2.01],[25,11.08]],"id":41419611},{"atb":[[70,2.89],[38,7.19],[190,1.05]],"id":41419657},{"atb":[[6.2,51.17],[8.2,27.72],[13,16.63]],"id":41419591},{"atb":[[18,15.65],[26,7.98],[55,3.69]],"id":41435525},{"atb":[[10.5,28.01],[26,7.98],[15.5,13.76]],"id":41419620},{"atb":[[36,5.7],[19,11.08],[14,20.47]],"id":41419587},{"atb":[[42,4.86],[21,9.97],[15.5,18.35]],"id":41419632},{"atb":[[32,8.58],[160,1.25],[55,3.69]],"id":41419599},{"atb":[[9.2,32.45],[21,9.97],[13,16.63]],"id":41419628},{"atb":[[600,0.44],[700,0.28],[850,0.23]],"id":41419608},{"atb":[[65,3.11],[19,14.78],[28,7.39]],"id":41419637},{"atb":[[520,0.38],[270,0.99],[370,0.53]],"id":41419604},{"atb":[[75,2.69],[20,14],[30,6.88]],"id":41419612},{"atb":[[16,17.74],[44,4.64],[22,9.5]],"id":41419625},{"atb":[[11,19.95],[7.4,31.18],[5.7,56.62]],"id":41419592},{"atb":[[9,33.26],[20,10.5],[12.5,17.35]],"id":41419654},{"atb":[[17,12.47],[12,24.19],[29,7.12]],"id":41435526},{"atb":[[17.5,12.09],[12.5,23.13],[30,6.88]],"id":41419621},{"atb":[[10.5,28.01],[26,7.98],[15.5,13.76]],"id":41419633},{"atb":[[130,1.54],[65,4.15],[280,0.71]],"id":41419600},{"atb":[[300,0.66],[200,1.33],[450,0.44]],"id":41419629},{"atb":[[16.5,12.87],[11.5,25.34],[28,7.39]],"id":41419596}],"con":true,"img":false}]}
{"op":"mcm","clk":"5352107728","pt":1646182672826,"mc":[{"id":"1.195503871","rc":[{"atb":[[130,0],[380,0],[230,0]],"id":41419605},{"atb":[[80,0],[42,0],[210,0]],"id":41419593},{"atb":[[22,0],[13.5,0],[9.4,0]],"id":41419589},{"atb":[[600,0],[700,0],[850,0]],"id":41419601},{"atb":[[9,0],[20,0],[12.5,0]],"id":41419597},{"atb":[[6.4,0],[5.2,0],[9.4,0]],"id":28546943},{"atb":[[6.8,0],[9.8,0],[5.4,0]],"id":41419585},{"atb":[[7.2,0],[9.2,0],[15.5,0]],"id":41419590},{"atb":[[38,0],[95,0],[24,0]],"id":41419586},{"atb":[[18,0],[10.5,0],[8.2,0]],"id":41419598},{"atb":[[17,0],[48,0],[24,0]],"id":41419594},{"atb":[[10,0],[5.5,0],[7,0]],"id":28546950},{"atb":[[600,0],[700,0],[850,0]],"id":41419603},{"atb":[[6.2,0],[8.2,0],[13,0]],"id":41419591},{"atb":[[36,0],[19,0],[14,0]],"id":41419587},{"atb":[[32,0],[160,0],[55,0]],"id":41419599},{"atb":[[520,0],[270,0],[370,0]],"id":41419604},{"atb":[[11,0],[7.4,0],[5.7,0]],"id":41419592},{"atb":[[130,0],[65,0],[280,0]],"id":41419600},{"atb":[[16.5,0],[11.5,0],[28,0]],"id":41419596}],"con":true,"img":false}]}
{"op":"mcm","clk":"5352107735","pt":1646182673032,"mc":[{"id":"1.195503871","rc":[{"atb":[[6.8,0],[8.8,0],[14.5,0]],"id":41419634},{"atb":[[18,0],[10.5,0],[8.2,0]],"id":41419655},{"atb":[[600,0],[700,0],[850,0]],"id":41419622},{"atb":[[16.5,0],[46,0],[23,0]],"id":41435527},{"atb":[[9,0],[7,0],[15,0]],"id":41419651},{"atb":[[36,0],[90,0],[23,0]],"id":41419630},{"atb":[[19.5,0],[12,0],[8.8,0]],"id":41419659},{"atb":[[38,0],[19.5,0],[14.5,0]],"id":41419626},{"atb":[[34,0],[18.5,0],[13.5,0]],"id":41419639},{"atb":[[16,0],[44,0],[22,0]],"id":41419606},{"atb":[[18.5,0],[11,0],[8.4,0]],"id":41419635},{"atb":[[270,0],[120,0],[60,0]],"id":41419610},{"atb":[[6.8,0],[8.8,0],[14.5,0]],"id":41419656},{"atb":[[100,0],[50,0],[250,0]],"id":41419623},{"atb":[[260,0],[110,0],[55,0]],"id":41419652},{"atb":[[16.5,0],[11.5,0],[28,0]],"id":41435528},{"atb":[[8,0],[17.5,0],[10,0]],"id":41419660},{"atb":[[18,0],[10.5,0],[8.2,0]],"id":41419627},{"atb":[[10,0],[25,0],[15,0]],"id":41419640},{"atb":[[18.5,0],[27,0],[60,0]],"id":41419607},{"atb":[[310,0],[160,0],[80,0]],"id":41419636},{"atb":[[40,0],[100,0],[25,0]],"id":41419611},{"atb":[[70,0],[38,0],[190,0]],"id":41419657},{"atb":[[18,0],[26,0],[55,0]],"id":41435525},{"atb":[[10.5,0],[26,0],[15.5,0]],"id":41419620},{"atb":[[42,0],[21,0],[15.5,0]],"id":41419632},{"atb":[[9.2,0],[21,0],[13,0]],"id":41419628},{"atb":[[600,0],[700,0],[850,0]],"id":41419608},{"atb":[[65,0],[19,0],[28,0]],"id":41419637},{"atb":[[75,0],[20,0],[30,0]],"id":41419612},{"atb":[[16,0],[44,0],[22,0]],"id":41419625},{"atb":[[9,0],[20,0],[12.5,0]],"id":41419654},{"atb":[[17,0],[12,0],[29,0]],"id":41435526},{"atb":[[17.5,0],[12.5,0],[30,0]],"id":41419621},{"atb":[[10.5,0],[26,0],[15.5,0]],"id":41419633},{"atb":[[300,0],[200,0],[450,0]],"id":41419629}],"con":true,"img":false}]}
{"op":"mcm","clk":"5352108190","pt":1646182682179,"mc":[{"id":"1.195503871","rc":[{"atb":[[130,2.06],[380,0.52],[230,0.87]],"id":41419605},{"atb":[[6.8,45.88],[8.8,25.58],[14.5,14.78]],"id":41419634},{"atb":[[80,2.52],[42,6.48],[210,0.95]],"id":41419593},{"atb":[[18,11.73],[10.5,21],[8.2,36.96]],"id":41419655},{"atb":[[600,0.44],[700,0.28],[850,0.23]],"id":41419622},{"atb":[[22,9.5],[13.5,15.96],[9.4,31.68]],"id":41419589},{"atb":[[16.5,17.17],[46,4.43],[23,9.07]],"id":41435527},{"atb":[[9,24.94],[7,44.35],[15,14.25]],"id":41419651},{"atb":[[600,0.44],[700,0.28],[850,0.23]],"id":41419601},{"atb":[[36,5.7],[90,2.24],[23,12.09]],"id":41419630},{"atb":[[9,33.26],[20,10.5],[12.5,17.35]],"id":41419597},{"atb":[[6.4,36.96],[5.2,63.36],[9.4,23.75]],"id":28546943},{"atb":[[19.5,10.79],[12,18.14],[8.8,34.11]],"id":41419659},{"atb":[[38,5.39],[19.5,10.79],[14.5,19.71]],"id":41419626},{"atb":[[34,6.04],[18.5,11.4],[13.5,21.28]],"id":41419639},{"atb":[[16,17.74],[44,4.64],[22,9.5]],"id":41419606},{"atb":[[18.5,11.4],[11,19.95],[8.4,35.95]],"id":41419635},{"atb":[[6.8,34.41],[9.8,22.68],[5.4,60.48]],"id":41419585},{"atb":[[270,0.74],[120,1.67],[60,4.5]],"id":41419610},{"atb":[[6.8,45.88],[8.8,25.58],[14.5,14.78]],"id":41419656},{"atb":[[100,2.01],[50,5.43],[250,0.8]],"id":41419623},{"atb":[[7.2,42.92],[9.2,24.34],[15.5,13.76]],"id":41419590},{"atb":[[260,0.77],[110,1.82],[55,4.92]],"id":41419652},{"atb":[[16.5,12.87],[11.5,25.34],[28,7.39]],"id":41435528},{"atb":[[38,5.39],[95,2.12],[24,11.56]],"id":41419586},{"atb":[[18,11.73],[10.5,21],[8.2,36.96]],"id":41419598},{"atb":[[8,38.01],[17.5,12.09],[10,22.17]],"id":41419660},{"atb":[[18,11.73],[10.5,21],[8.2,36.96]],"id":41419627},{"atb":[[17,16.63],[48,4.24],[24,8.67]],"id":41419594},{"atb":[[10,29.56],[25,8.31],[15,14.25]],"id":41419640},{"atb":[[18.5,15.2],[27,7.67],[60,3.38]],"id":41419607},{"atb":[[10,22.17],[5.5,59.13],[7,33.26]],"id":28546950},{"atb":[[310,0.64],[160,1.25],[80,3.36]],"id":41419636},{"atb":[[600,0.44],[700,0.28],[850,0.23]],"id":41419603},{"atb":[[40,5.11],[100,2.01],[25,11.08]],"id":41419611},{"atb":[[70,2.89],[38,7.19],[190,1.05]],"id":41419657},{"atb":[[6.2,51.17],[8.2,27.72],[13,16.63]],"id":41419591},{"atb":[[18,15.65],[26,7.98],[55,3.69]],"id":41435525},{"atb":[[10.5,28.01],[26,7.98],[15.5,13.76]],"id":41419620},{"atb":[[36,5.7],[19,11.08],[14,20.47]],"id":41419587},{"atb":[[42,4.86],[21,9.97],[15.5,18.35]],"id":41419632},{"atb":[[32,8.58],[160,1.25],[55,3.69]],"id":41419599},{"atb":[[9.2,32.45],[21,9.97],[13,16.63]],"id":41419628},{"atb":[[600,0.44],[700,0.28],[850,0.23]],"id":41419608},{"atb":[[65,3.11],[19,14.78],[28,7.39]],"id":41419637},{"atb":[[520,0.38],[270,0.99],[370,0.53]],"id":41419604},{"atb":[[75,2.69],[20,14],[30,6.88]],"id":41419612},{"atb":[[16,17.74],[44,4.64],[22,9.5]],"id":41419625},{"atb":[[11,19.95],[7.4,31.18],[5.7,56.62]],"id":41419592},{"atb":[[9,33.26],[20,10.5],[12.5,17.35]],"id":41419654},{"atb":[[17,12.47],[12,24.19],[29,7.12]],"id":41435526},{"atb":[[17.5,12.09],[12.5,23.13],[30,6.88]],"id":41419621},{"atb":[[10.5,28.01],[26,7.98],[15.5,13.76]],"id":41419633},{"atb":[[130,1.54],[65,4.15],[280,0.71]],"id":41419600},{"atb":[[300,0.66],[200,1.33],[450,0.44]],"id":41419629},{"atb":[[16.5,12.87],[11.5,25.34],[28,7.39]],"id":41419596}],"con":true,"img":false}]}
{"op":"mcm","clk":"5352110774","pt":1646182735790,"mc":[{"id":"1.195503871","rc":[{"atb":[[130,0],[380,0],[230,0]],"id":41419605},{"atb":[[6.8,0],[8.8,0],[14.5,0]],"id":41419634},{"atb":[[80,0],[42,0],[210,0]],"id":41419593},{"atb":[[600,0],[700,0],[850,0]],"id":41419622},{"atb":[[22,0],[13.5,0],[9.4,0]],"id":41419589},{"atb":[[600,0],[700,0],[850,0]],"id":41419601},{"atb":[[36,0],[90,0],[23,0]],"id":41419630},{"atb":[[9,0],[20,0],[12.5,0]],"id":41419597},{"atb":[[6.4,0],[5.2,0],[9.4,0]],"id":28546943},{"atb":[[38,0],[19.5,0],[14.5,0]],"id":41419626},{"atb":[[16,0],[44,0],[22,0]],"id":41419606},{"atb":[[18.5,0],[11,0],[8.4,0]],"id":41419635},{"atb":[[6.8,0],[9.8,0],[5.4,0]],"id":41419585},{"atb":[[270,0],[120,0],[60,0]],"id":41419610},{"atb":[[100,0],[50,0],[250,0]],"id":41419623},{"atb":[[7.2,0],[9.2,0],[15.5,0]],"id":41419590},{"atb":[[38,0],[95,0],[24,0]],"id":41419586},{"atb":[[18,0],[10.5,0],[8.2,0]],"id":41419598},{"atb":[[18,0],[10.5,0],[8.2,0]],"id":41419627},{"atb":[[17,0],[48,0],[24,0]],"id":41419594},{"atb":[[18.5,0],[27,0],[60,0]],"id":41419607},{"atb":[[10,0],[5.5,0],[7,0]],"id":28546950},{"atb":[[600,0],[700,0],[850,0]],"id":41419603},{"atb":[[40,0],[100,0],[25,0]],"id":41419611},{"atb":[[6.2,0],[8.2,0],[13,0]],"id":41419591},{"atb":[[10.5,0],[26,0],[15.5,0]],"id":41419620},{"atb":[[36,0],[19,0],[14,0]],"id":41419587},{"atb":[[42,0],[21,0],[15.5,0]],"id":41419632},{"atb":[[32,0],[160,0],[55,0]],"id":41419599},{"atb":[[9.2,0],[21,0],[13,0]],"id":41419628},{"atb":[[600,0],[700,0],[850,0]],"id":41419608},{"atb":[[520,0],[270,0],[370,0]],"id":41419604},{"atb":[[75,0],[20,0],[30,0]],"id":41419612},{"atb":[[16,0],[44,0],[22,0]],"id":41419625},{"atb":[[11,0],[7.4,0],[5.7,0]],"id":41419592},{"atb":[[17.5,0],[12.5,0],[30,0]],"id":41419621},{"atb":[[10.5,0],[26,0],[15.5,0]],"id":41419633},{"atb":[[130,0],[65,0],[280,0]],"id":41419600},{"atb":[[300,0],[200,0],[450,0]],"id":41419629},{"atb":[[16.5,0],[11.5,0],[28,0]],"id":41419596}],"con":true,"img":false}]}
{"op":"mcm","clk":"5352110781","pt":1646182735847,"mc":[{"id":"1.195503871","rc":[{"atb":[[18,0],[10.5,0],[8.2,0]],"id":41419655},{"atb":[[16.5,0],[46,0],[23,0]],"id":41435527},{"atb":[[9,0],[7,0],[15,0]],"id":41419651},{"atb":[[19.5,0],[12,0],[8.8,0]],"id":41419659},{"atb":[[34,0],[18.5,0],[13.5,0]],"id":41419639},{"atb":[[6.8,0],[8.8,0],[14.5,0]],"id":41419656},{"atb":[[260,0],[110,0],[55,0]],"id":41419652},{"atb":[[16.5,0],[11.5,0],[28,0]],"id":41435528},{"atb":[[8,0],[17.5,0],[10,0]],"id":41419660},{"atb":[[10,0],[25,0],[15,0]],"id":41419640},{"atb":[[310,0],[160,0],[80,0]],"id":41419636},{"atb":[[70,0],[38,0],[190,0]],"id":41419657},{"atb":[[18,0],[26,0],[55,0]],"id":41435525},{"atb":[[65,0],[19,0],[28,0]],"id":41419637},{"atb":[[9,0],[20,0],[12.5,0]],"id":41419654},{"atb":[[17,0],[12,0],[29,0]],"id":41435526}],"con":true,"img":false}]}
{"op":"mcm","clk":"5352111126","pt":1646182743190,"mc":[{"id":"1.195503871","rc":[{"atb":[[150,1.78],[400,0.5],[250,0.8]],"id":41419605},{"atb":[[9,24.94],[7,44.35],[15,14.25]],"id":41419634},{"atb":[[80,2.52],[42,6.48],[210,0.95]],"id":41419593},{"atb":[[18,11.73],[10.5,21],[8.2,36.96]],"id":41419655},{"atb":[[600,0.44],[700,0.28],[850,0.23]],"id":41419622},{"atb":[[22,9.5],[13.5,15.96],[9.4,31.68]],"id":41419589},{"atb":[[16.5,17.17],[46,4.43],[23,9.07]],"id":41435527},{"atb":[[6.8,45.88],[8.8,25.58],[14.5,14.78]],"id":41419651},{"atb":[[600,0.44],[700,0.28],[850,0.23]],"id":41419601},{"atb":[[36,5.7],[90,2.24],[23,12.09]],"id":41419630},{"atb":[[9,33.26],[20,10.5],[12.5,17.35]],"id":41419597},{"atb":[[6.4,36.96],[5.2,63.36],[9.4,23.75]],"id":28546943},{"atb":[[19.5,10.79],[12,18.14],[8.8,34.11]],"id":41419659},{"atb":[[38,5.39],[19.5,10.79],[14.5,19.71]],"id":41419626},{"atb":[[36,5.7],[19,11.08],[14,20.47]],"id":41419639},{"atb":[[16,17.74],[44,4.64],[22,9.5]],"id":41419606},{"atb":[[18.5,11.4],[11,19.95],[8.4,35.95]],"id":41419635},{"atb":[[9.6,23.2],[5.3,61.88],[6.6,35.63]],"id":41419585},{"atb":[[260,0.77],[110,1.82],[55,4.92]],"id":41419610},{"atb":[[6.8,45.88],[8.8,25.58],[14.5,14.78]],"id":41419656},{"atb":[[100,2.01],[50,5.43],[250,0.8]],"id":41419623},{"atb":[[7.2,42.92],[9.2,24.34],[15.5,13.76]],"id":41419590},{"atb":[[260,0.77],[110,1.82],[55,4.92]],"id":41419652},{"atb":[[16.5,12.87],[11.5,25.34],[28,7.39]],"id":41435528},{"atb":[[38,5.39],[95,2.12],[24,11.56]],"id":41419586},{"atb":[[18.5,11.4],[11,19.95],[8.4,35.95]],"id":41419598},{"atb":[[18,11.73],[10.5,21],[8.2,36.96]],"id":41419660},{"atb":[[8,38.01],[17.5,12.09],[10,22.17]],"id":41419627},{"atb":[[17,16.63],[48,4.24],[24,8.67]],"id":41419594},{"atb":[[10.5,28.01],[26,7.98],[15.5,13.76]],"id":41419640},{"atb":[[18,15.65],[26,7.98],[55,3.69]],"id":41419607},{"atb":[[6.8,34.41],[9.8,22.68],[5.4,60.48]],"id":28546950},{"atb":[[330,0.6],[180,1.11],[90,2.98]],"id":41419636},{"atb":[[600,0.44],[700,0.28],[850,0.23]],"id":41419603},{"atb":[[40,5.11],[100,2.01],[25,11.08]],"id":41419611},{"atb":[[70,2.89],[38,7.19],[190,1.05]],"id":41419657},{"atb":[[6.4,49.28],[13.5,15.96],[8.4,26.97]],"id":41419591},{"atb":[[18,15.65],[26,7.98],[55,3.69]],"id":41435525},{"atb":[[10.5,28.01],[26,7.98],[15.5,13.76]],"id":41419620},{"atb":[[36,5.7],[19,11.08],[14,20.47]],"id":41419587},{"atb":[[42,4.86],[21,9.97],[15.5,18.35]],"id":41419632},{"atb":[[32,8.58],[160,1.25],[55,3.69]],"id":41419599},{"atb":[[9.2,32.45],[21,9.97],[13,16.63]],"id":41419628},{"atb":[[600,0.44],[700,0.28],[850,0.23]],"id":41419608},{"atb":[[70,2.89],[19.5,14.38],[29,7.12]],"id":41419637},{"atb":[[260,1.02],[360,0.55],[510,0.39]],"id":41419604},{"atb":[[32,6.44],[80,2.52],[21,13.3]],"id":41419612},{"atb":[[16,17.74],[44,4.64],[22,9.5]],"id":41419625},{"atb":[[5.6,57.85],[7.2,32.19],[10.5,21]],"id":41419592},{"atb":[[9,33.26],[20,10.5],[12.5,17.35]],"id":41419654},{"atb":[[17,12.47],[12,24.19],[29,7.12]],"id":41435526},{"atb":[[17.5,12.09],[12.5,23.13],[30,6.88]],"id":41419621},{"atb":[[10.5,28.01],[26,7.98],[15.5,13.76]],"id":41419633},{"atb":[[130,1.54],[65,4.15],[280,0.71]],"id":41419600},{"atb":[[290,0.69],[190,1.41],[440,0.45]],"id":41419629},{"atb":[[16.5,12.87],[11.5,25.34],[28,7.39]],"id":41419596}],"con":true,"img":false}]}
{"op":"mcm","clk":"5352146194","pt":1646183572653,"mc":[{"id":"1.195503871","marketDefinition":{"bspMarket":false,"turnInPlayEnabled":false,"persistenceEnabled":false,"marketBaseRate":7.0,"eventId":"31272499","eventTypeId":"4339","numberOfWinners":1,"bettingType":"ODDS","marketType":"EXACTA","marketTime":"2022-03-02T12:10:00.000Z","suspendTime":"2022-03-02T12:10:00.000Z","bspReconciled":false,"complete":true,"inPlay":false,"crossMatching":false,"runnersVoidable":false,"numberOfActiveRunners":56,"betDelay":0,"status":"OPEN","runners":[{"status":"ACTIVE","sortPriority":1,"id":41419585,"name":"1 - 2"},{"status":"ACTIVE","sortPriority":2,"id":41419586,"name":"1 - 3"},{"status":"ACTIVE","sortPriority":3,"id":41419587,"name":"1 - 4"},{"status":"ACTIVE","sortPriority":4,"id":41419589,"name":"1 - 6"},{"status":"ACTIVE","sortPriority":5,"id":41419590,"name":"1 - 7"},{"status":"ACTIVE","sortPriority":6,"id":41419591,"name":"1 - 8"},{"status":"ACTIVE","sortPriority":7,"id":28546943,"name":"1 - 9"},{"status":"ACTIVE","sortPriority":8,"id":41419592,"name":"2 - 1"},{"status":"ACTIVE","sortPriority":9,"id":41419593,"name":"2 - 3"},{"status":"ACTIVE","sortPriority":10,"id":41419594,"name":"2 - 4"},{"status":"ACTIVE","sortPriority":11,"id":41419596,"name":"2 - 6"},{"status":"ACTIVE","sortPriority":12,"id":41419597,"name":"2 - 7"},{"status":"ACTIVE","sortPriority":13,"id":41419598,"name":"2 - 8"},{"status":"ACTIVE","sortPriority":14,"id":41419651,"name":"2 - 9"},{"status":"ACTIVE","sortPriority":15,"id":41419599,"name":"3 - 1"},{"status":"ACTIVE","sortPriority":16,"id":41419600,"name":"3 - 2"},{"status":"ACTIVE","sortPriority":17,"id":41419601,"name":"3 - 4"},{"status":"ACTIVE","sortPriority":18,"id":41419603,"name":"3 - 6"},{"status":"ACTIVE","sortPriority":19,"id":41419604,"name":"3 - 7"},{"status":"ACTIVE","sortPriority":20,"id":41419605,"name":"3 - 8"},{"status":"ACTIVE","sortPriority":21,"id":41419652,"name":"3 - 9"},{"status":"ACTIVE","sortPriority":22,"id":41419606,"name":"4 - 1"},{"status":"ACTIVE","sortPriority":23,"id":41419607,"name":"4 - 2"},{"status":"ACTIVE","sortPriority":24,"id":41419608,"name":"4 - 3"},{"status":"ACTIVE","sortPriority":25,"id":41419610,"name":"4 - 6"},{"status":"ACTIVE","sortPriority":26,"id":41419611,"name":"4 - 7"},{"status":"ACTIVE","sortPriority":27,"id":41419612,"name":"4 - 8"},{"status":"ACTIVE","sortPriority":28,"id":41435525,"name":"4 - 9"},{"status":"ACTIVE","sortPriority":29,"id":41419620,"name":"6 - 1"},{"status":"ACTIVE","sortPriority":30,"id":41419621,"name":"6 - 2"},{"status":"ACTIVE","sortPriority":31,"id":41419622,"name":"6 - 3"},{"status":"ACTIVE","sortPriority":32,"id":41419623,"name":"6 - 4"},{"status":"ACTIVE","sortPriority":33,"id":41419625,"name":"6 - 7"},{"status":"ACTIVE","sortPriority":34,"id":41419626,"name":"6 - 8"},{"status":"ACTIVE","sortPriority":35,"id":41435526,"name":"6 - 9"},{"status":"ACTIVE","sortPriority":36,"id":41419627,"name":"7 - 1"},{"status":"ACTIVE","sortPriority":37,"id":41419628,"name":"7 - 2"},{"status":"ACTIVE","sortPriority":38,"id":41419629,"name":"7 - 3"},{"status":"ACTIVE","sortPriority":39,"id":41419630,"name":"7 - 4"},{"status":"ACTIVE","sortPriority":40,"id":41419632,"name":"7 - 6"},{"status":"ACTIVE","sortPriority":41,"id":41419633,"name":"7 - 8"},{"status":"ACTIVE","sortPriority":42,"id":41419654,"name":"7 - 9"},{"status":"ACTIVE","sortPriority":43,"id":41419634,"name":"8 - 1"},{"status":"ACTIVE","sortPriority":44,"id":41419635,"name":"8 - 2"},{"status":"ACTIVE","sortPriority":45,"id":41419636,"name":"8 - 3"},{"status":"ACTIVE","sortPriority":46,"id":41419637,"name":"8 - 4"},{"status":"ACTIVE","sortPriority":47,"id":41419639,"name":"8 - 6"},{"status":"ACTIVE","sortPriority":48,"id":41419640,"name":"8 - 7"},{"status":"ACTIVE","sortPriority":49,"id":41419655,"name":"8 - 9"},{"status":"ACTIVE","sortPriority":50,"id":28546950,"name":"9 - 1"},{"status":"ACTIVE","sortPriority":51,"id":41419656,"name":"9 - 2"},{"status":"ACTIVE","sortPriority":52,"id":41419657,"name":"9 - 3"},{"status":"ACTIVE","sortPriority":53,"id":41435527,"name":"9 - 4"},{"status":"ACTIVE","sortPriority":54,"id":41435528,"name":"9 - 6"},{"status":"ACTIVE","sortPriority":55,"id":41419659,"name":"9 - 7"},{"status":"ACTIVE","sortPriority":56,"id":41419660,"name":"9 - 8"}],"regulators":["MR_INT"],"venue":"Rockhampton","countryCode":"AU","discountAllowed":true,"timezone":"Australia/Queensland","openDate":"2022-03-02T08:28:00.000Z","version":4382597910,"name":"Exacta","eventName":"Rockhampton (AUS) 2nd Mar"},"rc":[],"con":true,"img":false}]}
{"op":"mcm","clk":"5352239454","pt":1646185602750,"mc":[{"id":"1.195503871","marketDefinition":{"bspMarket":false,"turnInPlayEnabled":false,"persistenceEnabled":false,"marketBaseRate":7.0,"eventId":"31272499","eventTypeId":"4339","numberOfWinners":1,"bettingType":"ODDS","marketType":"EXACTA","marketTime":"2022-03-02T12:10:00.000Z","suspendTime":"2022-03-02T12:10:00.000Z","bspReconciled":false,"complete":true,"inPlay":false,"crossMatching":false,"runnersVoidable":false,"numberOfActiveRunners":56,"betDelay":0,"status":"OPEN","runners":[{"status":"ACTIVE","sortPriority":1,"id":41419585,"name":"1 - 2"},{"status":"ACTIVE","sortPriority":2,"id":41419586,"name":"1 - 3"},{"status":"ACTIVE","sortPriority":3,"id":41419587,"name":"1 - 4"},{"status":"ACTIVE","sortPriority":4,"id":41419589,"name":"1 - 6"},{"status":"ACTIVE","sortPriority":5,"id":41419590,"name":"1 - 7"},{"status":"ACTIVE","sortPriority":6,"id":41419591,"name":"1 - 8"},{"status":"ACTIVE","sortPriority":7,"id":28546943,"name":"1 - 9"},{"status":"ACTIVE","sortPriority":8,"id":41419592,"name":"2 - 1"},{"status":"ACTIVE","sortPriority":9,"id":41419593,"name":"2 - 3"},{"status":"ACTIVE","sortPriority":10,"id":41419594,"name":"2 - 4"},{"status":"ACTIVE","sortPriority":11,"id":41419596,"name":"2 - 6"},{"status":"ACTIVE","sortPriority":12,"id":41419597,"name":"2 - 7"},{"status":"ACTIVE","sortPriority":13,"id":41419598,"name":"2 - 8"},{"status":"ACTIVE","sortPriority":14,"id":41419651,"name":"2 - 9"},{"status":"ACTIVE","sortPriority":15,"id":41419599,"name":"3 - 1"},{"status":"ACTIVE","sortPriority":16,"id":41419600,"name":"3 - 2"},{"status":"ACTIVE","sortPriority":17,"id":41419601,"name":"3 - 4"},{"status":"ACTIVE","sortPriority":18,"id":41419603,"name":"3 - 6"},{"status":"ACTIVE","sortPriority":19,"id":41419604,"name":"3 - 7"},{"status":"ACTIVE","sortPriority":20,"id":41419605,"name":"3 - 8"},{"status":"ACTIVE","sortPriority":21,"id":41419652,"name":"3 - 9"},{"status":"ACTIVE","sortPriority":22,"id":41419606,"name":"4 - 1"},{"status":"ACTIVE","sortPriority":23,"id":41419607,"name":"4 - 2"},{"status":"ACTIVE","sortPriority":24,"id":41419608,"name":"4 - 3"},{"status":"ACTIVE","sortPriority":25,"id":41419610,"name":"4 - 6"},{"status":"ACTIVE","sortPriority":26,"id":41419611,"name":"4 - 7"},{"status":"ACTIVE","sortPriority":27,"id":41419612,"name":"4 - 8"},{"status":"ACTIVE","sortPriority":28,"id":41435525,"name":"4 - 9"},{"status":"ACTIVE","sortPriority":29,"id":41419620,"name":"6 - 1"},{"status":"ACTIVE","sortPriority":30,"id":41419621,"name":"6 - 2"},{"status":"ACTIVE","sortPriority":31,"id":41419622,"name":"6 - 3"},{"status":"ACTIVE","sortPriority":32,"id":41419623,"name":"6 - 4"},{"status":"ACTIVE","sortPriority":33,"id":41419625,"name":"6 - 7"},{"status":"ACTIVE","sortPriority":34,"id":41419626,"name":"6 - 8"},{"status":"ACTIVE","sortPriority":35,"id":41435526,"name":"6 - 9"},{"status":"ACTIVE","sortPriority":36,"id":41419627,"name":"7 - 1"},{"status":"ACTIVE","sortPriority":37,"id":41419628,"name":"7 - 2"},{"status":"ACTIVE","sortPriority":38,"id":41419629,"name":"7 - 3"},{"status":"ACTIVE","sortPriority":39,"id":41419630,"name":"7 - 4"},{"status":"ACTIVE","sortPriority":40,"id":41419632,"name":"7 - 6"},{"status":"ACTIVE","sortPriority":41,"id":41419633,"name":"7 - 8"},{"status":"ACTIVE","sortPriority":42,"id":41419654,"name":"7 - 9"},{"status":"ACTIVE","sortPriority":43,"id":41419634,"name":"8 - 1"},{"status":"ACTIVE","sortPriority":44,"id":41419635,"name":"8 - 2"},{"status":"ACTIVE","sortPriority":45,"id":41419636,"name":"8 - 3"},{"status":"ACTIVE","sortPriority":46,"id":41419637,"name":"8 - 4"},{"status":"ACTIVE","sortPriority":47,"id":41419639,"name":"8 - 6"},{"status":"ACTIVE","sortPriority":48,"id":41419640,"name":"8 - 7"},{"status":"ACTIVE","sortPriority":49,"id":41419655,"name":"8 - 9"},{"status":"ACTIVE","sortPriority":50,"id":28546950,"name":"9 - 1"},{"status":"ACTIVE","sortPriority":51,"id":41419656,"name":"9 - 2"},{"status":"ACTIVE","sortPriority":52,"id":41419657,"name":"9 - 3"},{"status":"ACTIVE","sortPriority":53,"id":41435527,"name":"9 - 4"},{"status":"ACTIVE","sortPriority":54,"id":41435528,"name":"9 - 6"},{"status":"ACTIVE","sortPriority":55,"id":41419659,"name":"9 - 7"},{"status":"ACTIVE","sortPriority":56,"id":41419660,"name":"9 - 8"}],"regulators":["MR_INT"],"venue":"Rockhampton","countryCode":"AU","discountAllowed":true,"timezone":"Australia/Queensland","openDate":"2022-03-02T08:28:00.000Z","version":4382597910,"name":"Exacta","eventName":"Rockhampton (AUS) 2nd Mar"},"rc":[{"atb":[[150,1.78],[400,0.5],[250,0.8]],"id":41419605},{"atb":[[9,24.98],[7,44.42],[15,14.28]],"id":41419634},{"atb":[[80,2.53],[42,6.49],[210,0.95]],"id":41419593},{"atb":[[18,11.75],[10.5,21.04],[8.2,37.01]],"id":41419655},{"atb":[[600,0.44],[700,0.28],[850,0.23]],"id":41419622},{"atb":[[22,9.52],[13.5,15.99],[9.4,31.73]],"id":41419589},{"atb":[[16.5,17.19],[46,4.44],[23,9.08]],"id":41435527},{"atb":[[6.8,45.95],[8.8,25.62],[14.5,14.8]],"id":41419651},{"atb":[[600,0.44],[700,0.28],[850,0.23]],"id":41419601},{"atb":[[36,5.7],[90,2.24],[23,12.11]],"id":41419630},{"atb":[[9,33.31],[20,10.51],[12.5,17.38]],"id":41419597},{"atb":[[6.4,37.01],[5.2,63.46],[9.4,23.79]],"id":28546943},{"atb":[[19.5,10.8],[12,18.17],[8.8,34.17]],"id":41419659},{"atb":[[38,5.4],[19.5,10.8],[14.5,19.74]],"id":41419626},{"atb":[[36,5.7],[19,11.1],[14,20.5]],"id":41419639},{"atb":[[16,17.77],[44,4.65],[22,9.52]],"id":41419606},{"atb":[[18.5,11.42],[11,19.99],[8.4,36.01]],"id":41419635},{"atb":[[9.6,23.24],[5.3,61.98],[6.6,35.69]],"id":41419585},{"atb":[[260,0.77],[110,1.83],[55,4.93]],"id":41419610},{"atb":[[6.8,45.95],[8.8,25.62],[14.5,14.8]],"id":41419656},{"atb":[[100,2.01],[50,5.44],[250,0.8]],"id":41419623},{"atb":[[7.2,42.99],[9.2,24.37],[15.5,13.78]],"id":41419590},{"atb":[[260,0.77],[110,1.83],[55,4.93]],"id":41419652},{"atb":[[16.5,12.89],[11.5,25.38],[28,7.4]],"id":41435528},{"atb":[[38,5.4],[95,2.12],[24,11.58]],"id":41419586},{"atb":[[18.5,11.42],[11,19.99],[8.4,36.01]],"id":41419598},{"atb":[[18,11.75],[10.5,21.04],[8.2,37.01]],"id":41419660},{"atb":[[8,38.07],[17.5,12.11],[10,22.2]],"id":41419627},{"atb":[[17,16.65],[48,4.25],[24,8.69]],"id":41419594},{"atb":[[10.5,28.05],[26,7.99],[15.5,13.78]],"id":41419640},{"atb":[[18,15.67],[26,7.99],[55,3.7]],"id":41419607},{"atb":[[6.8,34.46],[9.8,22.71],[5.4,60.57]],"id":28546950},{"atb":[[330,0.6],[180,1.11],[90,2.99]],"id":41419636},{"atb":[[600,0.44],[700,0.28],[850,0.23]],"id":41419603},{"atb":[[40,5.12],[100,2.01],[25,11.1]],"id":41419611},{"atb":[[70,2.89],[38,7.2],[190,1.05]],"id":41419657},{"atb":[[6.4,49.35],[13.5,15.99],[8.4,27.01]],"id":41419591},{"atb":[[18,15.67],[26,7.99],[55,3.7]],"id":41435525},{"atb":[[10.5,28.05],[26,7.99],[15.5,13.78]],"id":41419620},{"atb":[[36,5.7],[19,11.1],[14,20.5]],"id":41419587},{"atb":[[42,4.87],[21,9.99],[15.5,18.38]],"id":41419632},{"atb":[[32,8.59],[160,1.25],[55,3.7]],"id":41419599},{"atb":[[9.2,32.5],[21,9.99],[13,16.65]],"id":41419628},{"atb":[[600,0.44],[700,0.28],[850,0.23]],"id":41419608},{"atb":[[70,2.89],[19.5,14.4],[29,7.13]],"id":41419637},{"atb":[[260,1.03],[360,0.55],[510,0.39]],"id":41419604},{"atb":[[32,6.45],[80,2.53],[21,13.32]],"id":41419612},{"atb":[[16,17.77],[44,4.65],[22,9.52]],"id":41419625},{"atb":[[5.6,57.94],[7.2,32.24],[10.5,21.04]],"id":41419592},{"atb":[[9,33.31],[20,10.51],[12.5,17.38]],"id":41419654},{"atb":[[17,12.49],[12,24.23],[29,7.13]],"id":41435526},{"atb":[[17.5,12.11],[12.5,23.17],[30,6.89]],"id":41419621},{"atb":[[10.5,28.05],[26,7.99],[15.5,13.78]],"id":41419633},{"atb":[[130,1.54],[65,4.16],[280,0.71]],"id":41419600},{"atb":[[290,0.69],[190,1.41],[440,0.45]],"id":41419629},{"atb":[[16.5,12.89],[11.5,25.38],[28,7.4]],"id":41419596}],"con":true,"img":true}]}
{"op":"mcm","clk":"5352466741","pt":1646191002693,"mc":[{"id":"1.195503871","marketDefinition":{"bspMarket":false,"turnInPlayEnabled":false,"persistenceEnabled":false,"marketBaseRate":7.0,"eventId":"31272499","eventTypeId":"4339","numberOfWinners":1,"bettingType":"ODDS","marketType":"EXACTA","marketTime":"2022-03-02T12:10:00.000Z","suspendTime":"2022-03-02T12:10:00.000Z","bspReconciled":false,"complete":true,"inPlay":false,"crossMatching":false,"runnersVoidable":false,"numberOfActiveRunners":56,"betDelay":0,"status":"OPEN","runners":[{"status":"ACTIVE","sortPriority":1,"id":41419585,"name":"1 - 2"},{"status":"ACTIVE","sortPriority":2,"id":41419586,"name":"1 - 3"},{"status":"ACTIVE","sortPriority":3,"id":41419587,"name":"1 - 4"},{"status":"ACTIVE","sortPriority":4,"id":41419589,"name":"1 - 6"},{"status":"ACTIVE","sortPriority":5,"id":41419590,"name":"1 - 7"},{"status":"ACTIVE","sortPriority":6,"id":41419591,"name":"1 - 8"},{"status":"ACTIVE","sortPriority":7,"id":28546943,"name":"1 - 9"},{"status":"ACTIVE","sortPriority":8,"id":41419592,"name":"2 - 1"},{"status":"ACTIVE","sortPriority":9,"id":41419593,"name":"2 - 3"},{"status":"ACTIVE","sortPriority":10,"id":41419594,"name":"2 - 4"},{"status":"ACTIVE","sortPriority":11,"id":41419596,"name":"2 - 6"},{"status":"ACTIVE","sortPriority":12,"id":41419597,"name":"2 - 7"},{"status":"ACTIVE","sortPriority":13,"id":41419598,"name":"2 - 8"},{"status":"ACTIVE","sortPriority":14,"id":41419651,"name":"2 - 9"},{"status":"ACTIVE","sortPriority":15,"id":41419599,"name":"3 - 1"},{"status":"ACTIVE","sortPriority":16,"id":41419600,"name":"3 - 2"},{"status":"ACTIVE","sortPriority":17,"id":41419601,"name":"3 - 4"},{"status":"ACTIVE","sortPriority":18,"id":41419603,"name":"3 - 6"},{"status":"ACTIVE","sortPriority":19,"id":41419604,"name":"3 - 7"},{"status":"ACTIVE","sortPriority":20,"id":41419605,"name":"3 - 8"},{"status":"ACTIVE","sortPriority":21,"id":41419652,"name":"3 - 9"},{"status":"ACTIVE","sortPriority":22,"id":41419606,"name":"4 - 1"},{"status":"ACTIVE","sortPriority":23,"id":41419607,"name":"4 - 2"},{"status":"ACTIVE","sortPriority":24,"id":41419608,"name":"4 - 3"},{"status":"ACTIVE","sortPriority":25,"id":41419610,"name":"4 - 6"},{"status":"ACTIVE","sortPriority":26,"id":41419611,"name":"4 - 7"},{"status":"ACTIVE","sortPriority":27,"id":41419612,"name":"4 - 8"},{"status":"ACTIVE","sortPriority":28,"id":41435525,"name":"4 - 9"},{"status":"ACTIVE","sortPriority":29,"id":41419620,"name":"6 - 1"},{"status":"ACTIVE","sortPriority":30,"id":41419621,"name":"6 - 2"},{"status":"ACTIVE","sortPriority":31,"id":41419622,"name":"6 - 3"},{"status":"ACTIVE","sortPriority":32,"id":41419623,"name":"6 - 4"},{"status":"ACTIVE","sortPriority":33,"id":41419625,"name":"6 - 7"},{"status":"ACTIVE","sortPriority":34,"id":41419626,"name":"6 - 8"},{"status":"ACTIVE","sortPriority":35,"id":41435526,"name":"6 - 9"},{"status":"ACTIVE","sortPriority":36,"id":41419627,"name":"7 - 1"},{"status":"ACTIVE","sortPriority":37,"id":41419628,"name":"7 - 2"},{"status":"ACTIVE","sortPriority":38,"id":41419629,"name":"7 - 3"},{"status":"ACTIVE","sortPriority":39,"id":41419630,"name":"7 - 4"},{"status":"ACTIVE","sortPriority":40,"id":41419632,"name":"7 - 6"},{"status":"ACTIVE","sortPriority":41,"id":41419633,"name":"7 - 8"},{"status":"ACTIVE","sortPriority":42,"id":41419654,"name":"7 - 9"},{"status":"ACTIVE","sortPriority":43,"id":41419634,"name":"8 - 1"},{"status":"ACTIVE","sortPriority":44,"id":41419635,"name":"8 - 2"},{"status":"ACTIVE","sortPriority":45,"id":41419636,"name":"8 - 3"},{"status":"ACTIVE","sortPriority":46,"id":41419637,"name":"8 - 4"},{"status":"ACTIVE","sortPriority":47,"id":41419639,"name":"8 - 6"},{"status":"ACTIVE","sortPriority":48,"id":41419640,"name":"8 - 7"},{"status":"ACTIVE","sortPriority":49,"id":41419655,"name":"8 - 9"},{"status":"ACTIVE","sortPriority":50,"id":28546950,"name":"9 - 1"},{"status":"ACTIVE","sortPriority":51,"id":41419656,"name":"9 - 2"},{"status":"ACTIVE","sortPriority":52,"id":41419657,"name":"9 - 3"},{"status":"ACTIVE","sortPriority":53,"id":41435527,"name":"9 - 4"},{"status":"ACTIVE","sortPriority":54,"id":41435528,"name":"9 - 6"},{"status":"ACTIVE","sortPriority":55,"id":41419659,"name":"9 - 7"},{"status":"ACTIVE","sortPriority":56,"id":41419660,"name":"9 - 8"}],"regulators":["MR_INT"],"venue":"Rockhampton","countryCode":"AU","discountAllowed":true,"timezone":"Australia/Queensland","openDate":"2022-03-02T08:28:00.000Z","version":4382597910,"name":"Exacta","eventName":"Rockhampton (AUS) 2nd Mar"},"rc":[{"atb":[[150,1.79],[400,0.5],[250,0.8]],"id":41419605},{"atb":[[9,25.02],[7,44.49],[15,14.3]],"id":41419634},{"atb":[[80,2.53],[42,6.51],[210,0.95]],"id":41419593},{"atb":[[18,11.77],[10.5,21.07],[8.2,37.08]],"id":41419655},{"atb":[[600,0.44],[700,0.28],[850,0.23]],"id":41419622},{"atb":[[22,9.53],[13.5,16.02],[9.4,31.78]],"id":41419589},{"atb":[[16.5,17.22],[46,4.45],[23,9.09]],"id":41435527},{"atb":[[6.8,46.03],[8.8,25.67],[14.5,14.83]],"id":41419651},{"atb":[[600,0.44],[700,0.28],[850,0.23]],"id":41419601},{"atb":[[36,5.71],[90,2.25],[23,12.13]],"id":41419630},{"atb":[[9,33.37],[20,10.53],[12.5,17.41]],"id":41419597},{"atb":[[6.4,37.08],[5.2,63.56],[9.4,23.83]],"id":28546943},{"atb":[[19.5,10.82],[12,18.2],[8.8,34.23]],"id":41419659},{"atb":[[38,5.41],[19.5,10.82],[14.5,19.77]],"id":41419626},{"atb":[[36,5.71],[19,11.12],[14,20.53]],"id":41419639},{"atb":[[16,17.8],[44,4.65],[22,9.53]],"id":41419606},{"atb":[[18.5,11.44],[11,20.02],[8.4,36.07]],"id":41419635},{"atb":[[9.6,23.28],[5.3,62.08],[6.6,35.75]],"id":41419585},{"atb":[[260,0.77],[110,1.83],[55,4.94]],"id":41419610},{"atb":[[6.8,46.03],[8.8,25.67],[14.5,14.83]],"id":41419656},{"atb":[[100,2.02],[50,5.45],[250,0.8]],"id":41419623},{"atb":[[7.2,43.06],[9.2,24.42],[15.5,13.8]],"id":41419590},{"atb":[[260,0.77],[110,1.83],[55,4.94]],"id":41419652},{"atb":[[16.5,12.91],[11.5,25.42],[28,7.41]],"id":41435528},{"atb":[[38,5.41],[95,2.13],[24,11.6]],"id":41419586},{"atb":[[18.5,11.44],[11,20.02],[8.4,36.07]],"id":41419598},{"atb":[[18,11.77],[10.5,21.07],[8.2,37.08]],"id":41419660},{"atb":[[8,38.14],[17.5,12.13],[10,22.24]],"id":41419627},{"atb":[[17,16.68],[48,4.26],[24,8.7]],"id":41419594},{"atb":[[10.5,28.1],[26,8],[15.5,13.8]],"id":41419640},{"atb":[[18,15.7],[26,8],[55,3.7]],"id":41419607},{"atb":[[6.8,34.52],[9.8,22.75],[5.4,60.67]],"id":28546950},{"atb":[[330,0.6],[180,1.11],[90,2.99]],"id":41419636},{"atb":[[600,0.44],[700,0.28],[850,0.23]],"id":41419603},{"atb":[[40,5.13],[100,2.02],[25,11.12]],"id":41419611},{"atb":[[70,2.9],[38,7.21],[190,1.05]],"id":41419657},{"atb":[[6.4,49.44],[13.5,16.02],[8.4,27.05]],"id":41419591},{"atb":[[18,15.7],[26,8],[55,3.7]],"id":41435525},{"atb":[[10.5,28.1],[26,8],[15.5,13.8]],"id":41419620},{"atb":[[36,5.71],[19,11.12],[14,20.53]],"id":41419587},{"atb":[[42,4.88],[21,10.01],[15.5,18.41]],"id":41419632},{"atb":[[32,8.61],[160,1.26],[55,3.7]],"id":41419599},{"atb":[[9.2,32.55],[21,10.01],[13,16.68]],"id":41419628},{"atb":[[600,0.44],[700,0.28],[850,0.23]],"id":41419608},{"atb":[[70,2.9],[19.5,14.43],[29,7.14]],"id":41419637},{"atb":[[260,1.03],[360,0.55],[510,0.39]],"id":41419604},{"atb":[[32,6.46],[80,2.53],[21,13.34]],"id":41419612},{"atb":[[16,17.8],[44,4.65],[22,9.53]],"id":41419625},{"atb":[[5.6,58.04],[7.2,32.29],[10.5,21.07]],"id":41419592},{"atb":[[9,33.37],[20,10.53],[12.5,17.41]],"id":41419654},{"atb":[[17,12.51],[12,24.27],[29,7.14]],"id":41435526},{"atb":[[17.5,12.13],[12.5,23.21],[30,6.9]],"id":41419621},{"atb":[[10.5,28.1],[26,8],[15.5,13.8]],"id":41419633},{"atb":[[130,1.55],[65,4.17],[280,0.71]],"id":41419600},{"atb":[[290,0.69],[190,1.41],[440,0.45]],"id":41419629},{"atb":[[16.5,12.91],[11.5,25.42],[28,7.41]],"id":41419596}],"con":true,"img":true}]}
{"op":"mcm","clk":"5352823544","pt":1646201802744,"mc":[{"id":"1.195503871","marketDefinition":{"bspMarket":false,"turnInPlayEnabled":false,"persistenceEnabled":false,"marketBaseRate":7.0,"eventId":"31272499","eventTypeId":"4339","numberOfWinners":1,"bettingType":"ODDS","marketType":"EXACTA","marketTime":"2022-03-02T12:10:00.000Z","suspendTime":"2022-03-02T12:10:00.000Z","bspReconciled":false,"complete":true,"inPlay":false,"crossMatching":false,"runnersVoidable":false,"numberOfActiveRunners":56,"betDelay":0,"status":"OPEN","runners":[{"status":"ACTIVE","sortPriority":1,"id":41419585,"name":"1 - 2"},{"status":"ACTIVE","sortPriority":2,"id":41419586,"name":"1 - 3"},{"status":"ACTIVE","sortPriority":3,"id":41419587,"name":"1 - 4"},{"status":"ACTIVE","sortPriority":4,"id":41419589,"name":"1 - 6"},{"status":"ACTIVE","sortPriority":5,"id":41419590,"name":"1 - 7"},{"status":"ACTIVE","sortPriority":6,"id":41419591,"name":"1 - 8"},{"status":"ACTIVE","sortPriority":7,"id":28546943,"name":"1 - 9"},{"status":"ACTIVE","sortPriority":8,"id":41419592,"name":"2 - 1"},{"status":"ACTIVE","sortPriority":9,"id":41419593,"name":"2 - 3"},{"status":"ACTIVE","sortPriority":10,"id":41419594,"name":"2 - 4"},{"status":"ACTIVE","sortPriority":11,"id":41419596,"name":"2 - 6"},{"status":"ACTIVE","sortPriority":12,"id":41419597,"name":"2 - 7"},{"status":"ACTIVE","sortPriority":13,"id":41419598,"name":"2 - 8"},{"status":"ACTIVE","sortPriority":14,"id":41419651,"name":"2 - 9"},{"status":"ACTIVE","sortPriority":15,"id":41419599,"name":"3 - 1"},{"status":"ACTIVE","sortPriority":16,"id":41419600,"name":"3 - 2"},{"status":"ACTIVE","sortPriority":17,"id":41419601,"name":"3 - 4"},{"status":"ACTIVE","sortPriority":18,"id":41419603,"name":"3 - 6"},{"status":"ACTIVE","sortPriority":19,"id":41419604,"name":"3 - 7"},{"status":"ACTIVE","sortPriority":20,"id":41419605,"name":"3 - 8"},{"status":"ACTIVE","sortPriority":21,"id":41419652,"name":"3 - 9"},{"status":"ACTIVE","sortPriority":22,"id":41419606,"name":"4 - 1"},{"status":"ACTIVE","sortPriority":23,"id":41419607,"name":"4 - 2"},{"status":"ACTIVE","sortPriority":24,"id":41419608,"name":"4 - 3"},{"status":"ACTIVE","sortPriority":25,"id":41419610,"name":"4 - 6"},{"status":"ACTIVE","sortPriority":26,"id":41419611,"name":"4 - 7"},{"status":"ACTIVE","sortPriority":27,"id":41419612,"name":"4 - 8"},{"status":"ACTIVE","sortPriority":28,"id":41435525,"name":"4 - 9"},{"status":"ACTIVE","sortPriority":29,"id":41419620,"name":"6 - 1"},{"status":"ACTIVE","sortPriority":30,"id":41419621,"name":"6 - 2"},{"status":"ACTIVE","sortPriority":31,"id":41419622,"name":"6 - 3"},{"status":"ACTIVE","sortPriority":32,"id":41419623,"name":"6 - 4"},{"status":"ACTIVE","sortPriority":33,"id":41419625,"name":"6 - 7"},{"status":"ACTIVE","sortPriority":34,"id":41419626,"name":"6 - 8"},{"status":"ACTIVE","sortPriority":35,"id":41435526,"name":"6 - 9"},{"status":"ACTIVE","sortPriority":36,"id":41419627,"name":"7 - 1"},{"status":"ACTIVE","sortPriority":37,"id":41419628,"name":"7 - 2"},{"status":"ACTIVE","sortPriority":38,"id":41419629,"name":"7 - 3"},{"status":"ACTIVE","sortPriority":39,"id":41419630,"name":"7 - 4"},{"status":"ACTIVE","sortPriority":40,"id":41419632,"name":"7 - 6"},{"status":"ACTIVE","sortPriority":41,"id":41419633,"name":"7 - 8"},{"status":"ACTIVE","sortPriority":42,"id":41419654,"name":"7 - 9"},{"status":"ACTIVE","sortPriority":43,"id":41419634,"name":"8 - 1"},{"status":"ACTIVE","sortPriority":44,"id":41419635,"name":"8 - 2"},{"status":"ACTIVE","sortPriority":45,"id":41419636,"name":"8 - 3"},{"status":"ACTIVE","sortPriority":46,"id":41419637,"name":"8 - 4"},{"status":"ACTIVE","sortPriority":47,"id":41419639,"name":"8 - 6"},{"status":"ACTIVE","sortPriority":48,"id":41419640,"name":"8 - 7"},{"status":"ACTIVE","sortPriority":49,"id":41419655,"name":"8 - 9"},{"status":"ACTIVE","sortPriority":50,"id":28546950,"name":"9 - 1"},{"status":"ACTIVE","sortPriority":51,"id":41419656,"name":"9 - 2"},{"status":"ACTIVE","sortPriority":52,"id":41419657,"name":"9 - 3"},{"status":"ACTIVE","sortPriority":53,"id":41435527,"name":"9 - 4"},{"status":"ACTIVE","sortPriority":54,"id":41435528,"name":"9 - 6"},{"status":"ACTIVE","sortPriority":55,"id":41419659,"name":"9 - 7"},{"status":"ACTIVE","sortPriority":56,"id":41419660,"name":"9 - 8"}],"regulators":["MR_INT"],"venue":"Rockhampton","countryCode":"AU","discountAllowed":true,"timezone":"Australia/Queensland","openDate":"2022-03-02T08:28:00.000Z","version":4382597910,"name":"Exacta","eventName":"Rockhampton (AUS) 2nd Mar"},"rc":[{"atb":[[150,1.79],[400,0.5],[250,0.8]],"id":41419605},{"atb":[[9,25.01],[7,44.48],[15,14.29]],"id":41419634},{"atb":[[80,2.53],[42,6.5],[210,0.95]],"id":41419593},{"atb":[[18,11.77],[10.5,21.07],[8.2,37.06]],"id":41419655},{"atb":[[600,0.44],[700,0.28],[850,0.23]],"id":41419622},{"atb":[[22,9.53],[13.5,16.01],[9.4,31.77]],"id":41419589},{"atb":[[16.5,17.22],[46,4.44],[23,9.09]],"id":41435527},{"atb":[[6.8,46.01],[8.8,25.66],[14.5,14.82]],"id":41419651},{"atb":[[600,0.44],[700,0.28],[850,0.23]],"id":41419601},{"atb":[[36,5.71],[90,2.24],[23,12.13]],"id":41419630},{"atb":[[9,33.36],[20,10.53],[12.5,17.4]],"id":41419597},{"atb":[[6.4,37.06],[5.2,63.54],[9.4,23.82]],"id":28546943},{"atb":[[19.5,10.82],[12,18.19],[8.8,34.21]],"id":41419659},{"atb":[[38,5.41],[19.5,10.82],[14.5,19.77]],"id":41419626},{"atb":[[36,5.71],[19,11.12],[14,20.52]],"id":41419639},{"atb":[[16,17.79],[44,4.65],[22,9.53]],"id":41419606},{"atb":[[18.5,11.43],[11,20.01],[8.4,36.06]],"id":41419635},{"atb":[[9.6,23.27],[5.3,62.06],[6.6,35.74]],"id":41419585},{"atb":[[260,0.77],[110,1.83],[55,4.94]],"id":41419610},{"atb":[[6.8,46.01],[8.8,25.66],[14.5,14.82]],"id":41419656},{"atb":[[100,2.02],[50,5.44],[250,0.8]],"id":41419623},{"atb":[[7.2,43.04],[9.2,24.41],[15.5,13.8]],"id":41419590},{"atb":[[260,0.77],[110,1.83],[55,4.94]],"id":41419652},{"atb":[[16.5,12.91],[11.5,25.41],[28,7.41]],"id":41435528},{"atb":[[38,5.41],[95,2.12],[24,11.6]],"id":41419586},{"atb":[[18.5,11.43],[11,20.01],[8.4,36.06]],"id":41419598},{"atb":[[18,11.77],[10.5,21.07],[8.2,37.06]],"id":41419660},{"atb":[[8,38.12],[17.5,12.13],[10,22.23]],"id":41419627},{"atb":[[17,16.68],[48,4.25],[24,8.7]],"id":41419594},{"atb":[[10.5,28.09],[26,8],[15.5,13.8]],"id":41419640},{"atb":[[18,15.69],[26,8],[55,3.7]],"id":41419607},{"atb":[[6.8,34.51],[9.8,22.74],[5.4,60.65]],"id":28546950},{"atb":[[330,0.6],[180,1.11],[90,2.99]],"id":41419636},{"atb":[[600,0.44],[700,0.28],[850,0.23]],"id":41419603},{"atb":[[40,5.13],[100,2.02],[25,11.12]],"id":41419611},{"atb":[[70,2.89],[38,7.21],[190,1.05]],"id":41419657},{"atb":[[6.4,49.42],[13.5,16.01],[8.4,27.04]],"id":41419591},{"atb":[[18,15.69],[26,8],[55,3.7]],"id":41435525},{"atb":[[10.5,28.09],[26,8],[15.5,13.8]],"id":41419620},{"atb":[[36,5.71],[19,11.12],[14,20.52]],"id":41419587},{"atb":[[42,4.88],[21,10],[15.5,18.4]],"id":41419632},{"atb":[[32,8.61],[160,1.26],[55,3.7]],"id":41419599},{"atb":[[9.2,32.54],[21,10],[13,16.68]],"id":41419628},{"atb":[[600,0.44],[700,0.28],[850,0.23]],"id":41419608},{"atb":[[70,2.89],[19.5,14.42],[29,7.14]],"id":41419637},{"atb":[[260,1.03],[360,0.55],[510,0.39]],"id":41419604},{"atb":[[32,6.45],[80,2.53],[21,13.34]],"id":41419612},{"atb":[[16,17.79],[44,4.65],[22,9.53]],"id":41419625},{"atb":[[5.6,58.01],[7.2,32.28],[10.5,21.07]],"id":41419592},{"atb":[[9,33.36],[20,10.53],[12.5,17.4]],"id":41419654},{"atb":[[17,12.5],[12,24.26],[29,7.14]],"id":41435526},{"atb":[[17.5,12.13],[12.5,23.2],[30,6.9]],"id":41419621},{"atb":[[10.5,28.09],[26,8],[15.5,13.8]],"id":41419633},{"atb":[[130,1.55],[65,4.17],[280,0.71]],"id":41419600},{"atb":[[290,0.69],[190,1.41],[440,0.45]],"id":41419629},{"atb":[[16.5,12.91],[11.5,25.41],[28,7.41]],"id":41419596}],"con":true,"img":true}]}
{"op":"mcm","clk":"5353028914","pt":1646207202761,"mc":[{"id":"1.195503871","marketDefinition":{"bspMarket":false,"turnInPlayEnabled":false,"persistenceEnabled":false,"marketBaseRate":7.0,"eventId":"31272499","eventTypeId":"4339","numberOfWinners":1,"bettingType":"ODDS","marketType":"EXACTA","marketTime":"2022-03-02T12:10:00.000Z","suspendTime":"2022-03-02T12:10:00.000Z","bspReconciled":false,"complete":true,"inPlay":false,"crossMatching":false,"runnersVoidable":false,"numberOfActiveRunners":56,"betDelay":0,"status":"OPEN","runners":[{"status":"ACTIVE","sortPriority":1,"id":41419585,"name":"1 - 2"},{"status":"ACTIVE","sortPriority":2,"id":41419586,"name":"1 - 3"},{"status":"ACTIVE","sortPriority":3,"id":41419587,"name":"1 - 4"},{"status":"ACTIVE","sortPriority":4,"id":41419589,"name":"1 - 6"},{"status":"ACTIVE","sortPriority":5,"id":41419590,"name":"1 - 7"},{"status":"ACTIVE","sortPriority":6,"id":41419591,"name":"1 - 8"},{"status":"ACTIVE","sortPriority":7,"id":28546943,"name":"1 - 9"},{"status":"ACTIVE","sortPriority":8,"id":41419592,"name":"2 - 1"},{"status":"ACTIVE","sortPriority":9,"id":41419593,"name":"2 - 3"},{"status":"ACTIVE","sortPriority":10,"id":41419594,"name":"2 - 4"},{"status":"ACTIVE","sortPriority":11,"id":41419596,"name":"2 - 6"},{"status":"ACTIVE","sortPriority":12,"id":41419597,"name":"2 - 7"},{"status":"ACTIVE","sortPriority":13,"id":41419598,"name":"2 - 8"},{"status":"ACTIVE","sortPriority":14,"id":41419651,"name":"2 - 9"},{"status":"ACTIVE","sortPriority":15,"id":41419599,"name":"3 - 1"},{"status":"ACTIVE","sortPriority":16,"id":41419600,"name":"3 - 2"},{"status":"ACTIVE","sortPriority":17,"id":41419601,"name":"3 - 4"},{"status":"ACTIVE","sortPriority":18,"id":41419603,"name":"3 - 6"},{"status":"ACTIVE","sortPriority":19,"id":41419604,"name":"3 - 7"},{"status":"ACTIVE","sortPriority":20,"id":41419605,"name":"3 - 8"},{"status":"ACTIVE","sortPriority":21,"id":41419652,"name":"3 - 9"},{"status":"ACTIVE","sortPriority":22,"id":41419606,"name":"4 - 1"},{"status":"ACTIVE","sortPriority":23,"id":41419607,"name":"4 - 2"},{"status":"ACTIVE","sortPriority":24,"id":41419608,"name":"4 - 3"},{"status":"ACTIVE","sortPriority":25,"id":41419610,"name":"4 - 6"},{"status":"ACTIVE","sortPriority":26,"id":41419611,"name":"4 - 7"},{"status":"ACTIVE","sortPriority":27,"id":41419612,"name":"4 - 8"},{"status":"ACTIVE","sortPriority":28,"id":41435525,"name":"4 - 9"},{"status":"ACTIVE","sortPriority":29,"id":41419620,"name":"6 - 1"},{"status":"ACTIVE","sortPriority":30,"id":41419621,"name":"6 - 2"},{"status":"ACTIVE","sortPriority":31,"id":41419622,"name":"6 - 3"},{"status":"ACTIVE","sortPriority":32,"id":41419623,"name":"6 - 4"},{"status":"ACTIVE","sortPriority":33,"id":41419625,"name":"6 - 7"},{"status":"ACTIVE","sortPriority":34,"id":41419626,"name":"6 - 8"},{"status":"ACTIVE","sortPriority":35,"id":41435526,"name":"6 - 9"},{"status":"ACTIVE","sortPriority":36,"id":41419627,"name":"7 - 1"},{"status":"ACTIVE","sortPriority":37,"id":41419628,"name":"7 - 2"},{"status":"ACTIVE","sortPriority":38,"id":41419629,"name":"7 - 3"},{"status":"ACTIVE","sortPriority":39,"id":41419630,"name":"7 - 4"},{"status":"ACTIVE","sortPriority":40,"id":41419632,"name":"7 - 6"},{"status":"ACTIVE","sortPriority":41,"id":41419633,"name":"7 - 8"},{"status":"ACTIVE","sortPriority":42,"id":41419654,"name":"7 - 9"},{"status":"ACTIVE","sortPriority":43,"id":41419634,"name":"8 - 1"},{"status":"ACTIVE","sortPriority":44,"id":41419635,"name":"8 - 2"},{"status":"ACTIVE","sortPriority":45,"id":41419636,"name":"8 - 3"},{"status":"ACTIVE","sortPriority":46,"id":41419637,"name":"8 - 4"},{"status":"ACTIVE","sortPriority":47,"id":41419639,"name":"8 - 6"},{"status":"ACTIVE","sortPriority":48,"id":41419640,"name":"8 - 7"},{"status":"ACTIVE","sortPriority":49,"id":41419655,"name":"8 - 9"},{"status":"ACTIVE","sortPriority":50,"id":28546950,"name":"9 - 1"},{"status":"ACTIVE","sortPriority":51,"id":41419656,"name":"9 - 2"},{"status":"ACTIVE","sortPriority":52,"id":41419657,"name":"9 - 3"},{"status":"ACTIVE","sortPriority":53,"id":41435527,"name":"9 - 4"},{"status":"ACTIVE","sortPriority":54,"id":41435528,"name":"9 - 6"},{"status":"ACTIVE","sortPriority":55,"id":41419659,"name":"9 - 7"},{"status":"ACTIVE","sortPriority":56,"id":41419660,"name":"9 - 8"}],"regulators":["MR_INT"],"venue":"Rockhampton","countryCode":"AU","discountAllowed":true,"timezone":"Australia/Queensland","openDate":"2022-03-02T08:28:00.000Z","version":4382597910,"name":"Exacta","eventName":"Rockhampton (AUS) 2nd Mar"},"rc":[{"atb":[[150,1.79],[400,0.5],[250,0.8]],"id":41419605},{"atb":[[9,25.01],[7,44.47],[15,14.29]],"id":41419634},{"atb":[[80,2.53],[42,6.5],[210,0.95]],"id":41419593},{"atb":[[18,11.76],[10.5,21.06],[8.2,37.05]],"id":41419655},{"atb":[[600,0.44],[700,0.28],[850,0.23]],"id":41419622},{"atb":[[22,9.53],[13.5,16],[9.4,31.76]],"id":41419589},{"atb":[[16.5,17.21],[46,4.44],[23,9.09]],"id":41435527},{"atb":[[6.8,46],[8.8,25.65],[14.5,14.82]],"id":41419651},{"atb":[[600,0.44],[700,0.28],[850,0.23]],"id":41419601},{"atb":[[36,5.71],[90,2.24],[23,12.12]],"id":41419630},{"atb":[[9,33.35],[20,10.52],[12.5,17.4]],"id":41419597},{"atb":[[6.4,37.05],[5.2,63.52],[9.4,23.82]],"id":28546943},{"atb":[[19.5,10.81],[12,18.19],[8.8,34.2]],"id":41419659},{"atb":[[38,5.4],[19.5,10.81],[14.5,19.76]],"id":41419626},{"atb":[[36,5.71],[19,11.11],[14,20.52]],"id":41419639},{"atb":[[16,17.78],[44,4.65],[22,9.53]],"id":41419606},{"atb":[[18.5,11.43],[11,20.01],[8.4,36.05]],"id":41419635},{"atb":[[9.6,23.26],[5.3,62.04],[6.6,35.73]],"id":41419585},{"atb":[[260,0.77],[110,1.83],[55,4.93]],"id":41419610},{"atb":[[6.8,46],[8.8,25.65],[14.5,14.82]],"id":41419656},{"atb":[[100,2.01],[50,5.44],[250,0.8]],"id":41419623},{"atb":[[7.2,43.03],[9.2,24.4],[15.5,13.79]],"id":41419590},{"atb":[[260,0.77],[110,1.83],[55,4.93]],"id":41419652},{"atb":[[16.5,12.9],[11.5,25.4],[28,7.41]],"id":41435528},{"atb":[[38,5.4],[95,2.12],[24,11.59]],"id":41419586},{"atb":[[18.5,11.43],[11,20.01],[8.4,36.05]],"id":41419598},{"atb":[[18,11.76],[10.5,21.06],[8.2,37.05]],"id":41419660},{"atb":[[8,38.11],[17.5,12.12],[10,22.23]],"id":41419627},{"atb":[[17,16.67],[48,4.25],[24,8.7]],"id":41419594},{"atb":[[10.5,28.08],[26,8],[15.5,13.79]],"id":41419640},{"atb":[[18,15.69],[26,8],[55,3.7]],"id":41419607},{"atb":[[6.8,34.5],[9.8,22.74],[5.4,60.63]],"id":28546950},{"atb":[[330,0.6],[180,1.11],[90,2.99]],"id":41419636},{"atb":[[600,0.44],[700,0.28],[850,0.23]],"id":41419603},{"atb":[[40,5.13],[100,2.01],[25,11.11]],"id":41419611},{"atb":[[70,2.89],[38,7.21],[190,1.05]],"id":41419657},{"atb":[[6.4,49.41],[13.5,16],[8.4,27.04]],"id":41419591},{"atb":[[18,15.69],[26,8],[55,3.7]],"id":41435525},{"atb":[[10.5,28.08],[26,8],[15.5,13.79]],"id":41419620},{"atb":[[36,5.71],[19,11.11],[14,20.52]],"id":41419587},{"atb":[[42,4.87],[21,10],[15.5,18.4]],"id":41419632},{"atb":[[32,8.6],[160,1.26],[55,3.7]],"id":41419599},{"atb":[[9.2,32.53],[21,10],[13,16.67]],"id":41419628},{"atb":[[600,0.44],[700,0.28],[850,0.23]],"id":41419608},{"atb":[[70,2.89],[19.5,14.42],[29,7.14]],"id":41419637},{"atb":[[260,1.03],[360,0.55],[510,0.39]],"id":41419604},{"atb":[[32,6.45],[80,2.53],[21,13.34]],"id":41419612},{"atb":[[16,17.78],[44,4.65],[22,9.53]],"id":41419625},{"atb":[[5.6,58],[7.2,32.27],[10.5,21.06]],"id":41419592},{"atb":[[9,33.35],[20,10.52],[12.5,17.4]],"id":41419654},{"atb":[[17,12.5],[12,24.25],[29,7.14]],"id":41435526},{"atb":[[17.5,12.12],[12.5,23.19],[30,6.89]],"id":41419621},{"atb":[[10.5,28.08],[26,8],[15.5,13.79]],"id":41419633},{"atb":[[130,1.55],[65,4.17],[280,0.71]],"id":41419600},{"atb":[[290,0.69],[190,1.41],[440,0.45]],"id":41419629},{"atb":[[16.5,12.9],[11.5,25.4],[28,7.41]],"id":41419596}],"con":true,"img":true}]}
{"op":"mcm","clk":"5353300301","pt":1646212602763,"mc":[{"id":"1.195503871","marketDefinition":{"bspMarket":false,"turnInPlayEnabled":false,"persistenceEnabled":false,"marketBaseRate":7.0,"eventId":"31272499","eventTypeId":"4339","numberOfWinners":1,"bettingType":"ODDS","marketType":"EXACTA","marketTime":"2022-03-02T12:10:00.000Z","suspendTime":"2022-03-02T12:10:00.000Z","bspReconciled":false,"complete":true,"inPlay":false,"crossMatching":false,"runnersVoidable":false,"numberOfActiveRunners":56,"betDelay":0,"status":"OPEN","runners":[{"status":"ACTIVE","sortPriority":1,"id":41419585,"name":"1 - 2"},{"status":"ACTIVE","sortPriority":2,"id":41419586,"name":"1 - 3"},{"status":"ACTIVE","sortPriority":3,"id":41419587,"name":"1 - 4"},{"status":"ACTIVE","sortPriority":4,"id":41419589,"name":"1 - 6"},{"status":"ACTIVE","sortPriority":5,"id":41419590,"name":"1 - 7"},{"status":"ACTIVE","sortPriority":6,"id":41419591,"name":"1 - 8"},{"status":"ACTIVE","sortPriority":7,"id":28546943,"name":"1 - 9"},{"status":"ACTIVE","sortPriority":8,"id":41419592,"name":"2 - 1"},{"status":"ACTIVE","sortPriority":9,"id":41419593,"name":"2 - 3"},{"status":"ACTIVE","sortPriority":10,"id":41419594,"name":"2 - 4"},{"status":"ACTIVE","sortPriority":11,"id":41419596,"name":"2 - 6"},{"status":"ACTIVE","sortPriority":12,"id":41419597,"name":"2 - 7"},{"status":"ACTIVE","sortPriority":13,"id":41419598,"name":"2 - 8"},{"status":"ACTIVE","sortPriority":14,"id":41419651,"name":"2 - 9"},{"status":"ACTIVE","sortPriority":15,"id":41419599,"name":"3 - 1"},{"status":"ACTIVE","sortPriority":16,"id":41419600,"name":"3 - 2"},{"status":"ACTIVE","sortPriority":17,"id":41419601,"name":"3 - 4"},{"status":"ACTIVE","sortPriority":18,"id":41419603,"name":"3 - 6"},{"status":"ACTIVE","sortPriority":19,"id":41419604,"name":"3 - 7"},{"status":"ACTIVE","sortPriority":20,"id":41419605,"name":"3 - 8"},{"status":"ACTIVE","sortPriority":21,"id":41419652,"name":"3 - 9"},{"status":"ACTIVE","sortPriority":22,"id":41419606,"name":"4 - 1"},{"status":"ACTIVE","sortPriority":23,"id":41419607,"name":"4 - 2"},{"status":"ACTIVE","sortPriority":24,"id":41419608,"name":"4 - 3"},{"status":"ACTIVE","sortPriority":25,"id":41419610,"name":"4 - 6"},{"status":"ACTIVE","sortPriority":26,"id":41419611,"name":"4 - 7"},{"status":"ACTIVE","sortPriority":27,"id":41419612,"name":"4 - 8"},{"status":"ACTIVE","sortPriority":28,"id":41435525,"name":"4 - 9"},{"status":"ACTIVE","sortPriority":29,"id":41419620,"name":"6 - 1"},{"status":"ACTIVE","sortPriority":30,"id":41419621,"name":"6 - 2"},{"status":"ACTIVE","sortPriority":31,"id":41419622,"name":"6 - 3"},{"status":"ACTIVE","sortPriority":32,"id":41419623,"name":"6 - 4"},{"status":"ACTIVE","sortPriority":33,"id":41419625,"name":"6 - 7"},{"status":"ACTIVE","sortPriority":34,"id":41419626,"name":"6 - 8"},{"status":"ACTIVE","sortPriority":35,"id":41435526,"name":"6 - 9"},{"status":"ACTIVE","sortPriority":36,"id":41419627,"name":"7 - 1"},{"status":"ACTIVE","sortPriority":37,"id":41419628,"name":"7 - 2"},{"status":"ACTIVE","sortPriority":38,"id":41419629,"name":"7 - 3"},{"status":"ACTIVE","sortPriority":39,"id":41419630,"name":"7 - 4"},{"status":"ACTIVE","sortPriority":40,"id":41419632,"name":"7 - 6"},{"status":"ACTIVE","sortPriority":41,"id":41419633,"name":"7 - 8"},{"status":"ACTIVE","sortPriority":42,"id":41419654,"name":"7 - 9"},{"status":"ACTIVE","sortPriority":43,"id":41419634,"name":"8 - 1"},{"status":"ACTIVE","sortPriority":44,"id":41419635,"name":"8 - 2"},{"status":"ACTIVE","sortPriority":45,"id":41419636,"name":"8 - 3"},{"status":"ACTIVE","sortPriority":46,"id":41419637,"name":"8 - 4"},{"status":"ACTIVE","sortPriority":47,"id":41419639,"name":"8 - 6"},{"status":"ACTIVE","sortPriority":48,"id":41419640,"name":"8 - 7"},{"status":"ACTIVE","sortPriority":49,"id":41419655,"name":"8 - 9"},{"status":"ACTIVE","sortPriority":50,"id":28546950,"name":"9 - 1"},{"status":"ACTIVE","sortPriority":51,"id":41419656,"name":"9 - 2"},{"status":"ACTIVE","sortPriority":52,"id":41419657,"name":"9 - 3"},{"status":"ACTIVE","sortPriority":53,"id":41435527,"name":"9 - 4"},{"status":"ACTIVE","sortPriority":54,"id":41435528,"name":"9 - 6"},{"status":"ACTIVE","sortPriority":55,"id":41419659,"name":"9 - 7"},{"status":"ACTIVE","sortPriority":56,"id":41419660,"name":"9 - 8"}],"regulators":["MR_INT"],"venue":"Rockhampton","countryCode":"AU","discountAllowed":true,"timezone":"Australia/Queensland","openDate":"2022-03-02T08:28:00.000Z","version":4382597910,"name":"Exacta","eventName":"Rockhampton (AUS) 2nd Mar"},"rc":[{"atb":[[150,1.78],[400,0.5],[250,0.8]],"id":41419605},{"atb":[[9,24.97],[7,44.4],[15,14.27]],"id":41419634},{"atb":[[80,2.52],[42,6.49],[210,0.95]],"id":41419593},{"atb":[[18,11.74],[10.5,21.03],[8.2,36.99]],"id":41419655},{"atb":[[600,0.44],[700,0.28],[850,0.23]],"id":41419622},{"atb":[[22,9.51],[13.5,15.98],[9.4,31.71]],"id":41419589},{"atb":[[16.5,17.18],[46,4.44],[23,9.07]],"id":41435527},{"atb":[[6.8,45.93],[8.8,25.61],[14.5,14.8]],"id":41419651},{"atb":[[600,0.44],[700,0.28],[850,0.23]],"id":41419601},{"atb":[[36,5.7],[90,2.24],[23,12.1]],"id":41419630},{"atb":[[9,33.29],[20,10.51],[12.5,17.37]],"id":41419597},{"atb":[[6.4,36.99],[5.2,63.42],[9.4,23.78]],"id":28546943},{"atb":[[19.5,10.8],[12,18.16],[8.8,34.15]],"id":41419659},{"atb":[[38,5.4],[19.5,10.8],[14.5,19.73]],"id":41419626},{"atb":[[36,5.7],[19,11.1],[14,20.49]],"id":41419639},{"atb":[[16,17.76],[44,4.64],[22,9.51]],"id":41419606},{"atb":[[18.5,11.41],[11,19.97],[8.4,35.99]],"id":41419635},{"atb":[[9.6,23.23],[5.3,61.94],[6.6,35.67]],"id":41419585},{"atb":[[260,0.77],[110,1.83],[55,4.93]],"id":41419610},{"atb":[[6.8,45.93],[8.8,25.61],[14.5,14.8]],"id":41419656},{"atb":[[100,2.01],[50,5.43],[250,0.8]],"id":41419623},{"atb":[[7.2,42.96],[9.2,24.36],[15.5,13.77]],"id":41419590},{"atb":[[260,0.77],[110,1.83],[55,4.93]],"id":41419652},{"atb":[[16.5,12.88],[11.5,25.36],[28,7.4]],"id":41435528},{"atb":[[38,5.4],[95,2.12],[24,11.58]],"id":41419586},{"atb":[[18.5,11.41],[11,19.97],[8.4,35.99]],"id":41419598},{"atb":[[18,11.74],[10.5,21.03],[8.2,36.99]],"id":41419660},{"atb":[[8,38.05],[17.5,12.1],[10,22.19]],"id":41419627},{"atb":[[17,16.64],[48,4.25],[24,8.68]],"id":41419594},{"atb":[[10.5,28.03],[26,7.98],[15.5,13.77]],"id":41419640},{"atb":[[18,15.66],[26,7.98],[55,3.7]],"id":41419607},{"atb":[[6.8,34.44],[9.8,22.7],[5.4,60.54]],"id":28546950},{"atb":[[330,0.6],[180,1.11],[90,2.99]],"id":41419636},{"atb":[[600,0.44],[700,0.28],[850,0.23]],"id":41419603},{"atb":[[40,5.12],[100,2.01],[25,11.1]],"id":41419611},{"atb":[[70,2.89],[38,7.19],[190,1.05]],"id":41419657},{"atb":[[6.4,49.33],[13.5,15.98],[8.4,26.99]],"id":41419591},{"atb":[[18,15.66],[26,7.98],[55,3.7]],"id":41435525},{"atb":[[10.5,28.03],[26,7.98],[15.5,13.77]],"id":41419620},{"atb":[[36,5.7],[19,11.1],[14,20.49]],"id":41419587},{"atb":[[42,4.87],[21,9.98],[15.5,18.37]],"id":41419632},{"atb":[[32,8.59],[160,1.25],[55,3.7]],"id":41419599},{"atb":[[9.2,32.48],[21,9.98],[13,16.64]],"id":41419628},{"atb":[[600,0.44],[700,0.28],[850,0.23]],"id":41419608},{"atb":[[70,2.89],[19.5,14.39],[29,7.13]],"id":41419637},{"atb":[[260,1.03],[360,0.55],[510,0.39]],"id":41419604},{"atb":[[32,6.44],[80,2.52],[21,13.31]],"id":41419612},{"atb":[[16,17.76],[44,4.64],[22,9.51]],"id":41419625},{"atb":[[5.6,57.91],[7.2,32.22],[10.5,21.03]],"id":41419592},{"atb":[[9,33.29],[20,10.51],[12.5,17.37]],"id":41419654},{"atb":[[17,12.48],[12,24.21],[29,7.13]],"id":41435526},{"atb":[[17.5,12.1],[12.5,23.16],[30,6.88]],"id":41419621},{"atb":[[10.5,28.03],[26,7.98],[15.5,13.77]],"id":41419633},{"atb":[[130,1.54],[65,4.16],[280,0.71]],"id":41419600},{"atb":[[290,0.69],[190,1.41],[440,0.45]],"id":41419629},{"atb":[[16.5,12.88],[11.5,25.36],[28,7.4]],"id":41419596}],"con":true,"img":true}]}
{"op":"mcm","clk":"5353500937","pt":1646215800357,"mc":[{"id":"1.195503871","rc":[{"atb":[[150,1.78],[400,0.5],[250,0.8]],"id":41419605},{"atb":[[9,24.97],[7,44.4],[15,14.27]],"id":41419634},{"atb":[[80,2.52],[42,6.49],[210,0.95]],"id":41419593},{"atb":[[18,11.74],[10.5,21.03],[8.2,36.99]],"id":41419655},{"atb":[[600,0.44],[700,0.28],[850,0.23]],"id":41419622},{"atb":[[22,9.51],[13.5,15.98],[9.4,31.71]],"id":41419589},{"atb":[[16.5,17.18],[46,4.44],[23,9.07]],"id":41435527},{"atb":[[6.8,45.93],[8.8,25.61],[14.5,14.8]],"id":41419651},{"atb":[[270,2.72],[600,0.44],[700,0.28],[850,0.23],[220,3.26]],"id":41419601},{"atb":[[36,5.7],[90,2.24],[23,12.1]],"id":41419630},{"atb":[[9,33.29],[20,10.51],[12.5,17.37]],"id":41419597},{"atb":[[6.4,36.99],[5.2,63.42],[9.4,23.78]],"id":28546943},{"atb":[[19.5,10.8],[12,18.16],[8.8,34.15]],"id":41419659},{"atb":[[38,5.4],[19.5,10.8],[14.5,19.73]],"id":41419626},{"atb":[[36,5.7],[19,11.1],[14,20.49]],"id":41419639},{"atb":[[16,17.76],[44,4.64],[22,9.51]],"id":41419606},{"atb":[[18.5,11.41],[11,19.97],[8.4,35.99]],"id":41419635},{"atb":[[9.6,23.23],[5.3,61.94],[6.6,35.67]],"id":41419585},{"atb":[[260,0.77],[110,1.83],[55,4.93]],"id":41419610},{"atb":[[6.8,45.93],[8.8,25.61],[14.5,14.8]],"id":41419656},{"atb":[[100,2.01],[50,5.43],[250,0.8]],"id":41419623},{"atb":[[7.2,42.96],[9.2,24.36],[15.5,13.77]],"id":41419590},{"atb":[[260,0.77],[110,1.83],[55,4.93]],"id":41419652},{"atb":[[16.5,12.88],[11.5,25.36],[28,7.4]],"id":41435528},{"atb":[[38,5.4],[95,2.12],[24,11.58]],"id":41419586},{"atb":[[18.5,11.41],[11,19.97],[8.4,35.99]],"id":41419598},{"atb":[[18,11.74],[10.5,21.03],[8.2,36.99]],"id":41419660},{"atb":[[8,38.05],[17.5,12.1],[10,22.19]],"id":41419627},{"atb":[[17,16.64],[48,4.25],[24,8.68]],"id":41419594},{"atb":[[10.5,28.03],[26,7.98],[15.5,13.77]],"id":41419640},{"atb":[[18,15.66],[26,7.98],[55,3.7]],"id":41419607},{"atb":[[6.8,34.44],[9.8,22.7],[5.4,60.54]],"id":28546950},{"atb":[[330,0.6],[180,1.11],[90,2.99]],"id":41419636},{"atb":[[600,0.44],[700,0.28],[850,0.23]],"id":41419603},{"atb":[[40,5.12],[100,2.01],[25,11.1]],"id":41419611},{"atb":[[70,2.89],[38,7.19],[190,1.05]],"id":41419657},{"atb":[[6.4,49.33],[13.5,15.98],[8.4,26.99]],"id":41419591},{"atb":[[18,15.66],[26,7.98],[55,3.7]],"id":41435525},{"atb":[[10.5,28.03],[26,7.98],[15.5,13.77]],"id":41419620},{"atb":[[34,2.72],[36,5.7],[19,11.1],[27,3.26],[14,20.49]],"id":41419587},{"atb":[[42,4.87],[21,9.98],[15.5,18.37]],"id":41419632},{"atb":[[32,8.59],[160,1.25],[55,3.7]],"id":41419599},{"atb":[[9.2,32.48],[21,9.98],[13,16.64]],"id":41419628},{"atb":[[600,0.44],[700,0.28],[850,0.23]],"id":41419608},{"atb":[[70,2.89],[19.5,14.39],[29,7.13]],"id":41419637},{"atb":[[260,1.03],[360,0.55],[510,0.39]],"id":41419604},{"atb":[[32,6.44],[80,2.52],[21,13.31]],"id":41419612},{"atb":[[16,17.76],[44,4.64],[22,9.51]],"id":41419625},{"atb":[[5.6,57.91],[7.2,32.22],[10.5,21.03]],"id":41419592},{"atb":[[9,33.29],[20,10.51],[12.5,17.37]],"id":41419654},{"atb":[[17,12.48],[12,24.21],[29,7.13]],"id":41435526},{"atb":[[17.5,12.1],[12.5,23.16],[30,6.88]],"id":41419621},{"atb":[[10.5,28.03],[26,7.98],[15.5,13.77]],"id":41419633},{"atb":[[130,1.54],[65,4.16],[280,0.71]],"id":41419600},{"atb":[[290,0.69],[190,1.41],[440,0.45]],"id":41419629},{"atb":[[16.5,12.88],[11.5,25.36],[28,7.4]],"id":41419596}],"con":true,"img":false}]}
{"op":"mcm","clk":"5353500945","pt":1646215800512,"mc":[{"id":"1.195503871","rc":[{"atb":[[140,2.72],[95,3.26]],"id":41419605},{"atb":[[17,3.26],[19.5,2.72]],"id":41419634},{"atb":[[44,3.26],[60,2.72]],"id":41419593},{"atb":[[21,3.26],[26,2.72]],"id":41419655},{"atb":[[130,2.72],[90,3.26]],"id":41419622},{"atb":[[19,3.26],[23,2.72]],"id":41419589},{"atb":[[40,3.26],[50,2.72]],"id":41435527},{"atb":[[16.5,3.26],[19,2.72]],"id":41419651},{"atb":[[70,2.72],[48,3.26]],"id":41419630},{"atb":[[18.5,3.26],[22,2.72]],"id":41419597},{"atb":[[11,3.26],[13.5,2.72]],"id":28546943},{"atb":[[22,3.26],[27,2.72]],"id":41419659},{"atb":[[42,3.26],[55,2.72]],"id":41419626},{"atb":[[40,2.72],[30,3.26]],"id":41419639},{"atb":[[65,2.72],[46,3.26]],"id":41419606},{"atb":[[19.5,3.26],[24,2.72]],"id":41419635},{"atb":[[12,2.72],[9.8,3.26]],"id":41419585},{"atb":[[85,3.26],[120,2.72]],"id":41419610},{"atb":[[18,3.26],[21,2.72]],"id":41419656},{"atb":[[70,3.26],[95,2.72]],"id":41419623},{"atb":[[17.5,2.72],[15,3.26]],"id":41419590},{"atb":[[140,2.72],[95,3.26]],"id":41419652},{"atb":[[36,2.72],[28,10.67]],"id":41435528},{"atb":[[36,3.26],[46,2.72]],"id":41419586},{"atb":[[18,3.26],[21,2.72]],"id":41419598},{"atb":[[20,3.26],[25,2.72]],"id":41419660},{"atb":[[23,3.26],[28,2.72]],"id":41419627},{"atb":[[34,3.26],[44,2.72]],"id":41419594},{"atb":[[34,2.72],[27,3.26]],"id":41419640},{"atb":[[75,2.72],[50,3.26]],"id":41419607},{"atb":[[17,2.72],[14.5,3.26]],"id":28546950},{"atb":[[75,2.72],[50,3.26]],"id":41419636},{"atb":[[150,3.26],[200,2.72]],"id":41419603},{"atb":[[75,3.26],[100,4.74]],"id":41419611},{"atb":[[70,5.61],[48,3.26]],"id":41419657},{"atb":[[12,3.26],[14.5,2.72]],"id":41419591},{"atb":[[80,2.72],[55,6.97]],"id":41435525},{"atb":[[40,2.72],[30,3.26]],"id":41419620},{"atb":[[42,8.14],[55,2.72]],"id":41419632},{"atb":[[80,3.26],[110,2.72]],"id":41419599},{"atb":[[32,2.72],[26,3.26]],"id":41419628},{"atb":[[170,3.26],[220,2.72]],"id":41419608},{"atb":[[42,3.26],[55,2.72]],"id":41419637},{"atb":[[160,2.72],[110,3.26]],"id":41419604},{"atb":[[85,2.72],[60,3.26]],"id":41419612},{"atb":[[44,7.91],[60,2.72]],"id":41419625},{"atb":[[11.5,3.26],[14,2.72]],"id":41419592},{"atb":[[36,2.72],[28,3.26]],"id":41419654},{"atb":[[38,3.26],[48,2.72]],"id":41435526},{"atb":[[36,3.26],[46,2.72]],"id":41419621},{"atb":[[38,2.72],[29,3.26]],"id":41419633},{"atb":[[130,4.27],[90,3.26]],"id":41419600},{"atb":[[70,3.26],[95,2.72]],"id":41419629},{"atb":[[32,2.72],[26,3.26]],"id":41419596}],"con":true,"img":false}]}
{"op":"mcm","clk":"5353508114","pt":1646215887368,"mc":[{"id":"1.195503871","rc":[{"atb":[[150,0],[400,0],[250,0]],"id":41419605},{"atb":[[80,0],[42,0],[210,0]],"id":41419593},{"atb":[[22,0],[13.5,0],[9.4,0]],"id":41419589},{"atb":[[600,0],[700,0],[850,0]],"id":41419601},{"atb":[[9,0],[20,0],[12.5,0]],"id":41419597},{"atb":[[6.4,0],[5.2,0],[9.4,0]],"id":28546943},{"atb":[[9.6,0],[5.3,0],[6.6,0]],"id":41419585},{"atb":[[7.2,0],[9.2,0],[15.5,0]],"id":41419590},{"atb":[[38,0],[95,0],[24,0]],"id":41419586},{"atb":[[18.5,0],[11,0],[8.4,0]],"id":41419598},{"atb":[[17,0],[48,0],[24,0]],"id":41419594},{"atb":[[6.8,0],[9.8,0],[5.4,0]],"id":28546950},{"atb":[[600,0],[700,0],[850,0]],"id":41419603},{"atb":[[6.4,0],[13.5,0],[8.4,0]],"id":41419591},{"atb":[[36,0],[19,0],[14,0]],"id":41419587},{"atb":[[32,0],[160,0],[55,0]],"id":41419599},{"atb":[[260,0],[360,0],[510,0]],"id":41419604},{"atb":[[5.6,0],[7.2,0],[10.5,0]],"id":41419592},{"atb":[[130,2.72],[65,0],[280,0]],"id":41419600},{"atb":[[16.5,0],[11.5,0],[28,0]],"id":41419596}],"con":true,"img":false}]}
{"op":"mcm","clk":"5353508124","pt":1646215887481,"mc":[{"id":"1.195503871","rc":[{"atb":[[9,0],[7,0],[15,0]],"id":41419634},{"atb":[[600,0],[700,0],[850,0]],"id":41419622},{"atb":[[36,0],[90,0],[23,0]],"id":41419630},{"atb":[[38,0],[19.5,0],[14.5,0]],"id":41419626},{"atb":[[16,0],[44,0],[22,0]],"id":41419606},{"atb":[[18.5,0],[11,0],[8.4,0]],"id":41419635},{"atb":[[260,0],[110,0],[55,0]],"id":41419610},{"atb":[[100,0],[50,0],[250,0]],"id":41419623},{"atb":[[8,0],[17.5,0],[10,0]],"id":41419627},{"atb":[[18,0],[26,0],[55,0]],"id":41419607},{"atb":[[40,0],[100,2.72],[25,0]],"id":41419611},{"atb":[[10.5,0],[26,0],[15.5,0]],"id":41419620},{"atb":[[42,3.26],[21,0],[15.5,0]],"id":41419632},{"atb":[[9.2,0],[21,0],[13,0]],"id":41419628},{"atb":[[600,0],[700,0],[850,0]],"id":41419608},{"atb":[[32,0],[80,0],[21,0]],"id":41419612},{"atb":[[16,0],[44,3.26],[22,0]],"id":41419625},{"atb":[[17.5,0],[12.5,0],[30,0]],"id":41419621},{"atb":[[10.5,0],[26,0],[15.5,0]],"id":41419633},{"atb":[[290,0],[190,0],[440,0]],"id":41419629}],"con":true,"img":false}]}
{"op":"mcm","clk":"5353508140","pt":1646215887692,"mc":[{"id":"1.195503871","rc":[{"atb":[[18,0],[10.5,0],[8.2,0]],"id":41419655},{"atb":[[16.5,0],[46,0],[23,0]],"id":41435527},{"atb":[[6.8,0],[8.8,0],[14.5,0]],"id":41419651},{"atb":[[19.5,0],[12,0],[8.8,0]],"id":41419659},{"atb":[[36,0],[19,0],[14,0]],"id":41419639},{"atb":[[6.8,0],[8.8,0],[14.5,0]],"id":41419656},{"atb":[[260,0],[110,0],[55,0]],"id":41419652},{"atb":[[16.5,0],[11.5,0],[28,3.26]],"id":41435528},{"atb":[[18,0],[10.5,0],[8.2,0]],"id":41419660},{"atb":[[10.5,0],[26,0],[15.5,0]],"id":41419640},{"atb":[[330,0],[180,0],[90,0]],"id":41419636},{"atb":[[70,2.72],[38,0],[190,0]],"id":41419657},{"atb":[[18,0],[26,0],[55,3.26]],"id":41435525},{"atb":[[70,0],[19.5,0],[29,0]],"id":41419637},{"atb":[[9,0],[20,0],[12.5,0]],"id":41419654},{"atb":[[17,0],[12,0],[29,0]],"id":41435526}],"con":true,"img":false}]}
{"op":"mcm","clk":"5353509926","pt":1646215907718,"mc":[{"id":"1.195503871","rc":[{"atb":[[140,4.64],[390,0.51],[240,0.83]],"id":41419605},{"atb":[[6.8,45.93],[8.8,25.61],[14.5,14.8]],"id":41419634},{"atb":[[90,2.24],[46,5.91],[230,0.87]],"id":41419593},{"atb":[[18,11.74],[10.5,21.03],[8.2,36.99]],"id":41419655},{"atb":[[600,0.44],[700,0.28],[850,0.23]],"id":41419622},{"atb":[[9.2,32.48],[21,9.98],[13,16.64]],"id":41419589},{"atb":[[16.5,17.18],[46,4.44],[23,9.07]],"id":41435527},{"atb":[[7.2,42.96],[9.2,24.36],[15.5,13.77]],"id":41419651},{"atb":[[600,0.44],[700,0.28],[850,0.23]],"id":41419601},{"atb":[[34,6.05],[85,2.37],[22,12.68]],"id":41419630},{"atb":[[9.2,32.48],[21,9.98],[13,16.64]],"id":41419597},{"atb":[[5.1,64.97],[9.2,24.36],[6.2,38.42]],"id":28546943},{"atb":[[8.6,35.05],[19,11.1],[11.5,19.02]],"id":41419659},{"atb":[[38,5.4],[19.5,10.8],[14.5,19.73]],"id":41419626},{"atb":[[34,6.05],[18.5,11.41],[13.5,21.3]],"id":41419639},{"atb":[[16,17.76],[44,4.64],[22,9.51]],"id":41419606},{"atb":[[8.6,35.05],[19,11.1],[11.5,19.02]],"id":41419635},{"atb":[[10,22.19],[5.5,59.19],[7,33.29]],"id":41419585},{"atb":[[100,2.01],[50,5.43],[250,0.8]],"id":41419610},{"atb":[[9,24.97],[7,44.4],[15,14.27]],"id":41419656},{"atb":[[95,4.85],[48,5.66],[240,0.83]],"id":41419623},{"atb":[[9,24.97],[7,44.4],[15,17.54]],"id":41419590},{"atb":[[100,2.01],[50,5.43],[250,0.8]],"id":41419652},{"atb":[[16,13.31],[11,26.63],[27,7.68]],"id":41435528},{"atb":[[36,8.97],[90,2.24],[23,12.1]],"id":41419586},{"atb":[[8.6,35.05],[19,11.1],[11.5,19.02]],"id":41419598},{"atb":[[8,38.05],[17.5,12.1],[10,22.19]],"id":41419660},{"atb":[[17,12.48],[9.8,22.7],[7.8,39.17]],"id":41419627},{"atb":[[17.5,16.14],[50,4.07],[25,8.32]],"id":41419594},{"atb":[[10.5,28.03],[26,7.98],[15.5,13.77]],"id":41419640},{"atb":[[18.5,15.22],[27,7.68],[60,3.38]],"id":41419607},{"atb":[[9.6,23.23],[5.3,61.94],[6.6,35.67]],"id":28546950},{"atb":[[320,0.62],[170,1.18],[85,3.17]],"id":41419636},{"atb":[[600,0.44],[700,0.28],[850,0.23]],"id":41419603},{"atb":[[38,5.4],[95,2.12],[24,11.58]],"id":41419611},{"atb":[[65,3.12],[36,7.61],[180,1.11]],"id":41419657},{"atb":[[6.2,51.22],[8.2,27.75],[13,16.64]],"id":41419591},{"atb":[[17.5,16.14],[50,4.07],[25,8.32]],"id":41435525},{"atb":[[10.5,28.03],[26,7.98],[15.5,13.77]],"id":41419620},{"atb":[[36,5.7],[19,11.1],[14,20.49]],"id":41419587},{"atb":[[42,8.14],[21,9.98],[15.5,18.37]],"id":41419632},{"atb":[[150,1.34],[50,4.07],[30,9.18]],"id":41419599},{"atb":[[22,9.51],[13.5,15.98],[9.4,31.71]],"id":41419628},{"atb":[[600,0.44],[700,0.28],[850,0.23]],"id":41419608},{"atb":[[65,3.12],[19,14.8],[28,7.4]],"id":41419637},{"atb":[[340,0.58],[490,0.4],[240,1.11]],"id":41419604},{"atb":[[75,2.69],[20,14.02],[30,6.88]],"id":41419612},{"atb":[[42,4.87],[21,9.98],[15.5,18.37]],"id":41419625},{"atb":[[12,18.16],[7.8,29.38],[5.9,54.36]],"id":41419592},{"atb":[[9,33.29],[20,10.51],[12.5,17.37]],"id":41419654},{"atb":[[17,12.48],[12,24.21],[29,7.13]],"id":41435526},{"atb":[[32,6.44],[18,11.74],[13,22.19]],"id":41419621},{"atb":[[10.5,28.03],[26,7.98],[15.5,13.77]],"id":41419633},{"atb":[[300,0.67],[150,1.34],[75,3.6]],"id":41419600},{"atb":[[270,0.74],[170,1.57],[420,0.47]],"id":41419629},{"atb":[[17,12.48],[12,24.21],[29,7.13]],"id":41419596}],"con":true,"img":false}]}
{"op":"mcm","clk":"5353586233","pt":1646216526175,"mc":[{"id":"1.195503871","rc":[{"atb":[[140,1.91],[95,0]],"id":41419605},{"atb":[[16.5,0],[19,0]],"id":41419651},{"atb":[[12,0],[9.8,0]],"id":41419585},{"atb":[[36,5.7],[46,0]],"id":41419586},{"atb":[[32,0],[26,0]],"id":41419628},{"atb":[[160,0],[110,0]],"id":41419604},{"atb":[[11.5,0],[14,0]],"id":41419592},{"atb":[[32,0],[26,0]],"id":41419596}],"con":true,"img":false}]}
{"op":"mcm","clk":"5353586364","pt":1646216526848,"mc":[{"id":"1.195503871","rc":[{"atb":[[150,2.72],[100,3.26]],"id":41419605},{"atb":[[17,3.26],[19.5,2.72]],"id":41419651},{"atb":[[10,25.46],[12.5,2.72]],"id":41419585},{"atb":[[38,3.26],[48,2.72]],"id":41419586},{"atb":[[34,2.72]],"id":41419628},{"atb":[[170,2.72],[120,3.26]],"id":41419604},{"atb":[[12,21.43],[14.5,2.72]],"id":41419592},{"atb":[[27,3.26]],"id":41419596}],"con":true,"img":false}]}
{"op":"mcm","clk":"5353586377","pt":1646216526955,"mc":[{"id":"1.195503871","rc":[{"atb":[[27,3.26]],"id":41419628},{"atb":[[34,2.72]],"id":41419596}],"con":true,"img":false}]}
{"op":"mcm","clk":"5353657758","pt":1646217255237,"mc":[{"id":"1.195503871","rc":[{"atb":[[18.5,0],[22,0]],"id":41419597},{"atb":[[22,0],[27,0]],"id":41419659}],"con":true,"img":false}]}
{"op":"mcm","clk":"5353657828","pt":1646217256065,"mc":[{"id":"1.195503871","rc":[{"atb":[[18,3.26],[21,12.71]],"id":41419597},{"atb":[[24,3.26],[29,2.72]],"id":41419659}],"con":true,"img":false}]}
{"op":"mcm","clk":"5353659383","pt":1646217273393,"mc":[{"id":"1.195503871","rc":[{"atb":[[18,0],[21,9.98]],"id":41419597},{"atb":[[24,0],[29,0]],"id":41419659}],"con":true,"img":false}]}
{"op":"mcm","clk":"5353659449","pt":1646217274075,"mc":[{"id":"1.195503871","rc":[{"atb":[[18.5,3.26],[22,2.72]],"id":41419597},{"atb":[[22,3.26],[27,2.72]],"id":41419659}],"con":true,"img":false}]}
{"op":"mcm","clk":"5353815830","pt":1646218755220,"mc":[{"id":"1.195503871","rc":[{"atb":[[22,0],[27,0]],"id":41419659}],"con":true,"img":false}]}
{"op":"mcm","clk":"5353815855","pt":1646218755432,"mc":[{"id":"1.195503871","rc":[{"atb":[[18.5,0],[22,0]],"id":41419597}],"con":true,"img":false}]}
{"op":"mcm","clk":"5353815914","pt":1646218756010,"mc":[{"id":"1.195503871","rc":[{"atb":[[24,3.26],[29,2.72]],"id":41419659}],"con":true,"img":false}]}
{"op":"mcm","clk":"5353815921","pt":1646218756114,"mc":[{"id":"1.195503871","rc":[{"atb":[[18,3.26],[21,12.71]],"id":41419597}],"con":true,"img":false}]}
{"op":"mcm","clk":"5353817686","pt":1646218773326,"mc":[{"id":"1.195503871","rc":[{"atb":[[24,0],[29,0]],"id":41419659}],"con":true,"img":false}]}
{"op":"mcm","clk":"5353817753","pt":1646218774122,"mc":[{"id":"1.195503871","rc":[{"atb":[[22,3.26],[27,2.72]],"id":41419659}],"con":true,"img":false}]}
{"op":"mcm","clk":"5353859143","pt":1646219186151,"mc":[{"id":"1.195503871","rc":[{"atb":[[140,1.91],[150,2.72],[100,3.27]],"id":41419605},{"atb":[[17,3.27],[19.5,2.72],[6.8,45.93],[8.8,25.61],[14.5,14.8]],"id":41419634},{"atb":[[90,2.24],[44,3.27],[46,5.91],[60,2.72]],"id":41419593},{"atb":[[18,11.75],[21,3.27],[10.5,21.03],[8.2,37],[26,2.72]],"id":41419655},{"atb":[[130,2.72],[90,3.27]],"id":41419622},{"atb":[[19,3.27],[9.2,32.48],[21,9.99],[23,2.72],[13,16.65]],"id":41419589},{"atb":[[16.5,17.18],[40,3.27],[46,4.44],[23,9.08],[50,2.72]],"id":41435527},{"atb":[[17,3.27],[7.2,42.96],[19.5,2.72],[9.2,24.36],[15.5,13.77]],"id":41419651},{"atb":[[270,2.72],[220,3.27]],"id":41419601},{"atb":[[70,2.72],[34,6.05],[85,2.37],[22,12.68],[48,3.27]],"id":41419630},{"atb":[[18,3.27],[9.2,32.48],[21,9.99],[13,16.65]],"id":41419597},{"atb":[[5.1,64.97],[9.2,24.36],[6.2,38.42],[11,3.27],[13.5,2.72]],"id":28546943},{"atb":[[8.6,35.05],[19,11.1],[22,3.27],[11.5,19.02],[27,2.72]],"id":41419659},{"atb":[[38,5.4],[19.5,10.8],[42,3.27],[55,2.72],[14.5,19.73]],"id":41419626},{"atb":[[34,6.05],[18.5,11.41],[40,2.72],[13.5,21.31],[30,3.27]],"id":41419639},{"atb":[[65,2.72],[16,17.76],[44,4.64],[22,9.51],[46,3.27]],"id":41419606},{"atb":[[8.6,35.05],[19.5,3.27],[19,11.1],[11.5,19.02],[24,2.72]],"id":41419635},{"atb":[[10,25.46],[5.5,59.19],[12.5,2.72],[7,33.3]],"id":41419585},{"atb":[[85,3.27],[100,2.01],[50,5.43],[120,2.72]],"id":41419610},{"atb":[[18,3.27],[9,24.97],[21,2.72],[7,44.4],[15,14.27]],"id":41419656},{"atb":[[70,3.27],[95,4.85],[48,5.66]],"id":41419623},{"atb":[[17.5,2.72],[9,24.97],[7,44.4],[15,17.54]],"id":41419590},{"atb":[[140,2.72],[95,3.27],[100,2.01],[50,5.43]],"id":41419652},{"atb":[[16,13.32],[36,2.72],[11,26.64],[27,7.68],[28,3.27]],"id":41435528},{"atb":[[36,5.7],[38,3.27],[90,2.24],[23,12.11],[48,2.72]],"id":41419586},{"atb":[[18,3.27],[8.6,35.05],[19,11.1],[21,2.72],[11.5,19.02]],"id":41419598},{"atb":[[8,38.05],[17.5,12.11],[20,3.27],[10,22.19],[25,2.72]],"id":41419660},{"atb":[[17,12.48],[23,3.27],[9.8,22.7],[28,2.72],[7.8,39.17]],"id":41419627},{"atb":[[34,3.27],[17.5,16.14],[44,2.72],[50,4.07],[25,8.32]],"id":41419594},{"atb":[[34,2.72],[10.5,28.04],[26,7.98],[27,3.27],[15.5,13.77]],"id":41419640},{"atb":[[75,2.72],[18.5,15.22],[50,3.27],[27,7.68],[60,3.38]],"id":41419607},{"atb":[[9.6,23.23],[17,2.72],[5.3,61.95],[6.6,35.67],[14.5,3.27]],"id":28546950},{"atb":[[75,2.72],[85,3.17],[50,3.27]],"id":41419636},{"atb":[[150,3.27],[200,2.72]],"id":41419603},{"atb":[[75,3.27],[38,5.4],[95,2.12],[24,11.58],[100,2.72]],"id":41419611},{"atb":[[65,3.12],[70,2.72],[36,7.61],[48,3.27]],"id":41419657},{"atb":[[6.2,51.23],[8.2,27.75],[12,3.27],[13,16.65],[14.5,2.72]],"id":41419591},{"atb":[[17.5,16.14],[80,2.72],[50,4.07],[25,8.32],[55,3.27]],"id":41435525},{"atb":[[40,2.72],[10.5,28.04],[26,7.98],[30,3.27],[15.5,13.77]],"id":41419620},{"atb":[[34,2.72],[36,5.7],[19,11.1],[27,3.27],[14,20.49]],"id":41419587},{"atb":[[42,8.14],[21,9.99],[55,2.72],[15.5,18.37]],"id":41419632},{"atb":[[80,3.27],[50,4.07],[110,2.72],[30,9.18]],"id":41419599},{"atb":[[34,2.72],[22,9.51],[27,3.27],[13.5,15.98],[9.4,31.71]],"id":41419628},{"atb":[[170,3.27],[220,2.72]],"id":41419608},{"atb":[[65,3.12],[19,14.8],[42,3.27],[55,2.72],[28,7.4]],"id":41419637},{"atb":[[170,2.72],[120,3.27]],"id":41419604},{"atb":[[75,2.69],[20,14.02],[85,2.72],[60,3.27],[30,6.88]],"id":41419612},{"atb":[[42,4.87],[21,9.99],[44,3.27],[60,2.72],[15.5,18.37]],"id":41419625},{"atb":[[12,21.43],[7.8,29.38],[14.5,2.72],[5.9,54.37]],"id":41419592},{"atb":[[36,2.72],[9,33.3],[20,10.51],[12.5,17.37],[28,3.27]],"id":41419654},{"atb":[[17,12.48],[38,3.27],[48,2.72],[12,24.22],[29,7.13]],"id":41435526},{"atb":[[32,6.44],[36,3.27],[18,11.75],[46,2.72],[13,22.19]],"id":41419621},{"atb":[[38,2.72],[10.5,28.04],[26,7.98],[29,3.27],[15.5,13.77]],"id":41419633},{"atb":[[130,2.72],[75,3.6],[90,3.27]],"id":41419600},{"atb":[[70,3.27],[95,2.72]],"id":41419629},{"atb":[[34,2.72],[17,12.48],[12,24.22],[27,3.27],[29,7.13]],"id":41419596}],"con":true,"img":false}]}
{"op":"mcm","clk":"5353859149","pt":1646219186250,"mc":[{"id":"1.195503871","rc":[{"atb":[[18,0]],"id":41419597}],"con":true,"img":false}]}
{"op":"mcm","clk":"5353859204","pt":1646219186833,"mc":[{"id":"1.195503871","rc":[{"atb":[[22,2.72]],"id":41419597}],"con":true,"img":false}]}
{"op":"mcm","clk":"5353859212","pt":1646219186937,"mc":[{"id":"1.195503871","rc":[{"atb":[[18.5,3.27]],"id":41419597}],"con":true,"img":false}]}
{"op":"mcm","clk":"5353880528","pt":1646219421607,"mc":[{"id":"1.195503871","rc":[{"atb":[[29,3.57]],"id":41419605},{"atb":[[6.4,18.52]],"id":41419634},{"atl":[[660,2]],"id":41419634},{"atb":[[28,3.7]],"id":41419593},{"atb":[[6.8,17.24]],"id":41419655},{"atl":[[700,2]],"id":41419655},{"atb":[[29,2]],"id":41419622},{"atb":[[5.9,19.98]],"id":41419589},{"atl":[[590,2]],"id":41419589},{"atb":[[12.5,8.7]],"id":41435527},{"atl":[[970,2]],"id":41435527},{"atb":[[4.1,27.56]],"id":41419651},{"atl":[[510,2]],"id":41419651},{"atb":[[30,2]],"id":41419601},{"atb":[[7.8,6.54]],"id":41419630},{"atl":[[1000,2]],"id":41419630},{"atb":[[4.2,19.98]],"id":41419597},{"atl":[[510,2]],"id":41419597},{"atb":[[3.9,34.48]],"id":28546943},{"atl":[[480,2]],"id":28546943},{"atb":[[4.9,22.2]],"id":41419659},{"atl":[[540,2]],"id":41419659},{"atb":[[13.5,8]],"id":41419626},{"atl":[[990,2]],"id":41419626},{"atb":[[9.8,11.36]],"id":41419639},{"atl":[[900,2]],"id":41419639},{"atb":[[26,4]],"id":41419606},{"atb":[[6.4,18.52]],"id":41419635},{"atl":[[650,2]],"id":41419635},{"atb":[[2.6,58.77]],"id":41419585},{"atl":[[410,2]],"id":41419585},{"atb":[[28,3.7]],"id":41419610},{"atb":[[4.2,28.54]],"id":41419656},{"atl":[[510,2]],"id":41419656},{"atb":[[27,3.85]],"id":41419623},{"atb":[[3.9,34.48]],"id":41419590},{"atl":[[490,2]],"id":41419590},{"atb":[[29,3.57]],"id":41419652},{"atb":[[6.8,15.36]],"id":41435528},{"atl":[[690,2]],"id":41435528},{"atb":[[28,3.7]],"id":41419586},{"atb":[[5.1,22.2]],"id":41419598},{"atl":[[550,2]],"id":41419598},{"atb":[[5.9,20.41]],"id":41419660},{"atl":[[590,2]],"id":41419660},{"atb":[[6,20]],"id":41419627},{"atl":[[600,2]],"id":41419627},{"atb":[[9,8.16]],"id":41419594},{"atl":[[880,2]],"id":41419594},{"atb":[[6,15.98]],"id":41419640},{"atl":[[610,2]],"id":41419640},{"atb":[[26,4]],"id":41419607},{"atb":[[4.4,29.41]],"id":28546950},{"atl":[[520,2]],"id":28546950},{"atb":[[29,3.57]],"id":41419636},{"atb":[[29,2]],"id":41419603},{"atb":[[26,4]],"id":41419611},{"atl":[[1000,2]],"id":41419611},{"atb":[[29,3.57]],"id":41419657},{"atb":[[4.7,27.03]],"id":41419591},{"atl":[[530,2]],"id":41419591},{"atb":[[26,4]],"id":41435525},{"atb":[[9.4,11.9]],"id":41419620},{"atl":[[890,2]],"id":41419620},{"atb":[[7.8,11.42]],"id":41419587},{"atl":[[830,2]],"id":41419587},{"atb":[[7.8,14.71]],"id":41419632},{"atl":[[830,2]],"id":41419632},{"atb":[[29,3.57]],"id":41419599},{"atb":[[5.9,19.04]],"id":41419628},{"atl":[[590,2]],"id":41419628},{"atb":[[30,2]],"id":41419608},{"atb":[[22,4.76]],"id":41419637},{"atl":[[1000,2]],"id":41419637},{"atb":[[29,2.24]],"id":41419604},{"atb":[[26,4]],"id":41419612},{"atb":[[9.4,9.74]],"id":41419625},{"atl":[[890,2]],"id":41419625},{"atb":[[3.7,37.04]],"id":41419592},{"atl":[[440,2]],"id":41419592},{"atb":[[6.2,19.23]],"id":41419654},{"atl":[[630,2]],"id":41419654},{"atb":[[11,10]],"id":41435526},{"atl":[[940,2]],"id":41435526},{"atb":[[8.8,12.82]],"id":41419621},{"atl":[[870,2]],"id":41419621},{"atb":[[6.2,15.98]],"id":41419633},{"atl":[[630,2]],"id":41419633},{"atb":[[29,3.57]],"id":41419600},{"atb":[[7.8,3.16]],"id":41419629},{"atb":[[6,14.26]],"id":41419596},{"atl":[[610,2]],"id":41419596}],"con":true,"img":false}]}
{"op":"mcm","clk":"5353885052","pt":1646219467285,"mc":[{"id":"1.195503871","rc":[{"atb":[[17,0],[19.5,0]],"id":41419634},{"atb":[[19,0],[23,0]],"id":41419589},{"atb":[[17.5,0],[15,14.27]],"id":41419590},{"atb":[[34,0],[27,0]],"id":41419587},{"atb":[[80,0],[110,0]],"id":41419599}],"con":true,"img":false}]}
{"op":"mcm","clk":"5353885066","pt":1646219467390,"mc":[{"id":"1.195503871","rc":[{"atb":[[17,0],[19.5,0]],"id":41419651},{"atb":[[65,0],[46,0]],"id":41419606},{"atb":[[12,0],[14.5,0]],"id":41419591}],"con":true,"img":false}]}
{"op":"mcm","clk":"5353885116","pt":1646219467976,"mc":[{"id":"1.195503871","rc":[{"atb":[[19.5,3.27],[24,2.72]],"id":41419589},{"atb":[[18,2.72],[15.5,3.27]],"id":41419590},{"atb":[[36,8.43],[28,3.27]],"id":41419587},{"atb":[[85,3.27],[120,2.72]],"id":41419599}],"con":true,"img":false}]}
{"op":"mcm","clk":"5353885126","pt":1646219468075,"mc":[{"id":"1.195503871","rc":[{"atb":[[17.5,3.27],[20,2.72]],"id":41419634},{"atb":[[16.5,3.27],[19,2.72]],"id":41419651},{"atb":[[12.5,3.27],[15,2.72]],"id":41419591}],"con":true,"img":false}]}
{"op":"mcm","clk":"5353885131","pt":1646219468186,"mc":[{"id":"1.195503871","rc":[{"atb":[[70,2.72],[48,3.27]],"id":41419606}],"con":true,"img":false}]}
{"op":"mcm","clk":"5353950454","pt":1646220115677,"mc":[{"id":"1.195503871","rc":[{"atl":[[630,2],[660,0]],"id":41419634},{"atl":[[700,0],[680,2]],"id":41419655},{"atl":[[570,2],[590,0]],"id":41419589},{"atb":[[12.5,0],[15,7.14]],"id":41435527},{"atl":[[950,2],[970,0]],"id":41435527},{"atl":[[490,2],[510,0]],"id":41419651},{"atl":[[490,2]],"id":41419597},{"atb":[[5.5,22.2],[4.9,0]],"id":41419659},{"atl":[[940,2],[990,0]],"id":41419626},{"atl":[[850,2]],"id":41419639},{"atl":[[1000,2]],"id":41419606},{"atl":[[610,2],[650,0]],"id":41419635},{"atl":[[390,2],[410,0]],"id":41419585},{"atb":[[4.2,0],[4.7,27.03]],"id":41419656},{"atl":[[490,0]],"id":41419590},{"atl":[[530,2],[550,0]],"id":41419598},{"atl":[[600,0],[580,2]],"id":41419627},{"atl":[[830,2],[880,0]],"id":41419594},{"atl":[[590,2],[610,0]],"id":41419640},{"atl":[[1000,2]],"id":41419607},{"atb":[[4.9,25.64],[4.4,0]],"id":28546950},{"atl":[[530,0],[520,2]],"id":41419591},{"atl":[[850,2],[890,0]],"id":41419620},{"atl":[[790,2],[830,0]],"id":41419587},{"atl":[[830,0],[800,2]],"id":41419632},{"atl":[[570,2]],"id":41419628},{"atl":[[860,2],[890,0]],"id":41419625},{"atl":[[420,2],[440,0]],"id":41419592},{"atl":[[910,2],[940,0]],"id":41435526},{"atl":[[830,2],[870,0]],"id":41419621},{"atl":[[630,0],[610,2]],"id":41419633},{"atl":[[590,2],[610,0]],"id":41419596}],"con":true,"img":false}]}
{"op":"mcm","clk":"5353950464","pt":1646220115772,"mc":[{"id":"1.195503871","rc":[{"atl":[[510,0]],"id":41419597},{"atl":[[900,0]],"id":41419639},{"atl":[[470,2]],"id":41419590},{"atl":[[590,0]],"id":41419628}],"con":true,"img":false}]}
{"op":"mcm","clk":"5353950506","pt":1646220116148,"mc":[{"id":"1.195503871","rc":[{"atb":[[18.5,0],[22,0]],"id":41419597}],"con":true,"img":false}]}
{"op":"mcm","clk":"5353950569","pt":1646220116872,"mc":[{"id":"1.195503871","rc":[{"atb":[[18,3.27],[21,12.71]],"id":41419597}],"con":true,"img":false}]}
{"op":"mcm","clk":"5353951172","pt":1646220122987,"mc":[{"id":"1.195503871","rc":[{"atl":[[990,2],[1000,0]],"id":41419630},{"atl":[[470,2],[480,0]],"id":28546943},{"atl":[[540,0],[530,2]],"id":41419659},{"atl":[[510,0],[500,2]],"id":41419656},{"atl":[[670,2],[690,0]],"id":41435528},{"atl":[[570,2],[590,0]],"id":41419660},{"atl":[[510,2]],"id":28546950},{"atl":[[630,0],[610,2]],"id":41419654}],"con":true,"img":false}]}
{"op":"mcm","clk":"5353951186","pt":1646220123067,"mc":[{"id":"1.195503871","rc":[{"atl":[[520,0]],"id":28546950}],"con":true,"img":false}]}
{"op":"mcm","clk":"5353953283","pt":1646220145711,"mc":[{"id":"1.195503871","rc":[{"atl":[[920,2],[950,0]],"id":41435527},{"atl":[[790,2],[800,0]],"id":41419632},{"atl":[[860,0],[850,2]],"id":41419625},{"atl":[[890,2],[910,0]],"id":41435526}],"con":true,"img":false}]}
{"op":"mcm","clk":"5353962063","pt":1646220243065,"mc":[{"id":"1.195503871","rc":[{"atb":[[5.5,0],[4.9,25.64]],"id":41419659},{"atl":[[1000,0]],"id":41419606},{"atl":[[1000,0]],"id":41419607}],"con":true,"img":false}]}
{"op":"mcm","clk":"5353979912","pt":1646220410936,"mc":[{"id":"1.195503871","rc":[{"atb":[[18,0],[21,9.99]],"id":41419597}],"con":true,"img":false}]}
{"op":"mcm","clk":"5353980008","pt":1646220411723,"mc":[{"id":"1.195503871","rc":[{"atb":[[18.5,3.27],[22,2.72]],"id":41419597}],"con":true,"img":false}]}
{"op":"mcm","clk":"5354030794","pt":1646220767829,"mc":[{"id":"1.195503871","rc":[{"atb":[[13.5,6.54],[7.8,0]],"id":41419630},{"atb":[[2.6,0],[3.55,39.22]],"id":41419585},{"atb":[[13.5,6],[28,0]],"id":41419610},{"atb":[[27,0],[13.5,7.7]],"id":41419623},{"atb":[[26,0],[13.5,7.27]],"id":41419611},{"atb":[[22,0],[13.5,8]],"id":41419637},{"atb":[[26,0],[13.5,7.27]],"id":41419612},{"atb":[[13.5,3.16],[7.8,0]],"id":41419629}],"con":true,"img":false}]}
{"op":"mcm","clk":"5354076829","pt":1646221206406,"mc":[{"id":"1.195503871","rc":[{"atl":[[630,0]],"id":41419634},{"atl":[[570,0]],"id":41419589},{"atb":[[4.1,0]],"id":41419651},{"atl":[[990,0]],"id":41419630},{"atl":[[490,0]],"id":41419597},{"atl":[[830,2]],"id":41419639},{"atl":[[420,2],[470,0]],"id":41419590},{"atl":[[570,0]],"id":41419660},{"atl":[[790,2]],"id":41419594},{"atl":[[570,2]],"id":41419640},{"atl":[[1000,0]],"id":41419611},{"atl":[[470,2]],"id":41419591},{"atl":[[680,2],[790,0]],"id":41419587},{"atb":[[11.5,9.52]],"id":41419625},{"atb":[[8.8,0]],"id":41419621}],"con":true,"img":false}]}
{"op":"mcm","clk":"5354076841","pt":1646221206515,"mc":[{"id":"1.195503871","rc":[{"atb":[[40,2.56],[29,0]],"id":41419605},{"atb":[[6.4,0],[8.2,13.89]],"id":41419634},{"atl":[[620,2]],"id":41419634},{"atb":[[40,2.56],[28,0]],"id":41419593},{"atb":[[6.8,0],[8.8,12.82]],"id":41419655},{"atl":[[630,2],[680,0]],"id":41419655},{"atb":[[40,2],[29,0]],"id":41419622},{"atb":[[7,16.67],[5.9,0]],"id":41419589},{"atl":[[550,2]],"id":41419589},{"atb":[[10,11.11],[15,0]],"id":41435527},{"atl":[[840,2],[920,0]],"id":41435527},{"atb":[[5.2,23.81]],"id":41419651},{"atb":[[40,2],[30,0]],"id":41419601},{"atl":[[930,2]],"id":41419630},{"atb":[[5.2,19.98],[4.2,0]],"id":41419597},{"atl":[[450,2]],"id":41419597},{"atb":[[4.9,25.64],[3.9,0]],"id":28546943},{"atl":[[460,2],[470,0]],"id":28546943},{"atb":[[5.6,21.74],[4.9,0]],"id":41419659},{"atl":[[530,0],[510,2]],"id":41419659},{"atl":[[840,2],[940,0]],"id":41419626},{"atl":[[750,2],[830,0],[850,0]],"id":41419639},{"atb":[[26,0],[15,7.14]],"id":41419606},{"atl":[[950,2]],"id":41419606},{"atb":[[8.6,48.21],[6.4,0]],"id":41419635},{"atb":[[4.1,32.26],[3.55,0]],"id":41419585},{"atl":[[1000,2]],"id":41419610},{"atb":[[5.9,20.41],[4.7,0]],"id":41419656},{"atb":[[4.9,25.64],[3.9,0]],"id":41419590},{"atb":[[40,2.56],[29,0]],"id":41419652},{"atb":[[6.8,0],[7.8,14.71]],"id":41435528},{"atb":[[38,5.97],[28,0]],"id":41419586},{"atb":[[5.1,0],[5.8,20.83]],"id":41419598},{"atl":[[530,0],[520,2]],"id":41419598},{"atb":[[7,16.67],[5.9,0]],"id":41419660},{"atl":[[550,2]],"id":41419660},{"atb":[[7.4,15.62],[6,0]],"id":41419627},{"atl":[[570,2],[580,0]],"id":41419627},{"atb":[[9,0],[10,8.16]],"id":41419594},{"atl":[[830,0]],"id":41419594},{"atb":[[7.4,15.62],[6,0]],"id":41419640},{"atl":[[590,0]],"id":41419640},{"atb":[[17,6.25],[26,0]],"id":41419607},{"atl":[[980,2]],"id":41419607},{"atb":[[5.6,21.74],[4.9,0]],"id":28546950},{"atb":[[40,2.56],[29,0]],"id":41419636},{"atb":[[40,2],[29,0]],"id":41419603},{"atl":[[890,2]],"id":41419611},{"atb":[[40,2.56],[29,0]],"id":41419657},{"atb":[[5.5,22.22],[4.7,0]],"id":41419591},{"atl":[[520,0]],"id":41419591},{"atb":[[19,5.56],[26,0]],"id":41435525},{"atl":[[1000,2]],"id":41435525},{"atb":[[12,9.09],[9.4,0]],"id":41419620},{"atl":[[810,2],[850,0]],"id":41419620},{"atb":[[8.8,12.82],[7.8,0]],"id":41419587},{"atb":[[9,12.5],[7.8,0]],"id":41419632},{"atl":[[740,2],[790,0]],"id":41419632},{"atb":[[40,2.56],[29,0]],"id":41419599},{"atb":[[7.8,14.71],[5.9,0]],"id":41419628},{"atl":[[570,0],[560,2]],"id":41419628},{"atb":[[40,2],[30,0]],"id":41419608},{"atl":[[900,2],[1000,0]],"id":41419637},{"atb":[[40,2.24],[29,0]],"id":41419604},{"atl":[[1000,2]],"id":41419612},{"atb":[[9.4,0]],"id":41419625},{"atl":[[800,2],[850,0]],"id":41419625},{"atb":[[3.7,0],[4.7,27.03]],"id":41419592},{"atb":[[8,14.29],[6.2,0]],"id":41419654},{"atl":[[580,2],[610,0]],"id":41419654},{"atb":[[20,5.26],[11,0]],"id":41435526},{"atb":[[13.5,8]],"id":41419621},{"atb":[[6.2,0],[7.8,14.71]],"id":41419633},{"atl":[[590,2],[610,0]],"id":41419633},{"atb":[[40,2.56],[29,0]],"id":41419600},{"atb":[[6,0],[7.8,14.26]],"id":41419596},{"atl":[[560,2],[590,0]],"id":41419596}],"con":true,"img":false}]}
{"op":"mcm","clk":"5354076865","pt":1646221206681,"mc":[{"id":"1.195503871","rc":[{"atb":[[18.5,0],[22,0]],"id":41419597},{"atb":[[22,0],[27,0]],"id":41419659},{"atb":[[18,0],[15.5,0]],"id":41419590},{"atb":[[75,0],[100,0]],"id":41419611}],"con":true,"img":false}]}
{"op":"mcm","clk":"5354076929","pt":1646221207406,"mc":[{"id":"1.195503871","rc":[{"atb":[[16,3.27],[18.5,2.72]],"id":41419597},{"atb":[[19.5,3.27],[24,2.72]],"id":41419659},{"atb":[[13,3.27],[15.5,2.72]],"id":41419590}],"con":true,"img":false}]}
{"op":"mcm","clk":"5354076956","pt":1646221207678,"mc":[{"id":"1.195503871","rc":[{"atb":[[85,2.72],[60,3.27]],"id":41419611}],"con":true,"img":false}]}
{"op":"mcm","clk":"5354077790","pt":1646221215722,"mc":[{"id":"1.195503871","rc":[{"atb":[[21,0],[26,0]],"id":41419655},{"atb":[[130,0],[90,0]],"id":41419622},{"atb":[[16.5,0],[19,0]],"id":41419651},{"atb":[[11,0],[13.5,0]],"id":28546943},{"atb":[[70,0],[95,2.12]],"id":41419623},{"atb":[[36,0],[28,0]],"id":41435528},{"atb":[[75,0],[50,0]],"id":41419607},{"atb":[[17,0],[14.5,0]],"id":28546950},{"atb":[[80,0],[55,0]],"id":41435525},{"atb":[[38,0],[48,0]],"id":41435526}],"con":true,"img":false}]}
{"op":"mcm","clk":"5354077800","pt":1646221215780,"mc":[{"id":"1.195503871","rc":[{"atl":[[610,0]],"id":41419635}],"con":true,"img":false}]}
{"op":"mcm","clk":"5354077806","pt":1646221215882,"mc":[{"id":"1.195503871","rc":[{"atl":[[600,2]],"id":41419635}],"con":true,"img":false}]}
{"op":"mcm","clk":"5354077865","pt":1646221216436,"mc":[{"id":"1.195503871","rc":[{"atb":[[22,3.27],[27,2.72]],"id":41419655},{"atb":[[140,2.72],[95,3.27]],"id":41419622},{"atb":[[17,3.27],[19.5,2.72]],"id":41419651},{"atb":[[11.5,3.27],[14,2.72]],"id":28546943},{"atb":[[75,3.27],[100,2.72]],"id":41419623},{"atb":[[38,2.72],[29,3.27]],"id":41435528},{"atb":[[17.5,2.72],[15,3.27]],"id":28546950},{"atb":[[85,2.72],[60,3.27]],"id":41435525},{"atb":[[40,3.27],[50,2.72]],"id":41435526}],"con":true,"img":false}]}
{"op":"mcm","clk":"5354077876","pt":1646221216503,"mc":[{"id":"1.195503871","rc":[{"atb":[[80,2.72],[55,3.27]],"id":41419607}],"con":true,"img":false}]}
{"op":"mcm","clk":"5354078811","pt":1646221225515,"mc":[{"id":"1.195503871","rc":[{"atl":[[380,2],[420,0]],"id":41419590},{"atl":[[710,2],[790,0]],"id":41419594},{"atl":[[540,2],[570,0]],"id":41419640},{"atl":[[440,2],[470,0]],"id":41419591},{"atl":[[630,2],[680,0]],"id":41419587}],"con":true,"img":false}]}
{"op":"mcm","clk":"5354078823","pt":1646221225618,"mc":[{"id":"1.195503871","rc":[{"atb":[[10,0],[13.5,8]],"id":41435527},{"atl":[[840,0]],"id":41435527},{"atl":[[890,2]],"id":41419637},{"atl":[[890,2],[1000,0]],"id":41419612}],"con":true,"img":false}]}
{"op":"mcm","clk":"5354078838","pt":1646221225725,"mc":[{"id":"1.195503871","rc":[{"atl":[[570,2],[620,0]],"id":41419634},{"atl":[[530,2],[550,0]],"id":41419589},{"atl":[[790,2]],"id":41435527},{"atb":[[6,20],[5.2,0]],"id":41419651},{"atl":[[830,2],[930,0]],"id":41419630},{"atb":[[16,0],[18.5,0]],"id":41419597},{"atl":[[420,2],[450,0]],"id":41419597},{"atb":[[6,20],[4.9,0]],"id":28546943},{"atl":[[510,0],[500,2]],"id":41419659},{"atl":[[750,0],[740,2]],"id":41419639},{"atb":[[17.5,6.06],[15,0]],"id":41419606},{"atl":[[850,2],[950,0]],"id":41419606},{"atb":[[7.4,15.62],[5.9,0]],"id":41419656},{"atb":[[9.8,11.36],[7.8,0]],"id":41435528},{"atl":[[520,0],[470,2]],"id":41419598},{"atl":[[540,2],[550,0]],"id":41419660},{"atl":[[540,2],[570,0]],"id":41419627},{"atb":[[17,0],[19.5,5.41]],"id":41419607},{"atl":[[870,2],[980,0]],"id":41419607},{"atb":[[5.6,0],[7,16.67]],"id":28546950},{"atl":[[790,2],[890,0]],"id":41419611},{"atl":[[900,2],[1000,0]],"id":41435525},{"atb":[[12,0],[14.5,7.41]],"id":41419620},{"atl":[[810,0],[800,2]],"id":41419620},{"atb":[[9,0],[10.5,10.53]],"id":41419632},{"atl":[[900,0]],"id":41419637},{"atb":[[5.5,22.22],[4.7,0]],"id":41419592},{"atb":[[20,0],[25,4.17]],"id":41435526},{"atb":[[16,6.67],[13.5,0]],"id":41419621},{"atl":[[560,2],[590,0]],"id":41419633},{"atl":[[560,0],[550,2]],"id":41419596}],"con":true,"img":false}]}
{"op":"mcm","clk":"5354078906","pt":1646221226411,"mc":[{"id":"1.195503871","rc":[{"atb":[[18,2.72],[15.5,3.27]],"id":41419597}],"con":true,"img":false}]}
{"op":"mcm","clk":"5354079597","pt":1646221232931,"mc":[{"id":"1.195503871","rc":[{"atl":[[500,0],[510,2]],"id":41419659},{"atl":[[830,2],[840,0]],"id":41419626},{"atl":[[850,0],[840,2]],"id":41419606},{"atb":[[19,0],[23,4.55]],"id":41435525},{"atl":[[630,0],[620,2]],"id":41419587},{"atl":[[890,0],[880,2]],"id":41419612},{"atl":[[790,2],[800,0]],"id":41419625},{"atl":[[560,0],[550,2]],"id":41419633}],"con":true,"img":false}]}
{"op":"mcm","clk":"5354079644","pt":1646221233349,"mc":[{"id":"1.195503871","rc":[{"atb":[[13,0],[15.5,0]],"id":41419590},{"atb":[[38,0],[29,0]],"id":41419633}],"con":true,"img":false}]}
{"op":"mcm","clk":"5354079716","pt":1646221234027,"mc":[{"id":"1.195503871","rc":[{"atb":[[12.5,3.27],[15,16.99]],"id":41419590},{"atb":[[36,2.72],[28,3.27]],"id":41419633}],"con":true,"img":false}]}
{"op":"mcm","clk":"5354079800","pt":1646221234914,"mc":[{"id":"1.195503871","rc":[{"atl":[[600,0],[590,2]],"id":41419635}],"con":true,"img":false}]}
{"op":"mcm","clk":"5354080288","pt":1646221238614,"mc":[{"id":"1.195503871","rc":[{"atl":[[540,0],[550,2]],"id":41419660}],"con":true,"img":false}]}
{"op":"mcm","clk":"5354092793","pt":1646221358595,"mc":[{"id":"1.195503871","rc":[{"atl":[[570,0]],"id":41419634},{"atl":[[530,0]],"id":41419589},{"atl":[[830,0],[840,2]],"id":41419626},{"atl":[[740,0],[750,2]],"id":41419639},{"atl":[[840,0]],"id":41419606},{"atl":[[1000,0]],"id":41419610},{"atl":[[550,2]],"id":41419627},{"atl":[[540,0],[550,2]],"id":41419640},{"atl":[[790,0]],"id":41419611},{"atl":[[550,0],[560,2]],"id":41419596}],"con":true,"img":false}]}
{"op":"mcm","clk":"5354092801","pt":1646221358700,"mc":[{"id":"1.195503871","rc":[{"atl":[[590,2]],"id":41419634},{"atl":[[540,2]],"id":41419589},{"atl":[[830,0],[870,2]],"id":41419630},{"atl":[[850,2]],"id":41419606},{"atl":[[590,0],[600,2]],"id":41419635},{"atl":[[470,0],[480,2]],"id":41419598},{"atl":[[540,0]],"id":41419627},{"atb":[[10,0],[8.8,12.24]],"id":41419594},{"atl":[[710,0],[740,2]],"id":41419594},{"atl":[[870,0],[910,2]],"id":41419607},{"atl":[[830,2]],"id":41419611},{"atb":[[5.5,0],[4.9,25.64]],"id":41419591},{"atl":[[440,0],[450,2]],"id":41419591},{"atl":[[800,0],[810,2]],"id":41419620},{"atl":[[560,0],[570,2]],"id":41419628},{"atl":[[890,0],[900,2]],"id":41419637},{"atl":[[580,0],[600,2]],"id":41419654}],"con":true,"img":false}]}
{"op":"mcm","clk":"5354096579","pt":1646221392416,"mc":[{"id":"1.195503871","rc":[{"atb":[[19.5,0],[24,0]],"id":41419659}],"con":true,"img":false}]}
{"op":"mcm","clk":"5354096627","pt":1646221393089,"mc":[{"id":"1.195503871","rc":[{"atb":[[22,3.27],[27,2.72]],"id":41419659}],"con":true,"img":false}]}
{"op":"mcm","clk":"5354101452","pt":1646221435570,"mc":[{"id":"1.195503871","rc":[{"atb":[[17.5,0],[20,0]],"id":41419634}],"con":true,"img":false}]}
{"op":"mcm","clk":"5354101541","pt":1646221436351,"mc":[{"id":"1.195503871","rc":[{"atb":[[17,3.27],[19.5,2.72]],"id":41419634}],"con":true,"img":false}]}
{"op":"mcm","clk":"5354103753","pt":1646221454792,"mc":[{"id":"1.195503871","rc":[{"atl":[[540,0]],"id":41419589},{"atb":[[5.6,0]],"id":41419659},{"atl":[[840,0]],"id":41419626},{"atl":[[460,2]],"id":41419598},{"atl":[[450,0]],"id":41419591}],"con":true,"img":false}]}
{"op":"mcm","clk":"5354103767","pt":1646221454898,"mc":[{"id":"1.195503871","rc":[{"atl":[[570,2],[590,0]],"id":41419634},{"atl":[[530,2]],"id":41419589},{"atl":[[830,2],[870,0]],"id":41419630},{"atb":[[6.2,19.23]],"id":41419659},{"atl":[[830,2]],"id":41419626},{"atl":[[750,0],[740,2]],"id":41419639},{"atl":[[600,0],[590,2]],"id":41419635},{"atl":[[1000,2]],"id":41419610},{"atl":[[480,0]],"id":41419598},{"atl":[[540,2],[550,0]],"id":41419627},{"atl":[[710,2],[740,0]],"id":41419594},{"atl":[[530,2],[550,0]],"id":41419640},{"atl":[[870,2],[910,0]],"id":41419607},{"atl":[[830,0],[800,2]],"id":41419611},{"atl":[[440,2]],"id":41419591},{"atl":[[810,0],[800,2]],"id":41419620},{"atl":[[570,0],[560,2]],"id":41419628},{"atl":[[890,2],[900,0]],"id":41419637},{"atl":[[600,0],[580,2]],"id":41419654},{"atl":[[560,0],[550,2]],"id":41419596}],"con":true,"img":false}]}
{"op":"mcm","clk":"5354103786","pt":1646221455106,"mc":[{"id":"1.195503871","rc":[{"atb":[[12.5,0],[15,14.27]],"id":41419590},{"atb":[[34,0],[27,0]],"id":41419640}],"con":true,"img":false}]}
{"op":"mcm","clk":"5354103801","pt":1646221455159,"mc":[{"id":"1.195503871","rc":[{"atl":[[540,2],[550,0]],"id":41419660}],"con":true,"img":false}]}
{"op":"mcm","clk":"5354103871","pt":1646221455787,"mc":[{"id":"1.195503871","rc":[{"atb":[[13,3.27],[15.5,2.72]],"id":41419590},{"atb":[[32,2.72],[26,11.26]],"id":41419640}],"con":true,"img":false}]}
{"op":"mcm","clk":"5354105939","pt":1646221472990,"mc":[{"id":"1.195503871","rc":[{"atl":[[850,0],[840,2]],"id":41419606},{"atl":[[790,2],[800,0]],"id":41419611},{"atb":[[4.9,0],[5.4,22.73]],"id":41419591}],"con":true,"img":false}]}
{"op":"mcm","clk":"5354105978","pt":1646221473303,"mc":[{"id":"1.195503871","rc":[{"atb":[[22,0],[27,0]],"id":41419659}],"con":true,"img":false}]}
{"op":"mcm","clk":"5354105984","pt":1646221473405,"mc":[{"id":"1.195503871","rc":[{"atb":[[13,0],[15.5,0]],"id":41419590}],"con":true,"img":false}]}
{"op":"mcm","clk":"5354106064","pt":1646221473984,"mc":[{"id":"1.195503871","rc":[{"atb":[[21,3.27],[26,2.72]],"id":41419659}],"con":true,"img":false}]}
{"op":"mcm","clk":"5354106100","pt":1646221474297,"mc":[{"id":"1.195503871","rc":[{"atb":[[12.5,3.27],[15,16.99]],"id":41419590}],"con":true,"img":false}]}
{"op":"mcm","clk":"5354108909","pt":1646221498440,"mc":[{"id":"1.195503871","rc":[{"atl":[[540,0],[550,2]],"id":41419660},{"atl":[[860,2],[870,0]],"id":41419607},{"atl":[[730,2]],"id":41419632}],"con":true,"img":false}]}
{"op":"mcm","clk":"5354108918","pt":1646221498542,"mc":[{"id":"1.195503871","rc":[{"atl":[[740,0]],"id":41419632}],"con":true,"img":false}]}
{"op":"mcm","clk":"5354108960","pt":1646221498910,"mc":[{"id":"1.195503871","rc":[{"atb":[[85,0],[60,0]],"id":41419611}],"con":true,"img":false}]}
{"op":"mcm","clk":"5354109034","pt":1646221499750,"mc":[{"id":"1.195503871","rc":[{"atb":[[80,2.72],[55,3.27]],"id":41419611}],"con":true,"img":false}]}
{"op":"mcm","clk":"5354124299","pt":1646221628695,"mc":[{"id":"1.195503871","rc":[{"atl":[[1000,0]],"id":41419610}],"con":true,"img":false}]}
{"op":"mcm","clk":"5354124320","pt":1646221628898,"mc":[{"id":"1.195503871","rc":[{"atl":[[1000,2]],"id":41419610}],"con":true,"img":false}]}
{"op":"mcm","clk":"5354124630","pt":1646221632282,"mc":[{"id":"1.195503871","rc":[{"atb":[[21,0],[26,0]],"id":41419659}],"con":true,"img":false}]}
{"op":"mcm","clk":"5354124703","pt":1646221633008,"mc":[{"id":"1.195503871","rc":[{"atb":[[22,3.27],[27,2.72]],"id":41419659}],"con":true,"img":false}]}
{"op":"mcm","clk":"5354140085","pt":1646221786249,"mc":[{"id":"1.195503871","rc":[{"atl":[[630,0],[610,2]],"id":41419655},{"atl":[[830,0],[820,2]],"id":41419626},{"atl":[[730,2],[740,0]],"id":41419639},{"atl":[[670,0],[640,2]],"id":41435528},{"atl":[[540,2],[550,0]],"id":41419660},{"atl":[[890,2],[900,0]],"id":41435525},{"atl":[[890,0],[880,2]],"id":41419637},{"atb":[[17.5,6.06],[25,0]],"id":41435526},{"atl":[[850,2],[890,0]],"id":41435526},{"atl":[[830,0],[820,2]],"id":41419621}],"con":true,"img":false}]}
{"op":"mcm","clk":"5354140109","pt":1646221786527,"mc":[{"id":"1.195503871","rc":[{"atb":[[12.5,0],[15,14.27]],"id":41419590},{"atb":[[32,0],[26,7.98]],"id":41419640},{"atb":[[80,0],[55,0]],"id":41419611},{"atb":[[36,0],[28,0]],"id":41419633}],"con":true,"img":false}]}
{"op":"mcm","clk":"5354140150","pt":1646221786938,"mc":[{"id":"1.195503871","rc":[{"atl":[[790,2],[800,0]],"id":41419620},{"atl":[[790,0],[780,2]],"id":41419625}],"con":true,"img":false}]}
{"op":"mcm","clk":"5354140174","pt":1646221787243,"mc":[{"id":"1.195503871","rc":[{"atb":[[16,2.72],[13.5,3.27]],"id":41419590},{"atb":[[34,2.72],[27,3.27]],"id":41419640},{"atb":[[85,2.72],[60,3.27]],"id":41419611},{"atb":[[38,2.72],[29,3.27]],"id":41419633}],"con":true,"img":false}]}
{"op":"mcm","clk":"5354141387","pt":1646221799545,"mc":[{"id":"1.195503871","rc":[{"atl":[[820,0],[810,2]],"id":41419626},{"atl":[[850,0],[840,2]],"id":41435526},{"atl":[[820,0],[810,2]],"id":41419621}],"con":true,"img":false}]}
{"op":"mcm","clk":"5354150454","pt":1646221895378,"mc":[{"id":"1.195503871","rc":[{"atb":[[22,0],[27,0]],"id":41419659}],"con":true,"img":false}]}
{"op":"mcm","clk":"5354150522","pt":1646221896056,"mc":[{"id":"1.195503871","rc":[{"atb":[[21,3.27],[26,2.72]],"id":41419659}],"con":true,"img":false}]}
{"op":"mcm","clk":"5354150865","pt":1646221899999,"mc":[{"id":"1.195503871","rc":[{"atl":[[530,0],[520,2]],"id":41419589},{"atl":[[790,0],[780,2]],"id":41435527},{"atl":[[700,2],[710,0]],"id":41419594},{"atl":[[790,0],[780,2]],"id":41419620},{"atl":[[810,0],[800,2]],"id":41419621}],"con":true,"img":false}]}
{"op":"mcm","clk":"5354153150","pt":1646221926529,"mc":[{"id":"1.195503871","rc":[{"atl":[[830,2],[840,0]],"id":41419606},{"atl":[[700,0],[690,2]],"id":41419594},{"atl":[[860,0],[850,2]],"id":41419607},{"atl":[[780,0],[770,2]],"id":41419620}],"con":true,"img":false}]}
{"op":"mcm","clk":"5354160544","pt":1646222012219,"mc":[{"id":"1.195503871","rc":[{"atb":[[21,0],[26,0]],"id":41419659}],"con":true,"img":false}]}
{"op":"mcm","clk":"5354160618","pt":1646222013207,"mc":[{"id":"1.195503871","rc":[{"atb":[[23,3.27],[28,2.72]],"id":41419659}],"con":true,"img":false}]}
{"op":"mcm","clk":"5354169073","pt":1646222107434,"mc":[{"id":"1.195503871","rc":[{"atl":[[800,0]],"id":41419621}],"con":true,"img":false}]}
{"op":"mcm","clk":"5354169086","pt":1646222107542,"mc":[{"id":"1.195503871","rc":[{"atl":[[790,2]],"id":41419621}],"con":true,"img":false}]}
{"op":"mcm","clk":"5354170615","pt":1646222122660,"mc":[{"id":"1.195503871","rc":[{"atb":[[23,0],[28,0]],"id":41419659}],"con":true,"img":false}]}
{"op":"mcm","clk":"5354170693","pt":1646222123467,"mc":[{"id":"1.195503871","rc":[{"atb":[[22,3.27],[27,2.72]],"id":41419659}],"con":true,"img":false}]}
{"op":"mcm","clk":"5354173441","pt":1646222157538,"mc":[{"id":"1.195503871","rc":[{"atb":[[140,0],[390,0],[240,0]],"id":41419605},{"atb":[[6.8,0],[8.8,0],[14.5,0]],"id":41419634},{"atb":[[90,0],[46,0],[230,0]],"id":41419593},{"atb":[[18,0],[10.5,0],[8.2,0]],"id":41419655},{"atb":[[600,0],[700,0],[850,0]],"id":41419622},{"atb":[[9.2,0],[21,0],[13,0]],"id":41419589},{"atb":[[16.5,0],[46,0],[23,0]],"id":41435527},{"atb":[[7.2,0],[9.2,0],[15.5,0]],"id":41419651},{"atb":[[600,0],[700,0],[850,0]],"id":41419601},{"atb":[[34,0],[85,0],[22,0]],"id":41419630},{"atb":[[9.2,0],[21,0],[13,0]],"id":41419597},{"atb":[[5.1,0],[9.2,0],[6.2,0]],"id":28546943},{"atb":[[8.6,0],[19,0],[11.5,0]],"id":41419659},{"atb":[[38,0],[19.5,0],[14.5,0]],"id":41419626},{"atb":[[34,0],[18.5,0],[13.5,0]],"id":41419639},{"atb":[[16,0],[44,0],[22,0]],"id":41419606},{"atb":[[8.6,13.16],[19,0],[11.5,0]],"id":41419635},{"atb":[[10,3.27],[5.5,0],[7,0]],"id":41419585},{"atb":[[100,0],[50,0],[250,0]],"id":41419610},{"atb":[[9,0],[7,0],[15,0]],"id":41419656},{"atb":[[95,0],[48,0],[240,0]],"id":41419623},{"atb":[[9,0],[7,0],[15,0]],"id":41419590},{"atb":[[100,0],[50,0],[250,0]],"id":41419652},{"atb":[[16,0],[11,0],[27,0]],"id":41435528},{"atb":[[36,0],[90,0],[23,0]],"id":41419586},{"atb":[[8.6,0],[19,0],[11.5,0]],"id":41419598},{"atb":[[8,0],[17.5,0],[10,0]],"id":41419660},{"atb":[[17,0],[9.8,0],[7.8,0]],"id":41419627},{"atb":[[17.5,0],[50,0],[25,0]],"id":41419594},{"atb":[[10.5,0],[26,0],[15.5,0]],"id":41419640},{"atb":[[18.5,0],[27,0],[60,0]],"id":41419607},{"atb":[[9.6,0],[5.3,0],[6.6,0]],"id":28546950},{"atb":[[320,0],[170,0],[85,0]],"id":41419636},{"atb":[[600,0],[700,0],[850,0]],"id":41419603},{"atb":[[38,0],[95,0],[24,0]],"id":41419611},{"atb":[[65,0],[36,0],[180,0]],"id":41419657},{"atb":[[6.2,0],[8.2,0],[13,0]],"id":41419591},{"atb":[[17.5,0],[50,0],[25,0]],"id":41435525},{"atb":[[10.5,0],[26,0],[15.5,0]],"id":41419620},{"atb":[[36,2.72],[19,0],[14,0]],"id":41419587},{"atb":[[42,3.27],[21,0],[15.5,0]],"id":41419632},{"atb":[[150,0],[50,0],[30,0]],"id":41419599},{"atb":[[22,0],[13.5,0],[9.4,0]],"id":41419628},{"atb":[[600,0],[700,0],[850,0]],"id":41419608},{"atb":[[65,0],[19,0],[28,0]],"id":41419637},{"atb":[[340,0],[490,0],[240,0]],"id":41419604},{"atb":[[75,0],[20,0],[30,0]],"id":41419612},{"atb":[[42,0],[21,0],[15.5,0]],"id":41419625},{"atb":[[12,3.27],[7.8,0],[5.9,0]],"id":41419592},{"atb":[[9,0],[20,0],[12.5,0]],"id":41419654},{"atb":[[17,0],[12,0],[29,0]],"id":41435526},{"atb":[[32,0],[18,0],[13,0]],"id":41419621},{"atb":[[10.5,0],[26,0],[15.5,0]],"id":41419633},{"atb":[[300,0],[150,0],[75,0]],"id":41419600},{"atb":[[270,0],[170,0],[420,0]],"id":41419629},{"atb":[[17,0],[12,0],[29,0]],"id":41419596}],"con":true,"img":false}]}
{"op":"mcm","clk":"5354173727","pt":1646222161032,"mc":[{"id":"1.195503871","rc":[{"atb":[[70,3.85],[38,7.19],[240,0.55]],"id":41419605},{"atb":[[8.8,17.07],[4.4,78.35],[5.4,60.54]],"id":41419634},{"atb":[[19,14.8],[90,1.49],[28,9.86]],"id":41419593},{"atb":[[5.1,64.97],[10.5,14.02],[6.2,51.23]],"id":41419655},{"atb":[[700,0.19],[400,0.67],[500,0.53]],"id":41419622},{"atb":[[5.6,57.91],[7.2,42.96],[13,11.1]],"id":41419589},{"atb":[[8.6,35.05],[23,6.05],[11.5,25.37]],"id":41435527},{"atb":[[5.6,57.91],[9.2,16.24],[4.6,74]],"id":41419651},{"atb":[[700,0.19],[400,0.67],[500,0.53]],"id":41419601},{"atb":[[16,17.76],[34,4.03],[11,26.64]],"id":41419630},{"atb":[[5.6,57.91],[7.2,42.96],[13,11.1]],"id":41419597},{"atb":[[6.2,25.61],[4.1,85.93],[3.55,104.47]],"id":28546943},{"atb":[[5.3,61.95],[11.5,12.68],[6.6,47.57]],"id":41419659},{"atb":[[19.5,7.19],[9.8,30.27],[7.8,39.17]],"id":41419626},{"atb":[[18.5,7.61],[7.4,41.62],[9.4,31.71]],"id":41419639},{"atb":[[22,6.34],[11,26.64],[8.4,35.99]],"id":41419606},{"atb":[[5.3,61.95],[11.5,12.68],[6.6,47.57]],"id":41419635},{"atb":[[4.5,76.11],[7,22.19],[3.75,96.87]],"id":41419585},{"atb":[[20,14.02],[100,1.34],[30,9.18]],"id":41419610},{"atb":[[9,16.65],[4.5,76.11],[5.5,59.19]],"id":41419656},{"atb":[[19.5,14.39],[95,1.41],[29,9.51]],"id":41419623},{"atb":[[9,16.65],[4.5,76.11],[5.5,59.19]],"id":41419590},{"atb":[[20,14.02],[100,1.34],[30,9.18]],"id":41419652},{"atb":[[16,8.87],[6.4,49.33],[8.4,35.99]],"id":41435528},{"atb":[[16.5,17.18],[36,3.8],[11.5,25.37]],"id":41419586},{"atb":[[5.3,61.95],[11.5,12.68],[6.6,47.57]],"id":41419598},{"atb":[[10,14.8],[5,66.6],[6,53.28]],"id":41419660},{"atb":[[9.8,15.13],[4.9,68.3],[5.9,54.37]],"id":41419627},{"atb":[[9,33.3],[25,5.54],[12.5,23.16]],"id":41419594},{"atb":[[6.2,51.23],[8.2,37],[15.5,9.18]],"id":41419640},{"atb":[[27,5.12],[13.5,21.31],[9.4,31.71]],"id":41419607},{"atb":[[4.3,80.72],[6.6,23.78],[3.65,100.52]],"id":28546950},{"atb":[[170,0.79],[44,6.19],[27,10.24]],"id":41419636},{"atb":[[700,0.19],[400,0.67],[500,0.53]],"id":41419603},{"atb":[[17,16.65],[38,3.6],[12,24.22]],"id":41419611},{"atb":[[65,2.08],[16.5,17.18],[23,12.11]],"id":41419657},{"atb":[[5.1,64.97],[8.2,18.49],[4.1,85.93]],"id":41419591},{"atb":[[9,33.3],[25,5.54],[12.5,23.16]],"id":41435525},{"atb":[[6.2,51.23],[8.2,37],[15.5,9.18]],"id":41419620},{"atb":[[9.6,30.97],[19,7.4],[7.6,40.36]],"id":41419587},{"atb":[[10.5,38.57],[21,6.66],[8.2,37]],"id":41419632},{"atb":[[20,14.02],[50,2.71],[15,19.02]],"id":41419599},{"atb":[[7.4,41.62],[13.5,10.65],[5.7,56.68]],"id":41419628},{"atb":[[700,0.19],[400,0.67],[500,0.53]],"id":41419608},{"atb":[[9.6,30.97],[28,4.93],[14,20.49]],"id":41419637},{"atb":[[140,1.91],[70,3.85],[340,0.39]],"id":41419604},{"atb":[[10,29.59],[30,4.59],[15,19.02]],"id":41419612},{"atb":[[21,6.66],[10.5,28.04],[8.2,37]],"id":41419625},{"atb":[[3.95,90.3],[4.9,68.3],[7.8,19.58]],"id":41419592},{"atb":[[5.5,59.19],[12.5,11.58],[7,44.4]],"id":41419654},{"atb":[[17,8.32],[6.8,45.93],[8.8,34.15]],"id":41435526},{"atb":[[7.2,42.96],[18,7.83],[9.2,32.48]],"id":41419621},{"atb":[[6.2,51.23],[8.2,37],[15.5,9.18]],"id":41419633},{"atb":[[150,0.89],[40,9.38],[25,11.1]],"id":41419600},{"atb":[[270,0.49],[85,3.17],[44,6.19]],"id":41419629},{"atb":[[17,8.32],[6.8,45.93],[8.8,34.15]],"id":41419596}],"con":true,"img":false}]}
{"op":"mcm","clk":"5354178152","pt":1646222216881,"mc":[{"id":"1.195503871","rc":[{"atb":[[22,0],[27,0]],"id":41419659}],"con":true,"img":false}]}
{"op":"mcm","clk":"5354178225","pt":1646222217675,"mc":[{"id":"1.195503871","rc":[{"atb":[[23,3.27],[28,2.72]],"id":41419659}],"con":true,"img":false}]}
{"op":"mcm","clk":"5354178733","pt":1646222223508,"mc":[{"id":"1.195503871","rc":[{"atb":[[23,0],[28,0]],"id":41419659}],"con":true,"img":false}]}
{"op":"mcm","clk":"5354178795","pt":1646222224194,"mc":[{"id":"1.195503871","rc":[{"atb":[[27,2.72]],"id":41419659}],"con":true,"img":false}]}
{"op":"mcm","clk":"5354178806","pt":1646222224289,"mc":[{"id":"1.195503871","rc":[{"atb":[[22,3.27]],"id":41419659}],"con":true,"img":false}]}
{"op":"mcm","clk":"5354179009","pt":1646222226582,"mc":[{"id":"1.195503871","rc":[{"atb":[[44,0],[60,0]],"id":41419593},{"atb":[[17,0],[19.5,0]],"id":41419651},{"atb":[[10,0],[12.5,0]],"id":41419585},{"atb":[[18,0],[21,0]],"id":41419656},{"atb":[[34,0],[27,0]],"id":41419640}],"con":true,"img":false}]}
{"op":"mcm","clk":"5354179017","pt":1646222226684,"mc":[{"id":"1.195503871","rc":[{"atb":[[34,0],[44,0]],"id":41419594},{"atb":[[12,0],[14.5,0]],"id":41419592},{"atb":[[38,0],[29,0]],"id":41419633}],"con":true,"img":false}]}
{"op":"mcm","clk":"5354179024","pt":1646222226797,"mc":[{"id":"1.195503871","rc":[{"atl":[[880,2]],"id":41435525}],"con":true,"img":false}]}
{"op":"mcm","clk":"5354179034","pt":1646222226893,"mc":[{"id":"1.195503871","rc":[{"atl":[[890,0]],"id":41435525}],"con":true,"img":false}]}
{"op":"mcm","clk":"5354179074","pt":1646222227324,"mc":[{"id":"1.195503871","rc":[{"atb":[[65,2.72],[46,3.27]],"id":41419593},{"atb":[[17.5,3.27],[20,2.72]],"id":41419651},{"atb":[[10.5,3.27],[13,2.72]],"id":41419585},{"atb":[[18.5,3.27],[22,2.72]],"id":41419656},{"atb":[[32,2.72],[26,3.27]],"id":41419640}],"con":true,"img":false}]}
{"op":"mcm","clk":"5354179084","pt":1646222227427,"mc":[{"id":"1.195503871","rc":[{"atb":[[36,3.27],[46,2.72]],"id":41419594},{"atb":[[12.5,3.27],[15,2.72]],"id":41419592},{"atb":[[36,2.72],[28,3.27]],"id":41419633}],"con":true,"img":false}]}
{"op":"mcm","clk":"5354180960","pt":1646222249633,"mc":[{"id":"1.195503871","rc":[{"atl":[[820,2]],"id":41419630},{"atl":[[880,0],[890,2]],"id":41435525},{"atl":[[720,2]],"id":41419632}],"con":true,"img":false}]}
{"op":"mcm","clk":"5354180968","pt":1646222249741,"mc":[{"id":"1.195503871","rc":[{"atl":[[830,0]],"id":41419630},{"atl":[[730,0]],"id":41419632}],"con":true,"img":false}]}
{"op":"mcm","clk":"5354185584","pt":1646222299477,"mc":[{"id":"1.195503871","rc":[{"atl":[[550,2]],"id":41419628},{"atl":[[570,2]],"id":41419654}],"con":true,"img":false}]}
{"op":"mcm","clk":"5354185597","pt":1646222299583,"mc":[{"id":"1.195503871","rc":[{"atl":[[560,0]],"id":41419628},{"atl":[[580,0]],"id":41419654}],"con":true,"img":false}]}
{"op":"mcm","clk":"5354186877","pt":1646222312425,"mc":[{"id":"1.195503871","rc":[{"atl":[[550,0],[560,2]],"id":41419628},{"atl":[[570,0],[580,2]],"id":41419654}],"con":true,"img":false}]}
{"op":"mcm","clk":"5354188006","pt":1646222323611,"mc":[{"id":"1.195503871","rc":[{"atl":[[570,2],[580,0]],"id":41419654}],"con":true,"img":false}]}
{"op":"mcm","clk":"5354188811","pt":1646222332059,"mc":[{"id":"1.195503871","rc":[{"atl":[[570,0],[580,2]],"id":41419654}],"con":true,"img":false}]}
{"op":"mcm","clk":"5354188997","pt":1646222333816,"mc":[{"id":"1.195503871","rc":[{"atb":[[32,0],[26,0]],"id":41419640}],"con":true,"img":false}]}
{"op":"mcm","clk":"5354189056","pt":1646222334643,"mc":[{"id":"1.195503871","rc":[{"atb":[[34,2.72],[27,3.27]],"id":41419640}],"con":true,"img":false}]}
{"op":"mcm","clk":"5354190292","pt":1646222347657,"mc":[{"id":"1.195503871","rc":[{"atb":[[34,0],[27,0]],"id":41419640}],"con":true,"img":false}]}
{"op":"mcm","clk":"5354190366","pt":1646222348443,"mc":[{"id":"1.195503871","rc":[{"atb":[[32,2.72],[26,3.27]],"id":41419640}],"con":true,"img":false}]}
{"op":"mcm","clk":"5354195728","pt":1646222400517,"mc":[{"id":"1.195503871","rc":[{"atl":[[570,2],[580,0]],"id":41419654}],"con":true,"img":false}]}
{"op":"mcm","clk":"5354195763","pt":1646222400725,"mc":[{"id":"1.195503871","rc":[{"atb":[[9.2,25.15]],"id":41419651},{"atl":[[510,2.4]],"id":41419651},{"atb":[[34,12.95]],"id":41419630},{"atl":[[840,1.45]],"id":41419630},{"atb":[[19.5,16.11]],"id":41419626},{"atl":[[830,1.47]],"id":41419626},{"atb":[[9,25.56]],"id":41419590},{"atl":[[400,3.07]],"id":41419590},{"atb":[[36,15.1]],"id":41419586},{"atb":[[70,4.95],[50,9.9]],"id":41435525},{"atl":[[240,4.95]],"id":41435525},{"atb":[[46,6.24]],"id":41419621},{"atl":[[780,0.2]],"id":41419621}],"con":true,"img":false}]}
{"op":"mcm","clk":"5354195779","pt":1646222400886,"mc":[{"id":"1.195503871","rc":[{"atb":[[160,4.95],[100,11.38],[120,9.9],[250,0.63]],"id":41419605},{"atl":[[1000,0.02]],"id":41419605},{"atb":[[18.5,9.9],[20,8.34],[21,4.95],[8.8,25.99]],"id":41419634},{"atl":[[560,0.28],[75,9.9],[590,2.08],[55,4.95]],"id":41419634},{"atb":[[160,4.95],[46,11.38],[95,1.68],[120,9.9]],"id":41419593},{"atl":[[1000,0.15]],"id":41419593},{"atb":[[10.5,22.93],[24,9.9],[27,8.82],[28,4.95]],"id":41419655},{"atl":[[600,0.26],[630,1.94],[80,9.9],[60,4.95]],"id":41419655},{"atb":[[160,4.95]],"id":41419622},{"atb":[[16.5,9.9],[18.5,4.95],[13,20.01]],"id":41419589},{"atl":[[540,2.27],[38,4.95],[46,9.9],[510,0.31]],"id":41419589},{"atb":[[40,13.17],[23,14.97],[48,4.95],[50,5.96]],"id":41435527},{"atl":[[770,0.2],[800,1.53],[110,4.95]],"id":41435527},{"atb":[[16,9.9],[18,4.95]],"id":41419651},{"atl":[[34,4.95],[42,9.9],[480,0.33]],"id":41419651},{"atb":[[44,9.9],[55,4.95]],"id":41419630},{"atl":[[170,4.95],[810,0.19]],"id":41419630},{"atb":[[11.5,9.9],[13,20.01],[13.5,4.95]],"id":41419597},{"atl":[[40,4.95],[48,9.9],[410,0.38],[440,2.79]],"id":41419597},{"atb":[[16.5,4.95],[6.2,34.53],[14,11.64],[14.5,9.9]],"id":28546943},{"atl":[[34,9.9],[28,4.95],[450,0.35],[480,2.55]],"id":28546943},{"atb":[[16,9.9],[18,4.95],[11.5,21.6]],"id":41419659},{"atl":[[65,9.9],[530,2.31],[48,4.95],[500,0.31]],"id":41419659},{"atb":[[44,9.9],[55,10.61]],"id":41419626},{"atl":[[800,0.19],[120,4.95]],"id":41419626},{"atb":[[18.5,16.53],[36,4.95],[40,6.79],[29,9.9]],"id":41419639},{"atl":[[85,4.95],[720,0.21],[750,1.63],[110,9.9]],"id":41419639},{"atb":[[22,15.26],[46,9.9],[60,4.95]],"id":41419606},{"atl":[[170,4.95],[820,0.19],[850,1.43]],"id":41419606},{"atb":[[22,9.9],[11.5,21.6],[24,9.61],[26,4.95]],"id":41419635},{"atl":[[75,9.9],[580,0.27],[610,2.01],[55,4.95]],"id":41419635},{"atb":[[11,9.9],[13,16.59],[7,31.11]],"id":41419585},{"atl":[[23,4.95],[380,0.41],[410,2.99],[27,9.9]],"id":41419585},{"atb":[[85,20.2],[110,4.95],[120,4.05]],"id":41419610},{"atl":[[990,0.15]],"id":41419610},{"atb":[[9,25.56],[19,9.9],[22,15.22]],"id":41419656},{"atl":[[520,2.35],[42,4.95],[50,9.9],[490,0.32]],"id":41419656},{"atb":[[75,11.38],[150,4.95],[110,11.36]],"id":41419623},{"atl":[[1000,0.15]],"id":41419623},{"atb":[[9.6,9.9],[11,4.95]],"id":41419590},{"atl":[[23,4.95],[370,0.43],[27,9.9]],"id":41419590},{"atb":[[150,1.06],[160,4.95],[95,11.38],[120,9.9]],"id":41419652},{"atb":[[16,17.79],[25,9.9],[29,8.22]],"id":41435528},{"atl":[[70,4.95],[630,0.25],[660,1.85],[90,9.9]],"id":41435528},{"atb":[[75,9.9],[95,4.95],[50,3.23]],"id":41419586},{"atl":[[1000,0.15]],"id":41419586},{"atb":[[16,9.9],[18,8.22],[11.5,21.6]],"id":41419598},{"atl":[[32,4.95],[40,9.9],[450,0.35],[480,2.55]],"id":41419598},{"atb":[[18,9.9],[20,8.22],[10,23.71]],"id":41419660},{"atl":[[530,0.29],[560,2.19],[44,4.95],[55,9.9]],"id":41419660},{"atb":[[19,9.9],[22,4.95],[9.8,24.05]],"id":41419627},{"atl":[[530,0.29],[560,2.19],[42,4.95],[50,9.9]],"id":41419627},{"atb":[[25,14.46],[26,9.9],[30,4.95]],"id":41419594},{"atl":[[680,0.23],[710,1.72],[95,4.95]],"id":41419594},{"atb":[[20,9.9],[24,4.95],[15.5,18.1]],"id":41419640},{"atl":[[520,0.3],[550,2.22],[44,4.95],[55,9.9]],"id":41419640},{"atb":[[46,9.9],[27,14.03],[60,4.95]],"id":41419607},{"atl":[[840,0.19],[220,4.95],[870,1.4]],"id":41419607},{"atb":[[17.5,11.64],[18.5,9.9],[21,4.95],[7,25.58]],"id":28546950},{"atl":[[530,2.31],[40,4.95],[48,9.9],[500,0.31]],"id":28546950},{"atb":[[160,4.95],[170,1.72],[50,11.38],[120,9.9]],"id":41419636},{"atb":[[38,12.51],[40,9.9],[48,4.95]],"id":41419611},{"atl":[[780,0.2],[810,1.5]],"id":41419611},{"atb":[[75,2.14],[160,4.95],[120,9.9]],"id":41419657},{"atb":[[8.2,27.41],[11.5,9.9],[13.5,4.95],[15,11.64]],"id":41419591},{"atl":[[32,9.9],[430,0.37],[27,4.95],[460,2.67]],"id":41419591},{"atl":[[880,0.17]],"id":41435525},{"atb":[[38,9.9],[42,3.86],[46,4.95]],"id":41419620},{"atl":[[760,0.2],[100,4.95]],"id":41419620},{"atb":[[19,16.31],[25,9.9],[29,4.95]],"id":41419587},{"atl":[[80,9.9],[640,1.91],[60,4.95]],"id":41419587},{"atb":[[32,4.95],[21,15.57],[27,9.9]],"id":41419632},{"atl":[[710,0.22],[740,1.65],[110,4.95]],"id":41419632},{"atb":[[130,1.23],[160,4.95],[50,10.83],[120,12.63]],"id":41419599},{"atb":[[21,9.9],[25,4.95],[13.5,19.57]],"id":41419628},{"atl":[[75,9.9],[580,2.11],[55,4.95],[1000,0.15]],"id":41419628},{"atb":[[75,4.95],[55,12.63]],"id":41419637},{"atl":[[150,4.95]],"id":41419637},{"atb":[[140,7.62],[160,4.95],[120,13.17]],"id":41419604},{"atb":[[65,4.95],[48,9.9],[30,13.51]],"id":41419612},{"atl":[[220,4.95],[870,0.17],[900,1.35]],"id":41419612},{"atb":[[21,15.57],[42,9.9],[50,4.95]],"id":41419625},{"atl":[[140,4.95],[770,0.2],[800,1.53]],"id":41419625},{"atb":[[11,9.9],[13,4.95],[7.8,28.5],[15,11.64]],"id":41419592},{"atl":[[25,4.95],[410,0.38],[440,2.79],[29,9.9]],"id":41419592},{"atb":[[12.5,20.49]],"id":41419654},{"atl":[[570,2.27],[600,2.04]],"id":41419654},{"atb":[[17.5,14.97],[44,9.9],[55,4.95]],"id":41435526},{"atl":[[860,1.42],[120,4.95]],"id":41435526},{"atb":[[18,16.75],[42,9.9],[50,4.95]],"id":41419621},{"atl":[[810,1.5],[110,4.95]],"id":41419621},{"atb":[[21,9.9],[25,4.95],[15.5,18.1]],"id":41419633},{"atl":[[540,0.29],[570,2.15],[75,9.9],[55,4.95]],"id":41419633},{"atb":[[160,0.99],[90,11.38]],"id":41419600},{"atl":[[1000,0.02]],"id":41419600},{"atb":[[280,0.56],[160,4.95],[85,11.28],[120,9.9]],"id":41419629},{"atb":[[17,17.24],[20,9.9],[24,4.95]],"id":41419596},{"atl":[[540,0.29],[570,2.15],[80,9.9],[60,4.95]],"id":41419596}],"con":true,"img":false}]}
{"op":"mcm","clk":"5354195796","pt":1646222400942,"mc":[{"id":"1.195503871","rc":[{"atl":[[490,0],[510,4.4]],"id":41419651},{"atl":[[380,0],[390,2]],"id":41419590},{"atl":[[890,0],[490,2]],"id":41435525},{"atb":[[60,2.68]],"id":41419637},{"atl":[[870,0.17]],"id":41419637},{"atb":[[19.5,9.9],[23,4.95]],"id":41419654},{"atl":[[80,9.9],[60,4.95]],"id":41419654},{"atb":[[55,7.89]],"id":41435526},{"atl":[[830,0.19]],"id":41435526}],"con":true,"img":false}]}
{"op":"mcm","clk":"5354195813","pt":1646222401049,"mc":[{"id":"1.195503871","rc":[{"atl":[[570,0]],"id":41419634},{"atl":[[460,0]],"id":28546943},{"atl":[[830,0]],"id":41419606},{"atl":[[70,2],[390,0]],"id":41419585},{"atl":[[100,2]],"id":41419598},{"atl":[[530,0]],"id":41419640},{"atl":[[510,0]],"id":28546950},{"atl":[[790,0]],"id":41419611},{"atl":[[440,0]],"id":41419591},{"atl":[[620,0],[230,2]],"id":41419587},{"atl":[[480,2]],"id":41419612},{"atl":[[70,2],[420,0]],"id":41419592},{"atl":[[550,0]],"id":41419633}],"con":true,"img":false}]}
{"op":"mcm","clk":"5354195830","pt":1646222401159,"mc":[{"id":"1.195503871","rc":[{"atl":[[170,2]],"id":41419634},{"atl":[[610,0],[220,2]],"id":41419655},{"atl":[[520,0],[130,2]],"id":41419589},{"atl":[[380,2],[780,0]],"id":41435527},{"atl":[[820,0],[420,2]],"id":41419630},{"atl":[[65,2],[420,0]],"id":41419597},{"atl":[[80,2]],"id":28546943},{"atl":[[110,2],[510,0]],"id":41419659},{"atl":[[810,0],[410,2]],"id":41419626},{"atl":[[330,2],[730,0]],"id":41419639},{"atl":[[440,2]],"id":41419606},{"atl":[[590,0],[200,2]],"id":41419635},{"atl":[[140,2],[500,0]],"id":41419656},{"atl":[[640,0],[240,2]],"id":41435528},{"atl":[[460,0]],"id":41419598},{"atl":[[540,0],[140,2]],"id":41419660},{"atl":[[540,0],[140,2]],"id":41419627},{"atl":[[310,2],[690,0]],"id":41419594},{"atl":[[140,2]],"id":41419640},{"atl":[[850,0],[460,2]],"id":41419607},{"atl":[[130,2]],"id":28546950},{"atl":[[800,2]],"id":41419611},{"atl":[[70,2]],"id":41419591},{"atl":[[380,2],[770,0]],"id":41419620},{"atl":[[320,2],[720,0]],"id":41419632},{"atl":[[560,0],[160,2]],"id":41419628},{"atl":[[880,0],[490,2]],"id":41419637},{"atl":[[880,0]],"id":41419612},{"atl":[[380,2],[780,0]],"id":41419625},{"atl":[[570,0.27],[170,2]],"id":41419654},{"atl":[[840,0],[440,2]],"id":41435526},{"atl":[[790,0],[400,2]],"id":41419621},{"atl":[[160,2]],"id":41419633},{"atl":[[550,0],[150,2]],"id":41419596}],"con":true,"img":false}]}
{"op":"mcm","clk":"5354195902","pt":1646222401541,"mc":[{"id":"1.195503871","rc":[{"atb":[[70,0],[38,0],[240,0]],"id":41419605},{"atb":[[8.8,8.91],[4.4,0],[5.4,0]],"id":41419634},{"atb":[[19,0],[90,0],[28,0]],"id":41419593},{"atb":[[5.1,0],[10.5,8.91],[6.2,0]],"id":41419655},{"atb":[[700,0],[400,0],[500,0]],"id":41419622},{"atb":[[5.6,0],[7.2,0],[13,8.91]],"id":41419589},{"atb":[[8.6,0],[23,8.91],[11.5,0]],"id":41435527},{"atb":[[5.6,0],[9.2,8.91],[4.6,0]],"id":41419651},{"atb":[[700,0],[400,0],[500,0]],"id":41419601},{"atb":[[16,0],[34,8.91],[11,0]],"id":41419630},{"atb":[[5.6,0],[7.2,0],[13,8.91]],"id":41419597},{"atb":[[6.2,8.91],[4.1,0],[3.55,0]],"id":28546943},{"atb":[[5.3,0],[11.5,8.91],[6.6,0]],"id":41419659},{"atb":[[19.5,8.91],[9.8,0],[7.8,0]],"id":41419626},{"atb":[[18.5,8.91],[7.4,0],[9.4,0]],"id":41419639},{"atb":[[22,8.91],[11,0],[8.4,0]],"id":41419606},{"atb":[[5.3,0],[11.5,8.91],[6.6,0]],"id":41419635},{"atb":[[4.5,0],[7,8.91],[3.75,0]],"id":41419585},{"atb":[[20,0],[100,0],[30,0]],"id":41419610},{"atb":[[9,8.91],[4.5,0],[5.5,0]],"id":41419656},{"atb":[[19.5,0],[95,0],[29,0]],"id":41419623},{"atb":[[9,8.91],[4.5,0],[5.5,0]],"id":41419590},{"atb":[[20,0],[100,0],[30,0]],"id":41419652},{"atb":[[16,8.91],[6.4,0],[8.4,0]],"id":41435528},{"atb":[[16.5,0],[36,11.29],[11.5,0]],"id":41419586},{"atb":[[5.3,0],[11.5,8.91],[6.6,0]],"id":41419598},{"atb":[[10,8.91],[5,0],[6,0]],"id":41419660},{"atb":[[9.8,8.91],[4.9,0],[5.9,0]],"id":41419627},{"atb":[[9,0],[25,8.91],[12.5,0]],"id":41419594},{"atb":[[6.2,0],[8.2,0],[15.5,8.91]],"id":41419640},{"atb":[[27,8.91],[13.5,0],[9.4,0]],"id":41419607},{"atb":[[4.3,0],[6.6,0],[3.65,0]],"id":28546950},{"atb":[[170,0.93],[44,0],[27,0]],"id":41419636},{"atb":[[700,0],[400,0],[500,0]],"id":41419603},{"atb":[[17,0],[38,8.91],[12,0]],"id":41419611},{"atb":[[65,0],[16.5,0],[23,0],[48,11.38]],"id":41419657},{"atb":[[5.1,0],[8.2,8.91],[4.1,0]],"id":41419591},{"atb":[[9,0],[25,8.91],[12.5,0]],"id":41435525},{"atl":[[910,1.34]],"id":41435525},{"atb":[[6.2,0],[8.2,0],[15.5,8.91]],"id":41419620},{"atl":[[790,1.54]],"id":41419620},{"atb":[[9.6,0],[19,8.91],[7.6,0]],"id":41419587},{"atl":[[610,0.26]],"id":41419587},{"atb":[[21,8.91],[10.5,10.53],[8.2,0]],"id":41419632},{"atb":[[20,0],[50,8.11],[15,0]],"id":41419599},{"atb":[[7.4,0],[13.5,8.91],[5.7,0]],"id":41419628},{"atb":[[700,0],[400,0],[500,0]],"id":41419608},{"atb":[[9.6,0],[28,8.91],[14,0]],"id":41419637},{"atl":[[900,1.35]],"id":41419637},{"atb":[[140,5.7],[70,0],[340,0]],"id":41419604},{"atb":[[10,0],[30,8.91],[15,0]],"id":41419612},{"atb":[[21,8.91],[10.5,0],[8.2,0]],"id":41419625},{"atb":[[3.95,0],[4.9,0],[7.8,8.91]],"id":41419592},{"atb":[[5.5,0],[12.5,8.91],[7,0]],"id":41419654},{"atb":[[17,0],[6.8,0],[8.8,0]],"id":41435526},{"atb":[[7.2,0],[18,8.91],[9.2,0]],"id":41419621},{"atb":[[6.2,0],[8.2,0],[15.5,8.91]],"id":41419633},{"atb":[[150,0],[160,5.95],[40,2.56],[25,0],[120,9.9]],"id":41419600},{"atb":[[270,0],[85,8.11],[44,0]],"id":41419629},{"atb":[[17,8.91],[6.8,0],[8.8,0]],"id":41419596}],"con":true,"img":false}]}
{"op":"mcm","clk":"5354195917","pt":1646222401638,"mc":[{"id":"1.195503871","rc":[{"atb":[[150,4.95],[160,0],[110,9.9],[120,0]],"id":41419593},{"atl":[[170,0],[200,4.95]],"id":41419630},{"atl":[[40,0],[44,4.95],[48,0],[55,9.9]],"id":41419597},{"atl":[[65,0],[75,9.9],[48,0],[55,4.95]],"id":41419659},{"atl":[[23,0],[25,4.95],[27,0],[29,9.9]],"id":41419590},{"atb":[[70,9.9],[75,0],[90,4.95],[95,0]],"id":41419586},{"atl":[[65,9.9],[42,0],[48,4.95],[50,0]],"id":41419627},{"atl":[[65,9.9],[44,0],[48,4.95],[55,0]],"id":41419640},{"atb":[[170,0]],"id":41419636},{"atl":[[65,4.95],[75,0],[85,9.9],[55,0]],"id":41419628},{"atl":[[140,0],[150,4.95]],"id":41419625},{"atl":[[80,0],[60,0]],"id":41419654},{"atl":[[65,4.95],[75,0],[85,9.9],[55,0]],"id":41419633}],"con":true,"img":false}]}
{"op":"mcm","clk":"5354195932","pt":1646222401778,"mc":[{"id":"1.195503871","rc":[{"atl":[[130,4.95]],"id":41419632},{"atl":[[70,4.95],[90,9.9]],"id":41419654}],"con":true,"img":false}]}
{"op":"mcm","clk":"5354195945","pt":1646222401849,"mc":[{"id":"1.195503871","rc":[{"atl":[[110,0]],"id":41419632}],"con":true,"img":false}]}
{"op":"mcm","clk":"5354195960","pt":1646222401949,"mc":[{"id":"1.195503871","rc":[{"atb":[[18.5,0],[20,13.29],[21,0]],"id":41419634},{"atb":[[95,12.99]],"id":41419622},{"atb":[[280,0.56],[40,10.11],[160,4.95],[120,9.9]],"id":41419601},{"atb":[[230,0.69]],"id":41419608}],"con":true,"img":false}]}
{"op":"mcm","clk":"5354195974","pt":1646222402055,"mc":[{"id":"1.195503871","rc":[{"atb":[[170,0.93]],"id":41419622},{"atb":[[40,10.11],[160,4.95],[210,0.75],[120,9.9]],"id":41419603},{"atb":[[40,10.11],[160,4.95],[120,9.9]],"id":41419608},{"atb":[[180,0.88]],"id":41419604},{"atl":[[1000,0.15]],"id":41419604}],"con":true,"img":false}]}
{"op":"mcm","clk":"5354196019","pt":1646222402398,"mc":[{"id":"1.195503871","rc":[{"atl":[[70,9.9],[75,0],[50,4.95],[55,0]],"id":41419659},{"atl":[[46,4.95],[60,9.9]],"id":41419627},{"atb":[[160,5.95]],"id":41419636}],"con":true,"img":false}]}
{"op":"mcm","clk":"5354196033","pt":1646222402438,"mc":[{"id":"1.195503871","rc":[{"atl":[[65,0],[48,0]],"id":41419627}],"con":true,"img":false}]}
{"op":"mcm","clk":"5354196602","pt":1646222405547,"mc":[{"id":"1.195503871","rc":[{"atb":[[6.6,17.86]],"id":41419590}],"con":true,"img":false}]}
{"op":"mcm","clk":"5354196617","pt":1646222405659,"mc":[{"id":"1.195503871","rc":[{"atb":[[40,0],[60,2]],"id":41419605},{"atb":[[10.5,10.53],[8.2,0]],"id":41419634},{"atb":[[40,0],[55,2]],"id":41419593},{"atb":[[12,9.09],[8.8,0]],"id":41419655},{"atb":[[40,0],[60,2]],"id":41419622},{"atb":[[9.2,12.2],[7,0]],"id":41419589},{"atb":[[18,5.88],[13.5,0]],"id":41435527},{"atb":[[8,14.29],[6,0]],"id":41419651},{"atb":[[40,8.11],[60,2]],"id":41419601},{"atb":[[7.2,16.13],[5.2,0]],"id":41419597},{"atb":[[6,0],[8.4,13.51]],"id":28546943},{"atb":[[8,14.29],[6.2,0]],"id":41419659},{"atb":[[9.8,0],[13.5,8]],"id":41419639},{"atb":[[17.5,0],[23,4.55]],"id":41419606},{"atb":[[8.6,0],[11,10]],"id":41419635},{"atb":[[7.4,0],[9.8,11.36]],"id":41419656},{"atb":[[4.9,0]],"id":41419590},{"atb":[[40,0],[60,2]],"id":41419652},{"atb":[[12,9.09],[9.8,0]],"id":41435528},{"atb":[[38,3.27],[55,2]],"id":41419586},{"atb":[[5.8,0],[7.6,15.15]],"id":41419598},{"atb":[[10,20.02],[7,0]],"id":41419660},{"atb":[[10,11.11],[7.4,0]],"id":41419627},{"atb":[[13,8.33],[8.8,0]],"id":41419594},{"atb":[[10,11.11],[7.4,0]],"id":41419640},{"atb":[[19.5,0],[25,4.17]],"id":41419607},{"atb":[[7,8.91],[9.4,11.9]],"id":28546950},{"atb":[[40,0],[60,2]],"id":41419636},{"atb":[[40,8.11],[60,2]],"id":41419603},{"atb":[[40,0],[60,2]],"id":41419657},{"atb":[[7.6,15.15],[5.4,0]],"id":41419591},{"atb":[[23,0],[30,3.45]],"id":41435525},{"atb":[[17.5,6.06],[14.5,0]],"id":41419620},{"atb":[[12,9.09],[8.8,0]],"id":41419587},{"atb":[[10.5,0],[13.5,8]],"id":41419632},{"atb":[[40,0],[60,2]],"id":41419599},{"atb":[[10.5,10.53],[7.8,0]],"id":41419628},{"atb":[[40,8.11],[60,2]],"id":41419608},{"atb":[[40,0],[55,2]],"id":41419604},{"atb":[[5.5,0],[7.4,15.62]],"id":41419592},{"atb":[[8,0],[11,10]],"id":41419654},{"atb":[[17.5,8.91],[23,4.55]],"id":41435526},{"atb":[[16,0],[19.5,5.41]],"id":41419621},{"atb":[[10.5,10.53],[7.8,0]],"id":41419633},{"atb":[[40,0],[60,2]],"id":41419600},{"atb":[[10,11.11],[7.8,0]],"id":41419596}],"con":true,"img":false}]}
{"op":"mcm","clk":"5354196681","pt":1646222406127,"mc":[{"id":"1.195503871","rc":[{"atl":[[880,2.17],[490,0]],"id":41435525}],"con":true,"img":false}]}
{"op":"mcm","clk":"5354196690","pt":1646222406229,"mc":[{"id":"1.195503871","rc":[{"atl":[[870,2.17],[480,0]],"id":41419612}],"con":true,"img":false}]}
{"op":"mcm","clk":"5354196703","pt":1646222406348,"mc":[{"id":"1.195503871","rc":[{"atb":[[70,3.85],[38,7.19],[240,0.55]],"id":41419605},{"atb":[[8.8,25.99],[4.4,78.35],[5.4,60.54]],"id":41419634},{"atb":[[19,14.8],[90,1.49],[28,9.86]],"id":41419593},{"atb":[[5.1,64.97],[10.5,22.93],[6.2,51.23]],"id":41419655},{"atb":[[700,0.19],[400,0.67],[500,0.53]],"id":41419622},{"atb":[[5.6,57.91],[7.2,42.96],[13,20.01]],"id":41419589},{"atb":[[8.6,35.05],[23,14.97],[11.5,25.37]],"id":41435527},{"atl":[[380,0],[770,2.2]],"id":41435527},{"atb":[[5.6,57.91],[9.2,25.15],[4.6,74]],"id":41419651},{"atb":[[700,0.19],[400,0.67],[500,0.53]],"id":41419601},{"atb":[[16,17.76],[34,12.95],[11,26.64]],"id":41419630},{"atb":[[5.6,57.91],[7.2,59.09],[13,20.01]],"id":41419597},{"atb":[[6.2,34.53],[4.1,85.93],[3.55,104.47]],"id":28546943},{"atb":[[5.3,61.95],[11.5,21.6],[6.6,47.57]],"id":41419659},{"atb":[[19.5,16.11],[9.8,30.27],[7.8,39.17]],"id":41419626},{"atl":[[410,0],[800,2.19]],"id":41419626},{"atb":[[18.5,16.53],[7.4,41.62],[9.4,31.71]],"id":41419639},{"atb":[[22,15.26],[11,26.64],[8.4,35.99]],"id":41419606},{"atl":[[820,2.19],[440,0]],"id":41419606},{"atb":[[5.3,61.95],[11.5,21.6],[6.6,47.57]],"id":41419635},{"atb":[[4.5,76.11],[7,31.11],[3.75,96.87]],"id":41419585},{"atb":[[20,14.02],[100,1.34],[30,9.18]],"id":41419610},{"atb":[[9,25.56],[4.5,76.11],[5.5,59.19]],"id":41419656},{"atb":[[19.5,14.39],[95,1.41],[29,9.51]],"id":41419623},{"atb":[[9,25.56],[4.5,76.11],[5.5,59.19]],"id":41419590},{"atb":[[20,14.02],[100,1.34],[30,9.18]],"id":41419652},{"atb":[[16,17.79],[6.4,49.33],[8.4,35.99]],"id":41435528},{"atb":[[16.5,17.18],[36,15.1],[11.5,25.37]],"id":41419586},{"atb":[[5.3,61.95],[11.5,21.6],[6.6,47.57]],"id":41419598},{"atb":[[10,34.82],[5,66.6],[6,53.28]],"id":41419660},{"atb":[[9.8,24.05],[4.9,68.3],[5.9,54.37]],"id":41419627},{"atb":[[9,33.3],[25,14.46],[12.5,23.16]],"id":41419594},{"atl":[[310,0],[680,2.23]],"id":41419594},{"atb":[[6.2,51.23],[8.2,37],[15.5,18.1]],"id":41419640},{"atb":[[27,14.03],[13.5,21.31],[9.4,31.71]],"id":41419607},{"atl":[[840,2.19],[460,0]],"id":41419607},{"atb":[[4.3,80.72],[6.6,23.78],[3.65,100.52]],"id":28546950},{"atb":[[170,0.79],[44,6.19],[27,10.24]],"id":41419636},{"atb":[[700,0.19],[400,0.67],[500,0.53]],"id":41419603},{"atb":[[17,16.65],[38,12.51],[12,24.22]],"id":41419611},{"atb":[[65,2.08],[16.5,17.18],[23,12.11]],"id":41419657},{"atb":[[5.1,64.97],[8.2,27.41],[4.1,85.93]],"id":41419591},{"atb":[[9,33.3],[25,14.46],[12.5,23.16]],"id":41435525},{"atb":[[6.2,51.23],[8.2,37],[15.5,18.1]],"id":41419620},{"atl":[[380,0],[760,2.2]],"id":41419620},{"atb":[[9.6,30.97],[19,16.31],[7.6,40.36]],"id":41419587},{"atb":[[21,15.57],[10.5,28.04],[8.2,37]],"id":41419632},{"atl":[[320,0],[710,2.22]],"id":41419632},{"atb":[[20,14.02],[50,10.83],[15,19.02]],"id":41419599},{"atb":[[7.4,41.62],[13.5,19.57],[5.7,56.68]],"id":41419628},{"atb":[[700,0.19],[400,0.67],[500,0.53]],"id":41419608},{"atb":[[9.6,30.97],[28,13.84],[14,20.49]],"id":41419637},{"atl":[[870,2.17],[490,0]],"id":41419637},{"atb":[[140,7.62],[70,3.85],[340,0.39]],"id":41419604},{"atb":[[10,29.59],[30,13.51],[15,19.02]],"id":41419612},{"atb":[[21,15.57],[10.5,28.04],[8.2,37]],"id":41419625},{"atb":[[3.95,90.3],[4.9,68.3],[7.8,28.5]],"id":41419592},{"atb":[[5.5,59.19],[12.5,20.49],[7,44.4]],"id":41419654},{"atb":[[17,8.32],[6.8,45.93],[8.8,34.15]],"id":41435526},{"atl":[[830,2.19],[440,0]],"id":41435526},{"atb":[[7.2,42.96],[18,16.75],[9.2,32.48]],"id":41419621},{"atl":[[780,2.2],[400,0]],"id":41419621},{"atb":[[6.2,51.23],[8.2,37],[15.5,18.1]],"id":41419633},{"atb":[[150,0.89],[40,6.82],[25,11.1]],"id":41419600},{"atb":[[270,0.49],[85,11.28],[44,6.19]],"id":41419629},{"atb":[[17,17.24],[6.8,45.93],[8.8,34.15]],"id":41419596}],"con":true,"img":false}]}
{"op":"mcm","clk":"5354196726","pt":1646222406551,"mc":[{"id":"1.195503871","rc":[{"atl":[[810,2.19],[420,0]],"id":41419630},{"atl":[[380,0],[770,2.2]],"id":41419625}],"con":true,"img":false}]}
{"op":"mcm","clk":"5354196757","pt":1646222406866,"mc":[{"id":"1.195503871","rc":[{"atb":[[95,3.27]],"id":41419622},{"atb":[[40,0]],"id":41419601},{"atb":[[40,0]],"id":41419603},{"atb":[[40,0]],"id":41419608},{"atl":[[1000,0]],"id":41419604}],"con":true,"img":false}]}
{"op":"mcm","clk":"5354197243","pt":1646222411241,"mc":[{"id":"1.195503871","rc":[{"atl":[[65,9.9],[46,0],[48,4.95],[60,0]],"id":41419627}],"con":true,"img":false}]}
{"op":"mcm","clk":"5354197745","pt":1646222416263,"mc":[{"id":"1.195503871","rc":[{"atl":[[70,0],[75,9.9],[50,0],[55,4.95]],"id":41419659}],"con":true,"img":false}]}
{"op":"mcm","clk":"5354197758","pt":1646222416366,"mc":[{"id":"1.195503871","rc":[{"atl":[[510,2]],"id":41419651},{"atl":[[370,3.86]],"id":41419590},{"atb":[[50,8.19]],"id":41419621}],"con":true,"img":false}]}
{"op":"mcm","clk":"5354197769","pt":1646222416470,"mc":[{"id":"1.195503871","rc":[{"atb":[[17.5,15.48],[9.2,16.24]],"id":41419651},{"atl":[[480,2.98]],"id":41419651},{"atb":[[34,4.03],[48,12.18]],"id":41419630},{"atb":[[19.5,7.19],[42,15.48]],"id":41419626},{"atb":[[9,16.65],[11,17.17]],"id":41419590},{"atl":[[400,0]],"id":41419590},{"atb":[[36,3.8],[55,12.32]],"id":41419586},{"atl":[[110,6.4]],"id":41419621}],"con":true,"img":false}]}
{"op":"mcm","clk":"5354197782","pt":1646222416574,"mc":[{"id":"1.195503871","rc":[{"atb":[[160,6.73]],"id":41419605},{"atb":[[17,15.48],[8.8,17.07]],"id":41419634},{"atl":[[590,0],[170,9.5]],"id":41419634},{"atb":[[150,6.01]],"id":41419593},{"atb":[[28,10.82]],"id":41419655},{"atb":[[23,6.05]],"id":41435527},{"atl":[[200,5.74]],"id":41419630},{"atl":[[44,8.64]],"id":41419597},{"atl":[[160,0.99]],"id":41419606},{"atl":[[55,7.89]],"id":41419635},{"atb":[[100,7.29]],"id":41419610},{"atb":[[18.5,25.35]],"id":41419656},{"atl":[[140,11.11],[42,8.82]],"id":41419656},{"atb":[[150,6.01],[75,3.27],[100,14.14]],"id":41419623},{"atl":[[140,11.11]],"id":41419660},{"atl":[[130,1.23]],"id":41419627},{"atl":[[210,0.75]],"id":41419607},{"atb":[[7,0]],"id":28546950},{"atl":[[130,11.81],[40,9.02]],"id":28546950},{"atb":[[50,3.27]],"id":41419636},{"atb":[[170,0.93]],"id":41419657},{"atb":[[46,8.47]],"id":41419620},{"atl":[[100,6.55]],"id":41419620},{"atb":[[19,7.4]],"id":41419587},{"atl":[[130,6.18]],"id":41419632},{"atb":[[50,2.71],[120,23.26]],"id":41419599},{"atb":[[25,17.17],[13.5,10.65]],"id":41419628},{"atl":[[160,9.97]],"id":41419628},{"atb":[[140,1.91]],"id":41419604},{"atb":[[21,6.66]],"id":41419625},{"atb":[[12.5,17.98],[7.8,19.58]],"id":41419592},{"atl":[[70,7.25],[170,9.5]],"id":41419654},{"atb":[[17.5,0]],"id":41435526},{"atb":[[42,24.62]],"id":41419621},{"atb":[[85,3.17]],"id":41419629}],"con":true,"img":false}]}
{"op":"mcm","clk":"5354197796","pt":1646222416682,"mc":[{"id":"1.195503871","rc":[{"atb":[[100,3.27]],"id":41419605},{"atl":[[55,7.89]],"id":41419634},{"atb":[[95,11.53],[46,3.27]],"id":41419593},{"atb":[[10.5,14.02],[24,30.37]],"id":41419655},{"atl":[[630,0],[220,7.79],[60,7.64]],"id":41419655},{"atb":[[18.5,17.17],[13,11.1]],"id":41419589},{"atl":[[130,11.81],[540,0]],"id":41419589},{"atb":[[40,27.89]],"id":41435527},{"atl":[[110,6.4]],"id":41435527},{"atb":[[13,11.1],[13.5,17.17]],"id":41419597},{"atl":[[65,14.21],[440,0]],"id":41419597},{"atb":[[16.5,15.18],[6.2,25.61],[14,33.73]],"id":28546943},{"atl":[[80,17.95],[28,10.82],[480,0]],"id":28546943},{"atb":[[18,17.17],[11.5,12.68]],"id":41419659},{"atl":[[530,0],[110,13.6]],"id":41419659},{"atl":[[120,6.28]],"id":41419626},{"atb":[[18.5,7.61],[30,17.98]],"id":41419639},{"atl":[[330,5.85],[85,6.83],[750,0]],"id":41419639},{"atb":[[22,6.34],[48,12.18]],"id":41419606},{"atb":[[22,31.56],[11.5,12.68],[26,11.29]],"id":41419635},{"atl":[[610,0],[200,8.37]],"id":41419635},{"atb":[[10.5,25.35],[7,22.19]],"id":41419585},{"atl":[[70,20.23],[23,12.15],[410,0]],"id":41419585},{"atb":[[85,13.17]],"id":41419610},{"atb":[[9,16.65]],"id":41419656},{"atl":[[520,0]],"id":41419656},{"atl":[[25,11.55]],"id":41419590},{"atb":[[140,10.84],[170,0.93],[95,3.27]],"id":41419652},{"atb":[[16,8.87],[25,29.48]],"id":41435528},{"atl":[[660,0],[240,7.31]],"id":41435528},{"atb":[[95,1.68]],"id":41419586},{"atb":[[16,29.48],[11.5,12.68]],"id":41419598},{"atl":[[100,14.76],[480,0]],"id":41419598},{"atb":[[18,29.48],[10,25.91]],"id":41419660},{"atl":[[560,0]],"id":41419660},{"atb":[[22,17.17],[9.8,15.13]],"id":41419627},{"atl":[[140,11.11],[560,0]],"id":41419627},{"atb":[[25,5.54],[30,13.87]],"id":41419594},{"atl":[[95,6.63]],"id":41419594},{"atb":[[24,17.17],[15.5,9.18]],"id":41419640},{"atl":[[140,11.11],[550,0],[48,8.32]],"id":41419640},{"atb":[[55,12.18],[27,5.12]],"id":41419607},{"atb":[[17.5,33.73],[21,12.88]],"id":28546950},{"atl":[[530,0]],"id":28546950},{"atb":[[120,20.54]],"id":41419636},{"atb":[[38,3.6],[48,11.98]],"id":41419611},{"atb":[[8.2,18.49],[12.5,17.98]],"id":41419591},{"atl":[[27,11.05],[460,0]],"id":41419591},{"atl":[[230,0.69]],"id":41435525},{"atb":[[28,15.48]],"id":41419587},{"atl":[[640,0],[230,7.54]],"id":41419587},{"atb":[[32,13.87],[21,6.66]],"id":41419632},{"atb":[[170,0.93]],"id":41419599},{"atl":[[65,7.43],[580,0]],"id":41419628},{"atb":[[75,7.09]],"id":41419637},{"atl":[[150,6.01]],"id":41419637},{"atb":[[170,4.62]],"id":41419604},{"atb":[[60,12.18],[30,4.59]],"id":41419612},{"atl":[[210,0.75]],"id":41419612},{"atb":[[44,12.18]],"id":41419625},{"atl":[[150,6.01]],"id":41419625},{"atl":[[70,16.71],[25,11.55],[440,0]],"id":41419592},{"atb":[[23,17.17],[12.5,11.58]],"id":41419654},{"atl":[[600,0]],"id":41419654},{"atb":[[44,21.32]],"id":41435526},{"atl":[[120,6.28]],"id":41435526},{"atb":[[18,7.83]],"id":41419621},{"atb":[[15.5,9.18]],"id":41419633},{"atl":[[65,7.43],[570,0],[160,9.97]],"id":41419633},{"atb":[[130,8.1],[90,3.27]],"id":41419600},{"atb":[[160,6.64]],"id":41419629},{"atb":[[17,8.32],[24,17.17]],"id":41419596},{"atl":[[570,0],[150,10.5],[55,2.93]],"id":41419596}],"con":true,"img":false}]}
{"op":"mcm","clk":"5354197807","pt":1646222416736,"mc":[{"id":"1.195503871","rc":[{"atl":[[55,7.89]],"id":41419659}],"con":true,"img":false}]}
{"op":"mcm","clk":"5354197817","pt":1646222416840,"mc":[{"id":"1.195503871","rc":[{"atl":[[390,0],[50,2.04]],"id":41419590},{"atl":[[70,16.71]],"id":41419591},{"atb":[[25,17.17]],"id":41419633}],"con":true,"img":false}]}
{"op":"mcm","clk":"5354197827","pt":1646222416954,"mc":[{"id":"1.195503871","rc":[{"atl":[[840,3.7],[870,0]],"id":41419607}],"con":true,"img":false}]}
{"op":"mcm","clk":"5354197841","pt":1646222417050,"mc":[{"id":"1.195503871","rc":[{"atl":[[820,3.74],[850,0]],"id":41419606},{"atb":[[46,2.72]],"id":41419621}],"con":true,"img":false}]}
{"op":"mcm","clk":"5354197858","pt":1646222417151,"mc":[{"id":"1.195503871","rc":[{"atb":[[60,12.18]],"id":41435525},{"atl":[[870,3.64],[900,0]],"id":41419612}],"con":true,"img":false}]}
{"op":"mcm","clk":"5354197871","pt":1646222417257,"mc":[{"id":"1.195503871","rc":[{"atl":[[410,0]],"id":41419597},{"atl":[[530,0]],"id":41419627},{"atl":[[840,3.5]],"id":41419607},{"atb":[[48,3.27],[120,20.55]],"id":41419657},{"atb":[[25,5.54]],"id":41435525},{"atl":[[880,3.62],[910,0]],"id":41435525},{"atb":[[40,12.53],[15.5,9.18]],"id":41419620},{"atl":[[760,2]],"id":41419620},{"atl":[[710,2]],"id":41419632},{"atb":[[55,25.57]],"id":41419637},{"atl":[[780,2]],"id":41419621}],"con":true,"img":false}]}
{"op":"mcm","clk":"5354197884","pt":1646222417363,"mc":[{"id":"1.195503871","rc":[{"atl":[[560,0]],"id":41419634},{"atb":[[95,9.85]],"id":41419593},{"atb":[[27,2.72]],"id":41419655},{"atl":[[810,2]],"id":41419630},{"atb":[[14,24.81]],"id":28546943},{"atl":[[720,0]],"id":41419639},{"atl":[[820,3.54]],"id":41419606},{"atb":[[24,2.72]],"id":41419635},{"atl":[[580,0]],"id":41419635},{"atl":[[380,0]],"id":41419585},{"atl":[[490,0]],"id":41419656},{"atb":[[110,9.9]],"id":41419623},{"atb":[[150,0]],"id":41419652},{"atb":[[50,0]],"id":41419586},{"atl":[[680,2]],"id":41419594},{"atl":[[500,0]],"id":28546950},{"atb":[[75,0]],"id":41419657},{"atl":[[430,0]],"id":41419591},{"atl":[[880,3.44]],"id":41435525},{"atb":[[42,0]],"id":41419620},{"atb":[[130,0]],"id":41419599},{"atb":[[28,4.93]],"id":41419637},{"atl":[[870,3.46]],"id":41419612},{"atl":[[570,0]],"id":41419654},{"atl":[[830,2]],"id":41435526},{"atl":[[540,0]],"id":41419633}],"con":true,"img":false}]}
{"op":"mcm","clk":"5354197893","pt":1646222417467,"mc":[{"id":"1.195503871","rc":[{"atl":[[600,0]],"id":41419655},{"atl":[[770,2]],"id":41435527},{"atl":[[28,4.95],[450,0]],"id":28546943},{"atl":[[500,0]],"id":41419659},{"atl":[[800,2]],"id":41419626},{"atl":[[370,3.43]],"id":41419590},{"atl":[[520,0]],"id":41419640},{"atb":[[17.5,24.81]],"id":28546950},{"atl":[[1000,0]],"id":41419628},{"atb":[[60,0]],"id":41419637},{"atl":[[870,2]],"id":41419637},{"atl":[[770,2]],"id":41419625},{"atl":[[410,0]],"id":41419592},{"atl":[[540,0]],"id":41419596}],"con":true,"img":false}]}
{"op":"mcm","clk":"5354197958","pt":1646222418042,"mc":[{"id":"1.195503871","rc":[{"atb":[[55,12.63]],"id":41419637}],"con":true,"img":false}]}
{"op":"mcm","clk":"5354197978","pt":1646222418251,"mc":[{"id":"1.195503871","rc":[{"atl":[[34,14.71]],"id":28546943}],"con":true,"img":false}]}
{"op":"mcm","clk":"5354198237","pt":1646222420232,"mc":[{"id":"1.195503871","rc":[{"atb":[[170,1.72]],"id":41419636}],"con":true,"img":false}]}
{"op":"mcm","clk":"5354198303","pt":1646222420649,"mc":[{"id":"1.195503871","rc":[{"atl":[[210,0]],"id":41419607},{"atl":[[230,0]],"id":41435525},{"atl":[[210,0],[230,4.95]],"id":41419612}],"con":true,"img":false}]}
{"op":"mcm","clk":"5354198321","pt":1646222420754,"mc":[{"id":"1.195503871","rc":[{"atl":[[160,0]],"id":41419606},{"atl":[[220,0]],"id":41419612},{"atl":[[55,0]],"id":41419596}],"con":true,"img":false}]}
{"op":"mcm","clk":"5354198340","pt":1646222420855,"mc":[{"id":"1.195503871","rc":[{"atl":[[870,1.46],[480,2]],"id":41419612}],"con":true,"img":false}]}
{"op":"mcm","clk":"5354198365","pt":1646222421065,"mc":[{"id":"1.195503871","rc":[{"atb":[[160,4.95]],"id":41419636}],"con":true,"img":false}]}
{"op":"mcm","clk":"5354198407","pt":1646222421477,"mc":[{"id":"1.195503871","rc":[{"atl":[[220,5.67]],"id":41419607},{"atl":[[240,5.61]],"id":41435525},{"atl":[[230,5.64]],"id":41419612}],"con":true,"img":false}]}
{"op":"mcm","clk":"5354198427","pt":1646222421636,"mc":[{"id":"1.195503871","rc":[{"atl":[[170,5.89]],"id":41419606},{"atl":[[75,2.14]],"id":41419596}],"con":true,"img":false}]}
{"op":"mcm","clk":"5354198798","pt":1646222424863,"mc":[{"id":"1.195503871","rc":[{"atb":[[38,32.26],[40,2.72]],"id":41419620}],"con":true,"img":false}]}
{"op":"mcm","clk":"5354198932","pt":1646222425958,"mc":[{"id":"1.195503871","rc":[{"atl":[[870,3.46],[480,0]],"id":41419612}],"con":true,"img":false}]}
{"op":"mcm","clk":"5354199568","pt":1646222431892,"mc":[{"id":"1.195503871","rc":[{"atl":[[370,0],[50,21.63]],"id":41419590}],"con":true,"img":false}]}
{"op":"mcm","clk":"5354199580","pt":1646222431995,"mc":[{"id":"1.195503871","rc":[{"atb":[[70,19.76],[55,2]],"id":41419586},{"atl":[[48,8.32]],"id":41419627}],"con":true,"img":false}]}
{"op":"mcm","clk":"5354199590","pt":1646222432100,"mc":[{"id":"1.195503871","rc":[{"atl":[[28,10.82]],"id":28546943},{"atl":[[130,11.38],[140,2]],"id":41419627},{"atl":[[150,2],[80,22.12],[60,7.64]],"id":41419596}],"con":true,"img":false}]}
{"op":"mcm","clk":"5354199623","pt":1646222432361,"mc":[{"id":"1.195503871","rc":[{"atl":[[240,5.49]],"id":41419607}],"con":true,"img":false}]}
{"op":"mcm","clk":"5354199633","pt":1646222432466,"mc":[{"id":"1.195503871","rc":[{"atl":[[190,6.94],[820,2]],"id":41419606},{"atl":[[840,1.5],[460,2]],"id":41419607}],"con":true,"img":false}]}
{"op":"mcm","clk":"5354199643","pt":1646222432569,"mc":[{"id":"1.195503871","rc":[{"atl":[[870,2],[250,5.28]],"id":41419612}],"con":true,"img":false}]}
{"op":"mcm","clk":"5354199654","pt":1646222432674,"mc":[{"id":"1.195503871","rc":[{"atl":[[820,0],[440,2]],"id":41419606},{"atb":[[25,9.33]],"id":41419660},{"atl":[[44,8.64]],"id":41419660},{"atl":[[130,10.15]],"id":41419627},{"atl":[[260,5.07],[880,2]],"id":41435525},{"atb":[[42,17.08]],"id":41419637}],"con":true,"img":false}]}
{"op":"mcm","clk":"5354199667","pt":1646222432777,"mc":[{"id":"1.195503871","rc":[{"atl":[[34,9.9],[28,4.95]],"id":28546943},{"atl":[[840,0]],"id":41419607},{"atl":[[870,0],[480,2]],"id":41419612},{"atl":[[75,0]],"id":41419596}],"con":true,"img":false}]}
{"op":"mcm","clk":"5354199680","pt":1646222432881,"mc":[{"id":"1.195503871","rc":[{"atl":[[880,0],[490,2]],"id":41435525}],"con":true,"img":false}]}
{"op":"mcm","clk":"5354199699","pt":1646222433086,"mc":[{"id":"1.195503871","rc":[{"atl":[[240,0]],"id":41419607}],"con":true,"img":false}]}
{"op":"mcm","clk":"5354199718","pt":1646222433295,"mc":[{"id":"1.195503871","rc":[{"atl":[[190,0]],"id":41419606}],"con":true,"img":false}]}
{"op":"mcm","clk":"5354199739","pt":1646222433503,"mc":[{"id":"1.195503871","rc":[{"atl":[[34,14.71]],"id":28546943},{"atb":[[25,2.72]],"id":41419660},{"atl":[[530,0],[44,4.95]],"id":41419660}],"con":true,"img":false}]}
{"op":"mcm","clk":"5354199816","pt":1646222434189,"mc":[{"id":"1.195503871","rc":[{"atb":[[20,16.56]],"id":41419660},{"atl":[[50,3.23]],"id":41419660}],"con":true,"img":false}]}
{"op":"mcm","clk":"5354199865","pt":1646222434594,"mc":[{"id":"1.195503871","rc":[{"atl":[[140,2]],"id":41419660}],"con":true,"img":false}]}
{"op":"mcm","clk":"5354199873","pt":1646222434697,"mc":[{"id":"1.195503871","rc":[{"atl":[[55,31.99]],"id":41419660}],"con":true,"img":false}]}
{"op":"mcm","clk":"5354200167","pt":1646222437567,"mc":[{"id":"1.195503871","rc":[{"atl":[[790,2],[800,0]],"id":41419611}],"con":true,"img":false}]}
{"op":"mcm","clk":"5354200373","pt":1646222439490,"mc":[{"id":"1.195503871","rc":[{"atl":[[150,10.93],[80,9.9]],"id":41419596}],"con":true,"img":false}]}
{"op":"mcm","clk":"5354200440","pt":1646222440113,"mc":[{"id":"1.195503871","rc":[{"atl":[[260,0],[490,4.73]],"id":41435525},{"atl":[[480,4.79],[250,0]],"id":41419612}],"con":true,"img":false}]}
{"op":"mcm","clk":"5354200510","pt":1646222440812,"mc":[{"id":"1.195503871","rc":[{"atb":[[19.5,0]],"id":41419621}],"con":true,"img":false}]}
{"op":"mcm","clk":"5354200518","pt":1646222440900,"mc":[{"id":"1.195503871","rc":[{"atb":[[16,6.67]],"id":41419621}],"con":true,"img":false}]}
{"op":"mcm","clk":"5354200538","pt":1646222441106,"mc":[{"id":"1.195503871","rc":[{"atb":[[20,11.06]],"id":41419651},{"atl":[[34,9.76]],"id":41419651},{"atb":[[40,9.9],[44,0],[48,4.95],[55,2.72]],"id":41419626},{"atb":[[16,0],[13.5,0]],"id":41419590},{"atb":[[85,0],[60,0]],"id":41419611},{"atb":[[85,4.61]],"id":41435525},{"atb":[[46,0],[30,13.17]],"id":41419620},{"atb":[[85,4.61]],"id":41419612},{"atb":[[50,0]],"id":41419625},{"atb":[[50,0]],"id":41419621}],"con":true,"img":false}]}
{"op":"mcm","clk":"5354200574","pt":1646222441525,"mc":[{"id":"1.195503871","rc":[{"atb":[[38,11.92]],"id":41419611}],"con":true,"img":false}]}
{"op":"mcm","clk":"5354200587","pt":1646222441579,"mc":[{"id":"1.195503871","rc":[{"atb":[[9,58.58],[11,20.8]],"id":41419590},{"atb":[[48,7.49]],"id":41419611},{"atb":[[38,9.9],[30,26.98]],"id":41419620},{"atb":[[34,9.9],[42,22.91],[44,3.27]],"id":41419625},{"atb":[[34,9.9],[36,12.18],[42,9.9]],"id":41419621}],"con":true,"img":false}]}
{"op":"mcm","clk":"5354200600","pt":1646222441699,"mc":[{"id":"1.195503871","rc":[{"atl":[[270,4.95]],"id":41419611}],"con":true,"img":false}]}
{"op":"mcm","clk":"5354200607","pt":1646222441794,"mc":[{"id":"1.195503871","rc":[{"atl":[[480,2.64]],"id":41419651},{"atb":[[13,3.27],[15.5,2.72]],"id":41419590},{"atb":[[65,3.27],[90,2.72]],"id":41419611},{"atb":[[38,14.19]],"id":41419620},{"atb":[[42,13.77]],"id":41419621}],"con":true,"img":false}]}
{"op":"mcm","clk":"5354200621","pt":1646222441894,"mc":[{"id":"1.195503871","rc":[{"atb":[[48,8.32]],"id":41419626}],"con":true,"img":false}]}
{"op":"mcm","clk":"5354200652","pt":1646222442209,"mc":[{"id":"1.195503871","rc":[{"atl":[[790,3.7],[810,0]],"id":41419611}],"con":true,"img":false}]}
{"op":"mcm","clk":"5354200666","pt":1646222442311,"mc":[{"id":"1.195503871","rc":[{"atb":[[9,16.65]],"id":41419590},{"atb":[[38,3.6]],"id":41419611},{"atl":[[270,5.54]],"id":41419611}],"con":true,"img":false}]}
{"op":"mcm","clk":"5354200715","pt":1646222442791,"mc":[{"id":"1.195503871","rc":[{"atb":[[23,0]],"id":41435526}],"con":true,"img":false}]}
{"op":"mcm","clk":"5354200735","pt":1646222443003,"mc":[{"id":"1.195503871","rc":[{"atl":[[780,0]],"id":41419611},{"atb":[[19,5.56]],"id":41435526}],"con":true,"img":false}]}
{"op":"mcm","clk":"5354200954","pt":1646222444979,"mc":[{"id":"1.195503871","rc":[{"atl":[[270,0],[790,2]],"id":41419611}],"con":true,"img":false}]}
{"op":"mcm","clk":"5354201026","pt":1646222445707,"mc":[{"id":"1.195503871","rc":[{"atl":[[780,0.2]],"id":41419611}],"con":true,"img":false}]}
{"op":"mcm","clk":"5354201040","pt":1646222445811,"mc":[{"id":"1.195503871","rc":[{"atl":[[270,4.95]],"id":41419611}],"con":true,"img":false}]}
{"op":"mcm","clk":"5354201062","pt":1646222446019,"mc":[{"id":"1.195503871","rc":[{"atl":[[790,0],[410,2]],"id":41419611}],"con":true,"img":false}]}
{"op":"mcm","clk":"5354201194","pt":1646222447182,"mc":[{"id":"1.195503871","rc":[{"atl":[[28,10.82]],"id":28546943}],"con":true,"img":false}]}
{"op":"mcm","clk":"5354201225","pt":1646222447493,"mc":[{"id":"1.195503871","rc":[{"atl":[[240,5.67]],"id":41419607}],"con":true,"img":false}]}
{"op":"mcm","clk":"5354201236","pt":1646222447597,"mc":[{"id":"1.195503871","rc":[{"atl":[[190,7.17]],"id":41419606},{"atl":[[480,2]],"id":41419612}],"con":true,"img":false}]}
{"op":"mcm","clk":"5354201245","pt":1646222447702,"mc":[{"id":"1.195503871","rc":[{"atb":[[25,9.33]],"id":41419660},{"atl":[[44,8.64]],"id":41419660},{"atl":[[260,5.24],[490,2]],"id":41435525},{"atl":[[250,5.45]],"id":41419612}],"con":true,"img":false}]}
{"op":"mcm","clk":"5354201271","pt":1646222447906,"mc":[{"id":"1.195503871","rc":[{"atl":[[34,9.9],[28,4.95]],"id":28546943}],"con":true,"img":false}]}
{"op":"mcm","clk":"5354201342","pt":1646222448484,"mc":[{"id":"1.195503871","rc":[{"atl":[[70,0],[75,4.95],[90,0],[95,9.9]],"id":41435528},{"atb":[[20,8.22]],"id":41419660},{"atl":[[50,0]],"id":41419660},{"atl":[[260,0]],"id":41435525}],"con":true,"img":false}]}
{"op":"mcm","clk":"5354201351","pt":1646222448584,"mc":[{"id":"1.195503871","rc":[{"atl":[[34,14.71]],"id":28546943}],"con":true,"img":false}]}
{"op":"mcm","clk":"5354201405","pt":1646222449001,"mc":[{"id":"1.195503871","rc":[{"atl":[[140,11.76],[55,9.9]],"id":41419660}],"con":true,"img":false}]}
{"op":"mcm","clk":"5354201435","pt":1646222449311,"mc":[{"id":"1.195503871","rc":[{"atl":[[230,0.69]],"id":41435528}],"con":true,"img":false}]}
{"op":"mcm","clk":"5354201498","pt":1646222449785,"mc":[{"id":"1.195503871","rc":[{"atl":[[230,6.64],[240,2]],"id":41435528}],"con":true,"img":false}]}
{"op":"mcm","clk":"5354201524","pt":1646222449996,"mc":[{"id":"1.195503871","rc":[{"atl":[[110,1.45],[120,4.95]],"id":41435527},{"atl":[[630,0]],"id":41435528}],"con":true,"img":false}]}
{"op":"mcm","clk":"5354201548","pt":1646222450199,"mc":[{"id":"1.195503871","rc":[{"atl":[[770,0],[400,2]],"id":41435527}],"con":true,"img":false}]}
{"op":"mcm","clk":"5354201590","pt":1646222450508,"mc":[{"id":"1.195503871","rc":[{"atl":[[770,1.77],[800,0]],"id":41435527}],"con":true,"img":false}]}
{"op":"mcm","clk":"5354201672","pt":1646222451082,"mc":[{"id":"1.195503871","rc":[{"atl":[[410,0]],"id":41419611}],"con":true,"img":false}]}
{"op":"mcm","clk":"5354201680","pt":1646222451187,"mc":[{"id":"1.195503871","rc":[{"atl":[[780,2.2]],"id":41419611}],"con":true,"img":false}]}
{"op":"mcm","clk":"5354201866","pt":1646222452900,"mc":[{"id":"1.195503871","rc":[{"atl":[[75,0],[80,4.95],[95,0],[100,9.9]],"id":41435528}],"con":true,"img":false}]}
{"op":"mcm","clk":"5354202060","pt":1646222454783,"mc":[{"id":"1.195503871","rc":[{"atl":[[460,5],[240,0]],"id":41419607}],"con":true,"img":false}]}
{"op":"mcm","clk":"5354202068","pt":1646222454886,"mc":[{"id":"1.195503871","rc":[{"atl":[[190,0],[440,5.13]],"id":41419606}],"con":true,"img":false}]}
{"op":"mcm","clk":"5354202078","pt":1646222454993,"mc":[{"id":"1.195503871","rc":[{"atl":[[260,5.31]],"id":41435525},{"atl":[[480,4.87],[250,0]],"id":41419612}],"con":true,"img":false}]}
{"op":"mcm","clk":"5354202147","pt":1646222455615,"mc":[{"id":"1.195503871","rc":[{"atl":[[440,2]],"id":41419606}],"con":true,"img":false}]}
{"op":"mcm","clk":"5354202221","pt":1646222456399,"mc":[{"id":"1.195503871","rc":[{"atb":[[48,17.21]],"id":41419611}],"con":true,"img":false}]}
{"op":"mcm","clk":"5354202230","pt":1646222456506,"mc":[{"id":"1.195503871","rc":[{"atb":[[11,52.71]],"id":41419590}],"con":true,"img":false}]}
{"op":"mcm","clk":"5354202252","pt":1646222456711,"mc":[{"id":"1.195503871","rc":[{"atb":[[40,6.79]],"id":41419620},{"atb":[[46,6.24]],"id":41419621}],"con":true,"img":false}]}
{"op":"mcm","clk":"5354202295","pt":1646222457125,"mc":[{"id":"1.195503871","rc":[{"atl":[[290,4.79]],"id":41419611}],"con":true,"img":false}]}
{"op":"mcm","clk":"5354202309","pt":1646222457229,"mc":[{"id":"1.195503871","rc":[{"atl":[[260,0.61]],"id":41419611}],"con":true,"img":false}]}
{"op":"mcm","clk":"5354202335","pt":1646222457390,"mc":[{"id":"1.195503871","rc":[{"atb":[[38,9.9]],"id":41419620},{"atb":[[42,9.9]],"id":41419621}],"con":true,"img":false}]}
{"op":"mcm","clk":"5354202378","pt":1646222457805,"mc":[{"id":"1.195503871","rc":[{"atl":[[780,0.2],[410,2]],"id":41419611}],"con":true,"img":false}]}
{"op":"mcm","clk":"5354202387","pt":1646222457910,"mc":[{"id":"1.195503871","rc":[{"atl":[[780,0]],"id":41419611}],"con":true,"img":false}]}
{"op":"mcm","clk":"5354202537","pt":1646222459209,"mc":[{"id":"1.195503871","rc":[{"atl":[[260,0]],"id":41419611}],"con":true,"img":false}]}
{"op":"mcm","clk":"5354202614","pt":1646222459892,"mc":[{"id":"1.195503871","rc":[{"atl":[[260,0.61]],"id":41419611}],"con":true,"img":false}]}
{"op":"mcm","clk":"5354202720","pt":1646222460832,"mc":[{"id":"1.195503871","rc":[{"atb":[[18.5,9.9],[20,8.34],[21,4.95]],"id":41419634},{"atb":[[150,1.06],[160,4.95],[110,0],[120,9.9]],"id":41419593},{"atb":[[24,20.46],[25,9.9],[28,5.86],[29,4.95]],"id":41419655},{"atb":[[16.5,0],[17,9.9],[18.5,12.21],[19,4.95]],"id":41419589},{"atb":[[40,17.98],[42,9.9],[48,0],[50,10.91]],"id":41435527},{"atl":[[150,4.95],[200,0.79]],"id":41419630},{"atl":[[40,4.95],[44,3.68],[48,9.9],[55,0]],"id":41419597},{"atb":[[16,0],[17,9.9],[18,12.21],[19,4.95]],"id":41419659},{"atl":[[140,9.9],[100,4.95],[120,1.32]],"id":41419626},{"atb":[[36,0],[38,4.95],[29,0],[30,27.89]],"id":41419639},{"atl":[[140,4.95],[170,0.93]],"id":41419606},{"atl":[[22,4.95],[23,7.2],[26,9.9],[27,0]],"id":41419585},{"atb":[[19.5,9.9],[23,4.95]],"id":41419656},{"atl":[[22,4.95],[25,6.6],[26,9.9],[29,0]],"id":41419590},{"atb":[[25,19.57],[26,9.9],[29,3.27],[30,4.95]],"id":41435528},{"atb":[[70,9.85],[75,9.9],[90,0],[95,6.63]],"id":41419586},{"atb":[[16,19.57],[16.5,9.9],[18,3.27],[18.5,4.95]],"id":41419598},{"atb":[[18,19.57],[18.5,9.9],[20,3.27],[21,4.95]],"id":41419660},{"atl":[[65,0],[40,4.95]],"id":41419627},{"atb":[[32,4.95],[26,0],[27,9.9],[30,8.91]],"id":41419594},{"atb":[[20,0],[21,9.9],[24,12.21],[25,4.95]],"id":41419640},{"atl":[[190,4.95],[220,0.72]],"id":41419607},{"atb":[[18.5,0],[19,9.9],[21,7.93],[22,4.95]],"id":28546950},{"atb":[[40,0],[42,9.9],[48,12.26],[50,4.95]],"id":41419611},{"atl":[[32,0],[26,4.95],[27,6.09],[30,9.9]],"id":41419591},{"atb":[[70,0],[75,4.95],[50,0],[55,9.9]],"id":41435525},{"atl":[[85,4.95],[100,1.6],[110,9.9]],"id":41419620},{"atb":[[32,8.91],[34,4.95],[27,0],[28,9.9]],"id":41419632},{"atl":[[65,2.47],[70,9.9],[85,0],[50,4.95]],"id":41419628},{"atb":[[65,0],[70,4.95],[48,0],[50,9.9]],"id":41419612},{"atl":[[130,4.95],[150,1.06]],"id":41419625},{"atl":[[70,2.29],[80,9.9],[90,0],[60,4.95]],"id":41419654},{"atl":[[110,4.95],[120,1.32]],"id":41435526},{"atl":[[130,9.9],[95,4.95],[110,1.45]],"id":41419621},{"atl":[[65,2.47],[75,9.9],[85,0],[55,4.95]],"id":41419633},{"atb":[[20,0],[21,9.9],[24,12.21],[25,4.95]],"id":41419596}],"con":true,"img":false}]}
{"op":"mcm","clk":"5354202739","pt":1646222460994,"mc":[{"id":"1.195503871","rc":[{"atl":[[810,0],[420,2]],"id":41419630},{"atl":[[370,2],[800,0]],"id":41419626},{"atb":[[19,0],[22,10.27]],"id":41419656},{"atl":[[340,2],[760,0]],"id":41419620},{"atl":[[340,2],[770,0]],"id":41419625},{"atl":[[830,0],[400,2]],"id":41435526},{"atl":[[360,2],[780,0]],"id":41419621}],"con":true,"img":false}]}
{"op":"mcm","clk":"5354202774","pt":1646222461308,"mc":[{"id":"1.195503871","rc":[{"atb":[[17,3.27],[19.5,26.84],[21,12.88]],"id":41419634},{"atb":[[160,5.95],[95,0],[120,18.84]],"id":41419593},{"atb":[[24,0],[27,22.8],[30,5.46]],"id":41419655},{"atb":[[18.5,0],[19,19.66]],"id":41419589},{"atl":[[150,6.01],[810,1.72],[840,0]],"id":41419630},{"atl":[[65,2],[40,9.02],[48,22.74]],"id":41419597},{"atb":[[18,0],[19,24.04]],"id":41419659},{"atl":[[140,19.92],[830,0]],"id":41419626},{"atl":[[140,6.09]],"id":41419606},{"atl":[[70,2],[21,7.93],[26,39.36]],"id":41419585},{"atb":[[18.5,3.27],[19.5,39.36],[24,6.89]],"id":41419656},{"atl":[[22,12.5],[50,2.04],[26,27.09]],"id":41419590},{"atb":[[25,0],[29,17.98]],"id":41435528},{"atb":[[16,0],[18,17.98]],"id":41419598},{"atb":[[18,0],[20,29.98]],"id":41419660},{"atb":[[32,13.87],[30,0]],"id":41419594},{"atb":[[24,0],[25,24.69]],"id":41419640},{"atl":[[190,5.79]],"id":41419607},{"atb":[[17.5,2.72],[19,38.04],[23,7.2]],"id":28546950},{"atl":[[70,2],[25,6.6],[30,33.7]],"id":41419591},{"atl":[[80,2.08],[790,0],[110,22.66]],"id":41419620},{"atb":[[32,0],[34,13.87]],"id":41419632},{"atl":[[70,22.12],[160,2],[50,8.19]],"id":41419628},{"atl":[[130,6.18],[770,1.81],[800,0]],"id":41419625},{"atl":[[80,22.12],[170,2],[60,7.64]],"id":41419654},{"atl":[[830,1.68],[860,0],[110,6.4]],"id":41435526},{"atl":[[130,20.69],[90,1.78],[810,0]],"id":41419621},{"atl":[[75,22.12],[160,2],[55,7.89]],"id":41419633},{"atb":[[24,0],[25,23.67]],"id":41419596}],"con":true,"img":false}]}
{"op":"mcm","clk":"5354202797","pt":1646222461517,"mc":[{"id":"1.195503871","rc":[{"atl":[[75,4.95],[80,0],[95,9.9],[100,0]],"id":41435528},{"atl":[[85,4.95],[95,1.68],[110,9.9]],"id":41419594},{"atl":[[65,0],[44,4.95],[48,3.37],[55,9.9]],"id":41419640},{"atl":[[260,5.56],[270,0]],"id":41419611},{"atl":[[220,4.95],[240,0.66]],"id":41435525},{"atl":[[140,9.9],[100,4.95]],"id":41419632},{"atl":[[190,4.95]],"id":41419612}],"con":true,"img":false}]}
{"op":"mcm","clk":"5354202808","pt":1646222461622,"mc":[{"id":"1.195503871","rc":[{"atl":[[130,1.23]],"id":41419632}],"con":true,"img":false}]}
{"op":"mcm","clk":"5354202816","pt":1646222461736,"mc":[{"id":"1.195503871","rc":[{"atl":[[320,2],[680,0]],"id":41419594},{"atl":[[320,2],[710,0]],"id":41419632}],"con":true,"img":false}]}
{"op":"mcm","clk":"5354202838","pt":1646222461887,"mc":[{"id":"1.195503871","rc":[{"atl":[[28,10.82]],"id":28546943},{"atl":[[710,0],[110,22.12]],"id":41419594},{"atl":[[190,5.79]],"id":41419612}],"con":true,"img":false}]}
{"op":"mcm","clk":"5354202852","pt":1646222462040,"mc":[{"id":"1.195503871","rc":[{"atb":[[20,0]],"id":41419634},{"atb":[[150,0]],"id":41419593},{"atb":[[28,0]],"id":41419655},{"atl":[[200,0]],"id":41419630},{"atl":[[44,0]],"id":41419597},{"atb":[[22,2.72]],"id":41419656},{"atl":[[25,0]],"id":41419590},{"atl":[[140,2],[55,22.27]],"id":41419640},{"atl":[[220,0]],"id":41419607},{"atl":[[27,0]],"id":41419591},{"atl":[[220,5.67]],"id":41435525},{"atl":[[100,0]],"id":41419620},{"atl":[[140,19.94],[740,0],[100,6.55]],"id":41419632},{"atl":[[65,0]],"id":41419628},{"atl":[[150,0]],"id":41419625},{"atl":[[70,0]],"id":41419654},{"atl":[[110,0]],"id":41419621},{"atl":[[65,0]],"id":41419633}],"con":true,"img":false}]}
{"op":"mcm","clk":"5354202861","pt":1646222462094,"mc":[{"id":"1.195503871","rc":[{"atl":[[170,0]],"id":41419606},{"atl":[[23,0]],"id":41419585},{"atb":[[21,0]],"id":28546950},{"atl":[[120,0]],"id":41435526}],"con":true,"img":false}]}
{"op":"mcm","clk":"5354202889","pt":1646222462410,"mc":[{"id":"1.195503871","rc":[{"atl":[[440,5.18]],"id":41419606}],"con":true,"img":false}]}
{"op":"mcm","clk":"5354202896","pt":1646222462515,"mc":[{"id":"1.195503871","rc":[{"atl":[[210,6.69],[460,2]],"id":41419607}],"con":true,"img":false}]}
{"op":"mcm","clk":"5354202913","pt":1646222462618,"mc":[{"id":"1.195503871","rc":[{"atl":[[34,9.9],[28,4.95]],"id":28546943},{"atl":[[230,4.95]],"id":41419612}],"con":true,"img":false}]}
{"op":"mcm","clk":"5354202922","pt":1646222462722,"mc":[{"id":"1.195503871","rc":[{"atl":[[240,0]],"id":41435525}],"con":true,"img":false}]}
{"op":"mcm","clk":"5354202930","pt":1646222462827,"mc":[{"id":"1.195503871","rc":[{"atl":[[130,0]],"id":41419632}],"con":true,"img":false}]}
{"op":"mcm","clk":"5354202970","pt":1646222463192,"mc":[{"id":"1.195503871","rc":[{"atl":[[260,0],[490,4.86]],"id":41435525}],"con":true,"img":false}]}
{"op":"mcm","clk":"5354202993","pt":1646222463400,"mc":[{"id":"1.195503871","rc":[{"atl":[[34,14.71]],"id":28546943}],"con":true,"img":false}]}
{"op":"mcm","clk":"5354203052","pt":1646222463920,"mc":[{"id":"1.195503871","rc":[{"atl":[[23,4.95],[27,9.9]],"id":41419590},{"atl":[[490,2]],"id":41435525},{"atl":[[100,4.95],[110,4.95]],"id":41419632},{"atl":[[130,0]],"id":41419625}],"con":true,"img":false}]}
{"op":"mcm","clk":"5354203065","pt":1646222464024,"mc":[{"id":"1.195503871","rc":[{"atl":[[110,6.4],[120,0]],"id":41435527},{"atl":[[22,0],[26,17.18]],"id":41419590},{"atl":[[140,10.03],[100,0]],"id":41419632},{"atl":[[140,4.95]],"id":41419625}],"con":true,"img":false}]}
{"op":"mcm","clk":"5354203084","pt":1646222464233,"mc":[{"id":"1.195503871","rc":[{"atl":[[290,0],[410,5.43]],"id":41419611}],"con":true,"img":false}]}
{"op":"mcm","clk":"5354203124","pt":1646222464600,"mc":[{"id":"1.195503871","rc":[{"atl":[[110,6.4]],"id":41419632}],"con":true,"img":false}]}
{"op":"mcm","clk":"5354203134","pt":1646222464704,"mc":[{"id":"1.195503871","rc":[{"atl":[[330,0.47]],"id":41419625}],"con":true,"img":false}]}
{"op":"mcm","clk":"5354203147","pt":1646222464808,"mc":[{"id":"1.195503871","rc":[{"atl":[[25,6.6]],"id":41419590}],"con":true,"img":false}]}
{"op":"mcm","clk":"5354203344","pt":1646222466307,"mc":[{"id":"1.195503871","rc":[{"atl":[[70,12.21],[75,9.9],[50,0],[55,4.95]],"id":41419628},{"atl":[[190,0],[200,4.95],[230,0]],"id":41419612}],"con":true,"img":false}]}
{"op":"mcm","clk":"5354203362","pt":1646222466515,"mc":[{"id":"1.195503871","rc":[{"atl":[[150,0],[160,4.95]],"id":41419630}],"con":true,"img":false}]}
{"op":"mcm","clk":"5354203390","pt":1646222466825,"mc":[{"id":"1.195503871","rc":[{"atl":[[70,9.9],[75,0],[50,4.95],[55,2.93]],"id":41419659},{"atl":[[220,6.44],[480,2]],"id":41419612}],"con":true,"img":false}]}
{"op":"mcm","clk":"5354203418","pt":1646222467135,"mc":[{"id":"1.195503871","rc":[{"atl":[[65,2.47]],"id":41419628},{"atl":[[1000,0.15]],"id":41419612}],"con":true,"img":false}]}
{"op":"mcm","clk":"5354203434","pt":1646222467304,"mc":[{"id":"1.195503871","rc":[{"atl":[[410,0.38]],"id":41419630},{"atl":[[70,22.12],[50,8.19],[110,2]],"id":41419659}],"con":true,"img":false}]}
{"op":"mcm","clk":"5354203531","pt":1646222468122,"mc":[{"id":"1.195503871","rc":[{"atl":[[55,0]],"id":41419659}],"con":true,"img":false}]}
{"op":"mcm","clk":"5354203559","pt":1646222468436,"mc":[{"id":"1.195503871","rc":[{"atb":[[90,12.57],[120,9.9]],"id":41419593},{"atl":[[65,20.26],[48,9.9]],"id":41419597},{"atl":[[80,9.9],[170,10.36]],"id":41419654}],"con":true,"img":false}]}
{"op":"mcm","clk":"5354203566","pt":1646222468549,"mc":[{"id":"1.195503871","rc":[{"atb":[[18.5,39.36],[19.5,2.72]],"id":41419634},{"atl":[[75,9.9],[160,10.88]],"id":41419633}],"con":true,"img":false}]}
{"op":"mcm","clk":"5354203648","pt":1646222469122,"mc":[{"id":"1.195503871","rc":[{"atl":[[140,0],[320,6.44]],"id":41419632}],"con":true,"img":false}]}
{"op":"mcm","clk":"5354203703","pt":1646222469636,"mc":[{"id":"1.195503871","rc":[{"atl":[[140,0],[150,4.95],[160,8.91],[440,2]],"id":41419606},{"atl":[[210,0],[460,5.09]],"id":41419607},{"atl":[[260,4.95],[270,4.95],[410,2]],"id":41419611},{"atl":[[240,5.94]],"id":41435525}],"con":true,"img":false}]}
{"op":"mcm","clk":"5354203736","pt":1646222469898,"mc":[{"id":"1.195503871","rc":[{"atl":[[260,0]],"id":41419611},{"atl":[[320,2]],"id":41419632}],"con":true,"img":false}]}
{"op":"mcm","clk":"5354203786","pt":1646222470420,"mc":[{"id":"1.195503871","rc":[{"atl":[[150,6.01],[160,0]],"id":41419606}],"con":true,"img":false}]}
{"op":"mcm","clk":"5354203795","pt":1646222470537,"mc":[{"id":"1.195503871","rc":[{"atl":[[270,5.54]],"id":41419611}],"con":true,"img":false}]}
{"op":"mcm","clk":"5354203840","pt":1646222470998,"mc":[{"id":"1.195503871","rc":[{"atb":[[48,2.53],[50,14.67]],"id":41419611}],"con":true,"img":false}]}
{"op":"mcm","clk":"5354203909","pt":1646222471730,"mc":[{"id":"1.195503871","rc":[{"atl":[[290,4.93]],"id":41419611}],"con":true,"img":false}]}
{"op":"mcm","clk":"5354204112","pt":1646222473821,"mc":[{"id":"1.195503871","rc":[{"atl":[[220,0],[480,4.98]],"id":41419612}],"con":true,"img":false}]}
{"op":"mcm","clk":"5354204183","pt":1646222474435,"mc":[{"id":"1.195503871","rc":[{"atl":[[70,9.9],[110,15.09]],"id":41419659}],"con":true,"img":false}]}
{"op":"mcm","clk":"5354204331","pt":1646222475843,"mc":[{"id":"1.195503871","rc":[{"atl":[[160,5.95],[810,0],[420,5.42]],"id":41419630},{"atb":[[19.5,9.9],[22,26.07]],"id":41419656},{"atl":[[23,12.15]],"id":41419590},{"atl":[[55,7.89]],"id":41419628},{"atl":[[140,6.09],[340,6.24],[770,0]],"id":41419625}],"con":true,"img":false}]}
{"op":"mcm","clk":"5354204392","pt":1646222476318,"mc":[{"id":"1.195503871","rc":[{"atb":[[46,0],[60,0]],"id":41419607}],"con":true,"img":false}]}
{"op":"mcm","clk":"5354204401","pt":1646222476410,"mc":[{"id":"1.195503871","rc":[{"atl":[[28,10.82]],"id":28546943},{"atb":[[65,4.95],[48,9.9]],"id":41419607},{"atb":[[75,2.14],[80,4.95],[55,2.72],[60,9.9]],"id":41419637},{"atl":[[200,5.74]],"id":41419612}],"con":true,"img":false}]}
{"op":"mcm","clk":"5354204413","pt":1646222476529,"mc":[{"id":"1.195503871","rc":[{"atl":[[410,0]],"id":41419630},{"atl":[[25,0]],"id":41419590},{"atl":[[130,9.72]],"id":41419632},{"atl":[[65,0]],"id":41419628},{"atl":[[900,2],[480,2.98]],"id":41419612}],"con":true,"img":false}]}
{"op":"mcm","clk":"5354204424","pt":1646222476629,"mc":[{"id":"1.195503871","rc":[{"atl":[[85,0],[90,4.95],[110,12.21],[120,9.9]],"id":41419594},{"atl":[[190,4.95]],"id":41419607},{"atl":[[330,0]],"id":41419625},{"atl":[[90,0]],"id":41419621}],"con":true,"img":false}]}
{"op":"mcm","clk":"5354204434","pt":1646222476738,"mc":[{"id":"1.195503871","rc":[{"atb":[[55,3.27],[27,20.34]],"id":41419607},{"atl":[[240,0],[490,4.94]],"id":41435525}],"con":true,"img":false}]}
{"op":"mcm","clk":"5354204447","pt":1646222476843,"mc":[{"id":"1.195503871","rc":[{"atb":[[80,6.95],[42,3.27],[60,20.44]],"id":41419637}],"con":true,"img":false}]}
{"op":"mcm","clk":"5354204462","pt":1646222476936,"mc":[{"id":"1.195503871","rc":[{"atl":[[170,8.5]],"id":41419606},{"atl":[[26,0],[27,42.71]],"id":41419590},{"atl":[[70,0],[75,29.2]],"id":41419628}],"con":true,"img":false}]}
{"op":"mcm","clk":"5354204482","pt":1646222477047,"mc":[{"id":"1.195503871","rc":[{"atb":[[30,0]],"id":41419655},{"atl":[[210,6.88],[460,2]],"id":41419607},{"atl":[[130,10.79],[360,6.01],[95,0]],"id":41419621}],"con":true,"img":false}]}
{"op":"mcm","clk":"5354204494","pt":1646222477153,"mc":[{"id":"1.195503871","rc":[{"atl":[[34,9.9],[28,4.95]],"id":28546943},{"atl":[[90,6.73]],"id":41419594},{"atl":[[190,0],[200,4.95]],"id":41419607},{"atl":[[1000,0]],"id":41419612},{"atl":[[130,0],[140,9.9],[100,4.95]],"id":41419621}],"con":true,"img":false}]}
{"op":"mcm","clk":"5354204520","pt":1646222477304,"mc":[{"id":"1.195503871","rc":[{"atl":[[95,1.68]],"id":41419621}],"con":true,"img":false}]}
{"op":"mcm","clk":"5354204547","pt":1646222477512,"mc":[{"id":"1.195503871","rc":[{"atb":[[25,36.23],[27,2.72]],"id":41419655},{"atb":[[75,0]],"id":41419637}],"con":true,"img":false}]}
{"op":"mcm","clk":"5354204568","pt":1646222477722,"mc":[{"id":"1.195503871","rc":[{"atb":[[27,8.82]],"id":41419655},{"atl":[[200,5.74]],"id":41419607},{"atl":[[490,2],[240,6.03]],"id":41435525}],"con":true,"img":false}]}
{"op":"mcm","clk":"5354204580","pt":1646222477836,"mc":[{"id":"1.195503871","rc":[{"atl":[[34,14.71]],"id":28546943},{"atl":[[95,0]],"id":41419594}],"con":true,"img":false}]}
{"op":"mcm","clk":"5354204638","pt":1646222478388,"mc":[{"id":"1.195503871","rc":[{"atb":[[18,0],[21,5]],"id":41435527},{"atl":[[1000,0]],"id":41419610},{"atl":[[110,0]],"id":41419594},{"atb":[[32,3.23],[25,0]],"id":41419607}],"con":true,"img":false}]}
{"op":"mcm","clk":"5354204651","pt":1646222478402,"mc":[{"id":"1.195503871","rc":[{"atl":[[120,21.99]],"id":41419594},{"atl":[[240,0]],"id":41435525}],"con":true,"img":false}]}
{"op":"mcm","clk":"5354204666","pt":1646222478566,"mc":[{"id":"1.195503871","rc":[{"atl":[[770,3.77],[400,0]],"id":41435527}],"con":true,"img":false}]}
{"op":"mcm","clk":"5354204671","pt":1646222478616,"mc":[{"id":"1.195503871","rc":[{"atl":[[1000,0]],"id":41419605},{"atl":[[65,4.95],[80,0],[85,9.9],[60,2.68]],"id":41419655},{"atb":[[20,2.72]],"id":41419651},{"atb":[[40,0],[42,25.39],[48,3.37],[50,4.95],[55,5.66]],"id":41419626},{"atl":[[100,6.55]],"id":41419626},{"atl":[[85,1.88],[90,4.95],[110,0],[120,9.9]],"id":41419639},{"atb":[[90,9.9],[120,9]],"id":41419610},{"atl":[[46,4.95],[60,9.9]],"id":41419656},{"atb":[[16.5,0],[17.5,4.95],[18.5,0]],"id":41419598},{"atl":[[32,10.06]],"id":41419598},{"atb":[[80,4.73]],"id":41419607},{"atb":[[32,9.9],[40,11.74]],"id":41419620},{"atl":[[90,4.95],[120,9.9]],"id":41419620},{"atl":[[1000,0.02]],"id":41419599},{"atl":[[150,1.06],[170,4.95]],"id":41419637},{"atb":[[34,0],[36,9.9],[42,13],[44,8.22]],"id":41419625},{"atb":[[15,2.72]],"id":41419592},{"atl":[[23,4.95],[27,9.9]],"id":41419592},{"atb":[[34,0],[38,9.9],[42,0],[46,11.2]],"id":41419621},{"atl":[[1000,0]],"id":41419600}],"con":true,"img":false}]}
{"op":"mcm","clk":"5354204679","pt":1646222478716,"mc":[{"id":"1.195503871","rc":[{"atl":[[160,0],[170,4.95]],"id":41419630},{"atb":[[70,5.02]],"id":41419606},{"atl":[[150,0],[160,4.95]],"id":41419606},{"atb":[[22,21.65],[23,9.9],[26,6.34],[27,4.95]],"id":41419635},{"atl":[[75,0],[80,9.9],[55,2.93],[60,4.95]],"id":41419635},{"atb":[[85,3.27],[110,0]],"id":41419610},{"atl":[[42,3.86],[50,0]],"id":41419656},{"atl":[[23,0],[24,4.95],[27,32.8],[28,9.9]],"id":41419590},{"atl":[[40,0],[42,4.95],[48,3.37],[50,9.9]],"id":41419627},{"atl":[[270,0],[290,4.95],[410,5.53]],"id":41419611},{"atl":[[220,0],[230,4.95]],"id":41435525},{"atb":[[38,0],[30,17.08]],"id":41419620},{"atl":[[85,0],[110,12.75]],"id":41419620},{"atl":[[520,2],[870,0]],"id":41419637},{"atl":[[200,0],[210,4.95]],"id":41419612},{"atl":[[140,4.95]],"id":41419625},{"atl":[[25,6.6],[29,0]],"id":41419592},{"atl":[[110,1.45],[120,4.95]],"id":41435526},{"atl":[[75,9.9],[80,0],[55,4.95],[60,2.68]],"id":41419596}],"con":true,"img":false}]}
{"op":"mcm","clk":"5354204713","pt":1646222479042,"mc":[{"id":"1.195503871","rc":[{"atl":[[85,27],[220,2]],"id":41419655},{"atl":[[130,11.17],[770,2],[110,1.45],[120,4.95]],"id":41435527},{"atb":[[42,13.17],[48,19.14]],"id":41419626},{"atl":[[330,2],[120,22.01]],"id":41419639},{"atl":[[140,2],[50,23.35]],"id":41419656},{"atb":[[17.5,34.65],[18,3.27]],"id":41419598},{"atb":[[32,31.99],[30,3.27]],"id":41419620},{"atl":[[110,0]],"id":41419620},{"atl":[[110,0],[120,4.95]],"id":41419632},{"atl":[[870,1.66],[900,0]],"id":41419637},{"atl":[[70,2],[27,31.99]],"id":41419592}],"con":true,"img":false}]}
{"op":"mcm","clk":"5354204726","pt":1646222479133,"mc":[{"id":"1.195503871","rc":[{"atb":[[22,0],[24,17.44]],"id":41419635},{"atl":[[80,24.62],[200,2]],"id":41419635},{"atb":[[90,26.06],[100,1.34]],"id":41419610},{"atl":[[42,8.82],[50,22.27]],"id":41419627},{"atl":[[410,3.53],[440,2]],"id":41419611},{"atl":[[400,5.62],[830,0]],"id":41435526},{"atl":[[75,22.12],[55,7.89]],"id":41419596}],"con":true,"img":false}]}
{"op":"mcm","clk":"5354204739","pt":1646222479237,"mc":[{"id":"1.195503871","rc":[{"atl":[[130,0]],"id":41419627},{"atl":[[150,2]],"id":41419596}],"con":true,"img":false}]}
{"op":"mcm","clk":"5354204753","pt":1646222479351,"mc":[{"id":"1.195503871","rc":[{"atb":[[8,14.29],[10.5,0]],"id":41419634},{"atb":[[8,0],[18,14.27],[9,12.5]],"id":41419651},{"atb":[[16.5,6.45],[13.5,0]],"id":41419630},{"atb":[[16.5,6.45],[48,15.77],[13.5,0]],"id":41419626},{"atl":[[140,10.01],[100,1.6],[110,4.95],[120,0]],"id":41419626},{"atb":[[16,6.67],[13.5,0]],"id":41419639},{"atb":[[4.1,0],[5.4,22.73]],"id":41419585},{"atb":[[16.5,6.45],[13.5,0]],"id":41419610},{"atb":[[16.5,6.45],[13.5,0]],"id":41419623},{"atb":[[7.6,0],[8.8,12.82],[15.5,9.9]],"id":41419598},{"atl":[[450,0]],"id":41419598},{"atb":[[10,0],[6,20]],"id":41419640},{"atb":[[16.5,6.45],[13.5,0]],"id":41419611},{"atb":[[16.5,6.45],[13.5,0]],"id":41419637},{"atb":[[16.5,6.45],[13.5,0]],"id":41419612},{"atb":[[16,6.67],[11.5,0]],"id":41419625},{"atl":[[140,0],[150,4.95]],"id":41419625},{"atb":[[13,18.16]],"id":41419592},{"atb":[[16.5,6.44],[13.5,0]],"id":41419629}],"con":true,"img":false}]}
{"op":"mcm","clk":"5354204766","pt":1646222479442,"mc":[{"id":"1.195503871","rc":[{"atl":[[170,5.89]],"id":41419630},{"atl":[[160,5.95]],"id":41419606},{"atb":[[23,0],[26,11.29],[27,0]],"id":41419635},{"atl":[[26,6.34]],"id":41419590},{"atl":[[290,0],[410,0],[400,0.39]],"id":41419611},{"atl":[[480,0.33]],"id":41435525},{"atl":[[210,5.71]],"id":41419612}],"con":true,"img":false}]}
{"op":"mcm","clk":"5354204775","pt":1646222479560,"mc":[{"id":"1.195503871","rc":[{"atl":[[120,22.02]],"id":41419620}],"con":true,"img":false}]}
{"op":"mcm","clk":"5354204803","pt":1646222479832,"mc":[{"id":"1.195503871","rc":[{"atl":[[120,6.28]],"id":41419632}],"con":true,"img":false}]}
{"op":"mcm","clk":"5354204816","pt":1646222479910,"mc":[{"id":"1.195503871","rc":[{"atl":[[48,0]],"id":41419627},{"atl":[[150,6.01]],"id":41419625},{"atl":[[60,0]],"id":41419596}],"con":true,"img":false}]}
{"op":"mcm","clk":"5354204908","pt":1646222480738,"mc":[{"id":"1.195503871","rc":[{"atl":[[480,0]],"id":41419612}],"con":true,"img":false}]}
{"op":"mcm","clk":"5354204918","pt":1646222480846,"mc":[{"id":"1.195503871","rc":[{"atl":[[900,3.61]],"id":41419612}],"con":true,"img":false}]}
{"op":"mcm","clk":"5354205020","pt":1646222481633,"mc":[{"id":"1.195503871","rc":[{"atl":[[32,4.95],[34,4.8],[40,9.9],[42,0]],"id":41419651},{"atb":[[65,4.95],[46,0],[48,22.09],[60,0]],"id":41419606},{"atl":[[32,5.11],[38,9.9],[40,0],[30,4.95]],"id":41419598}],"con":true,"img":false}]}
{"op":"mcm","clk":"5354205049","pt":1646222481841,"mc":[{"id":"1.195503871","rc":[{"atl":[[90,2],[510,0]],"id":41419651}],"con":true,"img":false}]}
{"op":"mcm","clk":"5354205082","pt":1646222482103,"mc":[{"id":"1.195503871","rc":[{"atl":[[40,31.99],[480,0]],"id":41419651},{"atl":[[38,24.86],[100,2]],"id":41419598}],"con":true,"img":false}]}
{"op":"mcm","clk":"5354205092","pt":1646222482208,"mc":[{"id":"1.195503871","rc":[{"atl":[[280,4.95]],"id":41419611},{"atl":[[75,12.21],[80,9.9],[55,0],[60,4.95]],"id":41419596}],"con":true,"img":false}]}
{"op":"mcm","clk":"5354205170","pt":1646222482936,"mc":[{"id":"1.195503871","rc":[{"atl":[[75,14.36]],"id":41419596}],"con":true,"img":false}]}
{"op":"mcm","clk":"5354205236","pt":1646222483509,"mc":[{"id":"1.195503871","rc":[{"atl":[[130,0],[320,6.57]],"id":41419632}],"con":true,"img":false}]}
{"op":"mcm","clk":"5354205254","pt":1646222483715,"mc":[{"id":"1.195503871","rc":[{"atb":[[55,14.14]],"id":41419637}],"con":true,"img":false}]}
{"op":"mcm","clk":"5354205263","pt":1646222483822,"mc":[{"id":"1.195503871","rc":[{"atl":[[170,0],[440,5.32]],"id":41419606},{"atl":[[75,9.9],[160,11.16]],"id":41419628},{"atb":[[60,9.9]],"id":41419637}],"con":true,"img":false}]}
{"op":"mcm","clk":"5354205283","pt":1646222484026,"mc":[{"id":"1.195503871","rc":[{"atl":[[210,0],[460,5.18]],"id":41419607},{"atl":[[490,4.98]],"id":41435525}],"con":true,"img":false}]}
{"op":"mcm","clk":"5354205362","pt":1646222484805,"mc":[{"id":"1.195503871","rc":[{"atl":[[280,5.52]],"id":41419611}],"con":true,"img":false}]}
{"op":"mcm","clk":"5354205373","pt":1646222484912,"mc":[{"id":"1.195503871","rc":[{"atl":[[770,0],[420,2]],"id":41435527}],"con":true,"img":false}]}
{"op":"mcm","clk":"5354205420","pt":1646222485330,"mc":[{"id":"1.195503871","rc":[{"atl":[[320,6.58],[120,9.9]],"id":41419594}],"con":true,"img":false}]}
{"op":"mcm","clk":"5354205446","pt":1646222485640,"mc":[{"id":"1.195503871","rc":[{"atl":[[400,0]],"id":41419611}],"con":true,"img":false}]}
{"op":"mcm","clk":"5354205493","pt":1646222486064,"mc":[{"id":"1.195503871","rc":[{"atb":[[19.5,27.42],[24,2.72]],"id":41419635},{"atl":[[440,5.34]],"id":41419611},{"atb":[[32,9.9],[30,28.09]],"id":41419620},{"atl":[[75,2.14],[80,28.32]],"id":41419596}],"con":true,"img":false}]}
{"op":"mcm","clk":"5354205506","pt":1646222486114,"mc":[{"id":"1.195503871","rc":[{"atl":[[140,12.51],[50,9.9]],"id":41419627}],"con":true,"img":false}]}
{"op":"mcm","clk":"5354205711","pt":1646222488135,"mc":[{"id":"1.195503871","rc":[{"atl":[[900,2],[230,6.42]],"id":41419612}],"con":true,"img":false}]}
{"op":"mcm","clk":"5354205720","pt":1646222488241,"mc":[{"id":"1.195503871","rc":[{"atb":[[400,2.24]],"id":41419608}],"con":true,"img":false}]}
{"op":"mcm","clk":"5354205733","pt":1646222488345,"mc":[{"id":"1.195503871","rc":[{"atl":[[520,2],[900,0]],"id":41419612}],"con":true,"img":false}]}
{"op":"mcm","clk":"5354205880","pt":1646222489846,"mc":[{"id":"1.195503871","rc":[{"atl":[[440,2]],"id":41419611}],"con":true,"img":false}]}
{"op":"mcm","clk":"5354205895","pt":1646222489944,"mc":[{"id":"1.195503871","rc":[{"atl":[[190,7.8],[420,2]],"id":41419630},{"atl":[[23,7.2]],"id":41419590},{"atl":[[340,2]],"id":41419625}],"con":true,"img":false}]}
{"op":"mcm","clk":"5354205917","pt":1646222490155,"mc":[{"id":"1.195503871","rc":[{"atl":[[280,0],[290,4.95]],"id":41419611},{"atl":[[170,8.72]],"id":41419625}],"con":true,"img":false}]}
{"op":"mcm","clk":"5354205978","pt":1646222490726,"mc":[{"id":"1.195503871","rc":[{"atl":[[28,10.82]],"id":28546943},{"atl":[[26,0]],"id":41419590},{"atl":[[320,2]],"id":41419632}],"con":true,"img":false}]}
{"op":"mcm","clk":"5354205987","pt":1646222490832,"mc":[{"id":"1.195503871","rc":[{"atl":[[430,0.37]],"id":41419611},{"atl":[[140,10.61]],"id":41419632}],"con":true,"img":false}]}
{"op":"mcm","clk":"5354206002","pt":1646222490936,"mc":[{"id":"1.195503871","rc":[{"atb":[[55,17.98],[27,5.12]],"id":41419607}],"con":true,"img":false}]}
{"op":"mcm","clk":"5354206013","pt":1646222491041,"mc":[{"id":"1.195503871","rc":[{"atl":[[440,2]],"id":41419606},{"atl":[[26,16.78],[27,0]],"id":41419590}],"con":true,"img":false}]}
{"op":"mcm","clk":"5354206025","pt":1646222491146,"mc":[{"id":"1.195503871","rc":[{"atl":[[180,8.25]],"id":41419606},{"atl":[[220,6.75],[460,2]],"id":41419607},{"atl":[[140,20.53],[360,2]],"id":41419621}],"con":true,"img":false}]}
{"op":"mcm","clk":"5354206057","pt":1646222491456,"mc":[{"id":"1.195503871","rc":[{"atl":[[34,9.9],[28,4.95]],"id":28546943}],"con":true,"img":false}]}
{"op":"mcm","clk":"5354206105","pt":1646222491822,"mc":[{"id":"1.195503871","rc":[{"atb":[[29,10.61]],"id":41419655}],"con":true,"img":false}]}
{"op":"mcm","clk":"5354206139","pt":1646222492136,"mc":[{"id":"1.195503871","rc":[{"atl":[[34,14.71]],"id":28546943}],"con":true,"img":false}]}
{"op":"mcm","clk":"5354206191","pt":1646222492653,"mc":[{"id":"1.195503871","rc":[{"atb":[[27,2.72]],"id":41419655}],"con":true,"img":false}]}
{"op":"mcm","clk":"5354206214","pt":1646222492859,"mc":[{"id":"1.195503871","rc":[{"atl":[[440,5.38]],"id":41419611}],"con":true,"img":false}]}
{"op":"mcm","clk":"5354206259","pt":1646222493223,"mc":[{"id":"1.195503871","rc":[{"atl":[[520,4.86],[870,0]],"id":41419637},{"atl":[[60,7.64]],"id":41419596}],"con":true,"img":false}]}
{"op":"mcm","clk":"5354206286","pt":1646222493531,"mc":[{"id":"1.195503871","rc":[{"atl":[[290,5.5]],"id":41419611},{"atl":[[230,5.64]],"id":41435525}],"con":true,"img":false}]}
{"op":"mcm","clk":"5354206343","pt":1646222494051,"mc":[{"id":"1.195503871","rc":[{"atl":[[75,0]],"id":41419596}],"con":true,"img":false}]}
{"op":"mcm","clk":"5354206376","pt":1646222494310,"mc":[{"id":"1.195503871","rc":[{"atl":[[430,0]],"id":41419611},{"atl":[[480,0]],"id":41435525}],"con":true,"img":false}]}
{"op":"mcm","clk":"5354206401","pt":1646222494515,"mc":[{"id":"1.195503871","rc":[{"atl":[[150,11.97]],"id":41419596}],"con":true,"img":false}]}
{"op":"mcm","clk":"5354206410","pt":1646222494624,"mc":[{"id":"1.195503871","rc":[{"atl":[[80,9.9]],"id":41419596}],"con":true,"img":false}]}
{"op":"mcm","clk":"5354206422","pt":1646222494724,"mc":[{"id":"1.195503871","rc":[{"atl":[[490,2],[250,5.98]],"id":41435525}],"con":true,"img":false}]}
{"op":"mcm","clk":"5354206450","pt":1646222495035,"mc":[{"id":"1.195503871","rc":[{"atl":[[520,4.87],[230,0]],"id":41419612}],"con":true,"img":false}]}
{"op":"mcm","clk":"5354206493","pt":1646222495449,"mc":[{"id":"1.195503871","rc":[{"atl":[[250,0]],"id":41435525}],"con":true,"img":false}]}
{"op":"mcm","clk":"5354206532","pt":1646222495867,"mc":[{"id":"1.195503871","rc":[{"atl":[[520,2]],"id":41419612}],"con":true,"img":false}]}
{"op":"mcm","clk":"5354206623","pt":1646222496752,"mc":[{"id":"1.195503871","rc":[{"atl":[[190,0]],"id":41419630}],"con":true,"img":false}]}
{"op":"mcm","clk":"5354206635","pt":1646222496857,"mc":[{"id":"1.195503871","rc":[{"atl":[[420,5.56]],"id":41419630}],"con":true,"img":false}]}
{"op":"mcm","clk":"5354206657","pt":1646222497066,"mc":[{"id":"1.195503871","rc":[{"atl":[[170,0],[340,6.41]],"id":41419625}],"con":true,"img":false}]}
{"op":"mcm","clk":"5354206675","pt":1646222497270,"mc":[{"id":"1.195503871","rc":[{"atb":[[9,0],[10,11.11]],"id":41419651},{"atb":[[16,0],[19.5,5.41]],"id":41419621}],"con":true,"img":false}]}
{"op":"mcm","clk":"5354206706","pt":1646222497534,"mc":[{"id":"1.195503871","rc":[{"atl":[[1000,0.02]],"id":41419605},{"atb":[[16,0],[17.5,25.39],[18,9.32],[19.5,4.95],[20,11.06]],"id":41419651},{"atl":[[32,4.16],[38,4.95],[40,22.08],[46,9.9]],"id":41419651},{"atb":[[44,0],[46,4.95],[55,0]],"id":41419630},{"atb":[[65,0],[70,2.72],[44,9.9],[48,12.18],[55,4.95]],"id":41419606},{"atb":[[11,0],[11.5,9.9],[13,11.64],[13.5,4.95]],"id":41419585},{"atl":[[22,0],[24,4.95],[26,29.45],[28,9.9]],"id":41419585},{"atb":[[13,0],[15.5,0]],"id":41419590},{"atb":[[38,7]],"id":41435528},{"atl":[[75,7.09]],"id":41435528},{"atl":[[32,0],[34,4.95],[38,14.95],[42,9.9],[30,0]],"id":41419598},{"atl":[[65,9.9],[44,3.68],[48,4.95],[55,0]],"id":41419660},{"atb":[[22,0]],"id":41419627},{"atb":[[65,0],[90,0]],"id":41419611},{"atl":[[1000,0.02]],"id":41419657},{"atl":[[75,9.9],[80,0],[55,4.95],[60,0]],"id":41419587},{"atb":[[21,0],[23,4.95],[25,12.21]],"id":41419628},{"atb":[[400,0.67]],"id":41419608},{"atl":[[160,4.95],[170,0]],"id":41419637},{"atb":[[15,14.05]],"id":41419592},{"atl":[[23,5.47],[25,11.55],[27,22.08],[29,9.9]],"id":41419592},{"atl":[[140,10.62],[150,9.9],[100,0],[110,4.95]],"id":41419621},{"atb":[[36,0],[21,0],[22,4.95],[25,0],[28,0]],"id":41419633},{"atl":[[1000,0.02]],"id":41419600},{"atl":[[1000,1.41]],"id":41419629}],"con":true,"img":false}]}
{"op":"mcm","clk":"5354206717","pt":1646222497638,"mc":[{"id":"1.195503871","rc":[{"atl":[[140,0],[320,6.69]],"id":41419632}],"con":true,"img":false}]}
{"op":"mcm","clk":"5354206725","pt":1646222497740,"mc":[{"id":"1.195503871","rc":[{"atl":[[440,2]],"id":41419611}],"con":true,"img":false}]}
{"op":"mcm","clk":"5354206745","pt":1646222497955,"mc":[{"id":"1.195503871","rc":[{"atb":[[24,9.9],[25,26.32],[28,4.95],[29,0]],"id":41419655},{"atb":[[17.5,13.17],[18,24.04]],"id":41419651},{"atl":[[38,19.66],[40,0]],"id":41419651},{"atb":[[46,21.51],[48,3.27]],"id":41419630},{"atl":[[180,0],[440,5.41]],"id":41419606},{"atb":[[10.5,3.27],[11.5,36.42],[14,12.19]],"id":41419585},{"atb":[[9,56.13],[11,20.8]],"id":41419590},{"atl":[[23,0]],"id":41419590},{"atl":[[38,0],[42,31.99]],"id":41419598},{"atl":[[65,31.13],[140,2]],"id":41419660},{"atb":[[17,9.9],[19,37.74]],"id":41419627},{"atl":[[200,0],[210,4.95],[220,0],[460,5.27]],"id":41419607},{"atb":[[42,26.25],[50,8.19]],"id":41419611},{"atl":[[290,0.55],[300,4.95]],"id":41419611},{"atb":[[10.5,38.92],[22,12.5]],"id":41419633}],"con":true,"img":false}]}
{"op":"mcm","clk":"5354206753","pt":1646222498066,"mc":[{"id":"1.195503871","rc":[{"atl":[[290,0]],"id":41419611},{"atl":[[250,6.02]],"id":41435525}],"con":true,"img":false}]}
{"op":"mcm","clk":"5354206774","pt":1646222498268,"mc":[{"id":"1.195503871","rc":[{"atb":[[18,14.71]],"id":41419651},{"atl":[[34,0]],"id":41419651},{"atb":[[55,7.89]],"id":41419606},{"atb":[[12,3.27],[14.5,2.72]],"id":41419590},{"atl":[[230,5.95]],"id":41435528},{"atl":[[38,4.28]],"id":41419598},{"atb":[[85,2.72],[60,3.27]],"id":41419611},{"atl":[[410,2],[440,0]],"id":41419611},{"atb":[[32,2.72],[19,9.9],[26,3.27]],"id":41419633}],"con":true,"img":false}]}
{"op":"mcm","clk":"5354206786","pt":1646222498377,"mc":[{"id":"1.195503871","rc":[{"atb":[[13,4.95]],"id":41419592},{"atl":[[25,4.95]],"id":41419592}],"con":true,"img":false}]}
{"op":"mcm","clk":"5354206795","pt":1646222498421,"mc":[{"id":"1.195503871","rc":[{"atl":[[26,0]],"id":41419590}],"con":true,"img":false}]}
{"op":"mcm","clk":"5354206806","pt":1646222498520,"mc":[{"id":"1.195503871","rc":[{"atl":[[28,49.58]],"id":41419590}],"con":true,"img":false}]}
{"op":"mcm","clk":"5354206813","pt":1646222498629,"mc":[{"id":"1.195503871","rc":[{"atb":[[28,10.82]],"id":41419655},{"atl":[[440,2]],"id":41419606},{"atb":[[13,2.72]],"id":41419585},{"atl":[[25,6.6]],"id":41419590},{"atl":[[1000,0.15]],"id":41419607},{"atb":[[48,0]],"id":41419611}],"con":true,"img":false}]}
{"op":"mcm","clk":"5354206823","pt":1646222498731,"mc":[{"id":"1.195503871","rc":[{"atl":[[900,2]],"id":41419607},{"atl":[[300,5.48]],"id":41419611}],"con":true,"img":false}]}
{"op":"mcm","clk":"5354206831","pt":1646222498832,"mc":[{"id":"1.195503871","rc":[{"atl":[[460,3.27]],"id":41419607}],"con":true,"img":false}]}
{"op":"mcm","clk":"5354206896","pt":1646222499558,"mc":[{"id":"1.195503871","rc":[{"atl":[[170,0],[180,4.95]],"id":41419630},{"atl":[[210,0],[220,4.95]],"id":41419612}],"con":true,"img":false}]}
{"op":"mcm","clk":"5354206954","pt":1646222500136,"mc":[{"id":"1.195503871","rc":[{"atl":[[320,4.71]],"id":41419611}],"con":true,"img":false}]}
