{"op":"mcm","clk":"5346220769","pt":1646178839801,"mc":[{"id":"1.195453681","marketDefinition":{"bspMarket":false,"turnInPlayEnabled":false,"persistenceEnabled":false,"marketBaseRate":7.0,"eventId":"31272494","eventTypeId":"4339","numberOfWinners":1,"bettingType":"ODDS","marketType":"MATCH_BET","marketTime":"2022-03-02T12:04:00.000Z","suspendTime":"2022-03-02T12:04:00.000Z","bspReconciled":false,"complete":true,"inPlay":false,"crossMatching":true,"runnersVoidable":false,"numberOfActiveRunners":2,"betDelay":0,"status":"OPEN","runners":[{"status":"ACTIVE","sortPriority":1,"id":40917619,"name":"5. Kens Crew"},{"status":"ACTIVE","sortPriority":2,"id":38554545,"name":"6. Call Me Harvey"}],"regulators":["MR_INT"],"venue":"Traralgon","countryCode":"AU","discountAllowed":true,"timezone":"Australia/Sydney","openDate":"2022-03-02T08:31:00.000Z","version":4382489953,"name":"Kens Crew v Call Me Harvey","eventName":"Traralgon (AUS) 2nd Mar"},"rc":[],"con":true,"img":false}]}
{"op":"mcm","clk":"5346224660","pt":1646178919306,"mc":[{"id":"1.195453681","rc":[{"atb":[[1.6,8.98],[1.7,7.69],[1.5,10.77]],"id":40917619},{"atb":[[1.86,6.26],[1.66,8.16],[1.76,7.09]],"id":38554545}],"con":true,"img":false}]}
{"op":"mcm","clk":"5346401501","pt":1646182002784,"mc":[{"id":"1.195453681","marketDefinition":{"bspMarket":false,"turnInPlayEnabled":false,"persistenceEnabled":false,"marketBaseRate":7.0,"eventId":"31272494","eventTypeId":"4339","numberOfWinners":1,"bettingType":"ODDS","marketType":"MATCH_BET","marketTime":"2022-03-02T12:04:00.000Z","suspendTime":"2022-03-02T12:04:00.000Z","bspReconciled":false,"complete":true,"inPlay":false,"crossMatching":true,"runnersVoidable":false,"numberOfActiveRunners":2,"betDelay":0,"status":"OPEN","runners":[{"status":"ACTIVE","sortPriority":1,"id":40917619,"name":"5. Kens Crew"},{"status":"ACTIVE","sortPriority":2,"id":38554545,"name":"6. Call Me Harvey"}],"regulators":["MR_INT"],"venue":"Traralgon","countryCode":"AU","discountAllowed":true,"timezone":"Australia/Sydney","openDate":"2022-03-02T08:31:00.000Z","version":4382489953,"name":"Kens Crew v Call Me Harvey","eventName":"Traralgon (AUS) 2nd Mar"},"rc":[{"atb":[[1.6,8.98],[1.7,7.69],[1.5,10.77]],"id":40917619},{"atb":[[1.86,6.26],[1.66,8.16],[1.76,7.09]],"id":38554545}],"con":true,"img":true}]}
{"op":"mcm","clk":"5346767856","pt":1646187402729,"mc":[{"id":"1.195453681","marketDefinition":{"bspMarket":false,"turnInPlayEnabled":false,"persistenceEnabled":false,"marketBaseRate":7.0,"eventId":"31272494","eventTypeId":"4339","numberOfWinners":1,"bettingType":"ODDS","marketType":"MATCH_BET","marketTime":"2022-03-02T12:04:00.000Z","suspendTime":"2022-03-02T12:04:00.000Z","bspReconciled":false,"complete":true,"inPlay":false,"crossMatching":true,"runnersVoidable":false,"numberOfActiveRunners":2,"betDelay":0,"status":"OPEN","runners":[{"status":"ACTIVE","sortPriority":1,"id":40917619,"name":"5. Kens Crew"},{"status":"ACTIVE","sortPriority":2,"id":38554545,"name":"6. Call Me Harvey"}],"regulators":["MR_INT"],"venue":"Traralgon","countryCode":"AU","discountAllowed":true,"timezone":"Australia/Sydney","openDate":"2022-03-02T08:31:00.000Z","version":4382489953,"name":"Kens Crew v Call Me Harvey","eventName":"Traralgon (AUS) 2nd Mar"},"rc":[{"atb":[[1.6,8.99],[1.7,7.71],[1.5,10.79]],"id":40917619},{"atb":[[1.86,6.27],[1.66,8.17],[1.76,7.1]],"id":38554545}],"con":true,"img":true}]}
{"op":"mcm","clk":"5347092407","pt":1646192802709,"mc":[{"id":"1.195453681","marketDefinition":{"bspMarket":false,"turnInPlayEnabled":false,"persistenceEnabled":false,"marketBaseRate":7.0,"eventId":"31272494","eventTypeId":"4339","numberOfWinners":1,"bettingType":"ODDS","marketType":"MATCH_BET","marketTime":"2022-03-02T12:04:00.000Z","suspendTime":"2022-03-02T12:04:00.000Z","bspReconciled":false,"complete":true,"inPlay":false,"crossMatching":true,"runnersVoidable":false,"numberOfActiveRunners":2,"betDelay":0,"status":"OPEN","runners":[{"status":"ACTIVE","sortPriority":1,"id":40917619,"name":"5. Kens Crew"},{"status":"ACTIVE","sortPriority":2,"id":38554545,"name":"6. Call Me Harvey"}],"regulators":["MR_INT"],"venue":"Traralgon","countryCode":"AU","discountAllowed":true,"timezone":"Australia/Sydney","openDate":"2022-03-02T08:31:00.000Z","version":4382489953,"name":"Kens Crew v Call Me Harvey","eventName":"Traralgon (AUS) 2nd Mar"},"rc":[{"atb":[[1.6,9.01],[1.7,7.72],[1.5,10.81]],"id":40917619},{"atb":[[1.86,6.28],[1.66,8.19],[1.76,7.11]],"id":38554545}],"con":true,"img":true}]}
{"op":"mcm","clk":"5347381268","pt":1646198202726,"mc":[{"id":"1.195453681","marketDefinition":{"bspMarket":false,"turnInPlayEnabled":false,"persistenceEnabled":false,"marketBaseRate":7.0,"eventId":"31272494","eventTypeId":"4339","numberOfWinners":1,"bettingType":"ODDS","marketType":"MATCH_BET","marketTime":"2022-03-02T12:04:00.000Z","suspendTime":"2022-03-02T12:04:00.000Z","bspReconciled":false,"complete":true,"inPlay":false,"crossMatching":true,"runnersVoidable":false,"numberOfActiveRunners":2,"betDelay":0,"status":"OPEN","runners":[{"status":"ACTIVE","sortPriority":1,"id":40917619,"name":"5. Kens Crew"},{"status":"ACTIVE","sortPriority":2,"id":38554545,"name":"6. Call Me Harvey"}],"regulators":["MR_INT"],"venue":"Traralgon","countryCode":"AU","discountAllowed":true,"timezone":"Australia/Sydney","openDate":"2022-03-02T08:31:00.000Z","version":4382489953,"name":"Kens Crew v Call Me Harvey","eventName":"Traralgon (AUS) 2nd Mar"},"rc":[{"atb":[[1.6,9],[1.7,7.72],[1.5,10.81]],"id":40917619},{"atb":[[1.86,6.28],[1.66,8.19],[1.76,7.11]],"id":38554545}],"con":true,"img":true}]}
{"op":"mcm","clk":"5347848944","pt":1646209002730,"mc":[{"id":"1.195453681","marketDefinition":{"bspMarket":false,"turnInPlayEnabled":false,"persistenceEnabled":false,"marketBaseRate":7.0,"eventId":"31272494","eventTypeId":"4339","numberOfWinners":1,"bettingType":"ODDS","marketType":"MATCH_BET","marketTime":"2022-03-02T12:04:00.000Z","suspendTime":"2022-03-02T12:04:00.000Z","bspReconciled":false,"complete":true,"inPlay":false,"crossMatching":true,"runnersVoidable":false,"numberOfActiveRunners":2,"betDelay":0,"status":"OPEN","runners":[{"status":"ACTIVE","sortPriority":1,"id":40917619,"name":"5. Kens Crew"},{"status":"ACTIVE","sortPriority":2,"id":38554545,"name":"6. Call Me Harvey"}],"regulators":["MR_INT"],"venue":"Traralgon","countryCode":"AU","discountAllowed":true,"timezone":"Australia/Sydney","openDate":"2022-03-02T08:31:00.000Z","version":4382489953,"name":"Kens Crew v Call Me Harvey","eventName":"Traralgon (AUS) 2nd Mar"},"rc":[{"atb":[[1.6,9],[1.7,7.71],[1.5,10.8]],"id":40917619},{"atb":[[1.86,6.28],[1.66,8.18],[1.76,7.11]],"id":38554545}],"con":true,"img":true}]}
{"op":"mcm","clk":"5348133127","pt":1646214402740,"mc":[{"id":"1.195453681","marketDefinition":{"bspMarket":false,"turnInPlayEnabled":false,"persistenceEnabled":false,"marketBaseRate":7.0,"eventId":"31272494","eventTypeId":"4339","numberOfWinners":1,"bettingType":"ODDS","marketType":"MATCH_BET","marketTime":"2022-03-02T12:04:00.000Z","suspendTime":"2022-03-02T12:04:00.000Z","bspReconciled":false,"complete":true,"inPlay":false,"crossMatching":true,"runnersVoidable":false,"numberOfActiveRunners":2,"betDelay":0,"status":"OPEN","runners":[{"status":"ACTIVE","sortPriority":1,"id":40917619,"name":"5. Kens Crew"},{"status":"ACTIVE","sortPriority":2,"id":38554545,"name":"6. Call Me Harvey"}],"regulators":["MR_INT"],"venue":"Traralgon","countryCode":"AU","discountAllowed":true,"timezone":"Australia/Sydney","openDate":"2022-03-02T08:31:00.000Z","version":4382489953,"name":"Kens Crew v Call Me Harvey","eventName":"Traralgon (AUS) 2nd Mar"},"rc":[{"atb":[[1.6,8.99],[1.7,7.7],[1.5,10.79]],"id":40917619},{"atb":[[1.86,6.27],[1.66,8.17],[1.76,7.1]],"id":38554545}],"con":true,"img":true}]}
{"op":"mcm","clk":"5348677829","pt":1646219802710,"mc":[{"id":"1.195453681","marketDefinition":{"bspMarket":false,"turnInPlayEnabled":false,"persistenceEnabled":false,"marketBaseRate":7.0,"eventId":"31272494","eventTypeId":"4339","numberOfWinners":1,"bettingType":"ODDS","marketType":"MATCH_BET","marketTime":"2022-03-02T12:04:00.000Z","suspendTime":"2022-03-02T12:04:00.000Z","bspReconciled":false,"complete":true,"inPlay":false,"crossMatching":true,"runnersVoidable":false,"numberOfActiveRunners":2,"betDelay":0,"status":"OPEN","runners":[{"status":"ACTIVE","sortPriority":1,"id":40917619,"name":"5. Kens Crew"},{"status":"ACTIVE","sortPriority":2,"id":38554545,"name":"6. Call Me Harvey"}],"regulators":["MR_INT"],"venue":"Traralgon","countryCode":"AU","discountAllowed":true,"timezone":"Australia/Sydney","openDate":"2022-03-02T08:31:00.000Z","version":4382489953,"name":"Kens Crew v Call Me Harvey","eventName":"Traralgon (AUS) 2nd Mar"},"rc":[{"atb":[[1.6,8.99],[1.7,7.7],[1.5,10.79]],"id":40917619},{"atb":[[1.86,6.27],[1.66,8.17],[1.76,7.1]],"id":38554545}],"con":true,"img":true}]}
{"op":"mcm","clk":"5348906211","pt":1646221801540,"mc":[{"id":"1.195453681","rc":[{"atb":[[1.6,0],[1.7,0],[1.5,0]],"id":40917619},{"atb":[[1.86,0],[1.66,0],[1.76,0]],"id":38554545}],"con":true,"img":false}]}
{"op":"mcm","clk":"5348906554","pt":1646221805607,"mc":[{"id":"1.195453681","rc":[{"atb":[[1.6,8.99],[1.7,7.7],[1.5,10.79]],"id":40917619},{"atb":[[1.86,6.27],[1.66,8.17],[1.76,7.1]],"id":38554545}],"con":true,"img":false}]}
{"op":"mcm","clk":"5348906664","pt":1646221806923,"mc":[{"id":"1.195453681","rc":[{"atb":[[1.87,2]],"id":38554545},{"atl":[[2.56,2]],"id":38554545}],"con":true,"img":false}]}
{"op":"mcm","clk":"5348906673","pt":1646221807019,"mc":[{"id":"1.195453681","rc":[{"atb":[[1.61,2]],"id":40917619},{"atl":[[2.26,2]],"id":40917619}],"con":true,"img":false}]}
{"op":"mcm","clk":"5348907090","pt":1646221812128,"mc":[{"id":"1.195453681","rc":[{"atb":[[1.88,2],[1.87,0]],"id":38554545}],"con":true,"img":false}]}
{"op":"mcm","clk":"5348907105","pt":1646221812224,"mc":[{"id":"1.195453681","rc":[{"atl":[[2.26,0],[2.14,2]],"id":40917619}],"con":true,"img":false}]}
{"op":"mcm","clk":"5348908413","pt":1646221825633,"mc":[{"id":"1.195453681","rc":[{"atb":[[1.89,2],[1.88,0]],"id":38554545}],"con":true,"img":false}]}
{"op":"mcm","clk":"5348908920","pt":1646221830838,"mc":[{"id":"1.195453681","rc":[{"atb":[[1.89,0],[1.88,2]],"id":38554545}],"con":true,"img":false}]}
{"op":"mcm","clk":"5348908978","pt":1646221831621,"mc":[{"id":"1.195453681","rc":[{"atb":[[1.89,2],[1.88,0]],"id":38554545}],"con":true,"img":false}]}
{"op":"mcm","clk":"5348909463","pt":1646221836729,"mc":[{"id":"1.195453681","rc":[{"atb":[[1.89,0],[1.88,2]],"id":38554545}],"con":true,"img":false}]}
{"op":"mcm","clk":"5348912283","pt":1646221867850,"mc":[{"id":"1.195453681","rc":[{"atb":[[1.89,2],[1.88,0]],"id":38554545}],"con":true,"img":false}]}
{"op":"mcm","clk":"5348912762","pt":1646221873095,"mc":[{"id":"1.195453681","rc":[{"atb":[[1.89,0],[1.88,2]],"id":38554545}],"con":true,"img":false}]}
{"op":"mcm","clk":"5348913517","pt":1646221882695,"mc":[{"id":"1.195453681","rc":[{"atb":[[1.89,2],[1.88,0]],"id":38554545}],"con":true,"img":false}]}
{"op":"mcm","clk":"5348913967","pt":1646221887899,"mc":[{"id":"1.195453681","rc":[{"atb":[[1.89,0],[1.88,2]],"id":38554545}],"con":true,"img":false}]}
{"op":"mcm","clk":"5348915019","pt":1646221900102,"mc":[{"id":"1.195453681","rc":[{"atb":[[1.88,0],[1.87,2]],"id":38554545}],"con":true,"img":false}]}
{"op":"mcm","clk":"5348915687","pt":1646221907293,"mc":[{"id":"1.195453681","rc":[{"atl":[[2.56,0],[2.54,2]],"id":38554545}],"con":true,"img":false}]}
{"op":"mcm","clk":"5348924000","pt":1646222001845,"mc":[{"id":"1.195453681","rc":[{"atb":[[1.63,2],[1.61,0]],"id":40917619},{"atl":[[2.54,0],[2.52,2]],"id":38554545}],"con":true,"img":false}]}
{"op":"mcm","clk":"5348926633","pt":1646222032698,"mc":[{"id":"1.195453681","rc":[{"atb":[[1.6,0],[1.7,0],[1.5,0]],"id":40917619},{"atb":[[1.86,0],[1.66,0],[1.76,0]],"id":38554545}],"con":true,"img":false}]}
{"op":"mcm","clk":"5348928010","pt":1646222048209,"mc":[{"id":"1.195453681","rc":[{"atb":[[1.8,6.74],[1.6,8.99],[1.7,7.7]],"id":40917619},{"atb":[[1.8,6.74],[1.6,8.99],[1.7,7.7]],"id":38554545}],"con":true,"img":false}]}
{"op":"mcm","clk":"5348928026","pt":1646222048391,"mc":[{"id":"1.195453681","rc":[{"atb":[[1.81,2]],"id":38554545}],"con":true,"img":false}]}
{"op":"mcm","clk":"5348928035","pt":1646222048491,"mc":[{"id":"1.195453681","rc":[{"atb":[[1.87,0]],"id":38554545}],"con":true,"img":false}]}
{"op":"mcm","clk":"5348934364","pt":1646222137803,"mc":[{"id":"1.195453681","rc":[{"atl":[[2.5,2],[2.52,0]],"id":38554545}],"con":true,"img":false}]}
{"op":"mcm","clk":"5348936213","pt":1646222162723,"mc":[{"id":"1.195453681","rc":[{"atl":[[2.5,0]],"id":38554545}],"con":true,"img":false}]}
{"op":"mcm","clk":"5348936229","pt":1646222162932,"mc":[{"id":"1.195453681","rc":[{"atl":[[2.54,2]],"id":38554545}],"con":true,"img":false}]}
{"op":"mcm","clk":"5348936337","pt":1646222164031,"mc":[{"id":"1.195453681","rc":[{"atl":[[2.52,15.42]],"id":38554545}],"con":true,"img":false}]}
{"op":"mcm","clk":"5348936347","pt":1646222164137,"mc":[{"id":"1.195453681","rc":[{"atl":[[2.54,0]],"id":38554545}],"con":true,"img":false}]}
{"op":"mcm","clk":"5348936744","pt":1646222169238,"mc":[{"id":"1.195453681","rc":[{"atl":[[2.5,2],[2.52,0]],"id":38554545}],"con":true,"img":false}]}
{"op":"mcm","clk":"5348940859","pt":1646222222735,"mc":[{"id":"1.195453681","rc":[{"atl":[[23,1.42]],"id":40917619},{"atl":[[22,1.42]],"id":38554545}],"con":true,"img":false}]}
{"op":"mcm","clk":"5348940884","pt":1646222222879,"mc":[{"id":"1.195453681","rc":[{"atl":[[2.82,2],[2.14,0]],"id":40917619}],"con":true,"img":false}]}
{"op":"mcm","clk":"5348941075","pt":1646222224947,"mc":[{"id":"1.195453681","rc":[{"atl":[[24,1.42]],"id":40917619},{"atl":[[23,1.42]],"id":38554545}],"con":true,"img":false}]}
{"op":"mcm","clk":"5348941325","pt":1646222227997,"mc":[{"id":"1.195453681","rc":[{"atl":[[2.82,0],[2.72,2],[21,1.42]],"id":40917619},{"atl":[[20,1.42]],"id":38554545}],"con":true,"img":false}]}
{"op":"mcm","clk":"5348941494","pt":1646222230188,"mc":[{"id":"1.195453681","rc":[{"atl":[[20,1.42]],"id":40917619},{"atl":[[19.5,1.42]],"id":38554545}],"con":true,"img":false}]}
{"op":"mcm","clk":"5348941652","pt":1646222232525,"mc":[{"id":"1.195453681","rc":[{"atl":[[22,1.42]],"id":40917619},{"atl":[[21,1.42]],"id":38554545}],"con":true,"img":false}]}
{"op":"mcm","clk":"5348941722","pt":1646222233612,"mc":[{"id":"1.195453681","rc":[{"atl":[[19.5,1.42]],"id":40917619},{"atl":[[19,1.42]],"id":38554545}],"con":true,"img":false}]}
{"op":"mcm","clk":"5348941738","pt":1646222233929,"mc":[{"id":"1.195453681","rc":[{"atl":[[2.72,0],[2.66,2]],"id":40917619}],"con":true,"img":false}]}
{"op":"mcm","clk":"5348941868","pt":1646222235740,"mc":[{"id":"1.195453681","rc":[{"atl":[[19.5,2.84]],"id":40917619},{"atl":[[19,2.84]],"id":38554545}],"con":true,"img":false}]}
{"op":"mcm","clk":"5348941997","pt":1646222237391,"mc":[{"id":"1.195453681","rc":[{"atl":[[25,1.42]],"id":40917619},{"atl":[[24,1.42]],"id":38554545}],"con":true,"img":false}]}
{"op":"mcm","clk":"5348942135","pt":1646222239118,"mc":[{"id":"1.195453681","rc":[{"atl":[[2.66,0],[2.7,2]],"id":40917619}],"con":true,"img":false}]}
{"op":"mcm","clk":"5348942150","pt":1646222239323,"mc":[{"id":"1.195453681","rc":[{"atl":[[17.5,1.42]],"id":40917619},{"atl":[[17.5,1.42]],"id":38554545}],"con":true,"img":false}]}
{"op":"mcm","clk":"5348942200","pt":1646222240103,"mc":[{"id":"1.195453681","rc":[{"atl":[[2.72,2],[2.7,0]],"id":40917619}],"con":true,"img":false}]}
{"op":"mcm","clk":"5348942379","pt":1646222242399,"mc":[{"id":"1.195453681","rc":[{"atl":[[2.5,0],[2.48,2]],"id":38554545}],"con":true,"img":false}]}
{"op":"mcm","clk":"5348942400","pt":1646222242606,"mc":[{"id":"1.195453681","rc":[{"atl":[[18,1.42]],"id":40917619},{"atl":[[17,1.42]],"id":38554545}],"con":true,"img":false}]}
{"op":"mcm","clk":"5348942493","pt":1646222243811,"mc":[{"id":"1.195453681","rc":[{"atl":[[17,1.42]],"id":40917619},{"atl":[[17,2.84]],"id":38554545}],"con":true,"img":false}]}
{"op":"mcm","clk":"5348942714","pt":1646222246644,"mc":[{"id":"1.195453681","rc":[{"atl":[[2.82,2]],"id":40917619}],"con":true,"img":false}]}
{"op":"mcm","clk":"5348942722","pt":1646222246755,"mc":[{"id":"1.195453681","rc":[{"atl":[[2.72,0]],"id":40917619}],"con":true,"img":false}]}
{"op":"mcm","clk":"5348942733","pt":1646222246796,"mc":[{"id":"1.195453681","rc":[{"atl":[[17,2.84]],"id":40917619},{"atl":[[18,1.42]],"id":38554545}],"con":true,"img":false}]}
{"op":"mcm","clk":"5348942812","pt":1646222247702,"mc":[{"id":"1.195453681","rc":[{"atl":[[2.5,2],[2.48,0]],"id":38554545}],"con":true,"img":false}]}
{"op":"mcm","clk":"5348942902","pt":1646222248954,"mc":[{"id":"1.195453681","rc":[{"atl":[[18.5,1.42]],"id":40917619},{"atl":[[18,2.84]],"id":38554545}],"con":true,"img":false}]}
{"op":"mcm","clk":"5348943030","pt":1646222250727,"mc":[{"id":"1.195453681","rc":[{"atl":[[18.5,2.84]],"id":40917619},{"atl":[[18.5,1.42]],"id":38554545}],"con":true,"img":false}]}
{"op":"mcm","clk":"5348943114","pt":1646222251822,"mc":[{"id":"1.195453681","rc":[{"atl":[[2.82,0],[2.68,2]],"id":40917619}],"con":true,"img":false}]}
{"op":"mcm","clk":"5348943126","pt":1646222252035,"mc":[{"id":"1.195453681","rc":[{"atl":[[19,1.42]],"id":40917619},{"atl":[[18.5,2.84]],"id":38554545}],"con":true,"img":false}]}
{"op":"mcm","clk":"5348943178","pt":1646222252708,"mc":[{"id":"1.195453681","rc":[{"atl":[[2.5,0],[2.48,2]],"id":38554545}],"con":true,"img":false}]}
{"op":"mcm","clk":"5348943266","pt":1646222254022,"mc":[{"id":"1.195453681","rc":[{"atl":[[19,2.84]],"id":40917619}],"con":true,"img":false}]}
{"op":"mcm","clk":"5348943525","pt":1646222256941,"mc":[{"id":"1.195453681","rc":[{"atl":[[2.78,2],[2.68,0]],"id":40917619}],"con":true,"img":false}]}
{"op":"mcm","clk":"5348943719","pt":1646222259365,"mc":[{"id":"1.195453681","rc":[{"atl":[[2.5,2],[2.48,0]],"id":38554545}],"con":true,"img":false}]}
{"op":"mcm","clk":"5348943962","pt":1646222262126,"mc":[{"id":"1.195453681","rc":[{"atl":[[2.72,2],[2.78,0]],"id":40917619}],"con":true,"img":false}]}
{"op":"mcm","clk":"5348944185","pt":1646222264435,"mc":[{"id":"1.195453681","rc":[{"atl":[[2.5,0],[2.48,2]],"id":38554545}],"con":true,"img":false}]}
{"op":"mcm","clk":"5348947334","pt":1646222301927,"mc":[{"id":"1.195453681","rc":[{"atb":[[1.8,0],[1.6,0],[1.7,0]],"id":40917619},{"atb":[[1.8,0],[1.6,0],[1.7,0]],"id":38554545}],"con":true,"img":false}]}
{"op":"mcm","clk":"5348947355","pt":1646222302085,"mc":[{"id":"1.195453681","rc":[{"atb":[[1.64,2],[1.63,8.7]],"id":40917619},{"atl":[[2.72,10.2]],"id":40917619},{"atb":[[1.81,11.97]],"id":38554545},{"atl":[[2.48,11.95]],"id":38554545}],"con":true,"img":false}]}
{"op":"mcm","clk":"5348947468","pt":1646222303505,"mc":[{"id":"1.195453681","rc":[{"atb":[[1.64,10.59]],"id":40917619}],"con":true,"img":false}]}
{"op":"mcm","clk":"5348947611","pt":1646222305677,"mc":[{"id":"1.195453681","rc":[{"atl":[[16.5,1.42]],"id":40917619},{"atl":[[16.5,1.42]],"id":38554545}],"con":true,"img":false}]}
{"op":"mcm","clk":"5348947711","pt":1646222307078,"mc":[{"id":"1.195453681","rc":[{"atl":[[16,1.42]],"id":40917619},{"atl":[[16,1.42]],"id":38554545}],"con":true,"img":false}]}
{"op":"mcm","clk":"5348947817","pt":1646222308489,"mc":[{"id":"1.195453681","rc":[{"atl":[[15.5,1.42]],"id":40917619},{"atl":[[15.5,1.42]],"id":38554545}],"con":true,"img":false}]}
{"op":"mcm","clk":"5348947913","pt":1646222309881,"mc":[{"id":"1.195453681","rc":[{"atl":[[15,1.42]],"id":40917619},{"atl":[[15,1.42]],"id":38554545}],"con":true,"img":false}]}
{"op":"mcm","clk":"5348948097","pt":1646222312420,"mc":[{"id":"1.195453681","rc":[{"atl":[[14,1.42]],"id":40917619},{"atl":[[14,1.42]],"id":38554545}],"con":true,"img":false}]}
{"op":"mcm","clk":"5348948149","pt":1646222313095,"mc":[{"id":"1.195453681","rc":[{"atb":[[1.79,6.82],[1.89,6.06],[1.69,7.82]],"id":40917619},{"atb":[[1.56,9.63],[1.46,11.72],[1.66,8.17]],"id":38554545}],"con":true,"img":false}]}
{"op":"mcm","clk":"5348948217","pt":1646222313791,"mc":[{"id":"1.195453681","rc":[{"atl":[[13.5,1.42]],"id":40917619},{"atl":[[14.5,1.42]],"id":38554545}],"con":true,"img":false}]}
{"op":"mcm","clk":"5348948259","pt":1646222314295,"mc":[{"id":"1.195453681","rc":[{"atb":[[1.9,8.57]],"id":40917619}],"con":true,"img":false}]}
{"op":"mcm","clk":"5348948564","pt":1646222318288,"mc":[{"id":"1.195453681","rc":[{"atb":[[1.93,1.42]],"id":40917619},{"atl":[[13,1.42]],"id":40917619},{"atl":[[13,1.42]],"id":38554545}],"con":true,"img":false}]}
{"op":"mcm","clk":"5348948585","pt":1646222318713,"mc":[{"id":"1.195453681","rc":[{"atb":[[1.93,9.99]],"id":40917619}],"con":true,"img":false}]}
{"op":"mcm","clk":"5348948656","pt":1646222319590,"mc":[{"id":"1.195453681","rc":[{"atb":[[1.91,1.42]],"id":40917619},{"atl":[[14.5,1.42]],"id":40917619},{"atl":[[13.5,1.42]],"id":38554545}],"con":true,"img":false}]}
{"op":"mcm","clk":"5348948716","pt":1646222320507,"mc":[{"id":"1.195453681","rc":[{"atl":[[13,0],[13.5,0],[14,0]],"id":40917619},{"atl":[[13,0],[14,0]],"id":38554545}],"con":true,"img":false}]}
{"op":"mcm","clk":"5348948754","pt":1646222321185,"mc":[{"id":"1.195453681","rc":[{"atb":[[1.95,1.42]],"id":40917619},{"atl":[[14.5,2.84]],"id":40917619}],"con":true,"img":false}]}
{"op":"mcm","clk":"5348948795","pt":1646222321598,"mc":[{"id":"1.195453681","rc":[{"atb":[[1.95,10]],"id":40917619}],"con":true,"img":false}]}
{"op":"mcm","clk":"5348948810","pt":1646222321802,"mc":[{"id":"1.195453681","rc":[{"atb":[[1.63,0]],"id":40917619}],"con":true,"img":false}]}
{"op":"mcm","clk":"5348948823","pt":1646222322008,"mc":[{"id":"1.195453681","rc":[{"atb":[[1.91,0]],"id":40917619},{"atl":[[14.5,1.42]],"id":40917619},{"atl":[[13.5,0],[14.5,0],[15,0]],"id":38554545}],"con":true,"img":false}]}
{"op":"mcm","clk":"5348948962","pt":1646222323718,"mc":[{"id":"1.195453681","rc":[{"atb":[[1.93,8.57]],"id":40917619},{"atl":[[14.5,0],[15,0],[15.5,0]],"id":40917619},{"atl":[[15.5,0]],"id":38554545}],"con":true,"img":false}]}
{"op":"mcm","clk":"5348949095","pt":1646222325433,"mc":[{"id":"1.195453681","rc":[{"atl":[[16,0],[16.5,0],[17,0]],"id":40917619},{"atl":[[16,0],[16.5,0],[17,0]],"id":38554545}],"con":true,"img":false}]}
{"op":"mcm","clk":"5348949217","pt":1646222327229,"mc":[{"id":"1.195453681","rc":[{"atl":[[17.5,0],[18,0]],"id":40917619},{"atl":[[17.5,0],[18,0]],"id":38554545}],"con":true,"img":false}]}
{"op":"mcm","clk":"5348949243","pt":1646222327696,"mc":[{"id":"1.195453681","rc":[{"atl":[[26,1.42]],"id":40917619},{"atl":[[25,1.42]],"id":38554545}],"con":true,"img":false}]}
{"op":"mcm","clk":"5348949328","pt":1646222328789,"mc":[{"id":"1.195453681","rc":[{"atl":[[18.5,0],[19,0],[19.5,0],[20,0]],"id":40917619},{"atl":[[18.5,0],[19,0],[19.5,0]],"id":38554545}],"con":true,"img":false}]}
{"op":"mcm","clk":"5348949402","pt":1646222329825,"mc":[{"id":"1.195453681","rc":[{"atl":[[26,2.84]],"id":40917619},{"atl":[[25,2.84]],"id":38554545}],"con":true,"img":false}]}
{"op":"mcm","clk":"5348949434","pt":1646222330192,"mc":[{"id":"1.195453681","rc":[{"atl":[[21,0],[22,0],[23,0],[24,0]],"id":40917619},{"atl":[[20,0],[21,0]],"id":38554545}],"con":true,"img":false}]}
{"op":"mcm","clk":"5348949513","pt":1646222331232,"mc":[{"id":"1.195453681","rc":[{"atl":[[28,1.42]],"id":40917619},{"atl":[[27,1.42]],"id":38554545}],"con":true,"img":false}]}
{"op":"mcm","clk":"5348949583","pt":1646222332214,"mc":[{"id":"1.195453681","rc":[{"atl":[[22,0]],"id":38554545}],"con":true,"img":false}]}
{"op":"mcm","clk":"5348949703","pt":1646222333919,"mc":[{"id":"1.195453681","rc":[{"atl":[[25,0]],"id":40917619}],"con":true,"img":false}]}
{"op":"mcm","clk":"5348949794","pt":1646222335111,"mc":[{"id":"1.195453681","rc":[{"atl":[[29,1.42]],"id":40917619},{"atl":[[29,1.42]],"id":38554545}],"con":true,"img":false}]}
{"op":"mcm","clk":"5348949847","pt":1646222335936,"mc":[{"id":"1.195453681","rc":[{"atl":[[2.72,8.2],[2.7,16.78]],"id":40917619}],"con":true,"img":false}]}
{"op":"mcm","clk":"5348949881","pt":1646222336303,"mc":[{"id":"1.195453681","rc":[{"atl":[[26,0]],"id":40917619},{"atl":[[23,0]],"id":38554545}],"con":true,"img":false}]}
{"op":"mcm","clk":"5348949925","pt":1646222337019,"mc":[{"id":"1.195453681","rc":[{"atl":[[2.68,8.17]],"id":40917619}],"con":true,"img":false}]}
{"op":"mcm","clk":"5348949944","pt":1646222337333,"mc":[{"id":"1.195453681","rc":[{"atl":[[30,1.42]],"id":40917619},{"atl":[[29,2.84]],"id":38554545}],"con":true,"img":false}]}
{"op":"mcm","clk":"5348950072","pt":1646222338732,"mc":[{"id":"1.195453681","rc":[{"atl":[[32,1.42]],"id":40917619},{"atl":[[30,1.42]],"id":38554545}],"con":true,"img":false}]}
{"op":"mcm","clk":"5348950167","pt":1646222340031,"mc":[{"id":"1.195453681","rc":[{"atl":[[34,1.42]],"id":40917619},{"atl":[[32,1.42]],"id":38554545}],"con":true,"img":false}]}
{"op":"mcm","clk":"5348950231","pt":1646222341016,"mc":[{"id":"1.195453681","rc":[{"atl":[[2.66,16.78],[2.7,0]],"id":40917619}],"con":true,"img":false}]}
{"op":"mcm","clk":"5348950274","pt":1646222341535,"mc":[{"id":"1.195453681","rc":[{"atl":[[2.64,8.19]],"id":40917619}],"con":true,"img":false}]}
{"op":"mcm","clk":"5348950278","pt":1646222341641,"mc":[{"id":"1.195453681","rc":[{"atl":[[34,2.84]],"id":40917619},{"atl":[[32,2.84]],"id":38554545}],"con":true,"img":false}]}
{"op":"mcm","clk":"5348950408","pt":1646222343350,"mc":[{"id":"1.195453681","rc":[{"atl":[[36,1.42]],"id":40917619},{"atl":[[34,1.42]],"id":38554545}],"con":true,"img":false}]}
{"op":"mcm","clk":"5348950495","pt":1646222344747,"mc":[{"id":"1.195453681","rc":[{"atl":[[36,1.42]],"id":38554545}],"con":true,"img":false}]}
{"op":"mcm","clk":"5348950615","pt":1646222346158,"mc":[{"id":"1.195453681","rc":[{"atl":[[2.62,16.78]],"id":40917619}],"con":true,"img":false}]}
{"op":"mcm","clk":"5348950623","pt":1646222346259,"mc":[{"id":"1.195453681","rc":[{"atl":[[2.66,0]],"id":40917619}],"con":true,"img":false}]}
{"op":"mcm","clk":"5348950771","pt":1646222348122,"mc":[{"id":"1.195453681","rc":[{"atl":[[2.6,8.19]],"id":40917619}],"con":true,"img":false}]}
{"op":"mcm","clk":"5348950947","pt":1646222350117,"mc":[{"id":"1.195453681","rc":[{"atb":[[1.81,3.24]],"id":38554545},{"trd":[[1.81,17.46]],"ltp":1.81,"tv":17.46,"id":38554545}],"con":true,"img":false}]}
{"op":"mcm","clk":"5348950958","pt":1646222350221,"mc":[{"id":"1.195453681","rc":[{"atb":[[1.81,0]],"id":38554545}],"con":true,"img":false}]}
{"op":"mcm","clk":"5348951047","pt":1646222351358,"mc":[{"id":"1.195453681","rc":[{"atl":[[2.58,16.77],[2.62,0]],"id":40917619}],"con":true,"img":false}]}
{"op":"mcm","clk":"5348951245","pt":1646222353434,"mc":[{"id":"1.195453681","rc":[{"atl":[[22,1.42]],"id":38554545}],"con":true,"img":false}]}
{"op":"mcm","clk":"5348951349","pt":1646222354831,"mc":[{"id":"1.195453681","rc":[{"atl":[[26,1.42]],"id":40917619},{"atl":[[21,1.42]],"id":38554545}],"con":true,"img":false}]}
{"op":"mcm","clk":"5348951458","pt":1646222356236,"mc":[{"id":"1.195453681","rc":[{"atl":[[25,1.42]],"id":40917619},{"atl":[[20,1.42]],"id":38554545}],"con":true,"img":false}]}
{"op":"mcm","clk":"5348951603","pt":1646222358217,"mc":[{"id":"1.195453681","rc":[{"atl":[[23,1.42]],"id":40917619},{"atl":[[19,1.42]],"id":38554545}],"con":true,"img":false}]}
{"op":"mcm","clk":"5348951671","pt":1646222359150,"mc":[{"id":"1.195453681","rc":[{"atb":[[1.95,3]],"id":40917619},{"trd":[[1.95,14]],"ltp":1.95,"tv":14.0,"id":40917619}],"con":true,"img":false}]}
{"op":"mcm","clk":"5348951686","pt":1646222359369,"mc":[{"id":"1.195453681","rc":[{"atb":[[1.95,0],[1.93,4.57]],"id":40917619},{"atl":[[2.72,0],[2.56,8.13]],"id":40917619},{"trd":[[1.93,8],[1.95,20]],"ltp":1.93,"tv":28.0,"id":40917619},{"atb":[[1.67,10.25]],"id":38554545}],"con":true,"img":false}]}
{"op":"mcm","clk":"5348951690","pt":1646222359427,"mc":[{"id":"1.195453681","rc":[{"atb":[[1.93,0]],"id":40917619},{"atl":[[1.93,2.43]],"id":40917619},{"trd":[[1.93,17.14]],"ltp":1.93,"tv":17.14,"id":40917619}],"con":true,"img":false}]}
{"op":"mcm","clk":"5348951697","pt":1646222359533,"mc":[{"id":"1.195453681","rc":[{"atl":[[2.54,16.34],[2.58,0],[1.93,0]],"id":40917619},{"trd":[[1.93,22]],"ltp":1.93,"tv":22.0,"id":40917619}],"con":true,"img":false}]}
{"op":"mcm","clk":"5348951703","pt":1646222359638,"mc":[{"id":"1.195453681","rc":[{"atl":[[1.93,7],[22,1.42]],"id":40917619},{"atl":[[18,1.42]],"id":38554545}],"con":true,"img":false}]}
{"op":"mcm","clk":"5348951712","pt":1646222359738,"mc":[{"id":"1.195453681","rc":[{"atl":[[1.93,0],[2.52,8.32],[2.68,0]],"id":40917619},{"trd":[[1.93,36]],"ltp":1.93,"tv":36.0,"id":40917619}],"con":true,"img":false}]}
{"op":"mcm","clk":"5348951716","pt":1646222359835,"mc":[{"id":"1.195453681","rc":[{"atl":[[1.93,14],[2.52,16.64]],"id":40917619}],"con":true,"img":false}]}
{"op":"mcm","clk":"5348951725","pt":1646222359941,"mc":[{"id":"1.195453681","rc":[{"atl":[[1.93,0]],"id":40917619},{"trd":[[1.93,64]],"ltp":1.93,"tv":64.0,"id":40917619}],"con":true,"img":false}]}
{"op":"mcm","clk":"5348951731","pt":1646222360042,"mc":[{"id":"1.195453681","rc":[{"atl":[[1.93,7]],"id":40917619}],"con":true,"img":false}]}
{"op":"mcm","clk":"5348951741","pt":1646222360149,"mc":[{"id":"1.195453681","rc":[{"atl":[[1.93,0]],"id":40917619},{"trd":[[1.93,78]],"ltp":1.93,"tv":78.0,"id":40917619}],"con":true,"img":false}]}
{"op":"mcm","clk":"5348951749","pt":1646222360252,"mc":[{"id":"1.195453681","rc":[{"atl":[[1.93,6]],"id":40917619}],"con":true,"img":false}]}
{"op":"mcm","clk":"5348951826","pt":1646222361039,"mc":[{"id":"1.195453681","rc":[{"atl":[[21,1.42]],"id":40917619},{"atl":[[17.5,1.42]],"id":38554545}],"con":true,"img":false}]}
{"op":"mcm","clk":"5348951893","pt":1646222361976,"mc":[{"id":"1.195453681","rc":[{"atb":[[1.79,0],[1.89,0],[1.69,0]],"id":40917619},{"atb":[[1.56,0],[1.46,0],[1.66,0]],"id":38554545}],"con":true,"img":false}]}
{"op":"mcm","clk":"5348952087","pt":1646222364255,"mc":[{"id":"1.195453681","rc":[{"atl":[[17.5,0],[18,0]],"id":38554545}],"con":true,"img":false}]}
{"op":"mcm","clk":"5348952173","pt":1646222365447,"mc":[{"id":"1.195453681","rc":[{"atl":[[24,1.42]],"id":40917619},{"atl":[[23,1.42]],"id":38554545}],"con":true,"img":false}]}
{"op":"mcm","clk":"5348952196","pt":1646222365861,"mc":[{"id":"1.195453681","rc":[{"atl":[[19,0]],"id":38554545}],"con":true,"img":false}]}
{"op":"mcm","clk":"5348952274","pt":1646222367057,"mc":[{"id":"1.195453681","rc":[{"atl":[[24,2.84]],"id":40917619},{"atl":[[23,2.84]],"id":38554545}],"con":true,"img":false}]}
{"op":"mcm","clk":"5348952299","pt":1646222367473,"mc":[{"id":"1.195453681","rc":[{"atl":[[20,0]],"id":38554545}],"con":true,"img":false}]}
{"op":"mcm","clk":"5348952373","pt":1646222368662,"mc":[{"id":"1.195453681","rc":[{"atl":[[27,1.42]],"id":40917619},{"atl":[[26,1.42]],"id":38554545}],"con":true,"img":false}]}
{"op":"mcm","clk":"5348952430","pt":1646222369281,"mc":[{"id":"1.195453681","rc":[{"atl":[[21,0]],"id":40917619},{"atl":[[21,0],[22,0],[23,0]],"id":38554545}],"con":true,"img":false}]}
{"op":"mcm","clk":"5348952479","pt":1646222370264,"mc":[{"id":"1.195453681","rc":[{"atl":[[27,2.84]],"id":40917619},{"atl":[[26,2.84]],"id":38554545}],"con":true,"img":false}]}
{"op":"mcm","clk":"5348952508","pt":1646222370685,"mc":[{"id":"1.195453681","rc":[{"atl":[[22,0],[23,0],[24,0]],"id":40917619},{"atl":[[24,0],[25,0],[26,1.42]],"id":38554545}],"con":true,"img":false}]}
{"op":"mcm","clk":"5348952541","pt":1646222371100,"mc":[{"id":"1.195453681","rc":[{"atb":[[1.8,6.74],[1.6,8.99],[1.7,7.7]],"id":40917619},{"atb":[[1.8,6.74],[1.6,8.99],[1.7,7.7]],"id":38554545}],"con":true,"img":false}]}
{"op":"mcm","clk":"5348952627","pt":1646222371984,"mc":[{"id":"1.195453681","rc":[{"atl":[[38,1.42]],"id":40917619},{"atl":[[38,1.42]],"id":38554545}],"con":true,"img":false}]}
{"op":"mcm","clk":"5348952685","pt":1646222372659,"mc":[{"id":"1.195453681","rc":[{"atl":[[25,0],[26,0],[27,0]],"id":40917619},{"atl":[[26,0],[27,0],[29,0],[30,0]],"id":38554545}],"con":true,"img":false}]}
{"op":"mcm","clk":"5348952738","pt":1646222373490,"mc":[{"id":"1.195453681","rc":[{"atl":[[38,2.84]],"id":40917619},{"atl":[[38,2.84]],"id":38554545}],"con":true,"img":false}]}
{"op":"mcm","clk":"5348952830","pt":1646222374691,"mc":[{"id":"1.195453681","rc":[{"atl":[[32,0],[28,0],[29,0],[30,0]],"id":40917619},{"atl":[[32,0],[34,0]],"id":38554545}],"con":true,"img":false}]}
{"op":"mcm","clk":"5348952858","pt":1646222374962,"mc":[{"id":"1.195453681","rc":[{"atb":[[1.81,10.42],[1.71,10.42]],"id":38554545}],"con":true,"img":false}]}
{"op":"mcm","clk":"5348952872","pt":1646222375161,"mc":[{"id":"1.195453681","rc":[{"atl":[[46,1.42]],"id":40917619},{"atl":[[42,1.42]],"id":38554545}],"con":true,"img":false}]}
{"op":"mcm","clk":"5348952952","pt":1646222376259,"mc":[{"id":"1.195453681","rc":[{"atl":[[34,0],[36,0],[38,0]],"id":40917619},{"atl":[[36,0],[38,0]],"id":38554545}],"con":true,"img":false}]}
{"op":"mcm","clk":"5348953161","pt":1646222378770,"mc":[{"id":"1.195453681","rc":[{"atl":[[46,0]],"id":40917619},{"atl":[[42,0]],"id":38554545}],"con":true,"img":false}]}
{"op":"mcm","clk":"5348953239","pt":1646222379871,"mc":[{"id":"1.195453681","rc":[{"atl":[[95,1.42]],"id":40917619},{"atl":[[75,1.36]],"id":38554545}],"con":true,"img":false}]}
{"op":"mcm","clk":"5348953264","pt":1646222380271,"mc":[{"id":"1.195453681","rc":[{"atb":[[1.81,30.34]],"id":38554545}],"con":true,"img":false}]}
{"op":"mcm","clk":"5348953501","pt":1646222383495,"mc":[{"id":"1.195453681","rc":[{"atl":[[75,0]],"id":38554545}],"con":true,"img":false}]}
{"op":"mcm","clk":"5348953590","pt":1646222384382,"mc":[{"id":"1.195453681","rc":[{"atb":[[1.82,9.73]],"id":38554545}],"con":true,"img":false}]}
{"op":"mcm","clk":"5348953600","pt":1646222384488,"mc":[{"id":"1.195453681","rc":[{"atl":[[130,0.95]],"id":38554545}],"con":true,"img":false}]}
{"op":"mcm","clk":"5348953661","pt":1646222385378,"mc":[{"id":"1.195453681","rc":[{"atb":[[1.83,19.48],[1.81,10.42]],"id":38554545}],"con":true,"img":false}]}
{"op":"mcm","clk":"5348953757","pt":1646222386671,"mc":[{"id":"1.195453681","rc":[{"atl":[[130,1.91]],"id":38554545}],"con":true,"img":false}]}
{"op":"mcm","clk":"5348953990","pt":1646222390291,"mc":[{"id":"1.195453681","rc":[{"atl":[[140,0.95]],"id":38554545}],"con":true,"img":false}]}
{"op":"mcm","clk":"5348954111","pt":1646222391891,"mc":[{"id":"1.195453681","rc":[{"atb":[[1.84,19.47]],"id":38554545}],"con":true,"img":false}]}
{"op":"mcm","clk":"5348954116","pt":1646222391995,"mc":[{"id":"1.195453681","rc":[{"atb":[[1.85,19.7]],"id":38554545}],"con":true,"img":false}]}
{"op":"mcm","clk":"5348954125","pt":1646222392099,"mc":[{"id":"1.195453681","rc":[{"atb":[[1.83,0]],"id":38554545}],"con":true,"img":false}]}
{"op":"mcm","clk":"5348954206","pt":1646222393125,"mc":[{"id":"1.195453681","rc":[{"atb":[[1.8,0],[1.6,0],[1.7,0]],"id":40917619},{"atb":[[1.8,0],[1.6,0],[1.7,0]],"id":38554545}],"con":true,"img":false}]}
{"op":"mcm","clk":"5348954224","pt":1646222393341,"mc":[{"id":"1.195453681","rc":[{"atl":[[150,0.95]],"id":38554545}],"con":true,"img":false}]}
{"op":"mcm","clk":"5348954260","pt":1646222393706,"mc":[{"id":"1.195453681","rc":[{"atb":[[1.67,0],[1.86,9.58]],"id":38554545}],"con":true,"img":false}]}
{"op":"mcm","clk":"5348954272","pt":1646222393923,"mc":[{"id":"1.195453681","rc":[{"atl":[[95,0]],"id":40917619},{"atb":[[1.85,0],[1.87,19.32]],"id":38554545}],"con":true,"img":false}]}
{"op":"mcm","clk":"5348954347","pt":1646222394921,"mc":[{"id":"1.195453681","rc":[{"atb":[[1.88,9.72]],"id":38554545}],"con":true,"img":false}]}
{"op":"mcm","clk":"5348954397","pt":1646222395710,"mc":[{"id":"1.195453681","rc":[{"atl":[[160,0.95]],"id":38554545}],"con":true,"img":false}]}
{"op":"mcm","clk":"5348954585","pt":1646222398311,"mc":[{"id":"1.195453681","rc":[{"atl":[[100,0.91]],"id":38554545}],"con":true,"img":false}]}
{"op":"mcm","clk":"5348954633","pt":1646222398989,"mc":[{"id":"1.195453681","rc":[{"atb":[[1.89,19.31],[1.87,0]],"id":38554545}],"con":true,"img":false}]}
{"op":"mcm","clk":"5348954756","pt":1646222400835,"mc":[{"id":"1.195453681","rc":[{"atl":[[110,0.91]],"id":38554545}],"con":true,"img":false}]}
{"op":"mcm","clk":"5348954767","pt":1646222400937,"mc":[{"id":"1.195453681","rc":[{"atb":[[1.9,9.73]],"id":38554545}],"con":true,"img":false}]}
{"op":"mcm","clk":"5348954786","pt":1646222401101,"mc":[{"id":"1.195453681","rc":[{"atb":[[1.89,0],[1.91,19.31]],"id":38554545}],"con":true,"img":false}]}
{"op":"mcm","clk":"5348954953","pt":1646222403008,"mc":[{"id":"1.195453681","rc":[{"atl":[[120,0.91]],"id":38554545}],"con":true,"img":false}]}
{"op":"mcm","clk":"5348955289","pt":1646222406231,"mc":[{"id":"1.195453681","rc":[{"atb":[[1.8,6.74],[1.9,14.56],[1.7,7.7]],"id":40917619},{"atb":[[1.64,8.43],[1.44,12.26],[1.54,9.99]],"id":38554545}],"con":true,"img":false}]}
{"op":"mcm","clk":"5348955309","pt":1646222406499,"mc":[{"id":"1.195453681","rc":[{"atl":[[95,0.91]],"id":38554545}],"con":true,"img":false}]}
{"op":"mcm","clk":"5348955359","pt":1646222406919,"mc":[{"id":"1.195453681","rc":[{"atb":[[1.91,8.68]],"id":40917619}],"con":true,"img":false}]}
{"op":"mcm","clk":"5348955372","pt":1646222407124,"mc":[{"id":"1.195453681","rc":[{"atl":[[1.93,0]],"id":40917619},{"trd":[[1.93,90]],"ltp":1.93,"tv":90.0,"id":40917619}],"con":true,"img":false}]}
{"op":"mcm","clk":"5348955392","pt":1646222407344,"mc":[{"id":"1.195453681","rc":[{"atl":[[2.54,0],[2.5,16.83]],"id":40917619}],"con":true,"img":false}]}
{"op":"mcm","clk":"5348955481","pt":1646222408331,"mc":[{"id":"1.195453681","rc":[{"atl":[[95,1.82]],"id":38554545}],"con":true,"img":false}]}
{"op":"mcm","clk":"5348955631","pt":1646222409928,"mc":[{"id":"1.195453681","rc":[{"atl":[[2.64,0],[2.48,8.61]],"id":40917619}],"con":true,"img":false}]}
{"op":"mcm","clk":"5348955728","pt":1646222410918,"mc":[{"id":"1.195453681","rc":[{"atl":[[85,1.36]],"id":38554545}],"con":true,"img":false}]}
{"op":"mcm","clk":"5348955738","pt":1646222411026,"mc":[{"id":"1.195453681","rc":[{"atl":[[3.1,4],[3.35,4],[3.25,4],[3.3,4],[3.05,4],[3.2,4],[3.15,4]],"id":38554545}],"con":true,"img":false}]}
{"op":"mcm","clk":"5348955845","pt":1646222412230,"mc":[{"id":"1.195453681","rc":[{"atb":[[1.95,15]],"id":38554545}],"con":true,"img":false}]}
{"op":"mcm","clk":"5348955865","pt":1646222412543,"mc":[{"id":"1.195453681","rc":[{"atl":[[2.5,0],[2.46,17.3]],"id":40917619}],"con":true,"img":false}]}
{"op":"mcm","clk":"5348955898","pt":1646222413023,"mc":[{"id":"1.195453681","rc":[{"atl":[[2.6,0],[2.44,8.64]],"id":40917619},{"atl":[[3.1,6],[3.35,6],[3.25,6],[3.3,6],[3.05,6],[3.2,6],[3.15,6]],"id":38554545}],"con":true,"img":false}]}
{"op":"mcm","clk":"5348955951","pt":1646222413844,"mc":[{"id":"1.195453681","rc":[{"atb":[[1.95,30]],"id":38554545},{"atl":[[75,1.42]],"id":38554545}],"con":true,"img":false}]}
{"op":"mcm","clk":"5348956009","pt":1646222414638,"mc":[{"id":"1.195453681","rc":[{"atb":[[1.92,9.55]],"id":38554545}],"con":true,"img":false}]}
{"op":"mcm","clk":"5348956019","pt":1646222414843,"mc":[{"id":"1.195453681","rc":[{"atb":[[1.93,19.28],[1.81,0],[1.91,0]],"id":38554545}],"con":true,"img":false}]}
{"op":"mcm","clk":"5348956100","pt":1646222416049,"mc":[{"id":"1.195453681","rc":[{"atl":[[90,1.42]],"id":38554545}],"con":true,"img":false}]}
{"op":"mcm","clk":"5348956191","pt":1646222417564,"mc":[{"id":"1.195453681","rc":[{"atb":[[1.96,1.42]],"id":38554545},{"atl":[[80,1.42]],"id":38554545}],"con":true,"img":false}]}
{"op":"mcm","clk":"5348956204","pt":1646222417721,"mc":[{"id":"1.195453681","rc":[{"atl":[[2.42,17.33],[2.46,0]],"id":40917619},{"atb":[[1.96,16.97],[1.93,0]],"id":38554545}],"con":true,"img":false}]}
{"op":"mcm","clk":"5348956212","pt":1646222417831,"mc":[{"id":"1.195453681","rc":[{"atl":[[2.4,8.81]],"id":40917619}],"con":true,"img":false}]}
{"op":"mcm","clk":"5348956293","pt":1646222418927,"mc":[{"id":"1.195453681","rc":[{"atb":[[1.96,18.39]],"id":38554545},{"atl":[[70,1.42]],"id":38554545}],"con":true,"img":false}]}
{"op":"mcm","clk":"5348956389","pt":1646222420018,"mc":[{"id":"1.195453681","rc":[{"atb":[[1.97,9.3]],"id":38554545}],"con":true,"img":false}]}
{"op":"mcm","clk":"5348956402","pt":1646222420125,"mc":[{"id":"1.195453681","rc":[{"atb":[[1.98,15.31],[1.84,9.73],[1.96,2.84]],"id":38554545}],"con":true,"img":false}]}
{"op":"mcm","clk":"5348956561","pt":1646222421841,"mc":[{"id":"1.195453681","rc":[{"atl":[[65,1.42]],"id":38554545}],"con":true,"img":false}]}
{"op":"mcm","clk":"5348956594","pt":1646222422260,"mc":[{"id":"1.195453681","rc":[{"atb":[[1.96,0]],"id":38554545}],"con":true,"img":false}]}
{"op":"mcm","clk":"5348956648","pt":1646222422938,"mc":[{"id":"1.195453681","rc":[{"atl":[[2.42,0],[2.38,17.33]],"id":40917619}],"con":true,"img":false}]}
{"op":"mcm","clk":"5348956842","pt":1646222425067,"mc":[{"id":"1.195453681","rc":[{"atl":[[60,1.42]],"id":38554545}],"con":true,"img":false}]}
{"op":"mcm","clk":"5348956872","pt":1646222425328,"mc":[{"id":"1.195453681","rc":[{"atl":[[2.36,18.12]],"id":40917619}],"con":true,"img":false}]}
{"op":"mcm","clk":"5348956881","pt":1646222425430,"mc":[{"id":"1.195453681","rc":[{"atl":[[2.56,0]],"id":40917619}],"con":true,"img":false}]}
{"op":"mcm","clk":"5348956961","pt":1646222426365,"mc":[{"id":"1.195453681","rc":[{"atb":[[1.98,24.52]],"id":38554545}],"con":true,"img":false}]}
{"op":"mcm","clk":"5348956971","pt":1646222426476,"mc":[{"id":"1.195453681","rc":[{"atb":[[1.88,0]],"id":38554545}],"con":true,"img":false}]}
{"op":"mcm","clk":"5348957129","pt":1646222428135,"mc":[{"id":"1.195453681","rc":[{"atl":[[2.38,0],[2.34,17.51]],"id":40917619}],"con":true,"img":false}]}
{"op":"mcm","clk":"5348957159","pt":1646222428448,"mc":[{"id":"1.195453681","rc":[{"atl":[[55,1.42]],"id":38554545}],"con":true,"img":false}]}
{"op":"mcm","clk":"5348957184","pt":1646222428757,"mc":[{"id":"1.195453681","rc":[{"atl":[[2.52,8.32]],"id":40917619}],"con":true,"img":false}]}
{"op":"mcm","clk":"5348957190","pt":1646222428859,"mc":[{"id":"1.195453681","rc":[{"atl":[[2.32,9.12]],"id":40917619},{"atb":[[1.99,9.19]],"id":38554545}],"con":true,"img":false}]}
{"op":"mcm","clk":"5348957200","pt":1646222428964,"mc":[{"id":"1.195453681","rc":[{"atb":[[1.9,0]],"id":38554545}],"con":true,"img":false}]}
{"op":"mcm","clk":"5348957213","pt":1646222429068,"mc":[{"id":"1.195453681","rc":[{"atb":[[2,18.4],[1.98,9.21]],"id":38554545}],"con":true,"img":false}]}
{"op":"mcm","clk":"5348957540","pt":1646222433240,"mc":[{"id":"1.195453681","rc":[{"atl":[[2.3,2],[2.34,0]],"id":40917619}],"con":true,"img":false}]}
{"op":"mcm","clk":"5348959079","pt":1646222452795,"mc":[{"id":"1.195453681","rc":[{"atb":[[1.8,0],[1.9,8.57],[1.7,0]],"id":40917619},{"atb":[[1.64,0],[1.44,0],[1.54,0]],"id":38554545}],"con":true,"img":false}]}
{"op":"mcm","clk":"5348959231","pt":1646222454676,"mc":[{"id":"1.195453681","rc":[{"atl":[[2.3,11.16]],"id":40917619}],"con":true,"img":false}]}
{"op":"mcm","clk":"5348959245","pt":1646222454883,"mc":[{"id":"1.195453681","rc":[{"atl":[[2.48,0]],"id":40917619}],"con":true,"img":false}]}
{"op":"mcm","clk":"5348959759","pt":1646222460989,"mc":[{"id":"1.195453681","rc":[{"atb":[[1.64,19.02],[1.84,6.42],[1.74,7.29]],"id":40917619},{"atb":[[1.64,8.43],[1.74,7.29],[1.54,9.99]],"id":38554545}],"con":true,"img":false}]}
{"op":"mcm","clk":"5348960008","pt":1646222463915,"mc":[{"id":"1.195453681","rc":[{"atb":[[1.99,0]],"id":38554545}],"con":true,"img":false}]}
{"op":"mcm","clk":"5348960024","pt":1646222464123,"mc":[{"id":"1.195453681","rc":[{"atb":[[2,0],[1.99,18.52]],"id":38554545}],"con":true,"img":false}]}
{"op":"mcm","clk":"5348960038","pt":1646222464344,"mc":[{"id":"1.195453681","rc":[{"atb":[[1.64,17.02]],"id":40917619},{"atl":[[2.48,9.95],[2.56,18.52]],"id":38554545}],"con":true,"img":false}]}
{"op":"mcm","clk":"5348960056","pt":1646222464491,"mc":[{"id":"1.195453681","rc":[{"atb":[[1.6,17.82]],"id":40917619}],"con":true,"img":false}]}
{"op":"mcm","clk":"5348960082","pt":1646222464907,"mc":[{"id":"1.195453681","rc":[{"atb":[[1.98,0]],"id":38554545}],"con":true,"img":false}]}
{"op":"mcm","clk":"5348960248","pt":1646222466512,"mc":[{"id":"1.195453681","rc":[{"atb":[[1.97,0]],"id":38554545}],"con":true,"img":false}]}
{"op":"mcm","clk":"5348960296","pt":1646222467083,"mc":[{"id":"1.195453681","rc":[{"atl":[[55,0],[60,0],[65,0],[70,0],[75,0],[80,0],[85,0],[90,0],[95,0],[100,0],[110,0],[120,0],[130,0],[140,0],[150,0],[160,0]],"id":38554545}],"con":true,"img":false}]}
{"op":"mcm","clk":"5348960320","pt":1646222467395,"mc":[{"id":"1.195453681","rc":[{"atb":[[1.96,9.33]],"id":38554545}],"con":true,"img":false}]}
{"op":"mcm","clk":"5348960457","pt":1646222469217,"mc":[{"id":"1.195453681","rc":[{"atb":[[1.97,18.88]],"id":38554545}],"con":true,"img":false}]}
{"op":"mcm","clk":"5348960464","pt":1646222469319,"mc":[{"id":"1.195453681","rc":[{"atb":[[1.99,0]],"id":38554545}],"con":true,"img":false}]}
{"op":"mcm","clk":"5348960483","pt":1646222469581,"mc":[{"id":"1.195453681","rc":[{"atl":[[80,1.42]],"id":38554545}],"con":true,"img":false}]}
{"op":"mcm","clk":"5348960664","pt":1646222471716,"mc":[{"id":"1.195453681","rc":[{"atb":[[1.98,1.42]],"id":38554545},{"atl":[[75,1.42]],"id":38554545}],"con":true,"img":false}]}
{"op":"mcm","clk":"5348960688","pt":1646222471923,"mc":[{"id":"1.195453681","rc":[{"atb":[[1.98,10.67]],"id":38554545}],"con":true,"img":false}]}
{"op":"mcm","clk":"5348960704","pt":1646222472083,"mc":[{"id":"1.195453681","rc":[{"atb":[[1.99,19.29],[1.97,0]],"id":38554545}],"con":true,"img":false}]}
{"op":"mcm","clk":"5348960788","pt":1646222473230,"mc":[{"id":"1.195453681","rc":[{"atb":[[1.98,12.09]],"id":38554545},{"atl":[[75,2.84]],"id":38554545}],"con":true,"img":false}]}
{"op":"mcm","clk":"5348960839","pt":1646222473805,"mc":[{"id":"1.195453681","rc":[{"atb":[[1.98,10.67]],"id":38554545}],"con":true,"img":false}]}
{"op":"mcm","clk":"5348960970","pt":1646222475732,"mc":[{"id":"1.195453681","rc":[{"atb":[[1.98,9.25]],"id":38554545}],"con":true,"img":false}]}
{"op":"mcm","clk":"5348961038","pt":1646222476413,"mc":[{"id":"1.195453681","rc":[{"atl":[[70,1.42]],"id":38554545}],"con":true,"img":false}]}
{"op":"mcm","clk":"5348961210","pt":1646222478605,"mc":[{"id":"1.195453681","rc":[{"atb":[[2,9.06]],"id":38554545}],"con":true,"img":false}]}
{"op":"mcm","clk":"5348961215","pt":1646222478711,"mc":[{"id":"1.195453681","rc":[{"atb":[[1.91,0]],"id":40917619}],"con":true,"img":false}]}
{"op":"mcm","clk":"5348961220","pt":1646222478816,"mc":[{"id":"1.195453681","rc":[{"atb":[[1.99,0],[2.02,18.31]],"id":38554545}],"con":true,"img":false}]}
{"op":"mcm","clk":"5348961248","pt":1646222479233,"mc":[{"id":"1.195453681","rc":[{"atb":[[1.9,0]],"id":40917619},{"atb":[[2.04,8.79]],"id":38554545}],"con":true,"img":false}]}
{"op":"mcm","clk":"5348961260","pt":1646222479388,"mc":[{"id":"1.195453681","rc":[{"atb":[[1.92,0]],"id":38554545}],"con":true,"img":false}]}
{"op":"mcm","clk":"5348961278","pt":1646222479802,"mc":[{"id":"1.195453681","rc":[{"atb":[[1.85,9.61]],"id":40917619}],"con":true,"img":false}]}
{"op":"mcm","clk":"5348961377","pt":1646222481580,"mc":[{"id":"1.195453681","rc":[{"atb":[[1.64,8.59],[1.84,0],[1.74,0]],"id":40917619},{"atb":[[1.64,0],[1.74,0],[1.54,0]],"id":38554545}],"con":true,"img":false}]}
{"op":"mcm","clk":"5348961535","pt":1646222483512,"mc":[{"id":"1.195453681","rc":[{"atl":[[65,1.42]],"id":38554545}],"con":true,"img":false}]}
{"op":"mcm","clk":"5348961574","pt":1646222484027,"mc":[{"id":"1.195453681","rc":[{"atb":[[2.02,0],[2.06,17.86]],"id":38554545}],"con":true,"img":false}]}
{"op":"mcm","clk":"5348961681","pt":1646222485232,"mc":[{"id":"1.195453681","rc":[{"atl":[[65,2.84]],"id":38554545}],"con":true,"img":false}]}
{"op":"mcm","clk":"5348961697","pt":1646222485437,"mc":[{"id":"1.195453681","rc":[{"atb":[[2.08,8.7]],"id":38554545}],"con":true,"img":false}]}
{"op":"mcm","clk":"5348961707","pt":1646222485550,"mc":[{"id":"1.195453681","rc":[{"atb":[[1.96,0]],"id":38554545}],"con":true,"img":false}]}
{"op":"mcm","clk":"5348961713","pt":1646222485644,"mc":[{"id":"1.195453681","rc":[{"atb":[[2.08,0]],"id":38554545}],"con":true,"img":false}]}
{"op":"mcm","clk":"5348961960","pt":1646222489067,"mc":[{"id":"1.195453681","rc":[{"atb":[[1.86,6.27],[1.66,8.17],[1.76,7.1]],"id":40917619},{"atb":[[1.6,8.99],[1.7,7.7],[1.5,10.79]],"id":38554545}],"con":true,"img":false}]}
{"op":"mcm","clk":"5348962043","pt":1646222490257,"mc":[{"id":"1.195453681","rc":[{"atb":[[2.08,8.71]],"id":38554545}],"con":true,"img":false}]}
{"op":"mcm","clk":"5348962063","pt":1646222490410,"mc":[{"id":"1.195453681","rc":[{"atb":[[2.1,17.51],[2.06,0]],"id":38554545}],"con":true,"img":false}]}
{"op":"mcm","clk":"5348962113","pt":1646222491035,"mc":[{"id":"1.195453681","rc":[{"atb":[[1.67,43.51]],"id":40917619},{"atb":[[2.02,28.57]],"id":38554545}],"con":true,"img":false}]}
{"op":"mcm","clk":"5348962241","pt":1646222492343,"mc":[{"id":"1.195453681","rc":[{"atl":[[65,0],[70,0],[75,0],[80,0]],"id":38554545}],"con":true,"img":false}]}
{"op":"mcm","clk":"5348962307","pt":1646222493220,"mc":[{"id":"1.195453681","rc":[{"atb":[[1.86,16.07]],"id":40917619}],"con":true,"img":false}]}
{"op":"mcm","clk":"5348962329","pt":1646222493540,"mc":[{"id":"1.195453681","rc":[{"atb":[[1.86,6.27]],"id":40917619},{"atl":[[2.3,9.16],[2.28,18.77]],"id":40917619}],"con":true,"img":false}]}
{"op":"mcm","clk":"5348962455","pt":1646222495039,"mc":[{"id":"1.195453681","rc":[{"atb":[[1.85,0]],"id":40917619},{"atl":[[2.26,20.59]],"id":40917619},{"atb":[[1.98,0],[2.12,16.41],[1.71,0]],"id":38554545}],"con":true,"img":false}]}
{"op":"mcm","clk":"5348962465","pt":1646222495139,"mc":[{"id":"1.195453681","rc":[{"atl":[[2.44,0]],"id":40917619}],"con":true,"img":false}]}
{"op":"mcm","clk":"5348962472","pt":1646222495244,"mc":[{"id":"1.195453681","rc":[{"atb":[[1.77,10.35]],"id":40917619}],"con":true,"img":false}]}
{"op":"mcm","clk":"5348962486","pt":1646222495453,"mc":[{"id":"1.195453681","rc":[{"atb":[[2.04,36.82]],"id":38554545}],"con":true,"img":false}]}
{"op":"mcm","clk":"5348962495","pt":1646222495557,"mc":[{"id":"1.195453681","rc":[{"atb":[[2.14,17.51]],"id":38554545}],"con":true,"img":false}]}
{"op":"mcm","clk":"5348962503","pt":1646222495658,"mc":[{"id":"1.195453681","rc":[{"atb":[[2.1,0]],"id":38554545}],"con":true,"img":false}]}
{"op":"mcm","clk":"5348962513","pt":1646222495767,"mc":[{"id":"1.195453681","rc":[{"atb":[[1.86,0]],"id":40917619},{"trd":[[1.86,12.54]],"ltp":1.86,"tv":12.54,"id":40917619}],"con":true,"img":false}]}
{"op":"mcm","clk":"5348962534","pt":1646222496022,"mc":[{"id":"1.195453681","rc":[{"atb":[[1.67,0]],"id":40917619}],"con":true,"img":false}]}
{"op":"mcm","clk":"5348962552","pt":1646222496230,"mc":[{"id":"1.195453681","rc":[{"atb":[[2.16,8.3]],"id":38554545}],"con":true,"img":false}]}
{"op":"mcm","clk":"5348962560","pt":1646222496333,"mc":[{"id":"1.195453681","rc":[{"atb":[[2,0],[2.14,0]],"id":38554545}],"con":true,"img":false}]}
{"op":"mcm","clk":"5348962569","pt":1646222496440,"mc":[{"id":"1.195453681","rc":[{"atb":[[1.65,44.85]],"id":40917619},{"atb":[[2.08,35.7],[2.18,17.01]],"id":38554545}],"con":true,"img":false}]}
{"op":"mcm","clk":"5348962614","pt":1646222496962,"mc":[{"id":"1.195453681","rc":[{"atb":[[2.02,0]],"id":38554545}],"con":true,"img":false}]}
{"op":"mcm","clk":"5348962753","pt":1646222498624,"mc":[{"id":"1.195453681","rc":[{"atl":[[2.24,18.29],[2.28,0]],"id":40917619}],"con":true,"img":false}]}
{"op":"mcm","clk":"5348962818","pt":1646222499562,"mc":[{"id":"1.195453681","rc":[{"atb":[[1.77,24.35]],"id":40917619},{"atl":[[2.24,33.71]],"id":40917619},{"atl":[[2.48,26.36]],"id":38554545}],"con":true,"img":false}]}
{"op":"mcm","clk":"5348962857","pt":1646222499923,"mc":[{"id":"1.195453681","rc":[{"atb":[[1.68,42.87]],"id":40917619},{"atb":[[2.18,41.71]],"id":38554545}],"con":true,"img":false}]}
{"op":"mcm","clk":"5348962862","pt":1646222500081,"mc":[{"id":"1.195453681","rc":[{"atl":[[2.22,10.18]],"id":40917619}],"con":true,"img":false}]}
{"op":"mcm","clk":"5348962878","pt":1646222500246,"mc":[{"id":"1.195453681","rc":[{"atl":[[2.52,0]],"id":40917619}],"con":true,"img":false}]}
{"op":"mcm","clk":"5348962899","pt":1646222500466,"mc":[{"id":"1.195453681","rc":[{"atl":[[2.24,18.29]],"id":40917619}],"con":true,"img":false}]}
{"op":"mcm","clk":"5348962913","pt":1646222500664,"mc":[{"id":"1.195453681","rc":[{"atl":[[2.22,25.6]],"id":40917619}],"con":true,"img":false}]}
{"op":"mcm","clk":"5348962947","pt":1646222501027,"mc":[{"id":"1.195453681","rc":[{"atl":[[2.22,10.18]],"id":40917619}],"con":true,"img":false}]}
{"op":"mcm","clk":"5348962955","pt":1646222501132,"mc":[{"id":"1.195453681","rc":[{"atb":[[1.78,10.28]],"id":40917619},{"atl":[[2.24,33.71]],"id":40917619},{"atl":[[2.46,8.22]],"id":38554545}],"con":true,"img":false}]}
{"op":"mcm","clk":"5348962979","pt":1646222501445,"mc":[{"id":"1.195453681","rc":[{"atb":[[1.76,45.45]],"id":40917619},{"atb":[[2.18,17.01],[2.16,33.42]],"id":38554545}],"con":true,"img":false}]}
{"op":"mcm","clk":"5348962985","pt":1646222501554,"mc":[{"id":"1.195453681","rc":[{"atb":[[1.77,10.35]],"id":40917619},{"atl":[[2.24,18.29]],"id":40917619},{"atl":[[2.48,9.95]],"id":38554545}],"con":true,"img":false}]}
{"op":"mcm","clk":"5348962994","pt":1646222501658,"mc":[{"id":"1.195453681","rc":[{"atb":[[1.78,24.28]],"id":40917619},{"atl":[[2.22,25.6]],"id":40917619},{"atb":[[2.18,23.97]],"id":38554545},{"atl":[[2.46,24.63]],"id":38554545}],"con":true,"img":false}]}
{"op":"mcm","clk":"5348963018","pt":1646222502072,"mc":[{"id":"1.195453681","rc":[{"atb":[[1.78,10.28]],"id":40917619},{"atl":[[2.46,8.22]],"id":38554545}],"con":true,"img":false}]}
{"op":"mcm","clk":"5348963042","pt":1646222502434,"mc":[{"id":"1.195453681","rc":[{"atb":[[1.76,7.1]],"id":40917619}],"con":true,"img":false}]}
{"op":"mcm","clk":"5348963075","pt":1646222502846,"mc":[{"id":"1.195453681","rc":[{"atl":[[2.2,10.18]],"id":40917619}],"con":true,"img":false}]}
{"op":"mcm","clk":"5348963084","pt":1646222502962,"mc":[{"id":"1.195453681","rc":[{"atl":[[2.36,9.06]],"id":40917619}],"con":true,"img":false}]}
{"op":"mcm","clk":"5348963111","pt":1646222503264,"mc":[{"id":"1.195453681","rc":[{"atl":[[2.22,10.18]],"id":40917619}],"con":true,"img":false}]}
{"op":"mcm","clk":"5348963148","pt":1646222503677,"mc":[{"id":"1.195453681","rc":[{"atl":[[2.2,30.54]],"id":40917619}],"con":true,"img":false}]}
{"op":"mcm","clk":"5348963157","pt":1646222503782,"mc":[{"id":"1.195453681","rc":[{"atb":[[1.7,1.42]],"id":40917619},{"atb":[[2.06,1.42]],"id":38554545},{"atl":[[2.44,1.42]],"id":38554545}],"con":true,"img":false}]}
{"op":"mcm","clk":"5348963165","pt":1646222503836,"mc":[{"id":"1.195453681","rc":[{"atl":[[2.24,0],[2.18,20.47]],"id":40917619}],"con":true,"img":false}]}
{"op":"mcm","clk":"5348963181","pt":1646222504046,"mc":[{"id":"1.195453681","rc":[{"atl":[[2.2,10.18]],"id":40917619}],"con":true,"img":false}]}
{"op":"mcm","clk":"5348963187","pt":1646222504148,"mc":[{"id":"1.195453681","rc":[{"atl":[[2.16,10.24]],"id":40917619}],"con":true,"img":false}]}
{"op":"mcm","clk":"5348963193","pt":1646222504253,"mc":[{"id":"1.195453681","rc":[{"atl":[[2.4,0]],"id":40917619}],"con":true,"img":false}]}
{"op":"mcm","clk":"5348963201","pt":1646222504355,"mc":[{"id":"1.195453681","rc":[{"atl":[[2.18,0],[2.14,2]],"id":40917619}],"con":true,"img":false}]}
{"op":"mcm","clk":"5348963207","pt":1646222504459,"mc":[{"id":"1.195453681","rc":[{"atl":[[2.18,29.29]],"id":40917619}],"con":true,"img":false}]}
{"op":"mcm","clk":"5348963245","pt":1646222504876,"mc":[{"id":"1.195453681","rc":[{"atl":[[2.18,0]],"id":40917619}],"con":true,"img":false}]}
{"op":"mcm","clk":"5348963256","pt":1646222504980,"mc":[{"id":"1.195453681","rc":[{"atl":[[2.14,31.29]],"id":40917619}],"con":true,"img":false}]}
{"op":"mcm","clk":"5348963278","pt":1646222505239,"mc":[{"id":"1.195453681","rc":[{"atb":[[1.7,2.84]],"id":40917619},{"atl":[[2.12,10.24]],"id":40917619},{"atb":[[2.06,2.84]],"id":38554545},{"atl":[[2.44,11]],"id":38554545}],"con":true,"img":false}]}
{"op":"mcm","clk":"5348963287","pt":1646222505343,"mc":[{"id":"1.195453681","rc":[{"atl":[[2.36,0]],"id":40917619}],"con":true,"img":false}]}
{"op":"mcm","clk":"5348963296","pt":1646222505451,"mc":[{"id":"1.195453681","rc":[{"atb":[[1.7,44.49]],"id":40917619},{"atl":[[2.14,6]],"id":40917619}],"con":true,"img":false}]}
{"op":"mcm","clk":"5348963336","pt":1646222505869,"mc":[{"id":"1.195453681","rc":[{"atl":[[2.14,2]],"id":40917619}],"con":true,"img":false}]}
{"op":"mcm","clk":"5348963364","pt":1646222506281,"mc":[{"id":"1.195453681","rc":[{"atl":[[2.12,30.74]],"id":40917619}],"con":true,"img":false}]}
{"op":"mcm","clk":"5348963395","pt":1646222506650,"mc":[{"id":"1.195453681","rc":[{"atb":[[2.02,1.42]],"id":38554545},{"atl":[[2.5,1.42]],"id":38554545}],"con":true,"img":false}]}
{"op":"mcm","clk":"5348963402","pt":1646222506754,"mc":[{"id":"1.195453681","rc":[{"atl":[[2.1,10.26]],"id":40917619}],"con":true,"img":false}]}
{"op":"mcm","clk":"5348963411","pt":1646222506855,"mc":[{"id":"1.195453681","rc":[{"atl":[[2.32,0]],"id":40917619}],"con":true,"img":false}]}
{"op":"mcm","clk":"5348963425","pt":1646222507058,"mc":[{"id":"1.195453681","rc":[{"atl":[[2.12,10.24]],"id":40917619}],"con":true,"img":false}]}
{"op":"mcm","clk":"5348963457","pt":1646222507483,"mc":[{"id":"1.195453681","rc":[{"atl":[[2.1,30.8]],"id":40917619}],"con":true,"img":false}]}
{"op":"mcm","clk":"5348963633","pt":1646222509458,"mc":[{"id":"1.195453681","rc":[{"atl":[[2.08,2]],"id":40917619}],"con":true,"img":false}]}
{"op":"mcm","clk":"5348963637","pt":1646222509557,"mc":[{"id":"1.195453681","rc":[{"atl":[[2.14,0]],"id":40917619}],"con":true,"img":false}]}
{"op":"mcm","clk":"5348963660","pt":1646222509883,"mc":[{"id":"1.195453681","rc":[{"atl":[[2.1,10.26]],"id":40917619}],"con":true,"img":false}]}
{"op":"mcm","clk":"5348963670","pt":1646222509980,"mc":[{"id":"1.195453681","rc":[{"atl":[[2.08,22.54]],"id":40917619}],"con":true,"img":false}]}
{"op":"mcm","clk":"5348963692","pt":1646222510251,"mc":[{"id":"1.195453681","rc":[{"atb":[[1.72,1.42]],"id":40917619},{"atl":[[2.42,1.42]],"id":38554545}],"con":true,"img":false}]}
{"op":"mcm","clk":"5348963701","pt":1646222510354,"mc":[{"id":"1.195453681","rc":[{"atl":[[2.08,6]],"id":40917619}],"con":true,"img":false}]}
{"op":"mcm","clk":"5348963721","pt":1646222510557,"mc":[{"id":"1.195453681","rc":[{"atl":[[2.42,9.61]],"id":38554545}],"con":true,"img":false}]}
{"op":"mcm","clk":"5348963738","pt":1646222510770,"mc":[{"id":"1.195453681","rc":[{"atl":[[2.3,0],[2.06,10.28]],"id":40917619}],"con":true,"img":false}]}
{"op":"mcm","clk":"5348963766","pt":1646222511237,"mc":[{"id":"1.195453681","rc":[{"atl":[[2.08,2]],"id":40917619}],"con":true,"img":false}]}
{"op":"mcm","clk":"5348963796","pt":1646222511655,"mc":[{"id":"1.195453681","rc":[{"atl":[[2.06,30.86]],"id":40917619}],"con":true,"img":false}]}
{"op":"mcm","clk":"5348963800","pt":1646222511763,"mc":[{"id":"1.195453681","rc":[{"atb":[[1.72,2.84]],"id":40917619},{"atl":[[2.42,11.03]],"id":38554545}],"con":true,"img":false}]}
{"op":"mcm","clk":"5348963850","pt":1646222512447,"mc":[{"id":"1.195453681","rc":[{"atl":[[2.4,8.15]],"id":38554545}],"con":true,"img":false}]}
{"op":"mcm","clk":"5348963861","pt":1646222512559,"mc":[{"id":"1.195453681","rc":[{"atl":[[2.48,0]],"id":38554545}],"con":true,"img":false}]}
{"op":"mcm","clk":"5348963884","pt":1646222512766,"mc":[{"id":"1.195453681","rc":[{"atb":[[1.66,0],[1.76,0]],"id":40917619},{"atl":[[2.04,10.28],[2.26,10.29]],"id":40917619},{"atb":[[1.6,0],[1.7,0],[1.5,0]],"id":38554545}],"con":true,"img":false}]}
{"op":"mcm","clk":"5348963917","pt":1646222513192,"mc":[{"id":"1.195453681","rc":[{"atl":[[2.06,10.28]],"id":40917619}],"con":true,"img":false}]}
{"op":"mcm","clk":"5348963924","pt":1646222513285,"mc":[{"id":"1.195453681","rc":[{"atl":[[2.04,30.86]],"id":40917619}],"con":true,"img":false}]}
{"op":"mcm","clk":"5348964031","pt":1646222514694,"mc":[{"id":"1.195453681","rc":[{"atl":[[2.02,20.58]],"id":40917619}],"con":true,"img":false}]}
{"op":"mcm","clk":"5348964050","pt":1646222514844,"mc":[{"id":"1.195453681","rc":[{"atl":[[2.08,0]],"id":40917619}],"con":true,"img":false}]}
{"op":"mcm","clk":"5348964065","pt":1646222515056,"mc":[{"id":"1.195453681","rc":[{"atl":[[2.04,10.28]],"id":40917619}],"con":true,"img":false}]}
{"op":"mcm","clk":"5348964073","pt":1646222515161,"mc":[{"id":"1.195453681","rc":[{"atl":[[2.02,41.16]],"id":40917619}],"con":true,"img":false}]}
{"op":"mcm","clk":"5348964081","pt":1646222515269,"mc":[{"id":"1.195453681","rc":[{"atb":[[1.6,0],[1.71,1.42]],"id":40917619},{"atl":[[2.56,0],[2.38,1.42]],"id":38554545}],"con":true,"img":false}]}
{"op":"mcm","clk":"5348964094","pt":1646222515478,"mc":[{"id":"1.195453681","rc":[{"atb":[[1.57,20.58]],"id":40917619},{"atl":[[2.64,22.05]],"id":38554545}],"con":true,"img":false}]}
{"op":"mcm","clk":"5348964108","pt":1646222515683,"mc":[{"id":"1.195453681","rc":[{"atl":[[2,10.35],[2.2,0]],"id":40917619},{"atb":[[2.04,28.02],[2.2,8.16]],"id":38554545}],"con":true,"img":false}]}
{"op":"mcm","clk":"5348964123","pt":1646222515890,"mc":[{"id":"1.195453681","rc":[{"atb":[[2.22,16.31],[2.18,6.95]],"id":38554545}],"con":true,"img":false}]}
{"op":"mcm","clk":"5348964129","pt":1646222515992,"mc":[{"id":"1.195453681","rc":[{"atb":[[2.04,0]],"id":38554545}],"con":true,"img":false}]}
{"op":"mcm","clk":"5348964146","pt":1646222516150,"mc":[{"id":"1.195453681","rc":[{"atl":[[2.02,20.58]],"id":40917619},{"atb":[[2.18,0]],"id":38554545}],"con":true,"img":false}]}
{"op":"mcm","clk":"5348964152","pt":1646222516256,"mc":[{"id":"1.195453681","rc":[{"atl":[[2,30.93]],"id":40917619},{"atb":[[2.2,15.12]],"id":38554545}],"con":true,"img":false}]}
{"op":"mcm","clk":"5348964156","pt":1646222516359,"mc":[{"id":"1.195453681","rc":[{"atl":[[2.38,9.51],[2.46,0]],"id":38554545}],"con":true,"img":false}]}
{"op":"mcm","clk":"5348964164","pt":1646222516464,"mc":[{"id":"1.195453681","rc":[{"atb":[[2.22,40.2]],"id":38554545}],"con":true,"img":false}]}
{"op":"mcm","clk":"5348964179","pt":1646222516672,"mc":[{"id":"1.195453681","rc":[{"atb":[[1.78,0]],"id":40917619},{"atl":[[1.99,10.39],[2.1,0]],"id":40917619}],"con":true,"img":false}]}
{"op":"mcm","clk":"5348964197","pt":1646222516983,"mc":[{"id":"1.195453681","rc":[{"atl":[[2.38,10.93]],"id":38554545}],"con":true,"img":false}]}
{"op":"mcm","clk":"5348964216","pt":1646222517295,"mc":[{"id":"1.195453681","rc":[{"atl":[[2,10.35]],"id":40917619}],"con":true,"img":false}]}
{"op":"mcm","clk":"5348964222","pt":1646222517396,"mc":[{"id":"1.195453681","rc":[{"atl":[[1.99,30.97]],"id":40917619},{"atl":[[2.44,2.84],[2.36,8.06]],"id":38554545}],"con":true,"img":false}]}
{"op":"mcm","clk":"5348964228","pt":1646222517453,"mc":[{"id":"1.195453681","rc":[{"atb":[[1.65,0]],"id":40917619},{"atb":[[2.22,16.31],[2.2,39.42]],"id":38554545}],"con":true,"img":false}]}
{"op":"mcm","clk":"5348964306","pt":1646222518495,"mc":[{"id":"1.195453681","rc":[{"atl":[[2.06,0],[1.98,10.43]],"id":40917619},{"atb":[[2.22,24.4]],"id":38554545}],"con":true,"img":false}]}
{"op":"mcm","clk":"5348964315","pt":1646222518601,"mc":[{"id":"1.195453681","rc":[{"atb":[[2.08,26.99]],"id":38554545}],"con":true,"img":false}]}
{"op":"mcm","clk":"5348964338","pt":1646222518863,"mc":[{"id":"1.195453681","rc":[{"atl":[[1.99,10.39]],"id":40917619}],"con":true,"img":false}]}
{"op":"mcm","clk":"5348964345","pt":1646222518972,"mc":[{"id":"1.195453681","rc":[{"atb":[[1.72,43.33]],"id":40917619},{"atl":[[1.98,31.01]],"id":40917619},{"atb":[[2.08,0]],"id":38554545}],"con":true,"img":false}]}
{"op":"mcm","clk":"5348964356","pt":1646222519076,"mc":[{"id":"1.195453681","rc":[{"atl":[[2.5,0]],"id":38554545}],"con":true,"img":false}]}
{"op":"mcm","clk":"5348964375","pt":1646222519282,"mc":[{"id":"1.195453681","rc":[{"atb":[[1.77,0]],"id":40917619},{"atl":[[1.97,10.5],[2.04,0]],"id":40917619}],"con":true,"img":false}]}
{"op":"mcm","clk":"5348964418","pt":1646222519801,"mc":[{"id":"1.195453681","rc":[{"atl":[[1.98,10.43],[1.96,41.53]],"id":40917619}],"con":true,"img":false}]}
{"op":"mcm","clk":"5348964428","pt":1646222519900,"mc":[{"id":"1.195453681","rc":[{"atl":[[2.02,0],[1.97,31.08]],"id":40917619}],"con":true,"img":false}]}
{"op":"mcm","clk":"5348964438","pt":1646222520004,"mc":[{"id":"1.195453681","rc":[{"atb":[[2.22,48.3]],"id":38554545}],"con":true,"img":false}]}
{"op":"mcm","clk":"5348964468","pt":1646222520379,"mc":[{"id":"1.195453681","rc":[{"atl":[[1.97,10.5]],"id":40917619}],"con":true,"img":false}]}
{"op":"mcm","clk":"5348964476","pt":1646222520478,"mc":[{"id":"1.195453681","rc":[{"atl":[[1.96,62.11]],"id":40917619}],"con":true,"img":false}]}
{"op":"mcm","clk":"5348964501","pt":1646222520794,"mc":[{"id":"1.195453681","rc":[{"atl":[[2,0],[1.95,10.52]],"id":40917619}],"con":true,"img":false}]}
{"op":"mcm","clk":"5348964547","pt":1646222521261,"mc":[{"id":"1.195453681","rc":[{"atl":[[1.96,41.53]],"id":40917619}],"con":true,"img":false}]}
{"op":"mcm","clk":"5348964557","pt":1646222521371,"mc":[{"id":"1.195453681","rc":[{"atl":[[1.95,31.1]],"id":40917619}],"con":true,"img":false}]}
{"op":"mcm","clk":"5348964578","pt":1646222521579,"mc":[{"id":"1.195453681","rc":[{"atb":[[2.24,8]],"id":38554545}],"con":true,"img":false}]}
{"op":"mcm","clk":"5348964582","pt":1646222521685,"mc":[{"id":"1.195453681","rc":[{"atl":[[1.94,21.14]],"id":40917619}],"con":true,"img":false}]}
{"op":"mcm","clk":"5348964590","pt":1646222521787,"mc":[{"id":"1.195453681","rc":[{"atl":[[1.99,0],[2.26,0]],"id":40917619},{"atb":[[2.22,31.99],[2.12,8.2],[2.26,19.08]],"id":38554545}],"con":true,"img":false}]}
{"op":"mcm","clk":"5348964604","pt":1646222521988,"mc":[{"id":"1.195453681","rc":[{"atb":[[2.16,8.3]],"id":38554545}],"con":true,"img":false}]}
{"op":"mcm","clk":"5348964611","pt":1646222522094,"mc":[{"id":"1.195453681","rc":[{"atl":[[1.95,10.52]],"id":40917619}],"con":true,"img":false}]}
{"op":"mcm","clk":"5348964632","pt":1646222522203,"mc":[{"id":"1.195453681","rc":[{"atl":[[1.94,41.72]],"id":40917619}],"con":true,"img":false}]}
{"op":"mcm","clk":"5348964641","pt":1646222522300,"mc":[{"id":"1.195453681","rc":[{"atb":[[1.67,1.42]],"id":40917619},{"atb":[[2.08,1.42]],"id":38554545},{"atl":[[2.46,1.42]],"id":38554545}],"con":true,"img":false}]}
{"op":"mcm","clk":"5348964704","pt":1646222523099,"mc":[{"id":"1.195453681","rc":[{"atb":[[1.6,8.99],[1.7,52.19]],"id":40917619},{"trd":[[1.8,6.74]],"ltp":1.8,"tv":6.74,"id":40917619},{"atb":[[1.6,8.99],[1.7,7.7],[2.26,13.7],[1.8,6.74]],"id":38554545},{"trd":[[2.26,5.37]],"ltp":2.26,"tv":5.37,"id":38554545}],"con":true,"img":false}]}
{"op":"mcm","clk":"5348964718","pt":1646222523296,"mc":[{"id":"1.195453681","rc":[{"atb":[[1.73,10.76]],"id":40917619}],"con":true,"img":false}]}
{"op":"mcm","clk":"5348964727","pt":1646222523403,"mc":[{"id":"1.195453681","rc":[{"atb":[[2.26,0]],"id":38554545}],"con":true,"img":false}]}
{"op":"mcm","clk":"5348964774","pt":1646222523987,"mc":[{"id":"1.195453681","rc":[{"atb":[[2.22,8.09]],"id":38554545}],"con":true,"img":false}]}
{"op":"mcm","clk":"5348964780","pt":1646222524088,"mc":[{"id":"1.195453681","rc":[{"atb":[[1.66,1.42]],"id":40917619},{"atl":[[1.88,1.42]],"id":40917619},{"atb":[[2.18,1.42]],"id":38554545},{"atl":[[2.5,1.42]],"id":38554545}],"con":true,"img":false}]}
{"op":"mcm","clk":"5348964848","pt":1646222524977,"mc":[{"id":"1.195453681","rc":[{"atl":[[1.88,22.71],[1.96,0]],"id":40917619}],"con":true,"img":false}]}
{"op":"mcm","clk":"5348964870","pt":1646222525289,"mc":[{"id":"1.195453681","rc":[{"atl":[[1.98,0],[1.87,10.82]],"id":40917619},{"atl":[[2.36,0]],"id":38554545}],"con":true,"img":false}]}
{"op":"mcm","clk":"5348964882","pt":1646222525500,"mc":[{"id":"1.195453681","rc":[{"atb":[[1.73,0]],"id":40917619}],"con":true,"img":false}]}
{"op":"mcm","clk":"5348964890","pt":1646222525598,"mc":[{"id":"1.195453681","rc":[{"atb":[[1.65,1.42]],"id":40917619},{"atb":[[2.1,1.42]],"id":38554545},{"atl":[[2.52,1.42]],"id":38554545}],"con":true,"img":false}]}
{"op":"mcm","clk":"5348964920","pt":1646222526018,"mc":[{"id":"1.195453681","rc":[{"atb":[[1.72,2.84]],"id":40917619}],"con":true,"img":false}]}
{"op":"mcm","clk":"5348964927","pt":1646222526076,"mc":[{"id":"1.195453681","rc":[{"atl":[[2.38,2.84]],"id":38554545}],"con":true,"img":false}]}
{"op":"mcm","clk":"5348964936","pt":1646222526177,"mc":[{"id":"1.195453681","rc":[{"atb":[[1.71,12.45]],"id":40917619}],"con":true,"img":false}]}
{"op":"mcm","clk":"5348964943","pt":1646222526280,"mc":[{"id":"1.195453681","rc":[{"atl":[[1.88,21.29]],"id":40917619},{"atb":[[2.18,0]],"id":38554545}],"con":true,"img":false}]}
{"op":"mcm","clk":"5348965005","pt":1646222527008,"mc":[{"id":"1.195453681","rc":[{"atb":[[1.65,2.84]],"id":40917619},{"atl":[[2.52,2.84]],"id":38554545}],"con":true,"img":false}]}
{"op":"mcm","clk":"5348965047","pt":1646222527537,"mc":[{"id":"1.195453681","rc":[{"atb":[[1.72,13.87]],"id":40917619}],"con":true,"img":false}]}
{"op":"mcm","clk":"5348965059","pt":1646222527697,"mc":[{"id":"1.195453681","rc":[{"atl":[[2.38,10.59]],"id":38554545}],"con":true,"img":false}]}
{"op":"mcm","clk":"5348965085","pt":1646222528005,"mc":[{"id":"1.195453681","rc":[{"atb":[[1.72,54.36]],"id":40917619}],"con":true,"img":false}]}
{"op":"mcm","clk":"5348965096","pt":1646222528108,"mc":[{"id":"1.195453681","rc":[{"atl":[[2.46,0]],"id":38554545}],"con":true,"img":false}]}
{"op":"mcm","clk":"5348965158","pt":1646222528686,"mc":[{"id":"1.195453681","rc":[{"atl":[[1.83,1.42]],"id":40917619}],"con":true,"img":false}]}
{"op":"mcm","clk":"5348965286","pt":1646222530094,"mc":[{"id":"1.195453681","rc":[{"atl":[[1.83,55.61],[1.88,0]],"id":40917619}],"con":true,"img":false}]}
{"op":"mcm","clk":"5348965481","pt":1646222531911,"mc":[{"id":"1.195453681","rc":[{"atl":[[1.83,57.03]],"id":40917619},{"atl":[[2.46,1.42]],"id":38554545}],"con":true,"img":false}]}
{"op":"mcm","clk":"5348965577","pt":1646222533109,"mc":[{"id":"1.195453681","rc":[{"atl":[[1.82,21.82]],"id":40917619}],"con":true,"img":false}]}
{"op":"mcm","clk":"5348965585","pt":1646222533213,"mc":[{"id":"1.195453681","rc":[{"atl":[[1.97,0],[2.22,0]],"id":40917619}],"con":true,"img":false}]}
{"op":"mcm","clk":"5348965618","pt":1646222533577,"mc":[{"id":"1.195453681","rc":[{"atl":[[1.89,1.42]],"id":40917619},{"atb":[[2.18,1.42]],"id":38554545},{"atl":[[2.46,2.84]],"id":38554545}],"con":true,"img":false}]}
{"op":"mcm","clk":"5348965640","pt":1646222533790,"mc":[{"id":"1.195453681","rc":[{"atb":[[1.72,43.33]],"id":40917619},{"atl":[[2.38,2.84]],"id":38554545}],"con":true,"img":false}]}
{"op":"mcm","clk":"5348965655","pt":1646222533996,"mc":[{"id":"1.195453681","rc":[{"atb":[[1.72,2.84]],"id":40917619}],"con":true,"img":false}]}
{"op":"mcm","clk":"5348965700","pt":1646222534615,"mc":[{"id":"1.195453681","rc":[{"atb":[[1.72,8.52]],"id":40917619},{"atl":[[2.38,7.82]],"id":38554545}],"con":true,"img":false}]}
{"op":"mcm","clk":"5348965766","pt":1646222535301,"mc":[{"id":"1.195453681","rc":[{"atl":[[1.83,2.84],[1.81,23.29]],"id":40917619}],"con":true,"img":false}]}
{"op":"mcm","clk":"5348965796","pt":1646222535711,"mc":[{"id":"1.195453681","rc":[{"atl":[[1.85,1.42]],"id":40917619},{"atb":[[2.18,2.84]],"id":38554545}],"con":true,"img":false}]}
{"op":"mcm","clk":"5348965827","pt":1646222536026,"mc":[{"id":"1.195453681","rc":[{"atb":[[1.72,49.01]],"id":40917619},{"atb":[[2.22,31.99]],"id":38554545}],"con":true,"img":false}]}
{"op":"mcm","clk":"5348965941","pt":1646222536720,"mc":[{"id":"1.195453681","rc":[{"atb":[[1.72,43.33]],"id":40917619},{"atl":[[2.38,2.84]],"id":38554545}],"con":true,"img":false}]}
{"op":"mcm","clk":"5348965966","pt":1646222536987,"mc":[{"id":"1.195453681","rc":[{"atb":[[1.72,2.84]],"id":40917619}],"con":true,"img":false}]}
{"op":"mcm","clk":"5348966046","pt":1646222537927,"mc":[{"id":"1.195453681","rc":[{"atl":[[1.86,1.42]],"id":40917619}],"con":true,"img":false}]}
{"op":"mcm","clk":"5348966069","pt":1646222538137,"mc":[{"id":"1.195453681","rc":[{"atb":[[1.73,10.92]],"id":40917619},{"atl":[[2.38,10.62]],"id":38554545}],"con":true,"img":false}]}
{"op":"mcm","clk":"5348966107","pt":1646222538513,"mc":[{"id":"1.195453681","rc":[{"atb":[[1.72,43.33]],"id":40917619},{"atl":[[2.36,7.84]],"id":38554545}],"con":true,"img":false}]}
{"op":"mcm","clk":"5348966152","pt":1646222539023,"mc":[{"id":"1.195453681","rc":[{"atl":[[2.46,0]],"id":38554545}],"con":true,"img":false}]}
{"op":"mcm","clk":"5348966267","pt":1646222540319,"mc":[{"id":"1.195453681","rc":[{"atl":[[1.86,2.84]],"id":40917619}],"con":true,"img":false}]}
{"op":"mcm","clk":"5348966311","pt":1646222540793,"mc":[{"id":"1.195453681","rc":[{"atb":[[1.73,18.24]],"id":40917619}],"con":true,"img":false}]}
{"op":"mcm","clk":"5348966353","pt":1646222541324,"mc":[{"id":"1.195453681","rc":[{"atl":[[1.8,10.74]],"id":40917619}],"con":true,"img":false}]}
{"op":"mcm","clk":"5348966368","pt":1646222541529,"mc":[{"id":"1.195453681","rc":[{"atl":[[1.79,30.71],[1.81,0],[2.16,0]],"id":40917619}],"con":true,"img":false}]}
{"op":"mcm","clk":"5348966405","pt":1646222541995,"mc":[{"id":"1.195453681","rc":[{"atb":[[2.24,31.51]],"id":38554545}],"con":true,"img":false}]}
{"op":"mcm","clk":"5348966421","pt":1646222542201,"mc":[{"id":"1.195453681","rc":[{"atl":[[1.88,1.42]],"id":40917619},{"atl":[[2.46,1.42]],"id":38554545}],"con":true,"img":false}]}
{"op":"mcm","clk":"5348966462","pt":1646222542829,"mc":[{"id":"1.195453681","rc":[{"atb":[[2.26,7.89]],"id":38554545}],"con":true,"img":false}]}
{"op":"mcm","clk":"5348966471","pt":1646222542930,"mc":[{"id":"1.195453681","rc":[{"atb":[[1.73,10.92]],"id":40917619}],"con":true,"img":false}]}
{"op":"mcm","clk":"5348966480","pt":1646222543028,"mc":[{"id":"1.195453681","rc":[{"atb":[[2.16,0]],"id":38554545}],"con":true,"img":false}]}
{"op":"mcm","clk":"5348966784","pt":1646222546940,"mc":[{"id":"1.195453681","rc":[{"atb":[[1.73,0]],"id":40917619},{"atl":[[1.78,10.84]],"id":40917619},{"atl":[[2.36,0]],"id":38554545}],"con":true,"img":false}]}
{"op":"mcm","clk":"5348966795","pt":1646222547134,"mc":[{"id":"1.195453681","rc":[{"atl":[[2.12,0],[1.79,0],[1.77,34.28]],"id":40917619}],"con":true,"img":false}]}
{"op":"mcm","clk":"5348966803","pt":1646222547235,"mc":[{"id":"1.195453681","rc":[{"atl":[[1.94,21.14]],"id":40917619},{"atb":[[2.2,32.46]],"id":38554545}],"con":true,"img":false}]}
{"op":"mcm","clk":"5348966811","pt":1646222547349,"mc":[{"id":"1.195453681","rc":[{"atl":[[1.79,20.58]],"id":40917619},{"atb":[[2.26,14.85]],"id":38554545}],"con":true,"img":false}]}
{"op":"mcm","clk":"5348966831","pt":1646222547497,"mc":[{"id":"1.195453681","rc":[{"atb":[[1.72,2.84],[1.71,53.52]],"id":40917619},{"atb":[[2.2,8.16]],"id":38554545}],"con":true,"img":false}]}
{"op":"mcm","clk":"5348966865","pt":1646222548018,"mc":[{"id":"1.195453681","rc":[{"atb":[[1.71,12.45]],"id":40917619}],"con":true,"img":false}]}
{"op":"mcm","clk":"5348966880","pt":1646222548231,"mc":[{"id":"1.195453681","rc":[{"atb":[[2.28,7.82],[2.2,0]],"id":38554545}],"con":true,"img":false}]}
{"op":"mcm","clk":"5348966905","pt":1646222548549,"mc":[{"id":"1.195453681","rc":[{"atb":[[2.26,37.99]],"id":38554545}],"con":true,"img":false}]}
{"op":"mcm","clk":"5348966941","pt":1646222549215,"mc":[{"id":"1.195453681","rc":[{"atb":[[2.26,31.03]],"id":38554545}],"con":true,"img":false}]}
{"op":"mcm","clk":"5348966948","pt":1646222549321,"mc":[{"id":"1.195453681","rc":[{"atb":[[2.28,14.78]],"id":38554545}],"con":true,"img":false}]}
{"op":"mcm","clk":"5348967277","pt":1646222553534,"mc":[{"id":"1.195453681","rc":[{"atb":[[1.63,1.42]],"id":40917619},{"atl":[[1.84,1.42]],"id":40917619},{"atb":[[2.28,7.82]],"id":38554545},{"atl":[[2.56,1.42]],"id":38554545}],"con":true,"img":false}]}
{"op":"mcm","clk":"5348967287","pt":1646222553741,"mc":[{"id":"1.195453681","rc":[{"atb":[[1.72,13.79]],"id":40917619}],"con":true,"img":false}]}
{"op":"mcm","clk":"5348967314","pt":1646222554061,"mc":[{"id":"1.195453681","rc":[{"atb":[[1.71,53.52]],"id":40917619}],"con":true,"img":false}]}
{"op":"mcm","clk":"5348967501","pt":1646222556211,"mc":[{"id":"1.195453681","rc":[{"atl":[[1.78,12.84],[1.77,0]],"id":40917619}],"con":true,"img":false}]}
{"op":"mcm","clk":"5348967525","pt":1646222556525,"mc":[{"id":"1.195453681","rc":[{"atb":[[2.26,7.89]],"id":38554545}],"con":true,"img":false}]}
{"op":"mcm","clk":"5348967925","pt":1646222561433,"mc":[{"id":"1.195453681","rc":[{"atl":[[1.78,10.84],[1.79,22.58]],"id":40917619}],"con":true,"img":false}]}
{"op":"mcm","clk":"5348968625","pt":1646222569557,"mc":[{"id":"1.195453681","rc":[{"atb":[[1.73,10.86]],"id":40917619},{"atl":[[1.78,0]],"id":40917619},{"atb":[[2.28,0]],"id":38554545},{"atl":[[2.36,7.83]],"id":38554545}],"con":true,"img":false}]}
{"op":"mcm","clk":"5348968664","pt":1646222569931,"mc":[{"id":"1.195453681","rc":[{"atl":[[1.79,2]],"id":40917619},{"atb":[[2.26,13.38]],"id":38554545}],"con":true,"img":false}]}
{"op":"mcm","clk":"5348968670","pt":1646222570039,"mc":[{"id":"1.195453681","rc":[{"atb":[[1.68,0]],"id":40917619}],"con":true,"img":false}]}
{"op":"mcm","clk":"5348968682","pt":1646222570143,"mc":[{"id":"1.195453681","rc":[{"atl":[[1.79,12.7]],"id":40917619}],"con":true,"img":false}]}
{"op":"mcm","clk":"5348968725","pt":1646222570552,"mc":[{"id":"1.195453681","rc":[{"atl":[[1.79,16.7]],"id":40917619}],"con":true,"img":false}]}
{"op":"mcm","clk":"5348968775","pt":1646222571029,"mc":[{"id":"1.195453681","rc":[{"atb":[[1.72,54.28]],"id":40917619}],"con":true,"img":false}]}
{"op":"mcm","clk":"5348968811","pt":1646222571445,"mc":[{"id":"1.195453681","rc":[{"atb":[[2.28,7.87]],"id":38554545}],"con":true,"img":false}]}
{"op":"mcm","clk":"5348968827","pt":1646222571657,"mc":[{"id":"1.195453681","rc":[{"atl":[[1.78,10.79]],"id":40917619},{"atl":[[2.36,0]],"id":38554545}],"con":true,"img":false}]}
{"op":"mcm","clk":"5348968836","pt":1646222571754,"mc":[{"id":"1.195453681","rc":[{"atb":[[1.73,0]],"id":40917619},{"atl":[[1.94,10.57]],"id":40917619}],"con":true,"img":false}]}
{"op":"mcm","clk":"5348968841","pt":1646222571859,"mc":[{"id":"1.195453681","rc":[{"atb":[[2.26,7.89]],"id":38554545}],"con":true,"img":false}]}
{"op":"mcm","clk":"5348968856","pt":1646222572076,"mc":[{"id":"1.195453681","rc":[{"atb":[[1.72,13.79]],"id":40917619},{"atl":[[1.79,12.7]],"id":40917619}],"con":true,"img":false}]}
{"op":"mcm","clk":"5348968870","pt":1646222572232,"mc":[{"id":"1.195453681","rc":[{"atb":[[2.28,16.24]],"id":38554545}],"con":true,"img":false}]}
{"op":"mcm","clk":"5348968889","pt":1646222572542,"mc":[{"id":"1.195453681","rc":[{"atl":[[1.78,21.4]],"id":40917619}],"con":true,"img":false}]}
{"op":"mcm","clk":"5348968927","pt":1646222573061,"mc":[{"id":"1.195453681","rc":[{"atb":[[2.26,31.03]],"id":38554545}],"con":true,"img":false}]}
{"op":"mcm","clk":"5348969185","pt":1646222575934,"mc":[{"id":"1.195453681","rc":[{"atl":[[1.77,10.88]],"id":40917619}],"con":true,"img":false}]}
{"op":"mcm","clk":"5348969191","pt":1646222576036,"mc":[{"id":"1.195453681","rc":[{"atl":[[1.82,10.91],[1.77,0]],"id":40917619}],"con":true,"img":false}]}
{"op":"mcm","clk":"5348969200","pt":1646222576146,"mc":[{"id":"1.195453681","rc":[{"atb":[[2.3,7.8],[2.22,23.89]],"id":38554545}],"con":true,"img":false}]}
{"op":"mcm","clk":"5348969208","pt":1646222576343,"mc":[{"id":"1.195453681","rc":[{"atl":[[1.78,10.79],[1.77,10.92]],"id":40917619},{"atl":[[2.38,2.84]],"id":38554545}],"con":true,"img":false}]}
{"op":"mcm","clk":"5348969278","pt":1646222577493,"mc":[{"id":"1.195453681","rc":[{"atb":[[1.6,0],[1.7,44.49]],"id":40917619},{"atb":[[1.6,0],[1.7,0],[1.8,0]],"id":38554545}],"con":true,"img":false}]}
{"op":"mcm","clk":"5348969355","pt":1646222578434,"mc":[{"id":"1.195453681","rc":[{"atb":[[1.72,2.84]],"id":40917619},{"atl":[[2.48,1.42]],"id":38554545}],"con":true,"img":false}]}
{"op":"mcm","clk":"5348969393","pt":1646222578957,"mc":[{"id":"1.195453681","rc":[{"atb":[[1.71,12.45]],"id":40917619}],"con":true,"img":false}]}
{"op":"mcm","clk":"5348969419","pt":1646222579270,"mc":[{"id":"1.195453681","rc":[{"atl":[[2.4,0]],"id":38554545}],"con":true,"img":false}]}
{"op":"mcm","clk":"5348969433","pt":1646222579481,"mc":[{"id":"1.195453681","rc":[{"atb":[[1.71,1.42]],"id":40917619},{"atl":[[2.42,2.84]],"id":38554545}],"con":true,"img":false}]}
{"op":"mcm","clk":"5348969438","pt":1646222579580,"mc":[{"id":"1.195453681","rc":[{"atb":[[2.22,0]],"id":38554545}],"con":true,"img":false}]}
{"op":"mcm","clk":"5348969443","pt":1646222579640,"mc":[{"id":"1.195453681","rc":[{"atl":[[2.44,0]],"id":38554545}],"con":true,"img":false}]}
{"op":"mcm","clk":"5348969470","pt":1646222580056,"mc":[{"id":"1.195453681","rc":[{"atb":[[1.7,2.84],[1.61,47.79]],"id":40917619},{"atb":[[2.22,23.89],[2.26,7.89],[2.24,8]],"id":38554545}],"con":true,"img":false}]}
{"op":"mcm","clk":"5348969513","pt":1646222580571,"mc":[{"id":"1.195453681","rc":[{"atl":[[1.77,21.63]],"id":40917619}],"con":true,"img":false}]}
{"op":"mcm","clk":"5348969522","pt":1646222580676,"mc":[{"id":"1.195453681","rc":[{"atb":[[2.28,7.87]],"id":38554545}],"con":true,"img":false}]}
{"op":"mcm","clk":"5348969531","pt":1646222580781,"mc":[{"id":"1.195453681","rc":[{"atb":[[2.3,16.17]],"id":38554545}],"con":true,"img":false}]}
{"op":"mcm","clk":"5348969559","pt":1646222581051,"mc":[{"id":"1.195453681","rc":[{"atb":[[1.64,54.14]],"id":40917619},{"atl":[[1.76,11.21]],"id":40917619},{"atb":[[2.32,7.61]],"id":38554545}],"con":true,"img":false}]}
{"op":"mcm","clk":"5348969571","pt":1646222581162,"mc":[{"id":"1.195453681","rc":[{"atb":[[2.3,7.8]],"id":38554545}],"con":true,"img":false}]}
{"op":"mcm","clk":"5348969587","pt":1646222581271,"mc":[{"id":"1.195453681","rc":[{"atl":[[1.8,0]],"id":40917619},{"atb":[[2.24,0]],"id":38554545}],"con":true,"img":false}]}
{"op":"mcm","clk":"5348969609","pt":1646222581477,"mc":[{"id":"1.195453681","rc":[{"atb":[[1.64,8.59],[1.61,0]],"id":40917619},{"atb":[[2.22,0]],"id":38554545}],"con":true,"img":false}]}
{"op":"mcm","clk":"5348969615","pt":1646222581579,"mc":[{"id":"1.195453681","rc":[{"atb":[[1.6,8.99],[1.7,10.55]],"id":40917619},{"atl":[[1.76,4.46],[1.77,10.92]],"id":40917619},{"trd":[[1.76,13.49]],"ltp":1.76,"tv":13.49,"id":40917619},{"atb":[[1.6,8.99],[1.7,7.7],[1.8,6.74]],"id":38554545}],"con":true,"img":false}]}
{"op":"mcm","clk":"5348969632","pt":1646222581699,"mc":[{"id":"1.195453681","rc":[{"atl":[[1.76,15.17]],"id":40917619},{"atb":[[2.32,14.88]],"id":38554545}],"con":true,"img":false}]}
{"op":"mcm","clk":"5348969636","pt":1646222581739,"mc":[{"id":"1.195453681","rc":[{"atb":[[1.67,12.78]],"id":40917619},{"atl":[[2.46,8.96]],"id":38554545}],"con":true,"img":false}]}
{"op":"mcm","clk":"5348969655","pt":1646222581965,"mc":[{"id":"1.195453681","rc":[{"atb":[[1.68,42.87]],"id":40917619},{"atb":[[2.3,30.22]],"id":38554545}],"con":true,"img":false}]}
{"op":"mcm","clk":"5348969700","pt":1646222582486,"mc":[{"id":"1.195453681","rc":[{"atb":[[1.63,0],[1.67,11.36],[1.7,7.7],[1.66,0],[1.65,0],[1.71,0]],"id":40917619},{"atl":[[2.5,0],[2.48,0],[2.56,0],[2.42,0],[2.52,0],[2.46,7.53]],"id":38554545}],"con":true,"img":false}]}
{"op":"mcm","clk":"5348969727","pt":1646222582785,"mc":[{"id":"1.195453681","rc":[{"atl":[[1.79,2],[1.75,11.34]],"id":40917619},{"atb":[[2.26,0],[2.34,7.55]],"id":38554545}],"con":true,"img":false}]}
{"op":"mcm","clk":"5348969741","pt":1646222582944,"mc":[{"id":"1.195453681","rc":[{"atl":[[2.46,0]],"id":38554545}],"con":true,"img":false}]}
{"op":"mcm","clk":"5348969748","pt":1646222583043,"mc":[{"id":"1.195453681","rc":[{"atb":[[1.68,0],[1.65,44.85]],"id":40917619},{"atb":[[2.3,7.8],[2.24,23.51]],"id":38554545}],"con":true,"img":false}]}
{"op":"mcm","clk":"5348969765","pt":1646222583254,"mc":[{"id":"1.195453681","rc":[{"atb":[[1.72,0]],"id":40917619},{"trd":[[1.72,9.62]],"ltp":1.72,"tv":9.62,"id":40917619},{"atl":[[2.38,0]],"id":38554545},{"trd":[[2.38,2.83]],"ltp":2.38,"tv":2.83,"id":38554545}],"con":true,"img":false}]}
{"op":"mcm","clk":"5348969773","pt":1646222583359,"mc":[{"id":"1.195453681","rc":[{"atl":[[2.38,0]],"id":38554545},{"trd":[[2.38,2.85]],"ltp":2.38,"tv":2.85,"id":38554545}],"con":true,"img":false}]}
{"op":"mcm","clk":"5348969792","pt":1646222583569,"mc":[{"id":"1.195453681","rc":[{"atb":[[1.65,0]],"id":40917619},{"atl":[[2.64,0],[2.66,2]],"id":38554545}],"con":true,"img":false}]}
{"op":"mcm","clk":"5348969799","pt":1646222583673,"mc":[{"id":"1.195453681","rc":[{"atl":[[2.64,5.58]],"id":38554545}],"con":true,"img":false}]}
{"op":"mcm","clk":"5348969833","pt":1646222583991,"mc":[{"id":"1.195453681","rc":[{"atl":[[2.62,7.48]],"id":38554545}],"con":true,"img":false}]}
{"op":"mcm","clk":"5348969839","pt":1646222584088,"mc":[{"id":"1.195453681","rc":[{"atb":[[1.61,47.79]],"id":40917619},{"atb":[[2.26,23.13]],"id":38554545},{"atl":[[2.64,0]],"id":38554545}],"con":true,"img":false}]}
{"op":"mcm","clk":"5348969866","pt":1646222584354,"mc":[{"id":"1.195453681","rc":[{"atl":[[2.6,6.06]],"id":38554545}],"con":true,"img":false}]}
{"op":"mcm","clk":"5348969882","pt":1646222584557,"mc":[{"id":"1.195453681","rc":[{"atl":[[2.62,12.53]],"id":38554545}],"con":true,"img":false}]}
{"op":"mcm","clk":"5348969898","pt":1646222584773,"mc":[{"id":"1.195453681","rc":[{"atl":[[2.58,7.49]],"id":38554545}],"con":true,"img":false}]}
{"op":"mcm","clk":"5348969918","pt":1646222584988,"mc":[{"id":"1.195453681","rc":[{"atl":[[2.62,7.48]],"id":38554545}],"con":true,"img":false}]}
{"op":"mcm","clk":"5348969922","pt":1646222585105,"mc":[{"id":"1.195453681","rc":[{"atb":[[1.63,46.27]],"id":40917619},{"atb":[[2.34,29.3]],"id":38554545}],"con":true,"img":false}]}
{"op":"mcm","clk":"5348969932","pt":1646222585162,"mc":[{"id":"1.195453681","rc":[{"atl":[[2.6,11.11]],"id":38554545}],"con":true,"img":false}]}
{"op":"mcm","clk":"5348969960","pt":1646222585477,"mc":[{"id":"1.195453681","rc":[{"atb":[[2.36,7.54],[2.28,0]],"id":38554545}],"con":true,"img":false}]}
{"op":"mcm","clk":"5348970220","pt":1646222588558,"mc":[{"id":"1.195453681","rc":[{"atl":[[2.56,6.15],[2.6,5.05]],"id":38554545}],"con":true,"img":false}]}
{"op":"mcm","clk":"5348970236","pt":1646222588764,"mc":[{"id":"1.195453681","rc":[{"atl":[[2.54,7.57],[2.6,7.05],[2.66,0]],"id":38554545}],"con":true,"img":false}]}
{"op":"mcm","clk":"5348970250","pt":1646222588967,"mc":[{"id":"1.195453681","rc":[{"atb":[[1.65,44.85]],"id":40917619},{"atb":[[2.32,36.97],[2.34,7.55]],"id":38554545}],"con":true,"img":false}]}
{"op":"mcm","clk":"5348970298","pt":1646222589488,"mc":[{"id":"1.195453681","rc":[{"atl":[[2.56,0]],"id":38554545}],"con":true,"img":false}]}
{"op":"mcm","clk":"5348970351","pt":1646222590063,"mc":[{"id":"1.195453681","rc":[{"atb":[[1.65,0]],"id":40917619}],"con":true,"img":false}]}
{"op":"mcm","clk":"5348970426","pt":1646222590898,"mc":[{"id":"1.195453681","rc":[{"atb":[[2.22,1.42]],"id":38554545}],"con":true,"img":false}]}
{"op":"mcm","clk":"5348970569","pt":1646222592560,"mc":[{"id":"1.195453681","rc":[{"atl":[[2.52,6.25]],"id":38554545}],"con":true,"img":false}]}
{"op":"mcm","clk":"5348970575","pt":1646222592661,"mc":[{"id":"1.195453681","rc":[{"atl":[[2.5,7.47]],"id":38554545}],"con":true,"img":false}]}
{"op":"mcm","clk":"5348970604","pt":1646222592974,"mc":[{"id":"1.195453681","rc":[{"atb":[[1.65,44.85]],"id":40917619}],"con":true,"img":false}]}
{"op":"mcm","clk":"5348970617","pt":1646222593180,"mc":[{"id":"1.195453681","rc":[{"atl":[[1.76,4.46]],"id":40917619}],"con":true,"img":false}]}
{"op":"mcm","clk":"5348970623","pt":1646222593281,"mc":[{"id":"1.195453681","rc":[{"atl":[[1.75,22.05]],"id":40917619}],"con":true,"img":false}]}
{"op":"mcm","clk":"5348970630","pt":1646222593385,"mc":[{"id":"1.195453681","rc":[{"atl":[[2.52,7.67]],"id":38554545}],"con":true,"img":false}]}
{"op":"mcm","clk":"5348970700","pt":1646222594381,"mc":[{"id":"1.195453681","rc":[{"atl":[[2.52,1.42]],"id":38554545}],"con":true,"img":false}]}
{"op":"mcm","clk":"5348970774","pt":1646222595315,"mc":[{"id":"1.195453681","rc":[{"atl":[[1.75,11.34]],"id":40917619}],"con":true,"img":false}]}
{"op":"mcm","clk":"5348970869","pt":1646222596466,"mc":[{"id":"1.195453681","rc":[{"atl":[[2.48,6.35]],"id":38554545}],"con":true,"img":false}]}
{"op":"mcm","clk":"5348971013","pt":1646222598197,"mc":[{"id":"1.195453681","rc":[{"atl":[[2.62,0],[2.48,13.81]],"id":38554545}],"con":true,"img":false}]}
{"op":"mcm","clk":"5348971039","pt":1646222598507,"mc":[{"id":"1.195453681","rc":[{"atb":[[1.61,0]],"id":40917619}],"con":true,"img":false}]}
{"op":"mcm","clk":"5348971088","pt":1646222599083,"mc":[{"id":"1.195453681","rc":[{"atl":[[2.46,7.5]],"id":38554545}],"con":true,"img":false}]}
{"op":"mcm","clk":"5348971094","pt":1646222599191,"mc":[{"id":"1.195453681","rc":[{"atl":[[2.58,0]],"id":38554545}],"con":true,"img":false}]}
{"op":"mcm","clk":"5348971117","pt":1646222599499,"mc":[{"id":"1.195453681","rc":[{"atb":[[1.68,42.87]],"id":40917619},{"atb":[[2.32,14.88],[2.3,30.22]],"id":38554545},{"atl":[[2.48,7.46]],"id":38554545}],"con":true,"img":false}]}
{"op":"mcm","clk":"5348971149","pt":1646222599917,"mc":[{"id":"1.195453681","rc":[{"atl":[[2.6,5.05],[2.58,2],[2.46,13.9]],"id":38554545}],"con":true,"img":false}]}
{"op":"mcm","clk":"5348971156","pt":1646222599970,"mc":[{"id":"1.195453681","rc":[{"atb":[[1.68,0]],"id":40917619},{"atb":[[2.24,0]],"id":38554545}],"con":true,"img":false}]}
{"op":"mcm","clk":"5348971198","pt":1646222600487,"mc":[{"id":"1.195453681","rc":[{"atb":[[1.68,42.87]],"id":40917619},{"atl":[[2.56,1.42]],"id":38554545}],"con":true,"img":false}]}
{"op":"mcm","clk":"5348971449","pt":1646222603209,"mc":[{"id":"1.195453681","rc":[{"atb":[[1.67,0]],"id":40917619},{"atl":[[2.5,0],[2.48,0],[2.46,6.4]],"id":38554545}],"con":true,"img":false}]}
{"op":"mcm","clk":"5348971466","pt":1646222603367,"mc":[{"id":"1.195453681","rc":[{"atl":[[2.52,8.78]],"id":38554545}],"con":true,"img":false}]}
{"op":"mcm","clk":"5348971476","pt":1646222603477,"mc":[{"id":"1.195453681","rc":[{"atb":[[1.68,0],[1.65,0]],"id":40917619},{"atb":[[2.34,29.3]],"id":38554545}],"con":true,"img":false}]}
{"op":"mcm","clk":"5348971502","pt":1646222603787,"mc":[{"id":"1.195453681","rc":[{"atl":[[2.56,2.84]],"id":38554545}],"con":true,"img":false}]}
{"op":"mcm","clk":"5348971519","pt":1646222604001,"mc":[{"id":"1.195453681","rc":[{"atb":[[2.34,7.55]],"id":38554545}],"con":true,"img":false}]}
{"op":"mcm","clk":"5348971558","pt":1646222604470,"mc":[{"id":"1.195453681","rc":[{"atb":[[1.65,44.85]],"id":40917619},{"atb":[[2.32,36.97]],"id":38554545},{"atl":[[2.46,0]],"id":38554545}],"con":true,"img":false}]}
{"op":"mcm","clk":"5348971567","pt":1646222604578,"mc":[{"id":"1.195453681","rc":[{"atl":[[2.5,6.3]],"id":38554545}],"con":true,"img":false}]}
{"op":"mcm","clk":"5348971598","pt":1646222605007,"mc":[{"id":"1.195453681","rc":[{"atb":[[1.66,11.45]],"id":40917619},{"atl":[[2.48,7.51]],"id":38554545}],"con":true,"img":false}]}
{"op":"mcm","clk":"5348971605","pt":1646222605103,"mc":[{"id":"1.195453681","rc":[{"atl":[[2.6,7.05],[2.58,0]],"id":38554545}],"con":true,"img":false}]}
{"op":"mcm","clk":"5348971620","pt":1646222605313,"mc":[{"id":"1.195453681","rc":[{"atb":[[2.32,29.7]],"id":38554545},{"atl":[[2.6,2]],"id":38554545}],"con":true,"img":false}]}
{"op":"mcm","clk":"5348971641","pt":1646222605576,"mc":[{"id":"1.195453681","rc":[{"atb":[[2.36,0]],"id":38554545}],"con":true,"img":false}]}
{"op":"mcm","clk":"5348971645","pt":1646222605679,"mc":[{"id":"1.195453681","rc":[{"atl":[[1.81,1.42]],"id":40917619},{"atb":[[2.24,1.42]],"id":38554545},{"atl":[[2.62,1.42]],"id":38554545}],"con":true,"img":false}]}
{"op":"mcm","clk":"5348971732","pt":1646222606680,"mc":[{"id":"1.195453681","rc":[{"atl":[[2.5,0],[2.48,13.86]],"id":38554545}],"con":true,"img":false}]}
{"op":"mcm","clk":"5348971760","pt":1646222607096,"mc":[{"id":"1.195453681","rc":[{"atl":[[2.56,0]],"id":38554545}],"con":true,"img":false}]}
{"op":"mcm","clk":"5348971896","pt":1646222608713,"mc":[{"id":"1.195453681","rc":[{"atl":[[2.46,7.57]],"id":38554545}],"con":true,"img":false}]}
{"op":"mcm","clk":"5348971912","pt":1646222608871,"mc":[{"id":"1.195453681","rc":[{"atb":[[1.7,18.94]],"id":40917619}],"con":true,"img":false}]}
{"op":"mcm","clk":"5348971923","pt":1646222608977,"mc":[{"id":"1.195453681","rc":[{"atb":[[1.67,43.51]],"id":40917619}],"con":true,"img":false}]}
{"op":"mcm","clk":"5348971970","pt":1646222609502,"mc":[{"id":"1.195453681","rc":[{"atb":[[2.32,7.61]],"id":38554545}],"con":true,"img":false}]}
{"op":"mcm","clk":"5348971975","pt":1646222609600,"mc":[{"id":"1.195453681","rc":[{"atl":[[2.64,1.42],[2.48,7.51]],"id":38554545}],"con":true,"img":false}]}
{"op":"mcm","clk":"5348972006","pt":1646222610025,"mc":[{"id":"1.195453681","rc":[{"atb":[[2.32,29.7]],"id":38554545}],"con":true,"img":false}]}
{"op":"mcm","clk":"5348972052","pt":1646222610592,"mc":[{"id":"1.195453681","rc":[{"atb":[[1.71,10.85]],"id":40917619},{"atb":[[2.32,22.08],[2.34,0]],"id":38554545}],"con":true,"img":false}]}
{"op":"mcm","clk":"5348972063","pt":1646222610708,"mc":[{"id":"1.195453681","rc":[{"atl":[[1.76,0],[1.77,0],[1.75,0]],"id":40917619},{"atb":[[2.3,22.42]],"id":38554545}],"con":true,"img":false}]}
{"op":"mcm","clk":"5348972066","pt":1646222610802,"mc":[{"id":"1.195453681","rc":[{"atl":[[1.75,7.61]],"id":40917619},{"atb":[[2.34,5.42]],"id":38554545}],"con":true,"img":false}]}
{"op":"mcm","clk":"5348972076","pt":1646222610910,"mc":[{"id":"1.195453681","rc":[{"atl":[[1.78,0]],"id":40917619}],"con":true,"img":false}]}
{"op":"mcm","clk":"5348972084","pt":1646222611016,"mc":[{"id":"1.195453681","rc":[{"atb":[[2.32,0],[2.3,0],[2.26,0],[2.24,24.93],[2.28,7.86]],"id":38554545}],"con":true,"img":false}]}
{"op":"mcm","clk":"5348972093","pt":1646222611124,"mc":[{"id":"1.195453681","rc":[{"atb":[[2.34,0]],"id":38554545},{"trd":[[2.34,10.83]],"ltp":2.34,"tv":10.83,"id":38554545}],"con":true,"img":false}]}
{"op":"mcm","clk":"5348972102","pt":1646222611222,"mc":[{"id":"1.195453681","rc":[{"atl":[[1.75,0]],"id":40917619},{"atb":[[2.28,0]],"id":38554545}],"con":true,"img":false}]}
{"op":"mcm","clk":"5348972108","pt":1646222611273,"mc":[{"id":"1.195453681","rc":[{"atl":[[1.82,0],[1.81,12.11]],"id":40917619}],"con":true,"img":false}]}
{"op":"mcm","clk":"5348972121","pt":1646222611377,"mc":[{"id":"1.195453681","rc":[{"atl":[[1.79,0],[1.81,14.11]],"id":40917619}],"con":true,"img":false}]}
{"op":"mcm","clk":"5348972128","pt":1646222611482,"mc":[{"id":"1.195453681","rc":[{"atb":[[2.24,1.42]],"id":38554545}],"con":true,"img":false}]}
{"op":"mcm","clk":"5348972137","pt":1646222611585,"mc":[{"id":"1.195453681","rc":[{"atl":[[1.8,10.64]],"id":40917619}],"con":true,"img":false}]}
{"op":"mcm","clk":"5348972149","pt":1646222611689,"mc":[{"id":"1.195453681","rc":[{"atl":[[1.81,25.16]],"id":40917619}],"con":true,"img":false}]}
{"op":"mcm","clk":"5348972158","pt":1646222611795,"mc":[{"id":"1.195453681","rc":[{"atb":[[2.24,9.37]],"id":38554545}],"con":true,"img":false}]}
{"op":"mcm","clk":"5348972183","pt":1646222612007,"mc":[{"id":"1.195453681","rc":[{"atb":[[2.24,32.89]],"id":38554545}],"con":true,"img":false}]}
{"op":"mcm","clk":"5348972205","pt":1646222612313,"mc":[{"id":"1.195453681","rc":[{"atl":[[1.81,14.11]],"id":40917619}],"con":true,"img":false}]}
{"op":"mcm","clk":"5348972216","pt":1646222612419,"mc":[{"id":"1.195453681","rc":[{"atl":[[1.8,21.69]],"id":40917619},{"atb":[[2.24,41.56]],"id":38554545}],"con":true,"img":false}]}
{"op":"mcm","clk":"5348972236","pt":1646222612626,"mc":[{"id":"1.195453681","rc":[{"atb":[[2.26,7.95]],"id":38554545}],"con":true,"img":false}]}
{"op":"mcm","clk":"5348972246","pt":1646222612677,"mc":[{"id":"1.195453681","rc":[{"atl":[[1.79,1.42]],"id":40917619},{"atb":[[2.26,9.37]],"id":38554545}],"con":true,"img":false}]}
{"op":"mcm","clk":"5348972268","pt":1646222612991,"mc":[{"id":"1.195453681","rc":[{"atb":[[2.24,32.89]],"id":38554545}],"con":true,"img":false}]}
{"op":"mcm","clk":"5348972276","pt":1646222613096,"mc":[{"id":"1.195453681","rc":[{"atl":[[1.8,10.64]],"id":40917619},{"atb":[[2.26,18.04]],"id":38554545}],"con":true,"img":false}]}
{"op":"mcm","clk":"5348972284","pt":1646222613201,"mc":[{"id":"1.195453681","rc":[{"atl":[[1.79,12.47]],"id":40917619}],"con":true,"img":false}]}
{"op":"mcm","clk":"5348972293","pt":1646222613306,"mc":[{"id":"1.195453681","rc":[{"atl":[[1.83,0],[1.79,23.17],[1.89,0],[1.84,0],[1.85,0],[1.88,0],[1.86,0]],"id":40917619},{"atb":[[2.22,0],[2.1,0],[2.08,0],[2.24,31.47],[2.02,0],[2.06,0],[2.18,0]],"id":38554545}],"con":true,"img":false}]}
{"op":"mcm","clk":"5348972318","pt":1646222613616,"mc":[{"id":"1.195453681","rc":[{"atl":[[1.79,14.96]],"id":40917619}],"con":true,"img":false}]}
{"op":"mcm","clk":"5348972357","pt":1646222613988,"mc":[{"id":"1.195453681","rc":[{"atb":[[2.28,22.77]],"id":38554545},{"atl":[[1000,0.07]],"id":38554545}],"con":true,"img":false}]}
{"op":"mcm","clk":"5348972373","pt":1646222614196,"mc":[{"id":"1.195453681","rc":[{"atl":[[1000,0]],"id":38554545}],"con":true,"img":false}]}
{"op":"mcm","clk":"5348972383","pt":1646222614299,"mc":[{"id":"1.195453681","rc":[{"atb":[[2.28,22.7]],"id":38554545},{"trd":[[2.28,0.13]],"ltp":2.28,"tv":0.13,"id":38554545}],"con":true,"img":false}]}
{"op":"mcm","clk":"5348972395","pt":1646222614512,"mc":[{"id":"1.195453681","rc":[{"atl":[[1.78,10.81]],"id":40917619},{"atb":[[2.26,9.37]],"id":38554545},{"atl":[[2.58,2],[2.46,13.97]],"id":38554545}],"con":true,"img":false}]}
{"op":"mcm","clk":"5348972403","pt":1646222614614,"mc":[{"id":"1.195453681","rc":[{"atb":[[2.28,31.37]],"id":38554545},{"atl":[[2.6,0]],"id":38554545}],"con":true,"img":false}]}
{"op":"mcm","clk":"5348972425","pt":1646222615033,"mc":[{"id":"1.195453681","rc":[{"atb":[[1.63,0]],"id":40917619},{"atl":[[1.79,12.12]],"id":40917619},{"atb":[[2.28,8.67],[2.26,32.51]],"id":38554545}],"con":true,"img":false}]}
{"op":"mcm","clk":"5348972432","pt":1646222615088,"mc":[{"id":"1.195453681","rc":[{"atl":[[2.44,7.81]],"id":38554545}],"con":true,"img":false}]}
{"op":"mcm","clk":"5348972439","pt":1646222615190,"mc":[{"id":"1.195453681","rc":[{"atl":[[2.54,0]],"id":38554545}],"con":true,"img":false}]}
{"op":"mcm","clk":"5348972477","pt":1646222615610,"mc":[{"id":"1.195453681","rc":[{"atl":[[1.78,21.56]],"id":40917619},{"atb":[[2.28,7.83]],"id":38554545},{"atl":[[2.56,1.42]],"id":38554545}],"con":true,"img":false}]}
{"op":"mcm","clk":"5348972509","pt":1646222616026,"mc":[{"id":"1.195453681","rc":[{"atb":[[1.69,42.24]],"id":40917619},{"atl":[[1.78,10.75]],"id":40917619},{"atb":[[2.28,16.31]],"id":38554545}],"con":true,"img":false}]}
{"op":"mcm","clk":"5348972524","pt":1646222616236,"mc":[{"id":"1.195453681","rc":[{"atl":[[1.78,21.55]],"id":40917619}],"con":true,"img":false}]}
{"op":"mcm","clk":"5348972542","pt":1646222616392,"mc":[{"id":"1.195453681","rc":[{"atl":[[1.81,12.69],[1.78,10.75]],"id":40917619}],"con":true,"img":false}]}
{"op":"mcm","clk":"5348972547","pt":1646222616496,"mc":[{"id":"1.195453681","rc":[{"atl":[[1.79,14.12],[1.81,10.69],[1.78,0]],"id":40917619}],"con":true,"img":false}]}
{"op":"mcm","clk":"5348972588","pt":1646222617026,"mc":[{"id":"1.195453681","rc":[{"atl":[[1.79,25.72]],"id":40917619}],"con":true,"img":false}]}
{"op":"mcm","clk":"5348972667","pt":1646222617913,"mc":[{"id":"1.195453681","rc":[{"atl":[[1.78,1.42]],"id":40917619},{"atl":[[2.4,1.42]],"id":38554545}],"con":true,"img":false}]}
{"op":"mcm","clk":"5348972685","pt":1646222618121,"mc":[{"id":"1.195453681","rc":[{"atl":[[1.78,12.23]],"id":40917619}],"con":true,"img":false}]}
{"op":"mcm","clk":"5348972706","pt":1646222618428,"mc":[{"id":"1.195453681","rc":[{"atl":[[1.79,14.12]],"id":40917619}],"con":true,"img":false}]}
{"op":"mcm","clk":"5348972716","pt":1646222618549,"mc":[{"id":"1.195453681","rc":[{"atl":[[1.78,23.83]],"id":40917619}],"con":true,"img":false}]}
{"op":"mcm","clk":"5348972768","pt":1646222619116,"mc":[{"id":"1.195453681","rc":[{"atl":[[2.4,9.23]],"id":38554545}],"con":true,"img":false}]}
{"op":"mcm","clk":"5348972774","pt":1646222619212,"mc":[{"id":"1.195453681","rc":[{"atl":[[2.52,1.42]],"id":38554545}],"con":true,"img":false}]}
{"op":"mcm","clk":"5348972793","pt":1646222619532,"mc":[{"id":"1.195453681","rc":[{"atb":[[1.65,0]],"id":40917619},{"atl":[[2.46,7.57]],"id":38554545}],"con":true,"img":false}]}
{"op":"mcm","clk":"5348972848","pt":1646222620533,"mc":[{"id":"1.195453681","rc":[{"atl":[[1.78,25.25]],"id":40917619},{"atb":[[2.18,1.42]],"id":38554545},{"atl":[[2.4,10.66]],"id":38554545}],"con":true,"img":false}]}
{"op":"mcm","clk":"5348972854","pt":1646222620632,"mc":[{"id":"1.195453681","rc":[{"atl":[[1.81,0],[1.77,10.93]],"id":40917619},{"atb":[[2.3,7.77]],"id":38554545}],"con":true,"img":false}]}
{"op":"mcm","clk":"5348972889","pt":1646222621001,"mc":[{"id":"1.195453681","rc":[{"atb":[[1.7,60.59]],"id":40917619},{"atl":[[1.78,13.65]],"id":40917619},{"atb":[[2.28,7.83]],"id":38554545}],"con":true,"img":false}]}
{"op":"mcm","clk":"5348972936","pt":1646222621523,"mc":[{"id":"1.195453681","rc":[{"atl":[[1.77,22.9]],"id":40917619},{"atb":[[2.3,16.93]],"id":38554545}],"con":true,"img":false}]}
{"op":"mcm","clk":"5348972976","pt":1646222622093,"mc":[{"id":"1.195453681","rc":[{"atl":[[1.77,10.93]],"id":40917619},{"atb":[[2.3,7.77]],"id":38554545}],"con":true,"img":false}]}
{"op":"mcm","clk":"5348972985","pt":1646222622201,"mc":[{"id":"1.195453681","rc":[{"atl":[[1.76,10.98]],"id":40917619},{"atb":[[2.32,7.73]],"id":38554545}],"con":true,"img":false}]}
{"op":"mcm","clk":"5348972994","pt":1646222622312,"mc":[{"id":"1.195453681","rc":[{"atl":[[1.8,0]],"id":40917619},{"atb":[[2.24,23.51]],"id":38554545}],"con":true,"img":false}]}
{"op":"mcm","clk":"5348973039","pt":1646222622937,"mc":[{"id":"1.195453681","rc":[{"atl":[[1.76,0]],"id":40917619}],"con":true,"img":false}]}
{"op":"mcm","clk":"5348973046","pt":1646222623029,"mc":[{"id":"1.195453681","rc":[{"atb":[[1.7,18.94]],"id":40917619}],"con":true,"img":false}]}
{"op":"mcm","clk":"5348973055","pt":1646222623139,"mc":[{"id":"1.195453681","rc":[{"atb":[[2.32,0]],"id":38554545}],"con":true,"img":false}]}
{"op":"mcm","clk":"5348973153","pt":1646222624337,"mc":[{"id":"1.195453681","rc":[{"atl":[[1.82,1.42]],"id":40917619},{"atb":[[2.22,1.42]],"id":38554545},{"atl":[[2.54,1.42]],"id":38554545}],"con":true,"img":false}]}
{"op":"mcm","clk":"5348973203","pt":1646222625022,"mc":[{"id":"1.195453681","rc":[{"atb":[[1.71,0]],"id":40917619},{"atl":[[2.4,2.84]],"id":38554545}],"con":true,"img":false}]}
{"op":"mcm","clk":"5348973217","pt":1646222625221,"mc":[{"id":"1.195453681","rc":[{"atl":[[1.79,12.7]],"id":40917619}],"con":true,"img":false}]}
{"op":"mcm","clk":"5348973225","pt":1646222625340,"mc":[{"id":"1.195453681","rc":[{"atb":[[1.71,11.1]],"id":40917619},{"atl":[[2.4,10.54]],"id":38554545}],"con":true,"img":false}]}
{"op":"mcm","clk":"5348973242","pt":1646222625535,"mc":[{"id":"1.195453681","rc":[{"atb":[[2.28,30.6]],"id":38554545}],"con":true,"img":false}]}
{"op":"mcm","clk":"5348973272","pt":1646222625911,"mc":[{"id":"1.195453681","rc":[{"atl":[[2.48,0],[2.38,7.75]],"id":38554545}],"con":true,"img":false}]}
{"op":"mcm","clk":"5348973280","pt":1646222626009,"mc":[{"id":"1.195453681","rc":[{"atb":[[2.28,7.83]],"id":38554545}],"con":true,"img":false}]}
{"op":"mcm","clk":"5348973288","pt":1646222626116,"mc":[{"id":"1.195453681","rc":[{"atl":[[2.38,0]],"id":38554545}],"con":true,"img":false}]}
{"op":"mcm","clk":"5348973325","pt":1646222626529,"mc":[{"id":"1.195453681","rc":[{"atb":[[1.7,60.59]],"id":40917619}],"con":true,"img":false}]}
{"op":"mcm","clk":"5348973332","pt":1646222626640,"mc":[{"id":"1.195453681","rc":[{"atb":[[2.16,1.42]],"id":38554545},{"atl":[[2.54,2.84]],"id":38554545}],"con":true,"img":false}]}
{"op":"mcm","clk":"5348973348","pt":1646222626797,"mc":[{"id":"1.195453681","rc":[{"atl":[[1.77,23.2]],"id":40917619},{"atb":[[2.3,17.16]],"id":38554545}],"con":true,"img":false}]}
{"op":"mcm","clk":"5348973471","pt":1646222628044,"mc":[{"id":"1.195453681","rc":[{"atl":[[1.79,10.7],[1.76,2]],"id":40917619},{"atl":[[2.58,0]],"id":38554545}],"con":true,"img":false}]}
{"op":"mcm","clk":"5348973490","pt":1646222628207,"mc":[{"id":"1.195453681","rc":[{"atb":[[2.32,7.73]],"id":38554545},{"atl":[[2.66,2]],"id":38554545}],"con":true,"img":false}]}
{"op":"mcm","clk":"5348973505","pt":1646222628325,"mc":[{"id":"1.195453681","rc":[{"atl":[[1.76,12.99]],"id":40917619}],"con":true,"img":false}]}
{"op":"mcm","clk":"5348973510","pt":1646222628411,"mc":[{"id":"1.195453681","rc":[{"atl":[[1.82,0],[1.77,10.93]],"id":40917619},{"atb":[[2.22,0]],"id":38554545}],"con":true,"img":false}]}
{"op":"mcm","clk":"5348973523","pt":1646222628522,"mc":[{"id":"1.195453681","rc":[{"atb":[[1.7,18.94]],"id":40917619},{"atl":[[1.76,25.26]],"id":40917619},{"atb":[[2.28,30.6]],"id":38554545}],"con":true,"img":false}]}
{"op":"mcm","clk":"5348973544","pt":1646222628727,"mc":[{"id":"1.195453681","rc":[{"atb":[[2.3,7.77]],"id":38554545}],"con":true,"img":false}]}
{"op":"mcm","clk":"5348973556","pt":1646222628834,"mc":[{"id":"1.195453681","rc":[{"atb":[[2.32,17.12]],"id":38554545}],"con":true,"img":false}]}
{"op":"mcm","clk":"5348973568","pt":1646222628937,"mc":[{"id":"1.195453681","rc":[{"atl":[[1.76,14.27]],"id":40917619},{"atb":[[2.32,9.39]],"id":38554545}],"con":true,"img":false}]}
{"op":"mcm","clk":"5348973604","pt":1646222629354,"mc":[{"id":"1.195453681","rc":[{"atl":[[1.76,17.02]],"id":40917619},{"atb":[[2.32,7.71]],"id":38554545}],"con":true,"img":false}]}
{"op":"mcm","clk":"5348973614","pt":1646222629410,"mc":[{"id":"1.195453681","rc":[{"atb":[[2.3,17.16]],"id":38554545}],"con":true,"img":false}]}
{"op":"mcm","clk":"5348973646","pt":1646222629827,"mc":[{"id":"1.195453681","rc":[{"atl":[[1000,1.69]],"id":40917619},{"atl":[[1000,1.73]],"id":38554545}],"con":true,"img":false}]}
{"op":"mcm","clk":"5348973652","pt":1646222629925,"mc":[{"id":"1.195453681","rc":[{"atb":[[2.3,7.77]],"id":38554545}],"con":true,"img":false}]}
{"op":"mcm","clk":"5348973661","pt":1646222630029,"mc":[{"id":"1.195453681","rc":[{"atl":[[1000,0.02]],"id":40917619},{"atb":[[2.32,17.1]],"id":38554545},{"atl":[[1000,0.06]],"id":38554545}],"con":true,"img":false}]}
{"op":"mcm","clk":"5348973671","pt":1646222630236,"mc":[{"id":"1.195453681","rc":[{"atl":[[1000,0]],"id":40917619},{"atl":[[1000,0]],"id":38554545}],"con":true,"img":false}]}
{"op":"mcm","clk":"5348973680","pt":1646222630354,"mc":[{"id":"1.195453681","rc":[{"atl":[[1.76,17.05]],"id":40917619},{"atl":[[2.42,0.06]],"id":38554545}],"con":true,"img":false}]}
{"op":"mcm","clk":"5348973715","pt":1646222630708,"mc":[{"id":"1.195453681","rc":[{"atl":[[2.4,2.84]],"id":38554545}],"con":true,"img":false}]}
{"op":"mcm","clk":"5348973721","pt":1646222630815,"mc":[{"id":"1.195453681","rc":[{"atb":[[2.16,2.84]],"id":38554545}],"con":true,"img":false}]}
{"op":"mcm","clk":"5348973807","pt":1646222631914,"mc":[{"id":"1.195453681","rc":[{"atl":[[2.42,7.73]],"id":38554545}],"con":true,"img":false}]}
{"op":"mcm","clk":"5348973833","pt":1646222632222,"mc":[{"id":"1.195453681","rc":[{"atl":[[2.4,10.52]],"id":38554545}],"con":true,"img":false}]}
{"op":"mcm","clk":"5348973943","pt":1646222633625,"mc":[{"id":"1.195453681","rc":[{"atl":[[2.4,2.84]],"id":38554545}],"con":true,"img":false}]}
{"op":"mcm","clk":"5348973985","pt":1646222634149,"mc":[{"id":"1.195453681","rc":[{"atb":[[1.71,0]],"id":40917619}],"con":true,"img":false}]}
{"op":"mcm","clk":"5348974004","pt":1646222634416,"mc":[{"id":"1.195453681","rc":[{"atl":[[1.75,11.09]],"id":40917619}],"con":true,"img":false}]}
{"op":"mcm","clk":"5348974010","pt":1646222634519,"mc":[{"id":"1.195453681","rc":[{"atl":[[1.76,15.05]],"id":40917619},{"atb":[[2.26,24.56],[2.34,7.66]],"id":38554545}],"con":true,"img":false}]}
{"op":"mcm","clk":"5348974014","pt":1646222634618,"mc":[{"id":"1.195453681","rc":[{"atl":[[1.79,0],[1.75,13.09]],"id":40917619}],"con":true,"img":false}]}
{"op":"mcm","clk":"5348974041","pt":1646222634939,"mc":[{"id":"1.195453681","rc":[{"atl":[[1.76,11.05]],"id":40917619}],"con":true,"img":false}]}
{"op":"mcm","clk":"5348974046","pt":1646222635042,"mc":[{"id":"1.195453681","rc":[{"atb":[[2.24,0]],"id":38554545}],"con":true,"img":false}]}
{"op":"mcm","clk":"5348974054","pt":1646222635147,"mc":[{"id":"1.195453681","rc":[{"atb":[[2.32,7.71]],"id":38554545}],"con":true,"img":false}]}
{"op":"mcm","clk":"5348974062","pt":1646222635248,"mc":[{"id":"1.195453681","rc":[{"atl":[[1.75,28.15]],"id":40917619}],"con":true,"img":false}]}
{"op":"mcm","clk":"5348974091","pt":1646222635617,"mc":[{"id":"1.195453681","rc":[{"atb":[[2.34,18.64]],"id":38554545}],"con":true,"img":false}]}
{"op":"mcm","clk":"5348974105","pt":1646222635829,"mc":[{"id":"1.195453681","rc":[{"atl":[[2.42,0.06]],"id":38554545}],"con":true,"img":false}]}
{"op":"mcm","clk":"5348974118","pt":1646222636037,"mc":[{"id":"1.195453681","rc":[{"atb":[[1.68,42.87],[1.69,0]],"id":40917619},{"atb":[[2.3,30.19]],"id":38554545}],"con":true,"img":false}]}
{"op":"mcm","clk":"5348974164","pt":1646222636556,"mc":[{"id":"1.195453681","rc":[{"atl":[[1.82,1.42]],"id":40917619},{"atb":[[2.22,1.42]],"id":38554545},{"atl":[[2.48,1.42]],"id":38554545}],"con":true,"img":false}]}
{"op":"mcm","clk":"5348974241","pt":1646222637553,"mc":[{"id":"1.195453681","rc":[{"atl":[[1.74,11.18]],"id":40917619}],"con":true,"img":false}]}
{"op":"mcm","clk":"5348974254","pt":1646222637714,"mc":[{"id":"1.195453681","rc":[{"atb":[[1.7,7.7]],"id":40917619},{"atl":[[1.78,2.84]],"id":40917619},{"atb":[[2.36,7.6],[2.28,22.77]],"id":38554545}],"con":true,"img":false}]}
{"op":"mcm","clk":"5348974273","pt":1646222638036,"mc":[{"id":"1.195453681","rc":[{"atl":[[1.75,13.09]],"id":40917619},{"atb":[[2.26,1.42]],"id":38554545}],"con":true,"img":false}]}
{"op":"mcm","clk":"5348974281","pt":1646222638143,"mc":[{"id":"1.195453681","rc":[{"trd":[[1.71,3.98]],"ltp":1.71,"tv":3.98,"id":40917619},{"atl":[[2.4,0]],"id":38554545},{"trd":[[2.4,2.84]],"ltp":2.4,"tv":2.84,"id":38554545}],"con":true,"img":false}]}
{"op":"mcm","clk":"5348974289","pt":1646222638256,"mc":[{"id":"1.195453681","rc":[{"atb":[[2.34,7.66]],"id":38554545}],"con":true,"img":false}]}
{"op":"mcm","clk":"5348974296","pt":1646222638347,"mc":[{"id":"1.195453681","rc":[{"atl":[[1.82,2.84]],"id":40917619},{"atb":[[2.22,2.84],[2.36,18.58]],"id":38554545}],"con":true,"img":false}]}
{"op":"mcm","clk":"5348974313","pt":1646222638559,"mc":[{"id":"1.195453681","rc":[{"atl":[[1.74,25.55]],"id":40917619},{"atb":[[2.3,7.77]],"id":38554545}],"con":true,"img":false}]}
{"op":"mcm","clk":"5348974319","pt":1646222638657,"mc":[{"id":"1.195453681","rc":[{"atb":[[1.68,0]],"id":40917619}],"con":true,"img":false}]}
{"op":"mcm","clk":"5348974340","pt":1646222638920,"mc":[{"id":"1.195453681","rc":[{"atb":[[1.7,0]],"id":40917619},{"atl":[[1.69,3.26]],"id":40917619},{"trd":[[1.69,11.28],[1.7,15.5]],"ltp":1.69,"tv":26.78,"id":40917619},{"atl":[[2.44,0],[2.42,0]],"id":38554545},{"trd":[[2.44,7.81],[2.42,0.06]],"ltp":2.44,"tv":7.86,"id":38554545}],"con":true,"img":false}]}
{"op":"mcm","clk":"5348974343","pt":1646222639025,"mc":[{"id":"1.195453681","rc":[{"atb":[[1.68,42.87]],"id":40917619},{"atl":[[1.69,0]],"id":40917619},{"trd":[[1.69,17.8]],"ltp":1.69,"tv":17.8,"id":40917619},{"atb":[[2.32,29.8]],"id":38554545}],"con":true,"img":false}]}
{"op":"mcm","clk":"5348974351","pt":1646222639136,"mc":[{"id":"1.195453681","rc":[{"atl":[[1.73,11.35],[1.77,0]],"id":40917619},{"atb":[[2.3,0],[2.38,7.53]],"id":38554545},{"atl":[[2.54,0],[2.52,0],[2.46,0]],"id":38554545}],"con":true,"img":false}]}
{"op":"mcm","clk":"5348974387","pt":1646222639653,"mc":[{"id":"1.195453681","rc":[{"atb":[[1.67,0],[1.68,0]],"id":40917619},{"atl":[[1.74,11.18]],"id":40917619},{"atb":[[2.36,7.6]],"id":38554545}],"con":true,"img":false}]}
{"op":"mcm","clk":"5348974401","pt":1646222639764,"mc":[{"id":"1.195453681","rc":[{"atl":[[1.73,25.72]],"id":40917619},{"atb":[[2.38,18.51]],"id":38554545}],"con":true,"img":false}]}
{"op":"mcm","clk":"5348974423","pt":1646222639916,"mc":[{"id":"1.195453681","rc":[{"atl":[[1.72,11.41]],"id":40917619}],"con":true,"img":false}]}
{"op":"mcm","clk":"5348974431","pt":1646222640032,"mc":[{"id":"1.195453681","rc":[{"atb":[[1.58,50.25]],"id":40917619},{"atb":[[2.32,7.71],[2.3,22.42]],"id":38554545}],"con":true,"img":false}]}
{"op":"mcm","clk":"5348974443","pt":1646222640132,"mc":[{"id":"1.195453681","rc":[{"atl":[[1.76,0.02]],"id":40917619},{"atb":[[2.32,0],[2.4,7.48]],"id":38554545}],"con":true,"img":false}]}
{"op":"mcm","clk":"5348974458","pt":1646222640351,"mc":[{"id":"1.195453681","rc":[{"atl":[[1.73,11.35]],"id":40917619}],"con":true,"img":false}]}
{"op":"mcm","clk":"5348974466","pt":1646222640460,"mc":[{"id":"1.195453681","rc":[{"atl":[[1.72,25.78]],"id":40917619}],"con":true,"img":false}]}
{"op":"mcm","clk":"5348974487","pt":1646222640758,"mc":[{"id":"1.195453681","rc":[{"atb":[[2.38,7.53]],"id":38554545}],"con":true,"img":false}]}
{"op":"mcm","clk":"5348974493","pt":1646222640816,"mc":[{"id":"1.195453681","rc":[{"atb":[[2.4,18.46]],"id":38554545}],"con":true,"img":false}]}
{"op":"mcm","clk":"5348974499","pt":1646222640918,"mc":[{"id":"1.195453681","rc":[{"atl":[[1.75,2],[1.71,11.51]],"id":40917619}],"con":true,"img":false}]}
{"op":"mcm","clk":"5348974504","pt":1646222641024,"mc":[{"id":"1.195453681","rc":[{"atb":[[2.32,22.08]],"id":38554545}],"con":true,"img":false}]}
{"op":"mcm","clk":"5348974538","pt":1646222641451,"mc":[{"id":"1.195453681","rc":[{"atl":[[1.72,11.41]],"id":40917619}],"con":true,"img":false}]}
{"op":"mcm","clk":"5348974546","pt":1646222641543,"mc":[{"id":"1.195453681","rc":[{"atl":[[1.71,25.88]],"id":40917619}],"con":true,"img":false}]}
{"op":"mcm","clk":"5348974563","pt":1646222641755,"mc":[{"id":"1.195453681","rc":[{"atb":[[2.42,7.42]],"id":38554545}],"con":true,"img":false}]}
{"op":"mcm","clk":"5348974571","pt":1646222641855,"mc":[{"id":"1.195453681","rc":[{"atl":[[1.71,14.37]],"id":40917619},{"atb":[[2.34,0],[2.4,10.98]],"id":38554545}],"con":true,"img":false}]}
{"op":"mcm","clk":"5348974584","pt":1646222641967,"mc":[{"id":"1.195453681","rc":[{"atb":[[2.42,0]],"id":38554545}],"con":true,"img":false}]}
{"op":"mcm","clk":"5348974593","pt":1646222642069,"mc":[{"id":"1.195453681","rc":[{"atb":[[2.28,0]],"id":38554545}],"con":true,"img":false}]}
{"op":"mcm","clk":"5348974600","pt":1646222642169,"mc":[{"id":"1.195453681","rc":[{"atb":[[2.4,18.45]],"id":38554545}],"con":true,"img":false}]}
{"op":"mcm","clk":"5348974605","pt":1646222642223,"mc":[{"id":"1.195453681","rc":[{"atl":[[1.71,0]],"id":40917619},{"atb":[[2.4,7.47]],"id":38554545}],"con":true,"img":false}]}
{"op":"mcm","clk":"5348974615","pt":1646222642337,"mc":[{"id":"1.195453681","rc":[{"atl":[[1.72,25.78]],"id":40917619},{"atb":[[2.4,0],[2.42,10.98]],"id":38554545},{"atl":[[2.48,0]],"id":38554545}],"con":true,"img":false}]}
{"op":"mcm","clk":"5348974639","pt":1646222642556,"mc":[{"id":"1.195453681","rc":[{"atl":[[1.71,11.52]],"id":40917619}],"con":true,"img":false}]}
{"op":"mcm","clk":"5348974677","pt":1646222642973,"mc":[{"id":"1.195453681","rc":[{"atb":[[2.42,0]],"id":38554545}],"con":true,"img":false}]}
{"op":"mcm","clk":"5348974682","pt":1646222643018,"mc":[{"id":"1.195453681","rc":[{"atl":[[1.72,11.41]],"id":40917619},{"atb":[[2.4,20.82]],"id":38554545}],"con":true,"img":false}]}
{"op":"mcm","clk":"5348974689","pt":1646222643176,"mc":[{"id":"1.195453681","rc":[{"atl":[[1.71,25.89]],"id":40917619},{"atb":[[2.38,18.51]],"id":38554545}],"con":true,"img":false}]}
{"op":"mcm","clk":"5348974706","pt":1646222643339,"mc":[{"id":"1.195453681","rc":[{"atb":[[2.42,7.42]],"id":38554545}],"con":true,"img":false}]}
{"op":"mcm","clk":"5348974722","pt":1646222643544,"mc":[{"id":"1.195453681","rc":[{"atb":[[2.42,0]],"id":38554545}],"con":true,"img":false}]}
{"op":"mcm","clk":"5348974740","pt":1646222643751,"mc":[{"id":"1.195453681","rc":[{"atb":[[2.38,7.53]],"id":38554545}],"con":true,"img":false}]}
{"op":"mcm","clk":"5348974745","pt":1646222643849,"mc":[{"id":"1.195453681","rc":[{"atb":[[2.4,31.8]],"id":38554545}],"con":true,"img":false}]}
{"op":"mcm","clk":"5348974756","pt":1646222643965,"mc":[{"id":"1.195453681","rc":[{"atl":[[1.7,11.62]],"id":40917619},{"atb":[[2.42,7.4]],"id":38554545}],"con":true,"img":false}]}
{"op":"mcm","clk":"5348974766","pt":1646222644061,"mc":[{"id":"1.195453681","rc":[{"atl":[[1.74,0]],"id":40917619}],"con":true,"img":false}]}
{"op":"mcm","clk":"5348974789","pt":1646222644328,"mc":[{"id":"1.195453681","rc":[{"atl":[[1.71,11.52]],"id":40917619},{"atb":[[2.4,20.82]],"id":38554545}],"con":true,"img":false}]}
{"op":"mcm","clk":"5348974801","pt":1646222644470,"mc":[{"id":"1.195453681","rc":[{"atl":[[1.7,25.99]],"id":40917619},{"atb":[[2.42,18.38]],"id":38554545}],"con":true,"img":false}]}
{"op":"mcm","clk":"5348974817","pt":1646222644533,"mc":[{"id":"1.195453681","rc":[{"atb":[[2.4,0]],"id":38554545}],"con":true,"img":false}]}
{"op":"mcm","clk":"5348974829","pt":1646222644654,"mc":[{"id":"1.195453681","rc":[{"atb":[[2.44,7.36]],"id":38554545}],"con":true,"img":false}]}
{"op":"mcm","clk":"5348974833","pt":1646222644749,"mc":[{"id":"1.195453681","rc":[{"atb":[[1.03,2.87]],"id":38554545},{"atl":[[2.54,4.47]],"id":38554545}],"con":true,"img":false}]}
{"op":"mcm","clk":"5348974844","pt":1646222644856,"mc":[{"id":"1.195453681","rc":[{"atb":[[1.66,0]],"id":40917619}],"con":true,"img":false}]}
{"op":"mcm","clk":"5348974854","pt":1646222644953,"mc":[{"id":"1.195453681","rc":[{"atb":[[1.03,0.14]],"id":38554545}],"con":true,"img":false}]}
{"op":"mcm","clk":"5348974862","pt":1646222645051,"mc":[{"id":"1.195453681","rc":[{"atb":[[2.36,29.04],[2.42,7.4]],"id":38554545}],"con":true,"img":false}]}
{"op":"mcm","clk":"5348974870","pt":1646222645153,"mc":[{"id":"1.195453681","rc":[{"atb":[[1.03,0],[2.44,18.34]],"id":38554545}],"con":true,"img":false}]}
{"op":"mcm","clk":"5348974883","pt":1646222645265,"mc":[{"id":"1.195453681","rc":[{"atb":[[2.52,0.14]],"id":38554545}],"con":true,"img":false}]}
{"op":"mcm","clk":"5348974886","pt":1646222645313,"mc":[{"id":"1.195453681","rc":[{"atl":[[1.69,11.76]],"id":40917619}],"con":true,"img":false}]}
{"op":"mcm","clk":"5348974899","pt":1646222645471,"mc":[{"id":"1.195453681","rc":[{"atl":[[1.73,0]],"id":40917619},{"atb":[[2.44,7.36],[2.52,0]],"id":38554545},{"atl":[[2.54,0]],"id":38554545},{"trd":[[2.52,0.29],[2.54,8.94]],"ltp":2.52,"tv":9.22,"id":38554545}],"con":true,"img":false}]}
{"op":"mcm","clk":"5348974906","pt":1646222645529,"mc":[{"id":"1.195453681","rc":[{"atb":[[2.42,18.38]],"id":38554545}],"con":true,"img":false}]}
{"op":"mcm","clk":"5348974909","pt":1646222645637,"mc":[{"id":"1.195453681","rc":[{"atl":[[1.82,0],[1.78,0]],"id":40917619},{"atb":[[2.22,0],[2.26,0],[2.38,9.53],[2.18,0],[2.16,0]],"id":38554545},{"atl":[[2.56,0],[2.64,0],[2.62,0]],"id":38554545}],"con":true,"img":false}]}
{"op":"mcm","clk":"5348974917","pt":1646222645732,"mc":[{"id":"1.195453681","rc":[{"atl":[[1.7,11.62]],"id":40917619},{"atl":[[2.72,2]],"id":38554545}],"con":true,"img":false}]}
{"op":"mcm","clk":"5348974933","pt":1646222645841,"mc":[{"id":"1.195453681","rc":[{"atl":[[1.69,26.13]],"id":40917619},{"atl":[[2.66,0]],"id":38554545}],"con":true,"img":false}]}
{"op":"mcm","clk":"5348974951","pt":1646222646053,"mc":[{"id":"1.195453681","rc":[{"atb":[[1.58,0],[1.49,59.49]],"id":40917619}],"con":true,"img":false}]}
{"op":"mcm","clk":"5348974957","pt":1646222646150,"mc":[{"id":"1.195453681","rc":[{"atb":[[2.42,7.4]],"id":38554545}],"con":true,"img":false}]}
{"op":"mcm","clk":"5348974968","pt":1646222646255,"mc":[{"id":"1.195453681","rc":[{"atb":[[2.44,18.34]],"id":38554545}],"con":true,"img":false}]}
{"op":"mcm","clk":"5348974980","pt":1646222646462,"mc":[{"id":"1.195453681","rc":[{"atb":[[2.46,7.3]],"id":38554545}],"con":true,"img":false}]}
{"op":"mcm","clk":"5348974996","pt":1646222646565,"mc":[{"id":"1.195453681","rc":[{"atb":[[2.36,21.43]],"id":38554545}],"con":true,"img":false}]}
{"op":"mcm","clk":"5348975002","pt":1646222646667,"mc":[{"id":"1.195453681","rc":[{"atb":[[2.44,12.8]],"id":38554545}],"con":true,"img":false}]}
{"op":"mcm","clk":"5348975041","pt":1646222647034,"mc":[{"id":"1.195453681","rc":[{"atb":[[2.3,0]],"id":38554545}],"con":true,"img":false}]}
{"op":"mcm","clk":"5348975125","pt":1646222647939,"mc":[{"id":"1.195453681","rc":[{"atb":[[2.46,0]],"id":38554545}],"con":true,"img":false}]}
{"op":"mcm","clk":"5348975160","pt":1646222648358,"mc":[{"id":"1.195453681","rc":[{"atb":[[1.57,0],[1.58,2]],"id":40917619},{"atb":[[2.38,7.53]],"id":38554545}],"con":true,"img":false}]}
{"op":"mcm","clk":"5348975175","pt":1646222648527,"mc":[{"id":"1.195453681","rc":[{"atb":[[2.34,2]],"id":38554545}],"con":true,"img":false}]}
{"op":"mcm","clk":"5348975207","pt":1646222649061,"mc":[{"id":"1.195453681","rc":[{"atb":[[1.49,0]],"id":40917619}],"con":true,"img":false}]}
{"op":"mcm","clk":"5348975251","pt":1646222649526,"mc":[{"id":"1.195453681","rc":[{"atb":[[1.47,62.02]],"id":40917619}],"con":true,"img":false}]}
{"op":"mcm","clk":"5348975274","pt":1646222649842,"mc":[{"id":"1.195453681","rc":[{"atb":[[1.03,2.87]],"id":40917619}],"con":true,"img":false}]}
{"op":"mcm","clk":"5348975288","pt":1646222650059,"mc":[{"id":"1.195453681","rc":[{"atb":[[1.03,0.14]],"id":40917619}],"con":true,"img":false}]}
{"op":"mcm","clk":"5348975303","pt":1646222650257,"mc":[{"id":"1.195453681","rc":[{"atb":[[1.03,0]],"id":40917619}],"con":true,"img":false}]}
{"op":"mcm","clk":"5348975312","pt":1646222650364,"mc":[{"id":"1.195453681","rc":[{"atl":[[1.69,25.98]],"id":40917619},{"trd":[[1.69,18.1]],"ltp":1.69,"tv":18.1,"id":40917619}],"con":true,"img":false}]}
{"op":"mcm","clk":"5348975406","pt":1646222651470,"mc":[{"id":"1.195453681","rc":[{"atl":[[1.68,12.66]],"id":40917619}],"con":true,"img":false}]}
{"op":"mcm","clk":"5348975421","pt":1646222651674,"mc":[{"id":"1.195453681","rc":[{"atb":[[2.46,7.3]],"id":38554545}],"con":true,"img":false}]}
{"op":"mcm","clk":"5348975455","pt":1646222652045,"mc":[{"id":"1.195453681","rc":[{"atl":[[1.69,11.61]],"id":40917619},{"atb":[[2.44,7.36],[2.38,28.65]],"id":38554545},{"atl":[[2.72,0],[2.7,2]],"id":38554545}],"con":true,"img":false}]}
{"op":"mcm","clk":"5348975462","pt":1646222652150,"mc":[{"id":"1.195453681","rc":[{"atl":[[1.68,27.03]],"id":40917619},{"atb":[[2.46,12.74]],"id":38554545}],"con":true,"img":false}]}
{"op":"mcm","clk":"5348975528","pt":1646222652948,"mc":[{"id":"1.195453681","rc":[{"atb":[[1.64,0]],"id":40917619},{"atb":[[2.48,7.22]],"id":38554545}],"con":true,"img":false}]}
{"op":"mcm","clk":"5348975536","pt":1646222653050,"mc":[{"id":"1.195453681","rc":[{"atb":[[2.38,21.12]],"id":38554545}],"con":true,"img":false}]}
{"op":"mcm","clk":"5348975543","pt":1646222653157,"mc":[{"id":"1.195453681","rc":[{"atl":[[1.67,12],[1.68,12.66]],"id":40917619},{"atb":[[2.46,7.3]],"id":38554545}],"con":true,"img":false}]}
{"op":"mcm","clk":"5348975550","pt":1646222653260,"mc":[{"id":"1.195453681","rc":[{"atb":[[1.63,4.46]],"id":40917619},{"atl":[[1.72,0]],"id":40917619}],"con":true,"img":false}]}
{"op":"mcm","clk":"5348975580","pt":1646222653576,"mc":[{"id":"1.195453681","rc":[{"atb":[[1.46,63.37],[1.47,0]],"id":40917619},{"atb":[[2.32,0]],"id":38554545}],"con":true,"img":false}]}
{"op":"mcm","clk":"5348975597","pt":1646222653783,"mc":[{"id":"1.195453681","rc":[{"atb":[[2.48,12.45]],"id":38554545}],"con":true,"img":false}]}
{"op":"mcm","clk":"5348975613","pt":1646222653958,"mc":[{"id":"1.195453681","rc":[{"atb":[[2.5,7.18]],"id":38554545}],"con":true,"img":false}]}
{"op":"mcm","clk":"5348975621","pt":1646222654057,"mc":[{"id":"1.195453681","rc":[{"atb":[[2.42,0]],"id":38554545}],"con":true,"img":false}]}
{"op":"mcm","clk":"5348975661","pt":1646222654584,"mc":[{"id":"1.195453681","rc":[{"atb":[[2.42,20.53]],"id":38554545}],"con":true,"img":false}]}
{"op":"mcm","clk":"5348975668","pt":1646222654677,"mc":[{"id":"1.195453681","rc":[{"atl":[[1.67,24.73]],"id":40917619}],"con":true,"img":false}]}
{"op":"mcm","clk":"5348975685","pt":1646222654946,"mc":[{"id":"1.195453681","rc":[{"atl":[[1.66,12.12]],"id":40917619}],"con":true,"img":false}]}
{"op":"mcm","clk":"5348975694","pt":1646222655051,"mc":[{"id":"1.195453681","rc":[{"atl":[[1.71,0]],"id":40917619}],"con":true,"img":false}]}
{"op":"mcm","clk":"5348975868","pt":1646222657258,"mc":[{"id":"1.195453681","rc":[{"atl":[[2.72,2],[2.7,0]],"id":38554545}],"con":true,"img":false}]}
{"op":"mcm","clk":"5348975952","pt":1646222658157,"mc":[{"id":"1.195453681","rc":[{"atl":[[1.75,0]],"id":40917619}],"con":true,"img":false}]}
{"op":"mcm","clk":"5348975970","pt":1646222658360,"mc":[{"id":"1.195453681","rc":[{"atl":[[1.78,2]],"id":40917619}],"con":true,"img":false}]}
{"op":"mcm","clk":"5348976124","pt":1646222660187,"mc":[{"id":"1.195453681","rc":[{"atl":[[1.68,0]],"id":40917619}],"con":true,"img":false}]}
{"op":"mcm","clk":"5348976194","pt":1646222661184,"mc":[{"id":"1.195453681","rc":[{"atl":[[2.72,6]],"id":38554545}],"con":true,"img":false}]}
{"op":"mcm","clk":"5348976280","pt":1646222662393,"mc":[{"id":"1.195453681","rc":[{"atb":[[1.6,0]],"id":40917619},{"atb":[[1.6,0],[1.7,0],[1.8,0]],"id":38554545}],"con":true,"img":false}]}
{"op":"mcm","clk":"5348976287","pt":1646222662499,"mc":[{"id":"1.195453681","rc":[{"atl":[[2.72,4],[2.7,2]],"id":38554545}],"con":true,"img":false}]}
{"op":"mcm","clk":"5348976559","pt":1646222666374,"mc":[{"id":"1.195453681","rc":[{"atb":[[1.58,0],[1.57,2]],"id":40917619}],"con":true,"img":false}]}
{"op":"mcm","clk":"5348976581","pt":1646222666683,"mc":[{"id":"1.195453681","rc":[{"atl":[[1.66,0]],"id":40917619}],"con":true,"img":false}]}
{"op":"mcm","clk":"5348976598","pt":1646222666952,"mc":[{"id":"1.195453681","rc":[{"atl":[[1.66,12.2]],"id":40917619}],"con":true,"img":false}]}
{"op":"mcm","clk":"5348976644","pt":1646222667693,"mc":[{"id":"1.195453681","rc":[{"atl":[[2.68,2],[2.7,0]],"id":38554545}],"con":true,"img":false}]}
{"op":"mcm","clk":"5348976957","pt":1646222671760,"mc":[{"id":"1.195453681","rc":[{"atl":[[2.72,0]],"id":38554545}],"con":true,"img":false}]}
{"op":"mcm","clk":"5348976967","pt":1646222671872,"mc":[{"id":"1.195453681","rc":[{"atl":[[2.68,4],[2.7,2]],"id":38554545}],"con":true,"img":false}]}
{"op":"mcm","clk":"5348977032","pt":1646222672659,"mc":[{"id":"1.195453681","rc":[{"atl":[[2.68,0]],"id":38554545}],"con":true,"img":false}]}
{"op":"mcm","clk":"5348977066","pt":1646222673186,"mc":[{"id":"1.195453681","rc":[{"atb":[[1.51,10.57],[1.61,8.84]],"id":40917619},{"atl":[[1.66,4.61]],"id":40917619},{"trd":[[1.66,15.19]],"ltp":1.66,"tv":15.19,"id":40917619},{"atb":[[1.85,6.34],[1.75,7.19],[1.65,8.3]],"id":38554545},{"atl":[[2.7,6]],"id":38554545}],"con":true,"img":false}]}
{"op":"mcm","clk":"5348977081","pt":1646222673393,"mc":[{"id":"1.195453681","rc":[{"atb":[[1.62,12.18]],"id":40917619}],"con":true,"img":false}]}
{"op":"mcm","clk":"5348977122","pt":1646222674071,"mc":[{"id":"1.195453681","rc":[{"atb":[[1.49,59.49]],"id":40917619}],"con":true,"img":false}]}
{"op":"mcm","clk":"5348977184","pt":1646222675066,"mc":[{"id":"1.195453681","rc":[{"atb":[[1.63,0]],"id":40917619}],"con":true,"img":false}]}
{"op":"mcm","clk":"5348977316","pt":1646222676683,"mc":[{"id":"1.195453681","rc":[{"atl":[[1.66,2.94]],"id":40917619},{"trd":[[1.66,16.85]],"ltp":1.66,"tv":16.85,"id":40917619},{"atb":[[2.5,0]],"id":38554545},{"trd":[[2.5,15.48]],"ltp":2.5,"tv":15.48,"id":38554545}],"con":true,"img":false}]}
{"op":"mcm","clk":"5348977324","pt":1646222676789,"mc":[{"id":"1.195453681","rc":[{"atl":[[2.68,7.13]],"id":38554545}],"con":true,"img":false}]}
{"op":"mcm","clk":"5348977346","pt":1646222677052,"mc":[{"id":"1.195453681","rc":[{"atb":[[1.46,0],[1.52,56.06]],"id":40917619},{"atb":[[2.36,0]],"id":38554545},{"atl":[[2.66,2],[2.7,4]],"id":38554545}],"con":true,"img":false}]}
{"op":"mcm","clk":"5348977372","pt":1646222677371,"mc":[{"id":"1.195453681","rc":[{"atb":[[2.48,7.22]],"id":38554545}],"con":true,"img":false}]}
{"op":"mcm","clk":"5348977422","pt":1646222677993,"mc":[{"id":"1.195453681","rc":[{"atl":[[1.66,0]],"id":40917619},{"atl":[[2.66,9.15]],"id":38554545}],"con":true,"img":false}]}
{"op":"mcm","clk":"5348977466","pt":1646222678562,"mc":[{"id":"1.195453681","rc":[{"atb":[[1.59,49.4]],"id":40917619},{"atb":[[2.48,26.91]],"id":38554545}],"con":true,"img":false}]}
{"op":"mcm","clk":"5348977490","pt":1646222678981,"mc":[{"id":"1.195453681","rc":[{"atb":[[2.5,7.19]],"id":38554545}],"con":true,"img":false}]}
{"op":"mcm","clk":"5348978198","pt":1646222687031,"mc":[{"id":"1.195453681","marketDefinition":{"bspMarket":false,"turnInPlayEnabled":false,"persistenceEnabled":false,"marketBaseRate":7.0,"eventId":"31272494","eventTypeId":"4339","numberOfWinners":1,"bettingType":"ODDS","marketType":"MATCH_BET","marketTime":"2022-03-02T12:04:00.000Z","suspendTime":"2022-03-02T12:04:00.000Z","bspReconciled":false,"complete":true,"inPlay":false,"crossMatching":true,"runnersVoidable":false,"numberOfActiveRunners":2,"betDelay":0,"status":"SUSPENDED","runners":[{"status":"ACTIVE","sortPriority":1,"id":40917619,"name":"5. Kens Crew"},{"status":"ACTIVE","sortPriority":2,"id":38554545,"name":"6. Call Me Harvey"}],"regulators":["MR_INT"],"venue":"Traralgon","countryCode":"AU","discountAllowed":true,"timezone":"Australia/Sydney","openDate":"2022-03-02T08:31:00.000Z","version":4383063380,"name":"Kens Crew v Call Me Harvey","eventName":"Traralgon (AUS) 2nd Mar"},"rc":[],"con":true,"img":false}]}
{"op":"mcm","clk":"5348978198","pt":1646222687031,"mc":[{"id":"1.195453681","rc":[{"atb":[[1.59,0],[1.57,0],[1.62,0],[1.49,0],[1.51,0],[1.61,0],[1.52,0]],"id":40917619},{"atl":[[1.67,0],[1.7,0],[1.78,0],[1.94,0],[1.87,0],[1.95,0],[1.69,0],[1.76,0]],"id":40917619},{"atb":[[2.5,0],[1.84,0],[1.85,0],[2.12,0],[2.44,0],[1.95,0],[2.48,0],[2.34,0],[1.82,0],[2.42,0],[2.38,0],[2.46,0],[1.86,0],[1.75,0],[1.65,0]],"id":38554545},{"atl":[[3.2,0],[3.1,0],[3.35,0],[2.66,0],[3.15,0],[3.25,0],[3.3,0],[2.68,0],[3.05,0],[2.7,0]],"id":38554545}],"con":true,"img":false}]}
{"op":"mcm","clk":"5348982140","pt":1646222741756,"mc":[{"id":"1.195453681","rc":[{"trd":[[1.72,0],[1.8,0],[1.7,0],[1.86,0],[1.66,0],[1.93,0],[1.95,0],[1.71,0],[1.69,0],[1.76,0]],"ltp":1.72,"tv":0.0,"id":40917619},{"trd":[[2.4,0],[2.54,0],[1.81,0],[2.5,0],[2.42,0],[2.38,0],[2.52,0],[2.28,0],[2.44,0],[2.26,0],[2.34,0]],"ltp":2.4,"tv":0.0,"id":38554545}],"con":true,"img":false}]}
{"op":"mcm","clk":"5348982208","pt":1646222742733,"mc":[{"id":"1.195453681","marketDefinition":{"bspMarket":false,"turnInPlayEnabled":false,"persistenceEnabled":false,"marketBaseRate":7.0,"eventId":"31272494","eventTypeId":"4339","numberOfWinners":1,"bettingType":"ODDS","marketType":"MATCH_BET","marketTime":"2022-03-02T12:04:00.000Z","suspendTime":"2022-03-02T12:04:00.000Z","bspReconciled":false,"complete":true,"inPlay":false,"crossMatching":false,"runnersVoidable":false,"numberOfActiveRunners":0,"betDelay":0,"status":"CLOSED","settledTime":"2022-03-02T12:05:40.000Z","runners":[{"status":"WINNER","sortPriority":1,"id":40917619,"name":"5. Kens Crew"},{"status":"LOSER","sortPriority":2,"id":38554545,"name":"6. Call Me Harvey"}],"regulators":["MR_INT"],"venue":"Traralgon","countryCode":"AU","discountAllowed":true,"timezone":"Australia/Sydney","openDate":"2022-03-02T08:31:00.000Z","version":4383065812,"name":"Kens Crew v Call Me Harvey","eventName":"Traralgon (AUS) 2nd Mar"},"rc":[],"con":true,"img":false}]}
