{"op":"mcm","clk":"5352092076","pt":1646182318991,"mc":[{"id":"1.195503860","marketDefinition":{"bspMarket":false,"turnInPlayEnabled":false,"persistenceEnabled":false,"marketBaseRate":7.0,"eventId":"31272499","eventTypeId":"4339","numberOfWinners":1,"bettingType":"ODDS","marketType":"EXACTA","marketTime":"2022-03-02T08:34:00.000Z","suspendTime":"2022-03-02T08:34:00.000Z","bspReconciled":false,"complete":true,"inPlay":false,"crossMatching":false,"runnersVoidable":false,"numberOfActiveRunners":56,"betDelay":0,"status":"OPEN","runners":[{"status":"ACTIVE","sortPriority":1,"id":41419585,"name":"1 - 2"},{"status":"ACTIVE","sortPriority":2,"id":41419586,"name":"1 - 3"},{"status":"ACTIVE","sortPriority":3,"id":41419587,"name":"1 - 4"},{"status":"ACTIVE","sortPriority":4,"id":41419588,"name":"1 - 5"},{"status":"ACTIVE","sortPriority":5,"id":41419589,"name":"1 - 6"},{"status":"ACTIVE","sortPriority":6,"id":41419590,"name":"1 - 7"},{"status":"ACTIVE","sortPriority":7,"id":41419591,"name":"1 - 8"},{"status":"ACTIVE","sortPriority":8,"id":41419592,"name":"2 - 1"},{"status":"ACTIVE","sortPriority":9,"id":41419593,"name":"2 - 3"},{"status":"ACTIVE","sortPriority":10,"id":41419594,"name":"2 - 4"},{"status":"ACTIVE","sortPriority":11,"id":41419595,"name":"2 - 5"},{"status":"ACTIVE","sortPriority":12,"id":41419596,"name":"2 - 6"},{"status":"ACTIVE","sortPriority":13,"id":41419597,"name":"2 - 7"},{"status":"ACTIVE","sortPriority":14,"id":41419598,"name":"2 - 8"},{"status":"ACTIVE","sortPriority":15,"id":41419599,"name":"3 - 1"},{"status":"ACTIVE","sortPriority":16,"id":41419600,"name":"3 - 2"},{"status":"ACTIVE","sortPriority":17,"id":41419601,"name":"3 - 4"},{"status":"ACTIVE","sortPriority":18,"id":41419602,"name":"3 - 5"},{"status":"ACTIVE","sortPriority":19,"id":41419603,"name":"3 - 6"},{"status":"ACTIVE","sortPriority":20,"id":41419604,"name":"3 - 7"},{"status":"ACTIVE","sortPriority":21,"id":41419605,"name":"3 - 8"},{"status":"ACTIVE","sortPriority":22,"id":41419606,"name":"4 - 1"},{"status":"ACTIVE","sortPriority":23,"id":41419607,"name":"4 - 2"},{"status":"ACTIVE","sortPriority":24,"id":41419608,"name":"4 - 3"},{"status":"ACTIVE","sortPriority":25,"id":41419609,"name":"4 - 5"},{"status":"ACTIVE","sortPriority":26,"id":41419610,"name":"4 - 6"},{"status":"ACTIVE","sortPriority":27,"id":41419611,"name":"4 - 7"},{"status":"ACTIVE","sortPriority":28,"id":41419612,"name":"4 - 8"},{"status":"ACTIVE","sortPriority":29,"id":41419613,"name":"5 - 1"},{"status":"ACTIVE","sortPriority":30,"id":41419614,"name":"5 - 2"},{"status":"ACTIVE","sortPriority":31,"id":41419615,"name":"5 - 3"},{"status":"ACTIVE","sortPriority":32,"id":41419616,"name":"5 - 4"},{"status":"ACTIVE","sortPriority":33,"id":41419617,"name":"5 - 6"},{"status":"ACTIVE","sortPriority":34,"id":41419618,"name":"5 - 7"},{"status":"ACTIVE","sortPriority":35,"id":41419619,"name":"5 - 8"},{"status":"ACTIVE","sortPriority":36,"id":41419620,"name":"6 - 1"},{"status":"ACTIVE","sortPriority":37,"id":41419621,"name":"6 - 2"},{"status":"ACTIVE","sortPriority":38,"id":41419622,"name":"6 - 3"},{"status":"ACTIVE","sortPriority":39,"id":41419623,"name":"6 - 4"},{"status":"ACTIVE","sortPriority":40,"id":41419624,"name":"6 - 5"},{"status":"ACTIVE","sortPriority":41,"id":41419625,"name":"6 - 7"},{"status":"ACTIVE","sortPriority":42,"id":41419626,"name":"6 - 8"},{"status":"ACTIVE","sortPriority":43,"id":41419627,"name":"7 - 1"},{"status":"ACTIVE","sortPriority":44,"id":41419628,"name":"7 - 2"},{"status":"ACTIVE","sortPriority":45,"id":41419629,"name":"7 - 3"},{"status":"ACTIVE","sortPriority":46,"id":41419630,"name":"7 - 4"},{"status":"ACTIVE","sortPriority":47,"id":41419631,"name":"7 - 5"},{"status":"ACTIVE","sortPriority":48,"id":41419632,"name":"7 - 6"},{"status":"ACTIVE","sortPriority":49,"id":41419633,"name":"7 - 8"},{"status":"ACTIVE","sortPriority":50,"id":41419634,"name":"8 - 1"},{"status":"ACTIVE","sortPriority":51,"id":41419635,"name":"8 - 2"},{"status":"ACTIVE","sortPriority":52,"id":41419636,"name":"8 - 3"},{"status":"ACTIVE","sortPriority":53,"id":41419637,"name":"8 - 4"},{"status":"ACTIVE","sortPriority":54,"id":41419638,"name":"8 - 5"},{"status":"ACTIVE","sortPriority":55,"id":41419639,"name":"8 - 6"},{"status":"ACTIVE","sortPriority":56,"id":41419640,"name":"8 - 7"}],"regulators":["MR_INT"],"venue":"Rockhampton","countryCode":"AU","discountAllowed":true,"timezone":"Australia/Queensland","openDate":"2022-03-02T08:34:00.000Z","version":4382565134,"name":"Exacta","eventName":"Rockhampton (AUS) 2nd Mar"},"rc":[],"con":true,"img":false}]}
{"op":"mcm","clk":"5352095595","pt":1646182411189,"mc":[{"id":"1.195503860","rc":[{"atb":[[10,29.56],[25,8.31],[15,14.25]],"id":41419609},{"atb":[[150,1.78],[400,0.5],[250,0.8]],"id":41419638},{"atb":[[140,1.43],[48,4.24],[29,9.5]],"id":41419605},{"atb":[[600,0.44],[700,0.28],[850,0.23]],"id":41419634},{"atb":[[16,17.74],[44,4.64],[22,9.5]],"id":41419617},{"atb":[[32,6.44],[80,2.52],[21,13.3]],"id":41419613},{"atb":[[3.6,102.35],[5.7,42.46],[4.2,62.36]],"id":41419593},{"atb":[[34,6.04],[18.5,11.4],[13.5,21.28]],"id":41419622},{"atb":[[140,1.91],[390,0.51],[240,0.83]],"id":41419589},{"atb":[[16,17.74],[44,4.64],[22,9.5]],"id":41419618},{"atb":[[17,12.47],[9.8,22.68],[7.8,39.13]],"id":41419601},{"atb":[[16.5,17.17],[46,4.43],[23,9.07]],"id":41419630},{"atb":[[18,11.73],[10.5,21],[8.2,36.96]],"id":41419597},{"atb":[[600,0.44],[700,0.28],[850,0.23]],"id":41419626},{"atb":[[600,0.44],[700,0.28],[850,0.23]],"id":41419639},{"atb":[[32,6.44],[80,2.52],[21,13.3]],"id":41419606},{"atb":[[75,2.69],[20,14],[30,6.88]],"id":41419635},{"atb":[[17,12.47],[9.8,22.68],[7.8,39.13]],"id":41419602},{"atb":[[34,6.04],[18.5,11.4],[13.5,21.28]],"id":41419585},{"atb":[[5.6,57.85],[7.2,32.19],[10.5,21]],"id":41419614},{"atb":[[16,17.74],[44,4.64],[22,9.5]],"id":41419610},{"atb":[[16.5,17.17],[46,4.43],[23,9.07]],"id":41419623},{"atb":[[140,1.91],[390,0.51],[240,0.83]],"id":41419590},{"atb":[[340,0.58],[190,1.05],[95,2.83]],"id":41419619},{"atb":[[17.5,16.12],[50,4.07],[25,8.31]],"id":41419586},{"atb":[[16.5,17.17],[46,4.43],[23,9.07]],"id":41419631},{"atb":[[16.5,17.17],[46,4.43],[23,9.07]],"id":41419598},{"atb":[[370,0.53],[220,0.9],[120,2.23]],"id":41419627},{"atb":[[5.6,43.39],[4.6,73.92],[8.2,27.72]],"id":41419594},{"atb":[[600,0.44],[700,0.28],[850,0.23]],"id":41419640},{"atb":[[5.6,57.85],[7.2,32.19],[10.5,21]],"id":41419607},{"atb":[[80,2.52],[42,6.48],[210,0.95]],"id":41419636},{"atb":[[17,12.47],[12,24.19],[29,7.12]],"id":41419603},{"atb":[[18,11.73],[10.5,21],[8.2,36.96]],"id":41419615},{"atb":[[16,17.74],[44,4.64],[22,9.5]],"id":41419611},{"atb":[[16.5,17.17],[46,4.43],[23,9.07]],"id":41419624},{"atb":[[600,0.44],[700,0.28],[850,0.23]],"id":41419591},{"atb":[[370,0.53],[220,0.9],[120,2.23]],"id":41419620},{"atb":[[36,5.7],[90,2.24],[23,12.09]],"id":41419587},{"atb":[[150,1.33],[50,4.07],[30,9.17]],"id":41419632},{"atb":[[16.5,17.17],[46,4.43],[23,9.07]],"id":41419599},{"atb":[[9.6,30.94],[23,9.07],[14,15.35]],"id":41419628},{"atb":[[5.6,43.39],[4.6,73.92],[8.2,27.72]],"id":41419595},{"atb":[[18,11.73],[10.5,21],[8.2,36.96]],"id":41419608},{"atb":[[150,1.78],[400,0.5],[250,0.8]],"id":41419637},{"atb":[[17,12.47],[12,24.19],[29,7.12]],"id":41419604},{"atb":[[10,29.56],[25,8.31],[15,14.25]],"id":41419616},{"atb":[[340,0.58],[190,1.05],[95,2.83]],"id":41419612},{"atb":[[150,1.33],[50,4.07],[30,9.17]],"id":41419625},{"atb":[[10.5,28.01],[26,7.98],[15.5,13.76]],"id":41419592},{"atb":[[9.6,30.94],[23,9.07],[14,15.35]],"id":41419621},{"atb":[[36,5.7],[90,2.24],[23,12.09]],"id":41419588},{"atb":[[600,0.44],[700,0.28],[850,0.23]],"id":41419633},{"atb":[[7.4,31.18],[5.2,47.52],[4.2,83.16]],"id":41419600},{"atb":[[34,6.04],[18.5,11.4],[13.5,21.28]],"id":41419629},{"atb":[[18,11.73],[10.5,21],[8.2,36.96]],"id":41419596}],"con":true,"img":false}]}
{"op":"mcm","clk":"5352145805","pt":1646183565635,"mc":[{"id":"1.195503860","marketDefinition":{"bspMarket":false,"turnInPlayEnabled":false,"persistenceEnabled":false,"marketBaseRate":7.0,"eventId":"31272499","eventTypeId":"4339","numberOfWinners":1,"bettingType":"ODDS","marketType":"EXACTA","marketTime":"2022-03-02T08:28:00.000Z","suspendTime":"2022-03-02T08:28:00.000Z","bspReconciled":false,"complete":true,"inPlay":false,"crossMatching":false,"runnersVoidable":false,"numberOfActiveRunners":56,"betDelay":0,"status":"OPEN","runners":[{"status":"ACTIVE","sortPriority":1,"id":41419585,"name":"1 - 2"},{"status":"ACTIVE","sortPriority":2,"id":41419586,"name":"1 - 3"},{"status":"ACTIVE","sortPriority":3,"id":41419587,"name":"1 - 4"},{"status":"ACTIVE","sortPriority":4,"id":41419588,"name":"1 - 5"},{"status":"ACTIVE","sortPriority":5,"id":41419589,"name":"1 - 6"},{"status":"ACTIVE","sortPriority":6,"id":41419590,"name":"1 - 7"},{"status":"ACTIVE","sortPriority":7,"id":41419591,"name":"1 - 8"},{"status":"ACTIVE","sortPriority":8,"id":41419592,"name":"2 - 1"},{"status":"ACTIVE","sortPriority":9,"id":41419593,"name":"2 - 3"},{"status":"ACTIVE","sortPriority":10,"id":41419594,"name":"2 - 4"},{"status":"ACTIVE","sortPriority":11,"id":41419595,"name":"2 - 5"},{"status":"ACTIVE","sortPriority":12,"id":41419596,"name":"2 - 6"},{"status":"ACTIVE","sortPriority":13,"id":41419597,"name":"2 - 7"},{"status":"ACTIVE","sortPriority":14,"id":41419598,"name":"2 - 8"},{"status":"ACTIVE","sortPriority":15,"id":41419599,"name":"3 - 1"},{"status":"ACTIVE","sortPriority":16,"id":41419600,"name":"3 - 2"},{"status":"ACTIVE","sortPriority":17,"id":41419601,"name":"3 - 4"},{"status":"ACTIVE","sortPriority":18,"id":41419602,"name":"3 - 5"},{"status":"ACTIVE","sortPriority":19,"id":41419603,"name":"3 - 6"},{"status":"ACTIVE","sortPriority":20,"id":41419604,"name":"3 - 7"},{"status":"ACTIVE","sortPriority":21,"id":41419605,"name":"3 - 8"},{"status":"ACTIVE","sortPriority":22,"id":41419606,"name":"4 - 1"},{"status":"ACTIVE","sortPriority":23,"id":41419607,"name":"4 - 2"},{"status":"ACTIVE","sortPriority":24,"id":41419608,"name":"4 - 3"},{"status":"ACTIVE","sortPriority":25,"id":41419609,"name":"4 - 5"},{"status":"ACTIVE","sortPriority":26,"id":41419610,"name":"4 - 6"},{"status":"ACTIVE","sortPriority":27,"id":41419611,"name":"4 - 7"},{"status":"ACTIVE","sortPriority":28,"id":41419612,"name":"4 - 8"},{"status":"ACTIVE","sortPriority":29,"id":41419613,"name":"5 - 1"},{"status":"ACTIVE","sortPriority":30,"id":41419614,"name":"5 - 2"},{"status":"ACTIVE","sortPriority":31,"id":41419615,"name":"5 - 3"},{"status":"ACTIVE","sortPriority":32,"id":41419616,"name":"5 - 4"},{"status":"ACTIVE","sortPriority":33,"id":41419617,"name":"5 - 6"},{"status":"ACTIVE","sortPriority":34,"id":41419618,"name":"5 - 7"},{"status":"ACTIVE","sortPriority":35,"id":41419619,"name":"5 - 8"},{"status":"ACTIVE","sortPriority":36,"id":41419620,"name":"6 - 1"},{"status":"ACTIVE","sortPriority":37,"id":41419621,"name":"6 - 2"},{"status":"ACTIVE","sortPriority":38,"id":41419622,"name":"6 - 3"},{"status":"ACTIVE","sortPriority":39,"id":41419623,"name":"6 - 4"},{"status":"ACTIVE","sortPriority":40,"id":41419624,"name":"6 - 5"},{"status":"ACTIVE","sortPriority":41,"id":41419625,"name":"6 - 7"},{"status":"ACTIVE","sortPriority":42,"id":41419626,"name":"6 - 8"},{"status":"ACTIVE","sortPriority":43,"id":41419627,"name":"7 - 1"},{"status":"ACTIVE","sortPriority":44,"id":41419628,"name":"7 - 2"},{"status":"ACTIVE","sortPriority":45,"id":41419629,"name":"7 - 3"},{"status":"ACTIVE","sortPriority":46,"id":41419630,"name":"7 - 4"},{"status":"ACTIVE","sortPriority":47,"id":41419631,"name":"7 - 5"},{"status":"ACTIVE","sortPriority":48,"id":41419632,"name":"7 - 6"},{"status":"ACTIVE","sortPriority":49,"id":41419633,"name":"7 - 8"},{"status":"ACTIVE","sortPriority":50,"id":41419634,"name":"8 - 1"},{"status":"ACTIVE","sortPriority":51,"id":41419635,"name":"8 - 2"},{"status":"ACTIVE","sortPriority":52,"id":41419636,"name":"8 - 3"},{"status":"ACTIVE","sortPriority":53,"id":41419637,"name":"8 - 4"},{"status":"ACTIVE","sortPriority":54,"id":41419638,"name":"8 - 5"},{"status":"ACTIVE","sortPriority":55,"id":41419639,"name":"8 - 6"},{"status":"ACTIVE","sortPriority":56,"id":41419640,"name":"8 - 7"}],"regulators":["MR_INT"],"venue":"Rockhampton","countryCode":"AU","discountAllowed":true,"timezone":"Australia/Queensland","openDate":"2022-03-02T08:34:00.000Z","version":4382597814,"name":"Exacta","eventName":"Rockhampton (AUS) 2nd Mar"},"rc":[],"con":true,"img":false}]}
{"op":"mcm","clk":"5352146184","pt":1646183572645,"mc":[{"id":"1.195503860","marketDefinition":{"bspMarket":false,"turnInPlayEnabled":false,"persistenceEnabled":false,"marketBaseRate":7.0,"eventId":"31272499","eventTypeId":"4339","numberOfWinners":1,"bettingType":"ODDS","marketType":"EXACTA","marketTime":"2022-03-02T08:28:00.000Z","suspendTime":"2022-03-02T08:28:00.000Z","bspReconciled":false,"complete":true,"inPlay":false,"crossMatching":false,"runnersVoidable":false,"numberOfActiveRunners":56,"betDelay":0,"status":"OPEN","runners":[{"status":"ACTIVE","sortPriority":1,"id":41419585,"name":"1 - 2"},{"status":"ACTIVE","sortPriority":2,"id":41419586,"name":"1 - 3"},{"status":"ACTIVE","sortPriority":3,"id":41419587,"name":"1 - 4"},{"status":"ACTIVE","sortPriority":4,"id":41419588,"name":"1 - 5"},{"status":"ACTIVE","sortPriority":5,"id":41419589,"name":"1 - 6"},{"status":"ACTIVE","sortPriority":6,"id":41419590,"name":"1 - 7"},{"status":"ACTIVE","sortPriority":7,"id":41419591,"name":"1 - 8"},{"status":"ACTIVE","sortPriority":8,"id":41419592,"name":"2 - 1"},{"status":"ACTIVE","sortPriority":9,"id":41419593,"name":"2 - 3"},{"status":"ACTIVE","sortPriority":10,"id":41419594,"name":"2 - 4"},{"status":"ACTIVE","sortPriority":11,"id":41419595,"name":"2 - 5"},{"status":"ACTIVE","sortPriority":12,"id":41419596,"name":"2 - 6"},{"status":"ACTIVE","sortPriority":13,"id":41419597,"name":"2 - 7"},{"status":"ACTIVE","sortPriority":14,"id":41419598,"name":"2 - 8"},{"status":"ACTIVE","sortPriority":15,"id":41419599,"name":"3 - 1"},{"status":"ACTIVE","sortPriority":16,"id":41419600,"name":"3 - 2"},{"status":"ACTIVE","sortPriority":17,"id":41419601,"name":"3 - 4"},{"status":"ACTIVE","sortPriority":18,"id":41419602,"name":"3 - 5"},{"status":"ACTIVE","sortPriority":19,"id":41419603,"name":"3 - 6"},{"status":"ACTIVE","sortPriority":20,"id":41419604,"name":"3 - 7"},{"status":"ACTIVE","sortPriority":21,"id":41419605,"name":"3 - 8"},{"status":"ACTIVE","sortPriority":22,"id":41419606,"name":"4 - 1"},{"status":"ACTIVE","sortPriority":23,"id":41419607,"name":"4 - 2"},{"status":"ACTIVE","sortPriority":24,"id":41419608,"name":"4 - 3"},{"status":"ACTIVE","sortPriority":25,"id":41419609,"name":"4 - 5"},{"status":"ACTIVE","sortPriority":26,"id":41419610,"name":"4 - 6"},{"status":"ACTIVE","sortPriority":27,"id":41419611,"name":"4 - 7"},{"status":"ACTIVE","sortPriority":28,"id":41419612,"name":"4 - 8"},{"status":"ACTIVE","sortPriority":29,"id":41419613,"name":"5 - 1"},{"status":"ACTIVE","sortPriority":30,"id":41419614,"name":"5 - 2"},{"status":"ACTIVE","sortPriority":31,"id":41419615,"name":"5 - 3"},{"status":"ACTIVE","sortPriority":32,"id":41419616,"name":"5 - 4"},{"status":"ACTIVE","sortPriority":33,"id":41419617,"name":"5 - 6"},{"status":"ACTIVE","sortPriority":34,"id":41419618,"name":"5 - 7"},{"status":"ACTIVE","sortPriority":35,"id":41419619,"name":"5 - 8"},{"status":"ACTIVE","sortPriority":36,"id":41419620,"name":"6 - 1"},{"status":"ACTIVE","sortPriority":37,"id":41419621,"name":"6 - 2"},{"status":"ACTIVE","sortPriority":38,"id":41419622,"name":"6 - 3"},{"status":"ACTIVE","sortPriority":39,"id":41419623,"name":"6 - 4"},{"status":"ACTIVE","sortPriority":40,"id":41419624,"name":"6 - 5"},{"status":"ACTIVE","sortPriority":41,"id":41419625,"name":"6 - 7"},{"status":"ACTIVE","sortPriority":42,"id":41419626,"name":"6 - 8"},{"status":"ACTIVE","sortPriority":43,"id":41419627,"name":"7 - 1"},{"status":"ACTIVE","sortPriority":44,"id":41419628,"name":"7 - 2"},{"status":"ACTIVE","sortPriority":45,"id":41419629,"name":"7 - 3"},{"status":"ACTIVE","sortPriority":46,"id":41419630,"name":"7 - 4"},{"status":"ACTIVE","sortPriority":47,"id":41419631,"name":"7 - 5"},{"status":"ACTIVE","sortPriority":48,"id":41419632,"name":"7 - 6"},{"status":"ACTIVE","sortPriority":49,"id":41419633,"name":"7 - 8"},{"status":"ACTIVE","sortPriority":50,"id":41419634,"name":"8 - 1"},{"status":"ACTIVE","sortPriority":51,"id":41419635,"name":"8 - 2"},{"status":"ACTIVE","sortPriority":52,"id":41419636,"name":"8 - 3"},{"status":"ACTIVE","sortPriority":53,"id":41419637,"name":"8 - 4"},{"status":"ACTIVE","sortPriority":54,"id":41419638,"name":"8 - 5"},{"status":"ACTIVE","sortPriority":55,"id":41419639,"name":"8 - 6"},{"status":"ACTIVE","sortPriority":56,"id":41419640,"name":"8 - 7"}],"regulators":["MR_INT"],"venue":"Rockhampton","countryCode":"AU","discountAllowed":true,"timezone":"Australia/Queensland","openDate":"2022-03-02T08:28:00.000Z","version":4382597888,"name":"Exacta","eventName":"Rockhampton (AUS) 2nd Mar"},"rc":[],"con":true,"img":false}]}
{"op":"mcm","clk":"5352239429","pt":1646185602748,"mc":[{"id":"1.195503860","marketDefinition":{"bspMarket":false,"turnInPlayEnabled":false,"persistenceEnabled":false,"marketBaseRate":7.0,"eventId":"31272499","eventTypeId":"4339","numberOfWinners":1,"bettingType":"ODDS","marketType":"EXACTA","marketTime":"2022-03-02T08:28:00.000Z","suspendTime":"2022-03-02T08:28:00.000Z","bspReconciled":false,"complete":true,"inPlay":false,"crossMatching":false,"runnersVoidable":false,"numberOfActiveRunners":56,"betDelay":0,"status":"OPEN","runners":[{"status":"ACTIVE","sortPriority":1,"id":41419585,"name":"1 - 2"},{"status":"ACTIVE","sortPriority":2,"id":41419586,"name":"1 - 3"},{"status":"ACTIVE","sortPriority":3,"id":41419587,"name":"1 - 4"},{"status":"ACTIVE","sortPriority":4,"id":41419588,"name":"1 - 5"},{"status":"ACTIVE","sortPriority":5,"id":41419589,"name":"1 - 6"},{"status":"ACTIVE","sortPriority":6,"id":41419590,"name":"1 - 7"},{"status":"ACTIVE","sortPriority":7,"id":41419591,"name":"1 - 8"},{"status":"ACTIVE","sortPriority":8,"id":41419592,"name":"2 - 1"},{"status":"ACTIVE","sortPriority":9,"id":41419593,"name":"2 - 3"},{"status":"ACTIVE","sortPriority":10,"id":41419594,"name":"2 - 4"},{"status":"ACTIVE","sortPriority":11,"id":41419595,"name":"2 - 5"},{"status":"ACTIVE","sortPriority":12,"id":41419596,"name":"2 - 6"},{"status":"ACTIVE","sortPriority":13,"id":41419597,"name":"2 - 7"},{"status":"ACTIVE","sortPriority":14,"id":41419598,"name":"2 - 8"},{"status":"ACTIVE","sortPriority":15,"id":41419599,"name":"3 - 1"},{"status":"ACTIVE","sortPriority":16,"id":41419600,"name":"3 - 2"},{"status":"ACTIVE","sortPriority":17,"id":41419601,"name":"3 - 4"},{"status":"ACTIVE","sortPriority":18,"id":41419602,"name":"3 - 5"},{"status":"ACTIVE","sortPriority":19,"id":41419603,"name":"3 - 6"},{"status":"ACTIVE","sortPriority":20,"id":41419604,"name":"3 - 7"},{"status":"ACTIVE","sortPriority":21,"id":41419605,"name":"3 - 8"},{"status":"ACTIVE","sortPriority":22,"id":41419606,"name":"4 - 1"},{"status":"ACTIVE","sortPriority":23,"id":41419607,"name":"4 - 2"},{"status":"ACTIVE","sortPriority":24,"id":41419608,"name":"4 - 3"},{"status":"ACTIVE","sortPriority":25,"id":41419609,"name":"4 - 5"},{"status":"ACTIVE","sortPriority":26,"id":41419610,"name":"4 - 6"},{"status":"ACTIVE","sortPriority":27,"id":41419611,"name":"4 - 7"},{"status":"ACTIVE","sortPriority":28,"id":41419612,"name":"4 - 8"},{"status":"ACTIVE","sortPriority":29,"id":41419613,"name":"5 - 1"},{"status":"ACTIVE","sortPriority":30,"id":41419614,"name":"5 - 2"},{"status":"ACTIVE","sortPriority":31,"id":41419615,"name":"5 - 3"},{"status":"ACTIVE","sortPriority":32,"id":41419616,"name":"5 - 4"},{"status":"ACTIVE","sortPriority":33,"id":41419617,"name":"5 - 6"},{"status":"ACTIVE","sortPriority":34,"id":41419618,"name":"5 - 7"},{"status":"ACTIVE","sortPriority":35,"id":41419619,"name":"5 - 8"},{"status":"ACTIVE","sortPriority":36,"id":41419620,"name":"6 - 1"},{"status":"ACTIVE","sortPriority":37,"id":41419621,"name":"6 - 2"},{"status":"ACTIVE","sortPriority":38,"id":41419622,"name":"6 - 3"},{"status":"ACTIVE","sortPriority":39,"id":41419623,"name":"6 - 4"},{"status":"ACTIVE","sortPriority":40,"id":41419624,"name":"6 - 5"},{"status":"ACTIVE","sortPriority":41,"id":41419625,"name":"6 - 7"},{"status":"ACTIVE","sortPriority":42,"id":41419626,"name":"6 - 8"},{"status":"ACTIVE","sortPriority":43,"id":41419627,"name":"7 - 1"},{"status":"ACTIVE","sortPriority":44,"id":41419628,"name":"7 - 2"},{"status":"ACTIVE","sortPriority":45,"id":41419629,"name":"7 - 3"},{"status":"ACTIVE","sortPriority":46,"id":41419630,"name":"7 - 4"},{"status":"ACTIVE","sortPriority":47,"id":41419631,"name":"7 - 5"},{"status":"ACTIVE","sortPriority":48,"id":41419632,"name":"7 - 6"},{"status":"ACTIVE","sortPriority":49,"id":41419633,"name":"7 - 8"},{"status":"ACTIVE","sortPriority":50,"id":41419634,"name":"8 - 1"},{"status":"ACTIVE","sortPriority":51,"id":41419635,"name":"8 - 2"},{"status":"ACTIVE","sortPriority":52,"id":41419636,"name":"8 - 3"},{"status":"ACTIVE","sortPriority":53,"id":41419637,"name":"8 - 4"},{"status":"ACTIVE","sortPriority":54,"id":41419638,"name":"8 - 5"},{"status":"ACTIVE","sortPriority":55,"id":41419639,"name":"8 - 6"},{"status":"ACTIVE","sortPriority":56,"id":41419640,"name":"8 - 7"}],"regulators":["MR_INT"],"venue":"Rockhampton","countryCode":"AU","discountAllowed":true,"timezone":"Australia/Queensland","openDate":"2022-03-02T08:28:00.000Z","version":4382597888,"name":"Exacta","eventName":"Rockhampton (AUS) 2nd Mar"},"rc":[{"atb":[[10,29.61],[25,8.32],[15,14.28]],"id":41419609},{"atb":[[150,1.78],[400,0.5],[250,0.8]],"id":41419638},{"atb":[[140,1.43],[48,4.25],[29,9.52]],"id":41419605},{"atb":[[600,0.44],[700,0.28],[850,0.23]],"id":41419634},{"atb":[[16,17.77],[44,4.65],[22,9.52]],"id":41419617},{"atb":[[32,6.45],[80,2.53],[21,13.32]],"id":41419613},{"atb":[[3.6,102.51],[5.7,42.53],[4.2,62.46]],"id":41419593},{"atb":[[34,6.05],[18.5,11.42],[13.5,21.32]],"id":41419622},{"atb":[[140,1.91],[390,0.51],[240,0.83]],"id":41419589},{"atb":[[16,17.77],[44,4.65],[22,9.52]],"id":41419618},{"atb":[[17,12.49],[9.8,22.71],[7.8,39.19]],"id":41419601},{"atb":[[16.5,17.19],[46,4.44],[23,9.08]],"id":41419630},{"atb":[[18,11.75],[10.5,21.04],[8.2,37.01]],"id":41419597},{"atb":[[600,0.44],[700,0.28],[850,0.23]],"id":41419626},{"atb":[[600,0.44],[700,0.28],[850,0.23]],"id":41419639},{"atb":[[32,6.45],[80,2.53],[21,13.32]],"id":41419606},{"atb":[[75,2.69],[20,14.03],[30,6.89]],"id":41419635},{"atb":[[17,12.49],[9.8,22.71],[7.8,39.19]],"id":41419602},{"atb":[[34,6.05],[18.5,11.42],[13.5,21.32]],"id":41419585},{"atb":[[5.6,57.94],[7.2,32.24],[10.5,21.04]],"id":41419614},{"atb":[[16,17.77],[44,4.65],[22,9.52]],"id":41419610},{"atb":[[16.5,17.19],[46,4.44],[23,9.08]],"id":41419623},{"atb":[[140,1.91],[390,0.51],[240,0.83]],"id":41419590},{"atb":[[340,0.58],[190,1.05],[95,2.83]],"id":41419619},{"atb":[[17.5,16.15],[50,4.07],[25,8.32]],"id":41419586},{"atb":[[16.5,17.19],[46,4.44],[23,9.08]],"id":41419631},{"atb":[[16.5,17.19],[46,4.44],[23,9.08]],"id":41419598},{"atb":[[370,0.53],[220,0.91],[120,2.24]],"id":41419627},{"atb":[[5.6,43.45],[4.6,74.03],[8.2,27.76]],"id":41419594},{"atb":[[600,0.44],[700,0.28],[850,0.23]],"id":41419640},{"atb":[[5.6,57.94],[7.2,32.24],[10.5,21.04]],"id":41419607},{"atb":[[80,2.53],[42,6.49],[210,0.95]],"id":41419636},{"atb":[[17,12.49],[12,24.23],[29,7.13]],"id":41419603},{"atb":[[18,11.75],[10.5,21.04],[8.2,37.01]],"id":41419615},{"atb":[[16,17.77],[44,4.65],[22,9.52]],"id":41419611},{"atb":[[16.5,17.19],[46,4.44],[23,9.08]],"id":41419624},{"atb":[[600,0.44],[700,0.28],[850,0.23]],"id":41419591},{"atb":[[370,0.53],[220,0.91],[120,2.24]],"id":41419620},{"atb":[[36,5.7],[90,2.24],[23,12.11]],"id":41419587},{"atb":[[150,1.34],[50,4.07],[30,9.19]],"id":41419632},{"atb":[[16.5,17.19],[46,4.44],[23,9.08]],"id":41419599},{"atb":[[9.6,30.99],[23,9.08],[14,15.37]],"id":41419628},{"atb":[[5.6,43.45],[4.6,74.03],[8.2,27.76]],"id":41419595},{"atb":[[18,11.75],[10.5,21.04],[8.2,37.01]],"id":41419608},{"atb":[[150,1.78],[400,0.5],[250,0.8]],"id":41419637},{"atb":[[17,12.49],[12,24.23],[29,7.13]],"id":41419604},{"atb":[[10,29.61],[25,8.32],[15,14.28]],"id":41419616},{"atb":[[340,0.58],[190,1.05],[95,2.83]],"id":41419612},{"atb":[[150,1.34],[50,4.07],[30,9.19]],"id":41419625},{"atb":[[10.5,28.05],[26,7.99],[15.5,13.78]],"id":41419592},{"atb":[[9.6,30.99],[23,9.08],[14,15.37]],"id":41419621},{"atb":[[36,5.7],[90,2.24],[23,12.11]],"id":41419588},{"atb":[[600,0.44],[700,0.28],[850,0.23]],"id":41419633},{"atb":[[7.4,31.23],[5.2,47.59],[4.2,83.29]],"id":41419600},{"atb":[[34,6.05],[18.5,11.42],[13.5,21.32]],"id":41419629},{"atb":[[18,11.75],[10.5,21.04],[8.2,37.01]],"id":41419596}],"con":true,"img":true}]}
{"op":"mcm","clk":"5352466717","pt":1646191002691,"mc":[{"id":"1.195503860","marketDefinition":{"bspMarket":false,"turnInPlayEnabled":false,"persistenceEnabled":false,"marketBaseRate":7.0,"eventId":"31272499","eventTypeId":"4339","numberOfWinners":1,"bettingType":"ODDS","marketType":"EXACTA","marketTime":"2022-03-02T08:28:00.000Z","suspendTime":"2022-03-02T08:28:00.000Z","bspReconciled":false,"complete":true,"inPlay":false,"crossMatching":false,"runnersVoidable":false,"numberOfActiveRunners":56,"betDelay":0,"status":"OPEN","runners":[{"status":"ACTIVE","sortPriority":1,"id":41419585,"name":"1 - 2"},{"status":"ACTIVE","sortPriority":2,"id":41419586,"name":"1 - 3"},{"status":"ACTIVE","sortPriority":3,"id":41419587,"name":"1 - 4"},{"status":"ACTIVE","sortPriority":4,"id":41419588,"name":"1 - 5"},{"status":"ACTIVE","sortPriority":5,"id":41419589,"name":"1 - 6"},{"status":"ACTIVE","sortPriority":6,"id":41419590,"name":"1 - 7"},{"status":"ACTIVE","sortPriority":7,"id":41419591,"name":"1 - 8"},{"status":"ACTIVE","sortPriority":8,"id":41419592,"name":"2 - 1"},{"status":"ACTIVE","sortPriority":9,"id":41419593,"name":"2 - 3"},{"status":"ACTIVE","sortPriority":10,"id":41419594,"name":"2 - 4"},{"status":"ACTIVE","sortPriority":11,"id":41419595,"name":"2 - 5"},{"status":"ACTIVE","sortPriority":12,"id":41419596,"name":"2 - 6"},{"status":"ACTIVE","sortPriority":13,"id":41419597,"name":"2 - 7"},{"status":"ACTIVE","sortPriority":14,"id":41419598,"name":"2 - 8"},{"status":"ACTIVE","sortPriority":15,"id":41419599,"name":"3 - 1"},{"status":"ACTIVE","sortPriority":16,"id":41419600,"name":"3 - 2"},{"status":"ACTIVE","sortPriority":17,"id":41419601,"name":"3 - 4"},{"status":"ACTIVE","sortPriority":18,"id":41419602,"name":"3 - 5"},{"status":"ACTIVE","sortPriority":19,"id":41419603,"name":"3 - 6"},{"status":"ACTIVE","sortPriority":20,"id":41419604,"name":"3 - 7"},{"status":"ACTIVE","sortPriority":21,"id":41419605,"name":"3 - 8"},{"status":"ACTIVE","sortPriority":22,"id":41419606,"name":"4 - 1"},{"status":"ACTIVE","sortPriority":23,"id":41419607,"name":"4 - 2"},{"status":"ACTIVE","sortPriority":24,"id":41419608,"name":"4 - 3"},{"status":"ACTIVE","sortPriority":25,"id":41419609,"name":"4 - 5"},{"status":"ACTIVE","sortPriority":26,"id":41419610,"name":"4 - 6"},{"status":"ACTIVE","sortPriority":27,"id":41419611,"name":"4 - 7"},{"status":"ACTIVE","sortPriority":28,"id":41419612,"name":"4 - 8"},{"status":"ACTIVE","sortPriority":29,"id":41419613,"name":"5 - 1"},{"status":"ACTIVE","sortPriority":30,"id":41419614,"name":"5 - 2"},{"status":"ACTIVE","sortPriority":31,"id":41419615,"name":"5 - 3"},{"status":"ACTIVE","sortPriority":32,"id":41419616,"name":"5 - 4"},{"status":"ACTIVE","sortPriority":33,"id":41419617,"name":"5 - 6"},{"status":"ACTIVE","sortPriority":34,"id":41419618,"name":"5 - 7"},{"status":"ACTIVE","sortPriority":35,"id":41419619,"name":"5 - 8"},{"status":"ACTIVE","sortPriority":36,"id":41419620,"name":"6 - 1"},{"status":"ACTIVE","sortPriority":37,"id":41419621,"name":"6 - 2"},{"status":"ACTIVE","sortPriority":38,"id":41419622,"name":"6 - 3"},{"status":"ACTIVE","sortPriority":39,"id":41419623,"name":"6 - 4"},{"status":"ACTIVE","sortPriority":40,"id":41419624,"name":"6 - 5"},{"status":"ACTIVE","sortPriority":41,"id":41419625,"name":"6 - 7"},{"status":"ACTIVE","sortPriority":42,"id":41419626,"name":"6 - 8"},{"status":"ACTIVE","sortPriority":43,"id":41419627,"name":"7 - 1"},{"status":"ACTIVE","sortPriority":44,"id":41419628,"name":"7 - 2"},{"status":"ACTIVE","sortPriority":45,"id":41419629,"name":"7 - 3"},{"status":"ACTIVE","sortPriority":46,"id":41419630,"name":"7 - 4"},{"status":"ACTIVE","sortPriority":47,"id":41419631,"name":"7 - 5"},{"status":"ACTIVE","sortPriority":48,"id":41419632,"name":"7 - 6"},{"status":"ACTIVE","sortPriority":49,"id":41419633,"name":"7 - 8"},{"status":"ACTIVE","sortPriority":50,"id":41419634,"name":"8 - 1"},{"status":"ACTIVE","sortPriority":51,"id":41419635,"name":"8 - 2"},{"status":"ACTIVE","sortPriority":52,"id":41419636,"name":"8 - 3"},{"status":"ACTIVE","sortPriority":53,"id":41419637,"name":"8 - 4"},{"status":"ACTIVE","sortPriority":54,"id":41419638,"name":"8 - 5"},{"status":"ACTIVE","sortPriority":55,"id":41419639,"name":"8 - 6"},{"status":"ACTIVE","sortPriority":56,"id":41419640,"name":"8 - 7"}],"regulators":["MR_INT"],"venue":"Rockhampton","countryCode":"AU","discountAllowed":true,"timezone":"Australia/Queensland","openDate":"2022-03-02T08:28:00.000Z","version":4382597888,"name":"Exacta","eventName":"Rockhampton (AUS) 2nd Mar"},"rc":[{"atb":[[10,29.66],[25,8.34],[15,14.3]],"id":41419609},{"atb":[[150,1.79],[400,0.5],[250,0.8]],"id":41419638},{"atb":[[140,1.44],[48,4.26],[29,9.53]],"id":41419605},{"atb":[[600,0.44],[700,0.28],[850,0.23]],"id":41419634},{"atb":[[16,17.8],[44,4.65],[22,9.53]],"id":41419617},{"atb":[[32,6.46],[80,2.53],[21,13.34]],"id":41419613},{"atb":[[3.6,102.68],[5.7,42.6],[4.2,62.57]],"id":41419593},{"atb":[[34,6.06],[18.5,11.44],[13.5,21.35]],"id":41419622},{"atb":[[140,1.92],[390,0.51],[240,0.83]],"id":41419589},{"atb":[[16,17.8],[44,4.65],[22,9.53]],"id":41419618},{"atb":[[17,12.51],[9.8,22.75],[7.8,39.26]],"id":41419601},{"atb":[[16.5,17.22],[46,4.45],[23,9.09]],"id":41419630},{"atb":[[18,11.77],[10.5,21.07],[8.2,37.08]],"id":41419597},{"atb":[[600,0.44],[700,0.28],[850,0.23]],"id":41419626},{"atb":[[600,0.44],[700,0.28],[850,0.23]],"id":41419639},{"atb":[[32,6.46],[80,2.53],[21,13.34]],"id":41419606},{"atb":[[75,2.7],[20,14.05],[30,6.9]],"id":41419635},{"atb":[[17,12.51],[9.8,22.75],[7.8,39.26]],"id":41419602},{"atb":[[34,6.06],[18.5,11.44],[13.5,21.35]],"id":41419585},{"atb":[[5.6,58.04],[7.2,32.29],[10.5,21.07]],"id":41419614},{"atb":[[16,17.8],[44,4.65],[22,9.53]],"id":41419610},{"atb":[[16.5,17.22],[46,4.45],[23,9.09]],"id":41419623},{"atb":[[140,1.92],[390,0.51],[240,0.83]],"id":41419590},{"atb":[[340,0.58],[190,1.05],[95,2.84]],"id":41419619},{"atb":[[17.5,16.17],[50,4.08],[25,8.34]],"id":41419586},{"atb":[[16.5,17.22],[46,4.45],[23,9.09]],"id":41419631},{"atb":[[16.5,17.22],[46,4.45],[23,9.09]],"id":41419598},{"atb":[[370,0.54],[220,0.91],[120,2.24]],"id":41419627},{"atb":[[5.6,43.53],[4.6,74.16],[8.2,27.81]],"id":41419594},{"atb":[[600,0.44],[700,0.28],[850,0.23]],"id":41419640},{"atb":[[5.6,58.04],[7.2,32.29],[10.5,21.07]],"id":41419607},{"atb":[[80,2.53],[42,6.51],[210,0.95]],"id":41419636},{"atb":[[17,12.51],[12,24.27],[29,7.14]],"id":41419603},{"atb":[[18,11.77],[10.5,21.07],[8.2,37.08]],"id":41419615},{"atb":[[16,17.8],[44,4.65],[22,9.53]],"id":41419611},{"atb":[[16.5,17.22],[46,4.45],[23,9.09]],"id":41419624},{"atb":[[600,0.44],[700,0.28],[850,0.23]],"id":41419591},{"atb":[[370,0.54],[220,0.91],[120,2.24]],"id":41419620},{"atb":[[36,5.71],[90,2.25],[23,12.13]],"id":41419587},{"atb":[[150,1.34],[50,4.08],[30,9.2]],"id":41419632},{"atb":[[16.5,17.22],[46,4.45],[23,9.09]],"id":41419599},{"atb":[[9.6,31.04],[23,9.09],[14,15.4]],"id":41419628},{"atb":[[5.6,43.53],[4.6,74.16],[8.2,27.81]],"id":41419595},{"atb":[[18,11.77],[10.5,21.07],[8.2,37.08]],"id":41419608},{"atb":[[150,1.79],[400,0.5],[250,0.8]],"id":41419637},{"atb":[[17,12.51],[12,24.27],[29,7.14]],"id":41419604},{"atb":[[10,29.66],[25,8.34],[15,14.3]],"id":41419616},{"atb":[[340,0.58],[190,1.05],[95,2.84]],"id":41419612},{"atb":[[150,1.34],[50,4.08],[30,9.2]],"id":41419625},{"atb":[[10.5,28.1],[26,8],[15.5,13.8]],"id":41419592},{"atb":[[9.6,31.04],[23,9.09],[14,15.4]],"id":41419621},{"atb":[[36,5.71],[90,2.25],[23,12.13]],"id":41419588},{"atb":[[600,0.44],[700,0.28],[850,0.23]],"id":41419633},{"atb":[[7.4,31.28],[5.2,47.67],[4.2,83.43]],"id":41419600},{"atb":[[34,6.06],[18.5,11.44],[13.5,21.35]],"id":41419629},{"atb":[[18,11.77],[10.5,21.07],[8.2,37.08]],"id":41419596}],"con":true,"img":true}]}
{"op":"mcm","clk":"5352823523","pt":1646201802742,"mc":[{"id":"1.195503860","marketDefinition":{"bspMarket":false,"turnInPlayEnabled":false,"persistenceEnabled":false,"marketBaseRate":7.0,"eventId":"31272499","eventTypeId":"4339","numberOfWinners":1,"bettingType":"ODDS","marketType":"EXACTA","marketTime":"2022-03-02T08:28:00.000Z","suspendTime":"2022-03-02T08:28:00.000Z","bspReconciled":false,"complete":true,"inPlay":false,"crossMatching":false,"runnersVoidable":false,"numberOfActiveRunners":56,"betDelay":0,"status":"OPEN","runners":[{"status":"ACTIVE","sortPriority":1,"id":41419585,"name":"1 - 2"},{"status":"ACTIVE","sortPriority":2,"id":41419586,"name":"1 - 3"},{"status":"ACTIVE","sortPriority":3,"id":41419587,"name":"1 - 4"},{"status":"ACTIVE","sortPriority":4,"id":41419588,"name":"1 - 5"},{"status":"ACTIVE","sortPriority":5,"id":41419589,"name":"1 - 6"},{"status":"ACTIVE","sortPriority":6,"id":41419590,"name":"1 - 7"},{"status":"ACTIVE","sortPriority":7,"id":41419591,"name":"1 - 8"},{"status":"ACTIVE","sortPriority":8,"id":41419592,"name":"2 - 1"},{"status":"ACTIVE","sortPriority":9,"id":41419593,"name":"2 - 3"},{"status":"ACTIVE","sortPriority":10,"id":41419594,"name":"2 - 4"},{"status":"ACTIVE","sortPriority":11,"id":41419595,"name":"2 - 5"},{"status":"ACTIVE","sortPriority":12,"id":41419596,"name":"2 - 6"},{"status":"ACTIVE","sortPriority":13,"id":41419597,"name":"2 - 7"},{"status":"ACTIVE","sortPriority":14,"id":41419598,"name":"2 - 8"},{"status":"ACTIVE","sortPriority":15,"id":41419599,"name":"3 - 1"},{"status":"ACTIVE","sortPriority":16,"id":41419600,"name":"3 - 2"},{"status":"ACTIVE","sortPriority":17,"id":41419601,"name":"3 - 4"},{"status":"ACTIVE","sortPriority":18,"id":41419602,"name":"3 - 5"},{"status":"ACTIVE","sortPriority":19,"id":41419603,"name":"3 - 6"},{"status":"ACTIVE","sortPriority":20,"id":41419604,"name":"3 - 7"},{"status":"ACTIVE","sortPriority":21,"id":41419605,"name":"3 - 8"},{"status":"ACTIVE","sortPriority":22,"id":41419606,"name":"4 - 1"},{"status":"ACTIVE","sortPriority":23,"id":41419607,"name":"4 - 2"},{"status":"ACTIVE","sortPriority":24,"id":41419608,"name":"4 - 3"},{"status":"ACTIVE","sortPriority":25,"id":41419609,"name":"4 - 5"},{"status":"ACTIVE","sortPriority":26,"id":41419610,"name":"4 - 6"},{"status":"ACTIVE","sortPriority":27,"id":41419611,"name":"4 - 7"},{"status":"ACTIVE","sortPriority":28,"id":41419612,"name":"4 - 8"},{"status":"ACTIVE","sortPriority":29,"id":41419613,"name":"5 - 1"},{"status":"ACTIVE","sortPriority":30,"id":41419614,"name":"5 - 2"},{"status":"ACTIVE","sortPriority":31,"id":41419615,"name":"5 - 3"},{"status":"ACTIVE","sortPriority":32,"id":41419616,"name":"5 - 4"},{"status":"ACTIVE","sortPriority":33,"id":41419617,"name":"5 - 6"},{"status":"ACTIVE","sortPriority":34,"id":41419618,"name":"5 - 7"},{"status":"ACTIVE","sortPriority":35,"id":41419619,"name":"5 - 8"},{"status":"ACTIVE","sortPriority":36,"id":41419620,"name":"6 - 1"},{"status":"ACTIVE","sortPriority":37,"id":41419621,"name":"6 - 2"},{"status":"ACTIVE","sortPriority":38,"id":41419622,"name":"6 - 3"},{"status":"ACTIVE","sortPriority":39,"id":41419623,"name":"6 - 4"},{"status":"ACTIVE","sortPriority":40,"id":41419624,"name":"6 - 5"},{"status":"ACTIVE","sortPriority":41,"id":41419625,"name":"6 - 7"},{"status":"ACTIVE","sortPriority":42,"id":41419626,"name":"6 - 8"},{"status":"ACTIVE","sortPriority":43,"id":41419627,"name":"7 - 1"},{"status":"ACTIVE","sortPriority":44,"id":41419628,"name":"7 - 2"},{"status":"ACTIVE","sortPriority":45,"id":41419629,"name":"7 - 3"},{"status":"ACTIVE","sortPriority":46,"id":41419630,"name":"7 - 4"},{"status":"ACTIVE","sortPriority":47,"id":41419631,"name":"7 - 5"},{"status":"ACTIVE","sortPriority":48,"id":41419632,"name":"7 - 6"},{"status":"ACTIVE","sortPriority":49,"id":41419633,"name":"7 - 8"},{"status":"ACTIVE","sortPriority":50,"id":41419634,"name":"8 - 1"},{"status":"ACTIVE","sortPriority":51,"id":41419635,"name":"8 - 2"},{"status":"ACTIVE","sortPriority":52,"id":41419636,"name":"8 - 3"},{"status":"ACTIVE","sortPriority":53,"id":41419637,"name":"8 - 4"},{"status":"ACTIVE","sortPriority":54,"id":41419638,"name":"8 - 5"},{"status":"ACTIVE","sortPriority":55,"id":41419639,"name":"8 - 6"},{"status":"ACTIVE","sortPriority":56,"id":41419640,"name":"8 - 7"}],"regulators":["MR_INT"],"venue":"Rockhampton","countryCode":"AU","discountAllowed":true,"timezone":"Australia/Queensland","openDate":"2022-03-02T08:28:00.000Z","version":4382597888,"name":"Exacta","eventName":"Rockhampton (AUS) 2nd Mar"},"rc":[{"atb":[[10,29.65],[25,8.33],[15,14.29]],"id":41419609},{"atb":[[150,1.79],[400,0.5],[250,0.8]],"id":41419638},{"atb":[[140,1.44],[48,4.25],[29,9.53]],"id":41419605},{"atb":[[600,0.44],[700,0.28],[850,0.23]],"id":41419634},{"atb":[[16,17.79],[44,4.65],[22,9.53]],"id":41419617},{"atb":[[32,6.45],[80,2.53],[21,13.34]],"id":41419613},{"atb":[[3.6,102.64],[5.7,42.58],[4.2,62.54]],"id":41419593},{"atb":[[34,6.06],[18.5,11.43],[13.5,21.34]],"id":41419622},{"atb":[[140,1.92],[390,0.51],[240,0.83]],"id":41419589},{"atb":[[16,17.79],[44,4.65],[22,9.53]],"id":41419618},{"atb":[[17,12.5],[9.8,22.74],[7.8,39.24]],"id":41419601},{"atb":[[16.5,17.22],[46,4.44],[23,9.09]],"id":41419630},{"atb":[[18,11.77],[10.5,21.07],[8.2,37.06]],"id":41419597},{"atb":[[600,0.44],[700,0.28],[850,0.23]],"id":41419626},{"atb":[[600,0.44],[700,0.28],[850,0.23]],"id":41419639},{"atb":[[32,6.45],[80,2.53],[21,13.34]],"id":41419606},{"atb":[[75,2.7],[20,14.04],[30,6.9]],"id":41419635},{"atb":[[17,12.5],[9.8,22.74],[7.8,39.24]],"id":41419602},{"atb":[[34,6.06],[18.5,11.43],[13.5,21.34]],"id":41419585},{"atb":[[5.6,58.01],[7.2,32.28],[10.5,21.07]],"id":41419614},{"atb":[[16,17.79],[44,4.65],[22,9.53]],"id":41419610},{"atb":[[16.5,17.22],[46,4.44],[23,9.09]],"id":41419623},{"atb":[[140,1.92],[390,0.51],[240,0.83]],"id":41419590},{"atb":[[340,0.58],[190,1.05],[95,2.83]],"id":41419619},{"atb":[[17.5,16.17],[50,4.08],[25,8.33]],"id":41419586},{"atb":[[16.5,17.22],[46,4.44],[23,9.09]],"id":41419631},{"atb":[[16.5,17.22],[46,4.44],[23,9.09]],"id":41419598},{"atb":[[370,0.54],[220,0.91],[120,2.24]],"id":41419627},{"atb":[[5.6,43.51],[4.6,74.13],[8.2,27.8]],"id":41419594},{"atb":[[600,0.44],[700,0.28],[850,0.23]],"id":41419640},{"atb":[[5.6,58.01],[7.2,32.28],[10.5,21.07]],"id":41419607},{"atb":[[80,2.53],[42,6.5],[210,0.95]],"id":41419636},{"atb":[[17,12.5],[12,24.26],[29,7.14]],"id":41419603},{"atb":[[18,11.77],[10.5,21.07],[8.2,37.06]],"id":41419615},{"atb":[[16,17.79],[44,4.65],[22,9.53]],"id":41419611},{"atb":[[16.5,17.22],[46,4.44],[23,9.09]],"id":41419624},{"atb":[[600,0.44],[700,0.28],[850,0.23]],"id":41419591},{"atb":[[370,0.54],[220,0.91],[120,2.24]],"id":41419620},{"atb":[[36,5.71],[90,2.24],[23,12.13]],"id":41419587},{"atb":[[150,1.34],[50,4.08],[30,9.2]],"id":41419632},{"atb":[[16.5,17.22],[46,4.44],[23,9.09]],"id":41419599},{"atb":[[9.6,31.03],[23,9.09],[14,15.39]],"id":41419628},{"atb":[[5.6,43.51],[4.6,74.13],[8.2,27.8]],"id":41419595},{"atb":[[18,11.77],[10.5,21.07],[8.2,37.06]],"id":41419608},{"atb":[[150,1.79],[400,0.5],[250,0.8]],"id":41419637},{"atb":[[17,12.5],[12,24.26],[29,7.14]],"id":41419604},{"atb":[[10,29.65],[25,8.33],[15,14.29]],"id":41419616},{"atb":[[340,0.58],[190,1.05],[95,2.83]],"id":41419612},{"atb":[[150,1.34],[50,4.08],[30,9.2]],"id":41419625},{"atb":[[10.5,28.09],[26,8],[15.5,13.8]],"id":41419592},{"atb":[[9.6,31.03],[23,9.09],[14,15.39]],"id":41419621},{"atb":[[36,5.71],[90,2.24],[23,12.13]],"id":41419588},{"atb":[[600,0.44],[700,0.28],[850,0.23]],"id":41419633},{"atb":[[7.4,31.27],[5.2,47.66],[4.2,83.4]],"id":41419600},{"atb":[[34,6.06],[18.5,11.43],[13.5,21.34]],"id":41419629},{"atb":[[18,11.77],[10.5,21.07],[8.2,37.06]],"id":41419596}],"con":true,"img":true}]}
{"op":"mcm","clk":"5352844660","pt":1646202480475,"mc":[{"id":"1.195503860","rc":[{"atb":[[10,29.65],[25,11.61],[15,14.29],[30,2.73]],"id":41419609},{"atb":[[150,1.79],[170,2.73],[400,0.5],[120,3.27],[250,0.8]],"id":41419638},{"atb":[[140,1.44],[44,3.27],[48,4.25],[29,9.53],[60,2.73]],"id":41419605},{"atb":[[600,0.44],[300,2.73],[700,0.28],[850,0.23],[250,3.27]],"id":41419634},{"atb":[[16,17.79],[36,3.27],[44,4.65],[22,9.53],[46,2.73]],"id":41419617},{"atb":[[32,6.45],[80,2.53],[21,13.34],[42,3.27],[55,2.73]],"id":41419613},{"atb":[[3.6,102.64],[7.6,2.73],[5.7,42.58],[6.6,3.27],[4.2,62.54]],"id":41419593},{"atb":[[34,6.06],[18.5,11.43],[42,3.27],[13.5,21.34],[55,2.73]],"id":41419622},{"atb":[[130,2.73],[140,1.92],[90,3.27],[390,0.51],[240,0.83]],"id":41419589},{"atb":[[16,17.79],[36,3.27],[44,4.65],[22,9.53],[46,2.73]],"id":41419618},{"atb":[[17,12.5],[17.5,3.27],[20,2.73],[9.8,22.74],[7.8,39.24]],"id":41419601},{"atb":[[16.5,17.22],[44,3.27],[46,4.44],[23,9.09],[60,2.73]],"id":41419630},{"atb":[[16.5,2.73],[18,11.77],[10.5,21.07],[8.2,37.06],[14,3.27]],"id":41419597},{"atb":[[600,0.44],[700,0.28],[170,2.73],[850,0.23],[120,3.27]],"id":41419626},{"atb":[[600,0.44],[700,0.28],[200,3.27],[850,0.23],[250,2.73]],"id":41419639},{"atb":[[32,6.45],[80,2.53],[21,13.34],[42,3.27],[55,2.73]],"id":41419606},{"atb":[[75,2.7],[20,14.04],[80,3.27],[110,2.73],[30,6.9]],"id":41419635},{"atb":[[17,12.5],[17.5,3.27],[20,2.73],[9.8,22.74],[7.8,39.24]],"id":41419602},{"atb":[[34,6.06],[18.5,11.43],[42,3.27],[13.5,21.34],[55,2.73]],"id":41419585},{"atb":[[5.6,58.01],[7.2,32.28],[17,2.73],[10.5,21.07],[14.5,3.27]],"id":41419614},{"atb":[[16,17.79],[36,3.27],[44,4.65],[22,9.53],[46,2.73]],"id":41419610},{"atb":[[16.5,17.22],[44,3.27],[46,4.44],[23,9.09],[60,2.73]],"id":41419623},{"atb":[[130,2.73],[140,1.92],[90,3.27],[390,0.51],[240,0.83]],"id":41419590},{"atb":[[340,0.58],[85,2.73],[190,1.05],[95,2.83],[60,3.27]],"id":41419619},{"atb":[[17.5,16.17],[70,2.73],[48,3.27],[50,4.08],[25,8.33]],"id":41419586},{"atb":[[16.5,17.22],[44,3.27],[46,4.44],[23,9.09],[60,2.73]],"id":41419631},{"atb":[[16.5,17.22],[36,2.73],[46,4.44],[23,9.09],[28,3.27]],"id":41419598},{"atb":[[80,3.27],[370,0.54],[220,0.91],[110,2.73],[120,2.24]],"id":41419627},{"atb":[[5.6,43.51],[8,3.27],[9,2.73],[4.6,74.13],[8.2,27.8]],"id":41419594},{"atb":[[600,0.44],[700,0.28],[200,3.27],[850,0.23],[250,2.73]],"id":41419640},{"atb":[[5.6,58.01],[7.2,32.28],[17,2.73],[10.5,21.07],[14.5,3.27]],"id":41419607},{"atb":[[140,2.73],[80,2.53],[42,6.5],[95,3.27],[210,0.95]],"id":41419636},{"atb":[[17,12.5],[34,2.73],[12,24.26],[27,3.27],[29,7.14]],"id":41419603},{"atb":[[18,11.77],[20,3.27],[10.5,21.07],[8.2,37.06],[25,2.73]],"id":41419615},{"atb":[[16,17.79],[36,3.27],[44,4.65],[22,9.53],[46,2.73]],"id":41419611},{"atb":[[16.5,17.22],[44,3.27],[46,4.44],[23,9.09],[60,2.73]],"id":41419624},{"atb":[[600,0.44],[700,0.28],[180,3.27],[850,0.23],[230,2.73]],"id":41419591},{"atb":[[80,3.27],[370,0.54],[220,0.91],[110,2.73],[120,2.24]],"id":41419620},{"atb":[[36,5.71],[85,2.73],[90,2.24],[23,12.13],[60,3.27]],"id":41419587},{"atb":[[65,3.27],[150,1.34],[90,2.73],[50,4.08],[30,9.2]],"id":41419632},{"atb":[[16.5,17.22],[40,2.73],[46,4.44],[23,9.09],[30,3.27]],"id":41419599},{"atb":[[9.6,31.03],[40,2.73],[23,9.09],[14,15.39],[30,3.27]],"id":41419628},{"atb":[[5.6,43.51],[8,3.27],[9,2.73],[4.6,74.13],[8.2,27.8]],"id":41419595},{"atb":[[18,11.77],[20,3.27],[10.5,21.07],[8.2,37.06],[25,2.73]],"id":41419608},{"atb":[[150,1.79],[170,2.73],[400,0.5],[120,3.27],[250,0.8]],"id":41419637},{"atb":[[17,12.5],[34,2.73],[12,24.26],[27,3.27],[29,7.14]],"id":41419604},{"atb":[[10,29.65],[25,11.61],[15,14.29],[30,2.73]],"id":41419616},{"atb":[[340,0.58],[85,2.73],[190,1.05],[95,2.83],[60,3.27]],"id":41419612},{"atb":[[65,3.27],[150,1.34],[90,2.73],[50,4.08],[30,9.2]],"id":41419625},{"atb":[[17.5,3.27],[20,2.73],[10.5,28.09],[26,8],[15.5,13.8]],"id":41419592},{"atb":[[9.6,31.03],[40,2.73],[23,9.09],[14,15.39],[30,3.27]],"id":41419621},{"atb":[[36,5.71],[85,2.73],[90,2.24],[23,12.13],[60,3.27]],"id":41419588},{"atb":[[600,0.44],[700,0.28],[170,2.73],[850,0.23],[120,3.27]],"id":41419633},{"atb":[[11,2.73],[7.4,31.27],[5.2,47.66],[4.2,83.4],[9.4,3.27]],"id":41419600},{"atb":[[34,6.06],[18.5,11.43],[42,3.27],[13.5,21.34],[55,2.73]],"id":41419629},{"atb":[[17.5,2.73],[18,11.77],[10.5,21.07],[8.2,37.06],[15,3.27]],"id":41419596}],"con":true,"img":false}]}
{"op":"mcm","clk":"5352934045","pt":1646205055052,"mc":[{"id":"1.195503860","rc":[{"atb":[[10,29.64],[25,11.61],[30,2.72],[15,14.29]],"id":41419609},{"atb":[[150,1.79],[170,2.72],[400,0.5],[120,3.27],[250,0.8]],"id":41419638},{"atb":[[140,1.44],[44,3.27],[48,4.25],[29,9.53],[60,2.72]],"id":41419605},{"atb":[[600,0.44],[300,2.72],[250,3.27]],"id":41419634},{"atb":[[16,17.78],[36,3.27],[44,4.65],[22,9.53],[46,2.72]],"id":41419617},{"atb":[[32,6.45],[80,2.53],[42,3.27],[21,13.34],[55,2.72]],"id":41419613},{"atb":[[3.6,0],[7.6,2.72],[5.7,0],[6.6,3.27],[4.2,0]],"id":41419593},{"atb":[[34,6.06],[18.5,11.43],[42,3.27],[55,2.72],[13.5,21.34]],"id":41419622},{"atb":[[130,2.72],[140,0],[90,3.27],[390,0],[240,0]],"id":41419589},{"atb":[[16,17.78],[36,3.27],[44,4.65],[22,9.53],[46,2.72]],"id":41419618},{"atb":[[17.5,3.27],[17,0],[20,2.72],[9.8,0],[7.8,0]],"id":41419601},{"atb":[[16.5,17.21],[44,3.27],[46,4.44],[23,9.09],[60,2.72]],"id":41419630},{"atb":[[16.5,2.72],[18,0],[10.5,0],[8.2,0],[14,3.27]],"id":41419597},{"atb":[[600,0.44],[170,2.72],[120,3.27]],"id":41419626},{"atb":[[600,0.44],[200,3.27],[250,2.72]],"id":41419639},{"atb":[[32,6.45],[80,2.53],[42,3.27],[21,13.34],[55,2.72]],"id":41419606},{"atb":[[75,2.7],[80,3.27],[20,14.04],[110,2.72],[30,6.89]],"id":41419635},{"atb":[[17.5,3.27],[17,0],[20,2.72],[9.8,0],[7.8,0]],"id":41419602},{"atb":[[34,0],[18.5,0],[42,3.27],[55,2.72],[13.5,0]],"id":41419585},{"atb":[[5.6,58],[17,2.72],[7.2,32.27],[10.5,21.06],[14.5,3.27]],"id":41419614},{"atb":[[16,17.78],[36,3.27],[44,4.65],[22,9.53],[46,2.72]],"id":41419610},{"atb":[[16.5,17.21],[44,3.27],[46,4.44],[23,9.09],[60,2.72]],"id":41419623},{"atb":[[130,2.72],[140,0],[90,3.27],[390,0],[240,0]],"id":41419590},{"atb":[[340,0.58],[85,2.72],[190,1.05],[95,2.83],[60,3.27]],"id":41419619},{"atb":[[70,2.72],[17.5,0],[48,3.27],[50,0],[25,0]],"id":41419586},{"atb":[[16.5,17.21],[44,3.27],[46,4.44],[23,9.09],[60,2.72]],"id":41419631},{"atb":[[16.5,0],[36,2.72],[46,0],[23,0],[28,3.27]],"id":41419598},{"atb":[[80,3.27],[370,0.54],[220,0.91],[110,2.72],[120,2.24]],"id":41419627},{"atb":[[8,3.27],[5.6,0],[9,2.72],[4.6,0],[8.2,0]],"id":41419594},{"atb":[[600,0.44],[200,3.27],[250,2.72]],"id":41419640},{"atb":[[5.6,58],[17,2.72],[7.2,32.27],[10.5,21.06],[14.5,3.27]],"id":41419607},{"atb":[[140,2.72],[80,2.53],[42,6.5],[95,3.27],[210,0.95]],"id":41419636},{"atb":[[34,2.72],[17,0],[12,0],[27,3.27],[29,0]],"id":41419603},{"atb":[[18,11.76],[20,3.27],[10.5,21.06],[8.2,37.05],[25,2.72]],"id":41419615},{"atb":[[16,17.78],[36,3.27],[44,4.65],[22,9.53],[46,2.72]],"id":41419611},{"atb":[[16.5,17.21],[44,3.27],[46,4.44],[23,9.09],[60,2.72]],"id":41419624},{"atb":[[600,0],[700,0],[180,3.27],[850,0],[230,2.72]],"id":41419591},{"atb":[[80,3.27],[370,0.54],[220,0.91],[110,2.72],[120,2.24]],"id":41419620},{"atb":[[36,0],[85,2.72],[90,0],[23,0],[60,3.27]],"id":41419587},{"atb":[[65,3.27],[150,1.34],[90,2.72],[50,4.08],[30,9.2]],"id":41419632},{"atb":[[16.5,0],[40,2.72],[46,0],[23,0],[30,3.27]],"id":41419599},{"atb":[[9.6,31.02],[40,2.72],[23,9.09],[14,15.39],[30,3.27]],"id":41419628},{"atb":[[8,3.27],[5.6,0],[9,2.72],[4.6,0],[8.2,0]],"id":41419595},{"atb":[[18,11.76],[20,3.27],[10.5,21.06],[8.2,37.05],[25,2.72]],"id":41419608},{"atb":[[150,1.79],[170,2.72],[400,0.5],[120,3.27],[250,0.8]],"id":41419637},{"atb":[[34,2.72],[17,0],[12,0],[27,3.27],[29,0]],"id":41419604},{"atb":[[10,29.64],[25,11.61],[30,2.72],[15,14.29]],"id":41419616},{"atb":[[340,0.58],[85,2.72],[190,1.05],[95,2.83],[60,3.27]],"id":41419612},{"atb":[[65,3.27],[150,1.34],[90,2.72],[50,4.08],[30,9.2]],"id":41419625},{"atb":[[17.5,3.27],[20,2.72],[10.5,0],[26,0],[15.5,0]],"id":41419592},{"atb":[[9.6,31.02],[40,2.72],[23,9.09],[14,15.39],[30,3.27]],"id":41419621},{"atb":[[36,0],[85,2.72],[90,0],[23,0],[60,3.27]],"id":41419588},{"atb":[[600,0.44],[170,2.72],[120,3.27]],"id":41419633},{"atb":[[11,2.72],[7.4,0],[5.2,0],[4.2,0],[9.4,3.27]],"id":41419600},{"atb":[[34,6.06],[18.5,11.43],[42,3.27],[55,2.72],[13.5,21.34]],"id":41419629},{"atb":[[17.5,2.72],[18,0],[10.5,0],[8.2,0],[15,3.27]],"id":41419596}],"con":true,"img":false}]}
{"op":"mcm","clk":"5352934050","pt":1646205055157,"mc":[{"id":"1.195503860","rc":[{"atb":[[10,0],[25,3.27],[15,0]],"id":41419609},{"atb":[[150,0],[400,0],[250,0]],"id":41419638},{"atb":[[140,0],[48,0],[29,0]],"id":41419605},{"atb":[[600,0],[700,0],[850,0]],"id":41419634},{"atb":[[16,0],[44,0],[22,0]],"id":41419617},{"atb":[[32,0],[80,0],[21,0]],"id":41419613},{"atb":[[34,0],[18.5,0],[13.5,0]],"id":41419622},{"atb":[[16,0],[44,0],[22,0]],"id":41419618},{"atb":[[16.5,0],[46,0],[23,0]],"id":41419630},{"atb":[[600,0],[700,0],[850,0]],"id":41419626},{"atb":[[600,0],[700,0],[850,0]],"id":41419639},{"atb":[[32,0],[80,0],[21,0]],"id":41419606},{"atb":[[75,0],[20,0],[30,0]],"id":41419635},{"atb":[[5.6,0],[7.2,0],[10.5,0]],"id":41419614},{"atb":[[16,0],[44,0],[22,0]],"id":41419610},{"atb":[[16.5,0],[46,0],[23,0]],"id":41419623},{"atb":[[340,0],[190,0],[95,0]],"id":41419619},{"atb":[[16.5,0],[46,0],[23,0]],"id":41419631},{"atb":[[370,0],[220,0],[120,0]],"id":41419627},{"atb":[[600,0],[700,0],[850,0]],"id":41419640},{"atb":[[5.6,0],[7.2,0],[10.5,0]],"id":41419607},{"atb":[[80,0],[42,0],[210,0]],"id":41419636},{"atb":[[18,0],[10.5,0],[8.2,0]],"id":41419615},{"atb":[[16,0],[44,0],[22,0]],"id":41419611},{"atb":[[16.5,0],[46,0],[23,0]],"id":41419624},{"atb":[[370,0],[220,0],[120,0]],"id":41419620},{"atb":[[150,0],[50,0],[30,0]],"id":41419632},{"atb":[[9.6,0],[23,0],[14,0]],"id":41419628},{"atb":[[18,0],[10.5,0],[8.2,0]],"id":41419608},{"atb":[[150,0],[400,0],[250,0]],"id":41419637},{"atb":[[10,0],[25,3.27],[15,0]],"id":41419616},{"atb":[[340,0],[190,0],[95,0]],"id":41419612},{"atb":[[150,0],[50,0],[30,0]],"id":41419625},{"atb":[[9.6,0],[23,0],[14,0]],"id":41419621},{"atb":[[600,0],[700,0],[850,0]],"id":41419633},{"atb":[[34,0],[18.5,0],[13.5,0]],"id":41419629}],"con":true,"img":false}]}
{"op":"mcm","clk":"5352934749","pt":1646205071715,"mc":[{"id":"1.195503860","rc":[{"atb":[[24,8.7],[9.8,30.32],[14.5,14.82]],"id":41419609},{"atb":[[34,8.08],[170,1.18],[60,6.11]],"id":41419605},{"atb":[[4.5,57.17],[6,40.02],[3.75,97.02]],"id":41419593},{"atb":[[130,4.79],[380,0.52],[230,0.87]],"id":41419589},{"atb":[[18,11.76],[10.5,21.06],[8.2,37.05]],"id":41419601},{"atb":[[16.5,15.63],[9.6,23.26],[7.6,40.42]],"id":41419597},{"atb":[[75,2.7],[20,14.04],[30,6.89]],"id":41419606},{"atb":[[18,11.76],[10.5,21.06],[8.2,37.05]],"id":41419602},{"atb":[[34,6.06],[18.5,11.43],[13.5,21.34]],"id":41419585},{"atb":[[16,17.78],[44,4.65],[22,9.53]],"id":41419610},{"atb":[[340,0.58],[190,1.05],[95,2.83]],"id":41419590},{"atb":[[18,15.69],[26,8],[55,3.7]],"id":41419586},{"atb":[[16.5,17.21],[46,4.44],[23,9.09]],"id":41419598},{"atb":[[8,31.86],[4.5,76.23],[5.5,44.47]],"id":41419594},{"atb":[[10,22.23],[5.5,59.29],[7,33.35]],"id":41419607},{"atb":[[17.5,12.12],[12.5,23.19],[30,6.89]],"id":41419603},{"atb":[[42,4.87],[21,10],[15.5,18.4]],"id":41419611},{"atb":[[600,0.44],[700,0.28],[850,0.23]],"id":41419591},{"atb":[[36,5.71],[90,2.24],[23,12.12]],"id":41419587},{"atb":[[17,16.67],[48,4.25],[24,8.7]],"id":41419599},{"atb":[[8,31.86],[4.5,76.23],[5.5,44.47]],"id":41419595},{"atb":[[18.5,11.43],[11,20.01],[8.4,36.05]],"id":41419608},{"atb":[[17,12.5],[12,24.25],[29,7.14]],"id":41419604},{"atb":[[330,0.6],[180,1.11],[90,2.99]],"id":41419612},{"atb":[[10.5,28.08],[26,8],[15.5,13.79]],"id":41419592},{"atb":[[36,5.71],[90,2.24],[23,12.12]],"id":41419588},{"atb":[[4.3,80.85],[5.3,46.53],[7.6,30.32]],"id":41419600},{"atb":[[8,38.11],[17.5,14.85],[10,22.23]],"id":41419596}],"con":true,"img":false}]}
{"op":"mcm","clk":"5352934755","pt":1646205071768,"mc":[{"id":"1.195503860","rc":[{"atb":[[140,1.92],[390,0.51],[240,0.83]],"id":41419638},{"atb":[[600,0.44],[700,0.28],[850,0.23]],"id":41419634},{"atb":[[16,17.78],[44,4.65],[22,9.53]],"id":41419617},{"atb":[[75,2.7],[20,14.04],[30,6.89]],"id":41419613},{"atb":[[36,5.71],[19,11.11],[14,20.52]],"id":41419622},{"atb":[[42,4.87],[21,10],[15.5,18.4]],"id":41419618},{"atb":[[16,17.78],[44,7.93],[22,9.53]],"id":41419630},{"atb":[[600,0.44],[700,0.28],[850,0.23]],"id":41419626},{"atb":[[600,0.44],[700,0.28],[850,0.23]],"id":41419639},{"atb":[[75,2.7],[20,14.04],[30,6.89]],"id":41419635},{"atb":[[10,22.23],[5.5,59.29],[7,33.35]],"id":41419614},{"atb":[[16.5,17.21],[46,4.44],[23,9.09]],"id":41419623},{"atb":[[330,0.6],[180,1.11],[90,2.99]],"id":41419619},{"atb":[[16,17.78],[44,7.93],[22,9.53]],"id":41419631},{"atb":[[320,0.62],[170,1.18],[85,3.17]],"id":41419627},{"atb":[[600,0.44],[700,0.28],[850,0.23]],"id":41419640},{"atb":[[95,5.4],[48,5.67],[240,0.83]],"id":41419636},{"atb":[[18.5,11.43],[11,20.01],[8.4,36.05]],"id":41419615},{"atb":[[16.5,17.21],[46,4.44],[23,9.09]],"id":41419624},{"atb":[[360,0.55],[210,0.95],[110,5.17]],"id":41419620},{"atb":[[44,4.65],[27,10.26],[120,1.68]],"id":41419632},{"atb":[[9.2,32.53],[21,10],[13,16.67]],"id":41419628},{"atb":[[140,1.92],[390,0.51],[240,0.83]],"id":41419637},{"atb":[[24,8.7],[9.8,30.32],[14.5,14.82]],"id":41419616},{"atb":[[44,4.65],[27,10.26],[120,1.68]],"id":41419625},{"atb":[[9.6,31.02],[23,9.09],[14,15.39]],"id":41419621},{"atb":[[600,0.44],[700,0.28],[850,0.23]],"id":41419633},{"atb":[[32,6.45],[18,11.76],[13,22.23]],"id":41419629}],"con":true,"img":false}]}
{"op":"mcm","clk":"5352953461","pt":1646205518512,"mc":[{"id":"1.195503860","rc":[{"atb":[[25,0],[30,0]],"id":41419609},{"atb":[[36,0],[46,0]],"id":41419617},{"atb":[[42,0],[55,0]],"id":41419613},{"atb":[[7.6,0],[6.6,0]],"id":41419593},{"atb":[[130,2.06],[90,0]],"id":41419589},{"atb":[[36,0],[46,0]],"id":41419618},{"atb":[[17.5,0],[20,0]],"id":41419601},{"atb":[[44,4.65],[60,0]],"id":41419630},{"atb":[[42,0],[55,0]],"id":41419606},{"atb":[[17.5,0],[20,0]],"id":41419602},{"atb":[[42,0],[55,0]],"id":41419585},{"atb":[[17,0],[14.5,0]],"id":41419614},{"atb":[[36,0],[46,0]],"id":41419610},{"atb":[[44,0],[60,0]],"id":41419623},{"atb":[[130,0],[90,0]],"id":41419590},{"atb":[[70,0],[48,0]],"id":41419586},{"atb":[[44,4.65],[60,0]],"id":41419631},{"atb":[[80,0],[110,0]],"id":41419627},{"atb":[[34,0],[27,0]],"id":41419603},{"atb":[[20,0],[25,0]],"id":41419615},{"atb":[[36,0],[46,0]],"id":41419611},{"atb":[[80,0],[110,2.44]],"id":41419620},{"atb":[[85,0],[60,0]],"id":41419587},{"atb":[[65,0],[90,0]],"id":41419632},{"atb":[[40,0],[30,0]],"id":41419599},{"atb":[[20,0],[25,0]],"id":41419608},{"atb":[[34,0],[27,0]],"id":41419604},{"atb":[[25,0],[30,0]],"id":41419616},{"atb":[[65,0],[90,0]],"id":41419625},{"atb":[[85,0],[60,0]],"id":41419588},{"atb":[[11,0],[9.4,0]],"id":41419600}],"con":true,"img":false}]}
{"op":"mcm","clk":"5352953473","pt":1646205518718,"mc":[{"id":"1.195503860","rc":[{"atb":[[44,0],[60,0]],"id":41419624}],"con":true,"img":false}]}
{"op":"mcm","clk":"5352953484","pt":1646205519231,"mc":[{"id":"1.195503860","rc":[{"atb":[[32,2.72],[26,3.27]],"id":41419609},{"atb":[[38,3.27],[48,2.72]],"id":41419617},{"atb":[[44,3.27],[60,2.72]],"id":41419613},{"atb":[[6.8,3.27],[7.8,2.72]],"id":41419593},{"atb":[[140,2.72],[95,3.27]],"id":41419589},{"atb":[[38,3.27],[48,2.72]],"id":41419618},{"atb":[[18.5,3.27],[22,2.72]],"id":41419601},{"atb":[[65,2.72],[46,3.27]],"id":41419630},{"atb":[[44,3.27],[60,2.72]],"id":41419606},{"atb":[[19,3.27],[23,2.72]],"id":41419602},{"atb":[[44,3.27],[60,2.72]],"id":41419585},{"atb":[[17.5,2.72],[15,3.27]],"id":41419614},{"atb":[[38,3.27],[48,2.72]],"id":41419610},{"atb":[[65,2.72],[46,7.72]],"id":41419623},{"atb":[[140,2.72],[95,6.11]],"id":41419590},{"atb":[[80,2.72],[55,6.98]],"id":41419586},{"atb":[[65,2.72],[46,3.27]],"id":41419631},{"atb":[[85,6.45],[120,2.72]],"id":41419627},{"atb":[[36,2.72],[28,3.27]],"id":41419603},{"atb":[[22,3.27],[27,2.72]],"id":41419615},{"atb":[[38,3.27],[48,2.72]],"id":41419611},{"atb":[[85,3.27],[120,2.72]],"id":41419620},{"atb":[[65,3.27],[90,4.97]],"id":41419587},{"atb":[[70,3.27],[95,2.72]],"id":41419632},{"atb":[[34,3.27],[44,2.72]],"id":41419599},{"atb":[[22,3.27],[27,2.72]],"id":41419608},{"atb":[[36,2.72],[28,3.27]],"id":41419604},{"atb":[[32,2.72],[26,3.27]],"id":41419616},{"atb":[[70,3.27],[95,2.72]],"id":41419625},{"atb":[[65,3.27],[90,4.97]],"id":41419588},{"atb":[[9.6,3.27],[11.5,2.72]],"id":41419600}],"con":true,"img":false}]}
{"op":"mcm","clk":"5352953492","pt":1646205519538,"mc":[{"id":"1.195503860","rc":[{"atb":[[65,2.72],[46,7.72]],"id":41419624}],"con":true,"img":false}]}
{"op":"mcm","clk":"5352956209","pt":1646205602900,"mc":[{"id":"1.195503860","rc":[{"atb":[[80,2.72],[55,3.27]],"id":41419612}],"con":true,"img":false}]}
{"op":"mcm","clk":"5352956214","pt":1646205603004,"mc":[{"id":"1.195503860","rc":[{"atb":[[44,0],[60,3.38]],"id":41419605},{"atb":[[140,0],[95,0]],"id":41419589},{"atb":[[34,2.72],[36,0],[27,3.27],[28,0]],"id":41419598},{"atb":[[180,0],[230,0]],"id":41419591},{"atb":[[85,0],[60,0]],"id":41419612}],"con":true,"img":false}]}
{"op":"mcm","clk":"5352956216","pt":1646205603107,"mc":[{"id":"1.195503860","rc":[{"atb":[[70,3.27],[80,0],[95,2.72],[110,0]],"id":41419635},{"atb":[[17.5,0],[15,0]],"id":41419614},{"atb":[[65,0],[46,4.44]],"id":41419623},{"atb":[[70,0],[95,0]],"id":41419632},{"atb":[[160,2.72],[170,0],[110,3.27],[120,0]],"id":41419633},{"atb":[[9.6,0],[11.5,0]],"id":41419600},{"atb":[[42,0],[55,0]],"id":41419629}],"con":true,"img":false}]}
{"op":"mcm","clk":"5352956221","pt":1646205603220,"mc":[{"id":"1.195503860","rc":[{"atb":[[42,0],[55,0]],"id":41419622},{"atb":[[130,2.72],[140,0],[90,3.27],[95,2.12]],"id":41419636},{"atb":[[22,0],[27,0]],"id":41419615},{"atb":[[85,0],[120,0]],"id":41419620},{"atb":[[22,0],[27,0]],"id":41419608},{"atb":[[17.5,12.12],[17,2.72],[14.5,3.27],[15,0]],"id":41419596}],"con":true,"img":false}]}
{"op":"mcm","clk":"5352956224","pt":1646205603317,"mc":[{"id":"1.195503860","rc":[{"atb":[[150,2.72],[170,0],[100,3.27],[120,0]],"id":41419638},{"atb":[[80,0],[55,3.7]],"id":41419586},{"atb":[[65,0],[46,0]],"id":41419631},{"atb":[[65,0],[46,4.44]],"id":41419624},{"atb":[[8,28.58],[9,0]],"id":41419595},{"atb":[[36,0],[28,0]],"id":41419604}],"con":true,"img":false}]}
{"op":"mcm","clk":"5352956227","pt":1646205603420,"mc":[{"id":"1.195503860","rc":[{"atb":[[280,2.72],[300,0],[230,3.27],[250,0]],"id":41419634},{"atb":[[38,0],[48,0]],"id":41419610}],"con":true,"img":false}]}
{"op":"mcm","clk":"5352956230","pt":1646205603524,"mc":[{"id":"1.195503860","rc":[{"atb":[[32,0],[26,0]],"id":41419609},{"atb":[[38,0],[48,0]],"id":41419617},{"atb":[[18.5,0],[22,0]],"id":41419601},{"atb":[[170,3.27],[200,0],[220,2.72],[250,0]],"id":41419640},{"atb":[[38,0],[48,0]],"id":41419611},{"atb":[[34,0],[44,0]],"id":41419599},{"atb":[[150,2.72],[170,0],[100,3.27],[120,0]],"id":41419637}],"con":true,"img":false}]}
{"op":"mcm","clk":"5352956234","pt":1646205603628,"mc":[{"id":"1.195503860","rc":[{"atb":[[38,0],[48,0]],"id":41419618},{"atb":[[170,3.27],[200,0],[220,2.72],[250,0]],"id":41419639},{"atb":[[44,0],[60,0]],"id":41419606},{"atb":[[44,0],[60,0]],"id":41419585},{"atb":[[80,2.72],[85,0],[55,3.27],[60,0]],"id":41419619},{"atb":[[17.5,0],[20,0]],"id":41419592},{"atb":[[40,0],[30,0]],"id":41419621}],"con":true,"img":false}]}
{"op":"mcm","clk":"5352956236","pt":1646205603731,"mc":[{"id":"1.195503860","rc":[{"atb":[[140,2.72],[95,3.27]],"id":41419589},{"atb":[[160,2.72],[170,0],[110,3.27],[120,0]],"id":41419626},{"atb":[[180,3.27],[230,2.72]],"id":41419591}],"con":true,"img":false}]}
{"op":"mcm","clk":"5352956242","pt":1646205603837,"mc":[{"id":"1.195503860","rc":[{"atb":[[44,3.27],[60,6.11]],"id":41419605},{"atb":[[17.5,2.72],[15,3.27]],"id":41419614},{"atb":[[65,2.72],[46,7.72]],"id":41419623},{"atb":[[70,3.27],[95,2.72]],"id":41419632},{"atb":[[9.6,3.27],[11.5,2.72]],"id":41419600},{"atb":[[42,3.27],[55,2.72]],"id":41419629}],"con":true,"img":false}]}
{"op":"mcm","clk":"5352956248","pt":1646205604046,"mc":[{"id":"1.195503860","rc":[{"atb":[[42,3.27],[55,2.72]],"id":41419622},{"atb":[[80,2.72],[55,6.98]],"id":41419586},{"atb":[[65,2.72],[46,3.27]],"id":41419631},{"atb":[[22,3.27],[27,2.72]],"id":41419615},{"atb":[[65,2.72],[46,7.72]],"id":41419624},{"atb":[[85,3.27],[120,2.72]],"id":41419620},{"atb":[[8,31.86],[9,2.72]],"id":41419595},{"atb":[[22,3.27],[27,2.72]],"id":41419608},{"atb":[[36,2.72],[28,3.27]],"id":41419604}],"con":true,"img":false}]}
{"op":"mcm","clk":"5352956256","pt":1646205604252,"mc":[{"id":"1.195503860","rc":[{"atb":[[32,2.72],[26,3.27]],"id":41419609},{"atb":[[38,3.27],[48,2.72]],"id":41419617},{"atb":[[38,3.27],[48,2.72]],"id":41419610},{"atb":[[38,3.27],[48,2.72]],"id":41419611},{"atb":[[34,3.27],[44,2.72]],"id":41419599}],"con":true,"img":false}]}
{"op":"mcm","clk":"5352956261","pt":1646205604306,"mc":[{"id":"1.195503860","rc":[{"atb":[[38,3.27],[48,2.72]],"id":41419618},{"atb":[[18.5,3.27],[22,2.72]],"id":41419601},{"atb":[[44,3.27],[60,2.72]],"id":41419606},{"atb":[[44,3.27],[60,2.72]],"id":41419585},{"atb":[[17.5,3.27],[20,2.72]],"id":41419592},{"atb":[[40,2.72],[30,3.27]],"id":41419621}],"con":true,"img":false}]}
{"op":"mcm","clk":"5353022020","pt":1646207201197,"mc":[{"id":"1.195503860","rc":[{"atb":[[32,0],[26,0]],"id":41419609},{"atb":[[17.5,0],[15,0]],"id":41419614},{"atb":[[80,0],[55,0]],"id":41419619},{"atb":[[17,0],[14.5,0]],"id":41419607},{"atb":[[65,0],[90,2.24]],"id":41419587},{"atb":[[32,0],[26,0]],"id":41419616},{"atb":[[65,0],[90,2.24]],"id":41419588}],"con":true,"img":false}]}
{"op":"mcm","clk":"5353022074","pt":1646207201873,"mc":[{"id":"1.195503860","rc":[{"atb":[[34,2.72],[27,3.27]],"id":41419609},{"atb":[[18,2.72],[15.5,3.27]],"id":41419614},{"atb":[[85,2.72],[60,3.27]],"id":41419619},{"atb":[[70,3.27],[95,2.72]],"id":41419587},{"atb":[[34,2.72],[27,3.27]],"id":41419616}],"con":true,"img":false}]}
{"op":"mcm","clk":"5353022090","pt":1646207202184,"mc":[{"id":"1.195503860","rc":[{"atb":[[17.5,2.72],[15,3.27]],"id":41419607},{"atb":[[70,3.27],[95,2.72]],"id":41419588}],"con":true,"img":false}]}
{"op":"mcm","clk":"5353031809","pt":1646207232548,"mc":[{"id":"1.195503860","rc":[{"atb":[[19,0],[23,0]],"id":41419602}],"con":true,"img":false}]}
{"op":"mcm","clk":"5353031848","pt":1646207233316,"mc":[{"id":"1.195503860","rc":[{"atb":[[18.5,3.27],[22,2.72]],"id":41419602}],"con":true,"img":false}]}
{"op":"mcm","clk":"5353032898","pt":1646207256500,"mc":[{"id":"1.195503860","rc":[{"atb":[[16.5,12.9],[14,0]],"id":41419597},{"atb":[[8,28.58],[9,0]],"id":41419594},{"atb":[[8,28.58],[9,0]],"id":41419595},{"atb":[[17.5,0],[20,0]],"id":41419592}],"con":true,"img":false}]}
{"op":"mcm","clk":"5353032945","pt":1646207257178,"mc":[{"id":"1.195503860","rc":[{"atb":[[13,3.27],[15.5,2.72]],"id":41419597},{"atb":[[9.8,2.72],[8.8,3.27]],"id":41419594},{"atb":[[9,3.27],[10,2.72]],"id":41419595},{"atb":[[13,3.27],[15.5,16.52]],"id":41419592}],"con":true,"img":false}]}
{"op":"mcm","clk":"5353040927","pt":1646207433347,"mc":[{"id":"1.195503860","rc":[{"atb":[[18,0],[15.5,0]],"id":41419614}],"con":true,"img":false}]}
{"op":"mcm","clk":"5353040940","pt":1646207433655,"mc":[{"id":"1.195503860","rc":[{"atb":[[34,0],[27,0]],"id":41419609},{"atb":[[17.5,0],[15,0]],"id":41419607}],"con":true,"img":false}]}
{"op":"mcm","clk":"5353040953","pt":1646207434068,"mc":[{"id":"1.195503860","rc":[{"atb":[[17.5,2.72],[15,3.27]],"id":41419614}],"con":true,"img":false}]}
{"op":"mcm","clk":"5353040963","pt":1646207434377,"mc":[{"id":"1.195503860","rc":[{"atb":[[32,2.72],[26,3.27]],"id":41419609},{"atb":[[17,2.72],[14.5,3.27]],"id":41419607}],"con":true,"img":false}]}
{"op":"mcm","clk":"5353041841","pt":1646207459709,"mc":[{"id":"1.195503860","rc":[{"atb":[[21,5]],"id":41419605},{"atl":[[880,2]],"id":41419605},{"atb":[[22,2]],"id":41419634},{"atb":[[14,7.69]],"id":41419618},{"atl":[[800,2]],"id":41419618},{"atb":[[8.2,50.94]],"id":41419601},{"atl":[[590,2]],"id":41419601},{"atb":[[22,14.29]],"id":41419630},{"atl":[[910,2]],"id":41419630},{"atb":[[4.9,25.64]],"id":41419597},{"atl":[[380,2]],"id":41419597},{"atb":[[22,2]],"id":41419626},{"atb":[[9.4,11.9]],"id":41419585},{"atl":[[750,2]],"id":41419585},{"atb":[[6.4,18.52]],"id":41419614},{"atl":[[480,2]],"id":41419614},{"atb":[[22,4.76]],"id":41419623},{"atl":[[1000,2]],"id":41419623},{"atb":[[22,3.79]],"id":41419590},{"atb":[[22,4.76]],"id":41419619},{"atl":[[1000,2]],"id":41419619},{"atb":[[22,3.91]],"id":41419627},{"atl":[[970,2]],"id":41419627},{"atb":[[6,20]],"id":41419607},{"atl":[[460,2]],"id":41419607},{"atb":[[22,2]],"id":41419591},{"atb":[[22,4.76]],"id":41419587},{"atb":[[22,4.76]],"id":41419632},{"atb":[[8.8,12.82]],"id":41419608},{"atl":[[630,2]],"id":41419608},{"atb":[[8.8,12.82]],"id":41419616},{"atl":[[620,2]],"id":41419616},{"atb":[[4.5,24.53]],"id":41419592},{"atl":[[410,2]],"id":41419592},{"atb":[[22,4.76]],"id":41419588},{"atb":[[22,2]],"id":41419633},{"atb":[[4.8,26.32]],"id":41419600},{"atl":[[360,2]],"id":41419600},{"atb":[[14.5,7.41]],"id":41419629},{"atl":[[810,2]],"id":41419629},{"atb":[[5.8,20.83]],"id":41419596},{"atl":[[450,2]],"id":41419596}],"con":true,"img":false}]}
{"op":"mcm","clk":"5353041844","pt":1646207459812,"mc":[{"id":"1.195503860","rc":[{"atb":[[8.6,13.16]],"id":41419609},{"atl":[[610,2]],"id":41419609},{"atb":[[22,3.84]],"id":41419638},{"atb":[[22,14.29]],"id":41419617},{"atl":[[910,2]],"id":41419617},{"atb":[[16,6.56]],"id":41419613},{"atl":[[830,2]],"id":41419613},{"atb":[[3.8,35.71]],"id":41419593},{"atl":[[260,2]],"id":41419593},{"atb":[[22,4.76]],"id":41419622},{"atl":[[1000,2]],"id":41419622},{"atb":[[22,4.14]],"id":41419589},{"atb":[[22,2]],"id":41419639},{"atb":[[14.5,6.56]],"id":41419606},{"atl":[[810,2]],"id":41419606},{"atb":[[22,4.76]],"id":41419635},{"atl":[[940,2]],"id":41419635},{"atb":[[8.4,13.51]],"id":41419602},{"atl":[[600,2]],"id":41419602},{"atb":[[21,5]],"id":41419610},{"atl":[[890,2]],"id":41419610},{"atb":[[22,4.76]],"id":41419586},{"atl":[[1000,2]],"id":41419586},{"atb":[[22,14.29]],"id":41419631},{"atl":[[930,2]],"id":41419631},{"atb":[[8.4,8.9]],"id":41419598},{"atl":[[530,2]],"id":41419598},{"atb":[[4.6,27.78]],"id":41419594},{"atl":[[340,2]],"id":41419594},{"atb":[[22,2]],"id":41419640},{"atb":[[22,4.76]],"id":41419636},{"atb":[[14,7.69]],"id":41419603},{"atl":[[800,2]],"id":41419603},{"atb":[[9.2,12.2]],"id":41419615},{"atl":[[650,2]],"id":41419615},{"atb":[[13,8.33]],"id":41419611},{"atl":[[780,2]],"id":41419611},{"atb":[[22,4.76]],"id":41419624},{"atl":[[1000,2]],"id":41419624},{"atb":[[22,4.76]],"id":41419620},{"atb":[[10,8.52]],"id":41419599},{"atl":[[720,2]],"id":41419599},{"atb":[[8.2,13.89]],"id":41419628},{"atl":[[590,2]],"id":41419628},{"atb":[[4.7,27.03]],"id":41419595},{"atl":[[350,2]],"id":41419595},{"atb":[[22,3.84]],"id":41419637},{"atb":[[8.8,12.82]],"id":41419604},{"atl":[[620,2]],"id":41419604},{"atb":[[22,4.76]],"id":41419612},{"atl":[[1000,2]],"id":41419612},{"atb":[[22,4.76]],"id":41419625},{"atb":[[10.5,10.53]],"id":41419621},{"atl":[[740,2]],"id":41419621}],"con":true,"img":false}]}
{"op":"mcm","clk":"5353042713","pt":1646207483924,"mc":[{"id":"1.195503860","rc":[{"atb":[[18.5,0],[22,0]],"id":41419602}],"con":true,"img":false}]}
{"op":"mcm","clk":"5353042750","pt":1646207484854,"mc":[{"id":"1.195503860","rc":[{"atb":[[19,3.27],[23,2.72]],"id":41419602}],"con":true,"img":false}]}
{"op":"mcm","clk":"5353043044","pt":1646207493038,"mc":[{"id":"1.195503860","rc":[{"atl":[[1000,0]],"id":41419624}],"con":true,"img":false}]}
{"op":"mcm","clk":"5353056954","pt":1646207882994,"mc":[{"id":"1.195503860","rc":[{"atl":[[910,0],[900,2]],"id":41419617},{"atl":[[890,2],[910,0]],"id":41419630},{"atl":[[380,0],[370,2]],"id":41419597},{"atl":[[890,0],[870,2]],"id":41419610},{"atl":[[910,2],[930,0]],"id":41419631},{"atl":[[940,2],[970,0]],"id":41419627},{"atl":[[780,0],[770,2]],"id":41419611},{"atl":[[1000,2]],"id":41419624},{"atl":[[1000,2]],"id":41419632},{"atl":[[550,2],[590,0]],"id":41419628},{"atl":[[720,2],[740,0]],"id":41419621},{"atl":[[790,2],[810,0]],"id":41419629},{"atl":[[440,2],[450,0]],"id":41419596}],"con":true,"img":false}]}
{"op":"mcm","clk":"5353056973","pt":1646207883405,"mc":[{"id":"1.195503860","rc":[{"atb":[[13,0],[15.5,0]],"id":41419597}],"con":true,"img":false}]}
{"op":"mcm","clk":"5353056978","pt":1646207883508,"mc":[{"id":"1.195503860","rc":[{"atl":[[810,0],[800,2]],"id":41419606},{"atl":[[940,0],[930,2]],"id":41419635},{"atl":[[730,2],[750,0]],"id":41419585},{"atl":[[410,0],[400,2]],"id":41419592}],"con":true,"img":false}]}
{"op":"mcm","clk":"5353056995","pt":1646207883918,"mc":[{"id":"1.195503860","rc":[{"atb":[[13,0],[15.5,13.79]],"id":41419592}],"con":true,"img":false}]}
{"op":"mcm","clk":"5353057011","pt":1646207884227,"mc":[{"id":"1.195503860","rc":[{"atb":[[12.5,3.27],[15,2.72]],"id":41419597}],"con":true,"img":false}]}
{"op":"mcm","clk":"5353057029","pt":1646207884642,"mc":[{"id":"1.195503860","rc":[{"atb":[[12.5,3.27],[15,2.72]],"id":41419592}],"con":true,"img":false}]}
{"op":"mcm","clk":"5353057177","pt":1646207888128,"mc":[{"id":"1.195503860","rc":[{"atl":[[870,0],[880,2]],"id":41419610},{"atl":[[450,2]],"id":41419596}],"con":true,"img":false}]}
{"op":"mcm","clk":"5353057183","pt":1646207888231,"mc":[{"id":"1.195503860","rc":[{"atl":[[900,0],[910,2]],"id":41419617},{"atl":[[890,0],[900,2]],"id":41419630},{"atl":[[910,0],[920,2]],"id":41419631},{"atl":[[440,0]],"id":41419596}],"con":true,"img":false}]}
{"op":"mcm","clk":"5353057423","pt":1646207893645,"mc":[{"id":"1.195503860","rc":[{"atl":[[800,0],[810,2]],"id":41419606},{"atl":[[770,0],[780,2]],"id":41419611}],"con":true,"img":false}]}
{"op":"mcm","clk":"5353057441","pt":1646207893961,"mc":[{"id":"1.195503860","rc":[{"atb":[[12.5,0],[15,0]],"id":41419597}],"con":true,"img":false}]}
{"op":"mcm","clk":"5353057473","pt":1646207894621,"mc":[{"id":"1.195503860","rc":[{"atb":[[12,3.27],[14.5,2.72]],"id":41419597}],"con":true,"img":false}]}
{"op":"mcm","clk":"5353057822","pt":1646207902121,"mc":[{"id":"1.195503860","rc":[{"atl":[[440,2],[450,0]],"id":41419596}],"con":true,"img":false}]}
{"op":"mcm","clk":"5353066597","pt":1646208102209,"mc":[{"id":"1.195503860","rc":[{"atb":[[9,0],[10,0]],"id":41419595}],"con":true,"img":false}]}
{"op":"mcm","clk":"5353066624","pt":1646208102926,"mc":[{"id":"1.195503860","rc":[{"atb":[[9.8,2.72],[8.8,3.27]],"id":41419595}],"con":true,"img":false}]}
{"op":"mcm","clk":"5353071947","pt":1646208222388,"mc":[{"id":"1.195503860","rc":[{"atl":[[1000,0]],"id":41419619},{"atl":[[1000,0]],"id":41419624},{"atl":[[1000,0]],"id":41419632},{"atb":[[10.5,0],[8.8,12.82]],"id":41419621},{"atb":[[5.8,0],[5,25]],"id":41419596}],"con":true,"img":false}]}
{"op":"mcm","clk":"5353072962","pt":1646208244284,"mc":[{"id":"1.195503860","rc":[{"atl":[[1000,2]],"id":41419619},{"atl":[[1000,2]],"id":41419624},{"atl":[[1000,2]],"id":41419632},{"atb":[[9.8,11.36],[8.8,0]],"id":41419621},{"atb":[[5.6,21.74],[5,0]],"id":41419596}],"con":true,"img":false}]}
{"op":"mcm","clk":"5353074765","pt":1646208280768,"mc":[{"id":"1.195503860","rc":[{"atl":[[930,2]],"id":41419627}],"con":true,"img":false}]}
{"op":"mcm","clk":"5353074772","pt":1646208280863,"mc":[{"id":"1.195503860","rc":[{"atl":[[940,0]],"id":41419627}],"con":true,"img":false}]}
{"op":"mcm","clk":"5353083339","pt":1646208460602,"mc":[{"id":"1.195503860","rc":[{"atl":[[880,2],[910,0]],"id":41419617},{"atl":[[940,2],[1000,0]],"id":41419622},{"atl":[[860,2],[880,0]],"id":41419610},{"atl":[[770,2],[800,0]],"id":41419603},{"atl":[[1000,2]],"id":41419620},{"atl":[[1000,2]],"id":41419625},{"atl":[[640,2],[720,0]],"id":41419621},{"atl":[[430,2],[440,0]],"id":41419596}],"con":true,"img":false}]}
{"op":"mcm","clk":"5353083366","pt":1646208461115,"mc":[{"id":"1.195503860","rc":[{"atb":[[12,0],[14.5,0]],"id":41419597}],"con":true,"img":false}]}
{"op":"mcm","clk":"5353083396","pt":1646208461785,"mc":[{"id":"1.195503860","rc":[{"atb":[[12.5,3.27],[15,2.72]],"id":41419597}],"con":true,"img":false}]}
{"op":"mcm","clk":"5353083614","pt":1646208466527,"mc":[{"id":"1.195503860","rc":[{"atl":[[760,2],[810,0]],"id":41419606},{"atb":[[5.6,21.74],[6.4,0]],"id":41419614},{"atl":[[450,2],[480,0]],"id":41419614},{"atl":[[1000,0]],"id":41419586},{"atb":[[4,33.33],[4.6,0]],"id":41419594},{"atl":[[310,2],[340,0]],"id":41419594},{"atb":[[6,0],[5.4,22.73]],"id":41419607},{"atl":[[440,2],[460,0]],"id":41419607},{"atl":[[1000,2]],"id":41419587},{"atb":[[10,0],[12.5,8.52]],"id":41419599},{"atb":[[4.1,32.26],[4.7,0]],"id":41419595},{"atl":[[330,2],[350,0]],"id":41419595},{"atb":[[17.5,6.06],[14.5,0]],"id":41419629}],"con":true,"img":false}]}
{"op":"mcm","clk":"5353083639","pt":1646208467194,"mc":[{"id":"1.195503860","rc":[{"atb":[[12.5,0],[15,0]],"id":41419592}],"con":true,"img":false}]}
{"op":"mcm","clk":"5353083676","pt":1646208467915,"mc":[{"id":"1.195503860","rc":[{"atb":[[16,2.72],[13.5,3.27]],"id":41419592}],"con":true,"img":false}]}
{"op":"mcm","clk":"5353085269","pt":1646208505771,"mc":[{"id":"1.195503860","rc":[{"atb":[[9.8,0],[8.8,0]],"id":41419595}],"con":true,"img":false}]}
{"op":"mcm","clk":"5353085304","pt":1646208506438,"mc":[{"id":"1.195503860","rc":[{"atb":[[9,3.27],[10,2.72]],"id":41419595}],"con":true,"img":false}]}
{"op":"mcm","clk":"5353087239","pt":1646208553130,"mc":[{"id":"1.195503860","rc":[{"atb":[[9,0],[10,0]],"id":41419595}],"con":true,"img":false}]}
{"op":"mcm","clk":"5353087280","pt":1646208553798,"mc":[{"id":"1.195503860","rc":[{"atb":[[9.8,2.72],[8.8,3.27]],"id":41419595}],"con":true,"img":false}]}
{"op":"mcm","clk":"5353088242","pt":1646208575654,"mc":[{"id":"1.195503860","rc":[{"atl":[[600,2],[610,0]],"id":41419609},{"atb":[[16,0],[22,4.76]],"id":41419613},{"atl":[[260,0],[230,2]],"id":41419593},{"atb":[[20,5.26],[14,0]],"id":41419618},{"atl":[[590,0],[580,2]],"id":41419601},{"atb":[[18.5,5.71],[14.5,0]],"id":41419606},{"atl":[[440,2],[450,0]],"id":41419614},{"atl":[[1000,0]],"id":41419619},{"atl":[[930,0]],"id":41419627},{"atb":[[4,0],[3.7,37.04]],"id":41419594},{"atl":[[310,0],[240,2]],"id":41419594},{"atl":[[430,2],[440,0]],"id":41419607},{"atb":[[17.5,18.18],[14,0]],"id":41419603},{"atl":[[650,0],[640,2]],"id":41419615},{"atb":[[18.5,5.71],[13,0]],"id":41419611},{"atl":[[1000,0]],"id":41419620},{"atl":[[1000,0]],"id":41419587},{"atl":[[1000,0]],"id":41419632},{"atb":[[16.5,6.45],[12.5,0]],"id":41419599},{"atb":[[4.1,0],[3.75,36.36]],"id":41419595},{"atl":[[260,2],[330,0]],"id":41419595},{"atl":[[630,0],[620,2]],"id":41419608},{"atb":[[10.5,10.53],[8.8,0]],"id":41419604},{"atl":[[590,2],[620,0]],"id":41419616},{"atl":[[1000,0]],"id":41419612},{"atl":[[1000,0]],"id":41419625},{"atb":[[4.5,0],[5.7,21.28]],"id":41419592}],"con":true,"img":false}]}
{"op":"mcm","clk":"5353088259","pt":1646208575964,"mc":[{"id":"1.195503860","rc":[{"atb":[[9.8,0],[8.8,0]],"id":41419594},{"atb":[[9.8,0],[8.8,0]],"id":41419595},{"atb":[[16,0],[13.5,0]],"id":41419592}],"con":true,"img":false}]}
{"op":"mcm","clk":"5353088287","pt":1646208576634,"mc":[{"id":"1.195503860","rc":[{"atb":[[18,3.27],[21,2.72]],"id":41419592}],"con":true,"img":false}]}
{"op":"mcm","clk":"5353088298","pt":1646208576940,"mc":[{"id":"1.195503860","rc":[{"atb":[[9.2,2.72],[8.2,3.27]],"id":41419594},{"atb":[[9.6,2.72],[8.6,3.27]],"id":41419595}],"con":true,"img":false}]}
{"op":"mcm","clk":"5353088877","pt":1646208589364,"mc":[{"id":"1.195503860","rc":[{"atb":[[12.5,0]],"id":41419597}],"con":true,"img":false}]}
{"op":"mcm","clk":"5353088886","pt":1646208589571,"mc":[{"id":"1.195503860","rc":[{"atb":[[15,0]],"id":41419597}],"con":true,"img":false}]}
{"op":"mcm","clk":"5353088904","pt":1646208590037,"mc":[{"id":"1.195503860","rc":[{"atb":[[14.5,3.27]],"id":41419597}],"con":true,"img":false}]}
{"op":"mcm","clk":"5353088915","pt":1646208590346,"mc":[{"id":"1.195503860","rc":[{"atb":[[17,2.72]],"id":41419597}],"con":true,"img":false}]}
{"op":"mcm","clk":"5353089062","pt":1646208593355,"mc":[{"id":"1.195503860","rc":[{"atl":[[570,2],[580,0]],"id":41419601},{"atb":[[5.5,22.22],[4.9,0]],"id":41419597},{"atl":[[600,0],[590,2]],"id":41419602},{"atl":[[430,2],[440,0]],"id":41419614},{"atl":[[230,2]],"id":41419594},{"atl":[[620,2],[640,0]],"id":41419615},{"atb":[[9.2,44.73],[8.2,0]],"id":41419628},{"atl":[[260,0],[250,2]],"id":41419595},{"atl":[[590,0],[580,2]],"id":41419616},{"atb":[[17.5,0],[20,5.26]],"id":41419629},{"atb":[[5.6,0],[6.2,19.23]],"id":41419596}],"con":true,"img":false}]}
{"op":"mcm","clk":"5353089069","pt":1646208593458,"mc":[{"id":"1.195503860","rc":[{"atl":[[240,0]],"id":41419594}],"con":true,"img":false}]}
{"op":"mcm","clk":"5353089086","pt":1646208593768,"mc":[{"id":"1.195503860","rc":[{"atb":[[9.2,0],[8.2,0]],"id":41419594}],"con":true,"img":false}]}
{"op":"mcm","clk":"5353089100","pt":1646208594076,"mc":[{"id":"1.195503860","rc":[{"atb":[[9.6,0],[8.6,0]],"id":41419595}],"con":true,"img":false}]}
{"op":"mcm","clk":"5353089115","pt":1646208594488,"mc":[{"id":"1.195503860","rc":[{"atb":[[8,31.86],[9,2.72]],"id":41419594}],"con":true,"img":false}]}
{"op":"mcm","clk":"5353089131","pt":1646208594744,"mc":[{"id":"1.195503860","rc":[{"atb":[[8.4,3.27],[9.4,2.72]],"id":41419595}],"con":true,"img":false}]}
{"op":"mcm","clk":"5353089512","pt":1646208603092,"mc":[{"id":"1.195503860","rc":[{"atl":[[570,0],[580,2]],"id":41419601},{"atl":[[590,0],[600,2]],"id":41419602},{"atl":[[430,0],[440,2]],"id":41419614},{"atl":[[620,0],[640,2]],"id":41419615},{"atl":[[580,0],[590,2]],"id":41419616}],"con":true,"img":false}]}
{"op":"mcm","clk":"5353094508","pt":1646208708835,"mc":[{"id":"1.195503860","rc":[{"atb":[[8,28.58],[9,0]],"id":41419594}],"con":true,"img":false}]}
{"op":"mcm","clk":"5353094520","pt":1646208709101,"mc":[{"id":"1.195503860","rc":[{"atb":[[8.4,0],[9.4,0]],"id":41419595}],"con":true,"img":false}]}
{"op":"mcm","clk":"5353094542","pt":1646208709610,"mc":[{"id":"1.195503860","rc":[{"atb":[[9.2,2.72],[8.2,3.27]],"id":41419594}],"con":true,"img":false}]}
{"op":"mcm","clk":"5353094557","pt":1646208710019,"mc":[{"id":"1.195503860","rc":[{"atb":[[9.6,2.72],[8.6,3.27]],"id":41419595}],"con":true,"img":false}]}
{"op":"mcm","clk":"5353096997","pt":1646208763297,"mc":[{"id":"1.195503860","rc":[{"atb":[[17,0],[14.5,0]],"id":41419607}],"con":true,"img":false}]}
{"op":"mcm","clk":"5353097022","pt":1646208763967,"mc":[{"id":"1.195503860","rc":[{"atb":[[17.5,2.72],[15,3.27]],"id":41419607}],"con":true,"img":false}]}
{"op":"mcm","clk":"5353097144","pt":1646208766607,"mc":[{"id":"1.195503860","rc":[{"atl":[[1000,2]],"id":41419587}],"con":true,"img":false}]}
{"op":"mcm","clk":"5353099258","pt":1646208811688,"mc":[{"id":"1.195503860","rc":[{"atb":[[24,0],[9.8,0],[14.5,0]],"id":41419609},{"atb":[[140,0],[390,0],[240,0]],"id":41419638},{"atb":[[34,0],[170,0],[60,2.72]],"id":41419605},{"atb":[[600,0],[700,0],[850,0]],"id":41419634},{"atb":[[16,0],[44,0],[22,4.76]],"id":41419617},{"atb":[[75,0],[20,0],[30,0]],"id":41419613},{"atb":[[4.5,0],[6,0],[3.75,0]],"id":41419593},{"atb":[[36,0],[19,0],[14,0]],"id":41419622},{"atb":[[130,0],[380,0],[230,0]],"id":41419589},{"atb":[[42,0],[21,0],[15.5,0]],"id":41419618},{"atb":[[18,0],[10.5,0],[8.2,13.89]],"id":41419601},{"atb":[[16,0],[44,0],[22,4.76]],"id":41419630},{"atb":[[16.5,0],[9.6,0],[7.6,0]],"id":41419597},{"atb":[[600,0],[700,0],[850,0]],"id":41419626},{"atb":[[600,0],[700,0],[850,0]],"id":41419639},{"atb":[[75,0],[20,0],[30,0]],"id":41419606},{"atb":[[75,0],[20,0],[30,0]],"id":41419635},{"atb":[[18,0],[10.5,0],[8.2,0]],"id":41419602},{"atb":[[34,0],[18.5,0],[13.5,0]],"id":41419585},{"atb":[[10,0],[5.5,0],[7,0]],"id":41419614},{"atb":[[16,0],[44,0],[22,0]],"id":41419610},{"atb":[[16.5,0],[46,3.27],[23,0]],"id":41419623},{"atb":[[340,0],[190,0],[95,3.27]],"id":41419590},{"atb":[[330,0],[180,0],[90,0]],"id":41419619},{"atb":[[18,0],[26,0],[55,3.27]],"id":41419586},{"atb":[[16,0],[44,0],[22,4.76]],"id":41419631},{"atb":[[16.5,0],[46,0],[23,0]],"id":41419598},{"atb":[[320,0],[170,0],[85,3.27]],"id":41419627},{"atb":[[8,0],[4.5,0],[5.5,0]],"id":41419594},{"atb":[[600,0],[700,0],[850,0]],"id":41419640},{"atb":[[10,0],[5.5,0],[7,0]],"id":41419607},{"atb":[[95,0],[48,0],[240,0]],"id":41419636},{"atb":[[17.5,6.06],[12.5,0],[30,0]],"id":41419603},{"atb":[[18.5,0],[11,0],[8.4,0]],"id":41419615},{"atb":[[42,0],[21,0],[15.5,0]],"id":41419611},{"atb":[[16.5,0],[46,3.27],[23,0]],"id":41419624},{"atb":[[600,0],[700,0],[850,0]],"id":41419591},{"atb":[[360,0],[210,0],[110,0]],"id":41419620},{"atb":[[36,0],[90,0],[23,0]],"id":41419587},{"atb":[[44,0],[27,0],[120,0]],"id":41419632},{"atb":[[17,0],[48,0],[24,0]],"id":41419599},{"atb":[[9.2,12.2],[21,0],[13,0]],"id":41419628},{"atb":[[8,0],[4.5,0],[5.5,0]],"id":41419595},{"atb":[[18.5,0],[11,0],[8.4,0]],"id":41419608},{"atb":[[140,0],[390,0],[240,0]],"id":41419637},{"atb":[[17,0],[12,0],[29,0]],"id":41419604},{"atb":[[24,0],[9.8,0],[14.5,0]],"id":41419616},{"atb":[[330,0],[180,0],[90,0]],"id":41419612},{"atb":[[44,0],[27,0],[120,0]],"id":41419625},{"atb":[[10.5,0],[26,0],[15.5,0]],"id":41419592},{"atb":[[9.6,0],[23,0],[14,0]],"id":41419621},{"atb":[[36,0],[90,0],[23,0]],"id":41419588},{"atb":[[600,0],[700,0],[850,0]],"id":41419633},{"atb":[[4.3,0],[5.3,0],[7.6,0]],"id":41419600},{"atb":[[32,0],[18,0],[13,0]],"id":41419629},{"atb":[[8,0],[17.5,0],[10,0]],"id":41419596}],"con":true,"img":false}]}
{"op":"mcm","clk":"5353099317","pt":1646208812873,"mc":[{"id":"1.195503860","rc":[{"atb":[[9.6,0],[8.6,0]],"id":41419595}],"con":true,"img":false}]}
{"op":"mcm","clk":"5353099340","pt":1646208813340,"mc":[{"id":"1.195503860","rc":[{"atb":[[9.2,0],[8.2,0]],"id":41419594}],"con":true,"img":false}]}
{"op":"mcm","clk":"5353099357","pt":1646208813545,"mc":[{"id":"1.195503860","rc":[{"atb":[[8.8,3.27]],"id":41419595}],"con":true,"img":false}]}
{"op":"mcm","clk":"5353099364","pt":1646208813854,"mc":[{"id":"1.195503860","rc":[{"atb":[[9.8,2.72]],"id":41419595}],"con":true,"img":false}]}
{"op":"mcm","clk":"5353099383","pt":1646208814268,"mc":[{"id":"1.195503860","rc":[{"atb":[[8.4,3.27],[9.4,2.72]],"id":41419594}],"con":true,"img":false}]}
{"op":"mcm","clk":"5353099507","pt":1646208816814,"mc":[{"id":"1.195503860","rc":[{"atb":[[7.8,39.23],[14.5,9.87],[5.9,54.45]],"id":41419609},{"atb":[[70,3.86],[38,7.21],[240,0.55]],"id":41419638},{"atb":[[16,17.78],[22,12.7],[60,4.98]],"id":41419605},{"atb":[[700,0.19],[400,0.67],[500,0.53]],"id":41419634},{"atb":[[22,11.11],[11,26.68],[8.4,36.05]],"id":41419617},{"atb":[[10,29.64],[30,4.6],[15,19.05]],"id":41419613},{"atb":[[4.5,38.11],[2.9,140.42],[3.25,118.58]],"id":41419593},{"atb":[[9.6,31.02],[19,7.41],[7.6,40.42]],"id":41419622},{"atb":[[65,4.17],[36,7.62],[230,0.58]],"id":41419589},{"atb":[[21,6.67],[10.5,28.08],[8.2,37.05]],"id":41419618},{"atb":[[5.1,65.07],[10.5,14.04],[6.2,51.31]],"id":41419601},{"atb":[[22,11.11],[11,26.68],[8.4,36.05]],"id":41419630},{"atb":[[9.6,15.51],[4.8,70.21],[5.8,55.58]],"id":41419597},{"atb":[[700,0.19],[400,0.67],[500,0.53]],"id":41419626},{"atb":[[700,0.19],[400,0.67],[500,0.53]],"id":41419639},{"atb":[[10,29.64],[30,4.6],[15,19.05]],"id":41419606},{"atb":[[10,29.64],[30,4.6],[15,19.05]],"id":41419635},{"atb":[[5.1,65.07],[10.5,14.04],[6.2,51.31]],"id":41419602},{"atb":[[18.5,7.62],[7.4,41.69],[9.4,43.66]],"id":41419585},{"atb":[[4.5,76.23],[7,22.23],[3.75,97.02]],"id":41419614},{"atb":[[22,6.35],[11,26.68],[8.4,36.05]],"id":41419610},{"atb":[[8.6,35.1],[23,6.06],[11.5,25.4]],"id":41419623},{"atb":[[190,0.7],[48,5.67],[29,9.53]],"id":41419590},{"atb":[[180,0.74],[46,5.92],[28,9.87]],"id":41419619},{"atb":[[9.2,32.53],[26,5.33],[13,22.23]],"id":41419586},{"atb":[[22,11.11],[11,26.68],[8.4,36.05]],"id":41419631},{"atb":[[8.6,35.1],[23,6.06],[11.5,25.4]],"id":41419598},{"atb":[[170,0.79],[44,6.2],[27,10.26]],"id":41419627},{"atb":[[5.5,29.64],[3.25,118.58],[3.75,97.02]],"id":41419594},{"atb":[[700,0.19],[400,0.67],[500,0.53]],"id":41419640},{"atb":[[4.5,76.23],[7,22.23],[3.75,97.02]],"id":41419607},{"atb":[[19.5,14.42],[95,1.41],[29,9.53]],"id":41419636},{"atb":[[17.5,14.14],[9,33.35],[7,44.47]],"id":41419603},{"atb":[[6.4,49.41],[11,13.34],[5.2,63.52]],"id":41419615},{"atb":[[21,6.67],[10.5,28.08],[8.2,37.05]],"id":41419611},{"atb":[[8.6,35.1],[23,6.06],[11.5,25.4]],"id":41419624},{"atb":[[700,0.19],[400,0.67],[500,0.53]],"id":41419591},{"atb":[[32,8.6],[210,0.63],[55,4.93]],"id":41419620},{"atb":[[16.5,17.21],[36,3.81],[11.5,25.4]],"id":41419587},{"atb":[[18.5,15.24],[44,3.1],[13.5,21.34]],"id":41419632},{"atb":[[24,5.8],[12,24.25],[8.8,34.2]],"id":41419599},{"atb":[[5.6,58],[7.2,43.03],[13,11.11]],"id":41419628},{"atb":[[5.5,29.64],[3.25,118.58],[3.75,133.38]],"id":41419595},{"atb":[[6.4,49.41],[11,13.34],[5.2,63.52]],"id":41419608},{"atb":[[70,3.86],[38,7.21],[240,0.55]],"id":41419637},{"atb":[[17,8.34],[6.8,46],[8.8,34.2]],"id":41419604},{"atb":[[7.8,39.23],[14.5,9.87],[5.9,54.45]],"id":41419616},{"atb":[[180,0.74],[46,5.92],[28,9.87]],"id":41419612},{"atb":[[18.5,15.24],[44,3.1],[13.5,21.34]],"id":41419625},{"atb":[[6.2,51.31],[8.2,37.05],[15.5,9.2]],"id":41419592},{"atb":[[5.8,55.58],[7.6,40.42],[14,10.26]],"id":41419621},{"atb":[[16.5,17.21],[36,3.81],[11.5,25.4]],"id":41419588},{"atb":[[700,0.19],[400,0.67],[500,0.53]],"id":41419633},{"atb":[[5.3,31.02],[3.15,124.09],[3.65,100.68]],"id":41419600},{"atb":[[7.2,43.03],[18,7.84],[9.2,32.53]],"id":41419629},{"atb":[[10,14.82],[5,66.7],[6,53.36]],"id":41419596}],"con":true,"img":false}]}
{"op":"mcm","clk":"5353100125","pt":1646208829793,"mc":[{"id":"1.195503860","rc":[{"atl":[[600,0],[580,2]],"id":41419609},{"atl":[[570,2],[580,0]],"id":41419601},{"atl":[[600,0],[590,2]],"id":41419602},{"atl":[[430,2],[440,0]],"id":41419614},{"atl":[[430,0],[420,2]],"id":41419607},{"atl":[[620,2],[640,0]],"id":41419615},{"atl":[[620,0],[610,2]],"id":41419608},{"atl":[[570,2],[590,0]],"id":41419616}],"con":true,"img":false}]}
{"op":"mcm","clk":"5353100153","pt":1646208830258,"mc":[{"id":"1.195503860","rc":[{"atb":[[8.4,0],[9.4,0]],"id":41419594},{"atb":[[9.8,0],[8.8,0]],"id":41419595},{"atb":[[34,0],[27,0]],"id":41419616}],"con":true,"img":false}]}
{"op":"mcm","clk":"5353100188","pt":1646208830981,"mc":[{"id":"1.195503860","rc":[{"atb":[[8,3.27],[9,2.72]],"id":41419594}],"con":true,"img":false}]}
{"op":"mcm","clk":"5353100205","pt":1646208831291,"mc":[{"id":"1.195503860","rc":[{"atb":[[9.6,2.72],[8.6,3.27]],"id":41419595},{"atb":[[32,2.72],[26,3.27]],"id":41419616}],"con":true,"img":false}]}
{"op":"mcm","clk":"5353100592","pt":1646208839378,"mc":[{"id":"1.195503860","rc":[{"atl":[[570,0],[560,2]],"id":41419616}],"con":true,"img":false}]}
{"op":"mcm","clk":"5353101046","pt":1646208848880,"mc":[{"id":"1.195503860","rc":[{"atl":[[560,0],[550,2]],"id":41419616}],"con":true,"img":false}]}
{"op":"mcm","clk":"5353101553","pt":1646208858710,"mc":[{"id":"1.195503860","rc":[{"atb":[[6.8,0],[7.8,0]],"id":41419593},{"atb":[[17.5,0],[15,0]],"id":41419607}],"con":true,"img":false}]}
{"op":"mcm","clk":"5353101609","pt":1646208859592,"mc":[{"id":"1.195503860","rc":[{"atb":[[8,2.72],[7,3.27]],"id":41419593},{"atb":[[17,2.72],[14.5,3.27]],"id":41419607}],"con":true,"img":false}]}
{"op":"mcm","clk":"5353101842","pt":1646208864530,"mc":[{"id":"1.195503860","rc":[{"atb":[[4.5,0],[2.9,0],[3.25,0]],"id":41419593},{"atb":[[65,0],[36,0],[230,0]],"id":41419589},{"atb":[[5.1,0],[10.5,0],[6.2,0]],"id":41419601},{"atb":[[9.6,0],[4.8,0],[5.8,0]],"id":41419597},{"atb":[[5.1,0],[10.5,0],[6.2,0]],"id":41419602},{"atb":[[18.5,0],[7.4,0],[9.4,11.9]],"id":41419585},{"atb":[[190,0],[48,0],[29,0]],"id":41419590},{"atb":[[9.2,0],[26,0],[13,0]],"id":41419586},{"atb":[[8.6,0],[23,0],[11.5,0]],"id":41419598},{"atb":[[5.5,0],[3.25,0],[3.75,0]],"id":41419594},{"atb":[[17.5,6.06],[9,0],[7,0]],"id":41419603},{"atb":[[700,0],[400,0],[500,0]],"id":41419591},{"atb":[[16.5,0],[36,0],[11.5,0]],"id":41419587},{"atb":[[24,0],[12,0],[8.8,0]],"id":41419599},{"atb":[[5.5,0],[3.25,0],[3.75,36.36]],"id":41419595},{"atb":[[17,0],[6.8,0],[8.8,0]],"id":41419604},{"atb":[[6.2,0],[8.2,0],[15.5,0]],"id":41419592},{"atb":[[16.5,0],[36,0],[11.5,0]],"id":41419588},{"atb":[[5.3,0],[3.15,0],[3.65,0]],"id":41419600},{"atb":[[10,0],[5,0],[6,0]],"id":41419596}],"con":true,"img":false}]}
{"op":"mcm","clk":"5353101849","pt":1646208864633,"mc":[{"id":"1.195503860","rc":[{"atb":[[7.8,0],[14.5,0],[5.9,0]],"id":41419609},{"atb":[[16,0],[22,0],[60,2.72]],"id":41419605},{"atb":[[22,4.76],[11,0],[8.4,0]],"id":41419617},{"atb":[[10,0],[30,0],[15,0]],"id":41419613},{"atb":[[9.6,0],[19,0],[7.6,0]],"id":41419622},{"atb":[[21,0],[10.5,0],[8.2,0]],"id":41419618},{"atb":[[10,0],[30,0],[15,0]],"id":41419606},{"atb":[[4.5,0],[7,0],[3.75,0]],"id":41419614},{"atb":[[22,0],[11,0],[8.4,0]],"id":41419610},{"atb":[[8.6,0],[23,0],[11.5,0]],"id":41419623},{"atb":[[180,0],[46,0],[28,0]],"id":41419619},{"atb":[[4.5,0],[7,0],[3.75,0]],"id":41419607},{"atb":[[6.4,0],[11,0],[5.2,0]],"id":41419615},{"atb":[[21,0],[10.5,0],[8.2,0]],"id":41419611},{"atb":[[8.6,0],[23,0],[11.5,0]],"id":41419624},{"atb":[[32,0],[210,0],[55,0]],"id":41419620},{"atb":[[6.4,0],[11,0],[5.2,0]],"id":41419608},{"atb":[[7.8,0],[14.5,0],[5.9,0]],"id":41419616},{"atb":[[180,0],[46,0],[28,0]],"id":41419612},{"atb":[[5.8,0],[7.6,0],[14,0]],"id":41419621}],"con":true,"img":false}]}
{"op":"mcm","clk":"5353101853","pt":1646208864738,"mc":[{"id":"1.195503860","rc":[{"atb":[[70,0],[38,0],[240,0]],"id":41419638},{"atb":[[700,0],[400,0],[500,0]],"id":41419634},{"atb":[[22,4.76],[11,0],[8.4,0]],"id":41419630},{"atb":[[700,0],[400,0],[500,0]],"id":41419626},{"atb":[[700,0],[400,0],[500,0]],"id":41419639},{"atb":[[10,0],[30,0],[15,0]],"id":41419635},{"atb":[[22,4.76],[11,0],[8.4,0]],"id":41419631},{"atb":[[170,0],[44,0],[27,0]],"id":41419627},{"atb":[[700,0],[400,0],[500,0]],"id":41419640},{"atb":[[19.5,0],[95,0],[29,0]],"id":41419636},{"atb":[[18.5,0],[44,0],[13.5,0]],"id":41419632},{"atb":[[5.6,0],[7.2,0],[13,0]],"id":41419628},{"atb":[[70,0],[38,0],[240,0]],"id":41419637},{"atb":[[18.5,0],[44,0],[13.5,0]],"id":41419625},{"atb":[[700,0],[400,0],[500,0]],"id":41419633},{"atb":[[7.2,0],[18,0],[9.2,0]],"id":41419629}],"con":true,"img":false}]}
{"op":"mcm","clk":"5353102519","pt":1646208879570,"mc":[{"id":"1.195503860","rc":[{"atb":[[7.8,39.23],[14.5,9.87],[5.9,54.45]],"id":41419609},{"atb":[[75,3.6],[40,6.83],[250,0.53]],"id":41419638},{"atb":[[16,17.78],[22,12.7],[60,4.98]],"id":41419605},{"atb":[[700,0.19],[400,0.67],[500,0.53]],"id":41419634},{"atb":[[22,11.11],[11,26.68],[8.4,36.05]],"id":41419617},{"atb":[[10,29.64],[30,4.6],[15,19.05]],"id":41419613},{"atb":[[4.5,38.11],[2.9,140.42],[3.25,118.58]],"id":41419593},{"atb":[[9.6,31.02],[19,7.41],[7.6,40.42]],"id":41419622},{"atb":[[65,4.17],[36,7.62],[230,0.58]],"id":41419589},{"atb":[[8,38.11],[20,12.27],[10,29.64]],"id":41419618},{"atb":[[5.1,65.07],[10.5,14.04],[6.2,51.31]],"id":41419601},{"atb":[[21,6.67],[10.5,28.08],[8.2,37.05]],"id":41419630},{"atb":[[5.6,58],[9.2,16.26],[4.6,74.11]],"id":41419597},{"atb":[[700,0.19],[400,0.67],[500,0.53]],"id":41419626},{"atb":[[700,0.19],[400,0.67],[500,0.53]],"id":41419639},{"atb":[[10,29.64],[30,4.6],[15,19.05]],"id":41419606},{"atb":[[10,29.64],[30,4.6],[15,19.05]],"id":41419635},{"atb":[[5.1,65.07],[10.5,14.04],[6.2,51.31]],"id":41419602},{"atb":[[18.5,7.62],[7.4,41.69],[9.4,43.66]],"id":41419585},{"atb":[[4.5,76.23],[7,22.23],[3.75,97.02]],"id":41419614},{"atb":[[22,6.35],[11,26.68],[8.4,36.05]],"id":41419610},{"atb":[[8.6,35.1],[23,6.06],[11.5,25.4]],"id":41419623},{"atb":[[150,0.89],[40,6.83],[25,11.11]],"id":41419590},{"atb":[[180,0.74],[46,5.92],[28,9.87]],"id":41419619},{"atb":[[9.2,32.53],[26,5.33],[13,22.23]],"id":41419586},{"atb":[[21,6.67],[10.5,28.08],[8.2,37.05]],"id":41419631},{"atb":[[8.6,35.1],[23,6.06],[11.5,25.4]],"id":41419598},{"atb":[[130,1.03],[36,7.62],[23,12.12]],"id":41419627},{"atb":[[5.6,29],[3.8,95.28],[3.3,116]],"id":41419594},{"atb":[[700,0.19],[400,0.67],[500,0.53]],"id":41419640},{"atb":[[4.5,76.23],[7,22.23],[3.75,97.02]],"id":41419607},{"atb":[[19.5,14.42],[95,1.41],[29,9.53]],"id":41419636},{"atb":[[17.5,14.14],[9,33.35],[7,44.47]],"id":41419603},{"atb":[[6.4,49.41],[11,13.34],[5.2,63.52]],"id":41419615},{"atb":[[8,38.11],[20,7.01],[10,29.64]],"id":41419611},{"atb":[[8.6,35.1],[23,6.06],[11.5,25.4]],"id":41419624},{"atb":[[700,0.19],[400,0.67],[500,0.53]],"id":41419591},{"atb":[[34,8.08],[220,0.61],[60,4.51]],"id":41419620},{"atb":[[16.5,17.21],[36,3.81],[11.5,25.4]],"id":41419587},{"atb":[[17.5,16.16],[40,3.42],[12.5,23.19]],"id":41419632},{"atb":[[24,5.8],[12,24.25],[8.8,34.2]],"id":41419599},{"atb":[[12,12.12],[6.8,46],[5.4,60.63]],"id":41419628},{"atb":[[5.6,29],[3.8,95.28],[3.3,116]],"id":41419595},{"atb":[[6.4,49.41],[11,13.34],[5.2,63.52]],"id":41419608},{"atb":[[75,3.6],[40,6.83],[250,0.53]],"id":41419637},{"atb":[[16.5,8.6],[8.6,35.1],[6.6,47.64]],"id":41419604},{"atb":[[7.8,39.23],[14.5,9.87],[5.9,54.45]],"id":41419616},{"atb":[[180,0.74],[46,5.92],[28,9.87]],"id":41419612},{"atb":[[17.5,16.16],[40,3.42],[12.5,23.19]],"id":41419625},{"atb":[[6.2,51.31],[8.2,37.05],[15.5,9.2]],"id":41419592},{"atb":[[5.8,55.58],[7.6,40.42],[14,10.26]],"id":41419621},{"atb":[[16.5,17.21],[36,3.81],[11.5,25.4]],"id":41419588},{"atb":[[700,0.19],[400,0.67],[500,0.53]],"id":41419633},{"atb":[[3.2,121.27],[3.7,98.82],[5.4,30.32]],"id":41419600},{"atb":[[17.5,8.08],[9,33.35],[7,44.47]],"id":41419629},{"atb":[[10,14.82],[5,66.7],[6,53.36]],"id":41419596}],"con":true,"img":false}]}
{"op":"mcm","clk":"5353105375","pt":1646208941513,"mc":[{"id":"1.195503860","rc":[{"atl":[[420,2]],"id":41419614}],"con":true,"img":false}]}
{"op":"mcm","clk":"5353105382","pt":1646208941619,"mc":[{"id":"1.195503860","rc":[{"atl":[[430,0]],"id":41419614}],"con":true,"img":false}]}
{"op":"mcm","clk":"5353105405","pt":1646208942228,"mc":[{"id":"1.195503860","rc":[{"atb":[[9.6,0],[8.6,0]],"id":41419595}],"con":true,"img":false}]}
{"op":"mcm","clk":"5353105439","pt":1646208942906,"mc":[{"id":"1.195503860","rc":[{"atb":[[8.4,3.27],[9.4,2.72]],"id":41419595}],"con":true,"img":false}]}
{"op":"mcm","clk":"5353105584","pt":1646208945896,"mc":[{"id":"1.195503860","rc":[{"atb":[[16,6.67],[22,0]],"id":41419613},{"atb":[[20,7.01],[13.5,8]],"id":41419618},{"atl":[[920,0],[910,2]],"id":41419631},{"atl":[[240,2],[250,0]],"id":41419595},{"atl":[[1000,2]],"id":41419588}],"con":true,"img":false}]}
{"op":"mcm","clk":"5353105598","pt":1646208946205,"mc":[{"id":"1.195503860","rc":[{"atb":[[8,0],[9,0]],"id":41419594}],"con":true,"img":false}]}
{"op":"mcm","clk":"5353105613","pt":1646208946510,"mc":[{"id":"1.195503860","rc":[{"atl":[[910,0],[900,2]],"id":41419631}],"con":true,"img":false}]}
{"op":"mcm","clk":"5353105649","pt":1646208947231,"mc":[{"id":"1.195503860","rc":[{"atb":[[8.4,3.27],[9.4,2.72]],"id":41419594}],"con":true,"img":false}]}
{"op":"mcm","clk":"5353105719","pt":1646208948833,"mc":[{"id":"1.195503860","rc":[{"atb":[[8.4,0],[9.4,0]],"id":41419595}],"con":true,"img":false}]}
{"op":"mcm","clk":"5353105765","pt":1646208949714,"mc":[{"id":"1.195503860","rc":[{"atb":[[9.2,2.72],[8.2,3.27]],"id":41419595}],"con":true,"img":false}]}
{"op":"mcm","clk":"5353106623","pt":1646208968727,"mc":[{"id":"1.195503860","rc":[{"atl":[[830,0],[820,2]],"id":41419613},{"atl":[[770,2],[800,0]],"id":41419618},{"atl":[[410,2],[420,0]],"id":41419614},{"atl":[[880,2],[900,0]],"id":41419631},{"atl":[[620,0],[610,2]],"id":41419615},{"atl":[[1000,0]],"id":41419587},{"atl":[[230,2],[240,0]],"id":41419595}],"con":true,"img":false}]}
{"op":"mcm","clk":"5353106648","pt":1646208969239,"mc":[{"id":"1.195503860","rc":[{"atb":[[9.2,0],[8.2,0]],"id":41419595}],"con":true,"img":false}]}
{"op":"mcm","clk":"5353106668","pt":1646208969756,"mc":[{"id":"1.195503860","rc":[{"atb":[[38,0],[48,0]],"id":41419617},{"atb":[[8,0],[7,0]],"id":41419593},{"atb":[[42,0],[55,0]],"id":41419622},{"atb":[[160,0],[110,0]],"id":41419626},{"atb":[[170,0],[220,0]],"id":41419639},{"atb":[[38,0],[48,0]],"id":41419610},{"atb":[[65,0],[46,0]],"id":41419623},{"atb":[[170,0],[220,0]],"id":41419640},{"atb":[[36,0],[28,0]],"id":41419603},{"atb":[[65,0],[46,0]],"id":41419624},{"atb":[[85,0],[120,0]],"id":41419620},{"atb":[[70,0],[95,0]],"id":41419632},{"atb":[[70,0],[95,0]],"id":41419625},{"atb":[[40,0],[30,0]],"id":41419621},{"atb":[[17,0],[14.5,0]],"id":41419596}],"con":true,"img":false}]}
{"op":"mcm","clk":"5353106678","pt":1646208969963,"mc":[{"id":"1.195503860","rc":[{"atb":[[17,0],[14.5,0]],"id":41419597},{"atb":[[21,0],[22,11.11]],"id":41419610},{"atb":[[8,3.27],[9,2.72]],"id":41419595},{"atb":[[11,10],[9.8,0]],"id":41419621}],"con":true,"img":false}]}
{"op":"mcm","clk":"5353106700","pt":1646208970425,"mc":[{"id":"1.195503860","rc":[{"atb":[[42,3.27],[55,2.72]],"id":41419617},{"atb":[[8,2.72],[7,3.27]],"id":41419593},{"atb":[[44,3.27],[60,2.72]],"id":41419622},{"atb":[[130,3.27],[180,2.72]],"id":41419626},{"atb":[[190,3.27],[240,2.72]],"id":41419639},{"atb":[[40,3.27],[50,2.72]],"id":41419610},{"atb":[[70,2.72],[48,3.27]],"id":41419623},{"atb":[[170,3.27],[220,2.72]],"id":41419640},{"atb":[[70,2.72],[48,3.27]],"id":41419624},{"atb":[[130,2.72],[90,3.27]],"id":41419620},{"atb":[[75,3.27],[100,2.72]],"id":41419625},{"atb":[[34,3.27],[44,2.72]],"id":41419621}],"con":true,"img":false}]}
{"op":"mcm","clk":"5353106705","pt":1646208970528,"mc":[{"id":"1.195503860","rc":[{"atb":[[38,2.72],[29,3.27]],"id":41419603},{"atb":[[70,3.27],[95,2.72]],"id":41419632},{"atb":[[16,3.27],[18.5,2.72]],"id":41419596}],"con":true,"img":false}]}
{"op":"mcm","clk":"5353106710","pt":1646208970732,"mc":[{"id":"1.195503860","rc":[{"atb":[[16.5,2.72],[14,3.27]],"id":41419597}],"con":true,"img":false}]}
{"op":"mcm","clk":"5353106715","pt":1646208970836,"mc":[{"id":"1.195503860","rc":[{"atb":[[17.5,8.08],[20,5.26]],"id":41419603}],"con":true,"img":false}]}
{"op":"mcm","clk":"5353107308","pt":1646208986470,"mc":[{"id":"1.195503860","rc":[{"atb":[[8,0],[7,0]],"id":41419593},{"atb":[[16.5,0],[14,0]],"id":41419597}],"con":true,"img":false}]}
{"op":"mcm","clk":"5353107327","pt":1646208986985,"mc":[{"id":"1.195503860","rc":[{"atb":[[32,0],[26,0]],"id":41419616}],"con":true,"img":false}]}
{"op":"mcm","clk":"5353107332","pt":1646208987086,"mc":[{"id":"1.195503860","rc":[{"atb":[[18.5,0],[22,0]],"id":41419601},{"atb":[[80,0],[55,0]],"id":41419612}],"con":true,"img":false}]}
{"op":"mcm","clk":"5353107336","pt":1646208987190,"mc":[{"id":"1.195503860","rc":[{"atb":[[32,0],[26,0]],"id":41419609},{"atb":[[17,0],[14.5,0]],"id":41419607},{"atb":[[22,0],[27,0]],"id":41419608}],"con":true,"img":false}]}
{"op":"mcm","clk":"5353107341","pt":1646208987243,"mc":[{"id":"1.195503860","rc":[{"atb":[[6.8,3.27],[7.8,2.72]],"id":41419593},{"atb":[[16,2.72],[13.5,3.27]],"id":41419597}],"con":true,"img":false}]}
{"op":"mcm","clk":"5353107345","pt":1646208987346,"mc":[{"id":"1.195503860","rc":[{"atb":[[5.7,21.28],[5.4,0]],"id":41419607},{"atb":[[9.2,12.2],[8.8,0]],"id":41419608}],"con":true,"img":false}]}
{"op":"mcm","clk":"5353107368","pt":1646208987868,"mc":[{"id":"1.195503860","rc":[{"atb":[[19,3.27],[23,2.72]],"id":41419601},{"atb":[[34,2.72],[27,3.27]],"id":41419616},{"atb":[[85,2.72],[60,3.27]],"id":41419612}],"con":true,"img":false}]}
{"op":"mcm","clk":"5353107372","pt":1646208987971,"mc":[{"id":"1.195503860","rc":[{"atb":[[34,2.72],[27,3.27]],"id":41419609},{"atb":[[18,2.72],[15.5,3.27]],"id":41419607},{"atb":[[23,3.27],[28,2.72]],"id":41419608}],"con":true,"img":false}]}
{"op":"mcm","clk":"5353107467","pt":1646208990651,"mc":[{"id":"1.195503860","rc":[{"atl":[[820,0],[830,2]],"id":41419613},{"atl":[[770,0],[800,2]],"id":41419618},{"atl":[[410,0],[420,2]],"id":41419614},{"atl":[[880,0],[890,2]],"id":41419631},{"atl":[[610,0],[620,2]],"id":41419615},{"atl":[[1000,2]],"id":41419587}],"con":true,"img":false}]}
{"op":"mcm","clk":"5353107481","pt":1646208990962,"mc":[{"id":"1.195503860","rc":[{"atb":[[18,0],[21,0]],"id":41419592}],"con":true,"img":false}]}
{"op":"mcm","clk":"5353107514","pt":1646208991803,"mc":[{"id":"1.195503860","rc":[{"atb":[[17,3.27],[19.5,2.72]],"id":41419592}],"con":true,"img":false}]}
{"op":"mcm","clk":"5353108166","pt":1646209005674,"mc":[{"id":"1.195503860","rc":[{"atb":[[150,0],[100,0]],"id":41419638},{"atb":[[38,0],[48,0]],"id":41419618},{"atb":[[22,0],[27,0]],"id":41419615}],"con":true,"img":false}]}
{"op":"mcm","clk":"5353108170","pt":1646209005778,"mc":[{"id":"1.195503860","rc":[{"atb":[[44,0],[60,0]],"id":41419613},{"atb":[[85,0],[60,0]],"id":41419619}],"con":true,"img":false}]}
{"op":"mcm","clk":"5353108180","pt":1646209006084,"mc":[{"id":"1.195503860","rc":[{"atb":[[19,0],[23,0]],"id":41419602},{"atb":[[18,0],[15.5,0]],"id":41419607},{"atb":[[150,0],[100,0]],"id":41419637}],"con":true,"img":false}]}
{"op":"mcm","clk":"5353108192","pt":1646209006396,"mc":[{"id":"1.195503860","rc":[{"atb":[[40,3.27],[50,2.72]],"id":41419618}],"con":true,"img":false}]}
{"op":"mcm","clk":"5353108205","pt":1646209006703,"mc":[{"id":"1.195503860","rc":[{"atb":[[160,2.72],[110,3.27]],"id":41419638},{"atb":[[65,2.72],[46,3.27]],"id":41419613},{"atb":[[65,3.27],[90,2.72]],"id":41419619},{"atb":[[24,3.27],[29,2.72]],"id":41419615}],"con":true,"img":false}]}
{"op":"mcm","clk":"5353108220","pt":1646209007114,"mc":[{"id":"1.195503860","rc":[{"atb":[[19.5,3.27],[24,2.72]],"id":41419602},{"atb":[[17.5,2.72],[15,3.27]],"id":41419607},{"atb":[[160,2.72],[110,3.27]],"id":41419637}],"con":true,"img":false}]}
{"op":"mcm","clk":"5353109068","pt":1646209026498,"mc":[{"id":"1.195503860","rc":[{"atb":[[8.4,0],[9.4,0]],"id":41419594}],"con":true,"img":false}]}
{"op":"mcm","clk":"5353109130","pt":1646209027536,"mc":[{"id":"1.195503860","rc":[{"atb":[[9.6,2.72],[8.6,3.27]],"id":41419594}],"con":true,"img":false}]}
{"op":"mcm","clk":"5353109666","pt":1646209041029,"mc":[{"id":"1.195503860","rc":[{"atb":[[6.8,0],[7.8,0]],"id":41419593}],"con":true,"img":false}]}
{"op":"mcm","clk":"5353109695","pt":1646209041955,"mc":[{"id":"1.195503860","rc":[{"atb":[[7.6,2.72],[6.6,3.27]],"id":41419593}],"con":true,"img":false}]}
{"op":"mcm","clk":"5353109864","pt":1646209046853,"mc":[{"id":"1.195503860","rc":[{"atb":[[8,0],[9,0]],"id":41419595}],"con":true,"img":false}]}
{"op":"mcm","clk":"5353109871","pt":1646209047161,"mc":[{"id":"1.195503860","rc":[{"atb":[[40,0],[50,0]],"id":41419610},{"atb":[[70,0],[48,0]],"id":41419623},{"atb":[[70,0],[48,0]],"id":41419624}],"con":true,"img":false}]}
{"op":"mcm","clk":"5353109898","pt":1646209047738,"mc":[{"id":"1.195503860","rc":[{"atb":[[9.6,2.72],[8.6,3.27]],"id":41419595}],"con":true,"img":false}]}
{"op":"mcm","clk":"5353109908","pt":1646209047939,"mc":[{"id":"1.195503860","rc":[{"atb":[[42,3.27]],"id":41419610},{"atb":[[75,2.72],[50,3.27]],"id":41419623},{"atb":[[75,2.72],[50,3.27]],"id":41419624}],"con":true,"img":false}]}
{"op":"mcm","clk":"5353109914","pt":1646209048042,"mc":[{"id":"1.195503860","rc":[{"atb":[[55,2.72]],"id":41419610}],"con":true,"img":false}]}
{"op":"mcm","clk":"5353111267","pt":1646209081258,"mc":[{"id":"1.195503860","rc":[{"atb":[[30,13.54]],"id":41419606},{"atl":[[780,1.57]],"id":41419606}],"con":true,"img":false}]}
{"op":"mcm","clk":"5353111273","pt":1646209081417,"mc":[{"id":"1.195503860","rc":[{"atb":[[25,9.92],[14.5,18.82],[29,4.96]],"id":41419609},{"atl":[[570,0.27],[75,9.92],[600,2.05],[55,4.96]],"id":41419609},{"atb":[[160,7.69],[110,11.4],[120,9.92]],"id":41419638},{"atl":[[1000,0.15]],"id":41419638},{"atb":[[65,2.48],[22,25.01],[90,9.92],[120,4.96]],"id":41419605},{"atl":[[870,0.18],[230,4.96],[900,1.36]],"id":41419605},{"atb":[[75,4.96],[22,20.06],[55,12.65],[60,2.69]],"id":41419617},{"atl":[[170,4.96],[870,0.18],[900,1.36]],"id":41419617},{"atb":[[44,9.92],[55,4.96],[30,13.54]],"id":41419613},{"atl":[[130,4.96],[820,0.19],[850,1.44]],"id":41419613},{"atb":[[7.2,4.96],[4.5,47.06],[6.4,9.92],[7.6,11.67]],"id":41419593},{"atl":[[11.5,4.96],[13.5,9.92],[220,0.72],[250,4.93]],"id":41419593},{"atb":[[65,2.48],[80,9.92],[22,13.7],[100,4.96]],"id":41419622},{"atl":[[230,4.96],[930,0.16],[960,1.27]],"id":41419622},{"atb":[[160,4.96],[95,11.4],[120,9.92]],"id":41419589},{"atl":[[1000,0.15]],"id":41419589},{"atb":[[20,15.96],[42,9.92],[50,10.93]],"id":41419618},{"atl":[[790,0.2],[820,1.49],[110,4.96]],"id":41419618},{"atb":[[10.5,22.99],[22,9.92],[23,9.94],[26,4.96]],"id":41419601},{"atl":[[560,0.28],[75,9.92],[590,2.08],[55,4.96]],"id":41419601},{"atb":[[70,12.22],[22,13.7],[90,4.96]],"id":41419630},{"atl":[[170,4.96],[890,0.18],[920,1.33]],"id":41419630},{"atb":[[9.2,25.21],[11.5,9.92],[13.5,8.23]],"id":41419597},{"atl":[[360,0.44],[390,3.16],[25,4.96],[29,9.92]],"id":41419597},{"atb":[[46,9.92],[60,10.38]],"id":41419606},{"atl":[[760,0],[750,0.21],[780,3.57],[120,4.96]],"id":41419606},{"atb":[[80,9.92],[95,4.41],[100,4.96],[30,13.54]],"id":41419635},{"atl":[[920,0.17],[950,1.29]],"id":41419635},{"atb":[[10.5,22.99],[21,9.92],[24,9.63],[25,4.96]],"id":41419602},{"atl":[[75,9.92],[580,0.27],[610,2.01],[55,4.96]],"id":41419602},{"atb":[[18.5,16.57],[38,9.92],[46,4.96]],"id":41419585},{"atl":[[140,4.96],[720,0.21],[750,1.63]],"id":41419585},{"atb":[[12.5,9.92],[7,31.17],[14.5,4.96]],"id":41419614},{"atl":[[24,4.96],[440,2.8],[28,9.92],[1000,0.15]],"id":41419614},{"atb":[[22,20.06],[46,9.92],[60,7.65]],"id":41419610},{"atl":[[170,4.96],[850,0.18],[880,1.39]],"id":41419610},{"atb":[[80,2],[85,9.92],[23,15.01],[110,4.96]],"id":41419623},{"atl":[[990,0.15]],"id":41419623},{"atb":[[150,5.85],[160,0.99],[95,11.4],[110,9.92]],"id":41419590},{"atl":[[1000,0.15]],"id":41419590},{"atb":[[65,11.4],[140,4.96],[100,9.92]],"id":41419619},{"atl":[[1000,0.15]],"id":41419619},{"atb":[[85,11.81],[26,15.1],[110,4.96]],"id":41419586},{"atl":[[1000,0.15]],"id":41419586},{"atb":[[65,5.21],[70,4.96],[22,13.7],[50,9.92]],"id":41419631},{"atl":[[150,4.96],[910,1.34],[1000,0.15]],"id":41419631},{"atb":[[23,24.93],[27,8.23]],"id":41419598},{"atl":[[520,0.3],[70,4.96],[550,2.23],[90,9.92]],"id":41419598},{"atb":[[130,5.99],[140,1.14],[85,11.4],[95,9.92]],"id":41419627},{"atl":[[1000,0.15]],"id":41419627},{"atb":[[5.6,37.94],[7.6,4.96],[6.8,9.92]],"id":41419594},{"atl":[[11.5,4.96],[13.5,9.92],[220,0.72],[250,4.93]],"id":41419594},{"atb":[[12.5,9.92],[7,31.17],[14.5,4.96]],"id":41419607},{"atl":[[24,4.96],[410,0.38],[440,2.8],[28,9.92]],"id":41419607},{"atb":[[140,1.14],[160,4.96],[90,11.4],[120,9.92]],"id":41419636},{"atl":[[1000,0.15]],"id":41419636},{"atb":[[20,14.2],[40,4.07],[46,9.92],[60,4.96]],"id":41419603},{"atl":[[140,4.96],[760,0.2],[790,1.55]],"id":41419603},{"atb":[[32,4.96],[11,22.28],[27,9.92],[29,8.4]],"id":41419615},{"atl":[[70,4.96],[610,0.26],[640,1.92],[90,9.92]],"id":41419615},{"atb":[[20,15.96],[44,9.92],[50,3.24],[55,4.96]],"id":41419611},{"atl":[[130,4.96],[770,0.2],[800,1.53]],"id":41419611},{"atb":[[80,2],[90,9.92],[23,15.01],[120,4.96]],"id":41419624},{"atl":[[240,4.96],[990,0.15]],"id":41419624},{"atb":[[150,4.96],[90,11.4],[110,9.92]],"id":41419620},{"atl":[[1000,0.15]],"id":41419620},{"atb":[[36,12.75],[85,9.92],[100,1.6],[110,4.96]],"id":41419587},{"atl":[[990,0.15]],"id":41419587},{"atb":[[130,4.96],[40,13.18],[95,12.65],[100,1.6]],"id":41419632},{"atl":[[1000,0.15]],"id":41419632},{"atb":[[40,9.92],[46,3.52],[24,14.74],[48,4.96]],"id":41419599},{"atl":[[710,0.22],[740,1.65],[110,4.96]],"id":41419599},{"atb":[[12,21.07],[24,9.92],[28,4.96]],"id":41419628},{"atl":[[540,0.29],[70,4.96],[570,2.15],[90,9.92]],"id":41419628},{"atb":[[5.6,37.94],[7.2,4.96],[6.4,9.92]],"id":41419595},{"atl":[[13,4.96],[220,0.72],[15,9.92],[250,4.93]],"id":41419595},{"atb":[[11,22.28],[24,9.92],[28,13.56]],"id":41419608},{"atl":[[65,4.96],[600,0.26],[630,1.95],[85,9.92]],"id":41419608},{"atb":[[160,7.69],[110,11.4],[120,9.92]],"id":41419637},{"atl":[[1000,0.15]],"id":41419637},{"atb":[[16.5,17.55],[34,4.96],[36,7.26],[28,13.19]],"id":41419604},{"atl":[[610,0.26],[640,1.92],[90,4.96],[120,9.92]],"id":41419604},{"atb":[[21,9.92],[25,4.96],[14.5,18.82]],"id":41419616},{"atl":[[540,0.29],[570,2.15],[75,9.92],[55,4.96]],"id":41419616},{"atb":[[140,4.96],[100,9.92],[60,11.4]],"id":41419612},{"atl":[[1000,0.15]],"id":41419612},{"atb":[[140,4.96],[40,13.18],[100,12.65],[110,1.45]],"id":41419625},{"atl":[[1000,0.15]],"id":41419625},{"atb":[[11.5,9.92],[13.5,4.96]],"id":41419592},{"atl":[[40,4.96],[48,9.92],[390,0.4],[420,2.93]],"id":41419592},{"atb":[[32,9.92],[40,4.96],[44,6.42],[14,19.2]],"id":41419621},{"atl":[[630,0.25],[660,1.86],[95,4.96]],"id":41419621},{"atb":[[130,4.96],[36,12.75],[95,12.65],[100,1.6]],"id":41419588},{"atl":[[990,0.15]],"id":41419588},{"atb":[[160,7.69]],"id":41419633},{"atl":[[1000,0.15]],"id":41419633},{"atb":[[9.6,13.19],[11,4.96],[11.5,11.67],[5.4,39.26]],"id":41419600},{"atl":[[20,4.96],[350,0.45],[380,3.24],[24,9.92]],"id":41419600},{"atb":[[20,14.2],[46,9.92],[55,5.67],[60,4.96]],"id":41419629},{"atl":[[130,4.96],[780,0.2],[810,1.51]],"id":41419629},{"atb":[[16,8.23],[10,23.77],[14,9.92]],"id":41419596},{"atl":[[32,4.96],[40,9.92],[420,0.37],[450,2.73]],"id":41419596}],"con":true,"img":false}]}
{"op":"mcm","clk":"5353111281","pt":1646209081583,"mc":[{"id":"1.195503860","rc":[{"atl":[[580,0],[200,2]],"id":41419609},{"atl":[[750,2],[880,0]],"id":41419605},{"atl":[[540,2],[880,0]],"id":41419617},{"atl":[[830,0],[440,2]],"id":41419613},{"atl":[[25,4.17],[230,0]],"id":41419593},{"atl":[[750,2],[940,0]],"id":41419622},{"atl":[[800,0],[410,2]],"id":41419618},{"atl":[[570,0],[190,2]],"id":41419601},{"atl":[[530,2]],"id":41419630},{"atl":[[65,2],[370,0]],"id":41419597},{"atl":[[930,0],[940,2]],"id":41419635},{"atl":[[590,0],[200,2]],"id":41419602},{"atl":[[730,0],[390,2]],"id":41419585},{"atl":[[70,2],[420,0]],"id":41419614},{"atl":[[530,2],[860,0]],"id":41419610},{"atl":[[890,0],[500,2]],"id":41419631},{"atl":[[530,0],[230,2]],"id":41419598},{"atl":[[26,4],[230,0]],"id":41419594},{"atl":[[70,2],[420,0]],"id":41419607},{"atl":[[770,0],[470,2]],"id":41419603},{"atl":[[620,0],[240,2]],"id":41419615},{"atl":[[780,0],[460,2]],"id":41419611},{"atl":[[860,2],[1000,0]],"id":41419624},{"atl":[[720,0],[410,2]],"id":41419599},{"atl":[[550,0],[240,2]],"id":41419628},{"atl":[[26,4],[230,0]],"id":41419595},{"atl":[[610,0],[230,2]],"id":41419608},{"atl":[[620,0],[330,2]],"id":41419604},{"atl":[[190,2]],"id":41419616},{"atl":[[70,2],[400,0]],"id":41419592},{"atl":[[640,0],[350,2]],"id":41419621},{"atl":[[360,0],[48,2.13]],"id":41419600},{"atl":[[790,0],[460,2]],"id":41419629},{"atl":[[90,2],[430,0]],"id":41419596}],"con":true,"img":false}]}
{"op":"mcm","clk":"5353111289","pt":1646209081688,"mc":[{"id":"1.195503860","rc":[{"atl":[[900,0]],"id":41419630},{"atl":[[550,0]],"id":41419616}],"con":true,"img":false}]}
{"op":"mcm","clk":"5353111302","pt":1646209082002,"mc":[{"id":"1.195503860","rc":[{"atl":[[1000,1.22]],"id":41419624}],"con":true,"img":false}]}
{"op":"mcm","clk":"5353111325","pt":1646209082575,"mc":[{"id":"1.195503860","rc":[{"atl":[[13,0],[13.5,4.96],[15,0],[15.5,9.92]],"id":41419595}],"con":true,"img":false}]}
{"op":"mcm","clk":"5353111357","pt":1646209083310,"mc":[{"id":"1.195503860","rc":[{"atl":[[250,4.96]],"id":41419623},{"atl":[[250,4.96]],"id":41419587}],"con":true,"img":false}]}
{"op":"mcm","clk":"5353111369","pt":1646209083466,"mc":[{"id":"1.195503860","rc":[{"atl":[[830,2],[1000,0]],"id":41419623},{"atl":[[860,2],[1000,0]],"id":41419587}],"con":true,"img":false}]}
{"op":"mcm","clk":"5353111386","pt":1646209083780,"mc":[{"id":"1.195503860","rc":[{"atl":[[1000,1.23]],"id":41419623},{"atl":[[1000,1.23]],"id":41419587}],"con":true,"img":false}]}
{"op":"mcm","clk":"5353111467","pt":1646209085545,"mc":[{"id":"1.195503860","rc":[{"atb":[[8.6,0],[11.5,9.52],[7.8,0],[14.5,8.94],[5.9,0]],"id":41419609},{"atb":[[75,0],[40,0],[250,0]],"id":41419638},{"atb":[[16,0],[22,12.3],[60,2.72]],"id":41419605},{"atb":[[700,0],[400,0],[500,0]],"id":41419634},{"atb":[[22,13.7],[11,0],[8.4,0]],"id":41419617},{"atb":[[16,0],[10,0],[22,4.76],[30,8.94],[15,0]],"id":41419613},{"atb":[[4.5,37.51],[2.9,0],[3.8,0],[3.25,0]],"id":41419593},{"atb":[[9.6,0],[19,0],[7.6,0]],"id":41419622},{"atb":[[65,0],[36,0],[230,0]],"id":41419589},{"atb":[[8,0],[20,14.2],[10,0],[13.5,0]],"id":41419618},{"atb":[[5.1,0],[10.5,8.94],[6.2,0],[8.2,0],[11,10]],"id":41419601},{"atb":[[21,0],[10.5,0],[8.2,0]],"id":41419630},{"atb":[[5.6,0],[7.2,16.13],[9.2,8.94],[4.6,0],[5.5,0]],"id":41419597},{"atb":[[700,0],[400,0],[500,0]],"id":41419626},{"atb":[[700,0],[400,0],[500,0]],"id":41419639},{"atb":[[18.5,0],[10,0],[22,4.76],[30,8.94],[15,0]],"id":41419606},{"atb":[[10,0],[30,8.94],[15,0]],"id":41419635},{"atb":[[5.1,0],[10.5,8.94],[6.2,0],[11.5,9.52],[8.4,0]],"id":41419602},{"atb":[[18.5,8.94],[7.4,0],[9.4,11.9]],"id":41419585},{"atb":[[5.6,0],[7.2,16.13],[4.5,0],[7,8.94],[3.75,0]],"id":41419614},{"atb":[[22,13.7],[11,0],[8.4,0]],"id":41419610},{"atb":[[8.6,0],[23,8.94],[11.5,0]],"id":41419623},{"atb":[[150,4.96],[40,0],[25,0]],"id":41419590},{"atb":[[180,0],[46,0],[28,0]],"id":41419619},{"atb":[[9.2,0],[26,9.76],[13,0]],"id":41419586},{"atb":[[21,0],[10.5,0],[8.2,0]],"id":41419631},{"atb":[[8.6,0],[23,18.87],[11.5,0],[12,9.09],[8.4,0]],"id":41419598},{"atb":[[130,4.96],[36,0],[23,0]],"id":41419627},{"atb":[[5.6,8.94],[4.6,27.78],[3.7,0],[3.8,0],[3.3,0]],"id":41419594},{"atb":[[700,0],[400,0],[500,0]],"id":41419640},{"atb":[[4.5,0],[7.4,15.62],[5.7,0],[7,8.94],[3.75,0]],"id":41419607},{"atb":[[19.5,0],[95,0],[29,0]],"id":41419636},{"atb":[[17.5,0],[9,0],[7,0]],"id":41419603},{"atb":[[6.4,0],[9.2,0],[11,8.94],[12,9.09],[5.2,0]],"id":41419615},{"atb":[[8,0],[18.5,0],[20,8.94],[10,0],[22,4.76]],"id":41419611},{"atb":[[8.6,0],[23,8.94],[11.5,0]],"id":41419624},{"atb":[[700,0],[400,0],[500,0]],"id":41419591},{"atb":[[34,0],[220,0],[60,0]],"id":41419620},{"atb":[[16.5,0],[36,8.94],[11.5,0]],"id":41419587},{"atb":[[17.5,0],[40,9.76],[12.5,0]],"id":41419632},{"atb":[[16.5,0],[20,5.26],[24,8.94],[12,0],[8.8,0]],"id":41419599},{"atb":[[9.2,0],[12,18.03],[6.8,0],[5.4,0]],"id":41419628},{"atb":[[5.6,8.94],[4.6,27.78],[3.8,0],[3.3,0],[3.75,0]],"id":41419595},{"atb":[[6.4,0],[9.2,0],[11,8.94],[12,9.09],[5.2,0]],"id":41419608},{"atb":[[75,0],[40,0],[250,0]],"id":41419637},{"atb":[[16.5,8.94],[8.6,0],[10.5,0],[6.6,0],[14.5,7.41]],"id":41419604},{"atb":[[11,10],[8.8,0],[7.8,0],[14.5,8.94],[5.9,0]],"id":41419616},{"atb":[[180,0],[46,0],[28,0]],"id":41419612},{"atb":[[17.5,0],[40,9.76],[12.5,0]],"id":41419625},{"atb":[[7.2,16.13],[6.2,0],[8.2,0],[5.7,0],[15.5,0]],"id":41419592},{"atb":[[5.8,0],[11,0],[7.6,0],[14,8.94],[15.5,6.9]],"id":41419621},{"atb":[[16.5,0],[36,8.94],[11.5,0]],"id":41419588},{"atb":[[700,0],[400,0],[500,0]],"id":41419633},{"atb":[[4.8,0],[3.2,0],[3.7,0],[6.6,17.86],[5.4,8.94]],"id":41419600},{"atb":[[17.5,0],[9,0],[7,0]],"id":41419629},{"atb":[[9,12.5],[10,8.94],[5,0],[6.2,0],[6,0]],"id":41419596}],"con":true,"img":false}]}
{"op":"mcm","clk":"5353111487","pt":1646209086019,"mc":[{"id":"1.195503860","rc":[{"atb":[[170,0.93]],"id":41419638},{"atb":[[160,4.96],[22,10.12],[120,9.92]],"id":41419634},{"atb":[[170,0.93]],"id":41419589},{"atb":[[160,4.96],[22,10.12],[190,0.84],[120,9.92]],"id":41419626},{"atl":[[1000,0.15]],"id":41419626},{"atb":[[160,4.96],[22,10.12],[120,9.92],[250,0.63]],"id":41419639},{"atl":[[1000,0.44]],"id":41419639},{"atb":[[150,1.06]],"id":41419619},{"atb":[[160,4.96],[22,10.12],[230,0.69],[120,9.92]],"id":41419640},{"atl":[[1000,0.15]],"id":41419640},{"atb":[[160,4.96],[22,10.12],[240,0.66],[120,9.92]],"id":41419591},{"atb":[[160,0.99]],"id":41419620},{"atb":[[170,0.93]],"id":41419637},{"atb":[[140,1.14],[100,0]],"id":41419612},{"atb":[[13.5,17.22]],"id":41419592},{"atb":[[170,0.93],[22,9.86]],"id":41419633}],"con":true,"img":false}]}
{"op":"mcm","clk":"5353111494","pt":1646209086114,"mc":[{"id":"1.195503860","rc":[{"atl":[[11.5,0],[12,4.96],[13.5,0],[14,9.92]],"id":41419594},{"atb":[[130,4.96],[95,9.92]],"id":41419612}],"con":true,"img":false}]}
{"op":"mcm","clk":"5353111517","pt":1646209086587,"mc":[{"id":"1.195503860","rc":[{"atl":[[11.5,0],[12,4.96],[13.5,0],[14,9.92]],"id":41419593}],"con":true,"img":false}]}
{"op":"mcm","clk":"5353111523","pt":1646209086689,"mc":[{"id":"1.195503860","rc":[{"atl":[[820,2.19],[440,0]],"id":41419613},{"atl":[[530,0],[890,2.18]],"id":41419630},{"atl":[[940,0],[950,3.29]],"id":41419635},{"atl":[[470,0]],"id":41419603},{"atl":[[990,2.15]],"id":41419624}],"con":true,"img":false}]}
{"op":"mcm","clk":"5353111528","pt":1646209086792,"mc":[{"id":"1.195503860","rc":[{"atl":[[750,0],[870,2.18]],"id":41419605},{"atl":[[540,0],[870,2.18]],"id":41419617},{"atl":[[750,0],[930,2.16]],"id":41419622},{"atl":[[790,2.2]],"id":41419618},{"atl":[[720,2.21],[390,0]],"id":41419585},{"atl":[[530,0],[850,2.18]],"id":41419610},{"atl":[[900,2],[500,0]],"id":41419631},{"atl":[[760,2.2]],"id":41419603},{"atl":[[770,2.2],[460,0]],"id":41419611},{"atl":[[860,0]],"id":41419624},{"atl":[[710,2.22],[410,0]],"id":41419599},{"atl":[[630,2.25],[350,0]],"id":41419621},{"atl":[[780,2.2],[460,0]],"id":41419629}],"con":true,"img":false}]}
{"op":"mcm","clk":"5353111531","pt":1646209086895,"mc":[{"id":"1.195503860","rc":[{"atl":[[410,0]],"id":41419618}],"con":true,"img":false}]}
{"op":"mcm","clk":"5353111537","pt":1646209086998,"mc":[{"id":"1.195503860","rc":[{"atb":[[140,0]],"id":41419612}],"con":true,"img":false}]}
{"op":"mcm","clk":"5353111563","pt":1646209087672,"mc":[{"id":"1.195503860","rc":[{"atb":[[130,6.19]],"id":41419612}],"con":true,"img":false}]}
{"op":"mcm","clk":"5353111585","pt":1646209088607,"mc":[{"id":"1.195503860","rc":[{"atl":[[990,2.15]],"id":41419623},{"atl":[[860,0],[990,2.15]],"id":41419587}],"con":true,"img":false}]}
{"op":"mcm","clk":"5353111588","pt":1646209088711,"mc":[{"id":"1.195503860","rc":[{"atl":[[830,0]],"id":41419623}],"con":true,"img":false}]}
{"op":"mcm","clk":"5353111611","pt":1646209089487,"mc":[{"id":"1.195503860","rc":[{"atb":[[7.8,39.23],[14.5,18.82],[5.9,54.45]],"id":41419609},{"atb":[[75,3.6],[40,6.83],[250,0.53]],"id":41419638},{"atb":[[16,17.78],[22,25.01],[60,4.98]],"id":41419605},{"atb":[[700,0.19],[400,0.67],[500,0.53]],"id":41419634},{"atb":[[22,20.06],[11,26.68],[8.4,36.05]],"id":41419617},{"atb":[[10,29.64],[30,13.54],[15,19.05]],"id":41419613},{"atb":[[4.5,75.63],[2.9,140.42],[3.25,118.58]],"id":41419593},{"atb":[[9.6,31.02],[19,7.41],[7.6,40.42]],"id":41419622},{"atb":[[65,4.17],[36,7.62],[230,0.58]],"id":41419589},{"atb":[[8,38.11],[20,21.22],[10,29.64]],"id":41419618},{"atb":[[5.1,65.07],[10.5,22.99],[6.2,51.31]],"id":41419601},{"atb":[[21,6.67],[10.5,28.08],[8.2,37.05]],"id":41419630},{"atb":[[5.6,58],[9.2,25.21],[4.6,74.11]],"id":41419597},{"atb":[[700,0.19],[400,0.67],[500,0.53]],"id":41419626},{"atb":[[700,0.19],[400,0.67],[500,0.53]],"id":41419639},{"atb":[[10,29.64],[30,13.54],[15,19.05]],"id":41419606},{"atb":[[10,29.64],[30,13.54],[15,19.05]],"id":41419635},{"atb":[[5.1,65.07],[10.5,22.99],[6.2,51.31]],"id":41419602},{"atb":[[18.5,16.57],[7.4,41.69],[9.4,43.66]],"id":41419585},{"atb":[[4.5,76.23],[7,31.17],[3.75,97.02]],"id":41419614},{"atb":[[22,20.06],[11,26.68],[8.4,36.05]],"id":41419610},{"atb":[[8.6,35.1],[23,15.01],[11.5,25.4]],"id":41419623},{"atb":[[150,5.85],[40,6.83],[25,11.11]],"id":41419590},{"atb":[[180,0.74],[46,5.92],[28,9.87]],"id":41419619},{"atb":[[9.2,32.53],[26,15.1],[13,22.23]],"id":41419586},{"atb":[[21,6.67],[10.5,28.08],[8.2,37.05]],"id":41419631},{"atb":[[8.6,35.1],[23,24.93],[11.5,25.4]],"id":41419598},{"atb":[[130,5.99],[36,7.62],[23,12.12]],"id":41419627},{"atb":[[5.6,37.94],[3.8,95.28],[3.3,116]],"id":41419594},{"atb":[[700,0.19],[400,0.67],[500,0.53]],"id":41419640},{"atb":[[4.5,76.23],[7,31.17],[3.75,97.02]],"id":41419607},{"atb":[[19.5,14.42],[95,1.41],[29,9.53]],"id":41419636},{"atb":[[17.5,8.08],[9,33.35],[7,44.47]],"id":41419603},{"atb":[[6.4,49.41],[11,22.28],[5.2,63.52]],"id":41419615},{"atb":[[8,38.11],[20,15.96],[10,29.64]],"id":41419611},{"atb":[[8.6,35.1],[23,15.01],[11.5,25.4]],"id":41419624},{"atb":[[700,0.19],[400,0.67],[500,0.53]],"id":41419591},{"atb":[[34,8.08],[220,0.61],[60,4.51]],"id":41419620},{"atb":[[16.5,17.21],[36,12.75],[11.5,25.4]],"id":41419587},{"atb":[[17.5,16.16],[40,13.18],[12.5,23.19]],"id":41419632},{"atb":[[24,14.74],[12,24.25],[8.8,34.2]],"id":41419599},{"atb":[[12,30.16],[6.8,46],[5.4,60.63]],"id":41419628},{"atb":[[5.6,37.94],[3.8,95.28],[3.3,116]],"id":41419595},{"atb":[[6.4,49.41],[11,22.28],[5.2,63.52]],"id":41419608},{"atb":[[75,3.6],[40,6.83],[250,0.53]],"id":41419637},{"atb":[[16.5,17.55],[8.6,35.1],[6.6,47.64]],"id":41419604},{"atb":[[7.8,39.23],[14.5,18.82],[5.9,54.45]],"id":41419616},{"atb":[[180,0.74],[46,5.92],[28,9.87]],"id":41419612},{"atb":[[17.5,16.16],[40,13.18],[12.5,23.19]],"id":41419625},{"atb":[[6.2,51.31],[8.2,37.05],[15.5,9.2]],"id":41419592},{"atb":[[5.8,55.58],[7.6,40.42],[14,19.2]],"id":41419621},{"atb":[[16.5,17.21],[36,12.75],[11.5,25.4]],"id":41419588},{"atb":[[700,0.19],[400,0.67],[500,0.53]],"id":41419633},{"atb":[[3.2,121.27],[3.7,98.82],[5.4,39.26]],"id":41419600},{"atb":[[17.5,8.08],[9,33.35],[7,44.47]],"id":41419629},{"atb":[[10,23.77],[5,66.7],[6,53.36]],"id":41419596}],"con":true,"img":false}]}
{"op":"mcm","clk":"5353111630","pt":1646209089902,"mc":[{"id":"1.195503860","rc":[{"atb":[[22,2]],"id":41419626},{"atl":[[1000,0]],"id":41419626},{"atl":[[1000,0]],"id":41419640},{"atb":[[22,2]],"id":41419591},{"atb":[[22,2]],"id":41419633},{"atb":[[18.5,11.8]],"id":41419596}],"con":true,"img":false}]}
{"op":"mcm","clk":"5353111640","pt":1646209090015,"mc":[{"id":"1.195503860","rc":[{"atb":[[22,2]],"id":41419634},{"atl":[[1000,0]],"id":41419639},{"atb":[[13.5,4.96]],"id":41419592}],"con":true,"img":false}]}
{"op":"mcm","clk":"5353111655","pt":1646209090267,"mc":[{"id":"1.195503860","rc":[{"atb":[[22,2]],"id":41419639},{"atb":[[22,2]],"id":41419640}],"con":true,"img":false}]}
{"op":"mcm","clk":"5353111738","pt":1646209092616,"mc":[{"id":"1.195503860","rc":[{"atb":[[18.5,2.72]],"id":41419596}],"con":true,"img":false}]}
{"op":"mcm","clk":"5353111762","pt":1646209093121,"mc":[{"id":"1.195503860","rc":[{"atb":[[65,5.21]],"id":41419613}],"con":true,"img":false}]}
{"op":"mcm","clk":"5353111776","pt":1646209093482,"mc":[{"id":"1.195503860","rc":[{"atb":[[16,18.82]],"id":41419596}],"con":true,"img":false}]}
{"op":"mcm","clk":"5353111904","pt":1646209096995,"mc":[{"id":"1.195503860","rc":[{"atb":[[44,15.98],[30,4.6]],"id":41419606}],"con":true,"img":false}]}
{"op":"mcm","clk":"5353111911","pt":1646209097106,"mc":[{"id":"1.195503860","rc":[{"atb":[[160,9.87],[110,3.27]],"id":41419638},{"atb":[[120,6.29]],"id":41419605},{"atl":[[230,5.65]],"id":41419605},{"atb":[[75,7.1]],"id":41419617},{"atl":[[170,5.9]],"id":41419617},{"atb":[[46,15.54],[30,4.6]],"id":41419613},{"atb":[[4.5,66.68],[6.6,18.04]],"id":41419593},{"atl":[[25,18.93],[250,0]],"id":41419593},{"atb":[[65,13.55],[22,4.76],[100,6.56]],"id":41419622},{"atl":[[230,5.65]],"id":41419622},{"atb":[[160,7.22],[95,3.27]],"id":41419589},{"atb":[[40,15.54],[20,12.27]],"id":41419618},{"atl":[[110,6.41]],"id":41419618},{"atb":[[26,11.31]],"id":41419601},{"atl":[[590,0],[55,7.9]],"id":41419601},{"atb":[[65,14.17],[22,4.76]],"id":41419630},{"atl":[[170,5.9]],"id":41419630},{"atb":[[9.2,16.26],[11.5,29.57]],"id":41419597},{"atl":[[65,21.65],[25,11.57]],"id":41419597},{"atb":[[80,23.08]],"id":41419635},{"atl":[[950,2],[940,1.35]],"id":41419635},{"atb":[[21,31.64],[25,11.57]],"id":41419602},{"atl":[[610,0],[200,8.39],[55,7.9]],"id":41419602},{"atb":[[18.5,7.62],[44,12.22]],"id":41419585},{"atl":[[130,1.23]],"id":41419585},{"atb":[[7,22.23],[14.5,17.22]],"id":41419614},{"atb":[[22,11.11]],"id":41419610},{"atl":[[170,5.9]],"id":41419610},{"atb":[[80,12.6],[23,6.06],[110,6.41]],"id":41419623},{"atl":[[250,5.6]],"id":41419623},{"atb":[[65,3.27],[140,7.65]],"id":41419619},{"atb":[[80,14.17],[26,5.33],[120,1.33]],"id":41419586},{"atb":[[70,7.26],[50,24.68]],"id":41419631},{"atl":[[150,6.02]],"id":41419631},{"atl":[[70,7.26],[550,0],[230,7.55]],"id":41419598},{"atb":[[5.6,29],[7.6,18.3]],"id":41419594},{"atl":[[12,18.3],[26,17.34],[250,0]],"id":41419594},{"atb":[[130,8.48],[170,0.93],[90,3.27]],"id":41419636},{"atb":[[40,17.51],[20,5.26],[60,7.65]],"id":41419603},{"atl":[[140,6.1]],"id":41419603},{"atb":[[27,29.81]],"id":41419615},{"atl":[[640,0],[240,7.32]],"id":41419615},{"atb":[[20,7.01],[48,11.61]],"id":41419611},{"atl":[[130,6.19]],"id":41419611},{"atb":[[80,12.6],[23,6.06],[120,6.29]],"id":41419624},{"atl":[[240,5.62]],"id":41419624},{"atb":[[150,7.35],[90,3.27]],"id":41419620},{"atb":[[95,10.01]],"id":41419587},{"atb":[[140,1.14]],"id":41419632},{"atb":[[44,12.04],[48,8.34],[24,5.8]],"id":41419599},{"atl":[[110,6.41]],"id":41419599},{"atb":[[7.2,18.3]],"id":41419595},{"atl":[[26,17.34]],"id":41419595},{"atb":[[11,13.34],[23,25.42]],"id":41419608},{"atl":[[65,7.44],[630,0],[230,7.55]],"id":41419608},{"atb":[[160,9.87],[110,3.27]],"id":41419637},{"atb":[[16.5,8.6],[28,31.4]],"id":41419604},{"atl":[[330,5.87],[640,0],[90,6.74]],"id":41419604},{"atb":[[95,20.26],[60,3.27]],"id":41419612},{"atb":[[150,1.06]],"id":41419625},{"atl":[[70,14.26],[38,4.29]],"id":41419592},{"atb":[[34,15.54],[14,10.26]],"id":41419621},{"atl":[[95,6.64]],"id":41419621},{"atb":[[130,6.19],[36,3.81],[95,18.6]],"id":41419588},{"atb":[[9.6,35.34],[5.4,30.32]],"id":41419600},{"atl":[[380,0],[48,24.28]],"id":41419600},{"atb":[[20,5.26],[46,24.68]],"id":41419629},{"atl":[[32,10.08],[450,0]],"id":41419596}],"con":true,"img":false}]}
{"op":"mcm","clk":"5353111915","pt":1646209097212,"mc":[{"id":"1.195503860","rc":[{"atb":[[27,15.54]],"id":41419609},{"atl":[[600,0],[200,8.39]],"id":41419609},{"atb":[[65,13.55],[22,12.7]],"id":41419605},{"atb":[[22,11.11],[55,24.03]],"id":41419617},{"atl":[[130,6.19]],"id":41419613},{"atl":[[12,19.39]],"id":41419593},{"atb":[[10.5,14.04],[22,32.07]],"id":41419601},{"atl":[[190,8.73]],"id":41419601},{"atl":[[390,0]],"id":41419597},{"atl":[[120,6.29]],"id":41419606},{"atb":[[100,6.56],[30,4.6]],"id":41419635},{"atb":[[10.5,14.04]],"id":41419602},{"atl":[[390,2]],"id":41419585},{"atl":[[70,14.26],[440,0]],"id":41419614},{"atb":[[140,8.28],[95,3.27]],"id":41419590},{"atb":[[22,4.76]],"id":41419631},{"atb":[[85,3.27]],"id":41419627},{"atb":[[7,22.23],[14.5,17.22]],"id":41419607},{"atl":[[70,14.26],[440,0]],"id":41419607},{"atb":[[32,10.08],[11,13.34]],"id":41419615},{"atl":[[70,7.26]],"id":41419615},{"atb":[[55,7.9]],"id":41419611},{"atb":[[36,3.81],[110,6.41]],"id":41419587},{"atl":[[250,5.6]],"id":41419587},{"atb":[[40,3.42],[95,22.41]],"id":41419632},{"atb":[[12,21.21],[28,17.22]],"id":41419628},{"atl":[[570,0],[240,7.32]],"id":41419628},{"atb":[[5.6,29]],"id":41419595},{"atl":[[13.5,17.66],[250,0]],"id":41419595},{"atb":[[25,17.22],[14.5,9.87]],"id":41419616},{"atl":[[570,0],[190,8.73]],"id":41419616},{"atb":[[40,3.42],[100,22.21]],"id":41419625},{"atl":[[420,0]],"id":41419592},{"atl":[[20,13.31]],"id":41419600},{"atb":[[60,7.65]],"id":41419629},{"atl":[[130,6.19]],"id":41419629},{"atb":[[10,14.82],[14,32.07]],"id":41419596},{"atl":[[90,16.21]],"id":41419596}],"con":true,"img":false}]}
{"op":"mcm","clk":"5353111919","pt":1646209097314,"mc":[{"id":"1.195503860","rc":[{"atl":[[720,0.21]],"id":41419585}],"con":true,"img":false}]}
{"op":"mcm","clk":"5353111925","pt":1646209097616,"mc":[{"id":"1.195503860","rc":[{"atl":[[720,1.98],[750,0]],"id":41419585}],"con":true,"img":false}]}
{"op":"mcm","clk":"5353111937","pt":1646209097929,"mc":[{"id":"1.195503860","rc":[{"atb":[[14.5,9.87]],"id":41419609},{"atb":[[65,11.07]],"id":41419605},{"atl":[[870,2]],"id":41419605},{"atb":[[60,0]],"id":41419617},{"atl":[[870,2]],"id":41419617},{"atb":[[65,11.07]],"id":41419622},{"atl":[[930,2]],"id":41419622},{"atl":[[790,2]],"id":41419618},{"atb":[[23,2.72]],"id":41419601},{"atl":[[560,0]],"id":41419601},{"atb":[[90,6.74]],"id":41419630},{"atl":[[890,2]],"id":41419630},{"atl":[[360,0]],"id":41419597},{"atl":[[750,0]],"id":41419606},{"atb":[[95,2.72]],"id":41419635},{"atb":[[24,2.72]],"id":41419602},{"atl":[[580,0]],"id":41419602},{"atl":[[720,1.76]],"id":41419585},{"atb":[[46,21.37]],"id":41419610},{"atl":[[850,2]],"id":41419610},{"atb":[[80,10.6]],"id":41419623},{"atl":[[990,2]],"id":41419623},{"atb":[[85,9.92]],"id":41419586},{"atb":[[65,2.72]],"id":41419631},{"atl":[[1000,0]],"id":41419631},{"atl":[[520,0]],"id":41419598},{"atb":[[120,8.48]],"id":41419627},{"atl":[[220,0]],"id":41419594},{"atb":[[140,0]],"id":41419636},{"atb":[[40,13.44]],"id":41419603},{"atl":[[760,2]],"id":41419603},{"atb":[[50,0]],"id":41419611},{"atl":[[770,2]],"id":41419611},{"atb":[[80,10.6]],"id":41419624},{"atl":[[990,2]],"id":41419624},{"atb":[[100,0]],"id":41419587},{"atb":[[100,0]],"id":41419632},{"atb":[[46,0]],"id":41419599},{"atl":[[710,2]],"id":41419599},{"atl":[[220,0]],"id":41419595},{"atl":[[600,0]],"id":41419608},{"atl":[[610,0]],"id":41419604},{"atb":[[110,0]],"id":41419625},{"atl":[[390,0]],"id":41419592},{"atl":[[630,2]],"id":41419621},{"atb":[[100,0]],"id":41419588},{"atl":[[350,0]],"id":41419600},{"atb":[[55,2.72]],"id":41419629},{"atl":[[420,0]],"id":41419596}],"con":true,"img":false}]}
{"op":"mcm","clk":"5353111939","pt":1646209097990,"mc":[{"id":"1.195503860","rc":[{"atl":[[820,2]],"id":41419613},{"atl":[[220,0]],"id":41419593},{"atb":[[29,2.72]],"id":41419615},{"atl":[[610,0]],"id":41419615},{"atl":[[990,2]],"id":41419587},{"atl":[[780,2]],"id":41419629}],"con":true,"img":false}]}
{"op":"mcm","clk":"5353111951","pt":1646209098404,"mc":[{"id":"1.195503860","rc":[{"atl":[[140,9.16],[780,2]],"id":41419606}],"con":true,"img":false}]}
{"op":"mcm","clk":"5353111956","pt":1646209098505,"mc":[{"id":"1.195503860","rc":[{"atl":[[780,0],[430,2]],"id":41419606}],"con":true,"img":false}]}
{"op":"mcm","clk":"5353111963","pt":1646209098711,"mc":[{"id":"1.195503860","rc":[{"atb":[[70,9.92]],"id":41419630}],"con":true,"img":false}]}
{"op":"mcm","clk":"5353112033","pt":1646209100313,"mc":[{"id":"1.195503860","rc":[{"atl":[[32,4.96]],"id":41419596}],"con":true,"img":false}]}
{"op":"mcm","clk":"5353112060","pt":1646209101092,"mc":[{"id":"1.195503860","rc":[{"atl":[[38,4.29]],"id":41419596}],"con":true,"img":false}]}
{"op":"mcm","clk":"5353112074","pt":1646209101530,"mc":[{"id":"1.195503860","rc":[{"atl":[[260,4.96]],"id":41419588}],"con":true,"img":false}]}
{"op":"mcm","clk":"5353112080","pt":1646209101688,"mc":[{"id":"1.195503860","rc":[{"atl":[[910,2],[1000,0]],"id":41419588}],"con":true,"img":false}]}
{"op":"mcm","clk":"5353112088","pt":1646209101889,"mc":[{"id":"1.195503860","rc":[{"atl":[[1000,1.28]],"id":41419588}],"con":true,"img":false}]}
{"op":"mcm","clk":"5353112104","pt":1646209102307,"mc":[{"id":"1.195503860","rc":[{"atl":[[250,0.63]],"id":41419588}],"con":true,"img":false}]}
{"op":"mcm","clk":"5353112145","pt":1646209103292,"mc":[{"id":"1.195503860","rc":[{"atl":[[990,0]],"id":41419588}],"con":true,"img":false}]}
{"op":"mcm","clk":"5353112205","pt":1646209104697,"mc":[{"id":"1.195503860","rc":[{"atb":[[42,16.94],[55,12.65]],"id":41419617},{"atl":[[940,0],[950,3.35]],"id":41419635},{"atb":[[44,30.91],[48,2.72]],"id":41419611},{"atb":[[85,25.23],[95,2.72]],"id":41419587},{"atb":[[40,31.89],[44,2.72]],"id":41419599},{"atb":[[70,15.54],[95,12.65]],"id":41419588}],"con":true,"img":false}]}
{"op":"mcm","clk":"5353112212","pt":1646209104902,"mc":[{"id":"1.195503860","rc":[{"atb":[[70,4.96],[75,4.96],[50,9.92]],"id":41419617}],"con":true,"img":false}]}
{"op":"mcm","clk":"5353112217","pt":1646209105006,"mc":[{"id":"1.195503860","rc":[{"atb":[[75,0],[55,2.72]],"id":41419617}],"con":true,"img":false}]}
{"op":"mcm","clk":"5353112239","pt":1646209105630,"mc":[{"id":"1.195503860","rc":[{"atb":[[70,7.26]],"id":41419617},{"atl":[[950,2]],"id":41419635},{"atb":[[18.5,11.8]],"id":41419596}],"con":true,"img":false}]}
{"op":"mcm","clk":"5353112262","pt":1646209106096,"mc":[{"id":"1.195503860","rc":[{"atl":[[140,0],[430,5.02]],"id":41419606}],"con":true,"img":false}]}
{"op":"mcm","clk":"5353112271","pt":1646209106405,"mc":[{"id":"1.195503860","rc":[{"atb":[[16,8.23],[18.5,2.72]],"id":41419596}],"con":true,"img":false}]}
{"op":"mcm","clk":"5353112312","pt":1646209107436,"mc":[{"id":"1.195503860","rc":[{"atb":[[14,44.29]],"id":41419596}],"con":true,"img":false}]}
{"op":"mcm","clk":"5353112360","pt":1646209108626,"mc":[{"id":"1.195503860","rc":[{"atl":[[12,0],[12.5,4.96],[14,0],[14.5,9.92]],"id":41419593},{"atb":[[80,20.52],[85,0],[100,4.96],[110,0]],"id":41419623}],"con":true,"img":false}]}
{"op":"mcm","clk":"5353112364","pt":1646209108934,"mc":[{"id":"1.195503860","rc":[{"atb":[[18.5,11.8]],"id":41419596}],"con":true,"img":false}]}
{"op":"mcm","clk":"5353112375","pt":1646209109139,"mc":[{"id":"1.195503860","rc":[{"atb":[[75,14.17],[80,9.92]],"id":41419623}],"con":true,"img":false}]}
{"op":"mcm","clk":"5353112384","pt":1646209109294,"mc":[{"id":"1.195503860","rc":[{"atl":[[14,12.21]],"id":41419593}],"con":true,"img":false}]}
{"op":"mcm","clk":"5353112387","pt":1646209109398,"mc":[{"id":"1.195503860","rc":[{"atb":[[100,6.56]],"id":41419623}],"con":true,"img":false}]}
{"op":"mcm","clk":"5353112406","pt":1646209109811,"mc":[{"id":"1.195503860","rc":[{"atb":[[14,32.07]],"id":41419596}],"con":true,"img":false}]}
{"op":"mcm","clk":"5353112410","pt":1646209109916,"mc":[{"id":"1.195503860","rc":[{"atl":[[21,4.96],[25,9.92]],"id":41419600}],"con":true,"img":false}]}
{"op":"mcm","clk":"5353112413","pt":1646209110019,"mc":[{"id":"1.195503860","rc":[{"atl":[[20,0],[24,0]],"id":41419600}],"con":true,"img":false}]}
{"op":"mcm","clk":"5353112433","pt":1646209110637,"mc":[{"id":"1.195503860","rc":[{"atl":[[21,0],[25,0]],"id":41419600}],"con":true,"img":false}]}
{"op":"mcm","clk":"5353112436","pt":1646209110843,"mc":[{"id":"1.195503860","rc":[{"atl":[[48,22.15],[50,2.04]],"id":41419600}],"con":true,"img":false}]}
{"op":"mcm","clk":"5353112438","pt":1646209110896,"mc":[{"id":"1.195503860","rc":[{"atl":[[46,3.52]],"id":41419600}],"con":true,"img":false}]}
{"op":"mcm","clk":"5353112450","pt":1646209111204,"mc":[{"id":"1.195503860","rc":[{"atl":[[48,0],[55,23.99]],"id":41419600},{"atb":[[18.5,2.72]],"id":41419596}],"con":true,"img":false}]}
{"op":"mcm","clk":"5353112465","pt":1646209111512,"mc":[{"id":"1.195503860","rc":[{"atl":[[130,0]],"id":41419585},{"atl":[[38,0]],"id":41419592},{"atl":[[21,4.96],[25,9.92]],"id":41419600}],"con":true,"img":false}]}
{"op":"mcm","clk":"5353112490","pt":1646209112132,"mc":[{"id":"1.195503860","rc":[{"atl":[[55,0]],"id":41419600},{"atb":[[16,18.82]],"id":41419596}],"con":true,"img":false}]}
{"op":"mcm","clk":"5353112493","pt":1646209112235,"mc":[{"id":"1.195503860","rc":[{"atl":[[140,6.1]],"id":41419585}],"con":true,"img":false}]}
{"op":"mcm","clk":"5353112500","pt":1646209112441,"mc":[{"id":"1.195503860","rc":[{"atl":[[720,3.76],[390,0]],"id":41419585}],"con":true,"img":false}]}
{"op":"mcm","clk":"5353112505","pt":1646209112546,"mc":[{"id":"1.195503860","rc":[{"atb":[[42,3.27]],"id":41419617},{"atl":[[14.5,42.07]],"id":41419593},{"atl":[[940,1.39]],"id":41419635},{"atb":[[80,2.72],[85,19.28]],"id":41419586},{"atl":[[46,3.52]],"id":41419592},{"atl":[[21,12.9],[46,25.67]],"id":41419600}],"con":true,"img":false}]}
{"op":"mcm","clk":"5353112508","pt":1646209112597,"mc":[{"id":"1.195503860","rc":[{"atb":[[50,22.77]],"id":41419617},{"atl":[[12.5,18.77],[25,4.17]],"id":41419593},{"atl":[[40,29.57],[90,2]],"id":41419596}],"con":true,"img":false}]}
{"op":"mcm","clk":"5353112519","pt":1646209112803,"mc":[{"id":"1.195503860","rc":[{"atl":[[140,1.14],[150,4.96]],"id":41419585},{"atl":[[260,0],[250,0]],"id":41419588},{"atl":[[32,10.08]],"id":41419596}],"con":true,"img":false}]}
{"op":"mcm","clk":"5353112523","pt":1646209112907,"mc":[{"id":"1.195503860","rc":[{"atl":[[140,0],[720,1.76],[390,2]],"id":41419585},{"atl":[[910,0],[920,2]],"id":41419588}],"con":true,"img":false}]}
{"op":"mcm","clk":"5353112533","pt":1646209113216,"mc":[{"id":"1.195503860","rc":[{"atl":[[160,8.27],[720,0]],"id":41419585},{"atl":[[70,2],[48,22.56]],"id":41419592}],"con":true,"img":false}]}
{"op":"mcm","clk":"5353112536","pt":1646209113320,"mc":[{"id":"1.195503860","rc":[{"atl":[[46,22.15]],"id":41419600}],"con":true,"img":false}]}
{"op":"mcm","clk":"5353112544","pt":1646209113526,"mc":[{"id":"1.195503860","rc":[{"atl":[[14,0]],"id":41419593},{"atl":[[910,0.17]],"id":41419588},{"atl":[[38,0]],"id":41419596}],"con":true,"img":false}]}
{"op":"mcm","clk":"5353112547","pt":1646209113629,"mc":[{"id":"1.195503860","rc":[{"atl":[[380,0.42]],"id":41419585}],"con":true,"img":false}]}
{"op":"mcm","clk":"5353112550","pt":1646209113734,"mc":[{"id":"1.195503860","rc":[{"atl":[[140,9.47]],"id":41419606}],"con":true,"img":false}]}
{"op":"mcm","clk":"5353112553","pt":1646209113838,"mc":[{"id":"1.195503860","rc":[{"atl":[[430,2]],"id":41419606}],"con":true,"img":false}]}
{"op":"mcm","clk":"5353112560","pt":1646209114045,"mc":[{"id":"1.195503860","rc":[{"atl":[[160,0]],"id":41419585}],"con":true,"img":false}]}
{"op":"mcm","clk":"5353112588","pt":1646209114611,"mc":[{"id":"1.195503860","rc":[{"atl":[[140,0]],"id":41419606}],"con":true,"img":false}]}
{"op":"mcm","clk":"5353112603","pt":1646209115025,"mc":[{"id":"1.195503860","rc":[{"atl":[[70,7.26]],"id":41419628}],"con":true,"img":false}]}
{"op":"mcm","clk":"5353112637","pt":1646209115847,"mc":[{"id":"1.195503860","rc":[{"atl":[[540,0]],"id":41419628}],"con":true,"img":false}]}
{"op":"mcm","clk":"5353112645","pt":1646209116002,"mc":[{"id":"1.195503860","rc":[{"atl":[[260,4.96]],"id":41419588}],"con":true,"img":false}]}
{"op":"mcm","clk":"5353112658","pt":1646209116412,"mc":[{"id":"1.195503860","rc":[{"atl":[[70,4.96]],"id":41419628}],"con":true,"img":false}]}
{"op":"mcm","clk":"5353112686","pt":1646209117237,"mc":[{"id":"1.195503860","rc":[{"atl":[[920,3.44],[1000,0]],"id":41419588}],"con":true,"img":false}]}
{"op":"mcm","clk":"5353112698","pt":1646209117546,"mc":[{"id":"1.195503860","rc":[{"atl":[[260,5.57]],"id":41419588}],"con":true,"img":false}]}
{"op":"mcm","clk":"5353112725","pt":1646209118325,"mc":[{"id":"1.195503860","rc":[{"atl":[[910,0]],"id":41419588}],"con":true,"img":false}]}
{"op":"mcm","clk":"5353112746","pt":1646209118944,"mc":[{"id":"1.195503860","rc":[{"atl":[[40,0],[42,4.96],[48,12.63],[50,9.92]],"id":41419592},{"atl":[[920,2]],"id":41419588}],"con":true,"img":false}]}
{"op":"mcm","clk":"5353112756","pt":1646209119253,"mc":[{"id":"1.195503860","rc":[{"atl":[[260,0.61]],"id":41419588}],"con":true,"img":false}]}
{"op":"mcm","clk":"5353112762","pt":1646209119357,"mc":[{"id":"1.195503860","rc":[{"atb":[[44,9.92],[46,0],[55,4.96],[60,0]],"id":41419603},{"atl":[[260,0]],"id":41419588}],"con":true,"img":false}]}
{"op":"mcm","clk":"5353112772","pt":1646209119512,"mc":[{"id":"1.195503860","rc":[{"atl":[[920,0],[930,2]],"id":41419588}],"con":true,"img":false}]}
{"op":"mcm","clk":"5353112794","pt":1646209119923,"mc":[{"id":"1.195503860","rc":[{"atl":[[25,48.41],[14.5,9.92]],"id":41419593},{"atl":[[940,0],[950,3.4]],"id":41419635}],"con":true,"img":false}]}
{"op":"mcm","clk":"5353112798","pt":1646209120026,"mc":[{"id":"1.195503860","rc":[{"atl":[[130,1.23],[140,4.96]],"id":41419613},{"atb":[[55,7.9]],"id":41419603},{"atl":[[1000,0.15]],"id":41419588},{"atl":[[90,16.94]],"id":41419596}],"con":true,"img":false}]}
{"op":"mcm","clk":"5353112802","pt":1646209120131,"mc":[{"id":"1.195503860","rc":[{"atl":[[820,0],[440,2]],"id":41419613},{"atl":[[40,9.92]],"id":41419596}],"con":true,"img":false}]}
{"op":"mcm","clk":"5353112827","pt":1646209120648,"mc":[{"id":"1.195503860","rc":[{"atl":[[820,1.63],[850,0]],"id":41419613},{"atl":[[270,4.96]],"id":41419588}],"con":true,"img":false}]}
{"op":"mcm","clk":"5353112837","pt":1646209120856,"mc":[{"id":"1.195503860","rc":[{"atl":[[930,0]],"id":41419588}],"con":true,"img":false}]}
{"op":"mcm","clk":"5353112844","pt":1646209120909,"mc":[{"id":"1.195503860","rc":[{"atb":[[9.2,12.2],[11,0]],"id":41419601},{"atb":[[17,0],[19.5,0]],"id":41419592},{"atb":[[18.5,11.8]],"id":41419596},{"atl":[[32,4.96]],"id":41419596}],"con":true,"img":false}]}
{"op":"mcm","clk":"5353112851","pt":1646209121014,"mc":[{"id":"1.195503860","rc":[{"atl":[[150,0],[160,4.96]],"id":41419585},{"atb":[[32,0],[26,9.92],[27,19.89],[30,4.96]],"id":41419615}],"con":true,"img":false}]}
{"op":"mcm","clk":"5353112854","pt":1646209121117,"mc":[{"id":"1.195503860","rc":[{"atl":[[170,0.93],[190,4.96]],"id":41419617},{"atb":[[7.6,2.72]],"id":41419593},{"atb":[[240,0.66]],"id":41419589},{"atl":[[130,4.96],[110,1.45]],"id":41419618},{"atb":[[20,4.96],[22,22.15],[26,0]],"id":41419601},{"atl":[[25,4.96]],"id":41419597},{"atb":[[60,5.42]],"id":41419585},{"atl":[[24,0],[26,4.96],[28,0],[30,9.92]],"id":41419614},{"atl":[[150,1.06],[170,4.96]],"id":41419631},{"atb":[[34,7.54]],"id":41419598},{"atb":[[9.6,0],[8.6,0]],"id":41419594},{"atb":[[12.5,0],[13.5,4.96],[14.5,0]],"id":41419607},{"atl":[[24,11.86]],"id":41419607},{"atl":[[240,0.66],[250,4.96]],"id":41419624},{"atl":[[270,4.96],[250,0.63]],"id":41419587},{"atb":[[9.6,0],[8.6,0]],"id":41419595},{"atb":[[19,9.92],[22,4.96],[24,0],[28,2.72]],"id":41419608},{"atb":[[15.5,21.83]],"id":41419592},{"atl":[[130,1.23],[140,4.96]],"id":41419629}],"con":true,"img":false}]}
{"op":"mcm","clk":"5353112862","pt":1646209121221,"mc":[{"id":"1.195503860","rc":[{"atl":[[870,0]],"id":41419617},{"atl":[[790,0],[450,2]],"id":41419618},{"atl":[[530,2],[900,0]],"id":41419631},{"atl":[[940,2]],"id":41419624},{"atl":[[480,2]],"id":41419629}],"con":true,"img":false}]}
{"op":"mcm","clk":"5353112867","pt":1646209121323,"mc":[{"id":"1.195503860","rc":[{"atl":[[570,2]],"id":41419617},{"atl":[[140,9.62]],"id":41419606},{"atl":[[990,0]],"id":41419624},{"atb":[[15.5,32.78]],"id":41419592},{"atl":[[270,0]],"id":41419588},{"atb":[[11.5,2.72]],"id":41419600},{"atl":[[780,0]],"id":41419629}],"con":true,"img":false}]}
{"op":"mcm","clk":"5353112876","pt":1646209121531,"mc":[{"id":"1.195503860","rc":[{"atl":[[870,1.54],[900,0]],"id":41419617},{"atb":[[160,4.96],[170,2.8]],"id":41419589},{"atl":[[820,0]],"id":41419618},{"atb":[[20,29.71],[22,0]],"id":41419601},{"atl":[[910,0],[900,1.49]],"id":41419631},{"atb":[[5.6,82.05],[7.6,29.02]],"id":41419594},{"atb":[[13.5,27.11]],"id":41419607},{"atl":[[990,1.35],[1000,0]],"id":41419624},{"atl":[[990,3.35],[1000,0]],"id":41419587},{"atb":[[5.6,81.1],[7.2,30.57]],"id":41419595},{"atb":[[22,27.3],[23,3.27]],"id":41419608},{"atl":[[780,1.71],[810,0]],"id":41419629}],"con":true,"img":false}]}
{"op":"mcm","clk":"5353112886","pt":1646209121633,"mc":[{"id":"1.195503860","rc":[{"atl":[[790,1.69]],"id":41419618},{"atb":[[18.5,3.27],[22,2.72]],"id":41419592},{"atb":[[16,8.23]],"id":41419596},{"atl":[[40,13.99]],"id":41419596}],"con":true,"img":false}]}
{"op":"mcm","clk":"5353112898","pt":1646209121839,"mc":[{"id":"1.195503860","rc":[{"atb":[[25,0],[27,3.27],[28,4.96],[29,0]],"id":41419609},{"atb":[[65,4.96],[70,0],[48,9.92],[50,12.84]],"id":41419617},{"atb":[[7.2,30.57]],"id":41419593},{"atb":[[170,1.86]],"id":41419589},{"atl":[[130,0],[120,4.96]],"id":41419618},{"atb":[[22,7.56]],"id":41419601},{"atl":[[29,15.59]],"id":41419597},{"atl":[[65,2.48]],"id":41419614},{"atb":[[8,3.27],[9,2.72]],"id":41419594},{"atb":[[11.5,9.92]],"id":41419607},{"atl":[[410,0]],"id":41419607},{"atb":[[29,8.4]],"id":41419615},{"atl":[[110,1.45],[120,4.96]],"id":41419599},{"atb":[[9.2,3.27],[10.5,2.72]],"id":41419595},{"atb":[[23,10.49]],"id":41419608}],"con":true,"img":false}]}
{"op":"mcm","clk":"5353112904","pt":1646209121941,"mc":[{"id":"1.195503860","rc":[{"atl":[[710,0],[410,2]],"id":41419599}],"con":true,"img":false}]}
{"op":"mcm","clk":"5353112918","pt":1646209122148,"mc":[{"id":"1.195503860","rc":[{"atb":[[11,20.84]],"id":41419600}],"con":true,"img":false}]}
{"op":"mcm","clk":"5353112924","pt":1646209122251,"mc":[{"id":"1.195503860","rc":[{"atl":[[65,14.74]],"id":41419614}],"con":true,"img":false}]}
{"op":"mcm","clk":"5353112931","pt":1646209122356,"mc":[{"id":"1.195503860","rc":[{"atl":[[70,2]],"id":41419614},{"atl":[[710,1.89],[740,0]],"id":41419599}],"con":true,"img":false}]}
{"op":"mcm","clk":"5353112944","pt":1646209122560,"mc":[{"id":"1.195503860","rc":[{"atb":[[60,2.69]],"id":41419617},{"atl":[[1000,0]],"id":41419614}],"con":true,"img":false}]}
{"op":"mcm","clk":"5353112960","pt":1646209122819,"mc":[{"id":"1.195503860","rc":[{"atl":[[25,0],[29,5.67]],"id":41419597},{"atl":[[170,4.96]],"id":41419585},{"atl":[[70,2.3],[75,4.96],[90,0],[95,9.92]],"id":41419598},{"atl":[[270,0],[250,0]],"id":41419587},{"atl":[[42,0],[46,8.48],[50,0]],"id":41419592}],"con":true,"img":false}]}
{"op":"mcm","clk":"5353112965","pt":1646209122922,"mc":[{"id":"1.195503860","rc":[{"atl":[[26,4.96],[30,9.92]],"id":41419597},{"atl":[[160,0]],"id":41419585},{"atb":[[180,1.63]],"id":41419619},{"atl":[[70,0]],"id":41419598},{"atb":[[26,0],[27,0],[29,13.36],[30,0]],"id":41419615},{"atl":[[70,0],[75,4.96],[90,0],[95,9.92]],"id":41419628}],"con":true,"img":false}]}
{"op":"mcm","clk":"5353112971","pt":1646209123129,"mc":[{"id":"1.195503860","rc":[{"atb":[[55,10.79]],"id":41419617}],"con":true,"img":false}]}
{"op":"mcm","clk":"5353112975","pt":1646209123240,"mc":[{"id":"1.195503860","rc":[{"atb":[[50,0]],"id":41419617}],"con":true,"img":false}]}
{"op":"mcm","clk":"5353112979","pt":1646209123350,"mc":[{"id":"1.195503860","rc":[{"atl":[[65,2],[32,24.53]],"id":41419597},{"atl":[[95,24.17],[230,2]],"id":41419598},{"atb":[[12,33.53]],"id":41419615},{"atl":[[990,2]],"id":41419587},{"atl":[[70,19.52],[48,0]],"id":41419592}],"con":true,"img":false}]}
{"op":"mcm","clk":"5353112991","pt":1646209123651,"mc":[{"id":"1.195503860","rc":[{"atl":[[170,0]],"id":41419585},{"atl":[[75,0],[95,14.25]],"id":41419598},{"atl":[[270,4.96],[980,0.16]],"id":41419587},{"atl":[[46,3.52]],"id":41419592}],"con":true,"img":false}]}
{"op":"mcm","clk":"5353113004","pt":1646209123856,"mc":[{"id":"1.195503860","rc":[{"atl":[[390,0],[430,2]],"id":41419585}],"con":true,"img":false}]}
{"op":"mcm","clk":"5353113010","pt":1646209123959,"mc":[{"id":"1.195503860","rc":[{"atb":[[150,0],[180,0.74]],"id":41419619},{"atl":[[220,0.72]],"id":41419598},{"atb":[[29,8.4]],"id":41419615},{"atl":[[230,0.69]],"id":41419628}],"con":true,"img":false}]}
{"op":"mcm","clk":"5353113014","pt":1646209124063,"mc":[{"id":"1.195503860","rc":[{"atl":[[260,2],[230,0]],"id":41419598},{"atl":[[75,2]],"id":41419592}],"con":true,"img":false}]}
{"op":"mcm","clk":"5353113021","pt":1646209124116,"mc":[{"id":"1.195503860","rc":[{"atl":[[70,17.52]],"id":41419592}],"con":true,"img":false}]}
{"op":"mcm","clk":"5353113031","pt":1646209124321,"mc":[{"id":"1.195503860","rc":[{"atl":[[160,4.96]],"id":41419585},{"atb":[[140,4.96],[100,22.44]],"id":41419619},{"atl":[[70,4.96],[90,9.92]],"id":41419598},{"atl":[[44,4.96],[55,9.92]],"id":41419592}],"con":true,"img":false}]}
{"op":"mcm","clk":"5353113039","pt":1646209124528,"mc":[{"id":"1.195503860","rc":[{"atl":[[240,2]],"id":41419628}],"con":true,"img":false}]}
{"op":"mcm","clk":"5353113045","pt":1646209124630,"mc":[{"id":"1.195503860","rc":[{"atb":[[150,1.06]],"id":41419619},{"atb":[[26,9.92],[30,4.96]],"id":41419615},{"atl":[[230,6.58]],"id":41419628}],"con":true,"img":false}]}
{"op":"mcm","clk":"5353113059","pt":1646209125041,"mc":[{"id":"1.195503860","rc":[{"atl":[[270,0]],"id":41419587}],"con":true,"img":false}]}
{"op":"mcm","clk":"5353113065","pt":1646209125144,"mc":[{"id":"1.195503860","rc":[{"atl":[[160,0],[170,4.96]],"id":41419585},{"atl":[[70,0],[75,4.96],[90,0],[95,24.17]],"id":41419598}],"con":true,"img":false}]}
{"op":"mcm","clk":"5353113080","pt":1646209125454,"mc":[{"id":"1.195503860","rc":[{"atb":[[25,9.92],[26,0],[29,13.36],[30,0]],"id":41419615}],"con":true,"img":false}]}
{"op":"mcm","clk":"5353113094","pt":1646209125762,"mc":[{"id":"1.195503860","rc":[{"atb":[[27,18.04]],"id":41419609},{"atl":[[270,4.96]],"id":41419587},{"atl":[[46,8.48],[60,9.92]],"id":41419592}],"con":true,"img":false}]}
{"op":"mcm","clk":"5353113099","pt":1646209125814,"mc":[{"id":"1.195503860","rc":[{"atl":[[44,0],[55,0]],"id":41419592}],"con":true,"img":false}]}
{"op":"mcm","clk":"5353113101","pt":1646209125916,"mc":[{"id":"1.195503860","rc":[{"atb":[[29,7.69]],"id":41419615}],"con":true,"img":false}]}
{"op":"mcm","clk":"5353113108","pt":1646209126123,"mc":[{"id":"1.195503860","rc":[{"atb":[[24,13.19],[25,0],[28,4.96],[29,2.72]],"id":41419615}],"con":true,"img":false}]}
{"op":"mcm","clk":"5353113117","pt":1646209126431,"mc":[{"id":"1.195503860","rc":[{"atl":[[32,34.45],[26,0],[27,4.96],[30,0]],"id":41419597},{"atl":[[170,0],[180,4.96]],"id":41419585},{"atl":[[75,0],[80,4.96],[95,14.25],[100,9.92]],"id":41419598},{"atl":[[270,0]],"id":41419587},{"atl":[[65,9.92],[46,0],[48,4.96],[60,0]],"id":41419592}],"con":true,"img":false}]}
{"op":"mcm","clk":"5353113127","pt":1646209126740,"mc":[{"id":"1.195503860","rc":[{"atb":[[29,8.4]],"id":41419615},{"atl":[[65,12.4]],"id":41419592}],"con":true,"img":false}]}
{"op":"mcm","clk":"5353113143","pt":1646209127255,"mc":[{"id":"1.195503860","rc":[{"atl":[[370,0.43]],"id":41419585}],"con":true,"img":false}]}
{"op":"mcm","clk":"5353113160","pt":1646209127565,"mc":[{"id":"1.195503860","rc":[{"atl":[[950,2],[940,1.44]],"id":41419635},{"atl":[[12,0],[12.5,4.96],[14,0],[14.5,9.92]],"id":41419594},{"atl":[[46,3.52]],"id":41419592}],"con":true,"img":false}]}
{"op":"mcm","clk":"5353113170","pt":1646209127823,"mc":[{"id":"1.195503860","rc":[{"atb":[[29,2.72]],"id":41419615},{"atl":[[32,10.08]],"id":41419596}],"con":true,"img":false}]}
{"op":"mcm","clk":"5353113181","pt":1646209128130,"mc":[{"id":"1.195503860","rc":[{"atl":[[380,0]],"id":41419585},{"atl":[[270,4.96]],"id":41419587}],"con":true,"img":false}]}
{"op":"mcm","clk":"5353113191","pt":1646209128336,"mc":[{"id":"1.195503860","rc":[{"atl":[[65,9.92]],"id":41419592}],"con":true,"img":false}]}
{"op":"mcm","clk":"5353113195","pt":1646209128439,"mc":[{"id":"1.195503860","rc":[{"atl":[[940,0]],"id":41419635},{"atl":[[380,3.59]],"id":41419585},{"atl":[[25,6.61]],"id":41419594},{"atl":[[65,22.56],[70,0]],"id":41419592}],"con":true,"img":false}]}
{"op":"mcm","clk":"5353113205","pt":1646209128645,"mc":[{"id":"1.195503860","rc":[{"atb":[[28,10.84]],"id":41419615},{"atl":[[40,9.92]],"id":41419596}],"con":true,"img":false}]}
{"op":"mcm","clk":"5353113211","pt":1646209128747,"mc":[{"id":"1.195503860","rc":[{"atl":[[140,0],[430,5.17]],"id":41419606},{"atl":[[170,0.93]],"id":41419585}],"con":true,"img":false}]}
{"op":"mcm","clk":"5353113218","pt":1646209128953,"mc":[{"id":"1.195503860","rc":[{"atl":[[25,23.85],[26,4]],"id":41419594}],"con":true,"img":false}]}
{"op":"mcm","clk":"5353113243","pt":1646209129468,"mc":[{"id":"1.195503860","rc":[{"atl":[[430,2]],"id":41419606},{"atl":[[370,0]],"id":41419585}],"con":true,"img":false}]}
{"op":"mcm","clk":"5353113287","pt":1646209130651,"mc":[{"id":"1.195503860","rc":[{"atl":[[95,0],[100,23.67]],"id":41419598}],"con":true,"img":false}]}
{"op":"mcm","clk":"5353113316","pt":1646209131320,"mc":[{"id":"1.195503860","rc":[{"atb":[[16,13.31]],"id":41419597}],"con":true,"img":false}]}
{"op":"mcm","clk":"5353113321","pt":1646209131423,"mc":[{"id":"1.195503860","rc":[{"atl":[[80,0],[85,4.96],[100,13.75],[110,9.92]],"id":41419598},{"atl":[[75,0],[95,0]],"id":41419628}],"con":true,"img":false}]}
{"op":"mcm","clk":"5353113325","pt":1646209131532,"mc":[{"id":"1.195503860","rc":[{"atl":[[270,2]],"id":41419628}],"con":true,"img":false}]}
{"op":"mcm","clk":"5353113328","pt":1646209131632,"mc":[{"id":"1.195503860","rc":[{"atl":[[80,4.96],[100,9.92],[240,0]],"id":41419628}],"con":true,"img":false}]}
{"op":"mcm","clk":"5353113336","pt":1646209131840,"mc":[{"id":"1.195503860","rc":[{"atl":[[220,0.72]],"id":41419628}],"con":true,"img":false}]}
{"op":"mcm","clk":"5353113341","pt":1646209131942,"mc":[{"id":"1.195503860","rc":[{"atl":[[230,0.69],[250,5.5]],"id":41419628}],"con":true,"img":false}]}
{"op":"mcm","clk":"5353113375","pt":1646209132564,"mc":[{"id":"1.195503860","rc":[{"atl":[[230,0]],"id":41419628}],"con":true,"img":false}]}
{"op":"mcm","clk":"5353113390","pt":1646209132771,"mc":[{"id":"1.195503860","rc":[{"atl":[[32,24.53],[34,9.92],[27,0],[28,4.96]],"id":41419597}],"con":true,"img":false}]}
{"op":"mcm","clk":"5353113395","pt":1646209132881,"mc":[{"id":"1.195503860","rc":[{"atl":[[46,0]],"id":41419592}],"con":true,"img":false}]}
{"op":"mcm","clk":"5353113420","pt":1646209133551,"mc":[{"id":"1.195503860","rc":[{"atl":[[65,9.92],[75,14.26],[60,2.69]],"id":41419592}],"con":true,"img":false}]}
{"op":"mcm","clk":"5353113449","pt":1646209134328,"mc":[{"id":"1.195503860","rc":[{"atl":[[75,2]],"id":41419592}],"con":true,"img":false}]}
{"op":"mcm","clk":"5353113466","pt":1646209134851,"mc":[{"id":"1.195503860","rc":[{"atl":[[940,1.46]],"id":41419635}],"con":true,"img":false}]}
{"op":"mcm","clk":"5353113507","pt":1646209135572,"mc":[{"id":"1.195503860","rc":[{"atl":[[820,0],[440,5.14]],"id":41419613}],"con":true,"img":false}]}
{"op":"mcm","clk":"5353113534","pt":1646209136242,"mc":[{"id":"1.195503860","rc":[{"atl":[[140,9.92]],"id":41419606}],"con":true,"img":false}]}
{"op":"mcm","clk":"5353113539","pt":1646209136449,"mc":[{"id":"1.195503860","rc":[{"atl":[[570,4.43],[870,0]],"id":41419617},{"atl":[[530,4.61],[900,0]],"id":41419631},{"atb":[[5.6,29],[7.6,51.17]],"id":41419594},{"atl":[[940,3.47],[990,0]],"id":41419624},{"atl":[[990,3.39]],"id":41419587},{"atb":[[5.6,29],[7.2,71.15]],"id":41419595},{"atl":[[780,0],[480,4.89]],"id":41419629},{"atl":[[32,5.12],[34,4.96],[40,0],[42,9.92]],"id":41419596}],"con":true,"img":false}]}
{"op":"mcm","clk":"5353113543","pt":1646209136552,"mc":[{"id":"1.195503860","rc":[{"atl":[[450,5.08]],"id":41419618}],"con":true,"img":false}]}
{"op":"mcm","clk":"5353113545","pt":1646209136655,"mc":[{"id":"1.195503860","rc":[{"atl":[[790,0]],"id":41419618}],"con":true,"img":false}]}
{"op":"mcm","clk":"5353113549","pt":1646209136759,"mc":[{"id":"1.195503860","rc":[{"atb":[[7.6,26.79]],"id":41419593}],"con":true,"img":false}]}
{"op":"mcm","clk":"5353113555","pt":1646209136965,"mc":[{"id":"1.195503860","rc":[{"atl":[[42,36.95],[90,2]],"id":41419596}],"con":true,"img":false}]}
{"op":"mcm","clk":"5353113564","pt":1646209137272,"mc":[{"id":"1.195503860","rc":[{"atl":[[710,0],[410,5.38]],"id":41419599}],"con":true,"img":false}]}
{"op":"mcm","clk":"5353113571","pt":1646209137434,"mc":[{"id":"1.195503860","rc":[{"atb":[[70,2.3]],"id":41419617}],"con":true,"img":false}]}
{"op":"mcm","clk":"5353113574","pt":1646209137540,"mc":[{"id":"1.195503860","rc":[{"atb":[[7.2,4.96]],"id":41419593}],"con":true,"img":false}]}
{"op":"mcm","clk":"5353113585","pt":1646209137736,"mc":[{"id":"1.195503860","rc":[{"atb":[[180,1.63]],"id":41419619}],"con":true,"img":false}]}
{"op":"mcm","clk":"5353113604","pt":1646209138147,"mc":[{"id":"1.195503860","rc":[{"atb":[[55,2.72],[60,10.6]],"id":41419617},{"atl":[[100,0],[110,22.6]],"id":41419598}],"con":true,"img":false}]}
{"op":"mcm","clk":"5353113609","pt":1646209138251,"mc":[{"id":"1.195503860","rc":[{"atb":[[21,21.71],[25,0]],"id":41419602},{"atl":[[170,0]],"id":41419585},{"atl":[[85,0],[90,4.96],[110,12.68],[120,9.92]],"id":41419598},{"atb":[[23,9.92],[24,38.88],[12,9.09],[27,4.96],[28,4.96]],"id":41419615},{"atl":[[270,0],[280,4.96]],"id":41419587},{"atl":[[65,22.18]],"id":41419592}],"con":true,"img":false}]}
{"op":"mcm","clk":"5353113613","pt":1646209138353,"mc":[{"id":"1.195503860","rc":[{"atb":[[20,9.92],[24,7.69]],"id":41419602},{"atb":[[24,28.95],[28,0]],"id":41419615}],"con":true,"img":false}]}
{"op":"mcm","clk":"5353113624","pt":1646209138559,"mc":[{"id":"1.195503860","rc":[{"atb":[[150,0],[180,0.74]],"id":41419619},{"atl":[[270,0.58]],"id":41419587}],"con":true,"img":false}]}
{"op":"mcm","clk":"5353113630","pt":1646209138663,"mc":[{"id":"1.195503860","rc":[{"atb":[[21,0]],"id":41419602},{"atl":[[380,0],[430,5.24]],"id":41419585}],"con":true,"img":false}]}
{"op":"mcm","clk":"5353113635","pt":1646209138764,"mc":[{"id":"1.195503860","rc":[{"atb":[[19.5,27.52]],"id":41419602}],"con":true,"img":false}]}
{"op":"mcm","clk":"5353113639","pt":1646209138866,"mc":[{"id":"1.195503860","rc":[{"atl":[[90,6.74]],"id":41419598},{"atl":[[80,6.97]],"id":41419628}],"con":true,"img":false}]}
{"op":"mcm","clk":"5353113643","pt":1646209138970,"mc":[{"id":"1.195503860","rc":[{"atb":[[22,7.56]],"id":41419602},{"atl":[[180,5.85]],"id":41419585}],"con":true,"img":false}]}
{"op":"mcm","clk":"5353113648","pt":1646209139073,"mc":[{"id":"1.195503860","rc":[{"atl":[[29,10.63]],"id":41419597}],"con":true,"img":false}]}
{"op":"mcm","clk":"5353113652","pt":1646209139175,"mc":[{"id":"1.195503860","rc":[{"atl":[[34,0],[28,0]],"id":41419597}],"con":true,"img":false}]}
{"op":"mcm","clk":"5353113657","pt":1646209139239,"mc":[{"id":"1.195503860","rc":[{"atb":[[150,1.06]],"id":41419619},{"atl":[[980,0]],"id":41419587}],"con":true,"img":false}]}
{"op":"mcm","clk":"5353113671","pt":1646209139539,"mc":[{"id":"1.195503860","rc":[{"atl":[[430,2]],"id":41419585},{"atl":[[220,7.08],[250,0]],"id":41419628}],"con":true,"img":false}]}
{"op":"mcm","clk":"5353113675","pt":1646209139640,"mc":[{"id":"1.195503860","rc":[{"atl":[[32,0],[65,23.55]],"id":41419597},{"atl":[[220,0]],"id":41419598},{"atl":[[220,6.35]],"id":41419628}],"con":true,"img":false}]}
{"op":"mcm","clk":"5353113680","pt":1646209139744,"mc":[{"id":"1.195503860","rc":[{"atl":[[36,9.92]],"id":41419597},{"atb":[[140,7.65],[100,9.92]],"id":41419619}],"con":true,"img":false}]}
{"op":"mcm","clk":"5353113720","pt":1646209140880,"mc":[{"id":"1.195503860","rc":[{"atl":[[280,0]],"id":41419587},{"atl":[[70,9.92],[50,4.96]],"id":41419592}],"con":true,"img":false}]}
{"op":"mcm","clk":"5353113724","pt":1646209140942,"mc":[{"id":"1.195503860","rc":[{"atl":[[65,12.26],[48,0]],"id":41419592}],"con":true,"img":false}]}
{"op":"mcm","clk":"5353113739","pt":1646209141246,"mc":[{"id":"1.195503860","rc":[{"atb":[[28,0]],"id":41419609},{"atb":[[44,0],[55,0]],"id":41419613},{"atl":[[11.5,4.96],[13.5,9.92]],"id":41419593},{"atb":[[42,0],[46,9.92],[50,5.97],[60,4.96]],"id":41419618},{"atb":[[70,0],[75,9.92],[90,1.78],[95,4.96]],"id":41419630},{"atb":[[12.5,0],[14.5,12.26]],"id":41419614},{"atb":[[80,0],[100,1.6]],"id":41419623},{"atb":[[150,0.89],[160,5.96],[110,0],[120,9.92]],"id":41419590},{"atb":[[140,2.69],[100,0]],"id":41419619},{"atb":[[85,9.36],[110,0]],"id":41419586},{"atb":[[23,15.01],[27,3.27]],"id":41419598},{"atb":[[130,1.03],[150,4.96],[95,0],[110,9.92]],"id":41419627},{"atl":[[24,6.9],[28,0]],"id":41419607},{"atb":[[90,9.92],[120,4.96]],"id":41419587},{"atl":[[110,6.41]],"id":41419599},{"atb":[[26,9.92],[30,8.23]],"id":41419628},{"atb":[[7.8,4.96],[7,9.92]],"id":41419595},{"atb":[[130,1.23],[95,10.34]],"id":41419612},{"atb":[[16,3.27],[14,22.15]],"id":41419596}],"con":true,"img":false}]}
{"op":"mcm","clk":"5353113744","pt":1646209141351,"mc":[{"id":"1.195503860","rc":[{"atb":[[25,9.92],[29,4.96]],"id":41419609},{"atb":[[65,0],[70,7.26],[48,0]],"id":41419617},{"atb":[[65,10.17],[48,9.92]],"id":41419613},{"atl":[[12.5,13.81],[14.5,0]],"id":41419593},{"atl":[[75,0],[40,4.96],[48,9.92],[55,2.94]],"id":41419601},{"atb":[[11.5,19.65],[13,9.92],[13.5,3.27],[15,4.96]],"id":41419597},{"atb":[[38,0],[42,9.92],[46,0],[50,4.96]],"id":41419585},{"atb":[[13.5,9.92],[15.5,4.96]],"id":41419614},{"atb":[[65,4.96],[46,11.44],[48,9.92],[60,2.69]],"id":41419610},{"atb":[[90,9.92],[120,4.96]],"id":41419623},{"atb":[[150,6.02],[110,9.92]],"id":41419619},{"atb":[[90,9.92],[120,6.29]],"id":41419586},{"atb":[[65,12.65],[70,2.3],[85,4.96],[50,14.76]],"id":41419631},{"atb":[[25,9.92],[29,4.96]],"id":41419598},{"atl":[[22,4.96],[26,9.92]],"id":41419607},{"atl":[[130,4.96],[140,1.14]],"id":41419603},{"atl":[[65,4.96],[70,2.3],[85,9.92],[90,0]],"id":41419615},{"atb":[[44,20.98],[46,9.92],[55,2.94],[60,4.96]],"id":41419611},{"atb":[[85,15.31],[110,1.45]],"id":41419587},{"atl":[[990,2]],"id":41419587},{"atb":[[130,0],[140,6.1],[95,12.49],[100,9.92]],"id":41419632},{"atl":[[120,0]],"id":41419599},{"atb":[[24,0],[28,12.26]],"id":41419628},{"atb":[[7.2,66.19],[6.4,0]],"id":41419595},{"atl":[[65,2.48],[85,0],[46,4.96],[60,9.92]],"id":41419608},{"atb":[[140,4.96],[100,9.92]],"id":41419612},{"atb":[[32,0],[34,25.46],[40,0],[42,4.96]],"id":41419621},{"atb":[[130,1.23],[140,4.96],[95,2.72],[100,9.92]],"id":41419588},{"atl":[[17.5,4.96],[19.5,9.92],[21,7.94],[25,0]],"id":41419600},{"atb":[[65,4.96],[46,14.76],[48,9.92],[60,2.69]],"id":41419629},{"atb":[[17,4.96],[15,9.92]],"id":41419596}],"con":true,"img":false}]}
{"op":"mcm","clk":"5353113746","pt":1646209141454,"mc":[{"id":"1.195503860","rc":[{"atl":[[190,6.73],[120,2]],"id":41419601},{"atl":[[70,9.92],[75,0],[50,4.96],[55,2.94]],"id":41419602},{"atl":[[450,2]],"id":41419603},{"atb":[[150,2.39],[160,5.96],[110,0]],"id":41419620},{"atl":[[140,2],[230,5.55]],"id":41419608},{"atl":[[85,4.96],[90,1.78],[110,9.92],[120,0]],"id":41419604},{"atb":[[140,0],[150,6.02],[100,12.28],[110,9.92]],"id":41419625},{"atl":[[40,2.56],[50,0]],"id":41419600}],"con":true,"img":false}]}
{"op":"mcm","clk":"5353113749","pt":1646209141558,"mc":[{"id":"1.195503860","rc":[{"atl":[[180,4.96]],"id":41419585},{"atl":[[90,4.96]],"id":41419598},{"atl":[[12.5,0],[13,4.96],[14.5,0],[15,9.92]],"id":41419594},{"atb":[[55,4.96]],"id":41419603},{"atl":[[760,0]],"id":41419603},{"atl":[[270,0]],"id":41419587},{"atl":[[80,4.96]],"id":41419628},{"atb":[[11.5,0],[13.5,0],[15,4.96]],"id":41419592},{"atl":[[50,8.2]],"id":41419592}],"con":true,"img":false}]}
{"op":"mcm","clk":"5353113753","pt":1646209141663,"mc":[{"id":"1.195503860","rc":[{"atb":[[27,3.27],[14.5,37.07]],"id":41419609},{"atb":[[46,3.27],[30,19.65]],"id":41419613},{"atl":[[11.5,20.08],[25,4.17],[13.5,51.54]],"id":41419593},{"atb":[[65,2.48],[40,3.27],[46,24.86]],"id":41419618},{"atb":[[65,2.72],[75,20.28],[100,1.6]],"id":41419630},{"atb":[[75,2.72],[50,11.13]],"id":41419623},{"atb":[[80,8.77],[85,0]],"id":41419586},{"atb":[[130,4.26],[160,0.99],[120,2.72]],"id":41419627},{"atl":[[70,2]],"id":41419607},{"atb":[[130,1.23],[85,0],[95,12.85]],"id":41419587}],"con":true,"img":false}]}
{"op":"mcm","clk":"5353113759","pt":1646209141767,"mc":[{"id":"1.195503860","rc":[{"atl":[[40,9.03],[190,0],[55,21.58]],"id":41419601},{"atb":[[11.5,0],[13.5,33.87]],"id":41419597},{"atb":[[14.5,0],[15,18.04]],"id":41419614},{"atb":[[65,7.44],[46,0],[55,10.79]],"id":41419610},{"atb":[[130,1.23]],"id":41419623},{"atb":[[65,26.89],[90,1.78],[50,0]],"id":41419631},{"atb":[[23,6.06],[27,24.54]],"id":41419598},{"atl":[[26,30.49]],"id":41419607},{"atl":[[760,1.83],[790,0],[120,1.33]],"id":41419603},{"atl":[[85,24.68],[240,2]],"id":41419615},{"atb":[[44,0],[48,11.16],[60,7.65]],"id":41419611},{"atl":[[65,24.12]],"id":41419608},{"atb":[[130,4.18],[95,0]],"id":41419612},{"atb":[[70,3.27],[150,1.06],[100,19.13]],"id":41419588},{"atl":[[17,9.92],[21,34.53],[46,0]],"id":41419600},{"atb":[[70,2.3],[46,0],[55,14.07]],"id":41419629},{"atb":[[16,18.28],[14,0]],"id":41419596}],"con":true,"img":false}]}
{"op":"mcm","clk":"5353113761","pt":1646209141869,"mc":[{"id":"1.195503860","rc":[{"atl":[[60,2.69]],"id":41419615},{"atl":[[230,0]],"id":41419608}],"con":true,"img":false}]}
{"op":"mcm","clk":"5353113766","pt":1646209141972,"mc":[{"id":"1.195503860","rc":[{"atl":[[29,4.96]],"id":41419597},{"atl":[[70,30.02],[48,3.33],[200,2]],"id":41419602},{"atl":[[13,4.96],[15,9.92]],"id":41419595},{"atl":[[330,2],[80,2],[110,22.71]],"id":41419604}],"con":true,"img":false}]}
{"op":"mcm","clk":"5353113769","pt":1646209142075,"mc":[{"id":"1.195503860","rc":[{"atl":[[36,0],[38,9.92],[29,0],[30,4.96]],"id":41419597},{"atl":[[940,0],[950,3.47]],"id":41419635},{"atl":[[180,0]],"id":41419585},{"atl":[[130,9.92],[90,0],[95,4.96],[120,0]],"id":41419598},{"atb":[[42,9.92],[44,0],[50,4.96],[55,0]],"id":41419603},{"atb":[[23,0],[26,4.96],[27,0]],"id":41419615},{"atl":[[80,0],[85,4.96],[100,0],[110,9.92]],"id":41419628},{"atl":[[13.5,12.7],[15.5,0]],"id":41419595},{"atb":[[9.6,25.42],[9,9.92],[11,15.87],[9.8,4.96]],"id":41419600}],"con":true,"img":false}]}
{"op":"mcm","clk":"5353113774","pt":1646209142178,"mc":[{"id":"1.195503860","rc":[{"atb":[[19.5,37.45],[20,0],[23,4.96],[24,2.72]],"id":41419602},{"atl":[[190,4.96]],"id":41419585},{"atl":[[140,9.92],[95,1.68],[100,4.96]],"id":41419621}],"con":true,"img":false}]}
{"op":"mcm","clk":"5353113780","pt":1646209142345,"mc":[{"id":"1.195503860","rc":[{"atb":[[30,4.6]],"id":41419613},{"atl":[[12.5,0]],"id":41419593},{"atb":[[50,2.72]],"id":41419618},{"atb":[[90,0]],"id":41419630},{"atb":[[50,3.27]],"id":41419623},{"atb":[[140,0]],"id":41419627},{"atb":[[46,3.52]],"id":41419603},{"atb":[[110,0]],"id":41419587},{"atl":[[1000,0.15]],"id":41419587},{"atl":[[15,24.68]],"id":41419595},{"atl":[[60,0]],"id":41419592},{"atl":[[630,0],[370,2]],"id":41419621}],"con":true,"img":false}]}
{"op":"mcm","clk":"5353113784","pt":1646209142440,"mc":[{"id":"1.195503860","rc":[{"atl":[[55,18.64]],"id":41419601},{"atl":[[420,0.37]],"id":41419585},{"atb":[[60,0]],"id":41419610},{"atb":[[100,0]],"id":41419623},{"atb":[[70,0]],"id":41419631},{"atl":[[95,6.64]],"id":41419598},{"atl":[[140,0]],"id":41419603},{"atl":[[85,9.92]],"id":41419615},{"atb":[[55,0]],"id":41419611},{"atl":[[990,0],[1000,2.15]],"id":41419587},{"atl":[[85,6.85]],"id":41419628},{"atl":[[26,4]],"id":41419595},{"atb":[[130,0]],"id":41419588},{"atb":[[9.6,3.27],[9.8,27.11]],"id":41419600},{"atl":[[21,26.58]],"id":41419600},{"atb":[[60,0]],"id":41419629}],"con":true,"img":false}]}
{"op":"mcm","clk":"5353113790","pt":1646209142645,"mc":[{"id":"1.195503860","rc":[{"atl":[[36,4.53]],"id":41419597},{"atl":[[70,9.92],[55,0]],"id":41419602},{"atl":[[70,0]],"id":41419615},{"atl":[[13,0],[15,14.76]],"id":41419595},{"atl":[[90,0]],"id":41419604},{"atl":[[140,19.98],[660,0]],"id":41419621}],"con":true,"img":false}]}
{"op":"mcm","clk":"5353113793","pt":1646209142748,"mc":[{"id":"1.195503860","rc":[{"atl":[[950,2]],"id":41419635},{"atb":[[40,0],[42,22.56]],"id":41419603},{"atb":[[22,9.92]],"id":41419615},{"atl":[[13.5,17.66],[15.5,9.92]],"id":41419595},{"atl":[[110,9.92]],"id":41419604},{"atl":[[65,0],[70,30.06]],"id":41419592}],"con":true,"img":false}]}
{"op":"mcm","clk":"5353113807","pt":1646209143161,"mc":[{"id":"1.195503860","rc":[{"atl":[[15,0]],"id":41419595}],"con":true,"img":false}]}
{"op":"mcm","clk":"5353113813","pt":1646209143368,"mc":[{"id":"1.195503860","rc":[{"atl":[[430,5.27]],"id":41419585},{"atl":[[24,6.9]],"id":41419594}],"con":true,"img":false}]}
{"op":"mcm","clk":"5353113820","pt":1646209143471,"mc":[{"id":"1.195503860","rc":[{"atl":[[140,0],[430,5.27]],"id":41419606}],"con":true,"img":false}]}
{"op":"mcm","clk":"5353113834","pt":1646209143782,"mc":[{"id":"1.195503860","rc":[{"atl":[[190,5.8]],"id":41419585}],"con":true,"img":false}]}
{"op":"mcm","clk":"5353113852","pt":1646209144042,"mc":[{"id":"1.195503860","rc":[{"atl":[[24,24.57],[25,0]],"id":41419594}],"con":true,"img":false}]}
{"op":"mcm","clk":"5353113860","pt":1646209144249,"mc":[{"id":"1.195503860","rc":[{"atl":[[36,14.45],[38,0],[29,4.96],[30,0]],"id":41419597},{"atb":[[19.5,27.52],[20,9.92],[23,0],[24,7.69]],"id":41419602},{"atl":[[180,4.96],[190,0.84]],"id":41419585},{"atb":[[130,0]],"id":41419623},{"atl":[[130,0],[90,4.96],[95,1.68],[120,9.92]],"id":41419598},{"atb":[[42,12.63],[44,9.92],[50,0],[55,4.96]],"id":41419603},{"atb":[[22,0],[23,9.92],[26,0],[27,4.96]],"id":41419615},{"atl":[[280,4.96]],"id":41419587},{"atl":[[80,4.96],[85,1.88],[100,9.92],[110,0]],"id":41419628},{"atl":[[65,9.92],[70,20.13],[48,4.96],[50,3.24]],"id":41419592}],"con":true,"img":false}]}
{"op":"mcm","clk":"5353113866","pt":1646209144354,"mc":[{"id":"1.195503860","rc":[{"atb":[[65,0]],"id":41419618},{"atl":[[12.5,4.96],[13,0],[14.5,9.92],[15,0]],"id":41419594}],"con":true,"img":false}]}
{"op":"mcm","clk":"5353113878","pt":1646209144559,"mc":[{"id":"1.195503860","rc":[{"atb":[[65,4.96],[70,0],[48,9.92]],"id":41419617}],"con":true,"img":false}]}
{"op":"mcm","clk":"5353113883","pt":1646209144662,"mc":[{"id":"1.195503860","rc":[{"atl":[[420,0]],"id":41419585}],"con":true,"img":false}]}
{"op":"mcm","clk":"5353113888","pt":1646209144765,"mc":[{"id":"1.195503860","rc":[{"atl":[[11.5,0],[12,4.96],[13.5,41.62],[14,9.92]],"id":41419593},{"atb":[[65,0],[46,9.92],[48,0],[60,4.96]],"id":41419610},{"atb":[[29,8.4]],"id":41419615},{"atb":[[44,9.92],[46,0],[55,4.96],[60,0]],"id":41419611},{"atl":[[46,3.52]],"id":41419592},{"atl":[[17,0],[17.5,0],[18,4.96],[19.5,0],[20,9.92]],"id":41419600}],"con":true,"img":false}]}
{"op":"mcm","clk":"5353113894","pt":1646209144972,"mc":[{"id":"1.195503860","rc":[{"atb":[[85,9.92],[90,0],[110,4.96],[120,1.33]],"id":41419623}],"con":true,"img":false}]}
{"op":"mcm","clk":"5353113898","pt":1646209145075,"mc":[{"id":"1.195503860","rc":[{"atb":[[60,7.65]],"id":41419618}],"con":true,"img":false}]}
{"op":"mcm","clk":"5353113908","pt":1646209145388,"mc":[{"id":"1.195503860","rc":[{"atb":[[65,7.44],[55,16.7],[60,0]],"id":41419617}],"con":true,"img":false}]}
{"op":"mcm","clk":"5353113914","pt":1646209145448,"mc":[{"id":"1.195503860","rc":[{"atl":[[13,13.23]],"id":41419593},{"atb":[[60,7.65]],"id":41419610},{"atb":[[29,2.72]],"id":41419615},{"atb":[[55,7.9]],"id":41419611},{"atl":[[50,0]],"id":41419592},{"atl":[[20,18.28]],"id":41419600}],"con":true,"img":false}]}
{"op":"mcm","clk":"5353113919","pt":1646209145647,"mc":[{"id":"1.195503860","rc":[{"atb":[[120,0]],"id":41419623}],"con":true,"img":false}]}
{"op":"mcm","clk":"5353113937","pt":1646209146162,"mc":[{"id":"1.195503860","rc":[{"atl":[[830,2],[890,0]],"id":41419630},{"atl":[[150,2],[200,0]],"id":41419602},{"atl":[[1000,2.15]],"id":41419586},{"atl":[[260,0],[210,2]],"id":41419598},{"atl":[[21,5],[26,0]],"id":41419594},{"atl":[[70,0],[48,2.13]],"id":41419607},{"atl":[[190,2],[240,0]],"id":41419615},{"atl":[[270,0],[220,8.35]],"id":41419628},{"atl":[[260,2],[330,0]],"id":41419604},{"atl":[[1000,2.15]],"id":41419612},{"atl":[[75,0],[60,2]],"id":41419592},{"atl":[[1000,2.15]],"id":41419588}],"con":true,"img":false}]}
{"op":"mcm","clk":"5353113945","pt":1646209146367,"mc":[{"id":"1.195503860","rc":[{"atb":[[110,6.41]],"id":41419623},{"atb":[[27,11.06]],"id":41419615}],"con":true,"img":false}]}
{"op":"mcm","clk":"5353113950","pt":1646209146470,"mc":[{"id":"1.195503860","rc":[{"atl":[[40,4.96]],"id":41419601},{"atl":[[70,0],[75,9.92],[50,0],[55,4.96]],"id":41419602},{"atl":[[80,6.97]],"id":41419628},{"atb":[[9,0],[10,4.96],[9.8,22.15]],"id":41419600}],"con":true,"img":false}]}
{"op":"mcm","clk":"5353113961","pt":1646209146676,"mc":[{"id":"1.195503860","rc":[{"atl":[[100,24.12]],"id":41419628}],"con":true,"img":false}]}
{"op":"mcm","clk":"5353113966","pt":1646209146779,"mc":[{"id":"1.195503860","rc":[{"atl":[[220,2]],"id":41419628}],"con":true,"img":false}]}
{"op":"mcm","clk":"5353113985","pt":1646209147251,"mc":[{"id":"1.195503860","rc":[{"atl":[[46,3.52]],"id":41419601},{"atl":[[85,0]],"id":41419628}],"con":true,"img":false}]}
{"op":"mcm","clk":"5353114001","pt":1646209147552,"mc":[{"id":"1.195503860","rc":[{"atb":[[14.5,9.87]],"id":41419609}],"con":true,"img":false}]}
{"op":"mcm","clk":"5353114023","pt":1646209148171,"mc":[{"id":"1.195503860","rc":[{"atl":[[70,0],[60,12.13]],"id":41419592}],"con":true,"img":false}]}
{"op":"mcm","clk":"5353114055","pt":1646209148894,"mc":[{"id":"1.195503860","rc":[{"atb":[[46,30.09],[55,2.72]],"id":41419610},{"atb":[[44,30.91],[48,2.72]],"id":41419611},{"atl":[[290,2],[370,0]],"id":41419621}],"con":true,"img":false}]}
{"op":"mcm","clk":"5353114078","pt":1646209149461,"mc":[{"id":"1.195503860","rc":[{"atl":[[940,1.51]],"id":41419635}],"con":true,"img":false}]}
{"op":"mcm","clk":"5353114144","pt":1646209150961,"mc":[{"id":"1.195503860","rc":[{"atl":[[140,10.22],[430,2]],"id":41419606}],"con":true,"img":false}]}
{"op":"mcm","clk":"5353114149","pt":1646209151067,"mc":[{"id":"1.195503860","rc":[{"atl":[[350,2],[430,0]],"id":41419606},{"atl":[[300,4.77]],"id":41419587},{"atb":[[7.2,25.61],[7.8,18.3]],"id":41419595}],"con":true,"img":false}]}
{"op":"mcm","clk":"5353114155","pt":1646209151168,"mc":[{"id":"1.195503860","rc":[{"atl":[[760,2],[1000,0.15]],"id":41419587}],"con":true,"img":false}]}
{"op":"mcm","clk":"5353114194","pt":1646209151997,"mc":[{"id":"1.195503860","rc":[{"atl":[[130,11.03],[410,2]],"id":41419599}],"con":true,"img":false}]}
{"op":"mcm","clk":"5353114202","pt":1646209152203,"mc":[{"id":"1.195503860","rc":[{"atl":[[320,2],[410,0]],"id":41419599}],"con":true,"img":false}]}
{"op":"mcm","clk":"5353114214","pt":1646209152462,"mc":[{"id":"1.195503860","rc":[{"atb":[[48,28.4],[55,2.72]],"id":41419617}],"con":true,"img":false}]}
{"op":"mcm","clk":"5353114249","pt":1646209153291,"mc":[{"id":"1.195503860","rc":[{"atb":[[20,32.62]],"id":41419602},{"atl":[[280,5.52]],"id":41419587}],"con":true,"img":false}]}
{"op":"mcm","clk":"5353114252","pt":1646209153394,"mc":[{"id":"1.195503860","rc":[{"atb":[[19.5,3.27]],"id":41419602}],"con":true,"img":false}]}
{"op":"mcm","clk":"5353114262","pt":1646209153603,"mc":[{"id":"1.195503860","rc":[{"atb":[[24,14.59]],"id":41419602},{"atl":[[170,0.93]],"id":41419585},{"atl":[[85,1.88]],"id":41419598}],"con":true,"img":false}]}
{"op":"mcm","clk":"5353114271","pt":1646209153759,"mc":[{"id":"1.195503860","rc":[{"atl":[[330,2],[430,3.27]],"id":41419585}],"con":true,"img":false}]}
{"op":"mcm","clk":"5353114278","pt":1646209153966,"mc":[{"id":"1.195503860","rc":[{"atl":[[430,0]],"id":41419585},{"atl":[[95,16.45],[110,0]],"id":41419598},{"atl":[[100,9.92],[220,8.53]],"id":41419628}],"con":true,"img":false}]}
{"op":"mcm","clk":"5353114282","pt":1646209154070,"mc":[{"id":"1.195503860","rc":[{"atl":[[190,8.42]],"id":41419585},{"atl":[[1000,0]],"id":41419587},{"atl":[[290,4.96]],"id":41419612},{"atl":[[290,4.96]],"id":41419588}],"con":true,"img":false}]}
{"op":"mcm","clk":"5353114288","pt":1646209154172,"mc":[{"id":"1.195503860","rc":[{"atl":[[900,2],[1000,0.15]],"id":41419612},{"atl":[[870,2],[1000,0.15]],"id":41419588}],"con":true,"img":false}]}
{"op":"mcm","clk":"5353114294","pt":1646209154377,"mc":[{"id":"1.195503860","rc":[{"atl":[[190,7.58]],"id":41419585},{"atl":[[95,14.76]],"id":41419598}],"con":true,"img":false}]}
{"op":"mcm","clk":"5353114296","pt":1646209154482,"mc":[{"id":"1.195503860","rc":[{"atb":[[22,0]],"id":41419602},{"atl":[[900,0],[1000,2.15]],"id":41419612},{"atl":[[870,0],[1000,2.15]],"id":41419588}],"con":true,"img":false}]}
{"op":"mcm","clk":"5353114299","pt":1646209154588,"mc":[{"id":"1.195503860","rc":[{"atl":[[280,0.56]],"id":41419588}],"con":true,"img":false}]}
{"op":"mcm","clk":"5353114304","pt":1646209154689,"mc":[{"id":"1.195503860","rc":[{"atl":[[1000,3.59]],"id":41419612},{"atl":[[1000,3.59]],"id":41419588}],"con":true,"img":false}]}
{"op":"mcm","clk":"5353114330","pt":1646209155370,"mc":[{"id":"1.195503860","rc":[{"atl":[[1000,3.43]],"id":41419588}],"con":true,"img":false}]}
{"op":"mcm","clk":"5353114335","pt":1646209155465,"mc":[{"id":"1.195503860","rc":[{"atl":[[1000,2.15]],"id":41419612}],"con":true,"img":false}]}
{"op":"mcm","clk":"5353114359","pt":1646209156085,"mc":[{"id":"1.195503860","rc":[{"atb":[[75,15.13]],"id":41419623}],"con":true,"img":false}]}
{"op":"mcm","clk":"5353114361","pt":1646209156188,"mc":[{"id":"1.195503860","rc":[{"atb":[[27,18.04]],"id":41419609},{"atb":[[46,18.32]],"id":41419613},{"atl":[[12,19.39]],"id":41419593},{"atl":[[48,28.56],[55,0]],"id":41419601},{"atl":[[760,0],[450,5.2]],"id":41419603},{"atl":[[85,26.95]],"id":41419615}],"con":true,"img":false}]}
{"op":"mcm","clk":"5353114375","pt":1646209156498,"mc":[{"id":"1.195503860","rc":[{"atl":[[40,9.03]],"id":41419601},{"atl":[[940,0],[950,3.51]],"id":41419635},{"atl":[[75,29.23]],"id":41419602},{"atl":[[110,23.08]],"id":41419604},{"atl":[[18,14.3]],"id":41419600}],"con":true,"img":false}]}
{"op":"mcm","clk":"5353114390","pt":1646209156912,"mc":[{"id":"1.195503860","rc":[{"atl":[[13,0]],"id":41419593},{"atb":[[55,7.9]],"id":41419603},{"atl":[[26,24.72]],"id":41419595}],"con":true,"img":false}]}
{"op":"mcm","clk":"5353114411","pt":1646209157173,"mc":[{"id":"1.195503860","rc":[{"atl":[[46,0]],"id":41419601},{"atl":[[29,10.63]],"id":41419597},{"atb":[[42,0],[44,24.68]],"id":41419603},{"atb":[[10,35.98],[9.8,0]],"id":41419600},{"atl":[[20,9.92]],"id":41419600}],"con":true,"img":false}]}
{"op":"mcm","clk":"5353114423","pt":1646209157483,"mc":[{"id":"1.195503860","rc":[{"atl":[[13.5,0],[14,65.66]],"id":41419593}],"con":true,"img":false}]}
{"op":"mcm","clk":"5353114426","pt":1646209157586,"mc":[{"id":"1.195503860","rc":[{"atb":[[46,0]],"id":41419603}],"con":true,"img":false}]}
{"op":"mcm","clk":"5353114438","pt":1646209157894,"mc":[{"id":"1.195503860","rc":[{"atl":[[12.5,18.77]],"id":41419594}],"con":true,"img":false}]}
{"op":"mcm","clk":"5353114445","pt":1646209157999,"mc":[{"id":"1.195503860","rc":[{"atl":[[36,9.92]],"id":41419597}],"con":true,"img":false}]}
{"op":"mcm","clk":"5353114447","pt":1646209158102,"mc":[{"id":"1.195503860","rc":[{"atl":[[350,6.14]],"id":41419606},{"atl":[[300,0],[760,3.9]],"id":41419587}],"con":true,"img":false}]}
{"op":"mcm","clk":"5353114450","pt":1646209158205,"mc":[{"id":"1.195503860","rc":[{"atl":[[140,0]],"id":41419606}],"con":true,"img":false}]}
{"op":"mcm","clk":"5353114465","pt":1646209158566,"mc":[{"id":"1.195503860","rc":[{"atl":[[21,27.21],[24,0]],"id":41419594}],"con":true,"img":false}]}
{"op":"mcm","clk":"5353114475","pt":1646209158876,"mc":[{"id":"1.195503860","rc":[{"atl":[[350,2]],"id":41419606},{"atl":[[760,2]],"id":41419587}],"con":true,"img":false}]}
{"op":"mcm","clk":"5353114480","pt":1646209159082,"mc":[{"id":"1.195503860","rc":[{"atl":[[130,0],[320,6.54]],"id":41419599}],"con":true,"img":false}]}
{"op":"mcm","clk":"5353114483","pt":1646209159184,"mc":[{"id":"1.195503860","rc":[{"atb":[[29,8.4]],"id":41419615}],"con":true,"img":false}]}
{"op":"mcm","clk":"5353114519","pt":1646209160009,"mc":[{"id":"1.195503860","rc":[{"atb":[[27,4.96]],"id":41419615},{"atl":[[320,2]],"id":41419599}],"con":true,"img":false}]}
{"op":"mcm","clk":"5353114537","pt":1646209160369,"mc":[{"id":"1.195503860","rc":[{"atb":[[19.5,32.39]],"id":41419602}],"con":true,"img":false}]}
{"op":"mcm","clk":"5353114540","pt":1646209160471,"mc":[{"id":"1.195503860","rc":[{"atb":[[20,9.92]],"id":41419602}],"con":true,"img":false}]}
{"op":"mcm","clk":"5353114649","pt":1646209163105,"mc":[{"id":"1.195503860","rc":[{"atl":[[48,9.92]],"id":41419601}],"con":true,"img":false}]}
{"op":"mcm","clk":"5353114658","pt":1646209163522,"mc":[{"id":"1.195503860","rc":[{"atl":[[120,14.22]],"id":41419601}],"con":true,"img":false}]}
{"op":"mcm","clk":"5353114675","pt":1646209163779,"mc":[{"id":"1.195503860","rc":[{"atl":[[950,2],[940,1.55]],"id":41419635}],"con":true,"img":false}]}
{"op":"mcm","clk":"5353114685","pt":1646209164190,"mc":[{"id":"1.195503860","rc":[{"atb":[[38,17.87],[44,9.92]],"id":41419603}],"con":true,"img":false}]}
{"op":"mcm","clk":"5353114691","pt":1646209164397,"mc":[{"id":"1.195503860","rc":[{"atl":[[25,59.9],[14,9.92]],"id":41419593}],"con":true,"img":false}]}
{"op":"mcm","clk":"5353114695","pt":1646209164500,"mc":[{"id":"1.195503860","rc":[{"atl":[[940,0]],"id":41419635}],"con":true,"img":false}]}
{"op":"mcm","clk":"5353114723","pt":1646209165278,"mc":[{"id":"1.195503860","rc":[{"atl":[[140,10.51]],"id":41419606}],"con":true,"img":false}]}
{"op":"mcm","clk":"5353114728","pt":1646209165588,"mc":[{"id":"1.195503860","rc":[{"atl":[[300,4.9]],"id":41419587}],"con":true,"img":false}]}
{"op":"mcm","clk":"5353114765","pt":1646209166520,"mc":[{"id":"1.195503860","rc":[{"atl":[[130,11.34]],"id":41419599}],"con":true,"img":false}]}
{"op":"mcm","clk":"5353114838","pt":1646209168633,"mc":[{"id":"1.195503860","rc":[{"atb":[[180,1.63]],"id":41419619},{"atb":[[29,2.72]],"id":41419615}],"con":true,"img":false}]}
{"op":"mcm","clk":"5353114865","pt":1646209169305,"mc":[{"id":"1.195503860","rc":[{"atb":[[27,11.06]],"id":41419615}],"con":true,"img":false}]}
{"op":"mcm","clk":"5353114870","pt":1646209169407,"mc":[{"id":"1.195503860","rc":[{"atb":[[150,4.96],[180,0.74]],"id":41419619}],"con":true,"img":false}]}
{"op":"mcm","clk":"5353114885","pt":1646209169925,"mc":[{"id":"1.195503860","rc":[{"atl":[[17.5,4.96],[18,9.33],[19.5,9.92],[20,0]],"id":41419600}],"con":true,"img":false}]}
{"op":"mcm","clk":"5353114899","pt":1646209170195,"mc":[{"id":"1.195503860","rc":[{"atb":[[160,0.99]],"id":41419619}],"con":true,"img":false}]}
{"op":"mcm","clk":"5353114908","pt":1646209170394,"mc":[{"id":"1.195503860","rc":[{"atl":[[17,9.92],[19.5,38.59],[21,0]],"id":41419600}],"con":true,"img":false}]}
{"op":"mcm","clk":"5353114916","pt":1646209170703,"mc":[{"id":"1.195503860","rc":[{"atl":[[940,1.57]],"id":41419635},{"atb":[[140,0],[150,7.56]],"id":41419619}],"con":true,"img":false}]}
{"op":"mcm","clk":"5353114921","pt":1646209170910,"mc":[{"id":"1.195503860","rc":[{"atl":[[300,4.96]],"id":41419586}],"con":true,"img":false}]}
{"op":"mcm","clk":"5353114924","pt":1646209171012,"mc":[{"id":"1.195503860","rc":[{"atl":[[860,2]],"id":41419586}],"con":true,"img":false}]}
{"op":"mcm","clk":"5353114926","pt":1646209171115,"mc":[{"id":"1.195503860","rc":[{"atl":[[1000,0.15]],"id":41419586}],"con":true,"img":false}]}
{"op":"mcm","clk":"5353114929","pt":1646209171321,"mc":[{"id":"1.195503860","rc":[{"atl":[[18,0]],"id":41419600}],"con":true,"img":false}]}
{"op":"mcm","clk":"5353114932","pt":1646209171424,"mc":[{"id":"1.195503860","rc":[{"atl":[[290,0.55],[320,4.65]],"id":41419586}],"con":true,"img":false}]}
{"op":"mcm","clk":"5353114965","pt":1646209172197,"mc":[{"id":"1.195503860","rc":[{"atl":[[140,0],[350,6.25]],"id":41419606},{"atl":[[1000,0]],"id":41419586}],"con":true,"img":false}]}
{"op":"mcm","clk":"5353114973","pt":1646209172506,"mc":[{"id":"1.195503860","rc":[{"atl":[[300,0],[760,3.95]],"id":41419587}],"con":true,"img":false}]}
{"op":"mcm","clk":"5353115017","pt":1646209173497,"mc":[{"id":"1.195503860","rc":[{"atl":[[320,6.66]],"id":41419599}],"con":true,"img":false}]}
{"op":"mcm","clk":"5353115021","pt":1646209173592,"mc":[{"id":"1.195503860","rc":[{"atl":[[130,0]],"id":41419599}],"con":true,"img":false}]}
{"op":"mcm","clk":"5353115047","pt":1646209174315,"mc":[{"id":"1.195503860","rc":[{"atl":[[320,2]],"id":41419599}],"con":true,"img":false}]}
{"op":"mcm","clk":"5353115106","pt":1646209175708,"mc":[{"id":"1.195503860","rc":[{"atl":[[1000,2.15]],"id":41419627},{"atl":[[1000,2.15]],"id":41419632},{"atl":[[1000,2.15]],"id":41419625},{"atl":[[65,2],[90,0]],"id":41419596}],"con":true,"img":false}]}
{"op":"mcm","clk":"5353115117","pt":1646209175915,"mc":[{"id":"1.195503860","rc":[{"atl":[[75,0],[80,9.92],[55,0],[60,4.96]],"id":41419609},{"atl":[[170,5.9],[190,0]],"id":41419617},{"atb":[[65,5.21],[44,9.92],[48,0],[55,4.96]],"id":41419613},{"atl":[[140,0],[120,4.96]],"id":41419613},{"atb":[[240,0]],"id":41419589},{"atb":[[42,9.92],[50,7.69]],"id":41419618},{"atl":[[150,9.92],[110,6.41]],"id":41419618},{"atb":[[20,24.75]],"id":41419601},{"atb":[[75,10.36],[95,0]],"id":41419630},{"atl":[[170,0.93]],"id":41419630},{"atb":[[16,2.72]],"id":41419597},{"atb":[[46,0],[60,2.72]],"id":41419606},{"atl":[[120,1.33]],"id":41419606},{"atb":[[60,2.72]],"id":41419585},{"atl":[[170,0.93]],"id":41419610},{"atl":[[240,4.96],[250,0.63]],"id":41419623},{"atl":[[150,6.02],[170,0]],"id":41419631},{"atb":[[130,9.22],[150,0],[110,0]],"id":41419627},{"atl":[[250,0]],"id":41419624},{"atl":[[300,4.96]],"id":41419632},{"atb":[[21,9.92],[25,4.96]],"id":41419608},{"atl":[[75,9.92],[55,4.96]],"id":41419608},{"atb":[[21,0],[22,9.92],[25,12.26],[26,4.96]],"id":41419616},{"atl":[[75,0],[80,9.92],[55,0],[60,4.96]],"id":41419616},{"atb":[[18.5,0],[22,0],[15.5,20.15]],"id":41419592},{"atl":[[140,10.06],[100,0]],"id":41419621},{"atb":[[11.5,17.85]],"id":41419600},{"atl":[[38,9.92],[30,4.96]],"id":41419596}],"con":true,"img":false}]}
{"op":"mcm","clk":"5353115121","pt":1646209176019,"mc":[{"id":"1.195503860","rc":[{"atl":[[570,2.43],[430,2]],"id":41419617},{"atl":[[340,2],[440,3.14]],"id":41419613},{"atb":[[7.2,0],[6.4,0],[7.6,31.75],[6.8,9.92]],"id":41419593},{"atb":[[46,14.94],[60,2.69]],"id":41419618},{"atl":[[330,2],[450,3.08],[120,0]],"id":41419618},{"atb":[[21,4.96],[23,9.94]],"id":41419601},{"atb":[[65,12.65],[85,4.96],[100,0]],"id":41419630},{"atl":[[160,4.96]],"id":41419630},{"atb":[[13,0],[13.5,38.83],[15,0]],"id":41419597},{"atb":[[42,9.92],[50,4.96]],"id":41419606},{"atl":[[150,9.92],[110,4.96]],"id":41419606},{"atl":[[160,4.96]],"id":41419610},{"atl":[[610,2],[990,0]],"id":41419623},{"atl":[[530,2.61],[400,2]],"id":41419631},{"atb":[[160,0]],"id":41419627},{"atb":[[8,0],[9,0]],"id":41419594},{"atl":[[65,0],[75,4.96],[85,17.03],[95,9.92]],"id":41419615},{"atl":[[130,1.23],[120,4.96]],"id":41419611},{"atl":[[240,5.62]],"id":41419624},{"atl":[[860,2],[1000,0.15]],"id":41419632},{"atb":[[19,0],[22,22.34],[28,8.6]],"id":41419608},{"atl":[[46,3.06],[60,0]],"id":41419608},{"atl":[[310,4.84]],"id":41419612},{"atb":[[15,0],[15.5,9.2]],"id":41419592},{"atl":[[90,4.96],[120,9.92]],"id":41419621},{"atb":[[130,4.96],[140,0],[150,0],[95,12.65],[100,9.21]],"id":41419588},{"atl":[[260,4.96],[290,0]],"id":41419588},{"atl":[[34,0],[42,27.03]],"id":41419596}],"con":true,"img":false}]}
{"op":"mcm","clk":"5353115125","pt":1646209176121,"mc":[{"id":"1.195503860","rc":[{"atl":[[830,0],[420,2]],"id":41419630},{"atl":[[410,2],[850,0]],"id":41419610},{"atl":[[22,0],[23,4.96],[26,20.57],[27,9.92]],"id":41419607},{"atl":[[340,2],[770,0]],"id":41419611},{"atl":[[700,2],[940,1.47]],"id":41419624},{"atl":[[840,2],[1000,0.15]],"id":41419612},{"atl":[[720,2],[1000,1.43]],"id":41419588}],"con":true,"img":false}]}
{"op":"mcm","clk":"5353115130","pt":1646209176329,"mc":[{"id":"1.195503860","rc":[{"atl":[[570,0],[190,7.91]],"id":41419617},{"atl":[[110,1.55]],"id":41419613},{"atb":[[160,8.59],[170,0]],"id":41419589},{"atl":[[150,19.95]],"id":41419618},{"atb":[[65,18.01],[75,0]],"id":41419630},{"atb":[[44,3.27],[30,18.29]],"id":41419606},{"atl":[[240,5.62],[990,1.51],[1000,0]],"id":41419623},{"atl":[[530,0],[170,8.84]],"id":41419631},{"atb":[[130,5.99],[120,10.01]],"id":41419627},{"atl":[[940,0]],"id":41419624},{"atl":[[290,0.55],[860,0],[1000,2.15]],"id":41419632},{"atb":[[22,0],[23,25.25]],"id":41419608},{"atl":[[65,2.48],[60,14.76]],"id":41419608},{"atb":[[25,0],[26,19.72]],"id":41419616},{"atb":[[7.2,0],[8.2,62.51],[11,9.92],[13,4.96],[7,16.67]],"id":41419592},{"atl":[[140,0],[290,7.18]],"id":41419621},{"atl":[[34,15],[42,0],[30,10.43]],"id":41419596}],"con":true,"img":false}]}
{"op":"mcm","clk":"5353115136","pt":1646209176433,"mc":[{"id":"1.195503860","rc":[{"atl":[[340,6.42],[440,0]],"id":41419613},{"atl":[[450,0]],"id":41419618},{"atb":[[20,0],[21,33.17]],"id":41419601},{"atl":[[830,1.8],[920,0]],"id":41419630},{"atb":[[9.2,56.31],[13.5,8.23]],"id":41419597},{"atl":[[150,1.06],[850,1.76],[880,0]],"id":41419610},{"atb":[[5.6,97.45],[7.6,29.02]],"id":41419594},{"atl":[[770,1.94],[800,0],[110,1.45]],"id":41419611},{"atl":[[1000,3.65]],"id":41419632},{"atl":[[85,1.88]],"id":41419621},{"atb":[[95,27.41],[100,0]],"id":41419588}],"con":true,"img":false}]}
{"op":"mcm","clk":"5353115138","pt":1646209176536,"mc":[{"id":"1.195503860","rc":[{"atl":[[720,4.07]],"id":41419588}],"con":true,"img":false}]}
{"op":"mcm","clk":"5353115142","pt":1646209176597,"mc":[{"id":"1.195503860","rc":[{"atl":[[190,0.84]],"id":41419609},{"atb":[[180,0.88]],"id":41419589},{"atb":[[13.5,20.93]],"id":41419597},{"atb":[[55,2.94]],"id":41419606},{"atb":[[50,8.2]],"id":41419585},{"atl":[[180,0.88]],"id":41419616},{"atb":[[16,3.27],[18.5,2.72]],"id":41419592},{"atl":[[1000,0]],"id":41419588},{"atb":[[11,0]],"id":41419600}],"con":true,"img":false}]}
{"op":"mcm","clk":"5353115145","pt":1646209176699,"mc":[{"id":"1.195503860","rc":[{"atb":[[22,0]],"id":41419601},{"atb":[[70,2.3]],"id":41419630},{"atl":[[160,5.96]],"id":41419630},{"atb":[[120,11.34]],"id":41419627},{"atb":[[9.6,2.72],[8.6,3.27]],"id":41419594},{"atb":[[23,18.04]],"id":41419608},{"atl":[[65,0]],"id":41419608},{"atb":[[8.4,12.63]],"id":41419592},{"atb":[[100,0.84]],"id":41419588}],"con":true,"img":false}]}
{"op":"mcm","clk":"5353115149","pt":1646209176803,"mc":[{"id":"1.195503860","rc":[{"atl":[[260,5.57]],"id":41419588}],"con":true,"img":false}]}
{"op":"mcm","clk":"5353115154","pt":1646209177002,"mc":[{"id":"1.195503860","rc":[{"atl":[[190,8.76],[200,2]],"id":41419609},{"atl":[[130,0]],"id":41419613},{"atl":[[150,9.92]],"id":41419618},{"atl":[[250,0]],"id":41419623},{"atl":[[940,1.59]],"id":41419624},{"atl":[[1000,3.49]],"id":41419632},{"atl":[[180,9.25],[190,2]],"id":41419616},{"atb":[[8.2,37.05]],"id":41419592},{"atl":[[290,2]],"id":41419621},{"atb":[[9.6,44.61],[10,4.96]],"id":41419600},{"atl":[[32,0]],"id":41419596}],"con":true,"img":false}]}
{"op":"mcm","clk":"5353115158","pt":1646209177208,"mc":[{"id":"1.195503860","rc":[{"atb":[[21,4.96]],"id":41419601},{"atl":[[170,0]],"id":41419610},{"atl":[[800,2],[860,0]],"id":41419586},{"atb":[[5.6,29]],"id":41419594},{"atl":[[130,0]],"id":41419611},{"atl":[[95,0]],"id":41419621}],"con":true,"img":false}]}
{"op":"mcm","clk":"5353115162","pt":1646209177413,"mc":[{"id":"1.195503860","rc":[{"atl":[[570,0]],"id":41419609},{"atl":[[540,0]],"id":41419616}],"con":true,"img":false}]}
{"op":"mcm","clk":"5353115166","pt":1646209177516,"mc":[{"id":"1.195503860","rc":[{"atl":[[940,0],[950,3.57]],"id":41419635},{"atl":[[280,0]],"id":41419588}],"con":true,"img":false}]}
{"op":"mcm","clk":"5353115171","pt":1646209177619,"mc":[{"id":"1.195503860","rc":[{"atl":[[540,2],[430,0]],"id":41419617},{"atl":[[340,4.42],[430,2]],"id":41419613},{"atl":[[330,0],[410,2]],"id":41419618},{"atl":[[170,0]],"id":41419630},{"atl":[[150,0],[210,2]],"id":41419602},{"atl":[[610,0],[760,2]],"id":41419623},{"atl":[[800,0]],"id":41419586},{"atl":[[400,0],[510,2]],"id":41419631},{"atl":[[280,2],[190,0]],"id":41419615},{"atl":[[1000,1.49]],"id":41419632},{"atl":[[320,0],[380,2]],"id":41419599},{"atl":[[260,0],[320,2]],"id":41419604},{"atl":[[840,0]],"id":41419612},{"atl":[[1000,0.15]],"id":41419625},{"atl":[[65,11.92],[60,10.13]],"id":41419592}],"con":true,"img":false}]}
{"op":"mcm","clk":"5353115248","pt":1646209179624,"mc":[{"id":"1.195503860","rc":[{"atl":[[150,20],[350,2]],"id":41419606}],"con":true,"img":false}]}
{"op":"mcm","clk":"5353115253","pt":1646209179726,"mc":[{"id":"1.195503860","rc":[{"atl":[[300,5.03]],"id":41419587}],"con":true,"img":false}]}
{"op":"mcm","clk":"5353115255","pt":1646209179830,"mc":[{"id":"1.195503860","rc":[{"atl":[[760,2]],"id":41419587}],"con":true,"img":false}]}
{"op":"mcm","clk":"5353115284","pt":1646209180517,"mc":[{"id":"1.195503860","rc":[{"atl":[[300,0]],"id":41419587}],"con":true,"img":false}]}
{"op":"mcm","clk":"5353115290","pt":1646209180621,"mc":[{"id":"1.195503860","rc":[{"atl":[[130,11.65]],"id":41419599}],"con":true,"img":false}]}
{"op":"mcm","clk":"5353115330","pt":1646209181241,"mc":[{"id":"1.195503860","rc":[{"atl":[[520,2],[420,0]],"id":41419630},{"atl":[[410,0],[510,2]],"id":41419610},{"atl":[[340,0],[430,2]],"id":41419611},{"atl":[[700,0],[940,3.59]],"id":41419624},{"atl":[[720,2.07],[910,2]],"id":41419588}],"con":true,"img":false}]}
{"op":"mcm","clk":"5353115340","pt":1646209181405,"mc":[{"id":"1.195503860","rc":[{"atl":[[280,0.56],[250,4.96]],"id":41419587}],"con":true,"img":false}]}
{"op":"mcm","clk":"5353115344","pt":1646209181510,"mc":[{"id":"1.195503860","rc":[{"atl":[[350,0],[410,2]],"id":41419606}],"con":true,"img":false}]}
{"op":"mcm","clk":"5353115357","pt":1646209181721,"mc":[{"id":"1.195503860","rc":[{"atb":[[140,2.28]],"id":41419631},{"atl":[[940,2]],"id":41419624}],"con":true,"img":false}]}
{"op":"mcm","clk":"5353115361","pt":1646209181824,"mc":[{"id":"1.195503860","rc":[{"atb":[[42,0],[44,13.19],[50,0],[55,7.9]],"id":41419606}],"con":true,"img":false}]}
{"op":"mcm","clk":"5353115366","pt":1646209181928,"mc":[{"id":"1.195503860","rc":[{"atl":[[250,5.6]],"id":41419587},{"atb":[[18.5,2.72]],"id":41419596},{"atl":[[30,4.96]],"id":41419596}],"con":true,"img":false}]}
{"op":"mcm","clk":"5353115376","pt":1646209182136,"mc":[{"id":"1.195503860","rc":[{"atl":[[150,4.96],[180,0]],"id":41419585},{"atb":[[65,12.65],[85,15.75]],"id":41419631},{"atl":[[150,4.96]],"id":41419631},{"atl":[[65,2],[42,4.96],[48,0],[50,9.92]],"id":41419592}],"con":true,"img":false}]}
{"op":"mcm","clk":"5353115387","pt":1646209182333,"mc":[{"id":"1.195503860","rc":[{"atl":[[80,4.96],[90,0],[100,9.92],[120,0]],"id":41419598}],"con":true,"img":false}]}
{"op":"mcm","clk":"5353115394","pt":1646209182436,"mc":[{"id":"1.195503860","rc":[{"atb":[[24,38.88],[28,4.96]],"id":41419615}],"con":true,"img":false}]}
{"op":"mcm","clk":"5353115400","pt":1646209182539,"mc":[{"id":"1.195503860","rc":[{"atb":[[23,0],[27,6.1]],"id":41419615},{"atl":[[50,22.56]],"id":41419592}],"con":true,"img":false}]}
{"op":"mcm","clk":"5353115405","pt":1646209182643,"mc":[{"id":"1.195503860","rc":[{"atl":[[150,6.02]],"id":41419585},{"atb":[[180,1.63]],"id":41419619},{"atl":[[42,8.83],[60,0]],"id":41419592},{"atb":[[17,14.88]],"id":41419596},{"atl":[[34,19.81]],"id":41419596}],"con":true,"img":false}]}
{"op":"mcm","clk":"5353115409","pt":1646209182745,"mc":[{"id":"1.195503860","rc":[{"atl":[[760,0],[990,3.51]],"id":41419623},{"atl":[[280,0]],"id":41419587}],"con":true,"img":false}]}
{"op":"mcm","clk":"5353115417","pt":1646209182849,"mc":[{"id":"1.195503860","rc":[{"atl":[[80,6.97]],"id":41419598},{"atl":[[310,0],[1000,1.67]],"id":41419612}],"con":true,"img":false}]}
{"op":"mcm","clk":"5353115422","pt":1646209182913,"mc":[{"id":"1.195503860","rc":[{"atb":[[24,13.19],[27,20.87]],"id":41419615}],"con":true,"img":false}]}
{"op":"mcm","clk":"5353115430","pt":1646209183022,"mc":[{"id":"1.195503860","rc":[{"atl":[[540,4.81],[190,0]],"id":41419617},{"atl":[[170,0],[510,4.98]],"id":41419631},{"atb":[[85,17.07],[120,4.06]],"id":41419627},{"atl":[[34,4.81],[38,32.07]],"id":41419596}],"con":true,"img":false}]}
{"op":"mcm","clk":"5353115435","pt":1646209183121,"mc":[{"id":"1.195503860","rc":[{"atb":[[29,8.4]],"id":41419615}],"con":true,"img":false}]}
{"op":"mcm","clk":"5353115443","pt":1646209183326,"mc":[{"id":"1.195503860","rc":[{"atl":[[910,3.66]],"id":41419588}],"con":true,"img":false}]}
{"op":"mcm","clk":"5353115447","pt":1646209183432,"mc":[{"id":"1.195503860","rc":[{"atl":[[46,0]],"id":41419592},{"atl":[[720,0]],"id":41419588}],"con":true,"img":false}]}
{"op":"mcm","clk":"5353115454","pt":1646209183533,"mc":[{"id":"1.195503860","rc":[{"atl":[[170,0]],"id":41419585},{"atb":[[160,0],[180,0.74]],"id":41419619}],"con":true,"img":false}]}
{"op":"mcm","clk":"5353115460","pt":1646209183627,"mc":[{"id":"1.195503860","rc":[{"atl":[[85,0]],"id":41419598},{"atl":[[240,4.96],[250,0.63]],"id":41419587},{"atl":[[1000,0.15]],"id":41419612}],"con":true,"img":false}]}
{"op":"mcm","clk":"5353115473","pt":1646209183835,"mc":[{"id":"1.195503860","rc":[{"atb":[[25,0],[27,3.27],[29,0]],"id":41419609},{"atl":[[150,0],[160,4.96]],"id":41419585},{"atl":[[85,4.96]],"id":41419598},{"atb":[[27,14.76]],"id":41419615},{"atl":[[300,0]],"id":41419632},{"atl":[[65,0],[42,0],[44,4.96],[50,12.63],[55,9.92],[60,2]],"id":41419592}],"con":true,"img":false}]}
{"op":"mcm","clk":"5353115481","pt":1646209183938,"mc":[{"id":"1.195503860","rc":[{"atb":[[28,4.96]],"id":41419609},{"atl":[[80,0],[100,0]],"id":41419598},{"atb":[[24,3.27],[27,19.72],[28,0],[29,2.72]],"id":41419615}],"con":true,"img":false}]}
{"op":"mcm","clk":"5353115486","pt":1646209184041,"mc":[{"id":"1.195503860","rc":[{"atl":[[330,6.61],[190,0]],"id":41419585},{"atb":[[150,4.96],[110,22.3]],"id":41419619},{"atl":[[910,2]],"id":41419588}],"con":true,"img":false}]}
{"op":"mcm","clk":"5353115493","pt":1646209184144,"mc":[{"id":"1.195503860","rc":[{"atl":[[95,0],[100,15.26]],"id":41419598}],"con":true,"img":false}]}
{"op":"mcm","clk":"5353115499","pt":1646209184204,"mc":[{"id":"1.195503860","rc":[{"atb":[[160,0.99]],"id":41419619}],"con":true,"img":false}]}
{"op":"mcm","clk":"5353115503","pt":1646209184309,"mc":[{"id":"1.195503860","rc":[{"atb":[[14.5,30.32]],"id":41419609},{"atl":[[240,0],[250,5.6]],"id":41419587},{"atl":[[1000,0]],"id":41419632}],"con":true,"img":false}]}
{"op":"mcm","clk":"5353115515","pt":1646209184617,"mc":[{"id":"1.195503860","rc":[{"atl":[[950,2],[940,1.61]],"id":41419635},{"atl":[[320,0.49]],"id":41419585},{"atl":[[80,2],[85,0]],"id":41419598},{"atl":[[300,4.96]],"id":41419632},{"atl":[[44,0],[50,15.87],[55,0]],"id":41419592}],"con":true,"img":false}]}
{"op":"mcm","clk":"5353115521","pt":1646209184848,"mc":[{"id":"1.195503860","rc":[{"atb":[[110,9.92]],"id":41419619},{"atb":[[12.5,11.44]],"id":41419615}],"con":true,"img":false}]}
{"op":"mcm","clk":"5353115541","pt":1646209185340,"mc":[{"id":"1.195503860","rc":[{"atl":[[940,0]],"id":41419635},{"atl":[[80,6.97],[100,25.18]],"id":41419598},{"atl":[[42,4.96],[50,25.8]],"id":41419592}],"con":true,"img":false}]}
{"op":"mcm","clk":"5353115586","pt":1646209186316,"mc":[{"id":"1.195503860","rc":[{"atl":[[520,0],[830,3.8]],"id":41419630},{"atl":[[270,5.67]],"id":41419587}],"con":true,"img":false}]}
{"op":"mcm","clk":"5353115594","pt":1646209186422,"mc":[{"id":"1.195503860","rc":[{"atl":[[110,6.41]],"id":41419606},{"atl":[[240,4.96],[250,0.63]],"id":41419587}],"con":true,"img":false}]}
{"op":"mcm","clk":"5353115604","pt":1646209186625,"mc":[{"id":"1.195503860","rc":[{"atl":[[350,2],[430,0]],"id":41419613},{"atl":[[320,2],[410,0]],"id":41419606},{"atl":[[820,2]],"id":41419586},{"atl":[[280,0],[230,2]],"id":41419615},{"atl":[[630,2],[760,0]],"id":41419587},{"atl":[[880,2]],"id":41419632},{"atl":[[320,0],[250,2]],"id":41419604},{"atl":[[1000,2.15]],"id":41419612},{"atl":[[1000,2.15]],"id":41419625}],"con":true,"img":false}]}
{"op":"mcm","clk":"5353115617","pt":1646209186934,"mc":[{"id":"1.195503860","rc":[{"atl":[[80,9.92],[60,4.96]],"id":41419602}],"con":true,"img":false}]}
{"op":"mcm","clk":"5353115620","pt":1646209187041,"mc":[{"id":"1.195503860","rc":[{"atl":[[75,19.31],[55,0]],"id":41419602}],"con":true,"img":false}]}
{"op":"mcm","clk":"5353115633","pt":1646209187337,"mc":[{"id":"1.195503860","rc":[{"atl":[[110,4.96],[120,0]],"id":41419606}],"con":true,"img":false}]}
{"op":"mcm","clk":"5353115639","pt":1646209187544,"mc":[{"id":"1.195503860","rc":[{"atl":[[75,0]],"id":41419602},{"atl":[[130,0],[380,6.03]],"id":41419599}],"con":true,"img":false}]}
{"op":"mcm","clk":"5353115646","pt":1646209187811,"mc":[{"id":"1.195503860","rc":[{"atl":[[320,6.79]],"id":41419606}],"con":true,"img":false}]}
{"op":"mcm","clk":"5353115650","pt":1646209187913,"mc":[{"id":"1.195503860","rc":[{"atl":[[150,9.92]],"id":41419606}],"con":true,"img":false}]}
{"op":"mcm","clk":"5353115660","pt":1646209188222,"mc":[{"id":"1.195503860","rc":[{"atl":[[80,29.14]],"id":41419602}],"con":true,"img":false}]}
{"op":"mcm","clk":"5353115671","pt":1646209188633,"mc":[{"id":"1.195503860","rc":[{"atl":[[110,6.41]],"id":41419606}],"con":true,"img":false}]}
{"op":"mcm","clk":"5353115706","pt":1646209189352,"mc":[{"id":"1.195503860","rc":[{"atl":[[60,14.26]],"id":41419592}],"con":true,"img":false}]}
{"op":"mcm","clk":"5353115710","pt":1646209189456,"mc":[{"id":"1.195503860","rc":[{"atl":[[50,13.16]],"id":41419592}],"con":true,"img":false}]}
{"op":"mcm","clk":"5353115718","pt":1646209189622,"mc":[{"id":"1.195503860","rc":[{"atb":[[24,15.54]],"id":41419615}],"con":true,"img":false}]}
{"op":"mcm","clk":"5353115723","pt":1646209189725,"mc":[{"id":"1.195503860","rc":[{"atb":[[27,4.96]],"id":41419615}],"con":true,"img":false}]}
{"op":"mcm","clk":"5353115735","pt":1646209190038,"mc":[{"id":"1.195503860","rc":[{"atl":[[540,2],[190,8.11]],"id":41419617},{"atl":[[410,5.75]],"id":41419618},{"atl":[[260,5.92],[990,2]],"id":41419623},{"atl":[[170,9.07]],"id":41419631},{"atl":[[120,22.78]],"id":41419621}],"con":true,"img":false}]}
