{"op":"mcm","clk":"5305619424","pt":1646080581424,"mc":[{"id":"1.195395432","marketDefinition":{"bspMarket":true,"turnInPlayEnabled":false,"persistenceEnabled":false,"marketBaseRate":7.0,"eventId":"31270458","eventTypeId":"4339","numberOfWinners":3,"bettingType":"ODDS","marketType":"PLACE","marketTime":"2022-03-01T03:57:00.000Z","suspendTime":"2022-03-01T03:57:00.000Z","bspReconciled":false,"complete":true,"inPlay":false,"crossMatching":false,"runnersVoidable":false,"numberOfActiveRunners":8,"betDelay":0,"status":"OPEN","runners":[{"status":"ACTIVE","sortPriority":1,"id":39296632,"name":"1. Evolution Girl"},{"status":"ACTIVE","sortPriority":2,"id":38124326,"name":"2. Nanny In Town"},{"status":"ACTIVE","sortPriority":3,"id":41729332,"name":"3. Highland Wonder"},{"status":"ACTIVE","sortPriority":4,"id":27453791,"name":"4. Headwall"},{"status":"ACTIVE","sortPriority":5,"id":41375430,"name":"6. Just Posh"},{"status":"ACTIVE","sortPriority":6,"id":41375435,"name":"7. Rojo Diamond"},{"status":"ACTIVE","sortPriority":7,"id":35784172,"name":"8. Buckle Up Kenzie"},{"status":"ACTIVE","sortPriority":8,"id":41375426,"name":"9. Wynburn Rebel"}],"regulators":["MR_INT"],"venue":"Devonport","countryCode":"AU","discountAllowed":true,"timezone":"Australia/Sydney","openDate":"2022-03-01T02:00:00.000Z","version":4380714794,"name":"To Be Placed","eventName":"Devonport (AUS) 1st Mar"},"rc":[],"con":true,"img":false}]}
{"op":"mcm","clk":"5305743109","pt":1646082027013,"mc":[{"id":"1.195395432","rc":[{"atb":[[1.6,201.36],[1.55,219.67],[1.65,92.93]],"id":39296632},{"atl":[[3.45,4.9],[3.95,8.14],[4.9,6.16],[2.98,6.06],[5.9,9.8]],"id":39296632},{"spn":2.31,"spf":"NaN","id":39296632},{"atb":[[1.01,24163.68],[1.05,1208.18]],"id":41375435},{"atl":[[2.24,9.68],[2.04,11.55],[2.44,16.68],[2.64,14.65],[2.84,26.12]],"id":41375435},{"spn":1.54,"spf":"NaN","id":41375435},{"atb":[[2.06,56.98],[1.98,123.28],[1.93,129.91]],"id":41729332},{"atl":[[16,3.2],[6.4,2.22],[11,2.4],[5.2,2.86],[8.4,3.24]],"id":41729332},{"spn":3.63,"spf":"NaN","id":41729332},{"atb":[[1.18,671.21],[1.23,262.65],[1.13,929.37]],"id":41375430},{"atl":[[3.45,19.61],[2.38,8.7],[2.58,7.6],[2.98,12.13],[2.78,13.5]],"id":41375430},{"spn":1.8,"spf":"NaN","id":41375430},{"atb":[[2,120.81],[1.95,127.17],[2.1,54.91]],"id":27453791},{"atl":[[16.5,3.1],[8.6,3.16],[5.3,2.79],[11.5,2.28],[6.6,2.14]],"id":27453791},{"spn":3.7,"spf":"NaN","id":27453791},{"atb":[[5.5,26.84],[6,24.16],[7,10.06]],"id":38124326},{"atl":[[290,0.16],[95,0.25],[190,0.12],[48,0.25],[29,0.42]],"id":38124326},{"spn":18.0,"spf":"NaN","id":38124326},{"atb":[[1.8,151.02],[1.85,71.06],[1.75,161.09]],"id":35784172},{"atl":[[4.5,3.43],[9,6],[5.5,5.34],[7,4],[3.75,4.36]],"id":35784172},{"spn":2.8,"spf":"NaN","id":35784172},{"atb":[[2.06,56.98],[1.98,123.28],[1.93,129.91]],"id":41375426},{"atl":[[16,3.2],[6.4,2.22],[11,2.4],[5.2,2.86],[8.4,3.24]],"id":41375426},{"spn":3.63,"spf":"NaN","id":41375426}],"con":true,"img":false}]}
{"op":"mcm","clk":"5305747397","pt":1646082083779,"mc":[{"id":"1.195395432","rc":[{"atb":[[1.6,0],[1.55,0],[1.65,0]],"id":39296632},{"atl":[[3.45,0],[3.95,0],[4.9,0],[2.98,0],[5.9,0]],"id":39296632},{"atb":[[1.01,0],[1.05,0]],"id":41375435},{"atl":[[2.24,0],[2.04,0],[2.44,0],[2.64,0],[2.84,0]],"id":41375435},{"atb":[[2.06,0],[1.98,0],[1.93,0]],"id":41729332},{"atl":[[16,0],[6.4,0],[11,0],[5.2,0],[8.4,0]],"id":41729332},{"atb":[[1.18,0],[1.23,0],[1.13,0]],"id":41375430},{"atl":[[3.45,0],[2.38,0],[2.58,0],[2.98,0],[2.78,0]],"id":41375430},{"atb":[[2,0],[1.95,0],[2.1,0]],"id":27453791},{"atl":[[16.5,0],[8.6,0],[5.3,0],[11.5,0],[6.6,0]],"id":27453791},{"atb":[[5.5,0],[6,0],[7,0]],"id":38124326},{"atl":[[290,0],[95,0],[190,0],[48,0],[29,0]],"id":38124326},{"atb":[[1.8,0],[1.85,0],[1.75,0]],"id":35784172},{"atl":[[4.5,0],[9,0],[5.5,0],[7,0],[3.75,0]],"id":35784172},{"atb":[[2.06,0],[1.98,0],[1.93,0]],"id":41375426},{"atl":[[16,0],[6.4,0],[11,0],[5.2,0],[8.4,0]],"id":41375426}],"con":true,"img":false}]}
{"op":"mcm","clk":"5305747684","pt":1646082087094,"mc":[{"id":"1.195395432","rc":[{"atb":[[1.6,201.36],[1.55,219.67],[1.65,92.93]],"id":39296632},{"atl":[[3.45,4.9],[3.95,8.14],[4.9,6.16],[2.98,6.06],[5.9,9.8]],"id":39296632},{"atb":[[1.01,24163.68],[1.05,1208.18]],"id":41375435},{"atl":[[2.24,9.68],[2.04,11.55],[2.44,16.68],[2.64,14.65],[2.84,26.12]],"id":41375435},{"atb":[[2.06,56.98],[1.98,123.28],[1.93,129.91]],"id":41729332},{"atl":[[16,3.2],[6.4,2.22],[11,2.4],[5.2,2.86],[8.4,3.24]],"id":41729332},{"atb":[[1.18,671.21],[1.23,262.65],[1.13,929.37]],"id":41375430},{"atl":[[3.45,19.61],[2.38,8.7],[2.58,7.6],[2.98,12.13],[2.78,13.5]],"id":41375430},{"atb":[[2,120.81],[1.95,127.17],[2.1,54.91]],"id":27453791},{"atl":[[16.5,3.1],[8.6,3.16],[5.3,2.79],[11.5,2.28],[6.6,2.14]],"id":27453791},{"atb":[[5.5,26.84],[6,24.16],[7,10.06]],"id":38124326},{"atl":[[290,0.16],[95,0.25],[190,0.12],[48,0.25],[29,0.42]],"id":38124326},{"atb":[[1.8,151.02],[1.85,71.06],[1.75,161.09]],"id":35784172},{"atl":[[4.5,3.43],[9,6],[5.5,5.34],[7,4],[3.75,4.36]],"id":35784172},{"atb":[[2.06,56.98],[1.98,123.28],[1.93,129.91]],"id":41375426},{"atl":[[16,3.2],[6.4,2.22],[11,2.4],[5.2,2.86],[8.4,3.24]],"id":41375426}],"con":true,"img":false}]}
{"op":"mcm","clk":"5305767161","pt":1646082352333,"mc":[{"id":"1.195395432","rc":[{"atb":[[2.06,0],[1.98,0],[1.93,0]],"id":41375426},{"atl":[[16,0],[6.4,0],[11,0],[5.2,0],[8.4,0]],"id":41375426},{"spn":"NaN","spf":"NaN","id":41375426}],"con":true,"img":false}]}
{"op":"mcm","clk":"5305767422","pt":1646082356443,"mc":[{"id":"1.195395432","rc":[{"atb":[[3.4,50.34],[3.15,56.19],[3.65,22.79]],"id":41375426},{"atl":[[32,0.77],[10.5,1.26],[21,1.2],[55,0.88],[15.5,0.82]],"id":41375426}],"con":true,"img":false}]}
{"op":"mcm","clk":"5305885875","pt":1646083972757,"mc":[{"id":"1.195395432","rc":[{"atb":[[1.6,0],[1.55,0],[1.65,0]],"id":39296632},{"atl":[[3.45,0],[3.95,0],[4.9,0],[2.98,0],[5.9,0]],"id":39296632},{"spn":"NaN","spf":"NaN","id":39296632},{"atb":[[1.01,0],[1.05,0]],"id":41375435},{"atl":[[2.24,0],[2.04,0],[2.44,0],[2.64,0],[2.84,0]],"id":41375435},{"spn":"NaN","spf":"NaN","id":41375435},{"atb":[[2.06,0],[1.98,0],[1.93,0]],"id":41729332},{"atl":[[16,0],[6.4,0],[11,0],[5.2,0],[8.4,0]],"id":41729332},{"spn":"NaN","spf":"NaN","id":41729332},{"atb":[[1.18,0],[1.23,0],[1.13,0]],"id":41375430},{"atl":[[3.45,0],[2.38,0],[2.58,0],[2.98,0],[2.78,0]],"id":41375430},{"spn":"NaN","spf":"NaN","id":41375430},{"atb":[[2,0],[1.95,0],[2.1,0]],"id":27453791},{"atl":[[16.5,0],[8.6,0],[5.3,0],[11.5,0],[6.6,0]],"id":27453791},{"spn":"NaN","spf":"NaN","id":27453791},{"atb":[[1.8,0],[1.85,0],[1.75,0]],"id":35784172},{"atl":[[4.5,0],[9,0],[5.5,0],[7,0],[3.75,0]],"id":35784172},{"spn":"NaN","spf":"NaN","id":35784172},{"atb":[[3.4,0],[3.15,0],[3.65,0]],"id":41375426},{"atl":[[32,0],[10.5,0],[21,0],[55,0],[15.5,0]],"id":41375426}],"con":true,"img":false}]}
{"op":"mcm","clk":"5305886412","pt":1646083981396,"mc":[{"id":"1.195395432","rc":[{"atb":[[1.7,172.59],[1.75,80.54],[1.65,185.87]],"id":39296632},{"atl":[[4,4],[8,6.86],[5,6],[6,4.8],[3.5,4.8]],"id":39296632},{"atb":[[1.01,24163.68],[1.02,3020.46]],"id":41375435},{"atl":[[1.99,12.13],[2.38,17.41],[2.18,10.18],[2.58,15.21],[2.78,27]],"id":41375435},{"atb":[[2,120.81],[2.2,50.34],[2.1,109.83]],"id":41729332},{"atl":[[17.5,2.91],[9,3],[5.5,2.66],[12.5,2.08],[7,2]],"id":41729332},{"atb":[[1.12,1006.82],[1.07,1725.97],[1.17,355.34]],"id":41375430},{"atl":[[2.86,12.92],[2.46,8.23],[2.66,14.47],[3.15,22.35],[2.26,9.53]],"id":41375430},{"atb":[[2.3,46.47],[2.2,100.68],[2.1,109.83]],"id":27453791},{"atl":[[5.6,2.61],[7.2,1.93],[18,2.82],[9.2,2.92],[13,2]],"id":27453791},{"atb":[[1.85,142.14],[1.9,134.24],[1.95,63.58]],"id":35784172},{"atl":[[5.6,2.61],[7.2,3.87],[4.6,3.33],[9.2,2.92],[13,4]],"id":35784172},{"atb":[[3.25,53.69],[3.5,48.32],[3.75,21.96]],"id":41375426},{"atl":[[16.5,0.77],[65,0.75],[36,0.68],[11.5,1.14],[23,1.09]],"id":41375426}],"con":true,"img":false}]}
{"op":"mcm","clk":"5305907843","pt":1646084392840,"mc":[{"id":"1.195395432","rc":[{"atb":[[1.7,0],[1.75,0],[1.65,0]],"id":39296632},{"atl":[[4,0],[8,0],[5,0],[6,0],[3.5,0]],"id":39296632},{"atb":[[1.01,0],[1.02,0]],"id":41375435},{"atl":[[1.99,0],[2.38,0],[2.18,0],[2.58,0],[2.78,0]],"id":41375435},{"atb":[[2,0],[2.2,0],[2.1,0]],"id":41729332},{"atl":[[17.5,0],[9,0],[5.5,0],[12.5,0],[7,0]],"id":41729332},{"atb":[[1.12,0],[1.07,0],[1.17,0]],"id":41375430},{"atl":[[2.86,0],[2.46,0],[2.66,0],[3.15,0],[2.26,0]],"id":41375430},{"atb":[[2.3,0],[2.2,0],[2.1,0]],"id":27453791},{"atl":[[5.6,0],[7.2,0],[18,0],[9.2,0],[13,0]],"id":27453791},{"atb":[[1.85,0],[1.9,0],[1.95,0]],"id":35784172},{"atl":[[5.6,0],[7.2,0],[4.6,0],[9.2,0],[13,0]],"id":35784172},{"atb":[[3.25,0],[3.5,0],[3.75,0]],"id":41375426},{"atl":[[16.5,0],[65,0],[36,0],[11.5,0],[23,0]],"id":41375426}],"con":true,"img":false}]}
{"op":"mcm","clk":"5305908162","pt":1646084398474,"mc":[{"id":"1.195395432","rc":[{"atb":[[1.8,151.02],[1.85,142.14],[1.9,67.12]],"id":39296632},{"atl":[[4,4],[8,3.43],[5,3],[10,5.34],[6,4.8]],"id":39296632},{"atb":[[1.01,30204.61]],"id":41375435},{"atl":[[2.36,17.67],[2.56,15.4],[1.98,12.26],[2.16,10.36],[2.76,27.3]],"id":41375435},{"atb":[[1.8,151.02],[1.85,142.14],[1.9,67.12]],"id":41729332},{"atl":[[4,4],[8,3.43],[5,3],[10,5.34],[6,4.8]],"id":41729332},{"atb":[[1.12,1006.82],[1.07,1725.97],[1.17,355.34]],"id":41375430},{"atl":[[2.86,12.92],[2.46,8.23],[2.66,14.47],[3.15,22.35],[2.26,9.53]],"id":41375430},{"atb":[[1.98,61.64],[1.88,137.29],[1.93,129.91]],"id":27453791},{"atl":[[4.9,3.08],[9.8,2.73],[7.8,3.53],[5.9,2.45],[14.5,3.56]],"id":27453791},{"atb":[[2.06,56.98],[1.98,123.28],[1.93,129.91]],"id":35784172},{"atl":[[16,3.2],[6.4,2.22],[11,2.4],[5.2,2.86],[8.4,3.24]],"id":35784172},{"atb":[[4.3,18.3],[3.9,41.66],[3.65,45.59]],"id":41375426},{"atl":[[32,0.77],[21,0.6],[55,0.44],[110,0.43],[15.5,0.82]],"id":41375426}],"con":true,"img":false}]}
{"op":"mcm","clk":"5305909276","pt":1646084420582,"mc":[{"id":"1.195395432","rc":[{"atb":[[1.8,0],[1.85,0],[1.9,0]],"id":41729332},{"atl":[[4,0],[8,0],[5,0],[10,0],[6,0]],"id":41729332},{"atb":[[1.98,0],[1.88,0],[1.93,0]],"id":27453791},{"atl":[[4.9,0],[9.8,0],[7.8,0],[5.9,0],[14.5,0]],"id":27453791},{"atb":[[2.06,0],[1.98,0],[1.93,0]],"id":35784172},{"atl":[[16,0],[6.4,0],[11,0],[5.2,0],[8.4,0]],"id":35784172}],"con":true,"img":false}]}
{"op":"mcm","clk":"5305909467","pt":1646084424376,"mc":[{"id":"1.195395432","rc":[{"atb":[[2.3,46.47],[2.2,100.68],[2.1,109.83]],"id":41729332},{"atl":[[5.6,2.61],[7.2,1.93],[18,2.82],[9.2,2.92],[13,2]],"id":41729332},{"atb":[[1.85,142.14],[1.9,134.24],[1.95,63.58]],"id":27453791},{"atl":[[5.6,2.61],[7.2,3.87],[4.6,3.33],[9.2,2.92],[13,4]],"id":27453791},{"atb":[[2,60.4],[1.9,134.24],[1.95,127.17]],"id":35784172},{"atl":[[5.1,2.92],[6.2,2.31],[10.5,2.52],[8.2,3.33],[15.5,3.31]],"id":35784172}],"con":true,"img":false}]}
{"op":"mcm","clk":"5305912238","pt":1646084481986,"mc":[{"id":"1.195395432","rc":[{"atb":[[1.8,0],[1.85,0],[1.9,0]],"id":39296632},{"atl":[[4,0],[8,0],[5,0],[10,0],[6,0]],"id":39296632},{"spn":1.49,"spf":"NaN","id":41375435},{"spn":3.95,"spf":"NaN","id":41729332},{"spn":1.71,"spf":"NaN","id":41375430},{"atb":[[1.85,0],[1.9,0],[1.95,0]],"id":27453791},{"atl":[[5.6,0],[7.2,0],[4.6,0],[9.2,0],[13,0]],"id":27453791},{"atb":[[2,0],[1.9,0],[1.95,0]],"id":35784172},{"atl":[[5.1,0],[6.2,0],[10.5,0],[8.2,0],[15.5,0]],"id":35784172},{"spn":9.9,"spf":"NaN","id":41375426}],"con":true,"img":false}]}
{"op":"mcm","clk":"5305912505","pt":1646084488469,"mc":[{"id":"1.195395432","rc":[{"atb":[[1.85,142.14],[1.9,134.24],[1.95,63.58]],"id":39296632},{"atl":[[5.6,2.61],[7.2,3.87],[4.6,3.33],[9.2,2.92],[13,4]],"id":39296632},{"atb":[[1.85,142.14],[1.9,134.24],[1.95,63.58]],"id":27453791},{"atl":[[5.6,2.61],[7.2,3.87],[4.6,3.33],[9.2,2.92],[13,4]],"id":27453791},{"atb":[[2.06,113.98],[2.26,47.94],[2.16,104.15]],"id":35784172},{"atl":[[5.6,2.61],[7.2,1.93],[18,2.82],[9.2,2.92],[13,2]],"id":35784172}],"con":true,"img":false}]}
{"op":"mcm","clk":"5305990515","pt":1646086602699,"mc":[{"id":"1.195395432","marketDefinition":{"bspMarket":true,"turnInPlayEnabled":false,"persistenceEnabled":false,"marketBaseRate":7.0,"eventId":"31270458","eventTypeId":"4339","numberOfWinners":3,"bettingType":"ODDS","marketType":"PLACE","marketTime":"2022-03-01T03:57:00.000Z","suspendTime":"2022-03-01T03:57:00.000Z","bspReconciled":false,"complete":true,"inPlay":false,"crossMatching":false,"runnersVoidable":false,"numberOfActiveRunners":8,"betDelay":0,"status":"OPEN","runners":[{"status":"ACTIVE","sortPriority":1,"id":39296632,"name":"1. Evolution Girl"},{"status":"ACTIVE","sortPriority":2,"id":38124326,"name":"2. Nanny In Town"},{"status":"ACTIVE","sortPriority":3,"id":41729332,"name":"3. Highland Wonder"},{"status":"ACTIVE","sortPriority":4,"id":27453791,"name":"4. Headwall"},{"status":"ACTIVE","sortPriority":5,"id":41375430,"name":"6. Just Posh"},{"status":"ACTIVE","sortPriority":6,"id":41375435,"name":"7. Rojo Diamond"},{"status":"ACTIVE","sortPriority":7,"id":35784172,"name":"8. Buckle Up Kenzie"},{"status":"ACTIVE","sortPriority":8,"id":41375426,"name":"9. Wynburn Rebel"}],"regulators":["MR_INT"],"venue":"Devonport","countryCode":"AU","discountAllowed":true,"timezone":"Australia/Sydney","openDate":"2022-03-01T02:00:00.000Z","version":4380714794,"name":"To Be Placed","eventName":"Devonport (AUS) 1st Mar"},"rc":[{"atb":[[1.85,142.11],[1.9,134.22],[1.95,63.57]],"id":39296632},{"atl":[[5.6,2.61],[7.2,3.87],[4.6,3.33],[9.2,2.92],[13,4]],"id":39296632},{"spn":3.27,"spf":"NaN","id":39296632},{"atb":[[1.01,30199.7]],"id":41375435},{"atl":[[2.36,17.67],[2.56,15.4],[1.98,12.25],[2.16,10.35],[2.76,27.3]],"id":41375435},{"spn":1.49,"spf":"NaN","id":41375435},{"atb":[[2.3,46.46],[2.2,100.66],[2.1,109.81]],"id":41729332},{"atl":[[5.6,2.61],[7.2,1.93],[18,2.82],[9.2,2.92],[13,2]],"id":41729332},{"spn":3.95,"spf":"NaN","id":41729332},{"atb":[[1.12,1006.65],[1.07,1725.69],[1.17,355.29]],"id":41375430},{"atl":[[2.86,12.91],[2.46,8.23],[2.66,14.47],[3.15,22.35],[2.26,9.53]],"id":41375430},{"spn":1.71,"spf":"NaN","id":41375430},{"atb":[[1.85,142.11],[1.9,134.22],[1.95,63.57]],"id":27453791},{"atl":[[5.6,2.61],[7.2,3.87],[4.6,3.33],[9.2,2.92],[13,4]],"id":27453791},{"spn":3.27,"spf":"NaN","id":27453791},{"atb":[[5.5,26.84],[6,24.15],[7,10.06]],"id":38124326},{"atl":[[290,0.16],[95,0.25],[190,0.12],[48,0.25],[29,0.42]],"id":38124326},{"spn":18.0,"spf":"NaN","id":38124326},{"atb":[[2.06,113.96],[2.26,47.93],[2.16,104.13]],"id":35784172},{"atl":[[5.6,2.61],[7.2,1.93],[18,2.82],[9.2,2.92],[13,2]],"id":35784172},{"spn":3.93,"spf":"NaN","id":35784172},{"atb":[[4.3,18.3],[3.9,41.65],[3.65,45.58]],"id":41375426},{"atl":[[32,0.77],[21,0.6],[55,0.44],[110,0.43],[15.5,0.82]],"id":41375426},{"spn":9.9,"spf":"NaN","id":41375426}],"con":true,"img":true}]}
{"op":"mcm","clk":"5306404684","pt":1646097402651,"mc":[{"id":"1.195395432","marketDefinition":{"bspMarket":true,"turnInPlayEnabled":false,"persistenceEnabled":false,"marketBaseRate":7.0,"eventId":"31270458","eventTypeId":"4339","numberOfWinners":3,"bettingType":"ODDS","marketType":"PLACE","marketTime":"2022-03-01T03:57:00.000Z","suspendTime":"2022-03-01T03:57:00.000Z","bspReconciled":false,"complete":true,"inPlay":false,"crossMatching":false,"runnersVoidable":false,"numberOfActiveRunners":8,"betDelay":0,"status":"OPEN","runners":[{"status":"ACTIVE","sortPriority":1,"id":39296632,"name":"1. Evolution Girl"},{"status":"ACTIVE","sortPriority":2,"id":38124326,"name":"2. Nanny In Town"},{"status":"ACTIVE","sortPriority":3,"id":41729332,"name":"3. Highland Wonder"},{"status":"ACTIVE","sortPriority":4,"id":27453791,"name":"4. Headwall"},{"status":"ACTIVE","sortPriority":5,"id":41375430,"name":"6. Just Posh"},{"status":"ACTIVE","sortPriority":6,"id":41375435,"name":"7. Rojo Diamond"},{"status":"ACTIVE","sortPriority":7,"id":35784172,"name":"8. Buckle Up Kenzie"},{"status":"ACTIVE","sortPriority":8,"id":41375426,"name":"9. Wynburn Rebel"}],"regulators":["MR_INT"],"venue":"Devonport","countryCode":"AU","discountAllowed":true,"timezone":"Australia/Sydney","openDate":"2022-03-01T02:00:00.000Z","version":4380714794,"name":"To Be Placed","eventName":"Devonport (AUS) 1st Mar"},"rc":[{"atb":[[1.85,142.02],[1.9,134.13],[1.95,63.53]],"id":39296632},{"atl":[[5.6,2.61],[7.2,3.87],[4.6,3.33],[9.2,2.92],[13,4]],"id":39296632},{"spn":3.27,"spf":"NaN","id":39296632},{"atb":[[1.01,30180.1]],"id":41375435},{"atl":[[2.36,17.65],[2.56,15.39],[1.98,12.25],[2.16,10.35],[2.76,27.28]],"id":41375435},{"spn":1.49,"spf":"NaN","id":41375435},{"atb":[[2.3,46.43],[2.2,100.6],[2.1,109.74]],"id":41729332},{"atl":[[5.6,2.61],[7.2,1.93],[18,2.82],[9.2,2.92],[13,2]],"id":41729332},{"spn":3.95,"spf":"NaN","id":41729332},{"atb":[[1.12,1006],[1.07,1724.57],[1.17,355.05]],"id":41375430},{"atl":[[2.86,12.91],[2.46,8.22],[2.66,14.46],[3.15,22.33],[2.26,9.52]],"id":41375430},{"spn":1.71,"spf":"NaN","id":41375430},{"atb":[[1.85,142.02],[1.9,134.13],[1.95,63.53]],"id":27453791},{"atl":[[5.6,2.61],[7.2,3.87],[4.6,3.33],[9.2,2.92],[13,4]],"id":27453791},{"spn":3.27,"spf":"NaN","id":27453791},{"atb":[[5.5,26.82],[6,24.14],[7,10.06]],"id":38124326},{"atl":[[290,0.16],[95,0.25],[190,0.12],[48,0.25],[29,0.42]],"id":38124326},{"spn":18.0,"spf":"NaN","id":38124326},{"atb":[[2.06,113.88],[2.26,47.9],[2.16,104.06]],"id":35784172},{"atl":[[5.6,2.61],[7.2,1.93],[18,2.82],[9.2,2.92],[13,2]],"id":35784172},{"spn":3.93,"spf":"NaN","id":35784172},{"atb":[[4.3,18.29],[3.9,41.63],[3.65,45.55]],"id":41375426},{"atl":[[32,0.77],[21,0.6],[55,0.44],[110,0.43],[15.5,0.82]],"id":41375426},{"spn":9.9,"spf":"NaN","id":41375426}],"con":true,"img":true}]}
{"op":"mcm","clk":"5306480845","pt":1646099241891,"mc":[{"id":"1.195395432","rc":[{"atb":[[1.85,0],[1.9,0],[1.95,0]],"id":39296632},{"atl":[[5.6,0],[7.2,0],[4.6,0],[9.2,0],[13,0]],"id":39296632},{"atb":[[1.01,30180.1]],"id":41375435},{"atl":[[2.36,17.65],[2.56,15.39],[1.98,12.25],[2.16,10.35],[2.76,27.28]],"id":41375435},{"atb":[[2.3,0],[2.2,0],[2.1,0]],"id":41729332},{"atl":[[5.6,0],[7.2,0],[18,0],[9.2,0],[13,0]],"id":41729332},{"spn":"NaN","spf":"NaN","id":41729332},{"atb":[[1.12,0],[1.07,0],[1.17,0]],"id":41375430},{"atl":[[2.86,0],[2.46,0],[2.66,0],[3.15,0],[2.26,0]],"id":41375430},{"spn":"NaN","spf":"NaN","id":41375430},{"atb":[[1.85,0],[1.9,0],[1.95,0]],"id":27453791},{"atl":[[5.6,0],[7.2,0],[4.6,0],[9.2,0],[13,0]],"id":27453791},{"atb":[[5.5,0],[6,0],[7,0]],"id":38124326},{"atl":[[290,0],[95,0],[190,0],[48,0],[29,0]],"id":38124326},{"spn":"NaN","spf":"NaN","id":38124326},{"atb":[[2.06,0],[2.26,0],[2.16,0]],"id":35784172},{"atl":[[5.6,0],[7.2,0],[18,0],[9.2,0],[13,0]],"id":35784172},{"atb":[[4.3,0],[3.9,0],[3.65,0]],"id":41375426},{"atl":[[32,0],[21,0],[55,0],[110,0],[15.5,0]],"id":41375426},{"spn":"NaN","spf":"NaN","id":41375426}],"con":true,"img":false}]}
{"op":"mcm","clk":"5306481149","pt":1646099248573,"mc":[{"id":"1.195395432","rc":[{"atb":[[1.8,150.9],[1.85,71],[1.75,160.96]],"id":39296632},{"atl":[[4.5,3.42],[9,6],[5.5,5.33],[7,4],[3.75,4.36]],"id":39296632},{"atb":[[2.4,86.22],[2.5,80.48],[2.6,37.72]],"id":41729332},{"atl":[[6.2,2.3],[10.5,2.52],[21,2.4],[8.2,1.66],[15.5,1.65]],"id":41729332},{"atb":[[1.15,402.4],[1.1,1207.2],[1.05,2414.4]],"id":41375430},{"atl":[[2.82,13.19],[2.22,9.84],[2.42,8.45],[2.62,14.82],[3.05,23.43]],"id":41375430},{"atb":[[1.8,75.45],[1.7,172.45],[1.75,160.96]],"id":27453791},{"atl":[[3.6,4.61],[6.4,4.44],[5.2,5.71],[4.2,3.75],[8.4,6.49]],"id":27453791},{"atb":[[8,17.24],[9,7.54],[7,20.12]],"id":38124326},{"atl":[[300,0.08],[50,0.24],[100,0.11],[200,0.11],[400,0.11]],"id":38124326},{"atb":[[2,120.72],[2.2,50.3],[2.1,109.74]],"id":35784172},{"atl":[[17.5,2.9],[9,3],[5.5,2.66],[12.5,2.08],[7,2]],"id":35784172},{"atb":[[3.45,49.27],[3.95,20.46],[3.7,44.71]],"id":41375426},{"atl":[[18.5,0.68],[85,0.57],[44,0.55],[13.5,0.96],[27,0.92]],"id":41375426}],"con":true,"img":false}]}
{"op":"mcm","clk":"5306548890","pt":1646100679247,"mc":[{"id":"1.195395432","rc":[{"atb":[[1.8,150.96],[1.85,71.04],[1.75,161.03]],"id":39296632},{"atl":[[4.5,3.43],[9,6],[5.5,5.34],[7,4],[3.75,4.36]],"id":39296632},{"spn":2.8,"spf":"NaN","id":39296632},{"atb":[[1.01,30193.17]],"id":41375435},{"spl":[[1.01,5.41]],"id":41375435},{"atl":[[2.36,17.66],[2.56,15.39],[1.98,12.25],[2.16,10.35],[2.76,27.29]],"id":41375435},{"spn":1.01,"spf":1.0,"id":41375435},{"atb":[[2.4,86.26],[2.5,80.51],[2.6,37.74]],"id":41729332},{"atl":[[6.2,2.31],[10.5,2.52],[21,2.4],[8.2,1.66],[15.5,1.65]],"id":41729332},{"spn":4.4,"spf":"NaN","id":41729332},{"atb":[[1.15,402.57],[1.1,1207.72],[1.05,2415.45]],"id":41375430},{"atl":[[2.82,13.2],[2.22,9.84],[2.42,8.45],[2.62,14.83],[3.05,23.44]],"id":41375430},{"spn":1.68,"spf":"NaN","id":41375430},{"atb":[[1.8,75.48],[1.7,172.53],[1.75,161.03]],"id":27453791},{"atl":[[3.6,4.62],[6.4,4.44],[5.2,5.71],[4.2,3.75],[8.4,6.49]],"id":27453791},{"spn":2.7,"spf":"NaN","id":27453791},{"atb":[[8,17.25],[9,7.54],[7,20.12]],"id":38124326},{"atl":[[50,0.24]],"id":38124326},{"spn":29.5,"spf":"NaN","id":38124326},{"atb":[[2,120.77],[2.2,50.32],[2.1,109.79]],"id":35784172},{"atl":[[17.5,2.91],[9,3],[5.5,2.66],[12.5,2.08],[7,2]],"id":35784172},{"spn":3.85,"spf":"NaN","id":35784172},{"atb":[[3.45,49.29],[3.95,20.46],[3.7,44.73]],"id":41375426},{"atl":[[18.5,0.68],[85,0.57],[44,0.55],[13.5,0.96],[27,0.92]],"id":41375426},{"spn":8.72,"spf":"NaN","id":41375426}],"con":true,"img":false}]}
{"op":"mcm","clk":"5306567779","pt":1646101083239,"mc":[{"id":"1.195395432","marketDefinition":{"bspMarket":true,"turnInPlayEnabled":false,"persistenceEnabled":false,"marketBaseRate":7.0,"eventId":"31270458","eventTypeId":"4339","numberOfWinners":3,"bettingType":"ODDS","marketType":"PLACE","marketTime":"2022-03-01T04:22:00.000Z","suspendTime":"2022-03-01T04:22:00.000Z","bspReconciled":false,"complete":true,"inPlay":false,"crossMatching":false,"runnersVoidable":false,"numberOfActiveRunners":8,"betDelay":0,"status":"OPEN","runners":[{"status":"ACTIVE","sortPriority":1,"id":39296632,"name":"1. Evolution Girl"},{"status":"ACTIVE","sortPriority":2,"id":38124326,"name":"2. Nanny In Town"},{"status":"ACTIVE","sortPriority":3,"id":41729332,"name":"3. Highland Wonder"},{"status":"ACTIVE","sortPriority":4,"id":27453791,"name":"4. Headwall"},{"status":"ACTIVE","sortPriority":5,"id":41375430,"name":"6. Just Posh"},{"status":"ACTIVE","sortPriority":6,"id":41375435,"name":"7. Rojo Diamond"},{"status":"ACTIVE","sortPriority":7,"id":35784172,"name":"8. Buckle Up Kenzie"},{"status":"ACTIVE","sortPriority":8,"id":41375426,"name":"9. Wynburn Rebel"}],"regulators":["MR_INT"],"venue":"Devonport","countryCode":"AU","discountAllowed":true,"timezone":"Australia/Sydney","openDate":"2022-03-01T02:00:00.000Z","version":4381058170,"name":"To Be Placed","eventName":"Devonport (AUS) 1st Mar"},"rc":[],"con":true,"img":false}]}
{"op":"mcm","clk":"5306630296","pt":1646102422976,"mc":[{"id":"1.195395432","rc":[{"atb":[[2.4,0],[2.5,0],[2.6,0]],"id":41729332},{"atl":[[6.2,0],[10.5,0],[21,0],[8.2,0],[15.5,0]],"id":41729332},{"spn":"NaN","spf":"NaN","id":41729332},{"atb":[[1.8,0],[1.7,0],[1.75,0]],"id":27453791},{"atl":[[3.6,0],[6.4,0],[5.2,0],[4.2,0],[8.4,0]],"id":27453791},{"spn":"NaN","spf":"NaN","id":27453791}],"con":true,"img":false}]}
{"op":"mcm","clk":"5306631047","pt":1646102436299,"mc":[{"id":"1.195395432","rc":[{"atb":[[2.36,44.4],[2.26,95.84],[2.16,104.11]],"id":41729332},{"atl":[[18.5,2.74],[7.4,1.87],[5.7,2.55],[13.5,1.92],[9.4,2.86]],"id":41729332},{"atb":[[1.98,61.62],[1.88,137.24],[1.93,129.86]],"id":27453791},{"atl":[[4.9,3.07],[9.8,2.73],[7.8,3.53],[5.9,2.45],[14.5,3.56]],"id":27453791}],"con":true,"img":false}]}
{"op":"mcm","clk":"5306653013","pt":1646102802685,"mc":[{"id":"1.195395432","marketDefinition":{"bspMarket":true,"turnInPlayEnabled":false,"persistenceEnabled":false,"marketBaseRate":7.0,"eventId":"31270458","eventTypeId":"4339","numberOfWinners":3,"bettingType":"ODDS","marketType":"PLACE","marketTime":"2022-03-01T04:22:00.000Z","suspendTime":"2022-03-01T04:22:00.000Z","bspReconciled":false,"complete":true,"inPlay":false,"crossMatching":false,"runnersVoidable":false,"numberOfActiveRunners":8,"betDelay":0,"status":"OPEN","runners":[{"status":"ACTIVE","sortPriority":1,"id":39296632,"name":"1. Evolution Girl"},{"status":"ACTIVE","sortPriority":2,"id":38124326,"name":"2. Nanny In Town"},{"status":"ACTIVE","sortPriority":3,"id":41729332,"name":"3. Highland Wonder"},{"status":"ACTIVE","sortPriority":4,"id":27453791,"name":"4. Headwall"},{"status":"ACTIVE","sortPriority":5,"id":41375430,"name":"6. Just Posh"},{"status":"ACTIVE","sortPriority":6,"id":41375435,"name":"7. Rojo Diamond"},{"status":"ACTIVE","sortPriority":7,"id":35784172,"name":"8. Buckle Up Kenzie"},{"status":"ACTIVE","sortPriority":8,"id":41375426,"name":"9. Wynburn Rebel"}],"regulators":["MR_INT"],"venue":"Devonport","countryCode":"AU","discountAllowed":true,"timezone":"Australia/Sydney","openDate":"2022-03-01T02:00:00.000Z","version":4381058170,"name":"To Be Placed","eventName":"Devonport (AUS) 1st Mar"},"rc":[{"atb":[[1.8,150.96],[1.85,71.04],[1.75,161.03]],"id":39296632},{"atl":[[4.5,3.43],[9,6],[5.5,5.34],[7,4],[3.75,4.36]],"id":39296632},{"spn":2.8,"spf":"NaN","id":39296632},{"atb":[[1.01,30193.17]],"id":41375435},{"spl":[[1.01,5.41]],"id":41375435},{"atl":[[2.36,17.66],[2.56,15.39],[1.98,12.25],[2.16,10.35],[2.76,27.29]],"id":41375435},{"spn":1.01,"spf":1.0,"id":41375435},{"atb":[[2.36,44.4],[2.26,95.84],[2.16,104.11]],"id":41729332},{"atl":[[18.5,2.74],[7.4,1.87],[5.7,2.55],[13.5,1.92],[9.4,2.86]],"id":41729332},{"spn":4.03,"spf":"NaN","id":41729332},{"atb":[[1.15,402.57],[1.1,1207.72],[1.05,2415.45]],"id":41375430},{"atl":[[2.82,13.2],[2.22,9.84],[2.42,8.45],[2.62,14.83],[3.05,23.44]],"id":41375430},{"spn":1.68,"spf":"NaN","id":41375430},{"atb":[[1.98,61.62],[1.88,137.24],[1.93,129.86]],"id":27453791},{"atl":[[4.9,3.07],[9.8,2.73],[7.8,3.53],[5.9,2.45],[14.5,3.56]],"id":27453791},{"spn":3.44,"spf":"NaN","id":27453791},{"atb":[[8,17.25],[9,7.54],[7,20.12]],"id":38124326},{"atl":[[300,0.08],[50,0.24],[100,0.11],[200,0.11],[400,0.11]],"id":38124326},{"spn":29.5,"spf":"NaN","id":38124326},{"atb":[[2,120.77],[2.2,50.32],[2.1,109.79]],"id":35784172},{"atl":[[17.5,2.91],[9,3],[5.5,2.66],[12.5,2.08],[7,2]],"id":35784172},{"spn":3.85,"spf":"NaN","id":35784172},{"atb":[[3.45,49.29],[3.95,20.46],[3.7,44.73]],"id":41375426},{"atl":[[18.5,0.68],[85,0.57],[44,0.55],[13.5,0.96],[27,0.92]],"id":41375426},{"spn":8.72,"spf":"NaN","id":41375426}],"con":true,"img":true}]}
{"op":"mcm","clk":"5306668458","pt":1646103139885,"mc":[{"id":"1.195395432","rc":[{"atb":[[1.62,63.7],[1.76,56.95]],"id":39296632},{"atl":[[6.2,6.81],[5.5,14.96]],"id":39296632},{"atb":[[1.07,455.12],[1.05,768.35]],"id":41375435},{"atl":[[1.85,45.19],[1.7,43.28]],"id":41375435},{"spn":1.07,"spf":1.0,"id":41375435},{"atb":[[2.3,33.29],[2.06,35.47]],"id":41729332},{"atl":[[8.6,5.69],[9.8,4.27]],"id":41729332},{"spn":4.03,"spf":"NaN","id":41729332},{"atb":[[1.18,229.96],[1.22,196.76]],"id":41375430},{"atl":[[2.32,32.79],[2.58,25.97]],"id":41375430},{"spn":1.72,"spf":"NaN","id":41375430},{"atb":[[1.92,47.05],[1.75,57.35]],"id":27453791},{"atl":[[7.2,7.03],[6.4,8.01]],"id":27453791},{"spn":3.44,"spf":"NaN","id":27453791},{"atb":[[8,23.44],[6.8,6.79]],"id":38124326},{"atl":[[65,2.7],[70,2.7]],"id":38124326},{"atb":[[1.99,43.72],[1.81,51.94]],"id":35784172},{"atl":[[6.8,7.46],[7.6,6.49]],"id":35784172},{"atb":[[3.95,35.14],[3.4,18.39]],"id":41375426},{"atl":[[21,2.7],[22,2.7]],"id":41375426}],"con":true,"img":false}]}
{"op":"mcm","clk":"5306669155","pt":1646103155392,"mc":[{"id":"1.195395432","rc":[{"atb":[[1.07,104.62]],"id":41375435},{"atb":[[1.22,91.76]],"id":41375430}],"con":true,"img":false}]}
{"op":"mcm","clk":"5306670254","pt":1646103182375,"mc":[{"id":"1.195395432","rc":[{"atb":[[8,17.25]],"id":38124326}],"con":true,"img":false}]}
{"op":"mcm","clk":"5306670257","pt":1646103182424,"mc":[{"id":"1.195395432","rc":[{"atb":[[8.2,6.18]],"id":38124326}],"con":true,"img":false}]}
{"op":"mcm","clk":"5306670592","pt":1646103191282,"mc":[{"id":"1.195395432","rc":[{"atb":[[1.76,0]],"id":39296632},{"atb":[[2.3,0]],"id":41729332},{"atb":[[1.92,0]],"id":27453791},{"atb":[[1.99,0]],"id":35784172}],"con":true,"img":false}]}
{"op":"mcm","clk":"5306670596","pt":1646103191385,"mc":[{"id":"1.195395432","rc":[{"atb":[[1.86,56.95]],"id":39296632},{"atb":[[2.38,33.29]],"id":41729332},{"atb":[[1.99,47.05]],"id":27453791},{"atb":[[2.22,43.72]],"id":35784172}],"con":true,"img":false}]}
{"op":"mcm","clk":"5306671214","pt":1646103206893,"mc":[{"id":"1.195395432","rc":[{"spn":2.8,"spf":"NaN","id":39296632},{"atb":[[2.28,29.38]],"id":41729332},{"spn":4.04,"spf":"NaN","id":41729332},{"spn":3.44,"spf":"NaN","id":27453791},{"spn":3.86,"spf":"NaN","id":35784172}],"con":true,"img":false}]}
{"op":"mcm","clk":"5306671218","pt":1646103206995,"mc":[{"id":"1.195395432","rc":[{"atb":[[2.06,0]],"id":41729332},{"atb":[[1.75,0]],"id":27453791},{"atb":[[6.8,0]],"id":38124326},{"atb":[[3.4,0]],"id":41375426}],"con":true,"img":false}]}
{"op":"mcm","clk":"5306671221","pt":1646103207097,"mc":[{"id":"1.195395432","rc":[{"atb":[[1.89,57.35]],"id":27453791},{"atb":[[7.2,6.79]],"id":38124326},{"atb":[[3.75,18.39]],"id":41375426}],"con":true,"img":false}]}
{"op":"mcm","clk":"5306672718","pt":1646103244551,"mc":[{"id":"1.195395432","rc":[{"atb":[[3.95,20.46]],"id":41375426}],"con":true,"img":false}]}
{"op":"mcm","clk":"5306672721","pt":1646103244654,"mc":[{"id":"1.195395432","rc":[{"atb":[[4,14.67]],"id":41375426}],"con":true,"img":false}]}
{"op":"mcm","clk":"5306675394","pt":1646103311268,"mc":[{"id":"1.195395432","marketDefinition":{"bspMarket":true,"turnInPlayEnabled":false,"persistenceEnabled":false,"marketBaseRate":7.0,"eventId":"31270458","eventTypeId":"4339","numberOfWinners":3,"bettingType":"ODDS","marketType":"PLACE","marketTime":"2022-03-01T05:02:00.000Z","suspendTime":"2022-03-01T05:02:00.000Z","bspReconciled":false,"complete":true,"inPlay":false,"crossMatching":false,"runnersVoidable":false,"numberOfActiveRunners":8,"betDelay":0,"status":"OPEN","runners":[{"status":"ACTIVE","sortPriority":1,"id":39296632,"name":"1. Evolution Girl"},{"status":"ACTIVE","sortPriority":2,"id":38124326,"name":"2. Nanny In Town"},{"status":"ACTIVE","sortPriority":3,"id":41729332,"name":"3. Highland Wonder"},{"status":"ACTIVE","sortPriority":4,"id":27453791,"name":"4. Headwall"},{"status":"ACTIVE","sortPriority":5,"id":41375430,"name":"6. Just Posh"},{"status":"ACTIVE","sortPriority":6,"id":41375435,"name":"7. Rojo Diamond"},{"status":"ACTIVE","sortPriority":7,"id":35784172,"name":"8. Buckle Up Kenzie"},{"status":"ACTIVE","sortPriority":8,"id":41375426,"name":"9. Wynburn Rebel"}],"regulators":["MR_INT"],"venue":"Devonport","countryCode":"AU","discountAllowed":true,"timezone":"Australia/Sydney","openDate":"2022-03-01T02:00:00.000Z","version":4381083953,"name":"To Be Placed","eventName":"Devonport (AUS) 1st Mar"},"rc":[],"con":true,"img":false}]}
{"op":"mcm","clk":"5306778072","pt":1646106015625,"mc":[{"id":"1.195395432","rc":[{"atb":[[2.22,0]],"id":35784172},{"spn":3.85,"spf":"NaN","id":35784172},{"spn":8.75,"spf":"NaN","id":41375426}],"con":true,"img":false}]}
{"op":"mcm","clk":"5306778077","pt":1646106015725,"mc":[{"id":"1.195395432","rc":[{"atb":[[2.12,43.72]],"id":35784172}],"con":true,"img":false}]}
{"op":"mcm","clk":"5306778752","pt":1646106032651,"mc":[{"id":"1.195395432","rc":[{"atb":[[1.07,0]],"id":41375435}],"con":true,"img":false}]}
{"op":"mcm","clk":"5306778758","pt":1646106032753,"mc":[{"id":"1.195395432","rc":[{"atb":[[1.08,104.62]],"id":41375435}],"con":true,"img":false}]}
{"op":"mcm","clk":"5306780004","pt":1646106064901,"mc":[{"id":"1.195395432","rc":[{"atb":[[1.06,640.29],[1.05,0]],"id":41375435}],"con":true,"img":false}]}
{"op":"mcm","clk":"5306810826","pt":1646106995151,"mc":[{"id":"1.195395432","rc":[{"atb":[[1.9,108.21]],"id":39296632},{"spn":2.82,"spf":"NaN","id":39296632},{"atb":[[1.05,108.21]],"id":41375435},{"spn":1.08,"spf":1.0,"id":41375435},{"atb":[[1.19,108.21]],"id":41375430},{"atb":[[1.9,108.21]],"id":27453791},{"atb":[[1.9,108.21]],"id":35784172}],"con":true,"img":false}]}
{"op":"mcm","clk":"5306812210","pt":1646107031110,"mc":[{"id":"1.195395432","rc":[{"atb":[[1.86,0]],"id":39296632}],"con":true,"img":false}]}
{"op":"mcm","clk":"5306812215","pt":1646107031213,"mc":[{"id":"1.195395432","rc":[{"atb":[[1.91,56.95]],"id":39296632}],"con":true,"img":false}]}
{"op":"mcm","clk":"5306813070","pt":1646107054835,"mc":[{"id":"1.195395432","rc":[{"atb":[[1.18,0]],"id":41375430},{"atb":[[1.89,0],[1.91,47.07]],"id":27453791}],"con":true,"img":false}]}
{"op":"mcm","clk":"5306813075","pt":1646107054938,"mc":[{"id":"1.195395432","rc":[{"atb":[[1.2,229.96]],"id":41375430}],"con":true,"img":false}]}
{"op":"mcm","clk":"5306813175","pt":1646107058052,"mc":[{"id":"1.195395432","rc":[{"spn":2.83,"spf":"NaN","id":39296632},{"atb":[[1.81,0]],"id":35784172}],"con":true,"img":false}]}
{"op":"mcm","clk":"5306813179","pt":1646107058153,"mc":[{"id":"1.195395432","rc":[{"atb":[[1.91,51.94]],"id":35784172}],"con":true,"img":false}]}
{"op":"mcm","clk":"5306820122","pt":1646107229923,"mc":[{"id":"1.195395432","marketDefinition":{"bspMarket":true,"turnInPlayEnabled":false,"persistenceEnabled":false,"marketBaseRate":7.0,"eventId":"31270458","eventTypeId":"4339","numberOfWinners":3,"bettingType":"ODDS","marketType":"PLACE","marketTime":"2022-03-01T05:50:00.000Z","suspendTime":"2022-03-01T05:50:00.000Z","bspReconciled":false,"complete":true,"inPlay":false,"crossMatching":false,"runnersVoidable":false,"numberOfActiveRunners":8,"betDelay":0,"status":"OPEN","runners":[{"status":"ACTIVE","sortPriority":1,"id":39296632,"name":"1. Evolution Girl"},{"status":"ACTIVE","sortPriority":2,"id":38124326,"name":"2. Nanny In Town"},{"status":"ACTIVE","sortPriority":3,"id":41729332,"name":"3. Highland Wonder"},{"status":"ACTIVE","sortPriority":4,"id":27453791,"name":"4. Headwall"},{"status":"ACTIVE","sortPriority":5,"id":41375430,"name":"6. Just Posh"},{"status":"ACTIVE","sortPriority":6,"id":41375435,"name":"7. Rojo Diamond"},{"status":"ACTIVE","sortPriority":7,"id":35784172,"name":"8. Buckle Up Kenzie"},{"status":"ACTIVE","sortPriority":8,"id":41375426,"name":"9. Wynburn Rebel"}],"regulators":["MR_INT"],"venue":"Devonport","countryCode":"AU","discountAllowed":true,"timezone":"Australia/Sydney","openDate":"2022-03-01T02:00:00.000Z","version":4381118363,"name":"To Be Placed","eventName":"Devonport (AUS) 1st Mar"},"rc":[],"con":true,"img":false}]}
{"op":"mcm","clk":"5306856249","pt":1646108202673,"mc":[{"id":"1.195395432","marketDefinition":{"bspMarket":true,"turnInPlayEnabled":false,"persistenceEnabled":false,"marketBaseRate":7.0,"eventId":"31270458","eventTypeId":"4339","numberOfWinners":3,"bettingType":"ODDS","marketType":"PLACE","marketTime":"2022-03-01T05:50:00.000Z","suspendTime":"2022-03-01T05:50:00.000Z","bspReconciled":false,"complete":true,"inPlay":false,"crossMatching":false,"runnersVoidable":false,"numberOfActiveRunners":8,"betDelay":0,"status":"OPEN","runners":[{"status":"ACTIVE","sortPriority":1,"id":39296632,"name":"1. Evolution Girl"},{"status":"ACTIVE","sortPriority":2,"id":38124326,"name":"2. Nanny In Town"},{"status":"ACTIVE","sortPriority":3,"id":41729332,"name":"3. Highland Wonder"},{"status":"ACTIVE","sortPriority":4,"id":27453791,"name":"4. Headwall"},{"status":"ACTIVE","sortPriority":5,"id":41375430,"name":"6. Just Posh"},{"status":"ACTIVE","sortPriority":6,"id":41375435,"name":"7. Rojo Diamond"},{"status":"ACTIVE","sortPriority":7,"id":35784172,"name":"8. Buckle Up Kenzie"},{"status":"ACTIVE","sortPriority":8,"id":41375426,"name":"9. Wynburn Rebel"}],"regulators":["MR_INT"],"venue":"Devonport","countryCode":"AU","discountAllowed":true,"timezone":"Australia/Sydney","openDate":"2022-03-01T02:00:00.000Z","version":4381118363,"name":"To Be Placed","eventName":"Devonport (AUS) 1st Mar"},"rc":[{"atb":[[1.8,150.87],[1.85,70.99],[1.91,56.92],[1.9,108.15],[1.62,63.67],[1.75,160.93]],"id":39296632},{"atl":[[4.5,3.42],[9,6],[6.2,6.8],[5.5,14.95],[7,4],[3.75,4.36]],"id":39296632},{"spn":2.83,"spf":"NaN","id":39296632},{"atb":[[1.01,30175.21],[1.06,639.91],[1.08,104.56],[1.05,108.15]],"id":41375435},{"spl":[[1.01,5.4]],"id":41375435},{"atl":[[2.36,17.65],[2.56,15.39],[1.98,12.24],[1.85,45.17],[1.7,43.26],[2.16,10.35],[2.76,27.28]],"id":41375435},{"spn":1.08,"spf":1.0,"id":41375435},{"atb":[[2.36,44.37],[2.38,33.27],[2.28,29.36],[2.26,95.79],[2.16,104.05]],"id":41729332},{"atl":[[8.6,5.69],[18.5,2.74],[7.4,1.87],[9.8,4.27],[5.7,2.55],[13.5,1.91],[9.4,2.86]],"id":41729332},{"spn":4.04,"spf":"NaN","id":41729332},{"atb":[[1.2,229.82],[1.15,402.33],[1.19,108.15],[1.22,91.7],[1.1,1207],[1.05,2414.01]],"id":41375430},{"atl":[[2.82,13.19],[2.32,32.77],[2.22,9.84],[2.42,8.45],[2.58,25.95],[2.62,14.82],[3.05,23.42]],"id":41375430},{"spn":1.72,"spf":"NaN","id":41375430},{"atb":[[1.99,47.02],[1.98,61.58],[1.88,137.16],[1.91,47.04],[1.9,108.15],[1.93,129.78]],"id":27453791},{"atl":[[7.2,7.03],[6.4,8],[4.9,3.07],[9.8,2.73],[7.8,3.53],[5.9,2.44],[14.5,3.55]],"id":27453791},{"spn":3.44,"spf":"NaN","id":27453791},{"atb":[[8,17.24],[7.2,6.79],[9,7.54],[8.2,6.18],[7,20.11]],"id":38124326},{"atl":[[65,2.7],[70,2.7],[300,0.08],[50,0.24],[100,0.11],[200,0.11],[400,0.11]],"id":38124326},{"spn":29.5,"spf":"NaN","id":38124326},{"atb":[[2,120.7],[2.12,43.69],[1.91,51.91],[1.9,108.15],[2.2,50.29],[2.1,109.72]],"id":35784172},{"atl":[[17.5,2.9],[9,3],[5.5,2.66],[6.8,7.45],[7.6,6.48],[12.5,2.08],[7,2]],"id":35784172},{"spn":3.85,"spf":"NaN","id":35784172},{"atb":[[4,14.66],[3.45,49.26],[3.95,20.45],[3.7,44.7],[3.75,18.38]],"id":41375426},{"atl":[[18.5,0.68],[21,2.7],[85,0.57],[22,2.7],[44,0.55],[13.5,0.96],[27,0.92]],"id":41375426},{"spn":8.75,"spf":"NaN","id":41375426}],"con":true,"img":true}]}
{"op":"mcm","clk":"5306858509","pt":1646108229189,"mc":[{"id":"1.195395432","rc":[{"atb":[[1.8,150.87],[1.85,70.99],[1.91,56.92],[1.9,108.15],[1.62,63.67],[1.75,160.93]],"id":39296632},{"atl":[[4.5,3.42],[9,6],[6.2,6.8],[5.5,14.95],[7,4],[3.75,4.36]],"id":39296632},{"atb":[[1.01,30175.21],[1.06,639.91],[1.08,104.56],[1.05,108.15]],"id":41375435},{"spl":[[1.01,5.4]],"id":41375435},{"atl":[[2.36,17.65],[2.56,15.39],[1.98,12.24],[1.85,45.17],[1.7,43.26],[2.16,10.35],[2.76,27.28]],"id":41375435},{"atb":[[2.36,44.37],[2.4,1.66],[2.38,33.27],[2.28,29.36],[2.26,95.79],[2.16,104.05]],"id":41729332},{"atl":[[8.6,5.69],[18.5,2.74],[7.4,1.87],[9.8,4.27],[5.7,2.55],[13.5,1.91],[9.4,2.86]],"id":41729332},{"atb":[[1.2,229.82],[1.15,402.33],[1.19,108.15],[1.22,91.7],[1.1,1207],[1.05,2414.01]],"id":41375430},{"atl":[[2.82,13.19],[2.32,32.77],[2.22,9.84],[2.42,8.45],[2.58,25.95],[2.62,14.82],[3.05,23.42]],"id":41375430},{"atb":[[1.99,47.02],[1.98,61.58],[1.88,137.16],[1.91,47.04],[1.9,108.15],[1.93,129.78]],"id":27453791},{"atl":[[7.2,7.03],[6.4,8],[4.9,3.07],[9.8,2.73],[7.8,3.53],[5.9,2.44],[14.5,3.55]],"id":27453791},{"atb":[[8,17.24],[7.2,6.79],[9,7.54],[9.2,1.66],[8.2,6.18],[7,20.11]],"id":38124326},{"atl":[[65,2.7],[70,2.7],[50,0.24]],"id":38124326},{"atb":[[2,120.7],[2.22,1.66],[2.12,43.69],[1.91,51.91],[1.9,108.15],[2.2,50.29],[2.1,109.72]],"id":35784172},{"atl":[[17.5,2.9],[9,3],[5.5,2.66],[6.8,7.45],[7.6,6.48],[12.5,2.08],[7,2]],"id":35784172},{"atb":[[4,14.66],[3.45,49.26],[3.95,20.45],[4.1,1.66],[3.7,44.7],[3.75,18.38]],"id":41375426},{"atl":[[18.5,0.68],[21,2.7],[85,0.57],[22,2.7],[44,0.55],[13.5,0.96],[27,0.92]],"id":41375426}],"con":true,"img":false}]}
{"op":"mcm","clk":"5306859167","pt":1646108247797,"mc":[{"id":"1.195395432","marketDefinition":{"bspMarket":true,"turnInPlayEnabled":false,"persistenceEnabled":false,"marketBaseRate":7.0,"eventId":"31270458","eventTypeId":"4339","numberOfWinners":3,"bettingType":"ODDS","marketType":"PLACE","marketTime":"2022-03-01T05:50:00.000Z","suspendTime":"2022-03-01T05:50:00.000Z","bspReconciled":false,"complete":true,"inPlay":false,"crossMatching":true,"runnersVoidable":false,"numberOfActiveRunners":8,"betDelay":0,"status":"OPEN","runners":[{"status":"ACTIVE","sortPriority":1,"id":39296632,"name":"1. Evolution Girl"},{"status":"ACTIVE","sortPriority":2,"id":38124326,"name":"2. Nanny In Town"},{"status":"ACTIVE","sortPriority":3,"id":41729332,"name":"3. Highland Wonder"},{"status":"ACTIVE","sortPriority":4,"id":27453791,"name":"4. Headwall"},{"status":"ACTIVE","sortPriority":5,"id":41375430,"name":"6. Just Posh"},{"status":"ACTIVE","sortPriority":6,"id":41375435,"name":"7. Rojo Diamond"},{"status":"ACTIVE","sortPriority":7,"id":35784172,"name":"8. Buckle Up Kenzie"},{"status":"ACTIVE","sortPriority":8,"id":41375426,"name":"9. Wynburn Rebel"}],"regulators":["MR_INT"],"venue":"Devonport","countryCode":"AU","discountAllowed":true,"timezone":"Australia/Sydney","openDate":"2022-03-01T02:00:00.000Z","version":4381118363,"name":"To Be Placed","eventName":"Devonport (AUS) 1st Mar"},"rc":[],"con":true,"img":false}]}
{"op":"mcm","clk":"5306884236","pt":1646109167391,"mc":[{"id":"1.195395432","marketDefinition":{"bspMarket":true,"turnInPlayEnabled":false,"persistenceEnabled":false,"marketBaseRate":7.0,"eventId":"31270458","eventTypeId":"4339","numberOfWinners":3,"bettingType":"ODDS","marketType":"PLACE","marketTime":"2022-03-01T06:10:00.000Z","suspendTime":"2022-03-01T06:10:00.000Z","bspReconciled":false,"complete":true,"inPlay":false,"crossMatching":true,"runnersVoidable":false,"numberOfActiveRunners":8,"betDelay":0,"status":"OPEN","runners":[{"status":"ACTIVE","sortPriority":1,"id":39296632,"name":"1. Evolution Girl"},{"status":"ACTIVE","sortPriority":2,"id":38124326,"name":"2. Nanny In Town"},{"status":"ACTIVE","sortPriority":3,"id":41729332,"name":"3. Highland Wonder"},{"status":"ACTIVE","sortPriority":4,"id":27453791,"name":"4. Headwall"},{"status":"ACTIVE","sortPriority":5,"id":41375430,"name":"6. Just Posh"},{"status":"ACTIVE","sortPriority":6,"id":41375435,"name":"7. Rojo Diamond"},{"status":"ACTIVE","sortPriority":7,"id":35784172,"name":"8. Buckle Up Kenzie"},{"status":"ACTIVE","sortPriority":8,"id":41375426,"name":"9. Wynburn Rebel"}],"regulators":["MR_INT"],"venue":"Devonport","countryCode":"AU","discountAllowed":true,"timezone":"Australia/Sydney","openDate":"2022-03-01T02:00:00.000Z","version":4381128798,"name":"17:10TO BE PLACED","eventName":"Devonport (AUS) 1st Mar"},"rc":[],"con":true,"img":false}]}
{"op":"mcm","clk":"5306902942","pt":1646109778596,"mc":[{"id":"1.195395432","rc":[{"atb":[[1.86,35.97]],"id":39296632},{"atb":[[1.09,209.13]],"id":41375435},{"spn":1.09,"spf":1.0,"id":41375435},{"atb":[[2.3,23.8]],"id":41729332},{"spn":4.05,"spf":"NaN","id":41729332},{"atb":[[1.23,134.52]],"id":41375430},{"spn":1.72,"spf":"NaN","id":41375430},{"atb":[[1.94,32.91]],"id":27453791},{"spn":29.6,"spf":"NaN","id":38124326},{"atb":[[2.14,27.14]],"id":35784172},{"spn":3.86,"spf":"NaN","id":35784172},{"spn":8.8,"spf":"NaN","id":41375426}],"con":true,"img":false}]}
{"op":"mcm","clk":"5306903832","pt":1646109813034,"mc":[{"id":"1.195395432","rc":[{"atb":[[1.22,0]],"id":41375430}],"con":true,"img":false}]}
{"op":"mcm","clk":"5306903834","pt":1646109813138,"mc":[{"id":"1.195395432","rc":[{"atb":[[1.24,91.7]],"id":41375430}],"con":true,"img":false}]}
{"op":"mcm","clk":"5306903891","pt":1646109816459,"mc":[{"id":"1.195395432","rc":[{"atb":[[1.23,0]],"id":41375430}],"con":true,"img":false}]}
{"op":"mcm","clk":"5306903909","pt":1646109817274,"mc":[{"id":"1.195395432","rc":[{"atb":[[1.24,0]],"id":41375430}],"con":true,"img":false}]}
{"op":"mcm","clk":"5306903912","pt":1646109817377,"mc":[{"id":"1.195395432","rc":[{"atb":[[1.22,91.7]],"id":41375430}],"con":true,"img":false}]}
{"op":"mcm","clk":"5306903959","pt":1646109819946,"mc":[{"id":"1.195395432","rc":[{"atb":[[1.23,134.52]],"id":41375430}],"con":true,"img":false}]}
{"op":"mcm","clk":"5306904509","pt":1646109842596,"mc":[{"id":"1.195395432","rc":[{"atb":[[1.62,0],[1.76,51.94]],"id":39296632}],"con":true,"img":false}]}
{"op":"mcm","clk":"5306904745","pt":1646109853608,"mc":[{"id":"1.195395432","rc":[{"atb":[[1.22,0]],"id":41375430}],"con":true,"img":false}]}
{"op":"mcm","clk":"5306904748","pt":1646109853710,"mc":[{"id":"1.195395432","rc":[{"atb":[[1.24,91.7]],"id":41375430}],"con":true,"img":false}]}
{"op":"mcm","clk":"5306904825","pt":1646109856786,"mc":[{"id":"1.195395432","rc":[{"atb":[[1.23,0]],"id":41375430}],"con":true,"img":false}]}
{"op":"mcm","clk":"5306904833","pt":1646109856992,"mc":[{"id":"1.195395432","rc":[{"atb":[[1.24,0]],"id":41375430}],"con":true,"img":false}]}
{"op":"mcm","clk":"5306904838","pt":1646109857095,"mc":[{"id":"1.195395432","rc":[{"atb":[[1.22,91.7]],"id":41375430}],"con":true,"img":false}]}
{"op":"mcm","clk":"5306904909","pt":1646109860319,"mc":[{"id":"1.195395432","rc":[{"atb":[[1.23,134.52]],"id":41375430}],"con":true,"img":false}]}
{"op":"mcm","clk":"5306905680","pt":1646109894153,"mc":[{"id":"1.195395432","rc":[{"atb":[[1.22,0]],"id":41375430}],"con":true,"img":false}]}
{"op":"mcm","clk":"5306905682","pt":1646109894255,"mc":[{"id":"1.195395432","rc":[{"atb":[[1.24,91.7]],"id":41375430}],"con":true,"img":false}]}
{"op":"mcm","clk":"5306905742","pt":1646109896919,"mc":[{"id":"1.195395432","rc":[{"atb":[[1.23,0]],"id":41375430}],"con":true,"img":false}]}
{"op":"mcm","clk":"5306905753","pt":1646109897334,"mc":[{"id":"1.195395432","rc":[{"atb":[[1.24,0]],"id":41375430}],"con":true,"img":false}]}
{"op":"mcm","clk":"5306905757","pt":1646109897437,"mc":[{"id":"1.195395432","rc":[{"atb":[[1.22,91.7]],"id":41375430}],"con":true,"img":false}]}
{"op":"mcm","clk":"5306905838","pt":1646109900366,"mc":[{"id":"1.195395432","rc":[{"atb":[[1.23,134.52]],"id":41375430}],"con":true,"img":false}]}
{"op":"mcm","clk":"5306906765","pt":1646109933768,"mc":[{"id":"1.195395432","rc":[{"atb":[[1.22,0]],"id":41375430}],"con":true,"img":false}]}
{"op":"mcm","clk":"5306906769","pt":1646109933871,"mc":[{"id":"1.195395432","rc":[{"atb":[[1.24,91.7]],"id":41375430}],"con":true,"img":false}]}
{"op":"mcm","clk":"5306906816","pt":1646109935521,"mc":[{"id":"1.195395432","rc":[{"atb":[[1.23,0]],"id":41375430}],"con":true,"img":false}]}
{"op":"mcm","clk":"5306906851","pt":1646109936806,"mc":[{"id":"1.195395432","rc":[{"atb":[[1.24,0]],"id":41375430}],"con":true,"img":false}]}
{"op":"mcm","clk":"5306906856","pt":1646109936904,"mc":[{"id":"1.195395432","rc":[{"atb":[[1.22,91.7]],"id":41375430}],"con":true,"img":false}]}
{"op":"mcm","clk":"5306906903","pt":1646109939217,"mc":[{"id":"1.195395432","rc":[{"atb":[[1.23,134.52]],"id":41375430}],"con":true,"img":false}]}
{"op":"mcm","clk":"5306907558","pt":1646109972455,"mc":[{"id":"1.195395432","rc":[{"atb":[[1.22,0]],"id":41375430}],"con":true,"img":false}]}
{"op":"mcm","clk":"5306907560","pt":1646109972557,"mc":[{"id":"1.195395432","rc":[{"atb":[[1.24,91.7]],"id":41375430}],"con":true,"img":false}]}
{"op":"mcm","clk":"5306907628","pt":1646109975945,"mc":[{"id":"1.195395432","rc":[{"atb":[[1.23,0]],"id":41375430}],"con":true,"img":false}]}
{"op":"mcm","clk":"5306907654","pt":1646109976870,"mc":[{"id":"1.195395432","rc":[{"atb":[[1.24,0]],"id":41375430}],"con":true,"img":false}]}
{"op":"mcm","clk":"5306907657","pt":1646109976973,"mc":[{"id":"1.195395432","rc":[{"atb":[[1.22,91.7]],"id":41375430}],"con":true,"img":false}]}
{"op":"mcm","clk":"5306907700","pt":1646109979437,"mc":[{"id":"1.195395432","rc":[{"atb":[[1.23,134.52]],"id":41375430}],"con":true,"img":false}]}
{"op":"mcm","clk":"5306908301","pt":1646110011623,"mc":[{"id":"1.195395432","rc":[{"atb":[[1.22,0]],"id":41375430}],"con":true,"img":false}]}
{"op":"mcm","clk":"5306908304","pt":1646110011724,"mc":[{"id":"1.195395432","rc":[{"atb":[[1.24,91.7]],"id":41375430}],"con":true,"img":false}]}
{"op":"mcm","clk":"5306908369","pt":1646110014393,"mc":[{"id":"1.195395432","rc":[{"atb":[[1.23,0]],"id":41375430}],"con":true,"img":false}]}
{"op":"mcm","clk":"5306908398","pt":1646110015719,"mc":[{"id":"1.195395432","rc":[{"atb":[[1.24,0]],"id":41375430}],"con":true,"img":false}]}
{"op":"mcm","clk":"5306908402","pt":1646110015821,"mc":[{"id":"1.195395432","rc":[{"atb":[[1.22,91.7]],"id":41375430}],"con":true,"img":false}]}
{"op":"mcm","clk":"5306908442","pt":1646110017816,"mc":[{"id":"1.195395432","rc":[{"atb":[[1.23,134.52]],"id":41375430}],"con":true,"img":false}]}
{"op":"mcm","clk":"5306908862","pt":1646110032746,"mc":[{"id":"1.195395432","rc":[{"atl":[[85,15]],"id":41375435},{"atl":[[85,5]],"id":41375430}],"con":true,"img":false}]}
{"op":"mcm","clk":"5306909327","pt":1646110050179,"mc":[{"id":"1.195395432","rc":[{"atb":[[1.22,0]],"id":41375430}],"con":true,"img":false}]}
{"op":"mcm","clk":"5306909329","pt":1646110050280,"mc":[{"id":"1.195395432","rc":[{"atb":[[1.24,91.7]],"id":41375430}],"con":true,"img":false}]}
{"op":"mcm","clk":"5306909407","pt":1646110053148,"mc":[{"id":"1.195395432","rc":[{"atb":[[1.23,0]],"id":41375430}],"con":true,"img":false}]}
{"op":"mcm","clk":"5306909434","pt":1646110054067,"mc":[{"id":"1.195395432","rc":[{"atb":[[1.24,0]],"id":41375430}],"con":true,"img":false}]}
{"op":"mcm","clk":"5306909436","pt":1646110054170,"mc":[{"id":"1.195395432","rc":[{"atb":[[1.22,91.7]],"id":41375430}],"con":true,"img":false}]}
{"op":"mcm","clk":"5306909502","pt":1646110056671,"mc":[{"id":"1.195395432","rc":[{"atb":[[1.23,134.52]],"id":41375430}],"con":true,"img":false}]}
{"op":"mcm","clk":"5306910363","pt":1646110090134,"mc":[{"id":"1.195395432","rc":[{"atb":[[1.22,0]],"id":41375430}],"con":true,"img":false}]}
{"op":"mcm","clk":"5306910368","pt":1646110090236,"mc":[{"id":"1.195395432","rc":[{"atb":[[1.24,91.7]],"id":41375430}],"con":true,"img":false}]}
{"op":"mcm","clk":"5306910410","pt":1646110091926,"mc":[{"id":"1.195395432","rc":[{"atb":[[1.23,0]],"id":41375430}],"con":true,"img":false}]}
{"op":"mcm","clk":"5306910452","pt":1646110093714,"mc":[{"id":"1.195395432","rc":[{"atb":[[1.24,0]],"id":41375430}],"con":true,"img":false}]}
{"op":"mcm","clk":"5306910455","pt":1646110093815,"mc":[{"id":"1.195395432","rc":[{"atb":[[1.22,91.7]],"id":41375430}],"con":true,"img":false}]}
{"op":"mcm","clk":"5306910584","pt":1646110095445,"mc":[{"id":"1.195395432","rc":[{"atb":[[1.21,147.34]],"id":41375430}],"con":true,"img":false}]}
{"op":"mcm","clk":"5306913284","pt":1646110154094,"mc":[{"id":"1.195395432","rc":[{"atb":[[1.22,279.89]],"id":41375430},{"spn":1.72,"spf":"NaN","id":41375430}],"con":true,"img":false}]}
{"op":"mcm","clk":"5306913286","pt":1646110154196,"mc":[{"id":"1.195395432","rc":[{"atb":[[1.2,0]],"id":41375430}],"con":true,"img":false}]}
{"op":"mcm","clk":"5306913405","pt":1646110157789,"mc":[{"id":"1.195395432","rc":[{"atb":[[1.21,0]],"id":41375430}],"con":true,"img":false}]}
{"op":"mcm","clk":"5306913456","pt":1646110158919,"mc":[{"id":"1.195395432","rc":[{"atb":[[1.22,91.7]],"id":41375430}],"con":true,"img":false}]}
{"op":"mcm","clk":"5306913461","pt":1646110159021,"mc":[{"id":"1.195395432","rc":[{"atb":[[1.2,188.18]],"id":41375430}],"con":true,"img":false}]}
{"op":"mcm","clk":"5306913522","pt":1646110161222,"mc":[{"id":"1.195395432","rc":[{"atb":[[1.23,134.52]],"id":41375430}],"con":true,"img":false}]}
{"op":"mcm","clk":"5306914580","pt":1646110194166,"mc":[{"id":"1.195395432","rc":[{"atb":[[1.22,0]],"id":41375430}],"con":true,"img":false}]}
{"op":"mcm","clk":"5306914581","pt":1646110194270,"mc":[{"id":"1.195395432","rc":[{"atb":[[1.24,91.7]],"id":41375430}],"con":true,"img":false}]}
{"op":"mcm","clk":"5306914635","pt":1646110196164,"mc":[{"id":"1.195395432","rc":[{"atb":[[1.23,0]],"id":41375430}],"con":true,"img":false}]}
{"op":"mcm","clk":"5306914667","pt":1646110197288,"mc":[{"id":"1.195395432","rc":[{"atb":[[1.24,0]],"id":41375430}],"con":true,"img":false}]}
{"op":"mcm","clk":"5306914676","pt":1646110197392,"mc":[{"id":"1.195395432","rc":[{"atb":[[1.22,91.7]],"id":41375430}],"con":true,"img":false}]}
{"op":"mcm","clk":"5306914773","pt":1646110199851,"mc":[{"id":"1.195395432","rc":[{"atb":[[1.23,134.52]],"id":41375430}],"con":true,"img":false}]}
{"op":"mcm","clk":"5306915836","pt":1646110233100,"mc":[{"id":"1.195395432","rc":[{"atb":[[1.22,0]],"id":41375430},{"spn":1.72,"spf":"NaN","id":41375430}],"con":true,"img":false}]}
{"op":"mcm","clk":"5306915838","pt":1646110233201,"mc":[{"id":"1.195395432","rc":[{"atb":[[1.24,91.7]],"id":41375430}],"con":true,"img":false}]}
{"op":"mcm","clk":"5306915899","pt":1646110235101,"mc":[{"id":"1.195395432","rc":[{"atb":[[1.23,0]],"id":41375430}],"con":true,"img":false}]}
{"op":"mcm","clk":"5306915923","pt":1646110236027,"mc":[{"id":"1.195395432","rc":[{"atb":[[1.24,0]],"id":41375430}],"con":true,"img":false}]}
{"op":"mcm","clk":"5306915924","pt":1646110236129,"mc":[{"id":"1.195395432","rc":[{"atb":[[1.22,91.7]],"id":41375430}],"con":true,"img":false}]}
{"op":"mcm","clk":"5306915988","pt":1646110238644,"mc":[{"id":"1.195395432","rc":[{"atb":[[1.23,134.52]],"id":41375430}],"con":true,"img":false}]}
{"op":"mcm","clk":"5306917005","pt":1646110271190,"mc":[{"id":"1.195395432","rc":[{"atb":[[1.22,0]],"id":41375430}],"con":true,"img":false}]}
{"op":"mcm","clk":"5306917007","pt":1646110271294,"mc":[{"id":"1.195395432","rc":[{"atb":[[1.24,91.7]],"id":41375430}],"con":true,"img":false}]}
{"op":"mcm","clk":"5306917071","pt":1646110273860,"mc":[{"id":"1.195395432","rc":[{"atb":[[1.23,0]],"id":41375430}],"con":true,"img":false}]}
{"op":"mcm","clk":"5306917108","pt":1646110274986,"mc":[{"id":"1.195395432","rc":[{"atb":[[1.24,0]],"id":41375430}],"con":true,"img":false}]}
{"op":"mcm","clk":"5306917109","pt":1646110275083,"mc":[{"id":"1.195395432","rc":[{"atb":[[1.22,91.7]],"id":41375430}],"con":true,"img":false}]}
{"op":"mcm","clk":"5306917164","pt":1646110277499,"mc":[{"id":"1.195395432","rc":[{"atb":[[1.23,134.52]],"id":41375430}],"con":true,"img":false}]}
{"op":"mcm","clk":"5306918054","pt":1646110310348,"mc":[{"id":"1.195395432","rc":[{"atb":[[1.22,0]],"id":41375430}],"con":true,"img":false}]}
{"op":"mcm","clk":"5306918058","pt":1646110310450,"mc":[{"id":"1.195395432","rc":[{"atb":[[1.24,91.7]],"id":41375430}],"con":true,"img":false}]}
{"op":"mcm","clk":"5306918121","pt":1646110312451,"mc":[{"id":"1.195395432","rc":[{"atb":[[1.23,0]],"id":41375430}],"con":true,"img":false}]}
{"op":"mcm","clk":"5306918191","pt":1646110314348,"mc":[{"id":"1.195395432","rc":[{"atb":[[1.24,0]],"id":41375430}],"con":true,"img":false}]}
{"op":"mcm","clk":"5306918193","pt":1646110314447,"mc":[{"id":"1.195395432","rc":[{"atb":[[1.22,91.7]],"id":41375430}],"con":true,"img":false}]}
{"op":"mcm","clk":"5306918228","pt":1646110315833,"mc":[{"id":"1.195395432","rc":[{"atb":[[1.21,147.34]],"id":41375430}],"con":true,"img":false}]}
{"op":"mcm","clk":"5306918325","pt":1646110319465,"mc":[{"id":"1.195395432","rc":[{"atb":[[1.8,0],[1.85,0],[1.75,0]],"id":39296632},{"atl":[[4.5,0],[9,0],[5.5,9.61],[7,0],[3.75,0]],"id":39296632},{"atb":[[1.01,0]],"id":41375435},{"atl":[[2.36,0],[2.56,0],[1.98,0],[2.16,0],[2.76,0]],"id":41375435},{"atb":[[2.36,0],[2.26,0],[2.16,0]],"id":41729332},{"atl":[[18.5,0],[7.4,0],[5.7,0],[13.5,0],[9.4,0]],"id":41729332},{"atb":[[1.15,0],[1.1,0],[1.05,0]],"id":41375430},{"atl":[[2.82,0],[2.22,0],[2.42,0],[2.62,0],[3.05,0]],"id":41375430},{"atb":[[1.98,0],[1.88,0],[1.93,0]],"id":27453791},{"atl":[[4.9,0],[9.8,0],[7.8,0],[5.9,0],[14.5,0]],"id":27453791},{"atb":[[8,0],[9,0],[7,0]],"id":38124326},{"atl":[[300,0],[50,0],[100,0],[200,0],[400,0]],"id":38124326},{"atb":[[2,0],[2.2,0],[2.1,0]],"id":35784172},{"atl":[[17.5,0],[9,0],[5.5,0],[12.5,0],[7,0]],"id":35784172},{"atb":[[3.45,0],[3.95,0],[3.7,0]],"id":41375426},{"atl":[[18.5,0],[85,0],[44,0],[13.5,0],[27,0]],"id":41375426}],"con":true,"img":false}]}
{"op":"mcm","clk":"5306918391","pt":1646110321675,"mc":[{"id":"1.195395432","rc":[{"atb":[[1.8,150.06],[1.85,70.61],[1.75,160.06]],"id":39296632},{"atl":[[4.5,0.15],[5.5,10.57],[3.75,0.19]],"id":39296632},{"atb":[[1.01,30012.97]],"id":41375435},{"atl":[[2.36,3.17],[1.98,0.55],[2.16,0.46]],"id":41375435},{"atb":[[2.36,44.13],[2.26,95.27],[2.16,103.49]],"id":41729332},{"atl":[[7.4,0.08],[5.7,0.11],[9.4,0.51]],"id":41729332},{"atb":[[1.15,400.17],[1.1,1200.51],[1.05,2401.03]],"id":41375430},{"atl":[[2.22,0.44],[2.42,0.37],[2.62,2.67]],"id":41375430},{"atb":[[1.98,61.25],[1.88,136.42],[1.93,129.08]],"id":27453791},{"atl":[[4.9,0.14],[7.8,0.63],[5.9,0.1]],"id":27453791},{"atb":[[8,17.14],[9,7.5],[7,20]],"id":38124326},{"atl":[[50,0.01],[100,0],[200,0.02]],"id":38124326},{"atb":[[2,120.05],[2.2,50.02],[2.1,109.13]],"id":35784172},{"atl":[[9,0.54],[5.5,0.11],[7,0.09]],"id":35784172},{"atb":[[3.45,48.99],[3.95,20.34],[3.7,44.46]],"id":41375426},{"atl":[[18.5,0.03],[13.5,0.04],[27,0.16]],"id":41375426}],"con":true,"img":false}]}
{"op":"mcm","clk":"5306918419","pt":1646110322748,"mc":[{"id":"1.195395432","rc":[{"atb":[[1.86,0]],"id":39296632},{"atb":[[1.94,0]],"id":27453791},{"atb":[[2.14,0]],"id":35784172}],"con":true,"img":false}]}
{"op":"mcm","clk":"5306918456","pt":1646110324536,"mc":[{"id":"1.195395432","rc":[{"atb":[[2.3,0]],"id":41729332}],"con":true,"img":false}]}
{"op":"mcm","clk":"5306918502","pt":1646110326377,"mc":[{"id":"1.195395432","rc":[{"atb":[[1.86,35.97]],"id":39296632},{"atb":[[1.94,32.91]],"id":27453791},{"atb":[[2.14,27.14]],"id":35784172}],"con":true,"img":false}]}
{"op":"mcm","clk":"5306918551","pt":1646110328067,"mc":[{"id":"1.195395432","rc":[{"atb":[[2.3,23.8]],"id":41729332}],"con":true,"img":false}]}
{"op":"mcm","clk":"5306918905","pt":1646110339178,"mc":[{"id":"1.195395432","rc":[{"atb":[[1.62,63.67],[1.76,0]],"id":39296632}],"con":true,"img":false}]}
{"op":"mcm","clk":"5306920109","pt":1646110375055,"mc":[{"id":"1.195395432","rc":[{"spn":1.72,"spf":"NaN","id":41375430},{"atl":[[70,0]],"id":38124326},{"atl":[[22,0]],"id":41375426}],"con":true,"img":false}]}
{"op":"mcm","clk":"5306920114","pt":1646110375158,"mc":[{"id":"1.195395432","rc":[{"atl":[[75,2.7]],"id":38124326},{"atl":[[24,2.7]],"id":41375426}],"con":true,"img":false}]}
{"op":"mcm","clk":"5306920178","pt":1646110377257,"mc":[{"id":"1.195395432","rc":[{"atb":[[1.2,0]],"id":41375430}],"con":true,"img":false}]}
{"op":"mcm","clk":"5306920183","pt":1646110377360,"mc":[{"id":"1.195395432","rc":[{"atb":[[1.22,279.89]],"id":41375430}],"con":true,"img":false}]}
{"op":"mcm","clk":"5306920259","pt":1646110379661,"mc":[{"id":"1.195395432","rc":[{"atb":[[1.21,0]],"id":41375430}],"con":true,"img":false}]}
{"op":"mcm","clk":"5306920274","pt":1646110380068,"mc":[{"id":"1.195395432","rc":[{"atb":[[1.22,91.7]],"id":41375430}],"con":true,"img":false}]}
{"op":"mcm","clk":"5306920277","pt":1646110380122,"mc":[{"id":"1.195395432","rc":[{"atb":[[1.2,188.18]],"id":41375430}],"con":true,"img":false}]}
{"op":"mcm","clk":"5306920366","pt":1646110383043,"mc":[{"id":"1.195395432","rc":[{"atb":[[1.23,134.52]],"id":41375430}],"con":true,"img":false}]}
{"op":"mcm","clk":"5306920680","pt":1646110393693,"mc":[{"id":"1.195395432","rc":[{"atb":[[2.28,0]],"id":41729332}],"con":true,"img":false}]}
{"op":"mcm","clk":"5306920686","pt":1646110393795,"mc":[{"id":"1.195395432","rc":[{"atb":[[2.18,29.36]],"id":41729332}],"con":true,"img":false}]}
{"op":"mcm","clk":"5306921044","pt":1646110405484,"mc":[{"id":"1.195395432","rc":[{"atl":[[1.85,0]],"id":41375435}],"con":true,"img":false}]}
{"op":"mcm","clk":"5306921048","pt":1646110405587,"mc":[{"id":"1.195395432","rc":[{"atl":[[1.94,45.17]],"id":41375435}],"con":true,"img":false}]}
{"op":"mcm","clk":"5306921311","pt":1646110416794,"mc":[{"id":"1.195395432","rc":[{"atb":[[1.22,0]],"id":41375430}],"con":true,"img":false}]}
{"op":"mcm","clk":"5306921312","pt":1646110416897,"mc":[{"id":"1.195395432","rc":[{"atb":[[1.24,91.7]],"id":41375430}],"con":true,"img":false}]}
{"op":"mcm","clk":"5306921390","pt":1646110420118,"mc":[{"id":"1.195395432","rc":[{"atb":[[1.23,0]],"id":41375430}],"con":true,"img":false}]}
{"op":"mcm","clk":"5306921469","pt":1646110423034,"mc":[{"id":"1.195395432","rc":[{"atb":[[11,4.32]],"id":38124326}],"con":true,"img":false}]}
{"op":"mcm","clk":"5306921472","pt":1646110423133,"mc":[{"id":"1.195395432","rc":[{"atb":[[8.2,0]],"id":38124326}],"con":true,"img":false}]}
{"op":"mcm","clk":"5306921473","pt":1646110423236,"mc":[{"id":"1.195395432","rc":[{"atb":[[1.08,0]],"id":41375435},{"atb":[[2.12,0]],"id":35784172}],"con":true,"img":false}]}
{"op":"mcm","clk":"5306921476","pt":1646110423338,"mc":[{"id":"1.195395432","rc":[{"atb":[[1.12,104.56]],"id":41375435},{"atb":[[2.22,45.36]],"id":35784172}],"con":true,"img":false}]}
{"op":"mcm","clk":"5306921487","pt":1646110423595,"mc":[{"id":"1.195395432","rc":[{"atb":[[1.21,147.34]],"id":41375430}],"con":true,"img":false}]}
{"op":"mcm","clk":"5306921538","pt":1646110425434,"mc":[{"id":"1.195395432","rc":[{"atb":[[1.09,0]],"id":41375435},{"atb":[[2.14,0]],"id":35784172}],"con":true,"img":false}]}
{"op":"mcm","clk":"5306921631","pt":1646110428820,"mc":[{"id":"1.195395432","rc":[{"atb":[[1.07,365.97]],"id":41375435},{"atb":[[2.12,27.62]],"id":35784172}],"con":true,"img":false}]}
{"op":"mcm","clk":"5306921684","pt":1646110430817,"mc":[{"id":"1.195395432","rc":[{"atl":[[7.2,0]],"id":27453791}],"con":true,"img":false}]}
{"op":"mcm","clk":"5306921687","pt":1646110430919,"mc":[{"id":"1.195395432","rc":[{"atl":[[7.8,7.66]],"id":27453791}],"con":true,"img":false}]}
{"op":"mcm","clk":"5306921800","pt":1646110433943,"mc":[{"id":"1.195395432","rc":[{"atl":[[6.2,0]],"id":39296632},{"atl":[[1.7,0]],"id":41375435}],"con":true,"img":false}]}
{"op":"mcm","clk":"5306921804","pt":1646110434046,"mc":[{"id":"1.195395432","rc":[{"atl":[[6.6,6.8]],"id":39296632},{"atl":[[1.8,43.26]],"id":41375435},{"atb":[[1.94,0]],"id":27453791}],"con":true,"img":false}]}
{"op":"mcm","clk":"5306921906","pt":1646110437528,"mc":[{"id":"1.195395432","rc":[{"atb":[[1.86,0]],"id":39296632},{"spn":1.12,"spf":1.0,"id":41375435},{"spn":1.73,"spf":"NaN","id":41375430},{"atb":[[1.94,32.91]],"id":27453791},{"spn":30.5,"spf":"NaN","id":38124326}],"con":true,"img":false}]}
{"op":"mcm","clk":"5306921921","pt":1646110438450,"mc":[{"id":"1.195395432","rc":[{"atl":[[9.8,0]],"id":41729332}],"con":true,"img":false}]}
{"op":"mcm","clk":"5306921924","pt":1646110438550,"mc":[{"id":"1.195395432","rc":[{"atl":[[10.5,4.27]],"id":41729332}],"con":true,"img":false}]}
{"op":"mcm","clk":"5306922003","pt":1646110441062,"mc":[{"id":"1.195395432","rc":[{"atb":[[1.86,35.97]],"id":39296632},{"atb":[[2.3,0]],"id":41729332}],"con":true,"img":false}]}
{"op":"mcm","clk":"5306922016","pt":1646110441573,"mc":[{"id":"1.195395432","rc":[{"atl":[[7.6,0]],"id":35784172}],"con":true,"img":false}]}
{"op":"mcm","clk":"5306922020","pt":1646110441675,"mc":[{"id":"1.195395432","rc":[{"atl":[[8.2,6.48]],"id":35784172}],"con":true,"img":false}]}
{"op":"mcm","clk":"5306922072","pt":1646110442857,"mc":[{"id":"1.195395432","rc":[{"atl":[[2.58,0]],"id":41375430}],"con":true,"img":false}]}
{"op":"mcm","clk":"5306922078","pt":1646110442959,"mc":[{"id":"1.195395432","rc":[{"atl":[[2.74,25.95]],"id":41375430}],"con":true,"img":false}]}
{"op":"mcm","clk":"5306922115","pt":1646110444545,"mc":[{"id":"1.195395432","rc":[{"atb":[[2.28,24.17]],"id":41729332},{"atb":[[1.91,0]],"id":27453791},{"atb":[[2.12,0]],"id":35784172}],"con":true,"img":false}]}
{"op":"mcm","clk":"5306922120","pt":1646110444647,"mc":[{"id":"1.195395432","rc":[{"atb":[[1.89,47.04]],"id":27453791}],"con":true,"img":false}]}
{"op":"mcm","clk":"5306922186","pt":1646110448174,"mc":[{"id":"1.195395432","rc":[{"atb":[[2.12,27.62]],"id":35784172}],"con":true,"img":false}]}
{"op":"mcm","clk":"5306922347","pt":1646110453368,"mc":[{"id":"1.195395432","rc":[{"atb":[[1.06,0],[1.1,383.94]],"id":41375435}],"con":true,"img":false}]}
{"op":"mcm","clk":"5306922381","pt":1646110454850,"mc":[{"id":"1.195395432","rc":[{"atb":[[9,12.42]],"id":38124326}],"con":true,"img":false}]}
{"op":"mcm","clk":"5306922384","pt":1646110455054,"mc":[{"id":"1.195395432","rc":[{"atb":[[7.2,0]],"id":38124326}],"con":true,"img":false}]}
{"op":"mcm","clk":"5306922388","pt":1646110455257,"mc":[{"id":"1.195395432","rc":[{"atb":[[1.07,0]],"id":41375435}],"con":true,"img":false}]}
{"op":"mcm","clk":"5306922406","pt":1646110456382,"mc":[{"id":"1.195395432","rc":[{"atl":[[6.4,0]],"id":27453791}],"con":true,"img":false}]}
{"op":"mcm","clk":"5306922409","pt":1646110456483,"mc":[{"id":"1.195395432","rc":[{"atl":[[7.2,8]],"id":27453791}],"con":true,"img":false}]}
{"op":"mcm","clk":"5306922458","pt":1646110458784,"mc":[{"id":"1.195395432","rc":[{"atb":[[1.06,392.11]],"id":41375435},{"atb":[[1.94,0]],"id":27453791}],"con":true,"img":false}]}
{"op":"mcm","clk":"5306922537","pt":1646110462207,"mc":[{"id":"1.195395432","rc":[{"atl":[[8.6,0]],"id":41729332},{"atl":[[2.32,0]],"id":41375430},{"atb":[[1.94,32.91]],"id":27453791}],"con":true,"img":false}]}
{"op":"mcm","clk":"5306922540","pt":1646110462263,"mc":[{"id":"1.195395432","rc":[{"atl":[[9.6,5.69]],"id":41729332},{"atl":[[2.5,32.77]],"id":41375430}],"con":true,"img":false}]}
{"op":"mcm","clk":"5306922685","pt":1646110465797,"mc":[{"id":"1.195395432","rc":[{"atb":[[2.28,0]],"id":41729332}],"con":true,"img":false}]}
{"op":"mcm","clk":"5306922747","pt":1646110469173,"mc":[{"id":"1.195395432","rc":[{"atb":[[2.28,24.17]],"id":41729332}],"con":true,"img":false}]}
{"op":"mcm","clk":"5306922754","pt":1646110469480,"mc":[{"id":"1.195395432","rc":[{"atl":[[5.5,0.96]],"id":39296632}],"con":true,"img":false}]}
{"op":"mcm","clk":"5306922756","pt":1646110469582,"mc":[{"id":"1.195395432","rc":[{"atl":[[6.2,9.61]],"id":39296632}],"con":true,"img":false}]}
{"op":"mcm","clk":"5306922841","pt":1646110472702,"mc":[{"id":"1.195395432","rc":[{"atb":[[1.86,0]],"id":39296632}],"con":true,"img":false}]}
{"op":"mcm","clk":"5306922908","pt":1646110476190,"mc":[{"id":"1.195395432","rc":[{"atb":[[1.86,35.97]],"id":39296632}],"con":true,"img":false}]}
{"op":"mcm","clk":"5306923138","pt":1646110485108,"mc":[{"id":"1.195395432","rc":[{"atb":[[1.2,0]],"id":41375430}],"con":true,"img":false}]}
{"op":"mcm","clk":"5306923141","pt":1646110485212,"mc":[{"id":"1.195395432","rc":[{"atb":[[1.22,188.18]],"id":41375430}],"con":true,"img":false}]}
{"op":"mcm","clk":"5306923173","pt":1646110486434,"mc":[{"id":"1.195395432","rc":[{"atl":[[65,0]],"id":38124326}],"con":true,"img":false}]}
{"op":"mcm","clk":"5306923175","pt":1646110486537,"mc":[{"id":"1.195395432","rc":[{"atl":[[75,5.4]],"id":38124326}],"con":true,"img":false}]}
{"op":"mcm","clk":"5306923204","pt":1646110487818,"mc":[{"id":"1.195395432","rc":[{"atl":[[6.8,0]],"id":35784172}],"con":true,"img":false}]}
{"op":"mcm","clk":"5306923206","pt":1646110487918,"mc":[{"id":"1.195395432","rc":[{"atl":[[7.6,7.45]],"id":35784172}],"con":true,"img":false}]}
{"op":"mcm","clk":"5306923213","pt":1646110488326,"mc":[{"id":"1.195395432","rc":[{"atb":[[1.21,0]],"id":41375430}],"con":true,"img":false}]}
{"op":"mcm","clk":"5306923225","pt":1646110489199,"mc":[{"id":"1.195395432","rc":[{"atb":[[1.22,0]],"id":41375430}],"con":true,"img":false}]}
{"op":"mcm","clk":"5306923228","pt":1646110489303,"mc":[{"id":"1.195395432","rc":[{"atb":[[1.2,188.18]],"id":41375430}],"con":true,"img":false}]}
{"op":"mcm","clk":"5306923244","pt":1646110489917,"mc":[{"id":"1.195395432","rc":[{"atb":[[2.12,0]],"id":35784172}],"con":true,"img":false}]}
{"op":"mcm","clk":"5306923293","pt":1646110491709,"mc":[{"id":"1.195395432","rc":[{"atb":[[1.21,147.34]],"id":41375430}],"con":true,"img":false}]}
{"op":"mcm","clk":"5306923302","pt":1646110492018,"mc":[{"id":"1.195395432","rc":[{"atl":[[75,2.7]],"id":38124326}],"con":true,"img":false}]}
{"op":"mcm","clk":"5306923306","pt":1646110492123,"mc":[{"id":"1.195395432","rc":[{"atl":[[80,2.7]],"id":38124326}],"con":true,"img":false}]}
{"op":"mcm","clk":"5306923334","pt":1646110493405,"mc":[{"id":"1.195395432","rc":[{"atb":[[2.12,27.62]],"id":35784172}],"con":true,"img":false}]}
{"op":"mcm","clk":"5306924001","pt":1646110520171,"mc":[{"id":"1.195395432","rc":[{"atl":[[21,0]],"id":41375426}],"con":true,"img":false}]}
{"op":"mcm","clk":"5306924004","pt":1646110520273,"mc":[{"id":"1.195395432","rc":[{"atl":[[24,5.4]],"id":41375426}],"con":true,"img":false}]}
{"op":"mcm","clk":"5306924519","pt":1646110543723,"mc":[{"id":"1.195395432","marketDefinition":{"bspMarket":true,"turnInPlayEnabled":false,"persistenceEnabled":false,"marketBaseRate":7.0,"eventId":"31270458","eventTypeId":"4339","numberOfWinners":3,"bettingType":"ODDS","marketType":"PLACE","marketTime":"2022-03-01T06:10:00.000Z","suspendTime":"2022-03-01T06:10:00.000Z","bspReconciled":false,"complete":true,"inPlay":false,"crossMatching":true,"runnersVoidable":false,"numberOfActiveRunners":8,"betDelay":0,"status":"SUSPENDED","runners":[{"status":"ACTIVE","sortPriority":1,"id":39296632,"name":"1. Evolution Girl"},{"status":"ACTIVE","sortPriority":2,"id":38124326,"name":"2. Nanny In Town"},{"status":"ACTIVE","sortPriority":3,"id":41729332,"name":"3. Highland Wonder"},{"status":"ACTIVE","sortPriority":4,"id":27453791,"name":"4. Headwall"},{"status":"ACTIVE","sortPriority":5,"id":41375430,"name":"6. Just Posh"},{"status":"ACTIVE","sortPriority":6,"id":41375435,"name":"7. Rojo Diamond"},{"status":"ACTIVE","sortPriority":7,"id":35784172,"name":"8. Buckle Up Kenzie"},{"status":"ACTIVE","sortPriority":8,"id":41375426,"name":"9. Wynburn Rebel"}],"regulators":["MR_INT"],"venue":"Devonport","countryCode":"AU","discountAllowed":true,"timezone":"Australia/Sydney","openDate":"2022-03-01T02:00:00.000Z","version":4381133013,"name":"17:10TO BE PLACED","eventName":"Devonport (AUS) 1st Mar"},"rc":[],"con":true,"img":false}]}
{"op":"mcm","clk":"5306924547","pt":1646110544738,"mc":[{"id":"1.195395432","rc":[{"atb":[[1.9,0]],"id":39296632},{"atb":[[1.05,0]],"id":41375435},{"atb":[[1.19,0]],"id":41375430},{"atb":[[1.9,0]],"id":27453791},{"atb":[[1.9,0]],"id":35784172}],"con":true,"img":false}]}
{"op":"mcm","clk":"5306927094","pt":1646110677571,"mc":[{"id":"1.195395432","rc":[{"atb":[[1.8,0],[1.85,0],[1.75,0]],"id":39296632},{"atl":[[4.5,0],[5.5,0],[3.75,0]],"id":39296632},{"atb":[[1.01,0]],"id":41375435},{"atl":[[2.36,0],[1.98,0],[2.16,0]],"id":41375435},{"atb":[[2.36,0],[2.26,0],[2.16,0]],"id":41729332},{"atl":[[7.4,0],[5.7,0],[9.4,0]],"id":41729332},{"atb":[[1.15,0],[1.1,0],[1.05,0]],"id":41375430},{"atl":[[2.22,0],[2.42,0],[2.62,0]],"id":41375430},{"atb":[[1.98,0],[1.88,0],[1.93,0]],"id":27453791},{"atl":[[4.9,0],[7.8,7.03],[5.9,0]],"id":27453791},{"atb":[[8,0],[9,4.92],[7,0]],"id":38124326},{"atl":[[50,0],[100,0],[200,0]],"id":38124326},{"atb":[[2,0],[2.2,0],[2.1,0]],"id":35784172},{"atl":[[9,0],[5.5,0],[7,0]],"id":35784172},{"atb":[[3.45,0],[3.95,0],[3.7,0]],"id":41375426},{"atl":[[18.5,0],[13.5,0],[27,0]],"id":41375426}],"con":true,"img":false}]}
{"op":"mcm","clk":"5306927290","pt":1646110688783,"mc":[{"id":"1.195395432","marketDefinition":{"bspMarket":true,"turnInPlayEnabled":false,"persistenceEnabled":false,"marketBaseRate":7.0,"eventId":"31270458","eventTypeId":"4339","numberOfWinners":3,"bettingType":"ODDS","marketType":"PLACE","marketTime":"2022-03-01T06:10:00.000Z","suspendTime":"2022-03-01T06:10:00.000Z","bspReconciled":false,"complete":true,"inPlay":false,"crossMatching":false,"runnersVoidable":false,"numberOfActiveRunners":8,"betDelay":0,"status":"SUSPENDED","runners":[{"status":"ACTIVE","sortPriority":1,"id":39296632,"name":"1. Evolution Girl"},{"status":"ACTIVE","sortPriority":2,"id":38124326,"name":"2. Nanny In Town"},{"status":"ACTIVE","sortPriority":3,"id":41729332,"name":"3. Highland Wonder"},{"status":"ACTIVE","sortPriority":4,"id":27453791,"name":"4. Headwall"},{"status":"ACTIVE","sortPriority":5,"id":41375430,"name":"6. Just Posh"},{"status":"ACTIVE","sortPriority":6,"id":41375435,"name":"7. Rojo Diamond"},{"status":"ACTIVE","sortPriority":7,"id":35784172,"name":"8. Buckle Up Kenzie"},{"status":"ACTIVE","sortPriority":8,"id":41375426,"name":"9. Wynburn Rebel"}],"regulators":["MR_INT"],"venue":"Devonport","countryCode":"AU","discountAllowed":true,"timezone":"Australia/Sydney","openDate":"2022-03-01T02:00:00.000Z","version":4381133799,"name":"17:10TO BE PLACED","eventName":"Devonport (AUS) 1st Mar"},"rc":[],"con":true,"img":false}]}
{"op":"mcm","clk":"5306927290","pt":1646110688783,"mc":[{"id":"1.195395432","rc":[{"atb":[[1.91,0],[1.62,0],[1.86,0]],"id":39296632},{"atl":[[6.2,0],[6.6,0]],"id":39296632},{"atb":[[1.12,0],[1.06,0],[1.1,0]],"id":41375435},{"spl":[[1.01,0]],"id":41375435},{"atl":[[1.8,0],[85,0],[1.94,0]],"id":41375435},{"atb":[[2.4,0],[2.38,0],[2.28,0],[2.18,0]],"id":41729332},{"atl":[[9.6,0],[10.5,0]],"id":41729332},{"atb":[[1.2,0],[1.21,0],[1.24,0]],"id":41375430},{"atl":[[2.5,0],[2.74,0],[85,0]],"id":41375430},{"atb":[[1.99,0],[1.89,0],[1.94,0]],"id":27453791},{"atl":[[7.2,0],[7.8,0]],"id":27453791},{"atb":[[9,0],[9.2,0],[11,0]],"id":38124326},{"atl":[[75,0],[80,0]],"id":38124326},{"atb":[[2.22,0],[2.12,0],[1.91,0]],"id":35784172},{"atl":[[8.2,0],[7.6,0]],"id":35784172},{"atb":[[4,0],[4.1,0],[3.75,0]],"id":41375426},{"atl":[[24,0]],"id":41375426}],"con":true,"img":false}]}
{"op":"mcm","clk":"5306927312","pt":1646110689941,"mc":[{"id":"1.195395432","marketDefinition":{"bspMarket":true,"turnInPlayEnabled":false,"persistenceEnabled":false,"marketBaseRate":7.0,"eventId":"31270458","eventTypeId":"4339","numberOfWinners":3,"bettingType":"ODDS","marketType":"PLACE","marketTime":"2022-03-01T06:10:00.000Z","suspendTime":"2022-03-01T06:10:00.000Z","bspReconciled":false,"complete":true,"inPlay":false,"crossMatching":false,"runnersVoidable":false,"numberOfActiveRunners":0,"betDelay":0,"status":"CLOSED","settledTime":"2022-03-01T04:58:08.000Z","runners":[{"status":"REMOVED","sortPriority":1,"removalDate":"2022-03-01T04:58:08.000Z","id":39296632,"name":"1. Evolution Girl"},{"status":"REMOVED","sortPriority":2,"removalDate":"2022-03-01T04:58:08.000Z","id":38124326,"name":"2. Nanny In Town"},{"status":"REMOVED","sortPriority":3,"removalDate":"2022-03-01T04:58:08.000Z","id":41729332,"name":"3. Highland Wonder"},{"status":"REMOVED","sortPriority":4,"removalDate":"2022-03-01T04:58:08.000Z","id":27453791,"name":"4. Headwall"},{"status":"REMOVED","sortPriority":5,"removalDate":"2022-03-01T04:58:08.000Z","id":41375430,"name":"6. Just Posh"},{"status":"REMOVED","sortPriority":6,"removalDate":"2022-03-01T04:58:08.000Z","id":41375435,"name":"7. Rojo Diamond"},{"status":"REMOVED","sortPriority":7,"removalDate":"2022-03-01T04:58:08.000Z","id":35784172,"name":"8. Buckle Up Kenzie"},{"status":"REMOVED","sortPriority":8,"removalDate":"2022-03-01T04:58:08.000Z","id":41375426,"name":"9. Wynburn Rebel"}],"regulators":["MR_INT"],"venue":"Devonport","countryCode":"AU","discountAllowed":true,"timezone":"Australia/Sydney","openDate":"2022-03-01T02:00:00.000Z","version":4381133815,"name":"17:10TO BE PLACED","eventName":"Devonport (AUS) 1st Mar"},"rc":[],"con":true,"img":false}]}
