{"op":"mcm","clk":"5305619425","pt":1646080581424,"mc":[{"id":"1.195395427","marketDefinition":{"bspMarket":true,"turnInPlayEnabled":false,"persistenceEnabled":false,"marketBaseRate":7.0,"eventId":"31270458","eventTypeId":"4339","numberOfWinners":1,"bettingType":"ODDS","marketType":"WIN","marketTime":"2022-03-01T03:14:00.000Z","suspendTime":"2022-03-01T03:14:00.000Z","bspReconciled":false,"complete":true,"inPlay":false,"crossMatching":false,"runnersVoidable":false,"numberOfActiveRunners":7,"betDelay":0,"status":"OPEN","runners":[{"status":"ACTIVE","sortPriority":1,"id":43154456,"name":"1. Buckle Up Zion"},{"status":"ACTIVE","sortPriority":2,"id":43154457,"name":"2. Rambo Bobbie"},{"status":"ACTIVE","sortPriority":3,"id":39979946,"name":"3. Marshall Giblet"},{"status":"ACTIVE","sortPriority":4,"id":38407646,"name":"4. Hiccup Gus"},{"status":"ACTIVE","sortPriority":5,"id":42130949,"name":"5. Into The Fire"},{"status":"ACTIVE","sortPriority":6,"id":37284251,"name":"7. Shiffrin"},{"status":"ACTIVE","sortPriority":7,"id":36087680,"name":"8. White Poison"}],"regulators":["MR_INT"],"venue":"Devonport","countryCode":"AU","discountAllowed":true,"timezone":"Australia/Sydney","openDate":"2022-03-01T02:00:00.000Z","version":4380714787,"name":"R5 452m Gr5","eventName":"Devonport (AUS) 1st Mar"},"rc":[],"con":true,"img":false}]}
{"op":"mcm","clk":"5305743101","pt":1646082026907,"mc":[{"id":"1.195395427","rc":[{"atb":[[16.5,6.54],[20,5.34],[11.5,9.66],[14,7.8]],"id":37284251},{"atl":[[260,0.76],[310,0.64],[160,0.83],[210,0.63]],"id":37284251},{"spn":90.0,"spf":"NaN","id":37284251},{"atb":[[36,2.9],[18,5.97],[21,5.07],[26,4.05]],"id":42130949},{"atl":[[300,0.44],[350,0.37],[400,0.49],[450,0.44]],"id":42130949},{"spn":168.0,"spf":"NaN","id":42130949},{"atb":[[4,33.83],[3.5,40.59],[3.75,36.9],[4.7,27.43]],"id":38407646},{"atl":[[16,8.81],[18.5,7.55],[22,9.44],[27,7.62]],"id":38407646},{"spn":10.35,"spf":"NaN","id":38407646},{"atb":[[4,33.83],[3.5,40.59],[3.75,36.9],[4.7,27.43]],"id":43154456},{"atl":[[16,8.81],[18.5,7.55],[22,9.44],[27,7.62]],"id":43154456},{"spn":10.35,"spf":"NaN","id":43154456},{"atb":[[1.98,103.56],[1.88,115.33],[1.93,109.13],[2.1,92.26]],"id":43154457},{"atl":[[6.4,36.71],[7.4,30.97],[5.2,31.47],[5.7,28.12]],"id":43154457},{"spn":3.65,"spf":"NaN","id":43154457},{"atb":[[36,2.9],[18,5.97],[21,5.07],[26,4.05]],"id":39979946},{"atl":[[300,0.44],[350,0.37],[400,0.49],[450,0.44]],"id":39979946},{"spn":168.0,"spf":"NaN","id":39979946},{"atb":[[2.06,95.75],[1.98,103.56],[2.2,84.57],[1.93,109.13]],"id":36087680},{"atl":[[6.8,34.18],[7.8,29.15],[5.9,26.97],[5.4,30.04]],"id":36087680},{"spn":3.8,"spf":"NaN","id":36087680}],"con":true,"img":false}]}
{"op":"mcm","clk":"5305747397","pt":1646082083779,"mc":[{"id":"1.195395427","rc":[{"atb":[[16.5,0],[20,0],[11.5,0],[14,0]],"id":37284251},{"atl":[[260,0],[310,0],[160,0],[210,0]],"id":37284251},{"atb":[[36,0],[18,0],[21,0],[26,0]],"id":42130949},{"atl":[[300,0],[350,0],[400,0],[450,0]],"id":42130949},{"atb":[[4,0],[3.5,0],[3.75,0],[4.7,0]],"id":38407646},{"atl":[[16,0],[18.5,0],[22,0],[27,0]],"id":38407646},{"atb":[[4,0],[3.5,0],[3.75,0],[4.7,0]],"id":43154456},{"atl":[[16,0],[18.5,0],[22,0],[27,0]],"id":43154456},{"atb":[[1.98,0],[1.88,0],[1.93,0],[2.1,0]],"id":43154457},{"atl":[[6.4,0],[7.4,0],[5.2,0],[5.7,0]],"id":43154457},{"atb":[[36,0],[18,0],[21,0],[26,0]],"id":39979946},{"atl":[[300,0],[350,0],[400,0],[450,0]],"id":39979946},{"atb":[[2.06,0],[1.98,0],[2.2,0],[1.93,0]],"id":36087680},{"atl":[[6.8,0],[7.8,0],[5.9,0],[5.4,0]],"id":36087680}],"con":true,"img":false}]}
{"op":"mcm","clk":"5305747684","pt":1646082087094,"mc":[{"id":"1.195395427","rc":[{"atb":[[16.5,6.54],[20,5.34],[11.5,9.66],[14,7.8]],"id":37284251},{"atl":[[260,0.76],[310,0.64],[160,0.83],[210,0.63]],"id":37284251},{"atb":[[36,2.9],[18,5.97],[21,5.07],[26,4.05]],"id":42130949},{"atl":[[300,0.44],[350,0.37],[400,0.49],[450,0.44]],"id":42130949},{"atb":[[4,33.83],[3.5,40.59],[3.75,36.9],[4.7,27.43]],"id":38407646},{"atl":[[16,8.81],[18.5,7.55],[22,9.44],[27,7.62]],"id":38407646},{"atb":[[4,33.83],[3.5,40.59],[3.75,36.9],[4.7,27.43]],"id":43154456},{"atl":[[16,8.81],[18.5,7.55],[22,9.44],[27,7.62]],"id":43154456},{"atb":[[1.98,103.56],[1.88,115.33],[1.93,109.13],[2.1,92.26]],"id":43154457},{"atl":[[6.4,36.71],[7.4,30.97],[5.2,31.47],[5.7,28.12]],"id":43154457},{"atb":[[36,2.9],[18,5.97],[21,5.07],[26,4.05]],"id":39979946},{"atl":[[300,0.44],[350,0.37],[400,0.49],[450,0.44]],"id":39979946},{"atb":[[2.06,95.75],[1.98,103.56],[2.2,84.57],[1.93,109.13]],"id":36087680},{"atl":[[6.8,34.18],[7.8,29.15],[5.9,26.97],[5.4,30.04]],"id":36087680}],"con":true,"img":false}]}
{"op":"mcm","clk":"5305928458","pt":1646084873022,"mc":[{"id":"1.195395427","rc":[{"atb":[[16.5,0],[20,0],[11.5,0],[14,0]],"id":37284251},{"atl":[[260,0],[310,0],[160,0],[210,0]],"id":37284251},{"spn":"NaN","spf":"NaN","id":37284251},{"atb":[[36,0],[18,0],[21,0],[26,0]],"id":42130949},{"atl":[[300,0],[350,0],[400,0],[450,0]],"id":42130949},{"spn":"NaN","spf":"NaN","id":42130949},{"atb":[[36,0],[18,0],[21,0],[26,0]],"id":39979946},{"atl":[[300,0],[350,0],[400,0],[450,0]],"id":39979946},{"spn":"NaN","spf":"NaN","id":39979946},{"atb":[[2.06,0],[1.98,0],[2.2,0],[1.93,0]],"id":36087680},{"atl":[[6.8,0],[7.8,0],[5.9,0],[5.4,0]],"id":36087680},{"spn":"NaN","spf":"NaN","id":36087680}],"con":true,"img":false}]}
{"op":"mcm","clk":"5305928630","pt":1646084878445,"mc":[{"id":"1.195395427","rc":[{"atb":[[16.5,6.54],[20,5.34],[11.5,9.66],[14,7.8]],"id":37284251},{"atl":[[260,0.76],[310,0.64],[160,0.83],[210,0.63]],"id":37284251},{"atb":[[36,2.9],[18,5.97],[21,5.07],[26,4.05]],"id":42130949},{"atl":[[300,0.44],[350,0.37],[400,0.49],[450,0.44]],"id":42130949},{"atb":[[36,2.9],[18,5.97],[21,5.07],[26,4.05]],"id":39979946},{"atl":[[300,0.44],[350,0.37],[400,0.49],[450,0.44]],"id":39979946},{"atb":[[2.06,95.75],[1.98,103.56],[2.2,84.57],[1.93,109.13]],"id":36087680},{"atl":[[6.8,34.18],[7.8,29.15],[5.9,26.97],[5.4,30.04]],"id":36087680}],"con":true,"img":false}]}
{"op":"mcm","clk":"5305990535","pt":1646086602700,"mc":[{"id":"1.195395427","marketDefinition":{"bspMarket":true,"turnInPlayEnabled":false,"persistenceEnabled":false,"marketBaseRate":7.0,"eventId":"31270458","eventTypeId":"4339","numberOfWinners":1,"bettingType":"ODDS","marketType":"WIN","marketTime":"2022-03-01T03:14:00.000Z","suspendTime":"2022-03-01T03:14:00.000Z","bspReconciled":false,"complete":true,"inPlay":false,"crossMatching":false,"runnersVoidable":false,"numberOfActiveRunners":7,"betDelay":0,"status":"OPEN","runners":[{"status":"ACTIVE","sortPriority":1,"id":43154456,"name":"1. Buckle Up Zion"},{"status":"ACTIVE","sortPriority":2,"id":43154457,"name":"2. Rambo Bobbie"},{"status":"ACTIVE","sortPriority":3,"id":39979946,"name":"3. Marshall Giblet"},{"status":"ACTIVE","sortPriority":4,"id":38407646,"name":"4. Hiccup Gus"},{"status":"ACTIVE","sortPriority":5,"id":42130949,"name":"5. Into The Fire"},{"status":"ACTIVE","sortPriority":6,"id":37284251,"name":"7. Shiffrin"},{"status":"ACTIVE","sortPriority":7,"id":36087680,"name":"8. White Poison"}],"regulators":["MR_INT"],"venue":"Devonport","countryCode":"AU","discountAllowed":true,"timezone":"Australia/Sydney","openDate":"2022-03-01T02:00:00.000Z","version":4380714787,"name":"R5 452m Gr5","eventName":"Devonport (AUS) 1st Mar"},"rc":[{"atb":[[16.5,6.54],[20,5.34],[11.5,9.66],[14,7.8]],"id":37284251},{"atl":[[260,0.76],[310,0.64],[160,0.83],[210,0.63]],"id":37284251},{"spn":90.0,"spf":"NaN","id":37284251},{"atb":[[36,2.9],[18,5.96],[21,5.07],[26,4.05]],"id":42130949},{"atl":[[300,0.44],[350,0.37],[400,0.49],[450,0.44]],"id":42130949},{"spn":168.0,"spf":"NaN","id":42130949},{"atb":[[4,33.82],[3.5,40.59],[3.75,36.89],[4.7,27.42]],"id":38407646},{"atl":[[16,8.81],[18.5,7.54],[22,9.43],[27,7.62]],"id":38407646},{"spn":10.35,"spf":"NaN","id":38407646},{"atb":[[4,33.82],[3.5,40.59],[3.75,36.89],[4.7,27.42]],"id":43154456},{"atl":[[16,8.81],[18.5,7.54],[22,9.43],[27,7.62]],"id":43154456},{"spn":10.35,"spf":"NaN","id":43154456},{"atb":[[1.98,103.55],[1.88,115.31],[1.93,109.11],[2.1,92.24]],"id":43154457},{"atl":[[6.4,36.71],[7.4,30.97],[5.2,31.46],[5.7,28.12]],"id":43154457},{"spn":3.65,"spf":"NaN","id":43154457},{"atb":[[36,2.9],[18,5.96],[21,5.07],[26,4.05]],"id":39979946},{"atl":[[300,0.44],[350,0.37],[400,0.49],[450,0.44]],"id":39979946},{"spn":168.0,"spf":"NaN","id":39979946},{"atb":[[2.06,95.73],[1.98,103.55],[2.2,84.56],[1.93,109.11]],"id":36087680},{"atl":[[6.8,34.18],[7.8,29.15],[5.9,26.97],[5.4,30.03]],"id":36087680},{"spn":3.8,"spf":"NaN","id":36087680}],"con":true,"img":true}]}
{"op":"mcm","clk":"5306008485","pt":1646086988740,"mc":[{"id":"1.195395427","marketDefinition":{"bspMarket":true,"turnInPlayEnabled":false,"persistenceEnabled":false,"marketBaseRate":7.0,"eventId":"31270458","eventTypeId":"4339","numberOfWinners":1,"bettingType":"ODDS","marketType":"WIN","marketTime":"2022-03-01T03:14:00.000Z","suspendTime":"2022-03-01T03:14:00.000Z","bspReconciled":false,"complete":true,"inPlay":false,"crossMatching":false,"runnersVoidable":false,"numberOfActiveRunners":7,"betDelay":0,"status":"SUSPENDED","runners":[{"status":"ACTIVE","sortPriority":1,"id":43154456,"name":"1. Buckle Up Zion"},{"status":"ACTIVE","sortPriority":2,"id":43154457,"name":"2. Rambo Bobbie"},{"status":"ACTIVE","sortPriority":3,"id":39979946,"name":"3. Marshall Giblet"},{"status":"ACTIVE","sortPriority":4,"id":38407646,"name":"4. Hiccup Gus"},{"status":"ACTIVE","sortPriority":5,"id":42130949,"name":"5. Into The Fire"},{"status":"ACTIVE","sortPriority":6,"id":37284251,"name":"7. Shiffrin"},{"status":"ACTIVE","sortPriority":7,"id":36087680,"name":"8. White Poison"}],"regulators":["MR_INT"],"venue":"Devonport","countryCode":"AU","discountAllowed":true,"timezone":"Australia/Sydney","openDate":"2022-03-01T02:00:00.000Z","version":4380876477,"name":"R5 452m Gr5","eventName":"Devonport (AUS) 1st Mar"},"rc":[],"con":true,"img":false}]}
{"op":"mcm","clk":"5306009258","pt":1646087009064,"mc":[{"id":"1.195395427","marketDefinition":{"bspMarket":true,"turnInPlayEnabled":false,"persistenceEnabled":false,"marketBaseRate":7.0,"eventId":"31270458","eventTypeId":"4339","numberOfWinners":1,"bettingType":"ODDS","marketType":"WIN","marketTime":"2022-03-01T03:14:00.000Z","suspendTime":"2022-03-01T03:14:00.000Z","bspReconciled":false,"complete":true,"inPlay":false,"crossMatching":false,"runnersVoidable":false,"numberOfActiveRunners":6,"betDelay":0,"status":"SUSPENDED","runners":[{"status":"ACTIVE","sortPriority":1,"id":43154456,"name":"1. Buckle Up Zion"},{"status":"ACTIVE","sortPriority":2,"id":43154457,"name":"2. Rambo Bobbie"},{"status":"ACTIVE","sortPriority":3,"id":38407646,"name":"4. Hiccup Gus"},{"status":"ACTIVE","sortPriority":4,"id":42130949,"name":"5. Into The Fire"},{"status":"ACTIVE","sortPriority":5,"id":37284251,"name":"7. Shiffrin"},{"status":"ACTIVE","sortPriority":6,"id":36087680,"name":"8. White Poison"},{"status":"REMOVED","sortPriority":7,"removalDate":"2022-02-28T22:23:28.000Z","id":39979946,"name":"3. Marshall Giblet"}],"regulators":["MR_INT"],"venue":"Devonport","countryCode":"AU","discountAllowed":true,"timezone":"Australia/Sydney","openDate":"2022-03-01T02:00:00.000Z","version":4380876823,"name":"R5 452m Gr5","eventName":"Devonport (AUS) 1st Mar"},"rc":[],"con":true,"img":false}]}
{"op":"mcm","clk":"5306009258","pt":1646087009064,"mc":[{"id":"1.195395427","rc":[{"atb":[[16.5,0],[20,0],[11.5,0],[14,0]],"id":37284251},{"atl":[[260,0],[310,0],[160,0],[210,0]],"id":37284251},{"atb":[[36,0],[18,0],[21,0],[26,0]],"id":42130949},{"atl":[[300,0],[350,0],[400,0],[450,0]],"id":42130949},{"atb":[[4,0],[3.5,0],[3.75,0],[4.7,0]],"id":38407646},{"atl":[[16,0],[18.5,0],[22,0],[27,0]],"id":38407646},{"atb":[[4,0],[3.5,0],[3.75,0],[4.7,0]],"id":43154456},{"atl":[[16,0],[18.5,0],[22,0],[27,0]],"id":43154456},{"atb":[[1.98,0],[1.88,0],[1.93,0],[2.1,0]],"id":43154457},{"atl":[[6.4,0],[7.4,0],[5.2,0],[5.7,0]],"id":43154457},{"atb":[[36,0],[18,0],[21,0],[26,0]],"id":39979946},{"atl":[[300,0],[350,0],[400,0],[450,0]],"id":39979946},{"atb":[[2.06,0],[1.98,0],[2.2,0],[1.93,0]],"id":36087680},{"atl":[[6.8,0],[7.8,0],[5.9,0],[5.4,0]],"id":36087680}],"con":true,"img":false}]}
{"op":"mcm","clk":"5306009522","pt":1646087015788,"mc":[{"id":"1.195395427","marketDefinition":{"bspMarket":true,"turnInPlayEnabled":false,"persistenceEnabled":false,"marketBaseRate":7.0,"eventId":"31270458","eventTypeId":"4339","numberOfWinners":1,"bettingType":"ODDS","marketType":"WIN","marketTime":"2022-03-01T03:14:00.000Z","suspendTime":"2022-03-01T03:14:00.000Z","bspReconciled":false,"complete":true,"inPlay":false,"crossMatching":false,"runnersVoidable":false,"numberOfActiveRunners":6,"betDelay":0,"status":"OPEN","runners":[{"status":"ACTIVE","sortPriority":1,"id":43154456,"name":"1. Buckle Up Zion"},{"status":"ACTIVE","sortPriority":2,"id":43154457,"name":"2. Rambo Bobbie"},{"status":"ACTIVE","sortPriority":3,"id":38407646,"name":"4. Hiccup Gus"},{"status":"ACTIVE","sortPriority":4,"id":42130949,"name":"5. Into The Fire"},{"status":"ACTIVE","sortPriority":5,"id":37284251,"name":"7. Shiffrin"},{"status":"ACTIVE","sortPriority":6,"id":36087680,"name":"8. White Poison"},{"status":"REMOVED","sortPriority":7,"removalDate":"2022-02-28T22:23:28.000Z","id":39979946,"name":"3. Marshall Giblet"}],"regulators":["MR_INT"],"venue":"Devonport","countryCode":"AU","discountAllowed":true,"timezone":"Australia/Sydney","openDate":"2022-03-01T02:00:00.000Z","version":4380876836,"name":"R5 452m Gr5","eventName":"Devonport (AUS) 1st Mar"},"rc":[],"con":true,"img":false}]}
{"op":"mcm","clk":"5306110462","pt":1646089640399,"mc":[{"id":"1.195395427","rc":[{"spl":[[100,2]],"id":37284251},{"spn":1.0,"spf":1.0,"id":37284251},{"spl":[[100,2]],"id":42130949},{"spn":1.0,"spf":1.0,"id":42130949},{"spl":[[100,2]],"id":38407646},{"spn":1.0,"spf":1.0,"id":38407646},{"spl":[[100,2]],"id":43154456},{"spn":1.0,"spf":1.0,"id":43154456},{"spl":[[100,2]],"id":43154457},{"spn":1.0,"spf":1.0,"id":43154457},{"spl":[[100,2]],"id":36087680},{"spn":1.0,"spf":1.0,"id":36087680}],"con":true,"img":false}]}
{"op":"mcm","clk":"5306392632","pt":1646097240121,"mc":[{"id":"1.195395427","rc":[{"atb":[[22,0.49]],"id":37284251},{"spn":61.0,"spf":1.0,"id":37284251},{"atb":[[44,0.24]],"id":42130949},{"spn":72.0,"spf":1.0,"id":42130949},{"atb":[[5.1,2]],"id":38407646},{"spn":52.55,"spf":1.0,"id":38407646},{"atb":[[5.1,2]],"id":43154456},{"spn":52.55,"spf":1.0,"id":43154456},{"atb":[[2.16,2]],"id":43154457},{"spn":51.08,"spf":1.0,"id":43154457},{"atb":[[2.26,2]],"id":36087680},{"spn":51.13,"spf":1.0,"id":36087680}],"con":true,"img":false}]}
{"op":"mcm","clk":"5306443311","pt":1646098289419,"mc":[{"id":"1.195395427","rc":[{"atb":[[5.1,0]],"id":43154456},{"spn":1.0,"spf":1.0,"id":43154456}],"con":true,"img":false}]}
{"op":"mcm","clk":"5306443314","pt":1646098289521,"mc":[{"id":"1.195395427","rc":[{"atb":[[5,2]],"id":43154456}],"con":true,"img":false}]}
{"op":"mcm","clk":"5306474742","pt":1646099097531,"mc":[{"id":"1.195395427","rc":[{"atb":[[17.5,3.51],[14,10.27]],"id":37284251},{"atl":[[70,2.7],[95,2.7]],"id":37284251},{"spn":46.0,"spf":1.0,"id":37284251},{"atb":[[34,2.7],[26,4.57]],"id":42130949},{"atl":[[330,2.7],[240,0.24]],"id":42130949},{"atb":[[5.1,16.14],[4.2,41.1]],"id":38407646},{"atl":[[11.5,5.52],[15,9.19]],"id":38407646},{"spn":8.3,"spf":1.0,"id":38407646},{"atb":[[4.5,16.57],[3.8,38.92]],"id":43154456},{"atl":[[10.5,6.1],[14,8.38]],"id":43154456},{"spn":7.75,"spf":1.0,"id":43154456},{"atb":[[2.06,54.32],[1.85,136.48]],"id":43154457},{"atl":[[4.8,30.53],[3.6,22.31]],"id":43154457},{"spn":2.88,"spf":1.0,"id":43154457},{"atb":[[2.06,121.69],[2.34,43.29]],"id":36087680},{"atl":[[5.5,28.66],[4.2,18.12]],"id":36087680},{"spn":3.27,"spf":1.0,"id":36087680}],"con":true,"img":false}]}
{"op":"mcm","clk":"5306475197","pt":1646099105910,"mc":[{"id":"1.195395427","rc":[{"atb":[[3.05,35.12]],"id":38407646}],"con":true,"img":false}]}
{"op":"mcm","clk":"5306475203","pt":1646099106013,"mc":[{"id":"1.195395427","rc":[{"atb":[[1.61,118.03]],"id":36087680}],"con":true,"img":false}]}
{"op":"mcm","clk":"5306475662","pt":1646099114938,"mc":[{"id":"1.195395427","rc":[{"atb":[[1.01,2.23]],"id":38407646},{"atb":[[4.6,2.5]],"id":43154456},{"atb":[[2.1,8.19]],"id":43154457},{"atb":[[2.38,6.53]],"id":36087680}],"con":true,"img":false}]}
{"op":"mcm","clk":"5306475667","pt":1646099115041,"mc":[{"id":"1.195395427","rc":[{"atb":[[1.01,2.14]],"id":38407646}],"con":true,"img":false}]}
{"op":"mcm","clk":"5306475671","pt":1646099115143,"mc":[{"id":"1.195395427","rc":[{"atb":[[3.85,3.22]],"id":43154456}],"con":true,"img":false}]}
{"op":"mcm","clk":"5306475675","pt":1646099115246,"mc":[{"id":"1.195395427","rc":[{"atb":[[1.01,0],[5.2,2.18]],"id":38407646}],"con":true,"img":false}]}
{"op":"mcm","clk":"5306475679","pt":1646099115349,"mc":[{"id":"1.195395427","rc":[{"atb":[[5.2,4.33]],"id":38407646},{"atb":[[2.1,16.54]],"id":43154457}],"con":true,"img":false}]}
{"op":"mcm","clk":"5306475688","pt":1646099115555,"mc":[{"id":"1.195395427","rc":[{"atb":[[2.38,13.2]],"id":36087680}],"con":true,"img":false}]}
{"op":"mcm","clk":"5306476200","pt":1646099126679,"mc":[{"id":"1.195395427","marketDefinition":{"bspMarket":true,"turnInPlayEnabled":false,"persistenceEnabled":false,"marketBaseRate":7.0,"eventId":"31270458","eventTypeId":"4339","numberOfWinners":1,"bettingType":"ODDS","marketType":"WIN","marketTime":"2022-03-01T03:14:00.000Z","suspendTime":"2022-03-01T03:14:00.000Z","bspReconciled":false,"complete":true,"inPlay":false,"crossMatching":true,"runnersVoidable":false,"numberOfActiveRunners":6,"betDelay":0,"status":"OPEN","runners":[{"status":"ACTIVE","sortPriority":1,"id":43154456,"name":"1. Buckle Up Zion"},{"status":"ACTIVE","sortPriority":2,"id":43154457,"name":"2. Rambo Bobbie"},{"status":"ACTIVE","sortPriority":3,"id":38407646,"name":"4. Hiccup Gus"},{"status":"ACTIVE","sortPriority":4,"id":42130949,"name":"5. Into The Fire"},{"status":"ACTIVE","sortPriority":5,"id":37284251,"name":"7. Shiffrin"},{"status":"ACTIVE","sortPriority":6,"id":36087680,"name":"8. White Poison"},{"status":"REMOVED","sortPriority":7,"removalDate":"2022-02-28T22:23:28.000Z","id":39979946,"name":"3. Marshall Giblet"}],"regulators":["MR_INT"],"venue":"Devonport","countryCode":"AU","discountAllowed":true,"timezone":"Australia/Sydney","openDate":"2022-03-01T02:00:00.000Z","version":4380876836,"name":"R5 452m Gr5","eventName":"Devonport (AUS) 1st Mar"},"rc":[],"con":true,"img":false}]}
{"op":"mcm","clk":"5306479619","pt":1646099216338,"mc":[{"id":"1.195395427","rc":[{"atb":[[17.5,0]],"id":37284251},{"atl":[[11.5,0]],"id":38407646},{"spn":10.1,"spf":1.0,"id":38407646},{"spn":3.29,"spf":1.0,"id":36087680}],"con":true,"img":false}]}
{"op":"mcm","clk":"5306479624","pt":1646099216438,"mc":[{"id":"1.195395427","rc":[{"atb":[[18.5,3.51]],"id":37284251},{"atl":[[11,5.52]],"id":38407646}],"con":true,"img":false}]}
{"op":"mcm","clk":"5306490559","pt":1646099439416,"mc":[{"id":"1.195395427","rc":[{"atb":[[13,6]],"id":42130949},{"spn":8.1,"spf":1.0,"id":38407646}],"con":true,"img":false}]}
{"op":"mcm","clk":"5306490564","pt":1646099439518,"mc":[{"id":"1.195395427","rc":[{"atb":[[9.6,8.37]],"id":37284251}],"con":true,"img":false}]}
{"op":"mcm","clk":"5306503818","pt":1646099737864,"mc":[{"id":"1.195395427","rc":[{"atb":[[2.62,46.3]],"id":37284251},{"atb":[[2.62,46.3],[4.2,26.56]],"id":42130949},{"atl":[[17,8.5]],"id":43154457}],"con":true,"img":false}]}
{"op":"mcm","clk":"5306503823","pt":1646099737964,"mc":[{"id":"1.195395427","rc":[{"atb":[[4.2,26.56]],"id":37284251},{"atl":[[34,13.5]],"id":38407646},{"atl":[[34,13.5]],"id":43154457},{"atl":[[17,8.5]],"id":36087680}],"con":true,"img":false}]}
{"op":"mcm","clk":"5306503829","pt":1646099738065,"mc":[{"id":"1.195395427","rc":[{"atl":[[34,13.5]],"id":43154456},{"atl":[[34,13.5]],"id":36087680}],"con":true,"img":false}]}
{"op":"mcm","clk":"5306518023","pt":1646100048015,"mc":[{"id":"1.195395427","rc":[{"atb":[[18.5,3.51],[14,10.28]],"id":37284251},{"atl":[[70,2.7],[95,2.7]],"id":37284251},{"atb":[[34,2.7],[26,4.57]],"id":42130949},{"atl":[[330,2.7],[240,0.24]],"id":42130949},{"atb":[[5.1,16.15],[5.2,4.33],[4.2,41.12]],"id":38407646},{"atl":[[20,8.2],[11,5.52],[15,9.19]],"id":38407646},{"atb":[[4.5,16.57],[3.85,3.22],[4.6,2.5],[3.8,38.93]],"id":43154456},{"atl":[[19.5,8.2],[10.5,6.1],[14,8.38]],"id":43154456},{"atb":[[2.06,54.34],[1.85,136.54],[2.1,16.54]],"id":43154457},{"atl":[[4.8,30.54],[3.6,22.32],[6,8.2]],"id":43154457},{"atb":[[2.06,121.74],[2.38,13.19],[2.34,43.3]],"id":36087680},{"atl":[[7.2,8.2],[5.5,28.67],[4.2,18.13]],"id":36087680}],"con":true,"img":false}]}
{"op":"mcm","clk":"5306557164","pt":1646100856442,"mc":[{"id":"1.195395427","rc":[{"atb":[[10.5,10.53]],"id":37284251},{"atb":[[19,5.56]],"id":42130949},{"atb":[[2.5,51.28]],"id":38407646},{"atl":[[25,4.17]],"id":38407646},{"atb":[[2.46,6.44]],"id":43154456},{"atl":[[25,4.17]],"id":43154456},{"atb":[[1.12,86.62]],"id":36087680},{"atl":[[8.2,13.89]],"id":36087680}],"con":true,"img":false}]}
{"op":"mcm","clk":"5306557166","pt":1646100856539,"mc":[{"id":"1.195395427","rc":[{"atb":[[1.07,70.9]],"id":43154457},{"atl":[[8.6,13.16]],"id":43154457}],"con":true,"img":false}]}
{"op":"mcm","clk":"5306564712","pt":1646101011439,"mc":[{"id":"1.195395427","rc":[{"atb":[[1.01,2.23]],"id":43154456}],"con":true,"img":false}]}
{"op":"mcm","clk":"5306564716","pt":1646101011542,"mc":[{"id":"1.195395427","rc":[{"atl":[[1000,2.23]],"id":37284251},{"atb":[[1.01,2.23]],"id":38407646}],"con":true,"img":false}]}
{"op":"mcm","clk":"5306564720","pt":1646101011646,"mc":[{"id":"1.195395427","rc":[{"atb":[[1.01,0.73]],"id":43154456}],"con":true,"img":false}]}
{"op":"mcm","clk":"5306564722","pt":1646101011746,"mc":[{"id":"1.195395427","rc":[{"atl":[[1000,0.05]],"id":37284251},{"atb":[[1.01,0.7]],"id":38407646}],"con":true,"img":false}]}
{"op":"mcm","clk":"5306564725","pt":1646101011850,"mc":[{"id":"1.195395427","rc":[{"atb":[[1.01,0]],"id":43154456}],"con":true,"img":false}]}
{"op":"mcm","clk":"5306564730","pt":1646101011953,"mc":[{"id":"1.195395427","rc":[{"atb":[[5.1,0.73]],"id":43154456}],"con":true,"img":false}]}
{"op":"mcm","clk":"5306564736","pt":1646101012156,"mc":[{"id":"1.195395427","rc":[{"atb":[[1.01,0]],"id":38407646}],"con":true,"img":false}]}
{"op":"mcm","clk":"5306564741","pt":1646101012286,"mc":[{"id":"1.195395427","rc":[{"atb":[[5.3,0.7]],"id":38407646}],"con":true,"img":false}]}
{"op":"mcm","clk":"5306564747","pt":1646101012468,"mc":[{"id":"1.195395427","rc":[{"atl":[[1000,0]],"id":37284251}],"con":true,"img":false}]}
{"op":"mcm","clk":"5306564750","pt":1646101012571,"mc":[{"id":"1.195395427","rc":[{"atl":[[65,0.05]],"id":37284251}],"con":true,"img":false}]}
{"op":"mcm","clk":"5306565044","pt":1646101020260,"mc":[{"id":"1.195395427","rc":[{"atb":[[3,36]],"id":43154456}],"con":true,"img":false}]}
{"op":"mcm","clk":"5306566582","pt":1646101056821,"mc":[{"id":"1.195395427","rc":[{"atb":[[10.5,0]],"id":37284251},{"atb":[[19,0]],"id":42130949},{"atb":[[2.5,0]],"id":38407646},{"atl":[[25,0]],"id":38407646},{"atb":[[2.46,0]],"id":43154456},{"atl":[[25,0]],"id":43154456},{"atb":[[1.07,0]],"id":43154457},{"atl":[[8.6,0]],"id":43154457},{"atb":[[1.12,0]],"id":36087680},{"atl":[[8.2,0]],"id":36087680}],"con":true,"img":false}]}
{"op":"mcm","clk":"5306570030","pt":1646101131694,"mc":[{"id":"1.195395427","rc":[{"atb":[[1.04,2.23]],"id":37284251},{"spn":43.5,"spf":1.0,"id":37284251},{"spn":8.15,"spf":1.0,"id":38407646},{"spn":7.8,"spf":1.0,"id":43154456}],"con":true,"img":false}]}
{"op":"mcm","clk":"5306570036","pt":1646101131796,"mc":[{"id":"1.195395427","rc":[{"atb":[[1.04,0.16]],"id":37284251}],"con":true,"img":false}]}
{"op":"mcm","clk":"5306570042","pt":1646101132003,"mc":[{"id":"1.195395427","rc":[{"atb":[[1.04,0]],"id":37284251}],"con":true,"img":false}]}
{"op":"mcm","clk":"5306570045","pt":1646101132104,"mc":[{"id":"1.195395427","rc":[{"atb":[[23,0.16]],"id":37284251}],"con":true,"img":false}]}
{"op":"mcm","clk":"5306571179","pt":1646101156366,"mc":[{"id":"1.195395427","marketDefinition":{"bspMarket":true,"turnInPlayEnabled":false,"persistenceEnabled":false,"marketBaseRate":7.0,"eventId":"31270458","eventTypeId":"4339","numberOfWinners":1,"bettingType":"ODDS","marketType":"WIN","marketTime":"2022-03-01T03:42:00.000Z","suspendTime":"2022-03-01T03:42:00.000Z","bspReconciled":false,"complete":true,"inPlay":false,"crossMatching":true,"runnersVoidable":false,"numberOfActiveRunners":6,"betDelay":0,"status":"OPEN","runners":[{"status":"ACTIVE","sortPriority":1,"id":43154456,"name":"1. Buckle Up Zion"},{"status":"ACTIVE","sortPriority":2,"id":43154457,"name":"2. Rambo Bobbie"},{"status":"ACTIVE","sortPriority":3,"id":38407646,"name":"4. Hiccup Gus"},{"status":"ACTIVE","sortPriority":4,"id":42130949,"name":"5. Into The Fire"},{"status":"ACTIVE","sortPriority":5,"id":37284251,"name":"7. Shiffrin"},{"status":"ACTIVE","sortPriority":6,"id":36087680,"name":"8. White Poison"},{"status":"REMOVED","sortPriority":7,"removalDate":"2022-02-28T22:23:28.000Z","id":39979946,"name":"3. Marshall Giblet"}],"regulators":["MR_INT"],"venue":"Devonport","countryCode":"AU","discountAllowed":true,"timezone":"Australia/Sydney","openDate":"2022-03-01T02:00:00.000Z","version":4381058469,"name":"R5 452m Gr5","eventName":"Devonport (AUS) 1st Mar"},"rc":[],"con":true,"img":false}]}
{"op":"mcm","clk":"5306618759","pt":1646102198477,"mc":[{"id":"1.195395427","rc":[{"atb":[[22,0]],"id":37284251},{"spn":44.0,"spf":1.0,"id":37284251},{"atb":[[5.1,14.15]],"id":38407646}],"con":true,"img":false}]}
{"op":"mcm","clk":"5306618761","pt":1646102198578,"mc":[{"id":"1.195395427","rc":[{"atb":[[23,0.62]],"id":37284251},{"atb":[[5.5,2]],"id":38407646}],"con":true,"img":false}]}
{"op":"mcm","clk":"5306624485","pt":1646102305893,"mc":[{"id":"1.195395427","rc":[{"atb":[[5.2,2.14]],"id":38407646},{"spn":8.25,"spf":1.0,"id":38407646}],"con":true,"img":false}]}
{"op":"mcm","clk":"5306625000","pt":1646102314944,"mc":[{"id":"1.195395427","rc":[{"atb":[[4.3,3.06]],"id":38407646}],"con":true,"img":false}]}
{"op":"mcm","clk":"5306640495","pt":1646102641467,"mc":[{"id":"1.195395427","rc":[{"atb":[[2.16,0]],"id":43154457},{"spn":2.85,"spf":1.0,"id":43154457}],"con":true,"img":false}]}
{"op":"mcm","clk":"5306640503","pt":1646102641569,"mc":[{"id":"1.195395427","rc":[{"atb":[[2.36,2]],"id":43154457}],"con":true,"img":false}]}
{"op":"mcm","clk":"5306640602","pt":1646102643772,"mc":[{"id":"1.195395427","rc":[{"atl":[[3.5,5.15]],"id":43154457},{"atl":[[4.1,4.39]],"id":36087680}],"con":true,"img":false}]}
{"op":"mcm","clk":"5306640684","pt":1646102645372,"mc":[{"id":"1.195395427","rc":[{"atl":[[4.7,4.29]],"id":43154457}],"con":true,"img":false}]}
{"op":"mcm","clk":"5306640687","pt":1646102645473,"mc":[{"id":"1.195395427","rc":[{"atl":[[5.4,3.74]],"id":36087680}],"con":true,"img":false}]}
{"op":"mcm","clk":"5306645250","pt":1646102761124,"mc":[{"id":"1.195395427","rc":[{"atl":[[3.5,0]],"id":43154457},{"spn":2.98,"spf":1.0,"id":43154457},{"spn":3.24,"spf":1.0,"id":36087680}],"con":true,"img":false}]}
{"op":"mcm","clk":"5306645364","pt":1646102764138,"mc":[{"id":"1.195395427","rc":[{"atl":[[4.1,0]],"id":36087680}],"con":true,"img":false}]}
{"op":"mcm","clk":"5306645417","pt":1646102765727,"mc":[{"id":"1.195395427","rc":[{"atl":[[4.7,0]],"id":43154457}],"con":true,"img":false}]}
{"op":"mcm","clk":"5306645479","pt":1646102767109,"mc":[{"id":"1.195395427","rc":[{"atl":[[3.5,4.25]],"id":43154457},{"atl":[[4.1,3.63]],"id":36087680}],"con":true,"img":false}]}
{"op":"mcm","clk":"5306645633","pt":1646102771815,"mc":[{"id":"1.195395427","rc":[{"atl":[[5.4,0]],"id":36087680}],"con":true,"img":false}]}
{"op":"mcm","clk":"5306645873","pt":1646102777742,"mc":[{"id":"1.195395427","rc":[{"atl":[[4.7,4.29]],"id":43154457}],"con":true,"img":false}]}
{"op":"mcm","clk":"5306645877","pt":1646102777847,"mc":[{"id":"1.195395427","rc":[{"atl":[[5.4,3.74]],"id":36087680}],"con":true,"img":false}]}
{"op":"mcm","clk":"5306657708","pt":1646102884333,"mc":[{"id":"1.195395427","rc":[{"atl":[[3.5,0]],"id":43154457}],"con":true,"img":false}]}
{"op":"mcm","clk":"5306657833","pt":1646102887312,"mc":[{"id":"1.195395427","rc":[{"atl":[[4.1,0]],"id":36087680}],"con":true,"img":false}]}
{"op":"mcm","clk":"5306657939","pt":1646102890327,"mc":[{"id":"1.195395427","rc":[{"atl":[[3.5,4.25]],"id":43154457},{"atl":[[4.1,3.63]],"id":36087680}],"con":true,"img":false}]}
{"op":"mcm","clk":"5306658312","pt":1646102898419,"mc":[{"id":"1.195395427","rc":[{"atl":[[4.7,0]],"id":43154457}],"con":true,"img":false}]}
{"op":"mcm","clk":"5306658574","pt":1646102904267,"mc":[{"id":"1.195395427","rc":[{"atl":[[5.4,0]],"id":36087680}],"con":true,"img":false}]}
{"op":"mcm","clk":"5306658846","pt":1646102910378,"mc":[{"id":"1.195395427","rc":[{"atl":[[4.7,4.29]],"id":43154457},{"atl":[[5.4,3.74]],"id":36087680}],"con":true,"img":false}]}
{"op":"mcm","clk":"5306662944","pt":1646103007594,"mc":[{"id":"1.195395427","rc":[{"atl":[[3.5,0]],"id":43154457}],"con":true,"img":false}]}
{"op":"mcm","clk":"5306663085","pt":1646103010616,"mc":[{"id":"1.195395427","rc":[{"atl":[[4.1,0]],"id":36087680}],"con":true,"img":false}]}
{"op":"mcm","clk":"5306663195","pt":1646103013487,"mc":[{"id":"1.195395427","rc":[{"atl":[[3.5,4.25]],"id":43154457},{"atl":[[4.1,3.63]],"id":36087680}],"con":true,"img":false}]}
{"op":"mcm","clk":"5306663761","pt":1646103027546,"mc":[{"id":"1.195395427","rc":[{"atl":[[4.7,0]],"id":43154457}],"con":true,"img":false}]}
{"op":"mcm","clk":"5306664003","pt":1646103033640,"mc":[{"id":"1.195395427","rc":[{"atl":[[5.4,0]],"id":36087680}],"con":true,"img":false}]}
{"op":"mcm","clk":"5306664307","pt":1646103039559,"mc":[{"id":"1.195395427","rc":[{"atl":[[4.7,4.29]],"id":43154457}],"con":true,"img":false}]}
{"op":"mcm","clk":"5306664311","pt":1646103039663,"mc":[{"id":"1.195395427","rc":[{"atl":[[5.4,3.74]],"id":36087680}],"con":true,"img":false}]}
{"op":"mcm","clk":"5306668090","pt":1646103130773,"mc":[{"id":"1.195395427","rc":[{"atl":[[3.5,0]],"id":43154457}],"con":true,"img":false}]}
{"op":"mcm","clk":"5306668205","pt":1646103133691,"mc":[{"id":"1.195395427","rc":[{"atl":[[4.1,0]],"id":36087680}],"con":true,"img":false}]}
{"op":"mcm","clk":"5306668322","pt":1646103136707,"mc":[{"id":"1.195395427","rc":[{"atl":[[3.5,4.25]],"id":43154457},{"atl":[[4.1,3.63]],"id":36087680}],"con":true,"img":false}]}
{"op":"mcm","clk":"5306669364","pt":1646103160207,"mc":[{"id":"1.195395427","rc":[{"atl":[[4.7,0]],"id":43154457}],"con":true,"img":false}]}
{"op":"mcm","clk":"5306669612","pt":1646103166201,"mc":[{"id":"1.195395427","rc":[{"atl":[[5.4,0]],"id":36087680}],"con":true,"img":false}]}
{"op":"mcm","clk":"5306669846","pt":1646103171725,"mc":[{"id":"1.195395427","rc":[{"atl":[[4.7,4.29]],"id":43154457}],"con":true,"img":false}]}
{"op":"mcm","clk":"5306669852","pt":1646103171832,"mc":[{"id":"1.195395427","rc":[{"atl":[[5.4,3.74]],"id":36087680}],"con":true,"img":false}]}
{"op":"mcm","clk":"5306671837","pt":1646103222316,"mc":[{"id":"1.195395427","rc":[{"atb":[[4.7,3]],"id":43154456},{"atb":[[1.86,26.3]],"id":43154457},{"spn":2.93,"spf":1.0,"id":43154457},{"atb":[[2.08,20.95]],"id":36087680}],"con":true,"img":false}]}
{"op":"mcm","clk":"5306671844","pt":1646103222421,"mc":[{"id":"1.195395427","rc":[{"atb":[[5.1,0],[1.01,2.23]],"id":43154456}],"con":true,"img":false}]}
{"op":"mcm","clk":"5306671853","pt":1646103222623,"mc":[{"id":"1.195395427","rc":[{"atb":[[1.01,0.73]],"id":43154456}],"con":true,"img":false}]}
{"op":"mcm","clk":"5306671863","pt":1646103222828,"mc":[{"id":"1.195395427","rc":[{"atb":[[1.01,0]],"id":43154456}],"con":true,"img":false}]}
{"op":"mcm","clk":"5306671867","pt":1646103222929,"mc":[{"id":"1.195395427","rc":[{"atb":[[4.8,0.73]],"id":43154456}],"con":true,"img":false}]}
{"op":"mcm","clk":"5306673064","pt":1646103253975,"mc":[{"id":"1.195395427","rc":[{"atl":[[3.5,0]],"id":43154457}],"con":true,"img":false}]}
{"op":"mcm","clk":"5306673181","pt":1646103256893,"mc":[{"id":"1.195395427","rc":[{"atl":[[4.1,0]],"id":36087680}],"con":true,"img":false}]}
{"op":"mcm","clk":"5306673225","pt":1646103258071,"mc":[{"id":"1.195395427","rc":[{"atb":[[1.86,0]],"id":43154457}],"con":true,"img":false}]}
{"op":"mcm","clk":"5306673293","pt":1646103259860,"mc":[{"id":"1.195395427","rc":[{"atl":[[3.5,4.25]],"id":43154457},{"atl":[[4.1,3.63]],"id":36087680}],"con":true,"img":false}]}
{"op":"mcm","clk":"5306673313","pt":1646103260374,"mc":[{"id":"1.195395427","rc":[{"atb":[[2.08,0]],"id":36087680}],"con":true,"img":false}]}
{"op":"mcm","clk":"5306673432","pt":1646103263695,"mc":[{"id":"1.195395427","rc":[{"atb":[[1.86,26.3]],"id":43154457}],"con":true,"img":false}]}
{"op":"mcm","clk":"5306673547","pt":1646103266667,"mc":[{"id":"1.195395427","rc":[{"atb":[[2.08,20.95]],"id":36087680}],"con":true,"img":false}]}
{"op":"mcm","clk":"5306674522","pt":1646103292119,"mc":[{"id":"1.195395427","rc":[{"atb":[[1.01,2.23]],"id":43154456},{"spn":7.75,"spf":1.0,"id":43154456},{"atl":[[4.7,0]],"id":43154457}],"con":true,"img":false}]}
{"op":"mcm","clk":"5306674529","pt":1646103292322,"mc":[{"id":"1.195395427","rc":[{"atb":[[4.8,0],[1.01,0.73]],"id":43154456}],"con":true,"img":false}]}
{"op":"mcm","clk":"5306674534","pt":1646103292530,"mc":[{"id":"1.195395427","rc":[{"atb":[[1.01,0]],"id":43154456}],"con":true,"img":false}]}
{"op":"mcm","clk":"5306674536","pt":1646103292633,"mc":[{"id":"1.195395427","rc":[{"atb":[[5.1,0.73]],"id":43154456}],"con":true,"img":false}]}
{"op":"mcm","clk":"5306674553","pt":1646103293201,"mc":[{"id":"1.195395427","rc":[{"atb":[[1.85,0]],"id":43154457},{"atb":[[2.06,0]],"id":36087680}],"con":true,"img":false}]}
{"op":"mcm","clk":"5306674559","pt":1646103293304,"mc":[{"id":"1.195395427","rc":[{"atb":[[1.87,136.54]],"id":43154457},{"atb":[[2.1,121.74]],"id":36087680}],"con":true,"img":false}]}
{"op":"mcm","clk":"5306674741","pt":1646103298019,"mc":[{"id":"1.195395427","rc":[{"atb":[[1.86,0]],"id":43154457},{"atb":[[2.08,0]],"id":36087680}],"con":true,"img":false}]}
{"op":"mcm","clk":"5306674750","pt":1646103298226,"mc":[{"id":"1.195395427","rc":[{"atl":[[5.4,0]],"id":36087680}],"con":true,"img":false}]}
{"op":"mcm","clk":"5306675089","pt":1646103304140,"mc":[{"id":"1.195395427","rc":[{"atl":[[4.7,4.29]],"id":43154457}],"con":true,"img":false}]}
{"op":"mcm","clk":"5306675096","pt":1646103304240,"mc":[{"id":"1.195395427","rc":[{"atb":[[1.88,25.71]],"id":43154457},{"atb":[[2.12,20.2]],"id":36087680},{"atl":[[5.4,3.74]],"id":36087680}],"con":true,"img":false}]}
{"op":"mcm","clk":"5306677562","pt":1646103361999,"mc":[{"id":"1.195395427","rc":[{"spn":7.8,"spf":1.0,"id":43154456},{"atb":[[1.87,0]],"id":43154457},{"atb":[[2.1,0]],"id":36087680}],"con":true,"img":false}]}
{"op":"mcm","clk":"5306677565","pt":1646103362100,"mc":[{"id":"1.195395427","rc":[{"atb":[[1.89,136.54]],"id":43154457},{"atb":[[2.14,121.74]],"id":36087680}],"con":true,"img":false}]}
{"op":"mcm","clk":"5306677816","pt":1646103367093,"mc":[{"id":"1.195395427","rc":[{"atb":[[1.88,0]],"id":43154457},{"atb":[[2.12,0]],"id":36087680}],"con":true,"img":false}]}
{"op":"mcm","clk":"5306678067","pt":1646103372951,"mc":[{"id":"1.195395427","rc":[{"atb":[[1.9,25.13]],"id":43154457},{"atb":[[2.16,19.5]],"id":36087680}],"con":true,"img":false}]}
{"op":"mcm","clk":"5306678239","pt":1646103377116,"mc":[{"id":"1.195395427","rc":[{"atl":[[3.5,0]],"id":43154457}],"con":true,"img":false}]}
{"op":"mcm","clk":"5306678379","pt":1646103380247,"mc":[{"id":"1.195395427","rc":[{"atl":[[4.1,0]],"id":36087680}],"con":true,"img":false}]}
{"op":"mcm","clk":"5306678416","pt":1646103380761,"mc":[{"id":"1.195395427","rc":[{"atb":[[1.9,0]],"id":43154457}],"con":true,"img":false}]}
{"op":"mcm","clk":"5306678514","pt":1646103383128,"mc":[{"id":"1.195395427","rc":[{"atl":[[3.5,4.25]],"id":43154457},{"atl":[[4.1,3.63]],"id":36087680}],"con":true,"img":false}]}
{"op":"mcm","clk":"5306678522","pt":1646103383330,"mc":[{"id":"1.195395427","rc":[{"atb":[[2.16,0]],"id":36087680}],"con":true,"img":false}]}
{"op":"mcm","clk":"5306678635","pt":1646103386051,"mc":[{"id":"1.195395427","rc":[{"atb":[[1.9,25.13]],"id":43154457}],"con":true,"img":false}]}
{"op":"mcm","clk":"5306678742","pt":1646103389129,"mc":[{"id":"1.195395427","rc":[{"atb":[[2.16,19.5]],"id":36087680}],"con":true,"img":false}]}
{"op":"mcm","clk":"5306679256","pt":1646103400419,"mc":[{"id":"1.195395427","marketDefinition":{"bspMarket":true,"turnInPlayEnabled":false,"persistenceEnabled":false,"marketBaseRate":7.0,"eventId":"31270458","eventTypeId":"4339","numberOfWinners":1,"bettingType":"ODDS","marketType":"WIN","marketTime":"2022-03-01T04:22:00.000Z","suspendTime":"2022-03-01T04:22:00.000Z","bspReconciled":false,"complete":true,"inPlay":false,"crossMatching":true,"runnersVoidable":false,"numberOfActiveRunners":6,"betDelay":0,"status":"OPEN","runners":[{"status":"ACTIVE","sortPriority":1,"id":43154456,"name":"1. Buckle Up Zion"},{"status":"ACTIVE","sortPriority":2,"id":43154457,"name":"2. Rambo Bobbie"},{"status":"ACTIVE","sortPriority":3,"id":38407646,"name":"4. Hiccup Gus"},{"status":"ACTIVE","sortPriority":4,"id":42130949,"name":"5. Into The Fire"},{"status":"ACTIVE","sortPriority":5,"id":37284251,"name":"7. Shiffrin"},{"status":"ACTIVE","sortPriority":6,"id":36087680,"name":"8. White Poison"},{"status":"REMOVED","sortPriority":7,"removalDate":"2022-02-28T22:23:28.000Z","id":39979946,"name":"3. Marshall Giblet"}],"regulators":["MR_INT"],"venue":"Devonport","countryCode":"AU","discountAllowed":true,"timezone":"Australia/Sydney","openDate":"2022-03-01T02:00:00.000Z","version":4381084677,"name":"R5 452m Gr5","eventName":"Devonport (AUS) 1st Mar"},"rc":[],"con":true,"img":false}]}
{"op":"mcm","clk":"5306680145","pt":1646103424383,"mc":[{"id":"1.195395427","rc":[{"atl":[[4.7,0]],"id":43154457}],"con":true,"img":false}]}
{"op":"mcm","clk":"5306680312","pt":1646103430096,"mc":[{"id":"1.195395427","rc":[{"atb":[[1.89,0]],"id":43154457},{"atb":[[2.14,0]],"id":36087680}],"con":true,"img":false}]}
{"op":"mcm","clk":"5306680317","pt":1646103430198,"mc":[{"id":"1.195395427","rc":[{"atb":[[1.91,136.54]],"id":43154457},{"atb":[[2.18,121.74]],"id":36087680}],"con":true,"img":false}]}
{"op":"mcm","clk":"5306680329","pt":1646103430509,"mc":[{"id":"1.195395427","rc":[{"atl":[[5.4,0]],"id":36087680}],"con":true,"img":false}]}
{"op":"mcm","clk":"5306680467","pt":1646103435122,"mc":[{"id":"1.195395427","rc":[{"atb":[[1.9,0]],"id":43154457},{"atb":[[2.16,0]],"id":36087680}],"con":true,"img":false}]}
{"op":"mcm","clk":"5306680503","pt":1646103436298,"mc":[{"id":"1.195395427","rc":[{"atl":[[4.7,4.29]],"id":43154457}],"con":true,"img":false}]}
{"op":"mcm","clk":"5306680508","pt":1646103436503,"mc":[{"id":"1.195395427","rc":[{"atl":[[5.4,3.74]],"id":36087680}],"con":true,"img":false}]}
{"op":"mcm","clk":"5306680673","pt":1646103440908,"mc":[{"id":"1.195395427","rc":[{"atb":[[1.92,24.59]],"id":43154457},{"atb":[[2.2,18.85]],"id":36087680}],"con":true,"img":false}]}
{"op":"mcm","clk":"5306680809","pt":1646103445727,"mc":[{"id":"1.195395427","rc":[{"atb":[[14.5,6.87]],"id":37284251},{"atb":[[5.4,4.04]],"id":38407646},{"atb":[[4.8,6.13]],"id":43154456},{"atb":[[1.93,88.11]],"id":43154457},{"atb":[[2.22,49.49]],"id":36087680}],"con":true,"img":false}]}
{"op":"mcm","clk":"5306680814","pt":1646103445829,"mc":[{"id":"1.195395427","rc":[{"atb":[[1.01,2.23]],"id":43154456}],"con":true,"img":false}]}
{"op":"mcm","clk":"5306680817","pt":1646103445930,"mc":[{"id":"1.195395427","rc":[{"atb":[[5.1,0]],"id":43154456}],"con":true,"img":false}]}
{"op":"mcm","clk":"5306680821","pt":1646103446032,"mc":[{"id":"1.195395427","rc":[{"atb":[[1.01,0.73]],"id":43154456}],"con":true,"img":false}]}
{"op":"mcm","clk":"5306680823","pt":1646103446136,"mc":[{"id":"1.195395427","rc":[{"atb":[[1.01,0]],"id":43154456}],"con":true,"img":false}]}
{"op":"mcm","clk":"5306680829","pt":1646103446238,"mc":[{"id":"1.195395427","rc":[{"atb":[[4.9,0.73]],"id":43154456}],"con":true,"img":false}]}
{"op":"mcm","clk":"5306680955","pt":1646103449511,"mc":[{"id":"1.195395427","rc":[{"atb":[[4.7,0]],"id":43154456},{"atb":[[1.92,0]],"id":43154457},{"atb":[[2.2,0]],"id":36087680}],"con":true,"img":false}]}
{"op":"mcm","clk":"5306681050","pt":1646103452528,"mc":[{"id":"1.195395427","rc":[{"atb":[[4.8,0]],"id":43154456}],"con":true,"img":false}]}
{"op":"mcm","clk":"5306681144","pt":1646103455545,"mc":[{"id":"1.195395427","rc":[{"atb":[[1.2,2.23]],"id":43154456}],"con":true,"img":false}]}
{"op":"mcm","clk":"5306681153","pt":1646103455850,"mc":[{"id":"1.195395427","rc":[{"atb":[[1.2,1.9]],"id":43154456}],"con":true,"img":false}]}
{"op":"mcm","clk":"5306681155","pt":1646103455953,"mc":[{"id":"1.195395427","rc":[{"atb":[[4.7,6.13]],"id":43154456}],"con":true,"img":false}]}
{"op":"mcm","clk":"5306681163","pt":1646103456159,"mc":[{"id":"1.195395427","rc":[{"atb":[[1.2,0]],"id":43154456}],"con":true,"img":false}]}
{"op":"mcm","clk":"5306681169","pt":1646103456259,"mc":[{"id":"1.195395427","rc":[{"atb":[[5,3.9]],"id":43154456}],"con":true,"img":false}]}
{"op":"mcm","clk":"5306681177","pt":1646103456464,"mc":[{"id":"1.195395427","rc":[{"atb":[[1.94,24.07]],"id":43154457},{"atb":[[2.24,18.24]],"id":36087680}],"con":true,"img":false}]}
{"op":"mcm","clk":"5306681277","pt":1646103459531,"mc":[{"id":"1.195395427","rc":[{"atb":[[1.93,0]],"id":43154457},{"atb":[[2.22,0]],"id":36087680}],"con":true,"img":false}]}
{"op":"mcm","clk":"5306681409","pt":1646103463271,"mc":[{"id":"1.195395427","rc":[{"atb":[[1.95,78.84]],"id":43154457},{"atb":[[2.26,44.9]],"id":36087680}],"con":true,"img":false}]}
{"op":"mcm","clk":"5306681555","pt":1646103467370,"mc":[{"id":"1.195395427","rc":[{"atb":[[1.94,0]],"id":43154457},{"atb":[[2.24,0]],"id":36087680}],"con":true,"img":false}]}
{"op":"mcm","clk":"5306681766","pt":1646103472852,"mc":[{"id":"1.195395427","rc":[{"atb":[[1.96,23.56]],"id":43154457},{"atb":[[2.28,17.15]],"id":36087680}],"con":true,"img":false}]}
{"op":"mcm","clk":"5306681826","pt":1646103475051,"mc":[{"id":"1.195395427","rc":[{"atb":[[1.95,0]],"id":43154457},{"atb":[[2.26,2]],"id":36087680}],"con":true,"img":false}]}
{"op":"mcm","clk":"5306681936","pt":1646103478893,"mc":[{"id":"1.195395427","rc":[{"atb":[[1.97,69.56]],"id":43154457},{"atb":[[2.3,36.29]],"id":36087680}],"con":true,"img":false}]}
{"op":"mcm","clk":"5306682059","pt":1646103482788,"mc":[{"id":"1.195395427","rc":[{"atb":[[1.96,0]],"id":43154457},{"atb":[[2.28,0]],"id":36087680}],"con":true,"img":false}]}
{"op":"mcm","clk":"5306682242","pt":1646103488513,"mc":[{"id":"1.195395427","rc":[{"spn":7.75,"spf":1.0,"id":43154456},{"atb":[[1.98,23.09]],"id":43154457},{"atb":[[2.4,9.24]],"id":36087680},{"spn":3.25,"spf":1.0,"id":36087680}],"con":true,"img":false}]}
{"op":"mcm","clk":"5306682324","pt":1646103490816,"mc":[{"id":"1.195395427","rc":[{"atb":[[1.97,0]],"id":43154457},{"atb":[[2.3,0]],"id":36087680}],"con":true,"img":false}]}
{"op":"mcm","clk":"5306682419","pt":1646103494396,"mc":[{"id":"1.195395427","rc":[{"atb":[[1.99,60.28]],"id":43154457},{"atb":[[2.42,13.86]],"id":36087680}],"con":true,"img":false}]}
{"op":"mcm","clk":"5306682493","pt":1646103497202,"mc":[{"id":"1.195395427","rc":[{"atb":[[14,0]],"id":37284251},{"atb":[[1.91,0]],"id":43154457}],"con":true,"img":false}]}
{"op":"mcm","clk":"5306682498","pt":1646103497306,"mc":[{"id":"1.195395427","rc":[{"atb":[[15,10.28]],"id":37284251},{"atb":[[2,136.54]],"id":43154457}],"con":true,"img":false}]}
{"op":"mcm","clk":"5306682526","pt":1646103498125,"mc":[{"id":"1.195395427","rc":[{"atb":[[1.98,0]],"id":43154457},{"atb":[[2.4,0]],"id":36087680}],"con":true,"img":false}]}
{"op":"mcm","clk":"5306682567","pt":1646103499605,"mc":[{"id":"1.195395427","rc":[{"atb":[[14.5,0]],"id":37284251},{"atb":[[1.99,0]],"id":43154457}],"con":true,"img":false}]}
{"op":"mcm","clk":"5306682590","pt":1646103500421,"mc":[{"id":"1.195395427","rc":[{"atl":[[3.5,0]],"id":43154457}],"con":true,"img":false}]}
{"op":"mcm","clk":"5306682610","pt":1646103501189,"mc":[{"id":"1.195395427","rc":[{"atb":[[2.42,0]],"id":36087680}],"con":true,"img":false}]}
{"op":"mcm","clk":"5306682666","pt":1646103503231,"mc":[{"id":"1.195395427","rc":[{"atb":[[15.5,6.4]],"id":37284251},{"atb":[[2.02,51.01]],"id":43154457}],"con":true,"img":false}]}
{"op":"mcm","clk":"5306682672","pt":1646103503435,"mc":[{"id":"1.195395427","rc":[{"atl":[[4.1,0]],"id":36087680}],"con":true,"img":false}]}
{"op":"mcm","clk":"5306682687","pt":1646103503795,"mc":[{"id":"1.195395427","rc":[{"atb":[[2.02,73.19]],"id":43154457},{"atb":[[2.44,9.7]],"id":36087680}],"con":true,"img":false}]}
{"op":"mcm","clk":"5306682720","pt":1646103505020,"mc":[{"id":"1.195395427","rc":[{"atb":[[2.2,52.79]],"id":36087680}],"con":true,"img":false}]}
{"op":"mcm","clk":"5306682757","pt":1646103506302,"mc":[{"id":"1.195395427","rc":[{"atl":[[3.5,4.25]],"id":43154457},{"atl":[[4.1,3.63]],"id":36087680}],"con":true,"img":false}]}
{"op":"mcm","clk":"5306682800","pt":1646103508598,"mc":[{"id":"1.195395427","rc":[{"atb":[[2.02,22.18]],"id":43154457},{"atb":[[2.2,0]],"id":36087680}],"con":true,"img":false}]}
{"op":"mcm","clk":"5306682875","pt":1646103511412,"mc":[{"id":"1.195395427","rc":[{"atb":[[2.02,0]],"id":43154457},{"atb":[[2.44,0]],"id":36087680}],"con":true,"img":false}]}
{"op":"mcm","clk":"5306682901","pt":1646103512332,"mc":[{"id":"1.195395427","rc":[{"atb":[[2.12,27.82]],"id":43154457},{"atb":[[2.4,21.83]],"id":36087680}],"con":true,"img":false}]}
{"op":"mcm","clk":"5306682931","pt":1646103513204,"mc":[{"id":"1.195395427","rc":[{"atb":[[2,0]],"id":43154457}],"con":true,"img":false}]}
{"op":"mcm","clk":"5306682933","pt":1646103513304,"mc":[{"id":"1.195395427","rc":[{"atb":[[1.85,136.54]],"id":43154457}],"con":true,"img":false}]}
{"op":"mcm","clk":"5306683044","pt":1646103517255,"mc":[{"id":"1.195395427","rc":[{"atb":[[2.14,19.84]],"id":43154457},{"atb":[[2.42,15.28]],"id":36087680}],"con":true,"img":false}]}
{"op":"mcm","clk":"5306683140","pt":1646103520734,"mc":[{"id":"1.195395427","rc":[{"atb":[[2.12,0]],"id":43154457}],"con":true,"img":false}]}
{"op":"mcm","clk":"5306683249","pt":1646103524221,"mc":[{"id":"1.195395427","rc":[{"atb":[[2.14,0],[2.16,32.77]],"id":43154457}],"con":true,"img":false}]}
{"op":"mcm","clk":"5306683376","pt":1646103529342,"mc":[{"id":"1.195395427","rc":[{"atb":[[2.12,20.2]],"id":43154457}],"con":true,"img":false}]}
{"op":"mcm","clk":"5306683770","pt":1646103545971,"mc":[{"id":"1.195395427","rc":[{"atb":[[2.06,0]],"id":43154457},{"atb":[[2.34,0]],"id":36087680}],"con":true,"img":false}]}
{"op":"mcm","clk":"5306683774","pt":1646103546073,"mc":[{"id":"1.195395427","rc":[{"atb":[[2.18,54.34]],"id":43154457},{"atb":[[2.42,58.59]],"id":36087680}],"con":true,"img":false}]}
{"op":"mcm","clk":"5306683862","pt":1646103547970,"mc":[{"id":"1.195395427","rc":[{"atb":[[2.16,0]],"id":43154457}],"con":true,"img":false}]}
{"op":"mcm","clk":"5306683966","pt":1646103551604,"mc":[{"id":"1.195395427","rc":[{"atb":[[2.2,77.34]],"id":43154457},{"spn":3.26,"spf":1.0,"id":36087680}],"con":true,"img":false}]}
{"op":"mcm","clk":"5306684085","pt":1646103554579,"mc":[{"id":"1.195395427","rc":[{"atb":[[2.1,8.34]],"id":43154457},{"atb":[[2.38,6.66]],"id":36087680}],"con":true,"img":false}]}
{"op":"mcm","clk":"5306684109","pt":1646103555299,"mc":[{"id":"1.195395427","rc":[{"atb":[[2.12,0]],"id":43154457}],"con":true,"img":false}]}
{"op":"mcm","clk":"5306684180","pt":1646103556880,"mc":[{"id":"1.195395427","rc":[{"atl":[[4.7,0]],"id":43154457}],"con":true,"img":false}]}
{"op":"mcm","clk":"5306684231","pt":1646103558514,"mc":[{"id":"1.195395427","rc":[{"atb":[[2.2,0]],"id":43154457}],"con":true,"img":false}]}
{"op":"mcm","clk":"5306684291","pt":1646103560302,"mc":[{"id":"1.195395427","rc":[{"atb":[[2.12,20.2]],"id":43154457}],"con":true,"img":false}]}
{"op":"mcm","clk":"5306684331","pt":1646103561688,"mc":[{"id":"1.195395427","rc":[{"atb":[[15,0]],"id":37284251},{"atb":[[2.18,0]],"id":43154457}],"con":true,"img":false}]}
{"op":"mcm","clk":"5306684336","pt":1646103561793,"mc":[{"id":"1.195395427","rc":[{"atb":[[16,10.28]],"id":37284251},{"atb":[[2.14,54.34]],"id":43154457}],"con":true,"img":false}]}
{"op":"mcm","clk":"5306684348","pt":1646103562098,"mc":[{"id":"1.195395427","rc":[{"atb":[[1.86,107.91]],"id":43154457}],"con":true,"img":false}]}
{"op":"mcm","clk":"5306684356","pt":1646103562507,"mc":[{"id":"1.195395427","rc":[{"atb":[[1.01,2.23]],"id":43154456}],"con":true,"img":false}]}
{"op":"mcm","clk":"5306684363","pt":1646103562716,"mc":[{"id":"1.195395427","rc":[{"atb":[[1.01,0.73]],"id":43154456},{"atb":[[2.1,0]],"id":43154457},{"atb":[[2.38,0]],"id":36087680}],"con":true,"img":false}]}
{"op":"mcm","clk":"5306684367","pt":1646103562816,"mc":[{"id":"1.195395427","rc":[{"atl":[[5.4,0]],"id":36087680}],"con":true,"img":false}]}
{"op":"mcm","clk":"5306684371","pt":1646103562924,"mc":[{"id":"1.195395427","rc":[{"atb":[[4.9,0]],"id":43154456}],"con":true,"img":false}]}
{"op":"mcm","clk":"5306684379","pt":1646103563075,"mc":[{"id":"1.195395427","rc":[{"atb":[[1.01,0]],"id":43154456}],"con":true,"img":false}]}
{"op":"mcm","clk":"5306684380","pt":1646103563176,"mc":[{"id":"1.195395427","rc":[{"atb":[[5.1,0.73]],"id":43154456}],"con":true,"img":false}]}
{"op":"mcm","clk":"5306684388","pt":1646103563383,"mc":[{"id":"1.195395427","rc":[{"atb":[[2.46,5.1]],"id":36087680}],"con":true,"img":false}]}
{"op":"mcm","clk":"5306684396","pt":1646103563795,"mc":[{"id":"1.195395427","rc":[{"atb":[[15.5,0]],"id":37284251}],"con":true,"img":false}]}
{"op":"mcm","clk":"5306684434","pt":1646103565583,"mc":[{"id":"1.195395427","rc":[{"atb":[[2.4,0]],"id":36087680}],"con":true,"img":false}]}
{"op":"mcm","clk":"5306684494","pt":1646103567386,"mc":[{"id":"1.195395427","rc":[{"atb":[[16.5,5.98]],"id":37284251}],"con":true,"img":false}]}
{"op":"mcm","clk":"5306684498","pt":1646103567589,"mc":[{"id":"1.195395427","rc":[{"atb":[[2.12,0]],"id":43154457},{"atb":[[2.42,43.3]],"id":36087680}],"con":true,"img":false}]}
{"op":"mcm","clk":"5306684524","pt":1646103568715,"mc":[{"id":"1.195395427","rc":[{"atl":[[5.4,3.74]],"id":36087680}],"con":true,"img":false}]}
{"op":"mcm","clk":"5306684529","pt":1646103568817,"mc":[{"id":"1.195395427","rc":[{"atb":[[2.46,12.02]],"id":36087680}],"con":true,"img":false}]}
{"op":"mcm","clk":"5306684536","pt":1646103569124,"mc":[{"id":"1.195395427","rc":[{"atl":[[4.7,4.29]],"id":43154457}],"con":true,"img":false}]}
{"op":"mcm","clk":"5306684544","pt":1646103569277,"mc":[{"id":"1.195395427","rc":[{"atb":[[2.2,25.52]],"id":36087680}],"con":true,"img":false}]}
{"op":"mcm","clk":"5306684693","pt":1646103573398,"mc":[{"id":"1.195395427","rc":[{"atb":[[1.87,26.01]],"id":43154457},{"atb":[[2.22,18.55]],"id":36087680}],"con":true,"img":false}]}
{"op":"mcm","clk":"5306684718","pt":1646103574622,"mc":[{"id":"1.195395427","rc":[{"atb":[[2.18,8.55]],"id":43154457}],"con":true,"img":false}]}
{"op":"mcm","clk":"5306684770","pt":1646103576310,"mc":[{"id":"1.195395427","rc":[{"atb":[[1.86,0]],"id":43154457},{"atb":[[2.2,0]],"id":36087680}],"con":true,"img":false}]}
{"op":"mcm","clk":"5306684814","pt":1646103577794,"mc":[{"id":"1.195395427","rc":[{"atb":[[2.14,0]],"id":43154457},{"atb":[[2.42,0]],"id":36087680}],"con":true,"img":false}]}
{"op":"mcm","clk":"5306684818","pt":1646103577898,"mc":[{"id":"1.195395427","rc":[{"atb":[[2.06,54.34]],"id":43154457},{"atb":[[2.34,43.3]],"id":36087680}],"con":true,"img":false}]}
{"op":"mcm","clk":"5306684825","pt":1646103578204,"mc":[{"id":"1.195395427","rc":[{"atb":[[1.87,0]],"id":43154457}],"con":true,"img":false}]}
{"op":"mcm","clk":"5306684870","pt":1646103579897,"mc":[{"id":"1.195395427","rc":[{"atb":[[1.88,73.92]],"id":43154457},{"atb":[[2.24,54.13]],"id":36087680}],"con":true,"img":false}]}
{"op":"mcm","clk":"5306684899","pt":1646103580512,"mc":[{"id":"1.195395427","rc":[{"atb":[[2.22,0]],"id":36087680}],"con":true,"img":false}]}
{"op":"mcm","clk":"5306685011","pt":1646103583030,"mc":[{"id":"1.195395427","rc":[{"atb":[[1.89,25.42]],"id":43154457}],"con":true,"img":false}]}
{"op":"mcm","clk":"5306685063","pt":1646103584618,"mc":[{"id":"1.195395427","rc":[{"atb":[[2.46,6.92]],"id":36087680}],"con":true,"img":false}]}
{"op":"mcm","clk":"5306685083","pt":1646103585028,"mc":[{"id":"1.195395427","rc":[{"atb":[[1.88,0]],"id":43154457}],"con":true,"img":false}]}
{"op":"mcm","clk":"5306685109","pt":1646103585951,"mc":[{"id":"1.195395427","rc":[{"atb":[[2.26,19.96]],"id":36087680}],"con":true,"img":false}]}
{"op":"mcm","clk":"5306685222","pt":1646103588713,"mc":[{"id":"1.195395427","rc":[{"atb":[[1.9,68.65]],"id":43154457},{"atb":[[2.24,0]],"id":36087680}],"con":true,"img":false}]}
{"op":"mcm","clk":"5306685343","pt":1646103592348,"mc":[{"id":"1.195395427","rc":[{"atb":[[2.28,27.69]],"id":36087680}],"con":true,"img":false}]}
{"op":"mcm","clk":"5306685360","pt":1646103592757,"mc":[{"id":"1.195395427","rc":[{"atb":[[2.18,0]],"id":43154457},{"atb":[[2.46,0]],"id":36087680}],"con":true,"img":false}]}
{"op":"mcm","clk":"5306685380","pt":1646103593431,"mc":[{"id":"1.195395427","rc":[{"atb":[[1.89,0]],"id":43154457}],"con":true,"img":false}]}
{"op":"mcm","clk":"5306685382","pt":1646103593535,"mc":[{"id":"1.195395427","rc":[{"atb":[[2.1,6.77]],"id":43154457},{"atb":[[2.38,5.4]],"id":36087680}],"con":true,"img":false}]}
{"op":"mcm","clk":"5306685473","pt":1646103595756,"mc":[{"id":"1.195395427","rc":[{"atb":[[1.9,0]],"id":43154457},{"atb":[[2.26,2]],"id":36087680}],"con":true,"img":false}]}
{"op":"mcm","clk":"5306685573","pt":1646103598365,"mc":[{"id":"1.195395427","rc":[{"atb":[[1.91,19.29]],"id":43154457}],"con":true,"img":false}]}
{"op":"mcm","clk":"5306685587","pt":1646103598625,"mc":[{"id":"1.195395427","rc":[{"atb":[[2.1,15.95]],"id":43154457}],"con":true,"img":false}]}
{"op":"mcm","clk":"5306685604","pt":1646103599035,"mc":[{"id":"1.195395427","rc":[{"atb":[[2.38,12.72]],"id":36087680}],"con":true,"img":false}]}
{"op":"mcm","clk":"5306685610","pt":1646103599239,"mc":[{"id":"1.195395427","rc":[{"atb":[[1.86,57.01]],"id":43154457}],"con":true,"img":false}]}
{"op":"mcm","clk":"5306685698","pt":1646103601662,"mc":[{"id":"1.195395427","rc":[{"atb":[[2.3,6.48]],"id":36087680}],"con":true,"img":false}]}
{"op":"mcm","clk":"5306685760","pt":1646103602641,"mc":[{"id":"1.195395427","rc":[{"atb":[[1.86,0]],"id":43154457}],"con":true,"img":false}]}
{"op":"mcm","clk":"5306685848","pt":1646103604340,"mc":[{"id":"1.195395427","rc":[{"atb":[[2.28,0]],"id":36087680}],"con":true,"img":false}]}
{"op":"mcm","clk":"5306685932","pt":1646103606237,"mc":[{"id":"1.195395427","rc":[{"atb":[[1.92,89.81]],"id":43154457}],"con":true,"img":false}]}
{"op":"mcm","clk":"5306685990","pt":1646103608136,"mc":[{"id":"1.195395427","rc":[{"atb":[[2.4,19.08]],"id":36087680}],"con":true,"img":false}]}
{"op":"mcm","clk":"5306686011","pt":1646103608955,"mc":[{"id":"1.195395427","rc":[{"atb":[[1.91,0]],"id":43154457}],"con":true,"img":false}]}
{"op":"mcm","clk":"5306686105","pt":1646103611477,"mc":[{"id":"1.195395427","rc":[{"atb":[[2.3,0]],"id":36087680}],"con":true,"img":false}]}
{"op":"mcm","clk":"5306686191","pt":1646103614252,"mc":[{"id":"1.195395427","rc":[{"spn":7.8,"spf":1.0,"id":43154456},{"atb":[[1.93,24.33]],"id":43154457},{"spn":3.25,"spf":1.0,"id":36087680}],"con":true,"img":false}]}
{"op":"mcm","clk":"5306686288","pt":1646103616767,"mc":[{"id":"1.195395427","rc":[{"atb":[[1.92,0]],"id":43154457}],"con":true,"img":false}]}
{"op":"mcm","clk":"5306686304","pt":1646103616972,"mc":[{"id":"1.195395427","rc":[{"atb":[[2.42,13.35]],"id":36087680}],"con":true,"img":false}]}
{"op":"mcm","clk":"5306686412","pt":1646103620253,"mc":[{"id":"1.195395427","rc":[{"atb":[[1.94,80.83]],"id":43154457},{"atb":[[2.4,0]],"id":36087680}],"con":true,"img":false}]}
{"op":"mcm","clk":"5306686511","pt":1646103623683,"mc":[{"id":"1.195395427","rc":[{"atl":[[3.5,0]],"id":43154457}],"con":true,"img":false}]}
{"op":"mcm","clk":"5306686515","pt":1646103623887,"mc":[{"id":"1.195395427","rc":[{"atb":[[2.44,20.03]],"id":36087680}],"con":true,"img":false}]}
{"op":"mcm","clk":"5306686521","pt":1646103624092,"mc":[{"id":"1.195395427","rc":[{"atb":[[1.93,0]],"id":43154457},{"atb":[[2.42,0]],"id":36087680}],"con":true,"img":false}]}
{"op":"mcm","clk":"5306686566","pt":1646103625579,"mc":[{"id":"1.195395427","rc":[{"atb":[[1.94,0]],"id":43154457}],"con":true,"img":false}]}
{"op":"mcm","clk":"5306686571","pt":1646103625681,"mc":[{"id":"1.195395427","rc":[{"atb":[[17,8.11]],"id":37284251},{"atb":[[1.85,0]],"id":43154457},{"atb":[[2.34,0]],"id":36087680}],"con":true,"img":false}]}
{"op":"mcm","clk":"5306686575","pt":1646103625784,"mc":[{"id":"1.195395427","rc":[{"atb":[[16,0]],"id":37284251},{"atb":[[1.95,136.54]],"id":43154457},{"atb":[[2.42,43.3]],"id":36087680}],"con":true,"img":false}]}
{"op":"mcm","clk":"5306686595","pt":1646103626653,"mc":[{"id":"1.195395427","rc":[{"atl":[[4.1,0]],"id":36087680}],"con":true,"img":false}]}
{"op":"mcm","clk":"5306686680","pt":1646103629163,"mc":[{"id":"1.195395427","rc":[{"atb":[[16.5,0]],"id":37284251},{"atb":[[1.96,71.84]],"id":43154457}],"con":true,"img":false}]}
{"op":"mcm","clk":"5306686685","pt":1646103629367,"mc":[{"id":"1.195395427","rc":[{"atb":[[1.96,95.41]],"id":43154457},{"atb":[[2.46,14.02]],"id":36087680}],"con":true,"img":false}]}
{"op":"mcm","clk":"5306686690","pt":1646103629572,"mc":[{"id":"1.195395427","rc":[{"atl":[[3.5,4.25]],"id":43154457},{"atl":[[4.1,3.63]],"id":36087680}],"con":true,"img":false}]}
{"op":"mcm","clk":"5306686769","pt":1646103632594,"mc":[{"id":"1.195395427","rc":[{"atb":[[2.38,7.32]],"id":36087680}],"con":true,"img":false}]}
{"op":"mcm","clk":"5306686783","pt":1646103632910,"mc":[{"id":"1.195395427","rc":[{"atb":[[17.5,5.61]],"id":37284251},{"atb":[[2.44,0]],"id":36087680}],"con":true,"img":false}]}
{"op":"mcm","clk":"5306686838","pt":1646103634504,"mc":[{"id":"1.195395427","rc":[{"atb":[[1.96,71.84]],"id":43154457}],"con":true,"img":false}]}
{"op":"mcm","clk":"5306686895","pt":1646103636404,"mc":[{"id":"1.195395427","rc":[{"atb":[[2.48,21.04]],"id":36087680}],"con":true,"img":false}]}
{"op":"mcm","clk":"5306686910","pt":1646103636914,"mc":[{"id":"1.195395427","rc":[{"atb":[[2.46,0]],"id":36087680}],"con":true,"img":false}]}
{"op":"mcm","clk":"5306686995","pt":1646103639478,"mc":[{"id":"1.195395427","rc":[{"atb":[[1.97,23.32]],"id":43154457}],"con":true,"img":false}]}
{"op":"mcm","clk":"5306687047","pt":1646103641475,"mc":[{"id":"1.195395427","rc":[{"atb":[[1.96,0]],"id":43154457}],"con":true,"img":false}]}
{"op":"mcm","clk":"5306687050","pt":1646103641575,"mc":[{"id":"1.195395427","rc":[{"atb":[[2.46,5.1]],"id":36087680}],"con":true,"img":false}]}
{"op":"mcm","clk":"5306687078","pt":1646103642498,"mc":[{"id":"1.195395427","rc":[{"atb":[[2.44,15.71]],"id":36087680}],"con":true,"img":false}]}
{"op":"mcm","clk":"5306687138","pt":1646103644187,"mc":[{"id":"1.195395427","rc":[{"atb":[[2.38,0]],"id":36087680}],"con":true,"img":false}]}
{"op":"mcm","clk":"5306687168","pt":1646103645007,"mc":[{"id":"1.195395427","rc":[{"atb":[[1.98,62.86]],"id":43154457}],"con":true,"img":false}]}
{"op":"mcm","clk":"5306687291","pt":1646103649404,"mc":[{"id":"1.195395427","rc":[{"atb":[[1.97,0]],"id":43154457},{"atb":[[2.44,0]],"id":36087680}],"con":true,"img":false}]}
{"op":"mcm","clk":"5306687308","pt":1646103649815,"mc":[{"id":"1.195395427","rc":[{"atb":[[2.46,10.82]],"id":36087680}],"con":true,"img":false}]}
{"op":"mcm","clk":"5306687439","pt":1646103654733,"mc":[{"id":"1.195395427","rc":[{"atb":[[1.99,22.85]],"id":43154457},{"atb":[[2.5,14.72]],"id":36087680}],"con":true,"img":false}]}
{"op":"mcm","clk":"5306687489","pt":1646103656422,"mc":[{"id":"1.195395427","rc":[{"atb":[[2.42,0]],"id":36087680}],"con":true,"img":false}]}
{"op":"mcm","clk":"5306687492","pt":1646103656525,"mc":[{"id":"1.195395427","rc":[{"atb":[[2.5,58.03]],"id":36087680}],"con":true,"img":false}]}
{"op":"mcm","clk":"5306687514","pt":1646103657137,"mc":[{"id":"1.195395427","rc":[{"atb":[[1.98,0]],"id":43154457},{"atb":[[2.48,0]],"id":36087680}],"con":true,"img":false}]}
{"op":"mcm","clk":"5306687642","pt":1646103660706,"mc":[{"id":"1.195395427","rc":[{"atb":[[2,53.88]],"id":43154457},{"atb":[[2.2,77.28]],"id":36087680}],"con":true,"img":false}]}
{"op":"mcm","clk":"5306687692","pt":1646103662003,"mc":[{"id":"1.195395427","rc":[{"atb":[[2.5,43.3]],"id":36087680}],"con":true,"img":false}]}
{"op":"mcm","clk":"5306687784","pt":1646103664431,"mc":[{"id":"1.195395427","rc":[{"atb":[[1.99,0]],"id":43154457}],"con":true,"img":false}]}
{"op":"mcm","clk":"5306687823","pt":1646103665609,"mc":[{"id":"1.195395427","rc":[{"atb":[[2.46,5.71]],"id":36087680}],"con":true,"img":false}]}
{"op":"mcm","clk":"5306687858","pt":1646103667044,"mc":[{"id":"1.195395427","rc":[{"atb":[[2.22,18.55]],"id":36087680}],"con":true,"img":false}]}
{"op":"mcm","clk":"5306687931","pt":1646103669245,"mc":[{"id":"1.195395427","rc":[{"atb":[[2.2,0]],"id":36087680}],"con":true,"img":false}]}
{"op":"mcm","clk":"5306687968","pt":1646103670013,"mc":[{"id":"1.195395427","rc":[{"atb":[[2.02,21.55]],"id":43154457}],"con":true,"img":false}]}
{"op":"mcm","clk":"5306688039","pt":1646103672319,"mc":[{"id":"1.195395427","rc":[{"atb":[[2.22,0]],"id":36087680}],"con":true,"img":false}]}
{"op":"mcm","clk":"5306688062","pt":1646103672831,"mc":[{"id":"1.195395427","rc":[{"atb":[[2,0]],"id":43154457},{"atb":[[2.24,74.78],[2.5,0]],"id":36087680}],"con":true,"img":false}]}
{"op":"mcm","clk":"5306688070","pt":1646103672934,"mc":[{"id":"1.195395427","rc":[{"atb":[[2.34,43.3]],"id":36087680}],"con":true,"img":false}]}
{"op":"mcm","clk":"5306688122","pt":1646103674061,"mc":[{"id":"1.195395427","rc":[{"atb":[[2.46,0]],"id":36087680}],"con":true,"img":false}]}
{"op":"mcm","clk":"5306688250","pt":1646103676420,"mc":[{"id":"1.195395427","rc":[{"atb":[[2.12,26.94]],"id":43154457},{"atb":[[2.24,0]],"id":36087680},{"spn":3.22,"spf":1.0,"id":36087680}],"con":true,"img":false}]}
{"op":"mcm","clk":"5306688297","pt":1646103677751,"mc":[{"id":"1.195395427","rc":[{"atb":[[2.2,18.85]],"id":36087680}],"con":true,"img":false}]}
{"op":"mcm","clk":"5306688388","pt":1646103679957,"mc":[{"id":"1.195395427","rc":[{"atb":[[2.22,76.01]],"id":36087680}],"con":true,"img":false}]}
{"op":"mcm","clk":"5306688407","pt":1646103680368,"mc":[{"id":"1.195395427","rc":[{"atb":[[2.02,0]],"id":43154457}],"con":true,"img":false}]}
{"op":"mcm","clk":"5306688522","pt":1646103682729,"mc":[{"id":"1.195395427","rc":[{"atb":[[2.2,0]],"id":36087680}],"con":true,"img":false}]}
{"op":"mcm","clk":"5306688610","pt":1646103685033,"mc":[{"id":"1.195395427","rc":[{"atb":[[2.22,0]],"id":36087680}],"con":true,"img":false}]}
{"op":"mcm","clk":"5306688629","pt":1646103685544,"mc":[{"id":"1.195395427","rc":[{"atb":[[2.14,19.84]],"id":43154457}],"con":true,"img":false}]}
{"op":"mcm","clk":"5306688642","pt":1646103685952,"mc":[{"id":"1.195395427","rc":[{"atl":[[4.7,0]],"id":43154457},{"atb":[[2.38,6.05]],"id":36087680}],"con":true,"img":false}]}
{"op":"mcm","clk":"5306688727","pt":1646103687849,"mc":[{"id":"1.195395427","rc":[{"atb":[[17,0]],"id":37284251}],"con":true,"img":false}]}
{"op":"mcm","clk":"5306688730","pt":1646103687950,"mc":[{"id":"1.195395427","rc":[{"atb":[[18,8.11]],"id":37284251}],"con":true,"img":false}]}
{"op":"mcm","clk":"5306688745","pt":1646103688362,"mc":[{"id":"1.195395427","rc":[{"atb":[[1.97,23.32]],"id":36087680}],"con":true,"img":false}]}
{"op":"mcm","clk":"5306688757","pt":1646103688667,"mc":[{"id":"1.195395427","rc":[{"atb":[[2.12,0]],"id":43154457},{"atb":[[2.2,24.2]],"id":36087680}],"con":true,"img":false}]}
{"op":"mcm","clk":"5306688804","pt":1646103689654,"mc":[{"id":"1.195395427","rc":[{"atb":[[2.38,11.45]],"id":36087680}],"con":true,"img":false}]}
{"op":"mcm","clk":"5306688827","pt":1646103690275,"mc":[{"id":"1.195395427","rc":[{"atb":[[17.5,0]],"id":37284251}],"con":true,"img":false}]}
{"op":"mcm","clk":"5306688888","pt":1646103691966,"mc":[{"id":"1.195395427","rc":[{"atl":[[5.4,0]],"id":36087680}],"con":true,"img":false}]}
{"op":"mcm","clk":"5306688899","pt":1646103692271,"mc":[{"id":"1.195395427","rc":[{"atb":[[2.16,32.77]],"id":43154457}],"con":true,"img":false}]}
{"op":"mcm","clk":"5306688953","pt":1646103693449,"mc":[{"id":"1.195395427","rc":[{"atb":[[2.14,0]],"id":43154457},{"atb":[[1.97,0]],"id":36087680}],"con":true,"img":false}]}
{"op":"mcm","clk":"5306688974","pt":1646103694062,"mc":[{"id":"1.195395427","rc":[{"atb":[[19,5.15]],"id":37284251}],"con":true,"img":false}]}
{"op":"mcm","clk":"5306689136","pt":1646103697857,"mc":[{"id":"1.195395427","rc":[{"atl":[[4.7,3.55]],"id":43154457}],"con":true,"img":false}]}
{"op":"mcm","clk":"5306689141","pt":1646103697958,"mc":[{"id":"1.195395427","rc":[{"atl":[[5.4,3.08]],"id":36087680}],"con":true,"img":false}]}
{"op":"mcm","clk":"5306689179","pt":1646103698878,"mc":[{"id":"1.195395427","rc":[{"atb":[[2.12,20.2]],"id":43154457},{"atb":[[2.22,18.32]],"id":36087680}],"con":true,"img":false}]}
{"op":"mcm","clk":"5306689282","pt":1646103701085,"mc":[{"id":"1.195395427","rc":[{"atb":[[2.2,0]],"id":36087680}],"con":true,"img":false}]}
{"op":"mcm","clk":"5306689366","pt":1646103703189,"mc":[{"id":"1.195395427","rc":[{"atb":[[18,0]],"id":37284251}],"con":true,"img":false}]}
{"op":"mcm","clk":"5306689371","pt":1646103703289,"mc":[{"id":"1.195395427","rc":[{"atb":[[14.5,8.11]],"id":37284251}],"con":true,"img":false}]}
{"op":"mcm","clk":"5306689421","pt":1646103704567,"mc":[{"id":"1.195395427","rc":[{"atb":[[2.24,40.09]],"id":36087680}],"con":true,"img":false}]}
{"op":"mcm","clk":"5306689483","pt":1646103706304,"mc":[{"id":"1.195395427","rc":[{"atb":[[19,0]],"id":37284251}],"con":true,"img":false}]}
{"op":"mcm","clk":"5306689565","pt":1646103708196,"mc":[{"id":"1.195395427","rc":[{"atb":[[2.22,0]],"id":36087680}],"con":true,"img":false}]}
{"op":"mcm","clk":"5306689616","pt":1646103709983,"mc":[{"id":"1.195395427","rc":[{"atb":[[15,6.62]],"id":37284251}],"con":true,"img":false}]}
{"op":"mcm","clk":"5306689726","pt":1646103712998,"mc":[{"id":"1.195395427","rc":[{"atb":[[2.26,18.03]],"id":36087680}],"con":true,"img":false}]}
{"op":"mcm","clk":"5306689806","pt":1646103715604,"mc":[{"id":"1.195395427","rc":[{"atb":[[2.24,0]],"id":36087680}],"con":true,"img":false}]}
{"op":"mcm","clk":"5306689885","pt":1646103718384,"mc":[{"id":"1.195395427","rc":[{"atb":[[2.06,0]],"id":43154457}],"con":true,"img":false}]}
{"op":"mcm","clk":"5306689889","pt":1646103718486,"mc":[{"id":"1.195395427","rc":[{"atb":[[2.18,54.34]],"id":43154457}],"con":true,"img":false}]}
{"op":"mcm","clk":"5306689914","pt":1646103719207,"mc":[{"id":"1.195395427","rc":[{"atb":[[2.28,34.36]],"id":36087680}],"con":true,"img":false}]}
{"op":"mcm","clk":"5306689954","pt":1646103720905,"mc":[{"id":"1.195395427","rc":[{"atb":[[2.16,0]],"id":43154457}],"con":true,"img":false}]}
{"op":"mcm","clk":"5306689992","pt":1646103722197,"mc":[{"id":"1.195395427","rc":[{"atb":[[2.12,0]],"id":43154457},{"atb":[[2.26,2]],"id":36087680}],"con":true,"img":false}]}
{"op":"mcm","clk":"5306690062","pt":1646103724434,"mc":[{"id":"1.195395427","rc":[{"atb":[[1.96,96.6]],"id":43154457}],"con":true,"img":false}]}
{"op":"mcm","clk":"5306690099","pt":1646103725714,"mc":[{"id":"1.195395427","rc":[{"atb":[[2.1,9.18]],"id":43154457}],"con":true,"img":false}]}
{"op":"mcm","clk":"5306690151","pt":1646103727402,"mc":[{"id":"1.195395427","rc":[{"atb":[[1.96,120.16]],"id":43154457},{"atb":[[2.3,13.74]],"id":36087680}],"con":true,"img":false}]}
{"op":"mcm","clk":"5306690235","pt":1646103729805,"mc":[{"id":"1.195395427","rc":[{"atb":[[2.28,0]],"id":36087680}],"con":true,"img":false}]}
{"op":"mcm","clk":"5306690341","pt":1646103733236,"mc":[{"id":"1.195395427","rc":[{"atb":[[2.4,17.18]],"id":36087680}],"con":true,"img":false}]}
{"op":"mcm","clk":"5306690343","pt":1646103733437,"mc":[{"id":"1.195395427","rc":[{"atb":[[2.18,0]],"id":43154457}],"con":true,"img":false}]}
{"op":"mcm","clk":"5306690348","pt":1646103733542,"mc":[{"id":"1.195395427","rc":[{"atb":[[2.06,54.34]],"id":43154457}],"con":true,"img":false}]}
{"op":"mcm","clk":"5306690366","pt":1646103734053,"mc":[{"id":"1.195395427","rc":[{"atb":[[2.1,0]],"id":43154457}],"con":true,"img":false}]}
{"op":"mcm","clk":"5306690460","pt":1646103736312,"mc":[{"id":"1.195395427","rc":[{"atb":[[1.96,96.6]],"id":43154457},{"atb":[[2.3,0]],"id":36087680}],"con":true,"img":false}]}
{"op":"mcm","clk":"5306690660","pt":1646103742039,"mc":[{"id":"1.195395427","rc":[{"atb":[[1.97,23.32]],"id":43154457},{"atb":[[2.42,12.02]],"id":36087680},{"spn":3.26,"spf":1.0,"id":36087680}],"con":true,"img":false}]}
{"op":"mcm","clk":"5306690812","pt":1646103745465,"mc":[{"id":"1.195395427","rc":[{"atb":[[1.96,0]],"id":43154457},{"atb":[[2.4,0]],"id":36087680}],"con":true,"img":false}]}
{"op":"mcm","clk":"5306690880","pt":1646103746851,"mc":[{"id":"1.195395427","rc":[{"atl":[[3.5,0]],"id":43154457}],"con":true,"img":false}]}
{"op":"mcm","clk":"5306690955","pt":1646103749255,"mc":[{"id":"1.195395427","rc":[{"atb":[[1.98,94.63],[1.97,0]],"id":43154457},{"atb":[[2.42,0],[2.44,18.04]],"id":36087680}],"con":true,"img":false}]}
{"op":"mcm","clk":"5306690978","pt":1646103749765,"mc":[{"id":"1.195395427","rc":[{"atb":[[2.1,6.77]],"id":43154457},{"atl":[[4.1,0]],"id":36087680}],"con":true,"img":false}]}
{"op":"mcm","clk":"5306691052","pt":1646103751947,"mc":[{"id":"1.195395427","rc":[{"atb":[[2.1,14.36]],"id":43154457}],"con":true,"img":false}]}
{"op":"mcm","clk":"5306691076","pt":1646103752765,"mc":[{"id":"1.195395427","rc":[{"atb":[[1.98,0]],"id":43154457},{"atl":[[3.5,4.25]],"id":43154457},{"atl":[[4.1,3.63]],"id":36087680}],"con":true,"img":false}]}
{"op":"mcm","clk":"5306691147","pt":1646103754764,"mc":[{"id":"1.195395427","rc":[{"atb":[[1.99,12.28]],"id":43154457},{"atb":[[2.4,16.16]],"id":36087680}],"con":true,"img":false}]}
{"op":"mcm","clk":"5306691232","pt":1646103756369,"mc":[{"id":"1.195395427","rc":[{"atb":[[1.96,65.46]],"id":43154457},{"atb":[[2.44,0]],"id":36087680}],"con":true,"img":false}]}
{"op":"mcm","clk":"5306691363","pt":1646103760047,"mc":[{"id":"1.195395427","rc":[{"atb":[[1.96,0]],"id":43154457},{"atb":[[2.42,24.24]],"id":36087680}],"con":true,"img":false}]}
{"op":"mcm","clk":"5306691491","pt":1646103763688,"mc":[{"id":"1.195395427","rc":[{"atb":[[2,49.1]],"id":43154457}],"con":true,"img":false}]}
{"op":"mcm","clk":"5306691496","pt":1646103763791,"mc":[{"id":"1.195395427","rc":[{"atb":[[14.5,0]],"id":37284251}],"con":true,"img":false}]}
{"op":"mcm","clk":"5306691500","pt":1646103763895,"mc":[{"id":"1.195395427","rc":[{"atb":[[15.5,8.11]],"id":37284251}],"con":true,"img":false}]}
{"op":"mcm","clk":"5306691591","pt":1646103767072,"mc":[{"id":"1.195395427","rc":[{"atb":[[1.99,0]],"id":43154457}],"con":true,"img":false}]}
{"op":"mcm","clk":"5306691594","pt":1646103767175,"mc":[{"id":"1.195395427","rc":[{"atb":[[15,0]],"id":37284251}],"con":true,"img":false}]}
{"op":"mcm","clk":"5306691705","pt":1646103770705,"mc":[{"id":"1.195395427","rc":[{"atb":[[16,6.18]],"id":37284251}],"con":true,"img":false}]}
{"op":"mcm","clk":"5306691749","pt":1646103772401,"mc":[{"id":"1.195395427","rc":[{"atb":[[2.02,19.63]],"id":43154457}],"con":true,"img":false}]}
{"op":"mcm","clk":"5306691858","pt":1646103775891,"mc":[{"id":"1.195395427","rc":[{"atb":[[2,0]],"id":43154457}],"con":true,"img":false}]}
{"op":"mcm","clk":"5306691975","pt":1646103779590,"mc":[{"id":"1.195395427","rc":[{"atb":[[2.12,24.55]],"id":43154457}],"con":true,"img":false}]}
{"op":"mcm","clk":"5306692144","pt":1646103784410,"mc":[{"id":"1.195395427","rc":[{"atb":[[2.02,0]],"id":43154457}],"con":true,"img":false}]}
{"op":"mcm","clk":"5306692307","pt":1646103789590,"mc":[{"id":"1.195395427","rc":[{"atb":[[2.14,18.58]],"id":43154457}],"con":true,"img":false}]}
{"op":"mcm","clk":"5306692403","pt":1646103793229,"mc":[{"id":"1.195395427","rc":[{"atb":[[2.12,0]],"id":43154457}],"con":true,"img":false}]}
{"op":"mcm","clk":"5306692412","pt":1646103793431,"mc":[{"id":"1.195395427","rc":[{"atb":[[2.34,0]],"id":36087680}],"con":true,"img":false}]}
{"op":"mcm","clk":"5306692417","pt":1646103793534,"mc":[{"id":"1.195395427","rc":[{"atb":[[2.44,43.3]],"id":36087680}],"con":true,"img":false}]}
{"op":"mcm","clk":"5306692509","pt":1646103796817,"mc":[{"id":"1.195395427","rc":[{"atb":[[2.16,30.87]],"id":43154457},{"atb":[[2.42,0]],"id":36087680}],"con":true,"img":false}]}
{"op":"mcm","clk":"5306692518","pt":1646103797125,"mc":[{"id":"1.195395427","rc":[{"atb":[[2.14,0]],"id":43154457},{"atb":[[2.4,0]],"id":36087680}],"con":true,"img":false}]}
{"op":"mcm","clk":"5306692614","pt":1646103800420,"mc":[{"id":"1.195395427","rc":[{"atb":[[2.2,77.28]],"id":36087680}],"con":true,"img":false}]}
{"op":"mcm","clk":"5306692635","pt":1646103800933,"mc":[{"id":"1.195395427","rc":[{"atb":[[2.38,6.05]],"id":36087680}],"con":true,"img":false}]}
{"op":"mcm","clk":"5306692700","pt":1646103802824,"mc":[{"id":"1.195395427","rc":[{"atb":[[2.12,20.2]],"id":43154457},{"atb":[[2.2,96.13]],"id":36087680},{"spn":3.27,"spf":1.0,"id":36087680}],"con":true,"img":false}]}
{"op":"mcm","clk":"5306692848","pt":1646103806165,"mc":[{"id":"1.195395427","rc":[{"atb":[[2.38,0]],"id":36087680}],"con":true,"img":false}]}
{"op":"mcm","clk":"5306692924","pt":1646103808162,"mc":[{"id":"1.195395427","rc":[{"atb":[[2.44,0]],"id":36087680}],"con":true,"img":false}]}
{"op":"mcm","clk":"5306692929","pt":1646103808265,"mc":[{"id":"1.195395427","rc":[{"atb":[[2.34,43.3]],"id":36087680}],"con":true,"img":false}]}
{"op":"mcm","clk":"5306693293","pt":1646103818168,"mc":[{"id":"1.195395427","rc":[{"atl":[[4.7,0]],"id":43154457}],"con":true,"img":false}]}
{"op":"mcm","clk":"5306693489","pt":1646103822593,"mc":[{"id":"1.195395427","rc":[{"atb":[[16.5,6.54],[20,5.34],[11.5,9.66],[14,7.8]],"id":37284251},{"atl":[[260,0.76],[310,0.64],[160,0.83],[210,0.63]],"id":37284251},{"atb":[[36,2.9],[18,5.96],[21,5.07],[26,8.63]],"id":42130949},{"atl":[[300,0.44],[350,0.37],[400,0.49],[450,0.44]],"id":42130949},{"atb":[[4,33.81],[3.5,40.58],[3.75,36.89],[4.7,27.42]],"id":38407646},{"atl":[[16,8.8],[18.5,7.54],[22,9.43],[27,7.62]],"id":38407646},{"atb":[[4,33.81],[3.5,40.58],[3.75,36.89],[4.7,33.55]],"id":43154456},{"atl":[[16,8.8],[18.5,7.54],[22,9.43],[27,7.62]],"id":43154456},{"atb":[[1.98,103.52],[1.88,115.29],[1.93,109.09],[2.1,106.59]],"id":43154457},{"atl":[[6.4,36.7],[7.4,30.96],[5.2,31.45],[5.7,28.11]],"id":43154457},{"atb":[[2.06,95.71],[1.98,103.52],[2.2,180.68],[1.93,109.09]],"id":36087680},{"atl":[[6.8,34.17],[7.8,29.14],[5.9,26.96],[5.4,33.12]],"id":36087680}],"con":true,"img":false}]}
{"op":"mcm","clk":"5306693499","pt":1646103822794,"mc":[{"id":"1.195395427","rc":[{"atb":[[5.1,0],[1.01,2.23]],"id":43154456}],"con":true,"img":false}]}
{"op":"mcm","clk":"5306693508","pt":1646103822999,"mc":[{"id":"1.195395427","rc":[{"atb":[[1.01,0.73]],"id":43154456}],"con":true,"img":false}]}
{"op":"mcm","clk":"5306693515","pt":1646103823191,"mc":[{"id":"1.195395427","rc":[{"atb":[[1.01,0]],"id":43154456}],"con":true,"img":false}]}
{"op":"mcm","clk":"5306693519","pt":1646103823261,"mc":[{"id":"1.195395427","rc":[{"atb":[[4.8,0.73]],"id":43154456}],"con":true,"img":false}]}
{"op":"mcm","clk":"5306693543","pt":1646103823871,"mc":[{"id":"1.195395427","rc":[{"atb":[[15.5,0]],"id":37284251},{"atb":[[2.06,0]],"id":43154457}],"con":true,"img":false}]}
{"op":"mcm","clk":"5306693546","pt":1646103823972,"mc":[{"id":"1.195395427","rc":[{"atb":[[17,8.11]],"id":37284251},{"atb":[[2.18,54.34]],"id":43154457}],"con":true,"img":false}]}
{"op":"mcm","clk":"5306693550","pt":1646103824074,"mc":[{"id":"1.195395427","rc":[{"atb":[[2.38,6.05]],"id":36087680}],"con":true,"img":false}]}
{"op":"mcm","clk":"5306693558","pt":1646103824279,"mc":[{"id":"1.195395427","rc":[{"atl":[[5.4,30.03]],"id":36087680}],"con":true,"img":false}]}
{"op":"mcm","clk":"5306693582","pt":1646103824896,"mc":[{"id":"1.195395427","rc":[{"atb":[[2.38,11.45]],"id":36087680}],"con":true,"img":false}]}
{"op":"mcm","clk":"5306693619","pt":1646103826074,"mc":[{"id":"1.195395427","rc":[{"atb":[[16,0]],"id":37284251},{"atb":[[2.16,0]],"id":43154457},{"atb":[[2.2,103.4]],"id":36087680}],"con":true,"img":false}]}
{"op":"mcm","clk":"5306693702","pt":1646103828278,"mc":[{"id":"1.195395427","rc":[{"atb":[[2.12,0]],"id":43154457},{"atb":[[2.2,84.54]],"id":36087680}],"con":true,"img":false}]}
{"op":"mcm","clk":"5306693753","pt":1646103829604,"mc":[{"id":"1.195395427","rc":[{"atb":[[2.2,77.28]],"id":43154457},{"atb":[[2.22,42.96]],"id":36087680}],"con":true,"img":false}]}
{"op":"mcm","clk":"5306693774","pt":1646103830114,"mc":[{"id":"1.195395427","rc":[{"atl":[[4.7,3.55]],"id":43154457}],"con":true,"img":false}]}
{"op":"mcm","clk":"5306693779","pt":1646103830165,"mc":[{"id":"1.195395427","rc":[{"atl":[[5.3,3.14]],"id":36087680}],"con":true,"img":false}]}
{"op":"mcm","clk":"5306693811","pt":1646103830982,"mc":[{"id":"1.195395427","rc":[{"atb":[[4.6,0]],"id":43154456},{"atb":[[2.1,99.81]],"id":43154457}],"con":true,"img":false}]}
{"op":"mcm","clk":"5306693893","pt":1646103833077,"mc":[{"id":"1.195395427","rc":[{"atb":[[4.7,27.42]],"id":43154456}],"con":true,"img":false}]}
{"op":"mcm","clk":"5306693929","pt":1646103834201,"mc":[{"id":"1.195395427","rc":[{"atb":[[2.12,20.2]],"id":43154457},{"atb":[[2.24,17.18]],"id":36087680}],"con":true,"img":false}]}
{"op":"mcm","clk":"5306693991","pt":1646103836198,"mc":[{"id":"1.195395427","rc":[{"atb":[[4.3,0]],"id":38407646},{"atb":[[3.85,0]],"id":43154456},{"atb":[[2.1,92.22]],"id":43154457}],"con":true,"img":false}]}
{"op":"mcm","clk":"5306694002","pt":1646103836607,"mc":[{"id":"1.195395427","rc":[{"atb":[[4.8,9.51]],"id":43154456},{"atb":[[2.2,0]],"id":43154457},{"atb":[[2.22,0]],"id":36087680}],"con":true,"img":false}]}
{"op":"mcm","clk":"5306694019","pt":1646103837118,"mc":[{"id":"1.195395427","rc":[{"atb":[[5,2]],"id":43154456}],"con":true,"img":false}]}
{"op":"mcm","clk":"5306694071","pt":1646103838702,"mc":[{"id":"1.195395427","rc":[{"atb":[[2.18,0]],"id":43154457}],"con":true,"img":false}]}
{"op":"mcm","clk":"5306694074","pt":1646103838805,"mc":[{"id":"1.195395427","rc":[{"atb":[[2.14,54.34]],"id":43154457}],"con":true,"img":false}]}
{"op":"mcm","clk":"5306694117","pt":1646103840186,"mc":[{"id":"1.195395427","rc":[{"atb":[[2.2,77.28]],"id":43154457},{"atb":[[2.26,39.22]],"id":36087680}],"con":true,"img":false}]}
{"op":"mcm","clk":"5306694218","pt":1646103842083,"mc":[{"id":"1.195395427","rc":[{"atb":[[4.8,11.71]],"id":43154456}],"con":true,"img":false}]}
{"op":"mcm","clk":"5306694223","pt":1646103842287,"mc":[{"id":"1.195395427","rc":[{"atb":[[4.8,2.19]],"id":38407646}],"con":true,"img":false}]}
{"op":"mcm","clk":"5306694243","pt":1646103842801,"mc":[{"id":"1.195395427","rc":[{"atb":[[4.9,5.79]],"id":43154456}],"con":true,"img":false}]}
{"op":"mcm","clk":"5306694250","pt":1646103842901,"mc":[{"id":"1.195395427","rc":[{"atb":[[1.01,2.23]],"id":43154456}],"con":true,"img":false}]}
{"op":"mcm","clk":"5306694254","pt":1646103843004,"mc":[{"id":"1.195395427","rc":[{"atb":[[1.01,1.96]],"id":43154456}],"con":true,"img":false}]}
{"op":"mcm","clk":"5306694262","pt":1646103843207,"mc":[{"id":"1.195395427","rc":[{"atb":[[1.01,0]],"id":43154456}],"con":true,"img":false}]}
{"op":"mcm","clk":"5306694266","pt":1646103843310,"mc":[{"id":"1.195395427","rc":[{"atb":[[4.8,13.67]],"id":43154456}],"con":true,"img":false}]}
{"op":"mcm","clk":"5306694348","pt":1646103845409,"mc":[{"id":"1.195395427","rc":[{"atb":[[2.12,0]],"id":43154457},{"atb":[[2.24,0]],"id":36087680}],"con":true,"img":false}]}
{"op":"mcm","clk":"5306694458","pt":1646103848117,"mc":[{"id":"1.195395427","rc":[{"atb":[[2.24,6.72]],"id":43154457}],"con":true,"img":false}]}
{"op":"mcm","clk":"5306694461","pt":1646103848219,"mc":[{"id":"1.195395427","rc":[{"atb":[[2.2,0]],"id":43154457}],"con":true,"img":false}]}
{"op":"mcm","clk":"5306694565","pt":1646103850930,"mc":[{"id":"1.195395427","rc":[{"atb":[[2.16,19.5]],"id":43154457},{"atb":[[2.28,14.89]],"id":36087680}],"con":true,"img":false}]}
{"op":"mcm","clk":"5306694589","pt":1646103851697,"mc":[{"id":"1.195395427","rc":[{"atb":[[2.16,43.5]],"id":43154457}],"con":true,"img":false}]}
{"op":"mcm","clk":"5306694625","pt":1646103852716,"mc":[{"id":"1.195395427","rc":[{"atb":[[2.28,115.53]],"id":36087680}],"con":true,"img":false}]}
{"op":"mcm","clk":"5306694629","pt":1646103852819,"mc":[{"id":"1.195395427","rc":[{"atb":[[18.5,0]],"id":37284251},{"atb":[[34,0]],"id":42130949},{"atb":[[4.5,0]],"id":43154456},{"atl":[[10.5,0]],"id":43154456},{"atb":[[2.18,0]],"id":36087680}],"con":true,"img":false}]}
{"op":"mcm","clk":"5306694635","pt":1646103852921,"mc":[{"id":"1.195395427","rc":[{"atb":[[21,3.51]],"id":37284251},{"atb":[[38,2.7]],"id":42130949},{"atb":[[4.9,22.37]],"id":43154456},{"atl":[[9.8,6.1]],"id":43154456}],"con":true,"img":false}]}
{"op":"mcm","clk":"5306694654","pt":1646103853332,"mc":[{"id":"1.195395427","rc":[{"atb":[[2.26,2]],"id":36087680}],"con":true,"img":false}]}
{"op":"mcm","clk":"5306694802","pt":1646103856914,"mc":[{"id":"1.195395427","rc":[{"atb":[[2.3,31.5]],"id":36087680}],"con":true,"img":false}]}
{"op":"mcm","clk":"5306694966","pt":1646103860444,"mc":[{"id":"1.195395427","rc":[{"atb":[[2.28,100.64]],"id":36087680}],"con":true,"img":false}]}
{"op":"mcm","clk":"5306694994","pt":1646103861007,"mc":[{"id":"1.195395427","rc":[{"atb":[[4.8,11.71]],"id":43154456}],"con":true,"img":false}]}
{"op":"mcm","clk":"5306695170","pt":1646103865316,"mc":[{"id":"1.195395427","rc":[{"spn":7.4,"spf":1.0,"id":43154456},{"atb":[[2.4,8.01]],"id":36087680},{"spn":3.25,"spf":1.0,"id":36087680}],"con":true,"img":false}]}
{"op":"mcm","clk":"5306695212","pt":1646103866339,"mc":[{"id":"1.195395427","rc":[{"atb":[[4.8,9.51]],"id":43154456},{"atb":[[2.24,0]],"id":43154457}],"con":true,"img":false}]}
{"op":"mcm","clk":"5306695299","pt":1646103867927,"mc":[{"id":"1.195395427","rc":[{"atl":[[330,0]],"id":42130949},{"atb":[[4.2,0]],"id":38407646},{"atb":[[3.8,0]],"id":43154456},{"atb":[[1.95,0]],"id":43154457},{"atl":[[5.5,0]],"id":36087680}],"con":true,"img":false}]}
{"op":"mcm","clk":"5306695304","pt":1646103868029,"mc":[{"id":"1.195395427","rc":[{"atl":[[290,2.7]],"id":42130949},{"atb":[[4.8,43.31]],"id":38407646},{"atb":[[4.1,38.93]],"id":43154456},{"atb":[[1.99,136.54]],"id":43154457},{"atl":[[5.3,31.82]],"id":36087680}],"con":true,"img":false}]}
{"op":"mcm","clk":"5306695316","pt":1646103868336,"mc":[{"id":"1.195395427","rc":[{"atb":[[2.3,0]],"id":36087680}],"con":true,"img":false}]}
{"op":"mcm","clk":"5306695375","pt":1646103869921,"mc":[{"id":"1.195395427","rc":[{"atb":[[1.01,2.23]],"id":43154456},{"atb":[[2.2,6.2]],"id":43154457}],"con":true,"img":false}]}
{"op":"mcm","clk":"5306695381","pt":1646103870126,"mc":[{"id":"1.195395427","rc":[{"atb":[[1.01,1.86]],"id":43154456},{"atl":[[3.5,0]],"id":43154457}],"con":true,"img":false}]}
{"op":"mcm","clk":"5306695389","pt":1646103870330,"mc":[{"id":"1.195395427","rc":[{"atb":[[1.01,0]],"id":43154456}],"con":true,"img":false}]}
{"op":"mcm","clk":"5306695393","pt":1646103870433,"mc":[{"id":"1.195395427","rc":[{"atb":[[5,3.86]],"id":43154456}],"con":true,"img":false}]}
{"op":"mcm","clk":"5306695443","pt":1646103871764,"mc":[{"id":"1.195395427","rc":[{"atb":[[2.42,12.02]],"id":36087680}],"con":true,"img":false}]}
{"op":"mcm","clk":"5306695460","pt":1646103872223,"mc":[{"id":"1.195395427","rc":[{"atb":[[5,5.95]],"id":43154456},{"atb":[[2.2,13.16]],"id":43154457}],"con":true,"img":false}]}
{"op":"mcm","clk":"5306695485","pt":1646103872838,"mc":[{"id":"1.195395427","rc":[{"atb":[[4.9,16.57]],"id":43154456}],"con":true,"img":false}]}
{"op":"mcm","clk":"5306695491","pt":1646103872942,"mc":[{"id":"1.195395427","rc":[{"atl":[[4.1,0]],"id":36087680}],"con":true,"img":false}]}
{"op":"mcm","clk":"5306695507","pt":1646103873350,"mc":[{"id":"1.195395427","rc":[{"atb":[[4.8,0.73]],"id":43154456}],"con":true,"img":false}]}
{"op":"mcm","clk":"5306695584","pt":1646103875248,"mc":[{"id":"1.195395427","rc":[{"atb":[[2.4,0]],"id":36087680}],"con":true,"img":false}]}
{"op":"mcm","clk":"5306695613","pt":1646103875963,"mc":[{"id":"1.195395427","rc":[{"atl":[[3.5,4.25]],"id":43154457},{"atl":[[4.1,3.63]],"id":36087680}],"con":true,"img":false}]}
{"op":"mcm","clk":"5306695637","pt":1646103876832,"mc":[{"id":"1.195395427","rc":[{"atb":[[5.1,8.92]],"id":43154456}],"con":true,"img":false}]}
{"op":"mcm","clk":"5306695669","pt":1646103877956,"mc":[{"id":"1.195395427","rc":[{"atb":[[5.1,13.08]],"id":43154456}],"con":true,"img":false}]}
{"op":"mcm","clk":"5306695689","pt":1646103878467,"mc":[{"id":"1.195395427","rc":[{"atb":[[2.42,0]],"id":36087680}],"con":true,"img":false}]}
{"op":"mcm","clk":"5306695811","pt":1646103881448,"mc":[{"id":"1.195395427","rc":[{"atb":[[2.44,8.42]],"id":36087680}],"con":true,"img":false}]}
{"op":"mcm","clk":"5306695830","pt":1646103881860,"mc":[{"id":"1.195395427","rc":[{"atb":[[2.14,0]],"id":43154457},{"atb":[[2.28,0]],"id":36087680}],"con":true,"img":false}]}
{"op":"mcm","clk":"5306695835","pt":1646103881962,"mc":[{"id":"1.195395427","rc":[{"atb":[[2.18,54.34]],"id":43154457},{"atb":[[2.3,31.5],[2.22,100.64]],"id":36087680}],"con":true,"img":false}]}
{"op":"mcm","clk":"5306695890","pt":1646103883657,"mc":[{"id":"1.195395427","rc":[{"atb":[[2.16,19.5]],"id":43154457}],"con":true,"img":false}]}
{"op":"mcm","clk":"5306695913","pt":1646103884374,"mc":[{"id":"1.195395427","rc":[{"atb":[[4.8,41.12]],"id":38407646}],"con":true,"img":false}]}
{"op":"mcm","clk":"5306695946","pt":1646103885343,"mc":[{"id":"1.195395427","rc":[{"atb":[[2.3,0]],"id":36087680}],"con":true,"img":false}]}
{"op":"mcm","clk":"5306695976","pt":1646103886266,"mc":[{"id":"1.195395427","rc":[{"atb":[[2.16,0]],"id":43154457}],"con":true,"img":false}]}
{"op":"mcm","clk":"5306696006","pt":1646103887088,"mc":[{"id":"1.195395427","rc":[{"atb":[[2.22,22.73]],"id":43154457}],"con":true,"img":false}]}
{"op":"mcm","clk":"5306696083","pt":1646103888875,"mc":[{"id":"1.195395427","rc":[{"atb":[[2.4,18.94]],"id":36087680}],"con":true,"img":false}]}
{"op":"mcm","clk":"5306696130","pt":1646103890259,"mc":[{"id":"1.195395427","rc":[{"atb":[[4.9,2.13]],"id":38407646}],"con":true,"img":false}]}
{"op":"mcm","clk":"5306696158","pt":1646103891079,"mc":[{"id":"1.195395427","rc":[{"atb":[[2.2,6.95]],"id":43154457}],"con":true,"img":false}]}
{"op":"mcm","clk":"5306696174","pt":1646103891489,"mc":[{"id":"1.195395427","rc":[{"atb":[[2.24,17.31]],"id":43154457}],"con":true,"img":false}]}
{"op":"mcm","clk":"5306696281","pt":1646103893899,"mc":[{"id":"1.195395427","rc":[{"atb":[[2.22,0]],"id":43154457}],"con":true,"img":false}]}
{"op":"mcm","clk":"5306696401","pt":1646103896558,"mc":[{"id":"1.195395427","rc":[{"atb":[[2.2,0]],"id":43154457}],"con":true,"img":false}]}
{"op":"mcm","clk":"5306696407","pt":1646103896765,"mc":[{"id":"1.195395427","rc":[{"atb":[[4.9,0]],"id":43154456},{"atb":[[2.18,0]],"id":43154457}],"con":true,"img":false}]}
{"op":"mcm","clk":"5306696409","pt":1646103896865,"mc":[{"id":"1.195395427","rc":[{"atb":[[4.8,17.3]],"id":43154456},{"atb":[[2.12,54.34]],"id":43154457}],"con":true,"img":false}]}
{"op":"mcm","clk":"5306696417","pt":1646103897171,"mc":[{"id":"1.195395427","rc":[{"atb":[[2.26,28.97]],"id":43154457}],"con":true,"img":false}]}
{"op":"mcm","clk":"5306696574","pt":1646103901266,"mc":[{"id":"1.195395427","rc":[{"atb":[[2.24,0]],"id":43154457}],"con":true,"img":false}]}
{"op":"mcm","clk":"5306696672","pt":1646103903775,"mc":[{"id":"1.195395427","rc":[{"atb":[[2.26,0]],"id":43154457}],"con":true,"img":false}]}
{"op":"mcm","clk":"5306696764","pt":1646103906075,"mc":[{"id":"1.195395427","rc":[{"atb":[[5,4.08]],"id":43154456}],"con":true,"img":false}]}
{"op":"mcm","clk":"5306696770","pt":1646103906279,"mc":[{"id":"1.195395427","rc":[{"atb":[[2.14,19.84]],"id":43154457}],"con":true,"img":false}]}
{"op":"mcm","clk":"5306696797","pt":1646103907198,"mc":[{"id":"1.195395427","rc":[{"atb":[[2,92.74]],"id":43154457}],"con":true,"img":false}]}
{"op":"mcm","clk":"5306696825","pt":1646103907812,"mc":[{"id":"1.195395427","rc":[{"atb":[[21,9.24]],"id":37284251},{"atl":[[70,4.66]],"id":37284251},{"atl":[[240,0.81]],"id":42130949},{"atb":[[5.4,23.97]],"id":38407646},{"atl":[[11,11.74]],"id":38407646},{"atl":[[9.8,24.55]],"id":43154456},{"atb":[[2.14,41.49]],"id":43154457},{"atl":[[3.6,43.96]],"id":43154457},{"atb":[[2.4,40.58]],"id":36087680},{"atl":[[4.2,34.4]],"id":36087680}],"con":true,"img":false}]}
{"op":"mcm","clk":"5306696928","pt":1646103910579,"mc":[{"id":"1.195395427","rc":[{"atb":[[2,0]],"id":43154457}],"con":true,"img":false}]}
{"op":"mcm","clk":"5306697030","pt":1646103913902,"mc":[{"id":"1.195395427","rc":[{"atb":[[2.16,65.23]],"id":43154457}],"con":true,"img":false}]}
{"op":"mcm","clk":"5306697046","pt":1646103914311,"mc":[{"id":"1.195395427","rc":[{"atb":[[5,2]],"id":43154456}],"con":true,"img":false}]}
{"op":"mcm","clk":"5306697064","pt":1646103914980,"mc":[{"id":"1.195395427","rc":[{"atb":[[5.2,0]],"id":38407646},{"atb":[[1.01,2.23]],"id":43154456},{"atb":[[2.14,19.84]],"id":43154457},{"atb":[[2.38,6.05]],"id":36087680}],"con":true,"img":false}]}
{"op":"mcm","clk":"5306697066","pt":1646103915081,"mc":[{"id":"1.195395427","rc":[{"atb":[[1.01,1.9]],"id":43154456},{"atb":[[2.16,86.88]],"id":43154457}],"con":true,"img":false}]}
{"op":"mcm","clk":"5306697072","pt":1646103915285,"mc":[{"id":"1.195395427","rc":[{"atb":[[1.01,0]],"id":43154456}],"con":true,"img":false}]}
{"op":"mcm","clk":"5306697074","pt":1646103915386,"mc":[{"id":"1.195395427","rc":[{"atb":[[4.9,1.9]],"id":43154456}],"con":true,"img":false}]}
{"op":"mcm","clk":"5306697134","pt":1646103917280,"mc":[{"id":"1.195395427","rc":[{"atb":[[5.4,19.92]],"id":38407646}],"con":true,"img":false}]}
{"op":"mcm","clk":"5306697235","pt":1646103920203,"mc":[{"id":"1.195395427","rc":[{"atb":[[4.9,4.04]],"id":43154456}],"con":true,"img":false}]}
{"op":"mcm","clk":"5306697253","pt":1646103920614,"mc":[{"id":"1.195395427","rc":[{"atb":[[5.2,22.08]],"id":38407646}],"con":true,"img":false}]}
{"op":"mcm","clk":"5306697491","pt":1646103926348,"mc":[{"id":"1.195395427","rc":[{"atb":[[4.9,0]],"id":38407646},{"spn":7.45,"spf":1.0,"id":43154456},{"atb":[[2.38,0]],"id":36087680},{"spn":3.27,"spf":1.0,"id":36087680}],"con":true,"img":false}]}
{"op":"mcm","clk":"5306697526","pt":1646103927012,"mc":[{"id":"1.195395427","rc":[{"atb":[[1.01,2.23]],"id":38407646},{"atb":[[2.44,13.59]],"id":36087680}],"con":true,"img":false}]}
{"op":"mcm","clk":"5306697530","pt":1646103927218,"mc":[{"id":"1.195395427","rc":[{"atb":[[1.01,1.65]],"id":38407646}],"con":true,"img":false}]}
{"op":"mcm","clk":"5306697536","pt":1646103927422,"mc":[{"id":"1.195395427","rc":[{"atb":[[1.01,0]],"id":38407646}],"con":true,"img":false}]}
{"op":"mcm","clk":"5306697540","pt":1646103927525,"mc":[{"id":"1.195395427","rc":[{"atb":[[5.5,3.65]],"id":38407646}],"con":true,"img":false}]}
{"op":"mcm","clk":"5306697590","pt":1646103928805,"mc":[{"id":"1.195395427","rc":[{"atb":[[2.4,21.64]],"id":36087680}],"con":true,"img":false}]}
{"op":"mcm","clk":"5306697632","pt":1646103929724,"mc":[{"id":"1.195395427","rc":[{"atb":[[5.4,0]],"id":38407646},{"atb":[[2.4,0]],"id":36087680}],"con":true,"img":false}]}
{"op":"mcm","clk":"5306697636","pt":1646103929826,"mc":[{"id":"1.195395427","rc":[{"atb":[[5.5,22.64]],"id":38407646},{"atb":[[2.44,34.87]],"id":36087680}],"con":true,"img":false}]}
{"op":"mcm","clk":"5306697643","pt":1646103930032,"mc":[{"id":"1.195395427","rc":[{"atb":[[2.2,6.2]],"id":43154457}],"con":true,"img":false}]}
{"op":"mcm","clk":"5306697653","pt":1646103930235,"mc":[{"id":"1.195395427","rc":[{"atb":[[2.44,26.44]],"id":36087680}],"con":true,"img":false}]}
{"op":"mcm","clk":"5306697660","pt":1646103930439,"mc":[{"id":"1.195395427","rc":[{"atb":[[5.2,0]],"id":38407646},{"atb":[[2.34,0]],"id":36087680}],"con":true,"img":false}]}
{"op":"mcm","clk":"5306697667","pt":1646103930541,"mc":[{"id":"1.195395427","rc":[{"atb":[[2.42,43.3]],"id":36087680}],"con":true,"img":false}]}
{"op":"mcm","clk":"5306697737","pt":1646103932333,"mc":[{"id":"1.195395427","rc":[{"atb":[[2.2,13.16],[2.16,21.64]],"id":43154457},{"atb":[[2.24,74.78]],"id":36087680}],"con":true,"img":false}]}
{"op":"mcm","clk":"5306697759","pt":1646103932951,"mc":[{"id":"1.195395427","rc":[{"atb":[[2.14,0]],"id":43154457}],"con":true,"img":false}]}
{"op":"mcm","clk":"5306697802","pt":1646103934128,"mc":[{"id":"1.195395427","rc":[{"atb":[[5.2,22.08]],"id":38407646}],"con":true,"img":false}]}
{"op":"mcm","clk":"5306697872","pt":1646103935818,"mc":[{"id":"1.195395427","rc":[{"atb":[[2.26,19.96]],"id":36087680}],"con":true,"img":false}]}
{"op":"mcm","clk":"5306697883","pt":1646103936022,"mc":[{"id":"1.195395427","rc":[{"atb":[[2.22,22.73]],"id":43154457}],"con":true,"img":false}]}
{"op":"mcm","clk":"5306697888","pt":1646103936125,"mc":[{"id":"1.195395427","rc":[{"atb":[[5.5,20.98]],"id":38407646},{"atb":[[2.44,21.27]],"id":36087680}],"con":true,"img":false}]}
{"op":"mcm","clk":"5306697924","pt":1646103937348,"mc":[{"id":"1.195395427","rc":[{"atb":[[2.16,0]],"id":43154457}],"con":true,"img":false}]}
{"op":"mcm","clk":"5306697927","pt":1646103937451,"mc":[{"id":"1.195395427","rc":[{"atb":[[2.22,42.65]],"id":43154457}],"con":true,"img":false}]}
{"op":"mcm","clk":"5306697936","pt":1646103937758,"mc":[{"id":"1.195395427","rc":[{"atb":[[2.24,0]],"id":36087680}],"con":true,"img":false}]}
{"op":"mcm","clk":"5306697972","pt":1646103938627,"mc":[{"id":"1.195395427","rc":[{"atb":[[2.22,53.26]],"id":43154457}],"con":true,"img":false}]}
{"op":"mcm","clk":"5306697993","pt":1646103939240,"mc":[{"id":"1.195395427","rc":[{"atb":[[2.2,6.95]],"id":43154457}],"con":true,"img":false}]}
{"op":"mcm","clk":"5306698072","pt":1646103941242,"mc":[{"id":"1.195395427","rc":[{"atb":[[2.28,72.45]],"id":36087680}],"con":true,"img":false}]}
{"op":"mcm","clk":"5306698201","pt":1646103944469,"mc":[{"id":"1.195395427","rc":[{"atb":[[5.6,1.81],[5.1,0]],"id":38407646},{"atb":[[2.12,0]],"id":43154457}],"con":true,"img":false}]}
{"op":"mcm","clk":"5306698205","pt":1646103944572,"mc":[{"id":"1.195395427","rc":[{"atb":[[5.3,14.85]],"id":38407646},{"atb":[[2.18,54.34]],"id":43154457}],"con":true,"img":false}]}
{"op":"mcm","clk":"5306698212","pt":1646103944673,"mc":[{"id":"1.195395427","rc":[{"atb":[[2.46,5.71]],"id":36087680}],"con":true,"img":false}]}
{"op":"mcm","clk":"5306698253","pt":1646103946156,"mc":[{"id":"1.195395427","rc":[{"atb":[[2.26,2]],"id":36087680}],"con":true,"img":false}]}
{"op":"mcm","clk":"5306698309","pt":1646103947738,"mc":[{"id":"1.195395427","rc":[{"atb":[[5.2,0]],"id":38407646},{"atb":[[2.28,0]],"id":36087680}],"con":true,"img":false}]}
{"op":"mcm","clk":"5306698401","pt":1646103950443,"mc":[{"id":"1.195395427","rc":[{"atb":[[2.2,0]],"id":43154457},{"atl":[[4.7,0]],"id":43154457}],"con":true,"img":false}]}
{"op":"mcm","clk":"5306698424","pt":1646103951056,"mc":[{"id":"1.195395427","rc":[{"atb":[[1.01,2.23]],"id":38407646},{"atb":[[2.46,10.82]],"id":36087680}],"con":true,"img":false}]}
{"op":"mcm","clk":"5306698433","pt":1646103951262,"mc":[{"id":"1.195395427","rc":[{"atb":[[1.01,1.61]],"id":38407646}],"con":true,"img":false}]}
{"op":"mcm","clk":"5306698440","pt":1646103951364,"mc":[{"id":"1.195395427","rc":[{"atb":[[5.6,21.97],[1.01,0]],"id":38407646},{"atb":[[2.48,8.57]],"id":36087680}],"con":true,"img":false}]}
{"op":"mcm","clk":"5306698446","pt":1646103951465,"mc":[{"id":"1.195395427","rc":[{"atb":[[5.6,23.59]],"id":38407646}],"con":true,"img":false}]}
{"op":"mcm","clk":"5306698453","pt":1646103951674,"mc":[{"id":"1.195395427","rc":[{"atb":[[2.48,12.58]],"id":36087680}],"con":true,"img":false}]}
{"op":"mcm","clk":"5306698504","pt":1646103953098,"mc":[{"id":"1.195395427","rc":[{"atb":[[2.22,30.52]],"id":43154457}],"con":true,"img":false}]}
{"op":"mcm","clk":"5306698543","pt":1646103954273,"mc":[{"id":"1.195395427","rc":[{"atb":[[5.5,2]],"id":38407646},{"atb":[[2.44,0]],"id":36087680}],"con":true,"img":false}]}
{"op":"mcm","clk":"5306698547","pt":1646103954376,"mc":[{"id":"1.195395427","rc":[{"atb":[[2.22,19.91]],"id":43154457}],"con":true,"img":false}]}
{"op":"mcm","clk":"5306698552","pt":1646103954477,"mc":[{"id":"1.195395427","rc":[{"atb":[[5.6,41.68]],"id":38407646},{"atb":[[2.48,32.43]],"id":36087680}],"con":true,"img":false}]}
{"op":"mcm","clk":"5306698630","pt":1646103956266,"mc":[{"id":"1.195395427","rc":[{"atl":[[5.3,28.67]],"id":36087680}],"con":true,"img":false}]}
{"op":"mcm","clk":"5306698648","pt":1646103956675,"mc":[{"id":"1.195395427","rc":[{"atb":[[5.6,21.52]],"id":38407646},{"atb":[[2.12,65.73]],"id":43154457}],"con":true,"img":false}]}
{"op":"mcm","clk":"5306698725","pt":1646103958466,"mc":[{"id":"1.195395427","rc":[{"atl":[[290,0]],"id":42130949},{"atb":[[5.3,0.7]],"id":38407646},{"atb":[[2.18,0]],"id":43154457},{"atb":[[2.42,0]],"id":36087680}],"con":true,"img":false}]}
{"op":"mcm","clk":"5306698731","pt":1646103958568,"mc":[{"id":"1.195395427","rc":[{"atl":[[230,2.7]],"id":42130949},{"atb":[[5.1,14.15]],"id":38407646},{"atb":[[2.14,54.34]],"id":43154457},{"atb":[[2.46,54.13]],"id":36087680}],"con":true,"img":false}]}
{"op":"mcm","clk":"5306698767","pt":1646103959387,"mc":[{"id":"1.195395427","rc":[{"atl":[[240,0.24]],"id":42130949},{"atb":[[2.12,85.94]],"id":43154457}],"con":true,"img":false}]}
{"op":"mcm","clk":"5306698771","pt":1646103959489,"mc":[{"id":"1.195395427","rc":[{"atl":[[230,3.29]],"id":42130949}],"con":true,"img":false}]}
{"op":"mcm","clk":"5306698791","pt":1646103960102,"mc":[{"id":"1.195395427","rc":[{"atb":[[5.4,21.07]],"id":38407646}],"con":true,"img":false}]}
{"op":"mcm","clk":"5306698798","pt":1646103960306,"mc":[{"id":"1.195395427","rc":[{"atb":[[5.6,19.9]],"id":38407646}],"con":true,"img":false}]}
{"op":"mcm","clk":"5306698877","pt":1646103961893,"mc":[{"id":"1.195395427","rc":[{"atb":[[2.12,20.2]],"id":43154457},{"atb":[[2.48,23.85]],"id":36087680}],"con":true,"img":false}]}
{"op":"mcm","clk":"5306698892","pt":1646103962201,"mc":[{"id":"1.195395427","rc":[{"atb":[[2.48,19.85]],"id":36087680}],"con":true,"img":false}]}
{"op":"mcm","clk":"5306698902","pt":1646103962408,"mc":[{"id":"1.195395427","rc":[{"atl":[[3.5,9.02]],"id":43154457}],"con":true,"img":false}]}
{"op":"mcm","clk":"5306698908","pt":1646103962510,"mc":[{"id":"1.195395427","rc":[{"atl":[[4.1,7.71]],"id":36087680}],"con":true,"img":false}]}
{"op":"mcm","clk":"5306698939","pt":1646103963180,"mc":[{"id":"1.195395427","rc":[{"atb":[[2.46,49.02]],"id":36087680}],"con":true,"img":false}]}
{"op":"mcm","clk":"5306699040","pt":1646103965479,"mc":[{"id":"1.195395427","rc":[{"atb":[[2.16,54.78]],"id":43154457},{"atb":[[2.24,74.78]],"id":36087680}],"con":true,"img":false}]}
{"op":"mcm","clk":"5306699107","pt":1646103967315,"mc":[{"id":"1.195395427","rc":[{"atb":[[2.24,93.03]],"id":36087680}],"con":true,"img":false}]}
{"op":"mcm","clk":"5306699160","pt":1646103968490,"mc":[{"id":"1.195395427","rc":[{"atb":[[5.6,18.09]],"id":38407646},{"atb":[[2.46,43.3]],"id":36087680}],"con":true,"img":false}]}
{"op":"mcm","clk":"5306699176","pt":1646103968900,"mc":[{"id":"1.195395427","rc":[{"atl":[[3.6,22.32]],"id":43154457},{"atl":[[4.2,18.13]],"id":36087680}],"con":true,"img":false}]}
{"op":"mcm","clk":"5306699183","pt":1646103969002,"mc":[{"id":"1.195395427","rc":[{"atl":[[3.5,26.56]],"id":43154457},{"atl":[[4.1,22.36]],"id":36087680}],"con":true,"img":false}]}
{"op":"mcm","clk":"5306699197","pt":1646103969206,"mc":[{"id":"1.195395427","rc":[{"atb":[[1.01,2.23]],"id":38407646}],"con":true,"img":false}]}
{"op":"mcm","clk":"5306699208","pt":1646103969411,"mc":[{"id":"1.195395427","rc":[{"atb":[[1.01,1.58]],"id":38407646}],"con":true,"img":false}]}
{"op":"mcm","clk":"5306699217","pt":1646103969615,"mc":[{"id":"1.195395427","rc":[{"atb":[[1.01,0]],"id":38407646}],"con":true,"img":false}]}
{"op":"mcm","clk":"5306699221","pt":1646103969717,"mc":[{"id":"1.195395427","rc":[{"atb":[[5.7,1.58]],"id":38407646}],"con":true,"img":false}]}
{"op":"mcm","clk":"5306699229","pt":1646103969871,"mc":[{"id":"1.195395427","rc":[{"atb":[[2.12,0]],"id":43154457}],"con":true,"img":false}]}
{"op":"mcm","clk":"5306699316","pt":1646103971918,"mc":[{"id":"1.195395427","rc":[{"atb":[[9.6,0],[2.62,0],[4.2,0]],"id":37284251},{"atb":[[13,0],[2.62,0],[4.2,0]],"id":42130949},{"atb":[[3.05,0]],"id":38407646},{"atl":[[34,0],[20,0]],"id":38407646},{"atb":[[3,0]],"id":43154456},{"atl":[[34,0],[19.5,0]],"id":43154456},{"atl":[[17,0],[34,0],[6,0]],"id":43154457},{"atb":[[1.61,0]],"id":36087680},{"atl":[[7.2,0],[17,0],[34,0]],"id":36087680}],"con":true,"img":false}]}
{"op":"mcm","clk":"5306699350","pt":1646103972789,"mc":[{"id":"1.195395427","rc":[{"atl":[[230,0.58]],"id":42130949}],"con":true,"img":false}]}
{"op":"mcm","clk":"5306699355","pt":1646103972892,"mc":[{"id":"1.195395427","rc":[{"atl":[[290,2.7]],"id":42130949}],"con":true,"img":false}]}
{"op":"mcm","clk":"5306699418","pt":1646103974477,"mc":[{"id":"1.195395427","rc":[{"atb":[[5.7,3.36]],"id":38407646}],"con":true,"img":false}]}
{"op":"mcm","clk":"5306699441","pt":1646103975397,"mc":[{"id":"1.195395427","rc":[{"atb":[[2.24,15.33]],"id":43154457}],"con":true,"img":false}]}
{"op":"mcm","clk":"5306699488","pt":1646103976881,"mc":[{"id":"1.195395427","rc":[{"atb":[[5.4,0]],"id":38407646}],"con":true,"img":false}]}
{"op":"mcm","clk":"5306699525","pt":1646103978109,"mc":[{"id":"1.195395427","rc":[{"atb":[[2.5,4.97]],"id":36087680}],"con":true,"img":false}]}
{"op":"mcm","clk":"5306699544","pt":1646103978519,"mc":[{"id":"1.195395427","rc":[{"atb":[[2.16,0]],"id":43154457}],"con":true,"img":false}]}
{"op":"mcm","clk":"5306699611","pt":1646103980314,"mc":[{"id":"1.195395427","rc":[{"atb":[[5.8,5.05]],"id":38407646},{"atb":[[2.24,18.24]],"id":36087680}],"con":true,"img":false}]}
{"op":"mcm","clk":"5306699615","pt":1646103980416,"mc":[{"id":"1.195395427","rc":[{"atb":[[2.5,10.54]],"id":36087680}],"con":true,"img":false}]}
{"op":"mcm","clk":"5306699703","pt":1646103982108,"mc":[{"id":"1.195395427","rc":[{"atb":[[2.16,47.67]],"id":43154457}],"con":true,"img":false}]}
{"op":"mcm","clk":"5306699746","pt":1646103983393,"mc":[{"id":"1.195395427","rc":[{"atb":[[2.24,0]],"id":43154457},{"atb":[[2.24,0]],"id":36087680}],"con":true,"img":false}]}
{"op":"mcm","clk":"5306699774","pt":1646103984005,"mc":[{"id":"1.195395427","rc":[{"atb":[[2.52,15.8]],"id":36087680}],"con":true,"img":false}]}
{"op":"mcm","clk":"5306699787","pt":1646103984211,"mc":[{"id":"1.195395427","rc":[{"atb":[[2.22,0]],"id":43154457}],"con":true,"img":false}]}
{"op":"mcm","clk":"5306699803","pt":1646103984516,"mc":[{"id":"1.195395427","rc":[{"atb":[[2.24,18.99]],"id":43154457}],"con":true,"img":false}]}
{"op":"mcm","clk":"5306699881","pt":1646103986918,"mc":[{"id":"1.195395427","rc":[{"spn":8.4,"spf":1.0,"id":38407646},{"atb":[[2.46,0]],"id":36087680},{"spn":3.31,"spf":1.0,"id":36087680}],"con":true,"img":false}]}
{"op":"mcm","clk":"5306699884","pt":1646103987019,"mc":[{"id":"1.195395427","rc":[{"atb":[[2.5,53.84]],"id":36087680}],"con":true,"img":false}]}
{"op":"mcm","clk":"5306699952","pt":1646103988811,"mc":[{"id":"1.195395427","rc":[{"atb":[[2.18,19.17]],"id":43154457},{"atb":[[2.54,11.06]],"id":36087680}],"con":true,"img":false}]}
{"op":"mcm","clk":"5306700031","pt":1646103990811,"mc":[{"id":"1.195395427","rc":[{"atb":[[2.16,0]],"id":43154457},{"atb":[[2.52,0]],"id":36087680}],"con":true,"img":false}]}
{"op":"mcm","clk":"5306700137","pt":1646103993319,"mc":[{"id":"1.195395427","rc":[{"atl":[[3.5,22.3]],"id":43154457},{"atb":[[2.5,48.87]],"id":36087680}],"con":true,"img":false}]}
{"op":"mcm","clk":"5306700182","pt":1646103994445,"mc":[{"id":"1.195395427","rc":[{"atb":[[2.2,47.23]],"id":43154457},{"atb":[[2.56,16.59]],"id":36087680}],"con":true,"img":false}]}
{"op":"mcm","clk":"5306700213","pt":1646103995214,"mc":[{"id":"1.195395427","rc":[{"atb":[[5.6,0]],"id":38407646},{"atb":[[2.48,0]],"id":36087680}],"con":true,"img":false}]}
{"op":"mcm","clk":"5306700236","pt":1646103995623,"mc":[{"id":"1.195395427","rc":[{"atb":[[5.8,21.46]],"id":38407646},{"atb":[[2.52,20.74]],"id":36087680}],"con":true,"img":false}]}
{"op":"mcm","clk":"5306700268","pt":1646103996339,"mc":[{"id":"1.195395427","rc":[{"atl":[[4.1,18.72]],"id":36087680}],"con":true,"img":false}]}
{"op":"mcm","clk":"5306700325","pt":1646103997718,"mc":[{"id":"1.195395427","rc":[{"atb":[[5.8,16.41]],"id":38407646}],"con":true,"img":false}]}
{"op":"mcm","clk":"5306700358","pt":1646103998435,"mc":[{"id":"1.195395427","rc":[{"atb":[[2.18,0]],"id":43154457},{"atb":[[2.54,0]],"id":36087680}],"con":true,"img":false}]}
{"op":"mcm","clk":"5306700398","pt":1646103999255,"mc":[{"id":"1.195395427","rc":[{"atl":[[3.45,4.32]],"id":43154457},{"atl":[[4,3.72]],"id":36087680}],"con":true,"img":false}]}
{"op":"mcm","clk":"5306700467","pt":1646104000840,"mc":[{"id":"1.195395427","rc":[{"atl":[[240,0]],"id":42130949},{"atb":[[2.14,0]],"id":43154457}],"con":true,"img":false}]}
{"op":"mcm","clk":"5306700471","pt":1646104000942,"mc":[{"id":"1.195395427","rc":[{"atl":[[220,0.24]],"id":42130949},{"atb":[[2.12,54.34]],"id":43154457}],"con":true,"img":false}]}
{"op":"mcm","clk":"5306700479","pt":1646104001250,"mc":[{"id":"1.195395427","rc":[{"atb":[[5.9,18.92]],"id":38407646},{"atb":[[2.2,0]],"id":43154457}],"con":true,"img":false}]}
{"op":"mcm","clk":"5306700509","pt":1646104002223,"mc":[{"id":"1.195395427","rc":[{"atb":[[5.7,1.77]],"id":38407646}],"con":true,"img":false}]}
{"op":"mcm","clk":"5306700596","pt":1646104004527,"mc":[{"id":"1.195395427","rc":[{"atb":[[2.16,19.5]],"id":43154457},{"atb":[[2.5,43.3],[2.58,11.61]],"id":36087680}],"con":true,"img":false}]}
{"op":"mcm","clk":"5306700622","pt":1646104005037,"mc":[{"id":"1.195395427","rc":[{"atb":[[2.14,62.98]],"id":43154457}],"con":true,"img":false}]}
{"op":"mcm","clk":"5306700630","pt":1646104005242,"mc":[{"id":"1.195395427","rc":[{"atb":[[2.54,4.83]],"id":36087680}],"con":true,"img":false}]}
{"op":"mcm","clk":"5306700703","pt":1646104006628,"mc":[{"id":"1.195395427","rc":[{"atb":[[2.52,0]],"id":36087680}],"con":true,"img":false}]}
{"op":"mcm","clk":"5306700714","pt":1646104006831,"mc":[{"id":"1.195395427","rc":[{"atb":[[2.56,0]],"id":36087680}],"con":true,"img":false}]}
{"op":"mcm","clk":"5306700728","pt":1646104007137,"mc":[{"id":"1.195395427","rc":[{"atb":[[2.56,19.31]],"id":36087680}],"con":true,"img":false}]}
{"op":"mcm","clk":"5306700785","pt":1646104008472,"mc":[{"id":"1.195395427","rc":[{"atb":[[2.14,0]],"id":43154457}],"con":true,"img":false}]}
{"op":"mcm","clk":"5306700878","pt":1646104010264,"mc":[{"id":"1.195395427","rc":[{"atb":[[2.6,17.43]],"id":36087680}],"con":true,"img":false}]}
{"op":"mcm","clk":"5306700885","pt":1646104010469,"mc":[{"id":"1.195395427","rc":[{"atb":[[5.7,0]],"id":38407646}],"con":true,"img":false}]}
{"op":"mcm","clk":"5306700888","pt":1646104010571,"mc":[{"id":"1.195395427","rc":[{"atb":[[2.54,10.25]],"id":36087680}],"con":true,"img":false}]}
{"op":"mcm","clk":"5306700953","pt":1646104012059,"mc":[{"id":"1.195395427","rc":[{"atb":[[2.18,52.49]],"id":43154457}],"con":true,"img":false}]}
{"op":"mcm","clk":"5306700964","pt":1646104012367,"mc":[{"id":"1.195395427","rc":[{"atb":[[2.16,0]],"id":43154457}],"con":true,"img":false}]}
{"op":"mcm","clk":"5306701043","pt":1646104013852,"mc":[{"id":"1.195395427","rc":[{"atb":[[5.9,0]],"id":38407646}],"con":true,"img":false}]}
{"op":"mcm","clk":"5306701069","pt":1646104014365,"mc":[{"id":"1.195395427","rc":[{"atl":[[230,0]],"id":42130949},{"atb":[[5.8,0]],"id":38407646},{"atb":[[2.56,0],[2.5,0]],"id":36087680}],"con":true,"img":false}]}
{"op":"mcm","clk":"5306701075","pt":1646104014468,"mc":[{"id":"1.195395427","rc":[{"atb":[[2.36,43.3]],"id":36087680}],"con":true,"img":false}]}
{"op":"mcm","clk":"5306701085","pt":1646104014672,"mc":[{"id":"1.195395427","rc":[{"atl":[[220,0.86]],"id":42130949},{"atb":[[5.9,15.62]],"id":38407646},{"atb":[[2.58,30.24]],"id":36087680}],"con":true,"img":false}]}
{"op":"mcm","clk":"5306701096","pt":1646104014876,"mc":[{"id":"1.195395427","rc":[{"atb":[[2.58,18.62]],"id":36087680}],"con":true,"img":false}]}
{"op":"mcm","clk":"5306701206","pt":1646104017286,"mc":[{"id":"1.195395427","rc":[{"atb":[[5.4,21.07]],"id":38407646}],"con":true,"img":false}]}
{"op":"mcm","clk":"5306701235","pt":1646104017951,"mc":[{"id":"1.195395427","rc":[{"atb":[[2.14,19.84]],"id":43154457}],"con":true,"img":false}]}
{"op":"mcm","clk":"5306701353","pt":1646104020564,"mc":[{"id":"1.195395427","rc":[{"atb":[[2.18,0]],"id":43154457}],"con":true,"img":false}]}
{"op":"mcm","clk":"5306701377","pt":1646104021076,"mc":[{"id":"1.195395427","rc":[{"atb":[[2.62,12.2]],"id":36087680}],"con":true,"img":false}]}
{"op":"mcm","clk":"5306701420","pt":1646104021950,"mc":[{"id":"1.195395427","rc":[{"atb":[[2.58,0]],"id":36087680}],"con":true,"img":false}]}
{"op":"mcm","clk":"5306701443","pt":1646104022358,"mc":[{"id":"1.195395427","rc":[{"atb":[[2.6,35.38]],"id":36087680}],"con":true,"img":false}]}
{"op":"mcm","clk":"5306701484","pt":1646104023281,"mc":[{"id":"1.195395427","rc":[{"atb":[[2.54,5.41]],"id":36087680}],"con":true,"img":false}]}
{"op":"mcm","clk":"5306701528","pt":1646104024150,"mc":[{"id":"1.195395427","rc":[{"atb":[[2.16,57.74]],"id":43154457},{"atb":[[2.6,17.95]],"id":36087680}],"con":true,"img":false}]}
{"op":"mcm","clk":"5306701716","pt":1646104027683,"mc":[{"id":"1.195395427","rc":[{"atb":[[2.56,30.49]],"id":36087680}],"con":true,"img":false}]}
{"op":"mcm","clk":"5306701763","pt":1646104028557,"mc":[{"id":"1.195395427","rc":[{"atb":[[2.12,0]],"id":43154457},{"atb":[[2.54,0]],"id":36087680}],"con":true,"img":false}]}
{"op":"mcm","clk":"5306701770","pt":1646104028655,"mc":[{"id":"1.195395427","rc":[{"atb":[[2.18,54.34],[2.14,0]],"id":43154457}],"con":true,"img":false}]}
{"op":"mcm","clk":"5306701896","pt":1646104030862,"mc":[{"id":"1.195395427","rc":[{"atb":[[2.16,0]],"id":43154457}],"con":true,"img":false}]}
{"op":"mcm","clk":"5306702056","pt":1646104033681,"mc":[{"id":"1.195395427","rc":[{"atb":[[2.12,20.2]],"id":43154457}],"con":true,"img":false}]}
{"op":"mcm","clk":"5306702093","pt":1646104034401,"mc":[{"id":"1.195395427","rc":[{"atb":[[2.12,88.44]],"id":43154457}],"con":true,"img":false}]}
{"op":"mcm","clk":"5306702100","pt":1646104034503,"mc":[{"id":"1.195395427","rc":[{"atb":[[2.4,5.96]],"id":36087680}],"con":true,"img":false}]}
{"op":"mcm","clk":"5306702182","pt":1646104036090,"mc":[{"id":"1.195395427","rc":[{"atb":[[2.6,0]],"id":36087680}],"con":true,"img":false}]}
{"op":"mcm","clk":"5306702204","pt":1646104036499,"mc":[{"id":"1.195395427","rc":[{"atb":[[2.62,29.49]],"id":36087680}],"con":true,"img":false}]}
{"op":"mcm","clk":"5306702329","pt":1646104039313,"mc":[{"id":"1.195395427","rc":[{"atb":[[2.56,0]],"id":36087680}],"con":true,"img":false}]}
{"op":"mcm","clk":"5306702414","pt":1646104041613,"mc":[{"id":"1.195395427","rc":[{"atb":[[2.62,17.29]],"id":36087680}],"con":true,"img":false}]}
{"op":"mcm","clk":"5306702422","pt":1646104041817,"mc":[{"id":"1.195395427","rc":[{"atb":[[1.01,2.98]],"id":38407646},{"atb":[[2.18,0]],"id":43154457}],"con":true,"img":false}]}
{"op":"mcm","clk":"5306702427","pt":1646104041919,"mc":[{"id":"1.195395427","rc":[{"atb":[[2.14,54.34]],"id":43154457}],"con":true,"img":false}]}
{"op":"mcm","clk":"5306702454","pt":1646104042685,"mc":[{"id":"1.195395427","rc":[{"atb":[[2.42,65.3]],"id":36087680}],"con":true,"img":false}]}
{"op":"mcm","clk":"5306702460","pt":1646104042889,"mc":[{"id":"1.195395427","rc":[{"atb":[[1.01,1.78]],"id":38407646}],"con":true,"img":false}]}
{"op":"mcm","clk":"5306702489","pt":1646104043806,"mc":[{"id":"1.195395427","rc":[{"atb":[[1.01,0]],"id":38407646}],"con":true,"img":false}]}
{"op":"mcm","clk":"5306702491","pt":1646104043910,"mc":[{"id":"1.195395427","rc":[{"atl":[[11,9.96]],"id":38407646},{"trd":[[11,3.57]],"ltp":11.0,"tv":3.57,"id":38407646}],"con":true,"img":false}]}
{"op":"mcm","clk":"5306702502","pt":1646104044113,"mc":[{"id":"1.195395427","rc":[{"atb":[[5.5,0]],"id":38407646}],"con":true,"img":false}]}
{"op":"mcm","clk":"5306702509","pt":1646104044317,"mc":[{"id":"1.195395427","rc":[{"atb":[[2.12,20.2]],"id":43154457}],"con":true,"img":false}]}
{"op":"mcm","clk":"5306702533","pt":1646104044779,"mc":[{"id":"1.195395427","rc":[{"atl":[[3.4,2.5]],"id":43154457},{"atl":[[3.95,2.5]],"id":36087680}],"con":true,"img":false}]}
{"op":"mcm","clk":"5306702584","pt":1646104046109,"mc":[{"id":"1.195395427","rc":[{"atb":[[22,1.66]],"id":37284251},{"atb":[[5.2,2.5]],"id":43154456}],"con":true,"img":false}]}
{"op":"mcm","clk":"5306702631","pt":1646104047188,"mc":[{"id":"1.195395427","rc":[{"spn":8.45,"spf":1.0,"id":38407646},{"spn":7.5,"spf":1.0,"id":43154456},{"atb":[[2.12,0]],"id":43154457},{"spn":2.88,"spf":1.0,"id":43154457},{"atb":[[2.44,15.71]],"id":36087680},{"spn":3.28,"spf":1.0,"id":36087680}],"con":true,"img":false}]}
{"op":"mcm","clk":"5306702660","pt":1646104047804,"mc":[{"id":"1.195395427","rc":[{"atb":[[2.16,57.74]],"id":43154457}],"con":true,"img":false}]}
{"op":"mcm","clk":"5306702740","pt":1646104049492,"mc":[{"id":"1.195395427","rc":[{"atb":[[5.1,4.16]],"id":43154456},{"atb":[[2.42,0]],"id":36087680}],"con":true,"img":false}]}
{"op":"mcm","clk":"5306702794","pt":1646104050824,"mc":[{"id":"1.195395427","rc":[{"atb":[[5.1,0]],"id":43154456},{"atb":[[2.16,77.24]],"id":43154457}],"con":true,"img":false}]}
{"op":"mcm","clk":"5306702890","pt":1646104053129,"mc":[{"id":"1.195395427","rc":[{"atb":[[5,7.63]],"id":43154456},{"atb":[[2.46,63.51]],"id":36087680}],"con":true,"img":false}]}
{"op":"mcm","clk":"5306702923","pt":1646104053897,"mc":[{"id":"1.195395427","rc":[{"atb":[[5,10.13]],"id":43154456},{"atb":[[2.44,0]],"id":36087680}],"con":true,"img":false}]}
{"op":"mcm","clk":"5306702988","pt":1646104055435,"mc":[{"id":"1.195395427","rc":[{"atb":[[17,0],[21,5.73]],"id":37284251},{"atb":[[5.1,0]],"id":38407646},{"atl":[[11,6.22],[15,0]],"id":38407646},{"atb":[[4.8,0.73]],"id":43154456},{"atb":[[2.36,0]],"id":36087680}],"con":true,"img":false}]}
{"op":"mcm","clk":"5306702989","pt":1646104055535,"mc":[{"id":"1.195395427","rc":[{"atb":[[17,3.51],[14.5,8.11]],"id":37284251},{"atb":[[5.5,14.15]],"id":38407646},{"atl":[[13,3.73],[15.5,9.19]],"id":38407646},{"atb":[[4.4,16.57]],"id":43154456},{"atb":[[2.26,45.3]],"id":36087680}],"con":true,"img":false}]}
{"op":"mcm","clk":"5306703028","pt":1646104056302,"mc":[{"id":"1.195395427","rc":[{"atb":[[21,0]],"id":37284251}],"con":true,"img":false}]}
{"op":"mcm","clk":"5306703035","pt":1646104056406,"mc":[{"id":"1.195395427","rc":[{"atb":[[1.01,2.53]],"id":38407646}],"con":true,"img":false}]}
{"op":"mcm","clk":"5306703050","pt":1646104056612,"mc":[{"id":"1.195395427","rc":[{"atb":[[22,6.7]],"id":37284251},{"atb":[[1.01,1.69]],"id":38407646}],"con":true,"img":false}]}
{"op":"mcm","clk":"5306703064","pt":1646104056917,"mc":[{"id":"1.195395427","rc":[{"atb":[[1.01,0]],"id":38407646}],"con":true,"img":false}]}
{"op":"mcm","clk":"5306703072","pt":1646104057020,"mc":[{"id":"1.195395427","rc":[{"atb":[[6,1.69]],"id":38407646}],"con":true,"img":false}]}
{"op":"mcm","clk":"5306703128","pt":1646104057995,"mc":[{"id":"1.195395427","rc":[{"atb":[[5.4,0]],"id":38407646}],"con":true,"img":false}]}
{"op":"mcm","clk":"5306703166","pt":1646104058710,"mc":[{"id":"1.195395427","rc":[{"atb":[[2.4,0]],"id":36087680}],"con":true,"img":false}]}
{"op":"mcm","clk":"5306703184","pt":1646104059121,"mc":[{"id":"1.195395427","rc":[{"atb":[[2.42,15.93]],"id":36087680}],"con":true,"img":false}]}
{"op":"mcm","clk":"5306703299","pt":1646104061324,"mc":[{"id":"1.195395427","rc":[{"atb":[[2.46,0]],"id":36087680}],"con":true,"img":false}]}
{"op":"mcm","clk":"5306703354","pt":1646104062402,"mc":[{"id":"1.195395427","rc":[{"atb":[[4.9,2.13]],"id":43154456}],"con":true,"img":false}]}
{"op":"mcm","clk":"5306703458","pt":1646104064651,"mc":[{"id":"1.195395427","rc":[{"atb":[[5,4.5]],"id":43154456},{"atb":[[2.28,72.45]],"id":36087680}],"con":true,"img":false}]}
{"op":"mcm","clk":"5306703469","pt":1646104064822,"mc":[{"id":"1.195395427","rc":[{"atb":[[2.2,6.95]],"id":43154457}],"con":true,"img":false}]}
{"op":"mcm","clk":"5306703483","pt":1646104065314,"mc":[{"id":"1.195395427","rc":[{"atb":[[2.2,13.16]],"id":43154457}],"con":true,"img":false}]}
{"op":"mcm","clk":"5306703517","pt":1646104066335,"mc":[{"id":"1.195395427","rc":[{"atl":[[14,11.68]],"id":43154456}],"con":true,"img":false}]}
{"op":"mcm","clk":"5306703527","pt":1646104066641,"mc":[{"id":"1.195395427","rc":[{"atb":[[5,2]],"id":43154456},{"atb":[[2.42,0]],"id":36087680}],"con":true,"img":false}]}
{"op":"mcm","clk":"5306703573","pt":1646104067916,"mc":[{"id":"1.195395427","rc":[{"atb":[[5.3,3.75]],"id":43154456},{"atb":[[2.16,19.5]],"id":43154457}],"con":true,"img":false}]}
{"op":"mcm","clk":"5306703594","pt":1646104068633,"mc":[{"id":"1.195395427","rc":[{"atb":[[5.2,0]],"id":43154456}],"con":true,"img":false}]}
{"op":"mcm","clk":"5306703603","pt":1646104068939,"mc":[{"id":"1.195395427","rc":[{"atb":[[2.16,0]],"id":43154457}],"con":true,"img":false}]}
{"op":"mcm","clk":"5306703627","pt":1646104069453,"mc":[{"id":"1.195395427","rc":[{"atl":[[70,1.95]],"id":37284251},{"atl":[[220,0.61]],"id":42130949},{"atb":[[5.5,0]],"id":38407646},{"atl":[[9.8,18.44]],"id":43154456},{"atb":[[2.14,0]],"id":43154457},{"atl":[[3.6,0]],"id":43154457}],"con":true,"img":false}]}
{"op":"mcm","clk":"5306703630","pt":1646104069555,"mc":[{"id":"1.195395427","rc":[{"atl":[[60,2.7]],"id":37284251},{"atl":[[200,0.24]],"id":42130949},{"atb":[[5.1,14.15]],"id":38407646},{"atl":[[9,6.1]],"id":43154456},{"atb":[[2.12,54.34]],"id":43154457},{"atl":[[3.45,26.64]],"id":43154457}],"con":true,"img":false}]}
{"op":"mcm","clk":"5306703657","pt":1646104070725,"mc":[{"id":"1.195395427","rc":[{"atb":[[6.2,2.5]],"id":38407646},{"atb":[[4.9,0],[5.4,2.5]],"id":43154456}],"con":true,"img":false}]}
{"op":"mcm","clk":"5306703674","pt":1646104071133,"mc":[{"id":"1.195395427","rc":[{"atb":[[2.16,57.74]],"id":43154457}],"con":true,"img":false}]}
{"op":"mcm","clk":"5306703707","pt":1646104072052,"mc":[{"id":"1.195395427","rc":[{"atb":[[5,6.12]],"id":43154456},{"atb":[[2.3,17.4]],"id":36087680}],"con":true,"img":false}]}
{"op":"mcm","clk":"5306703731","pt":1646104072417,"mc":[{"id":"1.195395427","rc":[{"atb":[[6,0]],"id":38407646}],"con":true,"img":false}]}
{"op":"mcm","clk":"5306703740","pt":1646104072721,"mc":[{"id":"1.195395427","rc":[{"atb":[[5.3,0]],"id":43154456}],"con":true,"img":false}]}
{"op":"mcm","clk":"5306703787","pt":1646104074326,"mc":[{"id":"1.195395427","rc":[{"atb":[[2.28,0]],"id":36087680}],"con":true,"img":false}]}
{"op":"mcm","clk":"5306703805","pt":1646104074834,"mc":[{"id":"1.195395427","rc":[{"atb":[[2.26,14.69]],"id":43154457}],"con":true,"img":false}]}
{"op":"mcm","clk":"5306703810","pt":1646104075038,"mc":[{"id":"1.195395427","rc":[{"atl":[[70,0]],"id":37284251},{"atl":[[220,0]],"id":42130949},{"atl":[[9.8,0]],"id":43154456},{"atl":[[3.5,4.76]],"id":43154457}],"con":true,"img":false}]}
{"op":"mcm","clk":"5306703814","pt":1646104075344,"mc":[{"id":"1.195395427","rc":[{"atl":[[60,4.99]],"id":37284251},{"atl":[[200,0.92]],"id":42130949},{"atl":[[9,23.01]],"id":43154456},{"atl":[[3.45,43.11]],"id":43154457}],"con":true,"img":false}]}
{"op":"mcm","clk":"5306703873","pt":1646104077435,"mc":[{"id":"1.195395427","rc":[{"atb":[[5,2]],"id":43154456}],"con":true,"img":false}]}
{"op":"mcm","clk":"5306703881","pt":1646104077741,"mc":[{"id":"1.195395427","rc":[{"atb":[[5.1,6.26]],"id":43154456},{"atb":[[2.16,0]],"id":43154457},{"atb":[[2.32,70.25]],"id":36087680}],"con":true,"img":false}]}
{"op":"mcm","clk":"5306703964","pt":1646104080450,"mc":[{"id":"1.195395427","rc":[{"atb":[[2.2,6.95]],"id":43154457}],"con":true,"img":false}]}
{"op":"mcm","clk":"5306703986","pt":1646104081064,"mc":[{"id":"1.195395427","rc":[{"atb":[[2.28,25.04]],"id":43154457}],"con":true,"img":false}]}
{"op":"mcm","clk":"5306704018","pt":1646104082241,"mc":[{"id":"1.195395427","rc":[{"atb":[[2.24,0]],"id":43154457}],"con":true,"img":false}]}
{"op":"mcm","clk":"5306704028","pt":1646104082651,"mc":[{"id":"1.195395427","rc":[{"atb":[[5.2,2.5]],"id":43154456},{"atb":[[2.2,0]],"id":43154457},{"atb":[[2.3,0],[2.26,2]],"id":36087680},{"atl":[[4.2,0]],"id":36087680}],"con":true,"img":false}]}
{"op":"mcm","clk":"5306704032","pt":1646104082753,"mc":[{"id":"1.195395427","rc":[{"atl":[[3.5,0]],"id":43154457},{"atb":[[2.34,43.3]],"id":36087680},{"atl":[[3.65,18.13]],"id":36087680}],"con":true,"img":false}]}
{"op":"mcm","clk":"5306704041","pt":1646104082960,"mc":[{"id":"1.195395427","rc":[{"atb":[[2.26,32.79]],"id":43154457}],"con":true,"img":false}]}
{"op":"mcm","clk":"5306704100","pt":1646104084034,"mc":[{"id":"1.195395427","rc":[{"atl":[[3.95,0]],"id":36087680}],"con":true,"img":false}]}
{"op":"mcm","clk":"5306704153","pt":1646104085768,"mc":[{"id":"1.195395427","rc":[{"atb":[[5.1,0]],"id":43154456},{"atb":[[2.28,0]],"id":43154457},{"atb":[[2.32,0]],"id":36087680}],"con":true,"img":false}]}
{"op":"mcm","clk":"5306704181","pt":1646104086436,"mc":[{"id":"1.195395427","rc":[{"atb":[[2.26,18.09]],"id":43154457},{"atb":[[2.24,18.24]],"id":36087680}],"con":true,"img":false}]}
{"op":"mcm","clk":"5306704263","pt":1646104088732,"mc":[{"id":"1.195395427","rc":[{"atl":[[4.1,14.65]],"id":36087680}],"con":true,"img":false}]}
{"op":"mcm","clk":"5306704281","pt":1646104089445,"mc":[{"id":"1.195395427","rc":[{"atb":[[5.5,3.75]],"id":43154456},{"atb":[[2.14,65.3]],"id":43154457},{"atb":[[2.26,75.6]],"id":36087680}],"con":true,"img":false}]}
{"op":"mcm","clk":"5306704284","pt":1646104089648,"mc":[{"id":"1.195395427","rc":[{"atb":[[5.2,0]],"id":43154456},{"atb":[[2.14,85.15]],"id":43154457}],"con":true,"img":false}]}
{"op":"mcm","clk":"5306704300","pt":1646104090462,"mc":[{"id":"1.195395427","rc":[{"atb":[[5.4,0]],"id":43154456}],"con":true,"img":false}]}
{"op":"mcm","clk":"5306704356","pt":1646104092151,"mc":[{"id":"1.195395427","rc":[{"atb":[[2.24,0]],"id":36087680}],"con":true,"img":false}]}
{"op":"mcm","clk":"5306704488","pt":1646104095369,"mc":[{"id":"1.195395427","rc":[{"atb":[[4.9,5.26]],"id":43154456}],"con":true,"img":false}]}
{"op":"mcm","clk":"5306704548","pt":1646104097058,"mc":[{"id":"1.195395427","rc":[{"atb":[[5.5,0]],"id":43154456},{"atb":[[2.34,0]],"id":36087680},{"atl":[[3.65,0]],"id":36087680}],"con":true,"img":false}]}
{"op":"mcm","clk":"5306704551","pt":1646104097161,"mc":[{"id":"1.195395427","rc":[{"atb":[[2.28,43.3]],"id":36087680},{"atl":[[3.85,18.13]],"id":36087680}],"con":true,"img":false}]}
{"op":"mcm","clk":"5306704575","pt":1646104097974,"mc":[{"id":"1.195395427","rc":[{"atb":[[5.1,2.5]],"id":43154456}],"con":true,"img":false}]}
{"op":"mcm","clk":"5306704579","pt":1646104098077,"mc":[{"id":"1.195395427","rc":[{"atb":[[2.28,60.98]],"id":36087680}],"con":true,"img":false}]}
{"op":"mcm","clk":"5306704648","pt":1646104100380,"mc":[{"id":"1.195395427","rc":[{"atb":[[5.2,3.75]],"id":43154456},{"atb":[[2.26,2]],"id":36087680}],"con":true,"img":false}]}
{"op":"mcm","clk":"5306704655","pt":1646104100584,"mc":[{"id":"1.195395427","rc":[{"atl":[[3.4,7.41]],"id":43154457}],"con":true,"img":false}]}
{"op":"mcm","clk":"5306704658","pt":1646104100686,"mc":[{"id":"1.195395427","rc":[{"atl":[[5.2,3.21]],"id":36087680}],"con":true,"img":false}]}
{"op":"mcm","clk":"5306704688","pt":1646104101863,"mc":[{"id":"1.195395427","rc":[{"atb":[[5.1,0]],"id":43154456}],"con":true,"img":false}]}
{"op":"mcm","clk":"5306704705","pt":1646104102575,"mc":[{"id":"1.195395427","rc":[{"atb":[[2.26,0]],"id":43154457},{"atl":[[4.1,0]],"id":36087680}],"con":true,"img":false}]}
{"op":"mcm","clk":"5306704721","pt":1646104103087,"mc":[{"id":"1.195395427","rc":[{"atb":[[5.3,2.5]],"id":43154456},{"atb":[[2.28,17.22]],"id":43154457}],"con":true,"img":false}]}
{"op":"mcm","clk":"5306704732","pt":1646104103291,"mc":[{"id":"1.195395427","rc":[{"atb":[[4.9,0]],"id":43154456},{"atb":[[2.28,43.3]],"id":36087680}],"con":true,"img":false}]}
{"op":"mcm","clk":"5306704743","pt":1646104103651,"mc":[{"id":"1.195395427","rc":[{"atb":[[2.24,74.78]],"id":36087680}],"con":true,"img":false}]}
{"op":"mcm","clk":"5306704786","pt":1646104105180,"mc":[{"id":"1.195395427","rc":[{"atb":[[5.2,0]],"id":43154456}],"con":true,"img":false}]}
{"op":"mcm","clk":"5306704823","pt":1646104106455,"mc":[{"id":"1.195395427","rc":[{"atl":[[14,8.38]],"id":43154456}],"con":true,"img":false}]}
{"op":"mcm","clk":"5306704825","pt":1646104106557,"mc":[{"id":"1.195395427","rc":[{"atb":[[6.2,6.5]],"id":38407646},{"atl":[[10.5,3]],"id":38407646},{"atl":[[8.8,2.4]],"id":43154456},{"atb":[[2.36,5.11]],"id":43154457},{"atl":[[3.4,10.04]],"id":43154457},{"atb":[[2.64,4.05]],"id":36087680},{"atl":[[3.8,2.3]],"id":36087680}],"con":true,"img":false}]}
{"op":"mcm","clk":"5306704838","pt":1646104107270,"mc":[{"id":"1.195395427","rc":[{"spn":41.5,"spf":1.0,"id":37284251},{"atb":[[1.01,2.53]],"id":38407646},{"spn":8.35,"spf":1.0,"id":38407646},{"spn":7.05,"spf":1.0,"id":43154456},{"spn":3.22,"spf":1.0,"id":36087680}],"con":true,"img":false}]}
{"op":"mcm","clk":"5306704841","pt":1646104107474,"mc":[{"id":"1.195395427","rc":[{"atb":[[1.01,1.69]],"id":38407646}],"con":true,"img":false}]}
{"op":"mcm","clk":"5306704845","pt":1646104107677,"mc":[{"id":"1.195395427","rc":[{"atb":[[1.01,0]],"id":38407646}],"con":true,"img":false}]}
{"op":"mcm","clk":"5306704848","pt":1646104107779,"mc":[{"id":"1.195395427","rc":[{"atb":[[6.4,1.69]],"id":38407646}],"con":true,"img":false}]}
{"op":"mcm","clk":"5306704857","pt":1646104108186,"mc":[{"id":"1.195395427","rc":[{"atb":[[2.66,2.5]],"id":36087680}],"con":true,"img":false}]}
{"op":"mcm","clk":"5306704862","pt":1646104108390,"mc":[{"id":"1.195395427","rc":[{"atb":[[2.14,19.84]],"id":43154457},{"atb":[[2.24,0]],"id":36087680}],"con":true,"img":false}]}
{"op":"mcm","clk":"5306704893","pt":1646104109257,"mc":[{"id":"1.195395427","rc":[{"atb":[[4.9,3]],"id":43154456},{"atb":[[2.3,17.4]],"id":36087680}],"con":true,"img":false}]}
{"op":"mcm","clk":"5306704902","pt":1646104109665,"mc":[{"id":"1.195395427","rc":[{"atb":[[6.2,4]],"id":38407646}],"con":true,"img":false}]}
{"op":"mcm","clk":"5306704912","pt":1646104110175,"mc":[{"id":"1.195395427","rc":[{"atl":[[60,2.29]],"id":37284251},{"atl":[[200,0.68]],"id":42130949},{"atl":[[9,16.9]],"id":43154456}],"con":true,"img":false}]}
{"op":"mcm","clk":"5306704914","pt":1646104110277,"mc":[{"id":"1.195395427","rc":[{"atl":[[55,2.7]],"id":37284251},{"atl":[[190,0.24]],"id":42130949},{"atl":[[8.8,8.5]],"id":43154456}],"con":true,"img":false}]}
{"op":"mcm","clk":"5306704925","pt":1646104110684,"mc":[{"id":"1.195395427","rc":[{"atb":[[6.6,2.5]],"id":38407646}],"con":true,"img":false}]}
{"op":"mcm","clk":"5306704956","pt":1646104111502,"mc":[{"id":"1.195395427","rc":[{"atb":[[2.14,0]],"id":43154457}],"con":true,"img":false}]}
{"op":"mcm","clk":"5306704963","pt":1646104111705,"mc":[{"id":"1.195395427","rc":[{"atb":[[2.16,21.73]],"id":43154457},{"atb":[[2.68,3.75]],"id":36087680}],"con":true,"img":false}]}
{"op":"mcm","clk":"5306705025","pt":1646104113187,"mc":[{"id":"1.195395427","rc":[{"atl":[[3.75,2.5]],"id":36087680}],"con":true,"img":false}]}
{"op":"mcm","clk":"5306705029","pt":1646104113289,"mc":[{"id":"1.195395427","rc":[{"atb":[[2.66,0]],"id":36087680}],"con":true,"img":false}]}
{"op":"mcm","clk":"5306705072","pt":1646104114361,"mc":[{"id":"1.195395427","rc":[{"atb":[[4.9,0]],"id":43154456},{"atb":[[2.3,0]],"id":36087680}],"con":true,"img":false}]}
{"op":"mcm","clk":"5306705102","pt":1646104115281,"mc":[{"id":"1.195395427","rc":[{"atb":[[6.4,0]],"id":38407646}],"con":true,"img":false}]}
{"op":"mcm","clk":"5306705118","pt":1646104115689,"mc":[{"id":"1.195395427","rc":[{"atb":[[2.7,2.5]],"id":36087680}],"con":true,"img":false}]}
{"op":"mcm","clk":"5306705143","pt":1646104116404,"mc":[{"id":"1.195395427","rc":[{"atl":[[3.45,38.79]],"id":43154457}],"con":true,"img":false}]}
{"op":"mcm","clk":"5306705180","pt":1646104116865,"mc":[{"id":"1.195395427","rc":[{"atb":[[2.18,8.69]],"id":43154457}],"con":true,"img":false}]}
{"op":"mcm","clk":"5306705210","pt":1646104117579,"mc":[{"id":"1.195395427","rc":[{"atb":[[2.68,0]],"id":36087680}],"con":true,"img":false}]}
{"op":"mcm","clk":"5306705218","pt":1646104117885,"mc":[{"id":"1.195395427","rc":[{"atl":[[3.45,22.32]],"id":43154457}],"con":true,"img":false}]}
{"op":"mcm","clk":"5306705228","pt":1646104118189,"mc":[{"id":"1.195395427","rc":[{"atl":[[3.4,25.41]],"id":43154457},{"atl":[[3.85,28.23]],"id":36087680}],"con":true,"img":false}]}
{"op":"mcm","clk":"5306705249","pt":1646104119006,"mc":[{"id":"1.195395427","rc":[{"atb":[[2.16,0]],"id":43154457}],"con":true,"img":false}]}
{"op":"mcm","clk":"5306705270","pt":1646104119568,"mc":[{"id":"1.195395427","rc":[{"atb":[[1.2,2.23]],"id":36087680},{"atl":[[4,0]],"id":36087680}],"con":true,"img":false}]}
{"op":"mcm","clk":"5306705281","pt":1646104119874,"mc":[{"id":"1.195395427","rc":[{"atb":[[1.2,1.75]],"id":36087680}],"con":true,"img":false}]}
{"op":"mcm","clk":"5306705292","pt":1646104120182,"mc":[{"id":"1.195395427","rc":[{"atb":[[1.2,0]],"id":36087680}],"con":true,"img":false}]}
{"op":"mcm","clk":"5306705298","pt":1646104120284,"mc":[{"id":"1.195395427","rc":[{"atb":[[2.72,1.75]],"id":36087680}],"con":true,"img":false}]}
{"op":"mcm","clk":"5306705305","pt":1646104120590,"mc":[{"id":"1.195395427","rc":[{"atb":[[2.72,5.5]],"id":36087680}],"con":true,"img":false}]}
{"op":"mcm","clk":"5306705365","pt":1646104121874,"mc":[{"id":"1.195395427","rc":[{"atb":[[2.7,0]],"id":36087680}],"con":true,"img":false}]}
{"op":"mcm","clk":"5306705376","pt":1646104122282,"mc":[{"id":"1.195395427","rc":[{"atb":[[2.2,19.17]],"id":43154457}],"con":true,"img":false}]}
{"op":"mcm","clk":"5306705535","pt":1646104126517,"mc":[{"id":"1.195395427","rc":[{"atb":[[2.18,0]],"id":43154457},{"atb":[[2.72,3.75]],"id":36087680}],"con":true,"img":false}]}
{"op":"mcm","clk":"5306705626","pt":1646104129325,"mc":[{"id":"1.195395427","rc":[{"atl":[[60,0]],"id":37284251},{"atl":[[200,0]],"id":42130949},{"atb":[[5.9,0]],"id":38407646},{"atl":[[11,0]],"id":38407646},{"atl":[[9,0]],"id":43154456}],"con":true,"img":false}]}
{"op":"mcm","clk":"5306705634","pt":1646104129529,"mc":[{"id":"1.195395427","rc":[{"atl":[[55,5.21]],"id":37284251},{"atl":[[190,0.95]],"id":42130949},{"atb":[[6.2,17.43]],"id":38407646},{"atl":[[10.5,7.57]],"id":38407646},{"atl":[[8.8,25.85]],"id":43154456}],"con":true,"img":false}]}
{"op":"mcm","clk":"5306705707","pt":1646104131721,"mc":[{"id":"1.195395427","rc":[{"atb":[[2.22,7.66]],"id":43154457},{"atb":[[2.66,4.12]],"id":36087680}],"con":true,"img":false}]}
{"op":"mcm","clk":"5306705720","pt":1646104132231,"mc":[{"id":"1.195395427","rc":[{"atb":[[4.9,6.88]],"id":43154456}],"con":true,"img":false}]}
{"op":"mcm","clk":"5306705780","pt":1646104133817,"mc":[{"id":"1.195395427","rc":[{"atb":[[2.2,0]],"id":43154457},{"atb":[[2.72,0]],"id":36087680}],"con":true,"img":false}]}
{"op":"mcm","clk":"5306705802","pt":1646104134330,"mc":[{"id":"1.195395427","rc":[{"atb":[[4.9,9.89]],"id":43154456}],"con":true,"img":false}]}
{"op":"mcm","clk":"5306705867","pt":1646104135607,"mc":[{"id":"1.195395427","rc":[{"atb":[[2.68,2.5]],"id":36087680}],"con":true,"img":false}]}
{"op":"mcm","clk":"5306705929","pt":1646104137237,"mc":[{"id":"1.195395427","rc":[{"atb":[[2.24,16.62]],"id":43154457},{"atb":[[2.68,8.69]],"id":36087680}],"con":true,"img":false}]}
{"op":"mcm","clk":"5306706088","pt":1646104142043,"mc":[{"id":"1.195395427","rc":[{"atb":[[2.22,0]],"id":43154457}],"con":true,"img":false}]}
{"op":"mcm","clk":"5306706281","pt":1646104146541,"mc":[{"id":"1.195395427","rc":[{"atb":[[6.2,13.43]],"id":38407646},{"atb":[[2.64,0]],"id":36087680},{"atl":[[3.8,0]],"id":36087680}],"con":true,"img":false}]}
{"op":"mcm","clk":"5306706286","pt":1646104146644,"mc":[{"id":"1.195395427","rc":[{"atb":[[6.6,5.4]],"id":38407646},{"atl":[[3.75,5.5]],"id":36087680}],"con":true,"img":false}]}
{"op":"mcm","clk":"5306706302","pt":1646104147154,"mc":[{"id":"1.195395427","rc":[{"atb":[[2.3,5.62]],"id":43154457}],"con":true,"img":false}]}
{"op":"mcm","clk":"5306706341","pt":1646104148330,"mc":[{"id":"1.195395427","rc":[{"atb":[[2.38,2.5]],"id":43154457}],"con":true,"img":false}]}
{"op":"mcm","clk":"5306706375","pt":1646104149553,"mc":[{"id":"1.195395427","rc":[{"atb":[[2.24,0]],"id":43154457}],"con":true,"img":false}]}
{"op":"mcm","clk":"5306706389","pt":1646104150063,"mc":[{"id":"1.195395427","rc":[{"atb":[[2.66,0]],"id":36087680}],"con":true,"img":false}]}
{"op":"mcm","clk":"5306706481","pt":1646104152562,"mc":[{"id":"1.195395427","rc":[{"atb":[[2.3,0]],"id":43154457}],"con":true,"img":false}]}
{"op":"mcm","clk":"5306706487","pt":1646104152767,"mc":[{"id":"1.195395427","rc":[{"atb":[[2.68,2.5]],"id":36087680}],"con":true,"img":false}]}
{"op":"mcm","clk":"5306706492","pt":1646104152869,"mc":[{"id":"1.195395427","rc":[{"atb":[[2.32,6.26]],"id":43154457}],"con":true,"img":false}]}
{"op":"mcm","clk":"5306706535","pt":1646104154554,"mc":[{"id":"1.195395427","rc":[{"atb":[[2.3,56.54]],"id":36087680}],"con":true,"img":false}]}
{"op":"mcm","clk":"5306706553","pt":1646104155265,"mc":[{"id":"1.195395427","rc":[{"atb":[[2.64,8.69]],"id":36087680}],"con":true,"img":false}]}
{"op":"mcm","clk":"5306706629","pt":1646104157770,"mc":[{"id":"1.195395427","rc":[{"atb":[[2.3,0]],"id":36087680}],"con":true,"img":false}]}
{"op":"mcm","clk":"5306706649","pt":1646104158329,"mc":[{"id":"1.195395427","rc":[{"atb":[[1.2,2.23]],"id":43154457}],"con":true,"img":false}]}
{"op":"mcm","clk":"5306706658","pt":1646104158637,"mc":[{"id":"1.195395427","rc":[{"atb":[[1.2,1.75]],"id":43154457}],"con":true,"img":false}]}
{"op":"mcm","clk":"5306706668","pt":1646104158944,"mc":[{"id":"1.195395427","rc":[{"atb":[[1.2,0]],"id":43154457}],"con":true,"img":false}]}
{"op":"mcm","clk":"5306706672","pt":1646104159046,"mc":[{"id":"1.195395427","rc":[{"atb":[[2.4,1.75]],"id":43154457}],"con":true,"img":false}]}
{"op":"mcm","clk":"5306706686","pt":1646104159658,"mc":[{"id":"1.195395427","rc":[{"atb":[[2.38,0]],"id":43154457}],"con":true,"img":false}]}
{"op":"mcm","clk":"5306706723","pt":1646104160779,"mc":[{"id":"1.195395427","rc":[{"atl":[[8.8,36.67]],"id":43154456}],"con":true,"img":false}]}
{"op":"mcm","clk":"5306706728","pt":1646104160936,"mc":[{"id":"1.195395427","rc":[{"atb":[[2.7,3.75]],"id":36087680}],"con":true,"img":false}]}
{"op":"mcm","clk":"5306706762","pt":1646104161855,"mc":[{"id":"1.195395427","rc":[{"atb":[[2.4,12.57]],"id":43154457}],"con":true,"img":false}]}
{"op":"mcm","clk":"5306706772","pt":1646104162161,"mc":[{"id":"1.195395427","rc":[{"atb":[[2.68,0]],"id":36087680}],"con":true,"img":false}]}
{"op":"mcm","clk":"5306706776","pt":1646104162363,"mc":[{"id":"1.195395427","rc":[{"atl":[[10.5,18.39]],"id":38407646}],"con":true,"img":false}]}
{"op":"mcm","clk":"5306706783","pt":1646104162567,"mc":[{"id":"1.195395427","rc":[{"atb":[[6.2,0]],"id":38407646},{"atb":[[2.32,0]],"id":43154457}],"con":true,"img":false}]}
{"op":"mcm","clk":"5306706792","pt":1646104162873,"mc":[{"id":"1.195395427","rc":[{"atb":[[6.6,16.29]],"id":38407646}],"con":true,"img":false}]}
{"op":"mcm","clk":"5306706807","pt":1646104163281,"mc":[{"id":"1.195395427","rc":[{"atb":[[6.6,27.11]],"id":38407646},{"atb":[[2.4,10.82]],"id":43154457}],"con":true,"img":false}]}
{"op":"mcm","clk":"5306706824","pt":1646104163846,"mc":[{"id":"1.195395427","rc":[{"atb":[[1.01,2.53]],"id":38407646}],"con":true,"img":false}]}
{"op":"mcm","clk":"5306706827","pt":1646104164049,"mc":[{"id":"1.195395427","rc":[{"atb":[[1.01,1.69]],"id":38407646}],"con":true,"img":false}]}
{"op":"mcm","clk":"5306706831","pt":1646104164151,"mc":[{"id":"1.195395427","rc":[{"atb":[[23,11.44]],"id":37284251}],"con":true,"img":false}]}
{"op":"mcm","clk":"5306706835","pt":1646104164254,"mc":[{"id":"1.195395427","rc":[{"atb":[[1.01,0]],"id":38407646}],"con":true,"img":false}]}
{"op":"mcm","clk":"5306706838","pt":1646104164355,"mc":[{"id":"1.195395427","rc":[{"atb":[[6.8,1.69]],"id":38407646}],"con":true,"img":false}]}
{"op":"mcm","clk":"5306706853","pt":1646104164863,"mc":[{"id":"1.195395427","rc":[{"atb":[[22,5.03]],"id":37284251}],"con":true,"img":false}]}
{"op":"mcm","clk":"5306706857","pt":1646104165068,"mc":[{"id":"1.195395427","rc":[{"atb":[[2.68,10.82]],"id":36087680}],"con":true,"img":false}]}
{"op":"mcm","clk":"5306706887","pt":1646104166089,"mc":[{"id":"1.195395427","rc":[{"atb":[[5.2,22.08]],"id":38407646},{"atb":[[2.3,32.46]],"id":43154457}],"con":true,"img":false}]}
{"op":"mcm","clk":"5306706949","pt":1646104167473,"mc":[{"id":"1.195395427","rc":[{"atl":[[80,0.54]],"id":37284251},{"spn":39.0,"spf":1.0,"id":37284251},{"atl":[[280,0.15]],"id":42130949},{"atb":[[6.6,24.6]],"id":38407646},{"spn":8.65,"spf":1.0,"id":38407646},{"atb":[[3.8,24.36]],"id":43154456},{"atb":[[1.89,51.76]],"id":43154457},{"atl":[[4.2,13.52]],"id":43154457},{"spn":2.9,"spf":1.0,"id":43154457},{"atb":[[2.08,46.14]],"id":36087680},{"atl":[[4.5,12.36]],"id":36087680},{"spn":3.22,"spf":1.0,"id":36087680}],"con":true,"img":false}]}
{"op":"mcm","clk":"5306706953","pt":1646104167575,"mc":[{"id":"1.195395427","rc":[{"atl":[[95,0],[55,2.5]],"id":37284251},{"atb":[[38,0]],"id":42130949},{"atl":[[290,0],[190,0.71]],"id":42130949},{"atb":[[4.8,13.02]],"id":38407646},{"atl":[[13,0]],"id":38407646},{"atb":[[4.1,0],[4.4,0]],"id":43154456},{"atb":[[1.99,0],[2.12,0]],"id":43154457},{"atl":[[3.45,0]],"id":43154457},{"atb":[[2.22,0],[2.28,0]],"id":36087680},{"atl":[[3.85,10.1]],"id":36087680}],"con":true,"img":false}]}
{"op":"mcm","clk":"5306706958","pt":1646104167675,"mc":[{"id":"1.195395427","rc":[{"atl":[[140,2.7]],"id":37284251},{"atb":[[32,2.7]],"id":42130949},{"atl":[[440,2.7]],"id":42130949},{"atl":[[14,3.73]],"id":38407646},{"atb":[[4.2,16.57]],"id":43154456},{"atb":[[1.99,54.34]],"id":43154457},{"atb":[[2.22,43.3]],"id":36087680}],"con":true,"img":false}]}
{"op":"mcm","clk":"5306706984","pt":1646104168390,"mc":[{"id":"1.195395427","rc":[{"atb":[[2.3,46.53]],"id":43154457},{"atb":[[2.64,0]],"id":36087680}],"con":true,"img":false}]}
{"op":"mcm","clk":"5306707059","pt":1646104170992,"mc":[{"id":"1.195395427","rc":[{"atb":[[2.3,14.07]],"id":43154457},{"atb":[[2.7,0]],"id":36087680}],"con":true,"img":false}]}
{"op":"mcm","clk":"5306707115","pt":1646104172782,"mc":[{"id":"1.195395427","rc":[{"atb":[[22,0]],"id":37284251}],"con":true,"img":false}]}
{"op":"mcm","clk":"5306707125","pt":1646104173188,"mc":[{"id":"1.195395427","rc":[{"atb":[[23,15.83]],"id":37284251}],"con":true,"img":false}]}
{"op":"mcm","clk":"5306707130","pt":1646104173291,"mc":[{"id":"1.195395427","rc":[{"atb":[[2.72,2.63]],"id":36087680}],"con":true,"img":false}]}
{"op":"mcm","clk":"5306707185","pt":1646104174572,"mc":[{"id":"1.195395427","rc":[{"atb":[[2.32,29.76]],"id":43154457},{"atb":[[2.24,74.78]],"id":36087680}],"con":true,"img":false}]}
{"op":"mcm","clk":"5306707271","pt":1646104177889,"mc":[{"id":"1.195395427","rc":[{"atb":[[2.24,0]],"id":36087680}],"con":true,"img":false}]}
{"op":"mcm","clk":"5306707283","pt":1646104178397,"mc":[{"id":"1.195395427","rc":[{"atb":[[2.3,0]],"id":43154457}],"con":true,"img":false}]}
{"op":"mcm","clk":"5306707378","pt":1646104181367,"mc":[{"id":"1.195395427","rc":[{"atb":[[2.28,0]],"id":43154457},{"atb":[[2.64,7.23],[2.62,0]],"id":36087680}],"con":true,"img":false}]}
{"op":"mcm","clk":"5306707392","pt":1646104181674,"mc":[{"id":"1.195395427","rc":[{"atb":[[36,3.85]],"id":42130949},{"atb":[[2.32,45.33]],"id":43154457},{"atb":[[2.68,26.24]],"id":36087680}],"con":true,"img":false}]}
{"op":"mcm","clk":"5306707443","pt":1646104183611,"mc":[{"id":"1.195395427","rc":[{"atb":[[2.42,7.57]],"id":43154457}],"con":true,"img":false}]}
{"op":"mcm","clk":"5306707524","pt":1646104186067,"mc":[{"id":"1.195395427","rc":[{"atb":[[2.72,0]],"id":36087680}],"con":true,"img":false}]}
{"op":"mcm","clk":"5306707534","pt":1646104186373,"mc":[{"id":"1.195395427","rc":[{"atb":[[2.32,15.57]],"id":43154457}],"con":true,"img":false}]}
{"op":"mcm","clk":"5306707543","pt":1646104186576,"mc":[{"id":"1.195395427","rc":[{"atb":[[6.6,21.7]],"id":38407646},{"atl":[[10.5,15.39]],"id":38407646},{"atb":[[2.36,2]],"id":43154457},{"atl":[[3.4,22.78]],"id":43154457}],"con":true,"img":false}]}
{"op":"mcm","clk":"5306707549","pt":1646104186681,"mc":[{"id":"1.195395427","rc":[{"atl":[[13.5,2.45]],"id":38407646},{"atb":[[2.44,3]],"id":43154457},{"atl":[[3.35,3]],"id":43154457},{"atb":[[2.7,4]],"id":36087680}],"con":true,"img":false}]}
{"op":"mcm","clk":"5306707572","pt":1646104187291,"mc":[{"id":"1.195395427","rc":[{"atl":[[3.4,20.27]],"id":43154457}],"con":true,"img":false}]}
{"op":"mcm","clk":"5306707600","pt":1646104188108,"mc":[{"id":"1.195395427","rc":[{"atb":[[2.64,0]],"id":36087680}],"con":true,"img":false}]}
{"op":"mcm","clk":"5306707659","pt":1646104189895,"mc":[{"id":"1.195395427","rc":[{"atb":[[2.46,4.5]],"id":43154457}],"con":true,"img":false}]}
{"op":"mcm","clk":"5306707661","pt":1646104189996,"mc":[{"id":"1.195395427","rc":[{"atl":[[3.3,2.5]],"id":43154457}],"con":true,"img":false}]}
{"op":"mcm","clk":"5306707727","pt":1646104191682,"mc":[{"id":"1.195395427","rc":[{"atb":[[2.24,30.02]],"id":36087680}],"con":true,"img":false}]}
{"op":"mcm","clk":"5306707732","pt":1646104191785,"mc":[{"id":"1.195395427","rc":[{"atb":[[2.42,0]],"id":43154457},{"atb":[[2.72,2.8]],"id":36087680}],"con":true,"img":false}]}
{"op":"mcm","clk":"5306707767","pt":1646104193518,"mc":[{"id":"1.195395427","rc":[{"atb":[[4.8,34.63],[5.1,0]],"id":38407646}],"con":true,"img":false}]}
{"op":"mcm","clk":"5306707770","pt":1646104193620,"mc":[{"id":"1.195395427","rc":[{"atb":[[5.3,14.85]],"id":38407646}],"con":true,"img":false}]}
{"op":"mcm","clk":"5306707815","pt":1646104195202,"mc":[{"id":"1.195395427","rc":[{"atb":[[2.24,0]],"id":36087680}],"con":true,"img":false}]}
{"op":"mcm","clk":"5306707866","pt":1646104196787,"mc":[{"id":"1.195395427","rc":[{"atb":[[5.2,0]],"id":38407646}],"con":true,"img":false}]}
{"op":"mcm","clk":"5306707879","pt":1646104197100,"mc":[{"id":"1.195395427","rc":[{"atb":[[2.48,3.16]],"id":43154457}],"con":true,"img":false}]}
{"op":"mcm","clk":"5306707978","pt":1646104200207,"mc":[{"id":"1.195395427","rc":[{"atb":[[5.4,21.07]],"id":38407646},{"atb":[[2.46,0]],"id":43154457}],"con":true,"img":false}]}
{"op":"mcm","clk":"5306708111","pt":1646104203530,"mc":[{"id":"1.195395427","rc":[{"atb":[[2.5,4.74]],"id":43154457}],"con":true,"img":false}]}
{"op":"mcm","clk":"5306708137","pt":1646104204089,"mc":[{"id":"1.195395427","rc":[{"atb":[[2.48,0]],"id":43154457}],"con":true,"img":false}]}
{"op":"mcm","clk":"5306708247","pt":1646104206447,"mc":[{"id":"1.195395427","rc":[{"atl":[[80,0],[60,2.7]],"id":37284251},{"atl":[[280,0],[200,0.29]],"id":42130949},{"atl":[[3.6,22.32],[4.2,0]],"id":43154457},{"atl":[[4.5,0],[3.8,20.72]],"id":36087680}],"con":true,"img":false}]}
{"op":"mcm","clk":"5306708252","pt":1646104206502,"mc":[{"id":"1.195395427","rc":[{"atb":[[32,0]],"id":42130949},{"atl":[[14,0]],"id":38407646},{"atb":[[4.2,0]],"id":43154456},{"atb":[[1.99,0]],"id":43154457}],"con":true,"img":false}]}
{"op":"mcm","clk":"5306708256","pt":1646104206602,"mc":[{"id":"1.195395427","rc":[{"atb":[[38,2.7]],"id":42130949},{"atl":[[12.5,3.73]],"id":38407646},{"atb":[[4.4,16.57]],"id":43154456},{"atb":[[2.12,54.34]],"id":43154457}],"con":true,"img":false}]}
{"op":"mcm","clk":"5306708384","pt":1646104209311,"mc":[{"id":"1.195395427","rc":[{"atb":[[2.46,4.74]],"id":43154457}],"con":true,"img":false}]}
{"op":"mcm","clk":"5306708451","pt":1646104210941,"mc":[{"id":"1.195395427","rc":[{"atb":[[36,2.9]],"id":42130949},{"atl":[[3.85,0]],"id":36087680}],"con":true,"img":false}]}
{"op":"mcm","clk":"5306708457","pt":1646104211145,"mc":[{"id":"1.195395427","rc":[{"atl":[[3.8,29.81]],"id":36087680}],"con":true,"img":false}]}
{"op":"mcm","clk":"5306708793","pt":1646104220749,"mc":[{"id":"1.195395427","rc":[{"atl":[[8.8,47.49]],"id":43154456}],"con":true,"img":false}]}
{"op":"mcm","clk":"5306708803","pt":1646104220953,"mc":[{"id":"1.195395427","rc":[{"atl":[[3.4,15.36]],"id":43154457}],"con":true,"img":false}]}
{"op":"mcm","clk":"5306708835","pt":1646104221719,"mc":[{"id":"1.195395427","rc":[{"atb":[[2.5,15.56]],"id":43154457}],"con":true,"img":false}]}
{"op":"mcm","clk":"5306708847","pt":1646104222230,"mc":[{"id":"1.195395427","rc":[{"atl":[[10.5,26.22]],"id":38407646}],"con":true,"img":false}]}
{"op":"mcm","clk":"5306708879","pt":1646104223253,"mc":[{"id":"1.195395427","rc":[{"atb":[[6.8,12.51]],"id":38407646}],"con":true,"img":false}]}
{"op":"mcm","clk":"5306708897","pt":1646104223714,"mc":[{"id":"1.195395427","rc":[{"atb":[[2.32,0]],"id":43154457}],"con":true,"img":false}]}
{"op":"mcm","clk":"5306708902","pt":1646104223917,"mc":[{"id":"1.195395427","rc":[{"atb":[[2.5,24.79]],"id":43154457}],"con":true,"img":false}]}
{"op":"mcm","clk":"5306708914","pt":1646104224226,"mc":[{"id":"1.195395427","rc":[{"atb":[[23,26.66]],"id":37284251}],"con":true,"img":false}]}
{"op":"mcm","clk":"5306708959","pt":1646104225252,"mc":[{"id":"1.195395427","rc":[{"atb":[[2.72,13.62]],"id":36087680}],"con":true,"img":false}]}
{"op":"mcm","clk":"5306708974","pt":1646104225557,"mc":[{"id":"1.195395427","rc":[{"atb":[[5.4,0]],"id":38407646}],"con":true,"img":false}]}
{"op":"mcm","clk":"5306709010","pt":1646104226529,"mc":[{"id":"1.195395427","rc":[{"atb":[[6.6,10.82]],"id":38407646},{"atb":[[2.68,10.82]],"id":36087680}],"con":true,"img":false}]}
{"op":"mcm","clk":"5306709013","pt":1646104226733,"mc":[{"id":"1.195395427","rc":[{"atb":[[6.8,22.25]],"id":38407646},{"atb":[[2.44,0]],"id":43154457},{"atl":[[3.35,0]],"id":43154457},{"atb":[[2.72,27.87],[2.7,0]],"id":36087680}],"con":true,"img":false}]}
{"op":"mcm","clk":"5306709014","pt":1646104226836,"mc":[{"id":"1.195395427","rc":[{"atl":[[3.3,6.5]],"id":43154457},{"atb":[[2.74,3.7]],"id":36087680},{"atl":[[5.2,0]],"id":36087680}],"con":true,"img":false}]}
{"op":"mcm","clk":"5306709074","pt":1646104228831,"mc":[{"id":"1.195395427","rc":[{"atb":[[2.5,20.05]],"id":43154457},{"spn":3.24,"spf":1.0,"id":36087680}],"con":true,"img":false}]}
{"op":"mcm","clk":"5306709140","pt":1646104230672,"mc":[{"id":"1.195395427","rc":[{"atb":[[2.46,0]],"id":43154457},{"atb":[[2.72,25.06]],"id":36087680}],"con":true,"img":false}]}
{"op":"mcm","clk":"5306709178","pt":1646104231846,"mc":[{"id":"1.195395427","rc":[{"atb":[[2.42,55.15]],"id":43154457}],"con":true,"img":false}]}
{"op":"mcm","clk":"5306709214","pt":1646104232666,"mc":[{"id":"1.195395427","rc":[{"atl":[[75,0.58]],"id":37284251},{"atl":[[290,0.15]],"id":42130949},{"atb":[[6.8,25.14]],"id":38407646},{"atl":[[4.3,13.11]],"id":43154457},{"atl":[[4.7,11.69]],"id":36087680}],"con":true,"img":false}]}
{"op":"mcm","clk":"5306709218","pt":1646104232767,"mc":[{"id":"1.195395427","rc":[{"atl":[[60,0]],"id":37284251},{"atb":[[38,0]],"id":42130949},{"atl":[[200,0]],"id":42130949},{"atb":[[4.8,13.02],[5.3,0.7]],"id":38407646},{"atl":[[12.5,0]],"id":38407646},{"atb":[[4.4,0]],"id":43154456},{"atb":[[2.12,0]],"id":43154457},{"atl":[[3.6,0]],"id":43154457},{"atl":[[3.8,9.09]],"id":36087680}],"con":true,"img":false}]}
{"op":"mcm","clk":"5306709223","pt":1646104232868,"mc":[{"id":"1.195395427","rc":[{"atb":[[32,2.7]],"id":42130949},{"atl":[[13.5,6.18]],"id":38407646},{"atb":[[4.2,16.57]],"id":43154456},{"atb":[[1.99,54.34]],"id":43154457}],"con":true,"img":false}]}
{"op":"mcm","clk":"5306709264","pt":1646104233943,"mc":[{"id":"1.195395427","rc":[{"atb":[[36,3.85]],"id":42130949}],"con":true,"img":false}]}
{"op":"mcm","clk":"5306709337","pt":1646104235633,"mc":[{"id":"1.195395427","rc":[{"atb":[[2.44,15.65]],"id":43154457}],"con":true,"img":false}]}
{"op":"mcm","clk":"5306709426","pt":1646104237732,"mc":[{"id":"1.195395427","rc":[{"atb":[[2.42,0]],"id":43154457}],"con":true,"img":false}]}
{"op":"mcm","clk":"5306709557","pt":1646104240856,"mc":[{"id":"1.195395427","rc":[{"atb":[[2.46,45.12]],"id":43154457}],"con":true,"img":false}]}
{"op":"mcm","clk":"5306709619","pt":1646104242136,"mc":[{"id":"1.195395427","rc":[{"atb":[[2.44,0]],"id":43154457}],"con":true,"img":false}]}
{"op":"mcm","clk":"5306709815","pt":1646104246844,"mc":[{"id":"1.195395427","rc":[{"atb":[[2.42,15.87]],"id":43154457}],"con":true,"img":false}]}
{"op":"mcm","clk":"5306709929","pt":1646104249555,"mc":[{"id":"1.195395427","rc":[{"atb":[[2.46,0]],"id":43154457}],"con":true,"img":false}]}
{"op":"mcm","clk":"5306710066","pt":1646104252672,"mc":[{"id":"1.195395427","rc":[{"atb":[[2.44,50.14]],"id":43154457}],"con":true,"img":false}]}
{"op":"mcm","clk":"5306710225","pt":1646104256149,"mc":[{"id":"1.195395427","rc":[{"atb":[[2.42,0]],"id":43154457}],"con":true,"img":false}]}
{"op":"mcm","clk":"5306710320","pt":1646104258660,"mc":[{"id":"1.195395427","rc":[{"atl":[[290,0]],"id":42130949},{"atb":[[6.8,22.25]],"id":38407646},{"atb":[[2.44,0]],"id":43154457}],"con":true,"img":false}]}
{"op":"mcm","clk":"5306710323","pt":1646104258761,"mc":[{"id":"1.195395427","rc":[{"atl":[[280,0.15]],"id":42130949},{"atb":[[7,2.88]],"id":38407646}],"con":true,"img":false}]}
{"op":"mcm","clk":"5306710362","pt":1646104259889,"mc":[{"id":"1.195395427","rc":[{"atb":[[6.8,20.56]],"id":38407646}],"con":true,"img":false}]}
{"op":"mcm","clk":"5306710407","pt":1646104260869,"mc":[{"id":"1.195395427","rc":[{"atb":[[2.46,15.44]],"id":43154457}],"con":true,"img":false}]}
{"op":"mcm","clk":"5306710419","pt":1646104261075,"mc":[{"id":"1.195395427","rc":[{"atb":[[6.8,10.82]],"id":38407646}],"con":true,"img":false}]}
{"op":"mcm","clk":"5306710425","pt":1646104261177,"mc":[{"id":"1.195395427","rc":[{"atb":[[7,11.56]],"id":38407646}],"con":true,"img":false}]}
{"op":"mcm","clk":"5306710440","pt":1646104261688,"mc":[{"id":"1.195395427","rc":[{"atb":[[2.12,82.8]],"id":43154457}],"con":true,"img":false}]}
{"op":"mcm","clk":"5306710565","pt":1646104264807,"mc":[{"id":"1.195395427","rc":[{"atb":[[2.12,0]],"id":43154457}],"con":true,"img":false}]}
{"op":"mcm","clk":"5306710679","pt":1646104267874,"mc":[{"id":"1.195395427","rc":[{"atb":[[2.42,55.15]],"id":43154457}],"con":true,"img":false}]}
{"op":"mcm","clk":"5306710798","pt":1646104270485,"mc":[{"id":"1.195395427","rc":[{"atb":[[2.46,0]],"id":43154457}],"con":true,"img":false}]}
{"op":"mcm","clk":"5306711024","pt":1646104275906,"mc":[{"id":"1.195395427","rc":[{"atb":[[2.44,15.65]],"id":43154457}],"con":true,"img":false}]}
{"op":"mcm","clk":"5306711121","pt":1646104278206,"mc":[{"id":"1.195395427","rc":[{"atb":[[2.42,0]],"id":43154457}],"con":true,"img":false}]}
{"op":"mcm","clk":"5306711254","pt":1646104281227,"mc":[{"id":"1.195395427","rc":[{"atb":[[2.46,45.12]],"id":43154457}],"con":true,"img":false}]}
{"op":"mcm","clk":"5306711311","pt":1646104282814,"mc":[{"id":"1.195395427","rc":[{"atb":[[2.44,0]],"id":43154457}],"con":true,"img":false}]}
{"op":"mcm","clk":"5306711456","pt":1646104285630,"mc":[{"id":"1.195395427","rc":[{"atb":[[2.46,0]],"id":43154457}],"con":true,"img":false}]}
{"op":"mcm","clk":"5306711542","pt":1646104287726,"mc":[{"id":"1.195395427","rc":[{"atb":[[2.42,15.87]],"id":43154457}],"con":true,"img":false}]}
{"op":"mcm","clk":"5306711569","pt":1646104288339,"mc":[{"id":"1.195395427","rc":[{"atb":[[7,8.67]],"id":38407646}],"con":true,"img":false}]}
{"op":"mcm","clk":"5306711573","pt":1646104288442,"mc":[{"id":"1.195395427","rc":[{"atb":[[7.2,2.88]],"id":38407646}],"con":true,"img":false}]}
{"op":"mcm","clk":"5306711582","pt":1646104288701,"mc":[{"id":"1.195395427","rc":[{"atb":[[2.12,82.8]],"id":43154457}],"con":true,"img":false}]}
{"op":"mcm","clk":"5306711705","pt":1646104291618,"mc":[{"id":"1.195395427","rc":[{"spn":8.85,"spf":1.0,"id":38407646},{"atb":[[2.12,0]],"id":43154457}],"con":true,"img":false}]}
{"op":"mcm","clk":"5306711842","pt":1646104294742,"mc":[{"id":"1.195395427","rc":[{"atb":[[2.44,50.14]],"id":43154457}],"con":true,"img":false}]}
{"op":"mcm","clk":"5306711856","pt":1646104295051,"mc":[{"id":"1.195395427","rc":[{"atb":[[5,27.43]],"id":43154456}],"con":true,"img":false}]}
{"op":"mcm","clk":"5306711956","pt":1646104297707,"mc":[{"id":"1.195395427","rc":[{"atb":[[4.9,3]],"id":43154456}],"con":true,"img":false}]}
{"op":"mcm","clk":"5306712008","pt":1646104298734,"mc":[{"id":"1.195395427","rc":[{"atb":[[7,0]],"id":38407646}],"con":true,"img":false}]}
{"op":"mcm","clk":"5306712031","pt":1646104299142,"mc":[{"id":"1.195395427","rc":[{"atb":[[7.2,12.25]],"id":38407646}],"con":true,"img":false}]}
{"op":"mcm","clk":"5306712035","pt":1646104299245,"mc":[{"id":"1.195395427","rc":[{"atb":[[4.9,0]],"id":43154456},{"atb":[[2.42,0]],"id":43154457}],"con":true,"img":false}]}
{"op":"mcm","clk":"5306712115","pt":1646104300931,"mc":[{"id":"1.195395427","rc":[{"atb":[[5.1,5.63]],"id":43154456}],"con":true,"img":false}]}
{"op":"mcm","clk":"5306712178","pt":1646104302468,"mc":[{"id":"1.195395427","rc":[{"atb":[[2.44,0]],"id":43154457}],"con":true,"img":false}]}
{"op":"mcm","clk":"5306712266","pt":1646104304517,"mc":[{"id":"1.195395427","rc":[{"atb":[[1.2,2.23]],"id":43154456}],"con":true,"img":false}]}
{"op":"mcm","clk":"5306712281","pt":1646104304824,"mc":[{"id":"1.195395427","rc":[{"atb":[[1.2,1.75]],"id":43154456}],"con":true,"img":false}]}
{"op":"mcm","clk":"5306712304","pt":1646104305236,"mc":[{"id":"1.195395427","rc":[{"atb":[[1.2,0]],"id":43154456}],"con":true,"img":false}]}
{"op":"mcm","clk":"5306712309","pt":1646104305338,"mc":[{"id":"1.195395427","rc":[{"atb":[[5.4,1.75]],"id":43154456}],"con":true,"img":false}]}
{"op":"mcm","clk":"5306712321","pt":1646104305543,"mc":[{"id":"1.195395427","rc":[{"atb":[[2.46,15.44],[2.12,82.8]],"id":43154457}],"con":true,"img":false}]}
{"op":"mcm","clk":"5306712375","pt":1646104306870,"mc":[{"id":"1.195395427","rc":[{"atb":[[5.3,0]],"id":43154456}],"con":true,"img":false}]}
{"op":"mcm","clk":"5306712379","pt":1646104306925,"mc":[{"id":"1.195395427","rc":[{"atl":[[13.5,3.73]],"id":38407646}],"con":true,"img":false}]}
{"op":"mcm","clk":"5306712386","pt":1646104307026,"mc":[{"id":"1.195395427","rc":[{"atb":[[7.4,3.68]],"id":38407646},{"atl":[[10,3]],"id":38407646},{"atb":[[2.52,3]],"id":43154457}],"con":true,"img":false}]}
{"op":"mcm","clk":"5306712475","pt":1646104308560,"mc":[{"id":"1.195395427","rc":[{"atb":[[2.12,0]],"id":43154457}],"con":true,"img":false}]}
{"op":"mcm","clk":"5306712551","pt":1646104310141,"mc":[{"id":"1.195395427","rc":[{"atb":[[7.2,2.88]],"id":38407646},{"atl":[[10.5,21.64]],"id":38407646}],"con":true,"img":false}]}
{"op":"mcm","clk":"5306712554","pt":1646104310245,"mc":[{"id":"1.195395427","rc":[{"atb":[[7.4,11.9]],"id":38407646}],"con":true,"img":false}]}
{"op":"mcm","clk":"5306712616","pt":1646104311571,"mc":[{"id":"1.195395427","rc":[{"atb":[[2.54,4.5]],"id":43154457}],"con":true,"img":false}]}
{"op":"mcm","clk":"5306712632","pt":1646104311930,"mc":[{"id":"1.195395427","rc":[{"atb":[[5.4,0]],"id":43154456},{"atb":[[2.46,0]],"id":43154457}],"con":true,"img":false}]}
{"op":"mcm","clk":"5306712868","pt":1646104317354,"mc":[{"id":"1.195395427","rc":[{"atb":[[5.2,3.94]],"id":43154456},{"atb":[[2.56,3.16]],"id":43154457}],"con":true,"img":false}]}
{"op":"mcm","clk":"5306712947","pt":1646104319038,"mc":[{"id":"1.195395427","rc":[{"atb":[[2.54,0]],"id":43154457}],"con":true,"img":false}]}
{"op":"mcm","clk":"5306713015","pt":1646104320571,"mc":[{"id":"1.195395427","rc":[{"atb":[[2.36,16.71]],"id":43154457}],"con":true,"img":false}]}
{"op":"mcm","clk":"5306713023","pt":1646104320776,"mc":[{"id":"1.195395427","rc":[{"atb":[[2.54,12.99]],"id":36087680}],"con":true,"img":false}]}
{"op":"mcm","clk":"5306713234","pt":1646104325888,"mc":[{"id":"1.195395427","rc":[{"atb":[[7.2,0],[7.4,14.56]],"id":38407646}],"con":true,"img":false}]}
{"op":"mcm","clk":"5306713305","pt":1646104327576,"mc":[{"id":"1.195395427","rc":[{"atb":[[2.1,110.49]],"id":43154457}],"con":true,"img":false}]}
{"op":"mcm","clk":"5306713312","pt":1646104327780,"mc":[{"id":"1.195395427","rc":[{"atb":[[2.28,15.7]],"id":36087680}],"con":true,"img":false}]}
{"op":"mcm","clk":"5306714064","pt":1646104343119,"mc":[{"id":"1.195395427","rc":[{"atb":[[5.2,0]],"id":43154456},{"atb":[[2.56,0]],"id":43154457}],"con":true,"img":false}]}
{"op":"mcm","clk":"5306714174","pt":1646104345320,"mc":[{"id":"1.195395427","rc":[{"atb":[[2.42,9.01]],"id":43154457}],"con":true,"img":false}]}
{"op":"mcm","clk":"5306717403","pt":1646104402751,"mc":[{"id":"1.195395427","rc":[{"spn":8.7,"spf":1.0,"id":38407646},{"atb":[[5.1,0]],"id":43154456},{"spn":6.9,"spf":1.0,"id":43154456},{"atb":[[2.42,0]],"id":43154457},{"spn":2.91,"spf":1.0,"id":43154457}],"con":true,"img":false}]}
{"op":"mcm","clk":"5306718707","pt":1646104427560,"mc":[{"id":"1.195395427","rc":[{"atb":[[16.5,0],[20,0],[11.5,0],[14,0]],"id":37284251},{"atl":[[260,0],[310,0],[160,0],[210,0]],"id":37284251},{"atb":[[36,0.95],[18,0],[21,0],[26,4.57]],"id":42130949},{"atl":[[300,0],[350,0],[400,0],[450,0]],"id":42130949},{"atb":[[4,0],[3.5,0],[3.75,0],[4.7,0]],"id":38407646},{"atl":[[16,0],[18.5,0],[22,0],[27,0]],"id":38407646},{"atb":[[4,0],[3.5,0],[3.75,0],[4.7,0]],"id":43154456},{"atl":[[16,0],[18.5,0],[22,0],[27,0]],"id":43154456},{"atb":[[1.98,0],[1.88,0],[1.93,0],[2.1,18.27]],"id":43154457},{"atl":[[6.4,0],[7.4,0],[5.2,0],[5.7,0]],"id":43154457},{"atb":[[2.06,0],[1.98,0],[2.2,0],[1.93,0]],"id":36087680},{"atl":[[6.8,0],[7.8,0],[5.9,0],[5.4,0]],"id":36087680}],"con":true,"img":false}]}
{"op":"mcm","clk":"5306718713","pt":1646104427714,"mc":[{"id":"1.195395427","rc":[{"atb":[[3.35,2]],"id":38407646}],"con":true,"img":false}]}
{"op":"mcm","clk":"5306718744","pt":1646104428225,"mc":[{"id":"1.195395427","rc":[{"atb":[[1.01,3.36]],"id":37284251},{"atl":[[220,3.7]],"id":37284251},{"atb":[[1.01,3.36]],"id":42130949},{"atl":[[520,3.7]],"id":42130949},{"atb":[[6.2,4.79]],"id":38407646},{"atl":[[14.5,3.7]],"id":38407646},{"atb":[[4.4,7.32]],"id":43154456},{"atl":[[11,3.7]],"id":43154456},{"atb":[[1.97,25.69]],"id":43154457},{"atb":[[2.18,21.12]],"id":36087680}],"con":true,"img":false}]}
{"op":"mcm","clk":"5306718751","pt":1646104428431,"mc":[{"id":"1.195395427","rc":[{"atb":[[1.01,1.42]],"id":37284251}],"con":true,"img":false}]}
{"op":"mcm","clk":"5306718756","pt":1646104428534,"mc":[{"id":"1.195395427","rc":[{"atb":[[1.01,1.03]],"id":42130949}],"con":true,"img":false}]}
{"op":"mcm","clk":"5306718761","pt":1646104428636,"mc":[{"id":"1.195395427","rc":[{"atb":[[1.01,0]],"id":37284251}],"con":true,"img":false}]}
{"op":"mcm","clk":"5306718767","pt":1646104428738,"mc":[{"id":"1.195395427","rc":[{"atb":[[18.5,1.42]],"id":37284251},{"atb":[[1.01,0]],"id":42130949}],"con":true,"img":false}]}
{"op":"mcm","clk":"5306718773","pt":1646104428841,"mc":[{"id":"1.195395427","rc":[{"atb":[[25,1.03]],"id":42130949}],"con":true,"img":false}]}
{"op":"mcm","clk":"5306718858","pt":1646104430734,"mc":[{"id":"1.195395427","rc":[{"atb":[[16.5,13.94],[19,12.01],[23,31.57]],"id":37284251},{"atl":[[260,0.83],[160,0.68],[210,1.03]],"id":37284251},{"atb":[[32,9.68],[42,2.63],[26,13.22]],"id":42130949},{"atl":[[300,0.36],[350,0.61],[400,0.54]],"id":42130949},{"atb":[[4,72.07],[4.5,61.77],[5,27.02]],"id":38407646},{"atl":[[16,7.2],[18.5,12.35],[22,10.29]],"id":38407646},{"atb":[[4,72.07],[4.5,61.77],[5,54.45]],"id":43154456},{"atl":[[16,7.2],[18.5,12.35],[22,10.29]],"id":43154456},{"atb":[[2.06,203.98],[1.98,220.63],[2.16,93.19]],"id":43154457},{"atl":[[6.4,40.04],[5.2,25.73],[5.7,46]],"id":43154457},{"atb":[[2.06,203.98],[2.26,87.8],[2.16,186.39]],"id":36087680},{"atl":[[6.8,37.28],[5.9,44.12],[5.4,24.57]],"id":36087680}],"con":true,"img":false}]}
{"op":"mcm","clk":"5306719112","pt":1646104436833,"mc":[{"id":"1.195395427","rc":[{"atb":[[36,0]],"id":42130949}],"con":true,"img":false}]}
{"op":"mcm","clk":"5306719170","pt":1646104438363,"mc":[{"id":"1.195395427","rc":[{"atb":[[12,10.43]],"id":37284251},{"atb":[[3.45,32.4]],"id":43154456},{"atb":[[1.73,79.73]],"id":43154457}],"con":true,"img":false}]}
{"op":"mcm","clk":"5306719174","pt":1646104438465,"mc":[{"id":"1.195395427","rc":[{"atb":[[14.5,0]],"id":37284251},{"atb":[[32,6.97]],"id":42130949},{"atl":[[440,0]],"id":42130949},{"atb":[[4.8,0]],"id":38407646},{"atb":[[3.8,0]],"id":43154456},{"atb":[[1.89,0]],"id":43154457},{"atb":[[2.22,0]],"id":36087680}],"con":true,"img":false}]}
{"op":"mcm","clk":"5306719178","pt":1646104438567,"mc":[{"id":"1.195395427","rc":[{"atb":[[34,2.7]],"id":42130949},{"atl":[[510,2.7]],"id":42130949},{"atb":[[4.6,13.02]],"id":38407646},{"atb":[[2.28,59]],"id":36087680}],"con":true,"img":false}]}
{"op":"mcm","clk":"5306719183","pt":1646104438670,"mc":[{"id":"1.195395427","rc":[{"atl":[[8.8,58.31]],"id":43154456}],"con":true,"img":false}]}
{"op":"mcm","clk":"5306719235","pt":1646104440051,"mc":[{"id":"1.195395427","rc":[{"atb":[[2.52,13.82]],"id":43154457}],"con":true,"img":false}]}
{"op":"mcm","clk":"5306719253","pt":1646104440563,"mc":[{"id":"1.195395427","rc":[{"atl":[[10,13.82]],"id":38407646}],"con":true,"img":false}]}
{"op":"mcm","clk":"5306719300","pt":1646104441950,"mc":[{"id":"1.195395427","rc":[{"atb":[[7.4,25.38]],"id":38407646}],"con":true,"img":false}]}
{"op":"mcm","clk":"5306719303","pt":1646104442049,"mc":[{"id":"1.195395427","rc":[{"spl":[[1.01,38.95]],"id":36087680}],"con":true,"img":false}]}
{"op":"mcm","clk":"5306719370","pt":1646104443329,"mc":[{"id":"1.195395427","rc":[{"atb":[[23,42.39]],"id":37284251}],"con":true,"img":false}]}
{"op":"mcm","clk":"5306719425","pt":1646104444557,"mc":[{"id":"1.195395427","rc":[{"atb":[[2.74,14.52]],"id":36087680}],"con":true,"img":false}]}
{"op":"mcm","clk":"5306720070","pt":1646104459076,"mc":[{"id":"1.195395427","rc":[{"atl":[[1000,2.7]],"id":38407646},{"atl":[[1000,2.7]],"id":43154456}],"con":true,"img":false}]}
{"op":"mcm","clk":"5306720082","pt":1646104459282,"mc":[{"id":"1.195395427","rc":[{"atl":[[1000,2.72]],"id":38407646},{"atl":[[1000,2.73]],"id":43154456}],"con":true,"img":false}]}
{"op":"mcm","clk":"5306720093","pt":1646104459488,"mc":[{"id":"1.195395427","rc":[{"atl":[[1000,0.03]],"id":43154456}],"con":true,"img":false}]}
{"op":"mcm","clk":"5306720099","pt":1646104459591,"mc":[{"id":"1.195395427","rc":[{"atl":[[1000,0.02]],"id":38407646}],"con":true,"img":false}]}
{"op":"mcm","clk":"5306720107","pt":1646104459795,"mc":[{"id":"1.195395427","rc":[{"atl":[[1000,0]],"id":38407646},{"atl":[[1000,0]],"id":43154456}],"con":true,"img":false}]}
{"op":"mcm","clk":"5306720111","pt":1646104459898,"mc":[{"id":"1.195395427","rc":[{"atb":[[7.4,25.36]],"id":38407646},{"trd":[[7.4,0.04]],"ltp":7.4,"tv":0.04,"id":38407646},{"atb":[[5,54.42]],"id":43154456},{"trd":[[5,0.06]],"ltp":5.0,"tv":0.06,"id":43154456}],"con":true,"img":false}]}
{"op":"mcm","clk":"5306720118","pt":1646104460102,"mc":[{"id":"1.195395427","rc":[{"atb":[[5,52.45]],"id":43154456},{"atl":[[1000,2.7]],"id":43154457},{"atl":[[1000,2.7]],"id":36087680}],"con":true,"img":false}]}
{"op":"mcm","clk":"5306720125","pt":1646104460257,"mc":[{"id":"1.195395427","rc":[{"atl":[[1000,2.84]],"id":43154457},{"atl":[[1000,2.82]],"id":36087680}],"con":true,"img":false}]}
{"op":"mcm","clk":"5306720138","pt":1646104460568,"mc":[{"id":"1.195395427","rc":[{"atl":[[1000,0.13]],"id":43154457},{"atl":[[1000,0.12]],"id":36087680}],"con":true,"img":false}]}
{"op":"mcm","clk":"5306720140","pt":1646104460667,"mc":[{"id":"1.195395427","rc":[{"atl":[[4.3,0]],"id":43154457}],"con":true,"img":false}]}
{"op":"mcm","clk":"5306720143","pt":1646104460769,"mc":[{"id":"1.195395427","rc":[{"atl":[[1000,2.7]],"id":42130949},{"atl":[[1000,2.7]],"id":38407646},{"atl":[[4.2,13.11]],"id":43154457}],"con":true,"img":false}]}
{"op":"mcm","clk":"5306720151","pt":1646104460973,"mc":[{"id":"1.195395427","rc":[{"atl":[[1000,2.71]],"id":42130949},{"atl":[[1000,2.74]],"id":38407646}],"con":true,"img":false}]}
{"op":"mcm","clk":"5306720158","pt":1646104461179,"mc":[{"id":"1.195395427","rc":[{"atl":[[1000,0]],"id":42130949},{"atl":[[1000,0.04]],"id":38407646}],"con":true,"img":false}]}
{"op":"mcm","clk":"5306720170","pt":1646104461485,"mc":[{"id":"1.195395427","rc":[{"atl":[[1000,0]],"id":42130949},{"atl":[[1000,0]],"id":38407646}],"con":true,"img":false}]}
{"op":"mcm","clk":"5306720176","pt":1646104461589,"mc":[{"id":"1.195395427","rc":[{"atb":[[44,0.23]],"id":42130949},{"trd":[[44,0.01]],"ltp":44.0,"tv":0.01,"id":42130949},{"atb":[[7.4,25.32]],"id":38407646},{"trd":[[7.4,0.12]],"ltp":7.4,"tv":0.12,"id":38407646}],"con":true,"img":false}]}
{"op":"mcm","clk":"5306720182","pt":1646104461692,"mc":[{"id":"1.195395427","rc":[{"atb":[[44,0]],"id":42130949}],"con":true,"img":false}]}
{"op":"mcm","clk":"5306720186","pt":1646104461794,"mc":[{"id":"1.195395427","rc":[{"atl":[[1000,2.7]],"id":37284251}],"con":true,"img":false}]}
{"op":"mcm","clk":"5306720190","pt":1646104461896,"mc":[{"id":"1.195395427","rc":[{"atl":[[1000,0]],"id":36087680}],"con":true,"img":false}]}
{"op":"mcm","clk":"5306720195","pt":1646104461999,"mc":[{"id":"1.195395427","rc":[{"atl":[[1000,2.71]],"id":37284251},{"atb":[[2.74,14.4]],"id":36087680},{"trd":[[2.74,0.24]],"ltp":2.74,"tv":0.24,"id":36087680}],"con":true,"img":false}]}
{"op":"mcm","clk":"5306720207","pt":1646104462307,"mc":[{"id":"1.195395427","rc":[{"atl":[[1000,0]],"id":37284251}],"con":true,"img":false}]}
{"op":"mcm","clk":"5306720213","pt":1646104462409,"mc":[{"id":"1.195395427","rc":[{"atl":[[1000,0]],"id":43154457}],"con":true,"img":false}]}
{"op":"mcm","clk":"5306720218","pt":1646104462514,"mc":[{"id":"1.195395427","rc":[{"atl":[[1000,0]],"id":37284251},{"atb":[[2.52,13.68]],"id":43154457},{"trd":[[2.52,0.27]],"ltp":2.52,"tv":0.27,"id":43154457}],"con":true,"img":false}]}
{"op":"mcm","clk":"5306720223","pt":1646104462618,"mc":[{"id":"1.195395427","rc":[{"atb":[[23,42.38]],"id":37284251},{"trd":[[23,0.01]],"ltp":23.0,"tv":0.01,"id":37284251}],"con":true,"img":false}]}
{"op":"mcm","clk":"5306720228","pt":1646104462673,"mc":[{"id":"1.195395427","rc":[{"atb":[[2.36,14.71]],"id":43154457}],"con":true,"img":false}]}
{"op":"mcm","clk":"5306720233","pt":1646104462777,"mc":[{"id":"1.195395427","rc":[{"atb":[[23,41.92]],"id":37284251},{"spn":71.0,"spf":1.0,"id":42130949},{"spn":2.72,"spf":1.0,"id":36087680}],"con":true,"img":false}]}
{"op":"mcm","clk":"5306720306","pt":1646104464268,"mc":[{"id":"1.195395427","rc":[{"spb":[[32,96.66]],"id":37284251},{"spl":[[42,0.93]],"id":42130949},{"spb":[[8.8,52.63]],"id":38407646},{"spb":[[2.72,14.69]],"id":43154457},{"spb":[[3.25,23.8]],"id":36087680}],"con":true,"img":false}]}
{"op":"mcm","clk":"5306720311","pt":1646104464371,"mc":[{"id":"1.195395427","rc":[{"atb":[[1.01,10124.21]],"id":43154457}],"con":true,"img":false}]}
{"op":"mcm","clk":"5306720456","pt":1646104467192,"mc":[{"id":"1.195395427","rc":[{"atb":[[5.1,3.6]],"id":43154456}],"con":true,"img":false}]}
{"op":"mcm","clk":"5306720461","pt":1646104467295,"mc":[{"id":"1.195395427","rc":[{"atl":[[1000,2.23]],"id":37284251}],"con":true,"img":false}]}
{"op":"mcm","clk":"5306720467","pt":1646104467495,"mc":[{"id":"1.195395427","rc":[{"atl":[[65,0],[1000,0.07]],"id":37284251}],"con":true,"img":false}]}
{"op":"mcm","clk":"5306720476","pt":1646104467700,"mc":[{"id":"1.195395427","rc":[{"atl":[[1000,0]],"id":37284251}],"con":true,"img":false}]}
{"op":"mcm","clk":"5306720480","pt":1646104467803,"mc":[{"id":"1.195395427","rc":[{"atl":[[50,0.07]],"id":37284251}],"con":true,"img":false}]}
{"op":"mcm","clk":"5306721220","pt":1646104483709,"mc":[{"id":"1.195395427","rc":[{"atb":[[34,0]],"id":42130949}],"con":true,"img":false}]}
{"op":"mcm","clk":"5306721225","pt":1646104483813,"mc":[{"id":"1.195395427","rc":[{"atb":[[36,2.7]],"id":42130949}],"con":true,"img":false}]}
{"op":"mcm","clk":"5306722263","pt":1646104507368,"mc":[{"id":"1.195395427","rc":[{"atb":[[36,3]],"id":42130949}],"con":true,"img":false}]}
{"op":"mcm","clk":"5306722461","pt":1646104510849,"mc":[{"id":"1.195395427","rc":[{"atb":[[2.36,0],[2.1,0]],"id":43154457},{"atb":[[2.54,0],[2.28,43.3]],"id":36087680}],"con":true,"img":false}]}
{"op":"mcm","clk":"5306723269","pt":1646104527257,"mc":[{"id":"1.195395427","rc":[{"spn":41.0,"spf":66.0,"id":37284251},{"atb":[[36,0.3]],"id":42130949},{"spn":42.0,"spf":1.0,"id":42130949},{"spn":9.4,"spf":54.4,"id":38407646},{"spn":6.95,"spf":1.0,"id":43154456},{"spn":3.01,"spf":51.36,"id":43154457},{"spn":2.73,"spf":1.61,"id":36087680}],"con":true,"img":false}]}
{"op":"mcm","clk":"5306723274","pt":1646104527358,"mc":[{"id":"1.195395427","rc":[{"atb":[[34,2.7]],"id":42130949}],"con":true,"img":false}]}
{"op":"mcm","clk":"5306724329","pt":1646104551106,"mc":[{"id":"1.195395427","rc":[{"atb":[[1.01,2.23]],"id":43154456}],"con":true,"img":false}]}
{"op":"mcm","clk":"5306724342","pt":1646104551323,"mc":[{"id":"1.195395427","rc":[{"atb":[[1.01,0.71]],"id":43154456}],"con":true,"img":false}]}
{"op":"mcm","clk":"5306724349","pt":1646104551414,"mc":[{"id":"1.195395427","rc":[{"atb":[[4.8,0]],"id":43154456}],"con":true,"img":false}]}
{"op":"mcm","clk":"5306724355","pt":1646104551516,"mc":[{"id":"1.195395427","rc":[{"atb":[[1.01,0]],"id":43154456}],"con":true,"img":false}]}
{"op":"mcm","clk":"5306724361","pt":1646104551616,"mc":[{"id":"1.195395427","rc":[{"atb":[[5.2,0.71]],"id":43154456}],"con":true,"img":false}]}
{"op":"mcm","clk":"5306726043","pt":1646104587484,"mc":[{"id":"1.195395427","rc":[{"atb":[[24,4]],"id":37284251},{"spn":7.0,"spf":1.0,"id":43154456}],"con":true,"img":false}]}
{"op":"mcm","clk":"5306728518","pt":1646104635567,"mc":[{"id":"1.195395427","rc":[{"atb":[[17,0],[12,0]],"id":37284251},{"atl":[[140,0],[75,0]],"id":37284251},{"atb":[[34,0],[26,8.64]],"id":42130949},{"atl":[[280,0],[510,0]],"id":42130949},{"atb":[[4.6,0],[7.4,22.66]],"id":38407646},{"atl":[[13.5,0],[15.5,0]],"id":38407646},{"atb":[[3.45,0],[4.2,0]],"id":43154456},{"atl":[[8.8,52.2],[14,0]],"id":43154456},{"atb":[[1.73,0],[1.99,0]],"id":43154457},{"atl":[[4.8,0],[4.2,0]],"id":43154457},{"atb":[[2.28,0],[2.08,0]],"id":36087680},{"atl":[[5.3,0],[4.7,0]],"id":36087680}],"con":true,"img":false}]}
{"op":"mcm","clk":"5306728526","pt":1646104635770,"mc":[{"id":"1.195395427","rc":[{"atb":[[17,2.7],[12.5,9.65]],"id":37284251},{"atl":[[130,2.7],[80,0.54],[50,0],[200,0.07]],"id":37284251},{"atb":[[36,3],[27,4.45]],"id":42130949},{"atl":[[290,0.15],[500,2.7]],"id":42130949},{"atb":[[4.6,15.37],[7.4,25.32]],"id":38407646},{"atl":[[13.5,3.46],[15,11.31]],"id":38407646},{"atb":[[3.45,32.17],[4.3,13.11]],"id":43154456},{"atl":[[8.6,5.69],[13.5,10.58]],"id":43154456},{"atb":[[2,43.28],[1.74,77.44]],"id":43154457},{"atl":[[4.2,13.52],[4.7,34.64]],"id":43154457},{"atb":[[2.28,33.81],[2.08,45.9]],"id":36087680},{"atl":[[4.8,11.39],[5.2,28.34]],"id":36087680}],"con":true,"img":false}]}
{"op":"mcm","clk":"5306729533","pt":1646104656599,"mc":[{"id":"1.195395427","rc":[{"spn":43.5,"spf":66.0,"id":37284251},{"atb":[[36,0.3]],"id":42130949},{"atl":[[500,0]],"id":42130949},{"atl":[[15,0]],"id":38407646},{"atb":[[4.3,0]],"id":43154456},{"spn":6.9,"spf":1.0,"id":43154456},{"atb":[[2,0]],"id":43154457},{"atl":[[5.2,0]],"id":36087680}],"con":true,"img":false}]}
{"op":"mcm","clk":"5306729539","pt":1646104656701,"mc":[{"id":"1.195395427","rc":[{"atb":[[34,2.7]],"id":42130949},{"atl":[[510,2.7]],"id":42130949},{"atl":[[15.5,11.31]],"id":38407646},{"atb":[[4.2,13.11]],"id":43154456},{"atb":[[1.99,43.28]],"id":43154457},{"atl":[[5.3,28.34]],"id":36087680}],"con":true,"img":false}]}
{"op":"mcm","clk":"5306730332","pt":1646104671200,"mc":[{"id":"1.195395427","rc":[{"atb":[[1.04,2.23]],"id":37284251}],"con":true,"img":false}]}
{"op":"mcm","clk":"5306730345","pt":1646104671404,"mc":[{"id":"1.195395427","rc":[{"atb":[[1.04,0.14]],"id":37284251}],"con":true,"img":false}]}
{"op":"mcm","clk":"5306730357","pt":1646104671611,"mc":[{"id":"1.195395427","rc":[{"atb":[[23,41.77],[1.04,0]],"id":37284251}],"con":true,"img":false}]}
{"op":"mcm","clk":"5306730363","pt":1646104671713,"mc":[{"id":"1.195395427","rc":[{"atb":[[25,0.14]],"id":37284251}],"con":true,"img":false}]}
{"op":"mcm","clk":"5306731800","pt":1646104698855,"mc":[{"id":"1.195395427","rc":[{"atl":[[290,0]],"id":42130949}],"con":true,"img":false}]}
{"op":"mcm","clk":"5306731804","pt":1646104698957,"mc":[{"id":"1.195395427","rc":[{"atl":[[280,0.15]],"id":42130949}],"con":true,"img":false}]}
{"op":"mcm","clk":"5306735062","pt":1646104759129,"mc":[{"id":"1.195395427","rc":[{"atl":[[1000,2.7]],"id":43154457},{"atl":[[1000,2.7]],"id":36087680}],"con":true,"img":false}]}
{"op":"mcm","clk":"5306735074","pt":1646104759332,"mc":[{"id":"1.195395427","rc":[{"atl":[[1000,2.75]],"id":43154457},{"atl":[[1000,2.74]],"id":36087680}],"con":true,"img":false}]}
{"op":"mcm","clk":"5306735086","pt":1646104759639,"mc":[{"id":"1.195395427","rc":[{"atl":[[1000,0.04]],"id":43154457},{"atl":[[1000,0.04]],"id":36087680}],"con":true,"img":false}]}
{"op":"mcm","clk":"5306735098","pt":1646104759844,"mc":[{"id":"1.195395427","rc":[{"atl":[[1000,0]],"id":43154457},{"atl":[[1000,0]],"id":36087680}],"con":true,"img":false}]}
{"op":"mcm","clk":"5306735105","pt":1646104759946,"mc":[{"id":"1.195395427","rc":[{"atb":[[2.52,13.63]],"id":43154457},{"trd":[[2.52,0.37]],"ltp":2.52,"tv":0.37,"id":43154457},{"atb":[[2.74,14.36]],"id":36087680},{"trd":[[2.74,0.32]],"ltp":2.74,"tv":0.32,"id":36087680}],"con":true,"img":false}]}
{"op":"mcm","clk":"5306740076","pt":1646104872491,"mc":[{"id":"1.195395427","rc":[{"atl":[[220,0]],"id":37284251}],"con":true,"img":false}]}
{"op":"mcm","clk":"5306740091","pt":1646104872797,"mc":[{"id":"1.195395427","rc":[{"atl":[[520,0]],"id":42130949}],"con":true,"img":false}]}
{"op":"mcm","clk":"5306740104","pt":1646104873102,"mc":[{"id":"1.195395427","rc":[{"atl":[[11,0]],"id":43154456}],"con":true,"img":false}]}
{"op":"mcm","clk":"5306740116","pt":1646104873409,"mc":[{"id":"1.195395427","rc":[{"atb":[[4.4,0]],"id":43154456}],"con":true,"img":false}]}
{"op":"mcm","clk":"5306740124","pt":1646104873717,"mc":[{"id":"1.195395427","rc":[{"atb":[[25,0]],"id":42130949}],"con":true,"img":false}]}
{"op":"mcm","clk":"5306740134","pt":1646104874023,"mc":[{"id":"1.195395427","rc":[{"atb":[[18.5,0]],"id":37284251}],"con":true,"img":false}]}
{"op":"mcm","clk":"5306740145","pt":1646104874330,"mc":[{"id":"1.195395427","rc":[{"atb":[[6.2,0]],"id":38407646}],"con":true,"img":false}]}
{"op":"mcm","clk":"5306740153","pt":1646104874587,"mc":[{"id":"1.195395427","rc":[{"atl":[[14.5,0]],"id":38407646}],"con":true,"img":false}]}
{"op":"mcm","clk":"5306740164","pt":1646104874894,"mc":[{"id":"1.195395427","rc":[{"atb":[[2.18,0]],"id":36087680}],"con":true,"img":false}]}
{"op":"mcm","clk":"5306740176","pt":1646104875200,"mc":[{"id":"1.195395427","rc":[{"atb":[[1.97,0]],"id":43154457}],"con":true,"img":false}]}
{"op":"mcm","clk":"5306740388","pt":1646104880847,"mc":[{"id":"1.195395427","rc":[{"atl":[[510,0]],"id":42130949},{"atl":[[15.5,0]],"id":38407646}],"con":true,"img":false}]}
{"op":"mcm","clk":"5306740392","pt":1646104880949,"mc":[{"id":"1.195395427","rc":[{"atl":[[680,2.7]],"id":42130949},{"atl":[[17.5,11.31]],"id":38407646}],"con":true,"img":false}]}
{"op":"mcm","clk":"5306745134","pt":1646104996794,"mc":[{"id":"1.195395427","rc":[{"atb":[[4.2,0]],"id":43154456}],"con":true,"img":false}]}
{"op":"mcm","clk":"5306745136","pt":1646104996896,"mc":[{"id":"1.195395427","rc":[{"atb":[[4.1,13.11]],"id":43154456}],"con":true,"img":false}]}
{"op":"mcm","clk":"5306750791","pt":1646105126979,"mc":[{"id":"1.195395427","rc":[{"atb":[[1.01,0]],"id":43154457}],"con":true,"img":false}]}
{"op":"mcm","clk":"5306752030","pt":1646105155530,"mc":[{"id":"1.195395427","rc":[{"atb":[[5,27.02]],"id":43154456}],"con":true,"img":false}]}
{"op":"mcm","clk":"5306752034","pt":1646105155633,"mc":[{"id":"1.195395427","rc":[{"atb":[[5,52.45]],"id":43154456}],"con":true,"img":false}]}
{"op":"mcm","clk":"5306752038","pt":1646105155735,"mc":[{"id":"1.195395427","rc":[{"atb":[[1.01,2.23],[5.2,0]],"id":43154456}],"con":true,"img":false}]}
{"op":"mcm","clk":"5306752046","pt":1646105155892,"mc":[{"id":"1.195395427","rc":[{"atb":[[1.01,0.71]],"id":43154456}],"con":true,"img":false}]}
{"op":"mcm","clk":"5306752055","pt":1646105156097,"mc":[{"id":"1.195395427","rc":[{"atb":[[1.01,0]],"id":43154456}],"con":true,"img":false}]}
{"op":"mcm","clk":"5306752062","pt":1646105156200,"mc":[{"id":"1.195395427","rc":[{"atb":[[5.1,4.31]],"id":43154456}],"con":true,"img":false}]}
{"op":"mcm","clk":"5306756852","pt":1646105296481,"mc":[{"id":"1.195395427","rc":[{"atb":[[5,27.02]],"id":43154456},{"spn":6.85,"spf":1.0,"id":43154456}],"con":true,"img":false}]}
{"op":"mcm","clk":"5306761372","pt":1646105432480,"mc":[{"id":"1.195395427","rc":[{"atl":[[1000,2.23]],"id":37284251}],"con":true,"img":false}]}
{"op":"mcm","clk":"5306761387","pt":1646105432889,"mc":[{"id":"1.195395427","rc":[{"atl":[[1000,1.11]],"id":37284251}],"con":true,"img":false}]}
{"op":"mcm","clk":"5306761400","pt":1646105433197,"mc":[{"id":"1.195395427","rc":[{"atl":[[1000,0]],"id":37284251}],"con":true,"img":false}]}
{"op":"mcm","clk":"5306761402","pt":1646105433299,"mc":[{"id":"1.195395427","rc":[{"atb":[[25,0]],"id":37284251},{"atl":[[25,0.96]],"id":37284251},{"trd":[[25,0.29]],"ltp":25.0,"tv":0.29,"id":37284251}],"con":true,"img":false}]}
{"op":"mcm","clk":"5306761410","pt":1646105433503,"mc":[{"id":"1.195395427","rc":[{"atl":[[25,0]],"id":37284251},{"trd":[[25,2.23]],"ltp":25.0,"tv":2.23,"id":37284251}],"con":true,"img":false}]}
{"op":"mcm","clk":"5306766996","pt":1646105654874,"mc":[{"id":"1.195395427","rc":[{"atb":[[3.35,0]],"id":38407646}],"con":true,"img":false}]}
{"op":"mcm","clk":"5306773057","pt":1646105843198,"mc":[{"id":"1.195395427","rc":[{"atl":[[8.8,41.38]],"id":43154456}],"con":true,"img":false}]}
{"op":"mcm","clk":"5306773063","pt":1646105843300,"mc":[{"id":"1.195395427","rc":[{"atl":[[8.6,16.51]],"id":43154456}],"con":true,"img":false}]}
{"op":"mcm","clk":"5306773072","pt":1646105843813,"mc":[{"id":"1.195395427","rc":[{"atb":[[2.4,0]],"id":43154457}],"con":true,"img":false}]}
{"op":"mcm","clk":"5306773075","pt":1646105843914,"mc":[{"id":"1.195395427","rc":[{"atb":[[2.52,24.45]],"id":43154457}],"con":true,"img":false}]}
{"op":"mcm","clk":"5306773150","pt":1646105846011,"mc":[{"id":"1.195395427","rc":[{"atl":[[10.5,10.82]],"id":38407646}],"con":true,"img":false}]}
{"op":"mcm","clk":"5306773154","pt":1646105846118,"mc":[{"id":"1.195395427","rc":[{"atl":[[10,24.64]],"id":38407646}],"con":true,"img":false}]}
{"op":"mcm","clk":"5306773172","pt":1646105846728,"mc":[{"id":"1.195395427","rc":[{"atb":[[23,30.95]],"id":37284251}],"con":true,"img":false}]}
{"op":"mcm","clk":"5306773176","pt":1646105846832,"mc":[{"id":"1.195395427","rc":[{"atb":[[24,14.82]],"id":37284251}],"con":true,"img":false}]}
{"op":"mcm","clk":"5306773207","pt":1646105847498,"mc":[{"id":"1.195395427","rc":[{"atl":[[4.7,0]],"id":43154457},{"atl":[[4.8,0]],"id":36087680}],"con":true,"img":false}]}
{"op":"mcm","clk":"5306773210","pt":1646105847601,"mc":[{"id":"1.195395427","rc":[{"atl":[[5.1,34.64]],"id":43154457},{"atl":[[4.7,11.39]],"id":36087680}],"con":true,"img":false}]}
{"op":"mcm","clk":"5306773231","pt":1646105848214,"mc":[{"id":"1.195395427","rc":[{"atb":[[2.68,0]],"id":36087680}],"con":true,"img":false}]}
{"op":"mcm","clk":"5306773233","pt":1646105848316,"mc":[{"id":"1.195395427","rc":[{"atb":[[2.74,25.18]],"id":36087680}],"con":true,"img":false}]}
{"op":"mcm","clk":"5306774083","pt":1646105878479,"mc":[{"id":"1.195395427","rc":[{"atb":[[2,146.09]],"id":43154456}],"con":true,"img":false}]}
{"op":"mcm","clk":"5306774828","pt":1646105903177,"mc":[{"id":"1.195395427","rc":[{"atl":[[8.8,30.56]],"id":43154456}],"con":true,"img":false}]}
{"op":"mcm","clk":"5306774833","pt":1646105903281,"mc":[{"id":"1.195395427","rc":[{"atl":[[8.6,27.34]],"id":43154456},{"spn":2.73,"spf":1.61,"id":36087680}],"con":true,"img":false}]}
{"op":"mcm","clk":"5306774853","pt":1646105903794,"mc":[{"id":"1.195395427","rc":[{"atb":[[2.5,9.23]],"id":43154457}],"con":true,"img":false}]}
{"op":"mcm","clk":"5306774856","pt":1646105903895,"mc":[{"id":"1.195395427","rc":[{"atb":[[2.52,35.27]],"id":43154457}],"con":true,"img":false}]}
{"op":"mcm","clk":"5306774868","pt":1646105904406,"mc":[{"id":"1.195395427","rc":[{"atb":[[7.4,22.66]],"id":38407646}],"con":true,"img":false}]}
{"op":"mcm","clk":"5306774872","pt":1646105904509,"mc":[{"id":"1.195395427","rc":[{"atb":[[7.6,2.65]],"id":38407646}],"con":true,"img":false}]}
{"op":"mcm","clk":"5306774927","pt":1646105906298,"mc":[{"id":"1.195395427","rc":[{"atl":[[10.5,0]],"id":38407646}],"con":true,"img":false}]}
{"op":"mcm","clk":"5306774929","pt":1646105906402,"mc":[{"id":"1.195395427","rc":[{"atl":[[10,35.46]],"id":38407646}],"con":true,"img":false}]}
{"op":"mcm","clk":"5306774951","pt":1646105907012,"mc":[{"id":"1.195395427","rc":[{"atb":[[23,20.12]],"id":37284251}],"con":true,"img":false}]}
{"op":"mcm","clk":"5306774955","pt":1646105907062,"mc":[{"id":"1.195395427","rc":[{"atb":[[24,25.64]],"id":37284251}],"con":true,"img":false}]}
{"op":"mcm","clk":"5306775011","pt":1646105909315,"mc":[{"id":"1.195395427","rc":[{"atb":[[2.72,14.24]],"id":36087680}],"con":true,"img":false}]}
{"op":"mcm","clk":"5306775015","pt":1646105909415,"mc":[{"id":"1.195395427","rc":[{"atb":[[2.74,36]],"id":36087680}],"con":true,"img":false}]}
{"op":"mcm","clk":"5306775056","pt":1646105910800,"mc":[{"id":"1.195395427","rc":[{"atb":[[7.4,19.04]],"id":38407646}],"con":true,"img":false}]}
{"op":"mcm","clk":"5306775060","pt":1646105910905,"mc":[{"id":"1.195395427","rc":[{"atb":[[7.6,5.86]],"id":38407646}],"con":true,"img":false}]}
{"op":"mcm","clk":"5306781875","pt":1646106120995,"mc":[{"id":"1.195395427","rc":[{"spl":[[2.16,13.25]],"id":36087680},{"spn":2.73,"spf":1.61,"id":36087680}],"con":true,"img":false}]}
{"op":"mcm","clk":"5306781879","pt":1646106121044,"mc":[{"id":"1.195395427","rc":[{"atl":[[13.5,9.12]],"id":38407646}],"con":true,"img":false}]}
{"op":"mcm","clk":"5306781893","pt":1646106121148,"mc":[{"id":"1.195395427","rc":[{"atb":[[17,7.99],[19.5,5.28]],"id":37284251},{"atl":[[130,7.9],[80,5.74]],"id":37284251},{"atb":[[6.8,22.48]],"id":38407646},{"atl":[[13.5,14.79]],"id":38407646},{"atb":[[2.5,17.56],[2.18,8.33]],"id":43154457},{"atl":[[3.35,15.08]],"id":43154457},{"atb":[[2.72,22.13],[2.3,7.88]],"id":36087680},{"atl":[[3.8,23.54]],"id":36087680}],"con":true,"img":false}]}
{"op":"mcm","clk":"5306781898","pt":1646106121251,"mc":[{"id":"1.195395427","rc":[{"atb":[[26,13.84],[27,9.65]],"id":42130949},{"atb":[[7.6,9.36]],"id":38407646},{"atl":[[9.8,3.21]],"id":38407646},{"atb":[[5.1,8.29],[5,39.33]],"id":43154456},{"atl":[[8.8,36.35],[13.5,16.37],[8.4,3.43]],"id":43154456},{"atb":[[2.54,6.59]],"id":43154457},{"atl":[[3.3,12.2]],"id":43154457},{"atl":[[3.75,10.84]],"id":36087680}],"con":true,"img":false}]}
{"op":"mcm","clk":"5306781900","pt":1646106121352,"mc":[{"id":"1.195395427","rc":[{"atl":[[200,0],[1000,2.23]],"id":37284251}],"con":true,"img":false}]}
{"op":"mcm","clk":"5306781910","pt":1646106121558,"mc":[{"id":"1.195395427","rc":[{"atl":[[1000,0.07]],"id":37284251}],"con":true,"img":false}]}
{"op":"mcm","clk":"5306781923","pt":1646106121765,"mc":[{"id":"1.195395427","rc":[{"atl":[[1000,0]],"id":37284251}],"con":true,"img":false}]}
{"op":"mcm","clk":"5306781928","pt":1646106121866,"mc":[{"id":"1.195395427","rc":[{"atl":[[50,0.07]],"id":37284251}],"con":true,"img":false}]}
{"op":"mcm","clk":"5306781997","pt":1646106123666,"mc":[{"id":"1.195395427","rc":[{"atb":[[7.6,6.71]],"id":38407646},{"atl":[[8.6,21.64]],"id":43154456},{"atl":[[4.2,0]],"id":43154457},{"atl":[[4.7,0]],"id":36087680}],"con":true,"img":false}]}
{"op":"mcm","clk":"5306782002","pt":1646106123768,"mc":[{"id":"1.195395427","rc":[{"atb":[[7.8,2.65]],"id":38407646},{"atl":[[9.8,5.69]],"id":43154456},{"atl":[[4.1,13.52]],"id":43154457},{"atl":[[4.5,11.39]],"id":36087680}],"con":true,"img":false}]}
{"op":"mcm","clk":"5306782006","pt":1646106123872,"mc":[{"id":"1.195395427","rc":[{"atb":[[7.4,24.85],[7.8,6.11],[7,5.81]],"id":38407646},{"atl":[[8.6,27.43],[9.8,11.49]],"id":43154456},{"atl":[[3.4,30.48]],"id":43154457},{"atl":[[4.4,14.47]],"id":36087680}],"con":true,"img":false}]}
{"op":"mcm","clk":"5306782090","pt":1646106126387,"mc":[{"id":"1.195395427","rc":[{"atl":[[8.8,25.53]],"id":43154456}],"con":true,"img":false}]}
{"op":"mcm","clk":"5306782092","pt":1646106126488,"mc":[{"id":"1.195395427","rc":[{"atl":[[8.6,38.26]],"id":43154456}],"con":true,"img":false}]}
{"op":"mcm","clk":"5306782108","pt":1646106126999,"mc":[{"id":"1.195395427","rc":[{"atb":[[23,9.3]],"id":37284251}],"con":true,"img":false}]}
{"op":"mcm","clk":"5306782109","pt":1646106127102,"mc":[{"id":"1.195395427","rc":[{"atb":[[24,36.46]],"id":37284251}],"con":true,"img":false}]}
{"op":"mcm","clk":"5306783017","pt":1646106151308,"mc":[{"id":"1.195395427","rc":[{"atb":[[7.6,3.5]],"id":38407646},{"atl":[[10,32.46]],"id":38407646},{"atb":[[2.52,32.46]],"id":43154457}],"con":true,"img":false}]}
{"op":"mcm","clk":"5306783020","pt":1646106151410,"mc":[{"id":"1.195395427","rc":[{"atl":[[75,2.14]],"id":37284251},{"atb":[[7.8,10.11]],"id":38407646},{"atl":[[9.8,5.81]],"id":38407646},{"atb":[[2.56,3.15]],"id":43154457}],"con":true,"img":false}]}
{"op":"mcm","clk":"5306783025","pt":1646106151514,"mc":[{"id":"1.195395427","rc":[{"atl":[[50,0],[1000,2.23]],"id":37284251}],"con":true,"img":false}]}
{"op":"mcm","clk":"5306783031","pt":1646106151717,"mc":[{"id":"1.195395427","rc":[{"atl":[[1000,0.07]],"id":37284251}],"con":true,"img":false}]}
{"op":"mcm","clk":"5306783036","pt":1646106151923,"mc":[{"id":"1.195395427","rc":[{"atl":[[1000,0]],"id":37284251}],"con":true,"img":false}]}
{"op":"mcm","clk":"5306783039","pt":1646106152025,"mc":[{"id":"1.195395427","rc":[{"atl":[[70,0.07]],"id":37284251}],"con":true,"img":false}]}
{"op":"mcm","clk":"5306783282","pt":1646106158415,"mc":[{"id":"1.195395427","rc":[{"atl":[[80,5.19]],"id":37284251},{"atb":[[8,2.45]],"id":38407646}],"con":true,"img":false}]}
{"op":"mcm","clk":"5306783288","pt":1646106158518,"mc":[{"id":"1.195395427","rc":[{"atl":[[70,5.26],[75,2.68]],"id":37284251},{"atb":[[8,5.88],[5.3,6.49],[7.8,7.46],[6.6,16.61]],"id":38407646},{"atl":[[16,18.79]],"id":43154456},{"atl":[[4,7.56],[4.1,7.56]],"id":43154457},{"atl":[[4.5,18.64],[5.2,7.25]],"id":36087680}],"con":true,"img":false}]}
{"op":"mcm","clk":"5306783293","pt":1646106158622,"mc":[{"id":"1.195395427","rc":[{"atl":[[4,21.09]],"id":43154457}],"con":true,"img":false}]}
{"op":"mcm","clk":"5306783933","pt":1646106175521,"mc":[{"id":"1.195395427","rc":[{"atl":[[4.5,7.25]],"id":36087680}],"con":true,"img":false}]}
{"op":"mcm","clk":"5306783937","pt":1646106175624,"mc":[{"id":"1.195395427","rc":[{"atl":[[4.3,11.39]],"id":36087680}],"con":true,"img":false}]}
{"op":"mcm","clk":"5306784460","pt":1646106191345,"mc":[{"id":"1.195395427","rc":[{"atb":[[24,32.46]],"id":37284251},{"atl":[[75,0.54]],"id":37284251},{"atb":[[7.8,3.46]],"id":38407646},{"spn":9.3,"spf":54.4,"id":38407646},{"spn":6.75,"spf":1.0,"id":43154456}],"con":true,"img":false}]}
{"op":"mcm","clk":"5306784509","pt":1646106192882,"mc":[{"id":"1.195395427","rc":[{"atl":[[75,0]],"id":37284251}],"con":true,"img":false}]}
{"op":"mcm","clk":"5306784510","pt":1646106192936,"mc":[{"id":"1.195395427","rc":[{"atl":[[65,0.54]],"id":37284251}],"con":true,"img":false}]}
{"op":"mcm","clk":"5306785572","pt":1646106227681,"mc":[{"id":"1.195395427","rc":[{"atl":[[17.5,0]],"id":38407646}],"con":true,"img":false}]}
{"op":"mcm","clk":"5306785575","pt":1646106227785,"mc":[{"id":"1.195395427","rc":[{"atl":[[15.5,11.31]],"id":38407646}],"con":true,"img":false}]}
{"op":"mcm","clk":"5306785636","pt":1646106230391,"mc":[{"id":"1.195395427","rc":[{"atl":[[1000,2.23]],"id":37284251}],"con":true,"img":false}]}
{"op":"mcm","clk":"5306785641","pt":1646106230596,"mc":[{"id":"1.195395427","rc":[{"atl":[[70,5.19]],"id":37284251}],"con":true,"img":false}]}
{"op":"mcm","clk":"5306785645","pt":1646106230700,"mc":[{"id":"1.195395427","rc":[{"atl":[[1000,0.07]],"id":37284251}],"con":true,"img":false}]}
{"op":"mcm","clk":"5306785648","pt":1646106230801,"mc":[{"id":"1.195395427","rc":[{"atl":[[1000,0]],"id":37284251}],"con":true,"img":false}]}
{"op":"mcm","clk":"5306785651","pt":1646106230903,"mc":[{"id":"1.195395427","rc":[{"atl":[[50,0.07]],"id":37284251}],"con":true,"img":false}]}
{"op":"mcm","clk":"5306786121","pt":1646106244620,"mc":[{"id":"1.195395427","rc":[{"atl":[[65,0]],"id":37284251}],"con":true,"img":false}]}
{"op":"mcm","clk":"5306786124","pt":1646106244723,"mc":[{"id":"1.195395427","rc":[{"atl":[[50,0],[60,0.54],[1000,2.23]],"id":37284251}],"con":true,"img":false}]}
{"op":"mcm","clk":"5306786133","pt":1646106244926,"mc":[{"id":"1.195395427","rc":[{"atl":[[1000,0.07]],"id":37284251}],"con":true,"img":false}]}
{"op":"mcm","clk":"5306786141","pt":1646106245133,"mc":[{"id":"1.195395427","rc":[{"atl":[[1000,0]],"id":37284251}],"con":true,"img":false}]}
{"op":"mcm","clk":"5306786145","pt":1646106245238,"mc":[{"id":"1.195395427","rc":[{"atl":[[65,0.07]],"id":37284251}],"con":true,"img":false}]}
{"op":"mcm","clk":"5306786987","pt":1646106271847,"mc":[{"id":"1.195395427","rc":[{"atb":[[25,2.59]],"id":37284251}],"con":true,"img":false}]}
{"op":"mcm","clk":"5306786990","pt":1646106271950,"mc":[{"id":"1.195395427","rc":[{"atb":[[16.5,19.23],[19,17.29]],"id":37284251},{"atl":[[15,5.66],[15.5,16.97]],"id":38407646},{"atl":[[18.5,18.15],[18,5.8]],"id":43154456},{"atl":[[5,7.57],[3.95,7.57]],"id":43154457},{"atl":[[4.3,18.64],[4.2,7.25]],"id":36087680}],"con":true,"img":false}]}
{"op":"mcm","clk":"5306787162","pt":1646106277785,"mc":[{"id":"1.195395427","rc":[{"atl":[[60,0]],"id":37284251}],"con":true,"img":false}]}
{"op":"mcm","clk":"5306787166","pt":1646106277841,"mc":[{"id":"1.195395427","rc":[{"atl":[[65,0.62]],"id":37284251}],"con":true,"img":false}]}
{"op":"mcm","clk":"5306787732","pt":1646106295485,"mc":[{"id":"1.195395427","rc":[{"atb":[[16.5,5.28],[19,5.28],[23,4.39]],"id":37284251},{"atl":[[260,0],[160,0],[210,0]],"id":37284251},{"atb":[[32,0],[42,0],[26,5.19]],"id":42130949},{"atl":[[300,0],[350,0],[400,0]],"id":42130949},{"atb":[[4,0],[4.5,0],[5,0]],"id":38407646},{"atl":[[16,0],[18.5,0],[22,0]],"id":38407646},{"atb":[[4,0],[4.5,0],[5,12.3]],"id":43154456},{"atl":[[16,11.59],[18.5,5.8],[22,0]],"id":43154456},{"atb":[[2.06,0],[1.98,0],[2.16,0]],"id":43154457},{"atl":[[6.4,0],[5.2,0],[5.7,0]],"id":43154457},{"atb":[[2.06,0],[2.26,2],[2.16,0]],"id":36087680},{"atl":[[6.8,0],[5.9,0],[5.4,0]],"id":36087680}],"con":true,"img":false}]}
{"op":"mcm","clk":"5306787735","pt":1646106295584,"mc":[{"id":"1.195395427","rc":[{"atb":[[2.9,2]],"id":43154456}],"con":true,"img":false}]}
{"op":"mcm","clk":"5306787806","pt":1646106297694,"mc":[{"id":"1.195395427","rc":[{"atb":[[16.5,11.82],[20,5.34],[11.5,9.66],[14,7.8]],"id":37284251},{"atl":[[260,0.76],[310,0.64],[160,0.83],[210,0.63]],"id":37284251},{"atb":[[36,3.2],[18,5.96],[21,5.07],[26,9.25]],"id":42130949},{"atl":[[300,0.44],[350,0.37],[400,0.49],[450,0.44]],"id":42130949},{"atb":[[3.5,40.58],[3.75,36.89],[4,33.81],[4.7,27.42]],"id":38407646},{"atl":[[16,8.8],[18.5,7.54],[22,9.43],[27,7.62]],"id":38407646},{"atb":[[4,33.81],[3.5,40.58],[3.75,36.89],[4.7,27.42]],"id":43154456},{"atl":[[16,20.39],[18.5,13.34],[22,9.43],[27,7.62]],"id":43154456},{"atb":[[1.98,103.52],[1.88,115.29],[1.93,109.09],[2.1,92.22]],"id":43154457},{"atl":[[6.4,36.7],[7.4,30.96],[5.2,31.45],[5.7,28.11]],"id":43154457},{"atb":[[2.06,95.71],[1.98,103.52],[2.2,84.54],[1.93,109.09]],"id":36087680},{"atl":[[6.8,34.17],[7.8,29.14],[5.9,26.96],[5.4,30.03]],"id":36087680}],"con":true,"img":false}]}
{"op":"mcm","clk":"5306788229","pt":1646106311442,"mc":[{"id":"1.195395427","rc":[{"atl":[[65,0.07]],"id":37284251},{"atb":[[2.28,0]],"id":36087680}],"con":true,"img":false}]}
{"op":"mcm","clk":"5306788232","pt":1646106311496,"mc":[{"id":"1.195395427","rc":[{"atl":[[60,0.54]],"id":37284251},{"atb":[[2.22,33.81]],"id":36087680}],"con":true,"img":false}]}
{"op":"mcm","clk":"5306788493","pt":1646106320637,"mc":[{"id":"1.195395427","rc":[{"atl":[[1000,2.23]],"id":37284251}],"con":true,"img":false}]}
{"op":"mcm","clk":"5306788504","pt":1646106320847,"mc":[{"id":"1.195395427","rc":[{"atl":[[65,0]],"id":37284251}],"con":true,"img":false}]}
{"op":"mcm","clk":"5306788508","pt":1646106321047,"mc":[{"id":"1.195395427","rc":[{"atl":[[1000,0.07]],"id":37284251}],"con":true,"img":false}]}
{"op":"mcm","clk":"5306788525","pt":1646106321559,"mc":[{"id":"1.195395427","rc":[{"atl":[[1000,0]],"id":37284251}],"con":true,"img":false}]}
{"op":"mcm","clk":"5306788526","pt":1646106321615,"mc":[{"id":"1.195395427","rc":[{"atl":[[50,0.07]],"id":37284251}],"con":true,"img":false}]}
{"op":"mcm","clk":"5306788680","pt":1646106327428,"mc":[{"id":"1.195395427","rc":[{"atb":[[34,0]],"id":42130949}],"con":true,"img":false}]}
{"op":"mcm","clk":"5306788685","pt":1646106327529,"mc":[{"id":"1.195395427","rc":[{"atb":[[36,5.9]],"id":42130949}],"con":true,"img":false}]}
{"op":"mcm","clk":"5306789205","pt":1646106344173,"mc":[{"id":"1.195395427","rc":[{"atb":[[12.5,0],[14.5,7.26]],"id":37284251},{"atl":[[60,0]],"id":37284251},{"spn":41.0,"spf":66.0,"id":37284251},{"atb":[[36,3.2]],"id":42130949},{"atl":[[680,0]],"id":42130949},{"spn":39.0,"spf":1.0,"id":42130949},{"atb":[[4.6,0]],"id":38407646},{"atb":[[3.45,0],[3.8,23.31]],"id":43154456},{"atb":[[1.89,51.68],[1.74,0]],"id":43154457}],"con":true,"img":false}]}
{"op":"mcm","clk":"5306789207","pt":1646106344275,"mc":[{"id":"1.195395427","rc":[{"atl":[[65,0.54]],"id":37284251},{"atb":[[30,2.7]],"id":42130949},{"atl":[[440,2.7]],"id":42130949},{"atb":[[4.8,15.37]],"id":38407646}],"con":true,"img":false}]}
{"op":"mcm","clk":"5306790249","pt":1646106376208,"mc":[{"id":"1.195395427","rc":[{"atl":[[65,0]],"id":37284251}],"con":true,"img":false}]}
{"op":"mcm","clk":"5306790253","pt":1646106376309,"mc":[{"id":"1.195395427","rc":[{"atl":[[50,0],[60,0.54],[1000,2.23]],"id":37284251}],"con":true,"img":false}]}
{"op":"mcm","clk":"5306790261","pt":1646106376511,"mc":[{"id":"1.195395427","rc":[{"atl":[[1000,0.07]],"id":37284251}],"con":true,"img":false}]}
{"op":"mcm","clk":"5306790267","pt":1646106376715,"mc":[{"id":"1.195395427","rc":[{"atl":[[1000,0]],"id":37284251}],"con":true,"img":false}]}
{"op":"mcm","clk":"5306790270","pt":1646106376818,"mc":[{"id":"1.195395427","rc":[{"atl":[[65,0.07]],"id":37284251}],"con":true,"img":false}]}
{"op":"mcm","clk":"5306790765","pt":1646106392410,"mc":[{"id":"1.195395427","rc":[{"atb":[[30,0]],"id":42130949}],"con":true,"img":false}]}
{"op":"mcm","clk":"5306790771","pt":1646106392511,"mc":[{"id":"1.195395427","rc":[{"atb":[[32,2.7]],"id":42130949}],"con":true,"img":false}]}
{"op":"mcm","clk":"5306791203","pt":1646106408543,"mc":[{"id":"1.195395427","rc":[{"atl":[[60,0]],"id":37284251},{"spn":43.5,"spf":66.0,"id":37284251}],"con":true,"img":false}]}
{"op":"mcm","clk":"5306791207","pt":1646106408643,"mc":[{"id":"1.195395427","rc":[{"atl":[[65,0.62]],"id":37284251}],"con":true,"img":false}]}
{"op":"mcm","clk":"5306792079","pt":1646106440801,"mc":[{"id":"1.195395427","rc":[{"atl":[[65,0.07],[1000,2.23]],"id":37284251},{"atb":[[32,0]],"id":42130949}],"con":true,"img":false}]}
{"op":"mcm","clk":"5306792081","pt":1646106440903,"mc":[{"id":"1.195395427","rc":[{"atl":[[65,0],[60,0.54]],"id":37284251},{"atb":[[34,2.7]],"id":42130949}],"con":true,"img":false}]}
{"op":"mcm","clk":"5306792084","pt":1646106441005,"mc":[{"id":"1.195395427","rc":[{"atl":[[1000,0.07]],"id":37284251}],"con":true,"img":false}]}
{"op":"mcm","clk":"5306792088","pt":1646106441209,"mc":[{"id":"1.195395427","rc":[{"atl":[[1000,0]],"id":37284251}],"con":true,"img":false}]}
{"op":"mcm","clk":"5306792092","pt":1646106441261,"mc":[{"id":"1.195395427","rc":[{"atl":[[50,0.07]],"id":37284251}],"con":true,"img":false}]}
{"op":"mcm","clk":"5306793100","pt":1646106472441,"mc":[{"id":"1.195395427","rc":[{"spn":41.0,"spf":66.0,"id":37284251},{"atb":[[2.74,32.46]],"id":36087680},{"spn":2.73,"spf":1.61,"id":36087680}],"con":true,"img":false}]}
{"op":"mcm","clk":"5306793110","pt":1646106472838,"mc":[{"id":"1.195395427","rc":[{"atl":[[60,0]],"id":37284251}],"con":true,"img":false}]}
{"op":"mcm","clk":"5306793116","pt":1646106472939,"mc":[{"id":"1.195395427","rc":[{"atl":[[65,0.54],[1000,2.23]],"id":37284251}],"con":true,"img":false}]}
{"op":"mcm","clk":"5306793120","pt":1646106473042,"mc":[{"id":"1.195395427","rc":[{"atl":[[50,0]],"id":37284251}],"con":true,"img":false}]}
{"op":"mcm","clk":"5306793123","pt":1646106473144,"mc":[{"id":"1.195395427","rc":[{"atl":[[1000,0.07]],"id":37284251}],"con":true,"img":false}]}
{"op":"mcm","clk":"5306793130","pt":1646106473347,"mc":[{"id":"1.195395427","rc":[{"atl":[[1000,0]],"id":37284251}],"con":true,"img":false}]}
{"op":"mcm","clk":"5306793132","pt":1646106473449,"mc":[{"id":"1.195395427","rc":[{"atl":[[65,0.62]],"id":37284251}],"con":true,"img":false}]}
{"op":"mcm","clk":"5306793608","pt":1646106487870,"mc":[{"id":"1.195395427","rc":[{"atb":[[34,0]],"id":42130949}],"con":true,"img":false}]}
{"op":"mcm","clk":"5306793613","pt":1646106487973,"mc":[{"id":"1.195395427","rc":[{"atb":[[36,5.9]],"id":42130949}],"con":true,"img":false}]}
{"op":"mcm","clk":"5306794309","pt":1646106504087,"mc":[{"id":"1.195395427","rc":[{"atl":[[65,0.07]],"id":37284251},{"atb":[[36,3.2]],"id":42130949}],"con":true,"img":false}]}
{"op":"mcm","clk":"5306794313","pt":1646106504188,"mc":[{"id":"1.195395427","rc":[{"atl":[[60,0.54]],"id":37284251},{"atb":[[30,2.7]],"id":42130949}],"con":true,"img":false}]}
{"op":"mcm","clk":"5306794636","pt":1646106512374,"mc":[{"id":"1.195395427","rc":[{"atb":[[2.76,3.87]],"id":36087680}],"con":true,"img":false}]}
{"op":"mcm","clk":"5306795575","pt":1646106539137,"mc":[{"id":"1.195395427","rc":[{"atl":[[60,0]],"id":37284251},{"spn":43.5,"spf":66.0,"id":37284251},{"spn":2.74,"spf":1.61,"id":36087680}],"con":true,"img":false}]}
{"op":"mcm","clk":"5306795579","pt":1646106539238,"mc":[{"id":"1.195395427","rc":[{"atl":[[65,0.62]],"id":37284251}],"con":true,"img":false}]}
{"op":"mcm","clk":"5306796051","pt":1646106554051,"mc":[{"id":"1.195395427","rc":[{"atb":[[30,0]],"id":42130949}],"con":true,"img":false}]}
{"op":"mcm","clk":"5306796054","pt":1646106554154,"mc":[{"id":"1.195395427","rc":[{"atb":[[32,2.7]],"id":42130949}],"con":true,"img":false}]}
{"op":"mcm","clk":"5306796264","pt":1646106561056,"mc":[{"id":"1.195395427","rc":[{"atl":[[65,0.54]],"id":37284251}],"con":true,"img":false}]}
{"op":"mcm","clk":"5306796274","pt":1646106561257,"mc":[{"id":"1.195395427","rc":[{"atl":[[1000,2.23]],"id":37284251}],"con":true,"img":false}]}
{"op":"mcm","clk":"5306796293","pt":1646106561769,"mc":[{"id":"1.195395427","rc":[{"atl":[[1000,0.07]],"id":37284251}],"con":true,"img":false}]}
{"op":"mcm","clk":"5306796310","pt":1646106562279,"mc":[{"id":"1.195395427","rc":[{"atl":[[1000,0]],"id":37284251}],"con":true,"img":false}]}
{"op":"mcm","clk":"5306796313","pt":1646106562381,"mc":[{"id":"1.195395427","rc":[{"atl":[[50,0.07]],"id":37284251}],"con":true,"img":false}]}
{"op":"mcm","clk":"5306796456","pt":1646106569167,"mc":[{"id":"1.195395427","rc":[{"atl":[[65,0]],"id":37284251}],"con":true,"img":false}]}
{"op":"mcm","clk":"5306796460","pt":1646106569270,"mc":[{"id":"1.195395427","rc":[{"atl":[[60,0.54]],"id":37284251}],"con":true,"img":false}]}
{"op":"mcm","clk":"5306797241","pt":1646106603397,"mc":[{"id":"1.195395427","rc":[{"atl":[[60,0]],"id":37284251},{"spn":41.0,"spf":66.0,"id":37284251},{"atb":[[32,0]],"id":42130949}],"con":true,"img":false}]}
{"op":"mcm","clk":"5306797243","pt":1646106603499,"mc":[{"id":"1.195395427","rc":[{"atl":[[65,0.54],[50,0],[1000,2.23]],"id":37284251},{"atb":[[34,2.7]],"id":42130949}],"con":true,"img":false}]}
{"op":"mcm","clk":"5306797249","pt":1646106603704,"mc":[{"id":"1.195395427","rc":[{"atl":[[1000,0.07]],"id":37284251}],"con":true,"img":false}]}
{"op":"mcm","clk":"5306797256","pt":1646106603911,"mc":[{"id":"1.195395427","rc":[{"atl":[[1000,0]],"id":37284251}],"con":true,"img":false}]}
{"op":"mcm","clk":"5306797258","pt":1646106604009,"mc":[{"id":"1.195395427","rc":[{"atl":[[65,0.62]],"id":37284251}],"con":true,"img":false}]}
{"op":"mcm","clk":"5306797772","pt":1646106621846,"mc":[{"id":"1.195395427","rc":[{"atl":[[65,0.07]],"id":37284251}],"con":true,"img":false}]}
{"op":"mcm","clk":"5306797776","pt":1646106621946,"mc":[{"id":"1.195395427","rc":[{"atl":[[60,0.54]],"id":37284251}],"con":true,"img":false}]}
{"op":"mcm","clk":"5306798705","pt":1646106651782,"mc":[{"id":"1.195395427","rc":[{"atl":[[60,0]],"id":37284251},{"atb":[[34,0]],"id":42130949}],"con":true,"img":false}]}
