{"op":"mcm","clk":"5345904400","pt":1646079078743,"mc":[{"id":"1.195395444","marketDefinition":{"bspMarket":false,"turnInPlayEnabled":false,"persistenceEnabled":false,"marketBaseRate":5.0,"eventId":"31270459","eventTypeId":"4339","numberOfWinners":2,"bettingType":"ODDS","marketType":"PLACE","marketTime":"2022-03-01T00:12:00.000Z","suspendTime":"2022-03-01T00:12:00.000Z","bspReconciled":false,"complete":true,"inPlay":false,"crossMatching":false,"runnersVoidable":false,"numberOfActiveRunners":7,"betDelay":0,"status":"OPEN","runners":[{"status":"ACTIVE","sortPriority":1,"id":42236670,"name":"1. Nighthawk Storm"},{"status":"ACTIVE","sortPriority":2,"id":40917095,"name":"2. Goldstar Vale"},{"status":"ACTIVE","sortPriority":3,"id":42189436,"name":"3. Going Gorillas"},{"status":"ACTIVE","sortPriority":4,"id":41523279,"name":"4. Homebush Cardi"},{"status":"ACTIVE","sortPriority":5,"id":37174579,"name":"6. Yes Yes No"},{"status":"ACTIVE","sortPriority":6,"id":42070475,"name":"7. Breakpoint"},{"status":"ACTIVE","sortPriority":7,"id":42236682,"name":"8. Goldstar Brynley"}],"regulators":["MR_INT"],"venue":"Addington","countryCode":"NZ","discountAllowed":false,"timezone":"NZ","openDate":"2022-02-28T23:02:00.000Z","version":4380660695,"name":"To Be Placed","eventName":"Addington (NZL) 1st Mar"},"rc":[],"con":true,"img":false}]}
{"op":"mcm","clk":"5345904628","pt":1646079080740,"mc":[{"id":"1.195395444","marketDefinition":{"bspMarket":false,"turnInPlayEnabled":false,"persistenceEnabled":false,"marketBaseRate":5.0,"eventId":"31270459","eventTypeId":"4339","numberOfWinners":2,"bettingType":"ODDS","marketType":"PLACE","marketTime":"2022-03-01T00:12:00.000Z","suspendTime":"2022-03-01T00:12:00.000Z","bspReconciled":false,"complete":true,"inPlay":false,"crossMatching":false,"runnersVoidable":false,"numberOfActiveRunners":7,"betDelay":0,"status":"OPEN","runners":[{"status":"ACTIVE","sortPriority":1,"id":42236670,"name":"1. Nighthawk Storm"},{"status":"ACTIVE","sortPriority":2,"id":40917095,"name":"2. Goldstar Vale"},{"status":"ACTIVE","sortPriority":3,"id":42189436,"name":"3. Going Gorillas"},{"status":"ACTIVE","sortPriority":4,"id":41523279,"name":"4. Homebush Cardi"},{"status":"ACTIVE","sortPriority":5,"id":37174579,"name":"6. Yes Yes No"},{"status":"ACTIVE","sortPriority":6,"id":42070475,"name":"7. Breakpoint"},{"status":"ACTIVE","sortPriority":7,"id":42236682,"name":"8. Goldstar Brynley"}],"regulators":["MR_INT"],"venue":"Addington","countryCode":"NZ","discountAllowed":true,"timezone":"NZ","openDate":"2022-02-28T23:02:00.000Z","version":4380660695,"name":"To Be Placed","eventName":"Addington (NZL) 1st Mar"},"rc":[],"con":true,"img":false}]}
{"op":"mcm","clk":"5346126555","pt":1646081524658,"mc":[{"id":"1.195395444","rc":[{"atb":[[2.82,66.02],[2.92,62.59],[3.05,29.31]],"id":40917095},{"atl":[[32,1.54],[10.5,1.26],[21,1.2],[8.2,1.66],[15.5,1.65]],"id":40917095},{"atb":[[2.82,66.02],[2.92,62.59],[3.05,29.31]],"id":42189436},{"atl":[[32,1.54],[10.5,1.26],[21,1.2],[8.2,1.66],[15.5,1.65]],"id":42189436},{"atb":[[2.4,85.83],[2.5,80.11],[2.6,37.55]],"id":42236670},{"atl":[[6.2,2.31],[10.5,2.52],[21,2.4],[8.2,1.66],[15.5,1.65]],"id":42236670},{"atb":[[1.8,75.1],[1.7,171.66],[1.75,160.22]],"id":42070475},{"atl":[[3.6,4.62],[6.4,4.44],[5.2,5.72],[4.2,3.75],[8.4,6.49]],"id":42070475},{"atb":[[1.8,150.21],[1.85,141.37],[1.9,66.75]],"id":41523279},{"atl":[[4,4],[8,3.43],[5,3],[10,5.34],[6,4.8]],"id":41523279},{"atb":[[2,60.08],[1.9,133.52],[1.95,126.49]],"id":42236682},{"atl":[[5.1,2.92],[6.2,2.31],[10.5,2.52],[8.2,3.33],[15.5,3.31]],"id":42236682},{"atb":[[2.5,80.11],[2.6,75.1],[2.7,35.34]],"id":37174579},{"atl":[[16.5,1.54],[8.6,1.58],[11.5,2.28],[23,2.18],[6.6,2.14]],"id":37174579}],"con":true,"img":false}]}
{"op":"mcm","clk":"5346128127","pt":1646081544296,"mc":[{"id":"1.195395444","rc":[{"atb":[[2.82,0],[2.92,0],[3.05,0]],"id":40917095},{"atl":[[32,0],[10.5,0],[21,0],[8.2,0],[15.5,0]],"id":40917095},{"atb":[[2.82,0],[2.92,0],[3.05,0]],"id":42189436},{"atl":[[32,0],[10.5,0],[21,0],[8.2,0],[15.5,0]],"id":42189436},{"atb":[[2.4,0],[2.5,0],[2.6,0]],"id":42236670},{"atl":[[6.2,0],[10.5,0],[21,0],[8.2,0],[15.5,0]],"id":42236670},{"atb":[[1.8,0],[1.7,0],[1.75,0]],"id":42070475},{"atl":[[3.6,0],[6.4,0],[5.2,0],[4.2,0],[8.4,0]],"id":42070475},{"atb":[[1.8,0],[1.85,0],[1.9,0]],"id":41523279},{"atl":[[4,0],[8,0],[5,0],[10,0],[6,0]],"id":41523279},{"atb":[[2,0],[1.9,0],[1.95,0]],"id":42236682},{"atl":[[5.1,0],[6.2,0],[10.5,0],[8.2,0],[15.5,0]],"id":42236682},{"atb":[[2.5,0],[2.6,0],[2.7,0]],"id":37174579},{"atl":[[16.5,0],[8.6,0],[11.5,0],[23,0],[6.6,0]],"id":37174579}],"con":true,"img":false}]}
{"op":"mcm","clk":"5346129273","pt":1646081558930,"mc":[{"id":"1.195395444","rc":[{"atb":[[2.82,66.02],[2.92,62.59],[3.05,29.31]],"id":40917095},{"atl":[[32,1.54],[10.5,1.26],[21,1.2],[8.2,1.66],[15.5,1.65]],"id":40917095},{"atb":[[2.82,66.02],[2.92,62.59],[3.05,29.31]],"id":42189436},{"atl":[[32,1.54],[10.5,1.26],[21,1.2],[8.2,1.66],[15.5,1.65]],"id":42189436},{"atb":[[2.4,85.83],[2.5,80.11],[2.6,37.55]],"id":42236670},{"atl":[[6.2,2.31],[10.5,2.52],[21,2.4],[8.2,1.66],[15.5,1.65]],"id":42236670},{"atb":[[1.8,75.1],[1.7,171.66],[1.75,160.22]],"id":42070475},{"atl":[[3.6,4.62],[6.4,4.44],[5.2,5.72],[4.2,3.75],[8.4,6.49]],"id":42070475},{"atb":[[1.8,150.21],[1.85,141.37],[1.9,66.75]],"id":41523279},{"atl":[[4,4],[8,3.43],[5,3],[10,5.34],[6,4.8]],"id":41523279},{"atb":[[2,60.08],[1.9,133.52],[1.95,126.49]],"id":42236682},{"atl":[[5.1,2.92],[6.2,2.31],[10.5,2.52],[8.2,3.33],[15.5,3.31]],"id":42236682},{"atb":[[2.5,80.11],[2.6,75.1],[2.7,35.34]],"id":37174579},{"atl":[[16.5,1.54],[8.6,1.58],[11.5,2.28],[23,2.18],[6.6,2.14]],"id":37174579}],"con":true,"img":false}]}
{"op":"mcm","clk":"5346130620","pt":1646081576614,"mc":[{"id":"1.195395444","rc":[{"atb":[[2.82,0],[2.92,0],[3.05,0]],"id":40917095},{"atl":[[32,0],[10.5,0],[21,0],[8.2,0],[15.5,0]],"id":40917095},{"atb":[[2.82,0],[2.92,0],[3.05,0]],"id":42189436},{"atl":[[32,0],[10.5,0],[21,0],[8.2,0],[15.5,0]],"id":42189436},{"atb":[[2.4,0],[2.5,0],[2.6,0]],"id":42236670},{"atl":[[6.2,0],[10.5,0],[21,0],[8.2,0],[15.5,0]],"id":42236670},{"atb":[[1.8,0],[1.7,0],[1.75,0]],"id":42070475},{"atl":[[3.6,0],[6.4,0],[5.2,0],[4.2,0],[8.4,0]],"id":42070475},{"atb":[[1.8,0],[1.85,0],[1.9,0]],"id":41523279},{"atl":[[4,0],[8,0],[5,0],[10,0],[6,0]],"id":41523279},{"atb":[[2,0],[1.9,0],[1.95,0]],"id":42236682},{"atl":[[5.1,0],[6.2,0],[10.5,0],[8.2,0],[15.5,0]],"id":42236682},{"atb":[[2.5,0],[2.6,0],[2.7,0]],"id":37174579},{"atl":[[16.5,0],[8.6,0],[11.5,0],[23,0],[6.6,0]],"id":37174579}],"con":true,"img":false}]}
{"op":"mcm","clk":"5346131645","pt":1646081590850,"mc":[{"id":"1.195395444","rc":[{"atb":[[2.82,66.02],[2.92,62.59],[3.05,29.31]],"id":40917095},{"atl":[[32,1.54],[10.5,1.26],[21,1.2],[8.2,1.66],[15.5,1.65]],"id":40917095},{"atb":[[2.82,66.02],[2.92,62.59],[3.05,29.31]],"id":42189436},{"atl":[[32,1.54],[10.5,1.26],[21,1.2],[8.2,1.66],[15.5,1.65]],"id":42189436},{"atb":[[2.4,85.83],[2.5,80.11],[2.6,37.55]],"id":42236670},{"atl":[[6.2,2.31],[10.5,2.52],[21,2.4],[8.2,1.66],[15.5,1.65]],"id":42236670},{"atb":[[1.8,75.1],[1.7,171.66],[1.75,160.22]],"id":42070475},{"atl":[[3.6,4.62],[6.4,4.44],[5.2,5.72],[4.2,3.75],[8.4,6.49]],"id":42070475},{"atb":[[1.8,150.21],[1.85,141.37],[1.9,66.75]],"id":41523279},{"atl":[[4,4],[8,3.43],[5,3],[10,5.34],[6,4.8]],"id":41523279},{"atb":[[2,60.08],[1.9,133.52],[1.95,126.49]],"id":42236682},{"atl":[[5.1,2.92],[6.2,2.31],[10.5,2.52],[8.2,3.33],[15.5,3.31]],"id":42236682},{"atb":[[2.5,80.11],[2.6,75.1],[2.7,35.34]],"id":37174579},{"atl":[[16.5,1.54],[8.6,1.58],[11.5,2.28],[23,2.18],[6.6,2.14]],"id":37174579}],"con":true,"img":false}]}
{"op":"mcm","clk":"5346132643","pt":1646081604847,"mc":[{"id":"1.195395444","rc":[{"atb":[[2.82,0],[2.92,0],[3.05,0]],"id":40917095},{"atl":[[32,0],[10.5,0],[21,0],[8.2,0],[15.5,0]],"id":40917095},{"atb":[[2.82,0],[2.92,0],[3.05,0]],"id":42189436},{"atl":[[32,0],[10.5,0],[21,0],[8.2,0],[15.5,0]],"id":42189436},{"atb":[[2.4,0],[2.5,0],[2.6,0]],"id":42236670},{"atl":[[6.2,0],[10.5,0],[21,0],[8.2,0],[15.5,0]],"id":42236670},{"atb":[[1.8,0],[1.7,0],[1.75,0]],"id":42070475},{"atl":[[3.6,0],[6.4,0],[5.2,0],[4.2,0],[8.4,0]],"id":42070475},{"atb":[[1.8,0],[1.85,0],[1.9,0]],"id":41523279},{"atl":[[4,0],[8,0],[5,0],[10,0],[6,0]],"id":41523279},{"atb":[[2,0],[1.9,0],[1.95,0]],"id":42236682},{"atl":[[5.1,0],[6.2,0],[10.5,0],[8.2,0],[15.5,0]],"id":42236682},{"atb":[[2.5,0],[2.6,0],[2.7,0]],"id":37174579},{"atl":[[16.5,0],[8.6,0],[11.5,0],[23,0],[6.6,0]],"id":37174579}],"con":true,"img":false}]}
{"op":"mcm","clk":"5346133741","pt":1646081621322,"mc":[{"id":"1.195395444","rc":[{"atb":[[2.82,66.02],[2.92,62.59],[3.05,29.31]],"id":40917095},{"atl":[[32,1.54],[10.5,1.26],[21,1.2],[8.2,1.66],[15.5,1.65]],"id":40917095},{"atb":[[2.82,66.02],[2.92,62.59],[3.05,29.31]],"id":42189436},{"atl":[[32,1.54],[10.5,1.26],[21,1.2],[8.2,1.66],[15.5,1.65]],"id":42189436},{"atb":[[2.4,85.83],[2.5,80.11],[2.6,37.55]],"id":42236670},{"atl":[[6.2,2.31],[10.5,2.52],[21,2.4],[8.2,1.66],[15.5,1.65]],"id":42236670},{"atb":[[1.8,75.1],[1.7,171.66],[1.75,160.22]],"id":42070475},{"atl":[[3.6,4.62],[6.4,4.44],[5.2,5.72],[4.2,3.75],[8.4,6.49]],"id":42070475},{"atb":[[1.8,150.21],[1.85,141.37],[1.9,66.75]],"id":41523279},{"atl":[[4,4],[8,3.43],[5,3],[10,5.34],[6,4.8]],"id":41523279},{"atb":[[2,60.08],[1.9,133.52],[1.95,126.49]],"id":42236682},{"atl":[[5.1,2.92],[6.2,2.31],[10.5,2.52],[8.2,3.33],[15.5,3.31]],"id":42236682},{"atb":[[2.5,80.11],[2.6,75.1],[2.7,35.34]],"id":37174579},{"atl":[[16.5,1.54],[8.6,1.58],[11.5,2.28],[23,2.18],[6.6,2.14]],"id":37174579}],"con":true,"img":false}]}
{"op":"mcm","clk":"5346134763","pt":1646081637180,"mc":[{"id":"1.195395444","rc":[{"atb":[[2.82,0],[2.92,0],[3.05,0]],"id":40917095},{"atl":[[32,0],[10.5,0],[21,0],[8.2,0],[15.5,0]],"id":40917095},{"atb":[[2.82,0],[2.92,0],[3.05,0]],"id":42189436},{"atl":[[32,0],[10.5,0],[21,0],[8.2,0],[15.5,0]],"id":42189436},{"atb":[[2.4,0],[2.5,0],[2.6,0]],"id":42236670},{"atl":[[6.2,0],[10.5,0],[21,0],[8.2,0],[15.5,0]],"id":42236670},{"atb":[[1.8,0],[1.7,0],[1.75,0]],"id":42070475},{"atl":[[3.6,0],[6.4,0],[5.2,0],[4.2,0],[8.4,0]],"id":42070475},{"atb":[[1.8,0],[1.85,0],[1.9,0]],"id":41523279},{"atl":[[4,0],[8,0],[5,0],[10,0],[6,0]],"id":41523279},{"atb":[[2,0],[1.9,0],[1.95,0]],"id":42236682},{"atl":[[5.1,0],[6.2,0],[10.5,0],[8.2,0],[15.5,0]],"id":42236682},{"atb":[[2.5,0],[2.6,0],[2.7,0]],"id":37174579},{"atl":[[16.5,0],[8.6,0],[11.5,0],[23,0],[6.6,0]],"id":37174579}],"con":true,"img":false}]}
{"op":"mcm","clk":"5346135981","pt":1646081656756,"mc":[{"id":"1.195395444","rc":[{"atb":[[2.82,66.02],[2.92,62.59],[3.05,29.31]],"id":40917095},{"atl":[[32,1.54],[10.5,1.26],[21,1.2],[8.2,1.66],[15.5,1.65]],"id":40917095},{"atb":[[2.82,66.02],[2.92,62.59],[3.05,29.31]],"id":42189436},{"atl":[[32,1.54],[10.5,1.26],[21,1.2],[8.2,1.66],[15.5,1.65]],"id":42189436},{"atb":[[2.4,85.83],[2.5,80.11],[2.6,37.55]],"id":42236670},{"atl":[[6.2,2.31],[10.5,2.52],[21,2.4],[8.2,1.66],[15.5,1.65]],"id":42236670},{"atb":[[1.8,75.1],[1.7,171.66],[1.75,160.22]],"id":42070475},{"atl":[[3.6,4.62],[6.4,4.44],[5.2,5.72],[4.2,3.75],[8.4,6.49]],"id":42070475},{"atb":[[1.8,150.21],[1.85,141.37],[1.9,66.75]],"id":41523279},{"atl":[[4,4],[8,3.43],[5,3],[10,5.34],[6,4.8]],"id":41523279},{"atb":[[2,60.08],[1.9,133.52],[1.95,126.49]],"id":42236682},{"atl":[[5.1,2.92],[6.2,2.31],[10.5,2.52],[8.2,3.33],[15.5,3.31]],"id":42236682},{"atb":[[2.5,80.11],[2.6,75.1],[2.7,35.34]],"id":37174579},{"atl":[[16.5,1.54],[8.6,1.58],[11.5,2.28],[23,2.18],[6.6,2.14]],"id":37174579}],"con":true,"img":false}]}
{"op":"mcm","clk":"5346138665","pt":1646081695074,"mc":[{"id":"1.195395444","rc":[{"atb":[[2.82,0],[2.92,0],[3.05,0]],"id":40917095},{"atl":[[32,0],[10.5,0],[21,0],[8.2,0],[15.5,0]],"id":40917095},{"atb":[[2.82,0],[2.92,0],[3.05,0]],"id":42189436},{"atl":[[32,0],[10.5,0],[21,0],[8.2,0],[15.5,0]],"id":42189436},{"atb":[[2.4,0],[2.5,0],[2.6,0]],"id":42236670},{"atl":[[6.2,0],[10.5,0],[21,0],[8.2,0],[15.5,0]],"id":42236670},{"atb":[[1.8,0],[1.7,0],[1.75,0]],"id":42070475},{"atl":[[3.6,0],[6.4,0],[5.2,0],[4.2,0],[8.4,0]],"id":42070475},{"atb":[[1.8,0],[1.85,0],[1.9,0]],"id":41523279},{"atl":[[4,0],[8,0],[5,0],[10,0],[6,0]],"id":41523279},{"atb":[[2,0],[1.9,0],[1.95,0]],"id":42236682},{"atl":[[5.1,0],[6.2,0],[10.5,0],[8.2,0],[15.5,0]],"id":42236682},{"atb":[[2.5,0],[2.6,0],[2.7,0]],"id":37174579},{"atl":[[16.5,0],[8.6,0],[11.5,0],[23,0],[6.6,0]],"id":37174579}],"con":true,"img":false}]}
{"op":"mcm","clk":"5346140304","pt":1646081718873,"mc":[{"id":"1.195395444","rc":[{"atb":[[2.82,66.02],[2.92,62.59],[3.05,29.31]],"id":40917095},{"atl":[[32,1.54],[10.5,1.26],[21,1.2],[8.2,1.66],[15.5,1.65]],"id":40917095},{"atb":[[2.82,66.02],[2.92,62.59],[3.05,29.31]],"id":42189436},{"atl":[[32,1.54],[10.5,1.26],[21,1.2],[8.2,1.66],[15.5,1.65]],"id":42189436},{"atb":[[2.4,85.83],[2.5,80.11],[2.6,37.55]],"id":42236670},{"atl":[[6.2,2.31],[10.5,2.52],[21,2.4],[8.2,1.66],[15.5,1.65]],"id":42236670},{"atb":[[1.8,75.1],[1.7,171.66],[1.75,160.22]],"id":42070475},{"atl":[[3.6,4.62],[6.4,4.44],[5.2,5.72],[4.2,3.75],[8.4,6.49]],"id":42070475},{"atb":[[1.8,150.21],[1.85,141.37],[1.9,66.75]],"id":41523279},{"atl":[[4,4],[8,3.43],[5,3],[10,5.34],[6,4.8]],"id":41523279},{"atb":[[2,60.08],[1.9,133.52],[1.95,126.49]],"id":42236682},{"atl":[[5.1,2.92],[6.2,2.31],[10.5,2.52],[8.2,3.33],[15.5,3.31]],"id":42236682},{"atb":[[2.5,80.11],[2.6,75.1],[2.7,35.34]],"id":37174579},{"atl":[[16.5,1.54],[8.6,1.58],[11.5,2.28],[23,2.18],[6.6,2.14]],"id":37174579}],"con":true,"img":false}]}
{"op":"mcm","clk":"5346183390","pt":1646082292654,"mc":[{"id":"1.195395444","rc":[{"atb":[[2.82,0],[2.92,0],[3.05,0]],"id":40917095},{"atl":[[32,0],[10.5,0],[21,0],[8.2,0],[15.5,0]],"id":40917095},{"atb":[[2.82,0],[2.92,0],[3.05,0]],"id":42189436},{"atl":[[32,0],[10.5,0],[21,0],[8.2,0],[15.5,0]],"id":42189436},{"atb":[[2,0],[1.9,0],[1.95,0]],"id":42236682},{"atl":[[5.1,0],[6.2,0],[10.5,0],[8.2,0],[15.5,0]],"id":42236682}],"con":true,"img":false}]}
{"op":"mcm","clk":"5346184036","pt":1646082300481,"mc":[{"id":"1.195395444","rc":[{"atb":[[3.45,24.52],[3.2,54.62],[2.98,60.69]],"id":40917095},{"atl":[[18.5,1.37],[44,1.12],[13.5,0.96],[27,0.92],[9.4,1.42]],"id":40917095},{"atb":[[3.45,24.52],[3.2,54.62],[2.98,60.69]],"id":42189436},{"atl":[[18.5,1.37],[44,1.12],[13.5,0.96],[27,0.92],[9.4,1.42]],"id":42189436},{"atb":[[1.8,150.21],[1.85,141.37],[1.9,66.75]],"id":42236682},{"atl":[[4,4],[8,3.43],[5,3],[10,5.34],[6,4.8]],"id":42236682}],"con":true,"img":false}]}
{"op":"mcm","clk":"5346223513","pt":1646082745058,"mc":[{"id":"1.195395444","rc":[{"atb":[[3.45,0],[3.2,0],[2.98,0]],"id":40917095},{"atl":[[18.5,0],[44,0],[13.5,0],[27,0],[9.4,0]],"id":40917095},{"atb":[[3.45,0],[3.2,0],[2.98,0]],"id":42189436},{"atl":[[18.5,0],[44,0],[13.5,0],[27,0],[9.4,0]],"id":42189436},{"atb":[[2.4,0],[2.5,0],[2.6,0]],"id":42236670},{"atl":[[6.2,0],[10.5,0],[21,0],[8.2,0],[15.5,0]],"id":42236670},{"atb":[[1.8,0],[1.7,0],[1.75,0]],"id":42070475},{"atl":[[3.6,0],[6.4,0],[5.2,0],[4.2,0],[8.4,0]],"id":42070475},{"atb":[[1.8,0],[1.85,0],[1.9,0]],"id":41523279},{"atl":[[4,0],[8,0],[5,0],[10,0],[6,0]],"id":41523279},{"atb":[[1.8,0],[1.85,0],[1.9,0]],"id":42236682},{"atl":[[4,0],[8,0],[5,0],[10,0],[6,0]],"id":42236682},{"atb":[[2.5,0],[2.6,0],[2.7,0]],"id":37174579},{"atl":[[16.5,0],[8.6,0],[11.5,0],[23,0],[6.6,0]],"id":37174579}],"con":true,"img":false}]}
{"op":"mcm","clk":"5346225933","pt":1646082773230,"mc":[{"id":"1.195395444","rc":[{"atb":[[3.45,24.52],[3.2,54.62],[2.98,60.69]],"id":40917095},{"atl":[[18.5,1.37],[44,1.12],[13.5,0.96],[27,0.92],[9.4,1.42]],"id":40917095},{"atb":[[3.45,24.52],[3.2,54.62],[2.98,60.69]],"id":42189436},{"atl":[[18.5,1.37],[44,1.12],[13.5,0.96],[27,0.92],[9.4,1.42]],"id":42189436},{"atb":[[2.5,80.11],[2.6,75.1],[2.7,35.34]],"id":42236670},{"atl":[[16.5,1.54],[8.6,1.58],[11.5,2.28],[23,2.18],[6.6,2.14]],"id":42236670},{"atb":[[1.8,75.1],[1.7,171.66],[1.75,160.22]],"id":42070475},{"atl":[[3.6,4.62],[6.4,4.44],[5.2,5.72],[4.2,3.75],[8.4,6.49]],"id":42070475},{"atb":[[1.85,141.37],[1.9,133.52],[1.95,63.24]],"id":41523279},{"atl":[[5.6,2.61],[7.2,3.87],[4.6,3.33],[9.2,2.92],[13,4]],"id":41523279},{"atb":[[1.85,141.37],[1.9,133.52],[1.95,63.24]],"id":42236682},{"atl":[[5.6,2.61],[7.2,3.87],[4.6,3.33],[9.2,2.92],[13,4]],"id":42236682},{"atb":[[2.8,66.75],[2.9,31.62],[2.7,70.68]],"id":37174579},{"atl":[[19.5,1.29],[9.8,1.36],[7.8,1.76],[14.5,1.78],[29,1.71]],"id":37174579}],"con":true,"img":false}]}
{"op":"mcm","clk":"5346439475","pt":1646086403641,"mc":[{"id":"1.195395444","rc":[{"atb":[[3.45,24.52],[3.2,54.61],[2.98,60.68]],"id":40917095},{"atl":[[18.5,1.37],[44,1.12],[13.5,0.96],[27,0.92],[9.4,1.42]],"id":40917095},{"atb":[[3.45,24.52],[3.2,54.61],[2.98,60.68]],"id":42189436},{"atl":[[18.5,1.37],[44,1.12],[13.5,0.96],[27,0.92],[9.4,1.42]],"id":42189436},{"atb":[[2.5,80.09],[2.6,75.09],[2.7,35.33]],"id":42236670},{"atl":[[16.5,1.54],[8.6,1.58],[11.5,2.28],[23,2.18],[6.6,2.14]],"id":42236670},{"atb":[[1.8,75.09],[1.7,171.64],[1.75,160.19]],"id":42070475},{"atl":[[3.6,4.62],[6.4,4.44],[5.2,5.72],[4.2,3.75],[8.4,6.49]],"id":42070475},{"atb":[[1.85,141.35],[1.9,133.5],[1.95,63.23]],"id":41523279},{"atl":[[5.6,2.61],[7.2,3.87],[4.6,3.33],[9.2,2.92],[13,4]],"id":41523279},{"atb":[[1.85,0],[1.9,0],[1.95,0]],"id":42236682},{"atl":[[5.6,0],[7.2,0],[4.6,0],[9.2,0],[13,0]],"id":42236682},{"atb":[[2.8,66.74],[2.9,31.61],[2.7,70.67]],"id":37174579},{"atl":[[19.5,1.29],[9.8,1.36],[7.8,1.76],[14.5,1.78],[29,1.71]],"id":37174579}],"con":true,"img":false}]}
{"op":"mcm","clk":"5346439698","pt":1646086408536,"mc":[{"id":"1.195395444","rc":[{"atb":[[1.8,150.18],[1.85,141.35],[1.9,66.74]],"id":42236682},{"atl":[[4,4],[8,3.43],[5,3],[10,5.34],[6,4.8]],"id":42236682}],"con":true,"img":false}]}
{"op":"mcm","clk":"5346443271","pt":1646086494548,"mc":[{"id":"1.195395444","rc":[{"atb":[[3.45,0],[3.2,0],[2.98,0]],"id":40917095},{"atl":[[18.5,0],[44,0],[13.5,0],[27,0],[9.4,0]],"id":40917095},{"atb":[[1.8,0],[1.7,0],[1.75,0]],"id":42070475},{"atl":[[3.6,0],[6.4,0],[5.2,0],[4.2,0],[8.4,0]],"id":42070475}],"con":true,"img":false}]}
{"op":"mcm","clk":"5346443489","pt":1646086499142,"mc":[{"id":"1.195395444","rc":[{"atb":[[3.55,23.55],[3.3,52.23],[3.05,58.6]],"id":40917095},{"atl":[[19.5,1.29],[48,1.02],[9.8,1.36],[14.5,0.88],[29,0.86]],"id":40917095},{"atb":[[1.8,75.09],[1.7,171.64],[1.75,160.19]],"id":42070475},{"atl":[[3.6,4.62],[6.4,4.44],[5.2,5.72],[4.2,3.75],[8.4,6.49]],"id":42070475}],"con":true,"img":false}]}
{"op":"mcm","clk":"5346444530","pt":1646086526173,"mc":[{"id":"1.195395444","rc":[{"atb":[[3.55,0],[3.3,0],[3.05,0]],"id":40917095},{"atl":[[19.5,0],[48,0],[9.8,0],[14.5,0],[29,0]],"id":40917095},{"atb":[[1.8,0],[1.7,0],[1.75,0]],"id":42070475},{"atl":[[3.6,0],[6.4,0],[5.2,0],[4.2,0],[8.4,0]],"id":42070475}],"con":true,"img":false}]}
{"op":"mcm","clk":"5346444864","pt":1646086533010,"mc":[{"id":"1.195395444","rc":[{"atb":[[3.55,23.55],[3.3,52.23],[3.05,58.6]],"id":40917095},{"atl":[[19.5,1.29],[48,1.02],[9.8,1.36],[14.5,0.88],[29,0.86]],"id":40917095},{"atb":[[1.8,75.09],[1.7,171.64],[1.75,160.19]],"id":42070475},{"atl":[[3.6,4.62],[6.4,4.44],[5.2,5.72],[4.2,3.75],[8.4,6.49]],"id":42070475}],"con":true,"img":false}]}
{"op":"mcm","clk":"5346493103","pt":1646088279898,"mc":[{"id":"1.195395444","rc":[{"atb":[[3.1,19.32],[2.28,42.7]],"id":40917095},{"atl":[[23,2.7],[15.5,2.79]],"id":40917095},{"atb":[[3.25,27.12],[3.3,18.03]],"id":42189436},{"atl":[[18,2.38],[27,3.63]],"id":42189436},{"atb":[[1.79,68.33],[2.52,26.7]],"id":42236670},{"atl":[[10,4.5],[15,3.85]],"id":42236670},{"atb":[[1.76,40.59],[1.38,147.41]],"id":42070475},{"atl":[[4.8,10.68],[5.1,13.66]],"id":42070475},{"atb":[[1.96,40.59],[1.49,109.07]],"id":41523279},{"atl":[[6.6,7.24],[7,8.9]],"id":41523279},{"atb":[[1.43,137.81],[1.86,40.59]],"id":42236682},{"atl":[[5.9,20.38]],"id":42236682},{"atb":[[2.82,22.3],[1.96,55.95]],"id":37174579},{"atl":[[18,3.16],[12,3.69]],"id":37174579}],"con":true,"img":false}]}
{"op":"mcm","clk":"5346495874","pt":1646088378695,"mc":[{"id":"1.195395444","rc":[{"atb":[[2.82,0]],"id":37174579}],"con":true,"img":false}]}
{"op":"mcm","clk":"5346495876","pt":1646088378798,"mc":[{"id":"1.195395444","rc":[{"atb":[[2.92,22.3]],"id":37174579}],"con":true,"img":false}]}
{"op":"mcm","clk":"5346544820","pt":1646089950326,"mc":[{"id":"1.195395444","rc":[{"atb":[[2.56,64.1]],"id":40917095},{"atl":[[9.8,3.36]],"id":40917095},{"atb":[[2.88,53.19]],"id":42189436},{"atl":[[9.4,3.42]],"id":42189436},{"atb":[[2.44,69.44]],"id":42236670},{"atl":[[6.6,4.28]],"id":42236670},{"atb":[[1.81,75.09]],"id":42070475},{"atl":[[7,10.34]],"id":42070475},{"atb":[[1.08,218.14]],"id":41523279},{"atl":[[4.5,3.34]],"id":41523279},{"atb":[[1.91,66.75]],"id":42236682},{"atl":[[4.3,8]],"id":42236682},{"atb":[[2.94,31.62]],"id":37174579},{"atl":[[14.5,5.3]],"id":37174579}],"con":true,"img":false}]}
{"op":"mcm","clk":"5346545018","pt":1646089960572,"mc":[{"id":"1.195395444","rc":[{"atl":[[9,6.67],[7,0]],"id":41523279}],"con":true,"img":false}]}
{"op":"mcm","clk":"5346545021","pt":1646089960675,"mc":[{"id":"1.195395444","rc":[{"atl":[[4.8,0]],"id":42070475}],"con":true,"img":false}]}
{"op":"mcm","clk":"5346545023","pt":1646089960777,"mc":[{"id":"1.195395444","rc":[{"atl":[[5.1,24.34]],"id":42070475}],"con":true,"img":false}]}
{"op":"mcm","clk":"5346545273","pt":1646089975079,"mc":[{"id":"1.195395444","rc":[{"atl":[[9.6,6.86],[9.4,1.42]],"id":42189436}],"con":true,"img":false}]}
{"op":"mcm","clk":"5346545442","pt":1646089983514,"mc":[{"id":"1.195395444","rc":[{"atl":[[5.1,10.68],[6.8,9.65]],"id":42070475},{"atl":[[8.8,6.73],[5.9,8.28]],"id":42236682}],"con":true,"img":false}]}
{"op":"mcm","clk":"5346546024","pt":1646090006530,"mc":[{"id":"1.195395444","rc":[{"atb":[[2.28,0],[2.58,34.59]],"id":40917095},{"atl":[[23,0],[28,1.5],[15.5,0]],"id":40917095},{"atb":[[3.25,0],[1.94,64.91],[3.3,0]],"id":42189436},{"atl":[[19,2.25],[10,0],[28,2.7],[15,0]],"id":42236670},{"atl":[[5.9,0],[4.2,12.68]],"id":42236682},{"atb":[[2.92,0]],"id":37174579},{"atl":[[18,0],[14,4.12]],"id":37174579}],"con":true,"img":false}]}
{"op":"mcm","clk":"5346546028","pt":1646090006632,"mc":[{"id":"1.195395444","rc":[{"atl":[[42,2.7]],"id":40917095},{"atb":[[3.25,18.03]],"id":42189436},{"atb":[[2.92,52.08],[2.96,22.3],[2.94,0]],"id":37174579}],"con":true,"img":false}]}
{"op":"mcm","clk":"5346546426","pt":1646090024935,"mc":[{"id":"1.195395444","rc":[{"atl":[[9.4,6.26]],"id":42189436}],"con":true,"img":false}]}
{"op":"mcm","clk":"5346546428","pt":1646090025036,"mc":[{"id":"1.195395444","rc":[{"atl":[[18,0]],"id":42189436}],"con":true,"img":false}]}
{"op":"mcm","clk":"5346546430","pt":1646090025139,"mc":[{"id":"1.195395444","rc":[{"atl":[[6.6,0]],"id":41523279},{"atb":[[2.96,0]],"id":37174579}],"con":true,"img":false}]}
{"op":"mcm","clk":"5346546431","pt":1646090025242,"mc":[{"id":"1.195395444","rc":[{"atl":[[5.9,7.24]],"id":41523279},{"atb":[[2.82,22.3]],"id":37174579}],"con":true,"img":false}]}
{"op":"mcm","clk":"5346546676","pt":1646090034097,"mc":[{"id":"1.195395444","rc":[{"atl":[[4.3,0],[4.2,20.68]],"id":42236682}],"con":true,"img":false}]}
{"op":"mcm","clk":"5346546938","pt":1646090043621,"mc":[{"id":"1.195395444","rc":[{"atl":[[19,3.38],[27,0.92]],"id":42189436},{"atl":[[8.8,0],[5.9,12.09]],"id":42236682}],"con":true,"img":false}]}
{"op":"mcm","clk":"5346547498","pt":1646090062534,"mc":[{"id":"1.195395444","rc":[{"atl":[[17,2.53],[28,0]],"id":40917095},{"atb":[[2.82,0]],"id":37174579}],"con":true,"img":false}]}
{"op":"mcm","clk":"5346547501","pt":1646090062635,"mc":[{"id":"1.195395444","rc":[{"atb":[[2.94,22.3]],"id":37174579}],"con":true,"img":false}]}
{"op":"mcm","clk":"5346547503","pt":1646090062738,"mc":[{"id":"1.195395444","rc":[{"atb":[[2.96,31.62]],"id":37174579}],"con":true,"img":false}]}
{"op":"mcm","clk":"5346547505","pt":1646090062840,"mc":[{"id":"1.195395444","rc":[{"atb":[[2.92,0]],"id":37174579}],"con":true,"img":false}]}
{"op":"mcm","clk":"5346547975","pt":1646090083159,"mc":[{"id":"1.195395444","rc":[{"atl":[[42,0]],"id":40917095},{"atl":[[19,0]],"id":42236670},{"atb":[[2.94,0]],"id":37174579}],"con":true,"img":false}]}
{"op":"mcm","clk":"5346547976","pt":1646090083262,"mc":[{"id":"1.195395444","rc":[{"atl":[[26,2.7]],"id":40917095},{"atl":[[15.5,2.25]],"id":42236670},{"atb":[[2.82,22.3],[2.92,52.08],[2.96,0]],"id":37174579}],"con":true,"img":false}]}
{"op":"mcm","clk":"5346549449","pt":1646090144367,"mc":[{"id":"1.195395444","rc":[{"atb":[[2.82,0]],"id":37174579}],"con":true,"img":false}]}
{"op":"mcm","clk":"5346549451","pt":1646090144469,"mc":[{"id":"1.195395444","rc":[{"atb":[[2.94,22.3]],"id":37174579}],"con":true,"img":false}]}
{"op":"mcm","clk":"5346549453","pt":1646090144572,"mc":[{"id":"1.195395444","rc":[{"atb":[[2.92,0],[2.96,31.62]],"id":37174579}],"con":true,"img":false}]}
{"op":"mcm","clk":"5346549702","pt":1646090154061,"mc":[{"id":"1.195395444","rc":[{"atb":[[2.56,0],[2.44,69.44]],"id":40917095},{"atb":[[2.88,0],[2.76,56.82]],"id":42189436},{"atl":[[9.6,0],[10.5,10.53]],"id":42189436},{"atb":[[2.32,75.76],[2.44,0]],"id":42236670},{"atl":[[4.4,24.69],[4.2,12.68]],"id":42236682}],"con":true,"img":false}]}
{"op":"mcm","clk":"5346550034","pt":1646090167382,"mc":[{"id":"1.195395444","rc":[{"atl":[[9.4,1.42]],"id":42189436},{"atl":[[4.2,0],[8.4,6.73]],"id":42236682}],"con":true,"img":false}]}
{"op":"mcm","clk":"5346550035","pt":1646090167485,"mc":[{"id":"1.195395444","rc":[{"atl":[[10,4.83]],"id":42189436},{"atl":[[4.3,12.68],[5.9,0]],"id":42236682}],"con":true,"img":false}]}
{"op":"mcm","clk":"5346550663","pt":1646090191448,"mc":[{"id":"1.195395444","rc":[{"atl":[[17,0]],"id":40917095}],"con":true,"img":false}]}
{"op":"mcm","clk":"5346550664","pt":1646090191550,"mc":[{"id":"1.195395444","rc":[{"atl":[[19,2.53]],"id":40917095}],"con":true,"img":false}]}
{"op":"mcm","clk":"5346550959","pt":1646090204174,"mc":[{"id":"1.195395444","rc":[{"atb":[[2.94,0]],"id":37174579}],"con":true,"img":false}]}
{"op":"mcm","clk":"5346550962","pt":1646090204278,"mc":[{"id":"1.195395444","rc":[{"atb":[[2.98,22.3]],"id":37174579}],"con":true,"img":false}]}
{"op":"mcm","clk":"5346550964","pt":1646090204377,"mc":[{"id":"1.195395444","rc":[{"atb":[[2.92,52.08],[2.96,0]],"id":37174579}],"con":true,"img":false}]}
{"op":"mcm","clk":"5346551077","pt":1646090209086,"mc":[{"id":"1.195395444","rc":[{"atb":[[1.79,0],[2.34,40.28]],"id":42236670}],"con":true,"img":false}]}
{"op":"mcm","clk":"5346551211","pt":1646090214874,"mc":[{"id":"1.195395444","rc":[{"atb":[[2.54,64.94],[2.44,0]],"id":40917095},{"atb":[[2.88,53.19],[2.76,0]],"id":42189436},{"atl":[[9.6,4.83],[10.5,0]],"id":42189436},{"atl":[[4.3,25.37],[4.4,0]],"id":42236682}],"con":true,"img":false}]}
{"op":"mcm","clk":"5346551333","pt":1646090219276,"mc":[{"id":"1.195395444","rc":[{"atb":[[2.98,0]],"id":37174579}],"con":true,"img":false}]}
{"op":"mcm","clk":"5346551335","pt":1646090219379,"mc":[{"id":"1.195395444","rc":[{"atb":[[2.94,22.3]],"id":37174579}],"con":true,"img":false}]}
{"op":"mcm","clk":"5346551808","pt":1646090238633,"mc":[{"id":"1.195395444","rc":[{"atb":[[2.96,31.62]],"id":37174579}],"con":true,"img":false}]}
{"op":"mcm","clk":"5346551811","pt":1646090238687,"mc":[{"id":"1.195395444","rc":[{"atb":[[2.92,0]],"id":37174579}],"con":true,"img":false}]}
{"op":"mcm","clk":"5346552509","pt":1646090262625,"mc":[{"id":"1.195395444","rc":[{"atl":[[10,0]],"id":42189436}],"con":true,"img":false}]}
{"op":"mcm","clk":"5346552512","pt":1646090262730,"mc":[{"id":"1.195395444","rc":[{"atl":[[9.4,6.26]],"id":42189436}],"con":true,"img":false}]}
{"op":"mcm","clk":"5346552981","pt":1646090281559,"mc":[{"id":"1.195395444","rc":[{"atl":[[26,0]],"id":40917095},{"atl":[[13,3.38],[9.4,1.42]],"id":42189436},{"atl":[[8.4,0],[5.9,12.09]],"id":42236682},{"atb":[[2.94,0]],"id":37174579}],"con":true,"img":false}]}
{"op":"mcm","clk":"5346552982","pt":1646090281666,"mc":[{"id":"1.195395444","rc":[{"atl":[[30,2.7]],"id":40917095},{"atb":[[2.92,52.08],[2.98,22.3],[2.96,0]],"id":37174579}],"con":true,"img":false}]}
{"op":"mcm","clk":"5346552984","pt":1646090281766,"mc":[{"id":"1.195395444","rc":[{"atl":[[8.2,8.23],[5.9,0]],"id":42236682},{"atb":[[2.92,0],[3,31.62]],"id":37174579}],"con":true,"img":false}]}
{"op":"mcm","clk":"5346553431","pt":1646090300612,"mc":[{"id":"1.195395444","rc":[{"atb":[[2.98,0]],"id":37174579}],"con":true,"img":false}]}
{"op":"mcm","clk":"5346553432","pt":1646090300715,"mc":[{"id":"1.195395444","rc":[{"atb":[[2.82,22.3],[2.92,52.08],[3,0]],"id":37174579}],"con":true,"img":false}]}
{"op":"mcm","clk":"5346553953","pt":1646090323539,"mc":[{"id":"1.195395444","rc":[{"atl":[[4.2,8]],"id":42236682},{"atl":[[17.5,6.06]],"id":37174579}],"con":true,"img":false}]}
{"op":"mcm","clk":"5346553954","pt":1646090323654,"mc":[{"id":"1.195395444","rc":[{"atl":[[4.3,12.68]],"id":42236682},{"atl":[[14.5,1.78]],"id":37174579}],"con":true,"img":false}]}
{"op":"mcm","clk":"5346554253","pt":1646090334048,"mc":[{"id":"1.195395444","rc":[{"atb":[[2.32,0],[2.42,70.42]],"id":42236670}],"con":true,"img":false}]}
{"op":"mcm","clk":"5346554634","pt":1646090346748,"mc":[{"id":"1.195395444","rc":[{"atb":[[1.9,59.98]],"id":42236670},{"atl":[[5.9,12.09]],"id":42236682},{"atb":[[2.82,0]],"id":37174579},{"atl":[[17,3.35]],"id":37174579}],"con":true,"img":false}]}
{"op":"mcm","clk":"5346554637","pt":1646090346857,"mc":[{"id":"1.195395444","rc":[{"atb":[[2.34,0]],"id":42236670},{"atl":[[8.2,0]],"id":42236682},{"atb":[[2.94,22.3]],"id":37174579},{"atl":[[14,0]],"id":37174579}],"con":true,"img":false}]}
{"op":"mcm","clk":"5346554642","pt":1646090346958,"mc":[{"id":"1.195395444","rc":[{"atb":[[2.92,0],[2.96,31.62]],"id":37174579}],"con":true,"img":false}]}
{"op":"mcm","clk":"5346555410","pt":1646090370784,"mc":[{"id":"1.195395444","rc":[{"atl":[[15.5,0]],"id":42236670},{"atb":[[2.94,0]],"id":37174579}],"con":true,"img":false}]}
{"op":"mcm","clk":"5346555413","pt":1646090370888,"mc":[{"id":"1.195395444","rc":[{"atl":[[17.5,2.25]],"id":42236670},{"atb":[[2.82,22.3],[2.92,52.08],[2.96,0]],"id":37174579}],"con":true,"img":false}]}
{"op":"mcm","clk":"5346555933","pt":1646090387697,"mc":[{"id":"1.195395444","rc":[{"atl":[[9.4,6.26]],"id":42189436}],"con":true,"img":false}]}
{"op":"mcm","clk":"5346555937","pt":1646090387800,"mc":[{"id":"1.195395444","rc":[{"atl":[[13,0]],"id":42189436},{"atl":[[6.8,0]],"id":42070475},{"atl":[[4.3,0]],"id":42236682}],"con":true,"img":false}]}
{"op":"mcm","clk":"5346555944","pt":1646090387905,"mc":[{"id":"1.195395444","rc":[{"atl":[[9.6,0],[9.2,4.83],[13,3.38],[9.4,1.42]],"id":42189436},{"atl":[[6.2,9.65]],"id":42070475},{"atl":[[4.1,12.68]],"id":42236682}],"con":true,"img":false}]}
{"op":"mcm","clk":"5346556140","pt":1646090393132,"mc":[{"id":"1.195395444","rc":[{"atl":[[9.2,0],[9.4,11.08]],"id":42189436}],"con":true,"img":false}]}
{"op":"mcm","clk":"5346556142","pt":1646090393235,"mc":[{"id":"1.195395444","rc":[{"atl":[[12.5,6.26],[9.4,1.42]],"id":42189436}],"con":true,"img":false}]}
{"op":"mcm","clk":"5346556173","pt":1646090394013,"mc":[{"id":"1.195395444","rc":[{"atl":[[4.1,20.68],[4.2,0]],"id":42236682}],"con":true,"img":false}]}
{"op":"mcm","clk":"5346556924","pt":1646090412640,"mc":[{"id":"1.195395444","rc":[{"atl":[[19,0]],"id":40917095}],"con":true,"img":false}]}
{"op":"mcm","clk":"5346556928","pt":1646090412743,"mc":[{"id":"1.195395444","rc":[{"atl":[[22,2.53]],"id":40917095}],"con":true,"img":false}]}
{"op":"mcm","clk":"5346557624","pt":1646090430184,"mc":[{"id":"1.195395444","rc":[{"atl":[[13,0]],"id":42189436},{"atb":[[2.82,0]],"id":37174579}],"con":true,"img":false}]}
{"op":"mcm","clk":"5346557628","pt":1646090430236,"mc":[{"id":"1.195395444","rc":[{"atl":[[12,3.38]],"id":42189436},{"atb":[[2.94,22.3]],"id":37174579}],"con":true,"img":false}]}
{"op":"mcm","clk":"5346557631","pt":1646090430390,"mc":[{"id":"1.195395444","rc":[{"atl":[[12.5,0],[9.4,3.42]],"id":42189436},{"atb":[[2.92,0],[2.96,31.62]],"id":37174579}],"con":true,"img":false}]}
{"op":"mcm","clk":"5346558160","pt":1646090446965,"mc":[{"id":"1.195395444","rc":[{"atl":[[6.2,0]],"id":42070475},{"atl":[[4.1,8]],"id":42236682},{"atb":[[2.94,0]],"id":37174579}],"con":true,"img":false}]}
{"op":"mcm","clk":"5346558163","pt":1646090447068,"mc":[{"id":"1.195395444","rc":[{"atl":[[6.8,9.65]],"id":42070475},{"atl":[[4,16.69]],"id":42236682},{"atb":[[2.82,22.3],[2.92,52.08],[2.96,0]],"id":37174579}],"con":true,"img":false}]}
{"op":"mcm","clk":"5346558879","pt":1646090482755,"mc":[{"id":"1.195395444","rc":[{"atl":[[19,5.64],[28,2.7]],"id":42189436},{"atl":[[5.9,0]],"id":41523279}],"con":true,"img":false}]}
{"op":"mcm","clk":"5346558882","pt":1646090482857,"mc":[{"id":"1.195395444","rc":[{"atl":[[19,2.25],[12,0]],"id":42189436},{"atl":[[7,7.24]],"id":41523279}],"con":true,"img":false}]}
{"op":"mcm","clk":"5346559648","pt":1646090508993,"mc":[{"id":"1.195395444","rc":[{"atl":[[11,4.05]],"id":42236670}],"con":true,"img":false}]}
{"op":"mcm","clk":"5346559651","pt":1646090509094,"mc":[{"id":"1.195395444","rc":[{"atl":[[22,0]],"id":40917095},{"atl":[[17.5,0]],"id":42236670},{"atb":[[2.82,0]],"id":37174579}],"con":true,"img":false}]}
{"op":"mcm","clk":"5346559654","pt":1646090509196,"mc":[{"id":"1.195395444","rc":[{"atl":[[16.5,2.53]],"id":40917095},{"atb":[[2.94,22.3]],"id":37174579}],"con":true,"img":false}]}
{"op":"mcm","clk":"5346559659","pt":1646090509400,"mc":[{"id":"1.195395444","rc":[{"atb":[[2.92,0],[2.96,31.62]],"id":37174579}],"con":true,"img":false}]}
{"op":"mcm","clk":"5346559777","pt":1646090513983,"mc":[{"id":"1.195395444","rc":[{"atb":[[2.36,73.53],[2.54,0]],"id":40917095},{"atb":[[2.88,0],[2.64,60.98]],"id":42189436},{"atl":[[4.3,24.69],[4.1,0]],"id":42236682}],"con":true,"img":false}]}
{"op":"mcm","clk":"5346559897","pt":1646090518184,"mc":[{"id":"1.195395444","rc":[{"atl":[[5.2,14.96],[7,0]],"id":42070475},{"atb":[[1.08,0],[1.17,218.14]],"id":41523279}],"con":true,"img":false}]}
{"op":"mcm","clk":"5346560237","pt":1646090534706,"mc":[{"id":"1.195395444","rc":[{"atb":[[3.25,45.15],[1.94,0]],"id":42189436},{"atl":[[28,0],[15.5,3.72]],"id":42236670},{"atl":[[8,7.78],[6.8,0]],"id":42070475},{"atl":[[4,4],[8.8,6.73],[5.9,0]],"id":42236682},{"atb":[[2.94,0]],"id":37174579}],"con":true,"img":false}]}
{"op":"mcm","clk":"5346560238","pt":1646090534810,"mc":[{"id":"1.195395444","rc":[{"atl":[[4.2,12.68]],"id":42236682},{"atb":[[2.82,22.3],[2.92,52.08]],"id":37174579}],"con":true,"img":false}]}
{"op":"mcm","clk":"5346560240","pt":1646090534913,"mc":[{"id":"1.195395444","rc":[{"atb":[[2.96,0]],"id":37174579}],"con":true,"img":false}]}
{"op":"mcm","clk":"5346562391","pt":1646090631370,"mc":[{"id":"1.195395444","rc":[{"atb":[[2.82,0]],"id":37174579}],"con":true,"img":false}]}
{"op":"mcm","clk":"5346562393","pt":1646090631473,"mc":[{"id":"1.195395444","rc":[{"atb":[[2.94,22.3]],"id":37174579}],"con":true,"img":false}]}
{"op":"mcm","clk":"5346562397","pt":1646090631576,"mc":[{"id":"1.195395444","rc":[{"atb":[[2.96,31.62]],"id":37174579}],"con":true,"img":false}]}
{"op":"mcm","clk":"5346562399","pt":1646090631678,"mc":[{"id":"1.195395444","rc":[{"atb":[[2.92,0]],"id":37174579}],"con":true,"img":false}]}
{"op":"mcm","clk":"5346562801","pt":1646090650410,"mc":[{"id":"1.195395444","rc":[{"atb":[[3.1,0],[2.58,0]],"id":40917095},{"atl":[[16.5,0],[30,0]],"id":40917095},{"atb":[[3.25,0]],"id":42189436},{"atl":[[19,0],[28,0]],"id":42189436},{"atb":[[2.52,0],[1.9,0]],"id":42236670},{"atl":[[11,0],[15.5,0]],"id":42236670},{"atb":[[1.76,0],[1.38,0]],"id":42070475},{"atl":[[8,0],[5.1,0]],"id":42070475},{"atb":[[1.96,0],[1.49,0]],"id":41523279},{"atl":[[9,0],[7,0]],"id":41523279},{"atb":[[1.43,0],[1.86,0]],"id":42236682},{"atl":[[8.8,0],[4.2,0]],"id":42236682},{"atb":[[1.96,0],[2.94,0]],"id":37174579},{"atl":[[17,0],[12,0]],"id":37174579}],"con":true,"img":false}]}
{"op":"mcm","clk":"5346562805","pt":1646090650512,"mc":[{"id":"1.195395444","rc":[{"atb":[[2.92,52.08],[2.96,0]],"id":37174579}],"con":true,"img":false}]}
{"op":"mcm","clk":"5346564431","pt":1646090719476,"mc":[{"id":"1.195395444","rc":[{"atb":[[3.1,19.32],[2.38,39.61]],"id":40917095},{"atl":[[16.5,2.61],[24,2.7]],"id":40917095},{"atb":[[3.25,27.12],[3.3,18.03]],"id":42189436},{"atl":[[19.5,2.19],[28,2.7]],"id":42189436},{"atb":[[2.52,26.7],[1.77,70.11]],"id":42236670},{"atl":[[11,4.05],[15.5,3.72]],"id":42236670},{"atb":[[1.76,40.59],[1.38,147.41]],"id":42070475},{"atl":[[8,7.78],[5.1,9.89]],"id":42070475},{"atb":[[1.96,40.59],[1.49,109.07]],"id":41523279},{"atl":[[9,6.67],[7,6.76]],"id":41523279},{"atb":[[1.43,137.81],[1.86,40.59]],"id":42236682},{"atl":[[8.8,6.73],[4.2,12.68]],"id":42236682},{"atb":[[1.95,56.54],[2.94,20.92]],"id":37174579},{"atl":[[17,3.35],[13,3.38]],"id":37174579}],"con":true,"img":false}]}
{"op":"mcm","clk":"5346564432","pt":1646090719578,"mc":[{"id":"1.195395444","rc":[{"atb":[[2.92,0],[2.96,31.62]],"id":37174579}],"con":true,"img":false}]}
{"op":"mcm","clk":"5346567055","pt":1646090810211,"mc":[{"id":"1.195395444","rc":[{"atb":[[2.94,0]],"id":37174579}],"con":true,"img":false}]}
{"op":"mcm","clk":"5346567060","pt":1646090810319,"mc":[{"id":"1.195395444","rc":[{"atb":[[2.92,52.08],[2.98,20.92],[2.96,0]],"id":37174579}],"con":true,"img":false}]}
{"op":"mcm","clk":"5346567629","pt":1646090830667,"mc":[{"id":"1.195395444","rc":[{"atb":[[2.98,0]],"id":37174579}],"con":true,"img":false}]}
{"op":"mcm","clk":"5346567632","pt":1646090830766,"mc":[{"id":"1.195395444","rc":[{"atb":[[2.94,20.92]],"id":37174579}],"con":true,"img":false}]}
{"op":"mcm","clk":"5346567859","pt":1646090838576,"mc":[{"id":"1.195395444","rc":[{"atb":[[2.92,0],[2.96,31.62]],"id":37174579}],"con":true,"img":false}]}
{"op":"mcm","clk":"5346569189","pt":1646090881752,"mc":[{"id":"1.195395444","rc":[{"atb":[[2.94,0]],"id":37174579}],"con":true,"img":false}]}
{"op":"mcm","clk":"5346569191","pt":1646090881818,"mc":[{"id":"1.195395444","rc":[{"atb":[[2.92,52.08],[2.98,20.92]],"id":37174579}],"con":true,"img":false}]}
{"op":"mcm","clk":"5346569195","pt":1646090881913,"mc":[{"id":"1.195395444","rc":[{"atb":[[2.92,0],[3,31.62],[2.96,0]],"id":37174579}],"con":true,"img":false}]}
{"op":"mcm","clk":"5346570273","pt":1646090922103,"mc":[{"id":"1.195395444","rc":[{"atb":[[2.98,0]],"id":37174579}],"con":true,"img":false}]}
{"op":"mcm","clk":"5346570277","pt":1646090922207,"mc":[{"id":"1.195395444","rc":[{"atb":[[2.92,73],[3,0]],"id":37174579}],"con":true,"img":false}]}
{"op":"mcm","clk":"5346571660","pt":1646090968228,"mc":[{"id":"1.195395444","rc":[{"atb":[[2.92,52.08]],"id":37174579}],"con":true,"img":false}]}
{"op":"mcm","clk":"5346571663","pt":1646090968333,"mc":[{"id":"1.195395444","rc":[{"atb":[[2.94,20.92]],"id":37174579}],"con":true,"img":false}]}
{"op":"mcm","clk":"5346571669","pt":1646090968536,"mc":[{"id":"1.195395444","rc":[{"atb":[[2.92,0],[2.96,31.62]],"id":37174579}],"con":true,"img":false}]}
{"op":"mcm","clk":"5346572096","pt":1646090983949,"mc":[{"id":"1.195395444","rc":[{"atb":[[2.36,0],[2.7,58.82]],"id":40917095},{"atb":[[2.64,0],[2.94,51.55]],"id":42189436},{"atl":[[9.6,6.86],[9.4,1.42]],"id":42189436},{"atb":[[2.42,0],[2.52,92.49]],"id":42236670},{"atl":[[6.6,2.14],[7,8.56]],"id":42236670},{"atb":[[1.82,121.95],[1.91,0]],"id":42236682},{"atl":[[4.3,0],[3.95,12.69]],"id":42236682},{"atl":[[17.5,0],[21,3.56]],"id":37174579}],"con":true,"img":false}]}
{"op":"mcm","clk":"5346572213","pt":1646090987139,"mc":[{"id":"1.195395444","rc":[{"atb":[[2.94,0]],"id":37174579}],"con":true,"img":false}]}
{"op":"mcm","clk":"5346572218","pt":1646090987244,"mc":[{"id":"1.195395444","rc":[{"atb":[[2.82,20.92]],"id":37174579}],"con":true,"img":false}]}
{"op":"mcm","clk":"5346572223","pt":1646090987348,"mc":[{"id":"1.195395444","rc":[{"atb":[[2.92,52.08],[2.96,0]],"id":37174579}],"con":true,"img":false}]}
{"op":"mcm","clk":"5346572274","pt":1646090989141,"mc":[{"id":"1.195395444","rc":[{"atl":[[9.6,0],[13.5,8.96]],"id":42189436},{"atl":[[7,0],[8.4,10.7]],"id":42236670}],"con":true,"img":false}]}
{"op":"mcm","clk":"5346572562","pt":1646090997487,"mc":[{"id":"1.195395444","rc":[{"atb":[[3.65,2.8]],"id":40917095},{"atb":[[3.55,2.92]],"id":42189436},{"atb":[[2.76,4.23]],"id":42236670},{"atb":[[1.85,8.76]],"id":42070475},{"atb":[[2,7.45]],"id":41523279},{"atb":[[1.94,7.92]],"id":42236682},{"atb":[[2.98,3.76]],"id":37174579}],"con":true,"img":false}]}
{"op":"mcm","clk":"5346572567","pt":1646090997589,"mc":[{"id":"1.195395444","rc":[{"atb":[[1.86,75.09]],"id":42070475},{"atb":[[2.92,0],[3,31.62]],"id":37174579}],"con":true,"img":false}]}
{"op":"mcm","clk":"5346572570","pt":1646090997691,"mc":[{"id":"1.195395444","rc":[{"atb":[[1.81,0]],"id":42070475}],"con":true,"img":false}]}
{"op":"mcm","clk":"5346572665","pt":1646091000369,"mc":[{"id":"1.195395444","rc":[{"atb":[[1.85,0]],"id":42070475},{"atb":[[2.98,0]],"id":37174579}],"con":true,"img":false}]}
{"op":"mcm","clk":"5346572671","pt":1646091000470,"mc":[{"id":"1.195395444","rc":[{"atb":[[2.92,52.08],[3,0]],"id":37174579}],"con":true,"img":false}]}
{"op":"mcm","clk":"5346572751","pt":1646091002702,"mc":[{"id":"1.195395444","rc":[{"atb":[[1.81,123.46],[1.86,0]],"id":42070475}],"con":true,"img":false}]}
{"op":"mcm","clk":"5346572879","pt":1646091006373,"mc":[{"id":"1.195395444","rc":[{"atl":[[16.5,0]],"id":40917095},{"atb":[[3.25,0]],"id":42189436}],"con":true,"img":false}]}
{"op":"mcm","clk":"5346572884","pt":1646091006480,"mc":[{"id":"1.195395444","rc":[{"atl":[[24,0]],"id":40917095}],"con":true,"img":false}]}
{"op":"mcm","clk":"5346572891","pt":1646091006578,"mc":[{"id":"1.195395444","rc":[{"atl":[[38,2.7]],"id":40917095}],"con":true,"img":false}]}
{"op":"mcm","clk":"5346572986","pt":1646091009512,"mc":[{"id":"1.195395444","rc":[{"atb":[[1.85,8.76]],"id":42070475},{"atb":[[2.98,3.76]],"id":37174579}],"con":true,"img":false}]}
{"op":"mcm","clk":"5346572998","pt":1646091009675,"mc":[{"id":"1.195395444","rc":[{"atb":[[2.92,0],[3,31.62]],"id":37174579}],"con":true,"img":false}]}
{"op":"mcm","clk":"5346573018","pt":1646091010490,"mc":[{"id":"1.195395444","rc":[{"atb":[[1.82,0],[1.84,119.05]],"id":42236682}],"con":true,"img":false}]}
{"op":"mcm","clk":"5346573081","pt":1646091012398,"mc":[{"id":"1.195395444","rc":[{"atb":[[2.98,0]],"id":37174579}],"con":true,"img":false}]}
{"op":"mcm","clk":"5346573085","pt":1646091012500,"mc":[{"id":"1.195395444","rc":[{"atb":[[2.92,52.08]],"id":37174579}],"con":true,"img":false}]}
{"op":"mcm","clk":"5346573086","pt":1646091012601,"mc":[{"id":"1.195395444","rc":[{"atb":[[3,0]],"id":37174579}],"con":true,"img":false}]}
{"op":"mcm","clk":"5346573142","pt":1646091014918,"mc":[{"id":"1.195395444","rc":[{"atb":[[2.76,8.98]],"id":42236670}],"con":true,"img":false}]}
{"op":"mcm","clk":"5346573147","pt":1646091015021,"mc":[{"id":"1.195395444","rc":[{"atb":[[3.55,6.19]],"id":42189436}],"con":true,"img":false}]}
{"op":"mcm","clk":"5346573149","pt":1646091015123,"mc":[{"id":"1.195395444","rc":[{"atb":[[3.65,5.96]],"id":40917095}],"con":true,"img":false}]}
{"op":"mcm","clk":"5346573157","pt":1646091015284,"mc":[{"id":"1.195395444","rc":[{"atb":[[2,15.81]],"id":41523279}],"con":true,"img":false}]}
{"op":"mcm","clk":"5346573171","pt":1646091015487,"mc":[{"id":"1.195395444","rc":[{"atb":[[1.94,16.82]],"id":42236682},{"atb":[[2.98,4.22]],"id":37174579}],"con":true,"img":false}]}
{"op":"mcm","clk":"5346573174","pt":1646091015588,"mc":[{"id":"1.195395444","rc":[{"atl":[[13.5,0.96],[9.4,3.42]],"id":42189436},{"atl":[[6.6,4.28],[8.4,0]],"id":42236670}],"con":true,"img":false}]}
{"op":"mcm","clk":"5346573336","pt":1646091021413,"mc":[{"id":"1.195395444","rc":[{"atb":[[2.98,7.98]],"id":37174579}],"con":true,"img":false}]}
{"op":"mcm","clk":"5346573433","pt":1646091025018,"mc":[{"id":"1.195395444","rc":[{"atb":[[1.85,18.59]],"id":42070475}],"con":true,"img":false}]}
{"op":"mcm","clk":"5346573437","pt":1646091025224,"mc":[{"id":"1.195395444","rc":[{"atl":[[8.8,0],[5.9,12.09]],"id":42236682}],"con":true,"img":false}]}
{"op":"mcm","clk":"5346573440","pt":1646091025327,"mc":[{"id":"1.195395444","rc":[{"atl":[[4.2,0]],"id":42236682}],"con":true,"img":false}]}
{"op":"mcm","clk":"5346573445","pt":1646091025382,"mc":[{"id":"1.195395444","rc":[{"atl":[[4.9,12.68]],"id":42236682}],"con":true,"img":false}]}
{"op":"mcm","clk":"5346573495","pt":1646091027250,"mc":[{"id":"1.195395444","marketDefinition":{"bspMarket":false,"turnInPlayEnabled":false,"persistenceEnabled":false,"marketBaseRate":5.0,"eventId":"31270459","eventTypeId":"4339","numberOfWinners":2,"bettingType":"ODDS","marketType":"PLACE","marketTime":"2022-03-01T00:12:00.000Z","suspendTime":"2022-03-01T00:12:00.000Z","bspReconciled":false,"complete":true,"inPlay":false,"crossMatching":true,"runnersVoidable":false,"numberOfActiveRunners":7,"betDelay":0,"status":"OPEN","runners":[{"status":"ACTIVE","sortPriority":1,"id":42236670,"name":"1. Nighthawk Storm"},{"status":"ACTIVE","sortPriority":2,"id":40917095,"name":"2. Goldstar Vale"},{"status":"ACTIVE","sortPriority":3,"id":42189436,"name":"3. Going Gorillas"},{"status":"ACTIVE","sortPriority":4,"id":41523279,"name":"4. Homebush Cardi"},{"status":"ACTIVE","sortPriority":5,"id":37174579,"name":"6. Yes Yes No"},{"status":"ACTIVE","sortPriority":6,"id":42070475,"name":"7. Breakpoint"},{"status":"ACTIVE","sortPriority":7,"id":42236682,"name":"8. Goldstar Brynley"}],"regulators":["MR_INT"],"venue":"Addington","countryCode":"NZ","discountAllowed":true,"timezone":"NZ","openDate":"2022-02-28T23:02:00.000Z","version":4380660695,"name":"To Be Placed","eventName":"Addington (NZL) 1st Mar"},"rc":[],"con":true,"img":false}]}
{"op":"mcm","clk":"5346573550","pt":1646091029025,"mc":[{"id":"1.195395444","rc":[{"atb":[[1.81,0],[1.86,75.09]],"id":42070475}],"con":true,"img":false}]}
{"op":"mcm","clk":"5346573592","pt":1646091030415,"mc":[{"id":"1.195395444","rc":[{"atb":[[1.85,9.83]],"id":42070475}],"con":true,"img":false}]}
{"op":"mcm","clk":"5346573752","pt":1646091036425,"mc":[{"id":"1.195395444","rc":[{"atb":[[1.9,8.27]],"id":42070475}],"con":true,"img":false}]}
{"op":"mcm","clk":"5346573754","pt":1646091036532,"mc":[{"id":"1.195395444","rc":[{"atb":[[1.91,9.83],[1.86,0]],"id":42070475}],"con":true,"img":false}]}
{"op":"mcm","clk":"5346573812","pt":1646091038742,"mc":[{"id":"1.195395444","rc":[{"atb":[[2.92,0],[3,31.62]],"id":37174579}],"con":true,"img":false}]}
{"op":"mcm","clk":"5346573834","pt":1646091039413,"mc":[{"id":"1.195395444","rc":[{"atb":[[1.9,0]],"id":42070475},{"atb":[[2.98,4.22]],"id":37174579}],"con":true,"img":false}]}
{"op":"mcm","clk":"5346573923","pt":1646091041631,"mc":[{"id":"1.195395444","rc":[{"atb":[[1.91,0],[1.86,40.59]],"id":42070475}],"con":true,"img":false}]}
{"op":"mcm","clk":"5346573930","pt":1646091041837,"mc":[{"id":"1.195395444","rc":[{"atb":[[1.85,0]],"id":42070475}],"con":true,"img":false}]}
{"op":"mcm","clk":"5346573934","pt":1646091041940,"mc":[{"id":"1.195395444","rc":[{"atb":[[1.81,81.18],[1.86,0]],"id":42070475}],"con":true,"img":false}]}
{"op":"mcm","clk":"5346573974","pt":1646091043122,"mc":[{"id":"1.195395444","rc":[{"atb":[[2.72,31.78],[2.38,0]],"id":40917095},{"atl":[[16.5,2.61]],"id":40917095},{"atb":[[3.25,27.12]],"id":42189436},{"atl":[[8.8,6.73],[5.9,0]],"id":42236682},{"atb":[[2.82,0]],"id":37174579}],"con":true,"img":false}]}
{"op":"mcm","clk":"5346573977","pt":1646091043225,"mc":[{"id":"1.195395444","rc":[{"atb":[[2.94,20.92]],"id":37174579}],"con":true,"img":false}]}
{"op":"mcm","clk":"5346574038","pt":1646091045442,"mc":[{"id":"1.195395444","rc":[{"atb":[[3.05,3.63]],"id":37174579}],"con":true,"img":false}]}
{"op":"mcm","clk":"5346574134","pt":1646091048435,"mc":[{"id":"1.195395444","rc":[{"atb":[[1.85,8.76]],"id":42070475}],"con":true,"img":false}]}
{"op":"mcm","clk":"5346574238","pt":1646091052361,"mc":[{"id":"1.195395444","rc":[{"atl":[[5.8,14.52],[5.2,5.72]],"id":42070475},{"atb":[[1.84,0],[1.86,156.87]],"id":42236682}],"con":true,"img":false}]}
{"op":"mcm","clk":"5346574295","pt":1646091054063,"mc":[{"id":"1.195395444","rc":[{"atb":[[2.98,0]],"id":37174579}],"con":true,"img":false}]}
{"op":"mcm","clk":"5346574428","pt":1646091059168,"mc":[{"id":"1.195395444","rc":[{"atb":[[2.94,0]],"id":37174579}],"con":true,"img":false}]}
{"op":"mcm","clk":"5346574431","pt":1646091059271,"mc":[{"id":"1.195395444","rc":[{"atb":[[2.92,20.92]],"id":37174579}],"con":true,"img":false}]}
{"op":"mcm","clk":"5346574447","pt":1646091059942,"mc":[{"id":"1.195395444","rc":[{"atb":[[1.85,18.59]],"id":42070475},{"atb":[[3.05,7.71]],"id":37174579}],"con":true,"img":false}]}
{"op":"mcm","clk":"5346574577","pt":1646091064664,"mc":[{"id":"1.195395444","rc":[{"atb":[[3.1,20.92]],"id":37174579}],"con":true,"img":false}]}
{"op":"mcm","clk":"5346574578","pt":1646091064765,"mc":[{"id":"1.195395444","rc":[{"atb":[[3,0]],"id":37174579}],"con":true,"img":false}]}
{"op":"mcm","clk":"5346574637","pt":1646091066565,"mc":[{"id":"1.195395444","rc":[{"atb":[[3.05,4.07]],"id":37174579}],"con":true,"img":false}]}
{"op":"mcm","clk":"5346574667","pt":1646091067856,"mc":[{"id":"1.195395444","rc":[{"atb":[[1.81,0],[1.86,75.09]],"id":42070475}],"con":true,"img":false}]}
{"op":"mcm","clk":"5346574724","pt":1646091069663,"mc":[{"id":"1.195395444","rc":[{"atb":[[1.85,9.83]],"id":42070475}],"con":true,"img":false}]}
{"op":"mcm","clk":"5346574789","pt":1646091071255,"mc":[{"id":"1.195395444","rc":[{"atb":[[1.26,218.14],[1.17,0]],"id":41523279}],"con":true,"img":false}]}
{"op":"mcm","clk":"5346574854","pt":1646091072587,"mc":[{"id":"1.195395444","rc":[{"atb":[[2.96,3.8]],"id":37174579}],"con":true,"img":false}]}
{"op":"mcm","clk":"5346574900","pt":1646091074087,"mc":[{"id":"1.195395444","rc":[{"atl":[[25,16.63]],"id":40917095},{"atl":[[8,40.93]],"id":42070475}],"con":true,"img":false}]}
{"op":"mcm","clk":"5346574903","pt":1646091074189,"mc":[{"id":"1.195395444","rc":[{"atl":[[38,0]],"id":40917095},{"atb":[[3.25,0]],"id":42189436}],"con":true,"img":false}]}
{"op":"mcm","clk":"5346574907","pt":1646091074291,"mc":[{"id":"1.195395444","rc":[{"atb":[[3,27.12]],"id":42189436}],"con":true,"img":false}]}
{"op":"mcm","clk":"5346574944","pt":1646091075579,"mc":[{"id":"1.195395444","rc":[{"atb":[[1.9,8.27]],"id":42070475}],"con":true,"img":false}]}
{"op":"mcm","clk":"5346575001","pt":1646091077794,"mc":[{"id":"1.195395444","rc":[{"atb":[[3.05,0]],"id":37174579}],"con":true,"img":false}]}
{"op":"mcm","clk":"5346575009","pt":1646091077957,"mc":[{"id":"1.195395444","rc":[{"atb":[[3.1,0],[2.98,41.84]],"id":37174579}],"con":true,"img":false}]}
{"op":"mcm","clk":"5346575037","pt":1646091079184,"mc":[{"id":"1.195395444","rc":[{"atb":[[2.96,0]],"id":37174579}],"con":true,"img":false}]}
{"op":"mcm","clk":"5346575137","pt":1646091083098,"mc":[{"id":"1.195395444","rc":[{"atb":[[2.94,51.55]],"id":37174579}],"con":true,"img":false}]}
{"op":"mcm","clk":"5346575142","pt":1646091083200,"mc":[{"id":"1.195395444","rc":[{"atb":[[2.98,0]],"id":37174579}],"con":true,"img":false}]}
{"op":"mcm","clk":"5346575159","pt":1646091083775,"mc":[{"id":"1.195395444","rc":[{"atb":[[1.85,0]],"id":42070475}],"con":true,"img":false}]}
{"op":"mcm","clk":"5346575355","pt":1646091089758,"mc":[{"id":"1.195395444","rc":[{"atb":[[1.9,17.56]],"id":42070475}],"con":true,"img":false}]}
{"op":"mcm","clk":"5346575358","pt":1646091090010,"mc":[{"id":"1.195395444","rc":[{"atl":[[28,14.46]],"id":42189436},{"atl":[[15.5,24.27]],"id":42236670},{"atl":[[9,34.57]],"id":41523279},{"atl":[[8.8,38.7]],"id":42236682},{"atl":[[17,21.18]],"id":37174579}],"con":true,"img":false}]}
{"op":"mcm","clk":"5346575385","pt":1646091091090,"mc":[{"id":"1.195395444","rc":[{"atb":[[3,3.72]],"id":37174579}],"con":true,"img":false}]}
{"op":"mcm","clk":"5346575448","pt":1646091093476,"mc":[{"id":"1.195395444","rc":[{"atb":[[1.91,75.09],[1.86,0]],"id":42070475}],"con":true,"img":false}]}
{"op":"mcm","clk":"5346575482","pt":1646091094316,"mc":[{"id":"1.195395444","rc":[{"atb":[[1.9,9.28]],"id":42070475}],"con":true,"img":false}]}
{"op":"mcm","clk":"5346575666","pt":1646091100109,"mc":[{"id":"1.195395444","rc":[{"atb":[[1.95,7.84]],"id":42070475}],"con":true,"img":false}]}
{"op":"mcm","clk":"5346575670","pt":1646091100313,"mc":[{"id":"1.195395444","rc":[{"atb":[[1.91,0],[1.96,9.29]],"id":42070475}],"con":true,"img":false}]}
{"op":"mcm","clk":"5346575737","pt":1646091102017,"mc":[{"id":"1.195395444","rc":[{"atb":[[3,7.9]],"id":37174579}],"con":true,"img":false}]}
{"op":"mcm","clk":"5346575773","pt":1646091103198,"mc":[{"id":"1.195395444","rc":[{"atb":[[1.95,0]],"id":42070475}],"con":true,"img":false}]}
{"op":"mcm","clk":"5346575777","pt":1646091103302,"mc":[{"id":"1.195395444","rc":[{"atb":[[1.91,40.59],[1.96,0]],"id":42070475}],"con":true,"img":false}]}
{"op":"mcm","clk":"5346575784","pt":1646091103510,"mc":[{"id":"1.195395444","rc":[{"atb":[[3.05,20.92]],"id":37174579}],"con":true,"img":false}]}
{"op":"mcm","clk":"5346575786","pt":1646091103614,"mc":[{"id":"1.195395444","rc":[{"atb":[[2.94,0]],"id":37174579}],"con":true,"img":false}]}
{"op":"mcm","clk":"5346575832","pt":1646091105100,"mc":[{"id":"1.195395444","rc":[{"atb":[[1.77,0]],"id":42236670},{"atb":[[1.45,99.13],[1.38,0]],"id":42070475},{"atb":[[1.58,86.95],[1.49,0]],"id":41523279},{"atb":[[1.43,0],[1.51,92.23]],"id":42236682},{"atb":[[1.95,0]],"id":37174579}],"con":true,"img":false}]}
{"op":"mcm","clk":"5346575835","pt":1646091105201,"mc":[{"id":"1.195395444","rc":[{"atb":[[1.94,70.11]],"id":42236670},{"atb":[[2.14,56.54]],"id":37174579}],"con":true,"img":false}]}
{"op":"mcm","clk":"5346575882","pt":1646091106229,"mc":[{"id":"1.195395444","rc":[{"atb":[[3,4.18]],"id":37174579}],"con":true,"img":false}]}
{"op":"mcm","clk":"5346575947","pt":1646091107881,"mc":[{"id":"1.195395444","rc":[{"atb":[[1.9,0]],"id":42070475}],"con":true,"img":false}]}
{"op":"mcm","clk":"5346575971","pt":1646091108497,"mc":[{"id":"1.195395444","rc":[{"atb":[[1.81,81.18],[1.91,0]],"id":42070475}],"con":true,"img":false}]}
{"op":"mcm","clk":"5346576090","pt":1646091112095,"mc":[{"id":"1.195395444","rc":[{"atb":[[2.96,3.8]],"id":37174579}],"con":true,"img":false}]}
{"op":"mcm","clk":"5346576186","pt":1646091115223,"mc":[{"id":"1.195395444","rc":[{"atb":[[1.85,8.76]],"id":42070475}],"con":true,"img":false}]}
{"op":"mcm","clk":"5346576352","pt":1646091120136,"mc":[{"id":"1.195395444","rc":[{"atl":[[25,2.7]],"id":40917095},{"atl":[[28,2.7]],"id":42189436},{"atl":[[15.5,3.72]],"id":42236670},{"atl":[[9,6.67]],"id":41523279},{"atl":[[8.8,6.73]],"id":42236682},{"atb":[[3,0]],"id":37174579},{"atl":[[17,2.82]],"id":37174579}],"con":true,"img":false}]}
{"op":"mcm","clk":"5346576354","pt":1646091120338,"mc":[{"id":"1.195395444","rc":[{"atb":[[2.98,41.84],[3.05,0]],"id":37174579}],"con":true,"img":false}]}
{"op":"mcm","clk":"5346576381","pt":1646091121211,"mc":[{"id":"1.195395444","rc":[{"atb":[[2.96,0]],"id":37174579}],"con":true,"img":false}]}
{"op":"mcm","clk":"5346576384","pt":1646091121311,"mc":[{"id":"1.195395444","rc":[{"atb":[[2.98,0],[2.94,51.55]],"id":37174579}],"con":true,"img":false}]}
{"op":"mcm","clk":"5346576569","pt":1646091125945,"mc":[{"id":"1.195395444","rc":[{"atb":[[1.85,18.59]],"id":42070475}],"con":true,"img":false}]}
{"op":"mcm","clk":"5346576786","pt":1646091130418,"mc":[{"id":"1.195395444","rc":[{"atb":[[3,3.72]],"id":37174579}],"con":true,"img":false}]}
{"op":"mcm","clk":"5346576924","pt":1646091133749,"mc":[{"id":"1.195395444","rc":[{"atb":[[1.86,75.09]],"id":42070475}],"con":true,"img":false}]}
{"op":"mcm","clk":"5346576926","pt":1646091133852,"mc":[{"id":"1.195395444","rc":[{"atb":[[1.81,0]],"id":42070475}],"con":true,"img":false}]}
{"op":"mcm","clk":"5346577001","pt":1646091136365,"mc":[{"id":"1.195395444","rc":[{"atb":[[1.85,9.83]],"id":42070475}],"con":true,"img":false}]}
{"op":"mcm","clk":"5346577058","pt":1646091137956,"mc":[{"id":"1.195395444","rc":[{"atb":[[3,7.9]],"id":37174579}],"con":true,"img":false}]}
{"op":"mcm","clk":"5346577109","pt":1646091139750,"mc":[{"id":"1.195395444","rc":[{"atb":[[1.45,147.41]],"id":42070475},{"atb":[[1.51,137.81]],"id":42236682}],"con":true,"img":false}]}
{"op":"mcm","clk":"5346577203","pt":1646091142322,"mc":[{"id":"1.195395444","rc":[{"atb":[[1.9,8.27]],"id":42070475}],"con":true,"img":false}]}
{"op":"mcm","clk":"5346577349","pt":1646091146469,"mc":[{"id":"1.195395444","rc":[{"atb":[[2.94,0],[3.05,20.92]],"id":37174579}],"con":true,"img":false}]}
{"op":"mcm","clk":"5346577419","pt":1646091148269,"mc":[{"id":"1.195395444","rc":[{"atb":[[3,4.18]],"id":37174579}],"con":true,"img":false}]}
{"op":"mcm","clk":"5346577488","pt":1646091150061,"mc":[{"id":"1.195395444","rc":[{"atb":[[1.85,0]],"id":42070475}],"con":true,"img":false}]}
{"op":"mcm","clk":"5346577633","pt":1646091154268,"mc":[{"id":"1.195395444","rc":[{"atb":[[2.96,3.8]],"id":37174579}],"con":true,"img":false}]}
{"op":"mcm","clk":"5346577706","pt":1646091156063,"mc":[{"id":"1.195395444","rc":[{"atb":[[1.9,17.56]],"id":42070475}],"con":true,"img":false}]}
{"op":"mcm","clk":"5346577801","pt":1646091158779,"mc":[{"id":"1.195395444","rc":[{"atb":[[1.91,75.09],[1.86,0]],"id":42070475}],"con":true,"img":false}]}
{"op":"mcm","clk":"5346577817","pt":1646091159243,"mc":[{"id":"1.195395444","rc":[{"atl":[[25,16.63]],"id":40917095},{"atl":[[28,14.46]],"id":42189436},{"atl":[[15.5,24.27]],"id":42236670},{"atb":[[1.45,102.8]],"id":42070475},{"atl":[[9,34.57]],"id":41523279},{"atb":[[1.51,95.24]],"id":42236682},{"atl":[[8.8,38.7]],"id":42236682},{"atl":[[17,21.18]],"id":37174579}],"con":true,"img":false}]}
{"op":"mcm","clk":"5346577854","pt":1646091160173,"mc":[{"id":"1.195395444","rc":[{"atb":[[1.9,9.28]],"id":42070475}],"con":true,"img":false}]}
{"op":"mcm","clk":"5346577923","pt":1646091161968,"mc":[{"id":"1.195395444","rc":[{"atb":[[3,0]],"id":37174579}],"con":true,"img":false}]}
{"op":"mcm","clk":"5346577925","pt":1646091162073,"mc":[{"id":"1.195395444","rc":[{"atb":[[2.98,41.84],[3.05,0]],"id":37174579}],"con":true,"img":false}]}
{"op":"mcm","clk":"5346577984","pt":1646091163255,"mc":[{"id":"1.195395444","rc":[{"atb":[[2.96,0]],"id":37174579}],"con":true,"img":false}]}
{"op":"mcm","clk":"5346578102","pt":1646091166290,"mc":[{"id":"1.195395444","rc":[{"atb":[[1.95,7.84]],"id":42070475}],"con":true,"img":false}]}
{"op":"mcm","clk":"5346578108","pt":1646091166393,"mc":[{"id":"1.195395444","rc":[{"atb":[[1.96,9.29]],"id":42070475}],"con":true,"img":false}]}
{"op":"mcm","clk":"5346578111","pt":1646091166494,"mc":[{"id":"1.195395444","rc":[{"atb":[[1.91,0]],"id":42070475}],"con":true,"img":false}]}
{"op":"mcm","clk":"5346578139","pt":1646091167161,"mc":[{"id":"1.195395444","rc":[{"atb":[[2.98,0],[2.94,51.55]],"id":37174579}],"con":true,"img":false}]}
{"op":"mcm","clk":"5346578234","pt":1646091169368,"mc":[{"id":"1.195395444","rc":[{"atb":[[1.95,0]],"id":42070475}],"con":true,"img":false}]}
{"op":"mcm","clk":"5346578282","pt":1646091171476,"mc":[{"id":"1.195395444","rc":[{"atb":[[1.91,40.59]],"id":42070475}],"con":true,"img":false}]}
{"op":"mcm","clk":"5346578286","pt":1646091171578,"mc":[{"id":"1.195395444","rc":[{"atb":[[1.96,0]],"id":42070475}],"con":true,"img":false}]}
{"op":"mcm","clk":"5346578306","pt":1646091172401,"mc":[{"id":"1.195395444","rc":[{"atb":[[2.54,63.56],[2.7,0]],"id":40917095},{"atb":[[2.74,54.24],[2.94,0]],"id":42189436},{"atl":[[10,6.86],[9.4,1.42]],"id":42189436},{"atb":[[2.36,73.53],[2.52,26.7]],"id":42236670},{"atl":[[6.6,2.14],[7,8.56]],"id":42236670},{"atb":[[1.8,275.18],[1.86,40.59]],"id":42236682}],"con":true,"img":false}]}
{"op":"mcm","clk":"5346578368","pt":1646091174099,"mc":[{"id":"1.195395444","rc":[{"atb":[[1.9,0]],"id":42070475}],"con":true,"img":false}]}
{"op":"mcm","clk":"5346578413","pt":1646091175282,"mc":[{"id":"1.195395444","rc":[{"atb":[[3,3.72]],"id":37174579}],"con":true,"img":false}]}
{"op":"mcm","clk":"5346578471","pt":1646091176670,"mc":[{"id":"1.195395444","rc":[{"atb":[[1.81,81.18],[1.91,0]],"id":42070475}],"con":true,"img":false}]}
{"op":"mcm","clk":"5346578488","pt":1646091177186,"mc":[{"id":"1.195395444","rc":[{"atb":[[2.72,0]],"id":40917095},{"atl":[[25,2.7]],"id":40917095},{"atl":[[28,2.7]],"id":42189436},{"atl":[[15.5,3.72]],"id":42236670},{"atl":[[9,6.67]],"id":41523279},{"atl":[[8.8,6.73]],"id":42236682},{"atl":[[17,2.82]],"id":37174579}],"con":true,"img":false}]}
{"op":"mcm","clk":"5346578494","pt":1646091177285,"mc":[{"id":"1.195395444","rc":[{"atb":[[2.56,31.78]],"id":40917095}],"con":true,"img":false}]}
{"op":"mcm","clk":"5346578562","pt":1646091180407,"mc":[{"id":"1.195395444","rc":[{"atb":[[3,7.9]],"id":37174579}],"con":true,"img":false}]}
{"op":"mcm","clk":"5346578651","pt":1646091184410,"mc":[{"id":"1.195395444","rc":[{"atb":[[1.85,8.76]],"id":42070475}],"con":true,"img":false}]}
{"op":"mcm","clk":"5346578713","pt":1646091186820,"mc":[{"id":"1.195395444","rc":[{"atb":[[3.05,20.92]],"id":37174579}],"con":true,"img":false}]}
{"op":"mcm","clk":"5346578718","pt":1646091186873,"mc":[{"id":"1.195395444","rc":[{"atb":[[2.94,0]],"id":37174579}],"con":true,"img":false}]}
{"op":"mcm","clk":"5346578738","pt":1646091187391,"mc":[{"id":"1.195395444","rc":[{"atb":[[3,4.18]],"id":37174579}],"con":true,"img":false}]}
{"op":"mcm","clk":"5346578898","pt":1646091192136,"mc":[{"id":"1.195395444","rc":[{"atb":[[1.85,18.59]],"id":42070475}],"con":true,"img":false}]}
{"op":"mcm","clk":"5346578939","pt":1646091193291,"mc":[{"id":"1.195395444","rc":[{"atb":[[2.96,3.8]],"id":37174579}],"con":true,"img":false}]}
{"op":"mcm","clk":"5346579008","pt":1646091195285,"mc":[{"id":"1.195395444","rc":[{"atl":[[16.5,0],[23,1.84],[25,0]],"id":40917095},{"atb":[[3,0],[3.3,0],[2.08,56.5]],"id":42189436},{"atb":[[1.51,137.81]],"id":42236682},{"atl":[[17,0]],"id":37174579}],"con":true,"img":false}]}
{"op":"mcm","clk":"5346579010","pt":1646091195388,"mc":[{"id":"1.195395444","rc":[{"atl":[[32,2.7]],"id":40917095},{"atb":[[3.25,18.03]],"id":42189436},{"atl":[[20,2.82]],"id":37174579}],"con":true,"img":false}]}
{"op":"mcm","clk":"5346579197","pt":1646091201235,"mc":[{"id":"1.195395444","rc":[{"atb":[[1.86,75.09]],"id":42070475}],"con":true,"img":false}]}
{"op":"mcm","clk":"5346579200","pt":1646091201287,"mc":[{"id":"1.195395444","rc":[{"atb":[[1.81,0]],"id":42070475}],"con":true,"img":false}]}
{"op":"mcm","clk":"5346579238","pt":1646091202322,"mc":[{"id":"1.195395444","rc":[{"atb":[[1.85,9.83]],"id":42070475}],"con":true,"img":false}]}
{"op":"mcm","clk":"5346579292","pt":1646091203918,"mc":[{"id":"1.195395444","rc":[{"atb":[[3,0]],"id":37174579}],"con":true,"img":false}]}
{"op":"mcm","clk":"5346579295","pt":1646091204022,"mc":[{"id":"1.195395444","rc":[{"atb":[[2.98,41.84]],"id":37174579}],"con":true,"img":false}]}
{"op":"mcm","clk":"5346579296","pt":1646091204123,"mc":[{"id":"1.195395444","rc":[{"atb":[[3.05,0]],"id":37174579}],"con":true,"img":false}]}
{"op":"mcm","clk":"5346579337","pt":1646091205411,"mc":[{"id":"1.195395444","rc":[{"atb":[[2.96,0]],"id":37174579}],"con":true,"img":false}]}
{"op":"mcm","clk":"5346579339","pt":1646091205513,"mc":[{"id":"1.195395444","rc":[{"atb":[[2.98,0],[2.94,51.55]],"id":37174579}],"con":true,"img":false}]}
{"op":"mcm","clk":"5346579446","pt":1646091208335,"mc":[{"id":"1.195395444","rc":[{"atb":[[1.9,8.27]],"id":42070475}],"con":true,"img":false}]}
{"op":"mcm","clk":"5346579592","pt":1646091213311,"mc":[{"id":"1.195395444","rc":[{"atl":[[9.8,4.61]],"id":42189436},{"atl":[[6.8,6.99]],"id":42236670},{"atl":[[7,0]],"id":41523279},{"atl":[[4.9,0]],"id":42236682}],"con":true,"img":false}]}
{"op":"mcm","clk":"5346579594","pt":1646091213413,"mc":[{"id":"1.195395444","rc":[{"atl":[[19.5,0]],"id":42189436},{"atl":[[11,0]],"id":42236670},{"atl":[[6.2,6.76]],"id":41523279},{"atl":[[3.9,12.68]],"id":42236682}],"con":true,"img":false}]}
{"op":"mcm","clk":"5346579595","pt":1646091213517,"mc":[{"id":"1.195395444","rc":[{"atl":[[3.95,0],[3.9,25.37]],"id":42236682}],"con":true,"img":false}]}
{"op":"mcm","clk":"5346579598","pt":1646091213619,"mc":[{"id":"1.195395444","rc":[{"atl":[[3.95,25.38],[3.9,12.68]],"id":42236682}],"con":true,"img":false}]}
{"op":"mcm","clk":"5346579601","pt":1646091213722,"mc":[{"id":"1.195395444","rc":[{"atl":[[3.95,0],[3.9,16.68]],"id":42236682}],"con":true,"img":false}]}
{"op":"mcm","clk":"5346579620","pt":1646091214440,"mc":[{"id":"1.195395444","rc":[{"atb":[[3,3.72]],"id":37174579}],"con":true,"img":false}]}
{"op":"mcm","clk":"5346579657","pt":1646091215930,"mc":[{"id":"1.195395444","rc":[{"atb":[[1.85,0]],"id":42070475}],"con":true,"img":false}]}
{"op":"mcm","clk":"5346579822","pt":1646091222033,"mc":[{"id":"1.195395444","rc":[{"atb":[[1.9,17.56]],"id":42070475},{"atb":[[3,7.9]],"id":37174579}],"con":true,"img":false}]}
{"op":"mcm","clk":"5346579926","pt":1646091225541,"mc":[{"id":"1.195395444","rc":[{"atb":[[1.91,75.09],[1.86,0]],"id":42070475}],"con":true,"img":false}]}
{"op":"mcm","clk":"5346579959","pt":1646091226517,"mc":[{"id":"1.195395444","rc":[{"atb":[[1.9,9.28]],"id":42070475}],"con":true,"img":false}]}
{"op":"mcm","clk":"5346580057","pt":1646091229755,"mc":[{"id":"1.195395444","rc":[{"atl":[[32,13.35]],"id":40917095},{"atl":[[21,12.79],[28,0]],"id":42189436},{"atl":[[15.5,23.2]],"id":42236670},{"atl":[[8,0],[6.2,36.5]],"id":42070475},{"atb":[[1.51,95.24]],"id":42236682},{"atl":[[8.8,36.52],[5.7,8.28],[3.9,4]],"id":42236682},{"atb":[[2.3,43.74],[2.14,0]],"id":37174579},{"atl":[[20,21.18]],"id":37174579}],"con":true,"img":false}]}
{"op":"mcm","clk":"5346580058","pt":1646091229857,"mc":[{"id":"1.195395444","rc":[{"atl":[[3.95,8],[3.9,0]],"id":42236682},{"atb":[[2.94,0],[3.05,20.92]],"id":37174579}],"con":true,"img":false}]}
{"op":"mcm","clk":"5346580061","pt":1646091229959,"mc":[{"id":"1.195395444","rc":[{"atl":[[6.2,0]],"id":42070475},{"atl":[[9,32.77]],"id":41523279}],"con":true,"img":false}]}
{"op":"mcm","clk":"5346580063","pt":1646091230064,"mc":[{"id":"1.195395444","rc":[{"atl":[[7.8,36.5]],"id":42070475}],"con":true,"img":false}]}
{"op":"mcm","clk":"5346580148","pt":1646091232632,"mc":[{"id":"1.195395444","rc":[{"atb":[[1.95,7.84]],"id":42070475},{"atb":[[3,4.18]],"id":37174579}],"con":true,"img":false}]}
{"op":"mcm","clk":"5346580345","pt":1646091238431,"mc":[{"id":"1.195395444","rc":[{"atb":[[2.96,3.8]],"id":37174579}],"con":true,"img":false}]}
{"op":"mcm","clk":"5346580385","pt":1646091240443,"mc":[{"id":"1.195395444","rc":[{"atb":[[1.9,0]],"id":42070475}],"con":true,"img":false}]}
{"op":"mcm","clk":"5346580586","pt":1646091246353,"mc":[{"id":"1.195395444","rc":[{"atb":[[3,0]],"id":37174579}],"con":true,"img":false}]}
{"op":"mcm","clk":"5346580589","pt":1646091246455,"mc":[{"id":"1.195395444","rc":[{"atb":[[2.98,41.84],[3.05,0]],"id":37174579}],"con":true,"img":false}]}
{"op":"mcm","clk":"5346580592","pt":1646091246659,"mc":[{"id":"1.195395444","rc":[{"atb":[[1.95,16.65]],"id":42070475}],"con":true,"img":false}]}
{"op":"mcm","clk":"5346580611","pt":1646091247273,"mc":[{"id":"1.195395444","rc":[{"atb":[[2.92,0]],"id":37174579}],"con":true,"img":false}]}
{"op":"mcm","clk":"5346580612","pt":1646091247376,"mc":[{"id":"1.195395444","rc":[{"atb":[[2.96,24.72]],"id":37174579}],"con":true,"img":false}]}
{"op":"mcm","clk":"5346580649","pt":1646091248564,"mc":[{"id":"1.195395444","rc":[{"atb":[[2.96,20.92]],"id":37174579}],"con":true,"img":false}]}
{"op":"mcm","clk":"5346580672","pt":1646091249644,"mc":[{"id":"1.195395444","rc":[{"atb":[[1.96,75.09]],"id":42070475}],"con":true,"img":false}]}
{"op":"mcm","clk":"5346580677","pt":1646091249746,"mc":[{"id":"1.195395444","rc":[{"atb":[[1.91,0]],"id":42070475}],"con":true,"img":false}]}
{"op":"mcm","clk":"5346580705","pt":1646091250566,"mc":[{"id":"1.195395444","rc":[{"atb":[[1.95,8.8]],"id":42070475}],"con":true,"img":false}]}
{"op":"mcm","clk":"5346580801","pt":1646091253594,"mc":[{"id":"1.195395444","rc":[{"atb":[[3.05,3.63]],"id":37174579}],"con":true,"img":false}]}
{"op":"mcm","clk":"5346580913","pt":1646091256574,"mc":[{"id":"1.195395444","rc":[{"atb":[[2,7.45]],"id":42070475}],"con":true,"img":false}]}
{"op":"mcm","clk":"5346581075","pt":1646091262586,"mc":[{"id":"1.195395444","rc":[{"atb":[[2.08,0]],"id":42189436},{"atl":[[5.7,0],[3.9,13.99]],"id":42236682},{"atb":[[2.96,0]],"id":37174579}],"con":true,"img":false}]}
{"op":"mcm","clk":"5346581076","pt":1646091262691,"mc":[{"id":"1.195395444","rc":[{"atb":[[2.22,56.5]],"id":42189436},{"atl":[[3.95,0],[3.9,21.99]],"id":42236682},{"atb":[[2.92,20.92]],"id":37174579}],"con":true,"img":false}]}
{"op":"mcm","clk":"5346581108","pt":1646091263970,"mc":[{"id":"1.195395444","rc":[{"atb":[[1.95,0]],"id":42070475}],"con":true,"img":false}]}
{"op":"mcm","clk":"5346581113","pt":1646091264176,"mc":[{"id":"1.195395444","rc":[{"atb":[[3.05,7.71]],"id":37174579}],"con":true,"img":false}]}
{"op":"mcm","clk":"5346581267","pt":1646091269974,"mc":[{"id":"1.195395444","rc":[{"atb":[[2,15.81]],"id":42070475}],"con":true,"img":false}]}
{"op":"mcm","clk":"5346581278","pt":1646091270281,"mc":[{"id":"1.195395444","rc":[{"atb":[[3.1,20.92]],"id":37174579}],"con":true,"img":false}]}
{"op":"mcm","clk":"5346581283","pt":1646091270384,"mc":[{"id":"1.195395444","rc":[{"atb":[[2.98,0]],"id":37174579}],"con":true,"img":false}]}
{"op":"mcm","clk":"5346581315","pt":1646091271614,"mc":[{"id":"1.195395444","rc":[{"atb":[[3.05,4.07]],"id":37174579}],"con":true,"img":false}]}
{"op":"mcm","clk":"5346581367","pt":1646091273511,"mc":[{"id":"1.195395444","rc":[{"atb":[[2.02,75.09]],"id":42070475}],"con":true,"img":false}]}
{"op":"mcm","clk":"5346581370","pt":1646091273616,"mc":[{"id":"1.195395444","rc":[{"atb":[[1.96,0]],"id":42070475}],"con":true,"img":false}]}
{"op":"mcm","clk":"5346581389","pt":1646091274487,"mc":[{"id":"1.195395444","rc":[{"atb":[[2,8.36]],"id":42070475}],"con":true,"img":false}]}
{"op":"mcm","clk":"5346581496","pt":1646091277615,"mc":[{"id":"1.195395444","rc":[{"atb":[[2.96,3.8]],"id":37174579}],"con":true,"img":false}]}
{"op":"mcm","clk":"5346581515","pt":1646091278077,"mc":[{"id":"1.195395444","rc":[{"atb":[[3.25,0]],"id":42189436},{"atb":[[1.45,0],[1.52,77.36]],"id":42070475}],"con":true,"img":false}]}
{"op":"mcm","clk":"5346581519","pt":1646091278180,"mc":[{"id":"1.195395444","rc":[{"atb":[[3.5,18.03]],"id":42189436}],"con":true,"img":false}]}
{"op":"mcm","clk":"5346581609","pt":1646091280702,"mc":[{"id":"1.195395444","rc":[{"atb":[[2.06,7.02]],"id":42070475}],"con":true,"img":false}]}
{"op":"mcm","clk":"5346581832","pt":1646091288502,"mc":[{"id":"1.195395444","rc":[{"atb":[[2,0]],"id":42070475},{"atb":[[3.05,0]],"id":37174579}],"con":true,"img":false}]}
{"op":"mcm","clk":"5346581835","pt":1646091288600,"mc":[{"id":"1.195395444","rc":[{"atb":[[2.98,41.84]],"id":37174579}],"con":true,"img":false}]}
{"op":"mcm","clk":"5346581839","pt":1646091288705,"mc":[{"id":"1.195395444","rc":[{"atb":[[3.1,0]],"id":37174579}],"con":true,"img":false}]}
{"op":"mcm","clk":"5346581885","pt":1646091289628,"mc":[{"id":"1.195395444","rc":[{"atb":[[2.96,0]],"id":37174579}],"con":true,"img":false}]}
{"op":"mcm","clk":"5346582002","pt":1646091293535,"mc":[{"id":"1.195395444","rc":[{"atb":[[3.5,0]],"id":42189436}],"con":true,"img":false}]}
{"op":"mcm","clk":"5346582005","pt":1646091293640,"mc":[{"id":"1.195395444","rc":[{"atb":[[3.25,18.03]],"id":42189436}],"con":true,"img":false}]}
{"op":"mcm","clk":"5346582008","pt":1646091293740,"mc":[{"id":"1.195395444","rc":[{"atb":[[2.98,0],[2.94,51.55]],"id":37174579}],"con":true,"img":false}]}
{"op":"mcm","clk":"5346582053","pt":1646091295226,"mc":[{"id":"1.195395444","rc":[{"atb":[[2.06,14.91]],"id":42070475}],"con":true,"img":false}]}
{"op":"mcm","clk":"5346582106","pt":1646091297123,"mc":[{"id":"1.195395444","rc":[{"atb":[[2.02,0],[2.08,75.09]],"id":42070475}],"con":true,"img":false}]}
{"op":"mcm","clk":"5346582164","pt":1646091298612,"mc":[{"id":"1.195395444","rc":[{"atb":[[2.06,7.88]],"id":42070475}],"con":true,"img":false}]}
{"op":"mcm","clk":"5346582309","pt":1646091302049,"mc":[{"id":"1.195395444","rc":[{"atb":[[3,3.72]],"id":37174579}],"con":true,"img":false}]}
{"op":"mcm","clk":"5346582390","pt":1646091304727,"mc":[{"id":"1.195395444","rc":[{"atb":[[2.12,6.65]],"id":42070475}],"con":true,"img":false}]}
{"op":"mcm","clk":"5346582459","pt":1646091307135,"mc":[{"id":"1.195395444","rc":[{"atb":[[3,7.9]],"id":37174579}],"con":true,"img":false}]}
{"op":"mcm","clk":"5346582494","pt":1646091307953,"mc":[{"id":"1.195395444","rc":[{"atl":[[3.9,8]],"id":42236682}],"con":true,"img":false}]}
{"op":"mcm","clk":"5346582499","pt":1646091308008,"mc":[{"id":"1.195395444","rc":[{"atl":[[3.85,13.99]],"id":42236682}],"con":true,"img":false}]}
{"op":"mcm","clk":"5346582503","pt":1646091308110,"mc":[{"id":"1.195395444","rc":[{"atl":[[3.95,16],[3.9,0]],"id":42236682}],"con":true,"img":false}]}
{"op":"mcm","clk":"5346582611","pt":1646091312022,"mc":[{"id":"1.195395444","rc":[{"atb":[[2.94,0],[3.05,20.92]],"id":37174579}],"con":true,"img":false}]}
{"op":"mcm","clk":"5346582629","pt":1646091312740,"mc":[{"id":"1.195395444","rc":[{"atb":[[2.06,0]],"id":42070475}],"con":true,"img":false}]}
{"op":"mcm","clk":"5346582651","pt":1646091313617,"mc":[{"id":"1.195395444","rc":[{"atb":[[3,4.18]],"id":37174579}],"con":true,"img":false}]}
{"op":"mcm","clk":"5346582770","pt":1646091318554,"mc":[{"id":"1.195395444","rc":[{"atb":[[2.12,14.12]],"id":42070475}],"con":true,"img":false}]}
{"op":"mcm","clk":"5346582801","pt":1646091319635,"mc":[{"id":"1.195395444","rc":[{"atb":[[2.96,3.8]],"id":37174579}],"con":true,"img":false}]}
{"op":"mcm","clk":"5346582875","pt":1646091322351,"mc":[{"id":"1.195395444","rc":[{"atl":[[3.85,0]],"id":42236682}],"con":true,"img":false}]}
{"op":"mcm","clk":"5346582878","pt":1646091322456,"mc":[{"id":"1.195395444","rc":[{"atl":[[3.9,13.99]],"id":42236682}],"con":true,"img":false}]}
{"op":"mcm","clk":"5346582951","pt":1646091324969,"mc":[{"id":"1.195395444","rc":[{"atb":[[3,0]],"id":37174579}],"con":true,"img":false}]}
{"op":"mcm","clk":"5346582954","pt":1646091325071,"mc":[{"id":"1.195395444","rc":[{"atb":[[2.98,41.84]],"id":37174579}],"con":true,"img":false}]}
{"op":"mcm","clk":"5346582957","pt":1646091325174,"mc":[{"id":"1.195395444","rc":[{"atb":[[3.05,0]],"id":37174579}],"con":true,"img":false}]}
{"op":"mcm","clk":"5346582970","pt":1646091325636,"mc":[{"id":"1.195395444","rc":[{"atb":[[2.96,0]],"id":37174579}],"con":true,"img":false}]}
{"op":"mcm","clk":"5346583082","pt":1646091330148,"mc":[{"id":"1.195395444","rc":[{"atb":[[2.98,0],[2.94,51.55]],"id":37174579}],"con":true,"img":false}]}
{"op":"mcm","clk":"5346583110","pt":1646091331376,"mc":[{"id":"1.195395444","rc":[{"atl":[[3.95,0],[3.9,27.99]],"id":42236682}],"con":true,"img":false}]}
{"op":"mcm","clk":"5346583272","pt":1646091337789,"mc":[{"id":"1.195395444","rc":[{"atb":[[3,3.72]],"id":37174579}],"con":true,"img":false}]}
{"op":"mcm","clk":"5346583321","pt":1646091339587,"mc":[{"id":"1.195395444","rc":[{"atl":[[38,12.7]],"id":40917095}],"con":true,"img":false}]}
{"op":"mcm","clk":"5346583324","pt":1646091339690,"mc":[{"id":"1.195395444","rc":[{"atl":[[32,0]],"id":40917095},{"atb":[[3.25,0]],"id":42189436}],"con":true,"img":false}]}
{"op":"mcm","clk":"5346583327","pt":1646091339793,"mc":[{"id":"1.195395444","rc":[{"atb":[[3.5,18.03]],"id":42189436}],"con":true,"img":false}]}
{"op":"mcm","clk":"5346583403","pt":1646091342458,"mc":[{"id":"1.195395444","rc":[{"atb":[[3,7.9]],"id":37174579}],"con":true,"img":false}]}
{"op":"mcm","clk":"5346583788","pt":1646091353200,"mc":[{"id":"1.195395444","rc":[{"atb":[[2.94,0],[3.05,20.92]],"id":37174579}],"con":true,"img":false}]}
{"op":"mcm","clk":"5346583853","pt":1646091355782,"mc":[{"id":"1.195395444","rc":[{"atb":[[3,4.18]],"id":37174579}],"con":true,"img":false}]}
{"op":"mcm","clk":"5346583984","pt":1646091361782,"mc":[{"id":"1.195395444","rc":[{"atb":[[2.96,3.8]],"id":37174579}],"con":true,"img":false}]}
{"op":"mcm","clk":"5346584208","pt":1646091371328,"mc":[{"id":"1.195395444","rc":[{"atb":[[3,0]],"id":37174579}],"con":true,"img":false}]}
{"op":"mcm","clk":"5346584216","pt":1646091371533,"mc":[{"id":"1.195395444","rc":[{"atb":[[2.98,41.84],[3.05,0]],"id":37174579}],"con":true,"img":false}]}
{"op":"mcm","clk":"5346584228","pt":1646091371995,"mc":[{"id":"1.195395444","rc":[{"atl":[[3.9,14]],"id":42236682}],"con":true,"img":false}]}
{"op":"mcm","clk":"5346584230","pt":1646091372100,"mc":[{"id":"1.195395444","rc":[{"atl":[[3.85,13.99],[3.95,28],[3.9,0]],"id":42236682}],"con":true,"img":false}]}
{"op":"mcm","clk":"5346584234","pt":1646091372201,"mc":[{"id":"1.195395444","rc":[{"atl":[[3.95,0],[3.9,28]],"id":42236682}],"con":true,"img":false}]}
{"op":"mcm","clk":"5346584284","pt":1646091373808,"mc":[{"id":"1.195395444","rc":[{"atb":[[2.96,0]],"id":37174579}],"con":true,"img":false}]}
{"op":"mcm","clk":"5346584287","pt":1646091373911,"mc":[{"id":"1.195395444","rc":[{"atb":[[2.98,0],[2.94,51.55]],"id":37174579}],"con":true,"img":false}]}
{"op":"mcm","clk":"5346584512","pt":1646091382837,"mc":[{"id":"1.195395444","rc":[{"atb":[[3,3.72]],"id":37174579}],"con":true,"img":false}]}
{"op":"mcm","clk":"5346584653","pt":1646091388750,"mc":[{"id":"1.195395444","rc":[{"atb":[[3,7.9]],"id":37174579}],"con":true,"img":false}]}
{"op":"mcm","clk":"5346584862","pt":1646091396562,"mc":[{"id":"1.195395444","rc":[{"atb":[[2.94,0],[3.05,20.92]],"id":37174579}],"con":true,"img":false}]}
{"op":"mcm","clk":"5346584891","pt":1646091397744,"mc":[{"id":"1.195395444","rc":[{"atb":[[3,4.18]],"id":37174579}],"con":true,"img":false}]}
{"op":"mcm","clk":"5346585065","pt":1646091403752,"mc":[{"id":"1.195395444","rc":[{"atb":[[2.96,3.8]],"id":37174579}],"con":true,"img":false}]}
{"op":"mcm","clk":"5346585314","pt":1646091412754,"mc":[{"id":"1.195395444","rc":[{"atb":[[3,0]],"id":37174579}],"con":true,"img":false}]}
{"op":"mcm","clk":"5346585316","pt":1646091412855,"mc":[{"id":"1.195395444","rc":[{"atb":[[2.98,41.84],[3.05,0]],"id":37174579}],"con":true,"img":false}]}
{"op":"mcm","clk":"5346585344","pt":1646091413774,"mc":[{"id":"1.195395444","rc":[{"atb":[[2.96,0]],"id":37174579}],"con":true,"img":false}]}
{"op":"mcm","clk":"5346585350","pt":1646091413979,"mc":[{"id":"1.195395444","rc":[{"atb":[[2.98,0],[2.94,51.55]],"id":37174579}],"con":true,"img":false}]}
{"op":"mcm","clk":"5346585465","pt":1646091417741,"mc":[{"id":"1.195395444","rc":[{"atb":[[3.5,0]],"id":42189436}],"con":true,"img":false}]}
{"op":"mcm","clk":"5346585469","pt":1646091417844,"mc":[{"id":"1.195395444","rc":[{"atb":[[3.25,18.03]],"id":42189436}],"con":true,"img":false}]}
{"op":"mcm","clk":"5346585596","pt":1646091421872,"mc":[{"id":"1.195395444","rc":[{"atb":[[3,3.72]],"id":37174579}],"con":true,"img":false}]}
{"op":"mcm","clk":"5346585599","pt":1646091421973,"mc":[{"id":"1.195395444","rc":[{"atb":[[2.94,0],[3.05,20.92]],"id":37174579}],"con":true,"img":false}]}
{"op":"mcm","clk":"5346585687","pt":1646091424855,"mc":[{"id":"1.195395444","rc":[{"atb":[[3,0]],"id":37174579}],"con":true,"img":false}]}
{"op":"mcm","clk":"5346585693","pt":1646091424960,"mc":[{"id":"1.195395444","rc":[{"atb":[[2.94,41.84],[3.05,0]],"id":37174579}],"con":true,"img":false}]}
{"op":"mcm","clk":"5346585949","pt":1646091433867,"mc":[{"id":"1.195395444","rc":[{"atb":[[3,3.72]],"id":37174579}],"con":true,"img":false}]}
{"op":"mcm","clk":"5346586212","pt":1646091442807,"mc":[{"id":"1.195395444","rc":[{"atb":[[3,7.9]],"id":37174579}],"con":true,"img":false}]}
{"op":"mcm","clk":"5346586351","pt":1646091447121,"mc":[{"id":"1.195395444","rc":[{"atb":[[2.94,0],[3.05,20.92]],"id":37174579}],"con":true,"img":false}]}
{"op":"mcm","clk":"5346586399","pt":1646091448921,"mc":[{"id":"1.195395444","rc":[{"atb":[[3,4.18]],"id":37174579}],"con":true,"img":false}]}
{"op":"mcm","clk":"5346586416","pt":1646091449489,"mc":[{"id":"1.195395444","rc":[{"atl":[[23,0]],"id":40917095}],"con":true,"img":false}]}
{"op":"mcm","clk":"5346586418","pt":1646091449593,"mc":[{"id":"1.195395444","rc":[{"atl":[[26,1.84]],"id":40917095}],"con":true,"img":false}]}
{"op":"mcm","clk":"5346586587","pt":1646091454937,"mc":[{"id":"1.195395444","rc":[{"atb":[[2.96,3.8]],"id":37174579}],"con":true,"img":false}]}
{"op":"mcm","clk":"5346586756","pt":1646091460807,"mc":[{"id":"1.195395444","rc":[{"atb":[[3,0]],"id":37174579}],"con":true,"img":false}]}
{"op":"mcm","clk":"5346586759","pt":1646091460908,"mc":[{"id":"1.195395444","rc":[{"atb":[[2.98,41.84],[3.05,0]],"id":37174579}],"con":true,"img":false}]}
{"op":"mcm","clk":"5346586838","pt":1646091463842,"mc":[{"id":"1.195395444","rc":[{"atb":[[2.96,0]],"id":37174579}],"con":true,"img":false}]}
{"op":"mcm","clk":"5346586891","pt":1646091466050,"mc":[{"id":"1.195395444","rc":[{"atb":[[2.98,0],[2.94,51.55]],"id":37174579}],"con":true,"img":false}]}
{"op":"mcm","clk":"5346587058","pt":1646091472942,"mc":[{"id":"1.195395444","rc":[{"atb":[[3,3.72]],"id":37174579}],"con":true,"img":false}]}
{"op":"mcm","clk":"5346587064","pt":1646091473456,"mc":[{"id":"1.195395444","rc":[{"atb":[[3.25,0]],"id":42189436},{"atl":[[8.8,0],[7.8,35.81]],"id":42236682}],"con":true,"img":false}]}
{"op":"mcm","clk":"5346587065","pt":1646091473561,"mc":[{"id":"1.195395444","rc":[{"atb":[[3.5,18.03]],"id":42189436}],"con":true,"img":false}]}
{"op":"mcm","clk":"5346587165","pt":1646091478843,"mc":[{"id":"1.195395444","rc":[{"atb":[[3,7.9]],"id":37174579}],"con":true,"img":false}]}
{"op":"mcm","clk":"5346587261","pt":1646091482646,"mc":[{"id":"1.195395444","rc":[{"atb":[[2.94,0],[3.05,20.92]],"id":37174579}],"con":true,"img":false}]}
{"op":"mcm","clk":"5346587325","pt":1646091485067,"mc":[{"id":"1.195395444","rc":[{"atb":[[3,4.18]],"id":37174579}],"con":true,"img":false}]}
{"op":"mcm","clk":"5346587518","pt":1646091490869,"mc":[{"id":"1.195395444","rc":[{"atb":[[2.96,3.8]],"id":37174579}],"con":true,"img":false}]}
{"op":"mcm","clk":"5346587768","pt":1646091499292,"mc":[{"id":"1.195395444","rc":[{"atb":[[3,0]],"id":37174579}],"con":true,"img":false}]}
{"op":"mcm","clk":"5346587773","pt":1646091499348,"mc":[{"id":"1.195395444","rc":[{"atb":[[2.98,41.84]],"id":37174579}],"con":true,"img":false}]}
{"op":"mcm","clk":"5346587777","pt":1646091499449,"mc":[{"id":"1.195395444","rc":[{"atb":[[3.05,0]],"id":37174579}],"con":true,"img":false}]}
{"op":"mcm","clk":"5346587786","pt":1646091499961,"mc":[{"id":"1.195395444","rc":[{"atb":[[2.96,0]],"id":37174579}],"con":true,"img":false}]}
{"op":"mcm","clk":"5346587836","pt":1646091501856,"mc":[{"id":"1.195395444","rc":[{"atb":[[3.5,0]],"id":42189436}],"con":true,"img":false}]}
{"op":"mcm","clk":"5346587840","pt":1646091501958,"mc":[{"id":"1.195395444","rc":[{"atb":[[3.25,18.03]],"id":42189436}],"con":true,"img":false}]}
{"op":"mcm","clk":"5346587931","pt":1646091504472,"mc":[{"id":"1.195395444","rc":[{"atb":[[2.98,0],[2.94,51.55]],"id":37174579}],"con":true,"img":false}]}
{"op":"mcm","clk":"5346588169","pt":1646091512065,"mc":[{"id":"1.195395444","rc":[{"atb":[[3,3.72]],"id":37174579}],"con":true,"img":false}]}
{"op":"mcm","clk":"5346588401","pt":1646091519805,"mc":[{"id":"1.195395444","rc":[{"atb":[[2.92,0]],"id":37174579}],"con":true,"img":false}]}
{"op":"mcm","clk":"5346588402","pt":1646091519908,"mc":[{"id":"1.195395444","rc":[{"atb":[[2.96,20.92]],"id":37174579}],"con":true,"img":false}]}
{"op":"mcm","clk":"5346588414","pt":1646091520680,"mc":[{"id":"1.195395444","rc":[{"atb":[[3.05,20.92]],"id":37174579}],"con":true,"img":false}]}
{"op":"mcm","clk":"5346588415","pt":1646091520780,"mc":[{"id":"1.195395444","rc":[{"atb":[[2.94,0]],"id":37174579}],"con":true,"img":false}]}
{"op":"mcm","clk":"5346588526","pt":1646091524118,"mc":[{"id":"1.195395444","rc":[{"atb":[[3,0]],"id":37174579}],"con":true,"img":false}]}
{"op":"mcm","clk":"5346588571","pt":1646091525810,"mc":[{"id":"1.195395444","rc":[{"atb":[[2.98,41.84]],"id":37174579}],"con":true,"img":false}]}
{"op":"mcm","clk":"5346588573","pt":1646091525913,"mc":[{"id":"1.195395444","rc":[{"atb":[[3.05,0]],"id":37174579}],"con":true,"img":false}]}
{"op":"mcm","clk":"5346588801","pt":1646091533037,"mc":[{"id":"1.195395444","rc":[{"atb":[[3.05,3.63]],"id":37174579}],"con":true,"img":false}]}
{"op":"mcm","clk":"5346589000","pt":1646091540154,"mc":[{"id":"1.195395444","rc":[{"atb":[[3.05,7.71]],"id":37174579}],"con":true,"img":false}]}
{"op":"mcm","clk":"5346589062","pt":1646091541827,"mc":[{"id":"1.195395444","rc":[{"atb":[[3.1,20.92],[2.98,0]],"id":37174579}],"con":true,"img":false}]}
{"op":"mcm","clk":"5346589071","pt":1646091542341,"mc":[{"id":"1.195395444","rc":[{"atb":[[3.05,4.07]],"id":37174579}],"con":true,"img":false}]}
{"op":"mcm","clk":"5346589259","pt":1646091548039,"mc":[{"id":"1.195395444","rc":[{"atb":[[2.96,24.72]],"id":37174579}],"con":true,"img":false}]}
{"op":"mcm","clk":"5346589363","pt":1646091551333,"mc":[{"id":"1.195395444","rc":[{"atb":[[3.25,0]],"id":42189436},{"atl":[[13.5,22.88]],"id":42236670},{"atb":[[2.96,3.8]],"id":37174579}],"con":true,"img":false}]}
{"op":"mcm","clk":"5346589364","pt":1646091551431,"mc":[{"id":"1.195395444","rc":[{"atb":[[3.5,18.03]],"id":42189436},{"atl":[[15.5,0]],"id":42236670},{"atb":[[2.92,20.92]],"id":37174579}],"con":true,"img":false}]}
{"op":"mcm","clk":"5346589527","pt":1646091558729,"mc":[{"id":"1.195395444","rc":[{"atb":[[3.05,0]],"id":37174579}],"con":true,"img":false}]}
{"op":"mcm","clk":"5346589529","pt":1646091558829,"mc":[{"id":"1.195395444","rc":[{"atb":[[3.1,0],[2.98,41.84]],"id":37174579}],"con":true,"img":false}]}
{"op":"mcm","clk":"5346589563","pt":1646091560267,"mc":[{"id":"1.195395444","rc":[{"atb":[[2.96,0]],"id":37174579}],"con":true,"img":false}]}
{"op":"mcm","clk":"5346589658","pt":1646091564069,"mc":[{"id":"1.195395444","rc":[{"atb":[[2.98,0],[2.94,51.55]],"id":37174579}],"con":true,"img":false}]}
{"op":"mcm","clk":"5346589666","pt":1646091564377,"mc":[{"id":"1.195395444","rc":[{"atb":[[3.5,0]],"id":42189436}],"con":true,"img":false}]}
{"op":"mcm","clk":"5346589669","pt":1646091564479,"mc":[{"id":"1.195395444","rc":[{"atb":[[3.25,18.03]],"id":42189436}],"con":true,"img":false}]}
{"op":"mcm","clk":"5346589887","pt":1646091572070,"mc":[{"id":"1.195395444","rc":[{"atb":[[3,3.72]],"id":37174579}],"con":true,"img":false}]}
{"op":"mcm","clk":"5346590006","pt":1646091577062,"mc":[{"id":"1.195395444","rc":[{"atb":[[3,7.9]],"id":37174579}],"con":true,"img":false}]}
{"op":"mcm","clk":"5346590078","pt":1646091579577,"mc":[{"id":"1.195395444","rc":[{"atb":[[2.94,0],[3.05,20.92]],"id":37174579}],"con":true,"img":false}]}
{"op":"mcm","clk":"5346590125","pt":1646091581275,"mc":[{"id":"1.195395444","rc":[{"atb":[[3,4.18]],"id":37174579}],"con":true,"img":false}]}
{"op":"mcm","clk":"5346590220","pt":1646091583992,"mc":[{"id":"1.195395444","rc":[{"atb":[[2.36,0]],"id":42236670},{"atl":[[7,0]],"id":42236670},{"atb":[[1.87,114.94]],"id":42236682},{"atl":[[3.8,14]],"id":42236682}],"con":true,"img":false}]}
{"op":"mcm","clk":"5346590223","pt":1646091584094,"mc":[{"id":"1.195395444","rc":[{"atb":[[2.54,0],[2.66,47.67]],"id":40917095},{"atb":[[2.74,0],[2.9,52.63]],"id":42189436},{"atl":[[10,0],[9.4,6.03]],"id":42189436},{"atb":[[2.5,146.76]],"id":42236670},{"atl":[[6.8,13.99]],"id":42236670}],"con":true,"img":false}]}
{"op":"mcm","clk":"5346590225","pt":1646091584196,"mc":[{"id":"1.195395444","rc":[{"atl":[[9.6,4.61],[9.4,1.42]],"id":42189436},{"atb":[[1.8,150.18]],"id":42236682},{"atl":[[3.9,0]],"id":42236682}],"con":true,"img":false}]}
{"op":"mcm","clk":"5346590310","pt":1646091587174,"mc":[{"id":"1.195395444","rc":[{"atb":[[2.96,3.8]],"id":37174579}],"con":true,"img":false}]}
{"op":"mcm","clk":"5346590512","pt":1646091594714,"mc":[{"id":"1.195395444","rc":[{"atl":[[38,0],[44,10.38],[26,0]],"id":40917095}],"con":true,"img":false}]}
{"op":"mcm","clk":"5346590515","pt":1646091594817,"mc":[{"id":"1.195395444","rc":[{"atl":[[29,2.7]],"id":40917095}],"con":true,"img":false}]}
{"op":"mcm","clk":"5346590523","pt":1646091595078,"mc":[{"id":"1.195395444","rc":[{"atb":[[3,0]],"id":37174579}],"con":true,"img":false}]}
{"op":"mcm","clk":"5346590526","pt":1646091595179,"mc":[{"id":"1.195395444","rc":[{"atb":[[2.98,41.84],[3.05,0]],"id":37174579}],"con":true,"img":false}]}
{"op":"mcm","clk":"5346590545","pt":1646091596203,"mc":[{"id":"1.195395444","rc":[{"atb":[[2.96,0]],"id":37174579}],"con":true,"img":false}]}
{"op":"mcm","clk":"5346590677","pt":1646091600283,"mc":[{"id":"1.195395444","rc":[{"atb":[[2.94,51.55]],"id":37174579}],"con":true,"img":false}]}
{"op":"mcm","clk":"5346590680","pt":1646091600389,"mc":[{"id":"1.195395444","rc":[{"atb":[[2.98,0]],"id":37174579}],"con":true,"img":false}]}
{"op":"mcm","clk":"5346590893","pt":1646091607994,"mc":[{"id":"1.195395444","rc":[{"atb":[[1.86,0]],"id":42236682}],"con":true,"img":false}]}
{"op":"mcm","clk":"5346590898","pt":1646091608099,"mc":[{"id":"1.195395444","rc":[{"atb":[[1.88,40.59]],"id":42236682}],"con":true,"img":false}]}
{"op":"mcm","clk":"5346590905","pt":1646091608306,"mc":[{"id":"1.195395444","rc":[{"atb":[[3,3.72]],"id":37174579}],"con":true,"img":false}]}
{"op":"mcm","clk":"5346591129","pt":1646091615605,"mc":[{"id":"1.195395444","rc":[{"atb":[[3.05,20.92]],"id":37174579}],"con":true,"img":false}]}
{"op":"mcm","clk":"5346591132","pt":1646091615705,"mc":[{"id":"1.195395444","rc":[{"atb":[[2.94,0]],"id":37174579}],"con":true,"img":false}]}
{"op":"mcm","clk":"5346591176","pt":1646091617199,"mc":[{"id":"1.195395444","rc":[{"atb":[[3,0]],"id":37174579}],"con":true,"img":false}]}
{"op":"mcm","clk":"5346591264","pt":1646091620739,"mc":[{"id":"1.195395444","rc":[{"atb":[[2.94,41.84],[3.05,0]],"id":37174579}],"con":true,"img":false}]}
{"op":"mcm","clk":"5346591295","pt":1646091622332,"mc":[{"id":"1.195395444","rc":[{"atb":[[2.56,0]],"id":40917095},{"atl":[[9.8,0]],"id":42189436},{"atl":[[3.85,0]],"id":42236682}],"con":true,"img":false}]}
{"op":"mcm","clk":"5346591300","pt":1646091622434,"mc":[{"id":"1.195395444","rc":[{"atb":[[2.68,31.78]],"id":40917095},{"atl":[[9.4,6.03]],"id":42189436},{"atl":[[3.95,28],[3.8,0],[3.75,13.99]],"id":42236682}],"con":true,"img":false}]}
{"op":"mcm","clk":"5346591301","pt":1646091622537,"mc":[{"id":"1.195395444","rc":[{"atl":[[9.6,0],[9.4,10.64]],"id":42189436}],"con":true,"img":false}]}
{"op":"mcm","clk":"5346591460","pt":1646091629260,"mc":[{"id":"1.195395444","rc":[{"atb":[[3,3.72]],"id":37174579}],"con":true,"img":false}]}
{"op":"mcm","clk":"5346591631","pt":1646091637265,"mc":[{"id":"1.195395444","rc":[{"atb":[[3,7.9]],"id":37174579}],"con":true,"img":false}]}
{"op":"mcm","clk":"5346591671","pt":1646091638859,"mc":[{"id":"1.195395444","rc":[{"atl":[[9.4,6.03]],"id":42189436},{"atl":[[5.1,0]],"id":42070475},{"atl":[[3.75,0]],"id":42236682},{"atb":[[2.92,0]],"id":37174579}],"con":true,"img":false}]}
{"op":"mcm","clk":"5346591672","pt":1646091638968,"mc":[{"id":"1.195395444","rc":[{"atl":[[13,4.61]],"id":42189436},{"atl":[[5.7,9.89]],"id":42070475},{"atl":[[3.9,13.99]],"id":42236682},{"atb":[[2.96,20.92]],"id":37174579}],"con":true,"img":false}]}
{"op":"mcm","clk":"5346591728","pt":1646091640841,"mc":[{"id":"1.195395444","rc":[{"atb":[[2.94,0],[3.05,20.92]],"id":37174579}],"con":true,"img":false}]}
{"op":"mcm","clk":"5346591739","pt":1646091641249,"mc":[{"id":"1.195395444","rc":[{"atb":[[3,4.18]],"id":37174579}],"con":true,"img":false}]}
{"op":"mcm","clk":"5346591767","pt":1646091642578,"mc":[{"id":"1.195395444","rc":[{"atl":[[3.85,14],[3.95,0]],"id":42236682}],"con":true,"img":false}]}
{"op":"mcm","clk":"5346591894","pt":1646091647254,"mc":[{"id":"1.195395444","rc":[{"atb":[[2.96,24.72]],"id":37174579}],"con":true,"img":false}]}
{"op":"mcm","clk":"5346592036","pt":1646091653477,"mc":[{"id":"1.195395444","rc":[{"atl":[[29,0.86]],"id":40917095},{"atb":[[2.96,3.8]],"id":37174579}],"con":true,"img":false}]}
{"op":"mcm","clk":"5346592037","pt":1646091653580,"mc":[{"id":"1.195395444","rc":[{"atl":[[25,1.84]],"id":40917095},{"atb":[[2.92,20.92]],"id":37174579}],"con":true,"img":false}]}
{"op":"mcm","clk":"5346592064","pt":1646091654868,"mc":[{"id":"1.195395444","rc":[{"atb":[[3,0]],"id":37174579}],"con":true,"img":false}]}
{"op":"mcm","clk":"5346592066","pt":1646091654965,"mc":[{"id":"1.195395444","rc":[{"atb":[[2.98,41.84]],"id":37174579}],"con":true,"img":false}]}
{"op":"mcm","clk":"5346592069","pt":1646091655067,"mc":[{"id":"1.195395444","rc":[{"atb":[[3.05,0]],"id":37174579}],"con":true,"img":false}]}
{"op":"mcm","clk":"5346592098","pt":1646091656460,"mc":[{"id":"1.195395444","rc":[{"atb":[[2.96,0]],"id":37174579}],"con":true,"img":false}]}
{"op":"mcm","clk":"5346592102","pt":1646091656562,"mc":[{"id":"1.195395444","rc":[{"atb":[[2.98,0],[2.94,51.55]],"id":37174579}],"con":true,"img":false}]}
{"op":"mcm","clk":"5346592326","pt":1646091664675,"mc":[{"id":"1.195395444","rc":[{"atb":[[3,3.72]],"id":37174579}],"con":true,"img":false}]}
{"op":"mcm","clk":"5346592329","pt":1646091664776,"mc":[{"id":"1.195395444","rc":[{"atb":[[2.94,0],[3.05,20.92]],"id":37174579}],"con":true,"img":false}]}
{"op":"mcm","clk":"5346592401","pt":1646091667697,"mc":[{"id":"1.195395444","rc":[{"atb":[[3,0]],"id":37174579}],"con":true,"img":false}]}
{"op":"mcm","clk":"5346592463","pt":1646091669905,"mc":[{"id":"1.195395444","rc":[{"atb":[[2.94,41.84]],"id":37174579}],"con":true,"img":false}]}
{"op":"mcm","clk":"5346592467","pt":1646091670004,"mc":[{"id":"1.195395444","rc":[{"atb":[[3.05,0]],"id":37174579}],"con":true,"img":false}]}
{"op":"mcm","clk":"5346592626","pt":1646091676718,"mc":[{"id":"1.195395444","rc":[{"atb":[[3,3.72]],"id":37174579}],"con":true,"img":false}]}
{"op":"mcm","clk":"5346592777","pt":1646091682821,"mc":[{"id":"1.195395444","rc":[{"atl":[[5.7,0]],"id":42070475},{"atl":[[3.9,0]],"id":42236682}],"con":true,"img":false}]}
{"op":"mcm","clk":"5346592782","pt":1646091682925,"mc":[{"id":"1.195395444","rc":[{"atl":[[5.1,9.89]],"id":42070475},{"atl":[[3.8,13.99]],"id":42236682}],"con":true,"img":false}]}
{"op":"mcm","clk":"5346592785","pt":1646091683026,"mc":[{"id":"1.195395444","rc":[{"atl":[[3.85,0],[3.95,28]],"id":42236682}],"con":true,"img":false}]}
{"op":"mcm","clk":"5346592787","pt":1646091683081,"mc":[{"id":"1.195395444","rc":[{"atl":[[3.95,0],[3.75,14]],"id":42236682}],"con":true,"img":false}]}
{"op":"mcm","clk":"5346592797","pt":1646091683391,"mc":[{"id":"1.195395444","rc":[{"atb":[[3,7.9]],"id":37174579}],"con":true,"img":false}]}
{"op":"mcm","clk":"5346592968","pt":1646091689490,"mc":[{"id":"1.195395444","rc":[{"atb":[[2.94,0],[3.05,20.92]],"id":37174579}],"con":true,"img":false}]}
{"op":"mcm","clk":"5346593016","pt":1646091691736,"mc":[{"id":"1.195395444","rc":[{"atb":[[3,4.18]],"id":37174579}],"con":true,"img":false}]}
{"op":"mcm","clk":"5346593131","pt":1646091696521,"mc":[{"id":"1.195395444","rc":[{"atl":[[5.1,0]],"id":42070475}],"con":true,"img":false}]}
{"op":"mcm","clk":"5346593133","pt":1646091696623,"mc":[{"id":"1.195395444","rc":[{"atl":[[5.6,9.89]],"id":42070475}],"con":true,"img":false}]}
{"op":"mcm","clk":"5346593168","pt":1646091697706,"mc":[{"id":"1.195395444","rc":[{"atb":[[2.96,3.8]],"id":37174579}],"con":true,"img":false}]}
{"op":"mcm","clk":"5346593300","pt":1646091702928,"mc":[{"id":"1.195395444","rc":[{"atb":[[3,0]],"id":37174579}],"con":true,"img":false}]}
{"op":"mcm","clk":"5346593303","pt":1646091703033,"mc":[{"id":"1.195395444","rc":[{"atb":[[2.98,41.84]],"id":37174579}],"con":true,"img":false}]}
{"op":"mcm","clk":"5346593306","pt":1646091703130,"mc":[{"id":"1.195395444","rc":[{"atb":[[3.05,0]],"id":37174579}],"con":true,"img":false}]}
{"op":"mcm","clk":"5346593312","pt":1646091703335,"mc":[{"id":"1.195395444","rc":[{"atb":[[2.92,0]],"id":37174579}],"con":true,"img":false}]}
{"op":"mcm","clk":"5346593317","pt":1646091703438,"mc":[{"id":"1.195395444","rc":[{"atb":[[2.96,24.72]],"id":37174579}],"con":true,"img":false}]}
{"op":"mcm","clk":"5346593325","pt":1646091703747,"mc":[{"id":"1.195395444","rc":[{"atb":[[2.96,20.92]],"id":37174579}],"con":true,"img":false}]}
{"op":"mcm","clk":"5346593466","pt":1646091709738,"mc":[{"id":"1.195395444","rc":[{"atb":[[3.05,3.63]],"id":37174579}],"con":true,"img":false}]}
{"op":"mcm","clk":"5346593467","pt":1646091709838,"mc":[{"id":"1.195395444","rc":[{"atb":[[3.1,20.92],[2.98,0]],"id":37174579}],"con":true,"img":false}]}
{"op":"mcm","clk":"5346593554","pt":1646091712756,"mc":[{"id":"1.195395444","rc":[{"atb":[[3.55,0],[3.3,0],[3.05,0]],"id":40917095},{"atl":[[19.5,0],[48,0],[9.8,2],[14.5,0],[29,0]],"id":40917095},{"atb":[[3.05,0]],"id":37174579}],"con":true,"img":false}]}
{"op":"mcm","clk":"5346593558","pt":1646091712859,"mc":[{"id":"1.195395444","rc":[{"atl":[[9.8,0],[25,6.01]],"id":40917095},{"atb":[[2.98,41.84]],"id":37174579}],"con":true,"img":false}]}
{"op":"mcm","clk":"5346593561","pt":1646091712916,"mc":[{"id":"1.195395444","rc":[{"atb":[[3.1,0]],"id":37174579}],"con":true,"img":false}]}
{"op":"mcm","clk":"5346593602","pt":1646091714759,"mc":[{"id":"1.195395444","rc":[{"atb":[[2.96,0]],"id":37174579}],"con":true,"img":false}]}
{"op":"mcm","clk":"5346593604","pt":1646091714862,"mc":[{"id":"1.195395444","rc":[{"atb":[[2.92,20.92]],"id":37174579}],"con":true,"img":false}]}
{"op":"mcm","clk":"5346593631","pt":1646091715842,"mc":[{"id":"1.195395444","rc":[{"atb":[[3.65,3.15]],"id":40917095}],"con":true,"img":false}]}
{"op":"mcm","clk":"5346593674","pt":1646091717737,"mc":[{"id":"1.195395444","rc":[{"atb":[[3.1,0]],"id":40917095}],"con":true,"img":false}]}
{"op":"mcm","clk":"5346593680","pt":1646091717837,"mc":[{"id":"1.195395444","rc":[{"atb":[[3,19.32]],"id":40917095}],"con":true,"img":false}]}
{"op":"mcm","clk":"5346593685","pt":1646091717942,"mc":[{"id":"1.195395444","rc":[{"atb":[[2.94,51.55]],"id":37174579}],"con":true,"img":false}]}
{"op":"mcm","clk":"5346593689","pt":1646091718044,"mc":[{"id":"1.195395444","rc":[{"atb":[[2.98,0]],"id":37174579}],"con":true,"img":false}]}
{"op":"mcm","clk":"5346593717","pt":1646091719227,"mc":[{"id":"1.195395444","rc":[{"atb":[[2.82,66.01],[2.92,62.58],[3.05,29.3]],"id":40917095},{"atl":[[32,1.54],[10.5,1.26],[21,1.2],[8.2,1.66],[15.5,1.65]],"id":40917095}],"con":true,"img":false}]}
{"op":"mcm","clk":"5346593782","pt":1646091721634,"mc":[{"id":"1.195395444","rc":[{"atl":[[5.6,0]],"id":42070475},{"atl":[[3.8,0]],"id":42236682}],"con":true,"img":false}]}
{"op":"mcm","clk":"5346593783","pt":1646091721736,"mc":[{"id":"1.195395444","rc":[{"atl":[[5.1,9.89]],"id":42070475},{"atl":[[3.95,28],[4.9,13.99],[3.75,0]],"id":42236682}],"con":true,"img":false}]}
{"op":"mcm","clk":"5346593834","pt":1646091723549,"mc":[{"id":"1.195395444","rc":[{"atb":[[2.56,48.08],[2.52,108.94],[2.6,106.34],[2.64,12.2]],"id":42236670},{"atl":[[4.8,13.16],[4.6,5.56],[5,18.75],[5.2,29.76]],"id":42236670},{"atb":[[1.89,56.18],[1.85,288.41],[1.91,21.98],[1.87,201.15]],"id":42236682},{"atl":[[2.98,10.1],[3.15,34.88],[3.25,55.56],[3.05,24.39]],"id":42236682},{"atb":[[2.82,10.99],[2.74,43.1],[2.78,28.09],[2.7,144.2]],"id":37174579},{"atl":[[9,2.5],[10.5,13.16],[9.8,9.88],[9.4,5.95]],"id":37174579}],"con":true,"img":false}]}
{"op":"mcm","clk":"5346593838","pt":1646091723651,"mc":[{"id":"1.195395444","rc":[{"atb":[[3.2,56.82],[3.4,20.83],[3.5,8],[3.3,32.61]],"id":40917095},{"atl":[[8.2,19.02],[7.4,7.81],[7,3.33],[7.8,11.03]],"id":40917095},{"atb":[[3.45,44.93],[3.35,31.91],[3.55,14.03],[3.25,73.59]],"id":42189436},{"atl":[[8,10.71],[7.2,3.23],[7.6,7.58],[8.4,16.89]],"id":42189436},{"atb":[[1.72,173.61],[1.74,101.35],[1.78,25.64],[1.76,106.38]],"id":42070475},{"atl":[[5.6,10.87],[5.8,30.14],[6,25],[5.4,4.55]],"id":42070475},{"atb":[[1.36,55.56],[1.32,234.37],[1.3,250],[1.34,147.06]],"id":41523279},{"atl":[[3.2,9.09],[3.4,31.25],[3.3,21.74],[3.5,50]],"id":41523279},{"atl":[[3.95,0],[3.7,14]],"id":42236682}],"con":true,"img":false}]}
{"op":"mcm","clk":"5346593840","pt":1646091723753,"mc":[{"id":"1.195395444","rc":[{"atb":[[2.66,0],[2.76,56.82]],"id":40917095},{"atb":[[2.9,0],[3,50]],"id":42189436},{"atb":[[2.56,112.18],[2.5,80.09]],"id":42236670},{"atl":[[3.55,3.34],[4.5,0]],"id":41523279},{"atb":[[1.9,122.92],[1.87,86.21]],"id":42236682}],"con":true,"img":false}]}
{"op":"mcm","clk":"5346593901","pt":1646091724736,"mc":[{"id":"1.195395444","rc":[{"atb":[[3,3.72]],"id":37174579}],"con":true,"img":false}]}
{"op":"mcm","clk":"5346593987","pt":1646091727971,"mc":[{"id":"1.195395444","rc":[{"atb":[[3.65,0]],"id":40917095}],"con":true,"img":false}]}
{"op":"mcm","clk":"5346594008","pt":1646091728640,"mc":[{"id":"1.195395444","rc":[{"atl":[[5.1,0]],"id":42070475}],"con":true,"img":false}]}
{"op":"mcm","clk":"5346594010","pt":1646091728751,"mc":[{"id":"1.195395444","rc":[{"atl":[[5.7,9.89]],"id":42070475}],"con":true,"img":false}]}
{"op":"mcm","clk":"5346594056","pt":1646091730740,"mc":[{"id":"1.195395444","rc":[{"atb":[[3.5,10.98]],"id":40917095}],"con":true,"img":false}]}
{"op":"mcm","clk":"5346594083","pt":1646091732070,"mc":[{"id":"1.195395444","rc":[{"atl":[[8,14.29]],"id":40917095}],"con":true,"img":false}]}
{"op":"mcm","clk":"5346594085","pt":1646091732172,"mc":[{"id":"1.195395444","rc":[{"atl":[[25,1.84]],"id":40917095}],"con":true,"img":false}]}
{"op":"mcm","clk":"5346594097","pt":1646091732943,"mc":[{"id":"1.195395444","rc":[{"atb":[[3,7.9]],"id":37174579}],"con":true,"img":false}]}
{"op":"mcm","clk":"5346594186","pt":1646091737039,"mc":[{"id":"1.195395444","rc":[{"atb":[[3.05,20.92]],"id":37174579}],"con":true,"img":false}]}
{"op":"mcm","clk":"5346594191","pt":1646091737140,"mc":[{"id":"1.195395444","rc":[{"atb":[[2.94,0]],"id":37174579}],"con":true,"img":false}]}
{"op":"mcm","clk":"5346594224","pt":1646091738571,"mc":[{"id":"1.195395444","rc":[{"atl":[[11,4.05]],"id":40917095}],"con":true,"img":false}]}
{"op":"mcm","clk":"5346594227","pt":1646091738673,"mc":[{"id":"1.195395444","rc":[{"atl":[[25,0]],"id":40917095},{"atb":[[2.52,82.24]],"id":42236670},{"atl":[[6.8,7]],"id":42236670},{"atb":[[2.92,0]],"id":37174579}],"con":true,"img":false}]}
{"op":"mcm","clk":"5346594229","pt":1646091738775,"mc":[{"id":"1.195395444","rc":[{"atb":[[2.58,26.7]],"id":42236670},{"atl":[[7.6,6.99]],"id":42236670},{"atb":[[2.82,31.91]],"id":37174579}],"con":true,"img":false}]}
{"op":"mcm","clk":"5346594238","pt":1646091739081,"mc":[{"id":"1.195395444","rc":[{"atb":[[3.4,24.31]],"id":40917095}],"con":true,"img":false}]}
{"op":"mcm","clk":"5346594269","pt":1646091739854,"mc":[{"id":"1.195395444","rc":[{"atb":[[3,4.18]],"id":37174579}],"con":true,"img":false}]}
{"op":"mcm","clk":"5346594409","pt":1646091745797,"mc":[{"id":"1.195395444","rc":[{"atb":[[2.96,3.8]],"id":37174579}],"con":true,"img":false}]}
{"op":"mcm","clk":"5346594470","pt":1646091748566,"mc":[{"id":"1.195395444","rc":[{"atb":[[3,0]],"id":40917095},{"atb":[[3.25,55.56]],"id":42189436},{"atl":[[13,0]],"id":42189436},{"atl":[[4.8,10.68],[6.2,0]],"id":41523279},{"atl":[[4.9,0]],"id":42236682},{"atl":[[13,0]],"id":37174579}],"con":true,"img":false}]}
{"op":"mcm","clk":"5346594471","pt":1646091748669,"mc":[{"id":"1.195395444","rc":[{"atb":[[3.25,19.32]],"id":40917095},{"atb":[[3.5,18.03]],"id":42189436},{"atl":[[11.5,4.61]],"id":42189436},{"atl":[[4.5,13.99]],"id":42236682},{"atl":[[10,3.38]],"id":37174579}],"con":true,"img":false}]}
{"op":"mcm","clk":"5346594646","pt":1646091756106,"mc":[{"id":"1.195395444","rc":[{"atb":[[3,0]],"id":37174579}],"con":true,"img":false}]}
{"op":"mcm","clk":"5346594652","pt":1646091756311,"mc":[{"id":"1.195395444","rc":[{"atb":[[2.98,41.84],[3.05,0]],"id":37174579}],"con":true,"img":false}]}
{"op":"mcm","clk":"5346594697","pt":1646091757902,"mc":[{"id":"1.195395444","rc":[{"atb":[[2.96,0]],"id":37174579}],"con":true,"img":false}]}
{"op":"mcm","clk":"5346594717","pt":1646091758576,"mc":[{"id":"1.195395444","rc":[{"atb":[[2.68,0]],"id":40917095},{"atl":[[18.5,14.86],[44,0]],"id":40917095}],"con":true,"img":false}]}
{"op":"mcm","clk":"5346594722","pt":1646091758680,"mc":[{"id":"1.195395444","rc":[{"atb":[[2.78,31.78]],"id":40917095}],"con":true,"img":false}]}
{"op":"mcm","clk":"5346594728","pt":1646091758881,"mc":[{"id":"1.195395444","rc":[{"atl":[[13.5,0]],"id":42236670}],"con":true,"img":false}]}
{"op":"mcm","clk":"5346594730","pt":1646091758984,"mc":[{"id":"1.195395444","rc":[{"atl":[[11.5,25.17]],"id":42236670}],"con":true,"img":false}]}
{"op":"mcm","clk":"5346594787","pt":1646091761400,"mc":[{"id":"1.195395444","rc":[{"atb":[[2.92,52.08],[2.98,0]],"id":37174579}],"con":true,"img":false}]}
{"op":"mcm","clk":"5346594933","pt":1646091768597,"mc":[{"id":"1.195395444","rc":[{"atb":[[2.22,0]],"id":42189436},{"atl":[[9,0],[7,28.98]],"id":41523279},{"atl":[[7.8,0]],"id":42236682},{"atl":[[16,19.66],[20,0]],"id":37174579}],"con":true,"img":false}]}
{"op":"mcm","clk":"5346594937","pt":1646091768696,"mc":[{"id":"1.195395444","rc":[{"atb":[[2.46,56.5]],"id":42189436},{"atl":[[6.6,35.81]],"id":42236682}],"con":true,"img":false}]}
{"op":"mcm","clk":"5346594973","pt":1646091769825,"mc":[{"id":"1.195395444","rc":[{"atb":[[2.98,3.76]],"id":37174579}],"con":true,"img":false}]}
{"op":"mcm","clk":"5346595112","pt":1646091775000,"mc":[{"id":"1.195395444","rc":[{"atb":[[3,31.62]],"id":37174579}],"con":true,"img":false}]}
{"op":"mcm","clk":"5346595113","pt":1646091775100,"mc":[{"id":"1.195395444","rc":[{"atb":[[2.92,0]],"id":37174579}],"con":true,"img":false}]}
{"op":"mcm","clk":"5346595125","pt":1646091775919,"mc":[{"id":"1.195395444","rc":[{"atb":[[2.98,0]],"id":37174579}],"con":true,"img":false}]}
{"op":"mcm","clk":"5346595126","pt":1646091776022,"mc":[{"id":"1.195395444","rc":[{"atb":[[2.92,52.08]],"id":37174579}],"con":true,"img":false}]}
{"op":"mcm","clk":"5346595129","pt":1646091776126,"mc":[{"id":"1.195395444","rc":[{"atb":[[3,0]],"id":37174579}],"con":true,"img":false}]}
{"op":"mcm","clk":"5346595189","pt":1646091778736,"mc":[{"id":"1.195395444","rc":[{"atb":[[2.82,10.99]],"id":37174579}],"con":true,"img":false}]}
{"op":"mcm","clk":"5346595190","pt":1646091778839,"mc":[{"id":"1.195395444","rc":[{"atb":[[2.94,20.92]],"id":37174579}],"con":true,"img":false}]}
{"op":"mcm","clk":"5346595255","pt":1646091781301,"mc":[{"id":"1.195395444","rc":[{"atb":[[2.98,4.22]],"id":37174579}],"con":true,"img":false}]}
{"op":"mcm","clk":"5346595364","pt":1646091784840,"mc":[{"id":"1.195395444","rc":[{"atb":[[2.98,7.98]],"id":37174579}],"con":true,"img":false}]}
{"op":"mcm","clk":"5346595636","pt":1646091794544,"mc":[{"id":"1.195395444","rc":[{"atb":[[3,20.92]],"id":37174579}],"con":true,"img":false}]}
{"op":"mcm","clk":"5346595637","pt":1646091794645,"mc":[{"id":"1.195395444","rc":[{"atb":[[2.92,0]],"id":37174579}],"con":true,"img":false}]}
{"op":"mcm","clk":"5346595691","pt":1646091796948,"mc":[{"id":"1.195395444","rc":[{"atb":[[2.98,4.22]],"id":37174579}],"con":true,"img":false}]}
{"op":"mcm","clk":"5346595754","pt":1646091798640,"mc":[{"id":"1.195395444","rc":[{"atb":[[2.94,0]],"id":37174579}],"con":true,"img":false}]}
{"op":"mcm","clk":"5346595756","pt":1646091798741,"mc":[{"id":"1.195395444","rc":[{"atb":[[2.92,20.92]],"id":37174579}],"con":true,"img":false}]}
{"op":"mcm","clk":"5346595841","pt":1646091802843,"mc":[{"id":"1.195395444","rc":[{"atb":[[2.96,3.8]],"id":37174579}],"con":true,"img":false}]}
{"op":"mcm","clk":"5346596348","pt":1646091820575,"mc":[{"id":"1.195395444","rc":[{"atb":[[2.98,0]],"id":37174579}],"con":true,"img":false}]}
{"op":"mcm","clk":"5346596353","pt":1646091820785,"mc":[{"id":"1.195395444","rc":[{"atb":[[3,0],[2.98,41.84]],"id":37174579}],"con":true,"img":false}]}
{"op":"mcm","clk":"5346596440","pt":1646091823967,"mc":[{"id":"1.195395444","rc":[{"atb":[[2.96,0]],"id":37174579}],"con":true,"img":false}]}
{"op":"mcm","clk":"5346596505","pt":1646091825862,"mc":[{"id":"1.195395444","rc":[{"atb":[[2.98,0],[2.94,51.55]],"id":37174579}],"con":true,"img":false}]}
{"op":"mcm","clk":"5346596705","pt":1646091832900,"mc":[{"id":"1.195395444","rc":[{"atb":[[3,3.72]],"id":37174579}],"con":true,"img":false}]}
{"op":"mcm","clk":"5346596749","pt":1646091834593,"mc":[{"id":"1.195395444","rc":[{"atb":[[2.62,61.73],[2.76,0]],"id":40917095},{"atb":[[3,0],[2.84,54.35]],"id":42189436},{"atb":[[2.56,48.08],[2.44,69.44]],"id":42236670},{"atl":[[3.55,0],[3.75,36.36]],"id":41523279},{"atb":[[1.84,119.05],[1.9,66.74]],"id":42236682}],"con":true,"img":false}]}
{"op":"mcm","clk":"5346596896","pt":1646091838588,"mc":[{"id":"1.195395444","rc":[{"atb":[[2.64,38.26]],"id":40917095}],"con":true,"img":false}]}
{"op":"mcm","clk":"5346596900","pt":1646091838692,"mc":[{"id":"1.195395444","rc":[{"atb":[[2.78,0]],"id":40917095}],"con":true,"img":false}]}
{"op":"mcm","clk":"5346597085","pt":1646091843879,"mc":[{"id":"1.195395444","rc":[{"atb":[[2.94,0],[3.05,20.92]],"id":37174579}],"con":true,"img":false}]}
{"op":"mcm","clk":"5346597091","pt":1646091844190,"mc":[{"id":"1.195395444","rc":[{"atb":[[3,7.9]],"id":37174579}],"con":true,"img":false}]}
{"op":"mcm","clk":"5346597113","pt":1646091844908,"mc":[{"id":"1.195395444","rc":[{"atb":[[3,4.18]],"id":37174579}],"con":true,"img":false}]}
{"op":"mcm","clk":"5346597293","pt":1646091850919,"mc":[{"id":"1.195395444","rc":[{"atb":[[2.96,3.8]],"id":37174579}],"con":true,"img":false}]}
{"op":"mcm","clk":"5346597605","pt":1646091862629,"mc":[{"id":"1.195395444","rc":[{"atb":[[3,0]],"id":37174579}],"con":true,"img":false}]}
{"op":"mcm","clk":"5346597609","pt":1646091862731,"mc":[{"id":"1.195395444","rc":[{"atb":[[2.98,41.84]],"id":37174579}],"con":true,"img":false}]}
{"op":"mcm","clk":"5346597613","pt":1646091862836,"mc":[{"id":"1.195395444","rc":[{"atb":[[3.05,0]],"id":37174579}],"con":true,"img":false}]}
{"op":"mcm","clk":"5346597723","pt":1646091865919,"mc":[{"id":"1.195395444","rc":[{"atb":[[2.96,0]],"id":37174579}],"con":true,"img":false}]}
{"op":"mcm","clk":"5346597730","pt":1646091866125,"mc":[{"id":"1.195395444","rc":[{"atb":[[2.98,0],[2.94,51.55]],"id":37174579}],"con":true,"img":false}]}
{"op":"mcm","clk":"5346597994","pt":1646091874944,"mc":[{"id":"1.195395444","rc":[{"atb":[[3,3.72]],"id":37174579}],"con":true,"img":false}]}
{"op":"mcm","clk":"5346598125","pt":1646091878535,"mc":[{"id":"1.195395444","rc":[{"atb":[[1.88,0]],"id":42236682}],"con":true,"img":false}]}
{"op":"mcm","clk":"5346598129","pt":1646091878650,"mc":[{"id":"1.195395444","rc":[{"atb":[[1.81,40.59]],"id":42236682}],"con":true,"img":false}]}
{"op":"mcm","clk":"5346598331","pt":1646091883736,"mc":[{"id":"1.195395444","rc":[{"atb":[[2.94,0]],"id":37174579}],"con":true,"img":false}]}
{"op":"mcm","clk":"5346598338","pt":1646091883843,"mc":[{"id":"1.195395444","rc":[{"atb":[[3.05,20.92]],"id":37174579}],"con":true,"img":false}]}
{"op":"mcm","clk":"5346598509","pt":1646091887073,"mc":[{"id":"1.195395444","rc":[{"atb":[[3,0]],"id":37174579}],"con":true,"img":false}]}
{"op":"mcm","clk":"5346598569","pt":1646091889078,"mc":[{"id":"1.195395444","rc":[{"atb":[[2.94,41.84],[3.05,0]],"id":37174579}],"con":true,"img":false}]}
{"op":"mcm","clk":"5346598800","pt":1646091895955,"mc":[{"id":"1.195395444","rc":[{"atb":[[3,3.72]],"id":37174579}],"con":true,"img":false}]}
{"op":"mcm","clk":"5346599013","pt":1646091901393,"mc":[{"id":"1.195395444","rc":[{"atb":[[2.94,0],[3.05,20.92]],"id":37174579}],"con":true,"img":false}]}
{"op":"mcm","clk":"5346599055","pt":1646091902274,"mc":[{"id":"1.195395444","rc":[{"atb":[[3,0]],"id":37174579}],"con":true,"img":false}]}
{"op":"mcm","clk":"5346599241","pt":1646091906554,"mc":[{"id":"1.195395444","rc":[{"atb":[[2.94,41.84]],"id":37174579}],"con":true,"img":false}]}
{"op":"mcm","clk":"5346599246","pt":1646091906656,"mc":[{"id":"1.195395444","rc":[{"atb":[[3.05,0]],"id":37174579}],"con":true,"img":false}]}
{"op":"mcm","clk":"5346599281","pt":1646091907472,"mc":[{"id":"1.195395444","rc":[{"atb":[[3,4.18]],"id":37174579}],"con":true,"img":false}]}
{"op":"mcm","clk":"5346599546","pt":1646091914263,"mc":[{"id":"1.195395444","rc":[{"atb":[[3,7.9]],"id":37174579}],"con":true,"img":false}]}
{"op":"mcm","clk":"5346599701","pt":1646091918585,"mc":[{"id":"1.195395444","rc":[{"atb":[[2.92,0]],"id":37174579}],"con":true,"img":false}]}
{"op":"mcm","clk":"5346599705","pt":1646091918685,"mc":[{"id":"1.195395444","rc":[{"atb":[[2.96,20.92]],"id":37174579}],"con":true,"img":false}]}
{"op":"mcm","clk":"5346599892","pt":1646091923819,"mc":[{"id":"1.195395444","rc":[{"atb":[[2.94,0],[3.05,20.92]],"id":37174579}],"con":true,"img":false}]}
{"op":"mcm","clk":"5346600007","pt":1646091926193,"mc":[{"id":"1.195395444","rc":[{"atb":[[3,4.18]],"id":37174579}],"con":true,"img":false}]}
{"op":"mcm","clk":"5346600099","pt":1646091928709,"mc":[{"id":"1.195395444","rc":[{"atb":[[2.96,0]],"id":37174579}],"con":true,"img":false}]}
{"op":"mcm","clk":"5346600103","pt":1646091928814,"mc":[{"id":"1.195395444","rc":[{"atb":[[2.92,20.92]],"id":37174579}],"con":true,"img":false}]}
{"op":"mcm","clk":"5346600212","pt":1646091932095,"mc":[{"id":"1.195395444","rc":[{"atb":[[2.96,3.8]],"id":37174579}],"con":true,"img":false}]}
{"op":"mcm","clk":"5346600370","pt":1646091937427,"mc":[{"id":"1.195395444","rc":[{"atb":[[3,0]],"id":37174579}],"con":true,"img":false}]}
{"op":"mcm","clk":"5346600377","pt":1646091937630,"mc":[{"id":"1.195395444","rc":[{"atb":[[2.98,41.84]],"id":37174579}],"con":true,"img":false}]}
{"op":"mcm","clk":"5346600379","pt":1646091937733,"mc":[{"id":"1.195395444","rc":[{"atb":[[3.05,0]],"id":37174579}],"con":true,"img":false}]}
{"op":"mcm","clk":"5346600395","pt":1646091938093,"mc":[{"id":"1.195395444","rc":[{"atb":[[2.96,0]],"id":37174579}],"con":true,"img":false}]}
{"op":"mcm","clk":"5346600552","pt":1646091942713,"mc":[{"id":"1.195395444","rc":[{"atb":[[2.94,51.55]],"id":37174579}],"con":true,"img":false}]}
{"op":"mcm","clk":"5346600555","pt":1646091942817,"mc":[{"id":"1.195395444","rc":[{"atb":[[2.98,0]],"id":37174579}],"con":true,"img":false}]}
{"op":"mcm","clk":"5346600803","pt":1646091950113,"mc":[{"id":"1.195395444","rc":[{"atb":[[3,3.72]],"id":37174579}],"con":true,"img":false}]}
{"op":"mcm","clk":"5346600951","pt":1646091954524,"mc":[{"id":"1.195395444","rc":[{"atb":[[3.05,20.92]],"id":37174579}],"con":true,"img":false}]}
{"op":"mcm","clk":"5346600956","pt":1646091954622,"mc":[{"id":"1.195395444","rc":[{"atb":[[2.94,0]],"id":37174579}],"con":true,"img":false}]}
{"op":"mcm","clk":"5346600998","pt":1646091956116,"mc":[{"id":"1.195395444","rc":[{"atb":[[3,0]],"id":37174579}],"con":true,"img":false}]}
{"op":"mcm","clk":"5346601128","pt":1646091959646,"mc":[{"id":"1.195395444","rc":[{"atb":[[2.94,41.84]],"id":37174579}],"con":true,"img":false}]}
{"op":"mcm","clk":"5346601131","pt":1646091959749,"mc":[{"id":"1.195395444","rc":[{"atb":[[3.05,0]],"id":37174579}],"con":true,"img":false}]}
{"op":"mcm","clk":"5346601290","pt":1646091965343,"mc":[{"id":"1.195395444","rc":[{"atb":[[3.4,11.81],[3.5,2.98]],"id":40917095},{"atl":[[7,0],[6.6,3.57]],"id":40917095},{"atb":[[2.1,75.09]],"id":42070475}],"con":true,"img":false}]}
{"op":"mcm","clk":"5346601295","pt":1646091965445,"mc":[{"id":"1.195395444","rc":[{"atl":[[8.4,13.51]],"id":40917095},{"atb":[[2.08,0]],"id":42070475}],"con":true,"img":false}]}
{"op":"mcm","clk":"5346601298","pt":1646091965549,"mc":[{"id":"1.195395444","rc":[{"atl":[[8,0]],"id":40917095}],"con":true,"img":false}]}
{"op":"mcm","clk":"5346601361","pt":1646091968164,"mc":[{"id":"1.195395444","rc":[{"atb":[[3,3.72]],"id":37174579}],"con":true,"img":false}]}
{"op":"mcm","clk":"5346601363","pt":1646091968266,"mc":[{"id":"1.195395444","rc":[{"atb":[[3.5,0]],"id":40917095},{"atb":[[2.12,7.46]],"id":42070475}],"con":true,"img":false}]}
{"op":"mcm","clk":"5346601442","pt":1646091971345,"mc":[{"id":"1.195395444","rc":[{"atb":[[3.05,20.92]],"id":37174579}],"con":true,"img":false}]}
{"op":"mcm","clk":"5346601446","pt":1646091971444,"mc":[{"id":"1.195395444","rc":[{"atb":[[2.94,0]],"id":37174579}],"con":true,"img":false}]}
{"op":"mcm","clk":"5346601521","pt":1646091974267,"mc":[{"id":"1.195395444","rc":[{"atb":[[3.4,14.92]],"id":40917095},{"atb":[[2.14,6.53]],"id":42070475},{"atb":[[3,0]],"id":37174579}],"con":true,"img":false}]}
{"op":"mcm","clk":"5346601526","pt":1646091974472,"mc":[{"id":"1.195395444","rc":[{"atb":[[2.94,41.84],[3.05,0]],"id":37174579}],"con":true,"img":false}]}
{"op":"mcm","clk":"5346601549","pt":1646091975348,"mc":[{"id":"1.195395444","rc":[{"atb":[[3.3,54.35]],"id":40917095},{"atl":[[7,8.33]],"id":40917095}],"con":true,"img":false}]}
{"op":"mcm","clk":"5346601551","pt":1646091975449,"mc":[{"id":"1.195395444","rc":[{"atb":[[3.3,21.74]],"id":40917095}],"con":true,"img":false}]}
{"op":"mcm","clk":"5346601673","pt":1646091979763,"mc":[{"id":"1.195395444","rc":[{"atb":[[2.12,0]],"id":42070475}],"con":true,"img":false}]}
{"op":"mcm","clk":"5346601687","pt":1646091980172,"mc":[{"id":"1.195395444","rc":[{"atl":[[8.2,1.66]],"id":40917095}],"con":true,"img":false}]}
{"op":"mcm","clk":"5346601769","pt":1646091983156,"mc":[{"id":"1.195395444","rc":[{"atb":[[3,3.72]],"id":37174579}],"con":true,"img":false}]}
{"op":"mcm","clk":"5346601775","pt":1646091983260,"mc":[{"id":"1.195395444","rc":[{"atb":[[3.05,20.92]],"id":37174579}],"con":true,"img":false}]}
{"op":"mcm","clk":"5346601780","pt":1646091983361,"mc":[{"id":"1.195395444","rc":[{"atb":[[2.94,0]],"id":37174579}],"con":true,"img":false}]}
{"op":"mcm","clk":"5346601819","pt":1646091984485,"mc":[{"id":"1.195395444","rc":[{"atb":[[2.92,0]],"id":37174579}],"con":true,"img":false}]}
{"op":"mcm","clk":"5346601823","pt":1646091984587,"mc":[{"id":"1.195395444","rc":[{"atb":[[2.96,20.92]],"id":37174579}],"con":true,"img":false}]}
{"op":"mcm","clk":"5346601846","pt":1646091985355,"mc":[{"id":"1.195395444","rc":[{"atb":[[3.2,34.09]],"id":40917095},{"atl":[[7.4,11.72]],"id":40917095},{"atb":[[2.14,13.86]],"id":42070475}],"con":true,"img":false}]}
{"op":"mcm","clk":"5346601874","pt":1646091986177,"mc":[{"id":"1.195395444","rc":[{"atb":[[3,0]],"id":37174579}],"con":true,"img":false}]}
{"op":"mcm","clk":"5346601877","pt":1646091986280,"mc":[{"id":"1.195395444","rc":[{"atb":[[2.98,41.84]],"id":37174579}],"con":true,"img":false}]}
{"op":"mcm","clk":"5346601880","pt":1646091986382,"mc":[{"id":"1.195395444","rc":[{"atb":[[3.05,0]],"id":37174579}],"con":true,"img":false}]}
{"op":"mcm","clk":"5346602056","pt":1646091991460,"mc":[{"id":"1.195395444","rc":[{"atb":[[3.4,11.43]],"id":40917095}],"con":true,"img":false}]}
{"op":"mcm","clk":"5346602181","pt":1646091995203,"mc":[{"id":"1.195395444","rc":[{"atb":[[3.05,3.63]],"id":37174579}],"con":true,"img":false}]}
{"op":"mcm","clk":"5346602187","pt":1646091995407,"mc":[{"id":"1.195395444","rc":[{"atb":[[3.1,59.52]],"id":40917095},{"atl":[[7.8,29.41]],"id":40917095}],"con":true,"img":false}]}
{"op":"mcm","clk":"5346602195","pt":1646091995568,"mc":[{"id":"1.195395444","rc":[{"atl":[[7.8,18.38]],"id":40917095}],"con":true,"img":false}]}
{"op":"mcm","clk":"5346602261","pt":1646091997467,"mc":[{"id":"1.195395444","rc":[{"atb":[[3.25,23.03]],"id":40917095}],"con":true,"img":false}]}
{"op":"mcm","clk":"5346602286","pt":1646091998591,"mc":[{"id":"1.195395444","rc":[{"atb":[[2.96,0]],"id":37174579}],"con":true,"img":false}]}
{"op":"mcm","clk":"5346602289","pt":1646091998695,"mc":[{"id":"1.195395444","rc":[{"atb":[[2.92,20.92]],"id":37174579}],"con":true,"img":false}]}
{"op":"mcm","clk":"5346602403","pt":1646092002748,"mc":[{"id":"1.195395444","rc":[{"atb":[[3.1,20.92],[2.98,0]],"id":37174579}],"con":true,"img":false}]}
{"op":"mcm","clk":"5346602455","pt":1646092004289,"mc":[{"id":"1.195395444","rc":[{"atb":[[3.05,0]],"id":37174579}],"con":true,"img":false}]}
{"op":"mcm","clk":"5346602459","pt":1646092004392,"mc":[{"id":"1.195395444","rc":[{"atb":[[3.1,0],[2.94,41.84]],"id":37174579}],"con":true,"img":false}]}
{"op":"mcm","clk":"5346602704","pt":1646092013211,"mc":[{"id":"1.195395444","rc":[{"atb":[[3,3.72]],"id":37174579}],"con":true,"img":false}]}
{"op":"mcm","clk":"5346602706","pt":1646092013314,"mc":[{"id":"1.195395444","rc":[{"atb":[[2.94,0],[3.05,20.92]],"id":37174579}],"con":true,"img":false}]}
{"op":"mcm","clk":"5346602804","pt":1646092016191,"mc":[{"id":"1.195395444","rc":[{"atb":[[3,0]],"id":37174579}],"con":true,"img":false}]}
{"op":"mcm","clk":"5346602859","pt":1646092018396,"mc":[{"id":"1.195395444","rc":[{"atb":[[2.94,41.84],[3.05,0]],"id":37174579}],"con":true,"img":false}]}
{"op":"mcm","clk":"5346602867","pt":1646092018600,"mc":[{"id":"1.195395444","rc":[{"atb":[[2.92,0]],"id":37174579}],"con":true,"img":false}]}
{"op":"mcm","clk":"5346602873","pt":1646092018703,"mc":[{"id":"1.195395444","rc":[{"atb":[[2.92,52.08],[2.96,20.92]],"id":37174579}],"con":true,"img":false}]}
{"op":"mcm","clk":"5346602876","pt":1646092018806,"mc":[{"id":"1.195395444","rc":[{"atb":[[2.94,0]],"id":37174579}],"con":true,"img":false}]}
{"op":"mcm","clk":"5346603102","pt":1646092025326,"mc":[{"id":"1.195395444","rc":[{"atb":[[2.98,3.76]],"id":37174579}],"con":true,"img":false}]}
{"op":"mcm","clk":"5346603239","pt":1646092028636,"mc":[{"id":"1.195395444","rc":[{"atb":[[2.96,0]],"id":37174579}],"con":true,"img":false}]}
{"op":"mcm","clk":"5346603243","pt":1646092028736,"mc":[{"id":"1.195395444","rc":[{"atb":[[2.94,20.92]],"id":37174579}],"con":true,"img":false}]}
{"op":"mcm","clk":"5346603266","pt":1646092029509,"mc":[{"id":"1.195395444","rc":[{"atb":[[3,20.92]],"id":37174579}],"con":true,"img":false}]}
{"op":"mcm","clk":"5346603270","pt":1646092029612,"mc":[{"id":"1.195395444","rc":[{"atb":[[2.92,0]],"id":37174579}],"con":true,"img":false}]}
{"op":"mcm","clk":"5346603343","pt":1646092031323,"mc":[{"id":"1.195395444","rc":[{"atb":[[2.98,0]],"id":37174579}],"con":true,"img":false}]}
{"op":"mcm","clk":"5346603346","pt":1646092031422,"mc":[{"id":"1.195395444","rc":[{"atb":[[3,0],[2.96,41.84]],"id":37174579}],"con":true,"img":false}]}
{"op":"mcm","clk":"5346603634","pt":1646092040357,"mc":[{"id":"1.195395444","rc":[{"atb":[[3.05,3.63]],"id":37174579}],"con":true,"img":false}]}
{"op":"mcm","clk":"5346603636","pt":1646092040461,"mc":[{"id":"1.195395444","rc":[{"atb":[[3.1,20.92]],"id":37174579}],"con":true,"img":false}]}
{"op":"mcm","clk":"5346603639","pt":1646092040564,"mc":[{"id":"1.195395444","rc":[{"atb":[[2.96,0]],"id":37174579}],"con":true,"img":false}]}
{"op":"mcm","clk":"5346603728","pt":1646092043337,"mc":[{"id":"1.195395444","rc":[{"atb":[[3.05,0]],"id":37174579}],"con":true,"img":false}]}
{"op":"mcm","clk":"5346603730","pt":1646092043436,"mc":[{"id":"1.195395444","rc":[{"atb":[[2.96,41.84]],"id":37174579}],"con":true,"img":false}]}
{"op":"mcm","clk":"5346603735","pt":1646092043539,"mc":[{"id":"1.195395444","rc":[{"atb":[[3.1,0]],"id":37174579}],"con":true,"img":false}]}
{"op":"mcm","clk":"5346603790","pt":1646092045748,"mc":[{"id":"1.195395444","rc":[{"atb":[[3.05,4.07]],"id":37174579}],"con":true,"img":false}]}
{"op":"mcm","clk":"5346603793","pt":1646092045853,"mc":[{"id":"1.195395444","rc":[{"atb":[[3.1,20.92],[2.96,0]],"id":37174579}],"con":true,"img":false}]}
{"op":"mcm","clk":"5346603872","pt":1646092048675,"mc":[{"id":"1.195395444","rc":[{"atb":[[2.94,0]],"id":37174579}],"con":true,"img":false}]}
{"op":"mcm","clk":"5346603875","pt":1646092048777,"mc":[{"id":"1.195395444","rc":[{"atb":[[2.92,20.92]],"id":37174579}],"con":true,"img":false}]}
{"op":"mcm","clk":"5346603892","pt":1646092049344,"mc":[{"id":"1.195395444","rc":[{"atb":[[2.96,3.8]],"id":37174579}],"con":true,"img":false}]}
{"op":"mcm","clk":"5346604290","pt":1646092064087,"mc":[{"id":"1.195395444","rc":[{"atb":[[3.05,0]],"id":37174579}],"con":true,"img":false}]}
{"op":"mcm","clk":"5346604291","pt":1646092064190,"mc":[{"id":"1.195395444","rc":[{"atb":[[3.1,0],[2.98,41.84]],"id":37174579}],"con":true,"img":false}]}
{"op":"mcm","clk":"5346604370","pt":1646092067379,"mc":[{"id":"1.195395444","rc":[{"atb":[[2.96,0]],"id":37174579}],"con":true,"img":false}]}
{"op":"mcm","clk":"5346604375","pt":1646092067484,"mc":[{"id":"1.195395444","rc":[{"atb":[[2.98,0],[2.94,51.55]],"id":37174579}],"con":true,"img":false}]}
{"op":"mcm","clk":"5346604620","pt":1646092076398,"mc":[{"id":"1.195395444","rc":[{"atb":[[3,3.72]],"id":37174579}],"con":true,"img":false}]}
{"op":"mcm","clk":"5346604624","pt":1646092076502,"mc":[{"id":"1.195395444","rc":[{"atb":[[2.94,0],[3.05,20.92]],"id":37174579}],"con":true,"img":false}]}
{"op":"mcm","clk":"5346604717","pt":1646092079423,"mc":[{"id":"1.195395444","rc":[{"atb":[[3,0]],"id":37174579}],"con":true,"img":false}]}
{"op":"mcm","clk":"5346604724","pt":1646092079627,"mc":[{"id":"1.195395444","rc":[{"atb":[[2.94,41.84],[3.05,0]],"id":37174579}],"con":true,"img":false}]}
{"op":"mcm","clk":"5346604783","pt":1646092081727,"mc":[{"id":"1.195395444","rc":[{"atb":[[3,4.18]],"id":37174579}],"con":true,"img":false}]}
{"op":"mcm","clk":"5346604983","pt":1646092088390,"mc":[{"id":"1.195395444","rc":[{"atb":[[3,7.9]],"id":37174579}],"con":true,"img":false}]}
{"op":"mcm","clk":"5346605205","pt":1646092095215,"mc":[{"id":"1.195395444","rc":[{"atb":[[2.94,0],[3.05,20.92]],"id":37174579}],"con":true,"img":false}]}
{"op":"mcm","clk":"5346605269","pt":1646092097530,"mc":[{"id":"1.195395444","rc":[{"atb":[[3,4.18]],"id":37174579}],"con":true,"img":false}]}
{"op":"mcm","clk":"5346605437","pt":1646092103436,"mc":[{"id":"1.195395444","rc":[{"atb":[[2.96,3.8]],"id":37174579}],"con":true,"img":false}]}
{"op":"mcm","clk":"5346605698","pt":1646092110719,"mc":[{"id":"1.195395444","rc":[{"atb":[[3.45,18.88]],"id":40917095},{"atb":[[2.66,27.86]],"id":42236670},{"atb":[[1.81,57.11]],"id":42070475},{"atb":[[1.97,47.43]],"id":41523279},{"atb":[[1.95,33.65]],"id":42236682},{"atb":[[3.1,22.03]],"id":37174579}],"con":true,"img":false}]}
{"op":"mcm","clk":"5346605700","pt":1646092110820,"mc":[{"id":"1.195395444","rc":[{"atb":[[3.05,0],[3.15,20.92]],"id":37174579}],"con":true,"img":false}]}
{"op":"mcm","clk":"5346605726","pt":1646092111642,"mc":[{"id":"1.195395444","rc":[{"atb":[[3,0]],"id":37174579}],"con":true,"img":false}]}
{"op":"mcm","clk":"5346605769","pt":1646092112513,"mc":[{"id":"1.195395444","rc":[{"atb":[[2,8.36]],"id":41523279}],"con":true,"img":false}]}
{"op":"mcm","clk":"5346605827","pt":1646092114049,"mc":[{"id":"1.195395444","rc":[{"atb":[[3.1,0]],"id":37174579}],"con":true,"img":false}]}
{"op":"mcm","clk":"5346605896","pt":1646092115945,"mc":[{"id":"1.195395444","rc":[{"atb":[[2.98,41.84]],"id":37174579}],"con":true,"img":false}]}
{"op":"mcm","clk":"5346605899","pt":1646092116046,"mc":[{"id":"1.195395444","rc":[{"atb":[[3.15,0]],"id":37174579}],"con":true,"img":false}]}
{"op":"mcm","clk":"5346605938","pt":1646092117429,"mc":[{"id":"1.195395444","rc":[{"atb":[[2.98,65.2]],"id":37174579}],"con":true,"img":false}]}
{"op":"mcm","clk":"5346605972","pt":1646092118462,"mc":[{"id":"1.195395444","rc":[{"atb":[[2.02,7.3]],"id":41523279},{"atb":[[2.96,0]],"id":37174579}],"con":true,"img":false}]}
{"op":"mcm","clk":"5346606053","pt":1646092120867,"mc":[{"id":"1.195395444","rc":[{"atb":[[1.97,0]],"id":41523279},{"atb":[[2.98,41.84]],"id":37174579}],"con":true,"img":false}]}
{"op":"mcm","clk":"5346606060","pt":1646092121021,"mc":[{"id":"1.195395444","rc":[{"atb":[[2.94,51.55]],"id":37174579}],"con":true,"img":false}]}
{"op":"mcm","clk":"5346606063","pt":1646092121126,"mc":[{"id":"1.195395444","rc":[{"atb":[[2.98,0]],"id":37174579}],"con":true,"img":false}]}
{"op":"mcm","clk":"5346606072","pt":1646092121436,"mc":[{"id":"1.195395444","rc":[{"atb":[[2.02,0]],"id":41523279}],"con":true,"img":false}]}
{"op":"mcm","clk":"5346606176","pt":1646092124349,"mc":[{"id":"1.195395444","rc":[{"atb":[[1.97,25.08]],"id":41523279},{"atb":[[2.96,23.6]],"id":37174579}],"con":true,"img":false}]}
{"op":"mcm","clk":"5346606283","pt":1646092127430,"mc":[{"id":"1.195395444","rc":[{"atb":[[2,15.81]],"id":41523279},{"atb":[[3,3.72]],"id":37174579}],"con":true,"img":false}]}
{"op":"mcm","clk":"5346606343","pt":1646092129332,"mc":[{"id":"1.195395444","rc":[{"atb":[[2.96,0]],"id":37174579}],"con":true,"img":false}]}
{"op":"mcm","clk":"5346606415","pt":1646092131176,"mc":[{"id":"1.195395444","rc":[{"atb":[[3.05,20.92]],"id":37174579}],"con":true,"img":false}]}
{"op":"mcm","clk":"5346606418","pt":1646092131275,"mc":[{"id":"1.195395444","rc":[{"atb":[[2.94,0]],"id":37174579}],"con":true,"img":false}]}
{"op":"mcm","clk":"5346606451","pt":1646092132768,"mc":[{"id":"1.195395444","rc":[{"atb":[[3.05,28.37]],"id":37174579}],"con":true,"img":false}]}
{"op":"mcm","clk":"5346606477","pt":1646092133589,"mc":[{"id":"1.195395444","rc":[{"atb":[[3,0]],"id":37174579}],"con":true,"img":false}]}
{"op":"mcm","clk":"5346606638","pt":1646092138663,"mc":[{"id":"1.195395444","rc":[{"atb":[[2.92,0]],"id":37174579}],"con":true,"img":false}]}
{"op":"mcm","clk":"5346606642","pt":1646092138767,"mc":[{"id":"1.195395444","rc":[{"atb":[[2.96,20.92]],"id":37174579}],"con":true,"img":false}]}
{"op":"mcm","clk":"5346606667","pt":1646092139482,"mc":[{"id":"1.195395444","rc":[{"atb":[[3.1,3.54]],"id":37174579}],"con":true,"img":false}]}
{"op":"mcm","clk":"5346606716","pt":1646092140562,"mc":[{"id":"1.195395444","rc":[{"atb":[[2.56,112.18]],"id":42236670}],"con":true,"img":false}]}
{"op":"mcm","clk":"5346606722","pt":1646092140668,"mc":[{"id":"1.195395444","rc":[{"atb":[[2.62,0],[2.76,56.82]],"id":40917095},{"atl":[[8,14.29],[8.4,0]],"id":40917095},{"atb":[[3,50],[2.84,0]],"id":42189436},{"atb":[[2.44,0]],"id":42236670},{"atl":[[3.55,39.22],[3.75,0]],"id":41523279},{"atb":[[1.84,0],[1.9,133.49]],"id":42236682}],"con":true,"img":false}]}
{"op":"mcm","clk":"5346606753","pt":1646092141282,"mc":[{"id":"1.195395444","rc":[{"atb":[[3.05,20.92]],"id":37174579}],"con":true,"img":false}]}
{"op":"mcm","clk":"5346606812","pt":1646092142570,"mc":[{"id":"1.195395444","rc":[{"atb":[[3.1,0]],"id":37174579}],"con":true,"img":false}]}
{"op":"mcm","clk":"5346606815","pt":1646092142672,"mc":[{"id":"1.195395444","rc":[{"atb":[[2.98,41.84],[3.05,0]],"id":37174579}],"con":true,"img":false}]}
{"op":"mcm","clk":"5346606907","pt":1646092144772,"mc":[{"id":"1.195395444","rc":[{"atb":[[2.92,24.09]],"id":37174579}],"con":true,"img":false}]}
{"op":"mcm","clk":"5346607074","pt":1646092148675,"mc":[{"id":"1.195395444","rc":[{"atb":[[2.96,0]],"id":37174579}],"con":true,"img":false}]}
{"op":"mcm","clk":"5346607080","pt":1646092148778,"mc":[{"id":"1.195395444","rc":[{"atb":[[2.92,45.02],[2.98,0],[2.94,51.55]],"id":37174579}],"con":true,"img":false}]}
{"op":"mcm","clk":"5346607419","pt":1646092158614,"mc":[{"id":"1.195395444","rc":[{"atb":[[3,3.72]],"id":37174579}],"con":true,"img":false}]}
{"op":"mcm","clk":"5346607421","pt":1646092158716,"mc":[{"id":"1.195395444","rc":[{"atb":[[2.94,0],[3.05,45.02]],"id":37174579}],"con":true,"img":false}]}
{"op":"mcm","clk":"5346607491","pt":1646092161328,"mc":[{"id":"1.195395444","rc":[{"atb":[[3,0]],"id":37174579}],"con":true,"img":false}]}
{"op":"mcm","clk":"5346607495","pt":1646092161481,"mc":[{"id":"1.195395444","rc":[{"atb":[[2.94,51.55],[3.05,0]],"id":37174579}],"con":true,"img":false}]}
{"op":"mcm","clk":"5346607508","pt":1646092161790,"mc":[{"id":"1.195395444","rc":[{"atb":[[2.92,20.92]],"id":37174579}],"con":true,"img":false}]}
{"op":"mcm","clk":"5346607646","pt":1646092165284,"mc":[{"id":"1.195395444","rc":[{"atb":[[2.96,23.6]],"id":37174579}],"con":true,"img":false}]}
{"op":"mcm","clk":"5346607756","pt":1646092168617,"mc":[{"id":"1.195395444","rc":[{"atb":[[2.92,0]],"id":37174579}],"con":true,"img":false}]}
{"op":"mcm","clk":"5346607760","pt":1646092168719,"mc":[{"id":"1.195395444","rc":[{"atb":[[2.96,44.52]],"id":37174579}],"con":true,"img":false}]}
{"op":"mcm","clk":"5346608017","pt":1646092175637,"mc":[{"id":"1.195395444","rc":[{"atb":[[1.82,41.04]],"id":42070475},{"atb":[[2.02,11.06]],"id":41523279},{"atb":[[1.92,36.57]],"id":42236682}],"con":true,"img":false}]}
{"op":"mcm","clk":"5346608032","pt":1646092175994,"mc":[{"id":"1.195395444","rc":[{"atb":[[3.05,3.63]],"id":37174579}],"con":true,"img":false}]}
{"op":"mcm","clk":"5346608039","pt":1646092176198,"mc":[{"id":"1.195395444","rc":[{"atb":[[3.1,44.53],[2.94,0]],"id":37174579}],"con":true,"img":false}]}
{"op":"mcm","clk":"5346608131","pt":1646092178619,"mc":[{"id":"1.195395444","rc":[{"atb":[[2.64,0]],"id":40917095},{"atb":[[3.05,0]],"id":37174579}],"con":true,"img":false}]}
{"op":"mcm","clk":"5346608136","pt":1646092178722,"mc":[{"id":"1.195395444","rc":[{"atb":[[2.78,38.26]],"id":40917095}],"con":true,"img":false}]}
{"op":"mcm","clk":"5346608143","pt":1646092178928,"mc":[{"id":"1.195395444","rc":[{"atb":[[1.81,0]],"id":42070475},{"atb":[[1.97,0]],"id":41523279},{"atb":[[2.96,20.92]],"id":37174579}],"con":true,"img":false}]}
{"op":"mcm","clk":"5346608235","pt":1646092181341,"mc":[{"id":"1.195395444","rc":[{"atb":[[3.1,0],[2.98,50.51]],"id":37174579}],"con":true,"img":false}]}
{"op":"mcm","clk":"5346608264","pt":1646092182118,"mc":[{"id":"1.195395444","rc":[{"atb":[[2.02,0]],"id":41523279}],"con":true,"img":false}]}
{"op":"mcm","clk":"5346608270","pt":1646092182424,"mc":[{"id":"1.195395444","rc":[{"atb":[[1.83,55.74]],"id":42070475},{"atb":[[1.97,35.96]],"id":41523279},{"atb":[[2.92,24.09]],"id":37174579}],"con":true,"img":false}]}
{"op":"mcm","clk":"5346608303","pt":1646092183553,"mc":[{"id":"1.195395444","rc":[{"atl":[[8.8,12.82],[9.4,1.42]],"id":42189436},{"atb":[[1.9,66.74],[1.95,67.3]],"id":42236682},{"atl":[[9,0],[8.6,2.63]],"id":37174579}],"con":true,"img":false}]}
{"op":"mcm","clk":"5346608347","pt":1646092184632,"mc":[{"id":"1.195395444","rc":[{"atb":[[2,8.36]],"id":41523279},{"atb":[[1.94,8.89]],"id":42236682}],"con":true,"img":false}]}
{"op":"mcm","clk":"5346608416","pt":1646092186429,"mc":[{"id":"1.195395444","rc":[{"atb":[[1.82,0]],"id":42070475},{"atb":[[2.02,11.06]],"id":41523279}],"con":true,"img":false}]}
{"op":"mcm","clk":"5346608495","pt":1646092188635,"mc":[{"id":"1.195395444","rc":[{"atb":[[2.96,0]],"id":37174579}],"con":true,"img":false}]}
{"op":"mcm","clk":"5346608499","pt":1646092188738,"mc":[{"id":"1.195395444","rc":[{"atb":[[2.92,45.02],[2.94,51.55]],"id":37174579}],"con":true,"img":false}]}
{"op":"mcm","clk":"5346608502","pt":1646092188840,"mc":[{"id":"1.195395444","rc":[{"atb":[[2.98,0]],"id":37174579}],"con":true,"img":false}]}
{"op":"mcm","clk":"5346608506","pt":1646092189146,"mc":[{"id":"1.195395444","rc":[{"atb":[[1.97,0]],"id":41523279}],"con":true,"img":false}]}
{"op":"mcm","clk":"5346608545","pt":1646092190627,"mc":[{"id":"1.195395444","rc":[{"atb":[[1.99,7.52]],"id":42236682}],"con":true,"img":false}]}
{"op":"mcm","clk":"5346608550","pt":1646092190833,"mc":[{"id":"1.195395444","rc":[{"atb":[[1.84,40.06]],"id":42070475}],"con":true,"img":false}]}
{"op":"mcm","clk":"5346608623","pt":1646092192635,"mc":[{"id":"1.195395444","rc":[{"atb":[[1.97,35.96]],"id":41523279},{"atb":[[1.95,33.65]],"id":42236682}],"con":true,"img":false}]}
{"op":"mcm","clk":"5346608647","pt":1646092193249,"mc":[{"id":"1.195395444","rc":[{"atb":[[2.02,0]],"id":41523279},{"atb":[[1.92,0]],"id":42236682}],"con":true,"img":false}]}
{"op":"mcm","clk":"5346608660","pt":1646092193556,"mc":[{"id":"1.195395444","rc":[{"atl":[[9,6.25]],"id":37174579}],"con":true,"img":false}]}
{"op":"mcm","clk":"5346608675","pt":1646092194122,"mc":[{"id":"1.195395444","rc":[{"atb":[[1.99,0]],"id":42236682}],"con":true,"img":false}]}
{"op":"mcm","clk":"5346608680","pt":1646092194328,"mc":[{"id":"1.195395444","rc":[{"atb":[[1.83,0]],"id":42070475}],"con":true,"img":false}]}
{"op":"mcm","clk":"5346608754","pt":1646092196126,"mc":[{"id":"1.195395444","rc":[{"atb":[[1.92,50.29]],"id":42236682}],"con":true,"img":false}]}
{"op":"mcm","clk":"5346608790","pt":1646092197049,"mc":[{"id":"1.195395444","rc":[{"atb":[[3,3.72]],"id":37174579}],"con":true,"img":false}]}
{"op":"mcm","clk":"5346608810","pt":1646092197563,"mc":[{"id":"1.195395444","rc":[{"atb":[[2.02,5.84]],"id":41523279},{"atb":[[1.92,86.87]],"id":42236682}],"con":true,"img":false}]}
{"op":"mcm","clk":"5346608821","pt":1646092197767,"mc":[{"id":"1.195395444","rc":[{"atl":[[10.5,0]],"id":37174579}],"con":true,"img":false}]}
{"op":"mcm","clk":"5346608828","pt":1646092197922,"mc":[{"id":"1.195395444","rc":[{"atb":[[1.85,54.43]],"id":42070475}],"con":true,"img":false}]}
{"op":"mcm","clk":"5346608861","pt":1646092198642,"mc":[{"id":"1.195395444","rc":[{"atl":[[10,0]],"id":37174579}],"con":true,"img":false}]}
{"op":"mcm","clk":"5346608865","pt":1646092198744,"mc":[{"id":"1.195395444","rc":[{"atl":[[11.5,3.38]],"id":37174579}],"con":true,"img":false}]}
{"op":"mcm","clk":"5346608919","pt":1646092199669,"mc":[{"id":"1.195395444","rc":[{"atb":[[1.97,0]],"id":41523279},{"atb":[[2.92,20.92]],"id":37174579}],"con":true,"img":false}]}
{"op":"mcm","clk":"5346608992","pt":1646092201158,"mc":[{"id":"1.195395444","rc":[{"atb":[[1.94,76.19],[1.95,0]],"id":42236682}],"con":true,"img":false}]}
{"op":"mcm","clk":"5346609028","pt":1646092202133,"mc":[{"id":"1.195395444","rc":[{"atb":[[1.84,0]],"id":42070475}],"con":true,"img":false}]}
{"op":"mcm","clk":"5346609066","pt":1646092203260,"mc":[{"id":"1.195395444","rc":[{"atb":[[2.94,0],[3.05,20.92]],"id":37174579}],"con":true,"img":false}]}
{"op":"mcm","clk":"5346609071","pt":1646092203362,"mc":[{"id":"1.195395444","rc":[{"atb":[[1.97,19]],"id":41523279},{"atb":[[3.05,28.37]],"id":37174579}],"con":true,"img":false}]}
{"op":"mcm","clk":"5346609079","pt":1646092203567,"mc":[{"id":"1.195395444","rc":[{"atl":[[9.4,8.93]],"id":37174579}],"con":true,"img":false}]}
{"op":"mcm","clk":"5346609097","pt":1646092204131,"mc":[{"id":"1.195395444","rc":[{"atb":[[2.02,0]],"id":41523279}],"con":true,"img":false}]}
{"op":"mcm","clk":"5346609173","pt":1646092206032,"mc":[{"id":"1.195395444","rc":[{"atb":[[2,15.81]],"id":41523279}],"con":true,"img":false}]}
{"op":"mcm","clk":"5346609178","pt":1646092206134,"mc":[{"id":"1.195395444","rc":[{"atb":[[3,0]],"id":37174579}],"con":true,"img":false}]}
{"op":"mcm","clk":"5346609193","pt":1646092206443,"mc":[{"id":"1.195395444","rc":[{"atb":[[1.86,39.13]],"id":42070475}],"con":true,"img":false}]}
{"op":"mcm","clk":"5346609301","pt":1646092208352,"mc":[{"id":"1.195395444","rc":[{"atb":[[1.85,0]],"id":42070475},{"atb":[[3.05,20.92]],"id":37174579}],"con":true,"img":false}]}
{"op":"mcm","clk":"5346609307","pt":1646092208454,"mc":[{"id":"1.195395444","rc":[{"atb":[[2.94,41.84]],"id":37174579}],"con":true,"img":false}]}
{"op":"mcm","clk":"5346609310","pt":1646092208558,"mc":[{"id":"1.195395444","rc":[{"atb":[[3.05,0]],"id":37174579}],"con":true,"img":false}]}
{"op":"mcm","clk":"5346609314","pt":1646092208661,"mc":[{"id":"1.195395444","rc":[{"atb":[[2.92,0]],"id":37174579}],"con":true,"img":false}]}
{"op":"mcm","clk":"5346609319","pt":1646092208764,"mc":[{"id":"1.195395444","rc":[{"atb":[[2.02,11.06]],"id":41523279},{"atb":[[2.92,52.08],[2.96,20.92]],"id":37174579}],"con":true,"img":false}]}
{"op":"mcm","clk":"5346609324","pt":1646092208866,"mc":[{"id":"1.195395444","rc":[{"atb":[[2.92,0],[2.98,41.84],[2.94,0]],"id":37174579}],"con":true,"img":false}]}
{"op":"mcm","clk":"5346609339","pt":1646092209176,"mc":[{"id":"1.195395444","rc":[{"atb":[[1.98,7.6]],"id":42236682}],"con":true,"img":false}]}
{"op":"mcm","clk":"5346609477","pt":1646092211955,"mc":[{"id":"1.195395444","rc":[{"atb":[[1.87,53.18]],"id":42070475},{"atb":[[1.97,0]],"id":41523279},{"atb":[[1.92,36.57]],"id":42236682},{"atb":[[2.92,24.09]],"id":37174579}],"con":true,"img":false}]}
{"op":"mcm","clk":"5346609514","pt":1646092212981,"mc":[{"id":"1.195395444","rc":[{"atb":[[1.92,0]],"id":42236682}],"con":true,"img":false}]}
{"op":"mcm","clk":"5346609545","pt":1646092213553,"mc":[{"id":"1.195395444","rc":[{"atl":[[9.8,15.56]],"id":37174579}],"con":true,"img":false}]}
{"op":"mcm","clk":"5346609599","pt":1646092214943,"mc":[{"id":"1.195395444","rc":[{"atb":[[1.86,0]],"id":42070475},{"atb":[[2.02,0]],"id":41523279}],"con":true,"img":false}]}
{"op":"mcm","clk":"5346609615","pt":1646092215455,"mc":[{"id":"1.195395444","rc":[{"atb":[[1.97,35.96]],"id":41523279},{"atb":[[1.92,28.5]],"id":42236682}],"con":true,"img":false}]}
{"op":"mcm","clk":"5346609680","pt":1646092217203,"mc":[{"id":"1.195395444","rc":[{"atb":[[1.92,39.14]],"id":42236682}],"con":true,"img":false}]}
{"op":"mcm","clk":"5346609729","pt":1646092218080,"mc":[{"id":"1.195395444","rc":[{"atb":[[2,8.36]],"id":41523279},{"atb":[[3.05,3.63]],"id":37174579}],"con":true,"img":false}]}
{"op":"mcm","clk":"5346609734","pt":1646092218182,"mc":[{"id":"1.195395444","rc":[{"atb":[[3.1,20.92]],"id":37174579}],"con":true,"img":false}]}
{"op":"mcm","clk":"5346609738","pt":1646092218285,"mc":[{"id":"1.195395444","rc":[{"atb":[[2.98,0]],"id":37174579}],"con":true,"img":false}]}
{"op":"mcm","clk":"5346609747","pt":1646092218699,"mc":[{"id":"1.195395444","rc":[{"atb":[[2.96,0]],"id":37174579}],"con":true,"img":false}]}
{"op":"mcm","clk":"5346609751","pt":1646092218753,"mc":[{"id":"1.195395444","rc":[{"atb":[[2.92,45.02]],"id":37174579}],"con":true,"img":false}]}
{"op":"mcm","clk":"5346609794","pt":1646092219881,"mc":[{"id":"1.195395444","rc":[{"atb":[[1.88,37.44]],"id":42070475},{"atb":[[2.02,11.06]],"id":41523279}],"con":true,"img":false}]}
{"op":"mcm","clk":"5346609824","pt":1646092220596,"mc":[{"id":"1.195395444","rc":[{"atb":[[2.92,20.92]],"id":37174579}],"con":true,"img":false}]}
{"op":"mcm","clk":"5346609844","pt":1646092221160,"mc":[{"id":"1.195395444","rc":[{"atb":[[3.05,0]],"id":37174579}],"con":true,"img":false}]}
{"op":"mcm","clk":"5346609887","pt":1646092222190,"mc":[{"id":"1.195395444","rc":[{"atb":[[1.87,0]],"id":42070475},{"atb":[[1.97,0]],"id":41523279}],"con":true,"img":false}]}
{"op":"mcm","clk":"5346609945","pt":1646092223275,"mc":[{"id":"1.195395444","rc":[{"atb":[[3.1,0],[2.94,41.84]],"id":37174579}],"con":true,"img":false}]}
{"op":"mcm","clk":"5346609979","pt":1646092223897,"mc":[{"id":"1.195395444","rc":[{"atb":[[2.94,65.68]],"id":37174579}],"con":true,"img":false}]}
{"op":"mcm","clk":"5346610056","pt":1646092225799,"mc":[{"id":"1.195395444","rc":[{"atb":[[1.89,51.98]],"id":42070475},{"atb":[[1.97,35.96]],"id":41523279}],"con":true,"img":false}]}
{"op":"mcm","clk":"5346610083","pt":1646092226263,"mc":[{"id":"1.195395444","rc":[{"atb":[[2.02,0]],"id":41523279}],"con":true,"img":false}]}
{"op":"mcm","clk":"5346610175","pt":1646092228269,"mc":[{"id":"1.195395444","rc":[{"atb":[[1.88,0]],"id":42070475}],"con":true,"img":false}]}
{"op":"mcm","clk":"5346610265","pt":1646092230069,"mc":[{"id":"1.195395444","rc":[{"atb":[[3,3.72]],"id":37174579}],"con":true,"img":false}]}
{"op":"mcm","clk":"5346610277","pt":1646092230377,"mc":[{"id":"1.195395444","rc":[{"atb":[[2.02,5.84]],"id":41523279}],"con":true,"img":false}]}
{"op":"mcm","clk":"5346610384","pt":1646092232485,"mc":[{"id":"1.195395444","rc":[{"atb":[[1.97,0]],"id":41523279}],"con":true,"img":false}]}
{"op":"mcm","clk":"5346610402","pt":1646092232793,"mc":[{"id":"1.195395444","rc":[{"atb":[[1.9,34.67]],"id":42070475}],"con":true,"img":false}]}
{"op":"mcm","clk":"5346610478","pt":1646092234808,"mc":[{"id":"1.195395444","rc":[{"atb":[[2.02,0]],"id":41523279}],"con":true,"img":false}]}
{"op":"mcm","clk":"5346610533","pt":1646092236093,"mc":[{"id":"1.195395444","rc":[{"atb":[[1.89,0]],"id":42070475},{"atb":[[1.97,19]],"id":41523279}],"con":true,"img":false}]}
{"op":"mcm","clk":"5346610583","pt":1646092237376,"mc":[{"id":"1.195395444","rc":[{"atb":[[2.94,23.84],[3.05,20.92]],"id":37174579}],"con":true,"img":false}]}
{"op":"mcm","clk":"5346610633","pt":1646092238605,"mc":[{"id":"1.195395444","rc":[{"atl":[[11.5,0]],"id":37174579}],"con":true,"img":false}]}
{"op":"mcm","clk":"5346610638","pt":1646092238708,"mc":[{"id":"1.195395444","rc":[{"atl":[[9.6,3.38]],"id":37174579}],"con":true,"img":false}]}
{"op":"mcm","clk":"5346610652","pt":1646092239119,"mc":[{"id":"1.195395444","rc":[{"atb":[[2,15.81],[2.02,5.84]],"id":41523279},{"atb":[[3,0]],"id":37174579}],"con":true,"img":false}]}
{"op":"mcm","clk":"5346610657","pt":1646092239221,"mc":[{"id":"1.195395444","rc":[{"atb":[[2.96,41.84]],"id":37174579}],"con":true,"img":false}]}
{"op":"mcm","clk":"5346610661","pt":1646092239323,"mc":[{"id":"1.195395444","rc":[{"atb":[[3.05,0]],"id":37174579}],"con":true,"img":false}]}
{"op":"mcm","clk":"5346610673","pt":1646092239581,"mc":[{"id":"1.195395444","rc":[{"atb":[[1.91,50.84]],"id":42070475},{"atb":[[2.94,0]],"id":37174579}],"con":true,"img":false}]}
{"op":"mcm","clk":"5346610677","pt":1646092239683,"mc":[{"id":"1.195395444","rc":[{"atb":[[2.96,0],[2.94,51.55]],"id":37174579}],"con":true,"img":false}]}
{"op":"mcm","clk":"5346610745","pt":1646092241331,"mc":[{"id":"1.195395444","rc":[{"atb":[[1.97,0]],"id":41523279}],"con":true,"img":false}]}
{"op":"mcm","clk":"5346610827","pt":1646092243128,"mc":[{"id":"1.195395444","rc":[{"atb":[[2.96,23.6]],"id":37174579}],"con":true,"img":false}]}
{"op":"mcm","clk":"5346610828","pt":1646092243230,"mc":[{"id":"1.195395444","rc":[{"atb":[[2.98,23.61],[2.94,0]],"id":37174579}],"con":true,"img":false}]}
{"op":"mcm","clk":"5346610850","pt":1646092243691,"mc":[{"id":"1.195395444","rc":[{"atb":[[1.9,0]],"id":42070475}],"con":true,"img":false}]}
{"op":"mcm","clk":"5346610899","pt":1646092244925,"mc":[{"id":"1.195395444","rc":[{"atb":[[1.97,19]],"id":41523279}],"con":true,"img":false}]}
{"op":"mcm","clk":"5346610924","pt":1646092245798,"mc":[{"id":"1.195395444","rc":[{"atb":[[2.02,0]],"id":41523279}],"con":true,"img":false}]}
{"op":"mcm","clk":"5346610956","pt":1646092246620,"mc":[{"id":"1.195395444","rc":[{"atb":[[2.96,0]],"id":37174579}],"con":true,"img":false}]}
{"op":"mcm","clk":"5346611023","pt":1646092248109,"mc":[{"id":"1.195395444","rc":[{"atb":[[1.92,31.89]],"id":42070475}],"con":true,"img":false}]}
{"op":"mcm","clk":"5346611036","pt":1646092248316,"mc":[{"id":"1.195395444","rc":[{"atb":[[2.94,47.22]],"id":37174579}],"con":true,"img":false}]}
{"op":"mcm","clk":"5346611044","pt":1646092248520,"mc":[{"id":"1.195395444","rc":[{"atb":[[2.98,0]],"id":37174579}],"con":true,"img":false}]}
{"op":"mcm","clk":"5346611108","pt":1646092250110,"mc":[{"id":"1.195395444","rc":[{"atb":[[1.91,0]],"id":42070475},{"atb":[[3,23.12]],"id":37174579}],"con":true,"img":false}]}
{"op":"mcm","clk":"5346611136","pt":1646092250724,"mc":[{"id":"1.195395444","rc":[{"atb":[[2.02,11.06]],"id":41523279}],"con":true,"img":false}]}
{"op":"mcm","clk":"5346611217","pt":1646092252620,"mc":[{"id":"1.195395444","rc":[{"atl":[[8.4,2.7],[8.6,0],[18,5.88],[21,0]],"id":37174579}],"con":true,"img":false}]}
{"op":"mcm","clk":"5346611258","pt":1646092253609,"mc":[{"id":"1.195395444","rc":[{"atb":[[1.93,49.74]],"id":42070475},{"atb":[[1.97,0]],"id":41523279}],"con":true,"img":false}]}
{"op":"mcm","clk":"5346611317","pt":1646092255310,"mc":[{"id":"1.195395444","rc":[{"atb":[[3,0]],"id":37174579}],"con":true,"img":false}]}
{"op":"mcm","clk":"5346611374","pt":1646092257003,"mc":[{"id":"1.195395444","rc":[{"atb":[[1.92,0]],"id":42070475},{"atb":[[2.02,0]],"id":41523279}],"con":true,"img":false}]}
{"op":"mcm","clk":"5346611379","pt":1646092257104,"mc":[{"id":"1.195395444","rc":[{"atb":[[1.97,35.96]],"id":41523279}],"con":true,"img":false}]}
{"op":"mcm","clk":"5346611385","pt":1646092257208,"mc":[{"id":"1.195395444","rc":[{"atb":[[3,3.72]],"id":37174579}],"con":true,"img":false}]}
{"op":"mcm","clk":"5346611388","pt":1646092257310,"mc":[{"id":"1.195395444","rc":[{"atb":[[2.94,0],[3.05,20.92]],"id":37174579}],"con":true,"img":false}]}
{"op":"mcm","clk":"5346611444","pt":1646092258903,"mc":[{"id":"1.195395444","rc":[{"atb":[[2.96,23.6]],"id":37174579}],"con":true,"img":false}]}
{"op":"mcm","clk":"5346611488","pt":1646092260237,"mc":[{"id":"1.195395444","rc":[{"atb":[[2,8.36]],"id":41523279},{"atb":[[3,0]],"id":37174579}],"con":true,"img":false}]}
{"op":"mcm","clk":"5346611557","pt":1646092262043,"mc":[{"id":"1.195395444","rc":[{"atb":[[1.94,29.12]],"id":42070475},{"atb":[[2.02,11.06]],"id":41523279}],"con":true,"img":false}]}
{"op":"mcm","clk":"5346611576","pt":1646092262457,"mc":[{"id":"1.195395444","rc":[{"atb":[[2.98,41.84],[2.96,0],[3.05,0]],"id":37174579}],"con":true,"img":false}]}
{"op":"mcm","clk":"5346611589","pt":1646092262612,"mc":[{"id":"1.195395444","rc":[{"atb":[[2.98,0],[2.94,51.55]],"id":37174579}],"con":true,"img":false}]}
{"op":"mcm","clk":"5346611655","pt":1646092263946,"mc":[{"id":"1.195395444","rc":[{"atb":[[1.93,0]],"id":42070475},{"atb":[[1.97,0]],"id":41523279}],"con":true,"img":false}]}
{"op":"mcm","clk":"5346611734","pt":1646092265746,"mc":[{"id":"1.195395444","rc":[{"atb":[[2.96,23.6]],"id":37174579}],"con":true,"img":false}]}
{"op":"mcm","clk":"5346611798","pt":1646092267540,"mc":[{"id":"1.195395444","rc":[{"atb":[[1.95,48.7]],"id":42070475},{"atb":[[1.97,35.96]],"id":41523279}],"con":true,"img":false}]}
{"op":"mcm","clk":"5346611821","pt":1646092268154,"mc":[{"id":"1.195395444","rc":[{"atb":[[2.02,0]],"id":41523279}],"con":true,"img":false}]}
{"op":"mcm","clk":"5346611872","pt":1646092269128,"mc":[{"id":"1.195395444","rc":[{"atb":[[3,3.72]],"id":37174579}],"con":true,"img":false}]}
{"op":"mcm","clk":"5346611924","pt":1646092270360,"mc":[{"id":"1.195395444","rc":[{"atb":[[1.94,0]],"id":42070475}],"con":true,"img":false}]}
{"op":"mcm","clk":"5346611957","pt":1646092271032,"mc":[{"id":"1.195395444","rc":[{"atb":[[1.95,0]],"id":42070475},{"atb":[[2.96,0]],"id":37174579}],"con":true,"img":false}]}
{"op":"mcm","clk":"5346612014","pt":1646092272633,"mc":[{"id":"1.195395444","rc":[{"atb":[[2.02,5.84]],"id":41523279}],"con":true,"img":false}]}
{"op":"mcm","clk":"5346612094","pt":1646092274634,"mc":[{"id":"1.195395444","rc":[{"atb":[[1.81,57.11]],"id":42070475},{"atb":[[1.97,0]],"id":41523279},{"atb":[[3.05,7.45]],"id":37174579}],"con":true,"img":false}]}
{"op":"mcm","clk":"5346612102","pt":1646092274840,"mc":[{"id":"1.195395444","rc":[{"atb":[[1.81,98.66]],"id":42070475}],"con":true,"img":false}]}
{"op":"mcm","clk":"5346612163","pt":1646092276332,"mc":[{"id":"1.195395444","rc":[{"atb":[[3.1,7.45],[2.94,0]],"id":37174579}],"con":true,"img":false}]}
{"op":"mcm","clk":"5346612221","pt":1646092278177,"mc":[{"id":"1.195395444","rc":[{"atb":[[1.97,19]],"id":41523279}],"con":true,"img":false}]}
{"op":"mcm","clk":"5346612226","pt":1646092278382,"mc":[{"id":"1.195395444","rc":[{"atb":[[3,0]],"id":37174579}],"con":true,"img":false}]}
{"op":"mcm","clk":"5346612271","pt":1646092279967,"mc":[{"id":"1.195395444","rc":[{"atb":[[3.05,0]],"id":37174579}],"con":true,"img":false}]}
{"op":"mcm","clk":"5346612274","pt":1646092280068,"mc":[{"id":"1.195395444","rc":[{"atb":[[2.94,20.92]],"id":37174579}],"con":true,"img":false}]}
{"op":"mcm","clk":"5346612276","pt":1646092280172,"mc":[{"id":"1.195395444","rc":[{"atb":[[3.1,0]],"id":37174579}],"con":true,"img":false}]}
{"op":"mcm","clk":"5346612313","pt":1646092281248,"mc":[{"id":"1.195395444","rc":[{"atb":[[2,15.81]],"id":41523279}],"con":true,"img":false}]}
{"op":"mcm","clk":"5346612317","pt":1646092281351,"mc":[{"id":"1.195395444","rc":[{"atb":[[2.02,0]],"id":41523279}],"con":true,"img":false}]}
{"op":"mcm","clk":"5346612344","pt":1646092282379,"mc":[{"id":"1.195395444","rc":[{"atl":[[4.8,0],[4.6,0],[5,0],[5.5,4.44],[5.2,0]],"id":42236670},{"atl":[[5.6,0],[6.4,8.14],[5.8,14.52],[5.4,0]],"id":42070475},{"atb":[[1.44,147.06],[1.26,0],[1.36,0],[1.54,37.04]],"id":41523279},{"atb":[[1.8,272.9],[1.91,0],[1.9,88.96],[1.94,8.89]],"id":42236682},{"atb":[[2.82,0],[2,20],[2.74,0],[1.89,63.24],[2.78,0],[2.94,0],[2.7,70.67]],"id":37174579}],"con":true,"img":false}]}
{"op":"mcm","clk":"5346612353","pt":1646092282585,"mc":[{"id":"1.195395444","rc":[{"atl":[[6,0]],"id":42070475}],"con":true,"img":false}]}
{"op":"mcm","clk":"5346612386","pt":1646092283356,"mc":[{"id":"1.195395444","rc":[{"atb":[[2.96,23.6]],"id":37174579}],"con":true,"img":false}]}
{"op":"mcm","clk":"5346612431","pt":1646092284483,"mc":[{"id":"1.195395444","rc":[{"atb":[[1.98,0]],"id":42236682},{"atb":[[2.96,27.4]],"id":37174579}],"con":true,"img":false}]}
{"op":"mcm","clk":"5346612463","pt":1646092285052,"mc":[{"id":"1.195395444","rc":[{"atb":[[2.66,0]],"id":42236670}],"con":true,"img":false}]}
{"op":"mcm","clk":"5346612502","pt":1646092285771,"mc":[{"id":"1.195395444","rc":[{"atb":[[2.02,11.06]],"id":41523279}],"con":true,"img":false}]}
{"op":"mcm","clk":"5346612534","pt":1646092286743,"mc":[{"id":"1.195395444","rc":[{"atb":[[1.92,10.64]],"id":42236682}],"con":true,"img":false}]}
{"op":"mcm","clk":"5346612563","pt":1646092287564,"mc":[{"id":"1.195395444","rc":[{"atb":[[1.92,0]],"id":42236682}],"con":true,"img":false}]}
{"op":"mcm","clk":"5346612596","pt":1646092288589,"mc":[{"id":"1.195395444","rc":[{"atb":[[2.66,27.86]],"id":42236670}],"con":true,"img":false}]}
{"op":"mcm","clk":"5346612661","pt":1646092290387,"mc":[{"id":"1.195395444","rc":[{"atb":[[1.91,26.69]],"id":42236682}],"con":true,"img":false}]}
{"op":"mcm","clk":"5346612731","pt":1646092291980,"mc":[{"id":"1.195395444","rc":[{"atb":[[1.91,36.47]],"id":42236682}],"con":true,"img":false}]}
{"op":"mcm","clk":"5346612750","pt":1646092292390,"mc":[{"id":"1.195395444","rc":[{"atl":[[5.7,10.64]],"id":42236670},{"atl":[[6.8,8.62]],"id":42070475},{"atb":[[1.52,96.15]],"id":41523279},{"atb":[[1.88,56.82]],"id":42236682},{"atb":[[1.98,51.02]],"id":37174579}],"con":true,"img":false}]}
{"op":"mcm","clk":"5346612798","pt":1646092293363,"mc":[{"id":"1.195395444","rc":[{"atb":[[1.94,16.82]],"id":42236682}],"con":true,"img":false}]}
{"op":"mcm","clk":"5346612854","pt":1646092294955,"mc":[{"id":"1.195395444","rc":[{"atb":[[1.3,0]],"id":41523279},{"atb":[[1.89,0],[1.85,141.35],[1.87,0]],"id":42236682}],"con":true,"img":false}]}
{"op":"mcm","clk":"5346612870","pt":1646092295465,"mc":[{"id":"1.195395444","rc":[{"atb":[[2.66,0]],"id":42236670}],"con":true,"img":false}]}
{"op":"mcm","clk":"5346613001","pt":1646092298958,"mc":[{"id":"1.195395444","rc":[{"atb":[[2.66,27.86]],"id":42236670}],"con":true,"img":false}]}
{"op":"mcm","clk":"5346613012","pt":1646092299372,"mc":[{"id":"1.195395444","rc":[{"atb":[[3.05,4.07]],"id":37174579}],"con":true,"img":false}]}
{"op":"mcm","clk":"5346613018","pt":1646092299576,"mc":[{"id":"1.195395444","rc":[{"atb":[[2.56,48.08],[2.6,168.84]],"id":42236670}],"con":true,"img":false}]}
{"op":"mcm","clk":"5346613118","pt":1646092302403,"mc":[{"id":"1.195395444","rc":[{"atl":[[5.9,15.31]],"id":42236670},{"atl":[[7.2,12.1]],"id":42070475},{"atb":[[1.5,150]],"id":41523279},{"atb":[[1.86,87.21]],"id":42236682},{"atb":[[1.96,78.12],[2.96,3.8]],"id":37174579}],"con":true,"img":false}]}
{"op":"mcm","clk":"5346613162","pt":1646092303579,"mc":[{"id":"1.195395444","rc":[{"atb":[[1.32,0]],"id":41523279}],"con":true,"img":false}]}
{"op":"mcm","clk":"5346613253","pt":1646092305892,"mc":[{"id":"1.195395444","rc":[{"atb":[[2.98,11.22]],"id":37174579}],"con":true,"img":false}]}
{"op":"mcm","clk":"5346613490","pt":1646092312406,"mc":[{"id":"1.195395444","rc":[{"atl":[[6.2,24.04]],"id":42236670},{"atl":[[7.6,18.94]],"id":42070475},{"atb":[[1.48,250]],"id":41523279},{"atb":[[1.84,148.81]],"id":42236682},{"atb":[[1.94,132.98]],"id":37174579}],"con":true,"img":false}]}
{"op":"mcm","clk":"5346613574","pt":1646092314611,"mc":[{"id":"1.195395444","rc":[{"atl":[[7.6,0]],"id":42236670},{"atb":[[2.92,0]],"id":37174579}],"con":true,"img":false}]}
{"op":"mcm","clk":"5346613577","pt":1646092314714,"mc":[{"id":"1.195395444","rc":[{"atl":[[8.2,6.99]],"id":42236670},{"atb":[[2.72,20.92]],"id":37174579}],"con":true,"img":false}]}
{"op":"mcm","clk":"5346613642","pt":1646092316481,"mc":[{"id":"1.195395444","rc":[{"atb":[[3.05,0]],"id":37174579}],"con":true,"img":false}]}
{"op":"mcm","clk":"5346613730","pt":1646092319203,"mc":[{"id":"1.195395444","rc":[{"atb":[[1.34,0]],"id":41523279}],"con":true,"img":false}]}
{"op":"mcm","clk":"5346613739","pt":1646092319513,"mc":[{"id":"1.195395444","rc":[{"atb":[[2.98,0]],"id":37174579}],"con":true,"img":false}]}
{"op":"mcm","clk":"5346613845","pt":1646092323011,"mc":[{"id":"1.195395444","rc":[{"atb":[[2.82,15.2]],"id":37174579}],"con":true,"img":false}]}
{"op":"mcm","clk":"5346613851","pt":1646092323113,"mc":[{"id":"1.195395444","rc":[{"atb":[[2.96,8.06]],"id":37174579}],"con":true,"img":false}]}
{"op":"mcm","clk":"5346613855","pt":1646092323215,"mc":[{"id":"1.195395444","rc":[{"atb":[[2.44,47.56],[2.78,0]],"id":40917095},{"atl":[[7.8,0]],"id":42070475}],"con":true,"img":false}]}
{"op":"mcm","clk":"5346613861","pt":1646092323317,"mc":[{"id":"1.195395444","rc":[{"atl":[[6.6,36.5]],"id":42070475}],"con":true,"img":false}]}
{"op":"mcm","clk":"5346613941","pt":1646092325811,"mc":[{"id":"1.195395444","rc":[{"atl":[[6.6,0]],"id":40917095},{"atb":[[1.9,66.74],[1.86,23.26]],"id":42236682},{"atl":[[2.9,10.53]],"id":42236682}],"con":true,"img":false}]}
{"op":"mcm","clk":"5346613943","pt":1646092325913,"mc":[{"id":"1.195395444","rc":[{"atl":[[8,0],[8.2,15.55],[6.8,3.45]],"id":40917095},{"atl":[[2.98,0]],"id":42236682}],"con":true,"img":false}]}
{"op":"mcm","clk":"5346613963","pt":1646092326633,"mc":[{"id":"1.195395444","rc":[{"atb":[[1.88,0]],"id":42236682}],"con":true,"img":false}]}
{"op":"mcm","clk":"5346614253","pt":1646092335930,"mc":[{"id":"1.195395444","rc":[{"atl":[[7.2,8.06]],"id":40917095},{"atb":[[1.84,59.52]],"id":42236682},{"atl":[[2.94,25.77]],"id":42236682}],"con":true,"img":false}]}
{"op":"mcm","clk":"5346614341","pt":1646092338511,"mc":[{"id":"1.195395444","rc":[{"atl":[[8.2,0]],"id":42236670}],"con":true,"img":false}]}
{"op":"mcm","clk":"5346614347","pt":1646092338613,"mc":[{"id":"1.195395444","rc":[{"atl":[[7.8,6.99]],"id":42236670}],"con":true,"img":false}]}
{"op":"mcm","clk":"5346614552","pt":1646092344316,"mc":[{"id":"1.195395444","rc":[{"atl":[[7.4,0],[7,0],[7.8,0]],"id":40917095},{"atl":[[3.25,0]],"id":42236682}],"con":true,"img":false}]}
{"op":"mcm","clk":"5346614609","pt":1646092345956,"mc":[{"id":"1.195395444","rc":[{"atl":[[7.6,11.36]],"id":40917095},{"atb":[[1.82,91.46]],"id":42236682},{"atl":[[2.98,37.88]],"id":42236682}],"con":true,"img":false}]}
{"op":"mcm","clk":"5346614825","pt":1646092352326,"mc":[{"id":"1.195395444","rc":[{"atl":[[3.15,0]],"id":42236682}],"con":true,"img":false}]}
{"op":"mcm","clk":"5346614975","pt":1646092355972,"mc":[{"id":"1.195395444","rc":[{"atl":[[8,17.86]],"id":40917095},{"atb":[[1.8,429.15]],"id":42236682},{"atl":[[3.05,60.98]],"id":42236682}],"con":true,"img":false}]}
{"op":"mcm","clk":"5346615470","pt":1646092368563,"mc":[{"id":"1.195395444","rc":[{"atb":[[1.81,0]],"id":42236682}],"con":true,"img":false}]}
{"op":"mcm","clk":"5346615474","pt":1646092368665,"mc":[{"id":"1.195395444","rc":[{"atb":[[1.83,40.59]],"id":42236682}],"con":true,"img":false}]}
{"op":"mcm","clk":"5346617768","pt":1646092428556,"mc":[{"id":"1.195395444","rc":[{"atb":[[2.78,33.25]],"id":40917095}],"con":true,"img":false}]}
{"op":"mcm","clk":"5346617770","pt":1646092428658,"mc":[{"id":"1.195395444","rc":[{"atb":[[2.44,0]],"id":40917095}],"con":true,"img":false}]}
{"op":"mcm","clk":"5346618239","pt":1646092443182,"mc":[{"id":"1.195395444","rc":[{"atb":[[2.76,0]],"id":40917095},{"atl":[[3.55,0]],"id":41523279}],"con":true,"img":false}]}
{"op":"mcm","clk":"5346618243","pt":1646092443287,"mc":[{"id":"1.195395444","rc":[{"atb":[[2.64,60.98]],"id":40917095},{"atb":[[2.74,57.47],[3,0]],"id":42189436},{"atb":[[2.46,68.49],[2.6,106.34]],"id":42236670},{"atl":[[3.75,36.36]],"id":41523279}],"con":true,"img":false}]}
{"op":"mcm","clk":"5346618284","pt":1646092444875,"mc":[{"id":"1.195395444","rc":[{"atb":[[3.4,3.1],[3.5,8]],"id":40917095},{"atl":[[7,3.33]],"id":40917095}],"con":true,"img":false}]}
{"op":"mcm","clk":"5346618288","pt":1646092444981,"mc":[{"id":"1.195395444","rc":[{"atl":[[6.8,0]],"id":40917095}],"con":true,"img":false}]}
{"op":"mcm","clk":"5346618354","pt":1646092446983,"mc":[{"id":"1.195395444","rc":[{"atb":[[3.45,0]],"id":40917095}],"con":true,"img":false}]}
{"op":"mcm","clk":"5346618418","pt":1646092448678,"mc":[{"id":"1.195395444","rc":[{"atb":[[2.78,0]],"id":40917095}],"con":true,"img":false}]}
{"op":"mcm","clk":"5346618419","pt":1646092448784,"mc":[{"id":"1.195395444","rc":[{"atb":[[2.66,33.25]],"id":40917095}],"con":true,"img":false}]}
{"op":"mcm","clk":"5346618489","pt":1646092450474,"mc":[{"id":"1.195395444","rc":[{"atb":[[3.55,16]],"id":40917095}],"con":true,"img":false}]}
{"op":"mcm","clk":"5346618653","pt":1646092454900,"mc":[{"id":"1.195395444","rc":[{"atb":[[3.4,23.93]],"id":40917095},{"atl":[[7.4,7.81]],"id":40917095}],"con":true,"img":false}]}
{"op":"mcm","clk":"5346618692","pt":1646092455775,"mc":[{"id":"1.195395444","rc":[{"atb":[[3.4,20.83]],"id":40917095}],"con":true,"img":false}]}
{"op":"mcm","clk":"5346618709","pt":1646092456289,"mc":[{"id":"1.195395444","rc":[{"atb":[[3.1,0]],"id":40917095},{"atl":[[8,0],[7.2,0],[7.6,0]],"id":40917095}],"con":true,"img":false}]}
{"op":"mcm","clk":"5346618912","pt":1646092461776,"mc":[{"id":"1.195395444","rc":[{"atb":[[3.5,10.98]],"id":40917095}],"con":true,"img":false}]}
{"op":"mcm","clk":"5346619035","pt":1646092465032,"mc":[{"id":"1.195395444","rc":[{"atb":[[3.3,32.61]],"id":40917095},{"atl":[[7.8,11.03]],"id":40917095}],"con":true,"img":false}]}
{"op":"mcm","clk":"5346619355","pt":1646092474932,"mc":[{"id":"1.195395444","rc":[{"atb":[[3.2,56.82]],"id":40917095},{"atl":[[8.2,32.91]],"id":40917095}],"con":true,"img":false}]}
{"op":"mcm","clk":"5346619465","pt":1646092478626,"mc":[{"id":"1.195395444","rc":[{"atb":[[2.46,0],[2.76,39.28]],"id":42189436}],"con":true,"img":false}]}
{"op":"mcm","clk":"5346620563","pt":1646092515955,"mc":[{"id":"1.195395444","rc":[{"atb":[[2.64,0],[2.76,56.82]],"id":40917095},{"atl":[[8,14.29],[8.2,19.02]],"id":40917095},{"atb":[[2.74,0],[2.9,52.63]],"id":42189436},{"atb":[[2.46,0],[2.6,154.42]],"id":42236670},{"atl":[[3.55,39.22],[3.75,0]],"id":41523279},{"atl":[[2.92,10.42],[2.9,0]],"id":42236682}],"con":true,"img":false}]}
{"op":"mcm","clk":"5346620603","pt":1646092517387,"mc":[{"id":"1.195395444","rc":[{"atl":[[2.9,10.53]],"id":42236682}],"con":true,"img":false}]}
{"op":"mcm","clk":"5346620607","pt":1646092517490,"mc":[{"id":"1.195395444","rc":[{"atl":[[2.92,0]],"id":42236682}],"con":true,"img":false}]}
{"op":"mcm","clk":"5346620643","pt":1646092518566,"mc":[{"id":"1.195395444","rc":[{"atb":[[2.46,52.27]],"id":42189436}],"con":true,"img":false}]}
{"op":"mcm","clk":"5346620647","pt":1646092518670,"mc":[{"id":"1.195395444","rc":[{"atb":[[2.76,0]],"id":42189436}],"con":true,"img":false}]}
{"op":"mcm","clk":"5346621642","pt":1646092548610,"mc":[{"id":"1.195395444","rc":[{"atb":[[2.66,0]],"id":40917095}],"con":true,"img":false}]}
{"op":"mcm","clk":"5346621644","pt":1646092548711,"mc":[{"id":"1.195395444","rc":[{"atb":[[2.78,33.25]],"id":40917095}],"con":true,"img":false}]}
{"op":"mcm","clk":"5346622042","pt":1646092560109,"mc":[{"id":"1.195395444","rc":[{"atl":[[7.2,3.23],[7,0]],"id":40917095},{"atl":[[5.5,0],[6,4],[5.7,0],[5.9,0]],"id":42236670},{"atb":[[1.54,0],[1.5,40],[1.52,0]],"id":41523279},{"atb":[[1.83,64.69],[1.84,0],[1.86,0]],"id":42236682}],"con":true,"img":false}]}
{"op":"mcm","clk":"5346622047","pt":1646092560211,"mc":[{"id":"1.195395444","rc":[{"atl":[[6.8,0],[7,16.67]],"id":42236670}],"con":true,"img":false}]}
{"op":"mcm","clk":"5346622051","pt":1646092560415,"mc":[{"id":"1.195395444","rc":[{"atl":[[6,0]],"id":42236670}],"con":true,"img":false}]}
{"op":"mcm","clk":"5346622114","pt":1646092562620,"mc":[{"id":"1.195395444","rc":[{"atb":[[2.66,0]],"id":42236670}],"con":true,"img":false}]}
{"op":"mcm","clk":"5346622183","pt":1646092564619,"mc":[{"id":"1.195395444","rc":[{"atl":[[6,4]],"id":42236670}],"con":true,"img":false}]}
{"op":"mcm","clk":"5346622236","pt":1646092566106,"mc":[{"id":"1.195395444","rc":[{"atb":[[2.66,27.87]],"id":42236670}],"con":true,"img":false}]}
{"op":"mcm","clk":"5346622401","pt":1646092570119,"mc":[{"id":"1.195395444","rc":[{"atl":[[7.6,7.58]],"id":40917095},{"atb":[[1.48,104.17]],"id":41523279},{"atb":[[1.81,61.73]],"id":42236682}],"con":true,"img":false}]}
{"op":"mcm","clk":"5346622500","pt":1646092573555,"mc":[{"id":"1.195395444","rc":[{"atb":[[3.25,19.32]],"id":40917095}],"con":true,"img":false}]}
{"op":"mcm","clk":"5346622533","pt":1646092574636,"mc":[{"id":"1.195395444","rc":[{"atl":[[6.4,9.26],[6,0]],"id":42236670}],"con":true,"img":false}]}
{"op":"mcm","clk":"5346622588","pt":1646092576541,"mc":[{"id":"1.195395444","rc":[{"atl":[[8.2,1.66],[7.4,0],[7.8,0]],"id":40917095},{"atl":[[6,4]],"id":42236670}],"con":true,"img":false}]}
{"op":"mcm","clk":"5346622591","pt":1646092576650,"mc":[{"id":"1.195395444","rc":[{"atb":[[2.66,0]],"id":42236670}],"con":true,"img":false}]}
{"op":"mcm","clk":"5346622642","pt":1646092578343,"mc":[{"id":"1.195395444","rc":[{"atb":[[3.4,24.31]],"id":40917095}],"con":true,"img":false}]}
{"op":"mcm","clk":"5346622651","pt":1646092578652,"mc":[{"id":"1.195395444","rc":[{"atl":[[7.8,0]],"id":42236670}],"con":true,"img":false}]}
{"op":"mcm","clk":"5346622654","pt":1646092578754,"mc":[{"id":"1.195395444","rc":[{"atl":[[6.8,6.99]],"id":42236670}],"con":true,"img":false}]}
{"op":"mcm","clk":"5346622678","pt":1646092580138,"mc":[{"id":"1.195395444","rc":[{"atl":[[8,25]],"id":40917095},{"atb":[[2.66,27.87]],"id":42236670},{"atb":[[1.46,163.04]],"id":41523279},{"atb":[[1.79,94.94]],"id":42236682}],"con":true,"img":false}]}
{"op":"mcm","clk":"5346622690","pt":1646092580651,"mc":[{"id":"1.195395444","rc":[{"atl":[[6,0]],"id":42236670},{"atb":[[1.82,0],[1.8,272.9]],"id":42236682}],"con":true,"img":false}]}
{"op":"mcm","clk":"5346622855","pt":1646092586341,"mc":[{"id":"1.195395444","rc":[{"atl":[[6,4]],"id":42236670}],"con":true,"img":false}]}
{"op":"mcm","clk":"5346622915","pt":1646092588659,"mc":[{"id":"1.195395444","rc":[{"atb":[[2.66,0]],"id":42236670},{"atl":[[6,0]],"id":42236670},{"atb":[[1.83,24.1]],"id":42236682}],"con":true,"img":false}]}
{"op":"mcm","clk":"5346622918","pt":1646092588761,"mc":[{"id":"1.195395444","rc":[{"atb":[[1.82,40.59]],"id":42236682}],"con":true,"img":false}]}
{"op":"mcm","clk":"5346622965","pt":1646092590142,"mc":[{"id":"1.195395444","rc":[{"atl":[[8.4,16.89]],"id":40917095},{"atb":[[1.44,397.06]],"id":41523279},{"atb":[[1.77,162.34]],"id":42236682}],"con":true,"img":false}]}
{"op":"mcm","clk":"5346623085","pt":1646092593786,"mc":[{"id":"1.195395444","rc":[{"atb":[[2.66,27.87]],"id":42236670}],"con":true,"img":false}]}
{"op":"mcm","clk":"5346623174","pt":1646092596345,"mc":[{"id":"1.195395444","rc":[{"atl":[[6,4]],"id":42236670}],"con":true,"img":false}]}
{"op":"mcm","clk":"5346623252","pt":1646092598754,"mc":[{"id":"1.195395444","rc":[{"atb":[[2.66,0]],"id":42236670}],"con":true,"img":false}]}
{"op":"mcm","clk":"5346623293","pt":1646092599985,"mc":[{"id":"1.195395444","rc":[{"atl":[[6,0]],"id":42236670},{"atl":[[2.92,10.42],[2.9,0]],"id":42236682}],"con":true,"img":false}]}
{"op":"mcm","clk":"5346623316","pt":1646092600753,"mc":[{"id":"1.195395444","rc":[{"atl":[[6,4]],"id":42236670}],"con":true,"img":false}]}
{"op":"mcm","clk":"5346623321","pt":1646092600958,"mc":[{"id":"1.195395444","rc":[{"atl":[[6,0]],"id":42236670},{"atl":[[2.92,0],[2.94,10.31]],"id":42236682},{"atb":[[2,0],[1.98,0],[1.96,0],[1.94,0],[1.92,21.74]],"id":37174579},{"atl":[[7.6,3.03],[8.4,0]],"id":37174579}],"con":true,"img":false}]}
{"op":"mcm","clk":"5346623324","pt":1646092601061,"mc":[{"id":"1.195395444","rc":[{"atl":[[6,4]],"id":42236670}],"con":true,"img":false}]}
{"op":"mcm","clk":"5346623368","pt":1646092602294,"mc":[{"id":"1.195395444","rc":[{"atb":[[2.66,27.87]],"id":42236670}],"con":true,"img":false}]}
{"op":"mcm","clk":"5346623427","pt":1646092604091,"mc":[{"id":"1.195395444","rc":[{"atb":[[2.82,0]],"id":37174579}],"con":true,"img":false}]}
{"op":"mcm","clk":"5346623534","pt":1646092606811,"mc":[{"id":"1.195395444","rc":[{"atl":[[6,0]],"id":42236670}],"con":true,"img":false}]}
{"op":"mcm","clk":"5346623558","pt":1646092607480,"mc":[{"id":"1.195395444","rc":[{"atb":[[2.82,25.42]],"id":37174579}],"con":true,"img":false}]}
{"op":"mcm","clk":"5346623609","pt":1646092609170,"mc":[{"id":"1.195395444","rc":[{"atb":[[2.66,0]],"id":42236670}],"con":true,"img":false}]}
{"op":"mcm","clk":"5346623677","pt":1646092611015,"mc":[{"id":"1.195395444","rc":[{"atl":[[6,4]],"id":42236670},{"atl":[[2.98,25.25]],"id":42236682},{"atb":[[1.9,55.56]],"id":37174579},{"atl":[[8,7.14]],"id":37174579}],"con":true,"img":false}]}
{"op":"mcm","clk":"5346623745","pt":1646092612712,"mc":[{"id":"1.195395444","rc":[{"atl":[[7.2,0],[7,3.33]],"id":40917095},{"atb":[[3.4,8.33],[3.55,6.19]],"id":42189436},{"atb":[[2.66,27.87]],"id":42236670},{"atl":[[6.2,3.85],[6,0]],"id":42236670},{"atl":[[6.4,4.44],[6.6,40.07]],"id":42070475},{"atl":[[9,0],[9.8,1.36],[9.4,0]],"id":37174579}],"con":true,"img":false}]}
{"op":"mcm","clk":"5346623750","pt":1646092612915,"mc":[{"id":"1.195395444","rc":[{"atb":[[3.45,24.52]],"id":42189436}],"con":true,"img":false}]}
{"op":"mcm","clk":"5346623798","pt":1646092614405,"mc":[{"id":"1.195395444","rc":[{"atb":[[2.82,0]],"id":37174579}],"con":true,"img":false}]}
{"op":"mcm","clk":"5346623904","pt":1646092617886,"mc":[{"id":"1.195395444","rc":[{"atb":[[2.82,25.42]],"id":37174579}],"con":true,"img":false}]}
{"op":"mcm","clk":"5346623938","pt":1646092618712,"mc":[{"id":"1.195395444","rc":[{"atb":[[3.5,0]],"id":42189436},{"atl":[[9.6,0]],"id":37174579}],"con":true,"img":false}]}
{"op":"mcm","clk":"5346623943","pt":1646092618813,"mc":[{"id":"1.195395444","rc":[{"atb":[[3.4,26.36]],"id":42189436},{"atl":[[11,3.38]],"id":37174579}],"con":true,"img":false}]}
{"op":"mcm","clk":"5346624021","pt":1646092621023,"mc":[{"id":"1.195395444","rc":[{"atl":[[3.05,97.57]],"id":42236682},{"atb":[[1.88,85.23]],"id":37174579},{"atl":[[8.4,10.14]],"id":37174579}],"con":true,"img":false}]}
{"op":"mcm","clk":"5346624026","pt":1646092621125,"mc":[{"id":"1.195395444","rc":[{"atl":[[3.05,36.59]],"id":42236682}],"con":true,"img":false}]}
{"op":"mcm","clk":"5346624073","pt":1646092622714,"mc":[{"id":"1.195395444","rc":[{"atb":[[3.3,21.74]],"id":42189436},{"atl":[[6.6,11.07]],"id":42236670},{"atl":[[7,8.33]],"id":42070475}],"con":true,"img":false}]}
{"op":"mcm","clk":"5346624189","pt":1646092625991,"mc":[{"id":"1.195395444","rc":[{"atl":[[7.2,0],[6.8,0],[7.6,0]],"id":42070475},{"atl":[[2.92,10.42]],"id":42236682}],"con":true,"img":false}]}
{"op":"mcm","clk":"5346624282","pt":1646092628707,"mc":[{"id":"1.195395444","rc":[{"atl":[[6.6,3.57]],"id":42070475}],"con":true,"img":false}]}
{"op":"mcm","clk":"5346624288","pt":1646092628807,"mc":[{"id":"1.195395444","rc":[{"atl":[[6.8,36.5]],"id":42070475}],"con":true,"img":false}]}
{"op":"mcm","clk":"5346624360","pt":1646092631020,"mc":[{"id":"1.195395444","rc":[{"atb":[[1.86,145.35]],"id":37174579},{"atl":[[8.8,16.03]],"id":37174579}],"con":true,"img":false}]}
{"op":"mcm","clk":"5346624428","pt":1646092632713,"mc":[{"id":"1.195395444","rc":[{"atb":[[3.2,88.7]],"id":42189436},{"atl":[[7,29.17]],"id":42236670},{"atl":[[7.4,11.72]],"id":42070475}],"con":true,"img":false}]}
{"op":"mcm","clk":"5346624527","pt":1646092635738,"mc":[{"id":"1.195395444","rc":[{"atb":[[3.35,0],[3.25,0]],"id":42189436}],"con":true,"img":false}]}
{"op":"mcm","clk":"5346624536","pt":1646092636045,"mc":[{"id":"1.195395444","rc":[{"atl":[[2.96,25.51]],"id":42236682}],"con":true,"img":false}]}
{"op":"mcm","clk":"5346624608","pt":1646092638353,"mc":[{"id":"1.195395444","rc":[{"atl":[[2.98,0],[2.94,0],[3.05,0]],"id":42236682}],"con":true,"img":false}]}
{"op":"mcm","clk":"5346624621","pt":1646092638610,"mc":[{"id":"1.195395444","rc":[{"atb":[[3.4,8.33]],"id":42189436}],"con":true,"img":false}]}
{"op":"mcm","clk":"5346624625","pt":1646092638720,"mc":[{"id":"1.195395444","rc":[{"atb":[[3.25,18.03]],"id":42189436}],"con":true,"img":false}]}
{"op":"mcm","clk":"5346624776","pt":1646092642718,"mc":[{"id":"1.195395444","rc":[{"atb":[[3.1,59.52]],"id":42189436},{"atl":[[7.4,19.53]],"id":42236670},{"atl":[[7.8,18.38]],"id":42070475}],"con":true,"img":false}]}
{"op":"mcm","clk":"5346624818","pt":1646092644356,"mc":[{"id":"1.195395444","rc":[{"atl":[[6.4,0]],"id":42236670}],"con":true,"img":false}]}
{"op":"mcm","clk":"5346624855","pt":1646092646047,"mc":[{"id":"1.195395444","rc":[{"atl":[[3,37.5]],"id":42236682}],"con":true,"img":false}]}
{"op":"mcm","clk":"5346624883","pt":1646092646660,"mc":[{"id":"1.195395444","rc":[{"atb":[[2.66,0]],"id":42236670}],"con":true,"img":false}]}
{"op":"mcm","clk":"5346624984","pt":1646092650137,"mc":[{"id":"1.195395444","rc":[{"atb":[[2.66,27.87]],"id":42236670}],"con":true,"img":false}]}
{"op":"mcm","clk":"5346625143","pt":1646092656036,"mc":[{"id":"1.195395444","rc":[{"atl":[[3.1,59.52]],"id":42236682}],"con":true,"img":false}]}
{"op":"mcm","clk":"5346625210","pt":1646092658554,"mc":[{"id":"1.195395444","rc":[{"atl":[[11,0],[8.6,5.34]],"id":37174579}],"con":true,"img":false}]}
{"op":"mcm","clk":"5346625783","pt":1646092678682,"mc":[{"id":"1.195395444","rc":[{"atl":[[6.8,0]],"id":42236670}],"con":true,"img":false}]}
{"op":"mcm","clk":"5346625789","pt":1646092678784,"mc":[{"id":"1.195395444","rc":[{"atl":[[7.2,6.99]],"id":42236670}],"con":true,"img":false}]}
{"op":"mcm","clk":"5346626194","pt":1646092692516,"mc":[{"id":"1.195395444","rc":[{"atb":[[1.83,0],[1.86,23.26]],"id":42236682},{"atl":[[2.92,0],[2.9,10.53]],"id":42236682},{"atl":[[15.5,6.9],[18,0]],"id":37174579}],"con":true,"img":false}]}
{"op":"mcm","clk":"5346626449","pt":1646092702521,"mc":[{"id":"1.195395444","rc":[{"atb":[[1.84,59.52]],"id":42236682}],"con":true,"img":false}]}
{"op":"mcm","clk":"5346626475","pt":1646092703697,"mc":[{"id":"1.195395444","rc":[{"atb":[[1.79,0],[1.81,0],[1.77,0]],"id":42236682}],"con":true,"img":false}]}
{"op":"mcm","clk":"5346626635","pt":1646092708621,"mc":[{"id":"1.195395444","rc":[{"atb":[[1.82,0]],"id":42236682}],"con":true,"img":false}]}
{"op":"mcm","clk":"5346626640","pt":1646092708723,"mc":[{"id":"1.195395444","rc":[{"atb":[[1.81,40.59]],"id":42236682}],"con":true,"img":false}]}
{"op":"mcm","clk":"5346626780","pt":1646092712416,"mc":[{"id":"1.195395444","rc":[{"atb":[[1.82,91.46]],"id":42236682}],"con":true,"img":false}]}
{"op":"mcm","clk":"5346626985","pt":1646092718917,"mc":[{"id":"1.195395444","rc":[{"atl":[[7.6,0],[7.8,4.7]],"id":37174579}],"con":true,"img":false}]}
{"op":"mcm","clk":"5346627018","pt":1646092719841,"mc":[{"id":"1.195395444","rc":[{"atb":[[2.64,67.96],[2.6,106.34]],"id":42236670},{"atl":[[7.2,23.12],[7,12.49]],"id":42236670},{"atl":[[7.6,3.03],[7.8,1.76]],"id":37174579}],"con":true,"img":false}]}
{"op":"mcm","clk":"5346627093","pt":1646092721850,"mc":[{"id":"1.195395444","rc":[{"atl":[[7.4,3.12],[7.2,0]],"id":42189436},{"atl":[[2.88,10.64],[2.9,0]],"id":42236682}],"con":true,"img":false}]}
{"op":"mcm","clk":"5346627305","pt":1646092728619,"mc":[{"id":"1.195395444","rc":[{"atb":[[3.25,0]],"id":42189436}],"con":true,"img":false}]}
{"op":"mcm","clk":"5346627309","pt":1646092728722,"mc":[{"id":"1.195395444","rc":[{"atb":[[3.5,18.03]],"id":42189436}],"con":true,"img":false}]}
{"op":"mcm","clk":"5346627393","pt":1646092731844,"mc":[{"id":"1.195395444","rc":[{"atl":[[7.8,7.35]],"id":42189436},{"atb":[[1.8,429.15]],"id":42236682},{"atl":[[2.92,26.04]],"id":42236682}],"con":true,"img":false}]}
{"op":"mcm","clk":"5346627415","pt":1646092732562,"mc":[{"id":"1.195395444","rc":[{"atb":[[2.82,0],[2.92,0],[3.05,0]],"id":40917095},{"atl":[[32,0],[10.5,0],[21,0],[8.2,0],[15.5,0]],"id":40917095},{"atb":[[3.45,0],[3.2,34.09],[2.98,0]],"id":42189436},{"atl":[[44,0],[13.5,0],[9.4,0],[18.5,0],[27,0]],"id":42189436},{"atb":[[1.8,278.97],[1.85,0],[1.9,0]],"id":42236682},{"atl":[[8,0],[10,0],[4,0],[5,0],[6,0]],"id":42236682},{"atb":[[2.8,0],[2.9,0],[2.7,0]],"id":37174579},{"atl":[[19.5,0],[9.8,0],[7.8,0],[14.5,0],[29,0]],"id":37174579}],"con":true,"img":false}]}
{"op":"mcm","clk":"5346627428","pt":1646092733126,"mc":[{"id":"1.195395444","rc":[{"atl":[[8,0],[7.6,0],[8.4,0]],"id":42189436},{"atl":[[3.1,0]],"id":42236682}],"con":true,"img":false}]}
{"op":"mcm","clk":"5346627455","pt":1646092734149,"mc":[{"id":"1.195395444","rc":[{"atb":[[1.81,0]],"id":42236682}],"con":true,"img":false}]}
{"op":"mcm","clk":"5346627459","pt":1646092734250,"mc":[{"id":"1.195395444","rc":[{"atb":[[1.83,40.59]],"id":42236682}],"con":true,"img":false}]}
{"op":"mcm","clk":"5346627475","pt":1646092734661,"mc":[{"id":"1.195395444","rc":[{"atb":[[3.55,3.27]],"id":42189436},{"atb":[[1.94,8.89]],"id":42236682},{"atb":[[2.96,4.26]],"id":37174579}],"con":true,"img":false}]}
{"op":"mcm","clk":"5346627504","pt":1646092735431,"mc":[{"id":"1.195395444","rc":[{"atb":[[1.91,0]],"id":42236682},{"atb":[[2.82,0]],"id":37174579}],"con":true,"img":false}]}
{"op":"mcm","clk":"5346627539","pt":1646092736560,"mc":[{"id":"1.195395444","rc":[{"atb":[[3.55,39.56],[3.3,84.84],[3.05,58.6]],"id":40917095},{"atl":[[19.5,1.29],[48,1.02],[9.8,1.36],[14.5,0.88],[29,0.86]],"id":40917095},{"atb":[[3.4,58.39],[3.15,55.88],[3.65,22.67]],"id":42189436},{"atl":[[32,0.77],[21,14],[10.5,1.26],[55,0.88],[15.5,0.82]],"id":42189436},{"atb":[[1.8,429.15],[1.85,70.67],[1.75,160.19]],"id":42236682},{"atl":[[4.5,17.42],[9,6],[5.5,5.34],[7,4],[3.75,4.36]],"id":42236682},{"atb":[[2.5,80.09],[2.6,75.09],[2.7,35.33]],"id":37174579},{"atl":[[16.5,1.54],[8.6,6.92],[11.5,2.28],[23,2.18],[6.6,2.14]],"id":37174579}],"con":true,"img":false}]}
{"op":"mcm","clk":"5346627573","pt":1646092737636,"mc":[{"id":"1.195395444","rc":[{"atb":[[3.5,8]],"id":40917095}],"con":true,"img":false}]}
{"op":"mcm","clk":"5346627588","pt":1646092738352,"mc":[{"id":"1.195395444","rc":[{"atb":[[1.94,0]],"id":42236682}],"con":true,"img":false}]}
{"op":"mcm","clk":"5346627605","pt":1646092738968,"mc":[{"id":"1.195395444","rc":[{"atb":[[1.87,35.58]],"id":42236682},{"atb":[[2.74,21.31]],"id":37174579}],"con":true,"img":false}]}
{"op":"mcm","clk":"5346627641","pt":1646092739843,"mc":[{"id":"1.195395444","rc":[{"atb":[[1.87,48.93]],"id":42236682}],"con":true,"img":false}]}
{"op":"mcm","clk":"5346627721","pt":1646092741839,"mc":[{"id":"1.195395444","rc":[{"atl":[[8.2,10.42]],"id":42189436},{"atl":[[2.96,38.27]],"id":42236682}],"con":true,"img":false}]}
{"op":"mcm","clk":"5346627755","pt":1646092742455,"mc":[{"id":"1.195395444","rc":[{"atb":[[3.5,0]],"id":42189436}],"con":true,"img":false}]}
{"op":"mcm","clk":"5346627763","pt":1646092742558,"mc":[{"id":"1.195395444","rc":[{"atb":[[3.45,18.03]],"id":42189436}],"con":true,"img":false}]}
{"op":"mcm","clk":"5346627813","pt":1646092743585,"mc":[{"id":"1.195395444","rc":[{"atb":[[3.65,2.8]],"id":40917095},{"atb":[[3.75,2.71]],"id":42189436},{"atb":[[2.76,4.23]],"id":37174579}],"con":true,"img":false}]}
{"op":"mcm","clk":"5346627820","pt":1646092743688,"mc":[{"id":"1.195395444","rc":[{"atl":[[8,2.86],[7.6,0],[8.8,12.82],[7,0]],"id":40917095},{"atb":[[3.4,50.06],[3.65,30.22]],"id":42189436},{"atb":[[2.5,146.76],[2.64,12.2]],"id":42236670},{"atl":[[8,14.29],[7.2,6.99],[8.6,4.21],[6.2,0],[7.4,0],[6.6,2.14],[7,0]],"id":42236670},{"atl":[[8,17.15],[5.8,0],[7.4,0],[6.6,0],[7,0]],"id":42070475},{"atb":[[1.44,250],[1.68,86.96],[1.92,21.74],[1.5,0]],"id":41523279},{"atb":[[1.8,306.43]],"id":42236682},{"atb":[[1.89,0],[2.34,56.65],[1.92,0],[2.42,14.08]],"id":37174579}],"con":true,"img":false}]}
{"op":"mcm","clk":"5346627855","pt":1646092744358,"mc":[{"id":"1.195395444","rc":[{"atl":[[7.8,0]],"id":42070475}],"con":true,"img":false}]}
{"op":"mcm","clk":"5346627896","pt":1646092745379,"mc":[{"id":"1.195395444","rc":[{"atb":[[2,35.81]],"id":41523279}],"con":true,"img":false}]}
{"op":"mcm","clk":"5346627899","pt":1646092745480,"mc":[{"id":"1.195395444","rc":[{"atb":[[1.92,0]],"id":41523279}],"con":true,"img":false}]}
{"op":"mcm","clk":"5346627905","pt":1646092745686,"mc":[{"id":"1.195395444","rc":[{"atb":[[1.44,0]],"id":41523279}],"con":true,"img":false}]}
{"op":"mcm","clk":"5346627912","pt":1646092745841,"mc":[{"id":"1.195395444","rc":[{"atb":[[3.55,23.55]],"id":40917095},{"atb":[[2.66,0]],"id":42236670},{"atb":[[2.74,0]],"id":37174579}],"con":true,"img":false}]}
{"op":"mcm","clk":"5346627934","pt":1646092746558,"mc":[{"id":"1.195395444","rc":[{"atb":[[1.91,8.18]],"id":42236682}],"con":true,"img":false}]}
{"op":"mcm","clk":"5346628025","pt":1646092749377,"mc":[{"id":"1.195395444","rc":[{"atb":[[3.7,5.61]],"id":40917095},{"atb":[[2.66,27.87]],"id":42236670},{"atl":[[7.2,0]],"id":42236670},{"atl":[[6.8,0]],"id":42070475},{"atb":[[2.78,19.18]],"id":37174579}],"con":true,"img":false}]}
{"op":"mcm","clk":"5346628028","pt":1646092749478,"mc":[{"id":"1.195395444","rc":[{"atl":[[9,6.99]],"id":42236670},{"atl":[[7.8,36.5]],"id":42070475}],"con":true,"img":false}]}
{"op":"mcm","clk":"5346628051","pt":1646092750046,"mc":[{"id":"1.195395444","rc":[{"atb":[[3.4,20.83]],"id":40917095},{"atb":[[3.55,0]],"id":42189436},{"atb":[[2.96,0]],"id":37174579}],"con":true,"img":false}]}
{"op":"mcm","clk":"5346628101","pt":1646092751885,"mc":[{"id":"1.195395444","rc":[{"atl":[[3,100]],"id":42236682}],"con":true,"img":false}]}
{"op":"mcm","clk":"5346628104","pt":1646092751988,"mc":[{"id":"1.195395444","rc":[{"atl":[[3,62.5]],"id":42236682}],"con":true,"img":false}]}
{"op":"mcm","clk":"5346628155","pt":1646092753683,"mc":[{"id":"1.195395444","rc":[{"atl":[[8.4,6.76]],"id":40917095},{"atb":[[3.55,19.61]],"id":42189436},{"atl":[[8.6,16.45]],"id":42189436},{"atl":[[9,13.24]],"id":42236670},{"atl":[[8.4,13.25]],"id":42070475},{"atb":[[2.38,36.23]],"id":37174579}],"con":true,"img":false}]}
{"op":"mcm","clk":"5346628178","pt":1646092754455,"mc":[{"id":"1.195395444","rc":[{"atb":[[3.25,0]],"id":40917095},{"atb":[[1.76,65.79]],"id":42070475}],"con":true,"img":false}]}
{"op":"mcm","clk":"5346628182","pt":1646092754557,"mc":[{"id":"1.195395444","rc":[{"atb":[[3.35,19.32]],"id":40917095},{"atb":[[1.82,40.59]],"id":42070475}],"con":true,"img":false}]}
{"op":"mcm","clk":"5346628205","pt":1646092755380,"mc":[{"id":"1.195395444","rc":[{"atb":[[1.98,51.02]],"id":41523279}],"con":true,"img":false}]}
{"op":"mcm","clk":"5346628217","pt":1646092755790,"mc":[{"id":"1.195395444","rc":[{"atb":[[2,28.36]],"id":41523279}],"con":true,"img":false}]}
{"op":"mcm","clk":"5346628223","pt":1646092755993,"mc":[{"id":"1.195395444","rc":[{"atb":[[3.2,0],[3.1,0],[3.3,0]],"id":42189436},{"atb":[[1.88,0],[1.9,0],[1.86,0]],"id":37174579}],"con":true,"img":false}]}
{"op":"mcm","clk":"5346628227","pt":1646092756046,"mc":[{"id":"1.195395444","rc":[{"atb":[[2,20]],"id":41523279},{"atb":[[2.76,8.98]],"id":37174579}],"con":true,"img":false}]}
{"op":"mcm","clk":"5346628236","pt":1646092756252,"mc":[{"id":"1.195395444","rc":[{"atb":[[3.65,5.96]],"id":40917095}],"con":true,"img":false}]}
{"op":"mcm","clk":"5346628240","pt":1646092756359,"mc":[{"id":"1.195395444","rc":[{"atb":[[1.91,17.37]],"id":42236682}],"con":true,"img":false}]}
{"op":"mcm","clk":"5346628245","pt":1646092756457,"mc":[{"id":"1.195395444","rc":[{"atb":[[3.75,5.75]],"id":42189436}],"con":true,"img":false}]}
{"op":"mcm","clk":"5346628277","pt":1646092757380,"mc":[{"id":"1.195395444","rc":[{"atb":[[1.81,57.11]],"id":42070475}],"con":true,"img":false}]}
{"op":"mcm","clk":"5346628295","pt":1646092757894,"mc":[{"id":"1.195395444","rc":[{"atb":[[1.81,0]],"id":42070475},{"atb":[[1.97,0]],"id":41523279}],"con":true,"img":false}]}
{"op":"mcm","clk":"5346628340","pt":1646092759478,"mc":[{"id":"1.195395444","rc":[{"atl":[[11,0]],"id":40917095}],"con":true,"img":false}]}
{"op":"mcm","clk":"5346628345","pt":1646092759583,"mc":[{"id":"1.195395444","rc":[{"atl":[[12,4.05]],"id":40917095}],"con":true,"img":false}]}
{"op":"mcm","clk":"5346628398","pt":1646092761379,"mc":[{"id":"1.195395444","rc":[{"atb":[[1.83,55.75]],"id":42070475},{"atb":[[2.04,22.13]],"id":41523279}],"con":true,"img":false}]}
{"op":"mcm","clk":"5346628401","pt":1646092761483,"mc":[{"id":"1.195395444","rc":[{"atb":[[1.83,96.6]],"id":42070475}],"con":true,"img":false}]}
{"op":"mcm","clk":"5346628403","pt":1646092761588,"mc":[{"id":"1.195395444","rc":[{"atb":[[2.02,18.36]],"id":41523279}],"con":true,"img":false}]}
{"op":"mcm","clk":"5346628462","pt":1646092763698,"mc":[{"id":"1.195395444","rc":[{"atl":[[8.8,22.44]],"id":40917095},{"atb":[[3.45,48.64]],"id":42189436},{"atl":[[9.4,8.93]],"id":42236670},{"atl":[[8.8,9.62]],"id":42070475},{"atb":[[2.02,7.3]],"id":41523279},{"atb":[[2.34,112.62]],"id":37174579}],"con":true,"img":false}]}
{"op":"mcm","clk":"5346628525","pt":1646092765497,"mc":[{"id":"1.195395444","rc":[{"atb":[[1.96,118.71]],"id":41523279}],"con":true,"img":false}]}
{"op":"mcm","clk":"5346628598","pt":1646092767498,"mc":[{"id":"1.195395444","rc":[{"atb":[[1.46,0]],"id":41523279}],"con":true,"img":false}]}
{"op":"mcm","clk":"5346628623","pt":1646092767955,"mc":[{"id":"1.195395444","rc":[{"atb":[[2.02,15.49]],"id":41523279}],"con":true,"img":false}]}
{"op":"mcm","clk":"5346628633","pt":1646092768160,"mc":[{"id":"1.195395444","rc":[{"atb":[[2.06,15.49]],"id":41523279}],"con":true,"img":false}]}
{"op":"mcm","clk":"5346628683","pt":1646092769395,"mc":[{"id":"1.195395444","rc":[{"atb":[[3.45,30.61]],"id":42189436},{"atb":[[1.82,0]],"id":42070475}],"con":true,"img":false}]}
{"op":"mcm","clk":"5346628690","pt":1646092769498,"mc":[{"id":"1.195395444","rc":[{"atb":[[3.7,18.03]],"id":42189436},{"atb":[[1.84,40.59]],"id":42070475}],"con":true,"img":false}]}
{"op":"mcm","clk":"5346628775","pt":1646092771601,"mc":[{"id":"1.195395444","rc":[{"atb":[[1.83,40.85]],"id":42070475},{"atb":[[2.04,0]],"id":41523279}],"con":true,"img":false}]}
{"op":"mcm","clk":"5346628803","pt":1646092772480,"mc":[{"id":"1.195395444","rc":[{"atb":[[1.83,0]],"id":42070475}],"con":true,"img":false}]}
{"op":"mcm","clk":"5346628841","pt":1646092773705,"mc":[{"id":"1.195395444","rc":[{"atl":[[9.2,15.24]],"id":40917095},{"atb":[[3.35,53.19]],"id":42189436},{"atl":[[9.8,14.2]],"id":42236670},{"atl":[[9.2,15.24]],"id":42070475},{"atb":[[2.3,139.89]],"id":37174579}],"con":true,"img":false}]}
{"op":"mcm","clk":"5346628870","pt":1646092774475,"mc":[{"id":"1.195395444","rc":[{"atb":[[1.96,78.12]],"id":41523279},{"atl":[[4.5,3.43]],"id":42236682},{"atb":[[2.3,96.15]],"id":37174579}],"con":true,"img":false}]}
{"op":"mcm","clk":"5346628873","pt":1646092774578,"mc":[{"id":"1.195395444","rc":[{"atb":[[1.99,40.59]],"id":41523279},{"atl":[[3.7,27.99]],"id":42236682},{"atb":[[2.4,43.74]],"id":37174579}],"con":true,"img":false}]}
{"op":"mcm","clk":"5346628889","pt":1646092775093,"mc":[{"id":"1.195395444","rc":[{"atb":[[1.85,54.44]],"id":42070475},{"atb":[[2.08,30.98]],"id":41523279}],"con":true,"img":false}]}
{"op":"mcm","clk":"5346628897","pt":1646092775401,"mc":[{"id":"1.195395444","rc":[{"atb":[[1.94,132.98]],"id":41523279}],"con":true,"img":false}]}
{"op":"mcm","clk":"5346628924","pt":1646092776682,"mc":[{"id":"1.195395444","rc":[{"atb":[[2.02,8.19]],"id":41523279}],"con":true,"img":false}]}
{"op":"mcm","clk":"5346628939","pt":1646092777096,"mc":[{"id":"1.195395444","rc":[{"atb":[[1.85,94.33]],"id":42070475}],"con":true,"img":false}]}
{"op":"mcm","clk":"5346628990","pt":1646092779096,"mc":[{"id":"1.195395444","rc":[{"atb":[[2.06,0]],"id":41523279}],"con":true,"img":false}]}
{"op":"mcm","clk":"5346629000","pt":1646092779403,"mc":[{"id":"1.195395444","rc":[{"atl":[[9,6.25]],"id":42236670},{"atb":[[1.84,0]],"id":42070475}],"con":true,"img":false}]}
{"op":"mcm","clk":"5346629002","pt":1646092779505,"mc":[{"id":"1.195395444","rc":[{"atl":[[7.8,6.99]],"id":42236670},{"atb":[[1.81,40.59]],"id":42070475}],"con":true,"img":false}]}
{"op":"mcm","clk":"5346629068","pt":1646092782015,"mc":[{"id":"1.195395444","rc":[{"atb":[[2.66,0]],"id":42236670},{"atb":[[2.08,0]],"id":41523279}],"con":true,"img":false}]}
{"op":"mcm","clk":"5346629072","pt":1646092782117,"mc":[{"id":"1.195395444","rc":[{"atb":[[2.62,47.12],[2.76,0]],"id":40917095},{"atl":[[8,0],[8.6,2.63],[8.4,0]],"id":40917095},{"atb":[[1.48,0]],"id":41523279},{"atl":[[2.88,0],[2.9,10.53]],"id":42236682}],"con":true,"img":false}]}
{"op":"mcm","clk":"5346629075","pt":1646092782218,"mc":[{"id":"1.195395444","rc":[{"atl":[[9.2,27.44],[8.8,9.62]],"id":40917095}],"con":true,"img":false}]}
{"op":"mcm","clk":"5346629083","pt":1646092782580,"mc":[{"id":"1.195395444","rc":[{"atb":[[2.04,7.16]],"id":41523279}],"con":true,"img":false}]}
{"op":"mcm","clk":"5346629106","pt":1646092783297,"mc":[{"id":"1.195395444","rc":[{"atb":[[2.1,21.69]],"id":41523279}],"con":true,"img":false}]}
{"op":"mcm","clk":"5346629143","pt":1646092784420,"mc":[{"id":"1.195395444","rc":[{"atb":[[2.64,40.02],[2.78,0]],"id":40917095},{"atl":[[12,0]],"id":40917095}],"con":true,"img":false}]}
{"op":"mcm","clk":"5346629147","pt":1646092784522,"mc":[{"id":"1.195395444","rc":[{"atl":[[11.5,4.05]],"id":40917095}],"con":true,"img":false}]}
{"op":"mcm","clk":"5346629183","pt":1646092785397,"mc":[{"id":"1.195395444","rc":[{"atb":[[2.66,27.87]],"id":42236670},{"atb":[[2.12,41.31]],"id":41523279}],"con":true,"img":false}]}
{"op":"mcm","clk":"5346629277","pt":1646092788782,"mc":[{"id":"1.195395444","rc":[{"atb":[[2.04,0]],"id":41523279}],"con":true,"img":false}]}
{"op":"mcm","clk":"5346629297","pt":1646092789804,"mc":[{"id":"1.195395444","rc":[{"atb":[[2.1,0]],"id":41523279}],"con":true,"img":false}]}
{"op":"mcm","clk":"5346629359","pt":1646092792116,"mc":[{"id":"1.195395444","rc":[{"atl":[[9,6.25]],"id":40917095},{"atb":[[2.02,0]],"id":41523279},{"atl":[[2.94,25.77]],"id":42236682}],"con":true,"img":false}]}
{"op":"mcm","clk":"5346629362","pt":1646092792217,"mc":[{"id":"1.195395444","rc":[{"atl":[[9.2,15.24],[8.8,19.24]],"id":40917095},{"atb":[[2.12,0]],"id":41523279}],"con":true,"img":false}]}
{"op":"mcm","clk":"5346629365","pt":1646092792524,"mc":[{"id":"1.195395444","rc":[{"atl":[[2.92,0],[3,0],[2.96,0]],"id":42236682}],"con":true,"img":false}]}
{"op":"mcm","clk":"5346629418","pt":1646092794325,"mc":[{"id":"1.195395444","rc":[{"atb":[[2.04,32.6]],"id":41523279}],"con":true,"img":false}]}
{"op":"mcm","clk":"5346629461","pt":1646092795814,"mc":[{"id":"1.195395444","rc":[{"atb":[[2.02,40]],"id":41523279}],"con":true,"img":false}]}
{"op":"mcm","clk":"5346629504","pt":1646092797412,"mc":[{"id":"1.195395444","rc":[{"atl":[[9,18.75],[8.8,9.62]],"id":40917095}],"con":true,"img":false}]}
{"op":"mcm","clk":"5346629558","pt":1646092799311,"mc":[{"id":"1.195395444","rc":[{"atb":[[2.02,0]],"id":41523279}],"con":true,"img":false}]}
{"op":"mcm","clk":"5346629559","pt":1646092799414,"mc":[{"id":"1.195395444","rc":[{"atl":[[3.7,14]],"id":42236682}],"con":true,"img":false}]}
{"op":"mcm","clk":"5346629561","pt":1646092799517,"mc":[{"id":"1.195395444","rc":[{"atl":[[4.4,13.99]],"id":42236682}],"con":true,"img":false}]}
{"op":"mcm","clk":"5346629628","pt":1646092801322,"mc":[{"id":"1.195395444","rc":[{"atb":[[3.7,17.29],[3.55,46.92]],"id":40917095},{"atl":[[9,42.12],[7.8,2.5],[8.4,10.81],[8.6,7.63]],"id":40917095},{"atb":[[3.75,19.08],[3.65,56.88]],"id":42189436},{"atl":[[7.2,12.9],[8.2,42.08],[7.4,5.62]],"id":42189436},{"atb":[[2.82,5],[2.76,26.43],[2.9,2.5],[2.74,10],[2.66,62.77]],"id":42236670},{"atl":[[8,52.52],[7.2,5],[6.4,17.31]],"id":42236670},{"atb":[[1.85,123.71],[1.93,10],[2.14,28.55],[2.02,2.5],[1.97,5]],"id":42070475},{"atl":[[3.6,19.31],[5.3,5],[5.2,35.1],[4.9,2.5],[5.7,19.89]],"id":42070475},{"atb":[[2.04,71.5]],"id":41523279},{"atl":[[3.2,45.45]],"id":41523279},{"atb":[[2.1,5],[2.02,10],[1.91,47.85],[1.86,84.22],[2.18,2.5]],"id":42236682},{"atl":[[2.9,41.01],[3.7,74.96]],"id":42236682},{"atb":[[2.8,12.09],[3.1,10],[3.5,2.5],[3.3,5]],"id":37174579},{"atl":[[6.6,4.45]],"id":37174579}],"con":true,"img":false}]}
{"op":"mcm","clk":"5346629633","pt":1646092801429,"mc":[{"id":"1.195395444","rc":[{"atb":[[1.99,120.07]],"id":41523279},{"atl":[[3.4,97.68]],"id":41523279},{"atb":[[2.72,45.1]],"id":37174579},{"atl":[[8,31.32]],"id":37174579}],"con":true,"img":false}]}
{"op":"mcm","clk":"5346629654","pt":1646092802002,"mc":[{"id":"1.195395444","rc":[{"atl":[[9.4,8.93]],"id":40917095},{"atl":[[2.98,37.88]],"id":42236682}],"con":true,"img":false}]}
{"op":"mcm","clk":"5346629684","pt":1646092802724,"mc":[{"id":"1.195395444","rc":[{"atb":[[2.06,43.65]],"id":41523279}],"con":true,"img":false}]}
{"op":"mcm","clk":"5346629723","pt":1646092803703,"mc":[{"id":"1.195395444","rc":[{"atb":[[3.7,17.29],[3.35,19.31],[2.64,40],[3.55,46.91],[3.3,84.81],[3.65,5.95],[3.05,58.56]],"id":40917095},{"atl":[[11.5,4.05],[48,1.02],[14.5,0.88],[18.5,14.85],[19.5,1.29],[9.8,1.36],[29,0.85]],"id":40917095},{"atb":[[3.7,18.02],[3.4,50.02],[2.46,52.24],[3.15,55.84],[3.75,19.08],[3.65,56.86]],"id":42189436},{"atl":[[32,0.77],[10.5,1.26],[21,13.99],[11.5,4.6],[55,0.88],[15.5,0.82]],"id":42189436},{"atb":[[2.5,146.71],[2.6,106.29],[2.58,26.68],[1.94,70.06],[2.76,26.42],[2.66,62.77],[2.7,35.31]],"id":42236670},{"atl":[[16.5,1.54],[8.6,4.2],[11.5,25.16],[23,2.18],[6.6,2.14],[7.8,6.99]],"id":42236670},{"atb":[[1.85,123.69],[1.7,171.52],[2.14,28.55],[1.8,75.04],[1.81,40.56],[1.75,160.09],[1.52,77.31]],"id":42070475},{"atl":[[3.6,19.3],[6.4,4.44],[5.2,35.09],[5.7,19.89],[7.8,36.48],[4.2,3.75],[8.4,13.25]],"id":42070475},{"atb":[[1.99,120.04],[2.06,43.64],[1.58,86.9],[2.04,71.5],[1.85,141.26],[1.9,133.41],[1.95,63.19]],"id":41523279},{"atl":[[4.8,10.67],[5.6,2.61],[7.2,3.87],[4.6,3.33],[9.2,2.92],[13,4],[7,28.96]],"id":41523279},{"atb":[[1.83,40.56],[1.85,70.63],[1.51,95.18],[1.87,48.92],[1.8,306.33],[1.91,39.66],[1.75,160.09]],"id":42236682},{"atl":[[4.5,3.42],[9,6],[5.5,5.33],[4.4,13.98],[6.6,35.78],[7,4],[3.75,4.36]],"id":42236682},{"atb":[[2.72,45.08],[2.5,80.04],[2.6,75.04],[2.76,4.74],[2.4,43.71],[2.78,19.17],[2.7,35.31]],"id":37174579},{"atl":[[16,19.64],[16.5,1.54],[8.6,6.91],[11.5,2.28],[23,2.18],[6.6,4.45]],"id":37174579}],"con":true,"img":false}]}
{"op":"mcm","clk":"5346629743","pt":1646092804324,"mc":[{"id":"1.195395444","rc":[{"atl":[[8,14.29],[8.8,0]],"id":42189436},{"atl":[[3.4,139.35],[3.55,0]],"id":41523279}],"con":true,"img":false}]}
{"op":"mcm","clk":"5346629748","pt":1646092804429,"mc":[{"id":"1.195395444","rc":[{"atb":[[2.66,34.9]],"id":42236670},{"atb":[[1.85,69.26]],"id":42070475},{"atb":[[1.87,13.34]],"id":42236682},{"atb":[[2.78,0]],"id":37174579}],"con":true,"img":false}]}
{"op":"mcm","clk":"5346629752","pt":1646092804634,"mc":[{"id":"1.195395444","rc":[{"atb":[[1.85,29.38]],"id":42070475},{"atb":[[1.87,0]],"id":42236682}],"con":true,"img":false}]}
{"op":"mcm","clk":"5346629797","pt":1646092805821,"mc":[{"id":"1.195395444","rc":[{"atl":[[9,29.62],[8.6,20.79]],"id":40917095}],"con":true,"img":false}]}
{"op":"mcm","clk":"5346629824","pt":1646092806648,"mc":[{"id":"1.195395444","rc":[{"atb":[[2.04,38.9]],"id":41523279}],"con":true,"img":false}]}
{"op":"mcm","clk":"5346629842","pt":1646092807318,"mc":[{"id":"1.195395444","rc":[{"atl":[[9.2,0],[8.8,0]],"id":40917095}],"con":true,"img":false}]}
{"op":"mcm","clk":"5346629870","pt":1646092808033,"mc":[{"id":"1.195395444","rc":[{"atb":[[2.78,9.38]],"id":42236670},{"atb":[[2.04,44.48]],"id":42070475},{"atb":[[2.04,10.01]],"id":42236682},{"atb":[[3.35,7.5]],"id":37174579}],"con":true,"img":false}]}
{"op":"mcm","clk":"5346629906","pt":1646092808959,"mc":[{"id":"1.195395444","rc":[{"atb":[[2.04,77.08]],"id":42070475},{"atb":[[2.04,13.76]],"id":42236682}],"con":true,"img":false}]}
{"op":"mcm","clk":"5346629938","pt":1646092809731,"mc":[{"id":"1.195395444","rc":[{"atb":[[2.1,6.77]],"id":41523279},{"atb":[[1.95,7.84]],"id":42236682},{"atb":[[2.78,4.18]],"id":37174579}],"con":true,"img":false}]}
{"op":"mcm","clk":"5346629975","pt":1646092811019,"mc":[{"id":"1.195395444","rc":[{"atb":[[2.08,30.55]],"id":41523279}],"con":true,"img":false}]}
{"op":"mcm","clk":"5346630011","pt":1646092812051,"mc":[{"id":"1.195395444","rc":[{"atl":[[3.05,60.98]],"id":42236682}],"con":true,"img":false}]}
{"op":"mcm","clk":"5346630016","pt":1646092812153,"mc":[{"id":"1.195395444","rc":[{"atl":[[9.8,15.56]],"id":40917095}],"con":true,"img":false}]}
{"op":"mcm","clk":"5346630047","pt":1646092813030,"mc":[{"id":"1.195395444","rc":[{"atb":[[2.06,0]],"id":41523279}],"con":true,"img":false}]}
{"op":"mcm","clk":"5346630141","pt":1646092815349,"mc":[{"id":"1.195395444","rc":[{"atb":[[2.08,0]],"id":41523279}],"con":true,"img":false}]}
{"op":"mcm","clk":"5346630156","pt":1646092815865,"mc":[{"id":"1.195395444","rc":[{"atb":[[2.1,0]],"id":41523279}],"con":true,"img":false}]}
{"op":"mcm","clk":"5346630163","pt":1646092815968,"mc":[{"id":"1.195395444","rc":[{"atb":[[2.04,0]],"id":41523279}],"con":true,"img":false}]}
{"op":"mcm","clk":"5346630167","pt":1646092816025,"mc":[{"id":"1.195395444","rc":[{"atb":[[2,69.35],[1.99,40.56],[1.98,170.41]],"id":41523279}],"con":true,"img":false}]}
{"op":"mcm","clk":"5346630190","pt":1646092816536,"mc":[{"id":"1.195395444","rc":[{"atb":[[2.12,13.54]],"id":41523279}],"con":true,"img":false}]}
{"op":"mcm","clk":"5346630207","pt":1646092816848,"mc":[{"id":"1.195395444","rc":[{"atb":[[2.76,0]],"id":37174579}],"con":true,"img":false}]}
{"op":"mcm","clk":"5346630255","pt":1646092818571,"mc":[{"id":"1.195395444","rc":[{"atb":[[2.72,43.56],[2.62,0]],"id":40917095},{"atl":[[8,2.86],[8.6,18.16]],"id":40917095},{"atb":[[2.9,0],[3,50],[3.55,7.84],[3.65,49.31]],"id":42189436},{"atl":[[8,0],[8.4,13.51]],"id":42189436},{"atb":[[1.8,125],[1.68,0]],"id":41523279},{"atb":[[2.1,0],[2.02,0],[2.06,2.5],[2.18,0]],"id":42236682},{"atl":[[2.88,10.64],[2.9,30.48]],"id":42236682},{"atb":[[2.5,93.37],[2.42,0]],"id":37174579},{"atl":[[8,7.14],[8.6,9.54],[7.6,0],[6.6,2.14]],"id":37174579}],"con":true,"img":false}]}
{"op":"mcm","clk":"5346630263","pt":1646092818757,"mc":[{"id":"1.195395444","rc":[{"atl":[[8.2,13.89],[8.6,5]],"id":40917095},{"atb":[[1.95,17.84],[1.99,5]],"id":42236682},{"atl":[[8,5.62]],"id":37174579}],"con":true,"img":false}]}
{"op":"mcm","clk":"5346630268","pt":1646092818859,"mc":[{"id":"1.195395444","rc":[{"atl":[[9,6.25],[8.4,35.97],[7.6,12.12]],"id":40917095},{"atl":[[8.2,15.42],[7.8,37.9]],"id":42189436},{"atb":[[2.9,10],[2.66,0],[2.78,24.38]],"id":42236670},{"atl":[[8,24.29],[7.2,20]],"id":42236670},{"atb":[[2.04,148.87],[1.85,0]],"id":42070475},{"atl":[[4.9,51.14],[5.2,5.71]],"id":42070475},{"atb":[[2.12,58.31]],"id":41523279},{"atb":[[2.04,23.62],[1.95,54.46],[1.86,23.26]],"id":42236682},{"atl":[[2.94,62.39],[2.88,20.5],[3.7,14]],"id":42236682},{"atb":[[3.55,5.62]],"id":37174579}],"con":true,"img":false}]}
{"op":"mcm","clk":"5346630273","pt":1646092818963,"mc":[{"id":"1.195395444","rc":[{"atb":[[1.99,160.37],[1.98,51.02]],"id":41523279},{"atb":[[3.3,20.93]],"id":37174579}],"con":true,"img":false}]}
{"op":"mcm","clk":"5346630277","pt":1646092819065,"mc":[{"id":"1.195395444","rc":[{"atl":[[8.4,25.16]],"id":40917095},{"atb":[[2.76,8.97]],"id":42236670},{"atb":[[2,20]],"id":41523279},{"atb":[[1.91,9.18]],"id":42236682},{"atl":[[2.9,0]],"id":42236682},{"atb":[[2.8,0],[2.72,20.9]],"id":37174579}],"con":true,"img":false}]}
{"op":"mcm","clk":"5346630294","pt":1646092819430,"mc":[{"id":"1.195395444","rc":[{"atb":[[3.35,0]],"id":40917095},{"atl":[[5.7,10]],"id":42070475},{"atl":[[8.6,4.2]],"id":37174579}],"con":true,"img":false}]}
{"op":"mcm","clk":"5346630295","pt":1646092819532,"mc":[{"id":"1.195395444","rc":[{"atb":[[3.45,19.31]],"id":40917095},{"atl":[[5.1,9.89]],"id":42070475},{"atl":[[11.5,7.62]],"id":37174579}],"con":true,"img":false}]}
{"op":"mcm","clk":"5346630302","pt":1646092819737,"mc":[{"id":"1.195395444","rc":[{"atb":[[2.02,17.6]],"id":41523279}],"con":true,"img":false}]}
{"op":"mcm","clk":"5346630356","pt":1646092821438,"mc":[{"id":"1.195395444","rc":[{"atl":[[5.4,2]],"id":42189436},{"atb":[[3.75,4]],"id":42236670},{"atb":[[2.14,13.86]],"id":42070475},{"atl":[[8.4,0]],"id":37174579}],"con":true,"img":false}]}
{"op":"mcm","clk":"5346630362","pt":1646092821540,"mc":[{"id":"1.195395444","rc":[{"atl":[[5.4,14.26]],"id":42189436},{"atl":[[8.6,18.94]],"id":37174579}],"con":true,"img":false}]}
{"op":"mcm","clk":"5346630366","pt":1646092821646,"mc":[{"id":"1.195395444","rc":[{"atl":[[7.2,0]],"id":42189436},{"atb":[[2.12,44.77]],"id":41523279},{"atb":[[2.04,9.86],[1.95,46.62]],"id":42236682},{"atb":[[3.35,0],[2.78,0]],"id":37174579}],"con":true,"img":false}]}
{"op":"mcm","clk":"5346630371","pt":1646092821764,"mc":[{"id":"1.195395444","rc":[{"atl":[[5.3,2],[5.4,12.26]],"id":42189436},{"atb":[[3.8,3]],"id":42236670},{"atb":[[2.14,66.7]],"id":42070475}],"con":true,"img":false}]}
{"op":"mcm","clk":"5346630383","pt":1646092821870,"mc":[{"id":"1.195395444","rc":[{"atb":[[2.12,0]],"id":41523279}],"con":true,"img":false}]}
{"op":"mcm","clk":"5346630390","pt":1646092822075,"mc":[{"id":"1.195395444","rc":[{"atl":[[5.3,0],[5.2,4]],"id":42189436},{"atb":[[3.85,2]],"id":42236670},{"atb":[[2,51.3]],"id":41523279}],"con":true,"img":false}]}
{"op":"mcm","clk":"5346630396","pt":1646092822232,"mc":[{"id":"1.195395444","rc":[{"atb":[[2.78,9.38]],"id":42236670}],"con":true,"img":false}]}
{"op":"mcm","clk":"5346630436","pt":1646092823356,"mc":[{"id":"1.195395444","rc":[{"atb":[[2.78,0]],"id":42236670}],"con":true,"img":false}]}
