{"op":"mcm","clk":"5345904383","pt":1646079078732,"mc":[{"id":"1.195395443","marketDefinition":{"bspMarket":true,"turnInPlayEnabled":false,"persistenceEnabled":false,"marketBaseRate":5.0,"eventId":"31270459","eventTypeId":"4339","numberOfWinners":1,"bettingType":"ODDS","marketType":"WIN","marketTime":"2022-03-01T00:12:00.000Z","suspendTime":"2022-03-01T00:12:00.000Z","bspReconciled":false,"complete":true,"inPlay":false,"crossMatching":false,"runnersVoidable":false,"numberOfActiveRunners":7,"betDelay":0,"status":"OPEN","runners":[{"status":"ACTIVE","sortPriority":1,"id":42236670,"name":"1. Nighthawk Storm"},{"status":"ACTIVE","sortPriority":2,"id":40917095,"name":"2. Goldstar Vale"},{"status":"ACTIVE","sortPriority":3,"id":42189436,"name":"3. Going Gorillas"},{"status":"ACTIVE","sortPriority":4,"id":41523279,"name":"4. Homebush Cardi"},{"status":"ACTIVE","sortPriority":5,"id":37174579,"name":"6. Yes Yes No"},{"status":"ACTIVE","sortPriority":6,"id":42070475,"name":"7. Breakpoint"},{"status":"ACTIVE","sortPriority":7,"id":42236682,"name":"8. Goldstar Brynley"}],"regulators":["MR_INT"],"venue":"Addington","countryCode":"NZ","discountAllowed":false,"timezone":"NZ","openDate":"2022-02-28T23:02:00.000Z","version":4380660677,"name":"R5 295m C1","eventName":"Addington (NZL) 1st Mar"},"rc":[],"con":true,"img":false}]}
{"op":"mcm","clk":"5345904614","pt":1646079080731,"mc":[{"id":"1.195395443","marketDefinition":{"bspMarket":true,"turnInPlayEnabled":false,"persistenceEnabled":false,"marketBaseRate":5.0,"eventId":"31270459","eventTypeId":"4339","numberOfWinners":1,"bettingType":"ODDS","marketType":"WIN","marketTime":"2022-03-01T00:12:00.000Z","suspendTime":"2022-03-01T00:12:00.000Z","bspReconciled":false,"complete":true,"inPlay":false,"crossMatching":false,"runnersVoidable":false,"numberOfActiveRunners":7,"betDelay":0,"status":"OPEN","runners":[{"status":"ACTIVE","sortPriority":1,"id":42236670,"name":"1. Nighthawk Storm"},{"status":"ACTIVE","sortPriority":2,"id":40917095,"name":"2. Goldstar Vale"},{"status":"ACTIVE","sortPriority":3,"id":42189436,"name":"3. Going Gorillas"},{"status":"ACTIVE","sortPriority":4,"id":41523279,"name":"4. Homebush Cardi"},{"status":"ACTIVE","sortPriority":5,"id":37174579,"name":"6. Yes Yes No"},{"status":"ACTIVE","sortPriority":6,"id":42070475,"name":"7. Breakpoint"},{"status":"ACTIVE","sortPriority":7,"id":42236682,"name":"8. Goldstar Brynley"}],"regulators":["MR_INT"],"venue":"Addington","countryCode":"NZ","discountAllowed":true,"timezone":"NZ","openDate":"2022-02-28T23:02:00.000Z","version":4380660677,"name":"R5 295m C1","eventName":"Addington (NZL) 1st Mar"},"rc":[],"con":true,"img":false}]}
{"op":"mcm","clk":"5346126555","pt":1646081524658,"mc":[{"id":"1.195395443","rc":[{"atb":[[8,5.79],[5,40.59],[6,24.35],[7,13.53]],"id":40917095},{"atl":[[70,2.87],[38,3.57],[48,4.22],[29,4.72]],"id":40917095},{"spn":18.5,"spf":"NaN","id":40917095},{"atb":[[8,5.79],[5,40.59],[6,24.35],[7,13.53]],"id":42189436},{"atl":[[70,2.87],[38,3.57],[48,4.22],[29,4.72]],"id":42189436},{"spn":18.5,"spf":"NaN","id":42189436},{"atb":[[4,54.13],[5,30.44],[5.5,18.04],[6,8.11]],"id":42236670},{"atl":[[34,6.01],[18.5,7.56],[22,6.3],[27,7.63]],"id":42236670},{"spn":12.25,"spf":"NaN","id":42236670},{"atb":[[2.8,90.21],[3,60.89],[3.25,36.08],[3.5,16.23]],"id":42070475},{"atl":[[11,19.84],[13.5,15.87],[8.4,17.87],[9.4,15.75]],"id":42070475},{"spn":5.95,"spf":"NaN","id":42070475},{"atb":[[2.92,84.57],[3.8,14.5],[3.55,31.83],[3.3,52.95]],"id":41523279},{"atl":[[17,12.4],[12,12.02],[9.8,15.03],[14.5,14.7]],"id":41523279},{"spn":6.8,"spf":"NaN","id":41523279},{"atb":[[2.92,84.57],[3.8,14.5],[3.55,31.83],[3.3,52.95]],"id":42236682},{"atl":[[17,12.4],[12,12.02],[9.8,15.03],[14.5,14.7]],"id":42236682},{"spn":6.8,"spf":"NaN","id":42236682},{"atb":[[4.3,49.2],[5.8,16.91],[5.3,28.32],[6.6,7.24]],"id":37174579},{"atl":[[36,5.66],[19,7.35],[23,6.01],[28,7.35]],"id":37174579},{"spn":12.8,"spf":"NaN","id":37174579}],"con":true,"img":false}]}
{"op":"mcm","clk":"5346128115","pt":1646081544189,"mc":[{"id":"1.195395443","rc":[{"atb":[[8,0],[5,0],[6,0],[7,0]],"id":40917095},{"atl":[[70,0],[38,0],[48,0],[29,0]],"id":40917095},{"atb":[[8,0],[5,0],[6,0],[7,0]],"id":42189436},{"atl":[[70,0],[38,0],[48,0],[29,0]],"id":42189436},{"atb":[[4,0],[5,0],[5.5,0],[6,0]],"id":42236670},{"atl":[[34,0],[18.5,0],[22,0],[27,0]],"id":42236670},{"atb":[[2.8,0],[3,0],[3.25,0],[3.5,0]],"id":42070475},{"atl":[[11,0],[13.5,0],[8.4,0],[9.4,0]],"id":42070475},{"atb":[[2.92,0],[3.8,0],[3.55,0],[3.3,0]],"id":41523279},{"atl":[[17,0],[12,0],[9.8,0],[14.5,0]],"id":41523279},{"atb":[[2.92,0],[3.8,0],[3.55,0],[3.3,0]],"id":42236682},{"atl":[[17,0],[12,0],[9.8,0],[14.5,0]],"id":42236682},{"atb":[[4.3,0],[5.8,0],[5.3,0],[6.6,0]],"id":37174579},{"atl":[[36,0],[19,0],[23,0],[28,0]],"id":37174579}],"con":true,"img":false}]}
{"op":"mcm","clk":"5346129273","pt":1646081558930,"mc":[{"id":"1.195395443","rc":[{"atb":[[8,5.79],[5,40.59],[6,24.35],[7,13.53]],"id":40917095},{"atl":[[70,2.87],[38,3.57],[48,4.22],[29,4.72]],"id":40917095},{"atb":[[8,5.79],[5,40.59],[6,24.35],[7,13.53]],"id":42189436},{"atl":[[70,2.87],[38,3.57],[48,4.22],[29,4.72]],"id":42189436},{"atb":[[4,54.13],[5,30.44],[5.5,18.04],[6,8.11]],"id":42236670},{"atl":[[34,6.01],[18.5,7.56],[22,6.3],[27,7.63]],"id":42236670},{"atb":[[2.8,90.21],[3,60.89],[3.25,36.08],[3.5,16.23]],"id":42070475},{"atl":[[11,19.84],[13.5,15.87],[8.4,17.87],[9.4,15.75]],"id":42070475},{"atb":[[2.92,84.57],[3.8,14.5],[3.55,31.83],[3.3,52.95]],"id":41523279},{"atl":[[17,12.4],[12,12.02],[9.8,15.03],[14.5,14.7]],"id":41523279},{"atb":[[2.92,84.57],[3.8,14.5],[3.55,31.83],[3.3,52.95]],"id":42236682},{"atl":[[17,12.4],[12,12.02],[9.8,15.03],[14.5,14.7]],"id":42236682},{"atb":[[4.3,49.2],[5.8,16.91],[5.3,28.32],[6.6,7.24]],"id":37174579},{"atl":[[36,5.66],[19,7.35],[23,6.01],[28,7.35]],"id":37174579}],"con":true,"img":false}]}
{"op":"mcm","clk":"5346130613","pt":1646081576508,"mc":[{"id":"1.195395443","rc":[{"atb":[[8,0],[5,0],[6,0],[7,0]],"id":40917095},{"atl":[[70,0],[38,0],[48,0],[29,0]],"id":40917095},{"atb":[[8,0],[5,0],[6,0],[7,0]],"id":42189436},{"atl":[[70,0],[38,0],[48,0],[29,0]],"id":42189436},{"atb":[[4,0],[5,0],[5.5,0],[6,0]],"id":42236670},{"atl":[[34,0],[18.5,0],[22,0],[27,0]],"id":42236670},{"atb":[[2.8,0],[3,0],[3.25,0],[3.5,0]],"id":42070475},{"atl":[[11,0],[13.5,0],[8.4,0],[9.4,0]],"id":42070475},{"atb":[[2.92,0],[3.8,0],[3.55,0],[3.3,0]],"id":41523279},{"atl":[[17,0],[12,0],[9.8,0],[14.5,0]],"id":41523279},{"atb":[[2.92,0],[3.8,0],[3.55,0],[3.3,0]],"id":42236682},{"atl":[[17,0],[12,0],[9.8,0],[14.5,0]],"id":42236682},{"atb":[[4.3,0],[5.8,0],[5.3,0],[6.6,0]],"id":37174579},{"atl":[[36,0],[19,0],[23,0],[28,0]],"id":37174579}],"con":true,"img":false}]}
{"op":"mcm","clk":"5346131637","pt":1646081590749,"mc":[{"id":"1.195395443","rc":[{"atb":[[8,5.79],[5,40.59],[6,24.35],[7,13.53]],"id":40917095},{"atl":[[70,2.87],[38,3.57],[48,4.22],[29,4.72]],"id":40917095},{"atb":[[8,5.79],[5,40.59],[6,24.35],[7,13.53]],"id":42189436},{"atl":[[70,2.87],[38,3.57],[48,4.22],[29,4.72]],"id":42189436},{"atb":[[4,54.13],[5,30.44],[5.5,18.04],[6,8.11]],"id":42236670},{"atl":[[34,6.01],[18.5,7.56],[22,6.3],[27,7.63]],"id":42236670},{"atb":[[2.8,90.21],[3,60.89],[3.25,36.08],[3.5,16.23]],"id":42070475},{"atl":[[11,19.84],[13.5,15.87],[8.4,17.87],[9.4,15.75]],"id":42070475},{"atb":[[2.92,84.57],[3.8,14.5],[3.55,31.83],[3.3,52.95]],"id":41523279},{"atl":[[17,12.4],[12,12.02],[9.8,15.03],[14.5,14.7]],"id":41523279},{"atb":[[2.92,84.57],[3.8,14.5],[3.55,31.83],[3.3,52.95]],"id":42236682},{"atl":[[17,12.4],[12,12.02],[9.8,15.03],[14.5,14.7]],"id":42236682},{"atb":[[4.3,49.2],[5.8,16.91],[5.3,28.32],[6.6,7.24]],"id":37174579},{"atl":[[36,5.66],[19,7.35],[23,6.01],[28,7.35]],"id":37174579}],"con":true,"img":false}]}
{"op":"mcm","clk":"5346132637","pt":1646081604739,"mc":[{"id":"1.195395443","rc":[{"atb":[[8,0],[5,0],[6,0],[7,0]],"id":40917095},{"atl":[[70,0],[38,0],[48,0],[29,0]],"id":40917095},{"atb":[[8,0],[5,0],[6,0],[7,0]],"id":42189436},{"atl":[[70,0],[38,0],[48,0],[29,0]],"id":42189436},{"atb":[[4,0],[5,0],[5.5,0],[6,0]],"id":42236670},{"atl":[[34,0],[18.5,0],[22,0],[27,0]],"id":42236670},{"atb":[[2.8,0],[3,0],[3.25,0],[3.5,0]],"id":42070475},{"atl":[[11,0],[13.5,0],[8.4,0],[9.4,0]],"id":42070475},{"atb":[[2.92,0],[3.8,0],[3.55,0],[3.3,0]],"id":41523279},{"atl":[[17,0],[12,0],[9.8,0],[14.5,0]],"id":41523279},{"atb":[[2.92,0],[3.8,0],[3.55,0],[3.3,0]],"id":42236682},{"atl":[[17,0],[12,0],[9.8,0],[14.5,0]],"id":42236682},{"atb":[[4.3,0],[5.8,0],[5.3,0],[6.6,0]],"id":37174579},{"atl":[[36,0],[19,0],[23,0],[28,0]],"id":37174579}],"con":true,"img":false}]}
{"op":"mcm","clk":"5346133741","pt":1646081621322,"mc":[{"id":"1.195395443","rc":[{"atb":[[8,5.79],[5,40.59],[6,24.35],[7,13.53]],"id":40917095},{"atl":[[70,2.87],[38,3.57],[48,4.22],[29,4.72]],"id":40917095},{"atb":[[8,5.79],[5,40.59],[6,24.35],[7,13.53]],"id":42189436},{"atl":[[70,2.87],[38,3.57],[48,4.22],[29,4.72]],"id":42189436},{"atb":[[4,54.13],[5,30.44],[5.5,18.04],[6,8.11]],"id":42236670},{"atl":[[34,6.01],[18.5,7.56],[22,6.3],[27,7.63]],"id":42236670},{"atb":[[2.8,90.21],[3,60.89],[3.25,36.08],[3.5,16.23]],"id":42070475},{"atl":[[11,19.84],[13.5,15.87],[8.4,17.87],[9.4,15.75]],"id":42070475},{"atb":[[2.92,84.57],[3.8,14.5],[3.55,31.83],[3.3,52.95]],"id":41523279},{"atl":[[17,12.4],[12,12.02],[9.8,15.03],[14.5,14.7]],"id":41523279},{"atb":[[2.92,84.57],[3.8,14.5],[3.55,31.83],[3.3,52.95]],"id":42236682},{"atl":[[17,12.4],[12,12.02],[9.8,15.03],[14.5,14.7]],"id":42236682},{"atb":[[4.3,49.2],[5.8,16.91],[5.3,28.32],[6.6,7.24]],"id":37174579},{"atl":[[36,5.66],[19,7.35],[23,6.01],[28,7.35]],"id":37174579}],"con":true,"img":false}]}
{"op":"mcm","clk":"5346134755","pt":1646081637073,"mc":[{"id":"1.195395443","rc":[{"atb":[[8,0],[5,0],[6,0],[7,0]],"id":40917095},{"atl":[[70,0],[38,0],[48,0],[29,0]],"id":40917095},{"atb":[[8,0],[5,0],[6,0],[7,0]],"id":42189436},{"atl":[[70,0],[38,0],[48,0],[29,0]],"id":42189436},{"atb":[[4,0],[5,0],[5.5,0],[6,0]],"id":42236670},{"atl":[[34,0],[18.5,0],[22,0],[27,0]],"id":42236670},{"atb":[[2.8,0],[3,0],[3.25,0],[3.5,0]],"id":42070475},{"atl":[[11,0],[13.5,0],[8.4,0],[9.4,0]],"id":42070475},{"atb":[[2.92,0],[3.8,0],[3.55,0],[3.3,0]],"id":41523279},{"atl":[[17,0],[12,0],[9.8,0],[14.5,0]],"id":41523279},{"atb":[[2.92,0],[3.8,0],[3.55,0],[3.3,0]],"id":42236682},{"atl":[[17,0],[12,0],[9.8,0],[14.5,0]],"id":42236682},{"atb":[[4.3,0],[5.8,0],[5.3,0],[6.6,0]],"id":37174579},{"atl":[[36,0],[19,0],[23,0],[28,0]],"id":37174579}],"con":true,"img":false}]}
{"op":"mcm","clk":"5346135981","pt":1646081656756,"mc":[{"id":"1.195395443","rc":[{"atb":[[8,5.79],[5,40.59],[6,24.35],[7,13.53]],"id":40917095},{"atl":[[70,2.87],[38,3.57],[48,4.22],[29,4.72]],"id":40917095},{"atb":[[8,5.79],[5,40.59],[6,24.35],[7,13.53]],"id":42189436},{"atl":[[70,2.87],[38,3.57],[48,4.22],[29,4.72]],"id":42189436},{"atb":[[4,54.13],[5,30.44],[5.5,18.04],[6,8.11]],"id":42236670},{"atl":[[34,6.01],[18.5,7.56],[22,6.3],[27,7.63]],"id":42236670},{"atb":[[2.8,90.21],[3,60.89],[3.25,36.08],[3.5,16.23]],"id":42070475},{"atl":[[11,19.84],[13.5,15.87],[8.4,17.87],[9.4,15.75]],"id":42070475},{"atb":[[3.4,50.74],[3.9,13.99],[2.96,82.85],[3.65,30.63]],"id":41523279},{"atl":[[18,11.67],[10.5,13.92],[13,11.02],[15.5,13.68]],"id":41523279},{"spn":7.2,"spf":"NaN","id":41523279},{"atb":[[2.92,84.57],[3.8,14.5],[3.55,31.83],[3.3,52.95]],"id":42236682},{"atl":[[17,12.4],[12,12.02],[9.8,15.03],[14.5,14.7]],"id":42236682},{"atb":[[4.3,49.2],[5.8,16.91],[5.3,28.32],[6.6,7.24]],"id":37174579},{"atl":[[36,5.66],[19,7.35],[23,6.01],[28,7.35]],"id":37174579}],"con":true,"img":false}]}
{"op":"mcm","clk":"5346138572","pt":1646081694858,"mc":[{"id":"1.195395443","rc":[{"atb":[[8,0],[5,0],[6,0],[7,0]],"id":40917095},{"atl":[[70,0],[38,0],[48,0],[29,0]],"id":40917095},{"atb":[[8,0],[5,0],[6,0],[7,0]],"id":42189436},{"atl":[[70,0],[38,0],[48,0],[29,0]],"id":42189436},{"atb":[[4,0],[5,0],[5.5,0],[6,0]],"id":42236670},{"atl":[[34,0],[18.5,0],[22,0],[27,0]],"id":42236670},{"atb":[[2.8,0],[3,0],[3.25,0],[3.5,0]],"id":42070475},{"atl":[[11,0],[13.5,0],[8.4,0],[9.4,0]],"id":42070475},{"atb":[[3.4,0],[3.9,0],[2.96,0],[3.65,0]],"id":41523279},{"atl":[[18,0],[10.5,0],[13,0],[15.5,0]],"id":41523279},{"atb":[[2.92,0],[3.8,0],[3.55,0],[3.3,0]],"id":42236682},{"atl":[[17,0],[12,0],[9.8,0],[14.5,0]],"id":42236682},{"atb":[[4.3,0],[5.8,0],[5.3,0],[6.6,0]],"id":37174579},{"atl":[[36,0],[19,0],[23,0],[28,0]],"id":37174579}],"con":true,"img":false}]}
{"op":"mcm","clk":"5346140304","pt":1646081718873,"mc":[{"id":"1.195395443","rc":[{"atb":[[8,5.79],[5,40.59],[6,24.35],[7,13.53]],"id":40917095},{"atl":[[70,2.87],[38,3.57],[48,4.22],[29,4.72]],"id":40917095},{"atb":[[8,5.79],[5,40.59],[6,24.35],[7,13.53]],"id":42189436},{"atl":[[70,2.87],[38,3.57],[48,4.22],[29,4.72]],"id":42189436},{"atb":[[4,54.13],[5,30.44],[5.5,18.04],[6,8.11]],"id":42236670},{"atl":[[34,6.01],[18.5,7.56],[22,6.3],[27,7.63]],"id":42236670},{"atb":[[2.8,90.21],[3,60.89],[3.25,36.08],[3.5,16.23]],"id":42070475},{"atl":[[11,19.84],[13.5,15.87],[8.4,17.87],[9.4,15.75]],"id":42070475},{"atb":[[3.4,50.74],[3.9,13.99],[2.96,82.85],[3.65,30.63]],"id":41523279},{"atl":[[18,11.67],[10.5,13.92],[13,11.02],[15.5,13.68]],"id":41523279},{"atb":[[2.92,84.57],[3.8,14.5],[3.55,31.83],[3.3,52.95]],"id":42236682},{"atl":[[17,12.4],[12,12.02],[9.8,15.03],[14.5,14.7]],"id":42236682},{"atb":[[4.3,49.2],[5.8,16.91],[5.3,28.32],[6.6,7.24]],"id":37174579},{"atl":[[36,5.66],[19,7.35],[23,6.01],[28,7.35]],"id":37174579}],"con":true,"img":false}]}
{"op":"mcm","clk":"5346183390","pt":1646082292654,"mc":[{"id":"1.195395443","rc":[{"atb":[[8,0],[5,0],[6,0],[7,0]],"id":40917095},{"atl":[[70,0],[38,0],[48,0],[29,0]],"id":40917095},{"spn":"NaN","spf":"NaN","id":40917095},{"atb":[[8,0],[5,0],[6,0],[7,0]],"id":42189436},{"atl":[[70,0],[38,0],[48,0],[29,0]],"id":42189436},{"spn":"NaN","spf":"NaN","id":42189436},{"atb":[[2.92,0],[3.8,0],[3.55,0],[3.3,0]],"id":42236682},{"atl":[[17,0],[12,0],[9.8,0],[14.5,0]],"id":42236682},{"spn":"NaN","spf":"NaN","id":42236682}],"con":true,"img":false}]}
{"op":"mcm","clk":"5346184036","pt":1646082300481,"mc":[{"id":"1.195395443","rc":[{"atb":[[8,11.6],[9,5.07],[5.5,36.08],[7,20.29]],"id":40917095},{"atl":[[75,2.67],[40,3.39],[50,2.7],[100,2]],"id":40917095},{"atb":[[8,11.6],[9,5.07],[5.5,36.08],[7,20.29]],"id":42189436},{"atl":[[75,2.67],[40,3.39],[50,2.7],[100,2]],"id":42189436},{"atb":[[3.4,50.74],[3.9,13.99],[2.96,82.85],[3.65,30.63]],"id":42236682},{"atl":[[18,11.67],[10.5,13.92],[13,11.02],[15.5,13.68]],"id":42236682}],"con":true,"img":false}]}
{"op":"mcm","clk":"5346223502","pt":1646082744956,"mc":[{"id":"1.195395443","rc":[{"atb":[[8,0],[9,0],[5.5,0],[7,0]],"id":40917095},{"atl":[[75,0],[40,0],[50,0],[100,0]],"id":40917095},{"atb":[[8,0],[9,0],[5.5,0],[7,0]],"id":42189436},{"atl":[[75,0],[40,0],[50,0],[100,0]],"id":42189436},{"atb":[[4,0],[5,0],[5.5,0],[6,0]],"id":42236670},{"atl":[[34,0],[18.5,0],[22,0],[27,0]],"id":42236670},{"spn":"NaN","spf":"NaN","id":42236670},{"atb":[[2.8,0],[3,0],[3.25,0],[3.5,0]],"id":42070475},{"atl":[[11,0],[13.5,0],[8.4,0],[9.4,0]],"id":42070475},{"spn":"NaN","spf":"NaN","id":42070475},{"atb":[[3.4,0],[3.9,0],[2.96,0],[3.65,0]],"id":41523279},{"atl":[[18,0],[10.5,0],[13,0],[15.5,0]],"id":41523279},{"spn":"NaN","spf":"NaN","id":41523279},{"atb":[[3.4,0],[3.9,0],[2.96,0],[3.65,0]],"id":42236682},{"atl":[[18,0],[10.5,0],[13,0],[15.5,0]],"id":42236682},{"atb":[[4.3,0],[5.8,0],[5.3,0],[6.6,0]],"id":37174579},{"atl":[[36,0],[19,0],[23,0],[28,0]],"id":37174579},{"spn":"NaN","spf":"NaN","id":37174579}],"con":true,"img":false}]}
{"op":"mcm","clk":"5346225923","pt":1646082773125,"mc":[{"id":"1.195395443","rc":[{"atb":[[8,11.6],[9,5.07],[5.5,36.08],[7,20.29]],"id":40917095},{"atl":[[75,2.67],[40,3.39],[50,2.7],[100,2]],"id":40917095},{"atb":[[8,11.6],[9,5.07],[5.5,36.08],[7,20.29]],"id":42189436},{"atl":[[75,2.67],[40,3.39],[50,2.7],[100,2]],"id":42189436},{"atb":[[4,54.13],[5,30.44],[5.5,18.04],[6,8.11]],"id":42236670},{"atl":[[34,6.01],[18.5,7.56],[22,6.3],[27,7.63]],"id":42236670},{"atb":[[3.6,15.61],[3.1,57.99],[3.35,34.55],[2.84,88.25]],"id":42070475},{"atl":[[12,18.04],[9.8,15.03],[8.8,16.95],[14.5,14.7]],"id":42070475},{"atb":[[3.4,50.74],[3.9,13.99],[2.96,82.85],[3.65,30.63]],"id":41523279},{"atl":[[18,11.67],[10.5,13.92],[13,11.02],[15.5,13.68]],"id":41523279},{"atb":[[2.92,84.57],[3.8,14.5],[3.55,31.83],[3.3,52.95]],"id":42236682},{"atl":[[17,12.4],[12,12.02],[9.8,15.03],[14.5,14.7]],"id":42236682},{"atb":[[4.5,46.39],[5.5,27.06],[6,16.23],[7,6.76]],"id":37174579},{"atl":[[19.5,7.15],[38,5.36],[24,5.75],[29,7.08]],"id":37174579}],"con":true,"img":false}]}
{"op":"mcm","clk":"5346253003","pt":1646083002681,"mc":[{"id":"1.195395443","marketDefinition":{"bspMarket":true,"turnInPlayEnabled":false,"persistenceEnabled":false,"marketBaseRate":5.0,"eventId":"31270459","eventTypeId":"4339","numberOfWinners":1,"bettingType":"ODDS","marketType":"WIN","marketTime":"2022-03-01T00:12:00.000Z","suspendTime":"2022-03-01T00:12:00.000Z","bspReconciled":false,"complete":true,"inPlay":false,"crossMatching":false,"runnersVoidable":false,"numberOfActiveRunners":7,"betDelay":0,"status":"OPEN","runners":[{"status":"ACTIVE","sortPriority":1,"id":42236670,"name":"1. Nighthawk Storm"},{"status":"ACTIVE","sortPriority":2,"id":40917095,"name":"2. Goldstar Vale"},{"status":"ACTIVE","sortPriority":3,"id":42189436,"name":"3. Going Gorillas"},{"status":"ACTIVE","sortPriority":4,"id":41523279,"name":"4. Homebush Cardi"},{"status":"ACTIVE","sortPriority":5,"id":37174579,"name":"6. Yes Yes No"},{"status":"ACTIVE","sortPriority":6,"id":42070475,"name":"7. Breakpoint"},{"status":"ACTIVE","sortPriority":7,"id":42236682,"name":"8. Goldstar Brynley"}],"regulators":["MR_INT"],"venue":"Addington","countryCode":"NZ","discountAllowed":true,"timezone":"NZ","openDate":"2022-02-28T23:02:00.000Z","version":4380660677,"name":"R5 295m C1","eventName":"Addington (NZL) 1st Mar"},"rc":[{"atb":[[8,11.6],[9,5.07],[5.5,36.08],[7,20.29]],"id":40917095},{"atl":[[75,2.67],[40,3.39],[50,2.7],[100,2]],"id":40917095},{"spn":24.5,"spf":"NaN","id":40917095},{"atb":[[8,11.6],[9,5.07],[5.5,36.08],[7,20.29]],"id":42189436},{"atl":[[75,2.67],[40,3.39],[50,2.7],[100,2]],"id":42189436},{"spn":24.5,"spf":"NaN","id":42189436},{"atb":[[4,54.13],[5,30.44],[5.5,18.04],[6,8.11]],"id":42236670},{"atl":[[34,6.01],[18.5,7.56],[22,6.3],[27,7.63]],"id":42236670},{"spn":12.25,"spf":"NaN","id":42236670},{"atb":[[3.6,15.61],[3.1,57.99],[3.35,34.55],[2.84,88.25]],"id":42070475},{"atl":[[12,18.04],[9.8,15.03],[8.8,16.95],[14.5,14.7]],"id":42070475},{"spn":6.2,"spf":"NaN","id":42070475},{"atb":[[3.4,50.74],[3.9,13.99],[2.96,82.85],[3.65,30.63]],"id":41523279},{"atl":[[18,11.67],[10.5,13.92],[13,11.02],[15.5,13.68]],"id":41523279},{"spn":7.2,"spf":"NaN","id":41523279},{"atb":[[2.92,84.57],[3.8,14.5],[3.55,31.83],[3.3,52.95]],"id":42236682},{"atl":[[17,12.4],[12,12.02],[9.8,15.03],[14.5,14.7]],"id":42236682},{"spn":6.8,"spf":"NaN","id":42236682},{"atb":[[4.5,46.39],[5.5,27.06],[6,16.23],[7,6.76]],"id":37174579},{"atl":[[19.5,7.15],[38,5.36],[24,5.75],[29,7.08]],"id":37174579},{"spn":13.25,"spf":"NaN","id":37174579}],"con":true,"img":true}]}
{"op":"mcm","clk":"5346366659","pt":1646084657847,"mc":[{"id":"1.195395443","rc":[{"spn":24.5,"spf":"NaN","id":40917095},{"spn":24.5,"spf":"NaN","id":42189436},{"atb":[[5.6,1.81]],"id":42236670},{"spn":12.25,"spf":"NaN","id":42236670},{"spn":6.2,"spf":"NaN","id":42070475},{"atb":[[3.7,3.09]],"id":41523279},{"spn":7.2,"spf":"NaN","id":41523279},{"spn":6.8,"spf":"NaN","id":42236682},{"spn":13.25,"spf":"NaN","id":37174579}],"con":true,"img":false}]}
{"op":"mcm","clk":"5346366672","pt":1646084658053,"mc":[{"id":"1.195395443","rc":[{"atb":[[3.6,3.21]],"id":42236682},{"atb":[[1.01,1.67]],"id":37174579}],"con":true,"img":false}]}
{"op":"mcm","clk":"5346366693","pt":1646084658315,"mc":[{"id":"1.195395443","rc":[{"atb":[[3.4,3.48]],"id":42070475},{"atb":[[1.01,1.6]],"id":37174579}],"con":true,"img":false}]}
{"op":"mcm","clk":"5346366717","pt":1646084658727,"mc":[{"id":"1.195395443","rc":[{"atb":[[1.01,0]],"id":37174579}],"con":true,"img":false}]}
{"op":"mcm","clk":"5346366724","pt":1646084658828,"mc":[{"id":"1.195395443","rc":[{"atb":[[6.2,1.6]],"id":37174579}],"con":true,"img":false}]}
{"op":"mcm","clk":"5346406542","pt":1646085522177,"mc":[{"id":"1.195395443","rc":[{"atb":[[1.01,2.23]],"id":42236670},{"atb":[[3.7,5.85]],"id":41523279},{"atb":[[1.01,2.23]],"id":37174579}],"con":true,"img":false}]}
{"op":"mcm","clk":"5346406547","pt":1646085522275,"mc":[{"id":"1.195395443","rc":[{"atb":[[3.4,6.59]],"id":42070475},{"atb":[[3.6,6.08]],"id":42236682}],"con":true,"img":false}]}
{"op":"mcm","clk":"5346406563","pt":1646085522584,"mc":[{"id":"1.195395443","rc":[{"atb":[[1.01,1.61]],"id":42236670}],"con":true,"img":false}]}
{"op":"mcm","clk":"5346406569","pt":1646085522686,"mc":[{"id":"1.195395443","rc":[{"atb":[[1.01,1.43]],"id":37174579}],"con":true,"img":false}]}
{"op":"mcm","clk":"5346406587","pt":1646085523149,"mc":[{"id":"1.195395443","rc":[{"atb":[[1.01,0]],"id":42236670}],"con":true,"img":false}]}
{"op":"mcm","clk":"5346406591","pt":1646085523251,"mc":[{"id":"1.195395443","rc":[{"atb":[[5.6,3.43]],"id":42236670}],"con":true,"img":false}]}
{"op":"mcm","clk":"5346406599","pt":1646085523559,"mc":[{"id":"1.195395443","rc":[{"atb":[[1.01,0]],"id":37174579}],"con":true,"img":false}]}
{"op":"mcm","clk":"5346406604","pt":1646085523664,"mc":[{"id":"1.195395443","rc":[{"atb":[[6.2,3.03]],"id":37174579}],"con":true,"img":false}]}
{"op":"mcm","clk":"5346436035","pt":1646086320120,"mc":[{"id":"1.195395443","rc":[{"atb":[[8,11.59],[9,5.07],[8.6,1.33],[5.5,36.08],[7,20.29]],"id":40917095},{"atl":[[75,2.67],[40,3.39],[50,2.7],[100,2]],"id":40917095},{"atb":[[8,11.59],[9,5.07],[8.6,1.33],[5.5,36.08],[7,20.29]],"id":42189436},{"atl":[[75,2.67],[40,3.39],[50,2.7],[100,2]],"id":42189436},{"atb":[[5.6,5.43],[4,54.12],[5,30.44],[5.5,18.03],[6,8.11]],"id":42236670},{"atl":[[34,6.01],[18.5,7.56],[22,6.29],[27,7.63]],"id":42236670},{"atb":[[3.6,15.61],[3.1,57.98],[3.35,34.54],[3.4,6.59],[2.84,88.23],[3.55,2]],"id":42070475},{"atl":[[12,18.03],[9.8,15.02],[8.8,16.95],[14.5,14.69]],"id":42070475},{"atb":[[3.7,5.85],[3.4,50.73],[3.9,13.99],[2.96,82.83],[3.65,30.63]],"id":41523279},{"atl":[[18,11.66],[10.5,13.92],[13,11.02],[15.5,13.68]],"id":41523279},{"atb":[[3.6,6.08],[2.92,84.56],[3.85,2],[3.8,14.49],[3.55,31.83],[3.3,52.94]],"id":42236682},{"atl":[[17,12.39],[12,12.02],[9.8,15.02],[14.5,14.69]],"id":42236682},{"spn":6.82,"spf":"NaN","id":42236682},{"atb":[[4.5,46.38],[6.2,3.03],[5.5,27.06],[6,16.23],[7,6.76],[6.6,1.8]],"id":37174579},{"atl":[[19.5,7.14],[38,5.36],[24,5.75],[29,7.08]],"id":37174579}],"con":true,"img":false}]}
{"op":"mcm","clk":"5346436039","pt":1646086320218,"mc":[{"id":"1.195395443","rc":[{"atb":[[3.85,2]],"id":41523279}],"con":true,"img":false}]}
{"op":"mcm","clk":"5346437068","pt":1646086347406,"mc":[{"id":"1.195395443","marketDefinition":{"bspMarket":true,"turnInPlayEnabled":false,"persistenceEnabled":false,"marketBaseRate":5.0,"eventId":"31270459","eventTypeId":"4339","numberOfWinners":1,"bettingType":"ODDS","marketType":"WIN","marketTime":"2022-03-01T00:12:00.000Z","suspendTime":"2022-03-01T00:12:00.000Z","bspReconciled":false,"complete":true,"inPlay":false,"crossMatching":true,"runnersVoidable":false,"numberOfActiveRunners":7,"betDelay":0,"status":"OPEN","runners":[{"status":"ACTIVE","sortPriority":1,"id":42236670,"name":"1. Nighthawk Storm"},{"status":"ACTIVE","sortPriority":2,"id":40917095,"name":"2. Goldstar Vale"},{"status":"ACTIVE","sortPriority":3,"id":42189436,"name":"3. Going Gorillas"},{"status":"ACTIVE","sortPriority":4,"id":41523279,"name":"4. Homebush Cardi"},{"status":"ACTIVE","sortPriority":5,"id":37174579,"name":"6. Yes Yes No"},{"status":"ACTIVE","sortPriority":6,"id":42070475,"name":"7. Breakpoint"},{"status":"ACTIVE","sortPriority":7,"id":42236682,"name":"8. Goldstar Brynley"}],"regulators":["MR_INT"],"venue":"Addington","countryCode":"NZ","discountAllowed":true,"timezone":"NZ","openDate":"2022-02-28T23:02:00.000Z","version":4380660677,"name":"R5 295m C1","eventName":"Addington (NZL) 1st Mar"},"rc":[],"con":true,"img":false}]}
{"op":"mcm","clk":"5346439289","pt":1646086398496,"mc":[{"id":"1.195395443","rc":[{"atb":[[3.85,0]],"id":41523279}],"con":true,"img":false}]}
{"op":"mcm","clk":"5346439295","pt":1646086398602,"mc":[{"id":"1.195395443","rc":[{"atb":[[3.9,15.99]],"id":41523279}],"con":true,"img":false}]}
{"op":"mcm","clk":"5346439475","pt":1646086403641,"mc":[{"id":"1.195395443","rc":[{"atb":[[2.92,0],[3.8,0],[3.55,0],[3.3,0]],"id":42236682},{"atl":[[17,0],[12,0],[9.8,0],[14.5,0]],"id":42236682}],"con":true,"img":false}]}
{"op":"mcm","clk":"5346439690","pt":1646086408428,"mc":[{"id":"1.195395443","rc":[{"atb":[[3.4,50.73],[3.9,13.99],[2.96,82.83],[3.65,30.63]],"id":42236682},{"atl":[[18,11.66],[10.5,13.92],[13,11.02],[15.5,13.68]],"id":42236682}],"con":true,"img":false}]}
{"op":"mcm","clk":"5346439837","pt":1646086411820,"mc":[{"id":"1.195395443","rc":[{"atb":[[3.6,3.21]],"id":42236682}],"con":true,"img":false}]}
{"op":"mcm","clk":"5346440081","pt":1646086419015,"mc":[{"id":"1.195395443","rc":[{"atb":[[3.6,0]],"id":42236682}],"con":true,"img":false}]}
{"op":"mcm","clk":"5346440176","pt":1646086421850,"mc":[{"id":"1.195395443","rc":[{"atb":[[3.7,3.09]],"id":42236682}],"con":true,"img":false}]}
{"op":"mcm","clk":"5346440395","pt":1646086426844,"mc":[{"id":"1.195395443","rc":[{"atb":[[3.7,5.85]],"id":42236682}],"con":true,"img":false}]}
{"op":"mcm","clk":"5346441507","pt":1646086451165,"mc":[{"id":"1.195395443","rc":[{"atb":[[8.6,0]],"id":40917095}],"con":true,"img":false}]}
{"op":"mcm","clk":"5346441512","pt":1646086451267,"mc":[{"id":"1.195395443","rc":[{"atb":[[9.2,1.23]],"id":40917095}],"con":true,"img":false}]}
{"op":"mcm","clk":"5346443271","pt":1646086494548,"mc":[{"id":"1.195395443","rc":[{"atb":[[8,0],[9,0],[5.5,0],[7,0]],"id":40917095},{"atl":[[75,0],[40,0],[50,0],[100,0]],"id":40917095},{"spn":"Infinity","spf":"NaN","id":40917095},{"atb":[[3.6,0],[3.1,0],[3.35,0],[2.84,0]],"id":42070475},{"atl":[[12,0],[9.8,0],[8.8,0],[14.5,0]],"id":42070475},{"spn":"Infinity","spf":"NaN","id":42070475},{"spn":7.2,"spf":"NaN","id":42236682}],"con":true,"img":false}]}
{"op":"mcm","clk":"5346443489","pt":1646086499142,"mc":[{"id":"1.195395443","rc":[{"atb":[[9.6,4.71],[8.6,10.68],[5.8,33.82],[7.6,18.44]],"id":40917095},{"atl":[[65,2.06],[130,1.53],[90,2.22],[46,2.93]],"id":40917095},{"atb":[[3.4,23.5],[3.15,37.76],[2.96,62.13],[2.76,92.24]],"id":42070475},{"atl":[[11,19.84],[13.5,15.87],[8.4,17.87],[9.4,15.74]],"id":42070475}],"con":true,"img":false}]}
{"op":"mcm","clk":"5346443616","pt":1646086502142,"mc":[{"id":"1.195395443","rc":[{"atb":[[3.4,20.39]],"id":42070475}],"con":true,"img":false}]}
{"op":"mcm","clk":"5346443874","pt":1646086509167,"mc":[{"id":"1.195395443","rc":[{"atb":[[3.4,16.91]],"id":42070475}],"con":true,"img":false}]}
{"op":"mcm","clk":"5346443998","pt":1646086512356,"mc":[{"id":"1.195395443","rc":[{"atb":[[3.2,3.8]],"id":42070475}],"con":true,"img":false}]}
{"op":"mcm","clk":"5346444284","pt":1646086519889,"mc":[{"id":"1.195395443","rc":[{"atb":[[3.2,7.19]],"id":42070475}],"con":true,"img":false}]}
{"op":"mcm","clk":"5346444420","pt":1646086523590,"mc":[{"id":"1.195395443","rc":[{"atb":[[3.85,0]],"id":42236682}],"con":true,"img":false}]}
{"op":"mcm","clk":"5346444425","pt":1646086523697,"mc":[{"id":"1.195395443","rc":[{"atb":[[3.95,2]],"id":42236682}],"con":true,"img":false}]}
{"op":"mcm","clk":"5346444525","pt":1646086526069,"mc":[{"id":"1.195395443","rc":[{"atb":[[9.6,0],[8.6,0],[5.8,0],[7.6,0]],"id":40917095},{"atl":[[65,0],[130,0],[90,0],[46,0]],"id":40917095},{"atb":[[3.4,0],[3.15,0],[2.96,0],[2.76,0]],"id":42070475},{"atl":[[11,0],[13.5,0],[8.4,0],[9.4,0]],"id":42070475}],"con":true,"img":false}]}
{"op":"mcm","clk":"5346444864","pt":1646086533010,"mc":[{"id":"1.195395443","rc":[{"atb":[[9.6,4.71],[8.6,10.68],[5.8,33.82],[7.6,18.44]],"id":40917095},{"atl":[[65,2.06],[130,1.53],[90,2.22],[46,2.93]],"id":40917095},{"atb":[[2.8,90.2],[3,60.88],[3.25,36.08],[3.5,16.23]],"id":42070475},{"atl":[[11,19.84],[13.5,15.87],[8.4,17.87],[9.4,15.74]],"id":42070475}],"con":true,"img":false}]}
{"op":"mcm","clk":"5346444944","pt":1646086534498,"mc":[{"id":"1.195395443","rc":[{"atb":[[8.6,0]],"id":42189436}],"con":true,"img":false}]}
{"op":"mcm","clk":"5346444946","pt":1646086534599,"mc":[{"id":"1.195395443","rc":[{"atb":[[9.2,1.23]],"id":42189436}],"con":true,"img":false}]}
{"op":"mcm","clk":"5346444980","pt":1646086535317,"mc":[{"id":"1.195395443","rc":[{"atb":[[3.2,3.8]],"id":42070475}],"con":true,"img":false}]}
{"op":"mcm","clk":"5346445130","pt":1646086539118,"mc":[{"id":"1.195395443","rc":[{"atb":[[3.2,0]],"id":42070475}],"con":true,"img":false}]}
{"op":"mcm","clk":"5346445477","pt":1646086548213,"mc":[{"id":"1.195395443","rc":[{"atb":[[3.3,3.63]],"id":42070475}],"con":true,"img":false}]}
{"op":"mcm","clk":"5346445669","pt":1646086553001,"mc":[{"id":"1.195395443","rc":[{"atb":[[3.3,6.87]],"id":42070475}],"con":true,"img":false}]}
{"op":"mcm","clk":"5346449751","pt":1646086653549,"mc":[{"id":"1.195395443","rc":[{"spn":27.8,"spf":"NaN","id":40917095},{"spn":24.6,"spf":"NaN","id":42189436},{"atb":[[3.55,0]],"id":42070475},{"spn":5.95,"spf":"NaN","id":42070475},{"spn":7.22,"spf":"NaN","id":42236682}],"con":true,"img":false}]}
{"op":"mcm","clk":"5346449756","pt":1646086653655,"mc":[{"id":"1.195395443","rc":[{"atb":[[3.35,2]],"id":42070475}],"con":true,"img":false}]}
{"op":"mcm","clk":"5346457550","pt":1646086898861,"mc":[{"id":"1.195395443","rc":[{"atb":[[5.6,3.43]],"id":42236670}],"con":true,"img":false}]}
{"op":"mcm","clk":"5346457555","pt":1646086898964,"mc":[{"id":"1.195395443","rc":[{"atb":[[4.8,2]],"id":42236670}],"con":true,"img":false}]}
{"op":"mcm","clk":"5346463441","pt":1646087115986,"mc":[{"id":"1.195395443","rc":[{"atb":[[3.9,13.99]],"id":41523279}],"con":true,"img":false}]}
{"op":"mcm","clk":"5346463445","pt":1646087116089,"mc":[{"id":"1.195395443","rc":[{"atb":[[3.95,2]],"id":41523279}],"con":true,"img":false}]}
{"op":"mcm","clk":"5346464565","pt":1646087163343,"mc":[{"id":"1.195395443","rc":[{"atb":[[9.2,0]],"id":40917095}],"con":true,"img":false}]}
{"op":"mcm","clk":"5346464567","pt":1646087163446,"mc":[{"id":"1.195395443","rc":[{"atb":[[9.8,1.15]],"id":40917095}],"con":true,"img":false}]}
{"op":"mcm","clk":"5346484652","pt":1646087958310,"mc":[{"id":"1.195395443","rc":[{"atb":[[9.8,0]],"id":40917095},{"spn":7.22,"spf":"NaN","id":41523279}],"con":true,"img":false}]}
{"op":"mcm","clk":"5346484657","pt":1646087958412,"mc":[{"id":"1.195395443","rc":[{"atb":[[9.6,5.88]],"id":40917095}],"con":true,"img":false}]}
{"op":"mcm","clk":"5346484804","pt":1646087963884,"mc":[{"id":"1.195395443","rc":[{"atb":[[9.6,4.71]],"id":40917095},{"atb":[[3.35,0]],"id":42070475}],"con":true,"img":false}]}
{"op":"mcm","clk":"5346484808","pt":1646087963985,"mc":[{"id":"1.195395443","rc":[{"atb":[[8.6,12.01]],"id":40917095},{"atb":[[3.4,2]],"id":42070475}],"con":true,"img":false}]}
{"op":"mcm","clk":"5346486981","pt":1646088045092,"mc":[{"id":"1.195395443","rc":[{"atb":[[4.8,0]],"id":42236670},{"atb":[[3.95,0]],"id":41523279},{"spn":7.2,"spf":"NaN","id":41523279}],"con":true,"img":false}]}
{"op":"mcm","clk":"5346486983","pt":1646088045199,"mc":[{"id":"1.195395443","rc":[{"atb":[[4.9,2]],"id":42236670},{"atb":[[4,2]],"id":41523279}],"con":true,"img":false}]}
{"op":"mcm","clk":"5346489396","pt":1646088144112,"mc":[{"id":"1.195395443","rc":[{"atb":[[8.6,10.68]],"id":40917095},{"spn":7.25,"spf":"NaN","id":41523279}],"con":true,"img":false}]}
{"op":"mcm","clk":"5346489400","pt":1646088144218,"mc":[{"id":"1.195395443","rc":[{"atb":[[8.2,1.4]],"id":40917095}],"con":true,"img":false}]}
{"op":"mcm","clk":"5346489962","pt":1646088165989,"mc":[{"id":"1.195395443","rc":[{"atb":[[8.8,5.55],[5.9,21.7]],"id":40917095},{"atl":[[70,2.7],[36,2.7]],"id":40917095},{"atb":[[5.6,24.06],[8.2,6.01]],"id":42189436},{"atl":[[38,2.7],[48,2.7]],"id":42189436},{"atb":[[5.6,12.84],[4.1,38.58]],"id":42236670},{"atl":[[18,2.7],[26,4.78]],"id":42236670},{"atb":[[2.02,104.26],[3.3,25.7]],"id":42070475},{"atl":[[10.5,11.19],[8.2,6.01]],"id":42070475},{"atb":[[3.95,14.67],[2.98,60.68]],"id":41523279},{"atl":[[12.5,3.76],[15,8.58]],"id":41523279},{"atb":[[3.7,21.88],[2.2,104.45]],"id":42236682},{"atl":[[12.5,14.59]],"id":42236682},{"atb":[[4.6,29.46],[6.2,11.35]],"id":37174579},{"atl":[[25,2.7],[28,3.92]],"id":37174579}],"con":true,"img":false}]}
{"op":"mcm","clk":"5346490199","pt":1646088174978,"mc":[{"id":"1.195395443","rc":[{"atb":[[3.3,22.46]],"id":42070475}],"con":true,"img":false}]}
{"op":"mcm","clk":"5346490500","pt":1646088183905,"mc":[{"id":"1.195395443","rc":[{"atb":[[3.35,3.17]],"id":42070475}],"con":true,"img":false}]}
{"op":"mcm","clk":"5346491342","pt":1646088213739,"mc":[{"id":"1.195395443","rc":[{"spn":22.8,"spf":"NaN","id":40917095},{"spn":23.6,"spf":"NaN","id":42189436},{"spn":12.0,"spf":"NaN","id":42236670},{"atb":[[3.3,3.63]],"id":42070475},{"spn":5.85,"spf":"NaN","id":42070475}],"con":true,"img":false}]}
{"op":"mcm","clk":"5346491346","pt":1646088213840,"mc":[{"id":"1.195395443","rc":[{"atb":[[3.35,21.99]],"id":42070475}],"con":true,"img":false}]}
{"op":"mcm","clk":"5346491600","pt":1646088223020,"mc":[{"id":"1.195395443","rc":[{"atb":[[3.35,18.82]],"id":42070475}],"con":true,"img":false}]}
{"op":"mcm","clk":"5346491846","pt":1646088232038,"mc":[{"id":"1.195395443","rc":[{"atb":[[3.3,6.87]],"id":42070475}],"con":true,"img":false}]}
{"op":"mcm","clk":"5346492102","pt":1646088241842,"mc":[{"id":"1.195395443","rc":[{"atl":[[70,0]],"id":40917095},{"atl":[[48,0]],"id":42189436},{"atl":[[21,5.98]],"id":42236670},{"atl":[[12.5,0]],"id":41523279},{"atl":[[12.5,10.82]],"id":42236682},{"atl":[[25,0]],"id":37174579}],"con":true,"img":false}]}
{"op":"mcm","clk":"5346492105","pt":1646088241949,"mc":[{"id":"1.195395443","rc":[{"atl":[[44,2.7]],"id":40917095},{"atl":[[38,5.41]],"id":42189436},{"atl":[[26,0]],"id":42236670},{"atl":[[10,3.76]],"id":41523279},{"atl":[[10,3.76]],"id":42236682},{"atl":[[23,2.7]],"id":37174579}],"con":true,"img":false}]}
{"op":"mcm","clk":"5346493148","pt":1646088281285,"mc":[{"id":"1.195395443","rc":[{"atb":[[5.3,16.74]],"id":40917095},{"atb":[[5,18]],"id":42189436},{"atb":[[3.5,28.8]],"id":42236670},{"atb":[[2.24,58.06]],"id":42070475},{"atb":[[2.5,48]],"id":41523279},{"spn":7.0,"spf":"NaN","id":41523279},{"atb":[[2.46,49.32]],"id":42236682},{"spn":6.97,"spf":"NaN","id":42236682},{"atb":[[4,24]],"id":37174579}],"con":true,"img":false}]}
{"op":"mcm","clk":"5346493736","pt":1646088304949,"mc":[{"id":"1.195395443","rc":[{"atl":[[23,0]],"id":37174579}],"con":true,"img":false}]}
{"op":"mcm","clk":"5346493739","pt":1646088305054,"mc":[{"id":"1.195395443","rc":[{"atl":[[19,2.7]],"id":37174579}],"con":true,"img":false}]}
{"op":"mcm","clk":"5346494700","pt":1646088336066,"mc":[{"id":"1.195395443","rc":[{"atb":[[2.02,0],[2.26,84.4]],"id":42070475},{"atb":[[2.2,0],[2.48,84.97]],"id":42236682}],"con":true,"img":false}]}
{"op":"mcm","clk":"5346502898","pt":1646088402669,"mc":[{"id":"1.195395443","marketDefinition":{"bspMarket":true,"turnInPlayEnabled":false,"persistenceEnabled":false,"marketBaseRate":5.0,"eventId":"31270459","eventTypeId":"4339","numberOfWinners":1,"bettingType":"ODDS","marketType":"WIN","marketTime":"2022-03-01T00:12:00.000Z","suspendTime":"2022-03-01T00:12:00.000Z","bspReconciled":false,"complete":true,"inPlay":false,"crossMatching":true,"runnersVoidable":false,"numberOfActiveRunners":7,"betDelay":0,"status":"OPEN","runners":[{"status":"ACTIVE","sortPriority":1,"id":42236670,"name":"1. Nighthawk Storm"},{"status":"ACTIVE","sortPriority":2,"id":40917095,"name":"2. Goldstar Vale"},{"status":"ACTIVE","sortPriority":3,"id":42189436,"name":"3. Going Gorillas"},{"status":"ACTIVE","sortPriority":4,"id":41523279,"name":"4. Homebush Cardi"},{"status":"ACTIVE","sortPriority":5,"id":37174579,"name":"6. Yes Yes No"},{"status":"ACTIVE","sortPriority":6,"id":42070475,"name":"7. Breakpoint"},{"status":"ACTIVE","sortPriority":7,"id":42236682,"name":"8. Goldstar Brynley"}],"regulators":["MR_INT"],"venue":"Addington","countryCode":"NZ","discountAllowed":true,"timezone":"NZ","openDate":"2022-02-28T23:02:00.000Z","version":4380660677,"name":"R5 295m C1","eventName":"Addington (NZL) 1st Mar"},"rc":[{"atb":[[9.6,4.71],[8.6,10.68],[5.8,33.82],[8.2,1.4],[5.3,16.74],[7.6,18.44],[8.8,5.55],[5.9,21.7]],"id":40917095},{"atl":[[65,2.06],[130,1.53],[36,2.7],[44,2.7],[90,2.22],[46,2.93]],"id":40917095},{"spn":22.8,"spf":"NaN","id":40917095},{"atb":[[8,11.59],[5.6,24.06],[9,5.07],[9.2,1.23],[5,18],[8.2,6.01],[5.5,36.08],[7,20.29]],"id":42189436},{"atl":[[75,2.67],[38,5.41],[40,3.39],[50,2.7],[100,2]],"id":42189436},{"spn":23.6,"spf":"NaN","id":42189436},{"atb":[[5.6,12.84],[4,54.12],[5,30.44],[5.5,18.03],[4.1,38.58],[6,8.11],[4.9,2],[3.5,28.8]],"id":42236670},{"atl":[[34,6.01],[18,2.7],[18.5,7.56],[21,5.98],[22,6.29],[27,7.63]],"id":42236670},{"spn":12.0,"spf":"NaN","id":42236670},{"atb":[[2.8,90.2],[2.24,58.06],[3.35,18.82],[3.4,2],[3,60.88],[3.25,36.08],[2.26,84.4],[3.5,16.23],[3.3,6.87]],"id":42070475},{"atl":[[10.5,11.19],[8.2,6.01],[11,19.84],[13.5,15.87],[8.4,17.87],[9.4,15.74]],"id":42070475},{"spn":5.85,"spf":"NaN","id":42070475},{"atb":[[4,2],[2.5,48],[3.95,14.67],[3.7,5.85],[3.4,50.73],[2.98,60.68],[3.9,13.99],[2.96,82.83],[3.65,30.63]],"id":41523279},{"atl":[[18,11.66],[10,3.76],[10.5,13.92],[13,11.02],[15,8.58],[15.5,13.68]],"id":41523279},{"spn":7.0,"spf":"NaN","id":41523279},{"atb":[[3.95,2],[3.7,21.88],[3.4,50.73],[2.46,49.32],[3.9,13.99],[2.96,82.83],[3.65,30.63],[2.48,84.97]],"id":42236682},{"atl":[[18,11.66],[10,3.76],[10.5,13.92],[12.5,10.82],[13,11.02],[15.5,13.68]],"id":42236682},{"spn":6.97,"spf":"NaN","id":42236682},{"atb":[[4,24],[4.5,46.38],[4.6,29.46],[6.2,11.35],[5.5,27.06],[6,16.23],[7,6.76],[6.6,1.8]],"id":37174579},{"atl":[[19,2.7],[19.5,7.14],[38,5.36],[24,5.75],[28,3.92],[29,7.08]],"id":37174579},{"spn":13.0,"spf":"NaN","id":37174579}],"con":true,"img":true}]}
{"op":"mcm","clk":"5346504988","pt":1646088430393,"mc":[{"id":"1.195395443","rc":[{"atb":[[3.95,0]],"id":42236682},{"spn":13.0,"spf":"NaN","id":37174579}],"con":true,"img":false}]}
{"op":"mcm","clk":"5346504991","pt":1646088430495,"mc":[{"id":"1.195395443","rc":[{"atb":[[3.85,2]],"id":42236682}],"con":true,"img":false}]}
{"op":"mcm","clk":"5346507560","pt":1646088524716,"mc":[{"id":"1.195395443","rc":[{"atb":[[3.4,0]],"id":42070475},{"spn":6.95,"spf":"NaN","id":42236682}],"con":true,"img":false}]}
{"op":"mcm","clk":"5346507564","pt":1646088524817,"mc":[{"id":"1.195395443","rc":[{"atb":[[3.45,2]],"id":42070475}],"con":true,"img":false}]}
{"op":"mcm","clk":"5346509696","pt":1646088590308,"mc":[{"id":"1.195395443","rc":[{"atb":[[2.62,46.3]],"id":40917095},{"atb":[[2.62,46.3]],"id":42189436},{"atb":[[2.62,46.3]],"id":42236670},{"atl":[[34,13.5]],"id":42070475},{"atl":[[34,13.5]],"id":41523279},{"atl":[[34,13.5]],"id":42236682},{"atb":[[2.62,46.3]],"id":37174579}],"con":true,"img":false}]}
{"op":"mcm","clk":"5346509896","pt":1646088597908,"mc":[{"id":"1.195395443","rc":[{"atb":[[4.9,0]],"id":42236670}],"con":true,"img":false}]}
{"op":"mcm","clk":"5346509899","pt":1646088598010,"mc":[{"id":"1.195395443","rc":[{"atb":[[5.6,14.84]],"id":42236670}],"con":true,"img":false}]}
{"op":"mcm","clk":"5346510115","pt":1646088604641,"mc":[{"id":"1.195395443","rc":[{"atb":[[5.6,13.22]],"id":42236670}],"con":true,"img":false}]}
{"op":"mcm","clk":"5346510386","pt":1646088613658,"mc":[{"id":"1.195395443","rc":[{"atb":[[1.01,2.23]],"id":42236670}],"con":true,"img":false}]}
{"op":"mcm","clk":"5346510394","pt":1646088613863,"mc":[{"id":"1.195395443","rc":[{"atb":[[1.01,1.58]],"id":42236670}],"con":true,"img":false}]}
{"op":"mcm","clk":"5346510406","pt":1646088614068,"mc":[{"id":"1.195395443","rc":[{"atb":[[1.01,0]],"id":42236670}],"con":true,"img":false}]}
{"op":"mcm","clk":"5346510410","pt":1646088614170,"mc":[{"id":"1.195395443","rc":[{"atb":[[5.7,1.58]],"id":42236670}],"con":true,"img":false}]}
{"op":"mcm","clk":"5346511424","pt":1646088646378,"mc":[{"id":"1.195395443","rc":[{"atb":[[5.6,11.22]],"id":42236670}],"con":true,"img":false}]}
{"op":"mcm","clk":"5346511427","pt":1646088646478,"mc":[{"id":"1.195395443","rc":[{"atb":[[5.3,2]],"id":42236670}],"con":true,"img":false}]}
{"op":"mcm","clk":"5346511627","pt":1646088652687,"mc":[{"id":"1.195395443","rc":[{"atb":[[5.7,0]],"id":42236670}],"con":true,"img":false}]}
{"op":"mcm","clk":"5346511873","pt":1646088661717,"mc":[{"id":"1.195395443","rc":[{"atb":[[1.01,2.23]],"id":42236670}],"con":true,"img":false}]}
{"op":"mcm","clk":"5346511881","pt":1646088661921,"mc":[{"id":"1.195395443","rc":[{"atb":[[1.01,1.61]],"id":42236670}],"con":true,"img":false}]}
{"op":"mcm","clk":"5346511886","pt":1646088662129,"mc":[{"id":"1.195395443","rc":[{"atb":[[1.01,0]],"id":42236670}],"con":true,"img":false}]}
{"op":"mcm","clk":"5346511889","pt":1646088662230,"mc":[{"id":"1.195395443","rc":[{"atb":[[5.6,12.84]],"id":42236670}],"con":true,"img":false}]}
{"op":"mcm","clk":"5346513998","pt":1646088735934,"mc":[{"id":"1.195395443","rc":[{"atb":[[3.85,0]],"id":42236682}],"con":true,"img":false}]}
{"op":"mcm","clk":"5346514002","pt":1646088736037,"mc":[{"id":"1.195395443","rc":[{"atb":[[3.8,2]],"id":42236682}],"con":true,"img":false}]}
{"op":"mcm","clk":"5346518430","pt":1646088885658,"mc":[{"id":"1.195395443","rc":[{"atl":[[44,8.2]],"id":42236670},{"atl":[[18.5,8.2]],"id":41523279},{"atl":[[46,8.2]],"id":37174579}],"con":true,"img":false}]}
{"op":"mcm","clk":"5346518436","pt":1646088885759,"mc":[{"id":"1.195395443","rc":[{"atl":[[15,8.2]],"id":42070475},{"atl":[[18.5,8.2]],"id":42236682}],"con":true,"img":false}]}
{"op":"mcm","clk":"5346518527","pt":1646088888538,"mc":[{"id":"1.195395443","rc":[{"atl":[[5.6,4.05]],"id":42070475}],"con":true,"img":false}]}
{"op":"mcm","clk":"5346524425","pt":1646089102181,"mc":[{"id":"1.195395443","rc":[{"atl":[[130,9.73]],"id":40917095},{"atl":[[140,8.2]],"id":42189436},{"spn":4.55,"spf":"NaN","id":42070475}],"con":true,"img":false}]}
{"op":"mcm","clk":"5346524556","pt":1646089107985,"mc":[{"id":"1.195395443","rc":[{"spl":[[100,2]],"id":40917095},{"spl":[[100,2]],"id":42189436},{"spl":[[100,2]],"id":42236670},{"spl":[[100,2]],"id":42070475},{"spl":[[100,2]],"id":41523279},{"spl":[[100,2]],"id":42236682},{"spl":[[100,2]],"id":37174579}],"con":true,"img":false}]}
{"op":"mcm","clk":"5346534922","pt":1646089504273,"mc":[{"id":"1.195395443","rc":[{"spn":22.8,"spf":1.0,"id":40917095},{"spn":23.6,"spf":1.0,"id":42189436},{"spn":12.0,"spf":1.0,"id":42236670},{"atl":[[17,8.5]],"id":42070475},{"spn":4.55,"spf":1.0,"id":42070475},{"spn":7.0,"spf":1.0,"id":41523279},{"spn":6.95,"spf":1.0,"id":42236682},{"spn":13.0,"spf":1.0,"id":37174579}],"con":true,"img":false}]}
{"op":"mcm","clk":"5346544813","pt":1646089950122,"mc":[{"id":"1.195395443","rc":[{"atb":[[2.88,53.19]],"id":42070475},{"atl":[[11,29.84]],"id":42070475}],"con":true,"img":false}]}
{"op":"mcm","clk":"5346544820","pt":1646089950326,"mc":[{"id":"1.195395443","rc":[{"atb":[[3.85,35.09]],"id":40917095},{"atl":[[36,5.41]],"id":40917095},{"atb":[[4,33.33]],"id":42189436},{"atl":[[36,2.86]],"id":42189436},{"atb":[[3.4,41.67]],"id":42236670},{"atl":[[18,8.58]],"id":42236670},{"atb":[[2.78,48]],"id":41523279},{"atl":[[9.8,11.02]],"id":41523279},{"atb":[[3.4,92.4]],"id":42236682},{"atl":[[11.5,9.52]],"id":42236682},{"atb":[[4.9,25.64]],"id":37174579},{"atl":[[50,2.04]],"id":37174579}],"con":true,"img":false}]}
{"op":"mcm","clk":"5346545273","pt":1646089975079,"mc":[{"id":"1.195395443","rc":[{"atl":[[12,9.09]],"id":42236682}],"con":true,"img":false}]}
{"op":"mcm","clk":"5346545276","pt":1646089975181,"mc":[{"id":"1.195395443","rc":[{"atl":[[11.5,0]],"id":42236682}],"con":true,"img":false}]}
{"op":"mcm","clk":"5346545377","pt":1646089980384,"mc":[{"id":"1.195395443","rc":[{"atb":[[4,0]],"id":41523279}],"con":true,"img":false}]}
{"op":"mcm","clk":"5346545379","pt":1646089980486,"mc":[{"id":"1.195395443","rc":[{"atb":[[4.1,2]],"id":41523279}],"con":true,"img":false}]}
{"op":"mcm","clk":"5346545925","pt":1646090002625,"mc":[{"id":"1.195395443","rc":[{"atl":[[38,2.7]],"id":42189436},{"atl":[[10,0]],"id":41523279}],"con":true,"img":false}]}
{"op":"mcm","clk":"5346545930","pt":1646090002731,"mc":[{"id":"1.195395443","rc":[{"atl":[[34,2.7],[38,5.4]],"id":42189436},{"atl":[[9.6,3.76],[10,11.11]],"id":41523279}],"con":true,"img":false}]}
{"op":"mcm","clk":"5346545935","pt":1646090002834,"mc":[{"id":"1.195395443","rc":[{"atl":[[36,0]],"id":42189436},{"atl":[[9.8,0]],"id":41523279}],"con":true,"img":false}]}
{"op":"mcm","clk":"5346546370","pt":1646090022058,"mc":[{"id":"1.195395443","rc":[{"spn":21.6,"spf":1.0,"id":42189436},{"spn":6.85,"spf":1.0,"id":41523279},{"atb":[[2.98,63.32]],"id":42236682}],"con":true,"img":false}]}
{"op":"mcm","clk":"5346546372","pt":1646090022161,"mc":[{"id":"1.195395443","rc":[{"atl":[[9.6,0]],"id":41523279},{"atb":[[2.48,0]],"id":42236682},{"atb":[[4.6,0]],"id":37174579}],"con":true,"img":false}]}
{"op":"mcm","clk":"5346546374","pt":1646090022264,"mc":[{"id":"1.195395443","rc":[{"atl":[[9.8,3.76]],"id":41523279},{"atb":[[5,29.46]],"id":37174579}],"con":true,"img":false}]}
{"op":"mcm","clk":"5346546676","pt":1646090034097,"mc":[{"id":"1.195395443","rc":[{"atb":[[2.88,0],[2.98,50.51]],"id":42070475},{"atl":[[11.5,9.52]],"id":42236682}],"con":true,"img":false}]}
{"op":"mcm","clk":"5346546680","pt":1646090034198,"mc":[{"id":"1.195395443","rc":[{"atl":[[12,0]],"id":42236682}],"con":true,"img":false}]}
{"op":"mcm","clk":"5346546826","pt":1646090039114,"mc":[{"id":"1.195395443","rc":[{"atl":[[34,5.73],[38,2.7]],"id":42189436},{"atl":[[9.6,11.11],[10,0]],"id":41523279}],"con":true,"img":false}]}
{"op":"mcm","clk":"5346546827","pt":1646090039167,"mc":[{"id":"1.195395443","rc":[{"atl":[[38,5.4]],"id":42189436}],"con":true,"img":false}]}
{"op":"mcm","clk":"5346546828","pt":1646090039270,"mc":[{"id":"1.195395443","rc":[{"atl":[[34,2.7]],"id":42189436}],"con":true,"img":false}]}
{"op":"mcm","clk":"5346547991","pt":1646090084081,"mc":[{"id":"1.195395443","rc":[{"atl":[[9.8,0]],"id":41523279}],"con":true,"img":false}]}
{"op":"mcm","clk":"5346547994","pt":1646090084184,"mc":[{"id":"1.195395443","rc":[{"atl":[[9.6,0],[10,11.11],[9.4,3.76]],"id":41523279}],"con":true,"img":false}]}
{"op":"mcm","clk":"5346547996","pt":1646090084286,"mc":[{"id":"1.195395443","rc":[{"atl":[[10,0],[9.2,11.11]],"id":41523279}],"con":true,"img":false}]}
{"op":"mcm","clk":"5346548503","pt":1646090105092,"mc":[{"id":"1.195395443","rc":[{"atl":[[12.5,10.44],[15,0]],"id":41523279}],"con":true,"img":false}]}
{"op":"mcm","clk":"5346549009","pt":1646090125829,"mc":[{"id":"1.195395443","rc":[{"atl":[[9.4,0]],"id":41523279}],"con":true,"img":false}]}
{"op":"mcm","clk":"5346549011","pt":1646090125931,"mc":[{"id":"1.195395443","rc":[{"atl":[[9.2,0],[10,14.87]],"id":41523279}],"con":true,"img":false}]}
{"op":"mcm","clk":"5346549491","pt":1646090146262,"mc":[{"id":"1.195395443","rc":[{"atl":[[15,8.58]],"id":41523279},{"spn":7.05,"spf":1.0,"id":41523279}],"con":true,"img":false}]}
{"op":"mcm","clk":"5346549492","pt":1646090146364,"mc":[{"id":"1.195395443","rc":[{"atl":[[12.5,0]],"id":41523279}],"con":true,"img":false}]}
{"op":"mcm","clk":"5346549702","pt":1646090154061,"mc":[{"id":"1.195395443","rc":[{"atb":[[4,0],[3.7,37.04]],"id":42189436},{"atb":[[3.1,47.62],[3.4,0]],"id":42236670},{"atb":[[2.82,54.95],[2.98,0]],"id":42070475},{"atl":[[11.5,0],[12.5,19.52]],"id":42236682}],"con":true,"img":false}]}
{"op":"mcm","clk":"5346549705","pt":1646090154163,"mc":[{"id":"1.195395443","rc":[{"atl":[[34,5.73],[38,2.7]],"id":42189436}],"con":true,"img":false}]}
{"op":"mcm","clk":"5346549706","pt":1646090154266,"mc":[{"id":"1.195395443","rc":[{"atl":[[34,2.7],[38,5.4]],"id":42189436}],"con":true,"img":false}]}
{"op":"mcm","clk":"5346550296","pt":1646090177413,"mc":[{"id":"1.195395443","rc":[{"atl":[[10,11.11]],"id":41523279}],"con":true,"img":false}]}
{"op":"mcm","clk":"5346550297","pt":1646090177515,"mc":[{"id":"1.195395443","rc":[{"atl":[[9.8,3.76]],"id":41523279}],"con":true,"img":false}]}
{"op":"mcm","clk":"5346550298","pt":1646090177617,"mc":[{"id":"1.195395443","rc":[{"atl":[[9.6,11.11],[10,0]],"id":41523279}],"con":true,"img":false}]}
{"op":"mcm","clk":"5346551211","pt":1646090214874,"mc":[{"id":"1.195395443","rc":[{"atb":[[4,33.33],[3.7,0]],"id":42189436},{"atb":[[2.82,0],[2.96,51.02]],"id":42070475},{"spn":6.85,"spf":1.0,"id":41523279},{"atl":[[11,10],[12.5,10.82]],"id":42236682}],"con":true,"img":false}]}
{"op":"mcm","clk":"5346551212","pt":1646090214978,"mc":[{"id":"1.195395443","rc":[{"atl":[[34,5.73],[38,2.7]],"id":42189436}],"con":true,"img":false}]}
{"op":"mcm","clk":"5346551214","pt":1646090215077,"mc":[{"id":"1.195395443","rc":[{"atl":[[34,2.7],[38,5.4]],"id":42189436}],"con":true,"img":false}]}
{"op":"mcm","clk":"5346552014","pt":1646090245616,"mc":[{"id":"1.195395443","rc":[{"atl":[[9.8,0],[12.5,10.44],[15,0]],"id":41523279}],"con":true,"img":false}]}
{"op":"mcm","clk":"5346552018","pt":1646090245719,"mc":[{"id":"1.195395443","rc":[{"atl":[[9.6,0],[10,11.11],[9.4,3.76]],"id":41523279}],"con":true,"img":false}]}
{"op":"mcm","clk":"5346552020","pt":1646090245819,"mc":[{"id":"1.195395443","rc":[{"atl":[[10,0],[9.2,11.11]],"id":41523279}],"con":true,"img":false}]}
{"op":"mcm","clk":"5346552999","pt":1646090282563,"mc":[{"id":"1.195395443","rc":[{"atl":[[9.4,0]],"id":41523279},{"spn":6.65,"spf":1.0,"id":41523279}],"con":true,"img":false}]}
{"op":"mcm","clk":"5346553002","pt":1646090282664,"mc":[{"id":"1.195395443","rc":[{"atl":[[9.2,0],[10,14.87]],"id":41523279}],"con":true,"img":false}]}
{"op":"mcm","clk":"5346553953","pt":1646090323539,"mc":[{"id":"1.195395443","rc":[{"atl":[[10.5,24.45]],"id":42236682}],"con":true,"img":false}]}
{"op":"mcm","clk":"5346553954","pt":1646090323654,"mc":[{"id":"1.195395443","rc":[{"atb":[[3,110.88],[2.96,0]],"id":42070475},{"atl":[[11,0]],"id":42236682}],"con":true,"img":false}]}
{"op":"mcm","clk":"5346553966","pt":1646090324154,"mc":[{"id":"1.195395443","rc":[{"atl":[[10,11.11]],"id":41523279}],"con":true,"img":false}]}
{"op":"mcm","clk":"5346553970","pt":1646090324219,"mc":[{"id":"1.195395443","rc":[{"atl":[[9.8,3.76]],"id":41523279}],"con":true,"img":false}]}
{"op":"mcm","clk":"5346553973","pt":1646090324311,"mc":[{"id":"1.195395443","rc":[{"atl":[[9.6,11.11],[10,0]],"id":41523279}],"con":true,"img":false}]}
{"op":"mcm","clk":"5346554178","pt":1646090330922,"mc":[{"id":"1.195395443","rc":[{"atb":[[5.3,0]],"id":42236670}],"con":true,"img":false}]}
{"op":"mcm","clk":"5346554181","pt":1646090331023,"mc":[{"id":"1.195395443","rc":[{"atb":[[5.4,2]],"id":42236670}],"con":true,"img":false}]}
{"op":"mcm","clk":"5346554253","pt":1646090334048,"mc":[{"id":"1.195395443","rc":[{"atl":[[10.5,13.92],[11,10]],"id":42236682}],"con":true,"img":false}]}
{"op":"mcm","clk":"5346555522","pt":1646090374700,"mc":[{"id":"1.195395443","rc":[{"atl":[[9.8,0]],"id":41523279},{"spn":6.85,"spf":1.0,"id":41523279}],"con":true,"img":false}]}
{"op":"mcm","clk":"5346555526","pt":1646090374803,"mc":[{"id":"1.195395443","rc":[{"atl":[[10,11.11],[9.4,3.76]],"id":41523279}],"con":true,"img":false}]}
{"op":"mcm","clk":"5346555530","pt":1646090374861,"mc":[{"id":"1.195395443","rc":[{"atl":[[9.6,0]],"id":41523279}],"con":true,"img":false}]}
{"op":"mcm","clk":"5346555990","pt":1646090389024,"mc":[{"id":"1.195395443","rc":[{"atb":[[5.4,0]],"id":42236670}],"con":true,"img":false}]}
{"op":"mcm","clk":"5346555996","pt":1646090389127,"mc":[{"id":"1.195395443","rc":[{"atb":[[5.3,2]],"id":42236670}],"con":true,"img":false}]}
{"op":"mcm","clk":"5346556173","pt":1646090394013,"mc":[{"id":"1.195395443","rc":[{"atl":[[10.5,24.45],[11,0]],"id":42236682}],"con":true,"img":false}]}
{"op":"mcm","clk":"5346556418","pt":1646090400843,"mc":[{"id":"1.195395443","rc":[{"atl":[[9.4,0]],"id":41523279}],"con":true,"img":false}]}
{"op":"mcm","clk":"5346556422","pt":1646090400946,"mc":[{"id":"1.195395443","rc":[{"atl":[[9.8,3.76]],"id":41523279}],"con":true,"img":false}]}
{"op":"mcm","clk":"5346556714","pt":1646090407342,"mc":[{"id":"1.195395443","rc":[{"atl":[[9.6,11.11],[10,0]],"id":41523279}],"con":true,"img":false}]}
{"op":"mcm","clk":"5346558286","pt":1646090451675,"mc":[{"id":"1.195395443","rc":[{"atl":[[9.8,0]],"id":41523279}],"con":true,"img":false}]}
{"op":"mcm","clk":"5346558289","pt":1646090451777,"mc":[{"id":"1.195395443","rc":[{"atl":[[10,11.11],[9.4,3.76]],"id":41523279}],"con":true,"img":false}]}
{"op":"mcm","clk":"5346558292","pt":1646090451880,"mc":[{"id":"1.195395443","rc":[{"atl":[[9.6,0],[9.2,11.11]],"id":41523279}],"con":true,"img":false}]}
{"op":"mcm","clk":"5346558296","pt":1646090451981,"mc":[{"id":"1.195395443","rc":[{"atl":[[10,0]],"id":41523279}],"con":true,"img":false}]}
{"op":"mcm","clk":"5346559067","pt":1646090489966,"mc":[{"id":"1.195395443","rc":[{"atl":[[9.4,0]],"id":41523279}],"con":true,"img":false}]}
{"op":"mcm","clk":"5346559073","pt":1646090490020,"mc":[{"id":"1.195395443","rc":[{"atl":[[10,3.76]],"id":41523279}],"con":true,"img":false}]}
{"op":"mcm","clk":"5346559078","pt":1646090490126,"mc":[{"id":"1.195395443","rc":[{"atl":[[9.2,0],[10,14.87]],"id":41523279}],"con":true,"img":false}]}
{"op":"mcm","clk":"5346559777","pt":1646090513983,"mc":[{"id":"1.195395443","rc":[{"atb":[[3.85,0],[3.5,40]],"id":40917095},{"atb":[[4,0],[3.65,37.74]],"id":42189436},{"atb":[[2.8,145.76],[3,60.88]],"id":42070475},{"spn":7.05,"spf":1.0,"id":41523279},{"atb":[[3.05,48.78]],"id":42236682},{"atl":[[11.5,9.52]],"id":42236682}],"con":true,"img":false}]}
{"op":"mcm","clk":"5346559783","pt":1646090514085,"mc":[{"id":"1.195395443","rc":[{"atl":[[34,5.73],[38,2.7]],"id":42189436},{"atb":[[3.4,50.73]],"id":42236682},{"atl":[[10.5,13.92]],"id":42236682}],"con":true,"img":false}]}
{"op":"mcm","clk":"5346560387","pt":1646090542549,"mc":[{"id":"1.195395443","rc":[{"atl":[[10,11.11]],"id":41523279}],"con":true,"img":false}]}
{"op":"mcm","clk":"5346560389","pt":1646090542607,"mc":[{"id":"1.195395443","rc":[{"atl":[[9.8,3.76]],"id":41523279}],"con":true,"img":false}]}
{"op":"mcm","clk":"5346560390","pt":1646090542708,"mc":[{"id":"1.195395443","rc":[{"atl":[[9.6,11.11],[10,0]],"id":41523279}],"con":true,"img":false}]}
{"op":"mcm","clk":"5346560913","pt":1646090564238,"mc":[{"id":"1.195395443","rc":[{"atl":[[19,0]],"id":37174579}],"con":true,"img":false}]}
{"op":"mcm","clk":"5346560917","pt":1646090564343,"mc":[{"id":"1.195395443","rc":[{"atl":[[23,2.7]],"id":37174579}],"con":true,"img":false}]}
{"op":"mcm","clk":"5346562246","pt":1646090624647,"mc":[{"id":"1.195395443","rc":[{"atb":[[3.45,0]],"id":42070475},{"spn":6.85,"spf":1.0,"id":41523279},{"spn":13.25,"spf":1.0,"id":37174579}],"con":true,"img":false}]}
{"op":"mcm","clk":"5346562250","pt":1646090624749,"mc":[{"id":"1.195395443","rc":[{"atb":[[3.35,20.82]],"id":42070475}],"con":true,"img":false}]}
{"op":"mcm","clk":"5346562813","pt":1646090651027,"mc":[{"id":"1.195395443","rc":[{"spl":[[9.6,3.24]],"id":42189436}],"con":true,"img":false}]}
{"op":"mcm","clk":"5346562893","pt":1646090654821,"mc":[{"id":"1.195395443","rc":[{"atb":[[8.8,0],[5.9,0]],"id":40917095},{"atl":[[36,2.71],[44,0]],"id":40917095},{"atb":[[5.6,0],[8.2,0]],"id":42189436},{"atl":[[34,3.03],[38,0]],"id":42189436},{"atb":[[5.6,3.43],[4.1,0]],"id":42236670},{"atl":[[18,5.88],[21,0]],"id":42236670},{"atb":[[3.35,2],[2.26,0]],"id":42070475},{"atl":[[10.5,0],[8.2,0]],"id":42070475},{"atb":[[3.95,0],[2.98,0]],"id":41523279},{"atl":[[9.8,0],[12.5,0]],"id":41523279},{"atb":[[3.7,5.85],[2.98,0]],"id":42236682},{"atl":[[10,0],[12.5,0]],"id":42236682},{"atb":[[5,0],[6.2,3.03]],"id":37174579},{"atl":[[23,0],[28,0]],"id":37174579}],"con":true,"img":false}]}
{"op":"mcm","clk":"5346562900","pt":1646090655026,"mc":[{"id":"1.195395443","rc":[{"atl":[[36,0],[46,5.15]],"id":40917095},{"atl":[[34,0],[38,2.7]],"id":42189436},{"atl":[[9.6,0],[10,11.11]],"id":41523279}],"con":true,"img":false}]}
{"op":"mcm","clk":"5346563974","pt":1646090702792,"mc":[{"id":"1.195395443","rc":[{"atb":[[8.8,5.55],[5.9,21.7]],"id":40917095},{"atl":[[34,2.7],[44,2.7]],"id":40917095},{"spn":21.8,"spf":1.0,"id":40917095},{"atb":[[5.6,24.06],[8.2,6.01]],"id":42189436},{"atl":[[38,8.39]],"id":42189436},{"spn":9.4,"spf":1.0,"id":42189436},{"atb":[[5.6,12.84],[4.1,38.58]],"id":42236670},{"atl":[[18,8.58],[21,5.98]],"id":42236670},{"atb":[[3.35,20.42],[2.26,84.4]],"id":42070475},{"atl":[[10.5,11.19],[8.2,6.01]],"id":42070475},{"atb":[[3.95,14.67],[2.98,60.68]],"id":41523279},{"atl":[[9.8,4.91],[12.5,10.44]],"id":41523279},{"spn":6.95,"spf":1.0,"id":41523279},{"atb":[[3.7,21.88],[2.98,63.32]],"id":42236682},{"atl":[[10,4.81],[12.5,10.82]],"id":42236682},{"atb":[[5,26.51],[6.2,11.35]],"id":37174579},{"atl":[[23,2.7],[28,3.92]],"id":37174579}],"con":true,"img":false}]}
{"op":"mcm","clk":"5346563980","pt":1646090702998,"mc":[{"id":"1.195395443","rc":[{"atl":[[34,5.41],[46,2.93]],"id":40917095},{"atl":[[38,5.4]],"id":42189436},{"atl":[[9.6,11.11],[10,0]],"id":41523279}],"con":true,"img":false}]}
{"op":"mcm","clk":"5346563982","pt":1646090703050,"mc":[{"id":"1.195395443","rc":[{"atl":[[48,2.99]],"id":42189436}],"con":true,"img":false}]}
{"op":"mcm","clk":"5346564079","pt":1646090707408,"mc":[{"id":"1.195395443","rc":[{"atb":[[5.3,0]],"id":42236670}],"con":true,"img":false}]}
{"op":"mcm","clk":"5346564082","pt":1646090707608,"mc":[{"id":"1.195395443","rc":[{"atb":[[5.4,2]],"id":42236670}],"con":true,"img":false}]}
{"op":"mcm","clk":"5346564288","pt":1646090715113,"mc":[{"id":"1.195395443","rc":[{"atb":[[3.35,2]],"id":42070475}],"con":true,"img":false}]}
{"op":"mcm","clk":"5346564294","pt":1646090715215,"mc":[{"id":"1.195395443","rc":[{"atb":[[3.3,25.3]],"id":42070475}],"con":true,"img":false}]}
{"op":"mcm","clk":"5346564550","pt":1646090723903,"mc":[{"id":"1.195395443","rc":[{"atb":[[3.3,22.05]],"id":42070475}],"con":true,"img":false}]}
{"op":"mcm","clk":"5346564902","pt":1646090735802,"mc":[{"id":"1.195395443","rc":[{"atb":[[3.35,5.49]],"id":42070475}],"con":true,"img":false}]}
{"op":"mcm","clk":"5346565284","pt":1646090751647,"mc":[{"id":"1.195395443","rc":[{"atl":[[18,5.88]],"id":42236670},{"atb":[[3.3,3.63]],"id":42070475},{"atl":[[9.8,0]],"id":41523279}],"con":true,"img":false}]}
{"op":"mcm","clk":"5346565289","pt":1646090751750,"mc":[{"id":"1.195395443","rc":[{"atl":[[17.5,2.7]],"id":42236670},{"atb":[[3.35,23.91]],"id":42070475},{"atl":[[10,11.11],[9.4,4.91]],"id":41523279}],"con":true,"img":false}]}
{"op":"mcm","clk":"5346565294","pt":1646090751851,"mc":[{"id":"1.195395443","rc":[{"atl":[[9.6,0]],"id":41523279}],"con":true,"img":false}]}
{"op":"mcm","clk":"5346565536","pt":1646090759857,"mc":[{"id":"1.195395443","rc":[{"atb":[[3.35,20.42]],"id":42070475}],"con":true,"img":false}]}
{"op":"mcm","clk":"5346565832","pt":1646090768886,"mc":[{"id":"1.195395443","rc":[{"spn":11.75,"spf":1.0,"id":42236670},{"atb":[[3.3,7.19]],"id":42070475},{"spn":6.75,"spf":1.0,"id":41523279}],"con":true,"img":false}]}
{"op":"mcm","clk":"5346566183","pt":1646090780581,"mc":[{"id":"1.195395443","rc":[{"atl":[[9.6,11.11]],"id":41523279}],"con":true,"img":false}]}
{"op":"mcm","clk":"5346566184","pt":1646090780688,"mc":[{"id":"1.195395443","rc":[{"atl":[[10,0]],"id":41523279}],"con":true,"img":false}]}
{"op":"mcm","clk":"5346566229","pt":1646090782274,"mc":[{"id":"1.195395443","rc":[{"atl":[[48,0]],"id":42189436}],"con":true,"img":false}]}
{"op":"mcm","clk":"5346566231","pt":1646090782375,"mc":[{"id":"1.195395443","rc":[{"atl":[[38,8.39]],"id":42189436}],"con":true,"img":false}]}
{"op":"mcm","clk":"5346567508","pt":1646090826559,"mc":[{"id":"1.195395443","rc":[{"atl":[[23,0]],"id":37174579}],"con":true,"img":false}]}
{"op":"mcm","clk":"5346567510","pt":1646090826658,"mc":[{"id":"1.195395443","rc":[{"atl":[[19,2.7]],"id":37174579}],"con":true,"img":false}]}
{"op":"mcm","clk":"5346569487","pt":1646090892946,"mc":[{"id":"1.195395443","rc":[{"atl":[[38,5.4]],"id":42189436},{"spn":13.0,"spf":1.0,"id":37174579}],"con":true,"img":false}]}
{"op":"mcm","clk":"5346569491","pt":1646090893049,"mc":[{"id":"1.195395443","rc":[{"atl":[[36,2.99]],"id":42189436}],"con":true,"img":false}]}
{"op":"mcm","clk":"5346571279","pt":1646090956607,"mc":[{"id":"1.195395443","rc":[{"atl":[[38,2.7]],"id":42189436}],"con":true,"img":false}]}
{"op":"mcm","clk":"5346571282","pt":1646090956705,"mc":[{"id":"1.195395443","rc":[{"atl":[[36,5.69]],"id":42189436}],"con":true,"img":false}]}
{"op":"mcm","clk":"5346571284","pt":1646090956807,"mc":[{"id":"1.195395443","rc":[{"atl":[[34,3.03],[38,0]],"id":42189436}],"con":true,"img":false}]}
{"op":"mcm","clk":"5346571902","pt":1646090975129,"mc":[{"id":"1.195395443","rc":[{"atl":[[36,2.7]],"id":42189436}],"con":true,"img":false}]}
{"op":"mcm","clk":"5346571905","pt":1646090975229,"mc":[{"id":"1.195395443","rc":[{"atl":[[34,0],[36,5.56],[38,2.99]],"id":42189436}],"con":true,"img":false}]}
{"op":"mcm","clk":"5346572096","pt":1646090983949,"mc":[{"id":"1.195395443","rc":[{"atb":[[3.5,0],[3.75,36.36]],"id":40917095},{"atb":[[4,33.33],[3.65,0]],"id":42189436},{"atb":[[3.1,0],[3.35,42.55]],"id":42236670},{"atb":[[2.8,90.2],[3,110.88]],"id":42070475},{"atb":[[2.9,48],[2.78,0]],"id":41523279},{"atl":[[9.6,0],[9.2,11.11]],"id":41523279},{"atl":[[11.5,0],[9.8,9.52]],"id":42236682}],"con":true,"img":false}]}
{"op":"mcm","clk":"5346572101","pt":1646090984054,"mc":[{"id":"1.195395443","rc":[{"atb":[[5.4,0]],"id":42236670},{"atb":[[3.35,18.42]],"id":42070475}],"con":true,"img":false}]}
{"op":"mcm","clk":"5346572105","pt":1646090984154,"mc":[{"id":"1.195395443","rc":[{"atb":[[5.3,2]],"id":42236670},{"atb":[[3.4,2]],"id":42070475}],"con":true,"img":false}]}
{"op":"mcm","clk":"5346572496","pt":1646090995382,"mc":[{"id":"1.195395443","rc":[{"atl":[[11,19.84],[14.5,7.41]],"id":42070475},{"atb":[[2.9,0],[2.7,58.82]],"id":41523279},{"atl":[[10.5,24.45],[9.8,0]],"id":42236682}],"con":true,"img":false}]}
{"op":"mcm","clk":"5346573018","pt":1646091010490,"mc":[{"id":"1.195395443","rc":[{"atb":[[3.35,36.84],[3,60.88]],"id":42070475}],"con":true,"img":false}]}
{"op":"mcm","clk":"5346573073","pt":1646091012194,"mc":[{"id":"1.195395443","rc":[{"atb":[[3.3,3.56]],"id":42070475}],"con":true,"img":false}]}
{"op":"mcm","clk":"5346573094","pt":1646091013322,"mc":[{"id":"1.195395443","rc":[{"atl":[[9.4,0]],"id":41523279}],"con":true,"img":false}]}
{"op":"mcm","clk":"5346573096","pt":1646091013377,"mc":[{"id":"1.195395443","rc":[{"atl":[[10,4.91]],"id":41523279}],"con":true,"img":false}]}
{"op":"mcm","clk":"5346573099","pt":1646091013487,"mc":[{"id":"1.195395443","rc":[{"atl":[[9.2,0],[10,16.02]],"id":41523279}],"con":true,"img":false}]}
{"op":"mcm","clk":"5346573259","pt":1646091018415,"mc":[{"id":"1.195395443","rc":[{"atb":[[3.3,0]],"id":42070475},{"spn":7.05,"spf":1.0,"id":41523279}],"con":true,"img":false}]}
{"op":"mcm","clk":"5346573504","pt":1646091027388,"mc":[{"id":"1.195395443","rc":[{"atb":[[3.4,5.83]],"id":42070475}],"con":true,"img":false}]}
{"op":"mcm","clk":"5346573589","pt":1646091030311,"mc":[{"id":"1.195395443","rc":[{"atb":[[3.4,9.25]],"id":42070475}],"con":true,"img":false}]}
{"op":"mcm","clk":"5346573618","pt":1646091031241,"mc":[{"id":"1.195395443","rc":[{"atb":[[2.98,0],[2.48,84.97]],"id":42236682}],"con":true,"img":false}]}
{"op":"mcm","clk":"5346573622","pt":1646091031294,"mc":[{"id":"1.195395443","rc":[{"atl":[[19,0]],"id":37174579}],"con":true,"img":false}]}
{"op":"mcm","clk":"5346573625","pt":1646091031397,"mc":[{"id":"1.195395443","rc":[{"atl":[[23,2.7]],"id":37174579}],"con":true,"img":false}]}
{"op":"mcm","clk":"5346574148","pt":1646091048743,"mc":[{"id":"1.195395443","rc":[{"atb":[[3.35,18.42]],"id":42070475},{"atl":[[10,11.11]],"id":41523279}],"con":true,"img":false}]}
{"op":"mcm","clk":"5346574150","pt":1646091048848,"mc":[{"id":"1.195395443","rc":[{"atb":[[3.45,18.42]],"id":42070475},{"atl":[[9.8,4.91]],"id":41523279}],"con":true,"img":false}]}
{"op":"mcm","clk":"5346574153","pt":1646091049051,"mc":[{"id":"1.195395443","rc":[{"atl":[[9.6,11.11],[10,0]],"id":41523279}],"con":true,"img":false}]}
{"op":"mcm","clk":"5346574238","pt":1646091052361,"mc":[{"id":"1.195395443","rc":[{"atb":[[3.35,0],[3.4,43.91]],"id":42070475}],"con":true,"img":false}]}
{"op":"mcm","clk":"5346574385","pt":1646091057468,"mc":[{"id":"1.195395443","rc":[{"atb":[[3.4,40.49]],"id":42070475}],"con":true,"img":false}]}
{"op":"mcm","clk":"5346574544","pt":1646091063370,"mc":[{"id":"1.195395443","rc":[{"atb":[[3.4,36.66]],"id":42070475}],"con":true,"img":false}]}
{"op":"mcm","clk":"5346574716","pt":1646091069253,"mc":[{"id":"1.195395443","rc":[{"atb":[[3.45,22.17]],"id":42070475}],"con":true,"img":false}]}
{"op":"mcm","clk":"5346574718","pt":1646091069353,"mc":[{"id":"1.195395443","rc":[{"atb":[[3.45,25.52]],"id":42070475}],"con":true,"img":false}]}
{"op":"mcm","clk":"5346574789","pt":1646091071255,"mc":[{"id":"1.195395443","rc":[{"atb":[[4,33.33],[3.75,0]],"id":40917095}],"con":true,"img":false}]}
{"op":"mcm","clk":"5346575024","pt":1646091078470,"mc":[{"id":"1.195395443","rc":[{"atb":[[3.45,22.17]],"id":42070475},{"spn":6.85,"spf":1.0,"id":41523279},{"spn":13.25,"spf":1.0,"id":37174579}],"con":true,"img":false}]}
{"op":"mcm","clk":"5346575278","pt":1646091087384,"mc":[{"id":"1.195395443","rc":[{"atb":[[3.5,19.51]],"id":42070475}],"con":true,"img":false}]}
{"op":"mcm","clk":"5346575549","pt":1646091095992,"mc":[{"id":"1.195395443","rc":[{"atb":[[2.98,63.32],[2.48,0]],"id":42236682}],"con":true,"img":false}]}
{"op":"mcm","clk":"5346575553","pt":1646091096094,"mc":[{"id":"1.195395443","rc":[{"atl":[[9.8,0]],"id":41523279},{"atl":[[23,0]],"id":37174579}],"con":true,"img":false}]}
{"op":"mcm","clk":"5346575555","pt":1646091096200,"mc":[{"id":"1.195395443","rc":[{"atl":[[9.6,0],[10,11.11],[9.4,4.91]],"id":41523279},{"atl":[[19,2.7]],"id":37174579}],"con":true,"img":false}]}
{"op":"mcm","clk":"5346575560","pt":1646091096403,"mc":[{"id":"1.195395443","rc":[{"atl":[[10,0],[9.2,11.11]],"id":41523279}],"con":true,"img":false}]}
{"op":"mcm","clk":"5346576855","pt":1646091131752,"mc":[{"id":"1.195395443","rc":[{"atl":[[9.4,0]],"id":41523279}],"con":true,"img":false}]}
{"op":"mcm","clk":"5346576860","pt":1646091131853,"mc":[{"id":"1.195395443","rc":[{"atl":[[10,16.02]],"id":41523279}],"con":true,"img":false}]}
{"op":"mcm","clk":"5346576864","pt":1646091131906,"mc":[{"id":"1.195395443","rc":[{"atl":[[9.2,0]],"id":41523279}],"con":true,"img":false}]}
{"op":"mcm","clk":"5346577498","pt":1646091150470,"mc":[{"id":"1.195395443","rc":[{"spn":7.05,"spf":1.0,"id":41523279},{"atl":[[19,0]],"id":37174579}],"con":true,"img":false}]}
{"op":"mcm","clk":"5346577501","pt":1646091150573,"mc":[{"id":"1.195395443","rc":[{"atl":[[23,2.7]],"id":37174579}],"con":true,"img":false}]}
{"op":"mcm","clk":"5346578045","pt":1646091164691,"mc":[{"id":"1.195395443","rc":[{"atl":[[10,11.11]],"id":41523279}],"con":true,"img":false}]}
{"op":"mcm","clk":"5346578049","pt":1646091164795,"mc":[{"id":"1.195395443","rc":[{"atl":[[9.8,4.91]],"id":41523279}],"con":true,"img":false}]}
{"op":"mcm","clk":"5346578056","pt":1646091164954,"mc":[{"id":"1.195395443","rc":[{"atl":[[9.6,11.11]],"id":41523279}],"con":true,"img":false}]}
{"op":"mcm","clk":"5346578061","pt":1646091165057,"mc":[{"id":"1.195395443","rc":[{"atl":[[10,0]],"id":41523279}],"con":true,"img":false}]}
{"op":"mcm","clk":"5346578306","pt":1646091172401,"mc":[{"id":"1.195395443","rc":[{"atb":[[4,0],[3.7,37.04]],"id":40917095},{"atb":[[3.35,0],[3.05,48.78]],"id":42236670},{"atb":[[3.2,45.45],[3.4,2]],"id":42070475},{"atl":[[10.5,13.92],[11.5,9.52]],"id":42236682}],"con":true,"img":false}]}
{"op":"mcm","clk":"5346578748","pt":1646091188104,"mc":[{"id":"1.195395443","rc":[{"atb":[[3.45,3.75]],"id":42070475}],"con":true,"img":false}]}
{"op":"mcm","clk":"5346578751","pt":1646091188212,"mc":[{"id":"1.195395443","rc":[{"atb":[[3.3,18.42]],"id":42070475}],"con":true,"img":false}]}
{"op":"mcm","clk":"5346578787","pt":1646091189491,"mc":[{"id":"1.195395443","rc":[{"atb":[[3.45,0]],"id":42070475}],"con":true,"img":false}]}
{"op":"mcm","clk":"5346579014","pt":1646091195491,"mc":[{"id":"1.195395443","rc":[{"atb":[[3.3,22.41]],"id":42070475}],"con":true,"img":false}]}
{"op":"mcm","clk":"5346579016","pt":1646091195594,"mc":[{"id":"1.195395443","rc":[{"atb":[[3.5,16.23]],"id":42070475}],"con":true,"img":false}]}
{"op":"mcm","clk":"5346579351","pt":1646091205821,"mc":[{"id":"1.195395443","rc":[{"atl":[[9.8,0]],"id":41523279},{"atl":[[23,0]],"id":37174579}],"con":true,"img":false}]}
{"op":"mcm","clk":"5346579353","pt":1646091205923,"mc":[{"id":"1.195395443","rc":[{"atl":[[9.6,0],[10,11.11],[9.4,4.91]],"id":41523279},{"atl":[[19,2.7]],"id":37174579}],"con":true,"img":false}]}
{"op":"mcm","clk":"5346579598","pt":1646091213619,"mc":[{"id":"1.195395443","rc":[{"atb":[[3.35,3.49]],"id":42070475},{"spn":6.75,"spf":1.0,"id":41523279},{"spn":13.0,"spf":1.0,"id":37174579}],"con":true,"img":false}]}
{"op":"mcm","clk":"5346579846","pt":1646091222813,"mc":[{"id":"1.195395443","rc":[{"atl":[[9.4,0]],"id":41523279}],"con":true,"img":false}]}
{"op":"mcm","clk":"5346579852","pt":1646091222915,"mc":[{"id":"1.195395443","rc":[{"atl":[[9.8,4.91]],"id":41523279}],"con":true,"img":false}]}
{"op":"mcm","clk":"5346580067","pt":1646091230168,"mc":[{"id":"1.195395443","rc":[{"atl":[[9.6,11.11],[10,0]],"id":41523279}],"con":true,"img":false}]}
{"op":"mcm","clk":"5346580363","pt":1646091239252,"mc":[{"id":"1.195395443","rc":[{"atb":[[3.3,3.99]],"id":42070475}],"con":true,"img":false}]}
{"op":"mcm","clk":"5346580364","pt":1646091239356,"mc":[{"id":"1.195395443","rc":[{"atb":[[3.35,21.91]],"id":42070475}],"con":true,"img":false}]}
{"op":"mcm","clk":"5346580593","pt":1646091246763,"mc":[{"id":"1.195395443","rc":[{"atb":[[3.35,18.42]],"id":42070475}],"con":true,"img":false}]}
{"op":"mcm","clk":"5346580880","pt":1646091255703,"mc":[{"id":"1.195395443","rc":[{"atb":[[3.3,7.55]],"id":42070475}],"con":true,"img":false}]}
{"op":"mcm","clk":"5346580887","pt":1646091255757,"mc":[{"id":"1.195395443","rc":[{"atb":[[3.35,0]],"id":42070475}],"con":true,"img":false}]}
{"op":"mcm","clk":"5346580890","pt":1646091255859,"mc":[{"id":"1.195395443","rc":[{"atb":[[3.3,25.98]],"id":42070475}],"con":true,"img":false}]}
{"op":"mcm","clk":"5346581131","pt":1646091264688,"mc":[{"id":"1.195395443","rc":[{"atb":[[3.3,22.41]],"id":42070475}],"con":true,"img":false}]}
{"op":"mcm","clk":"5346581275","pt":1646091270180,"mc":[{"id":"1.195395443","rc":[{"atl":[[9.8,0]],"id":41523279}],"con":true,"img":false}]}
{"op":"mcm","clk":"5346581278","pt":1646091270281,"mc":[{"id":"1.195395443","rc":[{"atl":[[9.6,0],[10,11.11],[9.4,4.91]],"id":41523279}],"con":true,"img":false}]}
{"op":"mcm","clk":"5346581283","pt":1646091270384,"mc":[{"id":"1.195395443","rc":[{"atl":[[10,0],[9.2,11.11]],"id":41523279}],"con":true,"img":false}]}
{"op":"mcm","clk":"5346581374","pt":1646091273718,"mc":[{"id":"1.195395443","rc":[{"atb":[[3.35,3.49]],"id":42070475},{"spn":6.65,"spf":1.0,"id":41523279}],"con":true,"img":false}]}
{"op":"mcm","clk":"5346582297","pt":1646091301537,"mc":[{"id":"1.195395443","rc":[{"atb":[[3.3,3.99]],"id":42070475},{"atl":[[9.4,0]],"id":41523279}],"con":true,"img":false}]}
{"op":"mcm","clk":"5346582299","pt":1646091301639,"mc":[{"id":"1.195395443","rc":[{"atb":[[3.35,21.91]],"id":42070475},{"atl":[[10,4.91]],"id":41523279}],"con":true,"img":false}]}
{"op":"mcm","clk":"5346582302","pt":1646091301741,"mc":[{"id":"1.195395443","rc":[{"atl":[[9.2,0],[10,16.02]],"id":41523279}],"con":true,"img":false}]}
{"op":"mcm","clk":"5346582552","pt":1646091309854,"mc":[{"id":"1.195395443","rc":[{"atb":[[3.35,18.42]],"id":42070475}],"con":true,"img":false}]}
{"op":"mcm","clk":"5346582700","pt":1646091315929,"mc":[{"id":"1.195395443","rc":[{"atb":[[3.35,0]],"id":42070475}],"con":true,"img":false}]}
{"op":"mcm","clk":"5346582701","pt":1646091316033,"mc":[{"id":"1.195395443","rc":[{"atb":[[3.3,22.41]],"id":42070475}],"con":true,"img":false}]}
{"op":"mcm","clk":"5346583086","pt":1646091330353,"mc":[{"id":"1.195395443","rc":[{"atl":[[10,11.11]],"id":41523279}],"con":true,"img":false}]}
{"op":"mcm","clk":"5346583087","pt":1646091330455,"mc":[{"id":"1.195395443","rc":[{"atl":[[9.8,4.91]],"id":41523279}],"con":true,"img":false}]}
{"op":"mcm","clk":"5346583091","pt":1646091330559,"mc":[{"id":"1.195395443","rc":[{"atl":[[9.6,11.11],[10,0]],"id":41523279}],"con":true,"img":false}]}
{"op":"mcm","clk":"5346583167","pt":1646091333846,"mc":[{"id":"1.195395443","rc":[{"atb":[[3.35,3.49]],"id":42070475},{"spn":6.85,"spf":1.0,"id":41523279}],"con":true,"img":false}]}
{"op":"mcm","clk":"5346583936","pt":1646091359575,"mc":[{"id":"1.195395443","rc":[{"atb":[[3.3,3.99]],"id":42070475}],"con":true,"img":false}]}
{"op":"mcm","clk":"5346583937","pt":1646091359677,"mc":[{"id":"1.195395443","rc":[{"atb":[[3.35,21.91]],"id":42070475}],"con":true,"img":false}]}
{"op":"mcm","clk":"5346584099","pt":1646091366919,"mc":[{"id":"1.195395443","rc":[{"atb":[[3.35,18.42]],"id":42070475}],"con":true,"img":false}]}
{"op":"mcm","clk":"5346584342","pt":1646091375910,"mc":[{"id":"1.195395443","rc":[{"atb":[[3.3,7.55]],"id":42070475}],"con":true,"img":false}]}
{"op":"mcm","clk":"5346584422","pt":1646091380112,"mc":[{"id":"1.195395443","rc":[{"atl":[[9.8,0]],"id":41523279}],"con":true,"img":false}]}
{"op":"mcm","clk":"5346584423","pt":1646091380225,"mc":[{"id":"1.195395443","rc":[{"atl":[[9.6,0],[10,11.11],[9.4,4.91]],"id":41523279}],"con":true,"img":false}]}
{"op":"mcm","clk":"5346584873","pt":1646091396922,"mc":[{"id":"1.195395443","rc":[{"atl":[[9.4,0]],"id":41523279},{"spn":7.05,"spf":1.0,"id":41523279}],"con":true,"img":false}]}
{"op":"mcm","clk":"5346584875","pt":1646091397029,"mc":[{"id":"1.195395443","rc":[{"atl":[[9.8,4.91]],"id":41523279}],"con":true,"img":false}]}
{"op":"mcm","clk":"5346585045","pt":1646091402727,"mc":[{"id":"1.195395443","rc":[{"atl":[[9.6,11.11],[10,0]],"id":41523279}],"con":true,"img":false}]}
{"op":"mcm","clk":"5346586256","pt":1646091444501,"mc":[{"id":"1.195395443","rc":[{"atl":[[9.8,0]],"id":41523279}],"con":true,"img":false}]}
{"op":"mcm","clk":"5346586261","pt":1646091444603,"mc":[{"id":"1.195395443","rc":[{"atl":[[9.6,0],[10,11.11],[9.4,4.91]],"id":41523279}],"con":true,"img":false}]}
{"op":"mcm","clk":"5346586263","pt":1646091444705,"mc":[{"id":"1.195395443","rc":[{"atl":[[10,0],[9.2,11.11]],"id":41523279}],"con":true,"img":false}]}
{"op":"mcm","clk":"5346587185","pt":1646091479560,"mc":[{"id":"1.195395443","rc":[{"atl":[[9.4,0]],"id":41523279},{"spn":6.65,"spf":1.0,"id":41523279}],"con":true,"img":false}]}
{"op":"mcm","clk":"5346587188","pt":1646091479663,"mc":[{"id":"1.195395443","rc":[{"atl":[[10,4.91]],"id":41523279}],"con":true,"img":false}]}
{"op":"mcm","clk":"5346587191","pt":1646091479766,"mc":[{"id":"1.195395443","rc":[{"atl":[[9.2,0],[10,16.02]],"id":41523279}],"con":true,"img":false}]}
{"op":"mcm","clk":"5346588074","pt":1646091508373,"mc":[{"id":"1.195395443","rc":[{"atl":[[10,11.11]],"id":41523279}],"con":true,"img":false}]}
{"op":"mcm","clk":"5346588077","pt":1646091508475,"mc":[{"id":"1.195395443","rc":[{"atl":[[9.8,4.91]],"id":41523279}],"con":true,"img":false}]}
{"op":"mcm","clk":"5346588079","pt":1646091508579,"mc":[{"id":"1.195395443","rc":[{"atl":[[9.6,11.11],[10,0]],"id":41523279}],"con":true,"img":false}]}
{"op":"mcm","clk":"5346589407","pt":1646091553432,"mc":[{"id":"1.195395443","rc":[{"atl":[[9.8,0]],"id":41523279},{"spn":6.85,"spf":1.0,"id":41523279}],"con":true,"img":false}]}
{"op":"mcm","clk":"5346589412","pt":1646091553540,"mc":[{"id":"1.195395443","rc":[{"atl":[[10,11.11],[9.4,4.91]],"id":41523279}],"con":true,"img":false}]}
{"op":"mcm","clk":"5346589414","pt":1646091553641,"mc":[{"id":"1.195395443","rc":[{"atl":[[9.6,0]],"id":41523279}],"con":true,"img":false}]}
{"op":"mcm","clk":"5346589756","pt":1646091567460,"mc":[{"id":"1.195395443","rc":[{"atl":[[9.4,0]],"id":41523279}],"con":true,"img":false}]}
{"op":"mcm","clk":"5346589761","pt":1646091567560,"mc":[{"id":"1.195395443","rc":[{"atl":[[9.8,4.91]],"id":41523279}],"con":true,"img":false}]}
{"op":"mcm","clk":"5346589947","pt":1646091574378,"mc":[{"id":"1.195395443","rc":[{"atl":[[9.6,11.11],[10,0]],"id":41523279}],"con":true,"img":false}]}
{"op":"mcm","clk":"5346590220","pt":1646091583992,"mc":[{"id":"1.195395443","rc":[{"atb":[[4,33.33]],"id":40917095},{"atl":[[11.5,0]],"id":42236682}],"con":true,"img":false}]}
{"op":"mcm","clk":"5346590223","pt":1646091584094,"mc":[{"id":"1.195395443","rc":[{"atb":[[3.7,0]],"id":40917095},{"atb":[[3.2,0],[3.4,34.48]],"id":42070475},{"atl":[[10.5,24.45]],"id":42236682}],"con":true,"img":false}]}
{"op":"mcm","clk":"5346590440","pt":1646091592300,"mc":[{"id":"1.195395443","rc":[{"atb":[[3.3,3.99]],"id":42070475}],"con":true,"img":false}]}
{"op":"mcm","clk":"5346590614","pt":1646091598411,"mc":[{"id":"1.195395443","rc":[{"atb":[[3.3,0]],"id":42070475}],"con":true,"img":false}]}
{"op":"mcm","clk":"5346590783","pt":1646091604294,"mc":[{"id":"1.195395443","rc":[{"atb":[[3.45,7.09]],"id":42070475}],"con":true,"img":false}]}
{"op":"mcm","clk":"5346591363","pt":1646091625309,"mc":[{"id":"1.195395443","rc":[{"atb":[[3.35,0]],"id":42070475},{"atl":[[9.8,0]],"id":41523279}],"con":true,"img":false}]}
{"op":"mcm","clk":"5346591366","pt":1646091625410,"mc":[{"id":"1.195395443","rc":[{"atb":[[3.45,25.52]],"id":42070475},{"atl":[[10,11.11],[9.4,4.91]],"id":41523279}],"con":true,"img":false}]}
{"op":"mcm","clk":"5346591369","pt":1646091625516,"mc":[{"id":"1.195395443","rc":[{"atl":[[9.6,0]],"id":41523279}],"con":true,"img":false}]}
{"op":"mcm","clk":"5346591572","pt":1646091634345,"mc":[{"id":"1.195395443","rc":[{"atb":[[3.45,22.17]],"id":42070475}],"con":true,"img":false}]}
{"op":"mcm","clk":"5346591786","pt":1646091643353,"mc":[{"id":"1.195395443","rc":[{"atb":[[3.5,19.51]],"id":42070475}],"con":true,"img":false}]}
{"op":"mcm","clk":"5346591847","pt":1646091645463,"mc":[{"id":"1.195395443","rc":[{"atl":[[10,0],[9.2,11.11]],"id":41523279}],"con":true,"img":false}]}
{"op":"mcm","clk":"5346592055","pt":1646091654456,"mc":[{"id":"1.195395443","rc":[{"atb":[[3.3,43.48],[3.05,0]],"id":42236670},{"atb":[[3.45,61.21],[3.4,2]],"id":42070475},{"atl":[[10,15.63],[10.5,13.92]],"id":42236682}],"con":true,"img":false}]}
{"op":"mcm","clk":"5346592320","pt":1646091664571,"mc":[{"id":"1.195395443","rc":[{"atl":[[9.4,0]],"id":41523279}],"con":true,"img":false}]}
{"op":"mcm","clk":"5346592326","pt":1646091664675,"mc":[{"id":"1.195395443","rc":[{"atl":[[9.2,0],[10,16.02]],"id":41523279}],"con":true,"img":false}]}
{"op":"mcm","clk":"5346592477","pt":1646091670469,"mc":[{"id":"1.195395443","rc":[{"atb":[[3.45,57.46]],"id":42070475}],"con":true,"img":false}]}
{"op":"mcm","clk":"5346592614","pt":1646091676410,"mc":[{"id":"1.195395443","rc":[{"atb":[[3.5,23.19]],"id":42070475}],"con":true,"img":false}]}
{"op":"mcm","clk":"5346593059","pt":1646091693599,"mc":[{"id":"1.195395443","rc":[{"atl":[[10,11.11]],"id":41523279},{"spn":7.05,"spf":1.0,"id":41523279},{"atl":[[19,0]],"id":37174579},{"spn":13.25,"spf":1.0,"id":37174579}],"con":true,"img":false}]}
{"op":"mcm","clk":"5346593063","pt":1646091693703,"mc":[{"id":"1.195395443","rc":[{"atl":[[9.8,4.91]],"id":41523279},{"atl":[[23,2.7]],"id":37174579}],"con":true,"img":false}]}
{"op":"mcm","clk":"5346593069","pt":1646091693811,"mc":[{"id":"1.195395443","rc":[{"atl":[[9.6,11.11],[10,0]],"id":41523279}],"con":true,"img":false}]}
{"op":"mcm","clk":"5346593286","pt":1646091702312,"mc":[{"id":"1.195395443","rc":[{"atb":[[3.45,18.42],[3.4,43.67]],"id":42070475}],"con":true,"img":false}]}
{"op":"mcm","clk":"5346593303","pt":1646091703033,"mc":[{"id":"1.195395443","rc":[{"atl":[[10,4.81],[10.5,24.45]],"id":42236682}],"con":true,"img":false}]}
{"op":"mcm","clk":"5346593412","pt":1646091707430,"mc":[{"id":"1.195395443","rc":[{"atb":[[3.3,43.48]],"id":42070475}],"con":true,"img":false}]}
{"op":"mcm","clk":"5346593414","pt":1646091707530,"mc":[{"id":"1.195395443","rc":[{"atb":[[3.4,2]],"id":42070475}],"con":true,"img":false}]}
{"op":"mcm","clk":"5346593465","pt":1646091709634,"mc":[{"id":"1.195395443","rc":[{"atb":[[3.5,19.91]],"id":42070475}],"con":true,"img":false}]}
{"op":"mcm","clk":"5346593554","pt":1646091712756,"mc":[{"id":"1.195395443","rc":[{"atb":[[9.6,0],[8.6,0],[5.8,0],[7.6,0]],"id":40917095},{"atl":[[65,0],[130,8.2],[90,0],[46,0]],"id":40917095}],"con":true,"img":false}]}
{"op":"mcm","clk":"5346593704","pt":1646091718557,"mc":[{"id":"1.195395443","rc":[{"atb":[[3.5,16.23]],"id":42070475}],"con":true,"img":false}]}
{"op":"mcm","clk":"5346593715","pt":1646091719127,"mc":[{"id":"1.195395443","rc":[{"atb":[[9.6,4.71],[8.6,10.68],[5.8,33.82],[7.6,18.44]],"id":40917095},{"atl":[[130,9.73],[65,2.06],[90,2.22],[46,2.93]],"id":40917095}],"con":true,"img":false}]}
{"op":"mcm","clk":"5346593834","pt":1646091723549,"mc":[{"id":"1.195395443","rc":[{"atb":[[6.4,13.89],[6.8,8.62],[7.2,3.23],[6,25]],"id":40917095},{"atl":[[16.5,1.29],[17.5,3.03],[18.5,4.29],[19.5,6.76]],"id":40917095},{"atb":[[5.3,4.65],[4.9,19.23],[5.1,12.2],[4.7,33.78]],"id":42189436},{"atl":[[18,1.18],[19,2.78],[20,3.95],[22,5.95]],"id":42189436},{"atb":[[4.8,19.74],[5,42.94],[4.6,34.72],[5.2,4.76]],"id":42236670},{"atl":[[10.5,5.26],[11.5,7.14],[9.8,2.27],[12.5,10.87]],"id":42236670},{"atb":[[3.25,44.97],[3.15,23.26],[2.98,63.13],[3.05,36.59]],"id":42070475},{"atl":[[13,1.67],[14,3.85],[15,13.56],[16,8.33]],"id":42070475},{"atb":[[3.2,56.82],[3.4,71.56],[3.5,8],[3.3,32.61]],"id":42236682},{"atl":[[7.4,11.72],[6.6,3.57],[7,8.33],[7.8,18.38]],"id":42236682},{"atb":[[4.8,32.89],[5.4,4.55],[5,45.26],[5.2,11.9]],"id":37174579},{"atl":[[22,1],[24,7.92],[26,3],[28,8.55]],"id":37174579}],"con":true,"img":false}]}
{"op":"mcm","clk":"5346593838","pt":1646091723651,"mc":[{"id":"1.195395443","rc":[{"atl":[[34,2.7],[18.5,7.23]],"id":40917095},{"atl":[[36,2.7],[20,7.34]],"id":42189436},{"atl":[[18,0],[11.5,13.02]],"id":42236670},{"atb":[[3.1,35.71],[3,62.5],[3.3,8.7],[3.2,22.73]],"id":41523279},{"atl":[[7.4,19.53],[6.2,3.85],[6.6,8.93],[7,12.5]],"id":41523279}],"con":true,"img":false}]}
{"op":"mcm","clk":"5346593840","pt":1646091723753,"mc":[{"id":"1.195395443","rc":[{"atb":[[2.82,53.41],[2.7,0]],"id":41523279},{"atl":[[9.6,0],[7.2,11.11]],"id":41523279},{"atb":[[3.3,76.09],[3.05,0]],"id":42236682}],"con":true,"img":false}]}
{"op":"mcm","clk":"5346593892","pt":1646091724576,"mc":[{"id":"1.195395443","rc":[{"atb":[[3.35,3.92]],"id":42070475}],"con":true,"img":false}]}
{"op":"mcm","clk":"5346593931","pt":1646091726169,"mc":[{"id":"1.195395443","rc":[{"atb":[[3.45,0]],"id":42070475},{"atl":[[9.8,0]],"id":41523279},{"atl":[[23,0]],"id":37174579}],"con":true,"img":false}]}
{"op":"mcm","clk":"5346593933","pt":1646091726269,"mc":[{"id":"1.195395443","rc":[{"atb":[[3.35,22.34]],"id":42070475},{"atl":[[10,4.91]],"id":41523279},{"atl":[[19,2.7]],"id":37174579}],"con":true,"img":false}]}
{"op":"mcm","clk":"5346593946","pt":1646091726743,"mc":[{"id":"1.195395443","rc":[{"atb":[[3.3,0],[3.45,32.48]],"id":42070475}],"con":true,"img":false}]}
{"op":"mcm","clk":"5346594166","pt":1646091736068,"mc":[{"id":"1.195395443","rc":[{"atb":[[2.48,84.97]],"id":42236682}],"con":true,"img":false}]}
{"op":"mcm","clk":"5346594168","pt":1646091736169,"mc":[{"id":"1.195395443","rc":[{"atb":[[3.35,3.92]],"id":42070475},{"atb":[[2.98,0]],"id":42236682}],"con":true,"img":false}]}
{"op":"mcm","clk":"5346594169","pt":1646091736273,"mc":[{"id":"1.195395443","rc":[{"atb":[[3.3,18.42]],"id":42070475}],"con":true,"img":false}]}
{"op":"mcm","clk":"5346594342","pt":1646091742568,"mc":[{"id":"1.195395443","rc":[{"atb":[[3.35,0],[3.5,19.51]],"id":42070475}],"con":true,"img":false}]}
{"op":"mcm","clk":"5346594417","pt":1646091746163,"mc":[{"id":"1.195395443","rc":[{"atl":[[36,0]],"id":42189436}],"con":true,"img":false}]}
{"op":"mcm","clk":"5346594419","pt":1646091746260,"mc":[{"id":"1.195395443","rc":[{"atl":[[32,2.7]],"id":42189436}],"con":true,"img":false}]}
{"op":"mcm","clk":"5346594471","pt":1646091748669,"mc":[{"id":"1.195395443","rc":[{"atb":[[3.5,23.19]],"id":42070475}],"con":true,"img":false}]}
{"op":"mcm","clk":"5346594649","pt":1646091756209,"mc":[{"id":"1.195395443","rc":[{"atb":[[5.9,0]],"id":40917095},{"atl":[[34,0]],"id":40917095},{"spn":13.05,"spf":1.0,"id":40917095},{"spn":7.9,"spf":1.0,"id":42236670},{"spn":5.15,"spf":1.0,"id":41523279},{"spn":5.25,"spf":1.0,"id":42236682},{"spn":13.0,"spf":1.0,"id":37174579}],"con":true,"img":false}]}
{"op":"mcm","clk":"5346594652","pt":1646091756311,"mc":[{"id":"1.195395443","rc":[{"atb":[[6.2,21.7]],"id":40917095},{"atl":[[28,2.7]],"id":40917095}],"con":true,"img":false}]}
{"op":"mcm","clk":"5346595129","pt":1646091776126,"mc":[{"id":"1.195395443","rc":[{"atb":[[5,18.75]],"id":37174579}],"con":true,"img":false}]}
{"op":"mcm","clk":"5346595133","pt":1646091776231,"mc":[{"id":"1.195395443","rc":[{"atb":[[5.6,26.51]],"id":37174579}],"con":true,"img":false}]}
{"op":"mcm","clk":"5346595308","pt":1646091783306,"mc":[{"id":"1.195395443","rc":[{"atb":[[3.4,0]],"id":42070475},{"atb":[[4.1,0]],"id":41523279}],"con":true,"img":false}]}
{"op":"mcm","clk":"5346595309","pt":1646091783409,"mc":[{"id":"1.195395443","rc":[{"atb":[[3.45,34.48]],"id":42070475}],"con":true,"img":false}]}
{"op":"mcm","clk":"5346595312","pt":1646091783510,"mc":[{"id":"1.195395443","rc":[{"atb":[[4,2]],"id":41523279}],"con":true,"img":false}]}
{"op":"mcm","clk":"5346596019","pt":1646091809871,"mc":[{"id":"1.195395443","rc":[{"atb":[[2.98,0]],"id":41523279}],"con":true,"img":false}]}
{"op":"mcm","clk":"5346596022","pt":1646091809972,"mc":[{"id":"1.195395443","rc":[{"atb":[[2.84,60.68]],"id":41523279}],"con":true,"img":false}]}
{"op":"mcm","clk":"5346596221","pt":1646091816150,"mc":[{"id":"1.195395443","rc":[{"atb":[[8.8,0]],"id":40917095}],"con":true,"img":false}]}
{"op":"mcm","clk":"5346596224","pt":1646091816258,"mc":[{"id":"1.195395443","rc":[{"atb":[[7.8,5.55]],"id":40917095},{"spn":5.1,"spf":1.0,"id":41523279}],"con":true,"img":false}]}
{"op":"mcm","clk":"5346596749","pt":1646091834593,"mc":[{"id":"1.195395443","rc":[{"atl":[[18.5,4.29],[20,5.26]],"id":40917095},{"atl":[[20,3.95],[22,10.71]],"id":42189436},{"atl":[[11.5,7.14],[12,9.09]],"id":42236670},{"atb":[[3.45,2],[3.2,45.45]],"id":42070475},{"atb":[[2.82,0],[2.68,59.52]],"id":41523279},{"atl":[[7.8,14.71],[7.2,0]],"id":41523279}],"con":true,"img":false}]}
{"op":"mcm","clk":"5346596809","pt":1646091836080,"mc":[{"id":"1.195395443","rc":[{"atb":[[2.84,0]],"id":41523279}],"con":true,"img":false}]}
{"op":"mcm","clk":"5346596815","pt":1646091836181,"mc":[{"id":"1.195395443","rc":[{"atb":[[2.7,60.68]],"id":41523279}],"con":true,"img":false}]}
{"op":"mcm","clk":"5346596986","pt":1646091841718,"mc":[{"id":"1.195395443","rc":[{"atb":[[3.5,19.91]],"id":42070475}],"con":true,"img":false}]}
{"op":"mcm","clk":"5346597218","pt":1646091847891,"mc":[{"id":"1.195395443","rc":[{"atb":[[3.5,16.23]],"id":42070475}],"con":true,"img":false}]}
{"op":"mcm","clk":"5346597288","pt":1646091850718,"mc":[{"id":"1.195395443","rc":[{"atb":[[3.3,21.98]],"id":42070475}],"con":true,"img":false}]}
{"op":"mcm","clk":"5346597354","pt":1646091853696,"mc":[{"id":"1.195395443","rc":[{"atb":[[3.3,25.98]],"id":42070475}],"con":true,"img":false}]}
{"op":"mcm","clk":"5346597609","pt":1646091862731,"mc":[{"id":"1.195395443","rc":[{"atb":[[3.3,22.41]],"id":42070475}],"con":true,"img":false}]}
{"op":"mcm","clk":"5346597899","pt":1646091871612,"mc":[{"id":"1.195395443","rc":[{"atb":[[3.35,3.49]],"id":42070475}],"con":true,"img":false}]}
{"op":"mcm","clk":"5346600001","pt":1646091926088,"mc":[{"id":"1.195395443","rc":[{"atb":[[2.82,58.43],[2.26,0]],"id":42070475}],"con":true,"img":false}]}
{"op":"mcm","clk":"5346601789","pt":1646091983666,"mc":[{"id":"1.195395443","rc":[{"atb":[[3.4,24.35]],"id":42070475},{"atb":[[6.4,11.84]],"id":37174579}],"con":true,"img":false}]}
{"op":"mcm","clk":"5346602076","pt":1646091992081,"mc":[{"id":"1.195395443","rc":[{"atb":[[3.35,0]],"id":42070475},{"atb":[[6.2,9.92]],"id":37174579}],"con":true,"img":false}]}
{"op":"mcm","clk":"5346602174","pt":1646091994998,"mc":[{"id":"1.195395443","rc":[{"atb":[[3.4,0]],"id":42070475}],"con":true,"img":false}]}
{"op":"mcm","clk":"5346602266","pt":1646091997875,"mc":[{"id":"1.195395443","rc":[{"atb":[[3.35,28.41]],"id":42070475}],"con":true,"img":false}]}
{"op":"mcm","clk":"5346602365","pt":1646092000967,"mc":[{"id":"1.195395443","rc":[{"atb":[[1.01,2.23]],"id":37174579}],"con":true,"img":false}]}
{"op":"mcm","clk":"5346602368","pt":1646092001170,"mc":[{"id":"1.195395443","rc":[{"atb":[[1.01,1.46]],"id":37174579}],"con":true,"img":false}]}
{"op":"mcm","clk":"5346602372","pt":1646092001376,"mc":[{"id":"1.195395443","rc":[{"atb":[[1.01,0]],"id":37174579}],"con":true,"img":false}]}
{"op":"mcm","clk":"5346602374","pt":1646092001476,"mc":[{"id":"1.195395443","rc":[{"atb":[[6.6,3.26]],"id":37174579}],"con":true,"img":false}]}
{"op":"mcm","clk":"5346602376","pt":1646092001578,"mc":[{"id":"1.195395443","rc":[{"atb":[[3.3,18.42]],"id":42070475}],"con":true,"img":false}]}
{"op":"mcm","clk":"5346602432","pt":1646092003474,"mc":[{"id":"1.195395443","rc":[{"atb":[[6.4,0]],"id":37174579}],"con":true,"img":false}]}
{"op":"mcm","clk":"5346602511","pt":1646092006390,"mc":[{"id":"1.195395443","rc":[{"atb":[[7.2,5.07]],"id":37174579}],"con":true,"img":false}]}
{"op":"mcm","clk":"5346602606","pt":1646092010124,"mc":[{"id":"1.195395443","rc":[{"atb":[[6.6,1.8]],"id":37174579}],"con":true,"img":false}]}
{"op":"mcm","clk":"5346602672","pt":1646092012080,"mc":[{"id":"1.195395443","rc":[{"atb":[[7.2,0]],"id":37174579}],"con":true,"img":false}]}
{"op":"mcm","clk":"5346602693","pt":1646092013004,"mc":[{"id":"1.195395443","rc":[{"atb":[[3.4,3.83]],"id":42070475}],"con":true,"img":false}]}
{"op":"mcm","clk":"5346602772","pt":1646092015007,"mc":[{"id":"1.195395443","rc":[{"atb":[[3.35,0]],"id":42070475}],"con":true,"img":false}]}
{"op":"mcm","clk":"5346602775","pt":1646092015109,"mc":[{"id":"1.195395443","rc":[{"atb":[[6.4,11.84]],"id":37174579}],"con":true,"img":false}]}
{"op":"mcm","clk":"5346602852","pt":1646092017934,"mc":[{"id":"1.195395443","rc":[{"atb":[[3.55,12.17]],"id":42070475}],"con":true,"img":false}]}
{"op":"mcm","clk":"5346603332","pt":1646092031057,"mc":[{"id":"1.195395443","rc":[{"atb":[[3.3,21.98]],"id":42070475},{"atb":[[1.01,2.23]],"id":37174579}],"con":true,"img":false}]}
{"op":"mcm","clk":"5346603339","pt":1646092031218,"mc":[{"id":"1.195395443","rc":[{"atb":[[3.4,0]],"id":42070475},{"atb":[[1.01,1.46]],"id":37174579}],"con":true,"img":false}]}
{"op":"mcm","clk":"5346603343","pt":1646092031323,"mc":[{"id":"1.195395443","rc":[{"atb":[[1.01,0]],"id":37174579}],"con":true,"img":false}]}
{"op":"mcm","clk":"5346603346","pt":1646092031422,"mc":[{"id":"1.195395443","rc":[{"atb":[[6.6,3.26]],"id":37174579}],"con":true,"img":false}]}
{"op":"mcm","clk":"5346603397","pt":1646092033527,"mc":[{"id":"1.195395443","rc":[{"atb":[[3.55,0]],"id":42070475},{"atb":[[6.4,0]],"id":37174579}],"con":true,"img":false}]}
{"op":"mcm","clk":"5346603500","pt":1646092036555,"mc":[{"id":"1.195395443","rc":[{"atb":[[3.35,28.41]],"id":42070475},{"atb":[[7.2,5.07]],"id":37174579}],"con":true,"img":false}]}
{"op":"mcm","clk":"5346603523","pt":1646092037227,"mc":[{"id":"1.195395443","rc":[{"atb":[[3.3,25.98]],"id":42070475}],"con":true,"img":false}]}
{"op":"mcm","clk":"5346603628","pt":1646092040153,"mc":[{"id":"1.195395443","rc":[{"atb":[[6.6,1.8]],"id":37174579}],"con":true,"img":false}]}
{"op":"mcm","clk":"5346603687","pt":1646092042153,"mc":[{"id":"1.195395443","rc":[{"atb":[[7.2,0]],"id":37174579}],"con":true,"img":false}]}
{"op":"mcm","clk":"5346603718","pt":1646092043037,"mc":[{"id":"1.195395443","rc":[{"atb":[[3.3,22.41]],"id":42070475}],"con":true,"img":false}]}
{"op":"mcm","clk":"5346603768","pt":1646092045033,"mc":[{"id":"1.195395443","rc":[{"atb":[[6.4,11.84]],"id":37174579}],"con":true,"img":false}]}
{"op":"mcm","clk":"5346603967","pt":1646092052065,"mc":[{"id":"1.195395443","rc":[{"atb":[[3.4,3.42]],"id":42070475}],"con":true,"img":false}]}
{"op":"mcm","clk":"5346604043","pt":1646092055089,"mc":[{"id":"1.195395443","rc":[{"atb":[[3.35,0]],"id":42070475}],"con":true,"img":false}]}
{"op":"mcm","clk":"5346604052","pt":1646092055247,"mc":[{"id":"1.195395443","rc":[{"atb":[[3.3,18.42]],"id":42070475}],"con":true,"img":false}]}
{"op":"mcm","clk":"5346604121","pt":1646092057870,"mc":[{"id":"1.195395443","rc":[{"atb":[[3.55,12.17]],"id":42070475}],"con":true,"img":false}]}
{"op":"mcm","clk":"5346604216","pt":1646092061059,"mc":[{"id":"1.195395443","rc":[{"atb":[[1.01,2.23]],"id":37174579}],"con":true,"img":false}]}
{"op":"mcm","clk":"5346604221","pt":1646092061263,"mc":[{"id":"1.195395443","rc":[{"atb":[[1.01,1.46]],"id":37174579}],"con":true,"img":false}]}
{"op":"mcm","clk":"5346604226","pt":1646092061470,"mc":[{"id":"1.195395443","rc":[{"atb":[[1.01,0]],"id":37174579}],"con":true,"img":false}]}
{"op":"mcm","clk":"5346604229","pt":1646092061571,"mc":[{"id":"1.195395443","rc":[{"atb":[[6.6,3.26]],"id":37174579}],"con":true,"img":false}]}
{"op":"mcm","clk":"5346604280","pt":1646092063571,"mc":[{"id":"1.195395443","rc":[{"atb":[[6.4,0]],"id":37174579}],"con":true,"img":false}]}
{"op":"mcm","clk":"5346604291","pt":1646092064190,"mc":[{"id":"1.195395443","rc":[{"atb":[[3.4,0]],"id":42070475}],"con":true,"img":false}]}
{"op":"mcm","clk":"5346604341","pt":1646092066498,"mc":[{"id":"1.195395443","rc":[{"atb":[[3.55,0]],"id":42070475},{"atb":[[7.2,5.07]],"id":37174579}],"con":true,"img":false}]}
{"op":"mcm","clk":"5346604426","pt":1646092069368,"mc":[{"id":"1.195395443","rc":[{"atb":[[3.35,28.41]],"id":42070475}],"con":true,"img":false}]}
{"op":"mcm","clk":"5346604445","pt":1646092070085,"mc":[{"id":"1.195395443","rc":[{"atb":[[6.6,1.8]],"id":37174579}],"con":true,"img":false}]}
{"op":"mcm","clk":"5346604504","pt":1646092072397,"mc":[{"id":"1.195395443","rc":[{"atb":[[7.2,0]],"id":37174579}],"con":true,"img":false}]}
{"op":"mcm","clk":"5346604583","pt":1646092075419,"mc":[{"id":"1.195395443","rc":[{"atb":[[6.4,11.84]],"id":37174579}],"con":true,"img":false}]}
{"op":"mcm","clk":"5346604879","pt":1646092085212,"mc":[{"id":"1.195395443","rc":[{"atb":[[3.4,3.42]],"id":42070475}],"con":true,"img":false}]}
{"op":"mcm","clk":"5346604882","pt":1646092085315,"mc":[{"id":"1.195395443","rc":[{"atb":[[3.4,7.25]],"id":42070475}],"con":true,"img":false}]}
{"op":"mcm","clk":"5346604906","pt":1646092086083,"mc":[{"id":"1.195395443","rc":[{"atb":[[3.3,0]],"id":42070475}],"con":true,"img":false}]}
{"op":"mcm","clk":"5346604911","pt":1646092086186,"mc":[{"id":"1.195395443","rc":[{"atb":[[3.4,25.68]],"id":42070475}],"con":true,"img":false}]}
{"op":"mcm","clk":"5346604921","pt":1646092086700,"mc":[{"id":"1.195395443","rc":[{"atb":[[3.35,0]],"id":42070475}],"con":true,"img":false}]}
{"op":"mcm","clk":"5346605019","pt":1646092089623,"mc":[{"id":"1.195395443","rc":[{"atb":[[3.55,12.17]],"id":42070475}],"con":true,"img":false}]}
{"op":"mcm","clk":"5346605080","pt":1646092091208,"mc":[{"id":"1.195395443","rc":[{"atb":[[1.01,2.23]],"id":37174579}],"con":true,"img":false}]}
{"op":"mcm","clk":"5346605087","pt":1646092091413,"mc":[{"id":"1.195395443","rc":[{"atb":[[1.01,1.46]],"id":37174579}],"con":true,"img":false}]}
{"op":"mcm","clk":"5346605094","pt":1646092091618,"mc":[{"id":"1.195395443","rc":[{"atb":[[1.01,0]],"id":37174579}],"con":true,"img":false}]}
{"op":"mcm","clk":"5346605098","pt":1646092091721,"mc":[{"id":"1.195395443","rc":[{"atb":[[6.6,3.26]],"id":37174579}],"con":true,"img":false}]}
{"op":"mcm","clk":"5346605167","pt":1646092093826,"mc":[{"id":"1.195395443","rc":[{"atb":[[6.4,0]],"id":37174579}],"con":true,"img":false}]}
{"op":"mcm","clk":"5346605175","pt":1646092094237,"mc":[{"id":"1.195395443","rc":[{"atb":[[3.4,22.26]],"id":42070475}],"con":true,"img":false}]}
{"op":"mcm","clk":"5346605224","pt":1646092096141,"mc":[{"id":"1.195395443","rc":[{"atb":[[3.4,3.83]],"id":42070475}],"con":true,"img":false}]}
{"op":"mcm","clk":"5346605229","pt":1646092096242,"mc":[{"id":"1.195395443","rc":[{"atb":[[3.3,18.42]],"id":42070475}],"con":true,"img":false}]}
{"op":"mcm","clk":"5346605241","pt":1646092096708,"mc":[{"id":"1.195395443","rc":[{"atb":[[7.2,5.07]],"id":37174579}],"con":true,"img":false}]}
{"op":"mcm","clk":"5346605354","pt":1646092100203,"mc":[{"id":"1.195395443","rc":[{"atb":[[6.6,1.8]],"id":37174579}],"con":true,"img":false}]}
{"op":"mcm","clk":"5346605403","pt":1646092102412,"mc":[{"id":"1.195395443","rc":[{"atb":[[7.2,0]],"id":37174579}],"con":true,"img":false}]}
{"op":"mcm","clk":"5346605437","pt":1646092103436,"mc":[{"id":"1.195395443","rc":[{"atb":[[3.4,0]],"id":42070475}],"con":true,"img":false}]}
{"op":"mcm","clk":"5346605523","pt":1646092105435,"mc":[{"id":"1.195395443","rc":[{"atb":[[3.55,0]],"id":42070475},{"atb":[[6.4,11.84]],"id":37174579}],"con":true,"img":false}]}
{"op":"mcm","clk":"5346605606","pt":1646092108353,"mc":[{"id":"1.195395443","rc":[{"atb":[[3.35,28.41]],"id":42070475}],"con":true,"img":false}]}
{"op":"mcm","clk":"5346606063","pt":1646092121126,"mc":[{"id":"1.195395443","rc":[{"atb":[[1.01,2.23]],"id":37174579}],"con":true,"img":false}]}
{"op":"mcm","clk":"5346606068","pt":1646092121329,"mc":[{"id":"1.195395443","rc":[{"atb":[[1.01,1.46]],"id":37174579}],"con":true,"img":false}]}
{"op":"mcm","clk":"5346606076","pt":1646092121533,"mc":[{"id":"1.195395443","rc":[{"atb":[[3.4,3.83]],"id":42070475},{"atb":[[1.01,0]],"id":37174579}],"con":true,"img":false}]}
{"op":"mcm","clk":"5346606080","pt":1646092121636,"mc":[{"id":"1.195395443","rc":[{"atb":[[6.6,3.26]],"id":37174579}],"con":true,"img":false}]}
{"op":"mcm","clk":"5346606171","pt":1646092124144,"mc":[{"id":"1.195395443","rc":[{"atb":[[3.35,0]],"id":42070475},{"atb":[[6.4,0]],"id":37174579}],"con":true,"img":false}]}
{"op":"mcm","clk":"5346606270","pt":1646092127168,"mc":[{"id":"1.195395443","rc":[{"atb":[[3.55,12.17]],"id":42070475},{"atb":[[7.2,5.07]],"id":37174579}],"con":true,"img":false}]}
{"op":"mcm","clk":"5346606469","pt":1646092133385,"mc":[{"id":"1.195395443","rc":[{"atb":[[6.6,1.8]],"id":37174579}],"con":true,"img":false}]}
{"op":"mcm","clk":"5346606544","pt":1646092135687,"mc":[{"id":"1.195395443","rc":[{"atb":[[7.2,0]],"id":37174579}],"con":true,"img":false}]}
{"op":"mcm","clk":"5346606636","pt":1646092138560,"mc":[{"id":"1.195395443","rc":[{"atb":[[6.4,11.84]],"id":37174579}],"con":true,"img":false}]}
{"op":"mcm","clk":"5346606659","pt":1646092139379,"mc":[{"id":"1.195395443","rc":[{"atb":[[3.4,0]],"id":42070475}],"con":true,"img":false}]}
{"op":"mcm","clk":"5346606716","pt":1646092140562,"mc":[{"id":"1.195395443","rc":[{"atl":[[20,7.91]],"id":42189436}],"con":true,"img":false}]}
{"op":"mcm","clk":"5346606722","pt":1646092140668,"mc":[{"id":"1.195395443","rc":[{"atl":[[18.5,9.55],[20,0]],"id":40917095},{"atl":[[22,5.95]],"id":42189436},{"atb":[[3.45,30.42],[3.2,0]],"id":42070475},{"atb":[[2.82,54.95],[2.68,0]],"id":41523279},{"atl":[[7.8,0],[7.2,16.13]],"id":41523279}],"con":true,"img":false}]}
{"op":"mcm","clk":"5346606758","pt":1646092141386,"mc":[{"id":"1.195395443","rc":[{"atb":[[3.55,0]],"id":42070475}],"con":true,"img":false}]}
{"op":"mcm","clk":"5346606886","pt":1646092144312,"mc":[{"id":"1.195395443","rc":[{"atb":[[3.55,12.17]],"id":42070475}],"con":true,"img":false}]}
{"op":"mcm","clk":"5346606955","pt":1646092145897,"mc":[{"id":"1.195395443","rc":[{"atl":[[10.5,4.83],[9.8,0]],"id":42236670},{"trd":[[10.5,0.86],[9.8,4.54]],"ltp":10.5,"tv":5.4,"id":42236670}],"con":true,"img":false}]}
{"op":"mcm","clk":"5346606958","pt":1646092146001,"mc":[{"id":"1.195395443","rc":[{"atb":[[5.3,0]],"id":42236670},{"atl":[[12,10.78]],"id":42236670}],"con":true,"img":false}]}
{"op":"mcm","clk":"5346606962","pt":1646092146102,"mc":[{"id":"1.195395443","rc":[{"atl":[[10.5,0],[11.5,0],[12.5,0]],"id":42236670},{"atl":[[19,0]],"id":37174579}],"con":true,"img":false}]}
{"op":"mcm","clk":"5346606967","pt":1646092146205,"mc":[{"id":"1.195395443","rc":[{"atl":[[21,2.7]],"id":37174579}],"con":true,"img":false}]}
{"op":"mcm","clk":"5346607074","pt":1646092148675,"mc":[{"id":"1.195395443","rc":[{"atb":[[5.7,14.2]],"id":42236670}],"con":true,"img":false}]}
{"op":"mcm","clk":"5346607080","pt":1646092148778,"mc":[{"id":"1.195395443","rc":[{"atl":[[17.5,8.76]],"id":42236670}],"con":true,"img":false}]}
{"op":"mcm","clk":"5346607085","pt":1646092148880,"mc":[{"id":"1.195395443","rc":[{"atl":[[12,1.69]],"id":42236670}],"con":true,"img":false}]}
{"op":"mcm","clk":"5346607273","pt":1646092154312,"mc":[{"id":"1.195395443","rc":[{"atb":[[1.01,2.23]],"id":37174579}],"con":true,"img":false}]}
{"op":"mcm","clk":"5346607278","pt":1646092154516,"mc":[{"id":"1.195395443","rc":[{"atb":[[1.01,1.46]],"id":37174579}],"con":true,"img":false}]}
{"op":"mcm","clk":"5346607286","pt":1646092154721,"mc":[{"id":"1.195395443","rc":[{"atb":[[1.01,0]],"id":37174579}],"con":true,"img":false}]}
{"op":"mcm","clk":"5346607289","pt":1646092154774,"mc":[{"id":"1.195395443","rc":[{"atb":[[6.6,3.26]],"id":37174579}],"con":true,"img":false}]}
{"op":"mcm","clk":"5346607337","pt":1646092156008,"mc":[{"id":"1.195395443","rc":[{"atl":[[13,3.88]],"id":42236670}],"con":true,"img":false}]}
{"op":"mcm","clk":"5346607377","pt":1646092157283,"mc":[{"id":"1.195395443","rc":[{"atb":[[3.5,19.91]],"id":42070475}],"con":true,"img":false}]}
{"op":"mcm","clk":"5346607389","pt":1646092157795,"mc":[{"id":"1.195395443","rc":[{"atb":[[6.4,0]],"id":37174579}],"con":true,"img":false}]}
{"op":"mcm","clk":"5346607405","pt":1646092158307,"mc":[{"id":"1.195395443","rc":[{"atb":[[5.6,11.22]],"id":42236670},{"atb":[[3.5,23.19]],"id":42070475}],"con":true,"img":false}]}
{"op":"mcm","clk":"5346607479","pt":1646092160816,"mc":[{"id":"1.195395443","rc":[{"atb":[[7.2,5.07]],"id":37174579}],"con":true,"img":false}]}
{"op":"mcm","clk":"5346607570","pt":1646092163588,"mc":[{"id":"1.195395443","rc":[{"atb":[[5.6,9.41]],"id":42236670}],"con":true,"img":false}]}
{"op":"mcm","clk":"5346607679","pt":1646092166107,"mc":[{"id":"1.195395443","rc":[{"atl":[[14,5.37]],"id":42236670}],"con":true,"img":false}]}
{"op":"mcm","clk":"5346607680","pt":1646092166210,"mc":[{"id":"1.195395443","rc":[{"atl":[[14,12.93]],"id":42236670}],"con":true,"img":false}]}
{"op":"mcm","clk":"5346607686","pt":1646092166312,"mc":[{"id":"1.195395443","rc":[{"atb":[[1.01,2.23]],"id":42236670},{"atl":[[17.5,2.7]],"id":42236670},{"atb":[[6.6,1.8]],"id":37174579}],"con":true,"img":false}]}
{"op":"mcm","clk":"5346607696","pt":1646092166516,"mc":[{"id":"1.195395443","rc":[{"atb":[[1.01,1.7]],"id":42236670}],"con":true,"img":false}]}
{"op":"mcm","clk":"5346607698","pt":1646092166621,"mc":[{"id":"1.195395443","rc":[{"atb":[[1.01,0]],"id":42236670}],"con":true,"img":false}]}
{"op":"mcm","clk":"5346607702","pt":1646092166724,"mc":[{"id":"1.195395443","rc":[{"atb":[[5.8,1.7]],"id":42236670}],"con":true,"img":false}]}
{"op":"mcm","clk":"5346607745","pt":1646092168311,"mc":[{"id":"1.195395443","rc":[{"atb":[[7.2,0]],"id":37174579}],"con":true,"img":false}]}
{"op":"mcm","clk":"5346607781","pt":1646092169538,"mc":[{"id":"1.195395443","rc":[{"atb":[[5.8,3.62]],"id":42236670}],"con":true,"img":false}]}
{"op":"mcm","clk":"5346607849","pt":1646092171437,"mc":[{"id":"1.195395443","rc":[{"atb":[[5.7,0]],"id":42236670},{"atb":[[6.4,11.84]],"id":37174579}],"con":true,"img":false}]}
{"op":"mcm","clk":"5346608035","pt":1646092176095,"mc":[{"id":"1.195395443","rc":[{"atb":[[5.6,0]],"id":42236670},{"atl":[[15,8.31]],"id":42236670},{"atl":[[21,0]],"id":37174579}],"con":true,"img":false}]}
{"op":"mcm","clk":"5346608039","pt":1646092176198,"mc":[{"id":"1.195395443","rc":[{"atb":[[5.8,13.03]],"id":42236670},{"atl":[[20,2.7]],"id":37174579}],"con":true,"img":false}]}
{"op":"mcm","clk":"5346608119","pt":1646092178309,"mc":[{"id":"1.195395443","rc":[{"atb":[[5.8,11.32]],"id":42236670}],"con":true,"img":false}]}
{"op":"mcm","clk":"5346608303","pt":1646092183553,"mc":[{"id":"1.195395443","rc":[{"atb":[[7.4,3.12],[7.2,0]],"id":40917095},{"atl":[[18.5,4.29],[19,5.56]],"id":40917095},{"spn":9.0,"spf":1.0,"id":42236670},{"atb":[[3.45,2],[3.5,47.55]],"id":42070475},{"spn":4.57,"spf":1.0,"id":42070475},{"atl":[[21,1],[22,0]],"id":37174579},{"spn":13.25,"spf":1.0,"id":37174579}],"con":true,"img":false}]}
{"op":"mcm","clk":"5346608388","pt":1646092185811,"mc":[{"id":"1.195395443","rc":[{"atb":[[3.55,0]],"id":42070475}],"con":true,"img":false}]}
{"op":"mcm","clk":"5346608403","pt":1646092186121,"mc":[{"id":"1.195395443","rc":[{"atb":[[2.7,0]],"id":41523279}],"con":true,"img":false}]}
{"op":"mcm","clk":"5346608408","pt":1646092186222,"mc":[{"id":"1.195395443","rc":[{"atb":[[2.84,60.68]],"id":41523279}],"con":true,"img":false}]}
{"op":"mcm","clk":"5346608449","pt":1646092187352,"mc":[{"id":"1.195395443","rc":[{"atb":[[1.01,2.23]],"id":42236670},{"atb":[[1.01,2.23]],"id":37174579}],"con":true,"img":false}]}
{"op":"mcm","clk":"5346608452","pt":1646092187455,"mc":[{"id":"1.195395443","rc":[{"atb":[[5.8,9.41]],"id":42236670}],"con":true,"img":false}]}
{"op":"mcm","clk":"5346608457","pt":1646092187558,"mc":[{"id":"1.195395443","rc":[{"atb":[[1.01,1.78]],"id":42236670},{"atb":[[1.01,1.46]],"id":37174579}],"con":true,"img":false}]}
{"op":"mcm","clk":"5346608464","pt":1646092187762,"mc":[{"id":"1.195395443","rc":[{"atb":[[1.01,0]],"id":42236670}],"con":true,"img":false}]}
{"op":"mcm","clk":"5346608468","pt":1646092187812,"mc":[{"id":"1.195395443","rc":[{"atb":[[5.6,1.78]],"id":42236670}],"con":true,"img":false}]}
{"op":"mcm","clk":"5346608474","pt":1646092188020,"mc":[{"id":"1.195395443","rc":[{"atb":[[1.01,0]],"id":37174579}],"con":true,"img":false}]}
{"op":"mcm","clk":"5346608479","pt":1646092188123,"mc":[{"id":"1.195395443","rc":[{"atb":[[6.6,3.26]],"id":37174579}],"con":true,"img":false}]}
{"op":"mcm","clk":"5346608499","pt":1646092188738,"mc":[{"id":"1.195395443","rc":[{"atb":[[3.35,39.37]],"id":42070475}],"con":true,"img":false}]}
{"op":"mcm","clk":"5346608532","pt":1646092190117,"mc":[{"id":"1.195395443","rc":[{"atb":[[6.4,0]],"id":37174579}],"con":true,"img":false}]}
{"op":"mcm","clk":"5346608537","pt":1646092190320,"mc":[{"id":"1.195395443","rc":[{"atb":[[3.5,44.27]],"id":42070475}],"con":true,"img":false}]}
{"op":"mcm","clk":"5346608645","pt":1646092193147,"mc":[{"id":"1.195395443","rc":[{"atb":[[7.2,5.07]],"id":37174579}],"con":true,"img":false}]}
{"op":"mcm","clk":"5346608663","pt":1646092193659,"mc":[{"id":"1.195395443","rc":[{"atb":[[5.6,3.77]],"id":42236670}],"con":true,"img":false}]}
{"op":"mcm","clk":"5346608754","pt":1646092196126,"mc":[{"id":"1.195395443","rc":[{"atb":[[5.8,0]],"id":42236670}],"con":true,"img":false}]}
{"op":"mcm","clk":"5346608760","pt":1646092196227,"mc":[{"id":"1.195395443","rc":[{"atb":[[5.7,9.41]],"id":42236670}],"con":true,"img":false}]}
{"op":"mcm","clk":"5346608902","pt":1646092199360,"mc":[{"id":"1.195395443","rc":[{"atb":[[3.55,3.21]],"id":42070475},{"atb":[[6.6,1.8]],"id":37174579}],"con":true,"img":false}]}
{"op":"mcm","clk":"5346608910","pt":1646092199464,"mc":[{"id":"1.195395443","rc":[{"atb":[[3.5,40.59]],"id":42070475}],"con":true,"img":false}]}
{"op":"mcm","clk":"5346609016","pt":1646092201721,"mc":[{"id":"1.195395443","rc":[{"atb":[[3.35,0]],"id":42070475},{"atb":[[7.2,0]],"id":37174579}],"con":true,"img":false}]}
{"op":"mcm","clk":"5346609120","pt":1646092204747,"mc":[{"id":"1.195395443","rc":[{"atb":[[3.6,2.4]],"id":42070475},{"atb":[[6.4,11.84]],"id":37174579}],"con":true,"img":false}]}
{"op":"mcm","clk":"5346609178","pt":1646092206134,"mc":[{"id":"1.195395443","rc":[{"atl":[[17.5,0]],"id":42236670},{"atl":[[20,0]],"id":37174579}],"con":true,"img":false}]}
{"op":"mcm","clk":"5346609183","pt":1646092206289,"mc":[{"id":"1.195395443","rc":[{"atl":[[14.5,2.7]],"id":42236670},{"atl":[[19,2.7]],"id":37174579}],"con":true,"img":false}]}
{"op":"mcm","clk":"5346609646","pt":1646092216175,"mc":[{"id":"1.195395443","rc":[{"atb":[[5.7,0]],"id":42236670},{"atb":[[5.6,0]],"id":37174579}],"con":true,"img":false}]}
{"op":"mcm","clk":"5346609649","pt":1646092216278,"mc":[{"id":"1.195395443","rc":[{"atb":[[5.6,13.19]],"id":42236670},{"atb":[[5.3,26.51]],"id":37174579}],"con":true,"img":false}]}
{"op":"mcm","clk":"5346609812","pt":1646092220391,"mc":[{"id":"1.195395443","rc":[{"atb":[[1.01,2.23]],"id":37174579}],"con":true,"img":false}]}
{"op":"mcm","clk":"5346609824","pt":1646092220596,"mc":[{"id":"1.195395443","rc":[{"atb":[[1.01,1.46]],"id":37174579}],"con":true,"img":false}]}
{"op":"mcm","clk":"5346609828","pt":1646092220801,"mc":[{"id":"1.195395443","rc":[{"atb":[[1.01,0]],"id":37174579}],"con":true,"img":false}]}
{"op":"mcm","clk":"5346609834","pt":1646092220854,"mc":[{"id":"1.195395443","rc":[{"atb":[[6.6,3.26]],"id":37174579}],"con":true,"img":false}]}
{"op":"mcm","clk":"5346609951","pt":1646092223380,"mc":[{"id":"1.195395443","rc":[{"atb":[[6.4,0]],"id":37174579}],"con":true,"img":false}]}
{"op":"mcm","clk":"5346610083","pt":1646092226263,"mc":[{"id":"1.195395443","rc":[{"atb":[[7.2,5.07]],"id":37174579}],"con":true,"img":false}]}
{"op":"mcm","clk":"5346610282","pt":1646092230480,"mc":[{"id":"1.195395443","rc":[{"atl":[[12,0],[9.8,2.12]],"id":42236670}],"con":true,"img":false}]}
{"op":"mcm","clk":"5346610287","pt":1646092230582,"mc":[{"id":"1.195395443","rc":[{"atl":[[13,7.76],[14,5.37]],"id":42236670}],"con":true,"img":false}]}
{"op":"mcm","clk":"5346610378","pt":1646092232382,"mc":[{"id":"1.195395443","rc":[{"atb":[[6.6,1.8]],"id":37174579}],"con":true,"img":false}]}
{"op":"mcm","clk":"5346610478","pt":1646092234808,"mc":[{"id":"1.195395443","rc":[{"atb":[[7.2,0]],"id":37174579}],"con":true,"img":false}]}
{"op":"mcm","clk":"5346610593","pt":1646092237683,"mc":[{"id":"1.195395443","rc":[{"atb":[[6.4,11.84]],"id":37174579}],"con":true,"img":false}]}
{"op":"mcm","clk":"5346610709","pt":1646092240509,"mc":[{"id":"1.195395443","rc":[{"atl":[[10.5,4.9]],"id":42236670}],"con":true,"img":false}]}
{"op":"mcm","clk":"5346610902","pt":1646092245030,"mc":[{"id":"1.195395443","rc":[{"atl":[[13,3.88],[14,0],[15,0]],"id":42236670},{"spn":7.9,"spf":1.0,"id":42236670},{"spn":4.6,"spf":1.0,"id":42070475},{"spn":13.0,"spf":1.0,"id":37174579}],"con":true,"img":false}]}
{"op":"mcm","clk":"5346610940","pt":1646092246107,"mc":[{"id":"1.195395443","rc":[{"atl":[[14.5,0]],"id":42236670}],"con":true,"img":false}]}
{"op":"mcm","clk":"5346610943","pt":1646092246210,"mc":[{"id":"1.195395443","rc":[{"atl":[[18,2.7]],"id":42236670}],"con":true,"img":false}]}
{"op":"mcm","clk":"5346610976","pt":1646092247133,"mc":[{"id":"1.195395443","rc":[{"atb":[[7.4,0],[7.2,3.23]],"id":40917095},{"atl":[[16.5,0],[16,1.33]],"id":40917095}],"con":true,"img":false}]}
{"op":"mcm","clk":"5346611126","pt":1646092250519,"mc":[{"id":"1.195395443","rc":[{"atl":[[11.5,6.65]],"id":42236670}],"con":true,"img":false}]}
{"op":"mcm","clk":"5346611133","pt":1646092250621,"mc":[{"id":"1.195395443","rc":[{"atl":[[11.5,13.67]],"id":42236670}],"con":true,"img":false}]}
{"op":"mcm","clk":"5346611136","pt":1646092250724,"mc":[{"id":"1.195395443","rc":[{"atl":[[13,0]],"id":42236670}],"con":true,"img":false}]}
{"op":"mcm","clk":"5346611213","pt":1646092252517,"mc":[{"id":"1.195395443","rc":[{"atb":[[5.3,4.65]],"id":42236670},{"atl":[[21,0]],"id":37174579}],"con":true,"img":false}]}
{"op":"mcm","clk":"5346611217","pt":1646092252620,"mc":[{"id":"1.195395443","rc":[{"atb":[[5.2,0]],"id":42236670},{"atb":[[3.55,8.03],[3.5,16.23]],"id":42070475},{"atl":[[20,1.05]],"id":37174579}],"con":true,"img":false}]}
{"op":"mcm","clk":"5346611249","pt":1646092253404,"mc":[{"id":"1.195395443","rc":[{"atb":[[1.01,2.23]],"id":37174579}],"con":true,"img":false}]}
{"op":"mcm","clk":"5346611258","pt":1646092253609,"mc":[{"id":"1.195395443","rc":[{"atb":[[1.01,1.46]],"id":37174579}],"con":true,"img":false}]}
{"op":"mcm","clk":"5346611266","pt":1646092253814,"mc":[{"id":"1.195395443","rc":[{"atb":[[1.01,0]],"id":37174579}],"con":true,"img":false}]}
{"op":"mcm","clk":"5346611269","pt":1646092253918,"mc":[{"id":"1.195395443","rc":[{"atb":[[6.6,3.26]],"id":37174579}],"con":true,"img":false}]}
{"op":"mcm","clk":"5346611345","pt":1646092256130,"mc":[{"id":"1.195395443","rc":[{"atb":[[6.4,0]],"id":37174579}],"con":true,"img":false}]}
{"op":"mcm","clk":"5346611448","pt":1646092259059,"mc":[{"id":"1.195395443","rc":[{"atb":[[7.2,5.07]],"id":37174579}],"con":true,"img":false}]}
{"op":"mcm","clk":"5346611468","pt":1646092259518,"mc":[{"id":"1.195395443","rc":[{"atb":[[3.55,4.82]],"id":42070475}],"con":true,"img":false}]}
{"op":"mcm","clk":"5346611576","pt":1646092262457,"mc":[{"id":"1.195395443","rc":[{"atb":[[6.6,1.8]],"id":37174579}],"con":true,"img":false}]}
{"op":"mcm","clk":"5346611589","pt":1646092262612,"mc":[{"id":"1.195395443","rc":[{"atl":[[12.5,10.12]],"id":42236670},{"atl":[[22,2.38]],"id":37174579}],"con":true,"img":false}]}
{"op":"mcm","clk":"5346611687","pt":1646092264615,"mc":[{"id":"1.195395443","rc":[{"atb":[[7.2,0]],"id":37174579}],"con":true,"img":false}]}
{"op":"mcm","clk":"5346611798","pt":1646092267540,"mc":[{"id":"1.195395443","rc":[{"atb":[[6.4,11.84]],"id":37174579}],"con":true,"img":false}]}
{"op":"mcm","clk":"5346611884","pt":1646092269436,"mc":[{"id":"1.195395443","rc":[{"atl":[[28,3.92]],"id":37174579}],"con":true,"img":false}]}
{"op":"mcm","clk":"5346611966","pt":1646092271343,"mc":[{"id":"1.195395443","rc":[{"atb":[[3.3,21.98]],"id":42070475}],"con":true,"img":false}]}
{"op":"mcm","clk":"5346612010","pt":1646092272582,"mc":[{"id":"1.195395443","rc":[{"atl":[[24,9.01]],"id":37174579}],"con":true,"img":false}]}
{"op":"mcm","clk":"5346612233","pt":1646092278638,"mc":[{"id":"1.195395443","rc":[{"atl":[[15.5,1.38]],"id":40917095}],"con":true,"img":false}]}
{"op":"mcm","clk":"5346612240","pt":1646092278740,"mc":[{"id":"1.195395443","rc":[{"atl":[[16,0],[18.5,9.85],[19,0]],"id":40917095},{"atl":[[18,0],[18.5,1.14]],"id":42189436},{"atl":[[10,2.07],[9.8,0]],"id":42236670}],"con":true,"img":false}]}
{"op":"mcm","clk":"5346612245","pt":1646092278843,"mc":[{"id":"1.195395443","rc":[{"atl":[[18.5,3.92],[20,3.95]],"id":42189436}],"con":true,"img":false}]}
{"op":"mcm","clk":"5346612344","pt":1646092282379,"mc":[{"id":"1.195395443","rc":[{"atl":[[16,1.33],[15.5,0]],"id":40917095},{"atb":[[5.3,0],[5.5,40.52]],"id":42189436},{"atl":[[11.5,1.9],[13,0]],"id":42070475},{"atb":[[3.1,0],[3.3,0],[3.05,9.76],[3.2,0]],"id":41523279},{"atb":[[5.4,0],[5.1,4.88]],"id":37174579}],"con":true,"img":false}]}
{"op":"mcm","clk":"5346612392","pt":1646092283460,"mc":[{"id":"1.195395443","rc":[{"atb":[[1.01,2.23]],"id":37174579}],"con":true,"img":false}]}
{"op":"mcm","clk":"5346612398","pt":1646092283561,"mc":[{"id":"1.195395443","rc":[{"atb":[[1.01,1.46]],"id":37174579}],"con":true,"img":false}]}
{"op":"mcm","clk":"5346612402","pt":1646092283664,"mc":[{"id":"1.195395443","rc":[{"atb":[[1.01,0]],"id":37174579}],"con":true,"img":false}]}
{"op":"mcm","clk":"5346612407","pt":1646092283766,"mc":[{"id":"1.195395443","rc":[{"atb":[[6.6,3.26]],"id":37174579}],"con":true,"img":false}]}
{"op":"mcm","clk":"5346612413","pt":1646092283971,"mc":[{"id":"1.195395443","rc":[{"atl":[[18.5,1.14],[20,9.21]],"id":42189436}],"con":true,"img":false}]}
{"op":"mcm","clk":"5346612508","pt":1646092285974,"mc":[{"id":"1.195395443","rc":[{"atb":[[6.4,0]],"id":37174579}],"con":true,"img":false}]}
{"op":"mcm","clk":"5346612600","pt":1646092288743,"mc":[{"id":"1.195395443","rc":[{"atl":[[11,4.65]],"id":42236670}],"con":true,"img":false}]}
{"op":"mcm","clk":"5346612608","pt":1646092288948,"mc":[{"id":"1.195395443","rc":[{"atb":[[7.2,5.07]],"id":37174579}],"con":true,"img":false}]}
{"op":"mcm","clk":"5346612750","pt":1646092292390,"mc":[{"id":"1.195395443","rc":[{"atb":[[5.3,11.63]],"id":42189436},{"atl":[[19.5,2.7]],"id":42189436},{"atl":[[12.5,4.35]],"id":42070475},{"atb":[[2.98,25.25]],"id":41523279},{"atb":[[4.9,38.46],[5.2,0]],"id":37174579},{"atl":[[26,5]],"id":37174579}],"con":true,"img":false}]}
{"op":"mcm","clk":"5346612755","pt":1646092292493,"mc":[{"id":"1.195395443","rc":[{"atb":[[6.6,1.8]],"id":37174579}],"con":true,"img":false}]}
{"op":"mcm","clk":"5346612848","pt":1646092294797,"mc":[{"id":"1.195395443","rc":[{"atb":[[7.2,0]],"id":37174579}],"con":true,"img":false}]}
{"op":"mcm","clk":"5346612866","pt":1646092295364,"mc":[{"id":"1.195395443","rc":[{"atb":[[4.7,0]],"id":42189436},{"atl":[[19,0],[20,5.26],[22,0]],"id":42189436},{"atl":[[10.5,0],[11.5,7.02],[12.5,0]],"id":42236670},{"atl":[[14,0],[15,8.2],[16,0]],"id":42070475}],"con":true,"img":false}]}
{"op":"mcm","clk":"5346612892","pt":1646092296081,"mc":[{"id":"1.195395443","rc":[{"atb":[[5.3,0]],"id":37174579}],"con":true,"img":false}]}
{"op":"mcm","clk":"5346612897","pt":1646092296184,"mc":[{"id":"1.195395443","rc":[{"atb":[[5.6,26.51]],"id":37174579}],"con":true,"img":false}]}
{"op":"mcm","clk":"5346612955","pt":1646092297674,"mc":[{"id":"1.195395443","rc":[{"atb":[[6.4,11.84]],"id":37174579}],"con":true,"img":false}]}
{"op":"mcm","clk":"5346612993","pt":1646092298754,"mc":[{"id":"1.195395443","rc":[{"atl":[[12,6.35]],"id":42236670}],"con":true,"img":false}]}
{"op":"mcm","clk":"5346613018","pt":1646092299576,"mc":[{"id":"1.195395443","rc":[{"atl":[[6.8,3.45],[6.6,0]],"id":42236682},{"atl":[[19.5,8.22]],"id":37174579}],"con":true,"img":false}]}
{"op":"mcm","clk":"5346613021","pt":1646092299681,"mc":[{"id":"1.195395443","rc":[{"atl":[[20,0]],"id":37174579}],"con":true,"img":false}]}
{"op":"mcm","clk":"5346613103","pt":1646092301890,"mc":[{"id":"1.195395443","rc":[{"atb":[[3.3,25.98]],"id":42070475}],"con":true,"img":false}]}
{"op":"mcm","clk":"5346613118","pt":1646092302403,"mc":[{"id":"1.195395443","rc":[{"atb":[[5.1,18.29]],"id":42189436},{"atl":[[21,3.75]],"id":42189436},{"atl":[[13.5,21.87]],"id":42070475},{"atb":[[2.94,38.66]],"id":41523279}],"con":true,"img":false}]}
{"op":"mcm","clk":"5346613367","pt":1646092308762,"mc":[{"id":"1.195395443","rc":[{"spn":12.8,"spf":1.0,"id":40917095},{"atl":[[13,9.69]],"id":42236670},{"spn":8.0,"spf":1.0,"id":42236670},{"spn":5.35,"spf":1.0,"id":42236682}],"con":true,"img":false}]}
{"op":"mcm","clk":"5346613398","pt":1646092309580,"mc":[{"id":"1.195395443","rc":[{"atl":[[7.2,8.06]],"id":42236682},{"atb":[[4.7,20.27]],"id":37174579}],"con":true,"img":false}]}
{"op":"mcm","clk":"5346613431","pt":1646092310501,"mc":[{"id":"1.195395443","rc":[{"atb":[[3.3,22.41]],"id":42070475}],"con":true,"img":false}]}
{"op":"mcm","clk":"5346613490","pt":1646092312406,"mc":[{"id":"1.195395443","rc":[{"atb":[[4.9,32.05]],"id":42189436},{"atl":[[23,5.68]],"id":42189436},{"atl":[[14.5,16.67]],"id":42070475},{"atb":[[2.9,65.79]],"id":41523279}],"con":true,"img":false}]}
{"op":"mcm","clk":"5346613542","pt":1646092313689,"mc":[{"id":"1.195395443","rc":[{"atb":[[1.01,2.23]],"id":37174579}],"con":true,"img":false}]}
{"op":"mcm","clk":"5346613544","pt":1646092313792,"mc":[{"id":"1.195395443","rc":[{"atb":[[1.01,1.46]],"id":37174579}],"con":true,"img":false}]}
{"op":"mcm","clk":"5346613552","pt":1646092313998,"mc":[{"id":"1.195395443","rc":[{"atb":[[1.01,0]],"id":37174579}],"con":true,"img":false}]}
{"op":"mcm","clk":"5346613560","pt":1646092314100,"mc":[{"id":"1.195395443","rc":[{"atb":[[6.6,3.26]],"id":37174579}],"con":true,"img":false}]}
{"op":"mcm","clk":"5346613631","pt":1646092316215,"mc":[{"id":"1.195395443","rc":[{"atb":[[6.4,0]],"id":37174579}],"con":true,"img":false}]}
{"op":"mcm","clk":"5346613725","pt":1646092319100,"mc":[{"id":"1.195395443","rc":[{"atb":[[7.2,5.07]],"id":37174579}],"con":true,"img":false}]}
{"op":"mcm","clk":"5346613739","pt":1646092319513,"mc":[{"id":"1.195395443","rc":[{"atb":[[3.35,3.49]],"id":42070475}],"con":true,"img":false}]}
{"op":"mcm","clk":"5346613744","pt":1646092319615,"mc":[{"id":"1.195395443","rc":[{"atl":[[7.4,0],[7.8,0],[7.6,11.36],[7,0]],"id":42236682},{"atb":[[4.8,0],[4.5,82.09],[5,0]],"id":37174579}],"con":true,"img":false}]}
{"op":"mcm","clk":"5346613752","pt":1646092319922,"mc":[{"id":"1.195395443","rc":[{"atb":[[3,0]],"id":41523279}],"con":true,"img":false}]}
{"op":"mcm","clk":"5346613855","pt":1646092323215,"mc":[{"id":"1.195395443","rc":[{"atl":[[6.6,3.57]],"id":42236682}],"con":true,"img":false}]}
{"op":"mcm","clk":"5346613935","pt":1646092325604,"mc":[{"id":"1.195395443","rc":[{"atb":[[6.6,1.8]],"id":37174579}],"con":true,"img":false}]}
{"op":"mcm","clk":"5346613943","pt":1646092325913,"mc":[{"id":"1.195395443","rc":[{"atb":[[1.01,2.53]],"id":42236670}],"con":true,"img":false}]}
{"op":"mcm","clk":"5346613950","pt":1646092326118,"mc":[{"id":"1.195395443","rc":[{"atb":[[1.01,1.69]],"id":42236670}],"con":true,"img":false}]}
{"op":"mcm","clk":"5346613953","pt":1646092326221,"mc":[{"id":"1.195395443","rc":[{"atl":[[28,0]],"id":37174579}],"con":true,"img":false}]}
{"op":"mcm","clk":"5346613955","pt":1646092326324,"mc":[{"id":"1.195395443","rc":[{"atb":[[1.01,0]],"id":42236670},{"atl":[[25,3.92]],"id":37174579}],"con":true,"img":false}]}
{"op":"mcm","clk":"5346613959","pt":1646092326427,"mc":[{"id":"1.195395443","rc":[{"atb":[[6.2,1.69]],"id":42236670}],"con":true,"img":false}]}
{"op":"mcm","clk":"5346613997","pt":1646092327816,"mc":[{"id":"1.195395443","rc":[{"atb":[[7.2,0]],"id":37174579}],"con":true,"img":false}]}
{"op":"mcm","clk":"5346614086","pt":1646092330694,"mc":[{"id":"1.195395443","rc":[{"atb":[[6.4,11.84]],"id":37174579}],"con":true,"img":false}]}
{"op":"mcm","clk":"5346614164","pt":1646092333214,"mc":[{"id":"1.195395443","rc":[{"atl":[[7,8.33]],"id":42236682}],"con":true,"img":false}]}
{"op":"mcm","clk":"5346614510","pt":1646092343242,"mc":[{"id":"1.195395443","rc":[{"atl":[[7.4,11.72]],"id":42236682}],"con":true,"img":false}]}
{"op":"mcm","clk":"5346614514","pt":1646092343343,"mc":[{"id":"1.195395443","rc":[{"atl":[[6.8,0],[7.2,0],[7.6,0]],"id":42236682}],"con":true,"img":false}]}
{"op":"mcm","clk":"5346614591","pt":1646092345341,"mc":[{"id":"1.195395443","rc":[{"atb":[[2.84,0]],"id":41523279}],"con":true,"img":false}]}
{"op":"mcm","clk":"5346614593","pt":1646092345444,"mc":[{"id":"1.195395443","rc":[{"atb":[[2.96,143.51]],"id":41523279}],"con":true,"img":false}]}
{"op":"mcm","clk":"5346614629","pt":1646092346621,"mc":[{"id":"1.195395443","rc":[{"atb":[[1.01,2.23]],"id":37174579}],"con":true,"img":false}]}
{"op":"mcm","clk":"5346614635","pt":1646092346827,"mc":[{"id":"1.195395443","rc":[{"atb":[[1.01,1.46]],"id":37174579}],"con":true,"img":false}]}
{"op":"mcm","clk":"5346614642","pt":1646092347034,"mc":[{"id":"1.195395443","rc":[{"atb":[[1.01,0]],"id":37174579}],"con":true,"img":false}]}
{"op":"mcm","clk":"5346614647","pt":1646092347136,"mc":[{"id":"1.195395443","rc":[{"atb":[[6.6,3.26]],"id":37174579}],"con":true,"img":false}]}
{"op":"mcm","clk":"5346614721","pt":1646092349244,"mc":[{"id":"1.195395443","rc":[{"atb":[[6.4,0]],"id":37174579}],"con":true,"img":false}]}
{"op":"mcm","clk":"5346614815","pt":1646092352121,"mc":[{"id":"1.195395443","rc":[{"atb":[[7.2,5.07]],"id":37174579}],"con":true,"img":false}]}
{"op":"mcm","clk":"5346614863","pt":1646092353250,"mc":[{"id":"1.195395443","rc":[{"atl":[[7.8,18.38]],"id":42236682}],"con":true,"img":false}]}
{"op":"mcm","clk":"5346614903","pt":1646092354279,"mc":[{"id":"1.195395443","rc":[{"atl":[[10,0],[11,1.86]],"id":42236670}],"con":true,"img":false}]}
{"op":"mcm","clk":"5346614911","pt":1646092354431,"mc":[{"id":"1.195395443","rc":[{"atl":[[12,15.23]],"id":42236670}],"con":true,"img":false}]}
{"op":"mcm","clk":"5346614915","pt":1646092354534,"mc":[{"id":"1.195395443","rc":[{"atl":[[11.5,0]],"id":42236670}],"con":true,"img":false}]}
{"op":"mcm","clk":"5346614966","pt":1646092355663,"mc":[{"id":"1.195395443","rc":[{"atb":[[6.6,1.8]],"id":37174579}],"con":true,"img":false}]}
{"op":"mcm","clk":"5346615000","pt":1646092356637,"mc":[{"id":"1.195395443","rc":[{"atl":[[10,2.07]],"id":42236670}],"con":true,"img":false}]}
{"op":"mcm","clk":"5346615039","pt":1646092357770,"mc":[{"id":"1.195395443","rc":[{"atb":[[7.2,0]],"id":37174579}],"con":true,"img":false}]}
{"op":"mcm","clk":"5346615092","pt":1646092359460,"mc":[{"id":"1.195395443","rc":[{"atb":[[6.4,11.84]],"id":37174579}],"con":true,"img":false}]}
{"op":"mcm","clk":"5346615390","pt":1646092366660,"mc":[{"id":"1.195395443","rc":[{"atl":[[11,4.65]],"id":42236670}],"con":true,"img":false}]}
{"op":"mcm","clk":"5346615789","pt":1646092376679,"mc":[{"id":"1.195395443","rc":[{"spn":8.1,"spf":1.0,"id":42236670},{"spn":5.25,"spf":1.0,"id":42236682},{"atb":[[1.01,2.23]],"id":37174579}],"con":true,"img":false}]}
{"op":"mcm","clk":"5346615792","pt":1646092376782,"mc":[{"id":"1.195395443","rc":[{"atb":[[1.01,1.46]],"id":37174579}],"con":true,"img":false}]}
{"op":"mcm","clk":"5346615795","pt":1646092376885,"mc":[{"id":"1.195395443","rc":[{"atb":[[1.01,0]],"id":37174579}],"con":true,"img":false}]}
{"op":"mcm","clk":"5346615799","pt":1646092376988,"mc":[{"id":"1.195395443","rc":[{"atb":[[6.6,3.26]],"id":37174579}],"con":true,"img":false}]}
{"op":"mcm","clk":"5346615888","pt":1646092379513,"mc":[{"id":"1.195395443","rc":[{"atb":[[6.4,0]],"id":37174579}],"con":true,"img":false}]}
{"op":"mcm","clk":"5346616004","pt":1646092382394,"mc":[{"id":"1.195395443","rc":[{"atb":[[7.2,5.07]],"id":37174579}],"con":true,"img":false}]}
{"op":"mcm","clk":"5346616174","pt":1646092386195,"mc":[{"id":"1.195395443","rc":[{"atb":[[2.96,82.83]],"id":41523279}],"con":true,"img":false}]}
{"op":"mcm","clk":"5346616180","pt":1646092386300,"mc":[{"id":"1.195395443","rc":[{"atb":[[2.98,85.93]],"id":41523279}],"con":true,"img":false}]}
{"op":"mcm","clk":"5346616276","pt":1646092388715,"mc":[{"id":"1.195395443","rc":[{"atb":[[6.6,1.8]],"id":37174579}],"con":true,"img":false}]}
{"op":"mcm","clk":"5346616369","pt":1646092390923,"mc":[{"id":"1.195395443","rc":[{"atb":[[7.2,0]],"id":37174579}],"con":true,"img":false}]}
{"op":"mcm","clk":"5346616471","pt":1646092393805,"mc":[{"id":"1.195395443","rc":[{"atb":[[6.4,11.84]],"id":37174579}],"con":true,"img":false}]}
{"op":"mcm","clk":"5346617045","pt":1646092409712,"mc":[{"id":"1.195395443","rc":[{"atb":[[1.01,2.23]],"id":37174579}],"con":true,"img":false}]}
{"op":"mcm","clk":"5346617054","pt":1646092409920,"mc":[{"id":"1.195395443","rc":[{"atb":[[1.01,1.46]],"id":37174579}],"con":true,"img":false}]}
{"op":"mcm","clk":"5346617058","pt":1646092410022,"mc":[{"id":"1.195395443","rc":[{"atb":[[1.01,0]],"id":37174579}],"con":true,"img":false}]}
{"op":"mcm","clk":"5346617062","pt":1646092410124,"mc":[{"id":"1.195395443","rc":[{"atb":[[6.6,3.26]],"id":37174579}],"con":true,"img":false}]}
{"op":"mcm","clk":"5346617155","pt":1646092412335,"mc":[{"id":"1.195395443","rc":[{"atb":[[6.4,0]],"id":37174579}],"con":true,"img":false}]}
{"op":"mcm","clk":"5346617270","pt":1646092415219,"mc":[{"id":"1.195395443","rc":[{"atb":[[7.2,5.07]],"id":37174579}],"con":true,"img":false}]}
{"op":"mcm","clk":"5346617418","pt":1646092418853,"mc":[{"id":"1.195395443","rc":[{"atb":[[6.6,1.8]],"id":37174579}],"con":true,"img":false}]}
{"op":"mcm","clk":"5346617524","pt":1646092421059,"mc":[{"id":"1.195395443","rc":[{"atb":[[7.2,0]],"id":37174579}],"con":true,"img":false}]}
{"op":"mcm","clk":"5346617622","pt":1646092423939,"mc":[{"id":"1.195395443","rc":[{"atb":[[6.4,11.84]],"id":37174579}],"con":true,"img":false}]}
{"op":"mcm","clk":"5346618144","pt":1646092439879,"mc":[{"id":"1.195395443","rc":[{"atb":[[1.01,2.23]],"id":37174579}],"con":true,"img":false}]}
{"op":"mcm","clk":"5346618148","pt":1646092439984,"mc":[{"id":"1.195395443","rc":[{"atb":[[1.01,1.46]],"id":37174579}],"con":true,"img":false}]}
{"op":"mcm","clk":"5346618153","pt":1646092440087,"mc":[{"id":"1.195395443","rc":[{"atb":[[1.01,0]],"id":37174579}],"con":true,"img":false}]}
{"op":"mcm","clk":"5346618157","pt":1646092440189,"mc":[{"id":"1.195395443","rc":[{"atb":[[6.6,3.26]],"id":37174579}],"con":true,"img":false}]}
{"op":"mcm","clk":"5346618200","pt":1646092441589,"mc":[{"id":"1.195395443","rc":[{"atb":[[7.4,3.12],[7.2,0]],"id":40917095},{"atl":[[16,0],[17,1.25]],"id":40917095},{"atl":[[18.5,0],[18,1.18]],"id":42189436},{"atl":[[10,0],[9.8,2.12]],"id":42236670}],"con":true,"img":false}]}
{"op":"mcm","clk":"5346618203","pt":1646092441690,"mc":[{"id":"1.195395443","rc":[{"atl":[[11.5,9.52],[12,6.34]],"id":42236670}],"con":true,"img":false}]}
{"op":"mcm","clk":"5346618204","pt":1646092441792,"mc":[{"id":"1.195395443","rc":[{"atl":[[11.5,0],[12,15.44]],"id":42236670}],"con":true,"img":false}]}
{"op":"mcm","clk":"5346618220","pt":1646092442462,"mc":[{"id":"1.195395443","rc":[{"atb":[[6.4,0]],"id":37174579}],"con":true,"img":false}]}
{"op":"mcm","clk":"5346618239","pt":1646092443182,"mc":[{"id":"1.195395443","rc":[{"atl":[[21,5]],"id":40917095},{"atb":[[2.82,0]],"id":41523279},{"atl":[[7.2,0]],"id":41523279}],"con":true,"img":false}]}
{"op":"mcm","clk":"5346618243","pt":1646092443287,"mc":[{"id":"1.195395443","rc":[{"atl":[[18.5,4.29]],"id":40917095},{"atl":[[12,6.35],[12.5,8.7]],"id":42236670},{"atb":[[3.55,0],[3.3,45.67]],"id":42070475},{"atb":[[2.62,61.73]],"id":41523279},{"atl":[[7.4,35.15]],"id":41523279}],"con":true,"img":false}]}
{"op":"mcm","clk":"5346618301","pt":1646092445493,"mc":[{"id":"1.195395443","rc":[{"atb":[[3.6,0]],"id":42070475},{"atb":[[7.2,5.07]],"id":37174579}],"con":true,"img":false}]}
{"op":"mcm","clk":"5346618410","pt":1646092448370,"mc":[{"id":"1.195395443","rc":[{"atb":[[3.4,24.35]],"id":42070475}],"con":true,"img":false}]}
{"op":"mcm","clk":"5346618426","pt":1646092448887,"mc":[{"id":"1.195395443","rc":[{"atb":[[6.6,1.8]],"id":37174579}],"con":true,"img":false}]}
{"op":"mcm","clk":"5346618512","pt":1646092451194,"mc":[{"id":"1.195395443","rc":[{"atb":[[7.2,0]],"id":37174579}],"con":true,"img":false}]}
{"op":"mcm","clk":"5346618522","pt":1646092451604,"mc":[{"id":"1.195395443","rc":[{"atl":[[18,2.94]],"id":40917095}],"con":true,"img":false}]}
{"op":"mcm","clk":"5346618614","pt":1646092454076,"mc":[{"id":"1.195395443","rc":[{"atb":[[6.4,11.84]],"id":37174579}],"con":true,"img":false}]}
{"op":"mcm","clk":"5346618653","pt":1646092454900,"mc":[{"id":"1.195395443","rc":[{"atb":[[3.35,0]],"id":42070475}],"con":true,"img":false}]}
{"op":"mcm","clk":"5346618709","pt":1646092456289,"mc":[{"id":"1.195395443","rc":[{"atl":[[17.5,0],[18.5,0],[19.5,0]],"id":40917095}],"con":true,"img":false}]}
{"op":"mcm","clk":"5346618730","pt":1646092456904,"mc":[{"id":"1.195395443","rc":[{"atb":[[3.4,0]],"id":42070475}],"con":true,"img":false}]}
{"op":"mcm","clk":"5346618841","pt":1646092459884,"mc":[{"id":"1.195395443","rc":[{"atb":[[3.35,28.41]],"id":42070475}],"con":true,"img":false}]}
{"op":"mcm","clk":"5346618903","pt":1646092461621,"mc":[{"id":"1.195395443","rc":[{"atl":[[19,4.17]],"id":40917095}],"con":true,"img":false}]}
{"op":"mcm","clk":"5346619075","pt":1646092466108,"mc":[{"id":"1.195395443","rc":[{"atb":[[3.3,27.25]],"id":42070475}],"con":true,"img":false}]}
{"op":"mcm","clk":"5346619079","pt":1646092466213,"mc":[{"id":"1.195395443","rc":[{"atb":[[3.4,18.42]],"id":42070475}],"con":true,"img":false}]}
{"op":"mcm","clk":"5346619145","pt":1646092468424,"mc":[{"id":"1.195395443","rc":[{"atb":[[3.35,0]],"id":42070475}],"con":true,"img":false}]}
{"op":"mcm","clk":"5346619188","pt":1646092469910,"mc":[{"id":"1.195395443","rc":[{"atb":[[1.01,2.23]],"id":37174579}],"con":true,"img":false}]}
{"op":"mcm","clk":"5346619193","pt":1646092470113,"mc":[{"id":"1.195395443","rc":[{"atb":[[1.01,1.46]],"id":37174579}],"con":true,"img":false}]}
{"op":"mcm","clk":"5346619198","pt":1646092470419,"mc":[{"id":"1.195395443","rc":[{"atb":[[1.01,0]],"id":37174579}],"con":true,"img":false}]}
{"op":"mcm","clk":"5346619201","pt":1646092470523,"mc":[{"id":"1.195395443","rc":[{"atb":[[6.6,3.26]],"id":37174579}],"con":true,"img":false}]}
{"op":"mcm","clk":"5346619225","pt":1646092471291,"mc":[{"id":"1.195395443","rc":[{"atb":[[3.55,12.17]],"id":42070475}],"con":true,"img":false}]}
{"op":"mcm","clk":"5346619234","pt":1646092471598,"mc":[{"id":"1.195395443","rc":[{"atl":[[20,6.58]],"id":40917095}],"con":true,"img":false}]}
{"op":"mcm","clk":"5346619279","pt":1646092472830,"mc":[{"id":"1.195395443","rc":[{"atb":[[6.4,0]],"id":37174579}],"con":true,"img":false}]}
{"op":"mcm","clk":"5346619377","pt":1646092475701,"mc":[{"id":"1.195395443","rc":[{"atb":[[7.2,5.07]],"id":37174579}],"con":true,"img":false}]}
{"op":"mcm","clk":"5346619558","pt":1646092482002,"mc":[{"id":"1.195395443","rc":[{"atb":[[6.6,1.8]],"id":37174579}],"con":true,"img":false}]}
{"op":"mcm","clk":"5346619615","pt":1646092484207,"mc":[{"id":"1.195395443","rc":[{"atb":[[7.2,0]],"id":37174579}],"con":true,"img":false}]}
{"op":"mcm","clk":"5346619638","pt":1646092484924,"mc":[{"id":"1.195395443","rc":[{"atb":[[3.35,3.49]],"id":42070475}],"con":true,"img":false}]}
{"op":"mcm","clk":"5346619677","pt":1646092486105,"mc":[{"id":"1.195395443","rc":[{"atb":[[3.4,0]],"id":42070475}],"con":true,"img":false}]}
{"op":"mcm","clk":"5346619682","pt":1646092486212,"mc":[{"id":"1.195395443","rc":[{"atb":[[3.35,21.91]],"id":42070475}],"con":true,"img":false}]}
{"op":"mcm","clk":"5346619713","pt":1646092487232,"mc":[{"id":"1.195395443","rc":[{"atb":[[6.4,11.84]],"id":37174579}],"con":true,"img":false}]}
{"op":"mcm","clk":"5346619753","pt":1646092488719,"mc":[{"id":"1.195395443","rc":[{"atb":[[3.55,0]],"id":42070475}],"con":true,"img":false}]}
{"op":"mcm","clk":"5346619819","pt":1646092491549,"mc":[{"id":"1.195395443","rc":[{"atb":[[3.4,24.35]],"id":42070475}],"con":true,"img":false}]}
{"op":"mcm","clk":"5346619941","pt":1646092496158,"mc":[{"id":"1.195395443","rc":[{"atb":[[2.98,25.25]],"id":41523279}],"con":true,"img":false}]}
{"op":"mcm","clk":"5346619948","pt":1646092496260,"mc":[{"id":"1.195395443","rc":[{"atb":[[2.96,143.51]],"id":41523279}],"con":true,"img":false}]}
{"op":"mcm","clk":"5346620073","pt":1646092500060,"mc":[{"id":"1.195395443","rc":[{"spn":13.3,"spf":1.0,"id":40917095},{"spn":8.0,"spf":1.0,"id":42236670},{"atb":[[3.35,18.42]],"id":42070475},{"spn":4.55,"spf":1.0,"id":42070475}],"con":true,"img":false}]}
{"op":"mcm","clk":"5346620175","pt":1646092503063,"mc":[{"id":"1.195395443","rc":[{"atb":[[1.01,2.23]],"id":37174579}],"con":true,"img":false}]}
{"op":"mcm","clk":"5346620181","pt":1646092503267,"mc":[{"id":"1.195395443","rc":[{"atb":[[1.01,1.46]],"id":37174579}],"con":true,"img":false}]}
{"op":"mcm","clk":"5346620186","pt":1646092503473,"mc":[{"id":"1.195395443","rc":[{"atb":[[1.01,0]],"id":37174579}],"con":true,"img":false}]}
{"op":"mcm","clk":"5346620189","pt":1646092503576,"mc":[{"id":"1.195395443","rc":[{"atb":[[6.6,3.26]],"id":37174579}],"con":true,"img":false}]}
{"op":"mcm","clk":"5346620249","pt":1646092506042,"mc":[{"id":"1.195395443","rc":[{"atb":[[6.4,0]],"id":37174579}],"con":true,"img":false}]}
{"op":"mcm","clk":"5346620252","pt":1646092506146,"mc":[{"id":"1.195395443","rc":[{"atb":[[3.35,0]],"id":42070475}],"con":true,"img":false}]}
{"op":"mcm","clk":"5346620256","pt":1646092506247,"mc":[{"id":"1.195395443","rc":[{"atb":[[3.45,20.42]],"id":42070475}],"con":true,"img":false}]}
{"op":"mcm","clk":"5346620325","pt":1646092508975,"mc":[{"id":"1.195395443","rc":[{"atb":[[3.4,0]],"id":42070475},{"atb":[[7.2,5.07]],"id":37174579}],"con":true,"img":false}]}
{"op":"mcm","clk":"5346620330","pt":1646092509073,"mc":[{"id":"1.195395443","rc":[{"atb":[[3.45,23.76]],"id":42070475}],"con":true,"img":false}]}
{"op":"mcm","clk":"5346620442","pt":1646092511844,"mc":[{"id":"1.195395443","rc":[{"atb":[[3.55,12.17]],"id":42070475}],"con":true,"img":false}]}
{"op":"mcm","clk":"5346620533","pt":1646092515076,"mc":[{"id":"1.195395443","rc":[{"atb":[[6.6,1.8]],"id":37174579}],"con":true,"img":false}]}
{"op":"mcm","clk":"5346620563","pt":1646092515955,"mc":[{"id":"1.195395443","rc":[{"atb":[[7.4,0],[7.2,3.23]],"id":40917095},{"atl":[[19,9.17],[21,0]],"id":40917095},{"atb":[[3.5,40.59],[3.3,3.99]],"id":42070475},{"atb":[[2.62,0],[2.78,54.86]],"id":41523279},{"atl":[[7.4,19.53],[7,25.28]],"id":41523279},{"atl":[[6.8,3.45],[6.6,0]],"id":42236682}],"con":true,"img":false}]}
{"op":"mcm","clk":"5346620570","pt":1646092516158,"mc":[{"id":"1.195395443","rc":[{"atb":[[3.45,5.34]],"id":42070475}],"con":true,"img":false}]}
{"op":"mcm","clk":"5346620574","pt":1646092516261,"mc":[{"id":"1.195395443","rc":[{"atb":[[3.3,22.41]],"id":42070475}],"con":true,"img":false}]}
{"op":"mcm","clk":"5346620615","pt":1646092517694,"mc":[{"id":"1.195395443","rc":[{"atb":[[7.2,0]],"id":37174579}],"con":true,"img":false}]}
{"op":"mcm","clk":"5346620628","pt":1646092518156,"mc":[{"id":"1.195395443","rc":[{"atb":[[3.45,2]],"id":42070475}],"con":true,"img":false}]}
{"op":"mcm","clk":"5346620704","pt":1646092520565,"mc":[{"id":"1.195395443","rc":[{"atb":[[3.55,0]],"id":42070475},{"atb":[[6.4,11.84]],"id":37174579}],"con":true,"img":false}]}
{"op":"mcm","clk":"5346620784","pt":1646092523491,"mc":[{"id":"1.195395443","rc":[{"atb":[[3.35,39.37]],"id":42070475}],"con":true,"img":false}]}
{"op":"mcm","clk":"5346620842","pt":1646092525997,"mc":[{"id":"1.195395443","rc":[{"atl":[[7.2,8.06]],"id":42236682}],"con":true,"img":false}]}
{"op":"mcm","clk":"5346620908","pt":1646092528400,"mc":[{"id":"1.195395443","rc":[{"atl":[[7.4,0],[7.8,0],[7,0]],"id":42236682}],"con":true,"img":false}]}
{"op":"mcm","clk":"5346621179","pt":1646092535994,"mc":[{"id":"1.195395443","rc":[{"atl":[[7.6,11.36]],"id":42236682}],"con":true,"img":false}]}
{"op":"mcm","clk":"5346621183","pt":1646092536091,"mc":[{"id":"1.195395443","rc":[{"atb":[[3.55,3.21],[3.3,3.99]],"id":42070475},{"atb":[[1.01,2.23]],"id":37174579}],"con":true,"img":false}]}
{"op":"mcm","clk":"5346621190","pt":1646092536193,"mc":[{"id":"1.195395443","rc":[{"atb":[[3.4,18.42]],"id":42070475}],"con":true,"img":false}]}
{"op":"mcm","clk":"5346621196","pt":1646092536298,"mc":[{"id":"1.195395443","rc":[{"atb":[[1.01,1.46]],"id":37174579}],"con":true,"img":false}]}
{"op":"mcm","clk":"5346621203","pt":1646092536603,"mc":[{"id":"1.195395443","rc":[{"atb":[[1.01,0]],"id":37174579}],"con":true,"img":false}]}
{"op":"mcm","clk":"5346621210","pt":1646092536705,"mc":[{"id":"1.195395443","rc":[{"atb":[[6.6,3.26]],"id":37174579}],"con":true,"img":false}]}
{"op":"mcm","clk":"5346621254","pt":1646092537682,"mc":[{"id":"1.195395443","rc":[{"atb":[[3.35,0]],"id":42070475}],"con":true,"img":false}]}
{"op":"mcm","clk":"5346621315","pt":1646092539066,"mc":[{"id":"1.195395443","rc":[{"atb":[[6.4,0]],"id":37174579}],"con":true,"img":false}]}
{"op":"mcm","clk":"5346621366","pt":1646092540607,"mc":[{"id":"1.195395443","rc":[{"atb":[[3.6,2.4]],"id":42070475}],"con":true,"img":false}]}
{"op":"mcm","clk":"5346621419","pt":1646092542096,"mc":[{"id":"1.195395443","rc":[{"atb":[[7.2,5.07]],"id":37174579}],"con":true,"img":false}]}
{"op":"mcm","clk":"5346621534","pt":1646092545993,"mc":[{"id":"1.195395443","rc":[{"atl":[[8,17.86]],"id":42236682}],"con":true,"img":false}]}
{"op":"mcm","clk":"5346621540","pt":1646092546197,"mc":[{"id":"1.195395443","rc":[{"atb":[[3.4,0]],"id":42070475}],"con":true,"img":false}]}
{"op":"mcm","clk":"5346621544","pt":1646092546302,"mc":[{"id":"1.195395443","rc":[{"atb":[[3.3,22.41]],"id":42070475}],"con":true,"img":false}]}
{"op":"mcm","clk":"5346621623","pt":1646092548200,"mc":[{"id":"1.195395443","rc":[{"atb":[[6.6,1.8]],"id":37174579}],"con":true,"img":false}]}
{"op":"mcm","clk":"5346621708","pt":1646092550717,"mc":[{"id":"1.195395443","rc":[{"atb":[[7.2,0]],"id":37174579}],"con":true,"img":false}]}
{"op":"mcm","clk":"5346621857","pt":1646092554619,"mc":[{"id":"1.195395443","rc":[{"atb":[[6.4,11.84]],"id":37174579}],"con":true,"img":false}]}
{"op":"mcm","clk":"5346622042","pt":1646092560109,"mc":[{"id":"1.195395443","rc":[{"atl":[[17,0],[17.5,1.21]],"id":40917095},{"spn":13.55,"spf":1.0,"id":40917095},{"atl":[[10.5,1.96],[9.8,0]],"id":42236670},{"spn":8.35,"spf":1.0,"id":42236670},{"spn":4.6,"spf":1.0,"id":42070475},{"atb":[[2.98,0],[2.94,0],[3.05,0],[2.92,10.42]],"id":41523279},{"atb":[[3.4,59.06],[3.5,0]],"id":42236682},{"spn":5.35,"spf":1.0,"id":42236682}],"con":true,"img":false}]}
{"op":"mcm","clk":"5346622047","pt":1646092560211,"mc":[{"id":"1.195395443","rc":[{"atl":[[18,8.82],[19,4.17]],"id":40917095},{"atl":[[12,15.05],[12.5,0]],"id":42236670}],"con":true,"img":false}]}
{"op":"mcm","clk":"5346622205","pt":1646092565337,"mc":[{"id":"1.195395443","rc":[{"atl":[[18,2.94],[19,9.73]],"id":40917095}],"con":true,"img":false}]}
{"op":"mcm","clk":"5346622236","pt":1646092566106,"mc":[{"id":"1.195395443","rc":[{"atb":[[2.96,82.83]],"id":41523279}],"con":true,"img":false}]}
{"op":"mcm","clk":"5346622241","pt":1646092566207,"mc":[{"id":"1.195395443","rc":[{"atb":[[2.92,71.1]],"id":41523279}],"con":true,"img":false}]}
{"op":"mcm","clk":"5346622401","pt":1646092570119,"mc":[{"id":"1.195395443","rc":[{"atl":[[18.5,2.86]],"id":40917095},{"atl":[[11.5,4.43]],"id":42236670},{"atb":[[2.88,26.6]],"id":41523279},{"atb":[[3.3,65.22]],"id":42236682}],"con":true,"img":false}]}
{"op":"mcm","clk":"5346622548","pt":1646092575151,"mc":[{"id":"1.195395443","rc":[{"atb":[[1.01,2.23]],"id":37174579}],"con":true,"img":false}]}
{"op":"mcm","clk":"5346622556","pt":1646092575359,"mc":[{"id":"1.195395443","rc":[{"atb":[[1.01,1.46]],"id":37174579}],"con":true,"img":false}]}
{"op":"mcm","clk":"5346622561","pt":1646092575562,"mc":[{"id":"1.195395443","rc":[{"atb":[[1.01,0]],"id":37174579}],"con":true,"img":false}]}
{"op":"mcm","clk":"5346622566","pt":1646092575665,"mc":[{"id":"1.195395443","rc":[{"atb":[[6.6,3.26]],"id":37174579}],"con":true,"img":false}]}
{"op":"mcm","clk":"5346622571","pt":1646092575869,"mc":[{"id":"1.195395443","rc":[{"atb":[[3.3,18.42]],"id":42070475}],"con":true,"img":false}]}
{"op":"mcm","clk":"5346622588","pt":1646092576541,"mc":[{"id":"1.195395443","rc":[{"atl":[[11,0],[12,8.7],[13,0]],"id":42236670}],"con":true,"img":false}]}
{"op":"mcm","clk":"5346622591","pt":1646092576650,"mc":[{"id":"1.195395443","rc":[{"atl":[[18,0],[19,5.56],[20,0]],"id":40917095}],"con":true,"img":false}]}
{"op":"mcm","clk":"5346622616","pt":1646092577571,"mc":[{"id":"1.195395443","rc":[{"atb":[[6.4,0]],"id":37174579}],"con":true,"img":false}]}
{"op":"mcm","clk":"5346622678","pt":1646092580138,"mc":[{"id":"1.195395443","rc":[{"atl":[[19.5,4.05]],"id":40917095},{"atl":[[12.5,6.07]],"id":42236670},{"atb":[[2.84,40.76]],"id":41523279},{"atb":[[3.2,34.09]],"id":42236682}],"con":true,"img":false}]}
{"op":"mcm","clk":"5346622686","pt":1646092580446,"mc":[{"id":"1.195395443","rc":[{"atb":[[7.2,5.07]],"id":37174579}],"con":true,"img":false}]}
{"op":"mcm","clk":"5346622719","pt":1646092581368,"mc":[{"id":"1.195395443","rc":[{"atb":[[3.55,6.81]],"id":42070475}],"con":true,"img":false}]}
{"op":"mcm","clk":"5346622793","pt":1646092584243,"mc":[{"id":"1.195395443","rc":[{"atb":[[6.6,1.8]],"id":37174579}],"con":true,"img":false}]}
{"op":"mcm","clk":"5346622853","pt":1646092586237,"mc":[{"id":"1.195395443","rc":[{"atb":[[7.2,0]],"id":37174579}],"con":true,"img":false}]}
{"op":"mcm","clk":"5346622930","pt":1646092589068,"mc":[{"id":"1.195395443","rc":[{"atb":[[6.4,11.84]],"id":37174579}],"con":true,"img":false}]}
{"op":"mcm","clk":"5346622965","pt":1646092590142,"mc":[{"id":"1.195395443","rc":[{"atl":[[21,6.25]],"id":40917095},{"atl":[[13.5,9.31]],"id":42236670},{"atb":[[2.8,69.44]],"id":41523279},{"atb":[[3.1,59.52]],"id":42236682}],"con":true,"img":false}]}
{"op":"mcm","clk":"5346623293","pt":1646092599985,"mc":[{"id":"1.195395443","rc":[{"atb":[[7.4,3.12],[7.2,0]],"id":40917095},{"atb":[[2.9,0]],"id":41523279}],"con":true,"img":false}]}
{"op":"mcm","clk":"5346623321","pt":1646092600958,"mc":[{"id":"1.195395443","rc":[{"atb":[[7.4,0],[7.2,3.23]],"id":40917095},{"atb":[[3.55,39.22],[3.3,0]],"id":42236670},{"atb":[[3.6,9.22],[3.5,16.23]],"id":42070475},{"atl":[[7.2,16.13],[7,12.5]],"id":41523279},{"atb":[[4.8,5.26],[4.9,25.64],[5.1,0]],"id":37174579},{"atl":[[16.5,1.29],[19.5,7.14],[40,2.56],[50,0]],"id":37174579}],"con":true,"img":false}]}
{"op":"mcm","clk":"5346623470","pt":1646092605167,"mc":[{"id":"1.195395443","rc":[{"atb":[[1.01,2.23]],"id":37174579}],"con":true,"img":false}]}
{"op":"mcm","clk":"5346623478","pt":1646092605375,"mc":[{"id":"1.195395443","rc":[{"atb":[[1.01,1.46]],"id":37174579}],"con":true,"img":false}]}
{"op":"mcm","clk":"5346623491","pt":1646092605684,"mc":[{"id":"1.195395443","rc":[{"atb":[[1.01,0]],"id":37174579}],"con":true,"img":false}]}
{"op":"mcm","clk":"5346623496","pt":1646092605786,"mc":[{"id":"1.195395443","rc":[{"atb":[[6.6,3.26]],"id":37174579}],"con":true,"img":false}]}
{"op":"mcm","clk":"5346623567","pt":1646092607890,"mc":[{"id":"1.195395443","rc":[{"atb":[[6.4,0]],"id":37174579}],"con":true,"img":false}]}
{"op":"mcm","clk":"5346623587","pt":1646092608604,"mc":[{"id":"1.195395443","rc":[{"atb":[[3.55,3.6]],"id":42070475}],"con":true,"img":false}]}
{"op":"mcm","clk":"5346623667","pt":1646092610810,"mc":[{"id":"1.195395443","rc":[{"atb":[[7.2,5.07]],"id":37174579}],"con":true,"img":false}]}
{"op":"mcm","clk":"5346623677","pt":1646092611015,"mc":[{"id":"1.195395443","rc":[{"atb":[[4.6,13.89]],"id":37174579},{"atl":[[17.5,3.03]],"id":37174579}],"con":true,"img":false}]}
{"op":"mcm","clk":"5346623745","pt":1646092612712,"mc":[{"id":"1.195395443","rc":[{"atb":[[7.2,0],[7,3.33]],"id":40917095},{"atl":[[17.5,0],[17,1.25]],"id":40917095},{"atb":[[5.9,4.08],[5.5,36.08]],"id":42189436},{"atl":[[11.5,0],[12.5,0],[13.5,17.47]],"id":42070475},{"atb":[[3.3,8.7],[2.92,60.68]],"id":41523279},{"atb":[[4.8,0],[4.9,0],[3.3,52.18],[4.5,46.38],[4.6,0],[4.7,0]],"id":37174579},{"atl":[[22,0],[24,5.75],[26,0]],"id":37174579}],"con":true,"img":false}]}
{"op":"mcm","clk":"5346623798","pt":1646092614405,"mc":[{"id":"1.195395443","rc":[{"atb":[[6.6,1.8]],"id":37174579}],"con":true,"img":false}]}
{"op":"mcm","clk":"5346623845","pt":1646092616096,"mc":[{"id":"1.195395443","rc":[{"atl":[[25,0]],"id":37174579}],"con":true,"img":false}]}
{"op":"mcm","clk":"5346623850","pt":1646092616199,"mc":[{"id":"1.195395443","rc":[{"atl":[[28,3.92]],"id":37174579}],"con":true,"img":false}]}
{"op":"mcm","clk":"5346623860","pt":1646092616504,"mc":[{"id":"1.195395443","rc":[{"atb":[[7.2,0]],"id":37174579}],"con":true,"img":false}]}
{"op":"mcm","clk":"5346623885","pt":1646092617374,"mc":[{"id":"1.195395443","rc":[{"atb":[[3.55,0],[3.3,21.98]],"id":42070475}],"con":true,"img":false}]}
{"op":"mcm","clk":"5346623969","pt":1646092619486,"mc":[{"id":"1.195395443","rc":[{"atb":[[3.6,6.82]],"id":42070475},{"atb":[[6.4,11.84]],"id":37174579}],"con":true,"img":false}]}
{"op":"mcm","clk":"5346623975","pt":1646092619587,"mc":[{"id":"1.195395443","rc":[{"atb":[[3.6,0],[3.55,16.24]],"id":42070475}],"con":true,"img":false}]}
{"op":"mcm","clk":"5346624062","pt":1646092622405,"mc":[{"id":"1.195395443","rc":[{"spn":13.3,"spf":1.0,"id":40917095},{"atb":[[3.6,12.17]],"id":42070475},{"spn":11.75,"spf":1.0,"id":37174579}],"con":true,"img":false}]}
{"op":"mcm","clk":"5346624065","pt":1646092622508,"mc":[{"id":"1.195395443","rc":[{"atb":[[3.6,28.41],[3.55,0]],"id":42070475}],"con":true,"img":false}]}
{"op":"mcm","clk":"5346624073","pt":1646092622714,"mc":[{"id":"1.195395443","rc":[{"atb":[[6.6,8.93]],"id":40917095},{"atb":[[5.7,10.64]],"id":42189436},{"atl":[[14.5,11.11]],"id":42070475},{"atb":[[3.2,22.73]],"id":41523279},{"atb":[[3.2,22.73]],"id":37174579},{"atl":[[18.5,4.29]],"id":37174579}],"con":true,"img":false}]}
{"op":"mcm","clk":"5346624189","pt":1646092625991,"mc":[{"id":"1.195395443","rc":[{"atb":[[6.4,0],[6.8,0],[6,0]],"id":40917095},{"atb":[[4.9,0]],"id":42189436},{"atb":[[2.8,0]],"id":41523279}],"con":true,"img":false}]}
{"op":"mcm","clk":"5346624194","pt":1646092626094,"mc":[{"id":"1.195395443","rc":[{"atb":[[7.8,0]],"id":40917095},{"atl":[[10.5,0],[8.2,0],[13,8.86]],"id":42070475},{"atb":[[2.92,0]],"id":41523279},{"atb":[[5.6,0]],"id":37174579}],"con":true,"img":false}]}
{"op":"mcm","clk":"5346624200","pt":1646092626197,"mc":[{"id":"1.195395443","rc":[{"atb":[[8.8,5.55]],"id":40917095},{"atl":[[9.2,6.01]],"id":42070475},{"atb":[[2.98,60.68]],"id":41523279},{"atb":[[4.6,26.51]],"id":37174579}],"con":true,"img":false}]}
{"op":"mcm","clk":"5346624267","pt":1646092628238,"mc":[{"id":"1.195395443","rc":[{"atb":[[3.6,16.24]],"id":42070475}],"con":true,"img":false}]}
{"op":"mcm","clk":"5346624274","pt":1646092628393,"mc":[{"id":"1.195395443","rc":[{"atb":[[3.6,0],[3.55,32.48]],"id":42070475}],"con":true,"img":false}]}
{"op":"mcm","clk":"5346624303","pt":1646092629323,"mc":[{"id":"1.195395443","rc":[{"atb":[[3.3,18.42]],"id":42070475}],"con":true,"img":false}]}
{"op":"mcm","clk":"5346624364","pt":1646092631122,"mc":[{"id":"1.195395443","rc":[{"atb":[[3.6,24.35]],"id":42070475}],"con":true,"img":false}]}
{"op":"mcm","clk":"5346624423","pt":1646092632609,"mc":[{"id":"1.195395443","rc":[{"atb":[[3.6,48.71]],"id":42070475}],"con":true,"img":false}]}
{"op":"mcm","clk":"5346624428","pt":1646092632713,"mc":[{"id":"1.195395443","rc":[{"atb":[[6.2,36.12]],"id":40917095},{"atb":[[5.5,52.75]],"id":42189436},{"atb":[[3.55,0]],"id":42070475},{"atl":[[15.5,5.17]],"id":42070475},{"atb":[[3.1,35.71]],"id":41523279},{"atb":[[3.1,35.71]],"id":37174579},{"atl":[[19.5,13.9]],"id":37174579}],"con":true,"img":false}]}
{"op":"mcm","clk":"5346624512","pt":1646092635431,"mc":[{"id":"1.195395443","rc":[{"atb":[[3.6,24.36]],"id":42070475}],"con":true,"img":false}]}
{"op":"mcm","clk":"5346624517","pt":1646092635533,"mc":[{"id":"1.195395443","rc":[{"atb":[[3.6,0],[3.55,39.22]],"id":42070475}],"con":true,"img":false}]}
{"op":"mcm","clk":"5346624608","pt":1646092638353,"mc":[{"id":"1.195395443","rc":[{"atb":[[5.1,0]],"id":42189436},{"atb":[[3.6,29.41]],"id":42070475},{"atb":[[2.84,0]],"id":41523279},{"atb":[[1.01,2.23]],"id":37174579}],"con":true,"img":false}]}
{"op":"mcm","clk":"5346624614","pt":1646092638557,"mc":[{"id":"1.195395443","rc":[{"atb":[[1.01,1.46]],"id":37174579}],"con":true,"img":false}]}
{"op":"mcm","clk":"5346624625","pt":1646092638720,"mc":[{"id":"1.195395443","rc":[{"atb":[[1.01,0]],"id":37174579}],"con":true,"img":false}]}
{"op":"mcm","clk":"5346624628","pt":1646092638819,"mc":[{"id":"1.195395443","rc":[{"atb":[[6.6,3.26]],"id":37174579}],"con":true,"img":false}]}
{"op":"mcm","clk":"5346624728","pt":1646092641234,"mc":[{"id":"1.195395443","rc":[{"atb":[[6.4,0]],"id":37174579}],"con":true,"img":false}]}
{"op":"mcm","clk":"5346624776","pt":1646092642718,"mc":[{"id":"1.195395443","rc":[{"atb":[[5.9,25.51]],"id":40917095},{"atb":[[5.3,29.07]],"id":42189436},{"atl":[[16.5,8.06]],"id":42070475},{"atb":[[3,62.5]],"id":41523279},{"atb":[[3,62.5]],"id":37174579}],"con":true,"img":false}]}
{"op":"mcm","clk":"5346624810","pt":1646092644148,"mc":[{"id":"1.195395443","rc":[{"atb":[[7.2,5.07]],"id":37174579}],"con":true,"img":false}]}
{"op":"mcm","clk":"5346624843","pt":1646092645538,"mc":[{"id":"1.195395443","rc":[{"atb":[[3.6,58.82]],"id":42070475}],"con":true,"img":false}]}
{"op":"mcm","clk":"5346624846","pt":1646092645639,"mc":[{"id":"1.195395443","rc":[{"atb":[[3.55,0]],"id":42070475}],"con":true,"img":false}]}
{"op":"mcm","clk":"5346624883","pt":1646092646660,"mc":[{"id":"1.195395443","rc":[{"atb":[[2.88,0]],"id":41523279}],"con":true,"img":false}]}
{"op":"mcm","clk":"5346624943","pt":1646092648450,"mc":[{"id":"1.195395443","rc":[{"atb":[[3.6,29.41]],"id":42070475}],"con":true,"img":false}]}
{"op":"mcm","clk":"5346624990","pt":1646092650344,"mc":[{"id":"1.195395443","rc":[{"atb":[[6.6,1.8]],"id":37174579}],"con":true,"img":false}]}
{"op":"mcm","clk":"5346624997","pt":1646092650650,"mc":[{"id":"1.195395443","rc":[{"atb":[[3.55,39.22]],"id":42070475}],"con":true,"img":false}]}
{"op":"mcm","clk":"5346625000","pt":1646092650753,"mc":[{"id":"1.195395443","rc":[{"atb":[[3.6,0]],"id":42070475}],"con":true,"img":false}]}
{"op":"mcm","clk":"5346625019","pt":1646092651368,"mc":[{"id":"1.195395443","rc":[{"atb":[[3.65,22.05]],"id":42070475}],"con":true,"img":false}]}
{"op":"mcm","clk":"5346625048","pt":1646092652752,"mc":[{"id":"1.195395443","rc":[{"atb":[[7.2,0]],"id":37174579}],"con":true,"img":false}]}
{"op":"mcm","clk":"5346625128","pt":1646092655675,"mc":[{"id":"1.195395443","rc":[{"atb":[[6.4,11.84]],"id":37174579}],"con":true,"img":false}]}
{"op":"mcm","clk":"5346625264","pt":1646092660441,"mc":[{"id":"1.195395443","rc":[{"atb":[[3.6,38.46]],"id":42070475}],"con":true,"img":false}]}
{"op":"mcm","clk":"5346625270","pt":1646092660545,"mc":[{"id":"1.195395443","rc":[{"atb":[[3.55,0]],"id":42070475}],"con":true,"img":false}]}
{"op":"mcm","clk":"5346625413","pt":1646092666068,"mc":[{"id":"1.195395443","rc":[{"atb":[[5.6,0]],"id":42189436}],"con":true,"img":false}]}
{"op":"mcm","clk":"5346625417","pt":1646092666168,"mc":[{"id":"1.195395443","rc":[{"atb":[[5.8,24.06]],"id":42189436}],"con":true,"img":false}]}
{"op":"mcm","clk":"5346625573","pt":1646092671255,"mc":[{"id":"1.195395443","rc":[{"atb":[[1.01,2.23]],"id":37174579}],"con":true,"img":false}]}
{"op":"mcm","clk":"5346625581","pt":1646092671460,"mc":[{"id":"1.195395443","rc":[{"atb":[[1.01,1.46]],"id":37174579}],"con":true,"img":false}]}
{"op":"mcm","clk":"5346625589","pt":1646092671666,"mc":[{"id":"1.195395443","rc":[{"atb":[[1.01,0]],"id":37174579}],"con":true,"img":false}]}
{"op":"mcm","clk":"5346625593","pt":1646092671769,"mc":[{"id":"1.195395443","rc":[{"atb":[[6.6,3.26]],"id":37174579}],"con":true,"img":false}]}
{"op":"mcm","clk":"5346625672","pt":1646092674478,"mc":[{"id":"1.195395443","rc":[{"atb":[[6.4,0]],"id":37174579}],"con":true,"img":false}]}
{"op":"mcm","clk":"5346625757","pt":1646092677402,"mc":[{"id":"1.195395443","rc":[{"atb":[[7.2,5.07]],"id":37174579}],"con":true,"img":false}]}
{"op":"mcm","clk":"5346625923","pt":1646092683396,"mc":[{"id":"1.195395443","rc":[{"spn":4.62,"spf":1.0,"id":42070475},{"atb":[[6.6,1.8]],"id":37174579},{"spn":11.85,"spf":1.0,"id":37174579}],"con":true,"img":false}]}
{"op":"mcm","clk":"5346625940","pt":1646092684008,"mc":[{"id":"1.195395443","rc":[{"atl":[[1000,1.67]],"id":40917095},{"atl":[[1000,1.67]],"id":42189436},{"atl":[[1000,1.67]],"id":42236682},{"atl":[[1000,1.67]],"id":37174579}],"con":true,"img":false}]}
{"op":"mcm","clk":"5346625949","pt":1646092684214,"mc":[{"id":"1.195395443","rc":[{"atl":[[1000,0.5]],"id":40917095},{"atl":[[1000,0.47]],"id":42189436},{"atl":[[1000,1.27]],"id":42236682},{"atl":[[1000,0.51]],"id":37174579}],"con":true,"img":false}]}
{"op":"mcm","clk":"5346625956","pt":1646092684369,"mc":[{"id":"1.195395443","rc":[{"atl":[[1000,0]],"id":40917095}],"con":true,"img":false}]}
{"op":"mcm","clk":"5346625961","pt":1646092684472,"mc":[{"id":"1.195395443","rc":[{"atl":[[16.5,0.5]],"id":40917095}],"con":true,"img":false}]}
{"op":"mcm","clk":"5346625967","pt":1646092684584,"mc":[{"id":"1.195395443","rc":[{"atl":[[1000,0]],"id":42189436}],"con":true,"img":false}]}
{"op":"mcm","clk":"5346625971","pt":1646092684678,"mc":[{"id":"1.195395443","rc":[{"atl":[[17.5,0.47]],"id":42189436}],"con":true,"img":false}]}
{"op":"mcm","clk":"5346625974","pt":1646092684881,"mc":[{"id":"1.195395443","rc":[{"atl":[[1000,0]],"id":37174579}],"con":true,"img":false}]}
{"op":"mcm","clk":"5346625978","pt":1646092684992,"mc":[{"id":"1.195395443","rc":[{"atl":[[16,0.51]],"id":37174579}],"con":true,"img":false}]}
{"op":"mcm","clk":"5346625987","pt":1646092685187,"mc":[{"id":"1.195395443","rc":[{"atl":[[1000,0]],"id":42236682}],"con":true,"img":false}]}
{"op":"mcm","clk":"5346625992","pt":1646092685291,"mc":[{"id":"1.195395443","rc":[{"atl":[[6.6,1.27]],"id":42236682}],"con":true,"img":false}]}
{"op":"mcm","clk":"5346626017","pt":1646092686006,"mc":[{"id":"1.195395443","rc":[{"atb":[[7.2,0]],"id":37174579}],"con":true,"img":false}]}
{"op":"mcm","clk":"5346626021","pt":1646092686107,"mc":[{"id":"1.195395443","rc":[{"atb":[[8.8,0]],"id":40917095}],"con":true,"img":false}]}
{"op":"mcm","clk":"5346626025","pt":1646092686209,"mc":[{"id":"1.195395443","rc":[{"atb":[[7.8,5.55]],"id":40917095}],"con":true,"img":false}]}
{"op":"mcm","clk":"5346626099","pt":1646092688877,"mc":[{"id":"1.195395443","rc":[{"atb":[[6.4,11.84]],"id":37174579}],"con":true,"img":false}]}
{"op":"mcm","clk":"5346626147","pt":1646092691029,"mc":[{"id":"1.195395443","rc":[{"atb":[[1.03,2.9]],"id":42236670},{"atb":[[1.02,3]],"id":42070475},{"atb":[[1.02,2.98]],"id":41523279},{"atb":[[1.02,3]],"id":42236682}],"con":true,"img":false}]}
{"op":"mcm","clk":"5346626160","pt":1646092691389,"mc":[{"id":"1.195395443","rc":[{"atb":[[1.03,0.19]],"id":42236670},{"atb":[[1.02,0.28]],"id":41523279},{"atb":[[1.02,0.29]],"id":42236682}],"con":true,"img":false}]}
{"op":"mcm","clk":"5346626167","pt":1646092691491,"mc":[{"id":"1.195395443","rc":[{"atb":[[1.02,0.3]],"id":42070475}],"con":true,"img":false}]}
{"op":"mcm","clk":"5346626177","pt":1646092691902,"mc":[{"id":"1.195395443","rc":[{"atb":[[1.03,0]],"id":42236670},{"atb":[[1.02,0]],"id":41523279},{"atb":[[1.02,0]],"id":42236682}],"con":true,"img":false}]}
{"op":"mcm","clk":"5346626180","pt":1646092692003,"mc":[{"id":"1.195395443","rc":[{"atb":[[5.4,0.19]],"id":42236670},{"atb":[[1.02,0]],"id":42070475},{"atb":[[3.75,0.28]],"id":41523279},{"atb":[[3.55,0.29]],"id":42236682}],"con":true,"img":false}]}
{"op":"mcm","clk":"5346626182","pt":1646092692105,"mc":[{"id":"1.195395443","rc":[{"atb":[[3.5,16.53]],"id":42070475}],"con":true,"img":false}]}
{"op":"mcm","clk":"5346626190","pt":1646092692415,"mc":[{"id":"1.195395443","rc":[{"atl":[[7.4,35.15]],"id":41523279}],"con":true,"img":false}]}
{"op":"mcm","clk":"5346626194","pt":1646092692516,"mc":[{"id":"1.195395443","rc":[{"atb":[[3.6,0],[3.55,39.22]],"id":42070475},{"atl":[[7.2,0]],"id":41523279},{"atb":[[3.5,8],[3.4,50.73]],"id":42236682},{"atl":[[6.8,0],[6.6,4.84]],"id":42236682},{"atl":[[16,1.84],[16.5,0]],"id":37174579}],"con":true,"img":false}]}
{"op":"mcm","clk":"5346626301","pt":1646092696883,"mc":[{"id":"1.195395443","rc":[{"atb":[[7,0]],"id":37174579},{"atl":[[7,4.05]],"id":37174579},{"trd":[[7,13.53]],"ltp":7.0,"tv":13.53,"id":37174579}],"con":true,"img":false}]}
{"op":"mcm","clk":"5346626305","pt":1646092696988,"mc":[{"id":"1.195395443","rc":[{"atl":[[7,0]],"id":37174579},{"trd":[[7,21.64]],"ltp":7.0,"tv":21.64,"id":37174579}],"con":true,"img":false}]}
{"op":"mcm","clk":"5346626308","pt":1646092697092,"mc":[{"id":"1.195395443","rc":[{"atb":[[4,0],[4.5,28.57]],"id":42189436},{"atb":[[3.55,0],[3.7,22.06]],"id":42070475},{"atb":[[2.92,51.43],[2.78,0]],"id":41523279},{"atb":[[3.3,21.74],[3.45,40.82]],"id":42236682}],"con":true,"img":false}]}
{"op":"mcm","clk":"5346626376","pt":1646092699397,"mc":[{"id":"1.195395443","rc":[{"atb":[[3.65,0]],"id":42070475},{"atb":[[6.4,0]],"id":37174579}],"con":true,"img":false}]}
{"op":"mcm","clk":"5346626442","pt":1646092702215,"mc":[{"id":"1.195395443","rc":[{"atb":[[3.55,39.22],[3.7,0]],"id":42070475}],"con":true,"img":false}]}
{"op":"mcm","clk":"5346626444","pt":1646092702315,"mc":[{"id":"1.195395443","rc":[{"atb":[[3.55,75.51]],"id":42070475}],"con":true,"img":false}]}
{"op":"mcm","clk":"5346626449","pt":1646092702521,"mc":[{"id":"1.195395443","rc":[{"atb":[[3.4,71.56]],"id":42236682}],"con":true,"img":false}]}
{"op":"mcm","clk":"5346626475","pt":1646092703697,"mc":[{"id":"1.195395443","rc":[{"atb":[[3.1,0]],"id":42236682}],"con":true,"img":false}]}
{"op":"mcm","clk":"5346626510","pt":1646092704934,"mc":[{"id":"1.195395443","rc":[{"atl":[[18,0],[18.5,1.14]],"id":42189436},{"atb":[[3.5,0],[3.4,59.06]],"id":42236682}],"con":true,"img":false}]}
{"op":"mcm","clk":"5346626517","pt":1646092705085,"mc":[{"id":"1.195395443","rc":[{"atl":[[19,3.75]],"id":42189436}],"con":true,"img":false}]}
{"op":"mcm","clk":"5346626519","pt":1646092705188,"mc":[{"id":"1.195395443","rc":[{"atl":[[20,0]],"id":42189436}],"con":true,"img":false}]}
{"op":"mcm","clk":"5346626628","pt":1646092708517,"mc":[{"id":"1.195395443","rc":[{"atb":[[9.2,0]],"id":42189436}],"con":true,"img":false}]}
{"op":"mcm","clk":"5346626635","pt":1646092708621,"mc":[{"id":"1.195395443","rc":[{"atb":[[9.6,1.17]],"id":42189436}],"con":true,"img":false}]}
{"op":"mcm","clk":"5346626825","pt":1646092714007,"mc":[{"id":"1.195395443","rc":[{"atl":[[1000,1.67],[17.5,0]],"id":42189436}],"con":true,"img":false}]}
{"op":"mcm","clk":"5346626830","pt":1646092714107,"mc":[{"id":"1.195395443","rc":[{"atb":[[1.01,1.67]],"id":40917095},{"atb":[[1.01,1.67]],"id":42189436},{"atl":[[19,0],[19.5,7.59]],"id":42189436},{"atb":[[1.02,1.67]],"id":42236670},{"atb":[[3.45,0]],"id":42070475}],"con":true,"img":false}]}
{"op":"mcm","clk":"5346626841","pt":1646092714210,"mc":[{"id":"1.195395443","rc":[{"atb":[[1.01,0.85]],"id":42189436},{"atl":[[1000,0.47]],"id":42189436},{"atb":[[3.55,77.51]],"id":42070475}],"con":true,"img":false}]}
{"op":"mcm","clk":"5346626850","pt":1646092714313,"mc":[{"id":"1.195395443","rc":[{"atb":[[1.01,0.85]],"id":40917095},{"atb":[[1.02,1.3]],"id":42236670}],"con":true,"img":false}]}
{"op":"mcm","clk":"5346626854","pt":1646092714418,"mc":[{"id":"1.195395443","rc":[{"atl":[[1000,0]],"id":42189436}],"con":true,"img":false}]}
{"op":"mcm","clk":"5346626858","pt":1646092714518,"mc":[{"id":"1.195395443","rc":[{"atl":[[18,0.47]],"id":42189436}],"con":true,"img":false}]}
{"op":"mcm","clk":"5346626864","pt":1646092714724,"mc":[{"id":"1.195395443","rc":[{"atb":[[1.01,0]],"id":42189436}],"con":true,"img":false}]}
{"op":"mcm","clk":"5346626866","pt":1646092714825,"mc":[{"id":"1.195395443","rc":[{"atb":[[9.8,0.85]],"id":42189436}],"con":true,"img":false}]}
{"op":"mcm","clk":"5346626871","pt":1646092714929,"mc":[{"id":"1.195395443","rc":[{"atb":[[1.02,0]],"id":42236670},{"atb":[[3.1,59.52]],"id":42236682}],"con":true,"img":false}]}
{"op":"mcm","clk":"5346626875","pt":1646092715029,"mc":[{"id":"1.195395443","rc":[{"atb":[[6.4,1.3]],"id":42236670}],"con":true,"img":false}]}
{"op":"mcm","clk":"5346626878","pt":1646092715233,"mc":[{"id":"1.195395443","rc":[{"atb":[[1.01,0]],"id":40917095}],"con":true,"img":false}]}
{"op":"mcm","clk":"5346626880","pt":1646092715337,"mc":[{"id":"1.195395443","rc":[{"atb":[[9.8,0.85]],"id":40917095},{"atl":[[18.5,2.56]],"id":42189436},{"atl":[[10.5,3.38]],"id":42236670},{"atl":[[6.2,5.16]],"id":41523279},{"atl":[[6.4,1.35]],"id":42236682}],"con":true,"img":false}]}
{"op":"mcm","clk":"5346626883","pt":1646092715438,"mc":[{"id":"1.195395443","rc":[{"atb":[[6.2,0]],"id":42236670}],"con":true,"img":false}]}
{"op":"mcm","clk":"5346626886","pt":1646092715540,"mc":[{"id":"1.195395443","rc":[{"atb":[[6.2,1.65]],"id":42236670},{"atb":[[3.6,1.64]],"id":42070475},{"atb":[[4,3.64]],"id":41523279},{"atb":[[3.95,1.68]],"id":42236682},{"atb":[[6.4,1.59]],"id":37174579}],"con":true,"img":false}]}
{"op":"mcm","clk":"5346626894","pt":1646092715798,"mc":[{"id":"1.195395443","rc":[{"atb":[[1.02,1.67]],"id":42236670}],"con":true,"img":false}]}
{"op":"mcm","clk":"5346626900","pt":1646092715900,"mc":[{"id":"1.195395443","rc":[{"atb":[[6.4,0]],"id":42236670}],"con":true,"img":false}]}
{"op":"mcm","clk":"5346626904","pt":1646092716001,"mc":[{"id":"1.195395443","rc":[{"atb":[[1.02,1.3]],"id":42236670}],"con":true,"img":false}]}
{"op":"mcm","clk":"5346626910","pt":1646092716207,"mc":[{"id":"1.195395443","rc":[{"atb":[[1.02,0]],"id":42236670}],"con":true,"img":false}]}
{"op":"mcm","clk":"5346626913","pt":1646092716310,"mc":[{"id":"1.195395443","rc":[{"atb":[[6.2,2.95]],"id":42236670}],"con":true,"img":false}]}
{"op":"mcm","clk":"5346626938","pt":1646092717331,"mc":[{"id":"1.195395443","rc":[{"atl":[[9.2,0]],"id":42070475}],"con":true,"img":false}]}
{"op":"mcm","clk":"5346626943","pt":1646092717432,"mc":[{"id":"1.195395443","rc":[{"atl":[[8.2,6.01]],"id":42070475}],"con":true,"img":false}]}
{"op":"mcm","clk":"5346626972","pt":1646092718507,"mc":[{"id":"1.195395443","rc":[{"atb":[[4,1.64]],"id":41523279}],"con":true,"img":false}]}
{"op":"mcm","clk":"5346626978","pt":1646092718608,"mc":[{"id":"1.195395443","rc":[{"atb":[[4.1,2]],"id":41523279}],"con":true,"img":false}]}
{"op":"mcm","clk":"5346626985","pt":1646092718917,"mc":[{"id":"1.195395443","rc":[{"atl":[[19,0],[19.5,8.16]],"id":40917095},{"atl":[[12,0],[12.5,14.77]],"id":42236670},{"atb":[[3.35,33.08],[3.55,38.29]],"id":42070475},{"atb":[[2.8,48],[2.92,0]],"id":41523279},{"atl":[[7.4,19.53],[7.2,16.13]],"id":41523279},{"atl":[[6.8,3.45],[6.6,1.27]],"id":42236682},{"atl":[[16,0.51],[17,1.25]],"id":37174579}],"con":true,"img":false}]}
{"op":"mcm","clk":"5346626988","pt":1646092719021,"mc":[{"id":"1.195395443","rc":[{"atb":[[9.8,2.51]],"id":40917095}],"con":true,"img":false}]}
{"op":"mcm","clk":"5346626994","pt":1646092719227,"mc":[{"id":"1.195395443","rc":[{"atl":[[19.5,2.7],[20,5.12]],"id":42189436}],"con":true,"img":false}]}
{"op":"mcm","clk":"5346626998","pt":1646092719328,"mc":[{"id":"1.195395443","rc":[{"atb":[[3.6,4.8]],"id":42070475}],"con":true,"img":false}]}
{"op":"mcm","clk":"5346627002","pt":1646092719432,"mc":[{"id":"1.195395443","rc":[{"atb":[[1.01,2.23]],"id":37174579}],"con":true,"img":false}]}
{"op":"mcm","clk":"5346627007","pt":1646092719533,"mc":[{"id":"1.195395443","rc":[{"atl":[[6.4,0]],"id":42236682},{"atb":[[1.01,1.57]],"id":37174579},{"atl":[[17,2.64]],"id":37174579}],"con":true,"img":false}]}
{"op":"mcm","clk":"5346627011","pt":1646092719636,"mc":[{"id":"1.195395443","rc":[{"atb":[[9.8,0.85]],"id":40917095},{"atb":[[4,0]],"id":41523279},{"atl":[[6.8,4.8]],"id":42236682}],"con":true,"img":false}]}
{"op":"mcm","clk":"5346627015","pt":1646092719740,"mc":[{"id":"1.195395443","rc":[{"atb":[[1.01,1.66]],"id":40917095},{"atb":[[4.1,3.64]],"id":41523279},{"atb":[[1.01,0]],"id":37174579}],"con":true,"img":false}]}
{"op":"mcm","clk":"5346627018","pt":1646092719841,"mc":[{"id":"1.195395443","rc":[{"atb":[[3.35,0],[3.3,61.9]],"id":42070475},{"atb":[[6.2,11.5]],"id":37174579},{"atl":[[16.5,1.29],[17,1.39]],"id":37174579}],"con":true,"img":false}]}
{"op":"mcm","clk":"5346627026","pt":1646092720102,"mc":[{"id":"1.195395443","rc":[{"atl":[[17,0]],"id":37174579}],"con":true,"img":false}]}
{"op":"mcm","clk":"5346627031","pt":1646092720206,"mc":[{"id":"1.195395443","rc":[{"atb":[[1.01,0]],"id":40917095},{"atl":[[16.5,2.68]],"id":37174579}],"con":true,"img":false}]}
{"op":"mcm","clk":"5346627035","pt":1646092720308,"mc":[{"id":"1.195395443","rc":[{"atb":[[9.8,2.51]],"id":40917095}],"con":true,"img":false}]}
{"op":"mcm","clk":"5346627147","pt":1646092723952,"mc":[{"id":"1.195395443","rc":[{"atb":[[9.8,0.85]],"id":40917095}],"con":true,"img":false}]}
{"op":"mcm","clk":"5346627151","pt":1646092724051,"mc":[{"id":"1.195395443","rc":[{"atb":[[1.01,1.66]],"id":40917095}],"con":true,"img":false}]}
{"op":"mcm","clk":"5346627415","pt":1646092732562,"mc":[{"id":"1.195395443","rc":[{"atb":[[5.8,0],[9.6,0],[8.6,0],[7.6,0]],"id":40917095},{"atl":[[65,0],[130,8.2],[90,0],[46,0]],"id":40917095},{"atb":[[8,0],[9,0],[5.5,16.67],[7,0]],"id":42189436},{"atl":[[40,0],[50,0],[75,0],[100,0]],"id":42189436},{"atb":[[3.4,8.33],[3.9,0],[2.96,0],[3.65,0]],"id":42236682},{"atl":[[10.5,10.53],[13,0],[15.5,0],[18,0]],"id":42236682},{"atb":[[4.5,0],[5.5,0],[6,0]],"id":37174579},{"atl":[[19.5,6.76],[38,0],[24,0],[29,0]],"id":37174579}],"con":true,"img":false}]}
{"op":"mcm","clk":"5346627421","pt":1646092732869,"mc":[{"id":"1.195395443","rc":[{"atb":[[1.01,0]],"id":40917095},{"atb":[[3.95,0]],"id":42236682},{"atb":[[6.4,0]],"id":37174579}],"con":true,"img":false}]}
{"op":"mcm","clk":"5346627424","pt":1646092732971,"mc":[{"id":"1.195395443","rc":[{"atb":[[8.2,3.06]],"id":40917095},{"atb":[[3.8,3.68]],"id":42236682},{"atb":[[1.01,1.59]],"id":37174579}],"con":true,"img":false}]}
{"op":"mcm","clk":"5346627481","pt":1646092734867,"mc":[{"id":"1.195395443","rc":[{"atb":[[6,18.5]],"id":42189436},{"atb":[[4.7,25.01]],"id":37174579}],"con":true,"img":false}]}
{"op":"mcm","clk":"5346627526","pt":1646092736151,"mc":[{"id":"1.195395443","rc":[{"atl":[[44,0]],"id":40917095},{"atb":[[8.2,0]],"id":42189436},{"atl":[[38,0]],"id":42189436},{"atl":[[18,7.57],[12.5,0]],"id":42236682},{"atb":[[6.2,3.17]],"id":37174579},{"atl":[[38,2.86],[28,0]],"id":37174579}],"con":true,"img":false}]}
{"op":"mcm","clk":"5346627533","pt":1646092736253,"mc":[{"id":"1.195395443","rc":[{"atl":[[65,2.7]],"id":40917095},{"atb":[[6.8,6.01]],"id":42189436},{"atl":[[65,2.99]],"id":42189436},{"atb":[[5.4,8.32]],"id":37174579}],"con":true,"img":false}]}
{"op":"mcm","clk":"5346627539","pt":1646092736560,"mc":[{"id":"1.195395443","rc":[{"atb":[[8,11.79],[9,5.15],[5.5,36.68],[7,23.96]],"id":40917095},{"atl":[[75,2.65],[40,3.35],[50,2.67],[100,1.98]],"id":40917095},{"atb":[[5.8,58.45],[9.6,5.97],[8.6,10.86],[7.6,18.75]],"id":42189436},{"atl":[[65,5.03],[130,1.52],[90,2.2],[46,2.91]],"id":42189436},{"atb":[[3.45,74.5],[3.2,90.36],[2.88,87.8],[3.7,37.17]],"id":42236682},{"atl":[[11,13.09],[13.5,15.71],[9.4,15.58],[16,13.09]],"id":42236682},{"atb":[[4.3,44.28],[5.8,15.22],[5.3,25.48],[6.6,8.32]],"id":37174579},{"atl":[[36,6.01],[19,10.5],[23,6.38],[28,7.79]],"id":37174579}],"con":true,"img":false}]}
{"op":"mcm","clk":"5346627551","pt":1646092736968,"mc":[{"id":"1.195395443","rc":[{"atb":[[8.2,1.4]],"id":40917095},{"atb":[[9.8,2.45]],"id":42189436},{"atl":[[18.5,1.14]],"id":42189436},{"atb":[[1.01,0]],"id":37174579}],"con":true,"img":false}]}
{"op":"mcm","clk":"5346627557","pt":1646092737070,"mc":[{"id":"1.195395443","rc":[{"atb":[[9.2,1.66]],"id":40917095},{"atl":[[1000,1.42]],"id":42189436},{"atb":[[6.8,1.59]],"id":37174579}],"con":true,"img":false}]}
{"op":"mcm","clk":"5346627573","pt":1646092737636,"mc":[{"id":"1.195395443","rc":[{"atb":[[9.2,0]],"id":40917095}],"con":true,"img":false}]}
{"op":"mcm","clk":"5346627576","pt":1646092737738,"mc":[{"id":"1.195395443","rc":[{"atb":[[1.01,1.66]],"id":40917095}],"con":true,"img":false}]}
{"op":"mcm","clk":"5346627621","pt":1646092739378,"mc":[{"id":"1.195395443","rc":[{"atb":[[6,0]],"id":42189436},{"atb":[[4.7,0]],"id":37174579}],"con":true,"img":false}]}
{"op":"mcm","clk":"5346627662","pt":1646092740558,"mc":[{"id":"1.195395443","rc":[{"atb":[[3.7,34.41]],"id":42236682},{"atb":[[6.2,1.6]],"id":37174579}],"con":true,"img":false}]}
{"op":"mcm","clk":"5346627742","pt":1646092742250,"mc":[{"id":"1.195395443","rc":[{"atb":[[7.8,0]],"id":40917095},{"atl":[[8.2,0]],"id":42070475},{"atb":[[3.7,18.37]],"id":42236682}],"con":true,"img":false}]}
{"op":"mcm","clk":"5346627748","pt":1646092742353,"mc":[{"id":"1.195395443","rc":[{"atb":[[6.8,5.55]],"id":40917095},{"atl":[[9.2,6.01]],"id":42070475},{"atb":[[3.5,16.03]],"id":42236682}],"con":true,"img":false}]}
{"op":"mcm","clk":"5346627820","pt":1646092743688,"mc":[{"id":"1.195395443","rc":[{"atb":[[7.6,3.03],[7,20.63]],"id":40917095},{"spn":13.15,"spf":1.0,"id":40917095},{"atb":[[5.9,0],[6.6,3.57]],"id":42189436},{"spn":9.75,"spf":1.0,"id":42189436},{"atl":[[10.5,1.42],[11.5,0],[12,1.69],[12.5,6.07],[14,7.69]],"id":42236670},{"atb":[[3.55,76.59],[3.3,18.42]],"id":42070475},{"atl":[[8,2.86],[12,9.09],[13.5,15.87],[14.5,3.7]],"id":42070475},{"spn":4.6,"spf":1.0,"id":42070475},{"atb":[[3.1,9.52],[3.3,0],[3.2,0]],"id":41523279},{"spn":5.15,"spf":1.0,"id":41523279},{"atl":[[6.8,1.35],[7,3.33]],"id":42236682},{"spn":5.2,"spf":1.0,"id":42236682},{"atb":[[3.3,43.48],[3.5,8]],"id":37174579},{"spn":11.4,"spf":1.0,"id":37174579}],"con":true,"img":false}]}
{"op":"mcm","clk":"5346627841","pt":1646092744049,"mc":[{"id":"1.195395443","rc":[{"atb":[[1.01,3.33]],"id":40917095}],"con":true,"img":false}]}
{"op":"mcm","clk":"5346627844","pt":1646092744153,"mc":[{"id":"1.195395443","rc":[{"atb":[[1.01,2.51],[9.8,0]],"id":40917095},{"atl":[[10.5,0]],"id":42236670}],"con":true,"img":false}]}
{"op":"mcm","clk":"5346627849","pt":1646092744254,"mc":[{"id":"1.195395443","rc":[{"atb":[[1.01,0.85]],"id":40917095},{"atl":[[12,3.11]],"id":42236670}],"con":true,"img":false}]}
{"op":"mcm","clk":"5346627855","pt":1646092744358,"mc":[{"id":"1.195395443","rc":[{"atb":[[1.01,0],[9.2,1.66]],"id":40917095},{"atb":[[1.01,2.53]],"id":42236670}],"con":true,"img":false}]}
{"op":"mcm","clk":"5346627861","pt":1646092744458,"mc":[{"id":"1.195395443","rc":[{"atb":[[9.2,2.51]],"id":40917095},{"atb":[[1.01,1.69]],"id":42236670}],"con":true,"img":false}]}
{"op":"mcm","clk":"5346627869","pt":1646092744664,"mc":[{"id":"1.195395443","rc":[{"atb":[[1.01,0]],"id":42236670}],"con":true,"img":false}]}
{"op":"mcm","clk":"5346627876","pt":1646092744764,"mc":[{"id":"1.195395443","rc":[{"atb":[[6.4,1.69]],"id":42236670}],"con":true,"img":false}]}
{"op":"mcm","clk":"5346627882","pt":1646092744869,"mc":[{"id":"1.195395443","rc":[{"atb":[[9.2,0.85]],"id":40917095},{"atb":[[6.2,1.65],[1.02,1.67]],"id":42236670}],"con":true,"img":false}]}
{"op":"mcm","clk":"5346627886","pt":1646092744970,"mc":[{"id":"1.195395443","rc":[{"atb":[[1.01,1.66]],"id":40917095}],"con":true,"img":false}]}
{"op":"mcm","clk":"5346627889","pt":1646092745074,"mc":[{"id":"1.195395443","rc":[{"atb":[[1.02,1.27]],"id":42236670}],"con":true,"img":false}]}
{"op":"mcm","clk":"5346627893","pt":1646092745277,"mc":[{"id":"1.195395443","rc":[{"atb":[[1.02,0]],"id":42236670},{"atb":[[6.2,5.65]],"id":41523279},{"atl":[[6.2,0]],"id":41523279},{"trd":[[6.2,10.33]],"ltp":6.2,"tv":10.33,"id":41523279}],"con":true,"img":false}]}
{"op":"mcm","clk":"5346627896","pt":1646092745379,"mc":[{"id":"1.195395443","rc":[{"atb":[[6.6,1.27]],"id":42236670},{"atb":[[3.2,9.09]],"id":41523279},{"atl":[[6.4,3.7]],"id":41523279}],"con":true,"img":false}]}
{"op":"mcm","clk":"5346627899","pt":1646092745480,"mc":[{"id":"1.195395443","rc":[{"atl":[[12,1.42]],"id":42236670},{"atb":[[4.1,1.64]],"id":41523279},{"atl":[[7,15.63]],"id":41523279}],"con":true,"img":false}]}
{"op":"mcm","clk":"5346627902","pt":1646092745583,"mc":[{"id":"1.195395443","rc":[{"atl":[[7.4,0],[6.6,0],[7,3.13]],"id":41523279}],"con":true,"img":false}]}
{"op":"mcm","clk":"5346627921","pt":1646092746148,"mc":[{"id":"1.195395443","rc":[{"atb":[[4.6,0]],"id":37174579}],"con":true,"img":false}]}
{"op":"mcm","clk":"5346627927","pt":1646092746250,"mc":[{"id":"1.195395443","rc":[{"atb":[[4.4,26.51]],"id":37174579}],"con":true,"img":false}]}
{"op":"mcm","clk":"5346627961","pt":1646092747580,"mc":[{"id":"1.195395443","rc":[{"atl":[[18.5,8.57],[19.5,4.05]],"id":40917095}],"con":true,"img":false}]}
{"op":"mcm","clk":"5346628032","pt":1646092749584,"mc":[{"id":"1.195395443","rc":[{"atb":[[3.7,15.28]],"id":42236682},{"atb":[[6.2,0]],"id":37174579}],"con":true,"img":false}]}
{"op":"mcm","clk":"5346628054","pt":1646092750147,"mc":[{"id":"1.195395443","rc":[{"atl":[[12,3.11]],"id":42236670}],"con":true,"img":false}]}
{"op":"mcm","clk":"5346628057","pt":1646092750255,"mc":[{"id":"1.195395443","rc":[{"atl":[[6.4,0]],"id":41523279}],"con":true,"img":false}]}
{"op":"mcm","clk":"5346628062","pt":1646092750353,"mc":[{"id":"1.195395443","rc":[{"atl":[[7.2,0],[9.8,11.36]],"id":41523279}],"con":true,"img":false}]}
{"op":"mcm","clk":"5346628070","pt":1646092750760,"mc":[{"id":"1.195395443","rc":[{"spl":[[1.01,5.95]],"id":41523279}],"con":true,"img":false}]}
{"op":"mcm","clk":"5346628089","pt":1646092751477,"mc":[{"id":"1.195395443","rc":[{"atl":[[12,1.42]],"id":42236670}],"con":true,"img":false}]}
{"op":"mcm","clk":"5346628097","pt":1646092751789,"mc":[{"id":"1.195395443","rc":[{"atb":[[6.4,0]],"id":42236670}],"con":true,"img":false}]}
{"op":"mcm","clk":"5346628104","pt":1646092751988,"mc":[{"id":"1.195395443","rc":[{"atb":[[1.02,1.67]],"id":42236670}],"con":true,"img":false}]}
{"op":"mcm","clk":"5346628108","pt":1646092752094,"mc":[{"id":"1.195395443","rc":[{"atb":[[6.6,0]],"id":42236670}],"con":true,"img":false}]}
{"op":"mcm","clk":"5346628112","pt":1646092752197,"mc":[{"id":"1.195395443","rc":[{"atb":[[1.02,1.27]],"id":42236670}],"con":true,"img":false}]}
{"op":"mcm","clk":"5346628118","pt":1646092752356,"mc":[{"id":"1.195395443","rc":[{"atb":[[1.02,0]],"id":42236670}],"con":true,"img":false}]}
{"op":"mcm","clk":"5346628122","pt":1646092752454,"mc":[{"id":"1.195395443","rc":[{"atb":[[6.4,1.27]],"id":42236670}],"con":true,"img":false}]}
{"op":"mcm","clk":"5346628127","pt":1646092752556,"mc":[{"id":"1.195395443","rc":[{"atl":[[13,7.69],[14,0]],"id":42236670}],"con":true,"img":false}]}
{"op":"mcm","clk":"5346628136","pt":1646092752965,"mc":[{"id":"1.195395443","rc":[{"atb":[[4,30.84]],"id":41523279}],"con":true,"img":false}]}
{"op":"mcm","clk":"5346628155","pt":1646092753683,"mc":[{"id":"1.195395443","rc":[{"atb":[[7.2,8.06]],"id":40917095},{"atb":[[6.2,9.62]],"id":42189436},{"atl":[[8.4,24.63]],"id":42070475},{"atl":[[7.4,7.81]],"id":42236682},{"atb":[[3.4,20.83]],"id":37174579}],"con":true,"img":false}]}
{"op":"mcm","clk":"5346628208","pt":1646092755481,"mc":[{"id":"1.195395443","rc":[{"atb":[[3.1,23.81]],"id":41523279},{"atl":[[7.4,7.33]],"id":41523279}],"con":true,"img":false}]}
{"op":"mcm","clk":"5346628211","pt":1646092755584,"mc":[{"id":"1.195395443","rc":[{"atl":[[1000,1.67]],"id":40917095}],"con":true,"img":false}]}
{"op":"mcm","clk":"5346628213","pt":1646092755688,"mc":[{"id":"1.195395443","rc":[{"atl":[[16.5,0]],"id":40917095}],"con":true,"img":false}]}
{"op":"mcm","clk":"5346628217","pt":1646092755790,"mc":[{"id":"1.195395443","rc":[{"atl":[[19.5,9.46],[1000,0.5]],"id":40917095}],"con":true,"img":false}]}
{"op":"mcm","clk":"5346628220","pt":1646092755891,"mc":[{"id":"1.195395443","rc":[{"atl":[[18.5,2.86]],"id":40917095}],"con":true,"img":false}]}
{"op":"mcm","clk":"5346628227","pt":1646092756046,"mc":[{"id":"1.195395443","rc":[{"atl":[[1000,0]],"id":40917095}],"con":true,"img":false}]}
{"op":"mcm","clk":"5346628231","pt":1646092756149,"mc":[{"id":"1.195395443","rc":[{"atl":[[18.5,4.27],[18,0.5]],"id":40917095}],"con":true,"img":false}]}
{"op":"mcm","clk":"5346628245","pt":1646092756457,"mc":[{"id":"1.195395443","rc":[{"atl":[[18.5,9.98],[19.5,4.05]],"id":40917095}],"con":true,"img":false}]}
{"op":"mcm","clk":"5346628263","pt":1646092756868,"mc":[{"id":"1.195395443","rc":[{"spl":[[1.01,2.7]],"id":42236670}],"con":true,"img":false}]}
{"op":"mcm","clk":"5346628292","pt":1646092757787,"mc":[{"id":"1.195395443","rc":[{"atb":[[4,0]],"id":41523279}],"con":true,"img":false}]}
{"op":"mcm","clk":"5346628351","pt":1646092759892,"mc":[{"id":"1.195395443","rc":[{"atb":[[5.3,0]],"id":42189436},{"atl":[[12,3.11]],"id":42236670},{"atb":[[3,0]],"id":37174579}],"con":true,"img":false}]}
{"op":"mcm","clk":"5346628354","pt":1646092759994,"mc":[{"id":"1.195395443","rc":[{"atb":[[5.9,0],[6.2,21.7],[6.6,0]],"id":40917095},{"atl":[[14.5,0],[15.5,0],[16.5,0]],"id":42070475},{"atl":[[8,0],[7.2,0],[7.6,0]],"id":42236682}],"con":true,"img":false}]}
{"op":"mcm","clk":"5346628367","pt":1646092760461,"mc":[{"id":"1.195395443","rc":[{"atl":[[6.8,0]],"id":42236682}],"con":true,"img":false}]}
{"op":"mcm","clk":"5346628371","pt":1646092760558,"mc":[{"id":"1.195395443","rc":[{"atl":[[1000,3.02],[6.6,0]],"id":42236682}],"con":true,"img":false}]}
{"op":"mcm","clk":"5346628377","pt":1646092760764,"mc":[{"id":"1.195395443","rc":[{"atl":[[1000,2.62]],"id":42236682}],"con":true,"img":false}]}
{"op":"mcm","clk":"5346628385","pt":1646092760970,"mc":[{"id":"1.195395443","rc":[{"atl":[[1000,1.35]],"id":42236682}],"con":true,"img":false}]}
{"op":"mcm","clk":"5346628389","pt":1646092761073,"mc":[{"id":"1.195395443","rc":[{"atl":[[6.8,1.27]],"id":42236682}],"con":true,"img":false}]}
{"op":"mcm","clk":"5346628421","pt":1646092762358,"mc":[{"id":"1.195395443","rc":[{"atb":[[3.85,2.76]],"id":42236682}],"con":true,"img":false}]}
{"op":"mcm","clk":"5346628431","pt":1646092762770,"mc":[{"id":"1.195395443","rc":[{"spl":[[1.01,5.41]],"id":37174579}],"con":true,"img":false}]}
{"op":"mcm","clk":"5346628436","pt":1646092762873,"mc":[{"id":"1.195395443","rc":[{"atb":[[3.8,2]],"id":42236682}],"con":true,"img":false}]}
{"op":"mcm","clk":"5346628439","pt":1646092762975,"mc":[{"id":"1.195395443","rc":[{"atb":[[3.85,4.45]],"id":42236682}],"con":true,"img":false}]}
{"op":"mcm","clk":"5346628449","pt":1646092763181,"mc":[{"id":"1.195395443","rc":[{"atb":[[6.2,0]],"id":40917095},{"atl":[[10,0]],"id":42236682},{"atl":[[19,7.79]],"id":37174579}],"con":true,"img":false}]}
{"op":"mcm","clk":"5346628452","pt":1646092763285,"mc":[{"id":"1.195395443","rc":[{"atb":[[5.6,21.7]],"id":40917095},{"atl":[[9.2,4.81]],"id":42236682},{"atl":[[18,2.7]],"id":37174579}],"con":true,"img":false}]}
{"op":"mcm","clk":"5346628462","pt":1646092763698,"mc":[{"id":"1.195395443","rc":[{"atb":[[6.8,18.48]],"id":40917095},{"atb":[[5.9,15.31]],"id":42189436},{"atl":[[8.8,9.62]],"id":42070475},{"atl":[[7.8,11.03]],"id":42236682},{"atb":[[3.3,76.09]],"id":37174579}],"con":true,"img":false}]}
{"op":"mcm","clk":"5346628483","pt":1646092764158,"mc":[{"id":"1.195395443","rc":[{"atl":[[1000,0]],"id":42236682}],"con":true,"img":false}]}
{"op":"mcm","clk":"5346628487","pt":1646092764261,"mc":[{"id":"1.195395443","rc":[{"atl":[[7,4.68]],"id":42236682}],"con":true,"img":false}]}
{"op":"mcm","clk":"5346628525","pt":1646092765497,"mc":[{"id":"1.195395443","rc":[{"atb":[[3,37.5]],"id":41523279},{"atl":[[7.8,10.35]],"id":41523279}],"con":true,"img":false}]}
{"op":"mcm","clk":"5346628531","pt":1646092765594,"mc":[{"id":"1.195395443","rc":[{"atl":[[9.8,0],[7.8,21.71]],"id":41523279}],"con":true,"img":false}]}
{"op":"mcm","clk":"5346628598","pt":1646092767498,"mc":[{"id":"1.195395443","rc":[{"atb":[[5.5,0]],"id":42189436},{"atl":[[12,1.42]],"id":42236670},{"atb":[[3.1,0]],"id":37174579}],"con":true,"img":false}]}
{"op":"mcm","clk":"5346628633","pt":1646092768160,"mc":[{"id":"1.195395443","rc":[{"atb":[[6.8,12.93]],"id":40917095},{"atb":[[5.4,0]],"id":37174579}],"con":true,"img":false}]}
{"op":"mcm","clk":"5346628637","pt":1646092768262,"mc":[{"id":"1.195395443","rc":[{"atb":[[8.2,6.95]],"id":40917095},{"atb":[[5.9,8.32]],"id":37174579}],"con":true,"img":false}]}
{"op":"mcm","clk":"5346628707","pt":1646092769908,"mc":[{"id":"1.195395443","rc":[{"atl":[[12,3.11]],"id":42236670}],"con":true,"img":false}]}
{"op":"mcm","clk":"5346628819","pt":1646092773196,"mc":[{"id":"1.195395443","rc":[{"atb":[[6.8,0]],"id":42189436}],"con":true,"img":false}]}
{"op":"mcm","clk":"5346628822","pt":1646092773295,"mc":[{"id":"1.195395443","rc":[{"atb":[[8.8,6.01]],"id":42189436}],"con":true,"img":false}]}
{"op":"mcm","clk":"5346628841","pt":1646092773705,"mc":[{"id":"1.195395443","rc":[{"atb":[[6.4,23.15]],"id":40917095},{"atb":[[5.7,26.6]],"id":42189436},{"atl":[[9.2,21.25]],"id":42070475},{"atb":[[3.2,56.82]],"id":37174579}],"con":true,"img":false}]}
{"op":"mcm","clk":"5346628847","pt":1646092773807,"mc":[{"id":"1.195395443","rc":[{"atl":[[8.2,17.36]],"id":42236682}],"con":true,"img":false}]}
{"op":"mcm","clk":"5346628897","pt":1646092775401,"mc":[{"id":"1.195395443","rc":[{"atl":[[12,1.42]],"id":42236670}],"con":true,"img":false}]}
{"op":"mcm","clk":"5346628899","pt":1646092775503,"mc":[{"id":"1.195395443","rc":[{"atb":[[2.96,146.61]],"id":41523279},{"atl":[[8.2,16.29]],"id":41523279}],"con":true,"img":false}]}
{"op":"mcm","clk":"5346628958","pt":1646092778076,"mc":[{"id":"1.195395443","rc":[{"atl":[[65,0]],"id":40917095},{"atl":[[65,2.04]],"id":42189436},{"atl":[[13,10.28],[18,0]],"id":42236682},{"atl":[[38,0],[18,0],[27,4.08]],"id":37174579}],"con":true,"img":false}]}
{"op":"mcm","clk":"5346628962","pt":1646092778174,"mc":[{"id":"1.195395443","rc":[{"atl":[[38,2.7]],"id":40917095},{"atl":[[44,2.99]],"id":42189436},{"atl":[[18.5,6.99]],"id":37174579}],"con":true,"img":false}]}
{"op":"mcm","clk":"5346629013","pt":1646092780017,"mc":[{"id":"1.195395443","rc":[{"atl":[[12,3.11]],"id":42236670}],"con":true,"img":false}]}
{"op":"mcm","clk":"5346629072","pt":1646092782117,"mc":[{"id":"1.195395443","rc":[{"atb":[[7.6,0],[7,23.96]],"id":40917095},{"atl":[[17,0],[18,1.68]],"id":40917095},{"atl":[[12,1.42],[13,0],[14,7.69]],"id":42236670},{"atb":[[3.6,21.34],[3.55,38.29]],"id":42070475}],"con":true,"img":false}]}
{"op":"mcm","clk":"5346629089","pt":1646092782784,"mc":[{"id":"1.195395443","rc":[{"atl":[[18.5,8.57]],"id":40917095}],"con":true,"img":false}]}
{"op":"mcm","clk":"5346629092","pt":1646092782887,"mc":[{"id":"1.195395443","rc":[{"atl":[[18,3.1],[19.5,9.46]],"id":40917095}],"con":true,"img":false}]}
{"op":"mcm","clk":"5346629095","pt":1646092782990,"mc":[{"id":"1.195395443","rc":[{"atb":[[7.2,0]],"id":40917095},{"atl":[[18,8.98],[18.5,2.86],[19.5,4.05]],"id":40917095},{"atl":[[12,3.11]],"id":42236670}],"con":true,"img":false}]}
{"op":"mcm","clk":"5346629101","pt":1646092783195,"mc":[{"id":"1.195395443","rc":[{"atl":[[9.2,15.24]],"id":42070475}],"con":true,"img":false}]}
{"op":"mcm","clk":"5346629106","pt":1646092783297,"mc":[{"id":"1.195395443","rc":[{"atl":[[8.6,6.01]],"id":42070475}],"con":true,"img":false}]}
{"op":"mcm","clk":"5346629261","pt":1646092788116,"mc":[{"id":"1.195395443","rc":[{"atb":[[2.48,0],[2.9,66.02]],"id":42236682}],"con":true,"img":false}]}
{"op":"mcm","clk":"5346629262","pt":1646092788219,"mc":[{"id":"1.195395443","rc":[{"atl":[[13,0]],"id":42070475}],"con":true,"img":false}]}
{"op":"mcm","clk":"5346629266","pt":1646092788322,"mc":[{"id":"1.195395443","rc":[{"atl":[[11.5,8.86]],"id":42070475}],"con":true,"img":false}]}
{"op":"mcm","clk":"5346629327","pt":1646092790827,"mc":[{"id":"1.195395443","rc":[{"atl":[[12,1.42]],"id":42236670}],"con":true,"img":false}]}
{"op":"mcm","clk":"5346629347","pt":1646092791700,"mc":[{"id":"1.195395443","rc":[{"atb":[[9.6,12.14]],"id":37174579}],"con":true,"img":false}]}
{"op":"mcm","clk":"5346629350","pt":1646092791802,"mc":[{"id":"1.195395443","rc":[{"atl":[[1000,1.67]],"id":42070475}],"con":true,"img":false}]}
{"op":"mcm","clk":"5346629356","pt":1646092792008,"mc":[{"id":"1.195395443","rc":[{"atl":[[1000,1.52]],"id":42070475}],"con":true,"img":false}]}
{"op":"mcm","clk":"5346629359","pt":1646092792116,"mc":[{"id":"1.195395443","rc":[{"atb":[[6.6,8.93]],"id":40917095},{"atl":[[19,2.78]],"id":40917095}],"con":true,"img":false}]}
{"op":"mcm","clk":"5346629362","pt":1646092792217,"mc":[{"id":"1.195395443","rc":[{"atl":[[1000,0]],"id":42070475}],"con":true,"img":false}]}
{"op":"mcm","clk":"5346629363","pt":1646092792317,"mc":[{"id":"1.195395443","rc":[{"atl":[[5.5,1.52]],"id":42070475}],"con":true,"img":false}]}
{"op":"mcm","clk":"5346629382","pt":1646092793096,"mc":[{"id":"1.195395443","rc":[{"atb":[[6.4,15.97]],"id":42189436},{"atl":[[12,3.11]],"id":42236670},{"atb":[[2.44,39.81]],"id":42070475},{"atb":[[2.82,37.95]],"id":41523279},{"atb":[[2.48,41.44]],"id":42236682}],"con":true,"img":false}]}
{"op":"mcm","clk":"5346629388","pt":1646092793198,"mc":[{"id":"1.195395443","rc":[{"atb":[[5.8,34.38]],"id":42189436},{"atb":[[2.82,0]],"id":42070475},{"atb":[[2.98,0]],"id":41523279},{"atb":[[2.9,0]],"id":42236682}],"con":true,"img":false}]}
{"op":"mcm","clk":"5346629395","pt":1646092793399,"mc":[{"id":"1.195395443","rc":[{"atl":[[13.5,17.31],[14,0]],"id":42236670}],"con":true,"img":false}]}
{"op":"mcm","clk":"5346629527","pt":1646092798130,"mc":[{"id":"1.195395443","rc":[{"atb":[[4.1,22.99]],"id":42236670},{"atl":[[34,10.48],[27,0]],"id":37174579}],"con":true,"img":false}]}
{"op":"mcm","clk":"5346629533","pt":1646092798336,"mc":[{"id":"1.195395443","rc":[{"atl":[[18.5,0],[19.5,0],[21,0]],"id":40917095},{"atl":[[12,1.42]],"id":42236670},{"atl":[[6.4,3.47],[7,0]],"id":41523279}],"con":true,"img":false}]}
{"op":"mcm","clk":"5346629536","pt":1646092798438,"mc":[{"id":"1.195395443","rc":[{"atl":[[7.4,22.95],[7.8,10.35]],"id":41523279}],"con":true,"img":false}]}
{"op":"mcm","clk":"5346629552","pt":1646092799004,"mc":[{"id":"1.195395443","rc":[{"atl":[[18,7.56]],"id":40917095}],"con":true,"img":false}]}
{"op":"mcm","clk":"5346629553","pt":1646092799106,"mc":[{"id":"1.195395443","rc":[{"atl":[[18,1.68],[27,3.85],[1000,1.41]],"id":40917095}],"con":true,"img":false}]}
{"op":"mcm","clk":"5346629617","pt":1646092801012,"mc":[{"id":"1.195395443","rc":[{"atb":[[8.4,10.52]],"id":40917095}],"con":true,"img":false}]}
{"op":"mcm","clk":"5346629621","pt":1646092801115,"mc":[{"id":"1.195395443","rc":[{"atb":[[1.01,3.33]],"id":40917095}],"con":true,"img":false}]}
{"op":"mcm","clk":"5346629624","pt":1646092801218,"mc":[{"id":"1.195395443","rc":[{"atb":[[9.2,0]],"id":40917095}],"con":true,"img":false}]}
{"op":"mcm","clk":"5346629628","pt":1646092801322,"mc":[{"id":"1.195395443","rc":[{"atb":[[1.01,2.51]],"id":40917095}],"con":true,"img":false}]}
{"op":"mcm","clk":"5346629637","pt":1646092801531,"mc":[{"id":"1.195395443","rc":[{"atb":[[1.01,1.66]],"id":40917095}],"con":true,"img":false}]}
{"op":"mcm","clk":"5346629642","pt":1646092801634,"mc":[{"id":"1.195395443","rc":[{"atb":[[8.6,0.85]],"id":40917095}],"con":true,"img":false}]}
{"op":"mcm","clk":"5346629654","pt":1646092802002,"mc":[{"id":"1.195395443","rc":[{"atb":[[6.2,14.42]],"id":40917095},{"atl":[[20,3.95]],"id":40917095}],"con":true,"img":false}]}
{"op":"mcm","clk":"5346629670","pt":1646092802411,"mc":[{"id":"1.195395443","rc":[{"atl":[[18.5,4.29]],"id":37174579}],"con":true,"img":false}]}
{"op":"mcm","clk":"5346629675","pt":1646092802515,"mc":[{"id":"1.195395443","rc":[{"atl":[[22,2.7]],"id":37174579}],"con":true,"img":false}]}
{"op":"mcm","clk":"5346629699","pt":1646092803027,"mc":[{"id":"1.195395443","rc":[{"atl":[[12,3.11]],"id":42236670}],"con":true,"img":false}]}
{"op":"mcm","clk":"5346629737","pt":1646092804119,"mc":[{"id":"1.195395443","rc":[{"atb":[[8,11.78],[9,5.15],[1.01,1.66],[8.2,6.94],[8.4,0],[5.6,21.68],[8.6,0.85],[5.5,36.65],[7,23.95]],"id":40917095},{"atl":[[18,1.68],[75,2.65],[38,2.7],[40,3.35],[50,2.67],[100,1.98],[28,2.7],[1000,1.41]],"id":40917095},{"spn":13.5,"spf":1.0,"id":40917095},{"atb":[[6.4,15.96],[5.8,34.36],[9.6,5.96],[8.6,10.85],[7.6,18.74],[9.8,2.45],[8.8,6]],"id":42189436},{"spl":[[9.6,3.24]],"id":42189436},{"atl":[[32,2.7],[130,1.51],[44,2.99],[46,2.9],[1000,1.42],[65,2.04],[18,0.47],[90,2.2]],"id":42189436},{"atb":[[6.4,1.26],[5.4,0.19],[5.6,13.18],[4,54.08],[5,42.92],[6.2,1.65],[5.5,18.02],[4.1,22.98],[6,8.11]],"id":42236670},{"spl":[[1.01,2.7]],"id":42236670},{"atl":[[34,6],[18,2.7],[18.5,7.55],[21,5.97],[22,6.29],[12,3.11],[27,7.62]],"id":42236670},{"trd":[[10.5,0.86],[9.8,4.54]],"ltp":10.5,"tv":5.4,"id":42236670},{"spn":6.29,"spf":1.0,"id":42236670},{"atb":[[2.8,90.14],[3.6,21.34],[3,60.84],[2.44,39.79],[3.55,38.28],[3.25,44.94],[3.5,16.52],[3.3,18.41]],"id":42070475},{"atl":[[11,19.82],[11.5,8.85],[13.5,15.86],[8.4,24.62],[9.4,15.73],[5.6,4.05],[8.6,6],[5.5,1.52]],"id":42070475},{"spn":4.55,"spf":1.0,"id":42070475},{"atb":[[2.82,37.93],[3.75,0.28],[6.2,5.65],[3.95,14.66],[4.1,1.64],[3.7,5.84],[3.4,50.7],[3.9,13.98],[2.96,146.56],[3.65,30.61]],"id":41523279},{"spl":[[1.01,5.94]],"id":41523279},{"atl":[[18,11.66],[10,4.91],[10.5,13.91],[12.5,10.43],[13,11.01],[15.5,13.67]],"id":41523279},{"trd":[[6.2,10.32]],"ltp":6.2,"tv":10.32,"id":41523279},{"spn":6.09,"spf":1.0,"id":41523279},{"atb":[[3.85,4.45],[3.55,0.29],[3.5,16.02],[2.48,41.41],[3.45,74.48],[3.2,90.32],[2.88,87.74],[3.7,15.27]],"id":42236682},{"atl":[[9.2,4.8],[11,13.08],[6.8,1.26],[13,10.27],[13.5,15.7],[9.4,15.57],[16,13.08],[7,4.68]],"id":42236682},{"spn":5.32,"spf":1.0,"id":42236682},{"atb":[[4.3,44.25],[5.8,15.21],[5.3,25.46],[6.8,1.59],[4.4,26.5],[5.9,8.31],[9.6,12.13],[6.6,8.31]],"id":37174579},{"spl":[[1.01,5.4]],"id":37174579},{"atl":[[34,10.47],[36,6.01],[16,0.51],[16.5,2.68],[19,7.79],[22,2.7],[23,6.37],[28,7.79]],"id":37174579},{"trd":[[7,21.63]],"ltp":7.0,"tv":21.63,"id":37174579},{"spn":9.6,"spf":1.0,"id":37174579}],"con":true,"img":false}]}
{"op":"mcm","clk":"5346629842","pt":1646092807318,"mc":[{"id":"1.195395443","rc":[{"atb":[[6.4,0],[6.8,0]],"id":40917095},{"atl":[[12,1.42]],"id":42236670}],"con":true,"img":false}]}
{"op":"mcm","clk":"5346629849","pt":1646092807420,"mc":[{"id":"1.195395443","rc":[{"atl":[[20,8.42]],"id":40917095}],"con":true,"img":false}]}
{"op":"mcm","clk":"5346629852","pt":1646092807521,"mc":[{"id":"1.195395443","rc":[{"atl":[[27,0]],"id":40917095}],"con":true,"img":false}]}
{"op":"mcm","clk":"5346629875","pt":1646092808136,"mc":[{"id":"1.195395443","rc":[{"atl":[[38,6.14]],"id":40917095},{"atl":[[44,5.35]],"id":42189436},{"atl":[[21,9.62]],"id":42236670},{"atl":[[11.5,21.84]],"id":42070475},{"atl":[[13,21.24]],"id":42236682}],"con":true,"img":false}]}
{"op":"mcm","clk":"5346629883","pt":1646092808342,"mc":[{"id":"1.195395443","rc":[{"atl":[[8.6,0]],"id":42070475},{"atl":[[6.8,8.09]],"id":41523279},{"atb":[[5.9,0]],"id":37174579}],"con":true,"img":false}]}
{"op":"mcm","clk":"5346629889","pt":1646092808444,"mc":[{"id":"1.195395443","rc":[{"atl":[[8.2,6]],"id":42070475},{"atb":[[6,8.31]],"id":37174579}],"con":true,"img":false}]}
{"op":"mcm","clk":"5346630016","pt":1646092812153,"mc":[{"id":"1.195395443","rc":[{"atb":[[5.9,25.51]],"id":40917095},{"atl":[[22,5.95]],"id":40917095}],"con":true,"img":false}]}
{"op":"mcm","clk":"5346630047","pt":1646092813030,"mc":[{"id":"1.195395443","rc":[{"atl":[[12,3.11]],"id":42236670}],"con":true,"img":false}]}
{"op":"mcm","clk":"5346630152","pt":1646092815762,"mc":[{"id":"1.195395443","rc":[{"atl":[[12,1.42]],"id":42236670},{"atl":[[8.2,0],[7.4,15.62],[7.8,0]],"id":41523279}],"con":true,"img":false}]}
{"op":"mcm","clk":"5346630163","pt":1646092815968,"mc":[{"id":"1.195395443","rc":[{"atl":[[4.2,2.7]],"id":42070475}],"con":true,"img":false}]}
{"op":"mcm","clk":"5346630171","pt":1646092816125,"mc":[{"id":"1.195395443","rc":[{"atb":[[1.01,3.33],[8.6,0]],"id":40917095}],"con":true,"img":false}]}
{"op":"mcm","clk":"5346630181","pt":1646092816331,"mc":[{"id":"1.195395443","rc":[{"atb":[[1.01,2.57]],"id":40917095},{"atb":[[3.6,19.69]],"id":42070475}],"con":true,"img":false}]}
{"op":"mcm","clk":"5346630186","pt":1646092816433,"mc":[{"id":"1.195395443","rc":[{"atb":[[1.01,1.64]],"id":42070475}],"con":true,"img":false}]}
{"op":"mcm","clk":"5346630190","pt":1646092816536,"mc":[{"id":"1.195395443","rc":[{"atb":[[1.01,1.66]],"id":40917095}],"con":true,"img":false}]}
{"op":"mcm","clk":"5346630195","pt":1646092816640,"mc":[{"id":"1.195395443","rc":[{"atb":[[9.2,0.91]],"id":40917095}],"con":true,"img":false}]}
{"op":"mcm","clk":"5346630248","pt":1646092818342,"mc":[{"id":"1.195395443","rc":[{"atl":[[7.2,11.35]],"id":41523279}],"con":true,"img":false}]}
{"op":"mcm","clk":"5346630253","pt":1646092818446,"mc":[{"id":"1.195395443","rc":[{"atl":[[7.4,0],[7,11.56]],"id":41523279}],"con":true,"img":false}]}
{"op":"mcm","clk":"5346630255","pt":1646092818571,"mc":[{"id":"1.195395443","rc":[{"atb":[[7.6,3.03],[7,20.62]],"id":40917095},{"atl":[[17,1.25],[18,0.5]],"id":40917095},{"atb":[[6.2,0],[6,4],[6.6,0]],"id":42189436},{"atl":[[20,0],[21,7.59]],"id":42189436},{"atb":[[3.55,0],[3.25,44.44]],"id":42236670},{"atl":[[12,9.18],[13.5,9.31]],"id":42236670},{"atb":[[3.6,3.15],[3.2,39.4]],"id":42070475},{"atl":[[12,0],[8.8,22.44]],"id":42070475},{"atb":[[2.8,0],[3.05,37.93]],"id":41523279},{"atl":[[8,14.29]],"id":41523279},{"atb":[[3.45,33.66],[3.15,46.51]],"id":42236682},{"atl":[[10.5,0],[8.4,13.51]],"id":42236682},{"atb":[[3.5,0],[3.65,7.55]],"id":37174579},{"atl":[[40,0],[55,2],[16.5,1.39],[17.5,0],[18.5,0],[21,1]],"id":37174579}],"con":true,"img":false}]}
{"op":"mcm","clk":"5346630259","pt":1646092818663,"mc":[{"id":"1.195395443","rc":[{"atl":[[7,0]],"id":41523279}],"con":true,"img":false}]}
{"op":"mcm","clk":"5346630263","pt":1646092818757,"mc":[{"id":"1.195395443","rc":[{"atl":[[1000,3.08],[18,0],[18.5,5.71],[20,3.95]],"id":40917095}],"con":true,"img":false}]}
{"op":"mcm","clk":"5346630273","pt":1646092818963,"mc":[{"id":"1.195395443","rc":[{"atl":[[1000,1.92]],"id":40917095},{"atb":[[3.55,2]],"id":42070475}],"con":true,"img":false}]}
{"op":"mcm","clk":"5346630277","pt":1646092819065,"mc":[{"id":"1.195395443","rc":[{"atl":[[1000,0]],"id":40917095},{"atl":[[16.5,0]],"id":37174579}],"con":true,"img":false}]}
{"op":"mcm","clk":"5346630284","pt":1646092819167,"mc":[{"id":"1.195395443","rc":[{"atl":[[18.5,6.21],[18,1.41]],"id":40917095},{"atl":[[18.5,1.39]],"id":37174579}],"con":true,"img":false}]}
{"op":"mcm","clk":"5346630317","pt":1646092820043,"mc":[{"id":"1.195395443","rc":[{"atb":[[4,0],[4.6,27.78]],"id":40917095}],"con":true,"img":false}]}
{"op":"mcm","clk":"5346630353","pt":1646092821335,"mc":[{"id":"1.195395443","rc":[{"atb":[[3.6,0],[3.55,0]],"id":42070475},{"atl":[[3.55,11.6]],"id":42070475},{"trd":[[3.55,4],[3.6,6.31]],"ltp":3.55,"tv":10.3,"id":42070475}],"con":true,"img":false}]}
{"op":"mcm","clk":"5346630362","pt":1646092821540,"mc":[{"id":"1.195395443","rc":[{"atl":[[4.3,2.64],[3.55,0]],"id":42070475},{"trd":[[3.55,27.21]],"ltp":3.55,"tv":27.21,"id":42070475}],"con":true,"img":false}]}
{"op":"mcm","clk":"5346630371","pt":1646092821764,"mc":[{"id":"1.195395443","rc":[{"atl":[[1000,2.23]],"id":42236670},{"atl":[[1000,2.23]],"id":42236682},{"atl":[[1000,2.23]],"id":37174579}],"con":true,"img":false}]}
{"op":"mcm","clk":"5346630383","pt":1646092821870,"mc":[{"id":"1.195395443","rc":[{"atb":[[7.8,4]],"id":42236670}],"con":true,"img":false}]}
{"op":"mcm","clk":"5346630429","pt":1646092823151,"mc":[{"id":"1.195395443","rc":[{"atl":[[13,23.65]],"id":42070475},{"atb":[[2.6,51.93]],"id":41523279}],"con":true,"img":false}]}
{"op":"mcm","clk":"5346630431","pt":1646092823255,"mc":[{"id":"1.195395443","rc":[{"atb":[[6.4,0]],"id":42189436},{"atl":[[11.5,0]],"id":42070475},{"atb":[[2.82,0]],"id":41523279}],"con":true,"img":false}]}
{"op":"mcm","clk":"5346630436","pt":1646092823356,"mc":[{"id":"1.195395443","rc":[{"atb":[[6,19.96]],"id":42189436}],"con":true,"img":false}]}
{"op":"mcm","clk":"5346630438","pt":1646092823459,"mc":[{"id":"1.195395443","rc":[{"atl":[[12,3]],"id":42189436}],"con":true,"img":false}]}
{"op":"mcm","clk":"5346630442","pt":1646092823560,"mc":[{"id":"1.195395443","rc":[{"atb":[[8,2]],"id":42236670},{"atl":[[12,7.49],[1000,0.14]],"id":42236670},{"atl":[[1000,0.14]],"id":42236682},{"atl":[[1000,0.14]],"id":37174579}],"con":true,"img":false}]}
{"op":"mcm","clk":"5346630448","pt":1646092823665,"mc":[{"id":"1.195395443","rc":[{"atl":[[11.5,2]],"id":42189436},{"atb":[[8.2,4]],"id":42236670},{"atl":[[12,9.18]],"id":42236670},{"atl":[[19.5,0]],"id":37174579}],"con":true,"img":false}]}
{"op":"mcm","clk":"5346630454","pt":1646092823774,"mc":[{"id":"1.195395443","rc":[{"atl":[[12,3.11],[13.5,17.31]],"id":42236670}],"con":true,"img":false}]}
{"op":"mcm","clk":"5346630462","pt":1646092823974,"mc":[{"id":"1.195395443","rc":[{"atl":[[18.5,0]],"id":37174579}],"con":true,"img":false}]}
{"op":"mcm","clk":"5346630466","pt":1646092824074,"mc":[{"id":"1.195395443","rc":[{"atl":[[1000,1.54]],"id":37174579}],"con":true,"img":false}]}
{"op":"mcm","clk":"5346630473","pt":1646092824237,"mc":[{"id":"1.195395443","rc":[{"atb":[[9.8,0.85]],"id":42189436},{"atl":[[1000,0]],"id":42236682}],"con":true,"img":false}]}
{"op":"mcm","clk":"5346630476","pt":1646092824339,"mc":[{"id":"1.195395443","rc":[{"atb":[[1.01,1.6]],"id":42189436},{"atl":[[7,4.83]],"id":42236682}],"con":true,"img":false}]}
{"op":"mcm","clk":"5346630480","pt":1646092824441,"mc":[{"id":"1.195395443","rc":[{"atl":[[1000,0.14]],"id":37174579}],"con":true,"img":false}]}
{"op":"mcm","clk":"5346630485","pt":1646092824543,"mc":[{"id":"1.195395443","rc":[{"atl":[[18.5,1.39]],"id":37174579}],"con":true,"img":false}]}
{"op":"mcm","clk":"5346630497","pt":1646092824851,"mc":[{"id":"1.195395443","rc":[{"atl":[[11,2]],"id":42189436},{"atb":[[8.4,2]],"id":42236670},{"atl":[[12,1.42]],"id":42236670}],"con":true,"img":false}]}
{"op":"mcm","clk":"5346630513","pt":1646092825156,"mc":[{"id":"1.195395443","rc":[{"atl":[[18.5,0]],"id":37174579}],"con":true,"img":false}]}
{"op":"mcm","clk":"5346630520","pt":1646092825260,"mc":[{"id":"1.195395443","rc":[{"atl":[[1000,1.54]],"id":37174579}],"con":true,"img":false}]}
{"op":"mcm","clk":"5346630524","pt":1646092825463,"mc":[{"id":"1.195395443","rc":[{"atl":[[1000,0]],"id":42236670}],"con":true,"img":false}]}
{"op":"mcm","clk":"5346630528","pt":1646092825565,"mc":[{"id":"1.195395443","rc":[{"atl":[[12.5,6.21]],"id":42236670}],"con":true,"img":false}]}
{"op":"mcm","clk":"5346630578","pt":1646092826746,"mc":[{"id":"1.195395443","rc":[{"atl":[[12,7.64]],"id":42236670},{"atb":[[3.2,0],[3.3,57.81]],"id":42070475}],"con":true,"img":false}]}
{"op":"mcm","clk":"5346630584","pt":1646092826847,"mc":[{"id":"1.195395443","rc":[{"atl":[[13.5,9.31]],"id":42236670}],"con":true,"img":false}]}
