{"op":"mcm","clk":"5345904407","pt":1646079078752,"mc":[{"id":"1.195395448","marketDefinition":{"bspMarket":false,"turnInPlayEnabled":false,"persistenceEnabled":false,"marketBaseRate":5.0,"eventId":"31270459","eventTypeId":"4339","numberOfWinners":3,"bettingType":"ODDS","marketType":"PLACE","marketTime":"2022-03-01T00:47:00.000Z","suspendTime":"2022-03-01T00:47:00.000Z","bspReconciled":false,"complete":true,"inPlay":false,"crossMatching":false,"runnersVoidable":false,"numberOfActiveRunners":8,"betDelay":0,"status":"OPEN","runners":[{"status":"ACTIVE","sortPriority":1,"id":38541023,"name":"2. Know Beast"},{"status":"ACTIVE","sortPriority":2,"id":43154430,"name":"3. Gandia"},{"status":"ACTIVE","sortPriority":3,"id":42315317,"name":"4. Homebush Villa"},{"status":"ACTIVE","sortPriority":4,"id":40014837,"name":"5. Goldstar Farryn"},{"status":"ACTIVE","sortPriority":5,"id":37535509,"name":"6. King Kong Blonde"},{"status":"ACTIVE","sortPriority":6,"id":37076580,"name":"7. Mitcham Hamish"},{"status":"ACTIVE","sortPriority":7,"id":36899944,"name":"8. Goldstar Willa"},{"status":"ACTIVE","sortPriority":8,"id":40041375,"name":"9. Homebush George"}],"regulators":["MR_INT"],"venue":"Addington","countryCode":"NZ","discountAllowed":false,"timezone":"NZ","openDate":"2022-02-28T23:02:00.000Z","version":4380660707,"name":"To Be Placed","eventName":"Addington (NZL) 1st Mar"},"rc":[],"con":true,"img":false}]}
{"op":"mcm","clk":"5345904738","pt":1646079081735,"mc":[{"id":"1.195395448","marketDefinition":{"bspMarket":false,"turnInPlayEnabled":false,"persistenceEnabled":false,"marketBaseRate":5.0,"eventId":"31270459","eventTypeId":"4339","numberOfWinners":3,"bettingType":"ODDS","marketType":"PLACE","marketTime":"2022-03-01T00:47:00.000Z","suspendTime":"2022-03-01T00:47:00.000Z","bspReconciled":false,"complete":true,"inPlay":false,"crossMatching":false,"runnersVoidable":false,"numberOfActiveRunners":8,"betDelay":0,"status":"OPEN","runners":[{"status":"ACTIVE","sortPriority":1,"id":38541023,"name":"2. Know Beast"},{"status":"ACTIVE","sortPriority":2,"id":43154430,"name":"3. Gandia"},{"status":"ACTIVE","sortPriority":3,"id":42315317,"name":"4. Homebush Villa"},{"status":"ACTIVE","sortPriority":4,"id":40014837,"name":"5. Goldstar Farryn"},{"status":"ACTIVE","sortPriority":5,"id":37535509,"name":"6. King Kong Blonde"},{"status":"ACTIVE","sortPriority":6,"id":37076580,"name":"7. Mitcham Hamish"},{"status":"ACTIVE","sortPriority":7,"id":36899944,"name":"8. Goldstar Willa"},{"status":"ACTIVE","sortPriority":8,"id":40041375,"name":"9. Homebush George"}],"regulators":["MR_INT"],"venue":"Addington","countryCode":"NZ","discountAllowed":true,"timezone":"NZ","openDate":"2022-02-28T23:02:00.000Z","version":4380660707,"name":"To Be Placed","eventName":"Addington (NZL) 1st Mar"},"rc":[],"con":true,"img":false}]}
{"op":"mcm","clk":"5346126555","pt":1646081524658,"mc":[{"id":"1.195395448","rc":[{"atb":[[2.86,64.6],[3.15,27.94],[2.96,61.31]],"id":40014837},{"atl":[[16,1.6],[34,1.45],[11,1.2],[22,1.14],[8.4,1.62]],"id":40014837},{"atb":[[2,120.16],[2.2,50.07],[2.1,109.24]],"id":38541023},{"atl":[[17.5,2.91],[9,3],[5.5,2.66],[12.5,2.08],[7,2]],"id":38541023},{"atb":[[2.86,64.6],[3.15,27.94],[2.96,61.31]],"id":37535509},{"atl":[[16,1.6],[34,1.45],[11,1.2],[22,1.14],[8.4,1.62]],"id":37535509},{"atb":[[2.88,63.92],[2.98,30.34],[2.78,67.51]],"id":36899944},{"atl":[[32,1.54],[10.5,1.26],[21,1.2],[8.2,1.66],[15.5,1.65]],"id":36899944},{"atb":[[1.18,667.6],[1.23,261.23],[1.13,924.37]],"id":42315317},{"atl":[[3.45,19.61],[2.38,8.7],[2.58,7.6],[2.98,12.13],[2.78,13.5]],"id":42315317},{"atb":[[2,120.16],[2.2,50.07],[2.1,109.24]],"id":40041375},{"atl":[[17.5,2.91],[9,3],[5.5,2.66],[12.5,2.08],[7,2]],"id":40041375},{"atb":[[1.12,1001.4],[1.07,1716.69],[1.17,353.43]],"id":43154430},{"atl":[[2.86,12.92],[2.46,8.23],[2.66,14.47],[3.15,22.35],[2.26,9.53]],"id":43154430},{"atb":[[1.4,300.42],[1.45,267.04],[1.5,120.16]],"id":37076580},{"atl":[[3.45,9.8],[3.95,8.14],[4.9,12.32],[2.98,6.06],[2.78,6.75]],"id":37076580}],"con":true,"img":false}]}
{"op":"mcm","clk":"5346128165","pt":1646081544775,"mc":[{"id":"1.195395448","rc":[{"atb":[[2.86,0],[3.15,0],[2.96,0]],"id":40014837},{"atl":[[16,0],[34,0],[11,0],[22,0],[8.4,0]],"id":40014837},{"atb":[[2,0],[2.2,0],[2.1,0]],"id":38541023},{"atl":[[17.5,0],[9,0],[5.5,0],[12.5,0],[7,0]],"id":38541023},{"atb":[[2.86,0],[3.15,0],[2.96,0]],"id":37535509},{"atl":[[16,0],[34,0],[11,0],[22,0],[8.4,0]],"id":37535509},{"atb":[[2.88,0],[2.98,0],[2.78,0]],"id":36899944},{"atl":[[32,0],[10.5,0],[21,0],[8.2,0],[15.5,0]],"id":36899944},{"atb":[[1.18,0],[1.23,0],[1.13,0]],"id":42315317},{"atl":[[3.45,0],[2.38,0],[2.58,0],[2.98,0],[2.78,0]],"id":42315317},{"atb":[[2,0],[2.2,0],[2.1,0]],"id":40041375},{"atl":[[17.5,0],[9,0],[5.5,0],[12.5,0],[7,0]],"id":40041375},{"atb":[[1.12,0],[1.07,0],[1.17,0]],"id":43154430},{"atl":[[2.86,0],[2.46,0],[2.66,0],[3.15,0],[2.26,0]],"id":43154430},{"atb":[[1.4,0],[1.45,0],[1.5,0]],"id":37076580},{"atl":[[3.45,0],[3.95,0],[4.9,0],[2.98,0],[2.78,0]],"id":37076580}],"con":true,"img":false}]}
{"op":"mcm","clk":"5346129273","pt":1646081558930,"mc":[{"id":"1.195395448","rc":[{"atb":[[2.86,64.6],[3.15,27.94],[2.96,61.31]],"id":40014837},{"atl":[[16,1.6],[34,1.45],[11,1.2],[22,1.14],[8.4,1.62]],"id":40014837},{"atb":[[2,120.16],[2.2,50.07],[2.1,109.24]],"id":38541023},{"atl":[[17.5,2.91],[9,3],[5.5,2.66],[12.5,2.08],[7,2]],"id":38541023},{"atb":[[2.86,64.6],[3.15,27.94],[2.96,61.31]],"id":37535509},{"atl":[[16,1.6],[34,1.45],[11,1.2],[22,1.14],[8.4,1.62]],"id":37535509},{"atb":[[2.88,63.92],[2.98,30.34],[2.78,67.51]],"id":36899944},{"atl":[[32,1.54],[10.5,1.26],[21,1.2],[8.2,1.66],[15.5,1.65]],"id":36899944},{"atb":[[1.18,667.6],[1.23,261.23],[1.13,924.37]],"id":42315317},{"atl":[[3.45,19.61],[2.38,8.7],[2.58,7.6],[2.98,12.13],[2.78,13.5]],"id":42315317},{"atb":[[2,120.16],[2.2,50.07],[2.1,109.24]],"id":40041375},{"atl":[[17.5,2.91],[9,3],[5.5,2.66],[12.5,2.08],[7,2]],"id":40041375},{"atb":[[1.12,1001.4],[1.07,1716.69],[1.17,353.43]],"id":43154430},{"atl":[[2.86,12.92],[2.46,8.23],[2.66,14.47],[3.15,22.35],[2.26,9.53]],"id":43154430},{"atb":[[1.4,150.21],[1.3,400.56],[1.35,343.34]],"id":37076580},{"atl":[[4.3,14.56],[2.86,6.46],[2.66,7.23],[3.15,11.17],[3.65,9.06]],"id":37076580}],"con":true,"img":false}]}
{"op":"mcm","clk":"5346130668","pt":1646081577195,"mc":[{"id":"1.195395448","rc":[{"atb":[[2.86,0],[3.15,0],[2.96,0]],"id":40014837},{"atl":[[16,0],[34,0],[11,0],[22,0],[8.4,0]],"id":40014837},{"atb":[[2,0],[2.2,0],[2.1,0]],"id":38541023},{"atl":[[17.5,0],[9,0],[5.5,0],[12.5,0],[7,0]],"id":38541023},{"atb":[[2.86,0],[3.15,0],[2.96,0]],"id":37535509},{"atl":[[16,0],[34,0],[11,0],[22,0],[8.4,0]],"id":37535509},{"atb":[[2.88,0],[2.98,0],[2.78,0]],"id":36899944},{"atl":[[32,0],[10.5,0],[21,0],[8.2,0],[15.5,0]],"id":36899944},{"atb":[[1.18,0],[1.23,0],[1.13,0]],"id":42315317},{"atl":[[3.45,0],[2.38,0],[2.58,0],[2.98,0],[2.78,0]],"id":42315317},{"atb":[[2,0],[2.2,0],[2.1,0]],"id":40041375},{"atl":[[17.5,0],[9,0],[5.5,0],[12.5,0],[7,0]],"id":40041375},{"atb":[[1.12,0],[1.07,0],[1.17,0]],"id":43154430},{"atl":[[2.86,0],[2.46,0],[2.66,0],[3.15,0],[2.26,0]],"id":43154430},{"atb":[[1.4,0],[1.3,0],[1.35,0]],"id":37076580},{"atl":[[4.3,0],[2.86,0],[2.66,0],[3.15,0],[3.65,0]],"id":37076580}],"con":true,"img":false}]}
{"op":"mcm","clk":"5346131645","pt":1646081590850,"mc":[{"id":"1.195395448","rc":[{"atb":[[2.86,64.6],[3.15,27.94],[2.96,61.31]],"id":40014837},{"atl":[[16,1.6],[34,1.45],[11,1.2],[22,1.14],[8.4,1.62]],"id":40014837},{"atb":[[2,120.16],[2.2,50.07],[2.1,109.24]],"id":38541023},{"atl":[[17.5,2.91],[9,3],[5.5,2.66],[12.5,2.08],[7,2]],"id":38541023},{"atb":[[2.86,64.6],[3.15,27.94],[2.96,61.31]],"id":37535509},{"atl":[[16,1.6],[34,1.45],[11,1.2],[22,1.14],[8.4,1.62]],"id":37535509},{"atb":[[2.88,63.92],[2.98,30.34],[2.78,67.51]],"id":36899944},{"atl":[[32,1.54],[10.5,1.26],[21,1.2],[8.2,1.66],[15.5,1.65]],"id":36899944},{"atb":[[1.18,667.6],[1.23,261.23],[1.13,924.37]],"id":42315317},{"atl":[[3.45,19.61],[2.38,8.7],[2.58,7.6],[2.98,12.13],[2.78,13.5]],"id":42315317},{"atb":[[2,120.16],[2.2,50.07],[2.1,109.24]],"id":40041375},{"atl":[[17.5,2.91],[9,3],[5.5,2.66],[12.5,2.08],[7,2]],"id":40041375},{"atb":[[1.12,1001.4],[1.07,1716.69],[1.17,353.43]],"id":43154430},{"atl":[[2.86,12.92],[2.46,8.23],[2.66,14.47],[3.15,22.35],[2.26,9.53]],"id":43154430},{"atb":[[1.4,150.21],[1.3,400.56],[1.35,343.34]],"id":37076580},{"atl":[[4.3,14.56],[2.86,6.46],[2.66,7.23],[3.15,11.17],[3.65,9.06]],"id":37076580}],"con":true,"img":false}]}
{"op":"mcm","clk":"5346132691","pt":1646081605422,"mc":[{"id":"1.195395448","rc":[{"atb":[[2.86,0],[3.15,0],[2.96,0]],"id":40014837},{"atl":[[16,0],[34,0],[11,0],[22,0],[8.4,0]],"id":40014837},{"atb":[[2,0],[2.2,0],[2.1,0]],"id":38541023},{"atl":[[17.5,0],[9,0],[5.5,0],[12.5,0],[7,0]],"id":38541023},{"atb":[[2.86,0],[3.15,0],[2.96,0]],"id":37535509},{"atl":[[16,0],[34,0],[11,0],[22,0],[8.4,0]],"id":37535509},{"atb":[[2.88,0],[2.98,0],[2.78,0]],"id":36899944},{"atl":[[32,0],[10.5,0],[21,0],[8.2,0],[15.5,0]],"id":36899944},{"atb":[[1.18,0],[1.23,0],[1.13,0]],"id":42315317},{"atl":[[3.45,0],[2.38,0],[2.58,0],[2.98,0],[2.78,0]],"id":42315317},{"atb":[[2,0],[2.2,0],[2.1,0]],"id":40041375},{"atl":[[17.5,0],[9,0],[5.5,0],[12.5,0],[7,0]],"id":40041375},{"atb":[[1.12,0],[1.07,0],[1.17,0]],"id":43154430},{"atl":[[2.86,0],[2.46,0],[2.66,0],[3.15,0],[2.26,0]],"id":43154430},{"atb":[[1.4,0],[1.3,0],[1.35,0]],"id":37076580},{"atl":[[4.3,0],[2.86,0],[2.66,0],[3.15,0],[3.65,0]],"id":37076580}],"con":true,"img":false}]}
{"op":"mcm","clk":"5346133741","pt":1646081621322,"mc":[{"id":"1.195395448","rc":[{"atb":[[2.86,64.6],[3.15,27.94],[2.96,61.31]],"id":40014837},{"atl":[[16,1.6],[34,1.45],[11,1.2],[22,1.14],[8.4,1.62]],"id":40014837},{"atb":[[2,120.16],[2.2,50.07],[2.1,109.24]],"id":38541023},{"atl":[[17.5,2.91],[9,3],[5.5,2.66],[12.5,2.08],[7,2]],"id":38541023},{"atb":[[2.86,64.6],[3.15,27.94],[2.96,61.31]],"id":37535509},{"atl":[[16,1.6],[34,1.45],[11,1.2],[22,1.14],[8.4,1.62]],"id":37535509},{"atb":[[2.88,63.92],[2.98,30.34],[2.78,67.51]],"id":36899944},{"atl":[[32,1.54],[10.5,1.26],[21,1.2],[8.2,1.66],[15.5,1.65]],"id":36899944},{"atb":[[1.18,667.6],[1.23,261.23],[1.13,924.37]],"id":42315317},{"atl":[[3.45,19.61],[2.38,8.7],[2.58,7.6],[2.98,12.13],[2.78,13.5]],"id":42315317},{"atb":[[2,120.16],[2.2,50.07],[2.1,109.24]],"id":40041375},{"atl":[[17.5,2.91],[9,3],[5.5,2.66],[12.5,2.08],[7,2]],"id":40041375},{"atb":[[1.12,1001.4],[1.07,1716.69],[1.17,353.43]],"id":43154430},{"atl":[[2.86,12.92],[2.46,8.23],[2.66,14.47],[3.15,22.35],[2.26,9.53]],"id":43154430},{"atb":[[1.4,150.21],[1.3,400.56],[1.35,343.34]],"id":37076580},{"atl":[[4.3,14.56],[2.86,6.46],[2.66,7.23],[3.15,11.17],[3.65,9.06]],"id":37076580}],"con":true,"img":false}]}
{"op":"mcm","clk":"5346134790","pt":1646081637599,"mc":[{"id":"1.195395448","rc":[{"atb":[[2.86,0],[3.15,0],[2.96,0]],"id":40014837},{"atl":[[16,0],[34,0],[11,0],[22,0],[8.4,0]],"id":40014837},{"atb":[[2,0],[2.2,0],[2.1,0]],"id":38541023},{"atl":[[17.5,0],[9,0],[5.5,0],[12.5,0],[7,0]],"id":38541023},{"atb":[[2.86,0],[3.15,0],[2.96,0]],"id":37535509},{"atl":[[16,0],[34,0],[11,0],[22,0],[8.4,0]],"id":37535509},{"atb":[[2.88,0],[2.98,0],[2.78,0]],"id":36899944},{"atl":[[32,0],[10.5,0],[21,0],[8.2,0],[15.5,0]],"id":36899944},{"atb":[[1.18,0],[1.23,0],[1.13,0]],"id":42315317},{"atl":[[3.45,0],[2.38,0],[2.58,0],[2.98,0],[2.78,0]],"id":42315317},{"atb":[[2,0],[2.2,0],[2.1,0]],"id":40041375},{"atl":[[17.5,0],[9,0],[5.5,0],[12.5,0],[7,0]],"id":40041375},{"atb":[[1.12,0],[1.07,0],[1.17,0]],"id":43154430},{"atl":[[2.86,0],[2.46,0],[2.66,0],[3.15,0],[2.26,0]],"id":43154430},{"atb":[[1.4,0],[1.3,0],[1.35,0]],"id":37076580},{"atl":[[4.3,0],[2.86,0],[2.66,0],[3.15,0],[3.65,0]],"id":37076580}],"con":true,"img":false}]}
{"op":"mcm","clk":"5346135981","pt":1646081656756,"mc":[{"id":"1.195395448","rc":[{"atb":[[2.86,64.6],[3.15,27.94],[2.96,61.31]],"id":40014837},{"atl":[[16,1.6],[34,1.45],[11,1.2],[22,1.14],[8.4,1.62]],"id":40014837},{"atb":[[2,120.16],[2.2,50.07],[2.1,109.24]],"id":38541023},{"atl":[[17.5,2.91],[9,3],[5.5,2.66],[12.5,2.08],[7,2]],"id":38541023},{"atb":[[2.86,64.6],[3.15,27.94],[2.96,61.31]],"id":37535509},{"atl":[[16,1.6],[34,1.45],[11,1.2],[22,1.14],[8.4,1.62]],"id":37535509},{"atb":[[2.88,63.92],[2.98,30.34],[2.78,67.51]],"id":36899944},{"atl":[[32,1.54],[10.5,1.26],[21,1.2],[8.2,1.66],[15.5,1.65]],"id":36899944},{"atb":[[1.18,667.6],[1.23,261.23],[1.13,924.37]],"id":42315317},{"atl":[[3.45,19.61],[2.38,8.7],[2.58,7.6],[2.98,12.13],[2.78,13.5]],"id":42315317},{"atb":[[2,120.16],[2.2,50.07],[2.1,109.24]],"id":40041375},{"atl":[[17.5,2.91],[9,3],[5.5,2.66],[12.5,2.08],[7,2]],"id":40041375},{"atb":[[1.12,1001.4],[1.07,1716.69],[1.17,353.43]],"id":43154430},{"atl":[[2.86,12.92],[2.46,8.23],[2.66,14.47],[3.15,22.35],[2.26,9.53]],"id":43154430},{"atb":[[1.4,150.21],[1.3,400.56],[1.35,343.34]],"id":37076580},{"atl":[[4.3,14.56],[2.86,6.46],[2.66,7.23],[3.15,11.17],[3.65,9.06]],"id":37076580}],"con":true,"img":false}]}
{"op":"mcm","clk":"5346138699","pt":1646081695590,"mc":[{"id":"1.195395448","rc":[{"atb":[[2.86,0],[3.15,0],[2.96,0]],"id":40014837},{"atl":[[16,0],[34,0],[11,0],[22,0],[8.4,0]],"id":40014837},{"atb":[[2,0],[2.2,0],[2.1,0]],"id":38541023},{"atl":[[17.5,0],[9,0],[5.5,0],[12.5,0],[7,0]],"id":38541023},{"atb":[[2.86,0],[3.15,0],[2.96,0]],"id":37535509},{"atl":[[16,0],[34,0],[11,0],[22,0],[8.4,0]],"id":37535509},{"atb":[[2.88,0],[2.98,0],[2.78,0]],"id":36899944},{"atl":[[32,0],[10.5,0],[21,0],[8.2,0],[15.5,0]],"id":36899944},{"atb":[[1.18,0],[1.23,0],[1.13,0]],"id":42315317},{"atl":[[3.45,0],[2.38,0],[2.58,0],[2.98,0],[2.78,0]],"id":42315317},{"atb":[[2,0],[2.2,0],[2.1,0]],"id":40041375},{"atl":[[17.5,0],[9,0],[5.5,0],[12.5,0],[7,0]],"id":40041375},{"atb":[[1.12,0],[1.07,0],[1.17,0]],"id":43154430},{"atl":[[2.86,0],[2.46,0],[2.66,0],[3.15,0],[2.26,0]],"id":43154430},{"atb":[[1.4,0],[1.3,0],[1.35,0]],"id":37076580},{"atl":[[4.3,0],[2.86,0],[2.66,0],[3.15,0],[3.65,0]],"id":37076580}],"con":true,"img":false}]}
{"op":"mcm","clk":"5346140298","pt":1646081718733,"mc":[{"id":"1.195395448","rc":[{"atb":[[2.86,64.6],[3.15,27.94],[2.96,61.31]],"id":40014837},{"atl":[[16,1.6],[34,1.45],[11,1.2],[22,1.14],[8.4,1.62]],"id":40014837},{"atb":[[2,120.16],[2.2,50.07],[2.1,109.24]],"id":38541023},{"atl":[[17.5,2.91],[9,3],[5.5,2.66],[12.5,2.08],[7,2]],"id":38541023},{"atb":[[2.86,64.6],[3.15,27.94],[2.96,61.31]],"id":37535509},{"atl":[[16,1.6],[34,1.45],[11,1.2],[22,1.14],[8.4,1.62]],"id":37535509},{"atb":[[2.88,63.92],[2.98,30.34],[2.78,67.51]],"id":36899944},{"atl":[[32,1.54],[10.5,1.26],[21,1.2],[8.2,1.66],[15.5,1.65]],"id":36899944},{"atb":[[1.16,751.05],[1.21,286.11],[1.11,1092.44]],"id":42315317},{"atl":[[2.54,7.8],[2.74,13.81],[3.35,20.45],[2.94,12.39],[2.34,8.96]],"id":42315317},{"atb":[[2,120.16],[2.2,50.07],[2.1,109.24]],"id":40041375},{"atl":[[17.5,2.91],[9,3],[5.5,2.66],[12.5,2.08],[7,2]],"id":40041375},{"atb":[[1.03,4005.62],[1.13,462.19],[1.08,1502.11]],"id":43154430},{"atl":[[2.4,8.58],[2.8,13.35],[3,24.03],[2.6,15.02],[2.2,10.01]],"id":43154430},{"atb":[[1.4,150.21],[1.3,400.56],[1.35,343.34]],"id":37076580},{"atl":[[4.3,14.56],[2.86,6.46],[2.66,7.23],[3.15,11.17],[3.65,9.06]],"id":37076580}],"con":true,"img":false}]}
{"op":"mcm","clk":"5346223560","pt":1646082745586,"mc":[{"id":"1.195395448","rc":[{"atb":[[2.86,0],[3.15,0],[2.96,0]],"id":40014837},{"atl":[[16,0],[34,0],[11,0],[22,0],[8.4,0]],"id":40014837},{"atb":[[2,0],[2.2,0],[2.1,0]],"id":38541023},{"atl":[[17.5,0],[9,0],[5.5,0],[12.5,0],[7,0]],"id":38541023},{"atb":[[2.86,0],[3.15,0],[2.96,0]],"id":37535509},{"atl":[[16,0],[34,0],[11,0],[22,0],[8.4,0]],"id":37535509},{"atb":[[2.88,0],[2.98,0],[2.78,0]],"id":36899944},{"atl":[[32,0],[10.5,0],[21,0],[8.2,0],[15.5,0]],"id":36899944},{"atb":[[1.16,0],[1.21,0],[1.11,0]],"id":42315317},{"atl":[[2.54,0],[2.74,0],[3.35,0],[2.94,0],[2.34,0]],"id":42315317},{"atb":[[2,0],[2.2,0],[2.1,0]],"id":40041375},{"atl":[[17.5,0],[9,0],[5.5,0],[12.5,0],[7,0]],"id":40041375},{"atb":[[1.03,0],[1.13,0],[1.08,0]],"id":43154430},{"atl":[[2.4,0],[2.8,0],[3,0],[2.6,0],[2.2,0]],"id":43154430},{"atb":[[1.4,0],[1.3,0],[1.35,0]],"id":37076580},{"atl":[[4.3,0],[2.86,0],[2.66,0],[3.15,0],[3.65,0]],"id":37076580}],"con":true,"img":false}]}
{"op":"mcm","clk":"5346225933","pt":1646082773230,"mc":[{"id":"1.195395448","rc":[{"atb":[[2.86,64.6],[3.15,27.94],[2.96,61.31]],"id":40014837},{"atl":[[16,1.6],[34,1.45],[11,1.2],[22,1.14],[8.4,1.62]],"id":40014837},{"atb":[[2,120.16],[2.2,50.07],[2.1,109.24]],"id":38541023},{"atl":[[17.5,2.91],[9,3],[5.5,2.66],[12.5,2.08],[7,2]],"id":38541023},{"atb":[[2.86,64.6],[3.15,27.94],[2.96,61.31]],"id":37535509},{"atl":[[16,1.6],[34,1.45],[11,1.2],[22,1.14],[8.4,1.62]],"id":37535509},{"atb":[[2.88,63.92],[2.98,30.34],[2.78,67.51]],"id":36899944},{"atl":[[32,1.54],[10.5,1.26],[21,1.2],[8.2,1.66],[15.5,1.65]],"id":36899944},{"atb":[[1.16,751.05],[1.21,286.11],[1.11,1092.44]],"id":42315317},{"atl":[[2.54,7.8],[2.74,13.81],[3.35,20.45],[2.94,12.39],[2.34,8.96]],"id":42315317},{"atb":[[2,120.16],[2.2,50.07],[2.1,109.24]],"id":40041375},{"atl":[[17.5,2.91],[9,3],[5.5,2.66],[12.5,2.08],[7,2]],"id":40041375},{"atb":[[1.03,4005.62],[1.13,462.19],[1.08,1502.11]],"id":43154430},{"atl":[[2.4,8.58],[2.8,13.35],[3,24.03],[2.6,15.02],[2.2,10.01]],"id":43154430},{"atb":[[1.4,150.21],[1.3,400.56],[1.35,343.34]],"id":37076580},{"atl":[[4.3,14.56],[2.86,6.46],[2.66,7.23],[3.15,11.17],[3.65,9.06]],"id":37076580}],"con":true,"img":false}]}
{"op":"mcm","clk":"5346490125","pt":1646088172773,"mc":[{"id":"1.195395448","rc":[{"atb":[[2.86,0],[3.15,0],[2.96,0]],"id":40014837},{"atl":[[16,0],[34,0],[11,0],[22,0],[8.4,0]],"id":40014837},{"atb":[[2,120.14],[2.2,50.06],[2.1,109.22]],"id":38541023},{"atl":[[17.5,2.91],[9,3],[5.5,2.66],[12.5,2.08],[7,2]],"id":38541023},{"atb":[[2.86,0],[3.15,0],[2.96,0]],"id":37535509},{"atl":[[16,0],[34,0],[11,0],[22,0],[8.4,0]],"id":37535509},{"atb":[[2.88,63.91],[2.98,30.34],[2.78,67.5]],"id":36899944},{"atl":[[32,1.54],[10.5,1.26],[21,1.2],[8.2,1.66],[15.5,1.65]],"id":36899944},{"atb":[[1.16,0],[1.21,0],[1.11,0]],"id":42315317},{"atl":[[2.54,0],[2.74,0],[3.35,0],[2.94,0],[2.34,0]],"id":42315317},{"atb":[[2,0],[2.2,0],[2.1,0]],"id":40041375},{"atl":[[17.5,0],[9,0],[5.5,0],[12.5,0],[7,0]],"id":40041375},{"atb":[[1.03,0],[1.13,0],[1.08,0]],"id":43154430},{"atl":[[2.4,0],[2.8,0],[3,0],[2.6,0],[2.2,0]],"id":43154430},{"atb":[[1.4,150.18],[1.3,400.49],[1.35,343.28]],"id":37076580},{"atl":[[4.3,14.56],[2.86,6.46],[2.66,7.23],[3.15,11.17],[3.65,9.06]],"id":37076580}],"con":true,"img":false}]}
{"op":"mcm","clk":"5346490245","pt":1646088176376,"mc":[{"id":"1.195395448","rc":[{"atb":[[3.1,57.21],[3.35,25.56],[2.94,61.93]],"id":40014837},{"atl":[[17,1.5],[38,1.29],[12,1.09],[24,1.04],[8.8,1.54]],"id":40014837},{"atb":[[3.1,57.21],[3.35,25.56],[2.94,61.93]],"id":37535509},{"atl":[[17,1.5],[38,1.29],[12,1.09],[24,1.04],[8.8,1.54]],"id":37535509},{"atb":[[1.2,600.74],[1.25,240.29],[1.15,800.99]],"id":42315317},{"atl":[[3.6,18.48],[3.1,11.44],[2.44,8.34],[2.64,7.32],[2.84,13.05]],"id":42315317},{"atb":[[2.4,42.91],[2.3,92.42],[2.2,100.12]],"id":40041375},{"atl":[[9.6,2.79],[19,2.66],[5.8,2.5],[7.6,1.81],[14,1.85]],"id":40041375},{"atb":[[1.15,400.49],[1.1,1201.49],[1.05,2402.98]],"id":43154430},{"atl":[[2.82,13.2],[2.22,9.85],[2.42,8.45],[2.62,14.83],[3.05,23.44]],"id":43154430}],"con":true,"img":false}]}
{"op":"mcm","clk":"5346542803","pt":1646089853292,"mc":[{"id":"1.195395448","rc":[{"atb":[[2.88,0],[2.98,0],[2.78,0]],"id":36899944},{"atl":[[32,0],[10.5,0],[21,0],[8.2,0],[15.5,0]],"id":36899944}],"con":true,"img":false}]}
{"op":"mcm","clk":"5346542876","pt":1646089856467,"mc":[{"id":"1.195395448","rc":[{"atb":[[2.88,63.91],[2.98,30.34],[2.78,67.5]],"id":36899944},{"atl":[[32,1.54],[10.5,1.26],[21,1.2],[8.2,1.66],[15.5,1.65]],"id":36899944}],"con":true,"img":false}]}
{"op":"mcm","clk":"5346595431","pt":1646091786740,"mc":[{"id":"1.195395448","rc":[{"atb":[[3.25,18.03],[3.15,16.78]],"id":40014837},{"atl":[[22,2.7],[15,2.9]],"id":40014837},{"atb":[[2.02,35.19],[2.12,36.23]],"id":38541023},{"atl":[[11,3.58],[7.4,6.34]],"id":38541023},{"atb":[[3.25,18.03],[3.15,18.79]],"id":37535509},{"atl":[[22,2.7],[15,2.9]],"id":37535509},{"atb":[[2.9,41.63]],"id":36899944},{"atl":[[18.5,2.7],[12.5,3.52]],"id":36899944},{"atb":[[1.26,176.93]],"id":42315317},{"atl":[[2.42,28.58],[2.62,21.88]],"id":42315317},{"atb":[[2.32,30.75],[2.22,32.08]],"id":40041375},{"atl":[[12.5,3.4],[8.4,5.48]],"id":40041375},{"atb":[[1.16,268.44],[1.17,40.59]],"id":43154430},{"atl":[[2.2,35.72],[2.08,37.58]],"id":43154430},{"atb":[[1.41,102.83],[1.46,40.59]],"id":37076580},{"atl":[[3.6,16.23],[2.84,22.05]],"id":37076580}],"con":true,"img":false}]}
{"op":"mcm","clk":"5346595437","pt":1646091786947,"mc":[{"id":"1.195395448","rc":[{"atb":[[1.21,168.8]],"id":42315317},{"atb":[[1.11,390.21]],"id":43154430}],"con":true,"img":false}]}
{"op":"mcm","clk":"5346595440","pt":1646091787050,"mc":[{"id":"1.195395448","rc":[{"atl":[[22,0],[15,0]],"id":40014837},{"atb":[[1.26,40.59]],"id":42315317},{"atb":[[1.16,0]],"id":43154430}],"con":true,"img":false}]}
{"op":"mcm","clk":"5346595442","pt":1646091787152,"mc":[{"id":"1.195395448","rc":[{"atl":[[17.5,2.9],[26,2.7]],"id":40014837}],"con":true,"img":false}]}
{"op":"mcm","clk":"5346595636","pt":1646091794544,"mc":[{"id":"1.195395448","rc":[{"atl":[[15,0]],"id":37535509},{"atl":[[12.5,0]],"id":36899944}],"con":true,"img":false}]}
{"op":"mcm","clk":"5346595637","pt":1646091794645,"mc":[{"id":"1.195395448","rc":[{"atl":[[16.5,2.9]],"id":37535509},{"atl":[[14,3.52]],"id":36899944}],"con":true,"img":false}]}
{"op":"mcm","clk":"5346595907","pt":1646091805461,"mc":[{"id":"1.195395448","rc":[{"atb":[[1.17,0]],"id":43154430},{"atb":[[1.46,0]],"id":37076580}],"con":true,"img":false}]}
{"op":"mcm","clk":"5346595911","pt":1646091805565,"mc":[{"id":"1.195395448","rc":[{"atb":[[1.16,40.59]],"id":43154430},{"atb":[[1.41,143.42]],"id":37076580}],"con":true,"img":false}]}
{"op":"mcm","clk":"5346596469","pt":1646091824887,"mc":[{"id":"1.195395448","rc":[{"atb":[[3.25,0]],"id":40014837},{"atb":[[3.25,0]],"id":37535509},{"atb":[[2.9,20.27]],"id":36899944}],"con":true,"img":false}]}
{"op":"mcm","clk":"5346596473","pt":1646091824991,"mc":[{"id":"1.195395448","rc":[{"atb":[[3.4,18.03]],"id":40014837},{"atb":[[3.4,18.03]],"id":37535509},{"atb":[[3,21.36]],"id":36899944}],"con":true,"img":false}]}
{"op":"mcm","clk":"5346597204","pt":1646091847630,"mc":[{"id":"1.195395448","rc":[{"atb":[[2.32,0]],"id":40041375}],"con":true,"img":false}]}
{"op":"mcm","clk":"5346597209","pt":1646091847684,"mc":[{"id":"1.195395448","rc":[{"atb":[[2.42,30.75]],"id":40041375}],"con":true,"img":false}]}
{"op":"mcm","clk":"5346603085","pt":1646092024915,"mc":[{"id":"1.195395448","rc":[{"atb":[[3.45,18.04]],"id":40014837},{"atl":[[19.5,3.04]],"id":40014837},{"atb":[[1.46,100.12]],"id":38541023},{"atl":[[5.5,5.33]],"id":38541023},{"atb":[[3.45,18.8]],"id":37535509},{"atl":[[14,2.71]],"id":37535509},{"atb":[[2.74,57.47]],"id":36899944},{"atl":[[8.2,3.66]],"id":36899944},{"atb":[[1.27,168.8]],"id":42315317},{"atl":[[2.58,36.94]],"id":42315317},{"atb":[[1.17,85.82]],"id":40041375},{"atl":[[11,5.3]],"id":40041375},{"atb":[[1.17,390.21]],"id":43154430},{"atl":[[2.62,60.4]],"id":43154430},{"atb":[[1.35,628.99]],"id":37076580},{"atl":[[2.66,14.47]],"id":37076580}],"con":true,"img":false}]}
{"op":"mcm","clk":"5346603621","pt":1646092039947,"mc":[{"id":"1.195395448","rc":[{"atl":[[2.84,0]],"id":37076580}],"con":true,"img":false}]}
{"op":"mcm","clk":"5346603625","pt":1646092040051,"mc":[{"id":"1.195395448","rc":[{"atl":[[3.1,22.05]],"id":37076580}],"con":true,"img":false}]}
{"op":"mcm","clk":"5346604151","pt":1646092058997,"mc":[{"id":"1.195395448","rc":[{"atb":[[2.1,32.8]],"id":40014837},{"atl":[[19.5,2.7],[13,3.38]],"id":38541023},{"atl":[[26,1.62]],"id":37535509},{"atl":[[22,1.93]],"id":36899944},{"atb":[[1.67,58.42]],"id":40041375},{"atb":[[1.2,211.07]],"id":37076580}],"con":true,"img":false}]}
{"op":"mcm","clk":"5346604156","pt":1646092059101,"mc":[{"id":"1.195395448","rc":[{"atb":[[3.4,0],[3.15,0]],"id":40014837},{"atl":[[11,0],[7.4,0]],"id":38541023},{"atl":[[16.5,0],[22,0]],"id":37535509},{"atl":[[18.5,0],[14,0]],"id":36899944},{"atb":[[2.22,0]],"id":40041375},{"atb":[[1.41,40.59]],"id":37076580}],"con":true,"img":false}]}
{"op":"mcm","clk":"5346604160","pt":1646092059157,"mc":[{"id":"1.195395448","rc":[{"atb":[[3.15,18.03]],"id":40014837},{"atl":[[38,4]],"id":37535509},{"atl":[[32,4.25]],"id":36899944}],"con":true,"img":false}]}
{"op":"mcm","clk":"5346604162","pt":1646092059260,"mc":[{"id":"1.195395448","rc":[{"atb":[[3.45,0],[3.4,41.67]],"id":40014837}],"con":true,"img":false}]}
{"op":"mcm","clk":"5346604658","pt":1646092077425,"mc":[{"id":"1.195395448","rc":[{"atl":[[17.5,0],[26,0]],"id":40014837},{"atl":[[2.62,0]],"id":42315317},{"atl":[[10.5,4.11],[12.5,0],[8.4,0]],"id":40041375},{"atl":[[2.08,0]],"id":43154430},{"atl":[[3.1,0]],"id":37076580}],"con":true,"img":false}]}
{"op":"mcm","clk":"5346604660","pt":1646092077477,"mc":[{"id":"1.195395448","rc":[{"atl":[[17.5,2.7],[11.5,2.9]],"id":40014837},{"atl":[[2.42,50.46]],"id":42315317},{"atl":[[7.4,5.48]],"id":40041375},{"atl":[[1.96,37.58]],"id":43154430},{"atl":[[2.64,22.05]],"id":37076580}],"con":true,"img":false}]}
{"op":"mcm","clk":"5346604664","pt":1646092077579,"mc":[{"id":"1.195395448","rc":[{"atl":[[2.64,36.53],[2.66,7.23]],"id":37076580}],"con":true,"img":false}]}
{"op":"mcm","clk":"5346605248","pt":1646092096913,"mc":[{"id":"1.195395448","rc":[{"atl":[[2.42,28.58]],"id":42315317},{"atl":[[3.1,20.02]],"id":37076580}],"con":true,"img":false}]}
{"op":"mcm","clk":"5346605254","pt":1646092097016,"mc":[{"id":"1.195395448","rc":[{"atl":[[2.56,21.88]],"id":42315317},{"atl":[[3.6,0]],"id":37076580}],"con":true,"img":false}]}
{"op":"mcm","clk":"5346605259","pt":1646092097222,"mc":[{"id":"1.195395448","rc":[{"atl":[[2.2,0]],"id":43154430}],"con":true,"img":false}]}
{"op":"mcm","clk":"5346605262","pt":1646092097324,"mc":[{"id":"1.195395448","rc":[{"atl":[[2.4,35.72]],"id":43154430}],"con":true,"img":false}]}
{"op":"mcm","clk":"5346605952","pt":1646092117841,"mc":[{"id":"1.195395448","rc":[{"atb":[[3.15,0]],"id":40014837},{"atl":[[1.96,0]],"id":43154430}],"con":true,"img":false}]}
{"op":"mcm","clk":"5346605955","pt":1646092117944,"mc":[{"id":"1.195395448","rc":[{"atb":[[3.45,18.03]],"id":40014837},{"atl":[[2.1,37.58]],"id":43154430}],"con":true,"img":false}]}
{"op":"mcm","clk":"5346605957","pt":1646092118048,"mc":[{"id":"1.195395448","rc":[{"atb":[[3.4,0],[3.5,25.56]],"id":40014837}],"con":true,"img":false}]}
{"op":"mcm","clk":"5346606608","pt":1646092137792,"mc":[{"id":"1.195395448","rc":[{"atb":[[1.31,136.38]],"id":37076580}],"con":true,"img":false}]}
{"op":"mcm","clk":"5346606612","pt":1646092137894,"mc":[{"id":"1.195395448","rc":[{"atb":[[3.45,0]],"id":40014837},{"atl":[[13,0]],"id":38541023},{"atl":[[26,0]],"id":37535509},{"atl":[[22,0]],"id":36899944},{"atb":[[1.2,0]],"id":37076580},{"atl":[[2.64,14.48]],"id":37076580}],"con":true,"img":false}]}
{"op":"mcm","clk":"5346606616","pt":1646092137946,"mc":[{"id":"1.195395448","rc":[{"atb":[[3.4,41.67],[3.15,18.03]],"id":40014837},{"atl":[[10.5,3.38]],"id":38541023},{"atl":[[19.5,1.62]],"id":37535509},{"atl":[[17,1.93]],"id":36899944},{"atl":[[2.62,22.05]],"id":37076580}],"con":true,"img":false}]}
{"op":"mcm","clk":"5346606619","pt":1646092138049,"mc":[{"id":"1.195395448","rc":[{"atb":[[3.5,0]],"id":40014837},{"atl":[[2.64,0],[2.62,36.53]],"id":37076580}],"con":true,"img":false}]}
{"op":"mcm","clk":"5346607461","pt":1646092160098,"mc":[{"id":"1.195395448","rc":[{"atl":[[19.5,0]],"id":38541023},{"atl":[[38,1.29]],"id":37535509},{"atl":[[2.4,0]],"id":43154430}],"con":true,"img":false}]}
{"op":"mcm","clk":"5346607464","pt":1646092160200,"mc":[{"id":"1.195395448","rc":[{"atl":[[15.5,2.7]],"id":38541023},{"atl":[[29,2.7]],"id":37535509},{"atl":[[2.2,35.72]],"id":43154430}],"con":true,"img":false}]}
{"op":"mcm","clk":"5346609157","pt":1646092205672,"mc":[{"id":"1.195395448","rc":[{"atb":[[3.15,0]],"id":40014837},{"atl":[[10.5,0]],"id":38541023},{"atl":[[2.62,14.48]],"id":37076580}],"con":true,"img":false}]}
{"op":"mcm","clk":"5346609161","pt":1646092205774,"mc":[{"id":"1.195395448","rc":[{"atb":[[3.45,18.03]],"id":40014837},{"atl":[[9.6,3.38]],"id":38541023},{"atl":[[2.6,22.05],[2.64,28.96]],"id":37076580}],"con":true,"img":false}]}
{"op":"mcm","clk":"5346609164","pt":1646092205876,"mc":[{"id":"1.195395448","rc":[{"atl":[[2.62,0]],"id":37076580}],"con":true,"img":false}]}
{"op":"mcm","clk":"5346609167","pt":1646092205928,"mc":[{"id":"1.195395448","rc":[{"atb":[[3.4,0],[3.5,25.56]],"id":40014837}],"con":true,"img":false}]}
{"op":"mcm","clk":"5346610027","pt":1646092224876,"mc":[{"id":"1.195395448","rc":[{"atb":[[3.45,0]],"id":40014837},{"atl":[[2.6,0]],"id":37076580}],"con":true,"img":false}]}
{"op":"mcm","clk":"5346610030","pt":1646092224979,"mc":[{"id":"1.195395448","rc":[{"atb":[[3.4,41.67],[3.15,18.03],[3.5,0]],"id":40014837},{"atl":[[2.62,22.05]],"id":37076580}],"con":true,"img":false}]}
{"op":"mcm","clk":"5346610730","pt":1646092241021,"mc":[{"id":"1.195395448","rc":[{"atl":[[2.62,44.11]],"id":37076580}],"con":true,"img":false}]}
{"op":"mcm","clk":"5346610735","pt":1646092241123,"mc":[{"id":"1.195395448","rc":[{"atl":[[2.64,0]],"id":37076580}],"con":true,"img":false}]}
{"op":"mcm","clk":"5346611754","pt":1646092266257,"mc":[{"id":"1.195395448","rc":[{"atl":[[17,0]],"id":36899944}],"con":true,"img":false}]}
{"op":"mcm","clk":"5346611756","pt":1646092266363,"mc":[{"id":"1.195395448","rc":[{"atl":[[19,1.93]],"id":36899944}],"con":true,"img":false}]}
{"op":"mcm","clk":"5346612508","pt":1646092285974,"mc":[{"id":"1.195395448","rc":[{"atb":[[3.15,0]],"id":40014837},{"atl":[[2.62,22.06]],"id":37076580}],"con":true,"img":false}]}
{"op":"mcm","clk":"5346612511","pt":1646092286076,"mc":[{"id":"1.195395448","rc":[{"atb":[[3.45,18.03]],"id":40014837},{"atl":[[2.6,22.05],[2.64,44.12]],"id":37076580}],"con":true,"img":false}]}
{"op":"mcm","clk":"5346612514","pt":1646092286179,"mc":[{"id":"1.195395448","rc":[{"atb":[[3.5,25.56]],"id":40014837},{"atl":[[2.62,0]],"id":37076580}],"con":true,"img":false}]}
{"op":"mcm","clk":"5346612517","pt":1646092286282,"mc":[{"id":"1.195395448","rc":[{"atb":[[3.4,0]],"id":40014837},{"atl":[[2.62,44.12]],"id":37076580}],"con":true,"img":false}]}
{"op":"mcm","clk":"5346612521","pt":1646092286385,"mc":[{"id":"1.195395448","rc":[{"atl":[[2.64,0]],"id":37076580}],"con":true,"img":false}]}
{"op":"mcm","clk":"5346613196","pt":1646092304398,"mc":[{"id":"1.195395448","rc":[{"atb":[[3.45,0]],"id":40014837}],"con":true,"img":false}]}
{"op":"mcm","clk":"5346613199","pt":1646092304502,"mc":[{"id":"1.195395448","rc":[{"atb":[[3.15,18.03]],"id":40014837}],"con":true,"img":false}]}
{"op":"mcm","clk":"5346613202","pt":1646092304604,"mc":[{"id":"1.195395448","rc":[{"atb":[[3.4,41.67],[3.5,0]],"id":40014837}],"con":true,"img":false}]}
{"op":"mcm","clk":"5346615305","pt":1646092364762,"mc":[{"id":"1.195395448","rc":[{"atb":[[3.45,0],[3.3,43.48]],"id":37535509},{"atb":[[2.74,0],[2.62,61.73]],"id":36899944},{"atl":[[8.2,1.66],[8.4,7.34]],"id":36899944},{"atl":[[2.74,57.47],[2.62,14.83]],"id":43154430},{"atb":[[1.32,300.38],[1.35,343.28]],"id":37076580},{"atl":[[2.74,44.12],[2.62,0]],"id":37076580}],"con":true,"img":false}]}
{"op":"mcm","clk":"5346615541","pt":1646092370469,"mc":[{"id":"1.195395448","rc":[{"atb":[[3.15,0]],"id":40014837},{"atl":[[2.6,0]],"id":37076580}],"con":true,"img":false}]}
{"op":"mcm","clk":"5346615547","pt":1646092370567,"mc":[{"id":"1.195395448","rc":[{"atb":[[3.45,18.03]],"id":40014837},{"atl":[[2.72,22.05]],"id":37076580}],"con":true,"img":false}]}
{"op":"mcm","clk":"5346615552","pt":1646092370669,"mc":[{"id":"1.195395448","rc":[{"atb":[[3.4,0],[3.5,25.56]],"id":40014837}],"con":true,"img":false}]}
{"op":"mcm","clk":"5346616622","pt":1646092397710,"mc":[{"id":"1.195395448","rc":[{"atb":[[3.45,0]],"id":40014837},{"atl":[[11.5,0]],"id":40014837},{"atl":[[9.6,0]],"id":38541023},{"atl":[[19.5,0],[29,0]],"id":37535509},{"atb":[[2.9,0],[1.87,44.27]],"id":36899944},{"atl":[[2.42,0]],"id":42315317},{"atl":[[7.4,0]],"id":40041375}],"con":true,"img":false}]}
{"op":"mcm","clk":"5346616627","pt":1646092397812,"mc":[{"id":"1.195395448","rc":[{"atb":[[3.4,41.67],[3.15,18.03],[3.5,0]],"id":40014837},{"atl":[[13,2.9]],"id":40014837},{"atl":[[11,3.38]],"id":38541023},{"atl":[[34,2.7],[23,1.62]],"id":37535509},{"atl":[[2.56,50.46]],"id":42315317},{"atl":[[8,5.48]],"id":40041375}],"con":true,"img":false}]}
{"op":"mcm","clk":"5346617605","pt":1646092423323,"mc":[{"id":"1.195395448","rc":[{"atb":[[3.45,25.56],[3.3,0]],"id":37535509},{"atb":[[2.72,58.14],[2.62,0]],"id":36899944},{"atl":[[2.58,0]],"id":42315317},{"atl":[[2.74,0],[2.6,45.57]],"id":43154430},{"atb":[[1.35,628.99]],"id":37076580},{"atl":[[2.7,22.06]],"id":37076580}],"con":true,"img":false}]}
{"op":"mcm","clk":"5346617607","pt":1646092423424,"mc":[{"id":"1.195395448","rc":[{"atl":[[2.54,36.94]],"id":42315317}],"con":true,"img":false}]}
{"op":"mcm","clk":"5346617610","pt":1646092423528,"mc":[{"id":"1.195395448","rc":[{"atb":[[1.32,0]],"id":37076580},{"atl":[[2.74,0]],"id":37076580}],"con":true,"img":false}]}
{"op":"mcm","clk":"5346617644","pt":1646092424657,"mc":[{"id":"1.195395448","rc":[{"atb":[[3,0]],"id":36899944},{"atl":[[19,0],[8.2,7.3]],"id":36899944}],"con":true,"img":false}]}
{"op":"mcm","clk":"5346617648","pt":1646092424759,"mc":[{"id":"1.195395448","rc":[{"atb":[[2.9,21.36]],"id":36899944},{"atl":[[8,7.31],[8.2,1.66]],"id":36899944}],"con":true,"img":false}]}
{"op":"mcm","clk":"5346617654","pt":1646092424861,"mc":[{"id":"1.195395448","rc":[{"atl":[[9,5.63],[8.4,0]],"id":36899944}],"con":true,"img":false}]}
{"op":"mcm","clk":"5346617809","pt":1646092429835,"mc":[{"id":"1.195395448","rc":[{"atl":[[8,0],[8.2,15.55]],"id":36899944}],"con":true,"img":false}]}
{"op":"mcm","clk":"5346617812","pt":1646092429938,"mc":[{"id":"1.195395448","rc":[{"atl":[[8.2,1.66],[8.8,8.98]],"id":36899944}],"con":true,"img":false}]}
{"op":"mcm","clk":"5346618206","pt":1646092441897,"mc":[{"id":"1.195395448","rc":[{"atb":[[2.96,18.4],[2.1,0]],"id":40014837},{"atl":[[32,1.54]],"id":36899944}],"con":true,"img":false}]}
{"op":"mcm","clk":"5346618210","pt":1646092441998,"mc":[{"id":"1.195395448","rc":[{"atl":[[13.5,2.7]],"id":36899944}],"con":true,"img":false}]}
{"op":"mcm","clk":"5346618535","pt":1646092451911,"mc":[{"id":"1.195395448","rc":[{"atl":[[2.72,51.35]],"id":37076580}],"con":true,"img":false}]}
{"op":"mcm","clk":"5346618538","pt":1646092451963,"mc":[{"id":"1.195395448","rc":[{"atl":[[2.7,0]],"id":37076580}],"con":true,"img":false}]}
{"op":"mcm","clk":"5346618719","pt":1646092456597,"mc":[{"id":"1.195395448","rc":[{"atl":[[2.54,0],[2.52,36.94]],"id":42315317}],"con":true,"img":false}]}
{"op":"mcm","clk":"5346618772","pt":1646092457779,"mc":[{"id":"1.195395448","rc":[{"atl":[[8.2,7.3],[8.8,0]],"id":36899944}],"con":true,"img":false}]}
{"op":"mcm","clk":"5346618812","pt":1646092459011,"mc":[{"id":"1.195395448","rc":[{"atb":[[3.15,0]],"id":40014837},{"atl":[[2.56,0]],"id":42315317}],"con":true,"img":false}]}
{"op":"mcm","clk":"5346618817","pt":1646092459111,"mc":[{"id":"1.195395448","rc":[{"atb":[[3.45,18.03]],"id":40014837},{"atl":[[2.82,21.88],[2.5,28.58]],"id":42315317}],"con":true,"img":false}]}
{"op":"mcm","clk":"5346618818","pt":1646092459215,"mc":[{"id":"1.195395448","rc":[{"atb":[[3.4,0],[3.5,25.56]],"id":40014837}],"con":true,"img":false}]}
{"op":"mcm","clk":"5346619387","pt":1646092476107,"mc":[{"id":"1.195395448","rc":[{"atb":[[3.45,0]],"id":40014837}],"con":true,"img":false}]}
{"op":"mcm","clk":"5346619389","pt":1646092476214,"mc":[{"id":"1.195395448","rc":[{"atb":[[3.4,41.67],[3.15,18.03],[3.5,0]],"id":40014837}],"con":true,"img":false}]}
{"op":"mcm","clk":"5346619783","pt":1646092489852,"mc":[{"id":"1.195395448","rc":[{"atl":[[2.54,57.18]],"id":42315317}],"con":true,"img":false}]}
{"op":"mcm","clk":"5346619786","pt":1646092489953,"mc":[{"id":"1.195395448","rc":[{"atl":[[2.52,0]],"id":42315317}],"con":true,"img":false}]}
{"op":"mcm","clk":"5346619886","pt":1646092494060,"mc":[{"id":"1.195395448","rc":[{"atl":[[2.2,0]],"id":43154430}],"con":true,"img":false}]}
{"op":"mcm","clk":"5346619889","pt":1646092494162,"mc":[{"id":"1.195395448","rc":[{"atl":[[2.4,35.72]],"id":43154430}],"con":true,"img":false}]}
{"op":"mcm","clk":"5346620751","pt":1646092522257,"mc":[{"id":"1.195395448","rc":[{"atl":[[2.54,0],[2.52,36.94]],"id":42315317}],"con":true,"img":false}]}
{"op":"mcm","clk":"5346621284","pt":1646092538602,"mc":[{"id":"1.195395448","rc":[{"atb":[[3.15,0]],"id":40014837}],"con":true,"img":false}]}
{"op":"mcm","clk":"5346621291","pt":1646092538705,"mc":[{"id":"1.195395448","rc":[{"atb":[[3.45,18.03]],"id":40014837}],"con":true,"img":false}]}
{"op":"mcm","clk":"5346621297","pt":1646092538812,"mc":[{"id":"1.195395448","rc":[{"atb":[[3.4,0],[3.5,25.56]],"id":40014837}],"con":true,"img":false}]}
{"op":"mcm","clk":"5346621692","pt":1646092550405,"mc":[{"id":"1.195395448","rc":[{"atl":[[2.54,57.18]],"id":42315317}],"con":true,"img":false}]}
{"op":"mcm","clk":"5346621696","pt":1646092550507,"mc":[{"id":"1.195395448","rc":[{"atl":[[2.52,0]],"id":42315317}],"con":true,"img":false}]}
{"op":"mcm","clk":"5346622421","pt":1646092570735,"mc":[{"id":"1.195395448","rc":[{"atb":[[3.45,0]],"id":40014837},{"atl":[[23,0]],"id":37535509}],"con":true,"img":false}]}
{"op":"mcm","clk":"5346622424","pt":1646092570838,"mc":[{"id":"1.195395448","rc":[{"atb":[[3.4,41.67],[3.15,18.03],[3.5,0]],"id":40014837},{"atl":[[25,1.62]],"id":37535509}],"con":true,"img":false}]}
{"op":"mcm","clk":"5346623809","pt":1646092614710,"mc":[{"id":"1.195395448","rc":[{"atb":[[1.08,144.25],[1.17,0]],"id":40041375}],"con":true,"img":false}]}
{"op":"mcm","clk":"5346623948","pt":1646092618919,"mc":[{"id":"1.195395448","rc":[{"atl":[[2.82,0]],"id":42315317}],"con":true,"img":false}]}
{"op":"mcm","clk":"5346623952","pt":1646092619019,"mc":[{"id":"1.195395448","rc":[{"atl":[[2.52,21.88]],"id":42315317}],"con":true,"img":false}]}
{"op":"mcm","clk":"5346626147","pt":1646092691029,"mc":[{"id":"1.195395448","rc":[{"atb":[[3.15,0],[2.96,0]],"id":40014837},{"atl":[[17.5,0],[13,0]],"id":40014837},{"atb":[[2.02,0],[2.12,0]],"id":38541023},{"atl":[[11,0],[15.5,0]],"id":38541023},{"atb":[[3.4,0],[3.15,0]],"id":37535509},{"atl":[[34,0],[25,0]],"id":37535509},{"atb":[[2.9,0],[1.87,0]],"id":36899944},{"atl":[[9,0],[13.5,0]],"id":36899944},{"atb":[[1.21,0],[1.26,0]],"id":42315317},{"atl":[[2.5,0],[2.52,0]],"id":42315317},{"atb":[[2.42,0],[1.67,0]],"id":40041375},{"atl":[[8,0],[10.5,0]],"id":40041375},{"atb":[[1.16,0],[1.11,0]],"id":43154430},{"atl":[[2.4,0],[2.1,0]],"id":43154430},{"atb":[[1.41,0],[1.31,0]],"id":37076580},{"atl":[[2.72,29.3],[3.1,0]],"id":37076580}],"con":true,"img":false}]}
{"op":"mcm","clk":"5346626152","pt":1646092691184,"mc":[{"id":"1.195395448","rc":[{"atb":[[3.45,0],[3.4,41.67]],"id":37535509},{"atb":[[1.27,0],[1.26,384.62]],"id":42315317},{"atb":[[1.16,625],[1.17,0]],"id":43154430}],"con":true,"img":false}]}
{"op":"mcm","clk":"5346627403","pt":1646092732151,"mc":[{"id":"1.195395448","rc":[{"atb":[[3.4,0],[3.3,43.48]],"id":37535509},{"atb":[[2.72,0],[2.48,67.57]],"id":36899944},{"atl":[[2.54,0],[2.64,68.3]],"id":42315317},{"atl":[[2.72,24.68],[2.6,0]],"id":43154430},{"atb":[[1.32,312.5],[1.35,343.28]],"id":37076580},{"atl":[[2.72,0],[2.84,36.54]],"id":37076580}],"con":true,"img":false}]}
{"op":"mcm","clk":"5346628267","pt":1646092757077,"mc":[{"id":"1.195395448","rc":[{"atb":[[3.45,16.56],[2.96,18.4]],"id":40014837},{"atl":[[19.5,5.74],[13,3.38]],"id":40014837},{"atb":[[2.02,35.19],[2.12,36.23]],"id":38541023},{"atl":[[16.5,2.7],[11,4.05]],"id":38541023},{"atb":[[3.35,60.02]],"id":37535509},{"atl":[[34,2.7],[23,1.84]],"id":37535509},{"atb":[[2.9,21.36],[1.86,44.78]],"id":36899944},{"atl":[[9,5.07],[13.5,3.07]],"id":36899944},{"atb":[[1.21,168.8],[1.26,425.21]],"id":42315317},{"atl":[[2.54,25.05],[2.62,21.88]],"id":42315317},{"atb":[[2.32,30.75],[1.76,51.51]],"id":40041375},{"atl":[[8,5.79],[12,3.56]],"id":40041375},{"atb":[[1.16,665.59],[1.11,390.21]],"id":43154430},{"atl":[[2.4,30.84],[2.16,34.99]],"id":43154430},{"atb":[[1.41,40.59],[1.36,117.44]],"id":37076580},{"atl":[[2.82,22.3],[3.1,20.02]],"id":37076580}],"con":true,"img":false}]}
{"op":"mcm","clk":"5346628271","pt":1646092757174,"mc":[{"id":"1.195395448","rc":[{"atb":[[3.5,25.56]],"id":40014837}],"con":true,"img":false}]}
{"op":"mcm","clk":"5346628274","pt":1646092757278,"mc":[{"id":"1.195395448","rc":[{"atb":[[3.4,0]],"id":40014837},{"atb":[[3.35,42.83]],"id":37535509}],"con":true,"img":false}]}
{"op":"mcm","clk":"5346628277","pt":1646092757380,"mc":[{"id":"1.195395448","rc":[{"atb":[[3.15,17.19]],"id":37535509}],"con":true,"img":false}]}
{"op":"mcm","clk":"5346628416","pt":1646092762202,"mc":[{"id":"1.195395448","rc":[{"atb":[[3.4,41.67],[3.3,0]],"id":37535509},{"atb":[[2.62,61.73],[2.48,0]],"id":36899944},{"atl":[[2.54,50.11],[2.64,7.32]],"id":42315317},{"atl":[[2.72,0],[2.6,40.7]],"id":43154430},{"atb":[[1.32,0],[1.35,628.99]],"id":37076580},{"atl":[[2.72,22.3],[2.84,0]],"id":37076580}],"con":true,"img":false}]}
{"op":"mcm","clk":"5346629300","pt":1646092789905,"mc":[{"id":"1.195395448","rc":[{"atb":[[3.45,0]],"id":40014837},{"atb":[[3.35,25.56]],"id":37535509}],"con":true,"img":false}]}
{"op":"mcm","clk":"5346629305","pt":1646092790007,"mc":[{"id":"1.195395448","rc":[{"atb":[[3.4,41.67],[3.15,16.56],[3.5,0]],"id":40014837},{"atb":[[3.45,17.27]],"id":37535509}],"con":true,"img":false}]}
{"op":"mcm","clk":"5346629309","pt":1646092790110,"mc":[{"id":"1.195395448","rc":[{"atb":[[3.5,25.56]],"id":37535509}],"con":true,"img":false}]}
{"op":"mcm","clk":"5346629311","pt":1646092790213,"mc":[{"id":"1.195395448","rc":[{"atb":[[3.4,0]],"id":37535509}],"con":true,"img":false}]}
{"op":"mcm","clk":"5346629810","pt":1646092806335,"mc":[{"id":"1.195395448","rc":[{"atb":[[3.1,57.17],[3.35,25.54],[3.15,16.55],[2.96,18.39],[2.94,61.89]],"id":40014837},{"atl":[[17,1.5],[19.5,5.74],[38,1.29],[12,1.09],[24,1.04],[13,3.38],[8.8,1.54]],"id":40014837},{"atb":[[2,120.07],[2.02,35.17],[2.12,36.21],[2.2,50.02],[2.1,109.15]],"id":38541023},{"atl":[[16.5,2.7],[17.5,2.9],[9,3],[5.5,5.33],[11,4.05],[12.5,2.08],[7,2]],"id":38541023},{"atb":[[3.45,0],[3.1,57.17],[3.35,25.54],[3.15,17.18],[2.94,61.89]],"id":37535509},{"atl":[[17,1.5],[34,2.7],[38,1.29],[23,1.84],[12,1.09],[24,1.04],[8.8,1.54]],"id":37535509},{"atb":[[2.88,63.87],[2.9,21.34],[1.86,44.75],[2.98,30.32],[2.78,67.45]],"id":36899944},{"atl":[[32,1.54],[9,5.07],[10.5,1.26],[21,1.2],[8.2,7.3],[13.5,3.07],[15.5,1.65]],"id":36899944},{"atb":[[1.2,600.35],[1.25,240.14],[1.15,800.47],[1.21,168.69],[1.26,425.18]],"id":42315317},{"atl":[[3.6,18.47],[2.54,50.1],[3.1,11.43],[2.44,8.34],[2.64,7.32],[2.84,13.05],[2.62,21.86]],"id":42315317},{"atb":[[2.4,42.88],[2.32,30.73],[2.3,92.36],[2.2,100.05],[1.76,51.47]],"id":40041375},{"atl":[[8,5.79],[9.6,2.79],[19,2.66],[5.8,2.5],[7.6,1.81],[12,3.55],[14,1.84]],"id":40041375},{"atb":[[1.16,665.56],[1.15,400.23],[1.11,389.96],[1.1,1200.71],[1.05,2401.42]],"id":43154430},{"atl":[[2.4,30.82],[2.82,13.19],[2.22,9.84],[2.42,8.45],[2.62,14.82],[2.16,34.97],[3.05,23.43]],"id":43154430},{"atb":[[1.41,40.56],[1.4,150.08],[1.36,117.36],[1.3,400.23],[1.35,628.77]],"id":37076580},{"atl":[[2.82,22.28],[4.3,14.55],[2.86,6.45],[3.1,20.01],[2.66,7.23],[3.15,11.16],[3.65,9.05]],"id":37076580}],"con":true,"img":false}]}
{"op":"mcm","clk":"5346629818","pt":1646092806442,"mc":[{"id":"1.195395448","rc":[{"atb":[[3.35,42.8],[3.4,41.67]],"id":37535509}],"con":true,"img":false}]}
{"op":"mcm","clk":"5346629821","pt":1646092806543,"mc":[{"id":"1.195395448","rc":[{"atb":[[3.5,0]],"id":37535509}],"con":true,"img":false}]}
{"op":"mcm","clk":"5346630667","pt":1646092829460,"mc":[{"id":"1.195395448","rc":[{"atl":[[19.5,3.04]],"id":40014837},{"atl":[[2.54,25.06],[2.62,0]],"id":42315317},{"atb":[[2.32,0]],"id":40041375},{"atl":[[12,0]],"id":40041375},{"atl":[[2.4,0]],"id":43154430},{"atb":[[1.36,0]],"id":37076580},{"atl":[[2.82,0]],"id":37076580}],"con":true,"img":false}]}
{"op":"mcm","clk":"5346630677","pt":1646092829565,"mc":[{"id":"1.195395448","rc":[{"atl":[[19,2.7]],"id":40014837},{"atl":[[2.42,25.04],[2.52,21.86]],"id":42315317},{"atb":[[2.42,30.73]],"id":40041375},{"atl":[[10.5,3.55]],"id":40041375},{"atl":[[2.2,30.82]],"id":43154430},{"atb":[[1.31,117.36]],"id":37076580},{"atl":[[2.64,22.28]],"id":37076580}],"con":true,"img":false}]}
{"op":"mcm","clk":"5346631362","pt":1646092848611,"mc":[{"id":"1.195395448","rc":[{"atb":[[3.15,0]],"id":40014837}],"con":true,"img":false}]}
{"op":"mcm","clk":"5346631366","pt":1646092848668,"mc":[{"id":"1.195395448","rc":[{"atb":[[3.45,16.55]],"id":40014837}],"con":true,"img":false}]}
{"op":"mcm","clk":"5346631371","pt":1646092848770,"mc":[{"id":"1.195395448","rc":[{"atb":[[3.4,0],[3.5,25.54]],"id":40014837}],"con":true,"img":false}]}
{"op":"mcm","clk":"5346632015","pt":1646092867676,"mc":[{"id":"1.195395448","rc":[{"atb":[[3.45,0]],"id":40014837},{"atb":[[3.35,25.54]],"id":37535509}],"con":true,"img":false}]}
{"op":"mcm","clk":"5346632017","pt":1646092867780,"mc":[{"id":"1.195395448","rc":[{"atb":[[3.4,41.67],[3.15,16.55],[3.5,0]],"id":40014837},{"atb":[[3.45,17.25]],"id":37535509}],"con":true,"img":false}]}
{"op":"mcm","clk":"5346632022","pt":1646092867884,"mc":[{"id":"1.195395448","rc":[{"atb":[[3.5,25.54]],"id":37535509}],"con":true,"img":false}]}
{"op":"mcm","clk":"5346632024","pt":1646092867984,"mc":[{"id":"1.195395448","rc":[{"atb":[[3.4,0]],"id":37535509}],"con":true,"img":false}]}
{"op":"mcm","clk":"5346632698","pt":1646092886532,"mc":[{"id":"1.195395448","rc":[{"atb":[[3.45,0]],"id":37535509},{"atl":[[9,0]],"id":36899944}],"con":true,"img":false}]}
{"op":"mcm","clk":"5346632707","pt":1646092886635,"mc":[{"id":"1.195395448","rc":[{"atb":[[3.35,42.8],[3.4,41.67],[3.5,0]],"id":37535509},{"atl":[[8,5.07]],"id":36899944}],"con":true,"img":false}]}
{"op":"mcm","clk":"5346632711","pt":1646092886736,"mc":[{"id":"1.195395448","rc":[{"atl":[[8.2,1.66],[7.8,5.07]],"id":36899944}],"con":true,"img":false}]}
{"op":"mcm","clk":"5346633445","pt":1646092905364,"mc":[{"id":"1.195395448","rc":[{"atl":[[8,0]],"id":36899944}],"con":true,"img":false}]}
{"op":"mcm","clk":"5346633447","pt":1646092905468,"mc":[{"id":"1.195395448","rc":[{"atl":[[9,5.07]],"id":36899944}],"con":true,"img":false}]}
{"op":"mcm","clk":"5346633452","pt":1646092905522,"mc":[{"id":"1.195395448","rc":[{"atl":[[8.2,11.8],[7.8,0]],"id":36899944}],"con":true,"img":false}]}
{"op":"mcm","clk":"5346634219","pt":1646092923853,"mc":[{"id":"1.195395448","rc":[{"atb":[[3.15,0]],"id":40014837},{"atl":[[11,0]],"id":38541023}],"con":true,"img":false}]}
{"op":"mcm","clk":"5346634223","pt":1646092923953,"mc":[{"id":"1.195395448","rc":[{"atb":[[3.45,16.55]],"id":40014837},{"atl":[[12,4.05]],"id":38541023}],"con":true,"img":false}]}
{"op":"mcm","clk":"5346634228","pt":1646092924054,"mc":[{"id":"1.195395448","rc":[{"atb":[[3.4,0],[3.5,25.54]],"id":40014837}],"con":true,"img":false}]}
{"op":"mcm","clk":"5346635040","pt":1646092942373,"mc":[{"id":"1.195395448","rc":[{"atb":[[3.45,0]],"id":40014837},{"atb":[[3.35,25.54]],"id":37535509}],"con":true,"img":false}]}
{"op":"mcm","clk":"5346635047","pt":1646092942476,"mc":[{"id":"1.195395448","rc":[{"atb":[[3.4,41.67],[3.15,16.55]],"id":40014837},{"atb":[[3.45,17.25]],"id":37535509}],"con":true,"img":false}]}
{"op":"mcm","clk":"5346635052","pt":1646092942576,"mc":[{"id":"1.195395448","rc":[{"atb":[[3.5,0]],"id":40014837},{"atb":[[3.4,0],[3.5,25.54]],"id":37535509}],"con":true,"img":false}]}
{"op":"mcm","clk":"5346635704","pt":1646092960612,"mc":[{"id":"1.195395448","rc":[{"atb":[[3.45,0]],"id":37535509},{"atl":[[9,0]],"id":36899944}],"con":true,"img":false}]}
{"op":"mcm","clk":"5346635707","pt":1646092960717,"mc":[{"id":"1.195395448","rc":[{"atb":[[3.35,42.8],[3.4,41.67]],"id":37535509},{"atl":[[8,5.07]],"id":36899944}],"con":true,"img":false}]}
{"op":"mcm","clk":"5346635712","pt":1646092960816,"mc":[{"id":"1.195395448","rc":[{"atb":[[3.5,0]],"id":37535509},{"atl":[[7.8,5.07]],"id":36899944}],"con":true,"img":false}]}
{"op":"mcm","clk":"5346635715","pt":1646092960924,"mc":[{"id":"1.195395448","rc":[{"atl":[[8.2,1.66]],"id":36899944}],"con":true,"img":false}]}
{"op":"mcm","clk":"5346636351","pt":1646092978848,"mc":[{"id":"1.195395448","rc":[{"atl":[[8,0]],"id":36899944}],"con":true,"img":false}]}
{"op":"mcm","clk":"5346636356","pt":1646092978941,"mc":[{"id":"1.195395448","rc":[{"atl":[[9,5.07]],"id":36899944}],"con":true,"img":false}]}
{"op":"mcm","clk":"5346636361","pt":1646092979045,"mc":[{"id":"1.195395448","rc":[{"atl":[[8.2,11.8],[7.8,0]],"id":36899944}],"con":true,"img":false}]}
{"op":"mcm","clk":"5346637884","pt":1646093014657,"mc":[{"id":"1.195395448","rc":[{"atb":[[3.35,25.54]],"id":37535509},{"atl":[[23,0]],"id":37535509}],"con":true,"img":false}]}
{"op":"mcm","clk":"5346637887","pt":1646093014758,"mc":[{"id":"1.195395448","rc":[{"atb":[[3.45,17.25]],"id":37535509},{"atl":[[26,1.84]],"id":37535509}],"con":true,"img":false}]}
{"op":"mcm","clk":"5346637892","pt":1646093014862,"mc":[{"id":"1.195395448","rc":[{"atb":[[3.4,0],[3.5,25.54]],"id":37535509}],"con":true,"img":false}]}
{"op":"mcm","clk":"5346638524","pt":1646093032317,"mc":[{"id":"1.195395448","rc":[{"atb":[[3.15,0]],"id":40014837},{"atb":[[3.45,0]],"id":37535509},{"atl":[[9,0]],"id":36899944}],"con":true,"img":false}]}
{"op":"mcm","clk":"5346638529","pt":1646093032423,"mc":[{"id":"1.195395448","rc":[{"atb":[[3.45,16.55]],"id":40014837},{"atb":[[3.35,42.8]],"id":37535509},{"atl":[[8,5.07]],"id":36899944}],"con":true,"img":false}]}
{"op":"mcm","clk":"5346638537","pt":1646093032521,"mc":[{"id":"1.195395448","rc":[{"atb":[[3.4,41.67],[3.5,0]],"id":37535509}],"con":true,"img":false}]}
{"op":"mcm","clk":"5346638541","pt":1646093032624,"mc":[{"id":"1.195395448","rc":[{"atb":[[3.4,0],[3.5,25.54]],"id":40014837},{"atl":[[8.2,1.66],[7.8,5.07]],"id":36899944}],"con":true,"img":false}]}
{"op":"mcm","clk":"5346639171","pt":1646093049939,"mc":[{"id":"1.195395448","rc":[{"atb":[[3.45,0]],"id":40014837},{"atl":[[8,0]],"id":36899944}],"con":true,"img":false}]}
{"op":"mcm","clk":"5346639175","pt":1646093049992,"mc":[{"id":"1.195395448","rc":[{"atb":[[3.15,16.55]],"id":40014837},{"atl":[[9,5.07]],"id":36899944}],"con":true,"img":false}]}
{"op":"mcm","clk":"5346639176","pt":1646093050093,"mc":[{"id":"1.195395448","rc":[{"atb":[[3.4,41.67],[3.5,0]],"id":40014837},{"atl":[[8.2,11.8],[7.8,0]],"id":36899944}],"con":true,"img":false}]}
{"op":"mcm","clk":"5346640368","pt":1646093083954,"mc":[{"id":"1.195395448","rc":[{"atb":[[2.74,57.47],[2.62,0]],"id":36899944},{"atl":[[2.72,0],[2.78,44.58]],"id":37076580}],"con":true,"img":false}]}
{"op":"mcm","clk":"5346640396","pt":1646093084567,"mc":[{"id":"1.195395448","rc":[{"atb":[[3.35,25.54]],"id":37535509},{"atl":[[2.64,0]],"id":37076580}],"con":true,"img":false}]}
{"op":"mcm","clk":"5346640401","pt":1646093084670,"mc":[{"id":"1.195395448","rc":[{"atb":[[3.45,17.25]],"id":37535509},{"atl":[[2.76,22.28]],"id":37076580}],"con":true,"img":false}]}
{"op":"mcm","clk":"5346640407","pt":1646093084772,"mc":[{"id":"1.195395448","rc":[{"atb":[[3.5,25.54]],"id":37535509}],"con":true,"img":false}]}
{"op":"mcm","clk":"5346640410","pt":1646093084875,"mc":[{"id":"1.195395448","rc":[{"atb":[[3.4,0]],"id":37535509}],"con":true,"img":false}]}
{"op":"mcm","clk":"5346640683","pt":1646093092858,"mc":[{"id":"1.195395448","rc":[{"atb":[[3.5,2.97]],"id":40014837},{"atb":[[2.26,5.91]],"id":38541023},{"atb":[[3.6,2.86]],"id":37535509},{"atb":[[3.05,3.63]],"id":36899944},{"atb":[[2.48,5.03]],"id":40041375},{"atb":[[1.43,17.32]],"id":37076580}],"con":true,"img":false}]}
{"op":"mcm","clk":"5346640688","pt":1646093092962,"mc":[{"id":"1.195395448","rc":[{"atb":[[3.4,0],[3.5,28.51]],"id":40014837}],"con":true,"img":false}]}
{"op":"mcm","clk":"5346640807","pt":1646093095980,"mc":[{"id":"1.195395448","rc":[{"atb":[[3.5,25.54]],"id":40014837}],"con":true,"img":false}]}
{"op":"mcm","clk":"5346640878","pt":1646093098082,"mc":[{"id":"1.195395448","rc":[{"atb":[[3.4,41.67],[3.5,0]],"id":40014837}],"con":true,"img":false}]}
{"op":"mcm","clk":"5346640983","pt":1646093101775,"mc":[{"id":"1.195395448","rc":[{"atb":[[3.15,0]],"id":40014837},{"atb":[[3.45,0]],"id":37535509},{"atl":[[9,0]],"id":36899944}],"con":true,"img":false}]}
{"op":"mcm","clk":"5346640988","pt":1646093101876,"mc":[{"id":"1.195395448","rc":[{"atb":[[3.45,16.55]],"id":40014837},{"atb":[[3.35,42.8]],"id":37535509},{"atl":[[8,5.07]],"id":36899944}],"con":true,"img":false}]}
{"op":"mcm","clk":"5346640999","pt":1646093102082,"mc":[{"id":"1.195395448","rc":[{"atl":[[8.2,1.66],[7.8,5.07]],"id":36899944}],"con":true,"img":false}]}
{"op":"mcm","clk":"5346641152","pt":1646093105166,"mc":[{"id":"1.195395448","rc":[{"atb":[[3.5,2.97]],"id":40014837}],"con":true,"img":false}]}
{"op":"mcm","clk":"5346641230","pt":1646093107286,"mc":[{"id":"1.195395448","rc":[{"atl":[[2.54,0],[2.52,55.24]],"id":42315317}],"con":true,"img":false}]}
{"op":"mcm","clk":"5346641365","pt":1646093111214,"mc":[{"id":"1.195395448","rc":[{"atb":[[3.55,25.54]],"id":37535509}],"con":true,"img":false}]}
{"op":"mcm","clk":"5346641370","pt":1646093111316,"mc":[{"id":"1.195395448","rc":[{"atb":[[3.5,0]],"id":37535509}],"con":true,"img":false}]}
{"op":"mcm","clk":"5346641492","pt":1646093113903,"mc":[{"id":"1.195395448","rc":[{"atb":[[3.6,0]],"id":37535509}],"con":true,"img":false}]}
{"op":"mcm","clk":"5346641582","pt":1646093116299,"mc":[{"id":"1.195395448","rc":[{"atb":[[3.4,41.67]],"id":37535509}],"con":true,"img":false}]}
{"op":"mcm","clk":"5346641585","pt":1646093116415,"mc":[{"id":"1.195395448","rc":[{"atb":[[3.55,0]],"id":37535509}],"con":true,"img":false}]}
{"op":"mcm","clk":"5346641687","pt":1646093118722,"mc":[{"id":"1.195395448","rc":[{"atl":[[8,0]],"id":36899944}],"con":true,"img":false}]}
{"op":"mcm","clk":"5346641696","pt":1646093118828,"mc":[{"id":"1.195395448","rc":[{"atl":[[9,5.07]],"id":36899944}],"con":true,"img":false}]}
{"op":"mcm","clk":"5346641703","pt":1646093118891,"mc":[{"id":"1.195395448","rc":[{"atl":[[8.2,11.8],[7.8,0]],"id":36899944}],"con":true,"img":false}]}
{"op":"mcm","clk":"5346641710","pt":1646093118993,"mc":[{"id":"1.195395448","rc":[{"atl":[[8.2,1.66],[8.8,6.74]],"id":36899944}],"con":true,"img":false}]}
{"op":"mcm","clk":"5346641714","pt":1646093119087,"mc":[{"id":"1.195395448","rc":[{"atl":[[8.2,6.73],[8.8,0]],"id":36899944}],"con":true,"img":false}]}
{"op":"mcm","clk":"5346641720","pt":1646093119195,"mc":[{"id":"1.195395448","rc":[{"atl":[[8.2,1.66],[8.8,5.07]],"id":36899944}],"con":true,"img":false}]}
{"op":"mcm","clk":"5346641728","pt":1646093119398,"mc":[{"id":"1.195395448","rc":[{"atb":[[3.4,0],[3.5,19.53]],"id":40014837}],"con":true,"img":false}]}
{"op":"mcm","clk":"5346641761","pt":1646093120130,"mc":[{"id":"1.195395448","rc":[{"atb":[[3.5,16.56]],"id":40014837}],"con":true,"img":false}]}
{"op":"mcm","clk":"5346641906","pt":1646093123026,"mc":[{"id":"1.195395448","rc":[{"atb":[[3.5,2.97]],"id":37535509}],"con":true,"img":false}]}
{"op":"mcm","clk":"5346642035","pt":1646093126115,"mc":[{"id":"1.195395448","rc":[{"atb":[[3.45,19.59]],"id":40014837}],"con":true,"img":false}]}
{"op":"mcm","clk":"5346642120","pt":1646093127764,"mc":[{"id":"1.195395448","marketDefinition":{"bspMarket":false,"turnInPlayEnabled":false,"persistenceEnabled":false,"marketBaseRate":5.0,"eventId":"31270459","eventTypeId":"4339","numberOfWinners":3,"bettingType":"ODDS","marketType":"PLACE","marketTime":"2022-03-01T00:47:00.000Z","suspendTime":"2022-03-01T00:47:00.000Z","bspReconciled":false,"complete":true,"inPlay":false,"crossMatching":true,"runnersVoidable":false,"numberOfActiveRunners":8,"betDelay":0,"status":"OPEN","runners":[{"status":"ACTIVE","sortPriority":1,"id":38541023,"name":"2. Know Beast"},{"status":"ACTIVE","sortPriority":2,"id":43154430,"name":"3. Gandia"},{"status":"ACTIVE","sortPriority":3,"id":42315317,"name":"4. Homebush Villa"},{"status":"ACTIVE","sortPriority":4,"id":40014837,"name":"5. Goldstar Farryn"},{"status":"ACTIVE","sortPriority":5,"id":37535509,"name":"6. King Kong Blonde"},{"status":"ACTIVE","sortPriority":6,"id":37076580,"name":"7. Mitcham Hamish"},{"status":"ACTIVE","sortPriority":7,"id":36899944,"name":"8. Goldstar Willa"},{"status":"ACTIVE","sortPriority":8,"id":40041375,"name":"9. Homebush George"}],"regulators":["MR_INT"],"venue":"Addington","countryCode":"NZ","discountAllowed":true,"timezone":"NZ","openDate":"2022-02-28T23:02:00.000Z","version":4380660707,"name":"To Be Placed","eventName":"Addington (NZL) 1st Mar"},"rc":[],"con":true,"img":false}]}
{"op":"mcm","clk":"5346642226","pt":1646093130795,"mc":[{"id":"1.195395448","rc":[{"atb":[[3.05,7.71]],"id":36899944}],"con":true,"img":false}]}
{"op":"mcm","clk":"5346642233","pt":1646093131001,"mc":[{"id":"1.195395448","rc":[{"atb":[[2.26,12.54]],"id":38541023}],"con":true,"img":false}]}
{"op":"mcm","clk":"5346642238","pt":1646093131203,"mc":[{"id":"1.195395448","rc":[{"atb":[[2.46,5.72]],"id":40041375}],"con":true,"img":false}]}
{"op":"mcm","clk":"5346642248","pt":1646093131416,"mc":[{"id":"1.195395448","rc":[{"atb":[[3.5,6.32]],"id":37535509}],"con":true,"img":false}]}
{"op":"mcm","clk":"5346642254","pt":1646093131620,"mc":[{"id":"1.195395448","rc":[{"atb":[[1.43,36.76]],"id":37076580}],"con":true,"img":false}]}
{"op":"mcm","clk":"5346642415","pt":1646093135736,"mc":[{"id":"1.195395448","rc":[{"atb":[[3.45,3.03]],"id":40014837}],"con":true,"img":false}]}
{"op":"mcm","clk":"5346642422","pt":1646093135837,"mc":[{"id":"1.195395448","rc":[{"atb":[[3.15,16.55]],"id":40014837}],"con":true,"img":false}]}
{"op":"mcm","clk":"5346642467","pt":1646093136819,"mc":[{"id":"1.195395448","rc":[{"atb":[[3.45,6.44]],"id":40014837}],"con":true,"img":false}]}
{"op":"mcm","clk":"5346642720","pt":1646093142545,"mc":[{"id":"1.195395448","rc":[{"atb":[[3.4,0],[3.55,39.22]],"id":37535509}],"con":true,"img":false}]}
{"op":"mcm","clk":"5346642770","pt":1646093144135,"mc":[{"id":"1.195395448","rc":[{"atb":[[3.5,3.34]],"id":37535509}],"con":true,"img":false}]}
{"op":"mcm","clk":"5346642803","pt":1646093145318,"mc":[{"id":"1.195395448","rc":[{"atl":[[8.2,6.73],[8.8,0]],"id":36899944}],"con":true,"img":false}]}
{"op":"mcm","clk":"5346642807","pt":1646093145419,"mc":[{"id":"1.195395448","rc":[{"atl":[[8.2,1.66],[8.8,5.07]],"id":36899944}],"con":true,"img":false}]}
{"op":"mcm","clk":"5346643001","pt":1646093150037,"mc":[{"id":"1.195395448","rc":[{"atb":[[3.65,2.8]],"id":37535509}],"con":true,"img":false}]}
{"op":"mcm","clk":"5346643110","pt":1646093152413,"mc":[{"id":"1.195395448","rc":[{"atb":[[3.5,43.34]],"id":37535509}],"con":true,"img":false}]}
{"op":"mcm","clk":"5346643113","pt":1646093152516,"mc":[{"id":"1.195395448","rc":[{"atb":[[3.35,25.54],[3.55,0]],"id":37535509}],"con":true,"img":false}]}
{"op":"mcm","clk":"5346643120","pt":1646093152619,"mc":[{"id":"1.195395448","rc":[{"atb":[[3.45,17.25]],"id":37535509}],"con":true,"img":false}]}
{"op":"mcm","clk":"5346643131","pt":1646093152928,"mc":[{"id":"1.195395448","rc":[{"atb":[[3.65,0]],"id":37535509}],"con":true,"img":false}]}
{"op":"mcm","clk":"5346643335","pt":1646093159037,"mc":[{"id":"1.195395448","rc":[{"atb":[[3.6,2.86]],"id":37535509}],"con":true,"img":false}]}
{"op":"mcm","clk":"5346643423","pt":1646093161142,"mc":[{"id":"1.195395448","rc":[{"atb":[[3.5,40]],"id":37535509}],"con":true,"img":false}]}
{"op":"mcm","clk":"5346643618","pt":1646093166954,"mc":[{"id":"1.195395448","rc":[{"atb":[[3.6,6.08]],"id":37535509}],"con":true,"img":false}]}
{"op":"mcm","clk":"5346643684","pt":1646093169166,"mc":[{"id":"1.195395448","rc":[{"atb":[[2.9,0]],"id":36899944}],"con":true,"img":false}]}
{"op":"mcm","clk":"5346643689","pt":1646093169269,"mc":[{"id":"1.195395448","rc":[{"atb":[[3,21.34]],"id":36899944}],"con":true,"img":false}]}
{"op":"mcm","clk":"5346643753","pt":1646093171377,"mc":[{"id":"1.195395448","rc":[{"atl":[[8.2,6.73],[8.8,0]],"id":36899944}],"con":true,"img":false}]}
{"op":"mcm","clk":"5346644243","pt":1646093185767,"mc":[{"id":"1.195395448","rc":[{"atb":[[3.45,0]],"id":37535509}],"con":true,"img":false}]}
{"op":"mcm","clk":"5346644250","pt":1646093185868,"mc":[{"id":"1.195395448","rc":[{"atb":[[3.55,17.25]],"id":37535509}],"con":true,"img":false}]}
{"op":"mcm","clk":"5346645352","pt":1646093218439,"mc":[{"id":"1.195395448","rc":[{"atb":[[2.26,28.61],[2.96,0]],"id":40014837},{"atl":[[34,0]],"id":37535509}],"con":true,"img":false}]}
{"op":"mcm","clk":"5346645356","pt":1646093218541,"mc":[{"id":"1.195395448","rc":[{"atl":[[40,2.7]],"id":37535509}],"con":true,"img":false}]}
{"op":"mcm","clk":"5346646537","pt":1646093250676,"mc":[{"id":"1.195395448","rc":[{"atl":[[16.5,0]],"id":38541023}],"con":true,"img":false}]}
{"op":"mcm","clk":"5346646543","pt":1646093250780,"mc":[{"id":"1.195395448","rc":[{"atl":[[19.5,2.7]],"id":38541023}],"con":true,"img":false}]}
{"op":"mcm","clk":"5346647756","pt":1646093282624,"mc":[{"id":"1.195395448","rc":[{"atl":[[26,0]],"id":37535509}],"con":true,"img":false}]}
{"op":"mcm","clk":"5346647760","pt":1646093282680,"mc":[{"id":"1.195395448","rc":[{"atl":[[23,1.84]],"id":37535509}],"con":true,"img":false}]}
{"op":"mcm","clk":"5346649003","pt":1646093313852,"mc":[{"id":"1.195395448","rc":[{"atb":[[2.26,0],[2.96,18.39]],"id":40014837}],"con":true,"img":false}]}
{"op":"mcm","clk":"5346650061","pt":1646093344880,"mc":[{"id":"1.195395448","rc":[{"atb":[[1.31,0]],"id":37076580}],"con":true,"img":false}]}
{"op":"mcm","clk":"5346650063","pt":1646093344985,"mc":[{"id":"1.195395448","rc":[{"atb":[[1.36,117.36]],"id":37076580}],"con":true,"img":false}]}
{"op":"mcm","clk":"5346650510","pt":1646093360188,"mc":[{"id":"1.195395448","rc":[{"atb":[[1.36,0]],"id":37076580}],"con":true,"img":false}]}
{"op":"mcm","clk":"5346650514","pt":1646093360289,"mc":[{"id":"1.195395448","rc":[{"atb":[[1.31,117.36]],"id":37076580}],"con":true,"img":false}]}
{"op":"mcm","clk":"5346655452","pt":1646093507898,"mc":[{"id":"1.195395448","rc":[{"atb":[[2.26,28.61],[2.96,0]],"id":40014837},{"atl":[[23,0]],"id":37535509}],"con":true,"img":false}]}
{"op":"mcm","clk":"5346655456","pt":1646093508001,"mc":[{"id":"1.195395448","rc":[{"atl":[[25,1.84]],"id":37535509}],"con":true,"img":false}]}
{"op":"mcm","clk":"5346657180","pt":1646093564567,"mc":[{"id":"1.195395448","rc":[{"atl":[[12,0]],"id":38541023}],"con":true,"img":false}]}
{"op":"mcm","clk":"5346657184","pt":1646093564669,"mc":[{"id":"1.195395448","rc":[{"atl":[[13,4.05]],"id":38541023}],"con":true,"img":false}]}
{"op":"mcm","clk":"5346658768","pt":1646093619414,"mc":[{"id":"1.195395448","rc":[{"atl":[[13,0]],"id":38541023}],"con":true,"img":false}]}
{"op":"mcm","clk":"5346658771","pt":1646093619517,"mc":[{"id":"1.195395448","rc":[{"atl":[[12,4.05]],"id":38541023}],"con":true,"img":false}]}
{"op":"mcm","clk":"5346660165","pt":1646093660106,"mc":[{"id":"1.195395448","rc":[{"atb":[[2.26,0],[2.96,18.39]],"id":40014837}],"con":true,"img":false}]}
{"op":"mcm","clk":"5346660858","pt":1646093683941,"mc":[{"id":"1.195395448","rc":[{"atb":[[3.45,34.52],[3.5,0]],"id":37535509}],"con":true,"img":false}]}
{"op":"mcm","clk":"5346660906","pt":1646093685021,"mc":[{"id":"1.195395448","rc":[{"atb":[[3.6,3.21]],"id":37535509}],"con":true,"img":false}]}
{"op":"mcm","clk":"5346660971","pt":1646093686823,"mc":[{"id":"1.195395448","rc":[{"atl":[[12,0]],"id":38541023},{"atb":[[3.55,0]],"id":37535509}],"con":true,"img":false}]}
{"op":"mcm","clk":"5346660977","pt":1646093686925,"mc":[{"id":"1.195395448","rc":[{"atl":[[11.5,4.05]],"id":38541023},{"atb":[[3.5,17.25]],"id":37535509}],"con":true,"img":false}]}
{"op":"mcm","clk":"5346661141","pt":1646093691031,"mc":[{"id":"1.195395448","rc":[{"atb":[[3.55,2.92]],"id":37535509}],"con":true,"img":false}]}
{"op":"mcm","clk":"5346661500","pt":1646093700026,"mc":[{"id":"1.195395448","rc":[{"atb":[[3.6,0]],"id":37535509}],"con":true,"img":false}]}
{"op":"mcm","clk":"5346661754","pt":1646093705774,"mc":[{"id":"1.195395448","rc":[{"atb":[[3.55,6.19]],"id":37535509}],"con":true,"img":false}]}
{"op":"mcm","clk":"5346662014","pt":1646093713064,"mc":[{"id":"1.195395448","rc":[{"atb":[[1.31,0]],"id":37076580}],"con":true,"img":false}]}
{"op":"mcm","clk":"5346662017","pt":1646093713167,"mc":[{"id":"1.195395448","rc":[{"atb":[[1.36,117.36]],"id":37076580}],"con":true,"img":false}]}
{"op":"mcm","clk":"5346663424","pt":1646093753749,"mc":[{"id":"1.195395448","rc":[{"atl":[[2.54,50.08],[2.52,21.86]],"id":42315317}],"con":true,"img":false}]}
{"op":"mcm","clk":"5346663710","pt":1646093764745,"mc":[{"id":"1.195395448","rc":[{"atl":[[2.2,0]],"id":43154430}],"con":true,"img":false}]}
{"op":"mcm","clk":"5346663715","pt":1646093764846,"mc":[{"id":"1.195395448","rc":[{"atl":[[2.4,30.82]],"id":43154430}],"con":true,"img":false}]}
{"op":"mcm","clk":"5346664920","pt":1646093801518,"mc":[{"id":"1.195395448","rc":[{"atb":[[3.45,0],[3.4,34.52]],"id":37535509}],"con":true,"img":false}]}
{"op":"mcm","clk":"5346664941","pt":1646093802235,"mc":[{"id":"1.195395448","rc":[{"atb":[[3.55,3.27]],"id":37535509}],"con":true,"img":false}]}
{"op":"mcm","clk":"5346672392","pt":1646093802855,"mc":[{"id":"1.195395448","rc":[{"atb":[[3.5,0]],"id":37535509},{"atb":[[1.36,0]],"id":37076580}],"con":true,"img":false}]}
{"op":"mcm","clk":"5346672395","pt":1646093802905,"mc":[{"id":"1.195395448","rc":[{"atb":[[3.45,17.25]],"id":37535509},{"atb":[[1.31,117.36]],"id":37076580}],"con":true,"img":false}]}
{"op":"mcm","clk":"5346672620","pt":1646093808102,"mc":[{"id":"1.195395448","rc":[{"atb":[[3.5,2.97]],"id":37535509}],"con":true,"img":false}]}
{"op":"mcm","clk":"5346673043","pt":1646093820024,"mc":[{"id":"1.195395448","rc":[{"atb":[[3.55,0]],"id":37535509}],"con":true,"img":false}]}
{"op":"mcm","clk":"5346673197","pt":1646093824024,"mc":[{"id":"1.195395448","rc":[{"atb":[[1.15,650.23],[1.11,639.96],[1.13,250],[1.17,117.65]],"id":43154430},{"atl":[[2,50],[1.98,20.41],[2.04,72.12],[2.08,115.74]],"id":43154430}],"con":true,"img":false}]}
{"op":"mcm","clk":"5346673205","pt":1646093824179,"mc":[{"id":"1.195395448","rc":[{"atb":[[3.2,56.82],[3.4,20.83],[3.5,24.56],[3.3,32.61]],"id":40014837},{"atl":[[9.6,5.81],[9.2,2.44],[10,8.33],[11,12.5]],"id":40014837},{"atb":[[1.8,25],[1.74,168.92],[1.78,64.1],[1.76,98.68]],"id":38541023},{"atl":[[4.3,37.88],[3.85,7.02],[3.95,16.95],[4.1,24.19]],"id":38541023},{"atb":[[3.45,42.79],[3.2,22.73],[3.1,92.88],[3.4,0],[3,62.5],[3.3,8.7]],"id":37535509},{"atl":[[8.2,17.36],[7.4,7.81],[7,3.33],[7.8,11.03]],"id":37535509},{"atb":[[2.98,93.45],[3.25,8.89],[3.15,23.26],[3.05,44.3]],"id":36899944},{"atl":[[7.4,11.72],[6.6,3.57],[7,8.33],[7.8,18.38]],"id":36899944},{"atb":[[1.2,850.35],[1.26,502.1],[1.22,250],[1.24,208.33]],"id":42315317},{"atl":[[2,50],[1.98,20.41],[2.04,72.12],[2.08,115.74]],"id":42315317},{"atb":[[1.18,111.11],[1.12,250],[1.16,250],[1.14,250]],"id":40041375},{"atl":[[6.4,13.89],[5.8,6.67],[6,10],[6.8,21.55]],"id":40041375},{"atb":[[1.18,555.56],[1.16,40.56]],"id":43154430},{"atb":[[1.41,162.51],[1.43,83.27],[1.37,250],[1.39,192.31]],"id":37076580},{"atl":[[2.22,61.48],[2.18,42.37],[2.26,99.21],[2.14,17.54]],"id":37076580}],"con":true,"img":false}]}
{"op":"mcm","clk":"5346673210","pt":1646093824232,"mc":[{"id":"1.195395448","rc":[{"atl":[[4.1,27.19],[5.5,2.66]],"id":38541023},{"atl":[[8,5.07]],"id":36899944}],"con":true,"img":false}]}
{"op":"mcm","clk":"5346673213","pt":1646093824333,"mc":[{"id":"1.195395448","rc":[{"atl":[[8.2,1.66]],"id":36899944}],"con":true,"img":false}]}
{"op":"mcm","clk":"5346673247","pt":1646093825156,"mc":[{"id":"1.195395448","rc":[{"atb":[[3.45,25.54]],"id":37535509},{"atl":[[2.4,0]],"id":43154430},{"atl":[[3.1,0],[4.2,12.98]],"id":37076580}],"con":true,"img":false}]}
{"op":"mcm","clk":"5346673250","pt":1646093825261,"mc":[{"id":"1.195395448","rc":[{"atb":[[3.35,42.8]],"id":37535509},{"atl":[[2.58,30.82]],"id":43154430}],"con":true,"img":false}]}
{"op":"mcm","clk":"5346673313","pt":1646093826335,"mc":[{"id":"1.195395448","rc":[{"atb":[[3.45,3.4]],"id":40014837},{"atb":[[3.5,0]],"id":37535509},{"atb":[[3.05,40.66]],"id":36899944},{"atb":[[1.43,65.94]],"id":37076580}],"con":true,"img":false}]}
{"op":"mcm","clk":"5346673437","pt":1646093829263,"mc":[{"id":"1.195395448","rc":[{"atb":[[3.45,0],[3.4,41.67]],"id":37535509},{"atb":[[1.18,0],[1.17,705.89]],"id":43154430}],"con":true,"img":false}]}
{"op":"mcm","clk":"5346673582","pt":1646093832246,"mc":[{"id":"1.195395448","rc":[{"atb":[[3.6,2.86]],"id":40014837},{"atb":[[3.2,3.38]],"id":36899944},{"atb":[[1.46,16.19]],"id":37076580}],"con":true,"img":false}]}
{"op":"mcm","clk":"5346673588","pt":1646093832351,"mc":[{"id":"1.195395448","rc":[{"atb":[[3.6,6.27]],"id":40014837}],"con":true,"img":false}]}
{"op":"mcm","clk":"5346673592","pt":1646093832452,"mc":[{"id":"1.195395448","rc":[{"atb":[[3.5,8]],"id":40014837}],"con":true,"img":false}]}
{"op":"mcm","clk":"5346673676","pt":1646093835139,"mc":[{"id":"1.195395448","rc":[{"atb":[[1.79,45.41],[2.02,0]],"id":38541023}],"con":true,"img":false}]}
{"op":"mcm","clk":"5346673681","pt":1646093835241,"mc":[{"id":"1.195395448","rc":[{"atb":[[3.35,25.54],[3.15,0]],"id":37535509},{"atl":[[9,0],[13.5,0]],"id":36899944},{"atl":[[10.5,0]],"id":40041375}],"con":true,"img":false}]}
{"op":"mcm","clk":"5346673684","pt":1646093835397,"mc":[{"id":"1.195395448","rc":[{"atb":[[3.6,3.41]],"id":40014837},{"atb":[[3.15,17.25],[2.96,17.18]],"id":37535509},{"atl":[[17,3.07],[10.5,6.33]],"id":36899944},{"atl":[[12.5,3.55]],"id":40041375}],"con":true,"img":false}]}
{"op":"mcm","clk":"5346673769","pt":1646093837456,"mc":[{"id":"1.195395448","rc":[{"atb":[[3.6,0],[3.5,16]],"id":40014837}],"con":true,"img":false}]}
{"op":"mcm","clk":"5346673806","pt":1646093838378,"mc":[{"id":"1.195395448","rc":[{"atb":[[3.5,2.97]],"id":37535509}],"con":true,"img":false}]}
{"op":"mcm","clk":"5346673815","pt":1646093838586,"mc":[{"id":"1.195395448","rc":[{"atb":[[3.05,36.59]],"id":36899944},{"atb":[[1.43,46.51]],"id":37076580}],"con":true,"img":false}]}
{"op":"mcm","clk":"5346673894","pt":1646093841400,"mc":[{"id":"1.195395448","rc":[{"atb":[[3.5,18.97]],"id":40014837},{"atb":[[1.46,0]],"id":37076580}],"con":true,"img":false}]}
{"op":"mcm","clk":"5346674002","pt":1646093844172,"mc":[{"id":"1.195395448","rc":[{"atb":[[3.5,6.32]],"id":37535509}],"con":true,"img":false}]}
{"op":"mcm","clk":"5346674007","pt":1646093844278,"mc":[{"id":"1.195395448","rc":[{"atb":[[3.1,3.97]],"id":36899944}],"con":true,"img":false}]}
{"op":"mcm","clk":"5346674011","pt":1646093844380,"mc":[{"id":"1.195395448","rc":[{"atb":[[1.44,18.99]],"id":37076580}],"con":true,"img":false}]}
{"op":"mcm","clk":"5346674113","pt":1646093847196,"mc":[{"id":"1.195395448","rc":[{"atb":[[3.45,25.54],[3.4,0]],"id":37535509}],"con":true,"img":false}]}
{"op":"mcm","clk":"5346674118","pt":1646093847296,"mc":[{"id":"1.195395448","rc":[{"atb":[[3.45,0],[3.4,25.54]],"id":37535509}],"con":true,"img":false}]}
{"op":"mcm","clk":"5346674168","pt":1646093848475,"mc":[{"id":"1.195395448","rc":[{"atb":[[1.44,35.92]],"id":37076580}],"con":true,"img":false}]}
{"op":"mcm","clk":"5346674388","pt":1646093855209,"mc":[{"id":"1.195395448","rc":[{"atb":[[3.15,0]],"id":40014837},{"atl":[[11.5,0],[6,8.11]],"id":38541023},{"atl":[[12,4.78],[25,0]],"id":37535509},{"atb":[[3,0]],"id":36899944},{"atb":[[1.21,0]],"id":42315317},{"atl":[[8,0]],"id":40041375},{"atl":[[2.16,0]],"id":43154430}],"con":true,"img":false}]}
{"op":"mcm","clk":"5346674390","pt":1646093855313,"mc":[{"id":"1.195395448","rc":[{"atb":[[3.35,42.1]],"id":40014837},{"atb":[[3.1,25.32]],"id":36899944},{"atb":[[1.23,168.69]],"id":42315317},{"atl":[[6.6,5.79]],"id":40041375},{"atl":[[1.99,34.97]],"id":43154430}],"con":true,"img":false}]}
{"op":"mcm","clk":"5346674563","pt":1646093860497,"mc":[{"id":"1.195395448","rc":[{"atb":[[3.45,25.54]],"id":37535509}],"con":true,"img":false}]}
{"op":"mcm","clk":"5346674568","pt":1646093860598,"mc":[{"id":"1.195395448","rc":[{"atb":[[3.4,0]],"id":37535509}],"con":true,"img":false}]}
{"op":"mcm","clk":"5346674619","pt":1646093862292,"mc":[{"id":"1.195395448","rc":[{"atb":[[3.5,3.34]],"id":37535509}],"con":true,"img":false}]}
{"op":"mcm","clk":"5346674691","pt":1646093865185,"mc":[{"id":"1.195395448","rc":[{"atb":[[1.11,250],[1.14,306.66]],"id":43154430}],"con":true,"img":false}]}
{"op":"mcm","clk":"5346674703","pt":1646093865595,"mc":[{"id":"1.195395448","rc":[{"atb":[[3.45,0],[3.4,28.88]],"id":37535509}],"con":true,"img":false}]}
{"op":"mcm","clk":"5346675043","pt":1646093874430,"mc":[{"id":"1.195395448","rc":[{"atb":[[3.5,6.32]],"id":37535509}],"con":true,"img":false}]}
{"op":"mcm","clk":"5346675067","pt":1646093875148,"mc":[{"id":"1.195395448","rc":[{"atl":[[9.4,4.27]],"id":38541023},{"atb":[[2.8,21.38]],"id":36899944},{"atb":[[2.22,32.06]],"id":40041375}],"con":true,"img":false}]}
{"op":"mcm","clk":"5346675072","pt":1646093875206,"mc":[{"id":"1.195395448","rc":[{"atb":[[2.96,0]],"id":40014837},{"atl":[[19.5,0]],"id":38541023},{"atl":[[40,0]],"id":37535509},{"atb":[[1.86,0]],"id":36899944},{"atb":[[1.76,0]],"id":40041375},{"atb":[[1.31,0]],"id":37076580}],"con":true,"img":false}]}
{"op":"mcm","clk":"5346675075","pt":1646093875308,"mc":[{"id":"1.195395448","rc":[{"atb":[[3.25,18.39]],"id":40014837},{"atl":[[18,2.7]],"id":37535509},{"atb":[[1.38,117.36]],"id":37076580}],"con":true,"img":false}]}
{"op":"mcm","clk":"5346675392","pt":1646093884649,"mc":[{"id":"1.195395448","rc":[{"atl":[[3.85,0],[3.75,7.27]],"id":38541023}],"con":true,"img":false}]}
{"op":"mcm","clk":"5346675394","pt":1646093884751,"mc":[{"id":"1.195395448","rc":[{"atl":[[3.95,44.14]],"id":38541023}],"con":true,"img":false}]}
{"op":"mcm","clk":"5346675397","pt":1646093884853,"mc":[{"id":"1.195395448","rc":[{"atl":[[4.1,24.19]],"id":38541023}],"con":true,"img":false}]}
{"op":"mcm","clk":"5346675400","pt":1646093884957,"mc":[{"id":"1.195395448","rc":[{"atl":[[3.95,16.95],[4.1,56.45]],"id":38541023}],"con":true,"img":false}]}
{"op":"mcm","clk":"5346675409","pt":1646093885162,"mc":[{"id":"1.195395448","rc":[{"atb":[[3.45,25.54],[3.4,0]],"id":37535509}],"con":true,"img":false}]}
{"op":"mcm","clk":"5346675420","pt":1646093885263,"mc":[{"id":"1.195395448","rc":[{"atb":[[3.4,25.54]],"id":37535509}],"con":true,"img":false}]}
{"op":"mcm","clk":"5346675426","pt":1646093885365,"mc":[{"id":"1.195395448","rc":[{"atb":[[3.45,0]],"id":37535509}],"con":true,"img":false}]}
{"op":"mcm","clk":"5346675734","pt":1646093894649,"mc":[{"id":"1.195395448","rc":[{"atl":[[3.85,17.54]],"id":38541023}],"con":true,"img":false}]}
{"op":"mcm","clk":"5346675736","pt":1646093894752,"mc":[{"id":"1.195395448","rc":[{"atl":[[3.95,50.85],[4.1,24.19]],"id":38541023}],"con":true,"img":false}]}
{"op":"mcm","clk":"5346675754","pt":1646093895364,"mc":[{"id":"1.195395448","rc":[{"atl":[[4.3,0]],"id":38541023}],"con":true,"img":false}]}
{"op":"mcm","clk":"5346675836","pt":1646093897649,"mc":[{"id":"1.195395448","rc":[{"atb":[[3.45,25.54]],"id":37535509}],"con":true,"img":false}]}
{"op":"mcm","clk":"5346675839","pt":1646093897750,"mc":[{"id":"1.195395448","rc":[{"atb":[[3.4,0]],"id":37535509}],"con":true,"img":false}]}
{"op":"mcm","clk":"5346675848","pt":1646093897955,"mc":[{"id":"1.195395448","rc":[{"atb":[[3.45,0],[3.4,31.86]],"id":37535509}],"con":true,"img":false}]}
{"op":"mcm","clk":"5346675877","pt":1646093898778,"mc":[{"id":"1.195395448","rc":[{"atb":[[3.5,2.97]],"id":37535509}],"con":true,"img":false}]}
{"op":"mcm","clk":"5346676093","pt":1646093904774,"mc":[{"id":"1.195395448","rc":[{"atl":[[3.95,59.32]],"id":38541023}],"con":true,"img":false}]}
{"op":"mcm","clk":"5346676111","pt":1646093905287,"mc":[{"id":"1.195395448","rc":[{"atl":[[13,0]],"id":40014837}],"con":true,"img":false}]}
{"op":"mcm","clk":"5346676118","pt":1646093905389,"mc":[{"id":"1.195395448","rc":[{"atl":[[14.5,3.38]],"id":40014837}],"con":true,"img":false}]}
{"op":"mcm","clk":"5346676283","pt":1646093910307,"mc":[{"id":"1.195395448","rc":[{"atb":[[3.45,25.54],[3.4,0]],"id":37535509}],"con":true,"img":false}]}
{"op":"mcm","clk":"5346676291","pt":1646093910514,"mc":[{"id":"1.195395448","rc":[{"atb":[[3.45,0],[3.4,25.54]],"id":37535509}],"con":true,"img":false}]}
{"op":"mcm","clk":"5346676456","pt":1646093914720,"mc":[{"id":"1.195395448","rc":[{"atl":[[4.1,40.32]],"id":38541023}],"con":true,"img":false}]}
{"op":"mcm","clk":"5346676522","pt":1646093916517,"mc":[{"id":"1.195395448","rc":[{"atb":[[3.5,6.32]],"id":37535509}],"con":true,"img":false}]}
{"op":"mcm","clk":"5346677210","pt":1646093936633,"mc":[{"id":"1.195395448","rc":[{"atb":[[3.45,25.54],[3.4,0]],"id":37535509}],"con":true,"img":false}]}
{"op":"mcm","clk":"5346677240","pt":1646093937610,"mc":[{"id":"1.195395448","rc":[{"atb":[[3.5,3.34]],"id":37535509}],"con":true,"img":false}]}
{"op":"mcm","clk":"5346677388","pt":1646093941724,"mc":[{"id":"1.195395448","rc":[{"atb":[[3.4,28.88]],"id":37535509}],"con":true,"img":false}]}
{"op":"mcm","clk":"5346677393","pt":1646093941828,"mc":[{"id":"1.195395448","rc":[{"atb":[[3.45,0]],"id":37535509}],"con":true,"img":false}]}
{"op":"mcm","clk":"5346677518","pt":1646093945165,"mc":[{"id":"1.195395448","rc":[{"atb":[[3.4,35.85],[3.25,0]],"id":40014837}],"con":true,"img":false}]}
{"op":"mcm","clk":"5346677573","pt":1646093946653,"mc":[{"id":"1.195395448","rc":[{"atb":[[3.45,0]],"id":40014837}],"con":true,"img":false}]}
{"op":"mcm","clk":"5346677790","pt":1646093952460,"mc":[{"id":"1.195395448","rc":[{"atb":[[3.5,6.32]],"id":37535509}],"con":true,"img":false}]}
{"op":"mcm","clk":"5346677976","pt":1646093958476,"mc":[{"id":"1.195395448","rc":[{"atb":[[3.5,22.32]],"id":40014837}],"con":true,"img":false}]}
{"op":"mcm","clk":"5346678504","pt":1646093972772,"mc":[{"id":"1.195395448","rc":[{"atb":[[3.45,25.54],[3.4,0]],"id":37535509}],"con":true,"img":false}]}
{"op":"mcm","clk":"5346678530","pt":1646093973590,"mc":[{"id":"1.195395448","rc":[{"atb":[[3.5,3.34]],"id":37535509}],"con":true,"img":false}]}
{"op":"mcm","clk":"5346678620","pt":1646093976316,"mc":[{"id":"1.195395448","rc":[{"atb":[[3.5,0]],"id":37535509}],"con":true,"img":false}]}
{"op":"mcm","clk":"5346678675","pt":1646093977904,"mc":[{"id":"1.195395448","rc":[{"atb":[[3.4,41.67]],"id":37535509}],"con":true,"img":false}]}
{"op":"mcm","clk":"5346678678","pt":1646093978008,"mc":[{"id":"1.195395448","rc":[{"atb":[[3.45,0]],"id":37535509}],"con":true,"img":false}]}
{"op":"mcm","clk":"5346679008","pt":1646093985623,"mc":[{"id":"1.195395448","rc":[{"atb":[[3.5,2.97]],"id":37535509}],"con":true,"img":false}]}
{"op":"mcm","clk":"5346679349","pt":1646093994726,"mc":[{"id":"1.195395448","rc":[{"atb":[[3.5,6.32]],"id":37535509}],"con":true,"img":false}]}
{"op":"mcm","clk":"5346679492","pt":1646093997855,"mc":[{"id":"1.195395448","rc":[{"atb":[[3.45,25.54],[3.4,0]],"id":37535509}],"con":true,"img":false}]}
{"op":"mcm","clk":"5346679588","pt":1646094000733,"mc":[{"id":"1.195395448","rc":[{"atb":[[3.5,3.34]],"id":37535509}],"con":true,"img":false}]}
{"op":"mcm","clk":"5346679666","pt":1646094002937,"mc":[{"id":"1.195395448","rc":[{"atb":[[3.45,0],[3.4,28.88]],"id":37535509}],"con":true,"img":false}]}
{"op":"mcm","clk":"5346679915","pt":1646094009657,"mc":[{"id":"1.195395448","rc":[{"atb":[[3.5,6.32]],"id":37535509}],"con":true,"img":false}]}
{"op":"mcm","clk":"5346680077","pt":1646094015160,"mc":[{"id":"1.195395448","rc":[{"atb":[[3.15,0]],"id":37535509}],"con":true,"img":false}]}
{"op":"mcm","clk":"5346680082","pt":1646094015261,"mc":[{"id":"1.195395448","rc":[{"atb":[[3.45,17.25]],"id":37535509}],"con":true,"img":false}]}
{"op":"mcm","clk":"5346680347","pt":1646094023482,"mc":[{"id":"1.195395448","rc":[{"atb":[[3.45,42.79],[3.4,0]],"id":37535509}],"con":true,"img":false}]}
{"op":"mcm","clk":"5346680350","pt":1646094023585,"mc":[{"id":"1.195395448","rc":[{"atb":[[3.4,41.67]],"id":37535509}],"con":true,"img":false}]}
{"op":"mcm","clk":"5346680354","pt":1646094023687,"mc":[{"id":"1.195395448","rc":[{"atb":[[3.45,17.25]],"id":37535509}],"con":true,"img":false}]}
{"op":"mcm","clk":"5346680761","pt":1646094035190,"mc":[{"id":"1.195395448","rc":[{"atb":[[3.45,42.79]],"id":37535509}],"con":true,"img":false}]}
{"op":"mcm","clk":"5346680765","pt":1646094035293,"mc":[{"id":"1.195395448","rc":[{"atb":[[3.4,0]],"id":37535509}],"con":true,"img":false}]}
{"op":"mcm","clk":"5346680770","pt":1646094035397,"mc":[{"id":"1.195395448","rc":[{"atb":[[3.45,17.25],[3.4,41.67]],"id":37535509}],"con":true,"img":false}]}
{"op":"mcm","clk":"5346681186","pt":1646094046710,"mc":[{"id":"1.195395448","rc":[{"atb":[[3.45,42.79],[3.4,0]],"id":37535509}],"con":true,"img":false}]}
{"op":"mcm","clk":"5346681188","pt":1646094046813,"mc":[{"id":"1.195395448","rc":[{"atb":[[3.45,17.25],[3.4,25.54]],"id":37535509}],"con":true,"img":false}]}
{"op":"mcm","clk":"5346681505","pt":1646094055248,"mc":[{"id":"1.195395448","rc":[{"atb":[[3.45,0]],"id":37535509}],"con":true,"img":false}]}
{"op":"mcm","clk":"5346681509","pt":1646094055349,"mc":[{"id":"1.195395448","rc":[{"atb":[[3.15,17.25]],"id":37535509}],"con":true,"img":false}]}
{"op":"mcm","clk":"5346681626","pt":1646094058538,"mc":[{"id":"1.195395448","rc":[{"atb":[[3.45,25.54]],"id":37535509}],"con":true,"img":false}]}
{"op":"mcm","clk":"5346681633","pt":1646094058641,"mc":[{"id":"1.195395448","rc":[{"atb":[[3.4,0]],"id":37535509}],"con":true,"img":false}]}
{"op":"mcm","clk":"5346681724","pt":1646094060646,"mc":[{"id":"1.195395448","rc":[{"atb":[[3.5,3.34]],"id":37535509}],"con":true,"img":false}]}
{"op":"mcm","clk":"5346681828","pt":1646094063628,"mc":[{"id":"1.195395448","rc":[{"atb":[[3.45,0],[3.4,28.88]],"id":37535509}],"con":true,"img":false}]}
{"op":"mcm","clk":"5346681832","pt":1646094063731,"mc":[{"id":"1.195395448","rc":[{"atb":[[3.5,0]],"id":37535509}],"con":true,"img":false}]}
{"op":"mcm","clk":"5346682200","pt":1646094072663,"mc":[{"id":"1.195395448","rc":[{"atb":[[3.5,2.97]],"id":37535509}],"con":true,"img":false}]}
{"op":"mcm","clk":"5346682576","pt":1646094081540,"mc":[{"id":"1.195395448","rc":[{"atb":[[3.5,6.32]],"id":37535509}],"con":true,"img":false}]}
{"op":"mcm","clk":"5346682624","pt":1646094082974,"mc":[{"id":"1.195395448","rc":[{"atb":[[3.45,25.54],[3.4,0]],"id":37535509}],"con":true,"img":false}]}
{"op":"mcm","clk":"5346682627","pt":1646094083076,"mc":[{"id":"1.195395448","rc":[{"atb":[[3.45,0],[3.4,25.54]],"id":37535509}],"con":true,"img":false}]}
{"op":"mcm","clk":"5346683174","pt":1646094095018,"mc":[{"id":"1.195395448","rc":[{"atb":[[3.45,25.54]],"id":37535509}],"con":true,"img":false}]}
{"op":"mcm","clk":"5346683178","pt":1646094095069,"mc":[{"id":"1.195395448","rc":[{"atb":[[3.4,0]],"id":37535509}],"con":true,"img":false}]}
{"op":"mcm","clk":"5346683261","pt":1646094096864,"mc":[{"id":"1.195395448","rc":[{"atb":[[3.5,3.34]],"id":37535509}],"con":true,"img":false}]}
{"op":"mcm","clk":"5346683374","pt":1646094100101,"mc":[{"id":"1.195395448","rc":[{"atb":[[3.45,0],[3.4,28.88]],"id":37535509}],"con":true,"img":false}]}
{"op":"mcm","clk":"5346683718","pt":1646094108823,"mc":[{"id":"1.195395448","rc":[{"atb":[[3.5,6.32]],"id":37535509}],"con":true,"img":false}]}
{"op":"mcm","clk":"5346684121","pt":1646094118732,"mc":[{"id":"1.195395448","rc":[{"atb":[[3.45,25.54],[3.4,0]],"id":37535509}],"con":true,"img":false}]}
{"op":"mcm","clk":"5346684207","pt":1646094120736,"mc":[{"id":"1.195395448","rc":[{"atb":[[3.5,3.34]],"id":37535509}],"con":true,"img":false}]}
{"op":"mcm","clk":"5346684304","pt":1646094123148,"mc":[{"id":"1.195395448","rc":[{"atb":[[3.5,0]],"id":37535509}],"con":true,"img":false}]}
{"op":"mcm","clk":"5346684329","pt":1646094123813,"mc":[{"id":"1.195395448","rc":[{"atb":[[3.4,41.67]],"id":37535509}],"con":true,"img":false}]}
{"op":"mcm","clk":"5346684332","pt":1646094123915,"mc":[{"id":"1.195395448","rc":[{"atb":[[3.45,0]],"id":37535509}],"con":true,"img":false}]}
{"op":"mcm","clk":"5346684695","pt":1646094132743,"mc":[{"id":"1.195395448","rc":[{"atb":[[3.5,2.97]],"id":37535509}],"con":true,"img":false}]}
{"op":"mcm","clk":"5346684774","pt":1646094135259,"mc":[{"id":"1.195395448","rc":[{"atb":[[3.15,0]],"id":37535509}],"con":true,"img":false}]}
{"op":"mcm","clk":"5346684777","pt":1646094135360,"mc":[{"id":"1.195395448","rc":[{"atb":[[3.45,17.25]],"id":37535509}],"con":true,"img":false}]}
{"op":"mcm","clk":"5346685007","pt":1646094140865,"mc":[{"id":"1.195395448","rc":[{"atb":[[3.5,6.32]],"id":37535509}],"con":true,"img":false}]}
{"op":"mcm","clk":"5346685066","pt":1646094142153,"mc":[{"id":"1.195395448","rc":[{"atb":[[3.45,42.79],[3.4,0]],"id":37535509}],"con":true,"img":false}]}
{"op":"mcm","clk":"5346685072","pt":1646094142257,"mc":[{"id":"1.195395448","rc":[{"atb":[[3.45,17.25],[3.4,41.67]],"id":37535509}],"con":true,"img":false}]}
{"op":"mcm","clk":"5346685496","pt":1646094152479,"mc":[{"id":"1.195395448","rc":[{"atl":[[9,2.5],[9.2,0]],"id":40014837},{"atb":[[3.45,42.79],[3.4,0]],"id":37535509}],"con":true,"img":false}]}
{"op":"mcm","clk":"5346685570","pt":1646094154076,"mc":[{"id":"1.195395448","rc":[{"atb":[[3.5,3.34]],"id":37535509}],"con":true,"img":false}]}
{"op":"mcm","clk":"5346685627","pt":1646094155207,"mc":[{"id":"1.195395448","rc":[{"atb":[[3.45,25.54]],"id":37535509}],"con":true,"img":false}]}
{"op":"mcm","clk":"5346685633","pt":1646094155262,"mc":[{"id":"1.195395448","rc":[{"atb":[[3.15,17.25]],"id":37535509}],"con":true,"img":false}]}
{"op":"mcm","clk":"5346685803","pt":1646094159894,"mc":[{"id":"1.195395448","rc":[{"atb":[[3.55,2.92]],"id":37535509}],"con":true,"img":false}]}
{"op":"mcm","clk":"5346686252","pt":1646094170832,"mc":[{"id":"1.195395448","rc":[{"atb":[[3.5,0]],"id":37535509}],"con":true,"img":false}]}
{"op":"mcm","clk":"5346686491","pt":1646094176645,"mc":[{"id":"1.195395448","rc":[{"atb":[[3.55,6.19]],"id":37535509}],"con":true,"img":false}]}
{"op":"mcm","clk":"5346690073","pt":1646094284029,"mc":[{"id":"1.195395448","rc":[{"atl":[[9,0],[9.4,2.38]],"id":40014837},{"atb":[[1.8,0],[1.81,24.69]],"id":38541023},{"atb":[[3.45,0],[3.25,34.24]],"id":37535509},{"atl":[[11.5,9.52],[6.8,3.45],[14,0],[7,0]],"id":37535509},{"atb":[[2.84,54.35]],"id":36899944},{"atl":[[5.8,2.5],[5.9,4.08]],"id":40041375}],"con":true,"img":false}]}
{"op":"mcm","clk":"5346690076","pt":1646094284081,"mc":[{"id":"1.195395448","rc":[{"atb":[[2.74,0]],"id":36899944}],"con":true,"img":false}]}
{"op":"mcm","clk":"5346690121","pt":1646094286077,"mc":[{"id":"1.195395448","rc":[{"atb":[[3.55,3.27]],"id":37535509}],"con":true,"img":false}]}
{"op":"mcm","clk":"5346690272","pt":1646094292022,"mc":[{"id":"1.195395448","rc":[{"atb":[[3.45,3.03]],"id":37535509}],"con":true,"img":false}]}
{"op":"mcm","clk":"5346690323","pt":1646094294025,"mc":[{"id":"1.195395448","rc":[{"atl":[[9.8,5.68]],"id":40014837},{"atl":[[6.2,9.62]],"id":40041375}],"con":true,"img":false}]}
{"op":"mcm","clk":"5346690375","pt":1646094295715,"mc":[{"id":"1.195395448","rc":[{"atl":[[10,0],[11,0],[9.6,0]],"id":40014837},{"atl":[[6.4,0],[6.8,0],[6,0]],"id":40041375}],"con":true,"img":false}]}
{"op":"mcm","clk":"5346690540","pt":1646094301051,"mc":[{"id":"1.195395448","rc":[{"atb":[[3.55,0]],"id":37535509}],"con":true,"img":false}]}
{"op":"mcm","clk":"5346690644","pt":1646094304031,"mc":[{"id":"1.195395448","rc":[{"atl":[[10.5,7.89]],"id":40014837},{"atl":[[6.6,19.18]],"id":40041375}],"con":true,"img":false}]}
{"op":"mcm","clk":"5346690681","pt":1646094305158,"mc":[{"id":"1.195395448","rc":[{"atl":[[6.6,13.39]],"id":40041375}],"con":true,"img":false}]}
{"op":"mcm","clk":"5346690683","pt":1646094305259,"mc":[{"id":"1.195395448","rc":[{"atl":[[8.4,5.79]],"id":40041375}],"con":true,"img":false}]}
{"op":"mcm","clk":"5346690742","pt":1646094306948,"mc":[{"id":"1.195395448","rc":[{"atb":[[3.45,6.44]],"id":37535509}],"con":true,"img":false}]}
{"op":"mcm","clk":"5346691039","pt":1646094314053,"mc":[{"id":"1.195395448","rc":[{"atl":[[11.5,11.9]],"id":40014837},{"atl":[[7,20.83]],"id":40041375}],"con":true,"img":false}]}
{"op":"mcm","clk":"5346691083","pt":1646094315228,"mc":[{"id":"1.195395448","rc":[{"atb":[[3.15,0]],"id":37535509},{"atb":[[2.8,0]],"id":36899944}],"con":true,"img":false}]}
{"op":"mcm","clk":"5346691087","pt":1646094315331,"mc":[{"id":"1.195395448","rc":[{"atb":[[3.3,25.95]],"id":37535509},{"atb":[[2.86,21.38]],"id":36899944}],"con":true,"img":false}]}
{"op":"mcm","clk":"5346691490","pt":1646094325285,"mc":[{"id":"1.195395448","rc":[{"atb":[[3.35,25.54]],"id":40014837}],"con":true,"img":false}]}
{"op":"mcm","clk":"5346691494","pt":1646094325387,"mc":[{"id":"1.195395448","rc":[{"atb":[[3.45,16.55]],"id":40014837}],"con":true,"img":false}]}
{"op":"mcm","clk":"5346692253","pt":1646094345208,"mc":[{"id":"1.195395448","rc":[{"atl":[[8.4,0]],"id":40041375}],"con":true,"img":false}]}
{"op":"mcm","clk":"5346692256","pt":1646094345310,"mc":[{"id":"1.195395448","rc":[{"atl":[[6.8,5.79]],"id":40041375}],"con":true,"img":false}]}
{"op":"mcm","clk":"5346692606","pt":1646094353939,"mc":[{"id":"1.195395448","rc":[{"atl":[[15,6.76],[9.4,0],[8.6,2.63],[19.5,0]],"id":40014837},{"atb":[[1.81,0],[1.85,23.53]],"id":38541023},{"atb":[[3.2,68.18],[3.25,0]],"id":37535509},{"atl":[[8,0],[7.8,33.09]],"id":36899944},{"atl":[[6.2,3.85],[5.9,0]],"id":40041375},{"atl":[[1.98,0],[2.04,19.23],[2.6,0],[2.78,56.18]],"id":43154430}],"con":true,"img":false}]}
{"op":"mcm","clk":"5346692638","pt":1646094354446,"mc":[{"id":"1.195395448","rc":[{"atb":[[1.85,0],[1.86,23.26]],"id":38541023},{"atl":[[2,0]],"id":43154430}],"con":true,"img":false}]}
{"op":"mcm","clk":"5346692667","pt":1646094355117,"mc":[{"id":"1.195395448","rc":[{"atb":[[3.3,8.7]],"id":37535509},{"atl":[[1.99,0],[2.58,0],[2.76,24.33]],"id":43154430}],"con":true,"img":false}]}
{"op":"mcm","clk":"5346692671","pt":1646094355219,"mc":[{"id":"1.195395448","rc":[{"atb":[[3.25,17.25]],"id":37535509},{"atl":[[2.06,34.97]],"id":43154430}],"con":true,"img":false}]}
{"op":"mcm","clk":"5346692770","pt":1646094357839,"mc":[{"id":"1.195395448","rc":[{"atb":[[1.85,23.53],[1.86,0]],"id":38541023}],"con":true,"img":false}]}
{"op":"mcm","clk":"5346693055","pt":1646094363947,"mc":[{"id":"1.195395448","rc":[{"atl":[[9,6.25]],"id":40014837},{"atl":[[6.6,8.93]],"id":40041375},{"atl":[[2.08,46.3]],"id":43154430}],"con":true,"img":false}]}
{"op":"mcm","clk":"5346693119","pt":1646094365642,"mc":[{"id":"1.195395448","rc":[{"atl":[[11.5,0],[7.8,2.94],[8.6,0]],"id":40014837},{"atb":[[1.26,117.48],[1.17,588.24]],"id":42315317},{"atl":[[1.98,0],[1.92,21.74]],"id":42315317},{"atb":[[1.18,0],[1.27,74.07],[1.17,250]],"id":40041375},{"atl":[[2.54,12.99],[2.04,0],[2.08,0]],"id":43154430},{"atb":[[1.38,380.52]],"id":37076580}],"con":true,"img":false}]}
{"op":"mcm","clk":"5346693122","pt":1646094365744,"mc":[{"id":"1.195395448","rc":[{"atb":[[1.08,0]],"id":40041375},{"atb":[[1.35,343.06]],"id":37076580}],"con":true,"img":false}]}
{"op":"mcm","clk":"5346693131","pt":1646094366052,"mc":[{"id":"1.195395448","rc":[{"atb":[[1.86,23.26]],"id":38541023}],"con":true,"img":false}]}
{"op":"mcm","clk":"5346693134","pt":1646094366154,"mc":[{"id":"1.195395448","rc":[{"atb":[[1.85,0]],"id":38541023}],"con":true,"img":false}]}
{"op":"mcm","clk":"5346693254","pt":1646094369546,"mc":[{"id":"1.195395448","rc":[{"atb":[[1.85,23.53],[1.86,0]],"id":38541023}],"con":true,"img":false}]}
{"op":"mcm","clk":"5346693417","pt":1646094375145,"mc":[{"id":"1.195395448","rc":[{"atb":[[3.4,20.83]],"id":40014837},{"atl":[[2.06,0]],"id":43154430}],"con":true,"img":false}]}
{"op":"mcm","clk":"5346693420","pt":1646094375248,"mc":[{"id":"1.195395448","rc":[{"atb":[[3.35,40.57]],"id":40014837},{"atl":[[2.32,34.97]],"id":43154430}],"con":true,"img":false}]}
{"op":"mcm","clk":"5346693430","pt":1646094375659,"mc":[{"id":"1.195395448","rc":[{"atl":[[8.2,6.94]],"id":40014837},{"atl":[[1.94,53.19]],"id":42315317},{"atb":[[1.25,200]],"id":40041375},{"atl":[[7,12.5]],"id":40041375},{"atl":[[2.58,31.65]],"id":43154430}],"con":true,"img":false}]}
{"op":"mcm","clk":"5346693512","pt":1646094378585,"mc":[{"id":"1.195395448","rc":[{"atl":[[10.5,0]],"id":40014837},{"atb":[[1.85,0],[1.86,23.26]],"id":38541023},{"atl":[[2.08,0]],"id":42315317},{"atb":[[1.12,0],[1.14,0],[1.16,0]],"id":40041375}],"con":true,"img":false}]}
{"op":"mcm","clk":"5346693713","pt":1646094385171,"mc":[{"id":"1.195395448","rc":[{"atl":[[12,1.09]],"id":37535509},{"atl":[[6.8,0]],"id":40041375}],"con":true,"img":false}]}
{"op":"mcm","clk":"5346693715","pt":1646094385274,"mc":[{"id":"1.195395448","rc":[{"atl":[[11.5,13.2]],"id":37535509},{"atl":[[8.4,5.79]],"id":40041375}],"con":true,"img":false}]}
{"op":"mcm","clk":"5346693734","pt":1646094385682,"mc":[{"id":"1.195395448","rc":[{"atl":[[8.6,9.87]],"id":40014837},{"atl":[[1.96,78.12]],"id":42315317},{"atb":[[1.23,250]],"id":40041375},{"atl":[[7.4,19.53]],"id":40041375},{"atl":[[2.62,61.12]],"id":43154430}],"con":true,"img":false}]}
{"op":"mcm","clk":"5346693794","pt":1646094387484,"mc":[{"id":"1.195395448","rc":[{"atb":[[1.85,23.53]],"id":38541023}],"con":true,"img":false}]}
{"op":"mcm","clk":"5346693800","pt":1646094387586,"mc":[{"id":"1.195395448","rc":[{"atl":[[9.8,0]],"id":40014837},{"atb":[[1.86,0]],"id":38541023},{"atl":[[2.04,0]],"id":42315317}],"con":true,"img":false}]}
{"op":"mcm","clk":"5346693876","pt":1646094389693,"mc":[{"id":"1.195395448","rc":[{"atb":[[1.85,0],[1.86,23.26]],"id":38541023}],"con":true,"img":false}]}
{"op":"mcm","clk":"5346693909","pt":1646094390673,"mc":[{"id":"1.195395448","rc":[{"atb":[[1.85,23.53],[1.86,0]],"id":38541023}],"con":true,"img":false}]}
{"op":"mcm","clk":"5346693927","pt":1646094391187,"mc":[{"id":"1.195395448","rc":[{"atb":[[3.5,18.97]],"id":40014837}],"con":true,"img":false}]}
{"op":"mcm","clk":"5346694111","pt":1646094395198,"mc":[{"id":"1.195395448","rc":[{"atb":[[3.35,25.54]],"id":40014837}],"con":true,"img":false}]}
{"op":"mcm","clk":"5346694118","pt":1646094395300,"mc":[{"id":"1.195395448","rc":[{"atb":[[3.25,15.02]],"id":40014837}],"con":true,"img":false}]}
{"op":"mcm","clk":"5346694130","pt":1646094395711,"mc":[{"id":"1.195395448","rc":[{"atl":[[9,15.62]],"id":40014837},{"atl":[[1.98,127.55]],"id":42315317},{"atb":[[1.21,250]],"id":40041375},{"atl":[[2.66,75.3]],"id":43154430}],"con":true,"img":false}]}
{"op":"mcm","clk":"5346694201","pt":1646094397608,"mc":[{"id":"1.195395448","rc":[{"atb":[[3.45,19.96]],"id":40014837}],"con":true,"img":false}]}
{"op":"mcm","clk":"5346694282","pt":1646094399411,"mc":[{"id":"1.195395448","rc":[{"atl":[[2,0]],"id":42315317}],"con":true,"img":false}]}
{"op":"mcm","clk":"5346694333","pt":1646094400697,"mc":[{"id":"1.195395448","rc":[{"atb":[[1.83,60.24]],"id":38541023}],"con":true,"img":false}]}
{"op":"mcm","clk":"5346694339","pt":1646094400903,"mc":[{"id":"1.195395448","rc":[{"atl":[[7.8,0]],"id":40014837},{"atb":[[1.86,23.26]],"id":38541023},{"atb":[[3.2,22.73],[3.15,46.51]],"id":37535509},{"atl":[[1.92,0]],"id":42315317}],"con":true,"img":false}]}
{"op":"mcm","clk":"5346694343","pt":1646094401006,"mc":[{"id":"1.195395448","rc":[{"atl":[[8,2.86]],"id":40014837},{"atb":[[1.85,0]],"id":38541023},{"atl":[[1.9,22.22]],"id":42315317}],"con":true,"img":false}]}
{"op":"mcm","clk":"5346694348","pt":1646094401209,"mc":[{"id":"1.195395448","rc":[{"atb":[[1.83,0]],"id":38541023}],"con":true,"img":false}]}
{"op":"mcm","clk":"5346694498","pt":1646094405212,"mc":[{"id":"1.195395448","rc":[{"atl":[[14.5,0]],"id":40014837},{"atb":[[3.25,0]],"id":37535509},{"atl":[[2.76,0]],"id":43154430},{"atl":[[3.6,16.22],[4.2,0]],"id":37076580}],"con":true,"img":false}]}
{"op":"mcm","clk":"5346694502","pt":1646094405315,"mc":[{"id":"1.195395448","rc":[{"atl":[[13.5,3.38]],"id":40014837},{"atb":[[3.2,39.98]],"id":37535509},{"atl":[[2.56,24.33]],"id":43154430}],"con":true,"img":false}]}
{"op":"mcm","clk":"5346694702","pt":1646094410901,"mc":[{"id":"1.195395448","rc":[{"atl":[[8.4,6.76]],"id":40014837},{"atb":[[1.84,59.52]],"id":38541023},{"atl":[[1.92,54.35]],"id":42315317}],"con":true,"img":false}]}
{"op":"mcm","clk":"5346694797","pt":1646094413717,"mc":[{"id":"1.195395448","rc":[{"atl":[[9,0],[8.2,0],[8.6,0]],"id":40014837},{"atb":[[1.74,0]],"id":38541023},{"atl":[[1.98,0]],"id":42315317}],"con":true,"img":false}]}
{"op":"mcm","clk":"5346694848","pt":1646094415204,"mc":[{"id":"1.195395448","rc":[{"atb":[[2.86,0]],"id":36899944}],"con":true,"img":false}]}
{"op":"mcm","clk":"5346694851","pt":1646094415306,"mc":[{"id":"1.195395448","rc":[{"atb":[[2.9,21.38]],"id":36899944}],"con":true,"img":false}]}
{"op":"mcm","clk":"5346694954","pt":1646094417719,"mc":[{"id":"1.195395448","rc":[{"atl":[[8.4,0]],"id":40041375}],"con":true,"img":false}]}
{"op":"mcm","clk":"5346694960","pt":1646094417821,"mc":[{"id":"1.195395448","rc":[{"atl":[[7.2,5.79]],"id":40041375}],"con":true,"img":false}]}
{"op":"mcm","clk":"5346695090","pt":1646094420953,"mc":[{"id":"1.195395448","rc":[{"atl":[[8.8,11.16]],"id":40014837},{"atb":[[1.82,91.46]],"id":38541023},{"atl":[[1.94,79.79]],"id":42315317}],"con":true,"img":false}]}
{"op":"mcm","clk":"5346695358","pt":1646094426917,"mc":[{"id":"1.195395448","rc":[{"atb":[[1.76,0]],"id":38541023}],"con":true,"img":false}]}
{"op":"mcm","clk":"5346695534","pt":1646094430971,"mc":[{"id":"1.195395448","rc":[{"atl":[[9.2,15.24]],"id":40014837},{"atb":[[1.8,156.25]],"id":38541023},{"atl":[[1.96,130.21]],"id":42315317}],"con":true,"img":false}]}
{"op":"mcm","clk":"5346695737","pt":1646094435131,"mc":[{"id":"1.195395448","rc":[{"atl":[[3.6,0],[4.2,12.98]],"id":37076580}],"con":true,"img":false}]}
{"op":"mcm","clk":"5346695930","pt":1646094439747,"mc":[{"id":"1.195395448","rc":[{"atb":[[1.78,0]],"id":38541023}],"con":true,"img":false}]}
{"op":"mcm","clk":"5346696151","pt":1646094445149,"mc":[{"id":"1.195395448","rc":[{"atb":[[2.9,0]],"id":36899944}],"con":true,"img":false}]}
{"op":"mcm","clk":"5346696155","pt":1646094445250,"mc":[{"id":"1.195395448","rc":[{"atb":[[2.86,21.38]],"id":36899944}],"con":true,"img":false}]}
{"op":"mcm","clk":"5346696539","pt":1646094455216,"mc":[{"id":"1.195395448","rc":[{"atb":[[1.79,0]],"id":38541023}],"con":true,"img":false}]}
{"op":"mcm","clk":"5346696542","pt":1646094455267,"mc":[{"id":"1.195395448","rc":[{"atb":[[1.85,45.41]],"id":38541023}],"con":true,"img":false}]}
{"op":"mcm","clk":"5346696890","pt":1646094465126,"mc":[{"id":"1.195395448","rc":[{"atb":[[2.22,0]],"id":40041375}],"con":true,"img":false}]}
{"op":"mcm","clk":"5346696892","pt":1646094465227,"mc":[{"id":"1.195395448","rc":[{"atb":[[2.32,32.06]],"id":40041375}],"con":true,"img":false}]}
{"op":"mcm","clk":"5346697263","pt":1646094476113,"mc":[{"id":"1.195395448","rc":[{"atl":[[2.4,27.04]],"id":38541023}],"con":true,"img":false}]}
{"op":"mcm","clk":"5346697268","pt":1646094476215,"mc":[{"id":"1.195395448","rc":[{"atl":[[3.6,38.46],[3.95,25.42]],"id":38541023}],"con":true,"img":false}]}
{"op":"mcm","clk":"5346697271","pt":1646094476317,"mc":[{"id":"1.195395448","rc":[{"atb":[[1.46,0],[1.52,109.55]],"id":38541023},{"atb":[[3.3,48.69]],"id":37535509},{"atb":[[1.4,342.39],[1.38,117.36]],"id":37076580}],"con":true,"img":false}]}
{"op":"mcm","clk":"5346697272","pt":1646094476421,"mc":[{"id":"1.195395448","rc":[{"atb":[[3.15,0]],"id":37535509}],"con":true,"img":false}]}
{"op":"mcm","clk":"5346697990","pt":1646094495189,"mc":[{"id":"1.195395448","rc":[{"atb":[[1.85,0],[1.53,67.69]],"id":38541023},{"atl":[[2.32,0]],"id":43154430}],"con":true,"img":false}]}
{"op":"mcm","clk":"5346697994","pt":1646094495292,"mc":[{"id":"1.195395448","rc":[{"atl":[[2.46,34.97]],"id":43154430}],"con":true,"img":false}]}
{"op":"mcm","clk":"5346698421","pt":1646094506779,"mc":[{"id":"1.195395448","rc":[{"atb":[[1.27,82.23]],"id":42315317},{"atb":[[1.18,125.6]],"id":43154430},{"atb":[[1.45,25.14]],"id":37076580}],"con":true,"img":false}]}
{"op":"mcm","clk":"5346698425","pt":1646094506880,"mc":[{"id":"1.195395448","rc":[{"atb":[[1.19,125.61]],"id":43154430}],"con":true,"img":false}]}
{"op":"mcm","clk":"5346698427","pt":1646094506985,"mc":[{"id":"1.195395448","rc":[{"atb":[[1.17,117.65]],"id":43154430}],"con":true,"img":false}]}
{"op":"mcm","clk":"5346698566","pt":1646094511499,"mc":[{"id":"1.195395448","rc":[{"atb":[[1.18,0]],"id":43154430}],"con":true,"img":false}]}
{"op":"mcm","clk":"5346698572","pt":1646094511704,"mc":[{"id":"1.195395448","rc":[{"atl":[[9.2,12.2],[11.5,3.68]],"id":37535509},{"atl":[[7.8,18.38]],"id":36899944},{"atl":[[2.28,78.13]],"id":42315317},{"atl":[[2.54,37.33],[2.78,0]],"id":43154430}],"con":true,"img":false}]}
{"op":"mcm","clk":"5346698576","pt":1646094511807,"mc":[{"id":"1.195395448","rc":[{"atl":[[7.4,23.62]],"id":36899944},{"atl":[[2.54,0]],"id":42315317},{"atl":[[2.52,65.79],[2.78,0]],"id":37076580}],"con":true,"img":false}]}
{"op":"mcm","clk":"5346698581","pt":1646094512010,"mc":[{"id":"1.195395448","rc":[{"atb":[[1.19,0],[1.17,368.87]],"id":43154430}],"con":true,"img":false}]}
{"op":"mcm","clk":"5346698680","pt":1646094515197,"mc":[{"id":"1.195395448","rc":[{"atb":[[2.12,0]],"id":38541023},{"atl":[[4,13.52],[6,0]],"id":38541023},{"atb":[[3.2,22.73]],"id":37535509},{"atl":[[3.05,17.28],[2.52,0]],"id":42315317},{"atl":[[2.76,0]],"id":37076580}],"con":true,"img":false}]}
{"op":"mcm","clk":"5346698684","pt":1646094515299,"mc":[{"id":"1.195395448","rc":[{"atb":[[2.02,36.21]],"id":38541023},{"atb":[[3.35,42.8]],"id":37535509},{"atl":[[3.05,22.28]],"id":37076580}],"con":true,"img":false}]}
{"op":"mcm","clk":"5346698708","pt":1646094516324,"mc":[{"id":"1.195395448","rc":[{"atb":[[1.18,125.6]],"id":43154430}],"con":true,"img":false}]}
{"op":"mcm","clk":"5346698728","pt":1646094516789,"mc":[{"id":"1.195395448","rc":[{"atl":[[9.2,0],[11,10]],"id":37535509},{"atl":[[2.5,66.67],[2.28,0]],"id":42315317},{"atl":[[2.54,12.99],[2.76,56.82]],"id":43154430}],"con":true,"img":false}]}
{"op":"mcm","clk":"5346698731","pt":1646094516889,"mc":[{"id":"1.195395448","rc":[{"atl":[[8,14.29]],"id":36899944},{"atl":[[2.8,55.56],[2.52,0]],"id":37076580}],"con":true,"img":false}]}
{"op":"mcm","clk":"5346698733","pt":1646094516991,"mc":[{"id":"1.195395448","rc":[{"atl":[[7.4,11.72]],"id":36899944}],"con":true,"img":false}]}
{"op":"mcm","clk":"5346698739","pt":1646094517300,"mc":[{"id":"1.195395448","rc":[{"atb":[[2.26,5.91]],"id":38541023}],"con":true,"img":false}]}
{"op":"mcm","clk":"5346698751","pt":1646094517711,"mc":[{"id":"1.195395448","rc":[{"atb":[[2.26,0]],"id":38541023}],"con":true,"img":false}]}
{"op":"mcm","clk":"5346698796","pt":1646094519094,"mc":[{"id":"1.195395448","rc":[{"atb":[[1.19,125.61],[1.17,117.65]],"id":43154430}],"con":true,"img":false}]}
{"op":"mcm","clk":"5346699005","pt":1646094523434,"mc":[{"id":"1.195395448","rc":[{"atb":[[1.18,0]],"id":43154430}],"con":true,"img":false}]}
{"op":"mcm","clk":"5346699028","pt":1646094524206,"mc":[{"id":"1.195395448","rc":[{"atb":[[1.19,0],[1.17,368.87]],"id":43154430}],"con":true,"img":false}]}
{"op":"mcm","clk":"5346699055","pt":1646094525128,"mc":[{"id":"1.195395448","rc":[{"atb":[[1.38,0]],"id":37076580},{"atl":[[3.6,16.22],[4.2,0]],"id":37076580}],"con":true,"img":false}]}
{"op":"mcm","clk":"5346699058","pt":1646094525231,"mc":[{"id":"1.195395448","rc":[{"atb":[[1.41,279.88]],"id":37076580}],"con":true,"img":false}]}
{"op":"mcm","clk":"5346699106","pt":1646094526614,"mc":[{"id":"1.195395448","rc":[{"atb":[[1.2,87.93]],"id":43154430}],"con":true,"img":false}]}
{"op":"mcm","clk":"5346699281","pt":1646094531241,"mc":[{"id":"1.195395448","rc":[{"atb":[[1.21,87.93],[1.17,117.65]],"id":43154430}],"con":true,"img":false}]}
{"op":"mcm","clk":"5346699416","pt":1646094535138,"mc":[{"id":"1.195395448","rc":[{"atb":[[3.25,0]],"id":40014837},{"atl":[[9.4,0],[4,0],[7,7.98]],"id":38541023},{"atb":[[2.96,0]],"id":37535509},{"atl":[[9.2,12.2],[11,0]],"id":37535509},{"atb":[[2.86,0]],"id":36899944},{"atl":[[8,0],[7.4,26.01]],"id":36899944},{"atl":[[2.5,0],[2.28,78.13]],"id":42315317},{"atl":[[2.54,37.33],[2.76,0]],"id":43154430},{"atl":[[2.8,0],[2.52,65.79]],"id":37076580}],"con":true,"img":false}]}
{"op":"mcm","clk":"5346699418","pt":1646094535239,"mc":[{"id":"1.195395448","rc":[{"atb":[[3.4,35.85]],"id":40014837},{"atl":[[3.9,13.52]],"id":38541023},{"atb":[[3.15,17.18]],"id":37535509},{"atb":[[3,21.38]],"id":36899944}],"con":true,"img":false}]}
{"op":"mcm","clk":"5346699446","pt":1646094535961,"mc":[{"id":"1.195395448","rc":[{"atb":[[1.2,0]],"id":43154430}],"con":true,"img":false}]}
{"op":"mcm","clk":"5346699467","pt":1646094536321,"mc":[{"id":"1.195395448","rc":[{"atb":[[1.21,0],[1.17,293.51]],"id":43154430}],"con":true,"img":false}]}
{"op":"mcm","clk":"5346699617","pt":1646094540352,"mc":[{"id":"1.195395448","rc":[{"atl":[[9.2,0],[11,10]],"id":37535509},{"atl":[[8,14.29],[7.4,11.72]],"id":36899944},{"atl":[[2.5,66.67],[2.28,0]],"id":42315317},{"atl":[[2.54,12.99],[2.76,56.82]],"id":43154430},{"atl":[[2.8,55.56],[2.52,0]],"id":37076580}],"con":true,"img":false}]}
{"op":"mcm","clk":"5346699644","pt":1646094541131,"mc":[{"id":"1.195395448","rc":[{"atb":[[1.18,125.6]],"id":43154430}],"con":true,"img":false}]}
{"op":"mcm","clk":"5346699722","pt":1646094543242,"mc":[{"id":"1.195395448","rc":[{"atb":[[1.19,125.61],[1.17,117.65]],"id":43154430}],"con":true,"img":false}]}
{"op":"mcm","clk":"5346699773","pt":1646094545243,"mc":[{"id":"1.195395448","rc":[{"atl":[[3.05,0]],"id":37076580}],"con":true,"img":false}]}
{"op":"mcm","clk":"5346699775","pt":1646094545345,"mc":[{"id":"1.195395448","rc":[{"atl":[[2.78,22.28]],"id":37076580}],"con":true,"img":false}]}
{"op":"mcm","clk":"5346699795","pt":1646094546167,"mc":[{"id":"1.195395448","rc":[{"atb":[[1.18,0]],"id":43154430}],"con":true,"img":false}]}
{"op":"mcm","clk":"5346699802","pt":1646094546372,"mc":[{"id":"1.195395448","rc":[{"atb":[[1.19,0],[1.17,368.87]],"id":43154430}],"con":true,"img":false}]}
{"op":"mcm","clk":"5346699996","pt":1646094551361,"mc":[{"id":"1.195395448","rc":[{"atb":[[1.18,125.6]],"id":43154430}],"con":true,"img":false}]}
{"op":"mcm","clk":"5346700071","pt":1646094553692,"mc":[{"id":"1.195395448","rc":[{"atb":[[3.45,16.55]],"id":40014837}],"con":true,"img":false}]}
{"op":"mcm","clk":"5346700243","pt":1646094558167,"mc":[{"id":"1.195395448","rc":[{"atb":[[1.19,125.61]],"id":43154430}],"con":true,"img":false}]}
{"op":"mcm","clk":"5346700247","pt":1646094558268,"mc":[{"id":"1.195395448","rc":[{"atb":[[1.17,117.65]],"id":43154430}],"con":true,"img":false}]}
{"op":"mcm","clk":"5346700304","pt":1646094560270,"mc":[{"id":"1.195395448","rc":[{"atb":[[3.5,22.32]],"id":40014837}],"con":true,"img":false}]}
{"op":"mcm","clk":"5346700334","pt":1646094561094,"mc":[{"id":"1.195395448","rc":[{"atb":[[1.18,0]],"id":43154430}],"con":true,"img":false}]}
{"op":"mcm","clk":"5346700409","pt":1646094563406,"mc":[{"id":"1.195395448","rc":[{"atb":[[1.19,0],[1.17,368.87]],"id":43154430}],"con":true,"img":false}]}
{"op":"mcm","clk":"5346700498","pt":1646094566178,"mc":[{"id":"1.195395448","rc":[{"atb":[[1.2,87.93]],"id":43154430}],"con":true,"img":false}]}
{"op":"mcm","clk":"5346700616","pt":1646094569984,"mc":[{"id":"1.195395448","rc":[{"atb":[[1.21,87.93],[1.17,117.65]],"id":43154430}],"con":true,"img":false}]}
{"op":"mcm","clk":"5346700743","pt":1646094573802,"mc":[{"id":"1.195395448","rc":[{"atl":[[9.2,12.2],[11,0]],"id":37535509},{"atl":[[8,0],[7.4,26.01]],"id":36899944},{"atl":[[2.5,0],[2.28,78.13]],"id":42315317},{"atb":[[1.2,0]],"id":43154430},{"atl":[[2.54,37.33],[2.76,0]],"id":43154430},{"atl":[[2.8,0],[2.52,65.79]],"id":37076580}],"con":true,"img":false}]}
{"op":"mcm","clk":"5346700746","pt":1646094573901,"mc":[{"id":"1.195395448","rc":[{"atb":[[1.21,0],[1.17,293.51]],"id":43154430}],"con":true,"img":false}]}
{"op":"mcm","clk":"5346700801","pt":1646094575242,"mc":[{"id":"1.195395448","rc":[{"atl":[[2.78,0]],"id":37076580}],"con":true,"img":false}]}
{"op":"mcm","clk":"5346700808","pt":1646094575396,"mc":[{"id":"1.195395448","rc":[{"atl":[[3.05,22.28]],"id":37076580}],"con":true,"img":false}]}
{"op":"mcm","clk":"5346700890","pt":1646094578625,"mc":[{"id":"1.195395448","rc":[{"atb":[[1.18,125.6]],"id":43154430}],"con":true,"img":false}]}
{"op":"mcm","clk":"5346700919","pt":1646094579530,"mc":[{"id":"1.195395448","rc":[{"atl":[[9.2,0],[11,10]],"id":37535509},{"atl":[[8,14.29],[7.4,11.72]],"id":36899944},{"atl":[[2.5,66.67],[2.28,0]],"id":42315317},{"atl":[[2.54,12.99],[2.76,56.82]],"id":43154430},{"atl":[[2.8,55.56],[2.52,0]],"id":37076580}],"con":true,"img":false}]}
{"op":"mcm","clk":"5346701084","pt":1646094585112,"mc":[{"id":"1.195395448","rc":[{"atb":[[3,0]],"id":36899944}],"con":true,"img":false}]}
{"op":"mcm","clk":"5346701089","pt":1646094585216,"mc":[{"id":"1.195395448","rc":[{"atb":[[2.9,21.38]],"id":36899944}],"con":true,"img":false}]}
{"op":"mcm","clk":"5346701100","pt":1646094585525,"mc":[{"id":"1.195395448","rc":[{"atb":[[1.19,125.61],[1.17,117.65]],"id":43154430}],"con":true,"img":false}]}
{"op":"mcm","clk":"5346701213","pt":1646094588404,"mc":[{"id":"1.195395448","rc":[{"atb":[[1.18,0]],"id":43154430}],"con":true,"img":false}]}
{"op":"mcm","clk":"5346701293","pt":1646094590621,"mc":[{"id":"1.195395448","rc":[{"atb":[[1.19,0],[1.17,368.87]],"id":43154430}],"con":true,"img":false}]}
{"op":"mcm","clk":"5346701410","pt":1646094593650,"mc":[{"id":"1.195395448","rc":[{"atb":[[1.18,125.6]],"id":43154430}],"con":true,"img":false}]}
{"op":"mcm","clk":"5346701726","pt":1646094602045,"mc":[{"id":"1.195395448","rc":[{"atb":[[1.19,125.61],[1.17,117.65]],"id":43154430}],"con":true,"img":false}]}
{"op":"mcm","clk":"5346701841","pt":1646094605144,"mc":[{"id":"1.195395448","rc":[{"atl":[[3.05,0]],"id":37076580}],"con":true,"img":false}]}
{"op":"mcm","clk":"5346701845","pt":1646094605245,"mc":[{"id":"1.195395448","rc":[{"atl":[[2.78,22.28]],"id":37076580}],"con":true,"img":false}]}
{"op":"mcm","clk":"5346701897","pt":1646094606327,"mc":[{"id":"1.195395448","rc":[{"atb":[[1.18,0]],"id":43154430}],"con":true,"img":false}]}
{"op":"mcm","clk":"5346701928","pt":1646094607146,"mc":[{"id":"1.195395448","rc":[{"atb":[[1.19,0],[1.17,368.87]],"id":43154430}],"con":true,"img":false}]}
{"op":"mcm","clk":"5346702120","pt":1646094611478,"mc":[{"id":"1.195395448","rc":[{"atb":[[1.18,125.6]],"id":43154430}],"con":true,"img":false}]}
{"op":"mcm","clk":"5346702386","pt":1646094618369,"mc":[{"id":"1.195395448","rc":[{"atb":[[1.19,125.61],[1.17,117.65]],"id":43154430}],"con":true,"img":false}]}
{"op":"mcm","clk":"5346702503","pt":1646094621577,"mc":[{"id":"1.195395448","rc":[{"atb":[[1.18,0]],"id":43154430}],"con":true,"img":false}]}
{"op":"mcm","clk":"5346702596","pt":1646094623487,"mc":[{"id":"1.195395448","rc":[{"atb":[[1.19,0],[1.17,368.87]],"id":43154430}],"con":true,"img":false}]}
{"op":"mcm","clk":"5346702727","pt":1646094626674,"mc":[{"id":"1.195395448","rc":[{"atb":[[1.18,125.6]],"id":43154430}],"con":true,"img":false}]}
{"op":"mcm","clk":"5346703052","pt":1646094634603,"mc":[{"id":"1.195395448","rc":[{"atb":[[1.19,125.61],[1.17,117.65]],"id":43154430}],"con":true,"img":false}]}
{"op":"mcm","clk":"5346703172","pt":1646094638298,"mc":[{"id":"1.195395448","rc":[{"atb":[[1.18,0]],"id":43154430}],"con":true,"img":false}]}
{"op":"mcm","clk":"5346703176","pt":1646094638402,"mc":[{"id":"1.195395448","rc":[{"atb":[[1.19,0],[1.17,368.87]],"id":43154430}],"con":true,"img":false}]}
{"op":"mcm","clk":"5346703371","pt":1646094643479,"mc":[{"id":"1.195395448","rc":[{"atb":[[1.18,125.6]],"id":43154430}],"con":true,"img":false}]}
{"op":"mcm","clk":"5346703429","pt":1646094645222,"mc":[{"id":"1.195395448","rc":[{"atb":[[3.15,0]],"id":37535509}],"con":true,"img":false}]}
{"op":"mcm","clk":"5346703436","pt":1646094645325,"mc":[{"id":"1.195395448","rc":[{"atb":[[3.05,17.18]],"id":37535509}],"con":true,"img":false}]}
{"op":"mcm","clk":"5346703600","pt":1646094649337,"mc":[{"id":"1.195395448","rc":[{"atb":[[1.19,125.61]],"id":43154430}],"con":true,"img":false}]}
{"op":"mcm","clk":"5346703606","pt":1646094649439,"mc":[{"id":"1.195395448","rc":[{"atb":[[1.17,117.65]],"id":43154430}],"con":true,"img":false}]}
{"op":"mcm","clk":"5346703732","pt":1646094653232,"mc":[{"id":"1.195395448","rc":[{"atb":[[1.18,0]],"id":43154430}],"con":true,"img":false}]}
{"op":"mcm","clk":"5346703739","pt":1646094653334,"mc":[{"id":"1.195395448","rc":[{"atb":[[1.17,368.87]],"id":43154430}],"con":true,"img":false}]}
{"op":"mcm","clk":"5346703744","pt":1646094653437,"mc":[{"id":"1.195395448","rc":[{"atb":[[1.19,0]],"id":43154430}],"con":true,"img":false}]}
{"op":"mcm","clk":"5346703925","pt":1646094658254,"mc":[{"id":"1.195395448","rc":[{"atb":[[1.18,125.6]],"id":43154430}],"con":true,"img":false}]}
{"op":"mcm","clk":"5346704005","pt":1646094660152,"mc":[{"id":"1.195395448","rc":[{"atb":[[1.26,40.56],[1.24,83.33]],"id":42315317},{"atb":[[1.27,0],[1.25,0],[1.24,83.33]],"id":40041375},{"atb":[[1.16,165.56],[1.17,251.22]],"id":43154430},{"atl":[[2.22,0],[2.14,0],[2.24,16.13],[2.18,0]],"id":37076580}],"con":true,"img":false}]}
{"op":"mcm","clk":"5346704161","pt":1646094664156,"mc":[{"id":"1.195395448","rc":[{"atb":[[1.19,165.56]],"id":43154430}],"con":true,"img":false}]}
{"op":"mcm","clk":"5346704168","pt":1646094664257,"mc":[{"id":"1.195395448","rc":[{"atb":[[1.17,0]],"id":43154430}],"con":true,"img":false}]}
{"op":"mcm","clk":"5346704303","pt":1646094668051,"mc":[{"id":"1.195395448","rc":[{"atb":[[1.18,0]],"id":43154430}],"con":true,"img":false}]}
{"op":"mcm","clk":"5346704348","pt":1646094669285,"mc":[{"id":"1.195395448","rc":[{"atb":[[1.19,0],[1.17,331.12]],"id":43154430}],"con":true,"img":false}]}
{"op":"mcm","clk":"5346704383","pt":1646094670158,"mc":[{"id":"1.195395448","rc":[{"atb":[[1.22,227.27]],"id":42315317},{"atb":[[1.22,227.27]],"id":40041375},{"atb":[[1.14,556.66]],"id":43154430},{"atl":[[2.28,39.06]],"id":37076580}],"con":true,"img":false}]}
{"op":"mcm","clk":"5346704408","pt":1646094670875,"mc":[{"id":"1.195395448","rc":[{"atb":[[1.15,400.23],[1.11,0],[1.13,0]],"id":43154430}],"con":true,"img":false}]}
{"op":"mcm","clk":"5346704494","pt":1646094672940,"mc":[{"id":"1.195395448","rc":[{"atb":[[1.18,125.6]],"id":43154430}],"con":true,"img":false}]}
{"op":"mcm","clk":"5346704684","pt":1646094678181,"mc":[{"id":"1.195395448","rc":[{"atb":[[3.25,44.44]],"id":37535509}],"con":true,"img":false}]}
{"op":"mcm","clk":"5346704689","pt":1646094678282,"mc":[{"id":"1.195395448","rc":[{"atb":[[3.3,8.7]],"id":37535509}],"con":true,"img":false}]}
{"op":"mcm","clk":"5346704756","pt":1646094679875,"mc":[{"id":"1.195395448","rc":[{"atb":[[1.19,165.56],[1.17,0]],"id":43154430}],"con":true,"img":false}]}
{"op":"mcm","clk":"5346704769","pt":1646094680185,"mc":[{"id":"1.195395448","rc":[{"atb":[[1.18,250]],"id":42315317},{"atb":[[1.2,250]],"id":40041375},{"atb":[[1.12,250]],"id":43154430},{"atl":[[2.32,56.82]],"id":37076580}],"con":true,"img":false}]}
{"op":"mcm","clk":"5346704825","pt":1646094681883,"mc":[{"id":"1.195395448","rc":[{"atb":[[1.21,0],[1.23,0]],"id":40041375}],"con":true,"img":false}]}
{"op":"mcm","clk":"5346704847","pt":1646094682394,"mc":[{"id":"1.195395448","rc":[{"atb":[[1.18,0]],"id":43154430}],"con":true,"img":false}]}
{"op":"mcm","clk":"5346704936","pt":1646094685105,"mc":[{"id":"1.195395448","rc":[{"atb":[[1.19,0],[1.17,400.24]],"id":43154430}],"con":true,"img":false}]}
{"op":"mcm","clk":"5346705035","pt":1646094687678,"mc":[{"id":"1.195395448","rc":[{"atb":[[1.2,113.04]],"id":43154430}],"con":true,"img":false}]}
{"op":"mcm","clk":"5346705131","pt":1646094690186,"mc":[{"id":"1.195395448","rc":[{"atb":[[1.18,250]],"id":40041375},{"atb":[[1.1,1450.71]],"id":43154430},{"atl":[[2.36,91.91]],"id":37076580}],"con":true,"img":false}]}
{"op":"mcm","clk":"5346705273","pt":1646094694287,"mc":[{"id":"1.195395448","rc":[{"atl":[[2.26,0]],"id":37076580}],"con":true,"img":false}]}
{"op":"mcm","clk":"5346705320","pt":1646094695625,"mc":[{"id":"1.195395448","rc":[{"atb":[[1.21,165.56]],"id":43154430}],"con":true,"img":false}]}
{"op":"mcm","clk":"5346705324","pt":1646094695674,"mc":[{"id":"1.195395448","rc":[{"atb":[[1.17,0]],"id":43154430}],"con":true,"img":false}]}
{"op":"mcm","clk":"5346705409","pt":1646094697475,"mc":[{"id":"1.195395448","rc":[{"atl":[[9.2,12.2],[11,0]],"id":37535509},{"atl":[[8,0],[7.4,26.01]],"id":36899944},{"atl":[[2.5,0],[2.28,78.13]],"id":42315317},{"atl":[[2.54,37.33],[2.76,0]],"id":43154430},{"atl":[[2.8,0],[2.52,65.79]],"id":37076580}],"con":true,"img":false}]}
{"op":"mcm","clk":"5346705492","pt":1646094699384,"mc":[{"id":"1.195395448","rc":[{"atb":[[3.35,85.35],[3.25,0]],"id":37535509},{"atl":[[1.9,0],[1.86,23.26]],"id":42315317},{"atl":[[6.4,3.7],[6.2,0]],"id":40041375}],"con":true,"img":false}]}
{"op":"mcm","clk":"5346705516","pt":1646094700200,"mc":[{"id":"1.195395448","rc":[{"atb":[[1.2,0]],"id":43154430}],"con":true,"img":false}]}
{"op":"mcm","clk":"5346705540","pt":1646094700814,"mc":[{"id":"1.195395448","rc":[{"atb":[[1.17,400.24]],"id":43154430}],"con":true,"img":false}]}
{"op":"mcm","clk":"5346705543","pt":1646094700915,"mc":[{"id":"1.195395448","rc":[{"atb":[[1.21,0]],"id":43154430}],"con":true,"img":false}]}
{"op":"mcm","clk":"5346705693","pt":1646094704307,"mc":[{"id":"1.195395448","rc":[{"atl":[[9.2,0],[11.5,13.2]],"id":37535509},{"atl":[[7.4,11.72],[7.8,33.09]],"id":36899944},{"atl":[[2.42,95.46],[2.28,0]],"id":42315317},{"atl":[[2.54,12.99],[2.78,56.18]],"id":43154430},{"atl":[[2.8,55.56],[2.52,0]],"id":37076580}],"con":true,"img":false}]}
{"op":"mcm","clk":"5346705738","pt":1646094705433,"mc":[{"id":"1.195395448","rc":[{"atb":[[1.18,125.62]],"id":43154430}],"con":true,"img":false}]}
{"op":"mcm","clk":"5346705812","pt":1646094707331,"mc":[{"id":"1.195395448","rc":[{"atb":[[1.27,74.07]],"id":40041375}],"con":true,"img":false}]}
{"op":"mcm","clk":"5346705818","pt":1646094707432,"mc":[{"id":"1.195395448","rc":[{"atl":[[1.86,0],[1.87,22.99]],"id":42315317},{"atb":[[1.24,0]],"id":40041375}],"con":true,"img":false}]}
{"op":"mcm","clk":"5346705945","pt":1646094711123,"mc":[{"id":"1.195395448","rc":[{"atb":[[1.19,165.56],[1.17,0]],"id":43154430}],"con":true,"img":false}]}
{"op":"mcm","clk":"5346706073","pt":1646094714917,"mc":[{"id":"1.195395448","rc":[{"atb":[[1.18,0]],"id":43154430}],"con":true,"img":false}]}
{"op":"mcm","clk":"5346706080","pt":1646094715020,"mc":[{"id":"1.195395448","rc":[{"atb":[[1.17,400.24]],"id":43154430}],"con":true,"img":false}]}
{"op":"mcm","clk":"5346706084","pt":1646094715120,"mc":[{"id":"1.195395448","rc":[{"atb":[[1.19,0]],"id":43154430}],"con":true,"img":false}]}
{"op":"mcm","clk":"5346706143","pt":1646094717317,"mc":[{"id":"1.195395448","rc":[{"atl":[[1.86,23.26],[1.87,0]],"id":42315317}],"con":true,"img":false}]}
{"op":"mcm","clk":"5346706146","pt":1646094717419,"mc":[{"id":"1.195395448","rc":[{"atb":[[1.27,0],[1.24,83.33]],"id":40041375},{"atl":[[6.8,8.62]],"id":40041375}],"con":true,"img":false}]}
{"op":"mcm","clk":"5346706174","pt":1646094718444,"mc":[{"id":"1.195395448","rc":[{"atl":[[1.86,0],[1.87,22.99]],"id":42315317},{"atb":[[1.27,74.07],[1.24,0]],"id":40041375},{"atl":[[7.4,0],[6.6,0],[7,0]],"id":40041375}],"con":true,"img":false}]}
{"op":"mcm","clk":"5346706205","pt":1646094719424,"mc":[{"id":"1.195395448","rc":[{"atb":[[1.26,205.04],[1.17,0]],"id":42315317},{"atl":[[1.86,23.26],[1.87,0]],"id":42315317},{"atb":[[1.26,250],[1.33,60.61],[1.27,0]],"id":40041375},{"atb":[[1.16,40.56],[1.17,517.89]],"id":43154430},{"atl":[[2.54,0],[2.2,16.67]],"id":43154430}],"con":true,"img":false}]}
{"op":"mcm","clk":"5346706210","pt":1646094719525,"mc":[{"id":"1.195395448","rc":[{"atb":[[1.17,0]],"id":40041375}],"con":true,"img":false}]}
{"op":"mcm","clk":"5346706227","pt":1646094720245,"mc":[{"id":"1.195395448","rc":[{"atb":[[1.16,665.56],[1.17,117.65]],"id":43154430}],"con":true,"img":false}]}
{"op":"mcm","clk":"5346706231","pt":1646094720347,"mc":[{"id":"1.195395448","rc":[{"atb":[[1.18,125.62]],"id":43154430}],"con":true,"img":false}]}
{"op":"mcm","clk":"5346706380","pt":1646094725222,"mc":[{"id":"1.195395448","rc":[{"atl":[[7.2,0]],"id":40041375}],"con":true,"img":false}]}
{"op":"mcm","clk":"5346706384","pt":1646094725327,"mc":[{"id":"1.195395448","rc":[{"atl":[[8.8,5.79]],"id":40041375}],"con":true,"img":false}]}
{"op":"mcm","clk":"5346706432","pt":1646094726868,"mc":[{"id":"1.195395448","rc":[{"atl":[[1.86,0],[1.87,22.99]],"id":42315317},{"atb":[[1.36,55.56]],"id":40041375}],"con":true,"img":false}]}
{"op":"mcm","clk":"5346706436","pt":1646094726971,"mc":[{"id":"1.195395448","rc":[{"atb":[[1.33,0]],"id":40041375}],"con":true,"img":false}]}
{"op":"mcm","clk":"5346706457","pt":1646094727638,"mc":[{"id":"1.195395448","rc":[{"atl":[[1.86,23.26]],"id":42315317},{"atb":[[1.33,60.61],[1.36,0]],"id":40041375}],"con":true,"img":false}]}
{"op":"mcm","clk":"5346706462","pt":1646094727741,"mc":[{"id":"1.195395448","rc":[{"atl":[[1.87,0]],"id":42315317}],"con":true,"img":false}]}
{"op":"mcm","clk":"5346706499","pt":1646094729433,"mc":[{"id":"1.195395448","rc":[{"atl":[[2.24,40.32]],"id":43154430}],"con":true,"img":false}]}
{"op":"mcm","clk":"5346706529","pt":1646094730355,"mc":[{"id":"1.195395448","rc":[{"atb":[[1.19,125.62]],"id":43154430}],"con":true,"img":false}]}
{"op":"mcm","clk":"5346706533","pt":1646094730457,"mc":[{"id":"1.195395448","rc":[{"atb":[[1.16,40.56]],"id":43154430}],"con":true,"img":false}]}
{"op":"mcm","clk":"5346706676","pt":1646094734768,"mc":[{"id":"1.195395448","rc":[{"atb":[[1.18,0]],"id":43154430}],"con":true,"img":false}]}
{"op":"mcm","clk":"5346706678","pt":1646094734872,"mc":[{"id":"1.195395448","rc":[{"atl":[[1.86,0],[1.87,22.99]],"id":42315317},{"atb":[[1.33,0],[1.36,55.56]],"id":40041375},{"atb":[[1.19,0],[1.17,368.89]],"id":43154430},{"atl":[[2.66,0],[2.58,0],[2.62,14.82]],"id":43154430}],"con":true,"img":false}]}
{"op":"mcm","clk":"5346706688","pt":1646094735178,"mc":[{"id":"1.195395448","rc":[{"atl":[[4.2,12.98]],"id":37076580}],"con":true,"img":false}]}
{"op":"mcm","clk":"5346706691","pt":1646094735280,"mc":[{"id":"1.195395448","rc":[{"atl":[[2.56,0]],"id":43154430},{"atl":[[3.6,0]],"id":37076580}],"con":true,"img":false}]}
{"op":"mcm","clk":"5346706694","pt":1646094735332,"mc":[{"id":"1.195395448","rc":[{"atl":[[2.76,24.33]],"id":43154430}],"con":true,"img":false}]}
{"op":"mcm","clk":"5346706707","pt":1646094735642,"mc":[{"id":"1.195395448","rc":[{"atl":[[1.86,23.26],[1.87,0]],"id":42315317},{"atb":[[1.33,60.61],[1.36,0]],"id":40041375}],"con":true,"img":false}]}
{"op":"mcm","clk":"5346706800","pt":1646094738150,"mc":[{"id":"1.195395448","rc":[{"atl":[[8,0],[7.8,2.94]],"id":40014837},{"atb":[[1.86,0],[1.87,22.99]],"id":38541023}],"con":true,"img":false}]}
{"op":"mcm","clk":"5346706829","pt":1646094739379,"mc":[{"id":"1.195395448","rc":[{"atb":[[1.18,125.62]],"id":43154430}],"con":true,"img":false}]}
{"op":"mcm","clk":"5346706833","pt":1646094739479,"mc":[{"id":"1.195395448","rc":[{"atb":[[1.19,125.62]],"id":43154430},{"atl":[[2.28,58.59]],"id":43154430}],"con":true,"img":false}]}
{"op":"mcm","clk":"5346706837","pt":1646094739581,"mc":[{"id":"1.195395448","rc":[{"atb":[[1.17,117.65]],"id":43154430}],"con":true,"img":false}]}
{"op":"mcm","clk":"5346706942","pt":1646094742400,"mc":[{"id":"1.195395448","rc":[{"atl":[[8,2.86],[7.8,0]],"id":40014837},{"atb":[[1.33,0],[1.36,55.56]],"id":40041375}],"con":true,"img":false}]}
{"op":"mcm","clk":"5346706953","pt":1646094742657,"mc":[{"id":"1.195395448","rc":[{"atl":[[8,0],[7.8,2.94]],"id":40014837},{"atb":[[1.33,60.61],[1.36,0]],"id":40041375}],"con":true,"img":false}]}
{"op":"mcm","clk":"5346707006","pt":1646094744402,"mc":[{"id":"1.195395448","rc":[{"atb":[[1.18,0]],"id":43154430}],"con":true,"img":false}]}
{"op":"mcm","clk":"5346707018","pt":1646094744606,"mc":[{"id":"1.195395448","rc":[{"atb":[[1.19,0],[1.17,368.89]],"id":43154430}],"con":true,"img":false}]}
{"op":"mcm","clk":"5346707056","pt":1646094745680,"mc":[{"id":"1.195395448","rc":[{"atl":[[1.88,56.82]],"id":42315317}],"con":true,"img":false}]}
{"op":"mcm","clk":"5346707107","pt":1646094747069,"mc":[{"id":"1.195395448","rc":[{"atl":[[1.96,0]],"id":42315317}],"con":true,"img":false}]}
{"op":"mcm","clk":"5346707176","pt":1646094749479,"mc":[{"id":"1.195395448","rc":[{"atl":[[2.32,94.7]],"id":43154430}],"con":true,"img":false}]}
{"op":"mcm","clk":"5346707181","pt":1646094749581,"mc":[{"id":"1.195395448","rc":[{"atb":[[1.18,125.62]],"id":43154430}],"con":true,"img":false}]}
{"op":"mcm","clk":"5346707185","pt":1646094749684,"mc":[{"id":"1.195395448","rc":[{"atb":[[1.19,125.62],[1.17,117.65]],"id":43154430}],"con":true,"img":false}]}
{"op":"mcm","clk":"5346707223","pt":1646094750504,"mc":[{"id":"1.195395448","rc":[{"atl":[[8,2.86],[7.8,0]],"id":40014837},{"atb":[[1.36,55.56]],"id":40041375}],"con":true,"img":false}]}
{"op":"mcm","clk":"5346707226","pt":1646094750607,"mc":[{"id":"1.195395448","rc":[{"atb":[[1.33,0]],"id":40041375}],"con":true,"img":false}]}
{"op":"mcm","clk":"5346707278","pt":1646094751690,"mc":[{"id":"1.195395448","rc":[{"atl":[[8,0],[7.8,2.94]],"id":40014837},{"atb":[[1.33,60.61],[1.36,0]],"id":40041375}],"con":true,"img":false}]}
{"op":"mcm","clk":"5346707388","pt":1646094754613,"mc":[{"id":"1.195395448","rc":[{"atb":[[1.18,0]],"id":43154430}],"con":true,"img":false}]}
{"op":"mcm","clk":"5346707393","pt":1646094754716,"mc":[{"id":"1.195395448","rc":[{"atb":[[1.19,0],[1.17,368.89]],"id":43154430}],"con":true,"img":false}]}
{"op":"mcm","clk":"5346707426","pt":1646094755691,"mc":[{"id":"1.195395448","rc":[{"atl":[[1.9,83.33]],"id":42315317}],"con":true,"img":false}]}
{"op":"mcm","clk":"5346707546","pt":1646094759183,"mc":[{"id":"1.195395448","rc":[{"atl":[[8,2.86],[7.8,0]],"id":40014837},{"atl":[[1.94,0]],"id":42315317},{"atb":[[1.33,0]],"id":40041375}],"con":true,"img":false}]}
{"op":"mcm","clk":"5346707549","pt":1646094759287,"mc":[{"id":"1.195395448","rc":[{"atb":[[1.36,55.56]],"id":40041375}],"con":true,"img":false}]}
{"op":"mcm","clk":"5346707553","pt":1646094759490,"mc":[{"id":"1.195395448","rc":[{"atb":[[1.18,125.62]],"id":43154430}],"con":true,"img":false}]}
{"op":"mcm","clk":"5346707563","pt":1646094759901,"mc":[{"id":"1.195395448","rc":[{"atl":[[8,0],[7.8,2.94]],"id":40014837},{"atb":[[1.33,60.61],[1.36,0]],"id":40041375}],"con":true,"img":false}]}
{"op":"mcm","clk":"5346707721","pt":1646094764487,"mc":[{"id":"1.195395448","rc":[{"atb":[[1.19,125.62],[1.17,117.65]],"id":43154430}],"con":true,"img":false}]}
{"op":"mcm","clk":"5346707747","pt":1646094765203,"mc":[{"id":"1.195395448","rc":[{"atl":[[2.46,0]],"id":43154430}],"con":true,"img":false}]}
{"op":"mcm","clk":"5346707750","pt":1646094765305,"mc":[{"id":"1.195395448","rc":[{"atl":[[2.22,44.81]],"id":43154430}],"con":true,"img":false}]}
{"op":"mcm","clk":"5346707767","pt":1646094765714,"mc":[{"id":"1.195395448","rc":[{"atl":[[1.92,135.87]],"id":42315317}],"con":true,"img":false}]}
{"op":"mcm","clk":"5346707871","pt":1646094769053,"mc":[{"id":"1.195395448","rc":[{"atl":[[8,2.86],[7.8,0]],"id":40014837},{"atb":[[1.33,0],[1.36,55.56]],"id":40041375},{"atb":[[1.18,0]],"id":43154430}],"con":true,"img":false}]}
{"op":"mcm","clk":"5346707880","pt":1646094769207,"mc":[{"id":"1.195395448","rc":[{"atb":[[1.19,0],[1.17,368.89]],"id":43154430}],"con":true,"img":false}]}
{"op":"mcm","clk":"5346708043","pt":1646094773832,"mc":[{"id":"1.195395448","rc":[{"atb":[[1.18,125.62]],"id":43154430}],"con":true,"img":false}]}
{"op":"mcm","clk":"5346708106","pt":1646094775119,"mc":[{"id":"1.195395448","rc":[{"atl":[[11.5,9.52]],"id":37535509}],"con":true,"img":false}]}
{"op":"mcm","clk":"5346708109","pt":1646094775222,"mc":[{"id":"1.195395448","rc":[{"atl":[[12.5,3.68]],"id":37535509}],"con":true,"img":false}]}
{"op":"mcm","clk":"5346708117","pt":1646094775427,"mc":[{"id":"1.195395448","rc":[{"atl":[[8,0],[7.8,2.94]],"id":40014837},{"atb":[[1.33,60.61],[1.36,0]],"id":40041375}],"con":true,"img":false}]}
{"op":"mcm","clk":"5346708237","pt":1646094778819,"mc":[{"id":"1.195395448","rc":[{"atb":[[1.19,125.62]],"id":43154430}],"con":true,"img":false}]}
{"op":"mcm","clk":"5346708243","pt":1646094778919,"mc":[{"id":"1.195395448","rc":[{"atb":[[1.17,117.65]],"id":43154430}],"con":true,"img":false}]}
{"op":"mcm","clk":"5346708398","pt":1646094783431,"mc":[{"id":"1.195395448","rc":[{"atb":[[1.18,0]],"id":43154430}],"con":true,"img":false}]}
{"op":"mcm","clk":"5346708412","pt":1646094783944,"mc":[{"id":"1.195395448","rc":[{"atb":[[1.19,0],[1.17,368.89]],"id":43154430}],"con":true,"img":false}]}
{"op":"mcm","clk":"5346708476","pt":1646094785428,"mc":[{"id":"1.195395448","rc":[{"atb":[[1.31,161.29]],"id":40041375},{"atl":[[7.2,12.1]],"id":40041375}],"con":true,"img":false}]}
{"op":"mcm","clk":"5346708569","pt":1646094787540,"mc":[{"id":"1.195395448","rc":[{"atb":[[1.2,0],[1.18,0],[1.22,0]],"id":40041375}],"con":true,"img":false}]}
{"op":"mcm","clk":"5346708637","pt":1646094788929,"mc":[{"id":"1.195395448","rc":[{"atb":[[1.18,125.62]],"id":43154430}],"con":true,"img":false}]}
{"op":"mcm","clk":"5346708644","pt":1646094789030,"mc":[{"id":"1.195395448","rc":[{"atb":[[1.19,125.62],[1.17,117.65]],"id":43154430}],"con":true,"img":false}]}
{"op":"mcm","clk":"5346708799","pt":1646094792265,"mc":[{"id":"1.195395448","rc":[{"atl":[[8,2.86],[7.8,0]],"id":40014837},{"atb":[[1.36,55.56]],"id":40041375}],"con":true,"img":false}]}
{"op":"mcm","clk":"5346708818","pt":1646094792574,"mc":[{"id":"1.195395448","rc":[{"atl":[[8,0],[7.8,2.94]],"id":40014837},{"atb":[[1.36,0]],"id":40041375}],"con":true,"img":false}]}
{"op":"mcm","clk":"5346708888","pt":1646094793958,"mc":[{"id":"1.195395448","rc":[{"atb":[[1.18,0]],"id":43154430}],"con":true,"img":false}]}
{"op":"mcm","clk":"5346708902","pt":1646094794266,"mc":[{"id":"1.195395448","rc":[{"atb":[[1.17,368.89]],"id":43154430}],"con":true,"img":false}]}
{"op":"mcm","clk":"5346708906","pt":1646094794368,"mc":[{"id":"1.195395448","rc":[{"atb":[[1.19,0]],"id":43154430}],"con":true,"img":false}]}
{"op":"mcm","clk":"5346709130","pt":1646094799042,"mc":[{"id":"1.195395448","rc":[{"atb":[[1.18,125.62]],"id":43154430}],"con":true,"img":false}]}
{"op":"mcm","clk":"5346709250","pt":1646094802067,"mc":[{"id":"1.195395448","rc":[{"atl":[[8,2.86],[7.8,0]],"id":40014837},{"atb":[[1.36,55.56]],"id":40041375}],"con":true,"img":false}]}
{"op":"mcm","clk":"5346709327","pt":1646094803660,"mc":[{"id":"1.195395448","rc":[{"atb":[[1.19,125.62],[1.17,117.65]],"id":43154430}],"con":true,"img":false}]}
{"op":"mcm","clk":"5346709336","pt":1646094803865,"mc":[{"id":"1.195395448","rc":[{"atl":[[8,0],[7.8,2.94]],"id":40014837},{"atb":[[1.36,0]],"id":40041375}],"con":true,"img":false}]}
{"op":"mcm","clk":"5346709568","pt":1646094808802,"mc":[{"id":"1.195395448","rc":[{"atb":[[1.18,0]],"id":43154430}],"con":true,"img":false}]}
{"op":"mcm","clk":"5346709578","pt":1646094808958,"mc":[{"id":"1.195395448","rc":[{"atb":[[1.19,0],[1.17,368.89]],"id":43154430}],"con":true,"img":false}]}
{"op":"mcm","clk":"5346709667","pt":1646094811160,"mc":[{"id":"1.195395448","rc":[{"atl":[[8,2.86],[7.8,0]],"id":40014837},{"atb":[[1.36,55.56]],"id":40041375}],"con":true,"img":false}]}
{"op":"mcm","clk":"5346709782","pt":1646094813778,"mc":[{"id":"1.195395448","rc":[{"atb":[[1.18,125.62]],"id":43154430}],"con":true,"img":false}]}
{"op":"mcm","clk":"5346709959","pt":1646094817175,"mc":[{"id":"1.195395448","rc":[{"atl":[[8,0],[7.8,2.94]],"id":40014837},{"atb":[[1.36,0]],"id":40041375}],"con":true,"img":false}]}
{"op":"mcm","clk":"5346709994","pt":1646094817792,"mc":[{"id":"1.195395448","rc":[{"atl":[[8,2.86],[7.8,0]],"id":40014837},{"atb":[[1.36,55.56]],"id":40041375}],"con":true,"img":false}]}
{"op":"mcm","clk":"5346710016","pt":1646094818201,"mc":[{"id":"1.195395448","rc":[{"atb":[[1.19,125.62],[1.17,117.65]],"id":43154430}],"con":true,"img":false}]}
{"op":"mcm","clk":"5346710031","pt":1646094818409,"mc":[{"id":"1.195395448","rc":[{"atl":[[8,0],[7.8,2.94]],"id":40014837},{"atb":[[1.36,0]],"id":40041375}],"con":true,"img":false}]}
{"op":"mcm","clk":"5346710038","pt":1646094818615,"mc":[{"id":"1.195395448","rc":[{"atl":[[8,2.86],[7.8,0]],"id":40014837}],"con":true,"img":false}]}
{"op":"mcm","clk":"5346710093","pt":1646094820100,"mc":[{"id":"1.195395448","rc":[{"atb":[[1.36,55.56]],"id":40041375}],"con":true,"img":false}]}
{"op":"mcm","clk":"5346710115","pt":1646094820819,"mc":[{"id":"1.195395448","rc":[{"atb":[[1.18,0]],"id":43154430}],"con":true,"img":false}]}
{"op":"mcm","clk":"5346710208","pt":1646094823289,"mc":[{"id":"1.195395448","rc":[{"atb":[[1.19,0],[1.17,368.89]],"id":43154430}],"con":true,"img":false}]}
{"op":"mcm","clk":"5346710319","pt":1646094826008,"mc":[{"id":"1.195395448","rc":[{"atb":[[1.2,87.93]],"id":43154430}],"con":true,"img":false}]}
{"op":"mcm","clk":"5346710364","pt":1646094827292,"mc":[{"id":"1.195395448","rc":[{"atb":[[1.21,87.93],[1.17,117.65]],"id":43154430}],"con":true,"img":false}]}
{"op":"mcm","clk":"5346710465","pt":1646094830017,"mc":[{"id":"1.195395448","rc":[{"atl":[[7.6,20.75]],"id":40041375}],"con":true,"img":false}]}
{"op":"mcm","clk":"5346710470","pt":1646094830225,"mc":[{"id":"1.195395448","rc":[{"atl":[[11.5,0],[9.6,11.63]],"id":37535509},{"atl":[[7.4,23.62],[7.8,18.38]],"id":36899944},{"atl":[[2.42,25.04],[2.2,83.33]],"id":42315317},{"atl":[[2.52,65.79],[2.78,0]],"id":43154430},{"atl":[[2.8,0],[2.52,65.79]],"id":37076580}],"con":true,"img":false}]}
{"op":"mcm","clk":"5346710488","pt":1646094830737,"mc":[{"id":"1.195395448","rc":[{"atb":[[1.2,0]],"id":43154430}],"con":true,"img":false}]}
{"op":"mcm","clk":"5346710496","pt":1646094830945,"mc":[{"id":"1.195395448","rc":[{"atb":[[1.21,0],[1.17,293.51]],"id":43154430}],"con":true,"img":false}]}
{"op":"mcm","clk":"5346710587","pt":1646094834747,"mc":[{"id":"1.195395448","rc":[{"atl":[[2.32,15.15],[2.2,0]],"id":43154430}],"con":true,"img":false}]}
{"op":"mcm","clk":"5346710601","pt":1646094835157,"mc":[{"id":"1.195395448","rc":[{"atl":[[2.76,0]],"id":43154430},{"atl":[[2.78,0]],"id":37076580}],"con":true,"img":false}]}
{"op":"mcm","clk":"5346710608","pt":1646094835210,"mc":[{"id":"1.195395448","rc":[{"atl":[[2.8,24.33]],"id":43154430},{"atl":[[3.1,22.28]],"id":37076580}],"con":true,"img":false}]}
{"op":"mcm","clk":"5346710618","pt":1646094835414,"mc":[{"id":"1.195395448","rc":[{"atl":[[7.4,11.72],[7.8,33.09]],"id":36899944},{"atl":[[2.42,95.46],[2.2,0]],"id":42315317},{"atl":[[2.8,79.89],[2.52,0]],"id":43154430},{"atl":[[2.52,0],[2.78,56.18]],"id":37076580}],"con":true,"img":false}]}
{"op":"mcm","clk":"5346710651","pt":1646094836132,"mc":[{"id":"1.195395448","rc":[{"atb":[[1.18,125.62]],"id":43154430}],"con":true,"img":false}]}
{"op":"mcm","clk":"5346710655","pt":1646094836238,"mc":[{"id":"1.195395448","rc":[{"atb":[[1.19,125.62],[1.17,117.65]],"id":43154430}],"con":true,"img":false}]}
{"op":"mcm","clk":"5346710831","pt":1646094840857,"mc":[{"id":"1.195395448","rc":[{"atb":[[1.18,0]],"id":43154430}],"con":true,"img":false}]}
{"op":"mcm","clk":"5346710838","pt":1646094841011,"mc":[{"id":"1.195395448","rc":[{"atl":[[2.24,0]],"id":43154430}],"con":true,"img":false}]}
{"op":"mcm","clk":"5346710853","pt":1646094841421,"mc":[{"id":"1.195395448","rc":[{"atb":[[1.17,368.89]],"id":43154430}],"con":true,"img":false}]}
{"op":"mcm","clk":"5346710859","pt":1646094841524,"mc":[{"id":"1.195395448","rc":[{"atb":[[1.19,0]],"id":43154430}],"con":true,"img":false}]}
{"op":"mcm","clk":"5346710892","pt":1646094842446,"mc":[{"id":"1.195395448","rc":[{"atl":[[2.28,0]],"id":43154430}],"con":true,"img":false}]}
{"op":"mcm","clk":"5346710984","pt":1646094844757,"mc":[{"id":"1.195395448","rc":[{"atl":[[2.36,36.76]],"id":43154430}],"con":true,"img":false}]}
{"op":"mcm","clk":"5346711002","pt":1646094845225,"mc":[{"id":"1.195395448","rc":[{"atl":[[2.22,9.84]],"id":43154430}],"con":true,"img":false}]}
{"op":"mcm","clk":"5346711004","pt":1646094845322,"mc":[{"id":"1.195395448","rc":[{"atl":[[2.34,34.97]],"id":43154430}],"con":true,"img":false}]}
{"op":"mcm","clk":"5346711012","pt":1646094845526,"mc":[{"id":"1.195395448","rc":[{"atb":[[1.18,125.62]],"id":43154430}],"con":true,"img":false}]}
{"op":"mcm","clk":"5346711207","pt":1646094850348,"mc":[{"id":"1.195395448","rc":[{"atb":[[1.19,125.62],[1.17,117.65]],"id":43154430}],"con":true,"img":false}]}
{"op":"mcm","clk":"5346711312","pt":1646094852975,"mc":[{"id":"1.195395448","rc":[{"atb":[[1.18,0]],"id":43154430}],"con":true,"img":false}]}
{"op":"mcm","clk":"5346711316","pt":1646094853178,"mc":[{"id":"1.195395448","rc":[{"atb":[[1.17,368.89]],"id":43154430}],"con":true,"img":false}]}
{"op":"mcm","clk":"5346711320","pt":1646094853230,"mc":[{"id":"1.195395448","rc":[{"atb":[[1.19,0]],"id":43154430}],"con":true,"img":false}]}
{"op":"mcm","clk":"5346711324","pt":1646094853438,"mc":[{"id":"1.195395448","rc":[{"atl":[[2.4,0]],"id":38541023}],"con":true,"img":false}]}
{"op":"mcm","clk":"5346711328","pt":1646094853538,"mc":[{"id":"1.195395448","rc":[{"atl":[[3.6,0],[3.85,52.63],[2.3,27.04]],"id":38541023}],"con":true,"img":false}]}
{"op":"mcm","clk":"5346711332","pt":1646094853640,"mc":[{"id":"1.195395448","rc":[{"atl":[[3.6,38.46]],"id":38541023}],"con":true,"img":false}]}
{"op":"mcm","clk":"5346711336","pt":1646094853743,"mc":[{"id":"1.195395448","rc":[{"atl":[[3.85,17.53]],"id":38541023}],"con":true,"img":false}]}
{"op":"mcm","clk":"5346711369","pt":1646094854772,"mc":[{"id":"1.195395448","rc":[{"atl":[[2.4,53.57]],"id":43154430}],"con":true,"img":false}]}
{"op":"mcm","clk":"5346711499","pt":1646094858255,"mc":[{"id":"1.195395448","rc":[{"atb":[[1.18,125.62]],"id":43154430}],"con":true,"img":false}]}
{"op":"mcm","clk":"5346711642","pt":1646094861956,"mc":[{"id":"1.195395448","rc":[{"atb":[[1.19,125.62],[1.17,117.65]],"id":43154430}],"con":true,"img":false}]}
{"op":"mcm","clk":"5346711737","pt":1646094864773,"mc":[{"id":"1.195395448","rc":[{"atl":[[2.44,86.81]],"id":43154430}],"con":true,"img":false}]}
{"op":"mcm","clk":"5346711757","pt":1646094865290,"mc":[{"id":"1.195395448","rc":[{"atl":[[8.8,0]],"id":40041375},{"atl":[[3.1,0]],"id":37076580}],"con":true,"img":false}]}
{"op":"mcm","clk":"5346711760","pt":1646094865389,"mc":[{"id":"1.195395448","rc":[{"atl":[[7.4,5.79]],"id":40041375},{"atl":[[2.76,22.28]],"id":37076580}],"con":true,"img":false}]}
{"op":"mcm","clk":"5346711795","pt":1646094866158,"mc":[{"id":"1.195395448","rc":[{"atb":[[1.18,0]],"id":43154430}],"con":true,"img":false}]}
{"op":"mcm","clk":"5346711797","pt":1646094866261,"mc":[{"id":"1.195395448","rc":[{"atb":[[1.17,368.89]],"id":43154430}],"con":true,"img":false}]}
{"op":"mcm","clk":"5346711805","pt":1646094866363,"mc":[{"id":"1.195395448","rc":[{"atb":[[1.19,0]],"id":43154430}],"con":true,"img":false}]}
{"op":"mcm","clk":"5346712015","pt":1646094871594,"mc":[{"id":"1.195395448","rc":[{"atb":[[1.18,125.62]],"id":43154430},{"atl":[[2.14,17.54],[2.24,0]],"id":37076580}],"con":true,"img":false}]}
{"op":"mcm","clk":"5346712026","pt":1646094871800,"mc":[{"id":"1.195395448","rc":[{"atl":[[2.14,0],[2.24,16.13]],"id":37076580}],"con":true,"img":false}]}
{"op":"mcm","clk":"5346712155","pt":1646094874987,"mc":[{"id":"1.195395448","rc":[{"atb":[[1.19,125.62],[1.17,117.65]],"id":43154430}],"con":true,"img":false}]}
{"op":"mcm","clk":"5346712161","pt":1646094875191,"mc":[{"id":"1.195395448","rc":[{"atl":[[3.9,0]],"id":38541023},{"atb":[[3.35,68.09]],"id":37535509},{"atl":[[2.8,55.56]],"id":43154430},{"atb":[[1.41,162.51]],"id":37076580}],"con":true,"img":false}]}
{"op":"mcm","clk":"5346712167","pt":1646094875293,"mc":[{"id":"1.195395448","rc":[{"atl":[[3.8,13.52]],"id":38541023},{"atb":[[3.4,17.25]],"id":37535509},{"atl":[[2.78,24.33]],"id":43154430},{"atb":[[1.42,117.36]],"id":37076580}],"con":true,"img":false}]}
{"op":"mcm","clk":"5346712276","pt":1646094878726,"mc":[{"id":"1.195395448","rc":[{"atb":[[1.44,18.99]],"id":37076580}],"con":true,"img":false}]}
{"op":"mcm","clk":"5346712293","pt":1646094879190,"mc":[{"id":"1.195395448","rc":[{"atb":[[1.18,0]],"id":43154430}],"con":true,"img":false}]}
{"op":"mcm","clk":"5346712300","pt":1646094879399,"mc":[{"id":"1.195395448","rc":[{"atl":[[2.14,17.54],[2.24,0]],"id":37076580}],"con":true,"img":false}]}
{"op":"mcm","clk":"5346712304","pt":1646094879499,"mc":[{"id":"1.195395448","rc":[{"atl":[[2.14,0],[2.24,16.13]],"id":37076580}],"con":true,"img":false}]}
{"op":"mcm","clk":"5346712322","pt":1646094880114,"mc":[{"id":"1.195395448","rc":[{"atb":[[1.17,368.89]],"id":43154430}],"con":true,"img":false}]}
{"op":"mcm","clk":"5346712326","pt":1646094880215,"mc":[{"id":"1.195395448","rc":[{"atb":[[1.19,0]],"id":43154430}],"con":true,"img":false}]}
{"op":"mcm","clk":"5346712380","pt":1646094881806,"mc":[{"id":"1.195395448","rc":[{"atb":[[3.4,34.51]],"id":37535509},{"atl":[[1.84,23.81],[1.86,0]],"id":42315317},{"atl":[[2.14,17.54]],"id":37076580}],"con":true,"img":false}]}
{"op":"mcm","clk":"5346712384","pt":1646094881909,"mc":[{"id":"1.195395448","rc":[{"atb":[[3.35,25.54]],"id":37535509},{"atl":[[2.24,0]],"id":37076580}],"con":true,"img":false}]}
{"op":"mcm","clk":"5346712392","pt":1646094882113,"mc":[{"id":"1.195395448","rc":[{"atl":[[2.36,0],[2.32,0],[2.28,0]],"id":37076580}],"con":true,"img":false}]}
{"op":"mcm","clk":"5346712486","pt":1646094884527,"mc":[{"id":"1.195395448","rc":[{"atb":[[3.45,3.4]],"id":37535509},{"atb":[[1.18,125.62]],"id":43154430},{"atb":[[1.45,41.69]],"id":37076580}],"con":true,"img":false}]}
{"op":"mcm","clk":"5346712624","pt":1646094888631,"mc":[{"id":"1.195395448","rc":[{"atb":[[1.19,125.62]],"id":43154430}],"con":true,"img":false}]}
{"op":"mcm","clk":"5346712628","pt":1646094888737,"mc":[{"id":"1.195395448","rc":[{"atb":[[1.17,117.65]],"id":43154430}],"con":true,"img":false}]}
{"op":"mcm","clk":"5346712696","pt":1646094890536,"mc":[{"id":"1.195395448","rc":[{"atb":[[3.5,2.97]],"id":37535509}],"con":true,"img":false}]}
{"op":"mcm","clk":"5346712729","pt":1646094891716,"mc":[{"id":"1.195395448","rc":[{"atb":[[1.44,0]],"id":37076580}],"con":true,"img":false}]}
{"op":"mcm","clk":"5346712734","pt":1646094891818,"mc":[{"id":"1.195395448","rc":[{"atl":[[1.86,58.14]],"id":42315317},{"atb":[[1.18,0]],"id":43154430},{"atl":[[2.18,42.37]],"id":37076580}],"con":true,"img":false}]}
{"op":"mcm","clk":"5346712737","pt":1646094891922,"mc":[{"id":"1.195395448","rc":[{"atb":[[1.17,368.89]],"id":43154430}],"con":true,"img":false}]}
{"op":"mcm","clk":"5346712742","pt":1646094892025,"mc":[{"id":"1.195395448","rc":[{"atb":[[1.19,0]],"id":43154430}],"con":true,"img":false}]}
{"op":"mcm","clk":"5346712756","pt":1646094892536,"mc":[{"id":"1.195395448","rc":[{"atl":[[1.92,0]],"id":42315317}],"con":true,"img":false}]}
{"op":"mcm","clk":"5346712849","pt":1646094895210,"mc":[{"id":"1.195395448","rc":[{"atl":[[10.5,1.26]],"id":36899944},{"atb":[[1.42,0]],"id":37076580}],"con":true,"img":false}]}
{"op":"mcm","clk":"5346712852","pt":1646094895313,"mc":[{"id":"1.195395448","rc":[{"atl":[[11.5,5.07]],"id":36899944},{"atb":[[1.41,279.88]],"id":37076580}],"con":true,"img":false}]}
{"op":"mcm","clk":"5346712899","pt":1646094896549,"mc":[{"id":"1.195395448","rc":[{"atb":[[1.45,25.14]],"id":37076580}],"con":true,"img":false}]}
{"op":"mcm","clk":"5346712912","pt":1646094896856,"mc":[{"id":"1.195395448","rc":[{"atb":[[1.18,125.62]],"id":43154430}],"con":true,"img":false}]}
{"op":"mcm","clk":"5346712993","pt":1646094899056,"mc":[{"id":"1.195395448","rc":[{"atb":[[1.45,0]],"id":37076580}],"con":true,"img":false}]}
{"op":"mcm","clk":"5346713035","pt":1646094900343,"mc":[{"id":"1.195395448","rc":[{"atb":[[1.18,182.27],[1.16,153.86],[1.19,125.62],[1.17,117.65]],"id":43154430},{"atl":[[2.22,66.49],[2.34,131.18]],"id":43154430}],"con":true,"img":false}]}
{"op":"mcm","clk":"5346713040","pt":1646094900447,"mc":[{"id":"1.195395448","rc":[{"atb":[[3.7,2.5],[3.4,77.43],[3.5,44.81]],"id":40014837},{"atl":[[8.8,36.75],[8.4,17.57]],"id":40014837},{"atb":[[3.45,13.4],[3.85,2.5],[3.4,51.4],[3.5,11.41],[3.65,5]],"id":37535509},{"atl":[[6.8,11.89],[7.8,27.92]],"id":37535509},{"atb":[[3.25,24.31],[3.15,49.09]],"id":36899944},{"atl":[[6.4,12.92],[7.4,37.55],[7.6,2.5]],"id":36899944},{"atb":[[1.27,187.51],[1.25,420.34]],"id":42315317},{"atl":[[1.84,111.14],[1.88,176.63]],"id":42315317},{"atb":[[2.5,8.07],[2.58,10],[2.74,2.5],[2.42,46.87],[2.66,5]],"id":40041375},{"atl":[[5.8,9.71],[6.8,24.76]],"id":40041375},{"atb":[[1.27,5],[1.23,10],[1.31,2.5]],"id":43154430},{"atb":[[1.4,475.71],[1.44,10],[1.43,113.17],[1.48,5],[1.52,2.5]],"id":37076580},{"atl":[[2.66,91.91],[2.14,84.2]],"id":37076580}],"con":true,"img":false}]}
{"op":"mcm","clk":"5346713045","pt":1646094900549,"mc":[{"id":"1.195395448","rc":[{"atb":[[3.7,19.06],[3.5,36.81]],"id":40014837},{"atb":[[1.4,2.5],[1.36,5],[1.32,10]],"id":42315317},{"atb":[[1.19,0],[1.24,125.62]],"id":43154430}],"con":true,"img":false}]}
{"op":"mcm","clk":"5346713050","pt":1646094900653,"mc":[{"id":"1.195395448","rc":[{"atb":[[3.7,2.5],[3.5,74.93]],"id":40014837},{"atl":[[2.16,86.21]],"id":42315317},{"atl":[[2.54,64.94]],"id":43154430}],"con":true,"img":false}]}
{"op":"mcm","clk":"5346713055","pt":1646094900754,"mc":[{"id":"1.195395448","rc":[{"atl":[[7.8,18.38],[7,24.82]],"id":36899944},{"atl":[[2.42,25.04]],"id":42315317},{"atl":[[2.8,0]],"id":43154430},{"atl":[[2.64,60.98],[2.78,0]],"id":37076580}],"con":true,"img":false}]}
{"op":"mcm","clk":"5346713090","pt":1646094901834,"mc":[{"id":"1.195395448","rc":[{"atl":[[1.88,261.86]],"id":42315317},{"atl":[[2.22,61.48]],"id":37076580}],"con":true,"img":false}]}
{"op":"mcm","clk":"5346713094","pt":1646094901935,"mc":[{"id":"1.195395448","rc":[{"atl":[[1.88,205.04]],"id":42315317},{"atl":[[2.52,65.79]],"id":37076580}],"con":true,"img":false}]}
{"op":"mcm","clk":"5346713098","pt":1646094902040,"mc":[{"id":"1.195395448","rc":[{"atl":[[3.75,67.63]],"id":38541023},{"atl":[[2.64,0]],"id":37076580}],"con":true,"img":false}]}
{"op":"mcm","clk":"5346713117","pt":1646094902652,"mc":[{"id":"1.195395448","rc":[{"atb":[[3.5,71.95]],"id":40014837},{"atb":[[3.2,0]],"id":36899944}],"con":true,"img":false}]}
{"op":"mcm","clk":"5346713172","pt":1646094904245,"mc":[{"id":"1.195395448","rc":[{"atb":[[1.27,105.28]],"id":42315317},{"atb":[[1.18,56.65]],"id":43154430},{"atb":[[1.45,3.75]],"id":37076580}],"con":true,"img":false}]}
{"op":"mcm","clk":"5346713202","pt":1646094905272,"mc":[{"id":"1.195395448","rc":[{"atl":[[3.8,0]],"id":38541023},{"atb":[[3.05,0]],"id":37535509},{"atl":[[12.5,0]],"id":37535509},{"atl":[[7.4,0]],"id":40041375},{"atl":[[2.78,0]],"id":43154430}],"con":true,"img":false}]}
{"op":"mcm","clk":"5346713207","pt":1646094905375,"mc":[{"id":"1.195395448","rc":[{"atl":[[3.9,13.52]],"id":38541023},{"atb":[[3.15,17.18]],"id":37535509},{"atl":[[12,4.78]],"id":37535509},{"atl":[[9,5.79]],"id":40041375},{"atl":[[3,24.33]],"id":43154430}],"con":true,"img":false}]}
{"op":"mcm","clk":"5346713305","pt":1646094908658,"mc":[{"id":"1.195395448","rc":[{"atb":[[3.6,2.86]],"id":40014837},{"atb":[[3.3,3.24]],"id":36899944},{"atb":[[1.46,16.19]],"id":37076580}],"con":true,"img":false}]}
{"op":"mcm","clk":"5346713311","pt":1646094908761,"mc":[{"id":"1.195395448","rc":[{"atb":[[3.6,19.42],[3.5,33.83]],"id":40014837}],"con":true,"img":false}]}
{"op":"mcm","clk":"5346713313","pt":1646094908864,"mc":[{"id":"1.195395448","rc":[{"atb":[[3.6,2.86],[3.55,39.22]],"id":40014837}],"con":true,"img":false}]}
{"op":"mcm","clk":"5346713338","pt":1646094909539,"mc":[{"id":"1.195395448","rc":[{"atb":[[1.33,3.75]],"id":42315317},{"atb":[[1.25,3.5]],"id":43154430}],"con":true,"img":false}]}
{"op":"mcm","clk":"5346713424","pt":1646094911642,"mc":[{"id":"1.195395448","rc":[{"atb":[[3.6,0]],"id":40014837}],"con":true,"img":false}]}
{"op":"mcm","clk":"5346713429","pt":1646094911846,"mc":[{"id":"1.195395448","rc":[{"atl":[[1.9,138.89]],"id":42315317},{"atl":[[2.26,99.21]],"id":37076580}],"con":true,"img":false}]}
{"op":"mcm","clk":"5346713433","pt":1646094911948,"mc":[{"id":"1.195395448","rc":[{"atb":[[1.45,0]],"id":37076580}],"con":true,"img":false}]}
{"op":"mcm","clk":"5346713532","pt":1646094915285,"mc":[{"id":"1.195395448","rc":[{"atl":[[2.76,0]],"id":37076580}],"con":true,"img":false}]}
{"op":"mcm","clk":"5346713537","pt":1646094915394,"mc":[{"id":"1.195395448","rc":[{"atl":[[2.64,22.28]],"id":37076580}],"con":true,"img":false}]}
{"op":"mcm","clk":"5346713587","pt":1646094917186,"mc":[{"id":"1.195395448","rc":[{"atb":[[1.49,2.75]],"id":37076580}],"con":true,"img":false}]}
{"op":"mcm","clk":"5346713595","pt":1646094917494,"mc":[{"id":"1.195395448","rc":[{"atb":[[3.65,2.8]],"id":40014837}],"con":true,"img":false}]}
{"op":"mcm","clk":"5346713599","pt":1646094917596,"mc":[{"id":"1.195395448","rc":[{"atb":[[3.65,36.63]],"id":40014837}],"con":true,"img":false}]}
{"op":"mcm","clk":"5346713602","pt":1646094917699,"mc":[{"id":"1.195395448","rc":[{"atb":[[3.55,0]],"id":40014837}],"con":true,"img":false}]}
{"op":"mcm","clk":"5346713609","pt":1646094917854,"mc":[{"id":"1.195395448","rc":[{"atb":[[1.25,33.72],[1.16,40.56],[1.31,17.61]],"id":43154430}],"con":true,"img":false}]}
{"op":"mcm","clk":"5346713612","pt":1646094917957,"mc":[{"id":"1.195395448","rc":[{"atb":[[3.7,32.13],[3.4,35.85],[3.5,101.76]],"id":40014837},{"atl":[[8,13.82]],"id":40014837},{"atb":[[3.85,16.92],[3.4,34.51],[3.5,40.25]],"id":37535509},{"atb":[[3.3,31.16]],"id":36899944},{"atl":[[7.4,11.72],[7,58.78]],"id":36899944},{"atb":[[1.33,98.46],[1.4,49.86],[1.25,240.14]],"id":42315317},{"atb":[[2.58,32.06],[2.74,13.53],[2.42,30.73]],"id":40041375},{"atb":[[1.18,0]],"id":43154430},{"atb":[[1.4,342.39],[1.48,76.05],[1.52,38.03]],"id":37076580},{"atl":[[2.22,132.53],[2.66,7.23]],"id":37076580}],"con":true,"img":false}]}
{"op":"mcm","clk":"5346713616","pt":1646094918059,"mc":[{"id":"1.195395448","rc":[{"atb":[[3.65,2.8],[3.75,36.36]],"id":40014837}],"con":true,"img":false}]}
{"op":"mcm","clk":"5346713619","pt":1646094918162,"mc":[{"id":"1.195395448","rc":[{"atb":[[3.5,84.27]],"id":40014837},{"atl":[[8.4,6.76]],"id":40014837},{"atb":[[3.5,31.81]],"id":37535509},{"atb":[[3.25,11.39]],"id":36899944},{"atb":[[1.27,0]],"id":42315317},{"atb":[[2.5,0]],"id":40041375},{"atb":[[1.43,46.51]],"id":37076580}],"con":true,"img":false}]}
{"op":"mcm","clk":"5346713622","pt":1646094918265,"mc":[{"id":"1.195395448","rc":[{"atb":[[3.75,0],[3.65,40.54]],"id":40014837}],"con":true,"img":false}]}
{"op":"mcm","clk":"5346713694","pt":1646094920574,"mc":[{"id":"1.195395448","rc":[{"atb":[[3.65,37.74]],"id":40014837},{"atb":[[3.5,28.84]],"id":37535509},{"atb":[[3.3,27.92]],"id":36899944},{"atb":[[2.48,0]],"id":40041375},{"atb":[[1.46,0]],"id":37076580}],"con":true,"img":false}]}
{"op":"mcm","clk":"5346713700","pt":1646094920676,"mc":[{"id":"1.195395448","rc":[{"atb":[[3.55,39.22],[3.65,0]],"id":40014837}],"con":true,"img":false}]}
{"op":"mcm","clk":"5346713882","pt":1646094925204,"mc":[{"id":"1.195395448","rc":[{"atb":[[3.45,0],[3.35,50.25]],"id":40014837},{"atl":[[8.4,25.59]],"id":38541023},{"atb":[[3.05,29.58],[3.4,17.26]],"id":37535509},{"atb":[[2.8,30.72],[3.1,3.97]],"id":36899944},{"atl":[[11.5,0]],"id":36899944},{"atb":[[1.21,106.8]],"id":42315317},{"atb":[[2.22,38.57]],"id":40041375},{"atb":[[1.13,147.93]],"id":43154430},{"atb":[[1.41,239.31],[1.38,73.25]],"id":37076580},{"atl":[[2.64,0]],"id":37076580}],"con":true,"img":false}]}
{"op":"mcm","clk":"5346713887","pt":1646094925306,"mc":[{"id":"1.195395448","rc":[{"atb":[[3.6,16.55],[3.4,20.83]],"id":40014837},{"atl":[[7,2]],"id":38541023},{"atb":[[3.45,30.66],[3.15,0]],"id":37535509},{"atb":[[3.2,21.34],[2.9,0]],"id":36899944},{"atl":[[10.5,6.33]],"id":36899944},{"atb":[[1.23,0]],"id":42315317},{"atb":[[2.32,0]],"id":40041375},{"atb":[[1.14,250]],"id":43154430},{"atb":[[1.41,121.95],[1.44,50.56]],"id":37076580},{"atl":[[3,22.28]],"id":37076580}],"con":true,"img":false}]}
{"op":"mcm","clk":"5346713893","pt":1646094925467,"mc":[{"id":"1.195395448","rc":[{"atb":[[3.55,0],[3.65,37.74]],"id":40014837},{"atb":[[3.2,72.74],[3.15,23.26]],"id":36899944}],"con":true,"img":false}]}
{"op":"mcm","clk":"5346713938","pt":1646094926595,"mc":[{"id":"1.195395448","rc":[{"atb":[[3.8,2.65]],"id":40014837}],"con":true,"img":false}]}
{"op":"mcm","clk":"5346713942","pt":1646094926697,"mc":[{"id":"1.195395448","rc":[{"atb":[[3.8,34.78],[3.65,0]],"id":40014837},{"atb":[[3.6,2.86]],"id":37535509},{"atb":[[3.4,3.1]],"id":36899944},{"atb":[[1.51,14.6]],"id":37076580}],"con":true,"img":false}]}
{"op":"mcm","clk":"5346713947","pt":1646094926799,"mc":[{"id":"1.195395448","rc":[{"atb":[[2.64,4.54]],"id":40041375}],"con":true,"img":false}]}
{"op":"mcm","clk":"5346714048","pt":1646094929680,"mc":[{"id":"1.195395448","rc":[{"atb":[[3.8,32.13]],"id":40014837}],"con":true,"img":false}]}
{"op":"mcm","clk":"5346714111","pt":1646094931278,"mc":[{"id":"1.195395448","rc":[{"atb":[[1.49,0]],"id":37076580}],"con":true,"img":false}]}
{"op":"mcm","clk":"5346714133","pt":1646094931793,"mc":[{"id":"1.195395448","rc":[{"atb":[[3.8,0],[3.65,37.74]],"id":40014837}],"con":true,"img":false}]}
{"op":"mcm","clk":"5346714259","pt":1646094935190,"mc":[{"id":"1.195395448","rc":[{"atb":[[3.6,86],[3.65,67.93]],"id":40014837},{"atl":[[19,12.15]],"id":40014837},{"atb":[[1.53,117.65]],"id":38541023},{"atb":[[3.6,32.41],[3.5,0]],"id":37535509},{"atl":[[18,13.08]],"id":37535509},{"atb":[[3.4,21.33]],"id":36899944},{"atl":[[17,15.18]],"id":36899944},{"atl":[[3.05,0],[3.45,63.74],[2.42,0]],"id":42315317},{"atb":[[2.64,26.6],[2.58,10]],"id":40041375},{"atl":[[12.5,22.68]],"id":40041375},{"atl":[[3,74.11]],"id":43154430},{"atl":[[4.2,46.38]],"id":37076580}],"con":true,"img":false}]}
{"op":"mcm","clk":"5346714263","pt":1646094935291,"mc":[{"id":"1.195395448","rc":[{"atb":[[3.5,16.34]],"id":40014837},{"atl":[[2.56,25.04]],"id":42315317}],"con":true,"img":false}]}
{"op":"mcm","clk":"5346714267","pt":1646094935396,"mc":[{"id":"1.195395448","rc":[{"atb":[[3.65,37.74]],"id":40014837},{"atb":[[3.3,0]],"id":36899944}],"con":true,"img":false}]}
{"op":"mcm","clk":"5346714278","pt":1646094935808,"mc":[{"id":"1.195395448","rc":[{"atb":[[3.6,29.55]],"id":37535509},{"atb":[[3.4,18.23]],"id":36899944},{"atb":[[2.64,22.06]],"id":40041375}],"con":true,"img":false}]}
{"op":"mcm","clk":"5346714282","pt":1646094936016,"mc":[{"id":"1.195395448","rc":[{"atb":[[3.4,0]],"id":36899944}],"con":true,"img":false}]}
{"op":"mcm","clk":"5346714288","pt":1646094936117,"mc":[{"id":"1.195395448","rc":[{"atb":[[3.25,34.75],[3.15,77.53]],"id":36899944},{"atb":[[1.49,41.83]],"id":37076580}],"con":true,"img":false}]}
{"op":"mcm","clk":"5346714291","pt":1646094936222,"mc":[{"id":"1.195395448","rc":[{"atb":[[3.2,21.34]],"id":36899944},{"atb":[[1.48,5],[1.49,168.13]],"id":37076580}],"con":true,"img":false}]}
{"op":"mcm","clk":"5346714363","pt":1646094938432,"mc":[{"id":"1.195395448","rc":[{"atl":[[8,10.96],[9.6,2.33],[8.8,11.16],[8.4,0]],"id":40014837},{"atb":[[1.92,21.74],[1.87,0]],"id":38541023},{"atb":[[3.6,59.1],[3.4,0]],"id":37535509},{"atl":[[9.6,0],[7.2,3.23],[6.8,8.44]],"id":37535509},{"atb":[[1.4,0],[1.36,0],[1.26,281.96],[1.32,0],[1.24,0]],"id":42315317},{"atl":[[1.84,87.33],[1.88,318.68],[1.77,25.97],[2.16,0]],"id":42315317},{"atl":[[7.2,3.23],[6.4,0],[6.8,8.62]],"id":40041375},{"atb":[[1.16,165.56],[1.17,0]],"id":43154430},{"atl":[[2.54,0],[2.86,53.76]],"id":43154430},{"atb":[[1.44,40.56],[1.48,0],[1.4,150.08],[1.31,322.58],[1.52,0]],"id":37076580},{"atl":[[2.22,153.02],[2.14,66.66],[2.24,16.13],[2.52,0],[2.18,0]],"id":37076580}],"con":true,"img":false}]}
{"op":"mcm","clk":"5346714369","pt":1646094938638,"mc":[{"id":"1.195395448","rc":[{"atb":[[3.8,2.65]],"id":40014837},{"atl":[[8,0],[8.8,1.54]],"id":40014837},{"atl":[[7.4,32.19],[11.5,9.52],[6.8,0],[7.8,11.03]],"id":37535509},{"atb":[[1.27,5],[1.25,442.1],[1.23,10],[1.33,66.83],[1.31,2.5]],"id":42315317},{"atl":[[1.88,198.87],[1.86,193.86],[1.77,89.05]],"id":42315317},{"atl":[[7.2,30.72],[6.8,0]],"id":40041375},{"atb":[[1.49,229.08],[1.51,0]],"id":37076580},{"atl":[[2.24,128.83],[2.22,81.97],[2.14,0]],"id":37076580}],"con":true,"img":false}]}
{"op":"mcm","clk":"5346714375","pt":1646094938793,"mc":[{"id":"1.195395448","rc":[{"atl":[[9.6,28.63],[8.8,7.38]],"id":40014837},{"atl":[[6.8,9.06]],"id":37535509},{"atl":[[1.84,0]],"id":42315317},{"atl":[[2.24,189.78]],"id":37076580}],"con":true,"img":false}]}
{"op":"mcm","clk":"5346714384","pt":1646094938996,"mc":[{"id":"1.195395448","rc":[{"atl":[[6.8,0]],"id":37535509}],"con":true,"img":false}]}
{"op":"mcm","clk":"5346714387","pt":1646094939099,"mc":[{"id":"1.195395448","rc":[{"atl":[[7.4,44.69]],"id":37535509}],"con":true,"img":false}]}
{"op":"mcm","clk":"5346714411","pt":1646094939825,"mc":[{"id":"1.195395448","rc":[{"atb":[[3.8,34.78],[3.65,0]],"id":40014837}],"con":true,"img":false}]}
{"op":"mcm","clk":"5346714460","pt":1646094940700,"mc":[{"id":"1.195395448","rc":[{"atl":[[9.6,2.33],[18,5.88],[9.2,0],[10,2.22],[15,0]],"id":40014837},{"atb":[[1.92,0],[1.58,150.98],[1.94,21.28]],"id":38541023},{"atl":[[7.2,0],[7.4,40]],"id":37535509},{"atb":[[1.23,143.66]],"id":42315317},{"atl":[[7,3.33]],"id":40041375}],"con":true,"img":false}]}
{"op":"mcm","clk":"5346714467","pt":1646094940802,"mc":[{"id":"1.195395448","rc":[{"atb":[[1.52,0]],"id":38541023},{"atb":[[1.26,117.48]],"id":42315317}],"con":true,"img":false}]}
{"op":"mcm","clk":"5346714474","pt":1646094940904,"mc":[{"id":"1.195395448","rc":[{"atl":[[9.6,0]],"id":40014837}],"con":true,"img":false}]}
{"op":"mcm","clk":"5346714479","pt":1646094941007,"mc":[{"id":"1.195395448","rc":[{"atl":[[13.5,5.88]],"id":40014837}],"con":true,"img":false}]}
{"op":"mcm","clk":"5346714539","pt":1646094942341,"mc":[{"id":"1.195395448","rc":[{"atb":[[1.92,21.74],[1.98,20.41],[1.94,0]],"id":38541023},{"atb":[[2.9,52.63],[2.84,0]],"id":36899944},{"atl":[[7.2,16.13],[7,42.29]],"id":36899944},{"atb":[[1.25,669.37],[1.26,40.56],[1.23,10],[1.24,83.33]],"id":42315317},{"atb":[[1.16,40.56],[1.17,117.65]],"id":43154430},{"atb":[[1.41,126.95],[1.45,2.5]],"id":37076580},{"atl":[[2.14,17.54]],"id":37076580}],"con":true,"img":false}]}
{"op":"mcm","clk":"5346714548","pt":1646094942548,"mc":[{"id":"1.195395448","rc":[{"atb":[[1.98,0]],"id":38541023}],"con":true,"img":false}]}
{"op":"mcm","clk":"5346714558","pt":1646094942705,"mc":[{"id":"1.195395448","rc":[{"atb":[[3.8,32.13]],"id":40014837},{"atb":[[3.7,2.75]],"id":37535509}],"con":true,"img":false}]}
{"op":"mcm","clk":"5346714564","pt":1646094942808,"mc":[{"id":"1.195395448","rc":[{"atb":[[2.48,5.03]],"id":40041375}],"con":true,"img":false}]}
{"op":"mcm","clk":"5346714572","pt":1646094942908,"mc":[{"id":"1.195395448","rc":[{"atb":[[3.8,0],[3.65,37.74]],"id":40014837}],"con":true,"img":false}]}
{"op":"mcm","clk":"5346714596","pt":1646094943525,"mc":[{"id":"1.195395448","rc":[{"atb":[[1.33,63.08]],"id":42315317},{"atb":[[1.49,187.25]],"id":37076580}],"con":true,"img":false}]}
{"op":"mcm","clk":"5346714602","pt":1646094943630,"mc":[{"id":"1.195395448","rc":[{"atl":[[2.32,75.76]],"id":37076580}],"con":true,"img":false}]}
{"op":"mcm","clk":"5346714603","pt":1646094943732,"mc":[{"id":"1.195395448","rc":[{"atb":[[1.33,0]],"id":42315317},{"atl":[[2.22,0]],"id":37076580}],"con":true,"img":false}]}
{"op":"mcm","clk":"5346714607","pt":1646094943835,"mc":[{"id":"1.195395448","rc":[{"atb":[[1.27,75.54]],"id":42315317}],"con":true,"img":false}]}
{"op":"mcm","clk":"5346714614","pt":1646094944245,"mc":[{"id":"1.195395448","rc":[{"atb":[[1.44,218.66]],"id":37076580}],"con":true,"img":false}]}
{"op":"mcm","clk":"5346714618","pt":1646094944349,"mc":[{"id":"1.195395448","rc":[{"atb":[[1.49,60.95]],"id":37076580}],"con":true,"img":false}]}
{"op":"mcm","clk":"5346714625","pt":1646094944505,"mc":[{"id":"1.195395448","rc":[{"atb":[[1.49,0]],"id":37076580}],"con":true,"img":false}]}
{"op":"mcm","clk":"5346714629","pt":1646094944607,"mc":[{"id":"1.195395448","rc":[{"atb":[[3.3,3.24]],"id":36899944},{"atb":[[1.44,306.22],[1.52,14.32]],"id":37076580}],"con":true,"img":false}]}
{"op":"mcm","clk":"5346714636","pt":1646094944709,"mc":[{"id":"1.195395448","rc":[{"atb":[[3.2,72.74],[3.15,23.26]],"id":36899944}],"con":true,"img":false}]}
{"op":"mcm","clk":"5346714651","pt":1646094945225,"mc":[{"id":"1.195395448","rc":[{"atl":[[19,2.7]],"id":40014837},{"atl":[[18,2.7],[12,1.09]],"id":37535509},{"atb":[[3.2,51.4]],"id":36899944},{"atl":[[17,2.7]],"id":36899944},{"atl":[[3.45,13.89]],"id":42315317},{"atl":[[12.5,3.13]],"id":40041375},{"atl":[[4.2,12.98]],"id":37076580}],"con":true,"img":false}]}
{"op":"mcm","clk":"5346714655","pt":1646094945328,"mc":[{"id":"1.195395448","rc":[{"atl":[[13,3.68]],"id":37535509},{"atb":[[3.25,56.09]],"id":36899944}],"con":true,"img":false}]}
{"op":"mcm","clk":"5346714659","pt":1646094945429,"mc":[{"id":"1.195395448","rc":[{"atl":[[3.9,0]],"id":38541023}],"con":true,"img":false}]}
{"op":"mcm","clk":"5346714663","pt":1646094945532,"mc":[{"id":"1.195395448","rc":[{"atl":[[3.7,13.52]],"id":38541023}],"con":true,"img":false}]}
{"op":"mcm","clk":"5346714666","pt":1646094945635,"mc":[{"id":"1.195395448","rc":[{"atl":[[3.75,7.27],[3.7,83.11]],"id":38541023}],"con":true,"img":false}]}
{"op":"mcm","clk":"5346714670","pt":1646094945738,"mc":[{"id":"1.195395448","rc":[{"atl":[[3.25,4]],"id":38541023},{"atl":[[1.59,4]],"id":42315317}],"con":true,"img":false}]}
{"op":"mcm","clk":"5346714674","pt":1646094945842,"mc":[{"id":"1.195395448","rc":[{"atl":[[3.25,0],[3.05,3]],"id":38541023},{"atl":[[1.58,2]],"id":42315317}],"con":true,"img":false}]}
{"op":"mcm","clk":"5346714680","pt":1646094946047,"mc":[{"id":"1.195395448","rc":[{"atl":[[3.05,0],[2.74,2]],"id":38541023},{"atl":[[1.59,0],[1.58,0],[1.52,4]],"id":42315317}],"con":true,"img":false}]}
{"op":"mcm","clk":"5346714696","pt":1646094946407,"mc":[{"id":"1.195395448","rc":[{"atl":[[2.86,0],[2.38,72.46]],"id":43154430}],"con":true,"img":false}]}
{"op":"mcm","clk":"5346714704","pt":1646094946614,"mc":[{"id":"1.195395448","rc":[{"atl":[[8.2,48.84],[7.4,15.62]],"id":37535509},{"atl":[[2.24,77.08],[2.26,213.44]],"id":37076580}],"con":true,"img":false}]}
{"op":"mcm","clk":"5346714741","pt":1646094947748,"mc":[{"id":"1.195395448","rc":[{"atb":[[1.52,0]],"id":37076580}],"con":true,"img":false}]}
{"op":"mcm","clk":"5346714747","pt":1646094947852,"mc":[{"id":"1.195395448","rc":[{"atl":[[1.52,0]],"id":42315317}],"con":true,"img":false}]}
{"op":"mcm","clk":"5346714753","pt":1646094947952,"mc":[{"id":"1.195395448","rc":[{"atl":[[10,0],[10.5,2.11]],"id":40014837},{"atl":[[2.72,4]],"id":38541023},{"atb":[[1.31,0],[1.35,628.77]],"id":37076580}],"con":true,"img":false}]}
{"op":"mcm","clk":"5346714760","pt":1646094948055,"mc":[{"id":"1.195395448","rc":[{"atl":[[1.88,336.73],[1.86,58.14]],"id":42315317}],"con":true,"img":false}]}
{"op":"mcm","clk":"5346714763","pt":1646094948108,"mc":[{"id":"1.195395448","rc":[{"atl":[[2.72,0],[2.88,2],[2.74,0],[3.7,13.52]],"id":38541023}],"con":true,"img":false}]}
{"op":"mcm","clk":"5346714773","pt":1646094948414,"mc":[{"id":"1.195395448","rc":[{"atb":[[1.28,2.75]],"id":42315317},{"atb":[[1.46,20.05]],"id":37076580}],"con":true,"img":false}]}
{"op":"mcm","clk":"5346714816","pt":1646094949545,"mc":[{"id":"1.195395448","rc":[{"atl":[[2.84,3],[2.88,0]],"id":38541023}],"con":true,"img":false}]}
{"op":"mcm","clk":"5346714856","pt":1646094950730,"mc":[{"id":"1.195395448","rc":[{"atb":[[3.8,2.65]],"id":40014837},{"atl":[[7.8,7.35]],"id":37535509},{"atl":[[7.4,7.81]],"id":40041375}],"con":true,"img":false}]}
{"op":"mcm","clk":"5346714861","pt":1646094950833,"mc":[{"id":"1.195395448","rc":[{"atb":[[3.8,34.78]],"id":40014837}],"con":true,"img":false}]}
{"op":"mcm","clk":"5346714865","pt":1646094950935,"mc":[{"id":"1.195395448","rc":[{"atb":[[3.65,0]],"id":40014837}],"con":true,"img":false}]}
{"op":"mcm","clk":"5346714905","pt":1646094952018,"mc":[{"id":"1.195395448","rc":[{"atb":[[3.85,7.12]],"id":40014837},{"atb":[[3.6,29.55],[3.65,39.46]],"id":37535509},{"atb":[[3.3,38.02]],"id":36899944}],"con":true,"img":false}]}
{"op":"mcm","clk":"5346714907","pt":1646094952121,"mc":[{"id":"1.195395448","rc":[{"atb":[[3.6,16.55],[3.7,53.88],[3.8,2.65],[3.9,32.13]],"id":40014837},{"atb":[[3.25,32.73]],"id":36899944}],"con":true,"img":false}]}
{"op":"mcm","clk":"5346714912","pt":1646094952223,"mc":[{"id":"1.195395448","rc":[{"atb":[[3.7,24.25],[3.8,38.36],[3.9,0]],"id":40014837}],"con":true,"img":false}]}
{"op":"mcm","clk":"5346714917","pt":1646094952325,"mc":[{"id":"1.195395448","rc":[{"atb":[[1.9,55.56]],"id":38541023},{"atl":[[1.79,63.29]],"id":42315317},{"atl":[[2.18,42.37]],"id":37076580}],"con":true,"img":false}]}
{"op":"mcm","clk":"5346714996","pt":1646094954446,"mc":[{"id":"1.195395448","rc":[{"atl":[[10,2.22]],"id":40014837},{"atb":[[1.8,0]],"id":38541023},{"atl":[[2.82,4]],"id":38541023}],"con":true,"img":false}]}
{"op":"mcm","clk":"5346714999","pt":1646094954549,"mc":[{"id":"1.195395448","rc":[{"atl":[[1.88,251.5],[1.9,0],[1.86,0]],"id":42315317}],"con":true,"img":false}]}
{"op":"mcm","clk":"5346715004","pt":1646094954651,"mc":[{"id":"1.195395448","rc":[{"atl":[[2.8,4]],"id":38541023}],"con":true,"img":false}]}
{"op":"mcm","clk":"5346715013","pt":1646094954858,"mc":[{"id":"1.195395448","rc":[{"atb":[[3.8,35.71]],"id":40014837},{"atb":[[3.7,0]],"id":37535509},{"atb":[[3.3,34.78]],"id":36899944},{"atb":[[1.47,15.85]],"id":37076580}],"con":true,"img":false}]}
{"op":"mcm","clk":"5346715018","pt":1646094954960,"mc":[{"id":"1.195395448","rc":[{"atb":[[3.7,61.29],[3.8,0]],"id":40014837},{"atb":[[1.44,128.12]],"id":37076580}],"con":true,"img":false}]}
{"op":"mcm","clk":"5346715022","pt":1646094955062,"mc":[{"id":"1.195395448","rc":[{"atb":[[1.45,58.9]],"id":37076580}],"con":true,"img":false}]}
{"op":"mcm","clk":"5346715026","pt":1646094955164,"mc":[{"id":"1.195395448","rc":[{"atb":[[3.85,0]],"id":40014837}],"con":true,"img":false}]}
{"op":"mcm","clk":"5346715029","pt":1646094955268,"mc":[{"id":"1.195395448","rc":[{"atb":[[3.6,0],[3.75,10.88]],"id":40014837},{"atl":[[3.7,0]],"id":38541023},{"atb":[[3.45,13.4]],"id":37535509},{"atl":[[2.56,0]],"id":42315317}],"con":true,"img":false}]}
{"op":"mcm","clk":"5346715033","pt":1646094955372,"mc":[{"id":"1.195395448","rc":[{"atb":[[3.75,27.43]],"id":40014837},{"atl":[[3.9,13.52]],"id":38541023},{"atb":[[3.65,56.71]],"id":37535509},{"atl":[[2.32,25.04]],"id":42315317}],"con":true,"img":false}]}
{"op":"mcm","clk":"5346715039","pt":1646094955424,"mc":[{"id":"1.195395448","rc":[{"atb":[[1.27,283.78],[1.25,467.41],[1.31,52.04]],"id":42315317},{"atb":[[1.47,62.67]],"id":37076580},{"atl":[[2.24,170.72],[2.26,99.21]],"id":37076580}],"con":true,"img":false}]}
{"op":"mcm","clk":"5346715045","pt":1646094955525,"mc":[{"id":"1.195395448","rc":[{"atl":[[10.5,27.3]],"id":40014837},{"atb":[[1.27,213.24]],"id":42315317},{"atb":[[1.44,40.56]],"id":37076580},{"atl":[[2.14,87.72]],"id":37076580}],"con":true,"img":false}]}
{"op":"mcm","clk":"5346715049","pt":1646094955730,"mc":[{"id":"1.195395448","rc":[{"atl":[[2.24,109.77]],"id":37076580}],"con":true,"img":false}]}
{"op":"mcm","clk":"5346715085","pt":1646094956753,"mc":[{"id":"1.195395448","rc":[{"atb":[[1.47,46.82]],"id":37076580}],"con":true,"img":false}]}
{"op":"mcm","clk":"5346715090","pt":1646094957063,"mc":[{"id":"1.195395448","rc":[{"atl":[[2.78,3]],"id":38541023}],"con":true,"img":false}]}
{"op":"mcm","clk":"5346715162","pt":1646094959432,"mc":[{"id":"1.195395448","rc":[{"atl":[[2.82,0],[2.84,0],[2.76,3]],"id":38541023}],"con":true,"img":false}]}
{"op":"mcm","clk":"5346715171","pt":1646094959637,"mc":[{"id":"1.195395448","rc":[{"atl":[[2.8,0],[2.74,3],[2.78,0]],"id":38541023}],"con":true,"img":false}]}
{"op":"mcm","clk":"5346715181","pt":1646094959841,"mc":[{"id":"1.195395448","rc":[{"atb":[[3.6,99.25]],"id":37535509}],"con":true,"img":false}]}
{"op":"mcm","clk":"5346715185","pt":1646094959944,"mc":[{"id":"1.195395448","rc":[{"atb":[[3.5,81.8]],"id":40014837},{"atb":[[3.65,22.25]],"id":37535509}],"con":true,"img":false}]}
{"op":"mcm","clk":"5346715189","pt":1646094960049,"mc":[{"id":"1.195395448","rc":[{"atb":[[3.7,39.54]],"id":40014837}],"con":true,"img":false}]}
{"op":"mcm","clk":"5346715216","pt":1646094960767,"mc":[{"id":"1.195395448","rc":[{"atl":[[8.2,41.9]],"id":37535509},{"atl":[[7.8,11.03]],"id":40041375}],"con":true,"img":false}]}
{"op":"mcm","clk":"5346715267","pt":1646094962255,"mc":[{"id":"1.195395448","rc":[{"atl":[[2.76,97.89]],"id":38541023}],"con":true,"img":false}]}
{"op":"mcm","clk":"5346715272","pt":1646094962359,"mc":[{"id":"1.195395448","rc":[{"atb":[[1.88,85.23]],"id":38541023},{"atl":[[2.72,2]],"id":38541023},{"atb":[[1.25,240.14],[1.26,144.64]],"id":42315317},{"atl":[[1.81,92.59]],"id":42315317},{"atl":[[7.2,27.49],[7.6,1.81]],"id":40041375},{"atl":[[2.22,61.48]],"id":37076580}],"con":true,"img":false}]}
{"op":"mcm","clk":"5346715277","pt":1646094962461,"mc":[{"id":"1.195395448","rc":[{"atl":[[1.81,241.5]],"id":42315317}],"con":true,"img":false}]}
{"op":"mcm","clk":"5346715280","pt":1646094962564,"mc":[{"id":"1.195395448","rc":[{"atb":[[1.82,0]],"id":38541023},{"atl":[[2.76,94.89],[2.7,4]],"id":38541023},{"atl":[[1.88,113.63]],"id":42315317},{"atl":[[2.24,93.64]],"id":37076580}],"con":true,"img":false}]}
{"op":"mcm","clk":"5346715285","pt":1646094962667,"mc":[{"id":"1.195395448","rc":[{"atb":[[3.75,2.71]],"id":37535509},{"atb":[[3.4,3.1]],"id":36899944},{"atb":[[1.48,15.51]],"id":37076580}],"con":true,"img":false}]}
{"op":"mcm","clk":"5346715288","pt":1646094962771,"mc":[{"id":"1.195395448","rc":[{"atb":[[3.7,2.5],[3.8,35.71]],"id":40014837},{"atb":[[3.2,0],[3.4,36.43],[3.25,101.22]],"id":36899944},{"atb":[[1.46,153.83],[1.45,2.5],[1.48,82.4]],"id":37076580}],"con":true,"img":false}]}
{"op":"mcm","clk":"5346715295","pt":1646094962874,"mc":[{"id":"1.195395448","rc":[{"atb":[[3.3,0]],"id":36899944},{"atb":[[1.47,0]],"id":37076580}],"con":true,"img":false}]}
{"op":"mcm","clk":"5346715311","pt":1646094963234,"mc":[{"id":"1.195395448","rc":[{"atl":[[2.22,183.13]],"id":37076580}],"con":true,"img":false}]}
{"op":"mcm","clk":"5346715316","pt":1646094963388,"mc":[{"id":"1.195395448","rc":[{"atl":[[2.24,0]],"id":37076580}],"con":true,"img":false}]}
{"op":"mcm","clk":"5346715347","pt":1646094964372,"mc":[{"id":"1.195395448","rc":[{"atb":[[1.92,0],[1.58,0],[1.96,20.83]],"id":38541023},{"atl":[[2.72,0],[2.74,0],[2.68,2],[2.7,0]],"id":38541023},{"atb":[[1.2,600.35],[1.18,0],[1.26,40.56],[1.16,125],[1.22,0],[1.24,0]],"id":42315317},{"atb":[[2,20],[1.89,60.61],[1.26,0]],"id":40041375},{"atl":[[2.54,77.93],[2.32,0],[2.38,0]],"id":43154430},{"atl":[[2.54,77.93],[2.32,0],[2.22,121.65],[2.26,0],[2.14,70.18],[2.18,0]],"id":37076580}],"con":true,"img":false}]}
{"op":"mcm","clk":"5346715351","pt":1646094964474,"mc":[{"id":"1.195395448","rc":[{"atl":[[11,5]],"id":40014837},{"atl":[[2.36,142.48],[2.34,34.97]],"id":43154430},{"atl":[[2.14,0]],"id":37076580}],"con":true,"img":false}]}
{"op":"mcm","clk":"5346715356","pt":1646094964577,"mc":[{"id":"1.195395448","rc":[{"atb":[[1.96,0],[1.94,21.28]],"id":38541023},{"atl":[[2.76,0],[2.68,0]],"id":38541023},{"atb":[[2.9,0],[2.66,60.24]],"id":36899944},{"atl":[[7.4,27.34],[7.2,0]],"id":36899944},{"atb":[[1.08,231.8]],"id":42315317},{"atl":[[1.84,119.05],[1.88,0]],"id":42315317},{"atl":[[2.36,105.72],[2.54,12.99]],"id":43154430},{"atb":[[1.28,277.04],[1.45,0],[1.35,343.06],[1.41,121.95]],"id":37076580},{"atl":[[2.22,187.22]],"id":37076580}],"con":true,"img":false}]}
{"op":"mcm","clk":"5346715359","pt":1646094964678,"mc":[{"id":"1.195395448","rc":[{"atl":[[2.86,53.76]],"id":43154430}],"con":true,"img":false}]}
{"op":"mcm","clk":"5346715367","pt":1646094964883,"mc":[{"id":"1.195395448","rc":[{"atl":[[2.4,0]],"id":43154430}],"con":true,"img":false}]}
{"op":"mcm","clk":"5346715379","pt":1646094965140,"mc":[{"id":"1.195395448","rc":[{"atl":[[19,12.15]],"id":40014837},{"atb":[[3.05,0]],"id":37535509},{"atl":[[18,13.08],[13,0]],"id":37535509},{"atl":[[17,15.18]],"id":36899944},{"atl":[[12.5,23.06]],"id":40041375},{"atl":[[4.2,46.38]],"id":37076580}],"con":true,"img":false}]}
{"op":"mcm","clk":"5346715383","pt":1646094965242,"mc":[{"id":"1.195395448","rc":[{"atb":[[3.15,29.58]],"id":37535509},{"atl":[[12.5,3.68]],"id":37535509}],"con":true,"img":false}]}
{"op":"mcm","clk":"5346715399","pt":1646094965756,"mc":[{"id":"1.195395448","rc":[{"atb":[[3.4,33.33]],"id":36899944},{"atb":[[1.48,66.89]],"id":37076580}],"con":true,"img":false}]}
{"op":"mcm","clk":"5346715405","pt":1646094965961,"mc":[{"id":"1.195395448","rc":[{"atb":[[3.4,0]],"id":36899944},{"atb":[[1.48,0]],"id":37076580}],"con":true,"img":false}]}
{"op":"mcm","clk":"5346715410","pt":1646094966063,"mc":[{"id":"1.195395448","rc":[{"atb":[[3.25,128.36]],"id":36899944},{"atb":[[1.46,241.2]],"id":37076580}],"con":true,"img":false}]}
{"op":"mcm","clk":"5346715423","pt":1646094966473,"mc":[{"id":"1.195395448","rc":[{"atb":[[3.6,5],[3.7,0],[3.8,38.21],[3.5,76.8]],"id":40014837},{"atb":[[3.7,5],[3.9,2.5]],"id":37535509},{"atb":[[2.6,10],[2.58,0],[2.76,2.5],[2.74,11.03],[2.66,0],[2.68,5]],"id":40041375}],"con":true,"img":false}]}
{"op":"mcm","clk":"5346715426","pt":1646094966576,"mc":[{"id":"1.195395448","rc":[{"atb":[[3.85,14.42],[3.45,3.4],[3.9,19.73],[3.65,17.25]],"id":37535509},{"atb":[[2.76,12.28],[2.68,27.06]],"id":40041375}],"con":true,"img":false}]}
{"op":"mcm","clk":"5346715433","pt":1646094966679,"mc":[{"id":"1.195395448","rc":[{"atb":[[3.85,0]],"id":37535509},{"atb":[[2.64,0],[2.74,0]],"id":40041375}],"con":true,"img":false}]}
{"op":"mcm","clk":"5346715445","pt":1646094967191,"mc":[{"id":"1.195395448","rc":[{"atb":[[3.4,8.33],[3.5,68.8]],"id":40014837}],"con":true,"img":false}]}
{"op":"mcm","clk":"5346715448","pt":1646094967294,"mc":[{"id":"1.195395448","rc":[{"atl":[[2.44,0]],"id":43154430}],"con":true,"img":false}]}
{"op":"mcm","clk":"5346715483","pt":1646094968168,"mc":[{"id":"1.195395448","rc":[{"atb":[[1.25,30.22]],"id":43154430},{"atb":[[1.46,221.15]],"id":37076580}],"con":true,"img":false}]}
{"op":"mcm","clk":"5346715494","pt":1646094968475,"mc":[{"id":"1.195395448","rc":[{"atb":[[3.85,26.01]],"id":40014837},{"atb":[[3.6,29.55]],"id":37535509}],"con":true,"img":false}]}
{"op":"mcm","clk":"5346715498","pt":1646094968578,"mc":[{"id":"1.195395448","rc":[{"atb":[[3.7,39.46]],"id":37535509}],"con":true,"img":false}]}
{"op":"mcm","clk":"5346715503","pt":1646094968682,"mc":[{"id":"1.195395448","rc":[{"atb":[[3.5,3.34],[3.75,89.59]],"id":40014837},{"atb":[[3.75,0]],"id":37535509},{"atb":[[2.48,0]],"id":40041375}],"con":true,"img":false}]}
{"op":"mcm","clk":"5346715507","pt":1646094968785,"mc":[{"id":"1.195395448","rc":[{"atb":[[3.8,2.5],[3.75,125.95]],"id":40014837}],"con":true,"img":false}]}
{"op":"mcm","clk":"5346715541","pt":1646094969603,"mc":[{"id":"1.195395448","rc":[{"atb":[[1.98,20.41],[1.94,0]],"id":38541023},{"atb":[[2.9,52.63],[3.35,2.5],[2.66,0],[3.25,125.86],[3.15,28.26]],"id":36899944},{"atl":[[7.4,11.72],[7.2,16.13]],"id":36899944},{"atb":[[1.28,7.75],[1.27,208.24],[1.23,0],[1.32,2.5],[1.31,49.54]],"id":42315317},{"atl":[[1.92,108.7],[1.84,0]],"id":42315317},{"atb":[[1.41,126.95],[1.28,0],[1.45,2.5],[1.35,628.77]],"id":37076580}],"con":true,"img":false}]}
{"op":"mcm","clk":"5346715552","pt":1646094969758,"mc":[{"id":"1.195395448","rc":[{"atb":[[3.35,33.38]],"id":36899944},{"atb":[[1.32,87.12]],"id":42315317},{"atb":[[1.28,5],[1.23,0],[1.27,0],[1.32,2.5],[1.31,15.11],[1.24,135.62]],"id":43154430}],"con":true,"img":false}]}
{"op":"mcm","clk":"5346715556","pt":1646094969861,"mc":[{"id":"1.195395448","rc":[{"atb":[[1.28,80.12],[1.25,0],[1.32,40.06]],"id":43154430}],"con":true,"img":false}]}
{"op":"mcm","clk":"5346715563","pt":1646094969962,"mc":[{"id":"1.195395448","rc":[{"atb":[[3.25,98.72]],"id":36899944},{"atb":[[1.31,0]],"id":42315317}],"con":true,"img":false}]}
{"op":"mcm","clk":"5346715567","pt":1646094970064,"mc":[{"id":"1.195395448","rc":[{"atb":[[1.31,0]],"id":43154430}],"con":true,"img":false}]}
{"op":"mcm","clk":"5346715587","pt":1646094970475,"mc":[{"id":"1.195395448","rc":[{"atb":[[3.25,30.23],[3.15,115.63]],"id":36899944},{"atb":[[1.46,87.37],[1.44,218.3]],"id":37076580}],"con":true,"img":false}]}
{"op":"mcm","clk":"5346715590","pt":1646094970577,"mc":[{"id":"1.195395448","rc":[{"atl":[[2.82,3]],"id":38541023}],"con":true,"img":false}]}
{"op":"mcm","clk":"5346715594","pt":1646094970679,"mc":[{"id":"1.195395448","rc":[{"atl":[[8.6,16.45]],"id":37535509}],"con":true,"img":false}]}
{"op":"mcm","clk":"5346715598","pt":1646094970781,"mc":[{"id":"1.195395448","rc":[{"atl":[[2.82,0],[2.8,2]],"id":38541023}],"con":true,"img":false}]}
{"op":"mcm","clk":"5346715609","pt":1646094970987,"mc":[{"id":"1.195395448","rc":[{"atl":[[2.66,110.83]],"id":37076580}],"con":true,"img":false}]}
{"op":"mcm","clk":"5346715614","pt":1646094971089,"mc":[{"id":"1.195395448","rc":[{"atl":[[2.54,12.99],[2.22,65.57],[2.66,171.07]],"id":37076580}],"con":true,"img":false}]}
{"op":"mcm","clk":"5346715622","pt":1646094971295,"mc":[{"id":"1.195395448","rc":[{"atl":[[2.22,0]],"id":37076580}],"con":true,"img":false}]}
{"op":"mcm","clk":"5346715628","pt":1646094971400,"mc":[{"id":"1.195395448","rc":[{"atl":[[2.52,52.63]],"id":37076580}],"con":true,"img":false}]}
{"op":"mcm","clk":"5346715636","pt":1646094971604,"mc":[{"id":"1.195395448","rc":[{"atl":[[2.8,0],[2.66,4]],"id":38541023}],"con":true,"img":false}]}
{"op":"mcm","clk":"5346715661","pt":1646094972375,"mc":[{"id":"1.195395448","rc":[{"atl":[[2.54,77.93],[2.86,0]],"id":43154430}],"con":true,"img":false}]}
{"op":"mcm","clk":"5346715671","pt":1646094972686,"mc":[{"id":"1.195395448","rc":[{"atl":[[2.66,0],[2.78,3]],"id":38541023}],"con":true,"img":false}]}
{"op":"mcm","clk":"5346715677","pt":1646094972890,"mc":[{"id":"1.195395448","rc":[{"atl":[[2.76,2],[2.78,0]],"id":38541023}],"con":true,"img":false}]}
{"op":"mcm","clk":"5346715686","pt":1646094973199,"mc":[{"id":"1.195395448","rc":[{"atb":[[1.25,60.08]],"id":43154430},{"atb":[[1.47,48.11]],"id":37076580}],"con":true,"img":false}]}
{"op":"mcm","clk":"5346715689","pt":1646094973303,"mc":[{"id":"1.195395448","rc":[{"atb":[[1.45,153.61],[1.47,123.67]],"id":37076580}],"con":true,"img":false}]}
{"op":"mcm","clk":"5346715693","pt":1646094973405,"mc":[{"id":"1.195395448","rc":[{"atb":[[1.44,40.56]],"id":37076580}],"con":true,"img":false}]}
{"op":"mcm","clk":"5346715698","pt":1646094973510,"mc":[{"id":"1.195395448","rc":[{"atb":[[1.46,0]],"id":37076580}],"con":true,"img":false}]}
{"op":"mcm","clk":"5346715723","pt":1646094974184,"mc":[{"id":"1.195395448","rc":[{"atb":[[2.6,43.42]],"id":40041375}],"con":true,"img":false}]}
{"op":"mcm","clk":"5346715728","pt":1646094974287,"mc":[{"id":"1.195395448","rc":[{"atb":[[2.68,5]],"id":40041375}],"con":true,"img":false}]}
{"op":"mcm","clk":"5346715734","pt":1646094974389,"mc":[{"id":"1.195395448","rc":[{"atb":[[1.14,250]],"id":42315317},{"atl":[[1.83,150.6]],"id":42315317},{"atb":[[1.98,51.02]],"id":40041375},{"atl":[[8.2,17.36]],"id":40041375},{"atl":[[2.58,31.65]],"id":43154430},{"atl":[[2.58,31.65]],"id":37076580}],"con":true,"img":false}]}
{"op":"mcm","clk":"5346715738","pt":1646094974491,"mc":[{"id":"1.195395448","rc":[{"atl":[[2.56,64.1],[2.66,7.23],[2.58,139.45]],"id":37076580}],"con":true,"img":false}]}
{"op":"mcm","clk":"5346715742","pt":1646094974594,"mc":[{"id":"1.195395448","rc":[{"atl":[[2.56,0],[2.58,202.74]],"id":37076580}],"con":true,"img":false}]}
{"op":"mcm","clk":"5346715766","pt":1646094975261,"mc":[{"id":"1.195395448","rc":[{"atb":[[3.25,8.89]],"id":36899944}],"con":true,"img":false}]}
{"op":"mcm","clk":"5346715770","pt":1646094975362,"mc":[{"id":"1.195395448","rc":[{"atb":[[3.2,21.34]],"id":36899944}],"con":true,"img":false}]}
{"op":"mcm","clk":"5346715796","pt":1646094976183,"mc":[{"id":"1.195395448","rc":[{"atb":[[1.98,0],[1.96,20.83]],"id":38541023},{"atl":[[2.76,0],[2.74,2]],"id":38541023},{"atb":[[3.7,5],[3.65,72.73]],"id":37535509},{"atb":[[1.33,0],[1.31,0]],"id":40041375}],"con":true,"img":false}]}
{"op":"mcm","clk":"5346715806","pt":1646094976493,"mc":[{"id":"1.195395448","rc":[{"atl":[[2.74,0]],"id":38541023}],"con":true,"img":false}]}
{"op":"mcm","clk":"5346715830","pt":1646094977110,"mc":[{"id":"1.195395448","rc":[{"atb":[[3.3,21.74]],"id":40014837},{"atl":[[12,7.91]],"id":40014837}],"con":true,"img":false}]}
{"op":"mcm","clk":"5346715845","pt":1646094977470,"mc":[{"id":"1.195395448","rc":[{"atb":[[1.25,249.94]],"id":43154430}],"con":true,"img":false}]}
{"op":"mcm","clk":"5346715850","pt":1646094977573,"mc":[{"id":"1.195395448","rc":[{"atb":[[1.28,5]],"id":43154430}],"con":true,"img":false}]}
{"op":"mcm","clk":"5346715858","pt":1646094977777,"mc":[{"id":"1.195395448","rc":[{"atb":[[3.45,3.03]],"id":36899944}],"con":true,"img":false}]}
{"op":"mcm","clk":"5346715869","pt":1646094978084,"mc":[{"id":"1.195395448","rc":[{"atb":[[1.44,235.48],[1.45,2.5]],"id":37076580}],"con":true,"img":false}]}
{"op":"mcm","clk":"5346715882","pt":1646094978495,"mc":[{"id":"1.195395448","rc":[{"atl":[[3.75,82.2]],"id":38541023}],"con":true,"img":false}]}
{"op":"mcm","clk":"5346715898","pt":1646094979109,"mc":[{"id":"1.195395448","rc":[{"atb":[[3.45,19.39],[3.25,41.61]],"id":36899944}],"con":true,"img":false}]}
{"op":"mcm","clk":"5346715903","pt":1646094979212,"mc":[{"id":"1.195395448","rc":[{"atb":[[3.15,28.26]],"id":36899944}],"con":true,"img":false}]}
{"op":"mcm","clk":"5346715905","pt":1646094979317,"mc":[{"id":"1.195395448","rc":[{"atl":[[10,0]],"id":40014837},{"atb":[[3.35,2.5]],"id":36899944}],"con":true,"img":false}]}
{"op":"mcm","clk":"5346715913","pt":1646094979522,"mc":[{"id":"1.195395448","rc":[{"atl":[[10,2.22],[10.5,2.11],[11,30.6]],"id":40014837}],"con":true,"img":false}]}
{"op":"mcm","clk":"5346715955","pt":1646094980679,"mc":[{"id":"1.195395448","rc":[{"atb":[[2.66,4.48]],"id":40041375},{"atb":[[1.5,14.89]],"id":37076580}],"con":true,"img":false}]}
{"op":"mcm","clk":"5346715959","pt":1646094980782,"mc":[{"id":"1.195395448","rc":[{"atb":[[3.45,16.36]],"id":36899944},{"atb":[[1.44,40.56],[1.45,103.8],[1.5,65.54]],"id":37076580}],"con":true,"img":false}]}
{"op":"mcm","clk":"5346715963","pt":1646094980886,"mc":[{"id":"1.195395448","rc":[{"atb":[[3.45,0]],"id":36899944}],"con":true,"img":false}]}
{"op":"mcm","clk":"5346715969","pt":1646094980988,"mc":[{"id":"1.195395448","rc":[{"atb":[[1.47,48.11]],"id":37076580}],"con":true,"img":false}]}
{"op":"mcm","clk":"5346715973","pt":1646094981090,"mc":[{"id":"1.195395448","rc":[{"atb":[[3.25,53.98]],"id":36899944}],"con":true,"img":false}]}
{"op":"mcm","clk":"5346715978","pt":1646094981192,"mc":[{"id":"1.195395448","rc":[{"atb":[[3.35,25.54],[3.75,109.4]],"id":40014837},{"atl":[[3.45,0],[3.1,70.85]],"id":42315317},{"atb":[[1.44,0]],"id":37076580}],"con":true,"img":false}]}
{"op":"mcm","clk":"5346715982","pt":1646094981295,"mc":[{"id":"1.195395448","rc":[{"atb":[[3.25,24.71],[3.9,16.55]],"id":40014837},{"atl":[[3.7,7.41]],"id":38541023},{"atb":[[3.3,0],[3.4,8.33]],"id":37535509},{"atl":[[1.77,63.08],[1.76,26.32]],"id":42315317},{"atb":[[1.43,0],[1.48,40.56],[1.47,90.66]],"id":37076580}],"con":true,"img":false}]}
{"op":"mcm","clk":"5346715987","pt":1646094981399,"mc":[{"id":"1.195395448","rc":[{"atb":[[3.8,17.32],[3.75,0],[3.95,23.97]],"id":40014837},{"atl":[[3.75,74.93]],"id":38541023},{"atl":[[1.79,221.43],[1.81,92.59],[1.76,121.1]],"id":42315317}],"con":true,"img":false}]}
{"op":"mcm","clk":"5346715996","pt":1646094981606,"mc":[{"id":"1.195395448","rc":[{"atb":[[3.85,0]],"id":40014837},{"atb":[[1.98,20.41],[1.96,0]],"id":38541023},{"atl":[[3.2,2]],"id":38541023},{"atl":[[1.77,0]],"id":42315317}],"con":true,"img":false}]}
{"op":"mcm","clk":"5346716005","pt":1646094981810,"mc":[{"id":"1.195395448","rc":[{"atl":[[2.82,2],[3.2,0]],"id":38541023}],"con":true,"img":false}]}
{"op":"mcm","clk":"5346716016","pt":1646094982017,"mc":[{"id":"1.195395448","rc":[{"atl":[[2.8,2]],"id":38541023}],"con":true,"img":false}]}
{"op":"mcm","clk":"5346716027","pt":1646094982223,"mc":[{"id":"1.195395448","rc":[{"atl":[[2.8,0],[2.82,0],[2.78,3]],"id":38541023}],"con":true,"img":false}]}
{"op":"mcm","clk":"5346716032","pt":1646094982326,"mc":[{"id":"1.195395448","rc":[{"atb":[[3.35,28.2]],"id":36899944}],"con":true,"img":false}]}
{"op":"mcm","clk":"5346716041","pt":1646094982532,"mc":[{"id":"1.195395448","rc":[{"atb":[[3.25,41.61]],"id":36899944}],"con":true,"img":false}]}
{"op":"mcm","clk":"5346716052","pt":1646094982788,"mc":[{"id":"1.195395448","rc":[{"atb":[[2.66,26.54]],"id":40041375}],"con":true,"img":false}]}
{"op":"mcm","clk":"5346716055","pt":1646094982890,"mc":[{"id":"1.195395448","rc":[{"atb":[[2.6,10]],"id":40041375}],"con":true,"img":false}]}
{"op":"mcm","clk":"5346716075","pt":1646094983814,"mc":[{"id":"1.195395448","rc":[{"atb":[[2.66,22.06]],"id":40041375},{"atb":[[1.5,50.65]],"id":37076580}],"con":true,"img":false}]}
{"op":"mcm","clk":"5346716081","pt":1646094984018,"mc":[{"id":"1.195395448","rc":[{"atb":[[1.5,0]],"id":37076580}],"con":true,"img":false}]}
{"op":"mcm","clk":"5346716084","pt":1646094984121,"mc":[{"id":"1.195395448","rc":[{"atb":[[1.48,118.02]],"id":37076580}],"con":true,"img":false}]}
{"op":"mcm","clk":"5346716093","pt":1646094984430,"mc":[{"id":"1.195395448","rc":[{"atb":[[1.96,78.12]],"id":40041375},{"atl":[[2.62,61.12]],"id":43154430}],"con":true,"img":false}]}
{"op":"mcm","clk":"5346716146","pt":1646094986125,"mc":[{"id":"1.195395448","rc":[{"atl":[[2.76,3]],"id":38541023},{"atb":[[1.47,42.55]],"id":37076580}],"con":true,"img":false}]}
{"op":"mcm","clk":"5346716154","pt":1646094986330,"mc":[{"id":"1.195395448","rc":[{"atl":[[2.74,2]],"id":38541023}],"con":true,"img":false}]}
{"op":"mcm","clk":"5346716164","pt":1646094986639,"mc":[{"id":"1.195395448","rc":[{"atb":[[3.2,95.66]],"id":36899944}],"con":true,"img":false}]}
{"op":"mcm","clk":"5346716171","pt":1646094986741,"mc":[{"id":"1.195395448","rc":[{"atb":[[3.25,8.89]],"id":36899944}],"con":true,"img":false}]}
{"op":"mcm","clk":"5346716176","pt":1646094986843,"mc":[{"id":"1.195395448","rc":[{"atb":[[1.98,0],[1.96,20.83]],"id":38541023},{"atl":[[2.72,3],[2.76,0],[2.74,0],[2.78,0]],"id":38541023}],"con":true,"img":false}]}
{"op":"mcm","clk":"5346716184","pt":1646094987000,"mc":[{"id":"1.195395448","rc":[{"atl":[[2.72,0]],"id":38541023}],"con":true,"img":false}]}
{"op":"mcm","clk":"5346716250","pt":1646094988641,"mc":[{"id":"1.195395448","rc":[{"atb":[[3.25,0]],"id":40014837}],"con":true,"img":false}]}
{"op":"mcm","clk":"5346716256","pt":1646094988743,"mc":[{"id":"1.195395448","rc":[{"atb":[[3.15,24.71]],"id":40014837}],"con":true,"img":false}]}
{"op":"mcm","clk":"5346716260","pt":1646094988899,"mc":[{"id":"1.195395448","rc":[{"atl":[[1.81,251.96]],"id":42315317}],"con":true,"img":false}]}
{"op":"mcm","clk":"5346716263","pt":1646094989011,"mc":[{"id":"1.195395448","rc":[{"atl":[[1.79,63.29]],"id":42315317}],"con":true,"img":false}]}
{"op":"mcm","clk":"5346716283","pt":1646094989517,"mc":[{"id":"1.195395448","rc":[{"atb":[[3.2,34.09]],"id":40014837},{"atl":[[13,10.42]],"id":40014837}],"con":true,"img":false}]}
{"op":"mcm","clk":"5346716294","pt":1646094989827,"mc":[{"id":"1.195395448","rc":[{"atb":[[3.45,3.03]],"id":36899944},{"atb":[[2.48,5.03]],"id":40041375}],"con":true,"img":false}]}
{"op":"mcm","clk":"5346716298","pt":1646094989932,"mc":[{"id":"1.195395448","rc":[{"atb":[[3.45,19.39]],"id":36899944}],"con":true,"img":false}]}
{"op":"mcm","clk":"5346716307","pt":1646094990140,"mc":[{"id":"1.195395448","rc":[{"atb":[[3.35,2.5]],"id":36899944}],"con":true,"img":false}]}
{"op":"mcm","clk":"5346716343","pt":1646094991116,"mc":[{"id":"1.195395448","rc":[{"atb":[[3.9,0]],"id":40014837},{"atb":[[1.49,46.14]],"id":37076580}],"con":true,"img":false}]}
{"op":"mcm","clk":"5346716347","pt":1646094991217,"mc":[{"id":"1.195395448","rc":[{"atb":[[3.6,23.57],[3.45,16.55],[3.95,7.41],[3.8,2.5]],"id":40014837},{"atb":[[3.3,21.74]],"id":37535509},{"atb":[[1.45,113.61],[1.49,120.22],[1.47,190.71]],"id":37076580},{"atl":[[2.62,46.3]],"id":37076580}],"con":true,"img":false}]}
{"op":"mcm","clk":"5346716350","pt":1646094991320,"mc":[{"id":"1.195395448","rc":[{"atb":[[3.6,62.03]],"id":40014837},{"atb":[[1.12,250]],"id":42315317}],"con":true,"img":false}]}
{"op":"mcm","clk":"5346716355","pt":1646094991423,"mc":[{"id":"1.195395448","rc":[{"atb":[[3.95,0]],"id":40014837},{"atb":[[1.48,40.56]],"id":37076580}],"con":true,"img":false}]}
{"op":"mcm","clk":"5346716359","pt":1646094991524,"mc":[{"id":"1.195395448","rc":[{"atb":[[3.85,7.41]],"id":40014837}],"con":true,"img":false}]}
{"op":"mcm","clk":"5346716375","pt":1646094992141,"mc":[{"id":"1.195395448","rc":[{"atl":[[10,0],[11,25.6],[12,1.09],[13,0],[9.8,2.27]],"id":40014837},{"atb":[[1.96,0],[1.94,21.28]],"id":38541023},{"atb":[[3,0]],"id":37535509},{"atb":[[2.9,0],[2.66,60.24]],"id":36899944},{"atl":[[1.92,0],[1.84,119.05]],"id":42315317},{"atl":[[2.54,12.99],[2.86,53.76]],"id":43154430},{"atb":[[1.41,121.95],[1.28,300.18],[1.45,111.11],[1.37,0],[1.35,343.06]],"id":37076580}],"con":true,"img":false}]}
{"op":"mcm","clk":"5346716408","pt":1646094993140,"mc":[{"id":"1.195395448","rc":[{"atb":[[3.45,16.36]],"id":36899944},{"atb":[[1.38,0]],"id":37076580}],"con":true,"img":false}]}
{"op":"mcm","clk":"5346716412","pt":1646094993218,"mc":[{"id":"1.195395448","rc":[{"atb":[[1.36,73.25]],"id":37076580}],"con":true,"img":false}]}
{"op":"mcm","clk":"5346716421","pt":1646094993428,"mc":[{"id":"1.195395448","rc":[{"atb":[[3.45,0]],"id":36899944}],"con":true,"img":false}]}
{"op":"mcm","clk":"5346716424","pt":1646094993529,"mc":[{"id":"1.195395448","rc":[{"atb":[[3.35,18.86]],"id":36899944}],"con":true,"img":false}]}
{"op":"mcm","clk":"5346716462","pt":1646094994454,"mc":[{"id":"1.195395448","rc":[{"atl":[[3.7,86.42]],"id":38541023},{"atb":[[3.45,0]],"id":37535509},{"atb":[[1.94,132.98]],"id":40041375},{"atl":[[2.66,75.3]],"id":43154430}],"con":true,"img":false}]}
{"op":"mcm","clk":"5346716467","pt":1646094994554,"mc":[{"id":"1.195395448","rc":[{"atl":[[3.75,0]],"id":38541023}],"con":true,"img":false}]}
{"op":"mcm","clk":"5346716470","pt":1646094994656,"mc":[{"id":"1.195395448","rc":[{"atb":[[1.36,0]],"id":40041375}],"con":true,"img":false}]}
{"op":"mcm","clk":"5346716500","pt":1646094995530,"mc":[{"id":"1.195395448","rc":[{"atl":[[10.5,16.93],[11,0]],"id":40014837}],"con":true,"img":false}]}
{"op":"mcm","clk":"5346716508","pt":1646094995737,"mc":[{"id":"1.195395448","rc":[{"atl":[[7.4,27.34],[7.2,0]],"id":36899944}],"con":true,"img":false}]}
{"op":"mcm","clk":"5346716515","pt":1646094995945,"mc":[{"id":"1.195395448","rc":[{"atl":[[7.4,11.72],[7.2,16.13]],"id":36899944}],"con":true,"img":false}]}
{"op":"mcm","clk":"5346716602","pt":1646094998770,"mc":[{"id":"1.195395448","rc":[{"atb":[[3.7,2.75]],"id":40014837},{"atb":[[3.25,12.19]],"id":36899944},{"atb":[[1.52,14.32]],"id":37076580}],"con":true,"img":false}]}
{"op":"mcm","clk":"5346716611","pt":1646094998930,"mc":[{"id":"1.195395448","rc":[{"atb":[[3.6,5],[3.75,9.91],[3.7,17.96]],"id":40014837},{"atb":[[1.48,180.34],[1.47,42.55]],"id":37076580}],"con":true,"img":false}]}
{"op":"mcm","clk":"5346716652","pt":1646095000159,"mc":[{"id":"1.195395448","rc":[{"atl":[[21,12.95]],"id":37535509}],"con":true,"img":false}]}
{"op":"mcm","clk":"5346716655","pt":1646095000262,"mc":[{"id":"1.195395448","rc":[{"atl":[[18,0]],"id":37535509}],"con":true,"img":false}]}
{"op":"mcm","clk":"5346716682","pt":1646095001237,"mc":[{"id":"1.195395448","rc":[{"atb":[[3.2,34.09]],"id":37535509},{"atb":[[1.43,174.42]],"id":37076580},{"atl":[[2.66,82.53]],"id":37076580}],"con":true,"img":false}]}
{"op":"mcm","clk":"5346716686","pt":1646095001339,"mc":[{"id":"1.195395448","rc":[{"atb":[[1.1,250]],"id":42315317}],"con":true,"img":false}]}
{"op":"mcm","clk":"5346716703","pt":1646095001751,"mc":[{"id":"1.195395448","rc":[{"atb":[[3.7,15.21]],"id":40014837}],"con":true,"img":false}]}
{"op":"mcm","clk":"5346716722","pt":1646095002164,"mc":[{"id":"1.195395448","rc":[{"atb":[[3.1,116.69]],"id":40014837},{"atl":[[10.5,20.08]],"id":40014837},{"atb":[[1.92,54.35]],"id":38541023}],"con":true,"img":false}]}
{"op":"mcm","clk":"5346716757","pt":1646095003092,"mc":[{"id":"1.195395448","rc":[{"atb":[[1.84,0]],"id":38541023},{"atl":[[7.4,27.34]],"id":36899944},{"atb":[[1.39,0]],"id":37076580}],"con":true,"img":false}]}
{"op":"mcm","clk":"5346716761","pt":1646095003147,"mc":[{"id":"1.195395448","rc":[{"atl":[[7.2,0]],"id":36899944},{"atb":[[1.16,0]],"id":43154430}],"con":true,"img":false}]}
{"op":"mcm","clk":"5346716765","pt":1646095003245,"mc":[{"id":"1.195395448","rc":[{"atb":[[1.18,40.56]],"id":43154430}],"con":true,"img":false}]}
{"op":"mcm","clk":"5346716768","pt":1646095003351,"mc":[{"id":"1.195395448","rc":[{"atl":[[7.4,11.72],[7.2,16.13]],"id":36899944}],"con":true,"img":false}]}
{"op":"mcm","clk":"5346716772","pt":1646095003455,"mc":[{"id":"1.195395448","rc":[{"atb":[[1.49,74.08]],"id":37076580}],"con":true,"img":false}]}
{"op":"mcm","clk":"5346716839","pt":1646095005256,"mc":[{"id":"1.195395448","rc":[{"atb":[[3.45,0]],"id":40014837}],"con":true,"img":false}]}
{"op":"mcm","clk":"5346716844","pt":1646095005356,"mc":[{"id":"1.195395448","rc":[{"atb":[[3.4,24.88]],"id":40014837}],"con":true,"img":false}]}
{"op":"mcm","clk":"5346716906","pt":1646095006945,"mc":[{"id":"1.195395448","rc":[{"atb":[[3.75,32.09],[3.7,0]],"id":40014837}],"con":true,"img":false}]}
{"op":"mcm","clk":"5346716956","pt":1646095008258,"mc":[{"id":"1.195395448","rc":[{"atl":[[10,2.22],[9.8,0]],"id":40014837},{"atb":[[1.99,20.2],[1.94,0]],"id":38541023},{"atb":[[2.9,52.63],[2.66,0]],"id":36899944},{"atl":[[1.92,108.7],[1.84,0]],"id":42315317},{"atl":[[2.54,77.93],[2.86,0]],"id":43154430},{"atb":[[1.28,0],[1.52,108.32],[1.35,628.77]],"id":37076580}],"con":true,"img":false}]}
{"op":"mcm","clk":"5346716961","pt":1646095008364,"mc":[{"id":"1.195395448","rc":[{"atb":[[3.75,3.04]],"id":37535509},{"atb":[[1.49,0],[1.53,10.02]],"id":37076580}],"con":true,"img":false}]}
{"op":"mcm","clk":"5346716965","pt":1646095008464,"mc":[{"id":"1.195395448","rc":[{"atb":[[3.5,0]],"id":40014837},{"atb":[[3.7,39.46],[3.65,17.25]],"id":37535509},{"atb":[[3.1,0]],"id":36899944}],"con":true,"img":false}]}
{"op":"mcm","clk":"5346716968","pt":1646095008568,"mc":[{"id":"1.195395448","rc":[{"atb":[[1.52,124.39]],"id":37076580}],"con":true,"img":false}]}
{"op":"mcm","clk":"5346716993","pt":1646095009282,"mc":[{"id":"1.195395448","rc":[{"atb":[[3.4,16.55],[3.5,8]],"id":40014837},{"atl":[[3.75,7.27],[3.7,79.01]],"id":38541023},{"atb":[[3.4,0],[3.3,8.7]],"id":37535509},{"atl":[[1.77,25.97]],"id":42315317},{"atb":[[1.43,46.51],[1.47,0]],"id":37076580}],"con":true,"img":false}]}
{"op":"mcm","clk":"5346716998","pt":1646095009384,"mc":[{"id":"1.195395448","rc":[{"atl":[[1.79,232.59],[1.81,92.59],[1.76,94.78]],"id":42315317},{"atb":[[1.45,113.61]],"id":37076580}],"con":true,"img":false}]}
{"op":"mcm","clk":"5346717050","pt":1646095010874,"mc":[{"id":"1.195395448","rc":[{"atb":[[1.52,110.06]],"id":37076580}],"con":true,"img":false}]}
{"op":"mcm","clk":"5346717070","pt":1646095011388,"mc":[{"id":"1.195395448","rc":[{"atl":[[3.25,3]],"id":38541023},{"atb":[[1.45,2.5]],"id":37076580}],"con":true,"img":false}]}
{"op":"mcm","clk":"5346717077","pt":1646095011594,"mc":[{"id":"1.195395448","rc":[{"atl":[[3.6,123.05],[3.25,0],[2.9,4],[3.7,0]],"id":38541023}],"con":true,"img":false}]}
{"op":"mcm","clk":"5346717144","pt":1646095013656,"mc":[{"id":"1.195395448","rc":[{"atb":[[3.25,15.9]],"id":36899944}],"con":true,"img":false}]}
{"op":"mcm","clk":"5346717149","pt":1646095013757,"mc":[{"id":"1.195395448","rc":[{"atl":[[2.88,3]],"id":38541023}],"con":true,"img":false}]}
{"op":"mcm","clk":"5346717155","pt":1646095013963,"mc":[{"id":"1.195395448","rc":[{"atb":[[1.97,20.62]],"id":38541023},{"atl":[[2.9,0],[2.86,3]],"id":38541023}],"con":true,"img":false}]}
{"op":"mcm","clk":"5346717159","pt":1646095014066,"mc":[{"id":"1.195395448","rc":[{"atb":[[1.99,0]],"id":38541023}],"con":true,"img":false}]}
{"op":"mcm","clk":"5346717164","pt":1646095014169,"mc":[{"id":"1.195395448","rc":[{"atl":[[2.84,3],[2.88,0]],"id":38541023}],"con":true,"img":false}]}
{"op":"mcm","clk":"5346717194","pt":1646095015192,"mc":[{"id":"1.195395448","rc":[{"atb":[[1.26,0]],"id":42315317},{"atb":[[1.48,139.78]],"id":37076580},{"atl":[[3,0]],"id":37076580}],"con":true,"img":false}]}
{"op":"mcm","clk":"5346717198","pt":1646095015294,"mc":[{"id":"1.195395448","rc":[{"atb":[[1.28,48.32]],"id":42315317},{"atb":[[1.53,50.59]],"id":37076580},{"atl":[[3.15,33.45]],"id":37076580}],"con":true,"img":false}]}
{"op":"mcm","clk":"5346717238","pt":1646095016377,"mc":[{"id":"1.195395448","rc":[{"atl":[[2.82,3]],"id":38541023}],"con":true,"img":false}]}
{"op":"mcm","clk":"5346717273","pt":1646095017301,"mc":[{"id":"1.195395448","rc":[{"atb":[[2.42,0]],"id":40041375},{"atb":[[1.13,0]],"id":43154430}],"con":true,"img":false}]}
{"op":"mcm","clk":"5346717278","pt":1646095017406,"mc":[{"id":"1.195395448","rc":[{"atb":[[3.1,59.52],[3.35,0],[2.94,0]],"id":40014837},{"atl":[[17,0],[38,0],[12,0],[24,0],[8.8,5.84]],"id":40014837},{"atb":[[2,0],[2.2,0],[2.1,0]],"id":38541023},{"atl":[[9,0],[12.5,0],[17.5,0],[5.5,0],[7,0]],"id":38541023},{"atb":[[3.1,35.71],[3.35,0],[2.94,0]],"id":37535509},{"atl":[[17,0],[38,0],[12,0],[24,0],[8.8,0]],"id":37535509},{"atb":[[2.88,0],[2.98,63.13],[2.78,0]],"id":36899944},{"atl":[[32,0],[10.5,5.07],[8.2,0],[15.5,0],[21,0]],"id":36899944},{"atb":[[1.2,0],[1.25,0],[1.15,0]],"id":42315317},{"atl":[[3.6,0],[3.1,59.42],[2.44,0],[2.64,0],[2.84,0]],"id":42315317},{"atb":[[2.3,0],[2.44,30.73],[2.4,0],[2.2,0]],"id":40041375},{"atl":[[5.8,7.21],[14,0],[9.6,0],[19,0],[7.6,0]],"id":40041375},{"atb":[[1.15,147.93],[1.1,250],[1.05,0]],"id":43154430},{"atl":[[2.82,0],[2.22,56.65],[2.42,0],[2.62,46.3],[3.05,0]],"id":43154430},{"atb":[[1.4,0],[1.3,0],[1.35,285.71]],"id":37076580},{"atl":[[4.3,0],[2.86,0],[2.66,75.3],[3.15,22.28],[3.65,0]],"id":37076580}],"con":true,"img":false}]}
{"op":"mcm","clk":"5346717283","pt":1646095017611,"mc":[{"id":"1.195395448","rc":[{"atl":[[8.8,0]],"id":40014837},{"atb":[[1.92,125.84]],"id":38541023},{"atl":[[5.8,0]],"id":40041375},{"atl":[[2.22,0]],"id":43154430}],"con":true,"img":false}]}
{"op":"mcm","clk":"5346717286","pt":1646095017664,"mc":[{"id":"1.195395448","rc":[{"atl":[[10,11.11]],"id":40014837},{"atl":[[7,16.66]],"id":40041375},{"atl":[[2.34,94.67]],"id":43154430}],"con":true,"img":false}]}
{"op":"mcm","clk":"5346717291","pt":1646095017766,"mc":[{"id":"1.195395448","rc":[{"atl":[[10.5,5.26],[13.5,25.81]],"id":40014837},{"atl":[[7.2,0],[7.4,37.95]],"id":40041375},{"atl":[[2.54,199.58]],"id":43154430}],"con":true,"img":false}]}
{"op":"mcm","clk":"5346717294","pt":1646095017869,"mc":[{"id":"1.195395448","rc":[{"atl":[[2.36,0]],"id":43154430}],"con":true,"img":false}]}
{"op":"mcm","clk":"5346717306","pt":1646095018077,"mc":[{"id":"1.195395448","rc":[{"atl":[[2.8,3],[2.86,0]],"id":38541023}],"con":true,"img":false}]}
{"op":"mcm","clk":"5346717313","pt":1646095018283,"mc":[{"id":"1.195395448","rc":[{"atl":[[2.86,4]],"id":38541023}],"con":true,"img":false}]}
{"op":"mcm","clk":"5346717333","pt":1646095019000,"mc":[{"id":"1.195395448","rc":[{"atb":[[1.97,0],[1.96,20.83]],"id":38541023}],"con":true,"img":false}]}
{"op":"mcm","clk":"5346717338","pt":1646095019204,"mc":[{"id":"1.195395448","rc":[{"atl":[[2.78,2]],"id":38541023},{"atb":[[2.8,0],[2.52,41.99]],"id":36899944},{"atb":[[2.22,0],[2.04,56.54]],"id":40041375},{"atl":[[3.45,74.64],[3,0]],"id":43154430}],"con":true,"img":false}]}
{"op":"mcm","clk":"5346717342","pt":1646095019307,"mc":[{"id":"1.195395448","rc":[{"atb":[[3.4,37.38]],"id":40014837},{"atl":[[11,5]],"id":40014837},{"atl":[[2.84,0],[2.86,0]],"id":38541023},{"atb":[[3.2,22.73]],"id":37535509},{"atb":[[1.39,192.31]],"id":37076580}],"con":true,"img":false}]}
{"op":"mcm","clk":"5346717345","pt":1646095019409,"mc":[{"id":"1.195395448","rc":[{"atb":[[1.97,20.62]],"id":38541023},{"atl":[[2.76,2]],"id":38541023}],"con":true,"img":false}]}
{"op":"mcm","clk":"5346717347","pt":1646095019511,"mc":[{"id":"1.195395448","rc":[{"atb":[[3.1,0]],"id":40014837},{"atb":[[1.96,0]],"id":38541023}],"con":true,"img":false}]}
