{"op":"mcm","clk":"5346195390","pt":1646178339823,"mc":[{"id":"1.195453744","marketDefinition":{"bspMarket":false,"turnInPlayEnabled":false,"persistenceEnabled":false,"marketBaseRate":7.0,"eventId":"31272494","eventTypeId":"4339","numberOfWinners":1,"bettingType":"ODDS","marketType":"EXACTA","marketTime":"2022-03-02T11:12:00.000Z","suspendTime":"2022-03-02T11:12:00.000Z","bspReconciled":false,"complete":true,"inPlay":false,"crossMatching":false,"runnersVoidable":false,"numberOfActiveRunners":42,"betDelay":0,"status":"OPEN","runners":[{"status":"ACTIVE","sortPriority":1,"id":41419585,"name":"1 - 2"},{"status":"ACTIVE","sortPriority":2,"id":41419586,"name":"1 - 3"},{"status":"ACTIVE","sortPriority":3,"id":41419587,"name":"1 - 4"},{"status":"ACTIVE","sortPriority":4,"id":41419589,"name":"1 - 6"},{"status":"ACTIVE","sortPriority":5,"id":41419590,"name":"1 - 7"},{"status":"ACTIVE","sortPriority":6,"id":41419591,"name":"1 - 8"},{"status":"ACTIVE","sortPriority":7,"id":41419592,"name":"2 - 1"},{"status":"ACTIVE","sortPriority":8,"id":41419593,"name":"2 - 3"},{"status":"ACTIVE","sortPriority":9,"id":41419594,"name":"2 - 4"},{"status":"ACTIVE","sortPriority":10,"id":41419596,"name":"2 - 6"},{"status":"ACTIVE","sortPriority":11,"id":41419597,"name":"2 - 7"},{"status":"ACTIVE","sortPriority":12,"id":41419598,"name":"2 - 8"},{"status":"ACTIVE","sortPriority":13,"id":41419599,"name":"3 - 1"},{"status":"ACTIVE","sortPriority":14,"id":41419600,"name":"3 - 2"},{"status":"ACTIVE","sortPriority":15,"id":41419601,"name":"3 - 4"},{"status":"ACTIVE","sortPriority":16,"id":41419603,"name":"3 - 6"},{"status":"ACTIVE","sortPriority":17,"id":41419604,"name":"3 - 7"},{"status":"ACTIVE","sortPriority":18,"id":41419605,"name":"3 - 8"},{"status":"ACTIVE","sortPriority":19,"id":41419606,"name":"4 - 1"},{"status":"ACTIVE","sortPriority":20,"id":41419607,"name":"4 - 2"},{"status":"ACTIVE","sortPriority":21,"id":41419608,"name":"4 - 3"},{"status":"ACTIVE","sortPriority":22,"id":41419610,"name":"4 - 6"},{"status":"ACTIVE","sortPriority":23,"id":41419611,"name":"4 - 7"},{"status":"ACTIVE","sortPriority":24,"id":41419612,"name":"4 - 8"},{"status":"ACTIVE","sortPriority":25,"id":41419620,"name":"6 - 1"},{"status":"ACTIVE","sortPriority":26,"id":41419621,"name":"6 - 2"},{"status":"ACTIVE","sortPriority":27,"id":41419622,"name":"6 - 3"},{"status":"ACTIVE","sortPriority":28,"id":41419623,"name":"6 - 4"},{"status":"ACTIVE","sortPriority":29,"id":41419625,"name":"6 - 7"},{"status":"ACTIVE","sortPriority":30,"id":41419626,"name":"6 - 8"},{"status":"ACTIVE","sortPriority":31,"id":41419627,"name":"7 - 1"},{"status":"ACTIVE","sortPriority":32,"id":41419628,"name":"7 - 2"},{"status":"ACTIVE","sortPriority":33,"id":41419629,"name":"7 - 3"},{"status":"ACTIVE","sortPriority":34,"id":41419630,"name":"7 - 4"},{"status":"ACTIVE","sortPriority":35,"id":41419632,"name":"7 - 6"},{"status":"ACTIVE","sortPriority":36,"id":41419633,"name":"7 - 8"},{"status":"ACTIVE","sortPriority":37,"id":41419634,"name":"8 - 1"},{"status":"ACTIVE","sortPriority":38,"id":41419635,"name":"8 - 2"},{"status":"ACTIVE","sortPriority":39,"id":41419636,"name":"8 - 3"},{"status":"ACTIVE","sortPriority":40,"id":41419637,"name":"8 - 4"},{"status":"ACTIVE","sortPriority":41,"id":41419639,"name":"8 - 6"},{"status":"ACTIVE","sortPriority":42,"id":41419640,"name":"8 - 7"}],"regulators":["MR_INT"],"venue":"Traralgon","countryCode":"AU","discountAllowed":true,"timezone":"Australia/Sydney","openDate":"2022-03-02T08:31:00.000Z","version":4382480597,"name":"Exacta","eventName":"Traralgon (AUS) 2nd Mar"},"rc":[],"con":true,"img":false}]}
{"op":"mcm","clk":"5346203794","pt":1646178504538,"mc":[{"id":"1.195453744","rc":[{"atb":[[95,2.12],[48,5.66],[240,0.83]],"id":41419640},{"atb":[[7.2,42.91],[9.2,24.33],[15.5,13.76]],"id":41419639},{"atb":[[16,13.3],[11,26.6],[27,7.67]],"id":41419637},{"atb":[[17.5,12.09],[12.5,23.13],[30,6.88]],"id":41419636},{"atb":[[34,6.04],[18.5,11.4],[13.5,21.28]],"id":41419635},{"atb":[[16,17.74],[44,4.64],[22,9.5]],"id":41419634},{"atb":[[10.5,28],[26,7.98],[15.5,13.76]],"id":41419612},{"atb":[[75,2.69],[20,14],[30,6.88]],"id":41419611},{"atb":[[5.6,43.38],[4.6,73.91],[8.2,27.71]],"id":41419610},{"atb":[[17,12.47],[12,24.19],[29,7.12]],"id":41419625},{"atb":[[3.95,90.19],[6.8,34.4],[4.9,51.17]],"id":41419623},{"atb":[[5.6,43.38],[4.6,73.91],[8.2,27.71]],"id":41419622},{"atb":[[4.9,68.22],[8.8,25.58],[5.9,40.72]],"id":41419621},{"atb":[[12,18.14],[7.8,29.34],[5.9,54.3]],"id":41419620},{"atb":[[270,0.74],[120,1.67],[60,4.5]],"id":41419633},{"atb":[[42,4.86],[21,9.97],[15.5,18.35]],"id":41419632},{"atb":[[36,5.69],[90,2.24],[23,12.09]],"id":41419630},{"atb":[[150,1.33],[50,4.07],[30,9.17]],"id":41419629},{"atb":[[65,3.11],[36,7.6],[180,1.11]],"id":41419628},{"atb":[[310,0.64],[160,1.25],[80,3.36]],"id":41419627},{"atb":[[5.6,57.84],[7.2,32.18],[10.5,21]],"id":41419626}],"con":true,"img":false}]}
{"op":"mcm","clk":"5346203804","pt":1646178504644,"mc":[{"id":"1.195453744","rc":[{"atb":[[9.2,32.44],[21,9.97],[13,16.63]],"id":41419607},{"atb":[[17.5,12.09],[12.5,23.13],[30,6.88]],"id":41419605},{"atb":[[5.6,57.84],[7.2,32.18],[10.5,21]],"id":41419603},{"atb":[[16,13.3],[11,26.6],[27,7.67]],"id":41419593},{"atb":[[16,17.74],[44,4.64],[22,9.5]],"id":41419591},{"atb":[[17,12.47],[9.8,22.67],[7.8,39.12]],"id":41419589},{"atb":[[16.5,12.87],[11.5,25.34],[28,7.39]],"id":41419587},{"atb":[[9,33.26],[20,10.5],[12.5,17.35]],"id":41419601},{"atb":[[32,6.43],[18,11.73],[13,22.17]],"id":41419599},{"atb":[[150,1.33],[50,4.07],[30,9.17]],"id":41419597},{"atb":[[19.5,10.78],[12,18.14],[8.8,34.11]],"id":41419608},{"atb":[[16,13.3],[11,26.6],[27,7.67]],"id":41419606},{"atb":[[44,4.64],[27,10.23],[120,1.67]],"id":41419604},{"atb":[[36,5.69],[19,11.08],[14,20.46]],"id":41419585},{"atb":[[36,5.69],[19,11.08],[14,20.46]],"id":41419592},{"atb":[[130,1.54],[65,4.15],[280,0.71]],"id":41419590},{"atb":[[34,6.04],[18.5,11.4],[13.5,21.28]],"id":41419586},{"atb":[[16,13.3],[11,26.6],[27,7.67]],"id":41419600},{"atb":[[32,6.43],[18,11.73],[13,22.17]],"id":41419598},{"atb":[[8,28.5],[6,53.21],[12.5,17.35]],"id":41419596},{"atb":[[22,9.5],[13.5,15.96],[9.4,31.67]],"id":41419594}],"con":true,"img":false}]}
{"op":"mcm","clk":"5346401285","pt":1646182002774,"mc":[{"id":"1.195453744","marketDefinition":{"bspMarket":false,"turnInPlayEnabled":false,"persistenceEnabled":false,"marketBaseRate":7.0,"eventId":"31272494","eventTypeId":"4339","numberOfWinners":1,"bettingType":"ODDS","marketType":"EXACTA","marketTime":"2022-03-02T11:12:00.000Z","suspendTime":"2022-03-02T11:12:00.000Z","bspReconciled":false,"complete":true,"inPlay":false,"crossMatching":false,"runnersVoidable":false,"numberOfActiveRunners":42,"betDelay":0,"status":"OPEN","runners":[{"status":"ACTIVE","sortPriority":1,"id":41419585,"name":"1 - 2"},{"status":"ACTIVE","sortPriority":2,"id":41419586,"name":"1 - 3"},{"status":"ACTIVE","sortPriority":3,"id":41419587,"name":"1 - 4"},{"status":"ACTIVE","sortPriority":4,"id":41419589,"name":"1 - 6"},{"status":"ACTIVE","sortPriority":5,"id":41419590,"name":"1 - 7"},{"status":"ACTIVE","sortPriority":6,"id":41419591,"name":"1 - 8"},{"status":"ACTIVE","sortPriority":7,"id":41419592,"name":"2 - 1"},{"status":"ACTIVE","sortPriority":8,"id":41419593,"name":"2 - 3"},{"status":"ACTIVE","sortPriority":9,"id":41419594,"name":"2 - 4"},{"status":"ACTIVE","sortPriority":10,"id":41419596,"name":"2 - 6"},{"status":"ACTIVE","sortPriority":11,"id":41419597,"name":"2 - 7"},{"status":"ACTIVE","sortPriority":12,"id":41419598,"name":"2 - 8"},{"status":"ACTIVE","sortPriority":13,"id":41419599,"name":"3 - 1"},{"status":"ACTIVE","sortPriority":14,"id":41419600,"name":"3 - 2"},{"status":"ACTIVE","sortPriority":15,"id":41419601,"name":"3 - 4"},{"status":"ACTIVE","sortPriority":16,"id":41419603,"name":"3 - 6"},{"status":"ACTIVE","sortPriority":17,"id":41419604,"name":"3 - 7"},{"status":"ACTIVE","sortPriority":18,"id":41419605,"name":"3 - 8"},{"status":"ACTIVE","sortPriority":19,"id":41419606,"name":"4 - 1"},{"status":"ACTIVE","sortPriority":20,"id":41419607,"name":"4 - 2"},{"status":"ACTIVE","sortPriority":21,"id":41419608,"name":"4 - 3"},{"status":"ACTIVE","sortPriority":22,"id":41419610,"name":"4 - 6"},{"status":"ACTIVE","sortPriority":23,"id":41419611,"name":"4 - 7"},{"status":"ACTIVE","sortPriority":24,"id":41419612,"name":"4 - 8"},{"status":"ACTIVE","sortPriority":25,"id":41419620,"name":"6 - 1"},{"status":"ACTIVE","sortPriority":26,"id":41419621,"name":"6 - 2"},{"status":"ACTIVE","sortPriority":27,"id":41419622,"name":"6 - 3"},{"status":"ACTIVE","sortPriority":28,"id":41419623,"name":"6 - 4"},{"status":"ACTIVE","sortPriority":29,"id":41419625,"name":"6 - 7"},{"status":"ACTIVE","sortPriority":30,"id":41419626,"name":"6 - 8"},{"status":"ACTIVE","sortPriority":31,"id":41419627,"name":"7 - 1"},{"status":"ACTIVE","sortPriority":32,"id":41419628,"name":"7 - 2"},{"status":"ACTIVE","sortPriority":33,"id":41419629,"name":"7 - 3"},{"status":"ACTIVE","sortPriority":34,"id":41419630,"name":"7 - 4"},{"status":"ACTIVE","sortPriority":35,"id":41419632,"name":"7 - 6"},{"status":"ACTIVE","sortPriority":36,"id":41419633,"name":"7 - 8"},{"status":"ACTIVE","sortPriority":37,"id":41419634,"name":"8 - 1"},{"status":"ACTIVE","sortPriority":38,"id":41419635,"name":"8 - 2"},{"status":"ACTIVE","sortPriority":39,"id":41419636,"name":"8 - 3"},{"status":"ACTIVE","sortPriority":40,"id":41419637,"name":"8 - 4"},{"status":"ACTIVE","sortPriority":41,"id":41419639,"name":"8 - 6"},{"status":"ACTIVE","sortPriority":42,"id":41419640,"name":"8 - 7"}],"regulators":["MR_INT"],"venue":"Traralgon","countryCode":"AU","discountAllowed":true,"timezone":"Australia/Sydney","openDate":"2022-03-02T08:31:00.000Z","version":4382480597,"name":"Exacta","eventName":"Traralgon (AUS) 2nd Mar"},"rc":[{"atb":[[95,2.12],[48,5.66],[240,0.83]],"id":41419640},{"atb":[[9.2,32.45],[21,9.97],[13,16.63]],"id":41419607},{"atb":[[17.5,12.09],[12.5,23.13],[30,6.88]],"id":41419605},{"atb":[[17.5,12.09],[12.5,23.13],[30,6.88]],"id":41419636},{"atb":[[5.6,57.85],[7.2,32.19],[10.5,21]],"id":41419603},{"atb":[[16,17.74],[44,4.64],[22,9.5]],"id":41419634},{"atb":[[75,2.69],[20,14],[30,6.88]],"id":41419611},{"atb":[[16,13.3],[11,26.61],[27,7.67]],"id":41419593},{"atb":[[16,17.74],[44,4.64],[22,9.5]],"id":41419591},{"atb":[[5.6,43.39],[4.6,73.92],[8.2,27.72]],"id":41419622},{"atb":[[17,12.47],[9.8,22.68],[7.8,39.13]],"id":41419589},{"atb":[[12,18.14],[7.8,29.34],[5.9,54.31]],"id":41419620},{"atb":[[16.5,12.87],[11.5,25.34],[28,7.39]],"id":41419587},{"atb":[[9,33.26],[20,10.5],[12.5,17.35]],"id":41419601},{"atb":[[42,4.86],[21,9.97],[15.5,18.35]],"id":41419632},{"atb":[[32,6.44],[18,11.73],[13,22.17]],"id":41419599},{"atb":[[36,5.7],[90,2.24],[23,12.09]],"id":41419630},{"atb":[[150,1.33],[50,4.07],[30,9.17]],"id":41419597},{"atb":[[65,3.11],[36,7.6],[180,1.11]],"id":41419628},{"atb":[[5.6,57.85],[7.2,32.19],[10.5,21]],"id":41419626},{"atb":[[19.5,10.79],[12,18.14],[8.8,34.11]],"id":41419608},{"atb":[[7.2,42.92],[9.2,24.34],[15.5,13.76]],"id":41419639},{"atb":[[16,13.3],[11,26.61],[27,7.67]],"id":41419606},{"atb":[[16,13.3],[11,26.61],[27,7.67]],"id":41419637},{"atb":[[44,4.64],[27,10.23],[120,1.67]],"id":41419604},{"atb":[[34,6.04],[18.5,11.4],[13.5,21.28]],"id":41419635},{"atb":[[36,5.7],[19,11.08],[14,20.47]],"id":41419585},{"atb":[[10.5,28.01],[26,7.98],[15.5,13.76]],"id":41419612},{"atb":[[5.6,43.39],[4.6,73.92],[8.2,27.72]],"id":41419610},{"atb":[[17,12.47],[12,24.19],[29,7.12]],"id":41419625},{"atb":[[36,5.7],[19,11.08],[14,20.47]],"id":41419592},{"atb":[[3.95,90.2],[6.8,34.41],[4.9,51.17]],"id":41419623},{"atb":[[130,1.54],[65,4.15],[280,0.71]],"id":41419590},{"atb":[[4.9,68.23],[8.8,25.58],[5.9,40.73]],"id":41419621},{"atb":[[34,6.04],[18.5,11.4],[13.5,21.28]],"id":41419586},{"atb":[[270,0.74],[120,1.67],[60,4.5]],"id":41419633},{"atb":[[16,13.3],[11,26.61],[27,7.67]],"id":41419600},{"atb":[[32,6.44],[18,11.73],[13,22.17]],"id":41419598},{"atb":[[150,1.33],[50,4.07],[30,9.17]],"id":41419629},{"atb":[[8,28.51],[6,53.22],[12.5,17.35]],"id":41419596},{"atb":[[310,0.64],[160,1.25],[80,3.36]],"id":41419627},{"atb":[[22,9.5],[13.5,15.96],[9.4,31.68]],"id":41419594}],"con":true,"img":true}]}
{"op":"mcm","clk":"5346767646","pt":1646187402719,"mc":[{"id":"1.195453744","marketDefinition":{"bspMarket":false,"turnInPlayEnabled":false,"persistenceEnabled":false,"marketBaseRate":7.0,"eventId":"31272494","eventTypeId":"4339","numberOfWinners":1,"bettingType":"ODDS","marketType":"EXACTA","marketTime":"2022-03-02T11:12:00.000Z","suspendTime":"2022-03-02T11:12:00.000Z","bspReconciled":false,"complete":true,"inPlay":false,"crossMatching":false,"runnersVoidable":false,"numberOfActiveRunners":42,"betDelay":0,"status":"OPEN","runners":[{"status":"ACTIVE","sortPriority":1,"id":41419585,"name":"1 - 2"},{"status":"ACTIVE","sortPriority":2,"id":41419586,"name":"1 - 3"},{"status":"ACTIVE","sortPriority":3,"id":41419587,"name":"1 - 4"},{"status":"ACTIVE","sortPriority":4,"id":41419589,"name":"1 - 6"},{"status":"ACTIVE","sortPriority":5,"id":41419590,"name":"1 - 7"},{"status":"ACTIVE","sortPriority":6,"id":41419591,"name":"1 - 8"},{"status":"ACTIVE","sortPriority":7,"id":41419592,"name":"2 - 1"},{"status":"ACTIVE","sortPriority":8,"id":41419593,"name":"2 - 3"},{"status":"ACTIVE","sortPriority":9,"id":41419594,"name":"2 - 4"},{"status":"ACTIVE","sortPriority":10,"id":41419596,"name":"2 - 6"},{"status":"ACTIVE","sortPriority":11,"id":41419597,"name":"2 - 7"},{"status":"ACTIVE","sortPriority":12,"id":41419598,"name":"2 - 8"},{"status":"ACTIVE","sortPriority":13,"id":41419599,"name":"3 - 1"},{"status":"ACTIVE","sortPriority":14,"id":41419600,"name":"3 - 2"},{"status":"ACTIVE","sortPriority":15,"id":41419601,"name":"3 - 4"},{"status":"ACTIVE","sortPriority":16,"id":41419603,"name":"3 - 6"},{"status":"ACTIVE","sortPriority":17,"id":41419604,"name":"3 - 7"},{"status":"ACTIVE","sortPriority":18,"id":41419605,"name":"3 - 8"},{"status":"ACTIVE","sortPriority":19,"id":41419606,"name":"4 - 1"},{"status":"ACTIVE","sortPriority":20,"id":41419607,"name":"4 - 2"},{"status":"ACTIVE","sortPriority":21,"id":41419608,"name":"4 - 3"},{"status":"ACTIVE","sortPriority":22,"id":41419610,"name":"4 - 6"},{"status":"ACTIVE","sortPriority":23,"id":41419611,"name":"4 - 7"},{"status":"ACTIVE","sortPriority":24,"id":41419612,"name":"4 - 8"},{"status":"ACTIVE","sortPriority":25,"id":41419620,"name":"6 - 1"},{"status":"ACTIVE","sortPriority":26,"id":41419621,"name":"6 - 2"},{"status":"ACTIVE","sortPriority":27,"id":41419622,"name":"6 - 3"},{"status":"ACTIVE","sortPriority":28,"id":41419623,"name":"6 - 4"},{"status":"ACTIVE","sortPriority":29,"id":41419625,"name":"6 - 7"},{"status":"ACTIVE","sortPriority":30,"id":41419626,"name":"6 - 8"},{"status":"ACTIVE","sortPriority":31,"id":41419627,"name":"7 - 1"},{"status":"ACTIVE","sortPriority":32,"id":41419628,"name":"7 - 2"},{"status":"ACTIVE","sortPriority":33,"id":41419629,"name":"7 - 3"},{"status":"ACTIVE","sortPriority":34,"id":41419630,"name":"7 - 4"},{"status":"ACTIVE","sortPriority":35,"id":41419632,"name":"7 - 6"},{"status":"ACTIVE","sortPriority":36,"id":41419633,"name":"7 - 8"},{"status":"ACTIVE","sortPriority":37,"id":41419634,"name":"8 - 1"},{"status":"ACTIVE","sortPriority":38,"id":41419635,"name":"8 - 2"},{"status":"ACTIVE","sortPriority":39,"id":41419636,"name":"8 - 3"},{"status":"ACTIVE","sortPriority":40,"id":41419637,"name":"8 - 4"},{"status":"ACTIVE","sortPriority":41,"id":41419639,"name":"8 - 6"},{"status":"ACTIVE","sortPriority":42,"id":41419640,"name":"8 - 7"}],"regulators":["MR_INT"],"venue":"Traralgon","countryCode":"AU","discountAllowed":true,"timezone":"Australia/Sydney","openDate":"2022-03-02T08:31:00.000Z","version":4382480597,"name":"Exacta","eventName":"Traralgon (AUS) 2nd Mar"},"rc":[{"atb":[[95,2.12],[48,5.67],[240,0.83]],"id":41419640},{"atb":[[9.2,32.5],[21,9.99],[13,16.65]],"id":41419607},{"atb":[[17.5,12.11],[12.5,23.17],[30,6.89]],"id":41419605},{"atb":[[17.5,12.11],[12.5,23.17],[30,6.89]],"id":41419636},{"atb":[[5.6,57.94],[7.2,32.24],[10.5,21.04]],"id":41419603},{"atb":[[16,17.77],[44,4.65],[22,9.52]],"id":41419634},{"atb":[[75,2.69],[20,14.03],[30,6.89]],"id":41419611},{"atb":[[16,13.32],[11,26.65],[27,7.68]],"id":41419593},{"atb":[[16,17.77],[44,4.65],[22,9.52]],"id":41419591},{"atb":[[5.6,43.45],[4.6,74.03],[8.2,27.76]],"id":41419622},{"atb":[[17,12.49],[9.8,22.71],[7.8,39.19]],"id":41419589},{"atb":[[12,18.17],[7.8,29.39],[5.9,54.39]],"id":41419620},{"atb":[[16.5,12.89],[11.5,25.38],[28,7.4]],"id":41419587},{"atb":[[9,33.31],[20,10.51],[12.5,17.38]],"id":41419601},{"atb":[[42,4.87],[21,9.99],[15.5,18.38]],"id":41419632},{"atb":[[32,6.45],[18,11.75],[13,22.2]],"id":41419599},{"atb":[[36,5.7],[90,2.24],[23,12.11]],"id":41419630},{"atb":[[150,1.34],[50,4.07],[30,9.19]],"id":41419597},{"atb":[[65,3.12],[36,7.61],[180,1.11]],"id":41419628},{"atb":[[5.6,57.94],[7.2,32.24],[10.5,21.04]],"id":41419626},{"atb":[[19.5,10.8],[12,18.17],[8.8,34.17]],"id":41419608},{"atb":[[7.2,42.99],[9.2,24.37],[15.5,13.78]],"id":41419639},{"atb":[[16,13.32],[11,26.65],[27,7.68]],"id":41419606},{"atb":[[16,13.32],[11,26.65],[27,7.68]],"id":41419637},{"atb":[[44,4.65],[27,10.25],[120,1.67]],"id":41419604},{"atb":[[34,6.05],[18.5,11.42],[13.5,21.32]],"id":41419635},{"atb":[[36,5.7],[19,11.1],[14,20.5]],"id":41419585},{"atb":[[10.5,28.05],[26,7.99],[15.5,13.78]],"id":41419612},{"atb":[[5.6,43.45],[4.6,74.03],[8.2,27.76]],"id":41419610},{"atb":[[17,12.49],[12,24.23],[29,7.13]],"id":41419625},{"atb":[[36,5.7],[19,11.1],[14,20.5]],"id":41419592},{"atb":[[3.95,90.34],[6.8,34.46],[4.9,51.25]],"id":41419623},{"atb":[[130,1.54],[65,4.16],[280,0.71]],"id":41419590},{"atb":[[4.9,68.34],[8.8,25.62],[5.9,40.79]],"id":41419621},{"atb":[[34,6.05],[18.5,11.42],[13.5,21.32]],"id":41419586},{"atb":[[270,0.74],[120,1.67],[60,4.51]],"id":41419633},{"atb":[[16,13.32],[11,26.65],[27,7.68]],"id":41419600},{"atb":[[32,6.45],[18,11.75],[13,22.2]],"id":41419598},{"atb":[[150,1.34],[50,4.07],[30,9.19]],"id":41419629},{"atb":[[8,28.55],[6,53.3],[12.5,17.38]],"id":41419596},{"atb":[[310,0.64],[160,1.25],[80,3.37]],"id":41419627},{"atb":[[22,9.52],[13.5,15.99],[9.4,31.73]],"id":41419594}],"con":true,"img":true}]}
{"op":"mcm","clk":"5347092210","pt":1646192802700,"mc":[{"id":"1.195453744","marketDefinition":{"bspMarket":false,"turnInPlayEnabled":false,"persistenceEnabled":false,"marketBaseRate":7.0,"eventId":"31272494","eventTypeId":"4339","numberOfWinners":1,"bettingType":"ODDS","marketType":"EXACTA","marketTime":"2022-03-02T11:12:00.000Z","suspendTime":"2022-03-02T11:12:00.000Z","bspReconciled":false,"complete":true,"inPlay":false,"crossMatching":false,"runnersVoidable":false,"numberOfActiveRunners":42,"betDelay":0,"status":"OPEN","runners":[{"status":"ACTIVE","sortPriority":1,"id":41419585,"name":"1 - 2"},{"status":"ACTIVE","sortPriority":2,"id":41419586,"name":"1 - 3"},{"status":"ACTIVE","sortPriority":3,"id":41419587,"name":"1 - 4"},{"status":"ACTIVE","sortPriority":4,"id":41419589,"name":"1 - 6"},{"status":"ACTIVE","sortPriority":5,"id":41419590,"name":"1 - 7"},{"status":"ACTIVE","sortPriority":6,"id":41419591,"name":"1 - 8"},{"status":"ACTIVE","sortPriority":7,"id":41419592,"name":"2 - 1"},{"status":"ACTIVE","sortPriority":8,"id":41419593,"name":"2 - 3"},{"status":"ACTIVE","sortPriority":9,"id":41419594,"name":"2 - 4"},{"status":"ACTIVE","sortPriority":10,"id":41419596,"name":"2 - 6"},{"status":"ACTIVE","sortPriority":11,"id":41419597,"name":"2 - 7"},{"status":"ACTIVE","sortPriority":12,"id":41419598,"name":"2 - 8"},{"status":"ACTIVE","sortPriority":13,"id":41419599,"name":"3 - 1"},{"status":"ACTIVE","sortPriority":14,"id":41419600,"name":"3 - 2"},{"status":"ACTIVE","sortPriority":15,"id":41419601,"name":"3 - 4"},{"status":"ACTIVE","sortPriority":16,"id":41419603,"name":"3 - 6"},{"status":"ACTIVE","sortPriority":17,"id":41419604,"name":"3 - 7"},{"status":"ACTIVE","sortPriority":18,"id":41419605,"name":"3 - 8"},{"status":"ACTIVE","sortPriority":19,"id":41419606,"name":"4 - 1"},{"status":"ACTIVE","sortPriority":20,"id":41419607,"name":"4 - 2"},{"status":"ACTIVE","sortPriority":21,"id":41419608,"name":"4 - 3"},{"status":"ACTIVE","sortPriority":22,"id":41419610,"name":"4 - 6"},{"status":"ACTIVE","sortPriority":23,"id":41419611,"name":"4 - 7"},{"status":"ACTIVE","sortPriority":24,"id":41419612,"name":"4 - 8"},{"status":"ACTIVE","sortPriority":25,"id":41419620,"name":"6 - 1"},{"status":"ACTIVE","sortPriority":26,"id":41419621,"name":"6 - 2"},{"status":"ACTIVE","sortPriority":27,"id":41419622,"name":"6 - 3"},{"status":"ACTIVE","sortPriority":28,"id":41419623,"name":"6 - 4"},{"status":"ACTIVE","sortPriority":29,"id":41419625,"name":"6 - 7"},{"status":"ACTIVE","sortPriority":30,"id":41419626,"name":"6 - 8"},{"status":"ACTIVE","sortPriority":31,"id":41419627,"name":"7 - 1"},{"status":"ACTIVE","sortPriority":32,"id":41419628,"name":"7 - 2"},{"status":"ACTIVE","sortPriority":33,"id":41419629,"name":"7 - 3"},{"status":"ACTIVE","sortPriority":34,"id":41419630,"name":"7 - 4"},{"status":"ACTIVE","sortPriority":35,"id":41419632,"name":"7 - 6"},{"status":"ACTIVE","sortPriority":36,"id":41419633,"name":"7 - 8"},{"status":"ACTIVE","sortPriority":37,"id":41419634,"name":"8 - 1"},{"status":"ACTIVE","sortPriority":38,"id":41419635,"name":"8 - 2"},{"status":"ACTIVE","sortPriority":39,"id":41419636,"name":"8 - 3"},{"status":"ACTIVE","sortPriority":40,"id":41419637,"name":"8 - 4"},{"status":"ACTIVE","sortPriority":41,"id":41419639,"name":"8 - 6"},{"status":"ACTIVE","sortPriority":42,"id":41419640,"name":"8 - 7"}],"regulators":["MR_INT"],"venue":"Traralgon","countryCode":"AU","discountAllowed":true,"timezone":"Australia/Sydney","openDate":"2022-03-02T08:31:00.000Z","version":4382480597,"name":"Exacta","eventName":"Traralgon (AUS) 2nd Mar"},"rc":[{"atb":[[95,2.13],[48,5.68],[240,0.83]],"id":41419640},{"atb":[[9.2,32.55],[21,10.01],[13,16.68]],"id":41419607},{"atb":[[17.5,12.13],[12.5,23.21],[30,6.9]],"id":41419605},{"atb":[[17.5,12.13],[12.5,23.21],[30,6.9]],"id":41419636},{"atb":[[5.6,58.04],[7.2,32.29],[10.5,21.07]],"id":41419603},{"atb":[[16,17.8],[44,4.65],[22,9.53]],"id":41419634},{"atb":[[75,2.7],[20,14.05],[30,6.9]],"id":41419611},{"atb":[[16,13.34],[11,26.69],[27,7.7]],"id":41419593},{"atb":[[16,17.8],[44,4.65],[22,9.53]],"id":41419591},{"atb":[[5.6,43.53],[4.6,74.16],[8.2,27.81]],"id":41419622},{"atb":[[17,12.51],[9.8,22.75],[7.8,39.26]],"id":41419589},{"atb":[[12,18.2],[7.8,29.44],[5.9,54.48]],"id":41419620},{"atb":[[16.5,12.91],[11.5,25.42],[28,7.41]],"id":41419587},{"atb":[[9,33.37],[20,10.53],[12.5,17.41]],"id":41419601},{"atb":[[42,4.88],[21,10.01],[15.5,18.41]],"id":41419632},{"atb":[[32,6.46],[18,11.77],[13,22.24]],"id":41419599},{"atb":[[36,5.71],[90,2.25],[23,12.13]],"id":41419630},{"atb":[[150,1.34],[50,4.08],[30,9.2]],"id":41419597},{"atb":[[65,3.12],[36,7.63],[180,1.11]],"id":41419628},{"atb":[[5.6,58.04],[7.2,32.29],[10.5,21.07]],"id":41419626},{"atb":[[19.5,10.82],[12,18.2],[8.8,34.23]],"id":41419608},{"atb":[[7.2,43.06],[9.2,24.42],[15.5,13.8]],"id":41419639},{"atb":[[16,13.34],[11,26.69],[27,7.7]],"id":41419606},{"atb":[[16,13.34],[11,26.69],[27,7.7]],"id":41419637},{"atb":[[44,4.65],[27,10.26],[120,1.68]],"id":41419604},{"atb":[[34,6.06],[18.5,11.44],[13.5,21.35]],"id":41419635},{"atb":[[36,5.71],[19,11.12],[14,20.53]],"id":41419585},{"atb":[[10.5,28.1],[26,8],[15.5,13.8]],"id":41419612},{"atb":[[5.6,43.53],[4.6,74.16],[8.2,27.81]],"id":41419610},{"atb":[[17,12.51],[12,24.27],[29,7.14]],"id":41419625},{"atb":[[36,5.71],[19,11.12],[14,20.53]],"id":41419592},{"atb":[[3.95,90.5],[6.8,34.52],[4.9,51.34]],"id":41419623},{"atb":[[130,1.55],[65,4.17],[280,0.71]],"id":41419590},{"atb":[[4.9,68.45],[8.8,25.67],[5.9,40.86]],"id":41419621},{"atb":[[34,6.06],[18.5,11.44],[13.5,21.35]],"id":41419586},{"atb":[[270,0.74],[120,1.68],[60,4.52]],"id":41419633},{"atb":[[16,13.34],[11,26.69],[27,7.7]],"id":41419600},{"atb":[[32,6.46],[18,11.77],[13,22.24]],"id":41419598},{"atb":[[150,1.34],[50,4.08],[30,9.2]],"id":41419629},{"atb":[[8,28.6],[6,53.39],[12.5,17.41]],"id":41419596},{"atb":[[310,0.64],[160,1.26],[80,3.38]],"id":41419627},{"atb":[[22,9.53],[13.5,16.02],[9.4,31.78]],"id":41419594}],"con":true,"img":true}]}
{"op":"mcm","clk":"5347381083","pt":1646198202718,"mc":[{"id":"1.195453744","marketDefinition":{"bspMarket":false,"turnInPlayEnabled":false,"persistenceEnabled":false,"marketBaseRate":7.0,"eventId":"31272494","eventTypeId":"4339","numberOfWinners":1,"bettingType":"ODDS","marketType":"EXACTA","marketTime":"2022-03-02T11:12:00.000Z","suspendTime":"2022-03-02T11:12:00.000Z","bspReconciled":false,"complete":true,"inPlay":false,"crossMatching":false,"runnersVoidable":false,"numberOfActiveRunners":42,"betDelay":0,"status":"OPEN","runners":[{"status":"ACTIVE","sortPriority":1,"id":41419585,"name":"1 - 2"},{"status":"ACTIVE","sortPriority":2,"id":41419586,"name":"1 - 3"},{"status":"ACTIVE","sortPriority":3,"id":41419587,"name":"1 - 4"},{"status":"ACTIVE","sortPriority":4,"id":41419589,"name":"1 - 6"},{"status":"ACTIVE","sortPriority":5,"id":41419590,"name":"1 - 7"},{"status":"ACTIVE","sortPriority":6,"id":41419591,"name":"1 - 8"},{"status":"ACTIVE","sortPriority":7,"id":41419592,"name":"2 - 1"},{"status":"ACTIVE","sortPriority":8,"id":41419593,"name":"2 - 3"},{"status":"ACTIVE","sortPriority":9,"id":41419594,"name":"2 - 4"},{"status":"ACTIVE","sortPriority":10,"id":41419596,"name":"2 - 6"},{"status":"ACTIVE","sortPriority":11,"id":41419597,"name":"2 - 7"},{"status":"ACTIVE","sortPriority":12,"id":41419598,"name":"2 - 8"},{"status":"ACTIVE","sortPriority":13,"id":41419599,"name":"3 - 1"},{"status":"ACTIVE","sortPriority":14,"id":41419600,"name":"3 - 2"},{"status":"ACTIVE","sortPriority":15,"id":41419601,"name":"3 - 4"},{"status":"ACTIVE","sortPriority":16,"id":41419603,"name":"3 - 6"},{"status":"ACTIVE","sortPriority":17,"id":41419604,"name":"3 - 7"},{"status":"ACTIVE","sortPriority":18,"id":41419605,"name":"3 - 8"},{"status":"ACTIVE","sortPriority":19,"id":41419606,"name":"4 - 1"},{"status":"ACTIVE","sortPriority":20,"id":41419607,"name":"4 - 2"},{"status":"ACTIVE","sortPriority":21,"id":41419608,"name":"4 - 3"},{"status":"ACTIVE","sortPriority":22,"id":41419610,"name":"4 - 6"},{"status":"ACTIVE","sortPriority":23,"id":41419611,"name":"4 - 7"},{"status":"ACTIVE","sortPriority":24,"id":41419612,"name":"4 - 8"},{"status":"ACTIVE","sortPriority":25,"id":41419620,"name":"6 - 1"},{"status":"ACTIVE","sortPriority":26,"id":41419621,"name":"6 - 2"},{"status":"ACTIVE","sortPriority":27,"id":41419622,"name":"6 - 3"},{"status":"ACTIVE","sortPriority":28,"id":41419623,"name":"6 - 4"},{"status":"ACTIVE","sortPriority":29,"id":41419625,"name":"6 - 7"},{"status":"ACTIVE","sortPriority":30,"id":41419626,"name":"6 - 8"},{"status":"ACTIVE","sortPriority":31,"id":41419627,"name":"7 - 1"},{"status":"ACTIVE","sortPriority":32,"id":41419628,"name":"7 - 2"},{"status":"ACTIVE","sortPriority":33,"id":41419629,"name":"7 - 3"},{"status":"ACTIVE","sortPriority":34,"id":41419630,"name":"7 - 4"},{"status":"ACTIVE","sortPriority":35,"id":41419632,"name":"7 - 6"},{"status":"ACTIVE","sortPriority":36,"id":41419633,"name":"7 - 8"},{"status":"ACTIVE","sortPriority":37,"id":41419634,"name":"8 - 1"},{"status":"ACTIVE","sortPriority":38,"id":41419635,"name":"8 - 2"},{"status":"ACTIVE","sortPriority":39,"id":41419636,"name":"8 - 3"},{"status":"ACTIVE","sortPriority":40,"id":41419637,"name":"8 - 4"},{"status":"ACTIVE","sortPriority":41,"id":41419639,"name":"8 - 6"},{"status":"ACTIVE","sortPriority":42,"id":41419640,"name":"8 - 7"}],"regulators":["MR_INT"],"venue":"Traralgon","countryCode":"AU","discountAllowed":true,"timezone":"Australia/Sydney","openDate":"2022-03-02T08:31:00.000Z","version":4382480597,"name":"Exacta","eventName":"Traralgon (AUS) 2nd Mar"},"rc":[{"atb":[[95,2.12],[48,5.67],[240,0.83]],"id":41419640},{"atb":[[9.2,32.54],[21,10],[13,16.68]],"id":41419607},{"atb":[[17.5,12.13],[12.5,23.2],[30,6.9]],"id":41419605},{"atb":[[17.5,12.13],[12.5,23.2],[30,6.9]],"id":41419636},{"atb":[[5.6,58.01],[7.2,32.28],[10.5,21.07]],"id":41419603},{"atb":[[16,17.79],[44,4.65],[22,9.53]],"id":41419634},{"atb":[[75,2.7],[20,14.04],[30,6.9]],"id":41419611},{"atb":[[16,13.34],[11,26.68],[27,7.69]],"id":41419593},{"atb":[[16,17.79],[44,4.65],[22,9.53]],"id":41419591},{"atb":[[5.6,43.51],[4.6,74.13],[8.2,27.8]],"id":41419622},{"atb":[[17,12.5],[9.8,22.74],[7.8,39.24]],"id":41419589},{"atb":[[12,18.19],[7.8,29.43],[5.9,54.46]],"id":41419620},{"atb":[[16.5,12.91],[11.5,25.41],[28,7.41]],"id":41419587},{"atb":[[9,33.36],[20,10.53],[12.5,17.4]],"id":41419601},{"atb":[[42,4.88],[21,10],[15.5,18.4]],"id":41419632},{"atb":[[32,6.45],[18,11.77],[13,22.23]],"id":41419599},{"atb":[[36,5.71],[90,2.24],[23,12.13]],"id":41419630},{"atb":[[150,1.34],[50,4.08],[30,9.2]],"id":41419597},{"atb":[[65,3.12],[36,7.62],[180,1.11]],"id":41419628},{"atb":[[5.6,58.01],[7.2,32.28],[10.5,21.07]],"id":41419626},{"atb":[[19.5,10.82],[12,18.19],[8.8,34.21]],"id":41419608},{"atb":[[7.2,43.04],[9.2,24.41],[15.5,13.8]],"id":41419639},{"atb":[[16,13.34],[11,26.68],[27,7.69]],"id":41419606},{"atb":[[16,13.34],[11,26.68],[27,7.69]],"id":41419637},{"atb":[[44,4.65],[27,10.26],[120,1.68]],"id":41419604},{"atb":[[34,6.06],[18.5,11.43],[13.5,21.34]],"id":41419635},{"atb":[[36,5.71],[19,11.12],[14,20.52]],"id":41419585},{"atb":[[10.5,28.09],[26,8],[15.5,13.8]],"id":41419612},{"atb":[[5.6,43.51],[4.6,74.13],[8.2,27.8]],"id":41419610},{"atb":[[17,12.5],[12,24.26],[29,7.14]],"id":41419625},{"atb":[[36,5.71],[19,11.12],[14,20.52]],"id":41419592},{"atb":[[3.95,90.46],[6.8,34.51],[4.9,51.32]],"id":41419623},{"atb":[[130,1.55],[65,4.17],[280,0.71]],"id":41419590},{"atb":[[4.9,68.43],[8.8,25.66],[5.9,40.85]],"id":41419621},{"atb":[[34,6.06],[18.5,11.43],[13.5,21.34]],"id":41419586},{"atb":[[270,0.74],[120,1.68],[60,4.52]],"id":41419633},{"atb":[[16,13.34],[11,26.68],[27,7.69]],"id":41419600},{"atb":[[32,6.45],[18,11.77],[13,22.23]],"id":41419598},{"atb":[[150,1.34],[50,4.08],[30,9.2]],"id":41419629},{"atb":[[8,28.59],[6,53.37],[12.5,17.4]],"id":41419596},{"atb":[[310,0.64],[160,1.26],[80,3.37]],"id":41419627},{"atb":[[22,9.53],[13.5,16.01],[9.4,31.77]],"id":41419594}],"con":true,"img":true}]}
{"op":"mcm","clk":"5347572817","pt":1646202475426,"mc":[{"id":"1.195453744","rc":[{"atb":[[95,2.12],[48,5.67],[240,0.83]],"id":41419640},{"atb":[[9.2,0],[21,0],[13,0]],"id":41419607},{"atb":[[17.5,0],[12.5,0],[30,0]],"id":41419605},{"atb":[[17.5,12.13],[12.5,23.2],[30,6.9]],"id":41419636},{"atb":[[5.6,0],[7.2,0],[10.5,0]],"id":41419603},{"atb":[[16,17.79],[44,4.65],[22,9.53]],"id":41419634},{"atb":[[75,2.7],[20,14.04],[30,6.9]],"id":41419611},{"atb":[[16,0],[11,0],[27,0]],"id":41419593},{"atb":[[16,0],[44,0],[22,0]],"id":41419591},{"atb":[[5.6,43.51],[4.6,74.13],[8.2,27.8]],"id":41419622},{"atb":[[17,0],[9.8,0],[7.8,0]],"id":41419589},{"atb":[[12,18.19],[7.8,29.43],[5.9,54.46]],"id":41419620},{"atb":[[16.5,0],[11.5,0],[28,0]],"id":41419587},{"atb":[[9,0],[20,0],[12.5,0]],"id":41419601},{"atb":[[42,4.88],[21,10],[15.5,18.4]],"id":41419632},{"atb":[[32,0],[18,0],[13,0]],"id":41419599},{"atb":[[36,5.71],[90,2.24],[23,12.13]],"id":41419630},{"atb":[[150,0],[50,0],[30,0]],"id":41419597},{"atb":[[65,3.12],[36,7.62],[180,1.11]],"id":41419628},{"atb":[[5.6,58.01],[7.2,32.28],[10.5,21.07]],"id":41419626},{"atb":[[19.5,10.82],[12,18.19],[8.8,34.21]],"id":41419608},{"atb":[[7.2,43.04],[9.2,24.41],[15.5,13.8]],"id":41419639},{"atb":[[16,0],[11,0],[27,0]],"id":41419606},{"atb":[[16,13.34],[11,26.68],[27,7.69]],"id":41419637},{"atb":[[44,0],[27,0],[120,0]],"id":41419604},{"atb":[[34,6.06],[18.5,11.43],[13.5,21.34]],"id":41419635},{"atb":[[36,0],[19,0],[14,0]],"id":41419585},{"atb":[[10.5,28.09],[26,8],[15.5,13.8]],"id":41419612},{"atb":[[5.6,43.51],[4.6,74.13],[8.2,27.8]],"id":41419610},{"atb":[[17,12.5],[12,24.26],[29,7.14]],"id":41419625},{"atb":[[36,0],[19,0],[14,0]],"id":41419592},{"atb":[[3.95,90.46],[6.8,34.51],[4.9,51.32]],"id":41419623},{"atb":[[130,0],[65,0],[280,0]],"id":41419590},{"atb":[[4.9,68.43],[8.8,25.66],[5.9,40.85]],"id":41419621},{"atb":[[34,0],[18.5,0],[13.5,0]],"id":41419586},{"atb":[[270,0.74],[120,1.68],[60,4.52]],"id":41419633},{"atb":[[16,0],[11,0],[27,0]],"id":41419600},{"atb":[[32,0],[18,0],[13,0]],"id":41419598},{"atb":[[150,1.34],[50,4.08],[30,9.2]],"id":41419629},{"atb":[[8,0],[6,0],[12.5,0]],"id":41419596},{"atb":[[310,0.64],[160,1.26],[80,3.37]],"id":41419627},{"atb":[[22,0],[13.5,0],[9.4,0]],"id":41419594}],"con":true,"img":false}]}
{"op":"mcm","clk":"5347572823","pt":1646202475528,"mc":[{"id":"1.195453744","rc":[{"atb":[[95,0],[48,0],[240,0]],"id":41419640},{"atb":[[7.2,0],[9.2,0],[15.5,0]],"id":41419639}],"con":true,"img":false}]}
{"op":"mcm","clk":"5347572826","pt":1646202475632,"mc":[{"id":"1.195453744","rc":[{"atb":[[17.5,0],[12.5,0],[30,0]],"id":41419636},{"atb":[[16,0],[44,0],[22,0]],"id":41419634},{"atb":[[75,0],[20,0],[30,0]],"id":41419611},{"atb":[[5.6,0],[4.6,0],[8.2,0]],"id":41419622},{"atb":[[12,0],[7.8,0],[5.9,0]],"id":41419620},{"atb":[[42,0],[21,0],[15.5,0]],"id":41419632},{"atb":[[36,0],[90,0],[23,0]],"id":41419630},{"atb":[[65,0],[36,0],[180,0]],"id":41419628},{"atb":[[5.6,0],[7.2,0],[10.5,0]],"id":41419626},{"atb":[[19.5,0],[12,0],[8.8,0]],"id":41419608},{"atb":[[16,0],[11,0],[27,0]],"id":41419637},{"atb":[[34,0],[18.5,0],[13.5,0]],"id":41419635},{"atb":[[10.5,0],[26,0],[15.5,0]],"id":41419612},{"atb":[[5.6,0],[4.6,0],[8.2,0]],"id":41419610},{"atb":[[17,0],[12,0],[29,0]],"id":41419625},{"atb":[[3.95,0],[6.8,0],[4.9,0]],"id":41419623},{"atb":[[4.9,0],[8.8,0],[5.9,0]],"id":41419621},{"atb":[[270,0],[120,0],[60,0]],"id":41419633},{"atb":[[150,0],[50,0],[30,0]],"id":41419629},{"atb":[[310,0],[160,0],[80,0]],"id":41419627}],"con":true,"img":false}]}
{"op":"mcm","clk":"5347573699","pt":1646202497645,"mc":[{"id":"1.195453744","rc":[{"atb":[[280,0.71],[180,1.49],[430,0.46]],"id":41419640},{"atb":[[19.5,10.82],[12,18.19],[8.8,34.21]],"id":41419607},{"atb":[[40,5.13],[20,10.53],[15,19.06]],"id":41419605},{"atb":[[42,4.88],[21,10],[15.5,18.4]],"id":41419636},{"atb":[[8,28.59],[6,53.37],[12.5,17.4]],"id":41419603},{"atb":[[16.5,17.22],[46,4.44],[23,9.09]],"id":41419634},{"atb":[[36,5.71],[90,2.24],[23,12.13]],"id":41419611},{"atb":[[16.5,12.91],[11.5,25.41],[28,7.41]],"id":41419593},{"atb":[[16.5,17.22],[46,4.44],[23,9.09]],"id":41419591},{"atb":[[4.8,70.23],[8.6,26.33],[5.8,41.7]],"id":41419622},{"atb":[[7.2,43.04],[9.2,24.41],[15.5,13.8]],"id":41419589},{"atb":[[10,22.23],[5.5,59.3],[7,33.36]],"id":41419620},{"atb":[[16,13.34],[11,26.68],[27,7.69]],"id":41419587},{"atb":[[22,9.53],[13.5,16.01],[9.4,31.77]],"id":41419601},{"atb":[[16.5,17.22],[46,4.44],[23,9.09]],"id":41419632},{"atb":[[36,5.71],[19,11.12],[14,20.52]],"id":41419599},{"atb":[[44,4.65],[27,10.26],[120,1.68]],"id":41419630},{"atb":[[75,2.7],[40,6.84],[200,1]],"id":41419597},{"atb":[[100,2.02],[50,5.44],[250,0.8]],"id":41419628},{"atb":[[8,28.59],[6,53.37],[12.5,17.4]],"id":41419626},{"atb":[[9,33.36],[20,10.53],[12.5,17.4]],"id":41419608},{"atb":[[8,38.12],[17.5,12.13],[10,22.23]],"id":41419639},{"atb":[[10.5,28.09],[26,8],[15.5,13.8]],"id":41419606},{"atb":[[16.5,12.91],[11.5,25.41],[28,7.41]],"id":41419637},{"atb":[[95,2.12],[48,5.67],[240,0.83]],"id":41419604},{"atb":[[38,5.41],[19.5,10.82],[14.5,19.77]],"id":41419635},{"atb":[[34,6.06],[18.5,11.43],[13.5,21.34]],"id":41419585},{"atb":[[16,13.34],[11,26.68],[27,7.69]],"id":41419612},{"atb":[[4.4,78.49],[7.8,29.43],[5.4,45.49]],"id":41419610},{"atb":[[32,6.45],[18,11.77],[13,22.23]],"id":41419625},{"atb":[[32,6.45],[18,11.77],[13,22.23]],"id":41419592},{"atb":[[3.7,98.84],[4.4,58.86],[5.9,40.85]],"id":41419623},{"atb":[[360,0.55],[210,0.95],[110,2.44]],"id":41419590},{"atb":[[8,28.59],[4.5,76.25],[5.5,44.48]],"id":41419621},{"atb":[[36,5.71],[19,11.12],[14,20.52]],"id":41419586},{"atb":[[320,0.62],[220,1.21],[470,0.42]],"id":41419633},{"atb":[[16.5,12.91],[11.5,25.41],[28,7.41]],"id":41419600},{"atb":[[36,5.71],[19,11.12],[14,20.52]],"id":41419598},{"atb":[[130,1.55],[65,4.17],[280,0.71]],"id":41419629},{"atb":[[5.6,58.01],[7.2,32.28],[10.5,21.07]],"id":41419596},{"atb":[[140,1.92],[390,0.51],[240,0.83]],"id":41419627},{"atb":[[9,33.36],[20,10.53],[12.5,17.4]],"id":41419594}],"con":true,"img":false}]}
{"op":"mcm","clk":"5347848768","pt":1646209002722,"mc":[{"id":"1.195453744","marketDefinition":{"bspMarket":false,"turnInPlayEnabled":false,"persistenceEnabled":false,"marketBaseRate":7.0,"eventId":"31272494","eventTypeId":"4339","numberOfWinners":1,"bettingType":"ODDS","marketType":"EXACTA","marketTime":"2022-03-02T11:12:00.000Z","suspendTime":"2022-03-02T11:12:00.000Z","bspReconciled":false,"complete":true,"inPlay":false,"crossMatching":false,"runnersVoidable":false,"numberOfActiveRunners":42,"betDelay":0,"status":"OPEN","runners":[{"status":"ACTIVE","sortPriority":1,"id":41419585,"name":"1 - 2"},{"status":"ACTIVE","sortPriority":2,"id":41419586,"name":"1 - 3"},{"status":"ACTIVE","sortPriority":3,"id":41419587,"name":"1 - 4"},{"status":"ACTIVE","sortPriority":4,"id":41419589,"name":"1 - 6"},{"status":"ACTIVE","sortPriority":5,"id":41419590,"name":"1 - 7"},{"status":"ACTIVE","sortPriority":6,"id":41419591,"name":"1 - 8"},{"status":"ACTIVE","sortPriority":7,"id":41419592,"name":"2 - 1"},{"status":"ACTIVE","sortPriority":8,"id":41419593,"name":"2 - 3"},{"status":"ACTIVE","sortPriority":9,"id":41419594,"name":"2 - 4"},{"status":"ACTIVE","sortPriority":10,"id":41419596,"name":"2 - 6"},{"status":"ACTIVE","sortPriority":11,"id":41419597,"name":"2 - 7"},{"status":"ACTIVE","sortPriority":12,"id":41419598,"name":"2 - 8"},{"status":"ACTIVE","sortPriority":13,"id":41419599,"name":"3 - 1"},{"status":"ACTIVE","sortPriority":14,"id":41419600,"name":"3 - 2"},{"status":"ACTIVE","sortPriority":15,"id":41419601,"name":"3 - 4"},{"status":"ACTIVE","sortPriority":16,"id":41419603,"name":"3 - 6"},{"status":"ACTIVE","sortPriority":17,"id":41419604,"name":"3 - 7"},{"status":"ACTIVE","sortPriority":18,"id":41419605,"name":"3 - 8"},{"status":"ACTIVE","sortPriority":19,"id":41419606,"name":"4 - 1"},{"status":"ACTIVE","sortPriority":20,"id":41419607,"name":"4 - 2"},{"status":"ACTIVE","sortPriority":21,"id":41419608,"name":"4 - 3"},{"status":"ACTIVE","sortPriority":22,"id":41419610,"name":"4 - 6"},{"status":"ACTIVE","sortPriority":23,"id":41419611,"name":"4 - 7"},{"status":"ACTIVE","sortPriority":24,"id":41419612,"name":"4 - 8"},{"status":"ACTIVE","sortPriority":25,"id":41419620,"name":"6 - 1"},{"status":"ACTIVE","sortPriority":26,"id":41419621,"name":"6 - 2"},{"status":"ACTIVE","sortPriority":27,"id":41419622,"name":"6 - 3"},{"status":"ACTIVE","sortPriority":28,"id":41419623,"name":"6 - 4"},{"status":"ACTIVE","sortPriority":29,"id":41419625,"name":"6 - 7"},{"status":"ACTIVE","sortPriority":30,"id":41419626,"name":"6 - 8"},{"status":"ACTIVE","sortPriority":31,"id":41419627,"name":"7 - 1"},{"status":"ACTIVE","sortPriority":32,"id":41419628,"name":"7 - 2"},{"status":"ACTIVE","sortPriority":33,"id":41419629,"name":"7 - 3"},{"status":"ACTIVE","sortPriority":34,"id":41419630,"name":"7 - 4"},{"status":"ACTIVE","sortPriority":35,"id":41419632,"name":"7 - 6"},{"status":"ACTIVE","sortPriority":36,"id":41419633,"name":"7 - 8"},{"status":"ACTIVE","sortPriority":37,"id":41419634,"name":"8 - 1"},{"status":"ACTIVE","sortPriority":38,"id":41419635,"name":"8 - 2"},{"status":"ACTIVE","sortPriority":39,"id":41419636,"name":"8 - 3"},{"status":"ACTIVE","sortPriority":40,"id":41419637,"name":"8 - 4"},{"status":"ACTIVE","sortPriority":41,"id":41419639,"name":"8 - 6"},{"status":"ACTIVE","sortPriority":42,"id":41419640,"name":"8 - 7"}],"regulators":["MR_INT"],"venue":"Traralgon","countryCode":"AU","discountAllowed":true,"timezone":"Australia/Sydney","openDate":"2022-03-02T08:31:00.000Z","version":4382480597,"name":"Exacta","eventName":"Traralgon (AUS) 2nd Mar"},"rc":[{"atb":[[280,0.71],[180,1.49],[430,0.46]],"id":41419640},{"atb":[[19.5,10.81],[12,18.19],[8.8,34.2]],"id":41419607},{"atb":[[40,5.13],[20,10.52],[15,19.05]],"id":41419605},{"atb":[[42,4.87],[21,10],[15.5,18.4]],"id":41419636},{"atb":[[8,28.58],[6,53.36],[12.5,17.4]],"id":41419603},{"atb":[[16.5,17.21],[46,4.44],[23,9.09]],"id":41419634},{"atb":[[36,5.71],[90,2.24],[23,12.12]],"id":41419611},{"atb":[[16.5,12.9],[11.5,25.4],[28,7.41]],"id":41419593},{"atb":[[16.5,17.21],[46,4.44],[23,9.09]],"id":41419591},{"atb":[[4.8,70.21],[8.6,26.33],[5.8,41.69]],"id":41419622},{"atb":[[7.2,43.03],[9.2,24.4],[15.5,13.79]],"id":41419589},{"atb":[[10,22.23],[5.5,59.29],[7,33.35]],"id":41419620},{"atb":[[16,13.34],[11,26.68],[27,7.69]],"id":41419587},{"atb":[[22,9.53],[13.5,16],[9.4,31.76]],"id":41419601},{"atb":[[16.5,17.21],[46,4.44],[23,9.09]],"id":41419632},{"atb":[[36,5.71],[19,11.11],[14,20.52]],"id":41419599},{"atb":[[44,4.65],[27,10.26],[120,1.68]],"id":41419630},{"atb":[[75,2.7],[40,6.83],[200,1]],"id":41419597},{"atb":[[100,2.01],[50,5.44],[250,0.8]],"id":41419628},{"atb":[[8,28.58],[6,53.36],[12.5,17.4]],"id":41419626},{"atb":[[9,33.35],[20,10.52],[12.5,17.4]],"id":41419608},{"atb":[[8,38.11],[17.5,12.12],[10,22.23]],"id":41419639},{"atb":[[10.5,28.08],[26,8],[15.5,13.79]],"id":41419606},{"atb":[[16.5,12.9],[11.5,25.4],[28,7.41]],"id":41419637},{"atb":[[95,2.12],[48,5.67],[240,0.83]],"id":41419604},{"atb":[[38,5.4],[19.5,10.81],[14.5,19.76]],"id":41419635},{"atb":[[34,6.06],[18.5,11.43],[13.5,21.34]],"id":41419585},{"atb":[[16,13.34],[11,26.68],[27,7.69]],"id":41419612},{"atb":[[4.4,78.47],[7.8,29.42],[5.4,45.48]],"id":41419610},{"atb":[[32,6.45],[18,11.76],[13,22.23]],"id":41419625},{"atb":[[32,6.45],[18,11.76],[13,22.23]],"id":41419592},{"atb":[[3.7,98.82],[4.4,58.85],[5.9,40.84]],"id":41419623},{"atb":[[360,0.55],[210,0.95],[110,2.44]],"id":41419590},{"atb":[[8,28.58],[4.5,76.23],[5.5,44.47]],"id":41419621},{"atb":[[36,5.71],[19,11.11],[14,20.52]],"id":41419586},{"atb":[[320,0.62],[220,1.21],[470,0.42]],"id":41419633},{"atb":[[16.5,12.9],[11.5,25.4],[28,7.41]],"id":41419600},{"atb":[[36,5.71],[19,11.11],[14,20.52]],"id":41419598},{"atb":[[130,1.55],[65,4.17],[280,0.71]],"id":41419629},{"atb":[[5.6,58],[7.2,32.27],[10.5,21.06]],"id":41419596},{"atb":[[140,1.92],[390,0.51],[240,0.83]],"id":41419627},{"atb":[[9,33.35],[20,10.52],[12.5,17.4]],"id":41419594}],"con":true,"img":true}]}
{"op":"mcm","clk":"5348007851","pt":1646212320448,"mc":[{"id":"1.195453744","rc":[{"atb":[[280,0.71],[80,2.72],[180,1.48],[430,0.46],[55,3.26]],"id":41419640},{"atb":[[17.5,2.72],[19.5,10.8],[12,18.16],[8.8,34.15],[15,3.26]],"id":41419607},{"atb":[[36,2.72],[40,5.12],[20,10.51],[28,3.26],[15,19.02]],"id":41419605},{"atb":[[40,2.72],[42,4.87],[21,9.98],[30,3.26],[15.5,18.37]],"id":41419636},{"atb":[[8,28.54],[17.5,2.72],[6,53.27],[12.5,17.37],[15,3.26]],"id":41419603},{"atb":[[16.5,17.18],[40,3.26],[46,4.44],[23,9.07],[50,2.72]],"id":41419634},{"atb":[[32,3.26],[36,5.7],[42,2.72],[90,2.24],[23,12.1]],"id":41419611},{"atb":[[16.5,12.88],[32,2.72],[11.5,25.36],[26,3.26],[28,7.4]],"id":41419593},{"atb":[[16.5,17.18],[42,3.26],[46,4.44],[23,9.07],[55,2.72]],"id":41419591},{"atb":[[4.8,70.1],[8.6,26.29],[5.8,41.62],[9.8,2.72],[8.8,3.26]],"id":41419622},{"atb":[[7.2,42.96],[9.2,24.36],[23,3.26],[28,2.72],[15.5,13.77]],"id":41419589},{"atb":[[10,22.19],[5.5,59.19],[11,3.26],[13.5,2.72],[7,33.29]],"id":41419620},{"atb":[[16,13.31],[40,2.72],[11,26.63],[27,7.68],[30,3.26]],"id":41419587},{"atb":[[22,12.78],[13.5,15.98],[27,2.72],[9.4,31.71]],"id":41419601},{"atb":[[16.5,17.18],[65,2.72],[46,7.71],[23,9.07]],"id":41419632},{"atb":[[36,5.7],[19,11.1],[38,2.72],[14,20.49],[29,3.26]],"id":41419599},{"atb":[[85,2.72],[44,4.64],[27,10.24],[120,1.67],[60,3.26]],"id":41419630},{"atb":[[75,2.69],[40,6.82],[44,3.26],[200,1],[60,2.72]],"id":41419597},{"atb":[[75,3.26],[100,4.74],[50,5.43],[250,0.8]],"id":41419628},{"atb":[[8,28.54],[10,3.26],[6,53.27],[12.5,20.09]],"id":41419626},{"atb":[[9,33.29],[19.5,3.26],[20,10.51],[24,2.72],[12.5,17.37]],"id":41419608},{"atb":[[8,38.05],[17.5,12.1],[10,22.19],[20,3.26],[25,2.72]],"id":41419639},{"atb":[[10.5,28.03],[25,3.26],[26,7.98],[30,2.72],[15.5,13.77]],"id":41419606},{"atb":[[16.5,12.88],[36,2.72],[11.5,25.36],[28,10.67]],"id":41419637},{"atb":[[44,3.26],[95,2.12],[48,5.66],[240,0.83],[60,2.72]],"id":41419604},{"atb":[[38,5.4],[19.5,10.8],[40,2.72],[14.5,19.73],[30,3.26]],"id":41419635},{"atb":[[34,9.32],[18.5,11.41],[44,2.72],[13.5,21.3]],"id":41419585},{"atb":[[16,13.31],[20,3.26],[11,26.63],[25,2.72],[27,7.68]],"id":41419612},{"atb":[[10,3.26],[12.5,2.72],[4.4,78.34],[7.8,29.38],[5.4,45.4]],"id":41419610},{"atb":[[32,6.44],[18,11.74],[21,3.26],[13,22.19],[26,2.72]],"id":41419625},{"atb":[[32,6.44],[18,11.74],[38,2.72],[13,22.19],[29,3.26]],"id":41419592},{"atb":[[8,2.72],[3.7,98.66],[4.4,58.76],[7,3.26],[5.9,40.77]],"id":41419623},{"atb":[[65,3.26],[360,0.55],[90,2.72],[210,0.95],[110,2.44]],"id":41419590},{"atb":[[8,28.54],[4.5,76.11],[5.5,44.4],[9.8,2.72],[8.8,3.26]],"id":41419621},{"atb":[[34,3.26],[36,5.7],[19,11.1],[44,2.72],[14,20.49]],"id":41419586},{"atb":[[320,0.62],[85,3.26],[220,1.21],[470,0.42],[120,2.72]],"id":41419633},{"atb":[[16.5,12.88],[32,2.72],[11.5,25.36],[26,3.26],[28,7.4]],"id":41419600},{"atb":[[36,8.43],[19,11.1],[14,20.49],[28,3.26]],"id":41419598},{"atb":[[130,1.54],[65,4.16],[280,0.71],[75,3.26],[100,2.72]],"id":41419629},{"atb":[[5.6,57.91],[7.2,32.22],[17.5,2.72],[10.5,21.03],[15,3.26]],"id":41419596},{"atb":[[130,2.72],[140,1.91],[90,3.26],[390,0.51],[240,0.83]],"id":41419627},{"atb":[[16.5,3.26],[9,33.29],[19,2.72],[20,10.51],[12.5,17.37]],"id":41419594}],"con":true,"img":false}]}
{"op":"mcm","clk":"5348017796","pt":1646212515840,"mc":[{"id":"1.195453744","rc":[{"atb":[[17.5,0],[15,0]],"id":41419603}],"con":true,"img":false}]}
{"op":"mcm","clk":"5348017811","pt":1646212516150,"mc":[{"id":"1.195453744","rc":[{"atb":[[22,9.51],[27,0]],"id":41419601}],"con":true,"img":false}]}
{"op":"mcm","clk":"5348017817","pt":1646212516253,"mc":[{"id":"1.195453744","rc":[{"atb":[[9.8,0],[8.8,0]],"id":41419622}],"con":true,"img":false}]}
{"op":"mcm","clk":"5348017830","pt":1646212516561,"mc":[{"id":"1.195453744","rc":[{"atb":[[16,2.72],[13.5,3.26]],"id":41419603}],"con":true,"img":false}]}
{"op":"mcm","clk":"5348017853","pt":1646212516974,"mc":[{"id":"1.195453744","rc":[{"atb":[[20,3.26],[25,2.72]],"id":41419601}],"con":true,"img":false}]}
{"op":"mcm","clk":"5348017871","pt":1646212517284,"mc":[{"id":"1.195453744","rc":[{"atb":[[8.4,3.26],[9.4,2.72]],"id":41419622}],"con":true,"img":false}]}
{"op":"mcm","clk":"5348046827","pt":1646213046411,"mc":[{"id":"1.195453744","rc":[{"atb":[[8,0],[7,0]],"id":41419623},{"atb":[[9.8,0],[8.8,0]],"id":41419621}],"con":true,"img":false}]}
{"op":"mcm","clk":"5348046868","pt":1646213047088,"mc":[{"id":"1.195453744","rc":[{"atb":[[7.2,3.26],[8.2,2.72]],"id":41419623},{"atb":[[9,3.26],[10,2.72]],"id":41419621}],"con":true,"img":false}]}
{"op":"mcm","clk":"5348047320","pt":1646213054991,"mc":[{"id":"1.195453744","rc":[{"atb":[[16.5,0],[19,0]],"id":41419594}],"con":true,"img":false}]}
{"op":"mcm","clk":"5348047325","pt":1646213055097,"mc":[{"id":"1.195453744","rc":[{"atb":[[17.5,0],[15,0]],"id":41419607},{"atb":[[32,0],[42,0]],"id":41419611},{"atb":[[32,0],[26,0]],"id":41419593},{"atb":[[19.5,0],[24,0]],"id":41419608},{"atb":[[20,0],[25,0]],"id":41419612}],"con":true,"img":false}]}
{"op":"mcm","clk":"5348047353","pt":1646213055712,"mc":[{"id":"1.195453744","rc":[{"atb":[[16,2.72],[13.5,3.26]],"id":41419594}],"con":true,"img":false}]}
{"op":"mcm","clk":"5348047358","pt":1646213055819,"mc":[{"id":"1.195453744","rc":[{"atb":[[16,2.72],[13.5,3.26]],"id":41419607},{"atb":[[38,3.26],[48,2.72]],"id":41419611},{"atb":[[25,3.26],[30,2.72]],"id":41419593},{"atb":[[19,3.26],[23,2.72]],"id":41419608},{"atb":[[23,3.26],[28,2.72]],"id":41419612}],"con":true,"img":false}]}
{"op":"mcm","clk":"5348049995","pt":1646213103444,"mc":[{"id":"1.195453744","rc":[{"atb":[[23,0],[28,0]],"id":41419612}],"con":true,"img":false}]}
{"op":"mcm","clk":"5348049999","pt":1646213103546,"mc":[{"id":"1.195453744","rc":[{"atb":[[38,0],[48,0]],"id":41419611},{"atb":[[16,0],[13.5,0]],"id":41419594}],"con":true,"img":false}]}
{"op":"mcm","clk":"5348050033","pt":1646213104163,"mc":[{"id":"1.195453744","rc":[{"atb":[[20,3.26],[25,2.72]],"id":41419612}],"con":true,"img":false}]}
{"op":"mcm","clk":"5348050042","pt":1646213104370,"mc":[{"id":"1.195453744","rc":[{"atb":[[32,3.26],[42,2.72]],"id":41419611},{"atb":[[16.5,3.26],[19,2.72]],"id":41419594}],"con":true,"img":false}]}
{"op":"mcm","clk":"5348057641","pt":1646213242149,"mc":[{"id":"1.195453744","rc":[{"atb":[[80,0],[55,0]],"id":41419640},{"atb":[[10,0],[12.5,0]],"id":41419610},{"atb":[[24,3.26],[29,2.72]],"id":41419600}],"con":true,"img":false}]}
{"op":"mcm","clk":"5348057644","pt":1646213242247,"mc":[{"id":"1.195453744","rc":[{"atb":[[42,0],[55,0]],"id":41419591},{"atb":[[23,0],[28,0]],"id":41419589},{"atb":[[11,0],[13.5,0]],"id":41419620},{"atb":[[36,8.43],[28,3.26]],"id":41419599},{"atb":[[36,0],[28,7.4]],"id":41419637},{"atb":[[40,0],[30,0]],"id":41419635},{"atb":[[20,0],[25,0]],"id":41419612},{"atb":[[32,0],[26,0]],"id":41419600},{"atb":[[17.5,0],[15,0]],"id":41419596}],"con":true,"img":false}]}
{"op":"mcm","clk":"5348057652","pt":1646213242350,"mc":[{"id":"1.195453744","rc":[{"atb":[[40,0],[30,0]],"id":41419636},{"atb":[[38,0],[29,0]],"id":41419599},{"atb":[[44,0],[60,0]],"id":41419597}],"con":true,"img":false}]}
{"op":"mcm","clk":"5348057658","pt":1646213242456,"mc":[{"id":"1.195453744","rc":[{"atb":[[75,0],[100,2.01]],"id":41419628},{"atb":[[34,0],[44,0]],"id":41419586},{"atb":[[36,5.7],[28,0]],"id":41419598},{"atb":[[130,0],[85,3.26],[90,0],[120,2.72]],"id":41419627},{"atb":[[16.5,0],[19,0]],"id":41419594}],"con":true,"img":false}]}
{"op":"mcm","clk":"5348057661","pt":1646213242566,"mc":[{"id":"1.195453744","rc":[{"atb":[[34,2.72],[36,0],[27,3.26],[28,0]],"id":41419605},{"atb":[[40,0],[50,0]],"id":41419634},{"atb":[[32,0],[42,0]],"id":41419611},{"atb":[[40,0],[30,0]],"id":41419587},{"atb":[[65,0],[46,4.44]],"id":41419632},{"atb":[[25,0],[30,0]],"id":41419606},{"atb":[[9,0],[10,0]],"id":41419621},{"atb":[[70,3.26],[75,0],[95,2.72],[100,0]],"id":41419629}],"con":true,"img":false}]}
{"op":"mcm","clk":"5348057670","pt":1646213242723,"mc":[{"id":"1.195453744","rc":[{"atb":[[16,0],[17.5,2.72],[13.5,0],[15,3.26]],"id":41419607}],"con":true,"img":false}]}
{"op":"mcm","clk":"5348057677","pt":1646213242821,"mc":[{"id":"1.195453744","rc":[{"atb":[[10,3.26],[12.5,2.72]],"id":41419610}],"con":true,"img":false}]}
{"op":"mcm","clk":"5348057680","pt":1646213242925,"mc":[{"id":"1.195453744","rc":[{"atb":[[80,2.72],[55,3.26]],"id":41419640},{"atb":[[42,3.26],[55,2.72]],"id":41419591},{"atb":[[23,3.26],[28,2.72]],"id":41419589},{"atb":[[11,3.26],[13.5,2.72]],"id":41419620},{"atb":[[36,2.72],[28,10.67]],"id":41419637},{"atb":[[40,2.72],[30,3.26]],"id":41419635},{"atb":[[20,3.26],[25,2.72]],"id":41419612},{"atb":[[17.5,2.72],[15,3.26]],"id":41419596}],"con":true,"img":false}]}
{"op":"mcm","clk":"5348057685","pt":1646213243030,"mc":[{"id":"1.195453744","rc":[{"atb":[[40,2.72],[30,3.26]],"id":41419636},{"atb":[[44,3.26],[60,2.72]],"id":41419597}],"con":true,"img":false}]}
{"op":"mcm","clk":"5348057688","pt":1646213243135,"mc":[{"id":"1.195453744","rc":[{"atb":[[75,3.26],[100,4.74]],"id":41419628},{"atb":[[34,3.26],[44,2.72]],"id":41419586},{"atb":[[16.5,3.26],[19,2.72]],"id":41419594}],"con":true,"img":false}]}
{"op":"mcm","clk":"5348057691","pt":1646213243238,"mc":[{"id":"1.195453744","rc":[{"atb":[[40,3.26],[50,2.72]],"id":41419634},{"atb":[[32,3.26],[42,2.72]],"id":41419611},{"atb":[[40,2.72],[30,3.26]],"id":41419587},{"atb":[[65,2.72],[46,7.71]],"id":41419632},{"atb":[[25,3.26],[30,2.72]],"id":41419606},{"atb":[[9,3.26],[10,2.72]],"id":41419621}],"con":true,"img":false}]}
{"op":"mcm","clk":"5348057717","pt":1646213243914,"mc":[{"id":"1.195453744","rc":[{"atb":[[36,8.43],[28,3.26]],"id":41419598}],"con":true,"img":false}]}
{"op":"mcm","clk":"5348146143","pt":1646214555091,"mc":[{"id":"1.195453744","rc":[{"atb":[[17.5,0],[15,0]],"id":41419607},{"atb":[[32,0],[42,0]],"id":41419611},{"atb":[[20,0],[25,0]],"id":41419612},{"atb":[[16.5,0],[19,0]],"id":41419594}],"con":true,"img":false}]}
{"op":"mcm","clk":"5348146194","pt":1646214555767,"mc":[{"id":"1.195453744","rc":[{"atb":[[16,2.72],[13.5,3.26]],"id":41419607},{"atb":[[23,3.26],[28,2.72]],"id":41419612},{"atb":[[16,2.72],[13.5,3.26]],"id":41419594}],"con":true,"img":false}]}
{"op":"mcm","clk":"5348146204","pt":1646214555872,"mc":[{"id":"1.195453744","rc":[{"atb":[[38,3.26],[48,2.72]],"id":41419611}],"con":true,"img":false}]}
{"op":"mcm","clk":"5348155803","pt":1646214693581,"mc":[{"id":"1.195453744","rc":[{"atb":[[38,0],[48,0]],"id":41419611},{"atb":[[23,0],[28,0]],"id":41419612}],"con":true,"img":false}]}
{"op":"mcm","clk":"5348155856","pt":1646214694561,"mc":[{"id":"1.195453744","rc":[{"atb":[[32,3.26],[42,2.72]],"id":41419611},{"atb":[[20,3.26],[25,2.72]],"id":41419612}],"con":true,"img":false}]}
{"op":"mcm","clk":"5348179858","pt":1646215058033,"mc":[{"id":"1.195453744","rc":[{"atb":[[16,0]],"id":41419607}],"con":true,"img":false}]}
{"op":"mcm","clk":"5348179864","pt":1646215058137,"mc":[{"id":"1.195453744","rc":[{"atb":[[13.5,0]],"id":41419607},{"atb":[[16,0],[13.5,0]],"id":41419594}],"con":true,"img":false}]}
{"op":"mcm","clk":"5348179913","pt":1646215059117,"mc":[{"id":"1.195453744","rc":[{"atb":[[17.5,2.72],[15,3.26]],"id":41419607},{"atb":[[16.5,3.26],[19,2.72]],"id":41419594}],"con":true,"img":false}]}
{"op":"mcm","clk":"5348214548","pt":1646215538136,"mc":[{"id":"1.195453744","rc":[{"atb":[[16,0],[13.5,0]],"id":41419603},{"atb":[[8.4,0],[9.4,0]],"id":41419622}],"con":true,"img":false}]}
{"op":"mcm","clk":"5348214612","pt":1646215538923,"mc":[{"id":"1.195453744","rc":[{"atb":[[16.5,2.72],[14,3.26]],"id":41419603},{"atb":[[9.6,2.72],[8.6,29.56]],"id":41419622}],"con":true,"img":false}]}
{"op":"mcm","clk":"5348233794","pt":1646215755098,"mc":[{"id":"1.195453744","rc":[{"atb":[[17.5,0],[15,0]],"id":41419607},{"atb":[[32,0],[42,0]],"id":41419611},{"atb":[[36,0],[28,7.4]],"id":41419637},{"atb":[[20,0],[25,0]],"id":41419612},{"atb":[[16.5,0],[19,0]],"id":41419594}],"con":true,"img":false}]}
{"op":"mcm","clk":"5348233852","pt":1646215755768,"mc":[{"id":"1.195453744","rc":[{"atb":[[16,2.72],[13.5,3.26]],"id":41419607},{"atb":[[23,3.26],[28,2.72]],"id":41419612}],"con":true,"img":false}]}
{"op":"mcm","clk":"5348233858","pt":1646215755873,"mc":[{"id":"1.195453744","rc":[{"atb":[[38,3.26],[48,2.72]],"id":41419611},{"atb":[[34,2.72],[27,3.26]],"id":41419637},{"atb":[[16,2.72],[13.5,3.26]],"id":41419594}],"con":true,"img":false}]}
{"op":"mcm","clk":"5348235539","pt":1646215773757,"mc":[{"id":"1.195453744","rc":[{"atb":[[38,0],[48,0]],"id":41419611},{"atb":[[23,0],[28,0]],"id":41419612}],"con":true,"img":false}]}
{"op":"mcm","clk":"5348235589","pt":1646215774480,"mc":[{"id":"1.195453744","rc":[{"atb":[[20,3.26],[25,2.72]],"id":41419612}],"con":true,"img":false}]}
{"op":"mcm","clk":"5348235595","pt":1646215774584,"mc":[{"id":"1.195453744","rc":[{"atb":[[32,3.26],[42,2.72]],"id":41419611}],"con":true,"img":false}]}
{"op":"mcm","clk":"5348255179","pt":1646215980709,"mc":[{"id":"1.195453744","rc":[{"atb":[[11,0],[13.5,0]],"id":41419620}],"con":true,"img":false}]}
{"op":"mcm","clk":"5348255216","pt":1646215980927,"mc":[{"id":"1.195453744","rc":[{"atb":[[36,5.7],[28,0]],"id":41419598}],"con":true,"img":false}]}
{"op":"mcm","clk":"5348255278","pt":1646215981407,"mc":[{"id":"1.195453744","rc":[{"atb":[[11.5,3.26],[14,2.72]],"id":41419620}],"con":true,"img":false}]}
{"op":"mcm","clk":"5348255316","pt":1646215981719,"mc":[{"id":"1.195453744","rc":[{"atb":[[34,2.72],[27,3.26]],"id":41419598}],"con":true,"img":false}]}
{"op":"mcm","clk":"5348280506","pt":1646216137944,"mc":[{"id":"1.195453744","rc":[{"atb":[[16,0],[13.5,0]],"id":41419607},{"atb":[[16,0],[13.5,0]],"id":41419594}],"con":true,"img":false}]}
{"op":"mcm","clk":"5348280632","pt":1646216138682,"mc":[{"id":"1.195453744","rc":[{"atb":[[17.5,2.72],[15,3.26]],"id":41419607},{"atb":[[16.5,3.26],[19,2.72]],"id":41419594}],"con":true,"img":false}]}
{"op":"mcm","clk":"5348372954","pt":1646216997954,"mc":[{"id":"1.195453744","rc":[{"atb":[[20,0],[25,0]],"id":41419612}],"con":true,"img":false}]}
{"op":"mcm","clk":"5348372984","pt":1646216998369,"mc":[{"id":"1.195453744","rc":[{"atb":[[17.5,0],[15,0]],"id":41419607},{"atb":[[32,0],[42,0]],"id":41419611},{"atb":[[16.5,0],[19,0]],"id":41419594}],"con":true,"img":false}]}
{"op":"mcm","clk":"5348373032","pt":1646216998951,"mc":[{"id":"1.195453744","rc":[{"atb":[[22,3.26],[27,10.4]],"id":41419612}],"con":true,"img":false}]}
{"op":"mcm","clk":"5348373038","pt":1646216999051,"mc":[{"id":"1.195453744","rc":[{"atb":[[16,2.72],[13.5,3.26]],"id":41419594}],"con":true,"img":false}]}
{"op":"mcm","clk":"5348373063","pt":1646216999373,"mc":[{"id":"1.195453744","rc":[{"atb":[[16,2.72],[13.5,3.26]],"id":41419607}],"con":true,"img":false}]}
{"op":"mcm","clk":"5348373075","pt":1646216999475,"mc":[{"id":"1.195453744","rc":[{"atb":[[38,3.26],[48,2.72]],"id":41419611}],"con":true,"img":false}]}
{"op":"mcm","clk":"5348381859","pt":1646217093576,"mc":[{"id":"1.195453744","rc":[{"atb":[[38,0],[48,0]],"id":41419611}],"con":true,"img":false}]}
{"op":"mcm","clk":"5348381886","pt":1646217093890,"mc":[{"id":"1.195453744","rc":[{"atb":[[22,0],[27,7.68]],"id":41419612}],"con":true,"img":false}]}
{"op":"mcm","clk":"5348381943","pt":1646217094400,"mc":[{"id":"1.195453744","rc":[{"atb":[[32,3.26],[42,2.72]],"id":41419611}],"con":true,"img":false}]}
{"op":"mcm","clk":"5348381972","pt":1646217094673,"mc":[{"id":"1.195453744","rc":[{"atb":[[20,3.26],[25,2.72]],"id":41419612}],"con":true,"img":false}]}
{"op":"mcm","clk":"5348396149","pt":1646217255077,"mc":[{"id":"1.195453744","rc":[{"atb":[[34,0],[27,0]],"id":41419637}],"con":true,"img":false}]}
{"op":"mcm","clk":"5348396213","pt":1646217255857,"mc":[{"id":"1.195453744","rc":[{"atb":[[32,2.72],[26,3.26]],"id":41419637}],"con":true,"img":false}]}
{"op":"mcm","clk":"5348396291","pt":1646217256897,"mc":[{"id":"1.195453744","rc":[{"atb":[[16,0],[13.5,0]],"id":41419594}],"con":true,"img":false}]}
{"op":"mcm","clk":"5348396320","pt":1646217257158,"mc":[{"id":"1.195453744","rc":[{"atb":[[16,0]],"id":41419607}],"con":true,"img":false}]}
{"op":"mcm","clk":"5348396327","pt":1646217257262,"mc":[{"id":"1.195453744","rc":[{"atb":[[13.5,0]],"id":41419607}],"con":true,"img":false}]}
{"op":"mcm","clk":"5348396380","pt":1646217257784,"mc":[{"id":"1.195453744","rc":[{"atb":[[16.5,3.26],[19,2.72]],"id":41419594}],"con":true,"img":false}]}
{"op":"mcm","clk":"5348396391","pt":1646217257897,"mc":[{"id":"1.195453744","rc":[{"atb":[[17.5,2.72]],"id":41419607}],"con":true,"img":false}]}
{"op":"mcm","clk":"5348396421","pt":1646217258202,"mc":[{"id":"1.195453744","rc":[{"atb":[[15,3.26]],"id":41419607}],"con":true,"img":false}]}
{"op":"mcm","clk":"5348400983","pt":1646217306856,"mc":[{"id":"1.195453744","rc":[{"atb":[[16,2.98]],"id":41419640},{"atl":[[1000,2]],"id":41419640},{"atb":[[3.8,21.6]],"id":41419607},{"atl":[[460,2]],"id":41419607},{"atb":[[11,10]],"id":41419605},{"atl":[[940,2]],"id":41419605},{"atb":[[10.5,9.74]],"id":41419636},{"atl":[[930,2]],"id":41419636},{"atb":[[6.8,17.24]],"id":41419603},{"atl":[[710,2]],"id":41419603},{"atb":[[20,5.26]],"id":41419634},{"atl":[[1000,2]],"id":41419634},{"atb":[[6.4,6.54]],"id":41419611},{"atl":[[640,2]],"id":41419611},{"atb":[[6.8,14.8]],"id":41419593},{"atl":[[610,2]],"id":41419593},{"atb":[[12,8.88]],"id":41419591},{"atb":[[4.5,28.57]],"id":41419622},{"atl":[[500,2]],"id":41419622},{"atb":[[16,6.67]],"id":41419589},{"atl":[[1000,2]],"id":41419589},{"atb":[[5.9,20.41]],"id":41419620},{"atl":[[580,2]],"id":41419620},{"atb":[[12.5,8.7]],"id":41419587},{"atl":[[980,2]],"id":41419587},{"atb":[[6.2,19.04]],"id":41419601},{"atl":[[620,2]],"id":41419601},{"atb":[[25,4.17]],"id":41419632},{"atl":[[1000,2]],"id":41419632},{"atb":[[19.5,5.41]],"id":41419599},{"atl":[[1000,2]],"id":41419599},{"atb":[[23,4.55]],"id":41419630},{"atl":[[1000,2]],"id":41419630},{"atb":[[7.8,5.44]],"id":41419597},{"atl":[[830,2]],"id":41419597},{"atb":[[26,4]],"id":41419628},{"atb":[[3.85,35.09]],"id":41419626},{"atl":[[480,2]],"id":41419626},{"atb":[[4.9,21.02]],"id":41419608},{"atl":[[540,2]],"id":41419608},{"atb":[[6.4,18.52]],"id":41419639},{"atl":[[640,2]],"id":41419639},{"atb":[[6.2,15.98]],"id":41419606},{"atl":[[630,2]],"id":41419606},{"atb":[[6.4,14.8]],"id":41419637},{"atl":[[580,2]],"id":41419637},{"atb":[[22,4.76]],"id":41419604},{"atl":[[1000,2]],"id":41419604},{"atb":[[7,10.8]],"id":41419635},{"atl":[[740,2]],"id":41419635},{"atb":[[20,5.26]],"id":41419585},{"atl":[[1000,2]],"id":41419585},{"atb":[[5,15.36]],"id":41419612},{"atl":[[520,2]],"id":41419612},{"atb":[[3.85,35.09]],"id":41419610},{"atl":[[410,2]],"id":41419610},{"atb":[[5.4,12.9]],"id":41419625},{"atl":[[560,2]],"id":41419625},{"atb":[[7.2,12.9]],"id":41419592},{"atl":[[780,2]],"id":41419592},{"atb":[[3.1,47.62]],"id":41419623},{"atl":[[300,2]],"id":41419623},{"atb":[[27,3.85]],"id":41419590},{"atb":[[3.6,38.46]],"id":41419621},{"atl":[[420,2]],"id":41419621},{"atb":[[26,4]],"id":41419586},{"atb":[[27,2.44]],"id":41419633},{"atb":[[7,14.8]],"id":41419600},{"atl":[[750,2]],"id":41419600},{"atb":[[6.8,11.42]],"id":41419598},{"atl":[[620,2]],"id":41419598},{"atb":[[27,3.85]],"id":41419629},{"atb":[[4.8,26.32]],"id":41419596},{"atl":[[510,2]],"id":41419596},{"atb":[[28,3.7]],"id":41419627},{"atb":[[3.85,21.02]],"id":41419594},{"atl":[[480,2]],"id":41419594}],"con":true,"img":false}]}
{"op":"mcm","clk":"5348427600","pt":1646217597048,"mc":[{"id":"1.195453744","rc":[{"atb":[[32,0],[26,0]],"id":41419637}],"con":true,"img":false}]}
{"op":"mcm","clk":"5348427660","pt":1646217597728,"mc":[{"id":"1.195453744","rc":[{"atb":[[34,2.72],[27,3.26]],"id":41419637}],"con":true,"img":false}]}
{"op":"mcm","clk":"5348442599","pt":1646217749705,"mc":[{"id":"1.195453744","rc":[{"atb":[[16,0],[28,2.98]],"id":41419640},{"atb":[[6.4,0],[7.8,6.54]],"id":41419611},{"atl":[[1000,2]],"id":41419591},{"atb":[[7.8,14.71]],"id":41419639},{"atb":[[10,10.8],[7,0]],"id":41419635},{"atb":[[5,0]],"id":41419612},{"atl":[[560,0]],"id":41419625},{"atl":[[300,0]],"id":41419623},{"atl":[[750,0]],"id":41419600}],"con":true,"img":false}]}
{"op":"mcm","clk":"5348442610","pt":1646217749821,"mc":[{"id":"1.195453744","rc":[{"atb":[[5,21.6],[3.8,0]],"id":41419607},{"atb":[[11,0],[13.5,8]],"id":41419605},{"atl":[[940,0],[930,2]],"id":41419605},{"atb":[[19.5,5.41],[10.5,0]],"id":41419636},{"atl":[[900,2],[930,0]],"id":41419636},{"atb":[[8.2,13.89],[6.8,0]],"id":41419603},{"atl":[[620,2],[710,0]],"id":41419603},{"atl":[[940,2],[1000,0]],"id":41419634},{"atb":[[6.8,0],[9.4,11.9]],"id":41419593},{"atl":[[570,2],[610,0]],"id":41419593},{"atb":[[4.5,0],[5.3,23.26]],"id":41419622},{"atl":[[460,2],[500,0]],"id":41419622},{"atb":[[16,0],[10,11.11]],"id":41419589},{"atl":[[850,2],[1000,0]],"id":41419589},{"atb":[[4.9,25.64],[5.9,0]],"id":41419620},{"atl":[[580,0],[490,2]],"id":41419620},{"atb":[[8.2,13.89],[12.5,0]],"id":41419587},{"atl":[[790,2],[980,0]],"id":41419587},{"atb":[[6.2,0],[7.6,15.15]],"id":41419601},{"atl":[[580,2],[620,0]],"id":41419601},{"atb":[[32,3.23],[25,0]],"id":41419632},{"atb":[[19.5,0],[15.5,6.9]],"id":41419599},{"atl":[[960,2],[1000,0]],"id":41419599},{"atl":[[930,2],[1000,0]],"id":41419630},{"atb":[[10.5,5.44],[7.8,0]],"id":41419597},{"atl":[[780,2],[830,0]],"id":41419597},{"atb":[[36,2.86],[26,0]],"id":41419628},{"atb":[[3.85,0],[4.2,31.25]],"id":41419626},{"atl":[[450,2],[480,0]],"id":41419626},{"atb":[[6.4,18.52],[4.9,0]],"id":41419608},{"atb":[[6.4,0]],"id":41419639},{"atb":[[6.2,0],[8.2,13.89]],"id":41419606},{"atl":[[630,0],[620,2]],"id":41419606},{"atb":[[6.4,0],[8.4,13.51]],"id":41419637},{"atb":[[22,0],[27,3.85]],"id":41419604},{"atl":[[960,2],[1000,0]],"id":41419604},{"atb":[[20,0],[14,7.69]],"id":41419585},{"atl":[[940,2],[1000,0]],"id":41419585},{"atb":[[6.8,15.36]],"id":41419612},{"atb":[[4.5,28.57],[3.85,0]],"id":41419610},{"atb":[[6.8,12.9],[5.4,0]],"id":41419625},{"atl":[[550,2]],"id":41419625},{"atb":[[7.2,0],[9.2,12.2]],"id":41419592},{"atl":[[710,2],[780,0]],"id":41419592},{"atb":[[3.1,0],[3.35,42.55]],"id":41419623},{"atl":[[210,2]],"id":41419623},{"atb":[[36,2.86],[27,0]],"id":41419590},{"atb":[[3.6,0],[3.9,34.48]],"id":41419621},{"atl":[[350,2],[420,0]],"id":41419621},{"atb":[[26,0],[28,3.7]],"id":41419586},{"atl":[[1000,2]],"id":41419586},{"atb":[[36,2.44],[27,0]],"id":41419633},{"atb":[[9.2,12.2],[7,0]],"id":41419600},{"atl":[[730,2]],"id":41419600},{"atb":[[6.8,0],[8.8,11.42]],"id":41419598},{"atb":[[36,2.86],[27,0]],"id":41419629},{"atb":[[4.8,0],[5.5,22.22]],"id":41419596},{"atl":[[470,2],[510,0]],"id":41419596},{"atb":[[38,2.7],[28,0]],"id":41419627},{"atb":[[4.8,21.02],[3.85,0]],"id":41419594},{"atl":[[470,2],[480,0]],"id":41419594}],"con":true,"img":false}]}
{"op":"mcm","clk":"5348442636","pt":1646217750027,"mc":[{"id":"1.195453744","rc":[{"atb":[[7.2,0],[8.2,0]],"id":41419623},{"atb":[[16.5,0],[19,0]],"id":41419594}],"con":true,"img":false}]}
{"op":"mcm","clk":"5348442643","pt":1646217750080,"mc":[{"id":"1.195453744","rc":[{"atb":[[17.5,0],[15,0]],"id":41419607},{"atb":[[32,0],[42,0]],"id":41419611}],"con":true,"img":false}]}
{"op":"mcm","clk":"5348442711","pt":1646217750709,"mc":[{"id":"1.195453744","rc":[{"atb":[[6.4,3.26],[7.4,2.72]],"id":41419623},{"atb":[[17,3.26],[19.5,2.72]],"id":41419594}],"con":true,"img":false}]}
{"op":"mcm","clk":"5348442720","pt":1646217750810,"mc":[{"id":"1.195453744","rc":[{"atb":[[19,3.26],[23,2.72]],"id":41419607},{"atb":[[38,3.26],[48,2.72]],"id":41419611}],"con":true,"img":false}]}
{"op":"mcm","clk":"5348442944","pt":1646217753112,"mc":[{"id":"1.195453744","rc":[{"atl":[[460,0]],"id":41419607}],"con":true,"img":false}]}
{"op":"mcm","clk":"5348442955","pt":1646217753214,"mc":[{"id":"1.195453744","rc":[{"atl":[[450,2]],"id":41419607}],"con":true,"img":false}]}
{"op":"mcm","clk":"5348442977","pt":1646217753476,"mc":[{"id":"1.195453744","rc":[{"atb":[[19,0],[23,0]],"id":41419607}],"con":true,"img":false}]}
{"op":"mcm","clk":"5348443046","pt":1646217754211,"mc":[{"id":"1.195453744","rc":[{"atb":[[18.5,3.26],[22,2.72]],"id":41419607}],"con":true,"img":false}]}
{"op":"mcm","clk":"5348443127","pt":1646217754996,"mc":[{"id":"1.195453744","rc":[{"atl":[[900,0],[920,2]],"id":41419636},{"atl":[[940,0],[1000,2]],"id":41419634},{"atl":[[460,2]],"id":41419626}],"con":true,"img":false}]}
{"op":"mcm","clk":"5348443155","pt":1646217755312,"mc":[{"id":"1.195453744","rc":[{"atl":[[450,0]],"id":41419626}],"con":true,"img":false}]}
{"op":"mcm","clk":"5348443280","pt":1646217756415,"mc":[{"id":"1.195453744","rc":[{"atb":[[17,0],[19.5,0]],"id":41419594}],"con":true,"img":false}]}
{"op":"mcm","clk":"5348443346","pt":1646217757203,"mc":[{"id":"1.195453744","rc":[{"atb":[[16,3.26],[18.5,2.72]],"id":41419594}],"con":true,"img":false}]}
{"op":"mcm","clk":"5348443408","pt":1646217757781,"mc":[{"id":"1.195453744","rc":[{"atb":[[34,0],[27,0]],"id":41419598}],"con":true,"img":false}]}
{"op":"mcm","clk":"5348443484","pt":1646217758514,"mc":[{"id":"1.195453744","rc":[{"atb":[[36,8.43],[28,3.26]],"id":41419598}],"con":true,"img":false}]}
{"op":"mcm","clk":"5348444484","pt":1646217768628,"mc":[{"id":"1.195453744","rc":[{"atb":[[7.8,0],[9.4,6.54]],"id":41419611},{"atb":[[10,33.3],[7.8,0]],"id":41419639},{"atb":[[10,0],[13,8.33]],"id":41419635}],"con":true,"img":false}]}
{"op":"mcm","clk":"5348444500","pt":1646217768739,"mc":[{"id":"1.195453744","rc":[{"atb":[[5,0],[5.9,20.41]],"id":41419607},{"atb":[[16.5,6.45],[13.5,0]],"id":41419605},{"atl":[[840,2],[930,0]],"id":41419605},{"atb":[[19.5,0],[25,4.17]],"id":41419636},{"atl":[[580,2],[620,0]],"id":41419603},{"atl":[[570,0],[560,2]],"id":41419593},{"atl":[[430,2],[460,0]],"id":41419622},{"atb":[[10,0],[13,8.33]],"id":41419589},{"atl":[[780,2],[850,0]],"id":41419589},{"atb":[[6,20],[4.9,0]],"id":41419620},{"atl":[[460,2],[490,0]],"id":41419620},{"atb":[[10.5,10.53],[8.2,0]],"id":41419587},{"atl":[[730,2],[790,0]],"id":41419587},{"atl":[[550,2],[580,0]],"id":41419601},{"atb":[[19,16.66],[15.5,0]],"id":41419599},{"atl":[[870,2],[960,0]],"id":41419599},{"atl":[[780,0],[770,2]],"id":41419597},{"atb":[[5.1,24.39],[4.2,0]],"id":41419626},{"atb":[[6.4,0],[7.6,15.15]],"id":41419608},{"atl":[[590,2],[620,0]],"id":41419606},{"atl":[[940,2],[960,0]],"id":41419604},{"atb":[[18,5.88],[14,0]],"id":41419585},{"atl":[[850,2],[940,0]],"id":41419585},{"atb":[[8.6,13.16],[6.8,0]],"id":41419612},{"atl":[[520,2],[550,0]],"id":41419625},{"atl":[[660,2],[710,0]],"id":41419592},{"atl":[[160,2],[210,0]],"id":41419623},{"atb":[[4.5,104.68],[3.9,0]],"id":41419621},{"atl":[[320,2],[350,0]],"id":41419621},{"atb":[[34,6.29],[28,0]],"id":41419586},{"atl":[[650,2],[730,0]],"id":41419600},{"atl":[[440,2],[470,0]],"id":41419596},{"atl":[[440,2],[470,0]],"id":41419594}],"con":true,"img":false}]}
{"op":"mcm","clk":"5348462839","pt":1646217933388,"mc":[{"id":"1.195453744","rc":[{"atb":[[7.4,0]],"id":41419623}],"con":true,"img":false}]}
{"op":"mcm","clk":"5348462855","pt":1646217933490,"mc":[{"id":"1.195453744","rc":[{"atb":[[6.4,0]],"id":41419623}],"con":true,"img":false}]}
{"op":"mcm","clk":"5348462931","pt":1646217934073,"mc":[{"id":"1.195453744","rc":[{"atb":[[7.6,2.72]],"id":41419623}],"con":true,"img":false}]}
{"op":"mcm","clk":"5348462956","pt":1646217934284,"mc":[{"id":"1.195453744","rc":[{"atb":[[6.6,3.26]],"id":41419623}],"con":true,"img":false}]}
{"op":"mcm","clk":"5348469374","pt":1646217987394,"mc":[{"id":"1.195453744","rc":[{"atl":[[730,0],[740,2]],"id":41419587}],"con":true,"img":false}]}
{"op":"mcm","clk":"5348472706","pt":1646218015113,"mc":[{"id":"1.195453744","rc":[{"atl":[[730,2],[740,0]],"id":41419587}],"con":true,"img":false}]}
{"op":"mcm","clk":"5348508383","pt":1646218300397,"mc":[{"id":"1.195453744","rc":[{"atl":[[920,0],[910,2]],"id":41419636},{"atl":[[780,0],[770,2]],"id":41419589},{"atl":[[530,2],[550,0]],"id":41419601},{"atl":[[540,0],[530,2]],"id":41419608}],"con":true,"img":false}]}
{"op":"mcm","clk":"5348508410","pt":1646218300710,"mc":[{"id":"1.195453744","rc":[{"atb":[[7.6,0],[6.6,0]],"id":41419623}],"con":true,"img":false}]}
{"op":"mcm","clk":"5348508486","pt":1646218301440,"mc":[{"id":"1.195453744","rc":[{"atb":[[25,0],[27,3.85]],"id":41419636},{"atl":[[910,0],[920,2]],"id":41419636},{"atl":[[570,2],[580,0]],"id":41419603},{"atl":[[860,2],[870,0]],"id":41419599},{"atl":[[910,2],[930,0]],"id":41419630},{"atb":[[10.5,0],[13.5,5.44]],"id":41419597}],"con":true,"img":false}]}
{"op":"mcm","clk":"5348508499","pt":1646218301544,"mc":[{"id":"1.195453744","rc":[{"atb":[[6.4,3.26],[7.4,2.72]],"id":41419623}],"con":true,"img":false}]}
{"op":"mcm","clk":"5348508521","pt":1646218301699,"mc":[{"id":"1.195453744","rc":[{"atb":[[16,0],[18.5,0]],"id":41419594}],"con":true,"img":false}]}
{"op":"mcm","clk":"5348508617","pt":1646218302528,"mc":[{"id":"1.195453744","rc":[{"atb":[[6.4,0],[7.4,0]],"id":41419623},{"atb":[[17,3.26],[19.5,2.72]],"id":41419594}],"con":true,"img":false}]}
{"op":"mcm","clk":"5348508698","pt":1646218303258,"mc":[{"id":"1.195453744","rc":[{"atb":[[7.2,2.72],[6.2,3.26]],"id":41419623}],"con":true,"img":false}]}
{"op":"mcm","clk":"5348509243","pt":1646218308144,"mc":[{"id":"1.195453744","rc":[{"atl":[[550,2]],"id":41419603},{"atb":[[32,3.23],[20,0]],"id":41419634},{"atb":[[12,0],[29,3.57]],"id":41419591},{"atl":[[730,2],[770,0]],"id":41419589},{"atb":[[7.6,0]],"id":41419601},{"atb":[[5.6,21.74],[5.1,0]],"id":41419626},{"atl":[[460,0],[450,2]],"id":41419626},{"atb":[[7.6,0],[2.96,25.66]],"id":41419608},{"atb":[[8.4,0]],"id":41419637},{"atl":[[380,2],[410,0]],"id":41419610},{"atl":[[520,0],[510,2]],"id":41419625},{"atl":[[140,2]],"id":41419623},{"atl":[[620,2],[650,0]],"id":41419600},{"atb":[[10,11.11],[8.8,0]],"id":41419598}],"con":true,"img":false}]}
{"op":"mcm","clk":"5348509255","pt":1646218308248,"mc":[{"id":"1.195453744","rc":[{"atb":[[5.3,23.26],[5.9,0]],"id":41419607},{"atl":[[570,0]],"id":41419603},{"atb":[[2.96,24.67]],"id":41419601},{"atb":[[9.6,11.63]],"id":41419637},{"atl":[[160,0]],"id":41419623}],"con":true,"img":false}]}
{"op":"mcm","clk":"5348509955","pt":1646218313993,"mc":[{"id":"1.195453744","rc":[{"atl":[[830,2],[840,0]],"id":41419605},{"atb":[[8,14.29],[9.4,0]],"id":41419593},{"atl":[[730,0],[720,2]],"id":41419587},{"atl":[[530,0],[520,2]],"id":41419601},{"atb":[[32,3.23],[23,0]],"id":41419630},{"atl":[[590,0],[580,2]],"id":41419606},{"atl":[[800,2],[850,0]],"id":41419585},{"atb":[[6.8,0],[8.4,12.9]],"id":41419625},{"atl":[[660,0],[650,2]],"id":41419592},{"atl":[[620,0],[610,2]],"id":41419598},{"atl":[[430,2],[440,0]],"id":41419594}],"con":true,"img":false}]}
{"op":"mcm","clk":"5348509992","pt":1646218314248,"mc":[{"id":"1.195453744","rc":[{"atb":[[18.5,0],[22,0]],"id":41419607},{"atb":[[17,0],[19.5,0]],"id":41419594}],"con":true,"img":false}]}
{"op":"mcm","clk":"5348510053","pt":1646218314767,"mc":[{"id":"1.195453744","rc":[{"atl":[[790,2]],"id":41419599}],"con":true,"img":false}]}
{"op":"mcm","clk":"5348510071","pt":1646218314876,"mc":[{"id":"1.195453744","rc":[{"atl":[[860,0]],"id":41419599}],"con":true,"img":false}]}
{"op":"mcm","clk":"5348510083","pt":1646218314975,"mc":[{"id":"1.195453744","rc":[{"atb":[[18,3.26],[21,2.72]],"id":41419607},{"atb":[[16,3.26],[18.5,2.72]],"id":41419594}],"con":true,"img":false}]}
{"op":"mcm","clk":"5348510860","pt":1646218321376,"mc":[{"id":"1.195453744","rc":[{"atl":[[600,2],[620,0]],"id":41419600}],"con":true,"img":false}]}
{"op":"mcm","clk":"5348511073","pt":1646218323162,"mc":[{"id":"1.195453744","rc":[{"atb":[[32,0],[24,4.35]],"id":41419630}],"con":true,"img":false}]}
{"op":"mcm","clk":"5348514847","pt":1646218355108,"mc":[{"id":"1.195453744","rc":[{"atl":[[990,2],[1000,0]],"id":41419632}],"con":true,"img":false}]}
{"op":"mcm","clk":"5348516663","pt":1646218371235,"mc":[{"id":"1.195453744","rc":[{"atb":[[18,0],[21,5]],"id":41419585}],"con":true,"img":false}]}
{"op":"mcm","clk":"5348521071","pt":1646218416802,"mc":[{"id":"1.195453744","rc":[{"atl":[[830,0],[820,2]],"id":41419605},{"atb":[[27,0]],"id":41419636},{"atl":[[890,2],[920,0]],"id":41419636},{"atb":[[4.6,27.78],[5.3,0]],"id":41419622},{"atl":[[430,0],[420,2]],"id":41419622},{"atb":[[16,6.67],[13,0]],"id":41419589},{"atl":[[520,0],[500,2]],"id":41419601},{"atl":[[500,2]],"id":41419608},{"atb":[[17,6.25],[13,0]],"id":41419635},{"atl":[[140,0],[120,2]],"id":41419623},{"atb":[[32,3.23],[34,3.26]],"id":41419586}],"con":true,"img":false}]}
{"op":"mcm","clk":"5348521080","pt":1646218416902,"mc":[{"id":"1.195453744","rc":[{"atb":[[22,4.76]],"id":41419636},{"atl":[[530,0]],"id":41419608}],"con":true,"img":false}]}
{"op":"mcm","clk":"5348521102","pt":1646218417212,"mc":[{"id":"1.195453744","rc":[{"atb":[[7.2,0],[6.2,0]],"id":41419623}],"con":true,"img":false}]}
{"op":"mcm","clk":"5348521170","pt":1646218417991,"mc":[{"id":"1.195453744","rc":[{"atb":[[6,3.26],[7,2.72]],"id":41419623}],"con":true,"img":false}]}
{"op":"mcm","clk":"5348523310","pt":1646218441237,"mc":[{"id":"1.195453744","rc":[{"atb":[[18,0],[21,0]],"id":41419607},{"atb":[[16,0],[18.5,0]],"id":41419594}],"con":true,"img":false}]}
{"op":"mcm","clk":"5348523373","pt":1646218441968,"mc":[{"id":"1.195453744","rc":[{"atb":[[18.5,3.26],[22,2.72]],"id":41419607},{"atb":[[16.5,3.26],[19,2.72]],"id":41419594}],"con":true,"img":false}]}
{"op":"mcm","clk":"5348524702","pt":1646218455343,"mc":[{"id":"1.195453744","rc":[{"atb":[[16,5.44],[13.5,0]],"id":41419597}],"con":true,"img":false}]}
{"op":"mcm","clk":"5348538462","pt":1646218587129,"mc":[{"id":"1.195453744","rc":[{"atb":[[16.5,0],[14,0]],"id":41419603},{"atb":[[19,0],[23,0]],"id":41419608}],"con":true,"img":false}]}
{"op":"mcm","clk":"5348538471","pt":1646218587237,"mc":[{"id":"1.195453744","rc":[{"atb":[[9.6,0],[8.6,26.29]],"id":41419622},{"atb":[[20,0],[25,0]],"id":41419601},{"atb":[[36,5.7],[28,0]],"id":41419599},{"atb":[[24,0],[29,0]],"id":41419600}],"con":true,"img":false}]}
{"op":"mcm","clk":"5348538527","pt":1646218587961,"mc":[{"id":"1.195453744","rc":[{"atb":[[17,2.72],[14.5,3.26]],"id":41419603},{"atb":[[38,2.72],[29,3.26]],"id":41419599},{"atb":[[19.5,3.26],[24,2.72]],"id":41419608},{"atb":[[25,3.26],[30,2.72]],"id":41419600}],"con":true,"img":false}]}
{"op":"mcm","clk":"5348538537","pt":1646218588066,"mc":[{"id":"1.195453744","rc":[{"atb":[[9.8,2.72],[8.8,3.26]],"id":41419622},{"atb":[[21,3.26],[26,2.72]],"id":41419601}],"con":true,"img":false}]}
{"op":"mcm","clk":"5348539605","pt":1646218600310,"mc":[{"id":"1.195453744","rc":[{"atl":[[890,0],[880,2]],"id":41419636}],"con":true,"img":false}]}
{"op":"mcm","clk":"5348539634","pt":1646218600581,"mc":[{"id":"1.195453744","rc":[{"atb":[[6,0],[7,0]],"id":41419623}],"con":true,"img":false}]}
{"op":"mcm","clk":"5348539645","pt":1646218600677,"mc":[{"id":"1.195453744","rc":[{"atb":[[16.5,0],[19,0]],"id":41419594}],"con":true,"img":false}]}
{"op":"mcm","clk":"5348539704","pt":1646218601403,"mc":[{"id":"1.195453744","rc":[{"atb":[[6.8,2.72],[5.9,44.04]],"id":41419623},{"atb":[[17,3.26],[19.5,2.72]],"id":41419594}],"con":true,"img":false}]}
{"op":"mcm","clk":"5348540279","pt":1646218607593,"mc":[{"id":"1.195453744","rc":[{"atl":[[410,2],[420,0]],"id":41419622},{"atl":[[480,2],[500,0]],"id":41419608},{"atl":[[970,2],[1000,0]],"id":41419586}],"con":true,"img":false}]}
{"op":"mcm","clk":"5348540304","pt":1646218607901,"mc":[{"id":"1.195453744","rc":[{"atb":[[21,0],[26,0]],"id":41419601}],"con":true,"img":false}]}
{"op":"mcm","clk":"5348540369","pt":1646218608590,"mc":[{"id":"1.195453744","rc":[{"atb":[[20,3.26],[25,2.72]],"id":41419601}],"con":true,"img":false}]}
{"op":"mcm","clk":"5348546405","pt":1646218679592,"mc":[{"id":"1.195453744","rc":[{"atb":[[280,0],[180,0],[430,0]],"id":41419640},{"atb":[[19.5,0],[12,0],[8.8,0]],"id":41419607},{"atb":[[40,0],[20,0],[15,0]],"id":41419605},{"atb":[[42,0],[21,0],[15.5,0]],"id":41419636},{"atb":[[8,0],[6,0],[12.5,0]],"id":41419603},{"atb":[[16.5,0],[46,0],[23,0]],"id":41419634},{"atb":[[36,0],[90,0],[23,0]],"id":41419611},{"atb":[[16.5,0],[11.5,0],[28,0]],"id":41419593},{"atb":[[16.5,0],[46,0],[23,0]],"id":41419591},{"atb":[[4.8,0],[8.6,0],[5.8,0]],"id":41419622},{"atb":[[7.2,0],[9.2,0],[15.5,0]],"id":41419589},{"atb":[[10,0],[5.5,0],[7,0]],"id":41419620},{"atb":[[16,0],[11,0],[27,0]],"id":41419587},{"atb":[[22,0],[13.5,0],[9.4,0]],"id":41419601},{"atb":[[16.5,0],[46,3.26],[23,0]],"id":41419632},{"atb":[[36,0],[19,5.56],[14,0]],"id":41419599},{"atb":[[44,0],[27,0],[120,0]],"id":41419630},{"atb":[[75,0],[40,0],[200,0]],"id":41419597},{"atb":[[100,2.72],[50,0],[250,0]],"id":41419628},{"atb":[[8,0],[6,0],[12.5,2.72]],"id":41419626},{"atb":[[9,0],[20,0],[12.5,0]],"id":41419608},{"atb":[[8,0],[17.5,0],[10,11.11]],"id":41419639},{"atb":[[10.5,0],[26,0],[15.5,0]],"id":41419606},{"atb":[[16.5,0],[11.5,0],[28,0]],"id":41419637},{"atb":[[95,0],[48,0],[240,0]],"id":41419604},{"atb":[[38,0],[19.5,0],[14.5,0]],"id":41419635},{"atb":[[34,3.26],[18.5,0],[13.5,0]],"id":41419585},{"atb":[[16,0],[11,0],[27,0]],"id":41419612},{"atb":[[4.4,0],[7.8,0],[5.4,0]],"id":41419610},{"atb":[[32,0],[18,0],[13,0]],"id":41419625},{"atb":[[32,0],[18,0],[13,0]],"id":41419592},{"atb":[[3.7,0],[4.4,0],[5.9,3.26]],"id":41419623},{"atb":[[360,0],[210,0],[110,0]],"id":41419590},{"atb":[[8,0],[4.5,28.57],[5.5,0]],"id":41419621},{"atb":[[36,0],[19,0],[14,0]],"id":41419586},{"atb":[[320,0],[220,0],[470,0]],"id":41419633},{"atb":[[16.5,0],[11.5,0],[28,0]],"id":41419600},{"atb":[[36,2.72],[19,0],[14,0]],"id":41419598},{"atb":[[130,0],[65,0],[280,0]],"id":41419629},{"atb":[[5.6,0],[7.2,0],[10.5,0]],"id":41419596},{"atb":[[140,0],[390,0],[240,0]],"id":41419627},{"atb":[[9,0],[20,0],[12.5,0]],"id":41419594}],"con":true,"img":false}]}
{"op":"mcm","clk":"5348546809","pt":1646218684015,"mc":[{"id":"1.195453744","rc":[{"atb":[[280,0.47],[90,2.99],[46,5.91]],"id":41419640},{"atb":[[21,6.65],[10.5,28.03],[8.2,36.99]],"id":41419636},{"atb":[[8.6,35.05],[23,6.05],[11.5,25.36]],"id":41419634},{"atb":[[16.5,17.18],[36,3.8],[11.5,25.36]],"id":41419611},{"atb":[[5.8,27.75],[3.4,110.99],[3.9,91.85]],"id":41419622},{"atb":[[4.5,76.11],[7,22.19],[3.75,96.87]],"id":41419620},{"atb":[[8.6,35.05],[23,6.05],[11.5,25.36]],"id":41419632},{"atb":[[18.5,15.22],[44,3.09],[13.5,21.3]],"id":41419630},{"atb":[[20,14.02],[100,4.07],[30,9.18]],"id":41419628},{"atb":[[8,19.02],[4,88.79],[5,66.59]],"id":41419626},{"atb":[[10,25.91],[5,66.59],[6,53.27]],"id":41419639},{"atb":[[16.5,8.59],[8.6,35.05],[6.6,47.57]],"id":41419637},{"atb":[[19.5,7.19],[9.8,30.27],[7.8,39.17]],"id":41419635},{"atb":[[16,8.87],[6.4,49.33],[8.4,35.99]],"id":41419612},{"atb":[[3.2,121.08],[3.7,98.66],[5.4,30.27]],"id":41419610},{"atb":[[7.2,42.96],[18,7.83],[9.2,32.48]],"id":41419625},{"atb":[[3.2,121.08],[2.88,141.69],[4.4,39.17]],"id":41419623},{"atb":[[5.5,29.59],[3.25,118.39],[3.75,96.87]],"id":41419621},{"atb":[[320,0.41],[120,4.96],[60,4.51]],"id":41419633},{"atb":[[130,1.03],[36,10.47],[23,12.1]],"id":41419629},{"atb":[[70,3.85],[38,9.89],[240,0.55]],"id":41419627}],"con":true,"img":false}]}
{"op":"mcm","clk":"5348546830","pt":1646218684173,"mc":[{"id":"1.195453744","rc":[{"atb":[[12,12.1],[6.8,45.93],[5.4,60.54]],"id":41419607},{"atb":[[8,38.05],[20,7],[10,29.59]],"id":41419605},{"atb":[[8,19.02],[4,88.79],[5,66.59]],"id":41419603},{"atb":[[16.5,8.59],[8.6,35.05],[6.6,47.57]],"id":41419593},{"atb":[[8.6,35.05],[23,6.05],[11.5,25.36]],"id":41419591},{"atb":[[5.6,57.91],[9.2,16.24],[4.6,73.99]],"id":41419589},{"atb":[[16,8.87],[6.4,49.33],[8.4,35.99]],"id":41419587},{"atb":[[7.4,41.62],[13.5,10.65],[5.7,56.67]],"id":41419601},{"atb":[[9.6,30.97],[19,12.96],[7.6,40.36]],"id":41419599},{"atb":[[17.5,16.14],[75,1.79],[25,11.1]],"id":41419597},{"atb":[[5.5,59.19],[12.5,11.58],[7,44.4]],"id":41419608},{"atb":[[6.2,51.22],[8.2,50.88],[15.5,9.18]],"id":41419606},{"atb":[[19.5,14.39],[95,1.41],[29,9.51]],"id":41419604},{"atb":[[18.5,7.61],[7.4,41.62],[9.4,31.71]],"id":41419585},{"atb":[[7.2,42.96],[18,7.83],[9.2,44.68]],"id":41419592},{"atb":[[32,8.59],[210,0.63],[55,4.93]],"id":41419590},{"atb":[[9.6,30.97],[19,7.4],[7.6,40.36]],"id":41419586},{"atb":[[16.5,8.59],[8.6,35.05],[6.6,47.57]],"id":41419600},{"atb":[[9.6,30.97],[19,7.4],[7.6,40.36]],"id":41419598},{"atb":[[7.2,21.48],[4.6,73.99],[3.8,95.13]],"id":41419596},{"atb":[[5.5,59.19],[12.5,11.58],[7,44.4]],"id":41419594}],"con":true,"img":false}]}
{"op":"mcm","clk":"5348546842","pt":1646218684379,"mc":[{"id":"1.195453744","rc":[{"atb":[[9.2,32.48],[10.5,10.53]],"id":41419592}],"con":true,"img":false}]}
{"op":"mcm","clk":"5348548079","pt":1646218699109,"mc":[{"id":"1.195453744","rc":[{"atb":[[6.8,0],[5.9,0]],"id":41419623}],"con":true,"img":false}]}
{"op":"mcm","clk":"5348548143","pt":1646218699881,"mc":[{"id":"1.195453744","rc":[{"atb":[[6,3.26],[7,2.72]],"id":41419623}],"con":true,"img":false}]}
{"op":"mcm","clk":"5348548606","pt":1646218705499,"mc":[{"id":"1.195453744","rc":[{"atb":[[20,0],[25,0]],"id":41419601}],"con":true,"img":false}]}
{"op":"mcm","clk":"5348548668","pt":1646218706228,"mc":[{"id":"1.195453744","rc":[{"atb":[[21,3.26]],"id":41419601}],"con":true,"img":false}]}
{"op":"mcm","clk":"5348548702","pt":1646218706490,"mc":[{"id":"1.195453744","rc":[{"atb":[[26,2.72]],"id":41419601}],"con":true,"img":false}]}
{"op":"mcm","clk":"5348549420","pt":1646218715011,"mc":[{"id":"1.195453744","rc":[{"atl":[[1000,0]],"id":41419591},{"atl":[[110,2],[120,0]],"id":41419623}],"con":true,"img":false}]}
{"op":"mcm","clk":"5348549441","pt":1646218715324,"mc":[{"id":"1.195453744","rc":[{"atb":[[21,0],[26,0]],"id":41419601},{"atb":[[6,0],[7,0]],"id":41419623}],"con":true,"img":false}]}
{"op":"mcm","clk":"5348549505","pt":1646218716048,"mc":[{"id":"1.195453744","rc":[{"atb":[[20,3.26],[25,2.72]],"id":41419601}],"con":true,"img":false}]}
{"op":"mcm","clk":"5348549524","pt":1646218716258,"mc":[{"id":"1.195453744","rc":[{"atb":[[6.8,2.72],[5.9,3.26]],"id":41419623}],"con":true,"img":false}]}
{"op":"mcm","clk":"5348555180","pt":1646218784639,"mc":[{"id":"1.195453744","rc":[{"atb":[[17,0],[19.5,0]],"id":41419594}],"con":true,"img":false}]}
{"op":"mcm","clk":"5348555246","pt":1646218785317,"mc":[{"id":"1.195453744","rc":[{"atb":[[16.5,3.26],[19,2.72]],"id":41419594}],"con":true,"img":false}]}
{"op":"mcm","clk":"5348556663","pt":1646218802435,"mc":[{"id":"1.195453744","rc":[{"atb":[[6.8,0],[5.9,0]],"id":41419623}],"con":true,"img":false}]}
{"op":"mcm","clk":"5348556740","pt":1646218803226,"mc":[{"id":"1.195453744","rc":[{"atb":[[80,2.72],[90,2.99],[46,5.91],[55,3.27]],"id":41419640},{"atb":[[18.5,3.27],[22,2.72],[12,12.11],[6.8,45.93],[5.4,60.54]],"id":41419607},{"atb":[[8,38.05],[34,2.72],[20,7],[10,29.59],[27,3.27]],"id":41419605},{"atb":[[40,2.72],[21,6.66],[10.5,28.04],[8.2,37],[30,3.27]],"id":41419636},{"atb":[[8,19.02],[4,88.79],[17,2.72],[5,66.6],[14.5,3.27]],"id":41419603},{"atb":[[8.6,35.05],[40,3.27],[23,6.05],[11.5,25.37],[50,2.72]],"id":41419634},{"atb":[[16.5,17.18],[36,3.8],[38,3.27],[11.5,25.37],[48,2.72]],"id":41419611},{"atb":[[16.5,8.59],[8.6,35.05],[25,3.27],[6.6,47.57],[30,2.72]],"id":41419593},{"atb":[[8.6,35.05],[42,3.27],[23,6.05],[11.5,25.37],[55,2.72]],"id":41419591},{"atb":[[5.8,27.75],[3.4,111],[9.8,2.72],[8.8,3.27],[3.9,91.86]],"id":41419622},{"atb":[[5.6,57.91],[9.2,16.24],[4.6,74],[23,3.27],[28,2.72]],"id":41419589},{"atb":[[4.5,76.11],[11.5,3.27],[14,2.72],[7,22.19],[3.75,96.87]],"id":41419620},{"atb":[[16,8.87],[6.4,49.33],[40,2.72],[8.4,35.99],[30,3.27]],"id":41419587},{"atb":[[20,3.27],[7.4,41.62],[25,2.72],[13.5,10.65],[5.7,56.68]],"id":41419601},{"atb":[[65,2.72],[8.6,35.05],[46,3.27],[23,6.05],[11.5,25.37]],"id":41419632},{"atb":[[9.6,30.97],[38,2.72],[19,12.96],[7.6,40.36],[29,3.27]],"id":41419599},{"atb":[[18.5,15.22],[85,2.72],[44,3.09],[13.5,21.31],[60,3.27]],"id":41419630},{"atb":[[17.5,16.14],[44,3.27],[25,11.1],[60,2.72]],"id":41419597},{"atb":[[75,3.27],[20,14.02],[100,4.07],[30,9.18]],"id":41419628},{"atb":[[8,19.02],[4,88.79],[10,3.27],[5,66.6],[12.5,2.72]],"id":41419626},{"atb":[[19.5,3.27],[5.5,59.19],[24,2.72],[12.5,11.58],[7,44.4]],"id":41419608},{"atb":[[20,3.27],[10,25.91],[5,66.6],[6,53.28],[25,2.72]],"id":41419639},{"atb":[[6.2,51.23],[8.2,50.89],[25,3.27],[30,2.72],[15.5,9.18]],"id":41419606},{"atb":[[16.5,8.59],[34,2.72],[8.6,35.05],[27,3.27],[6.6,47.57]],"id":41419637},{"atb":[[19.5,14.39],[44,3.27],[29,9.51],[60,2.72]],"id":41419604},{"atb":[[19.5,7.19],[40,2.72],[9.8,30.27],[7.8,39.17],[30,3.27]],"id":41419635},{"atb":[[34,3.27],[18.5,7.61],[44,2.72],[7.4,41.62],[9.4,31.71]],"id":41419585},{"atb":[[16,8.87],[6.4,49.33],[20,3.27],[25,2.72],[8.4,35.99]],"id":41419612},{"atb":[[3.2,121.09],[10,3.27],[3.7,98.67],[12.5,2.72],[5.4,30.27]],"id":41419610},{"atb":[[7.2,42.96],[18,7.83],[9.2,32.48],[21,3.27],[26,2.72]],"id":41419625},{"atb":[[7.2,42.96],[18,7.83],[38,2.72],[9.2,32.48],[29,3.27]],"id":41419592},{"atb":[[3.2,121.09],[2.88,141.7],[6,3.27],[4.4,39.17],[7,2.72]],"id":41419623},{"atb":[[65,3.27],[32,8.59],[90,2.72],[55,4.93]],"id":41419590},{"atb":[[9,3.27],[10,2.72],[5.5,29.59],[3.25,118.39],[3.75,96.87]],"id":41419621},{"atb":[[9.6,30.97],[34,3.27],[19,7.4],[44,2.72],[7.6,40.36]],"id":41419586},{"atb":[[85,3.27],[120,4.96],[60,4.51]],"id":41419633},{"atb":[[16.5,8.59],[8.6,35.05],[25,3.27],[6.6,47.57],[30,2.72]],"id":41419600},{"atb":[[9.6,30.97],[36,2.72],[19,7.4],[7.6,40.36],[28,3.27]],"id":41419598},{"atb":[[70,3.27],[36,10.47],[95,2.72],[23,12.11]],"id":41419629},{"atb":[[17.5,2.72],[7.2,21.48],[4.6,74],[3.8,95.14],[15,3.27]],"id":41419596},{"atb":[[70,3.85],[38,9.89],[85,3.27],[120,2.72]],"id":41419627},{"atb":[[16.5,3.27],[19,2.72],[5.5,59.19],[12.5,11.58],[7,44.4]],"id":41419594}],"con":true,"img":false}]}
{"op":"mcm","clk":"5348558060","pt":1646218817355,"mc":[{"id":"1.195453744","rc":[{"atb":[[20,0],[25,0]],"id":41419601}],"con":true,"img":false}]}
{"op":"mcm","clk":"5348558138","pt":1646218818137,"mc":[{"id":"1.195453744","rc":[{"atb":[[21,3.27],[26,2.72]],"id":41419601}],"con":true,"img":false}]}
{"op":"mcm","clk":"5348558681","pt":1646218823983,"mc":[{"id":"1.195453744","rc":[{"atb":[[21,0]],"id":41419601}],"con":true,"img":false}]}
{"op":"mcm","clk":"5348558691","pt":1646218824101,"mc":[{"id":"1.195453744","rc":[{"atb":[[26,0]],"id":41419601}],"con":true,"img":false}]}
{"op":"mcm","clk":"5348558780","pt":1646218824972,"mc":[{"id":"1.195453744","rc":[{"atb":[[20,3.27],[25,2.72]],"id":41419601}],"con":true,"img":false}]}
{"op":"mcm","clk":"5348562134","pt":1646218864504,"mc":[{"id":"1.195453744","rc":[{"atb":[[16.5,0],[19,0]],"id":41419594}],"con":true,"img":false}]}
{"op":"mcm","clk":"5348562215","pt":1646218865343,"mc":[{"id":"1.195453744","rc":[{"atb":[[17,3.27],[19.5,2.72]],"id":41419594}],"con":true,"img":false}]}
{"op":"mcm","clk":"5348568445","pt":1646218921342,"mc":[{"id":"1.195453744","rc":[{"atb":[[130,4.95],[80,9.75],[95,9.9]],"id":41419640},{"atl":[[990,0.15]],"id":41419640},{"atb":[[12,21.02],[12.5,9.9],[14.5,4.95]],"id":41419607},{"atl":[[36,4.95],[44,9.9],[440,0.35],[470,2.61]],"id":41419607},{"atb":[[40,9.9],[48,4.95]],"id":41419605},{"atl":[[120,4.95]],"id":41419605},{"atb":[[65,4.95],[42,3.86],[22,13.67],[48,9.9]],"id":41419636},{"atl":[[150,4.95],[870,0.17],[900,1.36]],"id":41419636},{"atb":[[17.5,18.82],[19.5,4.95],[8.2,22.8]],"id":41419603},{"atl":[[540,0.29],[570,2.15],[46,4.95],[60,9.9]],"id":41419603},{"atb":[[32,12.08],[85,9.9],[110,4.95],[55,2.93]],"id":41419634},{"atl":[[220,4.95],[990,0.15]],"id":41419634},{"atb":[[34,4.95],[36,12.72],[28,9.9]],"id":41419611},{"atl":[[630,0.25],[660,1.85],[110,4.95]],"id":41419611},{"atb":[[16.5,17.51],[21,9.9],[25,8.22]],"id":41419593},{"atl":[[70,9.9],[550,0.28],[580,2.12],[50,4.95]],"id":41419593},{"atb":[[85,9.9],[110,4.95],[29,13.29]],"id":41419591},{"atb":[[9.6,9.9],[5.8,36.66],[11,4.95]],"id":41419622},{"atl":[[19.5,4.95],[23,9.9],[430,2.86]],"id":41419622},{"atb":[[29,5.66]],"id":41419589},{"atl":[[720,0.21]],"id":41419589},{"atb":[[14,11.64],[7,31.11]],"id":41419620},{"atl":[[450,0.35],[480,2.56]],"id":41419620},{"atb":[[16,17.79],[32,9.9],[40,11.74]],"id":41419587},{"atl":[[90,4.95],[710,0.22],[740,1.65],[120,9.9]],"id":41419587},{"atb":[[16,9.9],[18,4.95],[13.5,19.57]],"id":41419601},{"atl":[[520,2.36],[36,4.95],[44,9.9],[490,0.32]],"id":41419601},{"atb":[[70,2.29],[80,9.9],[100,4.95]],"id":41419632},{"atl":[[210,4.95],[980,0.16]],"id":41419632},{"atb":[[19,21.87],[40,4.06],[44,9.9],[55,4.95]],"id":41419599},{"atl":[[130,4.95],[780,0.2],[810,1.51]],"id":41419599},{"atb":[[75,4.95],[44,11.76],[55,9.9]],"id":41419630},{"atl":[[930,1.31]],"id":41419630},{"atb":[[42,9.9],[44,10.3],[50,4.95]],"id":41419597},{"atl":[[160,4.95],[760,0.2],[790,1.55]],"id":41419597},{"atb":[[140,4.95],[36,12.58],[100,13.97],[110,1.45]],"id":41419628},{"atl":[[1000,0.15]],"id":41419628},{"atb":[[12,9.9],[12.5,11.64],[14,4.95]],"id":41419626},{"atl":[[36,9.9],[440,0.35],[29,4.95]],"id":41419626},{"atb":[[16.5,4.95],[12.5,20.49],[14.5,9.9]],"id":41419608},{"atl":[[34,4.95],[42,9.9],[470,0.33],[500,2.45]],"id":41419608},{"atb":[[38,4.95],[30,9.9]],"id":41419639},{"atl":[[90,4.95],[120,9.9]],"id":41419639},{"atb":[[24,9.9],[28,4.95],[15.5,18.1]],"id":41419606},{"atl":[[570,0.27],[75,9.9],[600,2.04],[55,4.95]],"id":41419606},{"atb":[[16.5,17.51],[32,4.95],[27,13.17]],"id":41419637},{"atl":[[570,0.27],[75,4.95],[600,2.04],[95,9.9]],"id":41419637},{"atb":[[70,9.9],[44,10.3],[90,4.95],[100,1.6]],"id":41419604},{"atl":[[180,4.95],[930,0.16],[960,1.27]],"id":41419604},{"atb":[[19.5,16.11],[42,3.86]],"id":41419635},{"atl":[[730,0.21],[760,1.61]],"id":41419635},{"atb":[[80,4.95],[21,13.91],[46,3.52],[60,9.9]],"id":41419585},{"atl":[[160,4.95],[790,0.2],[820,1.49]],"id":41419585},{"atb":[[16,17.79],[20,13.17],[24,4.95]],"id":41419612},{"atl":[[540,2.27],[70,9.9],[50,4.95]],"id":41419612},{"atb":[[9.6,9.9],[11,4.95],[5.4,39.19]],"id":41419610},{"atl":[[18,4.95],[20,9.9],[370,0.43],[400,3.07]],"id":41419610},{"atb":[[18,16.75],[19,9.9],[22,4.95]],"id":41419625},{"atl":[[530,2.31],[42,4.95],[50,9.9],[500,0.31]],"id":41419625},{"atb":[[18,16.75],[36,4.95],[38,7],[29,13.17]],"id":41419592},{"atl":[[640,0.25],[670,1.83],[85,4.95],[110,9.9]],"id":41419592},{"atb":[[5.6,9.9],[6,8.22]],"id":41419623},{"atl":[[10.5,4.95],[12.5,9.9],[100,1.6]],"id":41419623},{"atb":[[65,11.38],[160,4.95],[120,9.9]],"id":41419590},{"atl":[[1000,0.15]],"id":41419590},{"atb":[[10,7.67],[9.2,9.9],[5.5,38.51]],"id":41419621},{"atl":[[16.5,4.95],[18.5,9.9],[340,3.61]],"id":41419621},{"atb":[[32,12.08],[46,3.52]],"id":41419586},{"atl":[[960,0.16],[990,1.23]],"id":41419586},{"atb":[[160,4.95],[85,12.99],[120,14.87]],"id":41419633},{"atb":[[16.5,17.51],[32,4.95],[27,9.9],[30,8.19]],"id":41419600},{"atl":[[65,4.95],[590,0.26],[620,1.97],[85,9.9]],"id":41419600},{"atb":[[36,7.25],[19,16.31],[26,9.9],[30,4.95]],"id":41419598},{"atl":[[75,4.95],[600,0.26],[630,1.95],[95,9.9]],"id":41419598},{"atb":[[130,5.98],[70,11.38],[140,1.13],[95,12.63]],"id":41419629},{"atl":[[1000,0.15]],"id":41419629},{"atb":[[17.5,11.64],[7.2,30.4]],"id":41419596},{"atl":[[430,0.37],[460,2.67]],"id":41419596},{"atb":[[160,4.95],[85,11.38],[120,12.63]],"id":41419627},{"atl":[[1000,0.15]],"id":41419627},{"atb":[[12.5,20.49]],"id":41419594},{"atl":[[420,0.37],[450,2.73]],"id":41419594}],"con":true,"img":false}]}
{"op":"mcm","clk":"5348568466","pt":1646218921403,"mc":[{"id":"1.195453744","rc":[{"atb":[[36,4.52],[20,15.92]],"id":41419605},{"atl":[[810,0.19],[840,1.46]],"id":41419605},{"atb":[[60,2.68]],"id":41419591},{"atl":[[1000,0.15]],"id":41419591},{"atb":[[9.8,11.64]],"id":41419622},{"atl":[[400,0.39]],"id":41419622},{"atb":[[16,15.58],[38,9.9],[46,4.95]],"id":41419589},{"atl":[[750,1.63],[110,4.95]],"id":41419589},{"atb":[[16,4.95],[14,21.55]],"id":41419620},{"atl":[[32,4.95],[40,9.9]],"id":41419620},{"atb":[[85,4.61]],"id":41419630},{"atl":[[900,0.17]],"id":41419630},{"atb":[[8,27.94]],"id":41419626},{"atl":[[470,2.61]],"id":41419626},{"atb":[[10,34.82]],"id":41419639},{"atl":[[660,1.85]],"id":41419639},{"atb":[[44,9.9],[55,4.95]],"id":41419635},{"atl":[[130,4.95]],"id":41419635},{"atb":[[25,9.33]],"id":41419612},{"atl":[[510,0.31]],"id":41419612},{"atb":[[4.4,48.09]],"id":41419623},{"atl":[[130,8.91]],"id":41419623},{"atb":[[10,16.59]],"id":41419621},{"atl":[[310,0.51]],"id":41419621},{"atb":[[65,9.9],[85,4.95]],"id":41419586},{"atl":[[210,4.95]],"id":41419586},{"atl":[[1000,0.15]],"id":41419633},{"atb":[[17,4.95],[15,13.17]],"id":41419596},{"atl":[[36,9.9],[29,4.95]],"id":41419596},{"atb":[[11.5,9.9],[13.5,4.95]],"id":41419594},{"atl":[[42,4.95],[50,9.9]],"id":41419594}],"con":true,"img":false}]}
{"op":"mcm","clk":"5348568484","pt":1646218921511,"mc":[{"id":"1.195453744","rc":[{"atl":[[450,0]],"id":41419607},{"atl":[[880,0]],"id":41419636},{"atl":[[1000,0]],"id":41419634},{"atl":[[640,0]],"id":41419611},{"atl":[[560,0],[170,2]],"id":41419593},{"atl":[[460,0],[470,2]],"id":41419620},{"atl":[[720,0]],"id":41419587},{"atb":[[32,12.08]],"id":41419632},{"atl":[[910,0]],"id":41419630},{"atl":[[450,0]],"id":41419626},{"atl":[[90,2]],"id":41419608},{"atb":[[26,6.34]],"id":41419639},{"atl":[[630,0.25]],"id":41419639},{"atl":[[540,2],[940,0]],"id":41419604},{"atl":[[740,0],[750,2]],"id":41419635},{"atl":[[800,0]],"id":41419585},{"atl":[[380,0]],"id":41419610},{"atl":[[510,0]],"id":41419625},{"atl":[[110,0]],"id":41419623},{"atl":[[44,2.33]],"id":41419621},{"atl":[[970,0]],"id":41419586},{"atl":[[430,0],[440,2]],"id":41419594}],"con":true,"img":false}]}
{"op":"mcm","clk":"5348568499","pt":1646218921621,"mc":[{"id":"1.195453744","rc":[{"atl":[[85,2]],"id":41419607},{"atl":[[820,0],[420,2]],"id":41419605},{"atl":[[490,2]],"id":41419636},{"atl":[[550,0],[160,2]],"id":41419603},{"atl":[[760,2]],"id":41419634},{"atl":[[290,2]],"id":41419611},{"atl":[[410,0],[55,2]],"id":41419622},{"atl":[[730,0],[380,2]],"id":41419589},{"atl":[[340,2]],"id":41419587},{"atl":[[100,2],[500,0]],"id":41419601},{"atl":[[680,2],[990,0]],"id":41419632},{"atl":[[790,0],[400,2]],"id":41419599},{"atl":[[920,2]],"id":41419630},{"atl":[[770,0],[430,2]],"id":41419597},{"atl":[[80,2]],"id":41419626},{"atl":[[480,0]],"id":41419608},{"atl":[[640,0],[340,2]],"id":41419639},{"atl":[[580,0],[190,2]],"id":41419606},{"atl":[[580,0],[200,2]],"id":41419637},{"atl":[[510,2]],"id":41419585},{"atl":[[520,0],[150,2]],"id":41419612},{"atl":[[46,2.22]],"id":41419610},{"atl":[[130,2]],"id":41419625},{"atl":[[650,0],[330,2]],"id":41419592},{"atl":[[16,6.67]],"id":41419623},{"atl":[[320,0]],"id":41419621},{"atl":[[980,2]],"id":41419586},{"atl":[[600,0],[210,2]],"id":41419600},{"atl":[[610,0],[250,2]],"id":41419598},{"atl":[[440,0],[450,2]],"id":41419596}],"con":true,"img":false}]}
{"op":"mcm","clk":"5348568510","pt":1646218921721,"mc":[{"id":"1.195453744","rc":[{"atl":[[90,2],[470,0]],"id":41419620}],"con":true,"img":false}]}
{"op":"mcm","clk":"5348568529","pt":1646218921823,"mc":[{"id":"1.195453744","rc":[{"atl":[[1000,1.22]],"id":41419634},{"atl":[[990,1.23]],"id":41419632}],"con":true,"img":false}]}
{"op":"mcm","clk":"5348568715","pt":1646218923417,"mc":[{"id":"1.195453744","rc":[{"atb":[[28,0]],"id":41419640},{"atb":[[22,8.91]],"id":41419636},{"atb":[[25,4.17]],"id":41419589},{"atb":[[9.2,12.2]],"id":41419620},{"atb":[[29,6.84]],"id":41419599},{"atb":[[16,0]],"id":41419597},{"atb":[[9.6,0],[14,7.69]],"id":41419637},{"atb":[[17,0],[26,4]],"id":41419635},{"atb":[[8.6,0]],"id":41419612},{"atb":[[4.5,0]],"id":41419610},{"atb":[[8.4,0]],"id":41419625}],"con":true,"img":false}]}
{"op":"mcm","clk":"5348568723","pt":1646218923521,"mc":[{"id":"1.195453744","rc":[{"atb":[[48,2.13]],"id":41419640},{"atb":[[5.3,0],[7,16.67]],"id":41419607},{"atb":[[16.5,0],[21,5]],"id":41419605},{"atb":[[30,6.72]],"id":41419636},{"atb":[[10.5,10.53],[8.2,8.91]],"id":41419603},{"atb":[[32,8.85],[46,2.22]],"id":41419634},{"atb":[[13,8.33],[9.4,0]],"id":41419611},{"atb":[[8,0],[10.5,10.53]],"id":41419593},{"atb":[[4.6,0],[5.9,20.41]],"id":41419622},{"atb":[[16,8.91]],"id":41419589},{"atb":[[6,0]],"id":41419620},{"atb":[[10.5,0],[15,7.14]],"id":41419587},{"atb":[[32,8.85],[46,5.49]],"id":41419632},{"atb":[[19,16.31]],"id":41419599},{"atb":[[34,3.03],[24,0]],"id":41419630},{"atb":[[22,4.76]],"id":41419597},{"atb":[[36,9.72],[50,2.04]],"id":41419628},{"atb":[[5.6,0],[8.2,13.89]],"id":41419626},{"atb":[[10,23.71],[15,7.14]],"id":41419639},{"atb":[[8.2,37],[11,10]],"id":41419606},{"atb":[[40,2.56],[27,0]],"id":41419604},{"atb":[[32,3.23],[21,8.91]],"id":41419585},{"atb":[[10,11.11]],"id":41419612},{"atb":[[6.4,18.52]],"id":41419610},{"atb":[[11.5,9.52]],"id":41419625},{"atb":[[10.5,0],[14.5,7.41]],"id":41419592},{"atb":[[3.85,35.09],[3.35,0]],"id":41419623},{"atb":[[36,0],[50,2.04]],"id":41419590},{"atb":[[4.5,0],[5.5,60.73]],"id":41419621},{"atb":[[32,8.85],[46,5.74]],"id":41419586},{"atb":[[36,0],[50,2.04]],"id":41419633},{"atb":[[9.2,0],[14,7.69]],"id":41419600},{"atb":[[10,0],[15,7.14]],"id":41419598},{"atb":[[36,7.61],[50,2.04]],"id":41419629},{"atb":[[5.5,0],[7.6,15.15]],"id":41419596},{"atb":[[38,7.19],[55,2]],"id":41419627},{"atb":[[4.8,0],[6.2,19.23]],"id":41419594}],"con":true,"img":false}]}
{"op":"mcm","clk":"5348568738","pt":1646218923625,"mc":[{"id":"1.195453744","rc":[{"atl":[[36,0],[38,4.95],[44,0],[46,9.9]],"id":41419607},{"atl":[[70,0],[75,9.9],[50,0],[55,4.95]],"id":41419612},{"atl":[[10.5,0],[11,4.95],[12.5,0],[13,9.9]],"id":41419623}],"con":true,"img":false}]}
{"op":"mcm","clk":"5348569153","pt":1646218926675,"mc":[{"id":"1.195453744","rc":[{"atl":[[490,0]],"id":41419636},{"atl":[[540,0],[930,2.16]],"id":41419604}],"con":true,"img":false}]}
{"op":"mcm","clk":"5348569166","pt":1646218926827,"mc":[{"id":"1.195453744","rc":[{"atl":[[810,2.19],[420,0]],"id":41419605},{"atl":[[870,2.17]],"id":41419636},{"atl":[[760,0],[990,2.15]],"id":41419634},{"atl":[[290,0],[630,2.25]],"id":41419611},{"atl":[[720,2.21],[380,0]],"id":41419589},{"atl":[[680,0],[980,2.16]],"id":41419632},{"atl":[[780,2.2],[400,0]],"id":41419599},{"atl":[[760,2.2],[430,0]],"id":41419597},{"atl":[[790,2.2],[510,0]],"id":41419585}],"con":true,"img":false}]}
{"op":"mcm","clk":"5348569381","pt":1646218928721,"mc":[{"id":"1.195453744","rc":[{"atl":[[920,0]],"id":41419630}],"con":true,"img":false}]}
{"op":"mcm","clk":"5348569392","pt":1646218928817,"mc":[{"id":"1.195453744","rc":[{"atl":[[910,2]],"id":41419630}],"con":true,"img":false}]}
{"op":"mcm","clk":"5348569466","pt":1646218929511,"mc":[{"id":"1.195453744","rc":[{"atl":[[42,0],[44,4.95],[50,0],[55,9.9]],"id":41419594}],"con":true,"img":false}]}
{"op":"mcm","clk":"5348569485","pt":1646218929711,"mc":[{"id":"1.195453744","rc":[{"atl":[[75,2],[440,0]],"id":41419594}],"con":true,"img":false}]}
{"op":"mcm","clk":"5348569587","pt":1646218930690,"mc":[{"id":"1.195453744","rc":[{"atl":[[75,0],[80,4.95],[95,0],[100,9.9]],"id":41419637},{"atb":[[65,0],[80,4.95],[85,0],[60,9.9]],"id":41419586}],"con":true,"img":false}]}
{"op":"mcm","clk":"5348569603","pt":1646218930854,"mc":[{"id":"1.195453744","rc":[{"atb":[[36,9.9],[44,4.95]],"id":41419589}],"con":true,"img":false}]}
{"op":"mcm","clk":"5348569615","pt":1646218930947,"mc":[{"id":"1.195453744","rc":[{"atb":[[38,0],[46,0]],"id":41419589}],"con":true,"img":false}]}
{"op":"mcm","clk":"5348569849","pt":1646218932991,"mc":[{"id":"1.195453744","rc":[{"atb":[[17.5,8.91],[17,12.63],[19.5,0],[19,4.95]],"id":41419603},{"atl":[[75,0],[80,9.9],[55,0],[60,4.95]],"id":41419606}],"con":true,"img":false}]}
{"op":"mcm","clk":"5348569926","pt":1646218933724,"mc":[{"id":"1.195453744","rc":[{"atl":[[1000,2.15]],"id":41419591}],"con":true,"img":false}]}
{"op":"mcm","clk":"5348569965","pt":1646218933991,"mc":[{"id":"1.195453744","rc":[{"atl":[[910,0],[920,2]],"id":41419630},{"atb":[[32,0],[26,9.9],[27,3.27],[30,4.95]],"id":41419637},{"atl":[[18,0],[18.5,4.95],[20,0],[21,9.9]],"id":41419610}],"con":true,"img":false}]}
{"op":"mcm","clk":"5348570248","pt":1646218937046,"mc":[{"id":"1.195453744","rc":[{"atb":[[12,12.11],[14.5,17.17]],"id":41419607},{"atl":[[80,2]],"id":41419607},{"atb":[[42,16.97],[22,0]],"id":41419636},{"atb":[[17,33.25],[8.2,0]],"id":41419603},{"atl":[[160,9.97]],"id":41419603},{"atl":[[220,5.67]],"id":41419634},{"atb":[[16.5,8.59],[21,29.48]],"id":41419593},{"atl":[[580,0],[170,9.51]],"id":41419593},{"atb":[[60,14.04]],"id":41419591},{"atl":[[430,0],[55,24.08]],"id":41419622},{"atl":[[480,0]],"id":41419620},{"atb":[[16,8.87],[30,25.35]],"id":41419587},{"atl":[[340,5.74],[740,0]],"id":41419587},{"atb":[[18,17.17],[13.5,10.65]],"id":41419601},{"atl":[[100,14.21]],"id":41419601},{"atb":[[19,7.4],[40,17.47],[55,7.89]],"id":41419599},{"atb":[[44,3.09],[60,11.1]],"id":41419630},{"atb":[[140,6.09],[36,0],[100,23.5]],"id":41419628},{"atb":[[16.5,17.17]],"id":41419608},{"atl":[[34,9.76],[90,14.21]],"id":41419608},{"atl":[[180,0.88]],"id":41419606},{"atb":[[27,15.48]],"id":41419637},{"atl":[[600,0],[80,6.95],[200,8.38]],"id":41419637},{"atb":[[44,3.27]],"id":41419604},{"atl":[[180,5.84]],"id":41419604},{"atb":[[19.5,7.19],[42,16.97],[55,7.89]],"id":41419635},{"atl":[[130,6.18],[750,3.69],[760,0]],"id":41419635},{"atb":[[80,6.95],[21,0],[46,16.11]],"id":41419585},{"atl":[[160,5.95]],"id":41419585},{"atb":[[16,8.87]],"id":41419612},{"atb":[[5.4,30.27]],"id":41419610},{"atl":[[44,3.68]],"id":41419610},{"atb":[[18,7.83],[21,15.48]],"id":41419625},{"atl":[[130,11.82],[530,0]],"id":41419625},{"atb":[[18,7.83],[29,30.95]],"id":41419592},{"atl":[[330,5.86],[670,0]],"id":41419592},{"atl":[[15.5,10.93]],"id":41419623},{"atb":[[5.5,51.81]],"id":41419621},{"atl":[[44,24.41]],"id":41419621},{"atb":[[32,0],[48,3.21]],"id":41419586},{"atl":[[210,5.71],[990,0]],"id":41419586},{"atb":[[85,3.27]],"id":41419633},{"atb":[[32,10.06],[27,29.44]],"id":41419600},{"atl":[[65,7.43],[620,0],[210,8.07]],"id":41419600},{"atb":[[19,7.4]],"id":41419598},{"atl":[[75,7.09]],"id":41419598},{"atb":[[70,3.27]],"id":41419629},{"atb":[[7.2,21.48],[15,35.26]],"id":41419596},{"atl":[[460,0]],"id":41419596},{"atb":[[120,20.82]],"id":41419627},{"atb":[[12.5,11.58],[13.5,17.17]],"id":41419594},{"atl":[[70,2.29],[75,14.21]],"id":41419594}],"con":true,"img":false}]}
{"op":"mcm","clk":"5348570259","pt":1646218937153,"mc":[{"id":"1.195453744","rc":[{"atb":[[95,15.85]],"id":41419640},{"atl":[[85,14.21]],"id":41419607},{"atb":[[36,18.61],[20,7],[48,8.32]],"id":41419605},{"atl":[[120,6.28]],"id":41419605},{"atb":[[65,7.43]],"id":41419636},{"atl":[[150,6.01]],"id":41419636},{"atl":[[570,0],[46,8.47]],"id":41419603},{"atb":[[32,0],[110,6.4],[55,14.66]],"id":41419634},{"atl":[[110,6.4]],"id":41419611},{"atb":[[29,3.57],[120,1.32]],"id":41419591},{"atb":[[9.6,31.99],[5.8,27.75],[11,20.8]],"id":41419622},{"atl":[[19.5,13.52]],"id":41419622},{"atb":[[16,0],[29,20.37],[30,5.46]],"id":41419589},{"atl":[[110,6.4]],"id":41419589},{"atb":[[16,15.52],[7,22.19]],"id":41419620},{"atl":[[90,16.19]],"id":41419620},{"atl":[[90,6.73]],"id":41419587},{"atl":[[520,0],[36,9.48]],"id":41419601},{"atb":[[100,6.55]],"id":41419632},{"atl":[[210,5.71]],"id":41419632},{"atl":[[130,6.18]],"id":41419599},{"atb":[[44,3.27],[50,12.29]],"id":41419597},{"atl":[[150,1.06]],"id":41419597},{"atb":[[8,19.02],[12,31.99],[14,17.15]],"id":41419626},{"atl":[[80,17.97],[29,10.61],[470,0]],"id":41419626},{"atb":[[12.5,11.58]],"id":41419608},{"atl":[[500,0]],"id":41419608},{"atb":[[10,14.8],[26,23.12]],"id":41419639},{"atl":[[660,0],[340,5.74]],"id":41419639},{"atb":[[25,15.48],[15.5,9.18]],"id":41419606},{"atl":[[600,0],[190,8.72]],"id":41419606},{"atb":[[16.5,8.59]],"id":41419637},{"atb":[[90,10.55]],"id":41419604},{"atb":[[20,34.4]],"id":41419612},{"atl":[[540,0],[140,1.13],[150,10.51]],"id":41419612},{"atb":[[10,15.48]],"id":41419610},{"atl":[[46,14.43],[400,0]],"id":41419610},{"atl":[[85,6.83]],"id":41419592},{"atb":[[5.6,32.04],[4.4,39.17]],"id":41419623},{"atl":[[16,28.8],[130,0]],"id":41419623},{"atb":[[65,3.27],[120,18.21]],"id":41419590},{"atb":[[9,25.35]],"id":41419621},{"atl":[[16.5,15.18],[340,0]],"id":41419621},{"atb":[[46,20.45]],"id":41419586},{"atl":[[980,3.29]],"id":41419586},{"atb":[[120,22.85]],"id":41419633},{"atb":[[16.5,8.59]],"id":41419600},{"atb":[[28,17.98]],"id":41419598},{"atl":[[630,0],[250,7.1]],"id":41419598},{"atb":[[95,23.21]],"id":41419629},{"atl":[[430,3.33],[29,10.61]],"id":41419596},{"atb":[[85,3.27]],"id":41419627},{"atl":[[450,0]],"id":41419594}],"con":true,"img":false}]}
{"op":"mcm","clk":"5348570263","pt":1646218937208,"mc":[{"id":"1.195453744","rc":[{"atb":[[80,2.72]],"id":41419640}],"con":true,"img":false}]}
{"op":"mcm","clk":"5348570276","pt":1646218937318,"mc":[{"id":"1.195453744","rc":[{"atl":[[32,10.06]],"id":41419620},{"atb":[[32,0],[70,13.07]],"id":41419632},{"atl":[[760,0.2],[430,2]],"id":41419597},{"atb":[[38,9.23]],"id":41419639},{"atl":[[90,6.73]],"id":41419639},{"atl":[[95,2],[450,0]],"id":41419596}],"con":true,"img":false}]}
{"op":"mcm","clk":"5348570299","pt":1646218937624,"mc":[{"id":"1.195453744","rc":[{"atb":[[19.5,8.56]],"id":41419603},{"atl":[[760,1.88],[790,0]],"id":41419597}],"con":true,"img":false}]}
{"op":"mcm","clk":"5348570317","pt":1646218937736,"mc":[{"id":"1.195453744","rc":[{"atl":[[440,0]],"id":41419607},{"atl":[[570,0]],"id":41419637},{"atl":[[790,2]],"id":41419585},{"atl":[[370,0]],"id":41419610},{"atl":[[100,0]],"id":41419623},{"atb":[[46,16.93]],"id":41419586},{"atb":[[30,2.72]],"id":41419600},{"atl":[[600,0]],"id":41419598},{"atl":[[420,0]],"id":41419594}],"con":true,"img":false}]}
{"op":"mcm","clk":"5348570328","pt":1646218937838,"mc":[{"id":"1.195453744","rc":[{"atl":[[470,0]],"id":41419607},{"atl":[[990,2]],"id":41419634},{"atb":[[11.5,17.98]],"id":41419620},{"atb":[[40,13.4]],"id":41419599},{"atb":[[110,0]],"id":41419628},{"atl":[[470,0]],"id":41419608},{"atl":[[570,0]],"id":41419606},{"atl":[[730,0]],"id":41419635},{"atb":[[46,12.58]],"id":41419585},{"atl":[[960,0]],"id":41419586}],"con":true,"img":false}]}
{"op":"mcm","clk":"5348570338","pt":1646218937941,"mc":[{"id":"1.195453744","rc":[{"atb":[[36,14.08]],"id":41419605},{"atl":[[810,2]],"id":41419605},{"atb":[[42,13.1]],"id":41419636},{"atl":[[870,2]],"id":41419636},{"atl":[[540,0]],"id":41419603},{"atb":[[55,11.72]],"id":41419634},{"atl":[[630,2]],"id":41419611},{"atb":[[60,11.35]],"id":41419591},{"atb":[[9.8,2.72]],"id":41419622},{"atl":[[400,0]],"id":41419622},{"atb":[[29,14.71]],"id":41419589},{"atl":[[720,2]],"id":41419589},{"atb":[[14,12.63]],"id":41419620},{"atl":[[710,0]],"id":41419587},{"atl":[[490,0]],"id":41419601},{"atb":[[70,10.77]],"id":41419632},{"atl":[[980,2]],"id":41419632},{"atl":[[780,2]],"id":41419599},{"atl":[[760,1.67]],"id":41419597},{"atb":[[12.5,2.72]],"id":41419626},{"atl":[[440,0]],"id":41419626},{"atl":[[930,2]],"id":41419604},{"atb":[[42,13.1]],"id":41419635},{"atl":[[510,0]],"id":41419612},{"atl":[[640,0]],"id":41419592},{"atl":[[310,0]],"id":41419621},{"atl":[[590,0]],"id":41419600},{"atl":[[430,2.96]],"id":41419596}],"con":true,"img":false}]}
{"op":"mcm","clk":"5348570358","pt":1646218938117,"mc":[{"id":"1.195453744","rc":[{"atl":[[450,0]],"id":41419620},{"atb":[[26,16.78]],"id":41419639},{"atl":[[630,0]],"id":41419639}],"con":true,"img":false}]}
{"op":"mcm","clk":"5348570393","pt":1646218938417,"mc":[{"id":"1.195453744","rc":[{"atb":[[17.5,0],[19.5,0]],"id":41419603}],"con":true,"img":false}]}
{"op":"mcm","clk":"5348570469","pt":1646218939102,"mc":[{"id":"1.195453744","rc":[{"atb":[[17.5,9.6]],"id":41419603}],"con":true,"img":false}]}
{"op":"mcm","clk":"5348570673","pt":1646218941442,"mc":[{"id":"1.195453744","rc":[{"atl":[[260,4.95]],"id":41419630}],"con":true,"img":false}]}
{"op":"mcm","clk":"5348570700","pt":1646218941640,"mc":[{"id":"1.195453744","rc":[{"atl":[[520,2],[920,0]],"id":41419630}],"con":true,"img":false}]}
{"op":"mcm","clk":"5348570741","pt":1646218942012,"mc":[{"id":"1.195453744","rc":[{"atl":[[260,5.56],[920,1.39],[930,0]],"id":41419630}],"con":true,"img":false}]}
{"op":"mcm","clk":"5348570788","pt":1646218942430,"mc":[{"id":"1.195453744","rc":[{"atl":[[80,0],[85,4.95],[100,0],[110,9.9]],"id":41419637}],"con":true,"img":false}]}
{"op":"mcm","clk":"5348570823","pt":1646218942944,"mc":[{"id":"1.195453744","rc":[{"atl":[[900,0]],"id":41419630}],"con":true,"img":false}]}
{"op":"mcm","clk":"5348570863","pt":1646218943218,"mc":[{"id":"1.195453744","rc":[{"atl":[[85,6.83]],"id":41419637}],"con":true,"img":false}]}
{"op":"mcm","clk":"5348571010","pt":1646218944624,"mc":[{"id":"1.195453744","rc":[{"atb":[[75,17.18],[100,13.97]],"id":41419628}],"con":true,"img":false}]}
{"op":"mcm","clk":"5348571241","pt":1646218946811,"mc":[{"id":"1.195453744","rc":[{"atl":[[520,0],[900,2]],"id":41419630}],"con":true,"img":false}]}
{"op":"mcm","clk":"5348571347","pt":1646218947897,"mc":[{"id":"1.195453744","rc":[{"atl":[[150,0]],"id":41419597}],"con":true,"img":false}]}
{"op":"mcm","clk":"5348571355","pt":1646218948008,"mc":[{"id":"1.195453744","rc":[{"atl":[[75,2.14],[80,4.95],[95,0],[100,9.9]],"id":41419598}],"con":true,"img":false}]}
{"op":"mcm","clk":"5348571436","pt":1646218948940,"mc":[{"id":"1.195453744","rc":[{"atl":[[150,1.06]],"id":41419597}],"con":true,"img":false}]}
{"op":"mcm","clk":"5348571520","pt":1646218949823,"mc":[{"id":"1.195453744","rc":[{"atl":[[1000,0.15]],"id":41419591},{"atb":[[6.2,19.23],[5.5,29.59]],"id":41419621}],"con":true,"img":false}]}
{"op":"mcm","clk":"5348571540","pt":1646218950134,"mc":[{"id":"1.195453744","rc":[{"atb":[[18.5,0],[22,0]],"id":41419607},{"atl":[[110,1.45],[120,4.95]],"id":41419589},{"atb":[[19.5,0],[24,0]],"id":41419608},{"atl":[[36,0],[38,9.9],[29,5.66],[30,4.95]],"id":41419596}],"con":true,"img":false}]}
{"op":"mcm","clk":"5348571545","pt":1646218950230,"mc":[{"id":"1.195453744","rc":[{"atl":[[150,0]],"id":41419597}],"con":true,"img":false}]}
{"op":"mcm","clk":"5348571558","pt":1646218950339,"mc":[{"id":"1.195453744","rc":[{"atl":[[720,0],[380,2]],"id":41419589}],"con":true,"img":false}]}
{"op":"mcm","clk":"5348571581","pt":1646218950645,"mc":[{"id":"1.195453744","rc":[{"atb":[[12,41.56],[14.5,15.29]],"id":41419607},{"atl":[[720,1.82],[750,0]],"id":41419589},{"atb":[[16.5,15.18],[12.5,43.52]],"id":41419608}],"con":true,"img":false}]}
{"op":"mcm","clk":"5348571605","pt":1646218950856,"mc":[{"id":"1.195453744","rc":[{"atb":[[18,3.27],[21,2.72]],"id":41419607},{"atb":[[19,3.27],[23,2.72]],"id":41419608}],"con":true,"img":false}]}
{"op":"mcm","clk":"5348571631","pt":1646218951017,"mc":[{"id":"1.195453744","rc":[{"atl":[[160,5.95]],"id":41419597}],"con":true,"img":false}]}
{"op":"mcm","clk":"5348571648","pt":1646218951217,"mc":[{"id":"1.195453744","rc":[{"atl":[[760,3.67],[430,0]],"id":41419597}],"con":true,"img":false}]}
{"op":"mcm","clk":"5348571761","pt":1646218952419,"mc":[{"id":"1.195453744","rc":[{"atb":[[12,12.11],[14.5,27.51]],"id":41419607},{"atl":[[38,9.23]],"id":41419607},{"atb":[[85,19.24],[60,0]],"id":41419591},{"atb":[[16.5,44.42],[12.5,11.58]],"id":41419608},{"atl":[[60,7.64]],"id":41419606},{"atl":[[150,8.8],[750,2]],"id":41419635},{"atl":[[18.5,14.01]],"id":41419610},{"atl":[[11,20.8]],"id":41419623},{"atb":[[80,6.95]],"id":41419586},{"atl":[[70,14.51],[75,2],[42,3.86]],"id":41419594}],"con":true,"img":false}]}
{"op":"mcm","clk":"5348571768","pt":1646218952552,"mc":[{"id":"1.195453744","rc":[{"atl":[[80,14.22],[85,2]],"id":41419607},{"atb":[[44,8.64],[29,0],[30,20.18]],"id":41419589},{"atl":[[180,8.22],[190,2]],"id":41419606},{"atl":[[140,10.57],[150,2],[55,7.89]],"id":41419612},{"atl":[[44,18.4],[46,2.22]],"id":41419610},{"atl":[[16,6.67],[15.5,37.88]],"id":41419623},{"atb":[[46,2.22],[48,17.92]],"id":41419586},{"atl":[[230,5.73],[980,2]],"id":41419586},{"atl":[[100,23.12],[250,2]],"id":41419598},{"atl":[[38,33.04],[430,0]],"id":41419596}],"con":true,"img":false}]}
{"op":"mcm","clk":"5348571778","pt":1646218952605,"mc":[{"id":"1.195453744","rc":[{"atl":[[750,0],[380,2]],"id":41419635}],"con":true,"img":false}]}
{"op":"mcm","clk":"5348571786","pt":1646218952760,"mc":[{"id":"1.195453744","rc":[{"atl":[[650,2],[980,0]],"id":41419586}],"con":true,"img":false}]}
{"op":"mcm","clk":"5348571812","pt":1646218953032,"mc":[{"id":"1.195453744","rc":[{"atb":[[19.5,8.56]],"id":41419603},{"atl":[[180,7.34],[760,2]],"id":41419597}],"con":true,"img":false}]}
{"op":"mcm","clk":"5348571834","pt":1646218953242,"mc":[{"id":"1.195453744","rc":[{"atl":[[80,12.21]],"id":41419607},{"atl":[[760,0],[440,2]],"id":41419597},{"atl":[[180,7.33]],"id":41419606},{"atl":[[150,0]],"id":41419635},{"atl":[[44,14.71]],"id":41419610},{"atl":[[15.5,26.95]],"id":41419623},{"atb":[[48,14.71]],"id":41419586},{"atl":[[230,0]],"id":41419586},{"atl":[[70,12.21]],"id":41419594}],"con":true,"img":false}]}
{"op":"mcm","clk":"5348571845","pt":1646218953343,"mc":[{"id":"1.195453744","rc":[{"atb":[[30,14.71]],"id":41419589},{"atl":[[140,9.43]],"id":41419612}],"con":true,"img":false}]}
{"op":"mcm","clk":"5348571862","pt":1646218953542,"mc":[{"id":"1.195453744","rc":[{"atb":[[17.5,36.63]],"id":41419603}],"con":true,"img":false}]}
{"op":"mcm","clk":"5348571873","pt":1646218953645,"mc":[{"id":"1.195453744","rc":[{"atb":[[17,12.63]],"id":41419603}],"con":true,"img":false}]}
{"op":"mcm","clk":"5348571894","pt":1646218953805,"mc":[{"id":"1.195453744","rc":[{"atb":[[17.5,27.02]],"id":41419603}],"con":true,"img":false}]}
{"op":"mcm","clk":"5348571935","pt":1646218954219,"mc":[{"id":"1.195453744","rc":[{"atb":[[19.5,0]],"id":41419603}],"con":true,"img":false}]}
{"op":"mcm","clk":"5348571950","pt":1646218954324,"mc":[{"id":"1.195453744","rc":[{"atl":[[110,1.45]],"id":41419611},{"atb":[[44,4.95]],"id":41419589},{"atb":[[44,0],[55,2.93]],"id":41419599},{"atl":[[34,4.95],[36,4.95],[44,9.9]],"id":41419608},{"atb":[[70,4.95],[80,2],[50,9.9],[60,0]],"id":41419586}],"con":true,"img":false}]}
{"op":"mcm","clk":"5348571953","pt":1646218954426,"mc":[{"id":"1.195453744","rc":[{"atl":[[110,0],[120,4.95]],"id":41419611},{"atb":[[120,0]],"id":41419591},{"atb":[[36,0],[38,4.95],[44,0],[30,24.62]],"id":41419589},{"atb":[[42,9.9],[50,4.95],[55,0]],"id":41419599},{"atl":[[260,0]],"id":41419630},{"atl":[[34,0],[42,0]],"id":41419608},{"atl":[[75,0],[80,9.9],[55,0],[60,4.95]],"id":41419612},{"atb":[[80,0]],"id":41419586},{"atl":[[42,0]],"id":41419594}],"con":true,"img":false}]}
{"op":"mcm","clk":"5348571963","pt":1646218954531,"mc":[{"id":"1.195453744","rc":[{"atl":[[85,0],[90,4.95],[110,0],[120,9.9]],"id":41419637}],"con":true,"img":false}]}
{"op":"mcm","clk":"5348571971","pt":1646218954636,"mc":[{"id":"1.195453744","rc":[{"atl":[[270,2],[630,0]],"id":41419611},{"atl":[[900,0],[920,3.39]],"id":41419630}],"con":true,"img":false}]}
{"op":"mcm","clk":"5348571991","pt":1646218954842,"mc":[{"id":"1.195453744","rc":[{"atb":[[38,11.15],[40,0]],"id":41419599},{"atl":[[42,14.71],[90,2]],"id":41419608}],"con":true,"img":false}]}
{"op":"mcm","clk":"5348572005","pt":1646218955049,"mc":[{"id":"1.195453744","rc":[{"atb":[[18,9.32]],"id":41419603},{"atl":[[42,18.58]],"id":41419608}],"con":true,"img":false}]}
{"op":"mcm","clk":"5348572020","pt":1646218955154,"mc":[{"id":"1.195453744","rc":[{"atl":[[110,1.45]],"id":41419611},{"atb":[[32,5.11]],"id":41419589},{"atb":[[42,13.77]],"id":41419599},{"atl":[[920,2],[910,0.17],[940,1.4]],"id":41419630},{"atl":[[36,0],[44,0]],"id":41419608},{"atl":[[75,2.14]],"id":41419612},{"atb":[[50,13.14]],"id":41419586}],"con":true,"img":false}]}
{"op":"mcm","clk":"5348572038","pt":1646218955309,"mc":[{"id":"1.195453744","rc":[{"atb":[[120,1.32]],"id":41419591},{"atl":[[19.5,8.56],[20,4.95],[23,0],[24,9.9]],"id":41419622},{"atl":[[90,6.73]],"id":41419637},{"atl":[[50,3.23]],"id":41419594}],"con":true,"img":false}]}
{"op":"mcm","clk":"5348572047","pt":1646218955422,"mc":[{"id":"1.195453744","rc":[{"atl":[[16.5,10.22],[17,4.95],[18.5,0],[19,9.9]],"id":41419621}],"con":true,"img":false}]}
{"op":"mcm","clk":"5348572070","pt":1646218955625,"mc":[{"id":"1.195453744","rc":[{"atl":[[270,6.92],[660,0]],"id":41419611}],"con":true,"img":false}]}
{"op":"mcm","clk":"5348572079","pt":1646218955728,"mc":[{"id":"1.195453744","rc":[{"atl":[[24,37.37]],"id":41419622}],"con":true,"img":false}]}
{"op":"mcm","clk":"5348572091","pt":1646218955838,"mc":[{"id":"1.195453744","rc":[{"atl":[[55,2]],"id":41419622},{"atl":[[34,4.95],[42,28.49]],"id":41419608},{"atl":[[19,39.84],[44,2.33]],"id":41419621}],"con":true,"img":false}]}
{"op":"mcm","clk":"5348572342","pt":1646218958634,"mc":[{"id":"1.195453744","rc":[{"atl":[[270,4.95]],"id":41419630}],"con":true,"img":false}]}
{"op":"mcm","clk":"5348572391","pt":1646218959315,"mc":[{"id":"1.195453744","rc":[{"atl":[[270,5.54],[920,3.44],[940,0]],"id":41419630}],"con":true,"img":false}]}
{"op":"mcm","clk":"5348572441","pt":1646218960040,"mc":[{"id":"1.195453744","rc":[{"atl":[[1000,2.15]],"id":41419591},{"atl":[[910,0]],"id":41419630},{"atb":[[5.5,51.81]],"id":41419621}],"con":true,"img":false}]}
{"op":"mcm","clk":"5348572450","pt":1646218960149,"mc":[{"id":"1.195453744","rc":[{"atb":[[6.2,0]],"id":41419621}],"con":true,"img":false}]}
{"op":"mcm","clk":"5348572473","pt":1646218960354,"mc":[{"id":"1.195453744","rc":[{"atl":[[1000,0.15]],"id":41419591},{"atb":[[20,0],[25,0]],"id":41419601},{"atb":[[6,4.95],[7,0]],"id":41419623},{"atb":[[17,0],[19.5,0]],"id":41419594}],"con":true,"img":false}]}
{"op":"mcm","clk":"5348572492","pt":1646218960567,"mc":[{"id":"1.195453744","rc":[{"atb":[[17.5,31.97],[17,2.72],[18,0],[19,0]],"id":41419603},{"atl":[[130,4.95],[110,0],[120,0]],"id":41419611},{"atb":[[9.6,22.08],[10.5,4.95],[11,0],[9.4,9.9]],"id":41419622},{"atl":[[90,1.78],[120,0]],"id":41419587},{"atl":[[270,0],[920,2]],"id":41419630},{"atl":[[180,0],[440,5.04]],"id":41419597},{"atl":[[130,9.9],[90,0],[95,4.95],[120,0]],"id":41419637},{"atl":[[42,0],[44,4.95],[50,0],[55,9.9]],"id":41419625}],"con":true,"img":false}]}
{"op":"mcm","clk":"5348572501","pt":1646218960611,"mc":[{"id":"1.195453744","rc":[{"atl":[[130,9.9],[95,4.95]],"id":41419587}],"con":true,"img":false}]}
{"op":"mcm","clk":"5348572523","pt":1646218960822,"mc":[{"id":"1.195453744","rc":[{"atb":[[18,14.27],[13.5,41.23]],"id":41419601},{"atl":[[65,4.95],[80,0],[85,9.9],[60,0]],"id":41419606},{"atb":[[5.6,9.9],[6,36.66],[4.4,110.16]],"id":41419623},{"atb":[[32,0],[26,9.9],[27,19.53],[30,7.67]],"id":41419600},{"atb":[[11.5,39.36],[13.5,17.12]],"id":41419594}],"con":true,"img":false}]}
{"op":"mcm","clk":"5348572543","pt":1646218961028,"mc":[{"id":"1.195453744","rc":[{"atl":[[38,0],[40,4.95],[46,0],[48,9.9]],"id":41419607},{"atb":[[17.5,4.95],[14.5,30.6]],"id":41419603},{"atl":[[130,20.25],[340,2]],"id":41419587},{"atb":[[21,3.27],[26,2.72]],"id":41419601},{"atb":[[40,9.9],[42,3.86],[48,4.95],[50,0]],"id":41419599},{"atb":[[7.2,2.72],[6.2,3.27]],"id":41419623},{"atl":[[75,0]],"id":41419598},{"atb":[[17,3.27],[19.5,2.72]],"id":41419594},{"atl":[[44,0],[55,0]],"id":41419594}],"con":true,"img":false}]}
{"op":"mcm","clk":"5348572564","pt":1646218961242,"mc":[{"id":"1.195453744","rc":[{"atb":[[17.5,0],[18,9.32]],"id":41419603},{"atl":[[260,0.61]],"id":41419611},{"atb":[[9.8,17.44]],"id":41419622},{"atl":[[260,4.95],[1000,0.15]],"id":41419630},{"atl":[[190,0.83]],"id":41419637},{"atl":[[120,1.32]],"id":41419625},{"atb":[[26,36.64]],"id":41419600},{"atl":[[46,4.95],[60,9.9]],"id":41419594}],"con":true,"img":false}]}
{"op":"mcm","clk":"5348572575","pt":1646218961363,"mc":[{"id":"1.195453744","rc":[{"atb":[[16.5,4.95],[14.5,40.51]],"id":41419603},{"atl":[[160,0.99],[170,4.95]],"id":41419597},{"atb":[[27,0]],"id":41419600}],"con":true,"img":false}]}
{"op":"mcm","clk":"5348572585","pt":1646218961470,"mc":[{"id":"1.195453744","rc":[{"atl":[[520,2],[920,0]],"id":41419630},{"atl":[[160,0]],"id":41419597},{"atb":[[90,4.95]],"id":41419604},{"atl":[[250,7.37]],"id":41419598}],"con":true,"img":false}]}
{"op":"mcm","clk":"5348572592","pt":1646218961567,"mc":[{"id":"1.195453744","rc":[{"atb":[[13.5,10.65]],"id":41419601},{"atl":[[170,0.93]],"id":41419606},{"atb":[[27,6.09]],"id":41419600},{"atl":[[100,9.9]],"id":41419598},{"atb":[[11.5,9.9]],"id":41419594},{"atl":[[70,0],[75,11.67]],"id":41419594}],"con":true,"img":false}]}
{"op":"mcm","clk":"5348572601","pt":1646218961675,"mc":[{"id":"1.195453744","rc":[{"atl":[[520,0],[920,2]],"id":41419630}],"con":true,"img":false}]}
{"op":"mcm","clk":"5348572611","pt":1646218961719,"mc":[{"id":"1.195453744","rc":[{"atl":[[190,7.92],[200,2]],"id":41419637},{"atl":[[130,2],[120,12.55]],"id":41419625},{"atl":[[80,6.95]],"id":41419598}],"con":true,"img":false}]}
{"op":"mcm","clk":"5348572620","pt":1646218961831,"mc":[{"id":"1.195453744","rc":[{"atl":[[40,0],[46,3.52],[48,0]],"id":41419607},{"atb":[[40,0],[48,0]],"id":41419599}],"con":true,"img":false}]}
{"op":"mcm","clk":"5348572632","pt":1646218961928,"mc":[{"id":"1.195453744","rc":[{"atl":[[500,0]],"id":41419625}],"con":true,"img":false}]}
{"op":"mcm","clk":"5348572670","pt":1646218962258,"mc":[{"id":"1.195453744","rc":[{"atl":[[430,0.37]],"id":41419597},{"atb":[[90,10.3]],"id":41419604}],"con":true,"img":false}]}
{"op":"mcm","clk":"5348572681","pt":1646218962359,"mc":[{"id":"1.195453744","rc":[{"atl":[[80,0],[85,12.09]],"id":41419607},{"atb":[[38,2.72],[29,21.79]],"id":41419599},{"atl":[[42,13.77],[90,14.21]],"id":41419608},{"atl":[[75,2]],"id":41419594}],"con":true,"img":false}]}
{"op":"mcm","clk":"5348572702","pt":1646218962549,"mc":[{"id":"1.195453744","rc":[{"atl":[[38,4.95],[46,13.42]],"id":41419607},{"atb":[[42,13.77],[50,4.95]],"id":41419599}],"con":true,"img":false}]}
{"op":"mcm","clk":"5348572869","pt":1646218964233,"mc":[{"id":"1.195453744","rc":[{"atl":[[160,0.99]],"id":41419597}],"con":true,"img":false}]}
{"op":"mcm","clk":"5348572934","pt":1646218964924,"mc":[{"id":"1.195453744","rc":[{"atl":[[430,0]],"id":41419597}],"con":true,"img":false}]}
{"op":"mcm","clk":"5348573012","pt":1646218965773,"mc":[{"id":"1.195453744","rc":[{"atl":[[720,0]],"id":41419589}],"con":true,"img":false}]}
{"op":"mcm","clk":"5348573023","pt":1646218965862,"mc":[{"id":"1.195453744","rc":[{"atl":[[380,5.56]],"id":41419589}],"con":true,"img":false}]}
{"op":"mcm","clk":"5348573196","pt":1646218967540,"mc":[{"id":"1.195453744","rc":[{"atl":[[38,9.23]],"id":41419607},{"atl":[[170,8.96],[180,0],[60,2.68]],"id":41419606},{"atl":[[150,9.09]],"id":41419635},{"atl":[[140,0],[80,26.96]],"id":41419612},{"atb":[[75,2.14]],"id":41419586},{"atl":[[230,5.92]],"id":41419586},{"atl":[[44,3.68],[60,22.12]],"id":41419594}],"con":true,"img":false}]}
{"op":"mcm","clk":"5348573205","pt":1646218967646,"mc":[{"id":"1.195453744","rc":[{"atb":[[40,4.06]],"id":41419589},{"atl":[[55,2.93]],"id":41419612}],"con":true,"img":false}]}
{"op":"mcm","clk":"5348573216","pt":1646218967749,"mc":[{"id":"1.195453744","rc":[{"atl":[[80,2],[100,0]],"id":41419598}],"con":true,"img":false}]}
{"op":"mcm","clk":"5348573224","pt":1646218967852,"mc":[{"id":"1.195453744","rc":[{"atl":[[85,4.95],[110,9.9]],"id":41419598}],"con":true,"img":false}]}
{"op":"mcm","clk":"5348573242","pt":1646218967963,"mc":[{"id":"1.195453744","rc":[{"atb":[[48,0],[50,28.98]],"id":41419586}],"con":true,"img":false}]}
{"op":"mcm","clk":"5348573276","pt":1646218968277,"mc":[{"id":"1.195453744","rc":[{"atb":[[32,19.82],[30,9.9]],"id":41419589},{"atl":[[90,15.17],[250,2]],"id":41419598},{"atl":[[50,0]],"id":41419594}],"con":true,"img":false}]}
{"op":"mcm","clk":"5348573288","pt":1646218968374,"mc":[{"id":"1.195453744","rc":[{"atl":[[46,9.9]],"id":41419607},{"atl":[[170,8.02]],"id":41419606},{"atb":[[50,25.75]],"id":41419586}],"con":true,"img":false}]}
{"op":"mcm","clk":"5348573301","pt":1646218968528,"mc":[{"id":"1.195453744","rc":[{"atb":[[32,14.71]],"id":41419589},{"atl":[[75,0]],"id":41419612}],"con":true,"img":false}]}
{"op":"mcm","clk":"5348573316","pt":1646218968635,"mc":[{"id":"1.195453744","rc":[{"atb":[[16.5,31.42]],"id":41419603}],"con":true,"img":false}]}
{"op":"mcm","clk":"5348573321","pt":1646218968737,"mc":[{"id":"1.195453744","rc":[{"atb":[[14.5,13.17]],"id":41419603}],"con":true,"img":false}]}
{"op":"mcm","clk":"5348573431","pt":1646218969951,"mc":[{"id":"1.195453744","rc":[{"atb":[[38,14.14],[29,6.84]],"id":41419599}],"con":true,"img":false}]}
{"op":"mcm","clk":"5348573449","pt":1646218970155,"mc":[{"id":"1.195453744","rc":[{"atl":[[1000,1.52],[250,0.63]],"id":41419630},{"atl":[[34,9.76]],"id":41419608}],"con":true,"img":false}]}
{"op":"mcm","clk":"5348573457","pt":1646218970268,"mc":[{"id":"1.195453744","rc":[{"atl":[[120,1.32]],"id":41419611},{"atb":[[55,2.93]],"id":41419599}],"con":true,"img":false}]}
{"op":"mcm","clk":"5348573476","pt":1646218970469,"mc":[{"id":"1.195453744","rc":[{"atl":[[90,1.78]],"id":41419637}],"con":true,"img":false}]}
{"op":"mcm","clk":"5348573501","pt":1646218970730,"mc":[{"id":"1.195453744","rc":[{"atl":[[260,5.88],[270,2]],"id":41419611}],"con":true,"img":false}]}
{"op":"mcm","clk":"5348573508","pt":1646218970832,"mc":[{"id":"1.195453744","rc":[{"atl":[[65,9.9],[46,3.52],[48,4.95],[60,0]],"id":41419603},{"atl":[[1000,1.36]],"id":41419630}],"con":true,"img":false}]}
{"op":"mcm","clk":"5348573536","pt":1646218971044,"mc":[{"id":"1.195453744","rc":[{"atl":[[260,5.27]],"id":41419611},{"atb":[[42,9.9]],"id":41419599},{"atl":[[250,0]],"id":41419630},{"atl":[[42,9.9]],"id":41419608}],"con":true,"img":false}]}
{"op":"mcm","clk":"5348573563","pt":1646218971358,"mc":[{"id":"1.195453744","rc":[{"atl":[[65,31.06],[160,2]],"id":41419603},{"atl":[[190,7.08]],"id":41419637}],"con":true,"img":false}]}
{"op":"mcm","clk":"5348573578","pt":1646218971469,"mc":[{"id":"1.195453744","rc":[{"atl":[[70,0],[50,0]],"id":41419593},{"atl":[[36,0],[38,4.95],[44,0],[46,9.9]],"id":41419601},{"atl":[[44,0]],"id":41419594}],"con":true,"img":false}]}
{"op":"mcm","clk":"5348573607","pt":1646218971680,"mc":[{"id":"1.195453744","rc":[{"atl":[[75,9.9],[55,4.95]],"id":41419593}],"con":true,"img":false}]}
{"op":"mcm","clk":"5348573627","pt":1646218971878,"mc":[{"id":"1.195453744","rc":[{"atl":[[250,0.63]],"id":41419630}],"con":true,"img":false}]}
{"op":"mcm","clk":"5348573634","pt":1646218971934,"mc":[{"id":"1.195453744","rc":[{"atl":[[160,0.99],[170,2],[190,7.23]],"id":41419593}],"con":true,"img":false}]}
{"op":"mcm","clk":"5348573647","pt":1646218972039,"mc":[{"id":"1.195453744","rc":[{"atl":[[75,14.21],[60,9.9]],"id":41419594}],"con":true,"img":false}]}
{"op":"mcm","clk":"5348573656","pt":1646218972141,"mc":[{"id":"1.195453744","rc":[{"atl":[[55,2.93]],"id":41419594}],"con":true,"img":false}]}
{"op":"mcm","clk":"5348573662","pt":1646218972245,"mc":[{"id":"1.195453744","rc":[{"atl":[[95,1.68]],"id":41419601}],"con":true,"img":false}]}
{"op":"mcm","clk":"5348573684","pt":1646218972557,"mc":[{"id":"1.195453744","rc":[{"atl":[[160,0]],"id":41419597}],"con":true,"img":false}]}
{"op":"mcm","clk":"5348573727","pt":1646218972867,"mc":[{"id":"1.195453744","rc":[{"atl":[[550,0]],"id":41419593},{"atl":[[95,13.9],[100,2]],"id":41419601}],"con":true,"img":false}]}
{"op":"mcm","clk":"5348573746","pt":1646218972969,"mc":[{"id":"1.195453744","rc":[{"atl":[[75,2]],"id":41419594}],"con":true,"img":false}]}
{"op":"mcm","clk":"5348573776","pt":1646218973228,"mc":[{"id":"1.195453744","rc":[{"atl":[[190,7.25],[440,2]],"id":41419597}],"con":true,"img":false}]}
{"op":"mcm","clk":"5348573812","pt":1646218973549,"mc":[{"id":"1.195453744","rc":[{"atl":[[250,0]],"id":41419630},{"atl":[[170,5.89]],"id":41419597}],"con":true,"img":false}]}
{"op":"mcm","clk":"5348573855","pt":1646218973957,"mc":[{"id":"1.195453744","rc":[{"atl":[[85,1.88],[90,4.95],[110,0],[120,9.9]],"id":41419592}],"con":true,"img":false}]}
{"op":"mcm","clk":"5348573891","pt":1646218974268,"mc":[{"id":"1.195453744","rc":[{"atl":[[260,5.56]],"id":41419630}],"con":true,"img":false}]}
{"op":"mcm","clk":"5348573915","pt":1646218974526,"mc":[{"id":"1.195453744","rc":[{"atl":[[330,2],[120,21.43]],"id":41419592}],"con":true,"img":false}]}
{"op":"mcm","clk":"5348573955","pt":1646218974941,"mc":[{"id":"1.195453744","rc":[{"atl":[[150,0],[380,5.63]],"id":41419635},{"atl":[[650,4.12],[230,0]],"id":41419586}],"con":true,"img":false}]}
{"op":"mcm","clk":"5348574034","pt":1646218975777,"mc":[{"id":"1.195453744","rc":[{"atb":[[10.5,0],[12.5,8.7]],"id":41419603}],"con":true,"img":false}]}
{"op":"mcm","clk":"5348574056","pt":1646218975935,"mc":[{"id":"1.195453744","rc":[{"atb":[[18,36.36]],"id":41419601},{"atb":[[6,82.32],[4.4,39.17]],"id":41419623},{"atl":[[650,2]],"id":41419586},{"atb":[[13.5,29.34]],"id":41419594}],"con":true,"img":false}]}
{"op":"mcm","clk":"5348574090","pt":1646218976250,"mc":[{"id":"1.195453744","rc":[{"atl":[[280,4.95]],"id":41419591},{"atb":[[10.5,21.64]],"id":41419622}],"con":true,"img":false}]}
{"op":"mcm","clk":"5348574113","pt":1646218976561,"mc":[{"id":"1.195453744","rc":[{"atl":[[130,20.59]],"id":41419637},{"atb":[[30,13.14]],"id":41419600},{"atl":[[60,22.12]],"id":41419594}],"con":true,"img":false}]}
{"op":"mcm","clk":"5348574119","pt":1646218976664,"mc":[{"id":"1.195453744","rc":[{"atl":[[190,0]],"id":41419637}],"con":true,"img":false}]}
{"op":"mcm","clk":"5348574146","pt":1646218976871,"mc":[{"id":"1.195453744","rc":[{"atl":[[270,0.58]],"id":41419591}],"con":true,"img":false}]}
{"op":"mcm","clk":"5348574174","pt":1646218977135,"mc":[{"id":"1.195453744","rc":[{"atb":[[42,21.63]],"id":41419599}],"con":true,"img":false}]}
{"op":"mcm","clk":"5348574184","pt":1646218977238,"mc":[{"id":"1.195453744","rc":[{"atb":[[9.8,2.72]],"id":41419622},{"atb":[[38,2.72]],"id":41419599}],"con":true,"img":false}]}
{"op":"mcm","clk":"5348574204","pt":1646218977446,"mc":[{"id":"1.195453744","rc":[{"atl":[[1000,1.54]],"id":41419591},{"atb":[[27,0]],"id":41419600}],"con":true,"img":false}]}
{"op":"mcm","clk":"5348574227","pt":1646218977758,"mc":[{"id":"1.195453744","rc":[{"atl":[[1000,1.38]],"id":41419591}],"con":true,"img":false}]}
{"op":"mcm","clk":"5348574250","pt":1646218977967,"mc":[{"id":"1.195453744","rc":[{"atb":[[25,30],[26,9.9]],"id":41419600}],"con":true,"img":false}]}
{"op":"mcm","clk":"5348574319","pt":1646218978746,"mc":[{"id":"1.195453744","rc":[{"atl":[[180,4.95]],"id":41419597}],"con":true,"img":false}]}
{"op":"mcm","clk":"5348574330","pt":1646218978858,"mc":[{"id":"1.195453744","rc":[{"atl":[[170,0]],"id":41419597}],"con":true,"img":false}]}
{"op":"mcm","clk":"5348574384","pt":1646218979472,"mc":[{"id":"1.195453744","rc":[{"atl":[[260,0]],"id":41419630}],"con":true,"img":false}]}
{"op":"mcm","clk":"5348574393","pt":1646218979576,"mc":[{"id":"1.195453744","rc":[{"atl":[[270,4.95]],"id":41419630}],"con":true,"img":false}]}
{"op":"mcm","clk":"5348574399","pt":1646218979627,"mc":[{"id":"1.195453744","rc":[{"atl":[[180,5.84]],"id":41419597}],"con":true,"img":false}]}
{"op":"mcm","clk":"5348574411","pt":1646218979735,"mc":[{"id":"1.195453744","rc":[{"atl":[[520,2],[920,0]],"id":41419630}],"con":true,"img":false}]}
{"op":"mcm","clk":"5348574430","pt":1646218979947,"mc":[{"id":"1.195453744","rc":[{"atl":[[940,1.47],[1000,0]],"id":41419630}],"con":true,"img":false}]}
{"op":"mcm","clk":"5348574449","pt":1646218980155,"mc":[{"id":"1.195453744","rc":[{"atl":[[910,0.17]],"id":41419630}],"con":true,"img":false}]}
{"op":"mcm","clk":"5348574481","pt":1646218980473,"mc":[{"id":"1.195453744","rc":[{"atl":[[190,0],[440,5.17]],"id":41419597}],"con":true,"img":false}]}
{"op":"mcm","clk":"5348574550","pt":1646218981050,"mc":[{"id":"1.195453744","rc":[{"atb":[[19,0],[23,0]],"id":41419608}],"con":true,"img":false}]}
{"op":"mcm","clk":"5348574578","pt":1646218981262,"mc":[{"id":"1.195453744","rc":[{"atl":[[46,0],[30,4.95]],"id":41419607},{"atb":[[40,0],[42,9.9],[48,3.37],[50,4.95]],"id":41419605},{"atb":[[16.5,26.47],[18.5,9.9],[21,4.95],[14.5,3.27]],"id":41419603},{"atl":[[95,4.95]],"id":41419611},{"atb":[[21,19.57],[22,9.9],[25,3.27],[26,4.95]],"id":41419593},{"atb":[[9.6,31.99],[10.5,16.68],[11,4.95],[9.4,0]],"id":41419622},{"atb":[[38,0],[40,13.97],[48,4.95],[30,0]],"id":41419589},{"atb":[[16,10.56],[16.5,4.95],[14,2.72],[14.5,9.9]],"id":41419620},{"atl":[[130,10.34],[90,6.73],[95,0],[120,9.9]],"id":41419587},{"atb":[[16,0],[16.5,9.9],[18,31.41],[18.5,4.95]],"id":41419601},{"atb":[[42,11.72],[46,9.9],[50,0],[60,4.95]],"id":41419599},{"atb":[[75,0],[80,4.95],[55,0],[60,21.01]],"id":41419630},{"atl":[[42,0],[28,4.95]],"id":41419608},{"atl":[[85,4.95],[90,1.78],[110,9.9],[120,0]],"id":41419639},{"atl":[[65,0],[70,9.9],[85,0],[50,4.95]],"id":41419606},{"atb":[[26,0],[30,0]],"id":41419637},{"atb":[[70,0],[75,9.9],[90,5.35],[95,6.37]],"id":41419604},{"atl":[[130,1.23],[120,4.95]],"id":41419635},{"atl":[[80,17.05],[44,4.95],[55,12.84],[60,0]],"id":41419612},{"atl":[[17,4.95],[18.5,9.05],[19,9.9],[21,0]],"id":41419610},{"atl":[[10.5,9.9],[11,15.85],[13,0],[9.4,4.95]],"id":41419623},{"atb":[[90,4.95],[50,15.84]],"id":41419586},{"atb":[[34,4.95],[26,0],[28,9.9],[30,8.19]],"id":41419600},{"atb":[[17.5,16.59],[17,0],[15,25.35],[15.5,9.9]],"id":41419596},{"atl":[[42,4.95],[46,0],[50,9.9],[60,12.21]],"id":41419594}],"con":true,"img":false}]}
{"op":"mcm","clk":"5348574585","pt":1646218981365,"mc":[{"id":"1.195453744","rc":[{"atb":[[32,4.95],[27,25.39]],"id":41419637}],"con":true,"img":false}]}
{"op":"mcm","clk":"5348574603","pt":1646218981570,"mc":[{"id":"1.195453744","rc":[{"atb":[[16.5,15.18],[12.5,43.52]],"id":41419608}],"con":true,"img":false}]}
{"op":"mcm","clk":"5348574625","pt":1646218981678,"mc":[{"id":"1.195453744","rc":[{"atb":[[36,0],[42,22.27]],"id":41419605},{"atb":[[16.5,0],[21,12.88]],"id":41419603},{"atl":[[95,6.63]],"id":41419611},{"atb":[[21,0],[25,15.48]],"id":41419593},{"atb":[[9.6,9.9]],"id":41419622},{"atb":[[48,8.32]],"id":41419589},{"atb":[[14.5,39.6]],"id":41419620},{"atl":[[80,2.09],[340,2],[110,22.67]],"id":41419639},{"atb":[[16.5,28.72],[27,13.17]],"id":41419637},{"atl":[[44,0]],"id":41419610},{"atl":[[11,37.94],[9.4,23.82]],"id":41419623},{"atb":[[90,6.73]],"id":41419586}],"con":true,"img":false}]}
{"op":"mcm","clk":"5348574631","pt":1646218981781,"mc":[{"id":"1.195453744","rc":[{"atl":[[30,10.42]],"id":41419607},{"atb":[[55,2.93]],"id":41419605},{"atb":[[18,30.55]],"id":41419603},{"atb":[[9.8,22.81]],"id":41419622},{"atb":[[17,9.9],[11.5,3.27]],"id":41419620},{"atl":[[110,1.45]],"id":41419635},{"atl":[[42,3.86]],"id":41419612},{"atl":[[19,30.73]],"id":41419610},{"atl":[[15.5,0]],"id":41419623}],"con":true,"img":false}]}
{"op":"mcm","clk":"5348574646","pt":1646218981886,"mc":[{"id":"1.195453744","rc":[{"atb":[[18.5,3.27],[22,2.72]],"id":41419608}],"con":true,"img":false}]}
{"op":"mcm","clk":"5348574661","pt":1646218981997,"mc":[{"id":"1.195453744","rc":[{"atl":[[36,4.95],[44,9.9]],"id":41419601}],"con":true,"img":false}]}
{"op":"mcm","clk":"5348574669","pt":1646218982052,"mc":[{"id":"1.195453744","rc":[{"atl":[[38,0],[46,0]],"id":41419601}],"con":true,"img":false}]}
{"op":"mcm","clk":"5348574696","pt":1646218982263,"mc":[{"id":"1.195453744","rc":[{"atl":[[70,24.62],[170,0]],"id":41419606},{"atl":[[130,10.68],[75,4.95]],"id":41419637},{"atl":[[80,0],[55,34.07]],"id":41419612},{"atl":[[230,6.1]],"id":41419586},{"atl":[[42,8.82],[60,0]],"id":41419594}],"con":true,"img":false}]}
{"op":"mcm","clk":"5348574706","pt":1646218982370,"mc":[{"id":"1.195453744","rc":[{"atb":[[18,21.22]],"id":41419603},{"atl":[[120,0]],"id":41419611},{"atl":[[90,0],[110,9.9]],"id":41419639},{"atb":[[16.5,8.59]],"id":41419637},{"atl":[[130,12.04],[380,2]],"id":41419635},{"atb":[[75,0]],"id":41419586},{"atl":[[55,15.15]],"id":41419594}],"con":true,"img":false}]}
{"op":"mcm","clk":"5348574711","pt":1646218982470,"mc":[{"id":"1.195453744","rc":[{"atb":[[48,0]],"id":41419605},{"atb":[[40,9.9]],"id":41419589},{"atb":[[16,0]],"id":41419620},{"atl":[[130,10.81]],"id":41419635},{"atl":[[55,31.13]],"id":41419612},{"atl":[[11,22.08]],"id":41419623}],"con":true,"img":false}]}
{"op":"mcm","clk":"5348574724","pt":1646218982578,"mc":[{"id":"1.195453744","rc":[{"atl":[[38,4.95]],"id":41419607},{"atl":[[270,0],[260,4.95]],"id":41419630}],"con":true,"img":false}]}
{"op":"mcm","clk":"5348574746","pt":1646218982790,"mc":[{"id":"1.195453744","rc":[{"atl":[[75,7.09]],"id":41419637},{"atb":[[70,19.66],[50,0]],"id":41419586}],"con":true,"img":false}]}
{"op":"mcm","clk":"5348574776","pt":1646218983045,"mc":[{"id":"1.195453744","rc":[{"atl":[[55,12.21]],"id":41419594}],"con":true,"img":false}]}
{"op":"mcm","clk":"5348574823","pt":1646218983564,"mc":[{"id":"1.195453744","rc":[{"atb":[[70,4.95]],"id":41419586}],"con":true,"img":false}]}
{"op":"mcm","clk":"5348574836","pt":1646218983671,"mc":[{"id":"1.195453744","rc":[{"atl":[[90,0]],"id":41419637}],"con":true,"img":false}]}
{"op":"mcm","clk":"5348574941","pt":1646218984656,"mc":[{"id":"1.195453744","rc":[{"atl":[[130,9.9],[85,0],[90,0],[95,4.95],[120,11.52]],"id":41419592}],"con":true,"img":false}]}
{"op":"mcm","clk":"5348574965","pt":1646218984868,"mc":[{"id":"1.195453744","rc":[{"atb":[[42,0],[46,21.63]],"id":41419599},{"atl":[[260,5.56],[910,1.71],[940,0]],"id":41419630}],"con":true,"img":false}]}
{"op":"mcm","clk":"5348574982","pt":1646218984973,"mc":[{"id":"1.195453744","rc":[{"atb":[[60,7.64]],"id":41419599}],"con":true,"img":false}]}
{"op":"mcm","clk":"5348574989","pt":1646218985077,"mc":[{"id":"1.195453744","rc":[{"atl":[[520,0],[900,2]],"id":41419630},{"atl":[[120,0]],"id":41419592}],"con":true,"img":false}]}
{"op":"mcm","clk":"5348575003","pt":1646218985183,"mc":[{"id":"1.195453744","rc":[{"atl":[[130,20.78]],"id":41419592}],"con":true,"img":false}]}
{"op":"mcm","clk":"5348575023","pt":1646218985391,"mc":[{"id":"1.195453744","rc":[{"atl":[[120,1.32]],"id":41419592}],"con":true,"img":false}]}
{"op":"mcm","clk":"5348575069","pt":1646218985653,"mc":[{"id":"1.195453744","rc":[{"atl":[[910,1.54]],"id":41419630}],"con":true,"img":false}]}
{"op":"mcm","clk":"5348575081","pt":1646218985755,"mc":[{"id":"1.195453744","rc":[{"atb":[[55,0]],"id":41419599}],"con":true,"img":false}]}
{"op":"mcm","clk":"5348575141","pt":1646218986271,"mc":[{"id":"1.195453744","rc":[{"atb":[[85,9.33],[90,9.9],[110,0],[120,6.28]],"id":41419591},{"atl":[[42,4.95],[44,0],[50,9.9],[55,0]],"id":41419625}],"con":true,"img":false}]}
{"op":"mcm","clk":"5348575177","pt":1646218986688,"mc":[{"id":"1.195453744","rc":[{"atl":[[160,9.85],[190,0],[55,7.89]],"id":41419593}],"con":true,"img":false}]}
{"op":"mcm","clk":"5348575218","pt":1646218987059,"mc":[{"id":"1.195453744","rc":[{"atl":[[36,9.48]],"id":41419601}],"con":true,"img":false}]}
{"op":"mcm","clk":"5348575266","pt":1646218987482,"mc":[{"id":"1.195453744","rc":[{"atl":[[160,8.85]],"id":41419593}],"con":true,"img":false}]}
{"op":"mcm","clk":"5348575305","pt":1646218987889,"mc":[{"id":"1.195453744","rc":[{"atl":[[95,12.21]],"id":41419601}],"con":true,"img":false}]}
{"op":"mcm","clk":"5348575314","pt":1646218987987,"mc":[{"id":"1.195453744","rc":[{"atl":[[200,7.1],[440,2]],"id":41419597}],"con":true,"img":false}]}
{"op":"mcm","clk":"5348575460","pt":1646218989549,"mc":[{"id":"1.195453744","rc":[{"atl":[[650,4.18]],"id":41419586}],"con":true,"img":false}]}
{"op":"mcm","clk":"5348575470","pt":1646218989654,"mc":[{"id":"1.195453744","rc":[{"atl":[[230,0]],"id":41419586}],"con":true,"img":false}]}
{"op":"mcm","clk":"5348575535","pt":1646218990282,"mc":[{"id":"1.195453744","rc":[{"atl":[[650,2]],"id":41419586}],"con":true,"img":false}]}
{"op":"mcm","clk":"5348575565","pt":1646218990591,"mc":[{"id":"1.195453744","rc":[{"atb":[[18.5,26.4],[18,9.32]],"id":41419601}],"con":true,"img":false}]}
{"op":"mcm","clk":"5348575599","pt":1646218990851,"mc":[{"id":"1.195453744","rc":[{"atb":[[11,20.8]],"id":41419622}],"con":true,"img":false}]}
{"op":"mcm","clk":"5348575634","pt":1646218991167,"mc":[{"id":"1.195453744","rc":[{"atb":[[34,9.76]],"id":41419600}],"con":true,"img":false}]}
{"op":"mcm","clk":"5348575720","pt":1646218991895,"mc":[{"id":"1.195453744","rc":[{"atb":[[10.5,0]],"id":41419622}],"con":true,"img":false}]}
{"op":"mcm","clk":"5348575732","pt":1646218992000,"mc":[{"id":"1.195453744","rc":[{"atb":[[46,9.9]],"id":41419599},{"atb":[[30,2.72]],"id":41419600}],"con":true,"img":false}]}
{"op":"mcm","clk":"5348575742","pt":1646218992048,"mc":[{"id":"1.195453744","rc":[{"atb":[[38,15.98]],"id":41419599}],"con":true,"img":false}]}
{"op":"mcm","clk":"5348575779","pt":1646218992362,"mc":[{"id":"1.195453744","rc":[{"atb":[[9.6,55.57],[9.8,2.72]],"id":41419622}],"con":true,"img":false}]}
{"op":"mcm","clk":"5348575812","pt":1646218992673,"mc":[{"id":"1.195453744","rc":[{"atb":[[25,3.27],[28,36.42]],"id":41419600}],"con":true,"img":false}]}
{"op":"mcm","clk":"5348576064","pt":1646218995069,"mc":[{"id":"1.195453744","rc":[{"atl":[[200,0],[440,5.27]],"id":41419597}],"con":true,"img":false}]}
{"op":"mcm","clk":"5348576163","pt":1646218996059,"mc":[{"id":"1.195453744","rc":[{"atl":[[440,2]],"id":41419597},{"atb":[[16.5,37.05],[12.5,11.58]],"id":41419608}],"con":true,"img":false}]}
{"op":"mcm","clk":"5348576183","pt":1646218996268,"mc":[{"id":"1.195453744","rc":[{"atl":[[110,23.04]],"id":41419639},{"atb":[[27,31.08]],"id":41419637},{"atb":[[65,9.9],[85,4.95]],"id":41419585}],"con":true,"img":false}]}
{"op":"mcm","clk":"5348576195","pt":1646218996367,"mc":[{"id":"1.195453744","rc":[{"atb":[[80,2],[60,0]],"id":41419585}],"con":true,"img":false}]}
{"op":"mcm","clk":"5348576234","pt":1646218996789,"mc":[{"id":"1.195453744","rc":[{"atb":[[65,26.11],[90,1.78],[46,0]],"id":41419585},{"atl":[[230,6.28]],"id":41419586}],"con":true,"img":false}]}
{"op":"mcm","clk":"5348576292","pt":1646218997375,"mc":[{"id":"1.195453744","rc":[{"atb":[[46,16.93]],"id":41419586}],"con":true,"img":false}]}
{"op":"mcm","clk":"5348576300","pt":1646218997471,"mc":[{"id":"1.195453744","rc":[{"atb":[[80,0]],"id":41419585}],"con":true,"img":false}]}
{"op":"mcm","clk":"5348576373","pt":1646218998367,"mc":[{"id":"1.195453744","rc":[{"atl":[[290,4.95]],"id":41419640},{"atl":[[130,20.25],[90,1.78],[95,4.95],[120,0]],"id":41419587}],"con":true,"img":false}]}
{"op":"mcm","clk":"5348576384","pt":1646218998471,"mc":[{"id":"1.195453744","rc":[{"atl":[[910,2],[1000,0]],"id":41419640}],"con":true,"img":false}]}
{"op":"mcm","clk":"5348576423","pt":1646218998898,"mc":[{"id":"1.195453744","rc":[{"atl":[[290,5.5],[910,0],[990,2.15],[1000,1.44]],"id":41419640}],"con":true,"img":false}]}
{"op":"mcm","clk":"5348576473","pt":1646218999362,"mc":[{"id":"1.195453744","rc":[{"atl":[[170,4.95],[180,0.88]],"id":41419597}],"con":true,"img":false}]}
{"op":"mcm","clk":"5348576492","pt":1646218999679,"mc":[{"id":"1.195453744","rc":[{"atl":[[990,2]],"id":41419640}],"con":true,"img":false}]}
{"op":"mcm","clk":"5348576503","pt":1646218999788,"mc":[{"id":"1.195453744","rc":[{"atl":[[170,5.89]],"id":41419597},{"atl":[[95,6.63]],"id":41419592}],"con":true,"img":false}]}
{"op":"mcm","clk":"5348576563","pt":1646219000361,"mc":[{"id":"1.195453744","rc":[{"atl":[[260,0.61],[250,4.95]],"id":41419630}],"con":true,"img":false}]}
{"op":"mcm","clk":"5348576574","pt":1646219000466,"mc":[{"id":"1.195453744","rc":[{"atl":[[520,2],[900,0]],"id":41419630}],"con":true,"img":false}]}
{"op":"mcm","clk":"5348576588","pt":1646219000571,"mc":[{"id":"1.195453744","rc":[{"atl":[[180,0]],"id":41419597},{"atl":[[120,0]],"id":41419592}],"con":true,"img":false}]}
{"op":"mcm","clk":"5348576607","pt":1646219000775,"mc":[{"id":"1.195453744","rc":[{"atl":[[290,0]],"id":41419640},{"atl":[[910,0],[900,1.61],[250,5.59]],"id":41419630}],"con":true,"img":false}]}
{"op":"mcm","clk":"5348576613","pt":1646219000880,"mc":[{"id":"1.195453744","rc":[{"atl":[[170,0],[180,4.95]],"id":41419597}],"con":true,"img":false}]}
{"op":"mcm","clk":"5348576623","pt":1646219000985,"mc":[{"id":"1.195453744","rc":[{"atl":[[990,0],[1000,3.44]],"id":41419640}],"con":true,"img":false}]}
{"op":"mcm","clk":"5348576630","pt":1646219001086,"mc":[{"id":"1.195453744","rc":[{"atl":[[330,6.41]],"id":41419592}],"con":true,"img":false}]}
{"op":"mcm","clk":"5348576639","pt":1646219001189,"mc":[{"id":"1.195453744","rc":[{"atl":[[130,9.9]],"id":41419592}],"con":true,"img":false}]}
{"op":"mcm","clk":"5348576648","pt":1646219001294,"mc":[{"id":"1.195453744","rc":[{"atl":[[1000,2]],"id":41419640}],"con":true,"img":false}]}
{"op":"mcm","clk":"5348576681","pt":1646219001607,"mc":[{"id":"1.195453744","rc":[{"atl":[[290,4.95],[1000,2.15]],"id":41419640},{"atl":[[260,0]],"id":41419630}],"con":true,"img":false}]}
{"op":"mcm","clk":"5348576699","pt":1646219001764,"mc":[{"id":"1.195453744","rc":[{"atl":[[180,5.84]],"id":41419597}],"con":true,"img":false}]}
{"op":"mcm","clk":"5348576766","pt":1646219002494,"mc":[{"id":"1.195453744","rc":[{"atl":[[290,0]],"id":41419640},{"atl":[[200,7.3]],"id":41419597}],"con":true,"img":false}]}
{"op":"mcm","clk":"5348576905","pt":1646219003906,"mc":[{"id":"1.195453744","rc":[{"atl":[[650,4.24],[230,0]],"id":41419586}],"con":true,"img":false}]}
{"op":"mcm","clk":"5348576916","pt":1646219004008,"mc":[{"id":"1.195453744","rc":[{"atl":[[260,4.95],[250,0]],"id":41419630},{"atl":[[130,0],[140,9.9],[95,1.68],[100,4.95]],"id":41419592}],"con":true,"img":false}]}
{"op":"mcm","clk":"5348576936","pt":1646219004215,"mc":[{"id":"1.195453744","rc":[{"atl":[[32,4.95],[38,0],[40,9.9],[30,0]],"id":41419607},{"atl":[[130,0],[140,9.9],[95,0],[100,4.95]],"id":41419611},{"atl":[[75,0],[80,9.9],[55,0],[60,4.95]],"id":41419593},{"atl":[[130,10.34],[140,9.9],[90,0],[95,0],[100,4.95]],"id":41419587},{"atl":[[180,0],[190,4.95]],"id":41419597},{"atl":[[70,14.71],[75,9.9],[50,0],[55,4.95]],"id":41419606},{"atl":[[75,0],[80,4.95],[95,0],[100,9.9]],"id":41419637},{"atl":[[42,0],[44,0],[46,4.95],[55,21.22],[60,9.9]],"id":41419612},{"atl":[[85,0],[90,4.95],[110,0]],"id":41419598},{"atl":[[42,0],[44,4.95],[50,0],[55,22.12]],"id":41419594}],"con":true,"img":false}]}
{"op":"mcm","clk":"5348576956","pt":1646219004378,"mc":[{"id":"1.195453744","rc":[{"atl":[[80,0]],"id":41419598}],"con":true,"img":false}]}
{"op":"mcm","clk":"5348577002","pt":1646219004583,"mc":[{"id":"1.195453744","rc":[{"atl":[[260,2]],"id":41419598}],"con":true,"img":false}]}
{"op":"mcm","clk":"5348577011","pt":1646219004694,"mc":[{"id":"1.195453744","rc":[{"atl":[[130,0],[140,20.4]],"id":41419587},{"atl":[[260,0],[290,4.95]],"id":41419630},{"atl":[[55,7.89]],"id":41419606},{"atl":[[55,0],[60,34.4]],"id":41419612},{"atl":[[140,0],[95,0],[100,0],[110,4.95]],"id":41419592},{"atl":[[250,5.86]],"id":41419598},{"atl":[[75,14.21],[55,9.9]],"id":41419594}],"con":true,"img":false}]}
{"op":"mcm","clk":"5348577020","pt":1646219004798,"mc":[{"id":"1.195453744","rc":[{"atl":[[510,0.31]],"id":41419630}],"con":true,"img":false}]}
{"op":"mcm","clk":"5348577033","pt":1646219004900,"mc":[{"id":"1.195453744","rc":[{"atl":[[32,0],[38,4.28],[40,0]],"id":41419607},{"atl":[[130,1.23]],"id":41419611},{"atl":[[75,2.14]],"id":41419593},{"atl":[[130,1.23]],"id":41419587},{"atl":[[190,0],[200,13.05]],"id":41419597},{"atl":[[95,1.68]],"id":41419637},{"atl":[[50,3.23]],"id":41419612},{"atl":[[50,3.23]],"id":41419594}],"con":true,"img":false}]}
{"op":"mcm","clk":"5348577040","pt":1646219005003,"mc":[{"id":"1.195453744","rc":[{"atl":[[34,4.95],[42,9.9]],"id":41419607}],"con":true,"img":false}]}
{"op":"mcm","clk":"5348577060","pt":1646219005213,"mc":[{"id":"1.195453744","rc":[{"atl":[[90,6.73]],"id":41419598}],"con":true,"img":false}]}
{"op":"mcm","clk":"5348577077","pt":1646219005366,"mc":[{"id":"1.195453744","rc":[{"atl":[[42,22.63],[85,2]],"id":41419607},{"atl":[[260,0],[140,20.41]],"id":41419611},{"atl":[[80,24.62],[160,0]],"id":41419593},{"atl":[[130,0],[100,24.61]],"id":41419637},{"atl":[[1000,0.15]],"id":41419592}],"con":true,"img":false}]}
{"op":"mcm","clk":"5348577089","pt":1646219005470,"mc":[{"id":"1.195453744","rc":[{"atl":[[60,0]],"id":41419606},{"atl":[[330,4.41],[740,2]],"id":41419592}],"con":true,"img":false}]}
{"op":"mcm","clk":"5348577123","pt":1646219005888,"mc":[{"id":"1.195453744","rc":[{"atl":[[75,29.54]],"id":41419606}],"con":true,"img":false}]}
{"op":"mcm","clk":"5348577133","pt":1646219005991,"mc":[{"id":"1.195453744","rc":[{"atl":[[70,0]],"id":41419606}],"con":true,"img":false}]}
{"op":"mcm","clk":"5348577218","pt":1646219006675,"mc":[{"id":"1.195453744","rc":[{"atb":[[32,0],[34,9.9],[40,6.79],[42,4.95]],"id":41419587},{"atb":[[32,9.9],[38,4.28],[40,4.95],[30,0]],"id":41419639},{"atb":[[36,0],[38,11.96],[29,21.04],[30,9.9]],"id":41419592},{"atb":[[7.2,0],[6.2,0]],"id":41419623},{"atl":[[16.5,15.18],[17,0],[18.5,9.9],[19,29.93]],"id":41419621}],"con":true,"img":false}]}
{"op":"mcm","clk":"5348577243","pt":1646219006885,"mc":[{"id":"1.195453744","rc":[{"atl":[[36,4.95],[44,9.9]],"id":41419607},{"atl":[[65,4.95],[80,14.71],[85,9.9],[60,0]],"id":41419593},{"atb":[[9.6,45.66],[10,4.95],[9.2,9.9],[11,0]],"id":41419622},{"atl":[[200,0],[230,4.95]],"id":41419597},{"atl":[[34,4.8],[38,9.9],[28,0],[30,4.95]],"id":41419608},{"atl":[[75,19.63],[80,9.9],[55,0],[60,4.95]],"id":41419606},{"atl":[[190,4.95]],"id":41419604},{"atl":[[130,0],[120,0]],"id":41419635},{"atl":[[90,0]],"id":41419598}],"con":true,"img":false}]}
{"op":"mcm","clk":"5348577254","pt":1646219006996,"mc":[{"id":"1.195453744","rc":[{"atl":[[34,0],[42,12.72]],"id":41419607},{"atl":[[140,10.5],[100,0]],"id":41419611},{"atl":[[36,0],[40,4.95],[44,0],[48,9.9]],"id":41419601},{"atl":[[290,0]],"id":41419630},{"atl":[[90,4.95],[120,9.9]],"id":41419637},{"atl":[[180,0.88]],"id":41419604},{"atl":[[130,4.95],[110,0]],"id":41419635},{"atl":[[70,9.9],[46,0],[50,8.19],[60,24.49]],"id":41419612},{"atl":[[140,9.9],[100,4.95]],"id":41419598},{"atl":[[44,0],[46,4.95],[55,0],[60,9.9]],"id":41419594}],"con":true,"img":false}]}
{"op":"mcm","clk":"5348577267","pt":1646219007095,"mc":[{"id":"1.195453744","rc":[{"atl":[[120,4.95]],"id":41419611},{"atb":[[34,27.35],[44,3.68],[30,3.27]],"id":41419587},{"atb":[[32,24.62],[42,3.86],[26,0]],"id":41419639},{"atl":[[80,0],[100,14.71]],"id":41419637},{"atl":[[550,2],[930,0]],"id":41419604},{"atb":[[6,36.66]],"id":41419623}],"con":true,"img":false}]}
{"op":"mcm","clk":"5348577293","pt":1646219007303,"mc":[{"id":"1.195453744","rc":[{"atl":[[38,24.41],[30,10.42]],"id":41419608},{"atl":[[180,0],[930,1.58],[960,0]],"id":41419604},{"atb":[[4.4,107.43]],"id":41419623}],"con":true,"img":false}]}
{"op":"mcm","clk":"5348577301","pt":1646219007405,"mc":[{"id":"1.195453744","rc":[{"atl":[[90,2]],"id":41419608},{"atb":[[6,39.93],[7,2.72]],"id":41419623}],"con":true,"img":false}]}
{"op":"mcm","clk":"5348577310","pt":1646219007508,"mc":[{"id":"1.195453744","rc":[{"atl":[[150,9.84]],"id":41419635}],"con":true,"img":false}]}
{"op":"mcm","clk":"5348577319","pt":1646219007611,"mc":[{"id":"1.195453744","rc":[{"atl":[[65,0],[80,24.62],[85,0],[60,4.95]],"id":41419593},{"atb":[[9.8,17.44]],"id":41419622},{"atl":[[430,0.37]],"id":41419597},{"atl":[[70,2.29],[80,0],[60,0]],"id":41419606},{"atl":[[95,1.68]],"id":41419598}],"con":true,"img":false}]}
{"op":"mcm","clk":"5348577324","pt":1646219007667,"mc":[{"id":"1.195453744","rc":[{"atl":[[36,0],[44,0]],"id":41419607},{"atl":[[46,3.52]],"id":41419601},{"atl":[[290,4.95]],"id":41419630},{"atl":[[90,0],[120,0]],"id":41419637},{"atl":[[370,0.43]],"id":41419635},{"atl":[[70,0],[50,3.23]],"id":41419612},{"atl":[[140,0],[90,4.95],[100,0],[120,9.9]],"id":41419598}],"con":true,"img":false}]}
{"op":"mcm","clk":"5348577335","pt":1646219007772,"mc":[{"id":"1.195453744","rc":[{"atb":[[40,2.72]],"id":41419587},{"atb":[[38,0]],"id":41419639}],"con":true,"img":false}]}
{"op":"mcm","clk":"5348577341","pt":1646219007875,"mc":[{"id":"1.195453744","rc":[{"atl":[[140,9.9],[100,4.95],[110,0]],"id":41419592}],"con":true,"img":false}]}
{"op":"mcm","clk":"5348577349","pt":1646219007978,"mc":[{"id":"1.195453744","rc":[{"atl":[[330,0],[340,2],[740,1.98]],"id":41419592}],"con":true,"img":false}]}
{"op":"mcm","clk":"5348577357","pt":1646219008083,"mc":[{"id":"1.195453744","rc":[{"atl":[[34,0]],"id":41419608},{"atl":[[190,5.79]],"id":41419604}],"con":true,"img":false}]}
{"op":"mcm","clk":"5348577365","pt":1646219008186,"mc":[{"id":"1.195453744","rc":[{"atl":[[95,0],[48,22.49]],"id":41419601}],"con":true,"img":false}]}
{"op":"mcm","clk":"5348577386","pt":1646219008397,"mc":[{"id":"1.195453744","rc":[{"atl":[[34,4.95],[42,22.63]],"id":41419607},{"atl":[[75,29.54],[55,4.95]],"id":41419606},{"atl":[[46,4.95],[60,34.4]],"id":41419612}],"con":true,"img":false}]}
{"op":"mcm","clk":"5348577400","pt":1646219008500,"mc":[{"id":"1.195453744","rc":[{"atb":[[34,7.53]],"id":41419637},{"atl":[[80,4.95],[100,24.61]],"id":41419637}],"con":true,"img":false}]}
{"op":"mcm","clk":"5348577503","pt":1646219009491,"mc":[{"id":"1.195453744","rc":[{"atl":[[440,5.36]],"id":41419597}],"con":true,"img":false}]}
{"op":"mcm","clk":"5348577667","pt":1646219011004,"mc":[{"id":"1.195453744","rc":[{"atl":[[650,2],[230,6.45]],"id":41419586}],"con":true,"img":false}]}
{"op":"mcm","clk":"5348577767","pt":1646219011897,"mc":[{"id":"1.195453744","rc":[{"atb":[[65,2.47],[70,4.95],[48,0],[50,9.9]],"id":41419636},{"atl":[[230,0]],"id":41419586}],"con":true,"img":false}]}
{"op":"mcm","clk":"5348577804","pt":1646219012310,"mc":[{"id":"1.195453744","rc":[{"atl":[[550,0],[930,3.58]],"id":41419604}],"con":true,"img":false}]}
{"op":"mcm","clk":"5348577815","pt":1646219012422,"mc":[{"id":"1.195453744","rc":[{"atb":[[75,2.14],[50,20.95]],"id":41419636}],"con":true,"img":false}]}
{"op":"mcm","clk":"5348577841","pt":1646219012726,"mc":[{"id":"1.195453744","rc":[{"atb":[[42,0]],"id":41419636}],"con":true,"img":false}]}
{"op":"mcm","clk":"5348577888","pt":1646219013202,"mc":[{"id":"1.195453744","rc":[{"atb":[[65,0]],"id":41419636}],"con":true,"img":false}]}
{"op":"mcm","clk":"5348577962","pt":1646219013983,"mc":[{"id":"1.195453744","rc":[{"atl":[[220,0.72]],"id":41419597},{"atl":[[34,9.9],[38,14.5],[28,4.95],[30,5.46]],"id":41419608}],"con":true,"img":false}]}
{"op":"mcm","clk":"5348577973","pt":1646219014085,"mc":[{"id":"1.195453744","rc":[{"atl":[[100,6.55]],"id":41419592}],"con":true,"img":false}]}
{"op":"mcm","clk":"5348577996","pt":1646219014297,"mc":[{"id":"1.195453744","rc":[{"atl":[[38,0],[90,18.62]],"id":41419608},{"atl":[[150,0],[370,4.46]],"id":41419635}],"con":true,"img":false}]}
{"op":"mcm","clk":"5348578068","pt":1646219014927,"mc":[{"id":"1.195453744","rc":[{"atl":[[520,4.87],[290,5.5],[900,0]],"id":41419630},{"atl":[[430,0]],"id":41419597},{"atl":[[1000,0]],"id":41419592}],"con":true,"img":false}]}
{"op":"mcm","clk":"5348578100","pt":1646219015186,"mc":[{"id":"1.195453744","rc":[{"atl":[[90,2]],"id":41419608},{"atl":[[340,6.4],[740,0]],"id":41419592}],"con":true,"img":false}]}
{"op":"mcm","clk":"5348578170","pt":1646219015914,"mc":[{"id":"1.195453744","rc":[{"atl":[[510,0]],"id":41419630}],"con":true,"img":false}]}
{"op":"mcm","clk":"5348578233","pt":1646219016489,"mc":[{"id":"1.195453744","rc":[{"atl":[[650,0],[710,2]],"id":41419586}],"con":true,"img":false}]}
{"op":"mcm","clk":"5348578257","pt":1646219016698,"mc":[{"id":"1.195453744","rc":[{"atb":[[18,0],[21,0]],"id":41419607},{"atl":[[290,0],[300,4.95]],"id":41419630},{"atb":[[42,0],[44,13.17],[50,7.34],[55,4.95]],"id":41419597},{"atb":[[16.5,32.09],[14.5,0],[15.5,4.95]],"id":41419608},{"atb":[[24,0],[26,4.95],[28,0]],"id":41419606},{"atb":[[25,2.72]],"id":41419612},{"atl":[[17,14.86]],"id":41419610},{"atl":[[42,0],[46,4.95],[50,0],[60,9.9]],"id":41419625},{"atl":[[140,0],[150,9.9],[100,0],[110,4.95]],"id":41419592},{"atl":[[130,9.9],[90,0],[95,6.63],[120,0]],"id":41419598},{"atl":[[32,4.95],[38,23.14],[40,9.9],[30,0]],"id":41419596},{"atb":[[11.5,0],[13.5,24.39],[14,4.95]],"id":41419594}],"con":true,"img":false}]}
{"op":"mcm","clk":"5348578276","pt":1646219016902,"mc":[{"id":"1.195453744","rc":[{"atb":[[30,8.19]],"id":41419593},{"atl":[[520,2]],"id":41419630}],"con":true,"img":false}]}
{"op":"mcm","clk":"5348578295","pt":1646219017114,"mc":[{"id":"1.195453744","rc":[{"atb":[[12,44.83],[14.5,15.29]],"id":41419607},{"atb":[[17.5,6.06],[15,0]],"id":41419587},{"atb":[[50,0],[55,16.37]],"id":41419597},{"atl":[[46,8.47]],"id":41419625},{"atb":[[13.5,12.17],[14,17.17]],"id":41419594}],"con":true,"img":false}]}
{"op":"mcm","clk":"5348578329","pt":1646219017424,"mc":[{"id":"1.195453744","rc":[{"atb":[[17.5,3.27],[20,2.72]],"id":41419607},{"atl":[[65,21.15],[75,9.9],[48,0],[55,4.95]],"id":41419603},{"atl":[[20,0],[21,4.95],[24,27.46],[25,9.9]],"id":41419622},{"atl":[[130,1.23],[150,4.95]],"id":41419599},{"atl":[[300,0],[290,4.95],[510,0.31]],"id":41419630},{"atl":[[34,9.9],[36,0],[28,4.95],[29,5.66]],"id":41419626},{"atb":[[17,4.95],[15.5,0]],"id":41419608},{"atl":[[34,0],[38,9.9],[28,0],[30,4.95]],"id":41419608},{"atb":[[24,9.9],[26,0],[28,4.95],[30,8.19]],"id":41419606},{"atb":[[19,9.9],[20,24.49],[22,4.95],[24,6.89]],"id":41419612},{"atl":[[17,4.95],[18.5,0]],"id":41419610},{"atl":[[330,0.47]],"id":41419592},{"atl":[[210,0.75],[240,4.95]],"id":41419586},{"atl":[[32,0],[36,9.9],[40,0],[29,10.61]],"id":41419596}],"con":true,"img":false}]}
{"op":"mcm","clk":"5348578347","pt":1646219017579,"mc":[{"id":"1.195453744","rc":[{"atl":[[780,0],[490,2]],"id":41419599}],"con":true,"img":false}]}
{"op":"mcm","clk":"5348578364","pt":1646219017786,"mc":[{"id":"1.195453744","rc":[{"atl":[[120,11.22]],"id":41419625}],"con":true,"img":false}]}
{"op":"mcm","clk":"5348578374","pt":1646219017894,"mc":[{"id":"1.195453744","rc":[{"atl":[[780,1.92],[810,0]],"id":41419599},{"atl":[[34,33.04],[80,2],[28,10.82]],"id":41419626},{"atb":[[16.5,10.22],[17,17.17]],"id":41419608},{"atb":[[20,3.27],[22,19.66]],"id":41419612},{"atl":[[19,9.9],[46,16.93]],"id":41419610}],"con":true,"img":false}]}
{"op":"mcm","clk":"5348578386","pt":1646219017996,"mc":[{"id":"1.195453744","rc":[{"atl":[[710,4.11]],"id":41419586}],"con":true,"img":false}]}
{"op":"mcm","clk":"5348578404","pt":1646219018203,"mc":[{"id":"1.195453744","rc":[{"atl":[[85,1.88]],"id":41419608},{"atl":[[19,18.71]],"id":41419610}],"con":true,"img":false}]}
{"op":"mcm","clk":"5348578440","pt":1646219018723,"mc":[{"id":"1.195453744","rc":[{"atl":[[29,0]],"id":41419626},{"atl":[[55,7.89]],"id":41419606}],"con":true,"img":false}]}
{"op":"mcm","clk":"5348578448","pt":1646219018772,"mc":[{"id":"1.195453744","rc":[{"atl":[[75,2],[60,22.12]],"id":41419594}],"con":true,"img":false}]}
{"op":"mcm","clk":"5348578459","pt":1646219018931,"mc":[{"id":"1.195453744","rc":[{"atl":[[32,5.11]],"id":41419607},{"atl":[[120,6.28]],"id":41419611},{"atl":[[60,7.64]],"id":41419593},{"atl":[[100,6.55]],"id":41419587},{"atl":[[280,0.56]],"id":41419630},{"atl":[[80,6.95]],"id":41419637},{"atl":[[46,8.47]],"id":41419612}],"con":true,"img":false}]}
{"op":"mcm","clk":"5348578466","pt":1646219018982,"mc":[{"id":"1.195453744","rc":[{"atl":[[44,3.68]],"id":41419594}],"con":true,"img":false}]}
{"op":"mcm","clk":"5348578484","pt":1646219019192,"mc":[{"id":"1.195453744","rc":[{"atl":[[280,5.52]],"id":41419630}],"con":true,"img":false}]}
{"op":"mcm","clk":"5348578495","pt":1646219019293,"mc":[{"id":"1.195453744","rc":[{"atl":[[290,0]],"id":41419630},{"atl":[[240,0.66]],"id":41419598}],"con":true,"img":false}]}
{"op":"mcm","clk":"5348578521","pt":1646219019504,"mc":[{"id":"1.195453744","rc":[{"atl":[[38,18],[42,9.9]],"id":41419607},{"atl":[[70,0]],"id":41419606},{"atl":[[100,1.6]],"id":41419592}],"con":true,"img":false}]}
{"op":"mcm","clk":"5348578534","pt":1646219019606,"mc":[{"id":"1.195453744","rc":[{"atl":[[38,13.71]],"id":41419607},{"atl":[[130,0]],"id":41419611},{"atl":[[75,0]],"id":41419593},{"atl":[[130,0]],"id":41419587},{"atl":[[510,0]],"id":41419630},{"atl":[[95,0]],"id":41419637},{"atl":[[50,0]],"id":41419612}],"con":true,"img":false}]}
{"op":"mcm","clk":"5348578544","pt":1646219019709,"mc":[{"id":"1.195453744","rc":[{"atl":[[240,6.95],[250,0]],"id":41419598},{"atl":[[50,0]],"id":41419594}],"con":true,"img":false}]}
{"op":"mcm","clk":"5348578573","pt":1646219020021,"mc":[{"id":"1.195453744","rc":[{"atl":[[170,10.89]],"id":41419593},{"atl":[[340,6.44]],"id":41419587},{"atl":[[75,9.9],[190,9.95]],"id":41419606},{"atl":[[200,9.55]],"id":41419637},{"atl":[[150,12.08],[60,9.9]],"id":41419612},{"atl":[[240,6.29]],"id":41419598}],"con":true,"img":false}]}
{"op":"mcm","clk":"5348578580","pt":1646219020124,"mc":[{"id":"1.195453744","rc":[{"atl":[[270,7.59],[140,0]],"id":41419611},{"atl":[[80,9.9]],"id":41419593},{"atl":[[140,9.9]],"id":41419587},{"atl":[[100,9.9]],"id":41419637}],"con":true,"img":false}]}
{"op":"mcm","clk":"5348578602","pt":1646219020285,"mc":[{"id":"1.195453744","rc":[{"atl":[[330,0]],"id":41419592}],"con":true,"img":false}]}
{"op":"mcm","clk":"5348578630","pt":1646219020490,"mc":[{"id":"1.195453744","rc":[{"atl":[[34,0],[36,9.9],[42,0],[29,4.95]],"id":41419607},{"atb":[[70,4.95],[46,0],[50,9.9],[60,2.68]],"id":41419599}],"con":true,"img":false}]}
{"op":"mcm","clk":"5348578693","pt":1646219021016,"mc":[{"id":"1.195453744","rc":[{"atb":[[75,2.14],[38,2.72],[50,21.26]],"id":41419599}],"con":true,"img":false}]}
{"op":"mcm","clk":"5348578703","pt":1646219021120,"mc":[{"id":"1.195453744","rc":[{"atb":[[34,9.9],[40,19.65]],"id":41419587},{"atl":[[370,0.43],[380,5.97]],"id":41419635}],"con":true,"img":false}]}
{"op":"mcm","clk":"5348578725","pt":1646219021330,"mc":[{"id":"1.195453744","rc":[{"atl":[[85,14.1]],"id":41419608},{"atl":[[210,7.21],[930,2]],"id":41419604},{"atb":[[5.6,57.47]],"id":41419623}],"con":true,"img":false}]}
{"op":"mcm","clk":"5348578736","pt":1646219021383,"mc":[{"id":"1.195453744","rc":[{"atb":[[4.4,39.17]],"id":41419623}],"con":true,"img":false}]}
{"op":"mcm","clk":"5348578749","pt":1646219021486,"mc":[{"id":"1.195453744","rc":[{"atl":[[590,2],[930,0]],"id":41419604}],"con":true,"img":false}]}
{"op":"mcm","clk":"5348578760","pt":1646219021592,"mc":[{"id":"1.195453744","rc":[{"atb":[[10,22.56]],"id":41419622},{"atl":[[40,9.02]],"id":41419601},{"atl":[[130,6.18]],"id":41419635},{"atl":[[710,2.11],[790,2]],"id":41419586}],"con":true,"img":false}]}
{"op":"mcm","clk":"5348578769","pt":1646219021695,"mc":[{"id":"1.195453744","rc":[{"atb":[[60,0]],"id":41419599}],"con":true,"img":false}]}
{"op":"mcm","clk":"5348578800","pt":1646219022004,"mc":[{"id":"1.195453744","rc":[{"atl":[[150,20.02],[340,2]],"id":41419592}],"con":true,"img":false}]}
{"op":"mcm","clk":"5348578848","pt":1646219022423,"mc":[{"id":"1.195453744","rc":[{"atb":[[9.8,2.72]],"id":41419622}],"con":true,"img":false}]}
{"op":"mcm","clk":"5348578863","pt":1646219022633,"mc":[{"id":"1.195453744","rc":[{"atl":[[46,0]],"id":41419601}],"con":true,"img":false}]}
{"op":"mcm","clk":"5348578873","pt":1646219022687,"mc":[{"id":"1.195453744","rc":[{"atl":[[370,0]],"id":41419635},{"atb":[[17,0],[19.5,0]],"id":41419594}],"con":true,"img":false}]}
{"op":"mcm","clk":"5348578922","pt":1646219023103,"mc":[{"id":"1.195453744","rc":[{"atl":[[48,9.9],[100,17.21]],"id":41419601}],"con":true,"img":false}]}
{"op":"mcm","clk":"5348578929","pt":1646219023209,"mc":[{"id":"1.195453744","rc":[{"atb":[[14,29.37]],"id":41419594}],"con":true,"img":false}]}
{"op":"mcm","clk":"5348578950","pt":1646219023425,"mc":[{"id":"1.195453744","rc":[{"atb":[[17.5,3.27],[20,2.72]],"id":41419594}],"con":true,"img":false}]}
{"op":"mcm","clk":"5348579002","pt":1646219023935,"mc":[{"id":"1.195453744","rc":[{"atb":[[12.5,46.89],[14,17.15]],"id":41419594}],"con":true,"img":false}]}
{"op":"mcm","clk":"5348579023","pt":1646219024093,"mc":[{"id":"1.195453744","rc":[{"atb":[[13.5,0]],"id":41419594}],"con":true,"img":false}]}
{"op":"mcm","clk":"5348579062","pt":1646219024510,"mc":[{"id":"1.195453744","rc":[{"atl":[[65,4.95],[85,9.9],[60,4.95]],"id":41419593},{"atl":[[100,0]],"id":41419592}],"con":true,"img":false}]}
{"op":"mcm","clk":"5348579072","pt":1646219024612,"mc":[{"id":"1.195453744","rc":[{"atl":[[80,0],[60,0]],"id":41419593}],"con":true,"img":false}]}
{"op":"mcm","clk":"5348579095","pt":1646219024819,"mc":[{"id":"1.195453744","rc":[{"atl":[[34,9.9],[80,21.07]],"id":41419626},{"atb":[[12.5,11.58]],"id":41419594}],"con":true,"img":false}]}
{"op":"mcm","clk":"5348579107","pt":1646219024923,"mc":[{"id":"1.195453744","rc":[{"atb":[[34,0],[27,0]],"id":41419605},{"atb":[[20,0],[25,0]],"id":41419639},{"atb":[[34,4.8],[27,27.81]],"id":41419637},{"atb":[[10,12.21],[12.5,0]],"id":41419610}],"con":true,"img":false}]}
{"op":"mcm","clk":"5348579140","pt":1646219025287,"mc":[{"id":"1.195453744","rc":[{"atl":[[65,7.43]],"id":41419593},{"atl":[[28,4.95]],"id":41419626},{"atb":[[11,20.8]],"id":41419610},{"atl":[[110,6.4]],"id":41419592}],"con":true,"img":false}]}
{"op":"mcm","clk":"5348579148","pt":1646219025389,"mc":[{"id":"1.195453744","rc":[{"atb":[[9.6,42.8],[10,0]],"id":41419610}],"con":true,"img":false}]}
{"op":"mcm","clk":"5348579166","pt":1646219025599,"mc":[{"id":"1.195453744","rc":[{"atb":[[36,2.72],[28,3.27]],"id":41419605},{"atb":[[21,3.27],[26,2.72]],"id":41419639},{"atb":[[36,2.72],[28,3.27]],"id":41419637},{"atb":[[12,2.72],[9.8,3.27]],"id":41419610}],"con":true,"img":false}]}
{"op":"mcm","clk":"5348579218","pt":1646219026114,"mc":[{"id":"1.195453744","rc":[{"atl":[[32,5.11]],"id":41419626},{"atb":[[32,22.65]],"id":41419637}],"con":true,"img":false}]}
{"op":"mcm","clk":"5348579229","pt":1646219026221,"mc":[{"id":"1.195453744","rc":[{"atb":[[27,9.9]],"id":41419637}],"con":true,"img":false}]}
{"op":"mcm","clk":"5348579411","pt":1646219028086,"mc":[{"id":"1.195453744","rc":[{"atl":[[590,4.59],[210,0]],"id":41419604},{"atl":[[150,10.23],[380,2]],"id":41419635}],"con":true,"img":false}]}
{"op":"mcm","clk":"5348579481","pt":1646219028812,"mc":[{"id":"1.195453744","rc":[{"atl":[[150,9.9],[340,6.51]],"id":41419592}],"con":true,"img":false}]}
{"op":"mcm","clk":"5348579502","pt":1646219029122,"mc":[{"id":"1.195453744","rc":[{"atl":[[590,2]],"id":41419604}],"con":true,"img":false}]}
{"op":"mcm","clk":"5348579681","pt":1646219030796,"mc":[{"id":"1.195453744","rc":[{"atl":[[36,0],[38,23.62],[29,0],[30,4.95]],"id":41419607},{"atl":[[300,5.13]],"id":41419630}],"con":true,"img":false}]}
{"op":"mcm","clk":"5348579720","pt":1646219031213,"mc":[{"id":"1.195453744","rc":[{"atb":[[12,12.11],[14.5,30.25]],"id":41419607},{"atb":[[14,29.99]],"id":41419594}],"con":true,"img":false}]}
{"op":"mcm","clk":"5348579789","pt":1646219031792,"mc":[{"id":"1.195453744","rc":[{"atl":[[780,0],[490,5.14]],"id":41419599},{"atl":[[34,32.23],[80,2],[28,10.82]],"id":41419626}],"con":true,"img":false}]}
{"op":"mcm","clk":"5348579820","pt":1646219032107,"mc":[{"id":"1.195453744","rc":[{"atl":[[210,4.95],[220,0.72]],"id":41419634},{"atb":[[16.5,4.95],[17.5,11.64],[14.5,9.9],[15.5,0]],"id":41419596}],"con":true,"img":false}]}
{"op":"mcm","clk":"5348579832","pt":1646219032217,"mc":[{"id":"1.195453744","rc":[{"atl":[[730,2]],"id":41419634}],"con":true,"img":false}]}
{"op":"mcm","clk":"5348579843","pt":1646219032321,"mc":[{"id":"1.195453744","rc":[{"atl":[[990,0]],"id":41419634}],"con":true,"img":false}]}
{"op":"mcm","clk":"5348579867","pt":1646219032520,"mc":[{"id":"1.195453744","rc":[{"atl":[[200,1.18],[990,1.55],[1000,0]],"id":41419634},{"atl":[[32,0],[28,4.95]],"id":41419626}],"con":true,"img":false}]}
{"op":"mcm","clk":"5348579898","pt":1646219032838,"mc":[{"id":"1.195453744","rc":[{"atl":[[30,10.42]],"id":41419607}],"con":true,"img":false}]}
{"op":"mcm","clk":"5348579955","pt":1646219033313,"mc":[{"id":"1.195453744","rc":[{"atl":[[220,0],[990,0]],"id":41419634},{"atl":[[32,5.11]],"id":41419626}],"con":true,"img":false}]}
{"op":"mcm","clk":"5348579988","pt":1646219033625,"mc":[{"id":"1.195453744","rc":[{"atl":[[32,0]],"id":41419607}],"con":true,"img":false}]}
{"op":"mcm","clk":"5348580035","pt":1646219033991,"mc":[{"id":"1.195453744","rc":[{"atl":[[270,2],[140,11.08]],"id":41419611}],"con":true,"img":false}]}
{"op":"mcm","clk":"5348580045","pt":1646219034097,"mc":[{"id":"1.195453744","rc":[{"atl":[[38,9.9],[85,20.26]],"id":41419607}],"con":true,"img":false}]}
{"op":"mcm","clk":"5348580104","pt":1646219034723,"mc":[{"id":"1.195453744","rc":[{"atl":[[140,0]],"id":41419611},{"atl":[[150,0],[380,6.08]],"id":41419635}],"con":true,"img":false}]}
{"op":"mcm","clk":"5348580141","pt":1646219035038,"mc":[{"id":"1.195453744","rc":[{"atl":[[210,7.4]],"id":41419604}],"con":true,"img":false}]}
{"op":"mcm","clk":"5348580339","pt":1646219036922,"mc":[{"id":"1.195453744","rc":[{"atl":[[1000,3.38]],"id":41419591},{"atl":[[730,2],[790,0]],"id":41419586}],"con":true,"img":false}]}
{"op":"mcm","clk":"5348580375","pt":1646219037240,"mc":[{"id":"1.195453744","rc":[{"atl":[[270,5.54],[280,0]],"id":41419591},{"atb":[[34,9.9],[40,0],[42,4.95],[48,0]],"id":41419589},{"atb":[[75,0]],"id":41419599},{"atl":[[280,0],[290,4.95]],"id":41419630},{"atb":[[65,16.2],[75,4.95],[85,0],[90,0],[55,9.9]],"id":41419585},{"atl":[[150,4.95],[160,0.99]],"id":41419585},{"atb":[[19,0],[22,14.71],[23,4.95],[25,9.33]],"id":41419612},{"atl":[[17,0],[17.5,4.95],[19,8.8],[19.5,9.9]],"id":41419610},{"atl":[[230,4.95],[240,0]],"id":41419586}],"con":true,"img":false}]}
{"op":"mcm","clk":"5348580393","pt":1646219037449,"mc":[{"id":"1.195453744","rc":[{"atl":[[790,0],[500,2]],"id":41419585}],"con":true,"img":false}]}
{"op":"mcm","clk":"5348580400","pt":1646219037499,"mc":[{"id":"1.195453744","rc":[{"atl":[[520,4.99],[300,0]],"id":41419630}],"con":true,"img":false}]}
{"op":"mcm","clk":"5348580409","pt":1646219037606,"mc":[{"id":"1.195453744","rc":[{"atl":[[290,5.37],[1000,2]],"id":41419591},{"atb":[[38,17.44],[50,9.9]],"id":41419599},{"atb":[[65,0]],"id":41419585},{"atl":[[820,0]],"id":41419585},{"atl":[[19.5,30.36],[46,2.22]],"id":41419610}],"con":true,"img":false}]}
{"op":"mcm","clk":"5348580420","pt":1646219037708,"mc":[{"id":"1.195453744","rc":[{"atb":[[55,24.62]],"id":41419585},{"atl":[[790,1.96]],"id":41419585}],"con":true,"img":false}]}
{"op":"mcm","clk":"5348580432","pt":1646219037826,"mc":[{"id":"1.195453744","rc":[{"atb":[[22,0],[23,31.42]],"id":41419612}],"con":true,"img":false}]}
{"op":"mcm","clk":"5348580447","pt":1646219037987,"mc":[{"id":"1.195453744","rc":[{"atb":[[36,4.52]],"id":41419589},{"atb":[[70,7.25]],"id":41419599},{"atl":[[290,5.5]],"id":41419630},{"atb":[[24,0]],"id":41419612},{"atl":[[19.5,38.93]],"id":41419610}],"con":true,"img":false}]}
{"op":"mcm","clk":"5348580456","pt":1646219038021,"mc":[{"id":"1.195453744","rc":[{"atb":[[60,2.68]],"id":41419585}],"con":true,"img":false}]}
{"op":"mcm","clk":"5348580467","pt":1646219038125,"mc":[{"id":"1.195453744","rc":[{"atl":[[150,6.01]],"id":41419585}],"con":true,"img":false}]}
{"op":"mcm","clk":"5348580476","pt":1646219038230,"mc":[{"id":"1.195453744","rc":[{"atl":[[36,9.9],[38,0],[29,4.95],[30,5.46]],"id":41419607},{"atb":[[18.5,0],[20,9.9],[21,7.93],[24,4.95]],"id":41419603},{"atl":[[130,9.9],[95,4.95],[120,1.32]],"id":41419611},{"atb":[[10,17.61],[9.2,0],[11.5,4.95],[9.8,12.63]],"id":41419622},{"atl":[[130,9.9],[140,0],[95,4.95],[100,1.6]],"id":41419587},{"atb":[[16.5,0],[21,8.22]],"id":41419601},{"atl":[[130,1.23],[120,4.95]],"id":41419635},{"atl":[[44,4.95],[46,3.52],[55,9.9],[60,0]],"id":41419612},{"atb":[[70,0],[75,9.9],[90,1.78],[95,4.95]],"id":41419586}],"con":true,"img":false}]}
{"op":"mcm","clk":"5348580484","pt":1646219038335,"mc":[{"id":"1.195453744","rc":[{"atl":[[9.6,9.9],[10.5,0],[8.8,4.95],[9.4,18.87]],"id":41419623},{"atl":[[42,4.95],[46,0],[50,9.9],[60,12.21]],"id":41419594}],"con":true,"img":false}]}
{"op":"mcm","clk":"5348580493","pt":1646219038442,"mc":[{"id":"1.195453744","rc":[{"atb":[[32,0],[34,14.71],[42,0]],"id":41419589}],"con":true,"img":false}]}
{"op":"mcm","clk":"5348580503","pt":1646219038492,"mc":[{"id":"1.195453744","rc":[{"atb":[[36,14.43],[44,4.95]],"id":41419589}],"con":true,"img":false}]}
{"op":"mcm","clk":"5348580522","pt":1646219038597,"mc":[{"id":"1.195453744","rc":[{"atb":[[18,0],[20,29.05],[24,11.84]],"id":41419603},{"atl":[[95,6.63]],"id":41419611},{"atb":[[9.6,0],[12,14.41],[9.8,44.14]],"id":41419622},{"atl":[[130,21.94],[340,2],[90,1.78]],"id":41419587},{"atl":[[120,6.28]],"id":41419635},{"atb":[[23,4.95]],"id":41419612},{"atl":[[150,2],[44,8.64],[55,31.13]],"id":41419612},{"atb":[[75,20.4],[100,1.6]],"id":41419586}],"con":true,"img":false}]}
{"op":"mcm","clk":"5348580541","pt":1646219038808,"mc":[{"id":"1.195453744","rc":[{"atl":[[160,0]],"id":41419585},{"atl":[[19.5,30.36]],"id":41419610},{"atl":[[9.6,52.68],[8.6,20.86],[11,0]],"id":41419623},{"atl":[[42,8.82],[50,22.74],[60,0]],"id":41419594}],"con":true,"img":false}]}
{"op":"mcm","clk":"5348580550","pt":1646219038913,"mc":[{"id":"1.195453744","rc":[{"atb":[[46,2.22]],"id":41419586}],"con":true,"img":false}]}
{"op":"mcm","clk":"5348580574","pt":1646219039124,"mc":[{"id":"1.195453744","rc":[{"atb":[[9.6,9.9],[9.8,23.72]],"id":41419610}],"con":true,"img":false}]}
{"op":"mcm","clk":"5348580594","pt":1646219039329,"mc":[{"id":"1.195453744","rc":[{"atb":[[21,0]],"id":41419603},{"atl":[[120,0]],"id":41419611},{"atb":[[10,0]],"id":41419622},{"atl":[[130,9.9],[100,0]],"id":41419587},{"atl":[[130,0]],"id":41419635},{"atl":[[46,0]],"id":41419612},{"atb":[[90,0]],"id":41419586}],"con":true,"img":false}]}
{"op":"mcm","clk":"5348580614","pt":1646219039537,"mc":[{"id":"1.195453744","rc":[{"atl":[[44,0]],"id":41419594}],"con":true,"img":false}]}
{"op":"mcm","clk":"5348580626","pt":1646219039643,"mc":[{"id":"1.195453744","rc":[{"atl":[[9.4,0]],"id":41419623}],"con":true,"img":false}]}
{"op":"mcm","clk":"5348580634","pt":1646219039695,"mc":[{"id":"1.195453744","rc":[{"atl":[[28,10.82]],"id":41419626}],"con":true,"img":false}]}
{"op":"mcm","clk":"5348580695","pt":1646219040322,"mc":[{"id":"1.195453744","rc":[{"atl":[[32,4.95],[36,0],[40,9.9],[29,0],[30,0]],"id":41419607},{"atb":[[19.5,9.9],[20,19.14],[23,4.95],[24,0]],"id":41419603},{"atl":[[130,0],[140,9.9],[95,0],[100,4.95]],"id":41419611},{"atb":[[12,0]],"id":41419622},{"atb":[[34,24.62],[36,4.52],[42,4.95],[44,0]],"id":41419589},{"atl":[[44,0],[46,4.95],[55,21.22],[60,9.9]],"id":41419612},{"atb":[[100,0]],"id":41419586},{"atl":[[42,0],[44,4.95],[50,12.84],[55,9.9]],"id":41419594}],"con":true,"img":false}]}
{"op":"mcm","clk":"5348580715","pt":1646219040530,"mc":[{"id":"1.195453744","rc":[{"atl":[[29,5.66]],"id":41419607},{"atl":[[32,0],[28,4.95]],"id":41419626}],"con":true,"img":false}]}
{"op":"mcm","clk":"5348580770","pt":1646219040996,"mc":[{"id":"1.195453744","rc":[{"atl":[[80,21.65]],"id":41419626}],"con":true,"img":false}]}
{"op":"mcm","clk":"5348580779","pt":1646219041006,"mc":[{"id":"1.195453744","rc":[{"atb":[[19.5,0],[21,7.93],[23,0]],"id":41419603},{"atl":[[140,0],[95,1.68],[100,0]],"id":41419611},{"atl":[[34,9.9]],"id":41419626},{"atl":[[50,3.23]],"id":41419612},{"atb":[[95,6.63]],"id":41419586},{"atl":[[48,3.37]],"id":41419594}],"con":true,"img":false}]}
{"op":"mcm","clk":"5348580792","pt":1646219041181,"mc":[{"id":"1.195453744","rc":[{"atb":[[9.8,62.16]],"id":41419622},{"atl":[[44,0],[55,0]],"id":41419594}],"con":true,"img":false}]}
{"op":"mcm","clk":"5348580800","pt":1646219041214,"mc":[{"id":"1.195453744","rc":[{"atl":[[32,5.11]],"id":41419626}],"con":true,"img":false}]}
{"op":"mcm","clk":"5348580829","pt":1646219041425,"mc":[{"id":"1.195453744","rc":[{"atb":[[18.5,0],[22,0]],"id":41419608}],"con":true,"img":false}]}
{"op":"mcm","clk":"5348580857","pt":1646219041631,"mc":[{"id":"1.195453744","rc":[{"atl":[[590,4.65],[210,0]],"id":41419604}],"con":true,"img":false}]}
{"op":"mcm","clk":"5348580867","pt":1646219041738,"mc":[{"id":"1.195453744","rc":[{"atb":[[19.5,9.9],[23,4.95]],"id":41419603},{"atl":[[130,9.9],[95,6.63]],"id":41419611},{"atl":[[80,2]],"id":41419626},{"atl":[[140,11.23],[380,2]],"id":41419635}],"con":true,"img":false}]}
{"op":"mcm","clk":"5348580880","pt":1646219041840,"mc":[{"id":"1.195453744","rc":[{"atb":[[17,14.86],[12.5,43.99]],"id":41419608},{"atl":[[42,4.95],[50,22.74]],"id":41419594}],"con":true,"img":false}]}
{"op":"mcm","clk":"5348580912","pt":1646219042101,"mc":[{"id":"1.195453744","rc":[{"atb":[[19,3.27],[23,2.72]],"id":41419608}],"con":true,"img":false}]}
{"op":"mcm","clk":"5348580921","pt":1646219042204,"mc":[{"id":"1.195453744","rc":[{"atb":[[25,2.72]],"id":41419612},{"atl":[[17.5,0],[17,4.95],[19,18.71],[19.5,20.45]],"id":41419610}],"con":true,"img":false}]}
{"op":"mcm","clk":"5348580928","pt":1646219042311,"mc":[{"id":"1.195453744","rc":[{"atl":[[30,10.42]],"id":41419608},{"atl":[[590,2]],"id":41419604}],"con":true,"img":false}]}
{"op":"mcm","clk":"5348580958","pt":1646219042622,"mc":[{"id":"1.195453744","rc":[{"atb":[[16.5,0]],"id":41419608}],"con":true,"img":false}]}
{"op":"mcm","clk":"5348580969","pt":1646219042728,"mc":[{"id":"1.195453744","rc":[{"atl":[[29,0]],"id":41419607},{"atl":[[130,0],[140,9.9],[95,0],[100,4.95]],"id":41419611}],"con":true,"img":false}]}
{"op":"mcm","clk":"5348580983","pt":1646219042834,"mc":[{"id":"1.195453744","rc":[{"atl":[[280,4.95],[290,0.55]],"id":41419630}],"con":true,"img":false}]}
{"op":"mcm","clk":"5348580994","pt":1646219042934,"mc":[{"id":"1.195453744","rc":[{"atl":[[42,4.95],[46,3.52],[50,9.9],[60,0]],"id":41419625}],"con":true,"img":false}]}
{"op":"mcm","clk":"5348581006","pt":1646219043039,"mc":[{"id":"1.195453744","rc":[{"atl":[[85,12.21],[30,4.95]],"id":41419608},{"atb":[[23,12.15]],"id":41419612}],"con":true,"img":false}]}
{"op":"mcm","clk":"5348581051","pt":1646219043409,"mc":[{"id":"1.195453744","rc":[{"atl":[[50,24.62],[120,0]],"id":41419625}],"con":true,"img":false}]}
{"op":"mcm","clk":"5348581062","pt":1646219043510,"mc":[{"id":"1.195453744","rc":[{"atl":[[38,4.28]],"id":41419607},{"atl":[[260,0.61]],"id":41419611}],"con":true,"img":false}]}
{"op":"mcm","clk":"5348581079","pt":1646219043717,"mc":[{"id":"1.195453744","rc":[{"atl":[[36,4.52]],"id":41419608},{"atl":[[44,4.95],[55,9.9]],"id":41419594}],"con":true,"img":false}]}
{"op":"mcm","clk":"5348581088","pt":1646219043821,"mc":[{"id":"1.195453744","rc":[{"atl":[[42,0],[50,12.84]],"id":41419594}],"con":true,"img":false}]}
{"op":"mcm","clk":"5348581127","pt":1646219044239,"mc":[{"id":"1.195453744","rc":[{"atl":[[290,0],[1000,3.56]],"id":41419591},{"atl":[[38,23.99],[85,0]],"id":41419608}],"con":true,"img":false}]}
{"op":"mcm","clk":"5348581206","pt":1646219045018,"mc":[{"id":"1.195453744","rc":[{"atl":[[280,0],[290,5.5]],"id":41419630}],"con":true,"img":false}]}
{"op":"mcm","clk":"5348581224","pt":1646219045227,"mc":[{"id":"1.195453744","rc":[{"atb":[[9.8,30.65],[8.8,23.36]],"id":41419622},{"atb":[[75,9.9],[46,12.87]],"id":41419586}],"con":true,"img":false}]}
{"op":"mcm","clk":"5348581236","pt":1646219045333,"mc":[{"id":"1.195453744","rc":[{"atl":[[34,32.23],[28,10.82]],"id":41419626}],"con":true,"img":false}]}
{"op":"mcm","clk":"5348581244","pt":1646219045437,"mc":[{"id":"1.195453744","rc":[{"atl":[[310,5.1]],"id":41419630}],"con":true,"img":false}]}
{"op":"mcm","clk":"5348581250","pt":1646219045539,"mc":[{"id":"1.195453744","rc":[{"atl":[[520,2]],"id":41419630}],"con":true,"img":false}]}
{"op":"mcm","clk":"5348581297","pt":1646219046007,"mc":[{"id":"1.195453744","rc":[{"atl":[[730,4.16]],"id":41419634},{"atl":[[32,0],[28,4.95]],"id":41419626}],"con":true,"img":false}]}
{"op":"mcm","clk":"5348581328","pt":1646219046319,"mc":[{"id":"1.195453744","rc":[{"atl":[[30,5.46]],"id":41419607},{"atl":[[310,0]],"id":41419630}],"con":true,"img":false}]}
{"op":"mcm","clk":"5348581365","pt":1646219046630,"mc":[{"id":"1.195453744","rc":[{"atl":[[38,4.95],[40,4.06],[46,9.9],[48,0]],"id":41419601}],"con":true,"img":false}]}
{"op":"mcm","clk":"5348581374","pt":1646219046737,"mc":[{"id":"1.195453744","rc":[{"atl":[[32,5.11]],"id":41419626},{"atl":[[75,4.95],[80,2],[95,9.9],[100,0]],"id":41419637}],"con":true,"img":false}]}
{"op":"mcm","clk":"5348581407","pt":1646219047044,"mc":[{"id":"1.195453744","rc":[{"atl":[[38,0]],"id":41419607}],"con":true,"img":false}]}
{"op":"mcm","clk":"5348581417","pt":1646219047147,"mc":[{"id":"1.195453744","rc":[{"atl":[[100,2]],"id":41419601}],"con":true,"img":false}]}
{"op":"mcm","clk":"5348581426","pt":1646219047211,"mc":[{"id":"1.195453744","rc":[{"atl":[[46,29.48]],"id":41419601},{"atl":[[75,7.09],[95,24.41],[200,2]],"id":41419637}],"con":true,"img":false}]}
{"op":"mcm","clk":"5348581443","pt":1646219047412,"mc":[{"id":"1.195453744","rc":[{"atl":[[260,6.72]],"id":41419611}],"con":true,"img":false}]}
{"op":"mcm","clk":"5348581454","pt":1646219047517,"mc":[{"id":"1.195453744","rc":[{"atl":[[40,25.39],[85,2]],"id":41419607}],"con":true,"img":false}]}
{"op":"mcm","clk":"5348581532","pt":1646219048239,"mc":[{"id":"1.195453744","rc":[{"atl":[[80,0]],"id":41419637}],"con":true,"img":false}]}
{"op":"mcm","clk":"5348581550","pt":1646219048443,"mc":[{"id":"1.195453744","rc":[{"atl":[[210,7.58]],"id":41419604},{"atl":[[140,0],[380,6.18]],"id":41419635}],"con":true,"img":false}]}
{"op":"mcm","clk":"5348581662","pt":1646219049649,"mc":[{"id":"1.195453744","rc":[{"atl":[[38,0],[40,9.02],[46,19.57],[48,9.9]],"id":41419601},{"atl":[[75,0],[80,4.95],[95,14.5],[100,9.9]],"id":41419637},{"atl":[[8.6,0]],"id":41419623}],"con":true,"img":false}]}
{"op":"mcm","clk":"5348581675","pt":1646219049752,"mc":[{"id":"1.195453744","rc":[{"atl":[[32,0],[34,4.95],[40,15.48],[42,9.9],[30,0]],"id":41419607},{"atb":[[19.5,0],[22,4.95],[23,0]],"id":41419603}],"con":true,"img":false}]}
{"op":"mcm","clk":"5348581701","pt":1646219050119,"mc":[{"id":"1.195453744","rc":[{"atl":[[9.6,9.9],[16,75.93]],"id":41419623}],"con":true,"img":false}]}
{"op":"mcm","clk":"5348581726","pt":1646219050433,"mc":[{"id":"1.195453744","rc":[{"atl":[[40,19.55]],"id":41419607},{"atl":[[44,3.68]],"id":41419601},{"atl":[[95,16.19]],"id":41419637},{"atl":[[9.6,28.34]],"id":41419623}],"con":true,"img":false}]}
{"op":"mcm","clk":"5348581735","pt":1646219050538,"mc":[{"id":"1.195453744","rc":[{"atl":[[46,0],[48,4.95],[60,0]],"id":41419612}],"con":true,"img":false}]}
{"op":"mcm","clk":"5348581742","pt":1646219050639,"mc":[{"id":"1.195453744","rc":[{"atb":[[25,9.33]],"id":41419612}],"con":true,"img":false}]}
{"op":"mcm","clk":"5348581761","pt":1646219050950,"mc":[{"id":"1.195453744","rc":[{"atl":[[310,5.15]],"id":41419630}],"con":true,"img":false}]}
{"op":"mcm","clk":"5348581772","pt":1646219051055,"mc":[{"id":"1.195453744","rc":[{"atl":[[290,5.51],[1000,2]],"id":41419591}],"con":true,"img":false}]}
{"op":"mcm","clk":"5348581792","pt":1646219051216,"mc":[{"id":"1.195453744","rc":[{"atl":[[44,0]],"id":41419601},{"atb":[[20,24.49]],"id":41419612}],"con":true,"img":false}]}
{"op":"mcm","clk":"5348581807","pt":1646219051421,"mc":[{"id":"1.195453744","rc":[{"atb":[[75,7.09]],"id":41419585},{"atb":[[23,4.95]],"id":41419612}],"con":true,"img":false}]}
{"op":"mcm","clk":"5348581823","pt":1646219051626,"mc":[{"id":"1.195453744","rc":[{"atl":[[790,3.96]],"id":41419585}],"con":true,"img":false}]}
{"op":"mcm","clk":"5348581829","pt":1646219051730,"mc":[{"id":"1.195453744","rc":[{"atl":[[500,0]],"id":41419585}],"con":true,"img":false}]}
{"op":"mcm","clk":"5348581838","pt":1646219051836,"mc":[{"id":"1.195453744","rc":[{"atl":[[290,0]],"id":41419591}],"con":true,"img":false}]}
{"op":"mcm","clk":"5348581848","pt":1646219051941,"mc":[{"id":"1.195453744","rc":[{"atl":[[95,1.68]],"id":41419611},{"atb":[[11.5,20.05]],"id":41419622},{"atl":[[130,22.23]],"id":41419587},{"atl":[[520,5.07],[310,0]],"id":41419630},{"atl":[[48,8.32]],"id":41419612}],"con":true,"img":false}]}
{"op":"mcm","clk":"5348581855","pt":1646219052046,"mc":[{"id":"1.195453744","rc":[{"atb":[[22,12.5]],"id":41419603}],"con":true,"img":false}]}
{"op":"mcm","clk":"5348581876","pt":1646219052255,"mc":[{"id":"1.195453744","rc":[{"atb":[[60,0]],"id":41419585},{"atl":[[170,9.42],[790,2]],"id":41419585},{"atl":[[8.8,25.28]],"id":41419623},{"atl":[[46,3.52]],"id":41419594}],"con":true,"img":false}]}
{"op":"mcm","clk":"5348581891","pt":1646219052413,"mc":[{"id":"1.195453744","rc":[{"atl":[[790,0],[510,2]],"id":41419585},{"atl":[[17,0],[17.5,4.95],[19,8.8],[19.5,30.36]],"id":41419610}],"con":true,"img":false}]}
{"op":"mcm","clk":"5348581900","pt":1646219052518,"mc":[{"id":"1.195453744","rc":[{"atb":[[75,2.14],[80,4.95],[55,14.71],[60,9.9]],"id":41419585}],"con":true,"img":false}]}
{"op":"mcm","clk":"5348581913","pt":1646219052625,"mc":[{"id":"1.195453744","rc":[{"atl":[[260,6.1]],"id":41419611},{"atl":[[520,2]],"id":41419630},{"atb":[[44,22.22]],"id":41419585}],"con":true,"img":false}]}
{"op":"mcm","clk":"5348581921","pt":1646219052727,"mc":[{"id":"1.195453744","rc":[{"atb":[[9.8,12.63]],"id":41419622},{"atb":[[55,0]],"id":41419585},{"atl":[[50,0]],"id":41419612},{"atl":[[48,13.61]],"id":41419594}],"con":true,"img":false}]}
{"op":"mcm","clk":"5348581929","pt":1646219052835,"mc":[{"id":"1.195453744","rc":[{"atl":[[50,0]],"id":41419594}],"con":true,"img":false}]}
{"op":"mcm","clk":"5348581938","pt":1646219052940,"mc":[{"id":"1.195453744","rc":[{"atl":[[48,10.24]],"id":41419594}],"con":true,"img":false}]}
{"op":"mcm","clk":"5348581952","pt":1646219053046,"mc":[{"id":"1.195453744","rc":[{"atl":[[28,10.82]],"id":41419626},{"atl":[[9.6,9.9]],"id":41419623}],"con":true,"img":false}]}
{"op":"mcm","clk":"5348581962","pt":1646219053148,"mc":[{"id":"1.195453744","rc":[{"atb":[[21,0]],"id":41419603},{"atl":[[150,12.7]],"id":41419612}],"con":true,"img":false}]}
{"op":"mcm","clk":"5348581973","pt":1646219053252,"mc":[{"id":"1.195453744","rc":[{"atl":[[55,0]],"id":41419612},{"atl":[[19.5,38.93]],"id":41419610}],"con":true,"img":false}]}
{"op":"mcm","clk":"5348581993","pt":1646219053412,"mc":[{"id":"1.195453744","rc":[{"atb":[[44,2.72]],"id":41419585}],"con":true,"img":false}]}
{"op":"mcm","clk":"5348582017","pt":1646219053615,"mc":[{"id":"1.195453744","rc":[{"atb":[[17,28.66],[20,0]],"id":41419603},{"atl":[[48,38.04]],"id":41419601},{"atl":[[95,1.68],[100,25.98]],"id":41419637}],"con":true,"img":false}]}
{"op":"mcm","clk":"5348582024","pt":1646219053719,"mc":[{"id":"1.195453744","rc":[{"atl":[[46,0]],"id":41419601}],"con":true,"img":false}]}
{"op":"mcm","clk":"5348582034","pt":1646219053821,"mc":[{"id":"1.195453744","rc":[{"atl":[[32,5.11]],"id":41419607},{"atl":[[32,0],[28,4.95]],"id":41419626}],"con":true,"img":false}]}
{"op":"mcm","clk":"5348582043","pt":1646219053926,"mc":[{"id":"1.195453744","rc":[{"atl":[[150,2]],"id":41419612},{"atl":[[19.5,30.36]],"id":41419610}],"con":true,"img":false}]}
{"op":"mcm","clk":"5348582051","pt":1646219054029,"mc":[{"id":"1.195453744","rc":[{"atl":[[40,4.06],[42,31.99]],"id":41419607}],"con":true,"img":false}]}
{"op":"mcm","clk":"5348582085","pt":1646219054355,"mc":[{"id":"1.195453744","rc":[{"atl":[[34,9.9],[80,22.12]],"id":41419626},{"atl":[[42,3.86]],"id":41419594}],"con":true,"img":false}]}
{"op":"mcm","clk":"5348582116","pt":1646219054614,"mc":[{"id":"1.195453744","rc":[{"atl":[[40,0]],"id":41419607},{"atl":[[32,5.11]],"id":41419626}],"con":true,"img":false}]}
{"op":"mcm","clk":"5348582153","pt":1646219054925,"mc":[{"id":"1.195453744","rc":[{"atl":[[590,4.72],[210,0]],"id":41419604}],"con":true,"img":false}]}
{"op":"mcm","clk":"5348582163","pt":1646219055028,"mc":[{"id":"1.195453744","rc":[{"atl":[[140,11.51],[380,2]],"id":41419635}],"con":true,"img":false}]}
{"op":"mcm","clk":"5348582174","pt":1646219055132,"mc":[{"id":"1.195453744","rc":[{"atb":[[17,28.95],[12.5,11.58]],"id":41419608},{"atl":[[46,0]],"id":41419594}],"con":true,"img":false}]}
{"op":"mcm","clk":"5348582211","pt":1646219055549,"mc":[{"id":"1.195453744","rc":[{"atl":[[200,4.95]],"id":41419597}],"con":true,"img":false}]}
{"op":"mcm","clk":"5348582220","pt":1646219055649,"mc":[{"id":"1.195453744","rc":[{"atl":[[230,0]],"id":41419597}],"con":true,"img":false}]}
{"op":"mcm","clk":"5348582247","pt":1646219056026,"mc":[{"id":"1.195453744","rc":[{"atl":[[200,5.74],[440,2],[230,7.01]],"id":41419597}],"con":true,"img":false}]}
{"op":"mcm","clk":"5348582276","pt":1646219056324,"mc":[{"id":"1.195453744","rc":[{"atl":[[280,4.95],[290,0.55]],"id":41419630}],"con":true,"img":false}]}
{"op":"mcm","clk":"5348582284","pt":1646219056429,"mc":[{"id":"1.195453744","rc":[{"atl":[[42,0],[44,4.95],[50,14.71],[55,9.9]],"id":41419625}],"con":true,"img":false}]}
{"op":"mcm","clk":"5348582328","pt":1646219056844,"mc":[{"id":"1.195453744","rc":[{"atl":[[280,5.52]],"id":41419630},{"atl":[[220,0]],"id":41419597}],"con":true,"img":false}]}
{"op":"mcm","clk":"5348582339","pt":1646219056948,"mc":[{"id":"1.195453744","rc":[{"atl":[[44,8.64]],"id":41419625}],"con":true,"img":false}]}
{"op":"mcm","clk":"5348582397","pt":1646219057526,"mc":[{"id":"1.195453744","rc":[{"atl":[[290,5.57]],"id":41419591}],"con":true,"img":false}]}
{"op":"mcm","clk":"5348582414","pt":1646219057631,"mc":[{"id":"1.195453744","rc":[{"atl":[[290,0]],"id":41419630}],"con":true,"img":false}]}
{"op":"mcm","clk":"5348582430","pt":1646219057729,"mc":[{"id":"1.195453744","rc":[{"atl":[[46,0]],"id":41419625}],"con":true,"img":false}]}
{"op":"mcm","clk":"5348582487","pt":1646219058247,"mc":[{"id":"1.195453744","rc":[{"atl":[[50,0],[55,37.48]],"id":41419625}],"con":true,"img":false}]}
{"op":"mcm","clk":"5348582518","pt":1646219058568,"mc":[{"id":"1.195453744","rc":[{"atl":[[34,32.23],[80,2],[28,10.82]],"id":41419626}],"con":true,"img":false}]}
{"op":"mcm","clk":"5348582536","pt":1646219058726,"mc":[{"id":"1.195453744","rc":[{"atl":[[300,5.4]],"id":41419630},{"atl":[[510,5.17]],"id":41419585}],"con":true,"img":false}]}
{"op":"mcm","clk":"5348582544","pt":1646219058823,"mc":[{"id":"1.195453744","rc":[{"atl":[[170,0]],"id":41419585}],"con":true,"img":false}]}
{"op":"mcm","clk":"5348582595","pt":1646219059361,"mc":[{"id":"1.195453744","rc":[{"atl":[[32,0],[28,4.95]],"id":41419626}],"con":true,"img":false}]}
{"op":"mcm","clk":"5348582613","pt":1646219059525,"mc":[{"id":"1.195453744","rc":[{"atl":[[510,2]],"id":41419585}],"con":true,"img":false}]}
{"op":"mcm","clk":"5348582652","pt":1646219060041,"mc":[{"id":"1.195453744","rc":[{"atb":[[17,2.72],[14.5,29.2]],"id":41419603},{"atl":[[48,9.9],[100,18.25]],"id":41419601},{"atl":[[32,5.11]],"id":41419626}],"con":true,"img":false}]}
{"op":"mcm","clk":"5348582695","pt":1646219060561,"mc":[{"id":"1.195453744","rc":[{"atl":[[75,2.14]],"id":41419637}],"con":true,"img":false}]}
{"op":"mcm","clk":"5348582703","pt":1646219060621,"mc":[{"id":"1.195453744","rc":[{"atl":[[260,0],[140,21.52]],"id":41419611}],"con":true,"img":false}]}
{"op":"mcm","clk":"5348582734","pt":1646219061030,"mc":[{"id":"1.195453744","rc":[{"atl":[[95,12.88],[100,9.9]],"id":41419637}],"con":true,"img":false}]}
{"op":"mcm","clk":"5348582750","pt":1646219061239,"mc":[{"id":"1.195453744","rc":[{"atl":[[95,11.2]],"id":41419637}],"con":true,"img":false}]}
{"op":"mcm","clk":"5348582772","pt":1646219061448,"mc":[{"id":"1.195453744","rc":[{"atl":[[380,6.28]],"id":41419635}],"con":true,"img":false}]}
{"op":"mcm","clk":"5348582783","pt":1646219061554,"mc":[{"id":"1.195453744","rc":[{"atl":[[140,0]],"id":41419635}],"con":true,"img":false}]}
{"op":"mcm","clk":"5348582792","pt":1646219061657,"mc":[{"id":"1.195453744","rc":[{"atl":[[210,7.75]],"id":41419604}],"con":true,"img":false}]}
{"op":"mcm","clk":"5348582800","pt":1646219061759,"mc":[{"id":"1.195453744","rc":[{"atl":[[590,2]],"id":41419604}],"con":true,"img":false}]}
{"op":"mcm","clk":"5348582829","pt":1646219062127,"mc":[{"id":"1.195453744","rc":[{"atb":[[240,1.22]],"id":41419627}],"con":true,"img":false}]}
{"op":"mcm","clk":"5348582837","pt":1646219062231,"mc":[{"id":"1.195453744","rc":[{"atl":[[380,2]],"id":41419635}],"con":true,"img":false}]}
{"op":"mcm","clk":"5348582847","pt":1646219062376,"mc":[{"id":"1.195453744","rc":[{"atl":[[230,0]],"id":41419597},{"atl":[[210,0]],"id":41419604}],"con":true,"img":false}]}
{"op":"mcm","clk":"5348582859","pt":1646219062442,"mc":[{"id":"1.195453744","rc":[{"atl":[[440,5.7]],"id":41419597},{"atl":[[16.5,10.22],[17.5,9.9],[18.5,0],[15.5,4.95]],"id":41419621}],"con":true,"img":false}]}
{"op":"mcm","clk":"5348582901","pt":1646219062964,"mc":[{"id":"1.195453744","rc":[{"atl":[[17.5,39.84],[19,0],[15.5,15.88]],"id":41419621},{"atb":[[240,0.55]],"id":41419627}],"con":true,"img":false}]}
{"op":"mcm","clk":"5348582929","pt":1646219063230,"mc":[{"id":"1.195453744","rc":[{"atl":[[65,2.47],[85,0]],"id":41419593}],"con":true,"img":false}]}
{"op":"mcm","clk":"5348582935","pt":1646219063330,"mc":[{"id":"1.195453744","rc":[{"atl":[[80,9.9],[60,4.95]],"id":41419593},{"atl":[[130,0],[90,4.95],[95,1.68],[120,9.9]],"id":41419598}],"con":true,"img":false}]}
{"op":"mcm","clk":"5348582952","pt":1646219063534,"mc":[{"id":"1.195453744","rc":[{"atl":[[130,9.9],[150,0],[95,4.95],[110,1.45]],"id":41419592}],"con":true,"img":false}]}
{"op":"mcm","clk":"5348582958","pt":1646219063640,"mc":[{"id":"1.195453744","rc":[{"atl":[[16.5,0]],"id":41419621},{"atb":[[170,0.93]],"id":41419627}],"con":true,"img":false}]}
{"op":"mcm","clk":"5348582966","pt":1646219063744,"mc":[{"id":"1.195453744","rc":[{"atl":[[75,21.82],[170,2]],"id":41419593}],"con":true,"img":false}]}
{"op":"mcm","clk":"5348582975","pt":1646219063848,"mc":[{"id":"1.195453744","rc":[{"atl":[[60,7.64]],"id":41419593},{"atl":[[90,6.73],[120,23.54]],"id":41419598}],"con":true,"img":false}]}
{"op":"mcm","clk":"5348582982","pt":1646219063953,"mc":[{"id":"1.195453744","rc":[{"atl":[[42,22.08],[28,4.95]],"id":41419607},{"atl":[[290,0],[1000,3.62]],"id":41419591},{"atl":[[42,4.95],[48,3.37],[50,9.9]],"id":41419612},{"atl":[[130,22.49],[340,2]],"id":41419592},{"atl":[[240,0]],"id":41419598}],"con":true,"img":false}]}
{"op":"mcm","clk":"5348582990","pt":1646219064057,"mc":[{"id":"1.195453744","rc":[{"atl":[[75,7.09],[80,0],[95,21.11],[100,0]],"id":41419637},{"atl":[[95,6.63]],"id":41419592}],"con":true,"img":false}]}
{"op":"mcm","clk":"5348583000","pt":1646219064161,"mc":[{"id":"1.195453744","rc":[{"atb":[[160,7.18],[120,12.63]],"id":41419627}],"con":true,"img":false}]}
{"op":"mcm","clk":"5348583038","pt":1646219064437,"mc":[{"id":"1.195453744","rc":[{"atl":[[34,19.66],[42,0],[28,10.82]],"id":41419607},{"atl":[[40,4.06]],"id":41419612},{"atb":[[6,36.66],[7,0]],"id":41419623}],"con":true,"img":false}]}
{"op":"mcm","clk":"5348583051","pt":1646219064531,"mc":[{"id":"1.195453744","rc":[{"atl":[[65,0]],"id":41419593},{"atb":[[80,6.95]],"id":41419585},{"atl":[[130,14.6],[55,9.9]],"id":41419625},{"atl":[[95,0]],"id":41419598}],"con":true,"img":false}]}
{"op":"mcm","clk":"5348583064","pt":1646219064642,"mc":[{"id":"1.195453744","rc":[{"atl":[[1000,2]],"id":41419591}],"con":true,"img":false}]}
{"op":"mcm","clk":"5348583085","pt":1646219064838,"mc":[{"id":"1.195453744","rc":[{"atb":[[5.6,9.9],[4.4,151.9]],"id":41419623}],"con":true,"img":false}]}
{"op":"mcm","clk":"5348583093","pt":1646219064941,"mc":[{"id":"1.195453744","rc":[{"atl":[[110,0]],"id":41419592}],"con":true,"img":false}]}
{"op":"mcm","clk":"5348583113","pt":1646219065150,"mc":[{"id":"1.195453744","rc":[{"atl":[[32,0],[28,4.95]],"id":41419607},{"atl":[[520,5.14],[300,0]],"id":41419630},{"atl":[[48,0]],"id":41419612},{"atb":[[7.2,2.72],[6.2,3.27]],"id":41419623}],"con":true,"img":false}]}
{"op":"mcm","clk":"5348583123","pt":1646219065254,"mc":[{"id":"1.195453744","rc":[{"atb":[[75,0]],"id":41419585}],"con":true,"img":false}]}
{"op":"mcm","clk":"5348583134","pt":1646219065356,"mc":[{"id":"1.195453744","rc":[{"atl":[[170,9.64]],"id":41419585}],"con":true,"img":false}]}
{"op":"mcm","clk":"5348583179","pt":1646219065728,"mc":[{"id":"1.195453744","rc":[{"atb":[[44,20.62]],"id":41419585}],"con":true,"img":false}]}
{"op":"mcm","clk":"5348583200","pt":1646219065934,"mc":[{"id":"1.195453744","rc":[{"atl":[[32,10.06],[34,14.71],[40,9.9],[28,0]],"id":41419607},{"atl":[[95,0]],"id":41419611},{"atl":[[520,2]],"id":41419630},{"atl":[[75,0],[80,4.95],[95,11.2],[100,9.9]],"id":41419637},{"atl":[[40,0],[42,0],[46,4.95],[50,0],[60,9.9]],"id":41419612},{"atl":[[42,0]],"id":41419594}],"con":true,"img":false}]}
{"op":"mcm","clk":"5348583218","pt":1646219066150,"mc":[{"id":"1.195453744","rc":[{"atl":[[28,10.82]],"id":41419626}],"con":true,"img":false}]}
{"op":"mcm","clk":"5348583230","pt":1646219066254,"mc":[{"id":"1.195453744","rc":[{"atl":[[330,4.95]],"id":41419640},{"atl":[[50,21.22]],"id":41419612}],"con":true,"img":false}]}
{"op":"mcm","clk":"5348583251","pt":1646219066456,"mc":[{"id":"1.195453744","rc":[{"atl":[[840,2],[1000,0.15]],"id":41419640}],"con":true,"img":false}]}
{"op":"mcm","clk":"5348583262","pt":1646219066560,"mc":[{"id":"1.195453744","rc":[{"atl":[[48,0],[55,31.99]],"id":41419594}],"con":true,"img":false}]}
{"op":"mcm","clk":"5348583275","pt":1646219066664,"mc":[{"id":"1.195453744","rc":[{"atl":[[330,5.43],[840,0],[1000,2.15]],"id":41419640},{"atl":[[100,6.55]],"id":41419611},{"atl":[[95,12.88]],"id":41419637},{"atl":[[55,2.93]],"id":41419612},{"atl":[[46,3.52]],"id":41419594}],"con":true,"img":false}]}
{"op":"mcm","clk":"5348583286","pt":1646219066731,"mc":[{"id":"1.195453744","rc":[{"atl":[[32,0],[40,0]],"id":41419607}],"con":true,"img":false}]}
{"op":"mcm","clk":"5348583303","pt":1646219066872,"mc":[{"id":"1.195453744","rc":[{"atl":[[34,19.66],[42,9.9]],"id":41419607},{"atl":[[32,0],[28,4.95]],"id":41419626}],"con":true,"img":false}]}
{"op":"mcm","clk":"5348583317","pt":1646219066933,"mc":[{"id":"1.195453744","rc":[{"atl":[[1000,3.79]],"id":41419640},{"atl":[[17.5,14.56]],"id":41419610}],"con":true,"img":false}]}
{"op":"mcm","clk":"5348583325","pt":1646219067038,"mc":[{"id":"1.195453744","rc":[{"atl":[[270,8.08],[140,9.9]],"id":41419611}],"con":true,"img":false}]}
{"op":"mcm","clk":"5348583355","pt":1646219067336,"mc":[{"id":"1.195453744","rc":[{"atl":[[1000,3.63]],"id":41419640},{"atl":[[34,9.9],[80,22.58]],"id":41419626},{"atl":[[95,1.68],[100,26.37]],"id":41419637}],"con":true,"img":false}]}
{"op":"mcm","clk":"5348583363","pt":1646219067441,"mc":[{"id":"1.195453744","rc":[{"atl":[[34,24.47]],"id":41419607},{"atl":[[44,8.64]],"id":41419594}],"con":true,"img":false}]}
{"op":"mcm","clk":"5348583383","pt":1646219067648,"mc":[{"id":"1.195453744","rc":[{"atl":[[32,5.11]],"id":41419626}],"con":true,"img":false}]}
{"op":"mcm","clk":"5348583392","pt":1646219067752,"mc":[{"id":"1.195453744","rc":[{"atl":[[1000,2]],"id":41419640},{"atl":[[19,0]],"id":41419610}],"con":true,"img":false}]}
{"op":"mcm","clk":"5348583415","pt":1646219067958,"mc":[{"id":"1.195453744","rc":[{"atl":[[210,7.84]],"id":41419604}],"con":true,"img":false}]}
{"op":"mcm","clk":"5348583438","pt":1646219068170,"mc":[{"id":"1.195453744","rc":[{"atl":[[140,11.77]],"id":41419635},{"atl":[[19.5,9.9],[46,38.08]],"id":41419610},{"atl":[[46,0]],"id":41419594}],"con":true,"img":false}]}
{"op":"mcm","clk":"5348583473","pt":1646219068439,"mc":[{"id":"1.195453744","rc":[{"atb":[[12,17.14]],"id":41419610}],"con":true,"img":false}]}
