{"op":"mcm","clk":"5352092074","pt":1646182318990,"mc":[{"id":"1.195503861","marketDefinition":{"bspMarket":false,"turnInPlayEnabled":false,"persistenceEnabled":false,"marketBaseRate":7.0,"eventId":"31272499","eventTypeId":"4339","numberOfWinners":1,"bettingType":"ODDS","marketType":"EXACTA","marketTime":"2022-03-02T08:54:00.000Z","suspendTime":"2022-03-02T08:54:00.000Z","bspReconciled":false,"complete":true,"inPlay":false,"crossMatching":false,"runnersVoidable":false,"numberOfActiveRunners":42,"betDelay":0,"status":"OPEN","runners":[{"status":"ACTIVE","sortPriority":1,"id":41419585,"name":"1 - 2"},{"status":"ACTIVE","sortPriority":2,"id":41419586,"name":"1 - 3"},{"status":"ACTIVE","sortPriority":3,"id":41419587,"name":"1 - 4"},{"status":"ACTIVE","sortPriority":4,"id":41419588,"name":"1 - 5"},{"status":"ACTIVE","sortPriority":5,"id":41419590,"name":"1 - 7"},{"status":"ACTIVE","sortPriority":6,"id":28546943,"name":"1 - 9"},{"status":"ACTIVE","sortPriority":7,"id":41419592,"name":"2 - 1"},{"status":"ACTIVE","sortPriority":8,"id":41419593,"name":"2 - 3"},{"status":"ACTIVE","sortPriority":9,"id":41419594,"name":"2 - 4"},{"status":"ACTIVE","sortPriority":10,"id":41419595,"name":"2 - 5"},{"status":"ACTIVE","sortPriority":11,"id":41419597,"name":"2 - 7"},{"status":"ACTIVE","sortPriority":12,"id":41419651,"name":"2 - 9"},{"status":"ACTIVE","sortPriority":13,"id":41419599,"name":"3 - 1"},{"status":"ACTIVE","sortPriority":14,"id":41419600,"name":"3 - 2"},{"status":"ACTIVE","sortPriority":15,"id":41419601,"name":"3 - 4"},{"status":"ACTIVE","sortPriority":16,"id":41419602,"name":"3 - 5"},{"status":"ACTIVE","sortPriority":17,"id":41419604,"name":"3 - 7"},{"status":"ACTIVE","sortPriority":18,"id":41419652,"name":"3 - 9"},{"status":"ACTIVE","sortPriority":19,"id":41419606,"name":"4 - 1"},{"status":"ACTIVE","sortPriority":20,"id":41419607,"name":"4 - 2"},{"status":"ACTIVE","sortPriority":21,"id":41419608,"name":"4 - 3"},{"status":"ACTIVE","sortPriority":22,"id":41419609,"name":"4 - 5"},{"status":"ACTIVE","sortPriority":23,"id":41419611,"name":"4 - 7"},{"status":"ACTIVE","sortPriority":24,"id":41435525,"name":"4 - 9"},{"status":"ACTIVE","sortPriority":25,"id":41419613,"name":"5 - 1"},{"status":"ACTIVE","sortPriority":26,"id":41419614,"name":"5 - 2"},{"status":"ACTIVE","sortPriority":27,"id":41419615,"name":"5 - 3"},{"status":"ACTIVE","sortPriority":28,"id":41419616,"name":"5 - 4"},{"status":"ACTIVE","sortPriority":29,"id":41419618,"name":"5 - 7"},{"status":"ACTIVE","sortPriority":30,"id":41419653,"name":"5 - 9"},{"status":"ACTIVE","sortPriority":31,"id":41419627,"name":"7 - 1"},{"status":"ACTIVE","sortPriority":32,"id":41419628,"name":"7 - 2"},{"status":"ACTIVE","sortPriority":33,"id":41419629,"name":"7 - 3"},{"status":"ACTIVE","sortPriority":34,"id":41419630,"name":"7 - 4"},{"status":"ACTIVE","sortPriority":35,"id":41419631,"name":"7 - 5"},{"status":"ACTIVE","sortPriority":36,"id":41419654,"name":"7 - 9"},{"status":"ACTIVE","sortPriority":37,"id":28546950,"name":"9 - 1"},{"status":"ACTIVE","sortPriority":38,"id":41419656,"name":"9 - 2"},{"status":"ACTIVE","sortPriority":39,"id":41419657,"name":"9 - 3"},{"status":"ACTIVE","sortPriority":40,"id":41435527,"name":"9 - 4"},{"status":"ACTIVE","sortPriority":41,"id":41419658,"name":"9 - 5"},{"status":"ACTIVE","sortPriority":42,"id":41419659,"name":"9 - 7"}],"regulators":["MR_INT"],"venue":"Rockhampton","countryCode":"AU","discountAllowed":true,"timezone":"Australia/Queensland","openDate":"2022-03-02T08:34:00.000Z","version":4382565133,"name":"Exacta","eventName":"Rockhampton (AUS) 2nd Mar"},"rc":[],"con":true,"img":false}]}
{"op":"mcm","clk":"5352095595","pt":1646182411189,"mc":[{"id":"1.195503861","rc":[{"atb":[[16.5,12.87],[11.5,25.34],[28,7.39]],"id":41419609},{"atb":[[16.5,12.87],[11.5,25.34],[28,7.39]],"id":41419607},{"atb":[[150,1.78],[400,0.5],[250,0.8]],"id":28546950},{"atb":[[42,4.86],[21,9.97],[15.5,18.35]],"id":41419615},{"atb":[[19.5,10.79],[12,18.14],[8.8,34.11]],"id":41419613},{"atb":[[7.2,42.92],[9.2,24.34],[15.5,13.76]],"id":41419611},{"atb":[[42,4.86],[21,9.97],[15.5,18.35]],"id":41419593},{"atb":[[600,0.44],[700,0.28],[850,0.23]],"id":41419657},{"atb":[[640,0.31],[390,0.68],[490,0.4]],"id":41435525},{"atb":[[130,1.54],[65,4.15],[280,0.71]],"id":41419653},{"atb":[[560,0.35],[710,0.28],[460,0.57]],"id":41435527},{"atb":[[16.5,12.87],[11.5,25.34],[28,7.39]],"id":41419587},{"atb":[[130,1.54],[65,4.15],[280,0.71]],"id":41419651},{"atb":[[4.8,70.02],[8.6,26.26],[5.8,41.58]],"id":41419618},{"atb":[[32,6.44],[80,2.52],[21,13.3]],"id":41419601},{"atb":[[17,16.63],[48,4.24],[24,8.67]],"id":41419599},{"atb":[[10,22.17],[5.5,59.13],[7,33.26]],"id":41419630},{"atb":[[4.8,70.02],[8.6,26.26],[5.8,41.58]],"id":41419597},{"atb":[[320,0.62],[170,1.18],[85,3.16]],"id":28546943},{"atb":[[7.2,32.19],[5.1,48.67],[4.1,85.84]],"id":41419628},{"atb":[[32,6.44],[80,2.52],[21,13.3]],"id":41419659},{"atb":[[18.5,11.4],[11,19.95],[8.4,35.95]],"id":41419595},{"atb":[[32,6.44],[80,2.52],[21,13.3]],"id":41419608},{"atb":[[17,12.47],[12,24.19],[29,7.12]],"id":41419606},{"atb":[[10,29.56],[25,8.31],[15,14.25]],"id":41419604},{"atb":[[16.5,17.17],[46,4.43],[23,9.07]],"id":41419602},{"atb":[[19.5,10.79],[12,18.14],[8.8,34.11]],"id":41419585},{"atb":[[16,13.3],[11,26.61],[27,7.67]],"id":41419616},{"atb":[[18.5,11.4],[11,19.95],[8.4,35.95]],"id":41419614},{"atb":[[19.5,10.79],[12,18.14],[8.8,34.11]],"id":41419592},{"atb":[[350,0.57],[200,1],[100,2.68]],"id":41419656},{"atb":[[5.1,64.9],[9.2,24.34],[6.2,38.38]],"id":41419590},{"atb":[[16.5,17.17],[46,4.43],[23,9.07]],"id":41419654},{"atb":[[19.5,10.79],[12,18.14],[8.8,34.11]],"id":41419588},{"atb":[[600,0.44],[700,0.28],[850,0.23]],"id":41419652},{"atb":[[16,17.74],[44,4.64],[22,9.5]],"id":41419586},{"atb":[[16.5,17.17],[46,4.43],[23,9.07]],"id":41419600},{"atb":[[7.2,32.19],[5.1,48.67],[4.1,85.84]],"id":41419631},{"atb":[[18.5,11.4],[11,19.95],[8.4,35.95]],"id":41419629},{"atb":[[7.4,31.18],[5.2,47.52],[4.2,83.16]],"id":41419627},{"atb":[[16,13.3],[11,26.61],[27,7.67]],"id":41419594},{"atb":[[350,0.57],[200,1],[100,2.68]],"id":41419658}],"con":true,"img":false}]}
{"op":"mcm","clk":"5352146188","pt":1646183572645,"mc":[{"id":"1.195503861","marketDefinition":{"bspMarket":false,"turnInPlayEnabled":false,"persistenceEnabled":false,"marketBaseRate":7.0,"eventId":"31272499","eventTypeId":"4339","numberOfWinners":1,"bettingType":"ODDS","marketType":"EXACTA","marketTime":"2022-03-02T08:54:00.000Z","suspendTime":"2022-03-02T08:54:00.000Z","bspReconciled":false,"complete":true,"inPlay":false,"crossMatching":false,"runnersVoidable":false,"numberOfActiveRunners":42,"betDelay":0,"status":"OPEN","runners":[{"status":"ACTIVE","sortPriority":1,"id":41419585,"name":"1 - 2"},{"status":"ACTIVE","sortPriority":2,"id":41419586,"name":"1 - 3"},{"status":"ACTIVE","sortPriority":3,"id":41419587,"name":"1 - 4"},{"status":"ACTIVE","sortPriority":4,"id":41419588,"name":"1 - 5"},{"status":"ACTIVE","sortPriority":5,"id":41419590,"name":"1 - 7"},{"status":"ACTIVE","sortPriority":6,"id":28546943,"name":"1 - 9"},{"status":"ACTIVE","sortPriority":7,"id":41419592,"name":"2 - 1"},{"status":"ACTIVE","sortPriority":8,"id":41419593,"name":"2 - 3"},{"status":"ACTIVE","sortPriority":9,"id":41419594,"name":"2 - 4"},{"status":"ACTIVE","sortPriority":10,"id":41419595,"name":"2 - 5"},{"status":"ACTIVE","sortPriority":11,"id":41419597,"name":"2 - 7"},{"status":"ACTIVE","sortPriority":12,"id":41419651,"name":"2 - 9"},{"status":"ACTIVE","sortPriority":13,"id":41419599,"name":"3 - 1"},{"status":"ACTIVE","sortPriority":14,"id":41419600,"name":"3 - 2"},{"status":"ACTIVE","sortPriority":15,"id":41419601,"name":"3 - 4"},{"status":"ACTIVE","sortPriority":16,"id":41419602,"name":"3 - 5"},{"status":"ACTIVE","sortPriority":17,"id":41419604,"name":"3 - 7"},{"status":"ACTIVE","sortPriority":18,"id":41419652,"name":"3 - 9"},{"status":"ACTIVE","sortPriority":19,"id":41419606,"name":"4 - 1"},{"status":"ACTIVE","sortPriority":20,"id":41419607,"name":"4 - 2"},{"status":"ACTIVE","sortPriority":21,"id":41419608,"name":"4 - 3"},{"status":"ACTIVE","sortPriority":22,"id":41419609,"name":"4 - 5"},{"status":"ACTIVE","sortPriority":23,"id":41419611,"name":"4 - 7"},{"status":"ACTIVE","sortPriority":24,"id":41435525,"name":"4 - 9"},{"status":"ACTIVE","sortPriority":25,"id":41419613,"name":"5 - 1"},{"status":"ACTIVE","sortPriority":26,"id":41419614,"name":"5 - 2"},{"status":"ACTIVE","sortPriority":27,"id":41419615,"name":"5 - 3"},{"status":"ACTIVE","sortPriority":28,"id":41419616,"name":"5 - 4"},{"status":"ACTIVE","sortPriority":29,"id":41419618,"name":"5 - 7"},{"status":"ACTIVE","sortPriority":30,"id":41419653,"name":"5 - 9"},{"status":"ACTIVE","sortPriority":31,"id":41419627,"name":"7 - 1"},{"status":"ACTIVE","sortPriority":32,"id":41419628,"name":"7 - 2"},{"status":"ACTIVE","sortPriority":33,"id":41419629,"name":"7 - 3"},{"status":"ACTIVE","sortPriority":34,"id":41419630,"name":"7 - 4"},{"status":"ACTIVE","sortPriority":35,"id":41419631,"name":"7 - 5"},{"status":"ACTIVE","sortPriority":36,"id":41419654,"name":"7 - 9"},{"status":"ACTIVE","sortPriority":37,"id":28546950,"name":"9 - 1"},{"status":"ACTIVE","sortPriority":38,"id":41419656,"name":"9 - 2"},{"status":"ACTIVE","sortPriority":39,"id":41419657,"name":"9 - 3"},{"status":"ACTIVE","sortPriority":40,"id":41435527,"name":"9 - 4"},{"status":"ACTIVE","sortPriority":41,"id":41419658,"name":"9 - 5"},{"status":"ACTIVE","sortPriority":42,"id":41419659,"name":"9 - 7"}],"regulators":["MR_INT"],"venue":"Rockhampton","countryCode":"AU","discountAllowed":true,"timezone":"Australia/Queensland","openDate":"2022-03-02T08:28:00.000Z","version":4382597890,"name":"Exacta","eventName":"Rockhampton (AUS) 2nd Mar"},"rc":[],"con":true,"img":false}]}
{"op":"mcm","clk":"5352148823","pt":1646183642815,"mc":[{"id":"1.195503861","marketDefinition":{"bspMarket":false,"turnInPlayEnabled":false,"persistenceEnabled":false,"marketBaseRate":7.0,"eventId":"31272499","eventTypeId":"4339","numberOfWinners":1,"bettingType":"ODDS","marketType":"EXACTA","marketTime":"2022-03-02T08:48:00.000Z","suspendTime":"2022-03-02T08:48:00.000Z","bspReconciled":false,"complete":true,"inPlay":false,"crossMatching":false,"runnersVoidable":false,"numberOfActiveRunners":42,"betDelay":0,"status":"OPEN","runners":[{"status":"ACTIVE","sortPriority":1,"id":41419585,"name":"1 - 2"},{"status":"ACTIVE","sortPriority":2,"id":41419586,"name":"1 - 3"},{"status":"ACTIVE","sortPriority":3,"id":41419587,"name":"1 - 4"},{"status":"ACTIVE","sortPriority":4,"id":41419588,"name":"1 - 5"},{"status":"ACTIVE","sortPriority":5,"id":41419590,"name":"1 - 7"},{"status":"ACTIVE","sortPriority":6,"id":28546943,"name":"1 - 9"},{"status":"ACTIVE","sortPriority":7,"id":41419592,"name":"2 - 1"},{"status":"ACTIVE","sortPriority":8,"id":41419593,"name":"2 - 3"},{"status":"ACTIVE","sortPriority":9,"id":41419594,"name":"2 - 4"},{"status":"ACTIVE","sortPriority":10,"id":41419595,"name":"2 - 5"},{"status":"ACTIVE","sortPriority":11,"id":41419597,"name":"2 - 7"},{"status":"ACTIVE","sortPriority":12,"id":41419651,"name":"2 - 9"},{"status":"ACTIVE","sortPriority":13,"id":41419599,"name":"3 - 1"},{"status":"ACTIVE","sortPriority":14,"id":41419600,"name":"3 - 2"},{"status":"ACTIVE","sortPriority":15,"id":41419601,"name":"3 - 4"},{"status":"ACTIVE","sortPriority":16,"id":41419602,"name":"3 - 5"},{"status":"ACTIVE","sortPriority":17,"id":41419604,"name":"3 - 7"},{"status":"ACTIVE","sortPriority":18,"id":41419652,"name":"3 - 9"},{"status":"ACTIVE","sortPriority":19,"id":41419606,"name":"4 - 1"},{"status":"ACTIVE","sortPriority":20,"id":41419607,"name":"4 - 2"},{"status":"ACTIVE","sortPriority":21,"id":41419608,"name":"4 - 3"},{"status":"ACTIVE","sortPriority":22,"id":41419609,"name":"4 - 5"},{"status":"ACTIVE","sortPriority":23,"id":41419611,"name":"4 - 7"},{"status":"ACTIVE","sortPriority":24,"id":41435525,"name":"4 - 9"},{"status":"ACTIVE","sortPriority":25,"id":41419613,"name":"5 - 1"},{"status":"ACTIVE","sortPriority":26,"id":41419614,"name":"5 - 2"},{"status":"ACTIVE","sortPriority":27,"id":41419615,"name":"5 - 3"},{"status":"ACTIVE","sortPriority":28,"id":41419616,"name":"5 - 4"},{"status":"ACTIVE","sortPriority":29,"id":41419618,"name":"5 - 7"},{"status":"ACTIVE","sortPriority":30,"id":41419653,"name":"5 - 9"},{"status":"ACTIVE","sortPriority":31,"id":41419627,"name":"7 - 1"},{"status":"ACTIVE","sortPriority":32,"id":41419628,"name":"7 - 2"},{"status":"ACTIVE","sortPriority":33,"id":41419629,"name":"7 - 3"},{"status":"ACTIVE","sortPriority":34,"id":41419630,"name":"7 - 4"},{"status":"ACTIVE","sortPriority":35,"id":41419631,"name":"7 - 5"},{"status":"ACTIVE","sortPriority":36,"id":41419654,"name":"7 - 9"},{"status":"ACTIVE","sortPriority":37,"id":28546950,"name":"9 - 1"},{"status":"ACTIVE","sortPriority":38,"id":41419656,"name":"9 - 2"},{"status":"ACTIVE","sortPriority":39,"id":41419657,"name":"9 - 3"},{"status":"ACTIVE","sortPriority":40,"id":41435527,"name":"9 - 4"},{"status":"ACTIVE","sortPriority":41,"id":41419658,"name":"9 - 5"},{"status":"ACTIVE","sortPriority":42,"id":41419659,"name":"9 - 7"}],"regulators":["MR_INT"],"venue":"Rockhampton","countryCode":"AU","discountAllowed":true,"timezone":"Australia/Queensland","openDate":"2022-03-02T08:28:00.000Z","version":4382599164,"name":"Exacta","eventName":"Rockhampton (AUS) 2nd Mar"},"rc":[],"con":true,"img":false}]}
{"op":"mcm","clk":"5352239430","pt":1646185602748,"mc":[{"id":"1.195503861","marketDefinition":{"bspMarket":false,"turnInPlayEnabled":false,"persistenceEnabled":false,"marketBaseRate":7.0,"eventId":"31272499","eventTypeId":"4339","numberOfWinners":1,"bettingType":"ODDS","marketType":"EXACTA","marketTime":"2022-03-02T08:48:00.000Z","suspendTime":"2022-03-02T08:48:00.000Z","bspReconciled":false,"complete":true,"inPlay":false,"crossMatching":false,"runnersVoidable":false,"numberOfActiveRunners":42,"betDelay":0,"status":"OPEN","runners":[{"status":"ACTIVE","sortPriority":1,"id":41419585,"name":"1 - 2"},{"status":"ACTIVE","sortPriority":2,"id":41419586,"name":"1 - 3"},{"status":"ACTIVE","sortPriority":3,"id":41419587,"name":"1 - 4"},{"status":"ACTIVE","sortPriority":4,"id":41419588,"name":"1 - 5"},{"status":"ACTIVE","sortPriority":5,"id":41419590,"name":"1 - 7"},{"status":"ACTIVE","sortPriority":6,"id":28546943,"name":"1 - 9"},{"status":"ACTIVE","sortPriority":7,"id":41419592,"name":"2 - 1"},{"status":"ACTIVE","sortPriority":8,"id":41419593,"name":"2 - 3"},{"status":"ACTIVE","sortPriority":9,"id":41419594,"name":"2 - 4"},{"status":"ACTIVE","sortPriority":10,"id":41419595,"name":"2 - 5"},{"status":"ACTIVE","sortPriority":11,"id":41419597,"name":"2 - 7"},{"status":"ACTIVE","sortPriority":12,"id":41419651,"name":"2 - 9"},{"status":"ACTIVE","sortPriority":13,"id":41419599,"name":"3 - 1"},{"status":"ACTIVE","sortPriority":14,"id":41419600,"name":"3 - 2"},{"status":"ACTIVE","sortPriority":15,"id":41419601,"name":"3 - 4"},{"status":"ACTIVE","sortPriority":16,"id":41419602,"name":"3 - 5"},{"status":"ACTIVE","sortPriority":17,"id":41419604,"name":"3 - 7"},{"status":"ACTIVE","sortPriority":18,"id":41419652,"name":"3 - 9"},{"status":"ACTIVE","sortPriority":19,"id":41419606,"name":"4 - 1"},{"status":"ACTIVE","sortPriority":20,"id":41419607,"name":"4 - 2"},{"status":"ACTIVE","sortPriority":21,"id":41419608,"name":"4 - 3"},{"status":"ACTIVE","sortPriority":22,"id":41419609,"name":"4 - 5"},{"status":"ACTIVE","sortPriority":23,"id":41419611,"name":"4 - 7"},{"status":"ACTIVE","sortPriority":24,"id":41435525,"name":"4 - 9"},{"status":"ACTIVE","sortPriority":25,"id":41419613,"name":"5 - 1"},{"status":"ACTIVE","sortPriority":26,"id":41419614,"name":"5 - 2"},{"status":"ACTIVE","sortPriority":27,"id":41419615,"name":"5 - 3"},{"status":"ACTIVE","sortPriority":28,"id":41419616,"name":"5 - 4"},{"status":"ACTIVE","sortPriority":29,"id":41419618,"name":"5 - 7"},{"status":"ACTIVE","sortPriority":30,"id":41419653,"name":"5 - 9"},{"status":"ACTIVE","sortPriority":31,"id":41419627,"name":"7 - 1"},{"status":"ACTIVE","sortPriority":32,"id":41419628,"name":"7 - 2"},{"status":"ACTIVE","sortPriority":33,"id":41419629,"name":"7 - 3"},{"status":"ACTIVE","sortPriority":34,"id":41419630,"name":"7 - 4"},{"status":"ACTIVE","sortPriority":35,"id":41419631,"name":"7 - 5"},{"status":"ACTIVE","sortPriority":36,"id":41419654,"name":"7 - 9"},{"status":"ACTIVE","sortPriority":37,"id":28546950,"name":"9 - 1"},{"status":"ACTIVE","sortPriority":38,"id":41419656,"name":"9 - 2"},{"status":"ACTIVE","sortPriority":39,"id":41419657,"name":"9 - 3"},{"status":"ACTIVE","sortPriority":40,"id":41435527,"name":"9 - 4"},{"status":"ACTIVE","sortPriority":41,"id":41419658,"name":"9 - 5"},{"status":"ACTIVE","sortPriority":42,"id":41419659,"name":"9 - 7"}],"regulators":["MR_INT"],"venue":"Rockhampton","countryCode":"AU","discountAllowed":true,"timezone":"Australia/Queensland","openDate":"2022-03-02T08:28:00.000Z","version":4382599164,"name":"Exacta","eventName":"Rockhampton (AUS) 2nd Mar"},"rc":[{"atb":[[16.5,12.89],[11.5,25.38],[28,7.4]],"id":41419609},{"atb":[[16.5,12.89],[11.5,25.38],[28,7.4]],"id":41419607},{"atb":[[150,1.78],[400,0.5],[250,0.8]],"id":28546950},{"atb":[[42,4.87],[21,9.99],[15.5,18.38]],"id":41419615},{"atb":[[19.5,10.8],[12,18.17],[8.8,34.17]],"id":41419613},{"atb":[[7.2,42.99],[9.2,24.37],[15.5,13.78]],"id":41419611},{"atb":[[42,4.87],[21,9.99],[15.5,18.38]],"id":41419593},{"atb":[[600,0.44],[700,0.28],[850,0.23]],"id":41419657},{"atb":[[640,0.31],[390,0.68],[490,0.4]],"id":41435525},{"atb":[[130,1.54],[65,4.16],[280,0.71]],"id":41419653},{"atb":[[560,0.35],[710,0.28],[460,0.57]],"id":41435527},{"atb":[[16.5,12.89],[11.5,25.38],[28,7.4]],"id":41419587},{"atb":[[130,1.54],[65,4.16],[280,0.71]],"id":41419651},{"atb":[[4.8,70.14],[8.6,26.3],[5.8,41.64]],"id":41419618},{"atb":[[32,6.45],[80,2.53],[21,13.32]],"id":41419601},{"atb":[[17,16.65],[48,4.25],[24,8.69]],"id":41419599},{"atb":[[10,22.2],[5.5,59.22],[7,33.31]],"id":41419630},{"atb":[[4.8,70.14],[8.6,26.3],[5.8,41.64]],"id":41419597},{"atb":[[320,0.62],[170,1.18],[85,3.17]],"id":28546943},{"atb":[[7.2,32.24],[5.1,48.75],[4.1,85.98]],"id":41419628},{"atb":[[32,6.45],[80,2.53],[21,13.32]],"id":41419659},{"atb":[[18.5,11.42],[11,19.99],[8.4,36.01]],"id":41419595},{"atb":[[32,6.45],[80,2.53],[21,13.32]],"id":41419608},{"atb":[[17,12.49],[12,24.23],[29,7.13]],"id":41419606},{"atb":[[10,29.61],[25,8.32],[15,14.28]],"id":41419604},{"atb":[[16.5,17.19],[46,4.44],[23,9.08]],"id":41419602},{"atb":[[19.5,10.8],[12,18.17],[8.8,34.17]],"id":41419585},{"atb":[[16,13.32],[11,26.65],[27,7.68]],"id":41419616},{"atb":[[18.5,11.42],[11,19.99],[8.4,36.01]],"id":41419614},{"atb":[[19.5,10.8],[12,18.17],[8.8,34.17]],"id":41419592},{"atb":[[350,0.57],[200,1],[100,2.69]],"id":41419656},{"atb":[[5.1,65],[9.2,24.37],[6.2,38.44]],"id":41419590},{"atb":[[16.5,17.19],[46,4.44],[23,9.08]],"id":41419654},{"atb":[[19.5,10.8],[12,18.17],[8.8,34.17]],"id":41419588},{"atb":[[600,0.44],[700,0.28],[850,0.23]],"id":41419652},{"atb":[[16,17.77],[44,4.65],[22,9.52]],"id":41419586},{"atb":[[16.5,17.19],[46,4.44],[23,9.08]],"id":41419600},{"atb":[[7.2,32.24],[5.1,48.75],[4.1,85.98]],"id":41419631},{"atb":[[18.5,11.42],[11,19.99],[8.4,36.01]],"id":41419629},{"atb":[[7.4,31.23],[5.2,47.59],[4.2,83.29]],"id":41419627},{"atb":[[16,13.32],[11,26.65],[27,7.68]],"id":41419594},{"atb":[[350,0.57],[200,1],[100,2.69]],"id":41419658}],"con":true,"img":true}]}
{"op":"mcm","clk":"5352466718","pt":1646191002691,"mc":[{"id":"1.195503861","marketDefinition":{"bspMarket":false,"turnInPlayEnabled":false,"persistenceEnabled":false,"marketBaseRate":7.0,"eventId":"31272499","eventTypeId":"4339","numberOfWinners":1,"bettingType":"ODDS","marketType":"EXACTA","marketTime":"2022-03-02T08:48:00.000Z","suspendTime":"2022-03-02T08:48:00.000Z","bspReconciled":false,"complete":true,"inPlay":false,"crossMatching":false,"runnersVoidable":false,"numberOfActiveRunners":42,"betDelay":0,"status":"OPEN","runners":[{"status":"ACTIVE","sortPriority":1,"id":41419585,"name":"1 - 2"},{"status":"ACTIVE","sortPriority":2,"id":41419586,"name":"1 - 3"},{"status":"ACTIVE","sortPriority":3,"id":41419587,"name":"1 - 4"},{"status":"ACTIVE","sortPriority":4,"id":41419588,"name":"1 - 5"},{"status":"ACTIVE","sortPriority":5,"id":41419590,"name":"1 - 7"},{"status":"ACTIVE","sortPriority":6,"id":28546943,"name":"1 - 9"},{"status":"ACTIVE","sortPriority":7,"id":41419592,"name":"2 - 1"},{"status":"ACTIVE","sortPriority":8,"id":41419593,"name":"2 - 3"},{"status":"ACTIVE","sortPriority":9,"id":41419594,"name":"2 - 4"},{"status":"ACTIVE","sortPriority":10,"id":41419595,"name":"2 - 5"},{"status":"ACTIVE","sortPriority":11,"id":41419597,"name":"2 - 7"},{"status":"ACTIVE","sortPriority":12,"id":41419651,"name":"2 - 9"},{"status":"ACTIVE","sortPriority":13,"id":41419599,"name":"3 - 1"},{"status":"ACTIVE","sortPriority":14,"id":41419600,"name":"3 - 2"},{"status":"ACTIVE","sortPriority":15,"id":41419601,"name":"3 - 4"},{"status":"ACTIVE","sortPriority":16,"id":41419602,"name":"3 - 5"},{"status":"ACTIVE","sortPriority":17,"id":41419604,"name":"3 - 7"},{"status":"ACTIVE","sortPriority":18,"id":41419652,"name":"3 - 9"},{"status":"ACTIVE","sortPriority":19,"id":41419606,"name":"4 - 1"},{"status":"ACTIVE","sortPriority":20,"id":41419607,"name":"4 - 2"},{"status":"ACTIVE","sortPriority":21,"id":41419608,"name":"4 - 3"},{"status":"ACTIVE","sortPriority":22,"id":41419609,"name":"4 - 5"},{"status":"ACTIVE","sortPriority":23,"id":41419611,"name":"4 - 7"},{"status":"ACTIVE","sortPriority":24,"id":41435525,"name":"4 - 9"},{"status":"ACTIVE","sortPriority":25,"id":41419613,"name":"5 - 1"},{"status":"ACTIVE","sortPriority":26,"id":41419614,"name":"5 - 2"},{"status":"ACTIVE","sortPriority":27,"id":41419615,"name":"5 - 3"},{"status":"ACTIVE","sortPriority":28,"id":41419616,"name":"5 - 4"},{"status":"ACTIVE","sortPriority":29,"id":41419618,"name":"5 - 7"},{"status":"ACTIVE","sortPriority":30,"id":41419653,"name":"5 - 9"},{"status":"ACTIVE","sortPriority":31,"id":41419627,"name":"7 - 1"},{"status":"ACTIVE","sortPriority":32,"id":41419628,"name":"7 - 2"},{"status":"ACTIVE","sortPriority":33,"id":41419629,"name":"7 - 3"},{"status":"ACTIVE","sortPriority":34,"id":41419630,"name":"7 - 4"},{"status":"ACTIVE","sortPriority":35,"id":41419631,"name":"7 - 5"},{"status":"ACTIVE","sortPriority":36,"id":41419654,"name":"7 - 9"},{"status":"ACTIVE","sortPriority":37,"id":28546950,"name":"9 - 1"},{"status":"ACTIVE","sortPriority":38,"id":41419656,"name":"9 - 2"},{"status":"ACTIVE","sortPriority":39,"id":41419657,"name":"9 - 3"},{"status":"ACTIVE","sortPriority":40,"id":41435527,"name":"9 - 4"},{"status":"ACTIVE","sortPriority":41,"id":41419658,"name":"9 - 5"},{"status":"ACTIVE","sortPriority":42,"id":41419659,"name":"9 - 7"}],"regulators":["MR_INT"],"venue":"Rockhampton","countryCode":"AU","discountAllowed":true,"timezone":"Australia/Queensland","openDate":"2022-03-02T08:28:00.000Z","version":4382599164,"name":"Exacta","eventName":"Rockhampton (AUS) 2nd Mar"},"rc":[{"atb":[[16.5,12.91],[11.5,25.42],[28,7.41]],"id":41419609},{"atb":[[16.5,12.91],[11.5,25.42],[28,7.41]],"id":41419607},{"atb":[[150,1.79],[400,0.5],[250,0.8]],"id":28546950},{"atb":[[42,4.88],[21,10.01],[15.5,18.41]],"id":41419615},{"atb":[[19.5,10.82],[12,18.2],[8.8,34.23]],"id":41419613},{"atb":[[7.2,43.06],[9.2,24.42],[15.5,13.8]],"id":41419611},{"atb":[[42,4.88],[21,10.01],[15.5,18.41]],"id":41419593},{"atb":[[600,0.44],[700,0.28],[850,0.23]],"id":41419657},{"atb":[[640,0.31],[390,0.68],[490,0.4]],"id":41435525},{"atb":[[130,1.55],[65,4.17],[280,0.71]],"id":41419653},{"atb":[[560,0.36],[710,0.28],[460,0.57]],"id":41435527},{"atb":[[16.5,12.91],[11.5,25.42],[28,7.41]],"id":41419587},{"atb":[[130,1.55],[65,4.17],[280,0.71]],"id":41419651},{"atb":[[4.8,70.25],[8.6,26.34],[5.8,41.71]],"id":41419618},{"atb":[[32,6.46],[80,2.53],[21,13.34]],"id":41419601},{"atb":[[17,16.68],[48,4.26],[24,8.7]],"id":41419599},{"atb":[[10,22.24],[5.5,59.32],[7,33.37]],"id":41419630},{"atb":[[4.8,70.25],[8.6,26.34],[5.8,41.71]],"id":41419597},{"atb":[[320,0.62],[170,1.18],[85,3.17]],"id":28546943},{"atb":[[7.2,32.29],[5.1,48.83],[4.1,86.12]],"id":41419628},{"atb":[[32,6.46],[80,2.53],[21,13.34]],"id":41419659},{"atb":[[18.5,11.44],[11,20.02],[8.4,36.07]],"id":41419595},{"atb":[[32,6.46],[80,2.53],[21,13.34]],"id":41419608},{"atb":[[17,12.51],[12,24.27],[29,7.14]],"id":41419606},{"atb":[[10,29.66],[25,8.34],[15,14.3]],"id":41419604},{"atb":[[16.5,17.22],[46,4.45],[23,9.09]],"id":41419602},{"atb":[[19.5,10.82],[12,18.2],[8.8,34.23]],"id":41419585},{"atb":[[16,13.34],[11,26.69],[27,7.7]],"id":41419616},{"atb":[[18.5,11.44],[11,20.02],[8.4,36.07]],"id":41419614},{"atb":[[19.5,10.82],[12,18.2],[8.8,34.23]],"id":41419592},{"atb":[[350,0.57],[200,1],[100,2.69]],"id":41419656},{"atb":[[5.1,65.11],[9.2,24.42],[6.2,38.5]],"id":41419590},{"atb":[[16.5,17.22],[46,4.45],[23,9.09]],"id":41419654},{"atb":[[19.5,10.82],[12,18.2],[8.8,34.23]],"id":41419588},{"atb":[[600,0.44],[700,0.28],[850,0.23]],"id":41419652},{"atb":[[16,17.8],[44,4.65],[22,9.53]],"id":41419586},{"atb":[[16.5,17.22],[46,4.45],[23,9.09]],"id":41419600},{"atb":[[7.2,32.29],[5.1,48.83],[4.1,86.12]],"id":41419631},{"atb":[[18.5,11.44],[11,20.02],[8.4,36.07]],"id":41419629},{"atb":[[7.4,31.28],[5.2,47.67],[4.2,83.43]],"id":41419627},{"atb":[[16,13.34],[11,26.69],[27,7.7]],"id":41419594},{"atb":[[350,0.57],[200,1],[100,2.69]],"id":41419658}],"con":true,"img":true}]}
{"op":"mcm","clk":"5352586059","pt":1646194224073,"mc":[{"id":"1.195503861","rc":[{"atb":[[16.5,12.91],[11.5,25.42],[28,7.41]],"id":41419609},{"atb":[[16.5,0],[11.5,0],[28,0]],"id":41419607},{"atb":[[150,0],[400,0],[250,0]],"id":28546950},{"atb":[[42,4.88],[21,10.01],[15.5,18.41]],"id":41419615},{"atb":[[19.5,10.82],[12,18.2],[8.8,34.23]],"id":41419613},{"atb":[[7.2,43.06],[9.2,24.42],[15.5,13.8]],"id":41419611},{"atb":[[42,0],[21,0],[15.5,0]],"id":41419593},{"atb":[[600,0.44],[700,0.28],[850,0.23]],"id":41419657},{"atb":[[640,0.31],[390,0.68],[490,0.4]],"id":41435525},{"atb":[[130,1.55],[65,4.17],[280,0.71]],"id":41419653},{"atb":[[560,0.36],[710,0.28],[460,0.57]],"id":41435527},{"atb":[[16.5,0],[11.5,0],[28,0]],"id":41419587},{"atb":[[130,1.55],[65,4.17],[280,0.71]],"id":41419651},{"atb":[[4.8,70.25],[8.6,26.34],[5.8,41.71]],"id":41419618},{"atb":[[32,0],[80,0],[21,0]],"id":41419601},{"atb":[[17,0],[48,0],[24,0]],"id":41419599},{"atb":[[10,22.24],[5.5,59.32],[7,33.37]],"id":41419630},{"atb":[[4.8,0],[8.6,0],[5.8,0]],"id":41419597},{"atb":[[320,0],[170,0],[85,0]],"id":28546943},{"atb":[[7.2,32.29],[5.1,48.83],[4.1,86.12]],"id":41419628},{"atb":[[32,6.46],[80,2.53],[21,13.34]],"id":41419659},{"atb":[[18.5,0],[11,0],[8.4,0]],"id":41419595},{"atb":[[32,0],[80,0],[21,0]],"id":41419608},{"atb":[[17,0],[12,0],[29,0]],"id":41419606},{"atb":[[10,0],[25,0],[15,0]],"id":41419604},{"atb":[[16.5,0],[46,0],[23,0]],"id":41419602},{"atb":[[19.5,0],[12,0],[8.8,0]],"id":41419585},{"atb":[[16,13.34],[11,26.69],[27,7.7]],"id":41419616},{"atb":[[18.5,11.44],[11,20.02],[8.4,36.07]],"id":41419614},{"atb":[[19.5,0],[12,0],[8.8,0]],"id":41419592},{"atb":[[350,0.57],[200,1],[100,2.69]],"id":41419656},{"atb":[[5.1,0],[9.2,0],[6.2,0]],"id":41419590},{"atb":[[16.5,17.22],[46,4.45],[23,9.09]],"id":41419654},{"atb":[[19.5,0],[12,0],[8.8,0]],"id":41419588},{"atb":[[600,0.44],[700,0.28],[850,0.23]],"id":41419652},{"atb":[[16,0],[44,0],[22,0]],"id":41419586},{"atb":[[16.5,0],[46,0],[23,0]],"id":41419600},{"atb":[[7.2,32.29],[5.1,48.83],[4.1,86.12]],"id":41419631},{"atb":[[18.5,11.44],[11,20.02],[8.4,36.07]],"id":41419629},{"atb":[[7.4,31.28],[5.2,47.67],[4.2,83.43]],"id":41419627},{"atb":[[16,0],[11,0],[27,0]],"id":41419594},{"atb":[[350,0.57],[200,1],[100,2.69]],"id":41419658}],"con":true,"img":false}]}
{"op":"mcm","clk":"5352586064","pt":1646194224128,"mc":[{"id":"1.195503861","rc":[{"atb":[[16.5,0],[11.5,0],[28,0]],"id":41419609},{"atb":[[42,0],[21,0],[15.5,0]],"id":41419615},{"atb":[[19.5,0],[12,0],[8.8,0]],"id":41419613},{"atb":[[7.2,0],[9.2,0],[15.5,0]],"id":41419611},{"atb":[[600,0],[700,0],[850,0]],"id":41419657},{"atb":[[640,0],[390,0],[490,0]],"id":41435525},{"atb":[[130,0],[65,0],[280,0]],"id":41419653},{"atb":[[560,0],[710,0],[460,0]],"id":41435527},{"atb":[[130,0],[65,0],[280,0]],"id":41419651},{"atb":[[4.8,0],[8.6,0],[5.8,0]],"id":41419618},{"atb":[[10,0],[5.5,0],[7,0]],"id":41419630},{"atb":[[7.2,0],[5.1,0],[4.1,0]],"id":41419628},{"atb":[[32,0],[80,0],[21,0]],"id":41419659},{"atb":[[16,0],[11,0],[27,0]],"id":41419616},{"atb":[[18.5,0],[11,0],[8.4,0]],"id":41419614},{"atb":[[350,0],[200,0],[100,0]],"id":41419656},{"atb":[[16.5,0],[46,0],[23,0]],"id":41419654},{"atb":[[600,0],[700,0],[850,0]],"id":41419652},{"atb":[[7.2,0],[5.1,0],[4.1,0]],"id":41419631},{"atb":[[18.5,0],[11,0],[8.4,0]],"id":41419629},{"atb":[[7.4,0],[5.2,0],[4.2,0]],"id":41419627},{"atb":[[350,0],[200,0],[100,0]],"id":41419658}],"con":true,"img":false}]}
{"op":"mcm","clk":"5352586491","pt":1646194236690,"mc":[{"id":"1.195503861","rc":[{"atb":[[32,6.46],[18,11.77],[13,22.24]],"id":41419609},{"atb":[[32,6.46],[18,11.77],[13,22.24]],"id":41419607},{"atb":[[150,1.79],[400,0.5],[250,0.8]],"id":28546950},{"atb":[[17.5,16.17],[50,4.08],[25,8.34]],"id":41419615},{"atb":[[9.2,32.55],[21,10.01],[13,16.68]],"id":41419613},{"atb":[[9,25.02],[7,44.49],[15,14.3]],"id":41419611},{"atb":[[600,0.44],[700,0.28],[850,0.23]],"id":41419657},{"atb":[[17.5,16.17],[50,4.08],[25,8.34]],"id":41419593},{"atb":[[610,0.32],[760,0.26],[510,0.52]],"id":41435525},{"atb":[[150,1.79],[400,0.5],[250,0.8]],"id":41419653},{"atb":[[590,0.45],[690,0.28],[840,0.24]],"id":41435527},{"atb":[[150,1.79],[400,0.5],[250,0.8]],"id":41419651},{"atb":[[16.5,12.91],[11.5,25.42],[28,7.41]],"id":41419587},{"atb":[[9,25.02],[5,66.74],[6,40.04]],"id":41419618},{"atb":[[40,5.13],[100,2.02],[25,11.12]],"id":41419601},{"atb":[[17,16.68],[48,4.26],[24,8.7]],"id":41419599},{"atb":[[5.1,65.11],[9.2,24.42],[6.2,38.5]],"id":41419630},{"atb":[[9,25.02],[5,66.74],[6,40.04]],"id":41419597},{"atb":[[320,0.62],[170,1.18],[85,3.17]],"id":28546943},{"atb":[[3.95,90.5],[6.8,34.52],[4.9,51.34]],"id":41419628},{"atb":[[32,6.46],[80,2.53],[21,13.34]],"id":41419659},{"atb":[[24,8.7],[9.8,30.34],[14.5,14.83]],"id":41419595},{"atb":[[38,5.41],[95,2.13],[24,11.6]],"id":41419608},{"atb":[[17,12.51],[12,24.27],[29,7.14]],"id":41419606},{"atb":[[10.5,28.1],[26,8],[15.5,13.8]],"id":41419604},{"atb":[[18,15.7],[26,8],[55,3.7]],"id":41419602},{"atb":[[9,33.37],[20,10.53],[12.5,17.41]],"id":41419585},{"atb":[[17.5,12.13],[12.5,23.21],[30,6.9]],"id":41419616},{"atb":[[24,8.7],[9.8,30.34],[14.5,14.83]],"id":41419614},{"atb":[[330,0.6],[230,1.16],[480,0.42]],"id":41419656},{"atb":[[9.2,32.55],[21,10.01],[13,16.68]],"id":41419592},{"atb":[[16,17.8],[44,4.65],[22,9.53]],"id":41419654},{"atb":[[5.6,43.53],[4.6,74.16],[8.2,27.81]],"id":41419590},{"atb":[[600,0.44],[700,0.28],[850,0.23]],"id":41419652},{"atb":[[9,33.37],[20,10.53],[12.5,17.41]],"id":41419588},{"atb":[[16.5,17.22],[46,4.45],[23,9.09]],"id":41419586},{"atb":[[18,15.7],[26,8],[55,3.7]],"id":41419600},{"atb":[[3.95,90.5],[6.8,34.52],[4.9,51.34]],"id":41419631},{"atb":[[18,11.77],[10.5,21.07],[8.2,37.08]],"id":41419629},{"atb":[[4.3,60.67],[5.8,41.71],[3.65,100.74]],"id":41419627},{"atb":[[330,0.6],[230,1.16],[480,0.42]],"id":41419658},{"atb":[[17.5,12.13],[12.5,23.21],[30,6.9]],"id":41419594}],"con":true,"img":false}]}
{"op":"mcm","clk":"5352597956","pt":1646194616031,"mc":[{"id":"1.195503861","rc":[{"atb":[[32,0],[18,0],[13,0]],"id":41419607},{"atb":[[150,0],[400,0],[250,0]],"id":28546950},{"atb":[[17.5,0],[50,0],[25,0]],"id":41419593},{"atb":[[16.5,0],[11.5,0],[28,0]],"id":41419587},{"atb":[[40,0],[100,0],[25,0]],"id":41419601},{"atb":[[17,0],[48,0],[24,0]],"id":41419599},{"atb":[[9,0],[5,0],[6,0]],"id":41419597},{"atb":[[320,0],[170,0],[85,0]],"id":28546943},{"atb":[[24,0],[9.8,0],[14.5,0]],"id":41419595},{"atb":[[38,0],[95,0],[24,0]],"id":41419608},{"atb":[[17,0],[12,0],[29,0]],"id":41419606},{"atb":[[10.5,0],[26,0],[15.5,0]],"id":41419604},{"atb":[[18,0],[26,0],[55,0]],"id":41419602},{"atb":[[9,0],[20,0],[12.5,0]],"id":41419585},{"atb":[[9.2,0],[21,0],[13,0]],"id":41419592},{"atb":[[5.6,0],[4.6,0],[8.2,0]],"id":41419590},{"atb":[[9,0],[20,0],[12.5,0]],"id":41419588},{"atb":[[16.5,0],[46,0],[23,0]],"id":41419586},{"atb":[[18,0],[26,0],[55,0]],"id":41419600},{"atb":[[17.5,0],[12.5,0],[30,0]],"id":41419594}],"con":true,"img":false}]}
{"op":"mcm","clk":"5352597963","pt":1646194616135,"mc":[{"id":"1.195503861","rc":[{"atb":[[32,0],[18,0],[13,0]],"id":41419609},{"atb":[[17.5,0],[50,0],[25,0]],"id":41419615},{"atb":[[9.2,0],[21,0],[13,0]],"id":41419613},{"atb":[[9,0],[7,0],[15,0]],"id":41419611},{"atb":[[600,0],[700,0],[850,0]],"id":41419657},{"atb":[[610,0],[760,0],[510,0]],"id":41435525},{"atb":[[150,0],[400,0],[250,0]],"id":41419653},{"atb":[[590,0],[690,0],[840,0]],"id":41435527},{"atb":[[150,0],[400,0],[250,0]],"id":41419651},{"atb":[[9,0],[5,0],[6,0]],"id":41419618},{"atb":[[5.1,0],[9.2,0],[6.2,0]],"id":41419630},{"atb":[[3.95,0],[6.8,0],[4.9,0]],"id":41419628},{"atb":[[32,0],[80,0],[21,0]],"id":41419659},{"atb":[[17.5,0],[12.5,0],[30,0]],"id":41419616},{"atb":[[24,0],[9.8,0],[14.5,0]],"id":41419614},{"atb":[[330,0],[230,0],[480,0]],"id":41419656},{"atb":[[16,0],[44,0],[22,0]],"id":41419654},{"atb":[[600,0],[700,0],[850,0]],"id":41419652},{"atb":[[3.95,0],[6.8,0],[4.9,0]],"id":41419631},{"atb":[[18,0],[10.5,0],[8.2,0]],"id":41419629},{"atb":[[4.3,0],[5.8,0],[3.65,0]],"id":41419627},{"atb":[[330,0],[230,0],[480,0]],"id":41419658}],"con":true,"img":false}]}
{"op":"mcm","clk":"5352598363","pt":1646194631252,"mc":[{"id":"1.195503861","rc":[{"atb":[[32,6.46],[18,11.77],[13,22.24]],"id":41419609},{"atb":[[32,6.46],[18,11.77],[13,22.24]],"id":41419607},{"atb":[[150,1.79],[400,0.5],[250,0.8]],"id":28546950},{"atb":[[17.5,16.17],[50,4.08],[25,8.34]],"id":41419615},{"atb":[[9.2,32.55],[21,10.01],[13,16.68]],"id":41419613},{"atb":[[9,25.02],[7,44.49],[15,14.3]],"id":41419611},{"atb":[[600,0.44],[700,0.28],[850,0.23]],"id":41419657},{"atb":[[17.5,16.17],[50,4.08],[25,8.34]],"id":41419593},{"atb":[[610,0.32],[760,0.26],[510,0.52]],"id":41435525},{"atb":[[150,1.79],[400,0.5],[250,0.8]],"id":41419653},{"atb":[[590,0.45],[690,0.28],[840,0.24]],"id":41435527},{"atb":[[150,1.79],[400,0.5],[250,0.8]],"id":41419651},{"atb":[[16.5,12.91],[11.5,25.42],[28,7.41]],"id":41419587},{"atb":[[9,25.02],[5,66.74],[6,40.04]],"id":41419618},{"atb":[[40,5.13],[100,2.02],[25,11.12]],"id":41419601},{"atb":[[17,16.68],[48,4.26],[24,8.7]],"id":41419599},{"atb":[[5.1,65.11],[9.2,24.42],[6.2,38.5]],"id":41419630},{"atb":[[9,25.02],[5,66.74],[6,40.04]],"id":41419597},{"atb":[[320,0.62],[170,1.18],[85,3.17]],"id":28546943},{"atb":[[3.95,90.5],[6.8,34.52],[4.9,51.34]],"id":41419628},{"atb":[[32,6.46],[80,2.53],[21,13.34]],"id":41419659},{"atb":[[24,8.7],[9.8,30.34],[14.5,14.83]],"id":41419595},{"atb":[[38,5.41],[95,2.13],[24,11.6]],"id":41419608},{"atb":[[17,12.51],[12,24.27],[29,7.14]],"id":41419606},{"atb":[[10.5,28.1],[26,8],[15.5,13.8]],"id":41419604},{"atb":[[18,15.7],[26,8],[55,3.7]],"id":41419602},{"atb":[[9,33.37],[20,10.53],[12.5,17.41]],"id":41419585},{"atb":[[17.5,12.13],[12.5,23.21],[30,6.9]],"id":41419616},{"atb":[[24,8.7],[9.8,30.34],[14.5,14.83]],"id":41419614},{"atb":[[330,0.6],[230,1.16],[480,0.42]],"id":41419656},{"atb":[[9.2,32.55],[21,10.01],[13,16.68]],"id":41419592},{"atb":[[16,17.8],[44,4.65],[22,9.53]],"id":41419654},{"atb":[[5.6,43.53],[4.6,74.16],[8.2,27.81]],"id":41419590},{"atb":[[600,0.44],[700,0.28],[850,0.23]],"id":41419652},{"atb":[[9,33.37],[20,10.53],[12.5,17.41]],"id":41419588},{"atb":[[16.5,17.22],[46,4.45],[23,9.09]],"id":41419586},{"atb":[[18,15.7],[26,8],[55,3.7]],"id":41419600},{"atb":[[3.95,90.5],[6.8,34.52],[4.9,51.34]],"id":41419631},{"atb":[[18,11.77],[10.5,21.07],[8.2,37.08]],"id":41419629},{"atb":[[4.3,60.67],[5.8,41.71],[3.65,100.74]],"id":41419627},{"atb":[[330,0.6],[230,1.16],[480,0.42]],"id":41419658},{"atb":[[17.5,12.13],[12.5,23.21],[30,6.9]],"id":41419594}],"con":true,"img":false}]}
{"op":"mcm","clk":"5352601741","pt":1646194734568,"mc":[{"id":"1.195503861","rc":[{"atb":[[32,0],[18,0],[13,0]],"id":41419609},{"atb":[[32,0],[18,0],[13,0]],"id":41419607},{"atb":[[150,0],[400,0],[250,0]],"id":28546950},{"atb":[[17.5,0],[50,0],[25,0]],"id":41419615},{"atb":[[9.2,0],[21,0],[13,0]],"id":41419613},{"atb":[[9,0],[7,0],[15,0]],"id":41419611},{"atb":[[17.5,0],[50,0],[25,0]],"id":41419593},{"atb":[[600,0],[700,0],[850,0]],"id":41419657},{"atb":[[610,0],[760,0],[510,0]],"id":41435525},{"atb":[[150,0],[400,0],[250,0]],"id":41419653},{"atb":[[590,0],[690,0],[840,0]],"id":41435527},{"atb":[[150,0],[400,0],[250,0]],"id":41419651},{"atb":[[16.5,0],[11.5,0],[28,0]],"id":41419587},{"atb":[[9,0],[5,0],[6,0]],"id":41419618},{"atb":[[40,0],[100,0],[25,0]],"id":41419601},{"atb":[[17,0],[48,0],[24,0]],"id":41419599},{"atb":[[5.1,0],[9.2,0],[6.2,0]],"id":41419630},{"atb":[[9,0],[5,0],[6,0]],"id":41419597},{"atb":[[320,0],[170,0],[85,0]],"id":28546943},{"atb":[[3.95,0],[6.8,0],[4.9,0]],"id":41419628},{"atb":[[24,0],[9.8,0],[14.5,0]],"id":41419595},{"atb":[[32,0],[80,0],[21,0]],"id":41419659},{"atb":[[38,0],[95,0],[24,0]],"id":41419608},{"atb":[[17,0],[12,0],[29,0]],"id":41419606},{"atb":[[10.5,0],[26,0],[15.5,0]],"id":41419604},{"atb":[[18,0],[26,0],[55,0]],"id":41419602},{"atb":[[9,0],[20,0],[12.5,0]],"id":41419585},{"atb":[[17.5,0],[12.5,0],[30,0]],"id":41419616},{"atb":[[24,0],[9.8,0],[14.5,0]],"id":41419614},{"atb":[[330,0],[230,0],[480,0]],"id":41419656},{"atb":[[9.2,0],[21,0],[13,0]],"id":41419592},{"atb":[[16,0],[44,0],[22,0]],"id":41419654},{"atb":[[5.6,0],[4.6,0],[8.2,0]],"id":41419590},{"atb":[[600,0],[700,0],[850,0]],"id":41419652},{"atb":[[9,0],[20,0],[12.5,0]],"id":41419588},{"atb":[[16.5,0],[46,0],[23,0]],"id":41419586},{"atb":[[18,0],[26,0],[55,0]],"id":41419600},{"atb":[[3.95,0],[6.8,0],[4.9,0]],"id":41419631},{"atb":[[18,0],[10.5,0],[8.2,0]],"id":41419629},{"atb":[[4.3,0],[5.8,0],[3.65,0]],"id":41419627},{"atb":[[330,0],[230,0],[480,0]],"id":41419658},{"atb":[[17.5,0],[12.5,0],[30,0]],"id":41419594}],"con":true,"img":false}]}
{"op":"mcm","clk":"5352602393","pt":1646194751778,"mc":[{"id":"1.195503861","rc":[{"atb":[[34,6.06],[18.5,11.44],[13.5,21.35]],"id":41419609},{"atb":[[34,6.06],[18.5,11.44],[13.5,21.35]],"id":41419607},{"atb":[[150,1.79],[400,0.5],[250,0.8]],"id":28546950},{"atb":[[17.5,16.17],[50,4.08],[25,8.34]],"id":41419615},{"atb":[[9.2,32.55],[21,10.01],[13,16.68]],"id":41419613},{"atb":[[7.2,43.06],[9.2,24.42],[15.5,13.8]],"id":41419611},{"atb":[[600,0.44],[700,0.28],[850,0.23]],"id":41419657},{"atb":[[17.5,16.17],[50,4.08],[25,8.34]],"id":41419593},{"atb":[[550,0.48],[650,0.3],[800,0.25]],"id":41435525},{"atb":[[150,1.79],[400,0.5],[250,0.8]],"id":41419653},{"atb":[[600,0.44],[700,0.28],[850,0.23]],"id":41435527},{"atb":[[150,1.79],[400,0.5],[250,0.8]],"id":41419651},{"atb":[[16.5,12.91],[11.5,25.42],[28,7.41]],"id":41419587},{"atb":[[9,25.02],[5,66.74],[6,40.04]],"id":41419618},{"atb":[[42,4.88],[26,10.67],[110,1.83]],"id":41419601},{"atb":[[17,16.68],[48,4.26],[24,8.7]],"id":41419599},{"atb":[[6.4,37.08],[5.2,63.56],[9.4,23.83]],"id":41419630},{"atb":[[9,25.02],[5,66.74],[6,40.04]],"id":41419597},{"atb":[[320,0.62],[170,1.18],[85,3.17]],"id":28546943},{"atb":[[3.95,90.5],[6.8,34.52],[4.9,51.34]],"id":41419628},{"atb":[[75,2.7],[20,14.05],[30,6.9]],"id":41419659},{"atb":[[24,8.7],[9.8,30.34],[14.5,14.83]],"id":41419595},{"atb":[[40,5.13],[100,2.02],[25,11.12]],"id":41419608},{"atb":[[17,12.51],[12,24.27],[29,7.14]],"id":41419606},{"atb":[[10.5,28.1],[26,8],[15.5,13.8]],"id":41419604},{"atb":[[18,15.7],[26,8],[55,3.7]],"id":41419602},{"atb":[[9,33.37],[20,10.53],[12.5,17.41]],"id":41419585},{"atb":[[32,6.46],[18,11.77],[13,22.24]],"id":41419616},{"atb":[[24,8.7],[9.8,30.34],[14.5,14.83]],"id":41419614},{"atb":[[330,0.6],[230,1.16],[480,0.42]],"id":41419656},{"atb":[[9.2,32.55],[21,10.01],[13,16.68]],"id":41419592},{"atb":[[5.6,43.53],[4.6,74.16],[8.2,27.81]],"id":41419590},{"atb":[[16,17.8],[44,4.65],[22,9.53]],"id":41419654},{"atb":[[9,33.37],[20,10.53],[12.5,17.41]],"id":41419588},{"atb":[[600,0.44],[700,0.28],[850,0.23]],"id":41419652},{"atb":[[16.5,17.22],[46,4.45],[23,9.09]],"id":41419586},{"atb":[[18,15.7],[26,8],[55,3.7]],"id":41419600},{"atb":[[3.95,90.5],[6.8,34.52],[4.9,51.34]],"id":41419631},{"atb":[[8,38.14],[17.5,12.13],[10,22.24]],"id":41419629},{"atb":[[4.3,60.67],[5.8,41.71],[3.65,100.74]],"id":41419627},{"atb":[[330,0.6],[230,1.16],[480,0.42]],"id":41419658},{"atb":[[32,6.46],[18,11.77],[13,22.24]],"id":41419594}],"con":true,"img":false}]}
{"op":"mcm","clk":"5352823524","pt":1646201802742,"mc":[{"id":"1.195503861","marketDefinition":{"bspMarket":false,"turnInPlayEnabled":false,"persistenceEnabled":false,"marketBaseRate":7.0,"eventId":"31272499","eventTypeId":"4339","numberOfWinners":1,"bettingType":"ODDS","marketType":"EXACTA","marketTime":"2022-03-02T08:48:00.000Z","suspendTime":"2022-03-02T08:48:00.000Z","bspReconciled":false,"complete":true,"inPlay":false,"crossMatching":false,"runnersVoidable":false,"numberOfActiveRunners":42,"betDelay":0,"status":"OPEN","runners":[{"status":"ACTIVE","sortPriority":1,"id":41419585,"name":"1 - 2"},{"status":"ACTIVE","sortPriority":2,"id":41419586,"name":"1 - 3"},{"status":"ACTIVE","sortPriority":3,"id":41419587,"name":"1 - 4"},{"status":"ACTIVE","sortPriority":4,"id":41419588,"name":"1 - 5"},{"status":"ACTIVE","sortPriority":5,"id":41419590,"name":"1 - 7"},{"status":"ACTIVE","sortPriority":6,"id":28546943,"name":"1 - 9"},{"status":"ACTIVE","sortPriority":7,"id":41419592,"name":"2 - 1"},{"status":"ACTIVE","sortPriority":8,"id":41419593,"name":"2 - 3"},{"status":"ACTIVE","sortPriority":9,"id":41419594,"name":"2 - 4"},{"status":"ACTIVE","sortPriority":10,"id":41419595,"name":"2 - 5"},{"status":"ACTIVE","sortPriority":11,"id":41419597,"name":"2 - 7"},{"status":"ACTIVE","sortPriority":12,"id":41419651,"name":"2 - 9"},{"status":"ACTIVE","sortPriority":13,"id":41419599,"name":"3 - 1"},{"status":"ACTIVE","sortPriority":14,"id":41419600,"name":"3 - 2"},{"status":"ACTIVE","sortPriority":15,"id":41419601,"name":"3 - 4"},{"status":"ACTIVE","sortPriority":16,"id":41419602,"name":"3 - 5"},{"status":"ACTIVE","sortPriority":17,"id":41419604,"name":"3 - 7"},{"status":"ACTIVE","sortPriority":18,"id":41419652,"name":"3 - 9"},{"status":"ACTIVE","sortPriority":19,"id":41419606,"name":"4 - 1"},{"status":"ACTIVE","sortPriority":20,"id":41419607,"name":"4 - 2"},{"status":"ACTIVE","sortPriority":21,"id":41419608,"name":"4 - 3"},{"status":"ACTIVE","sortPriority":22,"id":41419609,"name":"4 - 5"},{"status":"ACTIVE","sortPriority":23,"id":41419611,"name":"4 - 7"},{"status":"ACTIVE","sortPriority":24,"id":41435525,"name":"4 - 9"},{"status":"ACTIVE","sortPriority":25,"id":41419613,"name":"5 - 1"},{"status":"ACTIVE","sortPriority":26,"id":41419614,"name":"5 - 2"},{"status":"ACTIVE","sortPriority":27,"id":41419615,"name":"5 - 3"},{"status":"ACTIVE","sortPriority":28,"id":41419616,"name":"5 - 4"},{"status":"ACTIVE","sortPriority":29,"id":41419618,"name":"5 - 7"},{"status":"ACTIVE","sortPriority":30,"id":41419653,"name":"5 - 9"},{"status":"ACTIVE","sortPriority":31,"id":41419627,"name":"7 - 1"},{"status":"ACTIVE","sortPriority":32,"id":41419628,"name":"7 - 2"},{"status":"ACTIVE","sortPriority":33,"id":41419629,"name":"7 - 3"},{"status":"ACTIVE","sortPriority":34,"id":41419630,"name":"7 - 4"},{"status":"ACTIVE","sortPriority":35,"id":41419631,"name":"7 - 5"},{"status":"ACTIVE","sortPriority":36,"id":41419654,"name":"7 - 9"},{"status":"ACTIVE","sortPriority":37,"id":28546950,"name":"9 - 1"},{"status":"ACTIVE","sortPriority":38,"id":41419656,"name":"9 - 2"},{"status":"ACTIVE","sortPriority":39,"id":41419657,"name":"9 - 3"},{"status":"ACTIVE","sortPriority":40,"id":41435527,"name":"9 - 4"},{"status":"ACTIVE","sortPriority":41,"id":41419658,"name":"9 - 5"},{"status":"ACTIVE","sortPriority":42,"id":41419659,"name":"9 - 7"}],"regulators":["MR_INT"],"venue":"Rockhampton","countryCode":"AU","discountAllowed":true,"timezone":"Australia/Queensland","openDate":"2022-03-02T08:28:00.000Z","version":4382599164,"name":"Exacta","eventName":"Rockhampton (AUS) 2nd Mar"},"rc":[{"atb":[[34,6.06],[18.5,11.43],[13.5,21.34]],"id":41419609},{"atb":[[34,6.06],[18.5,11.43],[13.5,21.34]],"id":41419607},{"atb":[[150,1.79],[400,0.5],[250,0.8]],"id":28546950},{"atb":[[17.5,16.17],[50,4.08],[25,8.33]],"id":41419615},{"atb":[[9.2,32.54],[21,10],[13,16.68]],"id":41419613},{"atb":[[7.2,43.04],[9.2,24.41],[15.5,13.8]],"id":41419611},{"atb":[[17.5,16.17],[50,4.08],[25,8.33]],"id":41419593},{"atb":[[600,0.44],[700,0.28],[850,0.23]],"id":41419657},{"atb":[[550,0.48],[650,0.3],[800,0.25]],"id":41435525},{"atb":[[150,1.79],[400,0.5],[250,0.8]],"id":41419653},{"atb":[[600,0.44],[700,0.28],[850,0.23]],"id":41435527},{"atb":[[16.5,12.91],[11.5,25.41],[28,7.41]],"id":41419587},{"atb":[[150,1.79],[400,0.5],[250,0.8]],"id":41419651},{"atb":[[9,25.01],[5,66.72],[6,40.03]],"id":41419618},{"atb":[[42,4.88],[26,10.67],[110,1.83]],"id":41419601},{"atb":[[17,16.68],[48,4.25],[24,8.7]],"id":41419599},{"atb":[[6.4,37.06],[5.2,63.54],[9.4,23.82]],"id":41419630},{"atb":[[9,25.01],[5,66.72],[6,40.03]],"id":41419597},{"atb":[[320,0.62],[170,1.18],[85,3.17]],"id":28546943},{"atb":[[3.95,90.46],[6.8,34.51],[4.9,51.32]],"id":41419628},{"atb":[[24,8.7],[9.8,30.33],[14.5,14.82]],"id":41419595},{"atb":[[75,2.7],[20,14.04],[30,6.9]],"id":41419659},{"atb":[[40,5.13],[100,2.02],[25,11.12]],"id":41419608},{"atb":[[17,12.5],[12,24.26],[29,7.14]],"id":41419606},{"atb":[[10.5,28.09],[26,8],[15.5,13.8]],"id":41419604},{"atb":[[18,15.69],[26,8],[55,3.7]],"id":41419602},{"atb":[[9,33.36],[20,10.53],[12.5,17.4]],"id":41419585},{"atb":[[32,6.45],[18,11.77],[13,22.23]],"id":41419616},{"atb":[[24,8.7],[9.8,30.33],[14.5,14.82]],"id":41419614},{"atb":[[9.2,32.54],[21,10],[13,16.68]],"id":41419592},{"atb":[[330,0.6],[230,1.16],[480,0.42]],"id":41419656},{"atb":[[5.6,43.51],[4.6,74.13],[8.2,27.8]],"id":41419590},{"atb":[[16,17.79],[44,4.65],[22,9.53]],"id":41419654},{"atb":[[9,33.36],[20,10.53],[12.5,17.4]],"id":41419588},{"atb":[[600,0.44],[700,0.28],[850,0.23]],"id":41419652},{"atb":[[16.5,17.22],[46,4.44],[23,9.09]],"id":41419586},{"atb":[[18,15.69],[26,8],[55,3.7]],"id":41419600},{"atb":[[3.95,90.46],[6.8,34.51],[4.9,51.32]],"id":41419631},{"atb":[[8,38.12],[17.5,12.13],[10,22.23]],"id":41419629},{"atb":[[4.3,60.65],[5.8,41.7],[3.65,100.7]],"id":41419627},{"atb":[[330,0.6],[230,1.16],[480,0.42]],"id":41419658},{"atb":[[32,6.45],[18,11.77],[13,22.23]],"id":41419594}],"con":true,"img":true}]}
{"op":"mcm","clk":"5352884618","pt":1646203680380,"mc":[{"id":"1.195503861","rc":[{"atb":[[34,6.06],[18.5,11.43],[13.5,21.34]],"id":41419609},{"atb":[[34,6.06],[18.5,11.43],[13.5,21.34]],"id":41419607},{"atb":[[150,1.79],[400,0.5],[250,0.8]],"id":28546950},{"atb":[[17.5,16.17],[36,3.27],[46,2.73],[50,4.08],[25,8.33]],"id":41419615},{"atb":[[9.2,32.54],[21,10],[22,3.27],[13,16.68],[27,2.73]],"id":41419613},{"atb":[[7.2,43.04],[9.2,24.41],[15.5,13.8]],"id":41419611},{"atb":[[17.5,16.17],[50,4.08],[25,8.33]],"id":41419593},{"atb":[[600,0.44],[700,0.28]],"id":41419657},{"atb":[[550,0.48],[650,0.3]],"id":41435525},{"atb":[[150,1.79],[80,2.73],[400,0.5],[55,3.27],[250,0.8]],"id":41419653},{"atb":[[600,0.44],[700,0.28]],"id":41435527},{"atb":[[16.5,12.91],[11.5,25.41],[28,7.41]],"id":41419587},{"atb":[[150,1.79],[400,0.5],[250,0.8]],"id":41419651},{"atb":[[9,25.01],[5,66.72],[6,40.03]],"id":41419618},{"atb":[[42,4.88],[26,10.67],[110,1.83]],"id":41419601},{"atb":[[17,16.68],[48,4.25],[24,8.7]],"id":41419599},{"atb":[[6.4,39.79],[5.2,63.54],[5.7,3.27],[9.4,23.82]],"id":41419630},{"atb":[[9,25.01],[5,66.72],[6,40.03]],"id":41419597},{"atb":[[320,0.62],[170,1.18],[85,3.17]],"id":28546943},{"atb":[[3.95,90.46],[6.8,34.51],[4.9,51.32]],"id":41419628},{"atb":[[24,8.7],[9.8,30.33],[14.5,14.82]],"id":41419595},{"atb":[[75,2.7],[20,14.04],[30,6.9]],"id":41419659},{"atb":[[65,2.73],[40,5.13],[46,3.27],[100,2.02],[25,11.12]],"id":41419608},{"atb":[[17,12.5],[12,24.26],[29,7.14]],"id":41419606},{"atb":[[40,2.73],[10.5,28.09],[26,8],[30,3.27],[15.5,13.8]],"id":41419604},{"atb":[[18,15.69],[26,8],[55,3.7]],"id":41419602},{"atb":[[9,33.36],[20,10.53],[12.5,17.4]],"id":41419585},{"atb":[[32,6.45],[18,11.77],[13,22.23]],"id":41419616},{"atb":[[24,8.7],[9.8,30.33],[14.5,14.82]],"id":41419614},{"atb":[[9.2,32.54],[20,3.27],[21,10],[25,2.73],[13,16.68]],"id":41419592},{"atb":[[330,0.6],[230,1.16],[480,0.42]],"id":41419656},{"atb":[[5.6,43.51],[4.6,74.13],[8.2,27.8]],"id":41419590},{"atb":[[16,17.79],[44,4.65],[22,9.53]],"id":41419654},{"atb":[[9,33.36],[20,10.53],[12.5,17.4]],"id":41419588},{"atb":[[600,0.44],[700,0.28]],"id":41419652},{"atb":[[16.5,17.22],[46,4.44],[23,9.09]],"id":41419586},{"atb":[[18,15.69],[26,8],[55,3.7]],"id":41419600},{"atb":[[3.95,90.46],[6.8,34.51],[4.9,51.32]],"id":41419631},{"atb":[[8,38.12],[17.5,12.13],[10,22.23]],"id":41419629},{"atb":[[4.3,60.65],[5.8,41.7],[3.65,100.7]],"id":41419627},{"atb":[[330,0.6],[160,2.73],[110,3.27],[230,1.16],[480,0.42]],"id":41419658},{"atb":[[32,6.45],[18,11.77],[13,22.23]],"id":41419594}],"con":true,"img":false}]}
{"op":"mcm","clk":"5352884621","pt":1646203680484,"mc":[{"id":"1.195503861","rc":[{"atb":[[40,2.73],[30,3.27]],"id":41419609},{"atb":[[38,2.73],[29,3.27]],"id":41419607},{"atb":[[150,4.52],[100,3.27]],"id":28546950},{"atb":[[18.5,3.27],[22,2.73]],"id":41419611},{"atb":[[34,3.27],[44,2.73]],"id":41419593},{"atb":[[200,3.27],[250,2.73]],"id":41419657},{"atb":[[80,3.27],[110,2.73]],"id":41435525},{"atb":[[140,3.27],[190,2.73]],"id":41435527},{"atb":[[21,3.27],[26,2.73]],"id":41419587},{"atb":[[75,2.73],[50,3.27]],"id":41419651},{"atb":[[13,3.27],[15.5,2.73]],"id":41419618},{"atb":[[80,2.73],[55,3.27]],"id":41419601},{"atb":[[44,3.27],[60,2.73]],"id":41419599},{"atb":[[11.5,3.27],[14,2.73]],"id":41419597},{"atb":[[70,2.73],[48,3.27]],"id":28546943},{"atb":[[6,3.27],[7,2.73]],"id":41419628},{"atb":[[22,3.27],[27,2.73]],"id":41419595},{"atb":[[70,3.27],[95,2.73]],"id":41419659},{"atb":[[38,2.73],[29,10.42]],"id":41419606},{"atb":[[65,2.73],[46,3.27]],"id":41419602},{"atb":[[19.5,3.27],[24,2.73]],"id":41419585},{"atb":[[36,2.73],[28,3.27]],"id":41419616},{"atb":[[23,3.27],[28,2.73]],"id":41419614},{"atb":[[150,2.73],[100,3.27]],"id":41419656},{"atb":[[10,3.27],[12.5,2.73]],"id":41419590},{"atb":[[24,3.27],[29,2.73]],"id":41419654},{"atb":[[20,13.8],[25,2.73]],"id":41419588},{"atb":[[130,3.27],[180,2.73]],"id":41419652},{"atb":[[65,2.73],[46,3.27]],"id":41419600},{"atb":[[7.2,3.27],[8.2,2.73]],"id":41419631},{"atb":[[16,2.73],[13.5,3.27]],"id":41419629},{"atb":[[6.4,2.73],[5.7,3.27]],"id":41419627},{"atb":[[20,3.27],[25,2.73]],"id":41419594}],"con":true,"img":false}]}
{"op":"mcm","clk":"5352884627","pt":1646203680791,"mc":[{"id":"1.195503861","rc":[{"atb":[[40,2.73],[30,3.27]],"id":41419586}],"con":true,"img":false}]}
{"op":"mcm","clk":"5352917965","pt":1646204655536,"mc":[{"id":"1.195503861","rc":[{"atb":[[34,6.06],[18.5,11.43],[40,2.72],[13.5,21.34],[30,3.27]],"id":41419609},{"atb":[[34,6.06],[18.5,11.43],[38,2.72],[13.5,21.34],[29,3.27]],"id":41419607},{"atb":[[150,4.51],[400,0.5],[100,3.27],[250,0.8]],"id":28546950},{"atb":[[17.5,16.16],[36,3.27],[46,2.72],[50,4.08],[25,8.33]],"id":41419615},{"atb":[[9.2,32.53],[21,10],[22,3.27],[13,16.67],[27,2.72]],"id":41419613},{"atb":[[7.2,43.03],[18.5,3.27],[9.2,24.4],[22,2.72],[15.5,13.79]],"id":41419611},{"atb":[[600,0.44],[200,3.27],[250,2.72]],"id":41419657},{"atb":[[34,3.27],[17.5,16.16],[44,2.72],[50,4.08],[25,8.33]],"id":41419593},{"atb":[[550,0.48],[80,3.27],[110,2.72]],"id":41435525},{"atb":[[150,1.79],[80,2.72],[400,0.5],[55,3.27],[250,0.8]],"id":41419653},{"atb":[[140,3.27],[600,0.44],[190,2.72]],"id":41435527},{"atb":[[16.5,12.9],[21,0],[11.5,25.4],[26,0],[28,7.41]],"id":41419587},{"atb":[[150,1.79],[75,2.72],[400,0.5],[50,3.27],[250,0.8]],"id":41419651},{"atb":[[9,25.01],[5,66.7],[6,40.02],[13,3.27],[15.5,2.72]],"id":41419618},{"atb":[[80,2.72],[42,4.87],[26,10.67],[110,1.83],[55,3.27]],"id":41419601},{"atb":[[17,16.67],[44,3.27],[48,4.25],[24,8.7],[60,2.72]],"id":41419599},{"atb":[[6.4,39.78],[5.2,63.52],[5.7,3.27],[9.4,23.82]],"id":41419630},{"atb":[[9,25.01],[5,66.7],[11.5,3.27],[6,40.02],[14,2.72]],"id":41419597},{"atb":[[70,2.72],[320,0.62],[170,1.18],[85,3.17],[48,3.27]],"id":28546943},{"atb":[[3.95,90.44],[6.8,34.5],[6,3.27],[4.9,51.31],[7,2.72]],"id":41419628},{"atb":[[70,3.27],[75,2.7],[20,14.04],[95,2.72],[30,6.89]],"id":41419659},{"atb":[[22,3.27],[24,8.7],[9.8,30.32],[27,2.72],[14.5,14.82]],"id":41419595},{"atb":[[65,2.72],[40,5.13],[46,3.27],[100,2.01],[25,11.11]],"id":41419608},{"atb":[[17,12.5],[38,2.72],[12,24.25],[29,10.42]],"id":41419606},{"atb":[[40,2.72],[10.5,28.08],[26,8],[30,3.27],[15.5,13.79]],"id":41419604},{"atb":[[65,2.72],[18,15.69],[46,3.27],[26,8],[55,3.7]],"id":41419602},{"atb":[[9,33.35],[19.5,3.27],[20,10.52],[24,2.72],[12.5,17.4]],"id":41419585},{"atb":[[32,6.45],[36,2.72],[18,11.76],[13,22.23],[28,3.27]],"id":41419616},{"atb":[[23,3.27],[24,8.7],[9.8,30.32],[28,2.72],[14.5,14.82]],"id":41419614},{"atb":[[150,2.72],[330,0.6],[100,3.27],[230,1.16],[480,0.42]],"id":41419656},{"atb":[[20,3.27],[9.2,32.53],[21,10],[25,2.72],[13,16.67]],"id":41419592},{"atb":[[5.6,43.5],[10,3.27],[4.6,74.11],[8.2,27.79],[12.5,2.72]],"id":41419590},{"atb":[[16,17.78],[44,4.65],[22,9.53],[24,3.27],[29,2.72]],"id":41419654},{"atb":[[9,33.35],[20,13.8],[25,2.72],[12.5,17.4]],"id":41419588},{"atb":[[130,3.27],[600,0.44],[180,2.72]],"id":41419652},{"atb":[[16.5,17.21],[40,2.72],[46,4.44],[23,9.09],[30,3.27]],"id":41419586},{"atb":[[65,2.72],[18,15.69],[46,3.27],[26,8],[55,3.7]],"id":41419600},{"atb":[[7.2,3.27],[3.95,90.44],[8.2,2.72],[6.8,34.5],[4.9,51.31]],"id":41419631},{"atb":[[16,2.72],[8,38.11],[17.5,12.12],[10,22.23],[13.5,3.27]],"id":41419629},{"atb":[[4.3,60.63],[6.4,2.72],[5.8,41.69],[5.7,3.27],[3.65,100.68]],"id":41419627},{"atb":[[32,6.45],[18,11.76],[20,3.27],[25,2.72],[13,22.23]],"id":41419594},{"atb":[[330,0.6],[160,2.72],[110,3.27],[230,1.16],[480,0.42]],"id":41419658}],"con":true,"img":false}]}
{"op":"mcm","clk":"5352917976","pt":1646204655760,"mc":[{"id":"1.195503861","rc":[{"atb":[[6.4,37.05],[5.7,0]],"id":41419630}],"con":true,"img":false}]}
{"op":"mcm","clk":"5352917995","pt":1646204656117,"mc":[{"id":"1.195503861","rc":[{"atb":[[20,3.27],[25,2.72]],"id":41419587}],"con":true,"img":false}]}
{"op":"mcm","clk":"5352918013","pt":1646204656513,"mc":[{"id":"1.195503861","rc":[{"atb":[[5.8,3.27],[6.6,2.72]],"id":41419630}],"con":true,"img":false}]}
{"op":"mcm","clk":"5352918816","pt":1646204673377,"mc":[{"id":"1.195503861","rc":[{"atb":[[5.8,0],[6.6,0]],"id":41419630}],"con":true,"img":false}]}
{"op":"mcm","clk":"5352918847","pt":1646204674046,"mc":[{"id":"1.195503861","rc":[{"atb":[[6.4,39.78],[5.7,3.27]],"id":41419630}],"con":true,"img":false}]}
{"op":"mcm","clk":"5352944324","pt":1646205284304,"mc":[{"id":"1.195503861","rc":[{"atb":[[25,0]],"id":41419587}],"con":true,"img":false}]}
{"op":"mcm","clk":"5352944329","pt":1646205284406,"mc":[{"id":"1.195503861","rc":[{"atb":[[20,0]],"id":41419587}],"con":true,"img":false}]}
{"op":"mcm","clk":"5352944354","pt":1646205285127,"mc":[{"id":"1.195503861","rc":[{"atb":[[21,3.27],[26,2.72]],"id":41419587}],"con":true,"img":false}]}
{"op":"mcm","clk":"5352953568","pt":1646205521545,"mc":[{"id":"1.195503861","rc":[{"atb":[[38,0],[29,7.14]],"id":41419606}],"con":true,"img":false}]}
{"op":"mcm","clk":"5352953581","pt":1646205521855,"mc":[{"id":"1.195503861","rc":[{"atb":[[36,0],[28,0]],"id":41419616},{"atb":[[10,0],[12.5,0]],"id":41419590}],"con":true,"img":false}]}
{"op":"mcm","clk":"5352953601","pt":1646205522217,"mc":[{"id":"1.195503861","rc":[{"atb":[[36,2.72],[28,3.27]],"id":41419606}],"con":true,"img":false}]}
{"op":"mcm","clk":"5352953612","pt":1646205522523,"mc":[{"id":"1.195503861","rc":[{"atb":[[34,2.72],[27,3.27]],"id":41419616},{"atb":[[10.5,3.27],[13,2.72]],"id":41419590}],"con":true,"img":false}]}
{"op":"mcm","clk":"5352956336","pt":1646205606724,"mc":[{"id":"1.195503861","rc":[{"atb":[[34,0],[44,0]],"id":41419593}],"con":true,"img":false}]}
{"op":"mcm","clk":"5352956342","pt":1646205606827,"mc":[{"id":"1.195503861","rc":[{"atb":[[38,0],[29,0]],"id":41419607},{"atb":[[36,0],[46,0]],"id":41419615},{"atb":[[18.5,0],[22,0]],"id":41419611},{"atb":[[200,0],[250,0]],"id":41419657},{"atb":[[80,0],[55,0]],"id":41419653},{"atb":[[75,0],[50,0]],"id":41419651},{"atb":[[13,0],[15.5,0]],"id":41419618},{"atb":[[44,0],[60,0]],"id":41419599},{"atb":[[11.5,0],[14,0]],"id":41419597},{"atb":[[36,0],[28,0]],"id":41419606},{"atb":[[40,0],[30,0]],"id":41419604},{"atb":[[65,0],[46,0]],"id":41419602},{"atb":[[19.5,0],[24,0]],"id":41419585},{"atb":[[150,0],[100,0]],"id":41419656},{"atb":[[20,0],[25,0]],"id":41419592},{"atb":[[24,0],[29,0]],"id":41419654},{"atb":[[20,10.52],[25,0]],"id":41419588},{"atb":[[65,0],[46,0]],"id":41419600},{"atb":[[16,0],[13.5,0]],"id":41419629},{"atb":[[20,0],[25,0]],"id":41419594},{"atb":[[160,0],[110,0]],"id":41419658}],"con":true,"img":false}]}
{"op":"mcm","clk":"5352956349","pt":1646205606930,"mc":[{"id":"1.195503861","rc":[{"atb":[[6.4,37.05],[5.7,0]],"id":41419630},{"atb":[[70,0],[48,0]],"id":28546943},{"atb":[[65,0],[46,0]],"id":41419608},{"atb":[[34,0],[27,0]],"id":41419616},{"atb":[[10.5,0],[13,0]],"id":41419590},{"atb":[[40,0],[30,0]],"id":41419586}],"con":true,"img":false}]}
{"op":"mcm","clk":"5352956353","pt":1646205607033,"mc":[{"id":"1.195503861","rc":[{"atb":[[22,0],[27,0]],"id":41419613},{"atb":[[23,0],[28,0]],"id":41419614}],"con":true,"img":false}]}
{"op":"mcm","clk":"5352956357","pt":1646205607136,"mc":[{"id":"1.195503861","rc":[{"atb":[[80,0],[110,0]],"id":41435525}],"con":true,"img":false}]}
{"op":"mcm","clk":"5352956361","pt":1646205607240,"mc":[{"id":"1.195503861","rc":[{"atb":[[150,1.79],[100,0]],"id":28546950},{"atb":[[140,0],[190,0]],"id":41435527},{"atb":[[21,0],[26,0]],"id":41419587},{"atb":[[80,0],[55,0]],"id":41419601},{"atb":[[130,0],[180,0]],"id":41419652},{"atb":[[7.2,0],[8.2,0]],"id":41419631}],"con":true,"img":false}]}
{"op":"mcm","clk":"5352956364","pt":1646205607344,"mc":[{"id":"1.195503861","rc":[{"atb":[[40,0],[30,0]],"id":41419609}],"con":true,"img":false}]}
{"op":"mcm","clk":"5352956369","pt":1646205607447,"mc":[{"id":"1.195503861","rc":[{"atb":[[34,3.27],[44,2.72]],"id":41419593}],"con":true,"img":false}]}
{"op":"mcm","clk":"5352956373","pt":1646205607549,"mc":[{"id":"1.195503861","rc":[{"atb":[[38,2.72],[29,3.27]],"id":41419607},{"atb":[[36,3.27],[46,2.72]],"id":41419615},{"atb":[[18.5,3.27],[22,2.72]],"id":41419611},{"atb":[[200,3.27],[250,2.72]],"id":41419657},{"atb":[[80,2.72],[55,3.27]],"id":41419653},{"atb":[[75,2.72],[50,3.27]],"id":41419651},{"atb":[[13,3.27],[15.5,2.72]],"id":41419618},{"atb":[[44,3.27],[60,2.72]],"id":41419599},{"atb":[[11.5,3.27],[14,2.72]],"id":41419597},{"atb":[[36,2.72],[28,3.27]],"id":41419606},{"atb":[[40,2.72],[30,3.27]],"id":41419604},{"atb":[[65,2.72],[46,3.27]],"id":41419602},{"atb":[[19.5,3.27],[24,2.72]],"id":41419585},{"atb":[[20,3.27],[25,2.72]],"id":41419592},{"atb":[[150,2.72],[100,3.27]],"id":41419656},{"atb":[[24,3.27],[29,2.72]],"id":41419654},{"atb":[[20,13.8],[25,2.72]],"id":41419588},{"atb":[[65,2.72],[46,3.27]],"id":41419600},{"atb":[[16,2.72],[13.5,3.27]],"id":41419629},{"atb":[[20,3.27],[25,2.72]],"id":41419594},{"atb":[[160,2.72],[110,3.27]],"id":41419658}],"con":true,"img":false}]}
{"op":"mcm","clk":"5352956377","pt":1646205607652,"mc":[{"id":"1.195503861","rc":[{"atb":[[6.4,39.78],[5.7,3.27]],"id":41419630},{"atb":[[70,2.72],[48,3.27]],"id":28546943},{"atb":[[65,2.72],[46,3.27]],"id":41419608},{"atb":[[10.5,3.27],[13,2.72]],"id":41419590},{"atb":[[40,2.72],[30,3.27]],"id":41419586}],"con":true,"img":false}]}
{"op":"mcm","clk":"5352956386","pt":1646205607858,"mc":[{"id":"1.195503861","rc":[{"atb":[[22,3.27],[27,2.72]],"id":41419613},{"atb":[[80,3.27],[110,2.72]],"id":41435525},{"atb":[[34,2.72],[27,3.27]],"id":41419616},{"atb":[[23,3.27],[28,2.72]],"id":41419614}],"con":true,"img":false}]}
{"op":"mcm","clk":"5352956392","pt":1646205607910,"mc":[{"id":"1.195503861","rc":[{"atb":[[150,4.51],[100,3.27]],"id":28546950},{"atb":[[140,3.27],[190,2.72]],"id":41435527},{"atb":[[21,3.27],[26,2.72]],"id":41419587},{"atb":[[80,2.72],[55,3.27]],"id":41419601},{"atb":[[7.2,3.27],[8.2,2.72]],"id":41419631}],"con":true,"img":false}]}
{"op":"mcm","clk":"5352956401","pt":1646205608116,"mc":[{"id":"1.195503861","rc":[{"atb":[[40,2.72],[30,3.27]],"id":41419609},{"atb":[[130,3.27],[180,2.72]],"id":41419652}],"con":true,"img":false}]}
{"op":"mcm","clk":"5352964317","pt":1646205855400,"mc":[{"id":"1.195503861","rc":[{"atb":[[21,0],[26,0]],"id":41419587}],"con":true,"img":false}]}
{"op":"mcm","clk":"5352964338","pt":1646205856120,"mc":[{"id":"1.195503861","rc":[{"atb":[[20,3.27],[25,2.72]],"id":41419587}],"con":true,"img":false}]}
{"op":"mcm","clk":"5352974272","pt":1646206122802,"mc":[{"id":"1.195503861","rc":[{"atb":[[34,0],[27,0]],"id":41419616}],"con":true,"img":false}]}
{"op":"mcm","clk":"5352974296","pt":1646206123519,"mc":[{"id":"1.195503861","rc":[{"atb":[[36,2.72],[28,3.27]],"id":41419616}],"con":true,"img":false}]}
{"op":"mcm","clk":"5352974845","pt":1646206140513,"mc":[{"id":"1.195503861","rc":[{"atb":[[29,0]],"id":41419607}],"con":true,"img":false}]}
{"op":"mcm","clk":"5352974853","pt":1646206140825,"mc":[{"id":"1.195503861","rc":[{"atb":[[38,0]],"id":41419607},{"atb":[[36,0],[28,0]],"id":41419606}],"con":true,"img":false}]}
{"op":"mcm","clk":"5352974862","pt":1646206141233,"mc":[{"id":"1.195503861","rc":[{"atb":[[30,3.27]],"id":41419607}],"con":true,"img":false}]}
{"op":"mcm","clk":"5352974867","pt":1646206141542,"mc":[{"id":"1.195503861","rc":[{"atb":[[40,2.72]],"id":41419607},{"atb":[[38,2.72],[29,10.42]],"id":41419606}],"con":true,"img":false}]}
{"op":"mcm","clk":"5352984877","pt":1646206364291,"mc":[{"id":"1.195503861","rc":[{"atb":[[25,0]],"id":41419587}],"con":true,"img":false}]}
{"op":"mcm","clk":"5352984892","pt":1646206364595,"mc":[{"id":"1.195503861","rc":[{"atb":[[20,0]],"id":41419587}],"con":true,"img":false}]}
{"op":"mcm","clk":"5352984908","pt":1646206365001,"mc":[{"id":"1.195503861","rc":[{"atb":[[26,2.72]],"id":41419587}],"con":true,"img":false}]}
{"op":"mcm","clk":"5352984921","pt":1646206365309,"mc":[{"id":"1.195503861","rc":[{"atb":[[21,3.27]],"id":41419587}],"con":true,"img":false}]}
{"op":"mcm","clk":"5352997176","pt":1646206654842,"mc":[{"id":"1.195503861","rc":[{"atb":[[19.5,0],[24,0]],"id":41419585},{"atb":[[20,0],[25,0]],"id":41419592},{"atb":[[20,10.52],[25,0]],"id":41419588}],"con":true,"img":false}]}
{"op":"mcm","clk":"5352997185","pt":1646206655151,"mc":[{"id":"1.195503861","rc":[{"atb":[[22,0],[27,0]],"id":41419613},{"atb":[[10.5,0],[13,0]],"id":41419590}],"con":true,"img":false}]}
{"op":"mcm","clk":"5352997213","pt":1646206655721,"mc":[{"id":"1.195503861","rc":[{"atb":[[19,3.27],[23,2.72]],"id":41419585},{"atb":[[19.5,3.27],[24,2.72]],"id":41419592},{"atb":[[19.5,3.27],[24,2.72]],"id":41419588}],"con":true,"img":false}]}
{"op":"mcm","clk":"5352997222","pt":1646206655824,"mc":[{"id":"1.195503861","rc":[{"atb":[[12,2.72],[9.8,3.27]],"id":41419590}],"con":true,"img":false}]}
{"op":"mcm","clk":"5352997230","pt":1646206656030,"mc":[{"id":"1.195503861","rc":[{"atb":[[21,13.28],[26,2.72]],"id":41419613}],"con":true,"img":false}]}
{"op":"mcm","clk":"5353034982","pt":1646207303654,"mc":[{"id":"1.195503861","rc":[{"atb":[[21,0],[26,0]],"id":41419587},{"atb":[[6.4,37.05],[5.7,0]],"id":41419630}],"con":true,"img":false}]}
{"op":"mcm","clk":"5353035013","pt":1646207304579,"mc":[{"id":"1.195503861","rc":[{"atb":[[20,3.27],[25,2.72]],"id":41419587},{"atb":[[5.8,3.27],[6.6,2.72]],"id":41419630}],"con":true,"img":false}]}
{"op":"mcm","clk":"5353035399","pt":1646207313575,"mc":[{"id":"1.195503861","rc":[{"atb":[[5.8,0],[6.6,0]],"id":41419630}],"con":true,"img":false}]}
{"op":"mcm","clk":"5353035431","pt":1646207314399,"mc":[{"id":"1.195503861","rc":[{"atb":[[6.4,39.78],[5.7,3.27]],"id":41419630}],"con":true,"img":false}]}
{"op":"mcm","clk":"5353036825","pt":1646207343729,"mc":[{"id":"1.195503861","rc":[{"atb":[[40,0],[30,0]],"id":41419607},{"atb":[[38,0],[29,7.14]],"id":41419606}],"con":true,"img":false}]}
{"op":"mcm","clk":"5353036862","pt":1646207344611,"mc":[{"id":"1.195503861","rc":[{"atb":[[38,2.72],[29,3.27]],"id":41419607},{"atb":[[36,2.72],[28,3.27]],"id":41419606}],"con":true,"img":false}]}
{"op":"mcm","clk":"5353043923","pt":1646207522959,"mc":[{"id":"1.195503861","rc":[{"atb":[[12,0],[9.8,0]],"id":41419590}],"con":true,"img":false}]}
{"op":"mcm","clk":"5353043966","pt":1646207523787,"mc":[{"id":"1.195503861","rc":[{"atb":[[10,3.27],[12.5,2.72]],"id":41419590}],"con":true,"img":false}]}
{"op":"mcm","clk":"5353048946","pt":1646207667833,"mc":[{"id":"1.195503861","rc":[{"atb":[[20,0]],"id":41419587}],"con":true,"img":false}]}
{"op":"mcm","clk":"5353048955","pt":1646207668141,"mc":[{"id":"1.195503861","rc":[{"atb":[[25,0]],"id":41419587}],"con":true,"img":false}]}
{"op":"mcm","clk":"5353048971","pt":1646207668545,"mc":[{"id":"1.195503861","rc":[{"atb":[[21,3.27]],"id":41419587}],"con":true,"img":false}]}
{"op":"mcm","clk":"5353048980","pt":1646207668852,"mc":[{"id":"1.195503861","rc":[{"atb":[[26,2.72]],"id":41419587}],"con":true,"img":false}]}
{"op":"mcm","clk":"5353060855","pt":1646207977031,"mc":[{"id":"1.195503861","rc":[{"atb":[[10,0],[12.5,0]],"id":41419590}],"con":true,"img":false}]}
{"op":"mcm","clk":"5353060888","pt":1646207977748,"mc":[{"id":"1.195503861","rc":[{"atb":[[12,2.72],[9.8,3.27]],"id":41419590}],"con":true,"img":false}]}
{"op":"mcm","clk":"5353068826","pt":1646208155208,"mc":[{"id":"1.195503861","rc":[{"atb":[[18.5,0],[22,0]],"id":41419611},{"atb":[[6.4,37.05],[5.7,0]],"id":41419630},{"atb":[[6.4,0],[5.7,0]],"id":41419627}],"con":true,"img":false}]}
{"op":"mcm","clk":"5353068832","pt":1646208155309,"mc":[{"id":"1.195503861","rc":[{"atb":[[6,0],[7,0]],"id":41419628}],"con":true,"img":false}]}
{"op":"mcm","clk":"5353068869","pt":1646208155875,"mc":[{"id":"1.195503861","rc":[{"atb":[[5.6,3.27],[6.2,2.72]],"id":41419630}],"con":true,"img":false}]}
{"op":"mcm","clk":"5353068876","pt":1646208155980,"mc":[{"id":"1.195503861","rc":[{"atb":[[18,3.27],[21,2.72]],"id":41419611},{"atb":[[7.2,2.72],[6.2,3.27]],"id":41419628},{"atb":[[5.8,44.96],[6.6,2.72]],"id":41419627}],"con":true,"img":false}]}
{"op":"mcm","clk":"5353074440","pt":1646208273725,"mc":[{"id":"1.195503861","rc":[{"atb":[[9.8,0]],"id":41419590}],"con":true,"img":false}]}
{"op":"mcm","clk":"5353074452","pt":1646208274035,"mc":[{"id":"1.195503861","rc":[{"atb":[[12,0]],"id":41419590}],"con":true,"img":false}]}
{"op":"mcm","clk":"5353074476","pt":1646208274441,"mc":[{"id":"1.195503861","rc":[{"atb":[[10,3.27]],"id":41419590}],"con":true,"img":false}]}
{"op":"mcm","clk":"5353074492","pt":1646208274746,"mc":[{"id":"1.195503861","rc":[{"atb":[[12.5,2.72]],"id":41419590}],"con":true,"img":false}]}
{"op":"mcm","clk":"5353083947","pt":1646208473731,"mc":[{"id":"1.195503861","rc":[{"atb":[[10,0],[12.5,0]],"id":41419590}],"con":true,"img":false}]}
{"op":"mcm","clk":"5353083981","pt":1646208474404,"mc":[{"id":"1.195503861","rc":[{"atb":[[12,2.72],[9.8,3.27]],"id":41419590}],"con":true,"img":false}]}
{"op":"mcm","clk":"5353087349","pt":1646208555521,"mc":[{"id":"1.195503861","rc":[{"atb":[[21,0],[26,0]],"id":41419587},{"atb":[[5.6,0],[6.2,0]],"id":41419630},{"atb":[[7.2,0],[6.2,0]],"id":41419628},{"atb":[[5.8,41.69],[6.6,0]],"id":41419627}],"con":true,"img":false}]}
{"op":"mcm","clk":"5353087377","pt":1646208556194,"mc":[{"id":"1.195503861","rc":[{"atb":[[6,3.27],[7,2.72]],"id":41419628}],"con":true,"img":false}]}
{"op":"mcm","clk":"5353087389","pt":1646208556498,"mc":[{"id":"1.195503861","rc":[{"atb":[[6.4,39.78],[5.7,3.27]],"id":41419630},{"atb":[[6.4,2.72],[5.7,3.27]],"id":41419627}],"con":true,"img":false}]}
{"op":"mcm","clk":"5353087395","pt":1646208556599,"mc":[{"id":"1.195503861","rc":[{"atb":[[20,3.27],[25,2.72]],"id":41419587}],"con":true,"img":false}]}
{"op":"mcm","clk":"5353088144","pt":1646208573442,"mc":[{"id":"1.195503861","rc":[{"atb":[[6.4,37.05],[5.7,0]],"id":41419630}],"con":true,"img":false}]}
{"op":"mcm","clk":"5353088163","pt":1646208573751,"mc":[{"id":"1.195503861","rc":[{"atb":[[20,0],[25,0]],"id":41419587}],"con":true,"img":false}]}
{"op":"mcm","clk":"5353088175","pt":1646208574158,"mc":[{"id":"1.195503861","rc":[{"atb":[[5.6,3.27],[6.2,2.72]],"id":41419630}],"con":true,"img":false}]}
{"op":"mcm","clk":"5353088188","pt":1646208574417,"mc":[{"id":"1.195503861","rc":[{"atb":[[21,3.27],[26,2.72]],"id":41419587}],"con":true,"img":false}]}
{"op":"mcm","clk":"5353091324","pt":1646208641728,"mc":[{"id":"1.195503861","rc":[{"atb":[[9.8,11.36]],"id":41419609},{"atb":[[9.8,11.36]],"id":41419607},{"atb":[[65,2]],"id":28546950},{"atb":[[22,4.76]],"id":41419615},{"atb":[[9.8,11.36]],"id":41419613},{"atb":[[9.8,11.36]],"id":41419611},{"atb":[[120,2]],"id":41419657},{"atb":[[21,5]],"id":41419593},{"atb":[[50,2]],"id":41435525},{"atb":[[38,2.7]],"id":41419653},{"atb":[[90,2]],"id":41435527},{"atb":[[14,7.69]],"id":41419587},{"atb":[[34,3.03]],"id":41419651},{"atb":[[7.6,15.15]],"id":41419618},{"atl":[[420,2]],"id":41419618},{"atb":[[38,2.7]],"id":41419601},{"atb":[[29,3.57]],"id":41419599},{"atb":[[5.2,87.33]],"id":41419630},{"atl":[[370,2]],"id":41419630},{"atb":[[6.8,17.24]],"id":41419597},{"atl":[[420,2]],"id":41419597},{"atb":[[32,3.23]],"id":28546943},{"atb":[[3.8,35.71]],"id":41419628},{"atl":[[310,2]],"id":41419628},{"atb":[[44,2.33]],"id":41419659},{"atb":[[13,8.33]],"id":41419595},{"atb":[[30,3.45]],"id":41419608},{"atb":[[9.8,11.36]],"id":41419606},{"atb":[[19,5.56]],"id":41419604},{"atb":[[32,3.23]],"id":41419602},{"atb":[[4.9,21.06]],"id":41419585},{"atb":[[9.8,11.36]],"id":41419616},{"atb":[[9.8,41.68]],"id":41419614},{"atb":[[11.5,9.52]],"id":41419592},{"atb":[[70,2]],"id":41419656},{"atb":[[5.9,20.41]],"id":41419590},{"atl":[[410,2]],"id":41419590},{"atb":[[14,7.69]],"id":41419654},{"atb":[[11.5,9.52]],"id":41419588},{"atb":[[85,2]],"id":41419652},{"atb":[[19,5.56]],"id":41419586},{"atb":[[30,3.45]],"id":41419600},{"atb":[[4,33.33]],"id":41419631},{"atl":[[310,2]],"id":41419631},{"atb":[[7.8,14.71]],"id":41419629},{"atl":[[430,2]],"id":41419629},{"atb":[[3.5,40]],"id":41419627},{"atl":[[300,2]],"id":41419627},{"atb":[[15.5,6.9]],"id":41419594},{"atb":[[75,2]],"id":41419658}],"con":true,"img":false}]}
{"op":"mcm","clk":"5353098468","pt":1646208794534,"mc":[{"id":"1.195503861","rc":[{"atb":[[6,0],[7,0]],"id":41419628}],"con":true,"img":false}]}
{"op":"mcm","clk":"5353098480","pt":1646208794842,"mc":[{"id":"1.195503861","rc":[{"atb":[[6.4,0],[5.7,0]],"id":41419627}],"con":true,"img":false}]}
{"op":"mcm","clk":"5353098511","pt":1646208795315,"mc":[{"id":"1.195503861","rc":[{"atb":[[7.2,2.72],[6.2,3.27]],"id":41419628}],"con":true,"img":false}]}
{"op":"mcm","clk":"5353098529","pt":1646208795618,"mc":[{"id":"1.195503861","rc":[{"atb":[[5.8,44.96],[6.6,2.72]],"id":41419627}],"con":true,"img":false}]}
{"op":"mcm","clk":"5353111302","pt":1646209082002,"mc":[{"id":"1.195503861","rc":[{"atb":[[36,0],[28,0]],"id":41419616}],"con":true,"img":false}]}
{"op":"mcm","clk":"5353111337","pt":1646209082887,"mc":[{"id":"1.195503861","rc":[{"atb":[[34,2.72],[27,3.27]],"id":41419616}],"con":true,"img":false}]}
{"op":"mcm","clk":"5353111362","pt":1646209083407,"mc":[{"id":"1.195503861","rc":[{"atb":[[38,0],[29,0]],"id":41419607},{"atb":[[7.2,0],[6.2,0]],"id":41419628},{"atb":[[20,0],[25,0]],"id":41419594}],"con":true,"img":false}]}
{"op":"mcm","clk":"5353111369","pt":1646209083466,"mc":[{"id":"1.195503861","rc":[{"atb":[[18,0],[21,0]],"id":41419611},{"atb":[[21,0],[26,0]],"id":41419587},{"atb":[[5.6,0],[6.2,0]],"id":41419630},{"atb":[[36,0],[28,0]],"id":41419606},{"atb":[[5.8,41.69],[6.6,0]],"id":41419627}],"con":true,"img":false}]}
{"op":"mcm","clk":"5353111399","pt":1646209084082,"mc":[{"id":"1.195503861","rc":[{"atb":[[34,8.79],[27,3.27]],"id":41419607},{"atb":[[6.4,3.27],[7.4,2.72]],"id":41419628},{"atb":[[19.5,3.27],[24,2.72]],"id":41419594}],"con":true,"img":false}]}
{"op":"mcm","clk":"5353111409","pt":1646209084186,"mc":[{"id":"1.195503861","rc":[{"atb":[[16,3.27],[18.5,2.72]],"id":41419611},{"atb":[[20,3.27],[25,2.72]],"id":41419587},{"atb":[[5.5,3.27],[6,2.72]],"id":41419630},{"atb":[[34,2.72],[27,3.27]],"id":41419606},{"atb":[[6.8,2.72],[5.9,3.27]],"id":41419627}],"con":true,"img":false}]}
{"op":"mcm","clk":"5353114311","pt":1646209154895,"mc":[{"id":"1.195503861","rc":[{"atb":[[20,0],[25,0]],"id":41419587},{"atb":[[12,0],[9.8,0]],"id":41419590},{"atb":[[6.8,0],[5.9,0]],"id":41419627}],"con":true,"img":false}]}
{"op":"mcm","clk":"5353114338","pt":1646209155568,"mc":[{"id":"1.195503861","rc":[{"atb":[[16.5,16.18],[19,2.72]],"id":41419587},{"atb":[[9,3.27],[10,2.72]],"id":41419590},{"atb":[[4.8,3.27],[5.3,2.72]],"id":41419627}],"con":true,"img":false}]}
{"op":"mcm","clk":"5353119326","pt":1646209269461,"mc":[{"id":"1.195503861","rc":[{"atb":[[34,6.06],[27,0]],"id":41419607},{"atb":[[16,0],[18.5,0]],"id":41419611},{"atb":[[5.5,0],[6,0]],"id":41419630},{"atb":[[6.4,0],[7.4,0]],"id":41419628},{"atb":[[19.5,0],[24,0]],"id":41419594}],"con":true,"img":false}]}
{"op":"mcm","clk":"5353119355","pt":1646209270179,"mc":[{"id":"1.195503861","rc":[{"atb":[[38,2.72],[29,3.27]],"id":41419607},{"atb":[[19,3.27],[23,2.72]],"id":41419611},{"atb":[[5.8,3.27],[6.6,2.72]],"id":41419630},{"atb":[[6.8,37.77],[7.8,2.72]],"id":41419628},{"atb":[[32,9.18],[26,3.27]],"id":41419594}],"con":true,"img":false}]}
{"op":"mcm","clk":"5353122851","pt":1646209346858,"mc":[{"id":"1.195503861","rc":[{"atb":[[19.5,0],[24,0]],"id":41419592},{"atb":[[19.5,0],[24,0]],"id":41419588}],"con":true,"img":false}]}
{"op":"mcm","clk":"5353122903","pt":1646209347539,"mc":[{"id":"1.195503861","rc":[{"atb":[[20,3.27],[25,2.72]],"id":41419592},{"atb":[[20,13.8],[25,2.72]],"id":41419588}],"con":true,"img":false}]}
{"op":"mcm","clk":"5353131838","pt":1646209515932,"mc":[{"id":"1.195503861","rc":[{"atl":[[430,0]],"id":41419629}],"con":true,"img":false}]}
{"op":"mcm","clk":"5353131851","pt":1646209516190,"mc":[{"id":"1.195503861","rc":[{"atb":[[5.8,0],[6.6,0]],"id":41419630},{"atb":[[34,0],[27,0]],"id":41419606},{"atb":[[19,0],[23,0]],"id":41419585},{"atb":[[20,0],[25,0]],"id":41419592},{"atb":[[4.8,0],[5.3,0]],"id":41419627},{"atb":[[32,6.45],[26,0]],"id":41419594}],"con":true,"img":false}]}
{"op":"mcm","clk":"5353131896","pt":1646209516874,"mc":[{"id":"1.195503861","rc":[{"atb":[[7.2,2.72],[6.2,3.27]],"id":41419630},{"atb":[[36,2.72],[28,3.27]],"id":41419606},{"atb":[[19.5,3.27],[24,2.72]],"id":41419592},{"atb":[[5,3.27],[5.5,2.72]],"id":41419627}],"con":true,"img":false}]}
{"op":"mcm","clk":"5353131903","pt":1646209516971,"mc":[{"id":"1.195503861","rc":[{"atb":[[17.5,3.27],[20,13.25]],"id":41419585},{"atb":[[24,3.27],[29,2.72]],"id":41419594}],"con":true,"img":false}]}
{"op":"mcm","clk":"5353132777","pt":1646209531230,"mc":[{"id":"1.195503861","rc":[{"atb":[[16.5,12.9],[19,0]],"id":41419587},{"atb":[[36,0],[28,0]],"id":41419606}],"con":true,"img":false}]}
{"op":"mcm","clk":"5353132780","pt":1646209531285,"mc":[{"id":"1.195503861","rc":[{"atb":[[6.8,34.5],[7.8,0]],"id":41419628},{"atb":[[19.5,0],[24,0]],"id":41419592},{"atb":[[24,0],[29,0]],"id":41419594}],"con":true,"img":false}]}
{"op":"mcm","clk":"5353132808","pt":1646209531905,"mc":[{"id":"1.195503861","rc":[{"atb":[[17,3.27],[19.5,2.72]],"id":41419587},{"atb":[[34,2.72],[27,3.27]],"id":41419606}],"con":true,"img":false}]}
{"op":"mcm","clk":"5353132812","pt":1646209532010,"mc":[{"id":"1.195503861","rc":[{"atb":[[7.6,2.72],[6.6,3.27]],"id":41419628},{"atb":[[19,3.27],[23,2.72]],"id":41419592},{"atb":[[22,3.27],[27,2.72]],"id":41419594}],"con":true,"img":false}]}
{"op":"mcm","clk":"5353139872","pt":1646209658870,"mc":[{"id":"1.195503861","rc":[{"atb":[[5,0]],"id":41419627}],"con":true,"img":false}]}
{"op":"mcm","clk":"5353139879","pt":1646209658977,"mc":[{"id":"1.195503861","rc":[{"atb":[[5.5,0]],"id":41419627}],"con":true,"img":false}]}
{"op":"mcm","clk":"5353139904","pt":1646209659545,"mc":[{"id":"1.195503861","rc":[{"atb":[[5.2,3.27]],"id":41419627}],"con":true,"img":false}]}
{"op":"mcm","clk":"5353139914","pt":1646209659751,"mc":[{"id":"1.195503861","rc":[{"atb":[[5.7,2.72]],"id":41419627}],"con":true,"img":false}]}
{"op":"mcm","clk":"5353140093","pt":1646209662645,"mc":[{"id":"1.195503861","rc":[{"atb":[[9.8,0],[14.5,7.41]],"id":41419609},{"atb":[[9.8,0],[14.5,7.41]],"id":41419607},{"atb":[[9.8,0],[12.5,8.7]],"id":41419613},{"atb":[[21,0],[14.5,7.41]],"id":41419593},{"atb":[[34,0],[14.5,4.52]],"id":41419651},{"atb":[[44,0],[15,6.01]],"id":41419659},{"atb":[[9.8,0],[14.5,7.41]],"id":41419606},{"atb":[[7.4,15.62],[4.9,0]],"id":41419585},{"atb":[[9.8,0],[14.5,7.41]],"id":41419616},{"atb":[[9.8,30.32],[13.5,8]],"id":41419614}],"con":true,"img":false}]}
{"op":"mcm","clk":"5353142394","pt":1646209701396,"mc":[{"id":"1.195503861","rc":[{"atb":[[17,0],[19.5,0]],"id":41419587},{"atb":[[7.2,0],[6.2,0]],"id":41419630},{"atb":[[22,0],[27,0]],"id":41419594}],"con":true,"img":false}]}
{"op":"mcm","clk":"5353142429","pt":1646209702122,"mc":[{"id":"1.195503861","rc":[{"atb":[[16.5,16.18],[19,2.72]],"id":41419587},{"atb":[[6,3.27],[7,2.72]],"id":41419630},{"atb":[[23,3.27],[28,2.72]],"id":41419594}],"con":true,"img":false}]}
{"op":"mcm","clk":"5353144009","pt":1646209731614,"mc":[{"id":"1.195503861","rc":[{"atb":[[38,0],[29,0]],"id":41419607},{"atb":[[150,1.79],[100,0]],"id":28546950},{"atb":[[7.6,0],[6.6,0]],"id":41419628},{"atb":[[34,0],[27,0]],"id":41419606},{"atb":[[17.5,0],[20,10.52]],"id":41419585},{"atb":[[19,0],[23,0]],"id":41419592},{"atb":[[9,0],[10,0]],"id":41419590}],"con":true,"img":false}]}
{"op":"mcm","clk":"5353144042","pt":1646209732339,"mc":[{"id":"1.195503861","rc":[{"atb":[[34,8.79],[27,3.27]],"id":41419607},{"atb":[[140,2.72],[95,3.27]],"id":28546950},{"atb":[[6.8,37.77],[7.8,2.72]],"id":41419628},{"atb":[[18.5,3.27],[22,2.72]],"id":41419606},{"atb":[[18,2.72],[15.5,3.27]],"id":41419585},{"atb":[[12.5,3.27],[15,2.72]],"id":41419592},{"atb":[[10,3.27],[12.5,2.72]],"id":41419590}],"con":true,"img":false}]}
{"op":"mcm","clk":"5353145237","pt":1646209755499,"mc":[{"id":"1.195503861","rc":[{"atb":[[11.5,0],[14,0]],"id":41419597},{"atb":[[18,0],[15.5,0]],"id":41419585},{"atb":[[12.5,0],[15,0]],"id":41419592}],"con":true,"img":false}]}
{"op":"mcm","clk":"5353145263","pt":1646209756179,"mc":[{"id":"1.195503861","rc":[{"atb":[[11,3.27],[13.5,2.72]],"id":41419597},{"atb":[[17,2.72],[14.5,3.27]],"id":41419585},{"atb":[[11.5,12.79],[14,2.72]],"id":41419592}],"con":true,"img":false}]}
{"op":"mcm","clk":"5353146796","pt":1646209787351,"mc":[{"id":"1.195503861","rc":[{"atb":[[5.2,0]],"id":41419627}],"con":true,"img":false}]}
{"op":"mcm","clk":"5353146812","pt":1646209787630,"mc":[{"id":"1.195503861","rc":[{"atb":[[5.7,0]],"id":41419627}],"con":true,"img":false}]}
{"op":"mcm","clk":"5353146835","pt":1646209788043,"mc":[{"id":"1.195503861","rc":[{"atb":[[6.4,2.72]],"id":41419627}],"con":true,"img":false}]}
{"op":"mcm","clk":"5353146851","pt":1646209788354,"mc":[{"id":"1.195503861","rc":[{"atb":[[5.7,3.27]],"id":41419627}],"con":true,"img":false}]}
{"op":"mcm","clk":"5353147337","pt":1646209797047,"mc":[{"id":"1.195503861","rc":[{"atb":[[34,6.06],[27,0]],"id":41419607},{"atb":[[19,0],[23,0]],"id":41419611},{"atb":[[18.5,0],[22,0]],"id":41419606}],"con":true,"img":false}]}
{"op":"mcm","clk":"5353147341","pt":1646209797151,"mc":[{"id":"1.195503861","rc":[{"atb":[[11,10],[9.8,0]],"id":41419611}],"con":true,"img":false}]}
{"op":"mcm","clk":"5353147367","pt":1646209797829,"mc":[{"id":"1.195503861","rc":[{"atb":[[32,2.72],[26,3.27]],"id":41419607},{"atb":[[18,3.27],[21,2.72]],"id":41419611},{"atb":[[18,3.27],[21,2.72]],"id":41419606}],"con":true,"img":false}]}
{"op":"mcm","clk":"5353148879","pt":1646209825598,"mc":[{"id":"1.195503861","rc":[{"atb":[[16.5,12.9]],"id":41419587},{"atb":[[6,0],[7,0]],"id":41419630}],"con":true,"img":false}]}
{"op":"mcm","clk":"5353148886","pt":1646209825701,"mc":[{"id":"1.195503861","rc":[{"atb":[[19,0]],"id":41419587}],"con":true,"img":false}]}
{"op":"mcm","clk":"5353148918","pt":1646209826272,"mc":[{"id":"1.195503861","rc":[{"atb":[[9.2,3.27],[10.5,2.72]],"id":41419630}],"con":true,"img":false}]}
{"op":"mcm","clk":"5353148926","pt":1646209826376,"mc":[{"id":"1.195503861","rc":[{"atb":[[18,3.27]],"id":41419587}],"con":true,"img":false}]}
{"op":"mcm","clk":"5353148930","pt":1646209826479,"mc":[{"id":"1.195503861","rc":[{"atb":[[21,2.72]],"id":41419587}],"con":true,"img":false}]}
{"op":"mcm","clk":"5353151523","pt":1646209874340,"mc":[{"id":"1.195503861","rc":[{"atb":[[11,0],[13.5,0]],"id":41419597},{"atb":[[17,0],[14.5,0]],"id":41419585},{"atb":[[11.5,9.52],[14,0]],"id":41419592}],"con":true,"img":false}]}
{"op":"mcm","clk":"5353151571","pt":1646209875061,"mc":[{"id":"1.195503861","rc":[{"atb":[[11.5,3.27],[14,2.72]],"id":41419597},{"atb":[[16,3.27],[18.5,2.72]],"id":41419585},{"atb":[[13,19.95],[15.5,2.72]],"id":41419592}],"con":true,"img":false}]}
{"op":"mcm","clk":"5353153943","pt":1646209923143,"mc":[{"id":"1.195503861","rc":[{"atb":[[10,11.11],[14.5,0]],"id":41419609},{"atl":[[850,2]],"id":41419609},{"atb":[[7.6,13.47],[14.5,0]],"id":41419607},{"atl":[[720,2]],"id":41419607},{"atb":[[65,0],[30,3.45]],"id":28546950},{"atb":[[16,6.67],[22,0]],"id":41419615},{"atl":[[970,2]],"id":41419615},{"atb":[[5.3,23.26],[12.5,0]],"id":41419613},{"atl":[[510,2]],"id":41419613},{"atb":[[5.8,20.83],[11,0]],"id":41419611},{"atl":[[550,2]],"id":41419611},{"atl":[[1000,2]],"id":41419593},{"atb":[[32,2.45],[120,0]],"id":41419657},{"atb":[[50,0],[30,2.49]],"id":41435525},{"atb":[[38,0],[28,3.7]],"id":41419653},{"atl":[[1000,2]],"id":41419653},{"atb":[[90,0],[30,2.45]],"id":41435527},{"atb":[[5.3,15.1],[14,0]],"id":41419587},{"atl":[[530,2]],"id":41419587},{"atb":[[4,33.33],[7.6,0]],"id":41419618},{"atl":[[390,2],[420,0]],"id":41419618},{"atb":[[38,0],[28,3.7]],"id":41419601},{"atl":[[1000,2]],"id":41419601},{"atl":[[1000,2]],"id":41419599},{"atb":[[3.8,35.71],[5.2,63.52]],"id":41419630},{"atl":[[340,2],[370,0]],"id":41419630},{"atb":[[4.6,27.78],[6.8,0]],"id":41419597},{"atl":[[1000,2]],"id":28546943},{"atb":[[7.6,15.15],[13,0]],"id":41419595},{"atl":[[720,2]],"id":41419595},{"atb":[[7.2,14.56],[14.5,0]],"id":41419606},{"atl":[[660,2]],"id":41419606},{"atb":[[19,0],[12,9.09]],"id":41419604},{"atl":[[900,2]],"id":41419604},{"atb":[[5.5,22.22],[7.4,0]],"id":41419585},{"atl":[[540,2]],"id":41419585},{"atb":[[14.5,0],[5.4,13.87]],"id":41419616},{"atl":[[530,2]],"id":41419616},{"atb":[[5.8,16.7],[13.5,0]],"id":41419614},{"atl":[[550,2]],"id":41419614},{"atb":[[11.5,0],[5.9,20.02]],"id":41419592},{"atl":[[550,2]],"id":41419592},{"atb":[[70,0],[30,3.16]],"id":41419656},{"atb":[[3.85,35.09],[5.9,0]],"id":41419590},{"atb":[[11,10],[14,0]],"id":41419654},{"atl":[[870,2]],"id":41419654},{"atb":[[11.5,0],[6.6,17.86]],"id":41419588},{"atl":[[610,2]],"id":41419588},{"atb":[[32,2.45],[85,0]],"id":41419652},{"atb":[[19,0],[15.5,6.9]],"id":41419586},{"atl":[[960,2]],"id":41419586},{"atl":[[1000,2]],"id":41419600},{"atl":[[630,2]],"id":41419629},{"atb":[[6.4,13.36],[15.5,0]],"id":41419594},{"atl":[[580,2]],"id":41419594},{"atb":[[32,3.16],[75,0]],"id":41419658}],"con":true,"img":false}]}
{"op":"mcm","clk":"5353153959","pt":1646209923304,"mc":[{"id":"1.195503861","rc":[{"atb":[[32,0],[26,0]],"id":41419607},{"atb":[[18,0],[21,0]],"id":41419611},{"atb":[[13,0],[15.5,0]],"id":41419618},{"atb":[[18,0],[21,0]],"id":41419606},{"atb":[[6.4,0],[5.7,0]],"id":41419627},{"atb":[[23,0],[28,0]],"id":41419594}],"con":true,"img":false}]}
{"op":"mcm","clk":"5353153977","pt":1646209923710,"mc":[{"id":"1.195503861","rc":[{"atb":[[21,10],[26,0]],"id":41419613},{"atb":[[34,0],[27,0]],"id":41419616}],"con":true,"img":false}]}
{"op":"mcm","clk":"5353153997","pt":1646209924020,"mc":[{"id":"1.195503861","rc":[{"atb":[[38,2.72],[29,3.27]],"id":41419607},{"atb":[[19,3.27],[23,2.72]],"id":41419611},{"atb":[[36,2.72],[28,3.27]],"id":41419606},{"atb":[[7.2,2.72],[6.2,3.27]],"id":41419627},{"atb":[[32,9.18],[26,3.27]],"id":41419594}],"con":true,"img":false}]}
{"op":"mcm","clk":"5353154014","pt":1646209924327,"mc":[{"id":"1.195503861","rc":[{"atb":[[11.5,3.27],[14,2.72]],"id":41419618}],"con":true,"img":false}]}
{"op":"mcm","clk":"5353154031","pt":1646209924593,"mc":[{"id":"1.195503861","rc":[{"atb":[[20,3.27],[25,2.72]],"id":41419613},{"atb":[[23,3.27],[28,2.72]],"id":41419616}],"con":true,"img":false}]}
{"op":"mcm","clk":"5353154699","pt":1646209937416,"mc":[{"id":"1.195503861","rc":[{"atb":[[18,0]],"id":41419587}],"con":true,"img":false}]}
{"op":"mcm","clk":"5353154721","pt":1646209937825,"mc":[{"id":"1.195503861","rc":[{"atb":[[21,0]],"id":41419587}],"con":true,"img":false}]}
{"op":"mcm","clk":"5353154740","pt":1646209938130,"mc":[{"id":"1.195503861","rc":[{"atb":[[22,3.27]],"id":41419587}],"con":true,"img":false}]}
{"op":"mcm","clk":"5353154764","pt":1646209938540,"mc":[{"id":"1.195503861","rc":[{"atb":[[27,2.72]],"id":41419587}],"con":true,"img":false}]}
{"op":"mcm","clk":"5353155866","pt":1646209959871,"mc":[{"id":"1.195503861","rc":[{"atb":[[16,0]],"id":41419615},{"atb":[[22,4.52]],"id":41419653},{"atb":[[4,0]],"id":41419618},{"atb":[[18.5,5.71]],"id":41419599},{"atl":[[340,0]],"id":41419630},{"atb":[[3.8,0]],"id":41419628},{"atl":[[1000,2]],"id":41419659},{"atb":[[7.2,0]],"id":41419606},{"atl":[[660,0]],"id":41419606},{"atb":[[12,0]],"id":41419604},{"atb":[[4.8,26.32]],"id":41419585},{"atl":[[510,2]],"id":41419585},{"atb":[[5.9,0]],"id":41419592},{"atl":[[550,0]],"id":41419592},{"atb":[[11,0]],"id":41419654},{"atl":[[870,0]],"id":41419654},{"atb":[[3.1,47.62]],"id":41419627},{"atl":[[230,2]],"id":41419627}],"con":true,"img":false}]}
{"op":"mcm","clk":"5353155874","pt":1646209959975,"mc":[{"id":"1.195503861","rc":[{"atb":[[10,0],[14,7.69]],"id":41419609},{"atl":[[800,2],[850,0]],"id":41419609},{"atl":[[640,2],[720,0]],"id":41419607},{"atl":[[1000,2]],"id":28546950},{"atb":[[20,5.26]],"id":41419615},{"atl":[[910,2],[970,0]],"id":41419615},{"atb":[[5.3,0],[6.6,17.86]],"id":41419613},{"atl":[[480,2],[510,0]],"id":41419613},{"atb":[[5.8,0],[6.8,17.24]],"id":41419611},{"atl":[[530,2],[550,0]],"id":41419611},{"atl":[[920,2],[1000,0]],"id":41419593},{"atl":[[1000,2]],"id":41435525},{"atb":[[22,0],[27,3.85],[28,0]],"id":41419653},{"atl":[[930,2],[1000,0]],"id":41419653},{"atb":[[6.2,15.1],[5.3,0]],"id":41419587},{"atl":[[530,0],[510,2]],"id":41419587},{"atl":[[970,2]],"id":41419651},{"atb":[[5.3,23.26]],"id":41419618},{"atb":[[18.5,0],[22,4.76],[29,0]],"id":41419599},{"atl":[[900,2],[1000,0]],"id":41419599},{"atb":[[4.8,26.32],[3.8,0]],"id":41419630},{"atl":[[370,2]],"id":41419630},{"atb":[[4.6,0],[5.3,23.26]],"id":41419597},{"atb":[[32,0],[13.5,5.91]],"id":28546943},{"atl":[[930,2],[1000,0]],"id":28546943},{"atb":[[3.5,40]],"id":41419628},{"atb":[[10,11.11],[7.6,0]],"id":41419595},{"atl":[[1000,2]],"id":41419608},{"atb":[[5.4,19.66]],"id":41419606},{"atl":[[540,2]],"id":41419606},{"atb":[[17.5,6.06]],"id":41419604},{"atl":[[890,2],[900,0]],"id":41419604},{"atb":[[32,0],[36,2.86]],"id":41419602},{"atb":[[4.8,0],[5.6,21.74],[5.5,0]],"id":41419585},{"atl":[[540,0],[480,2],[510,0]],"id":41419585},{"atb":[[6.4,13.87],[5.4,0]],"id":41419616},{"atb":[[5.8,0],[7.4,15.62]],"id":41419614},{"atl":[[540,2],[550,0]],"id":41419614},{"atb":[[4.5,28.57]],"id":41419592},{"atl":[[460,2]],"id":41419592},{"atb":[[7,14.19]],"id":41419654},{"atl":[[630,2]],"id":41419654},{"atb":[[3.85,0],[4.7,27.03]],"id":41419590},{"atb":[[6.6,0],[7.8,14.71]],"id":41419588},{"atb":[[21,5],[15.5,0]],"id":41419586},{"atl":[[890,2],[960,0]],"id":41419586},{"atb":[[4,0],[5.5,22.22]],"id":41419631},{"atb":[[9,12.5],[7.8,0]],"id":41419629},{"atb":[[3.5,0]],"id":41419627},{"atl":[[300,0],[200,2]],"id":41419627},{"atb":[[6.4,0],[7.6,15.15]],"id":41419594},{"atl":[[560,2],[580,0]],"id":41419594}],"con":true,"img":false}]}
{"op":"mcm","clk":"5353155878","pt":1646209960078,"mc":[{"id":"1.195503861","rc":[{"atl":[[230,0]],"id":41419627}],"con":true,"img":false}]}
{"op":"mcm","clk":"5353155884","pt":1646209960181,"mc":[{"id":"1.195503861","rc":[{"atb":[[4.5,0],[5.3,23.26]],"id":41419592},{"atl":[[430,2],[460,0]],"id":41419592},{"atb":[[3.1,0],[3.5,40]],"id":41419627}],"con":true,"img":false}]}
{"op":"mcm","clk":"5353155890","pt":1646209960283,"mc":[{"id":"1.195503861","rc":[{"atb":[[36,0],[28,0]],"id":41419606}],"con":true,"img":false}]}
{"op":"mcm","clk":"5353155902","pt":1646209960490,"mc":[{"id":"1.195503861","rc":[{"atb":[[27,0]],"id":41419587}],"con":true,"img":false}]}
{"op":"mcm","clk":"5353155936","pt":1646209961167,"mc":[{"id":"1.195503861","rc":[{"atb":[[28,10.14]],"id":41419587},{"atb":[[23,3.27],[28,2.72]],"id":41419606}],"con":true,"img":false}]}
{"op":"mcm","clk":"5353156431","pt":1646209970376,"mc":[{"id":"1.195503861","rc":[{"atl":[[600,2],[640,0]],"id":41419607},{"atl":[[530,0],[520,2]],"id":41419611},{"atl":[[870,2],[970,0]],"id":41419651},{"atb":[[6.4,18.52],[5.3,0]],"id":41419618},{"atl":[[350,2],[370,0]],"id":41419630},{"atb":[[16.5,5.91],[13.5,0]],"id":28546943},{"atl":[[840,2],[930,0]],"id":28546943},{"atb":[[4,33.33],[3.5,0]],"id":41419628},{"atb":[[6.4,18.52],[5.4,0]],"id":41419606},{"atl":[[540,0],[510,2]],"id":41419606},{"atb":[[17.5,0],[21,5]],"id":41419604},{"atb":[[6.4,0],[7.6,13.87]],"id":41419616},{"atb":[[8.2,13.89],[7,0]],"id":41419654},{"atl":[[590,2],[630,0]],"id":41419654},{"atb":[[7.8,0],[9.4,11.9]],"id":41419588},{"atb":[[5.5,0],[6.6,17.86]],"id":41419631}],"con":true,"img":false}]}
{"op":"mcm","clk":"5353157011","pt":1646209981268,"mc":[{"id":"1.195503861","rc":[{"atb":[[13,16.67]],"id":41419592}],"con":true,"img":false}]}
{"op":"mcm","clk":"5353157033","pt":1646209981681,"mc":[{"id":"1.195503861","rc":[{"atb":[[16,0],[18.5,0]],"id":41419585},{"atb":[[15.5,0]],"id":41419592}],"con":true,"img":false}]}
{"op":"mcm","clk":"5353157054","pt":1646209981991,"mc":[{"id":"1.195503861","rc":[{"atb":[[17,3.27]],"id":41419592}],"con":true,"img":false}]}
{"op":"mcm","clk":"5353157072","pt":1646209982407,"mc":[{"id":"1.195503861","rc":[{"atb":[[19.5,2.72]],"id":41419592}],"con":true,"img":false}]}
{"op":"mcm","clk":"5353157092","pt":1646209982716,"mc":[{"id":"1.195503861","rc":[{"atb":[[19.5,3.27],[24,2.72]],"id":41419585}],"con":true,"img":false}]}
{"op":"mcm","clk":"5353157492","pt":1646209990211,"mc":[{"id":"1.195503861","rc":[{"atb":[[20,0],[25,12.5]],"id":41419615},{"atl":[[830,2],[840,0]],"id":28546943},{"atl":[[540,0],[550,2]],"id":41419614},{"atl":[[190,2],[200,0]],"id":41419627}],"con":true,"img":false}]}
{"op":"mcm","clk":"5353157512","pt":1646209990621,"mc":[{"id":"1.195503861","rc":[{"atb":[[19.5,0]],"id":41419592}],"con":true,"img":false}]}
{"op":"mcm","clk":"5353157535","pt":1646209990985,"mc":[{"id":"1.195503861","rc":[{"atb":[[28,7.41]],"id":41419587},{"atb":[[19.5,0],[24,0]],"id":41419585}],"con":true,"img":false}]}
{"op":"mcm","clk":"5353157558","pt":1646209991297,"mc":[{"id":"1.195503861","rc":[{"atb":[[20,2.72]],"id":41419592}],"con":true,"img":false}]}
{"op":"mcm","clk":"5353157593","pt":1646209991707,"mc":[{"id":"1.195503861","rc":[{"atb":[[19,3.27],[23,2.72]],"id":41419585}],"con":true,"img":false}]}
{"op":"mcm","clk":"5353157612","pt":1646209992013,"mc":[{"id":"1.195503861","rc":[{"atb":[[27,2.72]],"id":41419587}],"con":true,"img":false}]}
{"op":"mcm","clk":"5353157908","pt":1646209997324,"mc":[{"id":"1.195503861","rc":[{"atl":[[890,2],[900,0]],"id":41419599}],"con":true,"img":false}]}
{"op":"mcm","clk":"5353158321","pt":1646210004646,"mc":[{"id":"1.195503861","rc":[{"atl":[[480,0],[510,2]],"id":41419613},{"atl":[[920,0],[900,2]],"id":41419593},{"atl":[[930,0],[940,2]],"id":41419653},{"atl":[[850,2],[870,0]],"id":41419651},{"atl":[[300,2],[310,0]],"id":41419628},{"atl":[[700,2],[720,0]],"id":41419595},{"atl":[[430,0],[420,2]],"id":41419592},{"atl":[[540,2],[560,0]],"id":41419594}],"con":true,"img":false}]}
{"op":"mcm","clk":"5353158343","pt":1646210005008,"mc":[{"id":"1.195503861","rc":[{"atb":[[17,0],[20,0]],"id":41419592}],"con":true,"img":false}]}
{"op":"mcm","clk":"5353158385","pt":1646210005729,"mc":[{"id":"1.195503861","rc":[{"atb":[[18,2.72],[15.5,3.27]],"id":41419592}],"con":true,"img":false}]}
{"op":"mcm","clk":"5353158612","pt":1646210010505,"mc":[{"id":"1.195503861","rc":[{"atl":[[710,2]],"id":41419595}],"con":true,"img":false}]}
{"op":"mcm","clk":"5353158618","pt":1646210010607,"mc":[{"id":"1.195503861","rc":[{"atl":[[700,0]],"id":41419595}],"con":true,"img":false}]}
{"op":"mcm","clk":"5353159415","pt":1646210025635,"mc":[{"id":"1.195503861","rc":[{"atb":[[11.5,0]],"id":41419618}],"con":true,"img":false}]}
{"op":"mcm","clk":"5353159430","pt":1646210025943,"mc":[{"id":"1.195503861","rc":[{"atb":[[25,0]],"id":41419613}],"con":true,"img":false}]}
{"op":"mcm","clk":"5353159436","pt":1646210026046,"mc":[{"id":"1.195503861","rc":[{"atb":[[20,0]],"id":41419613},{"atb":[[14,0]],"id":41419618},{"atb":[[23,0],[28,0]],"id":41419616}],"con":true,"img":false}]}
{"op":"mcm","clk":"5353159452","pt":1646210026358,"mc":[{"id":"1.195503861","rc":[{"atb":[[13,3.27]],"id":41419618}],"con":true,"img":false}]}
{"op":"mcm","clk":"5353159469","pt":1646210026615,"mc":[{"id":"1.195503861","rc":[{"atb":[[26,2.72]],"id":41419613}],"con":true,"img":false}]}
{"op":"mcm","clk":"5353159489","pt":1646210027025,"mc":[{"id":"1.195503861","rc":[{"atb":[[21,13.28]],"id":41419613},{"atb":[[15.5,2.72]],"id":41419618},{"atb":[[34,2.72],[27,3.27]],"id":41419616}],"con":true,"img":false}]}
{"op":"mcm","clk":"5353160139","pt":1646210038063,"mc":[{"id":"1.195503861","rc":[{"atb":[[22,0]],"id":41419587}],"con":true,"img":false}]}
{"op":"mcm","clk":"5353160195","pt":1646210039069,"mc":[{"id":"1.195503861","rc":[{"atb":[[23,3.27]],"id":41419587}],"con":true,"img":false}]}
{"op":"mcm","clk":"5353160317","pt":1646210041586,"mc":[{"id":"1.195503861","rc":[{"atb":[[34,0],[18.5,0],[13.5,0]],"id":41419609},{"atb":[[34,0],[18.5,0],[13.5,0]],"id":41419607},{"atb":[[150,0],[400,0],[250,0]],"id":28546950},{"atb":[[17.5,0],[50,0],[25,4.17]],"id":41419615},{"atb":[[9.2,0],[21,3.27],[13,0]],"id":41419613},{"atb":[[7.2,0],[9.2,0],[15.5,0]],"id":41419611},{"atb":[[17.5,0],[50,0],[25,0]],"id":41419593},{"atb":[[600,0],[700,0],[850,0]],"id":41419657},{"atb":[[550,0],[650,0],[800,0]],"id":41435525},{"atb":[[150,0],[400,0],[250,0]],"id":41419653},{"atb":[[600,0],[700,0],[850,0]],"id":41435527},{"atb":[[16.5,0],[11.5,0],[28,0]],"id":41419587},{"atb":[[150,0],[400,0],[250,0]],"id":41419651},{"atb":[[9,0],[5,0],[6,0]],"id":41419618},{"atb":[[42,0],[26,0],[110,0]],"id":41419601},{"atb":[[17,0],[48,0],[24,0]],"id":41419599},{"atb":[[6.4,0],[5.2,0],[9.4,0]],"id":41419630},{"atb":[[9,0],[5,0],[6,0]],"id":41419597},{"atb":[[320,0],[170,0],[85,0]],"id":28546943},{"atb":[[3.95,0],[6.8,3.27],[4.9,0]],"id":41419628},{"atb":[[24,0],[9.8,0],[14.5,0]],"id":41419595},{"atb":[[75,0],[20,0],[30,0]],"id":41419659},{"atb":[[40,0],[100,0],[25,0]],"id":41419608},{"atb":[[17,0],[12,0],[29,0]],"id":41419606},{"atb":[[10.5,0],[26,0],[15.5,0]],"id":41419604},{"atb":[[18,0],[26,0],[55,0]],"id":41419602},{"atb":[[9,0],[20,0],[12.5,0]],"id":41419585},{"atb":[[32,0],[18,0],[13,0]],"id":41419616},{"atb":[[24,0],[9.8,0],[14.5,0]],"id":41419614},{"atb":[[9.2,0],[21,0],[13,0]],"id":41419592},{"atb":[[330,0],[230,0],[480,0]],"id":41419656},{"atb":[[16,0],[44,0],[22,0]],"id":41419654},{"atb":[[5.6,0],[4.6,0],[8.2,0]],"id":41419590},{"atb":[[9,0],[20,3.27],[12.5,0]],"id":41419588},{"atb":[[600,0],[700,0],[850,0]],"id":41419652},{"atb":[[16.5,0],[46,0],[23,0]],"id":41419586},{"atb":[[18,0],[26,0],[55,0]],"id":41419600},{"atb":[[3.95,0],[6.8,0],[4.9,0]],"id":41419631},{"atb":[[8,0],[17.5,0],[10,0]],"id":41419629},{"atb":[[4.3,0],[5.8,0],[3.65,0]],"id":41419627},{"atb":[[32,2.72],[18,0],[13,0]],"id":41419594},{"atb":[[330,0],[230,0],[480,0]],"id":41419658}],"con":true,"img":false}]}
{"op":"mcm","clk":"5353160552","pt":1646210045867,"mc":[{"id":"1.195503861","rc":[{"atb":[[18.5,7.62],[7.4,41.69],[9.4,31.76]],"id":41419609},{"atb":[[18.5,7.62],[7.4,41.69],[9.4,31.76]],"id":41419607},{"atb":[[75,3.6],[40,6.83],[250,0.53]],"id":28546950},{"atb":[[9,33.35],[25,9.72],[12.5,23.19]],"id":41419615},{"atb":[[5.6,58],[7.2,43.03],[13,11.11]],"id":41419613},{"atb":[[5.6,58],[9.2,16.26],[4.6,74.11]],"id":41419611},{"atb":[[9,33.35],[25,5.55],[12.5,23.19]],"id":41419593},{"atb":[[700,0.19],[400,0.67],[500,0.53]],"id":41419657},{"atb":[[650,0.2],[350,0.76],[450,0.59]],"id":41435525},{"atb":[[75,3.6],[40,6.83],[250,0.53]],"id":41419653},{"atb":[[700,0.19],[400,0.67],[500,0.53]],"id":41435527},{"atb":[[75,6.33],[40,6.83],[250,0.53]],"id":41419651},{"atb":[[16.5,8.6],[8.6,35.1],[6.6,47.64]],"id":41419587},{"atb":[[4,88.93],[6,26.68],[3.5,106.72]],"id":41419618},{"atb":[[18,15.69],[42,3.25],[13,22.23]],"id":41419601},{"atb":[[24,5.8],[12,24.25],[8.8,34.2]],"id":41419599},{"atb":[[3.6,102.62],[6.4,24.7],[4.2,83.37]],"id":41419630},{"atb":[[4,88.93],[6,26.68],[3.5,106.72]],"id":41419597},{"atb":[[170,0.79],[44,6.2],[27,10.26]],"id":28546943},{"atb":[[3.45,108.9],[4.9,34.2],[2.98,134.75]],"id":41419628},{"atb":[[7.8,39.23],[14.5,9.87],[5.9,54.45]],"id":41419595},{"atb":[[10,29.64],[15,25.06],[30,4.6]],"id":41419659},{"atb":[[17.5,16.16],[40,3.42],[12.5,23.19]],"id":41419608},{"atb":[[17,8.34],[6.8,46],[8.8,34.2]],"id":41419606},{"atb":[[6.2,51.31],[8.2,37.05],[15.5,9.2]],"id":41419604},{"atb":[[9.2,32.53],[26,5.33],[13,22.23]],"id":41419602},{"atb":[[5.5,59.29],[12.5,11.59],[7,44.47]],"id":41419585},{"atb":[[7.2,43.03],[18,7.84],[9.2,32.53]],"id":41419616},{"atb":[[7.8,39.23],[14.5,9.87],[5.9,54.45]],"id":41419614},{"atb":[[5.6,58],[7.2,43.03],[13,11.11]],"id":41419592},{"atb":[[130,2.06],[65,4.17],[330,0.4]],"id":41419656},{"atb":[[22,6.35],[11,26.68],[8.4,36.05]],"id":41419654},{"atb":[[5.6,29],[3.8,95.28],[3.3,116]],"id":41419590},{"atb":[[5.5,59.29],[12.5,11.59],[7,44.47]],"id":41419588},{"atb":[[700,0.19],[400,0.67],[500,0.53]],"id":41419652},{"atb":[[8.6,35.1],[23,6.06],[11.5,25.4]],"id":41419586},{"atb":[[9.2,32.53],[26,5.33],[13,22.23]],"id":41419600},{"atb":[[3.45,108.9],[4.9,34.2],[2.98,134.75]],"id":41419631},{"atb":[[10,14.82],[5,66.7],[6,53.36]],"id":41419629},{"atb":[[4.3,40.42],[2.86,143.44],[3.15,124.09]],"id":41419627},{"atb":[[130,2.06],[65,4.17],[330,0.4]],"id":41419658},{"atb":[[7.2,43.03],[18,7.84],[9.2,32.53]],"id":41419594}],"con":true,"img":false}]}
{"op":"mcm","clk":"5353161133","pt":1646210056356,"mc":[{"id":"1.195503861","rc":[{"atl":[[990,2],[1000,0]],"id":41419600}],"con":true,"img":false}]}
{"op":"mcm","clk":"5353161257","pt":1646210058883,"mc":[{"id":"1.195503861","rc":[{"atb":[[28,0]],"id":41419606}],"con":true,"img":false}]}
{"op":"mcm","clk":"5353161272","pt":1646210059191,"mc":[{"id":"1.195503861","rc":[{"atb":[[23,0]],"id":41419606}],"con":true,"img":false}]}
{"op":"mcm","clk":"5353161292","pt":1646210059552,"mc":[{"id":"1.195503861","rc":[{"atb":[[29,2.72]],"id":41419606}],"con":true,"img":false}]}
{"op":"mcm","clk":"5353161307","pt":1646210059865,"mc":[{"id":"1.195503861","rc":[{"atb":[[24,3.27]],"id":41419606}],"con":true,"img":false}]}
{"op":"mcm","clk":"5353162253","pt":1646210078176,"mc":[{"id":"1.195503861","rc":[{"atl":[[700,2]],"id":41419595}],"con":true,"img":false}]}
{"op":"mcm","clk":"5353162261","pt":1646210078276,"mc":[{"id":"1.195503861","rc":[{"atl":[[710,0]],"id":41419595}],"con":true,"img":false}]}
{"op":"mcm","clk":"5353162536","pt":1646210083480,"mc":[{"id":"1.195503861","rc":[{"atl":[[890,2],[900,0]],"id":41419593}],"con":true,"img":false}]}
{"op":"mcm","clk":"5353162549","pt":1646210083893,"mc":[{"id":"1.195503861","rc":[{"atb":[[24,0],[29,0]],"id":41419606}],"con":true,"img":false}]}
{"op":"mcm","clk":"5353162589","pt":1646210084611,"mc":[{"id":"1.195503861","rc":[{"atb":[[23,3.27],[28,2.72]],"id":41419606}],"con":true,"img":false}]}
{"op":"mcm","clk":"5353162700","pt":1646210086617,"mc":[{"id":"1.195503861","rc":[{"atb":[[27,0]],"id":41419587}],"con":true,"img":false}]}
{"op":"mcm","clk":"5353162734","pt":1646210087288,"mc":[{"id":"1.195503861","rc":[{"atb":[[28,2.72]],"id":41419587}],"con":true,"img":false}]}
{"op":"mcm","clk":"5353163329","pt":1646210098625,"mc":[{"id":"1.195503861","rc":[{"atb":[[10,0],[12.5,0]],"id":41419590}],"con":true,"img":false}]}
{"op":"mcm","clk":"5353163347","pt":1646210099083,"mc":[{"id":"1.195503861","rc":[{"atb":[[140,0],[95,0]],"id":28546950}],"con":true,"img":false}]}
{"op":"mcm","clk":"5353163353","pt":1646210099287,"mc":[{"id":"1.195503861","rc":[{"atb":[[10.5,3.27],[13,2.72]],"id":41419590}],"con":true,"img":false}]}
{"op":"mcm","clk":"5353163372","pt":1646210099801,"mc":[{"id":"1.195503861","rc":[{"atb":[[150,2.72],[100,3.27]],"id":28546950}],"con":true,"img":false}]}
{"op":"mcm","clk":"5353163494","pt":1646210102112,"mc":[{"id":"1.195503861","rc":[{"atl":[[710,2]],"id":41419595}],"con":true,"img":false}]}
{"op":"mcm","clk":"5353163497","pt":1646210102211,"mc":[{"id":"1.195503861","rc":[{"atl":[[700,0]],"id":41419595}],"con":true,"img":false}]}
{"op":"mcm","clk":"5353163793","pt":1646210107612,"mc":[{"id":"1.195503861","rc":[{"atb":[[19,0],[23,0]],"id":41419585}],"con":true,"img":false}]}
{"op":"mcm","clk":"5353163823","pt":1646210108330,"mc":[{"id":"1.195503861","rc":[{"atb":[[19.5,3.27],[24,2.72]],"id":41419585}],"con":true,"img":false}]}
{"op":"mcm","clk":"5353164101","pt":1646210113430,"mc":[{"id":"1.195503861","rc":[{"atl":[[700,2],[710,0]],"id":41419595}],"con":true,"img":false}]}
{"op":"mcm","clk":"5353164143","pt":1646210114147,"mc":[{"id":"1.195503861","rc":[{"atb":[[19.5,0]],"id":41419585}],"con":true,"img":false}]}
{"op":"mcm","clk":"5353164157","pt":1646210114408,"mc":[{"id":"1.195503861","rc":[{"atb":[[24,0]],"id":41419585}],"con":true,"img":false}]}
{"op":"mcm","clk":"5353164176","pt":1646210114811,"mc":[{"id":"1.195503861","rc":[{"atb":[[19,3.27]],"id":41419585}],"con":true,"img":false}]}
{"op":"mcm","clk":"5353164207","pt":1646210115226,"mc":[{"id":"1.195503861","rc":[{"atb":[[23,2.72]],"id":41419585}],"con":true,"img":false}]}
{"op":"mcm","clk":"5353164346","pt":1646210117749,"mc":[{"id":"1.195503861","rc":[{"atb":[[26,0]],"id":41419613}],"con":true,"img":false}]}
{"op":"mcm","clk":"5353164380","pt":1646210118315,"mc":[{"id":"1.195503861","rc":[{"atb":[[21,0]],"id":41419613}],"con":true,"img":false}]}
{"op":"mcm","clk":"5353164395","pt":1646210118622,"mc":[{"id":"1.195503861","rc":[{"atb":[[27,2.72]],"id":41419613}],"con":true,"img":false}]}
{"op":"mcm","clk":"5353164410","pt":1646210119031,"mc":[{"id":"1.195503861","rc":[{"atb":[[22,3.27]],"id":41419613}],"con":true,"img":false}]}
{"op":"mcm","clk":"5353165672","pt":1646210142891,"mc":[{"id":"1.195503861","rc":[{"atb":[[7.6,0],[8.8,12.82]],"id":41419607},{"atl":[[470,2],[510,0]],"id":41419613},{"atl":[[920,2],[940,0]],"id":41419653},{"atb":[[6.4,0],[5.2,23.81]],"id":41419618},{"atb":[[16.5,0],[19.5,5.41]],"id":28546943},{"atl":[[530,2],[550,0]],"id":41419614},{"atb":[[21,0],[24,4.35]],"id":41419586},{"atb":[[5.3,23.26],[6.6,0]],"id":41419631}],"con":true,"img":false}]}
{"op":"mcm","clk":"5353165692","pt":1646210143251,"mc":[{"id":"1.195503861","rc":[{"atb":[[22,0],[27,0]],"id":41419613}],"con":true,"img":false}]}
{"op":"mcm","clk":"5353165715","pt":1646210143558,"mc":[{"id":"1.195503861","rc":[{"atb":[[23,0]],"id":41419587}],"con":true,"img":false}]}
{"op":"mcm","clk":"5353165743","pt":1646210143968,"mc":[{"id":"1.195503861","rc":[{"atb":[[19.5,3.27],[24,2.72]],"id":41419613}],"con":true,"img":false}]}
{"op":"mcm","clk":"5353165759","pt":1646210144277,"mc":[{"id":"1.195503861","rc":[{"atb":[[25,3.27]],"id":41419587}],"con":true,"img":false}]}
{"op":"mcm","clk":"5353166798","pt":1646210163388,"mc":[{"id":"1.195503861","rc":[{"atl":[[890,2],[910,0]],"id":41419615},{"atl":[[460,2],[470,0]],"id":41419613},{"atl":[[920,0],[900,2]],"id":41419653},{"atl":[[530,0],[520,2]],"id":41419614}],"con":true,"img":false}]}
{"op":"mcm","clk":"5353166826","pt":1646210163994,"mc":[{"id":"1.195503861","rc":[{"atb":[[19.5,0],[24,0]],"id":41419613}],"con":true,"img":false}]}
{"op":"mcm","clk":"5353166862","pt":1646210164713,"mc":[{"id":"1.195503861","rc":[{"atb":[[18.5,3.27],[22,2.72]],"id":41419613}],"con":true,"img":false}]}
{"op":"mcm","clk":"5353167081","pt":1646210168711,"mc":[{"id":"1.195503861","rc":[{"atb":[[34,0],[27,0]],"id":41419616}],"con":true,"img":false}]}
{"op":"mcm","clk":"5353167120","pt":1646210169379,"mc":[{"id":"1.195503861","rc":[{"atb":[[32,2.72],[26,3.27]],"id":41419616}],"con":true,"img":false}]}
{"op":"mcm","clk":"5353167149","pt":1646210169899,"mc":[{"id":"1.195503861","rc":[{"atb":[[28,0]],"id":41419606}],"con":true,"img":false}]}
{"op":"mcm","clk":"5353167171","pt":1646210170311,"mc":[{"id":"1.195503861","rc":[{"atb":[[23,0]],"id":41419606}],"con":true,"img":false}]}
{"op":"mcm","clk":"5353167183","pt":1646210170618,"mc":[{"id":"1.195503861","rc":[{"atb":[[32,2.72]],"id":41419606}],"con":true,"img":false}]}
{"op":"mcm","clk":"5353167218","pt":1646210171291,"mc":[{"id":"1.195503861","rc":[{"atb":[[26,3.27]],"id":41419606}],"con":true,"img":false}]}
{"op":"mcm","clk":"5353167267","pt":1646210172419,"mc":[{"id":"1.195503861","rc":[{"atb":[[28,0]],"id":41419587}],"con":true,"img":false}]}
{"op":"mcm","clk":"5353167302","pt":1646210173091,"mc":[{"id":"1.195503861","rc":[{"atb":[[30,2.72]],"id":41419587}],"con":true,"img":false}]}
{"op":"mcm","clk":"5353168571","pt":1646210197406,"mc":[{"id":"1.195503861","rc":[{"atb":[[23,0]],"id":41419585}],"con":true,"img":false}]}
{"op":"mcm","clk":"5353168601","pt":1646210198124,"mc":[{"id":"1.195503861","rc":[{"atb":[[24,2.72]],"id":41419585}],"con":true,"img":false}]}
{"op":"mcm","clk":"5353172961","pt":1646210279645,"mc":[{"id":"1.195503861","rc":[{"atb":[[18.5,0],[7.4,0],[9.4,0]],"id":41419609},{"atb":[[18.5,0],[7.4,0],[9.4,0]],"id":41419607},{"atb":[[75,0],[40,0],[250,0]],"id":28546950},{"atb":[[9,0],[25,4.17],[12.5,0]],"id":41419615},{"atb":[[5.6,0],[7.2,0],[13,0]],"id":41419613},{"atb":[[5.6,0],[9.2,0],[4.6,0]],"id":41419611},{"atb":[[9,0],[25,0],[12.5,0]],"id":41419593},{"atb":[[700,0],[400,0],[500,0]],"id":41419657},{"atb":[[650,0],[350,0],[450,0]],"id":41435525},{"atb":[[75,0],[40,0],[250,0]],"id":41419653},{"atb":[[700,0],[400,0],[500,0]],"id":41435527},{"atb":[[16.5,0],[8.6,0],[6.6,0]],"id":41419587},{"atb":[[75,2.72],[40,0],[250,0]],"id":41419651},{"atb":[[4,0],[6,0],[3.5,0]],"id":41419618},{"atb":[[18,0],[42,0],[13,0]],"id":41419601},{"atb":[[24,0],[12,0],[8.8,0]],"id":41419599},{"atb":[[3.6,0],[6.4,0],[4.2,0]],"id":41419630},{"atb":[[4,0],[6,0],[3.5,0]],"id":41419597},{"atb":[[170,0],[44,0],[27,0]],"id":28546943},{"atb":[[3.45,0],[4.9,0],[2.98,0]],"id":41419628},{"atb":[[7.8,0],[14.5,0],[5.9,0]],"id":41419595},{"atb":[[10,0],[30,0],[15,6.01]],"id":41419659},{"atb":[[17.5,0],[40,0],[12.5,0]],"id":41419608},{"atb":[[17,0],[6.8,0],[8.8,0]],"id":41419606},{"atb":[[6.2,0],[8.2,0],[15.5,0]],"id":41419604},{"atb":[[9.2,0],[26,0],[13,0]],"id":41419602},{"atb":[[5.5,0],[12.5,0],[7,0]],"id":41419585},{"atb":[[7.2,0],[18,0],[9.2,0]],"id":41419616},{"atb":[[7.8,0],[14.5,0],[5.9,0]],"id":41419614},{"atb":[[5.6,0],[7.2,0],[13,0]],"id":41419592},{"atb":[[130,0],[65,0],[330,0]],"id":41419656},{"atb":[[5.6,0],[3.8,0],[3.3,0]],"id":41419590},{"atb":[[22,0],[11,0],[8.4,0]],"id":41419654},{"atb":[[5.5,0],[12.5,0],[7,0]],"id":41419588},{"atb":[[700,0],[400,0],[500,0]],"id":41419652},{"atb":[[8.6,0],[23,0],[11.5,0]],"id":41419586},{"atb":[[9.2,0],[26,0],[13,0]],"id":41419600},{"atb":[[3.45,0],[4.9,0],[2.98,0]],"id":41419631},{"atb":[[10,0],[5,0],[6,0]],"id":41419629},{"atb":[[4.3,0],[2.86,0],[3.15,0]],"id":41419627},{"atb":[[7.2,0],[18,0],[9.2,0]],"id":41419594},{"atb":[[130,0],[65,0],[330,0]],"id":41419658}],"con":true,"img":false}]}
{"op":"mcm","clk":"5353172983","pt":1646210280053,"mc":[{"id":"1.195503861","rc":[{"atl":[[1000,0]],"id":28546950}],"con":true,"img":false}]}
{"op":"mcm","clk":"5353173003","pt":1646210280314,"mc":[{"id":"1.195503861","rc":[{"atb":[[32,0],[26,0]],"id":41419616}],"con":true,"img":false}]}
{"op":"mcm","clk":"5353173008","pt":1646210280417,"mc":[{"id":"1.195503861","rc":[{"atb":[[7.2,16.13],[7.6,0]],"id":41419616}],"con":true,"img":false}]}
{"op":"mcm","clk":"5353173021","pt":1646210280528,"mc":[{"id":"1.195503861","rc":[{"atb":[[38,9.92],[42,3.87],[46,4.96],[14,16.63]],"id":41419609},{"atl":[[790,0.2],[820,1.49],[110,4.96]],"id":41419609},{"atb":[[25,9.92],[8.8,21.76],[29,8.23]],"id":41419607},{"atl":[[65,4.96],[590,0.26],[620,1.98],[85,9.92]],"id":41419607},{"atb":[[90,9.92],[30,12.39],[120,4.96]],"id":28546950},{"atb":[[70,4.96],[48,3.37],[50,9.92]],"id":41419615},{"atl":[[150,4.96],[880,0.18]],"id":41419615},{"atb":[[16,4.96],[6.6,26.8],[14,9.92]],"id":41419613},{"atl":[[34,4.96],[42,9.92],[450,0.35],[480,2.56]],"id":41419613},{"atb":[[19.5,9.92],[23,14.9],[6.8,26.18]],"id":41419611},{"atl":[[540,2.27],[42,4.96],[50,9.92],[510,0.31]],"id":41419611},{"atb":[[32,10.57],[260,0.61],[160,4.96],[120,9.92]],"id":41419657},{"atb":[[65,9.92],[85,4.96],[46,3.52],[14.5,16.35]],"id":41419593},{"atl":[[180,4.96],[880,0.18],[910,1.34]],"id":41419593},{"atb":[[130,4.96],[95,9.92],[110,4.18],[30,10.26]],"id":41435525},{"atl":[[990,0.15]],"id":41435525},{"atb":[[75,4.96],[80,4.73],[55,13.19]],"id":41419653},{"atl":[[220,4.96],[890,0.18]],"id":41419653},{"atb":[[160,4.96],[200,0.79],[30,10.57],[120,9.92]],"id":41435527},{"atb":[[17.5,9.92],[19.5,4.96],[6.2,24.04]],"id":41419587},{"atl":[[65,4.96],[530,2.31],[85,9.92],[500,0.31]],"id":41419587},{"atb":[[75,9.83],[55,9.92]],"id":41419651},{"atl":[[840,0.19]],"id":41419651},{"atb":[[10,9.92],[12,4.96],[5.2,32.75]],"id":41419618},{"atl":[[22,4.96],[380,0.42],[410,2.99],[26,9.92]],"id":41419618},{"atb":[[85,11.81],[110,4.96],[28,12.64]],"id":41419601},{"atl":[[990,0.15]],"id":41419601},{"atb":[[65,2.48],[70,9.92],[22,13.7],[90,4.96]],"id":41419599},{"atl":[[880,0.18],[910,1.34]],"id":41419599},{"atb":[[4.8,35.26],[10.5,7.69],[9.4,9.92]],"id":41419630},{"atl":[[18.5,4.96],[21,9.92],[370,3.32]],"id":41419630},{"atb":[[10,9.92],[5.3,32.2],[12,4.96],[14,11.67]],"id":41419597},{"atl":[[25,4.96],[410,0.38],[440,2.79],[29,9.92]],"id":41419597},{"atb":[[70,9.99],[19.5,14.35],[50,9.92]],"id":28546943},{"atl":[[820,0.19],[850,1.44]],"id":28546943},{"atb":[[4,42.27],[7.6,9.92],[7.8,11.67],[8.4,4.96]],"id":41419628},{"atl":[[16.5,9.92],[290,0.55],[320,3.84],[14.5,4.96]],"id":41419628},{"atb":[[32,4.96],[10,20.05],[27,12.65],[28,5.87]],"id":41419595},{"atl":[[80,4.96],[690,0.22],[720,1.7],[100,9.92]],"id":41419595},{"atb":[[90,9.92],[100,1.6],[15,14.95],[120,4.96]],"id":41419659},{"atl":[[990,0.15]],"id":41419659},{"atb":[[70,2.3],[80,9.92],[100,4.96],[30,12.39]],"id":41419608},{"atl":[[230,4.96],[990,0.15]],"id":41419608},{"atb":[[6.4,27.46],[19,9.92],[22,4.96]],"id":41419606},{"atl":[[530,2.31],[70,4.96],[90,9.92],[500,0.31]],"id":41419606},{"atb":[[80,4.96],[21,13.94],[42,3.87],[60,9.92]],"id":41419604},{"atl":[[160,4.96],[880,0.18],[910,1.34]],"id":41419604},{"atb":[[140,4.96],[70,2.3],[36,11.37],[100,9.92]],"id":41419602},{"atl":[[1000,0.15]],"id":41419602},{"atb":[[5.6,30.68],[17,9.92],[19,8.23]],"id":41419585},{"atl":[[75,9.92],[55,4.96],[470,0.33],[500,2.45]],"id":41419585},{"atb":[[18.5,9.92],[21,4.96],[7.6,8.94]],"id":41419616},{"atl":[[520,0.3],[550,2.23],[40,4.96],[48,9.92]],"id":41419616},{"atb":[[18,9.92],[20,4.96],[7.4,24.56]],"id":41419614},{"atl":[[540,2.27],[38,4.96],[46,9.92],[510,0.31]],"id":41419614},{"atb":[[5.3,32.2],[12,9.92],[14,4.96]],"id":41419592},{"atl":[[70,9.92],[50,4.96],[410,0.38],[440,2.79]],"id":41419592},{"atb":[[150,8.75],[110,9.92],[30,12.57]],"id":41419656},{"atb":[[11.5,9.92],[13,11.67],[13.5,4.96],[4.7,35.97]],"id":41419590},{"atl":[[24,4.96],[400,0.39],[430,2.86],[28,9.92]],"id":41419590},{"atb":[[8.2,22.83],[24,13.19],[28,4.96],[29,8.4]],"id":41419654},{"atl":[[75,4.96],[580,0.27],[610,2.01],[95,9.92]],"id":41419654},{"atb":[[26,16.27],[30,4.96],[9.4,20.84]],"id":41419588},{"atl":[[75,4.96],[600,0.26],[630,1.94],[95,9.92]],"id":41419588},{"atb":[[32,10.57],[160,4.96],[190,0.84],[120,9.92]],"id":41419652},{"atb":[[65,9.92],[85,4.96],[24,13.29]],"id":41419586},{"atl":[[170,4.96],[910,1.34]],"id":41419586},{"atb":[[70,2.3],[80,9.92],[100,4.96],[30,12.39]],"id":41419600},{"atl":[[240,4.96],[980,0.16]],"id":41419600},{"atb":[[8.2,16.63],[5.3,32.2],[7.4,9.92]],"id":41419631},{"atl":[[300,0.52],[330,3.72],[24,4.96],[28,9.92]],"id":41419631},{"atb":[[9,21.44],[22,9.92],[26,4.96]],"id":41419629},{"atl":[[70,4.96],[650,1.88],[90,9.92]],"id":41419629},{"atb":[[6.8,4.96],[6,9.92],[3.5,48.94]],"id":41419627},{"atl":[[11,4.96],[180,0.88],[13,9.92],[210,5.86]],"id":41419627},{"atb":[[20,9.92],[7.6,24.09],[24,4.96]],"id":41419594},{"atl":[[530,0.3],[560,2.19],[80,9.92],[60,4.96]],"id":41419594},{"atb":[[32,12.57],[160,7.69],[120,9.92]],"id":41419658}],"con":true,"img":false}]}
{"op":"mcm","clk":"5353173024","pt":1646210280625,"mc":[{"id":"1.195503861","rc":[{"atb":[[42,3.87]],"id":41419586},{"atl":[[880,0.18]],"id":41419586},{"atb":[[170,0.93]],"id":41419658},{"atl":[[1000,0.15]],"id":41419658}],"con":true,"img":false}]}
{"op":"mcm","clk":"5353173029","pt":1646210280734,"mc":[{"id":"1.195503861","rc":[{"atl":[[800,0],[400,2]],"id":41419609},{"atl":[[600,0],[230,2]],"id":41419607},{"atl":[[890,0],[490,2]],"id":41419615},{"atl":[[80,2],[460,0]],"id":41419613},{"atl":[[520,0],[140,2]],"id":41419611},{"atl":[[530,2],[890,0]],"id":41419593},{"atl":[[900,0],[500,2]],"id":41419653},{"atl":[[130,2],[510,0]],"id":41419587},{"atl":[[390,0],[55,2]],"id":41419618},{"atb":[[22,8.94],[28,3.7]],"id":41419599},{"atl":[[890,0],[900,2]],"id":41419599},{"atl":[[350,0],[44,2.33]],"id":41419630},{"atl":[[65,2],[420,0]],"id":41419597},{"atl":[[830,0],[840,2]],"id":28546943},{"atl":[[32,3.23],[300,0]],"id":41419628},{"atl":[[300,2],[700,0]],"id":41419595},{"atl":[[810,2],[1000,0]],"id":41419608},{"atl":[[130,2],[510,0]],"id":41419606},{"atl":[[890,0],[510,2]],"id":41419604},{"atl":[[110,2],[480,0]],"id":41419585},{"atl":[[530,0],[140,2]],"id":41419616},{"atl":[[520,0],[120,2]],"id":41419614},{"atl":[[70,11.92],[420,0]],"id":41419592},{"atl":[[590,0],[200,2]],"id":41419654},{"atl":[[70,2],[410,0]],"id":41419590},{"atl":[[280,2],[610,0]],"id":41419588},{"atl":[[530,2],[890,0]],"id":41419586},{"atl":[[730,2],[990,0]],"id":41419600},{"atl":[[65,2],[310,0]],"id":41419631},{"atl":[[260,2],[630,0]],"id":41419629},{"atl":[[21,5],[190,0]],"id":41419627},{"atl":[[540,0],[170,2]],"id":41419594}],"con":true,"img":false}]}
{"op":"mcm","clk":"5353173033","pt":1646210280829,"mc":[{"id":"1.195503861","rc":[{"atb":[[7.8,2.97]],"id":41419616}],"con":true,"img":false}]}
{"op":"mcm","clk":"5353173055","pt":1646210281139,"mc":[{"id":"1.195503861","rc":[{"atl":[[1000,1.22]],"id":41419608},{"atb":[[34,2.72],[27,3.27]],"id":41419616},{"atl":[[990,1.23]],"id":41419600}],"con":true,"img":false}]}
{"op":"mcm","clk":"5353173060","pt":1646210281243,"mc":[{"id":"1.195503861","rc":[{"atb":[[38,0],[42,8.83],[46,0]],"id":41419609},{"atl":[[70,2],[75,9.92],[50,0],[55,4.96]],"id":41419592},{"atl":[[240,0]],"id":41419600}],"con":true,"img":false}]}
{"op":"mcm","clk":"5353173067","pt":1646210281349,"mc":[{"id":"1.195503861","rc":[{"atb":[[25,13.11]],"id":41419615},{"atl":[[910,1.34]],"id":41419615},{"atb":[[27,12.79]],"id":41419653},{"atl":[[220,0],[920,1.33]],"id":41419653},{"atb":[[14.5,13.46]],"id":41419651},{"atl":[[870,1.4]],"id":41419651},{"atb":[[10.5,16.63]],"id":41419630},{"atl":[[340,0.46]],"id":41419630},{"atb":[[16.5,8.94]],"id":41419629},{"atl":[[620,0.25]],"id":41419629}],"con":true,"img":false}]}
{"op":"mcm","clk":"5353173077","pt":1646210281507,"mc":[{"id":"1.195503861","rc":[{"atb":[[14,7.69]],"id":41419609},{"atl":[[230,4.96]],"id":41419653},{"atl":[[850,0],[860,2]],"id":41419651},{"atl":[[75,0],[80,4.96],[95,0],[100,9.92]],"id":41419654}],"con":true,"img":false}]}
{"op":"mcm","clk":"5353173107","pt":1646210281923,"mc":[{"id":"1.195503861","rc":[{"atl":[[240,4.96]],"id":41419600}],"con":true,"img":false}]}
{"op":"mcm","clk":"5353173130","pt":1646210282335,"mc":[{"id":"1.195503861","rc":[{"atl":[[34,0],[42,0]],"id":41419613}],"con":true,"img":false}]}
{"op":"mcm","clk":"5353173151","pt":1646210282642,"mc":[{"id":"1.195503861","rc":[{"atl":[[36,4.96],[44,9.92]],"id":41419613}],"con":true,"img":false}]}
{"op":"mcm","clk":"5353173184","pt":1646210283112,"mc":[{"id":"1.195503861","rc":[{"atl":[[250,4.96]],"id":41419599}],"con":true,"img":false}]}
{"op":"mcm","clk":"5353173204","pt":1646210283416,"mc":[{"id":"1.195503861","rc":[{"atl":[[11,0],[11.5,4.96],[13,0],[13.5,9.92]],"id":41419627}],"con":true,"img":false}]}
{"op":"mcm","clk":"5353173226","pt":1646210283834,"mc":[{"id":"1.195503861","rc":[{"atb":[[18.5,7.62],[7.4,41.69],[9.4,31.76]],"id":41419609},{"atb":[[18.5,7.62],[7.4,41.69],[9.4,31.76]],"id":41419607},{"atb":[[75,3.6],[40,6.83],[250,0.53]],"id":28546950},{"atb":[[9,33.35],[25,18.67],[12.5,23.19]],"id":41419615},{"atb":[[5.6,58],[7.2,43.03],[13,11.11]],"id":41419613},{"atb":[[5.6,58],[9.2,16.26],[4.6,74.11]],"id":41419611},{"atb":[[9,33.35],[25,5.55],[12.5,23.19]],"id":41419593},{"atb":[[700,0.19],[400,0.67],[500,0.53]],"id":41419657},{"atb":[[650,0.2],[350,0.76],[450,0.59]],"id":41435525},{"atb":[[75,8.56],[40,6.83]],"id":41419653},{"atl":[[230,4.42]],"id":41419653},{"trd":[[230,1.06]],"ltp":230.0,"tv":1.06,"id":41419653},{"atb":[[700,0.19],[400,0.67],[500,0.53]],"id":41435527},{"atb":[[75,13.44],[40,6.83],[250,0.53]],"id":41419651},{"atb":[[16.5,8.6],[8.6,35.1],[6.6,47.64]],"id":41419587},{"atb":[[4,88.93],[6,26.68],[3.5,106.72]],"id":41419618},{"atb":[[18,15.69],[42,3.25],[13,22.23]],"id":41419601},{"atb":[[24,5.8],[12,24.25],[8.8,34.2]],"id":41419599},{"atl":[[250,0]],"id":41419599},{"atb":[[3.6,102.62],[6.4,24.7],[4.2,83.37]],"id":41419630},{"atb":[[4,88.93],[6,26.68],[3.5,106.72]],"id":41419597},{"atb":[[170,0.79],[44,6.2],[27,10.26]],"id":28546943},{"atb":[[3.45,108.9],[4.9,34.2],[2.98,134.75]],"id":41419628},{"atb":[[7.8,39.23],[14.5,9.87],[5.9,54.45]],"id":41419595},{"atb":[[10,29.64],[15,34.01],[30,4.6]],"id":41419659},{"atb":[[17.5,16.16],[40,3.42],[12.5,23.19]],"id":41419608},{"atb":[[17,8.34],[6.8,46],[8.8,34.2]],"id":41419606},{"atb":[[6.2,51.31],[8.2,37.05],[15.5,9.2]],"id":41419604},{"atb":[[9.2,32.53],[26,5.33],[13,22.23]],"id":41419602},{"atb":[[5.5,59.29],[12.5,11.59],[7,44.47]],"id":41419585},{"atb":[[7.2,59.16],[18,7.84],[9.2,32.53]],"id":41419616},{"atb":[[7.8,39.23],[14.5,9.87],[5.9,54.45]],"id":41419614},{"atb":[[5.6,58],[7.2,43.03],[13,11.11]],"id":41419592},{"atb":[[130,2.06],[65,4.17],[330,0.4]],"id":41419656},{"atb":[[22,6.35],[11,26.68],[8.4,36.05]],"id":41419654},{"atb":[[5.6,29],[3.8,95.28],[3.3,116]],"id":41419590},{"atb":[[5.5,59.29],[12.5,11.59],[7,44.47]],"id":41419588},{"atb":[[700,0.19],[400,0.67],[500,0.53]],"id":41419652},{"atb":[[8.6,35.1],[23,6.06],[11.5,25.4]],"id":41419586},{"atb":[[9.2,32.53],[26,5.33],[13,22.23]],"id":41419600},{"atb":[[3.45,108.9],[4.9,34.2],[2.98,134.75]],"id":41419631},{"atb":[[10,14.82],[5,66.7],[6,53.36]],"id":41419629},{"atb":[[4.3,40.42],[2.86,143.44],[3.15,124.09]],"id":41419627},{"atb":[[7.2,43.03],[18,7.84],[9.2,32.53]],"id":41419594},{"atb":[[130,2.06],[65,4.17],[330,0.4]],"id":41419658}],"con":true,"img":false}]}
{"op":"mcm","clk":"5353173256","pt":1646210284344,"mc":[{"id":"1.195503861","rc":[{"atb":[[32,2.45]],"id":41419652}],"con":true,"img":false}]}
{"op":"mcm","clk":"5353173267","pt":1646210284653,"mc":[{"id":"1.195503861","rc":[{"atb":[[32,2.45]],"id":41419657},{"atb":[[30,2.49]],"id":41435525},{"atb":[[85,0.53]],"id":41419653},{"atb":[[30,2.45]],"id":41435527},{"atl":[[250,4.96]],"id":41419599},{"atl":[[1000,0]],"id":41419658}],"con":true,"img":false}]}
{"op":"mcm","clk":"5353173291","pt":1646210285070,"mc":[{"id":"1.195503861","rc":[{"atb":[[12,9.09],[8.8,8.94]],"id":41419607},{"atb":[[50,2.04],[30,8.94]],"id":28546950},{"atl":[[1000,2]],"id":28546950},{"atb":[[25,14.5],[30,3.45]],"id":41419615},{"atb":[[8.2,13.89],[6.6,8.94]],"id":41419613},{"atb":[[6.8,8.94],[9.8,11.36]],"id":41419611},{"atb":[[32,0],[60,2]],"id":41419657},{"atb":[[48,2.13],[30,0]],"id":41435525},{"atb":[[55,2],[30,0]],"id":41435527},{"atb":[[6.2,8.94],[9.4,11.9]],"id":41419587},{"atb":[[6.8,17.24],[5.2,8.94]],"id":41419618},{"atb":[[48,2.13],[28,8.94]],"id":41419601},{"atb":[[4.8,8.94],[6.4,43.22]],"id":41419630},{"atb":[[7.2,16.13],[5.3,8.94]],"id":41419597},{"atb":[[19.5,8.94],[28,3.7]],"id":28546943},{"atb":[[4,8.94],[5,25]],"id":41419628},{"atb":[[10,8.94],[13,8.33]],"id":41419595},{"atb":[[48,2.13],[30,8.94]],"id":41419608},{"atb":[[6.4,8.94],[9.4,11.9]],"id":41419606},{"atb":[[34,3.03],[21,8.94]],"id":41419604},{"atb":[[36,8.51],[50,2.04]],"id":41419602},{"atb":[[5.6,8.94],[7.4,15.62]],"id":41419585},{"atb":[[9.2,12.2],[7.4,8.94]],"id":41419614},{"atb":[[5.3,8.94],[7.4,15.62]],"id":41419592},{"atb":[[50,2.04],[30,9.41]],"id":41419656},{"atb":[[6.2,19.23],[4.7,8.94]],"id":41419590},{"atb":[[8.2,8.94],[11.5,9.52]],"id":41419654},{"atb":[[32,0],[55,2]],"id":41419652},{"atb":[[13,8.33],[9.4,8.94]],"id":41419588},{"atb":[[36,2.86],[24,8.94]],"id":41419586},{"atb":[[46,5.49],[30,8.94]],"id":41419600},{"atb":[[7.2,19.4],[5.3,8.94]],"id":41419631},{"atb":[[9,8.94],[12.5,8.7]],"id":41419629},{"atb":[[3.5,8.94],[4.2,31.25]],"id":41419627},{"atb":[[32,9.41],[55,2]],"id":41419658},{"atb":[[10.5,10.53],[7.6,8.94]],"id":41419594}],"con":true,"img":false}]}
{"op":"mcm","clk":"5353173343","pt":1646210285848,"mc":[{"id":"1.195503861","rc":[{"atl":[[790,2.2],[400,0]],"id":41419609},{"atl":[[880,2.18],[490,0]],"id":41419615},{"atl":[[530,0],[880,2.18]],"id":41419593},{"atl":[[890,2.18],[500,0]],"id":41419653},{"atl":[[840,0],[850,3.44]],"id":28546943},{"atl":[[810,0],[990,2.15]],"id":41419608},{"atl":[[880,2.18],[510,0]],"id":41419604},{"atl":[[70,0],[75,11.92]],"id":41419592},{"atl":[[530,0],[880,2.18]],"id":41419586},{"atl":[[730,0],[980,2.16]],"id":41419600}],"con":true,"img":false}]}
{"op":"mcm","clk":"5353173394","pt":1646210286620,"mc":[{"id":"1.195503861","rc":[{"atl":[[860,0],[870,3.4]],"id":41419651}],"con":true,"img":false}]}
{"op":"mcm","clk":"5353173441","pt":1646210287547,"mc":[{"id":"1.195503861","rc":[{"atb":[[9.8,9.92]],"id":41419616}],"con":true,"img":false}]}
{"op":"mcm","clk":"5353173446","pt":1646210287649,"mc":[{"id":"1.195503861","rc":[{"atb":[[7.2,43.03]],"id":41419616}],"con":true,"img":false}]}
{"op":"mcm","clk":"5353173465","pt":1646210287958,"mc":[{"id":"1.195503861","rc":[{"atb":[[38,2.7],[28,0]],"id":41419599}],"con":true,"img":false}]}
{"op":"mcm","clk":"5353173524","pt":1646210289045,"mc":[{"id":"1.195503861","rc":[{"atl":[[40,4.96],[48,9.92]],"id":41419613},{"atl":[[230,0]],"id":41419653},{"atl":[[40,0],[48,0]],"id":41419616},{"atb":[[20,9.92],[24,4.96]],"id":41419629}],"con":true,"img":false}]}
{"op":"mcm","clk":"5353173530","pt":1646210289143,"mc":[{"id":"1.195503861","rc":[{"atb":[[18.5,0],[22,0]],"id":41419613},{"atl":[[36,0],[44,0]],"id":41419613},{"atl":[[250,4.96]],"id":41419601},{"atl":[[46,4.96],[60,9.92]],"id":41419616},{"atl":[[1000,0.15]],"id":41419656},{"atb":[[22,0],[26,0]],"id":41419629}],"con":true,"img":false}]}
{"op":"mcm","clk":"5353173533","pt":1646210289248,"mc":[{"id":"1.195503861","rc":[{"atl":[[810,2],[1000,0]],"id":41419601}],"con":true,"img":false}]}
{"op":"mcm","clk":"5353173548","pt":1646210289557,"mc":[{"id":"1.195503861","rc":[{"atl":[[810,0],[990,2.15],[1000,1.25]],"id":41419601}],"con":true,"img":false}]}
{"op":"mcm","clk":"5353173566","pt":1646210289917,"mc":[{"id":"1.195503861","rc":[{"atb":[[16,6.05],[19,3.27],[23,2.72]],"id":41419613}],"con":true,"img":false}]}
{"op":"mcm","clk":"5353173615","pt":1646210291047,"mc":[{"id":"1.195503861","rc":[{"atl":[[890,0.18],[910,2]],"id":41419653},{"atl":[[75,9.92],[410,2.38]],"id":41419592}],"con":true,"img":false}]}
{"op":"mcm","clk":"5353173882","pt":1646210296255,"mc":[{"id":"1.195503861","rc":[{"atl":[[110,6.41]],"id":41419609},{"atb":[[25,29.57],[8.8,0]],"id":41419607},{"atl":[[620,0],[230,7.54]],"id":41419607},{"atb":[[120,12],[30,0]],"id":28546950},{"atb":[[70,7.26]],"id":41419615},{"atl":[[150,6.02]],"id":41419615},{"atb":[[16,18.32],[6.6,0]],"id":41419613},{"atl":[[40,9.03],[80,14.26],[480,0]],"id":41419613},{"atb":[[19,25.42],[6.8,0]],"id":41419611},{"atl":[[540,0],[140,11.12],[42,8.83]],"id":41419611},{"atb":[[85,6.85],[46,16.16],[14.5,7.41]],"id":41419593},{"atl":[[180,5.85]],"id":41419593},{"atb":[[85,2.42]],"id":41419653},{"atb":[[19.5,17.22],[6.2,0]],"id":41419587},{"atl":[[530,0],[60,2.69]],"id":41419587},{"atb":[[12,17.22],[5.2,0]],"id":41419618},{"atl":[[22,12.52],[410,0],[55,14.26]],"id":41419618},{"atb":[[80,14.17],[110,6.41],[28,0]],"id":41419601},{"atl":[[250,5.6]],"id":41419601},{"atb":[[65,13.55],[90,6.74],[22,0]],"id":41419599},{"atl":[[900,3.4],[910,0],[240,0.66]],"id":41419599},{"atb":[[4.8,0],[9.2,25.42]],"id":41419630},{"atl":[[44,24.48]],"id":41419630},{"atb":[[5.3,0],[11.5,18.04]],"id":41419597},{"atl":[[65,16.76],[25,11.57],[440,0]],"id":41419597},{"atb":[[19.5,0],[50,20.16]],"id":28546943},{"atl":[[850,2],[840,1.51]],"id":28546943},{"atb":[[4,0],[7.6,32.07],[8.4,26.41]],"id":41419628},{"atl":[[32,25.38],[320,0],[14.5,16.72]],"id":41419628},{"atb":[[32,10.08],[10,0],[27,28.78]],"id":41419595},{"atl":[[300,6.25],[80,6.97],[720,0]],"id":41419595},{"atb":[[120,6.29]],"id":41419659},{"atb":[[70,13.11],[100,6.56],[30,0]],"id":41419608},{"atl":[[230,5.65]],"id":41419608},{"atb":[[6.4,0],[22,17.22]],"id":41419606},{"atl":[[130,11.82],[530,0],[65,2.48]],"id":41419606},{"atb":[[80,6.97],[42,17.03],[21,0]],"id":41419604},{"atl":[[160,5.96]],"id":41419604},{"atb":[[70,13.11],[36,0],[150,1.06]],"id":41419602},{"atb":[[5.6,0],[17,29.57]],"id":41419585},{"atl":[[50,3.24],[110,13.61],[500,0]],"id":41419585},{"atb":[[21,17.22],[7.6,0]],"id":41419616},{"atl":[[140,11.12],[550,0]],"id":41419616},{"atb":[[20,17.22]],"id":41419614},{"atl":[[540,0],[120,12.64]],"id":41419614},{"atb":[[5.3,0],[14,17.22]],"id":41419592},{"atl":[[50,3.24],[440,0]],"id":41419592},{"atb":[[130,5.74],[30,0]],"id":41419656},{"atb":[[11.5,32.07],[13.5,17.66]],"id":41419590},{"atl":[[24,11.86],[430,0]],"id":41419590},{"atb":[[8.2,0],[24,33.08]],"id":41419654},{"atl":[[75,2.14],[610,0],[200,8.38]],"id":41419654},{"atb":[[25,17.49],[30,10.43],[9.4,0]],"id":41419588},{"atl":[[280,6.55],[75,7.1],[630,0]],"id":41419588},{"atb":[[42,17.03],[24,0]],"id":41419586},{"atb":[[70,13.11],[100,6.56],[30,0]],"id":41419600},{"atl":[[240,5.62]],"id":41419600},{"atb":[[7.2,48.94],[5.3,0]],"id":41419631},{"atl":[[65,21.65],[330,0],[24,11.86]],"id":41419631},{"atb":[[16.5,29.65],[9,0]],"id":41419629},{"atl":[[260,6.9],[650,0]],"id":41419629},{"atb":[[6.2,18.04],[3.5,0]],"id":41419627},{"atl":[[21,19.76],[11.5,19.72]],"id":41419627},{"atb":[[7.6,0]],"id":41419594},{"atl":[[560,0],[170,9.51],[55,2.94]],"id":41419594},{"atb":[[32,0],[160,10.49]],"id":41419658}],"con":true,"img":false}]}
{"op":"mcm","clk":"5353173887","pt":1646210296354,"mc":[{"id":"1.195503861","rc":[{"atl":[[130,11.82]],"id":41419587},{"atl":[[130,1.23]],"id":41419616},{"atb":[[7.4,0]],"id":41419614},{"atl":[[410,5.49]],"id":41419592},{"atb":[[4.7,0]],"id":41419590},{"atl":[[210,0]],"id":41419627}],"con":true,"img":false}]}
{"op":"mcm","clk":"5353173898","pt":1646210296453,"mc":[{"id":"1.195503861","rc":[{"atl":[[70,2],[410,3.49]],"id":41419592}],"con":true,"img":false}]}
{"op":"mcm","clk":"5353173906","pt":1646210296560,"mc":[{"id":"1.195503861","rc":[{"atb":[[95,8.68],[15,25.06]],"id":41419659},{"atl":[[70,20.25]],"id":41419590},{"atb":[[85,6.85]],"id":41419586},{"atl":[[170,5.9]],"id":41419586}],"con":true,"img":false}]}
{"op":"mcm","clk":"5353173931","pt":1646210297075,"mc":[{"id":"1.195503861","rc":[{"atb":[[30,12.22]],"id":41419609},{"atl":[[790,2]],"id":41419609},{"atb":[[48,14],[25,5.55]],"id":41419615},{"atl":[[880,2]],"id":41419615},{"atl":[[450,0]],"id":41419613},{"atl":[[510,0]],"id":41419611},{"atb":[[46,12.63]],"id":41419593},{"atl":[[880,2]],"id":41419593},{"atb":[[75,15.14],[80,2.72],[27,3.85]],"id":41419653},{"atl":[[500,0]],"id":41419587},{"atb":[[55,20.07],[14.5,4.52]],"id":41419651},{"atl":[[870,2]],"id":41419651},{"atl":[[380,0]],"id":41419618},{"atb":[[85,9.92]],"id":41419601},{"atl":[[990,2]],"id":41419601},{"atb":[[65,11.07]],"id":41419599},{"atl":[[880,0]],"id":41419599},{"atl":[[410,0]],"id":41419597},{"atl":[[840,0]],"id":28546943},{"atb":[[7.8,2.72]],"id":41419628},{"atl":[[290,0]],"id":41419628},{"atb":[[100,0]],"id":41419659},{"atb":[[28,0]],"id":41419595},{"atl":[[690,0]],"id":41419595},{"atb":[[70,10.8]],"id":41419608},{"atl":[[990,2]],"id":41419608},{"atl":[[500,0]],"id":41419606},{"atb":[[42,13.16]],"id":41419604},{"atl":[[880,2]],"id":41419604},{"atb":[[70,10.8]],"id":41419602},{"atl":[[470,0]],"id":41419585},{"atl":[[410,3.1]],"id":41419592},{"atb":[[13,2.72]],"id":41419590},{"atl":[[400,0]],"id":41419590},{"atl":[[580,0]],"id":41419654},{"atb":[[26,9.92]],"id":41419588},{"atl":[[600,0]],"id":41419588},{"atb":[[70,10.8]],"id":41419600},{"atl":[[980,2]],"id":41419600},{"atl":[[300,0]],"id":41419631},{"atb":[[25,6.61]],"id":41419629},{"atl":[[70,7.26]],"id":41419629},{"atl":[[180,0]],"id":41419627},{"atb":[[24,17.22]],"id":41419594},{"atl":[[530,0]],"id":41419594}],"con":true,"img":false}]}
{"op":"mcm","clk":"5353173937","pt":1646210297132,"mc":[{"id":"1.195503861","rc":[{"atl":[[18.5,14.03],[370,0]],"id":41419630}],"con":true,"img":false}]}
{"op":"mcm","clk":"5353173941","pt":1646210297232,"mc":[{"id":"1.195503861","rc":[{"atl":[[860,1.47]],"id":41419651}],"con":true,"img":false}]}
{"op":"mcm","clk":"5353173946","pt":1646210297336,"mc":[{"id":"1.195503861","rc":[{"atl":[[520,0]],"id":41419616},{"atl":[[880,2]],"id":41419586}],"con":true,"img":false}]}
{"op":"mcm","clk":"5353173951","pt":1646210297439,"mc":[{"id":"1.195503861","rc":[{"atb":[[42,13.16]],"id":41419586}],"con":true,"img":false}]}
{"op":"mcm","clk":"5353173967","pt":1646210297851,"mc":[{"id":"1.195503861","rc":[{"atl":[[620,0]],"id":41419629}],"con":true,"img":false}]}
{"op":"mcm","clk":"5353173988","pt":1646210298164,"mc":[{"id":"1.195503861","rc":[{"atl":[[340,0]],"id":41419630},{"atb":[[16.5,20.7]],"id":41419629}],"con":true,"img":false}]}
{"op":"mcm","clk":"5353174008","pt":1646210298630,"mc":[{"id":"1.195503861","rc":[{"atb":[[25,0]],"id":41419629}],"con":true,"img":false}]}
{"op":"mcm","clk":"5353174024","pt":1646210298939,"mc":[{"id":"1.195503861","rc":[{"atl":[[40,4.07],[42,4.96],[48,0],[50,9.92]],"id":41419613},{"atl":[[250,0.63]],"id":41419601},{"atl":[[1000,0]],"id":41419656}],"con":true,"img":false}]}
{"op":"mcm","clk":"5353174028","pt":1646210299041,"mc":[{"id":"1.195503861","rc":[{"atl":[[40,0]],"id":41419613}],"con":true,"img":false}]}
{"op":"mcm","clk":"5353174039","pt":1646210299349,"mc":[{"id":"1.195503861","rc":[{"atl":[[990,0],[1000,3.25]],"id":41419601},{"atb":[[21,7.94]],"id":41419629}],"con":true,"img":false}]}
{"op":"mcm","clk":"5353174063","pt":1646210299769,"mc":[{"id":"1.195503861","rc":[{"atl":[[75,2.14]],"id":41419613}],"con":true,"img":false}]}
{"op":"mcm","clk":"5353174079","pt":1646210300125,"mc":[{"id":"1.195503861","rc":[{"atl":[[1000,2]],"id":41419601}],"con":true,"img":false}]}
{"op":"mcm","clk":"5353174096","pt":1646210300436,"mc":[{"id":"1.195503861","rc":[{"atl":[[260,4.96]],"id":41419601}],"con":true,"img":false}]}
{"op":"mcm","clk":"5353174108","pt":1646210300643,"mc":[{"id":"1.195503861","rc":[{"atl":[[1000,0]],"id":28546950}],"con":true,"img":false}]}
{"op":"mcm","clk":"5353174137","pt":1646210301263,"mc":[{"id":"1.195503861","rc":[{"atl":[[38,0],[46,0]],"id":41419614}],"con":true,"img":false}]}
{"op":"mcm","clk":"5353174150","pt":1646210301533,"mc":[{"id":"1.195503861","rc":[{"atl":[[130,2],[40,4.96],[48,9.92],[120,10.64]],"id":41419614}],"con":true,"img":false}]}
{"op":"mcm","clk":"5353174191","pt":1646210301857,"mc":[{"id":"1.195503861","rc":[{"atl":[[110,1.45]],"id":41419614}],"con":true,"img":false}]}
{"op":"mcm","clk":"5353174238","pt":1646210302626,"mc":[{"id":"1.195503861","rc":[{"atl":[[510,0]],"id":41419614}],"con":true,"img":false}]}
{"op":"mcm","clk":"5353174303","pt":1646210303769,"mc":[{"id":"1.195503861","rc":[{"atb":[[27,12.65]],"id":41419595}],"con":true,"img":false}]}
{"op":"mcm","clk":"5353174330","pt":1646210304177,"mc":[{"id":"1.195503861","rc":[{"atb":[[22,28.41]],"id":41419595},{"atb":[[90,24.36],[95,2.72]],"id":41419659}],"con":true,"img":false}]}
{"op":"mcm","clk":"5353174354","pt":1646210304447,"mc":[{"id":"1.195503861","rc":[{"atb":[[34,3.03]],"id":41419653}],"con":true,"img":false}]}
{"op":"mcm","clk":"5353174364","pt":1646210304545,"mc":[{"id":"1.195503861","rc":[{"atl":[[1000,2]],"id":28546950},{"atl":[[1000,0]],"id":41435525},{"atb":[[27,0]],"id":41419653}],"con":true,"img":false}]}
{"op":"mcm","clk":"5353174380","pt":1646210304753,"mc":[{"id":"1.195503861","rc":[{"atb":[[36,0],[46,0]],"id":41419615},{"atl":[[42,3.87],[46,4.96],[50,0],[60,9.92]],"id":41419611},{"atb":[[200,0],[250,0]],"id":41419657},{"atl":[[870,3.48]],"id":41419651},{"atl":[[22,4.96]],"id":41419618},{"atb":[[80,11.44],[55,0]],"id":41419601},{"atb":[[44,0],[60,0]],"id":41419599},{"atl":[[230,0.69],[250,4.96]],"id":41419608},{"atb":[[32,0],[26,0]],"id":41419606},{"atb":[[65,0],[46,0]],"id":41419602},{"atb":[[16,9.92],[18,4.96]],"id":41419585},{"atb":[[40,0],[30,0]],"id":41419586},{"atb":[[16,0],[13.5,0]],"id":41419629}],"con":true,"img":false}]}
{"op":"mcm","clk":"5353174383","pt":1646210304853,"mc":[{"id":"1.195503861","rc":[{"atl":[[860,0]],"id":41419651},{"atb":[[17,19.65],[19,3.27]],"id":41419585},{"atb":[[130,0],[180,0]],"id":41419652}],"con":true,"img":false}]}
{"op":"mcm","clk":"5353174388","pt":1646210304956,"mc":[{"id":"1.195503861","rc":[{"atl":[[940,2],[990,0]],"id":41419608}],"con":true,"img":false}]}
{"op":"mcm","clk":"5353174394","pt":1646210305061,"mc":[{"id":"1.195503861","rc":[{"atl":[[110,1.45],[120,4.96]],"id":41419609},{"atl":[[260,0],[1000,3.29]],"id":41419601}],"con":true,"img":false}]}
{"op":"mcm","clk":"5353174402","pt":1646210305264,"mc":[{"id":"1.195503861","rc":[{"atl":[[790,0],[430,2]],"id":41419609}],"con":true,"img":false}]}
{"op":"mcm","clk":"5353174408","pt":1646210305366,"mc":[{"id":"1.195503861","rc":[{"atl":[[990,1.3]],"id":41419608},{"atb":[[17,35.52],[22,12.52]],"id":41419606},{"atl":[[65,0]],"id":41419606}],"con":true,"img":false}]}
{"op":"mcm","clk":"5353174416","pt":1646210305475,"mc":[{"id":"1.195503861","rc":[{"atl":[[820,0]],"id":41419609},{"atb":[[38,3.27],[48,16.73]],"id":41419615},{"atb":[[260,3.34],[210,3.27]],"id":41419657},{"atl":[[870,2]],"id":41419651},{"atl":[[26,16.27]],"id":41419618},{"atl":[[250,0]],"id":41419601},{"atb":[[65,13.8],[46,3.27]],"id":41419599},{"atl":[[1000,0]],"id":41419608},{"atb":[[70,13.53],[48,3.27]],"id":41419602},{"atb":[[32,3.27],[42,15.88]],"id":41419586},{"atb":[[16.5,23.43],[14,3.27]],"id":41419629}],"con":true,"img":false}]}
{"op":"mcm","clk":"5353174420","pt":1646210305574,"mc":[{"id":"1.195503861","rc":[{"atb":[[85,12.65],[60,3.27]],"id":41419601},{"atb":[[34,2.72],[27,3.27]],"id":41419606}],"con":true,"img":false}]}
{"op":"mcm","clk":"5353174426","pt":1646210305679,"mc":[{"id":"1.195503861","rc":[{"atl":[[790,1.64]],"id":41419609}],"con":true,"img":false}]}
{"op":"mcm","clk":"5353174429","pt":1646210305729,"mc":[{"id":"1.195503861","rc":[{"atb":[[140,3.27],[190,3.56]],"id":41419652}],"con":true,"img":false}]}
{"op":"mcm","clk":"5353174438","pt":1646210305882,"mc":[{"id":"1.195503861","rc":[{"atl":[[1000,2]],"id":41419601}],"con":true,"img":false}]}
{"op":"mcm","clk":"5353174450","pt":1646210306038,"mc":[{"id":"1.195503861","rc":[{"atl":[[65,2.48]],"id":41419606}],"con":true,"img":false}]}
{"op":"mcm","clk":"5353174465","pt":1646210306350,"mc":[{"id":"1.195503861","rc":[{"atl":[[990,0.15]],"id":41419601}],"con":true,"img":false}]}
{"op":"mcm","clk":"5353174508","pt":1646210307169,"mc":[{"id":"1.195503861","rc":[{"atl":[[240,0]],"id":41419599}],"con":true,"img":false}]}
{"op":"mcm","clk":"5353174551","pt":1646210307842,"mc":[{"id":"1.195503861","rc":[{"atl":[[250,5.6]],"id":41419599}],"con":true,"img":false}]}
{"op":"mcm","clk":"5353174648","pt":1646210309746,"mc":[{"id":"1.195503861","rc":[{"atl":[[42,0],[50,0]],"id":41419613}],"con":true,"img":false}]}
{"op":"mcm","clk":"5353174662","pt":1646210310056,"mc":[{"id":"1.195503861","rc":[{"atl":[[44,4.96],[55,9.92]],"id":41419613},{"atl":[[260,4.96]],"id":41419601},{"atl":[[65,9.92],[46,0],[48,4.96],[60,0]],"id":41419616}],"con":true,"img":false}]}
{"op":"mcm","clk":"5353174669","pt":1646210310156,"mc":[{"id":"1.195503861","rc":[{"atl":[[900,2],[1000,0]],"id":41419601}],"con":true,"img":false}]}
{"op":"mcm","clk":"5353174687","pt":1646210310468,"mc":[{"id":"1.195503861","rc":[{"atl":[[80,2],[85,9.76]],"id":41419613}],"con":true,"img":false}]}
{"op":"mcm","clk":"5353174707","pt":1646210310777,"mc":[{"id":"1.195503861","rc":[{"atl":[[40,0],[42,4.96],[48,0],[50,9.92]],"id":41419614}],"con":true,"img":false}]}
{"op":"mcm","clk":"5353174713","pt":1646210310878,"mc":[{"id":"1.195503861","rc":[{"atl":[[910,0]],"id":41419653}],"con":true,"img":false}]}
{"op":"mcm","clk":"5353174719","pt":1646210310981,"mc":[{"id":"1.195503861","rc":[{"atl":[[920,3.33]],"id":41419653}],"con":true,"img":false}]}
{"op":"mcm","clk":"5353174736","pt":1646210311241,"mc":[{"id":"1.195503861","rc":[{"atl":[[85,0]],"id":41419613}],"con":true,"img":false}]}
{"op":"mcm","clk":"5353174750","pt":1646210311449,"mc":[{"id":"1.195503861","rc":[{"atl":[[920,2],[910,1.27]],"id":41419653}],"con":true,"img":false}]}
{"op":"mcm","clk":"5353174762","pt":1646210311656,"mc":[{"id":"1.195503861","rc":[{"atl":[[75,14.41],[44,8.65]],"id":41419613},{"atl":[[140,2],[60,31.94]],"id":41419611},{"atl":[[260,5.57]],"id":41419601},{"atl":[[270,4.88],[900,2]],"id":41419599},{"atl":[[840,1.56]],"id":28546943},{"atb":[[17,8.34],[22,24.78]],"id":41419606},{"atb":[[70,2.72],[100,18.88]],"id":41419602},{"atb":[[17,0],[18,17.22]],"id":41419585},{"atl":[[75,22.18],[110,2]],"id":41419585},{"atl":[[130,11.39],[140,2]],"id":41419616},{"atl":[[110,13.46],[120,0]],"id":41419614},{"atl":[[100,23.13],[200,2]],"id":41419654},{"atl":[[80,22.18],[170,2]],"id":41419594}],"con":true,"img":false}]}
{"op":"mcm","clk":"5353174766","pt":1646210311759,"mc":[{"id":"1.195503861","rc":[{"atl":[[130,2],[85,22.18]],"id":41419587},{"atl":[[530,2],[900,0]],"id":41419599},{"atl":[[130,2],[90,22.18]],"id":41419606},{"atl":[[70,11.7],[410,0]],"id":41419592},{"atb":[[16.5,2.72],[20,32.56]],"id":41419629}],"con":true,"img":false}]}
{"op":"mcm","clk":"5353174772","pt":1646210311860,"mc":[{"id":"1.195503861","rc":[{"atl":[[120,1.33]],"id":41419616}],"con":true,"img":false}]}
{"op":"mcm","clk":"5353174803","pt":1646210312380,"mc":[{"id":"1.195503861","rc":[{"atl":[[990,0]],"id":41419601}],"con":true,"img":false}]}
{"op":"mcm","clk":"5353174820","pt":1646210312638,"mc":[{"id":"1.195503861","rc":[{"atl":[[75,12.26]],"id":41419613},{"atl":[[860,1.52]],"id":41419651},{"atb":[[24,11.86]],"id":41419629}],"con":true,"img":false}]}
{"op":"mcm","clk":"5353174827","pt":1646210312741,"mc":[{"id":"1.195503861","rc":[{"atl":[[130,10.15]],"id":41419616}],"con":true,"img":false}]}
{"op":"mcm","clk":"5353174874","pt":1646210313472,"mc":[{"id":"1.195503861","rc":[{"atb":[[21,0]],"id":41419629}],"con":true,"img":false}]}
{"op":"mcm","clk":"5353174984","pt":1646210315274,"mc":[{"id":"1.195503861","rc":[{"atl":[[900,0],[990,2]],"id":41419601}],"con":true,"img":false}]}
{"op":"mcm","clk":"5353175083","pt":1646210317175,"mc":[{"id":"1.195503861","rc":[{"atl":[[42,8.83]],"id":41419614}],"con":true,"img":false}]}
{"op":"mcm","clk":"5353175118","pt":1646210317844,"mc":[{"id":"1.195503861","rc":[{"atl":[[110,12]],"id":41419614}],"con":true,"img":false}]}
{"op":"mcm","clk":"5353175153","pt":1646210318458,"mc":[{"id":"1.195503861","rc":[{"atl":[[260,0.61]],"id":41419601}],"con":true,"img":false}]}
{"op":"mcm","clk":"5353175171","pt":1646210318868,"mc":[{"id":"1.195503861","rc":[{"atl":[[910,0],[920,3.27]],"id":41419653},{"atl":[[270,4.96]],"id":41419601}],"con":true,"img":false}]}
{"op":"mcm","clk":"5353175188","pt":1646210319176,"mc":[{"id":"1.195503861","rc":[{"atl":[[270,0],[530,4.52]],"id":41419599},{"atl":[[840,0],[850,3.57]],"id":28546943},{"atb":[[16.5,28.31],[20,9.92]],"id":41419629}],"con":true,"img":false}]}
{"op":"mcm","clk":"5353175218","pt":1646210319591,"mc":[{"id":"1.195503861","rc":[{"atl":[[920,2]],"id":41419653}],"con":true,"img":false}]}
{"op":"mcm","clk":"5353175231","pt":1646210319750,"mc":[{"id":"1.195503861","rc":[{"atl":[[46,4.96],[60,9.92]],"id":41419613},{"atl":[[65,0],[48,0]],"id":41419616}],"con":true,"img":false}]}
{"op":"mcm","clk":"5353175238","pt":1646210319898,"mc":[{"id":"1.195503861","rc":[{"atl":[[44,0],[55,0]],"id":41419613},{"atl":[[860,3.52]],"id":41419651},{"atl":[[140,0],[70,9.92],[150,2],[50,4.96]],"id":41419616}],"con":true,"img":false}]}
{"op":"mcm","clk":"5353175244","pt":1646210319956,"mc":[{"id":"1.195503861","rc":[{"atl":[[310,2],[230,5.54]],"id":41419607},{"atb":[[36,2.86],[30,0]],"id":41419615},{"atl":[[870,0]],"id":41419651},{"atl":[[940,0]],"id":41419608},{"atb":[[7.2,32.81],[7,16.67]],"id":41419631}],"con":true,"img":false}]}
{"op":"mcm","clk":"5353175248","pt":1646210320057,"mc":[{"id":"1.195503861","rc":[{"atb":[[24,4.96]],"id":41419629}],"con":true,"img":false}]}
{"op":"mcm","clk":"5353175254","pt":1646210320162,"mc":[{"id":"1.195503861","rc":[{"atb":[[38,7.01]],"id":41419607},{"atl":[[65,2.7],[80,4.96],[85,0],[100,9.92]],"id":41419607},{"atl":[[150,1.06],[160,4.96]],"id":41419615},{"atb":[[65,4.96],[75,11.29]],"id":41419651},{"atl":[[860,2],[870,1.53]],"id":41419651},{"atb":[[14,2.72]],"id":41419597},{"atl":[[270,4.96],[250,0]],"id":41419608},{"atb":[[34,0],[27,0]],"id":41419606},{"atl":[[65,0]],"id":41419606},{"atl":[[130,0],[140,8.94]],"id":41419616},{"atl":[[42,0],[44,4.96],[50,0],[55,9.92]],"id":41419614},{"atb":[[14,4.96]],"id":41419592},{"atb":[[10.5,13.19],[11.5,22.15],[12.5,4.96],[13.5,0]],"id":41419590},{"atb":[[19.5,9.92],[20,0],[23,4.96],[24,0]],"id":41419629}],"con":true,"img":false}]}
{"op":"mcm","clk":"5353175257","pt":1646210320261,"mc":[{"id":"1.195503861","rc":[{"atl":[[520,2]],"id":41419615},{"atb":[[75,6.33],[55,10.15]],"id":41419651},{"atb":[[12,0],[13,16.08],[14,0]],"id":41419592}],"con":true,"img":false}]}
{"op":"mcm","clk":"5353175261","pt":1646210320365,"mc":[{"id":"1.195503861","rc":[{"atl":[[880,0]],"id":41419615}],"con":true,"img":false}]}
{"op":"mcm","clk":"5353175268","pt":1646210320469,"mc":[{"id":"1.195503861","rc":[{"atl":[[60,0]],"id":41419587},{"atl":[[990,3.34]],"id":41419601},{"atl":[[1000,0.15]],"id":41419656},{"atl":[[1000,0.15]],"id":41419658}],"con":true,"img":false}]}
{"op":"mcm","clk":"5353175272","pt":1646210320569,"mc":[{"id":"1.195503861","rc":[{"atl":[[100,23.38]],"id":41419607},{"atb":[[65,10.22]],"id":41419651},{"atl":[[70,0],[75,9.92],[50,0],[55,4.96]],"id":41419616}],"con":true,"img":false}]}
{"op":"mcm","clk":"5353175277","pt":1646210320674,"mc":[{"id":"1.195503861","rc":[{"atl":[[230,0]],"id":41419607},{"atl":[[880,1.52],[910,0]],"id":41419615},{"atl":[[70,2.3]],"id":41419613},{"atb":[[55,0]],"id":41419651},{"atb":[[17,35.52],[22,12.52]],"id":41419606},{"atl":[[130,12.35],[90,9.92]],"id":41419606},{"atb":[[13,28.34]],"id":41419592}],"con":true,"img":false}]}
{"op":"mcm","clk":"5353175282","pt":1646210320776,"mc":[{"id":"1.195503861","rc":[{"atb":[[20,8.35]],"id":41419629}],"con":true,"img":false}]}
{"op":"mcm","clk":"5353175286","pt":1646210320877,"mc":[{"id":"1.195503861","rc":[{"atl":[[790,0],[430,5.12]],"id":41419609},{"atl":[[590,0]],"id":41419607},{"atb":[[12,19.39]],"id":41419597},{"atb":[[36,2.72],[28,3.27]],"id":41419606},{"atl":[[70,7.26]],"id":41419606},{"atl":[[100,1.6]],"id":41419614},{"atb":[[13,15.96]],"id":41419590}],"con":true,"img":false}]}
{"op":"mcm","clk":"5353175289","pt":1646210320978,"mc":[{"id":"1.195503861","rc":[{"atl":[[130,12.36]],"id":41419587}],"con":true,"img":false}]}
{"op":"mcm","clk":"5353175294","pt":1646210321083,"mc":[{"id":"1.195503861","rc":[{"atl":[[85,9.92]],"id":41419587}],"con":true,"img":false}]}
{"op":"mcm","clk":"5353175296","pt":1646210321185,"mc":[{"id":"1.195503861","rc":[{"atl":[[1000,0]],"id":41419656}],"con":true,"img":false}]}
{"op":"mcm","clk":"5353175301","pt":1646210321291,"mc":[{"id":"1.195503861","rc":[{"atl":[[60,2.69]],"id":41419587},{"atl":[[1000,0]],"id":41419658}],"con":true,"img":false}]}
{"op":"mcm","clk":"5353175318","pt":1646210321594,"mc":[{"id":"1.195503861","rc":[{"atl":[[260,0]],"id":41419601}],"con":true,"img":false}]}
{"op":"mcm","clk":"5353175321","pt":1646210321646,"mc":[{"id":"1.195503861","rc":[{"atl":[[270,0]],"id":41419601}],"con":true,"img":false}]}
{"op":"mcm","clk":"5353175337","pt":1646210321958,"mc":[{"id":"1.195503861","rc":[{"atl":[[130,2]],"id":41419587}],"con":true,"img":false}]}
{"op":"mcm","clk":"5353175347","pt":1646210322267,"mc":[{"id":"1.195503861","rc":[{"atl":[[60,0]],"id":41419587},{"atl":[[990,2],[980,0.16]],"id":41419601}],"con":true,"img":false}]}
{"op":"mcm","clk":"5353175358","pt":1646210322674,"mc":[{"id":"1.195503861","rc":[{"atl":[[270,4.96]],"id":41419601}],"con":true,"img":false}]}
{"op":"mcm","clk":"5353175369","pt":1646210322887,"mc":[{"id":"1.195503861","rc":[{"atl":[[850,2],[990,0]],"id":41419601}],"con":true,"img":false}]}
{"op":"mcm","clk":"5353175374","pt":1646210322988,"mc":[{"id":"1.195503861","rc":[{"atl":[[60,2.69]],"id":41419587}],"con":true,"img":false}]}
{"op":"mcm","clk":"5353175486","pt":1646210325664,"mc":[{"id":"1.195503861","rc":[{"atl":[[75,0]],"id":41419613}],"con":true,"img":false}]}
{"op":"mcm","clk":"5353175497","pt":1646210325870,"mc":[{"id":"1.195503861","rc":[{"atl":[[70,14.56]],"id":41419613}],"con":true,"img":false}]}
{"op":"mcm","clk":"5353175536","pt":1646210326588,"mc":[{"id":"1.195503861","rc":[{"atl":[[910,1.31]],"id":41419653}],"con":true,"img":false}]}
{"op":"mcm","clk":"5353175544","pt":1646210326692,"mc":[{"id":"1.195503861","rc":[{"atl":[[270,5.55]],"id":41419601},{"atl":[[850,2],[840,1.61]],"id":28546943},{"atl":[[120,12.69]],"id":41419616},{"atl":[[100,13.87],[110,0]],"id":41419614}],"con":true,"img":false}]}
{"op":"mcm","clk":"5353175551","pt":1646210326796,"mc":[{"id":"1.195503861","rc":[{"atl":[[44,3.69]],"id":41419613},{"atl":[[85,22.18]],"id":41419587},{"atl":[[530,2],[270,5.04]],"id":41419599},{"atb":[[17,8.34]],"id":41419606},{"atl":[[140,0]],"id":41419616},{"atb":[[16.5,2.72],[19.5,33.19]],"id":41419629}],"con":true,"img":false}]}
{"op":"mcm","clk":"5353175558","pt":1646210326849,"mc":[{"id":"1.195503861","rc":[{"atb":[[22,38.11]],"id":41419606}],"con":true,"img":false}]}
{"op":"mcm","clk":"5353175563","pt":1646210326951,"mc":[{"id":"1.195503861","rc":[{"atl":[[110,1.45]],"id":41419616}],"con":true,"img":false}]}
{"op":"mcm","clk":"5353175580","pt":1646210327362,"mc":[{"id":"1.195503861","rc":[{"atl":[[70,2.3],[60,22.81]],"id":41419613},{"atl":[[980,0]],"id":41419601},{"atl":[[840,0]],"id":28546943}],"con":true,"img":false}]}
{"op":"mcm","clk":"5353175597","pt":1646210327672,"mc":[{"id":"1.195503861","rc":[{"atl":[[270,0]],"id":41419599},{"atl":[[120,11.36]],"id":41419616},{"atb":[[24,6.9]],"id":41419629}],"con":true,"img":false}]}
{"op":"mcm","clk":"5353175603","pt":1646210327777,"mc":[{"id":"1.195503861","rc":[{"atl":[[70,0]],"id":41419613}],"con":true,"img":false}]}
{"op":"mcm","clk":"5353175615","pt":1646210327993,"mc":[{"id":"1.195503861","rc":[{"atl":[[980,2]],"id":41419601}],"con":true,"img":false}]}
{"op":"mcm","clk":"5353175623","pt":1646210328088,"mc":[{"id":"1.195503861","rc":[{"atl":[[850,0]],"id":41419601},{"atl":[[1000,0.15]],"id":41419658}],"con":true,"img":false}]}
{"op":"mcm","clk":"5353175641","pt":1646210328450,"mc":[{"id":"1.195503861","rc":[{"atb":[[20,0]],"id":41419629}],"con":true,"img":false}]}
{"op":"mcm","clk":"5353175658","pt":1646210328758,"mc":[{"id":"1.195503861","rc":[{"atl":[[270,0]],"id":41419601},{"atl":[[260,4.96],[250,0]],"id":41419599}],"con":true,"img":false}]}
{"op":"mcm","clk":"5353175671","pt":1646210329069,"mc":[{"id":"1.195503861","rc":[{"atl":[[1000,0]],"id":41419658}],"con":true,"img":false}]}
{"op":"mcm","clk":"5353175685","pt":1646210329479,"mc":[{"id":"1.195503861","rc":[{"atl":[[260,5.57]],"id":41419599}],"con":true,"img":false}]}
{"op":"mcm","clk":"5353175705","pt":1646210329785,"mc":[{"id":"1.195503861","rc":[{"atl":[[270,4.96],[970,0.16]],"id":41419601}],"con":true,"img":false}]}
{"op":"mcm","clk":"5353175715","pt":1646210329990,"mc":[{"id":"1.195503861","rc":[{"atl":[[850,2],[980,0]],"id":41419601}],"con":true,"img":false}]}
{"op":"mcm","clk":"5353175726","pt":1646210330148,"mc":[{"id":"1.195503861","rc":[{"atl":[[850,0],[970,2.16]],"id":41419601}],"con":true,"img":false}]}
{"op":"mcm","clk":"5353175892","pt":1646210333855,"mc":[{"id":"1.195503861","rc":[{"atl":[[910,0]],"id":41419653}],"con":true,"img":false}]}
{"op":"mcm","clk":"5353175905","pt":1646210334167,"mc":[{"id":"1.195503861","rc":[{"atl":[[920,3.32]],"id":41419653},{"atl":[[280,4.93]],"id":41419599},{"atl":[[840,1.63]],"id":28546943}],"con":true,"img":false}]}
{"op":"mcm","clk":"5353175926","pt":1646210334580,"mc":[{"id":"1.195503861","rc":[{"atb":[[18.5,0],[7.4,0],[9.4,0]],"id":41419607},{"atb":[[75,0],[40,0],[250,0]],"id":28546950},{"atb":[[9,0],[25,0],[12.5,0]],"id":41419593},{"atb":[[16.5,0],[8.6,0],[6.6,0]],"id":41419587},{"atb":[[18,0],[42,0],[13,0]],"id":41419601},{"atb":[[24,0],[12,0],[8.8,0]],"id":41419599},{"atb":[[4,0],[6,0],[3.5,0]],"id":41419597},{"atb":[[170,0],[44,0],[27,0]],"id":28546943},{"atb":[[7.8,0],[14.5,0],[5.9,0]],"id":41419595},{"atb":[[17.5,0],[40,0],[12.5,0]],"id":41419608},{"atb":[[17,0],[6.8,0],[8.8,0]],"id":41419606},{"atb":[[6.2,0],[8.2,0],[15.5,0]],"id":41419604},{"atb":[[9.2,0],[26,0],[13,0]],"id":41419602},{"atb":[[5.5,0],[12.5,0],[7,0]],"id":41419585},{"atb":[[5.6,0],[7.2,0],[13,17.22]],"id":41419592},{"atb":[[5.6,0],[3.8,0],[3.3,0]],"id":41419590},{"atb":[[5.5,0],[12.5,0],[7,0]],"id":41419588},{"atb":[[8.6,0],[23,0],[11.5,0]],"id":41419586},{"atb":[[9.2,0],[26,0],[13,0]],"id":41419600},{"atb":[[7.2,0],[18,0],[9.2,0]],"id":41419594}],"con":true,"img":false}]}
{"op":"mcm","clk":"5353175931","pt":1646210334685,"mc":[{"id":"1.195503861","rc":[{"atb":[[18.5,0],[7.4,0],[9.4,0]],"id":41419609},{"atb":[[9,0],[25,0],[12.5,0]],"id":41419615},{"atb":[[5.6,0],[7.2,0],[13,0]],"id":41419613},{"atb":[[5.6,0],[9.2,0],[4.6,0]],"id":41419611},{"atb":[[700,0],[400,0],[500,0]],"id":41419657},{"atb":[[650,0],[350,0],[450,0]],"id":41435525},{"atb":[[75,11.53],[40,0]],"id":41419653},{"atb":[[700,0],[400,0],[500,0]],"id":41435527},{"atb":[[75,2.72],[40,0],[250,0]],"id":41419651},{"atb":[[4,0],[6,0],[3.5,0]],"id":41419618},{"atb":[[3.6,0],[6.4,18.52],[4.2,0]],"id":41419630},{"atb":[[3.45,0],[4.9,0],[2.98,0]],"id":41419628},{"atb":[[10,0],[30,0],[15,6.01]],"id":41419659},{"atb":[[7.2,0],[18,0],[9.2,0]],"id":41419616},{"atb":[[7.8,0],[14.5,0],[5.9,0]],"id":41419614},{"atb":[[130,3.67],[65,0],[330,0]],"id":41419656},{"atb":[[22,0],[11,0],[8.4,0]],"id":41419654},{"atb":[[700,0],[400,0],[500,0]],"id":41419652},{"atb":[[3.45,0],[4.9,0],[2.98,0]],"id":41419631},{"atb":[[10,0],[5,0],[6,0]],"id":41419629},{"atb":[[4.3,0],[2.86,0],[3.15,0]],"id":41419627},{"atb":[[130,0],[65,0],[330,0]],"id":41419658}],"con":true,"img":false}]}
{"op":"mcm","clk":"5353175942","pt":1646210334992,"mc":[{"id":"1.195503861","rc":[{"atb":[[120,4.96]],"id":28546950}],"con":true,"img":false}]}
{"op":"mcm","clk":"5353175950","pt":1646210335097,"mc":[{"id":"1.195503861","rc":[{"atb":[[160,13.62]],"id":41419657},{"atb":[[130,6.19],[95,23.54]],"id":41435525},{"atb":[[160,13.08]],"id":41435527},{"atb":[[65,4.96],[50,10.31]],"id":41419651},{"atb":[[48,11.13],[50,9.92]],"id":28546943},{"atl":[[110,13.72],[120,0]],"id":41419616},{"atb":[[130,0],[110,22.53]],"id":41419656},{"atb":[[140,13.18]],"id":41419652},{"atb":[[160,7.69],[120,21.48]],"id":41419658}],"con":true,"img":false}]}
{"op":"mcm","clk":"5353175958","pt":1646210335149,"mc":[{"id":"1.195503861","rc":[{"atb":[[100,12.22]],"id":28546950}],"con":true,"img":false}]}
{"op":"mcm","clk":"5353175971","pt":1646210335358,"mc":[{"id":"1.195503861","rc":[{"atl":[[280,4.96]],"id":41419651},{"atl":[[290,4.78]],"id":41419601},{"atl":[[1000,0.15]],"id":41419656},{"atl":[[1000,0.15]],"id":41419658}],"con":true,"img":false}]}
{"op":"mcm","clk":"5353175977","pt":1646210335461,"mc":[{"id":"1.195503861","rc":[{"atl":[[460,2]],"id":41419651}],"con":true,"img":false}]}
{"op":"mcm","clk":"5353175984","pt":1646210335565,"mc":[{"id":"1.195503861","rc":[{"atl":[[860,0]],"id":41419651}],"con":true,"img":false}]}
{"op":"mcm","clk":"5353175990","pt":1646210335668,"mc":[{"id":"1.195503861","rc":[{"atl":[[520,4.66],[880,0]],"id":41419615}],"con":true,"img":false}]}
{"op":"mcm","clk":"5353175996","pt":1646210335772,"mc":[{"id":"1.195503861","rc":[{"atb":[[110,2.72]],"id":41435525}],"con":true,"img":false}]}
{"op":"mcm","clk":"5353176004","pt":1646210335977,"mc":[{"id":"1.195503861","rc":[{"atl":[[280,5.52]],"id":41419651}],"con":true,"img":false}]}
{"op":"mcm","clk":"5353176007","pt":1646210336079,"mc":[{"id":"1.195503861","rc":[{"atl":[[860,1.6],[870,0]],"id":41419651}],"con":true,"img":false}]}
{"op":"mcm","clk":"5353176011","pt":1646210336183,"mc":[{"id":"1.195503861","rc":[{"atl":[[280,0.56]],"id":41419651},{"atl":[[1000,0]],"id":41419656}],"con":true,"img":false}]}
{"op":"mcm","clk":"5353176043","pt":1646210336798,"mc":[{"id":"1.195503861","rc":[{"atl":[[280,0],[840,0]],"id":41419651}],"con":true,"img":false}]}
{"op":"mcm","clk":"5353176049","pt":1646210336951,"mc":[{"id":"1.195503861","rc":[{"atl":[[280,4.96]],"id":41419651}],"con":true,"img":false}]}
{"op":"mcm","clk":"5353176064","pt":1646210337364,"mc":[{"id":"1.195503861","rc":[{"atl":[[270,5.55]],"id":41419601}],"con":true,"img":false}]}
{"op":"mcm","clk":"5353176069","pt":1646210337468,"mc":[{"id":"1.195503861","rc":[{"atl":[[280,5.52]],"id":41419651}],"con":true,"img":false}]}
{"op":"mcm","clk":"5353176099","pt":1646210338087,"mc":[{"id":"1.195503861","rc":[{"atl":[[970,2]],"id":41419601}],"con":true,"img":false}]}
{"op":"mcm","clk":"5353176120","pt":1646210338498,"mc":[{"id":"1.195503861","rc":[{"atl":[[280,4.96]],"id":41419651}],"con":true,"img":false}]}
{"op":"mcm","clk":"5353176135","pt":1646210338756,"mc":[{"id":"1.195503861","rc":[{"atl":[[280,0]],"id":41419651}],"con":true,"img":false}]}
{"op":"mcm","clk":"5353176153","pt":1646210339168,"mc":[{"id":"1.195503861","rc":[{"atl":[[450,0.35]],"id":41419651}],"con":true,"img":false}]}
{"op":"mcm","clk":"5353176203","pt":1646210340504,"mc":[{"id":"1.195503861","rc":[{"atb":[[40,12.65],[42,3.87],[48,4.96]],"id":41419609},{"atb":[[34,4.96],[25,19.65],[28,9.92],[29,3.27]],"id":41419607},{"atb":[[65,9.92],[70,2.3],[85,4.96],[50,0]],"id":41419615},{"atb":[[16,13.36],[17.5,4.96],[14,0],[15.5,9.92]],"id":41419613},{"atb":[[19.5,0],[21,9.92],[23,9.94],[25,4.96]],"id":41419611},{"atl":[[160,4.96],[180,0.88]],"id":41419593},{"atb":[[130,1.23],[95,13.61]],"id":41435525},{"atb":[[65,9.92],[75,6.57],[85,7.38],[55,3.27]],"id":41419653},{"atl":[[65,0],[80,9.92],[85,12.26],[60,7.65]],"id":41419587},{"atb":[[10,0],[10.5,9.92],[12,12.26],[12.5,4.96]],"id":41419618},{"atb":[[85,2.72],[90,9.92],[110,1.45],[120,4.96]],"id":41419601},{"atl":[[260,0.61],[240,4.96]],"id":41419599},{"atl":[[22,4.96],[25,6.61],[26,9.92],[29,0]],"id":41419597},{"atb":[[8.6,4.96],[7.6,22.15],[7.8,12.65],[8.4,21.45]],"id":41419628},{"atl":[[75,4.96],[80,2],[95,9.92],[100,0]],"id":41419595},{"atb":[[80,0],[85,9.92],[100,1.6],[110,4.96]],"id":41419608},{"atb":[[19,0],[21,9.92],[22,33.14],[25,4.96]],"id":41419606},{"atb":[[16,0],[17,9.92],[18,12.26],[19,8.23]],"id":41419585},{"atb":[[18.5,0],[19.5,9.92],[21,12.26],[23,4.96]],"id":41419616},{"atb":[[18,0],[24,4.96]],"id":41419614},{"atb":[[150,3.79],[160,4.96],[110,12.61],[120,9.92]],"id":41419656},{"atl":[[75,0],[46,4.96],[55,0],[60,9.92]],"id":41419592},{"atl":[[22,4.96],[24,6.9],[26,9.92],[28,0]],"id":41419590},{"atl":[[70,4.96],[75,2.14],[90,9.92],[95,0]],"id":41419588},{"atl":[[160,4.96],[170,0.93]],"id":41419586},{"atb":[[80,0],[85,9.92],[100,1.6],[110,4.96]],"id":41419600},{"atb":[[9.2,4.96],[8.2,11.67],[7.4,0],[8.4,9.92]],"id":41419631},{"atb":[[19.5,23.26],[21,9.92],[23,0],[25,4.96]],"id":41419629},{"atl":[[10.5,4.96],[11.5,14.76],[12.5,9.92],[13.5,0]],"id":41419627},{"atl":[[70,9.92],[80,12.26],[50,4.96],[60,0]],"id":41419594}],"con":true,"img":false}]}
{"op":"mcm","clk":"5353176209","pt":1646210340606,"mc":[{"id":"1.195503861","rc":[{"atl":[[860,3.6],[460,0]],"id":41419651}],"con":true,"img":false}]}
{"op":"mcm","clk":"5353176216","pt":1646210340660,"mc":[{"id":"1.195503861","rc":[{"atl":[[880,0],[510,2]],"id":41419593},{"atl":[[70,9.7],[60,11.92]],"id":41419592},{"atl":[[880,0],[510,2]],"id":41419586}],"con":true,"img":false}]}
{"op":"mcm","clk":"5353176221","pt":1646210340761,"mc":[{"id":"1.195503861","rc":[{"atb":[[140,4.96],[100,9.92]],"id":41435525},{"atl":[[70,4.96],[90,9.92]],"id":41419654}],"con":true,"img":false}]}
{"op":"mcm","clk":"5353176225","pt":1646210340866,"mc":[{"id":"1.195503861","rc":[{"atb":[[40,27.41],[30,3.27]],"id":41419609},{"atb":[[25,0]],"id":41419607},{"atb":[[65,24.24],[90,1.78]],"id":41419615},{"atb":[[17.5,17.85]],"id":41419613},{"atb":[[19,3.27],[21,32.07]],"id":41419611},{"atl":[[880,1.58]],"id":41419593},{"atb":[[12.5,19.72]],"id":41419618},{"atb":[[80,0]],"id":41419601},{"atl":[[26,34.54]],"id":41419597},{"atb":[[7.6,0]],"id":41419628},{"atl":[[300,2],[95,24.7]],"id":41419595},{"atb":[[70,0]],"id":41419608},{"atb":[[22,7.56],[25,23.16]],"id":41419606},{"atb":[[21,0],[23,19.72]],"id":41419616},{"atb":[[20,4.96]],"id":41419614},{"atl":[[80,0],[100,13.2]],"id":41419654},{"atl":[[70,2],[22,12.52],[26,34.97]],"id":41419590},{"atl":[[150,1.06]],"id":41419586},{"atb":[[70,0]],"id":41419600},{"atb":[[7.2,3.27],[8.2,43.83]],"id":41419631},{"atb":[[19.5,0],[21,31.03],[25,11.57]],"id":41419629},{"atl":[[10.5,21.67],[21,5],[12.5,32.07]],"id":41419627},{"atl":[[70,22.18],[80,0],[50,8.2]],"id":41419594}],"con":true,"img":false}]}
{"op":"mcm","clk":"5353176231","pt":1646210340969,"mc":[{"id":"1.195503861","rc":[{"atb":[[48,8.34]],"id":41419609},{"atb":[[29,18.04]],"id":41419607},{"atb":[[48,2.72]],"id":41419615},{"atb":[[16,1.09]],"id":41419613},{"atb":[[25,11.57]],"id":41419611},{"atl":[[150,1.06]],"id":41419593},{"atb":[[12,0]],"id":41419618},{"atb":[[130,1.23],[90,24.42]],"id":41419601},{"atl":[[65,2],[22,12.52]],"id":41419597},{"atb":[[8.8,20.36],[7.8,56.37]],"id":41419628},{"atl":[[70,2.3]],"id":41419595},{"atb":[[85,19.68],[120,1.33]],"id":41419608},{"atb":[[23,18.04]],"id":41419614},{"atl":[[70,0],[46,8.48],[60,24.18]],"id":41419592},{"atl":[[65,2.48]],"id":41419588},{"atl":[[880,1.58],[910,0]],"id":41419586},{"atb":[[85,20.28],[120,1.33]],"id":41419600},{"atb":[[9.2,24.32]],"id":41419631}],"con":true,"img":false}]}
{"op":"mcm","clk":"5353176233","pt":1646210341073,"mc":[{"id":"1.195503861","rc":[{"atb":[[170,0.93]],"id":41419656},{"atl":[[280,2],[90,25.52]],"id":41419588}],"con":true,"img":false}]}
{"op":"mcm","clk":"5353176239","pt":1646210341175,"mc":[{"id":"1.195503861","rc":[{"atl":[[42,4.96],[46,0],[50,9.92],[60,12.89]],"id":41419613},{"atl":[[260,4.96]],"id":41419601},{"atl":[[65,4.96],[70,2.3],[85,9.92],[90,0]],"id":41419606},{"atl":[[65,9.92],[75,12.26],[48,4.96],[55,0]],"id":41419585},{"atl":[[75,0],[46,4.96],[55,0],[60,9.92]],"id":41419616},{"atl":[[70,7.26],[80,14.76],[100,0]],"id":41419654},{"atl":[[23,4.96],[24,6.9],[27,9.92],[28,0]],"id":41419631}],"con":true,"img":false}]}
{"op":"mcm","clk":"5353176247","pt":1646210341279,"mc":[{"id":"1.195503861","rc":[{"atl":[[270,0.58],[850,2],[970,0]],"id":41419601}],"con":true,"img":false}]}
{"op":"mcm","clk":"5353176254","pt":1646210341485,"mc":[{"id":"1.195503861","rc":[{"atl":[[910,1.36]],"id":41419653},{"atl":[[840,0],[850,3.64]],"id":28546943}],"con":true,"img":false}]}
{"op":"mcm","clk":"5353176260","pt":1646210341591,"mc":[{"id":"1.195503861","rc":[{"atb":[[70,0]],"id":41419615},{"atl":[[42,8.83],[50,22.81],[60,0]],"id":41419613},{"atl":[[920,2]],"id":41419653},{"atl":[[250,0.63]],"id":41419601},{"atl":[[65,7.44],[130,2],[85,22.18]],"id":41419606},{"atl":[[65,29.57],[75,0],[48,8.34]],"id":41419585},{"atl":[[170,0]],"id":41419586},{"atl":[[65,2],[22,7.56],[27,39.45]],"id":41419631},{"atb":[[24,0]],"id":41419629},{"atl":[[11.5,0]],"id":41419627},{"atl":[[55,0]],"id":41419594}],"con":true,"img":false}]}
{"op":"mcm","clk":"5353176265","pt":1646210341691,"mc":[{"id":"1.195503861","rc":[{"atb":[[42,0]],"id":41419609},{"atb":[[23,2.72]],"id":41419611},{"atl":[[180,0]],"id":41419593},{"atl":[[25,0]],"id":41419597},{"atb":[[8.4,0]],"id":41419628},{"atl":[[50,0]],"id":41419592},{"atl":[[24,0]],"id":41419590},{"atb":[[100,0]],"id":41419600},{"atb":[[8.2,34.88]],"id":41419631}],"con":true,"img":false}]}
{"op":"mcm","clk":"5353176270","pt":1646210341794,"mc":[{"id":"1.195503861","rc":[{"atl":[[910,0]],"id":41419593}],"con":true,"img":false}]}
{"op":"mcm","clk":"5353176275","pt":1646210341897,"mc":[{"id":"1.195503861","rc":[{"atb":[[110,0]],"id":41419601},{"atl":[[80,0]],"id":41419595},{"atb":[[100,0]],"id":41419608},{"atb":[[150,2.72]],"id":41419656},{"atl":[[75,0]],"id":41419588}],"con":true,"img":false}]}
{"op":"mcm","clk":"5353176279","pt":1646210342000,"mc":[{"id":"1.195503861","rc":[{"atl":[[75,0]],"id":41419654}],"con":true,"img":false}]}
{"op":"mcm","clk":"5353176292","pt":1646210342307,"mc":[{"id":"1.195503861","rc":[{"atl":[[850,2]],"id":28546943}],"con":true,"img":false}]}
{"op":"mcm","clk":"5353176294","pt":1646210342361,"mc":[{"id":"1.195503861","rc":[{"atl":[[910,0]],"id":41419653}],"con":true,"img":false}]}
{"op":"mcm","clk":"5353176308","pt":1646210342668,"mc":[{"id":"1.195503861","rc":[{"atl":[[44,0]],"id":41419613},{"atl":[[270,0]],"id":41419601},{"atl":[[70,0]],"id":41419606},{"atl":[[50,0]],"id":41419585},{"atl":[[24,0]],"id":41419631}],"con":true,"img":false}]}
{"op":"mcm","clk":"5353176401","pt":1646210344162,"mc":[{"id":"1.195503861","rc":[{"atl":[[240,5.62]],"id":41419599}],"con":true,"img":false}]}
{"op":"mcm","clk":"5353176449","pt":1646210345091,"mc":[{"id":"1.195503861","rc":[{"atl":[[260,0]],"id":41419599}],"con":true,"img":false}]}
{"op":"mcm","clk":"5353176481","pt":1646210345504,"mc":[{"id":"1.195503861","rc":[{"atl":[[280,0]],"id":41419599}],"con":true,"img":false}]}
{"op":"mcm","clk":"5353176512","pt":1646210345868,"mc":[{"id":"1.195503861","rc":[{"atl":[[530,4.66]],"id":41419599}],"con":true,"img":false}]}
{"op":"mcm","clk":"5353176567","pt":1646210346792,"mc":[{"id":"1.195503861","rc":[{"atl":[[42,4.96]],"id":41419613}],"con":true,"img":false}]}
{"op":"mcm","clk":"5353176581","pt":1646210347000,"mc":[{"id":"1.195503861","rc":[{"atl":[[42,0],[44,4.96],[50,12.89],[55,9.92]],"id":41419613},{"atl":[[280,4.96]],"id":41419651}],"con":true,"img":false}]}
{"op":"mcm","clk":"5353176587","pt":1646210347105,"mc":[{"id":"1.195503861","rc":[{"atl":[[860,1.6],[460,2]],"id":41419651}],"con":true,"img":false}]}
{"op":"mcm","clk":"5353176604","pt":1646210347515,"mc":[{"id":"1.195503861","rc":[{"atl":[[48,3.37]],"id":41419613}],"con":true,"img":false}]}
{"op":"mcm","clk":"5353176629","pt":1646210347981,"mc":[{"id":"1.195503861","rc":[{"atb":[[40,12.65],[30,18.29]],"id":41419609},{"atb":[[40,0],[30,0]],"id":41419604},{"atb":[[150,0],[100,0]],"id":41419656},{"atb":[[24,29.81],[29,5.67]],"id":41419654},{"atl":[[70,22.34],[26,9.92]],"id":41419590},{"atb":[[65,0],[46,2.22]],"id":41419600},{"atb":[[7.2,0],[8.2,32.15]],"id":41419631},{"atb":[[16.5,28.31],[21,9.92]],"id":41419629},{"atb":[[7.2,0],[6.2,14.76]],"id":41419627},{"atl":[[21,39.3],[12.5,9.92]],"id":41419627}],"con":true,"img":false}]}
{"op":"mcm","clk":"5353176638","pt":1646210348186,"mc":[{"id":"1.195503861","rc":[{"atl":[[65,23.91],[26,9.92]],"id":41419597},{"atl":[[70,9.92],[170,10.37]],"id":41419594}],"con":true,"img":false}]}
{"op":"mcm","clk":"5353176650","pt":1646210348495,"mc":[{"id":"1.195503861","rc":[{"atl":[[80,0],[90,25.75]],"id":41419654},{"atb":[[6.2,0],[6.8,32.34],[6,46.68]],"id":41419627}],"con":true,"img":false}]}
{"op":"mcm","clk":"5353176658","pt":1646210348701,"mc":[{"id":"1.195503861","rc":[{"atl":[[130,12.96],[85,9.92]],"id":41419606},{"atb":[[32,3.27],[42,15.88]],"id":41419604},{"atl":[[65,9.92],[110,14.96]],"id":41419585},{"atb":[[7.4,3.27],[8.4,12.65]],"id":41419631}],"con":true,"img":false}]}
{"op":"mcm","clk":"5353176665","pt":1646210348803,"mc":[{"id":"1.195503861","rc":[{"atl":[[910,1.38]],"id":41419653},{"atb":[[160,7.69],[110,15.88]],"id":41419656},{"atb":[[25,3.27],[30,2.72]],"id":41419654},{"atb":[[70,2.72],[48,3.27]],"id":41419600},{"atb":[[6.4,3.27],[7.4,2.72]],"id":41419627}],"con":true,"img":false}]}
{"op":"mcm","clk":"5353176670","pt":1646210348912,"mc":[{"id":"1.195503861","rc":[{"atl":[[530,2],[260,5.48]],"id":41419599},{"atl":[[840,1.68]],"id":28546943}],"con":true,"img":false}]}
{"op":"mcm","clk":"5353176688","pt":1646210349315,"mc":[{"id":"1.195503861","rc":[{"atb":[[24,9.92]],"id":41419654}],"con":true,"img":false}]}
{"op":"mcm","clk":"5353176700","pt":1646210349472,"mc":[{"id":"1.195503861","rc":[{"atb":[[28,20.78],[30,8.2]],"id":41419654}],"con":true,"img":false}]}
{"op":"mcm","clk":"5353176719","pt":1646210349779,"mc":[{"id":"1.195503861","rc":[{"atb":[[110,8.62]],"id":41435525},{"atb":[[110,3.27]],"id":41419656}],"con":true,"img":false}]}
{"op":"mcm","clk":"5353176725","pt":1646210349883,"mc":[{"id":"1.195503861","rc":[{"atb":[[140,6.1],[95,0]],"id":41435525},{"atl":[[260,0]],"id":41419599},{"atb":[[120,21.82]],"id":41419656}],"con":true,"img":false}]}
{"op":"mcm","clk":"5353176736","pt":1646210350092,"mc":[{"id":"1.195503861","rc":[{"atb":[[7.2,43.06],[18,7.85],[9.2,32.56]],"id":41419609},{"atb":[[7.2,43.06],[18,7.85],[9.2,32.56]],"id":41419607},{"atb":[[75,3.6],[40,6.84],[250,0.53]],"id":28546950},{"atb":[[9.2,32.56],[26,5.33],[13,22.25]],"id":41419615},{"atb":[[5.6,58.05],[7.2,43.06],[13,11.12]],"id":41419613},{"atb":[[5.6,58.05],[9.2,16.28],[4.6,74.17]],"id":41419611},{"atb":[[9.2,32.56],[26,5.33],[13,22.25]],"id":41419593},{"atb":[[700,0.19],[400,0.67],[500,0.53]],"id":41419657},{"atb":[[650,0.2],[350,0.76],[450,0.59]],"id":41435525},{"atb":[[75,9.51],[40,5.58],[250,0.43]],"id":41419653},{"atb":[[700,0.19],[400,0.67],[500,0.53]],"id":41435527},{"atb":[[75,6.33],[40,6.84],[250,0.53]],"id":41419651},{"atb":[[16.5,8.61],[8.6,35.13],[6.6,47.68]],"id":41419587},{"atb":[[4,89],[6,26.7],[3.5,106.81]],"id":41419618},{"atb":[[19,14.83],[46,2.96],[14,20.54]],"id":41419601},{"atb":[[9,33.37],[25,5.56],[12.5,23.22]],"id":41419599},{"atb":[[3.6,102.7],[6.4,43.24],[4.2,83.44]],"id":41419630},{"atb":[[4,89],[6,26.7],[3.5,106.81]],"id":41419597},{"atb":[[170,0.79],[44,6.21],[27,10.27]],"id":28546943},{"atb":[[3.45,108.99],[4.9,34.23],[2.98,134.86]],"id":41419628},{"atb":[[5.8,55.63],[7.6,40.45],[14,10.27]],"id":41419595},{"atb":[[10,29.66],[15,25.08],[30,4.6]],"id":41419659},{"atb":[[18.5,15.25],[44,3.1],[13.5,21.36]],"id":41419608},{"atb":[[17,8.34],[6.8,46.03],[8.8,34.23]],"id":41419606},{"atb":[[6.2,51.35],[8.2,37.08],[15.5,9.2]],"id":41419604},{"atb":[[27,5.13],[13.5,21.36],[9.4,31.79]],"id":41419602},{"atb":[[5.5,59.33],[12.5,11.61],[7,44.5]],"id":41419585},{"atb":[[7.2,43.06],[18,7.85],[9.2,32.56]],"id":41419616},{"atb":[[5.8,55.63],[7.6,40.45],[14,10.27]],"id":41419614},{"atb":[[130,2.06],[65,4.17],[330,0.4]],"id":41419656},{"atb":[[5.6,58.05],[7.2,43.06],[13,28.35]],"id":41419592},{"atb":[[22,6.35],[11,26.7],[8.4,36.08]],"id":41419654},{"atb":[[5.5,29.66],[3.25,118.67],[3.75,97.1]],"id":41419590},{"atb":[[5.5,59.33],[12.5,11.61],[7,44.5]],"id":41419588},{"atb":[[700,0.19],[400,0.67],[500,0.53]],"id":41419652},{"atb":[[8.6,35.13],[23,6.06],[11.5,25.43]],"id":41419586},{"atb":[[27,5.13],[13.5,21.36],[9.4,31.79]],"id":41419600},{"atb":[[3.45,108.99],[4.9,34.23],[2.98,134.86]],"id":41419631},{"atb":[[5.1,65.13],[10.5,14.05],[6.2,51.35]],"id":41419629},{"atb":[[3.1,127.15],[2.84,145.12],[4.2,72.97]],"id":41419627},{"atb":[[7.2,43.06],[18,7.85],[9.2,32.56]],"id":41419594},{"atb":[[130,2.06],[65,4.17],[330,0.4]],"id":41419658}],"con":true,"img":false}]}
{"op":"mcm","clk":"5353176743","pt":1646210350198,"mc":[{"id":"1.195503861","rc":[{"atb":[[29,0]],"id":41419654}],"con":true,"img":false}]}
{"op":"mcm","clk":"5353176757","pt":1646210350506,"mc":[{"id":"1.195503861","rc":[{"atb":[[100,3.27],[120,12]],"id":28546950},{"atb":[[110,2.72]],"id":41435525},{"atb":[[65,15.32],[50,3.27]],"id":41419651},{"atb":[[48,3.27],[50,15.41]],"id":28546943},{"atb":[[140,3.27]],"id":41419652}],"con":true,"img":false}]}
{"op":"mcm","clk":"5353176760","pt":1646210350608,"mc":[{"id":"1.195503861","rc":[{"atb":[[160,4.96]],"id":41419657},{"atb":[[75,2.94],[80,7.77]],"id":41419653},{"atb":[[160,4.96]],"id":41435527},{"atb":[[160,9.68],[120,9.92]],"id":41419658}],"con":true,"img":false}]}
{"op":"mcm","clk":"5353176765","pt":1646210350816,"mc":[{"id":"1.195503861","rc":[{"atb":[[130,0]],"id":41435525},{"atl":[[280,5.52],[860,0],[460,5.1]],"id":41419651},{"atl":[[230,4.96],[240,0.66]],"id":41419599},{"atb":[[20,9.92],[21,0],[24,4.96],[25,0]],"id":41419629},{"atl":[[1000,0]],"id":41419658}],"con":true,"img":false}]}
{"op":"mcm","clk":"5353176769","pt":1646210350915,"mc":[{"id":"1.195503861","rc":[{"atl":[[280,0.56]],"id":41419651},{"atl":[[250,5.6]],"id":41419601}],"con":true,"img":false}]}
{"op":"mcm","clk":"5353176772","pt":1646210351018,"mc":[{"id":"1.195503861","rc":[{"atl":[[260,0]],"id":41419601}],"con":true,"img":false}]}
{"op":"mcm","clk":"5353176797","pt":1646210351484,"mc":[{"id":"1.195503861","rc":[{"atl":[[290,0]],"id":41419601}],"con":true,"img":false}]}
{"op":"mcm","clk":"5353176811","pt":1646210351793,"mc":[{"id":"1.195503861","rc":[{"atl":[[280,0],[450,0]],"id":41419651},{"atl":[[850,3.67]],"id":41419601},{"atb":[[17,9.92]],"id":41419629}],"con":true,"img":false}]}
{"op":"mcm","clk":"5353176824","pt":1646210351999,"mc":[{"id":"1.195503861","rc":[{"atl":[[310,0],[240,2]],"id":41419607},{"atl":[[70,2]],"id":41419613},{"atl":[[1000,2]],"id":41435525},{"atl":[[820,2],[920,0]],"id":41419653},{"atl":[[130,0],[100,2]],"id":41419587},{"atl":[[760,2],[850,0]],"id":28546943},{"atl":[[300,0],[210,2]],"id":41419595},{"atl":[[990,3.3]],"id":41419608},{"atl":[[800,2],[880,0]],"id":41419604},{"atl":[[280,0],[200,2]],"id":41419588}],"con":true,"img":false}]}
{"op":"mcm","clk":"5353176829","pt":1646210352109,"mc":[{"id":"1.195503861","rc":[{"atl":[[80,0]],"id":41419613}],"con":true,"img":false}]}
{"op":"mcm","clk":"5353176849","pt":1646210352417,"mc":[{"id":"1.195503861","rc":[{"atl":[[810,0.19]],"id":41419653}],"con":true,"img":false}]}
{"op":"mcm","clk":"5353176873","pt":1646210352820,"mc":[{"id":"1.195503861","rc":[{"atl":[[450,0.35]],"id":41419651},{"atl":[[750,0.21]],"id":28546943}],"con":true,"img":false}]}
{"op":"mcm","clk":"5353176890","pt":1646210353081,"mc":[{"id":"1.195503861","rc":[{"atl":[[890,0]],"id":41419653},{"atl":[[290,4.96]],"id":41419651}],"con":true,"img":false}]}
{"op":"mcm","clk":"5353176896","pt":1646210353183,"mc":[{"id":"1.195503861","rc":[{"atl":[[360,2],[460,3.1]],"id":41419651}],"con":true,"img":false}]}
{"op":"mcm","clk":"5353176911","pt":1646210353492,"mc":[{"id":"1.195503861","rc":[{"atl":[[360,0],[450,2.35]],"id":41419651},{"atl":[[820,0]],"id":28546943}],"con":true,"img":false}]}
{"op":"mcm","clk":"5353176922","pt":1646210353800,"mc":[{"id":"1.195503861","rc":[{"atl":[[290,5.51]],"id":41419651}],"con":true,"img":false}]}
{"op":"mcm","clk":"5353176955","pt":1646210354620,"mc":[{"id":"1.195503861","rc":[{"atl":[[450,2]],"id":41419651}],"con":true,"img":false}]}
{"op":"mcm","clk":"5353176971","pt":1646210354881,"mc":[{"id":"1.195503861","rc":[{"atb":[[19,0],[23,0]],"id":41419613}],"con":true,"img":false}]}
{"op":"mcm","clk":"5353176990","pt":1646210355294,"mc":[{"id":"1.195503861","rc":[{"atb":[[17.5,27.47]],"id":41419613}],"con":true,"img":false}]}
{"op":"mcm","clk":"5353176995","pt":1646210355398,"mc":[{"id":"1.195503861","rc":[{"atb":[[17.5,14.58],[15.5,32.07]],"id":41419613},{"atl":[[510,4.82]],"id":41419593},{"atl":[[60,11.92]],"id":41419592},{"atb":[[16.5,2.72],[17,35.51],[24,11.86]],"id":41419629}],"con":true,"img":false}]}
{"op":"mcm","clk":"5353177000","pt":1646210355501,"mc":[{"id":"1.195503861","rc":[{"atl":[[880,0]],"id":41419593},{"atl":[[50,25.27]],"id":41419592},{"atl":[[200,9.22]],"id":41419654},{"atl":[[510,4.82]],"id":41419586}],"con":true,"img":false}]}
{"op":"mcm","clk":"5353177006","pt":1646210355604,"mc":[{"id":"1.195503861","rc":[{"atl":[[48,2.13],[60,9.92]],"id":41419592},{"atl":[[90,9.92]],"id":41419654},{"atl":[[880,0]],"id":41419586}],"con":true,"img":false}]}
{"op":"mcm","clk":"5353177010","pt":1646210355707,"mc":[{"id":"1.195503861","rc":[{"atb":[[20,3.27],[25,2.72]],"id":41419613}],"con":true,"img":false}]}
{"op":"mcm","clk":"5353177019","pt":1646210355912,"mc":[{"id":"1.195503861","rc":[{"atl":[[48,0],[50,27.31]],"id":41419592}],"con":true,"img":false}]}
{"op":"mcm","clk":"5353177023","pt":1646210356016,"mc":[{"id":"1.195503861","rc":[{"atb":[[16,0]],"id":41419613}],"con":true,"img":false}]}
{"op":"mcm","clk":"5353177028","pt":1646210356118,"mc":[{"id":"1.195503861","rc":[{"atl":[[50,25.27],[60,11.92]],"id":41419592}],"con":true,"img":false}]}
{"op":"mcm","clk":"5353177040","pt":1646210356427,"mc":[{"id":"1.195503861","rc":[{"atl":[[44,8.65]],"id":41419613},{"atb":[[17,25.58]],"id":41419629}],"con":true,"img":false}]}
{"op":"mcm","clk":"5353177051","pt":1646210356685,"mc":[{"id":"1.195503861","rc":[{"atb":[[25,29.2],[28,4.96]],"id":41419654}],"con":true,"img":false}]}
{"op":"mcm","clk":"5353177082","pt":1646210357522,"mc":[{"id":"1.195503861","rc":[{"atl":[[48,0]],"id":41419613}],"con":true,"img":false}]}
{"op":"mcm","clk":"5353177104","pt":1646210358026,"mc":[{"id":"1.195503861","rc":[{"atl":[[50,0]],"id":41419613}],"con":true,"img":false}]}
{"op":"mcm","clk":"5353177122","pt":1646210358336,"mc":[{"id":"1.195503861","rc":[{"atl":[[55,36.33]],"id":41419613}],"con":true,"img":false}]}
{"op":"mcm","clk":"5353177142","pt":1646210358607,"mc":[{"id":"1.195503861","rc":[{"atl":[[230,5.65]],"id":41419599}],"con":true,"img":false}]}
{"op":"mcm","clk":"5353177162","pt":1646210359016,"mc":[{"id":"1.195503861","rc":[{"atb":[[90,0]],"id":41419615},{"atl":[[10.5,0],[11,4.96],[12.5,0],[13,9.92]],"id":41419627}],"con":true,"img":false}]}
{"op":"mcm","clk":"5353177183","pt":1646210359318,"mc":[{"id":"1.195503861","rc":[{"atl":[[240,0]],"id":41419599}],"con":true,"img":false}]}
{"op":"mcm","clk":"5353177201","pt":1646210359626,"mc":[{"id":"1.195503861","rc":[{"atb":[[65,9.92],[48,17.05]],"id":41419615}],"con":true,"img":false}]}
{"op":"mcm","clk":"5353177217","pt":1646210359938,"mc":[{"id":"1.195503861","rc":[{"atb":[[85,6.85]],"id":41419615},{"atl":[[20,8.35]],"id":41419627}],"con":true,"img":false}]}
{"op":"mcm","clk":"5353177236","pt":1646210360198,"mc":[{"id":"1.195503861","rc":[{"atl":[[250,5.82]],"id":41419599}],"con":true,"img":false}]}
{"op":"mcm","clk":"5353177242","pt":1646210360300,"mc":[{"id":"1.195503861","rc":[{"atl":[[530,0],[430,2]],"id":41419599}],"con":true,"img":false}]}
{"op":"mcm","clk":"5353177258","pt":1646210360609,"mc":[{"id":"1.195503861","rc":[{"atl":[[20,28.18],[21,5]],"id":41419627}],"con":true,"img":false}]}
{"op":"mcm","clk":"5353177359","pt":1646210362413,"mc":[{"id":"1.195503861","rc":[{"atl":[[50,0]],"id":41419592}],"con":true,"img":false}]}
{"op":"mcm","clk":"5353177381","pt":1646210362824,"mc":[{"id":"1.195503861","rc":[{"atl":[[60,36.35]],"id":41419592}],"con":true,"img":false}]}
{"op":"mcm","clk":"5353177395","pt":1646210363130,"mc":[{"id":"1.195503861","rc":[{"atb":[[6.4,25.42],[6,9.92]],"id":41419627}],"con":true,"img":false}]}
{"op":"mcm","clk":"5353177410","pt":1646210363438,"mc":[{"id":"1.195503861","rc":[{"atl":[[270,4.96]],"id":41419653}],"con":true,"img":false}]}
{"op":"mcm","clk":"5353177422","pt":1646210363595,"mc":[{"id":"1.195503861","rc":[{"atl":[[820,0],[420,2]],"id":41419653}],"con":true,"img":false}]}
{"op":"mcm","clk":"5353177434","pt":1646210363803,"mc":[{"id":"1.195503861","rc":[{"atl":[[910,0]],"id":41419653}],"con":true,"img":false}]}
{"op":"mcm","clk":"5353177459","pt":1646210364215,"mc":[{"id":"1.195503861","rc":[{"atl":[[820,1.67]],"id":41419653},{"atb":[[160,10.49],[120,9.92]],"id":41419656}],"con":true,"img":false}]}
{"op":"mcm","clk":"5353177524","pt":1646210365299,"mc":[{"id":"1.195503861","rc":[{"atl":[[55,9.92]],"id":41419613}],"con":true,"img":false}]}
{"op":"mcm","clk":"5353177538","pt":1646210365507,"mc":[{"id":"1.195503861","rc":[{"atl":[[70,19.77]],"id":41419613}],"con":true,"img":false}]}
{"op":"mcm","clk":"5353177572","pt":1646210366124,"mc":[{"id":"1.195503861","rc":[{"atl":[[850,2]],"id":41419601}],"con":true,"img":false}]}
{"op":"mcm","clk":"5353177585","pt":1646210366431,"mc":[{"id":"1.195503861","rc":[{"atl":[[270,5.45]],"id":41419601}],"con":true,"img":false}]}
{"op":"mcm","clk":"5353177592","pt":1646210366534,"mc":[{"id":"1.195503861","rc":[{"atl":[[670,2]],"id":41419601}],"con":true,"img":false}]}
{"op":"mcm","clk":"5353177596","pt":1646210366637,"mc":[{"id":"1.195503861","rc":[{"atl":[[850,0]],"id":41419601}],"con":true,"img":false}]}
{"op":"mcm","clk":"5353177600","pt":1646210366739,"mc":[{"id":"1.195503861","rc":[{"atl":[[270,5.55]],"id":41419653}],"con":true,"img":false}]}
{"op":"mcm","clk":"5353177613","pt":1646210367048,"mc":[{"id":"1.195503861","rc":[{"atl":[[70,9.92],[50,4.96]],"id":41419585},{"atl":[[70,2.3],[75,4.96],[90,0],[95,9.92]],"id":41419654}],"con":true,"img":false}]}
{"op":"mcm","clk":"5353177618","pt":1646210367102,"mc":[{"id":"1.195503861","rc":[{"atl":[[65,0],[48,0]],"id":41419585},{"atl":[[70,0]],"id":41419654}],"con":true,"img":false}]}
{"op":"mcm","clk":"5353177622","pt":1646210367204,"mc":[{"id":"1.195503861","rc":[{"atl":[[85,2],[110,12.96]],"id":41419585},{"atl":[[150,2],[200,7.22]],"id":41419654}],"con":true,"img":false}]}
{"op":"mcm","clk":"5353177629","pt":1646210367307,"mc":[{"id":"1.195503861","rc":[{"atl":[[250,0]],"id":41419599},{"atl":[[22,0],[23,4.96],[26,0],[27,9.92]],"id":41419590}],"con":true,"img":false}]}
{"op":"mcm","clk":"5353177635","pt":1646210367409,"mc":[{"id":"1.195503861","rc":[{"atl":[[430,5.42]],"id":41419599}],"con":true,"img":false}]}
{"op":"mcm","clk":"5353177639","pt":1646210367514,"mc":[{"id":"1.195503861","rc":[{"atl":[[810,0]],"id":41419653},{"atl":[[65,22.76],[110,0]],"id":41419585},{"atl":[[95,25.49],[200,0]],"id":41419654}],"con":true,"img":false}]}
{"op":"mcm","clk":"5353177658","pt":1646210367820,"mc":[{"id":"1.195503861","rc":[{"atl":[[80,2]],"id":41419585},{"atl":[[140,1.14]],"id":41419654}],"con":true,"img":false}]}
{"op":"mcm","clk":"5353177674","pt":1646210368232,"mc":[{"id":"1.195503861","rc":[{"atl":[[270,0],[260,4.96]],"id":41419608},{"atl":[[95,9.92]],"id":41419654},{"atl":[[65,2.48]],"id":41419590}],"con":true,"img":false}]}
{"op":"mcm","clk":"5353177680","pt":1646210368334,"mc":[{"id":"1.195503861","rc":[{"atl":[[780,2]],"id":41419608}],"con":true,"img":false}]}
{"op":"mcm","clk":"5353177686","pt":1646210368540,"mc":[{"id":"1.195503861","rc":[{"atl":[[990,1.3]],"id":41419608}],"con":true,"img":false}]}
{"op":"mcm","clk":"5353177690","pt":1646210368644,"mc":[{"id":"1.195503861","rc":[{"atb":[[260,0.61]],"id":41419657}],"con":true,"img":false}]}
{"op":"mcm","clk":"5353177698","pt":1646210368748,"mc":[{"id":"1.195503861","rc":[{"atl":[[780,3.89],[990,0]],"id":41419608},{"atl":[[65,24.63]],"id":41419590},{"atb":[[14,0]],"id":41419629}],"con":true,"img":false}]}
{"op":"mcm","clk":"5353177708","pt":1646210368850,"mc":[{"id":"1.195503861","rc":[{"atb":[[210,0]],"id":41419657},{"atl":[[810,2],[420,0]],"id":41419653},{"atl":[[70,2]],"id":41419590},{"atb":[[16.5,0]],"id":41419629}],"con":true,"img":false}]}
{"op":"mcm","clk":"5353177726","pt":1646210369315,"mc":[{"id":"1.195503861","rc":[{"atb":[[270,2.72]],"id":41419657}],"con":true,"img":false}]}
{"op":"mcm","clk":"5353177738","pt":1646210369624,"mc":[{"id":"1.195503861","rc":[{"atb":[[17.5,42.24],[15.5,9.92]],"id":41419613},{"atb":[[220,3.27]],"id":41419657},{"atb":[[17,28.31],[14.5,3.27]],"id":41419629}],"con":true,"img":false}]}
{"op":"mcm","clk":"5353177754","pt":1646210370035,"mc":[{"id":"1.195503861","rc":[{"atl":[[50,25.27],[60,11.92]],"id":41419592},{"atl":[[140,11.75]],"id":41419654}],"con":true,"img":false}]}
{"op":"mcm","clk":"5353177762","pt":1646210370137,"mc":[{"id":"1.195503861","rc":[{"atl":[[48,2.13],[60,9.92]],"id":41419592}],"con":true,"img":false}]}
{"op":"mcm","clk":"5353177809","pt":1646210371018,"mc":[{"id":"1.195503861","rc":[{"atl":[[290,4.96]],"id":41419651}],"con":true,"img":false}]}
{"op":"mcm","clk":"5353177824","pt":1646210371326,"mc":[{"id":"1.195503861","rc":[{"atl":[[270,0],[280,4.96]],"id":41419653},{"atl":[[290,0],[300,4.96]],"id":41419651},{"atl":[[260,4.96],[250,0.63]],"id":41419601}],"con":true,"img":false}]}
{"op":"mcm","clk":"5353177830","pt":1646210371428,"mc":[{"id":"1.195503861","rc":[{"atl":[[360,2],[450,0]],"id":41419651}],"con":true,"img":false}]}
{"op":"mcm","clk":"5353177850","pt":1646210371738,"mc":[{"id":"1.195503861","rc":[{"atl":[[300,5.49]],"id":41419651}],"con":true,"img":false}]}
{"op":"mcm","clk":"5353177869","pt":1646210372153,"mc":[{"id":"1.195503861","rc":[{"atl":[[280,5.52]],"id":41419653}],"con":true,"img":false}]}
{"op":"mcm","clk":"5353177885","pt":1646210372414,"mc":[{"id":"1.195503861","rc":[{"atl":[[230,4.96]],"id":41419599}],"con":true,"img":false}]}
{"op":"mcm","clk":"5353177906","pt":1646210372825,"mc":[{"id":"1.195503861","rc":[{"atl":[[270,0]],"id":41419601},{"atl":[[430,2],[240,4.96]],"id":41419599}],"con":true,"img":false}]}
{"op":"mcm","clk":"5353177909","pt":1646210372929,"mc":[{"id":"1.195503861","rc":[{"atl":[[230,0]],"id":41419599}],"con":true,"img":false}]}
{"op":"mcm","clk":"5353177924","pt":1646210373238,"mc":[{"id":"1.195503861","rc":[{"atl":[[670,4.22]],"id":41419601}],"con":true,"img":false}]}
{"op":"mcm","clk":"5353177937","pt":1646210373544,"mc":[{"id":"1.195503861","rc":[{"atl":[[240,5.62]],"id":41419599}],"con":true,"img":false}]}
{"op":"mcm","clk":"5353177944","pt":1646210373749,"mc":[{"id":"1.195503861","rc":[{"atb":[[5.7,21.28]],"id":41419628}],"con":true,"img":false}]}
{"op":"mcm","clk":"5353177950","pt":1646210373852,"mc":[{"id":"1.195503861","rc":[{"atb":[[5,0]],"id":41419628}],"con":true,"img":false}]}
{"op":"mcm","clk":"5353177962","pt":1646210374009,"mc":[{"id":"1.195503861","rc":[{"atl":[[11,20.84]],"id":41419627}],"con":true,"img":false}]}
{"op":"mcm","clk":"5353177977","pt":1646210374317,"mc":[{"id":"1.195503861","rc":[{"atl":[[260,5.75]],"id":41419599},{"atl":[[65,0],[70,31.34]],"id":41419585}],"con":true,"img":false}]}
{"op":"mcm","clk":"5353178004","pt":1646210375142,"mc":[{"id":"1.195503861","rc":[{"atl":[[20,19.83]],"id":41419627}],"con":true,"img":false}]}
{"op":"mcm","clk":"5353178009","pt":1646210375242,"mc":[{"id":"1.195503861","rc":[{"atl":[[48,0],[50,27.31]],"id":41419592}],"con":true,"img":false}]}
{"op":"mcm","clk":"5353178013","pt":1646210375345,"mc":[{"id":"1.195503861","rc":[{"atl":[[50,25.27],[60,11.92]],"id":41419592}],"con":true,"img":false}]}
{"op":"mcm","clk":"5353178019","pt":1646210375551,"mc":[{"id":"1.195503861","rc":[{"atb":[[36,0],[44,2.33]],"id":41419615},{"atb":[[34,0],[44,2.33]],"id":41419653},{"atb":[[8,14.29],[9.4,0]],"id":41419587},{"atl":[[85,14.26],[100,0]],"id":41419587},{"atb":[[38,0],[44,2.33]],"id":41419599},{"atl":[[760,0],[770,2]],"id":28546943},{"atl":[[780,1.89],[880,2]],"id":41419608},{"atb":[[9.2,0],[10.5,10.53]],"id":41419614}],"con":true,"img":false}]}
{"op":"mcm","clk":"5353178028","pt":1646210375860,"mc":[{"id":"1.195503861","rc":[{"atl":[[160,0],[180,4.96]],"id":41419615},{"atb":[[20,0],[25,0]],"id":41419613},{"atb":[[65,0],[75,9.92],[85,1.88],[95,4.96]],"id":41419593},{"atl":[[160,0],[200,4.96]],"id":41419593},{"atb":[[17.5,0],[19.5,12.26],[25,0],[30,0]],"id":41419587},{"atb":[[65,10.36],[80,4.96],[60,9.92]],"id":41419651},{"atb":[[70,0],[80,9.92],[90,1.78],[100,4.96]],"id":41419599},{"atb":[[10.5,11.67],[9.4,0]],"id":41419630},{"atl":[[18.5,9.07],[21,0]],"id":41419630},{"atb":[[14,14.94]],"id":41419597},{"atl":[[22,7.56],[24,4.96],[26,0],[28,9.92]],"id":41419597},{"atl":[[260,0],[280,4.96]],"id":41419608},{"atb":[[70,9.92],[80,2],[90,4.96],[60,0]],"id":41419604},{"atb":[[140,0],[150,6.02],[100,8.96],[110,9.92]],"id":41419602},{"atl":[[46,8.48]],"id":41419616},{"atb":[[28,8.6]],"id":41419614},{"atl":[[65,9.92],[44,3.23],[48,4.96],[55,0]],"id":41419614},{"atb":[[12,9.92],[13,23.38],[14,4.96]],"id":41419592},{"atl":[[270,4.96],[240,0.66]],"id":41419600},{"atb":[[6.2,4.96],[6.8,0],[6,0]],"id":41419627}],"con":true,"img":false}]}
{"op":"mcm","clk":"5353178044","pt":1646210376118,"mc":[{"id":"1.195503861","rc":[{"atb":[[9.6,4.96],[8.8,9.92]],"id":41419630},{"atl":[[16,4.96],[18,9.92]],"id":41419630}],"con":true,"img":false}]}
{"op":"mcm","clk":"5353178049","pt":1646210376220,"mc":[{"id":"1.195503861","rc":[{"atl":[[520,2.66],[450,2]],"id":41419615},{"atl":[[450,2],[510,2.82]],"id":41419593},{"atb":[[34,0],[38,2.7]],"id":41419604},{"atl":[[130,0],[140,2]],"id":41419614},{"atl":[[980,0],[990,3.23]],"id":41419600}],"con":true,"img":false}]}
{"op":"mcm","clk":"5353178054","pt":1646210376325,"mc":[{"id":"1.195503861","rc":[{"atl":[[520,4.66],[450,0]],"id":41419615},{"atl":[[510,4.82]],"id":41419593},{"atl":[[44,22.15],[28,3.7]],"id":41419630}],"con":true,"img":false}]}
{"op":"mcm","clk":"5353178060","pt":1646210376427,"mc":[{"id":"1.195503861","rc":[{"atl":[[520,2.66],[450,2]],"id":41419615},{"atl":[[450,0]],"id":41419593}],"con":true,"img":false}]}
{"op":"mcm","clk":"5353178064","pt":1646210376530,"mc":[{"id":"1.195503861","rc":[{"atb":[[17.5,14.58],[21,3.27],[13,42.44],[26,2.72]],"id":41419613},{"atb":[[75,24.49],[46,0],[48,1.57]],"id":41419593},{"atl":[[450,2],[510,2.82]],"id":41419593},{"atb":[[65,0],[75,18.35]],"id":41419651},{"atl":[[360,0],[460,5.1]],"id":41419651},{"atb":[[16.5,13.57],[8.6,68.17],[19.5,8.58],[21,3.27],[26,2.72],[14.5,9.92]],"id":41419587},{"atb":[[65,2.72],[70,2.3],[80,25.68]],"id":41419599},{"atb":[[12,4.96]],"id":41419597},{"atl":[[65,2],[28,46.94]],"id":41419597},{"atb":[[70,20.3],[42,2.72],[44,2.97]],"id":41419604},{"atl":[[110,12.26]],"id":41419616},{"atl":[[100,12.26]],"id":41419614},{"atb":[[13,11.12],[14,24.98]],"id":41419592},{"atl":[[990,2],[980,1.52]],"id":41419600},{"atb":[[6.4,3.27],[6.2,49.25]],"id":41419627}],"con":true,"img":false}]}
{"op":"mcm","clk":"5353178073","pt":1646210376633,"mc":[{"id":"1.195503861","rc":[{"atl":[[520,0]],"id":41419615},{"atl":[[450,0],[510,4.82]],"id":41419593},{"atb":[[6.4,116.13],[9.2,3.27]],"id":41419630},{"atl":[[19.5,72.88],[44,0],[15.5,10.94]],"id":41419630},{"atl":[[65,30.12],[100,0]],"id":41419614}],"con":true,"img":false}]}
{"op":"mcm","clk":"5353178079","pt":1646210376736,"mc":[{"id":"1.195503861","rc":[{"atl":[[450,2],[510,2.82]],"id":41419593}],"con":true,"img":false}]}
{"op":"mcm","clk":"5353178087","pt":1646210376840,"mc":[{"id":"1.195503861","rc":[{"atl":[[450,5.33]],"id":41419615},{"atl":[[450,3.33],[510,2]],"id":41419593},{"atl":[[50,0],[60,31.94]],"id":41419592}],"con":true,"img":false}]}
{"op":"mcm","clk":"5353178097","pt":1646210377148,"mc":[{"id":"1.195503861","rc":[{"atl":[[320,4.69],[460,2]],"id":41419651}],"con":true,"img":false}]}
{"op":"mcm","clk":"5353178120","pt":1646210377618,"mc":[{"id":"1.195503861","rc":[{"atb":[[48,0]],"id":41419593},{"atb":[[70,0]],"id":41419599},{"atl":[[18.5,0]],"id":41419630},{"atb":[[44,0]],"id":41419604}],"con":true,"img":false}]}
{"op":"mcm","clk":"5353178157","pt":1646210378339,"mc":[{"id":"1.195503861","rc":[{"atl":[[300,0.52]],"id":41419651}],"con":true,"img":false}]}
{"op":"mcm","clk":"5353178166","pt":1646210378544,"mc":[{"id":"1.195503861","rc":[{"atl":[[290,4.96]],"id":41419651}],"con":true,"img":false}]}
{"op":"mcm","clk":"5353178177","pt":1646210378749,"mc":[{"id":"1.195503861","rc":[{"atl":[[400,2],[460,0]],"id":41419651}],"con":true,"img":false}]}
{"op":"mcm","clk":"5353178287","pt":1646210381126,"mc":[{"id":"1.195503861","rc":[{"atl":[[70,9.92]],"id":41419585}],"con":true,"img":false}]}
{"op":"mcm","clk":"5353178311","pt":1646210381436,"mc":[{"id":"1.195503861","rc":[{"atl":[[260,0],[430,5.52]],"id":41419599},{"atl":[[80,20.98]],"id":41419585}],"con":true,"img":false}]}
{"op":"mcm","clk":"5353178329","pt":1646210381745,"mc":[{"id":"1.195503861","rc":[{"atl":[[48,3.37]],"id":41419585}],"con":true,"img":false}]}
{"op":"mcm","clk":"5353178340","pt":1646210382052,"mc":[{"id":"1.195503861","rc":[{"atl":[[75,7.1]],"id":41419654}],"con":true,"img":false}]}
{"op":"mcm","clk":"5353178353","pt":1646210382361,"mc":[{"id":"1.195503861","rc":[{"atl":[[23,12.17]],"id":41419590}],"con":true,"img":false}]}
{"op":"mcm","clk":"5353178363","pt":1646210382567,"mc":[{"id":"1.195503861","rc":[{"atl":[[70,0],[46,2.22]],"id":41419590}],"con":true,"img":false}]}
{"op":"mcm","clk":"5353178378","pt":1646210382826,"mc":[{"id":"1.195503861","rc":[{"atl":[[80,18.97]],"id":41419585},{"atl":[[140,10.61]],"id":41419654}],"con":true,"img":false}]}
{"op":"mcm","clk":"5353178382","pt":1646210382929,"mc":[{"id":"1.195503861","rc":[{"atl":[[450,5.33],[510,0]],"id":41419593}],"con":true,"img":false}]}
{"op":"mcm","clk":"5353178388","pt":1646210383032,"mc":[{"id":"1.195503861","rc":[{"atl":[[65,2.48],[46,35.11]],"id":41419590}],"con":true,"img":false}]}
{"op":"mcm","clk":"5353178407","pt":1646210383444,"mc":[{"id":"1.195503861","rc":[{"atl":[[65,0]],"id":41419590}],"con":true,"img":false}]}
{"op":"mcm","clk":"5353178413","pt":1646210383547,"mc":[{"id":"1.195503861","rc":[{"atb":[[17.5,42.24]],"id":41419613},{"atl":[[300,5.49]],"id":41419651}],"con":true,"img":false}]}
{"op":"mcm","clk":"5353178419","pt":1646210383649,"mc":[{"id":"1.195503861","rc":[{"atb":[[13,11.12]],"id":41419613},{"atl":[[290,0]],"id":41419651},{"atb":[[13,0],[15.5,0]],"id":41419618},{"atb":[[6.8,0],[7.8,53.64]],"id":41419628}],"con":true,"img":false}]}
{"op":"mcm","clk":"5353178424","pt":1646210383752,"mc":[{"id":"1.195503861","rc":[{"atl":[[260,0],[250,5.6]],"id":41419601}],"con":true,"img":false}]}
{"op":"mcm","clk":"5353178437","pt":1646210384060,"mc":[{"id":"1.195503861","rc":[{"atl":[[50,25.27],[60,11.92]],"id":41419592}],"con":true,"img":false}]}
{"op":"mcm","clk":"5353178442","pt":1646210384164,"mc":[{"id":"1.195503861","rc":[{"atl":[[270,5.64]],"id":41419601},{"atl":[[55,2],[60,9.92]],"id":41419592}],"con":true,"img":false}]}
{"op":"mcm","clk":"5353178446","pt":1646210384267,"mc":[{"id":"1.195503861","rc":[{"atl":[[320,0],[400,5.81]],"id":41419651},{"atb":[[6.8,62.72],[12.5,18.77]],"id":41419618},{"atl":[[670,2]],"id":41419601}],"con":true,"img":false}]}
{"op":"mcm","clk":"5353178450","pt":1646210384322,"mc":[{"id":"1.195503861","rc":[{"atb":[[16,2.72],[13.5,3.27]],"id":41419618},{"atb":[[8,2.72],[7,3.27]],"id":41419628}],"con":true,"img":false}]}
{"op":"mcm","clk":"5353178468","pt":1646210384733,"mc":[{"id":"1.195503861","rc":[{"atl":[[22,12.52]],"id":41419618}],"con":true,"img":false}]}
{"op":"mcm","clk":"5353178482","pt":1646210385042,"mc":[{"id":"1.195503861","rc":[{"atl":[[270,0]],"id":41419601},{"atb":[[8,42.38],[7.8,9.92]],"id":41419628}],"con":true,"img":false}]}
{"op":"mcm","clk":"5353178503","pt":1646210385564,"mc":[{"id":"1.195503861","rc":[{"atl":[[22,4.96],[26,9.92]],"id":41419618}],"con":true,"img":false}]}
{"op":"mcm","clk":"5353178544","pt":1646210386242,"mc":[{"id":"1.195503861","rc":[{"atl":[[50,3.24]],"id":41419618}],"con":true,"img":false}]}
{"op":"mcm","clk":"5353178568","pt":1646210386755,"mc":[{"id":"1.195503861","rc":[{"atl":[[55,2]],"id":41419618}],"con":true,"img":false}]}
{"op":"mcm","clk":"5353178582","pt":1646210387066,"mc":[{"id":"1.195503861","rc":[{"atl":[[50,15.5]],"id":41419618}],"con":true,"img":false}]}
{"op":"mcm","clk":"5353178593","pt":1646210387326,"mc":[{"id":"1.195503861","rc":[{"atl":[[270,5.67]],"id":41419601}],"con":true,"img":false}]}
{"op":"mcm","clk":"5353178637","pt":1646210388149,"mc":[{"id":"1.195503861","rc":[{"atl":[[80,0]],"id":41419585}],"con":true,"img":false}]}
{"op":"mcm","clk":"5353178650","pt":1646210388456,"mc":[{"id":"1.195503861","rc":[{"atl":[[260,5.91],[430,2]],"id":41419599},{"atl":[[70,29.57]],"id":41419585}],"con":true,"img":false}]}
{"op":"mcm","clk":"5353178668","pt":1646210388762,"mc":[{"id":"1.195503861","rc":[{"atl":[[400,2]],"id":41419651},{"atl":[[260,4.96]],"id":41419601}],"con":true,"img":false}]}
{"op":"mcm","clk":"5353178671","pt":1646210388865,"mc":[{"id":"1.195503861","rc":[{"atl":[[250,0.63]],"id":41419601}],"con":true,"img":false}]}
{"op":"mcm","clk":"5353178699","pt":1646210389278,"mc":[{"id":"1.195503861","rc":[{"atl":[[260,0]],"id":41419599}],"con":true,"img":false}]}
{"op":"mcm","clk":"5353178713","pt":1646210389539,"mc":[{"id":"1.195503861","rc":[{"atl":[[270,0]],"id":41419601}],"con":true,"img":false}]}
{"op":"mcm","clk":"5353178753","pt":1646210390259,"mc":[{"id":"1.195503861","rc":[{"atb":[[95,6.64]],"id":41419593}],"con":true,"img":false}]}
{"op":"mcm","clk":"5353178758","pt":1646210390360,"mc":[{"id":"1.195503861","rc":[{"atb":[[90,6.74]],"id":41419604}],"con":true,"img":false}]}
{"op":"mcm","clk":"5353178762","pt":1646210390464,"mc":[{"id":"1.195503861","rc":[{"atb":[[8.6,35.13],[19.5,32.74]],"id":41419587},{"atb":[[100,6.56]],"id":41419599},{"atb":[[6.4,43.24],[9.2,25.42]],"id":41419630},{"atl":[[18,32.07],[19.5,0]],"id":41419630}],"con":true,"img":false}]}
{"op":"mcm","clk":"5353178773","pt":1646210390773,"mc":[{"id":"1.195503861","rc":[{"atl":[[50,0],[55,19.52]],"id":41419592}],"con":true,"img":false}]}
{"op":"mcm","clk":"5353178786","pt":1646210391036,"mc":[{"id":"1.195503861","rc":[{"atb":[[85,0]],"id":41419593},{"atl":[[320,4.82]],"id":41419651}],"con":true,"img":false}]}
{"op":"mcm","clk":"5353178799","pt":1646210391454,"mc":[{"id":"1.195503861","rc":[{"atb":[[90,0]],"id":41419599},{"atb":[[80,0]],"id":41419604}],"con":true,"img":false}]}
{"op":"mcm","clk":"5353178802","pt":1646210391551,"mc":[{"id":"1.195503861","rc":[{"atb":[[75,9.92],[44,18.06]],"id":41419593}],"con":true,"img":false}]}
{"op":"mcm","clk":"5353178811","pt":1646210391861,"mc":[{"id":"1.195503861","rc":[{"atb":[[65,19.49],[80,9.92]],"id":41419599},{"atb":[[70,9.92],[42,15.66]],"id":41419604}],"con":true,"img":false}]}
{"op":"mcm","clk":"5353178924","pt":1646210394642,"mc":[{"id":"1.195503861","rc":[{"atb":[[20,9.92],[21,22.15],[24,4.96],[25,0]],"id":41419611},{"atb":[[9,4.96],[9.2,0],[8.2,42.07],[8.4,2.72]],"id":41419631}],"con":true,"img":false}]}
{"op":"mcm","clk":"5353178941","pt":1646210394951,"mc":[{"id":"1.195503861","rc":[{"atb":[[21,0],[26,0]],"id":41419587}],"con":true,"img":false}]}
{"op":"mcm","clk":"5353178956","pt":1646210395261,"mc":[{"id":"1.195503861","rc":[{"atl":[[260,5.98]],"id":41419599}],"con":true,"img":false}]}
{"op":"mcm","clk":"5353178976","pt":1646210395568,"mc":[{"id":"1.195503861","rc":[{"atb":[[23,9.94]],"id":41419611},{"atb":[[8.4,17.49]],"id":41419631}],"con":true,"img":false}]}
{"op":"mcm","clk":"5353179005","pt":1646210395979,"mc":[{"id":"1.195503861","rc":[{"atb":[[22,3.27],[27,2.72]],"id":41419587}],"con":true,"img":false}]}
{"op":"mcm","clk":"5353179070","pt":1646210397275,"mc":[{"id":"1.195503861","rc":[{"atl":[[280,4.96]],"id":41419653},{"atl":[[260,0],[250,5.6]],"id":41419601},{"atl":[[290,4.96]],"id":28546943},{"atl":[[75,9.92],[46,3.52],[55,4.96],[60,0]],"id":41419616}],"con":true,"img":false}]}
{"op":"mcm","clk":"5353179074","pt":1646210397379,"mc":[{"id":"1.195503861","rc":[{"atl":[[46,0]],"id":41419616}],"con":true,"img":false}]}
{"op":"mcm","clk":"5353179079","pt":1646210397488,"mc":[{"id":"1.195503861","rc":[{"atb":[[40,2.72],[42,9.92],[48,3.37],[50,4.96]],"id":41419609},{"atb":[[65,0],[80,9.92],[85,1.88],[100,4.96]],"id":41419615},{"atb":[[16,9.92],[17.5,37.28],[18,4.96],[15.5,0]],"id":41419613},{"atl":[[280,0],[290,4.96]],"id":41419653},{"atl":[[75,9.92],[80,0],[55,4.96],[60,2.69]],"id":41419587},{"atl":[[300,0.52],[290,4.96]],"id":41419651},{"atb":[[10.5,0],[11,9.92],[12.5,13.81],[13,4.96]],"id":41419618},{"atl":[[250,4.96]],"id":41419601},{"atl":[[230,4.96],[240,0.66]],"id":41419599},{"atl":[[370,2],[770,0]],"id":28546943},{"atb":[[8,52.3],[8.6,0],[8.8,25.32],[7.8,0]],"id":41419628},{"atb":[[85,9.76],[90,9.92],[110,0],[120,6.29]],"id":41419608},{"atb":[[17,0],[17.5,9.92],[19,3.27],[19.5,4.96]],"id":41419585},{"atb":[[20,0],[22,9.92],[24,0],[26,4.96]],"id":41419614},{"atl":[[44,4.96],[46,3.52],[55,11.92],[60,26.07]],"id":41419592},{"atl":[[22,4.96],[23,7.21],[26,9.92],[27,0]],"id":41419590},{"atb":[[85,10.36],[90,9.92],[110,0],[120,6.29]],"id":41419600},{"atb":[[9.6,4.96],[9,0],[8.2,32.15],[8.8,9.92]],"id":41419631},{"atb":[[20,0],[21,9.92],[24,6.9],[25,4.96]],"id":41419629},{"atl":[[10,4.96],[11,15.87],[12,9.92],[13,0]],"id":41419627}],"con":true,"img":false}]}
{"op":"mcm","clk":"5353179084","pt":1646210397588,"mc":[{"id":"1.195503861","rc":[{"atl":[[150,0],[120,2]],"id":41419616},{"atl":[[1000,0.15]],"id":41419656},{"atl":[[70,4.96],[75,2.14],[90,9.92],[95,0]],"id":41419654}],"con":true,"img":false}]}
{"op":"mcm","clk":"5353179088","pt":1646210397643,"mc":[{"id":"1.195503861","rc":[{"atl":[[440,2]],"id":41419653}],"con":true,"img":false}]}
{"op":"mcm","clk":"5353179093","pt":1646210397747,"mc":[{"id":"1.195503861","rc":[{"atl":[[1000,2.15]],"id":28546950},{"atb":[[70,9.92],[75,0],[90,4.96],[95,0]],"id":41419593},{"atl":[[810,0]],"id":41419653},{"atl":[[320,0],[400,5.9]],"id":41419651},{"atl":[[290,5.51],[770,2.02],[840,0]],"id":28546943},{"atb":[[65,9.92],[70,0],[85,4.96],[90,0]],"id":41419604},{"atl":[[75,22.56],[110,0]],"id":41419616},{"atb":[[24,0]],"id":41419629},{"atl":[[1000,0.15]],"id":41419658},{"atl":[[50,4.96]],"id":41419594}],"con":true,"img":false}]}
{"op":"mcm","clk":"5353179098","pt":1646210397849,"mc":[{"id":"1.195503861","rc":[{"atb":[[18,25.24]],"id":41419613},{"atl":[[810,2],[440,0]],"id":41419653},{"atl":[[270,5.79]],"id":41419601},{"atb":[[18,0]],"id":41419585},{"atb":[[8.4,43.51]],"id":41419631},{"atl":[[20,0],[9.8,18.04]],"id":41419627},{"atl":[[70,0],[75,9.92],[50,0],[55,4.96]],"id":41419594}],"con":true,"img":false}]}
{"op":"mcm","clk":"5353179102","pt":1646210397954,"mc":[{"id":"1.195503861","rc":[{"atb":[[42,24.68],[50,8.2],[30,3.27]],"id":41419609},{"atb":[[80,24.68],[48,2.72]],"id":41419615},{"atb":[[17.5,9.62]],"id":41419613},{"atl":[[280,0.56]],"id":41419651},{"atl":[[75,22.18],[85,2],[55,7.9]],"id":41419587},{"atb":[[6.8,17.24],[12.5,35.96]],"id":41419618},{"atl":[[220,0.72]],"id":41419599},{"atb":[[8,12.65],[7,65.85]],"id":41419628},{"atb":[[19,15.69]],"id":41419585},{"atl":[[44,8.65]],"id":41419592},{"atb":[[8.2,0]],"id":41419631},{"atb":[[17,2.72],[21,31.03]],"id":41419629},{"atl":[[12,32.07]],"id":41419627},{"atl":[[120,2]],"id":41419594}],"con":true,"img":false}]}
{"op":"mcm","clk":"5353179107","pt":1646210398057,"mc":[{"id":"1.195503861","rc":[{"atl":[[280,0.56],[810,3.81],[820,0]],"id":41419653},{"atl":[[260,4.96],[250,0]],"id":41419601},{"atl":[[65,0],[70,4.96],[85,0],[90,9.92]],"id":41419606},{"atl":[[70,2.3]],"id":41419616},{"atl":[[70,7.26],[140,0],[90,27.32]],"id":41419654},{"atl":[[21,7.94],[46,2.22],[26,35.44]],"id":41419590},{"atl":[[170,8.37]],"id":41419594}],"con":true,"img":false}]}
{"op":"mcm","clk":"5353179113","pt":1646210398161,"mc":[{"id":"1.195503861","rc":[{"atb":[[70,9.92],[80,14.76],[90,4.96],[100,0]],"id":41419615},{"atb":[[65,0],[75,12.86],[85,2.42],[95,4.96]],"id":41419653},{"atl":[[270,4.96],[290,0]],"id":41419653},{"atl":[[75,12.26],[80,9.92],[55,2.94],[60,7.65]],"id":41419587},{"atb":[[9.6,0],[8.6,9.92],[8.8,0],[9.4,4.96]],"id":41419631},{"atb":[[19.5,9.92],[21,21.1],[23,4.96],[25,0]],"id":41419629}],"con":true,"img":false}]}
