{"op":"mcm","clk":"5345985289","pt":1646174444249,"mc":[{"id":"1.195453618","marketDefinition":{"bspMarket":true,"turnInPlayEnabled":false,"persistenceEnabled":false,"marketBaseRate":7.0,"eventId":"31272494","eventTypeId":"4339","numberOfWinners":3,"bettingType":"ODDS","marketType":"PLACE","marketTime":"2022-03-02T09:50:00.000Z","suspendTime":"2022-03-02T09:50:00.000Z","bspReconciled":false,"complete":true,"inPlay":false,"crossMatching":false,"runnersVoidable":false,"numberOfActiveRunners":8,"betDelay":0,"status":"OPEN","runners":[{"status":"ACTIVE","sortPriority":1,"id":39209038,"name":"1. Dr Neeki"},{"status":"ACTIVE","sortPriority":2,"id":40812743,"name":"2. Establishment"},{"status":"ACTIVE","sortPriority":3,"id":43167174,"name":"3. Dr Jax"},{"status":"ACTIVE","sortPriority":4,"id":40908229,"name":"4. Zippy Artist"},{"status":"ACTIVE","sortPriority":5,"id":39980030,"name":"5. Shes Miss Orson"},{"status":"ACTIVE","sortPriority":6,"id":43167175,"name":"6. Ultimate Teddy"},{"status":"ACTIVE","sortPriority":7,"id":42300273,"name":"7. Dr Audrey"},{"status":"ACTIVE","sortPriority":8,"id":42390009,"name":"8. Basil Brush Rose"}],"regulators":["MR_INT"],"venue":"Traralgon","countryCode":"AU","discountAllowed":true,"timezone":"Australia/Sydney","openDate":"2022-03-02T08:31:00.000Z","version":4382425363,"name":"To Be Placed","eventName":"Traralgon (AUS) 2nd Mar"},"rc":[],"con":true,"img":false}]}
{"op":"mcm","clk":"5346059509","pt":1646175786400,"mc":[{"id":"1.195453618","rc":[{"atb":[[1.4,249.25],[1.3,332.33],[1.35,284.86]],"id":39209038},{"atl":[[2.86,38.98],[2.66,21.83],[3.15,33.72]],"id":39209038},{"spn":2.03,"spf":"NaN","id":39209038},{"atb":[[4.3,30.21],[3.9,34.38],[3.65,37.62]],"id":40812743},{"atl":[[32,2.34],[21,3.62],[15.5,2.49]],"id":40812743},{"spn":9.9,"spf":"NaN","id":40812743},{"atb":[[1.45,221.55],[1.55,181.27],[1.5,199.4]],"id":43167174},{"atl":[[2.82,19.91],[3.55,28.43],[3.05,35.37]],"id":43167174},{"spn":2.18,"spf":"NaN","id":43167174},{"atb":[[1.2,498.5],[1.25,398.8],[1.3,332.33]],"id":42300273},{"atl":[[2.54,23.54],[2.74,41.67],[2.94,37.37]],"id":42300273},{"spn":1.92,"spf":"NaN","id":42300273},{"atb":[[1.6,166.16],[1.55,181.27],[1.65,153.38]],"id":43167175},{"atl":[[3.45,29.59],[3.95,24.57],[2.98,18.31]],"id":43167175},{"spn":2.31,"spf":"NaN","id":43167175},{"atb":[[2.36,73.3],[2.26,79.12],[2.16,85.94]],"id":40908229},{"atl":[[7.4,11.32],[5.7,7.71],[9.4,8.63]],"id":40908229},{"spn":4.03,"spf":"NaN","id":40908229},{"atb":[[1.2,498.5],[1.25,398.8],[1.3,332.33]],"id":42390009},{"atl":[[2.54,23.54],[2.74,41.67],[2.94,37.37]],"id":42390009},{"spn":1.92,"spf":"NaN","id":42390009},{"atb":[[2.82,54.77],[2.92,51.92],[3.05,48.63]],"id":39980030},{"atl":[[10.5,7.63],[8.2,5.03],[15.5,5]],"id":39980030},{"spn":5.62,"spf":"NaN","id":39980030}],"con":true,"img":false}]}
{"op":"mcm","clk":"5346061998","pt":1646175839944,"mc":[{"id":"1.195453618","rc":[{"atb":[[1.4,0],[1.3,0],[1.35,0]],"id":39209038},{"atl":[[2.86,0],[2.66,0],[3.15,0]],"id":39209038},{"atb":[[4.3,0],[3.9,0],[3.65,0]],"id":40812743},{"atl":[[32,0],[21,0],[15.5,0]],"id":40812743},{"atb":[[1.45,0],[1.55,0],[1.5,0]],"id":43167174},{"atl":[[2.82,0],[3.55,0],[3.05,0]],"id":43167174},{"atb":[[1.2,0],[1.25,0],[1.3,0]],"id":42300273},{"atl":[[2.54,0],[2.74,0],[2.94,0]],"id":42300273},{"atb":[[1.6,0],[1.55,0],[1.65,0]],"id":43167175},{"atl":[[3.45,0],[3.95,0],[2.98,0]],"id":43167175},{"atb":[[2.36,0],[2.26,0],[2.16,0]],"id":40908229},{"atl":[[7.4,0],[5.7,0],[9.4,0]],"id":40908229},{"atb":[[1.2,0],[1.25,0],[1.3,0]],"id":42390009},{"atl":[[2.54,0],[2.74,0],[2.94,0]],"id":42390009},{"atb":[[2.82,0],[2.92,0],[3.05,0]],"id":39980030},{"atl":[[10.5,0],[8.2,0],[15.5,0]],"id":39980030}],"con":true,"img":false}]}
{"op":"mcm","clk":"5346062130","pt":1646175843036,"mc":[{"id":"1.195453618","rc":[{"atb":[[1.4,249.25],[1.3,332.33],[1.35,284.86]],"id":39209038},{"atl":[[2.86,38.98],[2.66,21.83],[3.15,33.72]],"id":39209038},{"atb":[[4.3,30.21],[3.9,34.38],[3.65,37.62]],"id":40812743},{"atl":[[32,2.34],[21,3.62],[15.5,2.49]],"id":40812743},{"atb":[[1.45,221.55],[1.55,181.27],[1.5,199.4]],"id":43167174},{"atl":[[2.82,19.91],[3.55,28.43],[3.05,35.37]],"id":43167174},{"atb":[[1.2,498.5],[1.25,398.8],[1.3,332.33]],"id":42300273},{"atl":[[2.54,23.54],[2.74,41.67],[2.94,37.37]],"id":42300273},{"atb":[[1.6,166.16],[1.55,181.27],[1.65,153.38]],"id":43167175},{"atl":[[3.45,29.59],[3.95,24.57],[2.98,18.31]],"id":43167175},{"atb":[[2.36,73.3],[2.26,79.12],[2.16,85.94]],"id":40908229},{"atl":[[7.4,11.32],[5.7,7.71],[9.4,8.63]],"id":40908229},{"atb":[[1.2,498.5],[1.25,398.8],[1.3,332.33]],"id":42390009},{"atl":[[2.54,23.54],[2.74,41.67],[2.94,37.37]],"id":42390009},{"atb":[[2.82,54.77],[2.92,51.92],[3.05,48.63]],"id":39980030},{"atl":[[10.5,7.63],[8.2,5.03],[15.5,5]],"id":39980030}],"con":true,"img":false}]}
{"op":"mcm","clk":"5346105155","pt":1646176602701,"mc":[{"id":"1.195453618","marketDefinition":{"bspMarket":true,"turnInPlayEnabled":false,"persistenceEnabled":false,"marketBaseRate":7.0,"eventId":"31272494","eventTypeId":"4339","numberOfWinners":3,"bettingType":"ODDS","marketType":"PLACE","marketTime":"2022-03-02T09:50:00.000Z","suspendTime":"2022-03-02T09:50:00.000Z","bspReconciled":false,"complete":true,"inPlay":false,"crossMatching":false,"runnersVoidable":false,"numberOfActiveRunners":8,"betDelay":0,"status":"OPEN","runners":[{"status":"ACTIVE","sortPriority":1,"id":39209038,"name":"1. Dr Neeki"},{"status":"ACTIVE","sortPriority":2,"id":40812743,"name":"2. Establishment"},{"status":"ACTIVE","sortPriority":3,"id":43167174,"name":"3. Dr Jax"},{"status":"ACTIVE","sortPriority":4,"id":40908229,"name":"4. Zippy Artist"},{"status":"ACTIVE","sortPriority":5,"id":39980030,"name":"5. Shes Miss Orson"},{"status":"ACTIVE","sortPriority":6,"id":43167175,"name":"6. Ultimate Teddy"},{"status":"ACTIVE","sortPriority":7,"id":42300273,"name":"7. Dr Audrey"},{"status":"ACTIVE","sortPriority":8,"id":42390009,"name":"8. Basil Brush Rose"}],"regulators":["MR_INT"],"venue":"Traralgon","countryCode":"AU","discountAllowed":true,"timezone":"Australia/Sydney","openDate":"2022-03-02T08:31:00.000Z","version":4382425363,"name":"To Be Placed","eventName":"Traralgon (AUS) 2nd Mar"},"rc":[{"atb":[[1.4,249.25],[1.3,332.33],[1.35,284.86]],"id":39209038},{"atl":[[2.86,38.98],[2.66,21.83],[3.15,33.72]],"id":39209038},{"spn":2.03,"spf":"NaN","id":39209038},{"atb":[[4.3,30.21],[3.9,34.38],[3.65,37.62]],"id":40812743},{"atl":[[32,2.34],[21,3.62],[15.5,2.49]],"id":40812743},{"spn":9.9,"spf":"NaN","id":40812743},{"atb":[[1.45,221.55],[1.55,181.27],[1.5,199.4]],"id":43167174},{"atl":[[2.82,19.91],[3.55,28.43],[3.05,35.37]],"id":43167174},{"spn":2.18,"spf":"NaN","id":43167174},{"atb":[[1.2,498.5],[1.25,398.8],[1.3,332.33]],"id":42300273},{"atl":[[2.54,23.54],[2.74,41.67],[2.94,37.37]],"id":42300273},{"spn":1.92,"spf":"NaN","id":42300273},{"atb":[[1.6,166.16],[1.55,181.27],[1.65,153.38]],"id":43167175},{"atl":[[3.45,29.59],[3.95,24.57],[2.98,18.31]],"id":43167175},{"spn":2.31,"spf":"NaN","id":43167175},{"atb":[[2.36,73.3],[2.26,79.12],[2.16,85.94]],"id":40908229},{"atl":[[7.4,11.32],[5.7,7.71],[9.4,8.63]],"id":40908229},{"spn":4.03,"spf":"NaN","id":40908229},{"atb":[[1.2,498.5],[1.25,398.8],[1.3,332.33]],"id":42390009},{"atl":[[2.54,23.54],[2.74,41.67],[2.94,37.37]],"id":42390009},{"spn":1.92,"spf":"NaN","id":42390009},{"atb":[[2.82,54.77],[2.92,51.92],[3.05,48.63]],"id":39980030},{"atl":[[10.5,7.63],[8.2,5.03],[15.5,5]],"id":39980030},{"spn":5.62,"spf":"NaN","id":39980030}],"con":true,"img":true}]}
{"op":"mcm","clk":"5346401613","pt":1646182002788,"mc":[{"id":"1.195453618","marketDefinition":{"bspMarket":true,"turnInPlayEnabled":false,"persistenceEnabled":false,"marketBaseRate":7.0,"eventId":"31272494","eventTypeId":"4339","numberOfWinners":3,"bettingType":"ODDS","marketType":"PLACE","marketTime":"2022-03-02T09:50:00.000Z","suspendTime":"2022-03-02T09:50:00.000Z","bspReconciled":false,"complete":true,"inPlay":false,"crossMatching":false,"runnersVoidable":false,"numberOfActiveRunners":8,"betDelay":0,"status":"OPEN","runners":[{"status":"ACTIVE","sortPriority":1,"id":39209038,"name":"1. Dr Neeki"},{"status":"ACTIVE","sortPriority":2,"id":40812743,"name":"2. Establishment"},{"status":"ACTIVE","sortPriority":3,"id":43167174,"name":"3. Dr Jax"},{"status":"ACTIVE","sortPriority":4,"id":40908229,"name":"4. Zippy Artist"},{"status":"ACTIVE","sortPriority":5,"id":39980030,"name":"5. Shes Miss Orson"},{"status":"ACTIVE","sortPriority":6,"id":43167175,"name":"6. Ultimate Teddy"},{"status":"ACTIVE","sortPriority":7,"id":42300273,"name":"7. Dr Audrey"},{"status":"ACTIVE","sortPriority":8,"id":42390009,"name":"8. Basil Brush Rose"}],"regulators":["MR_INT"],"venue":"Traralgon","countryCode":"AU","discountAllowed":true,"timezone":"Australia/Sydney","openDate":"2022-03-02T08:31:00.000Z","version":4382425363,"name":"To Be Placed","eventName":"Traralgon (AUS) 2nd Mar"},"rc":[{"atb":[[1.4,249.28],[1.3,332.37],[1.35,284.89]],"id":39209038},{"atl":[[2.86,38.98],[2.66,21.84],[3.15,33.72]],"id":39209038},{"spn":2.03,"spf":"NaN","id":39209038},{"atb":[[4.3,30.21],[3.9,34.38],[3.65,37.62]],"id":40812743},{"atl":[[32,2.34],[21,3.62],[15.5,2.49]],"id":40812743},{"spn":9.9,"spf":"NaN","id":40812743},{"atb":[[1.45,221.58],[1.55,181.29],[1.5,199.42]],"id":43167174},{"atl":[[2.82,19.92],[3.55,28.44],[3.05,35.37]],"id":43167174},{"spn":2.18,"spf":"NaN","id":43167174},{"atb":[[1.2,498.55],[1.25,398.84],[1.3,332.37]],"id":42300273},{"atl":[[2.54,23.54],[2.74,41.67],[2.94,37.38]],"id":42300273},{"spn":1.92,"spf":"NaN","id":42300273},{"atb":[[1.6,166.18],[1.55,181.29],[1.65,153.4]],"id":43167175},{"atl":[[3.45,29.6],[3.95,24.58],[2.98,18.31]],"id":43167175},{"spn":2.31,"spf":"NaN","id":43167175},{"atb":[[2.36,73.31],[2.26,79.13],[2.16,85.95]],"id":40908229},{"atl":[[7.4,11.32],[5.7,7.71],[9.4,8.63]],"id":40908229},{"spn":4.03,"spf":"NaN","id":40908229},{"atb":[[1.2,498.55],[1.25,398.84],[1.3,332.37]],"id":42390009},{"atl":[[2.54,23.54],[2.74,41.67],[2.94,37.38]],"id":42390009},{"spn":1.92,"spf":"NaN","id":42390009},{"atb":[[2.82,54.78],[2.92,51.93],[3.05,48.63]],"id":39980030},{"atl":[[10.5,7.63],[8.2,5.03],[15.5,5]],"id":39980030},{"spn":5.62,"spf":"NaN","id":39980030}],"con":true,"img":true}]}
{"op":"mcm","clk":"5346767967","pt":1646187402733,"mc":[{"id":"1.195453618","marketDefinition":{"bspMarket":true,"turnInPlayEnabled":false,"persistenceEnabled":false,"marketBaseRate":7.0,"eventId":"31272494","eventTypeId":"4339","numberOfWinners":3,"bettingType":"ODDS","marketType":"PLACE","marketTime":"2022-03-02T09:50:00.000Z","suspendTime":"2022-03-02T09:50:00.000Z","bspReconciled":false,"complete":true,"inPlay":false,"crossMatching":false,"runnersVoidable":false,"numberOfActiveRunners":8,"betDelay":0,"status":"OPEN","runners":[{"status":"ACTIVE","sortPriority":1,"id":39209038,"name":"1. Dr Neeki"},{"status":"ACTIVE","sortPriority":2,"id":40812743,"name":"2. Establishment"},{"status":"ACTIVE","sortPriority":3,"id":43167174,"name":"3. Dr Jax"},{"status":"ACTIVE","sortPriority":4,"id":40908229,"name":"4. Zippy Artist"},{"status":"ACTIVE","sortPriority":5,"id":39980030,"name":"5. Shes Miss Orson"},{"status":"ACTIVE","sortPriority":6,"id":43167175,"name":"6. Ultimate Teddy"},{"status":"ACTIVE","sortPriority":7,"id":42300273,"name":"7. Dr Audrey"},{"status":"ACTIVE","sortPriority":8,"id":42390009,"name":"8. Basil Brush Rose"}],"regulators":["MR_INT"],"venue":"Traralgon","countryCode":"AU","discountAllowed":true,"timezone":"Australia/Sydney","openDate":"2022-03-02T08:31:00.000Z","version":4382425363,"name":"To Be Placed","eventName":"Traralgon (AUS) 2nd Mar"},"rc":[{"atb":[[1.4,249.67],[1.3,332.89],[1.35,285.34]],"id":39209038},{"atl":[[2.86,39.04],[2.66,21.87],[3.15,33.78]],"id":39209038},{"spn":2.03,"spf":"NaN","id":39209038},{"atb":[[4.3,30.26],[3.9,34.44],[3.65,37.68]],"id":40812743},{"atl":[[32,2.34],[21,3.63],[15.5,2.5]],"id":40812743},{"spn":9.9,"spf":"NaN","id":40812743},{"atb":[[1.45,221.93],[1.55,181.58],[1.5,199.73]],"id":43167174},{"atl":[[2.82,19.95],[3.55,28.48],[3.05,35.43]],"id":43167174},{"spn":2.18,"spf":"NaN","id":43167174},{"atb":[[1.2,499.34],[1.25,399.47],[1.3,332.89]],"id":42300273},{"atl":[[2.54,23.58],[2.74,41.74],[2.94,37.43]],"id":42300273},{"spn":1.92,"spf":"NaN","id":42300273},{"atb":[[1.6,166.44],[1.55,181.58],[1.65,153.64]],"id":43167175},{"atl":[[3.45,29.64],[3.95,24.61],[2.98,18.34]],"id":43167175},{"spn":2.31,"spf":"NaN","id":43167175},{"atb":[[2.36,73.43],[2.26,79.26],[2.16,86.09]],"id":40908229},{"atl":[[7.4,11.34],[5.7,7.72],[9.4,8.64]],"id":40908229},{"spn":4.03,"spf":"NaN","id":40908229},{"atb":[[1.2,499.34],[1.25,399.47],[1.3,332.89]],"id":42390009},{"atl":[[2.54,23.58],[2.74,41.74],[2.94,37.43]],"id":42390009},{"spn":1.92,"spf":"NaN","id":42390009},{"atb":[[2.82,54.87],[2.92,52.01],[3.05,48.71]],"id":39980030},{"atl":[[10.5,7.64],[8.2,5.04],[15.5,5.01]],"id":39980030},{"spn":5.62,"spf":"NaN","id":39980030}],"con":true,"img":true}]}
{"op":"mcm","clk":"5347092518","pt":1646192802713,"mc":[{"id":"1.195453618","marketDefinition":{"bspMarket":true,"turnInPlayEnabled":false,"persistenceEnabled":false,"marketBaseRate":7.0,"eventId":"31272494","eventTypeId":"4339","numberOfWinners":3,"bettingType":"ODDS","marketType":"PLACE","marketTime":"2022-03-02T09:50:00.000Z","suspendTime":"2022-03-02T09:50:00.000Z","bspReconciled":false,"complete":true,"inPlay":false,"crossMatching":false,"runnersVoidable":false,"numberOfActiveRunners":8,"betDelay":0,"status":"OPEN","runners":[{"status":"ACTIVE","sortPriority":1,"id":39209038,"name":"1. Dr Neeki"},{"status":"ACTIVE","sortPriority":2,"id":40812743,"name":"2. Establishment"},{"status":"ACTIVE","sortPriority":3,"id":43167174,"name":"3. Dr Jax"},{"status":"ACTIVE","sortPriority":4,"id":40908229,"name":"4. Zippy Artist"},{"status":"ACTIVE","sortPriority":5,"id":39980030,"name":"5. Shes Miss Orson"},{"status":"ACTIVE","sortPriority":6,"id":43167175,"name":"6. Ultimate Teddy"},{"status":"ACTIVE","sortPriority":7,"id":42300273,"name":"7. Dr Audrey"},{"status":"ACTIVE","sortPriority":8,"id":42390009,"name":"8. Basil Brush Rose"}],"regulators":["MR_INT"],"venue":"Traralgon","countryCode":"AU","discountAllowed":true,"timezone":"Australia/Sydney","openDate":"2022-03-02T08:31:00.000Z","version":4382425363,"name":"To Be Placed","eventName":"Traralgon (AUS) 2nd Mar"},"rc":[{"atb":[[1.4,250.09],[1.3,333.46],[1.35,285.82]],"id":39209038},{"atl":[[2.86,39.11],[2.66,21.91],[3.15,33.83]],"id":39209038},{"spn":2.03,"spf":"NaN","id":39209038},{"atb":[[4.3,30.31],[3.9,34.49],[3.65,37.74]],"id":40812743},{"atl":[[32,2.34],[21,3.63],[15.5,2.5]],"id":40812743},{"spn":9.9,"spf":"NaN","id":40812743},{"atb":[[1.45,222.3],[1.55,181.88],[1.5,200.07]],"id":43167174},{"atl":[[2.82,19.98],[3.55,28.53],[3.05,35.49]],"id":43167174},{"spn":2.18,"spf":"NaN","id":43167174},{"atb":[[1.2,500.19],[1.25,400.15],[1.3,333.46]],"id":42300273},{"atl":[[2.54,23.62],[2.74,41.81],[2.94,37.5]],"id":42300273},{"spn":1.92,"spf":"NaN","id":42300273},{"atb":[[1.6,166.73],[1.55,181.88],[1.65,153.9]],"id":43167175},{"atl":[[3.45,29.69],[3.95,24.66],[2.98,18.37]],"id":43167175},{"spn":2.31,"spf":"NaN","id":43167175},{"atb":[[2.36,73.55],[2.26,79.39],[2.16,86.24]],"id":40908229},{"atl":[[7.4,11.36],[5.7,7.73],[9.4,8.66]],"id":40908229},{"spn":4.03,"spf":"NaN","id":40908229},{"atb":[[1.2,500.19],[1.25,400.15],[1.3,333.46]],"id":42390009},{"atl":[[2.54,23.62],[2.74,41.81],[2.94,37.5]],"id":42390009},{"spn":1.92,"spf":"NaN","id":42390009},{"atb":[[2.82,54.96],[2.92,52.1],[3.05,48.79]],"id":39980030},{"atl":[[10.5,7.65],[8.2,5.05],[15.5,5.01]],"id":39980030},{"spn":5.62,"spf":"NaN","id":39980030}],"con":true,"img":true}]}
{"op":"mcm","clk":"5347098668","pt":1646192875746,"mc":[{"id":"1.195453618","rc":[{"atb":[[1.4,0],[1.3,0],[1.35,0]],"id":39209038},{"atl":[[2.86,0],[2.66,0],[3.15,0]],"id":39209038},{"spn":"NaN","spf":"NaN","id":39209038},{"atb":[[4.3,0],[3.9,0],[3.65,0]],"id":40812743},{"atl":[[32,0],[21,0],[15.5,0]],"id":40812743},{"spn":"NaN","spf":"NaN","id":40812743},{"atb":[[1.45,0],[1.55,0],[1.5,0]],"id":43167174},{"atl":[[2.82,0],[3.55,0],[3.05,0]],"id":43167174},{"spn":"NaN","spf":"NaN","id":43167174},{"atb":[[1.2,0],[1.25,0],[1.3,0]],"id":42300273},{"atl":[[2.54,0],[2.74,0],[2.94,0]],"id":42300273},{"spn":"NaN","spf":"NaN","id":42300273},{"atb":[[1.6,0],[1.55,0],[1.65,0]],"id":43167175},{"atl":[[3.45,0],[3.95,0],[2.98,0]],"id":43167175},{"spn":"NaN","spf":"NaN","id":43167175},{"atb":[[2.36,73.55],[2.26,79.39],[2.16,86.24]],"id":40908229},{"atl":[[7.4,11.36],[5.7,7.73],[9.4,8.66]],"id":40908229},{"atb":[[1.2,0],[1.25,0],[1.3,0]],"id":42390009},{"atl":[[2.54,0],[2.74,0],[2.94,0]],"id":42390009},{"spn":"NaN","spf":"NaN","id":42390009},{"atb":[[2.82,0],[2.92,0],[3.05,0]],"id":39980030},{"atl":[[10.5,0],[8.2,0],[15.5,0]],"id":39980030},{"spn":"NaN","spf":"NaN","id":39980030}],"con":true,"img":false}]}
{"op":"mcm","clk":"5347099830","pt":1646192896961,"mc":[{"id":"1.195453618","rc":[{"atb":[[1.4,250.09],[1.3,333.46],[1.35,285.82]],"id":39209038},{"atl":[[2.86,39.11],[2.66,21.91],[3.15,33.83]],"id":39209038},{"atb":[[4.3,30.31],[3.9,34.49],[3.65,37.74]],"id":40812743},{"atl":[[32,2.34],[21,3.63],[15.5,2.5]],"id":40812743},{"atb":[[1.45,222.3],[1.55,181.88],[1.5,200.07]],"id":43167174},{"atl":[[2.82,19.98],[3.55,28.53],[3.05,35.49]],"id":43167174},{"atb":[[1.25,400.15],[1.3,333.46],[1.35,285.82]],"id":42300273},{"atl":[[2.8,40.41],[3,36.37],[2.6,22.73]],"id":42300273},{"atb":[[1.6,166.73],[1.55,181.88],[1.65,153.9]],"id":43167175},{"atl":[[3.45,29.69],[3.95,24.66],[2.98,18.37]],"id":43167175},{"atb":[[1.2,500.19],[1.25,400.15],[1.3,333.46]],"id":42390009},{"atl":[[2.54,23.62],[2.74,41.81],[2.94,37.5]],"id":42390009},{"atb":[[2.82,54.96],[2.92,52.1],[3.05,48.79]],"id":39980030},{"atl":[[10.5,7.65],[8.2,5.05],[15.5,5.01]],"id":39980030}],"con":true,"img":false}]}
{"op":"mcm","clk":"5347381374","pt":1646198202730,"mc":[{"id":"1.195453618","marketDefinition":{"bspMarket":true,"turnInPlayEnabled":false,"persistenceEnabled":false,"marketBaseRate":7.0,"eventId":"31272494","eventTypeId":"4339","numberOfWinners":3,"bettingType":"ODDS","marketType":"PLACE","marketTime":"2022-03-02T09:50:00.000Z","suspendTime":"2022-03-02T09:50:00.000Z","bspReconciled":false,"complete":true,"inPlay":false,"crossMatching":false,"runnersVoidable":false,"numberOfActiveRunners":8,"betDelay":0,"status":"OPEN","runners":[{"status":"ACTIVE","sortPriority":1,"id":39209038,"name":"1. Dr Neeki"},{"status":"ACTIVE","sortPriority":2,"id":40812743,"name":"2. Establishment"},{"status":"ACTIVE","sortPriority":3,"id":43167174,"name":"3. Dr Jax"},{"status":"ACTIVE","sortPriority":4,"id":40908229,"name":"4. Zippy Artist"},{"status":"ACTIVE","sortPriority":5,"id":39980030,"name":"5. Shes Miss Orson"},{"status":"ACTIVE","sortPriority":6,"id":43167175,"name":"6. Ultimate Teddy"},{"status":"ACTIVE","sortPriority":7,"id":42300273,"name":"7. Dr Audrey"},{"status":"ACTIVE","sortPriority":8,"id":42390009,"name":"8. Basil Brush Rose"}],"regulators":["MR_INT"],"venue":"Traralgon","countryCode":"AU","discountAllowed":true,"timezone":"Australia/Sydney","openDate":"2022-03-02T08:31:00.000Z","version":4382425363,"name":"To Be Placed","eventName":"Traralgon (AUS) 2nd Mar"},"rc":[{"atb":[[1.4,250],[1.3,333.33],[1.35,285.71]],"id":39209038},{"atl":[[2.86,39.09],[2.66,21.9],[3.15,33.82]],"id":39209038},{"spn":2.03,"spf":"NaN","id":39209038},{"atb":[[4.3,30.3],[3.9,34.48],[3.65,37.73]],"id":40812743},{"atl":[[32,2.34],[21,3.63],[15.5,2.5]],"id":40812743},{"spn":9.9,"spf":"NaN","id":40812743},{"atb":[[1.45,222.22],[1.55,181.81],[1.5,200]],"id":43167174},{"atl":[[2.82,19.97],[3.55,28.52],[3.05,35.47]],"id":43167174},{"spn":2.18,"spf":"NaN","id":43167174},{"atb":[[1.25,400],[1.3,333.33],[1.35,285.71]],"id":42300273},{"atl":[[2.8,40.4],[3,36.36],[2.6,22.73]],"id":42300273},{"spn":1.97,"spf":"NaN","id":42300273},{"atb":[[1.6,166.66],[1.55,181.81],[1.65,153.84]],"id":43167175},{"atl":[[3.45,29.68],[3.95,24.65],[2.98,18.36]],"id":43167175},{"spn":2.31,"spf":"NaN","id":43167175},{"atb":[[2.36,73.52],[2.26,79.36],[2.16,86.2]],"id":40908229},{"atl":[[7.4,11.36],[5.7,7.73],[9.4,8.65]],"id":40908229},{"spn":4.03,"spf":"NaN","id":40908229},{"atb":[[1.2,500],[1.25,400],[1.3,333.33]],"id":42390009},{"atl":[[2.54,23.61],[2.74,41.79],[2.94,37.48]],"id":42390009},{"spn":1.92,"spf":"NaN","id":42390009},{"atb":[[2.82,54.94],[2.92,52.08],[3.05,48.77]],"id":39980030},{"atl":[[10.5,7.65],[8.2,5.05],[15.5,5.01]],"id":39980030},{"spn":5.62,"spf":"NaN","id":39980030}],"con":true,"img":true}]}
{"op":"mcm","clk":"5347642491","pt":1646204154641,"mc":[{"id":"1.195453618","rc":[{"atb":[[1.4,250],[1.3,333.33],[1.35,285.71]],"id":39209038},{"atl":[[2.86,39.09],[2.66,21.9],[3.15,33.82]],"id":39209038},{"spn":2.03,"spf":"NaN","id":39209038},{"atb":[[4.3,30.3],[3.9,34.48],[3.65,37.73]],"id":40812743},{"atl":[[32,2.34],[21,3.63],[15.5,2.5]],"id":40812743},{"spn":9.9,"spf":"NaN","id":40812743},{"atb":[[1.45,0],[1.55,0],[1.5,0]],"id":43167174},{"atl":[[2.82,0],[3.55,0],[3.05,0]],"id":43167174},{"atb":[[1.25,0],[1.3,0],[1.35,0]],"id":42300273},{"atl":[[2.8,0],[3,0],[2.6,0]],"id":42300273},{"atb":[[1.6,0],[1.55,0],[1.65,0]],"id":43167175},{"atl":[[3.45,0],[3.95,0],[2.98,0]],"id":43167175},{"atb":[[2.36,73.52],[2.26,79.36],[2.16,86.2]],"id":40908229},{"atl":[[7.4,11.36],[5.7,7.73],[9.4,8.65]],"id":40908229},{"atb":[[1.2,500],[1.25,400],[1.3,333.33]],"id":42390009},{"atl":[[2.54,23.61],[2.74,41.79],[2.94,37.48]],"id":42390009},{"spn":1.92,"spf":"NaN","id":42390009},{"atb":[[2.82,0],[2.92,0],[3.05,0]],"id":39980030},{"atl":[[10.5,0],[8.2,0],[15.5,0]],"id":39980030}],"con":true,"img":false}]}
{"op":"mcm","clk":"5347642952","pt":1646204167458,"mc":[{"id":"1.195453618","rc":[{"atb":[[1.7,142.85],[1.75,133.33],[1.65,153.84]],"id":43167174},{"atl":[[4,24.24],[5,18.18],[3.5,14.54]],"id":43167174},{"atb":[[1.25,400],[1.3,333.33],[1.35,285.71]],"id":42300273},{"atl":[[2.8,40.4],[3,36.36],[2.6,22.73]],"id":42300273},{"atb":[[1.8,125],[1.85,117.64],[1.9,111.11]],"id":43167175},{"atl":[[4,12.12],[5,18.18],[6,14.54]],"id":43167175},{"atb":[[2.74,57.47],[2.84,54.34],[2.94,51.54]],"id":39980030},{"atl":[[8,5.19],[10,8.08],[15,5.19]],"id":39980030}],"con":true,"img":false}]}
{"op":"mcm","clk":"5347783790","pt":1646207698809,"mc":[{"id":"1.195453618","rc":[{"atb":[[1.4,249.93],[1.3,333.24],[1.35,285.63]],"id":39209038},{"atl":[[2.86,39.08],[2.66,21.89],[3.15,33.81]],"id":39209038},{"atb":[[4.3,30.29],[3.9,34.47],[3.65,37.72]],"id":40812743},{"atl":[[32,2.34],[21,3.63],[15.5,2.5]],"id":40812743},{"atb":[[1.7,142.81],[1.75,133.29],[1.65,153.8]],"id":43167174},{"atl":[[4,24.23],[5,18.17],[3.5,14.54]],"id":43167174},{"spn":2.62,"spf":"NaN","id":43167174},{"atb":[[1.25,399.89],[1.3,333.24],[1.35,285.63]],"id":42300273},{"atl":[[2.8,40.39],[3,36.35],[2.6,22.72]],"id":42300273},{"spn":1.97,"spf":"NaN","id":42300273},{"atb":[[1.8,124.96],[1.85,117.61],[1.9,111.08]],"id":43167175},{"atl":[[4,12.11],[5,18.17],[6,14.54]],"id":43167175},{"spn":2.95,"spf":"NaN","id":43167175},{"atb":[[2.36,0],[2.26,0],[2.16,0]],"id":40908229},{"atl":[[7.4,0],[5.7,0],[9.4,0]],"id":40908229},{"spn":"NaN","spf":"NaN","id":40908229},{"atb":[[1.2,499.86],[1.25,399.89],[1.3,333.24]],"id":42390009},{"atl":[[2.54,23.6],[2.74,41.78],[2.94,37.47]],"id":42390009},{"atb":[[2.74,0],[2.84,0],[2.94,0]],"id":39980030},{"atl":[[8,0],[10,0],[15,0]],"id":39980030}],"con":true,"img":false}]}
{"op":"mcm","clk":"5347785459","pt":1646207731834,"mc":[{"id":"1.195453618","rc":[{"atb":[[2.5,66.64],[2.6,62.48],[2.7,58.81]],"id":40908229},{"atl":[[8.6,9.56],[11.5,6.92],[6.6,6.49]],"id":40908229},{"atb":[[2.82,54.92],[2.92,52.06],[3.05,48.76]],"id":39980030},{"atl":[[10.5,7.65],[8.2,5.04],[15.5,5.01]],"id":39980030}],"con":true,"img":false}]}
{"op":"mcm","clk":"5347794746","pt":1646207936384,"mc":[{"id":"1.195453618","rc":[{"atl":[[5,45]],"id":40908229},{"spn":3.85,"spf":"NaN","id":40908229},{"spn":5.62,"spf":"NaN","id":39980030}],"con":true,"img":false}]}
{"op":"mcm","clk":"5347865343","pt":1646209259973,"mc":[{"id":"1.195453618","rc":[{"atb":[[1.41,100.73],[1.42,106.5]],"id":39209038},{"atl":[[3.85,14.49],[2.84,23.73]],"id":39209038},{"spn":2.04,"spf":"NaN","id":39209038},{"atb":[[4,13.87],[4.7,11.8]],"id":40812743},{"atl":[[46,2.72],[50,2.72]],"id":40812743},{"spn":10.1,"spf":"NaN","id":40812743},{"atb":[[1.66,66.16],[1.48,76.57]],"id":43167174},{"atl":[[3.95,14.8],[4.9,9.42]],"id":43167174},{"atb":[[1.36,83.04],[1.31,116.5]],"id":42300273},{"atl":[[2.98,18.24],[2.78,24.53]],"id":42300273},{"spn":1.98,"spf":"NaN","id":42300273},{"atb":[[1.91,47.98],[1.65,56.96]],"id":43167175},{"atl":[[6.4,6.85],[4.9,11.19]],"id":43167175},{"spn":2.95,"spf":"NaN","id":43167175},{"atb":[[2.02,42.81],[1.84,43.53]],"id":40908229},{"atl":[[4.9,11.19],[7.8,5.37]],"id":40908229},{"spn":3.8,"spf":"NaN","id":40908229},{"atb":[[1.32,140.86],[1.31,114.74]],"id":42390009},{"atl":[[2.72,25.38],[2.92,18.52]],"id":42390009},{"spn":1.93,"spf":"NaN","id":42390009},{"atb":[[2.88,23.22],[2.54,28.38]],"id":39980030},{"atl":[[26,2.72],[28,2.72]],"id":39980030}],"con":true,"img":false}]}
{"op":"mcm","clk":"5347870069","pt":1646209348001,"mc":[{"id":"1.195453618","rc":[{"atb":[[2.02,0]],"id":40908229},{"atb":[[2.54,0]],"id":39980030}],"con":true,"img":false}]}
{"op":"mcm","clk":"5347872524","pt":1646209405638,"mc":[{"id":"1.195453618","rc":[{"atb":[[2.62,26.95]],"id":40908229},{"atb":[[2.84,23.47]],"id":39980030}],"con":true,"img":false}]}
{"op":"mcm","clk":"5347873652","pt":1646209434406,"mc":[{"id":"1.195453618","rc":[{"atl":[[6.4,0]],"id":43167175}],"con":true,"img":false}]}
{"op":"mcm","clk":"5347873656","pt":1646209434499,"mc":[{"id":"1.195453618","rc":[{"atl":[[5.9,6.85]],"id":43167175}],"con":true,"img":false}]}
{"op":"mcm","clk":"5347875266","pt":1646209462335,"mc":[{"id":"1.195453618","rc":[{"atb":[[2.88,0]],"id":39980030}],"con":true,"img":false}]}
{"op":"mcm","clk":"5347875272","pt":1646209462431,"mc":[{"id":"1.195453618","rc":[{"atb":[[3.1,23.22]],"id":39980030}],"con":true,"img":false}]}
{"op":"mcm","clk":"5347942493","pt":1646210976157,"mc":[{"id":"1.195453618","rc":[{"atl":[[26,0]],"id":39980030},{"spn":5.65,"spf":"NaN","id":39980030}],"con":true,"img":false}]}
{"op":"mcm","clk":"5347942499","pt":1646210976259,"mc":[{"id":"1.195453618","rc":[{"atl":[[23,2.72]],"id":39980030}],"con":true,"img":false}]}
{"op":"mcm","clk":"5347944399","pt":1646211013636,"mc":[{"id":"1.195453618","rc":[{"atb":[[1.43,106.51]],"id":39209038},{"atl":[[4.2,31.25]],"id":39209038},{"atb":[[3,50]],"id":40812743},{"atl":[[15.5,5.01]],"id":40812743},{"atb":[[1.31,266.6]],"id":43167174},{"atl":[[3.75,29.08]],"id":43167174},{"atb":[[1.13,571.28]],"id":42300273},{"atl":[[8.4,13.51]],"id":42300273},{"atl":[[5.2,23.81]],"id":43167175},{"atb":[[2.22,81.97]],"id":40908229},{"atl":[[6.8,17.24]],"id":40908229},{"atb":[[1.08,666.48]],"id":42390009},{"atl":[[3.25,44.44]],"id":42390009},{"atb":[[2.88,53.19]],"id":39980030},{"atl":[[22,4.76]],"id":39980030}],"con":true,"img":false}]}
{"op":"mcm","clk":"5347944650","pt":1646211018865,"mc":[{"id":"1.195453618","rc":[{"atb":[[2.86,53.76],[3,0]],"id":40812743}],"con":true,"img":false}]}
{"op":"mcm","clk":"5347945211","pt":1646211028803,"mc":[{"id":"1.195453618","marketDefinition":{"bspMarket":true,"turnInPlayEnabled":false,"persistenceEnabled":false,"marketBaseRate":7.0,"eventId":"31272494","eventTypeId":"4339","numberOfWinners":3,"bettingType":"ODDS","marketType":"PLACE","marketTime":"2022-03-02T09:50:00.000Z","suspendTime":"2022-03-02T09:50:00.000Z","bspReconciled":false,"complete":true,"inPlay":false,"crossMatching":true,"runnersVoidable":false,"numberOfActiveRunners":8,"betDelay":0,"status":"OPEN","runners":[{"status":"ACTIVE","sortPriority":1,"id":39209038,"name":"1. Dr Neeki"},{"status":"ACTIVE","sortPriority":2,"id":40812743,"name":"2. Establishment"},{"status":"ACTIVE","sortPriority":3,"id":43167174,"name":"3. Dr Jax"},{"status":"ACTIVE","sortPriority":4,"id":40908229,"name":"4. Zippy Artist"},{"status":"ACTIVE","sortPriority":5,"id":39980030,"name":"5. Shes Miss Orson"},{"status":"ACTIVE","sortPriority":6,"id":43167175,"name":"6. Ultimate Teddy"},{"status":"ACTIVE","sortPriority":7,"id":42300273,"name":"7. Dr Audrey"},{"status":"ACTIVE","sortPriority":8,"id":42390009,"name":"8. Basil Brush Rose"}],"regulators":["MR_INT"],"venue":"Traralgon","countryCode":"AU","discountAllowed":true,"timezone":"Australia/Sydney","openDate":"2022-03-02T08:31:00.000Z","version":4382425363,"name":"To Be Placed","eventName":"Traralgon (AUS) 2nd Mar"},"rc":[],"con":true,"img":false}]}
{"op":"mcm","clk":"5347945961","pt":1646211043103,"mc":[{"id":"1.195453618","rc":[{"atb":[[1.42,0]],"id":39209038},{"spn":2.04,"spf":"NaN","id":39209038},{"atl":[[46,0]],"id":40812743},{"atl":[[3.95,0]],"id":43167174},{"atb":[[2.62,0]],"id":40908229},{"atb":[[1.32,0],[1.35,83.65]],"id":42390009},{"spn":1.94,"spf":"NaN","id":42390009},{"atl":[[23,0]],"id":39980030}],"con":true,"img":false}]}
{"op":"mcm","clk":"5347945963","pt":1646211043202,"mc":[{"id":"1.195453618","rc":[{"atb":[[1.46,106.5]],"id":39209038},{"atl":[[40,2.72]],"id":40812743},{"atl":[[3.7,14.8]],"id":43167174},{"atb":[[2.72,26.95]],"id":40908229},{"atl":[[13.5,2.72]],"id":39980030}],"con":true,"img":false}]}
{"op":"mcm","clk":"5347945970","pt":1646211043312,"mc":[{"id":"1.195453618","rc":[{"atb":[[1.43,0],[1.42,238.1]],"id":39209038}],"con":true,"img":false}]}
{"op":"mcm","clk":"5347946384","pt":1646211050683,"mc":[{"id":"1.195453618","rc":[{"atb":[[1.08,0],[1.17,588.24]],"id":42390009}],"con":true,"img":false}]}
{"op":"mcm","clk":"5347947309","pt":1646211068008,"mc":[{"id":"1.195453618","rc":[{"atb":[[1.41,0]],"id":39209038}],"con":true,"img":false}]}
{"op":"mcm","clk":"5347947316","pt":1646211068111,"mc":[{"id":"1.195453618","rc":[{"atb":[[1.43,100.73]],"id":39209038}],"con":true,"img":false}]}
{"op":"mcm","clk":"5347947425","pt":1646211069917,"mc":[{"id":"1.195453618","rc":[{"atb":[[1.31,0]],"id":42300273}],"con":true,"img":false}]}
{"op":"mcm","clk":"5347947432","pt":1646211070020,"mc":[{"id":"1.195453618","rc":[{"atb":[[1.36,199.54]],"id":42300273}],"con":true,"img":false}]}
{"op":"mcm","clk":"5347947477","pt":1646211070745,"mc":[{"id":"1.195453618","rc":[{"atl":[[28,0]],"id":39980030}],"con":true,"img":false}]}
{"op":"mcm","clk":"5347947484","pt":1646211070843,"mc":[{"id":"1.195453618","rc":[{"atl":[[15,2.72]],"id":39980030}],"con":true,"img":false}]}
{"op":"mcm","clk":"5347948026","pt":1646211080037,"mc":[{"id":"1.195453618","rc":[{"atb":[[1.42,0],[1.47,106.51]],"id":39209038}],"con":true,"img":false}]}
{"op":"mcm","clk":"5347948186","pt":1646211082622,"mc":[{"id":"1.195453618","rc":[{"atb":[[1.43,0]],"id":39209038}],"con":true,"img":false}]}
{"op":"mcm","clk":"5347948189","pt":1646211082723,"mc":[{"id":"1.195453618","rc":[{"atb":[[1.41,100.73]],"id":39209038}],"con":true,"img":false}]}
{"op":"mcm","clk":"5347949758","pt":1646211114092,"mc":[{"id":"1.195453618","rc":[{"atb":[[1.46,0]],"id":39209038},{"spn":2.06,"spf":"NaN","id":39209038},{"atl":[[50,0]],"id":40812743},{"spn":3.81,"spf":"NaN","id":40908229}],"con":true,"img":false}]}
{"op":"mcm","clk":"5347949763","pt":1646211114195,"mc":[{"id":"1.195453618","rc":[{"atb":[[1.48,106.5]],"id":39209038},{"atl":[[44,2.72]],"id":40812743}],"con":true,"img":false}]}
{"op":"mcm","clk":"5347949767","pt":1646211114295,"mc":[{"id":"1.195453618","rc":[{"atb":[[1.42,238.1],[1.47,0]],"id":39209038}],"con":true,"img":false}]}
{"op":"mcm","clk":"5347951541","pt":1646211150347,"mc":[{"id":"1.195453618","rc":[{"atb":[[1.42,0],[1.49,106.51]],"id":39209038}],"con":true,"img":false}]}
{"op":"mcm","clk":"5347953070","pt":1646211183394,"mc":[{"id":"1.195453618","rc":[{"atb":[[1.5,75.28]],"id":39209038},{"spn":2.08,"spf":"NaN","id":39209038}],"con":true,"img":false}]}
{"op":"mcm","clk":"5347953074","pt":1646211183499,"mc":[{"id":"1.195453618","rc":[{"atb":[[1.48,0]],"id":39209038}],"con":true,"img":false}]}
{"op":"mcm","clk":"5347953207","pt":1646211185990,"mc":[{"id":"1.195453618","rc":[{"atb":[[1.49,0],[1.51,100.74]],"id":39209038}],"con":true,"img":false}]}
{"op":"mcm","clk":"5347954712","pt":1646211218758,"mc":[{"id":"1.195453618","rc":[{"atb":[[1.5,0]],"id":39209038}],"con":true,"img":false}]}
{"op":"mcm","clk":"5347954717","pt":1646211218862,"mc":[{"id":"1.195453618","rc":[{"atb":[[1.52,75.28]],"id":39209038}],"con":true,"img":false}]}
{"op":"mcm","clk":"5347954720","pt":1646211218964,"mc":[{"id":"1.195453618","rc":[{"atb":[[1.42,238.1],[1.51,0]],"id":39209038}],"con":true,"img":false}]}
{"op":"mcm","clk":"5347954726","pt":1646211219060,"mc":[{"id":"1.195453618","rc":[{"atb":[[1.42,0],[1.53,100.74]],"id":39209038}],"con":true,"img":false}]}
{"op":"mcm","clk":"5347956313","pt":1646211252885,"mc":[{"id":"1.195453618","rc":[{"atb":[[1.52,0]],"id":39209038},{"spn":2.09,"spf":"NaN","id":39209038}],"con":true,"img":false}]}
{"op":"mcm","clk":"5347956320","pt":1646211252988,"mc":[{"id":"1.195453618","rc":[{"atb":[[1.54,75.28],[1.42,238.1]],"id":39209038}],"con":true,"img":false}]}
{"op":"mcm","clk":"5347956324","pt":1646211253092,"mc":[{"id":"1.195453618","rc":[{"atb":[[1.53,0]],"id":39209038}],"con":true,"img":false}]}
{"op":"mcm","clk":"5347956374","pt":1646211253965,"mc":[{"id":"1.195453618","rc":[{"atb":[[1.55,100.74],[1.42,0]],"id":39209038}],"con":true,"img":false}]}
{"op":"mcm","clk":"5347958089","pt":1646211284934,"mc":[{"id":"1.195453618","rc":[{"atb":[[1.54,0]],"id":39209038}],"con":true,"img":false}]}
{"op":"mcm","clk":"5347958095","pt":1646211285036,"mc":[{"id":"1.195453618","rc":[{"atb":[[1.56,75.28],[1.42,238.1]],"id":39209038}],"con":true,"img":false}]}
{"op":"mcm","clk":"5347958101","pt":1646211285138,"mc":[{"id":"1.195453618","rc":[{"atb":[[1.55,0]],"id":39209038}],"con":true,"img":false}]}
{"op":"mcm","clk":"5347958107","pt":1646211285241,"mc":[{"id":"1.195453618","rc":[{"atb":[[1.57,100.74],[1.42,0]],"id":39209038}],"con":true,"img":false}]}
{"op":"mcm","clk":"5347959591","pt":1646211316101,"mc":[{"id":"1.195453618","rc":[{"atb":[[1.56,0]],"id":39209038},{"spn":2.11,"spf":"NaN","id":39209038}],"con":true,"img":false}]}
{"op":"mcm","clk":"5347959597","pt":1646211316203,"mc":[{"id":"1.195453618","rc":[{"atb":[[1.58,75.28]],"id":39209038}],"con":true,"img":false}]}
{"op":"mcm","clk":"5347959601","pt":1646211316309,"mc":[{"id":"1.195453618","rc":[{"atb":[[1.57,0],[1.42,238.1]],"id":39209038}],"con":true,"img":false}]}
{"op":"mcm","clk":"5347960122","pt":1646211328877,"mc":[{"id":"1.195453618","rc":[{"atb":[[1.58,0]],"id":39209038}],"con":true,"img":false}]}
{"op":"mcm","clk":"5347960128","pt":1646211328980,"mc":[{"id":"1.195453618","rc":[{"atb":[[1.46,75.28]],"id":39209038}],"con":true,"img":false}]}
{"op":"mcm","clk":"5347961036","pt":1646211350333,"mc":[{"id":"1.195453618","rc":[{"atb":[[1.42,0],[1.47,100.74]],"id":39209038}],"con":true,"img":false}]}
{"op":"mcm","clk":"5347962392","pt":1646211379962,"mc":[{"id":"1.195453618","rc":[{"atb":[[1.46,0]],"id":39209038},{"spn":2.06,"spf":"NaN","id":39209038}],"con":true,"img":false}]}
{"op":"mcm","clk":"5347962399","pt":1646211380066,"mc":[{"id":"1.195453618","rc":[{"atb":[[1.42,238.1],[1.48,75.28],[1.47,0]],"id":39209038}],"con":true,"img":false}]}
{"op":"mcm","clk":"5347962414","pt":1646211380280,"mc":[{"id":"1.195453618","rc":[{"atb":[[1.42,0],[1.49,100.74]],"id":39209038}],"con":true,"img":false}]}
{"op":"mcm","clk":"5347963946","pt":1646211412096,"mc":[{"id":"1.195453618","rc":[{"atb":[[1.48,0]],"id":39209038}],"con":true,"img":false}]}
{"op":"mcm","clk":"5347963953","pt":1646211412197,"mc":[{"id":"1.195453618","rc":[{"atb":[[1.5,75.28],[1.49,0],[1.42,238.1]],"id":39209038}],"con":true,"img":false}]}
{"op":"mcm","clk":"5347965686","pt":1646211445199,"mc":[{"id":"1.195453618","rc":[{"atb":[[1.51,100.74]],"id":39209038},{"spn":2.08,"spf":"NaN","id":39209038}],"con":true,"img":false}]}
{"op":"mcm","clk":"5347965691","pt":1646211445303,"mc":[{"id":"1.195453618","rc":[{"atb":[[1.42,0]],"id":39209038}],"con":true,"img":false}]}
{"op":"mcm","clk":"5347966987","pt":1646211474784,"mc":[{"id":"1.195453618","rc":[{"atb":[[1.5,0]],"id":39209038}],"con":true,"img":false}]}
{"op":"mcm","clk":"5347966993","pt":1646211474887,"mc":[{"id":"1.195453618","rc":[{"atb":[[1.52,75.28]],"id":39209038}],"con":true,"img":false}]}
{"op":"mcm","clk":"5347966995","pt":1646211474988,"mc":[{"id":"1.195453618","rc":[{"atb":[[1.42,238.1],[1.51,0]],"id":39209038}],"con":true,"img":false}]}
{"op":"mcm","clk":"5347968266","pt":1646211507335,"mc":[{"id":"1.195453618","rc":[{"atb":[[1.42,0],[1.53,100.74]],"id":39209038},{"spn":2.09,"spf":"NaN","id":39209038}],"con":true,"img":false}]}
{"op":"mcm","clk":"5347968729","pt":1646211520069,"mc":[{"id":"1.195453618","rc":[{"atb":[[2.72,0],[1.84,0]],"id":40908229},{"atl":[[4.9,0]],"id":40908229}],"con":true,"img":false}]}
{"op":"mcm","clk":"5347968732","pt":1646211520171,"mc":[{"id":"1.195453618","rc":[{"atb":[[1.59,61.98],[1.71,61.5]],"id":40908229},{"atl":[[7,7.27]],"id":40908229}],"con":true,"img":false}]}
{"op":"mcm","clk":"5347969424","pt":1646211537192,"mc":[{"id":"1.195453618","rc":[{"atb":[[1.52,0]],"id":39209038}],"con":true,"img":false}]}
{"op":"mcm","clk":"5347969427","pt":1646211537295,"mc":[{"id":"1.195453618","rc":[{"atb":[[1.54,75.28],[1.42,238.1]],"id":39209038}],"con":true,"img":false}]}
{"op":"mcm","clk":"5347969431","pt":1646211537397,"mc":[{"id":"1.195453618","rc":[{"atb":[[1.53,0]],"id":39209038}],"con":true,"img":false}]}
{"op":"mcm","clk":"5347969782","pt":1646211546621,"mc":[{"id":"1.195453618","rc":[{"atb":[[1.66,0]],"id":43167174}],"con":true,"img":false}]}
{"op":"mcm","clk":"5347969785","pt":1646211546682,"mc":[{"id":"1.195453618","rc":[{"atb":[[1.71,66.16]],"id":43167174}],"con":true,"img":false}]}
{"op":"mcm","clk":"5347969848","pt":1646211548118,"mc":[{"id":"1.195453618","rc":[{"atb":[[1.54,0]],"id":39209038},{"atb":[[4.7,0]],"id":40812743},{"atb":[[1.36,116.5]],"id":42300273},{"atb":[[1.35,0]],"id":42390009}],"con":true,"img":false}]}
{"op":"mcm","clk":"5347969851","pt":1646211548219,"mc":[{"id":"1.195453618","rc":[{"atb":[[1.47,75.28]],"id":39209038},{"atb":[[5,11.8]],"id":40812743},{"atb":[[1.39,83.04]],"id":42300273},{"atb":[[1.37,83.65]],"id":42390009}],"con":true,"img":false}]}
{"op":"mcm","clk":"5347970153","pt":1646211555239,"mc":[{"id":"1.195453618","rc":[{"atb":[[2.86,0],[2.96,51.02]],"id":40812743},{"atl":[[3.6,29.08],[3.75,0]],"id":43167174},{"atl":[[5,41.49],[5.2,0]],"id":43167175},{"atb":[[2.88,0],[2.62,61.73]],"id":39980030}],"con":true,"img":false}]}
{"op":"mcm","clk":"5347970714","pt":1646211569052,"mc":[{"id":"1.195453618","rc":[{"atb":[[1.48,100.74]],"id":39209038},{"spn":2.07,"spf":"NaN","id":39209038},{"spn":10.25,"spf":"NaN","id":40812743},{"spn":1.99,"spf":"NaN","id":42300273},{"spn":3.85,"spf":"NaN","id":40908229},{"spn":1.95,"spf":"NaN","id":42390009}],"con":true,"img":false}]}
{"op":"mcm","clk":"5347970719","pt":1646211569107,"mc":[{"id":"1.195453618","rc":[{"atb":[[1.42,0]],"id":39209038}],"con":true,"img":false}]}
{"op":"mcm","clk":"5347970930","pt":1646211573336,"mc":[{"id":"1.195453618","rc":[{"atb":[[2.32,75.76],[2.22,0]],"id":40908229}],"con":true,"img":false}]}
{"op":"mcm","clk":"5347970970","pt":1646211574317,"mc":[{"id":"1.195453618","rc":[{"atl":[[6.6,13.01],[7.8,0]],"id":40908229}],"con":true,"img":false}]}
{"op":"mcm","clk":"5347971067","pt":1646211576338,"mc":[{"id":"1.195453618","rc":[{"atb":[[1.81,45.7],[1.65,0]],"id":43167175}],"con":true,"img":false}]}
{"op":"mcm","clk":"5347971235","pt":1646211580058,"mc":[{"id":"1.195453618","rc":[{"atb":[[1.81,0],[1.66,56.1]],"id":43167175},{"atl":[[8.2,4.93],[6.6,6.49]],"id":40908229}],"con":true,"img":false}]}
{"op":"mcm","clk":"5347971236","pt":1646211580159,"mc":[{"id":"1.195453618","rc":[{"atb":[[5,0]],"id":40812743},{"atb":[[1.91,0]],"id":43167175}],"con":true,"img":false}]}
{"op":"mcm","clk":"5347971239","pt":1646211580263,"mc":[{"id":"1.195453618","rc":[{"atb":[[4.7,11.8]],"id":40812743},{"atb":[[1.8,172.95]],"id":43167175}],"con":true,"img":false}]}
{"op":"mcm","clk":"5347971448","pt":1646211584451,"mc":[{"id":"1.195453618","rc":[{"atl":[[3.7,0]],"id":43167174}],"con":true,"img":false}]}
{"op":"mcm","clk":"5347971453","pt":1646211584548,"mc":[{"id":"1.195453618","rc":[{"atl":[[3.55,14.8]],"id":43167174}],"con":true,"img":false}]}
{"op":"mcm","clk":"5347971553","pt":1646211586873,"mc":[{"id":"1.195453618","rc":[{"atb":[[3.1,70.84],[2.62,0]],"id":39980030}],"con":true,"img":false}]}
{"op":"mcm","clk":"5347971702","pt":1646211590486,"mc":[{"id":"1.195453618","rc":[{"atb":[[1.71,0]],"id":43167174}],"con":true,"img":false}]}
{"op":"mcm","clk":"5347971707","pt":1646211590588,"mc":[{"id":"1.195453618","rc":[{"atb":[[1.66,66.16]],"id":43167174}],"con":true,"img":false}]}
{"op":"mcm","clk":"5347972062","pt":1646211599396,"mc":[{"id":"1.195453618","rc":[{"atb":[[1.47,0]],"id":39209038}],"con":true,"img":false}]}
{"op":"mcm","clk":"5347972068","pt":1646211599500,"mc":[{"id":"1.195453618","rc":[{"atb":[[1.49,75.28],[1.42,238.1],[1.48,0]],"id":39209038}],"con":true,"img":false}]}
{"op":"mcm","clk":"5347972517","pt":1646211605813,"mc":[{"id":"1.195453618","rc":[{"atb":[[1.41,100.57],[1.4,249.53],[1.3,332.71],[1.49,75.17],[1.35,285.18]],"id":39209038},{"atl":[[3.85,14.46],[2.86,39.02],[2.66,21.86],[2.84,23.69],[3.15,33.76]],"id":39209038},{"atb":[[4,13.85],[4.3,30.24],[3.9,34.42],[3.65,37.66],[4.7,11.78]],"id":40812743},{"atl":[[32,2.34],[40,2.72],[21,3.62],[44,2.72],[15.5,5.01]],"id":40812743},{"atb":[[1.7,142.59],[1.75,133.08],[1.66,66.05],[1.65,153.56],[1.48,76.45]],"id":43167174},{"atl":[[4,24.19],[5,18.14],[4.9,9.4],[3.55,14.78],[3.5,14.51]],"id":43167174},{"atb":[[1.36,116.32],[1.25,399.25],[1.3,332.71],[1.39,82.9],[1.35,285.18]],"id":42300273},{"atl":[[2.8,40.32],[3,36.29],[2.6,22.68],[2.98,18.21],[2.78,24.49]],"id":42300273},{"atb":[[1.8,172.67],[1.85,117.42],[1.9,110.9],[1.66,56.01]],"id":43167175},{"atl":[[4,12.09],[5,41.46],[6,14.51],[4.9,11.17],[5.9,6.84]],"id":43167175},{"atb":[[1.59,61.88],[2.5,66.54],[2.6,62.38],[1.71,61.4],[2.7,58.71]],"id":40908229},{"atl":[[8.6,9.55],[8.2,4.93],[11.5,6.91],[4.9,11.17],[6.6,6.47],[7,0]],"id":40908229},{"atb":[[1.2,499.07],[1.37,83.52],[1.25,399.25],[1.3,332.71],[1.31,114.56]],"id":42390009},{"atl":[[2.72,25.34],[2.92,18.49],[2.54,23.57],[2.74,41.71],[2.94,37.41]],"id":42390009},{"atb":[[2.82,54.84],[2.92,51.98],[3.1,70.8],[2.84,23.43],[3.05,48.68]],"id":39980030},{"atl":[[10.5,7.64],[8.2,5.04],[13.5,2.72],[15,2.72],[15.5,5]],"id":39980030}],"con":true,"img":false}]}
{"op":"mcm","clk":"5347972791","pt":1646211610403,"mc":[{"id":"1.195453618","rc":[{"atb":[[2.72,25.34],[1.71,0]],"id":40908229}],"con":true,"img":false}]}
{"op":"mcm","clk":"5347973824","pt":1646211630630,"mc":[{"id":"1.195453618","rc":[{"atb":[[1.5,100.58]],"id":39209038},{"spn":2.08,"spf":"NaN","id":39209038},{"spn":10.1,"spf":"NaN","id":40812743},{"spn":2.95,"spf":"NaN","id":43167175},{"spn":3.81,"spf":"NaN","id":40908229}],"con":true,"img":false}]}
{"op":"mcm","clk":"5347973832","pt":1646211630734,"mc":[{"id":"1.195453618","rc":[{"atb":[[1.42,0]],"id":39209038}],"con":true,"img":false}]}
{"op":"mcm","clk":"5347974195","pt":1646211637776,"mc":[{"id":"1.195453618","rc":[{"atb":[[1.59,0],[1.91,40.12]],"id":40908229}],"con":true,"img":false}]}
{"op":"mcm","clk":"5347975324","pt":1646211660806,"mc":[{"id":"1.195453618","rc":[{"atb":[[1.49,0]],"id":39209038}],"con":true,"img":false}]}
{"op":"mcm","clk":"5347975330","pt":1646211660916,"mc":[{"id":"1.195453618","rc":[{"atb":[[1.51,75.17]],"id":39209038}],"con":true,"img":false}]}
{"op":"mcm","clk":"5347975333","pt":1646211660958,"mc":[{"id":"1.195453618","rc":[{"atb":[[1.42,238.1]],"id":39209038}],"con":true,"img":false}]}
{"op":"mcm","clk":"5347975340","pt":1646211661061,"mc":[{"id":"1.195453618","rc":[{"atb":[[1.5,0]],"id":39209038}],"con":true,"img":false}]}
{"op":"mcm","clk":"5347975365","pt":1646211661479,"mc":[{"id":"1.195453618","rc":[{"atb":[[1.52,100.58]],"id":39209038}],"con":true,"img":false}]}
{"op":"mcm","clk":"5347975371","pt":1646211661582,"mc":[{"id":"1.195453618","rc":[{"atb":[[1.42,0]],"id":39209038}],"con":true,"img":false}]}
{"op":"mcm","clk":"5347975550","pt":1646211665500,"mc":[{"id":"1.195453618","rc":[{"atb":[[1.8,124.76]],"id":43167175}],"con":true,"img":false}]}
{"op":"mcm","clk":"5347975555","pt":1646211665601,"mc":[{"id":"1.195453618","rc":[{"atb":[[1.91,47.9]],"id":43167175}],"con":true,"img":false}]}
{"op":"mcm","clk":"5347976858","pt":1646211688433,"mc":[{"id":"1.195453618","rc":[{"atb":[[1.51,0]],"id":39209038}],"con":true,"img":false}]}
{"op":"mcm","clk":"5347976860","pt":1646211688543,"mc":[{"id":"1.195453618","rc":[{"atb":[[1.42,238.1],[1.53,75.17],[1.52,0]],"id":39209038}],"con":true,"img":false}]}
{"op":"mcm","clk":"5347976872","pt":1646211688750,"mc":[{"id":"1.195453618","rc":[{"atb":[[1.54,100.58],[1.42,0]],"id":39209038}],"con":true,"img":false}]}
{"op":"mcm","clk":"5347976921","pt":1646211689624,"mc":[{"id":"1.195453618","rc":[{"atb":[[4,0]],"id":40812743}],"con":true,"img":false}]}
{"op":"mcm","clk":"5347976927","pt":1646211689726,"mc":[{"id":"1.195453618","rc":[{"atb":[[4.4,13.85]],"id":40812743}],"con":true,"img":false}]}
{"op":"mcm","clk":"5347977111","pt":1646211693340,"mc":[{"id":"1.195453618","rc":[{"spn":2.1,"spf":"NaN","id":39209038},{"atb":[[2.82,54.95],[2.96,0]],"id":40812743},{"atl":[[3.6,0],[3.75,29.56]],"id":43167174},{"spn":2.95,"spf":"NaN","id":43167175},{"atb":[[2.86,53.76],[3.1,23.18]],"id":39980030}],"con":true,"img":false}]}
{"op":"mcm","clk":"5347977649","pt":1646211704243,"mc":[{"id":"1.195453618","rc":[{"atl":[[3.55,0]],"id":43167174}],"con":true,"img":false}]}
{"op":"mcm","clk":"5347977653","pt":1646211704352,"mc":[{"id":"1.195453618","rc":[{"atl":[[3.7,14.78]],"id":43167174}],"con":true,"img":false}]}
{"op":"mcm","clk":"5347978265","pt":1646211718202,"mc":[{"id":"1.195453618","rc":[{"atb":[[1.53,0]],"id":39209038}],"con":true,"img":false}]}
{"op":"mcm","clk":"5347978268","pt":1646211718304,"mc":[{"id":"1.195453618","rc":[{"atb":[[1.55,75.17]],"id":39209038}],"con":true,"img":false}]}
{"op":"mcm","clk":"5347978272","pt":1646211718406,"mc":[{"id":"1.195453618","rc":[{"atb":[[1.54,0],[1.42,238.1]],"id":39209038}],"con":true,"img":false}]}
{"op":"mcm","clk":"5347978389","pt":1646211721097,"mc":[{"id":"1.195453618","rc":[{"atb":[[1.37,0]],"id":42390009}],"con":true,"img":false}]}
{"op":"mcm","clk":"5347978395","pt":1646211721196,"mc":[{"id":"1.195453618","rc":[{"atb":[[1.35,83.52]],"id":42390009}],"con":true,"img":false}]}
{"op":"mcm","clk":"5347978756","pt":1646211728608,"mc":[{"id":"1.195453618","rc":[{"atb":[[1.55,0]],"id":39209038}],"con":true,"img":false}]}
{"op":"mcm","clk":"5347978764","pt":1646211728717,"mc":[{"id":"1.195453618","rc":[{"atb":[[1.46,75.17]],"id":39209038}],"con":true,"img":false}]}
{"op":"mcm","clk":"5347979443","pt":1646211746840,"mc":[{"id":"1.195453618","rc":[{"atb":[[2.84,0]],"id":39980030}],"con":true,"img":false}]}
{"op":"mcm","clk":"5347979446","pt":1646211746942,"mc":[{"id":"1.195453618","rc":[{"atb":[[2.88,23.43]],"id":39980030}],"con":true,"img":false}]}
{"op":"mcm","clk":"5347979496","pt":1646211748329,"mc":[{"id":"1.195453618","rc":[{"atb":[[1.47,100.58]],"id":39209038}],"con":true,"img":false}]}
{"op":"mcm","clk":"5347979497","pt":1646211748429,"mc":[{"id":"1.195453618","rc":[{"atb":[[1.42,0]],"id":39209038}],"con":true,"img":false}]}
{"op":"mcm","clk":"5347980789","pt":1646211777611,"mc":[{"id":"1.195453618","rc":[{"atb":[[1.46,0]],"id":39209038},{"spn":2.06,"spf":"NaN","id":39209038},{"spn":1.94,"spf":"NaN","id":42390009}],"con":true,"img":false}]}
{"op":"mcm","clk":"5347980796","pt":1646211777713,"mc":[{"id":"1.195453618","rc":[{"atb":[[1.48,75.17]],"id":39209038}],"con":true,"img":false}]}
{"op":"mcm","clk":"5347980799","pt":1646211777816,"mc":[{"id":"1.195453618","rc":[{"atb":[[1.42,238.1],[1.47,0]],"id":39209038}],"con":true,"img":false}]}
{"op":"mcm","clk":"5347980802","pt":1646211777917,"mc":[{"id":"1.195453618","rc":[{"atb":[[1.42,0],[1.49,100.58]],"id":39209038}],"con":true,"img":false}]}
{"op":"mcm","clk":"5347982309","pt":1646211806148,"mc":[{"id":"1.195453618","rc":[{"atb":[[1.48,0]],"id":39209038}],"con":true,"img":false}]}
{"op":"mcm","clk":"5347982316","pt":1646211806253,"mc":[{"id":"1.195453618","rc":[{"atb":[[1.5,75.17],[1.42,238.1]],"id":39209038}],"con":true,"img":false}]}
{"op":"mcm","clk":"5347982321","pt":1646211806355,"mc":[{"id":"1.195453618","rc":[{"atb":[[1.49,0]],"id":39209038}],"con":true,"img":false}]}
{"op":"mcm","clk":"5347982374","pt":1646211807283,"mc":[{"id":"1.195453618","rc":[{"atb":[[1.42,0],[1.51,100.58]],"id":39209038}],"con":true,"img":false}]}
{"op":"mcm","clk":"5347984102","pt":1646211837750,"mc":[{"id":"1.195453618","rc":[{"atb":[[1.5,0]],"id":39209038},{"spn":2.08,"spf":"NaN","id":39209038}],"con":true,"img":false}]}
{"op":"mcm","clk":"5347984108","pt":1646211837804,"mc":[{"id":"1.195453618","rc":[{"atb":[[1.52,75.17]],"id":39209038}],"con":true,"img":false}]}
{"op":"mcm","clk":"5347984111","pt":1646211837906,"mc":[{"id":"1.195453618","rc":[{"atb":[[1.42,238.1],[1.51,0]],"id":39209038}],"con":true,"img":false}]}
{"op":"mcm","clk":"5347984116","pt":1646211838009,"mc":[{"id":"1.195453618","rc":[{"atb":[[1.42,0],[1.53,100.58]],"id":39209038}],"con":true,"img":false}]}
{"op":"mcm","clk":"5347984864","pt":1646211853647,"mc":[{"id":"1.195453618","rc":[{"atb":[[1.39,0]],"id":42300273}],"con":true,"img":false}]}
{"op":"mcm","clk":"5347984868","pt":1646211853744,"mc":[{"id":"1.195453618","rc":[{"atb":[[1.37,82.9]],"id":42300273}],"con":true,"img":false}]}
{"op":"mcm","clk":"5347985532","pt":1646211866909,"mc":[{"id":"1.195453618","rc":[{"atb":[[1.52,0]],"id":39209038}],"con":true,"img":false}]}
{"op":"mcm","clk":"5347985538","pt":1646211866963,"mc":[{"id":"1.195453618","rc":[{"atb":[[1.54,75.17]],"id":39209038}],"con":true,"img":false}]}
{"op":"mcm","clk":"5347985543","pt":1646211867064,"mc":[{"id":"1.195453618","rc":[{"atb":[[1.42,238.1],[1.53,0]],"id":39209038}],"con":true,"img":false}]}
{"op":"mcm","clk":"5347985551","pt":1646211867168,"mc":[{"id":"1.195453618","rc":[{"atb":[[1.55,100.58],[1.42,0]],"id":39209038}],"con":true,"img":false}]}
{"op":"mcm","clk":"5347986955","pt":1646211895034,"mc":[{"id":"1.195453618","rc":[{"atb":[[1.54,0]],"id":39209038}],"con":true,"img":false}]}
{"op":"mcm","clk":"5347986960","pt":1646211895137,"mc":[{"id":"1.195453618","rc":[{"atb":[[1.56,75.17]],"id":39209038}],"con":true,"img":false}]}
{"op":"mcm","clk":"5347986967","pt":1646211895240,"mc":[{"id":"1.195453618","rc":[{"atb":[[1.55,0],[1.42,238.1]],"id":39209038}],"con":true,"img":false}]}
{"op":"mcm","clk":"5347986987","pt":1646211895602,"mc":[{"id":"1.195453618","rc":[{"atb":[[1.57,100.58],[1.42,0]],"id":39209038}],"con":true,"img":false}]}
{"op":"mcm","clk":"5347987641","pt":1646211909523,"mc":[{"id":"1.195453618","rc":[{"spn":2.11,"spf":"NaN","id":39209038},{"atb":[[4.8,1.66]],"id":40812743},{"spn":10.15,"spf":"NaN","id":40812743},{"spn":1.98,"spf":"NaN","id":42300273},{"atb":[[2.74,1.66]],"id":40908229},{"spn":3.82,"spf":"NaN","id":40908229},{"atb":[[3.15,1.66]],"id":39980030},{"spn":5.67,"spf":"NaN","id":39980030}],"con":true,"img":false}]}
{"op":"mcm","clk":"5347988361","pt":1646211924057,"mc":[{"id":"1.195453618","rc":[{"atb":[[1.56,0]],"id":39209038}],"con":true,"img":false}]}
{"op":"mcm","clk":"5347988368","pt":1646211924156,"mc":[{"id":"1.195453618","rc":[{"atb":[[1.57,0],[1.58,75.17],[1.42,238.1]],"id":39209038}],"con":true,"img":false}]}
{"op":"mcm","clk":"5347988375","pt":1646211924259,"mc":[{"id":"1.195453618","rc":[{"atb":[[1.59,100.58],[1.42,0]],"id":39209038}],"con":true,"img":false}]}
{"op":"mcm","clk":"5347989615","pt":1646211952812,"mc":[{"id":"1.195453618","rc":[{"atb":[[1.58,0]],"id":39209038}],"con":true,"img":false}]}
{"op":"mcm","clk":"5347989621","pt":1646211952916,"mc":[{"id":"1.195453618","rc":[{"atb":[[1.6,75.17]],"id":39209038}],"con":true,"img":false}]}
{"op":"mcm","clk":"5347989624","pt":1646211953017,"mc":[{"id":"1.195453618","rc":[{"atb":[[1.59,0],[1.42,238.1]],"id":39209038}],"con":true,"img":false}]}
{"op":"mcm","clk":"5347990128","pt":1646211963819,"mc":[{"id":"1.195453618","rc":[{"atb":[[1.6,0]],"id":39209038}],"con":true,"img":false}]}
{"op":"mcm","clk":"5347990132","pt":1646211963920,"mc":[{"id":"1.195453618","rc":[{"atb":[[1.46,75.17]],"id":39209038}],"con":true,"img":false}]}
{"op":"mcm","clk":"5347990927","pt":1646211980605,"mc":[{"id":"1.195453618","rc":[{"atb":[[1.42,0],[1.47,100.58]],"id":39209038},{"spn":2.06,"spf":"NaN","id":39209038}],"con":true,"img":false}]}
{"op":"mcm","clk":"5347992196","pt":1646212009939,"mc":[{"id":"1.195453618","rc":[{"atb":[[1.46,0]],"id":39209038}],"con":true,"img":false}]}
{"op":"mcm","clk":"5347992198","pt":1646212010039,"mc":[{"id":"1.195453618","rc":[{"atb":[[1.48,75.17]],"id":39209038}],"con":true,"img":false}]}
{"op":"mcm","clk":"5347992203","pt":1646212010099,"mc":[{"id":"1.195453618","rc":[{"atb":[[1.42,238.1],[1.47,0]],"id":39209038}],"con":true,"img":false}]}
{"op":"mcm","clk":"5347993631","pt":1646212037182,"mc":[{"id":"1.195453618","rc":[{"atb":[[1.42,0],[1.49,100.58]],"id":39209038}],"con":true,"img":false}]}
{"op":"mcm","clk":"5347994508","pt":1646212053585,"mc":[{"id":"1.195453618","rc":[{"atb":[[1.52,14.45]],"id":39209038},{"spn":2.09,"spf":"NaN","id":39209038},{"atb":[[1.79,9.51]],"id":43167174},{"spn":2.64,"spf":"NaN","id":43167174},{"atb":[[1.4,18.79]],"id":42300273},{"spn":2.0,"spf":"NaN","id":42300273},{"atb":[[1.95,7.91]],"id":43167175},{"spn":2.97,"spf":"NaN","id":43167175},{"atb":[[2.76,4.27]],"id":40908229},{"spn":3.83,"spf":"NaN","id":40908229},{"atb":[[1.38,19.78]],"id":42390009},{"spn":1.96,"spf":"NaN","id":42390009},{"atb":[[3.15,5.16]],"id":39980030}],"con":true,"img":false}]}
{"op":"mcm","clk":"5347994670","pt":1646212056719,"mc":[{"id":"1.195453618","rc":[{"atb":[[2.74,0]],"id":40908229}],"con":true,"img":false}]}
{"op":"mcm","clk":"5347995036","pt":1646212063922,"mc":[{"id":"1.195453618","rc":[{"atb":[[1.49,0],[1.53,75.17]],"id":39209038}],"con":true,"img":false}]}
{"op":"mcm","clk":"5347995102","pt":1646212065541,"mc":[{"id":"1.195453618","rc":[{"atb":[[1.52,0]],"id":39209038}],"con":true,"img":false}]}
{"op":"mcm","clk":"5347995207","pt":1646212067400,"mc":[{"id":"1.195453618","rc":[{"atb":[[1.48,0]],"id":39209038}],"con":true,"img":false}]}
{"op":"mcm","clk":"5347995211","pt":1646212067502,"mc":[{"id":"1.195453618","rc":[{"atb":[[1.54,75.17]],"id":39209038}],"con":true,"img":false}]}
{"op":"mcm","clk":"5347995310","pt":1646212069418,"mc":[{"id":"1.195453618","rc":[{"atl":[[3.45,14.78],[3.75,0]],"id":43167174},{"atl":[[5,18.14],[4.7,24.2]],"id":43167175},{"atl":[[3.25,0],[2.96,50.7]],"id":42390009}],"con":true,"img":false}]}
{"op":"mcm","clk":"5347995638","pt":1646212075631,"mc":[{"id":"1.195453618","rc":[{"atb":[[1.58,12.96]],"id":39209038}],"con":true,"img":false}]}
{"op":"mcm","clk":"5347995770","pt":1646212078568,"mc":[{"id":"1.195453618","rc":[{"atb":[[2.82,0],[1.26,60.5]],"id":40812743},{"atl":[[10.5,10.53],[8.4,0]],"id":42300273},{"atb":[[1.08,166.92]],"id":43167175},{"atb":[[1.17,0],[1.35,198.09]],"id":42390009}],"con":true,"img":false}]}
{"op":"mcm","clk":"5347995837","pt":1646212079728,"mc":[{"id":"1.195453618","rc":[{"atl":[[3.7,0]],"id":43167174}],"con":true,"img":false}]}
{"op":"mcm","clk":"5347995844","pt":1646212079822,"mc":[{"id":"1.195453618","rc":[{"atl":[[3.95,14.78]],"id":43167174}],"con":true,"img":false}]}
{"op":"mcm","clk":"5347996421","pt":1646212090470,"mc":[{"id":"1.195453618","rc":[{"atb":[[1.59,75.17],[1.53,0]],"id":39209038}],"con":true,"img":false}]}
{"op":"mcm","clk":"5347996530","pt":1646212092854,"mc":[{"id":"1.195453618","rc":[{"atb":[[1.58,0]],"id":39209038}],"con":true,"img":false}]}
{"op":"mcm","clk":"5347996672","pt":1646212095562,"mc":[{"id":"1.195453618","rc":[{"atb":[[1.59,0],[1.55,150.34]],"id":39209038}],"con":true,"img":false}]}
{"op":"mcm","clk":"5347996831","pt":1646212098771,"mc":[{"id":"1.195453618","rc":[{"atl":[[4.9,0]],"id":43167175}],"con":true,"img":false}]}
{"op":"mcm","clk":"5347996839","pt":1646212098873,"mc":[{"id":"1.195453618","rc":[{"atl":[[4.6,11.17]],"id":43167175}],"con":true,"img":false}]}
{"op":"mcm","clk":"5347997151","pt":1646212105012,"mc":[{"id":"1.195453618","rc":[{"atb":[[1.59,12.74]],"id":39209038}],"con":true,"img":false}]}
{"op":"mcm","clk":"5347997930","pt":1646212119814,"mc":[{"id":"1.195453618","rc":[{"atb":[[1.54,0]],"id":39209038},{"spn":2.12,"spf":"NaN","id":39209038},{"spn":2.62,"spf":"NaN","id":43167174}],"con":true,"img":false}]}
{"op":"mcm","clk":"5347997935","pt":1646212119921,"mc":[{"id":"1.195453618","rc":[{"atb":[[1.56,75.17]],"id":39209038}],"con":true,"img":false}]}
{"op":"mcm","clk":"5347997960","pt":1646212120335,"mc":[{"id":"1.195453618","rc":[{"atb":[[1.59,0]],"id":39209038}],"con":true,"img":false}]}
{"op":"mcm","clk":"5347998035","pt":1646212121729,"mc":[{"id":"1.195453618","rc":[{"atb":[[1.55,0],[1.57,100.58]],"id":39209038}],"con":true,"img":false}]}
{"op":"mcm","clk":"5347998445","pt":1646212129356,"mc":[{"id":"1.195453618","rc":[{"atb":[[1.61,12.32]],"id":39209038}],"con":true,"img":false}]}
{"op":"mcm","clk":"5347998692","pt":1646212133738,"mc":[{"id":"1.195453618","rc":[{"atb":[[1.31,0]],"id":42390009}],"con":true,"img":false}]}
{"op":"mcm","clk":"5347998696","pt":1646212133874,"mc":[{"id":"1.195453618","rc":[{"atb":[[1.36,114.56]],"id":42390009}],"con":true,"img":false}]}
{"op":"mcm","clk":"5347998808","pt":1646212135342,"mc":[{"id":"1.195453618","rc":[{"atb":[[1.38,0]],"id":42390009}],"con":true,"img":false}]}
{"op":"mcm","clk":"5347999152","pt":1646212141336,"mc":[{"id":"1.195453618","rc":[{"atb":[[1.39,19.27]],"id":42390009}],"con":true,"img":false}]}
{"op":"mcm","clk":"5347999413","pt":1646212147639,"mc":[{"id":"1.195453618","rc":[{"atb":[[1.57,0],[1.62,75.17]],"id":39209038}],"con":true,"img":false}]}
{"op":"mcm","clk":"5347999497","pt":1646212150259,"mc":[{"id":"1.195453618","rc":[{"atb":[[1.61,0]],"id":39209038}],"con":true,"img":false}]}
{"op":"mcm","clk":"5347999509","pt":1646212150575,"mc":[{"id":"1.195453618","rc":[{"atb":[[1.56,0]],"id":39209038}],"con":true,"img":false}]}
{"op":"mcm","clk":"5347999515","pt":1646212150670,"mc":[{"id":"1.195453618","rc":[{"atb":[[1.63,75.17]],"id":39209038}],"con":true,"img":false}]}
{"op":"mcm","clk":"5347999941","pt":1646212159400,"mc":[{"id":"1.195453618","rc":[{"atb":[[1.67,11.22]],"id":39209038}],"con":true,"img":false}]}
{"op":"mcm","clk":"5348000615","pt":1646212173305,"mc":[{"id":"1.195453618","rc":[{"atb":[[1.62,0],[1.68,75.17]],"id":39209038}],"con":true,"img":false}]}
{"op":"mcm","clk":"5348000659","pt":1646212174431,"mc":[{"id":"1.195453618","rc":[{"atb":[[1.67,0]],"id":39209038}],"con":true,"img":false}]}
{"op":"mcm","clk":"5348000701","pt":1646212175620,"mc":[{"id":"1.195453618","rc":[{"atl":[[3.85,0]],"id":39209038},{"atb":[[1.35,114.57]],"id":42390009}],"con":true,"img":false}]}
{"op":"mcm","clk":"5348000706","pt":1646212175724,"mc":[{"id":"1.195453618","rc":[{"atl":[[4.1,14.46]],"id":39209038},{"atb":[[1.36,198.09]],"id":42390009}],"con":true,"img":false}]}
{"op":"mcm","clk":"5348000842","pt":1646212178403,"mc":[{"id":"1.195453618","rc":[{"atb":[[1.64,150.34]],"id":39209038}],"con":true,"img":false}]}
{"op":"mcm","clk":"5348000846","pt":1646212178503,"mc":[{"id":"1.195453618","rc":[{"atb":[[1.68,0]],"id":39209038}],"con":true,"img":false}]}
{"op":"mcm","clk":"5348001288","pt":1646212186407,"mc":[{"id":"1.195453618","rc":[{"atb":[[1.68,11.06]],"id":39209038},{"spn":2.17,"spf":"NaN","id":39209038},{"spn":1.96,"spf":"NaN","id":42390009}],"con":true,"img":false}]}
{"op":"mcm","clk":"5348001895","pt":1646212199843,"mc":[{"id":"1.195453618","rc":[{"atb":[[1.36,396.18],[1.35,0]],"id":42390009}],"con":true,"img":false}]}
{"op":"mcm","clk":"5348002030","pt":1646212202962,"mc":[{"id":"1.195453618","rc":[{"atb":[[1.63,0]],"id":39209038}],"con":true,"img":false}]}
{"op":"mcm","clk":"5348002035","pt":1646212203063,"mc":[{"id":"1.195453618","rc":[{"atb":[[1.65,75.17]],"id":39209038}],"con":true,"img":false}]}
{"op":"mcm","clk":"5348002065","pt":1646212203736,"mc":[{"id":"1.195453618","rc":[{"atb":[[1.69,75.17]],"id":39209038}],"con":true,"img":false}]}
{"op":"mcm","clk":"5348002069","pt":1646212203839,"mc":[{"id":"1.195453618","rc":[{"atb":[[1.64,0]],"id":39209038}],"con":true,"img":false}]}
{"op":"mcm","clk":"5348002087","pt":1646212204256,"mc":[{"id":"1.195453618","rc":[{"atb":[[1.68,0]],"id":39209038}],"con":true,"img":false}]}
{"op":"mcm","clk":"5348002094","pt":1646212204460,"mc":[{"id":"1.195453618","rc":[{"atb":[[1.66,150.34],[1.69,0]],"id":39209038}],"con":true,"img":false}]}
{"op":"mcm","clk":"5348002518","pt":1646212213289,"mc":[{"id":"1.195453618","rc":[{"atb":[[1.7,10.74]],"id":39209038}],"con":true,"img":false}]}
{"op":"mcm","clk":"5348002883","pt":1646212220011,"mc":[{"id":"1.195453618","rc":[{"atb":[[1.7,22.65]],"id":39209038}],"con":true,"img":false}]}
{"op":"mcm","clk":"5348002888","pt":1646212220105,"mc":[{"id":"1.195453618","rc":[{"atb":[[1.4,39.63]],"id":42300273}],"con":true,"img":false}]}
{"op":"mcm","clk":"5348002902","pt":1646212220315,"mc":[{"id":"1.195453618","rc":[{"atb":[[2.76,9]],"id":40908229}],"con":true,"img":false}]}
{"op":"mcm","clk":"5348002910","pt":1646212220475,"mc":[{"id":"1.195453618","rc":[{"atb":[[1.95,16.69]],"id":43167175}],"con":true,"img":false}]}
{"op":"mcm","clk":"5348002915","pt":1646212220572,"mc":[{"id":"1.195453618","rc":[{"atb":[[3.1,27.15]],"id":39980030}],"con":true,"img":false}]}
{"op":"mcm","clk":"5348002925","pt":1646212220790,"mc":[{"id":"1.195453618","rc":[{"atb":[[1.39,40.65]],"id":42390009}],"con":true,"img":false}]}
{"op":"mcm","clk":"5348002935","pt":1646212220882,"mc":[{"id":"1.195453618","rc":[{"atb":[[1.79,20.07]],"id":43167174}],"con":true,"img":false}]}
{"op":"mcm","clk":"5348003390","pt":1646212229601,"mc":[{"id":"1.195453618","rc":[{"atb":[[1.66,0],[1.71,75.17]],"id":39209038}],"con":true,"img":false}]}
{"op":"mcm","clk":"5348003457","pt":1646212231203,"mc":[{"id":"1.195453618","rc":[{"atb":[[1.7,11.91]],"id":39209038}],"con":true,"img":false}]}
{"op":"mcm","clk":"5348003695","pt":1646212236600,"mc":[{"id":"1.195453618","rc":[{"atb":[[1.65,0]],"id":39209038}],"con":true,"img":false}]}
{"op":"mcm","clk":"5348003699","pt":1646212236707,"mc":[{"id":"1.195453618","rc":[{"atb":[[1.55,75.17]],"id":39209038}],"con":true,"img":false}]}
{"op":"mcm","clk":"5348003727","pt":1646212237321,"mc":[{"id":"1.195453618","rc":[{"atb":[[1.75,10.02]],"id":39209038}],"con":true,"img":false}]}
{"op":"mcm","clk":"5348004093","pt":1646212243843,"mc":[{"id":"1.195453618","rc":[{"atb":[[1.7,0]],"id":39209038}],"con":true,"img":false}]}
{"op":"mcm","clk":"5348004587","pt":1646212254443,"mc":[{"id":"1.195453618","rc":[{"atb":[[1.74,75.17],[1.71,0]],"id":39209038},{"spn":2.2,"spf":"NaN","id":39209038}],"con":true,"img":false}]}
{"op":"mcm","clk":"5348004633","pt":1646212255371,"mc":[{"id":"1.195453618","rc":[{"atb":[[1.75,0]],"id":39209038}],"con":true,"img":false}]}
{"op":"mcm","clk":"5348004874","pt":1646212259574,"mc":[{"id":"1.195453618","rc":[{"atb":[[1.56,150.34],[1.74,0]],"id":39209038}],"con":true,"img":false}]}
{"op":"mcm","clk":"5348005298","pt":1646212267492,"mc":[{"id":"1.195453618","rc":[{"atb":[[1.6,12.53]],"id":39209038}],"con":true,"img":false}]}
{"op":"mcm","clk":"5348006054","pt":1646212281913,"mc":[{"id":"1.195453618","rc":[{"atb":[[1.6,26.43]],"id":39209038}],"con":true,"img":false}]}
{"op":"mcm","clk":"5348006164","pt":1646212284128,"mc":[{"id":"1.195453618","rc":[{"atb":[[1.61,75.17]],"id":39209038}],"con":true,"img":false}]}
{"op":"mcm","clk":"5348006168","pt":1646212284230,"mc":[{"id":"1.195453618","rc":[{"atb":[[1.56,0]],"id":39209038}],"con":true,"img":false}]}
{"op":"mcm","clk":"5348006243","pt":1646212285527,"mc":[{"id":"1.195453618","rc":[{"atb":[[1.6,13.89]],"id":39209038}],"con":true,"img":false}]}
{"op":"mcm","clk":"5348006259","pt":1646212285833,"mc":[{"id":"1.195453618","rc":[{"atb":[[1.55,0]],"id":39209038}],"con":true,"img":false}]}
{"op":"mcm","clk":"5348006264","pt":1646212285936,"mc":[{"id":"1.195453618","rc":[{"atb":[[1.57,75.17]],"id":39209038}],"con":true,"img":false}]}
{"op":"mcm","clk":"5348006537","pt":1646212291423,"mc":[{"id":"1.195453618","rc":[{"atb":[[1.65,11.56]],"id":39209038}],"con":true,"img":false}]}
{"op":"mcm","clk":"5348007341","pt":1646212308469,"mc":[{"id":"1.195453618","rc":[{"atb":[[1.66,13.9],[1.61,0]],"id":39209038}],"con":true,"img":false}]}
{"op":"mcm","clk":"5348007387","pt":1646212309450,"mc":[{"id":"1.195453618","rc":[{"atb":[[1.57,0]],"id":39209038}],"con":true,"img":false}]}
{"op":"mcm","clk":"5348007392","pt":1646212309554,"mc":[{"id":"1.195453618","rc":[{"atb":[[1.48,75.17]],"id":39209038}],"con":true,"img":false}]}
{"op":"mcm","clk":"5348007400","pt":1646212309659,"mc":[{"id":"1.195453618","rc":[{"atb":[[1.65,0]],"id":39209038}],"con":true,"img":false}]}
{"op":"mcm","clk":"5348007412","pt":1646212309862,"mc":[{"id":"1.195453618","rc":[{"atb":[[1.66,0],[1.61,75.17]],"id":39209038}],"con":true,"img":false}]}
{"op":"mcm","clk":"5348007560","pt":1646212313362,"mc":[{"id":"1.195453618","rc":[{"atb":[[1.6,0]],"id":39209038}],"con":true,"img":false}]}
{"op":"mcm","clk":"5348007568","pt":1646212313567,"mc":[{"id":"1.195453618","rc":[{"atb":[[1.49,150.34],[1.61,0]],"id":39209038}],"con":true,"img":false}]}
{"op":"mcm","clk":"5348007589","pt":1646212313928,"mc":[{"id":"1.195453618","rc":[{"atl":[[3.45,0],[3.75,29.3]],"id":43167174},{"atl":[[5.1,24.39],[4.7,0]],"id":43167175},{"atl":[[3.25,44.44],[2.96,0]],"id":42390009}],"con":true,"img":false}]}
{"op":"mcm","clk":"5348007895","pt":1646212321643,"mc":[{"id":"1.195453618","rc":[{"atb":[[1.52,14.45]],"id":39209038},{"spn":2.09,"spf":"NaN","id":39209038},{"spn":2.64,"spf":"NaN","id":43167174}],"con":true,"img":false}]}
{"op":"mcm","clk":"5348008018","pt":1646212324486,"mc":[{"id":"1.195453618","rc":[{"atl":[[4.6,0]],"id":43167175}],"con":true,"img":false}]}
{"op":"mcm","clk":"5348008021","pt":1646212324582,"mc":[{"id":"1.195453618","rc":[{"atl":[[4.9,11.17]],"id":43167175}],"con":true,"img":false}]}
{"op":"mcm","clk":"5348008578","pt":1646212337515,"mc":[{"id":"1.195453618","rc":[{"atb":[[1.52,30.48]],"id":39209038}],"con":true,"img":false}]}
{"op":"mcm","clk":"5348008582","pt":1646212337568,"mc":[{"id":"1.195453618","rc":[{"atb":[[1.49,0],[1.53,75.17]],"id":39209038}],"con":true,"img":false}]}
{"op":"mcm","clk":"5348008640","pt":1646212339466,"mc":[{"id":"1.195453618","rc":[{"atb":[[1.48,0]],"id":39209038}],"con":true,"img":false}]}
{"op":"mcm","clk":"5348008645","pt":1646212339569,"mc":[{"id":"1.195453618","rc":[{"atb":[[1.5,75.17],[1.52,16.03]],"id":39209038}],"con":true,"img":false}]}
{"op":"mcm","clk":"5348008857","pt":1646212343995,"mc":[{"id":"1.195453618","rc":[{"atl":[[3.95,0]],"id":43167174}],"con":true,"img":false}]}
{"op":"mcm","clk":"5348008861","pt":1646212344098,"mc":[{"id":"1.195453618","rc":[{"atl":[[3.7,14.78]],"id":43167174}],"con":true,"img":false}]}
{"op":"mcm","clk":"5348008937","pt":1646212345593,"mc":[{"id":"1.195453618","rc":[{"atb":[[1.57,13.18]],"id":39209038}],"con":true,"img":false}]}
{"op":"mcm","clk":"5348008943","pt":1646212345699,"mc":[{"id":"1.195453618","rc":[{"atb":[[1.58,16.03],[1.53,0]],"id":39209038}],"con":true,"img":false}]}
{"op":"mcm","clk":"5348009100","pt":1646212348595,"mc":[{"id":"1.195453618","rc":[{"atb":[[1.57,0]],"id":39209038}],"con":true,"img":false}]}
{"op":"mcm","clk":"5348009105","pt":1646212348697,"mc":[{"id":"1.195453618","rc":[{"atb":[[1.53,75.17]],"id":39209038}],"con":true,"img":false}]}
{"op":"mcm","clk":"5348009111","pt":1646212348799,"mc":[{"id":"1.195453618","rc":[{"atb":[[1.58,0]],"id":39209038}],"con":true,"img":false}]}
{"op":"mcm","clk":"5348009700","pt":1646212358837,"mc":[{"id":"1.195453618","rc":[{"atb":[[1.57,13.18]],"id":39209038}],"con":true,"img":false}]}
{"op":"mcm","clk":"5348009988","pt":1646212364206,"mc":[{"id":"1.195453618","rc":[{"atb":[[1.52,0]],"id":39209038}],"con":true,"img":false}]}
{"op":"mcm","clk":"5348010410","pt":1646212372317,"mc":[{"id":"1.195453618","rc":[{"atb":[[1.58,75.17]],"id":39209038}],"con":true,"img":false}]}
{"op":"mcm","clk":"5348010416","pt":1646212372418,"mc":[{"id":"1.195453618","rc":[{"atb":[[1.53,0]],"id":39209038}],"con":true,"img":false}]}
{"op":"mcm","clk":"5348010541","pt":1646212374814,"mc":[{"id":"1.195453618","rc":[{"atl":[[3.45,14.78]],"id":43167174},{"atl":[[4.7,24.2]],"id":43167175},{"atl":[[3.25,0],[2.96,50.7]],"id":42390009}],"con":true,"img":false}]}
{"op":"mcm","clk":"5348010545","pt":1646212374917,"mc":[{"id":"1.195453618","rc":[{"atl":[[3.75,0]],"id":43167174},{"atl":[[5.1,0]],"id":43167175}],"con":true,"img":false}]}
{"op":"mcm","clk":"5348010580","pt":1646212375540,"mc":[{"id":"1.195453618","rc":[{"atb":[[1.57,0]],"id":39209038}],"con":true,"img":false}]}
{"op":"mcm","clk":"5348010693","pt":1646212377463,"mc":[{"id":"1.195453618","rc":[{"atb":[[1.51,150.34]],"id":39209038}],"con":true,"img":false}]}
{"op":"mcm","clk":"5348010698","pt":1646212377573,"mc":[{"id":"1.195453618","rc":[{"atb":[[1.58,0]],"id":39209038}],"con":true,"img":false}]}
{"op":"mcm","clk":"5348010747","pt":1646212378654,"mc":[{"id":"1.195453618","rc":[{"atb":[[1.5,0]],"id":39209038}],"con":true,"img":false}]}
{"op":"mcm","clk":"5348010753","pt":1646212378758,"mc":[{"id":"1.195453618","rc":[{"atb":[[1.52,75.17]],"id":39209038}],"con":true,"img":false}]}
{"op":"mcm","clk":"5348010940","pt":1646212382642,"mc":[{"id":"1.195453618","rc":[{"atl":[[3.75,29.56]],"id":43167174},{"spn":2.62,"spf":"NaN","id":43167174},{"atl":[[5.1,24.39],[4.7,0]],"id":43167175},{"atl":[[3.25,44.44]],"id":42390009}],"con":true,"img":false}]}
{"op":"mcm","clk":"5348010945","pt":1646212382746,"mc":[{"id":"1.195453618","rc":[{"atl":[[3.45,0]],"id":43167174},{"atl":[[2.96,0]],"id":42390009}],"con":true,"img":false}]}
{"op":"mcm","clk":"5348011213","pt":1646212387673,"mc":[{"id":"1.195453618","rc":[{"atb":[[1.55,13.66]],"id":39209038}],"con":true,"img":false}]}
{"op":"mcm","clk":"5348011869","pt":1646212400768,"mc":[{"id":"1.195453618","rc":[{"atb":[[1.56,75.17],[1.51,0]],"id":39209038}],"con":true,"img":false}]}
{"op":"mcm","clk":"5348011981","pt":1646212402587,"mc":[{"id":"1.195453618","rc":[{"atb":[[1.55,0]],"id":39209038}],"con":true,"img":false}]}
{"op":"mcm","clk":"5348012132","pt":1646212405888,"mc":[{"id":"1.195453618","rc":[{"atb":[[1.56,0],[1.53,150.34]],"id":39209038}],"con":true,"img":false}]}
{"op":"mcm","clk":"5348012566","pt":1646212414692,"mc":[{"id":"1.195453618","rc":[{"atb":[[1.57,13.18]],"id":39209038}],"con":true,"img":false}]}
{"op":"mcm","clk":"5348013049","pt":1646212423934,"mc":[{"id":"1.195453618","rc":[{"atb":[[1.58,75.17],[1.53,0]],"id":39209038}],"con":true,"img":false}]}
{"op":"mcm","clk":"5348013153","pt":1646212426619,"mc":[{"id":"1.195453618","rc":[{"atb":[[1.57,0]],"id":39209038}],"con":true,"img":false}]}
{"op":"mcm","clk":"5348013290","pt":1646212429035,"mc":[{"id":"1.195453618","rc":[{"atb":[[1.58,0],[1.53,150.34]],"id":39209038}],"con":true,"img":false}]}
{"op":"mcm","clk":"5348013328","pt":1646212429850,"mc":[{"id":"1.195453618","rc":[{"atb":[[1.52,0]],"id":39209038}],"con":true,"img":false}]}
{"op":"mcm","clk":"5348013337","pt":1646212429963,"mc":[{"id":"1.195453618","rc":[{"atb":[[1.54,75.17]],"id":39209038}],"con":true,"img":false}]}
{"op":"mcm","clk":"5348013655","pt":1646212435028,"mc":[{"id":"1.195453618","rc":[{"atl":[[3.45,14.78],[3.75,0]],"id":43167174},{"atl":[[5.1,0],[4.7,24.2]],"id":43167175},{"atl":[[3.25,0],[2.96,50.7]],"id":42390009}],"con":true,"img":false}]}
{"op":"mcm","clk":"5348013888","pt":1646212439652,"mc":[{"id":"1.195453618","rc":[{"atb":[[1.58,12.96]],"id":39209038}],"con":true,"img":false}]}
{"op":"mcm","clk":"5348014206","pt":1646212446085,"mc":[{"id":"1.195453618","rc":[{"spn":2.12,"spf":"NaN","id":39209038},{"atl":[[3.7,0]],"id":43167174}],"con":true,"img":false}]}
{"op":"mcm","clk":"5348014212","pt":1646212446167,"mc":[{"id":"1.195453618","rc":[{"atl":[[3.95,14.78]],"id":43167174}],"con":true,"img":false}]}
{"op":"mcm","clk":"5348014509","pt":1646212451853,"mc":[{"id":"1.195453618","rc":[{"atb":[[1.59,75.17],[1.53,0]],"id":39209038}],"con":true,"img":false}]}
{"op":"mcm","clk":"5348014611","pt":1646212453849,"mc":[{"id":"1.195453618","rc":[{"atb":[[1.58,0]],"id":39209038}],"con":true,"img":false}]}
{"op":"mcm","clk":"5348014617","pt":1646212453949,"mc":[{"id":"1.195453618","rc":[{"atb":[[1.59,0],[1.55,150.34]],"id":39209038}],"con":true,"img":false}]}
{"op":"mcm","clk":"5348015041","pt":1646212462903,"mc":[{"id":"1.195453618","rc":[{"atb":[[1.59,12.74]],"id":39209038}],"con":true,"img":false}]}
{"op":"mcm","clk":"5348015123","pt":1646212464907,"mc":[{"id":"1.195453618","rc":[{"atl":[[4.9,0]],"id":43167175}],"con":true,"img":false}]}
{"op":"mcm","clk":"5348015128","pt":1646212465003,"mc":[{"id":"1.195453618","rc":[{"atl":[[4.6,11.17]],"id":43167175}],"con":true,"img":false}]}
{"op":"mcm","clk":"5348015691","pt":1646212476597,"mc":[{"id":"1.195453618","rc":[{"atb":[[1.6,75.17],[1.55,0]],"id":39209038}],"con":true,"img":false}]}
{"op":"mcm","clk":"5348015712","pt":1646212477109,"mc":[{"id":"1.195453618","rc":[{"atb":[[1.59,0]],"id":39209038}],"con":true,"img":false}]}
{"op":"mcm","clk":"5348015728","pt":1646212477318,"mc":[{"id":"1.195453618","rc":[{"atb":[[1.6,0],[1.55,150.34]],"id":39209038}],"con":true,"img":false}]}
{"op":"mcm","clk":"5348015773","pt":1646212478134,"mc":[{"id":"1.195453618","rc":[{"atb":[[1.59,14.12]],"id":39209038}],"con":true,"img":false}]}
{"op":"mcm","clk":"5348015912","pt":1646212480405,"mc":[{"id":"1.195453618","rc":[{"atb":[[1.54,0]],"id":39209038}],"con":true,"img":false}]}
{"op":"mcm","clk":"5348015917","pt":1646212480510,"mc":[{"id":"1.195453618","rc":[{"atb":[[1.56,75.17]],"id":39209038}],"con":true,"img":false}]}
{"op":"mcm","clk":"5348016357","pt":1646212489103,"mc":[{"id":"1.195453618","rc":[{"atb":[[1.6,12.53]],"id":39209038}],"con":true,"img":false}]}
{"op":"mcm","clk":"5348016922","pt":1646212499738,"mc":[{"id":"1.195453618","rc":[{"atb":[[1.55,0],[1.61,14.13]],"id":39209038}],"con":true,"img":false}]}
{"op":"mcm","clk":"5348016938","pt":1646212500049,"mc":[{"id":"1.195453618","rc":[{"atb":[[1.56,0]],"id":39209038}],"con":true,"img":false}]}
{"op":"mcm","clk":"5348016941","pt":1646212500150,"mc":[{"id":"1.195453618","rc":[{"atb":[[1.47,75.17]],"id":39209038}],"con":true,"img":false}]}
{"op":"mcm","clk":"5348016992","pt":1646212501035,"mc":[{"id":"1.195453618","rc":[{"atb":[[1.6,0]],"id":39209038}],"con":true,"img":false}]}
{"op":"mcm","clk":"5348017000","pt":1646212501138,"mc":[{"id":"1.195453618","rc":[{"atb":[[1.6,75.17]],"id":39209038}],"con":true,"img":false}]}
{"op":"mcm","clk":"5348017005","pt":1646212501238,"mc":[{"id":"1.195453618","rc":[{"atb":[[1.61,0]],"id":39209038}],"con":true,"img":false}]}
{"op":"mcm","clk":"5348017111","pt":1646212502844,"mc":[{"id":"1.195453618","rc":[{"atb":[[1.59,0]],"id":39209038}],"con":true,"img":false}]}
{"op":"mcm","clk":"5348017122","pt":1646212503049,"mc":[{"id":"1.195453618","rc":[{"atb":[[1.6,0],[1.48,150.34]],"id":39209038}],"con":true,"img":false}]}
{"op":"mcm","clk":"5348017512","pt":1646212510070,"mc":[{"id":"1.195453618","rc":[{"atb":[[1.51,14.74]],"id":39209038},{"spn":2.08,"spf":"NaN","id":39209038}],"con":true,"img":false}]}
{"op":"mcm","clk":"5348018326","pt":1646212525160,"mc":[{"id":"1.195453618","rc":[{"atb":[[1.48,0],[1.52,75.17]],"id":39209038}],"con":true,"img":false}]}
{"op":"mcm","clk":"5348018444","pt":1646212527266,"mc":[{"id":"1.195453618","rc":[{"atl":[[3.45,0],[3.75,29.3]],"id":43167174},{"atl":[[5.1,24.39],[4.7,0]],"id":43167175},{"atl":[[3.25,44.44],[2.96,0]],"id":42390009}],"con":true,"img":false}]}
{"op":"mcm","clk":"5348018500","pt":1646212528352,"mc":[{"id":"1.195453618","rc":[{"atb":[[1.51,0]],"id":39209038}],"con":true,"img":false}]}
{"op":"mcm","clk":"5348018508","pt":1646212528463,"mc":[{"id":"1.195453618","rc":[{"atb":[[1.48,150.34],[1.52,0]],"id":39209038}],"con":true,"img":false}]}
{"op":"mcm","clk":"5348018607","pt":1646212530375,"mc":[{"id":"1.195453618","rc":[{"atb":[[1.47,0]],"id":39209038}],"con":true,"img":false}]}
{"op":"mcm","clk":"5348018615","pt":1646212530482,"mc":[{"id":"1.195453618","rc":[{"atb":[[1.49,75.17]],"id":39209038}],"con":true,"img":false}]}
{"op":"mcm","clk":"5348018618","pt":1646212530583,"mc":[{"id":"1.195453618","rc":[{"atb":[[1.42,238.1],[1.48,0]],"id":39209038}],"con":true,"img":false}]}
{"op":"mcm","clk":"5348018924","pt":1646212537184,"mc":[{"id":"1.195453618","rc":[{"atb":[[1.52,14.45]],"id":39209038}],"con":true,"img":false}]}
{"op":"mcm","clk":"5348018971","pt":1646212538270,"mc":[{"id":"1.195453618","rc":[{"atl":[[4.6,0]],"id":43167175}],"con":true,"img":false}]}
{"op":"mcm","clk":"5348018977","pt":1646212538378,"mc":[{"id":"1.195453618","rc":[{"atl":[[4.9,11.17]],"id":43167175}],"con":true,"img":false}]}
{"op":"mcm","clk":"5348019513","pt":1646212550333,"mc":[{"id":"1.195453618","rc":[{"atb":[[1.52,30.48]],"id":39209038}],"con":true,"img":false}]}
{"op":"mcm","clk":"5348019597","pt":1646212552390,"mc":[{"id":"1.195453618","rc":[{"atb":[[1.42,0],[1.53,75.17]],"id":39209038}],"con":true,"img":false}]}
{"op":"mcm","clk":"5348019788","pt":1646212556308,"mc":[{"id":"1.195453618","rc":[{"atb":[[1.52,16.03]],"id":39209038}],"con":true,"img":false}]}
{"op":"mcm","clk":"5348019795","pt":1646212556512,"mc":[{"id":"1.195453618","rc":[{"atl":[[3.45,14.78],[3.75,0]],"id":43167174},{"atl":[[5.1,0],[4.7,24.2]],"id":43167175},{"atl":[[3.25,0],[2.96,50.7]],"id":42390009}],"con":true,"img":false}]}
{"op":"mcm","clk":"5348019802","pt":1646212556622,"mc":[{"id":"1.195453618","rc":[{"atl":[[3.95,0]],"id":43167174}],"con":true,"img":false}]}
{"op":"mcm","clk":"5348019809","pt":1646212556722,"mc":[{"id":"1.195453618","rc":[{"atl":[[3.7,14.78]],"id":43167174}],"con":true,"img":false}]}
{"op":"mcm","clk":"5348020241","pt":1646212565230,"mc":[{"id":"1.195453618","rc":[{"atb":[[1.57,13.18]],"id":39209038}],"con":true,"img":false}]}
{"op":"mcm","clk":"5348020346","pt":1646212567560,"mc":[{"id":"1.195453618","rc":[{"atl":[[3.7,0]],"id":43167174}],"con":true,"img":false}]}
{"op":"mcm","clk":"5348020351","pt":1646212567656,"mc":[{"id":"1.195453618","rc":[{"atl":[[3.95,14.78]],"id":43167174}],"con":true,"img":false}]}
{"op":"mcm","clk":"5348020684","pt":1646212574064,"mc":[{"id":"1.195453618","rc":[{"atb":[[1.58,16.03],[1.53,0]],"id":39209038},{"spn":2.12,"spf":"NaN","id":39209038}],"con":true,"img":false}]}
{"op":"mcm","clk":"5348020706","pt":1646212574469,"mc":[{"id":"1.195453618","rc":[{"atb":[[1.52,0]],"id":39209038}],"con":true,"img":false}]}
{"op":"mcm","clk":"5348020793","pt":1646212576274,"mc":[{"id":"1.195453618","rc":[{"atb":[[1.57,0]],"id":39209038}],"con":true,"img":false}]}
{"op":"mcm","clk":"5348020969","pt":1646212579174,"mc":[{"id":"1.195453618","rc":[{"atb":[[1.58,0],[1.5,100.58]],"id":39209038}],"con":true,"img":false}]}
{"op":"mcm","clk":"5348021262","pt":1646212585139,"mc":[{"id":"1.195453618","rc":[{"atb":[[1.53,14.18]],"id":39209038}],"con":true,"img":false}]}
{"op":"mcm","clk":"5348021317","pt":1646212586277,"mc":[{"id":"1.195453618","rc":[{"atl":[[4.9,0]],"id":43167175}],"con":true,"img":false}]}
{"op":"mcm","clk":"5348021325","pt":1646212586380,"mc":[{"id":"1.195453618","rc":[{"atl":[[4.6,11.17]],"id":43167175}],"con":true,"img":false}]}
{"op":"mcm","clk":"5348021973","pt":1646212598209,"mc":[{"id":"1.195453618","rc":[{"atb":[[1.53,29.91]],"id":39209038}],"con":true,"img":false}]}
{"op":"mcm","clk":"5348022073","pt":1646212600575,"mc":[{"id":"1.195453618","rc":[{"atb":[[1.54,75.17],[1.5,0]],"id":39209038}],"con":true,"img":false}]}
{"op":"mcm","clk":"5348022236","pt":1646212603319,"mc":[{"id":"1.195453618","rc":[{"atb":[[1.53,15.73]],"id":39209038}],"con":true,"img":false}]}
{"op":"mcm","clk":"5348022583","pt":1646212609319,"mc":[{"id":"1.195453618","rc":[{"atb":[[1.58,12.96]],"id":39209038}],"con":true,"img":false}]}
{"op":"mcm","clk":"5348022610","pt":1646212609683,"mc":[{"id":"1.195453618","rc":[{"atb":[[1.49,0]],"id":39209038}],"con":true,"img":false}]}
{"op":"mcm","clk":"5348022615","pt":1646212609785,"mc":[{"id":"1.195453618","rc":[{"atb":[[1.55,75.17]],"id":39209038}],"con":true,"img":false}]}
{"op":"mcm","clk":"5348022759","pt":1646212612323,"mc":[{"id":"1.195453618","rc":[{"atb":[[1.58,0]],"id":39209038}],"con":true,"img":false}]}
{"op":"mcm","clk":"5348023197","pt":1646212618320,"mc":[{"id":"1.195453618","rc":[{"atb":[[1.59,12.74]],"id":39209038}],"con":true,"img":false}]}
{"op":"mcm","clk":"5348023451","pt":1646212621756,"mc":[{"id":"1.195453618","rc":[{"atb":[[1.6,75.17],[1.54,0]],"id":39209038}],"con":true,"img":false}]}
{"op":"mcm","clk":"5348023505","pt":1646212622526,"mc":[{"id":"1.195453618","rc":[{"atb":[[1.53,0]],"id":39209038}],"con":true,"img":false}]}
{"op":"mcm","clk":"5348023618","pt":1646212624432,"mc":[{"id":"1.195453618","rc":[{"atb":[[1.59,0]],"id":39209038}],"con":true,"img":false}]}
{"op":"mcm","clk":"5348023750","pt":1646212626811,"mc":[{"id":"1.195453618","rc":[{"atb":[[1.56,150.34]],"id":39209038}],"con":true,"img":false}]}
{"op":"mcm","clk":"5348023757","pt":1646212626914,"mc":[{"id":"1.195453618","rc":[{"atb":[[1.6,0]],"id":39209038}],"con":true,"img":false}]}
{"op":"mcm","clk":"5348024184","pt":1646212633529,"mc":[{"id":"1.195453618","rc":[{"atb":[[1.6,12.53]],"id":39209038}],"con":true,"img":false}]}
{"op":"mcm","clk":"5348025010","pt":1646212647657,"mc":[{"id":"1.195453618","rc":[{"atb":[[1.56,0],[1.61,75.17]],"id":39209038},{"spn":2.13,"spf":"NaN","id":39209038}],"con":true,"img":false}]}
{"op":"mcm","clk":"5348025049","pt":1646212648431,"mc":[{"id":"1.195453618","rc":[{"atb":[[1.6,0]],"id":39209038}],"con":true,"img":false}]}
{"op":"mcm","clk":"5348025238","pt":1646212651733,"mc":[{"id":"1.195453618","rc":[{"atb":[[1.55,0]],"id":39209038}],"con":true,"img":false}]}
{"op":"mcm","clk":"5348025243","pt":1646212651836,"mc":[{"id":"1.195453618","rc":[{"atb":[[1.62,75.17]],"id":39209038}],"con":true,"img":false}]}
{"op":"mcm","clk":"5348025728","pt":1646212660474,"mc":[{"id":"1.195453618","rc":[{"atb":[[1.66,11.39]],"id":39209038}],"con":true,"img":false}]}
{"op":"mcm","clk":"5348026130","pt":1646212668266,"mc":[{"id":"1.195453618","rc":[{"atb":[[1.67,75.17],[1.61,0]],"id":39209038}],"con":true,"img":false}]}
{"op":"mcm","clk":"5348026203","pt":1646212670473,"mc":[{"id":"1.195453618","rc":[{"atb":[[1.66,0]],"id":39209038}],"con":true,"img":false}]}
{"op":"mcm","clk":"5348026367","pt":1646212673516,"mc":[{"id":"1.195453618","rc":[{"atb":[[1.63,150.34],[1.67,0]],"id":39209038}],"con":true,"img":false}]}
{"op":"mcm","clk":"5348026795","pt":1646212681540,"mc":[{"id":"1.195453618","rc":[{"atb":[[1.67,11.22]],"id":39209038}],"con":true,"img":false}]}
{"op":"mcm","clk":"5348027218","pt":1646212688722,"mc":[{"id":"1.195453618","rc":[{"atb":[[1.67,23.67]],"id":39209038}],"con":true,"img":false}]}
{"op":"mcm","clk":"5348027511","pt":1646212693928,"mc":[{"id":"1.195453618","rc":[{"atb":[[1.63,0],[1.68,75.17]],"id":39209038}],"con":true,"img":false}]}
{"op":"mcm","clk":"5348027648","pt":1646212696649,"mc":[{"id":"1.195453618","rc":[{"atb":[[1.67,12.44]],"id":39209038}],"con":true,"img":false}]}
{"op":"mcm","clk":"5348027721","pt":1646212698148,"mc":[{"id":"1.195453618","rc":[{"atb":[[1.62,0]],"id":39209038}],"con":true,"img":false}]}
{"op":"mcm","clk":"5348027729","pt":1646212698271,"mc":[{"id":"1.195453618","rc":[{"atb":[[1.69,75.17]],"id":39209038}],"con":true,"img":false}]}
{"op":"mcm","clk":"5348028130","pt":1646212705627,"mc":[{"id":"1.195453618","rc":[{"atb":[[1.73,10.3]],"id":39209038}],"con":true,"img":false}]}
{"op":"mcm","clk":"5348028497","pt":1646212713356,"mc":[{"id":"1.195453618","rc":[{"atb":[[1.67,0]],"id":39209038},{"spn":2.19,"spf":"NaN","id":39209038}],"con":true,"img":false}]}
{"op":"mcm","clk":"5348028549","pt":1646212714131,"mc":[{"id":"1.195453618","rc":[{"atb":[[1.74,75.17],[1.68,0]],"id":39209038}],"con":true,"img":false}]}
{"op":"mcm","clk":"5348028569","pt":1646212714647,"mc":[{"id":"1.195453618","rc":[{"atb":[[1.73,0]],"id":39209038}],"con":true,"img":false}]}
{"op":"mcm","clk":"5348028573","pt":1646212714749,"mc":[{"id":"1.195453618","rc":[{"atb":[[1.74,0],[1.7,142.86]],"id":39209038}],"con":true,"img":false}]}
{"op":"mcm","clk":"5348029075","pt":1646212723635,"mc":[{"id":"1.195453618","rc":[{"atb":[[1.74,10.15]],"id":39209038}],"con":true,"img":false}]}
{"op":"mcm","clk":"5348029214","pt":1646212726576,"mc":[{"id":"1.195453618","rc":[{"atb":[[1.69,0]],"id":39209038}],"con":true,"img":false}]}
{"op":"mcm","clk":"5348029221","pt":1646212726678,"mc":[{"id":"1.195453618","rc":[{"atb":[[1.55,75.17]],"id":39209038}],"con":true,"img":false}]}
{"op":"mcm","clk":"5348029657","pt":1646212734763,"mc":[{"id":"1.195453618","rc":[{"atb":[[1.74,85.32],[1.7,0]],"id":39209038}],"con":true,"img":false}]}
{"op":"mcm","clk":"5348029702","pt":1646212735483,"mc":[{"id":"1.195453618","rc":[{"atb":[[1.74,75.17]],"id":39209038}],"con":true,"img":false}]}
{"op":"mcm","clk":"5348029931","pt":1646212739873,"mc":[{"id":"1.195453618","rc":[{"atb":[[1.56,150.34],[1.74,0]],"id":39209038}],"con":true,"img":false}]}
{"op":"mcm","clk":"5348030318","pt":1646212747483,"mc":[{"id":"1.195453618","rc":[{"atb":[[1.6,12.53]],"id":39209038}],"con":true,"img":false}]}
{"op":"mcm","clk":"5348030908","pt":1646212759635,"mc":[{"id":"1.195453618","rc":[{"atb":[[1.56,0],[1.61,75.17]],"id":39209038}],"con":true,"img":false}]}
{"op":"mcm","clk":"5348031051","pt":1646212762623,"mc":[{"id":"1.195453618","rc":[{"atb":[[1.6,0]],"id":39209038}],"con":true,"img":false}]}
{"op":"mcm","clk":"5348031166","pt":1646212764833,"mc":[{"id":"1.195453618","rc":[{"atb":[[1.56,150.34],[1.61,0]],"id":39209038}],"con":true,"img":false}]}
{"op":"mcm","clk":"5348031240","pt":1646212766232,"mc":[{"id":"1.195453618","rc":[{"atb":[[1.55,0]],"id":39209038}],"con":true,"img":false}]}
{"op":"mcm","clk":"5348031244","pt":1646212766335,"mc":[{"id":"1.195453618","rc":[{"atb":[[1.57,75.17]],"id":39209038}],"con":true,"img":false}]}
{"op":"mcm","clk":"5348031252","pt":1646212766438,"mc":[{"id":"1.195453618","rc":[{"atb":[[1.56,0],[1.42,238.1]],"id":39209038}],"con":true,"img":false}]}
{"op":"mcm","clk":"5348031286","pt":1646212766918,"mc":[{"id":"1.195453618","rc":[{"atb":[[1.57,0]],"id":39209038}],"con":true,"img":false}]}
{"op":"mcm","clk":"5348031299","pt":1646212767019,"mc":[{"id":"1.195453618","rc":[{"atb":[[1.48,75.17]],"id":39209038}],"con":true,"img":false}]}
{"op":"mcm","clk":"5348031683","pt":1646212774613,"mc":[{"id":"1.195453618","rc":[{"atb":[[1.51,14.74]],"id":39209038},{"spn":2.08,"spf":"NaN","id":39209038}],"con":true,"img":false}]}
{"op":"mcm","clk":"5348031973","pt":1646212779517,"mc":[{"id":"1.195453618","rc":[{"atl":[[3.45,0],[3.75,29.3]],"id":43167174},{"atl":[[5.1,24.39],[4.7,0]],"id":43167175},{"atl":[[3.25,44.44],[2.96,0]],"id":42390009}],"con":true,"img":false}]}
{"op":"mcm","clk":"5348032312","pt":1646212785953,"mc":[{"id":"1.195453618","rc":[{"atb":[[1.42,0],[1.52,75.17]],"id":39209038}],"con":true,"img":false}]}
{"op":"mcm","clk":"5348032339","pt":1646212786352,"mc":[{"id":"1.195453618","rc":[{"atb":[[1.37,266.6],[1.31,0]],"id":43167174},{"atb":[[1.36,198.09],[1.39,297.06]],"id":42390009},{"atb":[[3.2,27.16],[2.86,0]],"id":39980030}],"con":true,"img":false}]}
{"op":"mcm","clk":"5348032358","pt":1646212786662,"mc":[{"id":"1.195453618","rc":[{"atb":[[1.51,0]],"id":39209038}],"con":true,"img":false}]}
{"op":"mcm","clk":"5348032371","pt":1646212786826,"mc":[{"id":"1.195453618","rc":[{"atb":[[1.49,150.34],[1.52,0]],"id":39209038}],"con":true,"img":false}]}
{"op":"mcm","clk":"5348032400","pt":1646212787230,"mc":[{"id":"1.195453618","rc":[{"atb":[[1.36,83.52]],"id":42390009},{"atb":[[2.88,0]],"id":39980030}],"con":true,"img":false}]}
{"op":"mcm","clk":"5348032410","pt":1646212787337,"mc":[{"id":"1.195453618","rc":[{"atb":[[1.31,114.56]],"id":42390009},{"atb":[[2.84,23.43]],"id":39980030}],"con":true,"img":false}]}
{"op":"mcm","clk":"5348032462","pt":1646212788064,"mc":[{"id":"1.195453618","rc":[{"atl":[[2.92,0]],"id":42390009}],"con":true,"img":false}]}
{"op":"mcm","clk":"5348032466","pt":1646212788167,"mc":[{"id":"1.195453618","rc":[{"atl":[[3.2,18.49]],"id":42390009}],"con":true,"img":false}]}
{"op":"mcm","clk":"5348032515","pt":1646212789043,"mc":[{"id":"1.195453618","rc":[{"atb":[[3.15,3.49]],"id":39980030}],"con":true,"img":false}]}
{"op":"mcm","clk":"5348032544","pt":1646212789661,"mc":[{"id":"1.195453618","rc":[{"atb":[[1.39,277.78]],"id":42390009},{"atb":[[3.15,0]],"id":39980030}],"con":true,"img":false}]}
{"op":"mcm","clk":"5348032591","pt":1646212790447,"mc":[{"id":"1.195453618","rc":[{"atl":[[4.6,0]],"id":43167175}],"con":true,"img":false}]}
{"op":"mcm","clk":"5348032594","pt":1646212790544,"mc":[{"id":"1.195453618","rc":[{"atl":[[4.9,11.17]],"id":43167175}],"con":true,"img":false}]}
{"op":"mcm","clk":"5348032630","pt":1646212791421,"mc":[{"id":"1.195453618","rc":[{"atb":[[3.1,74.77]],"id":39980030}],"con":true,"img":false}]}
{"op":"mcm","clk":"5348032640","pt":1646212791537,"mc":[{"id":"1.195453618","rc":[{"atb":[[3.2,0]],"id":39980030}],"con":true,"img":false}]}
{"op":"mcm","clk":"5348032822","pt":1646212794845,"mc":[{"id":"1.195453618","rc":[{"atb":[[3.15,1.66]],"id":39980030}],"con":true,"img":false}]}
{"op":"mcm","clk":"5348032860","pt":1646212795574,"mc":[{"id":"1.195453618","rc":[{"atb":[[1.52,14.45]],"id":39209038},{"atb":[[1.42,17.9]],"id":42390009}],"con":true,"img":false}]}
{"op":"mcm","clk":"5348032875","pt":1646212795771,"mc":[{"id":"1.195453618","rc":[{"atb":[[1.49,0],[1.53,75.17]],"id":39209038}],"con":true,"img":false}]}
{"op":"mcm","clk":"5348033031","pt":1646212798576,"mc":[{"id":"1.195453618","rc":[{"atb":[[3.15,5.16]],"id":39980030}],"con":true,"img":false}]}
{"op":"mcm","clk":"5348033032","pt":1646212798679,"mc":[{"id":"1.195453618","rc":[{"atb":[[1.52,0]],"id":39209038}],"con":true,"img":false}]}
{"op":"mcm","clk":"5348033044","pt":1646212798878,"mc":[{"id":"1.195453618","rc":[{"atl":[[3.6,29.04],[3.75,0]],"id":43167174},{"atl":[[5.1,0],[4.9,35.37]],"id":43167175}],"con":true,"img":false}]}
{"op":"mcm","clk":"5348033108","pt":1646212800383,"mc":[{"id":"1.195453618","rc":[{"atl":[[4.2,0],[3.75,36.36]],"id":39209038},{"atl":[[5.8,20.83],[6.8,0]],"id":40908229},{"atl":[[2.82,50.7],[3.25,0]],"id":42390009},{"atl":[[16.5,6.45]],"id":39980030}],"con":true,"img":false}]}
{"op":"mcm","clk":"5348033115","pt":1646212800497,"mc":[{"id":"1.195453618","rc":[{"atl":[[22,0]],"id":39980030}],"con":true,"img":false}]}
{"op":"mcm","clk":"5348033132","pt":1646212800766,"mc":[{"id":"1.195453618","rc":[{"atl":[[3.45,14.49]],"id":42390009}],"con":true,"img":false}]}
{"op":"mcm","clk":"5348033137","pt":1646212800856,"mc":[{"id":"1.195453618","rc":[{"atl":[[3.2,0]],"id":42390009}],"con":true,"img":false}]}
{"op":"mcm","clk":"5348033144","pt":1646212800973,"mc":[{"id":"1.195453618","rc":[{"atb":[[1.49,150.34],[1.53,0]],"id":39209038}],"con":true,"img":false}]}
{"op":"mcm","clk":"5348033187","pt":1646212801798,"mc":[{"id":"1.195453618","rc":[{"atb":[[1.56,35.71],[1.54,92.59],[1.5,250],[1.52,144.23]],"id":39209038},{"atl":[[3.45,8.16],[3.55,19.61],[3.75,81.81],[3.65,28.3]],"id":39209038},{"atb":[[1.36,55.56],[1.32,234.37],[1.3,250],[1.34,147.06]],"id":40812743},{"atl":[[11,2],[12,4.55],[13,6.25],[14,9.62]],"id":40812743},{"atb":[[1.63,198.41],[1.67,74.63],[1.65,268.94],[1.69,28.99]],"id":43167174},{"atl":[[2.74,71.84],[2.66,30.12],[2.62,12.35],[2.7,44.12]],"id":43167174},{"atb":[[1.37,218.04],[1.33,250],[1.39,51.28],[1.35,499.47]],"id":42300273},{"atl":[[11,2],[12,4.55],[13,6.25],[14,9.62]],"id":42300273},{"atb":[[1.18,111.11],[1.12,250],[1.16,250],[1.14,250]],"id":43167175},{"atl":[[3.45,30.61],[3.35,21.28],[3.25,8.89],[3.55,49.02]],"id":43167175},{"atb":[[2.74,28.74],[2.66,75.3],[2.78,11.24],[2.7,102.83]],"id":40908229},{"atl":[[5.1,4.88],[5.3,11.63],[5.5,16.67],[5.7,26.6]],"id":40908229},{"atb":[[1.37,135.14],[1.33,250],[1.39,329.06],[1.35,214.29]],"id":42390009},{"atl":[[2.22,61.48],[2.18,42.37],[2.26,99.21],[2.14,17.54]],"id":42390009},{"atb":[[3.15,14.46],[2.98,37.88],[2.94,64.43],[3.05,73.07]],"id":39980030},{"atl":[[9.6,8.72],[9.2,6.1],[10,13.89],[8.8,2.56]],"id":39980030}],"con":true,"img":false}]}
{"op":"mcm","clk":"5348033192","pt":1646212801848,"mc":[{"id":"1.195453618","rc":[{"atl":[[13,9.88]],"id":40812743},{"atl":[[3.95,0]],"id":43167174}],"con":true,"img":false}]}
{"op":"mcm","clk":"5348033196","pt":1646212801948,"mc":[{"id":"1.195453618","rc":[{"atl":[[15.5,2.5]],"id":40812743},{"atl":[[3.55,14.78]],"id":43167174}],"con":true,"img":false}]}
{"op":"mcm","clk":"5348033248","pt":1646212802785,"mc":[{"id":"1.195453618","rc":[{"atb":[[4.4,0]],"id":40812743}],"con":true,"img":false}]}
{"op":"mcm","clk":"5348033252","pt":1646212802882,"mc":[{"id":"1.195453618","rc":[{"atb":[[3.95,13.85]],"id":40812743}],"con":true,"img":false}]}
{"op":"mcm","clk":"5348033270","pt":1646212803154,"mc":[{"id":"1.195453618","rc":[{"atb":[[1.39,307.69]],"id":42390009},{"atb":[[3.1,70.8]],"id":39980030}],"con":true,"img":false}]}
{"op":"mcm","clk":"5348033337","pt":1646212804753,"mc":[{"id":"1.195453618","rc":[{"atb":[[2.76,4.73]],"id":40908229}],"con":true,"img":false}]}
{"op":"mcm","clk":"5348033429","pt":1646212806473,"mc":[{"id":"1.195453618","rc":[{"atl":[[3.45,0],[3.55,7.84]],"id":39209038},{"atb":[[1.45,44.44],[1.26,0],[1.35,234.37],[1.36,0]],"id":40812743},{"atl":[[5,30],[10.5,0],[11,0]],"id":42300273},{"atb":[[2.82,10.99],[2.78,0]],"id":40908229},{"atl":[[9,2.5],[8.8,0]],"id":39980030}],"con":true,"img":false}]}
{"op":"mcm","clk":"5348033523","pt":1646212808379,"mc":[{"id":"1.195453618","rc":[{"atb":[[1.48,0]],"id":39209038}],"con":true,"img":false}]}
{"op":"mcm","clk":"5348033529","pt":1646212808490,"mc":[{"id":"1.195453618","rc":[{"atb":[[1.56,110.88]],"id":39209038}],"con":true,"img":false}]}
{"op":"mcm","clk":"5348033545","pt":1646212808895,"mc":[{"id":"1.195453618","rc":[{"atb":[[1.36,0]],"id":42390009}],"con":true,"img":false}]}
{"op":"mcm","clk":"5348033549","pt":1646212808997,"mc":[{"id":"1.195453618","rc":[{"atb":[[1.4,83.52]],"id":42390009}],"con":true,"img":false}]}
{"op":"mcm","clk":"5348033591","pt":1646212809885,"mc":[{"id":"1.195453618","rc":[{"atb":[[4.7,0]],"id":40812743}],"con":true,"img":false}]}
{"op":"mcm","clk":"5348033597","pt":1646212809985,"mc":[{"id":"1.195453618","rc":[{"atb":[[4.4,11.78]],"id":40812743}],"con":true,"img":false}]}
{"op":"mcm","clk":"5348033622","pt":1646212810709,"mc":[{"id":"1.195453618","rc":[{"atb":[[2.8,4.18]],"id":40908229},{"atb":[[1.42,0]],"id":42390009}],"con":true,"img":false}]}
{"op":"mcm","clk":"5348033743","pt":1646212812987,"mc":[{"id":"1.195453618","rc":[{"atb":[[4.8,0]],"id":40812743}],"con":true,"img":false}]}
{"op":"mcm","clk":"5348033747","pt":1646212813086,"mc":[{"id":"1.195453618","rc":[{"atb":[[4.5,1.66]],"id":40812743}],"con":true,"img":false}]}
{"op":"mcm","clk":"5348033898","pt":1646212816514,"mc":[{"id":"1.195453618","rc":[{"atl":[[3.65,18.87]],"id":39209038},{"atb":[[1.43,116.28]],"id":40812743},{"atl":[[5.2,11.9]],"id":42300273},{"atb":[[2.78,28.09]],"id":40908229},{"atl":[[9.4,5.95]],"id":39980030}],"con":true,"img":false}]}
{"op":"mcm","clk":"5348033912","pt":1646212816713,"mc":[{"id":"1.195453618","rc":[{"atb":[[1.6,12.53]],"id":39209038},{"atb":[[1.43,17.48]],"id":42390009}],"con":true,"img":false}]}
{"op":"mcm","clk":"5348033922","pt":1646212816922,"mc":[{"id":"1.195453618","rc":[{"atb":[[1.32,0],[1.3,0],[1.34,0]],"id":40812743},{"atl":[[14,0]],"id":42300273},{"atb":[[2.66,0]],"id":40908229},{"atl":[[9.6,0],[9.2,0],[10,0]],"id":39980030}],"con":true,"img":false}]}
{"op":"mcm","clk":"5348033992","pt":1646212818015,"mc":[{"id":"1.195453618","rc":[{"atl":[[3.6,0],[3.25,44.44]],"id":43167174}],"con":true,"img":false}]}
{"op":"mcm","clk":"5348034062","pt":1646212818996,"mc":[{"id":"1.195453618","rc":[{"atb":[[3.15,18.33]],"id":39980030}],"con":true,"img":false}]}
{"op":"mcm","clk":"5348034101","pt":1646212819715,"mc":[{"id":"1.195453618","rc":[{"atb":[[2.8,0]],"id":40908229}],"con":true,"img":false}]}
{"op":"mcm","clk":"5348034125","pt":1646212820130,"mc":[{"id":"1.195453618","rc":[{"atb":[[1.49,0],[1.61,92.59]],"id":39209038}],"con":true,"img":false}]}
{"op":"mcm","clk":"5348034226","pt":1646212821808,"mc":[{"id":"1.195453618","rc":[{"atb":[[1.37,135.14]],"id":42300273}],"con":true,"img":false}]}
{"op":"mcm","clk":"5348034233","pt":1646212821911,"mc":[{"id":"1.195453618","rc":[{"atb":[[1.38,82.9]],"id":42300273}],"con":true,"img":false}]}
{"op":"mcm","clk":"5348034351","pt":1646212823716,"mc":[{"id":"1.195453618","rc":[{"atb":[[1.6,0]],"id":39209038},{"atb":[[1.4,20.84]],"id":42300273}],"con":true,"img":false}]}
{"op":"mcm","clk":"5348034359","pt":1646212823819,"mc":[{"id":"1.195453618","rc":[{"atl":[[2.72,0],[2.16,37.58]],"id":42390009},{"atl":[[9.2,5.31],[13.5,0]],"id":39980030}],"con":true,"img":false}]}
{"op":"mcm","clk":"5348034365","pt":1646212823923,"mc":[{"id":"1.195453618","rc":[{"atb":[[1.57,175.44],[1.61,0]],"id":39209038},{"atl":[[3.4,18.16],[4.9,24.2]],"id":43167175}],"con":true,"img":false}]}
{"op":"mcm","clk":"5348034382","pt":1646212824199,"mc":[{"id":"1.195453618","rc":[{"atb":[[4.5,0]],"id":40812743},{"trd":[[4.5,3.33]],"ltp":4.5,"tv":3.33,"id":40812743},{"atb":[[2.82,0]],"id":40908229},{"trd":[[2.82,21.98]],"ltp":2.82,"tv":21.98,"id":40908229},{"atb":[[3.15,0]],"id":39980030},{"trd":[[3.15,36.67]],"ltp":3.15,"tv":36.67,"id":39980030}],"con":true,"img":false}]}
{"op":"mcm","clk":"5348034398","pt":1646212824408,"mc":[{"id":"1.195453618","rc":[{"atb":[[2.74,0],[2.78,0],[2.76,15.18],[2.7,58.71]],"id":40908229},{"atl":[[4.8,6.46]],"id":40908229},{"atb":[[3,9.24],[2.98,0],[2.94,0],[3.05,48.68]],"id":39980030},{"atl":[[8,3.66]],"id":39980030}],"con":true,"img":false}]}
{"op":"mcm","clk":"5348034430","pt":1646212824928,"mc":[{"id":"1.195453618","rc":[{"atb":[[4.5,1.66],[3.95,0]],"id":40812743},{"atb":[[2.78,1.66]],"id":40908229},{"atl":[[4.8,0]],"id":40908229}],"con":true,"img":false}]}
{"op":"mcm","clk":"5348034439","pt":1646212825019,"mc":[{"id":"1.195453618","rc":[{"atb":[[3.7,13.85]],"id":40812743}],"con":true,"img":false}]}
{"op":"mcm","clk":"5348034462","pt":1646212825393,"mc":[{"id":"1.195453618","rc":[{"atl":[[40,0]],"id":40812743}],"con":true,"img":false}]}
{"op":"mcm","clk":"5348034471","pt":1646212825500,"mc":[{"id":"1.195453618","rc":[{"atl":[[12.5,2.72]],"id":40812743}],"con":true,"img":false}]}
{"op":"mcm","clk":"5348034489","pt":1646212825709,"mc":[{"id":"1.195453618","rc":[{"atl":[[12,9.1],[13,6.25]],"id":40812743},{"atl":[[4.1,2.68]],"id":39980030}],"con":true,"img":false}]}
{"op":"mcm","clk":"5348034532","pt":1646212826526,"mc":[{"id":"1.195453618","rc":[{"atl":[[3.75,63.63]],"id":39209038},{"atb":[[1.41,182.93]],"id":40812743},{"atl":[[5.4,17.05]],"id":42300273}],"con":true,"img":false}]}
{"op":"mcm","clk":"5348034551","pt":1646212826799,"mc":[{"id":"1.195453618","rc":[{"atl":[[2.72,25.34]],"id":43167174}],"con":true,"img":false}]}
{"op":"mcm","clk":"5348034557","pt":1646212826902,"mc":[{"id":"1.195453618","rc":[{"atl":[[3.55,0]],"id":43167174}],"con":true,"img":false}]}
{"op":"mcm","clk":"5348034691","pt":1646212828799,"mc":[{"id":"1.195453618","rc":[{"atb":[[1.41,18.33]],"id":42300273}],"con":true,"img":false}]}
{"op":"mcm","clk":"5348034756","pt":1646212829631,"mc":[{"id":"1.195453618","rc":[{"atl":[[13,0]],"id":42300273}],"con":true,"img":false}]}
{"op":"mcm","clk":"5348034840","pt":1646212830828,"mc":[{"id":"1.195453618","rc":[{"atb":[[1.43,36.87]],"id":42390009}],"con":true,"img":false}]}
{"op":"mcm","clk":"5348034847","pt":1646212830927,"mc":[{"id":"1.195453618","rc":[{"atb":[[3.15,1.66]],"id":39980030},{"atl":[[4.1,5.66]],"id":39980030}],"con":true,"img":false}]}
{"op":"mcm","clk":"5348034864","pt":1646212831124,"mc":[{"id":"1.195453618","rc":[{"atl":[[8,0]],"id":39980030}],"con":true,"img":false}]}
{"op":"mcm","clk":"5348034917","pt":1646212831809,"mc":[{"id":"1.195453618","rc":[{"atb":[[1.61,12.32]],"id":39209038},{"atb":[[2.76,19.45]],"id":40908229}],"con":true,"img":false}]}
{"op":"mcm","clk":"5348035056","pt":1646212833723,"mc":[{"id":"1.195453618","rc":[{"atb":[[4.5,0]],"id":40812743},{"trd":[[4.5,6.66]],"ltp":4.5,"tv":6.66,"id":40812743},{"atb":[[2.78,0],[2.76,0]],"id":40908229},{"trd":[[2.76,38.91],[2.78,3.33]],"ltp":2.76,"tv":42.23,"id":40908229},{"atb":[[3.1,61.95],[3.15,0]],"id":39980030},{"trd":[[3.1,17.71],[3.15,40.01]],"ltp":3.1,"tv":57.72,"id":39980030}],"con":true,"img":false}]}
{"op":"mcm","clk":"5348035065","pt":1646212833920,"mc":[{"id":"1.195453618","rc":[{"atb":[[2.66,25.45],[2.58,66.84],[2.62,39.11],[2.7,68.65]],"id":40908229}],"con":true,"img":false}]}
{"op":"mcm","clk":"5348035086","pt":1646212834335,"mc":[{"id":"1.195453618","rc":[{"atl":[[3.6,13.86]],"id":42300273},{"atb":[[2.84,0]],"id":39980030}],"con":true,"img":false}]}
{"op":"mcm","clk":"5348035096","pt":1646212834430,"mc":[{"id":"1.195453618","rc":[{"atl":[[2.98,0]],"id":42300273},{"atb":[[2.44,23.43],[2.96,23.57]],"id":39980030},{"atl":[[9.8,8.52]],"id":39980030}],"con":true,"img":false}]}
{"op":"mcm","clk":"5348035167","pt":1646212835725,"mc":[{"id":"1.195453618","rc":[{"spn":2.13,"spf":"NaN","id":39209038},{"spn":7.7,"spf":"NaN","id":40812743},{"spn":2.2,"spf":"NaN","id":43167174},{"spn":2.0,"spf":"NaN","id":42300273},{"spn":2.6,"spf":"NaN","id":43167175},{"atl":[[3.55,3.32]],"id":40908229},{"spn":3.13,"spf":"NaN","id":40908229},{"spn":1.78,"spf":"NaN","id":42390009},{"spn":3.6,"spf":"NaN","id":39980030}],"con":true,"img":false}]}
{"op":"mcm","clk":"5348035208","pt":1646212836495,"mc":[{"id":"1.195453618","rc":[{"atl":[[3.85,43.86]],"id":39209038},{"atb":[[1.39,250]],"id":40812743},{"atl":[[5.6,27.17]],"id":42300273}],"con":true,"img":false}]}
{"op":"mcm","clk":"5348035227","pt":1646212836911,"mc":[{"id":"1.195453618","rc":[{"atb":[[2.74,1.66]],"id":40908229},{"atb":[[1.41,135.14],[1.39,51.28]],"id":42390009}],"con":true,"img":false}]}
{"op":"mcm","clk":"5348035234","pt":1646212837011,"mc":[{"id":"1.195453618","rc":[{"atl":[[12,0]],"id":42300273}],"con":true,"img":false}]}
{"op":"mcm","clk":"5348035270","pt":1646212837731,"mc":[{"id":"1.195453618","rc":[{"atb":[[1.43,19.38]],"id":42390009}],"con":true,"img":false}]}
{"op":"mcm","clk":"5348035364","pt":1646212839333,"mc":[{"id":"1.195453618","rc":[{"atl":[[3.55,7]],"id":40908229}],"con":true,"img":false}]}
{"op":"mcm","clk":"5348035442","pt":1646212840922,"mc":[{"id":"1.195453618","rc":[{"atl":[[4.1,0]],"id":39209038}],"con":true,"img":false}]}
{"op":"mcm","clk":"5348035451","pt":1646212841036,"mc":[{"id":"1.195453618","rc":[{"atl":[[3.7,14.46]],"id":39209038}],"con":true,"img":false}]}
{"op":"mcm","clk":"5348035467","pt":1646212841295,"mc":[{"id":"1.195453618","rc":[{"atl":[[2.84,0]],"id":39209038},{"atl":[[2.72,0]],"id":43167174},{"atl":[[4.5,12.45],[3.4,0]],"id":43167175},{"atl":[[4.9,0]],"id":40908229},{"atl":[[2.16,0],[2.68,25.34]],"id":42390009}],"con":true,"img":false}]}
{"op":"mcm","clk":"5348035468","pt":1646212841389,"mc":[{"id":"1.195453618","rc":[{"atl":[[3.1,23.69]],"id":39209038},{"atl":[[3.2,25.34]],"id":43167174},{"atl":[[5.6,11.17]],"id":40908229}],"con":true,"img":false}]}
{"op":"mcm","clk":"5348035473","pt":1646212841498,"mc":[{"id":"1.195453618","rc":[{"atb":[[1.36,0],[1.38,177.8]],"id":42300273}],"con":true,"img":false}]}
{"op":"mcm","clk":"5348035519","pt":1646212842432,"mc":[{"id":"1.195453618","rc":[{"atb":[[1.31,0]],"id":42390009}],"con":true,"img":false}]}
{"op":"mcm","clk":"5348035528","pt":1646212842528,"mc":[{"id":"1.195453618","rc":[{"atb":[[1.36,114.56]],"id":42390009}],"con":true,"img":false}]}
{"op":"mcm","clk":"5348035547","pt":1646212842836,"mc":[{"id":"1.195453618","rc":[{"atb":[[1.56,35.71],[1.57,0],[1.62,110.88]],"id":39209038},{"atb":[[3.1,68.38]],"id":39980030}],"con":true,"img":false}]}
{"op":"mcm","clk":"5348035555","pt":1646212842939,"mc":[{"id":"1.195453618","rc":[{"atb":[[1.62,186.05]],"id":39209038}],"con":true,"img":false}]}
{"op":"mcm","clk":"5348035569","pt":1646212843106,"mc":[{"id":"1.195453618","rc":[{"atb":[[4.4,0]],"id":40812743},{"trd":[[4.4,23.56]],"ltp":4.4,"tv":23.56,"id":40812743},{"atb":[[2.72,0],[2.74,0]],"id":40908229},{"trd":[[2.72,50.69],[2.74,3.33]],"ltp":2.72,"tv":54.01,"id":40908229}],"con":true,"img":false}]}
{"op":"mcm","clk":"5348035631","pt":1646212843830,"mc":[{"id":"1.195453618","rc":[{"atb":[[1.61,0]],"id":39209038},{"atb":[[3.2,9.47],[3.7,0]],"id":40812743},{"atb":[[1.91,15.99]],"id":40908229},{"atb":[[1.44,17.09]],"id":42390009},{"atl":[[3.45,0],[2.92,18.49]],"id":42390009},{"atl":[[15,0]],"id":39980030}],"con":true,"img":false}]}
{"op":"mcm","clk":"5348035638","pt":1646212843931,"mc":[{"id":"1.195453618","rc":[{"atl":[[12.5,2.72]],"id":39980030}],"con":true,"img":false}]}
{"op":"mcm","clk":"5348035666","pt":1646212844349,"mc":[{"id":"1.195453618","rc":[{"atb":[[1.41,0],[1.55,74.97]],"id":39209038}],"con":true,"img":false}]}
{"op":"mcm","clk":"5348035676","pt":1646212844437,"mc":[{"id":"1.195453618","rc":[{"atb":[[2.92,88.08]],"id":39980030},{"atl":[[10.5,20.8]],"id":39980030}],"con":true,"img":false}]}
{"op":"mcm","clk":"5348035768","pt":1646212845847,"mc":[{"id":"1.195453618","rc":[{"atb":[[1.4,0]],"id":42390009}],"con":true,"img":false}]}
{"op":"mcm","clk":"5348035773","pt":1646212845951,"mc":[{"id":"1.195453618","rc":[{"atb":[[1.38,83.52]],"id":42390009}],"con":true,"img":false}]}
{"op":"mcm","clk":"5348035868","pt":1646212847339,"mc":[{"id":"1.195453618","rc":[{"atl":[[44,0]],"id":40812743}],"con":true,"img":false}]}
{"op":"mcm","clk":"5348035878","pt":1646212847450,"mc":[{"id":"1.195453618","rc":[{"atl":[[13.5,2.72]],"id":40812743}],"con":true,"img":false}]}
{"op":"mcm","clk":"5348036016","pt":1646212849721,"mc":[{"id":"1.195453618","rc":[{"atb":[[1.66,11.39]],"id":39209038}],"con":true,"img":false}]}
{"op":"mcm","clk":"5348036056","pt":1646212850651,"mc":[{"id":"1.195453618","rc":[{"atb":[[1.4,0]],"id":42300273},{"atb":[[1.43,0]],"id":42390009}],"con":true,"img":false}]}
{"op":"mcm","clk":"5348036157","pt":1646212852669,"mc":[{"id":"1.195453618","rc":[{"atb":[[2.7,48.04]],"id":40908229},{"trd":[[2.7,41.23]],"ltp":2.7,"tv":41.23,"id":40908229}],"con":true,"img":false}]}
{"op":"mcm","clk":"5348036191","pt":1646212853234,"mc":[{"id":"1.195453618","rc":[{"atb":[[1.67,1.57]],"id":39209038},{"atb":[[4.4,1.49]],"id":40812743},{"atb":[[1.8,1.51]],"id":43167174},{"atb":[[1.42,1.61]],"id":42300273},{"atb":[[1.96,1.41]],"id":43167175},{"atb":[[2.72,1.43]],"id":40908229},{"atb":[[1.45,1.55]],"id":42390009},{"atb":[[3.15,1.54]],"id":39980030}],"con":true,"img":false}]}
{"op":"mcm","clk":"5348036198","pt":1646212853336,"mc":[{"id":"1.195453618","rc":[{"atl":[[9.2,0]],"id":39980030}],"con":true,"img":false}]}
{"op":"mcm","clk":"5348036202","pt":1646212853431,"mc":[{"id":"1.195453618","rc":[{"atl":[[5.2,5.31]],"id":39980030}],"con":true,"img":false}]}
{"op":"mcm","clk":"5348036222","pt":1646212853853,"mc":[{"id":"1.195453618","rc":[{"atl":[[2.64,1.37]],"id":39209038},{"atb":[[4.4,13.27]],"id":40812743},{"atl":[[11,3.45]],"id":40812743},{"atl":[[2.6,1.42]],"id":43167174},{"atl":[[2.58,1.36]],"id":42300273},{"atl":[[3.2,1.4]],"id":43167175},{"atb":[[2.72,26.78]],"id":40908229},{"atl":[[2.12,1.34]],"id":42390009}],"con":true,"img":false}]}
{"op":"mcm","clk":"5348036258","pt":1646212854424,"mc":[{"id":"1.195453618","rc":[{"atb":[[2.88,61.44]],"id":39980030}],"con":true,"img":false}]}
{"op":"mcm","clk":"5348036399","pt":1646212857560,"mc":[{"id":"1.195453618","rc":[{"atl":[[5.2,0]],"id":39980030}],"con":true,"img":false}]}
{"op":"mcm","clk":"5348036405","pt":1646212857666,"mc":[{"id":"1.195453618","rc":[{"atl":[[5.3,5.31]],"id":39980030}],"con":true,"img":false}]}
{"op":"mcm","clk":"5348036515","pt":1646212859368,"mc":[{"id":"1.195453618","rc":[{"atl":[[12.5,0]],"id":40812743}],"con":true,"img":false}]}
{"op":"mcm","clk":"5348036522","pt":1646212859472,"mc":[{"id":"1.195453618","rc":[{"atl":[[10.5,2.72]],"id":40812743}],"con":true,"img":false}]}
{"op":"mcm","clk":"5348036546","pt":1646212859944,"mc":[{"id":"1.195453618","rc":[{"atl":[[11,2]],"id":40812743}],"con":true,"img":false}]}
{"op":"mcm","clk":"5348036552","pt":1646212860048,"mc":[{"id":"1.195453618","rc":[{"atl":[[10.5,4.17]],"id":40812743}],"con":true,"img":false}]}
{"op":"mcm","clk":"5348036653","pt":1646212861570,"mc":[{"id":"1.195453618","rc":[{"atb":[[1.67,12.96],[1.62,75.17]],"id":39209038}],"con":true,"img":false}]}
{"op":"mcm","clk":"5348036736","pt":1646212862767,"mc":[{"id":"1.195453618","rc":[{"atl":[[3.75,8.71]],"id":40908229}],"con":true,"img":false}]}
{"op":"mcm","clk":"5348036742","pt":1646212862869,"mc":[{"id":"1.195453618","rc":[{"atl":[[5.6,0]],"id":40908229}],"con":true,"img":false}]}
{"op":"mcm","clk":"5348036744","pt":1646212862968,"mc":[{"id":"1.195453618","rc":[{"atl":[[3.5,17.1]],"id":40908229}],"con":true,"img":false}]}
{"op":"mcm","clk":"5348036777","pt":1646212863375,"mc":[{"id":"1.195453618","rc":[{"atb":[[1.41,0],[1.4,83.52]],"id":42390009},{"atl":[[2.12,19.2],[2.14,0]],"id":42390009}],"con":true,"img":false}]}
{"op":"mcm","clk":"5348036781","pt":1646212863440,"mc":[{"id":"1.195453618","rc":[{"atl":[[3.45,1.42]],"id":40908229}],"con":true,"img":false}]}
{"op":"mcm","clk":"5348036910","pt":1646212865553,"mc":[{"id":"1.195453618","rc":[{"atl":[[3.55,3.68]],"id":40908229}],"con":true,"img":false}]}
{"op":"mcm","clk":"5348036915","pt":1646212865650,"mc":[{"id":"1.195453618","rc":[{"atb":[[1.44,0]],"id":42390009}],"con":true,"img":false}]}
{"op":"mcm","clk":"5348036923","pt":1646212865757,"mc":[{"id":"1.195453618","rc":[{"atl":[[3.35,3.51]],"id":40908229}],"con":true,"img":false}]}
{"op":"mcm","clk":"5348036982","pt":1646212866684,"mc":[{"id":"1.195453618","rc":[{"atl":[[3.55,0]],"id":40908229}],"con":true,"img":false}]}
{"op":"mcm","clk":"5348036989","pt":1646212866742,"mc":[{"id":"1.195453618","rc":[{"atb":[[1.41,38.67]],"id":42300273}],"con":true,"img":false}]}
{"op":"mcm","clk":"5348036997","pt":1646212866937,"mc":[{"id":"1.195453618","rc":[{"atb":[[1.66,24.02]],"id":39209038}],"con":true,"img":false}]}
{"op":"mcm","clk":"5348037009","pt":1646212867145,"mc":[{"id":"1.195453618","rc":[{"atl":[[3.35,7.42]],"id":40908229}],"con":true,"img":false}]}
{"op":"mcm","clk":"5348037143","pt":1646212869674,"mc":[{"id":"1.195453618","rc":[{"atb":[[1.45,0]],"id":42390009}],"con":true,"img":false}]}
{"op":"mcm","clk":"5348037151","pt":1646212869777,"mc":[{"id":"1.195453618","rc":[{"atb":[[1.41,1.55]],"id":42390009}],"con":true,"img":false}]}
{"op":"mcm","clk":"5348037159","pt":1646212869836,"mc":[{"id":"1.195453618","rc":[{"atb":[[1.4,0],[1.39,218.32]],"id":42390009}],"con":true,"img":false}]}
{"op":"mcm","clk":"5348037184","pt":1646212870242,"mc":[{"id":"1.195453618","rc":[{"atb":[[1.41,0]],"id":42390009}],"con":true,"img":false}]}
{"op":"mcm","clk":"5348037191","pt":1646212870344,"mc":[{"id":"1.195453618","rc":[{"atb":[[1.4,1.55]],"id":42390009}],"con":true,"img":false}]}
{"op":"mcm","clk":"5348037251","pt":1646212871375,"mc":[{"id":"1.195453618","rc":[{"atb":[[4.4,10.92]],"id":40812743},{"trd":[[4.4,28.27]],"ltp":4.4,"tv":28.27,"id":40812743},{"atb":[[2.72,25.59]],"id":40908229},{"trd":[[2.72,53.06]],"ltp":2.72,"tv":53.06,"id":40908229}],"con":true,"img":false}]}
{"op":"mcm","clk":"5348037267","pt":1646212871588,"mc":[{"id":"1.195453618","rc":[{"atl":[[3.35,11.89],[3.5,0]],"id":40908229}],"con":true,"img":false}]}
{"op":"mcm","clk":"5348037284","pt":1646212871746,"mc":[{"id":"1.195453618","rc":[{"atl":[[3.7,0]],"id":39209038}],"con":true,"img":false}]}
{"op":"mcm","clk":"5348037290","pt":1646212871853,"mc":[{"id":"1.195453618","rc":[{"atl":[[3.8,14.46]],"id":39209038}],"con":true,"img":false}]}
{"op":"mcm","clk":"5348037301","pt":1646212871959,"mc":[{"id":"1.195453618","rc":[{"atl":[[10.5,5.44]],"id":40812743},{"atb":[[2.72,25.34]],"id":40908229},{"atl":[[3.35,12.89]],"id":40908229}],"con":true,"img":false}]}
{"op":"mcm","clk":"5348037525","pt":1646212875767,"mc":[{"id":"1.195453618","rc":[{"atb":[[1.81,45.63],[1.66,0]],"id":43167175}],"con":true,"img":false}]}
{"op":"mcm","clk":"5348037738","pt":1646212880091,"mc":[{"id":"1.195453618","rc":[{"atb":[[1.42,17.9]],"id":42390009}],"con":true,"img":false}]}
{"op":"mcm","clk":"5348037776","pt":1646212880975,"mc":[{"id":"1.195453618","rc":[{"atb":[[1.4,0]],"id":42390009}],"con":true,"img":false}]}
{"op":"mcm","clk":"5348037778","pt":1646212881070,"mc":[{"id":"1.195453618","rc":[{"atb":[[1.43,1.55]],"id":42390009}],"con":true,"img":false}]}
{"op":"mcm","clk":"5348037818","pt":1646212881792,"mc":[{"id":"1.195453618","rc":[{"atb":[[4.4,11.78]],"id":40812743}],"con":true,"img":false}]}
{"op":"mcm","clk":"5348037918","pt":1646212883394,"mc":[{"id":"1.195453618","rc":[{"atb":[[1.38,0]],"id":42390009}],"con":true,"img":false}]}
{"op":"mcm","clk":"5348037919","pt":1646212883487,"mc":[{"id":"1.195453618","rc":[{"atb":[[1.4,83.52]],"id":42390009}],"con":true,"img":false}]}
{"op":"mcm","clk":"5348038061","pt":1646212885993,"mc":[{"id":"1.195453618","rc":[{"atb":[[1.42,0]],"id":42390009}],"con":true,"img":false}]}
{"op":"mcm","clk":"5348038070","pt":1646212886297,"mc":[{"id":"1.195453618","rc":[{"atb":[[1.43,0]],"id":42390009}],"con":true,"img":false}]}
{"op":"mcm","clk":"5348038074","pt":1646212886394,"mc":[{"id":"1.195453618","rc":[{"atl":[[8.2,0],[5.6,7.94]],"id":40908229},{"atb":[[1.41,1.55]],"id":42390009}],"con":true,"img":false}]}
{"op":"mcm","clk":"5348038112","pt":1646212887207,"mc":[{"id":"1.195453618","rc":[{"atl":[[1000,2.25]],"id":39209038},{"atl":[[1000,2.25]],"id":40812743},{"atl":[[1000,2.25]],"id":43167174},{"atl":[[1000,2.25]],"id":42300273},{"atl":[[1000,2.25]],"id":43167175},{"atl":[[1000,2.25]],"id":42390009}],"con":true,"img":false}]}
{"op":"mcm","clk":"5348038116","pt":1646212887271,"mc":[{"id":"1.195453618","rc":[{"atb":[[2.44,0]],"id":39980030}],"con":true,"img":false}]}
{"op":"mcm","clk":"5348038126","pt":1646212887481,"mc":[{"id":"1.195453618","rc":[{"atb":[[2.84,23.43]],"id":39980030}],"con":true,"img":false}]}
{"op":"mcm","clk":"5348038151","pt":1646212887791,"mc":[{"id":"1.195453618","rc":[{"atl":[[1000,0.15]],"id":39209038},{"atl":[[1000,0.15]],"id":40812743},{"atl":[[1000,0.15]],"id":43167174},{"atl":[[1000,0.15]],"id":42300273},{"atl":[[1000,0.15]],"id":43167175},{"atl":[[1000,0.15]],"id":42390009}],"con":true,"img":false}]}
{"op":"mcm","clk":"5348038182","pt":1646212888299,"mc":[{"id":"1.195453618","rc":[{"atb":[[1.4,218.66],[1.39,51.28]],"id":42390009}],"con":true,"img":false}]}
{"op":"mcm","clk":"5348038207","pt":1646212888563,"mc":[{"id":"1.195453618","rc":[{"atl":[[1000,0]],"id":39209038},{"atl":[[1000,0]],"id":40812743},{"atl":[[1000,0]],"id":43167174},{"atl":[[1000,0]],"id":42300273},{"atl":[[1000,0]],"id":43167175},{"atl":[[1000,0]],"id":42390009}],"con":true,"img":false}]}
{"op":"mcm","clk":"5348038210","pt":1646212888660,"mc":[{"id":"1.195453618","rc":[{"atl":[[2.64,1.52]],"id":39209038},{"atl":[[10.5,5.59]],"id":40812743},{"atl":[[2.6,1.57]],"id":43167174},{"atl":[[2.58,1.51]],"id":42300273},{"atl":[[3.25,9.04]],"id":43167175},{"atl":[[2.1,0.15]],"id":42390009}],"con":true,"img":false}]}
{"op":"mcm","clk":"5348038398","pt":1646212891988,"mc":[{"id":"1.195453618","rc":[{"atb":[[1.43,17.48]],"id":42390009}],"con":true,"img":false}]}
{"op":"mcm","clk":"5348038424","pt":1646212892598,"mc":[{"id":"1.195453618","rc":[{"atb":[[1.41,0]],"id":42390009}],"con":true,"img":false}]}
{"op":"mcm","clk":"5348038431","pt":1646212892703,"mc":[{"id":"1.195453618","rc":[{"atb":[[1.44,1.55]],"id":42390009}],"con":true,"img":false}]}
{"op":"mcm","clk":"5348038525","pt":1646212894304,"mc":[{"id":"1.195453618","rc":[{"atl":[[12.5,3.55],[13.5,0]],"id":40812743}],"con":true,"img":false}]}
{"op":"mcm","clk":"5348039127","pt":1646212905501,"mc":[{"id":"1.195453618","rc":[{"spn":2.15,"spf":"NaN","id":39209038},{"spn":7.45,"spf":"NaN","id":40812743},{"spn":2.2,"spf":"NaN","id":43167174},{"spn":2.0,"spf":"NaN","id":42300273},{"spn":2.58,"spf":"NaN","id":43167175},{"spn":3.03,"spf":"NaN","id":40908229},{"atb":[[1.43,36.87]],"id":42390009},{"spn":1.77,"spf":"NaN","id":42390009},{"spn":3.62,"spf":"NaN","id":39980030}],"con":true,"img":false}]}
{"op":"mcm","clk":"5348039189","pt":1646212906786,"mc":[{"id":"1.195453618","rc":[{"atb":[[1.68,1.28]],"id":39209038},{"atb":[[4.5,1.2]],"id":40812743},{"atb":[[1.8,2.71]],"id":43167174},{"atb":[[1.42,2.8]],"id":42300273},{"atb":[[1.96,2.61]],"id":43167175},{"atb":[[2.74,1.25]],"id":40908229},{"atb":[[1.44,2.8]],"id":42390009},{"atb":[[3.15,2.81]],"id":39980030}],"con":true,"img":false}]}
{"op":"mcm","clk":"5348040075","pt":1646212923647,"mc":[{"id":"1.195453618","rc":[{"atb":[[3,0],[3.15,11.41]],"id":39980030}],"con":true,"img":false}]}
{"op":"mcm","clk":"5348040354","pt":1646212928830,"mc":[{"id":"1.195453618","rc":[{"atb":[[3.2,0],[3.7,7.17]],"id":40812743}],"con":true,"img":false}]}
{"op":"mcm","clk":"5348040417","pt":1646212930320,"mc":[{"id":"1.195453618","rc":[{"atl":[[5.6,0]],"id":40908229}],"con":true,"img":false}]}
{"op":"mcm","clk":"5348040421","pt":1646212930422,"mc":[{"id":"1.195453618","rc":[{"atl":[[5.4,7.94]],"id":40908229}],"con":true,"img":false}]}
{"op":"mcm","clk":"5348040469","pt":1646212931350,"mc":[{"id":"1.195453618","rc":[{"atb":[[3.15,9.97]],"id":39980030},{"trd":[[3.15,42.89]],"ltp":3.15,"tv":42.89,"id":39980030}],"con":true,"img":false}]}
{"op":"mcm","clk":"5348040483","pt":1646212931759,"mc":[{"id":"1.195453618","rc":[{"atl":[[4.1,6.88]],"id":39980030}],"con":true,"img":false}]}
{"op":"mcm","clk":"5348040488","pt":1646212931862,"mc":[{"id":"1.195453618","rc":[{"atb":[[3.15,9.87]],"id":39980030}],"con":true,"img":false}]}
{"op":"mcm","clk":"5348040518","pt":1646212932225,"mc":[{"id":"1.195453618","rc":[{"atb":[[2.82,9.28],[2.7,38.1]],"id":40908229}],"con":true,"img":false}]}
{"op":"mcm","clk":"5348040542","pt":1646212932642,"mc":[{"id":"1.195453618","rc":[{"atl":[[3.45,0]],"id":40908229}],"con":true,"img":false}]}
{"op":"mcm","clk":"5348040550","pt":1646212932740,"mc":[{"id":"1.195453618","rc":[{"atl":[[1000,1.42]],"id":40908229}],"con":true,"img":false}]}
{"op":"mcm","clk":"5348040576","pt":1646212933152,"mc":[{"id":"1.195453618","rc":[{"atb":[[2.74,0]],"id":40908229}],"con":true,"img":false}]}
{"op":"mcm","clk":"5348040582","pt":1646212933251,"mc":[{"id":"1.195453618","rc":[{"atb":[[1.02,1.25]],"id":40908229}],"con":true,"img":false}]}
{"op":"mcm","clk":"5348040606","pt":1646212933663,"mc":[{"id":"1.195453618","rc":[{"atb":[[3.05,71.22]],"id":39980030}],"con":true,"img":false}]}
{"op":"mcm","clk":"5348040694","pt":1646212934854,"mc":[{"id":"1.195453618","rc":[{"atb":[[2.92,51.98],[2.88,0],[2.96,0]],"id":39980030}],"con":true,"img":false}]}
{"op":"mcm","clk":"5348041054","pt":1646212942255,"mc":[{"id":"1.195453618","rc":[{"atb":[[2.78,23.73]],"id":40908229}],"con":true,"img":false}]}
{"op":"mcm","clk":"5348041131","pt":1646212943644,"mc":[{"id":"1.195453618","rc":[{"atb":[[2.98,35]],"id":39980030}],"con":true,"img":false}]}
{"op":"mcm","clk":"5348041417","pt":1646212949151,"mc":[{"id":"1.195453618","rc":[{"atl":[[4.1,4.2]],"id":39980030}],"con":true,"img":false}]}
{"op":"mcm","clk":"5348041430","pt":1646212949356,"mc":[{"id":"1.195453618","rc":[{"atl":[[1000,2.25]],"id":39980030}],"con":true,"img":false}]}
{"op":"mcm","clk":"5348041443","pt":1646212949665,"mc":[{"id":"1.195453618","rc":[{"atl":[[1000,2.2]],"id":39980030}],"con":true,"img":false}]}
{"op":"mcm","clk":"5348041451","pt":1646212949779,"mc":[{"id":"1.195453618","rc":[{"atl":[[1000,0]],"id":39980030}],"con":true,"img":false}]}
{"op":"mcm","clk":"5348041460","pt":1646212949875,"mc":[{"id":"1.195453618","rc":[{"atl":[[5,2.2]],"id":39980030}],"con":true,"img":false}]}
{"op":"mcm","clk":"5348041544","pt":1646212951164,"mc":[{"id":"1.195453618","rc":[{"atb":[[2.58,0]],"id":40908229}],"con":true,"img":false}]}
{"op":"mcm","clk":"5348041602","pt":1646212952146,"mc":[{"id":"1.195453618","rc":[{"atl":[[5,0]],"id":39980030}],"con":true,"img":false}]}
{"op":"mcm","clk":"5348041608","pt":1646212952249,"mc":[{"id":"1.195453618","rc":[{"atb":[[2.74,36.42]],"id":40908229}],"con":true,"img":false}]}
{"op":"mcm","clk":"5348041616","pt":1646212952355,"mc":[{"id":"1.195453618","rc":[{"atl":[[4,2.75]],"id":39980030}],"con":true,"img":false}]}
{"op":"mcm","clk":"5348041665","pt":1646212953074,"mc":[{"id":"1.195453618","rc":[{"atb":[[2.62,0]],"id":40908229}],"con":true,"img":false}]}
{"op":"mcm","clk":"5348041668","pt":1646212953178,"mc":[{"id":"1.195453618","rc":[{"atl":[[4.1,2.97]],"id":39980030}],"con":true,"img":false}]}
{"op":"mcm","clk":"5348041672","pt":1646212953280,"mc":[{"id":"1.195453618","rc":[{"atl":[[4,3.97]],"id":39980030}],"con":true,"img":false}]}
{"op":"mcm","clk":"5348041680","pt":1646212953487,"mc":[{"id":"1.195453618","rc":[{"atl":[[5.4,0]],"id":40908229}],"con":true,"img":false}]}
{"op":"mcm","clk":"5348041686","pt":1646212953589,"mc":[{"id":"1.195453618","rc":[{"atl":[[5.6,7.94]],"id":40908229}],"con":true,"img":false}]}
{"op":"mcm","clk":"5348041693","pt":1646212953691,"mc":[{"id":"1.195453618","rc":[{"atb":[[2.94,59.54]],"id":39980030}],"con":true,"img":false}]}
{"op":"mcm","clk":"5348041776","pt":1646212955190,"mc":[{"id":"1.195453618","rc":[{"atl":[[4,1.22]],"id":39980030}],"con":true,"img":false}]}
{"op":"mcm","clk":"5348041782","pt":1646212955292,"mc":[{"id":"1.195453618","rc":[{"atl":[[3.9,2.81]],"id":39980030}],"con":true,"img":false}]}
{"op":"mcm","clk":"5348041832","pt":1646212955960,"mc":[{"id":"1.195453618","rc":[{"atb":[[3.15,8.6]],"id":39980030}],"con":true,"img":false}]}
{"op":"mcm","clk":"5348041835","pt":1646212956061,"mc":[{"id":"1.195453618","rc":[{"atb":[[1.02,1.27]],"id":39980030}],"con":true,"img":false}]}
{"op":"mcm","clk":"5348041905","pt":1646212957397,"mc":[{"id":"1.195453618","rc":[{"atb":[[2.82,3.67]],"id":40908229},{"trd":[[2.82,33.18]],"ltp":2.82,"tv":33.18,"id":40908229}],"con":true,"img":false}]}
{"op":"mcm","clk":"5348041909","pt":1646212957449,"mc":[{"id":"1.195453618","rc":[{"atb":[[2.82,0],[2.74,0],[2.66,0],[2.78,0],[2.76,9.14]],"id":40908229}],"con":true,"img":false}]}
{"op":"mcm","clk":"5348041918","pt":1646212957654,"mc":[{"id":"1.195453618","rc":[{"atl":[[3.35,8.42]],"id":40908229}],"con":true,"img":false}]}
{"op":"mcm","clk":"5348041924","pt":1646212957757,"mc":[{"id":"1.195453618","rc":[{"atl":[[3.35,14.06]],"id":40908229}],"con":true,"img":false}]}
{"op":"mcm","clk":"5348042231","pt":1646212964296,"mc":[{"id":"1.195453618","rc":[{"atb":[[3.2,8.8],[3.7,0]],"id":40812743}],"con":true,"img":false}]}
{"op":"mcm","clk":"5348042357","pt":1646212966782,"mc":[{"id":"1.195453618","rc":[{"spn":2.16,"spf":"NaN","id":39209038},{"spn":7.5,"spf":"NaN","id":40812743},{"spn":3.05,"spf":"NaN","id":40908229},{"atl":[[4.1,0]],"id":39980030},{"spn":3.52,"spf":"NaN","id":39980030}],"con":true,"img":false}]}
{"op":"mcm","clk":"5348042379","pt":1646212967090,"mc":[{"id":"1.195453618","rc":[{"atl":[[5,2.44]],"id":39980030}],"con":true,"img":false}]}
{"op":"mcm","clk":"5348042406","pt":1646212967506,"mc":[{"id":"1.195453618","rc":[{"atb":[[2.72,48.71]],"id":40908229}],"con":true,"img":false}]}
{"op":"mcm","clk":"5348042968","pt":1646212977323,"mc":[{"id":"1.195453618","rc":[{"atl":[[8,3.43],[5.3,0]],"id":39980030}],"con":true,"img":false}]}
{"op":"mcm","clk":"5348042983","pt":1646212977523,"mc":[{"id":"1.195453618","rc":[{"atb":[[2.68,35.89]],"id":40908229}],"con":true,"img":false}]}
{"op":"mcm","clk":"5348042994","pt":1646212977783,"mc":[{"id":"1.195453618","rc":[{"atl":[[1000,2.25]],"id":39980030}],"con":true,"img":false}]}
{"op":"mcm","clk":"5348043153","pt":1646212980991,"mc":[{"id":"1.195453618","rc":[{"atl":[[5,0]],"id":39980030}],"con":true,"img":false}]}
{"op":"mcm","clk":"5348043170","pt":1646212981301,"mc":[{"id":"1.195453618","rc":[{"atl":[[3.85,3.17]],"id":39980030}],"con":true,"img":false}]}
{"op":"mcm","clk":"5348043174","pt":1646212981407,"mc":[{"id":"1.195453618","rc":[{"atl":[[1000,0.15]],"id":39980030}],"con":true,"img":false}]}
{"op":"mcm","clk":"5348043183","pt":1646212981610,"mc":[{"id":"1.195453618","rc":[{"atl":[[4,0]],"id":39980030}],"con":true,"img":false}]}
{"op":"mcm","clk":"5348043192","pt":1646212981717,"mc":[{"id":"1.195453618","rc":[{"atl":[[3.85,4.4]],"id":39980030}],"con":true,"img":false}]}
{"op":"mcm","clk":"5348043270","pt":1646212983318,"mc":[{"id":"1.195453618","rc":[{"atl":[[12,4.55],[13,14.58]],"id":40812743},{"atb":[[1.4,83.52],[1.37,270.28]],"id":42390009},{"atl":[[2.82,0],[2.94,88.96]],"id":42390009},{"atb":[[3.1,20.76],[2.98,85.51]],"id":39980030}],"con":true,"img":false}]}
{"op":"mcm","clk":"5348043491","pt":1646212987293,"mc":[{"id":"1.195453618","rc":[{"atb":[[1.05,1.82]],"id":39980030}],"con":true,"img":false}]}
{"op":"mcm","clk":"5348043499","pt":1646212987500,"mc":[{"id":"1.195453618","rc":[{"atb":[[2.64,61.28]],"id":40908229},{"atb":[[1.05,0.15]],"id":39980030}],"con":true,"img":false}]}
{"op":"mcm","clk":"5348043509","pt":1646212987707,"mc":[{"id":"1.195453618","rc":[{"atb":[[1.05,0]],"id":39980030}],"con":true,"img":false}]}
{"op":"mcm","clk":"5348043514","pt":1646212987810,"mc":[{"id":"1.195453618","rc":[{"atl":[[3.85,4.24]],"id":39980030},{"trd":[[3.85,0.31]],"ltp":3.85,"tv":0.31,"id":39980030}],"con":true,"img":false}]}
{"op":"mcm","clk":"5348043731","pt":1646212991336,"mc":[{"id":"1.195453618","rc":[{"atb":[[1.4,0]],"id":42390009}],"con":true,"img":false}]}
{"op":"mcm","clk":"5348043737","pt":1646212991440,"mc":[{"id":"1.195453618","rc":[{"atb":[[1.38,83.52]],"id":42390009}],"con":true,"img":false}]}
{"op":"mcm","clk":"5348043799","pt":1646212992516,"mc":[{"id":"1.195453618","rc":[{"atb":[[1.43,19.38]],"id":42390009}],"con":true,"img":false}]}
{"op":"mcm","clk":"5348043823","pt":1646212993033,"mc":[{"id":"1.195453618","rc":[{"atl":[[3.85,1.22]],"id":39980030}],"con":true,"img":false}]}
{"op":"mcm","clk":"5348043834","pt":1646212993338,"mc":[{"id":"1.195453618","rc":[{"atl":[[3.75,3.1]],"id":39980030}],"con":true,"img":false}]}
{"op":"mcm","clk":"5348043865","pt":1646212994112,"mc":[{"id":"1.195453618","rc":[{"atl":[[3.85,0]],"id":39980030}],"con":true,"img":false}]}
{"op":"mcm","clk":"5348043870","pt":1646212994218,"mc":[{"id":"1.195453618","rc":[{"atl":[[3.75,4.32]],"id":39980030}],"con":true,"img":false}]}
{"op":"mcm","clk":"5348043882","pt":1646212994525,"mc":[{"id":"1.195453618","rc":[{"atl":[[3.35,10.54]],"id":40908229}],"con":true,"img":false}]}
{"op":"mcm","clk":"5348043888","pt":1646212994628,"mc":[{"id":"1.195453618","rc":[{"atl":[[3.6,3.27]],"id":40908229}],"con":true,"img":false}]}
{"op":"mcm","clk":"5348043958","pt":1646212995801,"mc":[{"id":"1.195453618","rc":[{"atl":[[8,0]],"id":39980030}],"con":true,"img":false}]}
{"op":"mcm","clk":"5348043962","pt":1646212995906,"mc":[{"id":"1.195453618","rc":[{"atl":[[7.8,3.43]],"id":39980030}],"con":true,"img":false}]}
{"op":"mcm","clk":"5348044038","pt":1646212997512,"mc":[{"id":"1.195453618","rc":[{"atb":[[1.41,18.33]],"id":42390009}],"con":true,"img":false}]}
{"op":"mcm","clk":"5348044040","pt":1646212997614,"mc":[{"id":"1.195453618","rc":[{"atl":[[3.6,0]],"id":40908229}],"con":true,"img":false}]}
{"op":"mcm","clk":"5348044044","pt":1646212997717,"mc":[{"id":"1.195453618","rc":[{"atl":[[3.3,3.57]],"id":40908229}],"con":true,"img":false}]}
{"op":"mcm","clk":"5348044071","pt":1646212998538,"mc":[{"id":"1.195453618","rc":[{"atl":[[3.35,9.54]],"id":40908229}],"con":true,"img":false}]}
{"op":"mcm","clk":"5348044078","pt":1646212998642,"mc":[{"id":"1.195453618","rc":[{"atl":[[3.3,4.58]],"id":40908229}],"con":true,"img":false}]}
{"op":"mcm","clk":"5348044163","pt":1646213000602,"mc":[{"id":"1.195453618","rc":[{"atl":[[3.3,1]],"id":40908229}],"con":true,"img":false}]}
{"op":"mcm","clk":"5348044167","pt":1646213000706,"mc":[{"id":"1.195453618","rc":[{"atl":[[3.2,3.69]],"id":40908229}],"con":true,"img":false}]}
{"op":"mcm","clk":"5348044171","pt":1646213000809,"mc":[{"id":"1.195453618","rc":[{"atl":[[3.35,3.9],[3.3,6.73]],"id":40908229}],"con":true,"img":false}]}
{"op":"mcm","clk":"5348044184","pt":1646213001118,"mc":[{"id":"1.195453618","rc":[{"atl":[[3.3,5.73]],"id":40908229}],"con":true,"img":false}]}
{"op":"mcm","clk":"5348044189","pt":1646213001220,"mc":[{"id":"1.195453618","rc":[{"atl":[[3.2,4.7]],"id":40908229}],"con":true,"img":false}]}
{"op":"mcm","clk":"5348044329","pt":1646213003544,"mc":[{"id":"1.195453618","rc":[{"atl":[[3.2,1]],"id":40908229}],"con":true,"img":false}]}
{"op":"mcm","clk":"5348044339","pt":1646213003749,"mc":[{"id":"1.195453618","rc":[{"atl":[[3.15,3.75]],"id":40908229}],"con":true,"img":false}]}
{"op":"mcm","clk":"5348044342","pt":1646213003855,"mc":[{"id":"1.195453618","rc":[{"atl":[[3.2,0]],"id":40908229}],"con":true,"img":false}]}
{"op":"mcm","clk":"5348044348","pt":1646213003907,"mc":[{"id":"1.195453618","rc":[{"atl":[[3.25,1]],"id":40908229}],"con":true,"img":false}]}
{"op":"mcm","clk":"5348044395","pt":1646213004735,"mc":[{"id":"1.195453618","rc":[{"atl":[[3.25,0]],"id":40908229}],"con":true,"img":false}]}
{"op":"mcm","clk":"5348044400","pt":1646213004838,"mc":[{"id":"1.195453618","rc":[{"atl":[[3.15,4.76]],"id":40908229}],"con":true,"img":false}]}
{"op":"mcm","clk":"5348044532","pt":1646213007326,"mc":[{"id":"1.195453618","rc":[{"atl":[[3.35,0]],"id":40908229}],"con":true,"img":false}]}
{"op":"mcm","clk":"5348044551","pt":1646213007637,"mc":[{"id":"1.195453618","rc":[{"atb":[[1.43,0]],"id":42390009}],"con":true,"img":false}]}
{"op":"mcm","clk":"5348044569","pt":1646213007948,"mc":[{"id":"1.195453618","rc":[{"atl":[[3.15,8.91]],"id":40908229}],"con":true,"img":false}]}
{"op":"mcm","clk":"5348044592","pt":1646213008311,"mc":[{"id":"1.195453618","rc":[{"atb":[[1.44,0]],"id":42390009}],"con":true,"img":false}]}
{"op":"mcm","clk":"5348044599","pt":1646213008415,"mc":[{"id":"1.195453618","rc":[{"atb":[[1.42,2.8]],"id":42390009}],"con":true,"img":false}]}
{"op":"mcm","clk":"5348044609","pt":1646213008619,"mc":[{"id":"1.195453618","rc":[{"atb":[[3.15,12.47]],"id":39980030}],"con":true,"img":false}]}
{"op":"mcm","clk":"5348045342","pt":1646213020438,"mc":[{"id":"1.195453618","rc":[{"atb":[[1.41,38.67]],"id":42390009}],"con":true,"img":false}]}
{"op":"mcm","clk":"5348045370","pt":1646213020844,"mc":[{"id":"1.195453618","rc":[{"atl":[[5.3,5.17],[7.8,0]],"id":39980030}],"con":true,"img":false}]}
{"op":"mcm","clk":"5348045768","pt":1646213028350,"mc":[{"id":"1.195453618","rc":[{"atl":[[3.1,0]],"id":39209038},{"spn":2.95,"spf":"NaN","id":40908229},{"spn":1.76,"spf":"NaN","id":42390009},{"spn":3.45,"spf":"NaN","id":39980030}],"con":true,"img":false}]}
{"op":"mcm","clk":"5348045774","pt":1646213028453,"mc":[{"id":"1.195453618","rc":[{"atl":[[2.84,23.69]],"id":39209038}],"con":true,"img":false}]}
{"op":"mcm","clk":"5348047128","pt":1646213051204,"mc":[{"id":"1.195453618","rc":[{"atb":[[2.82,8.83],[2.76,0]],"id":40908229}],"con":true,"img":false}]}
{"op":"mcm","clk":"5348047612","pt":1646213061184,"mc":[{"id":"1.195453618","rc":[{"atb":[[2.78,22.58]],"id":40908229}],"con":true,"img":false}]}
{"op":"mcm","clk":"5348048182","pt":1646213071209,"mc":[{"id":"1.195453618","rc":[{"atb":[[2.72,25.34],[2.74,34.65],[2.64,0],[2.68,0]],"id":40908229}],"con":true,"img":false}]}
{"op":"mcm","clk":"5348048570","pt":1646213077724,"mc":[{"id":"1.195453618","rc":[{"atb":[[2.98,35],[3.05,120]],"id":39980030}],"con":true,"img":false}]}
{"op":"mcm","clk":"5348048763","pt":1646213081241,"mc":[{"id":"1.195453618","rc":[{"atb":[[2.7,97.21]],"id":40908229}],"con":true,"img":false}]}
{"op":"mcm","clk":"5348049146","pt":1646213087736,"mc":[{"id":"1.195453618","rc":[{"atl":[[3.9,0]],"id":39980030}],"con":true,"img":false}]}
{"op":"mcm","clk":"5348049165","pt":1646213087940,"mc":[{"id":"1.195453618","rc":[{"atl":[[1000,2.4]],"id":39980030}],"con":true,"img":false}]}
{"op":"mcm","clk":"5348049176","pt":1646213088240,"mc":[{"id":"1.195453618","rc":[{"atl":[[1000,2.34]],"id":39980030}],"con":true,"img":false}]}
{"op":"mcm","clk":"5348049184","pt":1646213088448,"mc":[{"id":"1.195453618","rc":[{"spn":2.98,"spf":"NaN","id":40908229},{"atl":[[1000,0.15]],"id":39980030}],"con":true,"img":false}]}
{"op":"mcm","clk":"5348049188","pt":1646213088549,"mc":[{"id":"1.195453618","rc":[{"atl":[[5,2.19]],"id":39980030}],"con":true,"img":false}]}
{"op":"mcm","clk":"5348049225","pt":1646213089526,"mc":[{"id":"1.195453618","rc":[{"atl":[[3.75,3.1]],"id":39980030}],"con":true,"img":false}]}
{"op":"mcm","clk":"5348049230","pt":1646213089631,"mc":[{"id":"1.195453618","rc":[{"atl":[[5.2,1.22]],"id":39980030}],"con":true,"img":false}]}
{"op":"mcm","clk":"5348049282","pt":1646213090712,"mc":[{"id":"1.195453618","rc":[{"atl":[[5,0]],"id":39980030}],"con":true,"img":false}]}
{"op":"mcm","clk":"5348049285","pt":1646213090820,"mc":[{"id":"1.195453618","rc":[{"atl":[[3.7,2.96]],"id":39980030}],"con":true,"img":false}]}
{"op":"mcm","clk":"5348049312","pt":1646213091336,"mc":[{"id":"1.195453618","rc":[{"atb":[[2.72,0]],"id":40908229},{"atl":[[5.2,0]],"id":39980030}],"con":true,"img":false}]}
{"op":"mcm","clk":"5348049317","pt":1646213091439,"mc":[{"id":"1.195453618","rc":[{"atb":[[2.76,25.34]],"id":40908229},{"atl":[[3.7,4.19]],"id":39980030}],"con":true,"img":false}]}
{"op":"mcm","clk":"5348049442","pt":1646213093722,"mc":[{"id":"1.195453618","rc":[{"atl":[[3.7,1.22]],"id":39980030}],"con":true,"img":false}]}
{"op":"mcm","clk":"5348049447","pt":1646213093826,"mc":[{"id":"1.195453618","rc":[{"atl":[[3.6,3.05]],"id":39980030}],"con":true,"img":false}]}
{"op":"mcm","clk":"5348049454","pt":1646213094031,"mc":[{"id":"1.195453618","rc":[{"atl":[[3.7,0]],"id":39980030}],"con":true,"img":false}]}
{"op":"mcm","clk":"5348049458","pt":1646213094132,"mc":[{"id":"1.195453618","rc":[{"atl":[[5.2,1.22]],"id":39980030}],"con":true,"img":false}]}
{"op":"mcm","clk":"5348049499","pt":1646213094953,"mc":[{"id":"1.195453618","rc":[{"atl":[[5.2,0]],"id":39980030}],"con":true,"img":false}]}
{"op":"mcm","clk":"5348049504","pt":1646213095059,"mc":[{"id":"1.195453618","rc":[{"atl":[[3.6,4.27]],"id":39980030}],"con":true,"img":false}]}
{"op":"mcm","clk":"5348049695","pt":1646213098335,"mc":[{"id":"1.195453618","rc":[{"atl":[[8,3.43],[5.3,0]],"id":39980030}],"con":true,"img":false}]}
{"op":"mcm","clk":"5348050783","pt":1646213117778,"mc":[{"id":"1.195453618","rc":[{"atl":[[8,0],[5.3,5.17]],"id":39980030}],"con":true,"img":false}]}
{"op":"mcm","clk":"5348056144","pt":1646213214174,"mc":[{"id":"1.195453618","rc":[{"atl":[[3.75,0]],"id":39980030},{"spn":3.37,"spf":"NaN","id":39980030}],"con":true,"img":false}]}
{"op":"mcm","clk":"5348056156","pt":1646213214382,"mc":[{"id":"1.195453618","rc":[{"atl":[[5,2.32]],"id":39980030}],"con":true,"img":false}]}
{"op":"mcm","clk":"5348056196","pt":1646213215006,"mc":[{"id":"1.195453618","rc":[{"atl":[[3.6,3.05]],"id":39980030}],"con":true,"img":false}]}
{"op":"mcm","clk":"5348056201","pt":1646213215114,"mc":[{"id":"1.195453618","rc":[{"atl":[[5.2,1.22]],"id":39980030}],"con":true,"img":false}]}
{"op":"mcm","clk":"5348056526","pt":1646213221197,"mc":[{"id":"1.195453618","rc":[{"atb":[[1.37,0],[1.33,0],[1.39,0],[1.35,0]],"id":42390009},{"atl":[[2.22,0],[2.12,1.34],[2.18,0],[2.26,0],[2.94,37.41]],"id":42390009}],"con":true,"img":false}]}
{"op":"mcm","clk":"5348056547","pt":1646213221611,"mc":[{"id":"1.195453618","rc":[{"atb":[[1.56,0],[1.67,1.57],[1.54,0],[1.5,0],[1.52,0]],"id":39209038},{"atl":[[3.85,0],[3.55,0],[3.65,0],[3.75,0]],"id":39209038},{"atb":[[1.63,0],[1.37,0],[1.67,0],[1.65,153.56],[1.69,0]],"id":43167174},{"atl":[[2.74,0],[2.66,0],[3.25,0],[2.62,0],[2.7,0]],"id":43167174},{"atb":[[1.18,0],[1.12,0],[1.16,0],[1.14,0],[1.08,0]],"id":43167175},{"atl":[[3.45,0],[3.35,0],[4.9,0],[3.25,0.15],[3.55,0]],"id":43167175}],"con":true,"img":false}]}
{"op":"mcm","clk":"5348056556","pt":1646213221817,"mc":[{"id":"1.195453618","rc":[{"atl":[[3.8,0]],"id":39209038},{"atb":[[1.41,0],[1.45,0],[1.43,0],[1.39,0],[1.35,0]],"id":40812743},{"atl":[[11,0],[12,0],[13,0],[14,0]],"id":40812743},{"atb":[[2.82,0],[2.74,0],[2.32,0],[2.78,0],[2.7,38.1]],"id":40908229},{"atl":[[5.8,0],[5.3,0],[5.1,0],[5.5,0],[5.7,0]],"id":40908229},{"atb":[[1.36,0],[1.38,0]],"id":42390009},{"atb":[[3.15,3.87],[2.98,0],[2.94,0],[3.05,48.68]],"id":39980030},{"atl":[[9,0],[10.5,7.64],[9.4,0],[16.5,0],[9.8,0]],"id":39980030}],"con":true,"img":false}]}
{"op":"mcm","clk":"5348056564","pt":1646213221925,"mc":[{"id":"1.195453618","rc":[{"atl":[[4.3,14.46]],"id":39209038},{"atl":[[2.6,0.15]],"id":43167174},{"atb":[[1.37,0],[1.33,0],[1.13,0],[1.39,0],[1.35,285.18]],"id":42300273},{"atl":[[5.6,0],[5,0],[5.2,0],[5.4,0]],"id":42300273},{"atl":[[3.2,0]],"id":43167175},{"atb":[[1.36,83.52],[1.31,114.56]],"id":42390009},{"atl":[[2.12,0]],"id":42390009}],"con":true,"img":false}]}
{"op":"mcm","clk":"5348056569","pt":1646213222027,"mc":[{"id":"1.195453618","rc":[{"atl":[[3.15,1.42]],"id":43167174},{"atl":[[3.95,1.4]],"id":43167175},{"atl":[[2.52,1.34]],"id":42390009}],"con":true,"img":false}]}
{"op":"mcm","clk":"5348056577","pt":1646213222130,"mc":[{"id":"1.195453618","rc":[{"atb":[[1.68,0]],"id":39209038},{"atl":[[2.1,0]],"id":42390009}],"con":true,"img":false}]}
{"op":"mcm","clk":"5348056582","pt":1646213222186,"mc":[{"id":"1.195453618","rc":[{"atb":[[1.67,2.85]],"id":39209038},{"atl":[[2.52,1.49]],"id":42390009}],"con":true,"img":false}]}
{"op":"mcm","clk":"5348056586","pt":1646213222288,"mc":[{"id":"1.195453618","rc":[{"atl":[[12.5,0]],"id":40812743},{"atb":[[1.38,82.9]],"id":42300273},{"atl":[[5.6,0],[6.6,12.99]],"id":40908229}],"con":true,"img":false}]}
{"op":"mcm","clk":"5348056591","pt":1646213222391,"mc":[{"id":"1.195453618","rc":[{"atl":[[10.5,5.44],[14.5,3.55]],"id":40812743},{"atl":[[2.6,0]],"id":43167174},{"atb":[[1.36,94.89]],"id":42300273},{"atl":[[3.25,0]],"id":43167175}],"con":true,"img":false}]}
{"op":"mcm","clk":"5348056597","pt":1646213222496,"mc":[{"id":"1.195453618","rc":[{"atl":[[10.5,3.99],[990,0.15]],"id":40812743},{"atl":[[3.15,1.57]],"id":43167174},{"atl":[[3.95,1.55]],"id":43167175}],"con":true,"img":false}]}
{"op":"mcm","clk":"5348056605","pt":1646213222599,"mc":[{"id":"1.195453618","rc":[{"atl":[[1000,1.45]],"id":40812743}],"con":true,"img":false}]}
{"op":"mcm","clk":"5348056624","pt":1646213223008,"mc":[{"id":"1.195453618","rc":[{"atb":[[1.41,20.33]],"id":42390009}],"con":true,"img":false}]}
{"op":"mcm","clk":"5348056842","pt":1646213226596,"mc":[{"id":"1.195453618","rc":[{"atl":[[5,0]],"id":39980030}],"con":true,"img":false}]}
{"op":"mcm","clk":"5348056864","pt":1646213226907,"mc":[{"id":"1.195453618","rc":[{"atl":[[3.55,3.27]],"id":39980030}],"con":true,"img":false}]}
{"op":"mcm","clk":"5348056903","pt":1646213227527,"mc":[{"id":"1.195453618","rc":[{"atl":[[5.2,0]],"id":39980030}],"con":true,"img":false}]}
{"op":"mcm","clk":"5348056908","pt":1646213227578,"mc":[{"id":"1.195453618","rc":[{"atl":[[3.55,4.5]],"id":39980030}],"con":true,"img":false}]}
{"op":"mcm","clk":"5348056979","pt":1646213229097,"mc":[{"id":"1.195453618","rc":[{"atb":[[1.39,19.27]],"id":42390009}],"con":true,"img":false}]}
{"op":"mcm","clk":"5348056987","pt":1646213229303,"mc":[{"id":"1.195453618","rc":[{"atl":[[3.45,17.79],[3.2,0]],"id":43167174}],"con":true,"img":false}]}
{"op":"mcm","clk":"5348056991","pt":1646213229407,"mc":[{"id":"1.195453618","rc":[{"atb":[[2.76,0]],"id":40908229}],"con":true,"img":false}]}
{"op":"mcm","clk":"5348056994","pt":1646213229511,"mc":[{"id":"1.195453618","rc":[{"atb":[[2.72,25.34]],"id":40908229}],"con":true,"img":false}]}
{"op":"mcm","clk":"5348057000","pt":1646213229614,"mc":[{"id":"1.195453618","rc":[{"atl":[[3.15,1.42]],"id":43167174}],"con":true,"img":false}]}
{"op":"mcm","clk":"5348057006","pt":1646213229722,"mc":[{"id":"1.195453618","rc":[{"atl":[[3.4,0.15]],"id":43167174}],"con":true,"img":false}]}
{"op":"mcm","clk":"5348057013","pt":1646213229824,"mc":[{"id":"1.195453618","rc":[{"atl":[[3.15,0]],"id":43167174}],"con":true,"img":false}]}
{"op":"mcm","clk":"5348057016","pt":1646213229927,"mc":[{"id":"1.195453618","rc":[{"atl":[[3.4,1.57]],"id":43167174}],"con":true,"img":false}]}
{"op":"mcm","clk":"5348057243","pt":1646213234321,"mc":[{"id":"1.195453618","rc":[{"atl":[[5.3,0]],"id":39980030}],"con":true,"img":false}]}
{"op":"mcm","clk":"5348057248","pt":1646213234425,"mc":[{"id":"1.195453618","rc":[{"atl":[[5.4,5.17]],"id":39980030}],"con":true,"img":false}]}
{"op":"mcm","clk":"5348057454","pt":1646213238412,"mc":[{"id":"1.195453618","rc":[{"atl":[[3.55,1.22]],"id":39980030}],"con":true,"img":false}]}
{"op":"mcm","clk":"5348057476","pt":1646213238924,"mc":[{"id":"1.195453618","rc":[{"atb":[[1.41,0]],"id":42390009}],"con":true,"img":false}]}
{"op":"mcm","clk":"5348057481","pt":1646213239132,"mc":[{"id":"1.195453618","rc":[{"atl":[[3.55,0]],"id":39980030}],"con":true,"img":false}]}
{"op":"mcm","clk":"5348057486","pt":1646213239235,"mc":[{"id":"1.195453618","rc":[{"atl":[[5.3,1.22]],"id":39980030}],"con":true,"img":false}]}
{"op":"mcm","clk":"5348057510","pt":1646213239652,"mc":[{"id":"1.195453618","rc":[{"atl":[[3.45,3.36]],"id":39980030}],"con":true,"img":false}]}
{"op":"mcm","clk":"5348057528","pt":1646213240020,"mc":[{"id":"1.195453618","rc":[{"atb":[[1.42,1.24]],"id":42390009},{"atl":[[5.3,0]],"id":39980030}],"con":true,"img":false}]}
{"op":"mcm","clk":"5348057531","pt":1646213240123,"mc":[{"id":"1.195453618","rc":[{"atb":[[1.4,1.55]],"id":42390009},{"atl":[[3.45,4.59]],"id":39980030}],"con":true,"img":false}]}
{"op":"mcm","clk":"5348057536","pt":1646213240240,"mc":[{"id":"1.195453618","rc":[{"atb":[[1.42,0]],"id":42390009}],"con":true,"img":false}]}
{"op":"mcm","clk":"5348057539","pt":1646213240338,"mc":[{"id":"1.195453618","rc":[{"atb":[[1.4,2.8]],"id":42390009}],"con":true,"img":false}]}
{"op":"mcm","clk":"5348057565","pt":1646213240852,"mc":[{"id":"1.195453618","rc":[{"atl":[[4.5,0]],"id":43167175}],"con":true,"img":false}]}
{"op":"mcm","clk":"5348057570","pt":1646213240908,"mc":[{"id":"1.195453618","rc":[{"atl":[[4.4,12.45]],"id":43167175}],"con":true,"img":false}]}
{"op":"mcm","clk":"5348057597","pt":1646213241321,"mc":[{"id":"1.195453618","rc":[{"atl":[[2.68,0]],"id":42390009}],"con":true,"img":false}]}
{"op":"mcm","clk":"5348057602","pt":1646213241423,"mc":[{"id":"1.195453618","rc":[{"atl":[[2.52,26.83]],"id":42390009}],"con":true,"img":false}]}
{"op":"mcm","clk":"5348057652","pt":1646213242350,"mc":[{"id":"1.195453618","rc":[{"atl":[[12.5,0]],"id":39980030}],"con":true,"img":false}]}
{"op":"mcm","clk":"5348057658","pt":1646213242456,"mc":[{"id":"1.195453618","rc":[{"atl":[[13.5,2.72]],"id":39980030}],"con":true,"img":false}]}
{"op":"mcm","clk":"5348057738","pt":1646213244333,"mc":[{"id":"1.195453618","rc":[{"atl":[[2.78,0]],"id":42300273}],"con":true,"img":false}]}
{"op":"mcm","clk":"5348057742","pt":1646213244428,"mc":[{"id":"1.195453618","rc":[{"atl":[[2.58,26]],"id":42300273}],"con":true,"img":false}]}
{"op":"mcm","clk":"5348057838","pt":1646213246332,"mc":[{"id":"1.195453618","rc":[{"atl":[[3.75,0]],"id":40908229}],"con":true,"img":false}]}
{"op":"mcm","clk":"5348057844","pt":1646213246435,"mc":[{"id":"1.195453618","rc":[{"atl":[[3.7,8.71]],"id":40908229}],"con":true,"img":false}]}
{"op":"mcm","clk":"5348058093","pt":1646213251340,"mc":[{"id":"1.195453618","rc":[{"atl":[[5.4,0]],"id":39980030}],"con":true,"img":false}]}
{"op":"mcm","clk":"5348058099","pt":1646213251441,"mc":[{"id":"1.195453618","rc":[{"atl":[[5.5,5.17]],"id":39980030}],"con":true,"img":false}]}
{"op":"mcm","clk":"5348058116","pt":1646213251864,"mc":[{"id":"1.195453618","rc":[{"atl":[[14.5,0],[15.5,5.31]],"id":40812743}],"con":true,"img":false}]}
{"op":"mcm","clk":"5348058232","pt":1646213253834,"mc":[{"id":"1.195453618","rc":[{"atb":[[1.39,40.65]],"id":42390009}],"con":true,"img":false}]}
{"op":"mcm","clk":"5348058587","pt":1646213261761,"mc":[{"id":"1.195453618","rc":[{"atl":[[4.4,0]],"id":43167175}],"con":true,"img":false}]}
{"op":"mcm","clk":"5348058590","pt":1646213261862,"mc":[{"id":"1.195453618","rc":[{"atl":[[4.3,12.45]],"id":43167175}],"con":true,"img":false}]}
{"op":"mcm","clk":"5348058725","pt":1646213264345,"mc":[{"id":"1.195453618","rc":[{"atb":[[2.72,0]],"id":40908229}],"con":true,"img":false}]}
{"op":"mcm","clk":"5348058730","pt":1646213264448,"mc":[{"id":"1.195453618","rc":[{"atb":[[2.62,25.34]],"id":40908229}],"con":true,"img":false}]}
{"op":"mcm","clk":"5348058817","pt":1646213265747,"mc":[{"id":"1.195453618","rc":[{"atl":[[13.5,0]],"id":39980030}],"con":true,"img":false}]}
{"op":"mcm","clk":"5348058822","pt":1646213265851,"mc":[{"id":"1.195453618","rc":[{"atl":[[14.5,2.72]],"id":39980030}],"con":true,"img":false}]}
{"op":"mcm","clk":"5348058840","pt":1646213266263,"mc":[{"id":"1.195453618","rc":[{"atl":[[3.7,0]],"id":40908229}],"con":true,"img":false}]}
{"op":"mcm","clk":"5348058844","pt":1646213266365,"mc":[{"id":"1.195453618","rc":[{"atb":[[3.2,0],[3.7,7.17]],"id":40812743},{"atl":[[3.65,8.71]],"id":40908229}],"con":true,"img":false}]}
{"op":"mcm","clk":"5348058859","pt":1646213266781,"mc":[{"id":"1.195453618","rc":[{"atl":[[5.5,0]],"id":39980030}],"con":true,"img":false}]}
{"op":"mcm","clk":"5348058862","pt":1646213266834,"mc":[{"id":"1.195453618","rc":[{"atl":[[5.6,5.17]],"id":39980030}],"con":true,"img":false}]}
{"op":"mcm","clk":"5348059060","pt":1646213271251,"mc":[{"id":"1.195453618","rc":[{"atl":[[3.4,14.79]],"id":42390009}],"con":true,"img":false}]}
{"op":"mcm","clk":"5348059063","pt":1646213271355,"mc":[{"id":"1.195453618","rc":[{"atl":[[2.92,0]],"id":42390009}],"con":true,"img":false}]}
{"op":"mcm","clk":"5348059158","pt":1646213272849,"mc":[{"id":"1.195453618","rc":[{"atl":[[15.5,2.5]],"id":40812743}],"con":true,"img":false}]}
{"op":"mcm","clk":"5348059163","pt":1646213272952,"mc":[{"id":"1.195453618","rc":[{"atl":[[16.5,2.81]],"id":40812743}],"con":true,"img":false}]}
{"op":"mcm","clk":"5348059559","pt":1646213281764,"mc":[{"id":"1.195453618","rc":[{"spn":2.15,"spf":"NaN","id":39209038},{"spn":2.6,"spf":"NaN","id":43167174},{"spn":2.95,"spf":"NaN","id":43167175},{"spn":2.92,"spf":"NaN","id":40908229},{"spn":1.96,"spf":"NaN","id":42390009},{"atl":[[5.6,0],[5.7,4.81]],"id":39980030},{"spn":3.3,"spf":"NaN","id":39980030}],"con":true,"img":false}]}
{"op":"mcm","clk":"5348059621","pt":1646213282793,"mc":[{"id":"1.195453618","rc":[{"atl":[[4.3,0]],"id":43167175}],"con":true,"img":false}]}
{"op":"mcm","clk":"5348059628","pt":1646213282897,"mc":[{"id":"1.195453618","rc":[{"atl":[[4.2,12.45]],"id":43167175}],"con":true,"img":false}]}
{"op":"mcm","clk":"5348059730","pt":1646213284759,"mc":[{"id":"1.195453618","rc":[{"atl":[[3.65,0]],"id":40908229}],"con":true,"img":false}]}
{"op":"mcm","clk":"5348059736","pt":1646213284863,"mc":[{"id":"1.195453618","rc":[{"atl":[[3.6,8.71]],"id":40908229}],"con":true,"img":false}]}
{"op":"mcm","clk":"5348059978","pt":1646213289764,"mc":[{"id":"1.195453618","rc":[{"atb":[[1.56,35.71],[1.54,92.59],[1.5,250],[1.52,144.23]],"id":39209038},{"atl":[[2.82,10.99],[2.86,65.9],[2.9,39.47],[2.94,64.43]],"id":39209038}],"con":true,"img":false}]}
{"op":"mcm","clk":"5348059997","pt":1646213290281,"mc":[{"id":"1.195453618","rc":[{"atl":[[14.5,0]],"id":39980030}],"con":true,"img":false}]}
{"op":"mcm","clk":"5348060000","pt":1646213290386,"mc":[{"id":"1.195453618","rc":[{"atl":[[15,2.72]],"id":39980030}],"con":true,"img":false}]}
{"op":"mcm","clk":"5348060052","pt":1646213291469,"mc":[{"id":"1.195453618","rc":[{"atb":[[2.92,88.08],[2.88,61.44],[3,9.24],[2.96,23.57]],"id":39980030},{"atl":[[9.6,8.72],[9.2,6.1],[10,13.89],[8.8,2.56]],"id":39980030}],"con":true,"img":false}]}
{"op":"mcm","clk":"5348060073","pt":1646213292194,"mc":[{"id":"1.195453618","rc":[{"atb":[[1.37,135.14],[1.33,250],[1.39,51.28],[1.35,499.47]],"id":42300273},{"atl":[[2.24,100.81],[2.12,17.86],[2.2,62.5],[2.16,43.1]],"id":42300273}],"con":true,"img":false}]}
{"op":"mcm","clk":"5348060103","pt":1646213292811,"mc":[{"id":"1.195453618","rc":[{"atl":[[2.58,25.85]],"id":42300273}],"con":true,"img":false}]}
{"op":"mcm","clk":"5348060107","pt":1646213292911,"mc":[{"id":"1.195453618","rc":[{"atl":[[2.1,0.15]],"id":42300273}],"con":true,"img":false}]}
{"op":"mcm","clk":"5348060115","pt":1646213292965,"mc":[{"id":"1.195453618","rc":[{"atl":[[2.58,24.49]],"id":42300273}],"con":true,"img":false}]}
{"op":"mcm","clk":"5348060121","pt":1646213293072,"mc":[{"id":"1.195453618","rc":[{"atl":[[2.1,1.51]],"id":42300273}],"con":true,"img":false}]}
{"op":"mcm","clk":"5348060134","pt":1646213293274,"mc":[{"id":"1.195453618","rc":[{"atl":[[3.6,0]],"id":40908229}],"con":true,"img":false}]}
{"op":"mcm","clk":"5348060141","pt":1646213293383,"mc":[{"id":"1.195453618","rc":[{"atl":[[3.7,8.71]],"id":40908229}],"con":true,"img":false}]}
{"op":"mcm","clk":"5348060164","pt":1646213293895,"mc":[{"id":"1.195453618","rc":[{"atl":[[4.2,0]],"id":43167175}],"con":true,"img":false}]}
{"op":"mcm","clk":"5348060166","pt":1646213293997,"mc":[{"id":"1.195453618","rc":[{"atl":[[4.9,12.45]],"id":43167175}],"con":true,"img":false}]}
{"op":"mcm","clk":"5348060313","pt":1646213297285,"mc":[{"id":"1.195453618","rc":[{"atl":[[3.45,0]],"id":43167174}],"con":true,"img":false}]}
{"op":"mcm","clk":"5348060318","pt":1646213297385,"mc":[{"id":"1.195453618","rc":[{"atl":[[3.95,17.79]],"id":43167174}],"con":true,"img":false}]}
{"op":"mcm","clk":"5348060344","pt":1646213297793,"mc":[{"id":"1.195453618","rc":[{"atl":[[3.4,0.15]],"id":43167174}],"con":true,"img":false}]}
{"op":"mcm","clk":"5348060352","pt":1646213297900,"mc":[{"id":"1.195453618","rc":[{"atl":[[3.45,1.42],[3.4,0]],"id":43167174}],"con":true,"img":false}]}
{"op":"mcm","clk":"5348060356","pt":1646213298002,"mc":[{"id":"1.195453618","rc":[{"atl":[[3.45,1.57]],"id":43167174}],"con":true,"img":false}]}
{"op":"mcm","clk":"5348060457","pt":1646213299807,"mc":[{"id":"1.195453618","rc":[{"atl":[[10.5,1.26],[15,2.17]],"id":40812743},{"atl":[[2.52,1.49]],"id":42390009}],"con":true,"img":false}]}
{"op":"mcm","clk":"5348060458","pt":1646213299903,"mc":[{"id":"1.195453618","rc":[{"atl":[[2.72,25.34]],"id":42390009}],"con":true,"img":false}]}
{"op":"mcm","clk":"5348060480","pt":1646213300627,"mc":[{"id":"1.195453618","rc":[{"atl":[[10.5,0]],"id":40812743}],"con":true,"img":false}]}
{"op":"mcm","clk":"5348060487","pt":1646213300687,"mc":[{"id":"1.195453618","rc":[{"atl":[[15,3.44]],"id":40812743}],"con":true,"img":false}]}
{"op":"mcm","clk":"5348060506","pt":1646213301303,"mc":[{"id":"1.195453618","rc":[{"atl":[[1000,0]],"id":40812743}],"con":true,"img":false}]}
{"op":"mcm","clk":"5348060511","pt":1646213301403,"mc":[{"id":"1.195453618","rc":[{"atl":[[14.5,1.45]],"id":40812743}],"con":true,"img":false}]}
{"op":"mcm","clk":"5348060515","pt":1646213301507,"mc":[{"id":"1.195453618","rc":[{"atb":[[3,0],[3.15,12.47]],"id":39980030}],"con":true,"img":false}]}
{"op":"mcm","clk":"5348060564","pt":1646213302195,"mc":[{"id":"1.195453618","rc":[{"atb":[[1.63,198.41],[1.67,74.63],[1.65,268.94],[1.69,28.99]],"id":43167174},{"atl":[[2.74,43.1],[2.66,12.05],[2.78,70.22],[2.7,29.41]],"id":43167174},{"atl":[[2.12,0],[2.14,17.54]],"id":42300273}],"con":true,"img":false}]}
{"op":"mcm","clk":"5348060581","pt":1646213302401,"mc":[{"id":"1.195453618","rc":[{"atl":[[15,2.17]],"id":40812743},{"atl":[[3.45,1.42]],"id":43167174},{"atl":[[2.1,1.36]],"id":42300273}],"con":true,"img":false}]}
{"op":"mcm","clk":"5348060584","pt":1646213302498,"mc":[{"id":"1.195453618","rc":[{"atl":[[14.5,2.71]],"id":40812743},{"atl":[[2.64,0.15]],"id":43167174},{"atl":[[2.12,0.15]],"id":42300273}],"con":true,"img":false}]}
{"op":"mcm","clk":"5348060596","pt":1646213302610,"mc":[{"id":"1.195453618","rc":[{"atl":[[3.45,0]],"id":43167174},{"atl":[[2.1,0]],"id":42300273}],"con":true,"img":false}]}
{"op":"mcm","clk":"5348060602","pt":1646213302716,"mc":[{"id":"1.195453618","rc":[{"atl":[[2.64,1.57]],"id":43167174},{"atl":[[2.12,1.51]],"id":42300273}],"con":true,"img":false}]}
{"op":"mcm","clk":"5348060629","pt":1646213303131,"mc":[{"id":"1.195453618","rc":[{"atl":[[14.5,1.26]],"id":40812743}],"con":true,"img":false}]}
{"op":"mcm","clk":"5348060634","pt":1646213303235,"mc":[{"id":"1.195453618","rc":[{"atl":[[1000,1.45]],"id":40812743}],"con":true,"img":false}]}
{"op":"mcm","clk":"5348060831","pt":1646213307114,"mc":[{"id":"1.195453618","rc":[{"atl":[[2.66,0],[2.7,11.76]],"id":43167174},{"atl":[[2.14,0],[2.16,17.24]],"id":42300273}],"con":true,"img":false}]}
{"op":"mcm","clk":"5348060841","pt":1646213307318,"mc":[{"id":"1.195453618","rc":[{"atl":[[16.5,0]],"id":40812743},{"atl":[[2.64,0.15]],"id":43167174},{"atl":[[2.12,0.15]],"id":42300273}],"con":true,"img":false}]}
{"op":"mcm","clk":"5348060845","pt":1646213307417,"mc":[{"id":"1.195453618","rc":[{"atl":[[18,2.81]],"id":40812743},{"atl":[[2.68,1.42]],"id":43167174},{"atl":[[2.14,1.36]],"id":42300273}],"con":true,"img":false}]}
{"op":"mcm","clk":"5348060872","pt":1646213307930,"mc":[{"id":"1.195453618","rc":[{"atl":[[2.62,12.35]],"id":43167174},{"atl":[[2.18,16.95],[2.16,0]],"id":42300273}],"con":true,"img":false}]}
{"op":"mcm","clk":"5348060886","pt":1646213308187,"mc":[{"id":"1.195453618","rc":[{"atl":[[2.64,0]],"id":43167174},{"atl":[[2.12,0]],"id":42300273}],"con":true,"img":false}]}
{"op":"mcm","clk":"5348060895","pt":1646213308350,"mc":[{"id":"1.195453618","rc":[{"atl":[[2.68,1.57]],"id":43167174},{"atl":[[2.14,1.51]],"id":42300273}],"con":true,"img":false}]}
{"op":"mcm","clk":"5348060915","pt":1646213308611,"mc":[{"id":"1.195453618","rc":[{"atl":[[2.68,0.15]],"id":43167174},{"atl":[[2.14,0.15]],"id":42300273}],"con":true,"img":false}]}
{"op":"mcm","clk":"5348060923","pt":1646213308711,"mc":[{"id":"1.195453618","rc":[{"atl":[[2.6,1.42]],"id":43167174},{"atl":[[2.16,1.36]],"id":42300273}],"con":true,"img":false}]}
{"op":"mcm","clk":"5348060928","pt":1646213308809,"mc":[{"id":"1.195453618","rc":[{"atl":[[2.68,0]],"id":43167174},{"atl":[[2.14,0]],"id":42300273}],"con":true,"img":false}]}
{"op":"mcm","clk":"5348060934","pt":1646213308914,"mc":[{"id":"1.195453618","rc":[{"atl":[[2.6,1.57]],"id":43167174},{"atl":[[2.16,1.51]],"id":42300273}],"con":true,"img":false}]}
{"op":"mcm","clk":"5348060958","pt":1646213309324,"mc":[{"id":"1.195453618","rc":[{"atl":[[5.7,0]],"id":39980030}],"con":true,"img":false}]}
{"op":"mcm","clk":"5348060962","pt":1646213309432,"mc":[{"id":"1.195453618","rc":[{"atl":[[5.3,4.81]],"id":39980030}],"con":true,"img":false}]}
{"op":"mcm","clk":"5348061062","pt":1646213311504,"mc":[{"id":"1.195453618","rc":[{"atb":[[4.5,22.63],[4.3,68.12],[4.9,5.13],[4.7,13.51]],"id":40812743},{"atl":[[11,2],[12,4.55],[13,6.25],[14,9.62]],"id":40812743},{"atb":[[3.05,71.22]],"id":39980030}],"con":true,"img":false}]}
{"op":"mcm","clk":"5348061083","pt":1646213312020,"mc":[{"id":"1.195453618","rc":[{"atl":[[990,0]],"id":40812743}],"con":true,"img":false}]}
{"op":"mcm","clk":"5348061089","pt":1646213312123,"mc":[{"id":"1.195453618","rc":[{"atb":[[4.5,21.43]],"id":40812743},{"atl":[[12,4.7],[14.5,0]],"id":40812743}],"con":true,"img":false}]}
{"op":"mcm","clk":"5348061095","pt":1646213312235,"mc":[{"id":"1.195453618","rc":[{"atb":[[4.8,1.2]],"id":40812743},{"atl":[[11,3.26]],"id":40812743}],"con":true,"img":false}]}
{"op":"mcm","clk":"5348061103","pt":1646213312328,"mc":[{"id":"1.195453618","rc":[{"atl":[[3.7,0]],"id":40908229}],"con":true,"img":false}]}
{"op":"mcm","clk":"5348061108","pt":1646213312432,"mc":[{"id":"1.195453618","rc":[{"atl":[[3.75,8.71]],"id":40908229}],"con":true,"img":false}]}
{"op":"mcm","clk":"5348061131","pt":1646213312738,"mc":[{"id":"1.195453618","rc":[{"atl":[[12,4.55]],"id":40812743}],"con":true,"img":false}]}
{"op":"mcm","clk":"5348061135","pt":1646213312839,"mc":[{"id":"1.195453618","rc":[{"atl":[[11,3.41],[1000,0]],"id":40812743}],"con":true,"img":false}]}
{"op":"mcm","clk":"5348061139","pt":1646213312938,"mc":[{"id":"1.195453618","rc":[{"atl":[[11,4.86]],"id":40812743}],"con":true,"img":false}]}
{"op":"mcm","clk":"5348061162","pt":1646213313300,"mc":[{"id":"1.195453618","rc":[{"atb":[[2.62,0]],"id":40908229}],"con":true,"img":false}]}
{"op":"mcm","clk":"5348061166","pt":1646213313404,"mc":[{"id":"1.195453618","rc":[{"atb":[[2.72,25.34]],"id":40908229}],"con":true,"img":false}]}
{"op":"mcm","clk":"5348061206","pt":1646213314129,"mc":[{"id":"1.195453618","rc":[{"atb":[[1.37,135.14],[1.33,250],[1.39,91.93],[1.35,214.29]],"id":42390009},{"atl":[[2.24,100.81],[2.12,17.86],[2.2,62.5],[2.16,43.1]],"id":42390009}],"con":true,"img":false}]}
{"op":"mcm","clk":"5348061232","pt":1646213314641,"mc":[{"id":"1.195453618","rc":[{"atl":[[2.52,0.15]],"id":42390009}],"con":true,"img":false}]}
{"op":"mcm","clk":"5348061239","pt":1646213314695,"mc":[{"id":"1.195453618","rc":[{"atl":[[2.1,1.34]],"id":42390009}],"con":true,"img":false}]}
{"op":"mcm","clk":"5348061244","pt":1646213314798,"mc":[{"id":"1.195453618","rc":[{"atl":[[3.75,0]],"id":40908229},{"atl":[[5.3,0]],"id":39980030}],"con":true,"img":false}]}
{"op":"mcm","clk":"5348061246","pt":1646213314905,"mc":[{"id":"1.195453618","rc":[{"atl":[[3.8,8.71]],"id":40908229},{"atl":[[5.4,4.81]],"id":39980030}],"con":true,"img":false}]}
{"op":"mcm","clk":"5348061254","pt":1646213315107,"mc":[{"id":"1.195453618","rc":[{"atl":[[2.52,0]],"id":42390009},{"atb":[[2.92,51.98],[2.88,0],[2.96,0]],"id":39980030}],"con":true,"img":false}]}
{"op":"mcm","clk":"5348061261","pt":1646213315217,"mc":[{"id":"1.195453618","rc":[{"atl":[[2.1,1.49]],"id":42390009}],"con":true,"img":false}]}
{"op":"mcm","clk":"5348061292","pt":1646213315933,"mc":[{"id":"1.195453618","rc":[{"atl":[[2.16,18.75]],"id":42300273}],"con":true,"img":false}]}
{"op":"mcm","clk":"5348061312","pt":1646213316299,"mc":[{"id":"1.195453618","rc":[{"atb":[[1.39,72.65]],"id":42390009}],"con":true,"img":false}]}
{"op":"mcm","clk":"5348061387","pt":1646213317944,"mc":[{"id":"1.195453618","rc":[{"atl":[[2.66,30.12]],"id":43167174}],"con":true,"img":false}]}
{"op":"mcm","clk":"5348061456","pt":1646213319255,"mc":[{"id":"1.195453618","rc":[{"atl":[[2.78,0]],"id":43167174},{"atl":[[2.16,1.51],[2.14,17.54]],"id":42300273}],"con":true,"img":false}]}
{"op":"mcm","clk":"5348061507","pt":1646213320042,"mc":[{"id":"1.195453618","rc":[{"atl":[[2.16,0]],"id":42300273}],"con":true,"img":false}]}
{"op":"mcm","clk":"5348061511","pt":1646213320142,"mc":[{"id":"1.195453618","rc":[{"atl":[[2.12,1.51]],"id":42300273}],"con":true,"img":false}]}
{"op":"mcm","clk":"5348061550","pt":1646213320864,"mc":[{"id":"1.195453618","rc":[{"atl":[[10.5,3.11],[15,0]],"id":40812743}],"con":true,"img":false}]}
{"op":"mcm","clk":"5348061558","pt":1646213321023,"mc":[{"id":"1.195453618","rc":[{"atl":[[11,3.6]],"id":40812743}],"con":true,"img":false}]}
{"op":"mcm","clk":"5348061562","pt":1646213321123,"mc":[{"id":"1.195453618","rc":[{"atl":[[10.5,4.37]],"id":40812743}],"con":true,"img":false}]}
{"op":"mcm","clk":"5348061581","pt":1646213321534,"mc":[{"id":"1.195453618","rc":[{"atb":[[2.98,35]],"id":39980030}],"con":true,"img":false}]}
{"op":"mcm","clk":"5348061694","pt":1646213323347,"mc":[{"id":"1.195453618","rc":[{"atb":[[1.42,17.9]],"id":42390009}],"con":true,"img":false}]}
{"op":"mcm","clk":"5348061715","pt":1646213323658,"mc":[{"id":"1.195453618","rc":[{"atb":[[1.4,1.55]],"id":42390009}],"con":true,"img":false}]}
{"op":"mcm","clk":"5348061719","pt":1646213323760,"mc":[{"id":"1.195453618","rc":[{"atb":[[1.4,0],[1.43,1.24]],"id":42390009}],"con":true,"img":false}]}
{"op":"mcm","clk":"5348061723","pt":1646213323863,"mc":[{"id":"1.195453618","rc":[{"atb":[[1.43,2.8]],"id":42390009}],"con":true,"img":false}]}
{"op":"mcm","clk":"5348061882","pt":1646213326851,"mc":[{"id":"1.195453618","rc":[{"atl":[[3.95,0]],"id":43167174}],"con":true,"img":false}]}
{"op":"mcm","clk":"5348061887","pt":1646213326958,"mc":[{"id":"1.195453618","rc":[{"atl":[[3.6,17.79]],"id":43167174}],"con":true,"img":false}]}
{"op":"mcm","clk":"5348061948","pt":1646213327940,"mc":[{"id":"1.195453618","rc":[{"atl":[[2.7,44.12]],"id":43167174}],"con":true,"img":false}]}
{"op":"mcm","clk":"5348062026","pt":1646213329232,"mc":[{"id":"1.195453618","rc":[{"atl":[[2.18,42.37]],"id":42300273}],"con":true,"img":false}]}
{"op":"mcm","clk":"5348062146","pt":1646213331563,"mc":[{"id":"1.195453618","rc":[{"atb":[[2.94,59.54]],"id":39980030}],"con":true,"img":false}]}
{"op":"mcm","clk":"5348062156","pt":1646213331659,"mc":[{"id":"1.195453618","rc":[{"atb":[[1.39,51.28]],"id":42390009}],"con":true,"img":false}]}
{"op":"mcm","clk":"5348062165","pt":1646213331866,"mc":[{"id":"1.195453618","rc":[{"atb":[[1.36,0]],"id":42300273}],"con":true,"img":false}]}
{"op":"mcm","clk":"5348062168","pt":1646213331967,"mc":[{"id":"1.195453618","rc":[{"atb":[[1.38,177.8]],"id":42300273}],"con":true,"img":false}]}
{"op":"mcm","clk":"5348062194","pt":1646213332433,"mc":[{"id":"1.195453618","rc":[{"atl":[[15,0]],"id":39980030}],"con":true,"img":false}]}
{"op":"mcm","clk":"5348062198","pt":1646213332538,"mc":[{"id":"1.195453618","rc":[{"atl":[[12.5,2.72]],"id":39980030}],"con":true,"img":false}]}
{"op":"mcm","clk":"5348062225","pt":1646213333156,"mc":[{"id":"1.195453618","rc":[{"atl":[[2.12,19.37],[2.14,0]],"id":42300273}],"con":true,"img":false}]}
{"op":"mcm","clk":"5348062256","pt":1646213333772,"mc":[{"id":"1.195453618","rc":[{"atl":[[2.92,18.49],[3.4,0]],"id":42390009}],"con":true,"img":false}]}
{"op":"mcm","clk":"5348062292","pt":1646213334463,"mc":[{"id":"1.195453618","rc":[{"atb":[[1.42,0]],"id":42390009}],"con":true,"img":false}]}
{"op":"mcm","clk":"5348062381","pt":1646213335751,"mc":[{"id":"1.195453618","rc":[{"atb":[[1.43,1.55]],"id":42390009}],"con":true,"img":false}]}
{"op":"mcm","clk":"5348062388","pt":1646213335864,"mc":[{"id":"1.195453618","rc":[{"atb":[[1.4,1.24]],"id":42390009}],"con":true,"img":false}]}
{"op":"mcm","clk":"5348062399","pt":1646213336061,"mc":[{"id":"1.195453618","rc":[{"atl":[[2.06,18.87],[2.12,1.51]],"id":42300273}],"con":true,"img":false}]}
{"op":"mcm","clk":"5348062407","pt":1646213336162,"mc":[{"id":"1.195453618","rc":[{"atb":[[1.89,56.18],[1.85,264.48],[1.91,69.88],[1.87,86.21]],"id":43167175},{"atl":[[3.45,30.61],[3.35,21.28],[3.25,8.89],[3.55,49.02]],"id":43167175}],"con":true,"img":false}]}
{"op":"mcm","clk":"5348062415","pt":1646213336263,"mc":[{"id":"1.195453618","rc":[{"atb":[[4.8,12.68]],"id":40812743}],"con":true,"img":false}]}
{"op":"mcm","clk":"5348062421","pt":1646213336370,"mc":[{"id":"1.195453618","rc":[{"atb":[[4.4,0]],"id":40812743},{"atb":[[1.36,0]],"id":42390009}],"con":true,"img":false}]}
{"op":"mcm","clk":"5348062429","pt":1646213336471,"mc":[{"id":"1.195453618","rc":[{"atl":[[3.95,0.15]],"id":43167175},{"atb":[[1.38,83.52]],"id":42390009}],"con":true,"img":false}]}
{"op":"mcm","clk":"5348062434","pt":1646213336574,"mc":[{"id":"1.195453618","rc":[{"atl":[[2.12,1.36]],"id":42300273},{"atl":[[3.2,1.4]],"id":43167175}],"con":true,"img":false}]}
{"op":"mcm","clk":"5348062437","pt":1646213336675,"mc":[{"id":"1.195453618","rc":[{"atl":[[2.04,0.15]],"id":42300273}],"con":true,"img":false}]}
{"op":"mcm","clk":"5348062444","pt":1646213336776,"mc":[{"id":"1.195453618","rc":[{"atl":[[2.06,0],[2.04,19.38]],"id":42300273},{"atb":[[2.82,8.83],[2.74,34.65],[2.78,22.58],[2.7,97.21]],"id":40908229},{"atl":[[5.1,4.88],[5.3,11.63],[5.5,16.67],[5.7,26.6]],"id":40908229}],"con":true,"img":false}]}
{"op":"mcm","clk":"5348062449","pt":1646213336883,"mc":[{"id":"1.195453618","rc":[{"atl":[[2.72,0]],"id":42390009}],"con":true,"img":false}]}
{"op":"mcm","clk":"5348062454","pt":1646213336983,"mc":[{"id":"1.195453618","rc":[{"atl":[[2.58,25.34]],"id":42390009}],"con":true,"img":false}]}
{"op":"mcm","clk":"5348062475","pt":1646213337247,"mc":[{"id":"1.195453618","rc":[{"atl":[[3.8,0]],"id":40908229},{"atl":[[5.4,0]],"id":39980030}],"con":true,"img":false}]}
{"op":"mcm","clk":"5348062480","pt":1646213337398,"mc":[{"id":"1.195453618","rc":[{"atl":[[3.85,8.71]],"id":40908229},{"atl":[[3.6,0],[5.5,4.81]],"id":39980030}],"con":true,"img":false}]}
{"op":"mcm","clk":"5348062484","pt":1646213337451,"mc":[{"id":"1.195453618","rc":[{"atl":[[3.95,0]],"id":43167175}],"con":true,"img":false}]}
{"op":"mcm","clk":"5348062488","pt":1646213337557,"mc":[{"id":"1.195453618","rc":[{"atl":[[3.25,9.04]],"id":43167175},{"atl":[[1000,2.4]],"id":39980030}],"con":true,"img":false}]}
{"op":"mcm","clk":"5348062494","pt":1646213337669,"mc":[{"id":"1.195453618","rc":[{"atl":[[1000,2.3]],"id":39980030}],"con":true,"img":false}]}
{"op":"mcm","clk":"5348062503","pt":1646213337864,"mc":[{"id":"1.195453618","rc":[{"atl":[[3.85,0]],"id":40908229},{"atl":[[1000,0.15]],"id":39980030}],"con":true,"img":false}]}
{"op":"mcm","clk":"5348062507","pt":1646213337967,"mc":[{"id":"1.195453618","rc":[{"atl":[[2.74,71.84]],"id":43167174},{"atl":[[3.9,8.71]],"id":40908229},{"atl":[[5.1,2.15]],"id":39980030}],"con":true,"img":false}]}
{"op":"mcm","clk":"5348062522","pt":1646213338275,"mc":[{"id":"1.195453618","rc":[{"atb":[[1.43,0]],"id":42390009}],"con":true,"img":false}]}
{"op":"mcm","clk":"5348062528","pt":1646213338406,"mc":[{"id":"1.195453618","rc":[{"atb":[[1.4,2.8]],"id":42390009}],"con":true,"img":false}]}
{"op":"mcm","clk":"5348062551","pt":1646213338747,"mc":[{"id":"1.195453618","rc":[{"atl":[[3.45,3.36]],"id":39980030}],"con":true,"img":false}]}
{"op":"mcm","clk":"5348062556","pt":1646213338848,"mc":[{"id":"1.195453618","rc":[{"atl":[[5.4,1.22]],"id":39980030}],"con":true,"img":false}]}
{"op":"mcm","clk":"5348062628","pt":1646213340389,"mc":[{"id":"1.195453618","rc":[{"atl":[[5.1,0]],"id":39980030}],"con":true,"img":false}]}
{"op":"mcm","clk":"5348062634","pt":1646213340497,"mc":[{"id":"1.195453618","rc":[{"atl":[[3.4,3.23]],"id":39980030}],"con":true,"img":false}]}
{"op":"mcm","clk":"5348062699","pt":1646213341688,"mc":[{"id":"1.195453618","rc":[{"atl":[[5.4,0]],"id":39980030}],"con":true,"img":false}]}
{"op":"mcm","clk":"5348062705","pt":1646213341744,"mc":[{"id":"1.195453618","rc":[{"atl":[[3.4,4.45]],"id":39980030}],"con":true,"img":false}]}
{"op":"mcm","clk":"5348062814","pt":1646213343459,"mc":[{"id":"1.195453618","rc":[{"spn":7.7,"spf":"NaN","id":40812743},{"spn":2.2,"spf":"NaN","id":43167174},{"spn":1.73,"spf":"NaN","id":42300273},{"spn":2.58,"spf":"NaN","id":43167175},{"spn":2.98,"spf":"NaN","id":40908229},{"atb":[[1.41,18.33]],"id":42390009},{"spn":1.75,"spf":"NaN","id":42390009},{"atl":[[3.4,1.22]],"id":39980030},{"spn":3.27,"spf":"NaN","id":39980030}],"con":true,"img":false}]}
{"op":"mcm","clk":"5348062820","pt":1646213343568,"mc":[{"id":"1.195453618","rc":[{"atl":[[3.35,3.27]],"id":39980030}],"con":true,"img":false}]}
{"op":"mcm","clk":"5348062846","pt":1646213344087,"mc":[{"id":"1.195453618","rc":[{"atb":[[1.4,1.55]],"id":42390009}],"con":true,"img":false}]}
{"op":"mcm","clk":"5348062850","pt":1646213344188,"mc":[{"id":"1.195453618","rc":[{"atb":[[1.42,1.24]],"id":42390009}],"con":true,"img":false}]}
{"op":"mcm","clk":"5348062864","pt":1646213344496,"mc":[{"id":"1.195453618","rc":[{"atb":[[1.4,0]],"id":42390009},{"atl":[[3.4,0]],"id":39980030}],"con":true,"img":false}]}
{"op":"mcm","clk":"5348062868","pt":1646213344560,"mc":[{"id":"1.195453618","rc":[{"atb":[[1.42,2.8]],"id":42390009},{"atl":[[3.35,4.5]],"id":39980030}],"con":true,"img":false}]}
{"op":"mcm","clk":"5348062874","pt":1646213344657,"mc":[{"id":"1.195453618","rc":[{"atl":[[3.35,0.19]],"id":39980030},{"trd":[[3.35,8.62]],"ltp":3.35,"tv":8.62,"id":39980030}],"con":true,"img":false}]}
{"op":"mcm","clk":"5348062878","pt":1646213344759,"mc":[{"id":"1.195453618","rc":[{"atl":[[2.84,0]],"id":39209038}],"con":true,"img":false}]}
{"op":"mcm","clk":"5348062884","pt":1646213344867,"mc":[{"id":"1.195453618","rc":[{"atl":[[2.88,23.69]],"id":39209038}],"con":true,"img":false}]}
{"op":"mcm","clk":"5348062920","pt":1646213345493,"mc":[{"id":"1.195453618","rc":[{"atb":[[4.9,0]],"id":40812743},{"trd":[[4.9,10.25]],"ltp":4.9,"tv":10.25,"id":40812743},{"atl":[[3.35,0]],"id":39980030}],"con":true,"img":false}]}
{"op":"mcm","clk":"5348062935","pt":1646213345695,"mc":[{"id":"1.195453618","rc":[{"atb":[[4.5,0],[4.3,30.24],[4.6,5.19],[4.7,0]],"id":40812743},{"atl":[[10,2.51]],"id":40812743}],"con":true,"img":false}]}
{"op":"mcm","clk":"5348062982","pt":1646213346374,"mc":[{"id":"1.195453618","rc":[{"atb":[[3.15,15.97]],"id":39980030}],"con":true,"img":false}]}
{"op":"mcm","clk":"5348062988","pt":1646213346476,"mc":[{"id":"1.195453618","rc":[{"atl":[[10.5,3.11]],"id":40812743}],"con":true,"img":false}]}
{"op":"mcm","clk":"5348062994","pt":1646213346575,"mc":[{"id":"1.195453618","rc":[{"atl":[[10,3.77]],"id":40812743}],"con":true,"img":false}]}
{"op":"mcm","clk":"5348063009","pt":1646213346780,"mc":[{"id":"1.195453618","rc":[{"atl":[[2.08,46.3]],"id":42300273}],"con":true,"img":false}]}
{"op":"mcm","clk":"5348063046","pt":1646213347291,"mc":[{"id":"1.195453618","rc":[{"atl":[[11,3.45]],"id":40812743}],"con":true,"img":false}]}
{"op":"mcm","clk":"5348063051","pt":1646213347396,"mc":[{"id":"1.195453618","rc":[{"atl":[[10,3.92]],"id":40812743}],"con":true,"img":false}]}
{"op":"mcm","clk":"5348063073","pt":1646213347660,"mc":[{"id":"1.195453618","rc":[{"atl":[[2.64,1.37]],"id":39209038},{"atl":[[10,3.77]],"id":40812743},{"atl":[[2.6,1.42]],"id":43167174},{"atl":[[2.04,19.23]],"id":42300273},{"atl":[[3.25,8.89]],"id":43167175},{"atl":[[2.1,1.34]],"id":42390009}],"con":true,"img":false}]}
{"op":"mcm","clk":"5348063079","pt":1646213347763,"mc":[{"id":"1.195453618","rc":[{"atl":[[990,0.15]],"id":39209038},{"atl":[[990,0.15]],"id":40812743},{"atl":[[990,0.15]],"id":43167174},{"atl":[[990,0.15]],"id":42300273},{"atl":[[990,0.15]],"id":43167175},{"atl":[[990,0.15]],"id":42390009},{"atl":[[8,3.43],[5.5,0]],"id":39980030}],"con":true,"img":false}]}
{"op":"mcm","clk":"5348063082","pt":1646213347871,"mc":[{"id":"1.195453618","rc":[{"atl":[[2.12,0]],"id":42300273}],"con":true,"img":false}]}
{"op":"mcm","clk":"5348063086","pt":1646213347969,"mc":[{"id":"1.195453618","rc":[{"atl":[[2.02,1.36]],"id":42300273}],"con":true,"img":false}]}
{"op":"mcm","clk":"5348063347","pt":1646213353289,"mc":[{"id":"1.195453618","rc":[{"atb":[[4.8,1.2]],"id":40812743}],"con":true,"img":false}]}
{"op":"mcm","clk":"5348063353","pt":1646213353392,"mc":[{"id":"1.195453618","rc":[{"atb":[[4.4,11.47]],"id":40812743}],"con":true,"img":false}]}
{"op":"mcm","clk":"5348063388","pt":1646213353973,"mc":[{"id":"1.195453618","rc":[{"atb":[[4.8,0]],"id":40812743}],"con":true,"img":false}]}
{"op":"mcm","clk":"5348063398","pt":1646213354074,"mc":[{"id":"1.195453618","rc":[{"atb":[[4.5,1.2]],"id":40812743}],"con":true,"img":false}]}
{"op":"mcm","clk":"5348063407","pt":1646213354284,"mc":[{"id":"1.195453618","rc":[{"atb":[[1.31,0]],"id":42390009}],"con":true,"img":false}]}
{"op":"mcm","clk":"5348063412","pt":1646213354385,"mc":[{"id":"1.195453618","rc":[{"atb":[[1.36,114.56]],"id":42390009}],"con":true,"img":false}]}
{"op":"mcm","clk":"5348063429","pt":1646213354797,"mc":[{"id":"1.195453618","rc":[{"atl":[[18,0],[12.5,3.55]],"id":40812743}],"con":true,"img":false}]}
{"op":"mcm","clk":"5348063445","pt":1646213355107,"mc":[{"id":"1.195453618","rc":[{"atl":[[11,2]],"id":40812743}],"con":true,"img":false}]}
{"op":"mcm","clk":"5348063454","pt":1646213355163,"mc":[{"id":"1.195453618","rc":[{"atl":[[9.8,1.45]],"id":40812743}],"con":true,"img":false}]}
{"op":"mcm","clk":"5348063475","pt":1646213355684,"mc":[{"id":"1.195453618","rc":[{"atb":[[4.4,25.22]],"id":40812743}],"con":true,"img":false}]}
{"op":"mcm","clk":"5348063484","pt":1646213355888,"mc":[{"id":"1.195453618","rc":[{"atl":[[2.18,0]],"id":42300273},{"atl":[[3.25,0],[3.3,8.7]],"id":43167175}],"con":true,"img":false}]}
{"op":"mcm","clk":"5348063493","pt":1646213356104,"mc":[{"id":"1.195453618","rc":[{"atl":[[10,2.51]],"id":40812743}],"con":true,"img":false}]}
{"op":"mcm","clk":"5348063503","pt":1646213356199,"mc":[{"id":"1.195453618","rc":[{"atl":[[9.8,2.71]],"id":40812743}],"con":true,"img":false}]}
{"op":"mcm","clk":"5348063505","pt":1646213356301,"mc":[{"id":"1.195453618","rc":[{"atl":[[3.2,0]],"id":43167175}],"con":true,"img":false}]}
{"op":"mcm","clk":"5348063510","pt":1646213356400,"mc":[{"id":"1.195453618","rc":[{"atl":[[3.25,1.4]],"id":43167175}],"con":true,"img":false}]}
{"op":"mcm","clk":"5348063526","pt":1646213356766,"mc":[{"id":"1.195453618","rc":[{"atl":[[2.12,66.96]],"id":42300273}],"con":true,"img":false}]}
{"op":"mcm","clk":"5348063531","pt":1646213356869,"mc":[{"id":"1.195453618","rc":[{"atl":[[9.8,1.26]],"id":40812743}],"con":true,"img":false}]}
{"op":"mcm","clk":"5348063536","pt":1646213356974,"mc":[{"id":"1.195453618","rc":[{"atl":[[1000,1.45]],"id":40812743}],"con":true,"img":false}]}
{"op":"mcm","clk":"5348063546","pt":1646213357182,"mc":[{"id":"1.195453618","rc":[{"atl":[[990,0]],"id":39209038},{"atl":[[990,0]],"id":43167174},{"atl":[[990,0]],"id":42300273},{"atl":[[990,0]],"id":43167175},{"atl":[[990,0]],"id":42390009}],"con":true,"img":false}]}
{"op":"mcm","clk":"5348063552","pt":1646213357285,"mc":[{"id":"1.195453618","rc":[{"atl":[[2.64,1.52]],"id":39209038},{"atl":[[2.6,1.57]],"id":43167174},{"atl":[[2.02,1.51]],"id":42300273},{"atl":[[4.9,0],[3.3,8.85]],"id":43167175},{"atl":[[2.1,1.49]],"id":42390009}],"con":true,"img":false}]}
{"op":"mcm","clk":"5348063558","pt":1646213357389,"mc":[{"id":"1.195453618","rc":[{"atl":[[4.3,12.45]],"id":43167175}],"con":true,"img":false}]}
{"op":"mcm","clk":"5348063607","pt":1646213358267,"mc":[{"id":"1.195453618","rc":[{"atb":[[2.72,0]],"id":40908229}],"con":true,"img":false}]}
{"op":"mcm","clk":"5348063615","pt":1646213358372,"mc":[{"id":"1.195453618","rc":[{"atb":[[2.8,25.34]],"id":40908229}],"con":true,"img":false}]}
{"op":"mcm","clk":"5348063699","pt":1646213359710,"mc":[{"id":"1.195453618","rc":[{"atb":[[1.41,38.67]],"id":42390009}],"con":true,"img":false}]}
{"op":"mcm","clk":"5348063707","pt":1646213359869,"mc":[{"id":"1.195453618","rc":[{"atl":[[2.24,0]],"id":42300273},{"atl":[[3.25,10.29],[3.3,0.15]],"id":43167175}],"con":true,"img":false}]}
{"op":"mcm","clk":"5348063713","pt":1646213359973,"mc":[{"id":"1.195453618","rc":[{"atl":[[2.06,18.87],[2.04,0],[2.12,0],[2.2,0],[2.08,0]],"id":42300273}],"con":true,"img":false}]}
{"op":"mcm","clk":"5348063734","pt":1646213360388,"mc":[{"id":"1.195453618","rc":[{"atl":[[2.02,1.36]],"id":42300273},{"atl":[[3.3,0]],"id":43167175}],"con":true,"img":false}]}
{"op":"mcm","clk":"5348063739","pt":1646213360491,"mc":[{"id":"1.195453618","rc":[{"atl":[[2.02,0],[2.04,0.15]],"id":42300273},{"atl":[[3.2,0.15]],"id":43167175}],"con":true,"img":false}]}
{"op":"mcm","clk":"5348063744","pt":1646213360594,"mc":[{"id":"1.195453618","rc":[{"atl":[[2.04,1.51]],"id":42300273}],"con":true,"img":false}]}
{"op":"mcm","clk":"5348063896","pt":1646213363806,"mc":[{"id":"1.195453618","rc":[{"atl":[[2.58,0]],"id":42300273}],"con":true,"img":false}]}
{"op":"mcm","clk":"5348063903","pt":1646213363908,"mc":[{"id":"1.195453618","rc":[{"atl":[[2.78,24.49]],"id":42300273}],"con":true,"img":false}]}
{"op":"mcm","clk":"5348064014","pt":1646213365717,"mc":[{"id":"1.195453618","rc":[{"atb":[[4.2,21.91]],"id":40812743},{"atl":[[10,0]],"id":40812743}],"con":true,"img":false}]}
{"op":"mcm","clk":"5348064241","pt":1646213370001,"mc":[{"id":"1.195453618","rc":[{"atl":[[2.1,45.45]],"id":42300273}],"con":true,"img":false}]}
{"op":"mcm","clk":"5348064473","pt":1646213373728,"mc":[{"id":"1.195453618","rc":[{"atl":[[9.6,2.62]],"id":40812743}],"con":true,"img":false}]}
{"op":"mcm","clk":"5348064577","pt":1646213375704,"mc":[{"id":"1.195453618","rc":[{"atb":[[4,38.95]],"id":40812743}],"con":true,"img":false}]}
{"op":"mcm","clk":"5348064733","pt":1646213378703,"mc":[{"id":"1.195453618","rc":[{"atl":[[2.04,20.74]],"id":42300273}],"con":true,"img":false}]}
{"op":"mcm","clk":"5348064738","pt":1646213378811,"mc":[{"id":"1.195453618","rc":[{"atl":[[5.4,8.3],[6.6,6.47]],"id":40908229}],"con":true,"img":false}]}
{"op":"mcm","clk":"5348065234","pt":1646213388720,"mc":[{"id":"1.195453618","rc":[{"atl":[[2.08,46.3]],"id":42300273}],"con":true,"img":false}]}
{"op":"mcm","clk":"5348065268","pt":1646213389438,"mc":[{"id":"1.195453618","rc":[{"atl":[[2.64,1.37]],"id":39209038},{"atl":[[2.6,1.42]],"id":43167174},{"atl":[[2.04,20.59]],"id":42300273},{"atl":[[3.2,0]],"id":43167175},{"atl":[[2.1,1.34]],"id":42390009}],"con":true,"img":false}]}
{"op":"mcm","clk":"5348065275","pt":1646213389541,"mc":[{"id":"1.195453618","rc":[{"atl":[[990,0.15]],"id":39209038},{"atl":[[990,0.15]],"id":43167174},{"atl":[[990,0.15]],"id":42300273},{"atl":[[990,0.15]],"id":43167175},{"atl":[[990,0.15]],"id":42390009}],"con":true,"img":false}]}
{"op":"mcm","clk":"5348065326","pt":1646213390325,"mc":[{"id":"1.195453618","rc":[{"atl":[[3.6,0]],"id":43167174}],"con":true,"img":false}]}
{"op":"mcm","clk":"5348065333","pt":1646213390425,"mc":[{"id":"1.195453618","rc":[{"atl":[[3.5,32.31]],"id":43167174}],"con":true,"img":false}]}
{"op":"mcm","clk":"5348065357","pt":1646213390838,"mc":[{"id":"1.195453618","rc":[{"atl":[[2.78,0]],"id":42300273}],"con":true,"img":false}]}
{"op":"mcm","clk":"5348065361","pt":1646213390940,"mc":[{"id":"1.195453618","rc":[{"atl":[[2.5,24.49]],"id":42300273}],"con":true,"img":false}]}
{"op":"mcm","clk":"5348065550","pt":1646213394731,"mc":[{"id":"1.195453618","rc":[{"atb":[[1.67,26.87]],"id":39209038},{"atl":[[2.82,0],[2.86,39.02],[2.9,0],[3.95,33.9],[3.55,7.84],[2.94,0]],"id":39209038},{"atb":[[4,0],[4.6,0],[1.42,44.52],[4.4,11.47],[4.2,0],[1.35,50.44]],"id":40812743},{"atl":[[13,12.5]],"id":40812743},{"atb":[[1.32,151.08]],"id":43167174},{"atl":[[3.4,41.67]],"id":43167174},{"atb":[[1.16,355.6]],"id":42300273},{"atl":[[2.06,0],[5,30],[2.04,1.36],[2.1,0],[2.08,0]],"id":42300273},{"atb":[[1.89,0],[1.85,117.42],[1.91,47.9],[1.87,0],[1.08,139.78]],"id":43167175},{"atl":[[4.7,27.03]],"id":43167175},{"atb":[[2.82,0],[2.3,69.3],[2.78,9.03]],"id":40908229},{"atl":[[6.4,17.82]],"id":40908229},{"atb":[[1.37,270.28]],"id":42390009},{"atl":[[2.94,88.11]],"id":42390009},{"atb":[[3.05,120]],"id":39980030},{"atl":[[17.5,6.06],[9.2,2.44],[8.8,0]],"id":39980030}],"con":true,"img":false}]}
{"op":"mcm","clk":"5348065554","pt":1646213394831,"mc":[{"id":"1.195453618","rc":[{"atb":[[1.18,111.11]],"id":43167175}],"con":true,"img":false}]}
{"op":"mcm","clk":"5348065581","pt":1646213395339,"mc":[{"id":"1.195453618","rc":[{"atl":[[2.04,0]],"id":42300273}],"con":true,"img":false}]}
{"op":"mcm","clk":"5348065586","pt":1646213395444,"mc":[{"id":"1.195453618","rc":[{"atl":[[990,0]],"id":39209038},{"atl":[[990,0]],"id":40812743},{"atl":[[990,0]],"id":43167174},{"atl":[[990,0],[2.48,1.36]],"id":42300273},{"atl":[[990,0]],"id":43167175},{"atl":[[990,0]],"id":42390009}],"con":true,"img":false}]}
{"op":"mcm","clk":"5348065592","pt":1646213395547,"mc":[{"id":"1.195453618","rc":[{"atl":[[2.64,1.52]],"id":39209038},{"atl":[[10.5,3.26]],"id":40812743},{"atl":[[2.6,1.57]],"id":43167174},{"atl":[[2.48,1.51]],"id":42300273},{"atl":[[3.2,0.15]],"id":43167175},{"atl":[[2.1,1.49]],"id":42390009}],"con":true,"img":false}]}
{"op":"mcm","clk":"5348065605","pt":1646213395857,"mc":[{"id":"1.195453618","rc":[{"atl":[[10.5,0.15]],"id":40812743}],"con":true,"img":false}]}
{"op":"mcm","clk":"5348065609","pt":1646213395961,"mc":[{"id":"1.195453618","rc":[{"atl":[[9.4,3.11]],"id":40812743}],"con":true,"img":false}]}
{"op":"mcm","clk":"5348065636","pt":1646213396533,"mc":[{"id":"1.195453618","rc":[{"atl":[[9.8,0]],"id":40812743}],"con":true,"img":false}]}
{"op":"mcm","clk":"5348065642","pt":1646213396634,"mc":[{"id":"1.195453618","rc":[{"atl":[[9.4,4.37]],"id":40812743}],"con":true,"img":false}]}
{"op":"mcm","clk":"5348065908","pt":1646213400851,"mc":[{"id":"1.195453618","rc":[{"atb":[[1.43,3.11]],"id":42300273}],"con":true,"img":false}]}
{"op":"mcm","clk":"5348065936","pt":1646213401260,"mc":[{"id":"1.195453618","rc":[{"atl":[[9.2,2.73],[9.6,0]],"id":40812743}],"con":true,"img":false}]}
{"op":"mcm","clk":"5348065955","pt":1646213401472,"mc":[{"id":"1.195453618","rc":[{"atb":[[1.42,1.18]],"id":42300273}],"con":true,"img":false}]}
{"op":"mcm","clk":"5348065965","pt":1646213401531,"mc":[{"id":"1.195453618","rc":[{"atb":[[1.43,4.72]],"id":42300273}],"con":true,"img":false}]}
{"op":"mcm","clk":"5348066020","pt":1646213402250,"mc":[{"id":"1.195453618","rc":[{"atl":[[2.5,0]],"id":42300273},{"atb":[[2.8,0]],"id":40908229}],"con":true,"img":false}]}
{"op":"mcm","clk":"5348066027","pt":1646213402357,"mc":[{"id":"1.195453618","rc":[{"atl":[[2.78,24.49]],"id":42300273},{"atb":[[2.76,25.34]],"id":40908229}],"con":true,"img":false}]}
{"op":"mcm","clk":"5348066042","pt":1646213402464,"mc":[{"id":"1.195453618","rc":[{"atl":[[9.4,3.11]],"id":40812743}],"con":true,"img":false}]}
{"op":"mcm","clk":"5348066056","pt":1646213402569,"mc":[{"id":"1.195453618","rc":[{"atl":[[9.2,3.99]],"id":40812743}],"con":true,"img":false}]}
{"op":"mcm","clk":"5348066068","pt":1646213402672,"mc":[{"id":"1.195453618","rc":[{"atl":[[2.48,0.15]],"id":42300273}],"con":true,"img":false}]}
{"op":"mcm","clk":"5348066075","pt":1646213402732,"mc":[{"id":"1.195453618","rc":[{"atl":[[2.58,1.36]],"id":42300273}],"con":true,"img":false}]}
{"op":"mcm","clk":"5348066084","pt":1646213402840,"mc":[{"id":"1.195453618","rc":[{"atl":[[2.48,0]],"id":42300273}],"con":true,"img":false}]}
{"op":"mcm","clk":"5348066089","pt":1646213402942,"mc":[{"id":"1.195453618","rc":[{"atl":[[2.58,1.51]],"id":42300273}],"con":true,"img":false}]}
{"op":"mcm","clk":"5348066251","pt":1646213404762,"mc":[{"id":"1.195453618","rc":[{"atl":[[3.65,18.87]],"id":39209038},{"atb":[[1.4,116.85]],"id":40812743},{"spn":6.85,"spf":"NaN","id":40812743},{"atl":[[5.2,11.9]],"id":42300273},{"spn":2.0,"spf":"NaN","id":42300273},{"atb":[[1.16,250]],"id":43167175},{"atb":[[2.74,23.1]],"id":40908229},{"spn":2.96,"spf":"NaN","id":40908229},{"spn":1.76,"spf":"NaN","id":42390009},{"atl":[[9.6,5.81]],"id":39980030},{"spn":3.3,"spf":"NaN","id":39980030}],"con":true,"img":false}]}
{"op":"mcm","clk":"5348066718","pt":1646213411753,"mc":[{"id":"1.195453618","rc":[{"atl":[[3.9,0]],"id":40908229}],"con":true,"img":false}]}
{"op":"mcm","clk":"5348066723","pt":1646213411856,"mc":[{"id":"1.195453618","rc":[{"atl":[[3.8,8.71]],"id":40908229}],"con":true,"img":false}]}
{"op":"mcm","clk":"5348066838","pt":1646213413773,"mc":[{"id":"1.195453618","rc":[{"atl":[[8,0]],"id":39980030}],"con":true,"img":false}]}
{"op":"mcm","clk":"5348066844","pt":1646213413876,"mc":[{"id":"1.195453618","rc":[{"atl":[[7.8,3.43]],"id":39980030}],"con":true,"img":false}]}
{"op":"mcm","clk":"5348066861","pt":1646213414289,"mc":[{"id":"1.195453618","rc":[{"atl":[[2.88,0]],"id":39209038}],"con":true,"img":false}]}
{"op":"mcm","clk":"5348066867","pt":1646213414396,"mc":[{"id":"1.195453618","rc":[{"atl":[[2.84,23.69]],"id":39209038}],"con":true,"img":false}]}
{"op":"mcm","clk":"5348066903","pt":1646213414757,"mc":[{"id":"1.195453618","rc":[{"atl":[[3.75,27.27]],"id":39209038},{"atb":[[1.38,184.51]],"id":40812743},{"atl":[[5.4,17.05]],"id":42300273},{"atb":[[1.14,250]],"id":43167175},{"atb":[[2.7,73.57]],"id":40908229},{"atl":[[10,8.33]],"id":39980030}],"con":true,"img":false}]}
{"op":"mcm","clk":"5348066906","pt":1646213414858,"mc":[{"id":"1.195453618","rc":[{"atl":[[3.5,14.51]],"id":43167174}],"con":true,"img":false}]}
{"op":"mcm","clk":"5348066915","pt":1646213414964,"mc":[{"id":"1.195453618","rc":[{"atl":[[3.35,17.79]],"id":43167174}],"con":true,"img":false}]}
{"op":"mcm","clk":"5348067231","pt":1646213420763,"mc":[{"id":"1.195453618","rc":[{"atl":[[9.4,0]],"id":40812743}],"con":true,"img":false}]}
{"op":"mcm","clk":"5348067237","pt":1646213420862,"mc":[{"id":"1.195453618","rc":[{"atl":[[9,3.11]],"id":40812743}],"con":true,"img":false}]}
{"op":"mcm","clk":"5348067278","pt":1646213421691,"mc":[{"id":"1.195453618","rc":[{"atl":[[9.2,2.73]],"id":40812743}],"con":true,"img":false}]}
{"op":"mcm","clk":"5348067283","pt":1646213421803,"mc":[{"id":"1.195453618","rc":[{"atl":[[9,4.37]],"id":40812743}],"con":true,"img":false}]}
{"op":"mcm","clk":"5348067325","pt":1646213422685,"mc":[{"id":"1.195453618","rc":[{"atb":[[1.45,41.55]],"id":40812743}],"con":true,"img":false}]}
{"op":"mcm","clk":"5348067435","pt":1646213424815,"mc":[{"id":"1.195453618","rc":[{"atl":[[3.85,43.86]],"id":39209038},{"atl":[[5.6,27.17]],"id":42300273},{"atb":[[1.12,250]],"id":43167175},{"atb":[[2.66,60.54]],"id":40908229},{"atl":[[11,12.5]],"id":39980030}],"con":true,"img":false}]}
{"op":"mcm","clk":"5348067595","pt":1646213428346,"mc":[{"id":"1.195453618","rc":[{"atl":[[9.2,0],[8.8,2.86]],"id":40812743}],"con":true,"img":false}]}
{"op":"mcm","clk":"5348067661","pt":1646213429389,"mc":[{"id":"1.195453618","rc":[{"atl":[[9,3.11]],"id":40812743}],"con":true,"img":false}]}
{"op":"mcm","clk":"5348067664","pt":1646213429491,"mc":[{"id":"1.195453618","rc":[{"atl":[[8.8,4.12]],"id":40812743}],"con":true,"img":false}]}
{"op":"mcm","clk":"5348067825","pt":1646213432813,"mc":[{"id":"1.195453618","rc":[{"atl":[[7.8,0]],"id":39980030}],"con":true,"img":false}]}
{"op":"mcm","clk":"5348067828","pt":1646213432915,"mc":[{"id":"1.195453618","rc":[{"atl":[[7.6,3.43]],"id":39980030}],"con":true,"img":false}]}
{"op":"mcm","clk":"5348067977","pt":1646213435301,"mc":[{"id":"1.195453618","rc":[{"atl":[[4.3,0]],"id":39209038}],"con":true,"img":false}]}
{"op":"mcm","clk":"5348067984","pt":1646213435404,"mc":[{"id":"1.195453618","rc":[{"atl":[[3.8,14.46]],"id":39209038}],"con":true,"img":false}]}
{"op":"mcm","clk":"5348068161","pt":1646213438722,"mc":[{"id":"1.195453618","rc":[{"atb":[[1.43,1.61]],"id":42300273}],"con":true,"img":false}]}
{"op":"mcm","clk":"5348068164","pt":1646213438825,"mc":[{"id":"1.195453618","rc":[{"atb":[[1.42,4.4]],"id":42300273}],"con":true,"img":false}]}
{"op":"mcm","clk":"5348068645","pt":1646213448327,"mc":[{"id":"1.195453618","rc":[{"atl":[[9,0],[8.6,3.8]],"id":40812743}],"con":true,"img":false}]}
{"op":"mcm","clk":"5348068666","pt":1646213448638,"mc":[{"id":"1.195453618","rc":[{"atl":[[8.8,2.86]],"id":40812743}],"con":true,"img":false}]}
{"op":"mcm","clk":"5348068673","pt":1646213448749,"mc":[{"id":"1.195453618","rc":[{"atl":[[8.6,5.07]],"id":40812743}],"con":true,"img":false}]}
{"op":"mcm","clk":"5348068853","pt":1646213451854,"mc":[{"id":"1.195453618","rc":[{"atl":[[7.6,0]],"id":39980030}],"con":true,"img":false}]}
{"op":"mcm","clk":"5348068861","pt":1646213451957,"mc":[{"id":"1.195453618","rc":[{"atl":[[7.4,3.43]],"id":39980030}],"con":true,"img":false}]}
{"op":"mcm","clk":"5348069030","pt":1646213454748,"mc":[{"id":"1.195453618","rc":[{"atl":[[8.4,2.99],[8.8,0]],"id":40812743}],"con":true,"img":false}]}
{"op":"mcm","clk":"5348069459","pt":1646213461651,"mc":[{"id":"1.195453618","rc":[{"atl":[[8.6,3.8]],"id":40812743}],"con":true,"img":false}]}
{"op":"mcm","clk":"5348069466","pt":1646213461754,"mc":[{"id":"1.195453618","rc":[{"atl":[[8.4,4.25]],"id":40812743}],"con":true,"img":false}]}
{"op":"mcm","clk":"5348069973","pt":1646213470751,"mc":[{"id":"1.195453618","rc":[{"spn":6.45,"spf":"NaN","id":40812743},{"atl":[[7.4,0]],"id":39980030}],"con":true,"img":false}]}
{"op":"mcm","clk":"5348069974","pt":1646213470852,"mc":[{"id":"1.195453618","rc":[{"atl":[[7.2,3.43]],"id":39980030}],"con":true,"img":false}]}
{"op":"mcm","clk":"5348070051","pt":1646213472046,"mc":[{"id":"1.195453618","rc":[{"atl":[[3.45,0]],"id":39980030}],"con":true,"img":false}]}
{"op":"mcm","clk":"5348070060","pt":1646213472252,"mc":[{"id":"1.195453618","rc":[{"atl":[[3.8,0]],"id":40908229}],"con":true,"img":false}]}
{"op":"mcm","clk":"5348070066","pt":1646213472356,"mc":[{"id":"1.195453618","rc":[{"atl":[[3.75,8.71]],"id":40908229},{"atb":[[1.02,0]],"id":39980030},{"atl":[[1000,1.81]],"id":39980030}],"con":true,"img":false}]}
{"op":"mcm","clk":"5348070070","pt":1646213472462,"mc":[{"id":"1.195453618","rc":[{"atb":[[3.2,1.27]],"id":39980030}],"con":true,"img":false}]}
{"op":"mcm","clk":"5348070095","pt":1646213472873,"mc":[{"id":"1.195453618","rc":[{"atl":[[1000,1.67]],"id":39980030}],"con":true,"img":false}]}
{"op":"mcm","clk":"5348070112","pt":1646213473290,"mc":[{"id":"1.195453618","rc":[{"atl":[[1000,0.15]],"id":39980030}],"con":true,"img":false}]}
{"op":"mcm","clk":"5348070115","pt":1646213473341,"mc":[{"id":"1.195453618","rc":[{"atl":[[7.6,1.52]],"id":39980030}],"con":true,"img":false}]}
{"op":"mcm","clk":"5348070225","pt":1646213474792,"mc":[{"id":"1.195453618","rc":[{"atl":[[8.6,0]],"id":40812743}],"con":true,"img":false}]}
{"op":"mcm","clk":"5348070233","pt":1646213474896,"mc":[{"id":"1.195453618","rc":[{"atl":[[8.2,3.8]],"id":40812743}],"con":true,"img":false}]}
{"op":"mcm","clk":"5348070273","pt":1646213475463,"mc":[{"id":"1.195453618","rc":[{"atl":[[8.4,2.99]],"id":40812743}],"con":true,"img":false}]}
{"op":"mcm","clk":"5348070282","pt":1646213475568,"mc":[{"id":"1.195453618","rc":[{"atl":[[8.2,5.07]],"id":40812743}],"con":true,"img":false}]}
{"op":"mcm","clk":"5348070567","pt":1646213480691,"mc":[{"id":"1.195453618","rc":[{"atl":[[8,3.14],[8.4,0]],"id":40812743}],"con":true,"img":false}]}
{"op":"mcm","clk":"5348070605","pt":1646213481463,"mc":[{"id":"1.195453618","rc":[{"atl":[[8.2,3.8]],"id":40812743}],"con":true,"img":false}]}
{"op":"mcm","clk":"5348070611","pt":1646213481568,"mc":[{"id":"1.195453618","rc":[{"atl":[[8,4.4]],"id":40812743}],"con":true,"img":false}]}
{"op":"mcm","clk":"5348070641","pt":1646213482291,"mc":[{"id":"1.195453618","rc":[{"atl":[[7.2,0]],"id":39980030}],"con":true,"img":false}]}
{"op":"mcm","clk":"5348070645","pt":1646213482392,"mc":[{"id":"1.195453618","rc":[{"atl":[[7.4,3.43]],"id":39980030}],"con":true,"img":false}]}
{"op":"mcm","clk":"5348070651","pt":1646213482523,"mc":[{"id":"1.195453618","rc":[{"atl":[[7.6,5.37]],"id":39980030}],"con":true,"img":false}]}
{"op":"mcm","clk":"5348070660","pt":1646213482680,"mc":[{"id":"1.195453618","rc":[{"atl":[[7.6,1.52]],"id":39980030}],"con":true,"img":false}]}
{"op":"mcm","clk":"5348070799","pt":1646213485876,"mc":[{"id":"1.195453618","rc":[{"atl":[[7.6,0]],"id":39980030}],"con":true,"img":false}]}
{"op":"mcm","clk":"5348070814","pt":1646213486288,"mc":[{"id":"1.195453618","rc":[{"atl":[[1000,1.81]],"id":39980030}],"con":true,"img":false}]}
{"op":"mcm","clk":"5348070827","pt":1646213486598,"mc":[{"id":"1.195453618","rc":[{"atl":[[1000,1.75]],"id":39980030}],"con":true,"img":false}]}
{"op":"mcm","clk":"5348070840","pt":1646213486907,"mc":[{"id":"1.195453618","rc":[{"atl":[[1000,0.15]],"id":39980030}],"con":true,"img":false}]}
{"op":"mcm","clk":"5348070846","pt":1646213486958,"mc":[{"id":"1.195453618","rc":[{"atl":[[7.2,1.6]],"id":39980030}],"con":true,"img":false}]}
{"op":"mcm","clk":"5348071487","pt":1646213500392,"mc":[{"id":"1.195453618","rc":[{"atl":[[8.2,0]],"id":40812743}],"con":true,"img":false}]}
{"op":"mcm","clk":"5348071494","pt":1646213500496,"mc":[{"id":"1.195453618","rc":[{"atl":[[8,8.21]],"id":40812743}],"con":true,"img":false}]}
{"op":"mcm","clk":"5348071767","pt":1646213505905,"mc":[{"id":"1.195453618","rc":[{"atl":[[7.4,0]],"id":39980030}],"con":true,"img":false}]}
{"op":"mcm","clk":"5348071777","pt":1646213506034,"mc":[{"id":"1.195453618","rc":[{"atl":[[8,3.43]],"id":39980030}],"con":true,"img":false}]}
{"op":"mcm","clk":"5348071829","pt":1646213506712,"mc":[{"id":"1.195453618","rc":[{"atl":[[1000,0]],"id":39980030}],"con":true,"img":false}]}
{"op":"mcm","clk":"5348071834","pt":1646213506814,"mc":[{"id":"1.195453618","rc":[{"atl":[[8,3.58]],"id":39980030}],"con":true,"img":false}]}
{"op":"mcm","clk":"5348074623","pt":1646213558785,"mc":[{"id":"1.195453618","rc":[{"spn":6.25,"spf":"NaN","id":40812743},{"atb":[[1.42,1.18]],"id":42300273},{"spn":5.2,"spf":"NaN","id":39980030}],"con":true,"img":false}]}
{"op":"mcm","clk":"5348074631","pt":1646213558889,"mc":[{"id":"1.195453618","rc":[{"atb":[[1.44,3.37]],"id":42300273}],"con":true,"img":false}]}
{"op":"mcm","clk":"5348074681","pt":1646213559876,"mc":[{"id":"1.195453618","rc":[{"atb":[[1.43,0]],"id":42300273}],"con":true,"img":false}]}
{"op":"mcm","clk":"5348074685","pt":1646213559982,"mc":[{"id":"1.195453618","rc":[{"atb":[[1.44,4.98]],"id":42300273}],"con":true,"img":false}]}
{"op":"mcm","clk":"5348079970","pt":1646213638348,"mc":[{"id":"1.195453618","rc":[{"spn":2.01,"spf":"NaN","id":42300273},{"atl":[[5.4,0]],"id":40908229}],"con":true,"img":false}]}
{"op":"mcm","clk":"5348079975","pt":1646213638452,"mc":[{"id":"1.195453618","rc":[{"atl":[[5.6,8.3]],"id":40908229}],"con":true,"img":false}]}
{"op":"mcm","clk":"5348080074","pt":1646213640163,"mc":[{"id":"1.195453618","rc":[{"atl":[[3.85,7.02],[3.55,0],[3.65,0],[3.75,0]],"id":39209038},{"atl":[[2.74,11.49],[2.66,0],[2.62,0],[2.7,0]],"id":43167174},{"atb":[[2.74,0],[2.78,0],[2.68,9.57],[2.7,38.1]],"id":40908229},{"atb":[[1.37,189.19],[1.39,0]],"id":42390009}],"con":true,"img":false}]}
{"op":"mcm","clk":"5348080114","pt":1646213640750,"mc":[{"id":"1.195453618","rc":[{"atl":[[2.6,1.42]],"id":43167174}],"con":true,"img":false}]}
{"op":"mcm","clk":"5348080120","pt":1646213640848,"mc":[{"id":"1.195453618","rc":[{"atl":[[3.8,0]],"id":39209038},{"atl":[[2.72,0.15]],"id":43167174}],"con":true,"img":false}]}
{"op":"mcm","clk":"5348080126","pt":1646213640965,"mc":[{"id":"1.195453618","rc":[{"atl":[[3.9,14.46]],"id":39209038},{"atl":[[2.6,0]],"id":43167174}],"con":true,"img":false}]}
{"op":"mcm","clk":"5348080132","pt":1646213641055,"mc":[{"id":"1.195453618","rc":[{"atl":[[2.72,1.57]],"id":43167174}],"con":true,"img":false}]}
{"op":"mcm","clk":"5348080638","pt":1646213648255,"mc":[{"id":"1.195453618","rc":[{"atb":[[2.76,0]],"id":40908229}],"con":true,"img":false}]}
{"op":"mcm","clk":"5348080641","pt":1646213648356,"mc":[{"id":"1.195453618","rc":[{"atb":[[2.72,25.34]],"id":40908229}],"con":true,"img":false}]}
{"op":"mcm","clk":"5348080743","pt":1646213650169,"mc":[{"id":"1.195453618","rc":[{"atl":[[3.95,50.85]],"id":39209038},{"atl":[[2.78,28.09]],"id":43167174},{"atb":[[2.64,24.51]],"id":40908229},{"atb":[[1.35,142.86]],"id":42390009}],"con":true,"img":false}]}
{"op":"mcm","clk":"5348081378","pt":1646213660204,"mc":[{"id":"1.195453618","rc":[{"atl":[[4.1,24.19]],"id":39209038},{"atl":[[2.82,41.21]],"id":43167174},{"atb":[[2.6,100.06]],"id":40908229},{"atb":[[1.33,227.27]],"id":42390009}],"con":true,"img":false}]}
{"op":"mcm","clk":"5348081495","pt":1646213661808,"mc":[{"id":"1.195453618","rc":[{"atb":[[1.38,94.89]],"id":42300273},{"atl":[[8,0.15]],"id":39980030}],"con":true,"img":false}]}
{"op":"mcm","clk":"5348081504","pt":1646213661870,"mc":[{"id":"1.195453618","rc":[{"atb":[[1.4,82.9]],"id":42300273},{"atl":[[7,3.43]],"id":39980030}],"con":true,"img":false}]}
{"op":"mcm","clk":"5348081676","pt":1646213664700,"mc":[{"id":"1.195453618","rc":[{"atb":[[1.41,20.33]],"id":42300273}],"con":true,"img":false}]}
{"op":"mcm","clk":"5348082040","pt":1646213670196,"mc":[{"id":"1.195453618","rc":[{"atl":[[4.3,37.88]],"id":39209038},{"atl":[[2.86,67.2]],"id":43167174},{"atb":[[2.56,64.42]],"id":40908229}],"con":true,"img":false}]}
{"op":"mcm","clk":"5348082050","pt":1646213670304,"mc":[{"id":"1.195453618","rc":[{"atb":[[1.31,250]],"id":42390009}],"con":true,"img":false}]}
{"op":"mcm","clk":"5348082071","pt":1646213670604,"mc":[{"id":"1.195453618","rc":[{"atb":[[1.43,17.48]],"id":42300273}],"con":true,"img":false}]}
{"op":"mcm","clk":"5348082116","pt":1646213671431,"mc":[{"id":"1.195453618","rc":[{"atb":[[1.42,0]],"id":42300273}],"con":true,"img":false}]}
{"op":"mcm","clk":"5348082124","pt":1646213671489,"mc":[{"id":"1.195453618","rc":[{"atb":[[1.44,6.17]],"id":42300273}],"con":true,"img":false}]}
{"op":"mcm","clk":"5348082473","pt":1646213677814,"mc":[{"id":"1.195453618","rc":[{"atl":[[8,4.4]],"id":40812743}],"con":true,"img":false}]}
{"op":"mcm","clk":"5348082480","pt":1646213677920,"mc":[{"id":"1.195453618","rc":[{"atl":[[7.8,3.8]],"id":40812743}],"con":true,"img":false}]}
{"op":"mcm","clk":"5348082577","pt":1646213679931,"mc":[{"id":"1.195453618","rc":[{"atl":[[8,3.14]],"id":40812743}],"con":true,"img":false}]}
{"op":"mcm","clk":"5348082583","pt":1646213680037,"mc":[{"id":"1.195453618","rc":[{"atl":[[7.8,5.07]],"id":40812743}],"con":true,"img":false}]}
{"op":"mcm","clk":"5348082588","pt":1646213680196,"mc":[{"id":"1.195453618","rc":[{"atb":[[2.66,0]],"id":40908229}],"con":true,"img":false}]}
{"op":"mcm","clk":"5348082838","pt":1646213684748,"mc":[{"id":"1.195453618","rc":[{"atb":[[1.37,135.14],[1.39,51.28]],"id":42390009}],"con":true,"img":false}]}
{"op":"mcm","clk":"5348082878","pt":1646213685328,"mc":[{"id":"1.195453618","rc":[{"atl":[[8,0],[7.6,3.31]],"id":40812743}],"con":true,"img":false}]}
{"op":"mcm","clk":"5348083003","pt":1646213687916,"mc":[{"id":"1.195453618","rc":[{"atl":[[7.8,3.8]],"id":40812743}],"con":true,"img":false}]}
{"op":"mcm","clk":"5348083013","pt":1646213688023,"mc":[{"id":"1.195453618","rc":[{"atl":[[7.6,4.57]],"id":40812743}],"con":true,"img":false}]}
{"op":"mcm","clk":"5348083388","pt":1646213694741,"mc":[{"id":"1.195453618","rc":[{"atb":[[1.37,270.28]],"id":42390009}],"con":true,"img":false}]}
{"op":"mcm","clk":"5348083517","pt":1646213697228,"mc":[{"id":"1.195453618","rc":[{"atb":[[1.31,0]],"id":42390009}],"con":true,"img":false}]}
{"op":"mcm","clk":"5348083973","pt":1646213704769,"mc":[{"id":"1.195453618","rc":[{"spn":6.05,"spf":"NaN","id":40812743},{"spn":2.26,"spf":"NaN","id":43167174},{"spn":2.93,"spf":"NaN","id":40908229},{"atb":[[1.35,214.29]],"id":42390009},{"spn":5.1,"spf":"NaN","id":39980030}],"con":true,"img":false}]}
{"op":"mcm","clk":"5348084133","pt":1646213707669,"mc":[{"id":"1.195453618","rc":[{"atb":[[1.37,189.19],[1.39,0]],"id":42390009}],"con":true,"img":false}]}
{"op":"mcm","clk":"5348084181","pt":1646213708493,"mc":[{"id":"1.195453618","rc":[{"atl":[[2.74,0],[2.62,12.35]],"id":43167174}],"con":true,"img":false}]}
{"op":"mcm","clk":"5348084210","pt":1646213708862,"mc":[{"id":"1.195453618","rc":[{"atl":[[2.72,0.15]],"id":43167174}],"con":true,"img":false}]}
{"op":"mcm","clk":"5348084214","pt":1646213708963,"mc":[{"id":"1.195453618","rc":[{"atl":[[2.6,1.42],[2.62,0],[2.74,11.49]],"id":43167174}],"con":true,"img":false}]}
{"op":"mcm","clk":"5348084234","pt":1646213709375,"mc":[{"id":"1.195453618","rc":[{"atl":[[2.72,0]],"id":43167174}],"con":true,"img":false}]}
{"op":"mcm","clk":"5348084239","pt":1646213709479,"mc":[{"id":"1.195453618","rc":[{"atl":[[2.6,0.15]],"id":43167174}],"con":true,"img":false}]}
{"op":"mcm","clk":"5348084246","pt":1646213709582,"mc":[{"id":"1.195453618","rc":[{"atl":[[2.72,1.42]],"id":43167174}],"con":true,"img":false}]}
{"op":"mcm","clk":"5348084253","pt":1646213709688,"mc":[{"id":"1.195453618","rc":[{"atl":[[2.6,0]],"id":43167174}],"con":true,"img":false}]}
{"op":"mcm","clk":"5348084264","pt":1646213709790,"mc":[{"id":"1.195453618","rc":[{"atl":[[2.72,1.57]],"id":43167174}],"con":true,"img":false}]}
{"op":"mcm","clk":"5348084360","pt":1646213711390,"mc":[{"id":"1.195453618","rc":[{"atb":[[1.36,55.56]],"id":43167175}],"con":true,"img":false}]}
{"op":"mcm","clk":"5348084365","pt":1646213711493,"mc":[{"id":"1.195453618","rc":[{"atl":[[3.85,0],[3.4,8.33]],"id":39209038},{"atb":[[1.45,0],[1.53,44.52],[1.35,0],[1.63,29.68]],"id":40812743},{"atb":[[1.63,31.75],[1.69,0]],"id":43167174},{"atl":[[5,25],[5.4,4.55]],"id":42300273},{"atb":[[1.18,0],[1.26,250],[1.08,0]],"id":43167175},{"atb":[[2.68,0],[2.76,9.14]],"id":40908229},{"atb":[[2.82,109.79],[3.05,71.22]],"id":39980030},{"atl":[[9.2,0],[8.8,2.56]],"id":39980030}],"con":true,"img":false}]}
{"op":"mcm","clk":"5348084606","pt":1646213715424,"mc":[{"id":"1.195453618","rc":[{"atb":[[1.67,0]],"id":43167174},{"atl":[[5.2,0]],"id":42300273}],"con":true,"img":false}]}
{"op":"mcm","clk":"5348084651","pt":1646213716198,"mc":[{"id":"1.195453618","rc":[{"atb":[[1.65,153.56]],"id":43167174},{"atb":[[1.33,60.61],[1.36,0]],"id":43167175}],"con":true,"img":false}]}
{"op":"mcm","clk":"5348084722","pt":1646213717700,"mc":[{"id":"1.195453618","rc":[{"atb":[[1.35,142.86]],"id":42390009}],"con":true,"img":false}]}
{"op":"mcm","clk":"5348084915","pt":1646213721385,"mc":[{"id":"1.195453618","rc":[{"atl":[[3.5,20]],"id":39209038},{"atb":[[1.61,76.63]],"id":40812743},{"atb":[[1.61,81.97]],"id":43167174},{"atl":[[5.6,0]],"id":42300273},{"atb":[[2.72,48.71]],"id":40908229},{"atl":[[9.2,6.1]],"id":39980030}],"con":true,"img":false}]}
