{"op":"mcm","clk":"5305619443","pt":1646080581435,"mc":[{"id":"1.195395431","marketDefinition":{"bspMarket":true,"turnInPlayEnabled":false,"persistenceEnabled":false,"marketBaseRate":7.0,"eventId":"31270458","eventTypeId":"4339","numberOfWinners":1,"bettingType":"ODDS","marketType":"WIN","marketTime":"2022-03-01T03:57:00.000Z","suspendTime":"2022-03-01T03:57:00.000Z","bspReconciled":false,"complete":true,"inPlay":false,"crossMatching":false,"runnersVoidable":false,"numberOfActiveRunners":8,"betDelay":0,"status":"OPEN","runners":[{"status":"ACTIVE","sortPriority":1,"id":39296632,"name":"1. Evolution Girl"},{"status":"ACTIVE","sortPriority":2,"id":38124326,"name":"2. Nanny In Town"},{"status":"ACTIVE","sortPriority":3,"id":41729332,"name":"3. Highland Wonder"},{"status":"ACTIVE","sortPriority":4,"id":27453791,"name":"4. Headwall"},{"status":"ACTIVE","sortPriority":5,"id":41375430,"name":"6. Just Posh"},{"status":"ACTIVE","sortPriority":6,"id":41375435,"name":"7. Rojo Diamond"},{"status":"ACTIVE","sortPriority":7,"id":35784172,"name":"8. Buckle Up Kenzie"},{"status":"ACTIVE","sortPriority":8,"id":41375426,"name":"9. Wynburn Rebel"}],"regulators":["MR_INT"],"venue":"Devonport","countryCode":"AU","discountAllowed":true,"timezone":"Australia/Sydney","openDate":"2022-03-01T02:00:00.000Z","version":4380714810,"name":"R7 452m Heat","eventName":"Devonport (AUS) 1st Mar"},"rc":[],"con":true,"img":false}]}
{"op":"mcm","clk":"5305743101","pt":1646082026907,"mc":[{"id":"1.195395431","rc":[{"atb":[[4.8,26.7],[4.3,30.75],[5.3,23.6],[6,20.29]],"id":39296632},{"atl":[[36,5.66],[19,7.34],[23,6],[28,7.34]],"id":39296632},{"spn":12.5,"spf":"NaN","id":39296632},{"atb":[[1.6,169.15],[1.55,184.53],[1.67,151.48],[1.5,202.98]],"id":41375435},{"atl":[[3.45,80.92],[3.2,60.08],[3.7,73.43],[2.98,66.75]],"id":41375435},{"spn":2.32,"spf":"NaN","id":41375435},{"atb":[[4.8,26.7],[5.8,21.14],[5.3,23.6],[7,16.91]],"id":41729332},{"atl":[[38,5.35],[24,5.74],[48,4.21],[29,4.72]],"id":41729332},{"spn":15.5,"spf":"NaN","id":41729332},{"atb":[[6.4,18.79],[7.4,15.86],[9.8,11.53],[8.4,13.71]],"id":27453791},{"atl":[[80,1.67],[160,1.24],[55,2.44],[110,1.81]],"id":27453791},{"spn":32.4,"spf":"NaN","id":27453791},{"atb":[[2.74,58.33],[2.64,61.88],[2.98,51.26],[2.84,55.15]],"id":41375430},{"atl":[[8,18.88],[9,16.52],[10,22.03],[12.5,17.24]],"id":41375430},{"spn":5.49,"spf":"NaN","id":41375430},{"atb":[[70,1.47],[34,3.07],[44,2.36],[27,3.9]],"id":38124326},{"atl":[[560,0.35],[410,0.32],[460,0.28],[510,0.38]],"id":38124326},{"spn":240.0,"spf":"NaN","id":38124326},{"atb":[[5,25.37],[5.5,22.55],[7.4,15.86],[6,20.29]],"id":35784172},{"atl":[[70,2.87],[38,3.57],[48,4.21],[29,4.72]],"id":35784172},{"spn":18.2,"spf":"NaN","id":35784172},{"atb":[[4.8,26.7],[5.8,21.14],[5.3,23.6],[7,16.91]],"id":41375426},{"atl":[[38,5.35],[24,5.74],[48,4.21],[29,4.72]],"id":41375426},{"spn":15.5,"spf":"NaN","id":41375426}],"con":true,"img":false}]}
{"op":"mcm","clk":"5305747397","pt":1646082083779,"mc":[{"id":"1.195395431","rc":[{"atb":[[4.8,0],[4.3,0],[5.3,0],[6,0]],"id":39296632},{"atl":[[36,0],[19,0],[23,0],[28,0]],"id":39296632},{"atb":[[1.6,0],[1.55,0],[1.67,0],[1.5,0]],"id":41375435},{"atl":[[3.45,0],[3.2,0],[3.7,0],[2.98,0]],"id":41375435},{"atb":[[4.8,0],[5.8,0],[5.3,0],[7,0]],"id":41729332},{"atl":[[38,0],[24,0],[48,0],[29,0]],"id":41729332},{"atb":[[6.4,0],[7.4,0],[9.8,0],[8.4,0]],"id":27453791},{"atl":[[80,0],[160,0],[55,0],[110,0]],"id":27453791},{"atb":[[2.74,0],[2.64,0],[2.98,0],[2.84,0]],"id":41375430},{"atl":[[8,0],[9,0],[10,0],[12.5,0]],"id":41375430},{"atb":[[70,0],[34,0],[44,0],[27,0]],"id":38124326},{"atl":[[560,0],[410,0],[460,0],[510,0]],"id":38124326},{"atb":[[5,0],[5.5,0],[7.4,0],[6,0]],"id":35784172},{"atl":[[70,0],[38,0],[48,0],[29,0]],"id":35784172},{"atb":[[4.8,0],[5.8,0],[5.3,0],[7,0]],"id":41375426},{"atl":[[38,0],[24,0],[48,0],[29,0]],"id":41375426}],"con":true,"img":false}]}
{"op":"mcm","clk":"5305747684","pt":1646082087094,"mc":[{"id":"1.195395431","rc":[{"atb":[[4.8,26.7],[4.3,30.75],[5.3,23.6],[6,20.29]],"id":39296632},{"atl":[[36,5.66],[19,7.34],[23,6],[28,7.34]],"id":39296632},{"atb":[[1.6,169.15],[1.55,184.53],[1.67,151.48],[1.5,202.98]],"id":41375435},{"atl":[[3.45,80.92],[3.2,60.08],[3.7,73.43],[2.98,66.75]],"id":41375435},{"atb":[[4.8,26.7],[5.8,21.14],[5.3,23.6],[7,16.91]],"id":41729332},{"atl":[[38,5.35],[24,5.74],[48,4.21],[29,4.72]],"id":41729332},{"atb":[[2.74,58.33],[2.64,61.88],[2.98,51.26],[2.84,55.15]],"id":41375430},{"atl":[[8,18.88],[9,16.52],[10,22.03],[12.5,17.24]],"id":41375430},{"atb":[[6.4,18.79],[7.4,15.86],[9.8,11.53],[8.4,13.71]],"id":27453791},{"atl":[[80,1.67],[160,1.24],[55,2.44],[110,1.81]],"id":27453791},{"atb":[[70,1.47],[34,3.07],[44,2.36],[27,3.9]],"id":38124326},{"atl":[[560,0.35],[410,0.32],[460,0.28],[510,0.38]],"id":38124326},{"atb":[[5,25.37],[5.5,22.55],[7.4,15.86],[6,20.29]],"id":35784172},{"atl":[[70,2.87],[38,3.57],[48,4.21],[29,4.72]],"id":35784172},{"atb":[[4.8,26.7],[5.8,21.14],[5.3,23.6],[7,16.91]],"id":41375426},{"atl":[[38,5.35],[24,5.74],[48,4.21],[29,4.72]],"id":41375426}],"con":true,"img":false}]}
{"op":"mcm","clk":"5305762942","pt":1646082292224,"mc":[{"id":"1.195395431","rc":[{"atl":[[24,0.18]],"id":41375426},{"trd":[[24,11.11]],"ltp":24.0,"tv":11.11,"id":41375426}],"con":true,"img":false}]}
{"op":"mcm","clk":"5305763142","pt":1646082295106,"mc":[{"id":"1.195395431","rc":[{"atl":[[24,0],[29,0.3]],"id":41375426},{"trd":[[29,8.82],[24,11.49]],"ltp":29.0,"tv":20.31,"id":41375426}],"con":true,"img":false}]}
{"op":"mcm","clk":"5305767161","pt":1646082352333,"mc":[{"id":"1.195395431","rc":[{"atb":[[4.8,0],[5.8,0],[5.3,0],[7,0]],"id":41375426},{"atl":[[38,0],[48,0],[29,0]],"id":41375426},{"spn":"NaN","spf":"NaN","id":41375426}],"con":true,"img":false}]}
{"op":"mcm","clk":"5305767422","pt":1646082356443,"mc":[{"id":"1.195395431","rc":[{"atb":[[18,9.73],[21,8.27],[28,6.12],[15.5,11.41]],"id":41375426},{"atl":[[290,0.28],[340,0.35],[390,0.31],[240,0.34]],"id":41375426}],"con":true,"img":false}]}
{"op":"mcm","clk":"5305885869","pt":1646083972659,"mc":[{"id":"1.195395431","rc":[{"atb":[[4.8,0],[4.3,0],[5.3,0],[6,0]],"id":39296632},{"atl":[[36,0],[19,0],[23,0],[28,0]],"id":39296632},{"spn":"NaN","spf":"NaN","id":39296632},{"atb":[[1.6,0],[1.55,0],[1.67,0],[1.5,0]],"id":41375435},{"atl":[[3.45,0],[3.2,0],[3.7,0],[2.98,0]],"id":41375435},{"spn":"NaN","spf":"NaN","id":41375435},{"atb":[[4.8,0],[5.8,0],[5.3,0],[7,0]],"id":41729332},{"atl":[[38,0],[24,0],[48,0],[29,0]],"id":41729332},{"spn":"NaN","spf":"NaN","id":41729332},{"atb":[[6.4,0],[7.4,0],[9.8,0],[8.4,0]],"id":27453791},{"atl":[[80,0],[160,0],[55,0],[110,0]],"id":27453791},{"spn":"NaN","spf":"NaN","id":27453791},{"atb":[[2.74,0],[2.64,0],[2.98,0],[2.84,0]],"id":41375430},{"atl":[[8,0],[9,0],[10,0],[12.5,0]],"id":41375430},{"spn":"NaN","spf":"NaN","id":41375430},{"atb":[[5,0],[5.5,0],[7.4,0],[6,0]],"id":35784172},{"atl":[[70,0],[38,0],[48,0],[29,0]],"id":35784172},{"spn":"NaN","spf":"NaN","id":35784172},{"atb":[[18,0],[21,0],[28,0],[15.5,0]],"id":41375426},{"atl":[[290,0],[340,0],[390,0],[240,0]],"id":41375426}],"con":true,"img":false}]}
{"op":"mcm","clk":"5305886418","pt":1646083981498,"mc":[{"id":"1.195395431","rc":[{"atb":[[4.8,26.04],[5.8,20.61],[5.3,23.01],[7,16.49]],"id":39296632},{"atl":[[38,5.44],[24,5.83],[48,4.28],[29,4.79]],"id":39296632},{"atb":[[1.6,164.92],[1.55,179.91],[1.67,147.69],[1.5,197.91]],"id":41375435},{"atl":[[3.45,82.17],[3.2,61.01],[3.7,74.56],[2.98,67.78]],"id":41375435},{"atb":[[6.4,18.32],[7.4,15.45],[9.8,11.24],[8.4,13.37]],"id":41729332},{"atl":[[80,1.69],[160,1.26],[55,2.48],[110,1.84]],"id":41729332},{"atb":[[2.5,65.96],[2.6,61.84],[2.84,53.77],[2.7,58.2]],"id":41375430},{"atl":[[7.2,21.64],[9.2,24.55],[10.5,21.19],[8.2,18.64]],"id":41375430},{"atb":[[7.2,15.96],[9.2,12.06],[8.2,13.74],[11.5,9.42]],"id":27453791},{"atl":[[80,1.69],[160,1.26],[210,0.96],[110,1.22]],"id":27453791},{"atb":[[9,12.36],[5.8,20.61],[7.6,14.99],[6.6,17.66]],"id":35784172},{"atl":[[65,2.09],[130,1.55],[90,2.26],[46,2.98]],"id":35784172},{"atb":[[16,11.02],[18.5,9.45],[22,7.87],[29,5.9]],"id":41375426},{"atl":[[300,0.27],[350,0.34],[400,0.3],[250,0.32]],"id":41375426}],"con":true,"img":false}]}
{"op":"mcm","clk":"5305897236","pt":1646084185960,"mc":[{"id":"1.195395431","rc":[{"spn":15.5,"spf":"NaN","id":39296632},{"atb":[[1.67,107.7]],"id":41375435},{"trd":[[1.67,79.99]],"ltp":1.67,"tv":79.99,"id":41375435},{"spn":2.32,"spf":"NaN","id":41375435},{"spn":32.4,"spf":"NaN","id":41729332},{"spn":5.02,"spf":"NaN","id":41375430},{"spn":45.75,"spf":"NaN","id":27453791},{"spn":27.5,"spf":"NaN","id":35784172},{"spn":139.5,"spf":"NaN","id":41375426}],"con":true,"img":false}]}
{"op":"mcm","clk":"5305897450","pt":1646084190357,"mc":[{"id":"1.195395431","rc":[{"atb":[[1.68,1.32]],"id":41375435},{"atb":[[2.86,1.29]],"id":41375430}],"con":true,"img":false}]}
{"op":"mcm","clk":"5305897550","pt":1646084192269,"mc":[{"id":"1.195395431","rc":[{"atl":[[2,40]],"id":41375435}],"con":true,"img":false}]}
{"op":"mcm","clk":"5305897577","pt":1646084192888,"mc":[{"id":"1.195395431","rc":[{"atb":[[1.68,0]],"id":41375435}],"con":true,"img":false}]}
{"op":"mcm","clk":"5305897583","pt":1646084192988,"mc":[{"id":"1.195395431","rc":[{"atb":[[1.02,1.32]],"id":41375435}],"con":true,"img":false}]}
{"op":"mcm","clk":"5305907834","pt":1646084392634,"mc":[{"id":"1.195395431","rc":[{"atb":[[4.8,0],[5.8,0],[5.3,0],[7,0]],"id":39296632},{"atl":[[38,0],[24,0],[48,0],[29,0]],"id":39296632},{"spn":"NaN","spf":"NaN","id":39296632},{"atb":[[1.6,0],[1.55,0],[1.67,0],[1.5,0]],"id":41375435},{"atl":[[3.45,0],[3.2,0],[3.7,0],[2.98,0]],"id":41375435},{"spn":1.51,"spf":"NaN","id":41375435},{"atb":[[6.4,0],[7.4,0],[9.8,0],[8.4,0]],"id":41729332},{"atl":[[80,0],[160,0],[55,0],[110,0]],"id":41729332},{"spn":"NaN","spf":"NaN","id":41729332},{"atb":[[2.5,0],[2.6,0],[2.84,0],[2.7,0]],"id":41375430},{"atl":[[7.2,0],[9.2,0],[10.5,0],[8.2,0]],"id":41375430},{"spn":"Infinity","spf":"NaN","id":41375430},{"atb":[[7.2,0],[9.2,0],[8.2,0],[11.5,0]],"id":27453791},{"atl":[[80,0],[160,0],[210,0],[110,0]],"id":27453791},{"spn":"NaN","spf":"NaN","id":27453791},{"atb":[[9,0],[5.8,0],[7.6,0],[6.6,0]],"id":35784172},{"atl":[[65,0],[130,0],[90,0],[46,0]],"id":35784172},{"spn":"NaN","spf":"NaN","id":35784172},{"atb":[[16,0],[18.5,0],[22,0],[29,0]],"id":41375426},{"atl":[[300,0],[350,0],[400,0],[250,0]],"id":41375426},{"spn":"NaN","spf":"NaN","id":41375426}],"con":true,"img":false}]}
{"op":"mcm","clk":"5305907843","pt":1646084392840,"mc":[{"id":"1.195395431","rc":[{"atb":[[1.02,1.28]],"id":39296632},{"atb":[[1.02,1.27]],"id":41729332},{"atb":[[1.02,1.23]],"id":27453791},{"atb":[[1.02,1.21]],"id":35784172},{"atb":[[1.02,1.22]],"id":41375426}],"con":true,"img":false}]}
{"op":"mcm","clk":"5305907850","pt":1646084392942,"mc":[{"id":"1.195395431","rc":[{"atb":[[2.86,0]],"id":41375430}],"con":true,"img":false}]}
{"op":"mcm","clk":"5305907852","pt":1646084393046,"mc":[{"id":"1.195395431","rc":[{"atb":[[1.02,1.29]],"id":41375430}],"con":true,"img":false}]}
{"op":"mcm","clk":"5305908162","pt":1646084398474,"mc":[{"id":"1.195395431","rc":[{"atb":[[5,27.23],[5.5,24.21],[7.4,17.02],[6,21.79]],"id":39296632},{"atl":[[70,2.74],[38,3.41],[48,4.02],[29,4.5]],"id":39296632},{"atb":[[1.6,153.75],[1.55,167.73],[1.67,137.69],[1.5,184.51]],"id":41375435},{"atl":[[3.45,85.45],[3.2,63.44],[3.7,77.54],[2.98,70.49]],"id":41375435},{"atb":[[6.4,20.17],[7.4,17.02],[9.8,12.37],[8.4,14.72]],"id":41729332},{"atl":[[80,1.59],[160,1.19],[55,2.33],[110,1.73]],"id":41729332},{"atb":[[2.5,72.63],[2.6,68.09],[2.84,59.21],[2.7,64.09]],"id":41375430},{"atl":[[7.2,20.35],[9.2,23.08],[10.5,19.93],[8.2,17.53]],"id":41375430},{"atb":[[5,27.23],[5.5,24.21],[7.4,17.02],[6,21.79]],"id":27453791},{"atl":[[70,2.74],[38,3.41],[48,4.02],[29,4.5]],"id":27453791},{"atb":[[9,13.61],[5.8,22.69],[7.6,16.5],[6.6,19.45]],"id":35784172},{"atl":[[65,1.97],[130,1.46],[90,2.12],[46,2.8]],"id":35784172},{"atb":[[16,11.69],[18.5,10.02],[22,8.35],[29,6.26]],"id":41375426},{"atl":[[300,0.24],[350,0.31],[400,0.27],[250,0.29]],"id":41375426}],"con":true,"img":false}]}
{"op":"mcm","clk":"5305908182","pt":1646084398941,"mc":[{"id":"1.195395431","rc":[{"atb":[[1.02,0]],"id":41375430}],"con":true,"img":false}]}
{"op":"mcm","clk":"5305908187","pt":1646084399046,"mc":[{"id":"1.195395431","rc":[{"atb":[[2.86,1.29]],"id":41375430}],"con":true,"img":false}]}
{"op":"mcm","clk":"5305909276","pt":1646084420582,"mc":[{"id":"1.195395431","rc":[{"atb":[[6.4,0],[7.4,0],[9.8,0],[8.4,0]],"id":41729332},{"atl":[[80,0],[160,0],[55,0],[110,0]],"id":41729332},{"atb":[[5,0],[5.5,0],[7.4,0],[6,0]],"id":27453791},{"atl":[[70,0],[38,0],[48,0],[29,0]],"id":27453791},{"atb":[[9,0],[5.8,0],[7.6,0],[6.6,0]],"id":35784172},{"atl":[[65,0],[130,0],[90,0],[46,0]],"id":35784172}],"con":true,"img":false}]}
{"op":"mcm","clk":"5305909467","pt":1646084424376,"mc":[{"id":"1.195395431","rc":[{"atb":[[6.4,20.17],[7.4,17.02],[9.8,12.37],[8.4,14.72]],"id":41729332},{"atl":[[80,1.59],[160,1.19],[55,2.33],[110,1.73]],"id":41729332},{"atb":[[5.5,24.21],[6,21.79],[7,18.16],[8.4,14.72]],"id":27453791},{"atl":[[75,2.56],[40,3.23],[50,2.57],[100,1.91]],"id":27453791},{"atb":[[8,15.56],[6,21.79],[7,18.16],[9.4,12.96]],"id":35784172},{"atl":[[75,1.7],[150,1.27],[50,2.57],[100,1.91]],"id":35784172}],"con":true,"img":false}]}
{"op":"mcm","clk":"5305909493","pt":1646084425000,"mc":[{"id":"1.195395431","rc":[{"atl":[[38,1.22]],"id":27453791},{"atl":[[7,1.31]],"id":41375430},{"atl":[[990,1.34]],"id":38124326},{"atl":[[990,1.22]],"id":41375426}],"con":true,"img":false}]}
{"op":"mcm","clk":"5305909849","pt":1646084431689,"mc":[{"id":"1.195395431","rc":[{"atb":[[7.6,1.54]],"id":39296632},{"atb":[[10,1.64]],"id":41729332},{"atb":[[2.86,2.82]],"id":41375430},{"atb":[[8.6,1.55]],"id":27453791},{"atb":[[9.6,1.64]],"id":35784172}],"con":true,"img":false}]}
{"op":"mcm","clk":"5305911069","pt":1646084457507,"mc":[{"id":"1.195395431","marketDefinition":{"bspMarket":true,"turnInPlayEnabled":false,"persistenceEnabled":false,"marketBaseRate":7.0,"eventId":"31270458","eventTypeId":"4339","numberOfWinners":1,"bettingType":"ODDS","marketType":"WIN","marketTime":"2022-03-01T03:57:00.000Z","suspendTime":"2022-03-01T03:57:00.000Z","bspReconciled":false,"complete":true,"inPlay":false,"crossMatching":true,"runnersVoidable":false,"numberOfActiveRunners":8,"betDelay":0,"status":"OPEN","runners":[{"status":"ACTIVE","sortPriority":1,"id":39296632,"name":"1. Evolution Girl"},{"status":"ACTIVE","sortPriority":2,"id":38124326,"name":"2. Nanny In Town"},{"status":"ACTIVE","sortPriority":3,"id":41729332,"name":"3. Highland Wonder"},{"status":"ACTIVE","sortPriority":4,"id":27453791,"name":"4. Headwall"},{"status":"ACTIVE","sortPriority":5,"id":41375430,"name":"6. Just Posh"},{"status":"ACTIVE","sortPriority":6,"id":41375435,"name":"7. Rojo Diamond"},{"status":"ACTIVE","sortPriority":7,"id":35784172,"name":"8. Buckle Up Kenzie"},{"status":"ACTIVE","sortPriority":8,"id":41375426,"name":"9. Wynburn Rebel"}],"regulators":["MR_INT"],"venue":"Devonport","countryCode":"AU","discountAllowed":true,"timezone":"Australia/Sydney","openDate":"2022-03-01T02:00:00.000Z","version":4380714810,"name":"R7 452m Heat","eventName":"Devonport (AUS) 1st Mar"},"rc":[],"con":true,"img":false}]}
{"op":"mcm","clk":"5305912238","pt":1646084481986,"mc":[{"id":"1.195395431","rc":[{"atb":[[5,0],[5.5,0],[7.4,0],[6,0]],"id":39296632},{"atl":[[70,0],[38,0],[48,0],[29,0]],"id":39296632},{"spn":"Infinity","spf":"NaN","id":39296632},{"spn":1.83,"spf":"NaN","id":41375435},{"spn":32.5,"spf":"NaN","id":41729332},{"spn":4.93,"spf":"NaN","id":41375430},{"atb":[[5.5,0],[6,0],[7,0],[8.4,0]],"id":27453791},{"atl":[[75,0],[40,0],[50,0],[100,0]],"id":27453791},{"spn":23.3,"spf":"NaN","id":27453791},{"atb":[[8,0],[6,0],[7,0],[9.4,0]],"id":35784172},{"atl":[[75,0],[150,0],[50,0],[100,0]],"id":35784172},{"spn":"Infinity","spf":"NaN","id":35784172},{"spn":139.5,"spf":"NaN","id":41375426}],"con":true,"img":false}]}
{"op":"mcm","clk":"5305912277","pt":1646084482764,"mc":[{"id":"1.195395431","rc":[{"atl":[[990,1.3]],"id":39296632},{"atl":[[38,0]],"id":27453791},{"atl":[[990,1.3]],"id":35784172}],"con":true,"img":false}]}
{"op":"mcm","clk":"5305912283","pt":1646084482872,"mc":[{"id":"1.195395431","rc":[{"atb":[[7.6,0]],"id":39296632},{"atb":[[8.6,0]],"id":27453791},{"atl":[[990,1.22]],"id":27453791},{"atb":[[9.6,0]],"id":35784172}],"con":true,"img":false}]}
{"op":"mcm","clk":"5305912288","pt":1646084482977,"mc":[{"id":"1.195395431","rc":[{"atb":[[1.02,2.83]],"id":39296632},{"atb":[[1.02,2.79]],"id":27453791},{"atb":[[1.02,2.86]],"id":35784172}],"con":true,"img":false}]}
{"op":"mcm","clk":"5305912505","pt":1646084488469,"mc":[{"id":"1.195395431","rc":[{"atb":[[8,15.56],[5.8,22.69],[5.3,25.33],[6.6,19.45]],"id":39296632},{"atl":[[65,2.96],[36,3.6],[90,2.12],[46,2.8]],"id":39296632},{"atb":[[5.5,24.21],[6,21.79],[7,18.16],[8.4,14.72]],"id":27453791},{"atl":[[75,2.56],[40,3.23],[50,2.57],[100,1.91]],"id":27453791},{"atb":[[6.4,20.17],[7.4,17.02],[9.8,12.37],[8.4,14.72]],"id":35784172},{"atl":[[80,1.59],[160,1.19],[55,2.33],[110,1.73]],"id":35784172}],"con":true,"img":false}]}
{"op":"mcm","clk":"5305912519","pt":1646084488884,"mc":[{"id":"1.195395431","rc":[{"atl":[[990,0]],"id":39296632},{"atl":[[990,0]],"id":27453791}],"con":true,"img":false}]}
{"op":"mcm","clk":"5305912522","pt":1646084488987,"mc":[{"id":"1.195395431","rc":[{"atl":[[34,1.3]],"id":39296632},{"atl":[[38,1.22]],"id":27453791}],"con":true,"img":false}]}
{"op":"mcm","clk":"5305912538","pt":1646084489247,"mc":[{"id":"1.195395431","rc":[{"atb":[[1.02,1.28]],"id":39296632},{"atb":[[1.02,1.23]],"id":27453791},{"atb":[[1.02,1.21]],"id":35784172}],"con":true,"img":false}]}
{"op":"mcm","clk":"5305912543","pt":1646084489350,"mc":[{"id":"1.195395431","rc":[{"atb":[[8.2,1.54]],"id":39296632},{"atb":[[8.6,1.55]],"id":27453791},{"atb":[[10,1.64]],"id":35784172}],"con":true,"img":false}]}
{"op":"mcm","clk":"5305962906","pt":1646085924678,"mc":[{"id":"1.195395431","rc":[{"atb":[[8,15.55],[5.8,22.69],[8.2,1.54],[5.3,25.33],[1.02,1.28],[6.6,19.45]],"id":39296632},{"atl":[[65,2.96],[34,1.3],[36,3.6],[90,2.12],[46,2.8]],"id":39296632},{"spn":21.1,"spf":"NaN","id":39296632},{"atb":[[1.6,153.73],[1.55,167.71],[1.67,137.67],[1.02,1.32],[1.5,184.48]],"id":41375435},{"atl":[[3.45,85.44],[1.8,20],[3.2,63.43],[3.7,77.52],[2.98,70.48]],"id":41375435},{"trd":[[1.67,79.98]],"ltp":1.67,"tv":79.98,"id":41375435},{"spn":1.73,"spf":"NaN","id":41375435},{"atb":[[6.4,20.17],[10,1.64],[7.4,17.02],[1.02,1.27],[9.8,12.37],[8.4,14.72]],"id":41729332},{"atl":[[80,1.59],[160,1.19],[55,2.33],[110,1.73]],"id":41729332},{"atb":[[8.6,1.55],[5.5,24.2],[1.02,1.23],[6,21.78],[7,18.15],[8.4,14.72]],"id":27453791},{"atl":[[75,2.55],[38,1.22],[40,3.23],[50,2.57],[100,1.91]],"id":27453791},{"atb":[[2.86,2.82],[2.5,72.62],[2.6,68.08],[2.84,59.2],[2.7,64.07]],"id":41375430},{"atl":[[7.2,20.35],[9.2,23.08],[10.5,19.92],[8.2,17.52],[7,1.31]],"id":41375430},{"atb":[[70,1.47],[34,3.07],[44,2.35],[27,3.9]],"id":38124326},{"atl":[[990,1.34]],"id":38124326},{"atb":[[6.4,20.17],[10,1.64],[7.4,17.02],[1.02,1.21],[9.8,12.37],[8.4,14.72]],"id":35784172},{"atl":[[80,1.59],[160,1.19],[55,2.33],[110,1.73],[990,1.3]],"id":35784172},{"spn":32.5,"spf":"NaN","id":35784172},{"atb":[[16,11.69],[18.5,10.02],[22,8.35],[1.02,1.22],[29,6.26]],"id":41375426},{"atl":[[990,1.22]],"id":41375426},{"trd":[[29,8.82],[24,11.49]],"ltp":29.0,"tv":20.31,"id":41375426}],"con":true,"img":false}]}
{"op":"mcm","clk":"5305990513","pt":1646086602699,"mc":[{"id":"1.195395431","marketDefinition":{"bspMarket":true,"turnInPlayEnabled":false,"persistenceEnabled":false,"marketBaseRate":7.0,"eventId":"31270458","eventTypeId":"4339","numberOfWinners":1,"bettingType":"ODDS","marketType":"WIN","marketTime":"2022-03-01T03:57:00.000Z","suspendTime":"2022-03-01T03:57:00.000Z","bspReconciled":false,"complete":true,"inPlay":false,"crossMatching":true,"runnersVoidable":false,"numberOfActiveRunners":8,"betDelay":0,"status":"OPEN","runners":[{"status":"ACTIVE","sortPriority":1,"id":39296632,"name":"1. Evolution Girl"},{"status":"ACTIVE","sortPriority":2,"id":38124326,"name":"2. Nanny In Town"},{"status":"ACTIVE","sortPriority":3,"id":41729332,"name":"3. Highland Wonder"},{"status":"ACTIVE","sortPriority":4,"id":27453791,"name":"4. Headwall"},{"status":"ACTIVE","sortPriority":5,"id":41375430,"name":"6. Just Posh"},{"status":"ACTIVE","sortPriority":6,"id":41375435,"name":"7. Rojo Diamond"},{"status":"ACTIVE","sortPriority":7,"id":35784172,"name":"8. Buckle Up Kenzie"},{"status":"ACTIVE","sortPriority":8,"id":41375426,"name":"9. Wynburn Rebel"}],"regulators":["MR_INT"],"venue":"Devonport","countryCode":"AU","discountAllowed":true,"timezone":"Australia/Sydney","openDate":"2022-03-01T02:00:00.000Z","version":4380714810,"name":"R7 452m Heat","eventName":"Devonport (AUS) 1st Mar"},"rc":[{"atb":[[8,15.55],[5.8,22.69],[8.2,1.54],[5.3,25.33],[1.02,1.28],[6.6,19.45]],"id":39296632},{"atl":[[65,2.96],[34,1.3],[36,3.6],[90,2.12],[46,2.8]],"id":39296632},{"spn":21.1,"spf":"NaN","id":39296632},{"atb":[[1.6,153.73],[1.55,167.71],[1.67,137.67],[1.02,1.32],[1.5,184.48]],"id":41375435},{"atl":[[2,40],[1.8,20],[3.45,85.44],[3.2,63.43],[3.7,77.52],[2.98,70.48]],"id":41375435},{"trd":[[1.67,79.98]],"ltp":1.67,"tv":79.98,"id":41375435},{"spn":1.73,"spf":"NaN","id":41375435},{"atb":[[6.4,20.17],[10,1.64],[7.4,17.02],[1.02,1.27],[9.8,12.37],[8.4,14.72]],"id":41729332},{"atl":[[80,1.59],[160,1.19],[55,2.33],[110,1.73]],"id":41729332},{"spn":32.5,"spf":"NaN","id":41729332},{"atb":[[8.6,1.55],[5.5,24.2],[1.02,1.23],[6,21.78],[7,18.15],[8.4,14.72]],"id":27453791},{"atl":[[75,2.55],[38,1.22],[40,3.23],[50,2.57],[100,1.91]],"id":27453791},{"spn":23.3,"spf":"NaN","id":27453791},{"atb":[[2.86,2.82],[2.5,72.62],[2.6,68.08],[2.84,59.2],[2.7,64.07]],"id":41375430},{"atl":[[7.2,20.35],[9.2,23.08],[10.5,19.92],[8.2,17.52],[7,1.31]],"id":41375430},{"spn":4.93,"spf":"NaN","id":41375430},{"atb":[[70,1.47],[34,3.07],[44,2.35],[27,3.9]],"id":38124326},{"atl":[[560,0.35],[410,0.32],[460,0.28],[990,1.34],[510,0.38]],"id":38124326},{"spn":240.0,"spf":"NaN","id":38124326},{"atb":[[6.4,20.17],[10,1.64],[7.4,17.02],[1.02,1.21],[9.8,12.37],[8.4,14.72]],"id":35784172},{"atl":[[80,1.59],[160,1.19],[55,2.33],[110,1.73],[990,1.3]],"id":35784172},{"spn":32.5,"spf":"NaN","id":35784172},{"atb":[[16,11.69],[18.5,10.02],[22,8.35],[1.02,1.22],[29,6.26]],"id":41375426},{"atl":[[300,0.24],[350,0.31],[400,0.27],[990,1.22],[250,0.29]],"id":41375426},{"trd":[[29,8.82],[24,11.49]],"ltp":29.0,"tv":20.31,"id":41375426},{"spn":139.5,"spf":"NaN","id":41375426}],"con":true,"img":true}]}
{"op":"mcm","clk":"5306049439","pt":1646088052865,"mc":[{"id":"1.195395431","rc":[{"spl":[[1.01,50]],"id":41375435},{"spn":1.67,"spf":1.0,"id":41375435}],"con":true,"img":false}]}
{"op":"mcm","clk":"5306113867","pt":1646089756803,"mc":[{"id":"1.195395431","rc":[{"spl":[[100,2]],"id":39296632},{"spn":21.1,"spf":1.0,"id":39296632},{"spl":[[100,2]],"id":41375435},{"spl":[[100,2]],"id":41729332},{"spn":32.5,"spf":1.0,"id":41729332},{"spl":[[100,2]],"id":27453791},{"spn":23.3,"spf":1.0,"id":27453791},{"spl":[[100,2]],"id":41375430},{"spn":4.93,"spf":1.0,"id":41375430},{"spl":[[100,2]],"id":38124326},{"spn":85.0,"spf":1.0,"id":38124326},{"spl":[[100,2]],"id":35784172},{"spn":32.5,"spf":1.0,"id":35784172},{"spl":[[100,2]],"id":41375426},{"spn":64.5,"spf":1.0,"id":41375426}],"con":true,"img":false}]}
{"op":"mcm","clk":"5306162756","pt":1646091287418,"mc":[{"id":"1.195395431","rc":[{"atb":[[1.67,132.26]],"id":41375435},{"trd":[[1.67,90.8]],"ltp":1.67,"tv":90.8,"id":41375435}],"con":true,"img":false}]}
{"op":"mcm","clk":"5306163116","pt":1646091295021,"mc":[{"id":"1.195395431","rc":[{"spl":[[1.01,55.41]],"id":41375435}],"con":true,"img":false}]}
{"op":"mcm","clk":"5306332255","pt":1646095709893,"mc":[{"id":"1.195395431","rc":[{"atb":[[8,15.54],[5.8,22.67],[8.2,1.54],[5.3,25.31],[1.02,1.28],[6.6,19.43]],"id":39296632},{"spl":[[8.6,2.7]],"id":39296632},{"atl":[[65,2.95],[34,1.3],[36,3.6],[90,2.12],[46,2.8]],"id":39296632},{"spn":8.4,"spf":1.0,"id":39296632},{"atb":[[1.6,153.63],[1.55,167.6],[1.67,132.17],[1.02,1.32],[1.5,184.36]],"id":41375435},{"spl":[[1.01,55.4]],"id":41375435},{"atl":[[3.45,85.38],[3.2,63.39],[3.7,77.47],[2.98,70.43]],"id":41375435},{"trd":[[1.67,90.77]],"ltp":1.67,"tv":90.77,"id":41375435},{"atb":[[6.4,20.15],[10,1.64],[7.4,17.01],[1.02,1.26],[9.8,12.36],[8.4,14.71]],"id":41729332},{"atl":[[80,1.59],[160,1.18],[55,2.33],[110,1.73]],"id":41729332},{"atb":[[8.6,1.55],[5.5,24.19],[1.02,1.23],[6,21.77],[7,18.14],[8.4,14.71]],"id":27453791},{"atl":[[75,2.55],[38,1.21],[40,3.23],[50,2.57],[100,1.9]],"id":27453791},{"atb":[[2.86,2.82],[2.5,72.57],[2.6,68.04],[2.84,59.16],[2.7,64.03]],"id":41375430},{"atl":[[7.2,20.34],[9.2,23.06],[10.5,19.91],[8.2,17.51],[7,1.31]],"id":41375430},{"atb":[[70,1.47],[34,3.07],[44,2.35],[27,3.89]],"id":38124326},{"atl":[[560,0.35],[410,0.32],[460,0.28],[990,1.34],[510,0.38]],"id":38124326},{"atb":[[6.4,20.15],[10,1.64],[7.4,17.01],[1.02,1.21],[9.8,12.36],[8.4,14.71]],"id":35784172},{"atl":[[80,1.59],[160,1.18],[55,2.33],[110,1.73],[990,1.3]],"id":35784172},{"atb":[[16,11.68],[18.5,10.01],[22,8.34],[1.02,1.21],[29,6.25]],"id":41375426},{"atl":[[300,0.24],[350,0.31],[400,0.27],[990,1.21],[250,0.29]],"id":41375426},{"trd":[[29,8.81],[24,11.48]],"ltp":29.0,"tv":20.29,"id":41375426}],"con":true,"img":false}]}
{"op":"mcm","clk":"5306433866","pt":1646098064596,"mc":[{"id":"1.195395431","rc":[{"atb":[[2.88,4.88]],"id":41375430},{"spn":4.94,"spf":1.0,"id":41375430}],"con":true,"img":false}]}
{"op":"mcm","clk":"5306433877","pt":1646098064902,"mc":[{"id":"1.195395431","rc":[{"atb":[[2.86,1.29]],"id":41375430}],"con":true,"img":false}]}
{"op":"mcm","clk":"5306433884","pt":1646098064957,"mc":[{"id":"1.195395431","rc":[{"atb":[[2.9,1.52]],"id":41375430}],"con":true,"img":false}]}
{"op":"mcm","clk":"5306433891","pt":1646098065162,"mc":[{"id":"1.195395431","rc":[{"atb":[[2.86,0]],"id":41375430}],"con":true,"img":false}]}
{"op":"mcm","clk":"5306433895","pt":1646098065265,"mc":[{"id":"1.195395431","rc":[{"atb":[[2.88,6.18]],"id":41375430}],"con":true,"img":false}]}
{"op":"mcm","clk":"5306436996","pt":1646098132407,"mc":[{"id":"1.195395431","rc":[{"atb":[[2.88,10.98]],"id":41375430},{"spn":4.95,"spf":1.0,"id":41375430}],"con":true,"img":false}]}
{"op":"mcm","clk":"5306480833","pt":1646099241686,"mc":[{"id":"1.195395431","rc":[{"atb":[[8,0],[5.8,0],[5.3,0],[6.6,0]],"id":39296632},{"atl":[[65,0],[36,0],[90,0],[46,0]],"id":39296632},{"atb":[[6.4,0],[7.4,0],[9.8,0],[8.4,0]],"id":41729332},{"atl":[[80,0],[160,0],[55,0],[110,0]],"id":41729332},{"spn":55.0,"spf":1.0,"id":41729332},{"atb":[[2.5,0],[2.6,0],[2.84,0],[2.7,0]],"id":41375430},{"atl":[[7.2,0],[9.2,0],[10.5,0],[8.2,0]],"id":41375430},{"atb":[[5.5,0],[6,0],[7,0],[8.4,0]],"id":27453791},{"atl":[[75,0],[40,0],[50,0],[100,0]],"id":27453791},{"atb":[[70,0],[34,0],[44,0],[27,0]],"id":38124326},{"atl":[[560,0],[410,0],[460,0],[510,0]],"id":38124326},{"spn":1.0,"spf":1.0,"id":38124326},{"atb":[[6.4,0],[7.4,0],[9.8,0],[8.4,0]],"id":35784172},{"atl":[[80,0],[160,0],[55,0],[110,0]],"id":35784172},{"spn":55.0,"spf":1.0,"id":35784172},{"atb":[[16,0],[18.5,0],[22,0],[29,0]],"id":41375426},{"atl":[[300,0],[350,0],[400,0],[250,0]],"id":41375426},{"spn":50.51,"spf":1.0,"id":41375426}],"con":true,"img":false}]}
{"op":"mcm","clk":"5306480851","pt":1646099241994,"mc":[{"id":"1.195395431","rc":[{"atl":[[990,1.27]],"id":41729332}],"con":true,"img":false}]}
{"op":"mcm","clk":"5306480857","pt":1646099242100,"mc":[{"id":"1.195395431","rc":[{"atb":[[8.2,0]],"id":39296632},{"atl":[[34,0]],"id":39296632},{"atb":[[10,0]],"id":41729332},{"atb":[[8.6,0]],"id":27453791},{"atl":[[38,0]],"id":27453791},{"atb":[[2.9,0]],"id":41375430},{"atl":[[7,0]],"id":41375430},{"atb":[[1.02,1.49]],"id":38124326},{"atb":[[10,0]],"id":35784172},{"atb":[[1.02,2.88]],"id":41375426}],"con":true,"img":false}]}
{"op":"mcm","clk":"5306480862","pt":1646099242154,"mc":[{"id":"1.195395431","rc":[{"atb":[[1.02,2.83]],"id":39296632},{"atl":[[990,1.3]],"id":39296632},{"atb":[[1.02,2.91]],"id":41729332},{"atb":[[1.02,2.79]],"id":27453791},{"atl":[[990,1.21]],"id":27453791},{"atb":[[1.01,1.52]],"id":41375430},{"atl":[[990,1.31]],"id":41375430},{"atb":[[1.02,2.85]],"id":35784172}],"con":true,"img":false}]}
{"op":"mcm","clk":"5306480870","pt":1646099242258,"mc":[{"id":"1.195395431","rc":[{"atb":[[1.02,2.77]],"id":38124326}],"con":true,"img":false}]}
{"op":"mcm","clk":"5306480878","pt":1646099242360,"mc":[{"id":"1.195395431","rc":[{"atb":[[2.88,9.68]],"id":41375430}],"con":true,"img":false}]}
{"op":"mcm","clk":"5306480884","pt":1646099242464,"mc":[{"id":"1.195395431","rc":[{"atb":[[1.02,1.29]],"id":41375430}],"con":true,"img":false}]}
{"op":"mcm","clk":"5306481143","pt":1646099248366,"mc":[{"id":"1.195395431","rc":[{"atb":[[2.88,4.88]],"id":41375430}],"con":true,"img":false}]}
{"op":"mcm","clk":"5306481149","pt":1646099248573,"mc":[{"id":"1.195395431","rc":[{"atb":[[8,15.74],[5.8,22.95],[5.3,25.63],[6.6,19.68]],"id":39296632},{"atl":[[65,2.93],[36,3.57],[90,2.1],[46,2.78]],"id":39296632},{"atb":[[9.6,12.81],[8.6,14.5],[7.6,16.7],[12.5,9.58]],"id":41729332},{"atl":[[130,0.96],[90,1.4],[180,1.04],[230,0.81]],"id":41729332},{"atb":[[2.5,73.47],[2.6,68.88],[2.84,59.9],[2.7,64.83]],"id":41375430},{"atl":[[7.2,20.16],[9.2,22.87],[10.5,19.74],[8.2,17.36]],"id":41375430},{"atb":[[5.5,24.49],[6,22.04],[7,18.36],[8.4,14.89]],"id":27453791},{"atl":[[75,2.53],[40,3.2],[50,2.55],[100,1.89]],"id":27453791},{"atb":[[70,1.59],[34,3.34],[44,2.56],[27,4.24]],"id":38124326},{"atl":[[560,0.33],[410,0.3],[460,0.27],[510,0.36]],"id":38124326},{"atb":[[6.4,20.41],[7.4,17.22],[9.8,12.52],[8.4,14.89]],"id":35784172},{"atl":[[80,1.58],[160,1.17],[55,2.31],[110,1.71]],"id":35784172},{"atb":[[16,11.77],[18.5,10.09],[22,8.41],[29,6.3]],"id":41375426},{"atl":[[300,0.23],[350,0.3],[400,0.27],[250,0.28]],"id":41375426}],"con":true,"img":false}]}
{"op":"mcm","clk":"5306481184","pt":1646099249289,"mc":[{"id":"1.195395431","rc":[{"atl":[[990,0]],"id":39296632},{"atl":[[990,0]],"id":27453791},{"atl":[[990,0]],"id":41375430}],"con":true,"img":false}]}
{"op":"mcm","clk":"5306481189","pt":1646099249392,"mc":[{"id":"1.195395431","rc":[{"atb":[[1.02,1.28]],"id":39296632},{"atl":[[34,1.3]],"id":39296632},{"atb":[[1.01,0],[1.02,0]],"id":41375430},{"atl":[[7,1.31]],"id":41375430},{"atb":[[1.02,1.23]],"id":27453791},{"atl":[[38,1.21]],"id":27453791},{"atb":[[1.02,1.21]],"id":35784172}],"con":true,"img":false}]}
{"op":"mcm","clk":"5306481194","pt":1646099249495,"mc":[{"id":"1.195395431","rc":[{"atb":[[8.2,1.54]],"id":39296632},{"atb":[[2.88,6.18],[2.9,1.52]],"id":41375430},{"atb":[[8.6,1.55]],"id":27453791},{"atb":[[10,1.64]],"id":35784172}],"con":true,"img":false}]}
{"op":"mcm","clk":"5306482163","pt":1646099269628,"mc":[{"id":"1.195395431","rc":[{"atb":[[2.88,10.98]],"id":41375430}],"con":true,"img":false}]}
{"op":"mcm","clk":"5306507308","pt":1646099820159,"mc":[{"id":"1.195395431","rc":[{"atb":[[7.6,1.53]],"id":39296632},{"atb":[[1.15,2]],"id":41375435},{"atb":[[7.6,18.23]],"id":41729332},{"spn":51.25,"spf":1.0,"id":41729332},{"atb":[[2.72,2]],"id":41375430},{"atb":[[8.2,1.4]],"id":27453791},{"atb":[[95,0.12]],"id":38124326},{"spn":97.5,"spf":1.0,"id":38124326},{"atb":[[10.5,1.06]],"id":35784172},{"spn":32.75,"spf":1.0,"id":35784172},{"spn":64.5,"spf":1.0,"id":41375426}],"con":true,"img":false}]}
{"op":"mcm","clk":"5306542660","pt":1646100545309,"mc":[{"id":"1.195395431","rc":[{"atb":[[8,15.75],[5.8,22.96],[8.2,1.54],[5.3,25.64],[1.02,1.28],[6.6,19.69]],"id":39296632},{"spl":[[8.6,2.7]],"id":39296632},{"atl":[[65,2.93],[34,1.3],[36,3.57],[90,2.11],[46,2.78]],"id":39296632},{"atb":[[1.6,153.69],[1.55,167.67],[1.67,132.23],[1.02,1.32],[1.5,184.44]],"id":41375435},{"spl":[[1.01,55.41]],"id":41375435},{"atl":[[3.45,85.42],[3.2,63.42],[3.7,77.51],[2.98,70.46]],"id":41375435},{"trd":[[1.67,90.79]],"ltp":1.67,"tv":90.79,"id":41375435},{"atb":[[9.6,12.82],[8.6,14.5],[1.02,2.91],[7.6,16.7],[12.5,9.58]],"id":41729332},{"atl":[[130,0.96],[90,1.4],[180,1.04],[230,0.81],[990,1.27]],"id":41729332},{"atb":[[8.6,1.55],[5.5,24.5],[1.02,1.23],[6,22.05],[7,18.37],[8.4,14.9]],"id":27453791},{"atl":[[75,2.53],[38,1.21],[40,3.2],[50,2.55],[100,1.89]],"id":27453791},{"atb":[[2.88,10.97],[2.9,1.52],[2.5,73.5],[2.6,68.91],[2.84,59.92],[2.7,64.86]],"id":41375430},{"atl":[[7.2,20.17],[9.2,22.88],[10.5,19.75],[8.2,17.37],[7,1.31]],"id":41375430},{"atb":[[70,1.59],[34,3.34],[44,2.56],[1.02,2.77],[27,4.24]],"id":38124326},{"atl":[[560,0.33],[410,0.3],[460,0.27],[990,1.34],[510,0.36]],"id":38124326},{"atb":[[6.4,20.42],[10,1.64],[7.4,17.22],[1.02,1.21],[9.8,12.53],[8.4,14.9]],"id":35784172},{"atl":[[80,1.58],[160,1.17],[55,2.31],[110,1.72],[990,1.3]],"id":35784172},{"atb":[[16,11.77],[18.5,10.09],[22,8.41],[1.02,2.88],[29,6.3]],"id":41375426},{"atl":[[300,0.23],[350,0.3],[400,0.27],[990,1.21],[250,0.28]],"id":41375426},{"trd":[[29,8.81],[24,11.49]],"ltp":29.0,"tv":20.3,"id":41375426}],"con":true,"img":false}]}
{"op":"mcm","clk":"5306542663","pt":1646100545408,"mc":[{"id":"1.195395431","rc":[{"atb":[[11.5,0.96]],"id":41729332}],"con":true,"img":false}]}
{"op":"mcm","clk":"5306567219","pt":1646101070921,"mc":[{"id":"1.195395431","rc":[{"atb":[[7.6,0]],"id":39296632},{"atb":[[1.15,0]],"id":41375435},{"atb":[[11.5,0]],"id":41729332},{"atb":[[8.2,0]],"id":27453791},{"atb":[[2.72,0]],"id":41375430},{"atb":[[95,0]],"id":38124326},{"spn":85.0,"spf":1.0,"id":38124326},{"atb":[[10.5,0]],"id":35784172},{"spn":32.5,"spf":1.0,"id":35784172}],"con":true,"img":false}]}
{"op":"mcm","clk":"5306568752","pt":1646101104275,"mc":[{"id":"1.195395431","marketDefinition":{"bspMarket":true,"turnInPlayEnabled":false,"persistenceEnabled":false,"marketBaseRate":7.0,"eventId":"31270458","eventTypeId":"4339","numberOfWinners":1,"bettingType":"ODDS","marketType":"WIN","marketTime":"2022-03-01T04:22:00.000Z","suspendTime":"2022-03-01T04:22:00.000Z","bspReconciled":false,"complete":true,"inPlay":false,"crossMatching":true,"runnersVoidable":false,"numberOfActiveRunners":8,"betDelay":0,"status":"OPEN","runners":[{"status":"ACTIVE","sortPriority":1,"id":39296632,"name":"1. Evolution Girl"},{"status":"ACTIVE","sortPriority":2,"id":38124326,"name":"2. Nanny In Town"},{"status":"ACTIVE","sortPriority":3,"id":41729332,"name":"3. Highland Wonder"},{"status":"ACTIVE","sortPriority":4,"id":27453791,"name":"4. Headwall"},{"status":"ACTIVE","sortPriority":5,"id":41375430,"name":"6. Just Posh"},{"status":"ACTIVE","sortPriority":6,"id":41375435,"name":"7. Rojo Diamond"},{"status":"ACTIVE","sortPriority":7,"id":35784172,"name":"8. Buckle Up Kenzie"},{"status":"ACTIVE","sortPriority":8,"id":41375426,"name":"9. Wynburn Rebel"}],"regulators":["MR_INT"],"venue":"Devonport","countryCode":"AU","discountAllowed":true,"timezone":"Australia/Sydney","openDate":"2022-03-01T02:00:00.000Z","version":4381058330,"name":"R7 452m Heat","eventName":"Devonport (AUS) 1st Mar"},"rc":[],"con":true,"img":false}]}
{"op":"mcm","clk":"5306578627","pt":1646101320135,"mc":[{"id":"1.195395431","rc":[{"atb":[[7.6,1.53]],"id":39296632},{"atb":[[1.15,2]],"id":41375435},{"atb":[[11.5,0.96]],"id":41729332},{"atb":[[2.72,2]],"id":41375430},{"atb":[[8.2,1.4]],"id":27453791},{"atb":[[95,0.12]],"id":38124326},{"spn":97.5,"spf":1.0,"id":38124326},{"atb":[[10.5,1.06]],"id":35784172},{"spn":32.75,"spf":1.0,"id":35784172}],"con":true,"img":false}]}
{"op":"mcm","clk":"5306579078","pt":1646101330256,"mc":[{"id":"1.195395431","rc":[{"atb":[[26,0.41]],"id":41375426}],"con":true,"img":false}]}
{"op":"mcm","clk":"5306592178","pt":1646101622220,"mc":[{"id":"1.195395431","rc":[{"atb":[[4.5,20.57],[2.62,46.3]],"id":39296632},{"atl":[[130,8.2]],"id":39296632},{"atb":[[1.3,240]],"id":41375435},{"atl":[[2.84,8.2]],"id":41375435},{"atb":[[6.6,12.86],[2.62,46.3],[4.2,26.56]],"id":41729332},{"atb":[[1.86,83.72]],"id":41375430},{"atl":[[13,8.2]],"id":41375430},{"atb":[[2.62,46.3],[4.7,19.46]],"id":27453791},{"atb":[[16,4.8],[2.62,46.3],[4.2,26.56]],"id":38124326},{"atb":[[5.5,16],[2.62,46.3]],"id":35784172},{"atb":[[11.5,6.86],[2.62,46.3],[4.2,26.56]],"id":41375426}],"con":true,"img":false}]}
{"op":"mcm","clk":"5306592191","pt":1646101622423,"mc":[{"id":"1.195395431","rc":[{"atl":[[17,8.5],[34,13.5]],"id":41375435},{"atl":[[34,13.5]],"id":41375430}],"con":true,"img":false}]}
{"op":"mcm","clk":"5306609151","pt":1646102011656,"mc":[{"id":"1.195395431","rc":[{"atb":[[1.67,129.34]],"id":41375435},{"trd":[[1.67,96.57]],"ltp":1.67,"tv":96.57,"id":41375435}],"con":true,"img":false}]}
{"op":"mcm","clk":"5306613802","pt":1646102104761,"mc":[{"id":"1.195395431","rc":[{"atb":[[7.6,0]],"id":39296632},{"atb":[[1.15,0]],"id":41375435},{"atb":[[11.5,0]],"id":41729332},{"atb":[[2.72,0]],"id":41375430},{"atb":[[8.2,0]],"id":27453791},{"atb":[[95,0]],"id":38124326},{"spn":85.0,"spf":1.0,"id":38124326},{"atb":[[10.5,0]],"id":35784172},{"spn":32.5,"spf":1.0,"id":35784172},{"atb":[[26,0]],"id":41375426}],"con":true,"img":false}]}
{"op":"mcm","clk":"5306630296","pt":1646102422976,"mc":[{"id":"1.195395431","rc":[{"atb":[[9.6,0],[8.6,0],[7.6,0],[12.5,0]],"id":41729332},{"atl":[[130,0],[90,0],[180,0],[230,0]],"id":41729332},{"spn":53.3,"spf":1.0,"id":41729332},{"atb":[[5.5,0],[6,0],[7,0],[8.4,0]],"id":27453791},{"atl":[[75,0],[40,0],[50,0],[100,0]],"id":27453791}],"con":true,"img":false}]}
{"op":"mcm","clk":"5306630334","pt":1646102423615,"mc":[{"id":"1.195395431","rc":[{"atb":[[8.6,0]],"id":27453791}],"con":true,"img":false}]}
{"op":"mcm","clk":"5306630350","pt":1646102423703,"mc":[{"id":"1.195395431","rc":[{"atb":[[1.01,1.55]],"id":27453791},{"atl":[[38,0]],"id":27453791}],"con":true,"img":false}]}
{"op":"mcm","clk":"5306630361","pt":1646102423898,"mc":[{"id":"1.195395431","rc":[{"atl":[[990,1.21]],"id":27453791}],"con":true,"img":false}]}
{"op":"mcm","clk":"5306631047","pt":1646102436299,"mc":[{"id":"1.195395431","rc":[{"atb":[[9.6,12.9],[8.6,14.6],[7.6,16.81],[12.5,9.65]],"id":41729332},{"atl":[[130,0.96],[90,1.4],[180,1.04],[230,0.81]],"id":41729332},{"atb":[[9,13.87],[5.8,23.12],[7.6,16.81],[6.6,19.82]],"id":27453791},{"atl":[[65,1.94],[130,1.45],[90,2.09],[46,2.76]],"id":27453791}],"con":true,"img":false}]}
{"op":"mcm","clk":"5306631067","pt":1646102436609,"mc":[{"id":"1.195395431","rc":[{"atb":[[1.01,0]],"id":27453791}],"con":true,"img":false}]}
{"op":"mcm","clk":"5306631074","pt":1646102436712,"mc":[{"id":"1.195395431","rc":[{"atb":[[9.2,1.55]],"id":27453791}],"con":true,"img":false}]}
{"op":"mcm","clk":"5306634882","pt":1646102520098,"mc":[{"id":"1.195395431","rc":[{"atb":[[7.6,1.53]],"id":39296632},{"atb":[[1.15,2]],"id":41375435},{"atb":[[11.5,0.96]],"id":41729332},{"spn":51.25,"spf":1.0,"id":41729332},{"atb":[[8.2,1.4]],"id":27453791},{"spn":27.6,"spf":1.0,"id":27453791},{"atb":[[2.82,2]],"id":41375430},{"atb":[[95,0.12]],"id":38124326},{"spn":97.5,"spf":1.0,"id":38124326},{"atb":[[10.5,1.06]],"id":35784172},{"spn":32.75,"spf":1.0,"id":35784172},{"atb":[[30,0.35]],"id":41375426},{"spn":65.0,"spf":1.0,"id":41375426}],"con":true,"img":false}]}
{"op":"mcm","clk":"5306668551","pt":1646103141982,"mc":[{"id":"1.195395431","rc":[{"atb":[[8.2,9.6],[6.8,20.52]],"id":39296632},{"atl":[[20,3.05],[28,3.6]],"id":39296632},{"atb":[[1.68,81.51],[1.51,238.72]],"id":41375435},{"atl":[[2.82,31.88],[2.96,62.11]],"id":41375435},{"spn":1.68,"spf":1.0,"id":41375435},{"atb":[[10.5,6.1],[9.8,12.69]],"id":41729332},{"atl":[[38,2.7],[50,2.7]],"id":41729332},{"spn":25.25,"spf":1.0,"id":41729332},{"atb":[[9.2,15.87],[10,6.44]],"id":27453791},{"atl":[[40,2.73],[29,2.7]],"id":27453791},{"spn":19.5,"spf":1.0,"id":27453791},{"atb":[[2.86,31.19],[2.62,71.14]],"id":41375430},{"atl":[[5.1,14.15],[6.8,19.2]],"id":41375430},{"spn":4.0,"spf":1.0,"id":41375430},{"atb":[[75,2.7],[80,2.7]],"id":38124326},{"atb":[[8.6,15.51],[10,8.09]],"id":35784172},{"atl":[[38,3.18],[28,2.7]],"id":35784172},{"spn":19.25,"spf":1.0,"id":35784172},{"atb":[[23,4.85],[30,3.05]],"id":41375426},{"atl":[[150,0.38],[210,2.7]],"id":41375426}],"con":true,"img":false}]}
{"op":"mcm","clk":"5306668582","pt":1646103142495,"mc":[{"id":"1.195395431","rc":[{"atb":[[1.02,0]],"id":39296632},{"atb":[[1.02,0]],"id":35784172}],"con":true,"img":false}]}
{"op":"mcm","clk":"5306668585","pt":1646103142594,"mc":[{"id":"1.195395431","rc":[{"atb":[[8.4,1.28]],"id":39296632},{"atb":[[1.02,1.26]],"id":41729332},{"atb":[[9.2,14.31]],"id":27453791},{"atb":[[10,9.3]],"id":35784172}],"con":true,"img":false}]}
{"op":"mcm","clk":"5306668592","pt":1646103142701,"mc":[{"id":"1.195395431","rc":[{"atb":[[13,1.64]],"id":41729332},{"atb":[[10.5,1.55]],"id":27453791}],"con":true,"img":false}]}
{"op":"mcm","clk":"5306668786","pt":1646103147409,"mc":[{"id":"1.195395431","rc":[{"atb":[[2.88,6.09]],"id":41375430}],"con":true,"img":false}]}
{"op":"mcm","clk":"5306668838","pt":1646103148583,"mc":[{"id":"1.195395431","rc":[{"atb":[[2.88,1.29]],"id":41375430}],"con":true,"img":false}]}
{"op":"mcm","clk":"5306668846","pt":1646103148789,"mc":[{"id":"1.195395431","rc":[{"atb":[[2.9,0]],"id":41375430}],"con":true,"img":false}]}
{"op":"mcm","clk":"5306668853","pt":1646103148891,"mc":[{"id":"1.195395431","rc":[{"atb":[[2.88,2.82]],"id":41375430}],"con":true,"img":false}]}
{"op":"mcm","clk":"5306669246","pt":1646103157593,"mc":[{"id":"1.195395431","rc":[{"atb":[[2.9,3.92]],"id":41375430}],"con":true,"img":false}]}
{"op":"mcm","clk":"5306669292","pt":1646103158518,"mc":[{"id":"1.195395431","rc":[{"atb":[[2.88,0]],"id":41375430}],"con":true,"img":false}]}
{"op":"mcm","clk":"5306669295","pt":1646103158618,"mc":[{"id":"1.195395431","rc":[{"atb":[[2.92,1.52],[2.9,5.21]],"id":41375430}],"con":true,"img":false}]}
{"op":"mcm","clk":"5306669325","pt":1646103159335,"mc":[{"id":"1.195395431","rc":[{"atb":[[2.9,10.52]],"id":41375430}],"con":true,"img":false}]}
{"op":"mcm","clk":"5306669440","pt":1646103162015,"mc":[{"id":"1.195395431","rc":[{"atb":[[7.6,0]],"id":39296632},{"atb":[[1.15,0]],"id":41375435},{"atb":[[11.5,0]],"id":41729332},{"atb":[[2.82,0]],"id":41375430},{"atb":[[8.2,0]],"id":27453791},{"atb":[[95,0]],"id":38124326},{"atb":[[10.5,0]],"id":35784172},{"atb":[[30,2.7]],"id":41375426}],"con":true,"img":false}]}
{"op":"mcm","clk":"5306674256","pt":1646103285916,"mc":[{"id":"1.195395431","rc":[{"spn":8.5,"spf":1.0,"id":39296632},{"atl":[[1.8,0.52]],"id":41375435},{"trd":[[1.8,38.95]],"ltp":1.8,"tv":38.95,"id":41375435},{"spn":25.5,"spf":1.0,"id":41729332},{"spn":4.01,"spf":1.0,"id":41375430},{"spn":19.75,"spf":1.0,"id":27453791},{"spn":90.0,"spf":1.0,"id":38124326},{"spn":19.0,"spf":1.0,"id":35784172}],"con":true,"img":false}]}
{"op":"mcm","clk":"5306674543","pt":1646103292892,"mc":[{"id":"1.195395431","rc":[{"atb":[[2.9,6.6]],"id":41375430}],"con":true,"img":false}]}
{"op":"mcm","clk":"5306674963","pt":1646103301930,"mc":[{"id":"1.195395431","rc":[{"atb":[[2.94,3.83]],"id":41375430}],"con":true,"img":false}]}
{"op":"mcm","clk":"5306674968","pt":1646103302032,"mc":[{"id":"1.195395431","rc":[{"atb":[[1.71,10.49]],"id":41375435}],"con":true,"img":false}]}
{"op":"mcm","clk":"5306674993","pt":1646103302546,"mc":[{"id":"1.195395431","rc":[{"atb":[[2.9,5.31]],"id":41375430}],"con":true,"img":false}]}
{"op":"mcm","clk":"5306674999","pt":1646103302599,"mc":[{"id":"1.195395431","rc":[{"atb":[[2.94,5.13]],"id":41375430}],"con":true,"img":false}]}
{"op":"mcm","clk":"5306675066","pt":1646103303730,"mc":[{"id":"1.195395431","rc":[{"atb":[[1.71,24.72]],"id":41375435}],"con":true,"img":false}]}
{"op":"mcm","clk":"5306675140","pt":1646103305317,"mc":[{"id":"1.195395431","rc":[{"atb":[[2.92,0]],"id":41375430}],"con":true,"img":false}]}
{"op":"mcm","clk":"5306675143","pt":1646103305420,"mc":[{"id":"1.195395431","rc":[{"atb":[[2.96,1.52]],"id":41375430}],"con":true,"img":false}]}
{"op":"mcm","clk":"5306675407","pt":1646103311633,"mc":[{"id":"1.195395431","rc":[{"atl":[[2.82,0]],"id":41375435}],"con":true,"img":false}]}
{"op":"mcm","clk":"5306675410","pt":1646103311735,"mc":[{"id":"1.195395431","rc":[{"atl":[[2.8,31.88]],"id":41375435}],"con":true,"img":false}]}
{"op":"mcm","clk":"5306675932","pt":1646103324734,"mc":[{"id":"1.195395431","rc":[{"atl":[[28,0]],"id":35784172}],"con":true,"img":false}]}
{"op":"mcm","clk":"5306675938","pt":1646103324834,"mc":[{"id":"1.195395431","rc":[{"atl":[[27,2.7]],"id":35784172}],"con":true,"img":false}]}
{"op":"mcm","clk":"5306676072","pt":1646103328297,"mc":[{"id":"1.195395431","marketDefinition":{"bspMarket":true,"turnInPlayEnabled":false,"persistenceEnabled":false,"marketBaseRate":7.0,"eventId":"31270458","eventTypeId":"4339","numberOfWinners":1,"bettingType":"ODDS","marketType":"WIN","marketTime":"2022-03-01T05:02:00.000Z","suspendTime":"2022-03-01T05:02:00.000Z","bspReconciled":false,"complete":true,"inPlay":false,"crossMatching":true,"runnersVoidable":false,"numberOfActiveRunners":8,"betDelay":0,"status":"OPEN","runners":[{"status":"ACTIVE","sortPriority":1,"id":39296632,"name":"1. Evolution Girl"},{"status":"ACTIVE","sortPriority":2,"id":38124326,"name":"2. Nanny In Town"},{"status":"ACTIVE","sortPriority":3,"id":41729332,"name":"3. Highland Wonder"},{"status":"ACTIVE","sortPriority":4,"id":27453791,"name":"4. Headwall"},{"status":"ACTIVE","sortPriority":5,"id":41375430,"name":"6. Just Posh"},{"status":"ACTIVE","sortPriority":6,"id":41375435,"name":"7. Rojo Diamond"},{"status":"ACTIVE","sortPriority":7,"id":35784172,"name":"8. Buckle Up Kenzie"},{"status":"ACTIVE","sortPriority":8,"id":41375426,"name":"9. Wynburn Rebel"}],"regulators":["MR_INT"],"venue":"Devonport","countryCode":"AU","discountAllowed":true,"timezone":"Australia/Sydney","openDate":"2022-03-01T02:00:00.000Z","version":4381083959,"name":"R7 452m Heat","eventName":"Devonport (AUS) 1st Mar"},"rc":[],"con":true,"img":false}]}
{"op":"mcm","clk":"5306676860","pt":1646103345594,"mc":[{"id":"1.195395431","rc":[{"atb":[[1.68,260.55]],"id":41375435}],"con":true,"img":false}]}
{"op":"mcm","clk":"5306676866","pt":1646103345698,"mc":[{"id":"1.195395431","rc":[{"atb":[[1.51,0]],"id":41375435}],"con":true,"img":false}]}
{"op":"mcm","clk":"5306677153","pt":1646103352771,"mc":[{"id":"1.195395431","rc":[{"atl":[[2.8,0]],"id":41375435},{"spn":1.69,"spf":1.0,"id":41375435},{"spn":4.03,"spf":1.0,"id":41375430},{"spn":18.5,"spf":1.0,"id":35784172}],"con":true,"img":false}]}
{"op":"mcm","clk":"5306677157","pt":1646103352923,"mc":[{"id":"1.195395431","rc":[{"atl":[[2.78,31.88]],"id":41375435}],"con":true,"img":false}]}
{"op":"mcm","clk":"5306677431","pt":1646103359179,"mc":[{"id":"1.195395431","rc":[{"atl":[[38,0]],"id":41729332}],"con":true,"img":false}]}
{"op":"mcm","clk":"5306677439","pt":1646103359282,"mc":[{"id":"1.195395431","rc":[{"atl":[[36,2.7]],"id":41729332}],"con":true,"img":false}]}
{"op":"mcm","clk":"5306677867","pt":1646103368115,"mc":[{"id":"1.195395431","rc":[{"atb":[[2.94,1.29]],"id":41375430}],"con":true,"img":false}]}
{"op":"mcm","clk":"5306677883","pt":1646103368424,"mc":[{"id":"1.195395431","rc":[{"atb":[[2.94,0]],"id":41375430}],"con":true,"img":false}]}
{"op":"mcm","clk":"5306677887","pt":1646103368527,"mc":[{"id":"1.195395431","rc":[{"atb":[[2.9,6.6]],"id":41375430}],"con":true,"img":false}]}
{"op":"mcm","clk":"5306677895","pt":1646103368733,"mc":[{"id":"1.195395431","rc":[{"atb":[[2.96,0]],"id":41375430}],"con":true,"img":false}]}
{"op":"mcm","clk":"5306677899","pt":1646103368835,"mc":[{"id":"1.195395431","rc":[{"atb":[[2.92,1.52]],"id":41375430}],"con":true,"img":false}]}
{"op":"mcm","clk":"5306678234","pt":1646103377013,"mc":[{"id":"1.195395431","rc":[{"atb":[[2.9,10.52]],"id":41375430}],"con":true,"img":false}]}
{"op":"mcm","clk":"5306678978","pt":1646103394371,"mc":[{"id":"1.195395431","rc":[{"atl":[[2.78,0]],"id":41375435}],"con":true,"img":false}]}
{"op":"mcm","clk":"5306678987","pt":1646103394475,"mc":[{"id":"1.195395431","rc":[{"atl":[[2.76,31.88]],"id":41375435}],"con":true,"img":false}]}
{"op":"mcm","clk":"5306679740","pt":1646103413494,"mc":[{"id":"1.195395431","rc":[{"atl":[[36,0]],"id":41729332},{"spn":31.5,"spf":1.0,"id":41729332},{"spn":4.01,"spf":1.0,"id":41375430}],"con":true,"img":false}]}
{"op":"mcm","clk":"5306679743","pt":1646103413596,"mc":[{"id":"1.195395431","rc":[{"atl":[[34,2.7]],"id":41729332}],"con":true,"img":false}]}
{"op":"mcm","clk":"5306680440","pt":1646103434198,"mc":[{"id":"1.195395431","rc":[{"atl":[[2.76,0]],"id":41375435}],"con":true,"img":false}]}
{"op":"mcm","clk":"5306680442","pt":1646103434300,"mc":[{"id":"1.195395431","rc":[{"atl":[[2.74,31.88]],"id":41375435}],"con":true,"img":false}]}
{"op":"mcm","clk":"5306681839","pt":1646103475463,"mc":[{"id":"1.195395431","rc":[{"atl":[[2.74,0]],"id":41375435},{"spn":23.5,"spf":1.0,"id":41729332}],"con":true,"img":false}]}
{"op":"mcm","clk":"5306681842","pt":1646103475564,"mc":[{"id":"1.195395431","rc":[{"atl":[[2.72,31.88]],"id":41375435}],"con":true,"img":false}]}
{"op":"mcm","clk":"5306682993","pt":1646103515612,"mc":[{"id":"1.195395431","rc":[{"atl":[[2.72,0]],"id":41375435}],"con":true,"img":false}]}
{"op":"mcm","clk":"5306682998","pt":1646103515713,"mc":[{"id":"1.195395431","rc":[{"atl":[[2.7,31.88]],"id":41375435}],"con":true,"img":false}]}
{"op":"mcm","clk":"5306683167","pt":1646103521863,"mc":[{"id":"1.195395431","rc":[{"atl":[[34,0]],"id":41729332}],"con":true,"img":false}]}
{"op":"mcm","clk":"5306683170","pt":1646103521914,"mc":[{"id":"1.195395431","rc":[{"atl":[[32,2.7]],"id":41729332}],"con":true,"img":false}]}
{"op":"mcm","clk":"5306684050","pt":1646103553807,"mc":[{"id":"1.195395431","rc":[{"atl":[[2.7,0]],"id":41375435},{"spn":22.5,"spf":1.0,"id":41729332}],"con":true,"img":false}]}
{"op":"mcm","clk":"5306684055","pt":1646103553912,"mc":[{"id":"1.195395431","rc":[{"atl":[[2.68,31.88]],"id":41375435}],"con":true,"img":false}]}
{"op":"mcm","clk":"5306685271","pt":1646103590248,"mc":[{"id":"1.195395431","rc":[{"atl":[[2.68,0]],"id":41375435}],"con":true,"img":false}]}
{"op":"mcm","clk":"5306685275","pt":1646103590351,"mc":[{"id":"1.195395431","rc":[{"atl":[[2.66,31.88]],"id":41375435}],"con":true,"img":false}]}
{"op":"mcm","clk":"5306686162","pt":1646103613275,"mc":[{"id":"1.195395431","rc":[{"atl":[[2.66,0]],"id":41375435}],"con":true,"img":false}]}
{"op":"mcm","clk":"5306686164","pt":1646103613378,"mc":[{"id":"1.195395431","rc":[{"atl":[[2.82,31.88]],"id":41375435}],"con":true,"img":false}]}
{"op":"mcm","clk":"5306687264","pt":1646103648484,"mc":[{"id":"1.195395431","rc":[{"atl":[[2.82,0]],"id":41375435}],"con":true,"img":false}]}
{"op":"mcm","clk":"5306687267","pt":1646103648586,"mc":[{"id":"1.195395431","rc":[{"atl":[[2.8,31.88]],"id":41375435}],"con":true,"img":false}]}
{"op":"mcm","clk":"5306688657","pt":1646103686364,"mc":[{"id":"1.195395431","rc":[{"atl":[[2.8,0]],"id":41375435}],"con":true,"img":false}]}
{"op":"mcm","clk":"5306688664","pt":1646103686465,"mc":[{"id":"1.195395431","rc":[{"atl":[[2.78,31.88]],"id":41375435}],"con":true,"img":false}]}
{"op":"mcm","clk":"5306689936","pt":1646103720085,"mc":[{"id":"1.195395431","rc":[{"atb":[[7.6,1.53]],"id":39296632},{"atb":[[11.5,0.96]],"id":41729332},{"atb":[[2.82,2]],"id":41375430},{"atb":[[9.6,1.17]],"id":27453791},{"atb":[[95,0.12]],"id":38124326},{"spn":97.5,"spf":1.0,"id":38124326},{"atb":[[10.5,1.06]],"id":35784172},{"spn":18.75,"spf":1.0,"id":35784172},{"atb":[[30,3.05]],"id":41375426}],"con":true,"img":false}]}
{"op":"mcm","clk":"5306690508","pt":1646103737641,"mc":[{"id":"1.195395431","rc":[{"atl":[[2.78,0]],"id":41375435}],"con":true,"img":false}]}
{"op":"mcm","clk":"5306690511","pt":1646103737743,"mc":[{"id":"1.195395431","rc":[{"atl":[[2.76,31.88]],"id":41375435}],"con":true,"img":false}]}
{"op":"mcm","clk":"5306691479","pt":1646103763279,"mc":[{"id":"1.195395431","rc":[{"atb":[[2.82,178.38]],"id":41729332}],"con":true,"img":false}]}
{"op":"mcm","clk":"5306692069","pt":1646103782515,"mc":[{"id":"1.195395431","rc":[{"atl":[[2.76,0]],"id":41375435}],"con":true,"img":false}]}
{"op":"mcm","clk":"5306692072","pt":1646103782617,"mc":[{"id":"1.195395431","rc":[{"atl":[[2.74,31.88]],"id":41375435}],"con":true,"img":false}]}
{"op":"mcm","clk":"5306692086","pt":1646103783182,"mc":[{"id":"1.195395431","rc":[{"atl":[[17,8.5]],"id":41375430}],"con":true,"img":false}]}
{"op":"mcm","clk":"5306693787","pt":1646103830471,"mc":[{"id":"1.195395431","rc":[{"atl":[[2.74,0]],"id":41375435}],"con":true,"img":false}]}
{"op":"mcm","clk":"5306693792","pt":1646103830574,"mc":[{"id":"1.195395431","rc":[{"atl":[[2.72,31.88]],"id":41375435}],"con":true,"img":false}]}
{"op":"mcm","clk":"5306695261","pt":1646103867159,"mc":[{"id":"1.195395431","rc":[{"atl":[[2.72,0]],"id":41375435}],"con":true,"img":false}]}
{"op":"mcm","clk":"5306695269","pt":1646103867260,"mc":[{"id":"1.195395431","rc":[{"atl":[[2.7,31.88]],"id":41375435}],"con":true,"img":false}]}
{"op":"mcm","clk":"5306696904","pt":1646103909914,"mc":[{"id":"1.195395431","rc":[{"atl":[[2.7,0]],"id":41375435}],"con":true,"img":false}]}
{"op":"mcm","clk":"5306696909","pt":1646103910017,"mc":[{"id":"1.195395431","rc":[{"atl":[[2.68,31.88]],"id":41375435}],"con":true,"img":false}]}
{"op":"mcm","clk":"5306698353","pt":1646103948963,"mc":[{"id":"1.195395431","rc":[{"atl":[[2.68,0]],"id":41375435}],"con":true,"img":false}]}
{"op":"mcm","clk":"5306698356","pt":1646103949066,"mc":[{"id":"1.195395431","rc":[{"atl":[[2.66,31.88]],"id":41375435}],"con":true,"img":false}]}
{"op":"mcm","clk":"5306699237","pt":1646103970077,"mc":[{"id":"1.195395431","rc":[{"atl":[[2.66,0]],"id":41375435}],"con":true,"img":false}]}
{"op":"mcm","clk":"5306699240","pt":1646103970179,"mc":[{"id":"1.195395431","rc":[{"atl":[[2.82,31.88]],"id":41375435}],"con":true,"img":false}]}
{"op":"mcm","clk":"5306700542","pt":1646104003143,"mc":[{"id":"1.195395431","rc":[{"atl":[[2.82,0]],"id":41375435}],"con":true,"img":false}]}
{"op":"mcm","clk":"5306700545","pt":1646104003246,"mc":[{"id":"1.195395431","rc":[{"atl":[[2.8,31.88]],"id":41375435}],"con":true,"img":false}]}
{"op":"mcm","clk":"5306703223","pt":1646104059839,"mc":[{"id":"1.195395431","rc":[{"atl":[[2.8,0]],"id":41375435}],"con":true,"img":false}]}
{"op":"mcm","clk":"5306703230","pt":1646104059941,"mc":[{"id":"1.195395431","rc":[{"atl":[[2.78,31.88]],"id":41375435}],"con":true,"img":false}]}
{"op":"mcm","clk":"5306703940","pt":1646104079736,"mc":[{"id":"1.195395431","rc":[{"atl":[[110,8.2]],"id":41729332},{"atl":[[70,8.2]],"id":27453791}],"con":true,"img":false}]}
{"op":"mcm","clk":"5306703945","pt":1646104079841,"mc":[{"id":"1.195395431","rc":[{"atl":[[70,8.2]],"id":35784172}],"con":true,"img":false}]}
{"op":"mcm","clk":"5306704688","pt":1646104101863,"mc":[{"id":"1.195395431","rc":[{"atl":[[2.78,0]],"id":41375435}],"con":true,"img":false}]}
{"op":"mcm","clk":"5306704693","pt":1646104101966,"mc":[{"id":"1.195395431","rc":[{"atl":[[2.76,31.88]],"id":41375435}],"con":true,"img":false}]}
{"op":"mcm","clk":"5306706154","pt":1646104143627,"mc":[{"id":"1.195395431","rc":[{"atl":[[2.76,0]],"id":41375435}],"con":true,"img":false}]}
{"op":"mcm","clk":"5306706160","pt":1646104143729,"mc":[{"id":"1.195395431","rc":[{"atl":[[2.74,31.88]],"id":41375435}],"con":true,"img":false}]}
{"op":"mcm","clk":"5306707492","pt":1646104185098,"mc":[{"id":"1.195395431","rc":[{"atl":[[2.74,0]],"id":41375435}],"con":true,"img":false}]}
{"op":"mcm","clk":"5306707494","pt":1646104185197,"mc":[{"id":"1.195395431","rc":[{"atl":[[2.72,31.88]],"id":41375435}],"con":true,"img":false}]}
{"op":"mcm","clk":"5306708844","pt":1646104222130,"mc":[{"id":"1.195395431","rc":[{"atl":[[2.72,0]],"id":41375435}],"con":true,"img":false}]}
{"op":"mcm","clk":"5306708847","pt":1646104222230,"mc":[{"id":"1.195395431","rc":[{"atl":[[2.7,31.88]],"id":41375435}],"con":true,"img":false}]}
{"op":"mcm","clk":"5306710385","pt":1646104260403,"mc":[{"id":"1.195395431","rc":[{"atl":[[2.7,0]],"id":41375435}],"con":true,"img":false}]}
{"op":"mcm","clk":"5306710389","pt":1646104260453,"mc":[{"id":"1.195395431","rc":[{"atl":[[2.68,31.88]],"id":41375435}],"con":true,"img":false}]}
{"op":"mcm","clk":"5306712020","pt":1646104298939,"mc":[{"id":"1.195395431","rc":[{"atl":[[2.68,0]],"id":41375435}],"con":true,"img":false}]}
{"op":"mcm","clk":"5306712027","pt":1646104299040,"mc":[{"id":"1.195395431","rc":[{"atl":[[2.66,31.88]],"id":41375435}],"con":true,"img":false}]}
{"op":"mcm","clk":"5306713012","pt":1646104320469,"mc":[{"id":"1.195395431","rc":[{"atl":[[2.66,0]],"id":41375435}],"con":true,"img":false}]}
{"op":"mcm","clk":"5306713015","pt":1646104320571,"mc":[{"id":"1.195395431","rc":[{"atl":[[2.82,31.88]],"id":41375435}],"con":true,"img":false}]}
{"op":"mcm","clk":"5306714648","pt":1646104354493,"mc":[{"id":"1.195395431","rc":[{"atl":[[2.82,0]],"id":41375435}],"con":true,"img":false}]}
{"op":"mcm","clk":"5306714651","pt":1646104354593,"mc":[{"id":"1.195395431","rc":[{"atl":[[2.8,31.88]],"id":41375435}],"con":true,"img":false}]}
{"op":"mcm","clk":"5306716785","pt":1646104393375,"mc":[{"id":"1.195395431","rc":[{"atl":[[2.8,0]],"id":41375435}],"con":true,"img":false}]}
{"op":"mcm","clk":"5306716791","pt":1646104393477,"mc":[{"id":"1.195395431","rc":[{"atl":[[2.78,31.88]],"id":41375435}],"con":true,"img":false}]}
{"op":"mcm","clk":"5306718937","pt":1646104432433,"mc":[{"id":"1.195395431","rc":[{"atl":[[2.78,0]],"id":41375435}],"con":true,"img":false}]}
{"op":"mcm","clk":"5306718941","pt":1646104432535,"mc":[{"id":"1.195395431","rc":[{"atl":[[2.76,31.88]],"id":41375435}],"con":true,"img":false}]}
{"op":"mcm","clk":"5306720728","pt":1646104473396,"mc":[{"id":"1.195395431","rc":[{"atl":[[2.76,0]],"id":41375435}],"con":true,"img":false}]}
{"op":"mcm","clk":"5306720731","pt":1646104473497,"mc":[{"id":"1.195395431","rc":[{"atl":[[2.74,31.88]],"id":41375435}],"con":true,"img":false}]}
{"op":"mcm","clk":"5306722570","pt":1646104513355,"mc":[{"id":"1.195395431","rc":[{"atl":[[2.74,0]],"id":41375435}],"con":true,"img":false}]}
{"op":"mcm","clk":"5306722575","pt":1646104513457,"mc":[{"id":"1.195395431","rc":[{"atl":[[2.72,31.88]],"id":41375435}],"con":true,"img":false}]}
{"op":"mcm","clk":"5306723242","pt":1646104526792,"mc":[{"id":"1.195395431","rc":[{"atb":[[7.6,0]],"id":39296632},{"atb":[[11.5,0]],"id":41729332},{"atb":[[9.6,0]],"id":27453791},{"atb":[[2.82,0]],"id":41375430},{"atb":[[95,0]],"id":38124326},{"atb":[[10.5,0]],"id":35784172},{"atb":[[30,2.7]],"id":41375426}],"con":true,"img":false}]}
{"op":"mcm","clk":"5306724442","pt":1646104553126,"mc":[{"id":"1.195395431","rc":[{"atl":[[2.72,0]],"id":41375435},{"spn":90.0,"spf":1.0,"id":38124326},{"spn":18.5,"spf":1.0,"id":35784172}],"con":true,"img":false}]}
{"op":"mcm","clk":"5306724447","pt":1646104553208,"mc":[{"id":"1.195395431","rc":[{"atl":[[2.7,31.88]],"id":41375435}],"con":true,"img":false}]}
{"op":"mcm","clk":"5306726239","pt":1646104591788,"mc":[{"id":"1.195395431","rc":[{"atl":[[2.7,0]],"id":41375435}],"con":true,"img":false}]}
{"op":"mcm","clk":"5306726241","pt":1646104591891,"mc":[{"id":"1.195395431","rc":[{"atl":[[2.68,31.88]],"id":41375435}],"con":true,"img":false}]}
{"op":"mcm","clk":"5306727619","pt":1646104620120,"mc":[{"id":"1.195395431","rc":[{"atb":[[7.6,1.53]],"id":39296632},{"atb":[[11.5,0.96]],"id":41729332},{"atb":[[9.6,1.17]],"id":27453791},{"atb":[[2.82,2]],"id":41375430},{"atb":[[95,0.12]],"id":38124326},{"spn":97.5,"spf":1.0,"id":38124326},{"atb":[[10.5,1.06]],"id":35784172},{"spn":18.75,"spf":1.0,"id":35784172},{"atb":[[30,3.05]],"id":41375426}],"con":true,"img":false}]}
{"op":"mcm","clk":"5306728243","pt":1646104630332,"mc":[{"id":"1.195395431","rc":[{"atl":[[2.68,0]],"id":41375435}],"con":true,"img":false}]}
{"op":"mcm","clk":"5306728250","pt":1646104630433,"mc":[{"id":"1.195395431","rc":[{"atl":[[2.66,31.88]],"id":41375435}],"con":true,"img":false}]}
{"op":"mcm","clk":"5306729285","pt":1646104651362,"mc":[{"id":"1.195395431","rc":[{"atl":[[2.66,0]],"id":41375435}],"con":true,"img":false}]}
{"op":"mcm","clk":"5306729289","pt":1646104651465,"mc":[{"id":"1.195395431","rc":[{"atl":[[2.82,31.88]],"id":41375435}],"con":true,"img":false}]}
{"op":"mcm","clk":"5306730956","pt":1646104682909,"mc":[{"id":"1.195395431","rc":[{"atl":[[2.82,0]],"id":41375435}],"con":true,"img":false}]}
{"op":"mcm","clk":"5306730964","pt":1646104683012,"mc":[{"id":"1.195395431","rc":[{"atl":[[2.8,31.88]],"id":41375435}],"con":true,"img":false}]}
{"op":"mcm","clk":"5306732755","pt":1646104718673,"mc":[{"id":"1.195395431","rc":[{"atl":[[2.8,0]],"id":41375435}],"con":true,"img":false}]}
{"op":"mcm","clk":"5306732762","pt":1646104718776,"mc":[{"id":"1.195395431","rc":[{"atl":[[2.78,31.88]],"id":41375435}],"con":true,"img":false}]}
{"op":"mcm","clk":"5306734954","pt":1646104756926,"mc":[{"id":"1.195395431","rc":[{"atl":[[2.78,0]],"id":41375435}],"con":true,"img":false}]}
{"op":"mcm","clk":"5306734958","pt":1646104757028,"mc":[{"id":"1.195395431","rc":[{"atl":[[2.76,31.88]],"id":41375435}],"con":true,"img":false}]}
{"op":"mcm","clk":"5306736596","pt":1646104793496,"mc":[{"id":"1.195395431","rc":[{"atl":[[2.76,0]],"id":41375435}],"con":true,"img":false}]}
{"op":"mcm","clk":"5306736603","pt":1646104793598,"mc":[{"id":"1.195395431","rc":[{"atl":[[2.74,31.88]],"id":41375435}],"con":true,"img":false}]}
{"op":"mcm","clk":"5306738242","pt":1646104828664,"mc":[{"id":"1.195395431","rc":[{"atl":[[2.74,0]],"id":41375435}],"con":true,"img":false}]}
{"op":"mcm","clk":"5306738248","pt":1646104828765,"mc":[{"id":"1.195395431","rc":[{"atl":[[2.72,31.88]],"id":41375435}],"con":true,"img":false}]}
{"op":"mcm","clk":"5306739733","pt":1646104863705,"mc":[{"id":"1.195395431","rc":[{"atl":[[1.9,5.38]],"id":41375435}],"con":true,"img":false}]}
{"op":"mcm","clk":"5306739831","pt":1646104866088,"mc":[{"id":"1.195395431","rc":[{"atl":[[2.72,0]],"id":41375435}],"con":true,"img":false}]}
{"op":"mcm","clk":"5306739836","pt":1646104866190,"mc":[{"id":"1.195395431","rc":[{"atl":[[2.7,31.88]],"id":41375435}],"con":true,"img":false}]}
{"op":"mcm","clk":"5306740043","pt":1646104871719,"mc":[{"id":"1.195395431","rc":[{"atl":[[2.4,4.89]],"id":41375435}],"con":true,"img":false}]}
{"op":"mcm","clk":"5306740605","pt":1646104886943,"mc":[{"id":"1.195395431","rc":[{"atl":[[2.7,0]],"id":41375435}],"con":true,"img":false}]}
{"op":"mcm","clk":"5306740609","pt":1646104887047,"mc":[{"id":"1.195395431","rc":[{"atl":[[2.82,31.88]],"id":41375435}],"con":true,"img":false}]}
{"op":"mcm","clk":"5306754719","pt":1646105223820,"mc":[{"id":"1.195395431","rc":[{"atb":[[8.6,2.5]],"id":39296632},{"spn":8.6,"spf":1.0,"id":39296632},{"atb":[[13.5,2.08]],"id":41729332},{"spn":22.75,"spf":1.0,"id":41729332},{"atb":[[11,2.08]],"id":27453791},{"spn":20.0,"spf":1.0,"id":27453791},{"atb":[[11,2.08]],"id":35784172},{"spn":19.0,"spf":1.0,"id":35784172}],"con":true,"img":false}]}
{"op":"mcm","clk":"5306754736","pt":1646105224333,"mc":[{"id":"1.195395431","rc":[{"atb":[[8.2,8.06]],"id":39296632},{"atb":[[13,0]],"id":41729332},{"atb":[[10.5,0]],"id":27453791},{"atb":[[10,7.66]],"id":35784172}],"con":true,"img":false}]}
{"op":"mcm","clk":"5306754741","pt":1646105224435,"mc":[{"id":"1.195395431","rc":[{"atb":[[8.6,4.04]],"id":39296632},{"atb":[[13.5,3.73]],"id":41729332},{"atb":[[11,3.64]],"id":27453791},{"atb":[[11,3.73]],"id":35784172}],"con":true,"img":false}]}
{"op":"mcm","clk":"5306772508","pt":1646105826854,"mc":[{"id":"1.195395431","rc":[{"atb":[[1.72,4.22]],"id":41375435},{"spn":1.69,"spf":1.0,"id":41375435}],"con":true,"img":false}]}
{"op":"mcm","clk":"5306772549","pt":1646105828489,"mc":[{"id":"1.195395431","rc":[{"atb":[[1.72,0]],"id":41375435}],"con":true,"img":false}]}
{"op":"mcm","clk":"5306772702","pt":1646105833306,"mc":[{"id":"1.195395431","rc":[{"atb":[[1.72,4.22]],"id":41375435}],"con":true,"img":false}]}
{"op":"mcm","clk":"5306772721","pt":1646105833770,"mc":[{"id":"1.195395431","rc":[{"atb":[[1.72,0]],"id":41375435}],"con":true,"img":false}]}
{"op":"mcm","clk":"5306772938","pt":1646105839307,"mc":[{"id":"1.195395431","rc":[{"atb":[[1.72,4.22]],"id":41375435}],"con":true,"img":false}]}
{"op":"mcm","clk":"5306772946","pt":1646105839613,"mc":[{"id":"1.195395431","rc":[{"atb":[[1.72,0]],"id":41375435}],"con":true,"img":false}]}
{"op":"mcm","clk":"5306773129","pt":1646105845399,"mc":[{"id":"1.195395431","rc":[{"atb":[[1.72,4.22]],"id":41375435}],"con":true,"img":false}]}
{"op":"mcm","clk":"5306773141","pt":1646105845704,"mc":[{"id":"1.195395431","rc":[{"atb":[[1.72,0]],"id":41375435}],"con":true,"img":false}]}
{"op":"mcm","clk":"5306773307","pt":1646105851025,"mc":[{"id":"1.195395431","rc":[{"atb":[[1.72,4.22]],"id":41375435}],"con":true,"img":false}]}
{"op":"mcm","clk":"5306773312","pt":1646105851230,"mc":[{"id":"1.195395431","rc":[{"atb":[[1.72,0]],"id":41375435}],"con":true,"img":false}]}
{"op":"mcm","clk":"5306773469","pt":1646105857219,"mc":[{"id":"1.195395431","rc":[{"atb":[[1.72,4.22]],"id":41375435}],"con":true,"img":false}]}
{"op":"mcm","clk":"5306773480","pt":1646105857629,"mc":[{"id":"1.195395431","rc":[{"atb":[[1.72,0]],"id":41375435}],"con":true,"img":false}]}
{"op":"mcm","clk":"5306773637","pt":1646105863257,"mc":[{"id":"1.195395431","rc":[{"atb":[[1.72,4.22]],"id":41375435}],"con":true,"img":false}]}
{"op":"mcm","clk":"5306773648","pt":1646105863616,"mc":[{"id":"1.195395431","rc":[{"atb":[[1.72,0]],"id":41375435}],"con":true,"img":false}]}
{"op":"mcm","clk":"5306773826","pt":1646105869456,"mc":[{"id":"1.195395431","rc":[{"atb":[[1.72,4.22]],"id":41375435}],"con":true,"img":false}]}
{"op":"mcm","clk":"5306773835","pt":1646105869763,"mc":[{"id":"1.195395431","rc":[{"atb":[[1.72,0]],"id":41375435}],"con":true,"img":false}]}
{"op":"mcm","clk":"5306773989","pt":1646105875233,"mc":[{"id":"1.195395431","rc":[{"atb":[[1.72,4.22]],"id":41375435}],"con":true,"img":false}]}
{"op":"mcm","clk":"5306774000","pt":1646105875668,"mc":[{"id":"1.195395431","rc":[{"atb":[[1.72,0]],"id":41375435}],"con":true,"img":false}]}
{"op":"mcm","clk":"5306774186","pt":1646105881860,"mc":[{"id":"1.195395431","rc":[{"atb":[[1.72,4.22]],"id":41375435}],"con":true,"img":false}]}
{"op":"mcm","clk":"5306774203","pt":1646105882376,"mc":[{"id":"1.195395431","rc":[{"atb":[[1.72,0]],"id":41375435}],"con":true,"img":false}]}
{"op":"mcm","clk":"5306774365","pt":1646105888066,"mc":[{"id":"1.195395431","rc":[{"atb":[[1.72,4.22]],"id":41375435}],"con":true,"img":false}]}
{"op":"mcm","clk":"5306774371","pt":1646105888273,"mc":[{"id":"1.195395431","rc":[{"atb":[[1.72,0]],"id":41375435}],"con":true,"img":false}]}
{"op":"mcm","clk":"5306774538","pt":1646105893980,"mc":[{"id":"1.195395431","rc":[{"atb":[[1.72,4.22]],"id":41375435}],"con":true,"img":false}]}
{"op":"mcm","clk":"5306774548","pt":1646105894391,"mc":[{"id":"1.195395431","rc":[{"atb":[[1.72,0]],"id":41375435}],"con":true,"img":false}]}
{"op":"mcm","clk":"5306774736","pt":1646105900091,"mc":[{"id":"1.195395431","rc":[{"atb":[[1.72,4.22]],"id":41375435}],"con":true,"img":false}]}
{"op":"mcm","clk":"5306774746","pt":1646105900502,"mc":[{"id":"1.195395431","rc":[{"atb":[[1.72,0]],"id":41375435}],"con":true,"img":false}]}
{"op":"mcm","clk":"5306774930","pt":1646105906504,"mc":[{"id":"1.195395431","rc":[{"atb":[[1.72,4.22]],"id":41375435}],"con":true,"img":false}]}
{"op":"mcm","clk":"5306774947","pt":1646105906910,"mc":[{"id":"1.195395431","rc":[{"atb":[[1.72,0]],"id":41375435}],"con":true,"img":false}]}
{"op":"mcm","clk":"5306775089","pt":1646105912589,"mc":[{"id":"1.195395431","rc":[{"atb":[[1.72,4.22]],"id":41375435}],"con":true,"img":false}]}
{"op":"mcm","clk":"5306775095","pt":1646105912997,"mc":[{"id":"1.195395431","rc":[{"atb":[[1.72,0]],"id":41375435}],"con":true,"img":false}]}
{"op":"mcm","clk":"5306775273","pt":1646105918726,"mc":[{"id":"1.195395431","rc":[{"atb":[[1.72,4.22]],"id":41375435}],"con":true,"img":false}]}
{"op":"mcm","clk":"5306775285","pt":1646105919131,"mc":[{"id":"1.195395431","rc":[{"atb":[[1.72,0]],"id":41375435}],"con":true,"img":false}]}
{"op":"mcm","clk":"5306775426","pt":1646105925124,"mc":[{"id":"1.195395431","rc":[{"atb":[[1.72,4.22]],"id":41375435}],"con":true,"img":false}]}
{"op":"mcm","clk":"5306775441","pt":1646105925433,"mc":[{"id":"1.195395431","rc":[{"atb":[[1.72,0]],"id":41375435}],"con":true,"img":false}]}
{"op":"mcm","clk":"5306775610","pt":1646105931216,"mc":[{"id":"1.195395431","rc":[{"atb":[[1.72,4.22]],"id":41375435}],"con":true,"img":false}]}
{"op":"mcm","clk":"5306775615","pt":1646105931627,"mc":[{"id":"1.195395431","rc":[{"atb":[[1.72,0]],"id":41375435}],"con":true,"img":false}]}
{"op":"mcm","clk":"5306775780","pt":1646105937040,"mc":[{"id":"1.195395431","rc":[{"atb":[[1.72,4.22]],"id":41375435}],"con":true,"img":false}]}
{"op":"mcm","clk":"5306775788","pt":1646105937244,"mc":[{"id":"1.195395431","rc":[{"atb":[[1.72,0]],"id":41375435}],"con":true,"img":false}]}
{"op":"mcm","clk":"5306775956","pt":1646105943120,"mc":[{"id":"1.195395431","rc":[{"atb":[[1.72,4.22]],"id":41375435}],"con":true,"img":false}]}
{"op":"mcm","clk":"5306775966","pt":1646105943426,"mc":[{"id":"1.195395431","rc":[{"atb":[[1.72,0]],"id":41375435}],"con":true,"img":false}]}
{"op":"mcm","clk":"5306776116","pt":1646105948436,"mc":[{"id":"1.195395431","rc":[{"atb":[[1.72,4.22]],"id":41375435}],"con":true,"img":false}]}
{"op":"mcm","clk":"5306776123","pt":1646105948843,"mc":[{"id":"1.195395431","rc":[{"atb":[[1.72,0]],"id":41375435}],"con":true,"img":false}]}
{"op":"mcm","clk":"5306776278","pt":1646105954167,"mc":[{"id":"1.195395431","rc":[{"atb":[[1.72,4.22]],"id":41375435}],"con":true,"img":false}]}
{"op":"mcm","clk":"5306776283","pt":1646105954475,"mc":[{"id":"1.195395431","rc":[{"atb":[[1.72,0]],"id":41375435}],"con":true,"img":false}]}
{"op":"mcm","clk":"5306776420","pt":1646105959438,"mc":[{"id":"1.195395431","rc":[{"atb":[[1.72,4.22]],"id":41375435}],"con":true,"img":false}]}
{"op":"mcm","clk":"5306776429","pt":1646105959742,"mc":[{"id":"1.195395431","rc":[{"atb":[[1.72,0]],"id":41375435}],"con":true,"img":false}]}
{"op":"mcm","clk":"5306776558","pt":1646105964967,"mc":[{"id":"1.195395431","rc":[{"atb":[[1.72,4.22]],"id":41375435}],"con":true,"img":false}]}
{"op":"mcm","clk":"5306776566","pt":1646105965275,"mc":[{"id":"1.195395431","rc":[{"atb":[[1.72,0]],"id":41375435}],"con":true,"img":false}]}
{"op":"mcm","clk":"5306776696","pt":1646105970393,"mc":[{"id":"1.195395431","rc":[{"atb":[[1.72,4.22]],"id":41375435}],"con":true,"img":false}]}
{"op":"mcm","clk":"5306776717","pt":1646105970855,"mc":[{"id":"1.195395431","rc":[{"atb":[[1.72,0]],"id":41375435}],"con":true,"img":false}]}
{"op":"mcm","clk":"5306776840","pt":1646105975962,"mc":[{"id":"1.195395431","rc":[{"atb":[[1.72,4.22]],"id":41375435}],"con":true,"img":false}]}
{"op":"mcm","clk":"5306776848","pt":1646105976269,"mc":[{"id":"1.195395431","rc":[{"atb":[[1.72,0]],"id":41375435}],"con":true,"img":false}]}
{"op":"mcm","clk":"5306777009","pt":1646105981388,"mc":[{"id":"1.195395431","rc":[{"atb":[[1.72,4.22]],"id":41375435}],"con":true,"img":false}]}
{"op":"mcm","clk":"5306777022","pt":1646105981795,"mc":[{"id":"1.195395431","rc":[{"atb":[[1.72,0]],"id":41375435}],"con":true,"img":false}]}
{"op":"mcm","clk":"5306777171","pt":1646105987112,"mc":[{"id":"1.195395431","rc":[{"atb":[[1.72,4.22]],"id":41375435}],"con":true,"img":false}]}
{"op":"mcm","clk":"5306777179","pt":1646105987421,"mc":[{"id":"1.195395431","rc":[{"atb":[[1.72,0]],"id":41375435}],"con":true,"img":false}]}
{"op":"mcm","clk":"5306777336","pt":1646105992497,"mc":[{"id":"1.195395431","rc":[{"atb":[[1.72,4.22]],"id":41375435}],"con":true,"img":false}]}
{"op":"mcm","clk":"5306777351","pt":1646105992803,"mc":[{"id":"1.195395431","rc":[{"atb":[[1.72,0]],"id":41375435}],"con":true,"img":false}]}
{"op":"mcm","clk":"5306777479","pt":1646105997709,"mc":[{"id":"1.195395431","rc":[{"atb":[[1.72,4.22]],"id":41375435}],"con":true,"img":false}]}
{"op":"mcm","clk":"5306777490","pt":1646105998118,"mc":[{"id":"1.195395431","rc":[{"atb":[[1.72,0]],"id":41375435}],"con":true,"img":false}]}
{"op":"mcm","clk":"5306777659","pt":1646106003901,"mc":[{"id":"1.195395431","rc":[{"atb":[[1.72,4.22]],"id":41375435}],"con":true,"img":false}]}
{"op":"mcm","clk":"5306777670","pt":1646106004205,"mc":[{"id":"1.195395431","rc":[{"atb":[[1.72,0]],"id":41375435}],"con":true,"img":false}]}
{"op":"mcm","clk":"5306777864","pt":1646106009946,"mc":[{"id":"1.195395431","rc":[{"atb":[[1.72,4.22]],"id":41375435}],"con":true,"img":false}]}
{"op":"mcm","clk":"5306777880","pt":1646106010405,"mc":[{"id":"1.195395431","rc":[{"atb":[[1.72,0]],"id":41375435}],"con":true,"img":false}]}
{"op":"mcm","clk":"5306778072","pt":1646106015625,"mc":[{"id":"1.195395431","rc":[{"atb":[[1.72,4.22]],"id":41375435}],"con":true,"img":false}]}
{"op":"mcm","clk":"5306778089","pt":1646106016032,"mc":[{"id":"1.195395431","rc":[{"atb":[[1.72,0]],"id":41375435}],"con":true,"img":false}]}
{"op":"mcm","clk":"5306778321","pt":1646106021415,"mc":[{"id":"1.195395431","rc":[{"atb":[[1.72,4.22]],"id":41375435}],"con":true,"img":false}]}
{"op":"mcm","clk":"5306778336","pt":1646106021827,"mc":[{"id":"1.195395431","rc":[{"atb":[[1.72,0]],"id":41375435}],"con":true,"img":false}]}
{"op":"mcm","clk":"5306778564","pt":1646106027367,"mc":[{"id":"1.195395431","rc":[{"atb":[[1.72,4.22]],"id":41375435}],"con":true,"img":false}]}
{"op":"mcm","clk":"5306778577","pt":1646106027626,"mc":[{"id":"1.195395431","rc":[{"atb":[[1.72,0]],"id":41375435}],"con":true,"img":false}]}
{"op":"mcm","clk":"5306778749","pt":1646106032549,"mc":[{"id":"1.195395431","rc":[{"atl":[[2.82,0]],"id":41375435},{"atl":[[27,0]],"id":35784172}],"con":true,"img":false}]}
{"op":"mcm","clk":"5306778752","pt":1646106032651,"mc":[{"id":"1.195395431","rc":[{"atl":[[2.78,31.88]],"id":41375435},{"atl":[[26,2.7]],"id":35784172}],"con":true,"img":false}]}
{"op":"mcm","clk":"5306778793","pt":1646106033574,"mc":[{"id":"1.195395431","rc":[{"atb":[[1.72,4.22]],"id":41375435}],"con":true,"img":false}]}
{"op":"mcm","clk":"5306778812","pt":1646106033984,"mc":[{"id":"1.195395431","rc":[{"atb":[[1.72,0]],"id":41375435}],"con":true,"img":false}]}
{"op":"mcm","clk":"5306779009","pt":1646106039258,"mc":[{"id":"1.195395431","rc":[{"atb":[[1.72,4.22]],"id":41375435}],"con":true,"img":false}]}
{"op":"mcm","clk":"5306779021","pt":1646106039564,"mc":[{"id":"1.195395431","rc":[{"atb":[[1.72,0]],"id":41375435}],"con":true,"img":false}]}
{"op":"mcm","clk":"5306779212","pt":1646106044987,"mc":[{"id":"1.195395431","rc":[{"atb":[[1.72,4.22]],"id":41375435}],"con":true,"img":false}]}
{"op":"mcm","clk":"5306779220","pt":1646106045294,"mc":[{"id":"1.195395431","rc":[{"atb":[[1.72,0]],"id":41375435}],"con":true,"img":false}]}
{"op":"mcm","clk":"5306779444","pt":1646106050360,"mc":[{"id":"1.195395431","rc":[{"atb":[[1.72,4.22]],"id":41375435}],"con":true,"img":false}]}
{"op":"mcm","clk":"5306779462","pt":1646106050667,"mc":[{"id":"1.195395431","rc":[{"atb":[[1.72,0]],"id":41375435}],"con":true,"img":false}]}
{"op":"mcm","clk":"5306779647","pt":1646106055997,"mc":[{"id":"1.195395431","rc":[{"atb":[[1.72,4.22]],"id":41375435}],"con":true,"img":false}]}
{"op":"mcm","clk":"5306779656","pt":1646106056303,"mc":[{"id":"1.195395431","rc":[{"atb":[[1.72,0]],"id":41375435}],"con":true,"img":false}]}
{"op":"mcm","clk":"5306779900","pt":1646106061880,"mc":[{"id":"1.195395431","rc":[{"atb":[[1.72,4.22]],"id":41375435}],"con":true,"img":false}]}
{"op":"mcm","clk":"5306779911","pt":1646106062288,"mc":[{"id":"1.195395431","rc":[{"atb":[[1.72,0]],"id":41375435}],"con":true,"img":false}]}
{"op":"mcm","clk":"5306780092","pt":1646106067715,"mc":[{"id":"1.195395431","rc":[{"atb":[[1.72,4.22]],"id":41375435}],"con":true,"img":false}]}
{"op":"mcm","clk":"5306780100","pt":1646106067919,"mc":[{"id":"1.195395431","rc":[{"atb":[[1.72,0]],"id":41375435}],"con":true,"img":false}]}
{"op":"mcm","clk":"5306780293","pt":1646106073602,"mc":[{"id":"1.195395431","rc":[{"atb":[[1.72,4.22]],"id":41375435},{"spn":18.5,"spf":1.0,"id":35784172}],"con":true,"img":false}]}
{"op":"mcm","clk":"5306780313","pt":1646106074012,"mc":[{"id":"1.195395431","rc":[{"atb":[[1.72,0]],"id":41375435}],"con":true,"img":false}]}
{"op":"mcm","clk":"5306780498","pt":1646106078929,"mc":[{"id":"1.195395431","rc":[{"atb":[[1.72,4.22]],"id":41375435}],"con":true,"img":false}]}
{"op":"mcm","clk":"5306780511","pt":1646106079237,"mc":[{"id":"1.195395431","rc":[{"atb":[[1.72,0]],"id":41375435}],"con":true,"img":false}]}
{"op":"mcm","clk":"5306780746","pt":1646106085030,"mc":[{"id":"1.195395431","rc":[{"atb":[[1.72,4.22]],"id":41375435}],"con":true,"img":false}]}
{"op":"mcm","clk":"5306780765","pt":1646106085443,"mc":[{"id":"1.195395431","rc":[{"atb":[[1.72,0]],"id":41375435}],"con":true,"img":false}]}
{"op":"mcm","clk":"5306780948","pt":1646106090720,"mc":[{"id":"1.195395431","rc":[{"atb":[[1.72,4.22]],"id":41375435}],"con":true,"img":false}]}
{"op":"mcm","clk":"5306780957","pt":1646106091128,"mc":[{"id":"1.195395431","rc":[{"atb":[[1.72,0]],"id":41375435}],"con":true,"img":false}]}
{"op":"mcm","clk":"5306781114","pt":1646106096252,"mc":[{"id":"1.195395431","rc":[{"atb":[[1.72,4.22]],"id":41375435}],"con":true,"img":false}]}
{"op":"mcm","clk":"5306781129","pt":1646106096611,"mc":[{"id":"1.195395431","rc":[{"atb":[[1.72,0]],"id":41375435}],"con":true,"img":false}]}
{"op":"mcm","clk":"5306781291","pt":1646106101931,"mc":[{"id":"1.195395431","rc":[{"atb":[[1.72,4.22]],"id":41375435}],"con":true,"img":false}]}
{"op":"mcm","clk":"5306781300","pt":1646106102443,"mc":[{"id":"1.195395431","rc":[{"atb":[[1.72,0]],"id":41375435}],"con":true,"img":false}]}
{"op":"mcm","clk":"5306781441","pt":1646106107557,"mc":[{"id":"1.195395431","rc":[{"atb":[[1.72,4.22]],"id":41375435}],"con":true,"img":false}]}
{"op":"mcm","clk":"5306781449","pt":1646106107864,"mc":[{"id":"1.195395431","rc":[{"atb":[[1.72,0]],"id":41375435}],"con":true,"img":false}]}
{"op":"mcm","clk":"5306781601","pt":1646106112842,"mc":[{"id":"1.195395431","rc":[{"atb":[[1.72,4.22]],"id":41375435}],"con":true,"img":false}]}
{"op":"mcm","clk":"5306781607","pt":1646106113146,"mc":[{"id":"1.195395431","rc":[{"atb":[[1.72,0]],"id":41375435}],"con":true,"img":false}]}
{"op":"mcm","clk":"5306781769","pt":1646106118377,"mc":[{"id":"1.195395431","rc":[{"atb":[[1.72,4.22]],"id":41375435}],"con":true,"img":false}]}
{"op":"mcm","clk":"5306781777","pt":1646106118786,"mc":[{"id":"1.195395431","rc":[{"atb":[[1.72,0]],"id":41375435}],"con":true,"img":false}]}
{"op":"mcm","clk":"5306782012","pt":1646106124179,"mc":[{"id":"1.195395431","rc":[{"atb":[[1.72,4.22]],"id":41375435}],"con":true,"img":false}]}
{"op":"mcm","clk":"5306782037","pt":1646106124695,"mc":[{"id":"1.195395431","rc":[{"atb":[[1.72,0]],"id":41375435}],"con":true,"img":false}]}
{"op":"mcm","clk":"5306782215","pt":1646106129762,"mc":[{"id":"1.195395431","rc":[{"atb":[[1.72,4.22]],"id":41375435}],"con":true,"img":false}]}
{"op":"mcm","clk":"5306782231","pt":1646106130170,"mc":[{"id":"1.195395431","rc":[{"atb":[[1.72,0]],"id":41375435}],"con":true,"img":false}]}
{"op":"mcm","clk":"5306782457","pt":1646106135398,"mc":[{"id":"1.195395431","rc":[{"atb":[[1.72,4.22]],"id":41375435}],"con":true,"img":false}]}
{"op":"mcm","clk":"5306782466","pt":1646106135705,"mc":[{"id":"1.195395431","rc":[{"atb":[[1.72,0]],"id":41375435}],"con":true,"img":false}]}
{"op":"mcm","clk":"5306782649","pt":1646106140671,"mc":[{"id":"1.195395431","rc":[{"atb":[[1.72,4.22]],"id":41375435}],"con":true,"img":false}]}
{"op":"mcm","clk":"5306782662","pt":1646106141081,"mc":[{"id":"1.195395431","rc":[{"atb":[[1.72,0]],"id":41375435}],"con":true,"img":false}]}
{"op":"mcm","clk":"5306782837","pt":1646106145991,"mc":[{"id":"1.195395431","rc":[{"atb":[[1.72,4.22]],"id":41375435}],"con":true,"img":false}]}
{"op":"mcm","clk":"5306782848","pt":1646106146398,"mc":[{"id":"1.195395431","rc":[{"atb":[[1.72,0]],"id":41375435}],"con":true,"img":false}]}
{"op":"mcm","clk":"5306783017","pt":1646106151308,"mc":[{"id":"1.195395431","rc":[{"atb":[[1.72,4.22]],"id":41375435}],"con":true,"img":false}]}
{"op":"mcm","clk":"5306783025","pt":1646106151514,"mc":[{"id":"1.195395431","rc":[{"atb":[[1.72,0]],"id":41375435}],"con":true,"img":false}]}
{"op":"mcm","clk":"5306783206","pt":1646106156523,"mc":[{"id":"1.195395431","rc":[{"atb":[[1.72,4.22]],"id":41375435}],"con":true,"img":false}]}
{"op":"mcm","clk":"5306783218","pt":1646106156830,"mc":[{"id":"1.195395431","rc":[{"atb":[[1.72,0]],"id":41375435}],"con":true,"img":false}]}
{"op":"mcm","clk":"5306783423","pt":1646106161805,"mc":[{"id":"1.195395431","rc":[{"atb":[[1.72,4.22]],"id":41375435}],"con":true,"img":false}]}
{"op":"mcm","clk":"5306783430","pt":1646106162012,"mc":[{"id":"1.195395431","rc":[{"atb":[[1.72,0]],"id":41375435}],"con":true,"img":false}]}
{"op":"mcm","clk":"5306783637","pt":1646106167437,"mc":[{"id":"1.195395431","rc":[{"atb":[[1.72,4.22]],"id":41375435}],"con":true,"img":false}]}
{"op":"mcm","clk":"5306783652","pt":1646106167845,"mc":[{"id":"1.195395431","rc":[{"atb":[[1.72,0]],"id":41375435}],"con":true,"img":false}]}
{"op":"mcm","clk":"5306783864","pt":1646106173116,"mc":[{"id":"1.195395431","rc":[{"atb":[[1.72,4.22]],"id":41375435}],"con":true,"img":false}]}
{"op":"mcm","clk":"5306783877","pt":1646106173526,"mc":[{"id":"1.195395431","rc":[{"atb":[[1.72,0]],"id":41375435}],"con":true,"img":false}]}
{"op":"mcm","clk":"5306784042","pt":1646106178455,"mc":[{"id":"1.195395431","rc":[{"atb":[[1.72,4.22]],"id":41375435}],"con":true,"img":false}]}
{"op":"mcm","clk":"5306784055","pt":1646106178764,"mc":[{"id":"1.195395431","rc":[{"atb":[[1.72,0]],"id":41375435}],"con":true,"img":false}]}
{"op":"mcm","clk":"5306784226","pt":1646106184442,"mc":[{"id":"1.195395431","rc":[{"atb":[[1.72,4.22]],"id":41375435}],"con":true,"img":false}]}
{"op":"mcm","clk":"5306784238","pt":1646106184851,"mc":[{"id":"1.195395431","rc":[{"atb":[[1.72,0]],"id":41375435}],"con":true,"img":false}]}
{"op":"mcm","clk":"5306784401","pt":1646106189761,"mc":[{"id":"1.195395431","rc":[{"atb":[[1.72,4.22]],"id":41375435}],"con":true,"img":false}]}
{"op":"mcm","clk":"5306784412","pt":1646106190169,"mc":[{"id":"1.195395431","rc":[{"atb":[[1.72,0]],"id":41375435}],"con":true,"img":false}]}
{"op":"mcm","clk":"5306784582","pt":1646106195445,"mc":[{"id":"1.195395431","rc":[{"atb":[[1.72,4.22]],"id":41375435}],"con":true,"img":false}]}
{"op":"mcm","clk":"5306784593","pt":1646106195849,"mc":[{"id":"1.195395431","rc":[{"atb":[[1.72,0]],"id":41375435}],"con":true,"img":false}]}
{"op":"mcm","clk":"5306784760","pt":1646106200962,"mc":[{"id":"1.195395431","rc":[{"atb":[[1.72,4.22]],"id":41375435}],"con":true,"img":false}]}
{"op":"mcm","clk":"5306784774","pt":1646106201478,"mc":[{"id":"1.195395431","rc":[{"atb":[[1.72,0]],"id":41375435}],"con":true,"img":false}]}
{"op":"mcm","clk":"5306784920","pt":1646106206289,"mc":[{"id":"1.195395431","rc":[{"atb":[[1.72,4.22]],"id":41375435}],"con":true,"img":false}]}
{"op":"mcm","clk":"5306784930","pt":1646106206598,"mc":[{"id":"1.195395431","rc":[{"atb":[[1.72,0]],"id":41375435}],"con":true,"img":false}]}
{"op":"mcm","clk":"5306785100","pt":1646106211975,"mc":[{"id":"1.195395431","rc":[{"atb":[[1.72,4.22]],"id":41375435}],"con":true,"img":false}]}
{"op":"mcm","clk":"5306785115","pt":1646106212381,"mc":[{"id":"1.195395431","rc":[{"atb":[[1.72,0]],"id":41375435}],"con":true,"img":false}]}
{"op":"mcm","clk":"5306785245","pt":1646106217087,"mc":[{"id":"1.195395431","rc":[{"atb":[[1.72,4.22]],"id":41375435}],"con":true,"img":false}]}
{"op":"mcm","clk":"5306785257","pt":1646106217494,"mc":[{"id":"1.195395431","rc":[{"atb":[[1.72,0]],"id":41375435}],"con":true,"img":false}]}
{"op":"mcm","clk":"5306785413","pt":1646106222510,"mc":[{"id":"1.195395431","rc":[{"atb":[[1.72,4.22]],"id":41375435}],"con":true,"img":false}]}
{"op":"mcm","clk":"5306785422","pt":1646106222920,"mc":[{"id":"1.195395431","rc":[{"atb":[[1.72,0]],"id":41375435}],"con":true,"img":false}]}
{"op":"mcm","clk":"5306785572","pt":1646106227681,"mc":[{"id":"1.195395431","rc":[{"atb":[[1.72,4.22]],"id":41375435}],"con":true,"img":false}]}
{"op":"mcm","clk":"5306785578","pt":1646106227991,"mc":[{"id":"1.195395431","rc":[{"atb":[[1.72,0]],"id":41375435}],"con":true,"img":false}]}
{"op":"mcm","clk":"5306785711","pt":1646106232593,"mc":[{"id":"1.195395431","rc":[{"atb":[[1.72,4.22]],"id":41375435}],"con":true,"img":false}]}
{"op":"mcm","clk":"5306785724","pt":1646106233105,"mc":[{"id":"1.195395431","rc":[{"atb":[[1.72,0]],"id":41375435}],"con":true,"img":false}]}
{"op":"mcm","clk":"5306785895","pt":1646106237912,"mc":[{"id":"1.195395431","rc":[{"atb":[[1.72,4.22]],"id":41375435}],"con":true,"img":false}]}
{"op":"mcm","clk":"5306785909","pt":1646106238322,"mc":[{"id":"1.195395431","rc":[{"atb":[[1.72,0]],"id":41375435}],"con":true,"img":false}]}
{"op":"mcm","clk":"5306786079","pt":1646106243242,"mc":[{"id":"1.195395431","rc":[{"atb":[[1.72,4.22]],"id":41375435}],"con":true,"img":false}]}
{"op":"mcm","clk":"5306786086","pt":1646106243501,"mc":[{"id":"1.195395431","rc":[{"atb":[[1.72,0]],"id":41375435}],"con":true,"img":false}]}
{"op":"mcm","clk":"5306786271","pt":1646106249332,"mc":[{"id":"1.195395431","rc":[{"atb":[[1.72,4.22]],"id":41375435}],"con":true,"img":false}]}
{"op":"mcm","clk":"5306786282","pt":1646106249845,"mc":[{"id":"1.195395431","rc":[{"atb":[[1.72,0]],"id":41375435}],"con":true,"img":false}]}
{"op":"mcm","clk":"5306786446","pt":1646106254659,"mc":[{"id":"1.195395431","rc":[{"atb":[[1.72,4.22]],"id":41375435}],"con":true,"img":false}]}
{"op":"mcm","clk":"5306786453","pt":1646106255020,"mc":[{"id":"1.195395431","rc":[{"atb":[[1.72,0]],"id":41375435}],"con":true,"img":false}]}
{"op":"mcm","clk":"5306786626","pt":1646106260166,"mc":[{"id":"1.195395431","rc":[{"atb":[[1.72,4.22]],"id":41375435}],"con":true,"img":false}]}
{"op":"mcm","clk":"5306786635","pt":1646106260425,"mc":[{"id":"1.195395431","rc":[{"atb":[[1.72,0]],"id":41375435}],"con":true,"img":false}]}
{"op":"mcm","clk":"5306786803","pt":1646106265447,"mc":[{"id":"1.195395431","rc":[{"atb":[[1.72,4.22]],"id":41375435}],"con":true,"img":false}]}
{"op":"mcm","clk":"5306786814","pt":1646106265755,"mc":[{"id":"1.195395431","rc":[{"atb":[[1.72,0]],"id":41375435}],"con":true,"img":false}]}
{"op":"mcm","clk":"5306786955","pt":1646106270665,"mc":[{"id":"1.195395431","rc":[{"atb":[[1.72,4.22]],"id":41375435}],"con":true,"img":false}]}
{"op":"mcm","clk":"5306786966","pt":1646106270973,"mc":[{"id":"1.195395431","rc":[{"atb":[[1.72,0]],"id":41375435}],"con":true,"img":false}]}
{"op":"mcm","clk":"5306787103","pt":1646106275841,"mc":[{"id":"1.195395431","rc":[{"atb":[[1.72,4.22]],"id":41375435}],"con":true,"img":false}]}
{"op":"mcm","clk":"5306787114","pt":1646106276148,"mc":[{"id":"1.195395431","rc":[{"atb":[[1.72,0]],"id":41375435}],"con":true,"img":false}]}
{"op":"mcm","clk":"5306787261","pt":1646106281069,"mc":[{"id":"1.195395431","rc":[{"atb":[[1.72,4.22]],"id":41375435}],"con":true,"img":false}]}
{"op":"mcm","clk":"5306787274","pt":1646106281478,"mc":[{"id":"1.195395431","rc":[{"atb":[[1.72,0]],"id":41375435}],"con":true,"img":false}]}
{"op":"mcm","clk":"5306787425","pt":1646106286399,"mc":[{"id":"1.195395431","rc":[{"atb":[[1.72,4.22]],"id":41375435}],"con":true,"img":false}]}
{"op":"mcm","clk":"5306787441","pt":1646106286763,"mc":[{"id":"1.195395431","rc":[{"atb":[[1.72,0]],"id":41375435}],"con":true,"img":false}]}
{"op":"mcm","clk":"5306787620","pt":1646106292503,"mc":[{"id":"1.195395431","rc":[{"atb":[[1.72,4.22]],"id":41375435}],"con":true,"img":false}]}
{"op":"mcm","clk":"5306787635","pt":1646106292810,"mc":[{"id":"1.195395431","rc":[{"atb":[[1.72,0]],"id":41375435}],"con":true,"img":false}]}
{"op":"mcm","clk":"5306787802","pt":1646106297591,"mc":[{"id":"1.195395431","rc":[{"atb":[[1.72,4.22]],"id":41375435}],"con":true,"img":false}]}
{"op":"mcm","clk":"5306787822","pt":1646106298105,"mc":[{"id":"1.195395431","rc":[{"atb":[[1.72,0]],"id":41375435}],"con":true,"img":false}]}
{"op":"mcm","clk":"5306787967","pt":1646106302893,"mc":[{"id":"1.195395431","rc":[{"atb":[[1.72,4.22]],"id":41375435}],"con":true,"img":false}]}
{"op":"mcm","clk":"5306787976","pt":1646106303203,"mc":[{"id":"1.195395431","rc":[{"atb":[[1.72,0]],"id":41375435}],"con":true,"img":false}]}
{"op":"mcm","clk":"5306788151","pt":1646106308524,"mc":[{"id":"1.195395431","rc":[{"atb":[[1.72,4.22]],"id":41375435}],"con":true,"img":false}]}
{"op":"mcm","clk":"5306788160","pt":1646106308935,"mc":[{"id":"1.195395431","rc":[{"atb":[[1.72,0]],"id":41375435}],"con":true,"img":false}]}
{"op":"mcm","clk":"5306788311","pt":1646106314027,"mc":[{"id":"1.195395431","rc":[{"atb":[[1.72,4.22]],"id":41375435}],"con":true,"img":false}]}
{"op":"mcm","clk":"5306788325","pt":1646106314334,"mc":[{"id":"1.195395431","rc":[{"atb":[[1.72,0]],"id":41375435}],"con":true,"img":false}]}
{"op":"mcm","clk":"5306788471","pt":1646106319822,"mc":[{"id":"1.195395431","rc":[{"atb":[[1.72,4.22]],"id":41375435}],"con":true,"img":false}]}
{"op":"mcm","clk":"5306788478","pt":1646106320130,"mc":[{"id":"1.195395431","rc":[{"atb":[[1.72,0]],"id":41375435}],"con":true,"img":false}]}
{"op":"mcm","clk":"5306788612","pt":1646106325247,"mc":[{"id":"1.195395431","rc":[{"atb":[[1.72,4.22]],"id":41375435}],"con":true,"img":false}]}
{"op":"mcm","clk":"5306788619","pt":1646106325656,"mc":[{"id":"1.195395431","rc":[{"atb":[[1.72,0]],"id":41375435}],"con":true,"img":false}]}
{"op":"mcm","clk":"5306788765","pt":1646106330451,"mc":[{"id":"1.195395431","rc":[{"atb":[[1.72,4.22]],"id":41375435}],"con":true,"img":false}]}
{"op":"mcm","clk":"5306788782","pt":1646106330859,"mc":[{"id":"1.195395431","rc":[{"atb":[[1.72,0]],"id":41375435}],"con":true,"img":false}]}
{"op":"mcm","clk":"5306788915","pt":1646106335738,"mc":[{"id":"1.195395431","rc":[{"atb":[[1.72,4.22]],"id":41375435}],"con":true,"img":false}]}
{"op":"mcm","clk":"5306788931","pt":1646106336045,"mc":[{"id":"1.195395431","rc":[{"atb":[[1.72,0]],"id":41375435}],"con":true,"img":false}]}
{"op":"mcm","clk":"5306789114","pt":1646106341161,"mc":[{"id":"1.195395431","rc":[{"atb":[[1.72,4.22]],"id":41375435}],"con":true,"img":false}]}
{"op":"mcm","clk":"5306789120","pt":1646106341463,"mc":[{"id":"1.195395431","rc":[{"atb":[[1.72,0]],"id":41375435}],"con":true,"img":false}]}
{"op":"mcm","clk":"5306789280","pt":1646106346778,"mc":[{"id":"1.195395431","rc":[{"atb":[[1.72,4.22]],"id":41375435}],"con":true,"img":false}]}
{"op":"mcm","clk":"5306789290","pt":1646106347086,"mc":[{"id":"1.195395431","rc":[{"atb":[[1.72,0]],"id":41375435}],"con":true,"img":false}]}
{"op":"mcm","clk":"5306789463","pt":1646106352197,"mc":[{"id":"1.195395431","rc":[{"atb":[[1.72,4.22]],"id":41375435}],"con":true,"img":false}]}
{"op":"mcm","clk":"5306789471","pt":1646106352456,"mc":[{"id":"1.195395431","rc":[{"atb":[[1.72,0]],"id":41375435}],"con":true,"img":false}]}
{"op":"mcm","clk":"5306789642","pt":1646106357564,"mc":[{"id":"1.195395431","rc":[{"atb":[[1.72,4.22]],"id":41375435}],"con":true,"img":false}]}
{"op":"mcm","clk":"5306789658","pt":1646106357973,"mc":[{"id":"1.195395431","rc":[{"atb":[[1.72,0]],"id":41375435}],"con":true,"img":false}]}
{"op":"mcm","clk":"5306789812","pt":1646106362885,"mc":[{"id":"1.195395431","rc":[{"atb":[[1.72,4.22]],"id":41375435}],"con":true,"img":false}]}
{"op":"mcm","clk":"5306789820","pt":1646106363194,"mc":[{"id":"1.195395431","rc":[{"atb":[[1.72,0]],"id":41375435}],"con":true,"img":false}]}
{"op":"mcm","clk":"5306789988","pt":1646106368687,"mc":[{"id":"1.195395431","rc":[{"atb":[[1.72,4.22]],"id":41375435}],"con":true,"img":false}]}
{"op":"mcm","clk":"5306789999","pt":1646106369099,"mc":[{"id":"1.195395431","rc":[{"atb":[[1.72,0]],"id":41375435}],"con":true,"img":false}]}
{"op":"mcm","clk":"5306790170","pt":1646106373908,"mc":[{"id":"1.195395431","rc":[{"atb":[[1.72,4.22]],"id":41375435}],"con":true,"img":false}]}
{"op":"mcm","clk":"5306790176","pt":1646106374217,"mc":[{"id":"1.195395431","rc":[{"atb":[[1.72,0]],"id":41375435}],"con":true,"img":false}]}
{"op":"mcm","clk":"5306790354","pt":1646106379425,"mc":[{"id":"1.195395431","rc":[{"atb":[[1.72,4.22]],"id":41375435}],"con":true,"img":false}]}
{"op":"mcm","clk":"5306790360","pt":1646106379732,"mc":[{"id":"1.195395431","rc":[{"atb":[[1.72,0]],"id":41375435}],"con":true,"img":false}]}
{"op":"mcm","clk":"5306790547","pt":1646106385509,"mc":[{"id":"1.195395431","rc":[{"atb":[[1.72,4.22]],"id":41375435}],"con":true,"img":false}]}
{"op":"mcm","clk":"5306790556","pt":1646106385814,"mc":[{"id":"1.195395431","rc":[{"atb":[[1.72,0]],"id":41375435}],"con":true,"img":false}]}
{"op":"mcm","clk":"5306790723","pt":1646106390927,"mc":[{"id":"1.195395431","rc":[{"atb":[[1.72,4.22]],"id":41375435}],"con":true,"img":false}]}
{"op":"mcm","clk":"5306790736","pt":1646106391441,"mc":[{"id":"1.195395431","rc":[{"atb":[[1.72,0]],"id":41375435}],"con":true,"img":false}]}
{"op":"mcm","clk":"5306790884","pt":1646106396343,"mc":[{"id":"1.195395431","rc":[{"atb":[[1.72,4.22]],"id":41375435}],"con":true,"img":false}]}
{"op":"mcm","clk":"5306790891","pt":1646106396753,"mc":[{"id":"1.195395431","rc":[{"atb":[[1.72,0]],"id":41375435}],"con":true,"img":false}]}
{"op":"mcm","clk":"5306791020","pt":1646106401838,"mc":[{"id":"1.195395431","rc":[{"atb":[[1.72,4.22]],"id":41375435}],"con":true,"img":false}]}
{"op":"mcm","clk":"5306791027","pt":1646106402248,"mc":[{"id":"1.195395431","rc":[{"atb":[[1.72,0]],"id":41375435}],"con":true,"img":false}]}
{"op":"mcm","clk":"5306791169","pt":1646106407416,"mc":[{"id":"1.195395431","rc":[{"atb":[[1.72,4.22]],"id":41375435}],"con":true,"img":false}]}
{"op":"mcm","clk":"5306791182","pt":1646106407927,"mc":[{"id":"1.195395431","rc":[{"atb":[[1.72,0]],"id":41375435}],"con":true,"img":false}]}
{"op":"mcm","clk":"5306791331","pt":1646106412763,"mc":[{"id":"1.195395431","rc":[{"atb":[[1.72,4.22]],"id":41375435}],"con":true,"img":false}]}
{"op":"mcm","clk":"5306791345","pt":1646106413170,"mc":[{"id":"1.195395431","rc":[{"atb":[[1.72,0]],"id":41375435}],"con":true,"img":false}]}
{"op":"mcm","clk":"5306791487","pt":1646106418429,"mc":[{"id":"1.195395431","rc":[{"atb":[[1.72,4.22]],"id":41375435}],"con":true,"img":false}]}
{"op":"mcm","clk":"5306791496","pt":1646106418839,"mc":[{"id":"1.195395431","rc":[{"atb":[[1.72,0]],"id":41375435}],"con":true,"img":false}]}
{"op":"mcm","clk":"5306791644","pt":1646106423649,"mc":[{"id":"1.195395431","rc":[{"atb":[[1.72,4.22]],"id":41375435}],"con":true,"img":false}]}
{"op":"mcm","clk":"5306791660","pt":1646106424058,"mc":[{"id":"1.195395431","rc":[{"atb":[[1.72,0]],"id":41375435}],"con":true,"img":false}]}
{"op":"mcm","clk":"5306791801","pt":1646106429168,"mc":[{"id":"1.195395431","rc":[{"atb":[[1.72,4.22]],"id":41375435}],"con":true,"img":false}]}
{"op":"mcm","clk":"5306791815","pt":1646106429678,"mc":[{"id":"1.195395431","rc":[{"atb":[[1.72,0]],"id":41375435}],"con":true,"img":false}]}
{"op":"mcm","clk":"5306791936","pt":1646106434378,"mc":[{"id":"1.195395431","rc":[{"atb":[[1.72,4.22]],"id":41375435}],"con":true,"img":false}]}
{"op":"mcm","clk":"5306791943","pt":1646106434786,"mc":[{"id":"1.195395431","rc":[{"atb":[[1.72,0]],"id":41375435}],"con":true,"img":false}]}
{"op":"mcm","clk":"5306792058","pt":1646106439680,"mc":[{"id":"1.195395431","rc":[{"atb":[[1.72,4.22]],"id":41375435}],"con":true,"img":false}]}
{"op":"mcm","clk":"5306792068","pt":1646106440088,"mc":[{"id":"1.195395431","rc":[{"atb":[[1.72,0]],"id":41375435}],"con":true,"img":false}]}
{"op":"mcm","clk":"5306792180","pt":1646106445095,"mc":[{"id":"1.195395431","rc":[{"atb":[[1.72,4.22]],"id":41375435}],"con":true,"img":false}]}
{"op":"mcm","clk":"5306792190","pt":1646106445503,"mc":[{"id":"1.195395431","rc":[{"atb":[[1.72,0]],"id":41375435}],"con":true,"img":false}]}
{"op":"mcm","clk":"5306792386","pt":1646106451280,"mc":[{"id":"1.195395431","rc":[{"atb":[[1.72,4.22]],"id":41375435}],"con":true,"img":false}]}
{"op":"mcm","clk":"5306792397","pt":1646106451587,"mc":[{"id":"1.195395431","rc":[{"atb":[[1.72,0]],"id":41375435}],"con":true,"img":false}]}
{"op":"mcm","clk":"5306792593","pt":1646106456799,"mc":[{"id":"1.195395431","rc":[{"atb":[[1.72,4.22]],"id":41375435}],"con":true,"img":false}]}
{"op":"mcm","clk":"5306792605","pt":1646106457105,"mc":[{"id":"1.195395431","rc":[{"atb":[[1.72,0]],"id":41375435}],"con":true,"img":false}]}
{"op":"mcm","clk":"5306792768","pt":1646106461910,"mc":[{"id":"1.195395431","rc":[{"atb":[[1.72,4.22]],"id":41375435}],"con":true,"img":false}]}
{"op":"mcm","clk":"5306792780","pt":1646106462216,"mc":[{"id":"1.195395431","rc":[{"atb":[[1.72,0]],"id":41375435}],"con":true,"img":false}]}
{"op":"mcm","clk":"5306792924","pt":1646106467020,"mc":[{"id":"1.195395431","rc":[{"atb":[[1.72,4.22]],"id":41375435}],"con":true,"img":false}]}
{"op":"mcm","clk":"5306792937","pt":1646106467429,"mc":[{"id":"1.195395431","rc":[{"atb":[[1.72,0]],"id":41375435}],"con":true,"img":false}]}
{"op":"mcm","clk":"5306793094","pt":1646106472228,"mc":[{"id":"1.195395431","rc":[{"atb":[[1.72,4.22]],"id":41375435}],"con":true,"img":false}]}
{"op":"mcm","clk":"5306793103","pt":1646106472531,"mc":[{"id":"1.195395431","rc":[{"atb":[[1.72,0]],"id":41375435}],"con":true,"img":false}]}
{"op":"mcm","clk":"5306793255","pt":1646106477539,"mc":[{"id":"1.195395431","rc":[{"atb":[[1.72,4.22]],"id":41375435}],"con":true,"img":false}]}
{"op":"mcm","clk":"5306793268","pt":1646106477945,"mc":[{"id":"1.195395431","rc":[{"atb":[[1.72,0]],"id":41375435}],"con":true,"img":false}]}
{"op":"mcm","clk":"5306793433","pt":1646106483165,"mc":[{"id":"1.195395431","rc":[{"atb":[[1.72,4.22]],"id":41375435}],"con":true,"img":false}]}
{"op":"mcm","clk":"5306793442","pt":1646106483370,"mc":[{"id":"1.195395431","rc":[{"atb":[[1.72,0]],"id":41375435}],"con":true,"img":false}]}
{"op":"mcm","clk":"5306793631","pt":1646106488536,"mc":[{"id":"1.195395431","rc":[{"atb":[[1.72,4.22]],"id":41375435}],"con":true,"img":false}]}
{"op":"mcm","clk":"5306793644","pt":1646106488944,"mc":[{"id":"1.195395431","rc":[{"atb":[[1.72,0]],"id":41375435}],"con":true,"img":false}]}
{"op":"mcm","clk":"5306793888","pt":1646106493963,"mc":[{"id":"1.195395431","rc":[{"atb":[[1.72,4.22]],"id":41375435}],"con":true,"img":false}]}
{"op":"mcm","clk":"5306793902","pt":1646106494372,"mc":[{"id":"1.195395431","rc":[{"atb":[[1.72,0]],"id":41375435}],"con":true,"img":false}]}
{"op":"mcm","clk":"5306794116","pt":1646106499591,"mc":[{"id":"1.195395431","rc":[{"atb":[[1.72,4.22]],"id":41375435}],"con":true,"img":false}]}
{"op":"mcm","clk":"5306794134","pt":1646106499950,"mc":[{"id":"1.195395431","rc":[{"atb":[[1.72,0]],"id":41375435}],"con":true,"img":false}]}
{"op":"mcm","clk":"5306794341","pt":1646106504904,"mc":[{"id":"1.195395431","rc":[{"atb":[[1.72,4.22]],"id":41375435}],"con":true,"img":false}]}
{"op":"mcm","clk":"5306794353","pt":1646106505161,"mc":[{"id":"1.195395431","rc":[{"atb":[[1.72,0]],"id":41375435}],"con":true,"img":false}]}
{"op":"mcm","clk":"5306794548","pt":1646106510173,"mc":[{"id":"1.195395431","rc":[{"atb":[[1.72,4.22]],"id":41375435}],"con":true,"img":false}]}
{"op":"mcm","clk":"5306794562","pt":1646106510583,"mc":[{"id":"1.195395431","rc":[{"atb":[[1.72,0]],"id":41375435}],"con":true,"img":false}]}
{"op":"mcm","clk":"5306794755","pt":1646106515397,"mc":[{"id":"1.195395431","rc":[{"atb":[[1.72,4.22]],"id":41375435}],"con":true,"img":false}]}
{"op":"mcm","clk":"5306794770","pt":1646106515706,"mc":[{"id":"1.195395431","rc":[{"atb":[[1.72,0]],"id":41375435}],"con":true,"img":false}]}
{"op":"mcm","clk":"5306794963","pt":1646106521591,"mc":[{"id":"1.195395431","rc":[{"atb":[[1.72,4.22]],"id":41375435}],"con":true,"img":false}]}
{"op":"mcm","clk":"5306794980","pt":1646106522000,"mc":[{"id":"1.195395431","rc":[{"atb":[[1.72,0]],"id":41375435}],"con":true,"img":false}]}
{"op":"mcm","clk":"5306795150","pt":1646106527522,"mc":[{"id":"1.195395431","rc":[{"atb":[[1.72,4.22]],"id":41375435}],"con":true,"img":false}]}
{"op":"mcm","clk":"5306795162","pt":1646106527828,"mc":[{"id":"1.195395431","rc":[{"atb":[[1.72,0]],"id":41375435}],"con":true,"img":false}]}
{"op":"mcm","clk":"5306795353","pt":1646106532951,"mc":[{"id":"1.195395431","rc":[{"atb":[[1.72,4.22]],"id":41375435}],"con":true,"img":false}]}
{"op":"mcm","clk":"5306795366","pt":1646106533207,"mc":[{"id":"1.195395431","rc":[{"atb":[[1.72,0]],"id":41375435}],"con":true,"img":false}]}
{"op":"mcm","clk":"5306795557","pt":1646106538624,"mc":[{"id":"1.195395431","rc":[{"atb":[[1.72,4.22]],"id":41375435}],"con":true,"img":false}]}
{"op":"mcm","clk":"5306795567","pt":1646106538932,"mc":[{"id":"1.195395431","rc":[{"atb":[[1.72,0]],"id":41375435}],"con":true,"img":false}]}
{"op":"mcm","clk":"5306795751","pt":1646106543954,"mc":[{"id":"1.195395431","rc":[{"atb":[[1.72,4.22]],"id":41375435}],"con":true,"img":false}]}
{"op":"mcm","clk":"5306795763","pt":1646106544261,"mc":[{"id":"1.195395431","rc":[{"atb":[[1.72,0]],"id":41375435}],"con":true,"img":false}]}
{"op":"mcm","clk":"5306795901","pt":1646106549035,"mc":[{"id":"1.195395431","rc":[{"atb":[[4.5,0],[2.62,0]],"id":39296632},{"atl":[[130,0]],"id":39296632},{"atb":[[1.3,0]],"id":41375435},{"atl":[[34,0],[2.84,0],[17,0]],"id":41375435},{"atb":[[2.62,0],[6.6,0],[4.2,0]],"id":41729332},{"atl":[[110,0]],"id":41729332},{"atb":[[2.62,0],[4.7,0]],"id":27453791},{"atl":[[70,0]],"id":27453791},{"atb":[[1.86,0]],"id":41375430},{"atl":[[17,0],[34,0],[13,0]],"id":41375430},{"atb":[[16,0],[2.62,0],[4.2,0]],"id":38124326},{"atb":[[5.5,0],[2.62,0]],"id":35784172},{"atl":[[70,0]],"id":35784172},{"atb":[[11.5,0],[2.62,0],[4.2,0]],"id":41375426}],"con":true,"img":false}]}
{"op":"mcm","clk":"5306795924","pt":1646106549750,"mc":[{"id":"1.195395431","rc":[{"atb":[[1.72,4.22]],"id":41375435}],"con":true,"img":false}]}
{"op":"mcm","clk":"5306795932","pt":1646106550056,"mc":[{"id":"1.195395431","rc":[{"atb":[[1.72,0]],"id":41375435}],"con":true,"img":false}]}
{"op":"mcm","clk":"5306796106","pt":1646106555739,"mc":[{"id":"1.195395431","rc":[{"atb":[[1.72,4.22]],"id":41375435}],"con":true,"img":false}]}
{"op":"mcm","clk":"5306796120","pt":1646106556148,"mc":[{"id":"1.195395431","rc":[{"atb":[[1.72,0]],"id":41375435}],"con":true,"img":false}]}
{"op":"mcm","clk":"5306796287","pt":1646106561564,"mc":[{"id":"1.195395431","rc":[{"atb":[[1.72,4.22]],"id":41375435}],"con":true,"img":false}]}
{"op":"mcm","clk":"5306796303","pt":1646106562075,"mc":[{"id":"1.195395431","rc":[{"atb":[[1.72,0]],"id":41375435}],"con":true,"img":false}]}
{"op":"mcm","clk":"5306796414","pt":1646106567279,"mc":[{"id":"1.195395431","rc":[{"atb":[[1.72,4.22]],"id":41375435}],"con":true,"img":false}]}
{"op":"mcm","clk":"5306796427","pt":1646106567686,"mc":[{"id":"1.195395431","rc":[{"atb":[[1.72,0]],"id":41375435}],"con":true,"img":false}]}
{"op":"mcm","clk":"5306796541","pt":1646106572863,"mc":[{"id":"1.195395431","rc":[{"atb":[[1.72,4.22]],"id":41375435}],"con":true,"img":false}]}
{"op":"mcm","clk":"5306796547","pt":1646106573271,"mc":[{"id":"1.195395431","rc":[{"atb":[[1.72,0]],"id":41375435}],"con":true,"img":false}]}
{"op":"mcm","clk":"5306796671","pt":1646106578684,"mc":[{"id":"1.195395431","rc":[{"atb":[[1.72,4.22]],"id":41375435}],"con":true,"img":false}]}
{"op":"mcm","clk":"5306796680","pt":1646106579092,"mc":[{"id":"1.195395431","rc":[{"atb":[[1.72,0]],"id":41375435}],"con":true,"img":false}]}
{"op":"mcm","clk":"5306796818","pt":1646106584805,"mc":[{"id":"1.195395431","rc":[{"atb":[[1.72,4.22]],"id":41375435}],"con":true,"img":false}]}
{"op":"mcm","clk":"5306796825","pt":1646106585211,"mc":[{"id":"1.195395431","rc":[{"atb":[[1.72,0]],"id":41375435}],"con":true,"img":false}]}
{"op":"mcm","clk":"5306796923","pt":1646106590513,"mc":[{"id":"1.195395431","rc":[{"atb":[[1.72,4.22]],"id":41375435}],"con":true,"img":false}]}
{"op":"mcm","clk":"5306796927","pt":1646106590819,"mc":[{"id":"1.195395431","rc":[{"atb":[[1.72,0]],"id":41375435}],"con":true,"img":false}]}
{"op":"mcm","clk":"5306797042","pt":1646106596178,"mc":[{"id":"1.195395431","rc":[{"atb":[[1.72,4.22]],"id":41375435}],"con":true,"img":false}]}
{"op":"mcm","clk":"5306797052","pt":1646106596484,"mc":[{"id":"1.195395431","rc":[{"atb":[[1.72,0]],"id":41375435}],"con":true,"img":false}]}
{"op":"mcm","clk":"5306797141","pt":1646106600114,"mc":[{"id":"1.195395431","rc":[{"atb":[[2.66,45.18]],"id":39296632},{"atb":[[2.66,45.18]],"id":41729332},{"atb":[[2.66,45.18]],"id":27453791},{"atb":[[4.3,46.97],[2.66,45.18]],"id":38124326}],"con":true,"img":false}]}
{"op":"mcm","clk":"5306797144","pt":1646106600216,"mc":[{"id":"1.195395431","rc":[{"atl":[[17,11.5],[34,15.5]],"id":41375435},{"atb":[[4.3,46.97]],"id":41729332},{"atb":[[4.3,46.97]],"id":27453791},{"atl":[[17,11.5],[34,15.5]],"id":41375430},{"atb":[[4.3,46.97],[2.66,45.18]],"id":35784172},{"atb":[[4.3,46.97],[2.66,45.18]],"id":41375426}],"con":true,"img":false}]}
{"op":"mcm","clk":"5306797189","pt":1646106601702,"mc":[{"id":"1.195395431","rc":[{"atb":[[1.72,4.22]],"id":41375435}],"con":true,"img":false}]}
{"op":"mcm","clk":"5306797206","pt":1646106602209,"mc":[{"id":"1.195395431","rc":[{"atb":[[1.72,0]],"id":41375435}],"con":true,"img":false}]}
{"op":"mcm","clk":"5306797355","pt":1646106607333,"mc":[{"id":"1.195395431","rc":[{"atb":[[1.72,4.22]],"id":41375435}],"con":true,"img":false}]}
{"op":"mcm","clk":"5306797363","pt":1646106607537,"mc":[{"id":"1.195395431","rc":[{"atb":[[1.72,0]],"id":41375435}],"con":true,"img":false}]}
{"op":"mcm","clk":"5306797485","pt":1646106612395,"mc":[{"id":"1.195395431","rc":[{"atb":[[1.72,4.22]],"id":41375435}],"con":true,"img":false}]}
{"op":"mcm","clk":"5306797489","pt":1646106612703,"mc":[{"id":"1.195395431","rc":[{"atb":[[1.72,0]],"id":41375435}],"con":true,"img":false}]}
{"op":"mcm","clk":"5306797690","pt":1646106618424,"mc":[{"id":"1.195395431","rc":[{"atb":[[1.72,4.22]],"id":41375435}],"con":true,"img":false}]}
{"op":"mcm","clk":"5306797704","pt":1646106618833,"mc":[{"id":"1.195395431","rc":[{"atb":[[1.72,0]],"id":41375435}],"con":true,"img":false}]}
{"op":"mcm","clk":"5306797821","pt":1646106623636,"mc":[{"id":"1.195395431","rc":[{"atb":[[1.72,4.22]],"id":41375435}],"con":true,"img":false}]}
{"op":"mcm","clk":"5306797829","pt":1646106623943,"mc":[{"id":"1.195395431","rc":[{"atb":[[1.72,0]],"id":41375435}],"con":true,"img":false}]}
{"op":"mcm","clk":"5306797995","pt":1646106629770,"mc":[{"id":"1.195395431","rc":[{"atb":[[1.72,4.22]],"id":41375435}],"con":true,"img":false}]}
{"op":"mcm","clk":"5306798012","pt":1646106630127,"mc":[{"id":"1.195395431","rc":[{"atb":[[1.72,0]],"id":41375435}],"con":true,"img":false}]}
{"op":"mcm","clk":"5306798163","pt":1646106635033,"mc":[{"id":"1.195395431","rc":[{"atb":[[1.72,4.22]],"id":41375435}],"con":true,"img":false}]}
{"op":"mcm","clk":"5306798176","pt":1646106635339,"mc":[{"id":"1.195395431","rc":[{"atb":[[1.72,0]],"id":41375435}],"con":true,"img":false}]}
{"op":"mcm","clk":"5306798359","pt":1646106641061,"mc":[{"id":"1.195395431","rc":[{"atb":[[1.72,4.22]],"id":41375435}],"con":true,"img":false}]}
{"op":"mcm","clk":"5306798375","pt":1646106641572,"mc":[{"id":"1.195395431","rc":[{"atb":[[1.72,0]],"id":41375435}],"con":true,"img":false}]}
{"op":"mcm","clk":"5306798513","pt":1646106646474,"mc":[{"id":"1.195395431","rc":[{"atb":[[1.72,4.22]],"id":41375435}],"con":true,"img":false}]}
{"op":"mcm","clk":"5306798527","pt":1646106646881,"mc":[{"id":"1.195395431","rc":[{"atb":[[1.72,0]],"id":41375435}],"con":true,"img":false}]}
{"op":"mcm","clk":"5306798727","pt":1646106652706,"mc":[{"id":"1.195395431","rc":[{"atb":[[1.72,4.22]],"id":41375435}],"con":true,"img":false}]}
{"op":"mcm","clk":"5306798739","pt":1646106653066,"mc":[{"id":"1.195395431","rc":[{"atb":[[1.72,0]],"id":41375435}],"con":true,"img":false}]}
{"op":"mcm","clk":"5306798892","pt":1646106657665,"mc":[{"id":"1.195395431","rc":[{"atb":[[1.72,4.22]],"id":41375435}],"con":true,"img":false}]}
{"op":"mcm","clk":"5306798905","pt":1646106658075,"mc":[{"id":"1.195395431","rc":[{"atb":[[1.72,0]],"id":41375435}],"con":true,"img":false}]}
{"op":"mcm","clk":"5306799125","pt":1646106663808,"mc":[{"id":"1.195395431","rc":[{"atb":[[1.72,4.22]],"id":41375435}],"con":true,"img":false}]}
{"op":"mcm","clk":"5306799134","pt":1646106664215,"mc":[{"id":"1.195395431","rc":[{"atb":[[1.72,0]],"id":41375435}],"con":true,"img":false}]}
{"op":"mcm","clk":"5306799277","pt":1646106669124,"mc":[{"id":"1.195395431","rc":[{"atb":[[1.72,4.22]],"id":41375435}],"con":true,"img":false}]}
{"op":"mcm","clk":"5306799288","pt":1646106669436,"mc":[{"id":"1.195395431","rc":[{"atb":[[1.72,0]],"id":41375435}],"con":true,"img":false}]}
{"op":"mcm","clk":"5306799437","pt":1646106674294,"mc":[{"id":"1.195395431","rc":[{"atb":[[1.72,4.22]],"id":41375435}],"con":true,"img":false}]}
{"op":"mcm","clk":"5306799442","pt":1646106674602,"mc":[{"id":"1.195395431","rc":[{"atb":[[1.72,0]],"id":41375435}],"con":true,"img":false}]}
{"op":"mcm","clk":"5306799639","pt":1646106679832,"mc":[{"id":"1.195395431","rc":[{"atb":[[1.72,4.22]],"id":41375435}],"con":true,"img":false}]}
{"op":"mcm","clk":"5306799650","pt":1646106680191,"mc":[{"id":"1.195395431","rc":[{"atb":[[1.72,0]],"id":41375435}],"con":true,"img":false}]}
{"op":"mcm","clk":"5306799807","pt":1646106685510,"mc":[{"id":"1.195395431","rc":[{"atb":[[1.72,4.22]],"id":41375435}],"con":true,"img":false}]}
{"op":"mcm","clk":"5306799816","pt":1646106685818,"mc":[{"id":"1.195395431","rc":[{"atb":[[1.72,0]],"id":41375435}],"con":true,"img":false}]}
{"op":"mcm","clk":"5306799969","pt":1646106690717,"mc":[{"id":"1.195395431","rc":[{"atb":[[1.72,4.22]],"id":41375435}],"con":true,"img":false}]}
{"op":"mcm","clk":"5306799977","pt":1646106690925,"mc":[{"id":"1.195395431","rc":[{"atb":[[1.72,0]],"id":41375435}],"con":true,"img":false}]}
{"op":"mcm","clk":"5306800154","pt":1646106696754,"mc":[{"id":"1.195395431","rc":[{"atb":[[1.72,4.22]],"id":41375435}],"con":true,"img":false}]}
{"op":"mcm","clk":"5306800163","pt":1646106697060,"mc":[{"id":"1.195395431","rc":[{"atb":[[1.72,0]],"id":41375435}],"con":true,"img":false}]}
{"op":"mcm","clk":"5306800347","pt":1646106702354,"mc":[{"id":"1.195395431","rc":[{"atb":[[1.72,4.22]],"id":41375435}],"con":true,"img":false}]}
{"op":"mcm","clk":"5306800369","pt":1646106702864,"mc":[{"id":"1.195395431","rc":[{"atb":[[1.72,0]],"id":41375435}],"con":true,"img":false}]}
{"op":"mcm","clk":"5306800597","pt":1646106708077,"mc":[{"id":"1.195395431","rc":[{"atb":[[1.72,4.22]],"id":41375435}],"con":true,"img":false}]}
{"op":"mcm","clk":"5306800605","pt":1646106708333,"mc":[{"id":"1.195395431","rc":[{"atb":[[1.72,0]],"id":41375435}],"con":true,"img":false}]}
{"op":"mcm","clk":"5306800779","pt":1646106713251,"mc":[{"id":"1.195395431","rc":[{"atb":[[1.72,4.22]],"id":41375435}],"con":true,"img":false}]}
{"op":"mcm","clk":"5306800788","pt":1646106713558,"mc":[{"id":"1.195395431","rc":[{"atb":[[1.72,0]],"id":41375435}],"con":true,"img":false}]}
{"op":"mcm","clk":"5306800967","pt":1646106719273,"mc":[{"id":"1.195395431","rc":[{"atb":[[1.72,4.22]],"id":41375435}],"con":true,"img":false}]}
{"op":"mcm","clk":"5306800980","pt":1646106719681,"mc":[{"id":"1.195395431","rc":[{"atb":[[1.72,0]],"id":41375435}],"con":true,"img":false}]}
{"op":"mcm","clk":"5306801184","pt":1646106725156,"mc":[{"id":"1.195395431","rc":[{"atb":[[1.72,4.22]],"id":41375435}],"con":true,"img":false}]}
{"op":"mcm","clk":"5306801191","pt":1646106725361,"mc":[{"id":"1.195395431","rc":[{"atb":[[1.72,0]],"id":41375435}],"con":true,"img":false}]}
{"op":"mcm","clk":"5306801399","pt":1646106730889,"mc":[{"id":"1.195395431","rc":[{"atb":[[1.72,4.22]],"id":41375435}],"con":true,"img":false}]}
{"op":"mcm","clk":"5306801414","pt":1646106731198,"mc":[{"id":"1.195395431","rc":[{"atb":[[1.72,0]],"id":41375435}],"con":true,"img":false}]}
{"op":"mcm","clk":"5306801611","pt":1646106736314,"mc":[{"id":"1.195395431","rc":[{"atb":[[1.72,4.22]],"id":41375435}],"con":true,"img":false}]}
{"op":"mcm","clk":"5306801629","pt":1646106736723,"mc":[{"id":"1.195395431","rc":[{"atb":[[1.72,0]],"id":41375435}],"con":true,"img":false}]}
{"op":"mcm","clk":"5306801777","pt":1646106741017,"mc":[{"id":"1.195395431","rc":[{"atl":[[20,13.87]],"id":39296632}],"con":true,"img":false}]}
{"op":"mcm","clk":"5306801806","pt":1646106741835,"mc":[{"id":"1.195395431","rc":[{"atb":[[1.72,4.22]],"id":41375435}],"con":true,"img":false}]}
{"op":"mcm","clk":"5306801814","pt":1646106742088,"mc":[{"id":"1.195395431","rc":[{"atb":[[1.72,0]],"id":41375435}],"con":true,"img":false}]}
{"op":"mcm","clk":"5306801836","pt":1646106742600,"mc":[{"id":"1.195395431","rc":[{"atb":[[8.6,14.87]],"id":39296632}],"con":true,"img":false}]}
{"op":"mcm","clk":"5306801864","pt":1646106743218,"mc":[{"id":"1.195395431","rc":[{"atb":[[8.4,0]],"id":39296632}],"con":true,"img":false}]}
{"op":"mcm","clk":"5306801870","pt":1646106743318,"mc":[{"id":"1.195395431","rc":[{"atb":[[8.8,1.28]],"id":39296632}],"con":true,"img":false}]}
{"op":"mcm","clk":"5306801902","pt":1646106744134,"mc":[{"id":"1.195395431","rc":[{"atb":[[95,10.94]],"id":38124326}],"con":true,"img":false}]}
{"op":"mcm","clk":"5306801924","pt":1646106744797,"mc":[{"id":"1.195395431","rc":[{"atb":[[8.6,12.36]],"id":39296632},{"atb":[[1.02,1.27]],"id":38124326}],"con":true,"img":false}]}
{"op":"mcm","clk":"5306801926","pt":1646106744899,"mc":[{"id":"1.195395431","rc":[{"atb":[[100,1.49]],"id":38124326}],"con":true,"img":false}]}
{"op":"mcm","clk":"5306801943","pt":1646106745512,"mc":[{"id":"1.195395431","rc":[{"atb":[[13.5,14.55]],"id":41729332}],"con":true,"img":false}]}
{"op":"mcm","clk":"5306801954","pt":1646106746019,"mc":[{"id":"1.195395431","rc":[{"atl":[[29,13.52]],"id":27453791}],"con":true,"img":false}]}
{"op":"mcm","clk":"5306801959","pt":1646106746225,"mc":[{"id":"1.195395431","rc":[{"atb":[[9,2.5]],"id":39296632}],"con":true,"img":false}]}
{"op":"mcm","clk":"5306801970","pt":1646106746840,"mc":[{"id":"1.195395431","rc":[{"atb":[[8.6,10.82]],"id":39296632}],"con":true,"img":false}]}
{"op":"mcm","clk":"5306801972","pt":1646106746938,"mc":[{"id":"1.195395431","rc":[{"atb":[[9,4.04]],"id":39296632}],"con":true,"img":false}]}
{"op":"mcm","clk":"5306801984","pt":1646106747400,"mc":[{"id":"1.195395431","rc":[{"atb":[[1.72,4.22]],"id":41375435},{"atb":[[11,14.46]],"id":27453791}],"con":true,"img":false}]}
{"op":"mcm","clk":"5306801993","pt":1646106747805,"mc":[{"id":"1.195395431","rc":[{"atb":[[1.72,0]],"id":41375435}],"con":true,"img":false}]}
{"op":"mcm","clk":"5306801998","pt":1646106748011,"mc":[{"id":"1.195395431","rc":[{"atl":[[5.1,24.97]],"id":41375430}],"con":true,"img":false}]}
{"op":"mcm","clk":"5306802015","pt":1646106748422,"mc":[{"id":"1.195395431","rc":[{"atl":[[7,0]],"id":41375430}],"con":true,"img":false}]}
{"op":"mcm","clk":"5306802018","pt":1646106748521,"mc":[{"id":"1.195395431","rc":[{"atl":[[5,1.31]],"id":41375430}],"con":true,"img":false}]}
{"op":"mcm","clk":"5306802048","pt":1646106749646,"mc":[{"id":"1.195395431","rc":[{"atb":[[1.71,35.54]],"id":41375435}],"con":true,"img":false}]}
{"op":"mcm","clk":"5306802069","pt":1646106750207,"mc":[{"id":"1.195395431","rc":[{"atl":[[26,13.52]],"id":35784172}],"con":true,"img":false}]}
{"op":"mcm","clk":"5306802112","pt":1646106751637,"mc":[{"id":"1.195395431","rc":[{"atb":[[11,14.55]],"id":35784172}],"con":true,"img":false}]}
{"op":"mcm","clk":"5306802142","pt":1646106752607,"mc":[{"id":"1.195395431","rc":[{"atb":[[1.72,4.22]],"id":41375435},{"atb":[[30,13.87]],"id":41375426}],"con":true,"img":false}]}
{"op":"mcm","clk":"5306802152","pt":1646106752913,"mc":[{"id":"1.195395431","rc":[{"atb":[[1.72,0]],"id":41375435},{"atb":[[1.02,1.21]],"id":41375426}],"con":true,"img":false}]}
{"op":"mcm","clk":"5306802154","pt":1646106753015,"mc":[{"id":"1.195395431","rc":[{"atb":[[32,1.66]],"id":41375426}],"con":true,"img":false}]}
{"op":"mcm","clk":"5306802159","pt":1646106753322,"mc":[{"id":"1.195395431","rc":[{"atb":[[75,0]],"id":38124326}],"con":true,"img":false}]}
{"op":"mcm","clk":"5306802163","pt":1646106753424,"mc":[{"id":"1.195395431","rc":[{"atb":[[60,2.7]],"id":38124326}],"con":true,"img":false}]}
{"op":"mcm","clk":"5306802312","pt":1646106758122,"mc":[{"id":"1.195395431","rc":[{"atb":[[1.72,4.22]],"id":41375435},{"atl":[[32,0]],"id":41729332}],"con":true,"img":false}]}
{"op":"mcm","clk":"5306802317","pt":1646106758225,"mc":[{"id":"1.195395431","rc":[{"atl":[[34,2.7]],"id":41729332}],"con":true,"img":false}]}
{"op":"mcm","clk":"5306802326","pt":1646106758430,"mc":[{"id":"1.195395431","rc":[{"atb":[[1.72,0]],"id":41375435}],"con":true,"img":false}]}
{"op":"mcm","clk":"5306802525","pt":1646106763954,"mc":[{"id":"1.195395431","rc":[{"spn":9.0,"spf":1.0,"id":39296632},{"atb":[[1.72,4.22]],"id":41375435},{"spn":1.7,"spf":1.0,"id":41375435},{"spn":23.75,"spf":1.0,"id":41729332},{"spn":3.96,"spf":1.0,"id":41375430},{"spn":100.0,"spf":1.0,"id":38124326},{"spn":66.0,"spf":1.0,"id":41375426}],"con":true,"img":false}]}
{"op":"mcm","clk":"5306802545","pt":1646106764414,"mc":[{"id":"1.195395431","rc":[{"atb":[[1.72,0]],"id":41375435}],"con":true,"img":false}]}
{"op":"mcm","clk":"5306802685","pt":1646106769621,"mc":[{"id":"1.195395431","rc":[{"atb":[[1.72,4.22]],"id":41375435}],"con":true,"img":false}]}
{"op":"mcm","clk":"5306802695","pt":1646106769928,"mc":[{"id":"1.195395431","rc":[{"atb":[[1.72,0]],"id":41375435}],"con":true,"img":false}]}
{"op":"mcm","clk":"5306802858","pt":1646106775249,"mc":[{"id":"1.195395431","rc":[{"atb":[[1.72,4.22]],"id":41375435}],"con":true,"img":false}]}
{"op":"mcm","clk":"5306802864","pt":1646106775556,"mc":[{"id":"1.195395431","rc":[{"atb":[[1.72,0]],"id":41375435}],"con":true,"img":false}]}
{"op":"mcm","clk":"5306802921","pt":1646106777343,"mc":[{"id":"1.195395431","rc":[{"atb":[[110,2.25]],"id":38124326}],"con":true,"img":false}]}
{"op":"mcm","clk":"5306802942","pt":1646106777858,"mc":[{"id":"1.195395431","rc":[{"atb":[[100,0]],"id":38124326}],"con":true,"img":false}]}
{"op":"mcm","clk":"5306802946","pt":1646106777961,"mc":[{"id":"1.195395431","rc":[{"atb":[[110,3.74]],"id":38124326}],"con":true,"img":false}]}
{"op":"mcm","clk":"5306803001","pt":1646106779755,"mc":[{"id":"1.195395431","rc":[{"atb":[[8.2,0]],"id":39296632},{"atb":[[80,0]],"id":38124326}],"con":true,"img":false}]}
{"op":"mcm","clk":"5306803005","pt":1646106779854,"mc":[{"id":"1.195395431","rc":[{"atb":[[8.8,9.34]],"id":39296632},{"atb":[[110,6.45]],"id":38124326}],"con":true,"img":false}]}
{"op":"mcm","clk":"5306803037","pt":1646106780776,"mc":[{"id":"1.195395431","rc":[{"atb":[[1.72,4.22]],"id":41375435}],"con":true,"img":false}]}
{"op":"mcm","clk":"5306803046","pt":1646106781031,"mc":[{"id":"1.195395431","rc":[{"atb":[[1.72,0]],"id":41375435}],"con":true,"img":false}]}
{"op":"mcm","clk":"5306803186","pt":1646106785067,"mc":[{"id":"1.195395431","rc":[{"atl":[[29,10.82]],"id":27453791},{"atl":[[26,10.82]],"id":35784172}],"con":true,"img":false}]}
{"op":"mcm","clk":"5306803189","pt":1646106785170,"mc":[{"id":"1.195395431","rc":[{"atl":[[28,2.7]],"id":27453791},{"atl":[[25,2.7]],"id":35784172}],"con":true,"img":false}]}
{"op":"mcm","clk":"5306803205","pt":1646106785782,"mc":[{"id":"1.195395431","rc":[{"atl":[[990,0]],"id":27453791},{"atl":[[990,0]],"id":35784172}],"con":true,"img":false}]}
{"op":"mcm","clk":"5306803207","pt":1646106785884,"mc":[{"id":"1.195395431","rc":[{"atl":[[27,1.21]],"id":27453791},{"atl":[[24,1.3]],"id":35784172}],"con":true,"img":false}]}
{"op":"mcm","clk":"5306803224","pt":1646106786446,"mc":[{"id":"1.195395431","rc":[{"atb":[[1.72,4.22]],"id":41375435}],"con":true,"img":false}]}
{"op":"mcm","clk":"5306803230","pt":1646106786753,"mc":[{"id":"1.195395431","rc":[{"atb":[[1.72,0]],"id":41375435}],"con":true,"img":false}]}
{"op":"mcm","clk":"5306803394","pt":1646106791465,"mc":[{"id":"1.195395431","rc":[{"atb":[[10,0]],"id":27453791}],"con":true,"img":false}]}
{"op":"mcm","clk":"5306803400","pt":1646106791566,"mc":[{"id":"1.195395431","rc":[{"atb":[[11.5,6.44]],"id":27453791}],"con":true,"img":false}]}
{"op":"mcm","clk":"5306803421","pt":1646106791976,"mc":[{"id":"1.195395431","rc":[{"atb":[[11,12.9]],"id":27453791}],"con":true,"img":false}]}
{"op":"mcm","clk":"5306803423","pt":1646106792078,"mc":[{"id":"1.195395431","rc":[{"atb":[[12,1.55]],"id":27453791}],"con":true,"img":false}]}
{"op":"mcm","clk":"5306803432","pt":1646106792283,"mc":[{"id":"1.195395431","rc":[{"atb":[[1.72,4.22]],"id":41375435}],"con":true,"img":false}]}
{"op":"mcm","clk":"5306803452","pt":1646106792897,"mc":[{"id":"1.195395431","rc":[{"atb":[[1.72,0]],"id":41375435}],"con":true,"img":false}]}
{"op":"mcm","clk":"5306803482","pt":1646106793766,"mc":[{"id":"1.195395431","rc":[{"atb":[[11,10.82]],"id":27453791}],"con":true,"img":false}]}
{"op":"mcm","clk":"5306803513","pt":1646106794790,"mc":[{"id":"1.195395431","rc":[{"atb":[[12.5,2.08]],"id":27453791}],"con":true,"img":false}]}
{"op":"mcm","clk":"5306803541","pt":1646106795454,"mc":[{"id":"1.195395431","rc":[{"atb":[[12,0]],"id":27453791}],"con":true,"img":false}]}
{"op":"mcm","clk":"5306803542","pt":1646106795557,"mc":[{"id":"1.195395431","rc":[{"atb":[[12.5,3.64]],"id":27453791}],"con":true,"img":false}]}
{"op":"mcm","clk":"5306803559","pt":1646106796170,"mc":[{"id":"1.195395431","rc":[{"atb":[[9.8,0]],"id":41729332}],"con":true,"img":false}]}
{"op":"mcm","clk":"5306803562","pt":1646106796272,"mc":[{"id":"1.195395431","rc":[{"atb":[[8.8,12.69]],"id":41729332}],"con":true,"img":false}]}
{"op":"mcm","clk":"5306803615","pt":1646106797856,"mc":[{"id":"1.195395431","rc":[{"atb":[[1.72,4.22]],"id":41375435}],"con":true,"img":false}]}
{"op":"mcm","clk":"5306803634","pt":1646106798265,"mc":[{"id":"1.195395431","rc":[{"atb":[[1.72,0]],"id":41375435}],"con":true,"img":false}]}
{"op":"mcm","clk":"5306803720","pt":1646106800970,"mc":[{"id":"1.195395431","rc":[{"atl":[[20,24.69]],"id":39296632}],"con":true,"img":false}]}
{"op":"mcm","clk":"5306803730","pt":1646106801378,"mc":[{"id":"1.195395431","rc":[{"atl":[[34,0]],"id":39296632}],"con":true,"img":false}]}
{"op":"mcm","clk":"5306803735","pt":1646106801481,"mc":[{"id":"1.195395431","rc":[{"atl":[[19.5,1.3]],"id":39296632}],"con":true,"img":false}]}
{"op":"mcm","clk":"5306803782","pt":1646106802758,"mc":[{"id":"1.195395431","rc":[{"atb":[[9,14.87]],"id":39296632}],"con":true,"img":false}]}
{"op":"mcm","clk":"5306803802","pt":1646106803370,"mc":[{"id":"1.195395431","rc":[{"atb":[[8.8,8.06]],"id":39296632}],"con":true,"img":false}]}
{"op":"mcm","clk":"5306803804","pt":1646106803472,"mc":[{"id":"1.195395431","rc":[{"atb":[[9.2,1.28]],"id":39296632}],"con":true,"img":false}]}
{"op":"mcm","clk":"5306803806","pt":1646106803575,"mc":[{"id":"1.195395431","rc":[{"atb":[[1.72,4.22]],"id":41375435}],"con":true,"img":false}]}
{"op":"mcm","clk":"5306803816","pt":1646106803882,"mc":[{"id":"1.195395431","rc":[{"atb":[[1.72,0]],"id":41375435}],"con":true,"img":false}]}
{"op":"mcm","clk":"5306803828","pt":1646106804189,"mc":[{"id":"1.195395431","rc":[{"atb":[[110,17.27]],"id":38124326}],"con":true,"img":false}]}
{"op":"mcm","clk":"5306803874","pt":1646106805365,"mc":[{"id":"1.195395431","rc":[{"atb":[[9,12.36]],"id":39296632}],"con":true,"img":false}]}
{"op":"mcm","clk":"5306803876","pt":1646106805469,"mc":[{"id":"1.195395431","rc":[{"atb":[[13.5,25.37]],"id":41729332}],"con":true,"img":false}]}
{"op":"mcm","clk":"5306803887","pt":1646106805877,"mc":[{"id":"1.195395431","rc":[{"atb":[[9.2,0]],"id":39296632}],"con":true,"img":false}]}
{"op":"mcm","clk":"5306803892","pt":1646106805979,"mc":[{"id":"1.195395431","rc":[{"atb":[[1.02,1.28]],"id":39296632}],"con":true,"img":false}]}
{"op":"mcm","clk":"5306803896","pt":1646106806081,"mc":[{"id":"1.195395431","rc":[{"atl":[[27,12.04]],"id":27453791}],"con":true,"img":false}]}
{"op":"mcm","clk":"5306803914","pt":1646106806594,"mc":[{"id":"1.195395431","rc":[{"atb":[[9.2,2.5]],"id":39296632}],"con":true,"img":false}]}
{"op":"mcm","clk":"5306803924","pt":1646106806899,"mc":[{"id":"1.195395431","rc":[{"atb":[[9,10.82]],"id":39296632}],"con":true,"img":false}]}
{"op":"mcm","clk":"5306803928","pt":1646106807001,"mc":[{"id":"1.195395431","rc":[{"atb":[[9.2,4.04]],"id":39296632}],"con":true,"img":false}]}
{"op":"mcm","clk":"5306803947","pt":1646106807562,"mc":[{"id":"1.195395431","rc":[{"atb":[[12.5,14.46]],"id":27453791},{"atb":[[8.6,0]],"id":35784172}],"con":true,"img":false}]}
{"op":"mcm","clk":"5306803949","pt":1646106807665,"mc":[{"id":"1.195395431","rc":[{"atb":[[7.6,15.51]],"id":35784172}],"con":true,"img":false}]}
{"op":"mcm","clk":"5306803962","pt":1646106808075,"mc":[{"id":"1.195395431","rc":[{"atl":[[5,12.13]],"id":41375430}],"con":true,"img":false}]}
{"op":"mcm","clk":"5306803992","pt":1646106809200,"mc":[{"id":"1.195395431","rc":[{"atb":[[1.72,4.22]],"id":41375435}],"con":true,"img":false}]}
{"op":"mcm","clk":"5306803999","pt":1646106809506,"mc":[{"id":"1.195395431","rc":[{"atb":[[1.72,0],[1.71,46.36]],"id":41375435}],"con":true,"img":false}]}
{"op":"mcm","clk":"5306804009","pt":1646106809964,"mc":[{"id":"1.195395431","rc":[{"atl":[[24,12.12]],"id":35784172}],"con":true,"img":false}]}
{"op":"mcm","clk":"5306804040","pt":1646106810984,"mc":[{"id":"1.195395431","rc":[{"atb":[[11,25.37]],"id":35784172}],"con":true,"img":false}]}
{"op":"mcm","clk":"5306804077","pt":1646106812007,"mc":[{"id":"1.195395431","rc":[{"atb":[[32,12.48]],"id":41375426}],"con":true,"img":false}]}
{"op":"mcm","clk":"5306804080","pt":1646106812110,"mc":[{"id":"1.195395431","rc":[{"atb":[[110,14.56]],"id":38124326}],"con":true,"img":false}]}
{"op":"mcm","clk":"5306804082","pt":1646106812211,"mc":[{"id":"1.195395431","rc":[{"atb":[[120,2.7]],"id":38124326}],"con":true,"img":false}]}
{"op":"mcm","clk":"5306804104","pt":1646106812874,"mc":[{"id":"1.195395431","rc":[{"atb":[[110,13.07]],"id":38124326}],"con":true,"img":false}]}
{"op":"mcm","clk":"5306804109","pt":1646106812977,"mc":[{"id":"1.195395431","rc":[{"atb":[[120,4.2]],"id":38124326}],"con":true,"img":false}]}
{"op":"mcm","clk":"5306804164","pt":1646106814814,"mc":[{"id":"1.195395431","rc":[{"atb":[[1.72,4.22]],"id":41375435}],"con":true,"img":false}]}
{"op":"mcm","clk":"5306804173","pt":1646106815223,"mc":[{"id":"1.195395431","rc":[{"atb":[[1.72,0]],"id":41375435}],"con":true,"img":false}]}
{"op":"mcm","clk":"5306804213","pt":1646106816400,"mc":[{"id":"1.195395431","rc":[{"atb":[[8.8,0]],"id":39296632},{"atl":[[34,0]],"id":41729332}],"con":true,"img":false}]}
{"op":"mcm","clk":"5306804216","pt":1646106816502,"mc":[{"id":"1.195395431","rc":[{"atb":[[8.2,8.06]],"id":39296632},{"atl":[[36,2.7]],"id":41729332}],"con":true,"img":false}]}
{"op":"mcm","clk":"5306804223","pt":1646106816707,"mc":[{"id":"1.195395431","rc":[{"atb":[[110,10.82]],"id":38124326}],"con":true,"img":false}]}
{"op":"mcm","clk":"5306804232","pt":1646106817011,"mc":[{"id":"1.195395431","rc":[{"atb":[[130,2.25]],"id":38124326}],"con":true,"img":false}]}
{"op":"mcm","clk":"5306804375","pt":1646106820588,"mc":[{"id":"1.195395431","rc":[{"atb":[[1.72,4.22]],"id":41375435}],"con":true,"img":false}]}
{"op":"mcm","clk":"5306804385","pt":1646106820894,"mc":[{"id":"1.195395431","rc":[{"atb":[[1.72,0]],"id":41375435}],"con":true,"img":false}]}
{"op":"mcm","clk":"5306804442","pt":1646106822329,"mc":[{"id":"1.195395431","rc":[{"atb":[[120,2.7]],"id":38124326}],"con":true,"img":false}]}
{"op":"mcm","clk":"5306804448","pt":1646106822431,"mc":[{"id":"1.195395431","rc":[{"atb":[[130,3.74]],"id":38124326}],"con":true,"img":false}]}
{"op":"mcm","clk":"5306804587","pt":1646106826518,"mc":[{"id":"1.195395431","rc":[{"spn":9.2,"spf":1.0,"id":39296632},{"atb":[[1.72,4.22]],"id":41375435},{"spn":1.7,"spf":1.0,"id":41375435},{"spn":24.75,"spf":1.0,"id":41729332},{"spn":19.75,"spf":1.0,"id":27453791},{"spn":130.0,"spf":1.0,"id":38124326},{"spn":17.5,"spf":1.0,"id":35784172}],"con":true,"img":false}]}
{"op":"mcm","clk":"5306804598","pt":1646106826824,"mc":[{"id":"1.195395431","rc":[{"atb":[[1.72,0]],"id":41375435}],"con":true,"img":false}]}
{"op":"mcm","clk":"5306804859","pt":1646106831933,"mc":[{"id":"1.195395431","rc":[{"atb":[[1.72,4.22]],"id":41375435}],"con":true,"img":false}]}
{"op":"mcm","clk":"5306804868","pt":1646106832242,"mc":[{"id":"1.195395431","rc":[{"atb":[[1.72,0]],"id":41375435}],"con":true,"img":false}]}
{"op":"mcm","clk":"5306805065","pt":1646106837659,"mc":[{"id":"1.195395431","rc":[{"atb":[[1.72,4.22]],"id":41375435}],"con":true,"img":false}]}
{"op":"mcm","clk":"5306805079","pt":1646106838016,"mc":[{"id":"1.195395431","rc":[{"atb":[[1.72,0]],"id":41375435}],"con":true,"img":false}]}
{"op":"mcm","clk":"5306805203","pt":1646106840829,"mc":[{"id":"1.195395431","rc":[{"atl":[[28,0]],"id":27453791}],"con":true,"img":false}]}
{"op":"mcm","clk":"5306805206","pt":1646106840932,"mc":[{"id":"1.195395431","rc":[{"atl":[[26,2.7]],"id":27453791}],"con":true,"img":false}]}
{"op":"mcm","clk":"5306805221","pt":1646106841544,"mc":[{"id":"1.195395431","rc":[{"atl":[[27,10.82]],"id":27453791}],"con":true,"img":false}]}
{"op":"mcm","clk":"5306805225","pt":1646106841647,"mc":[{"id":"1.195395431","rc":[{"atl":[[25,1.21]],"id":27453791}],"con":true,"img":false}]}
{"op":"mcm","clk":"5306805273","pt":1646106842924,"mc":[{"id":"1.195395431","rc":[{"atb":[[1.72,4.22]],"id":41375435}],"con":true,"img":false}]}
{"op":"mcm","clk":"5306805278","pt":1646106843128,"mc":[{"id":"1.195395431","rc":[{"atb":[[1.72,0]],"id":41375435}],"con":true,"img":false}]}
{"op":"mcm","clk":"5306805353","pt":1646106845329,"mc":[{"id":"1.195395431","rc":[{"atl":[[25,0]],"id":35784172}],"con":true,"img":false}]}
{"op":"mcm","clk":"5306805357","pt":1646106845431,"mc":[{"id":"1.195395431","rc":[{"atl":[[23,2.7]],"id":35784172}],"con":true,"img":false}]}
{"op":"mcm","clk":"5306805366","pt":1646106845840,"mc":[{"id":"1.195395431","rc":[{"atl":[[24,10.82]],"id":35784172}],"con":true,"img":false}]}
{"op":"mcm","clk":"5306805367","pt":1646106845943,"mc":[{"id":"1.195395431","rc":[{"atl":[[22,1.3]],"id":35784172}],"con":true,"img":false}]}
{"op":"mcm","clk":"5306805453","pt":1646106848551,"mc":[{"id":"1.195395431","rc":[{"atb":[[1.72,4.22]],"id":41375435}],"con":true,"img":false}]}
{"op":"mcm","clk":"5306805467","pt":1646106848960,"mc":[{"id":"1.195395431","rc":[{"atb":[[1.72,0]],"id":41375435}],"con":true,"img":false}]}
{"op":"mcm","clk":"5306805490","pt":1646106849573,"mc":[{"id":"1.195395431","rc":[{"atb":[[30,11.17]],"id":41375426}],"con":true,"img":false}]}
{"op":"mcm","clk":"5306805493","pt":1646106849676,"mc":[{"id":"1.195395431","rc":[{"atb":[[34,2.7]],"id":41375426}],"con":true,"img":false}]}
{"op":"mcm","clk":"5306805520","pt":1646106850339,"mc":[{"id":"1.195395431","rc":[{"atb":[[32,10.82]],"id":41375426}],"con":true,"img":false}]}
{"op":"mcm","clk":"5306805526","pt":1646106850441,"mc":[{"id":"1.195395431","rc":[{"atb":[[34,4.36]],"id":41375426}],"con":true,"img":false}]}
{"op":"mcm","clk":"5306805652","pt":1646106854066,"mc":[{"id":"1.195395431","rc":[{"atb":[[1.72,4.22]],"id":41375435}],"con":true,"img":false}]}
{"op":"mcm","clk":"5306805664","pt":1646106854373,"mc":[{"id":"1.195395431","rc":[{"atb":[[1.72,0]],"id":41375435}],"con":true,"img":false}]}
{"op":"mcm","clk":"5306805892","pt":1646106859644,"mc":[{"id":"1.195395431","rc":[{"atb":[[1.72,4.22]],"id":41375435}],"con":true,"img":false}]}
{"op":"mcm","clk":"5306805902","pt":1646106859949,"mc":[{"id":"1.195395431","rc":[{"atb":[[1.72,0]],"id":41375435}],"con":true,"img":false}]}
{"op":"mcm","clk":"5306806104","pt":1646106865871,"mc":[{"id":"1.195395431","rc":[{"atb":[[1.72,4.22]],"id":41375435}],"con":true,"img":false}]}
{"op":"mcm","clk":"5306806119","pt":1646106866280,"mc":[{"id":"1.195395431","rc":[{"atb":[[1.72,0]],"id":41375435}],"con":true,"img":false}]}
{"op":"mcm","clk":"5306806299","pt":1646106871489,"mc":[{"id":"1.195395431","rc":[{"atb":[[1.72,4.22]],"id":41375435}],"con":true,"img":false}]}
{"op":"mcm","clk":"5306806310","pt":1646106871897,"mc":[{"id":"1.195395431","rc":[{"atb":[[1.72,0]],"id":41375435}],"con":true,"img":false}]}
{"op":"mcm","clk":"5306806479","pt":1646106877158,"mc":[{"id":"1.195395431","rc":[{"atb":[[1.72,4.22]],"id":41375435}],"con":true,"img":false}]}
{"op":"mcm","clk":"5306806490","pt":1646106877489,"mc":[{"id":"1.195395431","rc":[{"atb":[[1.72,0]],"id":41375435}],"con":true,"img":false}]}
{"op":"mcm","clk":"5306806680","pt":1646106883006,"mc":[{"id":"1.195395431","rc":[{"atb":[[1.72,4.22]],"id":41375435}],"con":true,"img":false}]}
{"op":"mcm","clk":"5306806695","pt":1646106883466,"mc":[{"id":"1.195395431","rc":[{"atb":[[1.72,0]],"id":41375435}],"con":true,"img":false}]}
{"op":"mcm","clk":"5306806881","pt":1646106888887,"mc":[{"id":"1.195395431","rc":[{"atb":[[1.72,4.22]],"id":41375435},{"spn":18.75,"spf":1.0,"id":27453791},{"spn":16.5,"spf":1.0,"id":35784172},{"spn":67.0,"spf":1.0,"id":41375426}],"con":true,"img":false}]}
{"op":"mcm","clk":"5306806896","pt":1646106889193,"mc":[{"id":"1.195395431","rc":[{"atb":[[1.72,0]],"id":41375435}],"con":true,"img":false}]}
{"op":"mcm","clk":"5306807090","pt":1646106894620,"mc":[{"id":"1.195395431","rc":[{"atb":[[1.72,4.22]],"id":41375435}],"con":true,"img":false}]}
{"op":"mcm","clk":"5306807103","pt":1646106894926,"mc":[{"id":"1.195395431","rc":[{"atb":[[1.72,0]],"id":41375435}],"con":true,"img":false}]}
{"op":"mcm","clk":"5306807311","pt":1646106900504,"mc":[{"id":"1.195395431","rc":[{"atb":[[1.72,4.22],[1.61,32.79]],"id":41375435}],"con":true,"img":false}]}
{"op":"mcm","clk":"5306807318","pt":1646106900709,"mc":[{"id":"1.195395431","rc":[{"atb":[[1.72,0]],"id":41375435}],"con":true,"img":false}]}
{"op":"mcm","clk":"5306807523","pt":1646106906304,"mc":[{"id":"1.195395431","rc":[{"atb":[[1.72,4.22]],"id":41375435}],"con":true,"img":false}]}
{"op":"mcm","clk":"5306807533","pt":1646106906610,"mc":[{"id":"1.195395431","rc":[{"atb":[[1.72,0]],"id":41375435}],"con":true,"img":false}]}
{"op":"mcm","clk":"5306807570","pt":1646106907531,"mc":[{"id":"1.195395431","rc":[{"atb":[[1.48,41.88]],"id":41375435}],"con":true,"img":false}]}
{"op":"mcm","clk":"5306807772","pt":1646106912206,"mc":[{"id":"1.195395431","rc":[{"atb":[[1.72,4.22]],"id":41375435}],"con":true,"img":false}]}
{"op":"mcm","clk":"5306807782","pt":1646106912509,"mc":[{"id":"1.195395431","rc":[{"atb":[[1.72,0]],"id":41375435}],"con":true,"img":false}]}
{"op":"mcm","clk":"5306807860","pt":1646106914504,"mc":[{"id":"1.195395431","rc":[{"atb":[[2.82,13.1],[2.58,12.85]],"id":41375430}],"con":true,"img":false}]}
{"op":"mcm","clk":"5306807995","pt":1646106917729,"mc":[{"id":"1.195395431","rc":[{"atb":[[1.72,4.22]],"id":41375435}],"con":true,"img":false}]}
{"op":"mcm","clk":"5306808006","pt":1646106917939,"mc":[{"id":"1.195395431","rc":[{"atb":[[1.72,0]],"id":41375435}],"con":true,"img":false}]}
{"op":"mcm","clk":"5306808254","pt":1646106923565,"mc":[{"id":"1.195395431","rc":[{"atb":[[1.72,4.22]],"id":41375435}],"con":true,"img":false}]}
{"op":"mcm","clk":"5306808267","pt":1646106923823,"mc":[{"id":"1.195395431","rc":[{"atb":[[1.72,0]],"id":41375435}],"con":true,"img":false}]}
{"op":"mcm","clk":"5306808469","pt":1646106929142,"mc":[{"id":"1.195395431","rc":[{"atb":[[1.72,4.22]],"id":41375435}],"con":true,"img":false}]}
{"op":"mcm","clk":"5306808480","pt":1646106929448,"mc":[{"id":"1.195395431","rc":[{"atb":[[1.72,0]],"id":41375435}],"con":true,"img":false}]}
{"op":"mcm","clk":"5306808688","pt":1646106934878,"mc":[{"id":"1.195395431","rc":[{"atb":[[1.72,4.22]],"id":41375435}],"con":true,"img":false}]}
{"op":"mcm","clk":"5306808700","pt":1646106935183,"mc":[{"id":"1.195395431","rc":[{"atb":[[1.72,0]],"id":41375435}],"con":true,"img":false}]}
{"op":"mcm","clk":"5306808895","pt":1646106940657,"mc":[{"id":"1.195395431","rc":[{"atb":[[1.72,4.22]],"id":41375435}],"con":true,"img":false}]}
{"op":"mcm","clk":"5306808905","pt":1646106940963,"mc":[{"id":"1.195395431","rc":[{"atb":[[1.72,0]],"id":41375435}],"con":true,"img":false}]}
{"op":"mcm","clk":"5306809069","pt":1646106946281,"mc":[{"id":"1.195395431","rc":[{"atb":[[1.72,4.22]],"id":41375435}],"con":true,"img":false}]}
{"op":"mcm","clk":"5306809076","pt":1646106946587,"mc":[{"id":"1.195395431","rc":[{"atb":[[1.72,0]],"id":41375435}],"con":true,"img":false}]}
{"op":"mcm","clk":"5306809286","pt":1646106951763,"mc":[{"id":"1.195395431","rc":[{"atb":[[1.72,4.22]],"id":41375435}],"con":true,"img":false}]}
{"op":"mcm","clk":"5306809306","pt":1646106952174,"mc":[{"id":"1.195395431","rc":[{"atb":[[1.72,0]],"id":41375435}],"con":true,"img":false}]}
{"op":"mcm","clk":"5306809521","pt":1646106957704,"mc":[{"id":"1.195395431","rc":[{"atb":[[1.72,4.22]],"id":41375435}],"con":true,"img":false}]}
{"op":"mcm","clk":"5306809529","pt":1646106958011,"mc":[{"id":"1.195395431","rc":[{"atb":[[1.72,0]],"id":41375435}],"con":true,"img":false}]}
{"op":"mcm","clk":"5306809717","pt":1646106963383,"mc":[{"id":"1.195395431","rc":[{"atb":[[1.72,4.22]],"id":41375435}],"con":true,"img":false}]}
{"op":"mcm","clk":"5306809732","pt":1646106963794,"mc":[{"id":"1.195395431","rc":[{"atb":[[1.72,0]],"id":41375435}],"con":true,"img":false}]}
{"op":"mcm","clk":"5306809927","pt":1646106969230,"mc":[{"id":"1.195395431","rc":[{"atb":[[1.72,4.22]],"id":41375435}],"con":true,"img":false}]}
{"op":"mcm","clk":"5306809940","pt":1646106969589,"mc":[{"id":"1.195395431","rc":[{"atb":[[1.72,0]],"id":41375435}],"con":true,"img":false}]}
{"op":"mcm","clk":"5306810110","pt":1646106975121,"mc":[{"id":"1.195395431","rc":[{"atb":[[1.72,4.22]],"id":41375435}],"con":true,"img":false}]}
{"op":"mcm","clk":"5306810125","pt":1646106975530,"mc":[{"id":"1.195395431","rc":[{"atb":[[1.72,0]],"id":41375435}],"con":true,"img":false}]}
{"op":"mcm","clk":"5306810376","pt":1646106981428,"mc":[{"id":"1.195395431","rc":[{"atb":[[1.72,4.22]],"id":41375435}],"con":true,"img":false}]}
{"op":"mcm","clk":"5306810389","pt":1646106981732,"mc":[{"id":"1.195395431","rc":[{"atb":[[1.72,0]],"id":41375435}],"con":true,"img":false}]}
{"op":"mcm","clk":"5306810567","pt":1646106987472,"mc":[{"id":"1.195395431","rc":[{"atb":[[1.72,4.22]],"id":41375435}],"con":true,"img":false}]}
{"op":"mcm","clk":"5306810580","pt":1646106987777,"mc":[{"id":"1.195395431","rc":[{"atb":[[1.72,0]],"id":41375435}],"con":true,"img":false}]}
{"op":"mcm","clk":"5306810764","pt":1646106993257,"mc":[{"id":"1.195395431","rc":[{"atb":[[1.72,4.22]],"id":41375435}],"con":true,"img":false}]}
{"op":"mcm","clk":"5306810778","pt":1646106993665,"mc":[{"id":"1.195395431","rc":[{"atb":[[1.72,0]],"id":41375435}],"con":true,"img":false}]}
{"op":"mcm","clk":"5306810977","pt":1646106999240,"mc":[{"id":"1.195395431","rc":[{"atb":[[1.72,4.22]],"id":41375435}],"con":true,"img":false}]}
{"op":"mcm","clk":"5306810990","pt":1646106999546,"mc":[{"id":"1.195395431","rc":[{"atb":[[1.72,0]],"id":41375435}],"con":true,"img":false}]}
{"op":"mcm","clk":"5306811010","pt":1646107000060,"mc":[{"id":"1.195395431","rc":[{"atl":[[19.5,0],[20,15.17]],"id":39296632},{"trd":[[20,19.04],[19.5,2.6]],"ltp":20.0,"tv":21.64,"id":39296632},{"atl":[[22,0],[23,0],[24,5.41]],"id":35784172},{"trd":[[24,10.81],[22,2.6],[23,5.41]],"ltp":24.0,"tv":18.82,"id":35784172}],"con":true,"img":false}]}
{"op":"mcm","clk":"5306811016","pt":1646107000163,"mc":[{"id":"1.195395431","rc":[{"atb":[[10.5,0]],"id":35784172}],"con":true,"img":false}]}
{"op":"mcm","clk":"5306811040","pt":1646107000674,"mc":[{"id":"1.195395431","rc":[{"atb":[[9,13.64]],"id":39296632},{"atb":[[11,27.93]],"id":35784172}],"con":true,"img":false}]}
{"op":"mcm","clk":"5306811062","pt":1646107001186,"mc":[{"id":"1.195395431","rc":[{"atb":[[1.02,0]],"id":39296632}],"con":true,"img":false}]}
{"op":"mcm","clk":"5306811066","pt":1646107001288,"mc":[{"id":"1.195395431","rc":[{"atb":[[9.2,5.33]],"id":39296632}],"con":true,"img":false}]}
{"op":"mcm","clk":"5306811185","pt":1646107004666,"mc":[{"id":"1.195395431","rc":[{"atl":[[28,0]],"id":39296632},{"atb":[[1.68,81.51]],"id":41375435},{"atb":[[9.2,0],[7.8,17.26]],"id":27453791},{"atl":[[38,0]],"id":35784172},{"atb":[[19,5.93],[23,0]],"id":41375426}],"con":true,"img":false}]}
{"op":"mcm","clk":"5306811188","pt":1646107004768,"mc":[{"id":"1.195395431","rc":[{"atl":[[34,3.6]],"id":39296632},{"atb":[[1.61,211.82]],"id":41375435},{"atl":[[50,3.18]],"id":35784172}],"con":true,"img":false}]}
{"op":"mcm","clk":"5306811194","pt":1646107004973,"mc":[{"id":"1.195395431","rc":[{"atb":[[1.72,4.22]],"id":41375435}],"con":true,"img":false}]}
{"op":"mcm","clk":"5306811207","pt":1646107005381,"mc":[{"id":"1.195395431","rc":[{"atb":[[1.72,0]],"id":41375435}],"con":true,"img":false}]}
{"op":"mcm","clk":"5306811300","pt":1646107007991,"mc":[{"id":"1.195395431","rc":[{"atb":[[8,19.31]],"id":39296632},{"atb":[[1.11,226.56]],"id":41375435},{"atb":[[1.01,3.36]],"id":41729332},{"atb":[[2.54,16.18]],"id":41375430},{"atb":[[1.01,3.36]],"id":38124326}],"con":true,"img":false}]}
{"op":"mcm","clk":"5306811305","pt":1646107008094,"mc":[{"id":"1.195395431","rc":[{"atl":[[28,3.7]],"id":39296632},{"atl":[[90,5.1]],"id":41729332},{"atl":[[5.8,3.7]],"id":41375430},{"atb":[[1.01,3.36]],"id":27453791},{"atl":[[38,3.7]],"id":27453791},{"atb":[[1.01,3.36]],"id":35784172},{"atl":[[34,3.7]],"id":35784172},{"atb":[[1.01,3.36]],"id":41375426},{"atl":[[330,3.7]],"id":41375426}],"con":true,"img":false}]}
{"op":"mcm","clk":"5306811309","pt":1646107008249,"mc":[{"id":"1.195395431","rc":[{"atb":[[1.01,2.62]],"id":41729332},{"atb":[[1.01,0.29]],"id":38124326}],"con":true,"img":false}]}
{"op":"mcm","clk":"5306811314","pt":1646107008353,"mc":[{"id":"1.195395431","rc":[{"atb":[[1.01,2.83]],"id":27453791},{"atb":[[1.01,3.03]],"id":35784172},{"atb":[[1.01,0.99]],"id":41375426}],"con":true,"img":false}]}
{"op":"mcm","clk":"5306811324","pt":1646107008556,"mc":[{"id":"1.195395431","rc":[{"atb":[[1.01,0]],"id":41729332},{"atb":[[1.01,0]],"id":38124326}],"con":true,"img":false}]}
{"op":"mcm","clk":"5306811327","pt":1646107008658,"mc":[{"id":"1.195395431","rc":[{"atb":[[10.5,8.73]],"id":41729332},{"atb":[[1.01,0]],"id":27453791},{"atb":[[85,0.29]],"id":38124326},{"atb":[[1.01,0]],"id":35784172},{"atb":[[1.01,0]],"id":41375426}],"con":true,"img":false}]}
{"op":"mcm","clk":"5306811331","pt":1646107008760,"mc":[{"id":"1.195395431","rc":[{"atb":[[9.8,2.83]],"id":27453791},{"atb":[[9.2,3.03]],"id":35784172},{"atb":[[26,0.99]],"id":41375426}],"con":true,"img":false}]}
{"op":"mcm","clk":"5306811357","pt":1646107009378,"mc":[{"id":"1.195395431","rc":[{"atb":[[2.66,0]],"id":39296632},{"atl":[[17,0],[34,0]],"id":41375435},{"atb":[[4.3,0],[2.66,0]],"id":41729332},{"atb":[[4.3,0],[2.66,0]],"id":27453791},{"atl":[[17,0],[34,0]],"id":41375430},{"atb":[[4.3,0],[2.66,0]],"id":38124326},{"atb":[[4.3,0],[2.66,0]],"id":35784172},{"atb":[[4.3,0],[2.66,0]],"id":41375426}],"con":true,"img":false}]}
{"op":"mcm","clk":"5306811374","pt":1646107009787,"mc":[{"id":"1.195395431","rc":[{"atb":[[10,6.44]],"id":35784172}],"con":true,"img":false}]}
{"op":"mcm","clk":"5306811378","pt":1646107009889,"mc":[{"id":"1.195395431","rc":[{"atb":[[11.5,1.21]],"id":35784172}],"con":true,"img":false}]}
{"op":"mcm","clk":"5306811406","pt":1646107010556,"mc":[{"id":"1.195395431","rc":[{"atb":[[2.02,100]],"id":38124326}],"con":true,"img":false}]}
{"op":"mcm","clk":"5306811412","pt":1646107010666,"mc":[{"id":"1.195395431","rc":[{"atb":[[11,25.84]],"id":35784172}],"con":true,"img":false}]}
{"op":"mcm","clk":"5306811429","pt":1646107011069,"mc":[{"id":"1.195395431","rc":[{"atb":[[1.72,4.22]],"id":41375435}],"con":true,"img":false}]}
{"op":"mcm","clk":"5306811437","pt":1646107011279,"mc":[{"id":"1.195395431","rc":[{"atb":[[11.5,0]],"id":35784172}],"con":true,"img":false}]}
{"op":"mcm","clk":"5306811445","pt":1646107011382,"mc":[{"id":"1.195395431","rc":[{"atb":[[1.72,0]],"id":41375435},{"atb":[[1.02,1.21]],"id":35784172}],"con":true,"img":false}]}
{"op":"mcm","clk":"5306811492","pt":1646107012573,"mc":[{"id":"1.195395431","rc":[{"spn":1.7,"spf":1.0,"id":41375435},{"atb":[[2,50]],"id":38124326},{"spn":17.5,"spf":1.0,"id":35784172}],"con":true,"img":false}]}
{"op":"mcm","clk":"5306811498","pt":1646107012675,"mc":[{"id":"1.195395431","rc":[{"atb":[[2,60]],"id":38124326}],"con":true,"img":false}]}
{"op":"mcm","clk":"5306811514","pt":1646107013187,"mc":[{"id":"1.195395431","rc":[{"atl":[[23,0.05]],"id":39296632},{"atb":[[1.04,2.23]],"id":41729332},{"atl":[[1000,2.23]],"id":41729332},{"atl":[[29,0.55]],"id":35784172}],"con":true,"img":false}]}
{"op":"mcm","clk":"5306811516","pt":1646107013289,"mc":[{"id":"1.195395431","rc":[{"atb":[[2.86,0]],"id":41375430},{"atb":[[11.5,0]],"id":27453791},{"atb":[[120,0]],"id":38124326},{"atb":[[34,1.66]],"id":41375426}],"con":true,"img":false}]}
{"op":"mcm","clk":"5306811521","pt":1646107013391,"mc":[{"id":"1.195395431","rc":[{"atb":[[9.6,7.61]],"id":27453791},{"atb":[[2.72,31.19]],"id":41375430},{"atb":[[100,2.7]],"id":38124326},{"atb":[[32,13.52]],"id":41375426}],"con":true,"img":false}]}
{"op":"mcm","clk":"5306811525","pt":1646107013494,"mc":[{"id":"1.195395431","rc":[{"atb":[[1.04,0.29]],"id":41729332},{"atl":[[1000,0.53]],"id":41729332}],"con":true,"img":false}]}
{"op":"mcm","clk":"5306811542","pt":1646107013904,"mc":[{"id":"1.195395431","rc":[{"atb":[[1.04,0]],"id":41729332},{"atl":[[1000,0]],"id":41729332}],"con":true,"img":false}]}
{"op":"mcm","clk":"5306811546","pt":1646107014007,"mc":[{"id":"1.195395431","rc":[{"atl":[[34,0.53],[36,2.4]],"id":41729332},{"trd":[[36,0.59]],"ltp":36.0,"tv":0.59,"id":41729332}],"con":true,"img":false}]}
{"op":"mcm","clk":"5306811566","pt":1646107014475,"mc":[{"id":"1.195395431","rc":[{"atl":[[36,0]],"id":41729332},{"atl":[[29,2.7]],"id":35784172}],"con":true,"img":false}]}
{"op":"mcm","clk":"5306811573","pt":1646107014573,"mc":[{"id":"1.195395431","rc":[{"atl":[[40,2.4]],"id":41729332}],"con":true,"img":false}]}
{"op":"mcm","clk":"5306811591","pt":1646107014983,"mc":[{"id":"1.195395431","rc":[{"atb":[[1.02,0]],"id":41729332},{"atl":[[990,0]],"id":41729332}],"con":true,"img":false}]}
{"op":"mcm","clk":"5306811595","pt":1646107015084,"mc":[{"id":"1.195395431","rc":[{"atb":[[14,1.26]],"id":41729332},{"atl":[[38,1.27]],"id":41729332}],"con":true,"img":false}]}
{"op":"mcm","clk":"5306811607","pt":1646107015595,"mc":[{"id":"1.195395431","rc":[{"atl":[[38,0]],"id":41729332}],"con":true,"img":false}]}
{"op":"mcm","clk":"5306811609","pt":1646107015697,"mc":[{"id":"1.195395431","rc":[{"atl":[[1000,1.27]],"id":41729332}],"con":true,"img":false}]}
{"op":"mcm","clk":"5306811617","pt":1646107015902,"mc":[{"id":"1.195395431","rc":[{"atb":[[13.5,23.28]],"id":41729332}],"con":true,"img":false}]}
{"op":"mcm","clk":"5306811629","pt":1646107016106,"mc":[{"id":"1.195395431","rc":[{"atb":[[14,0]],"id":41729332}],"con":true,"img":false}]}
{"op":"mcm","clk":"5306811632","pt":1646107016208,"mc":[{"id":"1.195395431","rc":[{"atb":[[1.02,1.26]],"id":41729332},{"atl":[[1000,0]],"id":41729332}],"con":true,"img":false}]}
{"op":"mcm","clk":"5306811638","pt":1646107016311,"mc":[{"id":"1.195395431","rc":[{"atl":[[38,1.27]],"id":41729332}],"con":true,"img":false}]}
{"op":"mcm","clk":"5306811658","pt":1646107016773,"mc":[{"id":"1.195395431","rc":[{"atb":[[1.72,4.22]],"id":41375435},{"atl":[[38,0]],"id":41729332}],"con":true,"img":false}]}
{"op":"mcm","clk":"5306811663","pt":1646107016874,"mc":[{"id":"1.195395431","rc":[{"atl":[[1000,1.27]],"id":41729332}],"con":true,"img":false}]}
{"op":"mcm","clk":"5306811667","pt":1646107016977,"mc":[{"id":"1.195395431","rc":[{"atb":[[1.02,0]],"id":41729332}],"con":true,"img":false}]}
{"op":"mcm","clk":"5306811671","pt":1646107017079,"mc":[{"id":"1.195395431","rc":[{"atb":[[1.72,0]],"id":41375435},{"atb":[[14,1.26]],"id":41729332}],"con":true,"img":false}]}
{"op":"mcm","clk":"5306811711","pt":1646107018203,"mc":[{"id":"1.195395431","rc":[{"atb":[[14,0]],"id":41729332}],"con":true,"img":false}]}
{"op":"mcm","clk":"5306811714","pt":1646107018305,"mc":[{"id":"1.195395431","rc":[{"atb":[[1.02,1.26]],"id":41729332}],"con":true,"img":false}]}
{"op":"mcm","clk":"5306811844","pt":1646107021477,"mc":[{"id":"1.195395431","rc":[{"spl":[[1.01,133.86]],"id":41375435}],"con":true,"img":false}]}
{"op":"mcm","clk":"5306811848","pt":1646107021580,"mc":[{"id":"1.195395431","rc":[{"spl":[[1.01,8.22]],"id":27453791}],"con":true,"img":false}]}
{"op":"mcm","clk":"5306811875","pt":1646107022201,"mc":[{"id":"1.195395431","rc":[{"atl":[[40,2.7]],"id":41729332}],"con":true,"img":false}]}
{"op":"mcm","clk":"5306811883","pt":1646107022508,"mc":[{"id":"1.195395431","rc":[{"atb":[[2.9,6.6]],"id":41375430}],"con":true,"img":false}]}
{"op":"mcm","clk":"5306812089","pt":1646107027679,"mc":[{"id":"1.195395431","rc":[{"atb":[[9.4,4.07]],"id":39296632},{"atb":[[11.5,3.99]],"id":35784172}],"con":true,"img":false}]}
{"op":"mcm","clk":"5306812092","pt":1646107027782,"mc":[{"id":"1.195395431","rc":[{"atb":[[8.2,0]],"id":39296632},{"atb":[[10,0]],"id":35784172}],"con":true,"img":false}]}
{"op":"mcm","clk":"5306812111","pt":1646107028191,"mc":[{"id":"1.195395431","rc":[{"atb":[[9.2,3.79]],"id":39296632},{"atb":[[11,24.19]],"id":35784172}],"con":true,"img":false}]}
{"op":"mcm","clk":"5306812114","pt":1646107028300,"mc":[{"id":"1.195395431","rc":[{"atb":[[9.6,1.54]],"id":39296632},{"atb":[[12,1.64]],"id":35784172}],"con":true,"img":false}]}
{"op":"mcm","clk":"5306812128","pt":1646107028598,"mc":[{"id":"1.195395431","rc":[{"atb":[[9.2,1.28]],"id":39296632}],"con":true,"img":false}]}
{"op":"mcm","clk":"5306812169","pt":1646107029730,"mc":[{"id":"1.195395431","rc":[{"atl":[[20,25.99]],"id":39296632}],"con":true,"img":false}]}
{"op":"mcm","clk":"5306812206","pt":1646107030905,"mc":[{"id":"1.195395431","rc":[{"atl":[[130,2.7],[150,0]],"id":41375426}],"con":true,"img":false}]}
{"op":"mcm","clk":"5306812207","pt":1646107031008,"mc":[{"id":"1.195395431","rc":[{"atl":[[2.78,0]],"id":41375435},{"atl":[[5.1,10.82]],"id":41375430},{"atl":[[26,0]],"id":27453791}],"con":true,"img":false}]}
{"op":"mcm","clk":"5306812210","pt":1646107031110,"mc":[{"id":"1.195395431","rc":[{"atl":[[2.62,31.88]],"id":41375435},{"atl":[[24,2.7]],"id":27453791},{"atl":[[4.7,14.15]],"id":41375430}],"con":true,"img":false}]}
{"op":"mcm","clk":"5306812225","pt":1646107031416,"mc":[{"id":"1.195395431","rc":[{"atb":[[9.2,12.1]],"id":39296632}],"con":true,"img":false}]}
{"op":"mcm","clk":"5306812244","pt":1646107031724,"mc":[{"id":"1.195395431","rc":[{"atb":[[9.2,10.82]],"id":39296632}],"con":true,"img":false}]}
{"op":"mcm","clk":"5306812247","pt":1646107031828,"mc":[{"id":"1.195395431","rc":[{"atb":[[9,13.58],[9.4,5.36]],"id":39296632},{"atl":[[5,10.82]],"id":41375430},{"atl":[[25,0]],"id":27453791}],"con":true,"img":false}]}
{"op":"mcm","clk":"5306812251","pt":1646107031929,"mc":[{"id":"1.195395431","rc":[{"atl":[[4.6,1.31]],"id":41375430},{"atl":[[23,1.21]],"id":27453791}],"con":true,"img":false}]}
{"op":"mcm","clk":"5306812268","pt":1646107032390,"mc":[{"id":"1.195395431","rc":[{"atb":[[9,10.82]],"id":39296632}],"con":true,"img":false}]}
{"op":"mcm","clk":"5306812272","pt":1646107032491,"mc":[{"id":"1.195395431","rc":[{"atb":[[9.4,8.12]],"id":39296632}],"con":true,"img":false}]}
{"op":"mcm","clk":"5306812288","pt":1646107032799,"mc":[{"id":"1.195395431","rc":[{"atb":[[130,14.56]],"id":38124326}],"con":true,"img":false}]}
{"op":"mcm","clk":"5306812359","pt":1646107034232,"mc":[{"id":"1.195395431","rc":[{"atb":[[13.5,34.11]],"id":41729332}],"con":true,"img":false}]}
{"op":"mcm","clk":"5306812377","pt":1646107034692,"mc":[{"id":"1.195395431","rc":[{"atl":[[25,10.82]],"id":27453791}],"con":true,"img":false}]}
{"op":"mcm","clk":"5306812387","pt":1646107034998,"mc":[{"id":"1.195395431","rc":[{"atb":[[1.02,0]],"id":41729332}],"con":true,"img":false}]}
{"op":"mcm","clk":"5306812390","pt":1646107035100,"mc":[{"id":"1.195395431","rc":[{"atb":[[14,1.26]],"id":41729332}],"con":true,"img":false}]}
{"op":"mcm","clk":"5306812427","pt":1646107036123,"mc":[{"id":"1.195395431","rc":[{"atb":[[12.5,25.28]],"id":27453791}],"con":true,"img":false}]}
{"op":"mcm","clk":"5306812445","pt":1646107036635,"mc":[{"id":"1.195395431","rc":[{"atl":[[5,21.64]],"id":41375430}],"con":true,"img":false}]}
{"op":"mcm","clk":"5306812501","pt":1646107038116,"mc":[{"id":"1.195395431","rc":[{"atb":[[1.71,57.18]],"id":41375435}],"con":true,"img":false}]}
{"op":"mcm","clk":"5306812528","pt":1646107038731,"mc":[{"id":"1.195395431","rc":[{"atl":[[24,16.23]],"id":35784172}],"con":true,"img":false}]}
{"op":"mcm","clk":"5306812577","pt":1646107039908,"mc":[{"id":"1.195395431","rc":[{"atb":[[11.5,14.81]],"id":35784172}],"con":true,"img":false}]}
{"op":"mcm","clk":"5306812592","pt":1646107040216,"mc":[{"id":"1.195395431","rc":[{"atb":[[11,24.09]],"id":35784172}],"con":true,"img":false}]}
{"op":"mcm","clk":"5306812601","pt":1646107040421,"mc":[{"id":"1.195395431","rc":[{"atb":[[1.02,0]],"id":35784172}],"con":true,"img":false}]}
{"op":"mcm","clk":"5306812606","pt":1646107040524,"mc":[{"id":"1.195395431","rc":[{"atb":[[12,2.85]],"id":35784172}],"con":true,"img":false}]}
{"op":"mcm","clk":"5306812621","pt":1646107040832,"mc":[{"id":"1.195395431","rc":[{"atb":[[11,21.64]],"id":35784172}],"con":true,"img":false}]}
{"op":"mcm","clk":"5306812624","pt":1646107040935,"mc":[{"id":"1.195395431","rc":[{"atb":[[12,5.31]],"id":35784172},{"atb":[[34,12.48]],"id":41375426}],"con":true,"img":false}]}
{"op":"mcm","clk":"5306812648","pt":1646107041703,"mc":[{"id":"1.195395431","rc":[{"atb":[[12,4.09]],"id":35784172},{"atb":[[1.02,0]],"id":41375426}],"con":true,"img":false}]}
{"op":"mcm","clk":"5306812652","pt":1646107041804,"mc":[{"id":"1.195395431","rc":[{"atb":[[1.02,1.21]],"id":35784172},{"atb":[[36,1.21]],"id":41375426}],"con":true,"img":false}]}
{"op":"mcm","clk":"5306812708","pt":1646107043030,"mc":[{"id":"1.195395431","rc":[{"atl":[[23,2.7]],"id":39296632}],"con":true,"img":false}]}
{"op":"mcm","clk":"5306812803","pt":1646107046451,"mc":[{"id":"1.195395431","rc":[{"atb":[[1.71,46.69]],"id":41375435},{"atb":[[3.05,3.63]],"id":41375430}],"con":true,"img":false}]}
{"op":"mcm","clk":"5306812829","pt":1646107047319,"mc":[{"id":"1.195395431","rc":[{"atb":[[2.62,0]],"id":41375430}],"con":true,"img":false}]}
{"op":"mcm","clk":"5306812833","pt":1646107047421,"mc":[{"id":"1.195395431","rc":[{"atb":[[2.6,140.05]],"id":41375430}],"con":true,"img":false}]}
{"op":"mcm","clk":"5306813373","pt":1646107064542,"mc":[{"id":"1.195395431","rc":[{"atb":[[9.4,9.37]],"id":39296632},{"atl":[[4.9,29.55]],"id":41375430},{"atl":[[24,7.8]],"id":27453791}],"con":true,"img":false}]}
{"op":"mcm","clk":"5306813378","pt":1646107064643,"mc":[{"id":"1.195395431","rc":[{"atl":[[40,0]],"id":27453791},{"atl":[[6.8,0]],"id":41375430}],"con":true,"img":false}]}
{"op":"mcm","clk":"5306813519","pt":1646107068893,"mc":[{"id":"1.195395431","rc":[{"atl":[[4.7,0]],"id":41375430}],"con":true,"img":false}]}
{"op":"mcm","clk":"5306813524","pt":1646107069000,"mc":[{"id":"1.195395431","rc":[{"atl":[[4.6,15.46]],"id":41375430}],"con":true,"img":false}]}
{"op":"mcm","clk":"5306813585","pt":1646107070688,"mc":[{"id":"1.195395431","rc":[{"atb":[[11.5,10.82]],"id":35784172}],"con":true,"img":false}]}
{"op":"mcm","clk":"5306813592","pt":1646107070789,"mc":[{"id":"1.195395431","rc":[{"atb":[[12.5,3.99]],"id":35784172}],"con":true,"img":false}]}
{"op":"mcm","clk":"5306813628","pt":1646107071660,"mc":[{"id":"1.195395431","rc":[{"atb":[[36,0]],"id":41375426}],"con":true,"img":false}]}
{"op":"mcm","clk":"5306813631","pt":1646107071760,"mc":[{"id":"1.195395431","rc":[{"atb":[[1.02,1.21]],"id":41375426}],"con":true,"img":false}]}
{"op":"mcm","clk":"5306813723","pt":1646107074276,"mc":[{"id":"1.195395431","rc":[{"spn":9.51,"spf":1.0,"id":39296632},{"spn":1.69,"spf":1.0,"id":41375435},{"spn":24.0,"spf":1.0,"id":41729332},{"spn":3.82,"spf":1.0,"id":41375430},{"spn":12.5,"spf":1.0,"id":27453791},{"atb":[[12,2.45]],"id":35784172},{"spn":18.25,"spf":1.0,"id":35784172}],"con":true,"img":false}]}
{"op":"mcm","clk":"5306813726","pt":1646107074378,"mc":[{"id":"1.195395431","rc":[{"atb":[[13,1.64]],"id":35784172}],"con":true,"img":false}]}
{"op":"mcm","clk":"5306814241","pt":1646107090708,"mc":[{"id":"1.195395431","rc":[{"atb":[[1.48,0],[1.61,179.03]],"id":41375435},{"atb":[[2.82,2],[2.58,0]],"id":41375430}],"con":true,"img":false}]}
{"op":"mcm","clk":"5306814262","pt":1646107091221,"mc":[{"id":"1.195395431","rc":[{"atl":[[4.6,14.15]],"id":41375430},{"atl":[[23,0]],"id":27453791}],"con":true,"img":false}]}
{"op":"mcm","clk":"5306814266","pt":1646107091274,"mc":[{"id":"1.195395431","rc":[{"atl":[[1000,1.31]],"id":41375430},{"atl":[[1000,1.21]],"id":27453791}],"con":true,"img":false}]}
{"op":"mcm","clk":"5306814330","pt":1646107093116,"mc":[{"id":"1.195395431","rc":[{"atl":[[4.9,0]],"id":41375430}],"con":true,"img":false}]}
{"op":"mcm","clk":"5306814332","pt":1646107093219,"mc":[{"id":"1.195395431","rc":[{"atl":[[5,51.19]],"id":41375430}],"con":true,"img":false}]}
{"op":"mcm","clk":"5306816340","pt":1646107150819,"mc":[{"id":"1.195395431","rc":[{"atb":[[2.6,68.91]],"id":41375430},{"spn":18.5,"spf":1.0,"id":35784172}],"con":true,"img":false}]}
{"op":"mcm","clk":"5306816345","pt":1646107150922,"mc":[{"id":"1.195395431","rc":[{"atb":[[2.62,71.14]],"id":41375430}],"con":true,"img":false}]}
{"op":"mcm","clk":"5306817384","pt":1646107169517,"mc":[{"id":"1.195395431","rc":[{"atb":[[2.9,1.29]],"id":41375430}],"con":true,"img":false}]}
{"op":"mcm","clk":"5306817431","pt":1646107170435,"mc":[{"id":"1.195395431","rc":[{"atb":[[2.92,0]],"id":41375430}],"con":true,"img":false}]}
{"op":"mcm","clk":"5306817435","pt":1646107170538,"mc":[{"id":"1.195395431","rc":[{"atb":[[1.01,1.52]],"id":41375430}],"con":true,"img":false}]}
{"op":"mcm","clk":"5306817469","pt":1646107171313,"mc":[{"id":"1.195395431","rc":[{"atb":[[2.62,0]],"id":41375430}],"con":true,"img":false}]}
{"op":"mcm","clk":"5306817477","pt":1646107171410,"mc":[{"id":"1.195395431","rc":[{"atb":[[2.56,71.14]],"id":41375430}],"con":true,"img":false}]}
{"op":"mcm","clk":"5306817619","pt":1646107174945,"mc":[{"id":"1.195395431","rc":[{"atb":[[2.88,4.44]],"id":41375430}],"con":true,"img":false}]}
{"op":"mcm","clk":"5306818676","pt":1646107197541,"mc":[{"id":"1.195395431","rc":[{"atb":[[130,12.31]],"id":38124326}],"con":true,"img":false}]}
{"op":"mcm","clk":"5306819488","pt":1646107213700,"mc":[{"id":"1.195395431","rc":[{"atb":[[9.6,1.54],[8,19.3],[9,10.81],[8.6,10.81],[9.2,10.81],[5.8,22.95],[5.3,25.62],[6.8,20.51],[6.6,19.67],[9.4,8.93]],"id":39296632},{"spl":[[8.6,2.7]],"id":39296632},{"atl":[[65,2.93],[34,3.6],[36,3.57],[20,25.97],[90,2.1],[23,2.7],[46,2.77],[28,3.7]],"id":39296632},{"trd":[[20,19.03],[19.5,2.6]],"ltp":20.0,"tv":21.63,"id":39296632},{"atb":[[1.6,153.6],[1.55,167.57],[1.11,226.54],[1.67,129.26],[1.02,1.32],[1.68,81.46],[1.5,184.33],[1.71,46.67],[1.61,178.93]],"id":41375435},{"spl":[[1.01,133.82]],"id":41375435},{"atl":[[2.4,4.89],[3.45,85.37],[3.2,63.38],[3.7,77.46],[1.9,5.38],[2.98,70.42],[2.62,31.86],[2.96,62.08]],"id":41375435},{"trd":[[1.8,38.94],[1.67,96.54]],"ltp":1.8,"tv":135.48,"id":41375435},{"atb":[[9.6,12.89],[2.82,178.27],[8.6,14.59],[10.5,8.72],[7.6,16.8],[12.5,9.64],[13.5,34.09],[8.8,12.69],[14,1.26]],"id":41729332},{"atl":[[130,0.96],[34,0.53],[40,2.7],[90,5.1],[180,1.04],[50,2.7],[230,0.81],[1000,1.27]],"id":41729332},{"atb":[[2.56,71.1],[2.72,31.18],[2.88,4.44],[2.54,16.18],[1.01,1.52],[2.9,1.29],[2.5,73.46],[2.6,68.87],[2.84,59.89],[3.05,3.64],[2.7,64.82]],"id":41375430},{"atl":[[7.2,20.16],[5.1,10.81],[4.6,14.14],[5,51.16],[5.8,3.7],[9.2,22.86],[10.5,19.73],[8.2,17.36],[1000,1.31]],"id":41375430},{"atb":[[9.6,7.61],[9,13.86],[5.8,23.1],[11,10.81],[1.02,1.23],[7.6,16.8],[12.5,25.27],[9.8,2.83],[7.8,17.25],[6.6,19.8]],"id":27453791},{"spl":[[1.01,8.21]],"id":27453791},{"atl":[[65,1.94],[130,1.44],[38,3.7],[90,2.09],[46,2.76],[24,7.8],[25,10.81],[27,10.81],[29,10.81],[1000,1.21]],"id":27453791},{"atb":[[130,12.3],[34,3.34],[44,2.56],[60,2.7],[70,1.59],[95,10.93],[1.02,1.27],[100,2.7],[110,10.81],[27,4.23]],"id":38124326},{"atl":[[560,0.33],[410,0.3],[460,0.27],[990,1.34],[510,0.36]],"id":38124326},{"atb":[[6.4,20.4],[9.2,3.03],[11,21.63],[11.5,10.81],[7.4,17.21],[1.02,1.21],[12,2.45],[7.6,15.5],[12.5,3.69],[9.8,12.52],[13,1.64],[8.4,14.89]],"id":35784172},{"atl":[[34,3.7],[80,1.58],[160,1.17],[24,16.22],[50,3.18],[26,10.81],[55,2.31],[110,1.71],[29,2.7]],"id":35784172},{"trd":[[24,10.8],[22,2.6],[23,5.4]],"ltp":24.0,"tv":18.8,"id":35784172},{"atb":[[32,13.51],[16,11.77],[34,12.47],[18.5,10.09],[19,5.93],[22,8.4],[1.02,1.21],[29,6.3],[30,11.16]],"id":41375426},{"atl":[[130,2.7],[300,0.23],[330,3.7],[350,0.3],[400,0.27],[210,2.7],[990,1.21],[250,0.28]],"id":41375426},{"trd":[[29,8.81],[24,11.48]],"ltp":29.0,"tv":20.29,"id":41375426}],"con":true,"img":false}]}
{"op":"mcm","clk":"5306820326","pt":1646107236299,"mc":[{"id":"1.195395431","rc":[{"atb":[[2.56,0]],"id":41375430}],"con":true,"img":false}]}
{"op":"mcm","clk":"5306820331","pt":1646107236403,"mc":[{"id":"1.195395431","rc":[{"atb":[[2.62,71.1]],"id":41375430}],"con":true,"img":false}]}
{"op":"mcm","clk":"5306820351","pt":1646107237325,"mc":[{"id":"1.195395431","rc":[{"atb":[[1.71,43.03]],"id":41375435},{"trd":[[1.71,7.28]],"ltp":1.71,"tv":7.28,"id":41375435}],"con":true,"img":false}]}
{"op":"mcm","clk":"5306820394","pt":1646107238607,"mc":[{"id":"1.195395431","rc":[{"atb":[[1.56,217.27],[1.61,0]],"id":41375435}],"con":true,"img":false}]}
{"op":"mcm","clk":"5306820420","pt":1646107239732,"mc":[{"id":"1.195395431","rc":[{"atb":[[1.1,25.8]],"id":41375435}],"con":true,"img":false}]}
{"op":"mcm","clk":"5306820526","pt":1646107242943,"mc":[{"id":"1.195395431","marketDefinition":{"bspMarket":true,"turnInPlayEnabled":false,"persistenceEnabled":false,"marketBaseRate":7.0,"eventId":"31270458","eventTypeId":"4339","numberOfWinners":1,"bettingType":"ODDS","marketType":"WIN","marketTime":"2022-03-01T05:50:00.000Z","suspendTime":"2022-03-01T05:50:00.000Z","bspReconciled":false,"complete":true,"inPlay":false,"crossMatching":true,"runnersVoidable":false,"numberOfActiveRunners":8,"betDelay":0,"status":"OPEN","runners":[{"status":"ACTIVE","sortPriority":1,"id":39296632,"name":"1. Evolution Girl"},{"status":"ACTIVE","sortPriority":2,"id":38124326,"name":"2. Nanny In Town"},{"status":"ACTIVE","sortPriority":3,"id":41729332,"name":"3. Highland Wonder"},{"status":"ACTIVE","sortPriority":4,"id":27453791,"name":"4. Headwall"},{"status":"ACTIVE","sortPriority":5,"id":41375430,"name":"6. Just Posh"},{"status":"ACTIVE","sortPriority":6,"id":41375435,"name":"7. Rojo Diamond"},{"status":"ACTIVE","sortPriority":7,"id":35784172,"name":"8. Buckle Up Kenzie"},{"status":"ACTIVE","sortPriority":8,"id":41375426,"name":"9. Wynburn Rebel"}],"regulators":["MR_INT"],"venue":"Devonport","countryCode":"AU","discountAllowed":true,"timezone":"Australia/Sydney","openDate":"2022-03-01T02:00:00.000Z","version":4381118365,"name":"R7 452m Heat","eventName":"Devonport (AUS) 1st Mar"},"rc":[],"con":true,"img":false}]}
{"op":"mcm","clk":"5306827774","pt":1646107452260,"mc":[{"id":"1.195395431","rc":[{"atb":[[8,15.74]],"id":39296632},{"spn":1.68,"spf":1.0,"id":41375435}],"con":true,"img":false}]}
{"op":"mcm","clk":"5306827783","pt":1646107452463,"mc":[{"id":"1.195395431","rc":[{"atb":[[1.11,0]],"id":41375435}],"con":true,"img":false}]}
{"op":"mcm","clk":"5306827791","pt":1646107452667,"mc":[{"id":"1.195395431","rc":[{"atb":[[2.54,0]],"id":41375430}],"con":true,"img":false}]}
{"op":"mcm","clk":"5306827802","pt":1646107452924,"mc":[{"id":"1.195395431","rc":[{"atl":[[330,0]],"id":41375426}],"con":true,"img":false}]}
{"op":"mcm","clk":"5306827815","pt":1646107453231,"mc":[{"id":"1.195395431","rc":[{"atl":[[38,0]],"id":27453791}],"con":true,"img":false}]}
{"op":"mcm","clk":"5306827828","pt":1646107453536,"mc":[{"id":"1.195395431","rc":[{"atl":[[5.8,0]],"id":41375430}],"con":true,"img":false}]}
{"op":"mcm","clk":"5306827837","pt":1646107453741,"mc":[{"id":"1.195395431","rc":[{"atl":[[28,0]],"id":39296632}],"con":true,"img":false}]}
{"op":"mcm","clk":"5306827846","pt":1646107454051,"mc":[{"id":"1.195395431","rc":[{"atl":[[34,0]],"id":35784172}],"con":true,"img":false}]}
{"op":"mcm","clk":"5306827852","pt":1646107454251,"mc":[{"id":"1.195395431","rc":[{"atl":[[90,1.4]],"id":41729332}],"con":true,"img":false}]}
{"op":"mcm","clk":"5306827861","pt":1646107454568,"mc":[{"id":"1.195395431","rc":[{"atb":[[9.8,0]],"id":27453791}],"con":true,"img":false}]}
{"op":"mcm","clk":"5306827871","pt":1646107454764,"mc":[{"id":"1.195395431","rc":[{"atb":[[26,0]],"id":41375426}],"con":true,"img":false}]}
{"op":"mcm","clk":"5306827892","pt":1646107455173,"mc":[{"id":"1.195395431","rc":[{"atb":[[9.2,0]],"id":35784172}],"con":true,"img":false}]}
{"op":"mcm","clk":"5306827898","pt":1646107455375,"mc":[{"id":"1.195395431","rc":[{"atb":[[10.5,6.1]],"id":41729332}],"con":true,"img":false}]}
{"op":"mcm","clk":"5306827914","pt":1646107455635,"mc":[{"id":"1.195395431","rc":[{"atb":[[85,0]],"id":38124326}],"con":true,"img":false}]}
{"op":"mcm","clk":"5306883879","pt":1646109152372,"mc":[{"id":"1.195395431","marketDefinition":{"bspMarket":true,"turnInPlayEnabled":false,"persistenceEnabled":false,"marketBaseRate":7.0,"eventId":"31270458","eventTypeId":"4339","numberOfWinners":1,"bettingType":"ODDS","marketType":"WIN","marketTime":"2022-03-01T06:10:00.000Z","suspendTime":"2022-03-01T06:10:00.000Z","bspReconciled":false,"complete":true,"inPlay":false,"crossMatching":true,"runnersVoidable":false,"numberOfActiveRunners":8,"betDelay":0,"status":"OPEN","runners":[{"status":"ACTIVE","sortPriority":1,"id":39296632,"name":"1. Evolution Girl"},{"status":"ACTIVE","sortPriority":2,"id":38124326,"name":"2. Nanny In Town"},{"status":"ACTIVE","sortPriority":3,"id":41729332,"name":"3. Highland Wonder"},{"status":"ACTIVE","sortPriority":4,"id":27453791,"name":"4. Headwall"},{"status":"ACTIVE","sortPriority":5,"id":41375430,"name":"6. Just Posh"},{"status":"ACTIVE","sortPriority":6,"id":41375435,"name":"7. Rojo Diamond"},{"status":"ACTIVE","sortPriority":7,"id":35784172,"name":"8. Buckle Up Kenzie"},{"status":"ACTIVE","sortPriority":8,"id":41375426,"name":"9. Wynburn Rebel"}],"regulators":["MR_INT"],"venue":"Devonport","countryCode":"AU","discountAllowed":true,"timezone":"Australia/Sydney","openDate":"2022-03-01T02:00:00.000Z","version":4381128792,"name":"R7 452m Heat","eventName":"Devonport (AUS) 1st Mar"},"rc":[],"con":true,"img":false}]}
{"op":"mcm","clk":"5306897553","pt":1646109607621,"mc":[{"id":"1.195395431","rc":[{"atb":[[7.6,0]],"id":39296632},{"atb":[[95,10.81]],"id":38124326},{"atb":[[30,10.81]],"id":41375426}],"con":true,"img":false}]}
{"op":"mcm","clk":"5306897555","pt":1646109607723,"mc":[{"id":"1.195395431","rc":[{"atb":[[8,17.18]],"id":39296632},{"atb":[[110,10.91]],"id":38124326},{"atb":[[32,13.84]],"id":41375426}],"con":true,"img":false}]}
{"op":"mcm","clk":"5306897710","pt":1646109612287,"mc":[{"id":"1.195395431","rc":[{"atb":[[32,11.14]],"id":41375426}],"con":true,"img":false}]}
{"op":"mcm","clk":"5306897716","pt":1646109612389,"mc":[{"id":"1.195395431","rc":[{"atb":[[30,13.51]],"id":41375426}],"con":true,"img":false}]}
{"op":"mcm","clk":"5306898360","pt":1646109630762,"mc":[{"id":"1.195395431","rc":[{"atl":[[130,0]],"id":41375426}],"con":true,"img":false}]}
{"op":"mcm","clk":"5306898366","pt":1646109630861,"mc":[{"id":"1.195395431","rc":[{"atl":[[120,2.7]],"id":41375426}],"con":true,"img":false}]}
{"op":"mcm","clk":"5306899561","pt":1646109663455,"mc":[{"id":"1.195395431","rc":[{"atl":[[210,0]],"id":41375426}],"con":true,"img":false}]}
{"op":"mcm","clk":"5306899568","pt":1646109663558,"mc":[{"id":"1.195395431","rc":[{"atl":[[170,2.7]],"id":41375426}],"con":true,"img":false}]}
{"op":"mcm","clk":"5306905553","pt":1646109888922,"mc":[{"id":"1.195395431","rc":[{"atb":[[9.6,9.48]],"id":39296632},{"spn":9.6,"spf":1.0,"id":39296632},{"atb":[[14,8.4]],"id":41729332}],"con":true,"img":false}]}
{"op":"mcm","clk":"5306905562","pt":1646109889334,"mc":[{"id":"1.195395431","rc":[{"atb":[[13.5,32.44]],"id":41729332}],"con":true,"img":false}]}
{"op":"mcm","clk":"5306905565","pt":1646109889436,"mc":[{"id":"1.195395431","rc":[{"atb":[[9.4,7.65]],"id":39296632},{"atb":[[14.5,1.64]],"id":41729332}],"con":true,"img":false}]}
{"op":"mcm","clk":"5306905568","pt":1646109889537,"mc":[{"id":"1.195395431","rc":[{"atb":[[9.8,1.28]],"id":39296632}],"con":true,"img":false}]}
{"op":"mcm","clk":"5306905572","pt":1646109889742,"mc":[{"id":"1.195395431","rc":[{"atb":[[9.4,7.54]],"id":39296632}],"con":true,"img":false}]}
{"op":"mcm","clk":"5306905589","pt":1646109890305,"mc":[{"id":"1.195395431","rc":[{"atb":[[9.4,4.88]],"id":39296632}],"con":true,"img":false}]}
{"op":"mcm","clk":"5306905591","pt":1646109890406,"mc":[{"id":"1.195395431","rc":[{"atb":[[9.8,3.94]],"id":39296632}],"con":true,"img":false}]}
{"op":"mcm","clk":"5306905601","pt":1646109890715,"mc":[{"id":"1.195395431","rc":[{"atb":[[9.6,7.93]],"id":39296632}],"con":true,"img":false}]}
{"op":"mcm","clk":"5306905604","pt":1646109890818,"mc":[{"id":"1.195395431","rc":[{"atb":[[10,1.54]],"id":39296632}],"con":true,"img":false}]}
{"op":"mcm","clk":"5306905657","pt":1646109893536,"mc":[{"id":"1.195395431","rc":[{"atb":[[9.6,0]],"id":39296632}],"con":true,"img":false}]}
{"op":"mcm","clk":"5306905671","pt":1646109893843,"mc":[{"id":"1.195395431","rc":[{"atb":[[9.8,1.28]],"id":39296632}],"con":true,"img":false}]}
{"op":"mcm","clk":"5306905675","pt":1646109893948,"mc":[{"id":"1.195395431","rc":[{"atb":[[9.4,7.54]],"id":39296632}],"con":true,"img":false}]}
{"op":"mcm","clk":"5306905677","pt":1646109894051,"mc":[{"id":"1.195395431","rc":[{"atb":[[9.8,0]],"id":39296632}],"con":true,"img":false}]}
{"op":"mcm","clk":"5306905680","pt":1646109894153,"mc":[{"id":"1.195395431","rc":[{"atb":[[9.4,8.82]],"id":39296632}],"con":true,"img":false}]}
{"op":"mcm","clk":"5306905694","pt":1646109894716,"mc":[{"id":"1.195395431","rc":[{"atb":[[10,0]],"id":39296632}],"con":true,"img":false}]}
{"op":"mcm","clk":"5306905698","pt":1646109894818,"mc":[{"id":"1.195395431","rc":[{"atb":[[9.6,1.54]],"id":39296632}],"con":true,"img":false}]}
{"op":"mcm","clk":"5306905734","pt":1646109896457,"mc":[{"id":"1.195395431","rc":[{"atb":[[9.6,8.24]],"id":39296632}],"con":true,"img":false}]}
{"op":"mcm","clk":"5306905742","pt":1646109896919,"mc":[{"id":"1.195395431","rc":[{"atb":[[9.4,4.88]],"id":39296632}],"con":true,"img":false}]}
{"op":"mcm","clk":"5306905745","pt":1646109897023,"mc":[{"id":"1.195395431","rc":[{"atb":[[9.6,9.52],[9.8,2.65]],"id":39296632}],"con":true,"img":false}]}
{"op":"mcm","clk":"5306905753","pt":1646109897334,"mc":[{"id":"1.195395431","rc":[{"atb":[[9.6,7.98]],"id":39296632}],"con":true,"img":false}]}
{"op":"mcm","clk":"5306905757","pt":1646109897437,"mc":[{"id":"1.195395431","rc":[{"atb":[[9.8,4.19]],"id":39296632}],"con":true,"img":false}]}
{"op":"mcm","clk":"5306905776","pt":1646109898157,"mc":[{"id":"1.195395431","rc":[{"atb":[[9.6,6.69]],"id":39296632}],"con":true,"img":false}]}
{"op":"mcm","clk":"5306905782","pt":1646109898264,"mc":[{"id":"1.195395431","rc":[{"atb":[[9.8,5.48]],"id":39296632}],"con":true,"img":false}]}
{"op":"mcm","clk":"5306905813","pt":1646109899440,"mc":[{"id":"1.195395431","rc":[{"atb":[[9.6,0]],"id":39296632}],"con":true,"img":false}]}
{"op":"mcm","clk":"5306905823","pt":1646109899850,"mc":[{"id":"1.195395431","rc":[{"atb":[[9.8,2.83]],"id":39296632}],"con":true,"img":false}]}
{"op":"mcm","clk":"5306905827","pt":1646109899953,"mc":[{"id":"1.195395431","rc":[{"atb":[[9.4,7.54]],"id":39296632}],"con":true,"img":false}]}
{"op":"mcm","clk":"5306905844","pt":1646109900625,"mc":[{"id":"1.195395431","rc":[{"atb":[[9.8,0]],"id":39296632}],"con":true,"img":false}]}
{"op":"mcm","clk":"5306905846","pt":1646109900726,"mc":[{"id":"1.195395431","rc":[{"atb":[[9.6,1.54],[9.4,8.82]],"id":39296632}],"con":true,"img":false}]}
{"op":"mcm","clk":"5306905883","pt":1646109902435,"mc":[{"id":"1.195395431","rc":[{"atb":[[9.6,9.39]],"id":39296632}],"con":true,"img":false}]}
{"op":"mcm","clk":"5306905896","pt":1646109902949,"mc":[{"id":"1.195395431","rc":[{"atb":[[9.4,6.17]],"id":39296632}],"con":true,"img":false}]}
{"op":"mcm","clk":"5306905901","pt":1646109903052,"mc":[{"id":"1.195395431","rc":[{"atb":[[9.8,2.65],[9.4,4.88]],"id":39296632}],"con":true,"img":false}]}
{"op":"mcm","clk":"5306905905","pt":1646109903158,"mc":[{"id":"1.195395431","rc":[{"atb":[[9.8,3.94]],"id":39296632}],"con":true,"img":false}]}
{"op":"mcm","clk":"5306905911","pt":1646109903364,"mc":[{"id":"1.195395431","rc":[{"atb":[[9.6,7.85]],"id":39296632}],"con":true,"img":false}]}
{"op":"mcm","clk":"5306905915","pt":1646109903467,"mc":[{"id":"1.195395431","rc":[{"atb":[[9.8,5.48]],"id":39296632}],"con":true,"img":false}]}
{"op":"mcm","clk":"5306905964","pt":1646109905370,"mc":[{"id":"1.195395431","rc":[{"atb":[[9.6,0]],"id":39296632}],"con":true,"img":false}]}
{"op":"mcm","clk":"5306906050","pt":1646109908344,"mc":[{"id":"1.195395431","rc":[{"atb":[[10,4.11]],"id":39296632}],"con":true,"img":false}]}
{"op":"mcm","clk":"5306906074","pt":1646109909063,"mc":[{"id":"1.195395431","rc":[{"atb":[[9.8,4.19]],"id":39296632}],"con":true,"img":false}]}
{"op":"mcm","clk":"5306906077","pt":1646109909165,"mc":[{"id":"1.195395431","rc":[{"atb":[[10,5.39]],"id":39296632}],"con":true,"img":false}]}
{"op":"mcm","clk":"5306906761","pt":1646109933716,"mc":[{"id":"1.195395431","rc":[{"atb":[[10.5,4.29],[9.4,0]],"id":39296632}],"con":true,"img":false}]}
{"op":"mcm","clk":"5306906851","pt":1646109936806,"mc":[{"id":"1.195395431","rc":[{"atb":[[10,1.28]],"id":39296632}],"con":true,"img":false}]}
{"op":"mcm","clk":"5306906909","pt":1646109939630,"mc":[{"id":"1.195395431","rc":[{"atb":[[11,3.22]],"id":39296632}],"con":true,"img":false}]}
{"op":"mcm","clk":"5306907371","pt":1646109963472,"mc":[{"id":"1.195395431","rc":[{"atb":[[11.5,3.17]],"id":39296632},{"spn":11.5,"spf":1.0,"id":39296632},{"spn":24.25,"spf":1.0,"id":41729332}],"con":true,"img":false}]}
{"op":"mcm","clk":"5306907373","pt":1646109963526,"mc":[{"id":"1.195395431","rc":[{"atb":[[10.5,0]],"id":39296632}],"con":true,"img":false}]}
{"op":"mcm","clk":"5306907386","pt":1646109964344,"mc":[{"id":"1.195395431","rc":[{"atb":[[9.8,2.65]],"id":39296632}],"con":true,"img":false}]}
{"op":"mcm","clk":"5306907388","pt":1646109964447,"mc":[{"id":"1.195395431","rc":[{"atb":[[12,1.54]],"id":39296632}],"con":true,"img":false}]}
{"op":"mcm","clk":"5306907416","pt":1646109966246,"mc":[{"id":"1.195395431","rc":[{"atb":[[11,0]],"id":39296632}],"con":true,"img":false}]}
{"op":"mcm","clk":"5306907423","pt":1646109966657,"mc":[{"id":"1.195395431","rc":[{"atb":[[2.62,0]],"id":41375430}],"con":true,"img":false}]}
{"op":"mcm","clk":"5306907426","pt":1646109966758,"mc":[{"id":"1.195395431","rc":[{"atb":[[2.52,71.1]],"id":41375430}],"con":true,"img":false}]}
{"op":"mcm","clk":"5306907434","pt":1646109967065,"mc":[{"id":"1.195395431","rc":[{"atb":[[12,0]],"id":39296632}],"con":true,"img":false}]}
{"op":"mcm","clk":"5306907436","pt":1646109967167,"mc":[{"id":"1.195395431","rc":[{"atb":[[1.01,1.54]],"id":39296632}],"con":true,"img":false}]}
{"op":"mcm","clk":"5306907483","pt":1646109969270,"mc":[{"id":"1.195395431","rc":[{"atb":[[10,6.84]],"id":39296632}],"con":true,"img":false}]}
{"op":"mcm","clk":"5306907493","pt":1646109969834,"mc":[{"id":"1.195395431","rc":[{"atb":[[9.8,2.48]],"id":39296632}],"con":true,"img":false}]}
{"op":"mcm","clk":"5306907510","pt":1646109970453,"mc":[{"id":"1.195395431","rc":[{"atb":[[9.8,0]],"id":39296632}],"con":true,"img":false}]}
{"op":"mcm","clk":"5306907511","pt":1646109970556,"mc":[{"id":"1.195395431","rc":[{"atb":[[10.5,2.48]],"id":39296632}],"con":true,"img":false}]}
{"op":"mcm","clk":"5306907524","pt":1646109971068,"mc":[{"id":"1.195395431","rc":[{"atb":[[1.01,0]],"id":39296632}],"con":true,"img":false}]}
{"op":"mcm","clk":"5306907525","pt":1646109971171,"mc":[{"id":"1.195395431","rc":[{"atb":[[12,1.54]],"id":39296632}],"con":true,"img":false}]}
{"op":"mcm","clk":"5306907754","pt":1646109982350,"mc":[{"id":"1.195395431","rc":[{"atb":[[11.5,0]],"id":39296632}],"con":true,"img":false}]}
{"op":"mcm","clk":"5306907757","pt":1646109982452,"mc":[{"id":"1.195395431","rc":[{"atb":[[11,3.17]],"id":39296632}],"con":true,"img":false}]}
{"op":"mcm","clk":"5306907761","pt":1646109982656,"mc":[{"id":"1.195395431","rc":[{"atb":[[12,0]],"id":39296632}],"con":true,"img":false}]}
{"op":"mcm","clk":"5306907764","pt":1646109982758,"mc":[{"id":"1.195395431","rc":[{"atb":[[10.5,4.03]],"id":39296632}],"con":true,"img":false}]}
{"op":"mcm","clk":"5306907769","pt":1646109983275,"mc":[{"id":"1.195395431","rc":[{"atb":[[10.5,2.48]],"id":39296632}],"con":true,"img":false}]}
{"op":"mcm","clk":"5306907773","pt":1646109983371,"mc":[{"id":"1.195395431","rc":[{"atb":[[11.5,1.54]],"id":39296632}],"con":true,"img":false}]}
{"op":"mcm","clk":"5306907794","pt":1646109985361,"mc":[{"id":"1.195395431","rc":[{"atb":[[10,1.28]],"id":39296632}],"con":true,"img":false}]}
{"op":"mcm","clk":"5306907804","pt":1646109986178,"mc":[{"id":"1.195395431","rc":[{"atb":[[10.5,0]],"id":39296632}],"con":true,"img":false}]}
{"op":"mcm","clk":"5306907806","pt":1646109986280,"mc":[{"id":"1.195395431","rc":[{"atb":[[9.4,2.48]],"id":39296632}],"con":true,"img":false}]}
{"op":"mcm","clk":"5306907813","pt":1646109986789,"mc":[{"id":"1.195395431","rc":[{"atb":[[11.5,0]],"id":39296632}],"con":true,"img":false}]}
{"op":"mcm","clk":"5306907814","pt":1646109986891,"mc":[{"id":"1.195395431","rc":[{"atb":[[1.01,1.54]],"id":39296632}],"con":true,"img":false}]}
{"op":"mcm","clk":"5306907830","pt":1646109988267,"mc":[{"id":"1.195395431","rc":[{"atb":[[9.6,9.44]],"id":39296632}],"con":true,"img":false}]}
{"op":"mcm","clk":"5306907836","pt":1646109988573,"mc":[{"id":"1.195395431","rc":[{"atb":[[9.4,0]],"id":39296632}],"con":true,"img":false}]}
{"op":"mcm","clk":"5306907837","pt":1646109988676,"mc":[{"id":"1.195395431","rc":[{"atb":[[9.8,2.48]],"id":39296632}],"con":true,"img":false}]}
{"op":"mcm","clk":"5306907875","pt":1646109991180,"mc":[{"id":"1.195395431","rc":[{"atb":[[9.6,0]],"id":39296632}],"con":true,"img":false}]}
{"op":"mcm","clk":"5306907883","pt":1646109991586,"mc":[{"id":"1.195395431","rc":[{"atb":[[9.8,0]],"id":39296632}],"con":true,"img":false}]}
{"op":"mcm","clk":"5306907885","pt":1646109991688,"mc":[{"id":"1.195395431","rc":[{"atb":[[9.4,2.48]],"id":39296632}],"con":true,"img":false}]}
{"op":"mcm","clk":"5306907937","pt":1646109994190,"mc":[{"id":"1.195395431","rc":[{"atb":[[9.6,6.35]],"id":39296632}],"con":true,"img":false}]}
{"op":"mcm","clk":"5306907943","pt":1646109994598,"mc":[{"id":"1.195395431","rc":[{"atb":[[9.4,0]],"id":39296632}],"con":true,"img":false}]}
{"op":"mcm","clk":"5306907945","pt":1646109994700,"mc":[{"id":"1.195395431","rc":[{"atb":[[9.8,2.48]],"id":39296632}],"con":true,"img":false}]}
{"op":"mcm","clk":"5306907983","pt":1646109997101,"mc":[{"id":"1.195395431","rc":[{"atb":[[9.6,0]],"id":39296632}],"con":true,"img":false}]}
{"op":"mcm","clk":"5306908031","pt":1646110000012,"mc":[{"id":"1.195395431","rc":[{"atb":[[10,6.05]],"id":39296632}],"con":true,"img":false}]}
{"op":"mcm","clk":"5306908046","pt":1646110000577,"mc":[{"id":"1.195395431","rc":[{"atb":[[9.8,0]],"id":39296632}],"con":true,"img":false}]}
{"op":"mcm","clk":"5306908048","pt":1646110000679,"mc":[{"id":"1.195395431","rc":[{"atb":[[10.5,2.48]],"id":39296632}],"con":true,"img":false}]}
{"op":"mcm","clk":"5306908068","pt":1646110001902,"mc":[{"id":"1.195395431","rc":[{"atb":[[10,10.18],[11,0]],"id":39296632}],"con":true,"img":false}]}
{"op":"mcm","clk":"5306908106","pt":1646110004406,"mc":[{"id":"1.195395431","rc":[{"atb":[[10,5.42]],"id":39296632}],"con":true,"img":false}]}
{"op":"mcm","clk":"5306908107","pt":1646110004609,"mc":[{"id":"1.195395431","rc":[{"atb":[[10,4.13]],"id":39296632}],"con":true,"img":false}]}
{"op":"mcm","clk":"5306908110","pt":1646110004711,"mc":[{"id":"1.195395431","rc":[{"atb":[[10.5,0],[1.02,1.28]],"id":39296632}],"con":true,"img":false}]}
{"op":"mcm","clk":"5306908115","pt":1646110004813,"mc":[{"id":"1.195395431","rc":[{"atb":[[9.4,2.48]],"id":39296632}],"con":true,"img":false}]}
{"op":"mcm","clk":"5306908186","pt":1646110007376,"mc":[{"id":"1.195395431","rc":[{"atb":[[9.4,9.73]],"id":39296632}],"con":true,"img":false}]}
{"op":"mcm","clk":"5306908446","pt":1646110018022,"mc":[{"id":"1.195395431","rc":[{"atl":[[85,5]],"id":41375435}],"con":true,"img":false}]}
{"op":"mcm","clk":"5306908506","pt":1646110019714,"mc":[{"id":"1.195395431","rc":[{"atb":[[10,0],[9.6,5.65]],"id":39296632}],"con":true,"img":false}]}
{"op":"mcm","clk":"5306908518","pt":1646110020326,"mc":[{"id":"1.195395431","rc":[{"atb":[[1.02,0],[9.4,7.24]],"id":39296632}],"con":true,"img":false}]}
{"op":"mcm","clk":"5306908522","pt":1646110020426,"mc":[{"id":"1.195395431","rc":[{"atb":[[9.6,6.93],[9.8,2.48]],"id":39296632}],"con":true,"img":false}]}
{"op":"mcm","clk":"5306909223","pt":1646110046043,"mc":[{"id":"1.195395431","rc":[{"atb":[[10,4.75],[9.6,1.28]],"id":39296632},{"spn":10.0,"spf":1.0,"id":39296632}],"con":true,"img":false}]}
{"op":"mcm","clk":"5306909236","pt":1646110046553,"mc":[{"id":"1.195395431","rc":[{"atb":[[1.01,0]],"id":39296632}],"con":true,"img":false}]}
{"op":"mcm","clk":"5306909238","pt":1646110046656,"mc":[{"id":"1.195395431","rc":[{"atb":[[10.5,1.54]],"id":39296632}],"con":true,"img":false}]}
{"op":"mcm","clk":"5306909242","pt":1646110046861,"mc":[{"id":"1.195395431","rc":[{"atb":[[9.6,0],[9.8,0]],"id":39296632}],"con":true,"img":false}]}
{"op":"mcm","clk":"5306909246","pt":1646110046961,"mc":[{"id":"1.195395431","rc":[{"atb":[[9.6,2.48],[10,6.03]],"id":39296632}],"con":true,"img":false}]}
{"op":"mcm","clk":"5306909258","pt":1646110047371,"mc":[{"id":"1.195395431","rc":[{"atb":[[9.6,0]],"id":39296632}],"con":true,"img":false}]}
{"op":"mcm","clk":"5306909261","pt":1646110047473,"mc":[{"id":"1.195395431","rc":[{"atb":[[10.5,4.03]],"id":39296632}],"con":true,"img":false}]}
{"op":"mcm","clk":"5306909266","pt":1646110047678,"mc":[{"id":"1.195395431","rc":[{"atb":[[9.4,0]],"id":39296632}],"con":true,"img":false}]}
{"op":"mcm","clk":"5306910061","pt":1646110076386,"mc":[{"id":"1.195395431","rc":[{"atb":[[11,3.45]],"id":39296632}],"con":true,"img":false}]}
{"op":"mcm","clk":"5306910064","pt":1646110076491,"mc":[{"id":"1.195395431","rc":[{"atb":[[10,1.28]],"id":39296632}],"con":true,"img":false}]}
{"op":"mcm","clk":"5306910075","pt":1646110076694,"mc":[{"id":"1.195395431","rc":[{"atb":[[10.5,1.54]],"id":39296632}],"con":true,"img":false}]}
{"op":"mcm","clk":"5306910078","pt":1646110076796,"mc":[{"id":"1.195395431","rc":[{"atb":[[9.4,2.48]],"id":39296632}],"con":true,"img":false}]}
{"op":"mcm","clk":"5306910085","pt":1646110077101,"mc":[{"id":"1.195395431","rc":[{"atb":[[10.5,0]],"id":39296632}],"con":true,"img":false}]}
{"op":"mcm","clk":"5306910087","pt":1646110077204,"mc":[{"id":"1.195395431","rc":[{"atb":[[1.01,1.54]],"id":39296632}],"con":true,"img":false}]}
{"op":"mcm","clk":"5306910123","pt":1646110079400,"mc":[{"id":"1.195395431","rc":[{"atb":[[9.6,6.9]],"id":39296632}],"con":true,"img":false}]}
{"op":"mcm","clk":"5306910130","pt":1646110079806,"mc":[{"id":"1.195395431","rc":[{"atb":[[9.4,0]],"id":39296632}],"con":true,"img":false}]}
{"op":"mcm","clk":"5306910133","pt":1646110079912,"mc":[{"id":"1.195395431","rc":[{"atb":[[9.8,2.48]],"id":39296632}],"con":true,"img":false}]}
{"op":"mcm","clk":"5306910194","pt":1646110082414,"mc":[{"id":"1.195395431","rc":[{"atb":[[9.6,0]],"id":39296632}],"con":true,"img":false}]}
{"op":"mcm","clk":"5306910203","pt":1646110082821,"mc":[{"id":"1.195395431","rc":[{"atb":[[9.8,0]],"id":39296632}],"con":true,"img":false}]}
{"op":"mcm","clk":"5306910204","pt":1646110082923,"mc":[{"id":"1.195395431","rc":[{"atb":[[9.4,2.48]],"id":39296632}],"con":true,"img":false}]}
{"op":"mcm","clk":"5306910252","pt":1646110085429,"mc":[{"id":"1.195395431","rc":[{"atb":[[9.6,6.9]],"id":39296632}],"con":true,"img":false}]}
{"op":"mcm","clk":"5306910261","pt":1646110085789,"mc":[{"id":"1.195395431","rc":[{"atb":[[9.4,0]],"id":39296632}],"con":true,"img":false}]}
{"op":"mcm","clk":"5306910264","pt":1646110085893,"mc":[{"id":"1.195395431","rc":[{"atb":[[9.8,2.48]],"id":39296632}],"con":true,"img":false}]}
{"op":"mcm","clk":"5306910311","pt":1646110088298,"mc":[{"id":"1.195395431","rc":[{"atb":[[9.6,0]],"id":39296632}],"con":true,"img":false}]}
{"op":"mcm","clk":"5306910393","pt":1646110091317,"mc":[{"id":"1.195395431","rc":[{"atb":[[10,6.46]],"id":39296632}],"con":true,"img":false}]}
{"op":"mcm","clk":"5306910406","pt":1646110091825,"mc":[{"id":"1.195395431","rc":[{"atb":[[9.8,0]],"id":39296632}],"con":true,"img":false}]}
{"op":"mcm","clk":"5306910410","pt":1646110091926,"mc":[{"id":"1.195395431","rc":[{"atb":[[10.5,2.48]],"id":39296632}],"con":true,"img":false}]}
{"op":"mcm","clk":"5306910420","pt":1646110092128,"mc":[{"id":"1.195395431","rc":[{"atb":[[1.01,0]],"id":39296632}],"con":true,"img":false}]}
{"op":"mcm","clk":"5306910425","pt":1646110092230,"mc":[{"id":"1.195395431","rc":[{"atb":[[11.5,1.54]],"id":39296632}],"con":true,"img":false}]}
{"op":"mcm","clk":"5306910452","pt":1646110093714,"mc":[{"id":"1.195395431","rc":[{"atb":[[11,0]],"id":39296632}],"con":true,"img":false}]}
{"op":"mcm","clk":"5306910455","pt":1646110093815,"mc":[{"id":"1.195395431","rc":[{"atb":[[10,9.92]],"id":39296632}],"con":true,"img":false}]}
{"op":"mcm","clk":"5306910459","pt":1646110094225,"mc":[{"id":"1.195395431","rc":[{"atb":[[11.5,0]],"id":39296632}],"con":true,"img":false}]}
{"op":"mcm","clk":"5306910461","pt":1646110094331,"mc":[{"id":"1.195395431","rc":[{"atb":[[10.5,4.03]],"id":39296632}],"con":true,"img":false}]}
{"op":"mcm","clk":"5306910641","pt":1646110096151,"mc":[{"id":"1.195395431","rc":[{"atb":[[10,4.73]],"id":39296632}],"con":true,"img":false}]}
{"op":"mcm","clk":"5306910661","pt":1646110096529,"mc":[{"id":"1.195395431","rc":[{"atb":[[10.5,1.54]],"id":39296632}],"con":true,"img":false}]}
{"op":"mcm","clk":"5306910669","pt":1646110096635,"mc":[{"id":"1.195395431","rc":[{"atb":[[9.4,2.48]],"id":39296632}],"con":true,"img":false}]}
{"op":"mcm","clk":"5306910677","pt":1646110096841,"mc":[{"id":"1.195395431","rc":[{"atb":[[10.5,0]],"id":39296632}],"con":true,"img":false}]}
{"op":"mcm","clk":"5306910681","pt":1646110096963,"mc":[{"id":"1.195395431","rc":[{"atb":[[1.01,1.54]],"id":39296632}],"con":true,"img":false}]}
{"op":"mcm","clk":"5306910699","pt":1646110097229,"mc":[{"id":"1.195395431","rc":[{"atb":[[10,3.45]],"id":39296632}],"con":true,"img":false}]}
{"op":"mcm","clk":"5306910705","pt":1646110097332,"mc":[{"id":"1.195395431","rc":[{"atb":[[1.02,1.28]],"id":39296632}],"con":true,"img":false}]}
{"op":"mcm","clk":"5306910797","pt":1646110098920,"mc":[{"id":"1.195395431","rc":[{"atb":[[9.4,8.52]],"id":39296632}],"con":true,"img":false}]}
{"op":"mcm","clk":"5306911690","pt":1646110110460,"mc":[{"id":"1.195395431","rc":[{"atb":[[9.6,5.64]],"id":39296632}],"con":true,"img":false}]}
{"op":"mcm","clk":"5306911693","pt":1646110110558,"mc":[{"id":"1.195395431","rc":[{"atb":[[10,0]],"id":39296632}],"con":true,"img":false}]}
{"op":"mcm","clk":"5306911706","pt":1646110110969,"mc":[{"id":"1.195395431","rc":[{"atb":[[9.4,6.04]],"id":39296632}],"con":true,"img":false}]}
{"op":"mcm","clk":"5306911709","pt":1646110111073,"mc":[{"id":"1.195395431","rc":[{"atb":[[9.8,2.48]],"id":39296632}],"con":true,"img":false}]}
{"op":"mcm","clk":"5306911716","pt":1646110111174,"mc":[{"id":"1.195395431","rc":[{"atb":[[1.02,0]],"id":39296632}],"con":true,"img":false}]}
{"op":"mcm","clk":"5306911719","pt":1646110111276,"mc":[{"id":"1.195395431","rc":[{"atb":[[9.6,6.92]],"id":39296632}],"con":true,"img":false}]}
{"op":"mcm","clk":"5306912698","pt":1646110137093,"mc":[{"id":"1.195395431","rc":[{"atb":[[10,4.74],[9.6,1.28]],"id":39296632}],"con":true,"img":false}]}
{"op":"mcm","clk":"5306912711","pt":1646110137504,"mc":[{"id":"1.195395431","rc":[{"atb":[[9.8,0]],"id":39296632}],"con":true,"img":false}]}
{"op":"mcm","clk":"5306912716","pt":1646110137555,"mc":[{"id":"1.195395431","rc":[{"atb":[[9.6,2.48]],"id":39296632}],"con":true,"img":false}]}
{"op":"mcm","clk":"5306912719","pt":1646110137659,"mc":[{"id":"1.195395431","rc":[{"atb":[[10,6.02]],"id":39296632}],"con":true,"img":false}]}
{"op":"mcm","clk":"5306912727","pt":1646110137967,"mc":[{"id":"1.195395431","rc":[{"atb":[[9.6,0]],"id":39296632}],"con":true,"img":false}]}
{"op":"mcm","clk":"5306912731","pt":1646110138070,"mc":[{"id":"1.195395431","rc":[{"atb":[[10.5,2.48]],"id":39296632}],"con":true,"img":false}]}
{"op":"mcm","clk":"5306912763","pt":1646110138785,"mc":[{"id":"1.195395431","rc":[{"atb":[[9.4,0]],"id":39296632}],"con":true,"img":false}]}
{"op":"mcm","clk":"5306912778","pt":1646110139398,"mc":[{"id":"1.195395431","rc":[{"atb":[[10,4.74]],"id":39296632}],"con":true,"img":false}]}
{"op":"mcm","clk":"5306912781","pt":1646110139500,"mc":[{"id":"1.195395431","rc":[{"atb":[[1.02,1.28]],"id":39296632}],"con":true,"img":false}]}
{"op":"mcm","clk":"5306912804","pt":1646110139808,"mc":[{"id":"1.195395431","rc":[{"atb":[[10.5,0]],"id":39296632}],"con":true,"img":false}]}
{"op":"mcm","clk":"5306912807","pt":1646110139913,"mc":[{"id":"1.195395431","rc":[{"atb":[[9.4,2.48]],"id":39296632}],"con":true,"img":false}]}
{"op":"mcm","clk":"5306912878","pt":1646110141665,"mc":[{"id":"1.195395431","rc":[{"atb":[[9.4,10.79]],"id":39296632}],"con":true,"img":false}]}
{"op":"mcm","clk":"5306912901","pt":1646110142487,"mc":[{"id":"1.195395431","rc":[{"atb":[[1.02,0]],"id":39296632}],"con":true,"img":false}]}
{"op":"mcm","clk":"5306912907","pt":1646110142592,"mc":[{"id":"1.195395431","rc":[{"atb":[[10,6.02]],"id":39296632}],"con":true,"img":false}]}
{"op":"mcm","clk":"5306912912","pt":1646110142798,"mc":[{"id":"1.195395431","rc":[{"atb":[[9.4,8.3]],"id":39296632}],"con":true,"img":false}]}
{"op":"mcm","clk":"5306912915","pt":1646110142901,"mc":[{"id":"1.195395431","rc":[{"atb":[[10.5,2.48]],"id":39296632}],"con":true,"img":false}]}
{"op":"mcm","clk":"5306913658","pt":1646110165523,"mc":[{"id":"1.195395431","rc":[{"atb":[[10,1.28],[11,3.72]],"id":39296632}],"con":true,"img":false}]}
{"op":"mcm","clk":"5306913667","pt":1646110165727,"mc":[{"id":"1.195395431","rc":[{"atb":[[10.5,0]],"id":39296632}],"con":true,"img":false}]}
{"op":"mcm","clk":"5306913673","pt":1646110165828,"mc":[{"id":"1.195395431","rc":[{"atb":[[9.6,2.48]],"id":39296632}],"con":true,"img":false}]}
{"op":"mcm","clk":"5306913750","pt":1646110168032,"mc":[{"id":"1.195395431","rc":[{"atb":[[9.4,0]],"id":39296632}],"con":true,"img":false}]}
{"op":"mcm","clk":"5306913781","pt":1646110168748,"mc":[{"id":"1.195395431","rc":[{"atb":[[9.6,0]],"id":39296632}],"con":true,"img":false}]}
{"op":"mcm","clk":"5306913784","pt":1646110168799,"mc":[{"id":"1.195395431","rc":[{"atb":[[9.4,2.48]],"id":39296632}],"con":true,"img":false}]}
{"op":"mcm","clk":"5306913846","pt":1646110170905,"mc":[{"id":"1.195395431","rc":[{"atb":[[9.6,7.44]],"id":39296632},{"spn":11.0,"spf":1.0,"id":39296632}],"con":true,"img":false}]}
{"op":"mcm","clk":"5306913857","pt":1646110171110,"mc":[{"id":"1.195395431","rc":[{"atb":[[9.4,0]],"id":39296632}],"con":true,"img":false}]}
{"op":"mcm","clk":"5306913863","pt":1646110171211,"mc":[{"id":"1.195395431","rc":[{"atb":[[9.8,2.48]],"id":39296632}],"con":true,"img":false}]}
{"op":"mcm","clk":"5306913937","pt":1646110173825,"mc":[{"id":"1.195395431","rc":[{"atb":[[9.6,0]],"id":39296632}],"con":true,"img":false}]}
{"op":"mcm","clk":"5306913945","pt":1646110174232,"mc":[{"id":"1.195395431","rc":[{"atb":[[9.8,0]],"id":39296632}],"con":true,"img":false}]}
{"op":"mcm","clk":"5306913947","pt":1646110174335,"mc":[{"id":"1.195395431","rc":[{"atb":[[9.4,2.48]],"id":39296632}],"con":true,"img":false}]}
{"op":"mcm","clk":"5306914021","pt":1646110176740,"mc":[{"id":"1.195395431","rc":[{"atb":[[9.6,7.44]],"id":39296632}],"con":true,"img":false}]}
{"op":"mcm","clk":"5306914045","pt":1646110177253,"mc":[{"id":"1.195395431","rc":[{"atb":[[9.4,0]],"id":39296632}],"con":true,"img":false}]}
{"op":"mcm","clk":"5306914051","pt":1646110177356,"mc":[{"id":"1.195395431","rc":[{"atb":[[9.8,2.48]],"id":39296632}],"con":true,"img":false}]}
{"op":"mcm","clk":"5306914146","pt":1646110179765,"mc":[{"id":"1.195395431","rc":[{"atb":[[9.6,0]],"id":39296632}],"con":true,"img":false}]}
{"op":"mcm","clk":"5306914210","pt":1646110181723,"mc":[{"id":"1.195395431","rc":[{"atb":[[11,0]],"id":39296632}],"con":true,"img":false}]}
{"op":"mcm","clk":"5306914212","pt":1646110181825,"mc":[{"id":"1.195395431","rc":[{"atb":[[10,5.01]],"id":39296632}],"con":true,"img":false}]}
{"op":"mcm","clk":"5306914220","pt":1646110182034,"mc":[{"id":"1.195395431","rc":[{"atb":[[10,3.72]],"id":39296632}],"con":true,"img":false}]}
{"op":"mcm","clk":"5306914226","pt":1646110182136,"mc":[{"id":"1.195395431","rc":[{"atb":[[1.02,1.28]],"id":39296632}],"con":true,"img":false}]}
{"op":"mcm","clk":"5306914248","pt":1646110182750,"mc":[{"id":"1.195395431","rc":[{"atb":[[10,9.31]],"id":39296632}],"con":true,"img":false}]}
{"op":"mcm","clk":"5306914260","pt":1646110183366,"mc":[{"id":"1.195395431","rc":[{"atb":[[1.02,0],[9.8,0]],"id":39296632}],"con":true,"img":false}]}
{"op":"mcm","clk":"5306914261","pt":1646110183468,"mc":[{"id":"1.195395431","rc":[{"atb":[[10.5,3.77]],"id":39296632}],"con":true,"img":false}]}
{"op":"mcm","clk":"5306915184","pt":1646110212475,"mc":[{"id":"1.195395431","rc":[{"atb":[[10,5.58]],"id":39296632}],"con":true,"img":false}]}
{"op":"mcm","clk":"5306915187","pt":1646110212575,"mc":[{"id":"1.195395431","rc":[{"atb":[[11,3.72]],"id":39296632}],"con":true,"img":false}]}
{"op":"mcm","clk":"5306915273","pt":1646110215093,"mc":[{"id":"1.195395431","rc":[{"atb":[[10,0]],"id":39296632}],"con":true,"img":false}]}
{"op":"mcm","clk":"5306915338","pt":1646110217507,"mc":[{"id":"1.195395431","rc":[{"atb":[[10.5,1.28]],"id":39296632}],"con":true,"img":false}]}
{"op":"mcm","clk":"5306915340","pt":1646110217607,"mc":[{"id":"1.195395431","rc":[{"atb":[[9.4,2.48]],"id":39296632}],"con":true,"img":false}]}
{"op":"mcm","clk":"5306915392","pt":1646110219708,"mc":[{"id":"1.195395431","rc":[{"atb":[[9.6,7.44]],"id":39296632}],"con":true,"img":false}]}
{"op":"mcm","clk":"5306915836","pt":1646110233100,"mc":[{"id":"1.195395431","rc":[{"atb":[[11,0],[9.8,5.1]],"id":39296632},{"spn":10.13,"spf":1.0,"id":39296632}],"con":true,"img":false}]}
{"op":"mcm","clk":"5306915861","pt":1646110233819,"mc":[{"id":"1.195395431","rc":[{"atb":[[10.5,0],[9.4,0]],"id":39296632}],"con":true,"img":false}]}
{"op":"mcm","clk":"5306915868","pt":1646110233922,"mc":[{"id":"1.195395431","rc":[{"atb":[[9.8,8.87]],"id":39296632}],"con":true,"img":false}]}
{"op":"mcm","clk":"5306915924","pt":1646110236129,"mc":[{"id":"1.195395431","rc":[{"atb":[[9.6,0]],"id":39296632}],"con":true,"img":false}]}
{"op":"mcm","clk":"5306915996","pt":1646110239154,"mc":[{"id":"1.195395431","rc":[{"atb":[[9.4,11.04]],"id":39296632}],"con":true,"img":false}]}
{"op":"mcm","clk":"5306916708","pt":1646110261488,"mc":[{"id":"1.195395431","rc":[{"atb":[[9.8,3.77]],"id":39296632}],"con":true,"img":false}]}
{"op":"mcm","clk":"5306916713","pt":1646110261543,"mc":[{"id":"1.195395431","rc":[{"atb":[[10,5.1]],"id":39296632}],"con":true,"img":false}]}
{"op":"mcm","clk":"5306916726","pt":1646110261958,"mc":[{"id":"1.195395431","rc":[{"atb":[[9.8,1.28]],"id":39296632}],"con":true,"img":false}]}
{"op":"mcm","clk":"5306916732","pt":1646110262060,"mc":[{"id":"1.195395431","rc":[{"atb":[[9.6,2.48],[9.8,0]],"id":39296632}],"con":true,"img":false}]}
{"op":"mcm","clk":"5306916738","pt":1646110262160,"mc":[{"id":"1.195395431","rc":[{"atb":[[10,6.39]],"id":39296632}],"con":true,"img":false}]}
{"op":"mcm","clk":"5306916753","pt":1646110262675,"mc":[{"id":"1.195395431","rc":[{"atb":[[9.6,0]],"id":39296632}],"con":true,"img":false}]}
{"op":"mcm","clk":"5306916760","pt":1646110262777,"mc":[{"id":"1.195395431","rc":[{"atb":[[10.5,2.48]],"id":39296632}],"con":true,"img":false}]}
{"op":"mcm","clk":"5306916772","pt":1646110263186,"mc":[{"id":"1.195395431","rc":[{"atb":[[9.4,0]],"id":39296632}],"con":true,"img":false}]}
{"op":"mcm","clk":"5306916791","pt":1646110263855,"mc":[{"id":"1.195395431","rc":[{"atb":[[10,5.1]],"id":39296632}],"con":true,"img":false}]}
{"op":"mcm","clk":"5306916798","pt":1646110263959,"mc":[{"id":"1.195395431","rc":[{"atb":[[1.02,1.28]],"id":39296632}],"con":true,"img":false}]}
{"op":"mcm","clk":"5306916811","pt":1646110264471,"mc":[{"id":"1.195395431","rc":[{"atb":[[10.5,0]],"id":39296632}],"con":true,"img":false}]}
{"op":"mcm","clk":"5306916815","pt":1646110264575,"mc":[{"id":"1.195395431","rc":[{"atb":[[9.4,2.48]],"id":39296632}],"con":true,"img":false}]}
{"op":"mcm","clk":"5306916849","pt":1646110266062,"mc":[{"id":"1.195395431","rc":[{"atb":[[9.4,11.41]],"id":39296632}],"con":true,"img":false}]}
{"op":"mcm","clk":"5306916853","pt":1646110266262,"mc":[{"id":"1.195395431","rc":[{"atb":[[1.02,0]],"id":39296632}],"con":true,"img":false}]}
{"op":"mcm","clk":"5306916856","pt":1646110266366,"mc":[{"id":"1.195395431","rc":[{"atb":[[10,6.39]],"id":39296632}],"con":true,"img":false}]}
{"op":"mcm","clk":"5306916866","pt":1646110266777,"mc":[{"id":"1.195395431","rc":[{"atb":[[9.4,8.92]],"id":39296632}],"con":true,"img":false}]}
{"op":"mcm","clk":"5306916869","pt":1646110266878,"mc":[{"id":"1.195395431","rc":[{"atb":[[10.5,2.48]],"id":39296632}],"con":true,"img":false}]}
{"op":"mcm","clk":"5306917510","pt":1646110289600,"mc":[{"id":"1.195395431","rc":[{"atb":[[11,3.73]],"id":39296632}],"con":true,"img":false}]}
{"op":"mcm","clk":"5306917511","pt":1646110289710,"mc":[{"id":"1.195395431","rc":[{"atb":[[10,1.28]],"id":39296632}],"con":true,"img":false}]}
{"op":"mcm","clk":"5306917520","pt":1646110290422,"mc":[{"id":"1.195395431","rc":[{"atb":[[10.5,0]],"id":39296632}],"con":true,"img":false}]}
{"op":"mcm","clk":"5306917524","pt":1646110290522,"mc":[{"id":"1.195395431","rc":[{"atb":[[9.6,2.48]],"id":39296632}],"con":true,"img":false}]}
{"op":"mcm","clk":"5306917595","pt":1646110292727,"mc":[{"id":"1.195395431","rc":[{"atb":[[9.4,0]],"id":39296632}],"con":true,"img":false}]}
{"op":"mcm","clk":"5306917602","pt":1646110293388,"mc":[{"id":"1.195395431","rc":[{"atb":[[9.6,0]],"id":39296632},{"spn":11.0,"spf":1.0,"id":39296632}],"con":true,"img":false}]}
{"op":"mcm","clk":"5306917603","pt":1646110293494,"mc":[{"id":"1.195395431","rc":[{"atb":[[9.4,2.48]],"id":39296632}],"con":true,"img":false}]}
{"op":"mcm","clk":"5306917656","pt":1646110295636,"mc":[{"id":"1.195395431","rc":[{"atb":[[9.6,7.45]],"id":39296632}],"con":true,"img":false}]}
{"op":"mcm","clk":"5306917675","pt":1646110296310,"mc":[{"id":"1.195395431","rc":[{"atb":[[9.4,0]],"id":39296632}],"con":true,"img":false}]}
{"op":"mcm","clk":"5306917679","pt":1646110296411,"mc":[{"id":"1.195395431","rc":[{"atb":[[9.8,2.48]],"id":39296632}],"con":true,"img":false}]}
{"op":"mcm","clk":"5306917724","pt":1646110298614,"mc":[{"id":"1.195395431","rc":[{"atb":[[9.6,0]],"id":39296632}],"con":true,"img":false}]}
{"op":"mcm","clk":"5306917739","pt":1646110299324,"mc":[{"id":"1.195395431","rc":[{"atb":[[9.8,0]],"id":39296632}],"con":true,"img":false}]}
{"op":"mcm","clk":"5306917743","pt":1646110299427,"mc":[{"id":"1.195395431","rc":[{"atb":[[9.4,2.48]],"id":39296632}],"con":true,"img":false}]}
{"op":"mcm","clk":"5306917798","pt":1646110301524,"mc":[{"id":"1.195395431","rc":[{"atb":[[9.6,7.45]],"id":39296632}],"con":true,"img":false}]}
{"op":"mcm","clk":"5306917810","pt":1646110301828,"mc":[{"id":"1.195395431","rc":[{"atb":[[9.4,0]],"id":39296632}],"con":true,"img":false}]}
{"op":"mcm","clk":"5306917816","pt":1646110301931,"mc":[{"id":"1.195395431","rc":[{"atb":[[9.8,2.48]],"id":39296632}],"con":true,"img":false}]}
{"op":"mcm","clk":"5306917898","pt":1646110304446,"mc":[{"id":"1.195395431","rc":[{"atb":[[9.6,0]],"id":39296632}],"con":true,"img":false}]}
{"op":"mcm","clk":"5306917982","pt":1646110307426,"mc":[{"id":"1.195395431","rc":[{"atb":[[10,6.88]],"id":39296632}],"con":true,"img":false}]}
{"op":"mcm","clk":"5306917992","pt":1646110307737,"mc":[{"id":"1.195395431","rc":[{"atb":[[9.8,0]],"id":39296632}],"con":true,"img":false}]}
{"op":"mcm","clk":"5306917994","pt":1646110307838,"mc":[{"id":"1.195395431","rc":[{"atb":[[10.5,2.48],[11,0]],"id":39296632}],"con":true,"img":false}]}
{"op":"mcm","clk":"5306917996","pt":1646110307937,"mc":[{"id":"1.195395431","rc":[{"atb":[[10.5,6.21]],"id":39296632}],"con":true,"img":false}]}
