{"op":"mcm","clk":"5317728505","pt":1646251399889,"mc":[{"id":"1.195532863","marketDefinition":{"bspMarket":true,"turnInPlayEnabled":false,"persistenceEnabled":false,"marketBaseRate":5.0,"eventId":"31275720","eventTypeId":"4339","numberOfWinners":2,"bettingType":"ODDS","marketType":"PLACE","marketTime":"2022-03-03T15:28:00.000Z","suspendTime":"2022-03-03T15:28:00.000Z","bspReconciled":false,"complete":true,"inPlay":false,"crossMatching":false,"runnersVoidable":false,"numberOfActiveRunners":6,"betDelay":0,"status":"OPEN","runners":[{"status":"ACTIVE","sortPriority":1,"id":36042617,"name":"1. Newtown Freda"},{"status":"ACTIVE","sortPriority":2,"id":39693066,"name":"2. Olympic Sparrow"},{"status":"ACTIVE","sortPriority":3,"id":28603683,"name":"3. Droopys Diamante"},{"status":"ACTIVE","sortPriority":4,"id":35839928,"name":"4. Aero Abis"},{"status":"ACTIVE","sortPriority":5,"id":28691352,"name":"5. Award Winner"},{"status":"ACTIVE","sortPriority":6,"id":8668222,"name":"6. Made To Order"}],"regulators":["MR_INT"],"venue":"Romford","countryCode":"GB","discountAllowed":false,"timezone":"Europe/London","openDate":"2022-03-03T13:57:00.000Z","version":4384107309,"name":"To Be Placed","eventName":"Romford 3rd Mar"},"rc":[],"con":true,"img":false}]}
{"op":"mcm","clk":"5317728861","pt":1646251401766,"mc":[{"id":"1.195532863","marketDefinition":{"bspMarket":true,"turnInPlayEnabled":false,"persistenceEnabled":false,"marketBaseRate":5.0,"eventId":"31275720","eventTypeId":"4339","numberOfWinners":2,"bettingType":"ODDS","marketType":"PLACE","marketTime":"2022-03-03T15:28:00.000Z","suspendTime":"2022-03-03T15:28:00.000Z","bspReconciled":false,"complete":true,"inPlay":false,"crossMatching":false,"runnersVoidable":false,"numberOfActiveRunners":6,"betDelay":0,"status":"OPEN","runners":[{"status":"ACTIVE","sortPriority":1,"id":36042617,"name":"1. Newtown Freda"},{"status":"ACTIVE","sortPriority":2,"id":39693066,"name":"2. Olympic Sparrow"},{"status":"ACTIVE","sortPriority":3,"id":28603683,"name":"3. Droopys Diamante"},{"status":"ACTIVE","sortPriority":4,"id":35839928,"name":"4. Aero Abis"},{"status":"ACTIVE","sortPriority":5,"id":28691352,"name":"5. Award Winner"},{"status":"ACTIVE","sortPriority":6,"id":8668222,"name":"6. Made To Order"}],"regulators":["MR_INT"],"venue":"Romford","countryCode":"GB","discountAllowed":true,"timezone":"Europe/London","openDate":"2022-03-03T13:57:00.000Z","version":4384107309,"name":"To Be Placed","eventName":"Romford 3rd Mar"},"rc":[],"con":true,"img":false}]}
{"op":"mcm","clk":"5320483243","pt":1646296314465,"mc":[{"id":"1.195532863","rc":[{"spl":[[1.01,10]],"id":36042617},{"spn":1.0,"spf":1.0,"id":36042617}],"con":true,"img":false}]}
{"op":"mcm","clk":"5321200945","pt":1646307132127,"mc":[{"id":"1.195532863","rc":[{"atb":[[1.01,102.04]],"id":36042617},{"spn":1.01,"spf":1.0,"id":36042617},{"atb":[[1.01,102.04]],"id":39693066},{"spn":"Infinity","spf":"NaN","id":39693066},{"atb":[[1.01,102.04]],"id":35839928},{"spn":"Infinity","spf":"NaN","id":35839928},{"atb":[[1.01,102.04]],"id":28603683},{"spn":"Infinity","spf":"NaN","id":28603683},{"atb":[[1.01,102.04]],"id":8668222},{"spn":"Infinity","spf":"NaN","id":8668222},{"atb":[[1.01,102.04]],"id":28691352},{"spn":"Infinity","spf":"NaN","id":28691352}],"con":true,"img":false}]}
{"op":"mcm","clk":"5321220965","pt":1646307335462,"mc":[{"id":"1.195532863","rc":[{"atl":[[1000,5]],"id":39693066},{"spn":500.5,"spf":"NaN","id":39693066},{"atl":[[1000,5]],"id":36042617},{"atl":[[1000,5]],"id":35839928},{"spn":500.5,"spf":"NaN","id":35839928},{"atl":[[1000,5]],"id":28603683},{"spn":500.5,"spf":"NaN","id":28603683},{"atl":[[1000,5]],"id":8668222},{"spn":500.5,"spf":"NaN","id":8668222},{"atl":[[1000,5]],"id":28691352},{"spn":500.5,"spf":"NaN","id":28691352}],"con":true,"img":false}]}
{"op":"mcm","clk":"5321221031","pt":1646307335980,"mc":[{"id":"1.195532863","rc":[{"atb":[[1.01,4802.04]],"id":39693066},{"atb":[[1.01,4802.04]],"id":36042617},{"atb":[[1.01,4802.04]],"id":35839928},{"atb":[[1.01,4802.04]],"id":28603683},{"atb":[[1.01,4802.04]],"id":8668222},{"atb":[[1.01,4802.04]],"id":28691352}],"con":true,"img":false}]}
{"op":"mcm","clk":"5321419315","pt":1646309489573,"mc":[{"id":"1.195532863","rc":[{"spl":[[1.01,8.18]],"id":28691352},{"spn":1.01,"spf":1.0,"id":28691352}],"con":true,"img":false}]}
{"op":"mcm","clk":"5321809173","pt":1646313402548,"mc":[{"id":"1.195532863","marketDefinition":{"bspMarket":true,"turnInPlayEnabled":false,"persistenceEnabled":false,"marketBaseRate":5.0,"eventId":"31275720","eventTypeId":"4339","numberOfWinners":2,"bettingType":"ODDS","marketType":"PLACE","marketTime":"2022-03-03T15:28:00.000Z","suspendTime":"2022-03-03T15:28:00.000Z","bspReconciled":false,"complete":true,"inPlay":false,"crossMatching":false,"runnersVoidable":false,"numberOfActiveRunners":6,"betDelay":0,"status":"OPEN","runners":[{"status":"ACTIVE","sortPriority":1,"id":36042617,"name":"1. Newtown Freda"},{"status":"ACTIVE","sortPriority":2,"id":39693066,"name":"2. Olympic Sparrow"},{"status":"ACTIVE","sortPriority":3,"id":28603683,"name":"3. Droopys Diamante"},{"status":"ACTIVE","sortPriority":4,"id":35839928,"name":"4. Aero Abis"},{"status":"ACTIVE","sortPriority":5,"id":28691352,"name":"5. Award Winner"},{"status":"ACTIVE","sortPriority":6,"id":8668222,"name":"6. Made To Order"}],"regulators":["MR_INT"],"venue":"Romford","countryCode":"GB","discountAllowed":true,"timezone":"Europe/London","openDate":"2022-03-03T13:57:00.000Z","version":4384107309,"name":"To Be Placed","eventName":"Romford 3rd Mar"},"rc":[{"atb":[[1.01,4802.04]],"id":39693066},{"atl":[[1000,5]],"id":39693066},{"spn":500.5,"spf":"NaN","id":39693066},{"atb":[[1.01,4802.04]],"id":36042617},{"spl":[[1.01,10]],"id":36042617},{"atl":[[1000,5]],"id":36042617},{"spn":1.01,"spf":1.0,"id":36042617},{"atb":[[1.01,4802.04]],"id":35839928},{"atl":[[1000,5]],"id":35839928},{"spn":500.5,"spf":"NaN","id":35839928},{"atb":[[1.01,4802.04]],"id":28603683},{"atl":[[1000,5]],"id":28603683},{"spn":500.5,"spf":"NaN","id":28603683},{"atb":[[1.01,4802.04]],"id":8668222},{"atl":[[1000,5]],"id":8668222},{"spn":500.5,"spf":"NaN","id":8668222},{"atb":[[1.01,4802.04]],"id":28691352},{"spl":[[1.01,8.19]],"id":28691352},{"atl":[[1000,5]],"id":28691352},{"spn":1.01,"spf":1.0,"id":28691352}],"con":true,"img":true}]}
{"op":"mcm","clk":"5322377527","pt":1646319481723,"mc":[{"id":"1.195532863","rc":[{"atb":[[1.01,5052.04]],"id":39693066},{"atb":[[1.01,5052.04]],"id":36042617},{"atb":[[1.01,5052.04]],"id":35839928},{"atb":[[1.01,5052.04]],"id":28603683},{"atb":[[1.01,5052.04]],"id":8668222},{"atb":[[1.01,5052.04]],"id":28691352},{"spl":[[1.01,8.19]],"id":28691352}],"con":true,"img":false}]}
{"op":"mcm","clk":"5322456443","pt":1646320426299,"mc":[{"id":"1.195532863","rc":[{"atb":[[1.01,5054.04]],"id":36042617},{"spl":[[1.01,8.24]],"id":28691352}],"con":true,"img":false}]}
{"op":"mcm","clk":"5322456462","pt":1646320426514,"mc":[{"id":"1.195532863","rc":[{"atb":[[1.01,5056.03],[1.66,151.52]],"id":36042617},{"atl":[[11.5,5]],"id":36042617}],"con":true,"img":false}]}
{"op":"mcm","clk":"5322456468","pt":1646320426605,"mc":[{"id":"1.195532863","rc":[{"atb":[[1.01,5054.04]],"id":36042617}],"con":true,"img":false}]}
{"op":"mcm","clk":"5322456478","pt":1646320426716,"mc":[{"id":"1.195532863","rc":[{"atb":[[1.76,131.58]],"id":39693066},{"atl":[[16,5]],"id":39693066},{"atb":[[1.02,1.99]],"id":36042617},{"atb":[[1.91,109.89]],"id":35839928},{"atl":[[24,4.35]],"id":35839928},{"atb":[[1.53,188.68]],"id":28603683},{"atl":[[8.2,5]],"id":28603683},{"atb":[[1.6,166.67]],"id":8668222},{"atl":[[9.4,5]],"id":8668222},{"atb":[[1.18,555.56]],"id":28691352},{"atl":[[6.2,5]],"id":28691352}],"con":true,"img":false}]}
{"op":"mcm","clk":"5322456493","pt":1646320426913,"mc":[{"id":"1.195532863","rc":[{"atb":[[1.01,5054.04]],"id":39693066}],"con":true,"img":false}]}
{"op":"mcm","clk":"5322456500","pt":1646320427017,"mc":[{"id":"1.195532863","rc":[{"atb":[[1.01,5056.03]],"id":39693066}],"con":true,"img":false}]}
{"op":"mcm","clk":"5322456517","pt":1646320427176,"mc":[{"id":"1.195532863","rc":[{"atb":[[1.01,5054.04]],"id":39693066}],"con":true,"img":false}]}
{"op":"mcm","clk":"5322456529","pt":1646320427280,"mc":[{"id":"1.195532863","rc":[{"atb":[[1.02,1.99]],"id":39693066}],"con":true,"img":false}]}
{"op":"mcm","clk":"5322456539","pt":1646320427384,"mc":[{"id":"1.195532863","rc":[{"atb":[[1.01,5054.04]],"id":28603683}],"con":true,"img":false}]}
{"op":"mcm","clk":"5322456557","pt":1646320427590,"mc":[{"id":"1.195532863","rc":[{"atb":[[1.01,5056.03]],"id":28603683}],"con":true,"img":false}]}
{"op":"mcm","clk":"5322456571","pt":1646320427707,"mc":[{"id":"1.195532863","rc":[{"atb":[[1.01,5054.04]],"id":28603683}],"con":true,"img":false}]}
{"op":"mcm","clk":"5322456582","pt":1646320427806,"mc":[{"id":"1.195532863","rc":[{"atb":[[1.02,1.99]],"id":28603683}],"con":true,"img":false}]}
{"op":"mcm","clk":"5322456593","pt":1646320427911,"mc":[{"id":"1.195532863","rc":[{"atb":[[1.01,5054.04]],"id":35839928}],"con":true,"img":false}]}
{"op":"mcm","clk":"5322456613","pt":1646320428114,"mc":[{"id":"1.195532863","rc":[{"atb":[[1.01,5056.03]],"id":35839928}],"con":true,"img":false}]}
{"op":"mcm","clk":"5322456630","pt":1646320428319,"mc":[{"id":"1.195532863","rc":[{"atb":[[1.01,5054.04]],"id":35839928}],"con":true,"img":false}]}
{"op":"mcm","clk":"5322456641","pt":1646320428424,"mc":[{"id":"1.195532863","rc":[{"atb":[[1.02,1.99]],"id":35839928}],"con":true,"img":false}]}
{"op":"mcm","clk":"5322456658","pt":1646320428583,"mc":[{"id":"1.195532863","rc":[{"atb":[[1.01,5054.04]],"id":28691352}],"con":true,"img":false}]}
{"op":"mcm","clk":"5322456673","pt":1646320428789,"mc":[{"id":"1.195532863","rc":[{"atb":[[1.01,5056.03]],"id":28691352}],"con":true,"img":false}]}
{"op":"mcm","clk":"5322456702","pt":1646320429111,"mc":[{"id":"1.195532863","rc":[{"atb":[[1.01,5054.04]],"id":28691352}],"con":true,"img":false}]}
{"op":"mcm","clk":"5322456714","pt":1646320429309,"mc":[{"id":"1.195532863","rc":[{"atb":[[1.02,1.99]],"id":28691352}],"con":true,"img":false}]}
{"op":"mcm","clk":"5322456739","pt":1646320429529,"mc":[{"id":"1.195532863","rc":[{"atb":[[1.01,5054.04]],"id":8668222}],"con":true,"img":false}]}
{"op":"mcm","clk":"5322456755","pt":1646320429740,"mc":[{"id":"1.195532863","rc":[{"atb":[[1.01,5056.03]],"id":8668222}],"con":true,"img":false}]}
{"op":"mcm","clk":"5322456776","pt":1646320430051,"mc":[{"id":"1.195532863","rc":[{"atb":[[1.01,5054.04]],"id":8668222}],"con":true,"img":false}]}
{"op":"mcm","clk":"5322456784","pt":1646320430156,"mc":[{"id":"1.195532863","rc":[{"atb":[[1.02,1.99]],"id":8668222}],"con":true,"img":false}]}
{"op":"mcm","clk":"5322456900","pt":1646320431661,"mc":[{"id":"1.195532863","rc":[{"atb":[[1.02,0]],"id":36042617}],"con":true,"img":false}]}
{"op":"mcm","clk":"5322456908","pt":1646320431713,"mc":[{"id":"1.195532863","rc":[{"atb":[[1.67,1.99]],"id":36042617}],"con":true,"img":false}]}
{"op":"mcm","clk":"5322456930","pt":1646320432027,"mc":[{"id":"1.195532863","rc":[{"atb":[[1.02,0]],"id":39693066}],"con":true,"img":false}]}
{"op":"mcm","clk":"5322456938","pt":1646320432163,"mc":[{"id":"1.195532863","rc":[{"atb":[[1.77,1.99]],"id":39693066}],"con":true,"img":false}]}
{"op":"mcm","clk":"5322456954","pt":1646320432339,"mc":[{"id":"1.195532863","rc":[{"atb":[[1.02,0]],"id":28603683}],"con":true,"img":false}]}
{"op":"mcm","clk":"5322456965","pt":1646320432453,"mc":[{"id":"1.195532863","rc":[{"atb":[[1.54,1.99]],"id":28603683}],"con":true,"img":false}]}
{"op":"mcm","clk":"5322456988","pt":1646320432763,"mc":[{"id":"1.195532863","rc":[{"atb":[[1.02,0]],"id":35839928}],"con":true,"img":false}]}
{"op":"mcm","clk":"5322456996","pt":1646320432867,"mc":[{"id":"1.195532863","rc":[{"atb":[[1.92,1.99]],"id":35839928}],"con":true,"img":false}]}
{"op":"mcm","clk":"5322457008","pt":1646320433075,"mc":[{"id":"1.195532863","rc":[{"atb":[[1.02,0]],"id":28691352}],"con":true,"img":false}]}
{"op":"mcm","clk":"5322457014","pt":1646320433172,"mc":[{"id":"1.195532863","rc":[{"atb":[[1.19,1.99]],"id":28691352}],"con":true,"img":false}]}
{"op":"mcm","clk":"5322457044","pt":1646320433541,"mc":[{"id":"1.195532863","rc":[{"atb":[[1.02,0]],"id":8668222}],"con":true,"img":false}]}
{"op":"mcm","clk":"5322457053","pt":1646320433651,"mc":[{"id":"1.195532863","rc":[{"atb":[[1.61,1.99]],"id":8668222}],"con":true,"img":false}]}
{"op":"mcm","clk":"5322457590","pt":1646320440454,"mc":[{"id":"1.195532863","marketDefinition":{"bspMarket":true,"turnInPlayEnabled":false,"persistenceEnabled":false,"marketBaseRate":5.0,"eventId":"31275720","eventTypeId":"4339","numberOfWinners":2,"bettingType":"ODDS","marketType":"PLACE","marketTime":"2022-03-03T15:28:00.000Z","suspendTime":"2022-03-03T15:28:00.000Z","bspReconciled":false,"complete":true,"inPlay":false,"crossMatching":true,"runnersVoidable":false,"numberOfActiveRunners":6,"betDelay":0,"status":"OPEN","runners":[{"status":"ACTIVE","sortPriority":1,"id":36042617,"name":"1. Newtown Freda"},{"status":"ACTIVE","sortPriority":2,"id":39693066,"name":"2. Olympic Sparrow"},{"status":"ACTIVE","sortPriority":3,"id":28603683,"name":"3. Droopys Diamante"},{"status":"ACTIVE","sortPriority":4,"id":35839928,"name":"4. Aero Abis"},{"status":"ACTIVE","sortPriority":5,"id":28691352,"name":"5. Award Winner"},{"status":"ACTIVE","sortPriority":6,"id":8668222,"name":"6. Made To Order"}],"regulators":["MR_INT"],"venue":"Romford","countryCode":"GB","discountAllowed":true,"timezone":"Europe/London","openDate":"2022-03-03T13:57:00.000Z","version":4384107309,"name":"To Be Placed","eventName":"Romford 3rd Mar"},"rc":[],"con":true,"img":false}]}
{"op":"mcm","clk":"5322459319","pt":1646320460393,"mc":[{"id":"1.195532863","rc":[{"atb":[[1.75,53.33]],"id":39693066},{"atl":[[17,2.5],[18,5.88],[19,8.33],[20,13.16]],"id":39693066},{"atb":[[1.65,61.54]],"id":36042617},{"atl":[[12.5,3.48],[13.5,8],[14.5,11.11],[15.5,17.24]],"id":36042617},{"atb":[[1.9,44.44]],"id":35839928},{"atl":[[34,7.58],[26,1.6],[28,3.7],[30,5.17]],"id":35839928},{"atb":[[1.52,76.92]],"id":28603683},{"atl":[[8.6,5.26],[9,12.5],[9.8,28.41],[9.4,17.86]],"id":28603683},{"atb":[[1.59,67.8]],"id":8668222},{"atl":[[10.5,10.53],[11.5,14.29],[9.8,4.55],[12.5,21.74]],"id":8668222},{"atb":[[1.17,235.29]],"id":28691352},{"atl":[[7.4,23.44],[6.6,7.14],[7,16.67],[7.8,36.76]],"id":28691352}],"con":true,"img":false}]}
{"op":"mcm","clk":"5322460179","pt":1646320470397,"mc":[{"id":"1.195532863","rc":[{"atb":[[1.73,136.99]],"id":39693066},{"atb":[[1.63,158.73]],"id":36042617},{"atb":[[1.88,113.64]],"id":35839928},{"atb":[[1.5,200]],"id":28603683},{"atb":[[1.57,175.44]],"id":8668222},{"atb":[[1.15,250]],"id":28691352}],"con":true,"img":false}]}
{"op":"mcm","clk":"5322460273","pt":1646320471699,"mc":[{"id":"1.195532863","rc":[{"atb":[[1.79,2.15]],"id":39693066},{"atb":[[1.69,2.15]],"id":36042617},{"atb":[[1.94,2.15]],"id":35839928},{"atb":[[1.56,2.15]],"id":28603683},{"atb":[[1.63,2.15]],"id":8668222}],"con":true,"img":false}]}
{"op":"mcm","clk":"5322460292","pt":1646320471906,"mc":[{"id":"1.195532863","rc":[{"atb":[[1.79,4.31],[1.76,0]],"id":39693066},{"atb":[[1.66,0],[1.69,4.31]],"id":36042617},{"atb":[[1.91,0],[1.94,4.31]],"id":35839928},{"atb":[[1.56,4.31],[1.53,0]],"id":28603683},{"atb":[[1.63,4.31],[1.6,0]],"id":8668222}],"con":true,"img":false}]}
{"op":"mcm","clk":"5322460337","pt":1646320472480,"mc":[{"id":"1.195532863","rc":[{"atb":[[1.67,0]],"id":36042617}],"con":true,"img":false}]}
{"op":"mcm","clk":"5322460347","pt":1646320472583,"mc":[{"id":"1.195532863","rc":[{"atb":[[1.7,1.99]],"id":36042617}],"con":true,"img":false}]}
{"op":"mcm","clk":"5322460356","pt":1646320472694,"mc":[{"id":"1.195532863","rc":[{"atb":[[1.77,0]],"id":39693066}],"con":true,"img":false}]}
{"op":"mcm","clk":"5322460361","pt":1646320472792,"mc":[{"id":"1.195532863","rc":[{"atb":[[1.8,1.99]],"id":39693066}],"con":true,"img":false}]}
{"op":"mcm","clk":"5322460371","pt":1646320472895,"mc":[{"id":"1.195532863","rc":[{"atb":[[1.54,0]],"id":28603683}],"con":true,"img":false}]}
{"op":"mcm","clk":"5322460384","pt":1646320473000,"mc":[{"id":"1.195532863","rc":[{"atb":[[1.57,1.99]],"id":28603683}],"con":true,"img":false}]}
{"op":"mcm","clk":"5322460402","pt":1646320473212,"mc":[{"id":"1.195532863","rc":[{"atb":[[1.92,0]],"id":35839928}],"con":true,"img":false}]}
{"op":"mcm","clk":"5322460411","pt":1646320473317,"mc":[{"id":"1.195532863","rc":[{"atb":[[1.95,1.99]],"id":35839928}],"con":true,"img":false}]}
{"op":"mcm","clk":"5322460442","pt":1646320473623,"mc":[{"id":"1.195532863","rc":[{"atb":[[1.61,0]],"id":8668222}],"con":true,"img":false}]}
{"op":"mcm","clk":"5322460452","pt":1646320473730,"mc":[{"id":"1.195532863","rc":[{"atb":[[1.64,1.99]],"id":8668222}],"con":true,"img":false}]}
{"op":"mcm","clk":"5322460958","pt":1646320480434,"mc":[{"id":"1.195532863","rc":[{"atb":[[1.78,51.28]],"id":39693066},{"atb":[[1.68,58.82]],"id":36042617},{"atb":[[1.93,43.01]],"id":35839928},{"atb":[[1.55,72.73]],"id":28603683},{"atb":[[1.62,64.52]],"id":8668222},{"atb":[[1.13,250]],"id":28691352}],"con":true,"img":false}]}
{"op":"mcm","clk":"5322461749","pt":1646320490400,"mc":[{"id":"1.195532863","rc":[{"spn":8.9,"spf":"NaN","id":39693066},{"spn":1.68,"spf":1.0,"id":36042617},{"spn":12.97,"spf":"NaN","id":35839928},{"spn":4.88,"spf":"NaN","id":28603683},{"spn":5.52,"spf":"NaN","id":8668222},{"atb":[[1.11,250]],"id":28691352},{"spn":1.18,"spf":1.0,"id":28691352}],"con":true,"img":false}]}
{"op":"mcm","clk":"5322462210","pt":1646320497100,"mc":[{"id":"1.195532863","rc":[{"atb":[[1.53,6.93]],"id":28603683},{"atb":[[1.6,6.93]],"id":8668222},{"atb":[[1.19,194.14]],"id":28691352}],"con":true,"img":false}]}
{"op":"mcm","clk":"5322462221","pt":1646320497203,"mc":[{"id":"1.195532863","rc":[{"atb":[[1.2,235.29]],"id":28691352}],"con":true,"img":false}]}
{"op":"mcm","clk":"5322462228","pt":1646320497305,"mc":[{"id":"1.195532863","rc":[{"atb":[[1.18,0]],"id":28691352}],"con":true,"img":false}]}
{"op":"mcm","clk":"5322462235","pt":1646320497410,"mc":[{"id":"1.195532863","rc":[{"atb":[[1.19,192.15]],"id":28691352}],"con":true,"img":false}]}
{"op":"mcm","clk":"5322462245","pt":1646320497513,"mc":[{"id":"1.195532863","rc":[{"atb":[[1.21,1.99]],"id":28691352}],"con":true,"img":false}]}
{"op":"mcm","clk":"5322462495","pt":1646320500436,"mc":[{"id":"1.195532863","rc":[{"atb":[[1.19,402.68],[1.17,0]],"id":28691352}],"con":true,"img":false}]}
{"op":"mcm","clk":"5322462556","pt":1646320501220,"mc":[{"id":"1.195532863","rc":[{"atb":[[1.19,210.53]],"id":28691352}],"con":true,"img":false}]}
{"op":"mcm","clk":"5322462902","pt":1646320505618,"mc":[{"id":"1.195532863","rc":[{"atb":[[1.16,228.18]],"id":28691352}],"con":true,"img":false}]}
{"op":"mcm","clk":"5322463250","pt":1646320510417,"mc":[{"id":"1.195532863","rc":[{"atb":[[1.01,4804.04],[1.17,250]],"id":28691352}],"con":true,"img":false}]}
{"op":"mcm","clk":"5322463454","pt":1646320513345,"mc":[{"id":"1.195532863","rc":[{"atb":[[1.16,0]],"id":28691352}],"con":true,"img":false}]}
{"op":"mcm","clk":"5322463819","pt":1646320517752,"mc":[{"id":"1.195532863","rc":[{"atb":[[1.21,168.08]],"id":28691352}],"con":true,"img":false}]}
{"op":"mcm","clk":"5322463829","pt":1646320517857,"mc":[{"id":"1.195532863","rc":[{"atb":[[1.2,0],[1.22,210.53]],"id":28691352}],"con":true,"img":false}]}
{"op":"mcm","clk":"5322463862","pt":1646320518335,"mc":[{"id":"1.195532863","rc":[{"atb":[[1.21,166.09]],"id":28691352}],"con":true,"img":false}]}
{"op":"mcm","clk":"5322463869","pt":1646320518436,"mc":[{"id":"1.195532863","rc":[{"atb":[[1.23,1.99]],"id":28691352}],"con":true,"img":false}]}
{"op":"mcm","clk":"5322464064","pt":1646320520430,"mc":[{"id":"1.195532863","rc":[{"atb":[[1.21,356.57],[1.19,0]],"id":28691352}],"con":true,"img":false}]}
{"op":"mcm","clk":"5322464164","pt":1646320521640,"mc":[{"id":"1.195532863","rc":[{"atb":[[1.21,190.48],[1.11,0]],"id":28691352}],"con":true,"img":false}]}
{"op":"mcm","clk":"5322464499","pt":1646320525448,"mc":[{"id":"1.195532863","rc":[{"atb":[[1.18,202.82]],"id":28691352}],"con":true,"img":false}]}
{"op":"mcm","clk":"5322464781","pt":1646320529063,"mc":[{"id":"1.195532863","rc":[{"atb":[[1.79,2.15],[1.87,4.32]],"id":39693066},{"atl":[[16,0],[15,5]],"id":39693066},{"atb":[[1.75,4.32],[1.69,2.15]],"id":36042617},{"atl":[[11.5,0],[9.8,5]],"id":36042617},{"atb":[[1.94,2.15],[2.14,4.32]],"id":35839928},{"atl":[[23,3.7],[24,0]],"id":35839928},{"atb":[[1.56,2.15],[1.64,4.32]],"id":28603683},{"atl":[[9,25],[8.2,0]],"id":28603683},{"atb":[[1.63,2.15],[1.68,4.32]],"id":8668222},{"atl":[[8.4,5],[9.4,0]],"id":8668222},{"atb":[[1.22,0],[1.3,190.48]],"id":28691352},{"atl":[[6.2,0],[5.2,7.14]],"id":28691352}],"con":true,"img":false}]}
{"op":"mcm","clk":"5322464808","pt":1646320529372,"mc":[{"id":"1.195532863","rc":[{"atb":[[1.7,0]],"id":36042617}],"con":true,"img":false}]}
{"op":"mcm","clk":"5322464821","pt":1646320529477,"mc":[{"id":"1.195532863","rc":[{"atb":[[1.85,47.06],[1.78,0]],"id":39693066},{"atl":[[16,2.67],[17,0]],"id":39693066},{"atb":[[1.73,54.79],[1.68,0],[1.76,1.99]],"id":36042617},{"atl":[[10.5,4.21],[12.5,0]],"id":36042617},{"atb":[[1.93,0],[2.1,36.36]],"id":35839928},{"atl":[[25,1.67],[26,0]],"id":35839928},{"atb":[[1.55,0],[1.62,64.52]],"id":28603683},{"atl":[[8.6,0],[9,17.5]],"id":28603683},{"atb":[[1.62,0],[1.66,60.61]],"id":8668222},{"atl":[[9.8,0],[8.8,5.13]],"id":8668222}],"con":true,"img":false}]}
{"op":"mcm","clk":"5322464835","pt":1646320529591,"mc":[{"id":"1.195532863","rc":[{"atb":[[1.28,142.86],[1.21,0]],"id":28691352},{"atl":[[6.6,0],[5.4,9.09]],"id":28691352}],"con":true,"img":false}]}
{"op":"mcm","clk":"5322464847","pt":1646320529700,"mc":[{"id":"1.195532863","rc":[{"atb":[[1.8,0]],"id":39693066}],"con":true,"img":false}]}
{"op":"mcm","clk":"5322464854","pt":1646320529788,"mc":[{"id":"1.195532863","rc":[{"atb":[[1.88,1.99]],"id":39693066}],"con":true,"img":false}]}
{"op":"mcm","clk":"5322464865","pt":1646320529908,"mc":[{"id":"1.195532863","rc":[{"atb":[[1.63,0],[1.69,2.15]],"id":8668222},{"atb":[[1.33,2.15]],"id":28691352}],"con":true,"img":false}]}
{"op":"mcm","clk":"5322464877","pt":1646320530052,"mc":[{"id":"1.195532863","rc":[{"atb":[[1.57,0]],"id":28603683}],"con":true,"img":false}]}
{"op":"mcm","clk":"5322464884","pt":1646320530156,"mc":[{"id":"1.195532863","rc":[{"atb":[[1.65,1.99]],"id":28603683}],"con":true,"img":false}]}
{"op":"mcm","clk":"5322464903","pt":1646320530368,"mc":[{"id":"1.195532863","rc":[{"atb":[[1.95,0]],"id":35839928}],"con":true,"img":false}]}
{"op":"mcm","clk":"5322464911","pt":1646320530471,"mc":[{"id":"1.195532863","rc":[{"atb":[[2.16,1.99]],"id":35839928}],"con":true,"img":false}]}
{"op":"mcm","clk":"5322464938","pt":1646320530787,"mc":[{"id":"1.195532863","rc":[{"atb":[[1.23,0]],"id":28691352}],"con":true,"img":false}]}
{"op":"mcm","clk":"5322464949","pt":1646320530896,"mc":[{"id":"1.195532863","rc":[{"atb":[[1.31,1.99]],"id":28691352}],"con":true,"img":false}]}
{"op":"mcm","clk":"5322464963","pt":1646320531054,"mc":[{"id":"1.195532863","rc":[{"atb":[[1.64,0]],"id":8668222}],"con":true,"img":false}]}
{"op":"mcm","clk":"5322464976","pt":1646320531161,"mc":[{"id":"1.195532863","rc":[{"atb":[[1.69,4.14]],"id":8668222}],"con":true,"img":false}]}
{"op":"mcm","clk":"5322464993","pt":1646320531368,"mc":[{"id":"1.195532863","rc":[{"atb":[[1.53,0]],"id":28603683},{"atb":[[1.6,0]],"id":8668222},{"atb":[[1.18,0]],"id":28691352}],"con":true,"img":false}]}
{"op":"mcm","clk":"5322465094","pt":1646320532680,"mc":[{"id":"1.195532863","rc":[{"atb":[[1.31,0]],"id":28691352}],"con":true,"img":false}]}
{"op":"mcm","clk":"5322465102","pt":1646320532785,"mc":[{"id":"1.195532863","rc":[{"atb":[[1.34,1.99]],"id":28691352}],"con":true,"img":false}]}
{"op":"mcm","clk":"5322465343","pt":1646320535567,"mc":[{"id":"1.195532863","rc":[{"atb":[[1.53,11.99]],"id":28603683},{"atb":[[1.7,2.9]],"id":8668222},{"atb":[[1.31,4.14]],"id":28691352}],"con":true,"img":false}]}
{"op":"mcm","clk":"5322465365","pt":1646320535881,"mc":[{"id":"1.195532863","rc":[{"atb":[[1.69,2.15]],"id":8668222}],"con":true,"img":false}]}
{"op":"mcm","clk":"5322465375","pt":1646320535988,"mc":[{"id":"1.195532863","rc":[{"atb":[[1.71,1.99]],"id":8668222}],"con":true,"img":false}]}
{"op":"mcm","clk":"5322465413","pt":1646320536564,"mc":[{"id":"1.195532863","rc":[{"atb":[[2.18,1.65]],"id":35839928}],"con":true,"img":false}]}
{"op":"mcm","clk":"5322465491","pt":1646320537813,"mc":[{"id":"1.195532863","rc":[{"atb":[[1.98,4.32],[1.87,0]],"id":39693066},{"atl":[[14,5],[15,0]],"id":39693066},{"atb":[[1.8,4.32],[1.75,0]],"id":36042617},{"atl":[[9.8,0],[9.4,5]],"id":36042617},{"atb":[[2.28,2],[2.14,0]],"id":35839928},{"atl":[[21,3.7],[23,0]],"id":35839928},{"atb":[[1.64,0],[1.65,6.31]],"id":28603683},{"atb":[[1.74,2.16],[1.68,0]],"id":8668222},{"atl":[[8,5.13],[8.4,0]],"id":8668222},{"atb":[[1.3,0],[1.34,4.15]],"id":28691352},{"atl":[[4.8,9.09],[5.2,0]],"id":28691352}],"con":true,"img":false}]}
{"op":"mcm","clk":"5322465540","pt":1646320538491,"mc":[{"id":"1.195532863","rc":[{"atb":[[1.76,0]],"id":36042617}],"con":true,"img":false}]}
{"op":"mcm","clk":"5322465547","pt":1646320538598,"mc":[{"id":"1.195532863","rc":[{"atb":[[1.81,1.99]],"id":36042617}],"con":true,"img":false}]}
{"op":"mcm","clk":"5322465562","pt":1646320538810,"mc":[{"id":"1.195532863","rc":[{"atb":[[1.88,0]],"id":39693066}],"con":true,"img":false}]}
{"op":"mcm","clk":"5322465574","pt":1646320538912,"mc":[{"id":"1.195532863","rc":[{"atb":[[1.99,1.99]],"id":39693066}],"con":true,"img":false}]}
{"op":"mcm","clk":"5322465598","pt":1646320539177,"mc":[{"id":"1.195532863","rc":[{"atb":[[2.16,0]],"id":35839928}],"con":true,"img":false}]}
{"op":"mcm","clk":"5322465607","pt":1646320539284,"mc":[{"id":"1.195532863","rc":[{"atb":[[2.3,1.99]],"id":35839928}],"con":true,"img":false}]}
{"op":"mcm","clk":"5322465622","pt":1646320539491,"mc":[{"id":"1.195532863","rc":[{"atb":[[1.97,41.24],[1.85,0]],"id":39693066},{"atl":[[16,0],[15,2.86]],"id":39693066},{"atb":[[1.73,0],[1.79,50.63]],"id":36042617},{"atl":[[10.5,0],[9.8,4.55]],"id":36042617},{"atb":[[2.26,31.75],[2.1,0]],"id":35839928},{"atl":[[23,1.82],[25,0]],"id":35839928},{"atb":[[1.63,63.49],[1.62,0]],"id":28603683},{"atl":[[9,12.5],[9.4,4.76]],"id":28603683},{"atb":[[1.72,55.56],[1.66,0],[1.71,0]],"id":8668222},{"atl":[[8.8,0],[8.4,5.41]],"id":8668222},{"atb":[[1.28,0],[1.32,125]],"id":28691352},{"atl":[[5,10],[5.4,0]],"id":28691352}],"con":true,"img":false}]}
{"op":"mcm","clk":"5322465630","pt":1646320539594,"mc":[{"id":"1.195532863","rc":[{"atb":[[1.02,1.99]],"id":8668222},{"atb":[[1.27,16.55]],"id":28691352}],"con":true,"img":false}]}
{"op":"mcm","clk":"5322465644","pt":1646320539804,"mc":[{"id":"1.195532863","rc":[{"atb":[[1.27,0]],"id":28691352}],"con":true,"img":false}]}
{"op":"mcm","clk":"5322465767","pt":1646320541211,"mc":[{"id":"1.195532863","rc":[{"atb":[[1.53,0]],"id":28603683},{"atb":[[1.7,0]],"id":8668222},{"atb":[[1.31,0]],"id":28691352}],"con":true,"img":false}]}
{"op":"mcm","clk":"5322466050","pt":1646320544594,"mc":[{"id":"1.195532863","rc":[{"atb":[[2.18,0]],"id":35839928}],"con":true,"img":false}]}
{"op":"mcm","clk":"5322466066","pt":1646320544801,"mc":[{"id":"1.195532863","rc":[{"atb":[[2.32,1.65]],"id":35839928}],"con":true,"img":false}]}
{"op":"mcm","clk":"5322466129","pt":1646320545479,"mc":[{"id":"1.195532863","rc":[{"atb":[[1.53,12.61]],"id":28603683},{"atb":[[1.6,60.84]],"id":8668222},{"atb":[[1.18,9.95]],"id":28691352}],"con":true,"img":false}]}
{"op":"mcm","clk":"5322466201","pt":1646320546421,"mc":[{"id":"1.195532863","rc":[{"atb":[[2.32,3.65],[2.28,0]],"id":35839928}],"con":true,"img":false}]}
{"op":"mcm","clk":"5322466230","pt":1646320546689,"mc":[{"id":"1.195532863","rc":[{"atb":[[2.3,0]],"id":35839928}],"con":true,"img":false}]}
{"op":"mcm","clk":"5322466237","pt":1646320546798,"mc":[{"id":"1.195532863","rc":[{"atb":[[2.34,1.99]],"id":35839928}],"con":true,"img":false}]}
{"op":"mcm","clk":"5322466457","pt":1646320549499,"mc":[{"id":"1.195532863","rc":[{"atb":[[1.95,105.26]],"id":39693066},{"atl":[[16,6.67]],"id":39693066},{"atb":[[1.77,129.87]],"id":36042617},{"atl":[[10.5,10.53]],"id":36042617},{"atb":[[2.3,30.77],[2.26,0]],"id":35839928},{"atl":[[25,4.17]],"id":35839928},{"atb":[[1.61,163.93]],"id":28603683},{"atl":[[9.8,11.36]],"id":28603683},{"atb":[[1.7,142.86]],"id":8668222},{"atl":[[8.8,12.82]],"id":8668222},{"atb":[[1.3,250]],"id":28691352},{"atl":[[5.2,23.81]],"id":28691352}],"con":true,"img":false}]}
{"op":"mcm","clk":"5322466723","pt":1646320552586,"mc":[{"id":"1.195532863","rc":[{"spn":7.99,"spf":"NaN","id":39693066},{"spn":1.79,"spf":1.0,"id":36042617},{"atb":[[2.32,2]],"id":35839928},{"spn":11.67,"spf":"NaN","id":35839928},{"spn":5.32,"spf":"NaN","id":28603683},{"spn":4.87,"spf":"NaN","id":8668222},{"spn":1.33,"spf":1.0,"id":28691352}],"con":true,"img":false}]}
{"op":"mcm","clk":"5322466744","pt":1646320552795,"mc":[{"id":"1.195532863","rc":[{"atb":[[1.01,4804.04]],"id":39693066},{"atl":[[20,0]],"id":39693066},{"atb":[[1.01,4804.04]],"id":36042617},{"atl":[[15.5,0]],"id":36042617},{"atb":[[2.36,1.65]],"id":35839928},{"atl":[[34,0],[28,0],[30,0]],"id":35839928},{"atb":[[1.5,0],[1.52,0]],"id":28603683},{"atb":[[1.59,0],[1.01,4804.04],[1.57,0]],"id":8668222},{"atl":[[10.5,0],[11.5,0],[12.5,0]],"id":8668222}],"con":true,"img":false}]}
{"op":"mcm","clk":"5322466753","pt":1646320552898,"mc":[{"id":"1.195532863","rc":[{"atb":[[2.36,3.65]],"id":35839928}],"con":true,"img":false}]}
{"op":"mcm","clk":"5322466761","pt":1646320553003,"mc":[{"id":"1.195532863","rc":[{"atb":[[2.32,0]],"id":35839928}],"con":true,"img":false}]}
{"op":"mcm","clk":"5322466775","pt":1646320553213,"mc":[{"id":"1.195532863","rc":[{"atb":[[1.53,0]],"id":28603683},{"atb":[[1.6,0]],"id":8668222},{"atb":[[1.18,0]],"id":28691352}],"con":true,"img":false}]}
{"op":"mcm","clk":"5322466784","pt":1646320553318,"mc":[{"id":"1.195532863","rc":[{"atb":[[2.34,0]],"id":35839928}],"con":true,"img":false}]}
{"op":"mcm","clk":"5322466792","pt":1646320553425,"mc":[{"id":"1.195532863","rc":[{"atb":[[2.3,0],[2.32,30.3],[2.38,1.99]],"id":35839928}],"con":true,"img":false}]}
{"op":"mcm","clk":"5322467145","pt":1646320557424,"mc":[{"id":"1.195532863","rc":[{"atb":[[1.66,4.41]],"id":28603683},{"atb":[[1.03,444.44]],"id":8668222},{"atb":[[1.35,2.9]],"id":28691352}],"con":true,"img":false}]}
{"op":"mcm","clk":"5322467157","pt":1646320557529,"mc":[{"id":"1.195532863","rc":[{"atb":[[1.67,6.31],[1.65,1.99]],"id":28603683}],"con":true,"img":false}]}
{"op":"mcm","clk":"5322467185","pt":1646320557842,"mc":[{"id":"1.195532863","rc":[{"atb":[[1.65,0]],"id":28603683}],"con":true,"img":false}]}
{"op":"mcm","clk":"5322467192","pt":1646320557895,"mc":[{"id":"1.195532863","rc":[{"atb":[[1.68,1.99]],"id":28603683}],"con":true,"img":false}]}
{"op":"mcm","clk":"5322467203","pt":1646320558000,"mc":[{"id":"1.195532863","rc":[{"atb":[[1.34,2.16]],"id":28691352}],"con":true,"img":false}]}
{"op":"mcm","clk":"5322467214","pt":1646320558103,"mc":[{"id":"1.195532863","rc":[{"atb":[[1.36,1.99]],"id":28691352}],"con":true,"img":false}]}
{"op":"mcm","clk":"5322467224","pt":1646320558208,"mc":[{"id":"1.195532863","rc":[{"atb":[[1.36,4.15],[1.34,0]],"id":28691352}],"con":true,"img":false}]}
{"op":"mcm","clk":"5322467231","pt":1646320558313,"mc":[{"id":"1.195532863","rc":[{"atb":[[1.56,0],[1.69,2.15]],"id":28603683}],"con":true,"img":false}]}
{"op":"mcm","clk":"5322467302","pt":1646320559100,"mc":[{"id":"1.195532863","rc":[{"atb":[[1.68,0]],"id":28603683}],"con":true,"img":false}]}
{"op":"mcm","clk":"5322467311","pt":1646320559253,"mc":[{"id":"1.195532863","rc":[{"atb":[[1.7,1.99]],"id":28603683}],"con":true,"img":false}]}
{"op":"mcm","clk":"5322467333","pt":1646320559416,"mc":[{"id":"1.195532863","rc":[{"atl":[[14,0],[14.5,7.41]],"id":39693066},{"atb":[[2.32,0],[2.34,29.85]],"id":35839928},{"atb":[[1.68,58.82]],"id":28603683},{"atb":[[1.73,55.56],[1.74,0]],"id":8668222},{"atl":[[8,0],[7.8,5.41]],"id":8668222},{"atb":[[1.32,0],[1.34,117.65]],"id":28691352},{"atl":[[7.4,0],[7,0],[7.8,0]],"id":28691352}],"con":true,"img":false}]}
{"op":"mcm","clk":"5322467341","pt":1646320559517,"mc":[{"id":"1.195532863","rc":[{"atb":[[1.93,161.29]],"id":39693066},{"atl":[[17,9.38]],"id":39693066},{"atb":[[1.75,200]],"id":36042617},{"atl":[[11.5,14.29]],"id":36042617},{"atb":[[1.68,220.59]],"id":8668222},{"atl":[[9.2,18.29]],"id":8668222}],"con":true,"img":false}]}
{"op":"mcm","clk":"5322467413","pt":1646320560207,"mc":[{"id":"1.195532863","rc":[{"atb":[[2.4,8.24],[1.95,122.86]],"id":39693066},{"atl":[[16,20.73],[9.2,8.24]],"id":39693066},{"atb":[[1.77,150.92],[2.34,7.16]],"id":36042617},{"atl":[[8,7.16],[10.5,31.95]],"id":36042617},{"atb":[[2.8,5.52],[1.94,11.99]],"id":35839928},{"atl":[[11.5,5.52],[25,13.16]],"id":35839928},{"atb":[[1.67,28.4],[2.2,12.09]],"id":28603683},{"atl":[[9.8,34.31],[7.8,11.76]],"id":28603683},{"atb":[[1.7,228.34],[2.14,38.38]],"id":8668222},{"atl":[[7.2,12.9],[8.8,38.38]],"id":8668222},{"atb":[[1.37,14.32],[1.34,141.51]],"id":28691352},{"atl":[[3.8,14.32],[5.2,61.99]],"id":28691352}],"con":true,"img":false}]}
{"op":"mcm","clk":"5322467421","pt":1646320560310,"mc":[{"id":"1.195532863","rc":[{"atb":[[2.54,5],[1.98,0],[2.62,2.5],[2.42,4.32],[2.46,10]],"id":39693066},{"atl":[[6.2,2.5],[7,5],[7.8,10]],"id":39693066},{"atb":[[2.3,2.5],[2.22,5],[2.14,10],[2.36,4.32],[1.8,0]],"id":36042617},{"atl":[[6.2,10],[5.3,2.5],[5.7,5],[7.8,5],[9.4,0]],"id":36042617},{"atb":[[2.6,9.2]],"id":35839928},{"atl":[[11,3.7]],"id":35839928},{"atl":[[9,0],[7.6,11.76]],"id":28603683},{"atb":[[1.36,1.99],[1.38,4.15]],"id":28691352},{"atl":[[4.8,0],[3.75,10]],"id":28691352}],"con":true,"img":false}]}
{"op":"mcm","clk":"5322467436","pt":1646320560460,"mc":[{"id":"1.195532863","rc":[{"atl":[[8,0],[5.2,6.99]],"id":36042617},{"atb":[[2.9,10],[3.15,2.5],[2.98,5]],"id":35839928},{"atl":[[9,5],[21,0],[10.5,6.91],[8.2,2.5],[11.5,0],[9.8,10]],"id":35839928},{"atb":[[2.3,2.5],[2.22,5],[2.14,10]],"id":28603683},{"atl":[[5.5,2.5],[7.4,10.44],[7.8,0],[6.6,10],[5.9,5]],"id":28603683},{"atb":[[2.02,10],[2.18,2.5],[2.1,5]],"id":8668222},{"atl":[[4.8,2.5],[5.6,10],[5.2,5]],"id":8668222},{"atb":[[1.59,10],[1.63,5],[1.67,2.5]],"id":28691352},{"atl":[[3.85,5],[4.1,10],[3.65,2.5]],"id":28691352}],"con":true,"img":false}]}
{"op":"mcm","clk":"5322467442","pt":1646320560517,"mc":[{"id":"1.195532863","rc":[{"atb":[[2.42,0],[2.46,18.24],[2.2,12.13]],"id":39693066},{"atb":[[1.97,16.12]],"id":8668222},{"atb":[[1.36,20.46],[1.38,0]],"id":28691352},{"atl":[[4.8,24.32],[3.75,0]],"id":28691352}],"con":true,"img":false}]}
{"op":"mcm","clk":"5322467452","pt":1646320560623,"mc":[{"id":"1.195532863","rc":[{"atb":[[2.2,0]],"id":39693066},{"atb":[[2.36,2],[2.6,0]],"id":35839928},{"atl":[[11,0],[9.8,13.7]],"id":35839928},{"atb":[[1.97,0]],"id":8668222}],"con":true,"img":false}]}
{"op":"mcm","clk":"5322467473","pt":1646320560834,"mc":[{"id":"1.195532863","rc":[{"atb":[[2.64,1.65]],"id":39693066},{"atb":[[2.38,1.65]],"id":36042617},{"atb":[[2.82,1.65]],"id":35839928},{"atb":[[2.22,6.65]],"id":28603683},{"atb":[[2.16,1.65]],"id":8668222}],"con":true,"img":false}]}
{"op":"mcm","clk":"5322467491","pt":1646320561043,"mc":[{"id":"1.195532863","rc":[{"atb":[[1.81,0]],"id":36042617},{"atb":[[1.66,0]],"id":28603683},{"atb":[[1.35,0]],"id":28691352}],"con":true,"img":false}]}
{"op":"mcm","clk":"5322467501","pt":1646320561100,"mc":[{"id":"1.195532863","rc":[{"atb":[[2.38,3.64]],"id":36042617}],"con":true,"img":false}]}
{"op":"mcm","clk":"5322467523","pt":1646320561307,"mc":[{"id":"1.195532863","rc":[{"atb":[[2.36,0],[2.9,17.5]],"id":35839928}],"con":true,"img":false}]}
{"op":"mcm","clk":"5322467530","pt":1646320561412,"mc":[{"id":"1.195532863","rc":[{"atb":[[1.99,0]],"id":39693066}],"con":true,"img":false}]}
{"op":"mcm","clk":"5322467538","pt":1646320561518,"mc":[{"id":"1.195532863","rc":[{"atb":[[2.64,3.64]],"id":39693066}],"con":true,"img":false}]}
{"op":"mcm","clk":"5322467567","pt":1646320561832,"mc":[{"id":"1.195532863","rc":[{"atb":[[1.7,0]],"id":28603683}],"con":true,"img":false}]}
{"op":"mcm","clk":"5322467577","pt":1646320561936,"mc":[{"id":"1.195532863","rc":[{"atb":[[2.32,1.99]],"id":28603683}],"con":true,"img":false}]}
{"op":"mcm","clk":"5322467596","pt":1646320562147,"mc":[{"id":"1.195532863","rc":[{"atb":[[2.38,0]],"id":35839928}],"con":true,"img":false}]}
{"op":"mcm","clk":"5322467607","pt":1646320562198,"mc":[{"id":"1.195532863","rc":[{"atb":[[3.2,1.99]],"id":35839928}],"con":true,"img":false}]}
{"op":"mcm","clk":"5322467626","pt":1646320562410,"mc":[{"id":"1.195532863","rc":[{"atb":[[1.36,18.47]],"id":28691352}],"con":true,"img":false}]}
{"op":"mcm","clk":"5322467635","pt":1646320562513,"mc":[{"id":"1.195532863","rc":[{"atb":[[1.68,1.99]],"id":28691352}],"con":true,"img":false}]}
{"op":"mcm","clk":"5322467676","pt":1646320563143,"mc":[{"id":"1.195532863","rc":[{"atb":[[1.03,0]],"id":8668222}],"con":true,"img":false}]}
{"op":"mcm","clk":"5322467842","pt":1646320565238,"mc":[{"id":"1.195532863","rc":[{"atb":[[2.24,4.93]],"id":28603683},{"atb":[[1.6,6.73]],"id":28691352}],"con":true,"img":false}]}
{"op":"mcm","clk":"5322467878","pt":1646320565813,"mc":[{"id":"1.195532863","rc":[{"atb":[[2.1,28.4]],"id":28603683}],"con":true,"img":false}]}
{"op":"mcm","clk":"5322467888","pt":1646320565917,"mc":[{"id":"1.195532863","rc":[{"atb":[[1.67,22.09]],"id":28603683}],"con":true,"img":false}]}
{"op":"mcm","clk":"5322468059","pt":1646320567612,"mc":[{"id":"1.195532863","rc":[{"atb":[[1.2,2.24]],"id":8668222}],"con":true,"img":false}]}
{"op":"mcm","clk":"5322468072","pt":1646320567719,"mc":[{"id":"1.195532863","rc":[{"atb":[[1.86,9.38]],"id":8668222}],"con":true,"img":false}]}
{"op":"mcm","clk":"5322468083","pt":1646320567828,"mc":[{"id":"1.195532863","rc":[{"atl":[[7.8,18.24],[14.5,0]],"id":39693066},{"atb":[[1.73,0],[2.16,6.65]],"id":8668222},{"atl":[[5.6,20],[7.8,0]],"id":8668222}],"con":true,"img":false}]}
{"op":"mcm","clk":"5322468095","pt":1646320567936,"mc":[{"id":"1.195532863","rc":[{"atb":[[1.2,1.75],[1.86,0]],"id":8668222}],"con":true,"img":false}]}
{"op":"mcm","clk":"5322468134","pt":1646320568356,"mc":[{"id":"1.195532863","rc":[{"atb":[[1.2,0]],"id":8668222}],"con":true,"img":false}]}
{"op":"mcm","clk":"5322468144","pt":1646320568410,"mc":[{"id":"1.195532863","rc":[{"atb":[[2.2,1.75]],"id":8668222}],"con":true,"img":false}]}
{"op":"mcm","clk":"5322468162","pt":1646320568616,"mc":[{"id":"1.195532863","rc":[{"atb":[[2.82,0]],"id":35839928},{"atb":[[2.22,5]],"id":28603683},{"atb":[[2.16,5]],"id":8668222}],"con":true,"img":false}]}
{"op":"mcm","clk":"5322468170","pt":1646320568724,"mc":[{"id":"1.195532863","rc":[{"atb":[[2.36,0],[2.4,4.32]],"id":36042617},{"atl":[[5.7,14.49],[7.8,0]],"id":36042617},{"atl":[[7.6,0],[6.6,20.44]],"id":28603683}],"con":true,"img":false}]}
{"op":"mcm","clk":"5322468181","pt":1646320568839,"mc":[{"id":"1.195532863","rc":[{"atb":[[2.46,10],[2.66,3.65]],"id":39693066},{"atb":[[3.25,1.65]],"id":35839928},{"atb":[[2.34,1.65]],"id":28603683},{"atl":[[5.9,10.21]],"id":28603683},{"atb":[[2.2,3.4]],"id":8668222},{"atb":[[1.68,4.49],[1.36,0]],"id":28691352},{"atl":[[4.8,0],[3.85,21.82],[3.95,8.62]],"id":28691352}],"con":true,"img":false}]}
{"op":"mcm","clk":"5322468193","pt":1646320568939,"mc":[{"id":"1.195532863","rc":[{"atb":[[1.69,0],[2.28,2.15]],"id":28603683}],"con":true,"img":false}]}
{"op":"mcm","clk":"5322468212","pt":1646320569151,"mc":[{"id":"1.195532863","rc":[{"atb":[[1.67,0]],"id":28603683}],"con":true,"img":false}]}
{"op":"mcm","clk":"5322468241","pt":1646320569416,"mc":[{"id":"1.195532863","rc":[{"atb":[[2.68,23.81],[2.34,0]],"id":35839928},{"atl":[[8.6,5.26]],"id":35839928},{"atb":[[1.68,0],[2.1,64.76]],"id":28603683},{"atl":[[5.7,8.51]],"id":28603683},{"atb":[[1.34,23.86],[1.66,60.61]],"id":28691352},{"atl":[[3.75,14.55]],"id":28691352}],"con":true,"img":false}]}
{"op":"mcm","clk":"5322468249","pt":1646320569519,"mc":[{"id":"1.195532863","rc":[{"atb":[[2.3,30.77],[1.97,0]],"id":39693066},{"atl":[[16,14.06],[17,0],[18,0],[19,0],[6.6,7.14],[15,0]],"id":39693066},{"atb":[[2.26,31.75],[1.79,0],[2.38,1.65]],"id":36042617},{"atl":[[10.5,21.42],[11.5,0],[9.8,0],[13.5,0],[14.5,0],[5.4,9.09]],"id":36042617},{"atl":[[9.8,10],[8.4,5.26]],"id":35839928},{"atb":[[2.04,38.46]],"id":8668222},{"atl":[[5,10]],"id":8668222}],"con":true,"img":false}]}
{"op":"mcm","clk":"5322468257","pt":1646320569624,"mc":[{"id":"1.195532863","rc":[{"atl":[[6.4,7.14],[7.8,10]],"id":39693066},{"atb":[[2.42,1.99]],"id":36042617},{"atl":[[5.3,16.48],[5.7,5]],"id":36042617},{"atb":[[3.2,5.31],[2.9,10]],"id":35839928}],"con":true,"img":false}]}
{"op":"mcm","clk":"5322468264","pt":1646320569731,"mc":[{"id":"1.195532863","rc":[{"atl":[[8,5]],"id":39693066}],"con":true,"img":false}]}
{"op":"mcm","clk":"5322468273","pt":1646320569836,"mc":[{"id":"1.195532863","rc":[{"atb":[[2.64,1.65]],"id":39693066}],"con":true,"img":false}]}
{"op":"mcm","clk":"5322468282","pt":1646320569940,"mc":[{"id":"1.195532863","rc":[{"atb":[[2.68,1.99]],"id":39693066}],"con":true,"img":false}]}
{"op":"mcm","clk":"5322468341","pt":1646320570724,"mc":[{"id":"1.195532863","rc":[{"atl":[[8,0]],"id":39693066},{"atl":[[5.9,5]],"id":28603683},{"atl":[[3.95,0]],"id":28691352}],"con":true,"img":false}]}
{"op":"mcm","clk":"5322468440","pt":1646320571929,"mc":[{"id":"1.195532863","rc":[{"atb":[[2.24,0]],"id":28603683},{"atb":[[1.6,0]],"id":28691352}],"con":true,"img":false}]}
{"op":"mcm","clk":"5322468660","pt":1646320574643,"mc":[{"id":"1.195532863","rc":[{"atl":[[8.6,13.02],[8.4,0]],"id":35839928}],"con":true,"img":false}]}
{"op":"mcm","clk":"5322468679","pt":1646320574851,"mc":[{"id":"1.195532863","rc":[{"atl":[[6.4,0],[6.6,16.78]],"id":39693066},{"atl":[[5.3,2.5],[5.4,31.82]],"id":36042617},{"atl":[[8.6,5.26],[9,17.5]],"id":35839928}],"con":true,"img":false}]}
{"op":"mcm","clk":"5322468799","pt":1646320576159,"mc":[{"id":"1.195532863","rc":[{"atb":[[2.24,4.37]],"id":28603683},{"atb":[[2.22,3.41],[2.16,0]],"id":8668222},{"atl":[[5.6,10],[5.2,17.9]],"id":8668222},{"atb":[[1.69,3.14]],"id":28691352}],"con":true,"img":false}]}
{"op":"mcm","clk":"5322468843","pt":1646320576632,"mc":[{"id":"1.195532863","rc":[{"atb":[[2.64,0]],"id":39693066},{"atb":[[2.38,0]],"id":36042617},{"atb":[[2.2,1.75]],"id":8668222},{"atb":[[1.68,2.5]],"id":28691352}],"con":true,"img":false}]}
{"op":"mcm","clk":"5322468850","pt":1646320576732,"mc":[{"id":"1.195532863","rc":[{"atb":[[1.7,1.99]],"id":28691352}],"con":true,"img":false}]}
{"op":"mcm","clk":"5322468857","pt":1646320576836,"mc":[{"id":"1.195532863","rc":[{"atb":[[2.7,1.65]],"id":39693066},{"atb":[[2.44,1.65]],"id":36042617},{"atb":[[2.24,1.65]],"id":8668222}],"con":true,"img":false}]}
{"op":"mcm","clk":"5322468864","pt":1646320576942,"mc":[{"id":"1.195532863","rc":[{"atl":[[5.7,9.74]],"id":36042617}],"con":true,"img":false}]}
{"op":"mcm","clk":"5322468872","pt":1646320577048,"mc":[{"id":"1.195532863","rc":[{"atl":[[6.6,10],[5.9,16.01]],"id":28603683}],"con":true,"img":false}]}
{"op":"mcm","clk":"5322468878","pt":1646320577153,"mc":[{"id":"1.195532863","rc":[{"atb":[[2.66,0],[2.7,3.65]],"id":39693066},{"atb":[[1.7,4.49],[1.68,0]],"id":28691352}],"con":true,"img":false}]}
{"op":"mcm","clk":"5322468913","pt":1646320577627,"mc":[{"id":"1.195532863","rc":[{"atb":[[2.68,0]],"id":39693066}],"con":true,"img":false}]}
{"op":"mcm","clk":"5322468923","pt":1646320577736,"mc":[{"id":"1.195532863","rc":[{"atb":[[2.72,1.99]],"id":39693066},{"atl":[[5.7,5]],"id":36042617}],"con":true,"img":false}]}
{"op":"mcm","clk":"5322468940","pt":1646320577838,"mc":[{"id":"1.195532863","rc":[{"atb":[[2.54,15.82],[1.95,105.26],[2.7,10.15]],"id":39693066},{"atl":[[16,0],[6,6.5],[7,22.32]],"id":39693066},{"atb":[[2.34,28.17],[2.42,7.11],[1.77,129.87]],"id":36042617},{"atl":[[10.5,0],[5.4,54.44]],"id":36042617},{"atb":[[3.2,11.13],[2.98,17.82],[1.94,2.15]],"id":35839928},{"atl":[[8,5.82],[9,38.02],[25,4.17]],"id":35839928},{"atl":[[5.1,3.75],[9.8,11.36],[5.9,28.31]],"id":28603683},{"atb":[[2.22,7.84],[1.7,142.86],[2.14,57.22]],"id":8668222},{"atl":[[5.2,48.04],[8.8,12.82],[4.7,4.43]],"id":8668222},{"atb":[[1.34,0],[1.8,5.72],[1.67,12.04]],"id":28691352},{"atl":[[3.6,5.72],[3.8,29.58],[5.2,23.81]],"id":28691352}],"con":true,"img":false}]}
{"op":"mcm","clk":"5322468957","pt":1646320578046,"mc":[{"id":"1.195532863","rc":[{"atb":[[2.4,0]],"id":39693066},{"atl":[[9.2,0]],"id":39693066},{"atb":[[2.34,21.01]],"id":36042617},{"atb":[[2.8,0]],"id":35839928},{"atl":[[10.5,0],[8.8,3.22],[7.8,5.82]],"id":35839928},{"atl":[[5,3.75],[7.4,0]],"id":28603683},{"atb":[[2.14,18.83]],"id":8668222},{"atl":[[7.2,0]],"id":8668222},{"atb":[[1.37,0]],"id":28691352},{"atl":[[3.85,5],[3.8,15.26],[3.55,5.72]],"id":28691352}],"con":true,"img":false}]}
{"op":"mcm","clk":"5322468990","pt":1646320578359,"mc":[{"id":"1.195532863","rc":[{"atl":[[8,0]],"id":35839928},{"atl":[[5.1,0]],"id":28603683}],"con":true,"img":false}]}
{"op":"mcm","clk":"5322469013","pt":1646320578517,"mc":[{"id":"1.195532863","rc":[{"atb":[[1.7,2.5]],"id":28691352}],"con":true,"img":false}]}
{"op":"mcm","clk":"5322469021","pt":1646320578673,"mc":[{"id":"1.195532863","rc":[{"atb":[[1.81,1.99]],"id":28691352}],"con":true,"img":false}]}
{"op":"mcm","clk":"5322469039","pt":1646320578828,"mc":[{"id":"1.195532863","rc":[{"atb":[[2.34,14.14]],"id":36042617},{"atl":[[8.8,0]],"id":35839928}],"con":true,"img":false}]}
{"op":"mcm","clk":"5322469087","pt":1646320579459,"mc":[{"id":"1.195532863","rc":[{"atb":[[2.64,60.98]],"id":35839928},{"atl":[[8.2,8.06]],"id":35839928},{"atb":[[2.06,94.34]],"id":28603683},{"atl":[[5.2,9.52]],"id":28603683},{"atb":[[1.72,55.56],[1.66,0],[1.65,7.58]],"id":28691352},{"atl":[[3.65,17.59]],"id":28691352}],"con":true,"img":false}]}
{"op":"mcm","clk":"5322469101","pt":1646320579563,"mc":[{"id":"1.195532863","rc":[{"atb":[[1.73,0],[2.26,79.37]],"id":39693066},{"atl":[[6.4,7.41]],"id":39693066},{"atb":[[2.22,86.97],[1.63,0]],"id":36042617},{"atl":[[5.6,21.74]],"id":36042617},{"atb":[[2,100]],"id":8668222},{"atl":[[5.1,5],[5,0],[4.9,10.26]],"id":8668222}],"con":true,"img":false}]}
{"op":"mcm","clk":"5322469110","pt":1646320579668,"mc":[{"id":"1.195532863","rc":[{"atb":[[1.69,0],[2.46,2.15]],"id":36042617},{"atb":[[2.26,2.15],[1.69,0]],"id":8668222},{"atb":[[1.73,2.15],[1.33,0]],"id":28691352}],"con":true,"img":false}]}
{"op":"mcm","clk":"5322469143","pt":1646320580065,"mc":[{"id":"1.195532863","rc":[{"atb":[[1.65,0]],"id":28691352}],"con":true,"img":false}]}
{"op":"mcm","clk":"5322469160","pt":1646320580225,"mc":[{"id":"1.195532863","rc":[{"atb":[[2.2,0]],"id":8668222},{"atb":[[1.69,0]],"id":28691352}],"con":true,"img":false}]}
{"op":"mcm","clk":"5322469171","pt":1646320580335,"mc":[{"id":"1.195532863","rc":[{"atb":[[2.42,5.12]],"id":36042617}],"con":true,"img":false}]}
{"op":"mcm","clk":"5322469181","pt":1646320580436,"mc":[{"id":"1.195532863","rc":[{"atb":[[2.48,1.99]],"id":36042617}],"con":true,"img":false}]}
{"op":"mcm","clk":"5322469224","pt":1646320580957,"mc":[{"id":"1.195532863","rc":[{"atl":[[5.1,0]],"id":8668222}],"con":true,"img":false}]}
{"op":"mcm","clk":"5322469322","pt":1646320582365,"mc":[{"id":"1.195532863","rc":[{"atb":[[2.24,0]],"id":28603683}],"con":true,"img":false}]}
{"op":"mcm","clk":"5322469373","pt":1646320583044,"mc":[{"id":"1.195532863","rc":[{"atl":[[8.6,18.42],[9,25.52]],"id":35839928}],"con":true,"img":false}]}
{"op":"mcm","clk":"5322469392","pt":1646320583253,"mc":[{"id":"1.195532863","rc":[{"atl":[[3.55,0],[3.65,32.85]],"id":28691352}],"con":true,"img":false}]}
{"op":"mcm","clk":"5322469472","pt":1646320584350,"mc":[{"id":"1.195532863","rc":[{"atb":[[2.22,4.43],[2.26,4.31]],"id":8668222},{"atl":[[4.9,20.52],[5.2,35.14]],"id":8668222}],"con":true,"img":false}]}
{"op":"mcm","clk":"5322469493","pt":1646320584662,"mc":[{"id":"1.195532863","rc":[{"atb":[[2.7,8.5]],"id":39693066},{"atb":[[2.44,0]],"id":36042617},{"atb":[[2.26,6.98],[2.24,0]],"id":8668222},{"atb":[[1.73,13.71]],"id":28691352}],"con":true,"img":false}]}
{"op":"mcm","clk":"5322469505","pt":1646320584874,"mc":[{"id":"1.195532863","rc":[{"atb":[[2.74,1.65]],"id":39693066},{"atb":[[2.5,1.65]],"id":36042617},{"atb":[[2.28,1.65]],"id":8668222}],"con":true,"img":false}]}
{"op":"mcm","clk":"5322469526","pt":1646320585138,"mc":[{"id":"1.195532863","rc":[{"atl":[[5.5,15.77]],"id":28603683}],"con":true,"img":false}]}
{"op":"mcm","clk":"5322469532","pt":1646320585240,"mc":[{"id":"1.195532863","rc":[{"atb":[[2.74,3.65]],"id":39693066},{"atl":[[5.9,17.3]],"id":28603683}],"con":true,"img":false}]}
{"op":"mcm","clk":"5322469541","pt":1646320585346,"mc":[{"id":"1.195532863","rc":[{"atb":[[2.7,6.5]],"id":39693066}],"con":true,"img":false}]}
{"op":"mcm","clk":"5322469595","pt":1646320585971,"mc":[{"id":"1.195532863","rc":[{"atb":[[2.72,0]],"id":39693066}],"con":true,"img":false}]}
{"op":"mcm","clk":"5322469603","pt":1646320586074,"mc":[{"id":"1.195532863","rc":[{"atb":[[2.76,1.99]],"id":39693066}],"con":true,"img":false}]}
{"op":"mcm","clk":"5322469654","pt":1646320586861,"mc":[{"id":"1.195532863","rc":[{"atb":[[2.24,4.37]],"id":28603683}],"con":true,"img":false}]}
{"op":"mcm","clk":"5322469815","pt":1646320588479,"mc":[{"id":"1.195532863","rc":[{"atl":[[3.65,17.59],[3.75,50.91]],"id":28691352}],"con":true,"img":false}]}
{"op":"mcm","clk":"5322469896","pt":1646320589468,"mc":[{"id":"1.195532863","rc":[{"atb":[[2.22,122.95],[1.75,0]],"id":39693066},{"atl":[[6.8,17.24]],"id":39693066},{"atb":[[1.01,4804.04],[2.6,93.75]],"id":35839928},{"atl":[[8.6,26.32]],"id":35839928},{"atb":[[1.01,4804.04],[2.02,147.06]],"id":28603683},{"atl":[[5.4,22.73]],"id":28603683},{"atb":[[1.98,153.06]],"id":8668222},{"atl":[[5.1,24.39]],"id":8668222},{"atb":[[1.7,145.36],[1.15,0],[1.13,0],[1.17,0]],"id":28691352},{"atl":[[3.7,14.81],[3.65,2.5]],"id":28691352}],"con":true,"img":false}]}
{"op":"mcm","clk":"5322469904","pt":1646320589571,"mc":[{"id":"1.195532863","rc":[{"atb":[[2.18,127.12],[1.65,0]],"id":36042617},{"atl":[[5.8,31.25]],"id":36042617},{"atb":[[1.68,0]],"id":8668222}],"con":true,"img":false}]}
{"op":"mcm","clk":"5322470146","pt":1646320592562,"mc":[{"id":"1.195532863","rc":[{"atb":[[2.74,2]],"id":39693066}],"con":true,"img":false}]}
{"op":"mcm","clk":"5322470166","pt":1646320592770,"mc":[{"id":"1.195532863","rc":[{"atb":[[2.78,1.65]],"id":39693066}],"con":true,"img":false}]}
{"op":"mcm","clk":"5322470337","pt":1646320595077,"mc":[{"id":"1.195532863","rc":[{"atb":[[2.54,5],[2.76,5.37],[2.7,19.19]],"id":39693066},{"atl":[[6.4,27.71],[7,5]],"id":39693066},{"atb":[[2.48,5.49],[2.34,0],[2.42,16.08]],"id":36042617},{"atl":[[8.6,55.37],[9,5]],"id":35839928},{"atl":[[5.9,5],[5.4,37.53]],"id":28603683},{"atb":[[2.26,13.62],[2.14,0],[2.18,13.58]],"id":8668222},{"atl":[[4.9,38.24],[5.2,5]],"id":8668222},{"atb":[[1.72,82.35],[1.67,2.5]],"id":28691352},{"atl":[[3.7,57.67],[3.8,0],[3.55,8.58]],"id":28691352}],"con":true,"img":false}]}
{"op":"mcm","clk":"5322470347","pt":1646320595183,"mc":[{"id":"1.195532863","rc":[{"atb":[[2.7,12.69]],"id":39693066},{"atl":[[6.2,19.28]],"id":39693066},{"atb":[[2.42,10.96]],"id":36042617},{"atl":[[5.3,15.77]],"id":28603683},{"atb":[[2.22,0]],"id":8668222},{"atl":[[3.6,0]],"id":28691352}],"con":true,"img":false}]}
{"op":"mcm","clk":"5322470355","pt":1646320595288,"mc":[{"id":"1.195532863","rc":[{"atl":[[6.4,44.95],[6.2,2.5],[6.6,7.14]],"id":39693066},{"atl":[[5.3,0],[5.5,2.5],[5.4,53.3]],"id":28603683}],"con":true,"img":false}]}
{"op":"mcm","clk":"5322470600","pt":1646320598265,"mc":[{"id":"1.195532863","rc":[{"atb":[[2.26,10.95]],"id":8668222}],"con":true,"img":false}]}
{"op":"mcm","clk":"5322470702","pt":1646320599472,"mc":[{"id":"1.195532863","rc":[{"atb":[[1.93,0],[2.18,211.86]],"id":39693066},{"atl":[[7.2,24.19]],"id":39693066},{"atb":[[2.14,229.3],[1.75,0]],"id":36042617},{"atl":[[6,50]],"id":36042617},{"atb":[[2.56,160.26],[1.88,0]],"id":35839928},{"atl":[[9,23.75]],"id":35839928},{"atb":[[1.99,250],[1.61,0]],"id":28603683},{"atl":[[5.6,32.61],[9.8,0],[5.7,0],[9.4,0]],"id":28603683},{"atb":[[1.7,0],[1.96,250]],"id":8668222},{"atl":[[9.2,0],[5.3,34.88],[8.8,0],[8.4,0]],"id":8668222},{"atb":[[1.68,220.59]],"id":28691352},{"atl":[[3.7,42.86],[3.65,17.59]],"id":28691352}],"con":true,"img":false}]}
{"op":"mcm","clk":"5322470713","pt":1646320599574,"mc":[{"id":"1.195532863","rc":[{"atl":[[3.6,38.46],[3.75,14.55]],"id":28691352}],"con":true,"img":false}]}
{"op":"mcm","clk":"5322470720","pt":1646320599676,"mc":[{"id":"1.195532863","rc":[{"atl":[[3.65,55.33]],"id":28691352}],"con":true,"img":false}]}
{"op":"mcm","clk":"5322470729","pt":1646320599786,"mc":[{"id":"1.195532863","rc":[{"atl":[[3.6,0]],"id":28691352}],"con":true,"img":false}]}
{"op":"mcm","clk":"5322470961","pt":1646320602757,"mc":[{"id":"1.195532863","rc":[{"atb":[[2.12,18.91]],"id":8668222}],"con":true,"img":false}]}
{"op":"mcm","clk":"5322470988","pt":1646320603103,"mc":[{"id":"1.195532863","rc":[{"atb":[[2.12,51.66],[2.18,2.5]],"id":8668222}],"con":true,"img":false}]}
{"op":"mcm","clk":"5322471469","pt":1646320609484,"mc":[{"id":"1.195532863","rc":[{"atb":[[1.95,0]],"id":39693066},{"atl":[[7.6,37.88]],"id":39693066},{"atb":[[1.9,0]],"id":35839928},{"atl":[[25,0],[9.4,29.76]],"id":35839928},{"atb":[[1.63,0]],"id":28603683},{"atl":[[5.8,52.08]],"id":28603683},{"atb":[[1.72,0]],"id":8668222},{"atl":[[5.5,55.56]],"id":8668222},{"atb":[[1.66,250]],"id":28691352},{"atl":[[3.8,7.27],[3.75,36.36]],"id":28691352}],"con":true,"img":false}]}
{"op":"mcm","clk":"5322471476","pt":1646320609587,"mc":[{"id":"1.195532863","rc":[{"atb":[[1.77,0]],"id":36042617},{"atl":[[3.7,79.9],[3.8,0],[3.65,17.59]],"id":28691352}],"con":true,"img":false}]}
{"op":"mcm","clk":"5322471575","pt":1646320610897,"mc":[{"id":"1.195532863","rc":[{"atb":[[2.3,8.31]],"id":36042617}],"con":true,"img":false}]}
{"op":"mcm","clk":"5322471584","pt":1646320610999,"mc":[{"id":"1.195532863","rc":[{"atb":[[2.3,2.5]],"id":36042617}],"con":true,"img":false}]}
{"op":"mcm","clk":"5322471676","pt":1646320611993,"mc":[{"id":"1.195532863","rc":[{"atb":[[2.2,15.47]],"id":28603683}],"con":true,"img":false}]}
{"op":"mcm","clk":"5322471685","pt":1646320612097,"mc":[{"id":"1.195532863","rc":[{"atl":[[5.5,3.65]],"id":36042617}],"con":true,"img":false}]}
{"op":"mcm","clk":"5322471700","pt":1646320612303,"mc":[{"id":"1.195532863","rc":[{"atb":[[2.94,3.68]],"id":35839928}],"con":true,"img":false}]}
{"op":"mcm","clk":"5322471720","pt":1646320612510,"mc":[{"id":"1.195532863","rc":[{"atb":[[2.94,0]],"id":35839928},{"atb":[[2.2,12.09]],"id":28603683}],"con":true,"img":false}]}
{"op":"mcm","clk":"5322471775","pt":1646320613192,"mc":[{"id":"1.195532863","rc":[{"spn":4.39,"spf":"NaN","id":39693066},{"spn":2.47,"spf":1.0,"id":36042617},{"atl":[[8.4,7.61]],"id":35839928},{"spn":5.52,"spf":"NaN","id":35839928},{"spn":3.67,"spf":"NaN","id":28603683},{"spn":3.49,"spf":"NaN","id":8668222},{"spn":1.79,"spf":1.0,"id":28691352}],"con":true,"img":false}]}
{"op":"mcm","clk":"5322471783","pt":1646320613296,"mc":[{"id":"1.195532863","rc":[{"atl":[[5.5,0]],"id":36042617},{"atl":[[8.6,13.16],[8.2,19.7],[8.4,31.3]],"id":35839928}],"con":true,"img":false}]}
{"op":"mcm","clk":"5322471892","pt":1646320614497,"mc":[{"id":"1.195532863","rc":[{"atl":[[6.8,20.81],[6.6,0]],"id":39693066},{"atl":[[23,0]],"id":35839928},{"atb":[[1.3,0]],"id":28691352},{"atl":[[3.7,83.49],[3.55,0]],"id":28691352}],"con":true,"img":false}]}
{"op":"mcm","clk":"5322471904","pt":1646320614597,"mc":[{"id":"1.195532863","rc":[{"atl":[[3.7,40.63],[3.75,106.73]],"id":28691352}],"con":true,"img":false}]}
{"op":"mcm","clk":"5322471911","pt":1646320614703,"mc":[{"id":"1.195532863","rc":[{"atl":[[3.6,14.58],[3.7,3.59],[3.75,143.09]],"id":28691352}],"con":true,"img":false}]}
{"op":"mcm","clk":"5322471931","pt":1646320615011,"mc":[{"id":"1.195532863","rc":[{"atl":[[3.7,0]],"id":28691352}],"con":true,"img":false}]}
{"op":"mcm","clk":"5322471955","pt":1646320615327,"mc":[{"id":"1.195532863","rc":[{"atl":[[6.8,17.24]],"id":39693066}],"con":true,"img":false}]}
{"op":"mcm","clk":"5322472027","pt":1646320616216,"mc":[{"id":"1.195532863","rc":[{"atl":[[5.2,17.99]],"id":36042617}],"con":true,"img":false}]}
{"op":"mcm","clk":"5322472041","pt":1646320616427,"mc":[{"id":"1.195532863","rc":[{"atl":[[5.1,17.99],[5.4,31.71]],"id":36042617},{"atl":[[3.7,14.81],[3.65,2.5]],"id":28691352}],"con":true,"img":false}]}
{"op":"mcm","clk":"5322472049","pt":1646320616527,"mc":[{"id":"1.195532863","rc":[{"atl":[[5.1,21.49]],"id":36042617}],"con":true,"img":false}]}
{"op":"mcm","clk":"5322472055","pt":1646320616583,"mc":[{"id":"1.195532863","rc":[{"atl":[[5.3,38.72],[5.4,9.09]],"id":36042617}],"con":true,"img":false}]}
{"op":"mcm","clk":"5322472063","pt":1646320616690,"mc":[{"id":"1.195532863","rc":[{"atl":[[5.2,11]],"id":36042617}],"con":true,"img":false}]}
{"op":"mcm","clk":"5322472191","pt":1646320618107,"mc":[{"id":"1.195532863","rc":[{"atl":[[5.3,48.02],[5.4,0]],"id":36042617}],"con":true,"img":false}]}
{"op":"mcm","clk":"5322472212","pt":1646320618416,"mc":[{"id":"1.195532863","rc":[{"atl":[[8.4,44.81]],"id":35839928}],"con":true,"img":false}]}
{"op":"mcm","clk":"5322472220","pt":1646320618517,"mc":[{"id":"1.195532863","rc":[{"atl":[[8.2,8.06]],"id":35839928}],"con":true,"img":false}]}
{"op":"mcm","clk":"5322472319","pt":1646320619624,"mc":[{"id":"1.195532863","rc":[{"atb":[[1.73,96.06],[1.7,142.86],[1.69,10.77]],"id":28691352}],"con":true,"img":false}]}
{"op":"mcm","clk":"5322472346","pt":1646320620036,"mc":[{"id":"1.195532863","rc":[{"atb":[[1.69,0]],"id":28691352}],"con":true,"img":false}]}
{"op":"mcm","clk":"5322472475","pt":1646320621606,"mc":[{"id":"1.195532863","rc":[{"atl":[[5.1,3.5],[5.3,71.28]],"id":36042617}],"con":true,"img":false}]}
{"op":"mcm","clk":"5322472627","pt":1646320623599,"mc":[{"id":"1.195532863","rc":[{"atb":[[2.66,3.56]],"id":39693066}],"con":true,"img":false}]}
{"op":"mcm","clk":"5322472645","pt":1646320623808,"mc":[{"id":"1.195532863","rc":[{"atb":[[2.66,0]],"id":39693066}],"con":true,"img":false}]}
{"op":"mcm","clk":"5322472833","pt":1646320626328,"mc":[{"id":"1.195532863","rc":[{"atl":[[5.6,26.74],[6.2,0],[5.3,68.78],[5.2,13.5],[5.7,0]],"id":36042617},{"atb":[[2.28,11.4]],"id":28603683},{"atl":[[5.5,0],[6.6,0],[5.9,0],[5.4,55.8]],"id":28603683},{"atb":[[1.59,0],[1.63,0],[1.67,0]],"id":28691352}],"con":true,"img":false}]}
{"op":"mcm","clk":"5322472841","pt":1646320626435,"mc":[{"id":"1.195532863","rc":[{"atl":[[3.8,35.71]],"id":28691352}],"con":true,"img":false}]}
{"op":"mcm","clk":"5322473005","pt":1646320628309,"mc":[{"id":"1.195532863","rc":[{"atl":[[3.75,106.73]],"id":28691352}],"con":true,"img":false}]}
{"op":"mcm","clk":"5322473084","pt":1646320629346,"mc":[{"id":"1.195532863","rc":[{"atb":[[2.24,0]],"id":28603683}],"con":true,"img":false}]}
{"op":"mcm","clk":"5322473226","pt":1646320631030,"mc":[{"id":"1.195532863","rc":[{"atl":[[3.7,73.59],[3.75,36.36]],"id":28691352}],"con":true,"img":false}]}
{"op":"mcm","clk":"5322473237","pt":1646320631135,"mc":[{"id":"1.195532863","rc":[{"atl":[[3.35,15.23]],"id":28691352}],"con":true,"img":false}]}
{"op":"mcm","clk":"5322473247","pt":1646320631240,"mc":[{"id":"1.195532863","rc":[{"atl":[[3.6,0],[3.65,38.86],[3.75,0]],"id":28691352}],"con":true,"img":false}]}
{"op":"mcm","clk":"5322473275","pt":1646320631502,"mc":[{"id":"1.195532863","rc":[{"atl":[[3.45,16.33],[3.7,58.78]],"id":28691352}],"con":true,"img":false}]}
{"op":"mcm","clk":"5322473469","pt":1646320633704,"mc":[{"id":"1.195532863","rc":[{"atb":[[2.34,4.21]],"id":28603683}],"con":true,"img":false}]}
{"op":"mcm","clk":"5322473521","pt":1646320634234,"mc":[{"id":"1.195532863","rc":[{"atb":[[2.32,0]],"id":28603683}],"con":true,"img":false}]}
{"op":"mcm","clk":"5322473530","pt":1646320634335,"mc":[{"id":"1.195532863","rc":[{"atb":[[2.36,1.99]],"id":28603683}],"con":true,"img":false}]}
{"op":"mcm","clk":"5322473788","pt":1646320637619,"mc":[{"id":"1.195532863","rc":[{"atb":[[2.34,2.55]],"id":28603683}],"con":true,"img":false}]}
{"op":"mcm","clk":"5322473807","pt":1646320637827,"mc":[{"id":"1.195532863","rc":[{"atb":[[2.38,1.65]],"id":28603683}],"con":true,"img":false}]}
{"op":"mcm","clk":"5322473824","pt":1646320638034,"mc":[{"id":"1.195532863","rc":[{"atb":[[2.28,2.15]],"id":28603683}],"con":true,"img":false}]}
{"op":"mcm","clk":"5322474100","pt":1646320641537,"mc":[{"id":"1.195532863","rc":[{"atl":[[3.55,39.22]],"id":28691352}],"con":true,"img":false}]}
{"op":"mcm","clk":"5322474108","pt":1646320641640,"mc":[{"id":"1.195532863","rc":[{"atl":[[3.55,78.08],[3.65,2.5]],"id":28691352}],"con":true,"img":false}]}
{"op":"mcm","clk":"5322474143","pt":1646320642158,"mc":[{"id":"1.195532863","rc":[{"atb":[[2.34,0]],"id":28603683}],"con":true,"img":false}]}
{"op":"mcm","clk":"5322474186","pt":1646320642524,"mc":[{"id":"1.195532863","rc":[{"atb":[[2.28,11.4]],"id":28603683}],"con":true,"img":false}]}
{"op":"mcm","clk":"5322474245","pt":1646320643354,"mc":[{"id":"1.195532863","rc":[{"atb":[[2.36,0]],"id":28603683}],"con":true,"img":false}]}
{"op":"mcm","clk":"5322474252","pt":1646320643456,"mc":[{"id":"1.195532863","rc":[{"atb":[[2.32,1.99]],"id":28603683},{"atl":[[5,0],[3.8,0],[5.2,0]],"id":28691352}],"con":true,"img":false}]}
{"op":"mcm","clk":"5322474346","pt":1646320644656,"mc":[{"id":"1.195532863","rc":[{"atb":[[2.38,0]],"id":28603683}],"con":true,"img":false}]}
{"op":"mcm","clk":"5322474366","pt":1646320644863,"mc":[{"id":"1.195532863","rc":[{"atb":[[2.34,1.65]],"id":28603683}],"con":true,"img":false}]}
{"op":"mcm","clk":"5322474410","pt":1646320645439,"mc":[{"id":"1.195532863","rc":[{"atb":[[2.26,4.84]],"id":28603683}],"con":true,"img":false}]}
{"op":"mcm","clk":"5322474459","pt":1646320645916,"mc":[{"id":"1.195532863","rc":[{"atb":[[2.26,0]],"id":28603683}],"con":true,"img":false}]}
{"op":"mcm","clk":"5322474481","pt":1646320646229,"mc":[{"id":"1.195532863","rc":[{"atb":[[2.34,4.21]],"id":28603683}],"con":true,"img":false}]}
{"op":"mcm","clk":"5322474534","pt":1646320646855,"mc":[{"id":"1.195532863","rc":[{"atb":[[2.32,0]],"id":28603683}],"con":true,"img":false}]}
{"op":"mcm","clk":"5322474546","pt":1646320646960,"mc":[{"id":"1.195532863","rc":[{"atb":[[2.36,1.99]],"id":28603683}],"con":true,"img":false}]}
{"op":"mcm","clk":"5322474566","pt":1646320647116,"mc":[{"id":"1.195532863","rc":[{"atl":[[3.7,0],[3.55,158.96]],"id":28691352}],"con":true,"img":false}]}
{"op":"mcm","clk":"5322474894","pt":1646320651596,"mc":[{"id":"1.195532863","rc":[{"atl":[[3.65,59.1]],"id":28691352}],"con":true,"img":false}]}
{"op":"mcm","clk":"5322474907","pt":1646320651631,"mc":[{"id":"1.195532863","rc":[{"atb":[[2.34,2.55]],"id":28603683}],"con":true,"img":false}]}
{"op":"mcm","clk":"5322474920","pt":1646320651729,"mc":[{"id":"1.195532863","rc":[{"atb":[[2.38,1.65]],"id":28603683}],"con":true,"img":false}]}
{"op":"mcm","clk":"5322474928","pt":1646320651835,"mc":[{"id":"1.195532863","rc":[{"atb":[[2.28,2.15]],"id":28603683}],"con":true,"img":false}]}
{"op":"mcm","clk":"5322475148","pt":1646320654449,"mc":[{"id":"1.195532863","rc":[{"atb":[[2.34,0]],"id":28603683}],"con":true,"img":false}]}
{"op":"mcm","clk":"5322475213","pt":1646320655273,"mc":[{"id":"1.195532863","rc":[{"atb":[[2.36,0]],"id":28603683}],"con":true,"img":false}]}
{"op":"mcm","clk":"5322475224","pt":1646320655338,"mc":[{"id":"1.195532863","rc":[{"atb":[[2.32,1.99]],"id":28603683}],"con":true,"img":false}]}
{"op":"mcm","clk":"5322475442","pt":1646320658480,"mc":[{"id":"1.195532863","rc":[{"atb":[[2.28,11.4]],"id":28603683}],"con":true,"img":false}]}
{"op":"mcm","clk":"5322475461","pt":1646320658639,"mc":[{"id":"1.195532863","rc":[{"atb":[[2.38,0]],"id":28603683}],"con":true,"img":false}]}
{"op":"mcm","clk":"5322475474","pt":1646320658744,"mc":[{"id":"1.195532863","rc":[{"atb":[[2.24,4.37]],"id":28603683}],"con":true,"img":false}]}
{"op":"mcm","clk":"5322475485","pt":1646320658845,"mc":[{"id":"1.195532863","rc":[{"atb":[[2.34,1.65]],"id":28603683}],"con":true,"img":false}]}
{"op":"mcm","clk":"5322475507","pt":1646320659159,"mc":[{"id":"1.195532863","rc":[{"atb":[[2.2,15.1]],"id":28603683}],"con":true,"img":false}]}
{"op":"mcm","clk":"5322475545","pt":1646320659679,"mc":[{"id":"1.195532863","rc":[{"atb":[[2.2,12.09]],"id":28603683}],"con":true,"img":false}]}
{"op":"mcm","clk":"5322475706","pt":1646320661558,"mc":[{"id":"1.195532863","rc":[{"atl":[[3.75,90.91]],"id":28691352}],"con":true,"img":false}]}
{"op":"mcm","clk":"5322475933","pt":1646320664372,"mc":[{"id":"1.195532863","rc":[{"atb":[[2.24,0]],"id":28603683}],"con":true,"img":false}]}
{"op":"mcm","clk":"5322476275","pt":1646320668665,"mc":[{"id":"1.195532863","rc":[{"atb":[[2.34,4.21]],"id":28603683}],"con":true,"img":false}]}
{"op":"mcm","clk":"5322476345","pt":1646320669458,"mc":[{"id":"1.195532863","rc":[{"atb":[[2.32,0]],"id":28603683}],"con":true,"img":false}]}
{"op":"mcm","clk":"5322476358","pt":1646320669558,"mc":[{"id":"1.195532863","rc":[{"atb":[[2.36,1.99]],"id":28603683}],"con":true,"img":false}]}
{"op":"mcm","clk":"5322476609","pt":1646320672651,"mc":[{"id":"1.195532863","rc":[{"atb":[[2.34,2.55]],"id":28603683}],"con":true,"img":false}]}
{"op":"mcm","clk":"5322476625","pt":1646320672863,"mc":[{"id":"1.195532863","rc":[{"atb":[[2.38,1.65]],"id":28603683}],"con":true,"img":false}]}
{"op":"mcm","clk":"5322476718","pt":1646320674004,"mc":[{"id":"1.195532863","rc":[{"atb":[[2.28,2.15]],"id":28603683},{"spn":3.69,"spf":"NaN","id":28603683}],"con":true,"img":false}]}
{"op":"mcm","clk":"5322476729","pt":1646320674060,"mc":[{"id":"1.195532863","rc":[{"atb":[[2.3,11.75]],"id":28603683}],"con":true,"img":false}]}
{"op":"mcm","clk":"5322476798","pt":1646320674900,"mc":[{"id":"1.195532863","rc":[{"atb":[[2.36,4.14],[2.28,0]],"id":28603683}],"con":true,"img":false}]}
{"op":"mcm","clk":"5322476975","pt":1646320676905,"mc":[{"id":"1.195532863","rc":[{"atb":[[2.34,0]],"id":28603683}],"con":true,"img":false}]}
{"op":"mcm","clk":"5322477134","pt":1646320679107,"mc":[{"id":"1.195532863","rc":[{"atb":[[2.24,8.12]],"id":28603683}],"con":true,"img":false}]}
{"op":"mcm","clk":"5322477232","pt":1646320680325,"mc":[{"id":"1.195532863","rc":[{"atb":[[3.1,3]],"id":35839928},{"atb":[[2.28,3]],"id":28603683}],"con":true,"img":false}]}
{"op":"mcm","clk":"5322477242","pt":1646320680433,"mc":[{"id":"1.195532863","rc":[{"atl":[[6.6,4.63]],"id":39693066},{"atl":[[5.5,5.68]],"id":36042617},{"atb":[[2.96,7.48]],"id":35839928},{"atl":[[8.4,48.28]],"id":35839928},{"atb":[[2.22,3.41],[2.18,7.26]],"id":8668222},{"atl":[[5.1,28.14]],"id":8668222},{"atb":[[1.72,89.73]],"id":28691352}],"con":true,"img":false}]}
{"op":"mcm","clk":"5322477251","pt":1646320680536,"mc":[{"id":"1.195532863","rc":[{"atb":[[3.1,17.35],[2.98,5]],"id":35839928},{"atb":[[2.28,0]],"id":28603683}],"con":true,"img":false}]}
{"op":"mcm","clk":"5322477263","pt":1646320680652,"mc":[{"id":"1.195532863","rc":[{"atb":[[2.96,0]],"id":35839928},{"atb":[[2.12,18.91],[2.18,21.87]],"id":8668222},{"atb":[[1.72,88.05]],"id":28691352}],"con":true,"img":false}]}
{"op":"mcm","clk":"5322477268","pt":1646320680697,"mc":[{"id":"1.195532863","rc":[{"atl":[[4.6,2.25]],"id":8668222}],"con":true,"img":false}]}
{"op":"mcm","clk":"5322477277","pt":1646320680802,"mc":[{"id":"1.195532863","rc":[{"atl":[[4.8,18.18],[4.5,4.43],[4.6,4.75],[4.9,10.26]],"id":8668222}],"con":true,"img":false}]}
{"op":"mcm","clk":"5322477287","pt":1646320680906,"mc":[{"id":"1.195532863","rc":[{"atl":[[6.6,0]],"id":39693066},{"atl":[[5.5,0]],"id":36042617},{"atl":[[8.4,44.81]],"id":35839928},{"atb":[[2.22,0]],"id":8668222},{"atl":[[5.1,24.39],[5.2,9.06]],"id":8668222},{"atb":[[1.72,82.35]],"id":28691352}],"con":true,"img":false}]}
{"op":"mcm","clk":"5322477293","pt":1646320681011,"mc":[{"id":"1.195532863","rc":[{"atb":[[2.18,17.11]],"id":8668222},{"atl":[[4.6,2.25],[5.2,5],[4.4,4.43],[4.7,0]],"id":8668222},{"atl":[[3.55,168.96]],"id":28691352}],"con":true,"img":false}]}
{"op":"mcm","clk":"5322477319","pt":1646320681327,"mc":[{"id":"1.195532863","rc":[{"atb":[[2.24,30.17],[2.3,2.5]],"id":28603683}],"con":true,"img":false}]}
{"op":"mcm","clk":"5322477328","pt":1646320681434,"mc":[{"id":"1.195532863","rc":[{"atl":[[3.55,158.96]],"id":28691352}],"con":true,"img":false}]}
{"op":"mcm","clk":"5322477347","pt":1646320681645,"mc":[{"id":"1.195532863","rc":[{"atl":[[4.6,0]],"id":8668222}],"con":true,"img":false}]}
{"op":"mcm","clk":"5322477377","pt":1646320682020,"mc":[{"id":"1.195532863","rc":[{"atl":[[4.5,6.02]],"id":8668222}],"con":true,"img":false}]}
{"op":"mcm","clk":"5322477475","pt":1646320683231,"mc":[{"id":"1.195532863","rc":[{"atb":[[2.12,0]],"id":8668222}],"con":true,"img":false}]}
{"op":"mcm","clk":"5322477581","pt":1646320684431,"mc":[{"id":"1.195532863","rc":[{"atl":[[4.5,4.43]],"id":8668222}],"con":true,"img":false}]}
{"op":"mcm","clk":"5322477607","pt":1646320684745,"mc":[{"id":"1.195532863","rc":[{"atl":[[4.6,1.59]],"id":8668222}],"con":true,"img":false}]}
{"op":"mcm","clk":"5322477651","pt":1646320685115,"mc":[{"id":"1.195532863","rc":[{"atl":[[4.6,12.7],[4.9,0]],"id":8668222}],"con":true,"img":false}]}
{"op":"mcm","clk":"5322477749","pt":1646320686111,"mc":[{"id":"1.195532863","rc":[{"atl":[[4.5,17.13],[4.4,0]],"id":8668222}],"con":true,"img":false}]}
{"op":"mcm","clk":"5322477867","pt":1646320687424,"mc":[{"id":"1.195532863","rc":[{"atb":[[2.12,18.91]],"id":8668222}],"con":true,"img":false}]}
{"op":"mcm","clk":"5322477900","pt":1646320687843,"mc":[{"id":"1.195532863","rc":[{"atb":[[2.12,61.71],[2.18,2.5]],"id":8668222}],"con":true,"img":false}]}
{"op":"mcm","clk":"5322478087","pt":1646320690206,"mc":[{"id":"1.195532863","rc":[{"atb":[[1.08,50]],"id":39693066},{"atb":[[1.08,50]],"id":36042617},{"atb":[[1.08,50]],"id":35839928},{"atb":[[1.08,50]],"id":28603683},{"atb":[[1.08,50]],"id":8668222},{"atb":[[1.08,50]],"id":28691352}],"con":true,"img":false}]}
{"op":"mcm","clk":"5322478175","pt":1646320691245,"mc":[{"id":"1.195532863","rc":[{"atl":[[4.5,4.43],[4.6,40.48]],"id":8668222}],"con":true,"img":false}]}
{"op":"mcm","clk":"5322478189","pt":1646320691300,"mc":[{"id":"1.195532863","rc":[{"atl":[[4.8,44.5]],"id":8668222}],"con":true,"img":false}]}
{"op":"mcm","clk":"5322478198","pt":1646320691397,"mc":[{"id":"1.195532863","rc":[{"atl":[[4.6,12.7]],"id":8668222}],"con":true,"img":false}]}
{"op":"mcm","clk":"5322478552","pt":1646320696053,"mc":[{"id":"1.195532863","rc":[{"atl":[[4.6,1.59],[4.7,10.81]],"id":8668222}],"con":true,"img":false}]}
{"op":"mcm","clk":"5322478572","pt":1646320696207,"mc":[{"id":"1.195532863","rc":[{"atl":[[4.6,12.4]],"id":8668222}],"con":true,"img":false}]}
{"op":"mcm","clk":"5322478577","pt":1646320696314,"mc":[{"id":"1.195532863","rc":[{"atl":[[4.8,2.5],[4.7,57.23]],"id":8668222}],"con":true,"img":false}]}
{"op":"mcm","clk":"5322478616","pt":1646320696729,"mc":[{"id":"1.195532863","rc":[{"atl":[[5.1,17],[5.3,45.52],[5.2,2.5]],"id":36042617}],"con":true,"img":false}]}
{"op":"mcm","clk":"5322478626","pt":1646320696833,"mc":[{"id":"1.195532863","rc":[{"atl":[[5.1,28]],"id":36042617}],"con":true,"img":false}]}
{"op":"mcm","clk":"5322478645","pt":1646320697042,"mc":[{"id":"1.195532863","rc":[{"atl":[[3.6,2.5],[3.85,0],[4.1,0],[3.65,56.6]],"id":28691352}],"con":true,"img":false}]}
{"op":"mcm","clk":"5322478653","pt":1646320697145,"mc":[{"id":"1.195532863","rc":[{"atl":[[5.5,3]],"id":36042617},{"atl":[[8,2.5],[9,18.75],[8.2,5.56],[9.8,0]],"id":35839928}],"con":true,"img":false}]}
{"op":"mcm","clk":"5322478669","pt":1646320697351,"mc":[{"id":"1.195532863","rc":[{"atl":[[8.2,28.32],[8.4,13.51]],"id":35839928}],"con":true,"img":false}]}
{"op":"mcm","clk":"5322478683","pt":1646320697511,"mc":[{"id":"1.195532863","rc":[{"atl":[[8,16.01],[8.4,0]],"id":35839928}],"con":true,"img":false}]}
{"op":"mcm","clk":"5322478691","pt":1646320697616,"mc":[{"id":"1.195532863","rc":[{"atl":[[5.5,0]],"id":36042617},{"atl":[[8.2,41.83]],"id":35839928}],"con":true,"img":false}]}
{"op":"mcm","clk":"5322478699","pt":1646320697724,"mc":[{"id":"1.195532863","rc":[{"atl":[[8,2.5]],"id":35839928}],"con":true,"img":false}]}
{"op":"mcm","clk":"5322478739","pt":1646320698243,"mc":[{"id":"1.195532863","rc":[{"atl":[[4.6,10.81]],"id":8668222}],"con":true,"img":false}]}
{"op":"mcm","clk":"5322478748","pt":1646320698349,"mc":[{"id":"1.195532863","rc":[{"atl":[[5.3,4.76]],"id":28603683}],"con":true,"img":false}]}
{"op":"mcm","clk":"5322478754","pt":1646320698456,"mc":[{"id":"1.195532863","rc":[{"atl":[[5.3,21.14]],"id":28603683},{"atl":[[4.6,0],[4.7,81.62]],"id":8668222}],"con":true,"img":false}]}
{"op":"mcm","clk":"5322478762","pt":1646320698558,"mc":[{"id":"1.195532863","rc":[{"atl":[[5.4,41]],"id":28603683},{"atl":[[4.8,28.82]],"id":8668222}],"con":true,"img":false}]}
{"op":"mcm","clk":"5322478771","pt":1646320698610,"mc":[{"id":"1.195532863","rc":[{"atl":[[4.7,57.23]],"id":8668222}],"con":true,"img":false}]}
{"op":"mcm","clk":"5322478831","pt":1646320699420,"mc":[{"id":"1.195532863","rc":[{"atb":[[2.28,12.65]],"id":8668222}],"con":true,"img":false}]}
{"op":"mcm","clk":"5322478841","pt":1646320699521,"mc":[{"id":"1.195532863","rc":[{"atb":[[2.3,17.72],[2.12,18.91],[2.18,32.02]],"id":8668222}],"con":true,"img":false}]}
{"op":"mcm","clk":"5322478854","pt":1646320699730,"mc":[{"id":"1.195532863","rc":[{"atb":[[2.26,4.31]],"id":8668222}],"con":true,"img":false}]}
{"op":"mcm","clk":"5322478888","pt":1646320700248,"mc":[{"id":"1.195532863","rc":[{"atb":[[2.26,2.16],[2.36,2.15]],"id":8668222}],"con":true,"img":false}]}
{"op":"mcm","clk":"5322478927","pt":1646320700716,"mc":[{"id":"1.195532863","rc":[{"atb":[[2.28,11]],"id":8668222}],"con":true,"img":false}]}
{"op":"mcm","clk":"5322478935","pt":1646320700819,"mc":[{"id":"1.195532863","rc":[{"atb":[[2.38,1.65]],"id":8668222}],"con":true,"img":false}]}
{"op":"mcm","clk":"5322479013","pt":1646320701855,"mc":[{"id":"1.195532863","rc":[{"atl":[[5.1,14.5],[5.3,68.78]],"id":36042617}],"con":true,"img":false}]}
{"op":"mcm","clk":"5322479026","pt":1646320702061,"mc":[{"id":"1.195532863","rc":[{"atb":[[2.12,0]],"id":8668222}],"con":true,"img":false}]}
{"op":"mcm","clk":"5322479089","pt":1646320702743,"mc":[{"id":"1.195532863","rc":[{"atb":[[2.28,46.9],[2.18,2.5]],"id":8668222}],"con":true,"img":false}]}
{"op":"mcm","clk":"5322479144","pt":1646320703364,"mc":[{"id":"1.195532863","rc":[{"atl":[[4.8,96.99],[4.7,10.81]],"id":8668222}],"con":true,"img":false}]}
{"op":"mcm","clk":"5322479267","pt":1646320705240,"mc":[{"id":"1.195532863","rc":[{"atl":[[4.5,6.02]],"id":8668222}],"con":true,"img":false}]}
{"op":"mcm","clk":"5322479271","pt":1646320705346,"mc":[{"id":"1.195532863","rc":[{"atl":[[4.8,70.67],[4.5,16.83]],"id":8668222}],"con":true,"img":false}]}
{"op":"mcm","clk":"5322479309","pt":1646320706072,"mc":[{"id":"1.195532863","rc":[{"atb":[[2.38,4.33]],"id":8668222}],"con":true,"img":false}]}
{"op":"mcm","clk":"5322479357","pt":1646320706746,"mc":[{"id":"1.195532863","rc":[{"atl":[[4.9,25.64]],"id":8668222}],"con":true,"img":false}]}
{"op":"mcm","clk":"5322479557","pt":1646320709669,"mc":[{"id":"1.195532863","rc":[{"atb":[[2.28,55.56]],"id":8668222},{"atl":[[5.5,0]],"id":8668222},{"atl":[[3.35,0]],"id":28691352}],"con":true,"img":false}]}
{"op":"mcm","clk":"5322479564","pt":1646320709770,"mc":[{"id":"1.195532863","rc":[{"atb":[[2.26,0]],"id":8668222},{"atl":[[3.6,40.96],[3.35,23.67],[3.5,5.19]],"id":28691352}],"con":true,"img":false}]}
{"op":"mcm","clk":"5322479573","pt":1646320709875,"mc":[{"id":"1.195532863","rc":[{"atl":[[3.6,133.15],[3.55,39.22]],"id":28691352}],"con":true,"img":false}]}
{"op":"mcm","clk":"5322479590","pt":1646320710031,"mc":[{"id":"1.195532863","rc":[{"atl":[[3.6,40.96]],"id":28691352}],"con":true,"img":false}]}
{"op":"mcm","clk":"5322479607","pt":1646320710236,"mc":[{"id":"1.195532863","rc":[{"atl":[[3.5,0]],"id":28691352}],"con":true,"img":false}]}
{"op":"mcm","clk":"5322479612","pt":1646320710340,"mc":[{"id":"1.195532863","rc":[{"atl":[[4.5,15.24]],"id":8668222}],"con":true,"img":false}]}
{"op":"mcm","clk":"5322479620","pt":1646320710444,"mc":[{"id":"1.195532863","rc":[{"atl":[[4.8,96.72]],"id":8668222}],"con":true,"img":false}]}
{"op":"mcm","clk":"5322479631","pt":1646320710548,"mc":[{"id":"1.195532863","rc":[{"atl":[[4.5,4.43]],"id":8668222}],"con":true,"img":false}]}
{"op":"mcm","clk":"5322479638","pt":1646320710655,"mc":[{"id":"1.195532863","rc":[{"atl":[[4.6,1.59]],"id":8668222}],"con":true,"img":false}]}
{"op":"mcm","clk":"5322479734","pt":1646320711968,"mc":[{"id":"1.195532863","rc":[{"atl":[[3.45,24.84]],"id":28691352}],"con":true,"img":false}]}
{"op":"mcm","clk":"5322479756","pt":1646320712267,"mc":[{"id":"1.195532863","rc":[{"atl":[[3.45,16.33]],"id":28691352}],"con":true,"img":false}]}
{"op":"mcm","clk":"5322479871","pt":1646320714242,"mc":[{"id":"1.195532863","rc":[{"atb":[[2.3,38.76],[2.38,10.9],[2.28,19.66]],"id":8668222}],"con":true,"img":false}]}
{"op":"mcm","clk":"5322479879","pt":1646320714449,"mc":[{"id":"1.195532863","rc":[{"atb":[[2.3,21.04]],"id":8668222}],"con":true,"img":false}]}
{"op":"mcm","clk":"5322479917","pt":1646320715177,"mc":[{"id":"1.195532863","rc":[{"atb":[[2.44,2.15],[2.36,0]],"id":8668222}],"con":true,"img":false}]}
{"op":"mcm","clk":"5322479949","pt":1646320715642,"mc":[{"id":"1.195532863","rc":[{"atl":[[4.8,102]],"id":8668222}],"con":true,"img":false}]}
{"op":"mcm","clk":"5322479962","pt":1646320715850,"mc":[{"id":"1.195532863","rc":[{"atl":[[4.8,96.72]],"id":8668222}],"con":true,"img":false}]}
{"op":"mcm","clk":"5322480039","pt":1646320717249,"mc":[{"id":"1.195532863","rc":[{"atl":[[4.8,70.67],[4.6,12.4]],"id":8668222}],"con":true,"img":false}]}
{"op":"mcm","clk":"5322480049","pt":1646320717350,"mc":[{"id":"1.195532863","rc":[{"atl":[[5.1,36.59],[4.7,54.23]],"id":8668222}],"con":true,"img":false}]}
{"op":"mcm","clk":"5322480056","pt":1646320717452,"mc":[{"id":"1.195532863","rc":[{"atl":[[4.8,2.5]],"id":8668222}],"con":true,"img":false}]}
{"op":"mcm","clk":"5322480231","pt":1646320720165,"mc":[{"id":"1.195532863","rc":[{"atb":[[2.38,8.22]],"id":8668222}],"con":true,"img":false}]}
{"op":"mcm","clk":"5322480269","pt":1646320720581,"mc":[{"id":"1.195532863","rc":[{"atl":[[6.4,48.72]],"id":39693066},{"atl":[[5.3,24.58]],"id":28603683}],"con":true,"img":false}]}
{"op":"mcm","clk":"5322480283","pt":1646320720792,"mc":[{"id":"1.195532863","rc":[{"atl":[[5.2,33.33],[5.4,25.23]],"id":28603683},{"atl":[[4.6,10.81]],"id":8668222}],"con":true,"img":false}]}
{"op":"mcm","clk":"5322480314","pt":1646320721157,"mc":[{"id":"1.195532863","rc":[{"atl":[[5.3,21.14]],"id":28603683}],"con":true,"img":false}]}
{"op":"mcm","clk":"5322480336","pt":1646320721468,"mc":[{"id":"1.195532863","rc":[{"atl":[[6.4,44.95]],"id":39693066}],"con":true,"img":false}]}
{"op":"mcm","clk":"5322480348","pt":1646320721673,"mc":[{"id":"1.195532863","rc":[{"atb":[[2.38,6.57]],"id":8668222}],"con":true,"img":false}]}
{"op":"mcm","clk":"5322480355","pt":1646320721781,"mc":[{"id":"1.195532863","rc":[{"atl":[[5.2,37.77]],"id":28603683},{"atl":[[4.7,60.48]],"id":8668222}],"con":true,"img":false}]}
{"op":"mcm","clk":"5322480363","pt":1646320721884,"mc":[{"id":"1.195532863","rc":[{"atb":[[2.46,1.65]],"id":8668222}],"con":true,"img":false}]}
{"op":"mcm","clk":"5322480378","pt":1646320722090,"mc":[{"id":"1.195532863","rc":[{"atl":[[6.4,47.42]],"id":39693066}],"con":true,"img":false}]}
{"op":"mcm","clk":"5322480405","pt":1646320722354,"mc":[{"id":"1.195532863","rc":[{"atl":[[4.7,54.23]],"id":8668222}],"con":true,"img":false}]}
{"op":"mcm","clk":"5322480419","pt":1646320722458,"mc":[{"id":"1.195532863","rc":[{"atl":[[4.6,0],[4.7,79.87]],"id":8668222}],"con":true,"img":false}]}
{"op":"mcm","clk":"5322480441","pt":1646320722666,"mc":[{"id":"1.195532863","rc":[{"atl":[[4.6,5.1]],"id":8668222}],"con":true,"img":false}]}
{"op":"mcm","clk":"5322480500","pt":1646320723400,"mc":[{"id":"1.195532863","rc":[{"atb":[[3.25,13.65]],"id":35839928}],"con":true,"img":false}]}
{"op":"mcm","clk":"5322480516","pt":1646320723555,"mc":[{"id":"1.195532863","rc":[{"atb":[[3.1,0],[3.25,26.36],[3.15,23.69]],"id":35839928}],"con":true,"img":false}]}
{"op":"mcm","clk":"5322480533","pt":1646320723766,"mc":[{"id":"1.195532863","rc":[{"atb":[[3.2,5.31]],"id":35839928}],"con":true,"img":false}]}
{"op":"mcm","clk":"5322480542","pt":1646320723868,"mc":[{"id":"1.195532863","rc":[{"atb":[[3.2,3.32]],"id":35839928},{"atl":[[4.6,0]],"id":8668222}],"con":true,"img":false}]}
{"op":"mcm","clk":"5322480553","pt":1646320723972,"mc":[{"id":"1.195532863","rc":[{"atb":[[3.3,1.99]],"id":35839928},{"atl":[[4.8,28.82],[4.7,54.23]],"id":8668222}],"con":true,"img":false}]}
{"op":"mcm","clk":"5322480572","pt":1646320724181,"mc":[{"id":"1.195532863","rc":[{"atb":[[1.01,4806.04]],"id":35839928},{"atl":[[4.8,84.04],[4.7,10.81]],"id":8668222}],"con":true,"img":false}]}
{"op":"mcm","clk":"5322480581","pt":1646320724284,"mc":[{"id":"1.195532863","rc":[{"atb":[[1.01,4808.03]],"id":35839928}],"con":true,"img":false}]}
{"op":"mcm","clk":"5322480586","pt":1646320724389,"mc":[{"id":"1.195532863","rc":[{"atb":[[1.01,4806.04]],"id":35839928},{"atb":[[2.32,5.34]],"id":8668222},{"atl":[[3.55,135.65]],"id":28691352}],"con":true,"img":false}]}
{"op":"mcm","clk":"5322480592","pt":1646320724493,"mc":[{"id":"1.195532863","rc":[{"atb":[[3.3,3.98],[3.15,27.31]],"id":35839928}],"con":true,"img":false}]}
{"op":"mcm","clk":"5322480602","pt":1646320724597,"mc":[{"id":"1.195532863","rc":[{"atb":[[2.32,20.23],[2.3,0]],"id":8668222}],"con":true,"img":false}]}
{"op":"mcm","clk":"5322480608","pt":1646320724701,"mc":[{"id":"1.195532863","rc":[{"atb":[[3.15,23.69]],"id":35839928}],"con":true,"img":false}]}
{"op":"mcm","clk":"5322480643","pt":1646320725172,"mc":[{"id":"1.195532863","rc":[{"atl":[[4.7,17.65]],"id":8668222}],"con":true,"img":false}]}
{"op":"mcm","clk":"5322480653","pt":1646320725379,"mc":[{"id":"1.195532863","rc":[{"atb":[[2.72,5],[2.74,0]],"id":39693066}],"con":true,"img":false}]}
{"op":"mcm","clk":"5322480657","pt":1646320725484,"mc":[{"id":"1.195532863","rc":[{"atl":[[4.7,10.81]],"id":8668222}],"con":true,"img":false}]}
{"op":"mcm","clk":"5322480663","pt":1646320725588,"mc":[{"id":"1.195532863","rc":[{"atb":[[2.72,8.33]],"id":39693066}],"con":true,"img":false}]}
{"op":"mcm","clk":"5322480693","pt":1646320726059,"mc":[{"id":"1.195532863","rc":[{"atb":[[2.72,5]],"id":39693066}],"con":true,"img":false}]}
{"op":"mcm","clk":"5322480699","pt":1646320726162,"mc":[{"id":"1.195532863","rc":[{"atb":[[2.3,0],[2.32,2.5],[2.22,0],[2.14,0],[2.24,35.17]],"id":28603683}],"con":true,"img":false}]}
{"op":"mcm","clk":"5322480705","pt":1646320726268,"mc":[{"id":"1.195532863","rc":[{"atb":[[2.54,0],[2.62,0],[2.46,0]],"id":39693066}],"con":true,"img":false}]}
{"op":"mcm","clk":"5322480712","pt":1646320726399,"mc":[{"id":"1.195532863","rc":[{"atb":[[2.28,5.58]],"id":28603683}],"con":true,"img":false}]}
{"op":"mcm","clk":"5322480721","pt":1646320726558,"mc":[{"id":"1.195532863","rc":[{"atb":[[2.24,13.12],[2.28,14.24]],"id":28603683}],"con":true,"img":false}]}
{"op":"mcm","clk":"5322480810","pt":1646320727701,"mc":[{"id":"1.195532863","rc":[{"atl":[[5.3,58.14]],"id":8668222}],"con":true,"img":false}]}
{"op":"mcm","clk":"5322480836","pt":1646320727962,"mc":[{"id":"1.195532863","rc":[{"atl":[[4.5,9.06]],"id":8668222}],"con":true,"img":false}]}
{"op":"mcm","clk":"5322480868","pt":1646320728373,"mc":[{"id":"1.195532863","rc":[{"atb":[[2.24,5]],"id":28603683}],"con":true,"img":false}]}
{"op":"mcm","clk":"5322480891","pt":1646320728687,"mc":[{"id":"1.195532863","rc":[{"atb":[[3.25,24.71]],"id":35839928},{"atb":[[2.44,13.87]],"id":8668222}],"con":true,"img":false}]}
{"op":"mcm","clk":"5322480908","pt":1646320728899,"mc":[{"id":"1.195532863","rc":[{"atb":[[3.35,1.65]],"id":35839928},{"atb":[[2.38,0]],"id":8668222}],"con":true,"img":false}]}
{"op":"mcm","clk":"5322480927","pt":1646320729109,"mc":[{"id":"1.195532863","rc":[{"atl":[[4.5,4.43]],"id":8668222}],"con":true,"img":false}]}
{"op":"mcm","clk":"5322481044","pt":1646320730364,"mc":[{"id":"1.195532863","rc":[{"atb":[[2.72,0],[2.7,43.46]],"id":39693066},{"atb":[[2.44,18.45]],"id":8668222}],"con":true,"img":false}]}
{"op":"mcm","clk":"5322481054","pt":1646320730471,"mc":[{"id":"1.195532863","rc":[{"atb":[[2.3,78.02],[2.5,10],[2.58,5],[2.66,2.5],[2.7,30.77]],"id":39693066}],"con":true,"img":false}]}
{"op":"mcm","clk":"5322481068","pt":1646320730681,"mc":[{"id":"1.195532863","rc":[{"atb":[[2.44,13.87]],"id":8668222},{"atl":[[4.3,4.9]],"id":8668222}],"con":true,"img":false}]}
{"op":"mcm","clk":"5322481073","pt":1646320730785,"mc":[{"id":"1.195532863","rc":[{"atl":[[4.8,57.72],[4.2,11.78]],"id":8668222}],"con":true,"img":false}]}
{"op":"mcm","clk":"5322481083","pt":1646320730891,"mc":[{"id":"1.195532863","rc":[{"atl":[[4.5,0],[4.2,16.68]],"id":8668222}],"con":true,"img":false}]}
{"op":"mcm","clk":"5322481091","pt":1646320730996,"mc":[{"id":"1.195532863","rc":[{"atl":[[4.5,5.88]],"id":8668222}],"con":true,"img":false}]}
{"op":"mcm","clk":"5322481107","pt":1646320731204,"mc":[{"id":"1.195532863","rc":[{"atl":[[4.5,0],[4.4,11.76],[4.7,0]],"id":8668222}],"con":true,"img":false}]}
{"op":"mcm","clk":"5322481116","pt":1646320731307,"mc":[{"id":"1.195532863","rc":[{"atb":[[2.28,59.94]],"id":8668222}],"con":true,"img":false}]}
{"op":"mcm","clk":"5322481124","pt":1646320731363,"mc":[{"id":"1.195532863","rc":[{"atb":[[2.32,5.34]],"id":8668222}],"con":true,"img":false}]}
{"op":"mcm","clk":"5322481153","pt":1646320731779,"mc":[{"id":"1.195532863","rc":[{"atl":[[4.8,2.5],[4.4,66.36]],"id":8668222}],"con":true,"img":false}]}
{"op":"mcm","clk":"5322481216","pt":1646320732674,"mc":[{"id":"1.195532863","rc":[{"atb":[[2.26,3.59]],"id":8668222}],"con":true,"img":false}]}
{"op":"mcm","clk":"5322481243","pt":1646320733091,"mc":[{"id":"1.195532863","rc":[{"atb":[[2.38,5.72]],"id":28603683},{"atb":[[2.32,0],[2.26,0]],"id":8668222}],"con":true,"img":false}]}
{"op":"mcm","clk":"5322481358","pt":1646320734494,"mc":[{"id":"1.195532863","rc":[{"spn":5.57,"spf":"NaN","id":35839928},{"atb":[[2.36,2.15]],"id":28603683},{"spn":3.33,"spf":"NaN","id":8668222}],"con":true,"img":false}]}
{"op":"mcm","clk":"5322481366","pt":1646320734596,"mc":[{"id":"1.195532863","rc":[{"atb":[[2.4,1.99]],"id":28603683}],"con":true,"img":false}]}
{"op":"mcm","clk":"5322481446","pt":1646320735670,"mc":[{"id":"1.195532863","rc":[{"atb":[[2.38,4.06]],"id":28603683}],"con":true,"img":false}]}
{"op":"mcm","clk":"5322481452","pt":1646320735774,"mc":[{"id":"1.195532863","rc":[{"atb":[[2.42,1.65]],"id":28603683},{"atb":[[1.73,13.71],[1.72,95.48],[1.67,149.25]],"id":28691352}],"con":true,"img":false}]}
{"op":"mcm","clk":"5322481464","pt":1646320735983,"mc":[{"id":"1.195532863","rc":[{"atb":[[2.28,0]],"id":28603683},{"atb":[[1.72,93.36],[1.71,6.15]],"id":28691352}],"con":true,"img":false}]}
{"op":"mcm","clk":"5322481480","pt":1646320736191,"mc":[{"id":"1.195532863","rc":[{"atb":[[1.72,82.35]],"id":28691352}],"con":true,"img":false}]}
{"op":"mcm","clk":"5322481512","pt":1646320736608,"mc":[{"id":"1.195532863","rc":[{"atb":[[1.71,0]],"id":28691352}],"con":true,"img":false}]}
{"op":"mcm","clk":"5322481555","pt":1646320737242,"mc":[{"id":"1.195532863","rc":[{"atl":[[4.3,0]],"id":8668222}],"con":true,"img":false}]}
{"op":"mcm","clk":"5322481564","pt":1646320737351,"mc":[{"id":"1.195532863","rc":[{"atb":[[2.2,30.42]],"id":8668222},{"atl":[[4.8,28.82],[4.2,11.78]],"id":8668222}],"con":true,"img":false}]}
{"op":"mcm","clk":"5322481581","pt":1646320737555,"mc":[{"id":"1.195532863","rc":[{"atl":[[4.2,0]],"id":8668222}],"con":true,"img":false}]}
{"op":"mcm","clk":"5322481588","pt":1646320737657,"mc":[{"id":"1.195532863","rc":[{"atl":[[4.8,2.5],[4.3,24.24],[4.9,51.28]],"id":8668222}],"con":true,"img":false}]}
{"op":"mcm","clk":"5322481601","pt":1646320737869,"mc":[{"id":"1.195532863","rc":[{"atb":[[3.35,9],[3.2,17.64],[3.15,2.5]],"id":35839928}],"con":true,"img":false}]}
{"op":"mcm","clk":"5322481609","pt":1646320737978,"mc":[{"id":"1.195532863","rc":[{"atb":[[2.28,19.66],[2.2,98.74]],"id":8668222}],"con":true,"img":false}]}
{"op":"mcm","clk":"5322481614","pt":1646320738078,"mc":[{"id":"1.195532863","rc":[{"atb":[[3.25,12]],"id":35839928}],"con":true,"img":false}]}
{"op":"mcm","clk":"5322481635","pt":1646320738241,"mc":[{"id":"1.195532863","rc":[{"atb":[[3.3,1.99]],"id":35839928}],"con":true,"img":false}]}
{"op":"mcm","clk":"5322481642","pt":1646320738345,"mc":[{"id":"1.195532863","rc":[{"atb":[[3.4,1.99]],"id":35839928},{"atl":[[4.8,75.89],[4.1,5.2]],"id":8668222}],"con":true,"img":false}]}
{"op":"mcm","clk":"5322481649","pt":1646320738447,"mc":[{"id":"1.195532863","rc":[{"atl":[[4,24.24],[4.4,11.76]],"id":8668222}],"con":true,"img":false}]}
{"op":"mcm","clk":"5322481652","pt":1646320738554,"mc":[{"id":"1.195532863","rc":[{"atb":[[2.98,0],[2.9,0],[3.15,0]],"id":35839928},{"atl":[[4.8,2.5],[4.3,36.36],[4.9,25.64],[4.4,0]],"id":8668222}],"con":true,"img":false}]}
{"op":"mcm","clk":"5322481658","pt":1646320738657,"mc":[{"id":"1.195532863","rc":[{"atb":[[3.05,6.12]],"id":35839928}],"con":true,"img":false}]}
{"op":"mcm","clk":"5322481666","pt":1646320738763,"mc":[{"id":"1.195532863","rc":[{"atb":[[3.3,0]],"id":35839928}],"con":true,"img":false}]}
{"op":"mcm","clk":"5322481674","pt":1646320738869,"mc":[{"id":"1.195532863","rc":[{"atb":[[3.4,3.98]],"id":35839928}],"con":true,"img":false}]}
{"op":"mcm","clk":"5322481682","pt":1646320738972,"mc":[{"id":"1.195532863","rc":[{"atb":[[3.2,20.14]],"id":35839928}],"con":true,"img":false}]}
{"op":"mcm","clk":"5322481697","pt":1646320739139,"mc":[{"id":"1.195532863","rc":[{"atb":[[3.05,0]],"id":35839928}],"con":true,"img":false}]}
{"op":"mcm","clk":"5322481744","pt":1646320739770,"mc":[{"id":"1.195532863","rc":[{"atb":[[2.38,0]],"id":28603683}],"con":true,"img":false}]}
{"op":"mcm","clk":"5322481765","pt":1646320740075,"mc":[{"id":"1.195532863","rc":[{"atb":[[2.4,0]],"id":28603683}],"con":true,"img":false}]}
{"op":"mcm","clk":"5322481774","pt":1646320740128,"mc":[{"id":"1.195532863","rc":[{"atb":[[2.38,1.99]],"id":28603683}],"con":true,"img":false}]}
{"op":"mcm","clk":"5322481832","pt":1646320740764,"mc":[{"id":"1.195532863","rc":[{"atb":[[2.32,11.75]],"id":28603683}],"con":true,"img":false}]}
{"op":"mcm","clk":"5322481867","pt":1646320741140,"mc":[{"id":"1.195532863","rc":[{"atb":[[2.72,7.03],[2.7,0]],"id":39693066},{"atb":[[3.2,16.82],[3.1,47.62]],"id":35839928},{"atb":[[2.44,2.15]],"id":8668222},{"atl":[[4.3,24.24],[4.2,12.5]],"id":8668222}],"con":true,"img":false}]}
{"op":"mcm","clk":"5322481925","pt":1646320741701,"mc":[{"id":"1.195532863","rc":[{"atb":[[2.2,68.32]],"id":8668222}],"con":true,"img":false}]}
{"op":"mcm","clk":"5322481988","pt":1646320742641,"mc":[{"id":"1.195532863","rc":[{"atb":[[3.35,7.35]],"id":35839928},{"atb":[[2.42,0]],"id":28603683}],"con":true,"img":false}]}
{"op":"mcm","clk":"5322482006","pt":1646320742850,"mc":[{"id":"1.195532863","rc":[{"atb":[[3.45,1.65]],"id":35839928},{"atb":[[2.4,1.65]],"id":28603683}],"con":true,"img":false}]}
{"op":"mcm","clk":"5322482090","pt":1646320743948,"mc":[{"id":"1.195532863","rc":[{"atb":[[2.26,5.1]],"id":28603683}],"con":true,"img":false}]}
{"op":"mcm","clk":"5322482156","pt":1646320744692,"mc":[{"id":"1.195532863","rc":[{"atb":[[2.3,30.77],[2.66,19.41]],"id":39693066}],"con":true,"img":false}]}
{"op":"mcm","clk":"5322482166","pt":1646320744887,"mc":[{"id":"1.195532863","rc":[{"atl":[[3.95,13.27]],"id":8668222}],"con":true,"img":false}]}
{"op":"mcm","clk":"5322482182","pt":1646320745046,"mc":[{"id":"1.195532863","rc":[{"atl":[[4.3,0]],"id":8668222}],"con":true,"img":false}]}
{"op":"mcm","clk":"5322482189","pt":1646320745151,"mc":[{"id":"1.195532863","rc":[{"atl":[[4.8,0],[5.6,0],[4.1,18.1],[5.2,0],[4.2,0]],"id":8668222}],"con":true,"img":false}]}
{"op":"mcm","clk":"5322482196","pt":1646320745257,"mc":[{"id":"1.195532863","rc":[{"atl":[[4.1,12.9],[4.7,2.5]],"id":8668222}],"con":true,"img":false}]}
{"op":"mcm","clk":"5322482203","pt":1646320745361,"mc":[{"id":"1.195532863","rc":[{"atl":[[4.1,45.16]],"id":8668222}],"con":true,"img":false}]}
{"op":"mcm","clk":"5322482215","pt":1646320745463,"mc":[{"id":"1.195532863","rc":[{"atl":[[4,0],[5.2,11.39]],"id":8668222}],"con":true,"img":false}]}
{"op":"mcm","clk":"5322482232","pt":1646320745671,"mc":[{"id":"1.195532863","rc":[{"atl":[[3.95,0]],"id":8668222}],"con":true,"img":false}]}
{"op":"mcm","clk":"5322482241","pt":1646320745777,"mc":[{"id":"1.195532863","rc":[{"atl":[[4,11.83]],"id":8668222}],"con":true,"img":false}]}
{"op":"mcm","clk":"5322482250","pt":1646320745881,"mc":[{"id":"1.195532863","rc":[{"atl":[[4.9,98.63],[5.2,0]],"id":8668222}],"con":true,"img":false}]}
{"op":"mcm","clk":"5322482267","pt":1646320746147,"mc":[{"id":"1.195532863","rc":[{"atb":[[2.22,7.25]],"id":8668222},{"atl":[[4.1,32.26],[4.2,12.5]],"id":8668222}],"con":true,"img":false}]}
{"op":"mcm","clk":"5322482274","pt":1646320746247,"mc":[{"id":"1.195532863","rc":[{"atb":[[2.22,37.66]],"id":8668222}],"con":true,"img":false}]}
{"op":"mcm","clk":"5322482281","pt":1646320746355,"mc":[{"id":"1.195532863","rc":[{"atb":[[2.72,0],[2.7,10.74]],"id":39693066},{"atb":[[2.2,0]],"id":8668222}],"con":true,"img":false}]}
{"op":"mcm","clk":"5322482339","pt":1646320747187,"mc":[{"id":"1.195532863","rc":[{"atl":[[3.9,5.45]],"id":8668222}],"con":true,"img":false}]}
{"op":"mcm","clk":"5322482521","pt":1646320749491,"mc":[{"id":"1.195532863","rc":[{"atl":[[4,25.16],[4.2,0]],"id":8668222}],"con":true,"img":false}]}
{"op":"mcm","clk":"5322482559","pt":1646320749963,"mc":[{"id":"1.195532863","rc":[{"atb":[[2.22,30.41]],"id":8668222}],"con":true,"img":false}]}
{"op":"mcm","clk":"5322482680","pt":1646320751679,"mc":[{"id":"1.195532863","rc":[{"atl":[[3.85,18.83]],"id":8668222}],"con":true,"img":false}]}
{"op":"mcm","clk":"5322482690","pt":1646320751784,"mc":[{"id":"1.195532863","rc":[{"atb":[[3.25,28.46],[3.45,9]],"id":35839928},{"atl":[[4,13.33]],"id":8668222}],"con":true,"img":false}]}
{"op":"mcm","clk":"5322482699","pt":1646320751887,"mc":[{"id":"1.195532863","rc":[{"atb":[[3.2,2.5]],"id":35839928},{"atl":[[3.85,37.66],[4.1,0]],"id":8668222}],"con":true,"img":false}]}
{"op":"mcm","clk":"5322482707","pt":1646320751993,"mc":[{"id":"1.195532863","rc":[{"atb":[[3.35,0],[3.4,1.99]],"id":35839928}],"con":true,"img":false}]}
{"op":"mcm","clk":"5322482714","pt":1646320752095,"mc":[{"id":"1.195532863","rc":[{"atb":[[3.5,1.99]],"id":35839928},{"atl":[[4,0],[3.95,13.56]],"id":8668222}],"con":true,"img":false}]}
{"op":"mcm","clk":"5322482733","pt":1646320752257,"mc":[{"id":"1.195532863","rc":[{"atb":[[3.2,10.26]],"id":35839928}],"con":true,"img":false}]}
{"op":"mcm","clk":"5322482740","pt":1646320752358,"mc":[{"id":"1.195532863","rc":[{"atb":[[3.4,0]],"id":35839928},{"atl":[[3.95,80],[4.9,25.64]],"id":8668222}],"con":true,"img":false}]}
{"op":"mcm","clk":"5322482745","pt":1646320752465,"mc":[{"id":"1.195532863","rc":[{"atb":[[3.5,3.98]],"id":35839928}],"con":true,"img":false}]}
{"op":"mcm","clk":"5322482774","pt":1646320752829,"mc":[{"id":"1.195532863","rc":[{"atb":[[3.2,2.5]],"id":35839928}],"con":true,"img":false}]}
{"op":"mcm","clk":"5322482780","pt":1646320752894,"mc":[{"id":"1.195532863","rc":[{"atb":[[2.72,10.74],[2.7,0]],"id":39693066}],"con":true,"img":false}]}
{"op":"mcm","clk":"5322482843","pt":1646320753976,"mc":[{"id":"1.195532863","rc":[{"atl":[[3.9,0]],"id":8668222}],"con":true,"img":false}]}
{"op":"mcm","clk":"5322482865","pt":1646320754288,"mc":[{"id":"1.195532863","rc":[{"atb":[[2.24,6.87]],"id":8668222}],"con":true,"img":false}]}
{"op":"mcm","clk":"5322482876","pt":1646320754391,"mc":[{"id":"1.195532863","rc":[{"atb":[[2.22,0],[2.24,40.03]],"id":8668222}],"con":true,"img":false}]}
{"op":"mcm","clk":"5322482943","pt":1646320755285,"mc":[{"id":"1.195532863","rc":[{"atb":[[2.7,3.82]],"id":39693066}],"con":true,"img":false}]}
{"op":"mcm","clk":"5322482951","pt":1646320755387,"mc":[{"id":"1.195532863","rc":[{"atb":[[2.7,0]],"id":39693066}],"con":true,"img":false}]}
{"op":"mcm","clk":"5322483033","pt":1646320756174,"mc":[{"id":"1.195532863","rc":[{"atl":[[3.6,38.46],[3.55,138.15]],"id":28691352}],"con":true,"img":false}]}
{"op":"mcm","clk":"5322483114","pt":1646320757007,"mc":[{"id":"1.195532863","rc":[{"atl":[[3.85,18.83],[4.7,29.53]],"id":8668222}],"con":true,"img":false}]}
{"op":"mcm","clk":"5322483130","pt":1646320757164,"mc":[{"id":"1.195532863","rc":[{"atl":[[3.85,0]],"id":8668222}],"con":true,"img":false}]}
{"op":"mcm","clk":"5322483149","pt":1646320757372,"mc":[{"id":"1.195532863","rc":[{"atl":[[3.9,16.37]],"id":8668222}],"con":true,"img":false}]}
{"op":"mcm","clk":"5322483184","pt":1646320757793,"mc":[{"id":"1.195532863","rc":[{"atb":[[3.45,7.35]],"id":35839928}],"con":true,"img":false}]}
{"op":"mcm","clk":"5322483197","pt":1646320758004,"mc":[{"id":"1.195532863","rc":[{"atb":[[3.55,1.65]],"id":35839928}],"con":true,"img":false}]}
{"op":"mcm","clk":"5322483258","pt":1646320758796,"mc":[{"id":"1.195532863","rc":[{"atl":[[4,3.56],[3.95,13.56],[4.7,107.59]],"id":8668222}],"con":true,"img":false}]}
{"op":"mcm","clk":"5322483273","pt":1646320758960,"mc":[{"id":"1.195532863","rc":[{"atl":[[4,0]],"id":8668222}],"con":true,"img":false}]}
{"op":"mcm","clk":"5322483394","pt":1646320760377,"mc":[{"id":"1.195532863","rc":[{"atb":[[2.24,33.16]],"id":8668222}],"con":true,"img":false}]}
{"op":"mcm","clk":"5322483465","pt":1646320761164,"mc":[{"id":"1.195532863","rc":[{"atl":[[5.6,21.74],[5.1,17],[5.5,5],[5.2,0]],"id":36042617},{"atl":[[4,13.33],[3.95,0]],"id":8668222}],"con":true,"img":false}]}
{"op":"mcm","clk":"5322483472","pt":1646320761266,"mc":[{"id":"1.195532863","rc":[{"atl":[[5.1,34],[5.3,9.3],[5.5,41.22]],"id":36042617}],"con":true,"img":false}]}
{"op":"mcm","clk":"5322483482","pt":1646320761368,"mc":[{"id":"1.195532863","rc":[{"atl":[[5.3,15.68]],"id":36042617}],"con":true,"img":false}]}
{"op":"mcm","clk":"5322483491","pt":1646320761475,"mc":[{"id":"1.195532863","rc":[{"atl":[[5.3,9.3],[5.4,3.31]],"id":36042617}],"con":true,"img":false}]}
{"op":"mcm","clk":"5322483538","pt":1646320762099,"mc":[{"id":"1.195532863","rc":[{"atl":[[5.4,0]],"id":36042617}],"con":true,"img":false}]}
{"op":"mcm","clk":"5322483588","pt":1646320762575,"mc":[{"id":"1.195532863","rc":[{"atb":[[2.4,0],[2.38,31.75]],"id":36042617},{"atb":[[2.44,13.77]],"id":8668222}],"con":true,"img":false}]}
{"op":"mcm","clk":"5322483601","pt":1646320762781,"mc":[{"id":"1.195532863","rc":[{"atb":[[2.16,16.69]],"id":8668222}],"con":true,"img":false}]}
{"op":"mcm","clk":"5322483616","pt":1646320762990,"mc":[{"id":"1.195532863","rc":[{"atb":[[2.16,0]],"id":8668222}],"con":true,"img":false}]}
{"op":"mcm","clk":"5322483689","pt":1646320763974,"mc":[{"id":"1.195532863","rc":[{"atb":[[2.8,2]],"id":39693066},{"atb":[[2.52,2.64]],"id":36042617},{"atb":[[3.6,2.71]],"id":35839928},{"atb":[[2.42,2.94]],"id":28603683},{"atb":[[2.48,2.75]],"id":8668222},{"atb":[[1.82,3.37]],"id":28691352}],"con":true,"img":false}]}
{"op":"mcm","clk":"5322483695","pt":1646320764081,"mc":[{"id":"1.195532863","rc":[{"atb":[[2.8,7.9],[2.72,27.65],[2.66,2.5]],"id":39693066},{"atb":[[2.42,0],[2.52,13.73],[2.46,22.71]],"id":36042617},{"atb":[[2.32,2.5]],"id":28603683},{"atb":[[2.24,0],[2.28,59.42]],"id":8668222},{"atb":[[1.73,51.27],[1.72,55.56]],"id":28691352}],"con":true,"img":false}]}
{"op":"mcm","clk":"5322483703","pt":1646320764187,"mc":[{"id":"1.195532863","rc":[{"atb":[[2.7,5.37]],"id":39693066},{"atb":[[1.82,19.91]],"id":28691352}],"con":true,"img":false}]}
{"op":"mcm","clk":"5322483712","pt":1646320764291,"mc":[{"id":"1.195532863","rc":[{"atb":[[2.76,1.99]],"id":39693066},{"atb":[[2.48,0]],"id":36042617}],"con":true,"img":false}]}
{"op":"mcm","clk":"5322483720","pt":1646320764392,"mc":[{"id":"1.195532863","rc":[{"atb":[[2.54,1.99]],"id":36042617},{"atb":[[1.8,0]],"id":28691352}],"con":true,"img":false}]}
{"op":"mcm","clk":"5322483728","pt":1646320764498,"mc":[{"id":"1.195532863","rc":[{"atb":[[2.7,4.49]],"id":39693066},{"atb":[[2.44,3.01],[2.56,2.52],[2.38,35.09]],"id":36042617},{"atb":[[2.26,5.52]],"id":8668222},{"atb":[[1.72,62.02]],"id":28691352}],"con":true,"img":false}]}
{"op":"mcm","clk":"5322483737","pt":1646320764600,"mc":[{"id":"1.195532863","rc":[{"atb":[[2.7,0]],"id":39693066}],"con":true,"img":false}]}
{"op":"mcm","clk":"5322483743","pt":1646320764704,"mc":[{"id":"1.195532863","rc":[{"atb":[[2.76,0]],"id":39693066},{"atb":[[2.44,0],[2.58,2.15],[2.38,31.75],[2.46,20.56]],"id":36042617},{"atb":[[2.3,5.72],[2.26,0]],"id":8668222},{"atb":[[1.72,55.56]],"id":28691352}],"con":true,"img":false}]}
{"op":"mcm","clk":"5322483751","pt":1646320764805,"mc":[{"id":"1.195532863","rc":[{"atb":[[2.82,1.99]],"id":39693066}],"con":true,"img":false}]}
{"op":"mcm","clk":"5322483764","pt":1646320764968,"mc":[{"id":"1.195532863","rc":[{"atb":[[2.84,1.93]],"id":39693066},{"atb":[[2.38,0]],"id":28603683},{"atb":[[1.71,3.7]],"id":28691352}],"con":true,"img":false}]}
{"op":"mcm","clk":"5322483772","pt":1646320765069,"mc":[{"id":"1.195532863","rc":[{"atb":[[2.32,11.96],[2.44,1.99]],"id":28603683}],"con":true,"img":false}]}
{"op":"mcm","clk":"5322483777","pt":1646320765173,"mc":[{"id":"1.195532863","rc":[{"atb":[[2.46,2.81]],"id":28603683}],"con":true,"img":false}]}
{"op":"mcm","clk":"5322483794","pt":1646320765385,"mc":[{"id":"1.195532863","rc":[{"atb":[[3.5,1.99]],"id":35839928},{"atb":[[2.32,2.49]],"id":28603683}],"con":true,"img":false}]}
{"op":"mcm","clk":"5322483805","pt":1646320765488,"mc":[{"id":"1.195532863","rc":[{"atb":[[3.6,7.73],[3.25,12],[3.45,21.67],[3.65,1.99]],"id":35839928},{"atb":[[1.71,0]],"id":28691352}],"con":true,"img":false}]}
{"op":"mcm","clk":"5322483814","pt":1646320765592,"mc":[{"id":"1.195532863","rc":[{"atb":[[2.78,0]],"id":39693066},{"atb":[[2.5,0]],"id":36042617},{"atb":[[3.55,0],[3.7,2.54]],"id":35839928},{"atb":[[2.4,0]],"id":28603683},{"atb":[[2.46,0]],"id":8668222}],"con":true,"img":false}]}
{"op":"mcm","clk":"5322483821","pt":1646320765698,"mc":[{"id":"1.195532863","rc":[{"atb":[[3.45,14.32]],"id":35839928}],"con":true,"img":false}]}
{"op":"mcm","clk":"5322483830","pt":1646320765801,"mc":[{"id":"1.195532863","rc":[{"atb":[[2.6,1.65]],"id":36042617},{"atb":[[3.65,3.64]],"id":35839928},{"atb":[[2.48,1.65]],"id":28603683},{"atb":[[2.5,1.65]],"id":8668222},{"atb":[[1.81,0]],"id":28691352}],"con":true,"img":false}]}
{"op":"mcm","clk":"5322483846","pt":1646320765906,"mc":[{"id":"1.195532863","rc":[{"atb":[[1.83,1.99]],"id":28691352}],"con":true,"img":false}]}
{"op":"mcm","clk":"5322483850","pt":1646320766012,"mc":[{"id":"1.195532863","rc":[{"atb":[[2.5,2.69]],"id":28603683},{"atb":[[1.84,3.26]],"id":28691352}],"con":true,"img":false}]}
{"op":"mcm","clk":"5322483864","pt":1646320766171,"mc":[{"id":"1.195532863","rc":[{"atb":[[2.54,0]],"id":36042617}],"con":true,"img":false}]}
{"op":"mcm","clk":"5322483869","pt":1646320766278,"mc":[{"id":"1.195532863","rc":[{"atb":[[2.6,3.64]],"id":36042617}],"con":true,"img":false}]}
{"op":"mcm","clk":"5322483878","pt":1646320766385,"mc":[{"id":"1.195532863","rc":[{"atl":[[5.5,63.44]],"id":36042617}],"con":true,"img":false}]}
{"op":"mcm","clk":"5322483884","pt":1646320766488,"mc":[{"id":"1.195532863","rc":[{"atl":[[5.1,17]],"id":36042617},{"atb":[[2.44,0]],"id":28603683}],"con":true,"img":false}]}
{"op":"mcm","clk":"5322483890","pt":1646320766608,"mc":[{"id":"1.195532863","rc":[{"atb":[[2.26,0],[2.48,3.64]],"id":28603683}],"con":true,"img":false}]}
{"op":"mcm","clk":"5322483908","pt":1646320766864,"mc":[{"id":"1.195532863","rc":[{"atb":[[3.65,1.65]],"id":35839928}],"con":true,"img":false}]}
{"op":"mcm","clk":"5322483912","pt":1646320766966,"mc":[{"id":"1.195532863","rc":[{"atb":[[3.75,1.99]],"id":35839928}],"con":true,"img":false}]}
{"op":"mcm","clk":"5322483919","pt":1646320767073,"mc":[{"id":"1.195532863","rc":[{"atb":[[3.8,2.39]],"id":35839928}],"con":true,"img":false}]}
{"op":"mcm","clk":"5322483953","pt":1646320767599,"mc":[{"id":"1.195532863","rc":[{"atb":[[2.72,16.91],[2.74,5]],"id":39693066},{"atb":[[2.48,1.65]],"id":28603683},{"atb":[[2.44,2.15]],"id":8668222},{"atb":[[1.82,3.37]],"id":28691352},{"atl":[[3.35,0]],"id":28691352}],"con":true,"img":false}]}
{"op":"mcm","clk":"5322483962","pt":1646320767700,"mc":[{"id":"1.195532863","rc":[{"atb":[[2.52,1.99]],"id":28603683},{"atl":[[3.4,27.18]],"id":28691352}],"con":true,"img":false}]}
{"op":"mcm","clk":"5322483969","pt":1646320767805,"mc":[{"id":"1.195532863","rc":[{"atb":[[2.54,2.58]],"id":28603683},{"atl":[[3.6,142.14],[3.4,35.69],[3.55,41.72]],"id":28691352}],"con":true,"img":false}]}
{"op":"mcm","clk":"5322483984","pt":1646320768014,"mc":[{"id":"1.195532863","rc":[{"atb":[[3.75,0]],"id":35839928},{"atb":[[2.3,29.55],[2.28,19.66]],"id":8668222},{"atl":[[3.4,27.18]],"id":28691352}],"con":true,"img":false}]}
{"op":"mcm","clk":"5322483994","pt":1646320768071,"mc":[{"id":"1.195532863","rc":[{"atb":[[3.85,1.99]],"id":35839928},{"atl":[[5.2,33.33]],"id":28603683},{"atl":[[3.55,46.72]],"id":28691352}],"con":true,"img":false}]}
{"op":"mcm","clk":"5322484003","pt":1646320768172,"mc":[{"id":"1.195532863","rc":[{"atb":[[3.6,5.02],[3.8,0],[3.7,0]],"id":35839928},{"atl":[[5.3,44.4],[5.2,9.52]],"id":28603683},{"atl":[[3.6,103.68],[3.5,56]],"id":28691352}],"con":true,"img":false}]}
{"op":"mcm","clk":"5322484015","pt":1646320768279,"mc":[{"id":"1.195532863","rc":[{"atl":[[3.45,0],[3.55,44.72]],"id":28691352}],"con":true,"img":false}]}
{"op":"mcm","clk":"5322484031","pt":1646320768492,"mc":[{"id":"1.195532863","rc":[{"atb":[[1.83,0]],"id":28691352}],"con":true,"img":false}]}
{"op":"mcm","clk":"5322484040","pt":1646320768596,"mc":[{"id":"1.195532863","rc":[{"atb":[[3.9,2.25]],"id":35839928},{"atb":[[1.82,0],[1.84,0],[1.85,1.99]],"id":28691352},{"atl":[[3.55,41.72]],"id":28691352}],"con":true,"img":false}]}
{"op":"mcm","clk":"5322484059","pt":1646320768804,"mc":[{"id":"1.195532863","rc":[{"atb":[[2.3,23.83]],"id":8668222},{"atb":[[1.73,39.71],[1.74,54.44]],"id":28691352}],"con":true,"img":false}]}
{"op":"mcm","clk":"5322484075","pt":1646320769014,"mc":[{"id":"1.195532863","rc":[{"atb":[[2.52,0]],"id":28603683},{"atb":[[1.86,3.15]],"id":28691352}],"con":true,"img":false}]}
{"op":"mcm","clk":"5322484085","pt":1646320769071,"mc":[{"id":"1.195532863","rc":[{"atb":[[2.56,1.99]],"id":28603683}],"con":true,"img":false}]}
{"op":"mcm","clk":"5322484091","pt":1646320769176,"mc":[{"id":"1.195532863","rc":[{"atb":[[2.54,0],[2.5,0],[2.42,0],[2.46,0]],"id":28603683}],"con":true,"img":false}]}
{"op":"mcm","clk":"5322484112","pt":1646320769383,"mc":[{"id":"1.195532863","rc":[{"atb":[[3.85,0]],"id":35839928}],"con":true,"img":false}]}
{"op":"mcm","clk":"5322484134","pt":1646320769544,"mc":[{"id":"1.195532863","rc":[{"atb":[[3.95,1.99],[3.9,0]],"id":35839928},{"atb":[[2.58,2.48]],"id":28603683}],"con":true,"img":false}]}
{"op":"mcm","clk":"5322484147","pt":1646320769701,"mc":[{"id":"1.195532863","rc":[{"atb":[[3.95,4.18]],"id":35839928},{"atb":[[1.01,4806.04]],"id":28691352}],"con":true,"img":false}]}
{"op":"mcm","clk":"5322484155","pt":1646320769803,"mc":[{"id":"1.195532863","rc":[{"atb":[[1.01,4808.03]],"id":28691352}],"con":true,"img":false}]}
{"op":"mcm","clk":"5322484176","pt":1646320770065,"mc":[{"id":"1.195532863","rc":[{"atb":[[1.01,4806.04]],"id":28691352}],"con":true,"img":false}]}
{"op":"mcm","clk":"5322484185","pt":1646320770171,"mc":[{"id":"1.195532863","rc":[{"atb":[[1.74,56.43]],"id":28691352}],"con":true,"img":false}]}
{"op":"mcm","clk":"5322484210","pt":1646320770618,"mc":[{"id":"1.195532863","rc":[{"atb":[[2.56,0]],"id":28603683}],"con":true,"img":false}]}
{"op":"mcm","clk":"5322484221","pt":1646320770673,"mc":[{"id":"1.195532863","rc":[{"atb":[[2.6,1.99]],"id":28603683}],"con":true,"img":false}]}
{"op":"mcm","clk":"5322484228","pt":1646320770774,"mc":[{"id":"1.195532863","rc":[{"atb":[[2.58,0],[2.62,2.38]],"id":28603683},{"atl":[[4.2,31.25]],"id":8668222}],"con":true,"img":false}]}
{"op":"mcm","clk":"5322484235","pt":1646320770881,"mc":[{"id":"1.195532863","rc":[{"atb":[[1.2,2.24]],"id":28603683},{"atl":[[4.1,31.25],[4.2,90.65],[4.7,2.5]],"id":8668222},{"atb":[[1.74,54.44]],"id":28691352}],"con":true,"img":false}]}
{"op":"mcm","clk":"5322484245","pt":1646320770987,"mc":[{"id":"1.195532863","rc":[{"atb":[[1.87,1.99]],"id":28691352}],"con":true,"img":false}]}
{"op":"mcm","clk":"5322484251","pt":1646320771088,"mc":[{"id":"1.195532863","rc":[{"atb":[[1.88,3.04]],"id":28691352}],"con":true,"img":false}]}
{"op":"mcm","clk":"5322484259","pt":1646320771195,"mc":[{"id":"1.195532863","rc":[{"atb":[[1.2,1.8]],"id":28603683}],"con":true,"img":false}]}
{"op":"mcm","clk":"5322484279","pt":1646320771515,"mc":[{"id":"1.195532863","rc":[{"atb":[[1.2,0],[2.6,0]],"id":28603683}],"con":true,"img":false}]}
{"op":"mcm","clk":"5322484288","pt":1646320771618,"mc":[{"id":"1.195532863","rc":[{"atb":[[2.64,1.99],[2.56,1.8]],"id":28603683}],"con":true,"img":false}]}
{"op":"mcm","clk":"5322484304","pt":1646320771783,"mc":[{"id":"1.195532863","rc":[{"atb":[[2.62,0],[2.66,2.29]],"id":28603683},{"atb":[[1.85,0]],"id":28691352}],"con":true,"img":false}]}
{"op":"mcm","clk":"5322484312","pt":1646320771886,"mc":[{"id":"1.195532863","rc":[{"atb":[[1.89,1.99]],"id":28691352}],"con":true,"img":false}]}
{"op":"mcm","clk":"5322484328","pt":1646320772204,"mc":[{"id":"1.195532863","rc":[{"atb":[[2.64,0]],"id":28603683}],"con":true,"img":false}]}
{"op":"mcm","clk":"5322484339","pt":1646320772309,"mc":[{"id":"1.195532863","rc":[{"atb":[[2.68,1.99]],"id":28603683}],"con":true,"img":false}]}
{"op":"mcm","clk":"5322484348","pt":1646320772411,"mc":[{"id":"1.195532863","rc":[{"atb":[[2.66,0],[2.7,2.21]],"id":28603683},{"atl":[[4.1,90.65],[4.2,31.25]],"id":8668222}],"con":true,"img":false}]}
{"op":"mcm","clk":"5322484364","pt":1646320772678,"mc":[{"id":"1.195532863","rc":[{"atl":[[4.9,41.34]],"id":8668222}],"con":true,"img":false}]}
{"op":"mcm","clk":"5322484370","pt":1646320772781,"mc":[{"id":"1.195532863","rc":[{"atb":[[1.9,2.94]],"id":28691352}],"con":true,"img":false}]}
{"op":"mcm","clk":"5322484378","pt":1646320772886,"mc":[{"id":"1.195532863","rc":[{"atl":[[5.1,0],[5.3,0],[4.9,15.7]],"id":8668222}],"con":true,"img":false}]}
{"op":"mcm","clk":"5322484385","pt":1646320772993,"mc":[{"id":"1.195532863","rc":[{"atb":[[2.68,0]],"id":28603683},{"atb":[[1.73,2.15]],"id":28691352}],"con":true,"img":false}]}
{"op":"mcm","clk":"5322484390","pt":1646320773097,"mc":[{"id":"1.195532863","rc":[{"atb":[[2.72,1.99]],"id":28603683},{"atl":[[4.9,0]],"id":8668222}],"con":true,"img":false}]}
{"op":"mcm","clk":"5322484396","pt":1646320773199,"mc":[{"id":"1.195532863","rc":[{"atb":[[2.74,2.12],[2.7,0]],"id":28603683}],"con":true,"img":false}]}
{"op":"mcm","clk":"5322484403","pt":1646320773307,"mc":[{"id":"1.195532863","rc":[{"atb":[[1.89,0]],"id":28691352}],"con":true,"img":false}]}
{"op":"mcm","clk":"5322484412","pt":1646320773408,"mc":[{"id":"1.195532863","rc":[{"atb":[[1.91,1.99]],"id":28691352},{"atl":[[3.55,80.94],[3.5,16]],"id":28691352}],"con":true,"img":false}]}
{"op":"mcm","clk":"5322484419","pt":1646320773511,"mc":[{"id":"1.195532863","rc":[{"atb":[[2.32,7.05]],"id":8668222},{"atb":[[1.88,0],[1.9,0],[1.86,0],[1.75,5.98]],"id":28691352}],"con":true,"img":false}]}
{"op":"mcm","clk":"5322484439","pt":1646320773673,"mc":[{"id":"1.195532863","rc":[{"atb":[[3.65,0]],"id":35839928},{"atb":[[2.48,0]],"id":28603683}],"con":true,"img":false}]}
{"op":"mcm","clk":"5322484446","pt":1646320773777,"mc":[{"id":"1.195532863","rc":[{"atb":[[2.86,1.65]],"id":39693066},{"atb":[[4,1.65]],"id":35839928}],"con":true,"img":false}]}
{"op":"mcm","clk":"5322484452","pt":1646320773884,"mc":[{"id":"1.195532863","rc":[{"atb":[[2.88,1.86]],"id":39693066},{"atb":[[4.1,4.04]],"id":35839928}],"con":true,"img":false}]}
{"op":"mcm","clk":"5322484505","pt":1646320774816,"mc":[{"id":"1.195532863","rc":[{"atb":[[2.82,0]],"id":39693066}],"con":true,"img":false}]}
{"op":"mcm","clk":"5322484510","pt":1646320774873,"mc":[{"id":"1.195532863","rc":[{"atb":[[2.88,3.85]],"id":39693066}],"con":true,"img":false}]}
{"op":"mcm","clk":"5322484529","pt":1646320775087,"mc":[{"id":"1.195532863","rc":[{"atb":[[2.72,0]],"id":28603683}],"con":true,"img":false}]}
{"op":"mcm","clk":"5322484538","pt":1646320775187,"mc":[{"id":"1.195532863","rc":[{"atb":[[2.76,1.99]],"id":28603683},{"atb":[[1.73,0],[1.78,2.15]],"id":28691352}],"con":true,"img":false}]}
{"op":"mcm","clk":"5322484545","pt":1646320775291,"mc":[{"id":"1.195532863","rc":[{"atb":[[2.74,0],[2.78,2.04]],"id":28603683}],"con":true,"img":false}]}
{"op":"mcm","clk":"5322484551","pt":1646320775398,"mc":[{"id":"1.195532863","rc":[{"atb":[[3.95,2.19]],"id":35839928},{"atb":[[2.56,0]],"id":28603683}],"con":true,"img":false}]}
{"op":"mcm","clk":"5322484562","pt":1646320775502,"mc":[{"id":"1.195532863","rc":[{"atb":[[1.02,1.99]],"id":35839928}],"con":true,"img":false}]}
{"op":"mcm","clk":"5322484578","pt":1646320775711,"mc":[{"id":"1.195532863","rc":[{"atb":[[1.91,0]],"id":28691352}],"con":true,"img":false}]}
{"op":"mcm","clk":"5322484587","pt":1646320775817,"mc":[{"id":"1.195532863","rc":[{"atb":[[1.88,1.99]],"id":28691352}],"con":true,"img":false}]}
{"op":"mcm","clk":"5322484595","pt":1646320775921,"mc":[{"id":"1.195532863","rc":[{"atb":[[1.88,5.03]],"id":28691352}],"con":true,"img":false}]}
{"op":"mcm","clk":"5322484603","pt":1646320775974,"mc":[{"id":"1.195532863","rc":[{"atb":[[2.88,1.86]],"id":39693066}],"con":true,"img":false}]}
{"op":"mcm","clk":"5322484613","pt":1646320776083,"mc":[{"id":"1.195532863","rc":[{"atb":[[2.86,3.64]],"id":39693066}],"con":true,"img":false}]}
{"op":"mcm","clk":"5322484626","pt":1646320776292,"mc":[{"id":"1.195532863","rc":[{"atb":[[2.76,0]],"id":28603683}],"con":true,"img":false}]}
{"op":"mcm","clk":"5322484637","pt":1646320776397,"mc":[{"id":"1.195532863","rc":[{"atb":[[2.8,1.99]],"id":28603683}],"con":true,"img":false}]}
{"op":"mcm","clk":"5322484647","pt":1646320776501,"mc":[{"id":"1.195532863","rc":[{"atb":[[2.82,1.97],[2.78,0]],"id":28603683}],"con":true,"img":false}]}
{"op":"mcm","clk":"5322484654","pt":1646320776606,"mc":[{"id":"1.195532863","rc":[{"atb":[[3.5,0]],"id":35839928}],"con":true,"img":false}]}
{"op":"mcm","clk":"5322484663","pt":1646320776711,"mc":[{"id":"1.195532863","rc":[{"atb":[[1.02,3.98]],"id":35839928}],"con":true,"img":false}]}
{"op":"mcm","clk":"5322484672","pt":1646320776813,"mc":[{"id":"1.195532863","rc":[{"atb":[[1.87,0]],"id":28691352}],"con":true,"img":false}]}
{"op":"mcm","clk":"5322484681","pt":1646320776918,"mc":[{"id":"1.195532863","rc":[{"atb":[[1.79,1.99]],"id":28691352}],"con":true,"img":false}]}
{"op":"mcm","clk":"5322484694","pt":1646320777078,"mc":[{"id":"1.195532863","rc":[{"atb":[[2.8,0]],"id":28603683}],"con":true,"img":false}]}
{"op":"mcm","clk":"5322484702","pt":1646320777179,"mc":[{"id":"1.195532863","rc":[{"atb":[[2.38,1.99]],"id":28603683}],"con":true,"img":false}]}
{"op":"mcm","clk":"5322484709","pt":1646320777284,"mc":[{"id":"1.195532863","rc":[{"atb":[[2.82,0]],"id":28603683}],"con":true,"img":false}]}
{"op":"mcm","clk":"5322484715","pt":1646320777388,"mc":[{"id":"1.195532863","rc":[{"atb":[[2.4,3.01]],"id":28603683},{"atb":[[1.79,0]],"id":28691352}],"con":true,"img":false}]}
{"op":"mcm","clk":"5322484727","pt":1646320777494,"mc":[{"id":"1.195532863","rc":[{"atb":[[1.89,1.99]],"id":28691352}],"con":true,"img":false}]}
{"op":"mcm","clk":"5322484734","pt":1646320777598,"mc":[{"id":"1.195532863","rc":[{"atb":[[2.72,0],[2.88,6.47],[2.74,20.01]],"id":39693066},{"atb":[[2.56,18.71],[2.46,0]],"id":36042617},{"atb":[[2.32,32.53],[2.3,0]],"id":8668222},{"atb":[[1.9,2.94],[1.75,33.47]],"id":28691352}],"con":true,"img":false}]}
{"op":"mcm","clk":"5322484748","pt":1646320777808,"mc":[{"id":"1.195532863","rc":[{"atb":[[2.8,2]],"id":39693066},{"atb":[[2.38,0]],"id":28603683},{"atl":[[3.6,142.14]],"id":28691352}],"con":true,"img":false}]}
{"op":"mcm","clk":"5322484756","pt":1646320777912,"mc":[{"id":"1.195532863","rc":[{"atb":[[2.42,1.99]],"id":28603683}],"con":true,"img":false}]}
{"op":"mcm","clk":"5322484766","pt":1646320778118,"mc":[{"id":"1.195532863","rc":[{"atb":[[2.86,1.65]],"id":39693066},{"atb":[[2.44,2.87]],"id":28603683}],"con":true,"img":false}]}
{"op":"mcm","clk":"5322484770","pt":1646320778220,"mc":[{"id":"1.195532863","rc":[{"atb":[[2.9,1.99]],"id":39693066}],"con":true,"img":false}]}
{"op":"mcm","clk":"5322484778","pt":1646320778380,"mc":[{"id":"1.195532863","rc":[{"atb":[[2.92,1.8]],"id":39693066}],"con":true,"img":false}]}
{"op":"mcm","clk":"5322484782","pt":1646320778486,"mc":[{"id":"1.195532863","rc":[{"atb":[[1.89,0]],"id":28691352}],"con":true,"img":false}]}
{"op":"mcm","clk":"5322484788","pt":1646320778588,"mc":[{"id":"1.195532863","rc":[{"atb":[[1.91,1.99]],"id":28691352}],"con":true,"img":false}]}
{"op":"mcm","clk":"5322484803","pt":1646320778800,"mc":[{"id":"1.195532863","rc":[{"atl":[[3.55,41.72],[3.65,0],[3.75,0]],"id":28691352}],"con":true,"img":false}]}
{"op":"mcm","clk":"5322484809","pt":1646320778903,"mc":[{"id":"1.195532863","rc":[{"atb":[[3.45,0]],"id":35839928},{"atb":[[2.42,0]],"id":28603683}],"con":true,"img":false}]}
{"op":"mcm","clk":"5322484818","pt":1646320779004,"mc":[{"id":"1.195532863","rc":[{"atb":[[3.6,16.34]],"id":35839928},{"atb":[[2.46,1.99]],"id":28603683}],"con":true,"img":false}]}
{"op":"mcm","clk":"5322484827","pt":1646320779114,"mc":[{"id":"1.195532863","rc":[{"atb":[[2.84,0],[2.92,0],[2.88,4.61]],"id":39693066},{"atb":[[2.44,0],[2.4,0]],"id":28603683}],"con":true,"img":false}]}
{"op":"mcm","clk":"5322484835","pt":1646320779216,"mc":[{"id":"1.195532863","rc":[{"atb":[[2.24,16.44]],"id":28603683}],"con":true,"img":false}]}
{"op":"mcm","clk":"5322484850","pt":1646320779424,"mc":[{"id":"1.195532863","rc":[{"atb":[[2.46,0]],"id":28603683}],"con":true,"img":false}]}
{"op":"mcm","clk":"5322484862","pt":1646320779478,"mc":[{"id":"1.195532863","rc":[{"atb":[[2.38,1.99]],"id":28603683}],"con":true,"img":false}]}
{"op":"mcm","clk":"5322484890","pt":1646320779894,"mc":[{"id":"1.195532863","rc":[{"atb":[[1.2,2.24]],"id":28603683}],"con":true,"img":false}]}
{"op":"mcm","clk":"5322484913","pt":1646320780207,"mc":[{"id":"1.195532863","rc":[{"atb":[[1.2,2.1]],"id":28603683}],"con":true,"img":false}]}
{"op":"mcm","clk":"5322484922","pt":1646320780313,"mc":[{"id":"1.195532863","rc":[{"atl":[[4.4,44.12]],"id":8668222}],"con":true,"img":false}]}
{"op":"mcm","clk":"5322484928","pt":1646320780416,"mc":[{"id":"1.195532863","rc":[{"atb":[[2.92,1.8]],"id":39693066},{"atb":[[2.4,3.01]],"id":28603683}],"con":true,"img":false}]}
{"op":"mcm","clk":"5322484933","pt":1646320780522,"mc":[{"id":"1.195532863","rc":[{"atb":[[1.2,0]],"id":28603683}],"con":true,"img":false}]}
{"op":"mcm","clk":"5322484942","pt":1646320780625,"mc":[{"id":"1.195532863","rc":[{"atb":[[2.42,2.1]],"id":28603683}],"con":true,"img":false}]}
{"op":"mcm","clk":"5322484955","pt":1646320780787,"mc":[{"id":"1.195532863","rc":[{"atb":[[2.44,2.87],[2.24,5]],"id":28603683}],"con":true,"img":false}]}
{"op":"mcm","clk":"5322484968","pt":1646320780995,"mc":[{"id":"1.195532863","rc":[{"atb":[[1.88,1.99],[1.9,0]],"id":28691352}],"con":true,"img":false}]}
{"op":"mcm","clk":"5322484977","pt":1646320781102,"mc":[{"id":"1.195532863","rc":[{"atl":[[3,15.77]],"id":28691352}],"con":true,"img":false}]}
{"op":"mcm","clk":"5322484987","pt":1646320781204,"mc":[{"id":"1.195532863","rc":[{"atb":[[2.38,0]],"id":28603683},{"atl":[[3.6,38.46],[3.4,0],[3.55,128.08]],"id":28691352}],"con":true,"img":false}]}
{"op":"mcm","clk":"5322484991","pt":1646320781312,"mc":[{"id":"1.195532863","rc":[{"atb":[[2.46,1.99]],"id":28603683},{"atl":[[3.1,19.05]],"id":28691352}],"con":true,"img":false}]}
{"op":"mcm","clk":"5322485015","pt":1646320781724,"mc":[{"id":"1.195532863","rc":[{"atb":[[2.86,0]],"id":39693066},{"atb":[[4,0]],"id":35839928},{"atb":[[1.91,0]],"id":28691352}],"con":true,"img":false}]}
{"op":"mcm","clk":"5322485019","pt":1646320781828,"mc":[{"id":"1.195532863","rc":[{"atb":[[1.89,1.99]],"id":28691352}],"con":true,"img":false}]}
{"op":"mcm","clk":"5322485023","pt":1646320781933,"mc":[{"id":"1.195532863","rc":[{"atb":[[3.95,0],[4.1,0],[4.2,1.65]],"id":35839928},{"atb":[[2.48,1.65]],"id":28603683},{"atb":[[1.8,23.83]],"id":28691352}],"con":true,"img":false}]}
{"op":"mcm","clk":"5322485038","pt":1646320782092,"mc":[{"id":"1.195532863","rc":[{"atb":[[2.32,25.48]],"id":8668222},{"atb":[[1.74,0],[1.75,27.49]],"id":28691352}],"con":true,"img":false}]}
{"op":"mcm","clk":"5322485075","pt":1646320782621,"mc":[{"id":"1.195532863","rc":[{"atb":[[1.02,1.99]],"id":35839928}],"con":true,"img":false}]}
{"op":"mcm","clk":"5322485084","pt":1646320782728,"mc":[{"id":"1.195532863","rc":[{"atb":[[3.65,1.99]],"id":35839928}],"con":true,"img":false}]}
{"op":"mcm","clk":"5322485109","pt":1646320783102,"mc":[{"id":"1.195532863","rc":[{"atb":[[1.02,0]],"id":35839928}],"con":true,"img":false}]}
{"op":"mcm","clk":"5322485123","pt":1646320783315,"mc":[{"id":"1.195532863","rc":[{"atb":[[3.7,1.99]],"id":35839928}],"con":true,"img":false}]}
{"op":"mcm","clk":"5322485135","pt":1646320783521,"mc":[{"id":"1.195532863","rc":[{"atb":[[3.55,5.61]],"id":35839928}],"con":true,"img":false}]}
{"op":"mcm","clk":"5322485176","pt":1646320783933,"mc":[{"id":"1.195532863","rc":[{"atb":[[3.7,0]],"id":35839928},{"atb":[[2.42,4.6]],"id":28603683}],"con":true,"img":false}]}
{"op":"mcm","clk":"5322485184","pt":1646320784039,"mc":[{"id":"1.195532863","rc":[{"atb":[[2.6,23.37]],"id":36042617},{"atb":[[3.6,11.32],[3.55,0],[3.65,3.98]],"id":35839928},{"atb":[[2.32,0],[2.24,0]],"id":28603683},{"atb":[[1.59,169.49],[1.8,0],[1.67,0],[1.75,0]],"id":28691352}],"con":true,"img":false}]}
{"op":"mcm","clk":"5322485206","pt":1646320784211,"mc":[{"id":"1.195532863","rc":[{"atb":[[2.52,2.64]],"id":36042617},{"atb":[[2.42,2.5]],"id":28603683}],"con":true,"img":false}]}
{"op":"mcm","clk":"5322485232","pt":1646320784533,"mc":[{"id":"1.195532863","rc":[{"atb":[[3.05,3.63]],"id":35839928}],"con":true,"img":false}]}
{"op":"mcm","clk":"5322485258","pt":1646320784841,"mc":[{"id":"1.195532863","rc":[{"atb":[[3.05,0]],"id":35839928}],"con":true,"img":false}]}
{"op":"mcm","clk":"5322485283","pt":1646320785095,"mc":[{"id":"1.195532863","rc":[{"atb":[[3.6,0],[3.25,33.42]],"id":35839928}],"con":true,"img":false}]}
{"op":"mcm","clk":"5322485387","pt":1646320786431,"mc":[{"id":"1.195532863","rc":[{"atb":[[2.34,6.61]],"id":8668222},{"atb":[[1.73,9.16]],"id":28691352}],"con":true,"img":false}]}
{"op":"mcm","clk":"5322485401","pt":1646320786639,"mc":[{"id":"1.195532863","rc":[{"atb":[[2.32,0],[2.34,31.55]],"id":8668222}],"con":true,"img":false}]}
{"op":"mcm","clk":"5322485515","pt":1646320787937,"mc":[{"id":"1.195532863","rc":[{"atl":[[5.2,11.35]],"id":28603683}],"con":true,"img":false}]}
{"op":"mcm","clk":"5322485582","pt":1646320788821,"mc":[{"id":"1.195532863","rc":[{"atb":[[2.48,4.21]],"id":28603683}],"con":true,"img":false}]}
{"op":"mcm","clk":"5322485601","pt":1646320789133,"mc":[{"id":"1.195532863","rc":[{"atb":[[2.46,0]],"id":28603683}],"con":true,"img":false}]}
{"op":"mcm","clk":"5322485607","pt":1646320789228,"mc":[{"id":"1.195532863","rc":[{"atb":[[2.5,1.99]],"id":28603683}],"con":true,"img":false}]}
{"op":"mcm","clk":"5322485639","pt":1646320789638,"mc":[{"id":"1.195532863","rc":[{"atb":[[4.2,0]],"id":35839928},{"atb":[[2.48,2.55]],"id":28603683},{"atb":[[2.16,19.98]],"id":8668222},{"atl":[[4.6,69.44]],"id":8668222}],"con":true,"img":false}]}
{"op":"mcm","clk":"5322485652","pt":1646320789845,"mc":[{"id":"1.195532863","rc":[{"atb":[[3.7,1.65]],"id":35839928},{"atb":[[2.52,1.65]],"id":28603683},{"atb":[[2.16,0]],"id":8668222}],"con":true,"img":false}]}
{"op":"mcm","clk":"5322485663","pt":1646320789953,"mc":[{"id":"1.195532863","rc":[{"atb":[[3.65,1.99]],"id":35839928}],"con":true,"img":false}]}
{"op":"mcm","clk":"5322485671","pt":1646320790017,"mc":[{"id":"1.195532863","rc":[{"atb":[[3.3,1.99]],"id":35839928}],"con":true,"img":false}]}
{"op":"mcm","clk":"5322485687","pt":1646320790227,"mc":[{"id":"1.195532863","rc":[{"atb":[[3.3,0]],"id":35839928}],"con":true,"img":false}]}
{"op":"mcm","clk":"5322485697","pt":1646320790318,"mc":[{"id":"1.195532863","rc":[{"atb":[[3.7,3.64]],"id":35839928}],"con":true,"img":false}]}
{"op":"mcm","clk":"5322485717","pt":1646320790536,"mc":[{"id":"1.195532863","rc":[{"atb":[[3.7,1.65]],"id":35839928}],"con":true,"img":false}]}
{"op":"mcm","clk":"5322485724","pt":1646320790640,"mc":[{"id":"1.195532863","rc":[{"atb":[[3.3,1.99]],"id":35839928},{"atl":[[3.2,45.45]],"id":28691352}],"con":true,"img":false}]}
{"op":"mcm","clk":"5322485746","pt":1646320790854,"mc":[{"id":"1.195532863","rc":[{"atb":[[2.8,12.5],[2.9,7.32],[2.74,5]],"id":39693066},{"atb":[[1.73,40.32]],"id":28691352},{"atl":[[3.2,83.91],[3.55,88.86]],"id":28691352}],"con":true,"img":false}]}
{"op":"mcm","clk":"5322485754","pt":1646320790949,"mc":[{"id":"1.195532863","rc":[{"atb":[[3.3,0]],"id":35839928}],"con":true,"img":false}]}
{"op":"mcm","clk":"5322485761","pt":1646320791056,"mc":[{"id":"1.195532863","rc":[{"atb":[[2.88,0]],"id":39693066},{"atb":[[3.7,3.64]],"id":35839928},{"atb":[[2.34,24.94]],"id":8668222}],"con":true,"img":false}]}
{"op":"mcm","clk":"5322485777","pt":1646320791208,"mc":[{"id":"1.195532863","rc":[{"atb":[[3.2,14.34]],"id":35839928}],"con":true,"img":false}]}
{"op":"mcm","clk":"5322485786","pt":1646320791321,"mc":[{"id":"1.195532863","rc":[{"atb":[[3.25,12]],"id":35839928}],"con":true,"img":false}]}
{"op":"mcm","clk":"5322485854","pt":1646320791844,"mc":[{"id":"1.195532863","rc":[{"atb":[[3.65,0]],"id":35839928}],"con":true,"img":false}]}
{"op":"mcm","clk":"5322485860","pt":1646320791948,"mc":[{"id":"1.195532863","rc":[{"atb":[[3.75,1.99]],"id":35839928}],"con":true,"img":false}]}
{"op":"mcm","clk":"5322486002","pt":1646320793449,"mc":[{"id":"1.195532863","rc":[{"atb":[[2.48,0]],"id":28603683}],"con":true,"img":false}]}
{"op":"mcm","clk":"5322486057","pt":1646320793859,"mc":[{"id":"1.195532863","rc":[{"atb":[[2.5,0]],"id":28603683}],"con":true,"img":false}]}
{"op":"mcm","clk":"5322486067","pt":1646320793944,"mc":[{"id":"1.195532863","rc":[{"atb":[[2.46,1.99]],"id":28603683},{"atl":[[2.98,4.6]],"id":28691352}],"con":true,"img":false}]}
{"op":"mcm","clk":"5322486080","pt":1646320794152,"mc":[{"id":"1.195532863","rc":[{"atl":[[3.25,8.45]],"id":28691352}],"con":true,"img":false}]}
{"op":"mcm","clk":"5322486090","pt":1646320794217,"mc":[{"id":"1.195532863","rc":[{"atl":[[2.96,5.07]],"id":28691352}],"con":true,"img":false}]}
{"op":"mcm","clk":"5322486101","pt":1646320794324,"mc":[{"id":"1.195532863","rc":[{"atl":[[3.1,40.74],[2.98,0],[3.55,2.5],[3.05,19.51]],"id":28691352}],"con":true,"img":false}]}
{"op":"mcm","clk":"5322486107","pt":1646320794433,"mc":[{"id":"1.195532863","rc":[{"atl":[[3,0],[3.25,0]],"id":28691352}],"con":true,"img":false}]}
{"op":"mcm","clk":"5322486174","pt":1646320795266,"mc":[{"id":"1.195532863","rc":[{"spn":4.46,"spf":"NaN","id":39693066},{"spn":2.6,"spf":1.0,"id":36042617},{"spn":5.77,"spf":"NaN","id":35839928},{"spn":3.76,"spf":"NaN","id":28603683},{"atb":[[2.3,7.49]],"id":8668222},{"spn":3.2,"spf":"NaN","id":8668222},{"spn":1.81,"spf":1.0,"id":28691352}],"con":true,"img":false}]}
{"op":"mcm","clk":"5322486224","pt":1646320795846,"mc":[{"id":"1.195532863","rc":[{"atl":[[5.4,4.32]],"id":36042617}],"con":true,"img":false}]}
{"op":"mcm","clk":"5322486232","pt":1646320795954,"mc":[{"id":"1.195532863","rc":[{"atb":[[3.25,17],[3.45,2.5],[3.2,11.84]],"id":35839928}],"con":true,"img":false}]}
{"op":"mcm","clk":"5322486243","pt":1646320796050,"mc":[{"id":"1.195532863","rc":[{"atl":[[5.6,32.85],[5.3,32.56],[5.5,5],[5.4,56.92]],"id":36042617}],"con":true,"img":false}]}
{"op":"mcm","clk":"5322486251","pt":1646320796156,"mc":[{"id":"1.195532863","rc":[{"atb":[[3.25,31.32],[3.2,0]],"id":35839928}],"con":true,"img":false}]}
{"op":"mcm","clk":"5322486262","pt":1646320796258,"mc":[{"id":"1.195532863","rc":[{"atb":[[3.8,2.39]],"id":35839928},{"atb":[[2.54,2.58]],"id":28603683},{"atl":[[3,20],[3.05,0]],"id":28691352}],"con":true,"img":false}]}
{"op":"mcm","clk":"5322486291","pt":1646320796558,"mc":[{"id":"1.195532863","rc":[{"atl":[[5.6,21.74]],"id":36042617}],"con":true,"img":false}]}
{"op":"mcm","clk":"5322486314","pt":1646320796829,"mc":[{"id":"1.195532863","rc":[{"atb":[[2.8,2],[2.74,24.53]],"id":39693066},{"atb":[[2.46,0]],"id":28603683},{"atl":[[3.2,45.45],[3.1,81.48]],"id":28691352}],"con":true,"img":false}]}
{"op":"mcm","clk":"5322486322","pt":1646320796936,"mc":[{"id":"1.195532863","rc":[{"atb":[[2.56,1.99]],"id":28603683}],"con":true,"img":false}]}
{"op":"mcm","clk":"5322486333","pt":1646320797135,"mc":[{"id":"1.195532863","rc":[{"atb":[[2.58,2.48]],"id":28603683}],"con":true,"img":false}]}
{"op":"mcm","clk":"5322486341","pt":1646320797239,"mc":[{"id":"1.195532863","rc":[{"atb":[[3.75,0]],"id":35839928},{"atb":[[2.48,2.55]],"id":28603683}],"con":true,"img":false}]}
{"op":"mcm","clk":"5322486350","pt":1646320797355,"mc":[{"id":"1.195532863","rc":[{"atb":[[3.85,1.99]],"id":35839928}],"con":true,"img":false}]}
{"op":"mcm","clk":"5322486365","pt":1646320797558,"mc":[{"id":"1.195532863","rc":[{"atb":[[3.9,2.25]],"id":35839928}],"con":true,"img":false}]}
{"op":"mcm","clk":"5322486378","pt":1646320797721,"mc":[{"id":"1.195532863","rc":[{"atb":[[3.25,17],[3.7,1.99]],"id":35839928},{"atb":[[2.56,0],[2.52,0]],"id":28603683}],"con":true,"img":false}]}
{"op":"mcm","clk":"5322486389","pt":1646320797824,"mc":[{"id":"1.195532863","rc":[{"atb":[[2.6,1.99]],"id":28603683}],"con":true,"img":false}]}
{"op":"mcm","clk":"5322486396","pt":1646320797933,"mc":[{"id":"1.195532863","rc":[{"atb":[[2.54,0],[2.6,3.64],[2.44,0],[2.58,0],[2.4,0]],"id":28603683}],"con":true,"img":false}]}
{"op":"mcm","clk":"5322486414","pt":1646320798240,"mc":[{"id":"1.195532863","rc":[{"atb":[[2.5,0],[2.58,0],[2.66,0]],"id":39693066},{"atb":[[3.45,13.59]],"id":35839928}],"con":true,"img":false}]}
{"op":"mcm","clk":"5322486424","pt":1646320798347,"mc":[{"id":"1.195532863","rc":[{"atb":[[2.6,1.65],[2.62,2.38]],"id":28603683}],"con":true,"img":false}]}
{"op":"mcm","clk":"5322486431","pt":1646320798448,"mc":[{"id":"1.195532863","rc":[{"atb":[[2.5,1.99]],"id":28603683}],"con":true,"img":false}]}
{"op":"mcm","clk":"5322486460","pt":1646320798756,"mc":[{"id":"1.195532863","rc":[{"atb":[[3.85,0]],"id":35839928}],"con":true,"img":false}]}
{"op":"mcm","clk":"5322486473","pt":1646320798856,"mc":[{"id":"1.195532863","rc":[{"atb":[[3.95,1.99]],"id":35839928}],"con":true,"img":false}]}
{"op":"mcm","clk":"5322486480","pt":1646320798961,"mc":[{"id":"1.195532863","rc":[{"atb":[[3.8,0],[3.9,0]],"id":35839928}],"con":true,"img":false}]}
{"op":"mcm","clk":"5322486542","pt":1646320799657,"mc":[{"id":"1.195532863","rc":[{"atb":[[2.5,0]],"id":28603683}],"con":true,"img":false}]}
{"op":"mcm","clk":"5322486549","pt":1646320799756,"mc":[{"id":"1.195532863","rc":[{"atb":[[2.64,1.99]],"id":28603683}],"con":true,"img":false}]}
{"op":"mcm","clk":"5322486558","pt":1646320799862,"mc":[{"id":"1.195532863","rc":[{"atb":[[4,2.11]],"id":35839928}],"con":true,"img":false}]}
{"op":"mcm","clk":"5322486567","pt":1646320799967,"mc":[{"id":"1.195532863","rc":[{"atb":[[3.95,0]],"id":35839928},{"atb":[[2.66,2.29]],"id":28603683}],"con":true,"img":false}]}
{"op":"mcm","clk":"5322486578","pt":1646320800020,"mc":[{"id":"1.195532863","rc":[{"atb":[[3.75,1.99]],"id":35839928}],"con":true,"img":false}]}
{"op":"mcm","clk":"5322486583","pt":1646320800118,"mc":[{"id":"1.195532863","rc":[{"atb":[[2.6,3.64],[2.58,7.19]],"id":36042617},{"atb":[[4,0]],"id":35839928}],"con":true,"img":false}]}
{"op":"mcm","clk":"5322486593","pt":1646320800233,"mc":[{"id":"1.195532863","rc":[{"atb":[[3.8,2.39]],"id":35839928}],"con":true,"img":false}]}
{"op":"mcm","clk":"5322486600","pt":1646320800325,"mc":[{"id":"1.195532863","rc":[{"atb":[[2.58,27.22]],"id":36042617}],"con":true,"img":false}]}
{"op":"mcm","clk":"5322486613","pt":1646320800445,"mc":[{"id":"1.195532863","rc":[{"atb":[[2.58,22.18]],"id":36042617},{"atb":[[2.64,0]],"id":28603683}],"con":true,"img":false}]}
{"op":"mcm","clk":"5322486626","pt":1646320800548,"mc":[{"id":"1.195532863","rc":[{"atb":[[2.68,1.99]],"id":28603683}],"con":true,"img":false}]}
{"op":"mcm","clk":"5322486650","pt":1646320800655,"mc":[{"id":"1.195532863","rc":[{"atb":[[2.62,0],[2.66,0]],"id":28603683}],"con":true,"img":false}]}
{"op":"mcm","clk":"5322486662","pt":1646320800760,"mc":[{"id":"1.195532863","rc":[{"atb":[[3.75,0]],"id":35839928}],"con":true,"img":false}]}
{"op":"mcm","clk":"5322486670","pt":1646320800849,"mc":[{"id":"1.195532863","rc":[{"atb":[[4.1,1.99]],"id":35839928}],"con":true,"img":false}]}
{"op":"mcm","clk":"5322486680","pt":1646320800953,"mc":[{"id":"1.195532863","rc":[{"atb":[[2.7,2.21]],"id":28603683}],"con":true,"img":false}]}
{"op":"mcm","clk":"5322486691","pt":1646320801029,"mc":[{"id":"1.195532863","rc":[{"atb":[[4.2,3.82]],"id":35839928}],"con":true,"img":false}]}
{"op":"mcm","clk":"5322486698","pt":1646320801121,"mc":[{"id":"1.195532863","rc":[{"atl":[[5.4,52.6]],"id":36042617},{"atb":[[2.68,0]],"id":28603683}],"con":true,"img":false}]}
{"op":"mcm","clk":"5322486709","pt":1646320801231,"mc":[{"id":"1.195532863","rc":[{"atl":[[5.4,75.33]],"id":36042617},{"atb":[[2.62,1.99]],"id":28603683}],"con":true,"img":false}]}
{"op":"mcm","clk":"5322486714","pt":1646320801338,"mc":[{"id":"1.195532863","rc":[{"atl":[[5.3,9.3]],"id":36042617},{"atb":[[2.48,0],[2.7,0]],"id":28603683}],"con":true,"img":false}]}
{"op":"mcm","clk":"5322486724","pt":1646320801457,"mc":[{"id":"1.195532863","rc":[{"atb":[[3.7,0]],"id":35839928},{"atb":[[2.64,2.33]],"id":28603683}],"con":true,"img":false}]}
{"op":"mcm","clk":"5322486732","pt":1646320801545,"mc":[{"id":"1.195532863","rc":[{"atb":[[3.85,1.99]],"id":35839928}],"con":true,"img":false}]}
{"op":"mcm","clk":"5322486750","pt":1646320801742,"mc":[{"id":"1.195532863","rc":[{"atb":[[3.45,2.5]],"id":35839928}],"con":true,"img":false}]}
{"op":"mcm","clk":"5322486757","pt":1646320801869,"mc":[{"id":"1.195532863","rc":[{"atb":[[2.62,0]],"id":28603683}],"con":true,"img":false}]}
{"op":"mcm","clk":"5322486766","pt":1646320801964,"mc":[{"id":"1.195532863","rc":[{"atb":[[2.66,1.99]],"id":28603683}],"con":true,"img":false}]}
{"op":"mcm","clk":"5322486781","pt":1646320802160,"mc":[{"id":"1.195532863","rc":[{"atb":[[3.85,0]],"id":35839928},{"atb":[[2.68,2.25]],"id":28603683}],"con":true,"img":false}]}
{"op":"mcm","clk":"5322486790","pt":1646320802266,"mc":[{"id":"1.195532863","rc":[{"atb":[[1.02,1.99]],"id":35839928},{"atb":[[2.26,2.15],[2.36,0]],"id":28603683}],"con":true,"img":false}]}
{"op":"mcm","clk":"5322486818","pt":1646320802651,"mc":[{"id":"1.195532863","rc":[{"atb":[[2.66,0]],"id":28603683}],"con":true,"img":false}]}
{"op":"mcm","clk":"5322486826","pt":1646320802741,"mc":[{"id":"1.195532863","rc":[{"atb":[[2.7,1.99]],"id":28603683}],"con":true,"img":false}]}
{"op":"mcm","clk":"5322486846","pt":1646320802949,"mc":[{"id":"1.195532863","rc":[{"atb":[[4.1,0]],"id":35839928}],"con":true,"img":false}]}
{"op":"mcm","clk":"5322486857","pt":1646320803065,"mc":[{"id":"1.195532863","rc":[{"atb":[[1.02,3.98]],"id":35839928},{"atb":[[2.72,2.16]],"id":28603683}],"con":true,"img":false}]}
{"op":"mcm","clk":"5322486863","pt":1646320803163,"mc":[{"id":"1.195532863","rc":[{"atb":[[3.8,0],[4.2,0]],"id":35839928}],"con":true,"img":false}]}
{"op":"mcm","clk":"5322486878","pt":1646320803319,"mc":[{"id":"1.195532863","rc":[{"atb":[[3.45,19.62],[2.96,51.02]],"id":35839928}],"con":true,"img":false}]}
{"op":"mcm","clk":"5322486889","pt":1646320803438,"mc":[{"id":"1.195532863","rc":[{"atb":[[3.1,0]],"id":35839928},{"atb":[[2.7,0]],"id":28603683},{"atl":[[5.3,49.16]],"id":28603683},{"atl":[[4.3,9.39]],"id":8668222}],"con":true,"img":false}]}
{"op":"mcm","clk":"5322486898","pt":1646320803541,"mc":[{"id":"1.195532863","rc":[{"atb":[[3.5,2.9]],"id":35839928},{"atb":[[2.74,1.99]],"id":28603683}],"con":true,"img":false}]}
{"op":"mcm","clk":"5322486905","pt":1646320803642,"mc":[{"id":"1.195532863","rc":[{"atb":[[2.72,0],[2.64,0],[2.68,0]],"id":28603683}],"con":true,"img":false}]}
{"op":"mcm","clk":"5322486912","pt":1646320803747,"mc":[{"id":"1.195532863","rc":[{"atl":[[5.3,44.4]],"id":28603683}],"con":true,"img":false}]}
{"op":"mcm","clk":"5322486917","pt":1646320803852,"mc":[{"id":"1.195532863","rc":[{"atb":[[2.26,11.4]],"id":28603683}],"con":true,"img":false}]}
{"op":"mcm","clk":"5322486925","pt":1646320803949,"mc":[{"id":"1.195532863","rc":[{"atb":[[2.74,0],[2.76,2.08]],"id":28603683},{"atl":[[4.3,0]],"id":8668222}],"con":true,"img":false}]}
{"op":"mcm","clk":"5322486931","pt":1646320804049,"mc":[{"id":"1.195532863","rc":[{"atb":[[2.62,1.99]],"id":28603683}],"con":true,"img":false}]}
{"op":"mcm","clk":"5322486939","pt":1646320804160,"mc":[{"id":"1.195532863","rc":[{"atb":[[3.25,45.52]],"id":35839928},{"atb":[[2.76,0]],"id":28603683}],"con":true,"img":false}]}
{"op":"mcm","clk":"5322486955","pt":1646320804362,"mc":[{"id":"1.195532863","rc":[{"atb":[[1.02,1.99]],"id":35839928},{"atb":[[2.64,2.33],[2.26,2.15],[2.78,2.04]],"id":28603683}],"con":true,"img":false}]}
{"op":"mcm","clk":"5322486963","pt":1646320804417,"mc":[{"id":"1.195532863","rc":[{"atb":[[3.55,1.99]],"id":35839928}],"con":true,"img":false}]}
{"op":"mcm","clk":"5322486971","pt":1646320804529,"mc":[{"id":"1.195532863","rc":[{"atl":[[46,2.73]],"id":39693066},{"atl":[[46,2.73]],"id":36042617},{"atb":[[3.6,2.71]],"id":35839928},{"atl":[[46,2.73]],"id":35839928},{"atb":[[2.64,0],[2.78,0]],"id":28603683},{"atl":[[46,2.73]],"id":28603683},{"atl":[[46,2.73]],"id":8668222},{"atl":[[46,2.73]],"id":28691352}],"con":true,"img":false}]}
{"op":"mcm","clk":"5322487000","pt":1646320804948,"mc":[{"id":"1.195532863","rc":[{"atb":[[2.64,2.33]],"id":28603683}],"con":true,"img":false}]}
{"op":"mcm","clk":"5322487024","pt":1646320805361,"mc":[{"id":"1.195532863","rc":[{"atb":[[2.26,49.14]],"id":36042617},{"atl":[[3.1,129.1]],"id":28691352}],"con":true,"img":false}]}
{"op":"mcm","clk":"5322487032","pt":1646320805462,"mc":[{"id":"1.195532863","rc":[{"atl":[[5.2,4.48]],"id":36042617}],"con":true,"img":false}]}
{"op":"mcm","clk":"5322487038","pt":1646320805568,"mc":[{"id":"1.195532863","rc":[{"atb":[[2.26,31.75]],"id":36042617}],"con":true,"img":false}]}
{"op":"mcm","clk":"5322487043","pt":1646320805663,"mc":[{"id":"1.195532863","rc":[{"atb":[[2.62,2.55]],"id":36042617},{"atb":[[2.6,0]],"id":28603683}],"con":true,"img":false}]}
{"op":"mcm","clk":"5322487055","pt":1646320805724,"mc":[{"id":"1.195532863","rc":[{"atb":[[3.65,1.65]],"id":35839928},{"atb":[[2.66,1.65]],"id":28603683}],"con":true,"img":false}]}
{"op":"mcm","clk":"5322487064","pt":1646320805828,"mc":[{"id":"1.195532863","rc":[{"atb":[[2.58,39.41],[2.56,2.52]],"id":36042617},{"atb":[[3.7,2.54]],"id":35839928},{"atb":[[2.68,2.25]],"id":28603683}],"con":true,"img":false}]}
{"op":"mcm","clk":"5322487083","pt":1646320806144,"mc":[{"id":"1.195532863","rc":[{"atb":[[2.6,1.65]],"id":36042617}],"con":true,"img":false}]}
{"op":"mcm","clk":"5322487089","pt":1646320806235,"mc":[{"id":"1.195532863","rc":[{"atb":[[2.64,1.99]],"id":36042617}],"con":true,"img":false}]}
{"op":"mcm","clk":"5322487104","pt":1646320806452,"mc":[{"id":"1.195532863","rc":[{"atl":[[4.8,6],[5.1,9],[4.6,4],[5.5,14],[6,21]],"id":28603683}],"con":true,"img":false}]}
{"op":"mcm","clk":"5322487111","pt":1646320806556,"mc":[{"id":"1.195532863","rc":[{"atb":[[2.62,0]],"id":28603683},{"atl":[[5.3,21.14],[4.9,2.93]],"id":28603683}],"con":true,"img":false}]}
{"op":"mcm","clk":"5322487119","pt":1646320806667,"mc":[{"id":"1.195532863","rc":[{"atb":[[2.7,1.99]],"id":28603683},{"atl":[[4.8,16.53],[5.3,0],[5,27.33],[5.2,1.83]],"id":28603683}],"con":true,"img":false}]}
{"op":"mcm","clk":"5322487137","pt":1646320806864,"mc":[{"id":"1.195532863","rc":[{"atb":[[3.55,0]],"id":35839928},{"atb":[[2.72,2.16]],"id":28603683}],"con":true,"img":false}]}
{"op":"mcm","clk":"5322487145","pt":1646320806931,"mc":[{"id":"1.195532863","rc":[{"atb":[[3.75,1.99]],"id":35839928}],"con":true,"img":false}]}
{"op":"mcm","clk":"5322487153","pt":1646320807043,"mc":[{"id":"1.195532863","rc":[{"atl":[[5.2,0]],"id":36042617},{"atb":[[3.8,2.39]],"id":35839928}],"con":true,"img":false}]}
{"op":"mcm","clk":"5322487160","pt":1646320807143,"mc":[{"id":"1.195532863","rc":[{"atl":[[5.1,26.3],[5.4,52.6]],"id":36042617}],"con":true,"img":false}]}
{"op":"mcm","clk":"5322487168","pt":1646320807250,"mc":[{"id":"1.195532863","rc":[{"atb":[[3.25,17]],"id":35839928}],"con":true,"img":false}]}
{"op":"mcm","clk":"5322487177","pt":1646320807348,"mc":[{"id":"1.195532863","rc":[{"atl":[[5.4,82.68]],"id":36042617},{"atb":[[2.7,0]],"id":28603683}],"con":true,"img":false}]}
{"op":"mcm","clk":"5322487182","pt":1646320807455,"mc":[{"id":"1.195532863","rc":[{"atb":[[2.74,1.99]],"id":28603683}],"con":true,"img":false}]}
{"op":"mcm","clk":"5322487205","pt":1646320807674,"mc":[{"id":"1.195532863","rc":[{"atb":[[2.72,0],[2.64,0],[2.68,0]],"id":28603683}],"con":true,"img":false}]}
{"op":"mcm","clk":"5322487219","pt":1646320807866,"mc":[{"id":"1.195532863","rc":[{"atb":[[2.76,2.08]],"id":28603683}],"con":true,"img":false}]}
{"op":"mcm","clk":"5322487226","pt":1646320807968,"mc":[{"id":"1.195532863","rc":[{"atb":[[3.75,0]],"id":35839928}],"con":true,"img":false}]}
{"op":"mcm","clk":"5322487231","pt":1646320808030,"mc":[{"id":"1.195532863","rc":[{"atl":[[5.4,52.6]],"id":36042617},{"atb":[[3.85,1.99]],"id":35839928}],"con":true,"img":false}]}
{"op":"mcm","clk":"5322487237","pt":1646320808138,"mc":[{"id":"1.195532863","rc":[{"atb":[[3.6,0],[3.8,0],[3.5,0],[3.7,0]],"id":35839928}],"con":true,"img":false}]}
{"op":"mcm","clk":"5322487262","pt":1646320808450,"mc":[{"id":"1.195532863","rc":[{"atb":[[2.74,0]],"id":28603683}],"con":true,"img":false}]}
{"op":"mcm","clk":"5322487267","pt":1646320808559,"mc":[{"id":"1.195532863","rc":[{"atb":[[2.78,1.99]],"id":28603683}],"con":true,"img":false}]}
{"op":"mcm","clk":"5322487275","pt":1646320808666,"mc":[{"id":"1.195532863","rc":[{"atb":[[3.9,2.25]],"id":35839928},{"atb":[[2.76,0]],"id":28603683}],"con":true,"img":false}]}
{"op":"mcm","clk":"5322487285","pt":1646320808766,"mc":[{"id":"1.195532863","rc":[{"atb":[[2.8,2]],"id":28603683}],"con":true,"img":false}]}
{"op":"mcm","clk":"5322487292","pt":1646320808857,"mc":[{"id":"1.195532863","rc":[{"atb":[[3.85,0],[3.4,5.81]],"id":35839928}],"con":true,"img":false}]}
{"op":"mcm","clk":"5322487302","pt":1646320808959,"mc":[{"id":"1.195532863","rc":[{"atl":[[5.3,10.96]],"id":36042617},{"atb":[[3.45,31.46],[3.7,1.99]],"id":35839928}],"con":true,"img":false}]}
{"op":"mcm","clk":"5322487308","pt":1646320809077,"mc":[{"id":"1.195532863","rc":[{"atb":[[3.9,0]],"id":35839928}],"con":true,"img":false}]}
{"op":"mcm","clk":"5322487316","pt":1646320809126,"mc":[{"id":"1.195532863","rc":[{"atb":[[3.95,2.19],[3.4,0]],"id":35839928}],"con":true,"img":false}]}
{"op":"mcm","clk":"5322487322","pt":1646320809223,"mc":[{"id":"1.195532863","rc":[{"atb":[[3.75,2.46]],"id":35839928}],"con":true,"img":false}]}
{"op":"mcm","clk":"5322487331","pt":1646320809338,"mc":[{"id":"1.195532863","rc":[{"atb":[[3.95,0]],"id":35839928},{"atb":[[2.78,0]],"id":28603683}],"con":true,"img":false}]}
{"op":"mcm","clk":"5322487338","pt":1646320809445,"mc":[{"id":"1.195532863","rc":[{"atb":[[3.45,19.62]],"id":35839928},{"atb":[[2.82,1.99]],"id":28603683}],"con":true,"img":false}]}
{"op":"mcm","clk":"5322487345","pt":1646320809587,"mc":[{"id":"1.195532863","rc":[{"atl":[[5.3,9.3]],"id":36042617},{"atb":[[3.75,0]],"id":35839928},{"atb":[[2.8,0]],"id":28603683}],"con":true,"img":false}]}
{"op":"mcm","clk":"5322487352","pt":1646320809653,"mc":[{"id":"1.195532863","rc":[{"atb":[[3.7,0]],"id":35839928},{"atb":[[2.84,1.93]],"id":28603683}],"con":true,"img":false}]}
{"op":"mcm","clk":"5322487361","pt":1646320809788,"mc":[{"id":"1.195532863","rc":[{"atb":[[3.75,2.46],[3.95,1.99]],"id":35839928}],"con":true,"img":false}]}
{"op":"mcm","clk":"5322487368","pt":1646320809858,"mc":[{"id":"1.195532863","rc":[{"atb":[[3.7,2.54]],"id":35839928}],"con":true,"img":false}]}
{"op":"mcm","clk":"5322487375","pt":1646320809960,"mc":[{"id":"1.195532863","rc":[{"atb":[[4,2.11]],"id":35839928}],"con":true,"img":false}]}
{"op":"mcm","clk":"5322487398","pt":1646320810274,"mc":[{"id":"1.195532863","rc":[{"atb":[[2.82,0]],"id":28603683}],"con":true,"img":false}]}
{"op":"mcm","clk":"5322487409","pt":1646320810378,"mc":[{"id":"1.195532863","rc":[{"atb":[[2.44,1.99]],"id":28603683}],"con":true,"img":false}]}
{"op":"mcm","clk":"5322487416","pt":1646320810429,"mc":[{"id":"1.195532863","rc":[{"atb":[[2.84,0]],"id":28603683},{"atl":[[3.6,0]],"id":28691352}],"con":true,"img":false}]}
{"op":"mcm","clk":"5322487425","pt":1646320810534,"mc":[{"id":"1.195532863","rc":[{"atb":[[3.95,0]],"id":35839928},{"atb":[[2.68,2.25]],"id":28603683}],"con":true,"img":false}]}
{"op":"mcm","clk":"5322487430","pt":1646320810628,"mc":[{"id":"1.195532863","rc":[{"atb":[[4.1,1.99]],"id":35839928}],"con":true,"img":false}]}
{"op":"mcm","clk":"5322487442","pt":1646320810741,"mc":[{"id":"1.195532863","rc":[{"atb":[[3.75,0],[4,0],[3.7,0]],"id":35839928}],"con":true,"img":false}]}
{"op":"mcm","clk":"5322487452","pt":1646320810848,"mc":[{"id":"1.195532863","rc":[{"atl":[[5.3,15.37]],"id":36042617}],"con":true,"img":false}]}
{"op":"mcm","clk":"5322487464","pt":1646320811043,"mc":[{"id":"1.195532863","rc":[{"atb":[[3.25,45.52],[4.2,3.82]],"id":35839928}],"con":true,"img":false}]}
{"op":"mcm","clk":"5322487490","pt":1646320811364,"mc":[{"id":"1.195532863","rc":[{"atb":[[2.44,0]],"id":28603683}],"con":true,"img":false}]}
{"op":"mcm","clk":"5322487499","pt":1646320811467,"mc":[{"id":"1.195532863","rc":[{"atl":[[5.3,9.3]],"id":36042617},{"atb":[[2.7,1.99]],"id":28603683}],"con":true,"img":false}]}
{"op":"mcm","clk":"5322487505","pt":1646320811569,"mc":[{"id":"1.195532863","rc":[{"atb":[[2.7,5.11]],"id":39693066}],"con":true,"img":false}]}
{"op":"mcm","clk":"5322487513","pt":1646320811675,"mc":[{"id":"1.195532863","rc":[{"atb":[[4.1,0]],"id":35839928},{"atb":[[2.72,2.16]],"id":28603683}],"con":true,"img":false}]}
{"op":"mcm","clk":"5322487517","pt":1646320811778,"mc":[{"id":"1.195532863","rc":[{"atb":[[2.58,22.18],[2.56,47.02]],"id":36042617},{"atb":[[1.02,3.98]],"id":35839928}],"con":true,"img":false}]}
{"op":"mcm","clk":"5322487530","pt":1646320811922,"mc":[{"id":"1.195532863","rc":[{"atb":[[4.2,0]],"id":35839928}],"con":true,"img":false}]}
{"op":"mcm","clk":"5322487538","pt":1646320812041,"mc":[{"id":"1.195532863","rc":[{"atb":[[2.7,0]],"id":39693066},{"atb":[[3.7,2.54]],"id":35839928},{"atb":[[2.7,0]],"id":28603683}],"con":true,"img":false}]}
{"op":"mcm","clk":"5322487548","pt":1646320812144,"mc":[{"id":"1.195532863","rc":[{"atb":[[3.1,47.62],[2.96,0]],"id":35839928},{"atb":[[2.74,1.99]],"id":28603683}],"con":true,"img":false}]}
{"op":"mcm","clk":"5322487555","pt":1646320812247,"mc":[{"id":"1.195532863","rc":[{"atb":[[2.72,0],[2.68,0]],"id":28603683}],"con":true,"img":false}]}
{"op":"mcm","clk":"5322487563","pt":1646320812345,"mc":[{"id":"1.195532863","rc":[{"atl":[[5.1,17],[5.4,75.33]],"id":36042617}],"con":true,"img":false}]}
{"op":"mcm","clk":"5322487574","pt":1646320812450,"mc":[{"id":"1.195532863","rc":[{"atb":[[2.76,2.08]],"id":28603683}],"con":true,"img":false}]}
{"op":"mcm","clk":"5322487633","pt":1646320813072,"mc":[{"id":"1.195532863","rc":[{"atl":[[5.2,7.07]],"id":36042617}],"con":true,"img":false}]}
{"op":"mcm","clk":"5322487650","pt":1646320813271,"mc":[{"id":"1.195532863","rc":[{"atl":[[5.3,61.9],[5.4,22.73]],"id":36042617}],"con":true,"img":false}]}
{"op":"mcm","clk":"5322487674","pt":1646320813641,"mc":[{"id":"1.195532863","rc":[{"atb":[[2.74,0]],"id":28603683}],"con":true,"img":false}]}
{"op":"mcm","clk":"5322487684","pt":1646320813747,"mc":[{"id":"1.195532863","rc":[{"atb":[[2.6,0]],"id":36042617},{"atb":[[3.65,0]],"id":35839928},{"atb":[[2.66,0],[2.78,1.99]],"id":28603683}],"con":true,"img":false}]}
{"op":"mcm","clk":"5322487694","pt":1646320813842,"mc":[{"id":"1.195532863","rc":[{"atb":[[2.76,0]],"id":28603683}],"con":true,"img":false}]}
{"op":"mcm","clk":"5322487703","pt":1646320813957,"mc":[{"id":"1.195532863","rc":[{"atb":[[2.66,1.65]],"id":36042617},{"atb":[[3.7,0],[1.02,1.99]],"id":35839928},{"atb":[[2.8,2],[2.78,3.64]],"id":28603683}],"con":true,"img":false}]}
{"op":"mcm","clk":"5322487713","pt":1646320814075,"mc":[{"id":"1.195532863","rc":[{"atb":[[3.5,2.9],[3.75,4.45]],"id":35839928}],"con":true,"img":false}]}
{"op":"mcm","clk":"5322487737","pt":1646320814296,"mc":[{"id":"1.195532863","rc":[{"atb":[[2.78,1.65]],"id":28603683},{"atl":[[3.2,113.63]],"id":28691352}],"con":true,"img":false}]}
{"op":"mcm","clk":"5322487746","pt":1646320814405,"mc":[{"id":"1.195532863","rc":[{"atb":[[2.82,1.99]],"id":28603683},{"atl":[[3.2,68.18]],"id":28691352}],"con":true,"img":false}]}
{"op":"mcm","clk":"5322487757","pt":1646320814570,"mc":[{"id":"1.195532863","rc":[{"atb":[[3.75,2.46]],"id":35839928},{"atb":[[2.84,1.93]],"id":28603683}],"con":true,"img":false}]}
{"op":"mcm","clk":"5322487765","pt":1646320814675,"mc":[{"id":"1.195532863","rc":[{"atb":[[3.5,4.89]],"id":35839928}],"con":true,"img":false}]}
{"op":"mcm","clk":"5322487772","pt":1646320814739,"mc":[{"id":"1.195532863","rc":[{"atb":[[3.5,1.99],[3.75,0]],"id":35839928}],"con":true,"img":false}]}
{"op":"mcm","clk":"5322487780","pt":1646320814844,"mc":[{"id":"1.195532863","rc":[{"atb":[[3.1,126.92]],"id":35839928}],"con":true,"img":false}]}
{"op":"mcm","clk":"5322487788","pt":1646320814948,"mc":[{"id":"1.195532863","rc":[{"atb":[[3.25,17]],"id":35839928}],"con":true,"img":false}]}
{"op":"mcm","clk":"5322487803","pt":1646320815156,"mc":[{"id":"1.195532863","rc":[{"atb":[[3.55,2.81]],"id":35839928}],"con":true,"img":false}]}
{"op":"mcm","clk":"5322487841","pt":1646320815575,"mc":[{"id":"1.195532863","rc":[{"atl":[[5,52.33]],"id":28603683}],"con":true,"img":false}]}
{"op":"mcm","clk":"5322487858","pt":1646320815785,"mc":[{"id":"1.195532863","rc":[{"atb":[[3.5,0]],"id":35839928}],"con":true,"img":false}]}
{"op":"mcm","clk":"5322487865","pt":1646320815848,"mc":[{"id":"1.195532863","rc":[{"atb":[[3.6,1.99]],"id":35839928}],"con":true,"img":false}]}
{"op":"mcm","clk":"5322487870","pt":1646320815981,"mc":[{"id":"1.195532863","rc":[{"atb":[[3.65,2.63]],"id":35839928}],"con":true,"img":false}]}
{"op":"mcm","clk":"5322487879","pt":1646320816042,"mc":[{"id":"1.195532863","rc":[{"atb":[[3.55,9.28]],"id":35839928}],"con":true,"img":false}]}
{"op":"mcm","clk":"5322487902","pt":1646320816362,"mc":[{"id":"1.195532863","rc":[{"atb":[[3.45,2.5]],"id":35839928}],"con":true,"img":false}]}
{"op":"mcm","clk":"5322487910","pt":1646320816466,"mc":[{"id":"1.195532863","rc":[{"atb":[[3.6,0]],"id":35839928}],"con":true,"img":false}]}
{"op":"mcm","clk":"5322487920","pt":1646320816569,"mc":[{"id":"1.195532863","rc":[{"atb":[[3.7,1.99]],"id":35839928}],"con":true,"img":false}]}
{"op":"mcm","clk":"5322487938","pt":1646320816774,"mc":[{"id":"1.195532863","rc":[{"atb":[[3.75,2.46]],"id":35839928}],"con":true,"img":false}]}
{"op":"mcm","clk":"5322487949","pt":1646320816881,"mc":[{"id":"1.195532863","rc":[{"atb":[[3.1,47.62],[3.45,15.55]],"id":35839928}],"con":true,"img":false}]}
{"op":"mcm","clk":"5322487972","pt":1646320817075,"mc":[{"id":"1.195532863","rc":[{"atb":[[3.7,0]],"id":35839928}],"con":true,"img":false}]}
{"op":"mcm","clk":"5322487980","pt":1646320817191,"mc":[{"id":"1.195532863","rc":[{"atb":[[3.8,1.99]],"id":35839928}],"con":true,"img":false}]}
{"op":"mcm","clk":"5322487991","pt":1646320817246,"mc":[{"id":"1.195532863","rc":[{"atb":[[3.55,6.47],[3.75,0],[3.65,0]],"id":35839928}],"con":true,"img":false}]}
{"op":"mcm","clk":"5322488031","pt":1646320817668,"mc":[{"id":"1.195532863","rc":[{"atb":[[3.8,0]],"id":35839928}],"con":true,"img":false}]}
{"op":"mcm","clk":"5322488039","pt":1646320817771,"mc":[{"id":"1.195532863","rc":[{"atb":[[3.6,1.99],[3.85,2.31]],"id":35839928}],"con":true,"img":false}]}
{"op":"mcm","clk":"5322488048","pt":1646320817874,"mc":[{"id":"1.195532863","rc":[{"atb":[[3.6,4.7],[3.55,0]],"id":35839928}],"con":true,"img":false}]}
{"op":"mcm","clk":"5322488062","pt":1646320818079,"mc":[{"id":"1.195532863","rc":[{"atb":[[3.85,0]],"id":35839928}],"con":true,"img":false}]}
{"op":"mcm","clk":"5322488068","pt":1646320818188,"mc":[{"id":"1.195532863","rc":[{"atl":[[5.1,34],[5.4,0]],"id":36042617},{"atb":[[3.6,2.71]],"id":35839928}],"con":true,"img":false}]}
{"op":"mcm","clk":"5322488078","pt":1646320818281,"mc":[{"id":"1.195532863","rc":[{"atb":[[2.62,0]],"id":36042617},{"atb":[[3.9,2.25],[3.65,2.63]],"id":35839928}],"con":true,"img":false}]}
{"op":"mcm","clk":"5322488086","pt":1646320818342,"mc":[{"id":"1.195532863","rc":[{"atb":[[3.9,4.24]],"id":35839928}],"con":true,"img":false}]}
{"op":"mcm","clk":"5322488100","pt":1646320818478,"mc":[{"id":"1.195532863","rc":[{"atb":[[3.6,0],[3.45,2.5]],"id":35839928}],"con":true,"img":false}]}
{"op":"mcm","clk":"5322488129","pt":1646320818760,"mc":[{"id":"1.195532863","rc":[{"atb":[[2.64,0]],"id":36042617}],"con":true,"img":false}]}
{"op":"mcm","clk":"5322488141","pt":1646320818867,"mc":[{"id":"1.195532863","rc":[{"atb":[[2.6,1.99],[2.52,74.95]],"id":36042617}],"con":true,"img":false}]}
{"op":"mcm","clk":"5322488151","pt":1646320818970,"mc":[{"id":"1.195532863","rc":[{"atb":[[2.56,2.52]],"id":36042617}],"con":true,"img":false}]}
{"op":"mcm","clk":"5322488159","pt":1646320819074,"mc":[{"id":"1.195532863","rc":[{"atb":[[2.52,2.64]],"id":36042617},{"atl":[[5.3,5.62]],"id":28603683}],"con":true,"img":false}]}
{"op":"mcm","clk":"5322488170","pt":1646320819182,"mc":[{"id":"1.195532863","rc":[{"atl":[[4.4,3.7]],"id":28603683}],"con":true,"img":false}]}
{"op":"mcm","clk":"5322488180","pt":1646320819282,"mc":[{"id":"1.195532863","rc":[{"atl":[[4.9,18.77],[5,25]],"id":28603683}],"con":true,"img":false}]}
{"op":"mcm","clk":"5322488191","pt":1646320819375,"mc":[{"id":"1.195532863","rc":[{"atl":[[4.8,33.06],[4.9,15.84]],"id":28603683}],"con":true,"img":false}]}
{"op":"mcm","clk":"5322488211","pt":1646320819643,"mc":[{"id":"1.195532863","rc":[{"atl":[[5.3,0]],"id":28603683}],"con":true,"img":false}]}
{"op":"mcm","clk":"5322488294","pt":1646320820781,"mc":[{"id":"1.195532863","rc":[{"atb":[[2.8,0],[2.84,0]],"id":28603683}],"con":true,"img":false}]}
{"op":"mcm","clk":"5322488309","pt":1646320820948,"mc":[{"id":"1.195532863","rc":[{"atb":[[2.26,11.34]],"id":28603683}],"con":true,"img":false}]}
{"op":"mcm","clk":"5322488322","pt":1646320821147,"mc":[{"id":"1.195532863","rc":[{"atb":[[2.82,0]],"id":28603683}],"con":true,"img":false}]}
{"op":"mcm","clk":"5322488332","pt":1646320821259,"mc":[{"id":"1.195532863","rc":[{"atb":[[2.8,1.99]],"id":28603683}],"con":true,"img":false}]}
{"op":"mcm","clk":"5322488341","pt":1646320821372,"mc":[{"id":"1.195532863","rc":[{"atl":[[4.8,22.53],[5.8,0],[4.6,15.11]],"id":28603683}],"con":true,"img":false}]}
{"op":"mcm","clk":"5322488348","pt":1646320821473,"mc":[{"id":"1.195532863","rc":[{"atb":[[3.45,11.09]],"id":35839928}],"con":true,"img":false}]}
{"op":"mcm","clk":"5322488369","pt":1646320821786,"mc":[{"id":"1.195532863","rc":[{"atb":[[2.66,0]],"id":36042617},{"atb":[[2.78,0]],"id":28603683}],"con":true,"img":false}]}
{"op":"mcm","clk":"5322488383","pt":1646320821984,"mc":[{"id":"1.195532863","rc":[{"atb":[[2.62,1.65]],"id":36042617},{"atb":[[2.82,1.65]],"id":28603683}],"con":true,"img":false}]}
{"op":"mcm","clk":"5322488412","pt":1646320822357,"mc":[{"id":"1.195532863","rc":[{"atb":[[2.62,4.21]],"id":36042617}],"con":true,"img":false}]}
{"op":"mcm","clk":"5322488433","pt":1646320822679,"mc":[{"id":"1.195532863","rc":[{"atb":[[2.6,0]],"id":36042617}],"con":true,"img":false}]}
{"op":"mcm","clk":"5322488442","pt":1646320822801,"mc":[{"id":"1.195532863","rc":[{"atb":[[2.64,1.99]],"id":36042617}],"con":true,"img":false}]}
{"op":"mcm","clk":"5322488446","pt":1646320822871,"mc":[{"id":"1.195532863","rc":[{"atb":[[2.8,0]],"id":28603683}],"con":true,"img":false}]}
{"op":"mcm","clk":"5322488453","pt":1646320822974,"mc":[{"id":"1.195532863","rc":[{"atb":[[2.44,1.99]],"id":28603683},{"atl":[[3.3,108.7]],"id":28691352}],"con":true,"img":false}]}
{"op":"mcm","clk":"5322488528","pt":1646320824182,"mc":[{"id":"1.195532863","rc":[{"atl":[[3.5,0]],"id":28691352}],"con":true,"img":false}]}
{"op":"mcm","clk":"5322488534","pt":1646320824297,"mc":[{"id":"1.195532863","rc":[{"atb":[[2.56,39.1]],"id":36042617}],"con":true,"img":false}]}
{"op":"mcm","clk":"5322488544","pt":1646320824356,"mc":[{"id":"1.195532863","rc":[{"atl":[[6.4,44.95]],"id":39693066}],"con":true,"img":false}]}
{"op":"mcm","clk":"5322488648","pt":1646320825570,"mc":[{"id":"1.195532863","rc":[{"atl":[[3.55,0]],"id":28691352}],"con":true,"img":false}]}
{"op":"mcm","clk":"5322488969","pt":1646320829655,"mc":[{"id":"1.195532863","rc":[{"atb":[[2.62,2.55]],"id":36042617},{"atb":[[2.82,0]],"id":28603683}],"con":true,"img":false}]}
{"op":"mcm","clk":"5322488978","pt":1646320829760,"mc":[{"id":"1.195532863","rc":[{"atb":[[2.66,1.65]],"id":36042617},{"atb":[[2.46,1.65],[2.26,2.15],[2.2,41.39]],"id":28603683}],"con":true,"img":false}]}
{"op":"mcm","clk":"5322488998","pt":1646320829967,"mc":[{"id":"1.195532863","rc":[{"atl":[[4.8,48.85]],"id":28603683}],"con":true,"img":false}]}
{"op":"mcm","clk":"5322489008","pt":1646320830073,"mc":[{"id":"1.195532863","rc":[{"atb":[[2.54,6.62],[2.3,7.97]],"id":36042617}],"con":true,"img":false}]}
{"op":"mcm","clk":"5322489021","pt":1646320830282,"mc":[{"id":"1.195532863","rc":[{"atb":[[2.54,0],[2.3,2.5]],"id":36042617}],"con":true,"img":false}]}
{"op":"mcm","clk":"5322489086","pt":1646320831169,"mc":[{"id":"1.195532863","rc":[{"atb":[[2.58,58.76]],"id":36042617}],"con":true,"img":false}]}
{"op":"mcm","clk":"5322489094","pt":1646320831271,"mc":[{"id":"1.195532863","rc":[{"atb":[[2.56,2.52]],"id":36042617}],"con":true,"img":false}]}
{"op":"mcm","clk":"5322489118","pt":1646320831610,"mc":[{"id":"1.195532863","rc":[{"atl":[[4.3,4.65]],"id":28603683}],"con":true,"img":false}]}
{"op":"mcm","clk":"5322489124","pt":1646320831687,"mc":[{"id":"1.195532863","rc":[{"atl":[[4.8,63.55],[4.9,0]],"id":28603683}],"con":true,"img":false}]}
{"op":"mcm","clk":"5322489132","pt":1646320831792,"mc":[{"id":"1.195532863","rc":[{"atl":[[4.8,47.02],[4.4,0],[4.6,30.95]],"id":28603683}],"con":true,"img":false}]}
{"op":"mcm","clk":"5322489138","pt":1646320831900,"mc":[{"id":"1.195532863","rc":[{"atl":[[4.6,36.92]],"id":28603683}],"con":true,"img":false}]}
{"op":"mcm","clk":"5322489159","pt":1646320832158,"mc":[{"id":"1.195532863","rc":[{"atl":[[4.6,30.95]],"id":28603683}],"con":true,"img":false}]}
{"op":"mcm","clk":"5322489179","pt":1646320832474,"mc":[{"id":"1.195532863","rc":[{"atb":[[2.62,0]],"id":36042617}],"con":true,"img":false}]}
{"op":"mcm","clk":"5322489226","pt":1646320833094,"mc":[{"id":"1.195532863","rc":[{"atb":[[2.64,0]],"id":36042617}],"con":true,"img":false}]}
{"op":"mcm","clk":"5322489234","pt":1646320833256,"mc":[{"id":"1.195532863","rc":[{"atb":[[2.6,1.99]],"id":36042617}],"con":true,"img":false}]}
{"op":"mcm","clk":"5322489243","pt":1646320833345,"mc":[{"id":"1.195532863","rc":[{"atb":[[2.26,12.53],[2.2,12.09]],"id":28603683}],"con":true,"img":false}]}
{"op":"mcm","clk":"5322489249","pt":1646320833448,"mc":[{"id":"1.195532863","rc":[{"atb":[[2.6,21.56]],"id":36042617}],"con":true,"img":false}]}
{"op":"mcm","clk":"5322489278","pt":1646320833762,"mc":[{"id":"1.195532863","rc":[{"atb":[[2.58,38.73]],"id":36042617}],"con":true,"img":false}]}
{"op":"mcm","clk":"5322489480","pt":1646320836256,"mc":[{"id":"1.195532863","rc":[{"atb":[[2.48,2.75]],"id":28603683}],"con":true,"img":false}]}
{"op":"mcm","clk":"5322489491","pt":1646320836469,"mc":[{"id":"1.195532863","rc":[{"atb":[[2.44,0],[2.26,2.15],[2.28,5.83]],"id":28603683}],"con":true,"img":false}]}
{"op":"mcm","clk":"5322489499","pt":1646320836525,"mc":[{"id":"1.195532863","rc":[{"atb":[[2.5,1.99]],"id":28603683}],"con":true,"img":false}]}
{"op":"mcm","clk":"5322489506","pt":1646320836631,"mc":[{"id":"1.195532863","rc":[{"atb":[[2.52,2.64]],"id":28603683}],"con":true,"img":false}]}
{"op":"mcm","clk":"5322489524","pt":1646320836842,"mc":[{"id":"1.195532863","rc":[{"atb":[[2.58,2.15],[2.56,74.05]],"id":36042617},{"atb":[[2.5,0]],"id":28603683}],"con":true,"img":false}]}
{"op":"mcm","clk":"5322489534","pt":1646320836952,"mc":[{"id":"1.195532863","rc":[{"atb":[[2.54,1.99]],"id":28603683},{"atl":[[4.8,73.34],[4.6,15.11]],"id":28603683}],"con":true,"img":false}]}
{"op":"mcm","clk":"5322489543","pt":1646320837058,"mc":[{"id":"1.195532863","rc":[{"atb":[[2.48,0],[2.52,0]],"id":28603683}],"con":true,"img":false}]}
{"op":"mcm","clk":"5322489552","pt":1646320837157,"mc":[{"id":"1.195532863","rc":[{"atb":[[2.26,0],[2.34,2.15]],"id":28603683}],"con":true,"img":false}]}
{"op":"mcm","clk":"5322489602","pt":1646320837844,"mc":[{"id":"1.195532863","rc":[{"atb":[[2.66,0]],"id":36042617},{"atl":[[5.5,10.18]],"id":36042617},{"atb":[[2.54,0],[2.46,0]],"id":28603683}],"con":true,"img":false}]}
{"op":"mcm","clk":"5322489612","pt":1646320837942,"mc":[{"id":"1.195532863","rc":[{"atb":[[2.42,31.75]],"id":36042617},{"atb":[[2.44,2.87],[2.48,1.99]],"id":28603683}],"con":true,"img":false}]}
{"op":"mcm","clk":"5322489620","pt":1646320838048,"mc":[{"id":"1.195532863","rc":[{"atb":[[2.62,1.65],[2.38,0]],"id":36042617},{"atb":[[2.56,1.65]],"id":28603683}],"con":true,"img":false}]}
{"op":"mcm","clk":"5322489631","pt":1646320838151,"mc":[{"id":"1.195532863","rc":[{"atb":[[2.5,2.69],[2.58,2.48],[2.48,0]],"id":28603683}],"con":true,"img":false}]}
{"op":"mcm","clk":"5322489641","pt":1646320838254,"mc":[{"id":"1.195532863","rc":[{"atb":[[2.46,1.99]],"id":28603683}],"con":true,"img":false}]}
{"op":"mcm","clk":"5322489648","pt":1646320838359,"mc":[{"id":"1.195532863","rc":[{"atl":[[5.5,5]],"id":36042617}],"con":true,"img":false}]}
{"op":"mcm","clk":"5322489657","pt":1646320838462,"mc":[{"id":"1.195532863","rc":[{"atl":[[4.8,47.02],[5.4,2.5],[5.6,0],[4.5,11.43],[4.6,4],[5,0]],"id":28603683}],"con":true,"img":false}]}
{"op":"mcm","clk":"5322489678","pt":1646320838673,"mc":[{"id":"1.195532863","rc":[{"atl":[[4.8,20.7],[4.6,29]],"id":28603683}],"con":true,"img":false}]}
{"op":"mcm","clk":"5322489691","pt":1646320838777,"mc":[{"id":"1.195532863","rc":[{"atb":[[2.46,0]],"id":28603683},{"atl":[[3.9,27.37]],"id":8668222}],"con":true,"img":false}]}
{"op":"mcm","clk":"5322489696","pt":1646320838837,"mc":[{"id":"1.195532863","rc":[{"atb":[[2.6,1.99]],"id":28603683},{"atl":[[4.3,7.81]],"id":8668222}],"con":true,"img":false}]}
{"op":"mcm","clk":"5322489708","pt":1646320838941,"mc":[{"id":"1.195532863","rc":[{"atb":[[2.62,2.38]],"id":28603683}],"con":true,"img":false}]}
{"op":"mcm","clk":"5322489736","pt":1646320839253,"mc":[{"id":"1.195532863","rc":[{"atb":[[2.6,0]],"id":28603683}],"con":true,"img":false}]}
{"op":"mcm","clk":"5322489747","pt":1646320839359,"mc":[{"id":"1.195532863","rc":[{"atb":[[2.64,1.99]],"id":28603683},{"atl":[[4.3,0]],"id":8668222}],"con":true,"img":false}]}
{"op":"mcm","clk":"5322489765","pt":1646320839570,"mc":[{"id":"1.195532863","rc":[{"atb":[[2.5,0],[2.44,0],[2.58,0],[2.62,0]],"id":28603683}],"con":true,"img":false}]}
{"op":"mcm","clk":"5322489784","pt":1646320839776,"mc":[{"id":"1.195532863","rc":[{"atb":[[2.64,0]],"id":28603683},{"atl":[[3.85,12.06]],"id":8668222}],"con":true,"img":false}]}
{"op":"mcm","clk":"5322489792","pt":1646320839879,"mc":[{"id":"1.195532863","rc":[{"atb":[[2.58,1.99]],"id":28603683}],"con":true,"img":false}]}
{"op":"mcm","clk":"5322489800","pt":1646320839942,"mc":[{"id":"1.195532863","rc":[{"atb":[[2.58,4.47]],"id":28603683},{"atl":[[4,64.11],[4.1,31.25],[3.9,11]],"id":8668222}],"con":true,"img":false}]}
{"op":"mcm","clk":"5322489820","pt":1646320840248,"mc":[{"id":"1.195532863","rc":[{"atl":[[4,69.96]],"id":8668222}],"con":true,"img":false}]}
{"op":"mcm","clk":"5322489827","pt":1646320840358,"mc":[{"id":"1.195532863","rc":[{"atb":[[2.28,0]],"id":28603683}],"con":true,"img":false}]}
{"op":"mcm","clk":"5322489865","pt":1646320840764,"mc":[{"id":"1.195532863","rc":[{"atl":[[4,64.11]],"id":8668222}],"con":true,"img":false}]}
{"op":"mcm","clk":"5322489953","pt":1646320841861,"mc":[{"id":"1.195532863","rc":[{"atb":[[2.34,13.55]],"id":28603683}],"con":true,"img":false}]}
{"op":"mcm","clk":"5322489974","pt":1646320842174,"mc":[{"id":"1.195532863","rc":[{"atb":[[2.3,0]],"id":8668222}],"con":true,"img":false}]}
{"op":"mcm","clk":"5322490093","pt":1646320843483,"mc":[{"id":"1.195532863","rc":[{"atl":[[4.9,3.5]],"id":28603683}],"con":true,"img":false}]}
{"op":"mcm","clk":"5322490127","pt":1646320843794,"mc":[{"id":"1.195532863","rc":[{"atl":[[4.6,61.16]],"id":28603683}],"con":true,"img":false}]}
{"op":"mcm","clk":"5322490140","pt":1646320843851,"mc":[{"id":"1.195532863","rc":[{"atl":[[4.8,6],[4.9,0]],"id":28603683}],"con":true,"img":false}]}
{"op":"mcm","clk":"5322490175","pt":1646320844266,"mc":[{"id":"1.195532863","rc":[{"atb":[[2.36,8.48]],"id":28603683}],"con":true,"img":false}]}
{"op":"mcm","clk":"5322490293","pt":1646320845473,"mc":[{"id":"1.195532863","rc":[{"atb":[[2.36,24.9],[2.34,2.15]],"id":28603683}],"con":true,"img":false}]}
{"op":"mcm","clk":"5322490313","pt":1646320845682,"mc":[{"id":"1.195532863","rc":[{"atb":[[2.56,0]],"id":28603683}],"con":true,"img":false}]}
{"op":"mcm","clk":"5322490334","pt":1646320845889,"mc":[{"id":"1.195532863","rc":[{"atb":[[2.6,1.65]],"id":28603683}],"con":true,"img":false}]}
{"op":"mcm","clk":"5322490354","pt":1646320846048,"mc":[{"id":"1.195532863","rc":[{"atb":[[2.62,2.38]],"id":28603683}],"con":true,"img":false}]}
{"op":"mcm","clk":"5322490362","pt":1646320846161,"mc":[{"id":"1.195532863","rc":[{"atb":[[2.36,8.48]],"id":28603683}],"con":true,"img":false}]}
{"op":"mcm","clk":"5322490390","pt":1646320846468,"mc":[{"id":"1.195532863","rc":[{"atb":[[2.58,2.48]],"id":28603683},{"atb":[[2.3,7.49]],"id":8668222}],"con":true,"img":false}]}
{"op":"mcm","clk":"5322490397","pt":1646320846579,"mc":[{"id":"1.195532863","rc":[{"atb":[[2.64,1.99]],"id":28603683}],"con":true,"img":false}]}
{"op":"mcm","clk":"5322490404","pt":1646320846674,"mc":[{"id":"1.195532863","rc":[{"atb":[[2.66,2.29]],"id":28603683}],"con":true,"img":false}]}
{"op":"mcm","clk":"5322490418","pt":1646320846883,"mc":[{"id":"1.195532863","rc":[{"atl":[[4.7,27.03]],"id":28603683}],"con":true,"img":false}]}
{"op":"mcm","clk":"5322490424","pt":1646320846990,"mc":[{"id":"1.195532863","rc":[{"atb":[[2.64,0]],"id":28603683}],"con":true,"img":false}]}
{"op":"mcm","clk":"5322490431","pt":1646320847094,"mc":[{"id":"1.195532863","rc":[{"atb":[[2.68,1.99]],"id":28603683}],"con":true,"img":false}]}
{"op":"mcm","clk":"5322490441","pt":1646320847199,"mc":[{"id":"1.195532863","rc":[{"atb":[[2.58,0],[2.62,0],[2.66,0]],"id":28603683}],"con":true,"img":false}]}
{"op":"mcm","clk":"5322490475","pt":1646320847674,"mc":[{"id":"1.195532863","rc":[{"atb":[[2.68,0]],"id":28603683}],"con":true,"img":false}]}
{"op":"mcm","clk":"5322490483","pt":1646320847774,"mc":[{"id":"1.195532863","rc":[{"atb":[[2.62,1.99]],"id":28603683}],"con":true,"img":false}]}
{"op":"mcm","clk":"5322490501","pt":1646320847982,"mc":[{"id":"1.195532863","rc":[{"atb":[[2.64,2.33]],"id":28603683}],"con":true,"img":false}]}
{"op":"mcm","clk":"5322490534","pt":1646320848483,"mc":[{"id":"1.195532863","rc":[{"atb":[[2.62,0]],"id":28603683}],"con":true,"img":false}]}
{"op":"mcm","clk":"5322490547","pt":1646320848571,"mc":[{"id":"1.195532863","rc":[{"atb":[[2.66,1.99]],"id":28603683}],"con":true,"img":false}]}
{"op":"mcm","clk":"5322490554","pt":1646320848671,"mc":[{"id":"1.195532863","rc":[{"atb":[[2.68,2.25]],"id":28603683}],"con":true,"img":false}]}
{"op":"mcm","clk":"5322490588","pt":1646320848993,"mc":[{"id":"1.195532863","rc":[{"atb":[[2.66,0]],"id":28603683}],"con":true,"img":false}]}
{"op":"mcm","clk":"5322490598","pt":1646320849085,"mc":[{"id":"1.195532863","rc":[{"atb":[[2.7,1.99]],"id":28603683}],"con":true,"img":false}]}
{"op":"mcm","clk":"5322490604","pt":1646320849192,"mc":[{"id":"1.195532863","rc":[{"atb":[[2.64,0],[2.68,0]],"id":28603683}],"con":true,"img":false}]}
{"op":"mcm","clk":"5322490629","pt":1646320849501,"mc":[{"id":"1.195532863","rc":[{"atb":[[2.7,0]],"id":28603683}],"con":true,"img":false}]}
{"op":"mcm","clk":"5322490637","pt":1646320849566,"mc":[{"id":"1.195532863","rc":[{"atb":[[2.62,1.99]],"id":28603683}],"con":true,"img":false}]}
{"op":"mcm","clk":"5322490645","pt":1646320849665,"mc":[{"id":"1.195532863","rc":[{"atb":[[2.62,4.37]],"id":28603683}],"con":true,"img":false}]}
{"op":"mcm","clk":"5322490710","pt":1646320850390,"mc":[{"id":"1.195532863","rc":[{"atb":[[2.36,0]],"id":28603683}],"con":true,"img":false}]}
{"op":"mcm","clk":"5322490980","pt":1646320853784,"mc":[{"id":"1.195532863","rc":[{"atb":[[2.6,0],[2.34,13.42]],"id":28603683}],"con":true,"img":false}]}
{"op":"mcm","clk":"5322490993","pt":1646320853992,"mc":[{"id":"1.195532863","rc":[{"atb":[[2.94,1.65]],"id":39693066},{"atb":[[2.64,1.65]],"id":28603683}],"con":true,"img":false}]}
{"op":"mcm","clk":"5322491002","pt":1646320854096,"mc":[{"id":"1.195532863","rc":[{"atb":[[2.92,8.55],[2.74,5],[2.96,1.74]],"id":39693066},{"atb":[[2.66,2.29]],"id":28603683}],"con":true,"img":false}]}
{"op":"mcm","clk":"5322491010","pt":1646320854199,"mc":[{"id":"1.195532863","rc":[{"atb":[[2.8,14.45]],"id":39693066}],"con":true,"img":false}]}
{"op":"mcm","clk":"5322491017","pt":1646320854299,"mc":[{"id":"1.195532863","rc":[{"atb":[[2.9,1.99],[2.86,11.25]],"id":39693066},{"atl":[[8.4,14],[9.4,21],[7.6,46.88],[7,11],[6.6,4]],"id":39693066},{"atb":[[2.34,2.15]],"id":28603683}],"con":true,"img":false}]}
{"op":"mcm","clk":"5322491024","pt":1646320854407,"mc":[{"id":"1.195532863","rc":[{"atb":[[2.9,0]],"id":39693066},{"atb":[[2.62,17.9]],"id":36042617}],"con":true,"img":false}]}
{"op":"mcm","clk":"5322491032","pt":1646320854465,"mc":[{"id":"1.195532863","rc":[{"atb":[[2.96,3.73]],"id":39693066}],"con":true,"img":false}]}
{"op":"mcm","clk":"5322491038","pt":1646320854571,"mc":[{"id":"1.195532863","rc":[{"atb":[[2.58,51.49],[2.56,2.52]],"id":36042617}],"con":true,"img":false}]}
{"op":"mcm","clk":"5322491049","pt":1646320854671,"mc":[{"id":"1.195532863","rc":[{"atb":[[2.62,2.38]],"id":28603683}],"con":true,"img":false}]}
{"op":"mcm","clk":"5322491056","pt":1646320854771,"mc":[{"id":"1.195532863","rc":[{"atb":[[2.84,3.48],[2.86,0]],"id":39693066},{"atb":[[2.68,1.99]],"id":28603683}],"con":true,"img":false}]}
{"op":"mcm","clk":"5322491062","pt":1646320854884,"mc":[{"id":"1.195532863","rc":[{"atb":[[2.7,2.21]],"id":28603683}],"con":true,"img":false}]}
{"op":"mcm","clk":"5322491070","pt":1646320854981,"mc":[{"id":"1.195532863","rc":[{"atb":[[2.84,0]],"id":39693066}],"con":true,"img":false}]}
{"op":"mcm","clk":"5322491078","pt":1646320855086,"mc":[{"id":"1.195532863","rc":[{"atb":[[2.6,19.57]],"id":36042617},{"atl":[[4.9,38.46]],"id":28603683}],"con":true,"img":false}]}
{"op":"mcm","clk":"5322491088","pt":1646320855187,"mc":[{"id":"1.195532863","rc":[{"atb":[[2.64,1.99]],"id":36042617}],"con":true,"img":false}]}
{"op":"mcm","clk":"5322491112","pt":1646320855498,"mc":[{"id":"1.195532863","rc":[{"atb":[[2.96,1.74]],"id":39693066},{"spn":4.48,"spf":"NaN","id":39693066},{"spn":2.62,"spf":1.0,"id":36042617},{"spn":5.85,"spf":"NaN","id":35839928},{"spn":3.5,"spf":"NaN","id":28603683},{"spn":3.17,"spf":"NaN","id":8668222}],"con":true,"img":false}]}
{"op":"mcm","clk":"5322491118","pt":1646320855602,"mc":[{"id":"1.195532863","rc":[{"atb":[[2.94,3.64]],"id":39693066}],"con":true,"img":false}]}
{"op":"mcm","clk":"5322491140","pt":1646320855809,"mc":[{"id":"1.195532863","rc":[{"atb":[[2.56,15.18]],"id":36042617}],"con":true,"img":false}]}
{"op":"mcm","clk":"5322491151","pt":1646320855867,"mc":[{"id":"1.195532863","rc":[{"atb":[[2.68,0]],"id":28603683}],"con":true,"img":false}]}
{"op":"mcm","clk":"5322491160","pt":1646320855967,"mc":[{"id":"1.195532863","rc":[{"atb":[[2.72,1.99]],"id":28603683}],"con":true,"img":false}]}
{"op":"mcm","clk":"5322491170","pt":1646320856074,"mc":[{"id":"1.195532863","rc":[{"atb":[[2.62,0],[2.66,0],[2.7,0]],"id":28603683}],"con":true,"img":false}]}
{"op":"mcm","clk":"5322491198","pt":1646320856494,"mc":[{"id":"1.195532863","rc":[{"atb":[[2.56,2.52]],"id":36042617}],"con":true,"img":false}]}
{"op":"mcm","clk":"5322491216","pt":1646320856699,"mc":[{"id":"1.195532863","rc":[{"atb":[[2.72,0],[2.74,2.12]],"id":28603683}],"con":true,"img":false}]}
{"op":"mcm","clk":"5322491223","pt":1646320856829,"mc":[{"id":"1.195532863","rc":[{"atb":[[2.66,1.99]],"id":28603683}],"con":true,"img":false}]}
{"op":"mcm","clk":"5322491232","pt":1646320856908,"mc":[{"id":"1.195532863","rc":[{"atb":[[1.01,4806.04],[2.74,0]],"id":28603683}],"con":true,"img":false}]}
{"op":"mcm","clk":"5322491239","pt":1646320857013,"mc":[{"id":"1.195532863","rc":[{"atb":[[1.01,4808.03],[2.76,2.08]],"id":28603683}],"con":true,"img":false}]}
{"op":"mcm","clk":"5322491248","pt":1646320857067,"mc":[{"id":"1.195532863","rc":[{"atb":[[2.68,2.25]],"id":28603683}],"con":true,"img":false}]}
{"op":"mcm","clk":"5322491256","pt":1646320857172,"mc":[{"id":"1.195532863","rc":[{"atb":[[1.01,4806.04],[2.76,0]],"id":28603683}],"con":true,"img":false}]}
{"op":"mcm","clk":"5322491264","pt":1646320857276,"mc":[{"id":"1.195532863","rc":[{"atb":[[2.76,1.99]],"id":28603683}],"con":true,"img":false}]}
{"op":"mcm","clk":"5322491273","pt":1646320857378,"mc":[{"id":"1.195532863","rc":[{"atb":[[2.68,0]],"id":28603683}],"con":true,"img":false}]}
{"op":"mcm","clk":"5322491285","pt":1646320857487,"mc":[{"id":"1.195532863","rc":[{"atb":[[2.34,13.16],[2.76,0]],"id":28603683}],"con":true,"img":false}]}
{"op":"mcm","clk":"5322491292","pt":1646320857593,"mc":[{"id":"1.195532863","rc":[{"atb":[[2.68,2.25],[2.7,1.99]],"id":28603683}],"con":true,"img":false}]}
{"op":"mcm","clk":"5322491303","pt":1646320857695,"mc":[{"id":"1.195532863","rc":[{"atb":[[2.72,2.16]],"id":28603683}],"con":true,"img":false}]}
{"op":"mcm","clk":"5322491311","pt":1646320857797,"mc":[{"id":"1.195532863","rc":[{"atb":[[2.34,2.15],[2.66,0]],"id":28603683}],"con":true,"img":false}]}
{"op":"mcm","clk":"5322491319","pt":1646320857902,"mc":[{"id":"1.195532863","rc":[{"atb":[[2.7,3.98]],"id":28603683},{"atl":[[2.96,15.07]],"id":28691352}],"con":true,"img":false}]}
{"op":"mcm","clk":"5322491342","pt":1646320858213,"mc":[{"id":"1.195532863","rc":[{"atb":[[2.7,1.99]],"id":28603683}],"con":true,"img":false}]}
{"op":"mcm","clk":"5322491350","pt":1646320858269,"mc":[{"id":"1.195532863","rc":[{"atb":[[2.74,1.99]],"id":28603683}],"con":true,"img":false}]}
{"op":"mcm","clk":"5322491356","pt":1646320858371,"mc":[{"id":"1.195532863","rc":[{"atb":[[2.76,2.08]],"id":28603683}],"con":true,"img":false}]}
{"op":"mcm","clk":"5322491364","pt":1646320858479,"mc":[{"id":"1.195532863","rc":[{"atl":[[3.1,140.67]],"id":28691352}],"con":true,"img":false}]}
{"op":"mcm","clk":"5322491381","pt":1646320858790,"mc":[{"id":"1.195532863","rc":[{"atb":[[2.74,0]],"id":28603683}],"con":true,"img":false}]}
{"op":"mcm","clk":"5322491389","pt":1646320858894,"mc":[{"id":"1.195532863","rc":[{"atb":[[2.72,0],[2.76,0],[2.78,1.99],[2.68,0]],"id":28603683}],"con":true,"img":false}]}
{"op":"mcm","clk":"5322491401","pt":1646320859102,"mc":[{"id":"1.195532863","rc":[{"atl":[[3.1,129.1]],"id":28691352}],"con":true,"img":false}]}
{"op":"mcm","clk":"5322491425","pt":1646320859431,"mc":[{"id":"1.195532863","rc":[{"atb":[[2.7,0]],"id":28603683}],"con":true,"img":false}]}
{"op":"mcm","clk":"5322491440","pt":1646320859481,"mc":[{"id":"1.195532863","rc":[{"atb":[[2.62,36.93]],"id":36042617}],"con":true,"img":false}]}
{"op":"mcm","clk":"5322491452","pt":1646320859583,"mc":[{"id":"1.195532863","rc":[{"atb":[[2.44,1.99]],"id":28603683}],"con":true,"img":false}]}
{"op":"mcm","clk":"5322491461","pt":1646320859684,"mc":[{"id":"1.195532863","rc":[{"atb":[[2.6,0]],"id":36042617}],"con":true,"img":false}]}
{"op":"mcm","clk":"5322491471","pt":1646320859792,"mc":[{"id":"1.195532863","rc":[{"atb":[[2.48,13.06]],"id":8668222}],"con":true,"img":false}]}
{"op":"mcm","clk":"5322491493","pt":1646320860005,"mc":[{"id":"1.195532863","rc":[{"atb":[[2.58,2.15],[2.56,93.68]],"id":36042617},{"atb":[[2.44,0]],"id":28603683},{"atb":[[2.22,11.9]],"id":8668222}],"con":true,"img":false}]}
{"op":"mcm","clk":"5322491503","pt":1646320860109,"mc":[{"id":"1.195532863","rc":[{"atb":[[2.66,1.99]],"id":28603683},{"atb":[[2.22,0]],"id":8668222}],"con":true,"img":false}]}
{"op":"mcm","clk":"5322491521","pt":1646320860316,"mc":[{"id":"1.195532863","rc":[{"atb":[[2.26,2.15],[2.34,0],[2.78,0]],"id":28603683},{"atb":[[2.54,2.15],[2.44,0]],"id":8668222}],"con":true,"img":false}]}
{"op":"mcm","clk":"5322491530","pt":1646320860372,"mc":[{"id":"1.195532863","rc":[{"atb":[[2.68,1.99]],"id":28603683}],"con":true,"img":false}]}
{"op":"mcm","clk":"5322491536","pt":1646320860478,"mc":[{"id":"1.195532863","rc":[{"atb":[[3.9,15.24]],"id":35839928},{"atb":[[2.68,4.24]],"id":28603683},{"atb":[[2.42,3.24]],"id":8668222}],"con":true,"img":false}]}
{"op":"mcm","clk":"5322491551","pt":1646320860640,"mc":[{"id":"1.195532863","rc":[{"atb":[[2.34,0],[2.42,32.07]],"id":8668222}],"con":true,"img":false}]}
{"op":"mcm","clk":"5322491556","pt":1646320860689,"mc":[{"id":"1.195532863","rc":[{"atb":[[2.42,28.83]],"id":8668222}],"con":true,"img":false}]}
{"op":"mcm","clk":"5322491658","pt":1646320861790,"mc":[{"id":"1.195532863","rc":[{"atb":[[2.94,1.99]],"id":39693066},{"atb":[[2.62,35.27]],"id":36042617},{"atb":[[2.64,0]],"id":28603683},{"atb":[[2.5,0]],"id":8668222}],"con":true,"img":false}]}
{"op":"mcm","clk":"5322491676","pt":1646320861999,"mc":[{"id":"1.195532863","rc":[{"atb":[[2.98,1.65]],"id":39693066},{"atb":[[2.66,1.65]],"id":36042617},{"atb":[[2.7,1.65]],"id":28603683},{"atb":[[2.56,1.65]],"id":8668222}],"con":true,"img":false}]}
{"op":"mcm","clk":"5322491684","pt":1646320862111,"mc":[{"id":"1.195532863","rc":[{"atb":[[3,1.68]],"id":39693066},{"atb":[[2.72,2.16]],"id":28603683}],"con":true,"img":false}]}
{"op":"mcm","clk":"5322491719","pt":1646320862421,"mc":[{"id":"1.195532863","rc":[{"atb":[[2.94,0]],"id":39693066}],"con":true,"img":false}]}
{"op":"mcm","clk":"5322491729","pt":1646320862475,"mc":[{"id":"1.195532863","rc":[{"atb":[[2.98,3.64]],"id":39693066}],"con":true,"img":false}]}
{"op":"mcm","clk":"5322491756","pt":1646320862799,"mc":[{"id":"1.195532863","rc":[{"atb":[[2.62,19.03]],"id":36042617},{"atb":[[2.3,0]],"id":8668222}],"con":true,"img":false}]}
{"op":"mcm","clk":"5322491776","pt":1646320863008,"mc":[{"id":"1.195532863","rc":[{"atb":[[2.68,2.25]],"id":28603683}],"con":true,"img":false}]}
{"op":"mcm","clk":"5322491788","pt":1646320863109,"mc":[{"id":"1.195532863","rc":[{"atb":[[2.74,1.99]],"id":28603683}],"con":true,"img":false}]}
{"op":"mcm","clk":"5322491795","pt":1646320863213,"mc":[{"id":"1.195532863","rc":[{"atl":[[5.1,69.98]],"id":28603683}],"con":true,"img":false}]}
{"op":"mcm","clk":"5322491806","pt":1646320863320,"mc":[{"id":"1.195532863","rc":[{"atb":[[2.76,2.08]],"id":28603683}],"con":true,"img":false}]}
{"op":"mcm","clk":"5322491816","pt":1646320863372,"mc":[{"id":"1.195532863","rc":[{"atl":[[4.1,35.21]],"id":8668222}],"con":true,"img":false}]}
{"op":"mcm","clk":"5322491850","pt":1646320863792,"mc":[{"id":"1.195532863","rc":[{"atb":[[2.74,0]],"id":28603683},{"atl":[[4.1,31.25]],"id":8668222}],"con":true,"img":false}]}
{"op":"mcm","clk":"5322491862","pt":1646320863890,"mc":[{"id":"1.195532863","rc":[{"atb":[[2.78,1.99]],"id":28603683}],"con":true,"img":false}]}
{"op":"mcm","clk":"5322491872","pt":1646320863996,"mc":[{"id":"1.195532863","rc":[{"atb":[[2.72,0],[2.76,0],[2.68,0]],"id":28603683}],"con":true,"img":false}]}
{"op":"mcm","clk":"5322491905","pt":1646320864302,"mc":[{"id":"1.195532863","rc":[{"atb":[[2.78,0]],"id":28603683}],"con":true,"img":false}]}
{"op":"mcm","clk":"5322491914","pt":1646320864423,"mc":[{"id":"1.195532863","rc":[{"atb":[[2.72,4.15]],"id":28603683}],"con":true,"img":false}]}
{"op":"mcm","clk":"5322492034","pt":1646320865776,"mc":[{"id":"1.195532863","rc":[{"atb":[[3,6.29]],"id":39693066}],"con":true,"img":false}]}
{"op":"mcm","clk":"5322492043","pt":1646320865880,"mc":[{"id":"1.195532863","rc":[{"atb":[[2.92,24.54]],"id":39693066}],"con":true,"img":false}]}
{"op":"mcm","clk":"5322492052","pt":1646320865982,"mc":[{"id":"1.195532863","rc":[{"atb":[[2.8,2],[2.92,17.79]],"id":39693066}],"con":true,"img":false}]}
{"op":"mcm","clk":"5322492067","pt":1646320866191,"mc":[{"id":"1.195532863","rc":[{"atb":[[2.58,34.77]],"id":36042617}],"con":true,"img":false}]}
{"op":"mcm","clk":"5322492075","pt":1646320866294,"mc":[{"id":"1.195532863","rc":[{"atb":[[2.56,2.52]],"id":36042617}],"con":true,"img":false}]}
{"op":"mcm","clk":"5322492097","pt":1646320866504,"mc":[{"id":"1.195532863","rc":[{"atb":[[2.98,1.65]],"id":39693066}],"con":true,"img":false}]}
{"op":"mcm","clk":"5322492112","pt":1646320866604,"mc":[{"id":"1.195532863","rc":[{"atb":[[3.05,1.99]],"id":39693066}],"con":true,"img":false}]}
{"op":"mcm","clk":"5322492120","pt":1646320866710,"mc":[{"id":"1.195532863","rc":[{"atb":[[3.1,3.91]],"id":39693066}],"con":true,"img":false}]}
{"op":"mcm","clk":"5322492135","pt":1646320866918,"mc":[{"id":"1.195532863","rc":[{"atb":[[3.05,0]],"id":39693066}],"con":true,"img":false}]}
{"op":"mcm","clk":"5322492147","pt":1646320867022,"mc":[{"id":"1.195532863","rc":[{"atb":[[3.15,1.99]],"id":39693066}],"con":true,"img":false}]}
{"op":"mcm","clk":"5322492161","pt":1646320867185,"mc":[{"id":"1.195532863","rc":[{"atb":[[3.2,3.61]],"id":39693066},{"atb":[[2.66,4.21]],"id":36042617},{"atb":[[2.44,4.96]],"id":8668222}],"con":true,"img":false}]}
{"op":"mcm","clk":"5322492186","pt":1646320867393,"mc":[{"id":"1.195532863","rc":[{"atb":[[2.64,0]],"id":36042617}],"con":true,"img":false}]}
{"op":"mcm","clk":"5322492195","pt":1646320867502,"mc":[{"id":"1.195532863","rc":[{"atb":[[2.68,1.99]],"id":36042617}],"con":true,"img":false}]}
{"op":"mcm","clk":"5322492213","pt":1646320867705,"mc":[{"id":"1.195532863","rc":[{"atb":[[3.15,0]],"id":39693066}],"con":true,"img":false}]}
{"op":"mcm","clk":"5322492224","pt":1646320867809,"mc":[{"id":"1.195532863","rc":[{"atb":[[3.25,1.99]],"id":39693066}],"con":true,"img":false}]}
{"op":"mcm","clk":"5322492232","pt":1646320867915,"mc":[{"id":"1.195532863","rc":[{"atb":[[2.8,0],[3.1,0],[3,4.61],[2.92,15.99],[3.2,0],[2.96,0]],"id":39693066}],"con":true,"img":false}]}
{"op":"mcm","clk":"5322492275","pt":1646320868289,"mc":[{"id":"1.195532863","rc":[{"atb":[[3.3,3.35]],"id":39693066}],"con":true,"img":false}]}
{"op":"mcm","clk":"5322492303","pt":1646320868598,"mc":[{"id":"1.195532863","rc":[{"atb":[[3.25,0]],"id":39693066},{"atl":[[4,50.78],[3.95,13.56],[4.1,41.4]],"id":8668222}],"con":true,"img":false}]}
{"op":"mcm","clk":"5322492313","pt":1646320868709,"mc":[{"id":"1.195532863","rc":[{"atb":[[3.35,1.99],[3.3,0]],"id":39693066},{"atl":[[4,0],[3.95,59.68],[4.1,10.15]],"id":8668222}],"con":true,"img":false}]}
{"op":"mcm","clk":"5322492323","pt":1646320868811,"mc":[{"id":"1.195532863","rc":[{"atl":[[3.95,90.93]],"id":8668222}],"con":true,"img":false}]}
{"op":"mcm","clk":"5322492334","pt":1646320869032,"mc":[{"id":"1.195532863","rc":[{"atb":[[3.35,0]],"id":39693066}],"con":true,"img":false}]}
{"op":"mcm","clk":"5322492341","pt":1646320869123,"mc":[{"id":"1.195532863","rc":[{"atb":[[3.05,1.99]],"id":39693066},{"atl":[[4.1,0]],"id":8668222}],"con":true,"img":false}]}
{"op":"mcm","clk":"5322492364","pt":1646320869387,"mc":[{"id":"1.195532863","rc":[{"atb":[[1.73,9.16]],"id":28691352},{"atl":[[2.96,20.26]],"id":28691352}],"con":true,"img":false}]}
{"op":"mcm","clk":"5322492385","pt":1646320869706,"mc":[{"id":"1.195532863","rc":[{"atb":[[2.98,0]],"id":39693066},{"atb":[[2.66,2.55]],"id":36042617},{"atb":[[2.7,0]],"id":28603683},{"atl":[[2.96,15.07]],"id":28691352}],"con":true,"img":false}]}
{"op":"mcm","clk":"5322492394","pt":1646320869808,"mc":[{"id":"1.195532863","rc":[{"atb":[[2.26,13.57]],"id":28603683}],"con":true,"img":false}]}
{"op":"mcm","clk":"5322492399","pt":1646320869910,"mc":[{"id":"1.195532863","rc":[{"atb":[[3.1,1.65]],"id":39693066},{"atb":[[2.7,1.65]],"id":36042617},{"atb":[[2.74,1.65]],"id":28603683}],"con":true,"img":false}]}
{"op":"mcm","clk":"5322492537","pt":1646320871520,"mc":[{"id":"1.195532863","rc":[{"atb":[[2.62,51.65]],"id":36042617}],"con":true,"img":false}]}
{"op":"mcm","clk":"5322492548","pt":1646320871623,"mc":[{"id":"1.195532863","rc":[{"atb":[[2.58,2.15]],"id":36042617}],"con":true,"img":false}]}
{"op":"mcm","clk":"5322492567","pt":1646320871934,"mc":[{"id":"1.195532863","rc":[{"atb":[[2.74,0],[2.96,15.99]],"id":39693066}],"con":true,"img":false}]}
{"op":"mcm","clk":"5322492586","pt":1646320872200,"mc":[{"id":"1.195532863","rc":[{"atb":[[2.44,33.79],[2.42,0]],"id":8668222}],"con":true,"img":false}]}
{"op":"mcm","clk":"5322492657","pt":1646320873269,"mc":[{"id":"1.195532863","rc":[{"atb":[[2.66,0]],"id":36042617}],"con":true,"img":false}]}
{"op":"mcm","clk":"5322492691","pt":1646320873622,"mc":[{"id":"1.195532863","rc":[{"atb":[[2.68,0]],"id":36042617}],"con":true,"img":false}]}
{"op":"mcm","clk":"5322492700","pt":1646320873727,"mc":[{"id":"1.195532863","rc":[{"atb":[[2.64,1.99]],"id":36042617}],"con":true,"img":false}]}
{"op":"mcm","clk":"5322492717","pt":1646320873933,"mc":[{"id":"1.195532863","rc":[{"atb":[[2.64,21.08]],"id":36042617}],"con":true,"img":false}]}
{"op":"mcm","clk":"5322492737","pt":1646320874147,"mc":[{"id":"1.195532863","rc":[{"atb":[[2.62,32.62]],"id":36042617}],"con":true,"img":false}]}
{"op":"mcm","clk":"5322492796","pt":1646320874825,"mc":[{"id":"1.195532863","rc":[{"atl":[[2.94,12.92]],"id":28691352}],"con":true,"img":false}]}
{"op":"mcm","clk":"5322492807","pt":1646320874923,"mc":[{"id":"1.195532863","rc":[{"atl":[[3,70],[2.96,10]],"id":28691352}],"con":true,"img":false}]}
{"op":"mcm","clk":"5322492814","pt":1646320875028,"mc":[{"id":"1.195532863","rc":[{"atl":[[3.1,47.62],[3,114.16]],"id":28691352}],"con":true,"img":false}]}
{"op":"mcm","clk":"5322492920","pt":1646320876432,"mc":[{"id":"1.195532863","rc":[{"atl":[[3,94.16],[2.98,20.2]],"id":28691352}],"con":true,"img":false}]}
{"op":"mcm","clk":"5322492945","pt":1646320876695,"mc":[{"id":"1.195532863","rc":[{"atb":[[2.58,71.35]],"id":36042617}],"con":true,"img":false}]}
{"op":"mcm","clk":"5322492951","pt":1646320876797,"mc":[{"id":"1.195532863","rc":[{"atb":[[2.62,0]],"id":36042617}],"con":true,"img":false}]}
{"op":"mcm","clk":"5322492974","pt":1646320877108,"mc":[{"id":"1.195532863","rc":[{"atb":[[2.56,15.52]],"id":36042617}],"con":true,"img":false}]}
{"op":"mcm","clk":"5322492980","pt":1646320877213,"mc":[{"id":"1.195532863","rc":[{"atb":[[2.94,8.89],[3.05,7.32],[2.76,3.82]],"id":39693066},{"atl":[[7,19.89]],"id":39693066},{"atb":[[2.56,2.52]],"id":36042617}],"con":true,"img":false}]}
{"op":"mcm","clk":"5322492993","pt":1646320877321,"mc":[{"id":"1.195532863","rc":[{"atb":[[3,0],[2.76,0],[2.92,0],[2.96,35.34]],"id":39693066},{"atb":[[2.66,15.91]],"id":36042617}],"con":true,"img":false}]}
{"op":"mcm","clk":"5322493019","pt":1646320877633,"mc":[{"id":"1.195532863","rc":[{"atb":[[2.94,0]],"id":39693066},{"atb":[[2.64,19.09]],"id":36042617}],"con":true,"img":false}]}
{"op":"mcm","clk":"5322493031","pt":1646320877736,"mc":[{"id":"1.195532863","rc":[{"atl":[[7,11]],"id":39693066},{"atb":[[2.68,1.99],[2.7,0]],"id":36042617}],"con":true,"img":false}]}
{"op":"mcm","clk":"5322493041","pt":1646320877841,"mc":[{"id":"1.195532863","rc":[{"atb":[[2.72,2.5],[2.64,5],[2.56,10]],"id":39693066}],"con":true,"img":false}]}
{"op":"mcm","clk":"5322493047","pt":1646320877946,"mc":[{"id":"1.195532863","rc":[{"atb":[[2.68,3.64]],"id":36042617}],"con":true,"img":false}]}
{"op":"mcm","clk":"5322493060","pt":1646320878106,"mc":[{"id":"1.195532863","rc":[{"atb":[[2.64,62.85],[2.58,2.15]],"id":36042617}],"con":true,"img":false}]}
{"op":"mcm","clk":"5322493148","pt":1646320879513,"mc":[{"id":"1.195532863","rc":[{"atb":[[2.3,0],[3,8.98],[2.36,29.41],[2.96,19.35]],"id":39693066},{"atb":[[2.78,22.47],[2.68,0]],"id":35839928},{"atb":[[1.72,0],[1.68,58.82]],"id":28691352}],"con":true,"img":false}]}
{"op":"mcm","clk":"5322493154","pt":1646320879616,"mc":[{"id":"1.195532863","rc":[{"atb":[[2.54,7.3],[2.3,0],[2.22,81.97],[2.14,219.3],[2.4,4.68],[2.42,0]],"id":36042617},{"atb":[[3.1,0],[3.35,23.81]],"id":35839928},{"atb":[[2.3,13.58],[2.1,36.36]],"id":28603683},{"atb":[[2.54,19.45],[2.36,15.22],[2.28,11]],"id":8668222},{"atb":[[1.73,33.11],[1.59,0],[1.88,11.11],[1.78,11.31],[1.71,6.94]],"id":28691352}],"con":true,"img":false}]}
{"op":"mcm","clk":"5322493170","pt":1646320879822,"mc":[{"id":"1.195532863","rc":[{"atb":[[2.48,2.75]],"id":8668222},{"atb":[[1.71,0]],"id":28691352}],"con":true,"img":false}]}
{"op":"mcm","clk":"5322493174","pt":1646320879928,"mc":[{"id":"1.195532863","rc":[{"atb":[[2.4,0]],"id":36042617}],"con":true,"img":false}]}
{"op":"mcm","clk":"5322493194","pt":1646320880139,"mc":[{"id":"1.195532863","rc":[{"atb":[[3.95,12.68]],"id":35839928},{"atb":[[2.42,0]],"id":28603683},{"atb":[[2.54,2.15]],"id":8668222},{"atb":[[1.7,0]],"id":28691352}],"con":true,"img":false}]}
{"op":"mcm","clk":"5322493201","pt":1646320880250,"mc":[{"id":"1.195532863","rc":[{"atb":[[1.88,1.99],[1.78,2.15]],"id":28691352}],"con":true,"img":false}]}
{"op":"mcm","clk":"5322493212","pt":1646320880349,"mc":[{"id":"1.195532863","rc":[{"atb":[[3.45,2.5],[3.65,25.75]],"id":35839928},{"atb":[[2.54,19.45]],"id":8668222},{"atb":[[1.88,7.92]],"id":28691352}],"con":true,"img":false}]}
{"op":"mcm","clk":"5322493216","pt":1646320880407,"mc":[{"id":"1.195532863","rc":[{"atb":[[2.26,11.42],[2.48,2.15]],"id":28603683},{"atb":[[1.64,156.25]],"id":28691352}],"con":true,"img":false}]}
{"op":"mcm","clk":"5322493251","pt":1646320880827,"mc":[{"id":"1.195532863","rc":[{"atb":[[3.85,4.12],[3.9,13.25]],"id":35839928},{"atb":[[1.88,1.99]],"id":28691352}],"con":true,"img":false}]}
{"op":"mcm","clk":"5322493267","pt":1646320880934,"mc":[{"id":"1.195532863","rc":[{"atb":[[4,1.99]],"id":35839928}],"con":true,"img":false}]}
{"op":"mcm","clk":"5322493274","pt":1646320881038,"mc":[{"id":"1.195532863","rc":[{"atb":[[3.85,0]],"id":35839928}],"con":true,"img":false}]}
{"op":"mcm","clk":"5322493287","pt":1646320881140,"mc":[{"id":"1.195532863","rc":[{"atb":[[2.3,35.13]],"id":28603683}],"con":true,"img":false}]}
{"op":"mcm","clk":"5322493296","pt":1646320881246,"mc":[{"id":"1.195532863","rc":[{"atb":[[2.26,0]],"id":28603683}],"con":true,"img":false}]}
{"op":"mcm","clk":"5322493319","pt":1646320881512,"mc":[{"id":"1.195532863","rc":[{"atb":[[2.66,0]],"id":36042617}],"con":true,"img":false}]}
{"op":"mcm","clk":"5322493359","pt":1646320881928,"mc":[{"id":"1.195532863","rc":[{"atb":[[2.64,19.09],[2.58,53.49],[2.68,1.65]],"id":36042617}],"con":true,"img":false}]}
{"op":"mcm","clk":"5322493366","pt":1646320882026,"mc":[{"id":"1.195532863","rc":[{"atb":[[2.66,1.99]],"id":36042617}],"con":true,"img":false}]}
{"op":"mcm","clk":"5322493389","pt":1646320882443,"mc":[{"id":"1.195532863","rc":[{"atb":[[2.54,0]],"id":36042617},{"atb":[[2.54,2.15],[2.36,0]],"id":8668222}],"con":true,"img":false}]}
{"op":"mcm","clk":"5322493397","pt":1646320882548,"mc":[{"id":"1.195532863","rc":[{"atb":[[2.54,6.66]],"id":8668222}],"con":true,"img":false}]}
{"op":"mcm","clk":"5322493405","pt":1646320882655,"mc":[{"id":"1.195532863","rc":[{"atb":[[2.64,0],[2.44,69.44]],"id":36042617},{"atb":[[2.3,21.55]],"id":28603683},{"atb":[[2.26,26.22]],"id":8668222},{"atb":[[1.73,9.16],[1.64,0]],"id":28691352}],"con":true,"img":false}]}
{"op":"mcm","clk":"5322493411","pt":1646320882757,"mc":[{"id":"1.195532863","rc":[{"atl":[[5.2,0]],"id":36042617},{"atb":[[2.2,48.45]],"id":28603683},{"atb":[[1.6,166.67]],"id":28691352}],"con":true,"img":false}]}
{"op":"mcm","clk":"5322493429","pt":1646320882919,"mc":[{"id":"1.195532863","rc":[{"atl":[[5.5,105.22]],"id":36042617}],"con":true,"img":false}]}
{"op":"mcm","clk":"5322493435","pt":1646320883027,"mc":[{"id":"1.195532863","rc":[{"atl":[[5.1,17],[5.3,17.08]],"id":36042617},{"atb":[[2.54,2.15]],"id":8668222}],"con":true,"img":false}]}
{"op":"mcm","clk":"5322493449","pt":1646320883336,"mc":[{"id":"1.195532863","rc":[{"atb":[[2.56,45.12],[2.58,2.15]],"id":36042617}],"con":true,"img":false}]}
{"op":"mcm","clk":"5322493457","pt":1646320883437,"mc":[{"id":"1.195532863","rc":[{"atl":[[5.4,3.49]],"id":36042617},{"atb":[[1.73,0]],"id":28691352}],"con":true,"img":false}]}
{"op":"mcm","clk":"5322493463","pt":1646320883548,"mc":[{"id":"1.195532863","rc":[{"atl":[[5.3,32.56]],"id":36042617}],"con":true,"img":false}]}
{"op":"mcm","clk":"5322493466","pt":1646320883643,"mc":[{"id":"1.195532863","rc":[{"atl":[[5.5,83]],"id":36042617}],"con":true,"img":false}]}
{"op":"mcm","clk":"5322493486","pt":1646320883956,"mc":[{"id":"1.195532863","rc":[{"atl":[[5.4,0]],"id":36042617}],"con":true,"img":false}]}
{"op":"mcm","clk":"5322493527","pt":1646320884539,"mc":[{"id":"1.195532863","rc":[{"atb":[[2.66,0]],"id":36042617}],"con":true,"img":false}]}
{"op":"mcm","clk":"5322493533","pt":1646320884636,"mc":[{"id":"1.195532863","rc":[{"atb":[[2.6,1.99],[2.58,25.36]],"id":36042617}],"con":true,"img":false}]}
{"op":"mcm","clk":"5322493543","pt":1646320884855,"mc":[{"id":"1.195532863","rc":[{"atb":[[3.35,0],[3.8,25.36],[3.2,3.62]],"id":35839928}],"con":true,"img":false}]}
{"op":"mcm","clk":"5322493566","pt":1646320885057,"mc":[{"id":"1.195532863","rc":[{"atb":[[3.2,0]],"id":35839928}],"con":true,"img":false}]}
{"op":"mcm","clk":"5322493575","pt":1646320885163,"mc":[{"id":"1.195532863","rc":[{"atb":[[2.6,23.6]],"id":36042617}],"con":true,"img":false}]}
{"op":"mcm","clk":"5322493599","pt":1646320885468,"mc":[{"id":"1.195532863","rc":[{"atb":[[2.58,2.15]],"id":36042617}],"con":true,"img":false}]}
{"op":"mcm","clk":"5322493608","pt":1646320885572,"mc":[{"id":"1.195532863","rc":[{"atl":[[5,4.66]],"id":36042617}],"con":true,"img":false}]}
{"op":"mcm","clk":"5322493618","pt":1646320885682,"mc":[{"id":"1.195532863","rc":[{"atb":[[2.68,0]],"id":36042617}],"con":true,"img":false}]}
{"op":"mcm","clk":"5322493629","pt":1646320885789,"mc":[{"id":"1.195532863","rc":[{"atb":[[2.62,1.65]],"id":36042617},{"atl":[[4.9,16.24]],"id":36042617}],"con":true,"img":false}]}
{"op":"mcm","clk":"5322493637","pt":1646320885891,"mc":[{"id":"1.195532863","rc":[{"atb":[[2.58,6.52]],"id":36042617}],"con":true,"img":false}]}
{"op":"mcm","clk":"5322493646","pt":1646320885987,"mc":[{"id":"1.195532863","rc":[{"atl":[[5.1,13.5]],"id":36042617}],"con":true,"img":false}]}
{"op":"mcm","clk":"5322493653","pt":1646320886091,"mc":[{"id":"1.195532863","rc":[{"atl":[[2.8,9.12]],"id":28691352}],"con":true,"img":false}]}
{"op":"mcm","clk":"5322493661","pt":1646320886151,"mc":[{"id":"1.195532863","rc":[{"atl":[[3,44.16],[2.96,35.84],[2.94,0],[3.05,8.75]],"id":28691352}],"con":true,"img":false}]}
{"op":"mcm","clk":"5322493670","pt":1646320886299,"mc":[{"id":"1.195532863","rc":[{"atl":[[3,0],[2.96,74.08]],"id":28691352}],"con":true,"img":false}]}
{"op":"mcm","clk":"5322493677","pt":1646320886358,"mc":[{"id":"1.195532863","rc":[{"atl":[[3.05,0]],"id":28691352}],"con":true,"img":false}]}
{"op":"mcm","clk":"5322493687","pt":1646320886490,"mc":[{"id":"1.195532863","rc":[{"atl":[[5.1,23.26],[5.3,23.26]],"id":36042617},{"atl":[[2.96,35.84]],"id":28691352}],"con":true,"img":false}]}
{"op":"mcm","clk":"5322493749","pt":1646320887185,"mc":[{"id":"1.195532863","rc":[{"atl":[[4.6,66.88]],"id":28603683}],"con":true,"img":false}]}
{"op":"mcm","clk":"5322493756","pt":1646320887249,"mc":[{"id":"1.195532863","rc":[{"atb":[[2.32,75.76]],"id":39693066},{"atb":[[2.74,57.47]],"id":35839928},{"atb":[[1.66,151.52]],"id":28691352},{"atl":[[2.98,0],[2.84,21.74]],"id":28691352}],"con":true,"img":false}]}
{"op":"mcm","clk":"5322493793","pt":1646320887657,"mc":[{"id":"1.195532863","rc":[{"atl":[[4.6,61.16]],"id":28603683}],"con":true,"img":false}]}
{"op":"mcm","clk":"5322493823","pt":1646320887969,"mc":[{"id":"1.195532863","rc":[{"atb":[[2.22,0],[2.26,0],[2.18,0]],"id":39693066},{"atb":[[2.64,0],[2.6,0],[2.56,0]],"id":35839928}],"con":true,"img":false}]}
{"op":"mcm","clk":"5322493861","pt":1646320888595,"mc":[{"id":"1.195532863","rc":[{"atb":[[1.69,10.74]],"id":28691352}],"con":true,"img":false}]}
{"op":"mcm","clk":"5322493869","pt":1646320888651,"mc":[{"id":"1.195532863","rc":[{"atl":[[5.3,0],[4.9,32.48]],"id":36042617}],"con":true,"img":false}]}
{"op":"mcm","clk":"5322493952","pt":1646320889804,"mc":[{"id":"1.195532863","rc":[{"atb":[[2.3,30.77],[3,0],[2.36,0],[2.96,33.99]],"id":39693066},{"atb":[[3.05,19.51]],"id":35839928},{"atb":[[1.63,63.49]],"id":28691352}],"con":true,"img":false}]}
{"op":"mcm","clk":"5322493958","pt":1646320889846,"mc":[{"id":"1.195532863","rc":[{"atb":[[1.68,0]],"id":28691352}],"con":true,"img":false}]}
{"op":"mcm","clk":"5322493991","pt":1646320889948,"mc":[{"id":"1.195532863","rc":[{"atb":[[2.72,21.85],[2.96,14.63]],"id":39693066},{"atb":[[2.22,5.91]],"id":8668222},{"atl":[[2.8,0],[2.78,4.26]],"id":28691352}],"con":true,"img":false}]}
{"op":"mcm","clk":"5322493999","pt":1646320890063,"mc":[{"id":"1.195532863","rc":[{"atl":[[2.76,3.11]],"id":28691352}],"con":true,"img":false}]}
{"op":"mcm","clk":"5322494015","pt":1646320890264,"mc":[{"id":"1.195532863","rc":[{"atb":[[2.32,0]],"id":39693066}],"con":true,"img":false}]}
{"op":"mcm","clk":"5322494030","pt":1646320890470,"mc":[{"id":"1.195532863","rc":[{"atl":[[3.95,96.29]],"id":8668222}],"con":true,"img":false}]}
{"op":"mcm","clk":"5322494037","pt":1646320890583,"mc":[{"id":"1.195532863","rc":[{"atb":[[2.22,0]],"id":8668222},{"atl":[[2.78,0]],"id":28691352}],"con":true,"img":false}]}
{"op":"mcm","clk":"5322494050","pt":1646320890780,"mc":[{"id":"1.195532863","rc":[{"atl":[[5,0]],"id":36042617},{"atb":[[1.69,29.15]],"id":28691352},{"atl":[[2.76,0]],"id":28691352}],"con":true,"img":false}]}
{"op":"mcm","clk":"5322494060","pt":1646320890885,"mc":[{"id":"1.195532863","rc":[{"atl":[[2.78,3.95]],"id":28691352}],"con":true,"img":false}]}
{"op":"mcm","clk":"5322494066","pt":1646320890987,"mc":[{"id":"1.195532863","rc":[{"atl":[[5.5,105.22],[4.9,16.24]],"id":36042617}],"con":true,"img":false}]}
{"op":"mcm","clk":"5322494072","pt":1646320891091,"mc":[{"id":"1.195532863","rc":[{"atb":[[2.36,29.41]],"id":39693066},{"atb":[[2.26,0],[2.2,33.33]],"id":36042617},{"atb":[[3.1,19.05]],"id":35839928},{"atb":[[2.1,0],[2.14,35.09]],"id":28603683},{"atb":[[2,40],[2.04,0]],"id":8668222},{"atb":[[1.72,2.15],[1.59,67.8],[1.63,0],[1.78,0],[1.66,0]],"id":28691352},{"atl":[[2.82,21.98],[2.84,0],[2.78,0]],"id":28691352}],"con":true,"img":false}]}
{"op":"mcm","clk":"5322494084","pt":1646320891145,"mc":[{"id":"1.195532863","rc":[{"atl":[[4.9,0]],"id":36042617}],"con":true,"img":false}]}
{"op":"mcm","clk":"5322494090","pt":1646320891250,"mc":[{"id":"1.195532863","rc":[{"atl":[[5.6,104.15],[5.5,27.22]],"id":36042617},{"atl":[[2.8,3.11],[3.1,95.24],[2.96,10]],"id":28691352}],"con":true,"img":false}]}
{"op":"mcm","clk":"5322494104","pt":1646320891356,"mc":[{"id":"1.195532863","rc":[{"atl":[[5,20]],"id":36042617},{"atl":[[3.1,47.62],[2.96,57.62]],"id":28691352}],"con":true,"img":false}]}
{"op":"mcm","clk":"5322494112","pt":1646320891459,"mc":[{"id":"1.195532863","rc":[{"atb":[[3.8,60.26],[3.65,2.63]],"id":35839928}],"con":true,"img":false}]}
{"op":"mcm","clk":"5322494124","pt":1646320891564,"mc":[{"id":"1.195532863","rc":[{"atl":[[3.95,90.93]],"id":8668222}],"con":true,"img":false}]}
{"op":"mcm","clk":"5322494195","pt":1646320892553,"mc":[{"id":"1.195532863","rc":[{"atl":[[4.7,4.41]],"id":36042617}],"con":true,"img":false}]}
{"op":"mcm","clk":"5322494234","pt":1646320893174,"mc":[{"id":"1.195532863","rc":[{"atb":[[2.22,0]],"id":36042617},{"atl":[[5.1,13.5],[4.9,10.26]],"id":36042617},{"atl":[[2.82,0],[2.84,21.74]],"id":28691352}],"con":true,"img":false}]}
{"op":"mcm","clk":"5322494278","pt":1646320893953,"mc":[{"id":"1.195532863","rc":[{"atl":[[5.6,21.74],[5,80.52]],"id":36042617}],"con":true,"img":false}]}
{"op":"mcm","clk":"5322494355","pt":1646320894788,"mc":[{"id":"1.195532863","rc":[{"atb":[[1.69,18.41]],"id":28691352}],"con":true,"img":false}]}
{"op":"mcm","clk":"5322494366","pt":1646320894898,"mc":[{"id":"1.195532863","rc":[{"atb":[[3.05,21.96]],"id":39693066},{"atl":[[2.8,0]],"id":28691352}],"con":true,"img":false}]}
{"op":"mcm","clk":"5322494375","pt":1646320894997,"mc":[{"id":"1.195532863","rc":[{"atb":[[2.96,0]],"id":39693066},{"atl":[[2.72,3.95]],"id":28691352}],"con":true,"img":false}]}
{"op":"mcm","clk":"5322494391","pt":1646320895157,"mc":[{"id":"1.195532863","rc":[{"atb":[[2.72,2.49],[2.64,40.44]],"id":39693066}],"con":true,"img":false}]}
