{"op":"mcm","clk":"5345904394","pt":1646079078742,"mc":[{"id":"1.195395456","marketDefinition":{"bspMarket":false,"turnInPlayEnabled":false,"persistenceEnabled":false,"marketBaseRate":5.0,"eventId":"31270459","eventTypeId":"4339","numberOfWinners":3,"bettingType":"ODDS","marketType":"PLACE","marketTime":"2022-03-01T02:04:00.000Z","suspendTime":"2022-03-01T02:04:00.000Z","bspReconciled":false,"complete":true,"inPlay":false,"crossMatching":false,"runnersVoidable":false,"numberOfActiveRunners":8,"betDelay":0,"status":"OPEN","runners":[{"status":"ACTIVE","sortPriority":1,"id":37672294,"name":"1. Wizard Willie"},{"status":"ACTIVE","sortPriority":2,"id":28002629,"name":"2. St Andrews"},{"status":"ACTIVE","sortPriority":3,"id":43154433,"name":"3. Sapporo Bale"},{"status":"ACTIVE","sortPriority":4,"id":42393370,"name":"5. Goldstar Tookie"},{"status":"ACTIVE","sortPriority":5,"id":22150928,"name":"6. Smash Grenade"},{"status":"ACTIVE","sortPriority":6,"id":36993903,"name":"7. Baldrick"},{"status":"ACTIVE","sortPriority":7,"id":37267533,"name":"8. Diamond Empress"},{"status":"ACTIVE","sortPriority":8,"id":37455733,"name":"9. Just Stagger"}],"regulators":["MR_INT"],"venue":"Addington","countryCode":"NZ","discountAllowed":false,"timezone":"NZ","openDate":"2022-02-28T23:02:00.000Z","version":4380660683,"name":"To Be Placed","eventName":"Addington (NZL) 1st Mar"},"rc":[],"con":true,"img":false}]}
{"op":"mcm","clk":"5345904625","pt":1646079080740,"mc":[{"id":"1.195395456","marketDefinition":{"bspMarket":false,"turnInPlayEnabled":false,"persistenceEnabled":false,"marketBaseRate":5.0,"eventId":"31270459","eventTypeId":"4339","numberOfWinners":3,"bettingType":"ODDS","marketType":"PLACE","marketTime":"2022-03-01T02:04:00.000Z","suspendTime":"2022-03-01T02:04:00.000Z","bspReconciled":false,"complete":true,"inPlay":false,"crossMatching":false,"runnersVoidable":false,"numberOfActiveRunners":8,"betDelay":0,"status":"OPEN","runners":[{"status":"ACTIVE","sortPriority":1,"id":37672294,"name":"1. Wizard Willie"},{"status":"ACTIVE","sortPriority":2,"id":28002629,"name":"2. St Andrews"},{"status":"ACTIVE","sortPriority":3,"id":43154433,"name":"3. Sapporo Bale"},{"status":"ACTIVE","sortPriority":4,"id":42393370,"name":"5. Goldstar Tookie"},{"status":"ACTIVE","sortPriority":5,"id":22150928,"name":"6. Smash Grenade"},{"status":"ACTIVE","sortPriority":6,"id":36993903,"name":"7. Baldrick"},{"status":"ACTIVE","sortPriority":7,"id":37267533,"name":"8. Diamond Empress"},{"status":"ACTIVE","sortPriority":8,"id":37455733,"name":"9. Just Stagger"}],"regulators":["MR_INT"],"venue":"Addington","countryCode":"NZ","discountAllowed":true,"timezone":"NZ","openDate":"2022-02-28T23:02:00.000Z","version":4380660683,"name":"To Be Placed","eventName":"Addington (NZL) 1st Mar"},"rc":[],"con":true,"img":false}]}
{"op":"mcm","clk":"5346133847","pt":1646081622893,"mc":[{"id":"1.195395456","rc":[{"atb":[[2,60.08],[1.9,133.52],[1.95,126.49]],"id":37672294},{"atl":[[5.1,2.92],[6.2,2.31],[10.5,2.52],[8.2,3.33],[15.5,3.31]],"id":37672294},{"atb":[[1.85,141.37],[1.9,133.52],[1.95,63.24]],"id":28002629},{"atl":[[5.6,2.61],[7.2,3.87],[4.6,3.33],[9.2,2.92],[13,4]],"id":28002629},{"atb":[[1.2,600.84],[1.25,240.33],[1.15,801.12]],"id":42393370},{"atl":[[3.6,18.48],[3.1,11.44],[2.44,8.34],[2.64,7.32],[2.84,13.06]],"id":42393370},{"atb":[[2.8,33.38],[2.6,75.1],[2.7,70.68]],"id":37267533},{"atl":[[7.2,1.93],[18,1.41],[9.2,1.46],[13,2],[26,1.92]],"id":37267533},{"atb":[[2.82,66.02],[2.92,62.59],[3.05,29.31]],"id":36993903},{"atl":[[32,1.54],[10.5,1.26],[21,1.2],[8.2,1.66],[15.5,1.65]],"id":36993903},{"atb":[[2.74,69.06],[2.84,65.3],[2.94,30.97]],"id":37455733},{"atl":[[8,1.71],[10,1.33],[20,1.26],[15,1.71],[30,1.65]],"id":37455733},{"atb":[[2.3,46.21],[2.2,100.14],[2.1,109.24]],"id":22150928},{"atl":[[5.6,2.61],[7.2,1.93],[18,2.82],[9.2,2.92],[13,2]],"id":22150928},{"atb":[[1.01,12016.88],[1.02,6008.44],[1.07,858.34]],"id":43154433},{"atl":[[2.88,25.56],[2.28,9.38],[2.68,14.3],[2.08,11.12],[2.48,16.23]],"id":43154433}],"con":true,"img":false}]}
{"op":"mcm","clk":"5346134853","pt":1646081638490,"mc":[{"id":"1.195395456","rc":[{"atb":[[2,0],[1.9,0],[1.95,0]],"id":37672294},{"atl":[[5.1,0],[6.2,0],[10.5,0],[8.2,0],[15.5,0]],"id":37672294},{"atb":[[1.85,0],[1.9,0],[1.95,0]],"id":28002629},{"atl":[[5.6,0],[7.2,0],[4.6,0],[9.2,0],[13,0]],"id":28002629},{"atb":[[1.2,0],[1.25,0],[1.15,0]],"id":42393370},{"atl":[[3.6,0],[3.1,0],[2.44,0],[2.64,0],[2.84,0]],"id":42393370},{"atb":[[2.8,0],[2.6,0],[2.7,0]],"id":37267533},{"atl":[[7.2,0],[18,0],[9.2,0],[13,0],[26,0]],"id":37267533},{"atb":[[2.82,0],[2.92,0],[3.05,0]],"id":36993903},{"atl":[[32,0],[10.5,0],[21,0],[8.2,0],[15.5,0]],"id":36993903},{"atb":[[2.74,0],[2.84,0],[2.94,0]],"id":37455733},{"atl":[[8,0],[10,0],[20,0],[15,0],[30,0]],"id":37455733},{"atb":[[2.3,0],[2.2,0],[2.1,0]],"id":22150928},{"atl":[[5.6,0],[7.2,0],[18,0],[9.2,0],[13,0]],"id":22150928},{"atb":[[1.01,0],[1.02,0],[1.07,0]],"id":43154433},{"atl":[[2.88,0],[2.28,0],[2.68,0],[2.08,0],[2.48,0]],"id":43154433}],"con":true,"img":false}]}
{"op":"mcm","clk":"5346136100","pt":1646081658434,"mc":[{"id":"1.195395456","rc":[{"atb":[[2,60.08],[1.9,133.52],[1.95,126.49]],"id":37672294},{"atl":[[5.1,2.92],[6.2,2.31],[10.5,2.52],[8.2,3.33],[15.5,3.31]],"id":37672294},{"atb":[[1.85,141.37],[1.9,133.52],[1.95,63.24]],"id":28002629},{"atl":[[5.6,2.61],[7.2,3.87],[4.6,3.33],[9.2,2.92],[13,4]],"id":28002629},{"atb":[[1.2,600.84],[1.25,240.33],[1.15,801.12]],"id":42393370},{"atl":[[3.6,18.48],[3.1,11.44],[2.44,8.34],[2.64,7.32],[2.84,13.06]],"id":42393370},{"atb":[[2.8,33.38],[2.6,75.1],[2.7,70.68]],"id":37267533},{"atl":[[7.2,1.93],[18,1.41],[9.2,1.46],[13,2],[26,1.92]],"id":37267533},{"atb":[[2.82,66.02],[2.92,62.59],[3.05,29.31]],"id":36993903},{"atl":[[32,1.54],[10.5,1.26],[21,1.2],[8.2,1.66],[15.5,1.65]],"id":36993903},{"atb":[[2.74,69.06],[2.84,65.3],[2.94,30.97]],"id":37455733},{"atl":[[8,1.71],[10,1.33],[20,1.26],[15,1.71],[30,1.65]],"id":37455733},{"atb":[[2.3,46.21],[2.2,100.14],[2.1,109.24]],"id":22150928},{"atl":[[5.6,2.61],[7.2,1.93],[18,2.82],[9.2,2.92],[13,2]],"id":22150928},{"atb":[[1.01,12016.88],[1.02,6008.44],[1.07,858.34]],"id":43154433},{"atl":[[2.88,25.56],[2.28,9.38],[2.68,14.3],[2.08,11.12],[2.48,16.23]],"id":43154433}],"con":true,"img":false}]}
{"op":"mcm","clk":"5346138746","pt":1646081696372,"mc":[{"id":"1.195395456","rc":[{"atb":[[2,0],[1.9,0],[1.95,0]],"id":37672294},{"atl":[[5.1,0],[6.2,0],[10.5,0],[8.2,0],[15.5,0]],"id":37672294},{"atb":[[1.85,0],[1.9,0],[1.95,0]],"id":28002629},{"atl":[[5.6,0],[7.2,0],[4.6,0],[9.2,0],[13,0]],"id":28002629},{"atb":[[1.2,0],[1.25,0],[1.15,0]],"id":42393370},{"atl":[[3.6,0],[3.1,0],[2.44,0],[2.64,0],[2.84,0]],"id":42393370},{"atb":[[2.8,0],[2.6,0],[2.7,0]],"id":37267533},{"atl":[[7.2,0],[18,0],[9.2,0],[13,0],[26,0]],"id":37267533},{"atb":[[2.82,0],[2.92,0],[3.05,0]],"id":36993903},{"atl":[[32,0],[10.5,0],[21,0],[8.2,0],[15.5,0]],"id":36993903},{"atb":[[2.74,0],[2.84,0],[2.94,0]],"id":37455733},{"atl":[[8,0],[10,0],[20,0],[15,0],[30,0]],"id":37455733},{"atb":[[2.3,0],[2.2,0],[2.1,0]],"id":22150928},{"atl":[[5.6,0],[7.2,0],[18,0],[9.2,0],[13,0]],"id":22150928},{"atb":[[1.01,0],[1.02,0],[1.07,0]],"id":43154433},{"atl":[[2.88,0],[2.28,0],[2.68,0],[2.08,0],[2.48,0]],"id":43154433}],"con":true,"img":false}]}
{"op":"mcm","clk":"5346140410","pt":1646081720446,"mc":[{"id":"1.195395456","rc":[{"atb":[[2,120.16],[2.2,50.07],[2.1,109.24]],"id":37672294},{"atl":[[17.5,2.91],[9,3],[5.5,2.66],[12.5,2.08],[7,2]],"id":37672294},{"atb":[[1.4,300.42],[1.45,133.52],[1.35,343.34]],"id":28002629},{"atl":[[4.5,13.73],[2.9,6.32],[3.25,10.67],[3.75,8.74],[2.7,7.06]],"id":28002629},{"atb":[[1.2,600.84],[1.25,480.67],[1.3,200.28]],"id":42393370},{"atl":[[2.54,7.8],[3.85,16.86],[2.74,6.9],[3.35,10.22],[2.94,12.39]],"id":42393370},{"atb":[[2.88,63.92],[2.98,30.34],[2.78,67.51]],"id":37267533},{"atl":[[32,1.54],[10.5,1.26],[21,1.2],[8.2,1.66],[15.5,1.65]],"id":37267533},{"atb":[[3.45,24.52],[3.2,54.62],[2.98,60.69]],"id":36993903},{"atl":[[18.5,1.37],[44,1.12],[13.5,0.96],[27,0.92],[9.4,1.42]],"id":36993903},{"atb":[[2.88,63.92],[2.98,30.34],[2.78,67.51]],"id":37455733},{"atl":[[32,1.54],[10.5,1.26],[21,1.2],[8.2,1.66],[15.5,1.65]],"id":37455733},{"atb":[[2.4,85.83],[2.5,40.05],[2.3,92.43]],"id":22150928},{"atl":[[8,1.71],[10,2.66],[20,2.52],[6,2.4],[15,1.71]],"id":22150928},{"atb":[[1.01,12016.88],[1.02,6008.44],[1.07,858.34]],"id":43154433},{"atl":[[2.88,25.56],[2.28,9.38],[2.68,14.3],[2.08,11.12],[2.48,16.23]],"id":43154433}],"con":true,"img":false}]}
{"op":"mcm","clk":"5346196003","pt":1646082440986,"mc":[{"id":"1.195395456","rc":[{"atb":[[2,0],[2.2,0],[2.1,0]],"id":37672294},{"atl":[[17.5,0],[9,0],[5.5,0],[12.5,0],[7,0]],"id":37672294},{"atb":[[1.4,0],[1.45,0],[1.35,0]],"id":28002629},{"atl":[[4.5,0],[2.9,0],[3.25,0],[3.75,0],[2.7,0]],"id":28002629},{"atb":[[1.2,0],[1.25,0],[1.3,0]],"id":42393370},{"atl":[[2.54,0],[3.85,0],[2.74,0],[3.35,0],[2.94,0]],"id":42393370},{"atb":[[2.88,0],[2.98,0],[2.78,0]],"id":37267533},{"atl":[[32,0],[10.5,0],[21,0],[8.2,0],[15.5,0]],"id":37267533},{"atb":[[3.45,0],[3.2,0],[2.98,0]],"id":36993903},{"atl":[[18.5,0],[44,0],[13.5,0],[27,0],[9.4,0]],"id":36993903},{"atb":[[2.88,0],[2.98,0],[2.78,0]],"id":37455733},{"atl":[[32,0],[10.5,0],[21,0],[8.2,0],[15.5,0]],"id":37455733},{"atb":[[2.4,0],[2.5,0],[2.3,0]],"id":22150928},{"atl":[[8,0],[10,0],[20,0],[6,0],[15,0]],"id":22150928}],"con":true,"img":false}]}
{"op":"mcm","clk":"5346196483","pt":1646082446521,"mc":[{"id":"1.195395456","rc":[{"atb":[[2.3,46.21],[2.2,100.14],[2.1,109.24]],"id":37672294},{"atl":[[5.6,2.61],[7.2,1.93],[18,2.82],[9.2,2.92],[13,2]],"id":37672294},{"atb":[[1.4,300.42],[1.45,267.04],[1.5,120.16]],"id":28002629},{"atl":[[3.45,9.8],[3.95,8.14],[4.9,12.32],[2.98,6.06],[2.78,6.75]],"id":28002629},{"atb":[[1.2,600.84],[1.25,480.67],[1.3,200.28]],"id":42393370},{"atl":[[2.54,7.8],[3.85,16.86],[2.74,6.9],[3.35,10.22],[2.94,12.39]],"id":42393370},{"atb":[[2.82,66.02],[2.92,62.59],[3.05,29.31]],"id":37267533},{"atl":[[32,1.54],[10.5,1.26],[21,1.2],[8.2,1.66],[15.5,1.65]],"id":37267533},{"atb":[[3.55,23.56],[3.3,52.24],[3.05,58.61]],"id":36993903},{"atl":[[19.5,1.29],[48,1.02],[9.8,1.36],[14.5,0.88],[29,0.86]],"id":36993903},{"atb":[[2.9,63.24],[3,60.08],[3.25,26.7]],"id":37455733},{"atl":[[16,1.6],[34,1.45],[11,1.2],[22,1.14],[8.4,1.62]],"id":37455733},{"atb":[[2,120.16],[2.2,50.07],[2.1,109.24]],"id":22150928},{"atl":[[17.5,2.91],[9,3],[5.5,2.66],[12.5,2.08],[7,2]],"id":22150928}],"con":true,"img":false}]}
{"op":"mcm","clk":"5346204628","pt":1646082532158,"mc":[{"id":"1.195395456","rc":[{"atb":[[2,0],[2.2,0],[2.1,0]],"id":22150928},{"atl":[[17.5,0],[9,0],[5.5,0],[12.5,0],[7,0]],"id":22150928},{"atb":[[1.01,0],[1.02,0],[1.07,0]],"id":43154433},{"atl":[[2.88,0],[2.28,0],[2.68,0],[2.08,0],[2.48,0]],"id":43154433}],"con":true,"img":false}]}
{"op":"mcm","clk":"5346204839","pt":1646082534504,"mc":[{"id":"1.195395456","rc":[{"atb":[[2.4,85.83],[2.5,40.05],[2.3,92.43]],"id":22150928},{"atl":[[8,1.71],[10,2.66],[20,2.52],[6,2.4],[15,1.71]],"id":22150928},{"atb":[[1.01,24033.77],[1.05,1201.68]],"id":43154433},{"atl":[[2.24,9.68],[2.04,11.55],[2.44,16.68],[2.64,14.65],[2.84,26.12]],"id":43154433}],"con":true,"img":false}]}
{"op":"mcm","clk":"5346223656","pt":1646082746591,"mc":[{"id":"1.195395456","rc":[{"atb":[[2.3,0],[2.2,0],[2.1,0]],"id":37672294},{"atl":[[5.6,0],[7.2,0],[18,0],[9.2,0],[13,0]],"id":37672294},{"atb":[[1.4,0],[1.45,0],[1.5,0]],"id":28002629},{"atl":[[3.45,0],[3.95,0],[4.9,0],[2.98,0],[2.78,0]],"id":28002629},{"atb":[[1.2,0],[1.25,0],[1.3,0]],"id":42393370},{"atl":[[2.54,0],[3.85,0],[2.74,0],[3.35,0],[2.94,0]],"id":42393370},{"atb":[[2.82,0],[2.92,0],[3.05,0]],"id":37267533},{"atl":[[32,0],[10.5,0],[21,0],[8.2,0],[15.5,0]],"id":37267533},{"atb":[[3.55,0],[3.3,0],[3.05,0]],"id":36993903},{"atl":[[19.5,0],[48,0],[9.8,0],[14.5,0],[29,0]],"id":36993903},{"atb":[[2.9,0],[3,0],[3.25,0]],"id":37455733},{"atl":[[16,0],[34,0],[11,0],[22,0],[8.4,0]],"id":37455733},{"atb":[[2.4,0],[2.5,0],[2.3,0]],"id":22150928},{"atl":[[8,0],[10,0],[20,0],[6,0],[15,0]],"id":22150928},{"atb":[[1.01,0],[1.05,0]],"id":43154433},{"atl":[[2.24,0],[2.04,0],[2.44,0],[2.64,0],[2.84,0]],"id":43154433}],"con":true,"img":false}]}
{"op":"mcm","clk":"5346226108","pt":1646082775530,"mc":[{"id":"1.195395456","rc":[{"atb":[[2,120.16],[2.2,50.07],[2.1,109.24]],"id":37672294},{"atl":[[17.5,2.91],[9,3],[5.5,2.66],[12.5,2.08],[7,2]],"id":37672294},{"atb":[[1.25,480.67],[1.3,400.56],[1.35,171.66]],"id":28002629},{"atl":[[2.8,6.67],[4,16.02],[3,12.01],[2.6,7.51],[3.5,9.61]],"id":28002629},{"atb":[[1.2,600.84],[1.25,480.67],[1.3,200.28]],"id":42393370},{"atl":[[2.54,7.8],[3.85,16.86],[2.74,6.9],[3.35,10.22],[2.94,12.39]],"id":42393370},{"atb":[[2.88,63.92],[2.98,30.34],[2.78,67.51]],"id":37267533},{"atl":[[32,1.54],[10.5,1.26],[21,1.2],[8.2,1.66],[15.5,1.65]],"id":37267533},{"atb":[[3.45,24.52],[3.2,54.62],[2.98,60.69]],"id":36993903},{"atl":[[18.5,1.37],[44,1.12],[13.5,0.96],[27,0.92],[9.4,1.42]],"id":36993903},{"atb":[[2.88,63.92],[2.98,30.34],[2.78,67.51]],"id":37455733},{"atl":[[32,1.54],[10.5,1.26],[21,1.2],[8.2,1.66],[15.5,1.65]],"id":37455733},{"atb":[[2,120.16],[2.2,50.07],[2.1,109.24]],"id":22150928},{"atl":[[17.5,2.91],[9,3],[5.5,2.66],[12.5,2.08],[7,2]],"id":22150928},{"atb":[[1.01,24033.77],[1.05,1201.68]],"id":43154433},{"atl":[[2.24,9.68],[2.04,11.55],[2.44,16.68],[2.64,14.65],[2.84,26.12]],"id":43154433}],"con":true,"img":false}]}
{"op":"mcm","clk":"5346262710","pt":1646083101481,"mc":[{"id":"1.195395456","rc":[{"atb":[[2,0],[2.2,0],[2.1,0]],"id":37672294},{"atl":[[17.5,0],[9,0],[5.5,0],[12.5,0],[7,0]],"id":37672294}],"con":true,"img":false}]}
{"op":"mcm","clk":"5346262947","pt":1646083104399,"mc":[{"id":"1.195395456","rc":[{"atb":[[3.45,24.52],[3.2,54.62],[2.98,60.69]],"id":37672294},{"atl":[[18.5,1.37],[44,1.12],[13.5,0.96],[27,0.92],[9.4,1.42]],"id":37672294}],"con":true,"img":false}]}
{"op":"mcm","clk":"5346267327","pt":1646083161480,"mc":[{"id":"1.195395456","rc":[{"atb":[[3.45,0],[3.2,0],[2.98,0]],"id":37672294},{"atl":[[18.5,0],[44,0],[13.5,0],[27,0],[9.4,0]],"id":37672294},{"atb":[[1.25,0],[1.3,0],[1.35,0]],"id":28002629},{"atl":[[2.8,0],[4,0],[3,0],[2.6,0],[3.5,0]],"id":28002629},{"atb":[[1.2,0],[1.25,0],[1.3,0]],"id":42393370},{"atl":[[2.54,0],[3.85,0],[2.74,0],[3.35,0],[2.94,0]],"id":42393370},{"atb":[[2,0],[2.2,0],[2.1,0]],"id":22150928},{"atl":[[17.5,0],[9,0],[5.5,0],[12.5,0],[7,0]],"id":22150928},{"atb":[[1.01,0],[1.05,0]],"id":43154433},{"atl":[[2.24,0],[2.04,0],[2.44,0],[2.64,0],[2.84,0]],"id":43154433}],"con":true,"img":false}]}
{"op":"mcm","clk":"5346267674","pt":1646083166473,"mc":[{"id":"1.195395456","rc":[{"atb":[[2,120.16],[1.95,126.49],[2.1,54.62]],"id":37672294},{"atl":[[16.5,3.1],[8.6,3.16],[5.3,2.79],[11.5,2.28],[6.6,2.14]],"id":37672294},{"atb":[[1.4,150.21],[1.3,400.56],[1.35,343.34]],"id":28002629},{"atl":[[4.3,14.56],[2.86,6.46],[2.66,7.23],[3.15,11.17],[3.65,9.06]],"id":28002629},{"atb":[[1.2,600.84],[1.25,240.33],[1.15,801.12]],"id":42393370},{"atl":[[3.6,18.48],[3.1,11.44],[2.44,8.34],[2.64,7.32],[2.84,13.06]],"id":42393370},{"atb":[[2,60.08],[1.9,133.52],[1.95,126.49]],"id":22150928},{"atl":[[5.1,2.92],[6.2,2.31],[10.5,2.52],[8.2,3.33],[15.5,3.31]],"id":22150928},{"atb":[[1.01,12016.88],[1.02,6008.44],[1.07,858.34]],"id":43154433},{"atl":[[2.88,25.56],[2.28,9.38],[2.68,14.3],[2.08,11.12],[2.48,16.23]],"id":43154433}],"con":true,"img":false}]}
{"op":"mcm","clk":"5346272706","pt":1646083234955,"mc":[{"id":"1.195395456","marketDefinition":{"bspMarket":false,"turnInPlayEnabled":false,"persistenceEnabled":false,"marketBaseRate":5.0,"eventId":"31270459","eventTypeId":"4339","numberOfWinners":3,"bettingType":"ODDS","marketType":"PLACE","marketTime":"2022-03-01T02:04:00.000Z","suspendTime":"2022-03-01T02:04:00.000Z","bspReconciled":false,"complete":true,"inPlay":false,"crossMatching":false,"runnersVoidable":false,"numberOfActiveRunners":8,"betDelay":0,"status":"SUSPENDED","runners":[{"status":"ACTIVE","sortPriority":1,"id":37672294,"name":"1. Wizard Willie"},{"status":"ACTIVE","sortPriority":2,"id":28002629,"name":"2. St Andrews"},{"status":"ACTIVE","sortPriority":3,"id":43154433,"name":"3. Sapporo Bale"},{"status":"ACTIVE","sortPriority":4,"id":42393370,"name":"5. Goldstar Tookie"},{"status":"ACTIVE","sortPriority":5,"id":22150928,"name":"6. Smash Grenade"},{"status":"ACTIVE","sortPriority":6,"id":36993903,"name":"7. Baldrick"},{"status":"ACTIVE","sortPriority":7,"id":37267533,"name":"8. Diamond Empress"},{"status":"ACTIVE","sortPriority":8,"id":37455733,"name":"9. Just Stagger"}],"regulators":["MR_INT"],"venue":"Addington","countryCode":"NZ","discountAllowed":true,"timezone":"NZ","openDate":"2022-02-28T23:02:00.000Z","version":4380772704,"name":"To Be Placed","eventName":"Addington (NZL) 1st Mar"},"rc":[],"con":true,"img":false}]}
{"op":"mcm","clk":"5346274031","pt":1646083252299,"mc":[{"id":"1.195395456","rc":[{"atb":[[2.88,0],[2.98,0],[2.78,0]],"id":37455733},{"atl":[[32,0],[10.5,0],[21,0],[8.2,0],[15.5,0]],"id":37455733}],"con":true,"img":false}]}
{"op":"mcm","clk":"5346274089","pt":1646083252991,"mc":[{"id":"1.195395456","marketDefinition":{"bspMarket":false,"turnInPlayEnabled":false,"persistenceEnabled":false,"marketBaseRate":5.0,"eventId":"31270459","eventTypeId":"4339","numberOfWinners":3,"bettingType":"ODDS","marketType":"PLACE","marketTime":"2022-03-01T02:04:00.000Z","suspendTime":"2022-03-01T02:04:00.000Z","bspReconciled":false,"complete":true,"inPlay":false,"crossMatching":false,"runnersVoidable":false,"numberOfActiveRunners":7,"betDelay":0,"status":"SUSPENDED","runners":[{"status":"ACTIVE","sortPriority":1,"id":37672294,"name":"1. Wizard Willie"},{"status":"ACTIVE","sortPriority":2,"id":28002629,"name":"2. St Andrews"},{"status":"ACTIVE","sortPriority":3,"id":43154433,"name":"3. Sapporo Bale"},{"status":"ACTIVE","sortPriority":4,"id":42393370,"name":"5. Goldstar Tookie"},{"status":"ACTIVE","sortPriority":5,"id":22150928,"name":"6. Smash Grenade"},{"status":"ACTIVE","sortPriority":6,"id":37267533,"name":"8. Diamond Empress"},{"status":"ACTIVE","sortPriority":7,"id":37455733,"name":"9. Just Stagger"},{"status":"REMOVED","sortPriority":8,"removalDate":"2022-02-28T21:20:52.000Z","id":36993903,"name":"7. Baldrick"}],"regulators":["MR_INT"],"venue":"Addington","countryCode":"NZ","discountAllowed":true,"timezone":"NZ","openDate":"2022-02-28T23:02:00.000Z","version":4380773814,"name":"To Be Placed","eventName":"Addington (NZL) 1st Mar"},"rc":[],"con":true,"img":false}]}
{"op":"mcm","clk":"5346274089","pt":1646083252991,"mc":[{"id":"1.195395456","rc":[{"atb":[[2,0],[1.95,0],[2.1,0]],"id":37672294},{"atl":[[16.5,0],[8.6,0],[5.3,0],[11.5,0],[6.6,0]],"id":37672294},{"atb":[[1.4,0],[1.3,0],[1.35,0]],"id":28002629},{"atl":[[4.3,0],[2.86,0],[2.66,0],[3.15,0],[3.65,0]],"id":28002629},{"atb":[[1.2,0],[1.25,0],[1.15,0]],"id":42393370},{"atl":[[3.6,0],[3.1,0],[2.44,0],[2.64,0],[2.84,0]],"id":42393370},{"atb":[[2.88,0],[2.98,0],[2.78,0]],"id":37267533},{"atl":[[32,0],[10.5,0],[21,0],[8.2,0],[15.5,0]],"id":37267533},{"atb":[[3.45,0],[3.2,0],[2.98,0]],"id":36993903},{"atl":[[18.5,0],[44,0],[13.5,0],[27,0],[9.4,0]],"id":36993903},{"atb":[[2,0],[1.9,0],[1.95,0]],"id":22150928},{"atl":[[5.1,0],[6.2,0],[10.5,0],[8.2,0],[15.5,0]],"id":22150928},{"atb":[[1.01,0],[1.02,0],[1.07,0]],"id":43154433},{"atl":[[2.88,0],[2.28,0],[2.68,0],[2.08,0],[2.48,0]],"id":43154433}],"con":true,"img":false}]}
{"op":"mcm","clk":"5346274404","pt":1646083256995,"mc":[{"id":"1.195395456","marketDefinition":{"bspMarket":false,"turnInPlayEnabled":false,"persistenceEnabled":false,"marketBaseRate":5.0,"eventId":"31270459","eventTypeId":"4339","numberOfWinners":3,"bettingType":"ODDS","marketType":"PLACE","marketTime":"2022-03-01T02:04:00.000Z","suspendTime":"2022-03-01T02:04:00.000Z","bspReconciled":false,"complete":true,"inPlay":false,"crossMatching":false,"runnersVoidable":false,"numberOfActiveRunners":7,"betDelay":0,"status":"OPEN","runners":[{"status":"ACTIVE","sortPriority":1,"id":37672294,"name":"1. Wizard Willie"},{"status":"ACTIVE","sortPriority":2,"id":28002629,"name":"2. St Andrews"},{"status":"ACTIVE","sortPriority":3,"id":43154433,"name":"3. Sapporo Bale"},{"status":"ACTIVE","sortPriority":4,"id":42393370,"name":"5. Goldstar Tookie"},{"status":"ACTIVE","sortPriority":5,"id":22150928,"name":"6. Smash Grenade"},{"status":"ACTIVE","sortPriority":6,"id":37267533,"name":"8. Diamond Empress"},{"status":"ACTIVE","sortPriority":7,"id":37455733,"name":"9. Just Stagger"},{"status":"REMOVED","sortPriority":8,"removalDate":"2022-02-28T21:20:52.000Z","id":36993903,"name":"7. Baldrick"}],"regulators":["MR_INT"],"venue":"Addington","countryCode":"NZ","discountAllowed":true,"timezone":"NZ","openDate":"2022-02-28T23:02:00.000Z","version":4380773822,"name":"To Be Placed","eventName":"Addington (NZL) 1st Mar"},"rc":[],"con":true,"img":false}]}
{"op":"mcm","clk":"5346719186","pt":1646095072180,"mc":[{"id":"1.195395456","rc":[{"atb":[[1.67,61.08],[2.04,39]],"id":37672294},{"atl":[[8,5.79],[11.5,3.89]],"id":37672294},{"atb":[[1.25,147.11],[1.39,40.56]],"id":28002629},{"atl":[[5.1,8.97],[3.65,15.3]],"id":28002629},{"atb":[[1.2,215.8],[1.3,40.56]],"id":42393370},{"atl":[[4.3,12.98],[3.15,18.86]],"id":42393370},{"atb":[[2.82,22.28],[2.16,35.35]],"id":37267533},{"atl":[[20,2.7],[14,3.12]],"id":37267533},{"atb":[[3,20.28],[2.28,28.73]],"id":37455733},{"atl":[[22,2.7],[15,2.89]],"id":37455733},{"atb":[[1.62,60.33],[1.95,40.56]],"id":22150928},{"atl":[[10.5,3.93],[7.4,6.33]],"id":22150928},{"atb":[[1.08,40.56],[1.05,708.52]],"id":43154433},{"atl":[[2.4,25.3],[1.87,40.56]],"id":43154433}],"con":true,"img":false}]}
{"op":"mcm","clk":"5346774464","pt":1646096643076,"mc":[{"id":"1.195395456","rc":[{"atb":[[2.06,50.04]],"id":37672294},{"atl":[[7.8,4.84]],"id":37672294},{"atb":[[1.21,187.67]],"id":28002629},{"atl":[[3.3,12.14]],"id":28002629},{"atb":[[1.27,215.8]],"id":42393370},{"atl":[[3.1,15.92]],"id":42393370},{"atb":[[1.35,57.65]],"id":37267533},{"atl":[[13.5,2.91]],"id":37267533},{"atb":[[2.52,40.56]],"id":37455733},{"atl":[[55,2]],"id":37455733},{"atb":[[1.44,100.9]],"id":22150928},{"atl":[[7.2,5.14]],"id":22150928},{"atb":[[1.08,415.1]],"id":43154433},{"atl":[[1.84,32.94]],"id":43154433}],"con":true,"img":false}]}
{"op":"mcm","clk":"5346775914","pt":1646096682439,"mc":[{"id":"1.195395456","rc":[{"atl":[[7.6,6.19]],"id":37672294},{"atb":[[1.28,154.14]],"id":42393370},{"atl":[[3.05,21.09]],"id":42393370},{"atb":[[2.54,23.88]],"id":37455733}],"con":true,"img":false}]}
{"op":"mcm","clk":"5346775918","pt":1646096682542,"mc":[{"id":"1.195395456","rc":[{"atb":[[2.04,0]],"id":37672294},{"atl":[[8,0],[11.5,0],[7.4,5.79],[7.8,0]],"id":37672294},{"atl":[[3.65,0]],"id":28002629},{"atb":[[1.2,0]],"id":42393370},{"atl":[[4.3,0],[3.1,0],[3,18.87],[3.15,0]],"id":42393370},{"atl":[[14,0]],"id":37267533},{"atb":[[2.28,0]],"id":37455733},{"atl":[[15,0]],"id":37455733},{"atl":[[7.4,0]],"id":22150928},{"atb":[[1.08,374.54]],"id":43154433},{"atl":[[1.87,0]],"id":43154433}],"con":true,"img":false}]}
{"op":"mcm","clk":"5346775921","pt":1646096682644,"mc":[{"id":"1.195395456","rc":[{"atb":[[2.06,0],[1.85,100.08],[2.08,39]],"id":37672294},{"atl":[[6.8,5.79]],"id":37672294},{"atl":[[3.15,15.3]],"id":28002629},{"atl":[[2.74,18.86]],"id":42393370},{"atl":[[20,7.96],[11.5,3.12],[13.5,0]],"id":37267533},{"atl":[[13,2.89]],"id":37455733},{"atl":[[7.2,0],[6.4,6.33],[10,10.28]],"id":22150928},{"atb":[[1.06,749.08],[1.09,40.56],[1.08,0]],"id":43154433},{"atl":[[1.71,40.56]],"id":43154433}],"con":true,"img":false}]}
{"op":"mcm","clk":"5346775925","pt":1646096682749,"mc":[{"id":"1.195395456","rc":[{"atl":[[3.1,12.14],[3.3,0]],"id":28002629},{"atl":[[1.84,0],[1.7,32.94]],"id":43154433}],"con":true,"img":false}]}
{"op":"mcm","clk":"5346776517","pt":1646096698893,"mc":[{"id":"1.195395456","rc":[{"atb":[[2.08,0]],"id":37672294},{"atl":[[3.15,0]],"id":28002629},{"atl":[[2.74,0],[4.4,12.43],[3.05,0]],"id":42393370},{"atb":[[2.82,0],[1.83,49.41],[2.16,0]],"id":37267533},{"atb":[[2.54,0],[1.89,41.32],[3,0]],"id":37455733},{"atb":[[1.95,0]],"id":22150928},{"atl":[[2.4,0],[3,17.71],[1.71,0]],"id":43154433}],"con":true,"img":false}]}
{"op":"mcm","clk":"5346776520","pt":1646096698997,"mc":[{"id":"1.195395456","rc":[{"atb":[[1.97,39]],"id":37672294},{"atl":[[3.25,15.3]],"id":28002629},{"atl":[[3.05,18.86]],"id":42393370},{"atb":[[2.3,22.28]],"id":37267533},{"atb":[[2.54,20.28]],"id":37455733},{"atb":[[1.87,40.56]],"id":22150928},{"atl":[[2.16,40.56]],"id":43154433}],"con":true,"img":false}]}
{"op":"mcm","clk":"5346776523","pt":1646096699100,"mc":[{"id":"1.195395456","rc":[{"atl":[[3.1,0],[3.3,24.28]],"id":28002629},{"atl":[[3,0],[3.3,37.74]],"id":42393370},{"atb":[[2.52,0],[1.9,81.12]],"id":37455733},{"atl":[[1.84,65.88],[1.7,0]],"id":43154433}],"con":true,"img":false}]}
{"op":"mcm","clk":"5346777319","pt":1646096719319,"mc":[{"id":"1.195395456","rc":[{"atl":[[7.4,0],[6.8,11.58]],"id":37672294}],"con":true,"img":false}]}
{"op":"mcm","clk":"5346777322","pt":1646096719426,"mc":[{"id":"1.195395456","rc":[{"atb":[[1.98,61.08],[1.85,0]],"id":37672294},{"atl":[[20,2.7],[12,7.96]],"id":37267533},{"atl":[[10,0],[6.2,6.34]],"id":22150928},{"atb":[[1.06,0],[1.08,728.8]],"id":43154433}],"con":true,"img":false}]}
{"op":"mcm","clk":"5346777482","pt":1646096723537,"mc":[{"id":"1.195395456","rc":[{"atl":[[7.6,0]],"id":37672294},{"atl":[[11.5,0]],"id":37267533},{"atl":[[13,0]],"id":37455733},{"atl":[[10.5,0]],"id":22150928}],"con":true,"img":false}]}
{"op":"mcm","clk":"5346777485","pt":1646096723638,"mc":[{"id":"1.195395456","rc":[{"atl":[[9.2,4.99],[6.8,5.79]],"id":37672294},{"atl":[[8,5.79]],"id":37267533},{"atl":[[8.6,5.33]],"id":37455733},{"atb":[[1.62,83.13]],"id":22150928},{"atl":[[6.4,0],[8.4,5.05]],"id":22150928}],"con":true,"img":false}]}
{"op":"mcm","clk":"5346777487","pt":1646096723742,"mc":[{"id":"1.195395456","rc":[{"atl":[[6.2,5.79]],"id":37672294},{"atl":[[5.7,6.33]],"id":22150928}],"con":true,"img":false}]}
{"op":"mcm","clk":"5346777947","pt":1646096735669,"mc":[{"id":"1.195395456","rc":[{"atl":[[3.2,15.31],[3.3,0]],"id":28002629},{"atl":[[3,18.87],[3.3,0]],"id":42393370},{"atb":[[2.52,61.22],[1.9,0]],"id":37455733}],"con":true,"img":false}]}
{"op":"mcm","clk":"5346778334","pt":1646096748162,"mc":[{"id":"1.195395456","rc":[{"atl":[[20,0],[11.5,3.9]],"id":37267533},{"atl":[[22,0]],"id":37455733}],"con":true,"img":false}]}
{"op":"mcm","clk":"5346778338","pt":1646096748263,"mc":[{"id":"1.195395456","rc":[{"atl":[[13,2.7]],"id":37455733}],"con":true,"img":false}]}
{"op":"mcm","clk":"5346778571","pt":1646096755751,"mc":[{"id":"1.195395456","rc":[{"atl":[[5.6,6.34]],"id":22150928}],"con":true,"img":false}]}
{"op":"mcm","clk":"5346778576","pt":1646096755855,"mc":[{"id":"1.195395456","rc":[{"atl":[[6.2,0]],"id":22150928}],"con":true,"img":false}]}
{"op":"mcm","clk":"5346779064","pt":1646096772896,"mc":[{"id":"1.195395456","rc":[{"atb":[[1.97,0]],"id":37672294}],"con":true,"img":false}]}
{"op":"mcm","clk":"5346779069","pt":1646096773000,"mc":[{"id":"1.195395456","rc":[{"atb":[[1.99,39],[1.98,0],[1.85,117.65]],"id":37672294}],"con":true,"img":false}]}
{"op":"mcm","clk":"5346779702","pt":1646096797120,"mc":[{"id":"1.195395456","rc":[{"atl":[[3.25,0]],"id":28002629},{"atl":[[3.05,0]],"id":42393370}],"con":true,"img":false}]}
{"op":"mcm","clk":"5346779705","pt":1646096797222,"mc":[{"id":"1.195395456","rc":[{"atl":[[3.2,0],[3.15,15.3],[3.3,30.62]],"id":28002629},{"atl":[[3,0],[2.98,18.86],[3.3,37.74]],"id":42393370}],"con":true,"img":false}]}
{"op":"mcm","clk":"5346779973","pt":1646096808868,"mc":[{"id":"1.195395456","rc":[{"atb":[[2,61.08],[1.85,0]],"id":37672294}],"con":true,"img":false}]}
{"op":"mcm","clk":"5346780094","pt":1646096814762,"mc":[{"id":"1.195395456","rc":[{"atl":[[6.8,0],[7,11.58]],"id":37672294},{"atl":[[1.84,0],[1.86,116.28]],"id":43154433}],"con":true,"img":false}]}
{"op":"mcm","clk":"5346780255","pt":1646096821079,"mc":[{"id":"1.195395456","rc":[{"atl":[[3.15,0]],"id":28002629},{"atl":[[2.98,0]],"id":42393370},{"atl":[[5.4,9.22]],"id":22150928}],"con":true,"img":false}]}
{"op":"mcm","clk":"5346780261","pt":1646096821182,"mc":[{"id":"1.195395456","rc":[{"atl":[[3.25,15.3]],"id":28002629},{"atl":[[3.2,18.86]],"id":42393370},{"atl":[[5.3,6.34],[5.7,0]],"id":22150928}],"con":true,"img":false}]}
{"op":"mcm","clk":"5346780267","pt":1646096821283,"mc":[{"id":"1.195395456","rc":[{"atl":[[5.6,0]],"id":22150928}],"con":true,"img":false}]}
{"op":"mcm","clk":"5346780658","pt":1646096832831,"mc":[{"id":"1.195395456","rc":[{"atl":[[3.2,15.31]],"id":28002629},{"atl":[[3.15,18.87],[3.3,0]],"id":42393370}],"con":true,"img":false}]}
{"op":"mcm","clk":"5346780663","pt":1646096832936,"mc":[{"id":"1.195395456","rc":[{"atl":[[3.3,0]],"id":28002629}],"con":true,"img":false}]}
{"op":"mcm","clk":"5346781063","pt":1646096845019,"mc":[{"id":"1.195395456","rc":[{"atl":[[3.25,0]],"id":28002629}],"con":true,"img":false}]}
{"op":"mcm","clk":"5346781068","pt":1646096845123,"mc":[{"id":"1.195395456","rc":[{"atl":[[3.45,15.3],[3.2,0],[3.3,30.62]],"id":28002629}],"con":true,"img":false}]}
{"op":"mcm","clk":"5346781823","pt":1646096868691,"mc":[{"id":"1.195395456","rc":[{"atb":[[1.99,0]],"id":37672294},{"atl":[[6.8,7.05],[5.7,8.63]],"id":37672294}],"con":true,"img":false}]}
{"op":"mcm","clk":"5346781827","pt":1646096868792,"mc":[{"id":"1.195395456","rc":[{"atb":[[2,0],[2.02,39],[1.87,114.94]],"id":37672294},{"atl":[[9.2,0],[6.2,0]],"id":37672294}],"con":true,"img":false}]}
{"op":"mcm","clk":"5346782705","pt":1646096892196,"mc":[{"id":"1.195395456","rc":[{"atb":[[2.02,0]],"id":37672294},{"atl":[[3.2,0]],"id":42393370}],"con":true,"img":false}]}
{"op":"mcm","clk":"5346782711","pt":1646096892304,"mc":[{"id":"1.195395456","rc":[{"atb":[[1.91,39]],"id":37672294},{"atl":[[3.1,18.86],[3.15,0],[3.3,37.74]],"id":42393370}],"con":true,"img":false}]}
{"op":"mcm","clk":"5346783099","pt":1646096903632,"mc":[{"id":"1.195395456","rc":[{"atb":[[1.92,61.08],[1.87,0]],"id":37672294}],"con":true,"img":false}]}
{"op":"mcm","clk":"5346783456","pt":1646096914846,"mc":[{"id":"1.195395456","rc":[{"atl":[[3.45,0]],"id":28002629}],"con":true,"img":false}]}
{"op":"mcm","clk":"5346783461","pt":1646096914955,"mc":[{"id":"1.195395456","rc":[{"atl":[[3.25,15.3]],"id":28002629}],"con":true,"img":false}]}
{"op":"mcm","clk":"5346783466","pt":1646096915055,"mc":[{"id":"1.195395456","rc":[{"atl":[[3.2,15.31]],"id":28002629}],"con":true,"img":false}]}
{"op":"mcm","clk":"5346783469","pt":1646096915157,"mc":[{"id":"1.195395456","rc":[{"atl":[[3.3,0]],"id":28002629}],"con":true,"img":false}]}
{"op":"mcm","clk":"5346783913","pt":1646096926984,"mc":[{"id":"1.195395456","rc":[{"atl":[[3.3,0],[3.05,18.87]],"id":42393370}],"con":true,"img":false}]}
{"op":"mcm","clk":"5346785234","pt":1646096960750,"mc":[{"id":"1.195395456","rc":[{"atb":[[1.91,0]],"id":37672294}],"con":true,"img":false}]}
{"op":"mcm","clk":"5346785240","pt":1646096960856,"mc":[{"id":"1.195395456","rc":[{"atb":[[1.93,39]],"id":37672294}],"con":true,"img":false}]}
{"op":"mcm","clk":"5346785245","pt":1646096960957,"mc":[{"id":"1.195395456","rc":[{"atb":[[1.92,0],[1.87,114.94]],"id":37672294}],"con":true,"img":false}]}
{"op":"mcm","clk":"5346786261","pt":1646096983766,"mc":[{"id":"1.195395456","rc":[{"atl":[[3.25,0]],"id":28002629},{"atl":[[3.1,0]],"id":42393370}],"con":true,"img":false}]}
{"op":"mcm","clk":"5346786264","pt":1646096983866,"mc":[{"id":"1.195395456","rc":[{"atl":[[3.15,15.3],[3.3,30.62]],"id":28002629},{"atl":[[3,18.86],[3.3,37.74],[3.05,0]],"id":42393370}],"con":true,"img":false}]}
{"op":"mcm","clk":"5346786269","pt":1646096983972,"mc":[{"id":"1.195395456","rc":[{"atl":[[3.2,0]],"id":28002629}],"con":true,"img":false}]}
{"op":"mcm","clk":"5346786653","pt":1646096994883,"mc":[{"id":"1.195395456","rc":[{"atb":[[1.94,61.08]],"id":37672294}],"con":true,"img":false}]}
{"op":"mcm","clk":"5346786658","pt":1646096994987,"mc":[{"id":"1.195395456","rc":[{"atb":[[1.87,0]],"id":37672294}],"con":true,"img":false}]}
{"op":"mcm","clk":"5346787024","pt":1646097005796,"mc":[{"id":"1.195395456","rc":[{"atl":[[3.15,0]],"id":28002629},{"atl":[[3,0]],"id":42393370}],"con":true,"img":false}]}
{"op":"mcm","clk":"5346787028","pt":1646097005898,"mc":[{"id":"1.195395456","rc":[{"atl":[[3.25,15.3]],"id":28002629},{"atl":[[3.2,18.86]],"id":42393370}],"con":true,"img":false}]}
{"op":"mcm","clk":"5346787400","pt":1646097017539,"mc":[{"id":"1.195395456","rc":[{"atl":[[3.2,15.31]],"id":28002629},{"atl":[[3.15,18.87],[3.3,0]],"id":42393370}],"con":true,"img":false}]}
{"op":"mcm","clk":"5346787404","pt":1646097017592,"mc":[{"id":"1.195395456","rc":[{"atl":[[3.3,0]],"id":28002629}],"con":true,"img":false}]}
{"op":"mcm","clk":"5346787932","pt":1646097032466,"mc":[{"id":"1.195395456","rc":[{"atb":[[1.27,0],[1.25,308.3]],"id":42393370},{"atl":[[5.3,0],[5.4,21.9]],"id":22150928},{"atl":[[1.89,112.36],[1.86,0]],"id":43154433}],"con":true,"img":false}]}
{"op":"mcm","clk":"5346787935","pt":1646097032571,"mc":[{"id":"1.195395456","rc":[{"atl":[[8.2,13.89],[5.4,9.22]],"id":22150928}],"con":true,"img":false}]}
{"op":"mcm","clk":"5346788601","pt":1646097050557,"mc":[{"id":"1.195395456","rc":[{"atb":[[1.93,0]],"id":37672294},{"atb":[[1.28,0]],"id":42393370}],"con":true,"img":false}]}
{"op":"mcm","clk":"5346788603","pt":1646097050660,"mc":[{"id":"1.195395456","rc":[{"atb":[[1.88,113.64],[1.94,0],[1.95,39]],"id":37672294},{"atb":[[1.26,154.14]],"id":42393370}],"con":true,"img":false}]}
{"op":"mcm","clk":"5346789108","pt":1646097065708,"mc":[{"id":"1.195395456","rc":[{"atb":[[1.25,0],[1.26,385.37]],"id":42393370},{"atl":[[1.89,0],[1.86,40.56]],"id":43154433}],"con":true,"img":false}]}
{"op":"mcm","clk":"5346789111","pt":1646097065814,"mc":[{"id":"1.195395456","rc":[{"atl":[[5.3,9.22]],"id":22150928}],"con":true,"img":false}]}
{"op":"mcm","clk":"5346789114","pt":1646097065913,"mc":[{"id":"1.195395456","rc":[{"atl":[[8.2,0]],"id":22150928}],"con":true,"img":false}]}
{"op":"mcm","clk":"5346789368","pt":1646097072392,"mc":[{"id":"1.195395456","rc":[{"atl":[[3.25,0]],"id":28002629},{"atl":[[3.2,0]],"id":42393370},{"atl":[[1.86,0],[1.87,81.12]],"id":43154433}],"con":true,"img":false}]}
{"op":"mcm","clk":"5346789371","pt":1646097072495,"mc":[{"id":"1.195395456","rc":[{"atl":[[3.2,0],[3.15,15.3],[3.3,30.62]],"id":28002629},{"atl":[[3.1,18.86],[3.15,0],[3.3,37.74]],"id":42393370}],"con":true,"img":false}]}
{"op":"mcm","clk":"5346789745","pt":1646097083747,"mc":[{"id":"1.195395456","rc":[{"atb":[[1.88,0],[1.96,61.08]],"id":37672294}],"con":true,"img":false}]}
{"op":"mcm","clk":"5346790141","pt":1646097094135,"mc":[{"id":"1.195395456","rc":[{"atl":[[3.15,0]],"id":28002629}],"con":true,"img":false}]}
{"op":"mcm","clk":"5346790144","pt":1646097094239,"mc":[{"id":"1.195395456","rc":[{"atl":[[3.25,15.3]],"id":28002629}],"con":true,"img":false}]}
{"op":"mcm","clk":"5346790593","pt":1646097105344,"mc":[{"id":"1.195395456","rc":[{"atl":[[3.2,15.31],[3.3,0]],"id":28002629},{"atl":[[3.3,0],[3.05,18.87]],"id":42393370}],"con":true,"img":false}]}
{"op":"mcm","clk":"5346790971","pt":1646097115473,"mc":[{"id":"1.195395456","rc":[{"atb":[[1.26,231.23]],"id":42393370}],"con":true,"img":false}]}
{"op":"mcm","clk":"5346790978","pt":1646097115576,"mc":[{"id":"1.195395456","rc":[{"atb":[[1.27,154.14]],"id":42393370}],"con":true,"img":false}]}
{"op":"mcm","clk":"5346791850","pt":1646097136611,"mc":[{"id":"1.195395456","rc":[{"atb":[[1.95,0]],"id":37672294},{"atl":[[5.7,0]],"id":37672294},{"atl":[[8,0]],"id":37267533},{"atl":[[8.6,0],[13,0],[15,2.89]],"id":37455733}],"con":true,"img":false}]}
{"op":"mcm","clk":"5346791856","pt":1646097136713,"mc":[{"id":"1.195395456","rc":[{"atb":[[1.98,39],[1.88,113.64],[1.96,0]],"id":37672294},{"atl":[[7.2,16.13],[6.2,8.63],[7,0]],"id":37672294},{"atl":[[9.6,5.79]],"id":37267533},{"atl":[[22,2.7]],"id":37455733}],"con":true,"img":false}]}
{"op":"mcm","clk":"5346791861","pt":1646097136816,"mc":[{"id":"1.195395456","rc":[{"atb":[[1.99,61.08],[1.88,0]],"id":37672294}],"con":true,"img":false}]}
{"op":"mcm","clk":"5346792612","pt":1646097157374,"mc":[{"id":"1.195395456","rc":[{"atl":[[1.86,40.56],[1.87,0]],"id":43154433}],"con":true,"img":false}]}
{"op":"mcm","clk":"5346792617","pt":1646097157424,"mc":[{"id":"1.195395456","rc":[{"atl":[[1.87,40.56]],"id":43154433}],"con":true,"img":false}]}
{"op":"mcm","clk":"5346792620","pt":1646097157529,"mc":[{"id":"1.195395456","rc":[{"atl":[[1.86,0]],"id":43154433}],"con":true,"img":false}]}
{"op":"mcm","clk":"5346792646","pt":1646097158250,"mc":[{"id":"1.195395456","rc":[{"atl":[[6.8,0]],"id":37672294},{"atl":[[3.25,0]],"id":28002629},{"atl":[[3.1,0]],"id":42393370}],"con":true,"img":false}]}
{"op":"mcm","clk":"5346792650","pt":1646097158352,"mc":[{"id":"1.195395456","rc":[{"atl":[[7,7.05]],"id":37672294},{"atl":[[3.2,0],[3.15,15.3],[3.3,30.62]],"id":28002629},{"atl":[[3,18.86],[3.3,37.74],[3.05,0]],"id":42393370}],"con":true,"img":false}]}
{"op":"mcm","clk":"5346792656","pt":1646097158455,"mc":[{"id":"1.195395456","rc":[{"atl":[[3.1,15.31]],"id":28002629},{"atl":[[2.98,18.87]],"id":42393370}],"con":true,"img":false}]}
{"op":"mcm","clk":"5346792660","pt":1646097158557,"mc":[{"id":"1.195395456","rc":[{"atl":[[3.3,0]],"id":28002629},{"atl":[[3.3,0]],"id":42393370}],"con":true,"img":false}]}
{"op":"mcm","clk":"5346793532","pt":1646097179166,"mc":[{"id":"1.195395456","rc":[{"atl":[[8.6,5.33],[15,0]],"id":37455733}],"con":true,"img":false}]}
{"op":"mcm","clk":"5346793538","pt":1646097179272,"mc":[{"id":"1.195395456","rc":[{"atl":[[6.2,0]],"id":37672294},{"atl":[[9.6,0]],"id":37267533}],"con":true,"img":false}]}
{"op":"mcm","clk":"5346793541","pt":1646097179378,"mc":[{"id":"1.195395456","rc":[{"atl":[[5.7,8.63]],"id":37672294},{"atl":[[7.8,5.79]],"id":37267533}],"con":true,"img":false}]}
{"op":"mcm","clk":"5346794434","pt":1646097200138,"mc":[{"id":"1.195395456","rc":[{"atb":[[1.98,0]],"id":37672294},{"atl":[[5.7,0]],"id":37672294},{"atl":[[7.8,0]],"id":37267533},{"atl":[[15,2.89]],"id":37455733}],"con":true,"img":false}]}
{"op":"mcm","clk":"5346794441","pt":1646097200239,"mc":[{"id":"1.195395456","rc":[{"atb":[[2,39]],"id":37672294},{"atl":[[6.2,8.63]],"id":37672294},{"atl":[[9.6,5.79]],"id":37267533},{"atl":[[8.6,0]],"id":37455733}],"con":true,"img":false}]}
{"op":"mcm","clk":"5346794447","pt":1646097200292,"mc":[{"id":"1.195395456","rc":[{"atb":[[1.99,0],[1.88,113.64]],"id":37672294}],"con":true,"img":false}]}
{"op":"mcm","clk":"5346795265","pt":1646097220871,"mc":[{"id":"1.195395456","rc":[{"atl":[[3.15,0]],"id":28002629},{"atl":[[3,0]],"id":42393370},{"atb":[[2.3,0]],"id":37267533},{"atb":[[2.54,0]],"id":37455733},{"atl":[[2.16,0]],"id":43154433}],"con":true,"img":false}]}
{"op":"mcm","clk":"5346795272","pt":1646097220973,"mc":[{"id":"1.195395456","rc":[{"atl":[[3.05,15.3]],"id":28002629},{"atl":[[2.82,18.86]],"id":42393370},{"atb":[[2.62,22.28]],"id":37267533},{"atb":[[3,20.28]],"id":37455733},{"atl":[[1.82,40.56]],"id":43154433}],"con":true,"img":false}]}
{"op":"mcm","clk":"5346795279","pt":1646097221078,"mc":[{"id":"1.195395456","rc":[{"atl":[[3.1,0],[3.3,30.62]],"id":28002629},{"atl":[[2.98,0],[3.3,37.74]],"id":42393370},{"atb":[[2.52,0],[1.9,111.11]],"id":37455733},{"atl":[[1.81,40.56],[1.87,0]],"id":43154433}],"con":true,"img":false}]}
{"op":"mcm","clk":"5346795302","pt":1646097221545,"mc":[{"id":"1.195395456","rc":[{"atb":[[1.26,0],[1.24,308.3]],"id":42393370},{"atb":[[1.17,98.84],[1.35,0]],"id":37267533},{"atb":[[1.62,175.15]],"id":22150928}],"con":true,"img":false}]}
{"op":"mcm","clk":"5346795307","pt":1646097221647,"mc":[{"id":"1.195395456","rc":[{"atb":[[1.44,0]],"id":22150928}],"con":true,"img":false}]}
{"op":"mcm","clk":"5346795715","pt":1646097231881,"mc":[{"id":"1.195395456","rc":[{"atb":[[2.02,61.08],[1.88,0]],"id":37672294}],"con":true,"img":false}]}
{"op":"mcm","clk":"5346796089","pt":1646097241202,"mc":[{"id":"1.195395456","rc":[{"atb":[[2,0]],"id":37672294},{"atl":[[3.05,0]],"id":28002629},{"atb":[[1.27,0]],"id":42393370},{"atl":[[2.82,0],[3.25,18.93]],"id":42393370},{"atb":[[2.62,0]],"id":37267533},{"atb":[[1.89,0],[3,0]],"id":37455733},{"atl":[[1.82,0]],"id":43154433}],"con":true,"img":false}]}
{"op":"mcm","clk":"5346796093","pt":1646097241305,"mc":[{"id":"1.195395456","rc":[{"atb":[[1.88,113.64],[1.91,39]],"id":37672294},{"atl":[[3.25,15.3]],"id":28002629},{"atb":[[1.25,154.14]],"id":42393370},{"atl":[[3.2,18.86],[4.4,0]],"id":42393370},{"atb":[[2.3,22.28]],"id":37267533},{"atb":[[2.46,20.28],[1.93,41.32]],"id":37455733},{"atb":[[1.62,152.35]],"id":22150928},{"atl":[[2.16,40.56]],"id":43154433}],"con":true,"img":false}]}
{"op":"mcm","clk":"5346796097","pt":1646097241406,"mc":[{"id":"1.195395456","rc":[{"atb":[[2.02,0]],"id":37672294},{"atl":[[1.81,0],[1.87,81.12]],"id":43154433}],"con":true,"img":false}]}
{"op":"mcm","clk":"5346796519","pt":1646097252409,"mc":[{"id":"1.195395456","rc":[{"atl":[[3.2,15.31],[3.3,0]],"id":28002629},{"atl":[[3.15,18.93],[3.3,0]],"id":42393370},{"atb":[[1.9,0],[2.48,41.32]],"id":37455733}],"con":true,"img":false}]}
{"op":"mcm","clk":"5346797407","pt":1646097272428,"mc":[{"id":"1.195395456","rc":[{"atb":[[1.92,61.08],[1.88,0]],"id":37672294}],"con":true,"img":false}]}
{"op":"mcm","clk":"5346797584","pt":1646097277473,"mc":[{"id":"1.195395456","rc":[{"atl":[[5.3,0],[5.4,27.66]],"id":22150928},{"atl":[[1.9,111.11],[1.87,0]],"id":43154433}],"con":true,"img":false}]}
{"op":"mcm","clk":"5346797588","pt":1646097277525,"mc":[{"id":"1.195395456","rc":[{"atl":[[8.2,13.89],[5.4,9.22]],"id":22150928}],"con":true,"img":false}]}
{"op":"mcm","clk":"5346797773","pt":1646097282252,"mc":[{"id":"1.195395456","rc":[{"atb":[[1.91,0]],"id":37672294},{"atl":[[3.25,0]],"id":28002629},{"atl":[[3.2,0]],"id":42393370},{"atb":[[2.3,0]],"id":37267533},{"atb":[[2.46,0]],"id":37455733},{"atl":[[2.16,0]],"id":43154433}],"con":true,"img":false}]}
{"op":"mcm","clk":"5346797779","pt":1646097282353,"mc":[{"id":"1.195395456","rc":[{"atb":[[1.82,121.95],[1.92,0],[1.97,39]],"id":37672294},{"atl":[[3.2,0],[3.15,15.3],[3.3,30.62]],"id":28002629},{"atl":[[3.2,37.86],[2.86,18.86],[3.15,0]],"id":42393370},{"atb":[[2.58,22.28]],"id":37267533},{"atb":[[3,20.28],[2.48,0]],"id":37455733},{"atl":[[1.83,40.56]],"id":43154433}],"con":true,"img":false}]}
{"op":"mcm","clk":"5346797785","pt":1646097282456,"mc":[{"id":"1.195395456","rc":[{"atb":[[1.99,82.64]],"id":37455733}],"con":true,"img":false}]}
{"op":"mcm","clk":"5346797791","pt":1646097282558,"mc":[{"id":"1.195395456","rc":[{"atl":[[1.82,40.56],[1.9,0]],"id":43154433}],"con":true,"img":false}]}
{"op":"mcm","clk":"5346797822","pt":1646097283431,"mc":[{"id":"1.195395456","rc":[{"atl":[[3.1,15.31]],"id":28002629},{"atl":[[2.84,18.93]],"id":42393370}],"con":true,"img":false}]}
{"op":"mcm","clk":"5346797826","pt":1646097283533,"mc":[{"id":"1.195395456","rc":[{"atl":[[3.3,0]],"id":28002629},{"atl":[[3.2,0]],"id":42393370}],"con":true,"img":false}]}
{"op":"mcm","clk":"5346798439","pt":1646097302286,"mc":[{"id":"1.195395456","rc":[{"atb":[[1.83,49.3],[1.67,0]],"id":37672294},{"atl":[[2.82,23.79],[3.25,0]],"id":42393370},{"atb":[[2.28,28.73],[1.93,0]],"id":37455733},{"atl":[[2.36,26.04],[3,0]],"id":43154433}],"con":true,"img":false}]}
{"op":"mcm","clk":"5346798492","pt":1646097303211,"mc":[{"id":"1.195395456","rc":[{"atb":[[1.82,0],[1.98,49.3]],"id":37672294}],"con":true,"img":false}]}
{"op":"mcm","clk":"5346798904","pt":1646097313114,"mc":[{"id":"1.195395456","rc":[{"atb":[[2.78,55.68]],"id":37455733}],"con":true,"img":false}]}
{"op":"mcm","clk":"5346798910","pt":1646097313214,"mc":[{"id":"1.195395456","rc":[{"atb":[[1.99,0]],"id":37455733}],"con":true,"img":false}]}
{"op":"mcm","clk":"5346798946","pt":1646097314187,"mc":[{"id":"1.195395456","rc":[{"atl":[[2.8,18.93],[2.84,0]],"id":42393370}],"con":true,"img":false}]}
{"op":"mcm","clk":"5346799250","pt":1646097322338,"mc":[{"id":"1.195395456","rc":[{"atl":[[8.4,0]],"id":22150928}],"con":true,"img":false}]}
{"op":"mcm","clk":"5346799252","pt":1646097322391,"mc":[{"id":"1.195395456","rc":[{"atl":[[8,5.05]],"id":22150928}],"con":true,"img":false}]}
{"op":"mcm","clk":"5346799256","pt":1646097322545,"mc":[{"id":"1.195395456","rc":[{"atl":[[8.2,0],[5.4,20.78]],"id":22150928}],"con":true,"img":false}]}
{"op":"mcm","clk":"5346800068","pt":1646097342348,"mc":[{"id":"1.195395456","rc":[{"atl":[[3.15,0]],"id":28002629},{"atl":[[2.86,0]],"id":42393370},{"atl":[[1.83,0]],"id":43154433}],"con":true,"img":false}]}
{"op":"mcm","clk":"5346800072","pt":1646097342450,"mc":[{"id":"1.195395456","rc":[{"atl":[[3.1,0],[3.3,30.62],[3.05,15.3]],"id":28002629},{"atl":[[2.76,18.86]],"id":42393370},{"atl":[[1.82,0],[1.8,40.56],[1.9,81.12]],"id":43154433}],"con":true,"img":false}]}
{"op":"mcm","clk":"5346800077","pt":1646097342659,"mc":[{"id":"1.195395456","rc":[{"atl":[[2.8,0],[2.74,18.93]],"id":42393370}],"con":true,"img":false}]}
{"op":"mcm","clk":"5346800792","pt":1646097361871,"mc":[{"id":"1.195395456","rc":[{"atb":[[1.83,0],[1.97,0]],"id":37672294},{"atl":[[3.8,15.68]],"id":42393370},{"atl":[[1.89,39.8]],"id":43154433}],"con":true,"img":false}]}
{"op":"mcm","clk":"5346800796","pt":1646097361973,"mc":[{"id":"1.195395456","rc":[{"atb":[[1.99,88.31]],"id":37672294},{"atl":[[2.82,0]],"id":42393370},{"atl":[[2.36,0]],"id":43154433}],"con":true,"img":false}]}
{"op":"mcm","clk":"5346800802","pt":1646097362075,"mc":[{"id":"1.195395456","rc":[{"atb":[[2,68.81],[1.98,0]],"id":37672294}],"con":true,"img":false}]}
{"op":"mcm","clk":"5346801182","pt":1646097372611,"mc":[{"id":"1.195395456","rc":[{"atl":[[3,15.31],[3.3,0]],"id":28002629},{"atl":[[1.79,40.56],[1.9,0]],"id":43154433}],"con":true,"img":false}]}
{"op":"mcm","clk":"5346801490","pt":1646097381595,"mc":[{"id":"1.195395456","rc":[{"atb":[[1.64,63.94],[1.99,39]],"id":37672294},{"atb":[[2.8,20.43],[2.28,0]],"id":37455733},{"atl":[[2.36,26.04],[1.89,0]],"id":43154433}],"con":true,"img":false}]}
{"op":"mcm","clk":"5346802225","pt":1646097401115,"mc":[{"id":"1.195395456","rc":[{"atl":[[2.76,0]],"id":42393370}],"con":true,"img":false}]}
{"op":"mcm","clk":"5346802231","pt":1646097401219,"mc":[{"id":"1.195395456","rc":[{"atl":[[2.72,18.86],[3.75,36.36]],"id":42393370}],"con":true,"img":false}]}
{"op":"mcm","clk":"5346802236","pt":1646097401320,"mc":[{"id":"1.195395456","rc":[{"atl":[[2.74,0],[3.75,0],[2.7,18.93]],"id":42393370}],"con":true,"img":false}]}
{"op":"mcm","clk":"5346802974","pt":1646097420865,"mc":[{"id":"1.195395456","rc":[{"atb":[[1.99,0]],"id":37672294},{"atl":[[3.05,0]],"id":28002629},{"atl":[[1.8,0]],"id":43154433}],"con":true,"img":false}]}
{"op":"mcm","clk":"5346802978","pt":1646097420969,"mc":[{"id":"1.195395456","rc":[{"atb":[[2,0],[1.82,121.95],[2.02,39]],"id":37672294},{"atl":[[3,0],[2.98,15.3],[3.3,30.62]],"id":28002629},{"atl":[[1.79,0],[1.78,40.56],[1.9,81.12]],"id":43154433}],"con":true,"img":false}]}
{"op":"mcm","clk":"5346804031","pt":1646097450309,"mc":[{"id":"1.195395456","rc":[{"atb":[[1.82,0],[2.04,63.95]],"id":37672294},{"atl":[[3.3,0],[2.96,15.31]],"id":28002629},{"atl":[[1.9,0],[1.77,40.56]],"id":43154433}],"con":true,"img":false}]}
{"op":"mcm","clk":"5346804384","pt":1646097459201,"mc":[{"id":"1.195395456","rc":[{"atl":[[2.72,0]],"id":42393370}],"con":true,"img":false}]}
{"op":"mcm","clk":"5346804388","pt":1646097459311,"mc":[{"id":"1.195395456","rc":[{"atl":[[2.68,18.86],[3.75,36.36]],"id":42393370}],"con":true,"img":false}]}
{"op":"mcm","clk":"5346804393","pt":1646097459409,"mc":[{"id":"1.195395456","rc":[{"atl":[[2.7,0]],"id":42393370}],"con":true,"img":false}]}
{"op":"mcm","clk":"5346805042","pt":1646097477837,"mc":[{"id":"1.195395456","rc":[{"atl":[[2.68,0]],"id":42393370},{"atb":[[2.58,0]],"id":37267533},{"atb":[[2.8,0],[3,0],[1.94,39.12]],"id":37455733},{"atl":[[2.36,0],[1.78,0],[2.96,18.07]],"id":43154433}],"con":true,"img":false}]}
{"op":"mcm","clk":"5346805047","pt":1646097477941,"mc":[{"id":"1.195395456","rc":[{"atl":[[3.15,18.86]],"id":42393370},{"atb":[[2.3,22.28]],"id":37267533},{"atb":[[2.8,20.28],[1.99,101.01],[2.78,0]],"id":37455733},{"atl":[[1.77,0],[1.87,81.12],[2.14,40.56]],"id":43154433}],"con":true,"img":false}]}
{"op":"mcm","clk":"5346805052","pt":1646097478043,"mc":[{"id":"1.195395456","rc":[{"atb":[[1.99,0],[2.78,56.18]],"id":37455733}],"con":true,"img":false}]}
{"op":"mcm","clk":"5346805411","pt":1646097488275,"mc":[{"id":"1.195395456","rc":[{"atl":[[3.1,18.87]],"id":42393370}],"con":true,"img":false}]}
{"op":"mcm","clk":"5346805414","pt":1646097488376,"mc":[{"id":"1.195395456","rc":[{"atl":[[3.75,0]],"id":42393370}],"con":true,"img":false}]}
{"op":"mcm","clk":"5346805745","pt":1646097496692,"mc":[{"id":"1.195395456","rc":[{"atb":[[2.02,0]],"id":37672294},{"atl":[[2.98,0]],"id":28002629}],"con":true,"img":false}]}
{"op":"mcm","clk":"5346805751","pt":1646097496794,"mc":[{"id":"1.195395456","rc":[{"atb":[[2.06,39],[1.88,113.64]],"id":37672294},{"atl":[[3.3,30.62],[2.94,15.3]],"id":28002629}],"con":true,"img":false}]}
{"op":"mcm","clk":"5346805755","pt":1646097496898,"mc":[{"id":"1.195395456","rc":[{"atb":[[2.04,0]],"id":37672294},{"atl":[[2.96,0]],"id":28002629}],"con":true,"img":false}]}
{"op":"mcm","clk":"5346806476","pt":1646097514995,"mc":[{"id":"1.195395456","rc":[{"atb":[[2.06,0]],"id":37672294},{"atl":[[2.94,0]],"id":28002629},{"atl":[[3.8,0],[3.15,0],[3.05,21.09]],"id":42393370},{"atb":[[2.3,0]],"id":37267533},{"atb":[[2.8,0]],"id":37455733},{"atl":[[2.14,0]],"id":43154433}],"con":true,"img":false}]}
{"op":"mcm","clk":"5346806479","pt":1646097515099,"mc":[{"id":"1.195395456","rc":[{"atb":[[1.99,39]],"id":37672294},{"atl":[[3.1,15.3]],"id":28002629},{"atl":[[2.78,18.86]],"id":42393370},{"atb":[[2.64,22.28]],"id":37267533},{"atb":[[1.99,101.01],[3,20.28],[2.78,0]],"id":37455733},{"atl":[[1.81,40.56]],"id":43154433}],"con":true,"img":false}]}
{"op":"mcm","clk":"5346806483","pt":1646097515200,"mc":[{"id":"1.195395456","rc":[{"atl":[[1.8,40.56]],"id":43154433}],"con":true,"img":false}]}
{"op":"mcm","clk":"5346806487","pt":1646097515305,"mc":[{"id":"1.195395456","rc":[{"atl":[[1.87,0]],"id":43154433}],"con":true,"img":false}]}
{"op":"mcm","clk":"5346806542","pt":1646097516893,"mc":[{"id":"1.195395456","rc":[{"atl":[[2.76,18.87]],"id":42393370}],"con":true,"img":false}]}
{"op":"mcm","clk":"5346806545","pt":1646097516996,"mc":[{"id":"1.195395456","rc":[{"atl":[[3.1,0]],"id":42393370}],"con":true,"img":false}]}
{"op":"mcm","clk":"5346806850","pt":1646097525411,"mc":[{"id":"1.195395456","rc":[{"atb":[[2,63.95],[1.88,0]],"id":37672294},{"atl":[[3.3,0],[3.05,15.31]],"id":28002629}],"con":true,"img":false}]}
{"op":"mcm","clk":"5346807129","pt":1646097533919,"mc":[{"id":"1.195395456","rc":[{"atl":[[3.8,15.68],[3.05,0]],"id":42393370},{"atl":[[2.32,26.83],[2.96,0]],"id":43154433}],"con":true,"img":false}]}
{"op":"mcm","clk":"5346807161","pt":1646097534742,"mc":[{"id":"1.195395456","rc":[{"atl":[[7.2,0],[7.4,15.62]],"id":37672294},{"atb":[[1.25,385.37],[1.24,0]],"id":42393370}],"con":true,"img":false}]}
{"op":"mcm","clk":"5346807396","pt":1646097543564,"mc":[{"id":"1.195395456","rc":[{"atb":[[1.99,0],[2.78,56.18]],"id":37455733}],"con":true,"img":false}]}
{"op":"mcm","clk":"5346807626","pt":1646097551770,"mc":[{"id":"1.195395456","rc":[{"atl":[[7,0]],"id":37672294},{"atb":[[2.8,20.43],[1.94,0]],"id":37455733}],"con":true,"img":false}]}
{"op":"mcm","clk":"5346807630","pt":1646097551871,"mc":[{"id":"1.195395456","rc":[{"atl":[[7.2,7.05]],"id":37672294}],"con":true,"img":false}]}
{"op":"mcm","clk":"5346808127","pt":1646097567685,"mc":[{"id":"1.195395456","rc":[{"atb":[[1.99,0]],"id":37672294},{"atl":[[3.1,0]],"id":28002629},{"atl":[[2.78,0]],"id":42393370},{"atl":[[1.81,0]],"id":43154433}],"con":true,"img":false}]}
{"op":"mcm","clk":"5346808130","pt":1646097567789,"mc":[{"id":"1.195395456","rc":[{"atb":[[2,0],[2.02,39],[1.89,112.36]],"id":37672294},{"atl":[[3,15.3],[3.3,30.62]],"id":28002629},{"atl":[[2.74,18.86],[3.75,36.36],[2.76,0]],"id":42393370},{"atl":[[1.79,40.56],[1.86,81.12]],"id":43154433}],"con":true,"img":false}]}
{"op":"mcm","clk":"5346808132","pt":1646097567890,"mc":[{"id":"1.195395456","rc":[{"atl":[[3.05,0]],"id":28002629},{"atl":[[1.8,0]],"id":43154433}],"con":true,"img":false}]}
{"op":"mcm","clk":"5346808135","pt":1646097567995,"mc":[{"id":"1.195395456","rc":[{"atb":[[1.89,0],[2.04,63.95]],"id":37672294},{"atl":[[2.98,15.31],[3.3,0]],"id":28002629},{"atl":[[2.72,18.87],[3.75,0]],"id":42393370},{"atl":[[1.78,40.56],[1.86,0]],"id":43154433}],"con":true,"img":false}]}
{"op":"mcm","clk":"5346809216","pt":1646097594538,"mc":[{"id":"1.195395456","rc":[{"atb":[[2.08,6.89]],"id":37672294},{"atb":[[2.84,4.04]],"id":37455733},{"atb":[[1.91,8.18]],"id":22150928}],"con":true,"img":false}]}
{"op":"mcm","clk":"5346809222","pt":1646097594643,"mc":[{"id":"1.195395456","rc":[{"atb":[[2.1,39.01]],"id":37672294}],"con":true,"img":false}]}
{"op":"mcm","clk":"5346809225","pt":1646097594747,"mc":[{"id":"1.195395456","rc":[{"atb":[[2.04,0]],"id":37672294}],"con":true,"img":false}]}
{"op":"mcm","clk":"5346809353","pt":1646097597538,"mc":[{"id":"1.195395456","rc":[{"atb":[[2.08,0]],"id":37672294}],"con":true,"img":false}]}
{"op":"mcm","clk":"5346809357","pt":1646097597639,"mc":[{"id":"1.195395456","rc":[{"atb":[[2.04,78.02]],"id":37672294}],"con":true,"img":false}]}
{"op":"mcm","clk":"5346809359","pt":1646097597744,"mc":[{"id":"1.195395456","rc":[{"atb":[[2.1,0]],"id":37672294}],"con":true,"img":false}]}
{"op":"mcm","clk":"5346809638","pt":1646097606424,"mc":[{"id":"1.195395456","rc":[{"atb":[[2.08,6.89]],"id":37672294}],"con":true,"img":false}]}
{"op":"mcm","clk":"5346809643","pt":1646097606526,"mc":[{"id":"1.195395456","rc":[{"atb":[[2.04,0],[2.1,39.01]],"id":37672294}],"con":true,"img":false}]}
{"op":"mcm","clk":"5346809654","pt":1646097606833,"mc":[{"id":"1.195395456","rc":[{"atb":[[2.02,0]],"id":37672294},{"atl":[[3,0]],"id":28002629},{"atl":[[2.74,0]],"id":42393370},{"atb":[[1.83,0],[2.08,37.97]],"id":37267533},{"atl":[[1.79,0]],"id":43154433}],"con":true,"img":false}]}
{"op":"mcm","clk":"5346809657","pt":1646097606937,"mc":[{"id":"1.195395456","rc":[{"atb":[[2.06,39]],"id":37672294},{"atl":[[2.98,0],[2.96,15.3],[3.3,30.62]],"id":28002629},{"atl":[[2.72,0],[3.75,36.36],[2.7,18.86]],"id":42393370},{"atl":[[1.86,81.12],[1.77,40.56]],"id":43154433}],"con":true,"img":false}]}
{"op":"mcm","clk":"5346809661","pt":1646097607041,"mc":[{"id":"1.195395456","rc":[{"atl":[[3.3,0],[2.94,15.31]],"id":28002629},{"atl":[[2.68,18.87],[3.75,0]],"id":42393370},{"atl":[[1.78,0],[1.86,0],[1.76,40.56]],"id":43154433}],"con":true,"img":false}]}
{"op":"mcm","clk":"5346809756","pt":1646097609550,"mc":[{"id":"1.195395456","rc":[{"atb":[[2.08,0]],"id":37672294}],"con":true,"img":false}]}
{"op":"mcm","clk":"5346809758","pt":1646097609654,"mc":[{"id":"1.195395456","rc":[{"atb":[[2.08,78.02]],"id":37672294}],"con":true,"img":false}]}
{"op":"mcm","clk":"5346809760","pt":1646097609757,"mc":[{"id":"1.195395456","rc":[{"atb":[[2.1,0]],"id":37672294}],"con":true,"img":false}]}
{"op":"mcm","clk":"5346809978","pt":1646097615457,"mc":[{"id":"1.195395456","rc":[{"atb":[[2.12,6.65]],"id":37267533}],"con":true,"img":false}]}
{"op":"mcm","clk":"5346810097","pt":1646097618436,"mc":[{"id":"1.195395456","rc":[{"atb":[[2.12,6.65]],"id":37672294}],"con":true,"img":false}]}
{"op":"mcm","clk":"5346810634","pt":1646097637105,"mc":[{"id":"1.195395456","rc":[{"atb":[[2.14,39.01],[2.08,0]],"id":37672294}],"con":true,"img":false}]}
{"op":"mcm","clk":"5346810700","pt":1646097639470,"mc":[{"id":"1.195395456","rc":[{"atb":[[2.12,0]],"id":37672294}],"con":true,"img":false}]}
{"op":"mcm","clk":"5346810760","pt":1646097642190,"mc":[{"id":"1.195395456","rc":[{"atb":[[2.14,0],[2.08,78.02]],"id":37672294}],"con":true,"img":false}]}
{"op":"mcm","clk":"5346810766","pt":1646097642397,"mc":[{"id":"1.195395456","rc":[{"atb":[[2.06,0]],"id":37672294}],"con":true,"img":false}]}
{"op":"mcm","clk":"5346810770","pt":1646097642498,"mc":[{"id":"1.195395456","rc":[{"atb":[[2.1,39]],"id":37672294}],"con":true,"img":false}]}
{"op":"mcm","clk":"5346810984","pt":1646097651523,"mc":[{"id":"1.195395456","rc":[{"atb":[[2.14,6.53]],"id":37672294}],"con":true,"img":false}]}
{"op":"mcm","clk":"5346811068","pt":1646097654801,"mc":[{"id":"1.195395456","rc":[{"atl":[[5.5,22.22],[5.4,9.22]],"id":22150928}],"con":true,"img":false}]}
{"op":"mcm","clk":"5346811072","pt":1646097654905,"mc":[{"id":"1.195395456","rc":[{"atl":[[7.8,14.71]],"id":22150928}],"con":true,"img":false}]}
{"op":"mcm","clk":"5346811077","pt":1646097655005,"mc":[{"id":"1.195395456","rc":[{"atl":[[5.5,0]],"id":22150928}],"con":true,"img":false}]}
{"op":"mcm","clk":"5346811080","pt":1646097655109,"mc":[{"id":"1.195395456","rc":[{"atl":[[5.5,18.44],[7.8,0]],"id":22150928}],"con":true,"img":false}]}
{"op":"mcm","clk":"5346811234","pt":1646097659913,"mc":[{"id":"1.195395456","rc":[{"atl":[[2.96,0]],"id":28002629},{"atl":[[2.7,0]],"id":42393370},{"atb":[[2.64,0]],"id":37267533},{"atb":[[2.8,0],[3,0],[1.95,38.71]],"id":37455733},{"atl":[[2.32,0],[1.77,0],[2.96,18.07]],"id":43154433}],"con":true,"img":false}]}
{"op":"mcm","clk":"5346811239","pt":1646097660017,"mc":[{"id":"1.195395456","rc":[{"atl":[[2.92,15.3],[3.3,30.62]],"id":28002629},{"atl":[[2.66,18.86],[2.68,0],[3.75,36.36]],"id":42393370},{"atb":[[2.32,22.28]],"id":37267533},{"atb":[[2.8,20.28]],"id":37455733},{"atl":[[1.89,81.12],[2.14,40.56],[1.76,0]],"id":43154433}],"con":true,"img":false}]}
{"op":"mcm","clk":"5346811242","pt":1646097660119,"mc":[{"id":"1.195395456","rc":[{"atl":[[2.9,15.31],[3.3,0],[2.94,0]],"id":28002629},{"atl":[[2.64,18.87],[3.75,0]],"id":42393370}],"con":true,"img":false}]}
{"op":"mcm","clk":"5346811551","pt":1646097669332,"mc":[{"id":"1.195395456","rc":[{"atb":[[2.16,39.01],[2.08,0]],"id":37672294}],"con":true,"img":false}]}
{"op":"mcm","clk":"5346811663","pt":1646097672561,"mc":[{"id":"1.195395456","rc":[{"atb":[[2.14,0]],"id":37672294}],"con":true,"img":false}]}
{"op":"mcm","clk":"5346811735","pt":1646097674461,"mc":[{"id":"1.195395456","rc":[{"atb":[[2.12,78.02]],"id":37672294}],"con":true,"img":false}]}
{"op":"mcm","clk":"5346811739","pt":1646097674563,"mc":[{"id":"1.195395456","rc":[{"atb":[[2.16,0]],"id":37672294}],"con":true,"img":false}]}
{"op":"mcm","clk":"5346812533","pt":1646097694906,"mc":[{"id":"1.195395456","rc":[{"atb":[[2.32,0]],"id":37267533},{"atb":[[2.8,0]],"id":37455733},{"atl":[[2.14,0]],"id":43154433}],"con":true,"img":false}]}
{"op":"mcm","clk":"5346812540","pt":1646097694958,"mc":[{"id":"1.195395456","rc":[{"atb":[[2.68,22.28]],"id":37267533},{"atb":[[3,20.28]],"id":37455733},{"atl":[[1.8,40.56]],"id":43154433}],"con":true,"img":false}]}
{"op":"mcm","clk":"5346812544","pt":1646097695062,"mc":[{"id":"1.195395456","rc":[{"atl":[[1.79,40.56]],"id":43154433}],"con":true,"img":false}]}
{"op":"mcm","clk":"5346812548","pt":1646097695163,"mc":[{"id":"1.195395456","rc":[{"atl":[[1.89,0]],"id":43154433}],"con":true,"img":false}]}
{"op":"mcm","clk":"5346812617","pt":1646097696801,"mc":[{"id":"1.195395456","rc":[{"atb":[[2.12,0]],"id":37267533}],"con":true,"img":false}]}
{"op":"mcm","clk":"5346812828","pt":1646097702563,"mc":[{"id":"1.195395456","rc":[{"atb":[[2.16,6.42]],"id":37672294}],"con":true,"img":false}]}
{"op":"mcm","clk":"5346812829","pt":1646097702666,"mc":[{"id":"1.195395456","rc":[{"atb":[[2.12,0],[2.18,39.01]],"id":37672294}],"con":true,"img":false}]}
{"op":"mcm","clk":"5346812867","pt":1646097703901,"mc":[{"id":"1.195395456","rc":[{"atl":[[7.4,0],[7,16.67]],"id":37672294},{"atb":[[1.25,154.14],[1.26,384.62]],"id":42393370},{"atl":[[5.5,0],[5.4,18.44]],"id":22150928}],"con":true,"img":false}]}
{"op":"mcm","clk":"5346812932","pt":1646097705810,"mc":[{"id":"1.195395456","rc":[{"atb":[[2.16,0]],"id":37672294}],"con":true,"img":false}]}
{"op":"mcm","clk":"5346813014","pt":1646097707811,"mc":[{"id":"1.195395456","rc":[{"atb":[[2.12,78.02],[2.18,0]],"id":37672294}],"con":true,"img":false}]}
{"op":"mcm","clk":"5346813179","pt":1646097712327,"mc":[{"id":"1.195395456","rc":[{"atb":[[2.1,0]],"id":37672294},{"atl":[[2.92,0],[2.88,21.57]],"id":28002629},{"atl":[[2.66,0]],"id":42393370}],"con":true,"img":false}]}
{"op":"mcm","clk":"5346813185","pt":1646097712430,"mc":[{"id":"1.195395456","rc":[{"atb":[[2.14,39]],"id":37672294},{"atl":[[2.9,0],[2.86,15.31]],"id":28002629},{"atl":[[2.64,0],[2.62,18.86],[3.75,36.36]],"id":42393370}],"con":true,"img":false}]}
{"op":"mcm","clk":"5346813230","pt":1646097713915,"mc":[{"id":"1.195395456","rc":[{"atl":[[7.2,23.18],[7,0]],"id":37672294},{"atb":[[1.25,554.14],[1.26,0]],"id":42393370}],"con":true,"img":false}]}
{"op":"mcm","clk":"5346813486","pt":1646097720641,"mc":[{"id":"1.195395456","rc":[{"atb":[[2.18,6.31]],"id":37672294}],"con":true,"img":false}]}
{"op":"mcm","clk":"5346813811","pt":1646097729926,"mc":[{"id":"1.195395456","rc":[{"atb":[[2.8,20.43]],"id":37455733},{"atl":[[2.3,27.24]],"id":43154433}],"con":true,"img":false}]}
{"op":"mcm","clk":"5346813813","pt":1646097730026,"mc":[{"id":"1.195395456","rc":[{"atl":[[2.62,0]],"id":42393370},{"atb":[[1.95,0]],"id":37455733},{"atl":[[2.96,0]],"id":43154433}],"con":true,"img":false}]}
{"op":"mcm","clk":"5346813816","pt":1646097730128,"mc":[{"id":"1.195395456","rc":[{"atl":[[2.74,18.86]],"id":42393370}],"con":true,"img":false}]}
{"op":"mcm","clk":"5346813952","pt":1646097734226,"mc":[{"id":"1.195395456","rc":[{"atb":[[2.2,39.01]],"id":37672294}],"con":true,"img":false}]}
{"op":"mcm","clk":"5346813955","pt":1646097734329,"mc":[{"id":"1.195395456","rc":[{"atb":[[2.12,0]],"id":37672294}],"con":true,"img":false}]}
{"op":"mcm","clk":"5346814003","pt":1646097735760,"mc":[{"id":"1.195395456","rc":[{"atb":[[2.18,0]],"id":37672294}],"con":true,"img":false}]}
{"op":"mcm","clk":"5346814008","pt":1646097735863,"mc":[{"id":"1.195395456","rc":[{"atb":[[2.16,78.02]],"id":37672294}],"con":true,"img":false}]}
{"op":"mcm","clk":"5346814011","pt":1646097735964,"mc":[{"id":"1.195395456","rc":[{"atb":[[2.2,0]],"id":37672294}],"con":true,"img":false}]}
{"op":"mcm","clk":"5346814107","pt":1646097738838,"mc":[{"id":"1.195395456","rc":[{"atl":[[2.72,18.87],[3.75,0]],"id":42393370}],"con":true,"img":false}]}
{"op":"mcm","clk":"5346814303","pt":1646097744679,"mc":[{"id":"1.195395456","rc":[{"atb":[[2.2,6.2]],"id":37672294}],"con":true,"img":false}]}
{"op":"mcm","clk":"5346814307","pt":1646097744782,"mc":[{"id":"1.195395456","rc":[{"atb":[[2.22,39.01],[2.16,0]],"id":37672294}],"con":true,"img":false}]}
{"op":"mcm","clk":"5346814373","pt":1646097746678,"mc":[{"id":"1.195395456","rc":[{"atl":[[1.8,0]],"id":43154433}],"con":true,"img":false}]}
{"op":"mcm","clk":"5346814376","pt":1646097746782,"mc":[{"id":"1.195395456","rc":[{"atl":[[1.79,0],[1.84,81.12],[1.78,40.56]],"id":43154433}],"con":true,"img":false}]}
{"op":"mcm","clk":"5346814408","pt":1646097747758,"mc":[{"id":"1.195395456","rc":[{"atb":[[2.2,0]],"id":37672294}],"con":true,"img":false}]}
{"op":"mcm","clk":"5346814480","pt":1646097749859,"mc":[{"id":"1.195395456","rc":[{"atb":[[2.22,0],[2.16,78.02]],"id":37672294}],"con":true,"img":false}]}
{"op":"mcm","clk":"5346814721","pt":1646097756688,"mc":[{"id":"1.195395456","rc":[{"atb":[[2.2,6.2]],"id":37672294}],"con":true,"img":false}]}
{"op":"mcm","clk":"5346814948","pt":1646097763787,"mc":[{"id":"1.195395456","rc":[{"atl":[[2.88,0]],"id":28002629}],"con":true,"img":false}]}
{"op":"mcm","clk":"5346814951","pt":1646097763890,"mc":[{"id":"1.195395456","rc":[{"atl":[[2.86,0],[2.84,21.57],[3.3,30.62]],"id":28002629}],"con":true,"img":false}]}
{"op":"mcm","clk":"5346815234","pt":1646097772820,"mc":[{"id":"1.195395456","rc":[{"atl":[[1.84,0],[1.77,40.56]],"id":43154433}],"con":true,"img":false}]}
{"op":"mcm","clk":"5346815369","pt":1646097775934,"mc":[{"id":"1.195395456","rc":[{"atb":[[2.22,39.01],[2.16,0]],"id":37672294}],"con":true,"img":false}]}
{"op":"mcm","clk":"5346815422","pt":1646097777722,"mc":[{"id":"1.195395456","rc":[{"atb":[[2.2,0]],"id":37672294}],"con":true,"img":false}]}
{"op":"mcm","clk":"5346815423","pt":1646097777825,"mc":[{"id":"1.195395456","rc":[{"atb":[[2.22,0],[2.16,78.02]],"id":37672294}],"con":true,"img":false}]}
{"op":"mcm","clk":"5346815532","pt":1646097780702,"mc":[{"id":"1.195395456","rc":[{"atb":[[2.14,0]],"id":37672294},{"atl":[[2.84,0]],"id":28002629},{"atl":[[2.74,0]],"id":42393370}],"con":true,"img":false}]}
{"op":"mcm","clk":"5346815536","pt":1646097780802,"mc":[{"id":"1.195395456","rc":[{"atb":[[1.88,113.64],[2.18,39],[2.16,0]],"id":37672294},{"atl":[[3.05,21.57]],"id":28002629},{"atl":[[3.75,36.36],[2.7,18.86]],"id":42393370}],"con":true,"img":false}]}
{"op":"mcm","clk":"5346815537","pt":1646097780903,"mc":[{"id":"1.195395456","rc":[{"atl":[[2.72,0]],"id":42393370}],"con":true,"img":false}]}
{"op":"mcm","clk":"5346815797","pt":1646097787948,"mc":[{"id":"1.195395456","rc":[{"atb":[[1.66,12.65]],"id":22150928}],"con":true,"img":false}]}
{"op":"mcm","clk":"5346815809","pt":1646097788306,"mc":[{"id":"1.195395456","rc":[{"atb":[[2.84,8.58]],"id":37455733}],"con":true,"img":false}]}
{"op":"mcm","clk":"5346815848","pt":1646097789745,"mc":[{"id":"1.195395456","rc":[{"atb":[[2.24,6]],"id":37672294}],"con":true,"img":false}]}
{"op":"mcm","clk":"5346815850","pt":1646097789848,"mc":[{"id":"1.195395456","rc":[{"atl":[[3,21.57],[3.3,0]],"id":28002629}],"con":true,"img":false}]}
{"op":"mcm","clk":"5346816126","pt":1646097797343,"mc":[{"id":"1.195395456","rc":[{"atb":[[2.18,0]],"id":37672294}],"con":true,"img":false}]}
{"op":"mcm","clk":"5346816128","pt":1646097797446,"mc":[{"id":"1.195395456","rc":[{"atb":[[2.02,39]],"id":37672294}],"con":true,"img":false}]}
{"op":"mcm","clk":"5346816174","pt":1646097798831,"mc":[{"id":"1.195395456","rc":[{"atb":[[2.24,0]],"id":37672294}],"con":true,"img":false}]}
{"op":"mcm","clk":"5346816371","pt":1646097804761,"mc":[{"id":"1.195395456","rc":[{"atb":[[2.06,7.02]],"id":37672294}],"con":true,"img":false}]}
{"op":"mcm","clk":"5346816436","pt":1646097806581,"mc":[{"id":"1.195395456","rc":[{"atb":[[1.88,0],[2.08,39.01]],"id":37672294},{"atl":[[2.68,18.87],[3.75,0]],"id":42393370}],"con":true,"img":false}]}
{"op":"mcm","clk":"5346816466","pt":1646097807279,"mc":[{"id":"1.195395456","marketDefinition":{"bspMarket":false,"turnInPlayEnabled":false,"persistenceEnabled":false,"marketBaseRate":5.0,"eventId":"31270459","eventTypeId":"4339","numberOfWinners":3,"bettingType":"ODDS","marketType":"PLACE","marketTime":"2022-03-01T02:04:00.000Z","suspendTime":"2022-03-01T02:04:00.000Z","bspReconciled":false,"complete":true,"inPlay":false,"crossMatching":true,"runnersVoidable":false,"numberOfActiveRunners":7,"betDelay":0,"status":"OPEN","runners":[{"status":"ACTIVE","sortPriority":1,"id":37672294,"name":"1. Wizard Willie"},{"status":"ACTIVE","sortPriority":2,"id":28002629,"name":"2. St Andrews"},{"status":"ACTIVE","sortPriority":3,"id":43154433,"name":"3. Sapporo Bale"},{"status":"ACTIVE","sortPriority":4,"id":42393370,"name":"5. Goldstar Tookie"},{"status":"ACTIVE","sortPriority":5,"id":22150928,"name":"6. Smash Grenade"},{"status":"ACTIVE","sortPriority":6,"id":37267533,"name":"8. Diamond Empress"},{"status":"ACTIVE","sortPriority":7,"id":37455733,"name":"9. Just Stagger"},{"status":"REMOVED","sortPriority":8,"removalDate":"2022-02-28T21:20:52.000Z","id":36993903,"name":"7. Baldrick"}],"regulators":["MR_INT"],"venue":"Addington","countryCode":"NZ","discountAllowed":true,"timezone":"NZ","openDate":"2022-02-28T23:02:00.000Z","version":4380773822,"name":"To Be Placed","eventName":"Addington (NZL) 1st Mar"},"rc":[],"con":true,"img":false}]}
{"op":"mcm","clk":"5346816485","pt":1646097807867,"mc":[{"id":"1.195395456","rc":[{"atb":[[2.06,0]],"id":37672294}],"con":true,"img":false}]}
{"op":"mcm","clk":"5346816645","pt":1646097811671,"mc":[{"id":"1.195395456","rc":[{"atb":[[2.04,78.02],[2.08,0]],"id":37672294}],"con":true,"img":false}]}
{"op":"mcm","clk":"5346816792","pt":1646097814794,"mc":[{"id":"1.195395456","rc":[{"atl":[[1.78,0]],"id":43154433}],"con":true,"img":false}]}
{"op":"mcm","clk":"5346816798","pt":1646097814897,"mc":[{"id":"1.195395456","rc":[{"atl":[[1.76,40.56]],"id":43154433}],"con":true,"img":false}]}
{"op":"mcm","clk":"5346816801","pt":1646097814953,"mc":[{"id":"1.195395456","rc":[{"atl":[[1.84,81.12],[1.77,0]],"id":43154433}],"con":true,"img":false}]}
{"op":"mcm","clk":"5346816985","pt":1646097819774,"mc":[{"id":"1.195395456","rc":[{"atb":[[2.08,6.89]],"id":37672294}],"con":true,"img":false}]}
{"op":"mcm","clk":"5346817312","pt":1646097829100,"mc":[{"id":"1.195395456","rc":[{"atb":[[2.08,14.63]],"id":37672294}],"con":true,"img":false}]}
{"op":"mcm","clk":"5346817403","pt":1646097831101,"mc":[{"id":"1.195395456","rc":[{"atl":[[3.05,0]],"id":28002629}],"con":true,"img":false}]}
{"op":"mcm","clk":"5346817406","pt":1646097831205,"mc":[{"id":"1.195395456","rc":[{"atl":[[3,0],[2.98,21.57],[3.3,43.14]],"id":28002629}],"con":true,"img":false}]}
{"op":"mcm","clk":"5346817435","pt":1646097831973,"mc":[{"id":"1.195395456","rc":[{"atb":[[2.1,39.01]],"id":37672294}],"con":true,"img":false}]}
{"op":"mcm","clk":"5346817437","pt":1646097832076,"mc":[{"id":"1.195395456","rc":[{"atb":[[2.04,0]],"id":37672294}],"con":true,"img":false}]}
{"op":"mcm","clk":"5346817522","pt":1646097834793,"mc":[{"id":"1.195395456","rc":[{"atb":[[2.08,7.73]],"id":37672294}],"con":true,"img":false}]}
{"op":"mcm","clk":"5346817599","pt":1646097836743,"mc":[{"id":"1.195395456","rc":[{"atl":[[2.76,37.74]],"id":42393370},{"atb":[[1.17,0],[1.35,98.84]],"id":37267533},{"atb":[[1.44,40.71],[2.78,0]],"id":37455733},{"atb":[[1.62,60.33],[1.71,82.51]],"id":22150928}],"con":true,"img":false}]}
{"op":"mcm","clk":"5346817601","pt":1646097836797,"mc":[{"id":"1.195395456","rc":[{"atl":[[2.68,0]],"id":42393370}],"con":true,"img":false}]}
{"op":"mcm","clk":"5346817646","pt":1646097838027,"mc":[{"id":"1.195395456","rc":[{"atb":[[2.84,4.53]],"id":37455733}],"con":true,"img":false}]}
{"op":"mcm","clk":"5346817740","pt":1646097840289,"mc":[{"id":"1.195395456","rc":[{"atl":[[1.84,0],[1.75,40.56]],"id":43154433}],"con":true,"img":false}]}
{"op":"mcm","clk":"5346817767","pt":1646097840800,"mc":[{"id":"1.195395456","rc":[{"atb":[[2.14,6.53]],"id":37672294}],"con":true,"img":false}]}
{"op":"mcm","clk":"5346817772","pt":1646097840904,"mc":[{"id":"1.195395456","rc":[{"atb":[[2.1,0],[2.16,7.74]],"id":37672294}],"con":true,"img":false}]}
{"op":"mcm","clk":"5346817874","pt":1646097843833,"mc":[{"id":"1.195395456","rc":[{"atb":[[2.14,0]],"id":37672294}],"con":true,"img":false}]}
{"op":"mcm","clk":"5346817958","pt":1646097845988,"mc":[{"id":"1.195395456","rc":[{"atb":[[2.1,39.01]],"id":37672294}],"con":true,"img":false}]}
{"op":"mcm","clk":"5346817961","pt":1646097846092,"mc":[{"id":"1.195395456","rc":[{"atb":[[2.16,0]],"id":37672294}],"con":true,"img":false}]}
{"op":"mcm","clk":"5346818012","pt":1646097847325,"mc":[{"id":"1.195395456","rc":[{"atb":[[2.08,0]],"id":37672294}],"con":true,"img":false}]}
{"op":"mcm","clk":"5346818023","pt":1646097847636,"mc":[{"id":"1.195395456","rc":[{"atb":[[2.02,0]],"id":37672294},{"atb":[[2.8,0],[2.28,28.73]],"id":37455733}],"con":true,"img":false}]}
{"op":"mcm","clk":"5346818026","pt":1646097847736,"mc":[{"id":"1.195395456","rc":[{"atb":[[2.06,39]],"id":37672294}],"con":true,"img":false}]}
{"op":"mcm","clk":"5346818174","pt":1646097851125,"mc":[{"id":"1.195395456","rc":[{"atb":[[2.1,0],[2.08,78.02]],"id":37672294}],"con":true,"img":false}]}
{"op":"mcm","clk":"5346818255","pt":1646097853234,"mc":[{"id":"1.195395456","rc":[{"atb":[[2.84,0]],"id":37455733},{"atb":[[1.66,0]],"id":22150928}],"con":true,"img":false}]}
{"op":"mcm","clk":"5346818382","pt":1646097856421,"mc":[{"id":"1.195395456","rc":[{"atl":[[3.3,0],[2.96,21.57]],"id":28002629}],"con":true,"img":false}]}
{"op":"mcm","clk":"5346818474","pt":1646097858835,"mc":[{"id":"1.195395456","rc":[{"atb":[[2.12,6.65]],"id":37672294}],"con":true,"img":false}]}
{"op":"mcm","clk":"5346818485","pt":1646097859039,"mc":[{"id":"1.195395456","rc":[{"atb":[[1.75,11.13]],"id":22150928}],"con":true,"img":false}]}
{"op":"mcm","clk":"5346818694","pt":1646097863934,"mc":[{"id":"1.195395456","rc":[{"atl":[[2.98,0]],"id":28002629},{"atl":[[2.7,0]],"id":42393370},{"atb":[[2.68,0]],"id":37267533},{"atb":[[3,0],[2.28,0],[1.95,38.71]],"id":37455733},{"atl":[[2.3,0],[2.94,18.25],[1.76,0]],"id":43154433}],"con":true,"img":false}]}
{"op":"mcm","clk":"5346818701","pt":1646097864036,"mc":[{"id":"1.195395456","rc":[{"atl":[[3.85,35.09],[3.25,21.57],[2.96,0]],"id":28002629},{"atl":[[2.74,18.86],[3.75,36.36],[2.76,0]],"id":42393370},{"atb":[[2.32,22.28]],"id":37267533},{"atb":[[2.48,20.28]],"id":37455733},{"atl":[[1.83,81.12],[2.12,40.56],[1.75,0]],"id":43154433}],"con":true,"img":false}]}
{"op":"mcm","clk":"5346819191","pt":1646097876162,"mc":[{"id":"1.195395456","rc":[{"atb":[[2.14,39.01],[2.08,0]],"id":37672294}],"con":true,"img":false}]}
{"op":"mcm","clk":"5346819228","pt":1646097876982,"mc":[{"id":"1.195395456","rc":[{"atb":[[2.12,0]],"id":37672294}],"con":true,"img":false}]}
{"op":"mcm","clk":"5346819368","pt":1646097880481,"mc":[{"id":"1.195395456","rc":[{"atb":[[2.06,0]],"id":37672294}],"con":true,"img":false}]}
{"op":"mcm","clk":"5346819371","pt":1646097880583,"mc":[{"id":"1.195395456","rc":[{"atb":[[2.1,39]],"id":37672294}],"con":true,"img":false}]}
{"op":"mcm","clk":"5346819400","pt":1646097881258,"mc":[{"id":"1.195395456","rc":[{"atb":[[2.12,78.02]],"id":37672294}],"con":true,"img":false}]}
{"op":"mcm","clk":"5346819404","pt":1646097881361,"mc":[{"id":"1.195395456","rc":[{"atb":[[2.14,0]],"id":37672294}],"con":true,"img":false}]}
{"op":"mcm","clk":"5346819730","pt":1646097888980,"mc":[{"id":"1.195395456","rc":[{"atl":[[3.85,0],[3.2,21.57]],"id":28002629},{"atl":[[3.75,0],[2.76,37.74]],"id":42393370}],"con":true,"img":false}]}
{"op":"mcm","clk":"5346819960","pt":1646097894615,"mc":[{"id":"1.195395456","rc":[{"atl":[[1.83,0],[1.85,117.65]],"id":43154433}],"con":true,"img":false}]}
{"op":"mcm","clk":"5346820032","pt":1646097896516,"mc":[{"id":"1.195395456","rc":[{"atl":[[3.25,0]],"id":28002629},{"atb":[[2.32,0]],"id":37267533},{"atl":[[11.5,0],[14.5,3.03]],"id":37267533},{"atb":[[2.48,0]],"id":37455733},{"atb":[[1.62,0]],"id":22150928},{"atl":[[2.12,0]],"id":43154433}],"con":true,"img":false}]}
{"op":"mcm","clk":"5346820036","pt":1646097896619,"mc":[{"id":"1.195395456","rc":[{"atl":[[3.2,0],[3.85,35.09],[3.05,21.57]],"id":28002629},{"atb":[[2.68,22.28]],"id":37267533},{"atb":[[3,20.28]],"id":37455733},{"atb":[[1.72,60.33]],"id":22150928},{"atl":[[1.79,40.56]],"id":43154433}],"con":true,"img":false}]}
{"op":"mcm","clk":"5346820336","pt":1646097903989,"mc":[{"id":"1.195395456","rc":[{"atb":[[2.16,6.42]],"id":37672294}],"con":true,"img":false}]}
{"op":"mcm","clk":"5346820424","pt":1646097905997,"mc":[{"id":"1.195395456","rc":[{"atb":[[2.12,0],[2.18,39.01]],"id":37672294}],"con":true,"img":false}]}
{"op":"mcm","clk":"5346820472","pt":1646097907028,"mc":[{"id":"1.195395456","rc":[{"atb":[[2.16,0]],"id":37672294}],"con":true,"img":false}]}
{"op":"mcm","clk":"5346820478","pt":1646097907132,"mc":[{"id":"1.195395456","rc":[{"atb":[[2.12,78.02]],"id":37672294}],"con":true,"img":false}]}
{"op":"mcm","clk":"5346820484","pt":1646097907234,"mc":[{"id":"1.195395456","rc":[{"atb":[[2.18,0]],"id":37672294}],"con":true,"img":false}]}
{"op":"mcm","clk":"5346820739","pt":1646097912730,"mc":[{"id":"1.195395456","rc":[{"atb":[[2.1,0]],"id":37672294}],"con":true,"img":false}]}
{"op":"mcm","clk":"5346820742","pt":1646097912832,"mc":[{"id":"1.195395456","rc":[{"atb":[[1.88,113.64],[2.12,0],[2.14,39]],"id":37672294}],"con":true,"img":false}]}
{"op":"mcm","clk":"5346820743","pt":1646097912934,"mc":[{"id":"1.195395456","rc":[{"atb":[[2.16,63.95]],"id":37672294}],"con":true,"img":false}]}
{"op":"mcm","clk":"5346820747","pt":1646097913037,"mc":[{"id":"1.195395456","rc":[{"atb":[[1.88,0]],"id":37672294}],"con":true,"img":false}]}
{"op":"mcm","clk":"5346820777","pt":1646097913809,"mc":[{"id":"1.195395456","rc":[{"atb":[[1.75,0]],"id":22150928}],"con":true,"img":false}]}
{"op":"mcm","clk":"5346820982","pt":1646097919255,"mc":[{"id":"1.195395456","rc":[{"atl":[[1.85,0],[1.78,40.56]],"id":43154433}],"con":true,"img":false}]}
{"op":"mcm","clk":"5346821000","pt":1646097919818,"mc":[{"id":"1.195395456","rc":[{"atb":[[1.76,10.99]],"id":22150928}],"con":true,"img":false}]}
{"op":"mcm","clk":"5346821053","pt":1646097921157,"mc":[{"id":"1.195395456","rc":[{"atl":[[3,21.57]],"id":28002629}],"con":true,"img":false}]}
{"op":"mcm","clk":"5346821057","pt":1646097921260,"mc":[{"id":"1.195395456","rc":[{"atl":[[3.85,0]],"id":28002629}],"con":true,"img":false}]}
{"op":"mcm","clk":"5346821094","pt":1646097922032,"mc":[{"id":"1.195395456","rc":[{"atb":[[2.2,6.2]],"id":37672294}],"con":true,"img":false}]}
{"op":"mcm","clk":"5346821096","pt":1646097922135,"mc":[{"id":"1.195395456","rc":[{"atb":[[2.22,39.01],[2.16,0]],"id":37672294}],"con":true,"img":false}]}
{"op":"mcm","clk":"5346821207","pt":1646097925018,"mc":[{"id":"1.195395456","rc":[{"atb":[[2.2,0]],"id":37672294}],"con":true,"img":false}]}
{"op":"mcm","clk":"5346821211","pt":1646097925121,"mc":[{"id":"1.195395456","rc":[{"atb":[[2.22,0],[2.16,78.02]],"id":37672294}],"con":true,"img":false}]}
{"op":"mcm","clk":"5346821383","pt":1646097928923,"mc":[{"id":"1.195395456","rc":[{"atl":[[2.74,43.74],[3.8,0]],"id":42393370},{"atb":[[2.28,28.73],[1.95,0]],"id":37455733},{"atl":[[2.3,27.24],[2.94,0]],"id":43154433}],"con":true,"img":false}]}
{"op":"mcm","clk":"5346821542","pt":1646097933963,"mc":[{"id":"1.195395456","rc":[{"atb":[[2.2,6.2]],"id":37672294}],"con":true,"img":false}]}
{"op":"mcm","clk":"5346821547","pt":1646097934066,"mc":[{"id":"1.195395456","rc":[{"atb":[[2.22,39.01],[2.16,0]],"id":37672294}],"con":true,"img":false}]}
{"op":"mcm","clk":"5346821660","pt":1646097937047,"mc":[{"id":"1.195395456","rc":[{"atb":[[2.2,0]],"id":37672294}],"con":true,"img":false}]}
{"op":"mcm","clk":"5346821665","pt":1646097937149,"mc":[{"id":"1.195395456","rc":[{"atb":[[2.16,78.02]],"id":37672294}],"con":true,"img":false}]}
{"op":"mcm","clk":"5346821667","pt":1646097937252,"mc":[{"id":"1.195395456","rc":[{"atb":[[2.22,0]],"id":37672294}],"con":true,"img":false}]}
{"op":"mcm","clk":"5346821882","pt":1646097943653,"mc":[{"id":"1.195395456","rc":[{"atb":[[1.25,154.14],[1.26,384.62]],"id":42393370}],"con":true,"img":false}]}
{"op":"mcm","clk":"5346821936","pt":1646097944988,"mc":[{"id":"1.195395456","rc":[{"atl":[[4.3,12.98],[2.74,18.86]],"id":42393370},{"atb":[[2.68,0]],"id":37267533},{"atb":[[3,0],[2.28,0],[1.94,39.12]],"id":37455733},{"atl":[[1.79,0],[2.3,0],[2.96,18.07]],"id":43154433}],"con":true,"img":false}]}
{"op":"mcm","clk":"5346821939","pt":1646097945090,"mc":[{"id":"1.195395456","rc":[{"atb":[[2.32,22.28]],"id":37267533},{"atb":[[2.48,20.28]],"id":37455733},{"atl":[[1.84,81.12],[2.14,40.56]],"id":43154433}],"con":true,"img":false}]}
{"op":"mcm","clk":"5346821943","pt":1646097945193,"mc":[{"id":"1.195395456","rc":[{"atl":[[1.78,0]],"id":43154433}],"con":true,"img":false}]}
{"op":"mcm","clk":"5346822581","pt":1646097961113,"mc":[{"id":"1.195395456","rc":[{"atb":[[2.14,0]],"id":37672294},{"atl":[[3.05,0]],"id":28002629}],"con":true,"img":false}]}
{"op":"mcm","clk":"5346822586","pt":1646097961218,"mc":[{"id":"1.195395456","rc":[{"atb":[[2.18,39]],"id":37672294},{"atl":[[3.85,35.09],[2.98,21.57]],"id":28002629}],"con":true,"img":false}]}
{"op":"mcm","clk":"5346822590","pt":1646097961269,"mc":[{"id":"1.195395456","rc":[{"atb":[[1.89,112.36]],"id":37672294}],"con":true,"img":false}]}
{"op":"mcm","clk":"5346822593","pt":1646097961372,"mc":[{"id":"1.195395456","rc":[{"atb":[[2.16,0]],"id":37672294},{"atl":[[3.85,0],[3,0],[2.96,21.57]],"id":28002629}],"con":true,"img":false}]}
{"op":"mcm","clk":"5346823168","pt":1646097977134,"mc":[{"id":"1.195395456","rc":[{"atb":[[2.18,0]],"id":37672294},{"atb":[[2.32,0]],"id":37267533},{"atb":[[2.48,0]],"id":37455733},{"atl":[[2.14,0]],"id":43154433}],"con":true,"img":false}]}
{"op":"mcm","clk":"5346823171","pt":1646097977238,"mc":[{"id":"1.195395456","rc":[{"atb":[[2.02,39]],"id":37672294},{"atb":[[2.68,22.28]],"id":37267533},{"atb":[[3,20.28]],"id":37455733},{"atl":[[1.8,40.56]],"id":43154433}],"con":true,"img":false}]}
{"op":"mcm","clk":"5346823179","pt":1646097977443,"mc":[{"id":"1.195395456","rc":[{"atl":[[1.79,40.56],[1.84,0]],"id":43154433}],"con":true,"img":false}]}
{"op":"mcm","clk":"5346823424","pt":1646097985246,"mc":[{"id":"1.195395456","rc":[{"atb":[[1.89,0],[2.04,63.95]],"id":37672294}],"con":true,"img":false}]}
{"op":"mcm","clk":"5346823430","pt":1646097985402,"mc":[{"id":"1.195395456","rc":[{"atb":[[2.06,7.02]],"id":37672294}],"con":true,"img":false}]}
{"op":"mcm","clk":"5346823539","pt":1646097988431,"mc":[{"id":"1.195395456","rc":[{"atb":[[2.06,0]],"id":37672294}],"con":true,"img":false}]}
{"op":"mcm","clk":"5346823686","pt":1646097992734,"mc":[{"id":"1.195395456","rc":[{"atb":[[1.25,0]],"id":42393370}],"con":true,"img":false}]}
{"op":"mcm","clk":"5346823692","pt":1646097992835,"mc":[{"id":"1.195395456","rc":[{"atb":[[1.27,154.14]],"id":42393370}],"con":true,"img":false}]}
{"op":"mcm","clk":"5346823730","pt":1646097994119,"mc":[{"id":"1.195395456","rc":[{"atb":[[2.08,6.89]],"id":37672294}],"con":true,"img":false}]}
{"op":"mcm","clk":"5346824192","pt":1646098006955,"mc":[{"id":"1.195395456","rc":[{"atb":[[2.08,14.63]],"id":37672294}],"con":true,"img":false}]}
{"op":"mcm","clk":"5346824226","pt":1646098008135,"mc":[{"id":"1.195395456","rc":[{"atl":[[2.98,0]],"id":28002629},{"atl":[[4.3,0],[2.74,43.74]],"id":42393370},{"atb":[[2.28,28.73],[1.94,0]],"id":37455733},{"atl":[[2.3,27.24],[2.96,0]],"id":43154433}],"con":true,"img":false}]}
{"op":"mcm","clk":"5346824232","pt":1646098008239,"mc":[{"id":"1.195395456","rc":[{"atl":[[3.85,35.09],[2.96,0],[2.94,21.57]],"id":28002629}],"con":true,"img":false}]}
{"op":"mcm","clk":"5346824268","pt":1646098008956,"mc":[{"id":"1.195395456","rc":[{"atb":[[2.1,39.01]],"id":37672294}],"con":true,"img":false}]}
{"op":"mcm","clk":"5346824274","pt":1646098009057,"mc":[{"id":"1.195395456","rc":[{"atb":[[2.04,0]],"id":37672294}],"con":true,"img":false}]}
{"op":"mcm","clk":"5346824315","pt":1646098010135,"mc":[{"id":"1.195395456","rc":[{"atb":[[2.08,7.73]],"id":37672294}],"con":true,"img":false}]}
{"op":"mcm","clk":"5346824503","pt":1646098016043,"mc":[{"id":"1.195395456","rc":[{"atb":[[2.14,6.53]],"id":37672294}],"con":true,"img":false}]}
{"op":"mcm","clk":"5346824722","pt":1646098023696,"mc":[{"id":"1.195395456","rc":[{"atb":[[2.02,0]],"id":37672294},{"atl":[[2.94,0]],"id":28002629},{"atl":[[4.3,12.98],[2.74,18.86]],"id":42393370},{"atb":[[2.68,0]],"id":37267533},{"atb":[[3,0],[2.28,0],[1.94,39.12]],"id":37455733},{"atl":[[1.8,0],[2.3,0],[2.96,18.07]],"id":43154433}],"con":true,"img":false}]}
{"op":"mcm","clk":"5346824728","pt":1646098023798,"mc":[{"id":"1.195395456","rc":[{"atb":[[2.06,39]],"id":37672294},{"atl":[[3.45,21.57]],"id":28002629},{"atb":[[2.3,22.28]],"id":37267533},{"atb":[[2.48,20.28]],"id":37455733},{"atl":[[1.79,0],[1.84,81.12],[2.14,40.56]],"id":43154433}],"con":true,"img":false}]}
{"op":"mcm","clk":"5346824844","pt":1646098027798,"mc":[{"id":"1.195395456","rc":[{"atb":[[2.08,0]],"id":37672294}],"con":true,"img":false}]}
{"op":"mcm","clk":"5346824978","pt":1646098031695,"mc":[{"id":"1.195395456","rc":[{"atl":[[3.85,0],[3.4,21.57]],"id":28002629}],"con":true,"img":false}]}
{"op":"mcm","clk":"5346824992","pt":1646098032412,"mc":[{"id":"1.195395456","rc":[{"atb":[[2.16,39.01]],"id":37672294}],"con":true,"img":false}]}
{"op":"mcm","clk":"5346824994","pt":1646098032514,"mc":[{"id":"1.195395456","rc":[{"atb":[[2.1,0]],"id":37672294}],"con":true,"img":false}]}
{"op":"mcm","clk":"5346825034","pt":1646098034205,"mc":[{"id":"1.195395456","rc":[{"atb":[[2.14,0]],"id":37672294}],"con":true,"img":false}]}
{"op":"mcm","clk":"5346825144","pt":1646098037494,"mc":[{"id":"1.195395456","rc":[{"atb":[[2.16,0],[2.08,78.02]],"id":37672294}],"con":true,"img":false}]}
{"op":"mcm","clk":"5346825786","pt":1646098054520,"mc":[{"id":"1.195395456","rc":[{"atb":[[2.06,0]],"id":37672294},{"atl":[[3.45,0]],"id":28002629},{"atb":[[2.3,0]],"id":37267533},{"atb":[[2.48,0]],"id":37455733},{"atl":[[2.14,0]],"id":43154433}],"con":true,"img":false}]}
{"op":"mcm","clk":"5346825790","pt":1646098054624,"mc":[{"id":"1.195395456","rc":[{"atb":[[1.89,112.36],[2.1,39]],"id":37672294},{"atl":[[3.85,35.09],[3.1,21.57],[3.4,0]],"id":28002629},{"atb":[[2.66,22.28]],"id":37267533},{"atb":[[3,20.28]],"id":37455733},{"atl":[[1.8,40.56]],"id":43154433}],"con":true,"img":false}]}
{"op":"mcm","clk":"5346825794","pt":1646098054727,"mc":[{"id":"1.195395456","rc":[{"atb":[[2.08,0]],"id":37672294},{"atl":[[1.79,40.56],[1.84,0]],"id":43154433}],"con":true,"img":false}]}
{"op":"mcm","clk":"5346826062","pt":1646098061145,"mc":[{"id":"1.195395456","rc":[{"atb":[[2.14,6.53]],"id":37672294},{"atb":[[2.12,6.65]],"id":37267533}],"con":true,"img":false}]}
{"op":"mcm","clk":"5346826171","pt":1646098063671,"mc":[{"id":"1.195395456","rc":[{"atb":[[1.26,0],[1.24,308.3]],"id":42393370},{"atb":[[1.08,0],[1.07,769.36]],"id":43154433}],"con":true,"img":false}]}
{"op":"mcm","clk":"5346826403","pt":1646098069632,"mc":[{"id":"1.195395456","rc":[{"atl":[[3.8,13.13]],"id":28002629}],"con":true,"img":false}]}
{"op":"mcm","clk":"5346826408","pt":1646098069733,"mc":[{"id":"1.195395456","rc":[{"atl":[[5.1,0]],"id":28002629},{"atb":[[1.27,0]],"id":42393370}],"con":true,"img":false}]}
{"op":"mcm","clk":"5346826410","pt":1646098069837,"mc":[{"id":"1.195395456","rc":[{"atb":[[1.25,154.14]],"id":42393370}],"con":true,"img":false}]}
{"op":"mcm","clk":"5346826553","pt":1646098072828,"mc":[{"id":"1.195395456","rc":[{"atb":[[2.14,13.86]],"id":37672294}],"con":true,"img":false}]}
{"op":"mcm","clk":"5346826757","pt":1646098077550,"mc":[{"id":"1.195395456","rc":[{"atb":[[1.89,0],[2.16,39.01]],"id":37672294}],"con":true,"img":false}]}
{"op":"mcm","clk":"5346826766","pt":1646098077651,"mc":[{"id":"1.195395456","rc":[{"atl":[[3.85,0],[3.05,21.57]],"id":28002629}],"con":true,"img":false}]}
{"op":"mcm","clk":"5346826825","pt":1646098079243,"mc":[{"id":"1.195395456","rc":[{"atb":[[2.14,7.32]],"id":37672294}],"con":true,"img":false}]}
{"op":"mcm","clk":"5346827070","pt":1646098085052,"mc":[{"id":"1.195395456","rc":[{"atl":[[4.9,9.43]],"id":28002629}],"con":true,"img":false}]}
{"op":"mcm","clk":"5346827072","pt":1646098085154,"mc":[{"id":"1.195395456","rc":[{"atb":[[2.2,6.2]],"id":37672294},{"atl":[[3.1,0],[3.8,0]],"id":28002629},{"atb":[[2.66,0]],"id":37267533},{"atb":[[3,0]],"id":37455733},{"atl":[[1.8,0]],"id":43154433}],"con":true,"img":false}]}
{"op":"mcm","clk":"5346827075","pt":1646098085257,"mc":[{"id":"1.195395456","rc":[{"atl":[[3.45,21.57],[3.85,35.09],[3.05,0]],"id":28002629},{"atb":[[2.3,22.28]],"id":37267533},{"atb":[[2.48,20.28]],"id":37455733},{"atl":[[1.79,0],[1.87,81.12],[2.14,40.56]],"id":43154433}],"con":true,"img":false}]}
{"op":"mcm","clk":"5346827332","pt":1646098091791,"mc":[{"id":"1.195395456","rc":[{"atb":[[2.14,0]],"id":37672294}],"con":true,"img":false}]}
{"op":"mcm","clk":"5346827768","pt":1646098099973,"mc":[{"id":"1.195395456","rc":[{"atl":[[8.6,5.33]],"id":37455733}],"con":true,"img":false}]}
{"op":"mcm","clk":"5346827772","pt":1646098100075,"mc":[{"id":"1.195395456","rc":[{"atb":[[2.1,0]],"id":37672294},{"atl":[[6.2,0]],"id":37672294},{"atl":[[9.6,0]],"id":37267533},{"atl":[[15,0]],"id":37455733},{"atb":[[1.87,0]],"id":22150928}],"con":true,"img":false}]}
{"op":"mcm","clk":"5346827779","pt":1646098100178,"mc":[{"id":"1.195395456","rc":[{"atb":[[2.18,39]],"id":37672294},{"atl":[[7.2,7.05],[7.6,15.15],[5.9,8.63]],"id":37672294},{"atl":[[12,0],[7.8,5.79],[14,7.69]],"id":37267533},{"atb":[[1.92,40.56]],"id":22150928}],"con":true,"img":false}]}
{"op":"mcm","clk":"5346827782","pt":1646098100280,"mc":[{"id":"1.195395456","rc":[{"atb":[[2.22,39.01],[2.16,0]],"id":37672294}],"con":true,"img":false}]}
{"op":"mcm","clk":"5346827898","pt":1646098103303,"mc":[{"id":"1.195395456","rc":[{"atb":[[2.2,0]],"id":37672294},{"atb":[[1.91,0]],"id":22150928}],"con":true,"img":false}]}
{"op":"mcm","clk":"5346827900","pt":1646098103406,"mc":[{"id":"1.195395456","rc":[{"atb":[[2.22,0],[2.2,78.02]],"id":37672294}],"con":true,"img":false}]}
{"op":"mcm","clk":"5346828121","pt":1646098107976,"mc":[{"id":"1.195395456","rc":[{"atl":[[3.85,0],[3.4,21.57]],"id":28002629}],"con":true,"img":false}]}
{"op":"mcm","clk":"5346828391","pt":1646098115113,"mc":[{"id":"1.195395456","rc":[{"atb":[[1.72,0],[1.77,48.58]],"id":22150928},{"atb":[[1.05,0],[1.08,442.83]],"id":43154433}],"con":true,"img":false}]}
{"op":"mcm","clk":"5346828394","pt":1646098115216,"mc":[{"id":"1.195395456","rc":[{"atb":[[2.18,0]],"id":37672294},{"atl":[[7.2,0]],"id":37672294},{"atl":[[14.5,0]],"id":37267533},{"atb":[[1.92,0]],"id":22150928}],"con":true,"img":false}]}
{"op":"mcm","clk":"5346828401","pt":1646098115319,"mc":[{"id":"1.195395456","rc":[{"atb":[[1.83,120.48],[1.99,39]],"id":37672294},{"atl":[[7.4,7.05]],"id":37672294},{"atl":[[11.5,3.03]],"id":37267533},{"atb":[[1.84,40.56]],"id":22150928}],"con":true,"img":false}]}
{"op":"mcm","clk":"5346828404","pt":1646098115421,"mc":[{"id":"1.195395456","rc":[{"atb":[[2.2,0]],"id":37672294}],"con":true,"img":false}]}
{"op":"mcm","clk":"5346828837","pt":1646098130102,"mc":[{"id":"1.195395456","rc":[{"atl":[[22,0]],"id":37455733},{"atb":[[1.77,0]],"id":22150928}],"con":true,"img":false}]}
{"op":"mcm","clk":"5346828839","pt":1646098130205,"mc":[{"id":"1.195395456","rc":[{"atl":[[13,2.7]],"id":37455733},{"atb":[[1.72,48.58],[1.76,0]],"id":22150928}],"con":true,"img":false}]}
{"op":"mcm","clk":"5346829044","pt":1646098137641,"mc":[{"id":"1.195395456","rc":[{"atb":[[2,63.95],[1.83,0]],"id":37672294}],"con":true,"img":false}]}
{"op":"mcm","clk":"5346829298","pt":1646098145040,"mc":[{"id":"1.195395456","rc":[{"atl":[[3.45,0]],"id":28002629}],"con":true,"img":false}]}
{"op":"mcm","clk":"5346829301","pt":1646098145142,"mc":[{"id":"1.195395456","rc":[{"atl":[[3.85,35.09],[3.35,21.57],[3.4,0]],"id":28002629}],"con":true,"img":false}]}
{"op":"mcm","clk":"5346829987","pt":1646098167164,"mc":[{"id":"1.195395456","rc":[{"atl":[[3.85,0],[3.3,21.57]],"id":28002629}],"con":true,"img":false}]}
{"op":"mcm","clk":"5346830181","pt":1646098174096,"mc":[{"id":"1.195395456","rc":[{"atb":[[1.99,0]],"id":37672294}],"con":true,"img":false}]}
{"op":"mcm","clk":"5346830184","pt":1646098174199,"mc":[{"id":"1.195395456","rc":[{"atb":[[1.83,120.48],[2.02,39]],"id":37672294}],"con":true,"img":false}]}
{"op":"mcm","clk":"5346830187","pt":1646098174305,"mc":[{"id":"1.195395456","rc":[{"atb":[[2,0],[1.83,0],[2.04,63.95]],"id":37672294}],"con":true,"img":false}]}
{"op":"mcm","clk":"5346831025","pt":1646098203324,"mc":[{"id":"1.195395456","rc":[{"atl":[[3.35,0]],"id":28002629}],"con":true,"img":false}]}
{"op":"mcm","clk":"5346831027","pt":1646098203427,"mc":[{"id":"1.195395456","rc":[{"atl":[[3.85,35.09],[3.25,21.57],[3.3,0]],"id":28002629}],"con":true,"img":false}]}
{"op":"mcm","clk":"5346831034","pt":1646098203529,"mc":[{"id":"1.195395456","rc":[{"atl":[[3.2,21.57]],"id":28002629}],"con":true,"img":false}]}
{"op":"mcm","clk":"5346831041","pt":1646098203634,"mc":[{"id":"1.195395456","rc":[{"atl":[[3.85,0]],"id":28002629}],"con":true,"img":false}]}
{"op":"mcm","clk":"5346831466","pt":1646098217559,"mc":[{"id":"1.195395456","rc":[{"atb":[[2.02,0]],"id":37672294}],"con":true,"img":false}]}
{"op":"mcm","clk":"5346831470","pt":1646098217662,"mc":[{"id":"1.195395456","rc":[{"atb":[[1.83,120.48],[2.06,39],[2.04,0]],"id":37672294}],"con":true,"img":false}]}
{"op":"mcm","clk":"5346831475","pt":1646098217764,"mc":[{"id":"1.195395456","rc":[{"atb":[[2.08,63.95]],"id":37672294}],"con":true,"img":false}]}
{"op":"mcm","clk":"5346831478","pt":1646098217867,"mc":[{"id":"1.195395456","rc":[{"atb":[[1.83,0]],"id":37672294}],"con":true,"img":false}]}
{"op":"mcm","clk":"5346831910","pt":1646098232311,"mc":[{"id":"1.195395456","rc":[{"atl":[[11.5,0],[7.8,0]],"id":37267533},{"atl":[[13,0],[15,2.89]],"id":37455733}],"con":true,"img":false}]}
{"op":"mcm","clk":"5346831915","pt":1646098232413,"mc":[{"id":"1.195395456","rc":[{"atl":[[9.8,5.79],[13.5,3.03]],"id":37267533},{"atl":[[8.6,0],[23,2.7]],"id":37455733}],"con":true,"img":false}]}
{"op":"mcm","clk":"5346831919","pt":1646098232569,"mc":[{"id":"1.195395456","rc":[{"atl":[[13,8.33],[14,0]],"id":37267533}],"con":true,"img":false}]}
{"op":"mcm","clk":"5346832338","pt":1646098246922,"mc":[{"id":"1.195395456","rc":[{"atl":[[3.25,0]],"id":28002629},{"atb":[[2.3,0]],"id":37267533},{"atl":[[2.14,0]],"id":43154433}],"con":true,"img":false}]}
{"op":"mcm","clk":"5346832341","pt":1646098247024,"mc":[{"id":"1.195395456","rc":[{"atl":[[3.85,35.09],[3.15,21.57]],"id":28002629},{"atb":[[2.68,22.28]],"id":37267533},{"atl":[[1.81,40.56]],"id":43154433}],"con":true,"img":false}]}
{"op":"mcm","clk":"5346832346","pt":1646098247127,"mc":[{"id":"1.195395456","rc":[{"atl":[[3.2,0]],"id":28002629}],"con":true,"img":false}]}
{"op":"mcm","clk":"5346832351","pt":1646098247230,"mc":[{"id":"1.195395456","rc":[{"atl":[[1.8,40.56],[1.87,0]],"id":43154433}],"con":true,"img":false}]}
{"op":"mcm","clk":"5346832365","pt":1646098247640,"mc":[{"id":"1.195395456","rc":[{"atb":[[2.12,0]],"id":37267533}],"con":true,"img":false}]}
{"op":"mcm","clk":"5346832719","pt":1646098260358,"mc":[{"id":"1.195395456","rc":[{"atb":[[2.06,0]],"id":37672294},{"atl":[[3.15,0]],"id":28002629},{"atb":[[2.68,0]],"id":37267533},{"atl":[[1.81,0]],"id":43154433}],"con":true,"img":false}]}
{"op":"mcm","clk":"5346832722","pt":1646098260460,"mc":[{"id":"1.195395456","rc":[{"atb":[[1.83,120.48],[2.1,39],[2.08,0]],"id":37672294},{"atl":[[3.45,21.57]],"id":28002629},{"atb":[[2.3,22.28]],"id":37267533},{"atl":[[1.8,0],[1.87,81.12],[2.16,40.56]],"id":43154433}],"con":true,"img":false}]}
{"op":"mcm","clk":"5346832984","pt":1646098268166,"mc":[{"id":"1.195395456","rc":[{"atl":[[3.85,0],[3.4,21.57]],"id":28002629}],"con":true,"img":false}]}
{"op":"mcm","clk":"5346833215","pt":1646098274749,"mc":[{"id":"1.195395456","rc":[{"atb":[[2.1,0]],"id":37672294},{"atl":[[3.35,15.65],[4.9,0]],"id":28002629}],"con":true,"img":false}]}
{"op":"mcm","clk":"5346833217","pt":1646098274852,"mc":[{"id":"1.195395456","rc":[{"atb":[[2,39]],"id":37672294}],"con":true,"img":false}]}
{"op":"mcm","clk":"5346833411","pt":1646098281370,"mc":[{"id":"1.195395456","rc":[{"atb":[[1.83,0],[2.02,63.95]],"id":37672294}],"con":true,"img":false}]}
{"op":"mcm","clk":"5346833622","pt":1646098288802,"mc":[{"id":"1.195395456","rc":[{"atl":[[3.45,0]],"id":28002629},{"atl":[[13.5,0]],"id":37267533},{"atl":[[2.16,0]],"id":43154433}],"con":true,"img":false}]}
{"op":"mcm","clk":"5346833627","pt":1646098288904,"mc":[{"id":"1.195395456","rc":[{"atl":[[3.15,21.57]],"id":28002629},{"atl":[[12.5,3.03]],"id":37267533},{"atl":[[1.81,40.56]],"id":43154433}],"con":true,"img":false}]}
{"op":"mcm","clk":"5346833633","pt":1646098289006,"mc":[{"id":"1.195395456","rc":[{"atl":[[3.4,0],[3.3,18.61]],"id":28002629},{"atl":[[1.8,40.56]],"id":43154433}],"con":true,"img":false}]}
{"op":"mcm","clk":"5346833640","pt":1646098289110,"mc":[{"id":"1.195395456","rc":[{"atl":[[3.1,21.57],[3.3,0]],"id":28002629},{"atl":[[1.87,0]],"id":43154433}],"con":true,"img":false}]}
{"op":"mcm","clk":"5346834099","pt":1646098302907,"mc":[{"id":"1.195395456","rc":[{"atl":[[4.4,10.81]],"id":28002629},{"atb":[[2.3,0]],"id":37267533},{"atb":[[2.48,0]],"id":37455733}],"con":true,"img":false}]}
{"op":"mcm","clk":"5346834105","pt":1646098303007,"mc":[{"id":"1.195395456","rc":[{"atl":[[3.35,0]],"id":28002629},{"atb":[[1.26,231.23],[1.24,0]],"id":42393370},{"atb":[[2.66,22.28]],"id":37267533},{"atl":[[12.5,11.73],[13,0]],"id":37267533},{"atb":[[3,20.28]],"id":37455733},{"atb":[[1.08,1048.93],[1.07,0]],"id":43154433}],"con":true,"img":false}]}
{"op":"mcm","clk":"5346834631","pt":1646098317111,"mc":[{"id":"1.195395456","rc":[{"atb":[[2,0]],"id":37672294},{"atb":[[2.66,0]],"id":37267533},{"atb":[[3,0]],"id":37455733},{"atl":[[1.81,0]],"id":43154433}],"con":true,"img":false}]}
{"op":"mcm","clk":"5346834635","pt":1646098317214,"mc":[{"id":"1.195395456","rc":[{"atb":[[2.02,0],[2.04,39],[1.9,111.11]],"id":37672294},{"atb":[[2.32,22.28]],"id":37267533},{"atb":[[2.48,20.28]],"id":37455733},{"atl":[[1.8,0],[1.83,81.12],[2.14,40.56]],"id":43154433}],"con":true,"img":false}]}
{"op":"mcm","clk":"5346835132","pt":1646098331120,"mc":[{"id":"1.195395456","rc":[{"atl":[[3.15,0]],"id":28002629}],"con":true,"img":false}]}
{"op":"mcm","clk":"5346835135","pt":1646098331223,"mc":[{"id":"1.195395456","rc":[{"atl":[[3.85,35.09],[3.1,0],[3.05,21.57]],"id":28002629}],"con":true,"img":false}]}
{"op":"mcm","clk":"5346835383","pt":1646098337540,"mc":[{"id":"1.195395456","rc":[{"atb":[[2.06,63.95]],"id":37672294}],"con":true,"img":false}]}
{"op":"mcm","clk":"5346835386","pt":1646098337639,"mc":[{"id":"1.195395456","rc":[{"atb":[[1.9,0]],"id":37672294}],"con":true,"img":false}]}
{"op":"mcm","clk":"5346835655","pt":1646098344849,"mc":[{"id":"1.195395456","rc":[{"atb":[[2.04,0]],"id":37672294},{"atl":[[3.05,0]],"id":28002629}],"con":true,"img":false}]}
{"op":"mcm","clk":"5346835663","pt":1646098344953,"mc":[{"id":"1.195395456","rc":[{"atb":[[1.92,39],[1.9,111.11]],"id":37672294},{"atl":[[3.45,21.57]],"id":28002629}],"con":true,"img":false}]}
{"op":"mcm","clk":"5346835667","pt":1646098345055,"mc":[{"id":"1.195395456","rc":[{"atb":[[2.06,0]],"id":37672294}],"con":true,"img":false}]}
{"op":"mcm","clk":"5346835928","pt":1646098351466,"mc":[{"id":"1.195395456","rc":[{"atl":[[3.85,0],[3.4,21.57]],"id":28002629}],"con":true,"img":false}]}
{"op":"mcm","clk":"5346836187","pt":1646098358188,"mc":[{"id":"1.195395456","rc":[{"atb":[[1.25,0]],"id":42393370}],"con":true,"img":false}]}
{"op":"mcm","clk":"5346836193","pt":1646098358290,"mc":[{"id":"1.195395456","rc":[{"atb":[[1.27,154.14]],"id":42393370}],"con":true,"img":false}]}
{"op":"mcm","clk":"5346836246","pt":1646098359576,"mc":[{"id":"1.195395456","rc":[{"atl":[[7.6,0],[7,16.67]],"id":37672294},{"atb":[[1.27,346.83],[1.26,0]],"id":42393370},{"atl":[[9.8,14.55],[12.5,3.03]],"id":37267533},{"atl":[[26,4],[55,0]],"id":37455733},{"atb":[[1.1,544.74],[1.08,442.83]],"id":43154433},{"atl":[[1.83,0],[2.12,89.29]],"id":43154433}],"con":true,"img":false}]}
{"op":"mcm","clk":"5346836460","pt":1646098364967,"mc":[{"id":"1.195395456","rc":[{"atb":[[1.93,63.95]],"id":37672294}],"con":true,"img":false}]}
{"op":"mcm","clk":"5346836466","pt":1646098365067,"mc":[{"id":"1.195395456","rc":[{"atb":[[1.9,0]],"id":37672294}],"con":true,"img":false}]}
{"op":"mcm","clk":"5346836731","pt":1646098372104,"mc":[{"id":"1.195395456","rc":[{"atl":[[8.6,5.33]],"id":37455733},{"atb":[[1.05,708.52]],"id":43154433}],"con":true,"img":false}]}
{"op":"mcm","clk":"5346836734","pt":1646098372206,"mc":[{"id":"1.195395456","rc":[{"atl":[[9.8,8.76]],"id":37267533}],"con":true,"img":false}]}
{"op":"mcm","clk":"5346836739","pt":1646098372309,"mc":[{"id":"1.195395456","rc":[{"atl":[[12,9.09],[9.8,0],[7.8,5.79]],"id":37267533},{"atl":[[15,0]],"id":37455733},{"atb":[[1.08,0]],"id":43154433}],"con":true,"img":false}]}
{"op":"mcm","clk":"5346836746","pt":1646098372516,"mc":[{"id":"1.195395456","rc":[{"atb":[[1.28,346.84],[1.27,154.14]],"id":42393370}],"con":true,"img":false}]}
{"op":"mcm","clk":"5346836911","pt":1646098376999,"mc":[{"id":"1.195395456","rc":[{"atl":[[6.8,17.24],[7,0]],"id":37672294},{"atl":[[2.12,0],[2.1,40.56]],"id":43154433}],"con":true,"img":false}]}
{"op":"mcm","clk":"5346837254","pt":1646098385785,"mc":[{"id":"1.195395456","rc":[{"atl":[[13,3.38]],"id":37455733}],"con":true,"img":false}]}
{"op":"mcm","clk":"5346837258","pt":1646098385889,"mc":[{"id":"1.195395456","rc":[{"atl":[[3.45,0]],"id":28002629},{"atl":[[7.8,0]],"id":37267533},{"atl":[[8.6,0]],"id":37455733},{"atl":[[2.14,0]],"id":43154433}],"con":true,"img":false}]}
{"op":"mcm","clk":"5346837260","pt":1646098385993,"mc":[{"id":"1.195395456","rc":[{"atl":[[3.2,21.57],[3.85,35.09],[3.4,0]],"id":28002629},{"atl":[[9.8,5.79]],"id":37267533},{"atl":[[1.84,40.56]],"id":43154433}],"con":true,"img":false}]}
{"op":"mcm","clk":"5346837268","pt":1646098386101,"mc":[{"id":"1.195395456","rc":[{"atl":[[1.83,40.56]],"id":43154433}],"con":true,"img":false}]}
{"op":"mcm","clk":"5346837270","pt":1646098386198,"mc":[{"id":"1.195395456","rc":[{"atl":[[3.15,21.57]],"id":28002629},{"atl":[[2.1,0]],"id":43154433}],"con":true,"img":false}]}
{"op":"mcm","clk":"5346837276","pt":1646098386297,"mc":[{"id":"1.195395456","rc":[{"atl":[[3.85,0]],"id":28002629}],"con":true,"img":false}]}
{"op":"mcm","clk":"5346837330","pt":1646098387425,"mc":[{"id":"1.195395456","rc":[{"atl":[[2.72,18.87],[2.76,0]],"id":42393370},{"atb":[[1.26,75.96],[1.35,0]],"id":37267533},{"atb":[[1.44,0],[1.71,59.41]],"id":37455733},{"atb":[[1.85,48.59],[1.71,0]],"id":22150928}],"con":true,"img":false}]}
{"op":"mcm","clk":"5346837529","pt":1646098392140,"mc":[{"id":"1.195395456","rc":[{"atl":[[10,11.11],[12,0]],"id":37267533}],"con":true,"img":false}]}
{"op":"mcm","clk":"5346837541","pt":1646098392300,"mc":[{"id":"1.195395456","rc":[{"atb":[[1.28,0],[1.31,154.15]],"id":42393370}],"con":true,"img":false}]}
{"op":"mcm","clk":"5346837787","pt":1646098399643,"mc":[{"id":"1.195395456","rc":[{"atb":[[1.2,215.8],[1.27,0]],"id":42393370}],"con":true,"img":false}]}
{"op":"mcm","clk":"5346837794","pt":1646098399801,"mc":[{"id":"1.195395456","rc":[{"atb":[[1.92,0]],"id":37672294}],"con":true,"img":false}]}
{"op":"mcm","clk":"5346837799","pt":1646098399905,"mc":[{"id":"1.195395456","rc":[{"atb":[[2,39],[1.86,116.28],[1.93,0]],"id":37672294}],"con":true,"img":false}]}
{"op":"mcm","clk":"5346838239","pt":1646098412968,"mc":[{"id":"1.195395456","rc":[{"atl":[[7.4,0]],"id":37672294},{"atb":[[2.32,0]],"id":37267533},{"atl":[[9.8,0]],"id":37267533},{"atb":[[2.48,0]],"id":37455733},{"atl":[[1.84,0]],"id":43154433}],"con":true,"img":false}]}
{"op":"mcm","clk":"5346838242","pt":1646098413025,"mc":[{"id":"1.195395456","rc":[{"atl":[[6.6,7.05]],"id":37672294},{"atb":[[2.6,22.28]],"id":37267533},{"atl":[[9.4,5.79]],"id":37267533},{"atb":[[3,20.28]],"id":37455733},{"atl":[[1.82,40.56]],"id":43154433}],"con":true,"img":false}]}
{"op":"mcm","clk":"5346838246","pt":1646098413131,"mc":[{"id":"1.195395456","rc":[{"atl":[[10,0],[12,9.09]],"id":37267533},{"atl":[[1.83,0],[2.1,81.12]],"id":43154433}],"con":true,"img":false}]}
{"op":"mcm","clk":"5346838442","pt":1646098418674,"mc":[{"id":"1.195395456","rc":[{"atl":[[6.8,0],[7,16.67]],"id":37672294}],"con":true,"img":false}]}
{"op":"mcm","clk":"5346838470","pt":1646098419438,"mc":[{"id":"1.195395456","rc":[{"atb":[[2.02,63.95],[1.86,0]],"id":37672294}],"con":true,"img":false}]}
{"op":"mcm","clk":"5346838769","pt":1646098426259,"mc":[{"id":"1.195395456","rc":[{"atl":[[11.5,3.9]],"id":37267533}],"con":true,"img":false}]}
{"op":"mcm","clk":"5346838773","pt":1646098426359,"mc":[{"id":"1.195395456","rc":[{"atl":[[6.6,0]],"id":37672294},{"atl":[[2.74,0]],"id":42393370},{"atl":[[12.5,0]],"id":37267533},{"atb":[[1.84,0]],"id":22150928}],"con":true,"img":false}]}
{"op":"mcm","clk":"5346838776","pt":1646098426462,"mc":[{"id":"1.195395456","rc":[{"atl":[[6.8,7.05]],"id":37672294},{"atl":[[3.2,0]],"id":28002629},{"atb":[[1.3,0]],"id":42393370},{"atl":[[3.75,36.36],[2.7,18.86]],"id":42393370},{"atb":[[1.73,97.18],[1.86,40.56]],"id":22150928}],"con":true,"img":false}]}
{"op":"mcm","clk":"5346838781","pt":1646098426565,"mc":[{"id":"1.195395456","rc":[{"atl":[[4.3,30.3],[3.1,21.57]],"id":28002629},{"atb":[[1.21,308.3],[1.32,40.56],[1.31,0]],"id":42393370},{"atl":[[2.72,0]],"id":42393370},{"atb":[[1.85,0]],"id":22150928}],"con":true,"img":false}]}
{"op":"mcm","clk":"5346838784","pt":1646098426667,"mc":[{"id":"1.195395456","rc":[{"atl":[[3.15,0]],"id":28002629}],"con":true,"img":false}]}
{"op":"mcm","clk":"5346838823","pt":1646098427853,"mc":[{"id":"1.195395456","rc":[{"atb":[[2.06,7.02]],"id":37672294},{"atb":[[2.12,6.65]],"id":37267533}],"con":true,"img":false}]}
{"op":"mcm","clk":"5346838828","pt":1646098427954,"mc":[{"id":"1.195395456","rc":[{"atb":[[2.02,0],[2.08,39.01]],"id":37672294}],"con":true,"img":false}]}
{"op":"mcm","clk":"5346838970","pt":1646098430978,"mc":[{"id":"1.195395456","rc":[{"atb":[[2.06,0]],"id":37672294}],"con":true,"img":false}]}
{"op":"mcm","clk":"5346839033","pt":1646098432570,"mc":[{"id":"1.195395456","rc":[{"atl":[[12,0],[9.8,11.36]],"id":37267533},{"atl":[[1.81,40.56],[2.1,0]],"id":43154433}],"con":true,"img":false}]}
{"op":"mcm","clk":"5346839057","pt":1646098433184,"mc":[{"id":"1.195395456","rc":[{"atb":[[2.02,78.02],[2.08,0]],"id":37672294}],"con":true,"img":false}]}
{"op":"mcm","clk":"5346839091","pt":1646098434056,"mc":[{"id":"1.195395456","rc":[{"atb":[[1.9,8.27]],"id":22150928}],"con":true,"img":false}]}
{"op":"mcm","clk":"5346839297","pt":1646098439091,"mc":[{"id":"1.195395456","rc":[{"atb":[[2.06,7.02]],"id":37672294}],"con":true,"img":false}]}
{"op":"mcm","clk":"5346839399","pt":1646098441501,"mc":[{"id":"1.195395456","rc":[{"atb":[[1.99,75.76],[2.02,127.04],[2.06,25.89],[1.97,128.87]],"id":37672294},{"atl":[[4.5,5.71],[5.1,30.49],[4.9,19.23],[4.7,13.51]],"id":37672294},{"atb":[[1.36,138.89],[1.32,250],[1.34,220.59],[1.38,52.63]],"id":28002629},{"atl":[[2.86,10.75],[2.9,26.32],[2.98,63.13],[2.94,38.66]],"id":28002629},{"atb":[[1.28,178.57],[1.26,250],[1.3,66.67],[1.24,250]],"id":42393370},{"atl":[[2.54,81.17],[2.5,50],[2.42,14.08],[2.46,34.25]],"id":42393370},{"atb":[[1.36,55.56],[1.32,234.37],[1.3,250],[1.34,147.06]],"id":37267533},{"atl":[[5.6,4.35],[6.4,23.15],[5.8,10.42],[6,15]],"id":37267533},{"atb":[[1.79,63.29],[1.81,24.69],[1.77,97.4],[1.75,166.67]],"id":37455733},{"atl":[[11,2],[12,4.55],[13,9.63],[14,9.62]],"id":37455733},{"atb":[[1.92,81.52],[1.9,147.16],[1.96,20.83],[1.94,53.19]],"id":22150928},{"atl":[[3.6,28.85],[3.7,46.3],[3.4,8.33],[3.5,20]],"id":22150928},{"atb":[[1.02,250],[1.06,250],[1.08,250],[1.04,250]],"id":43154433},{"atl":[[1.56,89.29],[1.6,208.33],[1.58,129.31],[1.54,37.04]],"id":43154433}],"con":true,"img":false}]}
{"op":"mcm","clk":"5346839407","pt":1646098441707,"mc":[{"id":"1.195395456","rc":[{"atl":[[5.4,9.22],[4.7,11.75]],"id":22150928},{"atl":[[1.81,0],[1.65,40.56]],"id":43154433}],"con":true,"img":false}]}
{"op":"mcm","clk":"5346839426","pt":1646098442071,"mc":[{"id":"1.195395456","rc":[{"atb":[[1.9,138.89]],"id":22150928}],"con":true,"img":false}]}
{"op":"mcm","clk":"5346839433","pt":1646098442174,"mc":[{"id":"1.195395456","rc":[{"atl":[[9,5.11]],"id":37672294},{"atb":[[1.32,0]],"id":42393370},{"atl":[[14.5,3.03]],"id":37267533},{"atb":[[2.28,28.73]],"id":37455733},{"atb":[[1.72,0]],"id":22150928},{"atl":[[2.42,24.94]],"id":43154433}],"con":true,"img":false}]}
{"op":"mcm","clk":"5346839438","pt":1646098442275,"mc":[{"id":"1.195395456","rc":[{"atl":[[6.8,0]],"id":37672294},{"atb":[[1.3,107.23]],"id":42393370},{"atl":[[11.5,0]],"id":37267533},{"atb":[[1.94,0]],"id":37455733},{"atb":[[1.74,48.58]],"id":22150928},{"atl":[[2.96,0]],"id":43154433}],"con":true,"img":false}]}
{"op":"mcm","clk":"5346839610","pt":1646098445766,"mc":[{"id":"1.195395456","rc":[{"atl":[[2.5,100],[3.75,0]],"id":42393370},{"atb":[[1.73,0],[1.89,112.36]],"id":22150928}],"con":true,"img":false}]}
{"op":"mcm","clk":"5346839615","pt":1646098445868,"mc":[{"id":"1.195395456","rc":[{"atl":[[4.3,0],[2.94,77.32]],"id":28002629},{"atb":[[1.21,0],[1.31,178.57]],"id":42393370}],"con":true,"img":false}]}
{"op":"mcm","clk":"5346839711","pt":1646098448076,"mc":[{"id":"1.195395456","rc":[{"atb":[[1.41,18.17]],"id":28002629},{"atb":[[1.98,7.59]],"id":22150928}],"con":true,"img":false}]}
{"op":"mcm","clk":"5346839767","pt":1646098449206,"mc":[{"id":"1.195395456","rc":[{"atb":[[2.06,33.77]],"id":37672294}],"con":true,"img":false}]}
{"op":"mcm","clk":"5346839894","pt":1646098452182,"mc":[{"id":"1.195395456","rc":[{"atb":[[1.51,73.35]],"id":22150928}],"con":true,"img":false}]}
{"op":"mcm","clk":"5346839899","pt":1646098452281,"mc":[{"id":"1.195395456","rc":[{"atb":[[2,0]],"id":37672294},{"atb":[[1.74,0]],"id":22150928},{"atl":[[5.4,0]],"id":22150928}],"con":true,"img":false}]}
{"op":"mcm","clk":"5346839903","pt":1646098452387,"mc":[{"id":"1.195395456","rc":[{"atb":[[2.02,49.02],[2.04,39],[2.08,39.01]],"id":37672294},{"atl":[[4.9,9.22]],"id":22150928}],"con":true,"img":false}]}
{"op":"mcm","clk":"5346839989","pt":1646098454183,"mc":[{"id":"1.195395456","rc":[{"atb":[[2.06,26.74]],"id":37672294}],"con":true,"img":false}]}
{"op":"mcm","clk":"5346840051","pt":1646098455617,"mc":[{"id":"1.195395456","rc":[{"atb":[[1.39,61.98]],"id":28002629}],"con":true,"img":false}]}
{"op":"mcm","clk":"5346840065","pt":1646098455980,"mc":[{"id":"1.195395456","rc":[{"atb":[[1.98,16.12]],"id":22150928}],"con":true,"img":false}]}
{"op":"mcm","clk":"5346840124","pt":1646098457113,"mc":[{"id":"1.195395456","rc":[{"atb":[[1.41,0]],"id":28002629}],"con":true,"img":false}]}
{"op":"mcm","clk":"5346840275","pt":1646098460129,"mc":[{"id":"1.195395456","rc":[{"atb":[[2.12,6.65]],"id":37672294}],"con":true,"img":false}]}
{"op":"mcm","clk":"5346840374","pt":1646098462334,"mc":[{"id":"1.195395456","rc":[{"atl":[[9.4,0]],"id":37267533},{"atl":[[1.82,0]],"id":43154433}],"con":true,"img":false}]}
{"op":"mcm","clk":"5346840379","pt":1646098462437,"mc":[{"id":"1.195395456","rc":[{"atl":[[8.8,5.79]],"id":37267533},{"atl":[[1.76,40.56]],"id":43154433}],"con":true,"img":false}]}
{"op":"mcm","clk":"5346840408","pt":1646098463113,"mc":[{"id":"1.195395456","rc":[{"atb":[[1.42,17.73]],"id":28002629}],"con":true,"img":false}]}
{"op":"mcm","clk":"5346840599","pt":1646098467235,"mc":[{"id":"1.195395456","rc":[{"atb":[[2.06,18.87]],"id":37672294}],"con":true,"img":false}]}
{"op":"mcm","clk":"5346840763","pt":1646098471445,"mc":[{"id":"1.195395456","rc":[{"atb":[[2.14,18.87],[2.08,0]],"id":37672294}],"con":true,"img":false}]}
{"op":"mcm","clk":"5346840792","pt":1646098472116,"mc":[{"id":"1.195395456","rc":[{"atb":[[2.12,0]],"id":37672294}],"con":true,"img":false}]}
{"op":"mcm","clk":"5346840796","pt":1646098472217,"mc":[{"id":"1.195395456","rc":[{"atb":[[2,40.92]],"id":37672294},{"atl":[[5.9,0]],"id":37672294},{"atb":[[1.37,99.39]],"id":28002629},{"atl":[[3.1,0]],"id":28002629},{"atb":[[1.3,66.67],[1.29,148.73]],"id":42393370},{"atl":[[2.48,27.41]],"id":42393370},{"atb":[[1.86,0]],"id":22150928},{"atb":[[1.07,506.09]],"id":43154433}],"con":true,"img":false}]}
{"op":"mcm","clk":"5346840800","pt":1646098472320,"mc":[{"id":"1.195395456","rc":[{"atb":[[1.64,0]],"id":37672294},{"atl":[[5,8.63]],"id":37672294},{"atb":[[1.25,0]],"id":28002629},{"atl":[[2.92,21.57]],"id":28002629},{"atb":[[1.2,0],[1.3,400],[1.32,40.56]],"id":42393370},{"atl":[[2.7,0]],"id":42393370},{"atb":[[1.95,40.56]],"id":22150928},{"atb":[[1.05,0]],"id":43154433}],"con":true,"img":false}]}
{"op":"mcm","clk":"5346840803","pt":1646098472421,"mc":[{"id":"1.195395456","rc":[{"atl":[[2.9,52.64]],"id":28002629},{"atb":[[1.31,0]],"id":42393370}],"con":true,"img":false}]}
{"op":"mcm","clk":"5346840807","pt":1646098472524,"mc":[{"id":"1.195395456","rc":[{"atl":[[2.94,38.66]],"id":28002629}],"con":true,"img":false}]}
{"op":"mcm","clk":"5346840924","pt":1646098475150,"mc":[{"id":"1.195395456","rc":[{"atb":[[1.98,8.52]],"id":22150928}],"con":true,"img":false}]}
{"op":"mcm","clk":"5346840987","pt":1646098476634,"mc":[{"id":"1.195395456","rc":[{"atb":[[2.06,57.88],[2.14,0]],"id":37672294}],"con":true,"img":false}]}
{"op":"mcm","clk":"5346841167","pt":1646098481148,"mc":[{"id":"1.195395456","rc":[{"atb":[[1.99,7.52]],"id":22150928}],"con":true,"img":false}]}
{"op":"mcm","clk":"5346841221","pt":1646098482332,"mc":[{"id":"1.195395456","rc":[{"atb":[[2,0]],"id":37672294},{"atb":[[1.32,0]],"id":42393370}],"con":true,"img":false}]}
{"op":"mcm","clk":"5346841227","pt":1646098482435,"mc":[{"id":"1.195395456","rc":[{"atb":[[1.98,40.92]],"id":37672294},{"atb":[[1.31,40.56]],"id":42393370}],"con":true,"img":false}]}
{"op":"mcm","clk":"5346841294","pt":1646098484335,"mc":[{"id":"1.195395456","rc":[{"atb":[[2.1,6.77]],"id":37672294}],"con":true,"img":false}]}
{"op":"mcm","clk":"5346841327","pt":1646098485250,"mc":[{"id":"1.195395456","rc":[{"atb":[[1.39,40.56]],"id":28002629}],"con":true,"img":false}]}
{"op":"mcm","clk":"5346841399","pt":1646098487155,"mc":[{"id":"1.195395456","rc":[{"atb":[[1.42,0]],"id":28002629}],"con":true,"img":false}]}
{"op":"mcm","clk":"5346841561","pt":1646098491161,"mc":[{"id":"1.195395456","rc":[{"atb":[[1.3,66.67],[1.32,148.74]],"id":42393370}],"con":true,"img":false}]}
{"op":"mcm","clk":"5346841566","pt":1646098491265,"mc":[{"id":"1.195395456","rc":[{"atb":[[2.1,14.36]],"id":37672294}],"con":true,"img":false}]}
{"op":"mcm","clk":"5346841577","pt":1646098491470,"mc":[{"id":"1.195395456","rc":[{"atb":[[1.4,20.88]],"id":28002629}],"con":true,"img":false}]}
{"op":"mcm","clk":"5346841670","pt":1646098494049,"mc":[{"id":"1.195395456","rc":[{"atb":[[1.41,18.17]],"id":28002629}],"con":true,"img":false}]}
{"op":"mcm","clk":"5346841715","pt":1646098495348,"mc":[{"id":"1.195395456","rc":[{"atb":[[2.06,18.87],[2.12,39.01]],"id":37672294}],"con":true,"img":false}]}
{"op":"mcm","clk":"5346841782","pt":1646098497182,"mc":[{"id":"1.195395456","rc":[{"atb":[[2.1,7.59]],"id":37672294}],"con":true,"img":false}]}
{"op":"mcm","clk":"5346841977","pt":1646098502172,"mc":[{"id":"1.195395456","rc":[{"atb":[[2.04,0]],"id":37672294},{"atl":[[2.92,0]],"id":28002629},{"atl":[[2.48,0]],"id":42393370},{"atl":[[8.8,0]],"id":37267533},{"atb":[[1.07,708.52]],"id":43154433}],"con":true,"img":false}]}
{"op":"mcm","clk":"5346841982","pt":1646098502275,"mc":[{"id":"1.195395456","rc":[{"atb":[[2.08,39]],"id":37672294},{"atl":[[2.88,21.57],[2.9,26.32],[2.94,90.21]],"id":28002629},{"atl":[[2.44,27.41]],"id":42393370},{"atl":[[8.4,5.79]],"id":37267533}],"con":true,"img":false}]}
{"op":"mcm","clk":"5346842007","pt":1646098503152,"mc":[{"id":"1.195395456","rc":[{"atb":[[2.16,6.42]],"id":37672294}],"con":true,"img":false}]}
{"op":"mcm","clk":"5346842205","pt":1646098509470,"mc":[{"id":"1.195395456","rc":[{"atb":[[2.1,0]],"id":37672294}],"con":true,"img":false}]}
{"op":"mcm","clk":"5346842318","pt":1646098512290,"mc":[{"id":"1.195395456","rc":[{"atl":[[2.88,0]],"id":28002629},{"atb":[[1.31,0]],"id":42393370}],"con":true,"img":false}]}
{"op":"mcm","clk":"5346842321","pt":1646098512392,"mc":[{"id":"1.195395456","rc":[{"atl":[[2.92,21.57]],"id":28002629},{"atb":[[1.32,0],[1.3,364.15],[1.33,40.56]],"id":42393370}],"con":true,"img":false}]}
{"op":"mcm","clk":"5346842369","pt":1646098513984,"mc":[{"id":"1.195395456","rc":[{"atb":[[2.12,0],[2.18,39.01]],"id":37672294}],"con":true,"img":false}]}
{"op":"mcm","clk":"5346842383","pt":1646098514293,"mc":[{"id":"1.195395456","rc":[{"atb":[[2.16,0]],"id":37672294}],"con":true,"img":false}]}
{"op":"mcm","clk":"5346842498","pt":1646098517173,"mc":[{"id":"1.195395456","rc":[{"atl":[[2.5,50],[2.42,41.49]],"id":42393370},{"atl":[[8.6,13.16],[9.8,0]],"id":37267533},{"atl":[[4.2,31.25],[4.7,0]],"id":22150928},{"atl":[[1.58,258.62],[1.65,0]],"id":43154433}],"con":true,"img":false}]}
{"op":"mcm","clk":"5346842562","pt":1646098519075,"mc":[{"id":"1.195395456","rc":[{"atb":[[2.1,78.02]],"id":37672294}],"con":true,"img":false}]}
{"op":"mcm","clk":"5346842565","pt":1646098519175,"mc":[{"id":"1.195395456","rc":[{"atb":[[2.18,0]],"id":37672294}],"con":true,"img":false}]}
{"op":"mcm","clk":"5346842604","pt":1646098520405,"mc":[{"id":"1.195395456","rc":[{"atl":[[2.44,0]],"id":42393370}],"con":true,"img":false}]}
{"op":"mcm","clk":"5346842607","pt":1646098520509,"mc":[{"id":"1.195395456","rc":[{"atl":[[2.5,116.67],[2.42,14.08],[2.48,27.41]],"id":42393370}],"con":true,"img":false}]}
{"op":"mcm","clk":"5346842619","pt":1646098520666,"mc":[{"id":"1.195395456","rc":[{"atl":[[2.5,50],[2.46,68.5]],"id":42393370}],"con":true,"img":false}]}
{"op":"mcm","clk":"5346842623","pt":1646098520770,"mc":[{"id":"1.195395456","rc":[{"atl":[[2.9,52.64],[2.94,38.66]],"id":28002629}],"con":true,"img":false}]}
{"op":"mcm","clk":"5346842670","pt":1646098522305,"mc":[{"id":"1.195395456","rc":[{"atb":[[2.08,0]],"id":37672294}],"con":true,"img":false}]}
{"op":"mcm","clk":"5346842673","pt":1646098522408,"mc":[{"id":"1.195395456","rc":[{"atb":[[2.02,145.91],[2.12,39]],"id":37672294}],"con":true,"img":false}]}
{"op":"mcm","clk":"5346842678","pt":1646098522509,"mc":[{"id":"1.195395456","rc":[{"atb":[[2.1,0]],"id":37672294}],"con":true,"img":false}]}
{"op":"mcm","clk":"5346842791","pt":1646098525902,"mc":[{"id":"1.195395456","rc":[{"atl":[[2.5,104.82],[2.46,34.25]],"id":42393370},{"atl":[[8.6,0],[9.8,11.36]],"id":37267533},{"atl":[[1.58,129.31],[1.65,153.85]],"id":43154433}],"con":true,"img":false}]}
{"op":"mcm","clk":"5346842928","pt":1646098529198,"mc":[{"id":"1.195395456","rc":[{"atb":[[2.16,6.42]],"id":37672294}],"con":true,"img":false}]}
{"op":"mcm","clk":"5346842992","pt":1646098530799,"mc":[{"id":"1.195395456","rc":[{"atb":[[1.3,66.67],[1.32,178.57]],"id":42393370}],"con":true,"img":false}]}
{"op":"mcm","clk":"5346843057","pt":1646098532292,"mc":[{"id":"1.195395456","rc":[{"atb":[[1.98,0]],"id":37672294},{"atb":[[1.33,0]],"id":42393370}],"con":true,"img":false}]}
{"op":"mcm","clk":"5346843062","pt":1646098532391,"mc":[{"id":"1.195395456","rc":[{"atb":[[2,40.92]],"id":37672294},{"atb":[[1.31,40.56]],"id":42393370}],"con":true,"img":false}]}
{"op":"mcm","clk":"5346843328","pt":1646098539528,"mc":[{"id":"1.195395456","rc":[{"atb":[[2.16,13.62]],"id":37672294}],"con":true,"img":false}]}
{"op":"mcm","clk":"5346843375","pt":1646098540706,"mc":[{"id":"1.195395456","rc":[{"atb":[[2.02,49.02],[2.18,18.87]],"id":37672294}],"con":true,"img":false}]}
{"op":"mcm","clk":"5346843442","pt":1646098542196,"mc":[{"id":"1.195395456","rc":[{"atl":[[4.1,13.08]],"id":22150928}],"con":true,"img":false}]}
{"op":"mcm","clk":"5346843445","pt":1646098542298,"mc":[{"id":"1.195395456","rc":[{"atb":[[2.12,0]],"id":37672294},{"atl":[[2.92,0]],"id":28002629},{"atl":[[4.9,0]],"id":22150928}],"con":true,"img":false}]}
{"op":"mcm","clk":"5346843448","pt":1646098542400,"mc":[{"id":"1.195395456","rc":[{"atb":[[2.04,39]],"id":37672294},{"atl":[[2.88,21.57],[2.9,26.32],[2.94,90.21]],"id":28002629}],"con":true,"img":false}]}
{"op":"mcm","clk":"5346843523","pt":1646098544341,"mc":[{"id":"1.195395456","rc":[{"atb":[[2.16,7.2]],"id":37672294}],"con":true,"img":false}]}
{"op":"mcm","clk":"5346843750","pt":1646098550238,"mc":[{"id":"1.195395456","rc":[{"atb":[[2.08,6.89]],"id":37672294}],"con":true,"img":false}]}
{"op":"mcm","clk":"5346843824","pt":1646098552338,"mc":[{"id":"1.195395456","rc":[{"atl":[[5,0]],"id":37672294},{"atl":[[2.88,0]],"id":28002629},{"atb":[[1.31,0]],"id":42393370},{"atb":[[1.07,506.09]],"id":43154433},{"atl":[[1.76,0]],"id":43154433}],"con":true,"img":false}]}
{"op":"mcm","clk":"5346843825","pt":1646098552442,"mc":[{"id":"1.195395456","rc":[{"atl":[[6.2,8.63]],"id":37672294},{"atl":[[2.92,21.57]],"id":28002629},{"atb":[[1.32,0],[1.3,400],[1.33,40.56]],"id":42393370},{"atl":[[1.64,40.56]],"id":43154433}],"con":true,"img":false}]}
{"op":"mcm","clk":"5346843989","pt":1646098557743,"mc":[{"id":"1.195395456","rc":[{"atb":[[2.16,0]],"id":37672294}],"con":true,"img":false}]}
{"op":"mcm","clk":"5346843993","pt":1646098557845,"mc":[{"id":"1.195395456","rc":[{"atb":[[2.1,37.74]],"id":37672294}],"con":true,"img":false}]}
{"op":"mcm","clk":"5346843995","pt":1646098557946,"mc":[{"id":"1.195395456","rc":[{"atb":[[2.18,0]],"id":37672294}],"con":true,"img":false}]}
{"op":"mcm","clk":"5346844031","pt":1646098559330,"mc":[{"id":"1.195395456","rc":[{"atb":[[2.08,0]],"id":37672294}],"con":true,"img":false}]}
{"op":"mcm","clk":"5346844073","pt":1646098560560,"mc":[{"id":"1.195395456","rc":[{"atl":[[2.9,52.64],[2.94,38.66]],"id":28002629}],"con":true,"img":false}]}
{"op":"mcm","clk":"5346844117","pt":1646098562251,"mc":[{"id":"1.195395456","rc":[{"atb":[[1.33,0]],"id":42393370}],"con":true,"img":false}]}
{"op":"mcm","clk":"5346844121","pt":1646098562353,"mc":[{"id":"1.195395456","rc":[{"atb":[[1.31,40.56]],"id":42393370}],"con":true,"img":false}]}
{"op":"mcm","clk":"5346844139","pt":1646098562965,"mc":[{"id":"1.195395456","rc":[{"atb":[[2.06,94.35],[2.1,0]],"id":37672294}],"con":true,"img":false}]}
{"op":"mcm","clk":"5346844151","pt":1646098563333,"mc":[{"id":"1.195395456","rc":[{"atb":[[2.08,7.73]],"id":37672294}],"con":true,"img":false}]}
{"op":"mcm","clk":"5346844441","pt":1646098570464,"mc":[{"id":"1.195395456","rc":[{"atb":[[1.3,66.67],[1.32,148.74]],"id":42393370}],"con":true,"img":false}]}
{"op":"mcm","clk":"5346844471","pt":1646098571233,"mc":[{"id":"1.195395456","rc":[{"atb":[[2.1,6.77]],"id":37672294}],"con":true,"img":false}]}
{"op":"mcm","clk":"5346844498","pt":1646098572153,"mc":[{"id":"1.195395456","rc":[{"atb":[[1.07,708.52]],"id":43154433}],"con":true,"img":false}]}
{"op":"mcm","clk":"5346844632","pt":1646098575743,"mc":[{"id":"1.195395456","rc":[{"atb":[[2.06,18.87],[2.12,7.74]],"id":37672294}],"con":true,"img":false}]}
{"op":"mcm","clk":"5346844665","pt":1646098577275,"mc":[{"id":"1.195395456","rc":[{"atb":[[2.1,0]],"id":37672294}],"con":true,"img":false}]}
{"op":"mcm","clk":"5346844791","pt":1646098580861,"mc":[{"id":"1.195395456","rc":[{"atb":[[2.12,0],[2.1,18.87]],"id":37672294}],"con":true,"img":false}]}
{"op":"mcm","clk":"5346844829","pt":1646098582295,"mc":[{"id":"1.195395456","rc":[{"atl":[[6.2,0]],"id":37672294},{"atl":[[2.92,0]],"id":28002629},{"atb":[[1.07,506.09]],"id":43154433}],"con":true,"img":false}]}
{"op":"mcm","clk":"5346844833","pt":1646098582350,"mc":[{"id":"1.195395456","rc":[{"atl":[[5,8.63]],"id":37672294},{"atl":[[2.88,21.57]],"id":28002629}],"con":true,"img":false}]}
{"op":"mcm","clk":"5346844834","pt":1646098582449,"mc":[{"id":"1.195395456","rc":[{"atl":[[2.9,26.32],[2.94,90.21]],"id":28002629}],"con":true,"img":false}]}
{"op":"mcm","clk":"5346844857","pt":1646098583267,"mc":[{"id":"1.195395456","rc":[{"atb":[[2.08,14.63]],"id":37672294}],"con":true,"img":false}]}
{"op":"mcm","clk":"5346845203","pt":1646098592286,"mc":[{"id":"1.195395456","rc":[{"atl":[[2.88,0]],"id":28002629},{"atb":[[1.31,0]],"id":42393370}],"con":true,"img":false}]}
{"op":"mcm","clk":"5346845208","pt":1646098592388,"mc":[{"id":"1.195395456","rc":[{"atl":[[2.92,21.57]],"id":28002629},{"atb":[[1.3,364.15],[1.33,40.56]],"id":42393370}],"con":true,"img":false}]}
{"op":"mcm","clk":"5346845213","pt":1646098592490,"mc":[{"id":"1.195395456","rc":[{"atb":[[1.32,0]],"id":42393370}],"con":true,"img":false}]}
{"op":"mcm","clk":"5346845483","pt":1646098600194,"mc":[{"id":"1.195395456","rc":[{"atl":[[2.9,52.64],[2.94,38.66]],"id":28002629}],"con":true,"img":false}]}
{"op":"mcm","clk":"5346845568","pt":1646098602293,"mc":[{"id":"1.195395456","rc":[{"atb":[[1.33,0]],"id":42393370}],"con":true,"img":false}]}
{"op":"mcm","clk":"5346845572","pt":1646098602396,"mc":[{"id":"1.195395456","rc":[{"atb":[[1.31,40.56]],"id":42393370}],"con":true,"img":false}]}
{"op":"mcm","clk":"5346845818","pt":1646098610018,"mc":[{"id":"1.195395456","rc":[{"atb":[[1.3,66.67],[1.32,148.74]],"id":42393370}],"con":true,"img":false}]}
{"op":"mcm","clk":"5346846261","pt":1646098622321,"mc":[{"id":"1.195395456","rc":[{"atl":[[2.92,0]],"id":28002629},{"atl":[[2.48,0]],"id":42393370}],"con":true,"img":false}]}
{"op":"mcm","clk":"5346846266","pt":1646098622422,"mc":[{"id":"1.195395456","rc":[{"atl":[[2.88,21.57],[2.94,90.21]],"id":28002629},{"atl":[[2.44,27.41]],"id":42393370}],"con":true,"img":false}]}
{"op":"mcm","clk":"5346846272","pt":1646098622524,"mc":[{"id":"1.195395456","rc":[{"atl":[[2.9,26.32]],"id":28002629}],"con":true,"img":false}]}
{"op":"mcm","clk":"5346846601","pt":1646098632315,"mc":[{"id":"1.195395456","rc":[{"atl":[[2.88,0]],"id":28002629},{"atb":[[1.31,0]],"id":42393370},{"atl":[[2.44,0]],"id":42393370}],"con":true,"img":false}]}
{"op":"mcm","clk":"5346846604","pt":1646098632418,"mc":[{"id":"1.195395456","rc":[{"atl":[[2.92,21.57]],"id":28002629},{"atb":[[1.32,0],[1.3,364.15],[1.33,40.56]],"id":42393370},{"atl":[[2.48,27.41]],"id":42393370}],"con":true,"img":false}]}
{"op":"mcm","clk":"5346846847","pt":1646098639755,"mc":[{"id":"1.195395456","rc":[{"atl":[[2.9,52.64]],"id":28002629}],"con":true,"img":false}]}
{"op":"mcm","clk":"5346846848","pt":1646098639863,"mc":[{"id":"1.195395456","rc":[{"atl":[[2.94,38.66]],"id":28002629}],"con":true,"img":false}]}
{"op":"mcm","clk":"5346846938","pt":1646098642230,"mc":[{"id":"1.195395456","rc":[{"atb":[[1.33,0]],"id":42393370}],"con":true,"img":false}]}
{"op":"mcm","clk":"5346846940","pt":1646098642329,"mc":[{"id":"1.195395456","rc":[{"atb":[[1.31,40.56]],"id":42393370}],"con":true,"img":false}]}
{"op":"mcm","clk":"5346847200","pt":1646098649657,"mc":[{"id":"1.195395456","rc":[{"atb":[[1.3,66.67],[1.32,148.74]],"id":42393370}],"con":true,"img":false}]}
{"op":"mcm","clk":"5346847707","pt":1646098662162,"mc":[{"id":"1.195395456","rc":[{"atl":[[2.92,0]],"id":28002629},{"atl":[[2.48,0]],"id":42393370}],"con":true,"img":false}]}
{"op":"mcm","clk":"5346847712","pt":1646098662266,"mc":[{"id":"1.195395456","rc":[{"atl":[[2.88,21.57],[2.9,26.32],[2.94,90.21]],"id":28002629},{"atl":[[2.44,27.41]],"id":42393370}],"con":true,"img":false}]}
{"op":"mcm","clk":"5346848165","pt":1646098672270,"mc":[{"id":"1.195395456","rc":[{"atl":[[2.88,0]],"id":28002629},{"atb":[[1.31,0]],"id":42393370},{"atl":[[2.44,0]],"id":42393370}],"con":true,"img":false}]}
{"op":"mcm","clk":"5346848171","pt":1646098672375,"mc":[{"id":"1.195395456","rc":[{"atl":[[2.92,21.57]],"id":28002629},{"atb":[[1.32,0],[1.3,364.15],[1.33,40.56]],"id":42393370},{"atl":[[2.48,27.41]],"id":42393370}],"con":true,"img":false}]}
{"op":"mcm","clk":"5346848501","pt":1646098679200,"mc":[{"id":"1.195395456","rc":[{"atl":[[2.9,52.64],[2.94,38.66]],"id":28002629}],"con":true,"img":false}]}
{"op":"mcm","clk":"5346848642","pt":1646098682291,"mc":[{"id":"1.195395456","rc":[{"atb":[[1.33,0]],"id":42393370}],"con":true,"img":false}]}
{"op":"mcm","clk":"5346848646","pt":1646098682398,"mc":[{"id":"1.195395456","rc":[{"atb":[[1.31,40.56]],"id":42393370}],"con":true,"img":false}]}
{"op":"mcm","clk":"5346848944","pt":1646098689211,"mc":[{"id":"1.195395456","rc":[{"atb":[[1.3,66.67],[1.32,148.74]],"id":42393370}],"con":true,"img":false}]}
{"op":"mcm","clk":"5346849511","pt":1646098702249,"mc":[{"id":"1.195395456","rc":[{"atl":[[2.92,0]],"id":28002629},{"atl":[[2.48,0]],"id":42393370}],"con":true,"img":false}]}
{"op":"mcm","clk":"5346849517","pt":1646098702351,"mc":[{"id":"1.195395456","rc":[{"atl":[[2.88,21.57]],"id":28002629},{"atl":[[2.44,27.41]],"id":42393370}],"con":true,"img":false}]}
{"op":"mcm","clk":"5346849520","pt":1646098702403,"mc":[{"id":"1.195395456","rc":[{"atl":[[2.9,26.32],[2.94,90.21]],"id":28002629}],"con":true,"img":false}]}
{"op":"mcm","clk":"5346849525","pt":1646098702508,"mc":[{"id":"1.195395456","rc":[{"atl":[[2.86,32.32],[2.94,38.66]],"id":28002629}],"con":true,"img":false}]}
{"op":"mcm","clk":"5346849913","pt":1646098712248,"mc":[{"id":"1.195395456","rc":[{"atb":[[1.31,0]],"id":42393370}],"con":true,"img":false}]}
{"op":"mcm","clk":"5346849919","pt":1646098712349,"mc":[{"id":"1.195395456","rc":[{"atb":[[1.3,364.15],[1.33,40.56]],"id":42393370}],"con":true,"img":false}]}
{"op":"mcm","clk":"5346849924","pt":1646098712452,"mc":[{"id":"1.195395456","rc":[{"atb":[[1.32,0]],"id":42393370}],"con":true,"img":false}]}
{"op":"mcm","clk":"5346850329","pt":1646098722267,"mc":[{"id":"1.195395456","rc":[{"atb":[[1.33,0]],"id":42393370}],"con":true,"img":false}]}
{"op":"mcm","clk":"5346850333","pt":1646098722371,"mc":[{"id":"1.195395456","rc":[{"atb":[[1.31,40.56]],"id":42393370}],"con":true,"img":false}]}
{"op":"mcm","clk":"5346850579","pt":1646098728787,"mc":[{"id":"1.195395456","rc":[{"atb":[[1.3,66.67],[1.32,148.74]],"id":42393370}],"con":true,"img":false}]}
{"op":"mcm","clk":"5346850696","pt":1646098732278,"mc":[{"id":"1.195395456","rc":[{"atl":[[2.88,0]],"id":28002629}],"con":true,"img":false}]}
{"op":"mcm","clk":"5346850699","pt":1646098732379,"mc":[{"id":"1.195395456","rc":[{"atl":[[2.86,10.75],[2.84,21.57],[2.94,90.21]],"id":28002629}],"con":true,"img":false}]}
{"op":"mcm","clk":"5346851041","pt":1646098742198,"mc":[{"id":"1.195395456","rc":[{"atl":[[2.84,0]],"id":28002629},{"atl":[[2.44,0]],"id":42393370}],"con":true,"img":false}]}
{"op":"mcm","clk":"5346851050","pt":1646098742301,"mc":[{"id":"1.195395456","rc":[{"atl":[[2.92,21.57]],"id":28002629},{"atl":[[2.48,27.41]],"id":42393370}],"con":true,"img":false}]}
{"op":"mcm","clk":"5346851277","pt":1646098748566,"mc":[{"id":"1.195395456","rc":[{"atl":[[2.9,52.64],[2.94,38.66]],"id":28002629}],"con":true,"img":false}]}
{"op":"mcm","clk":"5346851437","pt":1646098752277,"mc":[{"id":"1.195395456","rc":[{"atb":[[1.31,0]],"id":42393370}],"con":true,"img":false}]}
{"op":"mcm","clk":"5346851452","pt":1646098752378,"mc":[{"id":"1.195395456","rc":[{"atb":[[1.32,0],[1.3,364.15],[1.33,40.56]],"id":42393370}],"con":true,"img":false}]}
{"op":"mcm","clk":"5346851458","pt":1646098752482,"mc":[{"id":"1.195395456","rc":[{"atb":[[1.32,178.57]],"id":42393370}],"con":true,"img":false}]}
{"op":"mcm","clk":"5346851466","pt":1646098752583,"mc":[{"id":"1.195395456","rc":[{"atb":[[1.3,66.67]],"id":42393370}],"con":true,"img":false}]}
{"op":"mcm","clk":"5346852264","pt":1646098772200,"mc":[{"id":"1.195395456","rc":[{"atl":[[2.92,0]],"id":28002629},{"atl":[[2.48,0]],"id":42393370}],"con":true,"img":false}]}
{"op":"mcm","clk":"5346852269","pt":1646098772304,"mc":[{"id":"1.195395456","rc":[{"atl":[[2.88,21.57],[2.9,26.32],[2.94,90.21]],"id":28002629},{"atl":[[2.44,27.41]],"id":42393370}],"con":true,"img":false}]}
{"op":"mcm","clk":"5346852675","pt":1646098782313,"mc":[{"id":"1.195395456","rc":[{"atl":[[2.88,0]],"id":28002629},{"atl":[[2.44,0]],"id":42393370}],"con":true,"img":false}]}
{"op":"mcm","clk":"5346852680","pt":1646098782416,"mc":[{"id":"1.195395456","rc":[{"atl":[[2.92,21.57]],"id":28002629},{"atl":[[2.48,27.41]],"id":42393370}],"con":true,"img":false}]}
{"op":"mcm","clk":"5346852885","pt":1646098788150,"mc":[{"id":"1.195395456","rc":[{"atl":[[2.9,52.64],[2.94,38.66]],"id":28002629}],"con":true,"img":false}]}
{"op":"mcm","clk":"5346853868","pt":1646098812236,"mc":[{"id":"1.195395456","rc":[{"atl":[[2.92,0]],"id":28002629},{"atl":[[2.48,0]],"id":42393370}],"con":true,"img":false}]}
{"op":"mcm","clk":"5346853872","pt":1646098812339,"mc":[{"id":"1.195395456","rc":[{"atl":[[2.88,21.57],[2.9,26.32],[2.94,90.21]],"id":28002629},{"atl":[[2.44,27.41]],"id":42393370}],"con":true,"img":false}]}
{"op":"mcm","clk":"5346854004","pt":1646098815780,"mc":[{"id":"1.195395456","rc":[{"atb":[[1.32,0],[1.29,327.3]],"id":42393370},{"atl":[[2.5,50],[2.62,61.73]],"id":42393370},{"atl":[[4.9,25.64],[4.2,0]],"id":22150928}],"con":true,"img":false}]}
{"op":"mcm","clk":"5346854270","pt":1646098822289,"mc":[{"id":"1.195395456","rc":[{"atl":[[2.88,0]],"id":28002629},{"atb":[[1.33,0]],"id":42393370},{"atl":[[2.44,0]],"id":42393370},{"atl":[[4.1,0]],"id":22150928}],"con":true,"img":false}]}
{"op":"mcm","clk":"5346854273","pt":1646098822341,"mc":[{"id":"1.195395456","rc":[{"atl":[[2.92,21.57]],"id":28002629},{"atb":[[1.31,40.56]],"id":42393370},{"atl":[[2.48,27.41]],"id":42393370},{"atl":[[4.8,13.08]],"id":22150928}],"con":true,"img":false}]}
{"op":"mcm","clk":"5346854525","pt":1646098827778,"mc":[{"id":"1.195395456","rc":[{"atl":[[4.5,0],[4.4,5.88]],"id":37672294},{"atb":[[1.36,55.56],[1.38,0]],"id":28002629},{"atl":[[2.9,52.64],[2.94,38.66]],"id":28002629},{"atl":[[5.6,0],[5.8,4.17]],"id":37267533},{"atl":[[11,0],[11.5,1.9]],"id":37455733}],"con":true,"img":false}]}
{"op":"mcm","clk":"5346854637","pt":1646098830085,"mc":[{"id":"1.195395456","rc":[{"atb":[[1.41,0]],"id":28002629}],"con":true,"img":false}]}
{"op":"mcm","clk":"5346854692","pt":1646098831165,"mc":[{"id":"1.195395456","rc":[{"atb":[[1.32,66.67],[1.29,148.73]],"id":42393370},{"atl":[[2.52,61.73],[2.62,0]],"id":42393370}],"con":true,"img":false}]}
{"op":"mcm","clk":"5346854725","pt":1646098832193,"mc":[{"id":"1.195395456","rc":[{"atb":[[1.37,0]],"id":28002629},{"atl":[[8.4,0]],"id":37267533}],"con":true,"img":false}]}
{"op":"mcm","clk":"5346854728","pt":1646098832295,"mc":[{"id":"1.195395456","rc":[{"atb":[[1.35,99.39]],"id":28002629},{"atl":[[9,5.79]],"id":37267533}],"con":true,"img":false}]}
{"op":"mcm","clk":"5346854976","pt":1646098837787,"mc":[{"id":"1.195395456","rc":[{"atb":[[1.34,147.06]],"id":28002629},{"atl":[[6,10]],"id":37267533},{"atl":[[12.5,4.35]],"id":37455733}],"con":true,"img":false}]}
{"op":"mcm","clk":"5346855009","pt":1646098838869,"mc":[{"id":"1.195395456","rc":[{"atb":[[1.39,59.66]],"id":28002629}],"con":true,"img":false}]}
{"op":"mcm","clk":"5346855195","pt":1646098843180,"mc":[{"id":"1.195395456","rc":[{"atl":[[12,0],[13,3.38],[14,0]],"id":37455733}],"con":true,"img":false}]}
{"op":"mcm","clk":"5346855280","pt":1646098845285,"mc":[{"id":"1.195395456","rc":[{"atb":[[1.4,0]],"id":28002629}],"con":true,"img":false}]}
{"op":"mcm","clk":"5346855358","pt":1646098847796,"mc":[{"id":"1.195395456","rc":[{"atb":[[1.32,234.37]],"id":28002629},{"atl":[[6.4,13.89]],"id":37267533},{"atl":[[13.5,6]],"id":37455733}],"con":true,"img":false}]}
{"op":"mcm","clk":"5346855483","pt":1646098851897,"mc":[{"id":"1.195395456","rc":[{"atl":[[2.92,0]],"id":28002629},{"atb":[[1.31,0]],"id":42393370},{"atl":[[2.48,0]],"id":42393370}],"con":true,"img":false}]}
{"op":"mcm","clk":"5346855488","pt":1646098851999,"mc":[{"id":"1.195395456","rc":[{"atl":[[2.88,21.57],[2.9,26.32],[2.94,90.21]],"id":28002629},{"atb":[[1.32,0],[1.3,215.41],[1.33,40.56]],"id":42393370},{"atl":[[2.44,27.41]],"id":42393370}],"con":true,"img":false}]}
{"op":"mcm","clk":"5346855677","pt":1646098856520,"mc":[{"id":"1.195395456","rc":[{"atb":[[1.01,30017.84]],"id":43154433},{"atl":[[2.24,19.36],[1.92,13.05],[2.04,11.54],[2.44,16.67],[2.64,29.28]],"id":43154433}],"con":true,"img":false}]}
{"op":"mcm","clk":"5346855718","pt":1646098857503,"mc":[{"id":"1.195395456","rc":[{"atb":[[1.42,19.89]],"id":28002629}],"con":true,"img":false}]}
{"op":"mcm","clk":"5346855733","pt":1646098857810,"mc":[{"id":"1.195395456","rc":[{"atb":[[1.3,250]],"id":28002629},{"atl":[[6.8,21.55]],"id":37267533},{"atl":[[14.5,9.26]],"id":37455733}],"con":true,"img":false}]}
{"op":"mcm","clk":"5346855881","pt":1646098861618,"mc":[{"id":"1.195395456","rc":[{"atl":[[2.88,0]],"id":28002629},{"atb":[[1.33,0]],"id":42393370}],"con":true,"img":false}]}
{"op":"mcm","clk":"5346855886","pt":1646098861718,"mc":[{"id":"1.195395456","rc":[{"atl":[[2.92,21.57]],"id":28002629},{"atb":[[1.31,40.56]],"id":42393370}],"con":true,"img":false}]}
{"op":"mcm","clk":"5346856064","pt":1646098867014,"mc":[{"id":"1.195395456","rc":[{"atl":[[2.9,52.64]],"id":28002629},{"atb":[[1.32,148.74]],"id":42393370}],"con":true,"img":false}]}
{"op":"mcm","clk":"5346856068","pt":1646098867115,"mc":[{"id":"1.195395456","rc":[{"atl":[[2.94,38.66]],"id":28002629},{"atb":[[1.3,66.67]],"id":42393370}],"con":true,"img":false}]}
{"op":"mcm","clk":"5346856206","pt":1646098871523,"mc":[{"id":"1.195395456","rc":[{"atb":[[1.35,0]],"id":28002629}],"con":true,"img":false}]}
{"op":"mcm","clk":"5346856209","pt":1646098871629,"mc":[{"id":"1.195395456","rc":[{"atb":[[1.37,99.39]],"id":28002629}],"con":true,"img":false}]}
{"op":"mcm","clk":"5346856242","pt":1646098872139,"mc":[{"id":"1.195395456","rc":[{"atb":[[1.39,40.56]],"id":28002629}],"con":true,"img":false}]}
{"op":"mcm","clk":"5346856455","pt":1646098878050,"mc":[{"id":"1.195395456","rc":[{"atb":[[1.4,18.62]],"id":28002629}],"con":true,"img":false}]}
{"op":"mcm","clk":"5346856619","pt":1646098882157,"mc":[{"id":"1.195395456","rc":[{"atb":[[1.37,0]],"id":28002629}],"con":true,"img":false}]}
{"op":"mcm","clk":"5346856623","pt":1646098882258,"mc":[{"id":"1.195395456","rc":[{"atb":[[1.35,99.39]],"id":28002629}],"con":true,"img":false}]}
{"op":"mcm","clk":"5346856681","pt":1646098884158,"mc":[{"id":"1.195395456","rc":[{"atb":[[1.4,0]],"id":28002629}],"con":true,"img":false}]}
{"op":"mcm","clk":"5346856836","pt":1646098887961,"mc":[{"id":"1.195395456","rc":[{"atb":[[1.42,0]],"id":28002629}],"con":true,"img":false}]}
{"op":"mcm","clk":"5346856913","pt":1646098890062,"mc":[{"id":"1.195395456","rc":[{"atb":[[1.39,59.66]],"id":28002629}],"con":true,"img":false}]}
{"op":"mcm","clk":"5346856993","pt":1646098892270,"mc":[{"id":"1.195395456","rc":[{"atl":[[2.92,0]],"id":28002629},{"atb":[[1.31,0]],"id":42393370}],"con":true,"img":false}]}
{"op":"mcm","clk":"5346856998","pt":1646098892373,"mc":[{"id":"1.195395456","rc":[{"atl":[[2.88,21.57]],"id":28002629},{"atb":[[1.33,40.56]],"id":42393370}],"con":true,"img":false}]}
{"op":"mcm","clk":"5346857001","pt":1646098892475,"mc":[{"id":"1.195395456","rc":[{"atl":[[2.9,26.32],[2.94,90.21]],"id":28002629},{"atb":[[1.32,0],[1.3,364.15]],"id":42393370}],"con":true,"img":false}]}
{"op":"mcm","clk":"5346857395","pt":1646098902181,"mc":[{"id":"1.195395456","rc":[{"atl":[[2.88,0]],"id":28002629},{"atb":[[1.33,0]],"id":42393370},{"atl":[[2.42,0]],"id":43154433}],"con":true,"img":false}]}
{"op":"mcm","clk":"5346857398","pt":1646098902278,"mc":[{"id":"1.195395456","rc":[{"atl":[[2.92,21.57]],"id":28002629},{"atb":[[1.31,40.56]],"id":42393370},{"atl":[[2.22,24.94]],"id":43154433}],"con":true,"img":false}]}
{"op":"mcm","clk":"5346857446","pt":1646098903774,"mc":[{"id":"1.195395456","rc":[{"atl":[[4.3,6.06],[4.4,0]],"id":37672294},{"atl":[[2.5,111.73],[2.52,0]],"id":42393370},{"atl":[[11,2],[11.5,0]],"id":37455733},{"atl":[[3.45,8.16],[3.4,0]],"id":22150928}],"con":true,"img":false}]}
{"op":"mcm","clk":"5346857527","pt":1646098905876,"mc":[{"id":"1.195395456","rc":[{"atb":[[1.42,19.89]],"id":28002629}],"con":true,"img":false}]}
{"op":"mcm","clk":"5346857561","pt":1646098907053,"mc":[{"id":"1.195395456","rc":[{"atl":[[2.9,52.64],[2.94,38.66]],"id":28002629},{"atb":[[1.3,66.67],[1.32,148.74]],"id":42393370}],"con":true,"img":false}]}
{"op":"mcm","clk":"5346857744","pt":1646098912200,"mc":[{"id":"1.195395456","rc":[{"atb":[[2,0]],"id":37672294}],"con":true,"img":false}]}
{"op":"mcm","clk":"5346857747","pt":1646098912252,"mc":[{"id":"1.195395456","rc":[{"atb":[[1.98,40.92]],"id":37672294}],"con":true,"img":false}]}
{"op":"mcm","clk":"5346857787","pt":1646098913791,"mc":[{"id":"1.195395456","rc":[{"atl":[[4.5,14.29]],"id":37672294},{"atl":[[3.55,19.61]],"id":22150928}],"con":true,"img":false}]}
{"op":"mcm","clk":"5346857858","pt":1646098916098,"mc":[{"id":"1.195395456","rc":[{"atl":[[5.1,0]],"id":37672294},{"atl":[[3.45,0],[3.4,8.33],[3.55,0]],"id":22150928}],"con":true,"img":false}]}
{"op":"mcm","clk":"5346858083","pt":1646098922204,"mc":[{"id":"1.195395456","rc":[{"atl":[[5,0]],"id":37672294},{"atb":[[1.35,0]],"id":28002629}],"con":true,"img":false}]}
{"op":"mcm","clk":"5346858085","pt":1646098922312,"mc":[{"id":"1.195395456","rc":[{"atl":[[6.2,8.63]],"id":37672294},{"atb":[[1.37,99.39]],"id":28002629}],"con":true,"img":false}]}
{"op":"mcm","clk":"5346858112","pt":1646098923185,"mc":[{"id":"1.195395456","rc":[{"atb":[[1.39,40.56]],"id":28002629}],"con":true,"img":false}]}
{"op":"mcm","clk":"5346858136","pt":1646098923804,"mc":[{"id":"1.195395456","rc":[{"atl":[[4.7,20.27]],"id":37672294}],"con":true,"img":false}]}
{"op":"mcm","clk":"5346858341","pt":1646098929088,"mc":[{"id":"1.195395456","rc":[{"atb":[[1.4,18.62]],"id":28002629}],"con":true,"img":false}]}
{"op":"mcm","clk":"5346858457","pt":1646098932208,"mc":[{"id":"1.195395456","rc":[{"atb":[[1.37,0]],"id":28002629},{"atl":[[2.92,0]],"id":28002629},{"atb":[[1.31,0]],"id":42393370},{"atl":[[2.44,0]],"id":42393370}],"con":true,"img":false}]}
{"op":"mcm","clk":"5346858460","pt":1646098932313,"mc":[{"id":"1.195395456","rc":[{"atb":[[1.35,99.39]],"id":28002629},{"atl":[[2.88,21.57],[2.9,26.32],[2.94,90.21]],"id":28002629},{"atb":[[1.3,364.15],[1.33,40.56]],"id":42393370},{"atl":[[2.48,27.41]],"id":42393370}],"con":true,"img":false}]}
{"op":"mcm","clk":"5346858463","pt":1646098932412,"mc":[{"id":"1.195395456","rc":[{"atb":[[1.32,0]],"id":42393370}],"con":true,"img":false}]}
{"op":"mcm","clk":"5346858499","pt":1646098933797,"mc":[{"id":"1.195395456","rc":[{"atl":[[4.9,32.05]],"id":37672294}],"con":true,"img":false}]}
{"op":"mcm","clk":"5346858544","pt":1646098935231,"mc":[{"id":"1.195395456","rc":[{"atb":[[1.4,0]],"id":28002629}],"con":true,"img":false}]}
{"op":"mcm","clk":"5346858576","pt":1646098935903,"mc":[{"id":"1.195395456","rc":[{"atb":[[1.42,0]],"id":28002629}],"con":true,"img":false}]}
{"op":"mcm","clk":"5346858799","pt":1646098941399,"mc":[{"id":"1.195395456","rc":[{"atb":[[1.39,59.66]],"id":28002629}],"con":true,"img":false}]}
{"op":"mcm","clk":"5346858998","pt":1646098946531,"mc":[{"id":"1.195395456","rc":[{"atl":[[2.86,32.32],[2.94,38.66]],"id":28002629},{"atb":[[1.3,66.67],[1.32,178.57]],"id":42393370}],"con":true,"img":false}]}
{"op":"mcm","clk":"5346859233","pt":1646098952225,"mc":[{"id":"1.195395456","rc":[{"atl":[[2.88,0]],"id":28002629},{"atb":[[1.33,0]],"id":42393370}],"con":true,"img":false}]}
{"op":"mcm","clk":"5346859240","pt":1646098952332,"mc":[{"id":"1.195395456","rc":[{"atl":[[2.92,21.57],[2.86,10.75],[2.94,90.21]],"id":28002629},{"atb":[[1.32,0],[1.3,400],[1.31,40.56]],"id":42393370}],"con":true,"img":false}]}
{"op":"mcm","clk":"5346859245","pt":1646098952431,"mc":[{"id":"1.195395456","rc":[{"atl":[[2.9,52.64],[2.94,38.66]],"id":28002629},{"atb":[[1.3,66.67],[1.32,148.74]],"id":42393370}],"con":true,"img":false}]}
{"op":"mcm","clk":"5346859559","pt":1646098960550,"mc":[{"id":"1.195395456","rc":[{"atb":[[1.42,19.89]],"id":28002629}],"con":true,"img":false}]}
{"op":"mcm","clk":"5346860096","pt":1646098972151,"mc":[{"id":"1.195395456","rc":[{"atl":[[6.2,0]],"id":37672294},{"atb":[[1.35,0]],"id":28002629},{"atl":[[2.92,0]],"id":28002629},{"atb":[[1.31,0]],"id":42393370}],"con":true,"img":false}]}
{"op":"mcm","clk":"5346860098","pt":1646098972255,"mc":[{"id":"1.195395456","rc":[{"atl":[[4.8,8.63]],"id":37672294},{"atb":[[1.37,99.39]],"id":28002629},{"atl":[[2.88,21.57],[2.9,26.32],[2.94,90.21]],"id":28002629},{"atb":[[1.32,0],[1.3,364.15],[1.33,40.56]],"id":42393370}],"con":true,"img":false}]}
{"op":"mcm","clk":"5346860106","pt":1646098972459,"mc":[{"id":"1.195395456","rc":[{"atl":[[4.3,0],[4.2,6.25]],"id":37672294},{"atb":[[1.36,0],[1.35,57.14]],"id":28002629},{"atl":[[5.8,0],[5.9,4.08]],"id":37267533},{"atl":[[3.45,8.16],[3.4,0]],"id":22150928}],"con":true,"img":false}]}
{"op":"mcm","clk":"5346860180","pt":1646098974255,"mc":[{"id":"1.195395456","rc":[{"atb":[[1.39,40.56]],"id":28002629}],"con":true,"img":false}]}
{"op":"mcm","clk":"5346860442","pt":1646098980468,"mc":[{"id":"1.195395456","rc":[{"atb":[[2.4,42.88],[2.3,92.36],[2.2,100.05]],"id":37267533},{"atl":[[9.6,2.79],[19,2.66],[5.8,2.5],[7.6,1.81],[14,1.84]],"id":37267533},{"atb":[[1.6,100.05],[1.55,218.31],[1.5,240.14]],"id":22150928},{"atl":[[2.88,6.38],[3.2,5.45],[3.7,55.19],[4.4,7.06],[5.4,10.91]],"id":22150928}],"con":true,"img":false}]}
{"op":"mcm","clk":"5346860445","pt":1646098980571,"mc":[{"id":"1.195395456","rc":[{"atb":[[1.4,18.62]],"id":28002629}],"con":true,"img":false}]}
{"op":"mcm","clk":"5346860512","pt":1646098982269,"mc":[{"id":"1.195395456","rc":[{"atb":[[1.37,0]],"id":28002629},{"atl":[[2.88,0]],"id":28002629},{"atb":[[1.33,0]],"id":42393370}],"con":true,"img":false}]}
{"op":"mcm","clk":"5346860515","pt":1646098982369,"mc":[{"id":"1.195395456","rc":[{"atb":[[1.35,156.53]],"id":28002629},{"atl":[[2.92,21.57]],"id":28002629},{"atb":[[1.31,40.56]],"id":42393370}],"con":true,"img":false}]}
{"op":"mcm","clk":"5346860520","pt":1646098982471,"mc":[{"id":"1.195395456","rc":[{"atb":[[1.33,151.52]],"id":28002629},{"atl":[[6.2,9.62]],"id":37267533},{"atl":[[3.55,19.61]],"id":22150928}],"con":true,"img":false}]}
{"op":"mcm","clk":"5346860593","pt":1646098983960,"mc":[{"id":"1.195395456","rc":[{"atb":[[1.4,0]],"id":28002629},{"atb":[[2.12,0]],"id":37267533}],"con":true,"img":false}]}
{"op":"mcm","clk":"5346860677","pt":1646098985972,"mc":[{"id":"1.195395456","rc":[{"atb":[[1.32,0],[1.3,0],[1.34,0]],"id":28002629},{"atl":[[6.4,0],[6.8,0],[6,0]],"id":37267533},{"atl":[[3.6,0],[3.7,8.89],[3.5,0]],"id":22150928}],"con":true,"img":false}]}
{"op":"mcm","clk":"5346860682","pt":1646098986073,"mc":[{"id":"1.195395456","rc":[{"atl":[[2.9,52.64],[2.94,38.66]],"id":28002629},{"atb":[[1.3,66.67],[1.32,148.74]],"id":42393370}],"con":true,"img":false}]}
{"op":"mcm","clk":"5346860848","pt":1646098989250,"mc":[{"id":"1.195395456","rc":[{"atb":[[1.38,19.6]],"id":28002629},{"atb":[[2.46,5.1]],"id":37267533}],"con":true,"img":false}]}
{"op":"mcm","clk":"5346860896","pt":1646098990584,"mc":[{"id":"1.195395456","rc":[{"atb":[[1.42,0]],"id":28002629}],"con":true,"img":false}]}
{"op":"mcm","clk":"5346860899","pt":1646098990687,"mc":[{"id":"1.195395456","rc":[{"atb":[[2,20],[2.06,0]],"id":37672294},{"atl":[[2.5,50]],"id":42393370},{"atb":[[1.36,0]],"id":37267533},{"atb":[[1.71,0]],"id":37455733},{"atl":[[1.6,0],[1.58,0],[1.76,131.58],[1.56,0],[1.54,0],[1.65,0]],"id":43154433}],"con":true,"img":false}]}
{"op":"mcm","clk":"5346860905","pt":1646098990740,"mc":[{"id":"1.195395456","rc":[{"atb":[[1.89,79.94],[2.1,0]],"id":37672294},{"atl":[[2.86,0],[2.2,16.67]],"id":28002629},{"atl":[[2.54,74.65],[2.42,0]],"id":42393370},{"atb":[[1.63,31.75],[1.26,0],[1.53,147.06]],"id":37267533},{"atb":[[1.79,0],[1.44,118.82],[1.81,0],[1.54,37.04],[1.77,0],[1.75,0]],"id":37455733},{"atb":[[2,8.52],[1.89,0]],"id":22150928},{"atl":[[1.76,157.9]],"id":43154433}],"con":true,"img":false}]}
{"op":"mcm","clk":"5346860909","pt":1646098990843,"mc":[{"id":"1.195395456","rc":[{"atl":[[2.9,26.32],[2.2,38.24]],"id":28002629}],"con":true,"img":false}]}
{"op":"mcm","clk":"5346860913","pt":1646098990944,"mc":[{"id":"1.195395456","rc":[{"atb":[[2.02,0]],"id":37672294},{"atl":[[2.9,64.98],[2.2,16.67]],"id":28002629}],"con":true,"img":false}]}
{"op":"mcm","clk":"5346860968","pt":1646098992181,"mc":[{"id":"1.195395456","rc":[{"atb":[[2.04,0]],"id":37672294},{"atl":[[4.8,0]],"id":37672294},{"atl":[[1.64,0]],"id":43154433}],"con":true,"img":false}]}
{"op":"mcm","clk":"5346860976","pt":1646098992281,"mc":[{"id":"1.195395456","rc":[{"atb":[[2,59]],"id":37672294},{"atl":[[5.9,8.63]],"id":37672294},{"atl":[[1.75,40.56]],"id":43154433}],"con":true,"img":false}]}
{"op":"mcm","clk":"5346860987","pt":1646098992485,"mc":[{"id":"1.195395456","rc":[{"atl":[[3.65,28.3]],"id":22150928}],"con":true,"img":false}]}
{"op":"mcm","clk":"5346861104","pt":1646098995264,"mc":[{"id":"1.195395456","rc":[{"atb":[[2.08,7.73]],"id":37672294}],"con":true,"img":false}]}
{"op":"mcm","clk":"5346861148","pt":1646098996445,"mc":[{"id":"1.195395456","rc":[{"atb":[[2.08,0]],"id":37672294}],"con":true,"img":false}]}
{"op":"mcm","clk":"5346861152","pt":1646098996547,"mc":[{"id":"1.195395456","rc":[{"atb":[[1.38,41.59]],"id":28002629}],"con":true,"img":false}]}
{"op":"mcm","clk":"5346861156","pt":1646098996753,"mc":[{"id":"1.195395456","rc":[{"atb":[[2.46,10.82]],"id":37267533}],"con":true,"img":false}]}
{"op":"mcm","clk":"5346861334","pt":1646099000661,"mc":[{"id":"1.195395456","rc":[{"atb":[[1.98,91.94]],"id":37672294},{"atb":[[1.31,241.94]],"id":28002629},{"atl":[[2.24,40.32]],"id":28002629},{"atl":[[2.46,0],[2.58,31.65]],"id":42393370},{"atb":[[1.61,81.97]],"id":37267533},{"atl":[[6.6,13.39]],"id":37267533},{"atb":[[1.52,96.15]],"id":37455733},{"atl":[[1.78,64.1]],"id":43154433}],"con":true,"img":false}]}
{"op":"mcm","clk":"5346861361","pt":1646099001275,"mc":[{"id":"1.195395456","rc":[{"atb":[[2.04,7.16]],"id":37672294}],"con":true,"img":false}]}
{"op":"mcm","clk":"5346861398","pt":1646099002173,"mc":[{"id":"1.195395456","rc":[{"atl":[[2.48,0]],"id":42393370}],"con":true,"img":false}]}
{"op":"mcm","clk":"5346861401","pt":1646099002272,"mc":[{"id":"1.195395456","rc":[{"atl":[[2.54,12.99],[2.52,27.41],[2.58,94.94]],"id":42393370}],"con":true,"img":false}]}
{"op":"mcm","clk":"5346861405","pt":1646099002374,"mc":[{"id":"1.195395456","rc":[{"atl":[[2.9,38.66],[2.98,0],[2.94,0]],"id":28002629},{"atl":[[2.5,0]],"id":42393370},{"atb":[[1.32,0],[1.3,0],[1.34,0]],"id":37267533}],"con":true,"img":false}]}
{"op":"mcm","clk":"5346861408","pt":1646099002481,"mc":[{"id":"1.195395456","rc":[{"atl":[[3.75,45.45]],"id":22150928}],"con":true,"img":false}]}
{"op":"mcm","clk":"5346861640","pt":1646099008490,"mc":[{"id":"1.195395456","rc":[{"atb":[[2.04,15.2]],"id":37672294}],"con":true,"img":false}]}
{"op":"mcm","clk":"5346861717","pt":1646099010699,"mc":[{"id":"1.195395456","rc":[{"atb":[[1.96,78.12]],"id":37672294},{"atb":[[1.29,250]],"id":28002629},{"atl":[[2.28,58.59]],"id":28002629},{"atl":[[2.62,46.3]],"id":42393370},{"atb":[[1.59,127.12]],"id":37267533},{"atl":[[7,20.83]],"id":37267533},{"atb":[[1.5,150]],"id":37455733},{"atl":[[1.8,93.75]],"id":43154433}],"con":true,"img":false}]}
{"op":"mcm","clk":"5346861727","pt":1646099010902,"mc":[{"id":"1.195395456","rc":[{"atl":[[2.9,0],[2.26,56.99]],"id":28002629}],"con":true,"img":false}]}
{"op":"mcm","clk":"5346861797","pt":1646099012185,"mc":[{"id":"1.195395456","rc":[{"atb":[[1.31,0]],"id":42393370},{"atl":[[2.52,0]],"id":42393370},{"atb":[[1.07,708.52]],"id":43154433}],"con":true,"img":false}]}
{"op":"mcm","clk":"5346861798","pt":1646099012289,"mc":[{"id":"1.195395456","rc":[{"atb":[[1.3,364.15],[1.33,40.56]],"id":42393370},{"atl":[[2.56,27.41],[2.62,108.03]],"id":42393370}],"con":true,"img":false}]}
{"op":"mcm","clk":"5346861801","pt":1646099012390,"mc":[{"id":"1.195395456","rc":[{"atb":[[1.32,0]],"id":42393370},{"atl":[[2.58,31.65]],"id":42393370}],"con":true,"img":false}]}
{"op":"mcm","clk":"5346861858","pt":1646099014083,"mc":[{"id":"1.195395456","rc":[{"atb":[[1.99,0],[1.97,0]],"id":37672294}],"con":true,"img":false}]}
{"op":"mcm","clk":"5346861919","pt":1646099015573,"mc":[{"id":"1.195395456","rc":[{"atb":[[1.51,0]],"id":22150928}],"con":true,"img":false}]}
{"op":"mcm","clk":"5346861924","pt":1646099015678,"mc":[{"id":"1.195395456","rc":[{"atb":[[1.61,73.35]],"id":22150928}],"con":true,"img":false}]}
{"op":"mcm","clk":"5346861970","pt":1646099016604,"mc":[{"id":"1.195395456","rc":[{"atb":[[2.42,28.88],[2.08,0]],"id":37267533}],"con":true,"img":false}]}
{"op":"mcm","clk":"5346862106","pt":1646099020712,"mc":[{"id":"1.195395456","rc":[{"atb":[[1.94,132.98]],"id":37672294},{"atl":[[2.32,94.7]],"id":28002629},{"atl":[[2.66,75.3]],"id":42393370},{"atb":[[1.57,219.3]],"id":37267533},{"atb":[[1.48,250]],"id":37455733},{"atl":[[1.82,152.44]],"id":43154433}],"con":true,"img":false}]}
{"op":"mcm","clk":"5346862152","pt":1646099021487,"mc":[{"id":"1.195395456","rc":[{"atl":[[4.3,6.06]],"id":37672294},{"atb":[[1.33,60.61],[1.35,99.39]],"id":28002629},{"atl":[[6.2,3.85],[5.9,0]],"id":37267533},{"atl":[[3.5,8],[3.45,0]],"id":22150928}],"con":true,"img":false}]}
{"op":"mcm","clk":"5346862161","pt":1646099021589,"mc":[{"id":"1.195395456","rc":[{"atl":[[4.2,0]],"id":37672294}],"con":true,"img":false}]}
{"op":"mcm","clk":"5346862189","pt":1646099022206,"mc":[{"id":"1.195395456","rc":[{"atb":[[1.35,0]],"id":28002629}],"con":true,"img":false}]}
{"op":"mcm","clk":"5346862194","pt":1646099022308,"mc":[{"id":"1.195395456","rc":[{"atb":[[1.34,99.39]],"id":28002629}],"con":true,"img":false}]}
{"op":"mcm","clk":"5346862320","pt":1646099025389,"mc":[{"id":"1.195395456","rc":[{"atb":[[1.38,21.99]],"id":28002629}],"con":true,"img":false}]}
{"op":"mcm","clk":"5346862337","pt":1646099025698,"mc":[{"id":"1.195395456","rc":[{"atb":[[1.3,66.67],[1.32,178.57]],"id":42393370},{"atl":[[2.54,40.4],[2.62,46.3]],"id":42393370}],"con":true,"img":false}]}
{"op":"mcm","clk":"5346862573","pt":1646099031496,"mc":[{"id":"1.195395456","rc":[{"atb":[[1.31,161.29]],"id":28002629},{"atl":[[6.6,8.93]],"id":37267533},{"atl":[[3.6,19.23]],"id":22150928}],"con":true,"img":false}]}
{"op":"mcm","clk":"5346862599","pt":1646099032320,"mc":[{"id":"1.195395456","rc":[{"atb":[[1.33,0]],"id":42393370},{"atl":[[2.56,0]],"id":42393370},{"atb":[[1.07,506.09]],"id":43154433}],"con":true,"img":false}]}
{"op":"mcm","clk":"5346862605","pt":1646099032423,"mc":[{"id":"1.195395456","rc":[{"atb":[[1.32,0],[1.3,400],[1.31,40.56]],"id":42393370},{"atl":[[2.54,12.99],[2.6,27.41],[2.62,108.03]],"id":42393370}],"con":true,"img":false}]}
{"op":"mcm","clk":"5346862836","pt":1646099037720,"mc":[{"id":"1.195395456","rc":[{"atl":[[3.55,0],[3.75,0],[3.65,0]],"id":22150928}],"con":true,"img":false}]}
{"op":"mcm","clk":"5346862868","pt":1646099038591,"mc":[{"id":"1.195395456","rc":[{"atb":[[1.38,0]],"id":28002629}],"con":true,"img":false}]}
{"op":"mcm","clk":"5346862965","pt":1646099041517,"mc":[{"id":"1.195395456","rc":[{"atb":[[1.27,250]],"id":28002629},{"atl":[[7,12.5]],"id":37267533},{"atl":[[3.7,36.67]],"id":22150928}],"con":true,"img":false}]}
{"op":"mcm","clk":"5346862987","pt":1646099042238,"mc":[{"id":"1.195395456","rc":[{"atb":[[1.34,0]],"id":28002629}],"con":true,"img":false}]}
{"op":"mcm","clk":"5346862990","pt":1646099042340,"mc":[{"id":"1.195395456","rc":[{"atb":[[1.32,99.39]],"id":28002629}],"con":true,"img":false}]}
{"op":"mcm","clk":"5346863110","pt":1646099045640,"mc":[{"id":"1.195395456","rc":[{"atb":[[1.3,66.67],[1.32,148.74]],"id":42393370},{"atl":[[2.58,63.3],[2.62,46.3]],"id":42393370}],"con":true,"img":false}]}
{"op":"mcm","clk":"5346863366","pt":1646099051540,"mc":[{"id":"1.195395456","rc":[{"atl":[[7.4,19.53]],"id":37267533},{"atl":[[3.8,44.64]],"id":22150928}],"con":true,"img":false}]}
{"op":"mcm","clk":"5346863391","pt":1646099052255,"mc":[{"id":"1.195395456","rc":[{"atl":[[2.6,0]],"id":42393370}],"con":true,"img":false}]}
{"op":"mcm","clk":"5346863397","pt":1646099052357,"mc":[{"id":"1.195395456","rc":[{"atl":[[2.56,27.41]],"id":42393370}],"con":true,"img":false}]}
{"op":"mcm","clk":"5346863401","pt":1646099052458,"mc":[{"id":"1.195395456","rc":[{"atl":[[2.58,31.65],[2.62,108.03]],"id":42393370}],"con":true,"img":false}]}
{"op":"mcm","clk":"5346863970","pt":1646099065438,"mc":[{"id":"1.195395456","rc":[{"atl":[[2.54,40.4],[2.62,46.3]],"id":42393370}],"con":true,"img":false}]}
{"op":"mcm","clk":"5346864291","pt":1646099072163,"mc":[{"id":"1.195395456","rc":[{"atb":[[1.31,0]],"id":42393370}],"con":true,"img":false}]}
{"op":"mcm","clk":"5346864297","pt":1646099072266,"mc":[{"id":"1.195395456","rc":[{"atb":[[1.32,0],[1.3,364.15],[1.33,40.56]],"id":42393370}],"con":true,"img":false}]}
{"op":"mcm","clk":"5346864728","pt":1646099082283,"mc":[{"id":"1.195395456","rc":[{"atb":[[1.33,0]],"id":42393370}],"con":true,"img":false}]}
{"op":"mcm","clk":"5346864733","pt":1646099082385,"mc":[{"id":"1.195395456","rc":[{"atb":[[1.31,40.56]],"id":42393370}],"con":true,"img":false}]}
{"op":"mcm","clk":"5346864846","pt":1646099085055,"mc":[{"id":"1.195395456","rc":[{"atb":[[1.32,148.74]],"id":42393370}],"con":true,"img":false}]}
{"op":"mcm","clk":"5346864853","pt":1646099085161,"mc":[{"id":"1.195395456","rc":[{"atb":[[1.3,66.67]],"id":42393370}],"con":true,"img":false}]}
{"op":"mcm","clk":"5346865172","pt":1646099092298,"mc":[{"id":"1.195395456","rc":[{"atl":[[2.56,0]],"id":42393370}],"con":true,"img":false}]}
{"op":"mcm","clk":"5346865176","pt":1646099092399,"mc":[{"id":"1.195395456","rc":[{"atl":[[2.52,27.41]],"id":42393370}],"con":true,"img":false}]}
{"op":"mcm","clk":"5346865179","pt":1646099092453,"mc":[{"id":"1.195395456","rc":[{"atl":[[2.54,12.99],[2.62,108.03]],"id":42393370}],"con":true,"img":false}]}
{"op":"mcm","clk":"5346865585","pt":1646099102187,"mc":[{"id":"1.195395456","rc":[{"atl":[[2.52,0]],"id":42393370}],"con":true,"img":false}]}
{"op":"mcm","clk":"5346865591","pt":1646099102289,"mc":[{"id":"1.195395456","rc":[{"atl":[[2.56,27.41]],"id":42393370}],"con":true,"img":false}]}
{"op":"mcm","clk":"5346865721","pt":1646099105081,"mc":[{"id":"1.195395456","rc":[{"atl":[[2.54,40.4],[2.62,46.3]],"id":42393370}],"con":true,"img":false}]}
{"op":"mcm","clk":"5346866055","pt":1646099112324,"mc":[{"id":"1.195395456","rc":[{"atb":[[1.31,0]],"id":42393370}],"con":true,"img":false}]}
{"op":"mcm","clk":"5346866063","pt":1646099112376,"mc":[{"id":"1.195395456","rc":[{"atb":[[1.33,40.56]],"id":42393370}],"con":true,"img":false}]}
{"op":"mcm","clk":"5346866070","pt":1646099112480,"mc":[{"id":"1.195395456","rc":[{"atb":[[1.32,0],[1.3,364.15]],"id":42393370}],"con":true,"img":false}]}
{"op":"mcm","clk":"5346866073","pt":1646099112584,"mc":[{"id":"1.195395456","rc":[{"atb":[[1.3,66.67],[1.32,178.57]],"id":42393370}],"con":true,"img":false}]}
{"op":"mcm","clk":"5346866863","pt":1646099132245,"mc":[{"id":"1.195395456","rc":[{"atl":[[2.56,0]],"id":42393370}],"con":true,"img":false}]}
{"op":"mcm","clk":"5346866866","pt":1646099132346,"mc":[{"id":"1.195395456","rc":[{"atl":[[2.52,27.41]],"id":42393370}],"con":true,"img":false}]}
{"op":"mcm","clk":"5346866870","pt":1646099132452,"mc":[{"id":"1.195395456","rc":[{"atl":[[2.54,12.99],[2.62,108.03]],"id":42393370}],"con":true,"img":false}]}
{"op":"mcm","clk":"5346866875","pt":1646099132656,"mc":[{"id":"1.195395456","rc":[{"atl":[[2.54,67.81],[2.62,46.3]],"id":42393370}],"con":true,"img":false}]}
{"op":"mcm","clk":"5346867814","pt":1646099158262,"mc":[{"id":"1.195395456","rc":[{"atb":[[1.21,0]],"id":28002629},{"atb":[[1.32,0],[1.29,327.3]],"id":42393370},{"atl":[[2.54,12.99],[2.62,108.03]],"id":42393370}],"con":true,"img":false}]}
{"op":"mcm","clk":"5346867822","pt":1646099158366,"mc":[{"id":"1.195395456","rc":[{"atb":[[1.16,322.58]],"id":28002629}],"con":true,"img":false}]}
{"op":"mcm","clk":"5346868005","pt":1646099162259,"mc":[{"id":"1.195395456","rc":[{"atb":[[1.33,0]],"id":42393370},{"atl":[[2.52,0]],"id":42393370}],"con":true,"img":false}]}
{"op":"mcm","clk":"5346868009","pt":1646099162362,"mc":[{"id":"1.195395456","rc":[{"atb":[[1.31,40.56]],"id":42393370},{"atl":[[2.56,27.41]],"id":42393370}],"con":true,"img":false}]}
{"op":"mcm","clk":"5346868780","pt":1646099182189,"mc":[{"id":"1.195395456","rc":[{"atb":[[1.07,708.52]],"id":43154433}],"con":true,"img":false}]}
{"op":"mcm","clk":"5346868823","pt":1646099183266,"mc":[{"id":"1.195395456","rc":[{"atb":[[1.32,66.67],[1.29,148.73]],"id":42393370},{"atl":[[2.54,40.4],[2.62,46.3]],"id":42393370}],"con":true,"img":false}]}
{"op":"mcm","clk":"5346869155","pt":1646099192194,"mc":[{"id":"1.195395456","rc":[{"atb":[[1.07,506.09]],"id":43154433}],"con":true,"img":false}]}
{"op":"mcm","clk":"5346877300","pt":1646099212291,"mc":[{"id":"1.195395456","rc":[{"atb":[[1.31,0]],"id":42393370},{"atl":[[2.56,0]],"id":42393370}],"con":true,"img":false}]}
{"op":"mcm","clk":"5346877306","pt":1646099212395,"mc":[{"id":"1.195395456","rc":[{"atb":[[1.32,0],[1.3,215.41],[1.33,40.56]],"id":42393370},{"atl":[[2.54,12.99],[2.52,27.41],[2.62,108.03]],"id":42393370}],"con":true,"img":false}]}
{"op":"mcm","clk":"5346877586","pt":1646099222288,"mc":[{"id":"1.195395456","rc":[{"atb":[[1.33,0]],"id":42393370},{"atl":[[2.52,0]],"id":42393370},{"atl":[[2.22,0]],"id":43154433}],"con":true,"img":false}]}
{"op":"mcm","clk":"5346877594","pt":1646099222390,"mc":[{"id":"1.195395456","rc":[{"atb":[[1.31,40.56]],"id":42393370},{"atl":[[2.56,27.41]],"id":42393370},{"atl":[[2.42,24.94]],"id":43154433}],"con":true,"img":false}]}
{"op":"mcm","clk":"5346877635","pt":1646099223775,"mc":[{"id":"1.195395456","rc":[{"atb":[[1.3,66.67],[1.32,148.74]],"id":42393370},{"atl":[[2.54,40.4],[2.62,46.3]],"id":42393370}],"con":true,"img":false}]}
{"op":"mcm","clk":"5346878562","pt":1646099252344,"mc":[{"id":"1.195395456","rc":[{"atb":[[1.31,0]],"id":42393370},{"atl":[[2.56,0]],"id":42393370}],"con":true,"img":false}]}
{"op":"mcm","clk":"5346878567","pt":1646099252446,"mc":[{"id":"1.195395456","rc":[{"atb":[[1.32,0],[1.3,364.15],[1.33,40.56]],"id":42393370},{"atl":[[2.54,12.99],[2.52,27.41],[2.62,108.03]],"id":42393370}],"con":true,"img":false}]}
{"op":"mcm","clk":"5346878572","pt":1646099252549,"mc":[{"id":"1.195395456","rc":[{"atb":[[1.32,178.57]],"id":42393370},{"atl":[[2.54,67.81]],"id":42393370}],"con":true,"img":false}]}
{"op":"mcm","clk":"5346878577","pt":1646099252652,"mc":[{"id":"1.195395456","rc":[{"atb":[[1.3,66.67]],"id":42393370},{"atl":[[2.62,46.3]],"id":42393370}],"con":true,"img":false}]}
{"op":"mcm","clk":"5346879567","pt":1646099280142,"mc":[{"id":"1.195395456","rc":[{"atl":[[2.24,0],[2.4,14.29],[2.32,0],[2.28,0],[2.2,0]],"id":28002629}],"con":true,"img":false}]}
{"op":"mcm","clk":"5346879572","pt":1646099280244,"mc":[{"id":"1.195395456","rc":[{"atl":[[2.9,52.63],[2.26,0]],"id":28002629}],"con":true,"img":false}]}
{"op":"mcm","clk":"5346879576","pt":1646099280345,"mc":[{"id":"1.195395456","rc":[{"atl":[[2.4,0]],"id":28002629}],"con":true,"img":false}]}
{"op":"mcm","clk":"5346880006","pt":1646099290169,"mc":[{"id":"1.195395456","rc":[{"atl":[[2.4,14.29],[2.52,82.24],[2.44,34.72],[2.48,50.68]],"id":28002629}],"con":true,"img":false}]}
{"op":"mcm","clk":"5346880011","pt":1646099290271,"mc":[{"id":"1.195395456","rc":[{"atl":[[2.9,0],[2.48,72.25]],"id":28002629}],"con":true,"img":false}]}
{"op":"mcm","clk":"5346880084","pt":1646099291887,"mc":[{"id":"1.195395456","rc":[{"atl":[[2.4,0]],"id":28002629}],"con":true,"img":false}]}
{"op":"mcm","clk":"5346880103","pt":1646099292247,"mc":[{"id":"1.195395456","rc":[{"atl":[[2.92,0]],"id":28002629}],"con":true,"img":false}]}
{"op":"mcm","clk":"5346880109","pt":1646099292350,"mc":[{"id":"1.195395456","rc":[{"atl":[[2.88,21.57]],"id":28002629}],"con":true,"img":false}]}
{"op":"mcm","clk":"5346880236","pt":1646099295374,"mc":[{"id":"1.195395456","rc":[{"atl":[[2.52,148.03],[2.48,50.68]],"id":28002629}],"con":true,"img":false}]}
{"op":"mcm","clk":"5346880434","pt":1646099300205,"mc":[{"id":"1.195395456","rc":[{"atl":[[2.4,14.29]],"id":28002629}],"con":true,"img":false}]}
{"op":"mcm","clk":"5346880468","pt":1646099300875,"mc":[{"id":"1.195395456","rc":[{"atl":[[2.48,101.36]],"id":28002629}],"con":true,"img":false}]}
{"op":"mcm","clk":"5346880473","pt":1646099300975,"mc":[{"id":"1.195395456","rc":[{"atl":[[2.52,82.24]],"id":28002629}],"con":true,"img":false}]}
{"op":"mcm","clk":"5346880564","pt":1646099303187,"mc":[{"id":"1.195395456","rc":[{"atl":[[2.4,0]],"id":28002629}],"con":true,"img":false}]}
{"op":"mcm","clk":"5346880592","pt":1646099303807,"mc":[{"id":"1.195395456","rc":[{"atb":[[1.29,327.3]],"id":42393370},{"atl":[[2.62,108.03]],"id":42393370}],"con":true,"img":false}]}
{"op":"mcm","clk":"5346880596","pt":1646099303907,"mc":[{"id":"1.195395456","rc":[{"atb":[[1.32,0]],"id":42393370},{"atl":[[2.54,12.99]],"id":42393370}],"con":true,"img":false}]}
{"op":"mcm","clk":"5346880862","pt":1646099310183,"mc":[{"id":"1.195395456","rc":[{"atl":[[2.4,14.29]],"id":28002629}],"con":true,"img":false}]}
{"op":"mcm","clk":"5346880951","pt":1646099312295,"mc":[{"id":"1.195395456","rc":[{"atb":[[1.33,0]],"id":42393370},{"atl":[[2.52,0]],"id":42393370}],"con":true,"img":false}]}
{"op":"mcm","clk":"5346880957","pt":1646099312397,"mc":[{"id":"1.195395456","rc":[{"atb":[[1.31,40.56]],"id":42393370},{"atl":[[2.6,27.41]],"id":42393370}],"con":true,"img":false}]}
{"op":"mcm","clk":"5346881194","pt":1646099317787,"mc":[{"id":"1.195395456","rc":[{"atl":[[2.4,0]],"id":28002629}],"con":true,"img":false}]}
{"op":"mcm","clk":"5346881219","pt":1646099318506,"mc":[{"id":"1.195395456","rc":[{"atl":[[4.3,0],[4.2,6.25]],"id":37672294},{"atb":[[1.34,58.82]],"id":28002629},{"atl":[[2.4,14.29]],"id":28002629},{"atb":[[1.32,66.67],[1.29,148.73]],"id":42393370},{"atl":[[2.58,63.3],[2.62,46.3]],"id":42393370},{"atl":[[3.45,8.16],[3.5,0]],"id":22150928}],"con":true,"img":false}]}
{"op":"mcm","clk":"5346881223","pt":1646099318608,"mc":[{"id":"1.195395456","rc":[{"atb":[[1.33,0]],"id":28002629},{"atl":[[2.38,34.72]],"id":28002629}],"con":true,"img":false}]}
{"op":"mcm","clk":"5346881226","pt":1646099318710,"mc":[{"id":"1.195395456","rc":[{"atl":[[2.48,50.68]],"id":28002629}],"con":true,"img":false}]}
{"op":"mcm","clk":"5346881240","pt":1646099319223,"mc":[{"id":"1.195395456","rc":[{"atb":[[1.33,60.61],[1.34,0]],"id":28002629},{"atl":[[2.4,0]],"id":28002629},{"atl":[[3.45,0],[3.5,8]],"id":22150928}],"con":true,"img":false}]}
{"op":"mcm","clk":"5346881272","pt":1646099320097,"mc":[{"id":"1.195395456","rc":[{"atl":[[2.4,14.29]],"id":28002629}],"con":true,"img":false}]}
{"op":"mcm","clk":"5346881358","pt":1646099322310,"mc":[{"id":"1.195395456","rc":[{"atb":[[1.98,51.02]],"id":37672294}],"con":true,"img":false}]}
{"op":"mcm","clk":"5346881363","pt":1646099322413,"mc":[{"id":"1.195395456","rc":[{"atb":[[1.97,40.92]],"id":37672294}],"con":true,"img":false}]}
{"op":"mcm","clk":"5346881399","pt":1646099323701,"mc":[{"id":"1.195395456","rc":[{"atl":[[2.38,0],[2.44,85.4]],"id":28002629},{"atb":[[1.32,0],[1.29,327.3]],"id":42393370}],"con":true,"img":false}]}
{"op":"mcm","clk":"5346881655","pt":1646099329712,"mc":[{"id":"1.195395456","rc":[{"atl":[[2.4,0]],"id":28002629}],"con":true,"img":false}]}
{"op":"mcm","clk":"5346881660","pt":1646099329815,"mc":[{"id":"1.195395456","rc":[{"atl":[[2.48,118.25]],"id":28002629}],"con":true,"img":false}]}
{"op":"mcm","clk":"5346881664","pt":1646099329918,"mc":[{"id":"1.195395456","rc":[{"atl":[[2.52,148.03],[2.44,34.72],[2.48,50.68]],"id":28002629}],"con":true,"img":false}]}
{"op":"mcm","clk":"5346881672","pt":1646099330125,"mc":[{"id":"1.195395456","rc":[{"atl":[[2.4,14.29]],"id":28002629}],"con":true,"img":false}]}
{"op":"mcm","clk":"5346882072","pt":1646099339327,"mc":[{"id":"1.195395456","rc":[{"atl":[[3.45,8.16]],"id":22150928}],"con":true,"img":false}]}
{"op":"mcm","clk":"5346882077","pt":1646099339428,"mc":[{"id":"1.195395456","rc":[{"atl":[[2.4,0]],"id":28002629},{"atl":[[3.5,0]],"id":22150928}],"con":true,"img":false}]}
{"op":"mcm","clk":"5346882100","pt":1646099340096,"mc":[{"id":"1.195395456","rc":[{"atl":[[2.4,14.29]],"id":28002629}],"con":true,"img":false}]}
{"op":"mcm","clk":"5346882104","pt":1646099340199,"mc":[{"id":"1.195395456","rc":[{"atl":[[2.52,82.24],[2.38,34.72]],"id":28002629}],"con":true,"img":false}]}
{"op":"mcm","clk":"5346882108","pt":1646099340301,"mc":[{"id":"1.195395456","rc":[{"atl":[[2.44,85.4]],"id":28002629}],"con":true,"img":false}]}
{"op":"mcm","clk":"5346882112","pt":1646099340405,"mc":[{"id":"1.195395456","rc":[{"atl":[[2.38,0]],"id":28002629}],"con":true,"img":false}]}
{"op":"mcm","clk":"5346882162","pt":1646099341944,"mc":[{"id":"1.195395456","rc":[{"atl":[[2.4,0]],"id":28002629},{"atl":[[1.76,0],[1.74,64.1],[1.65,30.77]],"id":43154433}],"con":true,"img":false}]}
{"op":"mcm","clk":"5346882166","pt":1646099342047,"mc":[{"id":"1.195395456","rc":[{"atl":[[2.52,148.03]],"id":28002629}],"con":true,"img":false}]}
{"op":"mcm","clk":"5346882170","pt":1646099342150,"mc":[{"id":"1.195395456","rc":[{"atl":[[2.4,14.29],[2.44,34.72]],"id":28002629}],"con":true,"img":false}]}
{"op":"mcm","clk":"5346882173","pt":1646099342254,"mc":[{"id":"1.195395456","rc":[{"atl":[[2.52,82.24],[2.48,118.25]],"id":28002629},{"atl":[[2.6,0]],"id":42393370}],"con":true,"img":false}]}
{"op":"mcm","clk":"5346882181","pt":1646099342307,"mc":[{"id":"1.195395456","rc":[{"atl":[[2.56,27.41]],"id":42393370}],"con":true,"img":false}]}
{"op":"mcm","clk":"5346882186","pt":1646099342409,"mc":[{"id":"1.195395456","rc":[{"atl":[[2.62,108.03]],"id":42393370}],"con":true,"img":false}]}
{"op":"mcm","clk":"5346882191","pt":1646099342512,"mc":[{"id":"1.195395456","rc":[{"atl":[[2.58,31.65]],"id":42393370}],"con":true,"img":false}]}
{"op":"mcm","clk":"5346882197","pt":1646099342615,"mc":[{"id":"1.195395456","rc":[{"atl":[[2.58,94.94],[2.62,46.3]],"id":42393370}],"con":true,"img":false}]}
{"op":"mcm","clk":"5346882477","pt":1646099349710,"mc":[{"id":"1.195395456","rc":[{"atl":[[2.4,0]],"id":28002629}],"con":true,"img":false}]}
{"op":"mcm","clk":"5346882562","pt":1646099351918,"mc":[{"id":"1.195395456","rc":[{"atl":[[1.67,74.63]],"id":43154433}],"con":true,"img":false}]}
{"op":"mcm","clk":"5346882567","pt":1646099352021,"mc":[{"id":"1.195395456","rc":[{"atl":[[1.72,105.4],[1.74,0]],"id":43154433}],"con":true,"img":false}]}
{"op":"mcm","clk":"5346882572","pt":1646099352122,"mc":[{"id":"1.195395456","rc":[{"atl":[[2.4,14.29]],"id":28002629}],"con":true,"img":false}]}
{"op":"mcm","clk":"5346882574","pt":1646099352225,"mc":[{"id":"1.195395456","rc":[{"atl":[[2.38,34.72],[2.48,50.68]],"id":28002629}],"con":true,"img":false}]}
{"op":"mcm","clk":"5346882752","pt":1646099357152,"mc":[{"id":"1.195395456","rc":[{"atl":[[2.4,0]],"id":28002629},{"atl":[[1.78,0],[1.8,0],[1.82,0]],"id":43154433}],"con":true,"img":false}]}
{"op":"mcm","clk":"5346882758","pt":1646099357358,"mc":[{"id":"1.195395456","rc":[{"atl":[[2.48,118.25]],"id":28002629}],"con":true,"img":false}]}
{"op":"mcm","clk":"5346882762","pt":1646099357460,"mc":[{"id":"1.195395456","rc":[{"atl":[[2.38,0]],"id":28002629}],"con":true,"img":false}]}
{"op":"mcm","clk":"5346882910","pt":1646099361936,"mc":[{"id":"1.195395456","rc":[{"atl":[[1.69,108.7]],"id":43154433}],"con":true,"img":false}]}
{"op":"mcm","clk":"5346882916","pt":1646099362142,"mc":[{"id":"1.195395456","rc":[{"atl":[[2.4,14.29]],"id":28002629}],"con":true,"img":false}]}
{"op":"mcm","clk":"5346882919","pt":1646099362242,"mc":[{"id":"1.195395456","rc":[{"atl":[[1.75,0]],"id":43154433}],"con":true,"img":false}]}
{"op":"mcm","clk":"5346882922","pt":1646099362344,"mc":[{"id":"1.195395456","rc":[{"atl":[[1.68,40.56]],"id":43154433}],"con":true,"img":false}]}
{"op":"mcm","clk":"5346883015","pt":1646099364871,"mc":[{"id":"1.195395456","rc":[{"atl":[[2.4,0]],"id":28002629}],"con":true,"img":false}]}
{"op":"mcm","clk":"5346883020","pt":1646099364972,"mc":[{"id":"1.195395456","rc":[{"atl":[[2.52,148.03],[2.48,50.68]],"id":28002629}],"con":true,"img":false}]}
{"op":"mcm","clk":"5346883249","pt":1646099371964,"mc":[{"id":"1.195395456","rc":[{"atl":[[1.71,176.06]],"id":43154433}],"con":true,"img":false}]}
{"op":"mcm","clk":"5346883257","pt":1646099372169,"mc":[{"id":"1.195395456","rc":[{"atl":[[2.4,14.29]],"id":28002629}],"con":true,"img":false}]}
{"op":"mcm","clk":"5346883262","pt":1646099372275,"mc":[{"id":"1.195395456","rc":[{"atl":[[2.52,82.24],[2.48,118.25]],"id":28002629}],"con":true,"img":false}]}
{"op":"mcm","clk":"5346883296","pt":1646099373252,"mc":[{"id":"1.195395456","rc":[{"atl":[[2.4,0]],"id":28002629}],"con":true,"img":false}]}
{"op":"mcm","clk":"5346883419","pt":1646099377361,"mc":[{"id":"1.195395456","rc":[{"atl":[[2.52,148.03],[2.48,50.68]],"id":28002629}],"con":true,"img":false}]}
{"op":"mcm","clk":"5346883522","pt":1646099381055,"mc":[{"id":"1.195395456","rc":[{"atl":[[2.4,14.29]],"id":28002629}],"con":true,"img":false}]}
{"op":"mcm","clk":"5346883691","pt":1646099387173,"mc":[{"id":"1.195395456","rc":[{"atl":[[2.52,82.24],[2.48,101.36]],"id":28002629}],"con":true,"img":false}]}
{"op":"mcm","clk":"5346883762","pt":1646099388870,"mc":[{"id":"1.195395456","rc":[{"atl":[[2.4,0]],"id":28002629}],"con":true,"img":false}]}
{"op":"mcm","clk":"5346883768","pt":1646099388976,"mc":[{"id":"1.195395456","rc":[{"atl":[[2.52,148.03],[2.48,50.68]],"id":28002629}],"con":true,"img":false}]}
{"op":"mcm","clk":"5346883832","pt":1646099391083,"mc":[{"id":"1.195395456","rc":[{"atl":[[2.4,14.29]],"id":28002629}],"con":true,"img":false}]}
{"op":"mcm","clk":"5346883838","pt":1646099391183,"mc":[{"id":"1.195395456","rc":[{"atl":[[2.52,82.24],[2.48,118.25]],"id":28002629}],"con":true,"img":false}]}
{"op":"mcm","clk":"5346883883","pt":1646099392273,"mc":[{"id":"1.195395456","rc":[{"atl":[[2.42,0]],"id":43154433}],"con":true,"img":false}]}
{"op":"mcm","clk":"5346883888","pt":1646099392375,"mc":[{"id":"1.195395456","rc":[{"atl":[[2.22,24.94]],"id":43154433}],"con":true,"img":false}]}
{"op":"mcm","clk":"5346884021","pt":1646099396797,"mc":[{"id":"1.195395456","rc":[{"atl":[[2.4,0]],"id":28002629}],"con":true,"img":false}]}
{"op":"mcm","clk":"5346884025","pt":1646099396901,"mc":[{"id":"1.195395456","rc":[{"atl":[[2.52,148.03]],"id":28002629}],"con":true,"img":false}]}
{"op":"mcm","clk":"5346884029","pt":1646099397004,"mc":[{"id":"1.195395456","rc":[{"atl":[[2.48,50.68]],"id":28002629}],"con":true,"img":false}]}
{"op":"mcm","clk":"5346884163","pt":1646099401083,"mc":[{"id":"1.195395456","rc":[{"atl":[[2.4,14.29]],"id":28002629}],"con":true,"img":false}]}
{"op":"mcm","clk":"5346884270","pt":1646099404076,"mc":[{"id":"1.195395456","rc":[{"atl":[[2.4,0]],"id":28002629}],"con":true,"img":false}]}
{"op":"mcm","clk":"5346884340","pt":1646099406495,"mc":[{"id":"1.195395456","rc":[{"atl":[[2.48,118.25]],"id":28002629}],"con":true,"img":false}]}
{"op":"mcm","clk":"5346884344","pt":1646099406597,"mc":[{"id":"1.195395456","rc":[{"atl":[[2.52,82.24]],"id":28002629}],"con":true,"img":false}]}
{"op":"mcm","clk":"5346884487","pt":1646099411128,"mc":[{"id":"1.195395456","rc":[{"atl":[[2.4,14.29]],"id":28002629}],"con":true,"img":false}]}
{"op":"mcm","clk":"5346884510","pt":1646099411798,"mc":[{"id":"1.195395456","rc":[{"atl":[[2.4,0]],"id":28002629}],"con":true,"img":false}]}
{"op":"mcm","clk":"5346884514","pt":1646099411901,"mc":[{"id":"1.195395456","rc":[{"atl":[[2.52,148.03]],"id":28002629}],"con":true,"img":false}]}
{"op":"mcm","clk":"5346884519","pt":1646099412001,"mc":[{"id":"1.195395456","rc":[{"atl":[[2.48,50.68]],"id":28002629}],"con":true,"img":false}]}
{"op":"mcm","clk":"5346884532","pt":1646099412315,"mc":[{"id":"1.195395456","rc":[{"atl":[[2.4,14.29]],"id":28002629}],"con":true,"img":false}]}
{"op":"mcm","clk":"5346884566","pt":1646099413130,"mc":[{"id":"1.195395456","rc":[{"atl":[[2.4,0]],"id":28002629}],"con":true,"img":false}]}
{"op":"mcm","clk":"5346884817","pt":1646099420426,"mc":[{"id":"1.195395456","rc":[{"atl":[[2.4,14.29]],"id":28002629}],"con":true,"img":false}]}
{"op":"mcm","clk":"5346884820","pt":1646099420530,"mc":[{"id":"1.195395456","rc":[{"atl":[[2.38,34.72]],"id":28002629}],"con":true,"img":false}]}
{"op":"mcm","clk":"5346884825","pt":1646099420632,"mc":[{"id":"1.195395456","rc":[{"atl":[[2.52,82.24]],"id":28002629}],"con":true,"img":false}]}
{"op":"mcm","clk":"5346884932","pt":1646099424231,"mc":[{"id":"1.195395456","rc":[{"atb":[[1.34,52.73]],"id":28002629},{"atb":[[1.32,28.39]],"id":42393370},{"atb":[[1.11,205.69]],"id":43154433}],"con":true,"img":false}]}
{"op":"mcm","clk":"5346884934","pt":1646099424335,"mc":[{"id":"1.195395456","rc":[{"atb":[[1.12,205.69],[1.1,0]],"id":43154433}],"con":true,"img":false}]}
{"op":"mcm","clk":"5346884977","pt":1646099425720,"mc":[{"id":"1.195395456","rc":[{"atl":[[2.38,0],[2.44,85.4]],"id":28002629}],"con":true,"img":false}]}
{"op":"mcm","clk":"5346885082","pt":1646099428702,"mc":[{"id":"1.195395456","rc":[{"atl":[[2.4,0]],"id":28002629}],"con":true,"img":false}]}
{"op":"mcm","clk":"5346885091","pt":1646099429008,"mc":[{"id":"1.195395456","rc":[{"atb":[[1.11,0]],"id":43154433}],"con":true,"img":false}]}
{"op":"mcm","clk":"5346885097","pt":1646099429112,"mc":[{"id":"1.195395456","rc":[{"atb":[[1.1,411.38]],"id":43154433}],"con":true,"img":false}]}
{"op":"mcm","clk":"5346885100","pt":1646099429211,"mc":[{"id":"1.195395456","rc":[{"atb":[[1.12,0]],"id":43154433}],"con":true,"img":false}]}
{"op":"mcm","clk":"5346885128","pt":1646099430441,"mc":[{"id":"1.195395456","rc":[{"atl":[[2.4,14.29]],"id":28002629}],"con":true,"img":false}]}
{"op":"mcm","clk":"5346885146","pt":1646099430851,"mc":[{"id":"1.195395456","rc":[{"atl":[[2.48,118.25]],"id":28002629}],"con":true,"img":false}]}
{"op":"mcm","clk":"5346885150","pt":1646099430907,"mc":[{"id":"1.195395456","rc":[{"atl":[[2.44,34.72]],"id":28002629}],"con":true,"img":false}]}
{"op":"mcm","clk":"5346885253","pt":1646099433932,"mc":[{"id":"1.195395456","rc":[{"atb":[[1.11,205.69]],"id":43154433}],"con":true,"img":false}]}
{"op":"mcm","clk":"5346885259","pt":1646099434037,"mc":[{"id":"1.195395456","rc":[{"atb":[[1.12,205.69],[1.1,0]],"id":43154433}],"con":true,"img":false}]}
{"op":"mcm","clk":"5346885293","pt":1646099435216,"mc":[{"id":"1.195395456","rc":[{"atb":[[2.06,29.18]],"id":37672294},{"atb":[[1.35,88.38]],"id":28002629},{"atb":[[1.33,56.79]],"id":42393370},{"atb":[[2.48,20.9]],"id":37267533},{"atb":[[2.02,17.04]],"id":22150928},{"atb":[[1.11,486.91]],"id":43154433}],"con":true,"img":false}]}
{"op":"mcm","clk":"5346885296","pt":1646099435318,"mc":[{"id":"1.195395456","rc":[{"atb":[[2,0],[2.04,8.52]],"id":22150928}],"con":true,"img":false}]}
{"op":"mcm","clk":"5346885325","pt":1646099436239,"mc":[{"id":"1.195395456","rc":[{"atl":[[2.4,0]],"id":28002629}],"con":true,"img":false}]}
{"op":"mcm","clk":"5346885329","pt":1646099436339,"mc":[{"id":"1.195395456","rc":[{"atl":[[2.52,148.03]],"id":28002629}],"con":true,"img":false}]}
{"op":"mcm","clk":"5346885334","pt":1646099436441,"mc":[{"id":"1.195395456","rc":[{"atl":[[2.48,50.68]],"id":28002629}],"con":true,"img":false}]}
{"op":"mcm","clk":"5346885342","pt":1646099436646,"mc":[{"id":"1.195395456","rc":[{"atl":[[2.4,14.29]],"id":28002629}],"con":true,"img":false}]}
{"op":"mcm","clk":"5346885368","pt":1646099437315,"mc":[{"id":"1.195395456","rc":[{"atl":[[2.4,0]],"id":28002629}],"con":true,"img":false}]}
{"op":"mcm","clk":"5346885408","pt":1646099438443,"mc":[{"id":"1.195395456","rc":[{"atl":[[4.3,6.06],[4.2,0]],"id":37672294},{"atb":[[1.33,0],[1.32,161.89]],"id":28002629},{"atl":[[2.4,14.29]],"id":28002629},{"atb":[[1.32,141.99],[1.29,148.73]],"id":42393370},{"atl":[[2.54,40.4],[2.58,31.65]],"id":42393370},{"atl":[[3.45,0],[3.5,8]],"id":22150928}],"con":true,"img":false}]}
{"op":"mcm","clk":"5346885418","pt":1646099438748,"mc":[{"id":"1.195395456","rc":[{"atb":[[1.34,0]],"id":28002629},{"atb":[[1.32,113.6]],"id":42393370},{"atb":[[2.02,0]],"id":22150928},{"atb":[[1.11,0]],"id":43154433}],"con":true,"img":false}]}
{"op":"mcm","clk":"5346885430","pt":1646099439160,"mc":[{"id":"1.195395456","rc":[{"atb":[[1.12,0],[1.1,411.38]],"id":43154433}],"con":true,"img":false}]}
{"op":"mcm","clk":"5346885451","pt":1646099439725,"mc":[{"id":"1.195395456","rc":[{"atb":[[1.32,99.39],[1.33,60.61]],"id":28002629},{"atl":[[2.4,0]],"id":28002629},{"atl":[[6.4,3.7],[6.2,0]],"id":37267533},{"atl":[[3.4,8.33],[3.5,0]],"id":22150928}],"con":true,"img":false}]}
{"op":"mcm","clk":"5346885473","pt":1646099440462,"mc":[{"id":"1.195395456","rc":[{"atb":[[2,17.04],[2.04,0]],"id":22150928}],"con":true,"img":false}]}
{"op":"mcm","clk":"5346885543","pt":1646099442648,"mc":[{"id":"1.195395456","rc":[{"atb":[[1.35,0]],"id":28002629},{"atb":[[2.06,17.04]],"id":22150928},{"atb":[[1.11,281.22]],"id":43154433}],"con":true,"img":false}]}
{"op":"mcm","clk":"5346885571","pt":1646099443520,"mc":[{"id":"1.195395456","rc":[{"atb":[[1.32,0],[1.29,327.3]],"id":42393370},{"atl":[[2.58,94.94]],"id":42393370}],"con":true,"img":false}]}
{"op":"mcm","clk":"5346885574","pt":1646099443623,"mc":[{"id":"1.195395456","rc":[{"atl":[[2.54,12.99]],"id":42393370}],"con":true,"img":false}]}
{"op":"mcm","clk":"5346885600","pt":1646099444345,"mc":[{"id":"1.195395456","rc":[{"atb":[[1.36,44.62]],"id":28002629},{"atb":[[1.34,39.76]],"id":42393370},{"atb":[[1.11,486.91]],"id":43154433}],"con":true,"img":false}]}
{"op":"mcm","clk":"5346885606","pt":1646099444548,"mc":[{"id":"1.195395456","rc":[{"atb":[[2,0],[2.08,17.04]],"id":22150928}],"con":true,"img":false}]}
{"op":"mcm","clk":"5346885611","pt":1646099444650,"mc":[{"id":"1.195395456","rc":[{"atl":[[2.4,14.29]],"id":28002629}],"con":true,"img":false}]}
{"op":"mcm","clk":"5346885615","pt":1646099444753,"mc":[{"id":"1.195395456","rc":[{"atl":[[2.52,82.24],[2.48,118.25]],"id":28002629}],"con":true,"img":false}]}
{"op":"mcm","clk":"5346885635","pt":1646099445318,"mc":[{"id":"1.195395456","rc":[{"atl":[[2.4,0]],"id":28002629}],"con":true,"img":false}]}
{"op":"mcm","clk":"5346885671","pt":1646099446446,"mc":[{"id":"1.195395456","rc":[{"atb":[[1.34,90.98]],"id":28002629}],"con":true,"img":false}]}
{"op":"mcm","clk":"5346885718","pt":1646099447629,"mc":[{"id":"1.195395456","rc":[{"atl":[[2.4,14.29]],"id":28002629}],"con":true,"img":false}]}
{"op":"mcm","clk":"5346885735","pt":1646099448242,"mc":[{"id":"1.195395456","rc":[{"atb":[[1.33,0]],"id":42393370},{"atb":[[2.06,0]],"id":22150928}],"con":true,"img":false}]}
{"op":"mcm","clk":"5346885739","pt":1646099448343,"mc":[{"id":"1.195395456","rc":[{"atb":[[1.12,411.38],[1.1,0]],"id":43154433}],"con":true,"img":false}]}
{"op":"mcm","clk":"5346885742","pt":1646099448446,"mc":[{"id":"1.195395456","rc":[{"atb":[[2,34.08],[2.08,0]],"id":22150928}],"con":true,"img":false}]}
{"op":"mcm","clk":"5346885789","pt":1646099449728,"mc":[{"id":"1.195395456","rc":[{"atl":[[6.8,8.62]],"id":37267533},{"atl":[[3.5,20]],"id":22150928}],"con":true,"img":false}]}
{"op":"mcm","clk":"5346885800","pt":1646099450038,"mc":[{"id":"1.195395456","rc":[{"atb":[[1.34,0]],"id":28002629}],"con":true,"img":false}]}
{"op":"mcm","clk":"5346885836","pt":1646099451267,"mc":[{"id":"1.195395456","rc":[{"atb":[[1.36,0]],"id":28002629},{"atb":[[1.34,0]],"id":42393370},{"atb":[[1.11,281.22]],"id":43154433}],"con":true,"img":false}]}
{"op":"mcm","clk":"5346885872","pt":1646099452147,"mc":[{"id":"1.195395456","rc":[{"atb":[[1.35,79.52]],"id":42393370},{"atb":[[2.02,30.32]],"id":22150928},{"atb":[[1.11,0]],"id":43154433}],"con":true,"img":false}]}
{"op":"mcm","clk":"5346885919","pt":1646099453427,"mc":[{"id":"1.195395456","rc":[{"atb":[[1.12,0],[1.1,822.76]],"id":43154433}],"con":true,"img":false}]}
{"op":"mcm","clk":"5346885927","pt":1646099453634,"mc":[{"id":"1.195395456","rc":[{"atl":[[2.4,0]],"id":28002629},{"atl":[[7.4,0],[6.6,0],[7,0]],"id":37267533},{"atl":[[3.8,0]],"id":22150928}],"con":true,"img":false}]}
{"op":"mcm","clk":"5346885943","pt":1646099454044,"mc":[{"id":"1.195395456","rc":[{"atb":[[1.34,90.98]],"id":28002629}],"con":true,"img":false}]}
{"op":"mcm","clk":"5346885947","pt":1646099454147,"mc":[{"id":"1.195395456","rc":[{"atl":[[2.52,148.03]],"id":28002629}],"con":true,"img":false}]}
{"op":"mcm","clk":"5346885951","pt":1646099454252,"mc":[{"id":"1.195395456","rc":[{"atl":[[2.48,50.68]],"id":28002629}],"con":true,"img":false}]}
{"op":"mcm","clk":"5346886013","pt":1646099456027,"mc":[{"id":"1.195395456","rc":[{"atb":[[1.11,281.22]],"id":43154433}],"con":true,"img":false}]}
{"op":"mcm","clk":"5346886059","pt":1646099457357,"mc":[{"id":"1.195395456","rc":[{"atb":[[1.34,143.72]],"id":28002629},{"atb":[[1.32,70.7]],"id":42393370},{"atb":[[1.12,281.23],[1.11,486.91],[1.1,0]],"id":43154433}],"con":true,"img":false}]}
{"op":"mcm","clk":"5346886065","pt":1646099457459,"mc":[{"id":"1.195395456","rc":[{"atb":[[2,0],[2.04,30.33]],"id":22150928}],"con":true,"img":false}]}
{"op":"mcm","clk":"5346886072","pt":1646099457562,"mc":[{"id":"1.195395456","rc":[{"atl":[[2.4,14.29]],"id":28002629}],"con":true,"img":false}]}
{"op":"mcm","clk":"5346886090","pt":1646099458074,"mc":[{"id":"1.195395456","rc":[{"atl":[[2.54,40.4],[2.58,31.65]],"id":42393370},{"atl":[[4.9,0],[4.2,27.56]],"id":22150928},{"atl":[[1.72,0],[1.67,149.26]],"id":43154433}],"con":true,"img":false}]}
{"op":"mcm","clk":"5346886152","pt":1646099459768,"mc":[{"id":"1.195395456","rc":[{"atl":[[7.2,12.1]],"id":37267533},{"atl":[[3.6,48.08]],"id":22150928}],"con":true,"img":false}]}
{"op":"mcm","clk":"5346886155","pt":1646099459871,"mc":[{"id":"1.195395456","rc":[{"atb":[[1.35,0]],"id":42393370},{"atb":[[2.02,0]],"id":22150928},{"atl":[[3.6,28.85]],"id":22150928},{"atb":[[1.11,205.69]],"id":43154433}],"con":true,"img":false}]}
{"op":"mcm","clk":"5346886160","pt":1646099460014,"mc":[{"id":"1.195395456","rc":[{"atb":[[2,60.66]],"id":22150928}],"con":true,"img":false}]}
{"op":"mcm","clk":"5346886166","pt":1646099460077,"mc":[{"id":"1.195395456","rc":[{"atb":[[2.04,0]],"id":22150928}],"con":true,"img":false}]}
{"op":"mcm","clk":"5346886170","pt":1646099460128,"mc":[{"id":"1.195395456","rc":[{"atb":[[1.11,0]],"id":43154433}],"con":true,"img":false}]}
{"op":"mcm","clk":"5346886173","pt":1646099460234,"mc":[{"id":"1.195395456","rc":[{"atb":[[1.1,562.46]],"id":43154433}],"con":true,"img":false}]}
{"op":"mcm","clk":"5346886176","pt":1646099460335,"mc":[{"id":"1.195395456","rc":[{"atb":[[1.12,0]],"id":43154433}],"con":true,"img":false}]}
{"op":"mcm","clk":"5346886202","pt":1646099461257,"mc":[{"id":"1.195395456","rc":[{"atb":[[1.99,0]],"id":22150928}],"con":true,"img":false}]}
{"op":"mcm","clk":"5346886222","pt":1646099461874,"mc":[{"id":"1.195395456","rc":[{"atl":[[2.4,0]],"id":28002629}],"con":true,"img":false}]}
{"op":"mcm","clk":"5346886237","pt":1646099462179,"mc":[{"id":"1.195395456","rc":[{"atb":[[1.07,708.52]],"id":43154433}],"con":true,"img":false}]}
{"op":"mcm","clk":"5346886275","pt":1646099463161,"mc":[{"id":"1.195395456","rc":[{"atl":[[2.4,14.29]],"id":28002629},{"atl":[[2.54,12.99],[2.58,94.94]],"id":42393370},{"atl":[[1.72,138.89]],"id":43154433}],"con":true,"img":false}]}
{"op":"mcm","clk":"5346886278","pt":1646099463262,"mc":[{"id":"1.195395456","rc":[{"atl":[[2.52,82.24],[2.48,118.25]],"id":28002629},{"atl":[[1.67,74.63]],"id":43154433}],"con":true,"img":false}]}
{"op":"mcm","clk":"5346886299","pt":1646099463775,"mc":[{"id":"1.195395456","rc":[{"atb":[[1.33,93.74]],"id":42393370},{"atb":[[2.02,30.32]],"id":22150928},{"atb":[[1.11,281.22]],"id":43154433}],"con":true,"img":false}]}
{"op":"mcm","clk":"5346886331","pt":1646099465057,"mc":[{"id":"1.195395456","rc":[{"atb":[[1.11,486.91]],"id":43154433}],"con":true,"img":false}]}
{"op":"mcm","clk":"5346886427","pt":1646099467174,"mc":[{"id":"1.195395456","rc":[{"atb":[[2.04,7.16]],"id":22150928}],"con":true,"img":false}]}
{"op":"mcm","clk":"5346886501","pt":1646099468869,"mc":[{"id":"1.195395456","rc":[{"atb":[[2,0],[2.06,30.33]],"id":22150928}],"con":true,"img":false}]}
{"op":"mcm","clk":"5346886511","pt":1646099469178,"mc":[{"id":"1.195395456","rc":[{"atb":[[1.12,486.92],[1.1,0]],"id":43154433}],"con":true,"img":false}]}
{"op":"mcm","clk":"5346886517","pt":1646099469276,"mc":[{"id":"1.195395456","rc":[{"atb":[[2.02,0]],"id":22150928}],"con":true,"img":false}]}
{"op":"mcm","clk":"5346886545","pt":1646099469792,"mc":[{"id":"1.195395456","rc":[{"atl":[[7.6,20.75]],"id":37267533},{"atl":[[3.7,55.19]],"id":22150928}],"con":true,"img":false}]}
{"op":"mcm","clk":"5346886559","pt":1646099469997,"mc":[{"id":"1.195395456","rc":[{"atb":[[2,39],[2.06,48.05],[1.89,0],[2.08,29.18]],"id":37672294},{"atl":[[2.4,0]],"id":28002629},{"atl":[[2.54,0],[2.86,64.51],[2.58,0],[2.62,0]],"id":42393370},{"atb":[[1.09,222.22],[1.53,0]],"id":37267533},{"atb":[[1.44,0],[1.81,24.69],[1.71,96.15]],"id":37455733},{"atl":[[1.87,137.93],[1.71,0],[1.69,0],[1.72,0],[1.67,0],[1.65,0]],"id":43154433}],"con":true,"img":false}]}
{"op":"mcm","clk":"5346886564","pt":1646099470059,"mc":[{"id":"1.195395456","rc":[{"atb":[[1.59,0],[1.63,0],[1.57,0],[1.61,0]],"id":37267533},{"atb":[[1.54,0]],"id":37455733}],"con":true,"img":false}]}
{"op":"mcm","clk":"5346886568","pt":1646099470150,"mc":[{"id":"1.195395456","rc":[{"atl":[[2.52,148.03],[2.48,50.68]],"id":28002629},{"atb":[[2.04,0]],"id":22150928}],"con":true,"img":false}]}
{"op":"mcm","clk":"5346886576","pt":1646099470369,"mc":[{"id":"1.195395456","rc":[{"atl":[[2.4,14.29]],"id":28002629},{"atl":[[2.66,0]],"id":42393370}],"con":true,"img":false}]}
{"op":"mcm","clk":"5346886651","pt":1646099472251,"mc":[{"id":"1.195395456","rc":[{"atl":[[2.56,0]],"id":42393370},{"atb":[[1.95,0]],"id":22150928},{"atl":[[1.68,0]],"id":43154433}],"con":true,"img":false}]}
{"op":"mcm","clk":"5346886655","pt":1646099472351,"mc":[{"id":"1.195395456","rc":[{"atl":[[2.84,27.41]],"id":42393370},{"atb":[[2.02,40.56]],"id":22150928},{"atl":[[1.86,40.56]],"id":43154433}],"con":true,"img":false}]}
{"op":"mcm","clk":"5346886666","pt":1646099472660,"mc":[{"id":"1.195395456","rc":[{"atb":[[1.11,281.22]],"id":43154433}],"con":true,"img":false}]}
{"op":"mcm","clk":"5346886681","pt":1646099473071,"mc":[{"id":"1.195395456","rc":[{"atb":[[2.06,18.87]],"id":37672294},{"atb":[[1.99,31.24]],"id":22150928},{"atb":[[1.11,0]],"id":43154433}],"con":true,"img":false}]}
{"op":"mcm","clk":"5346886689","pt":1646099473275,"mc":[{"id":"1.195395456","rc":[{"atb":[[2.04,8.03]],"id":37672294}],"con":true,"img":false}]}
{"op":"mcm","clk":"5346886692","pt":1646099473376,"mc":[{"id":"1.195395456","rc":[{"atl":[[5.7,21.28]],"id":37672294}],"con":true,"img":false}]}
{"op":"mcm","clk":"5346886696","pt":1646099473479,"mc":[{"id":"1.195395456","rc":[{"atl":[[7,0]],"id":37672294}],"con":true,"img":false}]}
{"op":"mcm","clk":"5346886712","pt":1646099473990,"mc":[{"id":"1.195395456","rc":[{"atb":[[2.04,60.66],[2.06,0]],"id":22150928}],"con":true,"img":false}]}
{"op":"mcm","clk":"5346886721","pt":1646099474247,"mc":[{"id":"1.195395456","rc":[{"atb":[[1.1,973.84]],"id":43154433}],"con":true,"img":false}]}
{"op":"mcm","clk":"5346886727","pt":1646099474349,"mc":[{"id":"1.195395456","rc":[{"atb":[[1.12,0]],"id":43154433}],"con":true,"img":false}]}
{"op":"mcm","clk":"5346886753","pt":1646099475168,"mc":[{"id":"1.195395456","rc":[{"atb":[[2.06,77.23],[2.08,0]],"id":37672294}],"con":true,"img":false}]}
{"op":"mcm","clk":"5346886802","pt":1646099476857,"mc":[{"id":"1.195395456","rc":[{"atb":[[1.98,0]],"id":22150928}],"con":true,"img":false}]}
{"op":"mcm","clk":"5346886807","pt":1646099476961,"mc":[{"id":"1.195395456","rc":[{"atb":[[2.1,28.02]],"id":37672294},{"atb":[[1.99,0]],"id":22150928},{"atb":[[1.11,280.24]],"id":43154433}],"con":true,"img":false}]}
{"op":"mcm","clk":"5346886829","pt":1646099477676,"mc":[{"id":"1.195395456","rc":[{"atl":[[2.4,0]],"id":28002629},{"atb":[[1.11,485.93]],"id":43154433}],"con":true,"img":false}]}
{"op":"mcm","clk":"5346886836","pt":1646099477985,"mc":[{"id":"1.195395456","rc":[{"atb":[[1.12,485.93]],"id":43154433}],"con":true,"img":false}]}
{"op":"mcm","clk":"5346886838","pt":1646099478084,"mc":[{"id":"1.195395456","rc":[{"atb":[[1.1,0]],"id":43154433}],"con":true,"img":false}]}
{"op":"mcm","clk":"5346886848","pt":1646099478494,"mc":[{"id":"1.195395456","rc":[{"atl":[[5.7,0],[6.6,17.86]],"id":37672294}],"con":true,"img":false}]}
{"op":"mcm","clk":"5346886862","pt":1646099478855,"mc":[{"id":"1.195395456","rc":[{"atb":[[2.12,28.03]],"id":37672294}],"con":true,"img":false}]}
{"op":"mcm","clk":"5346886866","pt":1646099478958,"mc":[{"id":"1.195395456","rc":[{"atb":[[2.06,18.87]],"id":37672294},{"atl":[[2.52,82.24],[2.48,118.25]],"id":28002629}],"con":true,"img":false}]}
{"op":"mcm","clk":"5346886871","pt":1646099479060,"mc":[{"id":"1.195395456","rc":[{"atl":[[2.52,148.03]],"id":28002629}],"con":true,"img":false}]}
{"op":"mcm","clk":"5346886874","pt":1646099479162,"mc":[{"id":"1.195395456","rc":[{"atl":[[2.48,50.68]],"id":28002629}],"con":true,"img":false}]}
{"op":"mcm","clk":"5346886906","pt":1646099479986,"mc":[{"id":"1.195395456","rc":[{"atb":[[2.02,49.02]],"id":37672294},{"atl":[[2.9,26.32]],"id":42393370},{"atb":[[1.07,250]],"id":37267533},{"atb":[[1.79,63.29]],"id":37455733},{"atl":[[1.89,56.18]],"id":43154433}],"con":true,"img":false}]}
{"op":"mcm","clk":"5346886919","pt":1646099480293,"mc":[{"id":"1.195395456","rc":[{"atl":[[2.4,14.29]],"id":28002629}],"con":true,"img":false}]}
{"op":"mcm","clk":"5346886924","pt":1646099480394,"mc":[{"id":"1.195395456","rc":[{"atl":[[2.52,82.24],[2.48,118.25]],"id":28002629}],"con":true,"img":false}]}
{"op":"mcm","clk":"5346886942","pt":1646099480809,"mc":[{"id":"1.195395456","rc":[{"atb":[[1.97,31.78]],"id":22150928},{"atb":[[1.11,205.69]],"id":43154433}],"con":true,"img":false}]}
{"op":"mcm","clk":"5346886993","pt":1646099482291,"mc":[{"id":"1.195395456","rc":[{"atb":[[1.31,0]],"id":42393370},{"atb":[[2.08,6.89]],"id":22150928},{"atl":[[4.8,0]],"id":22150928}],"con":true,"img":false}]}
{"op":"mcm","clk":"5346886997","pt":1646099482394,"mc":[{"id":"1.195395456","rc":[{"atb":[[1.34,40.56]],"id":42393370},{"atl":[[4.1,13.08]],"id":22150928}],"con":true,"img":false}]}
{"op":"mcm","clk":"5346887011","pt":1646099482802,"mc":[{"id":"1.195395456","rc":[{"atb":[[2.04,0],[2.1,0]],"id":37672294},{"atb":[[2.04,0],[2.1,40.56]],"id":22150928},{"atb":[[1.11,0]],"id":43154433}],"con":true,"img":false}]}
{"op":"mcm","clk":"5346887019","pt":1646099482957,"mc":[{"id":"1.195395456","rc":[{"atb":[[2.02,98.04],[2.12,0]],"id":37672294}],"con":true,"img":false}]}
{"op":"mcm","clk":"5346887023","pt":1646099483058,"mc":[{"id":"1.195395456","rc":[{"atb":[[1.1,971.86]],"id":43154433}],"con":true,"img":false}]}
{"op":"mcm","clk":"5346887028","pt":1646099483163,"mc":[{"id":"1.195395456","rc":[{"atb":[[1.12,0]],"id":43154433}],"con":true,"img":false}]}
{"op":"mcm","clk":"5346887091","pt":1646099484807,"mc":[{"id":"1.195395456","rc":[{"atb":[[1.33,0]],"id":42393370},{"atb":[[1.97,0]],"id":22150928},{"atb":[[1.13,237.13]],"id":43154433}],"con":true,"img":false}]}
{"op":"mcm","clk":"5346887106","pt":1646099485264,"mc":[{"id":"1.195395456","rc":[{"atb":[[1.32,0]],"id":42393370},{"atb":[[2.08,0]],"id":22150928}],"con":true,"img":false}]}
{"op":"mcm","clk":"5346887110","pt":1646099485365,"mc":[{"id":"1.195395456","rc":[{"atb":[[2.04,81.12]],"id":22150928}],"con":true,"img":false}]}
{"op":"mcm","clk":"5346887113","pt":1646099485468,"mc":[{"id":"1.195395456","rc":[{"atb":[[2.1,0]],"id":22150928}],"con":true,"img":false}]}
{"op":"mcm","clk":"5346887143","pt":1646099486085,"mc":[{"id":"1.195395456","rc":[{"atb":[[1.98,0],[1.96,0],[1.94,0]],"id":37672294},{"atl":[[2.4,0]],"id":28002629},{"atb":[[1.5,0],[1.48,0],[1.52,0]],"id":37455733}],"con":true,"img":false}]}
{"op":"mcm","clk":"5346887147","pt":1646099486187,"mc":[{"id":"1.195395456","rc":[{"atl":[[2.52,148.03],[2.48,50.68]],"id":28002629}],"con":true,"img":false}]}
{"op":"mcm","clk":"5346887176","pt":1646099486702,"mc":[{"id":"1.195395456","rc":[{"atb":[[2.08,28.54]],"id":37672294},{"atb":[[1.14,237.13],[1.1,0]],"id":43154433}],"con":true,"img":false}]}
{"op":"mcm","clk":"5346887182","pt":1646099486804,"mc":[{"id":"1.195395456","rc":[{"atb":[[2.02,49.02],[2.1,28.54]],"id":37672294}],"con":true,"img":false}]}
{"op":"mcm","clk":"5346887205","pt":1646099487265,"mc":[{"id":"1.195395456","rc":[{"atl":[[5.7,21.28],[6.6,0]],"id":37672294}],"con":true,"img":false}]}
{"op":"mcm","clk":"5346887218","pt":1646099487675,"mc":[{"id":"1.195395456","rc":[{"atl":[[2.4,14.29]],"id":28002629}],"con":true,"img":false}]}
{"op":"mcm","clk":"5346887229","pt":1646099487880,"mc":[{"id":"1.195395456","rc":[{"atb":[[1.14,398.74]],"id":43154433}],"con":true,"img":false}]}
{"op":"mcm","clk":"5346887253","pt":1646099488293,"mc":[{"id":"1.195395456","rc":[{"atb":[[2.06,25.89]],"id":37672294}],"con":true,"img":false}]}
{"op":"mcm","clk":"5346887277","pt":1646099488908,"mc":[{"id":"1.195395456","rc":[{"atb":[[1.31,99.44]],"id":42393370},{"atb":[[1.97,31.78]],"id":22150928}],"con":true,"img":false}]}
{"op":"mcm","clk":"5346887299","pt":1646099489473,"mc":[{"id":"1.195395456","rc":[{"atb":[[2.08,7.73]],"id":22150928}],"con":true,"img":false}]}
{"op":"mcm","clk":"5346887322","pt":1646099489984,"mc":[{"id":"1.195395456","rc":[{"atb":[[1.99,75.76]],"id":37672294},{"atl":[[2.94,38.66]],"id":42393370},{"atb":[[1.05,250]],"id":37267533},{"atb":[[1.77,97.4]],"id":37455733},{"atl":[[1.91,82.42]],"id":43154433}],"con":true,"img":false}]}
{"op":"mcm","clk":"5346887341","pt":1646099490521,"mc":[{"id":"1.195395456","rc":[{"atb":[[1.31,144.06]],"id":42393370}],"con":true,"img":false}]}
{"op":"mcm","clk":"5346887349","pt":1646099490701,"mc":[{"id":"1.195395456","rc":[{"atb":[[2.08,0]],"id":37672294},{"atb":[[1.13,0]],"id":43154433}],"con":true,"img":false}]}
{"op":"mcm","clk":"5346887355","pt":1646099490804,"mc":[{"id":"1.195395456","rc":[{"atb":[[2.1,0],[2.08,57.08]],"id":37672294}],"con":true,"img":false}]}
{"op":"mcm","clk":"5346887377","pt":1646099491270,"mc":[{"id":"1.195395456","rc":[{"atb":[[2.06,18.87]],"id":37672294}],"con":true,"img":false}]}
{"op":"mcm","clk":"5346887383","pt":1646099491371,"mc":[{"id":"1.195395456","rc":[{"atb":[[2.02,124.97],[2.08,0]],"id":37672294}],"con":true,"img":false}]}
{"op":"mcm","clk":"5346887416","pt":1646099492196,"mc":[{"id":"1.195395456","rc":[{"atb":[[1.63,64.96],[1.97,0]],"id":37672294}],"con":true,"img":false}]}
{"op":"mcm","clk":"5346887421","pt":1646099492296,"mc":[{"id":"1.195395456","rc":[{"atb":[[2,0]],"id":37672294},{"atb":[[1.32,0]],"id":28002629},{"atb":[[1.34,0]],"id":42393370},{"atb":[[2.02,0]],"id":22150928}],"con":true,"img":false}]}
{"op":"mcm","clk":"5346887429","pt":1646099492399,"mc":[{"id":"1.195395456","rc":[{"atb":[[2.04,39]],"id":37672294},{"atb":[[1.35,99.39]],"id":28002629},{"atb":[[1.32,40.56]],"id":42393370},{"atb":[[2.06,40.56]],"id":22150928}],"con":true,"img":false}]}
{"op":"mcm","clk":"5346887439","pt":1646099492603,"mc":[{"id":"1.195395456","rc":[{"atb":[[1.97,0]],"id":22150928}],"con":true,"img":false}]}
{"op":"mcm","clk":"5346887467","pt":1646099493373,"mc":[{"id":"1.195395456","rc":[{"atl":[[2.4,0]],"id":28002629}],"con":true,"img":false}]}
{"op":"mcm","clk":"5346887497","pt":1646099494096,"mc":[{"id":"1.195395456","rc":[{"atb":[[2.04,0],[2.1,40.56]],"id":22150928}],"con":true,"img":false}]}
{"op":"mcm","clk":"5346887524","pt":1646099494607,"mc":[{"id":"1.195395456","rc":[{"atb":[[2.08,28.54]],"id":37672294},{"atb":[[1.34,52.73]],"id":28002629},{"atb":[[1.1,308.26]],"id":43154433}],"con":true,"img":false}]}
{"op":"mcm","clk":"5346887542","pt":1646099495068,"mc":[{"id":"1.195395456","rc":[{"atl":[[2.4,14.29]],"id":28002629}],"con":true,"img":false}]}
{"op":"mcm","clk":"5346887545","pt":1646099495173,"mc":[{"id":"1.195395456","rc":[{"atb":[[1.34,0]],"id":28002629},{"atl":[[2.38,34.72]],"id":28002629},{"atb":[[1.14,237.13]],"id":43154433}],"con":true,"img":false}]}
{"op":"mcm","clk":"5346887550","pt":1646099495275,"mc":[{"id":"1.195395456","rc":[{"atl":[[2.38,0],[2.52,82.24],[2.44,85.4]],"id":28002629},{"atb":[[1.11,474.26],[1.14,0]],"id":43154433}],"con":true,"img":false}]}
{"op":"mcm","clk":"5346887596","pt":1646099496400,"mc":[{"id":"1.195395456","rc":[{"atb":[[2.12,27.52]],"id":22150928}],"con":true,"img":false}]}
{"op":"mcm","clk":"5346887602","pt":1646099496502,"mc":[{"id":"1.195395456","rc":[{"atb":[[2.14,27.53]],"id":22150928}],"con":true,"img":false}]}
{"op":"mcm","clk":"5346887605","pt":1646099496607,"mc":[{"id":"1.195395456","rc":[{"atb":[[2.1,0]],"id":22150928}],"con":true,"img":false}]}
{"op":"mcm","clk":"5346887673","pt":1646099498503,"mc":[{"id":"1.195395456","rc":[{"atb":[[1.36,85.62]],"id":28002629}],"con":true,"img":false}]}
{"op":"mcm","clk":"5346887680","pt":1646099498813,"mc":[{"id":"1.195395456","rc":[{"atl":[[2.44,34.72],[2.48,118.25]],"id":28002629}],"con":true,"img":false}]}
{"op":"mcm","clk":"5346887729","pt":1646099499997,"mc":[{"id":"1.195395456","rc":[{"atb":[[2.02,49.02],[1.97,128.87],[2.1,28.54]],"id":37672294},{"atl":[[5.9,0]],"id":37672294},{"atl":[[2.98,63.13]],"id":42393370},{"atb":[[1.03,250]],"id":37267533},{"atl":[[9,0]],"id":37267533},{"atb":[[1.75,166.67]],"id":37455733},{"atl":[[1.93,134.41]],"id":43154433}],"con":true,"img":false}]}
{"op":"mcm","clk":"5346887735","pt":1646099500098,"mc":[{"id":"1.195395456","rc":[{"atl":[[4.8,8.63]],"id":37672294},{"atl":[[7.4,5.79]],"id":37267533},{"atb":[[1.07,506.09]],"id":43154433}],"con":true,"img":false}]}
{"op":"mcm","clk":"5346887743","pt":1646099500302,"mc":[{"id":"1.195395456","rc":[{"atb":[[2.08,35.43]],"id":37672294},{"atb":[[2.1,6.77]],"id":22150928}],"con":true,"img":false}]}
{"op":"mcm","clk":"5346887746","pt":1646099500406,"mc":[{"id":"1.195395456","rc":[{"atb":[[1.36,130.25]],"id":28002629},{"atb":[[2.12,0]],"id":22150928},{"atb":[[1.12,188.54]],"id":43154433}],"con":true,"img":false}]}
{"op":"mcm","clk":"5346887755","pt":1646099500614,"mc":[{"id":"1.195395456","rc":[{"atl":[[2.4,0]],"id":28002629},{"atl":[[6.4,0],[6.2,3.85]],"id":37267533}],"con":true,"img":false}]}
{"op":"mcm","clk":"5346887757","pt":1646099500714,"mc":[{"id":"1.195395456","rc":[{"atb":[[1.11,0],[1.13,308.27]],"id":43154433}],"con":true,"img":false}]}
{"op":"mcm","clk":"5346887798","pt":1646099501590,"mc":[{"id":"1.195395456","rc":[{"atb":[[2.12,55.06],[2.14,0]],"id":22150928}],"con":true,"img":false}]}
{"op":"mcm","clk":"5346887821","pt":1646099502206,"mc":[{"id":"1.195395456","rc":[{"atb":[[2.08,6.89]],"id":37672294},{"atl":[[2.4,14.29]],"id":28002629},{"atl":[[7.4,0]],"id":37267533},{"atl":[[2.22,0]],"id":43154433}],"con":true,"img":false}]}
{"op":"mcm","clk":"5346887824","pt":1646099502306,"mc":[{"id":"1.195395456","rc":[{"atl":[[9.2,5.79]],"id":37267533},{"atl":[[2.42,24.94]],"id":43154433}],"con":true,"img":false}]}
