{"op":"mcm","clk":"5346195392","pt":1646178339823,"mc":[{"id":"1.195453721","marketDefinition":{"bspMarket":false,"turnInPlayEnabled":false,"persistenceEnabled":false,"marketBaseRate":7.0,"eventId":"31272494","eventTypeId":"4339","numberOfWinners":1,"bettingType":"ODDS","marketType":"EXACTA","marketTime":"2022-03-02T09:33:00.000Z","suspendTime":"2022-03-02T09:33:00.000Z","bspReconciled":false,"complete":true,"inPlay":false,"crossMatching":false,"runnersVoidable":false,"numberOfActiveRunners":30,"betDelay":0,"status":"OPEN","runners":[{"status":"ACTIVE","sortPriority":1,"id":41419585,"name":"1 - 2"},{"status":"ACTIVE","sortPriority":2,"id":41419586,"name":"1 - 3"},{"status":"ACTIVE","sortPriority":3,"id":41419587,"name":"1 - 4"},{"status":"ACTIVE","sortPriority":4,"id":41419590,"name":"1 - 7"},{"status":"ACTIVE","sortPriority":5,"id":41419591,"name":"1 - 8"},{"status":"ACTIVE","sortPriority":6,"id":41419592,"name":"2 - 1"},{"status":"ACTIVE","sortPriority":7,"id":41419593,"name":"2 - 3"},{"status":"ACTIVE","sortPriority":8,"id":41419594,"name":"2 - 4"},{"status":"ACTIVE","sortPriority":9,"id":41419597,"name":"2 - 7"},{"status":"ACTIVE","sortPriority":10,"id":41419598,"name":"2 - 8"},{"status":"ACTIVE","sortPriority":11,"id":41419599,"name":"3 - 1"},{"status":"ACTIVE","sortPriority":12,"id":41419600,"name":"3 - 2"},{"status":"ACTIVE","sortPriority":13,"id":41419601,"name":"3 - 4"},{"status":"ACTIVE","sortPriority":14,"id":41419604,"name":"3 - 7"},{"status":"ACTIVE","sortPriority":15,"id":41419605,"name":"3 - 8"},{"status":"ACTIVE","sortPriority":16,"id":41419606,"name":"4 - 1"},{"status":"ACTIVE","sortPriority":17,"id":41419607,"name":"4 - 2"},{"status":"ACTIVE","sortPriority":18,"id":41419608,"name":"4 - 3"},{"status":"ACTIVE","sortPriority":19,"id":41419611,"name":"4 - 7"},{"status":"ACTIVE","sortPriority":20,"id":41419612,"name":"4 - 8"},{"status":"ACTIVE","sortPriority":21,"id":41419627,"name":"7 - 1"},{"status":"ACTIVE","sortPriority":22,"id":41419628,"name":"7 - 2"},{"status":"ACTIVE","sortPriority":23,"id":41419629,"name":"7 - 3"},{"status":"ACTIVE","sortPriority":24,"id":41419630,"name":"7 - 4"},{"status":"ACTIVE","sortPriority":25,"id":41419633,"name":"7 - 8"},{"status":"ACTIVE","sortPriority":26,"id":41419634,"name":"8 - 1"},{"status":"ACTIVE","sortPriority":27,"id":41419635,"name":"8 - 2"},{"status":"ACTIVE","sortPriority":28,"id":41419636,"name":"8 - 3"},{"status":"ACTIVE","sortPriority":29,"id":41419637,"name":"8 - 4"},{"status":"ACTIVE","sortPriority":30,"id":41419640,"name":"8 - 7"}],"regulators":["MR_INT"],"venue":"Traralgon","countryCode":"AU","discountAllowed":true,"timezone":"Australia/Sydney","openDate":"2022-03-02T08:31:00.000Z","version":4382480607,"name":"Exacta","eventName":"Traralgon (AUS) 2nd Mar"},"rc":[],"con":true,"img":false}]}
{"op":"mcm","clk":"5346203715","pt":1646178502896,"mc":[{"id":"1.195453721","rc":[{"atb":[[4.4,78.25],[7.8,29.34],[5.4,45.35]],"id":41419640},{"atb":[[18,15.65],[26,7.98],[55,3.69]],"id":41419607},{"atb":[[5.7,42.46],[8.4,26.96],[4.7,71.91]],"id":41419605},{"atb":[[4.3,80.63],[5.3,46.41],[7.6,30.23]],"id":41419636},{"atb":[[6.4,36.95],[5.2,63.35],[9.4,23.75]],"id":41419634},{"atb":[[17.5,12.09],[12.5,23.13],[30,6.88]],"id":41419611},{"atb":[[10,29.56],[25,8.31],[15,14.25]],"id":41419593},{"atb":[[12,18.14],[7.8,29.34],[5.9,54.3]],"id":41419591},{"atb":[[36,5.69],[19,11.08],[14,20.46]],"id":41419587},{"atb":[[16,13.3],[11,26.6],[27,7.67]],"id":41419601},{"atb":[[16.5,12.87],[9.6,23.2],[7.6,40.31]],"id":41419599},{"atb":[[16.5,12.87],[11.5,25.34],[28,7.39]],"id":41419630},{"atb":[[10.5,28],[26,7.98],[15.5,13.76]],"id":41419597},{"atb":[[24,8.67],[9.8,30.23],[14.5,14.78]],"id":41419628},{"atb":[[17,12.47],[12,24.19],[29,7.12]],"id":41419608},{"atb":[[40,5.11],[20,10.5],[15,19]],"id":41419606},{"atb":[[8.6,35.01],[19,11.08],[11.5,19]],"id":41419637},{"atb":[[6.2,51.17],[8.2,27.71],[13,16.63]],"id":41419604},{"atb":[[7.2,42.91],[9.2,24.33],[15.5,13.76]],"id":41419635},{"atb":[[16.5,12.87],[11.5,25.34],[28,7.39]],"id":41419585},{"atb":[[24,8.67],[9.8,30.23],[14.5,14.78]],"id":41419612},{"atb":[[17,12.47],[12,24.19],[29,7.12]],"id":41419592},{"atb":[[18,11.73],[10.5,21],[8.2,36.95]],"id":41419590},{"atb":[[8,38.01],[17.5,12.09],[10,22.17]],"id":41419586},{"atb":[[4.8,70.02],[8.6,26.26],[5.8,41.57]],"id":41419633},{"atb":[[22,9.5],[13.5,15.96],[9.4,31.67]],"id":41419600},{"atb":[[18.5,11.4],[11,19.95],[8.4,35.95]],"id":41419598},{"atb":[[6.2,51.17],[8.2,27.71],[13,16.63]],"id":41419629},{"atb":[[17,12.47],[9.8,22.67],[7.8,39.12]],"id":41419627},{"atb":[[18,15.65],[26,7.98],[55,3.69]],"id":41419594}],"con":true,"img":false}]}
{"op":"mcm","clk":"5346401438","pt":1646182002781,"mc":[{"id":"1.195453721","marketDefinition":{"bspMarket":false,"turnInPlayEnabled":false,"persistenceEnabled":false,"marketBaseRate":7.0,"eventId":"31272494","eventTypeId":"4339","numberOfWinners":1,"bettingType":"ODDS","marketType":"EXACTA","marketTime":"2022-03-02T09:33:00.000Z","suspendTime":"2022-03-02T09:33:00.000Z","bspReconciled":false,"complete":true,"inPlay":false,"crossMatching":false,"runnersVoidable":false,"numberOfActiveRunners":30,"betDelay":0,"status":"OPEN","runners":[{"status":"ACTIVE","sortPriority":1,"id":41419585,"name":"1 - 2"},{"status":"ACTIVE","sortPriority":2,"id":41419586,"name":"1 - 3"},{"status":"ACTIVE","sortPriority":3,"id":41419587,"name":"1 - 4"},{"status":"ACTIVE","sortPriority":4,"id":41419590,"name":"1 - 7"},{"status":"ACTIVE","sortPriority":5,"id":41419591,"name":"1 - 8"},{"status":"ACTIVE","sortPriority":6,"id":41419592,"name":"2 - 1"},{"status":"ACTIVE","sortPriority":7,"id":41419593,"name":"2 - 3"},{"status":"ACTIVE","sortPriority":8,"id":41419594,"name":"2 - 4"},{"status":"ACTIVE","sortPriority":9,"id":41419597,"name":"2 - 7"},{"status":"ACTIVE","sortPriority":10,"id":41419598,"name":"2 - 8"},{"status":"ACTIVE","sortPriority":11,"id":41419599,"name":"3 - 1"},{"status":"ACTIVE","sortPriority":12,"id":41419600,"name":"3 - 2"},{"status":"ACTIVE","sortPriority":13,"id":41419601,"name":"3 - 4"},{"status":"ACTIVE","sortPriority":14,"id":41419604,"name":"3 - 7"},{"status":"ACTIVE","sortPriority":15,"id":41419605,"name":"3 - 8"},{"status":"ACTIVE","sortPriority":16,"id":41419606,"name":"4 - 1"},{"status":"ACTIVE","sortPriority":17,"id":41419607,"name":"4 - 2"},{"status":"ACTIVE","sortPriority":18,"id":41419608,"name":"4 - 3"},{"status":"ACTIVE","sortPriority":19,"id":41419611,"name":"4 - 7"},{"status":"ACTIVE","sortPriority":20,"id":41419612,"name":"4 - 8"},{"status":"ACTIVE","sortPriority":21,"id":41419627,"name":"7 - 1"},{"status":"ACTIVE","sortPriority":22,"id":41419628,"name":"7 - 2"},{"status":"ACTIVE","sortPriority":23,"id":41419629,"name":"7 - 3"},{"status":"ACTIVE","sortPriority":24,"id":41419630,"name":"7 - 4"},{"status":"ACTIVE","sortPriority":25,"id":41419633,"name":"7 - 8"},{"status":"ACTIVE","sortPriority":26,"id":41419634,"name":"8 - 1"},{"status":"ACTIVE","sortPriority":27,"id":41419635,"name":"8 - 2"},{"status":"ACTIVE","sortPriority":28,"id":41419636,"name":"8 - 3"},{"status":"ACTIVE","sortPriority":29,"id":41419637,"name":"8 - 4"},{"status":"ACTIVE","sortPriority":30,"id":41419640,"name":"8 - 7"}],"regulators":["MR_INT"],"venue":"Traralgon","countryCode":"AU","discountAllowed":true,"timezone":"Australia/Sydney","openDate":"2022-03-02T08:31:00.000Z","version":4382480607,"name":"Exacta","eventName":"Traralgon (AUS) 2nd Mar"},"rc":[{"atb":[[4.4,78.26],[7.8,29.34],[5.4,45.36]],"id":41419640},{"atb":[[18,15.65],[26,7.98],[55,3.69]],"id":41419607},{"atb":[[5.7,42.46],[8.4,26.97],[4.7,71.92]],"id":41419605},{"atb":[[4.3,80.64],[5.3,46.41],[7.6,30.24]],"id":41419636},{"atb":[[6.4,36.96],[5.2,63.36],[9.4,23.75]],"id":41419634},{"atb":[[17.5,12.09],[12.5,23.13],[30,6.88]],"id":41419611},{"atb":[[10,29.56],[25,8.31],[15,14.25]],"id":41419593},{"atb":[[12,18.14],[7.8,29.34],[5.9,54.31]],"id":41419591},{"atb":[[36,5.7],[19,11.08],[14,20.47]],"id":41419587},{"atb":[[16,13.3],[11,26.61],[27,7.67]],"id":41419601},{"atb":[[16.5,12.87],[9.6,23.2],[7.6,40.32]],"id":41419599},{"atb":[[16.5,12.87],[11.5,25.34],[28,7.39]],"id":41419630},{"atb":[[10.5,28.01],[26,7.98],[15.5,13.76]],"id":41419597},{"atb":[[24,8.67],[9.8,30.24],[14.5,14.78]],"id":41419628},{"atb":[[17,12.47],[12,24.19],[29,7.12]],"id":41419608},{"atb":[[40,5.11],[20,10.5],[15,19]],"id":41419606},{"atb":[[8.6,35.01],[19,11.08],[11.5,19]],"id":41419637},{"atb":[[6.2,51.17],[8.2,27.72],[13,16.63]],"id":41419604},{"atb":[[7.2,42.92],[9.2,24.34],[15.5,13.76]],"id":41419635},{"atb":[[16.5,12.87],[11.5,25.34],[28,7.39]],"id":41419585},{"atb":[[24,8.67],[9.8,30.24],[14.5,14.78]],"id":41419612},{"atb":[[17,12.47],[12,24.19],[29,7.12]],"id":41419592},{"atb":[[18,11.73],[10.5,21],[8.2,36.96]],"id":41419590},{"atb":[[8,38.01],[17.5,12.09],[10,22.17]],"id":41419586},{"atb":[[4.8,70.02],[8.6,26.26],[5.8,41.58]],"id":41419633},{"atb":[[22,9.5],[13.5,15.96],[9.4,31.68]],"id":41419600},{"atb":[[18.5,11.4],[11,19.95],[8.4,35.95]],"id":41419598},{"atb":[[6.2,51.17],[8.2,27.72],[13,16.63]],"id":41419629},{"atb":[[17,12.47],[9.8,22.68],[7.8,39.13]],"id":41419627},{"atb":[[18,15.65],[26,7.98],[55,3.69]],"id":41419594}],"con":true,"img":true}]}
{"op":"mcm","clk":"5346480400","pt":1646183121968,"mc":[{"id":"1.195453721","rc":[{"atb":[[4.4,0],[7.8,0],[5.4,0]],"id":41419640},{"atb":[[18,0],[26,0],[55,0]],"id":41419607},{"atb":[[5.7,0],[8.4,0],[4.7,0]],"id":41419605},{"atb":[[4.3,0],[5.3,0],[7.6,0]],"id":41419636},{"atb":[[6.4,0],[5.2,0],[9.4,0]],"id":41419634},{"atb":[[17.5,0],[12.5,0],[30,0]],"id":41419611},{"atb":[[10,0],[25,0],[15,0]],"id":41419593},{"atb":[[12,0],[7.8,0],[5.9,0]],"id":41419591},{"atb":[[36,0],[19,0],[14,0]],"id":41419587},{"atb":[[16,0],[11,0],[27,0]],"id":41419601},{"atb":[[16.5,0],[9.6,0],[7.6,0]],"id":41419599},{"atb":[[16.5,0],[11.5,0],[28,0]],"id":41419630},{"atb":[[10.5,0],[26,0],[15.5,0]],"id":41419597},{"atb":[[24,0],[9.8,0],[14.5,0]],"id":41419628},{"atb":[[17,0],[12,0],[29,0]],"id":41419608},{"atb":[[40,0],[20,0],[15,0]],"id":41419606},{"atb":[[8.6,0],[19,0],[11.5,0]],"id":41419637},{"atb":[[6.2,0],[8.2,0],[13,0]],"id":41419604},{"atb":[[7.2,0],[9.2,0],[15.5,0]],"id":41419635},{"atb":[[16.5,0],[11.5,0],[28,0]],"id":41419585},{"atb":[[24,0],[9.8,0],[14.5,0]],"id":41419612},{"atb":[[17,0],[12,0],[29,0]],"id":41419592},{"atb":[[18,0],[10.5,0],[8.2,0]],"id":41419590},{"atb":[[8,0],[17.5,0],[10,0]],"id":41419586},{"atb":[[4.8,0],[8.6,0],[5.8,0]],"id":41419633},{"atb":[[22,0],[13.5,0],[9.4,0]],"id":41419600},{"atb":[[18.5,0],[11,0],[8.4,0]],"id":41419598},{"atb":[[6.2,0],[8.2,0],[13,0]],"id":41419629},{"atb":[[17,0],[9.8,0],[7.8,0]],"id":41419627},{"atb":[[18,0],[26,0],[55,0]],"id":41419594}],"con":true,"img":false}]}
{"op":"mcm","clk":"5346480902","pt":1646183129046,"mc":[{"id":"1.195453721","rc":[{"atb":[[4.3,80.76],[5.3,46.49],[7.6,30.29]],"id":41419605},{"atb":[[9.6,30.99],[23,9.08],[14,15.37]],"id":41419593},{"atb":[[6.8,45.95],[8.8,25.62],[14.5,14.8]],"id":41419591},{"atb":[[17.5,16.15],[50,4.07],[25,8.32]],"id":41419587},{"atb":[[17.5,12.11],[12.5,23.17],[30,6.89]],"id":41419601},{"atb":[[18,11.75],[10.5,21.04],[8.2,37.01]],"id":41419599},{"atb":[[24,8.69],[9.8,30.29],[14.5,14.8]],"id":41419597},{"atb":[[11,19.99],[7.4,31.23],[5.7,56.7]],"id":41419604},{"atb":[[32,6.45],[18,11.75],[13,22.2]],"id":41419585},{"atb":[[34,6.05],[18.5,11.42],[13.5,21.32]],"id":41419592},{"atb":[[19.5,10.8],[12,18.17],[8.8,34.17]],"id":41419590},{"atb":[[8.6,35.07],[19,11.1],[11.5,19.03]],"id":41419586},{"atb":[[9,33.31],[20,10.51],[12.5,17.38]],"id":41419600},{"atb":[[8,38.07],[17.5,12.11],[10,22.2]],"id":41419598},{"atb":[[70,2.89],[19.5,14.4],[29,7.13]],"id":41419594}],"con":true,"img":false}]}
{"op":"mcm","clk":"5346480908","pt":1646183129149,"mc":[{"id":"1.195453721","rc":[{"atb":[[7.2,32.24],[5.1,48.75],[4.1,85.98]],"id":41419640},{"atb":[[75,2.69],[20,14.03],[30,6.89]],"id":41419607},{"atb":[[4,88.84],[5,49.97],[7,33.31]],"id":41419636},{"atb":[[11,19.99],[7.4,31.23],[5.7,56.7]],"id":41419634},{"atb":[[38,5.4],[19.5,10.8],[14.5,19.74]],"id":41419611},{"atb":[[32,6.45],[18,11.75],[13,22.2]],"id":41419630},{"atb":[[9.2,32.5],[21,9.99],[13,16.65]],"id":41419628},{"atb":[[36,5.7],[19,11.1],[14,20.5]],"id":41419608},{"atb":[[18,15.67],[26,7.99],[55,3.7]],"id":41419606},{"atb":[[9.2,32.5],[21,9.99],[13,16.65]],"id":41419637},{"atb":[[8.6,26.3],[14,15.37],[6.6,47.59]],"id":41419635},{"atb":[[16,13.32],[11,26.65],[27,7.68]],"id":41419612},{"atb":[[8,28.55],[4.5,76.15],[5.5,44.42]],"id":41419633},{"atb":[[11,19.99],[7.4,31.23],[5.7,56.7]],"id":41419629},{"atb":[[18.5,11.42],[11,19.99],[8.4,36.01]],"id":41419627}],"con":true,"img":false}]}
{"op":"mcm","clk":"5347092349","pt":1646192802706,"mc":[{"id":"1.195453721","marketDefinition":{"bspMarket":false,"turnInPlayEnabled":false,"persistenceEnabled":false,"marketBaseRate":7.0,"eventId":"31272494","eventTypeId":"4339","numberOfWinners":1,"bettingType":"ODDS","marketType":"EXACTA","marketTime":"2022-03-02T09:33:00.000Z","suspendTime":"2022-03-02T09:33:00.000Z","bspReconciled":false,"complete":true,"inPlay":false,"crossMatching":false,"runnersVoidable":false,"numberOfActiveRunners":30,"betDelay":0,"status":"OPEN","runners":[{"status":"ACTIVE","sortPriority":1,"id":41419585,"name":"1 - 2"},{"status":"ACTIVE","sortPriority":2,"id":41419586,"name":"1 - 3"},{"status":"ACTIVE","sortPriority":3,"id":41419587,"name":"1 - 4"},{"status":"ACTIVE","sortPriority":4,"id":41419590,"name":"1 - 7"},{"status":"ACTIVE","sortPriority":5,"id":41419591,"name":"1 - 8"},{"status":"ACTIVE","sortPriority":6,"id":41419592,"name":"2 - 1"},{"status":"ACTIVE","sortPriority":7,"id":41419593,"name":"2 - 3"},{"status":"ACTIVE","sortPriority":8,"id":41419594,"name":"2 - 4"},{"status":"ACTIVE","sortPriority":9,"id":41419597,"name":"2 - 7"},{"status":"ACTIVE","sortPriority":10,"id":41419598,"name":"2 - 8"},{"status":"ACTIVE","sortPriority":11,"id":41419599,"name":"3 - 1"},{"status":"ACTIVE","sortPriority":12,"id":41419600,"name":"3 - 2"},{"status":"ACTIVE","sortPriority":13,"id":41419601,"name":"3 - 4"},{"status":"ACTIVE","sortPriority":14,"id":41419604,"name":"3 - 7"},{"status":"ACTIVE","sortPriority":15,"id":41419605,"name":"3 - 8"},{"status":"ACTIVE","sortPriority":16,"id":41419606,"name":"4 - 1"},{"status":"ACTIVE","sortPriority":17,"id":41419607,"name":"4 - 2"},{"status":"ACTIVE","sortPriority":18,"id":41419608,"name":"4 - 3"},{"status":"ACTIVE","sortPriority":19,"id":41419611,"name":"4 - 7"},{"status":"ACTIVE","sortPriority":20,"id":41419612,"name":"4 - 8"},{"status":"ACTIVE","sortPriority":21,"id":41419627,"name":"7 - 1"},{"status":"ACTIVE","sortPriority":22,"id":41419628,"name":"7 - 2"},{"status":"ACTIVE","sortPriority":23,"id":41419629,"name":"7 - 3"},{"status":"ACTIVE","sortPriority":24,"id":41419630,"name":"7 - 4"},{"status":"ACTIVE","sortPriority":25,"id":41419633,"name":"7 - 8"},{"status":"ACTIVE","sortPriority":26,"id":41419634,"name":"8 - 1"},{"status":"ACTIVE","sortPriority":27,"id":41419635,"name":"8 - 2"},{"status":"ACTIVE","sortPriority":28,"id":41419636,"name":"8 - 3"},{"status":"ACTIVE","sortPriority":29,"id":41419637,"name":"8 - 4"},{"status":"ACTIVE","sortPriority":30,"id":41419640,"name":"8 - 7"}],"regulators":["MR_INT"],"venue":"Traralgon","countryCode":"AU","discountAllowed":true,"timezone":"Australia/Sydney","openDate":"2022-03-02T08:31:00.000Z","version":4382480607,"name":"Exacta","eventName":"Traralgon (AUS) 2nd Mar"},"rc":[{"atb":[[7.2,32.29],[5.1,48.83],[4.1,86.12]],"id":41419640},{"atb":[[75,2.7],[20,14.05],[30,6.9]],"id":41419607},{"atb":[[4.3,80.9],[5.3,46.56],[7.6,30.34]],"id":41419605},{"atb":[[4,88.99],[5,50.06],[7,33.37]],"id":41419636},{"atb":[[11,20.02],[7.4,31.28],[5.7,56.8]],"id":41419634},{"atb":[[38,5.41],[19.5,10.82],[14.5,19.77]],"id":41419611},{"atb":[[9.6,31.04],[23,9.09],[14,15.4]],"id":41419593},{"atb":[[6.8,46.03],[8.8,25.67],[14.5,14.83]],"id":41419591},{"atb":[[17.5,16.17],[50,4.08],[25,8.34]],"id":41419587},{"atb":[[17.5,12.13],[12.5,23.21],[30,6.9]],"id":41419601},{"atb":[[18,11.77],[10.5,21.07],[8.2,37.08]],"id":41419599},{"atb":[[32,6.46],[18,11.77],[13,22.24]],"id":41419630},{"atb":[[24,8.7],[9.8,30.34],[14.5,14.83]],"id":41419597},{"atb":[[9.2,32.55],[21,10.01],[13,16.68]],"id":41419628},{"atb":[[36,5.71],[19,11.12],[14,20.53]],"id":41419608},{"atb":[[18,15.7],[26,8],[55,3.7]],"id":41419606},{"atb":[[9.2,32.55],[21,10.01],[13,16.68]],"id":41419637},{"atb":[[11,20.02],[7.4,31.28],[5.7,56.8]],"id":41419604},{"atb":[[8.6,26.34],[14,15.4],[6.6,47.67]],"id":41419635},{"atb":[[32,6.46],[18,11.77],[13,22.24]],"id":41419585},{"atb":[[16,13.34],[11,26.69],[27,7.7]],"id":41419612},{"atb":[[34,6.06],[18.5,11.44],[13.5,21.35]],"id":41419592},{"atb":[[19.5,10.82],[12,18.2],[8.8,34.23]],"id":41419590},{"atb":[[8.6,35.13],[19,11.12],[11.5,19.06]],"id":41419586},{"atb":[[8,28.6],[4.5,76.28],[5.5,44.49]],"id":41419633},{"atb":[[9,33.37],[20,10.53],[12.5,17.41]],"id":41419600},{"atb":[[8,38.14],[17.5,12.13],[10,22.24]],"id":41419598},{"atb":[[11,20.02],[7.4,31.28],[5.7,56.8]],"id":41419629},{"atb":[[18.5,11.44],[11,20.02],[8.4,36.07]],"id":41419627},{"atb":[[70,2.9],[19.5,14.43],[29,7.14]],"id":41419594}],"con":true,"img":true}]}
{"op":"mcm","clk":"5347381213","pt":1646198202724,"mc":[{"id":"1.195453721","marketDefinition":{"bspMarket":false,"turnInPlayEnabled":false,"persistenceEnabled":false,"marketBaseRate":7.0,"eventId":"31272494","eventTypeId":"4339","numberOfWinners":1,"bettingType":"ODDS","marketType":"EXACTA","marketTime":"2022-03-02T09:33:00.000Z","suspendTime":"2022-03-02T09:33:00.000Z","bspReconciled":false,"complete":true,"inPlay":false,"crossMatching":false,"runnersVoidable":false,"numberOfActiveRunners":30,"betDelay":0,"status":"OPEN","runners":[{"status":"ACTIVE","sortPriority":1,"id":41419585,"name":"1 - 2"},{"status":"ACTIVE","sortPriority":2,"id":41419586,"name":"1 - 3"},{"status":"ACTIVE","sortPriority":3,"id":41419587,"name":"1 - 4"},{"status":"ACTIVE","sortPriority":4,"id":41419590,"name":"1 - 7"},{"status":"ACTIVE","sortPriority":5,"id":41419591,"name":"1 - 8"},{"status":"ACTIVE","sortPriority":6,"id":41419592,"name":"2 - 1"},{"status":"ACTIVE","sortPriority":7,"id":41419593,"name":"2 - 3"},{"status":"ACTIVE","sortPriority":8,"id":41419594,"name":"2 - 4"},{"status":"ACTIVE","sortPriority":9,"id":41419597,"name":"2 - 7"},{"status":"ACTIVE","sortPriority":10,"id":41419598,"name":"2 - 8"},{"status":"ACTIVE","sortPriority":11,"id":41419599,"name":"3 - 1"},{"status":"ACTIVE","sortPriority":12,"id":41419600,"name":"3 - 2"},{"status":"ACTIVE","sortPriority":13,"id":41419601,"name":"3 - 4"},{"status":"ACTIVE","sortPriority":14,"id":41419604,"name":"3 - 7"},{"status":"ACTIVE","sortPriority":15,"id":41419605,"name":"3 - 8"},{"status":"ACTIVE","sortPriority":16,"id":41419606,"name":"4 - 1"},{"status":"ACTIVE","sortPriority":17,"id":41419607,"name":"4 - 2"},{"status":"ACTIVE","sortPriority":18,"id":41419608,"name":"4 - 3"},{"status":"ACTIVE","sortPriority":19,"id":41419611,"name":"4 - 7"},{"status":"ACTIVE","sortPriority":20,"id":41419612,"name":"4 - 8"},{"status":"ACTIVE","sortPriority":21,"id":41419627,"name":"7 - 1"},{"status":"ACTIVE","sortPriority":22,"id":41419628,"name":"7 - 2"},{"status":"ACTIVE","sortPriority":23,"id":41419629,"name":"7 - 3"},{"status":"ACTIVE","sortPriority":24,"id":41419630,"name":"7 - 4"},{"status":"ACTIVE","sortPriority":25,"id":41419633,"name":"7 - 8"},{"status":"ACTIVE","sortPriority":26,"id":41419634,"name":"8 - 1"},{"status":"ACTIVE","sortPriority":27,"id":41419635,"name":"8 - 2"},{"status":"ACTIVE","sortPriority":28,"id":41419636,"name":"8 - 3"},{"status":"ACTIVE","sortPriority":29,"id":41419637,"name":"8 - 4"},{"status":"ACTIVE","sortPriority":30,"id":41419640,"name":"8 - 7"}],"regulators":["MR_INT"],"venue":"Traralgon","countryCode":"AU","discountAllowed":true,"timezone":"Australia/Sydney","openDate":"2022-03-02T08:31:00.000Z","version":4382480607,"name":"Exacta","eventName":"Traralgon (AUS) 2nd Mar"},"rc":[{"atb":[[7.2,32.28],[5.1,48.81],[4.1,86.09]],"id":41419640},{"atb":[[75,2.7],[20,14.04],[30,6.9]],"id":41419607},{"atb":[[4.3,80.87],[5.3,46.55],[7.6,30.33]],"id":41419605},{"atb":[[4,88.95],[5,50.04],[7,33.36]],"id":41419636},{"atb":[[11,20.01],[7.4,31.27],[5.7,56.78]],"id":41419634},{"atb":[[38,5.41],[19.5,10.82],[14.5,19.77]],"id":41419611},{"atb":[[9.6,31.03],[23,9.09],[14,15.39]],"id":41419593},{"atb":[[6.8,46.01],[8.8,25.66],[14.5,14.82]],"id":41419591},{"atb":[[17.5,16.17],[50,4.08],[25,8.33]],"id":41419587},{"atb":[[17.5,12.13],[12.5,23.2],[30,6.9]],"id":41419601},{"atb":[[18,11.77],[10.5,21.07],[8.2,37.06]],"id":41419599},{"atb":[[32,6.45],[18,11.77],[13,22.23]],"id":41419630},{"atb":[[24,8.7],[9.8,30.33],[14.5,14.82]],"id":41419597},{"atb":[[9.2,32.54],[21,10],[13,16.68]],"id":41419628},{"atb":[[36,5.71],[19,11.12],[14,20.52]],"id":41419608},{"atb":[[18,15.69],[26,8],[55,3.7]],"id":41419606},{"atb":[[9.2,32.54],[21,10],[13,16.68]],"id":41419637},{"atb":[[11,20.01],[7.4,31.27],[5.7,56.78]],"id":41419604},{"atb":[[8.6,26.33],[14,15.39],[6.6,47.66]],"id":41419635},{"atb":[[32,6.45],[18,11.77],[13,22.23]],"id":41419585},{"atb":[[16,13.34],[11,26.68],[27,7.69]],"id":41419612},{"atb":[[34,6.06],[18.5,11.43],[13.5,21.34]],"id":41419592},{"atb":[[19.5,10.82],[12,18.19],[8.8,34.21]],"id":41419590},{"atb":[[8.6,35.11],[19,11.12],[11.5,19.06]],"id":41419586},{"atb":[[8,28.59],[4.5,76.25],[5.5,44.48]],"id":41419633},{"atb":[[9,33.36],[20,10.53],[12.5,17.4]],"id":41419600},{"atb":[[8,38.12],[17.5,12.13],[10,22.23]],"id":41419598},{"atb":[[11,20.01],[7.4,31.27],[5.7,56.78]],"id":41419629},{"atb":[[18.5,11.43],[11,20.01],[8.4,36.06]],"id":41419627},{"atb":[[70,2.89],[19.5,14.42],[29,7.14]],"id":41419594}],"con":true,"img":true}]}
{"op":"mcm","clk":"5347724377","pt":1646206380384,"mc":[{"id":"1.195453721","rc":[{"atb":[[8,2.72],[7.2,32.27],[5.1,48.8],[4.1,86.06],[7,3.27]],"id":41419640},{"atb":[[75,5.43],[20,14.04],[50,3.27],[30,6.89]],"id":41419607},{"atb":[[4.3,80.85],[5.3,46.53],[7.6,30.32]],"id":41419605},{"atb":[[4,88.93],[8,2.72],[5,50.02],[7,36.62]],"id":41419636},{"atb":[[11,20.01],[7.4,31.26],[5.7,56.76]],"id":41419634},{"atb":[[38,8.68],[19.5,10.81],[48,2.72],[14.5,19.76]],"id":41419611},{"atb":[[9.6,31.02],[34,2.72],[23,9.09],[27,3.27],[14,15.39]],"id":41419593},{"atb":[[6.8,46],[8.8,25.65],[14.5,14.82]],"id":41419591},{"atb":[[17.5,16.16],[38,3.27],[48,2.72],[50,4.08],[25,8.33]],"id":41419587},{"atb":[[32,2.72],[17.5,12.12],[12.5,23.19],[26,3.27],[30,6.89]],"id":41419601},{"atb":[[18,11.76],[18.5,3.27],[10.5,21.06],[8.2,37.05],[22,2.72]],"id":41419599},{"atb":[[32,6.45],[18,11.76],[25,3.27],[13,22.23],[30,2.72]],"id":41419630},{"atb":[[24,8.7],[9.8,30.32],[14.5,14.82]],"id":41419597},{"atb":[[9.2,32.53],[20,3.27],[21,10],[25,2.72],[13,16.67]],"id":41419628},{"atb":[[36,5.71],[19,11.11],[38,3.27],[48,2.72],[14,20.52]],"id":41419608},{"atb":[[65,2.72],[18,15.69],[46,3.27],[26,8],[55,3.7]],"id":41419606},{"atb":[[18,2.72],[9.2,32.53],[21,10],[13,16.67],[15.5,3.27]],"id":41419637},{"atb":[[16,2.72],[11,20.01],[7.4,31.26],[5.7,56.76],[13.5,3.27]],"id":41419604},{"atb":[[8.6,26.33],[11,3.27],[13.5,2.72],[14,15.39],[6.6,47.64]],"id":41419635},{"atb":[[32,6.45],[18,11.76],[40,2.72],[13,22.23],[30,3.27]],"id":41419585},{"atb":[[16,13.34],[38,2.72],[11,26.68],[27,7.69],[29,3.27]],"id":41419612},{"atb":[[34,9.33],[18.5,11.43],[44,2.72],[13.5,21.34]],"id":41419592},{"atb":[[19.5,10.81],[21,3.27],[12,18.19],[26,2.72],[8.8,34.2]],"id":41419590},{"atb":[[8.6,35.1],[19,11.11],[22,3.27],[11.5,19.05],[27,2.72]],"id":41419586},{"atb":[[8,28.58],[4.5,76.23],[5.5,44.47],[11,2.72],[9.4,3.27]],"id":41419633},{"atb":[[9,33.35],[20,10.52],[12.5,17.4]],"id":41419600},{"atb":[[8,38.11],[17.5,12.12],[10,22.23]],"id":41419598},{"atb":[[11,20.01],[7.4,31.26],[13,3.27],[5.7,56.76],[15.5,2.72]],"id":41419629},{"atb":[[18.5,11.43],[18,3.27],[21,2.72],[11,20.01],[8.4,36.05]],"id":41419627},{"atb":[[65,2.72],[70,2.89],[19.5,14.42],[46,3.27],[29,7.14]],"id":41419594}],"con":true,"img":false}]}
{"op":"mcm","clk":"5347724381","pt":1646206380483,"mc":[{"id":"1.195453721","rc":[{"atb":[[9.6,3.27],[11.5,2.72]],"id":41419605},{"atb":[[9.6,3.27],[11.5,2.72]],"id":41419634},{"atb":[[17.5,3.27],[20,2.72]],"id":41419591},{"atb":[[34,2.72],[27,3.27]],"id":41419597},{"atb":[[20,13.8],[25,2.72]],"id":41419600},{"atb":[[22,3.27],[27,2.72]],"id":41419598}],"con":true,"img":false}]}
{"op":"mcm","clk":"5347724598","pt":1646206386217,"mc":[{"id":"1.195453721","rc":[{"atb":[[7,33.35]],"id":41419636}],"con":true,"img":false}]}
{"op":"mcm","clk":"5347724612","pt":1646206386474,"mc":[{"id":"1.195453721","rc":[{"atb":[[8,0]],"id":41419636},{"atb":[[11,0],[13.5,0]],"id":41419635}],"con":true,"img":false}]}
{"op":"mcm","clk":"5347724623","pt":1646206386885,"mc":[{"id":"1.195453721","rc":[{"atb":[[6.8,3.27]],"id":41419636}],"con":true,"img":false}]}
{"op":"mcm","clk":"5347724636","pt":1646206387194,"mc":[{"id":"1.195453721","rc":[{"atb":[[10.5,3.27],[13,2.72]],"id":41419635}],"con":true,"img":false}]}
{"op":"mcm","clk":"5347724643","pt":1646206387297,"mc":[{"id":"1.195453721","rc":[{"atb":[[7.8,2.72]],"id":41419636}],"con":true,"img":false}]}
{"op":"mcm","clk":"5347752261","pt":1646207111945,"mc":[{"id":"1.195453721","rc":[{"atb":[[6.8,0]],"id":41419636}],"con":true,"img":false}]}
{"op":"mcm","clk":"5347752278","pt":1646207112148,"mc":[{"id":"1.195453721","rc":[{"atb":[[13,0]],"id":41419635}],"con":true,"img":false}]}
{"op":"mcm","clk":"5347752291","pt":1646207112349,"mc":[{"id":"1.195453721","rc":[{"atb":[[7.8,0]],"id":41419636},{"atb":[[10.5,0]],"id":41419635}],"con":true,"img":false}]}
{"op":"mcm","clk":"5347752313","pt":1646207112862,"mc":[{"id":"1.195453721","rc":[{"atb":[[7.2,3.27]],"id":41419636},{"atb":[[14,18.12]],"id":41419635}],"con":true,"img":false}]}
{"op":"mcm","clk":"5347752330","pt":1646207113133,"mc":[{"id":"1.195453721","rc":[{"atb":[[8.2,2.72]],"id":41419636},{"atb":[[11.5,3.27]],"id":41419635}],"con":true,"img":false}]}
{"op":"mcm","clk":"5347876539","pt":1646209488540,"mc":[{"id":"1.195453721","rc":[{"atb":[[34,0],[27,0]],"id":41419593},{"atb":[[17.5,0],[20,0]],"id":41419591},{"atb":[[18,0],[15.5,0]],"id":41419637}],"con":true,"img":false}]}
{"op":"mcm","clk":"5347876547","pt":1646209488646,"mc":[{"id":"1.195453721","rc":[{"atb":[[13,0],[15.5,0]],"id":41419629}],"con":true,"img":false}]}
{"op":"mcm","clk":"5347876584","pt":1646209489271,"mc":[{"id":"1.195453721","rc":[{"atb":[[36,2.72],[28,3.27]],"id":41419593},{"atb":[[18,3.27],[21,2.72]],"id":41419591},{"atb":[[17.5,2.72],[15,3.27]],"id":41419637}],"con":true,"img":false}]}
{"op":"mcm","clk":"5347876589","pt":1646209489365,"mc":[{"id":"1.195453721","rc":[{"atb":[[16,2.72],[13.5,3.27]],"id":41419629}],"con":true,"img":false}]}
{"op":"mcm","clk":"5347897899","pt":1646209923967,"mc":[{"id":"1.195453721","rc":[{"atb":[[7.2,0],[8.2,0]],"id":41419636}],"con":true,"img":false}]}
{"op":"mcm","clk":"5347897943","pt":1646209924945,"mc":[{"id":"1.195453721","rc":[{"atb":[[8,2.72],[7,36.62]],"id":41419636}],"con":true,"img":false}]}
{"op":"mcm","clk":"5347900374","pt":1646209983339,"mc":[{"id":"1.195453721","rc":[{"atb":[[3.5,40]],"id":41419640},{"atl":[[330,2]],"id":41419640},{"atb":[[28,3.7]],"id":41419607},{"atl":[[1000,2]],"id":41419607},{"atb":[[4,33.33]],"id":41419605},{"atl":[[370,2]],"id":41419605},{"atb":[[3.1,47.62]],"id":41419636},{"atl":[[230,2]],"id":41419636},{"atb":[[3.85,35.09]],"id":41419634},{"atl":[[350,2]],"id":41419634},{"atb":[[27,3.85]],"id":41419611},{"atl":[[1000,2]],"id":41419611},{"atb":[[7.6,15.15]],"id":41419593},{"atl":[[720,2]],"id":41419593},{"atb":[[4,29.66]],"id":41419591},{"atl":[[600,2]],"id":41419591},{"atb":[[11.5,8.16]],"id":41419587},{"atl":[[1000,2]],"id":41419587},{"atb":[[7,13.8]],"id":41419601},{"atl":[[650,2]],"id":41419601},{"atb":[[5.1,23.54]],"id":41419599},{"atl":[[520,2]],"id":41419599},{"atb":[[7.4,12.92]],"id":41419630},{"atl":[[690,2]],"id":41419630},{"atb":[[11,10]],"id":41419597},{"atl":[[870,2]],"id":41419597},{"atb":[[6.2,19.23]],"id":41419628},{"atl":[[570,2]],"id":41419628},{"atb":[[16,6.67]],"id":41419608},{"atl":[[970,2]],"id":41419608},{"atb":[[11.5,7.42]],"id":41419606},{"atl":[[1000,2]],"id":41419606},{"atb":[[4.5,20.02]],"id":41419637},{"atl":[[500,2]],"id":41419637},{"atb":[[5,25]],"id":41419604},{"atl":[[520,2]],"id":41419604},{"atb":[[3.8,35.71]],"id":41419635},{"atl":[[410,2]],"id":41419635},{"atb":[[11,10]],"id":41419585},{"atl":[[870,2]],"id":41419585},{"atb":[[4,15.4]],"id":41419612},{"atl":[[880,2]],"id":41419612},{"atb":[[11,10]],"id":41419592},{"atl":[[870,2]],"id":41419592},{"atb":[[9.6,11.63]],"id":41419590},{"atl":[[830,2]],"id":41419590},{"atb":[[7.4,15.62]],"id":41419586},{"atl":[[680,2]],"id":41419586},{"atb":[[3.8,35.71]],"id":41419633},{"atl":[[410,2]],"id":41419633},{"atb":[[5.6,21.74]],"id":41419600},{"atl":[[540,2]],"id":41419600},{"atb":[[7,16.67]],"id":41419598},{"atl":[[640,2]],"id":41419598},{"atb":[[4.1,32.26]],"id":41419629},{"atl":[[480,2]],"id":41419629},{"atb":[[5.6,21.74]],"id":41419627},{"atl":[[540,2]],"id":41419627},{"atb":[[11.5,6.56]],"id":41419594},{"atl":[[1000,2]],"id":41419594}],"con":true,"img":false}]}
{"op":"mcm","clk":"5347905055","pt":1646210101142,"mc":[{"id":"1.195453721","rc":[{"atb":[[17.5,0],[15,0]],"id":41419637}],"con":true,"img":false}]}
{"op":"mcm","clk":"5347905078","pt":1646210101805,"mc":[{"id":"1.195453721","rc":[{"atb":[[18,2.72],[15.5,3.27]],"id":41419637}],"con":true,"img":false}]}
{"op":"mcm","clk":"5347949134","pt":1646211100075,"mc":[{"id":"1.195453721","rc":[{"atl":[[600,0],[590,2]],"id":41419591},{"atl":[[650,0],[640,2]],"id":41419601},{"atl":[[690,0],[680,2]],"id":41419630},{"atl":[[950,2],[970,0]],"id":41419608},{"atl":[[480,2],[500,0]],"id":41419637},{"atl":[[850,2],[870,0]],"id":41419585},{"atl":[[880,0],[870,2]],"id":41419612},{"atl":[[860,2],[870,0]],"id":41419592},{"atl":[[830,0],[810,2]],"id":41419590},{"atl":[[660,2],[680,0]],"id":41419586}],"con":true,"img":false}]}
{"op":"mcm","clk":"5347949149","pt":1646211100481,"mc":[{"id":"1.195453721","rc":[{"atb":[[8,0],[7,33.35]],"id":41419636}],"con":true,"img":false}]}
{"op":"mcm","clk":"5347949189","pt":1646211101159,"mc":[{"id":"1.195453721","rc":[{"atb":[[7.2,3.27],[8.2,2.72]],"id":41419636}],"con":true,"img":false}]}
{"op":"mcm","clk":"5347950227","pt":1646211123634,"mc":[{"id":"1.195453721","rc":[{"atb":[[7.2,0],[8.2,0]],"id":41419636}],"con":true,"img":false}]}
{"op":"mcm","clk":"5347950267","pt":1646211124301,"mc":[{"id":"1.195453721","rc":[{"atb":[[8,2.72],[7,36.62]],"id":41419636}],"con":true,"img":false}]}
{"op":"mcm","clk":"5347960956","pt":1646211348433,"mc":[{"id":"1.195453721","rc":[{"atb":[[22,4.76],[28,0]],"id":41419607},{"atb":[[4,0],[3.5,40]],"id":41419605},{"atb":[[3.45,40.82],[3.85,0]],"id":41419634},{"atb":[[4,0],[6.2,19.23]],"id":41419591},{"atb":[[20,5.26],[11.5,0]],"id":41419587},{"atb":[[11.5,0],[25,4.17]],"id":41419606},{"atb":[[11,0],[7.4,15.62]],"id":41419585},{"atb":[[4,0],[10.5,10.53]],"id":41419612}],"con":true,"img":false}]}
{"op":"mcm","clk":"5347964778","pt":1646211427106,"mc":[{"id":"1.195453721","rc":[{"atb":[[21,0]],"id":41419591},{"trd":[[21,5.45]],"ltp":21.0,"tv":5.45,"id":41419591}],"con":true,"img":false}]}
{"op":"mcm","clk":"5347965113","pt":1646211434528,"mc":[{"id":"1.195453721","rc":[{"atb":[[27,0]],"id":41419598},{"trd":[[27,5.45]],"ltp":27.0,"tv":5.45,"id":41419598}],"con":true,"img":false}]}
{"op":"mcm","clk":"5347965920","pt":1646211449541,"mc":[{"id":"1.195453721","rc":[{"atb":[[9.6,2.18],[11.5,0]],"id":41419605},{"trd":[[9.6,2.17],[11.5,5.45]],"ltp":9.6,"tv":7.62,"id":41419605}],"con":true,"img":false}]}
{"op":"mcm","clk":"5347965957","pt":1646211450319,"mc":[{"id":"1.195453721","rc":[{"atb":[[9.6,0]],"id":41419605}],"con":true,"img":false}]}
{"op":"mcm","clk":"5347966171","pt":1646211454454,"mc":[{"id":"1.195453721","rc":[{"atb":[[16.5,2.72]],"id":41419591}],"con":true,"img":false}]}
{"op":"mcm","clk":"5347966477","pt":1646211461636,"mc":[{"id":"1.195453721","rc":[{"atb":[[20,2.72]],"id":41419598}],"con":true,"img":false}]}
{"op":"mcm","clk":"5347966600","pt":1646211464769,"mc":[{"id":"1.195453721","rc":[{"atb":[[11,0],[9.4,1.63]],"id":41419633},{"trd":[[9.4,3.27],[11,5.45]],"ltp":9.4,"tv":8.72,"id":41419633}],"con":true,"img":false}]}
{"op":"mcm","clk":"5347967042","pt":1646211476577,"mc":[{"id":"1.195453721","rc":[{"atb":[[7.2,2.72]],"id":41419605}],"con":true,"img":false}]}
{"op":"mcm","clk":"5347967050","pt":1646211476887,"mc":[{"id":"1.195453721","rc":[{"atb":[[6.2,3.27]],"id":41419605}],"con":true,"img":false}]}
{"op":"mcm","clk":"5347967676","pt":1646211491608,"mc":[{"id":"1.195453721","rc":[{"atb":[[8.4,2.72]],"id":41419633}],"con":true,"img":false}]}
{"op":"mcm","clk":"5347981020","pt":1646211782214,"mc":[{"id":"1.195453721","rc":[{"atb":[[8,2.72],[7.2,32.22],[5.1,48.72],[4.1,85.93],[7,3.26]],"id":41419640},{"atb":[[75,5.42],[20,14.02],[50,3.26],[30,6.88]],"id":41419607},{"atb":[[7.2,2.72],[4.3,80.72],[6.2,3.26],[5.3,46.46],[7.6,30.27]],"id":41419605},{"trd":[[9.6,2.16],[11.5,5.44]],"ltp":9.6,"tv":7.6,"id":41419605},{"atb":[[8,2.72],[4,88.79],[5,49.94],[7,36.56]],"id":41419636},{"atb":[[9.6,3.26],[11,19.97],[11.5,2.72],[7.4,31.21],[5.7,56.67]],"id":41419634},{"atb":[[38,8.67],[19.5,10.8],[48,2.72],[14.5,19.73]],"id":41419611},{"atb":[[9.6,30.97],[36,2.72],[23,9.07],[28,3.26],[14,15.36]],"id":41419593},{"atb":[[16.5,2.72],[18,3.26],[6.8,45.93],[8.8,25.61],[14.5,14.8]],"id":41419591},{"trd":[[21,5.44]],"ltp":21.0,"tv":5.44,"id":41419591},{"atb":[[17.5,16.14],[38,3.26],[48,2.72],[50,4.07],[25,8.32]],"id":41419587},{"atb":[[32,2.72],[17.5,12.1],[12.5,23.16],[26,3.26],[30,6.88]],"id":41419601},{"atb":[[18.5,3.26],[18,11.74],[10.5,21.03],[22,2.72],[8.2,36.99]],"id":41419599},{"atb":[[32,6.44],[18,11.74],[25,3.26],[13,22.19],[30,2.72]],"id":41419630},{"atb":[[34,2.72],[24,8.68],[9.8,30.27],[27,3.26],[14.5,14.8]],"id":41419597},{"atb":[[20,3.26],[9.2,32.48],[21,9.98],[25,2.72],[13,16.64]],"id":41419628},{"atb":[[36,5.7],[38,3.26],[19,11.1],[48,2.72],[14,20.49]],"id":41419608},{"atb":[[65,2.72],[18,15.66],[46,3.26],[26,7.98],[55,3.7]],"id":41419606},{"atb":[[18,0],[9.2,32.48],[21,9.98],[13,16.64],[15.5,0]],"id":41419637},{"atb":[[16,2.72],[11,19.97],[7.4,31.21],[13.5,3.26],[5.7,56.67]],"id":41419604},{"atb":[[8.6,26.29],[11.5,3.26],[14,18.09],[6.6,47.57]],"id":41419635},{"atb":[[32,6.44],[18,11.74],[40,2.72],[13,22.19],[30,3.26]],"id":41419585},{"atb":[[16,13.31],[38,2.72],[11,26.63],[27,7.68],[29,3.26]],"id":41419612},{"atb":[[34,9.32],[18.5,11.41],[44,2.72],[13.5,21.3]],"id":41419592},{"atb":[[19.5,10.8],[21,3.26],[12,18.16],[26,2.72],[8.8,34.15]],"id":41419590},{"atb":[[8.6,35.05],[19,11.1],[22,3.26],[11.5,19.02],[27,2.72]],"id":41419586},{"atb":[[8,28.54],[4.5,76.11],[5.5,44.4],[8.4,2.72],[9.4,1.63]],"id":41419633},{"trd":[[9.4,3.26],[11,5.44]],"ltp":9.4,"tv":8.7,"id":41419633},{"atb":[[9,33.29],[20,10.51],[25,0],[12.5,17.37]],"id":41419600},{"atb":[[8,38.05],[17.5,12.1],[20,2.72],[10,22.19],[22,3.26]],"id":41419598},{"trd":[[27,5.44]],"ltp":27.0,"tv":5.44,"id":41419598},{"atb":[[16,2.72],[11,19.97],[7.4,31.21],[13.5,3.26],[5.7,56.67]],"id":41419629},{"atb":[[18.5,11.41],[18,3.26],[21,2.72],[11,19.97],[8.4,35.99]],"id":41419627},{"atb":[[65,2.72],[70,2.89],[19.5,14.39],[46,3.26],[29,7.13]],"id":41419594}],"con":true,"img":false}]}
{"op":"mcm","clk":"5347981062","pt":1646211783033,"mc":[{"id":"1.195453721","rc":[{"atb":[[17.5,2.72],[15,3.26]],"id":41419637},{"atb":[[21,3.26],[26,2.72]],"id":41419600}],"con":true,"img":false}]}
{"op":"mcm","clk":"5347981068","pt":1646211783139,"mc":[{"id":"1.195453721","rc":[{"atb":[[3.5,0],[3.75,36.36]],"id":41419605},{"atl":[[630,2],[640,0]],"id":41419601},{"atb":[[5.6,21.74],[5.1,0]],"id":41419599},{"atb":[[5,0],[5.5,22.22]],"id":41419604},{"atl":[[520,0],[510,2]],"id":41419604},{"atl":[[390,2],[410,0]],"id":41419635},{"atl":[[660,0],[650,2]],"id":41419586},{"atb":[[4.1,32.26],[3.8,0]],"id":41419633},{"atl":[[410,0],[400,2]],"id":41419633},{"atb":[[5.6,0],[6.2,19.23]],"id":41419600},{"atl":[[540,0],[530,2]],"id":41419600},{"atl":[[630,2],[640,0]],"id":41419598},{"atb":[[5.6,0],[6.2,19.23]],"id":41419627},{"atl":[[540,0],[530,2]],"id":41419627}],"con":true,"img":false}]}
{"op":"mcm","clk":"5347984387","pt":1646211843418,"mc":[{"id":"1.195453721","rc":[{"atb":[[7.2,0],[6.2,0]],"id":41419605}],"con":true,"img":false}]}
{"op":"mcm","clk":"5347984420","pt":1646211844241,"mc":[{"id":"1.195453721","rc":[{"atb":[[6.4,3.26],[7.4,2.72]],"id":41419605}],"con":true,"img":false}]}
{"op":"mcm","clk":"5348009334","pt":1646212353720,"mc":[{"id":"1.195453721","rc":[{"atl":[[630,0]],"id":41419601},{"atb":[[5,25]],"id":41419599},{"atb":[[4.1,32.26]],"id":41419635}],"con":true,"img":false}]}
{"op":"mcm","clk":"5348009341","pt":1646212353824,"mc":[{"id":"1.195453721","rc":[{"atl":[[620,2]],"id":41419601},{"atb":[[5.6,0]],"id":41419599},{"atb":[[3.8,0]],"id":41419635},{"atl":[[650,0],[640,2]],"id":41419586}],"con":true,"img":false}]}
{"op":"mcm","clk":"5348009376","pt":1646212354036,"mc":[{"id":"1.195453721","rc":[{"atb":[[8,0],[7,33.29]],"id":41419636}],"con":true,"img":false}]}
{"op":"mcm","clk":"5348009527","pt":1646212355129,"mc":[{"id":"1.195453721","rc":[{"atb":[[7.2,3.26],[8.2,2.72]],"id":41419636}],"con":true,"img":false}]}
{"op":"mcm","clk":"5348010849","pt":1646212380577,"mc":[{"id":"1.195453721","rc":[{"atb":[[18,5.88],[22,0]],"id":41419607},{"atb":[[3.45,0],[3.85,35.09]],"id":41419634},{"atl":[[780,2],[810,0]],"id":41419590},{"atb":[[6.2,0],[5.5,22.22]],"id":41419627}],"con":true,"img":false}]}
{"op":"mcm","clk":"5348011771","pt":1646212399170,"mc":[{"id":"1.195453721","rc":[{"atl":[[570,0],[560,2]],"id":41419628},{"atl":[[860,2],[870,0]],"id":41419612},{"atl":[[390,2],[400,0]],"id":41419633}],"con":true,"img":false}]}
{"op":"mcm","clk":"5348011829","pt":1646212400304,"mc":[{"id":"1.195453721","rc":[{"atb":[[8.4,0]],"id":41419633}],"con":true,"img":false}]}
{"op":"mcm","clk":"5348011884","pt":1646212400975,"mc":[{"id":"1.195453721","rc":[{"atb":[[8.6,2.72]],"id":41419633}],"con":true,"img":false}]}
{"op":"mcm","clk":"5348012503","pt":1646212413200,"mc":[{"id":"1.195453721","rc":[{"atl":[[350,0],[340,2]],"id":41419634},{"atl":[[560,0],[570,2]],"id":41419628},{"atl":[[860,0],[870,2]],"id":41419612}],"con":true,"img":false}]}
{"op":"mcm","clk":"5348012515","pt":1646212413507,"mc":[{"id":"1.195453721","rc":[{"atb":[[7.2,0],[8.2,0]],"id":41419636}],"con":true,"img":false}]}
{"op":"mcm","clk":"5348012544","pt":1646212414228,"mc":[{"id":"1.195453721","rc":[{"atb":[[8,2.72],[7,36.56]],"id":41419636}],"con":true,"img":false}]}
{"op":"mcm","clk":"5348013337","pt":1646212429963,"mc":[{"id":"1.195453721","rc":[{"atb":[[16,0],[13.5,0]],"id":41419604}],"con":true,"img":false}]}
{"op":"mcm","clk":"5348013377","pt":1646212430626,"mc":[{"id":"1.195453721","rc":[{"atb":[[16.5,2.72],[14,3.26]],"id":41419604}],"con":true,"img":false}]}
{"op":"mcm","clk":"5348013417","pt":1646212431259,"mc":[{"id":"1.195453721","rc":[{"atb":[[8,0],[7,0]],"id":41419640},{"atb":[[17.5,0],[15,0]],"id":41419637},{"atb":[[21,0],[26,0]],"id":41419600}],"con":true,"img":false}]}
{"op":"mcm","clk":"5348013448","pt":1646212431921,"mc":[{"id":"1.195453721","rc":[{"atb":[[7.2,35.49],[8.2,2.72]],"id":41419640}],"con":true,"img":false}]}
{"op":"mcm","clk":"5348013463","pt":1646212432233,"mc":[{"id":"1.195453721","rc":[{"atb":[[20,13.78],[25,2.72]],"id":41419600}],"con":true,"img":false}]}
{"op":"mcm","clk":"5348013470","pt":1646212432336,"mc":[{"id":"1.195453721","rc":[{"atb":[[18,2.72],[15.5,3.26]],"id":41419637}],"con":true,"img":false}]}
{"op":"mcm","clk":"5348013541","pt":1646212433266,"mc":[{"id":"1.195453721","rc":[{"atb":[[75,2.72],[20,0],[30,0]],"id":41419607},{"atb":[[4.3,0],[5.3,0],[7.6,0]],"id":41419605},{"atb":[[38,3.26],[19.5,0],[14.5,0]],"id":41419611},{"atb":[[9.6,0],[23,0],[14,0]],"id":41419593},{"atb":[[6.8,0],[8.8,0],[14.5,0]],"id":41419591},{"atb":[[17.5,0],[50,0],[25,0]],"id":41419587},{"atb":[[17.5,0],[12.5,0],[30,0]],"id":41419601},{"atb":[[18,0],[10.5,0],[8.2,0]],"id":41419599},{"atb":[[24,0],[9.8,0],[14.5,0]],"id":41419597},{"atb":[[36,0],[19,0],[14,0]],"id":41419608},{"atb":[[18,0],[26,0],[55,0]],"id":41419606},{"atb":[[11,0],[7.4,0],[5.7,0]],"id":41419604},{"atb":[[32,0],[18,0],[13,0]],"id":41419585},{"atb":[[16,0],[11,0],[27,0]],"id":41419612},{"atb":[[34,3.26],[18.5,0],[13.5,0]],"id":41419592},{"atb":[[19.5,0],[12,0],[8.8,0]],"id":41419590},{"atb":[[8.6,0],[19,0],[11.5,0]],"id":41419586},{"atb":[[9,0],[20,3.26],[12.5,0]],"id":41419600},{"atb":[[8,0],[17.5,0],[10,0]],"id":41419598},{"atb":[[70,0],[19.5,0],[29,0]],"id":41419594}],"con":true,"img":false}]}
{"op":"mcm","clk":"5348013547","pt":1646212433366,"mc":[{"id":"1.195453721","rc":[{"atb":[[7.2,3.26],[5.1,0],[4.1,0]],"id":41419640},{"atb":[[4,0],[5,0],[7,3.26]],"id":41419636},{"atb":[[11,0],[7.4,0],[5.7,0]],"id":41419634},{"atb":[[32,0],[18,0],[13,0]],"id":41419630},{"atb":[[9.2,0],[21,0],[13,0]],"id":41419628},{"atb":[[9.2,0],[21,0],[13,0]],"id":41419637},{"atb":[[8.6,0],[14,2.72],[6.6,0]],"id":41419635},{"atb":[[8,0],[4.5,0],[5.5,0]],"id":41419633},{"atb":[[11,0],[7.4,0],[5.7,0]],"id":41419629},{"atb":[[18.5,0],[11,0],[8.4,0]],"id":41419627}],"con":true,"img":false}]}
{"op":"mcm","clk":"5348014046","pt":1646212443198,"mc":[{"id":"1.195453721","rc":[{"atb":[[4.8,52.57],[6.6,35.67],[3.9,91.85]],"id":41419640},{"atb":[[36,5.7],[90,2.24],[23,12.1]],"id":41419607},{"atb":[[4.4,78.34],[7.8,29.38],[5.4,45.4]],"id":41419605},{"atb":[[3.95,90.29],[6.8,34.44],[4.9,51.22]],"id":41419636},{"atb":[[10,22.19],[5.5,59.19],[7,33.29]],"id":41419634},{"atb":[[34,6.05],[18.5,11.41],[13.5,21.3]],"id":41419611},{"atb":[[16,13.31],[11,26.63],[27,7.68]],"id":41419593},{"atb":[[6.8,45.93],[8.8,25.61],[14.5,14.8]],"id":41419591},{"atb":[[17.5,16.14],[50,4.07],[25,8.32]],"id":41419587},{"atb":[[17.5,12.1],[12.5,23.16],[30,6.88]],"id":41419601},{"atb":[[18.5,14.68],[11,19.97],[8.4,35.99]],"id":41419599},{"atb":[[17,12.48],[12,24.21],[29,7.13]],"id":41419630},{"atb":[[10.5,28.03],[26,7.98],[15.5,13.77]],"id":41419597},{"atb":[[24,8.68],[9.8,30.27],[14.5,14.8]],"id":41419628},{"atb":[[36,5.7],[19,11.1],[14,20.49]],"id":41419608},{"atb":[[18,15.66],[26,7.98],[55,3.7]],"id":41419606},{"atb":[[19.5,10.8],[12,18.16],[8.8,34.15]],"id":41419637},{"atb":[[11,19.97],[7.4,31.21],[5.7,56.67]],"id":41419604},{"atb":[[9,24.97],[7,44.4],[15,14.27]],"id":41419635},{"atb":[[40,7.84],[20,10.51],[15,19.02]],"id":41419585},{"atb":[[10.5,38.56],[26,7.98],[15.5,13.77]],"id":41419612},{"atb":[[40,5.12],[20,10.51],[15,19.02]],"id":41419592},{"atb":[[19.5,10.8],[12,18.16],[8.8,34.15]],"id":41419590},{"atb":[[19.5,10.8],[12,18.16],[8.8,34.15]],"id":41419586},{"atb":[[4.3,80.72],[5.3,46.46],[7.6,30.27]],"id":41419633},{"atb":[[10,29.59],[25,11.04],[15,14.27]],"id":41419600},{"atb":[[8.6,35.05],[19,11.1],[11.5,19.02]],"id":41419598},{"atb":[[11,19.97],[7.4,31.21],[5.7,56.67]],"id":41419629},{"atb":[[18.5,11.41],[11,19.97],[8.4,35.99]],"id":41419627},{"atb":[[34,6.05],[85,2.37],[22,12.68]],"id":41419594}],"con":true,"img":false}]}
{"op":"mcm","clk":"5348014135","pt":1646212445061,"mc":[{"id":"1.195453721","rc":[{"atb":[[20,0]],"id":41419598}],"con":true,"img":false}]}
{"op":"mcm","clk":"5348014184","pt":1646212445775,"mc":[{"id":"1.195453721","rc":[{"atb":[[21,2.72]],"id":41419598}],"con":true,"img":false}]}
{"op":"mcm","clk":"5348014343","pt":1646212448498,"mc":[{"id":"1.195453721","rc":[{"atb":[[4,33.33],[3.75,0]],"id":41419605},{"atb":[[3.1,0],[3.7,37.04]],"id":41419636},{"atb":[[3.85,0],[3.4,41.67]],"id":41419634},{"atl":[[310,2],[340,0]],"id":41419634},{"atb":[[20,5.26],[27,0]],"id":41419611},{"atb":[[7.6,0],[8.8,12.82]],"id":41419593},{"atl":[[670,2],[720,0]],"id":41419593},{"atl":[[550,2],[590,0]],"id":41419591},{"atb":[[20,0],[12.5,8.7]],"id":41419587},{"atl":[[910,2],[1000,0]],"id":41419587},{"atb":[[8,13.8],[7,0]],"id":41419601},{"atb":[[5,0],[5.5,22.22]],"id":41419599},{"atl":[[660,2],[680,0]],"id":41419630},{"atb":[[8,14.29],[11,0]],"id":41419597},{"atl":[[770,2],[870,0]],"id":41419597},{"atl":[[950,0],[940,2]],"id":41419608},{"atb":[[16.5,6.45],[25,0]],"id":41419606},{"atl":[[980,2],[1000,0]],"id":41419606},{"atl":[[460,2],[480,0]],"id":41419637},{"atb":[[5.5,0],[6.6,17.86]],"id":41419604},{"atb":[[4.1,0],[3.7,37.04]],"id":41419635},{"atl":[[350,2],[390,0]],"id":41419635},{"atl":[[790,2],[850,0]],"id":41419585},{"atl":[[820,2],[870,0]],"id":41419612},{"atb":[[11,0],[7.6,15.12]],"id":41419592},{"atl":[[710,2],[860,0]],"id":41419592},{"atl":[[720,2],[780,0]],"id":41419590},{"atl":[[570,2],[630,0]],"id":41419598},{"atb":[[5.1,24.39],[4.1,0]],"id":41419629},{"atl":[[920,2]],"id":41419594}],"con":true,"img":false}]}
{"op":"mcm","clk":"5348014344","pt":1646212448558,"mc":[{"id":"1.195453721","rc":[{"atb":[[4,33.33],[3.5,0]],"id":41419640},{"atl":[[310,2],[330,0]],"id":41419640},{"atl":[[940,2],[1000,0]],"id":41419607},{"atl":[[910,2],[1000,0]],"id":41419611},{"atl":[[600,2],[620,0]],"id":41419601},{"atb":[[8.6,13.16],[7.4,0]],"id":41419630},{"atb":[[6.2,0],[7.6,15.15]],"id":41419628},{"atl":[[570,0],[550,2]],"id":41419628},{"atb":[[9.6,11.63],[7.4,0]],"id":41419586},{"atl":[[590,2],[640,0]],"id":41419586},{"atb":[[5.1,24.39],[4.1,0]],"id":41419633},{"atb":[[6.2,0],[7.4,15.62]],"id":41419600},{"atb":[[5.5,0],[6.6,17.86]],"id":41419627},{"atl":[[530,0],[520,2]],"id":41419627},{"atl":[[1000,0]],"id":41419594}],"con":true,"img":false}]}
{"op":"mcm","clk":"5348014356","pt":1646212448762,"mc":[{"id":"1.195453721","rc":[{"atb":[[11.5,0],[14,0]],"id":41419635}],"con":true,"img":false}]}
{"op":"mcm","clk":"5348014374","pt":1646212449067,"mc":[{"id":"1.195453721","rc":[{"atb":[[9.6,0],[11.5,0]],"id":41419634}],"con":true,"img":false}]}
{"op":"mcm","clk":"5348014402","pt":1646212449478,"mc":[{"id":"1.195453721","rc":[{"atb":[[10.5,3.26],[13,2.72]],"id":41419635}],"con":true,"img":false}]}
{"op":"mcm","clk":"5348014424","pt":1646212449837,"mc":[{"id":"1.195453721","rc":[{"atb":[[9,3.26],[10,24.92]],"id":41419634}],"con":true,"img":false}]}
{"op":"mcm","clk":"5348014973","pt":1646212460998,"mc":[{"id":"1.195453721","rc":[{"atb":[[4,0],[4.7,27.03]],"id":41419605},{"atb":[[3.85,35.09],[3.4,0]],"id":41419634},{"atl":[[280,2],[310,0]],"id":41419634},{"atl":[[620,2],[670,0]],"id":41419593},{"atl":[[530,2],[550,0]],"id":41419591},{"atb":[[12.5,0],[15,7.14]],"id":41419587},{"atl":[[820,2],[910,0]],"id":41419587},{"atb":[[8,0],[9.8,11.36]],"id":41419601},{"atb":[[6.4,18.52],[5.5,0]],"id":41419599},{"atl":[[620,2],[660,0]],"id":41419630},{"atb":[[8,0],[9.6,11.63]],"id":41419597},{"atl":[[710,2],[770,0]],"id":41419597},{"atl":[[850,2],[940,0]],"id":41419608},{"atb":[[16.5,0],[20,5.26]],"id":41419606},{"atl":[[880,2],[980,0]],"id":41419606},{"atl":[[440,2],[460,0]],"id":41419637},{"atb":[[8,14.29],[6.6,0]],"id":41419604},{"atb":[[3.7,0],[4.2,31.25]],"id":41419635},{"atl":[[720,2],[790,0]],"id":41419585},{"atl":[[740,2],[820,0]],"id":41419612},{"atb":[[9.2,12.2],[7.6,0]],"id":41419592},{"atl":[[660,2],[710,0]],"id":41419592},{"atl":[[650,2],[720,0]],"id":41419590},{"atl":[[540,2],[570,0]],"id":41419598},{"atb":[[5.1,0],[6,20]],"id":41419629},{"atl":[[830,2],[920,0]],"id":41419594}],"con":true,"img":false}]}
{"op":"mcm","clk":"5348015728","pt":1646212477318,"mc":[{"id":"1.195453721","rc":[{"atl":[[310,0],[320,2]],"id":41419640},{"atl":[[530,0],[520,2]],"id":41419591},{"atl":[[820,0],[800,2]],"id":41419587},{"atl":[[880,0],[870,2]],"id":41419606},{"atl":[[430,2],[440,0]],"id":41419637},{"atl":[[340,2]],"id":41419635},{"atl":[[700,2],[720,0]],"id":41419585},{"atl":[[660,0],[640,2]],"id":41419592}],"con":true,"img":false}]}
{"op":"mcm","clk":"5348015736","pt":1646212477423,"mc":[{"id":"1.195453721","rc":[{"atl":[[940,0],[930,2]],"id":41419607},{"atl":[[350,0]],"id":41419635},{"atl":[[540,0],[520,2]],"id":41419598},{"atl":[[830,0],[820,2]],"id":41419594}],"con":true,"img":false}]}
{"op":"mcm","clk":"5348015749","pt":1646212477620,"mc":[{"id":"1.195453721","rc":[{"atb":[[10.5,0],[13,0]],"id":41419635}],"con":true,"img":false}]}
{"op":"mcm","clk":"5348015767","pt":1646212478031,"mc":[{"id":"1.195453721","rc":[{"atb":[[22,0]],"id":41419598}],"con":true,"img":false}]}
{"op":"mcm","clk":"5348015785","pt":1646212478342,"mc":[{"id":"1.195453721","rc":[{"atb":[[10,3.26],[12.5,2.72]],"id":41419635}],"con":true,"img":false}]}
{"op":"mcm","clk":"5348015819","pt":1646212478709,"mc":[{"id":"1.195453721","rc":[{"atb":[[14.5,3.26]],"id":41419598}],"con":true,"img":false}]}
{"op":"mcm","clk":"5348016674","pt":1646212495055,"mc":[{"id":"1.195453721","rc":[{"atl":[[920,2]],"id":41419611}],"con":true,"img":false}]}
{"op":"mcm","clk":"5348016679","pt":1646212495105,"mc":[{"id":"1.195453721","rc":[{"atl":[[910,0]],"id":41419611}],"con":true,"img":false}]}
{"op":"mcm","clk":"5348017246","pt":1646212505364,"mc":[{"id":"1.195453721","rc":[{"atb":[[11.5,9.52]],"id":41419597}],"con":true,"img":false}]}
{"op":"mcm","clk":"5348017252","pt":1646212505474,"mc":[{"id":"1.195453721","rc":[{"atl":[[310,2],[320,0]],"id":41419640},{"atl":[[260,2],[280,0]],"id":41419634},{"atl":[[740,2],[800,0]],"id":41419587},{"atl":[[600,0],[590,2]],"id":41419601},{"atl":[[520,0],[510,2]],"id":41419599},{"atl":[[620,0],[610,2]],"id":41419630},{"atb":[[9.6,0]],"id":41419597},{"atl":[[850,0],[840,2]],"id":41419608},{"atl":[[860,2],[870,0]],"id":41419606},{"atl":[[730,2],[740,0]],"id":41419612},{"atl":[[650,0],[640,2]],"id":41419590},{"atl":[[590,0],[580,2]],"id":41419586},{"atb":[[8,14.29],[7,0]],"id":41419598}],"con":true,"img":false}]}
{"op":"mcm","clk":"5348017265","pt":1646212505776,"mc":[{"id":"1.195453721","rc":[{"atb":[[18,0],[15.5,0]],"id":41419637}],"con":true,"img":false}]}
{"op":"mcm","clk":"5348017279","pt":1646212505984,"mc":[{"id":"1.195453721","rc":[{"atb":[[9,0],[10,22.19]],"id":41419634}],"con":true,"img":false}]}
{"op":"mcm","clk":"5348017305","pt":1646212506446,"mc":[{"id":"1.195453721","rc":[{"atb":[[17.5,2.72],[15,3.26]],"id":41419637}],"con":true,"img":false}]}
{"op":"mcm","clk":"5348017327","pt":1646212506759,"mc":[{"id":"1.195453721","rc":[{"atb":[[9.8,2.72],[8.8,3.26]],"id":41419634}],"con":true,"img":false}]}
{"op":"mcm","clk":"5348017345","pt":1646212507067,"mc":[{"id":"1.195453721","rc":[{"atl":[[920,0],[910,2]],"id":41419611}],"con":true,"img":false}]}
{"op":"mcm","clk":"5348017791","pt":1646212515690,"mc":[{"id":"1.195453721","rc":[{"atl":[[910,0],[900,2]],"id":41419611}],"con":true,"img":false}]}
{"op":"mcm","clk":"5348017878","pt":1646212517346,"mc":[{"id":"1.195453721","rc":[{"atl":[[730,0],[720,2]],"id":41419612}],"con":true,"img":false}]}
{"op":"mcm","clk":"5348018902","pt":1646212536571,"mc":[{"id":"1.195453721","rc":[{"atb":[[8,0]],"id":41419636}],"con":true,"img":false}]}
{"op":"mcm","clk":"5348018913","pt":1646212536879,"mc":[{"id":"1.195453721","rc":[{"atb":[[7,0]],"id":41419636}],"con":true,"img":false}]}
{"op":"mcm","clk":"5348018929","pt":1646212537292,"mc":[{"id":"1.195453721","rc":[{"atb":[[8.2,2.72]],"id":41419636}],"con":true,"img":false}]}
{"op":"mcm","clk":"5348018943","pt":1646212537603,"mc":[{"id":"1.195453721","rc":[{"atb":[[7.2,3.26]],"id":41419636}],"con":true,"img":false}]}
{"op":"mcm","clk":"5348021781","pt":1646212594188,"mc":[{"id":"1.195453721","rc":[{"atb":[[10,0]],"id":41419635}],"con":true,"img":false}]}
{"op":"mcm","clk":"5348021800","pt":1646212594550,"mc":[{"id":"1.195453721","rc":[{"atb":[[12.5,0]],"id":41419635}],"con":true,"img":false}]}
{"op":"mcm","clk":"5348021813","pt":1646212594860,"mc":[{"id":"1.195453721","rc":[{"atb":[[14.5,0]],"id":41419598}],"con":true,"img":false}]}
{"op":"mcm","clk":"5348021821","pt":1646212595167,"mc":[{"id":"1.195453721","rc":[{"atb":[[10.5,3.26]],"id":41419635}],"con":true,"img":false}]}
{"op":"mcm","clk":"5348021832","pt":1646212595476,"mc":[{"id":"1.195453721","rc":[{"atb":[[13,2.72]],"id":41419635}],"con":true,"img":false}]}
{"op":"mcm","clk":"5348021840","pt":1646212595580,"mc":[{"id":"1.195453721","rc":[{"atl":[[830,2],[840,0]],"id":41419608}],"con":true,"img":false}]}
{"op":"mcm","clk":"5348021857","pt":1646212595891,"mc":[{"id":"1.195453721","rc":[{"atb":[[18,3.26]],"id":41419598}],"con":true,"img":false}]}
{"op":"mcm","clk":"5348024994","pt":1646212647350,"mc":[{"id":"1.195453721","rc":[{"atb":[[8.2,0]],"id":41419636}],"con":true,"img":false}]}
{"op":"mcm","clk":"5348025004","pt":1646212647555,"mc":[{"id":"1.195453721","rc":[{"atb":[[7.2,0]],"id":41419636}],"con":true,"img":false}]}
{"op":"mcm","clk":"5348025029","pt":1646212648070,"mc":[{"id":"1.195453721","rc":[{"atb":[[8.4,2.72]],"id":41419636}],"con":true,"img":false}]}
{"op":"mcm","clk":"5348025049","pt":1646212648431,"mc":[{"id":"1.195453721","rc":[{"atb":[[7.4,3.26]],"id":41419636}],"con":true,"img":false}]}
{"op":"mcm","clk":"5348025313","pt":1646212653281,"mc":[{"id":"1.195453721","rc":[{"atl":[[890,2],[900,0]],"id":41419611},{"atl":[[590,0],[580,2]],"id":41419601},{"atl":[[600,2],[610,0]],"id":41419630},{"atl":[[830,0],[820,2]],"id":41419608},{"atl":[[860,0],[850,2]],"id":41419606},{"atb":[[9.2,0],[10.5,10.53]],"id":41419592}],"con":true,"img":false}]}
{"op":"mcm","clk":"5348025331","pt":1646212653538,"mc":[{"id":"1.195453721","rc":[{"atb":[[9.8,0],[8.8,0]],"id":41419634}],"con":true,"img":false}]}
{"op":"mcm","clk":"5348025372","pt":1646212654234,"mc":[{"id":"1.195453721","rc":[{"atb":[[9,3.26],[10,24.92]],"id":41419634}],"con":true,"img":false}]}
{"op":"mcm","clk":"5348025767","pt":1646212661295,"mc":[{"id":"1.195453721","rc":[{"atb":[[6.8,17.24]],"id":41419604}],"con":true,"img":false}]}
{"op":"mcm","clk":"5348025771","pt":1646212661397,"mc":[{"id":"1.195453721","rc":[{"atb":[[8,0]],"id":41419604}],"con":true,"img":false}]}
{"op":"mcm","clk":"5348025785","pt":1646212661553,"mc":[{"id":"1.195453721","rc":[{"atb":[[17.5,0],[15,0]],"id":41419637}],"con":true,"img":false}]}
{"op":"mcm","clk":"5348025837","pt":1646212662582,"mc":[{"id":"1.195453721","rc":[{"atb":[[18,2.72],[15.5,3.26]],"id":41419637}],"con":true,"img":false}]}
{"op":"mcm","clk":"5348025908","pt":1646212663667,"mc":[{"id":"1.195453721","rc":[{"atl":[[570,2]],"id":41419601}],"con":true,"img":false}]}
{"op":"mcm","clk":"5348025912","pt":1646212663771,"mc":[{"id":"1.195453721","rc":[{"atl":[[580,0]],"id":41419601}],"con":true,"img":false}]}
{"op":"mcm","clk":"5348026819","pt":1646212682004,"mc":[{"id":"1.195453721","rc":[{"atb":[[18,0],[15.5,0]],"id":41419637}],"con":true,"img":false}]}
{"op":"mcm","clk":"5348026860","pt":1646212682736,"mc":[{"id":"1.195453721","rc":[{"atb":[[17.5,2.72],[15,3.26]],"id":41419637}],"con":true,"img":false}]}
{"op":"mcm","clk":"5348027795","pt":1646212699432,"mc":[{"id":"1.195453721","rc":[{"atb":[[10.5,0]],"id":41419635}],"con":true,"img":false}]}
{"op":"mcm","clk":"5348027821","pt":1646212699850,"mc":[{"id":"1.195453721","rc":[{"atb":[[13,0]],"id":41419635}],"con":true,"img":false}]}
{"op":"mcm","clk":"5348027838","pt":1646212700153,"mc":[{"id":"1.195453721","rc":[{"atb":[[11,3.26]],"id":41419635}],"con":true,"img":false}]}
{"op":"mcm","clk":"5348027882","pt":1646212700822,"mc":[{"id":"1.195453721","rc":[{"atb":[[13.5,2.72]],"id":41419635}],"con":true,"img":false}]}
{"op":"mcm","clk":"5348028589","pt":1646212715060,"mc":[{"id":"1.195453721","rc":[{"atb":[[7.4,0],[8.4,0]],"id":41419636},{"atb":[[38,0],[48,0]],"id":41419587},{"atb":[[40,5.12],[30,0]],"id":41419585},{"atb":[[34,0],[44,0]],"id":41419592},{"atb":[[21,0],[26,0]],"id":41419590},{"atb":[[22,0],[27,0]],"id":41419586},{"atb":[[18,0],[21,0]],"id":41419627}],"con":true,"img":false}]}
{"op":"mcm","clk":"5348028633","pt":1646212715733,"mc":[{"id":"1.195453721","rc":[{"atb":[[32,3.26],[42,2.72]],"id":41419585},{"atb":[[23,3.26],[28,2.72]],"id":41419590},{"atb":[[18.5,14.68],[22,2.72]],"id":41419627}],"con":true,"img":false}]}
{"op":"mcm","clk":"5348028642","pt":1646212715833,"mc":[{"id":"1.195453721","rc":[{"atb":[[7.2,3.26],[8.2,2.72]],"id":41419636},{"atb":[[40,3.26],[50,6.8]],"id":41419587},{"atb":[[36,3.26],[46,2.72]],"id":41419592},{"atb":[[23,3.26],[28,2.72]],"id":41419586}],"con":true,"img":false}]}
{"op":"mcm","clk":"5348028719","pt":1646212717073,"mc":[{"id":"1.195453721","rc":[{"atb":[[11,0],[13.5,0]],"id":41419635}],"con":true,"img":false}]}
{"op":"mcm","clk":"5348028762","pt":1646212718055,"mc":[{"id":"1.195453721","rc":[{"atb":[[10.5,3.26],[13,2.72]],"id":41419635}],"con":true,"img":false}]}
{"op":"mcm","clk":"5348029237","pt":1646212726886,"mc":[{"id":"1.195453721","rc":[{"atl":[[920,2],[930,0]],"id":41419607}],"con":true,"img":false}]}
{"op":"mcm","clk":"5348029913","pt":1646212739562,"mc":[{"id":"1.195453721","rc":[{"atl":[[530,0],[520,2]],"id":41419600}],"con":true,"img":false}]}
{"op":"mcm","clk":"5348030137","pt":1646212743627,"mc":[{"id":"1.195453721","rc":[{"atb":[[4.8,0],[6.6,0],[3.9,0]],"id":41419640},{"atb":[[36,0],[90,0],[23,0]],"id":41419607},{"atb":[[4.4,0],[7.8,0],[5.4,0]],"id":41419605},{"atb":[[3.95,0],[6.8,0],[4.9,0]],"id":41419636},{"atb":[[10,2.72],[5.5,0],[7,0]],"id":41419634},{"atb":[[34,0],[18.5,0],[13.5,0]],"id":41419611},{"atb":[[16,0],[11,0],[27,0]],"id":41419593},{"atb":[[6.8,0],[8.8,0],[14.5,0]],"id":41419591},{"atb":[[17.5,0],[50,2.72],[25,0]],"id":41419587},{"atb":[[17.5,0],[12.5,0],[30,0]],"id":41419601},{"atb":[[18.5,3.26],[11,0],[8.4,0]],"id":41419599},{"atb":[[17,0],[12,0],[29,0]],"id":41419630},{"atb":[[10.5,0],[26,0],[15.5,0]],"id":41419597},{"atb":[[24,0],[9.8,0],[14.5,0]],"id":41419628},{"atb":[[36,0],[19,0],[14,0]],"id":41419608},{"atb":[[18,0],[26,0],[55,0]],"id":41419606},{"atb":[[19.5,0],[12,0],[8.8,0]],"id":41419637},{"atb":[[11,0],[7.4,0],[5.7,0]],"id":41419604},{"atb":[[9,0],[7,0],[15,0]],"id":41419635},{"atb":[[40,0],[20,0],[15,0]],"id":41419585},{"atb":[[10.5,10.53],[26,0],[15.5,0]],"id":41419612},{"atb":[[40,0],[20,0],[15,0]],"id":41419592},{"atb":[[19.5,0],[12,0],[8.8,0]],"id":41419590},{"atb":[[19.5,0],[12,0],[8.8,0]],"id":41419586},{"atb":[[4.3,0],[5.3,0],[7.6,0]],"id":41419633},{"atb":[[10,0],[25,2.72],[15,0]],"id":41419600},{"atb":[[8.6,0],[19,0],[11.5,0]],"id":41419598},{"atb":[[11,0],[7.4,0],[5.7,0]],"id":41419629},{"atb":[[18.5,3.26],[11,0],[8.4,0]],"id":41419627},{"atb":[[34,0],[85,0],[22,0]],"id":41419594}],"con":true,"img":false}]}
{"op":"mcm","clk":"5348030182","pt":1646212744599,"mc":[{"id":"1.195453721","rc":[{"atl":[[880,2]],"id":41419611},{"atl":[[820,0],[810,2]],"id":41419608}],"con":true,"img":false}]}
{"op":"mcm","clk":"5348030188","pt":1646212744703,"mc":[{"id":"1.195453721","rc":[{"atl":[[890,0]],"id":41419611}],"con":true,"img":false}]}
{"op":"mcm","clk":"5348030362","pt":1646212748419,"mc":[{"id":"1.195453721","rc":[{"atb":[[4.8,35.05],[3.4,110.99],[2.96,135.91]],"id":41419640},{"atb":[[16.5,17.18],[36,3.8],[11.5,25.36]],"id":41419607},{"atb":[[3.2,121.08],[3.7,98.66],[5.4,30.27]],"id":41419605},{"atb":[[3.45,108.73],[4.9,34.15],[2.98,134.54]],"id":41419636},{"atb":[[4.5,76.11],[7,22.19],[3.75,96.87]],"id":41419634},{"atb":[[18.5,7.61],[7.4,41.62],[9.4,31.71]],"id":41419611},{"atb":[[16,8.87],[6.4,49.33],[8.4,35.99]],"id":41419593},{"atb":[[8.8,17.07],[4.4,78.34],[5.4,60.54]],"id":41419591},{"atb":[[9,33.29],[25,5.54],[12.5,23.16]],"id":41419587},{"atb":[[17.5,8.07],[9,33.29],[7,44.4]],"id":41419601},{"atb":[[6.4,67.85],[11,13.31],[5.2,63.42]],"id":41419599},{"atb":[[17,8.32],[6.8,45.93],[8.8,34.15]],"id":41419630},{"atb":[[6.2,51.22],[8.2,36.99],[15.5,9.18]],"id":41419597},{"atb":[[7.8,39.17],[14.5,9.86],[5.9,54.36]],"id":41419628},{"atb":[[9.6,30.97],[19,7.4],[7.6,40.36]],"id":41419608},{"atb":[[9.2,32.48],[26,5.32],[13,22.19]],"id":41419606},{"atb":[[12,12.1],[6.8,45.93],[5.4,60.54]],"id":41419637},{"atb":[[3.85,93.47],[7.4,20.81],[4.7,71.99]],"id":41419604},{"atb":[[9,16.64],[4.5,76.11],[5.5,59.19]],"id":41419635},{"atb":[[8,38.05],[20,7],[10,29.59]],"id":41419585},{"atb":[[6.2,51.22],[8.2,36.99],[15.5,9.18]],"id":41419612},{"atb":[[8,38.05],[20,7],[10,29.59]],"id":41419592},{"atb":[[12,12.1],[6.8,45.93],[5.4,60.54]],"id":41419590},{"atb":[[12,12.1],[6.8,45.93],[5.4,60.54]],"id":41419586},{"atb":[[5.3,30.97],[3.15,123.9],[3.65,100.52]],"id":41419633},{"atb":[[8,38.05],[6,53.27],[15,9.51]],"id":41419600},{"atb":[[5.3,61.94],[11.5,12.68],[6.6,47.57]],"id":41419598},{"atb":[[3.85,93.47],[7.4,20.81],[4.7,71.99]],"id":41419629},{"atb":[[6.4,49.33],[11,13.31],[5.2,63.42]],"id":41419627},{"atb":[[16,17.76],[34,4.03],[11,26.63]],"id":41419594}],"con":true,"img":false}]}
{"op":"mcm","clk":"5348031039","pt":1646212762414,"mc":[{"id":"1.195453721","rc":[{"atb":[[6.4,0],[7.4,0]],"id":41419605}],"con":true,"img":false}]}
{"op":"mcm","clk":"5348031096","pt":1646212763399,"mc":[{"id":"1.195453721","rc":[{"atb":[[7.6,2.72],[6.6,3.26]],"id":41419605}],"con":true,"img":false}]}
{"op":"mcm","clk":"5348032726","pt":1646212793076,"mc":[{"id":"1.195453721","rc":[{"atb":[[17,6.25],[20,0]],"id":41419606}],"con":true,"img":false}]}
{"op":"mcm","clk":"5348033298","pt":1646212803779,"mc":[{"id":"1.195453721","rc":[{"atl":[[850,0],[840,2]],"id":41419606}],"con":true,"img":false}]}
{"op":"mcm","clk":"5348033597","pt":1646212809985,"mc":[{"id":"1.195453721","rc":[{"atb":[[10.5,0]],"id":41419635}],"con":true,"img":false}]}
{"op":"mcm","clk":"5348033600","pt":1646212810087,"mc":[{"id":"1.195453721","rc":[{"atb":[[13,0]],"id":41419635}],"con":true,"img":false}]}
{"op":"mcm","clk":"5348033622","pt":1646212810709,"mc":[{"id":"1.195453721","rc":[{"atb":[[11,3.26]],"id":41419635}],"con":true,"img":false}]}
{"op":"mcm","clk":"5348033639","pt":1646212810970,"mc":[{"id":"1.195453721","rc":[{"atb":[[13.5,2.72]],"id":41419635}],"con":true,"img":false}]}
{"op":"mcm","clk":"5348035423","pt":1646212840414,"mc":[{"id":"1.195453721","rc":[{"atb":[[18,0],[27,3.85]],"id":41419607},{"atb":[[3.95,33.9],[3.7,0]],"id":41419636},{"atl":[[220,2],[230,0]],"id":41419636},{"atb":[[6.2,0],[7.4,15.62]],"id":41419591},{"atl":[[520,0],[510,2]],"id":41419591},{"atb":[[9.8,0],[8.4,13.51]],"id":41419601},{"atl":[[770,2],[810,0]],"id":41419608},{"atb":[[17,0],[19.5,5.41]],"id":41419606},{"atl":[[800,2],[840,0]],"id":41419606},{"atb":[[7.4,0],[9.8,11.36]],"id":41419585},{"atb":[[9.6,0],[8.4,13.51]],"id":41419586}],"con":true,"img":false}]}
{"op":"mcm","clk":"5348035454","pt":1646212841134,"mc":[{"id":"1.195453721","rc":[{"atb":[[10,11.11],[8.8,0]],"id":41419593},{"atb":[[11.5,0],[14.5,7.41]],"id":41419597},{"atb":[[7.4,0],[8.4,13.51]],"id":41419600}],"con":true,"img":false}]}
{"op":"mcm","clk":"5348035688","pt":1646212844645,"mc":[{"id":"1.195453721","rc":[{"atl":[[730,2],[740,0]],"id":41419587},{"atl":[[600,0],[590,2]],"id":41419630},{"atl":[[520,0],[510,2]],"id":41419627}],"con":true,"img":false}]}
{"op":"mcm","clk":"5348035966","pt":1646212848940,"mc":[{"id":"1.195453721","rc":[{"atl":[[790,2]],"id":41419606}],"con":true,"img":false}]}
{"op":"mcm","clk":"5348035972","pt":1646212849048,"mc":[{"id":"1.195453721","rc":[{"atl":[[800,0]],"id":41419606}],"con":true,"img":false}]}
{"op":"mcm","clk":"5348038467","pt":1646212893267,"mc":[{"id":"1.195453721","rc":[{"atb":[[11,0]],"id":41419635}],"con":true,"img":false}]}
{"op":"mcm","clk":"5348038491","pt":1646212893682,"mc":[{"id":"1.195453721","rc":[{"atb":[[13.5,0]],"id":41419635}],"con":true,"img":false}]}
{"op":"mcm","clk":"5348038525","pt":1646212894304,"mc":[{"id":"1.195453721","rc":[{"atb":[[11.5,3.26]],"id":41419635}],"con":true,"img":false}]}
{"op":"mcm","clk":"5348038544","pt":1646212894557,"mc":[{"id":"1.195453721","rc":[{"atb":[[14,2.72]],"id":41419635}],"con":true,"img":false}]}
{"op":"mcm","clk":"5348043125","pt":1646212980521,"mc":[{"id":"1.195453721","rc":[{"atl":[[250,0.63]],"id":41419634},{"atb":[[16,17.78]],"id":41419593},{"atl":[[640,1.91]],"id":41419593},{"atb":[[25,14.45]],"id":41419587},{"atl":[[750,1.63]],"id":41419587},{"atb":[[25,9.9],[29,4.95]],"id":41419601},{"atl":[[560,0.28],[75,9.9],[55,4.95]],"id":41419601},{"atl":[[580,0.27]],"id":41419630},{"atb":[[25,9.33]],"id":41419628},{"atl":[[540,0.29]],"id":41419628},{"atb":[[34,4.95],[20,15.91],[28,9.9]],"id":41419585},{"atl":[[75,4.95],[720,1.7],[95,9.9]],"id":41419585},{"atb":[[12,21.01],[28,8.59]],"id":41419586},{"atl":[[570,0.27],[600,2.04]],"id":41419586},{"atb":[[5.3,37.99]],"id":41419633},{"atl":[[410,3.06]],"id":41419633},{"atb":[[11.5,21.59]],"id":41419598},{"atl":[[540,2.36]],"id":41419598},{"atb":[[16,11.63],[7.4,29.71]],"id":41419629},{"atl":[[470,0.33],[500,2.45]],"id":41419629},{"atb":[[34,12.94]],"id":41419594},{"atl":[[840,1.45]],"id":41419594}],"con":true,"img":false}]}
{"op":"mcm","clk":"5348043133","pt":1646212980626,"mc":[{"id":"1.195453721","rc":[{"atb":[[4.8,43.95],[8.2,11.63],[7.6,9.9],[8.4,4.95]],"id":41419640},{"atl":[[16.5,9.9],[300,0.52],[330,3.72],[14.5,4.95]],"id":41419640},{"atb":[[75,9.82],[36,12.7],[55,9.9]],"id":41419607},{"atl":[[180,4.95],[910,0.17],[940,1.3]],"id":41419607},{"atb":[[9.6,4.95],[8.8,9.9],[7.8,8.9],[5.4,39.17]],"id":41419605},{"atl":[[21,4.95],[360,0.44],[390,3.21],[25,9.9]],"id":41419605},{"atb":[[7.2,8.22],[6.4,9.9],[4.9,42.24]],"id":41419636},{"atl":[[11.5,4.95],[210,0.75],[13.5,9.9],[240,5.12]],"id":41419636},{"atb":[[7.6,4.95],[6.8,9.9],[7,31.1]],"id":41419634},{"atl":[[280,4.39],[13,4.95],[15,9.9]],"id":41419634},{"atb":[[70,4.95],[20,14.16],[50,13.14]],"id":41419611},{"atl":[[150,4.95],[870,0.17],[900,1.35]],"id":41419611},{"atb":[[32,4.95],[36,7.25],[27,9.9]],"id":41419593},{"atl":[[610,0.26],[85,4.95],[110,9.9]],"id":41419593},{"atb":[[17.5,9.9],[18,11.35],[19.5,4.95],[8.8,25.16]],"id":41419591},{"atl":[[530,2.38],[38,4.95],[46,9.9],[500,0.31]],"id":41419591},{"atb":[[32,9.9],[40,8.22]],"id":41419587},{"atl":[[720,0.21],[95,4.95]],"id":41419587},{"atb":[[17.5,16.97]],"id":41419601},{"atl":[[590,2.07]],"id":41419601},{"atb":[[17.5,9.9],[19.5,4.95],[11,22.22]],"id":41419599},{"atl":[[530,2.31],[36,4.95],[44,9.9],[500,0.31]],"id":41419599},{"atb":[[17,17.23],[21,9.9],[25,8.22]],"id":41419630},{"atl":[[75,9.9],[610,2.01],[55,4.95]],"id":41419630},{"atb":[[36,14.43],[44,4.95],[15.5,18.09]],"id":41419597},{"atl":[[700,0.22],[730,1.67],[110,4.95]],"id":41419597},{"atb":[[20,13.17],[24,4.95],[14.5,18.76]],"id":41419628},{"atl":[[570,2.15],[46,4.95],[60,9.9]],"id":41419628},{"atb":[[19,15.48],[44,9.9],[48,6.09],[55,4.95]],"id":41419608},{"atl":[[760,0.2],[790,1.54],[110,4.95]],"id":41419608},{"atb":[[42,9.9],[50,4.95],[26,14.23]],"id":41419606},{"atl":[[130,4.95],[780,0.2],[810,1.5]],"id":41419606},{"atb":[[10.5,9.9],[12,21.01],[12.5,4.95]],"id":41419637},{"atl":[[23,4.95],[420,0.37],[27,9.9],[450,2.73]],"id":41419637},{"atb":[[16.5,11.63],[18,9.9],[20,4.95],[7.4,29.71]],"id":41419604},{"atl":[[530,2.31],[42,4.95],[50,9.9],[500,0.31]],"id":41419604},{"atb":[[9,25.55],[10,4.95],[9.2,9.9]],"id":41419635},{"atl":[[19.5,4.95],[330,0.47],[360,3.41],[23,9.9]],"id":41419635},{"atl":[[690,0.22]],"id":41419585},{"atb":[[32,9.9],[38,7],[40,4.95],[15.5,18.09]],"id":41419612},{"atl":[[85,4.95],[710,0.22],[740,1.65],[110,9.9]],"id":41419612},{"atb":[[36,8.22],[20,15.91],[29,9.9]],"id":41419592},{"atl":[[630,0.25],[660,1.85],[100,4.95]],"id":41419592},{"atb":[[32,4.95],[12,21.01],[27,9.9],[29,5.66]],"id":41419590},{"atl":[[75,4.95],[630,0.25],[660,1.85],[95,9.9]],"id":41419590},{"atb":[[24,9.9],[28,13.54]],"id":41419586},{"atl":[[75,9.9],[55,4.95]],"id":41419586},{"atb":[[8.6,12.63],[9.4,13.6]],"id":41419633},{"atl":[[19.5,4.95],[23,9.9],[380,0.41]],"id":41419633},{"atb":[[21,9.9],[25,14.28],[15,18.42]],"id":41419600},{"atl":[[540,2.27],[46,4.95],[60,9.9],[510,0.31]],"id":41419600},{"atb":[[22,7.54],[23,9.9],[27,4.95]],"id":41419598},{"atl":[[80,9.9],[60,4.95],[510,0.31]],"id":41419598},{"atb":[[13.5,13.17],[15.5,4.95]],"id":41419629},{"atl":[[32,4.95],[40,9.9]],"id":41419629},{"atb":[[17.5,4.95],[11,22.22],[15.5,9.9]],"id":41419627},{"atl":[[530,2.31],[36,4.95],[44,9.9],[500,0.31]],"id":41419627},{"atb":[[65,10.15],[48,9.9]],"id":41419594},{"atl":[[170,4.95],[810,0.19]],"id":41419594}],"con":true,"img":false}]}
{"op":"mcm","clk":"5348043136","pt":1646212980679,"mc":[{"id":"1.195453721","rc":[{"atl":[[620,0],[640,3.91]],"id":41419593},{"atl":[[570,0],[190,2]],"id":41419601},{"atl":[[300,2],[700,0]],"id":41419585},{"atl":[[580,0],[590,2]],"id":41419586},{"atl":[[390,0],[400,2]],"id":41419633},{"atl":[[520,0],[540,4.36]],"id":41419598},{"atl":[[480,0],[490,2]],"id":41419629},{"atl":[[820,0],[840,3.45]],"id":41419594}],"con":true,"img":false}]}
{"op":"mcm","clk":"5348043142","pt":1646212980835,"mc":[{"id":"1.195453721","rc":[{"atl":[[32,3.23],[310,0]],"id":41419640},{"atl":[[520,2],[920,0]],"id":41419607},{"atl":[[65,2],[370,0]],"id":41419605},{"atl":[[22,4.76],[220,0]],"id":41419636},{"atl":[[260,0],[27,3.85]],"id":41419634},{"atl":[[880,0],[480,2]],"id":41419611},{"atl":[[110,2],[510,0]],"id":41419591},{"atl":[[330,2],[730,0]],"id":41419587},{"atl":[[110,2],[510,0]],"id":41419599},{"atl":[[590,0],[190,2]],"id":41419630},{"atl":[[710,0],[400,2]],"id":41419597},{"atl":[[550,0],[150,2]],"id":41419628},{"atl":[[370,2],[770,0]],"id":41419608},{"atl":[[790,0],[390,2]],"id":41419606},{"atl":[[65,2],[430,0]],"id":41419637},{"atl":[[130,2],[510,0]],"id":41419604},{"atl":[[340,0],[44,2.33]],"id":41419635},{"atl":[[330,2],[720,0]],"id":41419612},{"atl":[[640,0],[330,2]],"id":41419592},{"atl":[[640,0],[240,2]],"id":41419590},{"atl":[[520,0],[130,2]],"id":41419600},{"atl":[[110,2],[510,0]],"id":41419627}],"con":true,"img":false}]}
{"op":"mcm","clk":"5348043170","pt":1646212981301,"mc":[{"id":"1.195453721","rc":[{"atb":[[4,0],[5,25]],"id":41419640},{"atb":[[6,20],[4.7,0]],"id":41419605},{"atb":[[5,25],[3.95,0]],"id":41419636},{"atb":[[3.85,0],[4.7,27.03]],"id":41419634},{"atb":[[20,8.9],[28,3.7]],"id":41419611},{"atb":[[10,0],[14,7.69]],"id":41419593},{"atb":[[10.5,10.53],[7.4,0]],"id":41419591},{"atb":[[20,5.26],[15,0]],"id":41419587},{"atb":[[11,10],[8.4,0]],"id":41419601},{"atb":[[6.4,49.33],[8.2,13.89]],"id":41419599},{"atb":[[8.6,0],[11,10]],"id":41419630},{"atb":[[17,6.25],[14.5,0]],"id":41419597},{"atb":[[10,11.11],[7.6,0]],"id":41419628},{"atb":[[16,0],[24,4.35]],"id":41419608},{"atb":[[19.5,0],[27,3.85]],"id":41419606},{"atb":[[4.5,0],[6,20]],"id":41419637},{"atb":[[6.8,0],[9.4,11.9]],"id":41419604},{"atb":[[5.5,81.41],[4.2,0]],"id":41419635},{"atb":[[9.8,0],[12.5,8.7]],"id":41419585},{"atb":[[10.5,0],[14,7.69]],"id":41419612},{"atb":[[10.5,0],[14.5,7.41]],"id":41419592},{"atb":[[9.6,0],[15,7.14]],"id":41419590},{"atb":[[11.5,9.52],[8.4,0]],"id":41419586},{"atb":[[11.5,9.52],[8.4,0]],"id":41419600},{"atb":[[8,0],[11.5,31.11]],"id":41419598},{"atb":[[6,0],[7.8,14.71]],"id":41419629},{"atb":[[6.6,0],[8.4,13.51]],"id":41419627}],"con":true,"img":false}]}
{"op":"mcm","clk":"5348043174","pt":1646212981407,"mc":[{"id":"1.195453721","rc":[{"atl":[[13,0],[15,0]],"id":41419634}],"con":true,"img":false}]}
{"op":"mcm","clk":"5348043192","pt":1646212981717,"mc":[{"id":"1.195453721","rc":[{"atl":[[13.5,4.95],[15.5,9.9]],"id":41419634}],"con":true,"img":false}]}
{"op":"mcm","clk":"5348043318","pt":1646212984300,"mc":[{"id":"1.195453721","rc":[{"atl":[[46,0],[60,0]],"id":41419600}],"con":true,"img":false}]}
{"op":"mcm","clk":"5348043331","pt":1646212984712,"mc":[{"id":"1.195453721","rc":[{"atl":[[65,9.9],[48,4.95]],"id":41419600}],"con":true,"img":false}]}
{"op":"mcm","clk":"5348043417","pt":1646212986006,"mc":[{"id":"1.195453721","rc":[{"atl":[[520,0],[910,2.17]],"id":41419607},{"atl":[[870,2.17],[480,0]],"id":41419611},{"atl":[[330,0],[720,2.21]],"id":41419587},{"atl":[[700,2.22],[400,0]],"id":41419597},{"atl":[[370,0],[760,2.2]],"id":41419608},{"atl":[[390,0],[780,2.2]],"id":41419606},{"atl":[[630,2.25],[330,0]],"id":41419592}],"con":true,"img":false}]}
{"op":"mcm","clk":"5348043670","pt":1646212990497,"mc":[{"id":"1.195453721","rc":[{"atl":[[65,9.9],[46,0],[48,4.95],[60,0]],"id":41419628}],"con":true,"img":false}]}
{"op":"mcm","clk":"5348043745","pt":1646212991535,"mc":[{"id":"1.195453721","rc":[{"atl":[[65,0],[70,9.9],[48,0],[50,4.95]],"id":41419628}],"con":true,"img":false}]}
{"op":"mcm","clk":"5348043870","pt":1646212994218,"mc":[{"id":"1.195453721","rc":[{"atb":[[50,5.96]],"id":41419587}],"con":true,"img":false}]}
{"op":"mcm","clk":"5348043905","pt":1646212994938,"mc":[{"id":"1.195453721","rc":[{"atb":[[50,2.72]],"id":41419587}],"con":true,"img":false}]}
{"op":"mcm","clk":"5348043942","pt":1646212995597,"mc":[{"id":"1.195453721","rc":[{"atb":[[40,12.28]],"id":41419587},{"atb":[[30,8.19]],"id":41419630}],"con":true,"img":false}]}
{"op":"mcm","clk":"5348043977","pt":1646212996219,"mc":[{"id":"1.195453721","rc":[{"atl":[[13.5,17.63]],"id":41419634},{"atb":[[16,8.87],[28,17.98]],"id":41419593},{"atl":[[610,2.34],[640,2]],"id":41419593},{"atb":[[32,21.3],[25,5.54]],"id":41419587},{"atl":[[55,7.89]],"id":41419630},{"atl":[[140,1.13]],"id":41419628},{"atb":[[32,15.48],[20,7]],"id":41419585},{"atl":[[300,6.24],[720,0]],"id":41419585},{"atb":[[23,25.35],[12,12.1]],"id":41419586},{"atl":[[570,2.5],[600,0],[55,7.89]],"id":41419586},{"atl":[[380,3.84],[410,0]],"id":41419633},{"atb":[[22,26.12],[11.5,22.2]],"id":41419598},{"atl":[[540,2],[510,2.89]],"id":41419598},{"atb":[[7.4,20.81],[13.5,35.26]],"id":41419629},{"atl":[[32,10.06],[470,3.04],[500,0]],"id":41419629},{"atb":[[34,4.03],[46,15.77]],"id":41419594}],"con":true,"img":false}]}
{"op":"mcm","clk":"5348043983","pt":1646212996323,"mc":[{"id":"1.195453721","rc":[{"atl":[[180,5.84]],"id":41419607},{"atl":[[11.5,20.05]],"id":41419636},{"atb":[[70,7.25],[20,0],[48,14.12]],"id":41419611},{"atl":[[150,6.01]],"id":41419611},{"atl":[[85,6.83]],"id":41419593},{"atb":[[44,8.64]],"id":41419597},{"atl":[[110,6.4]],"id":41419597},{"atb":[[20,34.4],[14.5,9.86]],"id":41419628},{"atl":[[570,0],[150,10.5]],"id":41419628},{"atl":[[23,12.15]],"id":41419637},{"atb":[[20,13.29]],"id":41419604},{"atl":[[42,8.82]],"id":41419604},{"atb":[[32,10.06]],"id":41419590},{"atl":[[75,7.09]],"id":41419590}],"con":true,"img":false}]}
{"op":"mcm","clk":"5348043989","pt":1646212996430,"mc":[{"id":"1.195453721","rc":[{"atb":[[4.8,35.05],[7.6,31.99],[8.4,26.37]],"id":41419640},{"atl":[[32,25.31],[330,0],[14.5,16.69]],"id":41419640},{"atb":[[36,3.8],[50,15.48]],"id":41419607},{"atb":[[9.6,23.39],[7.8,29.5],[5.4,30.27]],"id":41419605},{"atl":[[65,22.03],[21,12.88],[390,0]],"id":41419605},{"atb":[[6.4,29.48]],"id":41419636},{"atl":[[22,24.33],[240,0]],"id":41419636},{"atb":[[7.6,18.03],[7,22.19]],"id":41419634},{"atl":[[280,0],[27,16.92]],"id":41419634},{"atb":[[17.5,31.99],[19.5,13.52],[8.8,17.07]],"id":41419591},{"atl":[[530,0],[38,9.23],[110,13.94]],"id":41419591},{"atb":[[17.5,8.07],[26,15.48]],"id":41419601},{"atl":[[590,0],[190,8.7]],"id":41419601},{"atb":[[18.5,15.48],[11,13.31]],"id":41419599},{"atl":[[530,0],[36,9.48],[110,13.59]],"id":41419599},{"atb":[[17,8.32],[21,34.29]],"id":41419630},{"atl":[[610,0],[190,8.7]],"id":41419630},{"atb":[[34,14.12],[15.5,9.18]],"id":41419597},{"atb":[[19,7.4],[44,24.62],[55,7.89]],"id":41419608},{"atl":[[110,6.4]],"id":41419608},{"atb":[[46,12.17],[26,5.32]],"id":41419606},{"atl":[[130,6.18]],"id":41419606},{"atb":[[12,12.1],[12.5,17.17]],"id":41419637},{"atl":[[65,14.21],[450,0]],"id":41419637},{"atb":[[16.5,33.71],[7.4,20.81]],"id":41419604},{"atl":[[130,11.8],[530,0]],"id":41419604},{"atb":[[9,16.64],[10,17.17]],"id":41419635},{"atl":[[19.5,13.52],[44,14.54],[360,0]],"id":41419635},{"atb":[[32,27.68],[40,9.01],[15.5,9.18]],"id":41419612},{"atl":[[330,5.85],[85,6.83],[740,0]],"id":41419612},{"atb":[[29,21.3]],"id":41419592},{"atl":[[100,6.55]],"id":41419592},{"atl":[[660,0],[240,7.3]],"id":41419590},{"atl":[[19.5,13.52]],"id":41419633},{"atb":[[20,25.35],[15,9.51]],"id":41419600},{"atl":[[130,11.8],[540,0],[48,8.32]],"id":41419600},{"atb":[[27,11.05]],"id":41419598},{"atl":[[60,7.64]],"id":41419598},{"atb":[[17.5,17.17],[11,13.31]],"id":41419627},{"atl":[[530,0],[110,13.59]],"id":41419627},{"atl":[[170,5.89]],"id":41419594}],"con":true,"img":false}]}
{"op":"mcm","clk":"5348044002","pt":1646212996637,"mc":[{"id":"1.195453721","rc":[{"atl":[[400,0],[55,2]],"id":41419633}],"con":true,"img":false}]}
{"op":"mcm","clk":"5348044025","pt":1646212997100,"mc":[{"id":"1.195453721","rc":[{"atl":[[910,2]],"id":41419607},{"atl":[[210,0]],"id":41419636},{"atl":[[250,0]],"id":41419634},{"atb":[[50,9.9]],"id":41419611},{"atl":[[870,2]],"id":41419611},{"atl":[[610,2.08]],"id":41419593},{"atl":[[580,0]],"id":41419630},{"atb":[[36,9.9]],"id":41419597},{"atl":[[700,2]],"id":41419597},{"atl":[[540,0]],"id":41419628},{"atl":[[420,0]],"id":41419637},{"atb":[[16.5,24.81]],"id":41419604},{"atl":[[500,0]],"id":41419604},{"atb":[[29,0]],"id":41419590},{"atl":[[630,0]],"id":41419590},{"atl":[[570,2.22]],"id":41419586},{"atl":[[470,2.7]],"id":41419629}],"con":true,"img":false}]}
{"op":"mcm","clk":"5348044028","pt":1646212997203,"mc":[{"id":"1.195453721","rc":[{"atb":[[8.2,2.72]],"id":41419640},{"atl":[[300,0]],"id":41419640},{"atb":[[7.8,20.6]],"id":41419605},{"atl":[[360,0]],"id":41419605},{"atb":[[4.9,34.15]],"id":41419636},{"atb":[[18,3.26]],"id":41419591},{"atl":[[500,0]],"id":41419591},{"atl":[[500,0]],"id":41419599},{"atb":[[48,2.72]],"id":41419608},{"atl":[[760,2]],"id":41419608},{"atl":[[780,2]],"id":41419606},{"atl":[[330,0]],"id":41419635},{"atb":[[38,2.72]],"id":41419612},{"atl":[[710,0]],"id":41419612},{"atb":[[20,7]],"id":41419592},{"atl":[[630,2]],"id":41419592},{"atb":[[12,12.1],[28,17.43]],"id":41419590},{"atl":[[380,3.42]],"id":41419633},{"atl":[[510,0]],"id":41419600},{"atb":[[22,18.57]],"id":41419598},{"atl":[[510,2.58]],"id":41419598},{"atl":[[810,0]],"id":41419594}],"con":true,"img":false}]}
{"op":"mcm","clk":"5348044044","pt":1646212997717,"mc":[{"id":"1.195453721","rc":[{"atl":[[190,6.73],[840,2]],"id":41419594}],"con":true,"img":false}]}
{"op":"mcm","clk":"5348044047","pt":1646212997820,"mc":[{"id":"1.195453721","rc":[{"atl":[[840,0],[490,2]],"id":41419594}],"con":true,"img":false}]}
{"op":"mcm","clk":"5348044163","pt":1646213000602,"mc":[{"id":"1.195453721","rc":[{"atl":[[95,6.63]],"id":41419587},{"atb":[[65,5.2]],"id":41419606},{"atb":[[17.5,0],[15,0]],"id":41419637},{"atb":[[11.5,0],[14,0]],"id":41419635}],"con":true,"img":false}]}
{"op":"mcm","clk":"5348044167","pt":1646213000706,"mc":[{"id":"1.195453721","rc":[{"atb":[[9,0],[10,0]],"id":41419634}],"con":true,"img":false}]}
{"op":"mcm","clk":"5348044197","pt":1646213001323,"mc":[{"id":"1.195453721","rc":[{"atb":[[7.6,42.05]],"id":41419634},{"atb":[[12.5,30.96]],"id":41419637},{"atb":[[10,34.78]],"id":41419635}],"con":true,"img":false}]}
{"op":"mcm","clk":"5348044201","pt":1646213001425,"mc":[{"id":"1.195453721","rc":[{"atb":[[9.8,2.72],[8.8,3.26]],"id":41419634},{"atl":[[720,2]],"id":41419587},{"atb":[[18,2.72],[15.5,3.26]],"id":41419637},{"atb":[[11,3.26],[13.5,2.72]],"id":41419635}],"con":true,"img":false}]}
{"op":"mcm","clk":"5348044400","pt":1646213004838,"mc":[{"id":"1.195453721","rc":[{"atb":[[27,39.36],[28,2.72]],"id":41419590}],"con":true,"img":false}]}
{"op":"mcm","clk":"5348044434","pt":1646213005512,"mc":[{"id":"1.195453721","rc":[{"atl":[[190,0],[490,4.64]],"id":41419594}],"con":true,"img":false}]}
{"op":"mcm","clk":"5348044453","pt":1646213005828,"mc":[{"id":"1.195453721","rc":[{"atl":[[120,4.95]],"id":41419608},{"atl":[[36,9.48]],"id":41419627}],"con":true,"img":false}]}
{"op":"mcm","clk":"5348044457","pt":1646213005932,"mc":[{"id":"1.195453721","rc":[{"atb":[[30,2.72]],"id":41419630},{"atl":[[55,4.95]],"id":41419630},{"atl":[[380,2],[110,1.45]],"id":41419608}],"con":true,"img":false}]}
{"op":"mcm","clk":"5348044459","pt":1646213006035,"mc":[{"id":"1.195453721","rc":[{"atl":[[760,0]],"id":41419608}],"con":true,"img":false}]}
{"op":"mcm","clk":"5348044480","pt":1646213006549,"mc":[{"id":"1.195453721","rc":[{"atl":[[760,1.7],[790,0]],"id":41419608},{"atl":[[500,0]],"id":41419627}],"con":true,"img":false}]}
{"op":"mcm","clk":"5348044493","pt":1646213006705,"mc":[{"id":"1.195453721","rc":[{"atb":[[25,14.82]],"id":41419630},{"atl":[[70,2.29]],"id":41419630}],"con":true,"img":false}]}
{"op":"mcm","clk":"5348044623","pt":1646213008826,"mc":[{"id":"1.195453721","rc":[{"atl":[[16,9.9],[13.5,4.95],[14,4.95]],"id":41419634}],"con":true,"img":false}]}
{"op":"mcm","clk":"5348044629","pt":1646213008929,"mc":[{"id":"1.195453721","rc":[{"atl":[[13.5,0],[15.5,0]],"id":41419634}],"con":true,"img":false}]}
{"op":"mcm","clk":"5348044672","pt":1646213009554,"mc":[{"id":"1.195453721","rc":[{"atl":[[15.5,8.9]],"id":41419634}],"con":true,"img":false}]}
{"op":"mcm","clk":"5348044679","pt":1646213009661,"mc":[{"id":"1.195453721","rc":[{"atl":[[16,0],[14,0]],"id":41419634},{"atb":[[50,5.96]],"id":41419587}],"con":true,"img":false}]}
{"op":"mcm","clk":"5348044717","pt":1646213010439,"mc":[{"id":"1.195453721","rc":[{"atl":[[13.5,4.95],[15.5,18.81]],"id":41419634}],"con":true,"img":false}]}
{"op":"mcm","clk":"5348044723","pt":1646213010542,"mc":[{"id":"1.195453721","rc":[{"atb":[[40,8.22],[50,2.72]],"id":41419587}],"con":true,"img":false}]}
{"op":"mcm","clk":"5348044783","pt":1646213011318,"mc":[{"id":"1.195453721","rc":[{"atb":[[42,3.86]],"id":41419587}],"con":true,"img":false}]}
{"op":"mcm","clk":"5348044788","pt":1646213011421,"mc":[{"id":"1.195453721","rc":[{"atl":[[16,9.9],[13.5,0],[14,4.95],[15.5,8.9]],"id":41419634}],"con":true,"img":false}]}
{"op":"mcm","clk":"5348044808","pt":1646213011630,"mc":[{"id":"1.195453721","rc":[{"atl":[[50,8.19]],"id":41419628}],"con":true,"img":false}]}
{"op":"mcm","clk":"5348044814","pt":1646213011734,"mc":[{"id":"1.195453721","rc":[{"atb":[[32,9.9],[40,18.01]],"id":41419587},{"atl":[[140,10.55]],"id":41419628},{"atl":[[380,0],[55,26.5]],"id":41419633}],"con":true,"img":false}]}
{"op":"mcm","clk":"5348044824","pt":1646213011839,"mc":[{"id":"1.195453721","rc":[{"atl":[[16,30.5],[27,3.85],[14,17.15]],"id":41419634},{"atl":[[150,2]],"id":41419628}],"con":true,"img":false}]}
{"op":"mcm","clk":"5348044829","pt":1646213011940,"mc":[{"id":"1.195453721","rc":[{"atl":[[75,27.5],[190,2]],"id":41419630}],"con":true,"img":false}]}
{"op":"mcm","clk":"5348044855","pt":1646213012356,"mc":[{"id":"1.195453721","rc":[{"atl":[[140,9.41]],"id":41419628}],"con":true,"img":false}]}
{"op":"mcm","clk":"5348044871","pt":1646213012622,"mc":[{"id":"1.195453721","rc":[{"atl":[[15.5,0]],"id":41419634}],"con":true,"img":false}]}
{"op":"mcm","clk":"5348044901","pt":1646213013334,"mc":[{"id":"1.195453721","rc":[{"atl":[[190,6.95],[490,2]],"id":41419594}],"con":true,"img":false}]}
{"op":"mcm","clk":"5348044956","pt":1646213014320,"mc":[{"id":"1.195453721","rc":[{"atl":[[190,0]],"id":41419594}],"con":true,"img":false}]}
{"op":"mcm","clk":"5348044996","pt":1646213015245,"mc":[{"id":"1.195453721","rc":[{"atl":[[80,9.9],[60,4.95]],"id":41419601}],"con":true,"img":false}]}
{"op":"mcm","clk":"5348044999","pt":1646213015351,"mc":[{"id":"1.195453721","rc":[{"atl":[[75,0],[55,0]],"id":41419601}],"con":true,"img":false}]}
{"op":"mcm","clk":"5348045034","pt":1646213015926,"mc":[{"id":"1.195453721","rc":[{"atl":[[75,14.71],[190,2],[60,7.64]],"id":41419601}],"con":true,"img":false}]}
{"op":"mcm","clk":"5348045067","pt":1646213016336,"mc":[{"id":"1.195453721","rc":[{"atb":[[65,2.72]],"id":41419606},{"atl":[[130,4.95]],"id":41419606}],"con":true,"img":false}]}
{"op":"mcm","clk":"5348045075","pt":1646213016435,"mc":[{"id":"1.195453721","rc":[{"atl":[[36,4.95]],"id":41419599}],"con":true,"img":false}]}
{"op":"mcm","clk":"5348045093","pt":1646213016746,"mc":[{"id":"1.195453721","rc":[{"atl":[[560,0]],"id":41419601}],"con":true,"img":false}]}
{"op":"mcm","clk":"5348045118","pt":1646213017162,"mc":[{"id":"1.195453721","rc":[{"atl":[[42,3.86]],"id":41419599},{"atb":[[50,8.19]],"id":41419606}],"con":true,"img":false}]}
{"op":"mcm","clk":"5348045159","pt":1646213017639,"mc":[{"id":"1.195453721","rc":[{"atl":[[110,2]],"id":41419599}],"con":true,"img":false}]}
{"op":"mcm","clk":"5348045181","pt":1646213017945,"mc":[{"id":"1.195453721","rc":[{"atl":[[44,24.62]],"id":41419599}],"con":true,"img":false}]}
{"op":"mcm","clk":"5348045199","pt":1646213018265,"mc":[{"id":"1.195453721","rc":[{"atl":[[130,6.18]],"id":41419606}],"con":true,"img":false}]}
{"op":"mcm","clk":"5348045289","pt":1646213019550,"mc":[{"id":"1.195453721","rc":[{"atl":[[16,9.9],[27,35.06]],"id":41419634}],"con":true,"img":false}]}
{"op":"mcm","clk":"5348045328","pt":1646213020232,"mc":[{"id":"1.195453721","rc":[{"atb":[[20,35.26],[21,0],[24,4.95],[25,9.33]],"id":41419600},{"atb":[[18.5,0],[22,0]],"id":41419627}],"con":true,"img":false}]}
{"op":"mcm","clk":"5348045370","pt":1646213020844,"mc":[{"id":"1.195453721","rc":[{"atb":[[17.5,14.56],[11,47.84]],"id":41419627},{"atl":[[190,7.07]],"id":41419594}],"con":true,"img":false}]}
{"op":"mcm","clk":"5348045392","pt":1646213021260,"mc":[{"id":"1.195453721","rc":[{"atb":[[18,3.26],[21,2.72]],"id":41419627}],"con":true,"img":false}]}
{"op":"mcm","clk":"5348045436","pt":1646213021936,"mc":[{"id":"1.195453721","rc":[{"atl":[[380,5.53],[760,0]],"id":41419608}],"con":true,"img":false}]}
{"op":"mcm","clk":"5348045520","pt":1646213023555,"mc":[{"id":"1.195453721","rc":[{"atl":[[75,0],[80,26.8]],"id":41419601}],"con":true,"img":false}]}
{"op":"mcm","clk":"5348045590","pt":1646213024948,"mc":[{"id":"1.195453721","rc":[{"atb":[[50,5.96]],"id":41419587}],"con":true,"img":false}]}
{"op":"mcm","clk":"5348045650","pt":1646213026084,"mc":[{"id":"1.195453721","rc":[{"atb":[[42,0],[50,2.72]],"id":41419587}],"con":true,"img":false}]}
{"op":"mcm","clk":"5348045685","pt":1646213026652,"mc":[{"id":"1.195453721","rc":[{"atb":[[32,23.82],[40,8.22]],"id":41419587}],"con":true,"img":false}]}
{"op":"mcm","clk":"5348045703","pt":1646213026960,"mc":[{"id":"1.195453721","rc":[{"atb":[[42,3.86]],"id":41419587}],"con":true,"img":false}]}
{"op":"mcm","clk":"5348045723","pt":1646213027366,"mc":[{"id":"1.195453721","rc":[{"atl":[[23,4.95]],"id":41419637}],"con":true,"img":false}]}
{"op":"mcm","clk":"5348045759","pt":1646213028040,"mc":[{"id":"1.195453721","rc":[{"atl":[[27,16]],"id":41419637}],"con":true,"img":false}]}
{"op":"mcm","clk":"5348045768","pt":1646213028350,"mc":[{"id":"1.195453721","rc":[{"atl":[[490,4.77]],"id":41419594}],"con":true,"img":false}]}
{"op":"mcm","clk":"5348045774","pt":1646213028453,"mc":[{"id":"1.195453721","rc":[{"atl":[[190,0]],"id":41419594}],"con":true,"img":false}]}
{"op":"mcm","clk":"5348045809","pt":1646213029066,"mc":[{"id":"1.195453721","rc":[{"atl":[[19.5,0],[20,4.95],[23,0],[24,9.9]],"id":41419635},{"atl":[[490,2]],"id":41419594}],"con":true,"img":false}]}
{"op":"mcm","clk":"5348045876","pt":1646213030057,"mc":[{"id":"1.195453721","rc":[{"atl":[[23,7.2]],"id":41419635}],"con":true,"img":false}]}
{"op":"mcm","clk":"5348045914","pt":1646213030773,"mc":[{"id":"1.195453721","rc":[{"atl":[[44,2.33],[24,27.96]],"id":41419635}],"con":true,"img":false}]}
{"op":"mcm","clk":"5348045930","pt":1646213031039,"mc":[{"id":"1.195453721","rc":[{"atl":[[80,9.9],[190,9.22]],"id":41419601}],"con":true,"img":false}]}
{"op":"mcm","clk":"5348045987","pt":1646213032076,"mc":[{"id":"1.195453721","rc":[{"atl":[[36,9.48]],"id":41419599}],"con":true,"img":false}]}
{"op":"mcm","clk":"5348046021","pt":1646213032771,"mc":[{"id":"1.195453721","rc":[{"atl":[[42,0]],"id":41419599},{"atl":[[65,0],[70,9.9],[48,0],[50,4.95]],"id":41419600}],"con":true,"img":false}]}
{"op":"mcm","clk":"5348046053","pt":1646213033340,"mc":[{"id":"1.195453721","rc":[{"atl":[[44,9.9],[110,14.54]],"id":41419599}],"con":true,"img":false}]}
{"op":"mcm","clk":"5348046069","pt":1646213033549,"mc":[{"id":"1.195453721","rc":[{"atl":[[65,2.47]],"id":41419600}],"con":true,"img":false}]}
{"op":"mcm","clk":"5348046097","pt":1646213034060,"mc":[{"id":"1.195453721","rc":[{"atl":[[70,29.65]],"id":41419600}],"con":true,"img":false}]}
{"op":"mcm","clk":"5348046101","pt":1646213034165,"mc":[{"id":"1.195453721","rc":[{"atl":[[130,2]],"id":41419600}],"con":true,"img":false}]}
{"op":"mcm","clk":"5348046181","pt":1646213035659,"mc":[{"id":"1.195453721","rc":[{"atl":[[20,0],[21,4.95],[24,18.06],[25,9.9]],"id":41419635}],"con":true,"img":false}]}
{"op":"mcm","clk":"5348046187","pt":1646213035764,"mc":[{"id":"1.195453721","rc":[{"atb":[[17.5,43.38],[11,13.31]],"id":41419627},{"atl":[[190,7.29]],"id":41419594}],"con":true,"img":false}]}
{"op":"mcm","clk":"5348046310","pt":1646213037878,"mc":[{"id":"1.195453721","rc":[{"atb":[[25,2.72]],"id":41419628},{"atb":[[65,5.2]],"id":41419606}],"con":true,"img":false}]}
{"op":"mcm","clk":"5348046365","pt":1646213038768,"mc":[{"id":"1.195453721","rc":[{"atb":[[24,11.84]],"id":41419628},{"atb":[[50,4.95]],"id":41419606}],"con":true,"img":false}]}
{"op":"mcm","clk":"5348046426","pt":1646213039854,"mc":[{"id":"1.195453721","rc":[{"atb":[[50,5.96]],"id":41419587}],"con":true,"img":false}]}
{"op":"mcm","clk":"5348046477","pt":1646213040576,"mc":[{"id":"1.195453721","rc":[{"atb":[[8.6,4.95],[7.6,22.08],[7.8,9.9],[8.4,21.42]],"id":41419640},{"atb":[[7.2,3.26],[6.4,19.57],[7.4,4.95],[6.6,9.9]],"id":41419636},{"atl":[[80,4.95],[85,1.88],[100,9.9],[110,0]],"id":41419593},{"atb":[[17.5,22.08],[18,13.17],[19.5,8.56],[20,4.95]],"id":41419591},{"atb":[[32,13.91],[34,9.9],[40,3.26],[42,8.82]],"id":41419587},{"atb":[[25,0],[26,25.39],[29,0],[30,4.95]],"id":41419601},{"atl":[[70,0],[44,4.95],[50,3.23],[55,9.9]],"id":41419628},{"atb":[[10.5,0],[12.5,26],[13,4.95]],"id":41419637},{"atb":[[10,29.83],[9.2,0],[10.5,4.95],[9.4,9.9]],"id":41419635},{"atl":[[19.5,8.56],[19,4.95],[22,9.9],[23,0]],"id":41419633},{"atl":[[75,9.9],[80,0],[55,4.95],[60,2.68]],"id":41419598},{"atl":[[32,5.11],[38,9.9],[40,0],[30,4.95]],"id":41419629},{"atl":[[34,4.95],[36,4.52],[42,9.9],[44,0]],"id":41419627},{"atl":[[160,4.95],[170,0.93]],"id":41419594}],"con":true,"img":false}]}
{"op":"mcm","clk":"5348046483","pt":1646213040681,"mc":[{"id":"1.195453721","rc":[{"atb":[[42,4.95],[50,2.72]],"id":41419587}],"con":true,"img":false}]}
{"op":"mcm","clk":"5348046489","pt":1646213040777,"mc":[{"id":"1.195453721","rc":[{"atl":[[300,2]],"id":41419593},{"atl":[[540,0],[200,2]],"id":41419598},{"atl":[[95,2],[490,0]],"id":41419629}],"con":true,"img":false}]}
{"op":"mcm","clk":"5348046497","pt":1646213040879,"mc":[{"id":"1.195453721","rc":[{"atl":[[640,0]],"id":41419593}],"con":true,"img":false}]}
{"op":"mcm","clk":"5348046504","pt":1646213040986,"mc":[{"id":"1.195453721","rc":[{"atb":[[6.4,0]],"id":41419636},{"atb":[[21,7.92]],"id":41419591},{"atl":[[140,0],[55,31.99]],"id":41419628},{"atb":[[12.5,13.78]],"id":41419637},{"atl":[[18.5,9.05],[22,43.4]],"id":41419633},{"atl":[[75,29.26],[510,0]],"id":41419598},{"atl":[[38,32.23],[470,0],[29,5.66]],"id":41419629},{"atl":[[42,23.99]],"id":41419627}],"con":true,"img":false}]}
{"op":"mcm","clk":"5348046510","pt":1646213041088,"mc":[{"id":"1.195453721","rc":[{"atb":[[8.8,20.32]],"id":41419640},{"atb":[[7.2,25.35]],"id":41419636},{"atl":[[610,0],[100,23.93]],"id":41419593},{"atb":[[17.5,0],[18,41.64]],"id":41419591},{"atb":[[10,17.61],[10.5,19.66]],"id":41419635},{"atl":[[55,2]],"id":41419633},{"atl":[[50,3.04]],"id":41419598},{"atl":[[34,9.76],[110,2]],"id":41419627}],"con":true,"img":false}]}
{"op":"mcm","clk":"5348046516","pt":1646213041191,"mc":[{"id":"1.195453721","rc":[{"atb":[[8.2,42.27]],"id":41419640},{"atl":[[75,2.14]],"id":41419593},{"atb":[[13,19.66]],"id":41419637},{"atl":[[160,5.95]],"id":41419594}],"con":true,"img":false}]}
{"op":"mcm","clk":"5348046524","pt":1646213041246,"mc":[{"id":"1.195453721","rc":[{"atb":[[7.6,0]],"id":41419640},{"atl":[[20,4.95],[21,0],[24,27.96],[25,0]],"id":41419635}],"con":true,"img":false}]}
{"op":"mcm","clk":"5348046543","pt":1646213041560,"mc":[{"id":"1.195453721","rc":[{"atb":[[32,0],[36,4.52],[40,12.17]],"id":41419587}],"con":true,"img":false}]}
{"op":"mcm","clk":"5348046555","pt":1646213041770,"mc":[{"id":"1.195453721","rc":[{"atb":[[19.5,0]],"id":41419591},{"atl":[[19.5,0],[22,9.9]],"id":41419633},{"atl":[[75,9.9]],"id":41419598},{"atl":[[32,0]],"id":41419629}],"con":true,"img":false}]}
{"op":"mcm","clk":"5348046564","pt":1646213041874,"mc":[{"id":"1.195453721","rc":[{"atb":[[8.4,0]],"id":41419640},{"atl":[[100,9.9]],"id":41419593},{"atl":[[60,0]],"id":41419598},{"atl":[[36,0]],"id":41419627},{"atl":[[170,0]],"id":41419594}],"con":true,"img":false}]}
{"op":"mcm","clk":"5348046569","pt":1646213041977,"mc":[{"id":"1.195453721","rc":[{"atl":[[85,0]],"id":41419593}],"con":true,"img":false}]}
{"op":"mcm","clk":"5348046657","pt":1646213043171,"mc":[{"id":"1.195453721","rc":[{"atl":[[190,0]],"id":41419594}],"con":true,"img":false}]}
{"op":"mcm","clk":"5348046663","pt":1646213043270,"mc":[{"id":"1.195453721","rc":[{"atl":[[490,4.86]],"id":41419594}],"con":true,"img":false}]}
{"op":"mcm","clk":"5348046750","pt":1646213045076,"mc":[{"id":"1.195453721","rc":[{"atl":[[20,13.29]],"id":41419635}],"con":true,"img":false}]}
{"op":"mcm","clk":"5348046807","pt":1646213045997,"mc":[{"id":"1.195453721","rc":[{"atl":[[23,0]],"id":41419635}],"con":true,"img":false}]}
{"op":"mcm","clk":"5348046827","pt":1646213046411,"mc":[{"id":"1.195453721","rc":[{"atl":[[180,0],[200,4.95]],"id":41419607},{"atl":[[16,0],[16.5,9.9],[14,0],[14.5,4.95]],"id":41419634},{"atl":[[75,0],[80,0],[85,4.95],[100,0],[110,9.9]],"id":41419593},{"atl":[[65,4.95],[80,0],[85,9.9],[60,0]],"id":41419601},{"atl":[[130,0],[140,4.95]],"id":41419606},{"atl":[[23,0],[24,4.95],[27,6.09],[28,9.9]],"id":41419637},{"atl":[[20,0],[21,4.95],[24,18.06],[25,9.9]],"id":41419635},{"atl":[[75,0],[80,4.95],[95,0],[100,9.9]],"id":41419585},{"atl":[[100,0],[110,4.95]],"id":41419592},{"atb":[[32,0],[26,9.9],[27,29.45],[30,4.95]],"id":41419590},{"atl":[[70,19.75],[75,9.9],[50,0],[55,4.95]],"id":41419600},{"atl":[[160,0],[180,4.95],[490,2]],"id":41419594}],"con":true,"img":false}]}
{"op":"mcm","clk":"5348046834","pt":1646213046494,"mc":[{"id":"1.195453721","rc":[{"atl":[[44,26.95]],"id":41419635}],"con":true,"img":false}]}
{"op":"mcm","clk":"5348046842","pt":1646213046571,"mc":[{"id":"1.195453721","rc":[{"atl":[[520,2],[910,0]],"id":41419607},{"atl":[[780,0],[390,2]],"id":41419606},{"atl":[[24,0]],"id":41419635},{"atl":[[630,0],[310,2]],"id":41419592}],"con":true,"img":false}]}
{"op":"mcm","clk":"5348046854","pt":1646213046779,"mc":[{"id":"1.195453721","rc":[{"atl":[[65,2]],"id":41419637}],"con":true,"img":false}]}
{"op":"mcm","clk":"5348046858","pt":1646213046882,"mc":[{"id":"1.195453721","rc":[{"atl":[[24,11.84],[28,26.33]],"id":41419637}],"con":true,"img":false}]}
{"op":"mcm","clk":"5348046868","pt":1646213047088,"mc":[{"id":"1.195453721","rc":[{"atl":[[180,4.95],[190,0.83],[200,0]],"id":41419607},{"atl":[[16.5,0],[16,9.9],[26,6.34],[14,4.95],[14.5,0]],"id":41419634},{"atl":[[85,1.88],[110,0]],"id":41419593},{"atl":[[65,0],[80,9.9],[85,0],[180,0.88],[60,4.95]],"id":41419601},{"atl":[[130,4.95],[140,0],[380,0.41]],"id":41419606},{"atl":[[23,4.95],[24,6.89],[27,16],[28,16.42]],"id":41419637},{"atl":[[21,0],[24,6.89],[25,0]],"id":41419635},{"atl":[[75,4.95],[290,0.55],[80,0],[95,9.9],[100,0]],"id":41419585},{"atl":[[140,9.9],[100,6.55],[110,0]],"id":41419592},{"atb":[[32,4.95],[26,0],[27,39.36],[29,5.66],[30,0]],"id":41419590},{"atl":[[75,0],[55,0]],"id":41419600},{"atl":[[180,0],[1000,0.15]],"id":41419594}],"con":true,"img":false}]}
{"op":"mcm","clk":"5348046876","pt":1646213047191,"mc":[{"id":"1.195453721","rc":[{"atl":[[70,29.65],[50,4.95]],"id":41419600}],"con":true,"img":false}]}
{"op":"mcm","clk":"5348046882","pt":1646213047290,"mc":[{"id":"1.195453721","rc":[{"atl":[[870,2],[490,0]],"id":41419594}],"con":true,"img":false}]}
{"op":"mcm","clk":"5348046892","pt":1646213047496,"mc":[{"id":"1.195453721","rc":[{"atl":[[940,0]],"id":41419607},{"atl":[[26,23.12],[27,3.85]],"id":41419634},{"atl":[[390,5.63]],"id":41419606},{"atl":[[290,5.44]],"id":41419585},{"atl":[[310,6.57]],"id":41419592},{"atb":[[27,9.9],[28,21.69]],"id":41419590},{"atl":[[130,12.92],[70,9.9]],"id":41419600}],"con":true,"img":false}]}
{"op":"mcm","clk":"5348046899","pt":1646213047601,"mc":[{"id":"1.195453721","rc":[{"atl":[[520,4.72]],"id":41419607},{"atl":[[810,0]],"id":41419606},{"atl":[[300,2]],"id":41419585},{"atl":[[660,0]],"id":41419592}],"con":true,"img":false}]}
{"op":"mcm","clk":"5348046911","pt":1646213047804,"mc":[{"id":"1.195453721","rc":[{"atl":[[80,4.95],[100,9.9]],"id":41419593},{"atl":[[180,8.77],[190,2]],"id":41419601},{"atl":[[27,9.9]],"id":41419637},{"atl":[[20,4.95],[24,16.8]],"id":41419635},{"atl":[[160,4.95]],"id":41419594}],"con":true,"img":false}]}
{"op":"mcm","clk":"5348046917","pt":1646213047862,"mc":[{"id":"1.195453721","rc":[{"atl":[[690,0]],"id":41419585}],"con":true,"img":false}]}
{"op":"mcm","clk":"5348046923","pt":1646213047963,"mc":[{"id":"1.195453721","rc":[{"atl":[[870,0],[470,2]],"id":41419594}],"con":true,"img":false}]}
{"op":"mcm","clk":"5348046935","pt":1646213048172,"mc":[{"id":"1.195453721","rc":[{"atl":[[42,9.9],[110,14.92]],"id":41419627}],"con":true,"img":false}]}
{"op":"mcm","clk":"5348046946","pt":1646213048378,"mc":[{"id":"1.195453721","rc":[{"atl":[[50,8.19]],"id":41419600}],"con":true,"img":false}]}
{"op":"mcm","clk":"5348046970","pt":1646213048789,"mc":[{"id":"1.195453721","rc":[{"atl":[[130,2],[70,30.25]],"id":41419600}],"con":true,"img":false}]}
{"op":"mcm","clk":"5348046983","pt":1646213048995,"mc":[{"id":"1.195453721","rc":[{"atl":[[44,8.64]],"id":41419628},{"atl":[[21,4.95],[25,9.9]],"id":41419635},{"atb":[[32,0],[27,0],[30,4.95]],"id":41419590}],"con":true,"img":false}]}
{"op":"mcm","clk":"5348046992","pt":1646213049095,"mc":[{"id":"1.195453721","rc":[{"atl":[[20,0],[24,6.89]],"id":41419635},{"atl":[[65,0]],"id":41419600}],"con":true,"img":false}]}
{"op":"mcm","clk":"5348047000","pt":1646213049197,"mc":[{"id":"1.195453721","rc":[{"atb":[[8.2,24.74]],"id":41419636},{"atb":[[7.6,37.1],[6.8,0],[7,32.1],[7.8,4.95]],"id":41419634},{"atl":[[55,7.89]],"id":41419630},{"atb":[[32,17.77],[34,9.9],[40,4.06],[42,4.95]],"id":41419612},{"atb":[[20,25.35],[21,9.9],[24,0],[25,14.28]],"id":41419600}],"con":true,"img":false}]}
{"op":"mcm","clk":"5348047015","pt":1646213049405,"mc":[{"id":"1.195453721","rc":[{"atl":[[170,4.95]],"id":41419594}],"con":true,"img":false}]}
{"op":"mcm","clk":"5348047024","pt":1646213049504,"mc":[{"id":"1.195453721","rc":[{"atl":[[50,4.95]],"id":41419600},{"atl":[[160,0]],"id":41419594}],"con":true,"img":false}]}
{"op":"mcm","clk":"5348047038","pt":1646213049672,"mc":[{"id":"1.195453721","rc":[{"atb":[[7.6,24.02],[7.8,19.66]],"id":41419634},{"atl":[[50,0]],"id":41419628},{"atb":[[32,0],[38,18.79],[44,3.68]],"id":41419612},{"atb":[[26,9.9]],"id":41419590}],"con":true,"img":false}]}
{"op":"mcm","clk":"5348047058","pt":1646213049974,"mc":[{"id":"1.195453721","rc":[{"atl":[[70,0]],"id":41419630},{"atl":[[70,20.34],[75,9.9],[50,0],[55,4.95]],"id":41419600}],"con":true,"img":false}]}
{"op":"mcm","clk":"5348047068","pt":1646213050183,"mc":[{"id":"1.195453721","rc":[{"atl":[[150,11.51],[55,9.9]],"id":41419628},{"atl":[[65,2.47]],"id":41419600},{"atl":[[170,0]],"id":41419594}],"con":true,"img":false}]}
{"op":"mcm","clk":"5348047079","pt":1646213050389,"mc":[{"id":"1.195453721","rc":[{"atl":[[1000,1.57]],"id":41419594}],"con":true,"img":false}]}
{"op":"mcm","clk":"5348047085","pt":1646213050488,"mc":[{"id":"1.195453721","rc":[{"atl":[[75,9.9],[190,9.51]],"id":41419630},{"atb":[[40,0]],"id":41419612}],"con":true,"img":false}]}
{"op":"mcm","clk":"5348047122","pt":1646213051103,"mc":[{"id":"1.195453721","rc":[{"atl":[[170,4.95]],"id":41419594}],"con":true,"img":false}]}
{"op":"mcm","clk":"5348047221","pt":1646213053110,"mc":[{"id":"1.195453721","rc":[{"atl":[[470,0]],"id":41419594}],"con":true,"img":false}]}
{"op":"mcm","clk":"5348047226","pt":1646213053168,"mc":[{"id":"1.195453721","rc":[{"atl":[[880,2]],"id":41419594}],"con":true,"img":false}]}
{"op":"mcm","clk":"5348047291","pt":1646213054481,"mc":[{"id":"1.195453721","rc":[{"atb":[[50,5.96]],"id":41419587},{"atl":[[23,0],[24,11.84],[27,0],[28,26.33]],"id":41419637}],"con":true,"img":false}]}
{"op":"mcm","clk":"5348047320","pt":1646213054991,"mc":[{"id":"1.195453721","rc":[{"atl":[[65,24.18]],"id":41419637}],"con":true,"img":false}]}
{"op":"mcm","clk":"5348047325","pt":1646213055097,"mc":[{"id":"1.195453721","rc":[{"atl":[[28,9.9]],"id":41419637}],"con":true,"img":false}]}
{"op":"mcm","clk":"5348047332","pt":1646213055299,"mc":[{"id":"1.195453721","rc":[{"atb":[[36,0],[50,2.72]],"id":41419587},{"atl":[[24,6.89],[28,0]],"id":41419637}],"con":true,"img":false}]}
{"op":"mcm","clk":"5348047343","pt":1646213055503,"mc":[{"id":"1.195453721","rc":[{"atl":[[22,43.4]],"id":41419633},{"atl":[[75,29.81]],"id":41419598}],"con":true,"img":false}]}
{"op":"mcm","clk":"5348047353","pt":1646213055712,"mc":[{"id":"1.195453721","rc":[{"atl":[[80,6.95],[100,24.33]],"id":41419593},{"atl":[[65,0],[70,2]],"id":41419637},{"atl":[[160,0.99]],"id":41419594}],"con":true,"img":false}]}
{"op":"mcm","clk":"5348047372","pt":1646213055984,"mc":[{"id":"1.195453721","rc":[{"atb":[[42,8.82]],"id":41419587},{"atl":[[23,4.95],[27,9.9]],"id":41419637}],"con":true,"img":false}]}
{"op":"mcm","clk":"5348047395","pt":1646213056496,"mc":[{"id":"1.195453721","rc":[{"atl":[[85,0]],"id":41419593}],"con":true,"img":false}]}
{"op":"mcm","clk":"5348047406","pt":1646213056804,"mc":[{"id":"1.195453721","rc":[{"atl":[[160,0],[1000,1.41]],"id":41419594}],"con":true,"img":false}]}
{"op":"mcm","clk":"5348047450","pt":1646213057786,"mc":[{"id":"1.195453721","rc":[{"atl":[[160,0.99]],"id":41419594}],"con":true,"img":false}]}
{"op":"mcm","clk":"5348047469","pt":1646213058198,"mc":[{"id":"1.195453721","rc":[{"atl":[[880,3.64]],"id":41419594}],"con":true,"img":false}]}
{"op":"mcm","clk":"5348047474","pt":1646213058302,"mc":[{"id":"1.195453721","rc":[{"atl":[[1000,0]],"id":41419594}],"con":true,"img":false}]}
{"op":"mcm","clk":"5348047508","pt":1646213059179,"mc":[{"id":"1.195453721","rc":[{"atl":[[160,0]],"id":41419594}],"con":true,"img":false}]}
{"op":"mcm","clk":"5348047550","pt":1646213059897,"mc":[{"id":"1.195453721","rc":[{"atl":[[170,5.89]],"id":41419594}],"con":true,"img":false}]}
{"op":"mcm","clk":"5348047603","pt":1646213060980,"mc":[{"id":"1.195453721","rc":[{"atl":[[44,2.33],[25,27.5]],"id":41419635}],"con":true,"img":false}]}
{"op":"mcm","clk":"5348047620","pt":1646213061293,"mc":[{"id":"1.195453721","rc":[{"atl":[[27,27.5]],"id":41419637}],"con":true,"img":false}]}
{"op":"mcm","clk":"5348047624","pt":1646213061393,"mc":[{"id":"1.195453721","rc":[{"atl":[[60,7.64]],"id":41419601}],"con":true,"img":false}]}
{"op":"mcm","clk":"5348047628","pt":1646213061495,"mc":[{"id":"1.195453721","rc":[{"atl":[[180,5.84]],"id":41419607},{"atl":[[21,12.88]],"id":41419635},{"atb":[[30,10.42]],"id":41419590}],"con":true,"img":false}]}
{"op":"mcm","clk":"5348047633","pt":1646213061600,"mc":[{"id":"1.195453721","rc":[{"atl":[[14,17.15]],"id":41419634},{"atl":[[130,6.18]],"id":41419606}],"con":true,"img":false}]}
{"op":"mcm","clk":"5348047661","pt":1646213062313,"mc":[{"id":"1.195453721","rc":[{"atl":[[190,0]],"id":41419607},{"atl":[[26,16.78]],"id":41419634},{"atl":[[180,7.88]],"id":41419601}],"con":true,"img":false}]}
{"op":"mcm","clk":"5348047667","pt":1646213062417,"mc":[{"id":"1.195453721","rc":[{"atl":[[380,0]],"id":41419606},{"atl":[[24,0]],"id":41419635},{"atb":[[29,0]],"id":41419590}],"con":true,"img":false}]}
{"op":"mcm","clk":"5348047678","pt":1646213062686,"mc":[{"id":"1.195453721","rc":[{"atl":[[520,2],[200,7.31]],"id":41419607},{"atl":[[300,6.87],[100,9.9]],"id":41419593},{"atl":[[60,2.68]],"id":41419600}],"con":true,"img":false}]}
{"op":"mcm","clk":"5348047690","pt":1646213062992,"mc":[{"id":"1.195453721","rc":[{"atl":[[150,9.75],[390,2]],"id":41419606},{"atb":[[26,39.36],[28,2.72]],"id":41419590}],"con":true,"img":false}]}
{"op":"mcm","clk":"5348047706","pt":1646213063303,"mc":[{"id":"1.195453721","rc":[{"atl":[[65,24.56],[70,0]],"id":41419600}],"con":true,"img":false}]}
{"op":"mcm","clk":"5348047729","pt":1646213063717,"mc":[{"id":"1.195453721","rc":[{"atl":[[65,22.08]],"id":41419600}],"con":true,"img":false}]}
{"op":"mcm","clk":"5348047735","pt":1646213063814,"mc":[{"id":"1.195453721","rc":[{"atl":[[200,0]],"id":41419607}],"con":true,"img":false}]}
{"op":"mcm","clk":"5348047743","pt":1646213064020,"mc":[{"id":"1.195453721","rc":[{"atl":[[150,0]],"id":41419606}],"con":true,"img":false}]}
{"op":"mcm","clk":"5348047770","pt":1646213064492,"mc":[{"id":"1.195453721","rc":[{"atl":[[50,3.23]],"id":41419600}],"con":true,"img":false}]}
{"op":"mcm","clk":"5348047788","pt":1646213064802,"mc":[{"id":"1.195453721","rc":[{"atl":[[190,7.72],[880,2]],"id":41419594}],"con":true,"img":false}]}
{"op":"mcm","clk":"5348047801","pt":1646213065006,"mc":[{"id":"1.195453721","rc":[{"atl":[[880,0],[470,2]],"id":41419594}],"con":true,"img":false}]}
{"op":"mcm","clk":"5348047805","pt":1646213065114,"mc":[{"id":"1.195453721","rc":[{"atb":[[9.8,0],[8.8,0]],"id":41419634},{"atb":[[11,0],[13.5,0]],"id":41419635}],"con":true,"img":false}]}
{"op":"mcm","clk":"5348047828","pt":1646213065518,"mc":[{"id":"1.195453721","rc":[{"atb":[[7.8,28.26],[7,86.83]],"id":41419634},{"atb":[[10.5,4.95],[9.4,55.22]],"id":41419635},{"atl":[[60,0]],"id":41419600}],"con":true,"img":false}]}
{"op":"mcm","clk":"5348047834","pt":1646213065622,"mc":[{"id":"1.195453721","rc":[{"atb":[[10.5,21.64]],"id":41419635}],"con":true,"img":false}]}
{"op":"mcm","clk":"5348047849","pt":1646213065786,"mc":[{"id":"1.195453721","rc":[{"atb":[[9,3.26],[10,2.72]],"id":41419634},{"atb":[[14,2.72]],"id":41419635}],"con":true,"img":false}]}
{"op":"mcm","clk":"5348047857","pt":1646213065884,"mc":[{"id":"1.195453721","rc":[{"atb":[[11.5,3.26]],"id":41419635}],"con":true,"img":false}]}
{"op":"mcm","clk":"5348047876","pt":1646213066192,"mc":[{"id":"1.195453721","rc":[{"atb":[[7.6,0]],"id":41419634}],"con":true,"img":false}]}
{"op":"mcm","clk":"5348047892","pt":1646213066506,"mc":[{"id":"1.195453721","rc":[{"atb":[[10,0]],"id":41419635}],"con":true,"img":false}]}
{"op":"mcm","clk":"5348047955","pt":1646213067690,"mc":[{"id":"1.195453721","rc":[{"atl":[[23,12.15]],"id":41419637}],"con":true,"img":false}]}
{"op":"mcm","clk":"5348047966","pt":1646213067897,"mc":[{"id":"1.195453721","rc":[{"atl":[[44,26.33],[25,9.9]],"id":41419635}],"con":true,"img":false}]}
{"op":"mcm","clk":"5348048013","pt":1646213068621,"mc":[{"id":"1.195453721","rc":[{"atl":[[24,0]],"id":41419637}],"con":true,"img":false}]}
{"op":"mcm","clk":"5348048040","pt":1646213068928,"mc":[{"id":"1.195453721","rc":[{"atb":[[50,5.96]],"id":41419587}],"con":true,"img":false}]}
{"op":"mcm","clk":"5348048070","pt":1646213069302,"mc":[{"id":"1.195453721","rc":[{"atl":[[70,23.16],[27,9.9]],"id":41419637},{"atl":[[50,0]],"id":41419600}],"con":true,"img":false}]}
{"op":"mcm","clk":"5348048115","pt":1646213070024,"mc":[{"id":"1.195453721","rc":[{"atb":[[42,4.95],[50,2.72]],"id":41419587}],"con":true,"img":false}]}
{"op":"mcm","clk":"5348048128","pt":1646213070223,"mc":[{"id":"1.195453721","rc":[{"atl":[[65,0],[75,29.7],[60,2.68]],"id":41419600}],"con":true,"img":false}]}
{"op":"mcm","clk":"5348048167","pt":1646213070904,"mc":[{"id":"1.195453721","rc":[{"atb":[[42,8.82]],"id":41419587}],"con":true,"img":false}]}
{"op":"mcm","clk":"5348048222","pt":1646213071925,"mc":[{"id":"1.195453721","rc":[{"atl":[[190,0],[470,5.16]],"id":41419594}],"con":true,"img":false}]}
{"op":"mcm","clk":"5348048405","pt":1646213075335,"mc":[{"id":"1.195453721","rc":[{"atb":[[25,9.33]],"id":41419628}],"con":true,"img":false}]}
{"op":"mcm","clk":"5348048464","pt":1646213076118,"mc":[{"id":"1.195453721","rc":[{"atb":[[24,4.95]],"id":41419628}],"con":true,"img":false}]}
{"op":"mcm","clk":"5348048519","pt":1646213076841,"mc":[{"id":"1.195453721","rc":[{"atl":[[200,7.5]],"id":41419607},{"atl":[[50,3.23]],"id":41419600}],"con":true,"img":false}]}
{"op":"mcm","clk":"5348048529","pt":1646213076943,"mc":[{"id":"1.195453721","rc":[{"atb":[[8.2,2.72]],"id":41419636},{"atl":[[38,4.28],[42,4.95],[46,0],[50,9.9]],"id":41419591},{"atl":[[150,9.9],[110,4.95]],"id":41419587},{"atb":[[25,9.9],[26,15.48],[29,4.95],[30,0]],"id":41419601},{"atb":[[25,2.72]],"id":41419628},{"atl":[[150,9.9],[110,6.4],[120,0]],"id":41419608},{"atb":[[42,0],[44,9.9],[50,0],[55,4.95]],"id":41419606},{"atl":[[40,4.95],[42,3.86],[48,9.9],[50,0]],"id":41419604},{"atb":[[42,6.59]],"id":41419585},{"atl":[[75,7.09],[80,4.95],[100,9.9]],"id":41419585},{"atb":[[25,7.67]],"id":41419600},{"atl":[[34,4.95]],"id":41419627}],"con":true,"img":false}]}
{"op":"mcm","clk":"5348048534","pt":1646213077045,"mc":[{"id":"1.195453721","rc":[{"atl":[[95,1.68]],"id":41419587},{"atb":[[17.5,0],[19.5,0]],"id":41419599},{"atb":[[19,9.9],[20,24.49],[22,4.95],[24,0]],"id":41419628},{"atl":[[75,2.14],[95,0]],"id":41419585},{"atb":[[19.5,9.9],[21,0],[23,4.95],[25,2.72]],"id":41419600}],"con":true,"img":false}]}
{"op":"mcm","clk":"5348048542","pt":1646213077107,"mc":[{"id":"1.195453721","rc":[{"atl":[[350,2],[720,0]],"id":41419587},{"atb":[[18,9.9],[20,4.95]],"id":41419599}],"con":true,"img":false}]}
{"op":"mcm","clk":"5348048546","pt":1646213077206,"mc":[{"id":"1.195453721","rc":[{"atl":[[150,10.02]],"id":41419606}],"con":true,"img":false}]}
{"op":"mcm","clk":"5348048552","pt":1646213077319,"mc":[{"id":"1.195453721","rc":[{"atl":[[150,19.93],[750,0]],"id":41419587},{"atl":[[38,4.28]],"id":41419604},{"atl":[[75,9.9],[60,24.77]],"id":41419600}],"con":true,"img":false}]}
{"op":"mcm","clk":"5348048556","pt":1646213077413,"mc":[{"id":"1.195453721","rc":[{"atl":[[50,29.05],[110,2]],"id":41419591},{"atl":[[130,2],[48,39.36]],"id":41419604},{"atl":[[290,0.55],[95,15.84]],"id":41419585}],"con":true,"img":false}]}
{"op":"mcm","clk":"5348048561","pt":1646213077519,"mc":[{"id":"1.195453721","rc":[{"atb":[[18.5,3.26],[11,47.84]],"id":41419599},{"atl":[[60,22.08]],"id":41419600}],"con":true,"img":false}]}
{"op":"mcm","clk":"5348048565","pt":1646213077621,"mc":[{"id":"1.195453721","rc":[{"atb":[[7.4,29.72]],"id":41419636},{"atb":[[22,12.5]],"id":41419628},{"atl":[[290,0]],"id":41419585},{"atb":[[24,6.89]],"id":41419600},{"atl":[[40,4.06]],"id":41419627}],"con":true,"img":false}]}
{"op":"mcm","clk":"5348048587","pt":1646213078033,"mc":[{"id":"1.195453721","rc":[{"atl":[[42,0]],"id":41419604},{"atb":[[23,19.66]],"id":41419600},{"atl":[[42,23.31],[110,2]],"id":41419627}],"con":true,"img":false}]}
{"op":"mcm","clk":"5348048592","pt":1646213078130,"mc":[{"id":"1.195453721","rc":[{"atb":[[20,3.26]],"id":41419600}],"con":true,"img":false}]}
{"op":"mcm","clk":"5348048637","pt":1646213078928,"mc":[{"id":"1.195453721","rc":[{"atl":[[470,2]],"id":41419594}],"con":true,"img":false}]}
{"op":"mcm","clk":"5348048648","pt":1646213079135,"mc":[{"id":"1.195453721","rc":[{"atl":[[190,7.94]],"id":41419594}],"con":true,"img":false}]}
{"op":"mcm","clk":"5348048675","pt":1646213079534,"mc":[{"id":"1.195453721","rc":[{"atb":[[7.8,67.93],[7,32.1]],"id":41419634},{"atb":[[10.5,55.51],[9.4,9.9]],"id":41419635}],"con":true,"img":false}]}
{"op":"mcm","clk":"5348048724","pt":1646213080525,"mc":[{"id":"1.195453721","rc":[{"atb":[[46,6.24]],"id":41419592}],"con":true,"img":false}]}
{"op":"mcm","clk":"5348048857","pt":1646213082943,"mc":[{"id":"1.195453721","rc":[{"atb":[[50,5.96]],"id":41419587}],"con":true,"img":false}]}
{"op":"mcm","clk":"5348048896","pt":1646213083624,"mc":[{"id":"1.195453721","rc":[{"atl":[[520,4.92],[200,0]],"id":41419607}],"con":true,"img":false}]}
{"op":"mcm","clk":"5348048913","pt":1646213083932,"mc":[{"id":"1.195453721","rc":[{"atb":[[42,4.95],[50,2.72]],"id":41419587}],"con":true,"img":false}]}
{"op":"mcm","clk":"5348048927","pt":1646213084234,"mc":[{"id":"1.195453721","rc":[{"atl":[[150,0],[390,5.9]],"id":41419606}],"con":true,"img":false}]}
{"op":"mcm","clk":"5348048980","pt":1646213084911,"mc":[{"id":"1.195453721","rc":[{"atb":[[42,8.82]],"id":41419587}],"con":true,"img":false}]}
{"op":"mcm","clk":"5348049031","pt":1646213085841,"mc":[{"id":"1.195453721","rc":[{"atb":[[19,0],[19.5,9.9],[22,7.54],[23,4.95]],"id":41419628}],"con":true,"img":false}]}
{"op":"mcm","clk":"5348049040","pt":1646213085945,"mc":[{"id":"1.195453721","rc":[{"atb":[[46,2.72]],"id":41419592}],"con":true,"img":false}]}
{"op":"mcm","clk":"5348049048","pt":1646213086081,"mc":[{"id":"1.195453721","rc":[{"atl":[[190,0],[470,5.24]],"id":41419594}],"con":true,"img":false}]}
{"op":"mcm","clk":"5348049072","pt":1646213086336,"mc":[{"id":"1.195453721","rc":[{"atb":[[22,31.6]],"id":41419628}],"con":true,"img":false}]}
{"op":"mcm","clk":"5348049077","pt":1646213086443,"mc":[{"id":"1.195453721","rc":[{"atb":[[20,3.26]],"id":41419628}],"con":true,"img":false}]}
{"op":"mcm","clk":"5348049096","pt":1646213086744,"mc":[{"id":"1.195453721","rc":[{"atb":[[36,12.75]],"id":41419592}],"con":true,"img":false}]}
{"op":"mcm","clk":"5348049206","pt":1646213089016,"mc":[{"id":"1.195453721","rc":[{"atl":[[50,0]],"id":41419600}],"con":true,"img":false}]}
{"op":"mcm","clk":"5348049209","pt":1646213089119,"mc":[{"id":"1.195453721","rc":[{"atl":[[16,0],[16.5,9.9],[14,0],[14.5,4.95]],"id":41419634}],"con":true,"img":false}]}
{"op":"mcm","clk":"5348049236","pt":1646213089733,"mc":[{"id":"1.195453721","rc":[{"atl":[[75,30.43],[55,7.89]],"id":41419600}],"con":true,"img":false}]}
{"op":"mcm","clk":"5348049242","pt":1646213089836,"mc":[{"id":"1.195453721","rc":[{"atl":[[16.5,0],[16,18.81],[14,4.95],[14.5,0]],"id":41419634},{"atl":[[60,0]],"id":41419600}],"con":true,"img":false}]}
{"op":"mcm","clk":"5348049278","pt":1646213090657,"mc":[{"id":"1.195453721","rc":[{"atl":[[520,2],[200,7.7]],"id":41419607}],"con":true,"img":false}]}
{"op":"mcm","clk":"5348049296","pt":1646213091026,"mc":[{"id":"1.195453721","rc":[{"atl":[[150,10.28],[390,2]],"id":41419606}],"con":true,"img":false}]}
{"op":"mcm","clk":"5348049312","pt":1646213091336,"mc":[{"id":"1.195453721","rc":[{"atb":[[18.5,24.71],[11,13.31]],"id":41419599}],"con":true,"img":false}]}
{"op":"mcm","clk":"5348049317","pt":1646213091439,"mc":[{"id":"1.195453721","rc":[{"atl":[[140,4.95],[150,1.06]],"id":41419611}],"con":true,"img":false}]}
{"op":"mcm","clk":"5348049327","pt":1646213091646,"mc":[{"id":"1.195453721","rc":[{"atl":[[870,0],[480,2]],"id":41419611}],"con":true,"img":false}]}
{"op":"mcm","clk":"5348049331","pt":1646213091748,"mc":[{"id":"1.195453721","rc":[{"atb":[[70,4.95]],"id":41419611}],"con":true,"img":false}]}
{"op":"mcm","clk":"5348049348","pt":1646213092055,"mc":[{"id":"1.195453721","rc":[{"atl":[[130,1.23],[870,1.76],[900,0]],"id":41419611}],"con":true,"img":false}]}
{"op":"mcm","clk":"5348049360","pt":1646213092325,"mc":[{"id":"1.195453721","rc":[{"atb":[[65,4.95],[70,0],[48,24.03],[50,0]],"id":41419611}],"con":true,"img":false}]}
{"op":"mcm","clk":"5348049385","pt":1646213092841,"mc":[{"id":"1.195453721","rc":[{"atb":[[65,7.43],[38,15.48],[48,12.63]],"id":41419611},{"atl":[[150,0]],"id":41419611},{"atl":[[190,8.14],[470,2]],"id":41419594}],"con":true,"img":false}]}
{"op":"mcm","clk":"5348049425","pt":1646213093453,"mc":[{"id":"1.195453721","rc":[{"atb":[[25,9.33]],"id":41419600}],"con":true,"img":false}]}
{"op":"mcm","clk":"5348049442","pt":1646213093722,"mc":[{"id":"1.195453721","rc":[{"atl":[[190,0]],"id":41419594}],"con":true,"img":false}]}
{"op":"mcm","clk":"5348049467","pt":1646213094236,"mc":[{"id":"1.195453721","rc":[{"atb":[[46,6.24]],"id":41419592},{"atb":[[24,0]],"id":41419600}],"con":true,"img":false}]}
{"op":"mcm","clk":"5348049495","pt":1646213094850,"mc":[{"id":"1.195453721","rc":[{"atb":[[20,28.86],[23,4.95]],"id":41419600}],"con":true,"img":false}]}
{"op":"mcm","clk":"5348049504","pt":1646213095059,"mc":[{"id":"1.195453721","rc":[{"atb":[[36,8.22]],"id":41419592}],"con":true,"img":false}]}
{"op":"mcm","clk":"5348049581","pt":1646213096355,"mc":[{"id":"1.195453721","rc":[{"atl":[[140,9.9],[150,10.02],[100,4.95],[110,0]],"id":41419587},{"atl":[[130,13.98],[75,9.9]],"id":41419600}],"con":true,"img":false}]}
{"op":"mcm","clk":"5348049593","pt":1646213096461,"mc":[{"id":"1.195453721","rc":[{"atb":[[25,2.72]],"id":41419600}],"con":true,"img":false}]}
{"op":"mcm","clk":"5348049603","pt":1646213096564,"mc":[{"id":"1.195453721","rc":[{"atb":[[50,5.96]],"id":41419587}],"con":true,"img":false}]}
{"op":"mcm","clk":"5348049622","pt":1646213096932,"mc":[{"id":"1.195453721","rc":[{"atl":[[140,21.04],[150,0]],"id":41419587}],"con":true,"img":false}]}
{"op":"mcm","clk":"5348049647","pt":1646213097241,"mc":[{"id":"1.195453721","rc":[{"atb":[[23,12.15]],"id":41419600}],"con":true,"img":false}]}
{"op":"mcm","clk":"5348049651","pt":1646213097345,"mc":[{"id":"1.195453721","rc":[{"atl":[[520,4.99],[200,0]],"id":41419607}],"con":true,"img":false}]}
{"op":"mcm","clk":"5348049658","pt":1646213097445,"mc":[{"id":"1.195453721","rc":[{"atb":[[42,4.95],[50,2.72]],"id":41419587}],"con":true,"img":false}]}
{"op":"mcm","clk":"5348049663","pt":1646213097555,"mc":[{"id":"1.195453721","rc":[{"atb":[[18,31.73],[18.5,9.9],[20,0],[21,12.88]],"id":41419591},{"atb":[[34,0],[36,9.9],[42,0],[44,4.95]],"id":41419587},{"atl":[[34,9.9],[38,22.32],[28,4.95],[30,0]],"id":41419629},{"atl":[[150,4.95],[170,0.93]],"id":41419594}],"con":true,"img":false}]}
{"op":"mcm","clk":"5348049670","pt":1646213097657,"mc":[{"id":"1.195453721","rc":[{"atl":[[150,0],[390,6]],"id":41419606}],"con":true,"img":false}]}
{"op":"mcm","clk":"5348049680","pt":1646213097961,"mc":[{"id":"1.195453721","rc":[{"atl":[[34,33.04],[38,0],[27,6.09]],"id":41419629}],"con":true,"img":false}]}
{"op":"mcm","clk":"5348049684","pt":1646213098025,"mc":[{"id":"1.195453721","rc":[{"atl":[[150,6.01]],"id":41419594}],"con":true,"img":false}]}
{"op":"mcm","clk":"5348049686","pt":1646213098126,"mc":[{"id":"1.195453721","rc":[{"atl":[[75,4.95],[80,2],[95,9.9],[100,0]],"id":41419593},{"atb":[[46,3.52]],"id":41419587}],"con":true,"img":false}]}
{"op":"mcm","clk":"5348049688","pt":1646213098230,"mc":[{"id":"1.195453721","rc":[{"atl":[[20,4.95],[24,9.9]],"id":41419635}],"con":true,"img":false}]}
{"op":"mcm","clk":"5348049695","pt":1646213098335,"mc":[{"id":"1.195453721","rc":[{"atl":[[21,7.92],[25,0]],"id":41419635}],"con":true,"img":false}]}
{"op":"mcm","clk":"5348049717","pt":1646213098641,"mc":[{"id":"1.195453721","rc":[{"atl":[[75,7.09],[300,2],[95,26.38]],"id":41419593},{"atb":[[40,3.26],[44,17.54]],"id":41419587},{"atl":[[34,9.9],[29,0]],"id":41419629}],"con":true,"img":false}]}
{"op":"mcm","clk":"5348049726","pt":1646213098743,"mc":[{"id":"1.195453721","rc":[{"atl":[[20,13.29],[44,2.33],[24,31.99]],"id":41419635}],"con":true,"img":false}]}
{"op":"mcm","clk":"5348049737","pt":1646213098953,"mc":[{"id":"1.195453721","rc":[{"atl":[[170,0]],"id":41419594}],"con":true,"img":false}]}
{"op":"mcm","clk":"5348049767","pt":1646213099524,"mc":[{"id":"1.195453721","rc":[{"atl":[[80,0]],"id":41419593},{"atl":[[21,0]],"id":41419635}],"con":true,"img":false}]}
{"op":"mcm","clk":"5348049771","pt":1646213099629,"mc":[{"id":"1.195453721","rc":[{"atl":[[170,9.22]],"id":41419594}],"con":true,"img":false}]}
{"op":"mcm","clk":"5348049845","pt":1646213101173,"mc":[{"id":"1.195453721","rc":[{"atb":[[20,0],[25,9.71]],"id":41419587},{"atb":[[11,0],[14,7.69]],"id":41419630}],"con":true,"img":false}]}
{"op":"mcm","clk":"5348049852","pt":1646213101233,"mc":[{"id":"1.195453721","rc":[{"atl":[[75,2.14],[95,16.47]],"id":41419593},{"atb":[[25,9.33]],"id":41419628}],"con":true,"img":false}]}
{"op":"mcm","clk":"5348049859","pt":1646213101336,"mc":[{"id":"1.195453721","rc":[{"atl":[[80,4.95],[100,9.9]],"id":41419593}],"con":true,"img":false}]}
{"op":"mcm","clk":"5348049867","pt":1646213101437,"mc":[{"id":"1.195453721","rc":[{"atb":[[30,8.19]],"id":41419630}],"con":true,"img":false}]}
{"op":"mcm","clk":"5348049923","pt":1646213102143,"mc":[{"id":"1.195453721","rc":[{"atb":[[25,8.22]],"id":41419630}],"con":true,"img":false}]}
{"op":"mcm","clk":"5348049927","pt":1646213102252,"mc":[{"id":"1.195453721","rc":[{"atb":[[22,24.06]],"id":41419628}],"con":true,"img":false}]}
{"op":"mcm","clk":"5348049992","pt":1646213103340,"mc":[{"id":"1.195453721","rc":[{"atl":[[14,17.15]],"id":41419634}],"con":true,"img":false}]}
{"op":"mcm","clk":"5348050010","pt":1646213103749,"mc":[{"id":"1.195453721","rc":[{"atl":[[160,4.95],[180,0.88]],"id":41419607},{"atl":[[75,9.9],[80,0],[55,4.95],[60,2.68]],"id":41419601},{"atl":[[23,7.2],[27,0]],"id":41419637},{"atl":[[130,9.9],[140,0],[95,4.95],[100,1.6]],"id":41419592},{"atb":[[32,4.95],[26,29.45],[27,9.9],[30,5.46]],"id":41419590},{"atl":[[75,0],[55,2.93]],"id":41419600}],"con":true,"img":false}]}
{"op":"mcm","clk":"5348050017","pt":1646213103856,"mc":[{"id":"1.195453721","rc":[{"atl":[[22,4.95],[26,9.9]],"id":41419637},{"atl":[[70,9.9],[50,4.95]],"id":41419600}],"con":true,"img":false}]}
{"op":"mcm","clk":"5348050033","pt":1646213104163,"mc":[{"id":"1.195453721","rc":[{"atl":[[520,2],[160,5.95],[200,7.89]],"id":41419607},{"atl":[[16,9.9]],"id":41419634},{"atl":[[75,24.62],[180,0]],"id":41419601},{"atl":[[70,2],[25,21.4]],"id":41419637},{"atl":[[130,2]],"id":41419600}],"con":true,"img":false}]}
{"op":"mcm","clk":"5348050037","pt":1646213104265,"mc":[{"id":"1.195453721","rc":[{"atl":[[130,22.06],[310,2],[95,6.63]],"id":41419592},{"atb":[[32,10.06],[26,0],[28,21.4]],"id":41419590},{"atl":[[65,24.32]],"id":41419600}],"con":true,"img":false}]}
{"op":"mcm","clk":"5348050042","pt":1646213104370,"mc":[{"id":"1.195453721","rc":[{"atl":[[50,8.19]],"id":41419600}],"con":true,"img":false}]}
{"op":"mcm","clk":"5348050050","pt":1646213104566,"mc":[{"id":"1.195453721","rc":[{"atl":[[150,10.54],[390,2]],"id":41419606}],"con":true,"img":false}]}
{"op":"mcm","clk":"5348050059","pt":1646213104773,"mc":[{"id":"1.195453721","rc":[{"atl":[[75,7.09],[80,0],[95,26.38],[100,0]],"id":41419593}],"con":true,"img":false}]}
{"op":"mcm","clk":"5348050068","pt":1646213104979,"mc":[{"id":"1.195453721","rc":[{"atl":[[180,0]],"id":41419607}],"con":true,"img":false}]}
{"op":"mcm","clk":"5348050076","pt":1646213105141,"mc":[{"id":"1.195453721","rc":[{"atl":[[100,0]],"id":41419592},{"atb":[[30,0]],"id":41419590},{"atl":[[55,0]],"id":41419600}],"con":true,"img":false}]}
{"op":"mcm","clk":"5348050082","pt":1646213105243,"mc":[{"id":"1.195453721","rc":[{"atl":[[300,7.27],[95,9.9]],"id":41419593},{"atl":[[150,0]],"id":41419606},{"atl":[[44,26.95],[24,9.9]],"id":41419635}],"con":true,"img":false}]}
{"op":"mcm","clk":"5348050100","pt":1646213105553,"mc":[{"id":"1.195453721","rc":[{"atl":[[870,0],[480,5.29]],"id":41419611}],"con":true,"img":false}]}
{"op":"mcm","clk":"5348050106","pt":1646213105761,"mc":[{"id":"1.195453721","rc":[{"atb":[[8,4.95],[7.2,9.9],[7.8,62.98],[7,22.19]],"id":41419634}],"con":true,"img":false}]}
{"op":"mcm","clk":"5348050113","pt":1646213105970,"mc":[{"id":"1.195453721","rc":[{"atl":[[75,2.14],[80,4.95],[95,0],[100,9.9]],"id":41419593}],"con":true,"img":false}]}
{"op":"mcm","clk":"5348050129","pt":1646213106270,"mc":[{"id":"1.195453721","rc":[{"atb":[[8,27.04]],"id":41419634},{"atl":[[140,4.95],[150,1.06],[470,5.36]],"id":41419594}],"con":true,"img":false}]}
{"op":"mcm","clk":"5348050136","pt":1646213106375,"mc":[{"id":"1.195453721","rc":[{"atb":[[7.8,23.31]],"id":41419634},{"atl":[[170,0]],"id":41419594}],"con":true,"img":false}]}
{"op":"mcm","clk":"5348050139","pt":1646213106479,"mc":[{"id":"1.195453721","rc":[{"atl":[[40,4.95],[42,0],[48,9.9],[50,19.14]],"id":41419591},{"atb":[[11.5,0],[14,0]],"id":41419635},{"atl":[[19,0],[19.5,4.95],[22,33.5],[23,9.9]],"id":41419633}],"con":true,"img":false}]}
{"op":"mcm","clk":"5348050157","pt":1646213106846,"mc":[{"id":"1.195453721","rc":[{"atl":[[80,0],[100,0]],"id":41419593}],"con":true,"img":false}]}
{"op":"mcm","clk":"5348050160","pt":1646213106950,"mc":[{"id":"1.195453721","rc":[{"atl":[[48,39.36],[50,0]],"id":41419591},{"atb":[[9,61.16],[10.5,21.64]],"id":41419635},{"atl":[[140,0]],"id":41419594}],"con":true,"img":false}]}
{"op":"mcm","clk":"5348050164","pt":1646213107049,"mc":[{"id":"1.195453721","rc":[{"atl":[[150,6.01]],"id":41419594}],"con":true,"img":false}]}
{"op":"mcm","clk":"5348050176","pt":1646213107257,"mc":[{"id":"1.195453721","rc":[{"atb":[[11,3.26],[13.5,2.72]],"id":41419635}],"con":true,"img":false}]}
{"op":"mcm","clk":"5348050179","pt":1646213107360,"mc":[{"id":"1.195453721","rc":[{"atl":[[20,0],[24,0]],"id":41419635},{"atl":[[140,9.9],[95,4.95],[100,4.95]],"id":41419592}],"con":true,"img":false}]}
{"op":"mcm","clk":"5348050183","pt":1646213107466,"mc":[{"id":"1.195453721","rc":[{"atl":[[21,4.95],[25,9.9]],"id":41419635},{"atl":[[130,12.15],[95,0]],"id":41419592}],"con":true,"img":false}]}
{"op":"mcm","clk":"5348050190","pt":1646213107569,"mc":[{"id":"1.195453721","rc":[{"atl":[[80,4.95],[100,9.9]],"id":41419593}],"con":true,"img":false}]}
{"op":"mcm","clk":"5348050217","pt":1646213108179,"mc":[{"id":"1.195453721","rc":[{"atl":[[24,6.89]],"id":41419635},{"atl":[[100,6.55]],"id":41419592}],"con":true,"img":false}]}
{"op":"mcm","clk":"5348050307","pt":1646213109973,"mc":[{"id":"1.195453721","rc":[{"atb":[[50,5.96]],"id":41419587}],"con":true,"img":false}]}
{"op":"mcm","clk":"5348050339","pt":1646213110693,"mc":[{"id":"1.195453721","rc":[{"atl":[[520,5.06],[200,0]],"id":41419607},{"atb":[[46,0],[50,2.72]],"id":41419587},{"atl":[[130,0],[140,21.33]],"id":41419592},{"atb":[[27,39.36],[28,2.72]],"id":41419590},{"atl":[[65,0],[70,32.75]],"id":41419600}],"con":true,"img":false}]}
{"op":"mcm","clk":"5348050356","pt":1646213111061,"mc":[{"id":"1.195453721","rc":[{"atl":[[150,10.66]],"id":41419606}],"con":true,"img":false}]}
{"op":"mcm","clk":"5348050363","pt":1646213111278,"mc":[{"id":"1.195453721","rc":[{"atb":[[40,15.48],[44,4.95]],"id":41419587},{"atl":[[34,33.7]],"id":41419629}],"con":true,"img":false}]}
{"op":"mcm","clk":"5348050368","pt":1646213111368,"mc":[{"id":"1.195453721","rc":[{"atl":[[460,0.34]],"id":41419594}],"con":true,"img":false}]}
{"op":"mcm","clk":"5348050373","pt":1646213111472,"mc":[{"id":"1.195453721","rc":[{"atl":[[520,2]],"id":41419607},{"atb":[[44,8.64]],"id":41419587}],"con":true,"img":false}]}
{"op":"mcm","clk":"5348050397","pt":1646213112084,"mc":[{"id":"1.195453721","rc":[{"atl":[[300,2],[100,25.93]],"id":41419593},{"atl":[[44,2.33],[25,27.5]],"id":41419635},{"atl":[[460,0]],"id":41419594}],"con":true,"img":false}]}
{"op":"mcm","clk":"5348050411","pt":1646213112290,"mc":[{"id":"1.195453721","rc":[{"atl":[[21,12.88]],"id":41419635}],"con":true,"img":false}]}
{"op":"mcm","clk":"5348050440","pt":1646213112658,"mc":[{"id":"1.195453721","rc":[{"atl":[[19.5,0],[19,4.95],[22,43.4],[23,0]],"id":41419633},{"atb":[[25,9.33]],"id":41419600}],"con":true,"img":false}]}
{"op":"mcm","clk":"5348050460","pt":1646213112975,"mc":[{"id":"1.195453721","rc":[{"atl":[[24,0]],"id":41419635},{"atl":[[170,9.44],[470,2]],"id":41419594}],"con":true,"img":false}]}
{"op":"mcm","clk":"5348050499","pt":1646213113586,"mc":[{"id":"1.195453721","rc":[{"atb":[[23,4.95]],"id":41419600}],"con":true,"img":false}]}
{"op":"mcm","clk":"5348050518","pt":1646213113892,"mc":[{"id":"1.195453721","rc":[{"atl":[[170,0]],"id":41419594}],"con":true,"img":false}]}
{"op":"mcm","clk":"5348050747","pt":1646213117099,"mc":[{"id":"1.195453721","rc":[{"atl":[[70,9.9]],"id":41419600}],"con":true,"img":false}]}
{"op":"mcm","clk":"5348050751","pt":1646213117201,"mc":[{"id":"1.195453721","rc":[{"atl":[[140,9.9],[310,7.21]],"id":41419592},{"atl":[[130,14.44]],"id":41419600}],"con":true,"img":false}]}
{"op":"mcm","clk":"5348050768","pt":1646213117468,"mc":[{"id":"1.195453721","rc":[{"atl":[[180,8.98]],"id":41419607},{"atl":[[150,0],[390,6.14]],"id":41419606}],"con":true,"img":false}]}
{"op":"mcm","clk":"5348050801","pt":1646213118185,"mc":[{"id":"1.195453721","rc":[{"atl":[[390,2]],"id":41419606}],"con":true,"img":false}]}
{"op":"mcm","clk":"5348050820","pt":1646213118594,"mc":[{"id":"1.195453721","rc":[{"atl":[[44,26.33],[25,9.9]],"id":41419635}],"con":true,"img":false}]}
{"op":"mcm","clk":"5348050878","pt":1646213119679,"mc":[{"id":"1.195453721","rc":[{"atl":[[170,9.54]],"id":41419594}],"con":true,"img":false}]}
{"op":"mcm","clk":"5348050901","pt":1646213120397,"mc":[{"id":"1.195453721","rc":[{"atb":[[9,16.64],[10.5,55.51]],"id":41419635}],"con":true,"img":false}]}
{"op":"mcm","clk":"5348051071","pt":1646213122988,"mc":[{"id":"1.195453721","rc":[{"atb":[[9,0],[10,0]],"id":41419634}],"con":true,"img":false}]}
{"op":"mcm","clk":"5348051088","pt":1646213123196,"mc":[{"id":"1.195453721","rc":[{"atb":[[50,5.96]],"id":41419587}],"con":true,"img":false}]}
{"op":"mcm","clk":"5348051100","pt":1646213123502,"mc":[{"id":"1.195453721","rc":[{"atb":[[8,49.69],[7.2,60.34]],"id":41419634}],"con":true,"img":false}]}
{"op":"mcm","clk":"5348051107","pt":1646213123606,"mc":[{"id":"1.195453721","rc":[{"atb":[[8,27.6]],"id":41419634}],"con":true,"img":false}]}
{"op":"mcm","clk":"5348051120","pt":1646213123773,"mc":[{"id":"1.195453721","rc":[{"atb":[[10.5,2.72]],"id":41419634}],"con":true,"img":false}]}
{"op":"mcm","clk":"5348051127","pt":1646213123873,"mc":[{"id":"1.195453721","rc":[{"atl":[[520,5.13],[180,0]],"id":41419607},{"atb":[[9.2,3.26]],"id":41419634}],"con":true,"img":false}]}
{"op":"mcm","clk":"5348051134","pt":1646213123986,"mc":[{"id":"1.195453721","rc":[{"atb":[[44,4.95],[50,2.72]],"id":41419587}],"con":true,"img":false}]}
{"op":"mcm","clk":"5348051151","pt":1646213124186,"mc":[{"id":"1.195453721","rc":[{"atb":[[7.8,0]],"id":41419634},{"atl":[[150,10.91]],"id":41419606}],"con":true,"img":false}]}
{"op":"mcm","clk":"5348051181","pt":1646213124503,"mc":[{"id":"1.195453721","rc":[{"atb":[[17.5,6.06],[15,0]],"id":41419590}],"con":true,"img":false}]}
{"op":"mcm","clk":"5348051204","pt":1646213124788,"mc":[{"id":"1.195453721","rc":[{"atl":[[11,4.95],[11.5,15.1],[13,9.9],[13.5,0]],"id":41419636},{"atb":[[42,3.86]],"id":41419587},{"atl":[[140,11.13],[150,9.9],[100,0],[110,4.95]],"id":41419587},{"atb":[[24,0],[25,9.9],[28,8.59],[29,4.95]],"id":41419586},{"atb":[[25,2.72]],"id":41419600},{"atb":[[21,10.65]],"id":41419627},{"atl":[[34,9.76]],"id":41419627}],"con":true,"img":false}]}
{"op":"mcm","clk":"5348051213","pt":1646213124891,"mc":[{"id":"1.195453721","rc":[{"atl":[[19,0],[19.5,4.95],[22,33.5],[23,9.9]],"id":41419633}],"con":true,"img":false}]}
{"op":"mcm","clk":"5348051227","pt":1646213125193,"mc":[{"id":"1.195453721","rc":[{"atb":[[7.2,22.08],[8.2,0]],"id":41419636},{"atl":[[11,20.8],[22,4.76],[13,47.08]],"id":41419636},{"atb":[[36,4.52],[28,14.71]],"id":41419593},{"atb":[[34,11.4],[27,0]],"id":41419597},{"atb":[[20,0],[25,6.6]],"id":41419628},{"atb":[[18,0],[15.5,0]],"id":41419637},{"atb":[[36,4.95],[46,3.52]],"id":41419592},{"atb":[[20,25.59],[25,0]],"id":41419600},{"atb":[[65,7.43],[46,12.5]],"id":41419594}],"con":true,"img":false}]}
{"op":"mcm","clk":"5348051233","pt":1646213125305,"mc":[{"id":"1.195453721","rc":[{"atb":[[30,5.46]],"id":41419586}],"con":true,"img":false}]}
{"op":"mcm","clk":"5348051241","pt":1646213125399,"mc":[{"id":"1.195453721","rc":[{"atb":[[40,3.26],[42,16.97]],"id":41419587},{"atb":[[23,3.26],[25,34.4]],"id":41419586}],"con":true,"img":false}]}
{"op":"mcm","clk":"5348051247","pt":1646213125511,"mc":[{"id":"1.195453721","rc":[{"atb":[[23,12.15]],"id":41419600},{"atb":[[17.5,33.77]],"id":41419627},{"atl":[[40,0]],"id":41419627}],"con":true,"img":false}]}
{"op":"mcm","clk":"5348051252","pt":1646213125605,"mc":[{"id":"1.195453721","rc":[{"atb":[[13,32.87]],"id":41419637}],"con":true,"img":false}]}
{"op":"mcm","clk":"5348051255","pt":1646213125669,"mc":[{"id":"1.195453721","rc":[{"atb":[[7.2,0],[6.6,73.67]],"id":41419636},{"atb":[[12,50.6],[13,18.16]],"id":41419637},{"atb":[[19.5,39.36],[20,0]],"id":41419600}],"con":true,"img":false}]}
{"op":"mcm","clk":"5348051269","pt":1646213125877,"mc":[{"id":"1.195453721","rc":[{"atb":[[8,2.72],[7,3.26]],"id":41419636},{"atl":[[11.5,0]],"id":41419636},{"atb":[[38,2.72],[29,3.26]],"id":41419597},{"atb":[[21,3.26],[26,2.72]],"id":41419628},{"atb":[[17.5,2.72],[15,3.26]],"id":41419637},{"atb":[[38,3.26],[48,2.72]],"id":41419592},{"atb":[[21,3.26],[26,2.72]],"id":41419600},{"atb":[[70,2.72],[48,13.17]],"id":41419594}],"con":true,"img":false}]}
{"op":"mcm","clk":"5348051278","pt":1646213125976,"mc":[{"id":"1.195453721","rc":[{"atb":[[38,2.72],[29,3.26]],"id":41419593},{"atl":[[22,12.5]],"id":41419637},{"atb":[[28,2.72]],"id":41419586},{"atl":[[42,9.9],[110,16.93]],"id":41419627},{"atl":[[170,0],[470,5.48]],"id":41419594}],"con":true,"img":false}]}
{"op":"mcm","clk":"5348051294","pt":1646213126287,"mc":[{"id":"1.195453721","rc":[{"atb":[[36,23.47]],"id":41419597},{"atb":[[12.5,0]],"id":41419637},{"atb":[[29,9.9]],"id":41419592},{"atb":[[75,2.14],[46,0],[48,33.16]],"id":41419594}],"con":true,"img":false}]}
{"op":"mcm","clk":"5348051300","pt":1646213126390,"mc":[{"id":"1.195453721","rc":[{"atb":[[34,0]],"id":41419597}],"con":true,"img":false}]}
{"op":"mcm","clk":"5348051306","pt":1646213126498,"mc":[{"id":"1.195453721","rc":[{"atb":[[32,19.04],[40,4.06]],"id":41419593},{"atb":[[22,0],[23,27.62]],"id":41419628},{"atb":[[38,18.25]],"id":41419592},{"atb":[[19.5,9.9]],"id":41419600}],"con":true,"img":false}]}
{"op":"mcm","clk":"5348051312","pt":1646213126594,"mc":[{"id":"1.195453721","rc":[{"atb":[[28,0]],"id":41419593}],"con":true,"img":false}]}
{"op":"mcm","clk":"5348051319","pt":1646213126697,"mc":[{"id":"1.195453721","rc":[{"atl":[[22,4.95],[23,0]],"id":41419637}],"con":true,"img":false}]}
{"op":"mcm","clk":"5348051341","pt":1646213127105,"mc":[{"id":"1.195453721","rc":[{"atl":[[26,31.99]],"id":41419637},{"atl":[[21,7.92],[25,0]],"id":41419635},{"atb":[[65,4.95]],"id":41419594}],"con":true,"img":false}]}
{"op":"mcm","clk":"5348051343","pt":1646213127207,"mc":[{"id":"1.195453721","rc":[{"atl":[[25,0]],"id":41419637},{"atl":[[20,4.95],[24,9.9]],"id":41419635}],"con":true,"img":false}]}
{"op":"mcm","clk":"5348051352","pt":1646213127370,"mc":[{"id":"1.195453721","rc":[{"atb":[[36,0]],"id":41419593},{"atl":[[25,6.6]],"id":41419637}],"con":true,"img":false}]}
{"op":"mcm","clk":"5348051361","pt":1646213127574,"mc":[{"id":"1.195453721","rc":[{"atl":[[44,2.33],[23,23.57]],"id":41419635}],"con":true,"img":false}]}
{"op":"mcm","clk":"5348051367","pt":1646213127678,"mc":[{"id":"1.195453721","rc":[{"atl":[[20,13.29]],"id":41419635}],"con":true,"img":false}]}
{"op":"mcm","clk":"5348051403","pt":1646213128498,"mc":[{"id":"1.195453721","rc":[{"atl":[[21,0]],"id":41419635}],"con":true,"img":false}]}
{"op":"mcm","clk":"5348051483","pt":1646213129893,"mc":[{"id":"1.195453721","rc":[{"atb":[[16,9.9],[17.5,28.81],[18,8.22],[15.5,0]],"id":41419627}],"con":true,"img":false}]}
{"op":"mcm","clk":"5348051512","pt":1646213130506,"mc":[{"id":"1.195453721","rc":[{"atl":[[520,2],[180,9.19]],"id":41419607},{"atl":[[150,0],[390,6.23]],"id":41419606}],"con":true,"img":false}]}
{"op":"mcm","clk":"5348051555","pt":1646213131294,"mc":[{"id":"1.195453721","rc":[{"atl":[[180,0]],"id":41419607}],"con":true,"img":false}]}
{"op":"mcm","clk":"5348051580","pt":1646213131703,"mc":[{"id":"1.195453721","rc":[{"atl":[[22,42.76],[13,9.9]],"id":41419636}],"con":true,"img":false}]}
{"op":"mcm","clk":"5348051619","pt":1646213132313,"mc":[{"id":"1.195453721","rc":[{"atl":[[140,4.95]],"id":41419594}],"con":true,"img":false}]}
{"op":"mcm","clk":"5348051625","pt":1646213132417,"mc":[{"id":"1.195453721","rc":[{"atl":[[150,1.06]],"id":41419594}],"con":true,"img":false}]}
{"op":"mcm","clk":"5348051648","pt":1646213132682,"mc":[{"id":"1.195453721","rc":[{"atl":[[170,9.76],[470,2]],"id":41419594}],"con":true,"img":false}]}
{"op":"mcm","clk":"5348051663","pt":1646213132994,"mc":[{"id":"1.195453721","rc":[{"atl":[[140,6.09]],"id":41419594}],"con":true,"img":false}]}
{"op":"mcm","clk":"5348051718","pt":1646213133810,"mc":[{"id":"1.195453721","rc":[{"atl":[[23,0]],"id":41419635},{"atl":[[150,6.01]],"id":41419594}],"con":true,"img":false}]}
{"op":"mcm","clk":"5348051724","pt":1646213133914,"mc":[{"id":"1.195453721","rc":[{"atl":[[24,44.4]],"id":41419635},{"atl":[[140,1.13],[150,4.95]],"id":41419594}],"con":true,"img":false}]}
{"op":"mcm","clk":"5348051775","pt":1646213134594,"mc":[{"id":"1.195453721","rc":[{"atl":[[150,0]],"id":41419594}],"con":true,"img":false}]}
{"op":"mcm","clk":"5348051827","pt":1646213135413,"mc":[{"id":"1.195453721","rc":[{"atb":[[32,12.21],[42,3.86]],"id":41419585},{"atb":[[18,4.95],[21,7.92]],"id":41419627},{"atl":[[150,4.95]],"id":41419594}],"con":true,"img":false}]}
{"op":"mcm","clk":"5348051876","pt":1646213136193,"mc":[{"id":"1.195453721","rc":[{"atb":[[50,5.96]],"id":41419587},{"atb":[[34,8.22],[44,2.72]],"id":41419585},{"atb":[[18.5,3.26],[22,2.72]],"id":41419627}],"con":true,"img":false}]}
{"op":"mcm","clk":"5348051889","pt":1646213136502,"mc":[{"id":"1.195453721","rc":[{"atb":[[8,67.27],[7.2,9.9]],"id":41419634}],"con":true,"img":false}]}
{"op":"mcm","clk":"5348051893","pt":1646213136602,"mc":[{"id":"1.195453721","rc":[{"atb":[[32,0],[34,21.33]],"id":41419585},{"atl":[[75,0]],"id":41419585},{"atb":[[17.5,0],[18.5,29.56]],"id":41419627},{"atl":[[34,4.95]],"id":41419627}],"con":true,"img":false}]}
{"op":"mcm","clk":"5348051902","pt":1646213136803,"mc":[{"id":"1.195453721","rc":[{"atl":[[180,9.29]],"id":41419607}],"con":true,"img":false}]}
{"op":"mcm","clk":"5348051906","pt":1646213136906,"mc":[{"id":"1.195453721","rc":[{"atb":[[42,13.1],[50,2.72]],"id":41419587}],"con":true,"img":false}]}
{"op":"mcm","clk":"5348051910","pt":1646213137009,"mc":[{"id":"1.195453721","rc":[{"atb":[[65,2.47],[70,4.95],[48,2.72],[50,9.9]],"id":41419611}],"con":true,"img":false}]}
{"op":"mcm","clk":"5348051918","pt":1646213137111,"mc":[{"id":"1.195453721","rc":[{"atl":[[150,11.15],[390,2]],"id":41419606},{"atl":[[95,0],[100,26.64]],"id":41419585}],"con":true,"img":false}]}
{"op":"mcm","clk":"5348051930","pt":1646213137318,"mc":[{"id":"1.195453721","rc":[{"atl":[[42,13.77]],"id":41419627}],"con":true,"img":false}]}
{"op":"mcm","clk":"5348051942","pt":1646213137480,"mc":[{"id":"1.195453721","rc":[{"atb":[[70,7.25],[38,3.26],[50,24.62]],"id":41419611}],"con":true,"img":false}]}
{"op":"mcm","clk":"5348051948","pt":1646213137583,"mc":[{"id":"1.195453721","rc":[{"atb":[[46,3.52]],"id":41419587},{"atb":[[44,6.41]],"id":41419585},{"atl":[[80,6.95]],"id":41419585}],"con":true,"img":false}]}
{"op":"mcm","clk":"5348051967","pt":1646213137791,"mc":[{"id":"1.195453721","rc":[{"atl":[[150,0]],"id":41419606}],"con":true,"img":false}]}
{"op":"mcm","clk":"5348051990","pt":1646213138202,"mc":[{"id":"1.195453721","rc":[{"atl":[[13.5,4.95],[15.5,9.9]],"id":41419634}],"con":true,"img":false}]}
{"op":"mcm","clk":"5348051995","pt":1646213138306,"mc":[{"id":"1.195453721","rc":[{"atl":[[16,0],[14,12.19]],"id":41419634}],"con":true,"img":false}]}
{"op":"mcm","clk":"5348052000","pt":1646213138412,"mc":[{"id":"1.195453721","rc":[{"atb":[[65,0]],"id":41419611},{"atb":[[42,0],[44,17.54]],"id":41419587},{"atb":[[25,9.9],[28,18.21]],"id":41419586}],"con":true,"img":false}]}
{"op":"mcm","clk":"5348052003","pt":1646213138520,"mc":[{"id":"1.195453721","rc":[{"atb":[[7,48.92],[6.6,9.9]],"id":41419636},{"atb":[[12,12.1],[13,35.34]],"id":41419637},{"atb":[[42,0]],"id":41419585},{"atb":[[21,30.17]],"id":41419600}],"con":true,"img":false}]}
{"op":"mcm","clk":"5348052016","pt":1646213138715,"mc":[{"id":"1.195453721","rc":[{"atl":[[26,0],[13.5,17.63],[15.5,31.99]],"id":41419634}],"con":true,"img":false}]}
{"op":"mcm","clk":"5348052038","pt":1646213139125,"mc":[{"id":"1.195453721","rc":[{"atb":[[65,16.35],[48,13.17]],"id":41419594}],"con":true,"img":false}]}
{"op":"mcm","clk":"5348052053","pt":1646213139398,"mc":[{"id":"1.195453721","rc":[{"atl":[[16,9.9],[13.5,12.68],[14,17.15],[15.5,22.08]],"id":41419634}],"con":true,"img":false}]}
{"op":"mcm","clk":"5348052071","pt":1646213139707,"mc":[{"id":"1.195453721","rc":[{"atl":[[13.5,0],[14,4.95]],"id":41419634}],"con":true,"img":false}]}
{"op":"mcm","clk":"5348052093","pt":1646213140049,"mc":[{"id":"1.195453721","rc":[{"atb":[[44,2.72]],"id":41419585},{"atl":[[80,4.95]],"id":41419585},{"atl":[[34,23.79],[36,9.9],[28,0],[29,4.95]],"id":41419629}],"con":true,"img":false}]}
{"op":"mcm","clk":"5348052111","pt":1646213140219,"mc":[{"id":"1.195453721","rc":[{"atl":[[16,0],[14,0]],"id":41419634},{"atl":[[44,26.95],[24,9.9]],"id":41419635}],"con":true,"img":false}]}
{"op":"mcm","clk":"5348052126","pt":1646213140417,"mc":[{"id":"1.195453721","rc":[{"atl":[[15.5,33.02]],"id":41419634}],"con":true,"img":false}]}
{"op":"mcm","clk":"5348052143","pt":1646213140626,"mc":[{"id":"1.195453721","rc":[{"atl":[[55,7.89]],"id":41419601},{"atb":[[26,9.06]],"id":41419628},{"atl":[[22,12.5]],"id":41419637},{"atl":[[19.5,0],[20,4.95],[23,0]],"id":41419633}],"con":true,"img":false}]}
{"op":"mcm","clk":"5348052151","pt":1646213140726,"mc":[{"id":"1.195453721","rc":[{"atb":[[34,26.13]],"id":41419585},{"atl":[[80,6.95]],"id":41419585}],"con":true,"img":false}]}
{"op":"mcm","clk":"5348052162","pt":1646213140888,"mc":[{"id":"1.195453721","rc":[{"atb":[[32,0],[26,9.9],[27,29.45],[30,4.95]],"id":41419590}],"con":true,"img":false}]}
{"op":"mcm","clk":"5348052174","pt":1646213141093,"mc":[{"id":"1.195453721","rc":[{"atl":[[13.5,4.95],[15.5,42.92]],"id":41419634}],"con":true,"img":false}]}
{"op":"mcm","clk":"5348052190","pt":1646213141407,"mc":[{"id":"1.195453721","rc":[{"atl":[[60,0]],"id":41419601},{"atb":[[25,0]],"id":41419628},{"atl":[[22,4.95],[25,0]],"id":41419637}],"con":true,"img":false}]}
{"op":"mcm","clk":"5348052197","pt":1646213141507,"mc":[{"id":"1.195453721","rc":[{"atl":[[55,4.95]],"id":41419601},{"atb":[[26,2.72]],"id":41419628},{"atl":[[80,4.95]],"id":41419585}],"con":true,"img":false}]}
{"op":"mcm","clk":"5348052203","pt":1646213141616,"mc":[{"id":"1.195453721","rc":[{"atl":[[11,4.95],[11.5,4.95],[13.5,9.9]],"id":41419636}],"con":true,"img":false}]}
{"op":"mcm","clk":"5348052209","pt":1646213141717,"mc":[{"id":"1.195453721","rc":[{"atl":[[11,0],[13,0]],"id":41419636},{"atb":[[29,5.66]],"id":41419590}],"con":true,"img":false}]}
{"op":"mcm","clk":"5348052221","pt":1646213141966,"mc":[{"id":"1.195453721","rc":[{"atl":[[75,9.9],[190,10.87]],"id":41419601},{"atb":[[21,31.47],[23,4.95]],"id":41419628},{"atl":[[70,14.21],[26,9.9]],"id":41419637}],"con":true,"img":false}]}
{"op":"mcm","clk":"5348052233","pt":1646213142119,"mc":[{"id":"1.195453721","rc":[{"atl":[[22,4.76],[13,22.08]],"id":41419636},{"atl":[[26,16.25]],"id":41419637}],"con":true,"img":false}]}
{"op":"mcm","clk":"5348052250","pt":1646213142326,"mc":[{"id":"1.195453721","rc":[{"atl":[[70,2.29]],"id":41419601},{"atb":[[23,12.15]],"id":41419628},{"atb":[[27,0],[28,21.69]],"id":41419590}],"con":true,"img":false}]}
{"op":"mcm","clk":"5348052257","pt":1646213142393,"mc":[{"id":"1.195453721","rc":[{"atl":[[13.5,21.3]],"id":41419636}],"con":true,"img":false}]}
{"op":"mcm","clk":"5348052286","pt":1646213142708,"mc":[{"id":"1.195453721","rc":[{"atb":[[28,31.99]],"id":41419585}],"con":true,"img":false}]}
{"op":"mcm","clk":"5348052291","pt":1646213142807,"mc":[{"id":"1.195453721","rc":[{"atb":[[34,13.03]],"id":41419585}],"con":true,"img":false}]}
{"op":"mcm","clk":"5348052301","pt":1646213142916,"mc":[{"id":"1.195453721","rc":[{"atl":[[520,5.24],[180,0]],"id":41419607}],"con":true,"img":false}]}
{"op":"mcm","clk":"5348052326","pt":1646213143222,"mc":[{"id":"1.195453721","rc":[{"atl":[[150,11.27]],"id":41419606},{"atl":[[300,7.62],[100,9.9]],"id":41419585}],"con":true,"img":false}]}
{"op":"mcm","clk":"5348052346","pt":1646213143625,"mc":[{"id":"1.195453721","rc":[{"atb":[[48,17.94],[50,9.9]],"id":41419611}],"con":true,"img":false}]}
{"op":"mcm","clk":"5348052431","pt":1646213145020,"mc":[{"id":"1.195453721","rc":[{"atl":[[27,16.92],[15.5,20.84]],"id":41419634}],"con":true,"img":false}]}
{"op":"mcm","clk":"5348052476","pt":1646213145595,"mc":[{"id":"1.195453721","rc":[{"atl":[[46,4.95],[60,9.9]],"id":41419628}],"con":true,"img":false}]}
{"op":"mcm","clk":"5348052484","pt":1646213145701,"mc":[{"id":"1.195453721","rc":[{"atl":[[44,0],[55,0]],"id":41419628}],"con":true,"img":false}]}
{"op":"mcm","clk":"5348052512","pt":1646213146214,"mc":[{"id":"1.195453721","rc":[{"atl":[[55,27.57]],"id":41419628}],"con":true,"img":false}]}
{"op":"mcm","clk":"5348052515","pt":1646213146315,"mc":[{"id":"1.195453721","rc":[{"atl":[[13,4.95],[13.5,0],[15,9.9],[15.5,10.93]],"id":41419634},{"atl":[[150,2]],"id":41419628}],"con":true,"img":false}]}
{"op":"mcm","clk":"5348052529","pt":1646213146519,"mc":[{"id":"1.195453721","rc":[{"atl":[[140,1.13]],"id":41419628}],"con":true,"img":false}]}
{"op":"mcm","clk":"5348052535","pt":1646213146622,"mc":[{"id":"1.195453721","rc":[{"atl":[[65,9.9],[46,0],[48,4.95],[60,0]],"id":41419628}],"con":true,"img":false}]}
{"op":"mcm","clk":"5348052564","pt":1646213147240,"mc":[{"id":"1.195453721","rc":[{"atb":[[18.5,21.44],[22,0]],"id":41419599},{"atl":[[55,0]],"id":41419628}],"con":true,"img":false}]}
{"op":"mcm","clk":"5348052597","pt":1646213147817,"mc":[{"id":"1.195453721","rc":[{"atb":[[18.5,0],[18,39.36],[20,13.29]],"id":41419599}],"con":true,"img":false}]}
{"op":"mcm","clk":"5348052604","pt":1646213147921,"mc":[{"id":"1.195453721","rc":[{"atb":[[19,3.26],[23,2.72]],"id":41419599}],"con":true,"img":false}]}
{"op":"mcm","clk":"5348052621","pt":1646213148322,"mc":[{"id":"1.195453721","rc":[{"atl":[[13,0],[13.5,85.81]],"id":41419636}],"con":true,"img":false}]}
{"op":"mcm","clk":"5348052636","pt":1646213148628,"mc":[{"id":"1.195453721","rc":[{"atb":[[18,9.9]],"id":41419599}],"con":true,"img":false}]}
{"op":"mcm","clk":"5348052644","pt":1646213148835,"mc":[{"id":"1.195453721","rc":[{"atb":[[75,7.09],[50,12.21]],"id":41419607},{"atb":[[50,5.96]],"id":41419587},{"atb":[[38,0],[48,0]],"id":41419608}],"con":true,"img":false}]}
{"op":"mcm","clk":"5348052667","pt":1646213149309,"mc":[{"id":"1.195453721","rc":[{"atl":[[520,2]],"id":41419607},{"atb":[[44,9.9],[24,25.6]],"id":41419608},{"atl":[[150,0],[390,6.37]],"id":41419606}],"con":true,"img":false}]}
{"op":"mcm","clk":"5348052673","pt":1646213149412,"mc":[{"id":"1.195453721","rc":[{"atl":[[180,9.48]],"id":41419607}],"con":true,"img":false}]}
{"op":"mcm","clk":"5348052676","pt":1646213149514,"mc":[{"id":"1.195453721","rc":[{"atb":[[80,2.72],[55,13.17]],"id":41419607},{"atb":[[46,0],[50,2.72]],"id":41419587},{"atb":[[40,3.26],[50,2.72]],"id":41419608}],"con":true,"img":false}]}
{"op":"mcm","clk":"5348052701","pt":1646213150022,"mc":[{"id":"1.195453721","rc":[{"atb":[[85,1.88],[50,0],[55,32.57]],"id":41419607},{"atb":[[7.6,0],[6.6,0]],"id":41419605},{"atb":[[40,15.48],[44,4.95]],"id":41419587}],"con":true,"img":false}]}
{"op":"mcm","clk":"5348052709","pt":1646213150230,"mc":[{"id":"1.195453721","rc":[{"atl":[[20,4.95],[21,7.92],[24,9.9],[25,0]],"id":41419605},{"atb":[[44,8.64]],"id":41419587},{"atl":[[140,9.9],[100,4.95],[110,1.45]],"id":41419597},{"atb":[[22,10.27]],"id":41419627},{"atl":[[34,9.76]],"id":41419627}],"con":true,"img":false}]}
{"op":"mcm","clk":"5348052710","pt":1646213150331,"mc":[{"id":"1.195453721","rc":[{"atb":[[21,24.38],[22,9.9],[25,3.26],[26,4.95]],"id":41419630},{"atl":[[700,0],[380,2]],"id":41419597}],"con":true,"img":false}]}
{"op":"mcm","clk":"5348052721","pt":1646213150640,"mc":[{"id":"1.195453721","rc":[{"atl":[[19.5,8.56],[24,39.36]],"id":41419605},{"atl":[[140,22.13],[730,0],[95,1.68]],"id":41419597}],"con":true,"img":false}]}
{"op":"mcm","clk":"5348052728","pt":1646213150743,"mc":[{"id":"1.195453721","rc":[{"atl":[[65,2]],"id":41419605}],"con":true,"img":false}]}
{"op":"mcm","clk":"5348052734","pt":1646213150801,"mc":[{"id":"1.195453721","rc":[{"atb":[[75,4.95]],"id":41419607},{"atb":[[6.8,3.26],[7.8,23.32]],"id":41419605},{"atb":[[21,0],[25,27.16]],"id":41419630}],"con":true,"img":false}]}
{"op":"mcm","clk":"5348052744","pt":1646213151008,"mc":[{"id":"1.195453721","rc":[{"atb":[[21,0]],"id":41419627},{"atl":[[42,9.9]],"id":41419627}],"con":true,"img":false}]}
{"op":"mcm","clk":"5348052758","pt":1646213151213,"mc":[{"id":"1.195453721","rc":[{"atl":[[13,17.17],[27,3.85]],"id":41419634},{"atb":[[25,23.89],[30,5.46]],"id":41419630}],"con":true,"img":false}]}
{"op":"mcm","clk":"5348052761","pt":1646213151314,"mc":[{"id":"1.195453721","rc":[{"atl":[[15.5,33.02]],"id":41419634}],"con":true,"img":false}]}
{"op":"mcm","clk":"5348052762","pt":1646213151418,"mc":[{"id":"1.195453721","rc":[{"atl":[[21,0]],"id":41419605},{"atl":[[110,0]],"id":41419597},{"atb":[[18.5,3.26],[18,34.95]],"id":41419627}],"con":true,"img":false}]}
{"op":"mcm","clk":"5348052773","pt":1646213151730,"mc":[{"id":"1.195453721","rc":[{"atb":[[36,0],[38,9.9],[44,3.68],[46,4.95]],"id":41419587},{"atl":[[130,4.95],[150,0],[170,19.67]],"id":41419594}],"con":true,"img":false}]}
{"op":"mcm","clk":"5348052787","pt":1646213152030,"mc":[{"id":"1.195453721","rc":[{"atl":[[15.5,22.08]],"id":41419634},{"atb":[[32,2.72],[26,8.22]],"id":41419630},{"atb":[[16,8.9],[13.5,31.99]],"id":41419629}],"con":true,"img":false}]}
{"op":"mcm","clk":"5348052794","pt":1646213152235,"mc":[{"id":"1.195453721","rc":[{"atb":[[40,3.26],[44,16.52]],"id":41419587},{"atl":[[120,1.83]],"id":41419594}],"con":true,"img":false}]}
{"op":"mcm","clk":"5348052797","pt":1646213152339,"mc":[{"id":"1.195453721","rc":[{"atl":[[75,7.09],[80,0],[95,9.9],[100,16.02]],"id":41419593}],"con":true,"img":false}]}
{"op":"mcm","clk":"5348052808","pt":1646213152547,"mc":[{"id":"1.195453721","rc":[{"atb":[[16.5,0],[36,0],[11.5,0]],"id":41419607},{"atb":[[3.2,0],[3.7,0],[5.4,0]],"id":41419605},{"atb":[[18.5,0],[7.4,0],[9.4,0]],"id":41419611},{"atb":[[16,0],[6.4,0],[8.4,0]],"id":41419593},{"atb":[[8.8,0],[4.4,0],[5.4,0]],"id":41419591},{"atb":[[9,0],[25,4.17],[12.5,0]],"id":41419587},{"atb":[[17.5,0],[9,0],[7,0]],"id":41419601},{"atb":[[6.4,0],[11,0],[5.2,0]],"id":41419599},{"atb":[[32,7.83]],"id":41419630},{"atb":[[6.2,0],[8.2,0],[15.5,0]],"id":41419597},{"atb":[[9.6,0],[19,0],[7.6,0]],"id":41419608},{"atb":[[9.2,0],[26,0],[13,0]],"id":41419606},{"atb":[[3.85,0],[7.4,0],[4.7,0]],"id":41419604},{"atl":[[18.5,4.95],[20,8.34],[21,9.9],[24,0]],"id":41419635},{"atb":[[8,0],[20,0],[10,0]],"id":41419585},{"atb":[[6.2,0],[8.2,0],[15.5,0]],"id":41419612},{"atb":[[8,0],[20,0],[10,0]],"id":41419592},{"atb":[[12,0],[6.8,0],[5.4,0]],"id":41419590},{"atb":[[12,0],[6.8,0],[5.4,0]],"id":41419586},{"atb":[[8,0],[6,0],[15,0]],"id":41419600},{"atb":[[5.3,0],[11.5,9.52],[6.6,0]],"id":41419598},{"atb":[[16,0],[34,0],[11,0]],"id":41419594}],"con":true,"img":false}]}
{"op":"mcm","clk":"5348052815","pt":1646213152649,"mc":[{"id":"1.195453721","rc":[{"atb":[[4.8,0],[3.4,0],[2.96,0]],"id":41419640},{"atb":[[3.45,0],[4.9,0],[2.98,0]],"id":41419636},{"atb":[[4.5,0],[7,0],[3.75,0]],"id":41419634},{"atb":[[17,0],[6.8,0],[8.8,0]],"id":41419630},{"atb":[[7.8,0],[14.5,0],[5.9,0]],"id":41419628},{"atb":[[12,0],[6.8,0],[5.4,0]],"id":41419637},{"atb":[[9,0],[4.5,0],[5.5,22.22]],"id":41419635},{"atb":[[5.3,7.01],[3.15,0],[3.65,0]],"id":41419633},{"atb":[[3.85,0],[7.4,0],[4.7,0]],"id":41419629},{"atb":[[6.4,0],[11,0],[5.2,0]],"id":41419627}],"con":true,"img":false}]}
{"op":"mcm","clk":"5348052826","pt":1646213152817,"mc":[{"id":"1.195453721","rc":[{"atb":[[16.5,2.72],[14,3.26]],"id":41419629},{"atl":[[170,9.9]],"id":41419594}],"con":true,"img":false}]}
{"op":"mcm","clk":"5348052843","pt":1646213153123,"mc":[{"id":"1.195453721","rc":[{"atl":[[18.5,14.01],[21,29.66],[44,2.33]],"id":41419635},{"atl":[[140,0]],"id":41419594}],"con":true,"img":false}]}
{"op":"mcm","clk":"5348052850","pt":1646213153231,"mc":[{"id":"1.195453721","rc":[{"atl":[[55,7.89]],"id":41419601},{"atb":[[26,9.06]],"id":41419628},{"atb":[[17,9.9],[13.5,9.9]],"id":41419629}],"con":true,"img":false}]}
{"op":"mcm","clk":"5348052854","pt":1646213153333,"mc":[{"id":"1.195453721","rc":[{"atb":[[30,0]],"id":41419630}],"con":true,"img":false}]}
{"op":"mcm","clk":"5348052860","pt":1646213153431,"mc":[{"id":"1.195453721","rc":[{"atb":[[15.5,21.37]],"id":41419629}],"con":true,"img":false}]}
{"op":"mcm","clk":"5348052865","pt":1646213153535,"mc":[{"id":"1.195453721","rc":[{"atl":[[170,20.02]],"id":41419594}],"con":true,"img":false}]}
{"op":"mcm","clk":"5348052881","pt":1646213153908,"mc":[{"id":"1.195453721","rc":[{"atl":[[70,0]],"id":41419601},{"atl":[[20,0]],"id":41419635}],"con":true,"img":false}]}
{"op":"mcm","clk":"5348052889","pt":1646213154115,"mc":[{"id":"1.195453721","rc":[{"atb":[[23,4.95]],"id":41419628},{"atb":[[16,0]],"id":41419629}],"con":true,"img":false}]}
{"op":"mcm","clk":"5348052893","pt":1646213154218,"mc":[{"id":"1.195453721","rc":[{"atb":[[32,5.11]],"id":41419590}],"con":true,"img":false}]}
{"op":"mcm","clk":"5348052906","pt":1646213154424,"mc":[{"id":"1.195453721","rc":[{"atl":[[22,56.28],[13.5,21.3]],"id":41419636}],"con":true,"img":false}]}
{"op":"mcm","clk":"5348052931","pt":1646213154935,"mc":[{"id":"1.195453721","rc":[{"atl":[[11.5,20.05]],"id":41419636},{"atb":[[28,2.72],[29,18.96]],"id":41419590}],"con":true,"img":false}]}
{"op":"mcm","clk":"5348052950","pt":1646213155344,"mc":[{"id":"1.195453721","rc":[{"atl":[[75,4.95],[80,0],[95,9.9],[100,0]],"id":41419585}],"con":true,"img":false}]}
{"op":"mcm","clk":"5348052958","pt":1646213155510,"mc":[{"id":"1.195453721","rc":[{"atl":[[520,5.31],[180,0]],"id":41419607}],"con":true,"img":false}]}
{"op":"mcm","clk":"5348052972","pt":1646213155714,"mc":[{"id":"1.195453721","rc":[{"atl":[[13.5,9.9]],"id":41419636},{"atl":[[150,11.51],[390,2]],"id":41419606}],"con":true,"img":false}]}
{"op":"mcm","clk":"5348053020","pt":1646213156334,"mc":[{"id":"1.195453721","rc":[{"atl":[[520,2]],"id":41419607}],"con":true,"img":false}]}
{"op":"mcm","clk":"5348053098","pt":1646213157628,"mc":[{"id":"1.195453721","rc":[{"atl":[[13.5,4.95],[15.5,31.99]],"id":41419634},{"atl":[[140,0],[85,4.95],[100,1.6],[110,9.9]],"id":41419592},{"atb":[[32,10.06],[26,0],[30,0]],"id":41419590},{"atl":[[70,0],[44,4.95],[50,3.23],[55,9.9]],"id":41419600}],"con":true,"img":false}]}
{"op":"mcm","clk":"5348053104","pt":1646213157729,"mc":[{"id":"1.195453721","rc":[{"atl":[[13,0],[15,0]],"id":41419634},{"atl":[[65,0],[48,0]],"id":41419628}],"con":true,"img":false}]}
{"op":"mcm","clk":"5348053115","pt":1646213157939,"mc":[{"id":"1.195453721","rc":[{"atl":[[46,4.95],[60,9.9]],"id":41419628}],"con":true,"img":false}]}
{"op":"mcm","clk":"5348053119","pt":1646213158038,"mc":[{"id":"1.195453721","rc":[{"atl":[[130,2],[42,3.86]],"id":41419600}],"con":true,"img":false}]}
{"op":"mcm","clk":"5348053132","pt":1646213158242,"mc":[{"id":"1.195453721","rc":[{"atl":[[15,22.08],[15.5,9.9]],"id":41419634},{"atl":[[310,2],[110,22.49]],"id":41419592},{"atl":[[55,31.99]],"id":41419600}],"con":true,"img":false}]}
{"op":"mcm","clk":"5348053144","pt":1646213158547,"mc":[{"id":"1.195453721","rc":[{"atl":[[15.5,18.81]],"id":41419634}],"con":true,"img":false}]}
{"op":"mcm","clk":"5348053158","pt":1646213158716,"mc":[{"id":"1.195453721","rc":[{"atl":[[140,13.53]],"id":41419628}],"con":true,"img":false}]}
{"op":"mcm","clk":"5348053170","pt":1646213158922,"mc":[{"id":"1.195453721","rc":[{"atl":[[50,0]],"id":41419600}],"con":true,"img":false}]}
{"op":"mcm","clk":"5348053178","pt":1646213159038,"mc":[{"id":"1.195453721","rc":[{"atl":[[46,8.47]],"id":41419628}],"con":true,"img":false}]}
{"op":"mcm","clk":"5348053193","pt":1646213159228,"mc":[{"id":"1.195453721","rc":[{"atl":[[21,9.9],[44,28.01]],"id":41419635}],"con":true,"img":false}]}
{"op":"mcm","clk":"5348053226","pt":1646213159849,"mc":[{"id":"1.195453721","rc":[{"atl":[[140,12.39]],"id":41419628}],"con":true,"img":false}]}
{"op":"mcm","clk":"5348053249","pt":1646213160254,"mc":[{"id":"1.195453721","rc":[{"atb":[[19,32.08]],"id":41419599}],"con":true,"img":false}]}
{"op":"mcm","clk":"5348053283","pt":1646213160934,"mc":[{"id":"1.195453721","rc":[{"atb":[[28,28.31],[29,0]],"id":41419590}],"con":true,"img":false}]}
{"op":"mcm","clk":"5348053288","pt":1646213161039,"mc":[{"id":"1.195453721","rc":[{"atb":[[40,0]],"id":41419593},{"atl":[[70,4.95],[75,0],[90,9.9],[95,0]],"id":41419593},{"atl":[[75,0],[80,4.95],[95,0],[100,9.9]],"id":41419585},{"atb":[[46,0]],"id":41419592}],"con":true,"img":false}]}
{"op":"mcm","clk":"5348053296","pt":1646213161238,"mc":[{"id":"1.195453721","rc":[{"atb":[[50,5.96]],"id":41419587}],"con":true,"img":false}]}
{"op":"mcm","clk":"5348053310","pt":1646213161647,"mc":[{"id":"1.195453721","rc":[{"atb":[[32,4.95],[29,25.35]],"id":41419593},{"atb":[[36,19.66],[38,3.26]],"id":41419592}],"con":true,"img":false}]}
{"op":"mcm","clk":"5348053315","pt":1646213161754,"mc":[{"id":"1.195453721","rc":[{"atl":[[180,8.08]],"id":41419607},{"atb":[[32,10.06]],"id":41419593},{"atb":[[44,31.16],[24,4.35]],"id":41419608},{"atl":[[150,0],[390,6.46]],"id":41419606},{"atl":[[290,0.55]],"id":41419585}],"con":true,"img":false}]}
{"op":"mcm","clk":"5348053332","pt":1646213162063,"mc":[{"id":"1.195453721","rc":[{"atb":[[44,12.83],[50,2.72]],"id":41419587}],"con":true,"img":false}]}
{"op":"mcm","clk":"5348053341","pt":1646213162124,"mc":[{"id":"1.195453721","rc":[{"atl":[[70,7.25]],"id":41419593}],"con":true,"img":false}]}
{"op":"mcm","clk":"5348053352","pt":1646213162329,"mc":[{"id":"1.195453721","rc":[{"atb":[[75,16.35],[55,13.17]],"id":41419607},{"atl":[[290,6.56],[300,2]],"id":41419585}],"con":true,"img":false}]}
{"op":"mcm","clk":"5348053364","pt":1646213162536,"mc":[{"id":"1.195453721","rc":[{"atl":[[390,2]],"id":41419606}],"con":true,"img":false}]}
{"op":"mcm","clk":"5348053378","pt":1646213162838,"mc":[{"id":"1.195453721","rc":[{"atb":[[46,8.47]],"id":41419587}],"con":true,"img":false}]}
{"op":"mcm","clk":"5348053387","pt":1646213162943,"mc":[{"id":"1.195453721","rc":[{"atb":[[5.3,30.97],[3.15,123.9],[3.65,100.52]],"id":41419605},{"atb":[[6.2,51.22],[8.2,36.99],[15.5,9.18]],"id":41419593},{"atb":[[5.6,57.91],[9.2,16.24],[4.6,73.99]],"id":41419591},{"atb":[[9.2,32.48],[26,5.32],[13,22.19]],"id":41419587},{"atb":[[17.5,8.07],[9,33.29],[7,44.4]],"id":41419601},{"atb":[[12,12.1],[6.8,45.93],[5.4,60.54]],"id":41419599},{"atb":[[6.2,51.22],[8.2,36.99],[15.5,9.18]],"id":41419597},{"atb":[[3.85,93.47],[7.4,20.81],[4.7,71.99]],"id":41419604},{"atb":[[21,6.65],[10.5,28.03],[8.2,36.99]],"id":41419585},{"atb":[[21,6.65],[10.5,28.03],[8.2,36.99]],"id":41419592},{"atb":[[5.5,59.19],[12.5,11.58],[7,44.4]],"id":41419590},{"atb":[[5.6,57.91],[7.2,42.96],[13,11.1]],"id":41419586},{"atb":[[5.8,55.49],[7.6,40.36],[14,10.24]],"id":41419600},{"atb":[[6.4,49.33],[11,13.31],[5.2,63.42]],"id":41419598},{"atb":[[32,4.29],[10.5,28.03],[15.5,18.37]],"id":41419594}],"con":true,"img":false}]}
{"op":"mcm","clk":"5348053395","pt":1646213163046,"mc":[{"id":"1.195453721","rc":[{"atb":[[3.35,113.35],[2.94,137.31],[4.7,35.99]],"id":41419640},{"atb":[[32,4.29],[10.5,28.03],[15.5,18.37]],"id":41419607},{"atb":[[4.8,35.05],[3.4,110.99],[2.96,135.91]],"id":41419636},{"atb":[[4.8,70.1],[7.6,20.18],[3.9,91.85]],"id":41419634},{"atb":[[18.5,7.61],[7.4,41.62],[9.4,31.71]],"id":41419611},{"atb":[[17,8.32],[6.8,45.93],[8.8,34.15]],"id":41419630},{"atb":[[5.8,55.49],[7.6,40.36],[14,10.24]],"id":41419628},{"atb":[[18.5,7.61],[7.4,41.62],[9.4,31.71]],"id":41419608},{"atb":[[27,8.97],[13.5,21.3],[9.4,31.71]],"id":41419606},{"atb":[[12,12.1],[6.8,45.93],[5.4,60.54]],"id":41419637},{"atb":[[8.8,17.07],[4.4,78.34],[5.4,60.54]],"id":41419635},{"atb":[[6.2,51.22],[8.2,36.99],[15.5,9.18]],"id":41419612},{"atb":[[5.3,37.99],[3.15,123.9],[3.65,100.52]],"id":41419633},{"atb":[[7.2,21.48],[4.6,73.99],[3.8,95.13]],"id":41419629},{"atb":[[5.3,61.94],[11.5,12.68],[6.6,47.57]],"id":41419627}],"con":true,"img":false}]}
{"op":"mcm","clk":"5348053422","pt":1646213163562,"mc":[{"id":"1.195453721","rc":[{"atb":[[10,1.42]],"id":41419640},{"atl":[[15,1.42]],"id":41419640},{"atb":[[50,1.42]],"id":41419607},{"atb":[[12,1.42]],"id":41419605},{"atl":[[18.5,1.42]],"id":41419605},{"atb":[[8.8,1.42]],"id":41419636},{"atl":[[12,1.42]],"id":41419636},{"atb":[[9.4,1.42]],"id":41419634},{"atl":[[16,1.42]],"id":41419634},{"atb":[[46,1.42]],"id":41419611},{"atb":[[30,1.42]],"id":41419593},{"atl":[[130,0.62]],"id":41419593},{"atb":[[20,1.42]],"id":41419591},{"atl":[[50,1.42]],"id":41419591},{"atb":[[42,1.42]],"id":41419587},{"atl":[[320,0.25]],"id":41419587},{"atb":[[28,1.42]],"id":41419601},{"atl":[[80,1.02]],"id":41419601},{"atb":[[21,1.42]],"id":41419599},{"atl":[[46,1.42]],"id":41419599},{"atb":[[28,1.42]],"id":41419630},{"atl":[[80,1.02]],"id":41419630},{"atb":[[34,1.42]],"id":41419597},{"atl":[[250,0.32]],"id":41419597},{"atb":[[25,1.42]],"id":41419628},{"atl":[[65,1.36]],"id":41419628},{"atb":[[42,1.42]],"id":41419608},{"atb":[[42,1.42]],"id":41419606},{"atb":[[15.5,1.42]],"id":41419637},{"atl":[[27,1.42]],"id":41419637},{"atb":[[21,1.42]],"id":41419604},{"atl":[[50,1.42]],"id":41419604},{"atl":[[22,1.42]],"id":41419635},{"atb":[[32,1.42]],"id":41419585},{"atl":[[190,0.43]],"id":41419585},{"atb":[[36,1.42]],"id":41419612},{"atl":[[200,0.4]],"id":41419612},{"atb":[[34,1.42]],"id":41419592},{"atl":[[240,0.33]],"id":41419592},{"atb":[[30,1.42]],"id":41419590},{"atl":[[110,0.74]],"id":41419590},{"atb":[[27,1.42]],"id":41419586},{"atl":[[80,1.02]],"id":41419586},{"atb":[[11.5,1.42]],"id":41419633},{"atl":[[17.5,1.42]],"id":41419633},{"atb":[[24,1.42]],"id":41419600},{"atl":[[60,1.42]],"id":41419600},{"atb":[[26,1.42]],"id":41419598},{"atl":[[80,1.25]],"id":41419598},{"atb":[[17.5,1.42]],"id":41419629},{"atl":[[38,1.42]],"id":41419629},{"atb":[[21,1.42]],"id":41419627},{"atl":[[44,1.42]],"id":41419627},{"atb":[[50,1.42]],"id":41419594}],"con":true,"img":false}]}
{"op":"mcm","clk":"5348053426","pt":1646213163618,"mc":[{"id":"1.195453721","rc":[{"atl":[[13.5,17.63]],"id":41419634}],"con":true,"img":false}]}
{"op":"mcm","clk":"5348053432","pt":1646213163725,"mc":[{"id":"1.195453721","rc":[{"atl":[[590,0],[200,2]],"id":41419586},{"atb":[[5.1,0],[7.4,15.62]],"id":41419633}],"con":true,"img":false}]}
{"op":"mcm","clk":"5348053435","pt":1646213163939,"mc":[{"id":"1.195453721","rc":[{"atb":[[8.2,2.72]],"id":41419640},{"atl":[[32,3.23]],"id":41419640},{"atb":[[7,3.26]],"id":41419636},{"atl":[[22,4.76]],"id":41419636},{"atl":[[110,2]],"id":41419599},{"atb":[[32,12.82]],"id":41419585},{"atl":[[330,2]],"id":41419612},{"atl":[[80,20.88]],"id":41419586},{"atb":[[8.6,33.45]],"id":41419633}],"con":true,"img":false}]}
{"op":"mcm","clk":"5348053440","pt":1646213164035,"mc":[{"id":"1.195453721","rc":[{"atb":[[8.6,27.04]],"id":41419640},{"atl":[[16.5,31.99]],"id":41419640},{"atb":[[12.5,13.78],[8.8,30],[7.8,2.72]],"id":41419605},{"atl":[[18,5.65],[24,9.9]],"id":41419605},{"atb":[[7.4,48.49]],"id":41419636},{"atl":[[13.5,28.68]],"id":41419636},{"atb":[[8,27.6],[9.2,15.48]],"id":41419634},{"atb":[[18.5,31.99],[18,3.26]],"id":41419591},{"atb":[[26,3.26],[28,12.82]],"id":41419601},{"atl":[[80,12.42],[190,2]],"id":41419601},{"atl":[[46,19.55]],"id":41419599},{"atb":[[25,0],[26,31.6]],"id":41419630},{"atl":[[80,22.9],[190,2]],"id":41419630},{"atb":[[21,3.26],[23,24.9]],"id":41419628},{"atb":[[13,18.16]],"id":41419637},{"atl":[[70,2],[27,10.32]],"id":41419637},{"atb":[[16.5,2.72],[18,31.99],[22,7.54]],"id":41419604},{"atb":[[28,9.9]],"id":41419585},{"atl":[[200,9.15]],"id":41419612},{"atl":[[110,16.65],[240,2]],"id":41419590},{"atl":[[570,0]],"id":41419586},{"atb":[[5.3,30.97],[12,14.41]],"id":41419633},{"atl":[[17.5,5.52],[22,0]],"id":41419633},{"atb":[[21,3.26],[23,25.26]],"id":41419600},{"atb":[[22,0],[23,31.99]],"id":41419598},{"atb":[[18.5,22.63],[18,4.95]],"id":41419627},{"atl":[[44,20.79],[110,2]],"id":41419627}],"con":true,"img":false}]}
{"op":"mcm","clk":"5348053445","pt":1646213164136,"mc":[{"id":"1.195453721","rc":[{"atl":[[15,0]],"id":41419634}],"con":true,"img":false}]}
{"op":"mcm","clk":"5348053450","pt":1646213164340,"mc":[{"id":"1.195453721","rc":[{"atl":[[15.5,40.98]],"id":41419634},{"atl":[[34,4.8],[38,4.95],[42,0],[46,9.9]],"id":41419627}],"con":true,"img":false}]}
{"op":"mcm","clk":"5348053488","pt":1646213164960,"mc":[{"id":"1.195453721","rc":[{"atl":[[15.5,1.42]],"id":41419640},{"atb":[[48,1.42]],"id":41419607},{"atb":[[11.5,1.42]],"id":41419605},{"atl":[[19,1.42]],"id":41419605},{"atl":[[12.5,1.42]],"id":41419636},{"atb":[[44,1.42]],"id":41419611},{"atl":[[140,0.62]],"id":41419593},{"atb":[[19.5,1.42]],"id":41419591},{"atl":[[55,1.42]],"id":41419591},{"atb":[[36,1.42]],"id":41419587},{"atl":[[330,0.25]],"id":41419587},{"atb":[[27,1.42]],"id":41419601},{"atl":[[85,1.02]],"id":41419601},{"atl":[[48,1.42]],"id":41419599},{"atb":[[27,1.42]],"id":41419630},{"atl":[[85,1.02]],"id":41419630},{"atl":[[260,0.32]],"id":41419597},{"atb":[[24,1.42]],"id":41419628},{"atl":[[70,1.36]],"id":41419628},{"atb":[[38,1.42]],"id":41419608},{"atl":[[28,1.42]],"id":41419637},{"atb":[[19.5,1.42],[20,4.95]],"id":41419604},{"atl":[[23,1.42]],"id":41419635},{"atl":[[180,0.45]],"id":41419585},{"atb":[[32,1.42]],"id":41419612},{"atl":[[210,0.4]],"id":41419612},{"atb":[[32,1.42]],"id":41419592},{"atl":[[230,0.35]],"id":41419592},{"atb":[[29,1.42]],"id":41419590},{"atl":[[120,0.74]],"id":41419590},{"atb":[[26,1.42]],"id":41419586},{"atl":[[85,1.02]],"id":41419586},{"atb":[[11,1.42]],"id":41419633},{"atl":[[18,1.42]],"id":41419633},{"atb":[[22,1.42]],"id":41419600},{"atl":[[65,1.42]],"id":41419600},{"atb":[[25,1.42]],"id":41419598},{"atl":[[85,1.25]],"id":41419598},{"atb":[[20,1.42]],"id":41419627},{"atl":[[46,11.33]],"id":41419627},{"atb":[[46,1.42]],"id":41419594}],"con":true,"img":false}]}
{"op":"mcm","clk":"5348053495","pt":1646213165062,"mc":[{"id":"1.195453721","rc":[{"atb":[[9.6,4.95]],"id":41419605},{"atl":[[19.5,0]],"id":41419605},{"atb":[[9.4,6.58]],"id":41419633},{"atl":[[18.5,0]],"id":41419633}],"con":true,"img":false}]}
{"op":"mcm","clk":"5348053505","pt":1646213165228,"mc":[{"id":"1.195453721","rc":[{"atl":[[16.5,9.9],[13.5,0],[14.5,4.95],[15.5,31.08]],"id":41419634}],"con":true,"img":false}]}
{"op":"mcm","clk":"5348053511","pt":1646213165333,"mc":[{"id":"1.195453721","rc":[{"atl":[[34,0]],"id":41419627}],"con":true,"img":false}]}
{"op":"mcm","clk":"5348053519","pt":1646213165538,"mc":[{"id":"1.195453721","rc":[{"atl":[[22,21.01]],"id":41419635},{"atb":[[18,9.32]],"id":41419629}],"con":true,"img":false}]}
{"op":"mcm","clk":"5348053523","pt":1646213165633,"mc":[{"id":"1.195453721","rc":[{"atl":[[44,2.33]],"id":41419635},{"atb":[[16.5,19.15],[15.5,4.95]],"id":41419629}],"con":true,"img":false}]}
{"op":"mcm","clk":"5348053528","pt":1646213165738,"mc":[{"id":"1.195453721","rc":[{"atb":[[10,0]],"id":41419640},{"atl":[[18.5,0]],"id":41419605},{"atb":[[8.8,0]],"id":41419636}],"con":true,"img":false}]}
{"op":"mcm","clk":"5348053533","pt":1646213165841,"mc":[{"id":"1.195453721","rc":[{"atl":[[18.5,2]],"id":41419605}],"con":true,"img":false}]}
{"op":"mcm","clk":"5348053543","pt":1646213166051,"mc":[{"id":"1.195453721","rc":[{"atl":[[15.5,2.84]],"id":41419640},{"atb":[[48,2.84]],"id":41419607},{"atb":[[11.5,2.84]],"id":41419605},{"atl":[[21,1.42]],"id":41419605},{"atl":[[12.5,2.84]],"id":41419636},{"atl":[[15.5,42.01]],"id":41419634},{"atb":[[44,2.84]],"id":41419611},{"atl":[[120,0.68]],"id":41419593},{"atb":[[19.5,2.84]],"id":41419591},{"atb":[[36,2.84]],"id":41419587},{"atl":[[280,0.29]],"id":41419587},{"atb":[[27,2.84]],"id":41419601},{"atl":[[85,2.04]],"id":41419601},{"atb":[[19.5,1.42]],"id":41419599},{"atl":[[48,2.84]],"id":41419599},{"atb":[[27,2.84]],"id":41419630},{"atl":[[85,2.04]],"id":41419630},{"atb":[[32,1.42]],"id":41419597},{"atl":[[220,0.37]],"id":41419597},{"atb":[[24,2.84]],"id":41419628},{"atl":[[70,2.78]],"id":41419628},{"atb":[[38,2.84]],"id":41419608},{"atb":[[40,1.42]],"id":41419606},{"atl":[[28,2.84]],"id":41419637},{"atb":[[19.5,2.84]],"id":41419604},{"atl":[[55,1.42]],"id":41419604},{"atl":[[23,2.84]],"id":41419635},{"atb":[[30,1.42]],"id":41419585},{"atl":[[170,0.47]],"id":41419585},{"atb":[[32,2.84]],"id":41419612},{"atl":[[180,0.45]],"id":41419612},{"atb":[[32,2.84]],"id":41419592},{"atl":[[210,0.38]],"id":41419592},{"atb":[[29,2.84]],"id":41419590},{"atl":[[100,0.81]],"id":41419590},{"atb":[[26,2.84]],"id":41419586},{"atl":[[85,2.11]],"id":41419586},{"atb":[[12.5,1.42]],"id":41419633},{"atl":[[19,1.42]],"id":41419633},{"atb":[[22,2.84]],"id":41419600},{"atl":[[65,2.84]],"id":41419600},{"atb":[[25,2.84]],"id":41419598},{"atl":[[32,1.42]],"id":41419629},{"atb":[[20,2.84]],"id":41419627},{"atl":[[46,12.75]],"id":41419627},{"atb":[[46,2.84]],"id":41419594}],"con":true,"img":false}]}
{"op":"mcm","clk":"5348053547","pt":1646213166152,"mc":[{"id":"1.195453721","rc":[{"atl":[[17,6.25]],"id":41419636},{"atl":[[210,2]],"id":41419593},{"atl":[[350,0]],"id":41419587},{"atl":[[44,0]],"id":41419635},{"atl":[[300,0]],"id":41419585},{"atl":[[260,2],[330,0]],"id":41419612},{"atl":[[260,2]],"id":41419592},{"atl":[[42,2.44],[55,0]],"id":41419633},{"atl":[[90,2]],"id":41419600},{"atl":[[150,2],[200,0]],"id":41419598},{"atl":[[370,2]],"id":41419594}],"con":true,"img":false}]}
{"op":"mcm","clk":"5348053550","pt":1646213166259,"mc":[{"id":"1.195453721","rc":[{"atl":[[22,0]],"id":41419636},{"atl":[[300,0]],"id":41419593},{"atl":[[280,2.29]],"id":41419587},{"atl":[[290,2],[380,0]],"id":41419597},{"atl":[[34,3.03]],"id":41419635},{"atl":[[250,2]],"id":41419585},{"atl":[[310,0]],"id":41419592},{"atl":[[130,0]],"id":41419600},{"atl":[[44,24.48]],"id":41419627},{"atl":[[470,0]],"id":41419594}],"con":true,"img":false}]}
{"op":"mcm","clk":"5348053560","pt":1646213166459,"mc":[{"id":"1.195453721","rc":[{"atb":[[17,0]],"id":41419629}],"con":true,"img":false}]}
{"op":"mcm","clk":"5348053568","pt":1646213166563,"mc":[{"id":"1.195453721","rc":[{"atb":[[44,6.41]],"id":41419585}],"con":true,"img":false}]}
{"op":"mcm","clk":"5348053574","pt":1646213166662,"mc":[{"id":"1.195453721","rc":[{"atl":[[32,17.84]],"id":41419629}],"con":true,"img":false}]}
{"op":"mcm","clk":"5348053582","pt":1646213166720,"mc":[{"id":"1.195453721","rc":[{"atl":[[12.5,11.92],[13.5,9.9]],"id":41419636},{"atl":[[34,0]],"id":41419629}],"con":true,"img":false}]}
{"op":"mcm","clk":"5348053602","pt":1646213167032,"mc":[{"id":"1.195453721","rc":[{"atl":[[18,0]],"id":41419633},{"atl":[[44,23.05]],"id":41419627}],"con":true,"img":false}]}
{"op":"mcm","clk":"5348053619","pt":1646213167237,"mc":[{"id":"1.195453721","rc":[{"atb":[[28,2.72],[29,17.61]],"id":41419590}],"con":true,"img":false}]}
{"op":"mcm","clk":"5348053628","pt":1646213167338,"mc":[{"id":"1.195453721","rc":[{"atb":[[34,8.22]],"id":41419585}],"con":true,"img":false}]}
{"op":"mcm","clk":"5348053636","pt":1646213167545,"mc":[{"id":"1.195453721","rc":[{"atb":[[10,1.42]],"id":41419640},{"atl":[[14,1.42]],"id":41419640},{"atb":[[46,1.42]],"id":41419607},{"atl":[[19.5,1.42]],"id":41419605},{"atb":[[8.6,1.42]],"id":41419636},{"atl":[[13,1.42]],"id":41419636},{"atb":[[42,1.42]],"id":41419611},{"atl":[[120,1.36]],"id":41419593},{"atb":[[34,1.42]],"id":41419587},{"atl":[[280,2.58]],"id":41419587},{"atl":[[90,1.02]],"id":41419601},{"atb":[[19.5,2.84]],"id":41419599},{"atl":[[50,1.42]],"id":41419599},{"atl":[[90,1.02]],"id":41419630},{"atb":[[32,2.84]],"id":41419597},{"atl":[[220,0.74]],"id":41419597},{"atl":[[75,1.42]],"id":41419628},{"atb":[[36,1.42]],"id":41419608},{"atl":[[29,1.42]],"id":41419637},{"atl":[[55,2.84]],"id":41419604},{"atb":[[30,2.84]],"id":41419585},{"atl":[[170,0.95]],"id":41419585},{"atl":[[190,0.43]],"id":41419612},{"atl":[[210,0.77]],"id":41419592},{"atl":[[100,1.63]],"id":41419590},{"atl":[[90,1.08]],"id":41419586},{"atb":[[12.5,2.84]],"id":41419633},{"atl":[[70,1.42]],"id":41419600},{"atb":[[24,1.42]],"id":41419598},{"atl":[[48,1.42]],"id":41419627},{"atb":[[44,1.42]],"id":41419594}],"con":true,"img":false}]}
{"op":"mcm","clk":"5348053648","pt":1646213167752,"mc":[{"id":"1.195453721","rc":[{"atl":[[520,5.37],[180,0]],"id":41419607}],"con":true,"img":false}]}
{"op":"mcm","clk":"5348053657","pt":1646213167958,"mc":[{"id":"1.195453721","rc":[{"atl":[[150,11.73]],"id":41419606}],"con":true,"img":false}]}
{"op":"mcm","clk":"5348053664","pt":1646213168055,"mc":[{"id":"1.195453721","rc":[{"atl":[[13.5,12.68]],"id":41419640}],"con":true,"img":false}]}
{"op":"mcm","clk":"5348053668","pt":1646213168158,"mc":[{"id":"1.195453721","rc":[{"atl":[[310,2],[390,0]],"id":41419606}],"con":true,"img":false}]}
{"op":"mcm","clk":"5348053691","pt":1646213168629,"mc":[{"id":"1.195453721","rc":[{"atl":[[520,2]],"id":41419607},{"atl":[[19,0]],"id":41419633}],"con":true,"img":false}]}
{"op":"mcm","clk":"5348053710","pt":1646213168939,"mc":[{"id":"1.195453721","rc":[{"atl":[[14.5,4.95]],"id":41419640}],"con":true,"img":false}]}
{"op":"mcm","clk":"5348053721","pt":1646213169144,"mc":[{"id":"1.195453721","rc":[{"atl":[[42,14.02]],"id":41419633}],"con":true,"img":false}]}
{"op":"mcm","clk":"5348053757","pt":1646213169759,"mc":[{"id":"1.195453721","rc":[{"atb":[[44,1.42]],"id":41419607},{"atl":[[150,0.68]],"id":41419593},{"atl":[[270,0.3]],"id":41419587},{"atl":[[95,1.08]],"id":41419601},{"atl":[[95,1.08]],"id":41419630},{"atl":[[210,0.38]],"id":41419597},{"atl":[[470,0.17]],"id":41419608},{"atl":[[160,0.51]],"id":41419585},{"atl":[[220,0.45]],"id":41419612},{"atl":[[220,0.38]],"id":41419592},{"atl":[[130,0.81]],"id":41419590},{"atl":[[95,1.08]],"id":41419586},{"atb":[[17,1.42]],"id":41419629},{"atl":[[34,1.42]],"id":41419629},{"atl":[[50,1.42]],"id":41419627},{"atb":[[42,1.42]],"id":41419594}],"con":true,"img":false}]}
{"op":"mcm","clk":"5348053769","pt":1646213169963,"mc":[{"id":"1.195453721","rc":[{"atl":[[44,3.68],[46,35.37]],"id":41419627}],"con":true,"img":false}]}
{"op":"mcm","clk":"5348053782","pt":1646213170233,"mc":[{"id":"1.195453721","rc":[{"atb":[[10,0]],"id":41419640},{"atb":[[8.6,0]],"id":41419636},{"atl":[[16,12.82]],"id":41419634}],"con":true,"img":false}]}
{"op":"mcm","clk":"5348053785","pt":1646213170334,"mc":[{"id":"1.195453721","rc":[{"atl":[[15.5,10.93]],"id":41419634}],"con":true,"img":false}]}
{"op":"mcm","clk":"5348053802","pt":1646213170743,"mc":[{"id":"1.195453721","rc":[{"atb":[[8.6,4.95],[8.2,28.92]],"id":41419640},{"atb":[[7.4,29.72],[7,25.84]],"id":41419636},{"atl":[[14.5,16.69]],"id":41419634}],"con":true,"img":false}]}
{"op":"mcm","clk":"5348053806","pt":1646213170847,"mc":[{"id":"1.195453721","rc":[{"atl":[[65,18.17],[140,0]],"id":41419628}],"con":true,"img":false}]}
{"op":"mcm","clk":"5348053825","pt":1646213171158,"mc":[{"id":"1.195453721","rc":[{"atb":[[44,2.84]],"id":41419607},{"atl":[[150,1.36]],"id":41419593},{"atl":[[270,0.61]],"id":41419587},{"atl":[[95,2.17]],"id":41419601},{"atl":[[95,2.17]],"id":41419630},{"atl":[[210,0.77]],"id":41419597},{"atl":[[470,0.34]],"id":41419608},{"atl":[[160,1.02]],"id":41419585},{"atl":[[220,0.9]],"id":41419612},{"atl":[[220,0.77]],"id":41419592},{"atl":[[130,1.63]],"id":41419590},{"atl":[[95,2.17]],"id":41419586},{"atb":[[17,2.84]],"id":41419629},{"atl":[[34,2.84]],"id":41419629},{"atl":[[50,2.84]],"id":41419627},{"atb":[[42,2.84]],"id":41419594}],"con":true,"img":false}]}
{"op":"mcm","clk":"5348053833","pt":1646213171358,"mc":[{"id":"1.195453721","rc":[{"atb":[[8.4,0],[9.4,11.9]],"id":41419627}],"con":true,"img":false}]}
{"op":"mcm","clk":"5348053842","pt":1646213171565,"mc":[{"id":"1.195453721","rc":[{"atl":[[15.5,0]],"id":41419634}],"con":true,"img":false}]}
{"op":"mcm","clk":"5348053846","pt":1646213171669,"mc":[{"id":"1.195453721","rc":[{"atb":[[19.5,0],[23,19.94],[24,7.79]],"id":41419628},{"atl":[[22,12.5]],"id":41419637},{"atl":[[36,0],[29,0],[30,4.95]],"id":41419629}],"con":true,"img":false}]}
{"op":"mcm","clk":"5348053892","pt":1646213172559,"mc":[{"id":"1.195453721","rc":[{"atl":[[270,0.3]],"id":41419587},{"atb":[[19,3.26],[20,42.11]],"id":41419599},{"atl":[[210,0.38]],"id":41419597},{"atl":[[470,0.17]],"id":41419608},{"atl":[[26,9.9]],"id":41419637},{"atl":[[160,0.51]],"id":41419585}],"con":true,"img":false}]}
{"op":"mcm","clk":"5348053908","pt":1646213172863,"mc":[{"id":"1.195453721","rc":[{"atb":[[18.5,22.08],[20,6.37],[21,0]],"id":41419591},{"atl":[[80,32.81],[60,4.95]],"id":41419630},{"atl":[[22,4.95]],"id":41419637},{"atb":[[32,0],[29,2.84],[30,6.37]],"id":41419590},{"atl":[[17.5,1.42]],"id":41419633},{"atl":[[27,0]],"id":41419629}],"con":true,"img":false}]}
{"op":"mcm","clk":"5348053915","pt":1646213172962,"mc":[{"id":"1.195453721","rc":[{"atl":[[75,0],[80,22.33],[55,0],[60,4.95]],"id":41419601},{"atl":[[75,0],[55,2.93]],"id":41419630},{"atl":[[22,0],[23,4.95],[26,0],[27,20.23]],"id":41419637}],"con":true,"img":false}]}
{"op":"mcm","clk":"5348053937","pt":1646213173434,"mc":[{"id":"1.195453721","rc":[{"atb":[[50,5.96]],"id":41419587},{"atl":[[27,11.33]],"id":41419637},{"atb":[[28,16.43]],"id":41419590},{"atl":[[32,1.42],[34,14.42]],"id":41419629}],"con":true,"img":false}]}
{"op":"mcm","clk":"5348053942","pt":1646213173538,"mc":[{"id":"1.195453721","rc":[{"atb":[[9.8,1.42]],"id":41419640},{"atb":[[8.8,1.42]],"id":41419636},{"atl":[[15.5,1.42]],"id":41419634},{"atl":[[160,0.68]],"id":41419593},{"atb":[[20,14.72]],"id":41419591},{"atl":[[290,0.3]],"id":41419587},{"atl":[[80,10.93],[85,16.76],[100,1.02]],"id":41419601},{"atl":[[100,1.02]],"id":41419630},{"atl":[[230,0.37]],"id":41419597},{"atl":[[490,0.16]],"id":41419608},{"atl":[[27,17.42],[28,11.92]],"id":41419637},{"atl":[[200,0.47]],"id":41419585},{"atl":[[250,0.38]],"id":41419592},{"atb":[[29,8.5]],"id":41419590},{"atl":[[140,0.81]],"id":41419590},{"atl":[[20,13.29]],"id":41419633},{"atl":[[32,6.53],[36,1.42]],"id":41419629},{"atl":[[55,1.42]],"id":41419627}],"con":true,"img":false}]}
{"op":"mcm","clk":"5348053946","pt":1646213173637,"mc":[{"id":"1.195453721","rc":[{"atb":[[18.5,31.99],[20,9.76],[21,4.95]],"id":41419591},{"atl":[[75,2.14]],"id":41419601},{"atl":[[22,4.95],[23,0],[26,9.9],[27,7.52]],"id":41419637}],"con":true,"img":false}]}
{"op":"mcm","clk":"5348053952","pt":1646213173742,"mc":[{"id":"1.195453721","rc":[{"atl":[[75,12.04],[80,1.02],[55,4.95],[60,0]],"id":41419601}],"con":true,"img":false}]}
{"op":"mcm","clk":"5348053959","pt":1646213173847,"mc":[{"id":"1.195453721","rc":[{"atl":[[180,8.08]],"id":41419607},{"atb":[[38,7],[29,3.26],[30,26.92]],"id":41419593},{"atl":[[150,0],[310,7.72]],"id":41419606},{"atl":[[80,6.95]],"id":41419585}],"con":true,"img":false}]}
{"op":"mcm","clk":"5348053965","pt":1646213174051,"mc":[{"id":"1.195453721","rc":[{"atl":[[520,0],[400,2]],"id":41419607}],"con":true,"img":false}]}
{"op":"mcm","clk":"5348053974","pt":1646213174256,"mc":[{"id":"1.195453721","rc":[{"atb":[[46,4.95],[50,2.72]],"id":41419587}],"con":true,"img":false}]}
{"op":"mcm","clk":"5348053976","pt":1646213174358,"mc":[{"id":"1.195453721","rc":[{"atl":[[210,0]],"id":41419597},{"atl":[[470,0]],"id":41419608},{"atl":[[160,0]],"id":41419585}],"con":true,"img":false}]}
{"op":"mcm","clk":"5348053981","pt":1646213174460,"mc":[{"id":"1.195453721","rc":[{"atl":[[290,0.55],[160,11.11]],"id":41419585}],"con":true,"img":false}]}
{"op":"mcm","clk":"5348053999","pt":1646213174766,"mc":[{"id":"1.195453721","rc":[{"atb":[[32,4.95]],"id":41419593},{"atl":[[290,0]],"id":41419585}],"con":true,"img":false}]}
{"op":"mcm","clk":"5348054016","pt":1646213175074,"mc":[{"id":"1.195453721","rc":[{"atb":[[46,8.47]],"id":41419587}],"con":true,"img":false}]}
{"op":"mcm","clk":"5348054049","pt":1646213175442,"mc":[{"id":"1.195453721","rc":[{"atl":[[110,0.74]],"id":41419593},{"atl":[[46,1.42]],"id":41419591},{"atl":[[260,0.31]],"id":41419587},{"atl":[[200,0.4]],"id":41419597},{"atl":[[440,0.18]],"id":41419608},{"atl":[[170,0.47]],"id":41419612},{"atl":[[200,0.4]],"id":41419592}],"con":true,"img":false}]}
{"op":"mcm","clk":"5348054072","pt":1646213175957,"mc":[{"id":"1.195453721","rc":[{"atl":[[46,15.13],[48,9.9]],"id":41419591}],"con":true,"img":false}]}
{"op":"mcm","clk":"5348054080","pt":1646213176059,"mc":[{"id":"1.195453721","rc":[{"atb":[[8.6,19.66],[8.2,2.72]],"id":41419640},{"atl":[[16.5,9.9],[14.5,19.66]],"id":41419640},{"atb":[[11.5,10.03],[8.8,9.9]],"id":41419605},{"atb":[[7.4,51.48],[7,3.26]],"id":41419636},{"atb":[[18.5,9.9],[19.5,16.56]],"id":41419591},{"atl":[[80,15.73],[85,2.04]],"id":41419601},{"atb":[[26,8.22],[27,14.57]],"id":41419630},{"atb":[[23,0],[24,33.87]],"id":41419628},{"atb":[[18,9.9],[20,19.66]],"id":41419604},{"atl":[[170,10.97],[200,0.4]],"id":41419612},{"atl":[[100,19.47],[110,0.74]],"id":41419590},{"atb":[[8.6,12.63],[11.5,25.41]],"id":41419633},{"atb":[[23,9.9],[25,14.72]],"id":41419598},{"atb":[[18.5,3.26],[20,15.68]],"id":41419627}],"con":true,"img":false}]}
{"op":"mcm","clk":"5348054089","pt":1646213176165,"mc":[{"id":"1.195453721","rc":[{"atl":[[27,19.73],[28,2.84]],"id":41419637},{"atb":[[13,13.21]],"id":41419633},{"atl":[[17.5,4.74]],"id":41419633}],"con":true,"img":false}]}
{"op":"mcm","clk":"5348054103","pt":1646213176364,"mc":[{"id":"1.195453721","rc":[{"atb":[[9.8,0]],"id":41419640},{"atb":[[8.8,0]],"id":41419636},{"atl":[[17.5,5.93]],"id":41419633},{"atl":[[32,5.11]],"id":41419629}],"con":true,"img":false}]}
{"op":"mcm","clk":"5348054118","pt":1646213176678,"mc":[{"id":"1.195453721","rc":[{"atb":[[9.8,18.01]],"id":41419640},{"atb":[[44,2.72]],"id":41419585},{"atl":[[80,4.95]],"id":41419585},{"atl":[[21,4.95],[25,9.9]],"id":41419633}],"con":true,"img":false}]}
{"op":"mcm","clk":"5348054122","pt":1646213176735,"mc":[{"id":"1.195453721","rc":[{"atl":[[20,8.34]],"id":41419633}],"con":true,"img":false}]}
{"op":"mcm","clk":"5348054131","pt":1646213176942,"mc":[{"id":"1.195453721","rc":[{"atb":[[7,0]],"id":41419636},{"atb":[[38,0],[48,15.22]],"id":41419611},{"atb":[[40,0],[50,0]],"id":41419587},{"atb":[[65,2.47],[46,8.9]],"id":41419606},{"atb":[[38,0]],"id":41419592},{"atb":[[23,0],[28,13.7]],"id":41419590},{"atb":[[23,0],[28,15.48]],"id":41419586},{"atb":[[12,0]],"id":41419633},{"atl":[[20,0]],"id":41419633},{"atb":[[21,0],[26,0]],"id":41419600}],"con":true,"img":false}]}
{"op":"mcm","clk":"5348054134","pt":1646213177046,"mc":[{"id":"1.195453721","rc":[{"atb":[[8,0]],"id":41419636},{"atb":[[48,0]],"id":41419592}],"con":true,"img":false}]}
{"op":"mcm","clk":"5348054138","pt":1646213177145,"mc":[{"id":"1.195453721","rc":[{"atb":[[38,4.28],[29,0]],"id":41419593}],"con":true,"img":false}]}
{"op":"mcm","clk":"5348054144","pt":1646213177354,"mc":[{"id":"1.195453721","rc":[{"atb":[[8.8,0]],"id":41419640},{"atb":[[32,3.23],[27,5.12]],"id":41419606},{"atb":[[34,13.03]],"id":41419585}],"con":true,"img":false}]}
{"op":"mcm","clk":"5348054149","pt":1646213177457,"mc":[{"id":"1.195453721","rc":[{"atb":[[9.8,19.43]],"id":41419640},{"atb":[[8.6,1.42]],"id":41419636},{"atb":[[42,21.36],[44,0]],"id":41419587},{"atl":[[300,0.31]],"id":41419587},{"atl":[[210,0.38]],"id":41419597},{"atb":[[23,1.42]],"id":41419628},{"atl":[[460,0.17]],"id":41419608},{"atb":[[34,12.82],[36,4.95]],"id":41419592},{"atl":[[19.5,1.42]],"id":41419633},{"atb":[[22,15.95],[23,12.15],[24,8.31]],"id":41419600},{"atb":[[18.5,1.42]],"id":41419629},{"atb":[[19.5,1.42]],"id":41419627}],"con":true,"img":false}]}
{"op":"mcm","clk":"5348054158","pt":1646213177665,"mc":[{"id":"1.195453721","rc":[{"atb":[[7.2,3.26]],"id":41419636},{"atb":[[50,12.63]],"id":41419611},{"atb":[[42,24.63],[55,2.72]],"id":41419587},{"atb":[[70,2.72],[48,3.26]],"id":41419606},{"atb":[[36,9.48],[42,3.26]],"id":41419592},{"atb":[[25,13.17],[30,8.19]],"id":41419586},{"atb":[[23,15.42],[28,2.72]],"id":41419600},{"atb":[[16.5,2.72],[17,17.79]],"id":41419629}],"con":true,"img":false}]}
{"op":"mcm","clk":"5348054167","pt":1646213177876,"mc":[{"id":"1.195453721","rc":[{"atb":[[8.2,2.72]],"id":41419636},{"atb":[[55,2.72]],"id":41419592},{"atb":[[24,3.26],[29,11.23]],"id":41419590}],"con":true,"img":false}]}
{"op":"mcm","clk":"5348054171","pt":1646213177970,"mc":[{"id":"1.195453721","rc":[{"atb":[[40,2.72],[30,30.19]],"id":41419593},{"atl":[[85,6.83]],"id":41419592},{"atb":[[19,8.8]],"id":41419629}],"con":true,"img":false}]}
{"op":"mcm","clk":"5348054174","pt":1646213178073,"mc":[{"id":"1.195453721","rc":[{"atb":[[70,5.02],[46,0]],"id":41419606}],"con":true,"img":false}]}
{"op":"mcm","clk":"5348054178","pt":1646213178178,"mc":[{"id":"1.195453721","rc":[{"atb":[[55,19.66]],"id":41419606},{"atb":[[23,8.22]],"id":41419600}],"con":true,"img":false}]}
{"op":"mcm","clk":"5348054182","pt":1646213178239,"mc":[{"id":"1.195453721","rc":[{"atl":[[38,9.23]],"id":41419627}],"con":true,"img":false}]}
{"op":"mcm","clk":"5348054193","pt":1646213178547,"mc":[{"id":"1.195453721","rc":[{"atl":[[70,4.95]],"id":41419593},{"atl":[[200,0]],"id":41419597},{"atl":[[440,0]],"id":41419608},{"atl":[[170,10.49]],"id":41419612}],"con":true,"img":false}]}
{"op":"mcm","clk":"5348054204","pt":1646213178783,"mc":[{"id":"1.195453721","rc":[{"atb":[[65,0]],"id":41419606},{"atl":[[85,4.95],[100,0]],"id":41419592},{"atb":[[18,0]],"id":41419629}],"con":true,"img":false}]}
{"op":"mcm","clk":"5348054219","pt":1646213179058,"mc":[{"id":"1.195453721","rc":[{"atl":[[44,0]],"id":41419627}],"con":true,"img":false}]}
{"op":"mcm","clk":"5348054240","pt":1646213179471,"mc":[{"id":"1.195453721","rc":[{"atl":[[200,9.36],[110,9.9]],"id":41419592}],"con":true,"img":false}]}
{"op":"mcm","clk":"5348054245","pt":1646213179573,"mc":[{"id":"1.195453721","rc":[{"atl":[[46,12.75],[48,30.42]],"id":41419627}],"con":true,"img":false}]}
{"op":"mcm","clk":"5348054250","pt":1646213179780,"mc":[{"id":"1.195453721","rc":[{"atl":[[180,0],[400,6.47]],"id":41419607},{"atl":[[17,4.95],[18.5,9.05],[19,9.9],[21,0]],"id":41419635}],"con":true,"img":false}]}
{"op":"mcm","clk":"5348054259","pt":1646213179942,"mc":[{"id":"1.195453721","rc":[{"atb":[[9.6,1.42]],"id":41419640},{"atb":[[29,1.42]],"id":41419593},{"atb":[[40,1.42]],"id":41419587},{"atl":[[240,0.38]],"id":41419597},{"atl":[[470,0.17]],"id":41419608},{"atb":[[12,1.42]],"id":41419633},{"atl":[[20,1.42]],"id":41419633},{"atb":[[18,1.42]],"id":41419629}],"con":true,"img":false}]}
{"op":"mcm","clk":"5348054263","pt":1646213180046,"mc":[{"id":"1.195453721","rc":[{"atl":[[150,11.96],[310,2]],"id":41419606}],"con":true,"img":false}]}
{"op":"mcm","clk":"5348054272","pt":1646213180251,"mc":[{"id":"1.195453721","rc":[{"atl":[[16.5,10.22],[19,30.73],[22,1.42]],"id":41419635}],"con":true,"img":false}]}
{"op":"mcm","clk":"5348054275","pt":1646213180351,"mc":[{"id":"1.195453721","rc":[{"atl":[[42,2.44]],"id":41419633}],"con":true,"img":false}]}
{"op":"mcm","clk":"5348054280","pt":1646213180561,"mc":[{"id":"1.195453721","rc":[{"atl":[[400,2]],"id":41419607},{"atl":[[16.5,0],[14.5,0],[15,4.95]],"id":41419634},{"atb":[[70,0],[50,2.72],[55,4.95]],"id":41419611},{"atl":[[36,0],[38,4.95],[44,0],[46,29.46]],"id":41419599},{"atb":[[34,0],[36,6.37],[38,2.72],[42,0],[44,0]],"id":41419612}],"con":true,"img":false}]}
{"op":"mcm","clk":"5348054289","pt":1646213180770,"mc":[{"id":"1.195453721","rc":[{"atb":[[32,3.23],[28,0]],"id":41419611}],"con":true,"img":false}]}
{"op":"mcm","clk":"5348054291","pt":1646213180869,"mc":[{"id":"1.195453721","rc":[{"atl":[[150,0]],"id":41419606}],"con":true,"img":false}]}
{"op":"mcm","clk":"5348054304","pt":1646213181074,"mc":[{"id":"1.195453721","rc":[{"atl":[[46,11.33],[48,14.42]],"id":41419599},{"atl":[[18.5,0]],"id":41419635},{"atb":[[32,22.49]],"id":41419612}],"con":true,"img":false}]}
{"op":"mcm","clk":"5348054311","pt":1646213181181,"mc":[{"id":"1.195453721","rc":[{"atl":[[110,0]],"id":41419593},{"atl":[[260,0],[270,0],[280,2]],"id":41419587},{"atl":[[200,8.95],[210,0],[220,0],[230,0]],"id":41419592}],"con":true,"img":false}]}
{"op":"mcm","clk":"5348054319","pt":1646213181285,"mc":[{"id":"1.195453721","rc":[{"atl":[[15,11.1]],"id":41419634},{"atb":[[50,5.96]],"id":41419611},{"atl":[[36,4.95],[38,0],[44,13.59],[46,1.42]],"id":41419599},{"atb":[[36,1.42]],"id":41419612}],"con":true,"img":false}]}
{"op":"mcm","clk":"5348054326","pt":1646213181344,"mc":[{"id":"1.195453721","rc":[{"atl":[[11,4.95],[11.5,15.1],[13,11.33],[13.5,0]],"id":41419636},{"atl":[[16.5,0]],"id":41419635},{"atb":[[32,32.39],[36,5.95],[40,4.95]],"id":41419612}],"con":true,"img":false}]}
{"op":"mcm","clk":"5348054336","pt":1646213181552,"mc":[{"id":"1.195453721","rc":[{"atl":[[17.5,3.32]],"id":41419633}],"con":true,"img":false}]}
{"op":"mcm","clk":"5348054341","pt":1646213181656,"mc":[{"id":"1.195453721","rc":[{"atl":[[19,2]],"id":41419633}],"con":true,"img":false}]}
{"op":"mcm","clk":"5348054347","pt":1646213181759,"mc":[{"id":"1.195453721","rc":[{"atl":[[11,16.35],[12,12.82],[12.5,2.84]],"id":41419636}],"con":true,"img":false}]}
{"op":"mcm","clk":"5348054359","pt":1646213182071,"mc":[{"id":"1.195453721","rc":[{"atl":[[19,39.53]],"id":41419635}],"con":true,"img":false}]}
{"op":"mcm","clk":"5348054367","pt":1646213182275,"mc":[{"id":"1.195453721","rc":[{"atb":[[10,1.42]],"id":41419640},{"atl":[[16.5,1.42]],"id":41419634},{"atb":[[40,1.42]],"id":41419611},{"atb":[[44,1.42]],"id":41419587},{"atl":[[310,0.27]],"id":41419587},{"atl":[[200,0.4]],"id":41419597},{"atl":[[420,0.19]],"id":41419608},{"atb":[[50,1.42]],"id":41419606},{"atl":[[21,1.42]],"id":41419635},{"atb":[[34,1.42]],"id":41419612},{"atl":[[150,0.54]],"id":41419612},{"atb":[[38,1.42]],"id":41419592},{"atl":[[270,0.33]],"id":41419592},{"atl":[[75,1.42]],"id":41419600},{"atb":[[16,0],[18,0]],"id":41419627}],"con":true,"img":false}]}
{"op":"mcm","clk":"5348054371","pt":1646213182377,"mc":[{"id":"1.195453721","rc":[{"atl":[[11,11.4],[11.5,20.05],[13,1.42]],"id":41419636}],"con":true,"img":false}]}
{"op":"mcm","clk":"5348054384","pt":1646213182642,"mc":[{"id":"1.195453721","rc":[{"atl":[[11,0],[11.5,4.95]],"id":41419636}],"con":true,"img":false}]}
{"op":"mcm","clk":"5348054390","pt":1646213182751,"mc":[{"id":"1.195453721","rc":[{"atb":[[9.6,22.37],[8.6,4.95]],"id":41419640}],"con":true,"img":false}]}
{"op":"mcm","clk":"5348054407","pt":1646213182961,"mc":[{"id":"1.195453721","rc":[{"atl":[[290,0]],"id":41419587}],"con":true,"img":false}]}
{"op":"mcm","clk":"5348054422","pt":1646213183372,"mc":[{"id":"1.195453721","rc":[{"atl":[[12,24.22]],"id":41419636},{"atl":[[17.5,4.95],[19.5,9.9]],"id":41419635}],"con":true,"img":false}]}
{"op":"mcm","clk":"5348054425","pt":1646213183470,"mc":[{"id":"1.195453721","rc":[{"atb":[[10,2.84]],"id":41419640},{"atl":[[16.5,2.84]],"id":41419634},{"atb":[[40,2.84]],"id":41419611},{"atb":[[44,2.84]],"id":41419587},{"atl":[[310,0.54]],"id":41419587},{"atl":[[200,0.81]],"id":41419597},{"atl":[[420,0.39]],"id":41419608},{"atb":[[50,2.84]],"id":41419606},{"atb":[[11.5,1.42]],"id":41419635},{"atl":[[17,0],[19,29.63],[19.5,11.33]],"id":41419635},{"atb":[[34,2.84]],"id":41419612},{"atl":[[150,1.08]],"id":41419612},{"atb":[[38,2.84]],"id":41419592},{"atl":[[270,0.67]],"id":41419592},{"atl":[[75,2.84]],"id":41419600}],"con":true,"img":false}]}
{"op":"mcm","clk":"5348054438","pt":1646213183676,"mc":[{"id":"1.195453721","rc":[{"atl":[[22,12.5]],"id":41419637}],"con":true,"img":false}]}
{"op":"mcm","clk":"5348054451","pt":1646213183981,"mc":[{"id":"1.195453721","rc":[{"atb":[[50,17.76]],"id":41419606},{"atb":[[11,15.48]],"id":41419635}],"con":true,"img":false}]}
{"op":"mcm","clk":"5348054454","pt":1646213184085,"mc":[{"id":"1.195453721","rc":[{"atb":[[55,4.95]],"id":41419606},{"atb":[[10.5,21.64]],"id":41419635}],"con":true,"img":false}]}
{"op":"mcm","clk":"5348054491","pt":1646213184657,"mc":[{"id":"1.195453721","rc":[{"atl":[[27,13.64]],"id":41419637}],"con":true,"img":false}]}
{"op":"mcm","clk":"5348054519","pt":1646213185175,"mc":[{"id":"1.195453721","rc":[{"atb":[[10,1.42]],"id":41419640}],"con":true,"img":false}]}
{"op":"mcm","clk":"5348054526","pt":1646213185289,"mc":[{"id":"1.195453721","rc":[{"atb":[[55,5.66]],"id":41419587}],"con":true,"img":false}]}
{"op":"mcm","clk":"5348054536","pt":1646213185488,"mc":[{"id":"1.195453721","rc":[{"atb":[[21,12.88]],"id":41419591},{"atl":[[55,7.89]],"id":41419601},{"atl":[[30,10.42]],"id":41419629}],"con":true,"img":false}]}
{"op":"mcm","clk":"5348054542","pt":1646213185585,"mc":[{"id":"1.195453721","rc":[{"atb":[[32,5.11]],"id":41419590}],"con":true,"img":false}]}
{"op":"mcm","clk":"5348054551","pt":1646213185747,"mc":[{"id":"1.195453721","rc":[{"atl":[[290,0.28]],"id":41419587},{"atl":[[190,0.43]],"id":41419597},{"atl":[[400,0.2]],"id":41419608},{"atb":[[46,1.42]],"id":41419606},{"atb":[[11.5,2.84]],"id":41419635},{"atl":[[19.5,12.75]],"id":41419635},{"atl":[[150,0.54]],"id":41419585},{"atb":[[30,1.42]],"id":41419612},{"atl":[[140,0.58]],"id":41419612},{"atl":[[280,0.33]],"id":41419592}],"con":true,"img":false}]}
{"op":"mcm","clk":"5348054555","pt":1646213185855,"mc":[{"id":"1.195453721","rc":[{"atl":[[180,8.08]],"id":41419607},{"atb":[[32,19.66],[30,4.69]],"id":41419593},{"atl":[[150,12.07]],"id":41419606}],"con":true,"img":false}]}
{"op":"mcm","clk":"5348054562","pt":1646213186058,"mc":[{"id":"1.195453721","rc":[{"atb":[[46,4.95]],"id":41419587},{"atl":[[19,8.8],[19.5,36.95]],"id":41419635}],"con":true,"img":false}]}
{"op":"mcm","clk":"5348054568","pt":1646213186160,"mc":[{"id":"1.195453721","rc":[{"atb":[[20,1.42]],"id":41419591},{"atl":[[75,9.9]],"id":41419601},{"atb":[[28,0],[29,36.51]],"id":41419590},{"atl":[[42,0]],"id":41419600},{"atl":[[32,0]],"id":41419629}],"con":true,"img":false}]}
{"op":"mcm","clk":"5348054572","pt":1646213186264,"mc":[{"id":"1.195453721","rc":[{"atb":[[34,9.76],[44,0]],"id":41419585},{"atl":[[150,12.63],[160,0]],"id":41419585},{"atb":[[29,30.85]],"id":41419590}],"con":true,"img":false}]}
{"op":"mcm","clk":"5348054576","pt":1646213186365,"mc":[{"id":"1.195453721","rc":[{"atb":[[18.5,0],[22,7.54]],"id":41419627}],"con":true,"img":false}]}
{"op":"mcm","clk":"5348054582","pt":1646213186572,"mc":[{"id":"1.195453721","rc":[{"atl":[[55,9.9],[60,20.99]],"id":41419600},{"atl":[[36,16.62]],"id":41419629}],"con":true,"img":false}]}
{"op":"mcm","clk":"5348054587","pt":1646213186676,"mc":[{"id":"1.195453721","rc":[{"atl":[[34,2.84]],"id":41419629}],"con":true,"img":false}]}
{"op":"mcm","clk":"5348054592","pt":1646213186777,"mc":[{"id":"1.195453721","rc":[{"atb":[[32,1.42],[30,32.08]],"id":41419585}],"con":true,"img":false}]}
{"op":"mcm","clk":"5348054604","pt":1646213186981,"mc":[{"id":"1.195453721","rc":[{"atb":[[10,0]],"id":41419640},{"atb":[[50,14.92]],"id":41419606},{"atl":[[50,3.23]],"id":41419600}],"con":true,"img":false}]}
{"op":"mcm","clk":"5348054613","pt":1646213187083,"mc":[{"id":"1.195453721","rc":[{"atb":[[36,3.26],[46,2.72]],"id":41419585},{"atl":[[20,6.37],[21,0],[25,0]],"id":41419633},{"atb":[[19,3.26],[23,2.72]],"id":41419627}],"con":true,"img":false}]}
{"op":"mcm","clk":"5348054627","pt":1646213187290,"mc":[{"id":"1.195453721","rc":[{"atl":[[80,6.95]],"id":41419585}],"con":true,"img":false}]}
{"op":"mcm","clk":"5348054638","pt":1646213187451,"mc":[{"id":"1.195453721","rc":[{"atl":[[12,12.82],[12.5,14.42]],"id":41419636}],"con":true,"img":false}]}
{"op":"mcm","clk":"5348054668","pt":1646213187966,"mc":[{"id":"1.195453721","rc":[{"atl":[[80,4.95]],"id":41419585},{"atl":[[140,13.56]],"id":41419612},{"atb":[[12,8.61]],"id":41419633},{"atb":[[20,2.84],[21,26.37]],"id":41419627}],"con":true,"img":false}]}
{"op":"mcm","clk":"5348054675","pt":1646213188070,"mc":[{"id":"1.195453721","rc":[{"atl":[[170,0]],"id":41419612},{"atb":[[11.5,1.42]],"id":41419633}],"con":true,"img":false}]}
{"op":"mcm","clk":"5348054680","pt":1646213188173,"mc":[{"id":"1.195453721","rc":[{"atb":[[10,1.42]],"id":41419640},{"atl":[[390,0.2]],"id":41419608},{"atl":[[20,1.42]],"id":41419635},{"atb":[[29,1.42]],"id":41419585},{"atl":[[110,0.74]],"id":41419585},{"atl":[[160,0.58]],"id":41419612},{"atl":[[230,0.35]],"id":41419592},{"atb":[[28,1.42]],"id":41419590},{"atb":[[25,1.42]],"id":41419600},{"atl":[[70,1.36]],"id":41419598},{"atl":[[40,1.42]],"id":41419629}],"con":true,"img":false}]}
{"op":"mcm","clk":"5348054697","pt":1646213188587,"mc":[{"id":"1.195453721","rc":[{"atb":[[9.6,1.42],[8.6,52.69]],"id":41419640},{"atb":[[44,0]],"id":41419587}],"con":true,"img":false}]}
{"op":"mcm","clk":"5348054742","pt":1646213189470,"mc":[{"id":"1.195453721","rc":[{"atb":[[9.4,1.42]],"id":41419640},{"atl":[[410,0.2]],"id":41419608},{"atl":[[120,0.74]],"id":41419585},{"atl":[[170,0.58]],"id":41419612}],"con":true,"img":false}]}
{"op":"mcm","clk":"5348054773","pt":1646213190132,"mc":[{"id":"1.195453721","marketDefinition":{"bspMarket":false,"turnInPlayEnabled":false,"persistenceEnabled":false,"marketBaseRate":7.0,"eventId":"31272494","eventTypeId":"4339","numberOfWinners":1,"bettingType":"ODDS","marketType":"EXACTA","marketTime":"2022-03-02T09:33:00.000Z","suspendTime":"2022-03-02T09:33:00.000Z","bspReconciled":false,"complete":true,"inPlay":false,"crossMatching":true,"runnersVoidable":false,"numberOfActiveRunners":30,"betDelay":0,"status":"OPEN","runners":[{"status":"ACTIVE","sortPriority":1,"id":41419585,"name":"1 - 2"},{"status":"ACTIVE","sortPriority":2,"id":41419586,"name":"1 - 3"},{"status":"ACTIVE","sortPriority":3,"id":41419587,"name":"1 - 4"},{"status":"ACTIVE","sortPriority":4,"id":41419590,"name":"1 - 7"},{"status":"ACTIVE","sortPriority":5,"id":41419591,"name":"1 - 8"},{"status":"ACTIVE","sortPriority":6,"id":41419592,"name":"2 - 1"},{"status":"ACTIVE","sortPriority":7,"id":41419593,"name":"2 - 3"},{"status":"ACTIVE","sortPriority":8,"id":41419594,"name":"2 - 4"},{"status":"ACTIVE","sortPriority":9,"id":41419597,"name":"2 - 7"},{"status":"ACTIVE","sortPriority":10,"id":41419598,"name":"2 - 8"},{"status":"ACTIVE","sortPriority":11,"id":41419599,"name":"3 - 1"},{"status":"ACTIVE","sortPriority":12,"id":41419600,"name":"3 - 2"},{"status":"ACTIVE","sortPriority":13,"id":41419601,"name":"3 - 4"},{"status":"ACTIVE","sortPriority":14,"id":41419604,"name":"3 - 7"},{"status":"ACTIVE","sortPriority":15,"id":41419605,"name":"3 - 8"},{"status":"ACTIVE","sortPriority":16,"id":41419606,"name":"4 - 1"},{"status":"ACTIVE","sortPriority":17,"id":41419607,"name":"4 - 2"},{"status":"ACTIVE","sortPriority":18,"id":41419608,"name":"4 - 3"},{"status":"ACTIVE","sortPriority":19,"id":41419611,"name":"4 - 7"},{"status":"ACTIVE","sortPriority":20,"id":41419612,"name":"4 - 8"},{"status":"ACTIVE","sortPriority":21,"id":41419627,"name":"7 - 1"},{"status":"ACTIVE","sortPriority":22,"id":41419628,"name":"7 - 2"},{"status":"ACTIVE","sortPriority":23,"id":41419629,"name":"7 - 3"},{"status":"ACTIVE","sortPriority":24,"id":41419630,"name":"7 - 4"},{"status":"ACTIVE","sortPriority":25,"id":41419633,"name":"7 - 8"},{"status":"ACTIVE","sortPriority":26,"id":41419634,"name":"8 - 1"},{"status":"ACTIVE","sortPriority":27,"id":41419635,"name":"8 - 2"},{"status":"ACTIVE","sortPriority":28,"id":41419636,"name":"8 - 3"},{"status":"ACTIVE","sortPriority":29,"id":41419637,"name":"8 - 4"},{"status":"ACTIVE","sortPriority":30,"id":41419640,"name":"8 - 7"}],"regulators":["MR_INT"],"venue":"Traralgon","countryCode":"AU","discountAllowed":true,"timezone":"Australia/Sydney","openDate":"2022-03-02T08:31:00.000Z","version":4382480607,"name":"Exacta","eventName":"Traralgon (AUS) 2nd Mar"},"rc":[],"con":true,"img":false}]}
{"op":"mcm","clk":"5348054786","pt":1646213190394,"mc":[{"id":"1.195453721","rc":[{"atb":[[10,0]],"id":41419640},{"atl":[[150,12.08],[110,0]],"id":41419585},{"atl":[[19.5,0],[20,4.95]],"id":41419633}],"con":true,"img":false}]}
{"op":"mcm","clk":"5348054793","pt":1646213190600,"mc":[{"id":"1.195453721","rc":[{"atl":[[110,0.74]],"id":41419593},{"atl":[[370,0.22]],"id":41419608},{"atl":[[160,0.51]],"id":41419585},{"atl":[[170,1.16]],"id":41419612}],"con":true,"img":false}]}
{"op":"mcm","clk":"5348054847","pt":1646213191695,"mc":[{"id":"1.195453721","rc":[{"atl":[[120,0]],"id":41419585}],"con":true,"img":false}]}
{"op":"mcm","clk":"5348054917","pt":1646213192574,"mc":[{"id":"1.195453721","rc":[{"atl":[[110,1.48]],"id":41419593},{"atl":[[180,0.45]],"id":41419597},{"atl":[[160,1.02]],"id":41419585}],"con":true,"img":false}]}
{"op":"mcm","clk":"5348055011","pt":1646213193969,"mc":[{"id":"1.195453721","rc":[{"atb":[[10,1.42]],"id":41419640},{"atl":[[270,0.3]],"id":41419587}],"con":true,"img":false}]}
{"op":"mcm","clk":"5348055063","pt":1646213195261,"mc":[{"id":"1.195453721","rc":[{"atb":[[60,1.36]],"id":41419607},{"atl":[[360,0.22]],"id":41419608},{"atl":[[220,0.37]],"id":41419592}],"con":true,"img":false}]}
{"op":"mcm","clk":"5348055079","pt":1646213195573,"mc":[{"id":"1.195453721","rc":[{"atb":[[10,0]],"id":41419640}],"con":true,"img":false}]}
{"op":"mcm","clk":"5348055132","pt":1646213196499,"mc":[{"id":"1.195453721","rc":[{"atb":[[60,2.72]],"id":41419607},{"atl":[[360,0.45]],"id":41419608},{"atl":[[220,0.74]],"id":41419592}],"con":true,"img":false}]}
{"op":"mcm","clk":"5348055269","pt":1646213198775,"mc":[{"id":"1.195453721","rc":[{"atb":[[10,1.42]],"id":41419640},{"atl":[[350,0.23]],"id":41419608},{"atb":[[55,1.42]],"id":41419594}],"con":true,"img":false}]}
