{"op":"mcm","clk":"5317728436","pt":1646251399785,"mc":[{"id":"1.195532855","marketDefinition":{"bspMarket":true,"turnInPlayEnabled":false,"persistenceEnabled":false,"marketBaseRate":5.0,"eventId":"31275720","eventTypeId":"4339","numberOfWinners":2,"bettingType":"ODDS","marketType":"PLACE","marketTime":"2022-03-03T14:12:00.000Z","suspendTime":"2022-03-03T14:12:00.000Z","bspReconciled":false,"complete":true,"inPlay":false,"crossMatching":false,"runnersVoidable":false,"numberOfActiveRunners":6,"betDelay":0,"status":"OPEN","runners":[{"status":"ACTIVE","sortPriority":1,"id":36042605,"name":"1. Droopys Icing"},{"status":"ACTIVE","sortPriority":2,"id":42190933,"name":"2. Patagonia"},{"status":"ACTIVE","sortPriority":3,"id":42609833,"name":"3. Tip Top Saka"},{"status":"ACTIVE","sortPriority":4,"id":41064149,"name":"4. Bang On Esmae"},{"status":"ACTIVE","sortPriority":5,"id":38833999,"name":"5. Adorable Emma"},{"status":"ACTIVE","sortPriority":6,"id":28603686,"name":"6. Trapstyle Flash"}],"regulators":["MR_INT"],"venue":"Romford","countryCode":"GB","discountAllowed":false,"timezone":"Europe/London","openDate":"2022-03-03T13:57:00.000Z","version":4384107288,"name":"To Be Placed","eventName":"Romford 3rd Mar"},"rc":[],"con":true,"img":false}]}
{"op":"mcm","clk":"5317728693","pt":1646251400815,"mc":[{"id":"1.195532855","marketDefinition":{"bspMarket":true,"turnInPlayEnabled":false,"persistenceEnabled":false,"marketBaseRate":5.0,"eventId":"31275720","eventTypeId":"4339","numberOfWinners":2,"bettingType":"ODDS","marketType":"PLACE","marketTime":"2022-03-03T14:12:00.000Z","suspendTime":"2022-03-03T14:12:00.000Z","bspReconciled":false,"complete":true,"inPlay":false,"crossMatching":false,"runnersVoidable":false,"numberOfActiveRunners":6,"betDelay":0,"status":"OPEN","runners":[{"status":"ACTIVE","sortPriority":1,"id":36042605,"name":"1. Droopys Icing"},{"status":"ACTIVE","sortPriority":2,"id":42190933,"name":"2. Patagonia"},{"status":"ACTIVE","sortPriority":3,"id":42609833,"name":"3. Tip Top Saka"},{"status":"ACTIVE","sortPriority":4,"id":41064149,"name":"4. Bang On Esmae"},{"status":"ACTIVE","sortPriority":5,"id":38833999,"name":"5. Adorable Emma"},{"status":"ACTIVE","sortPriority":6,"id":28603686,"name":"6. Trapstyle Flash"}],"regulators":["MR_INT"],"venue":"Romford","countryCode":"GB","discountAllowed":true,"timezone":"Europe/London","openDate":"2022-03-03T13:57:00.000Z","version":4384107288,"name":"To Be Placed","eventName":"Romford 3rd Mar"},"rc":[],"con":true,"img":false}]}
{"op":"mcm","clk":"5320821000","pt":1646302486808,"mc":[{"id":"1.195532855","rc":[{"atb":[[1.01,102.04]],"id":28603686},{"spn":"Infinity","spf":"NaN","id":28603686},{"atb":[[1.01,102.04]],"id":38833999},{"spn":"Infinity","spf":"NaN","id":38833999},{"atb":[[1.01,102.04]],"id":42609833},{"spn":"Infinity","spf":"NaN","id":42609833},{"atb":[[1.01,102.04]],"id":42190933},{"spn":"Infinity","spf":"NaN","id":42190933},{"atb":[[1.01,102.04]],"id":41064149},{"spn":"Infinity","spf":"NaN","id":41064149},{"atb":[[1.01,102.04]],"id":36042605},{"spn":"Infinity","spf":"NaN","id":36042605}],"con":true,"img":false}]}
{"op":"mcm","clk":"5320906665","pt":1646303731663,"mc":[{"id":"1.195532855","rc":[{"atl":[[1000,5]],"id":28603686},{"spn":500.5,"spf":"NaN","id":28603686},{"atl":[[1000,5]],"id":38833999},{"spn":500.5,"spf":"NaN","id":38833999},{"atl":[[1000,5]],"id":42609833},{"spn":500.5,"spf":"NaN","id":42609833},{"atl":[[1000,5]],"id":42190933},{"spn":500.5,"spf":"NaN","id":42190933},{"atl":[[1000,5]],"id":41064149},{"spn":500.5,"spf":"NaN","id":41064149},{"atl":[[1000,5]],"id":36042605},{"spn":500.5,"spf":"NaN","id":36042605}],"con":true,"img":false}]}
{"op":"mcm","clk":"5320906699","pt":1646303732072,"mc":[{"id":"1.195532855","rc":[{"atb":[[1.01,4802.04]],"id":28603686},{"atb":[[1.01,4802.04]],"id":38833999},{"atb":[[1.01,4802.04]],"id":42609833},{"atb":[[1.01,4802.04]],"id":42190933},{"atb":[[1.01,4802.04]],"id":41064149},{"atb":[[1.01,4802.04]],"id":36042605}],"con":true,"img":false}]}
{"op":"mcm","clk":"5321888681","pt":1646314187865,"mc":[{"id":"1.195532855","rc":[{"spl":[[1.01,1]],"id":28603686},{"spn":1.01,"spf":1.0,"id":28603686},{"spl":[[1.01,1]],"id":41064149},{"spn":1.01,"spf":1.0,"id":41064149}],"con":true,"img":false}]}
{"op":"mcm","clk":"5321960912","pt":1646314921689,"mc":[{"id":"1.195532855","rc":[{"atb":[[1.01,5052.04]],"id":28603686},{"atb":[[1.01,5052.04]],"id":38833999},{"atb":[[1.01,5052.04]],"id":42609833},{"atb":[[1.01,5052.04]],"id":42190933},{"atb":[[1.01,5052.04]],"id":41064149},{"atb":[[1.01,5052.04]],"id":36042605}],"con":true,"img":false}]}
{"op":"mcm","clk":"5322047597","pt":1646315801221,"mc":[{"id":"1.195532855","rc":[{"atl":[[46,2.73]],"id":28603686},{"atl":[[46,2.73]],"id":38833999},{"spn":23.5,"spf":"NaN","id":38833999},{"atl":[[46,2.73]],"id":42609833},{"spn":23.5,"spf":"NaN","id":42609833},{"atl":[[46,2.73]],"id":42190933},{"spn":23.5,"spf":"NaN","id":42190933},{"atl":[[46,2.73]],"id":41064149},{"atl":[[46,2.73]],"id":36042605},{"spn":23.5,"spf":"NaN","id":36042605}],"con":true,"img":false}]}
{"op":"mcm","clk":"5322049514","pt":1646315822492,"mc":[{"id":"1.195532855","marketDefinition":{"bspMarket":true,"turnInPlayEnabled":false,"persistenceEnabled":false,"marketBaseRate":5.0,"eventId":"31275720","eventTypeId":"4339","numberOfWinners":2,"bettingType":"ODDS","marketType":"PLACE","marketTime":"2022-03-03T14:12:00.000Z","suspendTime":"2022-03-03T14:12:00.000Z","bspReconciled":false,"complete":true,"inPlay":false,"crossMatching":true,"runnersVoidable":false,"numberOfActiveRunners":6,"betDelay":0,"status":"OPEN","runners":[{"status":"ACTIVE","sortPriority":1,"id":36042605,"name":"1. Droopys Icing"},{"status":"ACTIVE","sortPriority":2,"id":42190933,"name":"2. Patagonia"},{"status":"ACTIVE","sortPriority":3,"id":42609833,"name":"3. Tip Top Saka"},{"status":"ACTIVE","sortPriority":4,"id":41064149,"name":"4. Bang On Esmae"},{"status":"ACTIVE","sortPriority":5,"id":38833999,"name":"5. Adorable Emma"},{"status":"ACTIVE","sortPriority":6,"id":28603686,"name":"6. Trapstyle Flash"}],"regulators":["MR_INT"],"venue":"Romford","countryCode":"GB","discountAllowed":true,"timezone":"Europe/London","openDate":"2022-03-03T13:57:00.000Z","version":4384107288,"name":"To Be Placed","eventName":"Romford 3rd Mar"},"rc":[],"con":true,"img":false}]}
{"op":"mcm","clk":"5322051187","pt":1646315840956,"mc":[{"id":"1.195532855","rc":[{"atb":[[1.7,142.86]],"id":28603686},{"atl":[[13.5,3.87]],"id":28603686},{"atb":[[1.66,151.52]],"id":38833999},{"atl":[[12,3.87]],"id":38833999},{"atb":[[1.73,136.99]],"id":42609833},{"atl":[[15,3.87]],"id":42609833},{"atb":[[1.68,147.06]],"id":42190933},{"atl":[[12.5,3.87]],"id":42190933},{"atb":[[1.03,3333.33]],"id":41064149},{"atl":[[4.9,3.87]],"id":41064149},{"atb":[[1.76,131.58]],"id":36042605},{"atl":[[16,3.87]],"id":36042605}],"con":true,"img":false}]}
{"op":"mcm","clk":"5322051368","pt":1646315843150,"mc":[{"id":"1.195532855","rc":[{"atb":[[1.68,58.82]],"id":28603686},{"atl":[[16.5,9.68],[17.5,15.15],[14.5,2.96],[15.5,6.9]],"id":28603686},{"atb":[[1.64,62.5]],"id":38833999},{"atl":[[16,16.67],[13,3.33],[14,7.69],[15,10.71]],"id":38833999},{"atb":[[1.71,56.34]],"id":42609833},{"atl":[[16,2.67],[17,6.25],[18,8.82],[19,13.89]],"id":42609833},{"atb":[[1.66,60.61]],"id":42190933},{"atl":[[16.5,16.13],[13.5,3.2],[14.5,7.41],[15.5,10.34]],"id":42190933},{"atl":[[5.1,9.76],[5.3,23.26],[5.5,33.33],[5.7,53.19]],"id":41064149},{"atb":[[1.74,54.05]],"id":36042605},{"atl":[[17,2.5],[18,5.88],[19,8.33],[20,13.16]],"id":36042605}],"con":true,"img":false}]}
{"op":"mcm","clk":"5322052160","pt":1646315853162,"mc":[{"id":"1.195532855","rc":[{"atb":[[1.66,151.52]],"id":28603686},{"atb":[[1.62,161.29]],"id":38833999},{"atb":[[1.69,144.93]],"id":42609833},{"atb":[[1.64,156.25]],"id":42190933},{"atb":[[1.72,138.89]],"id":36042605}],"con":true,"img":false}]}
{"op":"mcm","clk":"5322052238","pt":1646315853979,"mc":[{"id":"1.195532855","rc":[{"atb":[[1.73,2.15]],"id":28603686},{"atb":[[1.69,2.15]],"id":38833999},{"atb":[[1.76,2.15]],"id":42609833},{"atb":[[1.71,2.15]],"id":42190933},{"atb":[[1.79,2.15]],"id":36042605}],"con":true,"img":false}]}
{"op":"mcm","clk":"5322052258","pt":1646315854147,"mc":[{"id":"1.195532855","rc":[{"atb":[[1.73,60.97],[1.7,0]],"id":28603686},{"atb":[[1.66,0],[1.69,64.65]],"id":38833999},{"atb":[[1.73,0],[1.76,58.49]],"id":42609833},{"atb":[[1.68,0],[1.71,62.76]],"id":42190933},{"atb":[[1.79,56.2],[1.76,0]],"id":36042605}],"con":true,"img":false}]}
{"op":"mcm","clk":"5322052546","pt":1646315858042,"mc":[{"id":"1.195532855","rc":[{"atb":[[1.71,56.34]],"id":28603686},{"atb":[[1.67,59.7]],"id":38833999},{"atb":[[1.74,54.05]],"id":42609833},{"atb":[[1.69,57.97]],"id":42190933},{"atb":[[1.77,51.95]],"id":36042605}],"con":true,"img":false}]}
{"op":"mcm","clk":"5322053815","pt":1646315874867,"mc":[{"id":"1.195532855","rc":[{"spn":1.73,"spf":1.0,"id":28603686},{"spn":6.84,"spf":"NaN","id":38833999},{"spn":8.38,"spf":"NaN","id":42609833},{"spn":7.1,"spf":"NaN","id":42190933},{"spn":1.03,"spf":1.0,"id":41064149},{"atb":[[1.01,5054.04]],"id":36042605},{"spn":8.89,"spf":"NaN","id":36042605}],"con":true,"img":false}]}
{"op":"mcm","clk":"5322053830","pt":1646315875073,"mc":[{"id":"1.195532855","rc":[{"atb":[[1.01,5056.03]],"id":36042605}],"con":true,"img":false}]}
{"op":"mcm","clk":"5322053859","pt":1646315875389,"mc":[{"id":"1.195532855","rc":[{"atb":[[1.01,5054.04]],"id":36042605}],"con":true,"img":false}]}
{"op":"mcm","clk":"5322053869","pt":1646315875495,"mc":[{"id":"1.195532855","rc":[{"atb":[[1.8,1.99]],"id":36042605}],"con":true,"img":false}]}
{"op":"mcm","clk":"5322053887","pt":1646315875692,"mc":[{"id":"1.195532855","rc":[{"atb":[[1.01,5054.04]],"id":42190933}],"con":true,"img":false}]}
{"op":"mcm","clk":"5322053904","pt":1646315875907,"mc":[{"id":"1.195532855","rc":[{"atb":[[1.01,5056.03]],"id":42190933}],"con":true,"img":false}]}
{"op":"mcm","clk":"5322053922","pt":1646315876163,"mc":[{"id":"1.195532855","rc":[{"atb":[[1.01,5054.04]],"id":42190933}],"con":true,"img":false}]}
{"op":"mcm","clk":"5322053931","pt":1646315876266,"mc":[{"id":"1.195532855","rc":[{"atb":[[1.72,1.99]],"id":42190933}],"con":true,"img":false}]}
{"op":"mcm","clk":"5322053958","pt":1646315876575,"mc":[{"id":"1.195532855","rc":[{"atb":[[1.01,5054.04]],"id":42609833}],"con":true,"img":false}]}
{"op":"mcm","clk":"5322053970","pt":1646315876784,"mc":[{"id":"1.195532855","rc":[{"atb":[[1.01,5056.03]],"id":42609833}],"con":true,"img":false}]}
{"op":"mcm","clk":"5322053994","pt":1646315877094,"mc":[{"id":"1.195532855","rc":[{"atb":[[1.01,5054.04]],"id":42609833}],"con":true,"img":false}]}
{"op":"mcm","clk":"5322054003","pt":1646315877198,"mc":[{"id":"1.195532855","rc":[{"atb":[[1.77,1.99]],"id":42609833}],"con":true,"img":false}]}
{"op":"mcm","clk":"5322054029","pt":1646315877459,"mc":[{"id":"1.195532855","rc":[{"atb":[[1.01,5054.04]],"id":41064149}],"con":true,"img":false}]}
{"op":"mcm","clk":"5322054058","pt":1646315877783,"mc":[{"id":"1.195532855","rc":[{"atb":[[1.01,5056.03]],"id":41064149}],"con":true,"img":false}]}
{"op":"mcm","clk":"5322054086","pt":1646315878086,"mc":[{"id":"1.195532855","rc":[{"atb":[[1.01,5054.04]],"id":41064149}],"con":true,"img":false}]}
{"op":"mcm","clk":"5322054095","pt":1646315878203,"mc":[{"id":"1.195532855","rc":[{"atb":[[1.04,1.99]],"id":41064149}],"con":true,"img":false}]}
{"op":"mcm","clk":"5322054106","pt":1646315878401,"mc":[{"id":"1.195532855","rc":[{"atb":[[1.01,5054.04]],"id":38833999}],"con":true,"img":false}]}
{"op":"mcm","clk":"5322054126","pt":1646315878663,"mc":[{"id":"1.195532855","rc":[{"atb":[[1.01,5056.03]],"id":38833999}],"con":true,"img":false}]}
{"op":"mcm","clk":"5322054140","pt":1646315878878,"mc":[{"id":"1.195532855","rc":[{"atb":[[1.01,5054.04]],"id":38833999}],"con":true,"img":false}]}
{"op":"mcm","clk":"5322054150","pt":1646315878993,"mc":[{"id":"1.195532855","rc":[{"atb":[[1.7,1.99]],"id":38833999}],"con":true,"img":false}]}
{"op":"mcm","clk":"5322054184","pt":1646315879411,"mc":[{"id":"1.195532855","rc":[{"atb":[[1.01,5054.04]],"id":28603686}],"con":true,"img":false}]}
{"op":"mcm","clk":"5322054205","pt":1646315879568,"mc":[{"id":"1.195532855","rc":[{"atb":[[1.01,5056.03]],"id":28603686}],"con":true,"img":false}]}
{"op":"mcm","clk":"5322054224","pt":1646315879883,"mc":[{"id":"1.195532855","rc":[{"atb":[[1.01,5054.04]],"id":28603686}],"con":true,"img":false}]}
{"op":"mcm","clk":"5322054235","pt":1646315879984,"mc":[{"id":"1.195532855","rc":[{"atb":[[1.74,1.99]],"id":28603686}],"con":true,"img":false}]}
{"op":"mcm","clk":"5322054540","pt":1646315884107,"mc":[{"id":"1.195532855","rc":[{"atb":[[1.72,55.56],[1.71,0]],"id":28603686},{"atb":[[1.67,0],[1.68,58.82]],"id":38833999},{"atb":[[1.74,0],[1.75,53.33]],"id":42609833},{"atb":[[1.7,57.14],[1.69,0]],"id":42190933},{"atb":[[1.78,51.28],[1.77,0]],"id":36042605}],"con":true,"img":false}]}
{"op":"mcm","clk":"5322055326","pt":1646315894119,"mc":[{"id":"1.195532855","rc":[{"atb":[[1.7,142.86]],"id":28603686},{"atb":[[1.66,151.52]],"id":38833999},{"atb":[[1.73,136.99]],"id":42609833},{"atb":[[1.68,147.06]],"id":42190933},{"atb":[[1.76,131.58]],"id":36042605}],"con":true,"img":false}]}
{"op":"mcm","clk":"5322055791","pt":1646315899708,"mc":[{"id":"1.195532855","rc":[{"atb":[[1.01,4804.04]],"id":28603686},{"atb":[[1.01,4804.04]],"id":38833999},{"atb":[[1.01,4804.04]],"id":42609833},{"atb":[[1.01,4804.04]],"id":42190933},{"atb":[[1.02,250]],"id":41064149}],"con":true,"img":false}]}
{"op":"mcm","clk":"5322055800","pt":1646315899815,"mc":[{"id":"1.195532855","rc":[{"atb":[[1.01,4804.04]],"id":36042605}],"con":true,"img":false}]}
{"op":"mcm","clk":"5322056139","pt":1646315904099,"mc":[{"id":"1.195532855","rc":[{"atb":[[1.68,220.59]],"id":28603686},{"atb":[[1.64,234.38]],"id":38833999},{"atb":[[1.71,211.27]],"id":42609833},{"atb":[[1.66,227.27]],"id":42190933},{"atb":[[1.74,202.7]],"id":36042605}],"con":true,"img":false}]}
{"op":"mcm","clk":"5322056880","pt":1646315914143,"mc":[{"id":"1.195532855","rc":[{"atb":[[1.66,250]],"id":28603686},{"atb":[[1.62,250]],"id":38833999},{"atb":[[1.69,250]],"id":42609833},{"atb":[[1.64,250]],"id":42190933},{"atb":[[1.72,250]],"id":36042605}],"con":true,"img":false}]}
{"op":"mcm","clk":"5322057972","pt":1646315929590,"mc":[{"id":"1.195532855","rc":[{"atb":[[2.1,13.46]],"id":28603686},{"atb":[[2.04,14.45]],"id":38833999},{"atb":[[2.2,12.65]],"id":42609833},{"atb":[[2.1,14.1]],"id":42190933}],"con":true,"img":false}]}
{"op":"mcm","clk":"5322058028","pt":1646315930278,"mc":[{"id":"1.195532855","rc":[{"atb":[[2.1,0],[2.08,5.58]],"id":28603686},{"atb":[[2.02,5.9],[2.04,0]],"id":38833999},{"atb":[[2.18,5],[2.2,0]],"id":42609833},{"atb":[[2.1,0],[2.08,5.58]],"id":42190933}],"con":true,"img":false}]}
{"op":"mcm","clk":"5322058034","pt":1646315930383,"mc":[{"id":"1.195532855","rc":[{"atb":[[1.73,2.15],[1.72,0],[2.06,37.74],[1.75,55.56],[2.08,0]],"id":28603686},{"atb":[[2,40],[1.68,0],[1.71,58.82],[1.69,2.15]],"id":38833999},{"atb":[[1.78,53.33],[2.18,0],[1.75,0],[2.16,34.48],[1.76,2.15]],"id":42609833},{"atb":[[1.73,57.14],[2.06,37.74],[1.7,0],[2.08,0]],"id":42190933}],"con":true,"img":false}]}
{"op":"mcm","clk":"5322058042","pt":1646315930488,"mc":[{"id":"1.195532855","rc":[{"atb":[[2.02,0]],"id":38833999},{"atb":[[1.71,2.15]],"id":42190933}],"con":true,"img":false}]}
{"op":"mcm","clk":"5322058045","pt":1646315930594,"mc":[{"id":"1.195532855","rc":[{"atb":[[1.72,0]],"id":42190933}],"con":true,"img":false}]}
{"op":"mcm","clk":"5322058053","pt":1646315930697,"mc":[{"id":"1.195532855","rc":[{"atb":[[2.1,1.99]],"id":42190933}],"con":true,"img":false}]}
{"op":"mcm","clk":"5322058076","pt":1646315930965,"mc":[{"id":"1.195532855","rc":[{"atb":[[1.77,0]],"id":42609833}],"con":true,"img":false}]}
{"op":"mcm","clk":"5322058084","pt":1646315931063,"mc":[{"id":"1.195532855","rc":[{"atb":[[2.2,1.99]],"id":42609833}],"con":true,"img":false}]}
{"op":"mcm","clk":"5322058104","pt":1646315931373,"mc":[{"id":"1.195532855","rc":[{"atb":[[1.7,0]],"id":38833999}],"con":true,"img":false}]}
{"op":"mcm","clk":"5322058111","pt":1646315931480,"mc":[{"id":"1.195532855","rc":[{"atb":[[2.04,1.99]],"id":38833999}],"con":true,"img":false}]}
{"op":"mcm","clk":"5322058124","pt":1646315931690,"mc":[{"id":"1.195532855","rc":[{"atb":[[1.74,0]],"id":28603686}],"con":true,"img":false}]}
{"op":"mcm","clk":"5322058131","pt":1646315931793,"mc":[{"id":"1.195532855","rc":[{"atb":[[2.1,1.99]],"id":28603686}],"con":true,"img":false}]}
{"op":"mcm","clk":"5322058179","pt":1646315932472,"mc":[{"id":"1.195532855","rc":[{"atb":[[2.1,0]],"id":42190933}],"con":true,"img":false}]}
{"op":"mcm","clk":"5322058188","pt":1646315932581,"mc":[{"id":"1.195532855","rc":[{"atb":[[2.08,1.99]],"id":42190933}],"con":true,"img":false}]}
{"op":"mcm","clk":"5322058211","pt":1646315932787,"mc":[{"id":"1.195532855","rc":[{"atb":[[2.2,0]],"id":42609833}],"con":true,"img":false}]}
{"op":"mcm","clk":"5322058218","pt":1646315932891,"mc":[{"id":"1.195532855","rc":[{"atb":[[2.18,1.99]],"id":42609833}],"con":true,"img":false}]}
{"op":"mcm","clk":"5322058237","pt":1646315933096,"mc":[{"id":"1.195532855","rc":[{"atb":[[2.04,0]],"id":38833999}],"con":true,"img":false}]}
{"op":"mcm","clk":"5322058243","pt":1646315933199,"mc":[{"id":"1.195532855","rc":[{"atb":[[2.02,1.99]],"id":38833999}],"con":true,"img":false}]}
{"op":"mcm","clk":"5322058261","pt":1646315933364,"mc":[{"id":"1.195532855","rc":[{"atb":[[2.1,0]],"id":28603686}],"con":true,"img":false}]}
{"op":"mcm","clk":"5322058266","pt":1646315933465,"mc":[{"id":"1.195532855","rc":[{"atb":[[2.08,1.99]],"id":28603686}],"con":true,"img":false}]}
{"op":"mcm","clk":"5322058362","pt":1646315934900,"mc":[{"id":"1.195532855","rc":[{"atb":[[2.06,0],[2.04,38.46]],"id":28603686},{"spn":2.08,"spf":1.0,"id":28603686},{"atb":[[2,0],[1.99,40.4]],"id":38833999},{"spn":7.01,"spf":"NaN","id":38833999},{"atb":[[2.16,0],[2.14,35.09]],"id":42609833},{"spn":8.59,"spf":"NaN","id":42609833},{"atb":[[2.06,0],[2.04,38.46]],"id":42190933},{"spn":7.29,"spf":"NaN","id":42190933},{"spn":1.04,"spf":1.0,"id":41064149},{"spn":8.9,"spf":"NaN","id":36042605}],"con":true,"img":false}]}
{"op":"mcm","clk":"5322058448","pt":1646315936218,"mc":[{"id":"1.195532855","rc":[{"atb":[[2.1,1.65]],"id":28603686},{"atb":[[2.04,1.65]],"id":38833999},{"atb":[[2.2,1.65]],"id":42609833},{"atb":[[2.1,1.65]],"id":42190933}],"con":true,"img":false}]}
{"op":"mcm","clk":"5322058497","pt":1646315936890,"mc":[{"id":"1.195532855","rc":[{"atb":[[2.08,0]],"id":42190933}],"con":true,"img":false}]}
{"op":"mcm","clk":"5322058504","pt":1646315936995,"mc":[{"id":"1.195532855","rc":[{"atb":[[2.06,37.74],[2.04,0]],"id":28603686},{"atb":[[2,40],[1.99,0]],"id":38833999},{"atb":[[2.14,0],[2.16,34.48]],"id":42609833},{"atb":[[2.06,39.73],[2.04,0]],"id":42190933}],"con":true,"img":false}]}
{"op":"mcm","clk":"5322058520","pt":1646315937200,"mc":[{"id":"1.195532855","rc":[{"atb":[[2.18,0]],"id":42609833}],"con":true,"img":false}]}
{"op":"mcm","clk":"5322058527","pt":1646315937304,"mc":[{"id":"1.195532855","rc":[{"atb":[[2.16,36.47]],"id":42609833}],"con":true,"img":false}]}
{"op":"mcm","clk":"5322058547","pt":1646315937575,"mc":[{"id":"1.195532855","rc":[{"atb":[[2.02,0]],"id":38833999}],"con":true,"img":false}]}
{"op":"mcm","clk":"5322058554","pt":1646315937675,"mc":[{"id":"1.195532855","rc":[{"atb":[[2,41.99]],"id":38833999}],"con":true,"img":false}]}
{"op":"mcm","clk":"5322058579","pt":1646315937986,"mc":[{"id":"1.195532855","rc":[{"atb":[[2.08,0]],"id":28603686}],"con":true,"img":false}]}
{"op":"mcm","clk":"5322058588","pt":1646315938092,"mc":[{"id":"1.195532855","rc":[{"atb":[[2.06,39.73]],"id":28603686}],"con":true,"img":false}]}
{"op":"mcm","clk":"5322058684","pt":1646315939394,"mc":[{"id":"1.195532855","rc":[{"atb":[[1.75,0],[2.1,41.38]],"id":28603686},{"atb":[[2.04,43.64],[1.71,0]],"id":38833999},{"atb":[[1.78,0],[2.2,38.12]],"id":42609833},{"atb":[[1.73,0],[2.1,41.38]],"id":42190933}],"con":true,"img":false}]}
{"op":"mcm","clk":"5322058728","pt":1646315939913,"mc":[{"id":"1.195532855","rc":[{"atl":[[12.5,3.87],[13.5,0]],"id":28603686},{"atl":[[11.5,3.87],[12,0]],"id":38833999},{"atl":[[11,3.87],[15,0]],"id":42609833},{"atl":[[12,3.87],[12.5,0]],"id":42190933},{"atb":[[1.12,250],[1.03,0]],"id":41064149},{"atl":[[4,9.76],[4.9,0]],"id":41064149},{"atb":[[1.79,2.15],[1.87,51.28]],"id":36042605},{"atl":[[16,0],[18,11.76]],"id":36042605}],"con":true,"img":false}]}
{"op":"mcm","clk":"5322058742","pt":1646315940028,"mc":[{"id":"1.195532855","rc":[{"atl":[[11.5,3.87],[12.5,0]],"id":28603686},{"atl":[[11,3.87]],"id":38833999},{"atl":[[10.5,3.87],[11,0]],"id":42609833},{"atb":[[2.06,37.74]],"id":42190933},{"atl":[[11.5,3.87]],"id":42190933},{"atb":[[1.91,12.19]],"id":36042605}],"con":true,"img":false}]}
{"op":"mcm","clk":"5322058748","pt":1646315940080,"mc":[{"id":"1.195532855","rc":[{"atl":[[11.5,0]],"id":38833999},{"atb":[[2.12,1.99]],"id":42190933},{"atl":[[12,0]],"id":42190933},{"atb":[[1.12,0],[1.21,250]],"id":41064149},{"atl":[[4,0],[3.8,9.76]],"id":41064149},{"atb":[[1.84,51.28],[1.87,0]],"id":36042605},{"atl":[[18,5.88],[19,13.89]],"id":36042605}],"con":true,"img":false}]}
{"op":"mcm","clk":"5322058773","pt":1646315940291,"mc":[{"id":"1.195532855","rc":[{"atl":[[12.5,3.48],[14.5,0]],"id":28603686},{"atl":[[12,3.64],[13,0]],"id":38833999},{"atl":[[16,0],[11.5,3.81]],"id":42609833},{"atb":[[2.06,0],[2.08,37.04]],"id":42190933},{"atl":[[12.5,3.48],[13.5,0]],"id":42190933},{"atb":[[1.19,210.53]],"id":41064149},{"atl":[[5.1,0],[3.9,13.79]],"id":41064149},{"atb":[[1.89,44.94],[1.91,0],[1.78,0]],"id":36042605},{"atl":[[17,0],[18,2.35]],"id":36042605}],"con":true,"img":false}]}
{"op":"mcm","clk":"5322058790","pt":1646315940396,"mc":[{"id":"1.195532855","rc":[{"atb":[[2.16,34.48]],"id":42609833},{"atb":[[1.84,0],[1.87,24.38]],"id":36042605},{"atl":[[19,8.33],[19.5,5.41]],"id":36042605}],"con":true,"img":false}]}
{"op":"mcm","clk":"5322058799","pt":1646315940504,"mc":[{"id":"1.195532855","rc":[{"atb":[[2.22,1.99]],"id":42609833}],"con":true,"img":false}]}
{"op":"mcm","clk":"5322058835","pt":1646315940809,"mc":[{"id":"1.195532855","rc":[{"atb":[[2,40]],"id":38833999}],"con":true,"img":false}]}
{"op":"mcm","clk":"5322058844","pt":1646315940917,"mc":[{"id":"1.195532855","rc":[{"atb":[[2.06,1.99]],"id":38833999}],"con":true,"img":false}]}
{"op":"mcm","clk":"5322058880","pt":1646315941186,"mc":[{"id":"1.195532855","rc":[{"atb":[[2.06,37.74]],"id":28603686},{"atb":[[2,0],[2.02,39.22]],"id":38833999},{"atb":[[2.18,33.9]],"id":42609833},{"atb":[[1.89,0]],"id":36042605},{"atl":[[18,0],[19,0]],"id":36042605}],"con":true,"img":false}]}
{"op":"mcm","clk":"5322058888","pt":1646315941291,"mc":[{"id":"1.195532855","rc":[{"atb":[[2.12,1.99]],"id":28603686},{"atb":[[2.16,0]],"id":42609833},{"atb":[[1.87,70.36]],"id":36042605},{"atl":[[19,2.22]],"id":36042605}],"con":true,"img":false}]}
{"op":"mcm","clk":"5322058945","pt":1646315942074,"mc":[{"id":"1.195532855","rc":[{"atb":[[1.8,0]],"id":36042605}],"con":true,"img":false}]}
{"op":"mcm","clk":"5322058963","pt":1646315942179,"mc":[{"id":"1.195532855","rc":[{"atb":[[1.88,1.99]],"id":36042605}],"con":true,"img":false}]}
{"op":"mcm","clk":"5322058993","pt":1646315942598,"mc":[{"id":"1.195532855","rc":[{"atb":[[1.04,0]],"id":41064149}],"con":true,"img":false}]}
{"op":"mcm","clk":"5322058999","pt":1646315942703,"mc":[{"id":"1.195532855","rc":[{"atb":[[1.22,1.99]],"id":41064149}],"con":true,"img":false}]}
{"op":"mcm","clk":"5322059215","pt":1646315945105,"mc":[{"id":"1.195532855","rc":[{"atb":[[2.06,0],[2.08,37.04]],"id":28603686},{"atb":[[1.2,200]],"id":41064149},{"atb":[[1.86,46.51],[1.87,24.38]],"id":36042605},{"atl":[[19,0],[20,2.11]],"id":36042605}],"con":true,"img":false}]}
{"op":"mcm","clk":"5322059319","pt":1646315946208,"mc":[{"id":"1.195532855","rc":[{"atb":[[2.1,39.73]],"id":28603686},{"atb":[[2.04,41.99]],"id":38833999},{"atb":[[2.2,36.47]],"id":42609833},{"atb":[[2.1,39.73]],"id":42190933}],"con":true,"img":false}]}
{"op":"mcm","clk":"5322059336","pt":1646315946407,"mc":[{"id":"1.195532855","rc":[{"atb":[[2.14,1.65]],"id":28603686},{"atb":[[2.08,1.65]],"id":38833999},{"atb":[[2.24,1.65]],"id":42609833},{"atb":[[2.14,1.65]],"id":42190933}],"con":true,"img":false}]}
{"op":"mcm","clk":"5322059486","pt":1646315948299,"mc":[{"id":"1.195532855","rc":[{"atb":[[2.14,3.65],[2.1,0]],"id":28603686},{"atb":[[2.04,0],[2.08,3.65]],"id":38833999},{"atb":[[2.24,3.65],[2.2,0]],"id":42609833},{"atb":[[2.14,3.65]],"id":42190933}],"con":true,"img":false}]}
{"op":"mcm","clk":"5322059496","pt":1646315948405,"mc":[{"id":"1.195532855","rc":[{"atb":[[2.12,39.03]],"id":28603686},{"atb":[[2.06,41.21],[2.08,1.65]],"id":38833999},{"atb":[[2.24,1.65],[2.22,35.89]],"id":42609833},{"atb":[[2.12,39.03],[2.14,1.65],[2.1,0]],"id":42190933}],"con":true,"img":false}]}
{"op":"mcm","clk":"5322059509","pt":1646315948508,"mc":[{"id":"1.195532855","rc":[{"atb":[[2.14,1.65]],"id":28603686}],"con":true,"img":false}]}
{"op":"mcm","clk":"5322059678","pt":1646315950292,"mc":[{"id":"1.195532855","rc":[{"atb":[[2.1,36.36]],"id":42190933},{"atl":[[13.5,8]],"id":42190933}],"con":true,"img":false}]}
{"op":"mcm","clk":"5322059693","pt":1646315950404,"mc":[{"id":"1.195532855","rc":[{"atb":[[2.08,0]],"id":42190933}],"con":true,"img":false}]}
{"op":"mcm","clk":"5322059786","pt":1646315951225,"mc":[{"id":"1.195532855","rc":[{"atb":[[2.02,0],[2.04,38.46]],"id":38833999},{"atl":[[13,8.33]],"id":38833999},{"atb":[[2.18,0],[2.2,33.33]],"id":42609833},{"atl":[[12.5,8.7]],"id":42609833}],"con":true,"img":false}]}
{"op":"mcm","clk":"5322060108","pt":1646315955115,"mc":[{"id":"1.195532855","rc":[{"atb":[[2.1,36.36],[2.08,0]],"id":28603686},{"atl":[[13.5,8]],"id":28603686},{"atb":[[1.18,250]],"id":41064149},{"atl":[[4,33.33]],"id":41064149},{"atb":[[1.84,119.05]],"id":36042605},{"atl":[[22,4.76]],"id":36042605}],"con":true,"img":false}]}
{"op":"mcm","clk":"5322060224","pt":1646315956318,"mc":[{"id":"1.195532855","rc":[{"atl":[[17,0],[18,0],[19,0]],"id":42609833},{"atl":[[16.5,0]],"id":42190933},{"atb":[[1.01,4804.04],[1.19,0]],"id":41064149},{"atl":[[5.3,0],[5.5,0],[5.7,0]],"id":41064149},{"atb":[[1.72,0]],"id":36042605},{"atl":[[20,0],[21,2]],"id":36042605}],"con":true,"img":false}]}
{"op":"mcm","clk":"5322060230","pt":1646315956420,"mc":[{"id":"1.195532855","rc":[{"atl":[[17.5,0]],"id":28603686},{"atl":[[16,0]],"id":38833999},{"atb":[[1.79,0],[1.9,2.15]],"id":36042605}],"con":true,"img":false}]}
{"op":"mcm","clk":"5322060237","pt":1646315956522,"mc":[{"id":"1.195532855","rc":[{"atb":[[1.9,4.3]],"id":36042605}],"con":true,"img":false}]}
{"op":"mcm","clk":"5322060243","pt":1646315956637,"mc":[{"id":"1.195532855","rc":[{"atb":[[1.88,26.37],[1.9,2.15],[1.87,0]],"id":36042605}],"con":true,"img":false}]}
{"op":"mcm","clk":"5322060250","pt":1646315956733,"mc":[{"id":"1.195532855","rc":[{"atb":[[1.88,47.44],[1.9,6.45],[1.86,0]],"id":36042605}],"con":true,"img":false}]}
{"op":"mcm","clk":"5322060258","pt":1646315956790,"mc":[{"id":"1.195532855","rc":[{"atb":[[1.86,116.28]],"id":36042605}],"con":true,"img":false}]}
{"op":"mcm","clk":"5322060271","pt":1646315956898,"mc":[{"id":"1.195532855","rc":[{"atb":[[1.9,2.15]],"id":36042605}],"con":true,"img":false}]}
{"op":"mcm","clk":"5322060280","pt":1646315957009,"mc":[{"id":"1.195532855","rc":[{"atb":[[1.88,161.08],[1.86,0]],"id":36042605}],"con":true,"img":false}]}
{"op":"mcm","clk":"5322060295","pt":1646315957213,"mc":[{"id":"1.195532855","rc":[{"atb":[[1.88,47.44],[1.9,113.26]],"id":36042605}],"con":true,"img":false}]}
{"op":"mcm","clk":"5322060335","pt":1646315957632,"mc":[{"id":"1.195532855","rc":[{"atb":[[1.88,45.45]],"id":36042605}],"con":true,"img":false}]}
{"op":"mcm","clk":"5322060347","pt":1646315957738,"mc":[{"id":"1.195532855","rc":[{"atb":[[1.91,1.99]],"id":36042605}],"con":true,"img":false}]}
{"op":"mcm","clk":"5322060360","pt":1646315957903,"mc":[{"id":"1.195532855","rc":[{"atb":[[1.89,44.94]],"id":36042605}],"con":true,"img":false}]}
{"op":"mcm","clk":"5322060374","pt":1646315958010,"mc":[{"id":"1.195532855","rc":[{"atb":[[1.88,0]],"id":36042605}],"con":true,"img":false}]}
{"op":"mcm","clk":"5322060614","pt":1646315960333,"mc":[{"id":"1.195532855","rc":[{"atb":[[2.06,94.34]],"id":42190933},{"atl":[[14.5,11.11]],"id":42190933}],"con":true,"img":false}]}
{"op":"mcm","clk":"5322060691","pt":1646315961232,"mc":[{"id":"1.195532855","rc":[{"atb":[[2,100]],"id":38833999},{"atl":[[14,11.54]],"id":38833999},{"atb":[[2.16,86.21]],"id":42609833},{"atl":[[13.5,12]],"id":42609833}],"con":true,"img":false}]}
{"op":"mcm","clk":"5322061034","pt":1646315965137,"mc":[{"id":"1.195532855","rc":[{"atb":[[2.06,94.34]],"id":28603686},{"atl":[[14.5,11.11]],"id":28603686},{"atb":[[1.16,250]],"id":41064149},{"atl":[[4.2,46.88]],"id":41064149}],"con":true,"img":false}]}
{"op":"mcm","clk":"5322061053","pt":1646315965344,"mc":[{"id":"1.195532855","rc":[{"atb":[[1.7,0],[1.68,0],[1.66,0]],"id":28603686},{"atl":[[16.5,0]],"id":28603686},{"atb":[[1.62,0]],"id":38833999},{"atl":[[10.5,3.87],[11,0]],"id":38833999},{"atb":[[1.73,0],[1.71,0],[1.69,0]],"id":42609833},{"atl":[[10.5,0],[11,8.7]],"id":42609833},{"atb":[[1.64,0],[1.68,0],[1.66,0]],"id":42190933},{"atl":[[11,3.87],[11.5,0]],"id":42190933},{"atl":[[3.8,0]],"id":41064149},{"atl":[[19,4.76]],"id":36042605}],"con":true,"img":false}]}
{"op":"mcm","clk":"5322061064","pt":1646315965404,"mc":[{"id":"1.195532855","rc":[{"atl":[[3.75,13.79]],"id":41064149},{"atl":[[19.5,0]],"id":36042605}],"con":true,"img":false}]}
{"op":"mcm","clk":"5322061183","pt":1646315966918,"mc":[{"id":"1.195532855","rc":[{"atb":[[1.73,0],[2.18,2.15]],"id":28603686},{"atb":[[2.12,2.15],[1.69,0]],"id":38833999},{"atb":[[2.28,2.15],[1.76,0]],"id":42609833},{"atb":[[2.18,2.15],[1.71,0]],"id":42190933}],"con":true,"img":false}]}
{"op":"mcm","clk":"5322061195","pt":1646315967025,"mc":[{"id":"1.195532855","rc":[{"atb":[[2.12,1.99],[2.18,4.3]],"id":28603686},{"atb":[[2.12,4.3]],"id":38833999},{"atb":[[2.22,1.99],[2.28,4.3]],"id":42609833},{"atb":[[2.12,1.99],[2.18,4.3]],"id":42190933}],"con":true,"img":false}]}
{"op":"mcm","clk":"5322061211","pt":1646315967231,"mc":[{"id":"1.195532855","rc":[{"atb":[[2.06,1.99]],"id":38833999}],"con":true,"img":false}]}
{"op":"mcm","clk":"5322061245","pt":1646315967706,"mc":[{"id":"1.195532855","rc":[{"atb":[[2.12,0]],"id":42190933}],"con":true,"img":false}]}
{"op":"mcm","clk":"5322061253","pt":1646315967823,"mc":[{"id":"1.195532855","rc":[{"atb":[[2.2,1.99]],"id":42190933}],"con":true,"img":false}]}
{"op":"mcm","clk":"5322061265","pt":1646315968020,"mc":[{"id":"1.195532855","rc":[{"atb":[[2.22,0]],"id":42609833},{"atb":[[1.87,114.94]],"id":36042605},{"atl":[[20,2.11]],"id":36042605}],"con":true,"img":false}]}
{"op":"mcm","clk":"5322061273","pt":1646315968125,"mc":[{"id":"1.195532855","rc":[{"atb":[[2.3,1.99]],"id":42609833}],"con":true,"img":false}]}
{"op":"mcm","clk":"5322061295","pt":1646315968332,"mc":[{"id":"1.195532855","rc":[{"atb":[[2.06,0]],"id":38833999}],"con":true,"img":false}]}
{"op":"mcm","clk":"5322061306","pt":1646315968438,"mc":[{"id":"1.195532855","rc":[{"atb":[[2.14,1.99]],"id":38833999}],"con":true,"img":false}]}
{"op":"mcm","clk":"5322061320","pt":1646315968645,"mc":[{"id":"1.195532855","rc":[{"atb":[[2.12,0]],"id":28603686}],"con":true,"img":false}]}
{"op":"mcm","clk":"5322061330","pt":1646315968745,"mc":[{"id":"1.195532855","rc":[{"atb":[[2.2,1.99]],"id":28603686}],"con":true,"img":false}]}
{"op":"mcm","clk":"5322061453","pt":1646315970321,"mc":[{"id":"1.195532855","rc":[{"atb":[[2.1,40.82],[2.16,34.48]],"id":42190933},{"atl":[[12,3.64],[12.5,0]],"id":42190933}],"con":true,"img":false}]}
{"op":"mcm","clk":"5322061487","pt":1646315970738,"mc":[{"id":"1.195532855","rc":[{"atb":[[2.1,36.36]],"id":42190933}],"con":true,"img":false}]}
{"op":"mcm","clk":"5322061528","pt":1646315971207,"mc":[{"id":"1.195532855","rc":[{"atb":[[2.04,0]],"id":38833999},{"atl":[[12,0]],"id":38833999},{"atl":[[11.5,0]],"id":42609833}],"con":true,"img":false}]}
{"op":"mcm","clk":"5322061533","pt":1646315971314,"mc":[{"id":"1.195532855","rc":[{"atb":[[2.04,4.72],[2.1,36.36]],"id":38833999},{"atl":[[11.5,3.81]],"id":38833999},{"atb":[[2.26,31.75]],"id":42609833},{"atl":[[12,3.64]],"id":42609833}],"con":true,"img":false}]}
{"op":"mcm","clk":"5322061564","pt":1646315971736,"mc":[{"id":"1.195532855","rc":[{"atb":[[2.04,0]],"id":38833999}],"con":true,"img":false}]}
{"op":"mcm","clk":"5322061704","pt":1646315973933,"mc":[{"id":"1.195532855","rc":[{"atb":[[1.92,16.25]],"id":42609833}],"con":true,"img":false}]}
{"op":"mcm","clk":"5322061725","pt":1646315974248,"mc":[{"id":"1.195532855","rc":[{"atb":[[1.92,0]],"id":42609833}],"con":true,"img":false}]}
{"op":"mcm","clk":"5322061785","pt":1646315975138,"mc":[{"id":"1.195532855","rc":[{"atb":[[2.1,40.82],[2.16,34.48]],"id":28603686},{"atl":[[15.5,17.24]],"id":28603686},{"atb":[[1.14,250]],"id":41064149},{"atl":[[3.85,14.04]],"id":41064149}],"con":true,"img":false}]}
{"op":"mcm","clk":"5322061807","pt":1646315975351,"mc":[{"id":"1.195532855","rc":[{"atb":[[2.1,36.36]],"id":28603686}],"con":true,"img":false}]}
{"op":"mcm","clk":"5322061877","pt":1646315976239,"mc":[{"id":"1.195532855","rc":[{"atb":[[2.14,0]],"id":28603686},{"atb":[[2.08,0]],"id":38833999},{"atb":[[2.24,0]],"id":42609833},{"atb":[[2.14,0]],"id":42190933}],"con":true,"img":false}]}
{"op":"mcm","clk":"5322061899","pt":1646315976445,"mc":[{"id":"1.195532855","rc":[{"atb":[[2.22,1.65]],"id":28603686},{"atb":[[2.16,1.65]],"id":38833999},{"atb":[[2.32,1.65]],"id":42609833},{"atb":[[2.22,1.65]],"id":42190933}],"con":true,"img":false}]}
{"op":"mcm","clk":"5322061909","pt":1646315976544,"mc":[{"id":"1.195532855","rc":[{"atb":[[2.22,3.65],[2.18,2.15]],"id":28603686}],"con":true,"img":false}]}
{"op":"mcm","clk":"5322061916","pt":1646315976654,"mc":[{"id":"1.195532855","rc":[{"atb":[[2.12,2.15],[2.16,3.65]],"id":38833999},{"atb":[[2.32,3.65],[2.28,2.15]],"id":42609833},{"atb":[[2.22,3.65],[2.18,2.15]],"id":42190933}],"con":true,"img":false}]}
{"op":"mcm","clk":"5322061923","pt":1646315976753,"mc":[{"id":"1.195532855","rc":[{"atb":[[2.16,1.65],[2.14,6.29]],"id":38833999},{"atb":[[2.32,1.65],[2.3,6.29]],"id":42609833},{"atb":[[2.22,1.65],[2.2,6.29]],"id":42190933}],"con":true,"img":false}]}
{"op":"mcm","clk":"5322061963","pt":1646315977223,"mc":[{"id":"1.195532855","rc":[{"atb":[[2.2,0]],"id":28603686}],"con":true,"img":false}]}
{"op":"mcm","clk":"5322061974","pt":1646315977325,"mc":[{"id":"1.195532855","rc":[{"atb":[[2.24,1.99]],"id":28603686}],"con":true,"img":false}]}
{"op":"mcm","clk":"5322062019","pt":1646315978049,"mc":[{"id":"1.195532855","rc":[{"atb":[[1.84,0],[1.74,0],[1.85,176.47],[1.76,0]],"id":36042605},{"atl":[[24,6.52]],"id":36042605}],"con":true,"img":false}]}
{"op":"mcm","clk":"5322062219","pt":1646315980340,"mc":[{"id":"1.195532855","rc":[{"atb":[[2.18,36.05]],"id":42190933}],"con":true,"img":false}]}
{"op":"mcm","clk":"5322062319","pt":1646315981243,"mc":[{"id":"1.195532855","rc":[{"atb":[[2.12,37.86],[2.1,0]],"id":38833999},{"atb":[[2.28,33.4]],"id":42609833},{"atl":[[13,8.33]],"id":42609833}],"con":true,"img":false}]}
{"op":"mcm","clk":"5322062638","pt":1646315985164,"mc":[{"id":"1.195532855","rc":[{"atb":[[2.2,33.33]],"id":28603686},{"atl":[[3.95,33.9]],"id":41064149}],"con":true,"img":false}]}
{"op":"mcm","clk":"5322062642","pt":1646315985268,"mc":[{"id":"1.195532855","rc":[{"atb":[[1.02,0]],"id":41064149}],"con":true,"img":false}]}
{"op":"mcm","clk":"5322062674","pt":1646315985530,"mc":[{"id":"1.195532855","rc":[{"atb":[[2.18,0],[2.26,2.15]],"id":28603686}],"con":true,"img":false}]}
{"op":"mcm","clk":"5322062681","pt":1646315985633,"mc":[{"id":"1.195532855","rc":[{"atb":[[2.22,1.65],[2.26,4.3]],"id":28603686}],"con":true,"img":false}]}
{"op":"mcm","clk":"5322062690","pt":1646315985741,"mc":[{"id":"1.195532855","rc":[{"atb":[[2.24,0]],"id":28603686}],"con":true,"img":false}]}
{"op":"mcm","clk":"5322062699","pt":1646315985846,"mc":[{"id":"1.195532855","rc":[{"atb":[[2.28,1.99]],"id":28603686}],"con":true,"img":false}]}
{"op":"mcm","clk":"5322062727","pt":1646315986270,"mc":[{"id":"1.195532855","rc":[{"atb":[[2.22,0]],"id":28603686}],"con":true,"img":false}]}
{"op":"mcm","clk":"5322062738","pt":1646315986377,"mc":[{"id":"1.195532855","rc":[{"atb":[[2.3,1.65]],"id":28603686}],"con":true,"img":false}]}
{"op":"mcm","clk":"5322062898","pt":1646315988048,"mc":[{"id":"1.195532855","rc":[{"atb":[[1.83,250]],"id":36042605},{"atl":[[26,10]],"id":36042605}],"con":true,"img":false}]}
{"op":"mcm","clk":"5322063093","pt":1646315990373,"mc":[{"id":"1.195532855","rc":[{"atb":[[2.14,87.72]],"id":42190933}],"con":true,"img":false}]}
{"op":"mcm","clk":"5322063353","pt":1646315991242,"mc":[{"id":"1.195532855","rc":[{"atb":[[2.08,92.59]],"id":38833999},{"atb":[[2.24,80.65]],"id":42609833},{"atl":[[14,11.54]],"id":42609833}],"con":true,"img":false}]}
{"op":"mcm","clk":"5322063736","pt":1646315994177,"mc":[{"id":"1.195532855","rc":[{"atb":[[2.3,3.65],[2.26,2.15]],"id":28603686}],"con":true,"img":false}]}
{"op":"mcm","clk":"5322063931","pt":1646315995176,"mc":[{"id":"1.195532855","rc":[{"atb":[[2.16,86.21]],"id":28603686},{"spn":2.3,"spf":1.0,"id":28603686},{"spn":6.33,"spf":"NaN","id":38833999},{"spn":6.66,"spf":"NaN","id":42609833},{"spn":6.61,"spf":"NaN","id":42190933},{"atl":[[4,0],[3.95,40.8],[4.1,48.39],[3.9,0],[4.2,0]],"id":41064149},{"spn":1.22,"spf":1.0,"id":41064149},{"spn":10.45,"spf":"NaN","id":36042605}],"con":true,"img":false}]}
{"op":"mcm","clk":"5322064091","pt":1646315996582,"mc":[{"id":"1.195532855","rc":[{"atb":[[2.28,0]],"id":28603686}],"con":true,"img":false}]}
{"op":"mcm","clk":"5322064096","pt":1646315996690,"mc":[{"id":"1.195532855","rc":[{"atb":[[2.32,1.99]],"id":28603686}],"con":true,"img":false}]}
{"op":"mcm","clk":"5322064151","pt":1646315997162,"mc":[{"id":"1.195532855","rc":[{"atl":[[3.95,33.9]],"id":41064149}],"con":true,"img":false}]}
{"op":"mcm","clk":"5322064248","pt":1646315998059,"mc":[{"id":"1.195532855","rc":[{"atl":[[21,0]],"id":36042605}],"con":true,"img":false}]}
{"op":"mcm","clk":"5322064503","pt":1646316000158,"mc":[{"id":"1.195532855","rc":[{"atb":[[1.18,440.72],[1.22,37.95]],"id":41064149},{"atl":[[2.92,35.96],[3.95,90.87]],"id":41064149}],"con":true,"img":false}]}
{"op":"mcm","clk":"5322064518","pt":1646316000269,"mc":[{"id":"1.195532855","rc":[{"atb":[[1.2,451.99],[1.21,0]],"id":41064149}],"con":true,"img":false}]}
{"op":"mcm","clk":"5322064529","pt":1646316000381,"mc":[{"id":"1.195532855","rc":[{"atb":[[2.54,2.5],[2.3,9.01],[2.38,10],[2.46,5],[2.2,45.23]],"id":28603686},{"atl":[[5.6,2.5],[8.6,5.36],[6,5],[6.8,10],[13.5,24.67]],"id":28603686},{"atb":[[2.36,5],[2.24,7.62],[2.28,10],[2.44,2.5],[2.08,112.94]],"id":38833999},{"atl":[[7.2,10],[6.4,5],[5.8,2.5],[13,25.64],[8.4,7.62]],"id":38833999},{"atb":[[2.4,11.24],[2.26,53.5]],"id":42609833},{"atl":[[5.6,5],[6,10],[12.5,26.7],[5.2,2.5],[8.4,10.81]],"id":42609833},{"atb":[[2.36,10],[2.3,7.62],[2.52,2.5],[2.44,5],[2.16,19.94],[2.1,136.36]],"id":42190933},{"atl":[[6.2,2.5],[13.5,24.67],[7,5],[7.8,10],[8.4,7.62]],"id":42190933},{"atb":[[1.58,2.5],[1.54,5],[1.19,42.5],[1.5,10]],"id":41064149},{"atl":[[2.92,0],[3.45,2.5],[3.85,24.04],[3.65,5]],"id":41064149},{"atb":[[2.92,5],[1.91,9.13],[3,2.5],[2.84,10],[1.87,177.06],[2.08,11.9]],"id":36042605},{"atl":[[8.6,5],[10,7.14],[22,14.98],[7.8,2.5],[9.4,10]],"id":36042605}],"con":true,"img":false}]}
{"op":"mcm","clk":"5322064548","pt":1646316000481,"mc":[{"id":"1.195532855","rc":[{"atb":[[1.2,200],[1.22,478.67]],"id":41064149}],"con":true,"img":false}]}
{"op":"mcm","clk":"5322064567","pt":1646316000601,"mc":[{"id":"1.195532855","rc":[{"atl":[[11.5,0],[6.8,13.87],[12,4.28]],"id":28603686},{"atb":[[2.28,16.29],[2.14,1.99]],"id":38833999},{"atl":[[7.2,13.87],[10.5,0]],"id":38833999},{"atb":[[2.32,24.13],[2.3,1.99]],"id":42609833},{"atl":[[11,0],[6,18.7]],"id":42609833},{"atb":[[2.36,16.29],[2.2,1.99]],"id":42190933},{"atl":[[11,0],[7.8,13.87]],"id":42190933},{"atb":[[1.19,0]],"id":41064149},{"atl":[[2.92,2],[3.65,42.74],[3.75,0]],"id":41064149},{"atb":[[2.5,44.94],[1.9,2.15],[1.87,114.94],[2.08,0]],"id":36042605},{"atl":[[19,0],[9.4,14.76]],"id":36042605}],"con":true,"img":false}]}
{"op":"mcm","clk":"5322064576","pt":1646316000688,"mc":[{"id":"1.195532855","rc":[{"atl":[[11,4.57]],"id":38833999},{"atl":[[11.5,6.85]],"id":42609833},{"atl":[[11.5,4.43]],"id":42190933},{"atl":[[19.5,3.77]],"id":36042605}],"con":true,"img":false}]}
{"op":"mcm","clk":"5322064588","pt":1646316000813,"mc":[{"id":"1.195532855","rc":[{"atl":[[12,0]],"id":28603686}],"con":true,"img":false}]}
{"op":"mcm","clk":"5322064605","pt":1646316000855,"mc":[{"id":"1.195532855","rc":[{"atl":[[11.5,0]],"id":42609833}],"con":true,"img":false}]}
{"op":"mcm","clk":"5322064654","pt":1646316001223,"mc":[{"id":"1.195532855","rc":[{"atl":[[11,0]],"id":38833999},{"atl":[[11.5,0]],"id":42190933},{"atl":[[19.5,0]],"id":36042605}],"con":true,"img":false}]}
{"op":"mcm","clk":"5322064674","pt":1646316001294,"mc":[{"id":"1.195532855","rc":[{"atb":[[2.3,32.76]],"id":42609833},{"atl":[[5.4,9.09]],"id":42609833}],"con":true,"img":false}]}
{"op":"mcm","clk":"5322064695","pt":1646316001396,"mc":[{"id":"1.195532855","rc":[{"atb":[[2.26,0]],"id":28603686},{"atb":[[2.12,0],[2.14,37.08]],"id":38833999},{"atl":[[11.5,0],[6,8]],"id":38833999},{"atb":[[2.28,0]],"id":42609833},{"atl":[[12,0],[12.5,18],[13.5,0]],"id":42609833},{"atb":[[1.53,2.15]],"id":41064149},{"atb":[[1.91,7.14]],"id":36042605}],"con":true,"img":false}]}
{"op":"mcm","clk":"5322064718","pt":1646316001533,"mc":[{"id":"1.195532855","rc":[{"atb":[[2.44,2.15]],"id":28603686},{"atb":[[2.34,2.15]],"id":38833999},{"atb":[[2.46,2.15]],"id":42609833},{"atb":[[1.02,1.99]],"id":36042605}],"con":true,"img":false}]}
{"op":"mcm","clk":"5322064761","pt":1646316001768,"mc":[{"id":"1.195532855","rc":[{"atb":[[2.2,0]],"id":42190933}],"con":true,"img":false}]}
{"op":"mcm","clk":"5322064780","pt":1646316001883,"mc":[{"id":"1.195532855","rc":[{"atb":[[2.54,1.99]],"id":42190933}],"con":true,"img":false}]}
{"op":"mcm","clk":"5322064803","pt":1646316002084,"mc":[{"id":"1.195532855","rc":[{"atb":[[2.34,5]],"id":42190933}],"con":true,"img":false}]}
{"op":"mcm","clk":"5322064828","pt":1646316002304,"mc":[{"id":"1.195532855","rc":[{"atb":[[2.3,30.77]],"id":42609833}],"con":true,"img":false}]}
{"op":"mcm","clk":"5322064846","pt":1646316002400,"mc":[{"id":"1.195532855","rc":[{"atb":[[2.42,1.99]],"id":42609833}],"con":true,"img":false}]}
{"op":"mcm","clk":"5322064881","pt":1646316002600,"mc":[{"id":"1.195532855","rc":[{"atb":[[2.3,7.01],[2.46,10]],"id":28603686},{"atb":[[1.22,476.68]],"id":41064149}],"con":true,"img":false}]}
{"op":"mcm","clk":"5322064892","pt":1646316002668,"mc":[{"id":"1.195532855","rc":[{"atb":[[1.59,1.99]],"id":41064149}],"con":true,"img":false}]}
{"op":"mcm","clk":"5322064915","pt":1646316002881,"mc":[{"id":"1.195532855","rc":[{"atb":[[2.14,35.09]],"id":38833999}],"con":true,"img":false}]}
{"op":"mcm","clk":"5322064933","pt":1646316002985,"mc":[{"id":"1.195532855","rc":[{"atb":[[1.02,1.99]],"id":38833999}],"con":true,"img":false}]}
{"op":"mcm","clk":"5322064946","pt":1646316003096,"mc":[{"id":"1.195532855","rc":[{"atb":[[2.34,0]],"id":42190933}],"con":true,"img":false}]}
{"op":"mcm","clk":"5322064961","pt":1646316003194,"mc":[{"id":"1.195532855","rc":[{"atb":[[2.32,0]],"id":28603686}],"con":true,"img":false}]}
{"op":"mcm","clk":"5322064974","pt":1646316003298,"mc":[{"id":"1.195532855","rc":[{"atb":[[2.56,1.99]],"id":28603686}],"con":true,"img":false}]}
{"op":"mcm","clk":"5322065114","pt":1646316004396,"mc":[{"id":"1.195532855","rc":[{"atb":[[2.42,0]],"id":42609833},{"atb":[[1.59,12.99]],"id":41064149}],"con":true,"img":false}]}
{"op":"mcm","clk":"5322065125","pt":1646316004477,"mc":[{"id":"1.195532855","rc":[{"atb":[[2.48,1.99]],"id":42609833}],"con":true,"img":false}]}
{"op":"mcm","clk":"5322065217","pt":1646316005207,"mc":[{"id":"1.195532855","rc":[{"atb":[[2.12,133.93]],"id":28603686},{"atl":[[5.8,8.33],[12.5,0]],"id":28603686},{"atb":[[1.2,0],[1.57,70.18]],"id":41064149},{"atl":[[2.96,20.41]],"id":41064149}],"con":true,"img":false}]}
{"op":"mcm","clk":"5322065393","pt":1646316006768,"mc":[{"id":"1.195532855","rc":[{"atb":[[2.06,0],[2.1,0]],"id":28603686},{"atb":[[2.18,2.15],[2.2,33.33]],"id":42190933},{"atl":[[12,0],[6.6,7.14]],"id":42190933},{"atb":[[1.89,0],[2.68,23.81]],"id":36042605},{"atl":[[20,0],[8.2,5.56]],"id":36042605}],"con":true,"img":false}]}
{"op":"mcm","clk":"5322065404","pt":1646316006874,"mc":[{"id":"1.195532855","rc":[{"atb":[[2,0],[1.64,0],[2.08,20.35],[1.66,0]],"id":38833999},{"atb":[[2.24,0],[2.2,0],[2.16,0]],"id":42609833},{"atl":[[8,5.56],[9.4,10]],"id":36042605}],"con":true,"img":false}]}
{"op":"mcm","clk":"5322065452","pt":1646316007395,"mc":[{"id":"1.195532855","rc":[{"atl":[[7.8,13.5]],"id":36042605}],"con":true,"img":false}]}
{"op":"mcm","clk":"5322065606","pt":1646316008876,"mc":[{"id":"1.195532855","rc":[{"atb":[[1.59,25.98],[1.22,35.96]],"id":41064149}],"con":true,"img":false}]}
{"op":"mcm","clk":"5322065616","pt":1646316008982,"mc":[{"id":"1.195532855","rc":[{"atl":[[6,15.83],[6.8,10]],"id":28603686},{"atb":[[2.36,10],[2.28,10]],"id":38833999},{"atl":[[7.2,10],[6.4,15.5]],"id":38833999},{"atl":[[5.6,16.59],[6,10]],"id":42609833},{"atb":[[2.5,7.62],[2.36,10]],"id":42190933},{"atl":[[7,14.64],[7.8,10]],"id":42190933}],"con":true,"img":false}]}
{"op":"mcm","clk":"5322065757","pt":1646316010397,"mc":[{"id":"1.195532855","rc":[{"atb":[[2.3,5.36]],"id":28603686},{"atb":[[2.16,0]],"id":38833999},{"atb":[[2.32,22.48]],"id":42609833},{"atb":[[2.22,0]],"id":42190933}],"con":true,"img":false}]}
{"op":"mcm","clk":"5322065776","pt":1646316010604,"mc":[{"id":"1.195532855","rc":[{"atb":[[2.58,1.65]],"id":28603686},{"atb":[[2.46,1.65]],"id":38833999},{"atb":[[2.5,1.65]],"id":42609833},{"atb":[[2.56,1.65]],"id":42190933},{"atb":[[3.05,1.65]],"id":36042605}],"con":true,"img":false}]}
{"op":"mcm","clk":"5322065801","pt":1646316010902,"mc":[{"id":"1.195532855","rc":[{"atb":[[2.46,5],[2.58,3.65]],"id":28603686}],"con":true,"img":false}]}
{"op":"mcm","clk":"5322065831","pt":1646316011296,"mc":[{"id":"1.195532855","rc":[{"atb":[[2.1,90.91]],"id":38833999},{"atl":[[6.4,34.02]],"id":38833999},{"atb":[[2.26,101.12]],"id":42609833},{"atl":[[5.6,38.33]],"id":42609833}],"con":true,"img":false}]}
{"op":"mcm","clk":"5322065859","pt":1646316011602,"mc":[{"id":"1.195532855","rc":[{"atb":[[2.56,0]],"id":28603686}],"con":true,"img":false}]}
{"op":"mcm","clk":"5322065874","pt":1646316011705,"mc":[{"id":"1.195532855","rc":[{"atb":[[2.6,1.99]],"id":28603686}],"con":true,"img":false}]}
{"op":"mcm","clk":"5322065904","pt":1646316012021,"mc":[{"id":"1.195532855","rc":[{"atl":[[8,0],[8.2,19.45]],"id":36042605}],"con":true,"img":false}]}
{"op":"mcm","clk":"5322065910","pt":1646316012107,"mc":[{"id":"1.195532855","rc":[{"atb":[[2.42,2.15],[2.34,0]],"id":38833999},{"atb":[[1.62,2.15],[1.53,0]],"id":41064149}],"con":true,"img":false}]}
{"op":"mcm","clk":"5322065945","pt":1646316012496,"mc":[{"id":"1.195532855","rc":[{"atb":[[1.59,23.99]],"id":41064149}],"con":true,"img":false}]}
{"op":"mcm","clk":"5322065954","pt":1646316012585,"mc":[{"id":"1.195532855","rc":[{"atb":[[1.63,1.99]],"id":41064149}],"con":true,"img":false}]}
{"op":"mcm","clk":"5322066144","pt":1646316015243,"mc":[{"id":"1.195532855","rc":[{"atb":[[2.08,231.48]],"id":28603686},{"atl":[[6,35.83]],"id":28603686},{"atb":[[1.57,0],[1.61,65.57]],"id":41064149},{"atl":[[3,50]],"id":41064149}],"con":true,"img":false}]}
{"op":"mcm","clk":"5322066150","pt":1646316015290,"mc":[{"id":"1.195532855","rc":[{"atl":[[3,74.04],[3.65,5]],"id":41064149}],"con":true,"img":false}]}
{"op":"mcm","clk":"5322066311","pt":1646316016807,"mc":[{"id":"1.195532855","rc":[{"atl":[[7,31.31]],"id":42190933},{"atb":[[2.64,60.98]],"id":36042605},{"atl":[[8.6,18.16]],"id":36042605}],"con":true,"img":false}]}
{"op":"mcm","clk":"5322066347","pt":1646316017178,"mc":[{"id":"1.195532855","rc":[{"atb":[[1.59,11],[1.61,89.56]],"id":41064149},{"atl":[[8.6,31.32],[8.2,5.56]],"id":36042605}],"con":true,"img":false}]}
{"op":"mcm","clk":"5322066366","pt":1646316017289,"mc":[{"id":"1.195532855","rc":[{"atb":[[2.36,5],[2.46,3.8]],"id":38833999}],"con":true,"img":false}]}
{"op":"mcm","clk":"5322066407","pt":1646316017698,"mc":[{"id":"1.195532855","rc":[{"atb":[[1.18,250],[1.59,50.26],[1.62,19.07]],"id":41064149},{"atl":[[3.95,33.9],[3,136.86],[2.84,16.92]],"id":41064149}],"con":true,"img":false}]}
{"op":"mcm","clk":"5322066423","pt":1646316017792,"mc":[{"id":"1.195532855","rc":[{"atb":[[2.44,9.85]],"id":28603686},{"atb":[[2.26,106.93]],"id":42609833}],"con":true,"img":false}]}
{"op":"mcm","clk":"5322066432","pt":1646316017904,"mc":[{"id":"1.195532855","rc":[{"atb":[[1.22,0]],"id":41064149},{"atl":[[2.92,0]],"id":41064149},{"atl":[[7.6,7.92]],"id":36042605}],"con":true,"img":false}]}
{"op":"mcm","clk":"5322066441","pt":1646316018003,"mc":[{"id":"1.195532855","rc":[{"atb":[[2.46,18.31],[2.58,8.27],[2.2,33.33]],"id":28603686},{"atl":[[5.5,4.62],[6,57.13],[13.5,7.99]],"id":28603686},{"atb":[[2.42,10.04],[2.46,8.53],[2.08,0]],"id":38833999},{"atl":[[5.6,4.73],[6.4,46.64],[13,8.33]],"id":38833999},{"atb":[[2.4,27.16],[2.26,85.18]],"id":42609833},{"atl":[[5.6,63.81],[5,3.49],[12.5,0]],"id":42609833},{"atb":[[2.54,5.74],[2.5,21.11],[2.16,0]],"id":42190933},{"atl":[[6,3.75],[13.5,7.99],[7,52.89]],"id":42190933},{"atl":[[8.6,58.95],[22,4.75]],"id":36042605}],"con":true,"img":false}]}
{"op":"mcm","clk":"5322066461","pt":1646316018206,"mc":[{"id":"1.195532855","rc":[{"atb":[[2.3,0],[2.44,2.15]],"id":28603686},{"atl":[[8.6,0],[5.8,18.33],[6,46.3]],"id":28603686},{"atb":[[2.24,0]],"id":38833999},{"atl":[[6.4,36.14],[6,18],[8.4,0]],"id":38833999},{"atb":[[2.26,79.37]],"id":42609833},{"atl":[[5.6,52.22],[8.4,0],[5.4,19.09]],"id":42609833},{"atb":[[2.3,0]],"id":42190933},{"atl":[[7,43.25],[8.4,0],[5.9,3.75]],"id":42190933},{"atl":[[10,0]],"id":36042605}],"con":true,"img":false}]}
{"op":"mcm","clk":"5322066663","pt":1646316019995,"mc":[{"id":"1.195532855","rc":[{"atl":[[5.8,10],[6,26.3],[5.7,8.51]],"id":28603686},{"atl":[[5.8,10.83],[6,10],[15,0]],"id":38833999},{"atl":[[5.2,12.02],[5.4,10]],"id":42609833},{"atl":[[6.2,10.19],[6.6,0],[15.5,0]],"id":42190933},{"atl":[[3.85,10],[2.88,21.28],[3.95,0],[4.1,0],[2.96,0]],"id":41064149},{"atb":[[1.83,0],[1.85,0],[1.87,0]],"id":36042605},{"atl":[[8,5.71],[8.6,45.79],[8.2,0]],"id":36042605}],"con":true,"img":false}]}
{"op":"mcm","clk":"5322066702","pt":1646316020417,"mc":[{"id":"1.195532855","rc":[{"atb":[[2.58,6.62]],"id":28603686}],"con":true,"img":false}]}
{"op":"mcm","clk":"5322066727","pt":1646316020615,"mc":[{"id":"1.195532855","rc":[{"atb":[[2.62,1.65]],"id":28603686}],"con":true,"img":false}]}
{"op":"mcm","clk":"5322066749","pt":1646316020826,"mc":[{"id":"1.195532855","rc":[{"atb":[[2.58,4.62],[2.62,3.65]],"id":28603686}],"con":true,"img":false}]}
{"op":"mcm","clk":"5322066755","pt":1646316020872,"mc":[{"id":"1.195532855","rc":[{"atb":[[2.52,3.75]],"id":28603686}],"con":true,"img":false}]}
{"op":"mcm","clk":"5322066807","pt":1646316021394,"mc":[{"id":"1.195532855","rc":[{"atb":[[2.6,0]],"id":28603686}],"con":true,"img":false}]}
{"op":"mcm","clk":"5322066814","pt":1646316021500,"mc":[{"id":"1.195532855","rc":[{"atb":[[2.64,1.99],[2.52,0]],"id":28603686}],"con":true,"img":false}]}
{"op":"mcm","clk":"5322066908","pt":1646316022495,"mc":[{"id":"1.195532855","rc":[{"atb":[[2.64,4.14],[2.44,0]],"id":28603686},{"atb":[[2.5,2.15],[2.42,7.89]],"id":38833999}],"con":true,"img":false}]}
{"op":"mcm","clk":"5322066981","pt":1646316023384,"mc":[{"id":"1.195532855","rc":[{"atl":[[6.2,20.38],[5.9,0]],"id":42190933}],"con":true,"img":false}]}
{"op":"mcm","clk":"5322067003","pt":1646316023592,"mc":[{"id":"1.195532855","rc":[{"atl":[[6.4,7.41],[6.2,12.69]],"id":42190933}],"con":true,"img":false}]}
{"op":"mcm","clk":"5322067163","pt":1646316025422,"mc":[{"id":"1.195532855","rc":[{"atl":[[8,20],[8.6,32.63]],"id":36042605}],"con":true,"img":false}]}
{"op":"mcm","clk":"5322067215","pt":1646316025887,"mc":[{"id":"1.195532855","rc":[{"atb":[[2.48,6.22]],"id":42609833},{"atb":[[2.5,13.49],[2.52,9.9]],"id":42190933}],"con":true,"img":false}]}
{"op":"mcm","clk":"5322067232","pt":1646316026093,"mc":[{"id":"1.195532855","rc":[{"atb":[[2.4,15.92]],"id":42609833}],"con":true,"img":false}]}
{"op":"mcm","clk":"5322067484","pt":1646316028605,"mc":[{"id":"1.195532855","rc":[{"atl":[[6.4,23.85],[6.2,2.5]],"id":42190933}],"con":true,"img":false}]}
{"op":"mcm","clk":"5322067597","pt":1646316029994,"mc":[{"id":"1.195532855","rc":[{"atl":[[5.9,20.41]],"id":28603686},{"atb":[[2.06,141.51]],"id":38833999},{"atl":[[6,30]],"id":38833999},{"atb":[[2.22,122.95]],"id":42609833},{"atl":[[5.4,32.73]],"id":42609833},{"atb":[[1.59,219.75]],"id":41064149},{"atl":[[2.92,52.08]],"id":41064149},{"atb":[[2.6,93.75]],"id":36042605},{"atl":[[8.4,13.51]],"id":36042605}],"con":true,"img":false}]}
{"op":"mcm","clk":"5322067603","pt":1646316030096,"mc":[{"id":"1.195532855","rc":[{"atl":[[2.92,90.28],[3,112.82]],"id":41064149}],"con":true,"img":false}]}
{"op":"mcm","clk":"5322067632","pt":1646316030516,"mc":[{"id":"1.195532855","rc":[{"atb":[[2.62,2]],"id":28603686},{"atb":[[2.46,6.88]],"id":38833999}],"con":true,"img":false}]}
{"op":"mcm","clk":"5322067653","pt":1646316030722,"mc":[{"id":"1.195532855","rc":[{"atb":[[2.66,1.65]],"id":28603686},{"atb":[[2.52,1.65]],"id":38833999}],"con":true,"img":false}]}
{"op":"mcm","clk":"5322067706","pt":1646316031399,"mc":[{"id":"1.195532855","rc":[{"atl":[[3.05,50.44]],"id":41064149}],"con":true,"img":false}]}
{"op":"mcm","clk":"5322067725","pt":1646316031712,"mc":[{"id":"1.195532855","rc":[{"atl":[[3.05,0]],"id":41064149}],"con":true,"img":false}]}
{"op":"mcm","clk":"5322067845","pt":1646316033019,"mc":[{"id":"1.195532855","rc":[{"atl":[[15.5,0]],"id":28603686},{"atb":[[2.48,6.88],[2.46,4.73]],"id":38833999},{"atl":[[14,0]],"id":38833999},{"atb":[[2.32,0],[2.38,30.77]],"id":42609833},{"atl":[[14,0]],"id":42609833},{"atb":[[1.18,0],[1.16,0],[1.14,0]],"id":41064149},{"atl":[[26,0]],"id":36042605}],"con":true,"img":false}]}
{"op":"mcm","clk":"5322067858","pt":1646316033114,"mc":[{"id":"1.195532855","rc":[{"atb":[[2.4,20.21]],"id":42609833},{"atb":[[2.58,2.15],[2.18,0]],"id":42190933}],"con":true,"img":false}]}
{"op":"mcm","clk":"5322067924","pt":1646316033690,"mc":[{"id":"1.195532855","rc":[{"atb":[[2.54,3.75]],"id":42190933}],"con":true,"img":false}]}
{"op":"mcm","clk":"5322067935","pt":1646316033799,"mc":[{"id":"1.195532855","rc":[{"atb":[[2.4,15.92]],"id":42609833},{"atb":[[2.6,1.99]],"id":42190933}],"con":true,"img":false}]}
{"op":"mcm","clk":"5322067971","pt":1646316034103,"mc":[{"id":"1.195532855","rc":[{"atb":[[1.63,12.99]],"id":41064149}],"con":true,"img":false}]}
{"op":"mcm","clk":"5322068031","pt":1646316034925,"mc":[{"id":"1.195532855","rc":[{"atb":[[1.59,180.49],[1.63,43.25],[1.61,140]],"id":41064149},{"atl":[[2.92,170.98],[3,50]],"id":41064149}],"con":true,"img":false}]}
{"op":"mcm","clk":"5322068039","pt":1646316034988,"mc":[{"id":"1.195532855","rc":[{"atb":[[1.59,169.49]],"id":41064149}],"con":true,"img":false}]}
{"op":"mcm","clk":"5322068052","pt":1646316035087,"mc":[{"id":"1.195532855","rc":[{"atb":[[1.62,2.15]],"id":41064149}],"con":true,"img":false}]}
{"op":"mcm","clk":"5322068062","pt":1646316035190,"mc":[{"id":"1.195532855","rc":[{"atb":[[2.46,5],[2.64,9.12],[2.58,16.17]],"id":28603686},{"atl":[[6,5],[5.7,26.99]],"id":28603686},{"atb":[[2.5,10.86],[2.42,0],[2.46,19.24]],"id":38833999},{"atl":[[6.4,23.52],[6,53.22],[5.4,8.71]],"id":38833999},{"atl":[[5.6,26.74],[4.8,7.28],[5.4,72.53]],"id":42609833},{"atb":[[2.5,0],[2.58,5.64],[2.52,21.84]],"id":42190933},{"atl":[[6.4,42.95],[7,21.67]],"id":42190933},{"atl":[[8,51.25],[8.6,5]],"id":36042605}],"con":true,"img":false}]}
{"op":"mcm","clk":"5322068072","pt":1646316035295,"mc":[{"id":"1.195532855","rc":[{"atb":[[2.58,11.55]],"id":28603686},{"atl":[[5.6,12.5],[5.8,0]],"id":28603686},{"atb":[[2.46,14.51]],"id":38833999},{"atl":[[5.6,0],[5.8,31.66],[6,43.22]],"id":38833999},{"atl":[[5,0],[5.2,35.83]],"id":42609833},{"atb":[[2.54,0]],"id":42190933}],"con":true,"img":false}]}
{"op":"mcm","clk":"5322068084","pt":1646316035402,"mc":[{"id":"1.195532855","rc":[{"atl":[[5.6,2.5],[5.7,47.4]],"id":28603686},{"atl":[[5.6,8.7],[5.8,23.33]],"id":38833999},{"atl":[[5,10],[5.2,26.31],[5.4,62.53]],"id":42609833}],"con":true,"img":false}]}
{"op":"mcm","clk":"5322068098","pt":1646316035605,"mc":[{"id":"1.195532855","rc":[{"atl":[[5.2,2.5],[4.9,25.64]],"id":42609833}],"con":true,"img":false}]}
{"op":"mcm","clk":"5322068389","pt":1646316039098,"mc":[{"id":"1.195532855","rc":[{"atb":[[1.54,27.3]],"id":41064149}],"con":true,"img":false}]}
{"op":"mcm","clk":"5322068422","pt":1646316039510,"mc":[{"id":"1.195532855","rc":[{"atb":[[1.54,5]],"id":41064149}],"con":true,"img":false}]}
{"op":"mcm","clk":"5322068434","pt":1646316039618,"mc":[{"id":"1.195532855","rc":[{"atl":[[2.84,0]],"id":41064149}],"con":true,"img":false}]}
{"op":"mcm","clk":"5322068438","pt":1646316039717,"mc":[{"id":"1.195532855","rc":[{"atl":[[2.86,43.01]],"id":41064149}],"con":true,"img":false}]}
{"op":"mcm","clk":"5322068447","pt":1646316039821,"mc":[{"id":"1.195532855","rc":[{"atl":[[2.92,132.78],[3,100]],"id":41064149}],"con":true,"img":false}]}
{"op":"mcm","clk":"5322068467","pt":1646316040026,"mc":[{"id":"1.195532855","rc":[{"atl":[[6.2,28.85]],"id":28603686},{"atb":[[1.57,250]],"id":41064149},{"atl":[[2.88,0],[2.9,21.05]],"id":41064149},{"atb":[[2.56,160.26]],"id":36042605},{"atl":[[8.8,19.23]],"id":36042605}],"con":true,"img":false}]}
{"op":"mcm","clk":"5322068501","pt":1646316040394,"mc":[{"id":"1.195532855","rc":[{"atb":[[2.56,0]],"id":42190933}],"con":true,"img":false}]}
{"op":"mcm","clk":"5322068510","pt":1646316040504,"mc":[{"id":"1.195532855","rc":[{"atb":[[2.62,1.65]],"id":42190933}],"con":true,"img":false}]}
{"op":"mcm","clk":"5322068532","pt":1646316040812,"mc":[{"id":"1.195532855","rc":[{"atl":[[5,35],[4.9,0]],"id":42609833}],"con":true,"img":false}]}
{"op":"mcm","clk":"5322068551","pt":1646316041025,"mc":[{"id":"1.195532855","rc":[{"atl":[[5,40.13]],"id":42609833}],"con":true,"img":false}]}
{"op":"mcm","clk":"5322068616","pt":1646316041801,"mc":[{"id":"1.195532855","rc":[{"atl":[[5,35]],"id":42609833}],"con":true,"img":false}]}
{"op":"mcm","clk":"5322068716","pt":1646316042998,"mc":[{"id":"1.195532855","rc":[{"atl":[[14.5,0]],"id":28603686},{"atl":[[24,0]],"id":36042605}],"con":true,"img":false}]}
{"op":"mcm","clk":"5322068785","pt":1646316044053,"mc":[{"id":"1.195532855","rc":[{"atb":[[1.62,0],[1.66,2.15]],"id":41064149}],"con":true,"img":false}]}
{"op":"mcm","clk":"5322068801","pt":1646316044203,"mc":[{"id":"1.195532855","rc":[{"atb":[[1.63,106.74]],"id":41064149}],"con":true,"img":false}]}
{"op":"mcm","clk":"5322068857","pt":1646316044925,"mc":[{"id":"1.195532855","rc":[{"atb":[[1.63,104.75]],"id":41064149}],"con":true,"img":false}]}
{"op":"mcm","clk":"5322068866","pt":1646316045030,"mc":[{"id":"1.195532855","rc":[{"atb":[[1.67,1.99]],"id":41064149}],"con":true,"img":false}]}
{"op":"mcm","clk":"5322068900","pt":1646316045398,"mc":[{"id":"1.195532855","rc":[{"atb":[[2.02,245.1]],"id":38833999},{"atl":[[5.8,44.16]],"id":38833999},{"atb":[[2.18,211.86]],"id":42609833},{"atl":[[5.2,26.31]],"id":42609833}],"con":true,"img":false}]}
{"op":"mcm","clk":"5322068944","pt":1646316045971,"mc":[{"id":"1.195532855","rc":[{"atl":[[5,10],[5.2,50.12]],"id":42609833}],"con":true,"img":false}]}
{"op":"mcm","clk":"5322069014","pt":1646316046795,"mc":[{"id":"1.195532855","rc":[{"atl":[[13,0]],"id":38833999},{"atl":[[13,0]],"id":42609833}],"con":true,"img":false}]}
{"op":"mcm","clk":"5322069092","pt":1646316047789,"mc":[{"id":"1.195532855","rc":[{"atl":[[2.92,184.86],[3,50]],"id":41064149}],"con":true,"img":false}]}
{"op":"mcm","clk":"5322069287","pt":1646316049976,"mc":[{"id":"1.195532855","rc":[{"atl":[[6.6,44.64]],"id":28603686},{"atl":[[9.2,30.49]],"id":36042605}],"con":true,"img":false}]}
{"op":"mcm","clk":"5322069423","pt":1646316051601,"mc":[{"id":"1.195532855","rc":[{"atb":[[2.5,4.17]],"id":42190933}],"con":true,"img":false}]}
{"op":"mcm","clk":"5322069435","pt":1646316051706,"mc":[{"id":"1.195532855","rc":[{"atb":[[1.7,44.34]],"id":41064149}],"con":true,"img":false}]}
{"op":"mcm","clk":"5322069441","pt":1646316051811,"mc":[{"id":"1.195532855","rc":[{"atb":[[2.52,28.28]],"id":42190933},{"atb":[[1.63,74.49]],"id":41064149}],"con":true,"img":false}]}
{"op":"mcm","clk":"5322069447","pt":1646316051865,"mc":[{"id":"1.195532855","rc":[{"atb":[[1.63,183.68],[1.61,89.56]],"id":41064149}],"con":true,"img":false}]}
{"op":"mcm","clk":"5322069452","pt":1646316051972,"mc":[{"id":"1.195532855","rc":[{"atb":[[2.52,21.84]],"id":42190933}],"con":true,"img":false}]}
{"op":"mcm","clk":"5322069459","pt":1646316052072,"mc":[{"id":"1.195532855","rc":[{"atl":[[5.8,86.62],[6,20]],"id":38833999},{"atl":[[5.2,85.88],[5.4,22.73]],"id":42609833},{"atb":[[2.6,6.68]],"id":42190933}],"con":true,"img":false}]}
{"op":"mcm","clk":"5322069465","pt":1646316052182,"mc":[{"id":"1.195532855","rc":[{"atb":[[2.5,0]],"id":42190933}],"con":true,"img":false}]}
{"op":"mcm","clk":"5322069473","pt":1646316052285,"mc":[{"id":"1.195532855","rc":[{"atb":[[2.58,2.15]],"id":42190933}],"con":true,"img":false}]}
{"op":"mcm","clk":"5322069478","pt":1646316052387,"mc":[{"id":"1.195532855","rc":[{"atb":[[1.67,0]],"id":41064149}],"con":true,"img":false}]}
{"op":"mcm","clk":"5322069487","pt":1646316052493,"mc":[{"id":"1.195532855","rc":[{"atb":[[1.71,1.99]],"id":41064149}],"con":true,"img":false}]}
{"op":"mcm","clk":"5322069570","pt":1646316053585,"mc":[{"id":"1.195532855","rc":[{"atb":[[2.52,3.19]],"id":28603686},{"atb":[[2.42,11.16]],"id":38833999}],"con":true,"img":false}]}
{"op":"mcm","clk":"5322069586","pt":1646316053793,"mc":[{"id":"1.195532855","rc":[{"atb":[[2.52,0]],"id":28603686},{"atb":[[2.42,0]],"id":38833999}],"con":true,"img":false}]}
{"op":"mcm","clk":"5322069606","pt":1646316054000,"mc":[{"id":"1.195532855","rc":[{"atb":[[1.73,2.15],[1.66,0]],"id":41064149}],"con":true,"img":false}]}
{"op":"mcm","clk":"5322069626","pt":1646316054211,"mc":[{"id":"1.195532855","rc":[{"atb":[[1.61,253.49]],"id":41064149},{"atl":[[2.94,51.55]],"id":41064149}],"con":true,"img":false}]}
{"op":"mcm","clk":"5322069635","pt":1646316054314,"mc":[{"id":"1.195532855","rc":[{"atl":[[13.5,0]],"id":28603686},{"atb":[[1.61,187.92]],"id":41064149},{"atl":[[22,0]],"id":36042605}],"con":true,"img":false}]}
{"op":"mcm","clk":"5322069719","pt":1646316055206,"mc":[{"id":"1.195532855","rc":[{"spn":2.66,"spf":1.0,"id":28603686},{"spn":3.96,"spf":"NaN","id":38833999},{"spn":3.65,"spf":"NaN","id":42609833},{"spn":4.31,"spf":"NaN","id":42190933},{"atb":[[1.71,0]],"id":41064149},{"spn":1.73,"spf":1.0,"id":41064149},{"spn":5.32,"spf":"NaN","id":36042605}],"con":true,"img":false}]}
{"op":"mcm","clk":"5322069725","pt":1646316055308,"mc":[{"id":"1.195532855","rc":[{"atb":[[1.74,1.99]],"id":41064149}],"con":true,"img":false}]}
{"op":"mcm","clk":"5322069732","pt":1646316055412,"mc":[{"id":"1.195532855","rc":[{"atl":[[6,30]],"id":38833999},{"atl":[[5.4,0]],"id":42609833}],"con":true,"img":false}]}
{"op":"mcm","clk":"5322069738","pt":1646316055516,"mc":[{"id":"1.195532855","rc":[{"atl":[[5.4,34.09]],"id":42609833}],"con":true,"img":false}]}
{"op":"mcm","clk":"5322069782","pt":1646316056087,"mc":[{"id":"1.195532855","rc":[{"atb":[[2.84,32.4]],"id":36042605}],"con":true,"img":false}]}
{"op":"mcm","clk":"5322069813","pt":1646316056503,"mc":[{"id":"1.195532855","rc":[{"atl":[[2.84,43.48]],"id":41064149}],"con":true,"img":false}]}
{"op":"mcm","clk":"5322069823","pt":1646316056608,"mc":[{"id":"1.195532855","rc":[{"atl":[[2.9,112.55]],"id":41064149}],"con":true,"img":false}]}
{"op":"mcm","clk":"5322069832","pt":1646316056711,"mc":[{"id":"1.195532855","rc":[{"atl":[[2.92,104.16],[2.86,0]],"id":41064149}],"con":true,"img":false}]}
{"op":"mcm","clk":"5322070357","pt":1646316062918,"mc":[{"id":"1.195532855","rc":[{"atl":[[2.88,21.28],[2.9,91.5]],"id":41064149}],"con":true,"img":false}]}
{"op":"mcm","clk":"5322070434","pt":1646316064014,"mc":[{"id":"1.195532855","rc":[{"atb":[[1.74,12.99]],"id":41064149}],"con":true,"img":false}]}
{"op":"mcm","clk":"5322070504","pt":1646316064583,"mc":[{"id":"1.195532855","rc":[{"atb":[[1.73,0],[1.77,2.15]],"id":41064149}],"con":true,"img":false}]}
{"op":"mcm","clk":"5322070522","pt":1646316064896,"mc":[{"id":"1.195532855","rc":[{"atb":[[1.74,11]],"id":41064149}],"con":true,"img":false}]}
{"op":"mcm","clk":"5322070537","pt":1646316065009,"mc":[{"id":"1.195532855","rc":[{"atb":[[1.78,1.99]],"id":41064149}],"con":true,"img":false}]}
{"op":"mcm","clk":"5322070574","pt":1646316065417,"mc":[{"id":"1.195532855","rc":[{"atl":[[6.4,51.3]],"id":38833999},{"atl":[[5.6,59.35]],"id":42609833}],"con":true,"img":false}]}
{"op":"mcm","clk":"5322070584","pt":1646316065523,"mc":[{"id":"1.195532855","rc":[{"atb":[[1.7,76.56]],"id":41064149}],"con":true,"img":false}]}
{"op":"mcm","clk":"5322070633","pt":1646316066096,"mc":[{"id":"1.195532855","rc":[{"atb":[[1.7,44.34]],"id":41064149}],"con":true,"img":false}]}
{"op":"mcm","clk":"5322070646","pt":1646316066302,"mc":[{"id":"1.195532855","rc":[{"atl":[[7.2,0],[6.4,46.3],[5.8,84.12],[5.7,2.5]],"id":38833999},{"atb":[[1.58,0],[1.54,0],[1.5,0]],"id":41064149},{"atl":[[8.6,0],[7.6,10.42],[7.8,11],[8.4,18.51],[9.4,0]],"id":36042605}],"con":true,"img":false}]}
{"op":"mcm","clk":"5322070654","pt":1646316066405,"mc":[{"id":"1.195532855","rc":[{"atl":[[5.6,26.12]],"id":38833999},{"atl":[[7.6,21.42]],"id":36042605}],"con":true,"img":false}]}
{"op":"mcm","clk":"5322070665","pt":1646316066508,"mc":[{"id":"1.195532855","rc":[{"atl":[[5.8,63.29]],"id":38833999},{"atl":[[8,36.96]],"id":36042605}],"con":true,"img":false}]}
{"op":"mcm","clk":"5322070811","pt":1646316068437,"mc":[{"id":"1.195532855","rc":[{"atb":[[1.63,74.49],[1.7,125.29]],"id":41064149}],"con":true,"img":false}]}
{"op":"mcm","clk":"5322070826","pt":1646316068595,"mc":[{"id":"1.195532855","rc":[{"atl":[[5.7,44.96]],"id":38833999}],"con":true,"img":false}]}
{"op":"mcm","clk":"5322070838","pt":1646316068709,"mc":[{"id":"1.195532855","rc":[{"atl":[[5.8,20.83]],"id":38833999}],"con":true,"img":false}]}
{"op":"mcm","clk":"5322071040","pt":1646316071542,"mc":[{"id":"1.195532855","rc":[{"atl":[[5.6,8.69],[5.7,66.24]],"id":38833999},{"atl":[[8,51.25],[7.6,10.42]],"id":36042605}],"con":true,"img":false}]}
{"op":"mcm","clk":"5322071156","pt":1646316072904,"mc":[{"id":"1.195532855","rc":[{"atb":[[1.59,250]],"id":41064149},{"atl":[[2.96,76.53]],"id":41064149}],"con":true,"img":false}]}
{"op":"mcm","clk":"5322071256","pt":1646316074306,"mc":[{"id":"1.195532855","rc":[{"atl":[[2.94,0]],"id":41064149}],"con":true,"img":false}]}
{"op":"mcm","clk":"5322071697","pt":1646316079912,"mc":[{"id":"1.195532855","rc":[{"atl":[[2.84,50.13]],"id":41064149}],"con":true,"img":false}]}
{"op":"mcm","clk":"5322071705","pt":1646316080016,"mc":[{"id":"1.195532855","rc":[{"atl":[[2.82,50.13],[2.92,52.08],[2.84,6.65]],"id":41064149}],"con":true,"img":false}]}
{"op":"mcm","clk":"5322071717","pt":1646316080121,"mc":[{"id":"1.195532855","rc":[{"atl":[[2.82,9.86],[2.88,85.84],[2.9,52.63],[2.84,5.5]],"id":41064149}],"con":true,"img":false}]}
{"op":"mcm","clk":"5322071725","pt":1646316080224,"mc":[{"id":"1.195532855","rc":[{"atl":[[2.92,55.57],[2.9,0],[2.84,59.85]],"id":41064149}],"con":true,"img":false}]}
{"op":"mcm","clk":"5322071735","pt":1646316080329,"mc":[{"id":"1.195532855","rc":[{"atl":[[2.92,52.08],[2.88,139.03]],"id":41064149}],"con":true,"img":false}]}
{"op":"mcm","clk":"5322071743","pt":1646316080433,"mc":[{"id":"1.195532855","rc":[{"atl":[[2.84,5.5]],"id":41064149}],"con":true,"img":false}]}
{"op":"mcm","clk":"5322071750","pt":1646316080538,"mc":[{"id":"1.195532855","rc":[{"atl":[[2.84,0]],"id":41064149}],"con":true,"img":false}]}
{"op":"mcm","clk":"5322071766","pt":1646316080643,"mc":[{"id":"1.195532855","rc":[{"atl":[[2.82,0]],"id":41064149}],"con":true,"img":false}]}
{"op":"mcm","clk":"5322071779","pt":1646316080746,"mc":[{"id":"1.195532855","rc":[{"atl":[[2.92,104.16],[2.88,85.84]],"id":41064149}],"con":true,"img":false}]}
{"op":"mcm","clk":"5322071790","pt":1646316080853,"mc":[{"id":"1.195532855","rc":[{"atl":[[2.84,15.64]],"id":41064149}],"con":true,"img":false}]}
{"op":"mcm","clk":"5322071818","pt":1646316081114,"mc":[{"id":"1.195532855","rc":[{"atl":[[2.84,0]],"id":41064149}],"con":true,"img":false}]}
{"op":"mcm","clk":"5322071831","pt":1646316081217,"mc":[{"id":"1.195532855","rc":[{"atl":[[2.86,9.86]],"id":41064149}],"con":true,"img":false}]}
{"op":"mcm","clk":"5322071845","pt":1646316081320,"mc":[{"id":"1.195532855","rc":[{"atl":[[2.92,72.91],[2.88,64.56]],"id":41064149}],"con":true,"img":false}]}
{"op":"mcm","clk":"5322072285","pt":1646316086649,"mc":[{"id":"1.195532855","rc":[{"atl":[[2.9,21.05]],"id":41064149}],"con":true,"img":false}]}
{"op":"mcm","clk":"5322072357","pt":1646316087641,"mc":[{"id":"1.195532855","rc":[{"atl":[[2.9,85.15]],"id":41064149}],"con":true,"img":false}]}
{"op":"mcm","clk":"5322072370","pt":1646316087749,"mc":[{"id":"1.195532855","rc":[{"atl":[[2.88,0]],"id":41064149}],"con":true,"img":false}]}
{"op":"mcm","clk":"5322072996","pt":1646316095034,"mc":[{"id":"1.195532855","rc":[{"atl":[[2.92,173.18]],"id":41064149}],"con":true,"img":false}]}
{"op":"mcm","clk":"5322073008","pt":1646316095147,"mc":[{"id":"1.195532855","rc":[{"atl":[[2.9,21.05]],"id":41064149}],"con":true,"img":false}]}
{"op":"mcm","clk":"5322073257","pt":1646316096645,"mc":[{"id":"1.195532855","rc":[{"atl":[[2.94,51.55]],"id":41064149}],"con":true,"img":false}]}
{"op":"mcm","clk":"5322073929","pt":1646316101959,"mc":[{"id":"1.195532855","rc":[{"atb":[[1.58,21.19]],"id":41064149}],"con":true,"img":false}]}
{"op":"mcm","clk":"5322073957","pt":1646316102277,"mc":[{"id":"1.195532855","rc":[{"atb":[[1.58,0]],"id":41064149}],"con":true,"img":false}]}
{"op":"mcm","clk":"5322074321","pt":1646316106655,"mc":[{"id":"1.195532855","rc":[{"atl":[[2.98,75.76]],"id":41064149}],"con":true,"img":false}]}
{"op":"mcm","clk":"5322074327","pt":1646316106758,"mc":[{"id":"1.195532855","rc":[{"atl":[[2.92,152.35],[3,0],[2.96,0]],"id":41064149}],"con":true,"img":false}]}
{"op":"mcm","clk":"5322075243","pt":1646316116587,"mc":[{"id":"1.195532855","rc":[{"atl":[[3.05,121.95]],"id":41064149},{"spn":1.78,"spf":1.0,"id":41064149}],"con":true,"img":false}]}
{"op":"mcm","clk":"5322075624","pt":1646316120488,"mc":[{"id":"1.195532855","rc":[{"atb":[[2.98,3.25]],"id":36042605}],"con":true,"img":false}]}
{"op":"mcm","clk":"5322075632","pt":1646316120592,"mc":[{"id":"1.195532855","rc":[{"atl":[[5.8,5.32]],"id":28603686},{"atb":[[2.44,5.89]],"id":38833999},{"atl":[[5.7,69.99]],"id":38833999},{"atl":[[5.1,3.75]],"id":42609833},{"atl":[[6.8,4.46]],"id":42190933},{"atl":[[2.94,64.57]],"id":41064149},{"atb":[[2.84,10]],"id":36042605},{"atl":[[8.2,3.57]],"id":36042605}],"con":true,"img":false}]}
{"op":"mcm","clk":"5322075640","pt":1646316120697,"mc":[{"id":"1.195532855","rc":[{"atl":[[5.1,34.07],[5,24.56],[5.2,26.31]],"id":42609833},{"atb":[[2.98,0]],"id":36042605}],"con":true,"img":false}]}
{"op":"mcm","clk":"5322075646","pt":1646316120807,"mc":[{"id":"1.195532855","rc":[{"atl":[[5.5,2.55]],"id":38833999},{"atb":[[2.84,35.52]],"id":36042605}],"con":true,"img":false}]}
{"op":"mcm","clk":"5322075657","pt":1646316120905,"mc":[{"id":"1.195532855","rc":[{"atl":[[5.6,43.52],[5.5,19.97]],"id":38833999}],"con":true,"img":false}]}
{"op":"mcm","clk":"5322075673","pt":1646316121015,"mc":[{"id":"1.195532855","rc":[{"atl":[[5.7,6.25]],"id":38833999}],"con":true,"img":false}]}
{"op":"mcm","clk":"5322075687","pt":1646316121111,"mc":[{"id":"1.195532855","rc":[{"atl":[[5.8,0]],"id":28603686},{"atb":[[2.44,2.5]],"id":38833999},{"atl":[[5.7,2.5]],"id":38833999},{"atl":[[5.1,30.32]],"id":42609833},{"atl":[[6.8,0]],"id":42190933},{"atl":[[2.94,51.55]],"id":41064149},{"atl":[[8.2,0]],"id":36042605}],"con":true,"img":false}]}
{"op":"mcm","clk":"5322075699","pt":1646316121221,"mc":[{"id":"1.195532855","rc":[{"atl":[[5.5,17.42]],"id":38833999}],"con":true,"img":false}]}
{"op":"mcm","clk":"5322075902","pt":1646316123209,"mc":[{"id":"1.195532855","rc":[{"atl":[[5.6,53.97]],"id":38833999}],"con":true,"img":false}]}
{"op":"mcm","clk":"5322075984","pt":1646316123895,"mc":[{"id":"1.195532855","rc":[{"atl":[[5.6,43.52]],"id":38833999}],"con":true,"img":false}]}
{"op":"mcm","clk":"5322076208","pt":1646316125616,"mc":[{"id":"1.195532855","rc":[{"atb":[[2.48,0],[2.46,28.27]],"id":38833999},{"atl":[[2.86,22]],"id":41064149}],"con":true,"img":false}]}
{"op":"mcm","clk":"5322076222","pt":1646316125721,"mc":[{"id":"1.195532855","rc":[{"atb":[[2.44,39.93]],"id":38833999}],"con":true,"img":false}]}
{"op":"mcm","clk":"5322076234","pt":1646316125822,"mc":[{"id":"1.195532855","rc":[{"atb":[[2.46,13.76]],"id":38833999},{"atl":[[5.1,54.71],[5,10]],"id":42609833},{"atl":[[2.92,100.27],[2.84,22]],"id":41064149}],"con":true,"img":false}]}
{"op":"mcm","clk":"5322076243","pt":1646316125927,"mc":[{"id":"1.195532855","rc":[{"atl":[[2.9,107.15],[2.84,31.86]],"id":41064149}],"con":true,"img":false}]}
{"op":"mcm","clk":"5322076248","pt":1646316126030,"mc":[{"id":"1.195532855","rc":[{"atl":[[5.6,65.26]],"id":38833999},{"atl":[[2.92,0],[2.88,21.28],[2.86,0],[2.9,86.1]],"id":41064149}],"con":true,"img":false}]}
{"op":"mcm","clk":"5322076258","pt":1646316126134,"mc":[{"id":"1.195532855","rc":[{"atl":[[5.5,0]],"id":38833999}],"con":true,"img":false}]}
{"op":"mcm","clk":"5322076272","pt":1646316126310,"mc":[{"id":"1.195532855","rc":[{"atl":[[5.6,43.52],[5.7,23.78]],"id":38833999}],"con":true,"img":false}]}
{"op":"mcm","clk":"5322076406","pt":1646316128024,"mc":[{"id":"1.195532855","rc":[{"atl":[[5.6,8.7],[5.7,79.27]],"id":38833999}],"con":true,"img":false}]}
{"op":"mcm","clk":"5322076701","pt":1646316130710,"mc":[{"id":"1.195532855","rc":[{"atb":[[2.6,8.91],[2.62,0]],"id":28603686},{"atl":[[5.6,0],[5.5,7.12],[6,0],[6.8,0],[5.9,25.41]],"id":28603686}],"con":true,"img":false}]}
{"op":"mcm","clk":"5322076712","pt":1646316130813,"mc":[{"id":"1.195532855","rc":[{"atb":[[2.56,3.83]],"id":28603686},{"atl":[[5.5,29.34],[5.9,70.07]],"id":28603686}],"con":true,"img":false}]}
{"op":"mcm","clk":"5322076719","pt":1646316130923,"mc":[{"id":"1.195532855","rc":[{"atl":[[5.7,8.51]],"id":28603686},{"atl":[[2.9,138.73],[2.84,9.86]],"id":41064149}],"con":true,"img":false}]}
{"op":"mcm","clk":"5322076730","pt":1646316131022,"mc":[{"id":"1.195532855","rc":[{"atb":[[2.56,0]],"id":28603686}],"con":true,"img":false}]}
{"op":"mcm","clk":"5322076739","pt":1646316131120,"mc":[{"id":"1.195532855","rc":[{"atl":[[2.84,0]],"id":41064149}],"con":true,"img":false}]}
{"op":"mcm","clk":"5322076748","pt":1646316131232,"mc":[{"id":"1.195532855","rc":[{"atb":[[2.6,5],[1.08,50]],"id":28603686},{"atb":[[1.08,50]],"id":38833999},{"atb":[[1.08,50]],"id":42609833},{"atb":[[1.08,50]],"id":42190933},{"atb":[[1.08,50]],"id":41064149},{"atb":[[1.08,50]],"id":36042605}],"con":true,"img":false}]}
{"op":"mcm","clk":"5322076755","pt":1646316131328,"mc":[{"id":"1.195532855","rc":[{"atl":[[2.86,9.86]],"id":41064149}],"con":true,"img":false}]}
{"op":"mcm","clk":"5322076765","pt":1646316131431,"mc":[{"id":"1.195532855","rc":[{"atl":[[2.9,86.1],[2.94,103.1]],"id":41064149}],"con":true,"img":false}]}
{"op":"mcm","clk":"5322076835","pt":1646316132219,"mc":[{"id":"1.195532855","rc":[{"atl":[[2.88,0],[2.9,107.15]],"id":41064149}],"con":true,"img":false}]}
{"op":"mcm","clk":"5322076877","pt":1646316132734,"mc":[{"id":"1.195532855","rc":[{"atb":[[2.48,13.76],[2.46,0]],"id":38833999}],"con":true,"img":false}]}
{"op":"mcm","clk":"5322076899","pt":1646316132943,"mc":[{"id":"1.195532855","rc":[{"atl":[[2.9,159.78],[2.94,51.55]],"id":41064149}],"con":true,"img":false}]}
{"op":"mcm","clk":"5322076911","pt":1646316133013,"mc":[{"id":"1.195532855","rc":[{"atl":[[2.9,73.68],[2.94,160.36]],"id":41064149}],"con":true,"img":false}]}
{"op":"mcm","clk":"5322077132","pt":1646316136031,"mc":[{"id":"1.195532855","rc":[{"atl":[[5.5,7.12],[5.9,90.48]],"id":28603686}],"con":true,"img":false}]}
{"op":"mcm","clk":"5322077285","pt":1646316138028,"mc":[{"id":"1.195532855","rc":[{"atl":[[2.94,211.91]],"id":41064149}],"con":true,"img":false}]}
{"op":"mcm","clk":"5322077293","pt":1646316138124,"mc":[{"id":"1.195532855","rc":[{"atl":[[2.9,21.05]],"id":41064149}],"con":true,"img":false}]}
{"op":"mcm","clk":"5322078052","pt":1646316147431,"mc":[{"id":"1.195532855","rc":[{"atb":[[2.4,46.69],[2.38,0]],"id":42609833}],"con":true,"img":false}]}
{"op":"mcm","clk":"5322078060","pt":1646316147533,"mc":[{"id":"1.195532855","rc":[{"atb":[[2.36,7.64]],"id":42609833}],"con":true,"img":false}]}
{"op":"mcm","clk":"5322078078","pt":1646316147748,"mc":[{"id":"1.195532855","rc":[{"atb":[[2.36,0]],"id":42609833}],"con":true,"img":false}]}
{"op":"mcm","clk":"5322078179","pt":1646316148846,"mc":[{"id":"1.195532855","rc":[{"atb":[[1.69,5.4]],"id":41064149}],"con":true,"img":false}]}
{"op":"mcm","clk":"5322078216","pt":1646316149259,"mc":[{"id":"1.195532855","rc":[{"atb":[[1.69,0]],"id":41064149}],"con":true,"img":false}]}
{"op":"mcm","clk":"5322078668","pt":1646316154553,"mc":[{"id":"1.195532855","rc":[{"atb":[[2.4,15.92],[2.42,46.69]],"id":42609833}],"con":true,"img":false}]}
{"op":"mcm","clk":"5322078696","pt":1646316154758,"mc":[{"id":"1.195532855","rc":[{"atb":[[2.4,0],[2.42,69.04]],"id":42609833}],"con":true,"img":false}]}
{"op":"mcm","clk":"5322078949","pt":1646316157734,"mc":[{"id":"1.195532855","rc":[{"atl":[[8.2,5],[7.4,2.5],[7.6,7.92],[8.4,13.51]],"id":36042605}],"con":true,"img":false}]}
{"op":"mcm","clk":"5322078958","pt":1646316157841,"mc":[{"id":"1.195532855","rc":[{"atl":[[5.5,4.24]],"id":38833999},{"atl":[[8,5.71],[7.2,5.62],[7.4,10.42],[7.8,36.84]],"id":36042605}],"con":true,"img":false}]}
{"op":"mcm","clk":"5322078966","pt":1646316157945,"mc":[{"id":"1.195532855","rc":[{"atl":[[5.6,51.16],[5.7,2.5],[5.4,17.41]],"id":38833999},{"atl":[[8.6,4.12],[7.6,6.06]],"id":36042605}],"con":true,"img":false}]}
{"op":"mcm","clk":"5322078972","pt":1646316158073,"mc":[{"id":"1.195532855","rc":[{"atl":[[8,0],[8.6,0]],"id":36042605}],"con":true,"img":false}]}
{"op":"mcm","clk":"5322078981","pt":1646316158126,"mc":[{"id":"1.195532855","rc":[{"atl":[[5.8,25.38]],"id":38833999}],"con":true,"img":false}]}
{"op":"mcm","clk":"5322079019","pt":1646316158647,"mc":[{"id":"1.195532855","rc":[{"atl":[[5.8,20.83]],"id":38833999}],"con":true,"img":false}]}
{"op":"mcm","clk":"5322079108","pt":1646316159645,"mc":[{"id":"1.195532855","rc":[{"atl":[[2.92,7.9]],"id":41064149}],"con":true,"img":false}]}
{"op":"mcm","clk":"5322079121","pt":1646316159753,"mc":[{"id":"1.195532855","rc":[{"atb":[[1.73,14.88]],"id":41064149},{"atl":[[2.88,8.26],[2.86,23.37]],"id":41064149}],"con":true,"img":false}]}
{"op":"mcm","clk":"5322079127","pt":1646316159853,"mc":[{"id":"1.195532855","rc":[{"atl":[[2.84,13.32],[2.94,103.1],[2.92,41.72],[2.86,9.86]],"id":41064149}],"con":true,"img":false}]}
{"op":"mcm","clk":"5322079135","pt":1646316159961,"mc":[{"id":"1.195532855","rc":[{"atb":[[1.73,47.23],[1.7,44.34]],"id":41064149},{"atl":[[2.94,51.55],[2.86,30.91]],"id":41064149}],"con":true,"img":false}]}
{"op":"mcm","clk":"5322079146","pt":1646316160060,"mc":[{"id":"1.195532855","rc":[{"atl":[[2.86,21.05]],"id":41064149}],"con":true,"img":false}]}
{"op":"mcm","clk":"5322079158","pt":1646316160165,"mc":[{"id":"1.195532855","rc":[{"atb":[[1.73,32.35]],"id":41064149}],"con":true,"img":false}]}
{"op":"mcm","clk":"5322079181","pt":1646316160432,"mc":[{"id":"1.195532855","rc":[{"atl":[[2.88,29.54]],"id":41064149}],"con":true,"img":false}]}
{"op":"mcm","clk":"5322079190","pt":1646316160539,"mc":[{"id":"1.195532855","rc":[{"atl":[[2.9,0]],"id":41064149}],"con":true,"img":false}]}
{"op":"mcm","clk":"5322079262","pt":1646316161366,"mc":[{"id":"1.195532855","rc":[{"atb":[[2.4,6.25],[2.42,22.35],[2.44,69.04]],"id":42609833}],"con":true,"img":false}]}
{"op":"mcm","clk":"5322079300","pt":1646316161743,"mc":[{"id":"1.195532855","rc":[{"atb":[[2.4,0]],"id":42609833}],"con":true,"img":false}]}
{"op":"mcm","clk":"5322079432","pt":1646316162944,"mc":[{"id":"1.195532855","rc":[{"atl":[[7.6,21.21]],"id":36042605}],"con":true,"img":false}]}
{"op":"mcm","clk":"5322079441","pt":1646316163041,"mc":[{"id":"1.195532855","rc":[{"atl":[[7.4,2.5]],"id":36042605}],"con":true,"img":false}]}
{"op":"mcm","clk":"5322079688","pt":1646316166166,"mc":[{"id":"1.195532855","rc":[{"atl":[[5.5,0]],"id":38833999}],"con":true,"img":false}]}
{"op":"mcm","clk":"5322079698","pt":1646316166405,"mc":[{"id":"1.195532855","rc":[{"atl":[[5.6,8.7],[5.7,84.07],[5.4,8.71]],"id":38833999}],"con":true,"img":false}]}
{"op":"mcm","clk":"5322079769","pt":1646316167152,"mc":[{"id":"1.195532855","rc":[{"atl":[[5.3,4.44]],"id":38833999}],"con":true,"img":false}]}
{"op":"mcm","clk":"5322079778","pt":1646316167258,"mc":[{"id":"1.195532855","rc":[{"atl":[[5.2,13.06]],"id":38833999}],"con":true,"img":false}]}
{"op":"mcm","clk":"5322079793","pt":1646316167357,"mc":[{"id":"1.195532855","rc":[{"atl":[[5.6,0],[5.5,8.89]],"id":38833999}],"con":true,"img":false}]}
{"op":"mcm","clk":"5322079805","pt":1646316167470,"mc":[{"id":"1.195532855","rc":[{"atl":[[5.4,0]],"id":38833999}],"con":true,"img":false}]}
{"op":"mcm","clk":"5322079816","pt":1646316167570,"mc":[{"id":"1.195532855","rc":[{"atl":[[5.7,88.38]],"id":38833999},{"atl":[[2.88,21.28]],"id":41064149}],"con":true,"img":false}]}
{"op":"mcm","clk":"5322079840","pt":1646316167772,"mc":[{"id":"1.195532855","rc":[{"atl":[[2.88,63],[2.86,0]],"id":41064149}],"con":true,"img":false}]}
{"op":"mcm","clk":"5322079849","pt":1646316167877,"mc":[{"id":"1.195532855","rc":[{"atl":[[2.84,15.84]],"id":41064149}],"con":true,"img":false}]}
{"op":"mcm","clk":"5322079862","pt":1646316167984,"mc":[{"id":"1.195532855","rc":[{"atl":[[5.7,84.07]],"id":38833999}],"con":true,"img":false}]}
{"op":"mcm","clk":"5322079874","pt":1646316168044,"mc":[{"id":"1.195532855","rc":[{"atb":[[2.46,24.5],[2.44,0]],"id":42609833}],"con":true,"img":false}]}
{"op":"mcm","clk":"5322079885","pt":1646316168149,"mc":[{"id":"1.195532855","rc":[{"atl":[[5.5,0],[5.4,9.09]],"id":38833999}],"con":true,"img":false}]}
{"op":"mcm","clk":"5322079899","pt":1646316168254,"mc":[{"id":"1.195532855","rc":[{"atl":[[5.3,0]],"id":38833999},{"atl":[[3.45,0],[3.85,0],[3.65,0]],"id":41064149}],"con":true,"img":false}]}
{"op":"mcm","clk":"5322079911","pt":1646316168363,"mc":[{"id":"1.195532855","rc":[{"atl":[[5.2,0]],"id":38833999},{"atl":[[8,14.29]],"id":36042605}],"con":true,"img":false}]}
{"op":"mcm","clk":"5322079922","pt":1646316168464,"mc":[{"id":"1.195532855","rc":[{"atl":[[2.84,13.32]],"id":41064149}],"con":true,"img":false}]}
{"op":"mcm","clk":"5322079931","pt":1646316168568,"mc":[{"id":"1.195532855","rc":[{"atl":[[5.3,14.96]],"id":38833999}],"con":true,"img":false}]}
{"op":"mcm","clk":"5322079948","pt":1646316168785,"mc":[{"id":"1.195532855","rc":[{"atl":[[5.2,3.53]],"id":38833999},{"atl":[[2.82,8.51]],"id":41064149}],"con":true,"img":false}]}
{"op":"mcm","clk":"5322079983","pt":1646316169045,"mc":[{"id":"1.195532855","rc":[{"atl":[[2.88,41.72],[2.86,21.51]],"id":41064149},{"atl":[[9.2,0]],"id":36042605}],"con":true,"img":false}]}
{"op":"mcm","clk":"5322080010","pt":1646316169355,"mc":[{"id":"1.195532855","rc":[{"atl":[[5.2,0]],"id":38833999}],"con":true,"img":false}]}
{"op":"mcm","clk":"5322080101","pt":1646316170236,"mc":[{"id":"1.195532855","rc":[{"atb":[[2.62,10.78]],"id":28603686},{"atb":[[2.5,24.62],[2.48,0]],"id":38833999},{"atl":[[5.6,2.5],[5.5,8.89],[5.7,81.57]],"id":38833999}],"con":true,"img":false}]}
{"op":"mcm","clk":"5322080112","pt":1646316170339,"mc":[{"id":"1.195532855","rc":[{"atb":[[2.6,24.11],[2.58,0]],"id":28603686},{"atb":[[2.36,35.06],[2.52,15.13],[2.44,2.5]],"id":38833999},{"atl":[[5.4,0]],"id":38833999}],"con":true,"img":false}]}
{"op":"mcm","clk":"5322080122","pt":1646316170446,"mc":[{"id":"1.195532855","rc":[{"atb":[[2.58,4.45]],"id":28603686},{"atb":[[2.46,5.89]],"id":38833999}],"con":true,"img":false}]}
{"op":"mcm","clk":"5322080134","pt":1646316170550,"mc":[{"id":"1.195532855","rc":[{"atb":[[2.58,7.86]],"id":28603686},{"atb":[[2.5,15.91]],"id":38833999}],"con":true,"img":false}]}
{"op":"mcm","clk":"5322080143","pt":1646316170653,"mc":[{"id":"1.195532855","rc":[{"atb":[[2.58,3.41]],"id":28603686},{"atb":[[2.46,0]],"id":38833999},{"atl":[[5.3,0]],"id":38833999}],"con":true,"img":false}]}
{"op":"mcm","clk":"5322080161","pt":1646316170869,"mc":[{"id":"1.195532855","rc":[{"atl":[[5.4,8.54]],"id":38833999}],"con":true,"img":false}]}
{"op":"mcm","clk":"5322080169","pt":1646316170967,"mc":[{"id":"1.195532855","rc":[{"atb":[[2.58,2.15]],"id":38833999}],"con":true,"img":false}]}
{"op":"mcm","clk":"5322080175","pt":1646316171068,"mc":[{"id":"1.195532855","rc":[{"atb":[[2.58,0]],"id":28603686},{"atb":[[2.5,13.76]],"id":38833999}],"con":true,"img":false}]}
{"op":"mcm","clk":"5322080272","pt":1646316172181,"mc":[{"id":"1.195532855","rc":[{"atl":[[5.6,11.2],[5.5,0]],"id":38833999}],"con":true,"img":false}]}
{"op":"mcm","clk":"5322080286","pt":1646316172280,"mc":[{"id":"1.195532855","rc":[{"atl":[[7.6,42.45],[7.8,11]],"id":36042605}],"con":true,"img":false}]}
{"op":"mcm","clk":"5322080300","pt":1646316172384,"mc":[{"id":"1.195532855","rc":[{"atl":[[5.6,46.06],[5.7,21.28]],"id":38833999}],"con":true,"img":false}]}
{"op":"mcm","clk":"5322080362","pt":1646316173075,"mc":[{"id":"1.195532855","rc":[{"atl":[[5.6,11.2],[5.7,79.08]],"id":38833999}],"con":true,"img":false}]}
{"op":"mcm","clk":"5322080478","pt":1646316174173,"mc":[{"id":"1.195532855","rc":[{"atl":[[2.8,14.63],[2.92,0],[2.86,70.15]],"id":41064149}],"con":true,"img":false}]}
{"op":"mcm","clk":"5322080494","pt":1646316174382,"mc":[{"id":"1.195532855","rc":[{"atl":[[2.8,27.95],[2.84,0]],"id":41064149}],"con":true,"img":false}]}
{"op":"mcm","clk":"5322080501","pt":1646316174487,"mc":[{"id":"1.195532855","rc":[{"atl":[[2.88,0]],"id":41064149}],"con":true,"img":false}]}
{"op":"mcm","clk":"5322080509","pt":1646316174591,"mc":[{"id":"1.195532855","rc":[{"atl":[[2.86,48.64],[2.84,21.74]],"id":41064149}],"con":true,"img":false}]}
{"op":"mcm","clk":"5322080521","pt":1646316174754,"mc":[{"id":"1.195532855","rc":[{"atb":[[2.46,2.15],[2.48,28.57]],"id":42609833}],"con":true,"img":false}]}
{"op":"mcm","clk":"5322080531","pt":1646316174857,"mc":[{"id":"1.195532855","rc":[{"atb":[[2.5,14.61]],"id":42609833}],"con":true,"img":false}]}
{"op":"mcm","clk":"5322080542","pt":1646316174961,"mc":[{"id":"1.195532855","rc":[{"atb":[[2.42,0],[2.46,32.93]],"id":42609833}],"con":true,"img":false}]}
{"op":"mcm","clk":"5322080549","pt":1646316175068,"mc":[{"id":"1.195532855","rc":[{"atb":[[2.48,24.34]],"id":42609833}],"con":true,"img":false}]}
{"op":"mcm","clk":"5322080558","pt":1646316175169,"mc":[{"id":"1.195532855","rc":[{"atb":[[2.44,6.68]],"id":38833999}],"con":true,"img":false}]}
{"op":"mcm","clk":"5322080574","pt":1646316175372,"mc":[{"id":"1.195532855","rc":[{"atb":[[2.42,70.42]],"id":42609833}],"con":true,"img":false}]}
{"op":"mcm","clk":"5322080584","pt":1646316175476,"mc":[{"id":"1.195532855","rc":[{"atb":[[2.48,1.99]],"id":42609833}],"con":true,"img":false}]}
{"op":"mcm","clk":"5322080599","pt":1646316175692,"mc":[{"id":"1.195532855","rc":[{"atb":[[2.48,0]],"id":42609833}],"con":true,"img":false}]}
{"op":"mcm","clk":"5322080606","pt":1646316175748,"mc":[{"id":"1.195532855","rc":[{"atb":[[2.44,2.5]],"id":38833999},{"atb":[[2.52,1.99]],"id":42609833}],"con":true,"img":false}]}
{"op":"mcm","clk":"5322080632","pt":1646316176166,"mc":[{"id":"1.195532855","rc":[{"atb":[[2.38,4.14]],"id":42609833}],"con":true,"img":false}]}
{"op":"mcm","clk":"5322080674","pt":1646316176693,"mc":[{"id":"1.195532855","rc":[{"spn":3.99,"spf":"NaN","id":38833999},{"atb":[[2.38,0]],"id":42609833},{"spn":3.66,"spf":"NaN","id":42609833},{"spn":5.12,"spf":"NaN","id":36042605}],"con":true,"img":false}]}
{"op":"mcm","clk":"5322080824","pt":1646316178575,"mc":[{"id":"1.195532855","rc":[{"atl":[[8.4,20.27]],"id":36042605}],"con":true,"img":false}]}
{"op":"mcm","clk":"5322080960","pt":1646316180405,"mc":[{"id":"1.195532855","rc":[{"atb":[[2.52,13.48]],"id":38833999},{"atb":[[2.5,12.96]],"id":42609833}],"con":true,"img":false}]}
{"op":"mcm","clk":"5322080970","pt":1646316180462,"mc":[{"id":"1.195532855","rc":[{"atb":[[2.42,0],[2.44,69.44]],"id":42609833}],"con":true,"img":false}]}
{"op":"mcm","clk":"5322080977","pt":1646316180570,"mc":[{"id":"1.195532855","rc":[{"atb":[[2.6,1.65]],"id":38833999},{"atb":[[2.54,1.65]],"id":42609833}],"con":true,"img":false}]}
{"op":"mcm","clk":"5322081048","pt":1646316181470,"mc":[{"id":"1.195532855","rc":[{"atb":[[2.56,2.15],[2.46,30.78]],"id":42609833}],"con":true,"img":false}]}
{"op":"mcm","clk":"5322081145","pt":1646316182682,"mc":[{"id":"1.195532855","rc":[{"atb":[[2.52,0]],"id":42609833}],"con":true,"img":false}]}
{"op":"mcm","clk":"5322081154","pt":1646316182778,"mc":[{"id":"1.195532855","rc":[{"atb":[[2.58,1.99]],"id":42609833}],"con":true,"img":false}]}
{"op":"mcm","clk":"5322081302","pt":1646316184501,"mc":[{"id":"1.195532855","rc":[{"atb":[[2.5,44.61],[2.58,16.95],[2.36,5]],"id":38833999}],"con":true,"img":false}]}
{"op":"mcm","clk":"5322081310","pt":1646316184608,"mc":[{"id":"1.195532855","rc":[{"atb":[[2.52,0]],"id":38833999}],"con":true,"img":false}]}
{"op":"mcm","clk":"5322081318","pt":1646316184709,"mc":[{"id":"1.195532855","rc":[{"atl":[[2.88,53.19]],"id":41064149}],"con":true,"img":false}]}
{"op":"mcm","clk":"5322081487","pt":1646316186799,"mc":[{"id":"1.195532855","rc":[{"atb":[[1.62,5.6]],"id":41064149}],"con":true,"img":false}]}
{"op":"mcm","clk":"5322081530","pt":1646316187315,"mc":[{"id":"1.195532855","rc":[{"atb":[[1.62,0]],"id":41064149}],"con":true,"img":false}]}
{"op":"mcm","clk":"5322081601","pt":1646316188206,"mc":[{"id":"1.195532855","rc":[{"atl":[[2.86,0],[2.84,87.22]],"id":41064149}],"con":true,"img":false}]}
{"op":"mcm","clk":"5322081613","pt":1646316188411,"mc":[{"id":"1.195532855","rc":[{"atl":[[2.86,24.39]],"id":41064149}],"con":true,"img":false}]}
{"op":"mcm","clk":"5322081630","pt":1646316188618,"mc":[{"id":"1.195532855","rc":[{"atl":[[2.86,0]],"id":41064149},{"atl":[[8.8,32.05]],"id":36042605}],"con":true,"img":false}]}
{"op":"mcm","clk":"5322081647","pt":1646316188885,"mc":[{"id":"1.195532855","rc":[{"atb":[[2.56,9.22]],"id":42609833}],"con":true,"img":false}]}
{"op":"mcm","clk":"5322081664","pt":1646316189085,"mc":[{"id":"1.195532855","rc":[{"atb":[[2.5,0]],"id":42609833}],"con":true,"img":false}]}
{"op":"mcm","clk":"5322081669","pt":1646316189190,"mc":[{"id":"1.195532855","rc":[{"atb":[[2.46,0],[2.44,124]],"id":42609833}],"con":true,"img":false}]}
{"op":"mcm","clk":"5322081684","pt":1646316189402,"mc":[{"id":"1.195532855","rc":[{"atb":[[2.54,0]],"id":42609833}],"con":true,"img":false}]}
{"op":"mcm","clk":"5322081703","pt":1646316189609,"mc":[{"id":"1.195532855","rc":[{"atb":[[2.6,1.65]],"id":42609833}],"con":true,"img":false}]}
{"op":"mcm","clk":"5322081800","pt":1646316190801,"mc":[{"id":"1.195532855","rc":[{"atb":[[2.5,6]],"id":42609833}],"con":true,"img":false}]}
{"op":"mcm","clk":"5322081813","pt":1646316191008,"mc":[{"id":"1.195532855","rc":[{"atb":[[2.5,13.76],[2.44,39.76]],"id":38833999}],"con":true,"img":false}]}
{"op":"mcm","clk":"5322081829","pt":1646316191215,"mc":[{"id":"1.195532855","rc":[{"atb":[[2.5,0]],"id":42609833}],"con":true,"img":false}]}
{"op":"mcm","clk":"5322082069","pt":1646316194608,"mc":[{"id":"1.195532855","rc":[{"atl":[[2.92,78.12]],"id":41064149}],"con":true,"img":false}]}
{"op":"mcm","clk":"5322082076","pt":1646316194712,"mc":[{"id":"1.195532855","rc":[{"atl":[[2.98,0],[2.94,0],[3.05,0]],"id":41064149}],"con":true,"img":false}]}
{"op":"mcm","clk":"5322082251","pt":1646316197012,"mc":[{"id":"1.195532855","rc":[{"atl":[[5.9,5.44]],"id":38833999}],"con":true,"img":false}]}
{"op":"mcm","clk":"5322082293","pt":1646316197519,"mc":[{"id":"1.195532855","rc":[{"atl":[[5.9,0]],"id":38833999}],"con":true,"img":false}]}
{"op":"mcm","clk":"5322082522","pt":1646316200529,"mc":[{"id":"1.195532855","rc":[{"atl":[[2.82,0]],"id":41064149}],"con":true,"img":false}]}
{"op":"mcm","clk":"5322082538","pt":1646316200743,"mc":[{"id":"1.195532855","rc":[{"atb":[[2.5,10],[2.52,14.44]],"id":42190933},{"atb":[[1.73,50.21]],"id":41064149},{"atl":[[2.8,14.63],[2.88,226.98],[2.84,35.48]],"id":41064149}],"con":true,"img":false}]}
{"op":"mcm","clk":"5322082550","pt":1646316200806,"mc":[{"id":"1.195532855","rc":[{"atb":[[2.5,14.91]],"id":42190933}],"con":true,"img":false}]}
{"op":"mcm","clk":"5322082558","pt":1646316200916,"mc":[{"id":"1.195532855","rc":[{"atb":[[2.5,10]],"id":42190933},{"atb":[[1.73,32.35]],"id":41064149}],"con":true,"img":false}]}
{"op":"mcm","clk":"5322082575","pt":1646316201112,"mc":[{"id":"1.195532855","rc":[{"atl":[[2.84,21.74]],"id":41064149}],"con":true,"img":false}]}
{"op":"mcm","clk":"5322082708","pt":1646316202617,"mc":[{"id":"1.195532855","rc":[{"atl":[[2.76,8.77]],"id":41064149}],"con":true,"img":false}]}
{"op":"mcm","clk":"5322082717","pt":1646316202721,"mc":[{"id":"1.195532855","rc":[{"atb":[[2.58,14.37]],"id":42609833},{"atl":[[2.88,106.38],[2.74,14.83],[2.84,73]],"id":41064149}],"con":true,"img":false}]}
{"op":"mcm","clk":"5322082730","pt":1646316202923,"mc":[{"id":"1.195532855","rc":[{"atb":[[2.56,2.15]],"id":42609833},{"atl":[[2.8,0]],"id":41064149}],"con":true,"img":false}]}
{"op":"mcm","clk":"5322082779","pt":1646316203602,"mc":[{"id":"1.195532855","rc":[{"atb":[[2.56,0],[2.64,2.15]],"id":42609833}],"con":true,"img":false}]}
{"op":"mcm","clk":"5322082795","pt":1646316203818,"mc":[{"id":"1.195532855","rc":[{"atb":[[2.58,12.38]],"id":42609833}],"con":true,"img":false}]}
{"op":"mcm","clk":"5322082804","pt":1646316203919,"mc":[{"id":"1.195532855","rc":[{"atb":[[2.66,1.99]],"id":42609833}],"con":true,"img":false}]}
{"op":"mcm","clk":"5322082837","pt":1646316204333,"mc":[{"id":"1.195532855","rc":[{"atl":[[2.78,22.47]],"id":41064149}],"con":true,"img":false}]}
{"op":"mcm","clk":"5322083046","pt":1646316207141,"mc":[{"id":"1.195532855","rc":[{"atl":[[2.88,53.19],[2.74,29.66]],"id":41064149}],"con":true,"img":false}]}
{"op":"mcm","clk":"5322083066","pt":1646316207450,"mc":[{"id":"1.195532855","rc":[{"atb":[[2.6,0]],"id":42609833}],"con":true,"img":false}]}
{"op":"mcm","clk":"5322083087","pt":1646316207627,"mc":[{"id":"1.195532855","rc":[{"atb":[[2.68,1.65]],"id":42609833}],"con":true,"img":false}]}
{"op":"mcm","clk":"5322083107","pt":1646316207834,"mc":[{"id":"1.195532855","rc":[{"atb":[[2.44,69.44],[2.58,33.98]],"id":42609833}],"con":true,"img":false}]}
{"op":"mcm","clk":"5322083686","pt":1646316214236,"mc":[{"id":"1.195532855","rc":[{"atl":[[2.84,21.74],[2.78,89.41]],"id":41064149}],"con":true,"img":false}]}
{"op":"mcm","clk":"5322083852","pt":1646316216259,"mc":[{"id":"1.195532855","rc":[{"atb":[[2.66,9.06]],"id":42609833}],"con":true,"img":false}]}
{"op":"mcm","clk":"5322083860","pt":1646316216330,"mc":[{"id":"1.195532855","rc":[{"atl":[[2.82,12.76]],"id":41064149}],"con":true,"img":false}]}
{"op":"mcm","clk":"5322083868","pt":1646316216427,"mc":[{"id":"1.195532855","rc":[{"atb":[[2.58,21.6]],"id":42609833}],"con":true,"img":false}]}
{"op":"mcm","clk":"5322083888","pt":1646316216639,"mc":[{"id":"1.195532855","rc":[{"atl":[[2.82,0]],"id":41064149}],"con":true,"img":false}]}
{"op":"mcm","clk":"5322083964","pt":1646316217728,"mc":[{"id":"1.195532855","rc":[{"atb":[[2.56,5.47]],"id":42609833}],"con":true,"img":false}]}
{"op":"mcm","clk":"5322083999","pt":1646316218246,"mc":[{"id":"1.195532855","rc":[{"atb":[[2.56,0]],"id":42609833}],"con":true,"img":false}]}
{"op":"mcm","clk":"5322084651","pt":1646316226284,"mc":[{"id":"1.195532855","rc":[{"atb":[[2.6,42.35],[2.62,0]],"id":28603686},{"atb":[[2.5,0],[2.52,24.44]],"id":42190933},{"atb":[[1.73,35.48]],"id":41064149},{"atb":[[3.1,2.5],[3,0],[2.84,25.52],[2.92,4.54],[2.88,10],[2.96,5]],"id":36042605}],"con":true,"img":false}]}
{"op":"mcm","clk":"5322084664","pt":1646316226460,"mc":[{"id":"1.195532855","rc":[{"atb":[[2.54,26.61],[2.6,26.64]],"id":28603686},{"atb":[[1.73,32.35]],"id":41064149},{"atb":[[2.84,0],[2.92,0]],"id":36042605}],"con":true,"img":false}]}
{"op":"mcm","clk":"5322084678","pt":1646316226661,"mc":[{"id":"1.195532855","rc":[{"atb":[[2.6,18.24]],"id":28603686},{"atb":[[2.88,25.35]],"id":36042605}],"con":true,"img":false}]}
{"op":"mcm","clk":"5322084749","pt":1646316227353,"mc":[{"id":"1.195532855","rc":[{"atb":[[2.26,86.61]],"id":42609833}],"con":true,"img":false}]}
{"op":"mcm","clk":"5322084768","pt":1646316227566,"mc":[{"id":"1.195532855","rc":[{"atb":[[2.26,79.37]],"id":42609833}],"con":true,"img":false}]}
{"op":"mcm","clk":"5322084779","pt":1646316227660,"mc":[{"id":"1.195532855","rc":[{"atl":[[2.8,10.12]],"id":41064149}],"con":true,"img":false}]}
{"op":"mcm","clk":"5322084790","pt":1646316227771,"mc":[{"id":"1.195532855","rc":[{"atl":[[5.6,8.7],[5.5,2.5],[5.9,5.21]],"id":38833999}],"con":true,"img":false}]}
{"op":"mcm","clk":"5322084800","pt":1646316227876,"mc":[{"id":"1.195532855","rc":[{"atl":[[5.3,18.6]],"id":38833999}],"con":true,"img":false}]}
{"op":"mcm","clk":"5322084808","pt":1646316227939,"mc":[{"id":"1.195532855","rc":[{"atl":[[5.6,53.62],[5.7,21.28],[5.9,0]],"id":38833999},{"atl":[[2.8,0]],"id":41064149}],"con":true,"img":false}]}
{"op":"mcm","clk":"5322084815","pt":1646316228038,"mc":[{"id":"1.195532855","rc":[{"atl":[[5.5,19.58]],"id":38833999}],"con":true,"img":false}]}
{"op":"mcm","clk":"5322084824","pt":1646316228148,"mc":[{"id":"1.195532855","rc":[{"atl":[[5.7,0],[5.4,0]],"id":38833999}],"con":true,"img":false}]}
{"op":"mcm","clk":"5322084839","pt":1646316228359,"mc":[{"id":"1.195532855","rc":[{"atl":[[5.6,75.36],[5.5,2.5],[5.7,9.14]],"id":38833999}],"con":true,"img":false}]}
{"op":"mcm","clk":"5322084865","pt":1646316228657,"mc":[{"id":"1.195532855","rc":[{"atl":[[5.7,0]],"id":38833999}],"con":true,"img":false}]}
{"op":"mcm","clk":"5322084895","pt":1646316228970,"mc":[{"id":"1.195532855","rc":[{"atl":[[5.5,11.39]],"id":38833999}],"con":true,"img":false}]}
{"op":"mcm","clk":"5322084909","pt":1646316229128,"mc":[{"id":"1.195532855","rc":[{"atl":[[5.6,66.66]],"id":38833999}],"con":true,"img":false}]}
{"op":"mcm","clk":"5322085301","pt":1646316234352,"mc":[{"id":"1.195532855","rc":[{"atb":[[3.05,0]],"id":36042605}],"con":true,"img":false}]}
{"op":"mcm","clk":"5322085323","pt":1646316234561,"mc":[{"id":"1.195532855","rc":[{"atb":[[3.15,1.65]],"id":36042605}],"con":true,"img":false}]}
{"op":"mcm","clk":"5322085350","pt":1646316234838,"mc":[{"id":"1.195532855","rc":[{"atb":[[2.6,0],[2.58,18.24]],"id":28603686},{"atb":[[2.5,0],[2.34,50.7],[2.88,10]],"id":36042605}],"con":true,"img":false}]}
{"op":"mcm","clk":"5322085405","pt":1646316235561,"mc":[{"id":"1.195532855","rc":[{"atb":[[2.58,25.06]],"id":28603686}],"con":true,"img":false}]}
{"op":"mcm","clk":"5322085432","pt":1646316235936,"mc":[{"id":"1.195532855","rc":[{"atb":[[2.58,18.24]],"id":28603686}],"con":true,"img":false}]}
{"op":"mcm","clk":"5322085466","pt":1646316236353,"mc":[{"id":"1.195532855","rc":[{"atl":[[2.76,0]],"id":41064149}],"con":true,"img":false}]}
{"op":"mcm","clk":"5322085473","pt":1646316236459,"mc":[{"id":"1.195532855","rc":[{"atl":[[2.74,14.83],[2.84,178.89],[2.78,22.47]],"id":41064149}],"con":true,"img":false}]}
{"op":"mcm","clk":"5322085578","pt":1646316237865,"mc":[{"id":"1.195532855","rc":[{"spn":3.95,"spf":"NaN","id":38833999},{"spn":3.74,"spf":"NaN","id":42609833},{"atl":[[2.72,9.06]],"id":41064149},{"spn":5.17,"spf":"NaN","id":36042605}],"con":true,"img":false}]}
{"op":"mcm","clk":"5322085585","pt":1646316237969,"mc":[{"id":"1.195532855","rc":[{"atl":[[2.7,15.05]],"id":41064149}],"con":true,"img":false}]}
{"op":"mcm","clk":"5322085590","pt":1646316238071,"mc":[{"id":"1.195532855","rc":[{"atl":[[2.84,124.54],[2.7,29.88]],"id":41064149}],"con":true,"img":false}]}
{"op":"mcm","clk":"5322085601","pt":1646316238425,"mc":[{"id":"1.195532855","rc":[{"atl":[[2.74,0]],"id":41064149}],"con":true,"img":false}]}
{"op":"mcm","clk":"5322085695","pt":1646316239686,"mc":[{"id":"1.195532855","rc":[{"atb":[[2.88,23.28]],"id":36042605}],"con":true,"img":false}]}
{"op":"mcm","clk":"5322085852","pt":1646316241882,"mc":[{"id":"1.195532855","rc":[{"atl":[[2.8,9.36]],"id":41064149}],"con":true,"img":false}]}
{"op":"mcm","clk":"5322085901","pt":1646316242673,"mc":[{"id":"1.195532855","rc":[{"atl":[[2.8,0]],"id":41064149}],"con":true,"img":false}]}
{"op":"mcm","clk":"5322086007","pt":1646316244190,"mc":[{"id":"1.195532855","rc":[{"atb":[[1.73,0]],"id":41064149},{"atl":[[2.74,22.99],[2.78,0]],"id":41064149},{"atb":[[2.88,10]],"id":36042605}],"con":true,"img":false}]}
{"op":"mcm","clk":"5322086022","pt":1646316244354,"mc":[{"id":"1.195532855","rc":[{"atb":[[1.72,8.66],[1.7,86.83]],"id":41064149}],"con":true,"img":false}]}
{"op":"mcm","clk":"5322086047","pt":1646316244670,"mc":[{"id":"1.195532855","rc":[{"atb":[[1.72,0]],"id":41064149}],"con":true,"img":false}]}
{"op":"mcm","clk":"5322086461","pt":1646316249268,"mc":[{"id":"1.195532855","rc":[{"atl":[[2.74,90.97],[2.84,21.74]],"id":41064149}],"con":true,"img":false}]}
{"op":"mcm","clk":"5322086487","pt":1646316249479,"mc":[{"id":"1.195532855","rc":[{"atl":[[5.8,5],[5.5,4.62],[5.9,85.48],[5.4,2.5]],"id":28603686},{"atb":[[2.5,0],[2.48,27.52]],"id":38833999}],"con":true,"img":false}]}
{"op":"mcm","clk":"5322086495","pt":1646316249585,"mc":[{"id":"1.195532855","rc":[{"atl":[[5.3,9.85],[5.7,47.09],[5.9,65.07],[5.4,7.12]],"id":28603686},{"atb":[[2.48,32.26]],"id":38833999}],"con":true,"img":false}]}
{"op":"mcm","clk":"5322086504","pt":1646316249683,"mc":[{"id":"1.195532855","rc":[{"atl":[[6,10.21],[5.7,55.6],[5.9,20.41],[5.4,2.5]],"id":28603686}],"con":true,"img":false}]}
{"op":"mcm","clk":"5322086511","pt":1646316249788,"mc":[{"id":"1.195532855","rc":[{"atl":[[5.5,0]],"id":28603686}],"con":true,"img":false}]}
{"op":"mcm","clk":"5322086520","pt":1646316249891,"mc":[{"id":"1.195532855","rc":[{"atl":[[5.5,12.35],[6,0],[5.7,47.09]],"id":28603686}],"con":true,"img":false}]}
{"op":"mcm","clk":"5322086530","pt":1646316249995,"mc":[{"id":"1.195532855","rc":[{"atb":[[2.48,27.52]],"id":38833999}],"con":true,"img":false}]}
{"op":"mcm","clk":"5322086672","pt":1646316251577,"mc":[{"id":"1.195532855","rc":[{"atl":[[5.5,21.24],[5.7,38.58]],"id":28603686}],"con":true,"img":false}]}
{"op":"mcm","clk":"5322086815","pt":1646316253095,"mc":[{"id":"1.195532855","rc":[{"atl":[[2.78,56.18]],"id":41064149}],"con":true,"img":false}]}
{"op":"mcm","clk":"5322086966","pt":1646316254661,"mc":[{"id":"1.195532855","rc":[{"atl":[[2.8,13.21]],"id":41064149}],"con":true,"img":false}]}
{"op":"mcm","clk":"5322086974","pt":1646316254764,"mc":[{"id":"1.195532855","rc":[{"atl":[[2.8,0]],"id":41064149}],"con":true,"img":false}]}
{"op":"mcm","clk":"5322086984","pt":1646316254865,"mc":[{"id":"1.195532855","rc":[{"atb":[[2.58,0],[2.62,18.24],[2.56,12.18]],"id":28603686},{"atb":[[2.5,11.98],[2.44,0],[2.58,4.65],[2.36,0],[2.52,11.94],[2.46,10]],"id":42190933},{"atl":[[2.92,0],[2.88,0],[2.84,0]],"id":41064149},{"atb":[[2.34,0],[2.56,210.96],[2.88,23.28]],"id":36042605}],"con":true,"img":false}]}
{"op":"mcm","clk":"5322086994","pt":1646316254977,"mc":[{"id":"1.195532855","rc":[{"atb":[[2.56,40.88]],"id":28603686},{"atb":[[2.64,6.61]],"id":42609833}],"con":true,"img":false}]}
{"op":"mcm","clk":"5322087007","pt":1646316255077,"mc":[{"id":"1.195532855","rc":[{"atb":[[2.54,2.5],[2.56,28.7]],"id":28603686}],"con":true,"img":false}]}
{"op":"mcm","clk":"5322087018","pt":1646316255177,"mc":[{"id":"1.195532855","rc":[{"atb":[[2.64,2.15]],"id":42609833},{"atb":[[2.5,4.17]],"id":42190933}],"con":true,"img":false}]}
{"op":"mcm","clk":"5322087026","pt":1646316255282,"mc":[{"id":"1.195532855","rc":[{"atb":[[2.5,0]],"id":42190933}],"con":true,"img":false}]}
{"op":"mcm","clk":"5322087035","pt":1646316255385,"mc":[{"id":"1.195532855","rc":[{"atb":[[2.5,27.52],[2.48,0]],"id":38833999}],"con":true,"img":false}]}
{"op":"mcm","clk":"5322087503","pt":1646316260415,"mc":[{"id":"1.195532855","rc":[{"atl":[[5.7,59.86]],"id":28603686}],"con":true,"img":false}]}
{"op":"mcm","clk":"5322087511","pt":1646316260476,"mc":[{"id":"1.195532855","rc":[{"atl":[[2.72,0]],"id":41064149}],"con":true,"img":false}]}
{"op":"mcm","clk":"5322087524","pt":1646316260581,"mc":[{"id":"1.195532855","rc":[{"atl":[[3.6,5],[2.74,22.99],[3.4,2.5],[3.8,10],[2.78,260.22],[2.7,15.05]],"id":41064149}],"con":true,"img":false}]}
{"op":"mcm","clk":"5322087541","pt":1646316260784,"mc":[{"id":"1.195532855","rc":[{"atl":[[2.7,3.39]],"id":41064149}],"con":true,"img":false}]}
{"op":"mcm","clk":"5322087547","pt":1646316260892,"mc":[{"id":"1.195532855","rc":[{"atl":[[2.72,19.54]],"id":41064149}],"con":true,"img":false}]}
{"op":"mcm","clk":"5322087612","pt":1646316261519,"mc":[{"id":"1.195532855","rc":[{"atl":[[6.6,0]],"id":28603686}],"con":true,"img":false}]}
{"op":"mcm","clk":"5322087645","pt":1646316261792,"mc":[{"id":"1.195532855","rc":[{"atl":[[2.74,84.07]],"id":41064149}],"con":true,"img":false}]}
{"op":"mcm","clk":"5322087652","pt":1646316261891,"mc":[{"id":"1.195532855","rc":[{"atl":[[2.82,82.42],[2.78,112.35]],"id":41064149}],"con":true,"img":false}]}
{"op":"mcm","clk":"5322087675","pt":1646316262198,"mc":[{"id":"1.195532855","rc":[{"atl":[[5.5,79.28],[5.7,21.28]],"id":28603686}],"con":true,"img":false}]}
{"op":"mcm","clk":"5322087693","pt":1646316262406,"mc":[{"id":"1.195532855","rc":[{"atl":[[5.9,25.62]],"id":28603686}],"con":true,"img":false}]}
{"op":"mcm","clk":"5322087710","pt":1646316262571,"mc":[{"id":"1.195532855","rc":[{"atl":[[5.9,20.41]],"id":28603686}],"con":true,"img":false}]}
{"op":"mcm","clk":"5322088009","pt":1646316266318,"mc":[{"id":"1.195532855","rc":[{"atl":[[2.68,19.54]],"id":41064149}],"con":true,"img":false}]}
{"op":"mcm","clk":"5322088017","pt":1646316266379,"mc":[{"id":"1.195532855","rc":[{"atl":[[2.78,56.17]],"id":41064149}],"con":true,"img":false}]}
{"op":"mcm","clk":"5322088022","pt":1646316266483,"mc":[{"id":"1.195532855","rc":[{"atl":[[2.8,6.04]],"id":41064149}],"con":true,"img":false}]}
{"op":"mcm","clk":"5322088032","pt":1646316266591,"mc":[{"id":"1.195532855","rc":[{"atl":[[2.8,0]],"id":41064149}],"con":true,"img":false}]}
{"op":"mcm","clk":"5322088118","pt":1646316267524,"mc":[{"id":"1.195532855","rc":[{"atl":[[2.72,42.8]],"id":41064149}],"con":true,"img":false}]}
{"op":"mcm","clk":"5322088239","pt":1646316268989,"mc":[{"id":"1.195532855","rc":[{"atl":[[5.9,30.61]],"id":28603686}],"con":true,"img":false}]}
{"op":"mcm","clk":"5322088294","pt":1646316269713,"mc":[{"id":"1.195532855","rc":[{"atl":[[2.7,0]],"id":41064149}],"con":true,"img":false}]}
{"op":"mcm","clk":"5322088307","pt":1646316269818,"mc":[{"id":"1.195532855","rc":[{"atl":[[2.74,141.54]],"id":41064149}],"con":true,"img":false}]}
{"op":"mcm","clk":"5322088315","pt":1646316269922,"mc":[{"id":"1.195532855","rc":[{"atl":[[2.68,0]],"id":41064149}],"con":true,"img":false}]}
{"op":"mcm","clk":"5322088326","pt":1646316270024,"mc":[{"id":"1.195532855","rc":[{"atl":[[2.66,2.61],[2.78,206.46]],"id":41064149}],"con":true,"img":false}]}
{"op":"mcm","clk":"5322088334","pt":1646316270129,"mc":[{"id":"1.195532855","rc":[{"atl":[[2.74,80.46]],"id":41064149}],"con":true,"img":false}]}
{"op":"mcm","clk":"5322088344","pt":1646316270191,"mc":[{"id":"1.195532855","rc":[{"atl":[[2.78,56.18]],"id":41064149}],"con":true,"img":false}]}
{"op":"mcm","clk":"5322088376","pt":1646316270602,"mc":[{"id":"1.195532855","rc":[{"atl":[[2.72,19.54],[2.7,23.53]],"id":41064149}],"con":true,"img":false}]}
{"op":"mcm","clk":"5322088400","pt":1646316270961,"mc":[{"id":"1.195532855","rc":[{"atl":[[5.6,3.72]],"id":28603686}],"con":true,"img":false}]}
{"op":"mcm","clk":"5322088540","pt":1646316272525,"mc":[{"id":"1.195532855","rc":[{"atb":[[2.58,18.24],[2.62,0]],"id":28603686}],"con":true,"img":false}]}
{"op":"mcm","clk":"5322088568","pt":1646316272890,"mc":[{"id":"1.195532855","rc":[{"atl":[[2.72,80.62]],"id":41064149}],"con":true,"img":false}]}
{"op":"mcm","clk":"5322088588","pt":1646316273201,"mc":[{"id":"1.195532855","rc":[{"atl":[[2.64,10.21]],"id":41064149}],"con":true,"img":false}]}
{"op":"mcm","clk":"5322088596","pt":1646316273309,"mc":[{"id":"1.195532855","rc":[{"atl":[[2.72,61.08]],"id":41064149}],"con":true,"img":false}]}
{"op":"mcm","clk":"5322088628","pt":1646316273720,"mc":[{"id":"1.195532855","rc":[{"atl":[[2.68,23.81],[2.7,0]],"id":41064149}],"con":true,"img":false}]}
{"op":"mcm","clk":"5322088657","pt":1646316274091,"mc":[{"id":"1.195532855","rc":[{"atl":[[2.72,0],[2.68,66.23]],"id":41064149}],"con":true,"img":false}]}
{"op":"mcm","clk":"5322088718","pt":1646316274919,"mc":[{"id":"1.195532855","rc":[{"atl":[[5.6,8.16]],"id":28603686}],"con":true,"img":false}]}
{"op":"mcm","clk":"5322088757","pt":1646316275404,"mc":[{"id":"1.195532855","rc":[{"atl":[[5.6,3.71]],"id":28603686},{"atl":[[2.74,22.99],[2.66,62.85]],"id":41064149}],"con":true,"img":false}]}
{"op":"mcm","clk":"5322088911","pt":1646316277530,"mc":[{"id":"1.195532855","rc":[{"atl":[[6.2,48.08]],"id":28603686}],"con":true,"img":false}]}
{"op":"mcm","clk":"5322088951","pt":1646316278110,"mc":[{"id":"1.195532855","rc":[{"atb":[[2.5,0],[2.48,33.9]],"id":38833999},{"atb":[[1.73,4.71]],"id":41064149}],"con":true,"img":false}]}
{"op":"mcm","clk":"5322088956","pt":1646316278217,"mc":[{"id":"1.195532855","rc":[{"atb":[[2.48,48.59]],"id":38833999},{"atb":[[1.73,47],[1.7,44.34]],"id":41064149}],"con":true,"img":false}]}
{"op":"mcm","clk":"5322088972","pt":1646316278626,"mc":[{"id":"1.195532855","rc":[{"atb":[[2.48,33.9]],"id":38833999},{"atb":[[1.73,26.51]],"id":41064149},{"atl":[[2.7,4.52]],"id":41064149}],"con":true,"img":false}]}
{"op":"mcm","clk":"5322089008","pt":1646316279208,"mc":[{"id":"1.195532855","rc":[{"atl":[[2.7,0]],"id":41064149}],"con":true,"img":false}]}
{"op":"mcm","clk":"5322089445","pt":1646316284736,"mc":[{"id":"1.195532855","rc":[{"atb":[[2.4,3.32]],"id":42609833}],"con":true,"img":false}]}
{"op":"mcm","clk":"5322089483","pt":1646316285215,"mc":[{"id":"1.195532855","rc":[{"atb":[[2.4,0]],"id":42609833}],"con":true,"img":false}]}
{"op":"mcm","clk":"5322089566","pt":1646316286313,"mc":[{"id":"1.195532855","rc":[{"atb":[[2.64,6.58]],"id":42609833}],"con":true,"img":false}]}
{"op":"mcm","clk":"5322089591","pt":1646316286646,"mc":[{"id":"1.195532855","rc":[{"atb":[[2.64,2.15]],"id":42609833}],"con":true,"img":false}]}
{"op":"mcm","clk":"5322090207","pt":1646316294347,"mc":[{"id":"1.195532855","rc":[{"atl":[[2.66,60.24]],"id":41064149}],"con":true,"img":false}]}
{"op":"mcm","clk":"5322090226","pt":1646316294552,"mc":[{"id":"1.195532855","rc":[{"atl":[[2.68,125.75]],"id":41064149}],"con":true,"img":false}]}
{"op":"mcm","clk":"5322090233","pt":1646316294656,"mc":[{"id":"1.195532855","rc":[{"atl":[[2.64,13.35],[2.66,0]],"id":41064149}],"con":true,"img":false}]}
{"op":"mcm","clk":"5322090252","pt":1646316294818,"mc":[{"id":"1.195532855","rc":[{"atl":[[2.74,95.67],[2.68,83.33]],"id":41064149}],"con":true,"img":false}]}
{"op":"mcm","clk":"5322090262","pt":1646316294918,"mc":[{"id":"1.195532855","rc":[{"atb":[[2.62,2.38]],"id":38833999},{"atb":[[2.64,2.33]],"id":42190933},{"atb":[[1.79,3.56]],"id":41064149},{"atb":[[3.2,3.61]],"id":36042605}],"con":true,"img":false}]}
{"op":"mcm","clk":"5322090269","pt":1646316295083,"mc":[{"id":"1.195532855","rc":[{"atb":[[2.44,2.5],[2.62,23.64],[2.48,80.41]],"id":38833999},{"atb":[[2.52,0],[2.64,7.02]],"id":42190933},{"atb":[[1.73,0],[1.74,41.44]],"id":41064149},{"atb":[[2.88,10],[2.96,16.45]],"id":36042605}],"con":true,"img":false}]}
{"op":"mcm","clk":"5322090278","pt":1646316295125,"mc":[{"id":"1.195532855","rc":[{"atb":[[2.48,83.63]],"id":38833999},{"atb":[[2.6,4.69],[2.58,15.15]],"id":42190933}],"con":true,"img":false}]}
{"op":"mcm","clk":"5322090288","pt":1646316295228,"mc":[{"id":"1.195532855","rc":[{"atb":[[2.58,2.15]],"id":38833999},{"atb":[[2.5,3.84],[2.6,0],[2.66,1.99]],"id":42190933}],"con":true,"img":false}]}
{"op":"mcm","clk":"5322090298","pt":1646316295332,"mc":[{"id":"1.195532855","rc":[{"atb":[[2.48,80.41]],"id":38833999},{"atb":[[2.52,3.1],[2.68,2.25]],"id":42190933}],"con":true,"img":false}]}
{"op":"mcm","clk":"5322090307","pt":1646316295434,"mc":[{"id":"1.195532855","rc":[{"atb":[[2.5,3.06]],"id":42190933}],"con":true,"img":false}]}
{"op":"mcm","clk":"5322090315","pt":1646316295539,"mc":[{"id":"1.195532855","rc":[{"atb":[[2.5,0]],"id":42190933},{"atb":[[1.78,0]],"id":41064149}],"con":true,"img":false}]}
{"op":"mcm","clk":"5322090323","pt":1646316295644,"mc":[{"id":"1.195532855","rc":[{"atb":[[1.8,1.99]],"id":41064149}],"con":true,"img":false}]}
{"op":"mcm","clk":"5322090339","pt":1646316295851,"mc":[{"id":"1.195532855","rc":[{"atb":[[2.52,0]],"id":42190933},{"atb":[[1.81,3.43]],"id":41064149}],"con":true,"img":false}]}
{"op":"mcm","clk":"5322090346","pt":1646316295953,"mc":[{"id":"1.195532855","rc":[{"atb":[[2.66,0]],"id":42190933}],"con":true,"img":false}]}
{"op":"mcm","clk":"5322090354","pt":1646316296057,"mc":[{"id":"1.195532855","rc":[{"atb":[[2.7,1.99]],"id":42190933},{"atb":[[1.74,11]],"id":41064149}],"con":true,"img":false}]}
{"op":"mcm","clk":"5322090367","pt":1646316296218,"mc":[{"id":"1.195532855","rc":[{"atb":[[2.72,2.16]],"id":42190933}],"con":true,"img":false}]}
{"op":"mcm","clk":"5322090372","pt":1646316296324,"mc":[{"id":"1.195532855","rc":[{"atb":[[2.52,3.28]],"id":28603686}],"con":true,"img":false}]}
{"op":"mcm","clk":"5322090411","pt":1646316296839,"mc":[{"id":"1.195532855","rc":[{"atb":[[2.52,0]],"id":28603686}],"con":true,"img":false}]}
{"op":"mcm","clk":"5322090431","pt":1646316297050,"mc":[{"id":"1.195532855","rc":[{"atb":[[2.7,0]],"id":42190933}],"con":true,"img":false}]}
{"op":"mcm","clk":"5322090441","pt":1646316297153,"mc":[{"id":"1.195532855","rc":[{"atb":[[2.72,0],[2.64,4.69],[2.74,1.99],[2.68,0]],"id":42190933}],"con":true,"img":false}]}
{"op":"mcm","clk":"5322090449","pt":1646316297257,"mc":[{"id":"1.195532855","rc":[{"atb":[[1.8,0]],"id":41064149}],"con":true,"img":false}]}
{"op":"mcm","clk":"5322090458","pt":1646316297359,"mc":[{"id":"1.195532855","rc":[{"atb":[[1.82,1.99]],"id":41064149}],"con":true,"img":false}]}
{"op":"mcm","clk":"5322090469","pt":1646316297464,"mc":[{"id":"1.195532855","rc":[{"atb":[[2.6,0]],"id":38833999},{"atb":[[2.62,0],[2.76,2.08]],"id":42190933},{"atb":[[1.79,0],[1.81,0]],"id":41064149},{"atb":[[3.15,0]],"id":36042605}],"con":true,"img":false}]}
{"op":"mcm","clk":"5322090489","pt":1646316297621,"mc":[{"id":"1.195532855","rc":[{"atb":[[2.64,1.65]],"id":38833999},{"atb":[[2.74,3.64]],"id":42190933},{"atb":[[3.25,1.65]],"id":36042605}],"con":true,"img":false}]}
{"op":"mcm","clk":"5322090497","pt":1646316297725,"mc":[{"id":"1.195532855","rc":[{"atb":[[2.66,2.29]],"id":38833999},{"atb":[[1.83,3.31]],"id":41064149},{"atb":[[3.3,3.35]],"id":36042605}],"con":true,"img":false}]}
{"op":"mcm","clk":"5322090511","pt":1646316297931,"mc":[{"id":"1.195532855","rc":[{"spn":3.98,"spf":"NaN","id":38833999},{"spn":4.38,"spf":"NaN","id":42190933},{"spn":1.83,"spf":1.0,"id":41064149},{"atb":[[2.96,5]],"id":36042605},{"spn":5.25,"spf":"NaN","id":36042605}],"con":true,"img":false}]}
{"op":"mcm","clk":"5322090553","pt":1646316298558,"mc":[{"id":"1.195532855","rc":[{"atb":[[2.74,1.65]],"id":42190933}],"con":true,"img":false}]}
{"op":"mcm","clk":"5322090561","pt":1646316298663,"mc":[{"id":"1.195532855","rc":[{"atb":[[2.78,1.99]],"id":42190933}],"con":true,"img":false}]}
{"op":"mcm","clk":"5322090575","pt":1646316298825,"mc":[{"id":"1.195532855","rc":[{"atb":[[2.8,2]],"id":42190933},{"atb":[[1.82,0]],"id":41064149}],"con":true,"img":false}]}
{"op":"mcm","clk":"5322090585","pt":1646316298924,"mc":[{"id":"1.195532855","rc":[{"atb":[[1.84,1.99]],"id":41064149}],"con":true,"img":false}]}
{"op":"mcm","clk":"5322090593","pt":1646316299029,"mc":[{"id":"1.195532855","rc":[{"atb":[[1.83,0],[1.85,3.2]],"id":41064149}],"con":true,"img":false}]}
{"op":"mcm","clk":"5322090601","pt":1646316299132,"mc":[{"id":"1.195532855","rc":[{"atb":[[2.78,0]],"id":42190933}],"con":true,"img":false}]}
{"op":"mcm","clk":"5322090610","pt":1646316299236,"mc":[{"id":"1.195532855","rc":[{"atb":[[2.58,0],[2.56,57.46]],"id":28603686},{"atb":[[2.8,0],[2.82,1.99],[2.76,0]],"id":42190933}],"con":true,"img":false}]}
{"op":"mcm","clk":"5322090619","pt":1646316299340,"mc":[{"id":"1.195532855","rc":[{"atb":[[2.56,18.24],[2.54,28.29]],"id":28603686}],"con":true,"img":false}]}
{"op":"mcm","clk":"5322090640","pt":1646316299659,"mc":[{"id":"1.195532855","rc":[{"atb":[[2.84,1.93]],"id":42190933}],"con":true,"img":false}]}
{"op":"mcm","clk":"5322090661","pt":1646316299921,"mc":[{"id":"1.195532855","rc":[{"atb":[[2.82,0]],"id":42190933},{"atl":[[2.62,61.73]],"id":41064149}],"con":true,"img":false}]}
{"op":"mcm","clk":"5322090666","pt":1646316300026,"mc":[{"id":"1.195532855","rc":[{"atb":[[2.66,1.99],[2.84,0]],"id":42190933},{"atl":[[2.64,10.21],[2.6,12.41],[2.68,23.81]],"id":41064149}],"con":true,"img":false}]}
{"op":"mcm","clk":"5322090676","pt":1646316300140,"mc":[{"id":"1.195532855","rc":[{"atb":[[2.76,2.08]],"id":42190933},{"atl":[[2.58,12.41]],"id":41064149}],"con":true,"img":false}]}
{"op":"mcm","clk":"5322090686","pt":1646316300234,"mc":[{"id":"1.195532855","rc":[{"atb":[[1.73,5],[1.84,0]],"id":41064149},{"atl":[[2.64,60.98],[2.58,0],[2.62,0],[2.7,6.78]],"id":41064149}],"con":true,"img":false}]}
{"op":"mcm","clk":"5322090692","pt":1646316300338,"mc":[{"id":"1.195532855","rc":[{"atb":[[1.85,0],[1.02,1.99]],"id":41064149},{"atl":[[2.6,14.41]],"id":41064149}],"con":true,"img":false}]}
{"op":"mcm","clk":"5322090704","pt":1646316300444,"mc":[{"id":"1.195532855","rc":[{"atb":[[1.73,0],[1.78,3.63],[1.62,6.69]],"id":41064149},{"atl":[[2.6,38.22],[2.7,0]],"id":41064149}],"con":true,"img":false}]}
{"op":"mcm","clk":"5322090715","pt":1646316300548,"mc":[{"id":"1.195532855","rc":[{"atl":[[2.64,0]],"id":41064149}],"con":true,"img":false}]}
{"op":"mcm","clk":"5322090743","pt":1646316300862,"mc":[{"id":"1.195532855","rc":[{"atb":[[1.83,3.48]],"id":41064149}],"con":true,"img":false}]}
{"op":"mcm","clk":"5322090753","pt":1646316300967,"mc":[{"id":"1.195532855","rc":[{"atb":[[1.62,0]],"id":41064149}],"con":true,"img":false}]}
{"op":"mcm","clk":"5322090763","pt":1646316301072,"mc":[{"id":"1.195532855","rc":[{"atb":[[1.83,0],[1.84,3.26]],"id":41064149}],"con":true,"img":false}]}
{"op":"mcm","clk":"5322090771","pt":1646316301137,"mc":[{"id":"1.195532855","rc":[{"atl":[[2.64,24.39],[2.68,3.01]],"id":41064149}],"con":true,"img":false}]}
{"op":"mcm","clk":"5322090780","pt":1646316301236,"mc":[{"id":"1.195532855","rc":[{"atb":[[1.84,0],[1.78,0]],"id":41064149}],"con":true,"img":false}]}
{"op":"mcm","clk":"5322090793","pt":1646316301340,"mc":[{"id":"1.195532855","rc":[{"atl":[[2.68,0]],"id":41064149}],"con":true,"img":false}]}
{"op":"mcm","clk":"5322090826","pt":1646316301653,"mc":[{"id":"1.195532855","rc":[{"atb":[[2.66,0]],"id":42190933}],"con":true,"img":false}]}
{"op":"mcm","clk":"5322090839","pt":1646316301757,"mc":[{"id":"1.195532855","rc":[{"atb":[[2.78,1.99]],"id":42190933}],"con":true,"img":false}]}
{"op":"mcm","clk":"5322090848","pt":1646316301861,"mc":[{"id":"1.195532855","rc":[{"atb":[[2.8,2]],"id":42190933},{"atb":[[1.78,3.63]],"id":41064149}],"con":true,"img":false}]}
{"op":"mcm","clk":"5322090855","pt":1646316301965,"mc":[{"id":"1.195532855","rc":[{"atb":[[1.02,0]],"id":41064149}],"con":true,"img":false}]}
{"op":"mcm","clk":"5322090869","pt":1646316302069,"mc":[{"id":"1.195532855","rc":[{"atb":[[1.78,5.62]],"id":41064149}],"con":true,"img":false}]}
{"op":"mcm","clk":"5322090946","pt":1646316302864,"mc":[{"id":"1.195532855","rc":[{"atb":[[2.78,0]],"id":42190933}],"con":true,"img":false}]}
{"op":"mcm","clk":"5322090955","pt":1646316302969,"mc":[{"id":"1.195532855","rc":[{"atb":[[2.82,1.99]],"id":42190933}],"con":true,"img":false}]}
{"op":"mcm","clk":"5322090969","pt":1646316303073,"mc":[{"id":"1.195532855","rc":[{"atb":[[2.8,0],[2.76,0]],"id":42190933}],"con":true,"img":false}]}
{"op":"mcm","clk":"5322090992","pt":1646316303235,"mc":[{"id":"1.195532855","rc":[{"atb":[[2.82,0]],"id":42190933}],"con":true,"img":false}]}
{"op":"mcm","clk":"5322091003","pt":1646316303342,"mc":[{"id":"1.195532855","rc":[{"atb":[[2.46,30.44],[2.58,4.65],[2.76,4.07]],"id":42190933}],"con":true,"img":false}]}
{"op":"mcm","clk":"5322091196","pt":1646316305532,"mc":[{"id":"1.195532855","rc":[{"atb":[[3.3,14.35]],"id":36042605}],"con":true,"img":false}]}
{"op":"mcm","clk":"5322091273","pt":1646316306372,"mc":[{"id":"1.195532855","rc":[{"atb":[[2.64,0]],"id":38833999},{"atb":[[2.74,0]],"id":42190933},{"atb":[[3.25,0]],"id":36042605}],"con":true,"img":false}]}
{"op":"mcm","clk":"5322091295","pt":1646316306578,"mc":[{"id":"1.195532855","rc":[{"atb":[[2.68,1.65]],"id":38833999},{"atb":[[2.78,1.65]],"id":42190933},{"atb":[[3.35,1.65]],"id":36042605}],"con":true,"img":false}]}
{"op":"mcm","clk":"5322091305","pt":1646316306630,"mc":[{"id":"1.195532855","rc":[{"atb":[[2.58,39.64],[2.48,33.9],[2.56,4.63],[2.66,24.78]],"id":38833999},{"atb":[[2.76,10.61]],"id":42190933},{"atb":[[1.74,55.24]],"id":41064149}],"con":true,"img":false}]}
{"op":"mcm","clk":"5322091316","pt":1646316306736,"mc":[{"id":"1.195532855","rc":[{"atb":[[2.62,2.38],[2.56,0],[2.7,2.21]],"id":38833999},{"atb":[[2.8,2],[2.46,9.99],[2.64,0],[2.58,16.33]],"id":42190933},{"atb":[[3.4,3.11]],"id":36042605}],"con":true,"img":false}]}
{"op":"mcm","clk":"5322091357","pt":1646316307149,"mc":[{"id":"1.195532855","rc":[{"atb":[[2.76,8.62]],"id":42190933}],"con":true,"img":false}]}
{"op":"mcm","clk":"5322091367","pt":1646316307252,"mc":[{"id":"1.195532855","rc":[{"atb":[[2.82,1.99]],"id":42190933}],"con":true,"img":false}]}
{"op":"mcm","clk":"5322091378","pt":1646316307360,"mc":[{"id":"1.195532855","rc":[{"atb":[[2.84,1.93]],"id":42190933}],"con":true,"img":false}]}
{"op":"mcm","clk":"5322091533","pt":1646316309133,"mc":[{"id":"1.195532855","rc":[{"atl":[[2.68,59.52]],"id":41064149}],"con":true,"img":false}]}
{"op":"mcm","clk":"5322091542","pt":1646316309238,"mc":[{"id":"1.195532855","rc":[{"atl":[[2.74,22.98],[2.6,36.22],[2.68,184.74]],"id":41064149}],"con":true,"img":false}]}
{"op":"mcm","clk":"5322091551","pt":1646316309351,"mc":[{"id":"1.195532855","rc":[{"atl":[[2.6,12.41],[2.68,244.26]],"id":41064149}],"con":true,"img":false}]}
{"op":"mcm","clk":"5322091567","pt":1646316309551,"mc":[{"id":"1.195532855","rc":[{"atl":[[2.6,0],[2.58,3.27]],"id":41064149}],"con":true,"img":false}]}
{"op":"mcm","clk":"5322091576","pt":1646316309655,"mc":[{"id":"1.195532855","rc":[{"atl":[[2.58,9.94]],"id":41064149}],"con":true,"img":false}]}
{"op":"mcm","clk":"5322091634","pt":1646316310177,"mc":[{"id":"1.195532855","rc":[{"atb":[[2.58,13.83]],"id":42190933},{"atl":[[2.64,0],[2.62,24.69],[2.68,184.74]],"id":41064149}],"con":true,"img":false}]}
{"op":"mcm","clk":"5322091861","pt":1646316312577,"mc":[{"id":"1.195532855","rc":[{"atl":[[5.6,0]],"id":28603686}],"con":true,"img":false}]}
{"op":"mcm","clk":"5322091887","pt":1646316312887,"mc":[{"id":"1.195532855","rc":[{"atl":[[5.5,82.27]],"id":28603686}],"con":true,"img":false}]}
{"op":"mcm","clk":"5322091906","pt":1646316313148,"mc":[{"id":"1.195532855","rc":[{"atl":[[5.5,79.28]],"id":28603686}],"con":true,"img":false}]}
{"op":"mcm","clk":"5322091946","pt":1646316313677,"mc":[{"id":"1.195532855","rc":[{"atl":[[3.6,0],[3.4,0],[3.8,0]],"id":41064149}],"con":true,"img":false}]}
{"op":"mcm","clk":"5322091989","pt":1646316314147,"mc":[{"id":"1.195532855","rc":[{"atl":[[5.4,6.36]],"id":28603686}],"con":true,"img":false}]}
{"op":"mcm","clk":"5322092000","pt":1646316314250,"mc":[{"id":"1.195532855","rc":[{"atl":[[5.3,19.7],[5.5,66.93]],"id":28603686}],"con":true,"img":false}]}
{"op":"mcm","clk":"5322092023","pt":1646316314562,"mc":[{"id":"1.195532855","rc":[{"atl":[[2.56,24.69],[2.68,125.22]],"id":41064149}],"con":true,"img":false}]}
{"op":"mcm","clk":"5322092035","pt":1646316314667,"mc":[{"id":"1.195532855","rc":[{"atl":[[2.56,50.66]],"id":41064149}],"con":true,"img":false}]}
{"op":"mcm","clk":"5322092047","pt":1646316314770,"mc":[{"id":"1.195532855","rc":[{"atl":[[2.58,3.27]],"id":41064149}],"con":true,"img":false}]}
{"op":"mcm","clk":"5322092060","pt":1646316314873,"mc":[{"id":"1.195532855","rc":[{"atb":[[2.58,2.15],[2.76,18.21]],"id":42190933}],"con":true,"img":false}]}
{"op":"mcm","clk":"5322092070","pt":1646316314976,"mc":[{"id":"1.195532855","rc":[{"atb":[[2.56,0],[2.54,46.53]],"id":28603686}],"con":true,"img":false}]}
{"op":"mcm","clk":"5322092079","pt":1646316315081,"mc":[{"id":"1.195532855","rc":[{"atb":[[2.54,20.74],[2.46,43.1]],"id":28603686}],"con":true,"img":false}]}
{"op":"mcm","clk":"5322092114","pt":1646316315451,"mc":[{"id":"1.195532855","rc":[{"atb":[[2.68,0]],"id":38833999},{"atb":[[2.78,0]],"id":42190933},{"atb":[[3.35,0]],"id":36042605}],"con":true,"img":false}]}
{"op":"mcm","clk":"5322092134","pt":1646316315656,"mc":[{"id":"1.195532855","rc":[{"atb":[[2.72,1.65]],"id":38833999},{"atb":[[2.86,1.65]],"id":42190933},{"atb":[[3.45,1.65]],"id":36042605}],"con":true,"img":false}]}
{"op":"mcm","clk":"5322092141","pt":1646316315760,"mc":[{"id":"1.195532855","rc":[{"atb":[[2.74,2.12]],"id":38833999},{"atb":[[2.88,1.86]],"id":42190933}],"con":true,"img":false}]}
{"op":"mcm","clk":"5322092149","pt":1646316315865,"mc":[{"id":"1.195532855","rc":[{"atb":[[2.76,8.62]],"id":42190933}],"con":true,"img":false}]}
{"op":"mcm","clk":"5322092198","pt":1646316316486,"mc":[{"id":"1.195532855","rc":[{"atb":[[2.82,0]],"id":42190933}],"con":true,"img":false}]}
{"op":"mcm","clk":"5322092209","pt":1646316316546,"mc":[{"id":"1.195532855","rc":[{"atb":[[2.88,3.85]],"id":42190933}],"con":true,"img":false}]}
{"op":"mcm","clk":"5322092328","pt":1646316317992,"mc":[{"id":"1.195532855","rc":[{"atb":[[2.88,1.86]],"id":42190933},{"atl":[[2.66,60.24]],"id":41064149}],"con":true,"img":false}]}
{"op":"mcm","clk":"5322092338","pt":1646316318097,"mc":[{"id":"1.195532855","rc":[{"atb":[[2.58,2.15],[2.74,12.32],[2.66,62.27]],"id":38833999},{"atb":[[2.86,3.64]],"id":42190933}],"con":true,"img":false}]}
{"op":"mcm","clk":"5322092352","pt":1646316318254,"mc":[{"id":"1.195532855","rc":[{"atb":[[2.66,39.78]],"id":38833999},{"atb":[[2.76,18.22]],"id":42190933}],"con":true,"img":false}]}
{"op":"mcm","clk":"5322092545","pt":1646316320551,"mc":[{"id":"1.195532855","rc":[{"atl":[[2.62,85.31],[2.68,0]],"id":41064149}],"con":true,"img":false}]}
{"op":"mcm","clk":"5322092673","pt":1646316322171,"mc":[{"id":"1.195532855","rc":[{"atl":[[2.62,97.89]],"id":41064149}],"con":true,"img":false}]}
{"op":"mcm","clk":"5322092685","pt":1646316322379,"mc":[{"id":"1.195532855","rc":[{"atl":[[2.62,85.31]],"id":41064149}],"con":true,"img":false}]}
{"op":"mcm","clk":"5322092726","pt":1646316322860,"mc":[{"id":"1.195532855","rc":[{"atb":[[2.68,2.25]],"id":28603686},{"atl":[[2.82,0]],"id":41064149},{"atb":[[3.45,4.66]],"id":36042605}],"con":true,"img":false}]}
{"op":"mcm","clk":"5322092735","pt":1646316322962,"mc":[{"id":"1.195532855","rc":[{"atb":[[2.54,2.5],[2.56,20.74],[2.68,13.86]],"id":28603686}],"con":true,"img":false}]}
{"op":"mcm","clk":"5322092743","pt":1646316323062,"mc":[{"id":"1.195532855","rc":[{"atb":[[2.64,4.14]],"id":28603686},{"atb":[[2.66,13.58]],"id":42609833},{"atl":[[2.6,8.38]],"id":41064149}],"con":true,"img":false}]}
{"op":"mcm","clk":"5322092756","pt":1646316323272,"mc":[{"id":"1.195532855","rc":[{"atb":[[2.6,6.11]],"id":28603686},{"atb":[[2.66,9.06]],"id":42609833},{"atl":[[2.6,0]],"id":41064149}],"con":true,"img":false}]}
{"op":"mcm","clk":"5322092788","pt":1646316323694,"mc":[{"id":"1.195532855","rc":[{"atb":[[2.64,2.15]],"id":28603686}],"con":true,"img":false}]}
{"op":"mcm","clk":"5322092797","pt":1646316323800,"mc":[{"id":"1.195532855","rc":[{"atb":[[2.7,1.99]],"id":28603686},{"atb":[[2.34,74.63],[2.76,11.68]],"id":42190933},{"atb":[[2.76,56.82],[2.56,160.26]],"id":36042605}],"con":true,"img":false}]}
{"op":"mcm","clk":"5322092803","pt":1646316323865,"mc":[{"id":"1.195532855","rc":[{"atb":[[2.54,5],[2.48,0]],"id":38833999},{"atb":[[2.76,2.08],[2.46,0]],"id":42190933},{"atb":[[3.3,27.21]],"id":36042605}],"con":true,"img":false}]}
{"op":"mcm","clk":"5322092813","pt":1646316323962,"mc":[{"id":"1.195532855","rc":[{"atb":[[2.72,2.16]],"id":28603686},{"atl":[[5.6,4.45]],"id":28603686}],"con":true,"img":false}]}
{"op":"mcm","clk":"5322092849","pt":1646316324377,"mc":[{"id":"1.195532855","rc":[{"atb":[[2.6,0],[2.66,0]],"id":28603686},{"atl":[[5.6,0],[5.4,2.5]],"id":28603686},{"atb":[[2.72,0]],"id":38833999},{"atb":[[2.86,1.99]],"id":42190933}],"con":true,"img":false}]}
{"op":"mcm","clk":"5322092867","pt":1646316324586,"mc":[{"id":"1.195532855","rc":[{"atl":[[5.3,9.85],[5.5,89.13]],"id":28603686},{"atb":[[2.76,1.65]],"id":38833999},{"atb":[[2.9,1.65]],"id":42190933}],"con":true,"img":false}]}
{"op":"mcm","clk":"5322092874","pt":1646316324688,"mc":[{"id":"1.195532855","rc":[{"atl":[[5.3,13.04]],"id":28603686},{"atb":[[2.78,2.04]],"id":38833999},{"atb":[[2.92,1.8]],"id":42190933}],"con":true,"img":false}]}
{"op":"mcm","clk":"5322092879","pt":1646316324794,"mc":[{"id":"1.195532855","rc":[{"atb":[[2.7,0]],"id":28603686}],"con":true,"img":false}]}
{"op":"mcm","clk":"5322092889","pt":1646316324901,"mc":[{"id":"1.195532855","rc":[{"atb":[[2.74,1.99]],"id":28603686}],"con":true,"img":false}]}
{"op":"mcm","clk":"5322092911","pt":1646316325061,"mc":[{"id":"1.195532855","rc":[{"atl":[[5.3,9.85]],"id":28603686}],"con":true,"img":false}]}
{"op":"mcm","clk":"5322092939","pt":1646316325272,"mc":[{"id":"1.195532855","rc":[{"atb":[[2.3,0],[2.26,0],[2.2,33.33]],"id":42609833},{"atb":[[2.26,31.75],[2.2,0]],"id":42190933},{"atb":[[1.59,67.8],[1.63,11]],"id":41064149},{"atl":[[2.6,25],[2.62,60.62]],"id":41064149}],"con":true,"img":false}]}
{"op":"mcm","clk":"5322092949","pt":1646316325376,"mc":[{"id":"1.195532855","rc":[{"atb":[[2.26,31.75],[2.2,0]],"id":28603686},{"atb":[[2.14,0],[2.2,33.33]],"id":38833999},{"atl":[[5.3,21.54]],"id":38833999},{"atb":[[1.62,7.94]],"id":41064149}],"con":true,"img":false}]}
{"op":"mcm","clk":"5322092960","pt":1646316325482,"mc":[{"id":"1.195532855","rc":[{"atl":[[5.6,44.92],[5.3,43.08]],"id":38833999},{"atb":[[2.22,0]],"id":42609833},{"atb":[[2.3,30.77],[2.26,0]],"id":42190933},{"atb":[[1.61,23.99]],"id":41064149}],"con":true,"img":false}]}
{"op":"mcm","clk":"5322092969","pt":1646316325586,"mc":[{"id":"1.195532855","rc":[{"atb":[[2.3,30.77],[2.26,0]],"id":28603686},{"atb":[[2.1,0],[2.02,0],[2.06,0]],"id":38833999},{"atb":[[2.14,35.09]],"id":42609833},{"atb":[[1.63,74.49],[1.62,0]],"id":41064149}],"con":true,"img":false}]}
{"op":"mcm","clk":"5322092978","pt":1646316325691,"mc":[{"id":"1.195532855","rc":[{"atb":[[2.86,0]],"id":42190933}],"con":true,"img":false}]}
{"op":"mcm","clk":"5322092988","pt":1646316325797,"mc":[{"id":"1.195532855","rc":[{"atl":[[5.3,40.14]],"id":38833999},{"atb":[[2.92,3.79]],"id":42190933}],"con":true,"img":false}]}
{"op":"mcm","clk":"5322093011","pt":1646316326065,"mc":[{"id":"1.195532855","rc":[{"atl":[[5,2]],"id":28603686},{"atb":[[2.8,11.43]],"id":42190933}],"con":true,"img":false}]}
{"op":"mcm","clk":"5322093019","pt":1646316326163,"mc":[{"id":"1.195532855","rc":[{"atl":[[5.5,31.09],[4.9,3.5],[5.4,15.8]],"id":28603686}],"con":true,"img":false}]}
{"op":"mcm","clk":"5322093030","pt":1646316326270,"mc":[{"id":"1.195532855","rc":[{"atb":[[2.64,11.71],[2.46,5]],"id":28603686},{"atl":[[5.3,0],[5.7,26.72]],"id":28603686}],"con":true,"img":false}]}
{"op":"mcm","clk":"5322093044","pt":1646316326373,"mc":[{"id":"1.195532855","rc":[{"atl":[[5.4,4.37]],"id":38833999},{"atb":[[2.92,1.8]],"id":42190933}],"con":true,"img":false}]}
{"op":"mcm","clk":"5322093054","pt":1646316326477,"mc":[{"id":"1.195532855","rc":[{"atl":[[5.6,0],[5.5,42.91]],"id":38833999},{"atb":[[2.9,3.64]],"id":42190933}],"con":true,"img":false}]}
{"op":"mcm","clk":"5322093067","pt":1646316326579,"mc":[{"id":"1.195532855","rc":[{"atl":[[5.7,9.87]],"id":38833999}],"con":true,"img":false}]}
{"op":"mcm","clk":"5322093074","pt":1646316326685,"mc":[{"id":"1.195532855","rc":[{"atl":[[5.7,21.28]],"id":28603686}],"con":true,"img":false}]}
{"op":"mcm","clk":"5322093092","pt":1646316326893,"mc":[{"id":"1.195532855","rc":[{"atl":[[5.1,9.76],[5.5,22.2]],"id":28603686},{"atb":[[2.2,0]],"id":42609833}],"con":true,"img":false}]}
{"op":"mcm","clk":"5322093099","pt":1646316326997,"mc":[{"id":"1.195532855","rc":[{"atl":[[5.7,0]],"id":38833999}],"con":true,"img":false}]}
{"op":"mcm","clk":"5322093206","pt":1646316328095,"mc":[{"id":"1.195532855","rc":[{"atb":[[2.6,13.87],[2.56,0]],"id":28603686},{"atl":[[5.8,0],[5.3,2.5],[5.4,13.3]],"id":28603686},{"atb":[[2.54,3],[2.74,2.12],[2.66,2.29]],"id":38833999},{"atb":[[2.4,9.76],[2.5,66.67],[2.44,0],[2.18,0]],"id":42609833},{"atb":[[2.8,2],[2.38,7.69]],"id":42190933},{"atb":[[3.3,14.35]],"id":36042605}],"con":true,"img":false}]}
{"op":"mcm","clk":"5322093219","pt":1646316328201,"mc":[{"id":"1.195532855","rc":[{"atb":[[2.72,6.14],[2.44,7.5]],"id":38833999}],"con":true,"img":false}]}
{"op":"mcm","clk":"5322093229","pt":1646316328305,"mc":[{"id":"1.195532855","rc":[{"atb":[[2.54,0]],"id":38833999},{"atb":[[2.4,0]],"id":42609833},{"atb":[[2.38,0]],"id":42190933}],"con":true,"img":false}]}
{"op":"mcm","clk":"5322093241","pt":1646316328464,"mc":[{"id":"1.195532855","rc":[{"atb":[[2.72,0]],"id":38833999}],"con":true,"img":false}]}
{"op":"mcm","clk":"5322093249","pt":1646316328579,"mc":[{"id":"1.195532855","rc":[{"atb":[[3.5,7.72]],"id":36042605}],"con":true,"img":false}]}
{"op":"mcm","clk":"5322093265","pt":1646316328778,"mc":[{"id":"1.195532855","rc":[{"atb":[[1.91,0]],"id":36042605}],"con":true,"img":false}]}
{"op":"mcm","clk":"5322093285","pt":1646316328987,"mc":[{"id":"1.195532855","rc":[{"atb":[[2.34,0],[2.46,68.49]],"id":42190933},{"atb":[[3.1,11.84],[2.76,0]],"id":36042605}],"con":true,"img":false}]}
{"op":"mcm","clk":"5322093346","pt":1646316329672,"mc":[{"id":"1.195532855","rc":[{"atl":[[5,9],[5.5,0]],"id":28603686}],"con":true,"img":false}]}
{"op":"mcm","clk":"5322093374","pt":1646316329985,"mc":[{"id":"1.195532855","rc":[{"atl":[[5,7]],"id":28603686}],"con":true,"img":false}]}
{"op":"mcm","clk":"5322093406","pt":1646316330301,"mc":[{"id":"1.195532855","rc":[{"atl":[[4.8,2.1]],"id":28603686}],"con":true,"img":false}]}
{"op":"mcm","clk":"5322093481","pt":1646316330986,"mc":[{"id":"1.195532855","rc":[{"atl":[[5.1,0],[5,17]],"id":28603686}],"con":true,"img":false}]}
{"op":"mcm","clk":"5322093492","pt":1646316331196,"mc":[{"id":"1.195532855","rc":[{"atl":[[4.8,0]],"id":28603686}],"con":true,"img":false}]}
{"op":"mcm","clk":"5322093528","pt":1646316331670,"mc":[{"id":"1.195532855","rc":[{"atl":[[2.6,86.24]],"id":41064149}],"con":true,"img":false}]}
{"op":"mcm","clk":"5322093537","pt":1646316331779,"mc":[{"id":"1.195532855","rc":[{"atl":[[2.62,0]],"id":41064149}],"con":true,"img":false}]}
{"op":"mcm","clk":"5322093641","pt":1646316332878,"mc":[{"id":"1.195532855","rc":[{"atb":[[2.16,86.21]],"id":38833999}],"con":true,"img":false}]}
{"op":"mcm","clk":"5322093659","pt":1646316333087,"mc":[{"id":"1.195532855","rc":[{"atb":[[2.1,90.91]],"id":42609833},{"atb":[[2.26,79.37]],"id":42190933},{"atb":[[1.61,187.92]],"id":41064149}],"con":true,"img":false}]}
{"op":"mcm","clk":"5322093679","pt":1646316333299,"mc":[{"id":"1.195532855","rc":[{"atl":[[5.1,9.76],[5,7]],"id":28603686},{"atb":[[2.06,0]],"id":42190933},{"atb":[[1.74,11]],"id":41064149}],"con":true,"img":false}]}
{"op":"mcm","clk":"5322093689","pt":1646316333406,"mc":[{"id":"1.195532855","rc":[{"atb":[[2.76,0]],"id":38833999},{"atb":[[2.9,1.99]],"id":42190933},{"atb":[[1.73,3.22]],"id":41064149},{"atb":[[3.45,3.01]],"id":36042605}],"con":true,"img":false}]}
{"op":"mcm","clk":"5322093709","pt":1646316333613,"mc":[{"id":"1.195532855","rc":[{"atb":[[2.8,1.65]],"id":38833999},{"atb":[[2.94,1.65]],"id":42190933},{"atb":[[3.55,1.65]],"id":36042605}],"con":true,"img":false}]}
{"op":"mcm","clk":"5322093719","pt":1646316333668,"mc":[{"id":"1.195532855","rc":[{"atb":[[2.62,0],[2.74,0],[2.66,0],[2.78,0],[2.7,0]],"id":38833999}],"con":true,"img":false}]}
{"op":"mcm","clk":"5322093731","pt":1646316333774,"mc":[{"id":"1.195532855","rc":[{"atb":[[2.36,20.62],[2.58,11.05]],"id":38833999},{"atb":[[2.96,1.74]],"id":42190933}],"con":true,"img":false}]}
{"op":"mcm","clk":"5322093748","pt":1646316333982,"mc":[{"id":"1.195532855","rc":[{"atb":[[2.82,1.97]],"id":38833999}],"con":true,"img":false}]}
{"op":"mcm","clk":"5322093756","pt":1646316334090,"mc":[{"id":"1.195532855","rc":[{"atb":[[2.72,10.04]],"id":28603686}],"con":true,"img":false}]}
{"op":"mcm","clk":"5322093776","pt":1646316334300,"mc":[{"id":"1.195532855","rc":[{"atb":[[2.68,2.25]],"id":28603686}],"con":true,"img":false}]}
{"op":"mcm","clk":"5322093788","pt":1646316334404,"mc":[{"id":"1.195532855","rc":[{"atb":[[1.73,0]],"id":41064149}],"con":true,"img":false}]}
{"op":"mcm","clk":"5322093820","pt":1646316334716,"mc":[{"id":"1.195532855","rc":[{"atl":[[5.1,20.26]],"id":28603686},{"atb":[[2.9,0]],"id":42190933}],"con":true,"img":false}]}
{"op":"mcm","clk":"5322093831","pt":1646316334776,"mc":[{"id":"1.195532855","rc":[{"atl":[[5,0]],"id":28603686},{"atb":[[2.96,3.73]],"id":42190933},{"atb":[[2.98,5.28]],"id":36042605}],"con":true,"img":false}]}
{"op":"mcm","clk":"5322093838","pt":1646316334873,"mc":[{"id":"1.195532855","rc":[{"atl":[[4.9,0]],"id":28603686},{"atb":[[3.4,14.02]],"id":36042605}],"con":true,"img":false}]}
{"op":"mcm","clk":"5322093849","pt":1646316334978,"mc":[{"id":"1.195532855","rc":[{"atl":[[5,3.56]],"id":28603686}],"con":true,"img":false}]}
{"op":"mcm","clk":"5322093873","pt":1646316335290,"mc":[{"id":"1.195532855","rc":[{"atb":[[2.98,0]],"id":36042605}],"con":true,"img":false}]}
{"op":"mcm","clk":"5322093902","pt":1646316335710,"mc":[{"id":"1.195532855","rc":[{"atb":[[2.96,1.74]],"id":42190933}],"con":true,"img":false}]}
{"op":"mcm","clk":"5322093913","pt":1646316335814,"mc":[{"id":"1.195532855","rc":[{"atb":[[2.94,3.64]],"id":42190933}],"con":true,"img":false}]}
{"op":"mcm","clk":"5322093970","pt":1646316336497,"mc":[{"id":"1.195532855","rc":[{"atl":[[5.1,10.5],[5.2,9.52]],"id":28603686}],"con":true,"img":false}]}
{"op":"mcm","clk":"5322093994","pt":1646316336809,"mc":[{"id":"1.195532855","rc":[{"atl":[[2.58,0]],"id":41064149}],"con":true,"img":false}]}
{"op":"mcm","clk":"5322094015","pt":1646316336971,"mc":[{"id":"1.195532855","rc":[{"atl":[[2.56,25.97],[2.6,25],[2.66,243.8]],"id":41064149}],"con":true,"img":false}]}
{"op":"mcm","clk":"5322094023","pt":1646316337074,"mc":[{"id":"1.195532855","rc":[{"atl":[[2.56,0],[2.54,3.29]],"id":41064149}],"con":true,"img":false}]}
{"op":"mcm","clk":"5322094037","pt":1646316337180,"mc":[{"id":"1.195532855","rc":[{"atl":[[5.2,49.56],[5.4,0]],"id":28603686},{"atl":[[2.54,9.97],[2.52,25],[2.66,183.56]],"id":41064149}],"con":true,"img":false}]}
{"op":"mcm","clk":"5322094118","pt":1646316338017,"mc":[{"id":"1.195532855","rc":[{"atl":[[4.7,2]],"id":28603686}],"con":true,"img":false}]}
{"op":"mcm","clk":"5322094139","pt":1646316338175,"mc":[{"id":"1.195532855","rc":[{"atl":[[4.6,4.36]],"id":28603686}],"con":true,"img":false}]}
{"op":"mcm","clk":"5322094148","pt":1646316338279,"mc":[{"id":"1.195532855","rc":[{"atl":[[5,0]],"id":28603686},{"atl":[[2.54,6.68]],"id":41064149}],"con":true,"img":false}]}
{"op":"mcm","clk":"5322094163","pt":1646316338384,"mc":[{"id":"1.195532855","rc":[{"atl":[[2.6,56.68]],"id":41064149}],"con":true,"img":false}]}
{"op":"mcm","clk":"5322094174","pt":1646316338488,"mc":[{"id":"1.195532855","rc":[{"atl":[[4.8,10.53],[5.2,40.04]],"id":28603686},{"atl":[[2.52,0]],"id":41064149}],"con":true,"img":false}]}
{"op":"mcm","clk":"5322094187","pt":1646316338592,"mc":[{"id":"1.195532855","rc":[{"atl":[[2.52,13.46]],"id":41064149}],"con":true,"img":false}]}
{"op":"mcm","clk":"5322094242","pt":1646316339219,"mc":[{"id":"1.195532855","rc":[{"atl":[[4.7,0]],"id":28603686}],"con":true,"img":false}]}
{"op":"mcm","clk":"5322094257","pt":1646316339380,"mc":[{"id":"1.195532855","rc":[{"atl":[[4.6,0]],"id":28603686}],"con":true,"img":false}]}
{"op":"mcm","clk":"5322094265","pt":1646316339481,"mc":[{"id":"1.195532855","rc":[{"atl":[[4.7,10.8]],"id":28603686}],"con":true,"img":false}]}
{"op":"mcm","clk":"5322094354","pt":1646316340424,"mc":[{"id":"1.195532855","rc":[{"atb":[[2.12,133.93]],"id":38833999}],"con":true,"img":false}]}
{"op":"mcm","clk":"5322094362","pt":1646316340479,"mc":[{"id":"1.195532855","rc":[{"atb":[[2.22,122.95]],"id":42190933}],"con":true,"img":false}]}
{"op":"mcm","clk":"5322094373","pt":1646316340587,"mc":[{"id":"1.195532855","rc":[{"atb":[[2.06,141.51]],"id":42609833},{"atb":[[1.59,250]],"id":41064149}],"con":true,"img":false}]}
{"op":"mcm","clk":"5322094394","pt":1646316340795,"mc":[{"id":"1.195532855","rc":[{"atl":[[4.6,3]],"id":28603686}],"con":true,"img":false}]}
{"op":"mcm","clk":"5322094400","pt":1646316340899,"mc":[{"id":"1.195532855","rc":[{"atl":[[5.1,0],[4.5,10.53]],"id":28603686}],"con":true,"img":false}]}
{"op":"mcm","clk":"5322094461","pt":1646316341580,"mc":[{"id":"1.195532855","rc":[{"atl":[[4.7,21.61]],"id":28603686},{"atb":[[2.26,111.12],[2.1,0]],"id":42190933},{"atl":[[2.6,31.68],[2.58,25.32]],"id":41064149},{"atb":[[2.86,21.51],[2.68,0]],"id":36042605}],"con":true,"img":false}]}
{"op":"mcm","clk":"5322094473","pt":1646316341685,"mc":[{"id":"1.195532855","rc":[{"atb":[[2.3,0],[2.26,31.75]],"id":28603686},{"atl":[[4.8,0]],"id":28603686},{"atb":[[2.3,0],[2.26,31.75]],"id":42190933},{"atb":[[1.59,67.8],[1.63,11]],"id":41064149},{"atl":[[2.56,25.64]],"id":41064149}],"con":true,"img":false}]}
{"op":"mcm","clk":"5322094513","pt":1646316342101,"mc":[{"id":"1.195532855","rc":[{"atl":[[4.6,0]],"id":28603686}],"con":true,"img":false}]}
{"op":"mcm","clk":"5322094540","pt":1646316342417,"mc":[{"id":"1.195532855","rc":[{"atb":[[2.8,0]],"id":38833999},{"atb":[[2.94,1.99]],"id":42190933}],"con":true,"img":false}]}
{"op":"mcm","clk":"5322094548","pt":1646316342516,"mc":[{"id":"1.195532855","rc":[{"atb":[[2.82,0]],"id":38833999}],"con":true,"img":false}]}
{"op":"mcm","clk":"5322094558","pt":1646316342621,"mc":[{"id":"1.195532855","rc":[{"atb":[[2.6,2.44],[2.84,1.65],[2.46,22.1]],"id":38833999},{"atb":[[2.98,1.65]],"id":42190933},{"atl":[[2.56,61],[2.66,60.24]],"id":41064149}],"con":true,"img":false}]}
{"op":"mcm","clk":"5322094567","pt":1646316342723,"mc":[{"id":"1.195532855","rc":[{"atb":[[2.44,2.5],[2.86,1.9]],"id":38833999},{"atb":[[3,1.68]],"id":42190933}],"con":true,"img":false}]}
{"op":"mcm","clk":"5322094638","pt":1646316343847,"mc":[{"id":"1.195532855","rc":[{"atl":[[2.5,13.46]],"id":41064149}],"con":true,"img":false}]}
{"op":"mcm","clk":"5322094645","pt":1646316343863,"mc":[{"id":"1.195532855","rc":[{"atl":[[2.6,0]],"id":41064149}],"con":true,"img":false}]}
{"op":"mcm","clk":"5322094652","pt":1646316343882,"mc":[{"id":"1.195532855","rc":[{"atl":[[2.58,38.14]],"id":41064149}],"con":true,"img":false}]}
{"op":"mcm","clk":"5322094693","pt":1646316344158,"mc":[{"id":"1.195532855","rc":[{"atl":[[4.8,4.03]],"id":28603686},{"atb":[[1.61,23.99]],"id":41064149},{"atl":[[2.56,38.61],[2.54,32.65]],"id":41064149}],"con":true,"img":false}]}
{"op":"mcm","clk":"5322094702","pt":1646316344207,"mc":[{"id":"1.195532855","rc":[{"atl":[[2.58,36.45]],"id":41064149}],"con":true,"img":false}]}
{"op":"mcm","clk":"5322094713","pt":1646316344319,"mc":[{"id":"1.195532855","rc":[{"atl":[[5.3,20.09]],"id":28603686}],"con":true,"img":false}]}
{"op":"mcm","clk":"5322094724","pt":1646316344416,"mc":[{"id":"1.195532855","rc":[{"atl":[[2.56,35.36]],"id":41064149}],"con":true,"img":false}]}
{"op":"mcm","clk":"5322094744","pt":1646316344624,"mc":[{"id":"1.195532855","rc":[{"atb":[[2.58,30.33]],"id":38833999}],"con":true,"img":false}]}
{"op":"mcm","clk":"5322094752","pt":1646316344728,"mc":[{"id":"1.195532855","rc":[{"atl":[[5.3,2.5]],"id":28603686},{"atb":[[2.36,5]],"id":38833999},{"atl":[[2.58,25.32]],"id":41064149}],"con":true,"img":false}]}
{"op":"mcm","clk":"5322094778","pt":1646316345039,"mc":[{"id":"1.195532855","rc":[{"atb":[[2.94,0]],"id":42190933}],"con":true,"img":false}]}
{"op":"mcm","clk":"5322094786","pt":1646316345142,"mc":[{"id":"1.195532855","rc":[{"atb":[[3,3.67]],"id":42190933}],"con":true,"img":false}]}
{"op":"mcm","clk":"5322094810","pt":1646316345455,"mc":[{"id":"1.195532855","rc":[{"atb":[[2.52,5.4]],"id":28603686}],"con":true,"img":false}]}
{"op":"mcm","clk":"5322094822","pt":1646316345508,"mc":[{"id":"1.195532855","rc":[{"atl":[[4.8,0]],"id":28603686}],"con":true,"img":false}]}
{"op":"mcm","clk":"5322094833","pt":1646316345619,"mc":[{"id":"1.195532855","rc":[{"atb":[[3,1.68]],"id":42190933}],"con":true,"img":false}]}
{"op":"mcm","clk":"5322094844","pt":1646316345720,"mc":[{"id":"1.195532855","rc":[{"atb":[[2.98,3.64]],"id":42190933}],"con":true,"img":false}]}
{"op":"mcm","clk":"5322094854","pt":1646316345824,"mc":[{"id":"1.195532855","rc":[{"atl":[[4.5,0],[5.2,63.85],[4.4,15.43],[4.7,27.92]],"id":28603686}],"con":true,"img":false}]}
{"op":"mcm","clk":"5322094862","pt":1646316345932,"mc":[{"id":"1.195532855","rc":[{"atb":[[2.52,0]],"id":28603686}],"con":true,"img":false}]}
{"op":"mcm","clk":"5322094871","pt":1646316346033,"mc":[{"id":"1.195532855","rc":[{"atl":[[4.7,17.12]],"id":28603686}],"con":true,"img":false}]}
{"op":"mcm","clk":"5322094882","pt":1646316346140,"mc":[{"id":"1.195532855","rc":[{"atl":[[4.6,11.11],[4.4,0],[4.7,6.31]],"id":28603686}],"con":true,"img":false}]}
{"op":"mcm","clk":"5322094897","pt":1646316346244,"mc":[{"id":"1.195532855","rc":[{"atl":[[5.3,7.28],[4.7,0]],"id":28603686}],"con":true,"img":false}]}
{"op":"mcm","clk":"5322094907","pt":1646316346348,"mc":[{"id":"1.195532855","rc":[{"atl":[[4.5,6.42]],"id":28603686}],"con":true,"img":false}]}
{"op":"mcm","clk":"5322094918","pt":1646316346455,"mc":[{"id":"1.195532855","rc":[{"atl":[[5.3,48.14],[5.2,23.81]],"id":28603686}],"con":true,"img":false}]}
{"op":"mcm","clk":"5322094928","pt":1646316346558,"mc":[{"id":"1.195532855","rc":[{"atl":[[5.3,2.5]],"id":28603686}],"con":true,"img":false}]}
{"op":"mcm","clk":"5322094986","pt":1646316347031,"mc":[{"id":"1.195532855","rc":[{"atl":[[4.6,14.11]],"id":28603686}],"con":true,"img":false}]}
{"op":"mcm","clk":"5322095066","pt":1646316347709,"mc":[{"id":"1.195532855","rc":[{"atb":[[2.08,231.48]],"id":38833999}],"con":true,"img":false}]}
{"op":"mcm","clk":"5322095075","pt":1646316347813,"mc":[{"id":"1.195532855","rc":[{"atl":[[2.56,0],[2.54,81.57]],"id":41064149}],"con":true,"img":false}]}
{"op":"mcm","clk":"5322095084","pt":1646316347916,"mc":[{"id":"1.195532855","rc":[{"atb":[[2.02,245.1]],"id":42609833}],"con":true,"img":false}]}
{"op":"mcm","clk":"5322095099","pt":1646316348022,"mc":[{"id":"1.195532855","rc":[{"atl":[[5.2,71.29]],"id":28603686},{"atl":[[2.5,31.8]],"id":41064149}],"con":true,"img":false}]}
{"op":"mcm","clk":"5322095113","pt":1646316348126,"mc":[{"id":"1.195532855","rc":[{"atl":[[2.54,74.89]],"id":41064149}],"con":true,"img":false}]}
{"op":"mcm","clk":"5322095151","pt":1646316348440,"mc":[{"id":"1.195532855","rc":[{"atl":[[4.6,3],[4.7,10.81]],"id":28603686},{"atl":[[5.6,4.42]],"id":38833999}],"con":true,"img":false}]}
{"op":"mcm","clk":"5322095164","pt":1646316348542,"mc":[{"id":"1.195532855","rc":[{"atl":[[5.7,3.04]],"id":38833999}],"con":true,"img":false}]}
{"op":"mcm","clk":"5322095172","pt":1646316348646,"mc":[{"id":"1.195532855","rc":[{"atl":[[5.4,0]],"id":38833999}],"con":true,"img":false}]}
{"op":"mcm","clk":"5322095197","pt":1646316348852,"mc":[{"id":"1.195532855","rc":[{"atl":[[5.6,95.66],[5.3,18.6],[5.5,11.39]],"id":38833999}],"con":true,"img":false}]}
{"op":"mcm","clk":"5322095204","pt":1646316348955,"mc":[{"id":"1.195532855","rc":[{"atl":[[5.6,91.24]],"id":38833999},{"atb":[[2.22,81.97]],"id":42190933},{"atb":[[2.82,54.95]],"id":36042605}],"con":true,"img":false}]}
{"op":"mcm","clk":"5322095221","pt":1646316349010,"mc":[{"id":"1.195532855","rc":[{"atl":[[5.7,0]],"id":38833999},{"atl":[[2.78,0]],"id":41064149}],"con":true,"img":false}]}
{"op":"mcm","clk":"5322095229","pt":1646316349115,"mc":[{"id":"1.195532855","rc":[{"atl":[[5.2,3]],"id":38833999},{"atb":[[2.64,0],[2.6,0],[2.56,0]],"id":36042605}],"con":true,"img":false}]}
{"op":"mcm","clk":"5322095241","pt":1646316349217,"mc":[{"id":"1.195532855","rc":[{"atl":[[5.1,4.08]],"id":38833999}],"con":true,"img":false}]}
{"op":"mcm","clk":"5322095249","pt":1646316349321,"mc":[{"id":"1.195532855","rc":[{"atl":[[5.6,69.5],[5.1,15.47]],"id":38833999}],"con":true,"img":false}]}
{"op":"mcm","clk":"5322095260","pt":1646316349427,"mc":[{"id":"1.195532855","rc":[{"atl":[[5.3,0]],"id":38833999}],"con":true,"img":false}]}
{"op":"mcm","clk":"5322095327","pt":1646316350152,"mc":[{"id":"1.195532855","rc":[{"atl":[[5.5,2.5],[5.3,9.3]],"id":38833999}],"con":true,"img":false}]}
{"op":"mcm","clk":"5322095396","pt":1646316350933,"mc":[{"id":"1.195532855","rc":[{"atl":[[4.6,15.84]],"id":28603686}],"con":true,"img":false}]}
{"op":"mcm","clk":"5322095406","pt":1646316351037,"mc":[{"id":"1.195532855","rc":[{"atl":[[4.6,3],[5.2,47.48],[4.7,21.62]],"id":28603686}],"con":true,"img":false}]}
{"op":"mcm","clk":"5322095442","pt":1646316351350,"mc":[{"id":"1.195532855","rc":[{"atb":[[2.84,0]],"id":38833999},{"atb":[[2.66,8.01],[2.58,0]],"id":42609833},{"atb":[[2.98,1.99]],"id":42190933},{"atb":[[1.57,175.44]],"id":41064149},{"atl":[[2.58,63.29]],"id":41064149}],"con":true,"img":false}]}
{"op":"mcm","clk":"5322095455","pt":1646316351454,"mc":[{"id":"1.195532855","rc":[{"atb":[[2.88,1.65]],"id":38833999},{"atb":[[2.66,1.99]],"id":42609833},{"atb":[[3.05,1.65]],"id":42190933}],"con":true,"img":false}]}
{"op":"mcm","clk":"5322095465","pt":1646316351558,"mc":[{"id":"1.195532855","rc":[{"atb":[[2.6,9.23],[2.58,11.05],[2.86,0],[2.46,53.06]],"id":38833999},{"atb":[[2.5,91.26]],"id":42609833}],"con":true,"img":false}]}
{"op":"mcm","clk":"5322095478","pt":1646316351611,"mc":[{"id":"1.195532855","rc":[{"atb":[[2.72,7.88]],"id":28603686},{"atb":[[2.98,0]],"id":42190933},{"atb":[[1.78,1.99]],"id":41064149}],"con":true,"img":false}]}
{"op":"mcm","clk":"5322095489","pt":1646316351716,"mc":[{"id":"1.195532855","rc":[{"atb":[[2.58,2.15]],"id":38833999},{"atb":[[2.66,9.06]],"id":42609833},{"atb":[[2.94,1.99]],"id":42190933},{"atb":[[1.7,100.92]],"id":41064149},{"atl":[[2.52,0]],"id":41064149}],"con":true,"img":false}]}
{"op":"mcm","clk":"5322095500","pt":1646316351820,"mc":[{"id":"1.195532855","rc":[{"atl":[[2.5,18.34],[2.58,126.58]],"id":41064149}],"con":true,"img":false}]}
{"op":"mcm","clk":"5322095509","pt":1646316351926,"mc":[{"id":"1.195532855","rc":[{"atl":[[2.5,0]],"id":41064149}],"con":true,"img":false}]}
{"op":"mcm","clk":"5322095521","pt":1646316352031,"mc":[{"id":"1.195532855","rc":[{"atl":[[2.52,22],[2.44,1.8]],"id":41064149}],"con":true,"img":false}]}
{"op":"mcm","clk":"5322095537","pt":1646316352136,"mc":[{"id":"1.195532855","rc":[{"atb":[[2.58,8.6]],"id":38833999}],"con":true,"img":false}]}
{"op":"mcm","clk":"5322095550","pt":1646316352240,"mc":[{"id":"1.195532855","rc":[{"atl":[[2.54,48.92],[2.52,48.32]],"id":41064149}],"con":true,"img":false}]}
{"op":"mcm","clk":"5322095573","pt":1646316352447,"mc":[{"id":"1.195532855","rc":[{"atl":[[4.6,0]],"id":28603686}],"con":true,"img":false}]}
{"op":"mcm","clk":"5322095579","pt":1646316352551,"mc":[{"id":"1.195532855","rc":[{"atb":[[2.44,6.59]],"id":38833999}],"con":true,"img":false}]}
{"op":"mcm","clk":"5322095585","pt":1646316352654,"mc":[{"id":"1.195532855","rc":[{"atl":[[4.5,0]],"id":28603686},{"atb":[[2.58,2.15]],"id":38833999},{"atl":[[5.2,0]],"id":38833999}],"con":true,"img":false}]}
{"op":"mcm","clk":"5322095593","pt":1646316352758,"mc":[{"id":"1.195532855","rc":[{"atl":[[4.6,10.73]],"id":28603686},{"atl":[[2.54,0],[2.58,311.39]],"id":41064149}],"con":true,"img":false}]}
{"op":"mcm","clk":"5322095604","pt":1646316352809,"mc":[{"id":"1.195532855","rc":[{"atl":[[5.3,45.66],[5.2,0]],"id":28603686},{"atl":[[2.44,0]],"id":41064149}],"con":true,"img":false}]}
{"op":"mcm","clk":"5322095621","pt":1646316353018,"mc":[{"id":"1.195532855","rc":[{"atb":[[2.44,2.5]],"id":38833999}],"con":true,"img":false}]}
{"op":"mcm","clk":"5322095640","pt":1646316353226,"mc":[{"id":"1.195532855","rc":[{"atb":[[2.68,0]],"id":28603686},{"atl":[[4.7,10.81]],"id":28603686},{"atl":[[2.56,25.64]],"id":41064149}],"con":true,"img":false}]}
{"op":"mcm","clk":"5322095650","pt":1646316353330,"mc":[{"id":"1.195532855","rc":[{"atb":[[2.64,2.15],[2.6,42.02]],"id":28603686},{"atl":[[4.8,10.53]],"id":28603686},{"atl":[[2.52,22]],"id":41064149}],"con":true,"img":false}]}
{"op":"mcm","clk":"5322095660","pt":1646316353442,"mc":[{"id":"1.195532855","rc":[{"atb":[[2.66,3.32]],"id":28603686}],"con":true,"img":false}]}
{"op":"mcm","clk":"5322095678","pt":1646316353645,"mc":[{"id":"1.195532855","rc":[{"atb":[[2.66,0]],"id":28603686}],"con":true,"img":false}]}
{"op":"mcm","clk":"5322095716","pt":1646316354064,"mc":[{"id":"1.195532855","rc":[{"atb":[[2.5,24.59],[2.66,1.99]],"id":42609833},{"atb":[[3.5,0]],"id":36042605}],"con":true,"img":false}]}
{"op":"mcm","clk":"5322095729","pt":1646316354118,"mc":[{"id":"1.195532855","rc":[{"atl":[[4.5,2.49]],"id":28603686},{"atb":[[2.4,71.43],[2.48,7.06]],"id":42609833}],"con":true,"img":false}]}
{"op":"mcm","clk":"5322095739","pt":1646316354228,"mc":[{"id":"1.195532855","rc":[{"atl":[[5.1,4.08],[5.5,24.72]],"id":38833999},{"atb":[[3.3,38.9],[3.45,13.34],[3.4,3.11]],"id":36042605}],"con":true,"img":false}]}
{"op":"mcm","clk":"5322095755","pt":1646316354331,"mc":[{"id":"1.195532855","rc":[{"atb":[[2.94,0]],"id":42190933}],"con":true,"img":false}]}
{"op":"mcm","clk":"5322095765","pt":1646316354435,"mc":[{"id":"1.195532855","rc":[{"atl":[[5.1,0]],"id":38833999},{"atb":[[3.05,3.64]],"id":42190933}],"con":true,"img":false}]}
{"op":"mcm","clk":"5322095775","pt":1646316354541,"mc":[{"id":"1.195532855","rc":[{"atl":[[4.8,0],[4.7,21.62]],"id":28603686},{"atl":[[5.6,91.24],[5.5,2.5],[5.2,9.98]],"id":38833999},{"atb":[[2.48,0]],"id":42609833}],"con":true,"img":false}]}
{"op":"mcm","clk":"5322095786","pt":1646316354643,"mc":[{"id":"1.195532855","rc":[{"atb":[[3.45,9.48]],"id":36042605}],"con":true,"img":false}]}
{"op":"mcm","clk":"5322095827","pt":1646316355062,"mc":[{"id":"1.195532855","rc":[{"atl":[[5.3,0],[5.4,9.09]],"id":38833999}],"con":true,"img":false}]}
{"op":"mcm","clk":"5322095842","pt":1646316355273,"mc":[{"id":"1.195532855","rc":[{"atl":[[5.2,0]],"id":38833999}],"con":true,"img":false}]}
{"op":"mcm","clk":"5322095865","pt":1646316355429,"mc":[{"id":"1.195532855","rc":[{"atl":[[5.3,8.69]],"id":38833999}],"con":true,"img":false}]}
{"op":"mcm","clk":"5322095876","pt":1646316355534,"mc":[{"id":"1.195532855","rc":[{"atb":[[3.05,1.65]],"id":42190933},{"atl":[[2.52,0]],"id":41064149}],"con":true,"img":false}]}
{"op":"mcm","clk":"5322095880","pt":1646316355639,"mc":[{"id":"1.195532855","rc":[{"atb":[[2.98,1.99]],"id":42190933},{"atl":[[2.56,35.5]],"id":41064149}],"con":true,"img":false}]}
{"op":"mcm","clk":"5322095917","pt":1646316356058,"mc":[{"id":"1.195532855","rc":[{"atl":[[5.5,11.39],[5.4,0]],"id":38833999}],"con":true,"img":false}]}
{"op":"mcm","clk":"5322095927","pt":1646316356161,"mc":[{"id":"1.195532855","rc":[{"atl":[[4.5,13.22]],"id":28603686},{"atb":[[2.18,127.12]],"id":42190933},{"atb":[[2.78,84.27]],"id":36042605}],"con":true,"img":false}]}
{"op":"mcm","clk":"5322095936","pt":1646316356270,"mc":[{"id":"1.195532855","rc":[{"atl":[[4.7,10.81]],"id":28603686}],"con":true,"img":false}]}
{"op":"mcm","clk":"5322095956","pt":1646316356422,"mc":[{"id":"1.195532855","rc":[{"atl":[[4.4,13.96]],"id":28603686}],"con":true,"img":false}]}
{"op":"mcm","clk":"5322095975","pt":1646316356632,"mc":[{"id":"1.195532855","rc":[{"atl":[[4.6,0]],"id":28603686},{"atb":[[2.98,0]],"id":42190933},{"atl":[[2.66,120.48],[2.58,248.1]],"id":41064149}],"con":true,"img":false}]}
{"op":"mcm","clk":"5322095983","pt":1646316356735,"mc":[{"id":"1.195532855","rc":[{"atb":[[3.05,3.64]],"id":42190933}],"con":true,"img":false}]}
{"op":"mcm","clk":"5322096013","pt":1646316357050,"mc":[{"id":"1.195532855","rc":[{"atl":[[4.3,3.61],[5.3,2.5],[4.7,58.87]],"id":28603686},{"atl":[[5.2,2.34]],"id":38833999},{"atl":[[4.7,2.94]],"id":42609833},{"atl":[[5.9,1.76]],"id":42190933},{"atl":[[2.54,2.58]],"id":41064149},{"atl":[[7,2.46]],"id":36042605}],"con":true,"img":false}]}
{"op":"mcm","clk":"5322096023","pt":1646316357151,"mc":[{"id":"1.195532855","rc":[{"atl":[[4.6,11.11],[4.7,48.06]],"id":28603686},{"atl":[[5.9,4.96]],"id":42190933},{"atl":[[6.8,4.21]],"id":36042605}],"con":true,"img":false}]}
{"op":"mcm","clk":"5322096031","pt":1646316357260,"mc":[{"id":"1.195532855","rc":[{"atl":[[4.5,2.49],[4.2,21.84]],"id":28603686},{"atl":[[5.1,0],[5,31.86],[4.6,3.82],[4.7,10.22]],"id":42609833},{"atb":[[3.05,1.65]],"id":42190933},{"atl":[[6.4,26.51],[6.2,17.12],[6,0],[6.6,3.71],[5.9,7.46]],"id":42190933},{"atl":[[7.4,19.96],[7.8,14.46],[7.2,0],[7.6,6.06],[7,4.96],[6.6,2.8]],"id":36042605}],"con":true,"img":false}]}
{"op":"mcm","clk":"5322096041","pt":1646316357361,"mc":[{"id":"1.195532855","rc":[{"atb":[[2.98,1.99]],"id":42190933},{"atl":[[6.4,7.4]],"id":42190933}],"con":true,"img":false}]}
{"op":"mcm","clk":"5322096046","pt":1646316357466,"mc":[{"id":"1.195532855","rc":[{"atl":[[4.4,11.76],[4.6,0],[4.1,4.04]],"id":28603686},{"atl":[[5.5,2.5],[5.4,9.09]],"id":38833999},{"atl":[[4.8,20.53],[4.5,3.25],[5.1,5],[5,21.86],[4.7,2.94]],"id":42609833},{"atl":[[6.4,0],[6.2,29.42],[6.6,4.63],[5.9,4.96]],"id":42190933},{"atl":[[2.56,9.86],[2.58,210.13]],"id":41064149},{"atl":[[7.2,6.67],[7.6,3.84],[7,9.13]],"id":36042605}],"con":true,"img":false}]}
{"op":"mcm","clk":"5322096069","pt":1646316357673,"mc":[{"id":"1.195532855","rc":[{"atl":[[4,4.04],[4.2,8.62]],"id":28603686},{"atl":[[4.8,10.53],[4.4,3.25],[5.1,10.22]],"id":42609833},{"atl":[[6.2,10.19],[6.6,3.06],[5.9,12.42]],"id":42190933},{"atl":[[7.2,0],[7.6,0],[6.6,7.01]],"id":36042605}],"con":true,"img":false}]}
{"op":"mcm","clk":"5322096083","pt":1646316357779,"mc":[{"id":"1.195532855","rc":[{"atl":[[5.1,5.22]],"id":42609833},{"atl":[[7.8,11]],"id":36042605}],"con":true,"img":false}]}
{"op":"mcm","clk":"5322096093","pt":1646316357831,"mc":[{"id":"1.195532855","rc":[{"atl":[[3.95,2.19]],"id":28603686},{"atl":[[4.3,3.61]],"id":42609833},{"atl":[[6.4,18.52],[5.9,4.96]],"id":42190933}],"con":true,"img":false}]}
{"op":"mcm","clk":"5322096111","pt":1646316358037,"mc":[{"id":"1.195532855","rc":[{"atl":[[4.4,0],[4.1,16.94]],"id":28603686},{"spn":2.74,"spf":1.0,"id":28603686},{"spn":4.04,"spf":"NaN","id":38833999},{"atl":[[4.8,0],[4.5,14.68]],"id":42609833},{"spn":3.49,"spf":"NaN","id":42609833},{"spn":4.47,"spf":"NaN","id":42190933},{"spn":1.78,"spf":1.0,"id":41064149},{"spn":5.07,"spf":"NaN","id":36042605}],"con":true,"img":false}]}
{"op":"mcm","clk":"5322096124","pt":1646316358143,"mc":[{"id":"1.195532855","rc":[{"atl":[[5.1,0]],"id":42609833},{"atb":[[2.98,0]],"id":42190933},{"atl":[[6.6,0]],"id":42190933}],"con":true,"img":false}]}
{"op":"mcm","clk":"5322096134","pt":1646316358256,"mc":[{"id":"1.195532855","rc":[{"atb":[[3.05,3.64]],"id":42190933}],"con":true,"img":false}]}
{"op":"mcm","clk":"5322096174","pt":1646316358668,"mc":[{"id":"1.195532855","rc":[{"atl":[[4.1,44.76],[4.7,0]],"id":28603686},{"atl":[[2.54,11.91]],"id":41064149}],"con":true,"img":false}]}
{"op":"mcm","clk":"5322096186","pt":1646316358770,"mc":[{"id":"1.195532855","rc":[{"atb":[[3.05,1.65]],"id":42190933}],"con":true,"img":false}]}
{"op":"mcm","clk":"5322096198","pt":1646316358823,"mc":[{"id":"1.195532855","rc":[{"atb":[[2.98,1.99]],"id":42190933},{"atl":[[2.56,0]],"id":41064149}],"con":true,"img":false}]}
{"op":"mcm","clk":"5322096207","pt":1646316358929,"mc":[{"id":"1.195532855","rc":[{"atl":[[2.66,301.42],[2.58,25.32]],"id":41064149}],"con":true,"img":false}]}
{"op":"mcm","clk":"5322096242","pt":1646316359343,"mc":[{"id":"1.195532855","rc":[{"atl":[[5.6,21.74],[5.4,44.65]],"id":38833999}],"con":true,"img":false}]}
{"op":"mcm","clk":"5322096258","pt":1646316359552,"mc":[{"id":"1.195532855","rc":[{"atb":[[2.4,0],[2.5,0]],"id":42609833},{"atl":[[5.6,54.35],[6,0],[5.2,23.81]],"id":42609833},{"atb":[[3.1,9.34],[2.88,0],[2.96,0]],"id":36042605}],"con":true,"img":false}]}
{"op":"mcm","clk":"5322096267","pt":1646316359657,"mc":[{"id":"1.195532855","rc":[{"atl":[[5.6,0],[5.2,11.03]],"id":38833999},{"atb":[[2.3,76.92]],"id":42609833},{"atb":[[2.98,0]],"id":42190933}],"con":true,"img":false}]}
{"op":"mcm","clk":"5322096279","pt":1646316359761,"mc":[{"id":"1.195532855","rc":[{"atb":[[3.05,3.64]],"id":42190933}],"con":true,"img":false}]}
{"op":"mcm","clk":"5322096287","pt":1646316359872,"mc":[{"id":"1.195532855","rc":[{"atl":[[5.1,8.27],[5.2,2.34],[5.4,66.39]],"id":38833999}],"con":true,"img":false}]}
{"op":"mcm","clk":"5322096303","pt":1646316360079,"mc":[{"id":"1.195532855","rc":[{"atl":[[5,2.56],[5.3,0],[5.2,13.37],[5.4,44.65]],"id":38833999}],"con":true,"img":false}]}
{"op":"mcm","clk":"5322096338","pt":1646316360440,"mc":[{"id":"1.195532855","rc":[{"atb":[[2.88,0]],"id":38833999},{"atb":[[3.05,1.65]],"id":42190933},{"atb":[[3.55,0]],"id":36042605}],"con":true,"img":false}]}
{"op":"mcm","clk":"5322096348","pt":1646316360548,"mc":[{"id":"1.195532855","rc":[{"atb":[[2.54,11.38],[2.46,30.96]],"id":38833999},{"atb":[[2.98,1.99]],"id":42190933}],"con":true,"img":false}]}
{"op":"mcm","clk":"5322096358","pt":1646316360651,"mc":[{"id":"1.195532855","rc":[{"atb":[[2.54,33.26],[2.62,1.65],[2.46,0]],"id":38833999},{"atl":[[5.2,22.89],[5.4,35.56]],"id":38833999},{"atb":[[3.5,1.65]],"id":36042605}],"con":true,"img":false}]}
{"op":"mcm","clk":"5322096411","pt":1646316361278,"mc":[{"id":"1.195532855","rc":[{"atb":[[2.98,0]],"id":42190933}],"con":true,"img":false}]}
{"op":"mcm","clk":"5322096423","pt":1646316361330,"mc":[{"id":"1.195532855","rc":[{"atb":[[3.05,3.64]],"id":42190933}],"con":true,"img":false}]}
{"op":"mcm","clk":"5322096464","pt":1646316361750,"mc":[{"id":"1.195532855","rc":[{"atl":[[2.54,37.23],[2.66,241.18]],"id":41064149}],"con":true,"img":false}]}
{"op":"mcm","clk":"5322096501","pt":1646316362067,"mc":[{"id":"1.195532855","rc":[{"atb":[[2.3,85.99]],"id":42609833}],"con":true,"img":false}]}
{"op":"mcm","clk":"5322096545","pt":1646316362383,"mc":[{"id":"1.195532855","rc":[{"atl":[[4.5,0]],"id":28603686}],"con":true,"img":false}]}
{"op":"mcm","clk":"5322096570","pt":1646316362545,"mc":[{"id":"1.195532855","rc":[{"atb":[[3.05,1.65]],"id":42190933}],"con":true,"img":false}]}
{"op":"mcm","clk":"5322096577","pt":1646316362649,"mc":[{"id":"1.195532855","rc":[{"atb":[[2.98,1.99]],"id":42190933}],"con":true,"img":false}]}
{"op":"mcm","clk":"5322096591","pt":1646316362755,"mc":[{"id":"1.195532855","rc":[{"atl":[[4.4,0],[4.2,3.61]],"id":42609833}],"con":true,"img":false}]}
{"op":"mcm","clk":"5322096613","pt":1646316362970,"mc":[{"id":"1.195532855","rc":[{"atl":[[4.1,4.04]],"id":42609833},{"atl":[[5.9,15.15]],"id":42190933}],"con":true,"img":false}]}
{"op":"mcm","clk":"5322096628","pt":1646316363079,"mc":[{"id":"1.195532855","rc":[{"atl":[[6.4,0]],"id":42190933}],"con":true,"img":false}]}
{"op":"mcm","clk":"5322096641","pt":1646316363184,"mc":[{"id":"1.195532855","rc":[{"atl":[[4.3,15.73],[4,3.61],[4.5,3.25],[4.2,0]],"id":42609833},{"atb":[[2.98,0]],"id":42190933}],"con":true,"img":false}]}
{"op":"mcm","clk":"5322096654","pt":1646316363238,"mc":[{"id":"1.195532855","rc":[{"atl":[[3.95,6.86]],"id":28603686},{"atb":[[3.05,3.64]],"id":42190933}],"con":true,"img":false}]}
{"op":"mcm","clk":"5322096666","pt":1646316363346,"mc":[{"id":"1.195532855","rc":[{"atl":[[4,0],[3.9,6.86]],"id":28603686},{"atl":[[3.95,2.19]],"id":42609833}],"con":true,"img":false}]}
{"op":"mcm","clk":"5322096682","pt":1646316363452,"mc":[{"id":"1.195532855","rc":[{"atl":[[3.85,2.31],[4.2,0]],"id":28603686}],"con":true,"img":false}]}
{"op":"mcm","clk":"5322096694","pt":1646316363556,"mc":[{"id":"1.195532855","rc":[{"atl":[[3.95,48.02],[4.1,16.94],[3.9,0]],"id":28603686}],"con":true,"img":false}]}
{"op":"mcm","clk":"5322096724","pt":1646316363878,"mc":[{"id":"1.195532855","rc":[{"atb":[[3.05,1.65]],"id":42190933}],"con":true,"img":false}]}
{"op":"mcm","clk":"5322096737","pt":1646316363933,"mc":[{"id":"1.195532855","rc":[{"atb":[[2.98,1.99]],"id":42190933}],"con":true,"img":false}]}
{"op":"mcm","clk":"5322096791","pt":1646316364463,"mc":[{"id":"1.195532855","rc":[{"atb":[[2.98,0],[2.14,307.02]],"id":42190933},{"atl":[[6.6,17.86]],"id":42190933}],"con":true,"img":false}]}
{"op":"mcm","clk":"5322096804","pt":1646316364568,"mc":[{"id":"1.195532855","rc":[{"atb":[[2.6,28.15],[2.62,5]],"id":28603686},{"atb":[[2.54,21.88],[2.58,13.04]],"id":38833999},{"atl":[[4.3,3.61],[4.1,16.94]],"id":42609833},{"atb":[[2.14,219.3],[3.05,3.64]],"id":42190933},{"atb":[[1.55,250]],"id":41064149},{"atl":[[2.6,3.16],[2.62,61.73]],"id":41064149},{"atb":[[2.74,143.68]],"id":36042605},{"atl":[[7.4,35.58]],"id":36042605}],"con":true,"img":false}]}
{"op":"mcm","clk":"5322096814","pt":1646316364673,"mc":[{"id":"1.195532855","rc":[{"atl":[[4.2,8.08]],"id":28603686}],"con":true,"img":false}]}
{"op":"mcm","clk":"5322096825","pt":1646316364780,"mc":[{"id":"1.195532855","rc":[{"atb":[[2.6,0],[2.62,23.59]],"id":28603686},{"atl":[[4.2,0]],"id":28603686},{"atl":[[2.6,72.64],[2.66,60.24]],"id":41064149}],"con":true,"img":false}]}
{"op":"mcm","clk":"5322096845","pt":1646316364935,"mc":[{"id":"1.195532855","rc":[{"atl":[[4.9,13.12]],"id":38833999}],"con":true,"img":false}]}
{"op":"mcm","clk":"5322096858","pt":1646316365039,"mc":[{"id":"1.195532855","rc":[{"atb":[[2.22,81.97]],"id":28603686},{"atl":[[4.3,33.91]],"id":28603686},{"atl":[[4.8,2.8]],"id":38833999}],"con":true,"img":false}]}
{"op":"mcm","clk":"5322096868","pt":1646316365146,"mc":[{"id":"1.195532855","rc":[{"atl":[[4.8,5.6],[5.1,0],[5.2,11.86]],"id":38833999},{"atb":[[3.05,1.65]],"id":42190933}],"con":true,"img":false}]}
{"op":"mcm","clk":"5322096881","pt":1646316365248,"mc":[{"id":"1.195532855","rc":[{"atl":[[5,12.56]],"id":38833999},{"atb":[[2.98,1.99]],"id":42190933}],"con":true,"img":false}]}
{"op":"mcm","clk":"5322096890","pt":1646316365353,"mc":[{"id":"1.195532855","rc":[{"atl":[[5.2,2.34]],"id":38833999},{"atl":[[14.5,0]],"id":42190933},{"atl":[[8,0],[8.8,0],[8.4,0]],"id":36042605}],"con":true,"img":false}]}
{"op":"mcm","clk":"5322096944","pt":1646316365878,"mc":[{"id":"1.195532855","rc":[{"atl":[[4.7,16.34]],"id":38833999},{"atb":[[2.98,0]],"id":42190933}],"con":true,"img":false}]}
{"op":"mcm","clk":"5322096956","pt":1646316365984,"mc":[{"id":"1.195532855","rc":[{"atb":[[3.05,3.64]],"id":42190933}],"con":true,"img":false}]}
{"op":"mcm","clk":"5322096967","pt":1646316366035,"mc":[{"id":"1.195532855","rc":[{"atb":[[2.12,0],[2.08,0],[2.16,0]],"id":28603686},{"atl":[[4,13.33],[4.3,3.61],[6.2,0],[4.1,4.04],[5.7,0],[5.9,0]],"id":28603686},{"atb":[[2.26,31.75],[2.2,0]],"id":38833999},{"atl":[[4.9,10.26],[5,2.56],[4.6,3.09]],"id":38833999}],"con":true,"img":false}]}
{"op":"mcm","clk":"5322096977","pt":1646316366140,"mc":[{"id":"1.195532855","rc":[{"atl":[[4.4,3.79]],"id":28603686},{"atl":[[2.6,118.04]],"id":41064149}],"con":true,"img":false}]}
{"op":"mcm","clk":"5322096986","pt":1646316366248,"mc":[{"id":"1.195532855","rc":[{"atl":[[4.4,0]],"id":28603686}],"con":true,"img":false}]}
{"op":"mcm","clk":"5322097001","pt":1646316366351,"mc":[{"id":"1.195532855","rc":[{"atl":[[2.6,72.64]],"id":41064149}],"con":true,"img":false}]}
{"op":"mcm","clk":"5322097030","pt":1646316366771,"mc":[{"id":"1.195532855","rc":[{"atb":[[3.05,1.65]],"id":42190933}],"con":true,"img":false}]}
{"op":"mcm","clk":"5322097036","pt":1646316366875,"mc":[{"id":"1.195532855","rc":[{"atl":[[3.85,9.95]],"id":28603686},{"atb":[[2.98,1.99]],"id":42190933}],"con":true,"img":false}]}
{"op":"mcm","clk":"5322097052","pt":1646316367081,"mc":[{"id":"1.195532855","rc":[{"atl":[[3.95,43.35]],"id":28603686},{"atl":[[4.8,16.13],[4.9,0]],"id":38833999}],"con":true,"img":false}]}
{"op":"mcm","clk":"5322097076","pt":1646316367247,"mc":[{"id":"1.195532855","rc":[{"atb":[[2.3,30.77]],"id":28603686},{"atl":[[4,0],[4.1,16.94],[4.2,12.5]],"id":28603686},{"atb":[[2.3,30.77],[2.26,0]],"id":38833999},{"atb":[[2.14,0],[2.1,36.36]],"id":42609833},{"atb":[[2.3,30.77],[2.26,0]],"id":42190933},{"atb":[[1.59,0],[1.54,74.07]],"id":41064149}],"con":true,"img":false}]}
{"op":"mcm","clk":"5322097097","pt":1646316367454,"mc":[{"id":"1.195532855","rc":[{"atb":[[2.98,0]],"id":42190933}],"con":true,"img":false}]}
{"op":"mcm","clk":"5322097108","pt":1646316367563,"mc":[{"id":"1.195532855","rc":[{"atb":[[3.05,3.64]],"id":42190933},{"atl":[[6.4,8.41]],"id":36042605}],"con":true,"img":false}]}
{"op":"mcm","clk":"5322097117","pt":1646316367662,"mc":[{"id":"1.195532855","rc":[{"atl":[[5,0],[4.1,31.46],[3.9,3.26]],"id":42609833},{"atl":[[6.6,45.82]],"id":42190933},{"atl":[[6.2,3.21],[7.4,18.12],[6.8,0],[7,41.41]],"id":36042605}],"con":true,"img":false}]}
{"op":"mcm","clk":"5322097124","pt":1646316367772,"mc":[{"id":"1.195532855","rc":[{"atl":[[3.85,2.31],[4.6,0]],"id":42609833},{"atl":[[6,7.01],[6.6,2.8]],"id":36042605}],"con":true,"img":false}]}
{"op":"mcm","clk":"5322097140","pt":1646316367980,"mc":[{"id":"1.195532855","rc":[{"atl":[[3.85,4.62],[4,0]],"id":42609833},{"atl":[[5.9,1.76]],"id":36042605}],"con":true,"img":false}]}
{"op":"mcm","clk":"5322097168","pt":1646316368243,"mc":[{"id":"1.195532855","rc":[{"atl":[[3.95,15.91],[4.1,70.72]],"id":28603686}],"con":true,"img":false}]}
{"op":"mcm","clk":"5322097197","pt":1646316368554,"mc":[{"id":"1.195532855","rc":[{"atb":[[3.05,1.65]],"id":42190933}],"con":true,"img":false}]}
{"op":"mcm","clk":"5322097206","pt":1646316368661,"mc":[{"id":"1.195532855","rc":[{"atl":[[3.95,2.19],[3.9,19.9]],"id":28603686},{"atb":[[2.98,1.99]],"id":42190933}],"con":true,"img":false}]}
{"op":"mcm","clk":"5322097244","pt":1646316369076,"mc":[{"id":"1.195532855","rc":[{"atl":[[3.95,41.83],[4.1,16.94]],"id":28603686}],"con":true,"img":false}]}
{"op":"mcm","clk":"5322097252","pt":1646316369179,"mc":[{"id":"1.195532855","rc":[{"atb":[[2.98,0]],"id":42190933}],"con":true,"img":false}]}
{"op":"mcm","clk":"5322097262","pt":1646316369284,"mc":[{"id":"1.195532855","rc":[{"atb":[[3.05,3.64]],"id":42190933}],"con":true,"img":false}]}
{"op":"mcm","clk":"5322097295","pt":1646316369547,"mc":[{"id":"1.195532855","rc":[{"atl":[[4.1,4.04]],"id":28603686},{"atl":[[3.95,15.75],[4.1,18.56]],"id":42609833},{"atb":[[1.57,0]],"id":41064149},{"atl":[[6.2,10.9]],"id":36042605}],"con":true,"img":false}]}
{"op":"mcm","clk":"5322097304","pt":1646316369652,"mc":[{"id":"1.195532855","rc":[{"atl":[[4.8,74.47]],"id":38833999}],"con":true,"img":false}]}
{"op":"mcm","clk":"5322097313","pt":1646316369755,"mc":[{"id":"1.195532855","rc":[{"atl":[[5.4,0]],"id":38833999}],"con":true,"img":false}]}
{"op":"mcm","clk":"5322097321","pt":1646316369861,"mc":[{"id":"1.195532855","rc":[{"atb":[[3.05,1.65]],"id":42190933}],"con":true,"img":false}]}
{"op":"mcm","clk":"5322097331","pt":1646316369967,"mc":[{"id":"1.195532855","rc":[{"atb":[[2.98,1.99]],"id":42190933}],"con":true,"img":false}]}
{"op":"mcm","clk":"5322097359","pt":1646316370278,"mc":[{"id":"1.195532855","rc":[{"atl":[[4.5,16.7]],"id":38833999}],"con":true,"img":false}]}
{"op":"mcm","clk":"5322097370","pt":1646316370385,"mc":[{"id":"1.195532855","rc":[{"atl":[[4.8,71.67],[4.5,33.04]],"id":38833999}],"con":true,"img":false}]}
{"op":"mcm","clk":"5322097380","pt":1646316370488,"mc":[{"id":"1.195532855","rc":[{"atl":[[4.4,3.42],[4.6,8.81],[4.7,0]],"id":38833999}],"con":true,"img":false}]}
{"op":"mcm","clk":"5322097402","pt":1646316370646,"mc":[{"id":"1.195532855","rc":[{"atl":[[4.6,3.09]],"id":38833999}],"con":true,"img":false}]}
{"op":"mcm","clk":"5322097421","pt":1646316370857,"mc":[{"id":"1.195532855","rc":[{"atb":[[2.98,0]],"id":42190933}],"con":true,"img":false}]}
{"op":"mcm","clk":"5322097432","pt":1646316370958,"mc":[{"id":"1.195532855","rc":[{"atb":[[3.05,3.64]],"id":42190933}],"con":true,"img":false}]}
{"op":"mcm","clk":"5322097495","pt":1646316371647,"mc":[{"id":"1.195532855","rc":[{"atb":[[3.05,1.65]],"id":42190933}],"con":true,"img":false}]}
{"op":"mcm","clk":"5322097504","pt":1646316371753,"mc":[{"id":"1.195532855","rc":[{"atb":[[2.98,1.99]],"id":42190933}],"con":true,"img":false}]}
{"op":"mcm","clk":"5322097526","pt":1646316371962,"mc":[{"id":"1.195532855","rc":[{"atl":[[4.6,14.2]],"id":38833999},{"atb":[[2.98,0]],"id":42190933}],"con":true,"img":false}]}
{"op":"mcm","clk":"5322097535","pt":1646316372071,"mc":[{"id":"1.195532855","rc":[{"atl":[[4.8,61.14]],"id":38833999},{"atb":[[3.05,3.64]],"id":42190933},{"atb":[[1.55,0]],"id":41064149}],"con":true,"img":false}]}
{"op":"mcm","clk":"5322097542","pt":1646316372173,"mc":[{"id":"1.195532855","rc":[{"atl":[[6.4,0]],"id":38833999}],"con":true,"img":false}]}
{"op":"mcm","clk":"5322097559","pt":1646316372380,"mc":[{"id":"1.195532855","rc":[{"atl":[[5.3,3.04]],"id":38833999}],"con":true,"img":false}]}
{"op":"mcm","clk":"5322097606","pt":1646316372856,"mc":[{"id":"1.195532855","rc":[{"atl":[[5.3,0]],"id":38833999}],"con":true,"img":false}]}
{"op":"mcm","clk":"5322097615","pt":1646316372967,"mc":[{"id":"1.195532855","rc":[{"atb":[[3.05,1.65]],"id":42190933}],"con":true,"img":false}]}
{"op":"mcm","clk":"5322097624","pt":1646316373067,"mc":[{"id":"1.195532855","rc":[{"atb":[[2.98,1.99]],"id":42190933}],"con":true,"img":false}]}
{"op":"mcm","clk":"5322097660","pt":1646316373449,"mc":[{"id":"1.195532855","rc":[{"atb":[[2.98,0]],"id":42190933}],"con":true,"img":false}]}
{"op":"mcm","clk":"5322097671","pt":1646316373555,"mc":[{"id":"1.195532855","rc":[{"atb":[[3.05,3.64]],"id":42190933}],"con":true,"img":false}]}
{"op":"mcm","clk":"5322097730","pt":1646316374181,"mc":[{"id":"1.195532855","rc":[{"atb":[[2.26,79.37]],"id":28603686},{"atl":[[4.4,29.41]],"id":28603686},{"atb":[[2.26,79.37]],"id":42190933},{"atl":[[7,30]],"id":42190933},{"atb":[[1.52,192.31]],"id":41064149},{"atl":[[2.66,90.36]],"id":41064149}],"con":true,"img":false}]}
{"op":"mcm","clk":"5322097739","pt":1646316374282,"mc":[{"id":"1.195532855","rc":[{"atb":[[3.05,1.65]],"id":42190933}],"con":true,"img":false}]}
{"op":"mcm","clk":"5322097747","pt":1646316374391,"mc":[{"id":"1.195532855","rc":[{"atb":[[2.98,1.99]],"id":42190933}],"con":true,"img":false}]}
{"op":"mcm","clk":"5322097772","pt":1646316374654,"mc":[{"id":"1.195532855","rc":[{"atb":[[2.98,0]],"id":42190933}],"con":true,"img":false}]}
{"op":"mcm","clk":"5322097782","pt":1646316374757,"mc":[{"id":"1.195532855","rc":[{"atb":[[3.05,3.64]],"id":42190933}],"con":true,"img":false}]}
{"op":"mcm","clk":"5322097820","pt":1646316375184,"mc":[{"id":"1.195532855","rc":[{"atl":[[4.3,16.7]],"id":38833999},{"atb":[[3.05,1.65]],"id":42190933}],"con":true,"img":false}]}
{"op":"mcm","clk":"5322097830","pt":1646316375289,"mc":[{"id":"1.195532855","rc":[{"atb":[[2.98,1.99]],"id":42190933}],"con":true,"img":false}]}
{"op":"mcm","clk":"5322097839","pt":1646316375394,"mc":[{"id":"1.195532855","rc":[{"atl":[[4.5,16.34],[4.2,3.82]],"id":38833999}],"con":true,"img":false}]}
{"op":"mcm","clk":"5322097860","pt":1646316375552,"mc":[{"id":"1.195532855","rc":[{"atl":[[4.4,15.18],[4.5,0],[4.1,3.82]],"id":38833999},{"atb":[[2.14,0]],"id":42190933}],"con":true,"img":false}]}
{"op":"mcm","clk":"5322097867","pt":1646316375659,"mc":[{"id":"1.195532855","rc":[{"atb":[[2.58,2.15],[2.56,18.46]],"id":38833999},{"atl":[[4.3,28.82],[4,2.11]],"id":38833999},{"atb":[[1.7,0]],"id":41064149},{"atb":[[3.1,0],[3.45,3.01],[2.92,52.08],[3.4,7.62]],"id":36042605},{"atl":[[6.2,19.67],[6,0]],"id":36042605}],"con":true,"img":false}]}
{"op":"mcm","clk":"5322097879","pt":1646316375769,"mc":[{"id":"1.195532855","rc":[{"atb":[[2.54,0],[2.56,28.01]],"id":38833999},{"atl":[[4.4,3.42]],"id":38833999},{"atb":[[2.98,0]],"id":42190933},{"atb":[[1.63,56.4]],"id":41064149}],"con":true,"img":false}]}
{"op":"mcm","clk":"5322097891","pt":1646316375871,"mc":[{"id":"1.195532855","rc":[{"atb":[[2.5,3.17]],"id":38833999},{"atb":[[3.05,3.64]],"id":42190933},{"atb":[[1.62,4.88],[1.69,3.29]],"id":41064149},{"atb":[[3.4,11.2]],"id":36042605}],"con":true,"img":false}]}
{"op":"mcm","clk":"5322097913","pt":1646316376079,"mc":[{"id":"1.195532855","rc":[{"atb":[[2.5,0]],"id":38833999},{"atl":[[4,6.59]],"id":38833999}],"con":true,"img":false}]}
{"op":"mcm","clk":"5322097922","pt":1646316376183,"mc":[{"id":"1.195532855","rc":[{"atl":[[4.3,12.12]],"id":38833999},{"atb":[[1.01,4806.04]],"id":42190933}],"con":true,"img":false}]}
{"op":"mcm","clk":"5322097942","pt":1646316376395,"mc":[{"id":"1.195532855","rc":[{"atb":[[2.06,94.34]],"id":42609833},{"atl":[[4.1,50.82]],"id":42609833},{"atb":[[1.01,4808.03]],"id":42190933},{"atb":[[1.62,0]],"id":41064149},{"atl":[[6.6,20.66]],"id":36042605}],"con":true,"img":false}]}
{"op":"mcm","clk":"5322097964","pt":1646316376553,"mc":[{"id":"1.195532855","rc":[{"atl":[[4.2,16.32]],"id":38833999},{"atb":[[1.01,4806.04]],"id":42190933}],"con":true,"img":false}]}
{"op":"mcm","clk":"5322097975","pt":1646316376657,"mc":[{"id":"1.195532855","rc":[{"atl":[[4.3,0]],"id":38833999},{"atl":[[5.6,0],[5.2,0],[5.4,0]],"id":42609833},{"atb":[[3.1,1.99]],"id":42190933}],"con":true,"img":false}]}
{"op":"mcm","clk":"5322098105","pt":1646316377772,"mc":[{"id":"1.195532855","rc":[{"atl":[[3.95,20.48]],"id":42609833},{"atl":[[6,8.56]],"id":36042605}],"con":true,"img":false}]}
{"op":"mcm","clk":"5322098121","pt":1646316377874,"mc":[{"id":"1.195532855","rc":[{"atl":[[3.95,37.02],[4.1,36.3],[3.8,4.06]],"id":42609833},{"atl":[[6.6,84.38],[7,9.13]],"id":36042605}],"con":true,"img":false}]}
{"op":"mcm","clk":"5322098132","pt":1646316377980,"mc":[{"id":"1.195532855","rc":[{"atl":[[3.95,32.29],[3.9,0],[3.75,2.46],[4.7,7.05]],"id":42609833},{"atb":[[1.69,0]],"id":41064149},{"atb":[[3.4,6.69]],"id":36042605},{"atl":[[6.4,0]],"id":36042605}],"con":true,"img":false}]}
{"op":"mcm","clk":"5322098154","pt":1646316378191,"mc":[{"id":"1.195532855","rc":[{"atl":[[3.85,2.31],[3.75,6.52]],"id":42609833}],"con":true,"img":false}]}
{"op":"mcm","clk":"5322098178","pt":1646316378401,"mc":[{"id":"1.195532855","rc":[{"atl":[[4.7,2.93]],"id":42609833}],"con":true,"img":false}]}
{"op":"mcm","clk":"5322098314","pt":1646316379560,"mc":[{"id":"1.195532855","rc":[{"atl":[[6.8,8.85]],"id":36042605}],"con":true,"img":false}]}
{"op":"mcm","clk":"5322098336","pt":1646316379773,"mc":[{"id":"1.195532855","rc":[{"atl":[[4.8,2.8],[4.2,51.28]],"id":38833999}],"con":true,"img":false}]}
{"op":"mcm","clk":"5322098420","pt":1646316380664,"mc":[{"id":"1.195532855","rc":[{"atl":[[6.8,0]],"id":36042605}],"con":true,"img":false}]}
{"op":"mcm","clk":"5322098430","pt":1646316380769,"mc":[{"id":"1.195532855","rc":[{"atl":[[3.85,16.35]],"id":42609833},{"atb":[[3.3,41.4],[3.4,3.11]],"id":36042605},{"atl":[[6.4,17.12],[6.2,10.9]],"id":36042605}],"con":true,"img":false}]}
{"op":"mcm","clk":"5322098439","pt":1646316380873,"mc":[{"id":"1.195532855","rc":[{"atb":[[2.22,204.92]],"id":42190933},{"atl":[[7.4,39.06]],"id":42190933}],"con":true,"img":false}]}
{"op":"mcm","clk":"5322098448","pt":1646316380978,"mc":[{"id":"1.195532855","rc":[{"atb":[[2.22,122.95]],"id":28603686},{"atl":[[4.6,41.67]],"id":28603686},{"atb":[[2.22,122.95]],"id":42190933},{"atb":[[1.5,250]],"id":41064149},{"atl":[[2.7,147.06]],"id":41064149}],"con":true,"img":false}]}
{"op":"mcm","clk":"5322098523","pt":1646316381766,"mc":[{"id":"1.195532855","rc":[{"atl":[[13.5,0]],"id":42190933},{"atl":[[2.74,0]],"id":41064149}],"con":true,"img":false}]}
{"op":"mcm","clk":"5322098635","pt":1646316383088,"mc":[{"id":"1.195532855","rc":[{"atl":[[7,34.13]],"id":36042605}],"con":true,"img":false}]}
{"op":"mcm","clk":"5322098643","pt":1646316383192,"mc":[{"id":"1.195532855","rc":[{"atl":[[7,27.46]],"id":36042605}],"con":true,"img":false}]}
{"op":"mcm","clk":"5322098653","pt":1646316383295,"mc":[{"id":"1.195532855","rc":[{"atb":[[2.26,79.37]],"id":38833999},{"atl":[[4.4,32.83]],"id":38833999}],"con":true,"img":false}]}
{"op":"mcm","clk":"5322098754","pt":1646316384401,"mc":[{"id":"1.195532855","rc":[{"atb":[[3.05,1.99]],"id":42190933}],"con":true,"img":false}]}
{"op":"mcm","clk":"5322098759","pt":1646316384508,"mc":[{"id":"1.195532855","rc":[{"atb":[[3.15,1.65]],"id":42190933}],"con":true,"img":false}]}
{"op":"mcm","clk":"5322098795","pt":1646316384877,"mc":[{"id":"1.195532855","rc":[{"atl":[[2.6,89.78]],"id":41064149}],"con":true,"img":false}]}
{"op":"mcm","clk":"5322098826","pt":1646316385191,"mc":[{"id":"1.195532855","rc":[{"atb":[[3.1,0]],"id":42190933}],"con":true,"img":false}]}
{"op":"mcm","clk":"5322098836","pt":1646316385297,"mc":[{"id":"1.195532855","rc":[{"atb":[[3.05,3.98]],"id":42190933}],"con":true,"img":false}]}
{"op":"mcm","clk":"5322098870","pt":1646316385561,"mc":[{"id":"1.195532855","rc":[{"atl":[[4,11.59]],"id":38833999}],"con":true,"img":false}]}
{"op":"mcm","clk":"5322098880","pt":1646316385676,"mc":[{"id":"1.195532855","rc":[{"atl":[[3.95,11.59],[4.1,0]],"id":38833999}],"con":true,"img":false}]}
{"op":"mcm","clk":"5322098891","pt":1646316385770,"mc":[{"id":"1.195532855","rc":[{"atl":[[3.95,27.21]],"id":38833999}],"con":true,"img":false}]}
{"op":"mcm","clk":"5322098900","pt":1646316385877,"mc":[{"id":"1.195532855","rc":[{"atl":[[4,7.11],[3.9,2.25]],"id":38833999},{"atl":[[2.6,72.64],[2.62,66.01]],"id":41064149}],"con":true,"img":false}]}
{"op":"mcm","clk":"5322098908","pt":1646316385981,"mc":[{"id":"1.195532855","rc":[{"atl":[[2.62,61.73]],"id":41064149}],"con":true,"img":false}]}
{"op":"mcm","clk":"5322098919","pt":1646316386090,"mc":[{"id":"1.195532855","rc":[{"atl":[[3.9,9.27]],"id":38833999}],"con":true,"img":false}]}
{"op":"mcm","clk":"5322098934","pt":1646316386299,"mc":[{"id":"1.195532855","rc":[{"atl":[[3.95,11.59]],"id":38833999}],"con":true,"img":false}]}
{"op":"mcm","clk":"5322098966","pt":1646316386773,"mc":[{"id":"1.195532855","rc":[{"atb":[[3.15,3.65]],"id":42190933}],"con":true,"img":false}]}
{"op":"mcm","clk":"5322099024","pt":1646316387475,"mc":[{"id":"1.195532855","rc":[{"atb":[[2.02,147.06]],"id":42609833},{"atl":[[3.95,52.63]],"id":42609833}],"con":true,"img":false}]}
{"op":"mcm","clk":"5322099034","pt":1646316387568,"mc":[{"id":"1.195532855","rc":[{"atb":[[2.18,211.86]],"id":28603686},{"atl":[[4.8,65.79]],"id":28603686},{"atb":[[2.18,211.86]],"id":42190933},{"atb":[[1.48,250]],"id":41064149}],"con":true,"img":false}]}
{"op":"mcm","clk":"5322099057","pt":1646316387782,"mc":[{"id":"1.195532855","rc":[{"atb":[[2.54,6.32]],"id":28603686},{"atb":[[2.12,0],[2.08,0],[2.16,0]],"id":38833999},{"atl":[[6,0]],"id":38833999},{"atb":[[3.05,1.99]],"id":42190933},{"atb":[[1.74,0]],"id":41064149}],"con":true,"img":false}]}
{"op":"mcm","clk":"5322099073","pt":1646316387884,"mc":[{"id":"1.195532855","rc":[{"atl":[[3.85,37.51],[3.95,36.09],[3.7,4.66]],"id":42609833},{"atb":[[1.02,1.99]],"id":42190933},{"atb":[[1.63,11],[1.61,102.18]],"id":41064149},{"atl":[[6.4,59.56],[6.6,20.66]],"id":36042605}],"con":true,"img":false}]}
{"op":"mcm","clk":"5322099087","pt":1646316387990,"mc":[{"id":"1.195532855","rc":[{"atb":[[2.54,2.5]],"id":28603686},{"atl":[[4.3,4.38]],"id":38833999}],"con":true,"img":false}]}
{"op":"mcm","clk":"5322099100","pt":1646316388094,"mc":[{"id":"1.195532855","rc":[{"atl":[[3.8,0],[3.75,2.46],[3.65,7.29]],"id":42609833}],"con":true,"img":false}]}
{"op":"mcm","clk":"5322099107","pt":1646316388199,"mc":[{"id":"1.195532855","rc":[{"atl":[[3.8,14.29]],"id":42609833},{"atb":[[1.77,0],[1.66,2.15]],"id":41064149}],"con":true,"img":false}]}
{"op":"mcm","clk":"5322099130","pt":1646316388407,"mc":[{"id":"1.195532855","rc":[{"atb":[[1.66,29.39]],"id":41064149}],"con":true,"img":false}]}
{"op":"mcm","clk":"5322099139","pt":1646316388459,"mc":[{"id":"1.195532855","rc":[{"atb":[[3.05,0]],"id":42190933}],"con":true,"img":false}]}
{"op":"mcm","clk":"5322099146","pt":1646316388564,"mc":[{"id":"1.195532855","rc":[{"atl":[[4.3,0]],"id":38833999},{"atb":[[1.02,3.98]],"id":42190933}],"con":true,"img":false}]}
{"op":"mcm","clk":"5322099246","pt":1646316389670,"mc":[{"id":"1.195532855","rc":[{"atb":[[1.78,0]],"id":41064149}],"con":true,"img":false}]}
{"op":"mcm","clk":"5322099258","pt":1646316389775,"mc":[{"id":"1.195532855","rc":[{"atl":[[4,47.43],[4.2,16.32]],"id":38833999},{"atb":[[1.56,178.57],[1.67,1.99],[1.61,78.19]],"id":41064149},{"atl":[[7.4,41.56]],"id":36042605}],"con":true,"img":false}]}
{"op":"mcm","clk":"5322099267","pt":1646316389881,"mc":[{"id":"1.195532855","rc":[{"atb":[[2.22,122.95]],"id":38833999},{"atl":[[4.6,44.76]],"id":38833999}],"con":true,"img":false}]}
{"op":"mcm","clk":"5322099298","pt":1646316390095,"mc":[{"id":"1.195532855","rc":[{"atl":[[6.4,4.32]],"id":42190933},{"atl":[[6.4,63.78]],"id":36042605}],"con":true,"img":false}]}
{"op":"mcm","clk":"5322099320","pt":1646316390304,"mc":[{"id":"1.195532855","rc":[{"atl":[[6.4,15.96],[6.6,17.86]],"id":42190933}],"con":true,"img":false}]}
{"op":"mcm","clk":"5322099334","pt":1646316390409,"mc":[{"id":"1.195532855","rc":[{"atl":[[4.2,19.99]],"id":38833999}],"con":true,"img":false}]}
{"op":"mcm","clk":"5322099350","pt":1646316390567,"mc":[{"id":"1.195532855","rc":[{"atl":[[4.2,16.32]],"id":38833999},{"atl":[[6.4,59.56]],"id":36042605}],"con":true,"img":false}]}
{"op":"mcm","clk":"5322099434","pt":1646316391508,"mc":[{"id":"1.195532855","rc":[{"atl":[[3.8,0],[3.75,17.01]],"id":42609833}],"con":true,"img":false}]}
{"op":"mcm","clk":"5322099449","pt":1646316391717,"mc":[{"id":"1.195532855","rc":[{"atl":[[4,12.67],[4.5,3.68]],"id":28603686}],"con":true,"img":false}]}
{"op":"mcm","clk":"5322099490","pt":1646316392092,"mc":[{"id":"1.195532855","rc":[{"atl":[[4.5,0]],"id":28603686}],"con":true,"img":false}]}
{"op":"mcm","clk":"5322099495","pt":1646316392192,"mc":[{"id":"1.195532855","rc":[{"atl":[[4,0]],"id":28603686}],"con":true,"img":false}]}
{"op":"mcm","clk":"5322099541","pt":1646316392716,"mc":[{"id":"1.195532855","rc":[{"atb":[[1.56,0],[1.58,172.41]],"id":41064149}],"con":true,"img":false}]}
{"op":"mcm","clk":"5322099580","pt":1646316393085,"mc":[{"id":"1.195532855","rc":[{"atb":[[1.62,26.88],[1.55,24.04]],"id":41064149}],"con":true,"img":false}]}
{"op":"mcm","clk":"5322099591","pt":1646316393197,"mc":[{"id":"1.195532855","rc":[{"atb":[[3,4.89]],"id":42190933},{"atb":[[1.62,0]],"id":41064149}],"con":true,"img":false}]}
{"op":"mcm","clk":"5322099625","pt":1646316393611,"mc":[{"id":"1.195532855","rc":[{"atb":[[1.55,0]],"id":41064149}],"con":true,"img":false}]}
{"op":"mcm","clk":"5322099644","pt":1646316393821,"mc":[{"id":"1.195532855","rc":[{"atb":[[3,1.68]],"id":42190933}],"con":true,"img":false}]}
{"op":"mcm","clk":"5322099924","pt":1646316396418,"mc":[{"id":"1.195532855","rc":[{"atb":[[2.18,211.86]],"id":38833999},{"atl":[[4.8,68.59]],"id":38833999}],"con":true,"img":false}]}
{"op":"mcm","clk":"5322099955","pt":1646316396676,"mc":[{"id":"1.195532855","rc":[{"atl":[[5.8,0]],"id":38833999}],"con":true,"img":false}]}
{"op":"mcm","clk":"5322100014","pt":1646316397377,"mc":[{"id":"1.195532855","rc":[{"atl":[[3.75,23.53]],"id":42609833}],"con":true,"img":false}]}
{"op":"mcm","clk":"5322100034","pt":1646316397692,"mc":[{"id":"1.195532855","rc":[{"atl":[[3.85,16.35],[3.65,12.4],[3.75,47.43]],"id":42609833}],"con":true,"img":false}]}
{"op":"mcm","clk":"5322100045","pt":1646316397801,"mc":[{"id":"1.195532855","rc":[{"atb":[[2.62,18.59],[2.56,10.03]],"id":28603686},{"atl":[[5.3,0]],"id":28603686},{"atb":[[2.44,0],[2.62,3.8],[2.56,9.55],[2.36,0],[2.28,0]],"id":38833999},{"atl":[[3.95,0],[4.1,32.26]],"id":38833999},{"atl":[[3.7,0],[3.75,83.52]],"id":42609833},{"atl":[[6.4,42.44],[6.2,30.13]],"id":36042605}],"con":true,"img":false}]}
{"op":"mcm","clk":"5322100053","pt":1646316397903,"mc":[{"id":"1.195532855","rc":[{"atb":[[2.62,1.65]],"id":38833999},{"atl":[[3.85,2.31],[3.65,7.74],[3.75,77]],"id":42609833}],"con":true,"img":false}]}
{"op":"mcm","clk":"5322100067","pt":1646316398020,"mc":[{"id":"1.195532855","rc":[{"atb":[[2.56,0],[2.54,3.31],[2.6,18.46],[2.58,25.27],[2.62,15.53]],"id":38833999},{"atl":[[4,7.11],[4.1,69.26]],"id":38833999},{"atb":[[1.99,250]],"id":42609833},{"atl":[[3.85,37.4]],"id":42609833}],"con":true,"img":false}]}
{"op":"mcm","clk":"5322100077","pt":1646316398117,"mc":[{"id":"1.195532855","rc":[{"atl":[[3.85,72.49],[3.75,40.91]],"id":42609833}],"con":true,"img":false}]}
{"op":"mcm","clk":"5322100089","pt":1646316398223,"mc":[{"id":"1.195532855","rc":[{"atb":[[2.54,2.5],[2.6,0],[2.58,36.16]],"id":38833999}],"con":true,"img":false}]}
{"op":"mcm","clk":"5322100120","pt":1646316398487,"mc":[{"id":"1.195532855","rc":[{"atb":[[2.52,3.63]],"id":38833999}],"con":true,"img":false}]}
{"op":"mcm","clk":"5322100134","pt":1646316398602,"mc":[{"id":"1.195532855","rc":[{"atb":[[2.52,0]],"id":38833999}],"con":true,"img":false}]}
{"op":"mcm","clk":"5322100437","pt":1646316401641,"mc":[{"id":"1.195532855","rc":[{"atl":[[2.56,11.4]],"id":41064149}],"con":true,"img":false}]}
{"op":"mcm","clk":"5322100460","pt":1646316401848,"mc":[{"id":"1.195532855","rc":[{"atl":[[2.56,0],[2.6,0],[2.58,138.72]],"id":41064149}],"con":true,"img":false}]}
{"op":"mcm","clk":"5322100482","pt":1646316402011,"mc":[{"id":"1.195532855","rc":[{"atl":[[3.85,169.79],[3.75,17]],"id":42609833}],"con":true,"img":false}]}
{"op":"mcm","clk":"5322100527","pt":1646316402426,"mc":[{"id":"1.195532855","rc":[{"atb":[[2.54,33.51],[2.58,13.04]],"id":38833999}],"con":true,"img":false}]}
{"op":"mcm","clk":"5322100566","pt":1646316402840,"mc":[{"id":"1.195532855","rc":[{"atb":[[2.72,0],[2.56,0],[2.42,30.77]],"id":28603686},{"atl":[[4.3,30.3],[4.1,37]],"id":38833999},{"atl":[[6.2,10.9],[6,28.56]],"id":36042605}],"con":true,"img":false}]}
{"op":"mcm","clk":"5322100581","pt":1646316402951,"mc":[{"id":"1.195532855","rc":[{"atb":[[2.66,19.86]],"id":28603686}],"con":true,"img":false}]}
{"op":"mcm","clk":"5322100587","pt":1646316403049,"mc":[{"id":"1.195532855","rc":[{"atb":[[2.54,38.17],[2.62,0]],"id":28603686}],"con":true,"img":false}]}
{"op":"mcm","clk":"5322100606","pt":1646316403214,"mc":[{"id":"1.195532855","rc":[{"atb":[[2.74,0],[2.66,0]],"id":28603686},{"atl":[[3.85,134.7],[3.65,24.75]],"id":42609833}],"con":true,"img":false}]}
{"op":"mcm","clk":"5322100617","pt":1646316403324,"mc":[{"id":"1.195532855","rc":[{"atb":[[2.66,1.99]],"id":28603686},{"atb":[[2.6,31.08],[2.58,2.15]],"id":38833999}],"con":true,"img":false}]}
{"op":"mcm","clk":"5322100630","pt":1646316403426,"mc":[{"id":"1.195532855","rc":[{"atb":[[2.54,60.56]],"id":28603686}],"con":true,"img":false}]}
{"op":"mcm","clk":"5322100726","pt":1646316404325,"mc":[{"id":"1.195532855","rc":[{"atl":[[4,4.24],[3.95,53.04]],"id":42609833}],"con":true,"img":false}]}
{"op":"mcm","clk":"5322100745","pt":1646316404530,"mc":[{"id":"1.195532855","rc":[{"atl":[[4,0]],"id":42609833}],"con":true,"img":false}]}
{"op":"mcm","clk":"5322100779","pt":1646316404850,"mc":[{"id":"1.195532855","rc":[{"atl":[[4.1,68.01]],"id":38833999}],"con":true,"img":false}]}
{"op":"mcm","clk":"5322100819","pt":1646316405320,"mc":[{"id":"1.195532855","rc":[{"atl":[[4.1,44.46]],"id":38833999}],"con":true,"img":false}]}
{"op":"mcm","clk":"5322100863","pt":1646316405840,"mc":[{"id":"1.195532855","rc":[{"atl":[[3.95,43.4]],"id":28603686},{"atl":[[4.1,37]],"id":38833999}],"con":true,"img":false}]}
{"op":"mcm","clk":"5322100879","pt":1646316405945,"mc":[{"id":"1.195532855","rc":[{"atl":[[2.56,5.7]],"id":41064149}],"con":true,"img":false}]}
{"op":"mcm","clk":"5322100900","pt":1646316406256,"mc":[{"id":"1.195532855","rc":[{"atl":[[2.56,0]],"id":41064149}],"con":true,"img":false}]}
{"op":"mcm","clk":"5322100924","pt":1646316406425,"mc":[{"id":"1.195532855","rc":[{"atl":[[2.58,25.32],[2.62,258.36]],"id":41064149}],"con":true,"img":false}]}
{"op":"mcm","clk":"5322100968","pt":1646316406950,"mc":[{"id":"1.195532855","rc":[{"atl":[[3.95,41.83]],"id":28603686}],"con":true,"img":false}]}
{"op":"mcm","clk":"5322100996","pt":1646316407216,"mc":[{"id":"1.195532855","rc":[{"atl":[[3.95,47.52]],"id":28603686}],"con":true,"img":false}]}
{"op":"mcm","clk":"5322101001","pt":1646316407316,"mc":[{"id":"1.195532855","rc":[{"atb":[[2.54,24.89]],"id":28603686}],"con":true,"img":false}]}
{"op":"mcm","clk":"5322101010","pt":1646316407422,"mc":[{"id":"1.195532855","rc":[{"atb":[[2.46,42.31]],"id":28603686},{"atl":[[4.5,6.41]],"id":38833999}],"con":true,"img":false}]}
{"op":"mcm","clk":"5322101023","pt":1646316407633,"mc":[{"id":"1.195532855","rc":[{"atb":[[2.54,2.5],[2.58,33.16]],"id":38833999}],"con":true,"img":false}]}
{"op":"mcm","clk":"5322101040","pt":1646316407844,"mc":[{"id":"1.195532855","rc":[{"atl":[[4.5,0]],"id":38833999}],"con":true,"img":false}]}
{"op":"mcm","clk":"5322101047","pt":1646316407955,"mc":[{"id":"1.195532855","rc":[{"atl":[[4.1,67.3]],"id":38833999}],"con":true,"img":false}]}
{"op":"mcm","clk":"5322101054","pt":1646316408059,"mc":[{"id":"1.195532855","rc":[{"atb":[[2.52,3.31]],"id":28603686},{"atl":[[4.3,0]],"id":38833999}],"con":true,"img":false}]}
{"op":"mcm","clk":"5322101086","pt":1646316408365,"mc":[{"id":"1.195532855","rc":[{"atb":[[2.52,0]],"id":28603686},{"atl":[[3.95,41.83]],"id":28603686}],"con":true,"img":false}]}
{"op":"mcm","clk":"5322101097","pt":1646316408432,"mc":[{"id":"1.195532855","rc":[{"atb":[[2.68,1.65]],"id":28603686}],"con":true,"img":false}]}
{"op":"mcm","clk":"5322101236","pt":1646316409637,"mc":[{"id":"1.195532855","rc":[{"atl":[[3.9,25.59]],"id":28603686}],"con":true,"img":false}]}
{"op":"mcm","clk":"5322101295","pt":1646316410257,"mc":[{"id":"1.195532855","rc":[{"atl":[[3.9,19.9]],"id":28603686}],"con":true,"img":false}]}
{"op":"mcm","clk":"5322101339","pt":1646316410633,"mc":[{"id":"1.195532855","rc":[{"atl":[[4.1,84.69]],"id":42609833}],"con":true,"img":false}]}
{"op":"mcm","clk":"5322101520","pt":1646316412565,"mc":[{"id":"1.195532855","rc":[{"atb":[[2.54,62.2],[2.46,5]],"id":28603686}],"con":true,"img":false}]}
{"op":"mcm","clk":"5322101638","pt":1646316413562,"mc":[{"id":"1.195532855","rc":[{"atl":[[3.85,16.42]],"id":28603686}],"con":true,"img":false}]}
{"op":"mcm","clk":"5322101660","pt":1646316413726,"mc":[{"id":"1.195532855","rc":[{"atl":[[3.8,19.9],[3.9,0]],"id":28603686},{"atl":[[3.75,25.64]],"id":42609833}],"con":true,"img":false}]}
{"op":"mcm","clk":"5322101673","pt":1646316413826,"mc":[{"id":"1.195532855","rc":[{"atl":[[3.75,2.46]],"id":28603686}],"con":true,"img":false}]}
{"op":"mcm","clk":"5322101688","pt":1646316413937,"mc":[{"id":"1.195532855","rc":[{"atl":[[4.3,9.17],[3.85,56.56],[3.95,12.14],[3.8,33.83]],"id":28603686}],"con":true,"img":false}]}
{"op":"mcm","clk":"5322101705","pt":1646316414136,"mc":[{"id":"1.195532855","rc":[{"atl":[[3.85,48.92]],"id":28603686}],"con":true,"img":false}]}
{"op":"mcm","clk":"5322101720","pt":1646316414254,"mc":[{"id":"1.195532855","rc":[{"atl":[[3.95,2.19]],"id":28603686},{"atl":[[3.75,17]],"id":42609833}],"con":true,"img":false}]}
{"op":"mcm","clk":"5322101730","pt":1646316414350,"mc":[{"id":"1.195532855","rc":[{"atl":[[5,2.39]],"id":28603686},{"atl":[[6.6,24.29]],"id":36042605}],"con":true,"img":false}]}
{"op":"mcm","clk":"5322101734","pt":1646316414447,"mc":[{"id":"1.195532855","rc":[{"atl":[[4.3,3.61]],"id":28603686}],"con":true,"img":false}]}
{"op":"mcm","clk":"5322101772","pt":1646316414861,"mc":[{"id":"1.195532855","rc":[{"atl":[[6.6,20.66]],"id":36042605}],"con":true,"img":false}]}
{"op":"mcm","clk":"5322102012","pt":1646316417545,"mc":[{"id":"1.195532855","rc":[{"atl":[[2.6,15.07]],"id":41064149}],"con":true,"img":false}]}
{"op":"mcm","clk":"5322102030","pt":1646316417757,"mc":[{"id":"1.195532855","rc":[{"atl":[[2.6,128.47],[2.62,61.73]],"id":41064149}],"con":true,"img":false}]}
{"op":"mcm","clk":"5322102049","pt":1646316417963,"mc":[{"id":"1.195532855","rc":[{"atl":[[2.6,113.4]],"id":41064149}],"con":true,"img":false}]}
{"op":"mcm","clk":"5322102058","pt":1646316418064,"mc":[{"id":"1.195532855","rc":[{"atb":[[2.54,59.7],[2.38,0],[2.46,0]],"id":28603686},{"spn":2.68,"spf":1.0,"id":28603686},{"atb":[[2.58,48.79]],"id":38833999},{"atl":[[4.1,37],[4.2,47.57]],"id":38833999},{"spn":3.26,"spf":"NaN","id":38833999},{"spn":3.16,"spf":"NaN","id":42609833},{"spn":4.52,"spf":"NaN","id":42190933},{"spn":1.67,"spf":1.0,"id":41064149},{"spn":4.7,"spf":"NaN","id":36042605}],"con":true,"img":false}]}
{"op":"mcm","clk":"5322102093","pt":1646316418434,"mc":[{"id":"1.195532855","rc":[{"atl":[[6.6,24.32]],"id":42190933}],"con":true,"img":false}]}
{"op":"mcm","clk":"5322102106","pt":1646316418593,"mc":[{"id":"1.195532855","rc":[{"atb":[[2.56,3.91],[2.58,33.16]],"id":38833999}],"con":true,"img":false}]}
{"op":"mcm","clk":"5322102142","pt":1646316418955,"mc":[{"id":"1.195532855","rc":[{"atb":[[2.56,0]],"id":38833999}],"con":true,"img":false}]}
{"op":"mcm","clk":"5322102149","pt":1646316419057,"mc":[{"id":"1.195532855","rc":[{"atl":[[6.6,17.86]],"id":42190933}],"con":true,"img":false}]}
{"op":"mcm","clk":"5322102272","pt":1646316420476,"mc":[{"id":"1.195532855","rc":[{"atb":[[2.08,3.88]],"id":42609833},{"atb":[[1.57,6.38]],"id":41064149}],"con":true,"img":false}]}
{"op":"mcm","clk":"5322102296","pt":1646316420651,"mc":[{"id":"1.195532855","rc":[{"atb":[[2.52,5.76]],"id":28603686}],"con":true,"img":false}]}
{"op":"mcm","clk":"5322102342","pt":1646316421062,"mc":[{"id":"1.195532855","rc":[{"atl":[[6.4,18.96]],"id":42190933},{"atl":[[6.4,45.49]],"id":36042605}],"con":true,"img":false}]}
{"op":"mcm","clk":"5322102389","pt":1646316421537,"mc":[{"id":"1.195532855","rc":[{"atl":[[6.4,15.96]],"id":42190933},{"atl":[[6.4,42.44]],"id":36042605}],"con":true,"img":false}]}
{"op":"mcm","clk":"5322102397","pt":1646316421642,"mc":[{"id":"1.195532855","rc":[{"atb":[[2.52,0]],"id":28603686}],"con":true,"img":false}]}
{"op":"mcm","clk":"5322102431","pt":1646316421953,"mc":[{"id":"1.195532855","rc":[{"atl":[[3.9,7.02]],"id":38833999}],"con":true,"img":false}]}
{"op":"mcm","clk":"5322102453","pt":1646316422164,"mc":[{"id":"1.195532855","rc":[{"atl":[[3.85,2.31],[3.9,0]],"id":38833999}],"con":true,"img":false}]}
{"op":"mcm","clk":"5322102476","pt":1646316422370,"mc":[{"id":"1.195532855","rc":[{"atl":[[3.95,15.94]],"id":38833999}],"con":true,"img":false}]}
{"op":"mcm","clk":"5322102483","pt":1646316422430,"mc":[{"id":"1.195532855","rc":[{"atl":[[3.85,42.45]],"id":28603686},{"atl":[[3.85,0]],"id":38833999}],"con":true,"img":false}]}
{"op":"mcm","clk":"5322102493","pt":1646316422538,"mc":[{"id":"1.195532855","rc":[{"atl":[[4,70.07],[4.1,0],[4.2,51.15]],"id":38833999}],"con":true,"img":false}]}
{"op":"mcm","clk":"5322102498","pt":1646316422640,"mc":[{"id":"1.195532855","rc":[{"atl":[[4.2,47.57]],"id":38833999}],"con":true,"img":false}]}
{"op":"mcm","clk":"5322102532","pt":1646316422954,"mc":[{"id":"1.195532855","rc":[{"atl":[[3.85,44.41]],"id":28603686}],"con":true,"img":false}]}
{"op":"mcm","clk":"5322102542","pt":1646316423063,"mc":[{"id":"1.195532855","rc":[{"atb":[[2.56,62.16],[2.6,0]],"id":38833999},{"atl":[[4,65.07],[4.4,62.24],[4.2,16.32]],"id":38833999}],"con":true,"img":false}]}
{"op":"mcm","clk":"5322102554","pt":1646316423168,"mc":[{"id":"1.195532855","rc":[{"atl":[[4.3,3.68]],"id":38833999}],"con":true,"img":false}]}
{"op":"mcm","clk":"5322102562","pt":1646316423272,"mc":[{"id":"1.195532855","rc":[{"atl":[[3.75,5.92]],"id":28603686},{"atb":[[2.56,124.01],[2.58,2.15]],"id":38833999}],"con":true,"img":false}]}
{"op":"mcm","clk":"5322102579","pt":1646316423475,"mc":[{"id":"1.195532855","rc":[{"atl":[[3.8,19.9]],"id":28603686},{"atb":[[2.76,0]],"id":42190933}],"con":true,"img":false}]}
{"op":"mcm","clk":"5322102588","pt":1646316423536,"mc":[{"id":"1.195532855","rc":[{"atl":[[4.3,0]],"id":38833999}],"con":true,"img":false}]}
{"op":"mcm","clk":"5322102834","pt":1646316426171,"mc":[{"id":"1.195532855","rc":[{"atl":[[3.95,18.13],[3.9,2.25]],"id":38833999}],"con":true,"img":false}]}
{"op":"mcm","clk":"5322102856","pt":1646316426376,"mc":[{"id":"1.195532855","rc":[{"atl":[[4,2.11]],"id":38833999}],"con":true,"img":false}]}
{"op":"mcm","clk":"5322102898","pt":1646316426865,"mc":[{"id":"1.195532855","rc":[{"atb":[[2.8,0]],"id":42190933}],"con":true,"img":false}]}
{"op":"mcm","clk":"5322102929","pt":1646316427174,"mc":[{"id":"1.195532855","rc":[{"atl":[[2.6,121.31]],"id":41064149}],"con":true,"img":false}]}
{"op":"mcm","clk":"5322102964","pt":1646316427458,"mc":[{"id":"1.195532855","rc":[{"atb":[[2.84,0]],"id":42190933}],"con":true,"img":false}]}
