{"op":"mcm","clk":"5305619416","pt":1646080581421,"mc":[{"id":"1.195395424","marketDefinition":{"bspMarket":true,"turnInPlayEnabled":false,"persistenceEnabled":false,"marketBaseRate":7.0,"eventId":"31270458","eventTypeId":"4339","numberOfWinners":3,"bettingType":"ODDS","marketType":"PLACE","marketTime":"2022-03-01T02:39:00.000Z","suspendTime":"2022-03-01T02:39:00.000Z","bspReconciled":false,"complete":true,"inPlay":false,"crossMatching":false,"runnersVoidable":false,"numberOfActiveRunners":8,"betDelay":0,"status":"OPEN","runners":[{"status":"ACTIVE","sortPriority":1,"id":40324448,"name":"1. Winklee Frankie"},{"status":"ACTIVE","sortPriority":2,"id":43154453,"name":"2. Epic Speed"},{"status":"ACTIVE","sortPriority":3,"id":39318318,"name":"3. Kindred"},{"status":"ACTIVE","sortPriority":4,"id":42248822,"name":"4. Blackbrush Scott"},{"status":"ACTIVE","sortPriority":5,"id":38185321,"name":"5. Hiccup Finley"},{"status":"ACTIVE","sortPriority":6,"id":40022793,"name":"6. Motton Miss"},{"status":"ACTIVE","sortPriority":7,"id":39133526,"name":"7. Tsar Bell"},{"status":"ACTIVE","sortPriority":8,"id":40576811,"name":"8. Tah Meg"}],"regulators":["MR_INT"],"venue":"Devonport","countryCode":"AU","discountAllowed":true,"timezone":"Australia/Sydney","openDate":"2022-03-01T02:00:00.000Z","version":4380714798,"name":"To Be Placed","eventName":"Devonport (AUS) 1st Mar"},"rc":[],"con":true,"img":false}]}
{"op":"mcm","clk":"5305693208","pt":1646081381487,"mc":[{"id":"1.195395424","rc":[{"atl":[[6.4,13.53]],"id":40022793},{"spn":1.0,"spf":"NaN","id":40022793}],"con":true,"img":false}]}
{"op":"mcm","clk":"5305743109","pt":1646082027013,"mc":[{"id":"1.195395424","rc":[{"atb":[[1.4,302.04],[1.45,268.48],[1.5,120.81]],"id":43154453},{"atl":[[3.45,9.8],[3.95,8.14],[4.9,12.32],[2.98,6.06],[2.78,6.75]],"id":43154453},{"spn":2.14,"spf":"NaN","id":43154453},{"atb":[[2.3,46.47],[2.2,100.68],[2.1,109.83]],"id":40324448},{"atl":[[5.6,2.61],[7.2,1.93],[18,2.82],[9.2,2.92],[13,2]],"id":40324448},{"spn":3.95,"spf":"NaN","id":40324448},{"atb":[[1.12,1006.82],[1.07,1725.97],[1.17,355.34]],"id":39133526},{"atl":[[2.86,12.92],[2.46,8.23],[2.66,14.47],[3.15,22.35],[2.26,9.53]],"id":39133526},{"spn":1.71,"spf":"NaN","id":39133526},{"atb":[[4.5,34.51],[5,30.2],[5.5,13.42]],"id":39318318},{"atl":[[18.5,0.68],[85,0.28],[170,0.28],[44,0.55],[27,0.46]],"id":39318318},{"spn":12.0,"spf":"NaN","id":39318318},{"atb":[[2,60.4],[1.9,134.24],[1.95,127.17]],"id":38185321},{"atl":[[5.1,2.92],[6.2,2.31],[10.5,2.52],[8.2,3.33],[15.5,3.31]],"id":38185321},{"spn":3.55,"spf":"NaN","id":38185321},{"atb":[[3.55,23.68],[3.3,52.52],[3.05,58.93]],"id":40022793},{"atl":[[19.5,1.29],[48,1.02],[9.8,1.36],[14.5,0.88],[29,0.86]],"id":40022793},{"spn":4.97,"spf":"NaN","id":40022793},{"atb":[[1.2,604.09],[1.25,483.27],[1.3,201.36]],"id":42248822},{"atl":[[2.54,7.8],[3.85,16.86],[2.74,6.9],[3.35,10.22],[2.94,12.39]],"id":42248822},{"spn":1.92,"spf":"NaN","id":42248822},{"atb":[[1.4,151.02],[1.3,402.72],[1.35,345.19]],"id":40576811},{"atl":[[4.3,14.56],[2.86,6.46],[2.66,7.23],[3.15,11.17],[3.65,9.06]],"id":40576811},{"spn":2.03,"spf":"NaN","id":40576811}],"con":true,"img":false}]}
{"op":"mcm","clk":"5305747392","pt":1646082083712,"mc":[{"id":"1.195395424","rc":[{"atb":[[1.4,0],[1.45,0],[1.5,0]],"id":43154453},{"atl":[[3.45,0],[3.95,0],[4.9,0],[2.98,0],[2.78,0]],"id":43154453},{"atb":[[2.3,0],[2.2,0],[2.1,0]],"id":40324448},{"atl":[[5.6,0],[7.2,0],[18,0],[9.2,0],[13,0]],"id":40324448},{"atb":[[1.12,0],[1.07,0],[1.17,0]],"id":39133526},{"atl":[[2.86,0],[2.46,0],[2.66,0],[3.15,0],[2.26,0]],"id":39133526},{"atb":[[4.5,0],[5,0],[5.5,0]],"id":39318318},{"atl":[[18.5,0],[85,0],[170,0],[44,0],[27,0]],"id":39318318},{"atb":[[2,0],[1.9,0],[1.95,0]],"id":38185321},{"atl":[[5.1,0],[6.2,0],[10.5,0],[8.2,0],[15.5,0]],"id":38185321},{"atb":[[3.55,0],[3.3,0],[3.05,0]],"id":40022793},{"atl":[[19.5,0],[48,0],[9.8,0],[14.5,0],[29,0]],"id":40022793},{"atb":[[1.2,0],[1.25,0],[1.3,0]],"id":42248822},{"atl":[[2.54,0],[3.85,0],[2.74,0],[3.35,0],[2.94,0]],"id":42248822},{"atb":[[1.4,0],[1.3,0],[1.35,0]],"id":40576811},{"atl":[[4.3,0],[2.86,0],[2.66,0],[3.15,0],[3.65,0]],"id":40576811}],"con":true,"img":false}]}
{"op":"mcm","clk":"5305747684","pt":1646082087094,"mc":[{"id":"1.195395424","rc":[{"atb":[[1.4,302.04],[1.45,268.48],[1.5,120.81]],"id":43154453},{"atl":[[3.45,9.8],[3.95,8.14],[4.9,12.32],[2.98,6.06],[2.78,6.75]],"id":43154453},{"atb":[[2.3,46.47],[2.2,100.68],[2.1,109.83]],"id":40324448},{"atl":[[5.6,2.61],[7.2,1.93],[18,2.82],[9.2,2.92],[13,2]],"id":40324448},{"atb":[[1.12,1006.82],[1.07,1725.97],[1.17,355.34]],"id":39133526},{"atl":[[2.86,12.92],[2.46,8.23],[2.66,14.47],[3.15,22.35],[2.26,9.53]],"id":39133526},{"atb":[[4.5,34.51],[5,30.2],[5.5,13.42]],"id":39318318},{"atl":[[18.5,0.68],[85,0.28],[170,0.28],[44,0.55],[27,0.46]],"id":39318318},{"atb":[[2,60.4],[1.9,134.24],[1.95,127.17]],"id":38185321},{"atl":[[5.1,2.92],[6.2,2.31],[10.5,2.52],[8.2,3.33],[15.5,3.31]],"id":38185321},{"atb":[[3.55,23.68],[3.3,52.52],[3.05,58.93]],"id":40022793},{"atl":[[19.5,1.29],[48,1.02],[9.8,1.36],[14.5,0.88],[29,0.86]],"id":40022793},{"atb":[[1.2,604.09],[1.25,483.27],[1.3,201.36]],"id":42248822},{"atl":[[2.54,7.8],[3.85,16.86],[2.74,6.9],[3.35,10.22],[2.94,12.39]],"id":42248822},{"atb":[[1.4,151.02],[1.3,402.72],[1.35,345.19]],"id":40576811},{"atl":[[4.3,14.56],[2.86,6.46],[2.66,7.23],[3.15,11.17],[3.65,9.06]],"id":40576811}],"con":true,"img":false}]}
{"op":"mcm","clk":"5305771293","pt":1646082412814,"mc":[{"id":"1.195395424","rc":[{"atb":[[1.12,0],[1.07,0],[1.17,0]],"id":39133526},{"atl":[[2.86,0],[2.46,0],[2.66,0],[3.15,0],[2.26,0]],"id":39133526},{"spn":"NaN","spf":"NaN","id":39133526},{"atb":[[2,0],[1.9,0],[1.95,0]],"id":38185321},{"atl":[[5.1,0],[6.2,0],[10.5,0],[8.2,0],[15.5,0]],"id":38185321},{"spn":"NaN","spf":"NaN","id":38185321},{"atb":[[3.55,0],[3.3,0],[3.05,0]],"id":40022793},{"atl":[[19.5,0],[48,0],[9.8,0],[14.5,0],[29,0]],"id":40022793},{"spn":1.0,"spf":"NaN","id":40022793}],"con":true,"img":false}]}
{"op":"mcm","clk":"5305771691","pt":1646082418557,"mc":[{"id":"1.195395424","rc":[{"atb":[[1.15,402.72],[1.1,1208.18],[1.05,2416.36]],"id":39133526},{"atl":[[2.82,13.2],[2.22,9.85],[2.42,8.46],[2.62,14.83],[3.05,23.44]],"id":39133526},{"atb":[[2,120.81],[2.2,50.34],[2.1,109.83]],"id":38185321},{"atl":[[17.5,2.91],[9,3],[5.5,2.66],[12.5,2.08],[7,2]],"id":38185321},{"atb":[[3.45,49.31],[3.95,20.47],[3.7,44.74]],"id":40022793},{"atl":[[18.5,0.68],[85,0.57],[44,0.55],[13.5,0.96],[27,0.92]],"id":40022793}],"con":true,"img":false}]}
{"op":"mcm","clk":"5305903121","pt":1646084300813,"mc":[{"id":"1.195395424","rc":[{"atb":[[1.4,0],[1.45,0],[1.5,0]],"id":43154453},{"atl":[[3.45,0],[3.95,0],[4.9,0],[2.98,0],[2.78,0]],"id":43154453},{"spn":"NaN","spf":"NaN","id":43154453},{"atb":[[2.3,0],[2.2,0],[2.1,0]],"id":40324448},{"atl":[[5.6,0],[7.2,0],[18,0],[9.2,0],[13,0]],"id":40324448},{"spn":"NaN","spf":"NaN","id":40324448},{"atb":[[1.15,0],[1.1,0],[1.05,0]],"id":39133526},{"atl":[[2.82,0],[2.22,0],[2.42,0],[2.62,0],[3.05,0]],"id":39133526},{"atb":[[4.5,0],[5,0],[5.5,0]],"id":39318318},{"atl":[[18.5,0],[85,0],[170,0],[44,0],[27,0]],"id":39318318},{"spn":"NaN","spf":"NaN","id":39318318},{"atb":[[2,0],[2.2,0],[2.1,0]],"id":38185321},{"atl":[[17.5,0],[9,0],[5.5,0],[12.5,0],[7,0]],"id":38185321},{"spn":5.17,"spf":"NaN","id":40022793},{"atb":[[1.4,0],[1.3,0],[1.35,0]],"id":40576811},{"atl":[[4.3,0],[2.86,0],[2.66,0],[3.15,0],[3.65,0]],"id":40576811},{"spn":"NaN","spf":"NaN","id":40576811}],"con":true,"img":false}]}
{"op":"mcm","clk":"5305903427","pt":1646084306443,"mc":[{"id":"1.195395424","rc":[{"atb":[[1.6,201.36],[1.55,219.67],[1.65,92.93]],"id":43154453},{"atl":[[3.45,4.9],[3.95,8.14],[4.9,6.16],[2.98,6.06],[5.9,9.8]],"id":43154453},{"atb":[[2,60.4],[1.9,134.24],[1.95,127.17]],"id":40324448},{"atl":[[5.1,2.92],[6.2,2.31],[10.5,2.52],[8.2,3.33],[15.5,3.31]],"id":40324448},{"atb":[[1.12,1006.82],[1.07,1725.97],[1.17,355.34]],"id":39133526},{"atl":[[2.86,12.92],[2.46,8.23],[2.66,14.47],[3.15,22.35],[2.26,9.53]],"id":39133526},{"atb":[[8,8.62],[6,24.16],[7,20.13]],"id":39318318},{"atl":[[75,0.16],[150,0.16],[40,0.3],[350,0.13],[250,0.09]],"id":39318318},{"atb":[[2.4,86.29],[2.5,40.27],[2.3,92.93]],"id":38185321},{"atl":[[8,1.71],[10,2.66],[20,2.52],[6,2.4],[15,1.71]],"id":38185321},{"atb":[[1.4,302.04],[1.45,134.24],[1.35,345.19]],"id":40576811},{"atl":[[4.5,13.73],[2.9,6.32],[3.25,10.67],[3.75,8.74],[2.7,7.06]],"id":40576811}],"con":true,"img":false}]}
{"op":"mcm","clk":"5305906151","pt":1646084361321,"mc":[{"id":"1.195395424","rc":[{"spn":2.31,"spf":"NaN","id":43154453},{"atb":[[2,0],[1.9,0],[1.95,0]],"id":40324448},{"atl":[[5.1,0],[6.2,0],[10.5,0],[8.2,0],[15.5,0]],"id":40324448},{"atb":[[1.12,0],[1.07,0],[1.17,0]],"id":39133526},{"atl":[[2.86,0],[2.46,0],[2.66,0],[3.15,0],[2.26,0]],"id":39133526},{"atb":[[8,0],[6,0],[7,0]],"id":39318318},{"atl":[[75,0],[150,0],[40,0],[350,0],[250,0]],"id":39318318},{"atb":[[2.4,0],[2.5,0],[2.3,0]],"id":38185321},{"atl":[[8,0],[10,0],[20,0],[6,0],[15,0]],"id":38185321},{"atb":[[3.45,0],[3.95,0],[3.7,0]],"id":40022793},{"atl":[[18.5,0],[85,0],[44,0],[13.5,0],[27,0]],"id":40022793},{"spn":1.0,"spf":"NaN","id":40022793},{"atb":[[1.2,0],[1.25,0],[1.3,0]],"id":42248822},{"atl":[[2.54,0],[3.85,0],[2.74,0],[3.35,0],[2.94,0]],"id":42248822},{"spn":"NaN","spf":"NaN","id":42248822},{"spn":2.07,"spf":"NaN","id":40576811}],"con":true,"img":false}]}
{"op":"mcm","clk":"5305906492","pt":1646084366425,"mc":[{"id":"1.195395424","rc":[{"atb":[[1.8,151.02],[1.85,142.14],[1.9,67.12]],"id":40324448},{"atl":[[4,4],[8,3.43],[5,3],[10,5.34],[6,4.8]],"id":40324448},{"atb":[[1.18,671.21],[1.23,262.65],[1.13,929.37]],"id":39133526},{"atl":[[3.45,19.61],[2.38,8.7],[2.58,7.6],[2.98,12.13],[2.78,13.5]],"id":39133526},{"atb":[[8,8.62],[6,24.16],[7,20.13]],"id":39318318},{"atl":[[75,0.16],[150,0.16],[40,0.3],[350,0.13],[250,0.09]],"id":39318318},{"atb":[[2.3,46.47],[2.2,100.68],[2.1,109.83]],"id":38185321},{"atl":[[5.6,2.61],[7.2,1.93],[18,2.82],[9.2,2.92],[13,2]],"id":38185321},{"atb":[[4.1,19.48],[3.8,43.14],[3.55,47.38]],"id":40022793},{"atl":[[19.5,0.64],[95,0.5],[48,0.5],[14.5,0.88],[29,0.86]],"id":40022793},{"atb":[[1.2,604.09],[1.25,483.27],[1.3,201.36]],"id":42248822},{"atl":[[2.54,7.8],[3.85,16.86],[2.74,6.9],[3.35,10.22],[2.94,12.39]],"id":42248822}],"con":true,"img":false}]}
{"op":"mcm","clk":"5305909276","pt":1646084420582,"mc":[{"id":"1.195395424","rc":[{"atb":[[1.8,0],[1.85,0],[1.9,0]],"id":40324448},{"atl":[[4,0],[8,0],[5,0],[10,0],[6,0]],"id":40324448},{"atb":[[8,0],[6,0],[7,0]],"id":39318318},{"atl":[[75,0],[150,0],[40,0],[350,0],[250,0]],"id":39318318},{"atb":[[2.3,0],[2.2,0],[2.1,0]],"id":38185321},{"atl":[[5.6,0],[7.2,0],[18,0],[9.2,0],[13,0]],"id":38185321}],"con":true,"img":false}]}
{"op":"mcm","clk":"5305909467","pt":1646084424376,"mc":[{"id":"1.195395424","rc":[{"atb":[[1.98,61.64],[1.88,137.29],[1.93,129.91]],"id":40324448},{"atl":[[4.9,3.08],[9.8,2.73],[7.8,3.53],[5.9,2.45],[14.5,3.56]],"id":40324448},{"spn":3.44,"spf":"NaN","id":40324448},{"spn":1.8,"spf":"NaN","id":39133526},{"atb":[[7.4,18.88],[8.4,16.32],[9.4,7.19]],"id":39318318},{"atl":[[310,0.07],[410,0.11],[210,0.11],[55,0.22],[110,0.1]],"id":39318318},{"spn":32.2,"spf":"NaN","id":39318318},{"atb":[[2.4,86.29],[2.5,80.54],[2.6,37.75]],"id":38185321},{"atl":[[6.2,2.31],[10.5,2.52],[21,2.4],[8.2,1.66],[15.5,1.65]],"id":38185321},{"spn":4.4,"spf":"NaN","id":38185321},{"spn":5.25,"spf":"NaN","id":40022793},{"spn":1.92,"spf":"NaN","id":42248822}],"con":true,"img":false}]}
{"op":"mcm","clk":"5305974975","pt":1646086312094,"mc":[{"id":"1.195395424","rc":[{"atb":[[1.6,201.33],[1.55,219.63],[1.65,92.92]],"id":43154453},{"atl":[[3.45,4.9],[3.95,8.14],[4.9,6.15],[2.98,6.06],[5.9,9.8]],"id":43154453},{"atb":[[1.98,61.63],[1.88,137.27],[1.93,129.89]],"id":40324448},{"atl":[[4.9,3.07],[9.8,2.73],[7.8,3.53],[5.9,2.45],[14.5,3.56]],"id":40324448},{"atb":[[1.18,0],[1.23,0],[1.13,0]],"id":39133526},{"atl":[[3.45,0],[2.38,0],[2.58,0],[2.98,0],[2.78,0]],"id":39133526},{"spn":"NaN","spf":"NaN","id":39133526},{"atb":[[7.4,0],[8.4,0],[9.4,0]],"id":39318318},{"atl":[[310,0],[410,0],[210,0],[55,0],[110,0]],"id":39318318},{"spn":"NaN","spf":"NaN","id":39318318},{"atb":[[2.4,0],[2.5,0],[2.6,0]],"id":38185321},{"atl":[[6.2,0],[10.5,0],[21,0],[8.2,0],[15.5,0]],"id":38185321},{"spn":"NaN","spf":"NaN","id":38185321},{"atb":[[4.1,0],[3.8,0],[3.55,0]],"id":40022793},{"atl":[[6.4,13.53],[19.5,0],[95,0],[48,0],[14.5,0],[29,0]],"id":40022793},{"spn":1.0,"spf":"NaN","id":40022793},{"atb":[[1.2,603.99],[1.25,483.19],[1.3,201.33]],"id":42248822},{"atl":[[2.54,7.8],[3.85,16.86],[2.74,6.9],[3.35,10.22],[2.94,12.38]],"id":42248822},{"atb":[[1.4,301.99],[1.45,134.22],[1.35,345.13]],"id":40576811},{"atl":[[4.5,13.73],[2.9,6.32],[3.25,10.67],[3.75,8.74],[2.7,7.06]],"id":40576811}],"con":true,"img":false}]}
{"op":"mcm","clk":"5305975045","pt":1646086314399,"mc":[{"id":"1.195395424","rc":[{"atb":[[1.19,317.89],[1.14,862.85],[1.09,1342.2]],"id":39133526},{"atl":[[2.88,12.78],[3.2,21.84],[2.28,9.38],[2.68,14.3],[2.48,8.11]],"id":39133526},{"atb":[[8.6,7.94],[7.6,18.3],[6.6,21.57]],"id":39318318},{"atl":[[280,0.08],[90,0.13],[180,0.13],[46,0.26],[380,0.12]],"id":39318318},{"atb":[[2.4,86.28],[2.5,40.26],[2.3,92.92]],"id":38185321},{"atl":[[8,1.71],[10,2.66],[20,2.52],[6,2.4],[15,1.71]],"id":38185321},{"atb":[[3.25,53.68],[3.5,48.31],[3.75,21.96]],"id":40022793},{"atl":[[16.5,0.77],[65,0.75],[36,0.68],[11.5,1.14],[23,1.09]],"id":40022793}],"con":true,"img":false}]}
{"op":"mcm","clk":"5305978856","pt":1646086433579,"mc":[{"id":"1.195395424","rc":[{"spn":1.73,"spf":"NaN","id":39133526},{"spn":27.3,"spf":"NaN","id":39318318},{"spn":4.25,"spf":"NaN","id":38185321},{"spn":5.07,"spf":"NaN","id":40022793},{"atb":[[1.4,0],[1.45,0],[1.35,0]],"id":40576811},{"atl":[[4.5,0],[2.9,0],[3.25,0],[3.75,0],[2.7,0]],"id":40576811},{"spn":"NaN","spf":"NaN","id":40576811}],"con":true,"img":false}]}
{"op":"mcm","clk":"5305979012","pt":1646086439355,"mc":[{"id":"1.195395424","rc":[{"atb":[[1.4,301.99],[1.45,134.22],[1.35,345.13]],"id":40576811},{"atl":[[4.5,13.73],[2.9,6.32],[3.25,10.67],[3.75,8.74],[2.7,7.06]],"id":40576811}],"con":true,"img":false}]}
{"op":"mcm","clk":"5305990532","pt":1646086602700,"mc":[{"id":"1.195395424","marketDefinition":{"bspMarket":true,"turnInPlayEnabled":false,"persistenceEnabled":false,"marketBaseRate":7.0,"eventId":"31270458","eventTypeId":"4339","numberOfWinners":3,"bettingType":"ODDS","marketType":"PLACE","marketTime":"2022-03-01T02:39:00.000Z","suspendTime":"2022-03-01T02:39:00.000Z","bspReconciled":false,"complete":true,"inPlay":false,"crossMatching":false,"runnersVoidable":false,"numberOfActiveRunners":8,"betDelay":0,"status":"OPEN","runners":[{"status":"ACTIVE","sortPriority":1,"id":40324448,"name":"1. Winklee Frankie"},{"status":"ACTIVE","sortPriority":2,"id":43154453,"name":"2. Epic Speed"},{"status":"ACTIVE","sortPriority":3,"id":39318318,"name":"3. Kindred"},{"status":"ACTIVE","sortPriority":4,"id":42248822,"name":"4. Blackbrush Scott"},{"status":"ACTIVE","sortPriority":5,"id":38185321,"name":"5. Hiccup Finley"},{"status":"ACTIVE","sortPriority":6,"id":40022793,"name":"6. Motton Miss"},{"status":"ACTIVE","sortPriority":7,"id":39133526,"name":"7. Tsar Bell"},{"status":"ACTIVE","sortPriority":8,"id":40576811,"name":"8. Tah Meg"}],"regulators":["MR_INT"],"venue":"Devonport","countryCode":"AU","discountAllowed":true,"timezone":"Australia/Sydney","openDate":"2022-03-01T02:00:00.000Z","version":4380714798,"name":"To Be Placed","eventName":"Devonport (AUS) 1st Mar"},"rc":[{"atb":[[1.6,201.33],[1.55,219.63],[1.65,92.92]],"id":43154453},{"atl":[[3.45,4.9],[3.95,8.14],[4.9,6.15],[2.98,6.06],[5.9,9.8]],"id":43154453},{"spn":2.31,"spf":"NaN","id":43154453},{"atb":[[1.98,61.63],[1.88,137.27],[1.93,129.89]],"id":40324448},{"atl":[[4.9,3.07],[9.8,2.73],[7.8,3.53],[5.9,2.45],[14.5,3.56]],"id":40324448},{"spn":3.44,"spf":"NaN","id":40324448},{"atb":[[1.19,317.89],[1.14,862.85],[1.09,1342.2]],"id":39133526},{"atl":[[2.88,12.78],[3.2,21.84],[2.28,9.38],[2.68,14.3],[2.48,8.11]],"id":39133526},{"spn":1.73,"spf":"NaN","id":39133526},{"atb":[[8.6,7.94],[7.6,18.3],[6.6,21.57]],"id":39318318},{"atl":[[280,0.08],[90,0.13],[180,0.13],[46,0.26],[380,0.12]],"id":39318318},{"spn":27.3,"spf":"NaN","id":39318318},{"atb":[[2.4,86.28],[2.5,40.26],[2.3,92.92]],"id":38185321},{"atl":[[8,1.71],[10,2.66],[20,2.52],[6,2.4],[15,1.71]],"id":38185321},{"spn":4.25,"spf":"NaN","id":38185321},{"atb":[[3.25,53.68],[3.5,48.31],[3.75,21.96]],"id":40022793},{"atl":[[16.5,0.77],[65,0.75],[36,0.68],[6.4,13.53],[11.5,1.14],[23,1.09]],"id":40022793},{"spn":5.07,"spf":"NaN","id":40022793},{"atb":[[1.2,603.99],[1.25,483.19],[1.3,201.33]],"id":42248822},{"atl":[[2.54,7.8],[3.85,16.86],[2.74,6.9],[3.35,10.22],[2.94,12.38]],"id":42248822},{"spn":1.92,"spf":"NaN","id":42248822},{"atb":[[1.4,301.99],[1.45,134.22],[1.35,345.13]],"id":40576811},{"atl":[[4.5,13.73],[2.9,6.32],[3.25,10.67],[3.75,8.74],[2.7,7.06]],"id":40576811},{"spn":2.07,"spf":"NaN","id":40576811}],"con":true,"img":true}]}
{"op":"mcm","clk":"5306001649","pt":1646086821983,"mc":[{"id":"1.195395424","rc":[{"atb":[[3.25,0],[3.5,0],[3.75,0]],"id":40022793},{"atl":[[16.5,0],[65,0],[36,0],[11.5,0],[23,0]],"id":40022793},{"spn":1.0,"spf":"NaN","id":40022793},{"spn":2.07,"spf":"NaN","id":40576811}],"con":true,"img":false}]}
{"op":"mcm","clk":"5306001879","pt":1646086826456,"mc":[{"id":"1.195395424","rc":[{"atb":[[4.3,18.3],[3.9,41.65],[3.65,45.58]],"id":40022793},{"atl":[[32,0.77],[21,0.6],[55,0.44],[110,0.43],[15.5,0.82]],"id":40022793}],"con":true,"img":false}]}
{"op":"mcm","clk":"5306082255","pt":1646088862319,"mc":[{"id":"1.195395424","rc":[{"atb":[[1.6,0],[1.55,0],[1.65,0]],"id":43154453},{"atl":[[3.45,0],[3.95,0],[4.9,0],[2.98,0],[5.9,0]],"id":43154453},{"spn":"NaN","spf":"NaN","id":43154453},{"atb":[[8.6,0],[7.6,0],[6.6,0]],"id":39318318},{"atl":[[280,0],[90,0],[180,0],[46,0],[380,0]],"id":39318318},{"spn":"NaN","spf":"NaN","id":39318318},{"atb":[[2.4,0],[2.5,0],[2.3,0]],"id":38185321},{"atl":[[8,0],[10,0],[20,0],[6,0],[15,0]],"id":38185321},{"spn":"NaN","spf":"NaN","id":38185321},{"spn":5.35,"spf":"NaN","id":40022793},{"atb":[[1.2,0],[1.25,0],[1.3,0]],"id":42248822},{"atl":[[2.54,0],[3.85,0],[2.74,0],[3.35,0],[2.94,0]],"id":42248822},{"spn":"NaN","spf":"NaN","id":42248822}],"con":true,"img":false}]}
{"op":"mcm","clk":"5306082406","pt":1646088866375,"mc":[{"id":"1.195395424","rc":[{"atb":[[1.45,268.44],[1.55,109.81],[1.5,241.59]],"id":43154453},{"atl":[[2.82,6.6],[5.1,11.72],[4.1,7.75],[3.55,9.42],[3.05,5.86]],"id":43154453},{"atb":[[8.6,7.94],[7.6,18.3],[6.6,21.57]],"id":39318318},{"atl":[[280,0.08],[90,0.13],[180,0.13],[46,0.26],[380,0.12]],"id":39318318},{"atb":[[2.4,86.28],[2.5,40.26],[2.3,92.92]],"id":38185321},{"atl":[[8,1.71],[10,2.66],[20,2.52],[6,2.4],[15,1.71]],"id":38185321},{"atb":[[1.2,603.99],[1.25,483.19],[1.3,201.33]],"id":42248822},{"atl":[[2.54,7.8],[3.85,16.86],[2.74,6.9],[3.35,10.22],[2.94,12.38]],"id":42248822}],"con":true,"img":false}]}
{"op":"mcm","clk":"5306196788","pt":1646092002681,"mc":[{"id":"1.195395424","marketDefinition":{"bspMarket":true,"turnInPlayEnabled":false,"persistenceEnabled":false,"marketBaseRate":7.0,"eventId":"31270458","eventTypeId":"4339","numberOfWinners":3,"bettingType":"ODDS","marketType":"PLACE","marketTime":"2022-03-01T02:39:00.000Z","suspendTime":"2022-03-01T02:39:00.000Z","bspReconciled":false,"complete":true,"inPlay":false,"crossMatching":false,"runnersVoidable":false,"numberOfActiveRunners":8,"betDelay":0,"status":"OPEN","runners":[{"status":"ACTIVE","sortPriority":1,"id":40324448,"name":"1. Winklee Frankie"},{"status":"ACTIVE","sortPriority":2,"id":43154453,"name":"2. Epic Speed"},{"status":"ACTIVE","sortPriority":3,"id":39318318,"name":"3. Kindred"},{"status":"ACTIVE","sortPriority":4,"id":42248822,"name":"4. Blackbrush Scott"},{"status":"ACTIVE","sortPriority":5,"id":38185321,"name":"5. Hiccup Finley"},{"status":"ACTIVE","sortPriority":6,"id":40022793,"name":"6. Motton Miss"},{"status":"ACTIVE","sortPriority":7,"id":39133526,"name":"7. Tsar Bell"},{"status":"ACTIVE","sortPriority":8,"id":40576811,"name":"8. Tah Meg"}],"regulators":["MR_INT"],"venue":"Devonport","countryCode":"AU","discountAllowed":true,"timezone":"Australia/Sydney","openDate":"2022-03-01T02:00:00.000Z","version":4380714798,"name":"To Be Placed","eventName":"Devonport (AUS) 1st Mar"},"rc":[{"atb":[[1.45,268.44],[1.55,109.81],[1.5,241.59]],"id":43154453},{"atl":[[2.82,6.6],[5.1,11.72],[4.1,7.75],[3.55,9.42],[3.05,5.86]],"id":43154453},{"spn":2.18,"spf":"NaN","id":43154453},{"atb":[[1.98,61.63],[1.88,137.27],[1.93,129.89]],"id":40324448},{"atl":[[4.9,3.07],[9.8,2.73],[7.8,3.53],[5.9,2.45],[14.5,3.56]],"id":40324448},{"spn":3.44,"spf":"NaN","id":40324448},{"atb":[[1.19,317.89],[1.14,862.85],[1.09,1342.2]],"id":39133526},{"atl":[[2.88,12.78],[3.2,21.84],[2.28,9.38],[2.68,14.3],[2.48,8.11]],"id":39133526},{"spn":1.73,"spf":"NaN","id":39133526},{"atb":[[8.6,7.94],[7.6,18.3],[6.6,21.57]],"id":39318318},{"atl":[[280,0.08],[90,0.13],[180,0.13],[46,0.26],[380,0.12]],"id":39318318},{"spn":27.3,"spf":"NaN","id":39318318},{"atb":[[2.4,86.28],[2.5,40.26],[2.3,92.92]],"id":38185321},{"atl":[[8,1.71],[10,2.66],[20,2.52],[6,2.4],[15,1.71]],"id":38185321},{"spn":4.25,"spf":"NaN","id":38185321},{"atb":[[4.3,18.3],[3.9,41.65],[3.65,45.58]],"id":40022793},{"atl":[[32,0.77],[6.4,13.53],[21,0.6],[55,0.44],[110,0.43],[15.5,0.82]],"id":40022793},{"spn":5.35,"spf":"NaN","id":40022793},{"atb":[[1.2,603.99],[1.25,483.19],[1.3,201.33]],"id":42248822},{"atl":[[2.54,7.8],[3.85,16.86],[2.74,6.9],[3.35,10.22],[2.94,12.38]],"id":42248822},{"spn":1.92,"spf":"NaN","id":42248822},{"atb":[[1.4,301.99],[1.45,134.22],[1.35,345.13]],"id":40576811},{"atl":[[4.5,13.73],[2.9,6.32],[3.25,10.67],[3.75,8.74],[2.7,7.06]],"id":40576811},{"spn":2.07,"spf":"NaN","id":40576811}],"con":true,"img":true}]}
{"op":"mcm","clk":"5306387149","pt":1646097082466,"mc":[{"id":"1.195395424","rc":[{"atb":[[1.56,71.73],[1.45,268.26],[1.55,109.74],[1.5,241.44],[1.51,76.35]],"id":43154453},{"atl":[[2.82,6.59],[5.1,11.71],[4.3,13.11],[4.1,7.74],[4.9,9.73],[3.55,9.41],[3.05,5.85]],"id":43154453},{"spn":2.19,"spf":"NaN","id":43154453},{"atb":[[1.72,58.95],[1.98,61.59],[1.88,137.18],[1.94,46.03],[1.93,129.8]],"id":40324448},{"atl":[[6.2,8.31],[6.8,7.57],[4.9,3.07],[9.8,2.73],[7.8,3.53],[5.9,2.45],[14.5,3.55]],"id":40324448},{"atb":[[1.2,218.5],[1.19,317.68],[1.14,862.29],[1.09,1341.33],[1.22,91.72]],"id":39133526},{"atl":[[2.88,12.77],[3.2,21.82],[2.32,32.78],[2.28,9.37],[2.46,29.74],[2.68,14.29],[2.48,8.11]],"id":39133526},{"spn":1.75,"spf":"NaN","id":39133526},{"atb":[[8.6,7.93],[9,5.4],[7.6,24.78],[6.6,21.55]],"id":39318318},{"atl":[[80,0.54],[85,2.7],[46,0.26]],"id":39318318},{"spn":27.5,"spf":"NaN","id":39318318},{"atb":[[2.4,86.22],[2.5,40.24],[2.3,92.86],[2.32,32.99],[2.46,29.63]],"id":38185321},{"atl":[[8,1.71],[10,2.66],[20,2.52],[10.5,4.86],[6,2.4],[9.8,4.91],[15,1.71]],"id":38185321},{"spn":4.25,"spf":"NaN","id":38185321},{"atb":[[4.3,18.29],[3.95,14.66],[3.9,41.63],[3.3,17.71],[3.65,45.55]],"id":40022793},{"atl":[[32,0.77],[17.5,2.7],[6.4,13.52],[21,0.6],[22,2.7],[55,0.44],[110,0.43],[15.5,0.82]],"id":40022793},{"atb":[[1.2,603.6],[1.25,482.88],[1.3,201.2],[1.33,139.57],[1.31,137.37]],"id":42248822},{"atl":[[2.54,7.79],[3.85,16.85],[2.74,6.9],[3.35,10.21],[3.25,18.38],[2.94,34.68]],"id":42248822},{"spn":1.93,"spf":"NaN","id":42248822},{"atb":[[1.4,301.8],[1.41,106.54],[1.45,134.13],[1.48,94.06],[1.35,344.91]],"id":40576811},{"atl":[[4.5,13.72],[3.85,15.18],[2.9,6.31],[3.25,10.67],[4.2,12.98],[3.75,8.73],[2.7,7.06]],"id":40576811},{"spn":2.09,"spf":"NaN","id":40576811}],"con":true,"img":false}]}
{"op":"mcm","clk":"5306389607","pt":1646097153880,"mc":[{"id":"1.195395424","rc":[{"atl":[[2.92,22.17]],"id":42248822}],"con":true,"img":false}]}
{"op":"mcm","clk":"5306389612","pt":1646097153984,"mc":[{"id":"1.195395424","rc":[{"atb":[[1.51,0]],"id":43154453},{"atb":[[1.94,0]],"id":40324448},{"atb":[[7.6,18.29]],"id":39318318},{"atb":[[2.32,0],[2.46,0]],"id":38185321},{"atb":[[3.3,0]],"id":40022793},{"atl":[[3.25,0]],"id":42248822},{"atb":[[1.41,0]],"id":40576811}],"con":true,"img":false}]}
{"op":"mcm","clk":"5306389617","pt":1646097154088,"mc":[{"id":"1.195395424","rc":[{"atb":[[1.56,148.09]],"id":43154453},{"atb":[[1.99,46.03]],"id":40324448},{"atb":[[7.8,6.49]],"id":39318318},{"atb":[[2.42,32.99],[2.52,29.63]],"id":38185321},{"atb":[[3.7,17.71]],"id":40022793},{"atb":[[1.46,106.54]],"id":40576811}],"con":true,"img":false}]}
{"op":"mcm","clk":"5306390763","pt":1646097188629,"mc":[{"id":"1.195395424","rc":[{"atl":[[2.94,12.38]],"id":42248822}],"con":true,"img":false}]}
{"op":"mcm","clk":"5306390770","pt":1646097188733,"mc":[{"id":"1.195395424","rc":[{"atl":[[2.92,44.48]],"id":42248822}],"con":true,"img":false}]}
{"op":"mcm","clk":"5306404701","pt":1646097402653,"mc":[{"id":"1.195395424","marketDefinition":{"bspMarket":true,"turnInPlayEnabled":false,"persistenceEnabled":false,"marketBaseRate":7.0,"eventId":"31270458","eventTypeId":"4339","numberOfWinners":3,"bettingType":"ODDS","marketType":"PLACE","marketTime":"2022-03-01T02:39:00.000Z","suspendTime":"2022-03-01T02:39:00.000Z","bspReconciled":false,"complete":true,"inPlay":false,"crossMatching":false,"runnersVoidable":false,"numberOfActiveRunners":8,"betDelay":0,"status":"OPEN","runners":[{"status":"ACTIVE","sortPriority":1,"id":40324448,"name":"1. Winklee Frankie"},{"status":"ACTIVE","sortPriority":2,"id":43154453,"name":"2. Epic Speed"},{"status":"ACTIVE","sortPriority":3,"id":39318318,"name":"3. Kindred"},{"status":"ACTIVE","sortPriority":4,"id":42248822,"name":"4. Blackbrush Scott"},{"status":"ACTIVE","sortPriority":5,"id":38185321,"name":"5. Hiccup Finley"},{"status":"ACTIVE","sortPriority":6,"id":40022793,"name":"6. Motton Miss"},{"status":"ACTIVE","sortPriority":7,"id":39133526,"name":"7. Tsar Bell"},{"status":"ACTIVE","sortPriority":8,"id":40576811,"name":"8. Tah Meg"}],"regulators":["MR_INT"],"venue":"Devonport","countryCode":"AU","discountAllowed":true,"timezone":"Australia/Sydney","openDate":"2022-03-01T02:00:00.000Z","version":4380714798,"name":"To Be Placed","eventName":"Devonport (AUS) 1st Mar"},"rc":[{"atb":[[1.56,148.09],[1.45,268.26],[1.55,109.74],[1.5,241.44]],"id":43154453},{"atl":[[2.82,6.59],[4.3,13.11],[5.1,11.71],[4.1,7.74],[4.9,9.73],[3.55,9.41],[3.05,5.85]],"id":43154453},{"spn":2.19,"spf":"NaN","id":43154453},{"atb":[[1.72,58.95],[1.99,46.03],[1.98,61.59],[1.88,137.18],[1.93,129.8]],"id":40324448},{"atl":[[6.2,8.31],[6.8,7.57],[4.9,3.07],[9.8,2.73],[7.8,3.53],[5.9,2.45],[14.5,3.55]],"id":40324448},{"spn":3.44,"spf":"NaN","id":40324448},{"atb":[[1.2,218.5],[1.19,317.68],[1.14,862.29],[1.22,91.72],[1.09,1341.33]],"id":39133526},{"atl":[[2.88,12.77],[3.2,21.82],[2.32,32.78],[2.28,9.37],[2.46,29.74],[2.68,14.29],[2.48,8.11]],"id":39133526},{"spn":1.75,"spf":"NaN","id":39133526},{"atb":[[9,5.4],[8.6,7.93],[7.6,18.29],[7.8,6.49],[6.6,21.55]],"id":39318318},{"atl":[[280,0.08],[80,0.54],[85,2.7],[90,0.13],[180,0.13],[46,0.26],[380,0.12]],"id":39318318},{"spn":27.5,"spf":"NaN","id":39318318},{"atb":[[2.4,86.22],[2.5,40.24],[2.3,92.86],[2.42,32.99],[2.52,29.63]],"id":38185321},{"atl":[[8,1.71],[10,2.66],[20,2.52],[10.5,4.86],[6,2.4],[9.8,4.91],[15,1.71]],"id":38185321},{"spn":4.26,"spf":"NaN","id":38185321},{"atb":[[4.3,18.29],[3.95,14.66],[3.7,17.71],[3.9,41.63],[3.65,45.55]],"id":40022793},{"atl":[[32,0.77],[17.5,2.7],[6.4,13.52],[21,0.6],[22,2.7],[55,0.44],[110,0.43],[15.5,0.82]],"id":40022793},{"spn":5.35,"spf":"NaN","id":40022793},{"atb":[[1.2,603.6],[1.25,482.88],[1.33,139.57],[1.3,201.2],[1.31,137.37]],"id":42248822},{"atl":[[2.92,44.48],[2.54,7.79],[3.85,16.85],[2.74,6.9],[3.35,10.21],[2.94,12.38]],"id":42248822},{"spn":1.93,"spf":"NaN","id":42248822},{"atb":[[1.4,301.8],[1.46,106.54],[1.45,134.13],[1.48,94.06],[1.35,344.91]],"id":40576811},{"atl":[[4.5,13.72],[3.85,15.18],[2.9,6.31],[3.25,10.67],[4.2,12.98],[3.75,8.73],[2.7,7.06]],"id":40576811},{"spn":2.09,"spf":"NaN","id":40576811}],"con":true,"img":true}]}
{"op":"mcm","clk":"5306463863","pt":1646098829466,"mc":[{"id":"1.195395424","rc":[{"spn":3.44,"spf":"NaN","id":40324448},{"atb":[[1.22,0]],"id":39133526},{"spn":1.74,"spf":"NaN","id":39133526},{"spn":4.26,"spf":"NaN","id":38185321},{"atb":[[1.33,85.42]],"id":42248822}],"con":true,"img":false}]}
{"op":"mcm","clk":"5306463868","pt":1646098829571,"mc":[{"id":"1.195395424","rc":[{"atb":[[1.21,91.72]],"id":39133526}],"con":true,"img":false}]}
{"op":"mcm","clk":"5306472492","pt":1646099039417,"mc":[{"id":"1.195395424","rc":[{"atb":[[1.16,291.52]],"id":39133526},{"spn":1.74,"spf":"NaN","id":39133526}],"con":true,"img":false}]}
{"op":"mcm","clk":"5306472496","pt":1646099039519,"mc":[{"id":"1.195395424","rc":[{"atb":[[1.2,0]],"id":39133526}],"con":true,"img":false}]}
{"op":"mcm","clk":"5306472827","pt":1646099048253,"mc":[{"id":"1.195395424","rc":[{"atb":[[1.21,0]],"id":39133526}],"con":true,"img":false}]}
{"op":"mcm","clk":"5306472832","pt":1646099048354,"mc":[{"id":"1.195395424","rc":[{"atb":[[1.2,91.72]],"id":39133526}],"con":true,"img":false}]}
{"op":"mcm","clk":"5306500035","pt":1646099653205,"mc":[{"id":"1.195395424","rc":[{"spn":1.74,"spf":"NaN","id":39133526},{"atb":[[2.54,1.67]],"id":38185321},{"spn":4.27,"spf":"NaN","id":38185321},{"atb":[[4.4,1.67]],"id":40022793},{"spn":5.4,"spf":"NaN","id":40022793}],"con":true,"img":false}]}
{"op":"mcm","clk":"5306500778","pt":1646099667601,"mc":[{"id":"1.195395424","marketDefinition":{"bspMarket":true,"turnInPlayEnabled":false,"persistenceEnabled":false,"marketBaseRate":7.0,"eventId":"31270458","eventTypeId":"4339","numberOfWinners":3,"bettingType":"ODDS","marketType":"PLACE","marketTime":"2022-03-01T02:39:00.000Z","suspendTime":"2022-03-01T02:39:00.000Z","bspReconciled":false,"complete":true,"inPlay":false,"crossMatching":true,"runnersVoidable":false,"numberOfActiveRunners":8,"betDelay":0,"status":"OPEN","runners":[{"status":"ACTIVE","sortPriority":1,"id":40324448,"name":"1. Winklee Frankie"},{"status":"ACTIVE","sortPriority":2,"id":43154453,"name":"2. Epic Speed"},{"status":"ACTIVE","sortPriority":3,"id":39318318,"name":"3. Kindred"},{"status":"ACTIVE","sortPriority":4,"id":42248822,"name":"4. Blackbrush Scott"},{"status":"ACTIVE","sortPriority":5,"id":38185321,"name":"5. Hiccup Finley"},{"status":"ACTIVE","sortPriority":6,"id":40022793,"name":"6. Motton Miss"},{"status":"ACTIVE","sortPriority":7,"id":39133526,"name":"7. Tsar Bell"},{"status":"ACTIVE","sortPriority":8,"id":40576811,"name":"8. Tah Meg"}],"regulators":["MR_INT"],"venue":"Devonport","countryCode":"AU","discountAllowed":true,"timezone":"Australia/Sydney","openDate":"2022-03-01T02:00:00.000Z","version":4380714798,"name":"To Be Placed","eventName":"Devonport (AUS) 1st Mar"},"rc":[],"con":true,"img":false}]}
{"op":"mcm","clk":"5306501985","pt":1646099695405,"mc":[{"id":"1.195395424","rc":[{"atb":[[1.6,12.41]],"id":43154453},{"atb":[[2.04,7.16]],"id":40324448},{"atb":[[2.58,4.71]],"id":38185321},{"atb":[[1.51,14.6]],"id":40576811}],"con":true,"img":false}]}
{"op":"mcm","clk":"5306502258","pt":1646099702511,"mc":[{"id":"1.195395424","rc":[{"atb":[[2.54,0]],"id":38185321}],"con":true,"img":false}]}
{"op":"mcm","clk":"5306502270","pt":1646099702716,"mc":[{"id":"1.195395424","rc":[{"atb":[[2.06,1.67]],"id":40324448},{"atb":[[2.6,1.67]],"id":38185321}],"con":true,"img":false}]}
{"op":"mcm","clk":"5306511001","pt":1646099902353,"mc":[{"id":"1.195395424","rc":[{"spn":2.21,"spf":"NaN","id":43154453},{"spn":3.48,"spf":"NaN","id":40324448},{"atb":[[1.2,0]],"id":39133526},{"spn":1.73,"spf":"NaN","id":39133526},{"spn":4.3,"spf":"NaN","id":38185321},{"spn":2.1,"spf":"NaN","id":40576811}],"con":true,"img":false}]}
{"op":"mcm","clk":"5306511006","pt":1646099902454,"mc":[{"id":"1.195395424","rc":[{"atb":[[1.22,91.72]],"id":39133526}],"con":true,"img":false}]}
{"op":"mcm","clk":"5306511979","pt":1646099923902,"mc":[{"id":"1.195395424","rc":[{"atb":[[1.24,296.18]],"id":43154453},{"atl":[[12,9.09]],"id":43154453},{"atb":[[2.06,8.84]],"id":40324448},{"atl":[[11,6.61]],"id":40324448},{"atl":[[2.34,42.16]],"id":39133526},{"atb":[[3.75,15.88]],"id":39318318},{"atl":[[80,2.54]],"id":39318318},{"atb":[[2.14,65.98]],"id":38185321},{"atl":[[6.8,4.8]],"id":38185321},{"atb":[[2.94,36]],"id":40022793},{"atl":[[16,6.67]],"id":40022793},{"atb":[[1.23,434.78]],"id":42248822},{"atl":[[2.52,7.8]],"id":42248822},{"atb":[[1.52,94.06]],"id":40576811},{"atl":[[7.8,14.71]],"id":40576811}],"con":true,"img":false}]}
{"op":"mcm","clk":"5306512023","pt":1646099924874,"mc":[{"id":"1.195395424","rc":[{"atb":[[1.22,0]],"id":39133526}],"con":true,"img":false}]}
{"op":"mcm","clk":"5306512027","pt":1646099924976,"mc":[{"id":"1.195395424","rc":[{"atb":[[1.21,91.72]],"id":39133526}],"con":true,"img":false}]}
{"op":"mcm","clk":"5306512055","pt":1646099925489,"mc":[{"id":"1.195395424","rc":[{"atl":[[2.92,22.3],[3.2,18.38]],"id":42248822}],"con":true,"img":false}]}
{"op":"mcm","clk":"5306512140","pt":1646099926982,"mc":[{"id":"1.195395424","rc":[{"atb":[[1.51,0]],"id":40576811}],"con":true,"img":false}]}
{"op":"mcm","clk":"5306512219","pt":1646099928517,"mc":[{"id":"1.195395424","rc":[{"atb":[[1.56,71.73]],"id":43154453},{"atb":[[1.2,218.5],[1.16,0]],"id":39133526}],"con":true,"img":false}]}
{"op":"mcm","clk":"5306512225","pt":1646099928620,"mc":[{"id":"1.195395424","rc":[{"atb":[[1.51,76.35]],"id":43154453}],"con":true,"img":false}]}
{"op":"mcm","clk":"5306512244","pt":1646099928981,"mc":[{"id":"1.195395424","rc":[{"atl":[[2.5,59.5],[2.34,0]],"id":39133526},{"atb":[[2.72,36.58],[2.94,0]],"id":40022793},{"atl":[[2.52,0],[2.68,15.6]],"id":42248822},{"atb":[[1.49,188.12],[1.52,0]],"id":40576811}],"con":true,"img":false}]}
{"op":"mcm","clk":"5306512513","pt":1646099935893,"mc":[{"id":"1.195395424","rc":[{"atb":[[1.52,14.32]],"id":40576811}],"con":true,"img":false}]}
{"op":"mcm","clk":"5306512817","pt":1646099943304,"mc":[{"id":"1.195395424","rc":[{"atb":[[3.2,23.82],[3.75,0]],"id":39318318}],"con":true,"img":false}]}
{"op":"mcm","clk":"5306513089","pt":1646099949210,"mc":[{"id":"1.195395424","rc":[{"atb":[[1.3,296.18],[1.24,0]],"id":43154453},{"atl":[[16,0],[13,8.33]],"id":40022793},{"atb":[[1.28,357.14],[1.23,0]],"id":42248822},{"atb":[[1.49,0],[1.53,94.06]],"id":40576811}],"con":true,"img":false}]}
{"op":"mcm","clk":"5306513169","pt":1646099951005,"mc":[{"id":"1.195395424","rc":[{"atb":[[1.52,0]],"id":40576811}],"con":true,"img":false}]}
{"op":"mcm","clk":"5306513225","pt":1646099952335,"mc":[{"id":"1.195395424","rc":[{"atb":[[1.48,0]],"id":40576811}],"con":true,"img":false}]}
{"op":"mcm","clk":"5306513228","pt":1646099952439,"mc":[{"id":"1.195395424","rc":[{"atb":[[1.5,94.06]],"id":40576811}],"con":true,"img":false}]}
{"op":"mcm","clk":"5306513301","pt":1646099954444,"mc":[{"id":"1.195395424","rc":[{"atb":[[1.51,188.12],[1.53,0]],"id":40576811}],"con":true,"img":false}]}
{"op":"mcm","clk":"5306513347","pt":1646099955523,"mc":[{"id":"1.195395424","rc":[{"atl":[[17.5,0]],"id":40022793}],"con":true,"img":false}]}
{"op":"mcm","clk":"5306513353","pt":1646099955625,"mc":[{"id":"1.195395424","rc":[{"atl":[[12.5,2.7]],"id":40022793}],"con":true,"img":false}]}
{"op":"mcm","clk":"5306513630","pt":1646099962907,"mc":[{"id":"1.195395424","rc":[{"spn":1.74,"spf":"NaN","id":39133526},{"atb":[[1.54,13.79]],"id":40576811},{"spn":2.12,"spf":"NaN","id":40576811}],"con":true,"img":false}]}
{"op":"mcm","clk":"5306513882","pt":1646099968550,"mc":[{"id":"1.195395424","rc":[{"atl":[[2.92,0]],"id":42248822}],"con":true,"img":false}]}
{"op":"mcm","clk":"5306513887","pt":1646099968650,"mc":[{"id":"1.195395424","rc":[{"atl":[[2.66,22.3]],"id":42248822}],"con":true,"img":false}]}
{"op":"mcm","clk":"5306514247","pt":1646099977063,"mc":[{"id":"1.195395424","rc":[{"atb":[[2.56,5.35]],"id":38185321}],"con":true,"img":false}]}
{"op":"mcm","clk":"5306514259","pt":1646099977269,"mc":[{"id":"1.195395424","rc":[{"atb":[[1.6,26.34]],"id":43154453},{"atb":[[1.54,29.27]],"id":40576811}],"con":true,"img":false}]}
{"op":"mcm","clk":"5306514266","pt":1646099977424,"mc":[{"id":"1.195395424","rc":[{"atb":[[2.04,15.2]],"id":40324448}],"con":true,"img":false}]}
{"op":"mcm","clk":"5306514361","pt":1646099979443,"mc":[{"id":"1.195395424","rc":[{"atb":[[1.55,94.06],[1.51,0]],"id":40576811}],"con":true,"img":false}]}
{"op":"mcm","clk":"5306514443","pt":1646099981031,"mc":[{"id":"1.195395424","rc":[{"atb":[[1.54,15.47]],"id":40576811}],"con":true,"img":false}]}
{"op":"mcm","clk":"5306514593","pt":1646099984460,"mc":[{"id":"1.195395424","rc":[{"atl":[[85,0]],"id":39318318},{"atb":[[1.5,0]],"id":40576811}],"con":true,"img":false}]}
{"op":"mcm","clk":"5306514598","pt":1646099984561,"mc":[{"id":"1.195395424","rc":[{"atl":[[75,2.7]],"id":39318318},{"atb":[[1.52,94.06]],"id":40576811}],"con":true,"img":false}]}
{"op":"mcm","clk":"5306514747","pt":1646099986933,"mc":[{"id":"1.195395424","rc":[{"atb":[[1.59,12.62]],"id":40576811}],"con":true,"img":false}]}
{"op":"mcm","clk":"5306514756","pt":1646099987050,"mc":[{"id":"1.195395424","rc":[{"atb":[[1.6,15.47],[1.55,0]],"id":40576811}],"con":true,"img":false}]}
{"op":"mcm","clk":"5306514924","pt":1646099990066,"mc":[{"id":"1.195395424","rc":[{"atb":[[1.59,0]],"id":40576811}],"con":true,"img":false}]}
{"op":"mcm","clk":"5306514929","pt":1646099990170,"mc":[{"id":"1.195395424","rc":[{"atb":[[1.6,0],[1.55,94.06]],"id":40576811}],"con":true,"img":false}]}
{"op":"mcm","clk":"5306515186","pt":1646099995363,"mc":[{"id":"1.195395424","rc":[{"atl":[[2.5,0],[2.28,39.12]],"id":39133526},{"atl":[[6.8,0],[7,7.2]],"id":38185321},{"atb":[[1.28,0],[1.29,344.83]],"id":42248822}],"con":true,"img":false}]}
{"op":"mcm","clk":"5306515257","pt":1646099996750,"mc":[{"id":"1.195395424","rc":[{"atb":[[1.54,0]],"id":40576811}],"con":true,"img":false}]}
{"op":"mcm","clk":"5306515263","pt":1646099996855,"mc":[{"id":"1.195395424","rc":[{"atb":[[1.55,0],[1.53,188.12]],"id":40576811}],"con":true,"img":false}]}
{"op":"mcm","clk":"5306515903","pt":1646100008293,"mc":[{"id":"1.195395424","rc":[{"atb":[[1.56,71.76],[1.6,26.34],[1.45,268.38],[1.55,109.79],[1.5,241.54],[1.51,76.39]],"id":43154453},{"atl":[[2.82,6.6],[4.3,13.11],[5.1,11.72],[4.1,7.74],[4.9,9.73],[3.55,9.42],[3.05,5.86]],"id":43154453},{"atb":[[1.72,58.97],[1.99,46.05],[2.06,8.83],[1.98,61.62],[2.04,15.2],[1.88,137.24],[1.93,129.86]],"id":40324448},{"atl":[[6.2,8.32],[6.8,7.57],[4.9,3.07],[9.8,2.73],[7.8,3.53],[5.9,2.45],[14.5,3.56]],"id":40324448},{"atb":[[1.2,218.6],[1.21,91.76],[1.19,317.82],[1.14,862.66],[1.09,1341.91]],"id":39133526},{"atl":[[2.88,12.78],[3.2,21.83],[2.32,32.79],[2.28,39.13],[2.46,29.76],[2.68,14.3],[2.48,8.11]],"id":39133526},{"atb":[[9,5.41],[8.6,7.94],[7.6,18.29],[7.8,6.49],[6.6,21.56]],"id":39318318},{"atl":[[75,2.7],[80,2.54],[46,0.26]],"id":39318318},{"atb":[[2.56,5.35],[2.4,86.26],[2.5,40.25],[2.3,92.9],[2.42,33],[2.52,29.64],[2.6,1.66],[2.58,4.71]],"id":38185321},{"atl":[[8,1.71],[10,2.66],[20,2.52],[10.5,4.86],[6,2.4],[9.8,4.91],[15,1.71]],"id":38185321},{"atb":[[4.3,18.29],[3.95,14.67],[3.7,17.72],[4.4,1.66],[3.9,41.64],[3.65,45.57]],"id":40022793},{"atl":[[32,0.77],[6.4,13.52],[21,0.6],[22,2.7],[12.5,2.7],[55,0.44],[110,0.43],[15.5,0.82]],"id":40022793},{"atb":[[1.2,603.86],[1.25,483.09],[1.33,85.46],[1.3,201.28],[1.31,137.43]],"id":42248822},{"atl":[[2.54,7.8],[3.2,18.39],[3.85,16.86],[2.74,6.9],[3.35,10.22],[2.66,22.31],[2.94,12.38]],"id":42248822},{"atb":[[1.4,301.93],[1.46,106.59],[1.45,134.19],[1.57,13.07],[1.52,94.1],[1.35,345.06]],"id":40576811},{"atl":[[4.5,13.72],[3.85,15.18],[2.9,6.32],[3.25,10.67],[4.2,12.98],[3.75,8.73],[2.7,7.06]],"id":40576811}],"con":true,"img":false}]}
{"op":"mcm","clk":"5306516450","pt":1646100018096,"mc":[{"id":"1.195395424","rc":[{"atb":[[1.57,27.71]],"id":40576811}],"con":true,"img":false}]}
{"op":"mcm","clk":"5306516667","pt":1646100021380,"mc":[{"id":"1.195395424","rc":[{"atb":[[1.58,94.1],[1.53,0]],"id":40576811}],"con":true,"img":false}]}
{"op":"mcm","clk":"5306516715","pt":1646100022513,"mc":[{"id":"1.195395424","rc":[{"atl":[[11,0],[9.4,7.06]],"id":40324448},{"atl":[[6.4,4.92],[7,0]],"id":38185321},{"atl":[[2.54,23.4],[2.68,0]],"id":42248822}],"con":true,"img":false}]}
{"op":"mcm","clk":"5306516745","pt":1646100023285,"mc":[{"id":"1.195395424","rc":[{"atb":[[1.57,14.64]],"id":40576811},{"spn":2.14,"spf":"NaN","id":40576811}],"con":true,"img":false}]}
{"op":"mcm","clk":"5306517068","pt":1646100029702,"mc":[{"id":"1.195395424","rc":[{"atl":[[2.32,0]],"id":39133526},{"atb":[[1.52,0]],"id":40576811}],"con":true,"img":false}]}
{"op":"mcm","clk":"5306517072","pt":1646100029806,"mc":[{"id":"1.195395424","rc":[{"atl":[[2.26,32.79]],"id":39133526},{"atb":[[1.54,94.1]],"id":40576811}],"con":true,"img":false}]}
{"op":"mcm","clk":"5306517079","pt":1646100029920,"mc":[{"id":"1.195395424","rc":[{"atl":[[2.24,32.8],[2.28,9.38]],"id":39133526}],"con":true,"img":false}]}
{"op":"mcm","clk":"5306517108","pt":1646100030323,"mc":[{"id":"1.195395424","rc":[{"atb":[[1.62,12.02]],"id":40576811}],"con":true,"img":false}]}
{"op":"mcm","clk":"5306517437","pt":1646100036636,"mc":[{"id":"1.195395424","rc":[{"atl":[[2.24,0],[2.4,65.6]],"id":39133526},{"atb":[[3.2,0],[2.42,26.24]],"id":39318318},{"atl":[[6.4,0],[6.2,4.92]],"id":38185321},{"atb":[[2.72,0],[2.58,36.6]],"id":40022793},{"atb":[[1.21,476.19],[1.29,0]],"id":42248822}],"con":true,"img":false}]}
{"op":"mcm","clk":"5306517526","pt":1646100038124,"mc":[{"id":"1.195395424","rc":[{"atb":[[1.57,0]],"id":40576811}],"con":true,"img":false}]}
{"op":"mcm","clk":"5306517891","pt":1646100044935,"mc":[{"id":"1.195395424","rc":[{"atb":[[1.62,25.48]],"id":40576811}],"con":true,"img":false}]}
{"op":"mcm","clk":"5306517932","pt":1646100045718,"mc":[{"id":"1.195395424","rc":[{"atb":[[1.63,94.1],[1.58,0]],"id":40576811}],"con":true,"img":false}]}
{"op":"mcm","clk":"5306518034","pt":1646100048310,"mc":[{"id":"1.195395424","rc":[{"atb":[[1.62,13.46]],"id":40576811}],"con":true,"img":false}]}
{"op":"mcm","clk":"5306518255","pt":1646100053524,"mc":[{"id":"1.195395424","rc":[{"atb":[[1.67,11.12]],"id":40576811}],"con":true,"img":false}]}
{"op":"mcm","clk":"5306518445","pt":1646100058233,"mc":[{"id":"1.195395424","rc":[{"atl":[[2.66,0]],"id":42248822},{"atb":[[1.54,0]],"id":40576811}],"con":true,"img":false}]}
{"op":"mcm","clk":"5306518451","pt":1646100058348,"mc":[{"id":"1.195395424","rc":[{"atl":[[2.52,22.31]],"id":42248822},{"atb":[[1.64,94.1]],"id":40576811}],"con":true,"img":false}]}
{"op":"mcm","clk":"5306518457","pt":1646100058441,"mc":[{"id":"1.195395424","rc":[{"atl":[[2.5,22.31]],"id":42248822}],"con":true,"img":false}]}
{"op":"mcm","clk":"5306518463","pt":1646100058540,"mc":[{"id":"1.195395424","rc":[{"atl":[[2.54,7.8]],"id":42248822}],"con":true,"img":false}]}
{"op":"mcm","clk":"5306518537","pt":1646100060133,"mc":[{"id":"1.195395424","rc":[{"atb":[[1.67,0]],"id":40576811}],"con":true,"img":false}]}
{"op":"mcm","clk":"5306518578","pt":1646100060757,"mc":[{"id":"1.195395424","rc":[{"atl":[[2.3,42.18]],"id":39133526},{"atb":[[2.42,0]],"id":39318318},{"atb":[[2.58,0]],"id":40022793}],"con":true,"img":false}]}
{"op":"mcm","clk":"5306518585","pt":1646100060850,"mc":[{"id":"1.195395424","rc":[{"atl":[[2.4,0]],"id":39133526},{"atb":[[2.64,26.24]],"id":39318318},{"atb":[[2.74,36.6]],"id":40022793},{"atb":[[1.23,434.78]],"id":42248822}],"con":true,"img":false}]}
{"op":"mcm","clk":"5306518591","pt":1646100060976,"mc":[{"id":"1.195395424","rc":[{"atb":[[1.21,0]],"id":42248822}],"con":true,"img":false}]}
{"op":"mcm","clk":"5306518727","pt":1646100063522,"mc":[{"id":"1.195395424","rc":[{"atb":[[1.62,0]],"id":40576811}],"con":true,"img":false}]}
{"op":"mcm","clk":"5306518854","pt":1646100066039,"mc":[{"id":"1.195395424","rc":[{"atb":[[1.68,10.96]],"id":40576811}],"con":true,"img":false}]}
{"op":"mcm","clk":"5306518867","pt":1646100066357,"mc":[{"id":"1.195395424","rc":[{"atl":[[4.9,0]],"id":43154453},{"atl":[[3.1,20.56],[2.46,0]],"id":39133526},{"atb":[[9,0],[3.4,17.85],[7.8,0],[4.2,13.52]],"id":39318318},{"atb":[[2.42,0]],"id":38185321},{"atb":[[3.7,0],[2.76,23.15]],"id":40022793},{"atl":[[3.2,0],[3.8,15.15]],"id":42248822},{"atl":[[4.2,0]],"id":40576811}],"con":true,"img":false}]}
{"op":"mcm","clk":"5306518869","pt":1646100066449,"mc":[{"id":"1.195395424","rc":[{"atl":[[5,9.73]],"id":43154453},{"atb":[[2.16,33]],"id":38185321},{"atl":[[4.4,12.98]],"id":40576811}],"con":true,"img":false}]}
{"op":"mcm","clk":"5306519022","pt":1646100069771,"mc":[{"id":"1.195395424","rc":[{"atb":[[1.63,0],[1.69,94.1]],"id":40576811}],"con":true,"img":false}]}
{"op":"mcm","clk":"5306519156","pt":1646100072239,"mc":[{"id":"1.195395424","rc":[{"atb":[[1.68,0]],"id":40576811}],"con":true,"img":false}]}
{"op":"mcm","clk":"5306519184","pt":1646100072852,"mc":[{"id":"1.195395424","rc":[{"atl":[[4.3,0]],"id":43154453},{"atl":[[2.26,0]],"id":39133526},{"atb":[[3.95,0]],"id":40022793},{"atl":[[3.85,0]],"id":40576811}],"con":true,"img":false}]}
{"op":"mcm","clk":"5306519190","pt":1646100072958,"mc":[{"id":"1.195395424","rc":[{"atl":[[4.9,13.11]],"id":43154453},{"atl":[[2.28,42.17]],"id":39133526},{"atb":[[3.7,14.67]],"id":40022793},{"atl":[[4.4,28.17]],"id":40576811}],"con":true,"img":false}]}
{"op":"mcm","clk":"5306519302","pt":1646100074950,"mc":[{"id":"1.195395424","rc":[{"atb":[[1.65,153.85],[1.69,0]],"id":40576811}],"con":true,"img":false}]}
{"op":"mcm","clk":"5306519695","pt":1646100083259,"mc":[{"id":"1.195395424","rc":[{"atb":[[1.69,10.79]],"id":40576811}],"con":true,"img":false}]}
{"op":"mcm","clk":"5306520059","pt":1646100091185,"mc":[{"id":"1.195395424","rc":[{"spn":27.3,"spf":"NaN","id":39318318},{"atl":[[2.52,0]],"id":42248822},{"spn":1.91,"spf":"NaN","id":42248822},{"spn":2.19,"spf":"NaN","id":40576811}],"con":true,"img":false}]}
{"op":"mcm","clk":"5306520063","pt":1646100091288,"mc":[{"id":"1.195395424","rc":[{"atl":[[2.52,44.62],[2.48,22.31]],"id":42248822}],"con":true,"img":false}]}
{"op":"mcm","clk":"5306520068","pt":1646100091389,"mc":[{"id":"1.195395424","rc":[{"atl":[[2.5,0],[2.52,0],[2.46,22.31]],"id":42248822}],"con":true,"img":false}]}
{"op":"mcm","clk":"5306520156","pt":1646100093383,"mc":[{"id":"1.195395424","rc":[{"atb":[[1.69,22.89]],"id":40576811}],"con":true,"img":false}]}
{"op":"mcm","clk":"5306520397","pt":1646100098766,"mc":[{"id":"1.195395424","rc":[{"atb":[[1.7,94.1]],"id":40576811}],"con":true,"img":false}]}
{"op":"mcm","clk":"5306520401","pt":1646100098869,"mc":[{"id":"1.195395424","rc":[{"atb":[[1.65,0]],"id":40576811}],"con":true,"img":false}]}
{"op":"mcm","clk":"5306520522","pt":1646100101377,"mc":[{"id":"1.195395424","rc":[{"atb":[[1.69,12.09]],"id":40576811}],"con":true,"img":false}]}
{"op":"mcm","clk":"5306520822","pt":1646100108179,"mc":[{"id":"1.195395424","rc":[{"atb":[[1.74,10.06]],"id":40576811}],"con":true,"img":false}]}
{"op":"mcm","clk":"5306520965","pt":1646100111561,"mc":[{"id":"1.195395424","rc":[{"atb":[[1.69,0]],"id":40576811}],"con":true,"img":false}]}
{"op":"mcm","clk":"5306521184","pt":1646100117080,"mc":[{"id":"1.195395424","rc":[{"atb":[[1.74,21.34]],"id":40576811}],"con":true,"img":false}]}
{"op":"mcm","clk":"5306521413","pt":1646100122321,"mc":[{"id":"1.195395424","rc":[{"atb":[[1.7,0],[1.75,94.1]],"id":40576811}],"con":true,"img":false}]}
{"op":"mcm","clk":"5306521547","pt":1646100125288,"mc":[{"id":"1.195395424","rc":[{"atb":[[1.74,11.27]],"id":40576811}],"con":true,"img":false}]}
{"op":"mcm","clk":"5306521814","pt":1646100131328,"mc":[{"id":"1.195395424","rc":[{"atb":[[1.79,9.43]],"id":40576811}],"con":true,"img":false}]}
{"op":"mcm","clk":"5306521821","pt":1646100131532,"mc":[{"id":"1.195395424","rc":[{"atb":[[1.8,11.28],[1.75,0]],"id":40576811}],"con":true,"img":false}]}
{"op":"mcm","clk":"5306521943","pt":1646100134302,"mc":[{"id":"1.195395424","rc":[{"atb":[[1.79,0]],"id":40576811}],"con":true,"img":false}]}
{"op":"mcm","clk":"5306521949","pt":1646100134403,"mc":[{"id":"1.195395424","rc":[{"atb":[[1.8,0],[1.75,94.1]],"id":40576811}],"con":true,"img":false}]}
{"op":"mcm","clk":"5306521971","pt":1646100134915,"mc":[{"id":"1.195395424","rc":[{"atb":[[1.74,0]],"id":40576811}],"con":true,"img":false}]}
{"op":"mcm","clk":"5306522181","pt":1646100139530,"mc":[{"id":"1.195395424","rc":[{"atb":[[1.75,0],[1.65,153.85]],"id":40576811}],"con":true,"img":false}]}
{"op":"mcm","clk":"5306522300","pt":1646100142141,"mc":[{"id":"1.195395424","rc":[{"atb":[[1.51,0]],"id":43154453},{"atl":[[4.9,0]],"id":43154453},{"atb":[[9,5.41],[4.2,0]],"id":39318318},{"atb":[[2.16,0]],"id":38185321},{"atb":[[3.7,0]],"id":40022793},{"atl":[[3.8,0],[3.25,18.39],[2.48,0]],"id":42248822},{"atb":[[1.64,0],[1.66,65.58]],"id":40576811},{"atl":[[4.4,12.98]],"id":40576811}],"con":true,"img":false}]}
{"op":"mcm","clk":"5306522303","pt":1646100142242,"mc":[{"id":"1.195395424","rc":[{"atb":[[1.56,148.15]],"id":43154453},{"atl":[[4.4,13.11]],"id":43154453},{"atb":[[2.42,33]],"id":38185321},{"atb":[[3.95,14.67]],"id":40022793},{"atl":[[2.44,22.31]],"id":42248822},{"atl":[[4.1,15.18]],"id":40576811}],"con":true,"img":false}]}
{"op":"mcm","clk":"5306522311","pt":1646100142345,"mc":[{"id":"1.195395424","rc":[{"atl":[[2.52,44.62],[2.46,0]],"id":42248822}],"con":true,"img":false}]}
{"op":"mcm","clk":"5306522516","pt":1646100147054,"mc":[{"id":"1.195395424","rc":[{"atb":[[9,0],[4.2,13.52]],"id":39318318},{"atb":[[2.42,0]],"id":38185321},{"atl":[[3.25,0],[3.75,15.15]],"id":42248822}],"con":true,"img":false}]}
{"op":"mcm","clk":"5306522520","pt":1646100147103,"mc":[{"id":"1.195395424","rc":[{"atb":[[2.16,33]],"id":38185321}],"con":true,"img":false}]}
{"op":"mcm","clk":"5306522616","pt":1646100149255,"mc":[{"id":"1.195395424","rc":[{"atb":[[1.7,10.65]],"id":40576811}],"con":true,"img":false}]}
{"op":"mcm","clk":"5306522886","pt":1646100155647,"mc":[{"id":"1.195395424","rc":[{"atb":[[3.95,0]],"id":40022793},{"atl":[[2.44,0]],"id":42248822},{"spn":1.92,"spf":"NaN","id":42248822},{"atl":[[4.1,0]],"id":40576811},{"spn":2.2,"spf":"NaN","id":40576811}],"con":true,"img":false}]}
{"op":"mcm","clk":"5306522890","pt":1646100155749,"mc":[{"id":"1.195395424","rc":[{"atb":[[3.7,14.67]],"id":40022793},{"atl":[[2.5,22.31]],"id":42248822},{"atl":[[4.4,28.17]],"id":40576811}],"con":true,"img":false}]}
{"op":"mcm","clk":"5306522923","pt":1646100156619,"mc":[{"id":"1.195395424","rc":[{"atl":[[2.4,71.43],[2.3,0]],"id":39133526},{"atb":[[2.42,36.16],[2.64,0]],"id":39318318},{"atb":[[2.74,0],[2.58,46.32]],"id":40022793}],"con":true,"img":false}]}
{"op":"mcm","clk":"5306522962","pt":1646100157643,"mc":[{"id":"1.195395424","rc":[{"atb":[[1.71,65.59]],"id":40576811}],"con":true,"img":false}]}
{"op":"mcm","clk":"5306522968","pt":1646100157744,"mc":[{"id":"1.195395424","rc":[{"atb":[[1.65,0]],"id":40576811}],"con":true,"img":false}]}
{"op":"mcm","clk":"5306522985","pt":1646100158359,"mc":[{"id":"1.195395424","rc":[{"atb":[[1.7,0]],"id":40576811}],"con":true,"img":false}]}
{"op":"mcm","clk":"5306522997","pt":1646100158563,"mc":[{"id":"1.195395424","rc":[{"atb":[[1.67,131.18],[1.71,0]],"id":40576811}],"con":true,"img":false}]}
{"op":"mcm","clk":"5306523082","pt":1646100160462,"mc":[{"id":"1.195395424","rc":[{"atb":[[2.76,0]],"id":40022793}],"con":true,"img":false}]}
{"op":"mcm","clk":"5306523090","pt":1646100160563,"mc":[{"id":"1.195395424","rc":[{"atb":[[2.6,23.15]],"id":40022793}],"con":true,"img":false}]}
{"op":"mcm","clk":"5306523238","pt":1646100164047,"mc":[{"id":"1.195395424","rc":[{"atl":[[4.4,15.18]],"id":40576811}],"con":true,"img":false}]}
{"op":"mcm","clk":"5306523244","pt":1646100164150,"mc":[{"id":"1.195395424","rc":[{"atl":[[5.1,12.98]],"id":40576811}],"con":true,"img":false}]}
{"op":"mcm","clk":"5306523292","pt":1646100164968,"mc":[{"id":"1.195395424","rc":[{"atb":[[1.2,0],[1.16,291.65]],"id":39133526}],"con":true,"img":false}]}
{"op":"mcm","clk":"5306523313","pt":1646100165427,"mc":[{"id":"1.195395424","rc":[{"atl":[[2.48,22.31]],"id":42248822}],"con":true,"img":false}]}
{"op":"mcm","clk":"5306523317","pt":1646100165530,"mc":[{"id":"1.195395424","rc":[{"atl":[[2.52,0]],"id":42248822}],"con":true,"img":false}]}
{"op":"mcm","clk":"5306523408","pt":1646100167323,"mc":[{"id":"1.195395424","rc":[{"atb":[[1.71,10.49]],"id":40576811}],"con":true,"img":false}]}
{"op":"mcm","clk":"5306523411","pt":1646100167426,"mc":[{"id":"1.195395424","rc":[{"atb":[[1.72,65.59],[1.67,0]],"id":40576811}],"con":true,"img":false}]}
{"op":"mcm","clk":"5306523549","pt":1646100170347,"mc":[{"id":"1.195395424","rc":[{"atb":[[1.71,0]],"id":40576811}],"con":true,"img":false}]}
{"op":"mcm","clk":"5306523554","pt":1646100170449,"mc":[{"id":"1.195395424","rc":[{"atb":[[1.67,131.18]],"id":40576811}],"con":true,"img":false}]}
{"op":"mcm","clk":"5306523559","pt":1646100170552,"mc":[{"id":"1.195395424","rc":[{"atb":[[1.72,0]],"id":40576811}],"con":true,"img":false}]}
{"op":"mcm","clk":"5306523772","pt":1646100175063,"mc":[{"id":"1.195395424","rc":[{"atb":[[1.71,11.75]],"id":40576811}],"con":true,"img":false}]}
{"op":"mcm","clk":"5306523981","pt":1646100179258,"mc":[{"id":"1.195395424","rc":[{"atb":[[1.71,22.25]],"id":40576811}],"con":true,"img":false}]}
{"op":"mcm","clk":"5306524751","pt":1646100192168,"mc":[{"id":"1.195395424","rc":[{"atb":[[1.21,0]],"id":39133526},{"atb":[[1.66,0]],"id":40576811}],"con":true,"img":false}]}
{"op":"mcm","clk":"5306524755","pt":1646100192269,"mc":[{"id":"1.195395424","rc":[{"atb":[[1.2,91.76]],"id":39133526},{"atb":[[1.68,65.58]],"id":40576811}],"con":true,"img":false}]}
{"op":"mcm","clk":"5306524793","pt":1646100193297,"mc":[{"id":"1.195395424","rc":[{"atb":[[1.72,65.59]],"id":40576811}],"con":true,"img":false}]}
{"op":"mcm","clk":"5306524799","pt":1646100193399,"mc":[{"id":"1.195395424","rc":[{"atb":[[1.67,0]],"id":40576811}],"con":true,"img":false}]}
{"op":"mcm","clk":"5306524852","pt":1646100194477,"mc":[{"id":"1.195395424","rc":[{"atb":[[1.71,11.75]],"id":40576811}],"con":true,"img":false}]}
{"op":"mcm","clk":"5306524982","pt":1646100196684,"mc":[{"id":"1.195395424","rc":[{"atb":[[9,5.41],[4.2,0]],"id":39318318},{"atb":[[3.7,0]],"id":40022793},{"atl":[[2.5,0]],"id":42248822},{"atl":[[4.4,0]],"id":40576811}],"con":true,"img":false}]}
{"op":"mcm","clk":"5306524990","pt":1646100196787,"mc":[{"id":"1.195395424","rc":[{"atb":[[3.95,14.67]],"id":40022793},{"atl":[[2.52,44.62],[2.46,22.31],[2.48,0]],"id":42248822},{"atl":[[4,15.18]],"id":40576811}],"con":true,"img":false}]}
{"op":"mcm","clk":"5306525163","pt":1646100200177,"mc":[{"id":"1.195395424","rc":[{"atb":[[9,0],[4.2,13.52]],"id":39318318}],"con":true,"img":false}]}
{"op":"mcm","clk":"5306525175","pt":1646100200382,"mc":[{"id":"1.195395424","rc":[{"atb":[[1.76,9.8]],"id":40576811}],"con":true,"img":false}]}
{"op":"mcm","clk":"5306525180","pt":1646100200485,"mc":[{"id":"1.195395424","rc":[{"atb":[[1.77,11.76]],"id":40576811}],"con":true,"img":false}]}
{"op":"mcm","clk":"5306525188","pt":1646100200587,"mc":[{"id":"1.195395424","rc":[{"atb":[[1.72,0]],"id":40576811}],"con":true,"img":false}]}
{"op":"mcm","clk":"5306525333","pt":1646100203506,"mc":[{"id":"1.195395424","rc":[{"atb":[[1.76,0]],"id":40576811}],"con":true,"img":false}]}
{"op":"mcm","clk":"5306525341","pt":1646100203608,"mc":[{"id":"1.195395424","rc":[{"atb":[[1.72,65.59],[1.68,0]],"id":40576811}],"con":true,"img":false}]}
{"op":"mcm","clk":"5306525347","pt":1646100203710,"mc":[{"id":"1.195395424","rc":[{"atb":[[1.5,65.58],[1.77,0]],"id":40576811}],"con":true,"img":false}]}
{"op":"mcm","clk":"5306525492","pt":1646100206895,"mc":[{"id":"1.195395424","rc":[{"atb":[[1.71,0]],"id":40576811}],"con":true,"img":false}]}
{"op":"mcm","clk":"5306525594","pt":1646100208795,"mc":[{"id":"1.195395424","rc":[{"atl":[[2.46,0]],"id":42248822},{"atb":[[1.51,131.18]],"id":40576811}],"con":true,"img":false}]}
{"op":"mcm","clk":"5306525600","pt":1646100208898,"mc":[{"id":"1.195395424","rc":[{"atl":[[2.5,22.31]],"id":42248822},{"atb":[[1.72,0]],"id":40576811}],"con":true,"img":false}]}
{"op":"mcm","clk":"5306525887","pt":1646100215299,"mc":[{"id":"1.195395424","rc":[{"atb":[[1.54,13.8]],"id":40576811}],"con":true,"img":false}]}
{"op":"mcm","clk":"5306526081","pt":1646100219398,"mc":[{"id":"1.195395424","rc":[{"spn":1.74,"spf":"NaN","id":39133526},{"atl":[[2.52,0],[2.48,22.31]],"id":42248822},{"spn":1.9,"spf":"NaN","id":42248822},{"spn":2.12,"spf":"NaN","id":40576811}],"con":true,"img":false}]}
{"op":"mcm","clk":"5306526341","pt":1646100225092,"mc":[{"id":"1.195395424","rc":[{"atb":[[1.54,29.26]],"id":40576811}],"con":true,"img":false}]}
{"op":"mcm","clk":"5306526604","pt":1646100231246,"mc":[{"id":"1.195395424","rc":[{"atb":[[1.55,65.59]],"id":40576811}],"con":true,"img":false}]}
{"op":"mcm","clk":"5306526608","pt":1646100231349,"mc":[{"id":"1.195395424","rc":[{"atb":[[1.51,0]],"id":40576811}],"con":true,"img":false}]}
{"op":"mcm","clk":"5306526720","pt":1646100233609,"mc":[{"id":"1.195395424","rc":[{"atb":[[1.54,15.46]],"id":40576811}],"con":true,"img":false}]}
{"op":"mcm","clk":"5306526990","pt":1646100239561,"mc":[{"id":"1.195395424","rc":[{"atb":[[1.59,12.63]],"id":40576811}],"con":true,"img":false}]}
{"op":"mcm","clk":"5306527003","pt":1646100239715,"mc":[{"id":"1.195395424","rc":[{"atb":[[1.6,15.46],[1.55,0]],"id":40576811}],"con":true,"img":false}]}
{"op":"mcm","clk":"5306527149","pt":1646100242654,"mc":[{"id":"1.195395424","rc":[{"atb":[[1.59,0]],"id":40576811}],"con":true,"img":false}]}
{"op":"mcm","clk":"5306527251","pt":1646100244449,"mc":[{"id":"1.195395424","rc":[{"atb":[[9,5.41]],"id":39318318}],"con":true,"img":false}]}
{"op":"mcm","clk":"5306527256","pt":1646100244554,"mc":[{"id":"1.195395424","rc":[{"atb":[[4.2,0]],"id":39318318}],"con":true,"img":false}]}
{"op":"mcm","clk":"5306527272","pt":1646100244964,"mc":[{"id":"1.195395424","rc":[{"atb":[[1.6,0],[1.55,65.59]],"id":40576811}],"con":true,"img":false}]}
{"op":"mcm","clk":"5306527528","pt":1646100249758,"mc":[{"id":"1.195395424","rc":[{"atb":[[1.54,0]],"id":40576811}],"con":true,"img":false}]}
{"op":"mcm","clk":"5306527547","pt":1646100250065,"mc":[{"id":"1.195395424","rc":[{"atb":[[1.55,0],[1.51,131.18]],"id":40576811}],"con":true,"img":false}]}
{"op":"mcm","clk":"5306527661","pt":1646100252327,"mc":[{"id":"1.195395424","rc":[{"atl":[[2.5,0]],"id":42248822}],"con":true,"img":false}]}
{"op":"mcm","clk":"5306527666","pt":1646100252428,"mc":[{"id":"1.195395424","rc":[{"atl":[[2.52,44.62],[2.46,22.31],[2.48,0]],"id":42248822}],"con":true,"img":false}]}
{"op":"mcm","clk":"5306527672","pt":1646100252531,"mc":[{"id":"1.195395424","rc":[{"atl":[[2.62,61.73]],"id":39133526},{"atl":[[6.2,0],[6.8,7.32]],"id":38185321}],"con":true,"img":false}]}
{"op":"mcm","clk":"5306527679","pt":1646100252637,"mc":[{"id":"1.195395424","rc":[{"atl":[[2.4,0]],"id":39133526}],"con":true,"img":false}]}
{"op":"mcm","clk":"5306527954","pt":1646100257467,"mc":[{"id":"1.195395424","rc":[{"atb":[[1.54,13.8]],"id":40576811}],"con":true,"img":false}]}
{"op":"mcm","clk":"5306528171","pt":1646100261574,"mc":[{"id":"1.195395424","rc":[{"atl":[[2.52,27.59]],"id":39133526},{"atb":[[3.7,15.09]],"id":40022793},{"atl":[[3.2,18.39]],"id":42248822}],"con":true,"img":false}]}
{"op":"mcm","clk":"5306528177","pt":1646100261675,"mc":[{"id":"1.195395424","rc":[{"atl":[[3.1,0]],"id":39133526},{"atb":[[2.16,0]],"id":38185321},{"atb":[[2.6,0]],"id":40022793},{"atl":[[3.75,0]],"id":42248822},{"atl":[[5.1,0]],"id":40576811}],"con":true,"img":false}]}
{"op":"mcm","clk":"5306528183","pt":1646100261777,"mc":[{"id":"1.195395424","rc":[{"atb":[[2.42,33]],"id":38185321},{"atl":[[4.4,12.98]],"id":40576811}],"con":true,"img":false}]}
{"op":"mcm","clk":"5306528348","pt":1646100264657,"mc":[{"id":"1.195395424","rc":[{"atb":[[3.4,0],[7.8,6.49]],"id":39318318}],"con":true,"img":false}]}
{"op":"mcm","clk":"5306528354","pt":1646100264761,"mc":[{"id":"1.195395424","rc":[{"atl":[[2.46,0]],"id":42248822}],"con":true,"img":false}]}
{"op":"mcm","clk":"5306528360","pt":1646100264861,"mc":[{"id":"1.195395424","rc":[{"atl":[[2.5,22.31]],"id":42248822}],"con":true,"img":false}]}
{"op":"mcm","clk":"5306528541","pt":1646100268095,"mc":[{"id":"1.195395424","rc":[{"atb":[[1.54,29.26]],"id":40576811}],"con":true,"img":false}]}
{"op":"mcm","clk":"5306528781","pt":1646100272091,"mc":[{"id":"1.195395424","rc":[{"atb":[[1.55,65.59],[1.51,0]],"id":40576811}],"con":true,"img":false}]}
{"op":"mcm","clk":"5306528805","pt":1646100272603,"mc":[{"id":"1.195395424","rc":[{"atb":[[1.54,15.46]],"id":40576811}],"con":true,"img":false}]}
{"op":"mcm","clk":"5306528901","pt":1646100274497,"mc":[{"id":"1.195395424","rc":[{"atl":[[2.52,0],[2.48,22.31]],"id":42248822}],"con":true,"img":false}]}
{"op":"mcm","clk":"5306529107","pt":1646100278390,"mc":[{"id":"1.195395424","rc":[{"atb":[[1.5,0]],"id":40576811}],"con":true,"img":false}]}
{"op":"mcm","clk":"5306529111","pt":1646100278493,"mc":[{"id":"1.195395424","rc":[{"atb":[[1.52,65.58]],"id":40576811}],"con":true,"img":false}]}
{"op":"mcm","clk":"5306529118","pt":1646100278594,"mc":[{"id":"1.195395424","rc":[{"atb":[[1.59,12.63]],"id":40576811}],"con":true,"img":false}]}
{"op":"mcm","clk":"5306529472","pt":1646100285310,"mc":[{"id":"1.195395424","rc":[{"spn":27.5,"spf":"NaN","id":39318318},{"atb":[[1.54,0]],"id":40576811},{"spn":2.14,"spf":"NaN","id":40576811}],"con":true,"img":false}]}
{"op":"mcm","clk":"5306529732","pt":1646100291087,"mc":[{"id":"1.195395424","rc":[{"atb":[[1.59,26.78]],"id":40576811}],"con":true,"img":false}]}
{"op":"mcm","clk":"5306529857","pt":1646100293903,"mc":[{"id":"1.195395424","rc":[{"atb":[[1.6,65.59],[1.55,0]],"id":40576811}],"con":true,"img":false}]}
{"op":"mcm","clk":"5306530008","pt":1646100296827,"mc":[{"id":"1.195395424","rc":[{"atb":[[1.59,14.15]],"id":40576811}],"con":true,"img":false}]}
{"op":"mcm","clk":"5306530293","pt":1646100302612,"mc":[{"id":"1.195395424","rc":[{"atb":[[1.64,11.64]],"id":40576811}],"con":true,"img":false}]}
{"op":"mcm","clk":"5306530301","pt":1646100302715,"mc":[{"id":"1.195395424","rc":[{"atb":[[1.65,14.15]],"id":40576811}],"con":true,"img":false}]}
{"op":"mcm","clk":"5306530312","pt":1646100302839,"mc":[{"id":"1.195395424","rc":[{"atb":[[1.6,0]],"id":40576811}],"con":true,"img":false}]}
{"op":"mcm","clk":"5306530534","pt":1646100305916,"mc":[{"id":"1.195395424","rc":[{"atb":[[1.64,0]],"id":40576811}],"con":true,"img":false}]}
{"op":"mcm","clk":"5306530582","pt":1646100306938,"mc":[{"id":"1.195395424","rc":[{"atl":[[2.5,0]],"id":42248822}],"con":true,"img":false}]}
{"op":"mcm","clk":"5306530587","pt":1646100307040,"mc":[{"id":"1.195395424","rc":[{"atl":[[2.52,44.62],[2.46,22.31],[2.48,0]],"id":42248822}],"con":true,"img":false}]}
{"op":"mcm","clk":"5306530630","pt":1646100307862,"mc":[{"id":"1.195395424","rc":[{"atb":[[1.6,65.59],[1.65,0]],"id":40576811}],"con":true,"img":false}]}
{"op":"mcm","clk":"5306530724","pt":1646100309449,"mc":[{"id":"1.195395424","rc":[{"atb":[[1.59,0]],"id":40576811}],"con":true,"img":false}]}
{"op":"mcm","clk":"5306530905","pt":1646100312937,"mc":[{"id":"1.195395424","rc":[{"atb":[[1.53,131.18]],"id":40576811}],"con":true,"img":false}]}
{"op":"mcm","clk":"5306530911","pt":1646100313037,"mc":[{"id":"1.195395424","rc":[{"atb":[[1.6,0]],"id":40576811}],"con":true,"img":false}]}
{"op":"mcm","clk":"5306531128","pt":1646100316829,"mc":[{"id":"1.195395424","rc":[{"atl":[[2.52,0]],"id":39133526}],"con":true,"img":false}]}
{"op":"mcm","clk":"5306531135","pt":1646100316929,"mc":[{"id":"1.195395424","rc":[{"atl":[[2.46,27.59]],"id":39133526}],"con":true,"img":false}]}
{"op":"mcm","clk":"5306531322","pt":1646100319846,"mc":[{"id":"1.195395424","rc":[{"atl":[[2.46,0]],"id":42248822}],"con":true,"img":false}]}
{"op":"mcm","clk":"5306531329","pt":1646100319951,"mc":[{"id":"1.195395424","rc":[{"atl":[[2.5,22.31]],"id":42248822}],"con":true,"img":false}]}
{"op":"mcm","clk":"5306531388","pt":1646100320921,"mc":[{"id":"1.195395424","rc":[{"atb":[[1.57,13.07]],"id":40576811}],"con":true,"img":false}]}
{"op":"mcm","clk":"5306531736","pt":1646100327937,"mc":[{"id":"1.195395424","rc":[{"atb":[[1.57,27.71]],"id":40576811}],"con":true,"img":false}]}
{"op":"mcm","clk":"5306531760","pt":1646100328447,"mc":[{"id":"1.195395424","rc":[{"atl":[[2.52,0],[2.48,22.31]],"id":42248822}],"con":true,"img":false}]}
{"op":"mcm","clk":"5306531812","pt":1646100329268,"mc":[{"id":"1.195395424","rc":[{"atb":[[1.58,65.59],[1.53,0]],"id":40576811}],"con":true,"img":false}]}
{"op":"mcm","clk":"5306531829","pt":1646100329676,"mc":[{"id":"1.195395424","rc":[{"atb":[[1.57,14.64]],"id":40576811}],"con":true,"img":false}]}
{"op":"mcm","clk":"5306532165","pt":1646100335773,"mc":[{"id":"1.195395424","rc":[{"atb":[[1.62,12.02]],"id":40576811}],"con":true,"img":false}]}
{"op":"mcm","clk":"5306532731","pt":1646100345564,"mc":[{"id":"1.195395424","rc":[{"atb":[[1.57,0]],"id":40576811},{"spn":2.16,"spf":"NaN","id":40576811}],"con":true,"img":false}]}
{"op":"mcm","clk":"5306532979","pt":1646100349872,"mc":[{"id":"1.195395424","rc":[{"atb":[[1.52,0]],"id":40576811}],"con":true,"img":false}]}
{"op":"mcm","clk":"5306532984","pt":1646100349972,"mc":[{"id":"1.195395424","rc":[{"atb":[[1.59,65.58]],"id":40576811}],"con":true,"img":false}]}
{"op":"mcm","clk":"5306533013","pt":1646100350487,"mc":[{"id":"1.195395424","rc":[{"atb":[[1.63,65.59],[1.58,0]],"id":40576811}],"con":true,"img":false}]}
{"op":"mcm","clk":"5306533048","pt":1646100351001,"mc":[{"id":"1.195395424","rc":[{"atb":[[1.62,0]],"id":40576811}],"con":true,"img":false}]}
{"op":"mcm","clk":"5306533323","pt":1646100355711,"mc":[{"id":"1.195395424","rc":[{"atb":[[1.6,131.18]],"id":40576811}],"con":true,"img":false}]}
{"op":"mcm","clk":"5306533329","pt":1646100355815,"mc":[{"id":"1.195395424","rc":[{"atb":[[1.63,0]],"id":40576811}],"con":true,"img":false}]}
{"op":"mcm","clk":"5306533601","pt":1646100361090,"mc":[{"id":"1.195395424","rc":[{"atl":[[9.8,0],[6.6,7.73]],"id":38185321},{"atl":[[2.5,0]],"id":42248822}],"con":true,"img":false}]}
{"op":"mcm","clk":"5306533605","pt":1646100361192,"mc":[{"id":"1.195395424","rc":[{"atl":[[2.52,44.62],[2.46,22.31],[2.48,0]],"id":42248822}],"con":true,"img":false}]}
{"op":"mcm","clk":"5306533610","pt":1646100361295,"mc":[{"id":"1.195395424","rc":[{"atl":[[2.52,0],[2.48,44.62]],"id":42248822}],"con":true,"img":false}]}
{"op":"mcm","clk":"5306533680","pt":1646100362727,"mc":[{"id":"1.195395424","rc":[{"atb":[[1.64,11.64]],"id":40576811}],"con":true,"img":false}]}
{"op":"mcm","clk":"5306534020","pt":1646100369405,"mc":[{"id":"1.195395424","rc":[{"atb":[[1.64,24.68]],"id":40576811}],"con":true,"img":false}]}
{"op":"mcm","clk":"5306534130","pt":1646100371508,"mc":[{"id":"1.195395424","rc":[{"atb":[[1.6,0],[1.65,65.59]],"id":40576811}],"con":true,"img":false}]}
{"op":"mcm","clk":"5306534311","pt":1646100374941,"mc":[{"id":"1.195395424","rc":[{"atb":[[1.64,13.04]],"id":40576811}],"con":true,"img":false}]}
{"op":"mcm","clk":"5306534645","pt":1646100381109,"mc":[{"id":"1.195395424","rc":[{"atb":[[1.59,0]],"id":40576811}],"con":true,"img":false}]}
{"op":"mcm","clk":"5306534650","pt":1646100381212,"mc":[{"id":"1.195395424","rc":[{"atb":[[1.66,65.58]],"id":40576811}],"con":true,"img":false}]}
{"op":"mcm","clk":"5306534658","pt":1646100381317,"mc":[{"id":"1.195395424","rc":[{"atb":[[1.67,65.59],[1.65,0]],"id":40576811}],"con":true,"img":false}]}
{"op":"mcm","clk":"5306534665","pt":1646100381425,"mc":[{"id":"1.195395424","rc":[{"atb":[[1.69,10.79]],"id":40576811}],"con":true,"img":false}]}
{"op":"mcm","clk":"5306534811","pt":1646100384544,"mc":[{"id":"1.195395424","rc":[{"atl":[[2.4,71.43],[2.62,0]],"id":39133526},{"atl":[[6.2,7.32],[6.8,0]],"id":38185321},{"atl":[[2.44,22.31],[2.48,0]],"id":42248822},{"atb":[[1.69,0]],"id":40576811}],"con":true,"img":false}]}
{"op":"mcm","clk":"5306534978","pt":1646100387827,"mc":[{"id":"1.195395424","rc":[{"atb":[[1.64,0]],"id":40576811}],"con":true,"img":false}]}
{"op":"mcm","clk":"5306534992","pt":1646100388032,"mc":[{"id":"1.195395424","rc":[{"atl":[[10,7.47],[6.6,0]],"id":38185321}],"con":true,"img":false}]}
{"op":"mcm","clk":"5306535123","pt":1646100390438,"mc":[{"id":"1.195395424","rc":[{"atb":[[1.71,10.49]],"id":40576811}],"con":true,"img":false}]}
{"op":"mcm","clk":"5306535129","pt":1646100390542,"mc":[{"id":"1.195395424","rc":[{"atl":[[4.4,0]],"id":43154453},{"atl":[[9.2,5.41],[6.8,0]],"id":40324448},{"atb":[[5.5,9.19],[7.8,0]],"id":39318318},{"atb":[[2.42,0],[1.9,48.69]],"id":38185321},{"atb":[[3.7,0],[2.6,25.47]],"id":40022793}],"con":true,"img":false}]}
{"op":"mcm","clk":"5306535133","pt":1646100390645,"mc":[{"id":"1.195395424","rc":[{"atl":[[5.1,24.83]],"id":43154453}],"con":true,"img":false}]}
{"op":"mcm","clk":"5306535618","pt":1646100399263,"mc":[{"id":"1.195395424","rc":[{"atb":[[1.71,22.25]],"id":40576811}],"con":true,"img":false}]}
{"op":"mcm","clk":"5306535765","pt":1646100402033,"mc":[{"id":"1.195395424","rc":[{"atb":[[1.72,65.59],[1.67,0]],"id":40576811}],"con":true,"img":false}]}
{"op":"mcm","clk":"5306535935","pt":1646100405052,"mc":[{"id":"1.195395424","rc":[{"atb":[[1.71,11.75]],"id":40576811}],"con":true,"img":false}]}
{"op":"mcm","clk":"5306536217","pt":1646100410944,"mc":[{"id":"1.195395424","rc":[{"spn":1.88,"spf":"NaN","id":42248822},{"atb":[[1.76,9.8]],"id":40576811},{"spn":2.23,"spf":"NaN","id":40576811}],"con":true,"img":false}]}
{"op":"mcm","clk":"5306536301","pt":1646100412586,"mc":[{"id":"1.195395424","rc":[{"atb":[[1.66,0]],"id":40576811}],"con":true,"img":false}]}
{"op":"mcm","clk":"5306536307","pt":1646100412690,"mc":[{"id":"1.195395424","rc":[{"atb":[[1.54,65.58]],"id":40576811}],"con":true,"img":false}]}
{"op":"mcm","clk":"5306536482","pt":1646100415564,"mc":[{"id":"1.195395424","rc":[{"atl":[[2.46,0]],"id":42248822}],"con":true,"img":false}]}
{"op":"mcm","clk":"5306536486","pt":1646100415666,"mc":[{"id":"1.195395424","rc":[{"atl":[[2.42,22.31],[2.52,44.62]],"id":42248822}],"con":true,"img":false}]}
{"op":"mcm","clk":"5306536490","pt":1646100415767,"mc":[{"id":"1.195395424","rc":[{"atl":[[2.44,0]],"id":42248822}],"con":true,"img":false}]}
{"op":"mcm","clk":"5306536495","pt":1646100415870,"mc":[{"id":"1.195395424","rc":[{"atl":[[2.4,22.31],[2.52,0]],"id":42248822}],"con":true,"img":false}]}
{"op":"mcm","clk":"5306536592","pt":1646100418076,"mc":[{"id":"1.195395424","rc":[{"atb":[[1.71,0]],"id":40576811}],"con":true,"img":false}]}
{"op":"mcm","clk":"5306536716","pt":1646100420490,"mc":[{"id":"1.195395424","rc":[{"atl":[[5.1,11.72]],"id":43154453}],"con":true,"img":false}]}
{"op":"mcm","clk":"5306536721","pt":1646100420593,"mc":[{"id":"1.195395424","rc":[{"atl":[[4.4,13.11]],"id":43154453}],"con":true,"img":false}]}
{"op":"mcm","clk":"5306536813","pt":1646100422596,"mc":[{"id":"1.195395424","rc":[{"atb":[[1.72,0],[1.77,65.59]],"id":40576811}],"con":true,"img":false}]}
{"op":"mcm","clk":"5306536839","pt":1646100423055,"mc":[{"id":"1.195395424","rc":[{"atb":[[1.76,0]],"id":40576811}],"con":true,"img":false}]}
{"op":"mcm","clk":"5306537035","pt":1646100427672,"mc":[{"id":"1.195395424","rc":[{"atb":[[1.55,131.18],[1.77,0]],"id":40576811}],"con":true,"img":false}]}
{"op":"mcm","clk":"5306537391","pt":1646100434799,"mc":[{"id":"1.195395424","rc":[{"atb":[[1.59,12.63]],"id":40576811}],"con":true,"img":false}]}
{"op":"mcm","clk":"5306537454","pt":1646100436082,"mc":[{"id":"1.195395424","rc":[{"atl":[[2.46,0]],"id":39133526}],"con":true,"img":false}]}
{"op":"mcm","clk":"5306537460","pt":1646100436185,"mc":[{"id":"1.195395424","rc":[{"atl":[[2.38,27.59]],"id":39133526}],"con":true,"img":false}]}
{"op":"mcm","clk":"5306537727","pt":1646100441989,"mc":[{"id":"1.195395424","rc":[{"atb":[[1.59,26.78]],"id":40576811}],"con":true,"img":false}]}
{"op":"mcm","clk":"5306538042","pt":1646100447998,"mc":[{"id":"1.195395424","rc":[{"atb":[[1.6,65.59]],"id":40576811}],"con":true,"img":false}]}
{"op":"mcm","clk":"5306538049","pt":1646100448098,"mc":[{"id":"1.195395424","rc":[{"atb":[[1.55,0]],"id":40576811}],"con":true,"img":false}]}
{"op":"mcm","clk":"5306538139","pt":1646100449895,"mc":[{"id":"1.195395424","rc":[{"atb":[[1.59,14.15]],"id":40576811}],"con":true,"img":false}]}
{"op":"mcm","clk":"5306538144","pt":1646100450000,"mc":[{"id":"1.195395424","rc":[{"atl":[[9.2,0],[7,7.03]],"id":40324448},{"atb":[[5.5,0],[7.8,6.49]],"id":39318318},{"atb":[[2.42,30.84],[1.9,0]],"id":38185321},{"atl":[[2.42,0],[2.38,31.36]],"id":42248822},{"atb":[[1.54,0]],"id":40576811}],"con":true,"img":false}]}
{"op":"mcm","clk":"5306538151","pt":1646100450100,"mc":[{"id":"1.195395424","rc":[{"atb":[[3.7,15.09],[2.6,0]],"id":40022793},{"atl":[[2.4,0],[2.36,22.31]],"id":42248822},{"atb":[[1.56,65.58]],"id":40576811}],"con":true,"img":false}]}
{"op":"mcm","clk":"5306538417","pt":1646100455793,"mc":[{"id":"1.195395424","rc":[{"atb":[[1.64,11.64]],"id":40576811}],"con":true,"img":false}]}
{"op":"mcm","clk":"5306538423","pt":1646100455898,"mc":[{"id":"1.195395424","rc":[{"atb":[[1.6,0],[1.65,14.15]],"id":40576811}],"con":true,"img":false}]}
{"op":"mcm","clk":"5306538433","pt":1646100456101,"mc":[{"id":"1.195395424","rc":[{"atb":[[1.56,0]],"id":40576811}],"con":true,"img":false}]}
{"op":"mcm","clk":"5306538441","pt":1646100456204,"mc":[{"id":"1.195395424","rc":[{"atb":[[1.5,65.58]],"id":40576811}],"con":true,"img":false}]}
{"op":"mcm","clk":"5306538565","pt":1646100458929,"mc":[{"id":"1.195395424","rc":[{"atb":[[1.64,0]],"id":40576811}],"con":true,"img":false}]}
{"op":"mcm","clk":"5306538650","pt":1646100461038,"mc":[{"id":"1.195395424","rc":[{"atb":[[1.6,65.59],[1.65,0]],"id":40576811}],"con":true,"img":false}]}
{"op":"mcm","clk":"5306538906","pt":1646100466941,"mc":[{"id":"1.195395424","rc":[{"atb":[[1.59,0]],"id":40576811}],"con":true,"img":false}]}
{"op":"mcm","clk":"5306538910","pt":1646100467042,"mc":[{"id":"1.195395424","rc":[{"atb":[[1.6,0],[1.51,131.18]],"id":40576811}],"con":true,"img":false}]}
{"op":"mcm","clk":"5306539233","pt":1646100473815,"mc":[{"id":"1.195395424","rc":[{"spn":1.84,"spf":"NaN","id":42248822},{"atb":[[1.54,13.8]],"id":40576811},{"spn":2.12,"spf":"NaN","id":40576811}],"con":true,"img":false}]}
{"op":"mcm","clk":"5306539715","pt":1646100483014,"mc":[{"id":"1.195395424","rc":[{"atl":[[2.38,0]],"id":42248822}],"con":true,"img":false}]}
{"op":"mcm","clk":"5306539719","pt":1646100483115,"mc":[{"id":"1.195395424","rc":[{"atl":[[2.52,44.62],[2.34,31.36]],"id":42248822}],"con":true,"img":false}]}
{"op":"mcm","clk":"5306539724","pt":1646100483218,"mc":[{"id":"1.195395424","rc":[{"atl":[[2.36,0]],"id":42248822}],"con":true,"img":false}]}
{"op":"mcm","clk":"5306539857","pt":1646100485633,"mc":[{"id":"1.195395424","rc":[{"atb":[[1.54,29.26]],"id":40576811}],"con":true,"img":false}]}
{"op":"mcm","clk":"5306539929","pt":1646100486916,"mc":[{"id":"1.195395424","rc":[{"atb":[[1.55,65.59],[1.51,0]],"id":40576811}],"con":true,"img":false}]}
{"op":"mcm","clk":"5306540034","pt":1646100488916,"mc":[{"id":"1.195395424","rc":[{"atb":[[1.54,15.46]],"id":40576811}],"con":true,"img":false}]}
{"op":"mcm","clk":"5306540365","pt":1646100494929,"mc":[{"id":"1.195395424","rc":[{"atb":[[1.59,12.63]],"id":40576811}],"con":true,"img":false}]}
{"op":"mcm","clk":"5306540420","pt":1646100496064,"mc":[{"id":"1.195395424","rc":[{"atl":[[2.34,0]],"id":42248822},{"atb":[[1.5,0]],"id":40576811}],"con":true,"img":false}]}
{"op":"mcm","clk":"5306540427","pt":1646100496164,"mc":[{"id":"1.195395424","rc":[{"atl":[[2.5,31.36]],"id":42248822},{"atb":[[1.56,65.58]],"id":40576811}],"con":true,"img":false}]}
{"op":"mcm","clk":"5306540522","pt":1646100497962,"mc":[{"id":"1.195395424","rc":[{"atb":[[1.59,0]],"id":40576811}],"con":true,"img":false}]}
{"op":"mcm","clk":"5306540761","pt":1646100502879,"mc":[{"id":"1.195395424","rc":[{"atl":[[2.52,0],[2.48,31.37]],"id":42248822}],"con":true,"img":false}]}
{"op":"mcm","clk":"5306540798","pt":1646100503851,"mc":[{"id":"1.195395424","rc":[{"atb":[[1.6,12.42]],"id":40576811}],"con":true,"img":false}]}
{"op":"mcm","clk":"5306540849","pt":1646100504978,"mc":[{"id":"1.195395424","rc":[{"atb":[[1.54,0]],"id":40576811}],"con":true,"img":false}]}
{"op":"mcm","clk":"5306540926","pt":1646100506670,"mc":[{"id":"1.195395424","rc":[{"atb":[[1.61,65.59]],"id":40576811}],"con":true,"img":false}]}
{"op":"mcm","clk":"5306540934","pt":1646100506772,"mc":[{"id":"1.195395424","rc":[{"atb":[[1.55,0]],"id":40576811}],"con":true,"img":false}]}
{"op":"mcm","clk":"5306541079","pt":1646100509949,"mc":[{"id":"1.195395424","rc":[{"atb":[[1.6,0]],"id":40576811}],"con":true,"img":false}]}
{"op":"mcm","clk":"5306541084","pt":1646100510051,"mc":[{"id":"1.195395424","rc":[{"atb":[[1.57,131.18],[1.61,0]],"id":40576811}],"con":true,"img":false}]}
{"op":"mcm","clk":"5306541434","pt":1646100518969,"mc":[{"id":"1.195395424","rc":[{"atb":[[1.61,12.21]],"id":40576811}],"con":true,"img":false}]}
{"op":"mcm","clk":"5306541440","pt":1646100519071,"mc":[{"id":"1.195395424","rc":[{"atb":[[1.62,65.59]],"id":40576811}],"con":true,"img":false}]}
{"op":"mcm","clk":"5306541445","pt":1646100519174,"mc":[{"id":"1.195395424","rc":[{"atb":[[1.57,0]],"id":40576811}],"con":true,"img":false}]}
{"op":"mcm","clk":"5306541559","pt":1646100521994,"mc":[{"id":"1.195395424","rc":[{"atb":[[1.61,0]],"id":40576811}],"con":true,"img":false}]}
{"op":"mcm","clk":"5306541662","pt":1646100524197,"mc":[{"id":"1.195395424","rc":[{"atb":[[1.57,131.18]],"id":40576811}],"con":true,"img":false}]}
{"op":"mcm","clk":"5306541669","pt":1646100524250,"mc":[{"id":"1.195395424","rc":[{"atb":[[1.62,0]],"id":40576811}],"con":true,"img":false}]}
{"op":"mcm","clk":"5306541679","pt":1646100524556,"mc":[{"id":"1.195395424","rc":[{"atl":[[2.4,0],[2.62,61.73]],"id":39133526},{"atl":[[6.2,0],[6.8,9.72]],"id":38185321}],"con":true,"img":false}]}
{"op":"mcm","clk":"5306541949","pt":1646100530954,"mc":[{"id":"1.195395424","rc":[{"atb":[[1.61,12.21]],"id":40576811}],"con":true,"img":false}]}
{"op":"mcm","clk":"5306542200","pt":1646100536287,"mc":[{"id":"1.195395424","rc":[{"atl":[[2.4,69.78],[2.62,0]],"id":39133526},{"atl":[[6.2,7.48],[6.8,0]],"id":38185321},{"spn":1.9,"spf":"NaN","id":42248822},{"spn":2.15,"spf":"NaN","id":40576811}],"con":true,"img":false}]}
{"op":"mcm","clk":"5306542234","pt":1646100536902,"mc":[{"id":"1.195395424","rc":[{"atl":[[2.5,0]],"id":42248822},{"atb":[[1.56,0]],"id":40576811}],"con":true,"img":false}]}
{"op":"mcm","clk":"5306542241","pt":1646100537005,"mc":[{"id":"1.195395424","rc":[{"atl":[[2.52,62.74],[2.46,31.36]],"id":42248822},{"atb":[[1.58,65.58]],"id":40576811}],"con":true,"img":false}]}
{"op":"mcm","clk":"5306542250","pt":1646100537105,"mc":[{"id":"1.195395424","rc":[{"atl":[[2.48,0]],"id":42248822}],"con":true,"img":false}]}
{"op":"mcm","clk":"5306542309","pt":1646100538385,"mc":[{"id":"1.195395424","rc":[{"atb":[[1.62,65.59]],"id":40576811}],"con":true,"img":false}]}
{"op":"mcm","clk":"5306542315","pt":1646100538487,"mc":[{"id":"1.195395424","rc":[{"atb":[[1.57,0]],"id":40576811}],"con":true,"img":false}]}
{"op":"mcm","clk":"5306542373","pt":1646100539972,"mc":[{"id":"1.195395424","rc":[{"atb":[[1.61,0]],"id":40576811}],"con":true,"img":false}]}
{"op":"mcm","clk":"5306542378","pt":1646100540075,"mc":[{"id":"1.195395424","rc":[{"atb":[[1.89,56.18],[1.85,147.06],[1.91,21.98],[1.87,86.21]],"id":40324448},{"atl":[[6.2,22.74],[5.7,4.26],[6.6,22.32],[5.9,12.65]],"id":40324448},{"atb":[[1.2,341.76],[1.18,250],[1.22,227.27],[1.24,83.33]],"id":39133526},{"atl":[[1.89,56.18],[1.91,82.42],[1.87,22.99],[1.93,134.41]],"id":39133526},{"atb":[[3.85,17.54],[3.95,6.78],[3.75,27.27],[3.65,47.17]],"id":39318318},{"atl":[[34,2.27],[38,3.38],[28,1],[30,1.72]],"id":39318318},{"atb":[[2.56,53.43],[2.52,111.88],[2.6,32.91],[2.64,12.2]],"id":38185321},{"atl":[[6.4,13.89],[5.8,4.17],[6,12.4],[6.8,21.55]],"id":38185321},{"atb":[[4,6.67],[3.7,61.39],[3.8,26.79],[3.9,58.88]],"id":40022793},{"atl":[[12,1.82],[13,12.5],[14,5.77],[15,8.93]],"id":40022793},{"atb":[[1.56,35.71],[1.59,131.18],[1.54,92.59],[1.62,0],[1.5,250],[1.52,144.23]],"id":40576811},{"atl":[[8.6,9.87],[9,15.62],[8.2,6.94],[7.8,17.65]],"id":40576811}],"con":true,"img":false}]}
{"op":"mcm","clk":"5306542383","pt":1646100540179,"mc":[{"id":"1.195395424","rc":[{"atl":[[80,0.54],[30,3.99]],"id":39318318}],"con":true,"img":false}]}
{"op":"mcm","clk":"5306542420","pt":1646100540894,"mc":[{"id":"1.195395424","rc":[{"atl":[[75,0]],"id":39318318}],"con":true,"img":false}]}
{"op":"mcm","clk":"5306542426","pt":1646100540996,"mc":[{"id":"1.195395424","rc":[{"atl":[[90,2.84]],"id":39318318}],"con":true,"img":false}]}
{"op":"mcm","clk":"5306542522","pt":1646100542790,"mc":[{"id":"1.195395424","rc":[{"atl":[[5,0],[6.2,7.49],[4.4,0]],"id":43154453},{"atb":[[5,10.82],[7.8,0]],"id":39318318},{"atb":[[2.42,0],[2.16,37.87]],"id":38185321},{"atb":[[2.82,22.39],[3.7,46.3]],"id":40022793},{"atl":[[4.4,0]],"id":40576811}],"con":true,"img":false}]}
{"op":"mcm","clk":"5306542530","pt":1646100542894,"mc":[{"id":"1.195395424","rc":[{"atl":[[5.4,13.11]],"id":43154453},{"atl":[[4.7,12.98]],"id":40576811}],"con":true,"img":false}]}
{"op":"mcm","clk":"5306542536","pt":1646100542994,"mc":[{"id":"1.195395424","rc":[{"atb":[[2.58,0]],"id":38185321}],"con":true,"img":false}]}
{"op":"mcm","clk":"5306542547","pt":1646100543303,"mc":[{"id":"1.195395424","rc":[{"atb":[[1.56,282.08],[1.6,59.67],[1.58,86.21],[1.54,231.48],[1.3,0],[1.35,285.71]],"id":43154453},{"atl":[[12,10.91],[13,4.17],[14,5.77],[15,8.93]],"id":43154453},{"atl":[[7.4,15.62],[4.9,8.2],[5.7,0],[9.4,0]],"id":40324448},{"atl":[[1.87,0],[2.08,92.59],[1.76,26.32],[2.4,0]],"id":39133526},{"atb":[[2.42,0],[3.4,36.16]],"id":39318318},{"atb":[[2.56,106.86],[2.14,0]],"id":38185321},{"atl":[[6.2,0],[6.8,38.79]],"id":38185321},{"atb":[[2.42,49.19],[2.58,0]],"id":40022793},{"atb":[[1.33,236.98],[1.29,250],[1.31,379.37],[1.35,57.14]],"id":42248822},{"atl":[[2.36,36.76],[2.4,53.57],[2.32,15.15],[2.44,86.81]],"id":42248822}],"con":true,"img":false}]}
{"op":"mcm","clk":"5306542562","pt":1646100543513,"mc":[{"id":"1.195395424","rc":[{"atb":[[3.4,0]],"id":39318318}],"con":true,"img":false}]}
{"op":"mcm","clk":"5306542564","pt":1646100543614,"mc":[{"id":"1.195395424","rc":[{"atb":[[2.52,35.84]],"id":39318318}],"con":true,"img":false}]}
{"op":"mcm","clk":"5306542631","pt":1646100544796,"mc":[{"id":"1.195395424","rc":[{"atl":[[2.38,0]],"id":39133526},{"atb":[[2.16,0]],"id":38185321},{"atl":[[2.46,0]],"id":42248822}],"con":true,"img":false}]}
{"op":"mcm","clk":"5306542637","pt":1646100544897,"mc":[{"id":"1.195395424","rc":[{"atl":[[2.54,27.59]],"id":39133526},{"atb":[[1.98,37.87]],"id":38185321},{"atl":[[2.5,31.36]],"id":42248822}],"con":true,"img":false}]}
{"op":"mcm","clk":"5306542660","pt":1646100545309,"mc":[{"id":"1.195395424","rc":[{"atl":[[34,5.3],[30,1.72]],"id":39318318}],"con":true,"img":false}]}
{"op":"mcm","clk":"5306542671","pt":1646100545715,"mc":[{"id":"1.195395424","rc":[{"atb":[[2.6,31.25]],"id":38185321}],"con":true,"img":false}]}
{"op":"mcm","clk":"5306542675","pt":1646100545818,"mc":[{"id":"1.195395424","rc":[{"atb":[[2.66,1.66]],"id":38185321}],"con":true,"img":false}]}
{"op":"mcm","clk":"5306542698","pt":1646100546073,"mc":[{"id":"1.195395424","rc":[{"atb":[[1.6,47.24]],"id":43154453}],"con":true,"img":false}]}
{"op":"mcm","clk":"5306542831","pt":1646100548888,"mc":[{"id":"1.195395424","rc":[{"atb":[[9,0]],"id":39318318}],"con":true,"img":false}]}
{"op":"mcm","clk":"5306542835","pt":1646100548991,"mc":[{"id":"1.195395424","rc":[{"atb":[[7.8,5.41]],"id":39318318},{"atb":[[2.66,6.15]],"id":38185321},{"atb":[[1.63,11.82]],"id":40576811}],"con":true,"img":false}]}
{"op":"mcm","clk":"5306542968","pt":1646100552017,"mc":[{"id":"1.195395424","rc":[{"atb":[[1.64,11.64]],"id":43154453},{"atb":[[1.38,19.61]],"id":42248822}],"con":true,"img":false}]}
{"op":"mcm","clk":"5306543037","pt":1646100553299,"mc":[{"id":"1.195395424","rc":[{"atl":[[5.1,12.2]],"id":40324448},{"atl":[[1.78,64.1]],"id":39133526}],"con":true,"img":false}]}
{"op":"mcm","clk":"5306543052","pt":1646100553710,"mc":[{"id":"1.195395424","rc":[{"atb":[[2.56,101.51]],"id":38185321},{"atb":[[1.63,25.07]],"id":40576811}],"con":true,"img":false}]}
{"op":"mcm","clk":"5306543177","pt":1646100556120,"mc":[{"id":"1.195395424","rc":[{"atl":[[2.4,107.14]],"id":42248822}],"con":true,"img":false}]}
{"op":"mcm","clk":"5306543185","pt":1646100556223,"mc":[{"id":"1.195395424","rc":[{"atl":[[2.52,0]],"id":42248822}],"con":true,"img":false}]}
{"op":"mcm","clk":"5306543341","pt":1646100558736,"mc":[{"id":"1.195395424","rc":[{"atl":[[2.28,9.38]],"id":39133526}],"con":true,"img":false}]}
{"op":"mcm","clk":"5306543349","pt":1646100558839,"mc":[{"id":"1.195395424","rc":[{"atl":[[1.77,32.79]],"id":39133526}],"con":true,"img":false}]}
{"op":"mcm","clk":"5306543361","pt":1646100559202,"mc":[{"id":"1.195395424","rc":[{"atb":[[1.64,65.59]],"id":40576811}],"con":true,"img":false}]}
{"op":"mcm","clk":"5306543364","pt":1646100559301,"mc":[{"id":"1.195395424","rc":[{"atb":[[1.59,0]],"id":40576811}],"con":true,"img":false}]}
{"op":"mcm","clk":"5306543395","pt":1646100559916,"mc":[{"id":"1.195395424","rc":[{"atb":[[1.6,33.33]],"id":43154453},{"atb":[[2.66,11.18]],"id":38185321}],"con":true,"img":false}]}
{"op":"mcm","clk":"5306543441","pt":1646100560840,"mc":[{"id":"1.195395424","rc":[{"atb":[[2.52,82.24]],"id":38185321},{"atb":[[1.58,0]],"id":40576811}],"con":true,"img":false}]}
{"op":"mcm","clk":"5306543447","pt":1646100560943,"mc":[{"id":"1.195395424","rc":[{"atb":[[2.58,29.64]],"id":38185321},{"atb":[[1.6,65.58]],"id":40576811}],"con":true,"img":false}]}
{"op":"mcm","clk":"5306543463","pt":1646100561101,"mc":[{"id":"1.195395424","rc":[{"atb":[[1.64,0]],"id":43154453},{"atb":[[1.63,13.25]],"id":40576811}],"con":true,"img":false}]}
{"op":"mcm","clk":"5306543534","pt":1646100562432,"mc":[{"id":"1.195395424","rc":[{"atb":[[2.42,0],[2.7,49.19]],"id":40022793}],"con":true,"img":false}]}
{"op":"mcm","clk":"5306543547","pt":1646100562736,"mc":[{"id":"1.195395424","rc":[{"atl":[[32,2.7]],"id":39318318},{"atl":[[6.6,7.73]],"id":38185321}],"con":true,"img":false}]}
{"op":"mcm","clk":"5306543554","pt":1646100562840,"mc":[{"id":"1.195395424","rc":[{"atb":[[1.56,210.32]],"id":43154453},{"atl":[[32,5.93],[80,0]],"id":39318318},{"atl":[[10,2.66]],"id":38185321}],"con":true,"img":false}]}
{"op":"mcm","clk":"5306543558","pt":1646100562944,"mc":[{"id":"1.195395424","rc":[{"atb":[[1.62,71.76]],"id":43154453},{"atl":[[34,2.27]],"id":39318318}],"con":true,"img":false}]}
{"op":"mcm","clk":"5306543575","pt":1646100563310,"mc":[{"id":"1.195395424","rc":[{"atl":[[5.3,17.44],[6.6,0]],"id":40324448},{"atl":[[1.89,0],[1.93,0],[1.8,93.75],[1.91,0]],"id":39133526}],"con":true,"img":false}]}
{"op":"mcm","clk":"5306543645","pt":1646100564746,"mc":[{"id":"1.195395424","rc":[{"atl":[[2.5,0]],"id":42248822}],"con":true,"img":false}]}
{"op":"mcm","clk":"5306543650","pt":1646100564799,"mc":[{"id":"1.195395424","rc":[{"atl":[[2.38,31.36]],"id":42248822}],"con":true,"img":false}]}
{"op":"mcm","clk":"5306543656","pt":1646100565004,"mc":[{"id":"1.195395424","rc":[{"atl":[[6.2,8.32]],"id":40324448}],"con":true,"img":false}]}
{"op":"mcm","clk":"5306543753","pt":1646100567052,"mc":[{"id":"1.195395424","rc":[{"atb":[[1.68,10.96]],"id":40576811}],"con":true,"img":false}]}
{"op":"mcm","clk":"5306543916","pt":1646100570127,"mc":[{"id":"1.195395424","rc":[{"atb":[[1.66,11.29]],"id":43154453}],"con":true,"img":false}]}
{"op":"mcm","clk":"5306544059","pt":1646100573351,"mc":[{"id":"1.195395424","rc":[{"atl":[[5.5,27.78]],"id":40324448},{"atl":[[1.82,152.44]],"id":39133526}],"con":true,"img":false}]}
{"op":"mcm","clk":"5306544109","pt":1646100574554,"mc":[{"id":"1.195395424","rc":[{"atl":[[5.9,2.45]],"id":40324448}],"con":true,"img":false}]}
{"op":"mcm","clk":"5306544131","pt":1646100575021,"mc":[{"id":"1.195395424","rc":[{"atl":[[2.36,73.52],[2.4,53.57]],"id":42248822}],"con":true,"img":false}]}
{"op":"mcm","clk":"5306544207","pt":1646100576760,"mc":[{"id":"1.195395424","rc":[{"atl":[[6.2,0]],"id":40324448},{"atb":[[1.16,0],[1.19,547.78]],"id":39133526}],"con":true,"img":false}]}
{"op":"mcm","clk":"5306544211","pt":1646100576863,"mc":[{"id":"1.195395424","rc":[{"atl":[[5.2,8.32]],"id":40324448}],"con":true,"img":false}]}
{"op":"mcm","clk":"5306544278","pt":1646100578144,"mc":[{"id":"1.195395424","rc":[{"atb":[[1.64,0],[1.69,13.25]],"id":40576811}],"con":true,"img":false}]}
{"op":"mcm","clk":"5306544307","pt":1646100578759,"mc":[{"id":"1.195395424","rc":[{"atl":[[7,0],[5.4,9.73]],"id":40324448}],"con":true,"img":false}]}
{"op":"mcm","clk":"5306544329","pt":1646100579221,"mc":[{"id":"1.195395424","rc":[{"atb":[[1.68,0]],"id":40576811}],"con":true,"img":false}]}
{"op":"mcm","clk":"5306544390","pt":1646100580659,"mc":[{"id":"1.195395424","rc":[{"atb":[[1.66,23.94]],"id":43154453},{"atb":[[1.63,0]],"id":40576811}],"con":true,"img":false}]}
{"op":"mcm","clk":"5306544475","pt":1646100582758,"mc":[{"id":"1.195395424","rc":[{"atb":[[1.56,133.93]],"id":43154453},{"atl":[[8.6,5.95],[10.5,0]],"id":38185321},{"atl":[[22,0]],"id":40022793},{"atb":[[1.46,0],[1.55,79.54]],"id":40576811}],"con":true,"img":false}]}
{"op":"mcm","clk":"5306544479","pt":1646100582861,"mc":[{"id":"1.195395424","rc":[{"atb":[[1.59,76.39]],"id":43154453},{"atl":[[14.5,2.7]],"id":40022793}],"con":true,"img":false}]}
{"op":"mcm","clk":"5306544492","pt":1646100583223,"mc":[{"id":"1.195395424","rc":[{"atb":[[1.61,65.59],[1.69,0]],"id":40576811}],"con":true,"img":false}]}
{"op":"mcm","clk":"5306544554","pt":1646100584860,"mc":[{"id":"1.195395424","rc":[{"atl":[[32,3.23],[90,0.13]],"id":39318318},{"atl":[[6.6,0]],"id":38185321},{"atl":[[2.38,0]],"id":42248822}],"con":true,"img":false}]}
{"op":"mcm","clk":"5306544558","pt":1646100584964,"mc":[{"id":"1.195395424","rc":[{"atl":[[36,2.7],[30,4.42]],"id":39318318},{"atl":[[6.2,7.73]],"id":38185321},{"atl":[[2.36,36.76],[2.4,125],[2.34,31.36]],"id":42248822}],"con":true,"img":false}]}
{"op":"mcm","clk":"5306544738","pt":1646100588761,"mc":[{"id":"1.195395424","rc":[{"atb":[[5,0]],"id":39318318}],"con":true,"img":false}]}
{"op":"mcm","clk":"5306544742","pt":1646100588865,"mc":[{"id":"1.195395424","rc":[{"atb":[[5.4,10.82]],"id":39318318}],"con":true,"img":false}]}
{"op":"mcm","clk":"5306544890","pt":1646100591938,"mc":[{"id":"1.195395424","rc":[{"atb":[[1.65,11.46]],"id":40576811}],"con":true,"img":false}]}
{"op":"mcm","clk":"5306544910","pt":1646100592454,"mc":[{"id":"1.195395424","rc":[{"atb":[[1.22,90.91],[1.24,0]],"id":39133526}],"con":true,"img":false}]}
{"op":"mcm","clk":"5306544979","pt":1646100593844,"mc":[{"id":"1.195395424","rc":[{"atl":[[2.4,53.56],[2.32,46.52]],"id":42248822}],"con":true,"img":false}]}
{"op":"mcm","clk":"5306545112","pt":1646100596860,"mc":[{"id":"1.195395424","rc":[{"spn":2.24,"spf":"NaN","id":43154453},{"spn":1.49,"spf":"NaN","id":39133526},{"spn":18.3,"spf":"NaN","id":39318318},{"spn":4.23,"spf":"NaN","id":38185321},{"spn":1.85,"spf":"NaN","id":42248822},{"atb":[[1.66,65.59],[1.61,0]],"id":40576811},{"spn":2.18,"spf":"NaN","id":40576811}],"con":true,"img":false}]}
{"op":"mcm","clk":"5306545162","pt":1646100598140,"mc":[{"id":"1.195395424","rc":[{"atb":[[1.65,0]],"id":40576811}],"con":true,"img":false}]}
{"op":"mcm","clk":"5306545166","pt":1646100598242,"mc":[{"id":"1.195395424","rc":[{"atb":[[1.66,0],[1.61,131.18]],"id":40576811}],"con":true,"img":false}]}
{"op":"mcm","clk":"5306545244","pt":1646100600348,"mc":[{"id":"1.195395424","rc":[{"atb":[[1.65,12.84]],"id":40576811}],"con":true,"img":false}]}
{"op":"mcm","clk":"5306545249","pt":1646100600445,"mc":[{"id":"1.195395424","rc":[{"atb":[[1.66,65.59],[1.61,0]],"id":40576811}],"con":true,"img":false}]}
{"op":"mcm","clk":"5306545266","pt":1646100600753,"mc":[{"id":"1.195395424","rc":[{"atl":[[11.5,4.12],[12.5,0]],"id":40022793}],"con":true,"img":false}]}
{"op":"mcm","clk":"5306545355","pt":1646100602448,"mc":[{"id":"1.195395424","rc":[{"atb":[[1.16,250]],"id":39133526}],"con":true,"img":false}]}
{"op":"mcm","clk":"5306545387","pt":1646100602961,"mc":[{"id":"1.195395424","rc":[{"atb":[[1.42,238.1],[1.35,0]],"id":43154453},{"atl":[[7.4,0],[4.9,3.07],[6.2,19.23],[4.7,5.41]],"id":40324448},{"atl":[[2.64,60.98],[2.08,0],[1.76,0],[1.99,20.2]],"id":39133526},{"atb":[[2.52,0],[3.5,35.84]],"id":39318318},{"atb":[[2.56,48.08],[2.28,78.13]],"id":38185321},{"atl":[[6.8,21.55],[6.6,17.86]],"id":38185321},{"atb":[[2.58,49.19],[2.7,0]],"id":40022793},{"atb":[[1.23,0],[1.3,495.4]],"id":42248822},{"atl":[[2.36,110.29],[2.32,15.15]],"id":42248822}],"con":true,"img":false}]}
{"op":"mcm","clk":"5306545593","pt":1646100606879,"mc":[{"id":"1.195395424","rc":[{"atb":[[1.7,10.65]],"id":40576811}],"con":true,"img":false}]}
{"op":"mcm","clk":"5306545602","pt":1646100607083,"mc":[{"id":"1.195395424","rc":[{"atb":[[1.71,12.84],[1.66,0]],"id":40576811}],"con":true,"img":false}]}
{"op":"mcm","clk":"5306545741","pt":1646100610372,"mc":[{"id":"1.195395424","rc":[{"atb":[[1.7,0]],"id":40576811}],"con":true,"img":false}]}
{"op":"mcm","clk":"5306545837","pt":1646100612168,"mc":[{"id":"1.195395424","rc":[{"atb":[[1.66,35.71]],"id":40576811}],"con":true,"img":false}]}
{"op":"mcm","clk":"5306545841","pt":1646100612270,"mc":[{"id":"1.195395424","rc":[{"atb":[[1.71,0]],"id":40576811}],"con":true,"img":false}]}
{"op":"mcm","clk":"5306545879","pt":1646100612988,"mc":[{"id":"1.195395424","rc":[{"atl":[[4.9,15.89]],"id":40324448},{"atl":[[1.78,0],[2.02,49.02]],"id":39133526}],"con":true,"img":false}]}
{"op":"mcm","clk":"5306545898","pt":1646100613296,"mc":[{"id":"1.195395424","rc":[{"atl":[[5.5,0]],"id":40324448},{"atl":[[1.8,0]],"id":39133526}],"con":true,"img":false}]}
{"op":"mcm","clk":"5306545987","pt":1646100614784,"mc":[{"id":"1.195395424","rc":[{"atl":[[5.4,0]],"id":40324448}],"con":true,"img":false}]}
{"op":"mcm","clk":"5306545992","pt":1646100614884,"mc":[{"id":"1.195395424","rc":[{"atl":[[6,9.73]],"id":40324448}],"con":true,"img":false}]}
{"op":"mcm","clk":"5306546089","pt":1646100616783,"mc":[{"id":"1.195395424","rc":[{"atb":[[1.64,11.64]],"id":40576811}],"con":true,"img":false}]}
{"op":"mcm","clk":"5306546167","pt":1646100618474,"mc":[{"id":"1.195395424","rc":[{"atb":[[1.65,0]],"id":40576811}],"con":true,"img":false}]}
{"op":"mcm","clk":"5306546174","pt":1646100618578,"mc":[{"id":"1.195395424","rc":[{"atb":[[1.65,71.42]],"id":40576811}],"con":true,"img":false}]}
{"op":"mcm","clk":"5306546179","pt":1646100618681,"mc":[{"id":"1.195395424","rc":[{"atb":[[1.66,0]],"id":40576811}],"con":true,"img":false}]}
{"op":"mcm","clk":"5306546279","pt":1646100620890,"mc":[{"id":"1.195395424","rc":[{"atl":[[1.77,0]],"id":39133526}],"con":true,"img":false}]}
{"op":"mcm","clk":"5306546284","pt":1646100620992,"mc":[{"id":"1.195395424","rc":[{"atl":[[1.81,32.79]],"id":39133526}],"con":true,"img":false}]}
{"op":"mcm","clk":"5306546295","pt":1646100621302,"mc":[{"id":"1.195395424","rc":[{"atb":[[1.64,0]],"id":40576811}],"con":true,"img":false}]}
{"op":"mcm","clk":"5306546310","pt":1646100621505,"mc":[{"id":"1.195395424","rc":[{"atl":[[6.2,0],[5.5,22.22]],"id":40324448},{"atl":[[2.4,65.6],[2.64,0]],"id":39133526},{"atb":[[3.5,0],[3.75,63.11]],"id":39318318},{"atb":[[2.52,148.03],[2.28,0]],"id":38185321},{"atl":[[6,24.8],[6.6,0]],"id":38185321},{"atb":[[2.88,45.09],[2.58,0]],"id":40022793},{"atb":[[1.37,236.98],[1.3,201.28]],"id":42248822},{"atl":[[2.36,36.76],[2.32,46.52]],"id":42248822}],"con":true,"img":false}]}
{"op":"mcm","clk":"5306546369","pt":1646100622796,"mc":[{"id":"1.195395424","rc":[{"atl":[[11.5,0]],"id":40022793}],"con":true,"img":false}]}
{"op":"mcm","clk":"5306546373","pt":1646100622897,"mc":[{"id":"1.195395424","rc":[{"atl":[[11,4.12]],"id":40022793}],"con":true,"img":false}]}
{"op":"mcm","clk":"5306546380","pt":1646100623000,"mc":[{"id":"1.195395424","rc":[{"atl":[[5.1,18.29]],"id":40324448},{"atl":[[1.82,0],[2.06,70.75]],"id":39133526}],"con":true,"img":false}]}
{"op":"mcm","clk":"5306546427","pt":1646100623673,"mc":[{"id":"1.195395424","rc":[{"atb":[[1.65,0],[1.61,142.84]],"id":40576811}],"con":true,"img":false}]}
{"op":"mcm","clk":"5306546506","pt":1646100625164,"mc":[{"id":"1.195395424","rc":[{"atb":[[1.38,0]],"id":42248822}],"con":true,"img":false}]}
{"op":"mcm","clk":"5306546581","pt":1646100626594,"mc":[{"id":"1.195395424","rc":[{"atb":[[1.34,294.12]],"id":42248822}],"con":true,"img":false}]}
{"op":"mcm","clk":"5306546586","pt":1646100626697,"mc":[{"id":"1.195395424","rc":[{"atb":[[1.37,0]],"id":42248822}],"con":true,"img":false}]}
{"op":"mcm","clk":"5306546807","pt":1646100630800,"mc":[{"id":"1.195395424","rc":[{"atl":[[1.81,0]],"id":39133526}],"con":true,"img":false}]}
{"op":"mcm","clk":"5306546809","pt":1646100630902,"mc":[{"id":"1.195395424","rc":[{"atl":[[2,32.79]],"id":39133526}],"con":true,"img":false}]}
{"op":"mcm","clk":"5306546943","pt":1646100633005,"mc":[{"id":"1.195395424","rc":[{"atl":[[5.3,29.07]],"id":40324448},{"atl":[[2.1,113.64]],"id":39133526}],"con":true,"img":false}]}
{"op":"mcm","clk":"5306546972","pt":1646100633677,"mc":[{"id":"1.195395424","rc":[{"atb":[[1.38,19.61]],"id":42248822},{"atb":[[1.65,11.46]],"id":40576811}],"con":true,"img":false}]}
{"op":"mcm","clk":"5306547121","pt":1646100636697,"mc":[{"id":"1.195395424","rc":[{"atl":[[5.2,0]],"id":40324448},{"atb":[[1.65,24.3]],"id":40576811}],"con":true,"img":false}]}
{"op":"mcm","clk":"5306547126","pt":1646100636796,"mc":[{"id":"1.195395424","rc":[{"atl":[[5,8.32]],"id":40324448}],"con":true,"img":false}]}
{"op":"mcm","clk":"5306547133","pt":1646100636904,"mc":[{"id":"1.195395424","rc":[{"atb":[[1.66,65.59],[1.61,0]],"id":40576811}],"con":true,"img":false}]}
{"op":"mcm","clk":"5306547206","pt":1646100638794,"mc":[{"id":"1.195395424","rc":[{"atb":[[1.6,0]],"id":40576811}],"con":true,"img":false}]}
{"op":"mcm","clk":"5306547212","pt":1646100638897,"mc":[{"id":"1.195395424","rc":[{"atb":[[1.62,65.58]],"id":40576811}],"con":true,"img":false}]}
{"op":"mcm","clk":"5306547241","pt":1646100639509,"mc":[{"id":"1.195395424","rc":[{"atb":[[1.65,12.84]],"id":40576811}],"con":true,"img":false}]}
{"op":"mcm","clk":"5306547260","pt":1646100639817,"mc":[{"id":"1.195395424","rc":[{"atb":[[1.37,236.98],[1.34,0]],"id":42248822}],"con":true,"img":false}]}
{"op":"mcm","clk":"5306547391","pt":1646100642796,"mc":[{"id":"1.195395424","rc":[{"atl":[[6.2,0]],"id":38185321},{"atb":[[1.33,151.52],[1.38,0]],"id":42248822},{"atl":[[2.34,0]],"id":42248822}],"con":true,"img":false}]}
{"op":"mcm","clk":"5306547394","pt":1646100642892,"mc":[{"id":"1.195395424","rc":[{"atl":[[5.9,7.73]],"id":38185321},{"atb":[[1.37,0],[1.33,445.64],[1.38,85.46]],"id":42248822},{"atl":[[2.4,125],[2.32,15.15],[2.3,31.36]],"id":42248822}],"con":true,"img":false}]}
{"op":"mcm","clk":"5306547460","pt":1646100644729,"mc":[{"id":"1.195395424","rc":[{"atl":[[11,0]],"id":40022793}],"con":true,"img":false}]}
{"op":"mcm","clk":"5306547464","pt":1646100644833,"mc":[{"id":"1.195395424","rc":[{"atl":[[10.5,4.12]],"id":40022793}],"con":true,"img":false}]}
{"op":"mcm","clk":"5306547522","pt":1646100646013,"mc":[{"id":"1.195395424","rc":[{"atb":[[1.7,10.65]],"id":40576811}],"con":true,"img":false}]}
{"op":"mcm","clk":"5306547716","pt":1646100650830,"mc":[{"id":"1.195395424","rc":[{"atb":[[1.38,0]],"id":42248822},{"atl":[[2.3,0]],"id":42248822}],"con":true,"img":false}]}
{"op":"mcm","clk":"5306547723","pt":1646100650934,"mc":[{"id":"1.195395424","rc":[{"atb":[[1.32,312.5],[1.34,85.46]],"id":42248822},{"atl":[[2.34,31.36]],"id":42248822}],"con":true,"img":false}]}
{"op":"mcm","clk":"5306547729","pt":1646100651036,"mc":[{"id":"1.195395424","rc":[{"atb":[[1.33,151.52]],"id":42248822}],"con":true,"img":false}]}
{"op":"mcm","clk":"5306547817","pt":1646100652835,"mc":[{"id":"1.195395424","rc":[{"atl":[[10.5,0]],"id":40022793}],"con":true,"img":false}]}
{"op":"mcm","clk":"5306547820","pt":1646100652939,"mc":[{"id":"1.195395424","rc":[{"atl":[[11.5,4.12]],"id":40022793}],"con":true,"img":false}]}
{"op":"mcm","clk":"5306547887","pt":1646100654427,"mc":[{"id":"1.195395424","rc":[{"atb":[[1.65,0]],"id":40576811}],"con":true,"img":false}]}
{"op":"mcm","clk":"5306547931","pt":1646100655146,"mc":[{"id":"1.195395424","rc":[{"atb":[[1.66,0],[1.71,65.59]],"id":40576811}],"con":true,"img":false}]}
{"op":"mcm","clk":"5306548059","pt":1646100657923,"mc":[{"id":"1.195395424","rc":[{"spn":3.38,"spf":"NaN","id":40324448},{"spn":1.6,"spf":"NaN","id":39133526},{"atb":[[1.38,19.61]],"id":42248822},{"atb":[[1.7,0]],"id":40576811},{"spn":2.2,"spf":"NaN","id":40576811}],"con":true,"img":false}]}
{"op":"mcm","clk":"5306548063","pt":1646100658023,"mc":[{"id":"1.195395424","rc":[{"atb":[[1.63,131.18]],"id":40576811}],"con":true,"img":false}]}
{"op":"mcm","clk":"5306548067","pt":1646100658126,"mc":[{"id":"1.195395424","rc":[{"atb":[[1.71,0]],"id":40576811}],"con":true,"img":false}]}
{"op":"mcm","clk":"5306548165","pt":1646100660848,"mc":[{"id":"1.195395424","rc":[{"atl":[[2.54,0]],"id":39133526},{"atb":[[1.62,0]],"id":40576811}],"con":true,"img":false}]}
{"op":"mcm","clk":"5306548168","pt":1646100660903,"mc":[{"id":"1.195395424","rc":[{"atl":[[2.38,27.59]],"id":39133526},{"atb":[[1.64,65.58]],"id":40576811}],"con":true,"img":false}]}
{"op":"mcm","clk":"5306548172","pt":1646100661008,"mc":[{"id":"1.195395424","rc":[{"atb":[[1.37,85.46],[1.32,0]],"id":42248822},{"atl":[[2.4,53.56],[2.32,46.52]],"id":42248822}],"con":true,"img":false}]}
{"op":"mcm","clk":"5306548253","pt":1646100662851,"mc":[{"id":"1.195395424","rc":[{"atl":[[6,0]],"id":40324448}],"con":true,"img":false}]}
{"op":"mcm","clk":"5306548257","pt":1646100662910,"mc":[{"id":"1.195395424","rc":[{"atl":[[5.4,9.73]],"id":40324448}],"con":true,"img":false}]}
{"op":"mcm","clk":"5306548314","pt":1646100663931,"mc":[{"id":"1.195395424","rc":[{"atb":[[1.38,0]],"id":42248822}],"con":true,"img":false}]}
{"op":"mcm","clk":"5306548322","pt":1646100664035,"mc":[{"id":"1.195395424","rc":[{"atb":[[1.35,228.06]],"id":42248822}],"con":true,"img":false}]}
{"op":"mcm","clk":"5306548328","pt":1646100664138,"mc":[{"id":"1.195395424","rc":[{"atb":[[1.37,0]],"id":42248822}],"con":true,"img":false}]}
{"op":"mcm","clk":"5306548531","pt":1646100669730,"mc":[{"id":"1.195395424","rc":[{"atb":[[1.68,10.96]],"id":40576811}],"con":true,"img":false}]}
{"op":"mcm","clk":"5306548657","pt":1646100673042,"mc":[{"id":"1.195395424","rc":[{"atb":[[1.38,19.61]],"id":42248822}],"con":true,"img":false}]}
{"op":"mcm","clk":"5306548667","pt":1646100673242,"mc":[{"id":"1.195395424","rc":[{"atb":[[1.37,151.52],[1.35,57.14]],"id":42248822}],"con":true,"img":false}]}
{"op":"mcm","clk":"5306548735","pt":1646100674731,"mc":[{"id":"1.195395424","rc":[{"atl":[[11.5,0]],"id":40022793}],"con":true,"img":false}]}
{"op":"mcm","clk":"5306548738","pt":1646100674833,"mc":[{"id":"1.195395424","rc":[{"atl":[[11,4.12]],"id":40022793}],"con":true,"img":false}]}
{"op":"mcm","clk":"5306548753","pt":1646100675242,"mc":[{"id":"1.195395424","rc":[{"atb":[[1.38,0]],"id":42248822}],"con":true,"img":false}]}
{"op":"mcm","clk":"5306548757","pt":1646100675344,"mc":[{"id":"1.195395424","rc":[{"atb":[[1.37,0],[1.35,342.85]],"id":42248822}],"con":true,"img":false}]}
{"op":"mcm","clk":"5306548777","pt":1646100676056,"mc":[{"id":"1.195395424","rc":[{"atb":[[1.69,65.59]],"id":40576811}],"con":true,"img":false}]}
{"op":"mcm","clk":"5306548782","pt":1646100676159,"mc":[{"id":"1.195395424","rc":[{"atb":[[1.63,0]],"id":40576811}],"con":true,"img":false}]}
{"op":"mcm","clk":"5306548866","pt":1646100678727,"mc":[{"id":"1.195395424","rc":[{"atl":[[4,0]],"id":40576811}],"con":true,"img":false}]}
{"op":"mcm","clk":"5306548872","pt":1646100678830,"mc":[{"id":"1.195395424","rc":[{"atl":[[4.4,15.18]],"id":40576811}],"con":true,"img":false}]}
{"op":"mcm","clk":"5306548886","pt":1646100679138,"mc":[{"id":"1.195395424","rc":[{"atb":[[1.38,21.97]],"id":42248822},{"atb":[[1.68,0]],"id":40576811}],"con":true,"img":false}]}
{"op":"mcm","clk":"5306548890","pt":1646100679247,"mc":[{"id":"1.195395424","rc":[{"atb":[[1.65,131.18],[1.69,0]],"id":40576811}],"con":true,"img":false}]}
{"op":"mcm","clk":"5306549050","pt":1646100682839,"mc":[{"id":"1.195395424","rc":[{"atb":[[1.34,0]],"id":42248822},{"atl":[[2.34,0]],"id":42248822}],"con":true,"img":false}]}
{"op":"mcm","clk":"5306549055","pt":1646100682945,"mc":[{"id":"1.195395424","rc":[{"atb":[[1.36,85.46]],"id":42248822},{"atl":[[2.4,125],[2.32,15.15],[2.3,31.36]],"id":42248822}],"con":true,"img":false}]}
{"op":"mcm","clk":"5306549239","pt":1646100687261,"mc":[{"id":"1.195395424","rc":[{"atb":[[1.69,10.79]],"id":40576811}],"con":true,"img":false}]}
{"op":"mcm","clk":"5306549377","pt":1646100690760,"mc":[{"id":"1.195395424","rc":[{"atl":[[2.3,0]],"id":42248822}],"con":true,"img":false}]}
{"op":"mcm","clk":"5306549383","pt":1646100690860,"mc":[{"id":"1.195395424","rc":[{"atl":[[2.34,31.36]],"id":42248822}],"con":true,"img":false}]}
{"op":"mcm","clk":"5306549388","pt":1646100690964,"mc":[{"id":"1.195395424","rc":[{"atb":[[1.39,19.11]],"id":42248822}],"con":true,"img":false}]}
{"op":"mcm","clk":"5306549492","pt":1646100693185,"mc":[{"id":"1.195395424","rc":[{"atb":[[1.37,151.52],[1.35,57.14]],"id":42248822}],"con":true,"img":false}]}
{"op":"mcm","clk":"5306549528","pt":1646100693857,"mc":[{"id":"1.195395424","rc":[{"atb":[[1.39,0]],"id":42248822}],"con":true,"img":false}]}
{"op":"mcm","clk":"5306549576","pt":1646100694981,"mc":[{"id":"1.195395424","rc":[{"atb":[[1.38,0]],"id":42248822}],"con":true,"img":false}]}
{"op":"mcm","clk":"5306549581","pt":1646100695082,"mc":[{"id":"1.195395424","rc":[{"atb":[[1.69,22.89]],"id":40576811}],"con":true,"img":false}]}
{"op":"mcm","clk":"5306549660","pt":1646100696884,"mc":[{"id":"1.195395424","rc":[{"atl":[[11,0]],"id":40022793}],"con":true,"img":false}]}
{"op":"mcm","clk":"5306549667","pt":1646100696985,"mc":[{"id":"1.195395424","rc":[{"atl":[[10.5,4.12]],"id":40022793},{"atb":[[1.7,65.59],[1.65,0]],"id":40576811}],"con":true,"img":false}]}
{"op":"mcm","clk":"5306549764","pt":1646100698884,"mc":[{"id":"1.195395424","rc":[{"atb":[[1.64,0]],"id":40576811}],"con":true,"img":false}]}
{"op":"mcm","clk":"5306549768","pt":1646100698986,"mc":[{"id":"1.195395424","rc":[{"atb":[[1.66,65.58]],"id":40576811}],"con":true,"img":false}]}
{"op":"mcm","clk":"5306549825","pt":1646100700068,"mc":[{"id":"1.195395424","rc":[{"atb":[[1.4,18.63]],"id":42248822},{"atb":[[1.69,12.09]],"id":40576811}],"con":true,"img":false}]}
{"op":"mcm","clk":"5306549846","pt":1646100700685,"mc":[{"id":"1.195395424","rc":[{"atl":[[2.4,53.56],[2.32,46.52]],"id":42248822}],"con":true,"img":false}]}
{"op":"mcm","clk":"5306550024","pt":1646100704891,"mc":[{"id":"1.195395424","rc":[{"atl":[[10.5,0]],"id":40022793}],"con":true,"img":false}]}
{"op":"mcm","clk":"5306550029","pt":1646100704992,"mc":[{"id":"1.195395424","rc":[{"atl":[[11.5,4.12]],"id":40022793}],"con":true,"img":false}]}
{"op":"mcm","clk":"5306550068","pt":1646100705869,"mc":[{"id":"1.195395424","rc":[{"atb":[[1.74,10.06]],"id":40576811}],"con":true,"img":false}]}
{"op":"mcm","clk":"5306550129","pt":1646100707098,"mc":[{"id":"1.195395424","rc":[{"atb":[[1.4,39.5]],"id":42248822}],"con":true,"img":false}]}
{"op":"mcm","clk":"5306550216","pt":1646100708773,"mc":[{"id":"1.195395424","rc":[{"atb":[[1.66,0]],"id":40576811}],"con":true,"img":false}]}
{"op":"mcm","clk":"5306550221","pt":1646100708872,"mc":[{"id":"1.195395424","rc":[{"atb":[[1.64,65.58]],"id":40576811}],"con":true,"img":false}]}
{"op":"mcm","clk":"5306550402","pt":1646100713290,"mc":[{"id":"1.195395424","rc":[{"atb":[[1.69,0]],"id":40576811}],"con":true,"img":false}]}
{"op":"mcm","clk":"5306550457","pt":1646100714472,"mc":[{"id":"1.195395424","rc":[{"atb":[[1.75,65.59]],"id":40576811}],"con":true,"img":false}]}
{"op":"mcm","clk":"5306550463","pt":1646100714576,"mc":[{"id":"1.195395424","rc":[{"atb":[[1.7,0]],"id":40576811}],"con":true,"img":false}]}
{"op":"mcm","clk":"5306550473","pt":1646100714781,"mc":[{"id":"1.195395424","rc":[{"atb":[[1.36,0]],"id":42248822}],"con":true,"img":false}]}
{"op":"mcm","clk":"5306550480","pt":1646100714885,"mc":[{"id":"1.195395424","rc":[{"atb":[[1.38,85.46]],"id":42248822}],"con":true,"img":false}]}
{"op":"mcm","clk":"5306550485","pt":1646100714989,"mc":[{"id":"1.195395424","rc":[{"atb":[[1.74,0]],"id":40576811}],"con":true,"img":false}]}
{"op":"mcm","clk":"5306550492","pt":1646100715093,"mc":[{"id":"1.195395424","rc":[{"atb":[[1.75,0],[1.65,131.18]],"id":40576811}],"con":true,"img":false}]}
{"op":"mcm","clk":"5306550609","pt":1646100717917,"mc":[{"id":"1.195395424","rc":[{"atb":[[1.4,20.87]],"id":42248822}],"con":true,"img":false}]}
{"op":"mcm","clk":"5306550756","pt":1646100720899,"mc":[{"id":"1.195395424","rc":[{"atb":[[2.82,0]],"id":40022793},{"spn":1.86,"spf":"NaN","id":42248822},{"spn":2.17,"spf":"NaN","id":40576811}],"con":true,"img":false}]}
{"op":"mcm","clk":"5306550761","pt":1646100720999,"mc":[{"id":"1.195395424","rc":[{"atb":[[2.9,22.39]],"id":40022793}],"con":true,"img":false}]}
{"op":"mcm","clk":"5306550837","pt":1646100722801,"mc":[{"id":"1.195395424","rc":[{"atl":[[2.34,0]],"id":42248822}],"con":true,"img":false}]}
{"op":"mcm","clk":"5306550842","pt":1646100722905,"mc":[{"id":"1.195395424","rc":[{"atl":[[2.3,31.36]],"id":42248822}],"con":true,"img":false}]}
{"op":"mcm","clk":"5306550844","pt":1646100723006,"mc":[{"id":"1.195395424","rc":[{"atl":[[2.4,125],[2.32,15.15]],"id":42248822}],"con":true,"img":false}]}
{"op":"mcm","clk":"5306550846","pt":1646100723108,"mc":[{"id":"1.195395424","rc":[{"atl":[[2.4,53.56],[2.32,77.89]],"id":42248822}],"con":true,"img":false}]}
{"op":"mcm","clk":"5306550894","pt":1646100723882,"mc":[{"id":"1.195395424","rc":[{"atb":[[1.41,18.17]],"id":42248822},{"atb":[[1.69,10.79]],"id":40576811}],"con":true,"img":false}]}
{"op":"mcm","clk":"5306551027","pt":1646100726807,"mc":[{"id":"1.195395424","rc":[{"atl":[[11.5,0]],"id":40022793}],"con":true,"img":false}]}
{"op":"mcm","clk":"5306551031","pt":1646100726910,"mc":[{"id":"1.195395424","rc":[{"atl":[[11,4.12]],"id":40022793}],"con":true,"img":false}]}
{"op":"mcm","clk":"5306551272","pt":1646100732514,"mc":[{"id":"1.195395424","rc":[{"atb":[[1.7,65.59],[1.65,0]],"id":40576811}],"con":true,"img":false}]}
{"op":"mcm","clk":"5306551293","pt":1646100733025,"mc":[{"id":"1.195395424","rc":[{"atb":[[1.69,0]],"id":40576811}],"con":true,"img":false}]}
{"op":"mcm","clk":"5306551341","pt":1646100733901,"mc":[{"id":"1.195395424","rc":[{"atb":[[1.4,0]],"id":42248822}],"con":true,"img":false}]}
{"op":"mcm","clk":"5306551381","pt":1646100734721,"mc":[{"id":"1.195395424","rc":[{"atl":[[5.4,0]],"id":40324448},{"atb":[[1.31,241.94]],"id":42248822},{"atb":[[1.64,0]],"id":40576811}],"con":true,"img":false}]}
{"op":"mcm","clk":"5306551385","pt":1646100734821,"mc":[{"id":"1.195395424","rc":[{"atl":[[5.2,9.73]],"id":40324448},{"atb":[[1.34,137.43]],"id":42248822},{"atb":[[1.66,65.58]],"id":40576811}],"con":true,"img":false}]}
{"op":"mcm","clk":"5306551536","pt":1646100737601,"mc":[{"id":"1.195395424","rc":[{"atb":[[1.67,131.18],[1.7,0]],"id":40576811}],"con":true,"img":false}]}
{"op":"mcm","clk":"5306551630","pt":1646100739504,"mc":[{"id":"1.195395424","rc":[{"atb":[[1.41,38.54]],"id":42248822}],"con":true,"img":false}]}
{"op":"mcm","clk":"5306551889","pt":1646100745002,"mc":[{"id":"1.195395424","rc":[{"atb":[[1.71,10.49]],"id":40576811}],"con":true,"img":false}]}
{"op":"mcm","clk":"5306552068","pt":1646100748742,"mc":[{"id":"1.195395424","rc":[{"atl":[[11,0]],"id":40022793}],"con":true,"img":false}]}
{"op":"mcm","clk":"5306552076","pt":1646100748845,"mc":[{"id":"1.195395424","rc":[{"atl":[[10.5,4.12]],"id":40022793}],"con":true,"img":false}]}
{"op":"mcm","clk":"5306552187","pt":1646100751148,"mc":[{"id":"1.195395424","rc":[{"atb":[[1.71,22.25]],"id":40576811}],"con":true,"img":false}]}
{"op":"mcm","clk":"5306552348","pt":1646100754735,"mc":[{"id":"1.195395424","rc":[{"atb":[[1.72,65.59],[1.67,0],[1.66,0]],"id":40576811}],"con":true,"img":false}]}
{"op":"mcm","clk":"5306552352","pt":1646100754837,"mc":[{"id":"1.195395424","rc":[{"atb":[[1.68,65.58]],"id":40576811}],"con":true,"img":false}]}
{"op":"mcm","clk":"5306552443","pt":1646100756839,"mc":[{"id":"1.195395424","rc":[{"atl":[[10.5,0]],"id":40022793}],"con":true,"img":false}]}
{"op":"mcm","clk":"5306552446","pt":1646100756942,"mc":[{"id":"1.195395424","rc":[{"atl":[[11.5,4.12]],"id":40022793}],"con":true,"img":false}]}
{"op":"mcm","clk":"5306552457","pt":1646100757251,"mc":[{"id":"1.195395424","rc":[{"atb":[[1.71,11.75]],"id":40576811}],"con":true,"img":false}]}
{"op":"mcm","clk":"5306552687","pt":1646100763021,"mc":[{"id":"1.195395424","rc":[{"atb":[[1.76,9.8]],"id":40576811}],"con":true,"img":false}]}
{"op":"mcm","clk":"5306552843","pt":1646100766754,"mc":[{"id":"1.195395424","rc":[{"atb":[[1.68,0]],"id":40576811}],"con":true,"img":false}]}
{"op":"mcm","clk":"5306552847","pt":1646100766858,"mc":[{"id":"1.195395424","rc":[{"atb":[[1.64,65.58]],"id":40576811}],"con":true,"img":false}]}
{"op":"mcm","clk":"5306552939","pt":1646100769471,"mc":[{"id":"1.195395424","rc":[{"atb":[[1.71,0]],"id":40576811}],"con":true,"img":false}]}
{"op":"mcm","clk":"5306553044","pt":1646100771774,"mc":[{"id":"1.195395424","rc":[{"atb":[[1.72,0],[1.77,65.59]],"id":40576811}],"con":true,"img":false}]}
{"op":"mcm","clk":"5306553061","pt":1646100772135,"mc":[{"id":"1.195395424","rc":[{"atb":[[1.76,0]],"id":40576811}],"con":true,"img":false}]}
{"op":"mcm","clk":"5306553067","pt":1646100772237,"mc":[{"id":"1.195395424","rc":[{"atb":[[1.65,131.18]],"id":40576811}],"con":true,"img":false}]}
{"op":"mcm","clk":"5306553072","pt":1646100772340,"mc":[{"id":"1.195395424","rc":[{"atb":[[1.77,0]],"id":40576811}],"con":true,"img":false}]}
{"op":"mcm","clk":"5306553353","pt":1646100778746,"mc":[{"id":"1.195395424","rc":[{"atl":[[11.5,0]],"id":40022793}],"con":true,"img":false}]}
{"op":"mcm","clk":"5306553360","pt":1646100778851,"mc":[{"id":"1.195395424","rc":[{"atl":[[11,4.12]],"id":40022793}],"con":true,"img":false}]}
{"op":"mcm","clk":"5306553501","pt":1646100782041,"mc":[{"id":"1.195395424","rc":[{"spn":1.85,"spf":"NaN","id":42248822},{"atb":[[1.69,10.79]],"id":40576811},{"spn":2.19,"spf":"NaN","id":40576811}],"con":true,"img":false}]}
{"op":"mcm","clk":"5306553750","pt":1646100787271,"mc":[{"id":"1.195395424","rc":[{"atb":[[1.69,22.89]],"id":40576811}],"con":true,"img":false}]}
{"op":"mcm","clk":"5306553848","pt":1646100789064,"mc":[{"id":"1.195395424","rc":[{"atb":[[1.7,65.59],[1.65,0]],"id":40576811}],"con":true,"img":false}]}
{"op":"mcm","clk":"5306553892","pt":1646100789987,"mc":[{"id":"1.195395424","rc":[{"atb":[[1.69,12.09]],"id":40576811}],"con":true,"img":false}]}
{"op":"mcm","clk":"5306553933","pt":1646100790764,"mc":[{"id":"1.195395424","rc":[{"atb":[[1.64,0]],"id":40576811}],"con":true,"img":false}]}
{"op":"mcm","clk":"5306553938","pt":1646100790862,"mc":[{"id":"1.195395424","rc":[{"atb":[[1.66,65.58]],"id":40576811}],"con":true,"img":false}]}
{"op":"mcm","clk":"5306554197","pt":1646100796193,"mc":[{"id":"1.195395424","rc":[{"atb":[[1.74,10.06]],"id":40576811}],"con":true,"img":false}]}
{"op":"mcm","clk":"5306554209","pt":1646100796396,"mc":[{"id":"1.195395424","rc":[{"atb":[[1.7,0],[1.75,12.1]],"id":40576811}],"con":true,"img":false}]}
{"op":"mcm","clk":"5306554242","pt":1646100796812,"mc":[{"id":"1.195395424","rc":[{"atb":[[1.66,0]],"id":40576811}],"con":true,"img":false}]}
{"op":"mcm","clk":"5306554248","pt":1646100796861,"mc":[{"id":"1.195395424","rc":[{"atb":[[1.61,65.58]],"id":40576811}],"con":true,"img":false}]}
{"op":"mcm","clk":"5306554348","pt":1646100799062,"mc":[{"id":"1.195395424","rc":[{"atb":[[1.74,0]],"id":40576811}],"con":true,"img":false}]}
{"op":"mcm","clk":"5306554427","pt":1646100800802,"mc":[{"id":"1.195395424","rc":[{"atl":[[11,0]],"id":40022793}],"con":true,"img":false}]}
{"op":"mcm","clk":"5306554431","pt":1646100800906,"mc":[{"id":"1.195395424","rc":[{"atl":[[10.5,4.12]],"id":40022793}],"con":true,"img":false}]}
{"op":"mcm","clk":"5306554449","pt":1646100801469,"mc":[{"id":"1.195395424","rc":[{"atb":[[1.7,35.71],[1.75,0]],"id":40576811}],"con":true,"img":false}]}
{"op":"mcm","clk":"5306554660","pt":1646100805010,"mc":[{"id":"1.195395424","rc":[{"atb":[[1.65,11.46]],"id":40576811}],"con":true,"img":false}]}
{"op":"mcm","clk":"5306554697","pt":1646100805569,"mc":[{"id":"1.195395424","rc":[{"atb":[[1.69,0]],"id":40576811}],"con":true,"img":false}]}
{"op":"mcm","clk":"5306554759","pt":1646100806611,"mc":[{"id":"1.195395424","rc":[{"atb":[[1.7,0],[1.66,71.42]],"id":40576811}],"con":true,"img":false}]}
{"op":"mcm","clk":"5306554824","pt":1646100808087,"mc":[{"id":"1.195395424","rc":[{"atb":[[1.65,0]],"id":40576811}],"con":true,"img":false}]}
{"op":"mcm","clk":"5306554862","pt":1646100808808,"mc":[{"id":"1.195395424","rc":[{"atl":[[10.5,0]],"id":40022793}],"con":true,"img":false}]}
{"op":"mcm","clk":"5306554866","pt":1646100808910,"mc":[{"id":"1.195395424","rc":[{"atl":[[11.5,4.12]],"id":40022793}],"con":true,"img":false}]}
{"op":"mcm","clk":"5306555020","pt":1646100811784,"mc":[{"id":"1.195395424","rc":[{"atb":[[1.62,142.84],[1.66,0]],"id":40576811}],"con":true,"img":false}]}
{"op":"mcm","clk":"5306555439","pt":1646100820293,"mc":[{"id":"1.195395424","rc":[{"atb":[[1.66,11.29]],"id":40576811}],"con":true,"img":false}]}
{"op":"mcm","clk":"5306555818","pt":1646100828240,"mc":[{"id":"1.195395424","rc":[{"atb":[[1.67,65.59],[1.62,0]],"id":40576811}],"con":true,"img":false}]}
{"op":"mcm","clk":"5306555852","pt":1646100829014,"mc":[{"id":"1.195395424","rc":[{"atb":[[1.66,0]],"id":40576811}],"con":true,"img":false}]}
{"op":"mcm","clk":"5306555858","pt":1646100829117,"mc":[{"id":"1.195395424","rc":[{"atb":[[1.67,0],[1.62,131.18]],"id":40576811}],"con":true,"img":false}]}
{"op":"mcm","clk":"5306555898","pt":1646100829934,"mc":[{"id":"1.195395424","rc":[{"atb":[[1.66,12.64]],"id":40576811}],"con":true,"img":false}]}
{"op":"mcm","clk":"5306555903","pt":1646100830037,"mc":[{"id":"1.195395424","rc":[{"atb":[[1.67,65.59]],"id":40576811}],"con":true,"img":false}]}
{"op":"mcm","clk":"5306555908","pt":1646100830141,"mc":[{"id":"1.195395424","rc":[{"atb":[[1.62,0]],"id":40576811}],"con":true,"img":false}]}
{"op":"mcm","clk":"5306555935","pt":1646100830705,"mc":[{"id":"1.195395424","rc":[{"atl":[[11.5,0]],"id":40022793},{"atb":[[1.61,0]],"id":40576811}],"con":true,"img":false}]}
{"op":"mcm","clk":"5306555940","pt":1646100830808,"mc":[{"id":"1.195395424","rc":[{"atl":[[11,4.12]],"id":40022793},{"atb":[[1.63,65.58]],"id":40576811}],"con":true,"img":false}]}
{"op":"mcm","clk":"5306556161","pt":1646100835223,"mc":[{"id":"1.195395424","rc":[{"atb":[[1.71,10.49]],"id":40576811}],"con":true,"img":false}]}
{"op":"mcm","clk":"5306556167","pt":1646100835337,"mc":[{"id":"1.195395424","rc":[{"atb":[[1.72,12.65],[1.67,0]],"id":40576811}],"con":true,"img":false}]}
{"op":"mcm","clk":"5306556297","pt":1646100838249,"mc":[{"id":"1.195395424","rc":[{"atb":[[1.71,0]],"id":40576811}],"con":true,"img":false}]}
{"op":"mcm","clk":"5306556404","pt":1646100840510,"mc":[{"id":"1.195395424","rc":[{"atb":[[1.72,0],[1.67,35.71]],"id":40576811}],"con":true,"img":false}]}
{"op":"mcm","clk":"5306556574","pt":1646100844057,"mc":[{"id":"1.195395424","rc":[{"atb":[[1.67,46.83]],"id":40576811},{"spn":2.18,"spf":"NaN","id":40576811}],"con":true,"img":false}]}
{"op":"mcm","clk":"5306556729","pt":1646100847546,"mc":[{"id":"1.195395424","rc":[{"atb":[[1.66,0]],"id":40576811}],"con":true,"img":false}]}
{"op":"mcm","clk":"5306556903","pt":1646100851240,"mc":[{"id":"1.195395424","rc":[{"atl":[[1.99,0],[2.02,19.61]],"id":39133526},{"atb":[[1.37,0],[1.35,228.06]],"id":42248822}],"con":true,"img":false}]}
{"op":"mcm","clk":"5306556988","pt":1646100852836,"mc":[{"id":"1.195395424","rc":[{"atl":[[5.2,0]],"id":40324448},{"atl":[[11,0]],"id":40022793},{"atb":[[1.34,0]],"id":42248822}],"con":true,"img":false}]}
{"op":"mcm","clk":"5306556992","pt":1646100852937,"mc":[{"id":"1.195395424","rc":[{"atl":[[5.4,9.73]],"id":40324448},{"atl":[[10.5,4.12]],"id":40022793},{"atb":[[1.32,137.43]],"id":42248822}],"con":true,"img":false}]}
{"op":"mcm","clk":"5306557038","pt":1646100854068,"mc":[{"id":"1.195395424","rc":[{"atb":[[1.67,59.3]],"id":40576811}],"con":true,"img":false}]}
{"op":"mcm","clk":"5306557099","pt":1646100855252,"mc":[{"id":"1.195395424","rc":[{"atl":[[5.3,52.33],[5.5,0]],"id":40324448},{"atl":[[1.98,20.41]],"id":39133526},{"atb":[[2.52,82.24],[2.68,12.2]],"id":38185321},{"atl":[[5.8,11.9],[6,12.4]],"id":38185321}],"con":true,"img":false}]}
{"op":"mcm","clk":"5306557121","pt":1646100855765,"mc":[{"id":"1.195395424","rc":[{"atb":[[2.66,9.51]],"id":38185321}],"con":true,"img":false}]}
{"op":"mcm","clk":"5306557132","pt":1646100855870,"mc":[{"id":"1.195395424","rc":[{"atb":[[2.7,1.66]],"id":38185321}],"con":true,"img":false}]}
{"op":"mcm","clk":"5306557154","pt":1646100856237,"mc":[{"id":"1.195395424","rc":[{"atb":[[1.67,48.17]],"id":40576811}],"con":true,"img":false}]}
{"op":"mcm","clk":"5306557177","pt":1646100856747,"mc":[{"id":"1.195395424","rc":[{"atl":[[5.4,0]],"id":40324448}],"con":true,"img":false}]}
{"op":"mcm","clk":"5306557182","pt":1646100856850,"mc":[{"id":"1.195395424","rc":[{"atl":[[6,9.73]],"id":40324448}],"con":true,"img":false}]}
{"op":"mcm","clk":"5306557261","pt":1646100858781,"mc":[{"id":"1.195395424","rc":[{"atl":[[2,0]],"id":39133526},{"atb":[[1.38,0]],"id":42248822}],"con":true,"img":false}]}
{"op":"mcm","clk":"5306557267","pt":1646100858833,"mc":[{"id":"1.195395424","rc":[{"atl":[[2.04,32.79]],"id":39133526},{"atb":[[1.36,85.46]],"id":42248822}],"con":true,"img":false}]}
{"op":"mcm","clk":"5306557291","pt":1646100859242,"mc":[{"id":"1.195395424","rc":[{"atb":[[1.41,20.36]],"id":42248822}],"con":true,"img":false}]}
{"op":"mcm","clk":"5306557354","pt":1646100860377,"mc":[{"id":"1.195395424","rc":[{"atl":[[5.8,4.17],[6,32.03]],"id":38185321}],"con":true,"img":false}]}
{"op":"mcm","clk":"5306557369","pt":1646100860738,"mc":[{"id":"1.195395424","rc":[{"atl":[[10.5,0]],"id":40022793}],"con":true,"img":false}]}
{"op":"mcm","clk":"5306557374","pt":1646100860842,"mc":[{"id":"1.195395424","rc":[{"atl":[[11.5,4.12]],"id":40022793}],"con":true,"img":false}]}
{"op":"mcm","clk":"5306557434","pt":1646100862179,"mc":[{"id":"1.195395424","rc":[{"atb":[[1.71,10.49]],"id":40576811}],"con":true,"img":false}]}
{"op":"mcm","clk":"5306557443","pt":1646100862336,"mc":[{"id":"1.195395424","rc":[{"atb":[[1.72,48.18],[1.67,12.46]],"id":40576811}],"con":true,"img":false}]}
{"op":"mcm","clk":"5306557582","pt":1646100865166,"mc":[{"id":"1.195395424","rc":[{"atb":[[1.39,19.11]],"id":42248822},{"atb":[[1.71,0]],"id":40576811}],"con":true,"img":false}]}
{"op":"mcm","clk":"5306557698","pt":1646100867483,"mc":[{"id":"1.195395424","rc":[{"atb":[[1.72,0],[1.68,96.36]],"id":40576811}],"con":true,"img":false}]}
{"op":"mcm","clk":"5306557929","pt":1646100872059,"mc":[{"id":"1.195395424","rc":[{"atb":[[1.41,0]],"id":42248822}],"con":true,"img":false}]}
{"op":"mcm","clk":"5306557991","pt":1646100873289,"mc":[{"id":"1.195395424","rc":[{"atl":[[5.6,21.74],[5.3,29.07]],"id":40324448},{"atl":[[2,20],[1.98,0]],"id":39133526},{"atb":[[2.52,148.03],[2.68,0]],"id":38185321},{"atl":[[6.2,15.46],[6,12.4]],"id":38185321}],"con":true,"img":false}]}
{"op":"mcm","clk":"5306558032","pt":1646100874113,"mc":[{"id":"1.195395424","rc":[{"atb":[[1.72,10.35]],"id":40576811}],"con":true,"img":false}]}
{"op":"mcm","clk":"5306558181","pt":1646100876684,"mc":[{"id":"1.195395424","rc":[{"atb":[[2.7,0]],"id":38185321}],"con":true,"img":false}]}
{"op":"mcm","clk":"5306558188","pt":1646100876887,"mc":[{"id":"1.195395424","rc":[{"atb":[[2.68,1.66]],"id":38185321}],"con":true,"img":false}]}
{"op":"mcm","clk":"5306558219","pt":1646100877457,"mc":[{"id":"1.195395424","rc":[{"atb":[[1.39,40.51]],"id":42248822}],"con":true,"img":false}]}
{"op":"mcm","clk":"5306558239","pt":1646100877865,"mc":[{"id":"1.195395424","rc":[{"atb":[[1.67,0]],"id":40576811}],"con":true,"img":false}]}
{"op":"mcm","clk":"5306558368","pt":1646100880788,"mc":[{"id":"1.195395424","rc":[{"atl":[[5.9,0]],"id":38185321}],"con":true,"img":false}]}
{"op":"mcm","clk":"5306558373","pt":1646100880891,"mc":[{"id":"1.195395424","rc":[{"atl":[[6,20.13]],"id":38185321}],"con":true,"img":false}]}
{"op":"mcm","clk":"5306558484","pt":1646100882905,"mc":[{"id":"1.195395424","rc":[{"atl":[[11.5,0]],"id":40022793}],"con":true,"img":false}]}
{"op":"mcm","clk":"5306558488","pt":1646100882956,"mc":[{"id":"1.195395424","rc":[{"atl":[[11,4.12]],"id":40022793}],"con":true,"img":false}]}
{"op":"mcm","clk":"5306558503","pt":1646100883263,"mc":[{"id":"1.195395424","rc":[{"atl":[[2.04,80.87]],"id":39133526},{"atb":[[1.73,65.59]],"id":40576811}],"con":true,"img":false}]}
{"op":"mcm","clk":"5306558511","pt":1646100883367,"mc":[{"id":"1.195395424","rc":[{"atb":[[1.72,21.94],[1.68,0]],"id":40576811}],"con":true,"img":false}]}
{"op":"mcm","clk":"5306558657","pt":1646100886297,"mc":[{"id":"1.195395424","rc":[{"atb":[[1.72,11.59]],"id":40576811}],"con":true,"img":false}]}
{"op":"mcm","clk":"5306558810","pt":1646100888914,"mc":[{"id":"1.195395424","rc":[{"atl":[[2.02,0],[2.06,0],[2.1,0]],"id":39133526}],"con":true,"img":false}]}
{"op":"mcm","clk":"5306558822","pt":1646100889071,"mc":[{"id":"1.195395424","rc":[{"atl":[[6.2,0],[6,35.59]],"id":38185321}],"con":true,"img":false}]}
{"op":"mcm","clk":"5306558975","pt":1646100892100,"mc":[{"id":"1.195395424","rc":[{"atb":[[1.77,9.68]],"id":40576811}],"con":true,"img":false}]}
{"op":"mcm","clk":"5306559038","pt":1646100893284,"mc":[{"id":"1.195395424","rc":[{"atl":[[2.08,69.44]],"id":39133526}],"con":true,"img":false}]}
{"op":"mcm","clk":"5306559356","pt":1646100898992,"mc":[{"id":"1.195395424","rc":[{"atb":[[1.73,0],[1.78,11.6]],"id":40576811}],"con":true,"img":false}]}
{"op":"mcm","clk":"5306559460","pt":1646100901102,"mc":[{"id":"1.195395424","rc":[{"atb":[[1.19,317.82]],"id":39133526}],"con":true,"img":false}]}
{"op":"mcm","clk":"5306559465","pt":1646100901204,"mc":[{"id":"1.195395424","rc":[{"atb":[[1.17,229.96]],"id":39133526}],"con":true,"img":false}]}
{"op":"mcm","clk":"5306559471","pt":1646100901308,"mc":[{"id":"1.195395424","rc":[{"atb":[[1.77,0]],"id":40576811}],"con":true,"img":false}]}
{"op":"mcm","clk":"5306559482","pt":1646100901512,"mc":[{"id":"1.195395424","rc":[{"atb":[[1.73,35.71],[1.78,0]],"id":40576811}],"con":true,"img":false}]}
{"op":"mcm","clk":"5306559487","pt":1646100901616,"mc":[{"id":"1.195395424","rc":[{"atb":[[1.72,0]],"id":40576811}],"con":true,"img":false}]}
{"op":"mcm","clk":"5306559545","pt":1646100902797,"mc":[{"id":"1.195395424","rc":[{"atl":[[6,0]],"id":40324448}],"con":true,"img":false}]}
{"op":"mcm","clk":"5306559552","pt":1646100902901,"mc":[{"id":"1.195395424","rc":[{"atl":[[5.5,9.73]],"id":40324448}],"con":true,"img":false}]}
{"op":"mcm","clk":"5306559571","pt":1646100903312,"mc":[{"id":"1.195395424","rc":[{"atl":[[2.12,111.61]],"id":39133526}],"con":true,"img":false}]}
{"op":"mcm","clk":"5306559741","pt":1646100906607,"mc":[{"id":"1.195395424","rc":[{"spn":1.61,"spf":"NaN","id":39133526},{"spn":4.24,"spf":"NaN","id":38185321},{"spn":1.84,"spf":"NaN","id":42248822},{"atb":[[1.73,0],[1.64,71.42]],"id":40576811},{"spn":2.17,"spf":"NaN","id":40576811}],"con":true,"img":false}]}
{"op":"mcm","clk":"5306559746","pt":1646100906708,"mc":[{"id":"1.195395424","rc":[{"atl":[[11,0]],"id":40022793}],"con":true,"img":false}]}
{"op":"mcm","clk":"5306559752","pt":1646100906812,"mc":[{"id":"1.195395424","rc":[{"atl":[[12.5,4.12]],"id":40022793}],"con":true,"img":false}]}
{"op":"mcm","clk":"5306559844","pt":1646100908710,"mc":[{"id":"1.195395424","rc":[{"atb":[[1.2,250]],"id":39133526}],"con":true,"img":false}]}
{"op":"mcm","clk":"5306559851","pt":1646100908812,"mc":[{"id":"1.195395424","rc":[{"atb":[[1.19,409.58]],"id":39133526}],"con":true,"img":false}]}
{"op":"mcm","clk":"5306560066","pt":1646100913328,"mc":[{"id":"1.195395424","rc":[{"atb":[[1.68,10.96]],"id":40576811}],"con":true,"img":false}]}
{"op":"mcm","clk":"5306560356","pt":1646100919603,"mc":[{"id":"1.195395424","rc":[{"atb":[[1.68,23.24]],"id":40576811}],"con":true,"img":false}]}
{"op":"mcm","clk":"5306560474","pt":1646100922127,"mc":[{"id":"1.195395424","rc":[{"atb":[[1.64,0],[1.69,65.59]],"id":40576811}],"con":true,"img":false}]}
{"op":"mcm","clk":"5306560586","pt":1646100924698,"mc":[{"id":"1.195395424","rc":[{"atb":[[1.68,12.28]],"id":40576811}],"con":true,"img":false}]}
{"op":"mcm","clk":"5306560857","pt":1646100930619,"mc":[{"id":"1.195395424","rc":[{"atb":[[1.73,10.21]],"id":40576811}],"con":true,"img":false}]}
{"op":"mcm","clk":"5306560961","pt":1646100932725,"mc":[{"id":"1.195395424","rc":[{"atb":[[1.63,0]],"id":40576811}],"con":true,"img":false}]}
{"op":"mcm","clk":"5306560965","pt":1646100932828,"mc":[{"id":"1.195395424","rc":[{"atb":[[1.7,65.58]],"id":40576811}],"con":true,"img":false}]}
{"op":"mcm","clk":"5306561052","pt":1646100934520,"mc":[{"id":"1.195395424","rc":[{"atb":[[1.73,0]],"id":40576811}],"con":true,"img":false}]}
{"op":"mcm","clk":"5306561176","pt":1646100937442,"mc":[{"id":"1.195395424","rc":[{"atb":[[1.71,65.59],[1.69,0]],"id":40576811}],"con":true,"img":false}]}
{"op":"mcm","clk":"5306561184","pt":1646100937647,"mc":[{"id":"1.195395424","rc":[{"atb":[[1.68,0]],"id":40576811}],"con":true,"img":false}]}
{"op":"mcm","clk":"5306561618","pt":1646100946681,"mc":[{"id":"1.195395424","rc":[{"atb":[[1.75,9.93]],"id":40576811}],"con":true,"img":false}]}
{"op":"mcm","clk":"5306561621","pt":1646100946784,"mc":[{"id":"1.195395424","rc":[{"atb":[[1.7,0]],"id":40576811}],"con":true,"img":false}]}
{"op":"mcm","clk":"5306561624","pt":1646100946887,"mc":[{"id":"1.195395424","rc":[{"atb":[[1.64,65.58]],"id":40576811}],"con":true,"img":false}]}
{"op":"mcm","clk":"5306561891","pt":1646100952580,"mc":[{"id":"1.195395424","rc":[{"atb":[[1.71,0],[1.76,65.59]],"id":40576811}],"con":true,"img":false}]}
{"op":"mcm","clk":"5306561980","pt":1646100954787,"mc":[{"id":"1.195395424","rc":[{"atl":[[4.7,0]],"id":40576811}],"con":true,"img":false}]}
{"op":"mcm","clk":"5306561984","pt":1646100954887,"mc":[{"id":"1.195395424","rc":[{"atl":[[5,12.98]],"id":40576811}],"con":true,"img":false}]}
{"op":"mcm","clk":"5306562016","pt":1646100955556,"mc":[{"id":"1.195395424","rc":[{"atb":[[1.75,0]],"id":40576811}],"con":true,"img":false}]}
{"op":"mcm","clk":"5306562128","pt":1646100957665,"mc":[{"id":"1.195395424","rc":[{"atb":[[1.65,131.18],[1.76,0]],"id":40576811}],"con":true,"img":false}]}
{"op":"mcm","clk":"5306562477","pt":1646100964794,"mc":[{"id":"1.195395424","rc":[{"atb":[[1.69,10.79]],"id":40576811}],"con":true,"img":false}]}
{"op":"mcm","clk":"5306562626","pt":1646100967616,"mc":[{"id":"1.195395424","rc":[{"atb":[[1.7,65.59],[1.65,0]],"id":40576811},{"spn":2.2,"spf":"NaN","id":40576811}],"con":true,"img":false}]}
{"op":"mcm","clk":"5306562782","pt":1646100970582,"mc":[{"id":"1.195395424","rc":[{"atb":[[1.69,0]],"id":40576811}],"con":true,"img":false}]}
{"op":"mcm","clk":"5306562882","pt":1646100972683,"mc":[{"id":"1.195395424","rc":[{"atb":[[1.65,131.18]],"id":40576811}],"con":true,"img":false}]}
{"op":"mcm","clk":"5306562887","pt":1646100972786,"mc":[{"id":"1.195395424","rc":[{"atb":[[1.7,0]],"id":40576811}],"con":true,"img":false}]}
{"op":"mcm","clk":"5306562933","pt":1646100973912,"mc":[{"id":"1.195395424","rc":[{"atb":[[1.69,12.09]],"id":40576811}],"con":true,"img":false}]}
{"op":"mcm","clk":"5306563185","pt":1646100979500,"mc":[{"id":"1.195395424","rc":[{"atb":[[1.69,22.89]],"id":40576811}],"con":true,"img":false}]}
{"op":"mcm","clk":"5306563585","pt":1646100987504,"mc":[{"id":"1.195395424","rc":[{"atb":[[1.7,65.59],[1.65,0]],"id":40576811}],"con":true,"img":false}]}
{"op":"mcm","clk":"5306563664","pt":1646100988647,"mc":[{"id":"1.195395424","rc":[{"atb":[[1.69,12.09]],"id":40576811}],"con":true,"img":false}]}
{"op":"mcm","clk":"5306563974","pt":1646100994613,"mc":[{"id":"1.195395424","rc":[{"atb":[[1.74,10.06]],"id":40576811}],"con":true,"img":false}]}
{"op":"mcm","clk":"5306563978","pt":1646100994715,"mc":[{"id":"1.195395424","rc":[{"atb":[[1.7,0],[1.75,12.1]],"id":40576811}],"con":true,"img":false}]}
{"op":"mcm","clk":"5306564064","pt":1646100996763,"mc":[{"id":"1.195395424","rc":[{"atb":[[1.64,0]],"id":40576811}],"con":true,"img":false}]}
{"op":"mcm","clk":"5306564069","pt":1646100996815,"mc":[{"id":"1.195395424","rc":[{"atb":[[1.61,65.58]],"id":40576811}],"con":true,"img":false}]}
{"op":"mcm","clk":"5306564101","pt":1646100997632,"mc":[{"id":"1.195395424","rc":[{"atb":[[1.74,0]],"id":40576811}],"con":true,"img":false}]}
{"op":"mcm","clk":"5306564205","pt":1646100999848,"mc":[{"id":"1.195395424","rc":[{"atb":[[1.7,35.71],[1.75,0]],"id":40576811}],"con":true,"img":false}]}
{"op":"mcm","clk":"5306564374","pt":1646101003639,"mc":[{"id":"1.195395424","rc":[{"atb":[[1.65,11.46]],"id":40576811}],"con":true,"img":false}]}
{"op":"mcm","clk":"5306564394","pt":1646101004054,"mc":[{"id":"1.195395424","rc":[{"atb":[[1.69,0]],"id":40576811}],"con":true,"img":false}]}
{"op":"mcm","clk":"5306564402","pt":1646101004260,"mc":[{"id":"1.195395424","rc":[{"atb":[[1.7,0],[1.66,71.42]],"id":40576811}],"con":true,"img":false}]}
{"op":"mcm","clk":"5306564478","pt":1646101006055,"mc":[{"id":"1.195395424","rc":[{"atl":[[2,0],[2.02,19.61]],"id":39133526}],"con":true,"img":false}]}
{"op":"mcm","clk":"5306564497","pt":1646101006563,"mc":[{"id":"1.195395424","rc":[{"atb":[[1.65,0]],"id":40576811}],"con":true,"img":false}]}
{"op":"mcm","clk":"5306564612","pt":1646101009334,"mc":[{"id":"1.195395424","rc":[{"atb":[[1.62,142.84]],"id":40576811}],"con":true,"img":false}]}
{"op":"mcm","clk":"5306564614","pt":1646101009437,"mc":[{"id":"1.195395424","rc":[{"atb":[[1.66,0]],"id":40576811}],"con":true,"img":false}]}
{"op":"mcm","clk":"5306564864","pt":1646101015647,"mc":[{"id":"1.195395424","rc":[{"atb":[[1.66,11.29]],"id":40576811}],"con":true,"img":false}]}
{"op":"mcm","clk":"5306564882","pt":1646101016059,"mc":[{"id":"1.195395424","rc":[{"atl":[[2.06,47.17]],"id":39133526}],"con":true,"img":false}]}
{"op":"mcm","clk":"5306564917","pt":1646101016981,"mc":[{"id":"1.195395424","rc":[{"atl":[[2.04,32.79],[2.12,0],[2.08,0]],"id":39133526}],"con":true,"img":false}]}
{"op":"mcm","clk":"5306564990","pt":1646101018777,"mc":[{"id":"1.195395424","rc":[{"atb":[[1.67,65.59],[1.62,0]],"id":40576811}],"con":true,"img":false}]}
{"op":"mcm","clk":"5306565112","pt":1646101021699,"mc":[{"id":"1.195395424","rc":[{"atb":[[1.66,0]],"id":40576811}],"con":true,"img":false}]}
{"op":"mcm","clk":"5306565210","pt":1646101023906,"mc":[{"id":"1.195395424","rc":[{"atb":[[1.67,0],[1.62,131.18]],"id":40576811}],"con":true,"img":false}]}
{"op":"mcm","clk":"5306565300","pt":1646101026062,"mc":[{"id":"1.195395424","rc":[{"atl":[[2.1,68.18]],"id":39133526}],"con":true,"img":false}]}
{"op":"mcm","clk":"5306565329","pt":1646101026777,"mc":[{"id":"1.195395424","rc":[{"atb":[[1.61,0]],"id":40576811}],"con":true,"img":false}]}
{"op":"mcm","clk":"5306565332","pt":1646101026880,"mc":[{"id":"1.195395424","rc":[{"atb":[[1.63,65.58]],"id":40576811}],"con":true,"img":false}]}
{"op":"mcm","clk":"5306565598","pt":1646101033678,"mc":[{"id":"1.195395424","rc":[{"spn":1.62,"spf":"NaN","id":39133526},{"atb":[[1.67,11.12]],"id":40576811},{"spn":2.18,"spf":"NaN","id":40576811}],"con":true,"img":false}]}
{"op":"mcm","clk":"5306565709","pt":1646101036090,"mc":[{"id":"1.195395424","rc":[{"atl":[[2.14,109.65]],"id":39133526}],"con":true,"img":false}]}
{"op":"mcm","clk":"5306565804","pt":1646101038197,"mc":[{"id":"1.195395424","rc":[{"atb":[[1.68,65.59]],"id":40576811}],"con":true,"img":false}]}
{"op":"mcm","clk":"5306565813","pt":1646101038300,"mc":[{"id":"1.195395424","rc":[{"atb":[[1.62,0]],"id":40576811}],"con":true,"img":false}]}
{"op":"mcm","clk":"5306565861","pt":1646101039584,"mc":[{"id":"1.195395424","rc":[{"atb":[[1.67,0]],"id":40576811}],"con":true,"img":false}]}
{"op":"mcm","clk":"5306565913","pt":1646101040813,"mc":[{"id":"1.195395424","rc":[{"atl":[[12.5,0]],"id":40022793}],"con":true,"img":false}]}
{"op":"mcm","clk":"5306565918","pt":1646101040914,"mc":[{"id":"1.195395424","rc":[{"atl":[[11.5,4.12]],"id":40022793}],"con":true,"img":false}]}
{"op":"mcm","clk":"5306566019","pt":1646101043320,"mc":[{"id":"1.195395424","rc":[{"atb":[[1.64,131.18]],"id":40576811}],"con":true,"img":false}]}
{"op":"mcm","clk":"5306566028","pt":1646101043423,"mc":[{"id":"1.195395424","rc":[{"atb":[[1.68,0]],"id":40576811}],"con":true,"img":false}]}
{"op":"mcm","clk":"5306566119","pt":1646101045730,"mc":[{"id":"1.195395424","rc":[{"atb":[[1.56,0],[1.6,0],[1.58,0],[1.54,0]],"id":43154453},{"atl":[[12,9.09],[13,0],[14,0],[15,0]],"id":43154453},{"atb":[[1.89,0],[1.85,0],[1.91,0],[1.87,0]],"id":40324448},{"atl":[[5.1,0],[5.3,0],[4.9,3.07],[4.7,0]],"id":40324448},{"atb":[[1.2,0],[1.18,0],[1.16,0],[1.22,0]],"id":39133526},{"atl":[[2.02,0],[2.06,0],[2.1,0],[2.14,0]],"id":39133526},{"atb":[[3.85,0],[3.95,0],[3.75,35.84],[3.65,0]],"id":39318318},{"atl":[[34,0],[38,0],[28,0],[30,2.7]],"id":39318318},{"atb":[[2.56,0],[2.52,65.79],[2.64,0],[2.6,0]],"id":38185321},{"atl":[[6.4,0],[5.8,0],[6,25.59],[6.8,0]],"id":38185321},{"atb":[[4,0],[3.7,0],[3.8,0],[3.9,41.64]],"id":40022793},{"atl":[[12,0],[13,8.33],[14,0],[15,0]],"id":40022793},{"atb":[[1.33,0],[1.29,0],[1.31,0],[1.35,170.92]],"id":42248822},{"atl":[[2.36,0],[2.4,0],[2.32,62.74],[2.44,0]],"id":42248822},{"atb":[[1.56,0],[1.54,0],[1.5,0],[1.52,0]],"id":40576811},{"atl":[[8.6,0],[9,0],[8.2,0],[7.8,14.71]],"id":40576811}],"con":true,"img":false}]}
{"op":"mcm","clk":"5306566165","pt":1646101046707,"mc":[{"id":"1.195395424","rc":[{"atb":[[1.15,291.65]],"id":39133526}],"con":true,"img":false}]}
{"op":"mcm","clk":"5306566168","pt":1646101046812,"mc":[{"id":"1.195395424","rc":[{"atb":[[1.59,0]],"id":43154453},{"atb":[[1.32,0]],"id":42248822}],"con":true,"img":false}]}
{"op":"mcm","clk":"5306566173","pt":1646101046913,"mc":[{"id":"1.195395424","rc":[{"atb":[[1.56,76.39]],"id":43154453},{"atb":[[1.15,0],[1.17,0]],"id":39133526},{"atb":[[1.31,137.43]],"id":42248822}],"con":true,"img":false}]}
{"op":"mcm","clk":"5306566249","pt":1646101048815,"mc":[{"id":"1.195395424","rc":[{"atb":[[2.66,5.02]],"id":38185321}],"con":true,"img":false}]}
{"op":"mcm","clk":"5306566373","pt":1646101051793,"mc":[{"id":"1.195395424","rc":[{"atb":[[1.68,10.96]],"id":40576811}],"con":true,"img":false}]}
{"op":"mcm","clk":"5306566409","pt":1646101052816,"mc":[{"id":"1.195395424","rc":[{"atb":[[1.19,317.82]],"id":39133526},{"atl":[[2.04,0]],"id":39133526},{"atb":[[2.58,0]],"id":38185321}],"con":true,"img":false}]}
{"op":"mcm","clk":"5306566413","pt":1646101052919,"mc":[{"id":"1.195395424","rc":[{"atb":[[1.17,91.76]],"id":39133526},{"atl":[[2.3,32.79]],"id":39133526},{"atb":[[2.54,29.64]],"id":38185321}],"con":true,"img":false}]}
{"op":"mcm","clk":"5306566606","pt":1646101057433,"mc":[{"id":"1.195395424","rc":[{"atb":[[1.64,0],[1.69,65.59]],"id":40576811}],"con":true,"img":false}]}
{"op":"mcm","clk":"5306566622","pt":1646101057794,"mc":[{"id":"1.195395424","rc":[{"atb":[[1.68,0]],"id":40576811}],"con":true,"img":false}]}
{"op":"mcm","clk":"5306566644","pt":1646101058305,"mc":[{"id":"1.195395424","rc":[{"atb":[[1.68,12.28]],"id":40576811}],"con":true,"img":false}]}
{"op":"mcm","clk":"5306566739","pt":1646101060716,"mc":[{"id":"1.195395424","rc":[{"atb":[[1.63,0]],"id":40576811}],"con":true,"img":false}]}
{"op":"mcm","clk":"5306566744","pt":1646101060819,"mc":[{"id":"1.195395424","rc":[{"atb":[[2.6,4.65]],"id":38185321},{"atb":[[1.65,65.58]],"id":40576811}],"con":true,"img":false}]}
{"op":"mcm","clk":"5306566866","pt":1646101063637,"mc":[{"id":"1.195395424","rc":[{"atb":[[1.73,10.21]],"id":40576811}],"con":true,"img":false}]}
{"op":"mcm","clk":"5306566883","pt":1646101064047,"mc":[{"id":"1.195395424","rc":[{"atb":[[2.66,0]],"id":38185321}],"con":true,"img":false}]}
{"op":"mcm","clk":"5306566910","pt":1646101064713,"mc":[{"id":"1.195395424","rc":[{"atb":[[1.15,291.65]],"id":39133526}],"con":true,"img":false}]}
{"op":"mcm","clk":"5306566955","pt":1646101065841,"mc":[{"id":"1.195395424","rc":[{"atb":[[2.68,0]],"id":38185321}],"con":true,"img":false}]}
{"op":"mcm","clk":"5306566961","pt":1646101065945,"mc":[{"id":"1.195395424","rc":[{"atb":[[2.62,1.66]],"id":38185321}],"con":true,"img":false}]}
{"op":"mcm","clk":"5306567149","pt":1646101069535,"mc":[{"id":"1.195395424","rc":[{"atb":[[2.58,5.28]],"id":38185321}],"con":true,"img":false}]}
{"op":"mcm","clk":"5306567388","pt":1646101074719,"mc":[{"id":"1.195395424","rc":[{"atl":[[36,0]],"id":39318318}],"con":true,"img":false}]}
{"op":"mcm","clk":"5306567394","pt":1646101074825,"mc":[{"id":"1.195395424","rc":[{"atl":[[38,2.7]],"id":39318318}],"con":true,"img":false}]}
{"op":"mcm","clk":"5306567472","pt":1646101076521,"mc":[{"id":"1.195395424","rc":[{"atb":[[1.68,0]],"id":40576811}],"con":true,"img":false}]}
{"op":"mcm","clk":"5306567613","pt":1646101079962,"mc":[{"id":"1.195395424","rc":[{"atb":[[1.73,21.64]],"id":40576811}],"con":true,"img":false}]}
{"op":"mcm","clk":"5306567638","pt":1646101080474,"mc":[{"id":"1.195395424","rc":[{"atb":[[1.74,65.59],[1.69,0]],"id":40576811}],"con":true,"img":false}]}
{"op":"mcm","clk":"5306567653","pt":1646101080733,"mc":[{"id":"1.195395424","rc":[{"atb":[[1.65,0]],"id":40576811}],"con":true,"img":false}]}
{"op":"mcm","clk":"5306567658","pt":1646101080836,"mc":[{"id":"1.195395424","rc":[{"atb":[[1.7,65.58]],"id":40576811}],"con":true,"img":false}]}
{"op":"mcm","clk":"5306567704","pt":1646101081760,"mc":[{"id":"1.195395424","rc":[{"atb":[[1.73,11.43]],"id":40576811}],"con":true,"img":false}]}
{"op":"mcm","clk":"5306567958","pt":1646101086739,"mc":[{"id":"1.195395424","rc":[{"atl":[[2.92,22.18],[3.2,0]],"id":42248822},{"atl":[[5,0]],"id":40576811}],"con":true,"img":false}]}
{"op":"mcm","clk":"5306567965","pt":1646101086842,"mc":[{"id":"1.195395424","rc":[{"atl":[[4.4,28.17]],"id":40576811}],"con":true,"img":false}]}
{"op":"mcm","clk":"5306568009","pt":1646101087766,"mc":[{"id":"1.195395424","rc":[{"atb":[[1.78,9.55]],"id":40576811}],"con":true,"img":false}]}
{"op":"mcm","clk":"5306568015","pt":1646101087870,"mc":[{"id":"1.195395424","rc":[{"atb":[[1.79,11.44],[1.74,0]],"id":40576811}],"con":true,"img":false}]}
{"op":"mcm","clk":"5306568054","pt":1646101088741,"mc":[{"id":"1.195395424","rc":[{"atb":[[1.7,0]],"id":40576811}],"con":true,"img":false}]}
{"op":"mcm","clk":"5306568059","pt":1646101088844,"mc":[{"id":"1.195395424","rc":[{"atb":[[1.6,65.58]],"id":40576811}],"con":true,"img":false}]}
{"op":"mcm","clk":"5306568141","pt":1646101090743,"mc":[{"id":"1.195395424","rc":[{"atb":[[1.78,0]],"id":40576811}],"con":true,"img":false}]}
{"op":"mcm","clk":"5306568256","pt":1646101092958,"mc":[{"id":"1.195395424","rc":[{"atb":[[1.79,0],[1.74,65.59]],"id":40576811}],"con":true,"img":false}]}
{"op":"mcm","clk":"5306568338","pt":1646101094753,"mc":[{"id":"1.195395424","rc":[{"atl":[[5,0]],"id":40324448},{"spn":3.48,"spf":"NaN","id":40324448},{"spn":1.73,"spf":"NaN","id":39133526},{"spn":19.3,"spf":"NaN","id":39318318},{"spn":4.31,"spf":"NaN","id":38185321},{"spn":2.22,"spf":"NaN","id":40576811}],"con":true,"img":false}]}
{"op":"mcm","clk":"5306568343","pt":1646101094854,"mc":[{"id":"1.195395424","rc":[{"atl":[[5.5,18.06]],"id":40324448}],"con":true,"img":false}]}
{"op":"mcm","clk":"5306568572","pt":1646101099784,"mc":[{"id":"1.195395424","rc":[{"atb":[[1.78,9.55]],"id":40576811}],"con":true,"img":false}]}
{"op":"mcm","clk":"5306568582","pt":1646101099991,"mc":[{"id":"1.195395424","rc":[{"atb":[[1.73,0]],"id":40576811}],"con":true,"img":false}]}
{"op":"mcm","clk":"5306568611","pt":1646101100760,"mc":[{"id":"1.195395424","rc":[{"atb":[[1.17,0]],"id":39133526}],"con":true,"img":false}]}
{"op":"mcm","clk":"5306568615","pt":1646101100864,"mc":[{"id":"1.195395424","rc":[{"atb":[[1.21,91.76]],"id":39133526}],"con":true,"img":false}]}
{"op":"mcm","clk":"5306568696","pt":1646101102762,"mc":[{"id":"1.195395424","rc":[{"atl":[[38,0]],"id":39318318}],"con":true,"img":false}]}
{"op":"mcm","clk":"5306568700","pt":1646101102865,"mc":[{"id":"1.195395424","rc":[{"atl":[[40,2.7]],"id":39318318}],"con":true,"img":false}]}
{"op":"mcm","clk":"5306568813","pt":1646101106297,"mc":[{"id":"1.195395424","rc":[{"atb":[[1.78,20.25]],"id":40576811}],"con":true,"img":false}]}
{"op":"mcm","clk":"5306569228","pt":1646101114818,"mc":[{"id":"1.195395424","rc":[{"atb":[[1.6,0]],"id":40576811}],"con":true,"img":false}]}
{"op":"mcm","clk":"5306569234","pt":1646101114918,"mc":[{"id":"1.195395424","rc":[{"atb":[[1.64,65.58]],"id":40576811}],"con":true,"img":false}]}
{"op":"mcm","clk":"5306569265","pt":1646101115586,"mc":[{"id":"1.195395424","rc":[{"atb":[[1.79,65.59],[1.74,0]],"id":40576811}],"con":true,"img":false}]}
{"op":"mcm","clk":"5306569378","pt":1646101117790,"mc":[{"id":"1.195395424","rc":[{"atb":[[1.78,10.7]],"id":40576811}],"con":true,"img":false}]}
{"op":"mcm","clk":"5306569589","pt":1646101122717,"mc":[{"id":"1.195395424","rc":[{"atb":[[1.2,218.6]],"id":39133526}],"con":true,"img":false}]}
{"op":"mcm","clk":"5306569594","pt":1646101122818,"mc":[{"id":"1.195395424","rc":[{"atb":[[1.15,0]],"id":39133526}],"con":true,"img":false}]}
{"op":"mcm","clk":"5306569636","pt":1646101123689,"mc":[{"id":"1.195395424","rc":[{"atb":[[1.83,8.98]],"id":40576811}],"con":true,"img":false}]}
{"op":"mcm","clk":"5306569639","pt":1646101123791,"mc":[{"id":"1.195395424","rc":[{"atb":[[1.79,0],[1.84,10.7]],"id":40576811}],"con":true,"img":false}]}
{"op":"mcm","clk":"5306569683","pt":1646101124713,"mc":[{"id":"1.195395424","rc":[{"atb":[[1.64,0]],"id":40576811}],"con":true,"img":false}]}
{"op":"mcm","clk":"5306569688","pt":1646101124816,"mc":[{"id":"1.195395424","rc":[{"atb":[[1.6,65.58]],"id":40576811}],"con":true,"img":false}]}
{"op":"mcm","clk":"5306569778","pt":1646101126714,"mc":[{"id":"1.195395424","rc":[{"atb":[[1.83,0]],"id":40576811}],"con":true,"img":false}]}
{"op":"mcm","clk":"5306569781","pt":1646101126817,"mc":[{"id":"1.195395424","rc":[{"atb":[[1.79,65.59]],"id":40576811}],"con":true,"img":false}]}
{"op":"mcm","clk":"5306569787","pt":1646101126918,"mc":[{"id":"1.195395424","rc":[{"atb":[[1.84,0]],"id":40576811}],"con":true,"img":false}]}
{"op":"mcm","clk":"5306570148","pt":1646101134107,"mc":[{"id":"1.195395424","rc":[{"atb":[[1.78,0]],"id":40576811}],"con":true,"img":false}]}
{"op":"mcm","clk":"5306570155","pt":1646101134210,"mc":[{"id":"1.195395424","rc":[{"atb":[[1.79,0],[1.61,131.18]],"id":40576811}],"con":true,"img":false}]}
{"op":"mcm","clk":"5306570183","pt":1646101134827,"mc":[{"id":"1.195395424","rc":[{"atl":[[40,0]],"id":39318318}],"con":true,"img":false}]}
{"op":"mcm","clk":"5306570188","pt":1646101134929,"mc":[{"id":"1.195395424","rc":[{"atl":[[44,2.7]],"id":39318318}],"con":true,"img":false}]}
{"op":"mcm","clk":"5306570533","pt":1646101141863,"mc":[{"id":"1.195395424","rc":[{"atb":[[1.65,11.46]],"id":40576811}],"con":true,"img":false}]}
{"op":"mcm","clk":"5306570580","pt":1646101142744,"mc":[{"id":"1.195395424","rc":[{"atb":[[6.8,7.57],[5.4,0]],"id":39318318}],"con":true,"img":false}]}
{"op":"mcm","clk":"5306570852","pt":1646101148744,"mc":[{"id":"1.195395424","rc":[{"atb":[[1.6,0]],"id":40576811}],"con":true,"img":false}]}
{"op":"mcm","clk":"5306570855","pt":1646101148841,"mc":[{"id":"1.195395424","rc":[{"atb":[[1.62,65.58]],"id":40576811}],"con":true,"img":false}]}
{"op":"mcm","clk":"5306570945","pt":1646101150742,"mc":[{"id":"1.195395424","rc":[{"atb":[[1.65,0]],"id":40576811}],"con":true,"img":false}]}
{"op":"mcm","clk":"5306571176","pt":1646101156340,"mc":[{"id":"1.195395424","rc":[{"spn":1.74,"spf":"NaN","id":39133526},{"atb":[[1.63,79.54]],"id":40576811},{"spn":2.16,"spf":"NaN","id":40576811}],"con":true,"img":false}]}
{"op":"mcm","clk":"5306571180","pt":1646101156442,"mc":[{"id":"1.195395424","rc":[{"atb":[[1.61,0]],"id":40576811}],"con":true,"img":false}]}
{"op":"mcm","clk":"5306571370","pt":1646101160752,"mc":[{"id":"1.195395424","rc":[{"atl":[[2.92,0],[3.1,18.39]],"id":42248822}],"con":true,"img":false}]}
{"op":"mcm","clk":"5306571469","pt":1646101162852,"mc":[{"id":"1.195395424","rc":[{"atb":[[1.67,11.12]],"id":40576811}],"con":true,"img":false}]}
{"op":"mcm","clk":"5306571474","pt":1646101162954,"mc":[{"id":"1.195395424","rc":[{"atb":[[1.68,65.59]],"id":40576811}],"con":true,"img":false}]}
{"op":"mcm","clk":"5306571479","pt":1646101163058,"mc":[{"id":"1.195395424","rc":[{"atb":[[1.63,0]],"id":40576811}],"con":true,"img":false}]}
{"op":"mcm","clk":"5306571600","pt":1646101165980,"mc":[{"id":"1.195395424","rc":[{"atb":[[1.67,0]],"id":40576811}],"con":true,"img":false}]}
{"op":"mcm","clk":"5306571640","pt":1646101166955,"mc":[{"id":"1.195395424","rc":[{"atb":[[1.36,222.9],[1.35,0]],"id":42248822}],"con":true,"img":false}]}
{"op":"mcm","clk":"5306571677","pt":1646101168081,"mc":[{"id":"1.195395424","rc":[{"atb":[[1.63,131.18],[1.68,0]],"id":40576811}],"con":true,"img":false}]}
{"op":"mcm","clk":"5306571923","pt":1646101174841,"mc":[{"id":"1.195395424","rc":[{"atb":[[1.55,0],[1.67,11.12]],"id":40576811}],"con":true,"img":false}]}
{"op":"mcm","clk":"5306571927","pt":1646101174942,"mc":[{"id":"1.195395424","rc":[{"atb":[[1.49,79.54]],"id":40576811}],"con":true,"img":false}]}
{"op":"mcm","clk":"5306572008","pt":1646101176839,"mc":[{"id":"1.195395424","rc":[{"atb":[[1.62,0]],"id":40576811}],"con":true,"img":false}]}
{"op":"mcm","clk":"5306572013","pt":1646101176941,"mc":[{"id":"1.195395424","rc":[{"atb":[[1.64,65.58]],"id":40576811}],"con":true,"img":false}]}
{"op":"mcm","clk":"5306572063","pt":1646101177866,"mc":[{"id":"1.195395424","rc":[{"atb":[[1.67,0]],"id":40576811}],"con":true,"img":false}]}
{"op":"mcm","clk":"5306572285","pt":1646101182890,"mc":[{"id":"1.195395424","rc":[{"atl":[[44,0]],"id":39318318}],"con":true,"img":false}]}
{"op":"mcm","clk":"5306572290","pt":1646101182993,"mc":[{"id":"1.195395424","rc":[{"atl":[[48,2.7]],"id":39318318}],"con":true,"img":false}]}
{"op":"mcm","clk":"5306572319","pt":1646101183866,"mc":[{"id":"1.195395424","rc":[{"atb":[[1.68,10.96]],"id":40576811}],"con":true,"img":false}]}
{"op":"mcm","clk":"5306572569","pt":1646101189864,"mc":[{"id":"1.195395424","rc":[{"atb":[[1.69,65.59]],"id":40576811}],"con":true,"img":false}]}
{"op":"mcm","clk":"5306572573","pt":1646101189966,"mc":[{"id":"1.195395424","rc":[{"atb":[[1.63,0]],"id":40576811}],"con":true,"img":false}]}
{"op":"mcm","clk":"5306572758","pt":1646101193096,"mc":[{"id":"1.195395424","rc":[{"atb":[[1.68,0]],"id":40576811}],"con":true,"img":false}]}
{"op":"mcm","clk":"5306572872","pt":1646101194992,"mc":[{"id":"1.195395424","rc":[{"atb":[[1.65,131.18],[1.69,0]],"id":40576811}],"con":true,"img":false}]}
{"op":"mcm","clk":"5306573200","pt":1646101202123,"mc":[{"id":"1.195395424","rc":[{"atb":[[1.69,10.79]],"id":40576811}],"con":true,"img":false}]}
{"op":"mcm","clk":"5306573312","pt":1646101204453,"mc":[{"id":"1.195395424","marketDefinition":{"bspMarket":true,"turnInPlayEnabled":false,"persistenceEnabled":false,"marketBaseRate":7.0,"eventId":"31270458","eventTypeId":"4339","numberOfWinners":3,"bettingType":"ODDS","marketType":"PLACE","marketTime":"2022-03-01T02:54:00.000Z","suspendTime":"2022-03-01T02:54:00.000Z","bspReconciled":false,"complete":true,"inPlay":false,"crossMatching":true,"runnersVoidable":false,"numberOfActiveRunners":8,"betDelay":0,"status":"OPEN","runners":[{"status":"ACTIVE","sortPriority":1,"id":40324448,"name":"1. Winklee Frankie"},{"status":"ACTIVE","sortPriority":2,"id":43154453,"name":"2. Epic Speed"},{"status":"ACTIVE","sortPriority":3,"id":39318318,"name":"3. Kindred"},{"status":"ACTIVE","sortPriority":4,"id":42248822,"name":"4. Blackbrush Scott"},{"status":"ACTIVE","sortPriority":5,"id":38185321,"name":"5. Hiccup Finley"},{"status":"ACTIVE","sortPriority":6,"id":40022793,"name":"6. Motton Miss"},{"status":"ACTIVE","sortPriority":7,"id":39133526,"name":"7. Tsar Bell"},{"status":"ACTIVE","sortPriority":8,"id":40576811,"name":"8. Tah Meg"}],"regulators":["MR_INT"],"venue":"Devonport","countryCode":"AU","discountAllowed":true,"timezone":"Australia/Sydney","openDate":"2022-03-01T02:00:00.000Z","version":4381059055,"name":"To Be Placed","eventName":"Devonport (AUS) 1st Mar"},"rc":[],"con":true,"img":false}]}
{"op":"mcm","clk":"5306573679","pt":1646101211518,"mc":[{"id":"1.195395424","rc":[{"atb":[[1.7,65.59]],"id":40576811}],"con":true,"img":false}]}
{"op":"mcm","clk":"5306573682","pt":1646101211620,"mc":[{"id":"1.195395424","rc":[{"atb":[[1.65,0]],"id":40576811}],"con":true,"img":false}]}
{"op":"mcm","clk":"5306573748","pt":1646101212826,"mc":[{"id":"1.195395424","rc":[{"atb":[[1.64,0]],"id":40576811}],"con":true,"img":false}]}
{"op":"mcm","clk":"5306573757","pt":1646101212933,"mc":[{"id":"1.195395424","rc":[{"atb":[[1.66,65.58]],"id":40576811}],"con":true,"img":false}]}
{"op":"mcm","clk":"5306573823","pt":1646101214016,"mc":[{"id":"1.195395424","rc":[{"atb":[[1.69,0]],"id":40576811}],"con":true,"img":false}]}
{"op":"mcm","clk":"5306573825","pt":1646101214118,"mc":[{"id":"1.195395424","rc":[{"atb":[[1.67,131.18],[1.7,0]],"id":40576811}],"con":true,"img":false}]}
{"op":"mcm","clk":"5306573897","pt":1646101215505,"mc":[{"id":"1.195395424","rc":[{"atb":[[1.2,0],[1.16,291.65]],"id":39133526}],"con":true,"img":false}]}
{"op":"mcm","clk":"5306574243","pt":1646101222835,"mc":[{"id":"1.195395424","rc":[{"atb":[[1.21,0]],"id":39133526},{"spn":1.73,"spf":"NaN","id":39133526},{"spn":2.18,"spf":"NaN","id":40576811}],"con":true,"img":false}]}
{"op":"mcm","clk":"5306574250","pt":1646101222935,"mc":[{"id":"1.195395424","rc":[{"atb":[[1.2,91.76]],"id":39133526}],"con":true,"img":false}]}
{"op":"mcm","clk":"5306574255","pt":1646101223040,"mc":[{"id":"1.195395424","rc":[{"atb":[[1.71,10.49]],"id":40576811}],"con":true,"img":false}]}
{"op":"mcm","clk":"5306574257","pt":1646101223142,"mc":[{"id":"1.195395424","rc":[{"atb":[[1.67,0]],"id":40576811}],"con":true,"img":false}]}
{"op":"mcm","clk":"5306574261","pt":1646101223194,"mc":[{"id":"1.195395424","rc":[{"atb":[[1.72,65.59]],"id":40576811}],"con":true,"img":false}]}
{"op":"mcm","clk":"5306574478","pt":1646101227045,"mc":[{"id":"1.195395424","rc":[{"atb":[[1.71,0]],"id":40576811}],"con":true,"img":false}]}
{"op":"mcm","clk":"5306574484","pt":1646101227150,"mc":[{"id":"1.195395424","rc":[{"atb":[[1.67,131.18]],"id":40576811}],"con":true,"img":false}]}
{"op":"mcm","clk":"5306574486","pt":1646101227199,"mc":[{"id":"1.195395424","rc":[{"atb":[[1.72,0]],"id":40576811}],"con":true,"img":false}]}
{"op":"mcm","clk":"5306574562","pt":1646101228741,"mc":[{"id":"1.195395424","rc":[{"atb":[[6.8,0]],"id":39318318}],"con":true,"img":false}]}
{"op":"mcm","clk":"5306574565","pt":1646101228841,"mc":[{"id":"1.195395424","rc":[{"atb":[[7.8,12.98]],"id":39318318}],"con":true,"img":false}]}
{"op":"mcm","clk":"5306574767","pt":1646101232850,"mc":[{"id":"1.195395424","rc":[{"atb":[[1.66,0]],"id":40576811}],"con":true,"img":false}]}
{"op":"mcm","clk":"5306574773","pt":1646101232902,"mc":[{"id":"1.195395424","rc":[{"atb":[[1.68,65.58],[1.5,200]],"id":40576811}],"con":true,"img":false}]}
{"op":"mcm","clk":"5306574778","pt":1646101233006,"mc":[{"id":"1.195395424","rc":[{"atb":[[1.67,0]],"id":40576811}],"con":true,"img":false}]}
{"op":"mcm","clk":"5306574863","pt":1646101234849,"mc":[{"id":"1.195395424","rc":[{"atb":[[1.68,0]],"id":40576811}],"con":true,"img":false}]}
{"op":"mcm","clk":"5306574866","pt":1646101234953,"mc":[{"id":"1.195395424","rc":[{"atb":[[1.59,65.58]],"id":40576811}],"con":true,"img":false}]}
{"op":"mcm","clk":"5306575034","pt":1646101238744,"mc":[{"id":"1.195395424","rc":[{"atb":[[7.8,7.57]],"id":39318318}],"con":true,"img":false}]}
{"op":"mcm","clk":"5306575042","pt":1646101238846,"mc":[{"id":"1.195395424","rc":[{"atb":[[8.4,5.41]],"id":39318318}],"con":true,"img":false}]}
{"op":"mcm","clk":"5306575300","pt":1646101244235,"mc":[{"id":"1.195395424","rc":[{"atb":[[1.63,11.82]],"id":40576811}],"con":true,"img":false}]}
{"op":"mcm","clk":"5306575322","pt":1646101244849,"mc":[{"id":"1.195395424","rc":[{"atl":[[48,0]],"id":39318318}],"con":true,"img":false}]}
{"op":"mcm","clk":"5306575328","pt":1646101244953,"mc":[{"id":"1.195395424","rc":[{"atl":[[50,2.7]],"id":39318318}],"con":true,"img":false}]}
{"op":"mcm","clk":"5306575611","pt":1646101250849,"mc":[{"id":"1.195395424","rc":[{"atb":[[1.63,25.07]],"id":40576811}],"con":true,"img":false}]}
{"op":"mcm","clk":"5306575773","pt":1646101254138,"mc":[{"id":"1.195395424","rc":[{"atb":[[1.64,65.59]],"id":40576811}],"con":true,"img":false}]}
{"op":"mcm","clk":"5306575776","pt":1646101254240,"mc":[{"id":"1.195395424","rc":[{"atb":[[1.5,0]],"id":40576811}],"con":true,"img":false}]}
{"op":"mcm","clk":"5306575855","pt":1646101256241,"mc":[{"id":"1.195395424","rc":[{"atb":[[1.63,13.25]],"id":40576811}],"con":true,"img":false}]}
{"op":"mcm","clk":"5306576165","pt":1646101262666,"mc":[{"id":"1.195395424","rc":[{"atb":[[1.68,10.96]],"id":40576811}],"con":true,"img":false}]}
{"op":"mcm","clk":"5306576170","pt":1646101262769,"mc":[{"id":"1.195395424","rc":[{"atb":[[1.69,13.25]],"id":40576811}],"con":true,"img":false}]}
{"op":"mcm","clk":"5306576176","pt":1646101262872,"mc":[{"id":"1.195395424","rc":[{"atb":[[1.64,0]],"id":40576811}],"con":true,"img":false}]}
{"op":"mcm","clk":"5306576325","pt":1646101265449,"mc":[{"id":"1.195395424","rc":[{"atb":[[1.68,0]],"id":40576811}],"con":true,"img":false}]}
{"op":"mcm","clk":"5306576408","pt":1646101267856,"mc":[{"id":"1.195395424","rc":[{"atb":[[1.64,65.59]],"id":40576811}],"con":true,"img":false}]}
{"op":"mcm","clk":"5306576415","pt":1646101267958,"mc":[{"id":"1.195395424","rc":[{"atb":[[1.69,0]],"id":40576811}],"con":true,"img":false}]}
{"op":"mcm","clk":"5306576484","pt":1646101269349,"mc":[{"id":"1.195395424","rc":[{"atb":[[1.63,0]],"id":40576811}],"con":true,"img":false}]}
{"op":"mcm","clk":"5306576491","pt":1646101269450,"mc":[{"id":"1.195395424","rc":[{"atb":[[1.64,0],[1.6,131.18]],"id":40576811}],"con":true,"img":false}]}
{"op":"mcm","clk":"5306576536","pt":1646101270892,"mc":[{"id":"1.195395424","rc":[{"atb":[[8.4,0]],"id":39318318}],"con":true,"img":false}]}
{"op":"mcm","clk":"5306576541","pt":1646101270995,"mc":[{"id":"1.195395424","rc":[{"atb":[[8.8,5.41]],"id":39318318}],"con":true,"img":false}]}
{"op":"mcm","clk":"5306576801","pt":1646101277205,"mc":[{"id":"1.195395424","rc":[{"atb":[[1.64,11.64]],"id":40576811}],"con":true,"img":false}]}
{"op":"mcm","clk":"5306576951","pt":1646101281000,"mc":[{"id":"1.195395424","rc":[{"atl":[[50,0]],"id":39318318}],"con":true,"img":false}]}
{"op":"mcm","clk":"5306576955","pt":1646101281103,"mc":[{"id":"1.195395424","rc":[{"atl":[[55,2.7]],"id":39318318}],"con":true,"img":false}]}
{"op":"mcm","clk":"5306577079","pt":1646101283681,"mc":[{"id":"1.195395424","rc":[{"spn":1.74,"spf":"NaN","id":39133526},{"spn":19.4,"spf":"NaN","id":39318318},{"atb":[[1.6,0],[1.65,65.59]],"id":40576811},{"spn":2.17,"spf":"NaN","id":40576811}],"con":true,"img":false}]}
{"op":"mcm","clk":"5306577185","pt":1646101286192,"mc":[{"id":"1.195395424","rc":[{"atb":[[1.64,0]],"id":40576811}],"con":true,"img":false}]}
{"op":"mcm","clk":"5306577188","pt":1646101286294,"mc":[{"id":"1.195395424","rc":[{"atb":[[1.6,131.18],[1.65,0]],"id":40576811}],"con":true,"img":false}]}
{"op":"mcm","clk":"5306577346","pt":1646101290811,"mc":[{"id":"1.195395424","rc":[{"atb":[[1.59,0]],"id":40576811}],"con":true,"img":false}]}
{"op":"mcm","clk":"5306577349","pt":1646101290914,"mc":[{"id":"1.195395424","rc":[{"atb":[[1.61,65.58]],"id":40576811}],"con":true,"img":false}]}
{"op":"mcm","clk":"5306577751","pt":1646101299294,"mc":[{"id":"1.195395424","rc":[{"atb":[[1.65,11.46]],"id":40576811}],"con":true,"img":false}]}
{"op":"mcm","clk":"5306577975","pt":1646101304619,"mc":[{"id":"1.195395424","rc":[{"atb":[[1.65,24.3]],"id":40576811}],"con":true,"img":false}]}
{"op":"mcm","clk":"5306578086","pt":1646101307032,"mc":[{"id":"1.195395424","rc":[{"atb":[[1.6,0],[1.66,65.59]],"id":40576811}],"con":true,"img":false}]}
{"op":"mcm","clk":"5306578149","pt":1646101308625,"mc":[{"id":"1.195395424","rc":[{"atb":[[1.17,100.93]],"id":39133526},{"atb":[[1.32,60.77]],"id":42248822},{"atb":[[1.62,26.73]],"id":40576811}],"con":true,"img":false}]}
{"op":"mcm","clk":"5306578218","pt":1646101310320,"mc":[{"id":"1.195395424","rc":[{"atb":[[1.65,12.84]],"id":40576811}],"con":true,"img":false}]}
{"op":"mcm","clk":"5306578333","pt":1646101312844,"mc":[{"id":"1.195395424","rc":[{"atb":[[8.8,0]],"id":39318318}],"con":true,"img":false}]}
{"op":"mcm","clk":"5306578339","pt":1646101312945,"mc":[{"id":"1.195395424","rc":[{"atb":[[9,5.41]],"id":39318318}],"con":true,"img":false}]}
{"op":"mcm","clk":"5306578377","pt":1646101313718,"mc":[{"id":"1.195395424","rc":[{"atb":[[1.62,0]],"id":40576811}],"con":true,"img":false}]}
{"op":"mcm","clk":"5306578477","pt":1646101316131,"mc":[{"id":"1.195395424","rc":[{"atb":[[1.7,10.65]],"id":40576811}],"con":true,"img":false}]}
{"op":"mcm","clk":"5306578481","pt":1646101316234,"mc":[{"id":"1.195395424","rc":[{"atb":[[1.71,12.84]],"id":40576811}],"con":true,"img":false}]}
{"op":"mcm","clk":"5306578486","pt":1646101316337,"mc":[{"id":"1.195395424","rc":[{"atb":[[1.66,0]],"id":40576811}],"con":true,"img":false}]}
{"op":"mcm","clk":"5306578582","pt":1646101319263,"mc":[{"id":"1.195395424","rc":[{"atb":[[1.57,39.69]],"id":43154453},{"atb":[[1.7,0]],"id":40576811}],"con":true,"img":false}]}
{"op":"mcm","clk":"5306578680","pt":1646101321368,"mc":[{"id":"1.195395424","rc":[{"atb":[[1.66,65.59],[1.71,0]],"id":40576811}],"con":true,"img":false}]}
{"op":"mcm","clk":"5306578778","pt":1646101323371,"mc":[{"id":"1.195395424","rc":[{"atb":[[1.65,0]],"id":40576811}],"con":true,"img":false}]}
{"op":"mcm","clk":"5306578784","pt":1646101323473,"mc":[{"id":"1.195395424","rc":[{"atb":[[1.62,131.18],[1.66,0]],"id":40576811}],"con":true,"img":false}]}
{"op":"mcm","clk":"5306579115","pt":1646101331132,"mc":[{"id":"1.195395424","rc":[{"atb":[[1.66,11.29]],"id":40576811}],"con":true,"img":false}]}
{"op":"mcm","clk":"5306579523","pt":1646101341347,"mc":[{"id":"1.195395424","rc":[{"atb":[[1.66,23.94]],"id":40576811}],"con":true,"img":false}]}
{"op":"mcm","clk":"5306579631","pt":1646101343756,"mc":[{"id":"1.195395424","rc":[{"spn":19.5,"spf":"NaN","id":39318318},{"atb":[[1.67,65.59],[1.62,0]],"id":40576811},{"spn":2.18,"spf":"NaN","id":40576811}],"con":true,"img":false}]}
{"op":"mcm","clk":"5306579687","pt":1646101344880,"mc":[{"id":"1.195395424","rc":[{"atb":[[1.61,0]],"id":40576811}],"con":true,"img":false}]}
{"op":"mcm","clk":"5306579691","pt":1646101344985,"mc":[{"id":"1.195395424","rc":[{"atb":[[1.63,65.58]],"id":40576811}],"con":true,"img":false}]}
{"op":"mcm","clk":"5306579764","pt":1646101346268,"mc":[{"id":"1.195395424","rc":[{"atb":[[1.66,12.64]],"id":40576811}],"con":true,"img":false}]}
{"op":"mcm","clk":"5306579875","pt":1646101348785,"mc":[{"id":"1.195395424","rc":[{"atb":[[1.18,242.95]],"id":39133526}],"con":true,"img":false}]}
{"op":"mcm","clk":"5306579882","pt":1646101348888,"mc":[{"id":"1.195395424","rc":[{"atb":[[1.16,0]],"id":39133526}],"con":true,"img":false}]}
{"op":"mcm","clk":"5306579982","pt":1646101350888,"mc":[{"id":"1.195395424","rc":[{"atl":[[55,0]],"id":39318318}],"con":true,"img":false}]}
{"op":"mcm","clk":"5306579989","pt":1646101350992,"mc":[{"id":"1.195395424","rc":[{"atl":[[60,2.7]],"id":39318318}],"con":true,"img":false}]}
{"op":"mcm","clk":"5306580049","pt":1646101352374,"mc":[{"id":"1.195395424","rc":[{"atb":[[1.71,10.49]],"id":40576811}],"con":true,"img":false}]}
{"op":"mcm","clk":"5306580054","pt":1646101352476,"mc":[{"id":"1.195395424","rc":[{"atb":[[1.72,12.65]],"id":40576811}],"con":true,"img":false}]}
{"op":"mcm","clk":"5306580059","pt":1646101352578,"mc":[{"id":"1.195395424","rc":[{"atb":[[1.67,0]],"id":40576811}],"con":true,"img":false}]}
{"op":"mcm","clk":"5306580064","pt":1646101352783,"mc":[{"id":"1.195395424","rc":[{"atb":[[1.63,0]],"id":40576811}],"con":true,"img":false}]}
{"op":"mcm","clk":"5306580070","pt":1646101352886,"mc":[{"id":"1.195395424","rc":[{"atb":[[1.17,0]],"id":39133526}],"con":true,"img":false}]}
{"op":"mcm","clk":"5306580077","pt":1646101352990,"mc":[{"id":"1.195395424","rc":[{"atb":[[1.57,65.58]],"id":40576811}],"con":true,"img":false}]}
{"op":"mcm","clk":"5306580191","pt":1646101355504,"mc":[{"id":"1.195395424","rc":[{"atb":[[1.71,0]],"id":40576811}],"con":true,"img":false}]}
{"op":"mcm","clk":"5306580198","pt":1646101355558,"mc":[{"id":"1.195395424","rc":[{"atb":[[1.72,0],[1.67,65.59]],"id":40576811}],"con":true,"img":false}]}
{"op":"mcm","clk":"5306580325","pt":1646101358179,"mc":[{"id":"1.195395424","rc":[{"atb":[[1.21,64.23]],"id":39133526}],"con":true,"img":false}]}
{"op":"mcm","clk":"5306580395","pt":1646101359466,"mc":[{"id":"1.195395424","rc":[{"atb":[[1.66,0]],"id":40576811}],"con":true,"img":false}]}
{"op":"mcm","clk":"5306580441","pt":1646101360696,"mc":[{"id":"1.195395424","rc":[{"atb":[[1.58,131.18],[1.67,0]],"id":40576811}],"con":true,"img":false}]}
{"op":"mcm","clk":"5306580742","pt":1646101367473,"mc":[{"id":"1.195395424","rc":[{"atb":[[1.62,12.02]],"id":40576811}],"con":true,"img":false}]}
{"op":"mcm","clk":"5306581042","pt":1646101374810,"mc":[{"id":"1.195395424","rc":[{"atb":[[1.62,25.48]],"id":40576811}],"con":true,"img":false}]}
{"op":"mcm","clk":"5306581070","pt":1646101375628,"mc":[{"id":"1.195395424","rc":[{"atb":[[1.63,65.59],[1.58,0]],"id":40576811}],"con":true,"img":false}]}
{"op":"mcm","clk":"5306581106","pt":1646101376607,"mc":[{"id":"1.195395424","rc":[{"atb":[[1.62,13.46]],"id":40576811}],"con":true,"img":false}]}
{"op":"mcm","clk":"5306581204","pt":1646101378811,"mc":[{"id":"1.195395424","rc":[{"atb":[[1.2,0]],"id":39133526}],"con":true,"img":false}]}
{"op":"mcm","clk":"5306581206","pt":1646101378913,"mc":[{"id":"1.195395424","rc":[{"atb":[[1.22,91.76]],"id":39133526}],"con":true,"img":false}]}
{"op":"mcm","clk":"5306581354","pt":1646101382509,"mc":[{"id":"1.195395424","rc":[{"atb":[[1.67,11.12]],"id":40576811}],"con":true,"img":false}]}
{"op":"mcm","clk":"5306581372","pt":1646101382817,"mc":[{"id":"1.195395424","rc":[{"atb":[[1.57,0]],"id":40576811}],"con":true,"img":false}]}
{"op":"mcm","clk":"5306581378","pt":1646101382919,"mc":[{"id":"1.195395424","rc":[{"atb":[[1.64,65.58]],"id":40576811}],"con":true,"img":false}]}
{"op":"mcm","clk":"5306581407","pt":1646101383648,"mc":[{"id":"1.195395424","rc":[{"atb":[[1.21,0]],"id":39133526}],"con":true,"img":false}]}
{"op":"mcm","clk":"5306581457","pt":1646101384818,"mc":[{"id":"1.195395424","rc":[{"atl":[[30,0]],"id":39318318}],"con":true,"img":false}]}
{"op":"mcm","clk":"5306581461","pt":1646101384919,"mc":[{"id":"1.195395424","rc":[{"atl":[[48,2.7],[55,2]],"id":39318318}],"con":true,"img":false}]}
{"op":"mcm","clk":"5306581464","pt":1646101385024,"mc":[{"id":"1.195395424","rc":[{"atl":[[32,0]],"id":39318318}],"con":true,"img":false}]}
{"op":"mcm","clk":"5306581491","pt":1646101385638,"mc":[{"id":"1.195395424","rc":[{"atb":[[1.67,0]],"id":40576811}],"con":true,"img":false}]}
{"op":"mcm","clk":"5306581537","pt":1646101386822,"mc":[{"id":"1.195395424","rc":[{"atl":[[5.5,8.32]],"id":40324448},{"atb":[[7.8,0]],"id":39318318}],"con":true,"img":false}]}
{"op":"mcm","clk":"5306581541","pt":1646101386925,"mc":[{"id":"1.195395424","rc":[{"atl":[[6.4,9.73]],"id":40324448},{"atb":[[6.8,7.57]],"id":39318318}],"con":true,"img":false}]}
{"op":"mcm","clk":"5306581646","pt":1646101389542,"mc":[{"id":"1.195395424","rc":[{"atb":[[1.23,64.23]],"id":39133526}],"con":true,"img":false}]}
{"op":"mcm","clk":"5306581705","pt":1646101390831,"mc":[{"id":"1.195395424","rc":[{"atb":[[1.22,0]],"id":39133526}],"con":true,"img":false}]}
{"op":"mcm","clk":"5306581711","pt":1646101390930,"mc":[{"id":"1.195395424","rc":[{"atb":[[1.2,91.76]],"id":39133526}],"con":true,"img":false}]}
{"op":"mcm","clk":"5306581730","pt":1646101391442,"mc":[{"id":"1.195395424","rc":[{"atb":[[1.68,10.96]],"id":40576811}],"con":true,"img":false}]}
{"op":"mcm","clk":"5306581789","pt":1646101392830,"mc":[{"id":"1.195395424","rc":[{"atb":[[9,0]],"id":39318318}],"con":true,"img":false}]}
{"op":"mcm","clk":"5306581795","pt":1646101392936,"mc":[{"id":"1.195395424","rc":[{"atb":[[7.8,5.41]],"id":39318318}],"con":true,"img":false}]}
{"op":"mcm","clk":"5306581868","pt":1646101394734,"mc":[{"id":"1.195395424","rc":[{"atb":[[1.62,0]],"id":40576811}],"con":true,"img":false}]}
{"op":"mcm","clk":"5306581895","pt":1646101395340,"mc":[{"id":"1.195395424","rc":[{"atb":[[1.23,0]],"id":39133526},{"atb":[[1.63,0],[1.69,65.59]],"id":40576811}],"con":true,"img":false}]}
{"op":"mcm","clk":"5306581989","pt":1646101397552,"mc":[{"id":"1.195395424","rc":[{"atb":[[1.68,0]],"id":40576811}],"con":true,"img":false}]}
{"op":"mcm","clk":"5306582111","pt":1646101400430,"mc":[{"id":"1.195395424","rc":[{"atb":[[1.65,131.18]],"id":40576811}],"con":true,"img":false}]}
{"op":"mcm","clk":"5306582116","pt":1646101400534,"mc":[{"id":"1.195395424","rc":[{"atb":[[1.69,0]],"id":40576811}],"con":true,"img":false}]}
{"op":"mcm","clk":"5306582128","pt":1646101400945,"mc":[{"id":"1.195395424","rc":[{"atb":[[1.21,64.23]],"id":39133526}],"con":true,"img":false}]}
{"op":"mcm","clk":"5306582300","pt":1646101404641,"mc":[{"id":"1.195395424","rc":[{"spn":1.74,"spf":"NaN","id":39133526},{"atl":[[48,4.83],[55,0]],"id":39318318},{"spn":27.3,"spf":"NaN","id":39318318},{"spn":2.17,"spf":"NaN","id":40576811}],"con":true,"img":false}]}
{"op":"mcm","clk":"5306582303","pt":1646101404744,"mc":[{"id":"1.195395424","rc":[{"atl":[[55,2]],"id":39318318}],"con":true,"img":false}]}
{"op":"mcm","clk":"5306582305","pt":1646101404845,"mc":[{"id":"1.195395424","rc":[{"atl":[[48,2.7]],"id":39318318}],"con":true,"img":false}]}
{"op":"mcm","clk":"5306582306","pt":1646101404947,"mc":[{"id":"1.195395424","rc":[{"atl":[[48,4.83],[55,0]],"id":39318318}],"con":true,"img":false}]}
{"op":"mcm","clk":"5306582310","pt":1646101405053,"mc":[{"id":"1.195395424","rc":[{"atl":[[55,2]],"id":39318318}],"con":true,"img":false}]}
{"op":"mcm","clk":"5306582315","pt":1646101405153,"mc":[{"id":"1.195395424","rc":[{"atl":[[48,2.7]],"id":39318318}],"con":true,"img":false}]}
{"op":"mcm","clk":"5306582321","pt":1646101405254,"mc":[{"id":"1.195395424","rc":[{"atl":[[48,4.83]],"id":39318318}],"con":true,"img":false}]}
{"op":"mcm","clk":"5306582324","pt":1646101405356,"mc":[{"id":"1.195395424","rc":[{"atl":[[55,0]],"id":39318318}],"con":true,"img":false}]}
{"op":"mcm","clk":"5306582378","pt":1646101406846,"mc":[{"id":"1.195395424","rc":[{"atl":[[48,2.13]],"id":39318318}],"con":true,"img":false}]}
{"op":"mcm","clk":"5306582386","pt":1646101406949,"mc":[{"id":"1.195395424","rc":[{"atl":[[38,2.7],[48,0],[55,2]],"id":39318318}],"con":true,"img":false}]}
{"op":"mcm","clk":"5306582391","pt":1646101407051,"mc":[{"id":"1.195395424","rc":[{"atl":[[38,4.7],[55,0]],"id":39318318}],"con":true,"img":false}]}
{"op":"mcm","clk":"5306582397","pt":1646101407155,"mc":[{"id":"1.195395424","rc":[{"atl":[[38,2.7],[55,2]],"id":39318318}],"con":true,"img":false}]}
{"op":"mcm","clk":"5306582400","pt":1646101407255,"mc":[{"id":"1.195395424","rc":[{"atl":[[38,5.4]],"id":39318318}],"con":true,"img":false}]}
{"op":"mcm","clk":"5306582403","pt":1646101407361,"mc":[{"id":"1.195395424","rc":[{"atl":[[55,0]],"id":39318318}],"con":true,"img":false}]}
{"op":"mcm","clk":"5306582481","pt":1646101409560,"mc":[{"id":"1.195395424","rc":[{"atb":[[1.69,10.79]],"id":40576811}],"con":true,"img":false}]}
{"op":"mcm","clk":"5306582891","pt":1646101418746,"mc":[{"id":"1.195395424","rc":[{"atb":[[1.69,22.89]],"id":40576811}],"con":true,"img":false}]}
{"op":"mcm","clk":"5306582895","pt":1646101418848,"mc":[{"id":"1.195395424","rc":[{"atb":[[1.64,0]],"id":40576811}],"con":true,"img":false}]}
{"op":"mcm","clk":"5306582900","pt":1646101418950,"mc":[{"id":"1.195395424","rc":[{"atb":[[1.66,65.58]],"id":40576811}],"con":true,"img":false}]}
{"op":"mcm","clk":"5306582941","pt":1646101419975,"mc":[{"id":"1.195395424","rc":[{"atb":[[1.7,65.59],[1.65,0]],"id":40576811}],"con":true,"img":false}]}
{"op":"mcm","clk":"5306583012","pt":1646101421671,"mc":[{"id":"1.195395424","rc":[{"atb":[[1.69,12.09]],"id":40576811}],"con":true,"img":false}]}
{"op":"mcm","clk":"5306583046","pt":1646101422494,"mc":[{"id":"1.195395424","rc":[{"atl":[[5.6,0],[5.5,16.64]],"id":40324448},{"atb":[[1.36,85.46],[1.35,263.42]],"id":42248822}],"con":true,"img":false}]}
{"op":"mcm","clk":"5306583066","pt":1646101422854,"mc":[{"id":"1.195395424","rc":[{"atb":[[1.2,0]],"id":39133526}],"con":true,"img":false}]}
{"op":"mcm","clk":"5306583073","pt":1646101422960,"mc":[{"id":"1.195395424","rc":[{"atb":[[1.22,91.76]],"id":39133526}],"con":true,"img":false}]}
{"op":"mcm","clk":"5306583169","pt":1646101425673,"mc":[{"id":"1.195395424","rc":[{"atb":[[1.15,291.65]],"id":39133526}],"con":true,"img":false}]}
{"op":"mcm","clk":"5306583174","pt":1646101425774,"mc":[{"id":"1.195395424","rc":[{"atb":[[1.18,0]],"id":39133526}],"con":true,"img":false}]}
{"op":"mcm","clk":"5306583212","pt":1646101426750,"mc":[{"id":"1.195395424","rc":[{"atb":[[1.21,0]],"id":39133526},{"atl":[[38,2.7]],"id":39318318},{"atb":[[1.32,0]],"id":42248822}],"con":true,"img":false}]}
{"op":"mcm","clk":"5306583215","pt":1646101426851,"mc":[{"id":"1.195395424","rc":[{"atl":[[36,2.7],[55,2]],"id":39318318}],"con":true,"img":false}]}
{"op":"mcm","clk":"5306583221","pt":1646101426956,"mc":[{"id":"1.195395424","rc":[{"atl":[[36,5.4],[38,0]],"id":39318318}],"con":true,"img":false}]}
{"op":"mcm","clk":"5306583228","pt":1646101427058,"mc":[{"id":"1.195395424","rc":[{"atl":[[55,0]],"id":39318318}],"con":true,"img":false}]}
{"op":"mcm","clk":"5306583248","pt":1646101427571,"mc":[{"id":"1.195395424","rc":[{"atb":[[1.74,10.06]],"id":40576811}],"con":true,"img":false}]}
{"op":"mcm","clk":"5306583390","pt":1646101430853,"mc":[{"id":"1.195395424","rc":[{"atb":[[7.8,0]],"id":39318318},{"atb":[[1.66,0]],"id":40576811}],"con":true,"img":false}]}
{"op":"mcm","clk":"5306583394","pt":1646101430956,"mc":[{"id":"1.195395424","rc":[{"atb":[[9,5.41]],"id":39318318},{"atb":[[1.62,65.58]],"id":40576811}],"con":true,"img":false}]}
{"op":"mcm","clk":"5306583468","pt":1646101432805,"mc":[{"id":"1.195395424","rc":[{"atb":[[1.22,0]],"id":39133526}],"con":true,"img":false}]}
{"op":"mcm","clk":"5306583473","pt":1646101432907,"mc":[{"id":"1.195395424","rc":[{"atb":[[1.2,91.76]],"id":39133526}],"con":true,"img":false}]}
{"op":"mcm","clk":"5306583498","pt":1646101433474,"mc":[{"id":"1.195395424","rc":[{"atb":[[1.16,128.47]],"id":39133526},{"atb":[[1.4,28.35]],"id":42248822}],"con":true,"img":false}]}
{"op":"mcm","clk":"5306583644","pt":1646101436970,"mc":[{"id":"1.195395424","rc":[{"atb":[[1.69,0]],"id":40576811}],"con":true,"img":false}]}
{"op":"mcm","clk":"5306583653","pt":1646101437174,"mc":[{"id":"1.195395424","rc":[{"atl":[[2.4,0],[2.52,55.2]],"id":39133526},{"atb":[[2.56,40.26],[2.52,0]],"id":38185321},{"atl":[[6.2,19.23],[6,10.13]],"id":38185321},{"atb":[[1.32,201.29],[1.35,0]],"id":42248822}],"con":true,"img":false}]}
{"op":"mcm","clk":"5306583711","pt":1646101438766,"mc":[{"id":"1.195395424","rc":[{"atl":[[2.38,0]],"id":39133526}],"con":true,"img":false}]}
{"op":"mcm","clk":"5306583717","pt":1646101438872,"mc":[{"id":"1.195395424","rc":[{"atl":[[2.5,27.59]],"id":39133526}],"con":true,"img":false}]}
{"op":"mcm","clk":"5306583738","pt":1646101439283,"mc":[{"id":"1.195395424","rc":[{"atb":[[1.75,65.59]],"id":40576811}],"con":true,"img":false}]}
{"op":"mcm","clk":"5306583742","pt":1646101439387,"mc":[{"id":"1.195395424","rc":[{"atb":[[1.7,0]],"id":40576811}],"con":true,"img":false}]}
{"op":"mcm","clk":"5306583758","pt":1646101439694,"mc":[{"id":"1.195395424","rc":[{"atb":[[2.6,0]],"id":38185321},{"atb":[[1.74,0]],"id":40576811}],"con":true,"img":false}]}
{"op":"mcm","clk":"5306583764","pt":1646101439795,"mc":[{"id":"1.195395424","rc":[{"atb":[[1.63,131.18]],"id":40576811}],"con":true,"img":false}]}
{"op":"mcm","clk":"5306583769","pt":1646101439897,"mc":[{"id":"1.195395424","rc":[{"atb":[[1.75,0]],"id":40576811}],"con":true,"img":false}]}
{"op":"mcm","clk":"5306583997","pt":1646101444585,"mc":[{"id":"1.195395424","rc":[{"atb":[[1.56,210.32],[1.6,33.33],[1.58,86.21],[1.54,231.48]],"id":43154453},{"atl":[[12,10.91],[13,4.17],[14,5.77],[15,8.93]],"id":43154453},{"atb":[[1.89,56.18],[1.85,147.06],[1.91,21.98],[1.87,86.21]],"id":40324448},{"atl":[[4.3,22.73],[4.5,35.71],[3.95,6.78],[4.1,16.13]],"id":40324448},{"atb":[[1.2,341.76],[1.18,250],[1.16,378.47],[1.22,90.91]],"id":39133526},{"atl":[[2.06,18.87],[2.18,105.93],[2.1,45.45],[2.14,65.79]],"id":39133526},{"atb":[[3.85,17.54],[3.95,6.78],[3.75,63.11],[3.65,47.17]],"id":39318318},{"atl":[[34,2.27],[38,3.38],[28,1],[30,1.72]],"id":39318318},{"atb":[[2.56,88.34],[2.52,82.24],[2.64,12.2],[2.6,31.25]],"id":38185321},{"atl":[[6.2,28.85],[6.6,13.39],[7,20.83],[5.9,4.08]],"id":38185321},{"atb":[[4,6.67],[3.7,46.3],[3.8,26.79],[3.9,58.88]],"id":40022793},{"atl":[[12,1.82],[13,12.5],[14,5.77],[15,8.93]],"id":40022793},{"atb":[[1.33,151.52],[1.29,250],[1.31,379.37],[1.35,57.14]],"id":42248822},{"atl":[[2.36,36.76],[2.4,53.57],[2.32,77.89],[2.44,86.81]],"id":42248822},{"atb":[[1.56,35.71],[1.54,92.59],[1.5,250],[1.52,144.23]],"id":40576811},{"atl":[[8,2.86],[9.2,15.24],[8.8,9.62],[8.4,6.76]],"id":40576811}],"con":true,"img":false}]}
{"op":"mcm","clk":"5306584002","pt":1646101444686,"mc":[{"id":"1.195395424","rc":[{"atl":[[36,2.7],[30,3.99]],"id":39318318},{"atb":[[2.62,6.26]],"id":38185321}],"con":true,"img":false}]}
{"op":"mcm","clk":"5306584008","pt":1646101444791,"mc":[{"id":"1.195395424","rc":[{"atb":[[2.62,4.59]],"id":38185321},{"atl":[[4.4,15.18]],"id":40576811}],"con":true,"img":false}]}
{"op":"mcm","clk":"5306584013","pt":1646101444892,"mc":[{"id":"1.195395424","rc":[{"atl":[[4.8,12.98]],"id":40576811}],"con":true,"img":false}]}
{"op":"mcm","clk":"5306584021","pt":1646101444994,"mc":[{"id":"1.195395424","rc":[{"atb":[[2.6,32.91]],"id":38185321}],"con":true,"img":false}]}
{"op":"mcm","clk":"5306584099","pt":1646101446691,"mc":[{"id":"1.195395424","rc":[{"atb":[[1.72,0]],"id":40324448},{"atb":[[6.8,0],[5.4,9.73]],"id":39318318}],"con":true,"img":false}]}
{"op":"mcm","clk":"5306584106","pt":1646101446813,"mc":[{"id":"1.195395424","rc":[{"atb":[[1.63,58.97]],"id":40324448}],"con":true,"img":false}]}
{"op":"mcm","clk":"5306584146","pt":1646101447712,"mc":[{"id":"1.195395424","rc":[{"atb":[[2.62,0]],"id":38185321},{"atb":[[1.67,11.12]],"id":40576811}],"con":true,"img":false}]}
{"op":"mcm","clk":"5306584151","pt":1646101447815,"mc":[{"id":"1.195395424","rc":[{"atb":[[1.68,65.59]],"id":40576811}],"con":true,"img":false}]}
{"op":"mcm","clk":"5306584155","pt":1646101447918,"mc":[{"id":"1.195395424","rc":[{"atb":[[1.63,0]],"id":40576811}],"con":true,"img":false}]}
{"op":"mcm","clk":"5306584229","pt":1646101449612,"mc":[{"id":"1.195395424","rc":[{"atb":[[1.57,0]],"id":43154453},{"atb":[[1.16,250]],"id":39133526}],"con":true,"img":false}]}
{"op":"mcm","clk":"5306584237","pt":1646101449817,"mc":[{"id":"1.195395424","rc":[{"atl":[[34,5.3],[30,1.72]],"id":39318318}],"con":true,"img":false}]}
{"op":"mcm","clk":"5306584277","pt":1646101450794,"mc":[{"id":"1.195395424","rc":[{"atl":[[36,0]],"id":39318318}],"con":true,"img":false}]}
{"op":"mcm","clk":"5306584282","pt":1646101450900,"mc":[{"id":"1.195395424","rc":[{"atl":[[32,2.7]],"id":39318318}],"con":true,"img":false}]}
{"op":"mcm","clk":"5306584315","pt":1646101451619,"mc":[{"id":"1.195395424","rc":[{"atb":[[1.67,0]],"id":40576811}],"con":true,"img":false}]}
{"op":"mcm","clk":"5306584323","pt":1646101451722,"mc":[{"id":"1.195395424","rc":[{"atb":[[1.63,131.18]],"id":40576811}],"con":true,"img":false}]}
{"op":"mcm","clk":"5306584329","pt":1646101451827,"mc":[{"id":"1.195395424","rc":[{"atb":[[2.6,31.25]],"id":38185321},{"atb":[[1.68,0]],"id":40576811}],"con":true,"img":false}]}
{"op":"mcm","clk":"5306584334","pt":1646101451928,"mc":[{"id":"1.195395424","rc":[{"atb":[[9.2,1.66]],"id":39318318},{"atb":[[2.66,1.66]],"id":38185321}],"con":true,"img":false}]}
{"op":"mcm","clk":"5306584375","pt":1646101452802,"mc":[{"id":"1.195395424","rc":[{"atb":[[9,0]],"id":39318318},{"atl":[[11.5,0]],"id":40022793}],"con":true,"img":false}]}
{"op":"mcm","clk":"5306584381","pt":1646101452903,"mc":[{"id":"1.195395424","rc":[{"atb":[[7.8,5.41]],"id":39318318},{"atl":[[12.5,4.12]],"id":40022793}],"con":true,"img":false}]}
{"op":"mcm","clk":"5306584419","pt":1646101453721,"mc":[{"id":"1.195395424","rc":[{"atb":[[2.66,6.15]],"id":38185321}],"con":true,"img":false}]}
{"op":"mcm","clk":"5306584493","pt":1646101455310,"mc":[{"id":"1.195395424","rc":[{"atb":[[2.58,0]],"id":38185321}],"con":true,"img":false}]}
{"op":"mcm","clk":"5306584511","pt":1646101455721,"mc":[{"id":"1.195395424","rc":[{"atb":[[1.23,63.63]],"id":39133526},{"atb":[[1.57,39.69]],"id":40576811}],"con":true,"img":false}]}
{"op":"mcm","clk":"5306584633","pt":1646101458813,"mc":[{"id":"1.195395424","rc":[{"atb":[[2.54,0]],"id":38185321},{"atb":[[1.62,0]],"id":40576811}],"con":true,"img":false}]}
{"op":"mcm","clk":"5306584640","pt":1646101458916,"mc":[{"id":"1.195395424","rc":[{"atb":[[9.2,0]],"id":39318318},{"atb":[[2.58,29.64]],"id":38185321},{"atb":[[1.64,65.58],[1.58,172.41]],"id":40576811}],"con":true,"img":false}]}
{"op":"mcm","clk":"5306584643","pt":1646101459017,"mc":[{"id":"1.195395424","rc":[{"atb":[[1.63,0]],"id":40576811}],"con":true,"img":false}]}
{"op":"mcm","clk":"5306584648","pt":1646101459119,"mc":[{"id":"1.195395424","rc":[{"atb":[[8.8,1.66]],"id":39318318}],"con":true,"img":false}]}
{"op":"mcm","clk":"5306584717","pt":1646101460817,"mc":[{"id":"1.195395424","rc":[{"atb":[[1.64,0]],"id":40576811}],"con":true,"img":false}]}
{"op":"mcm","clk":"5306584723","pt":1646101460919,"mc":[{"id":"1.195395424","rc":[{"atb":[[1.61,65.58]],"id":40576811}],"con":true,"img":false}]}
{"op":"mcm","clk":"5306584752","pt":1646101461737,"mc":[{"id":"1.195395424","rc":[{"atb":[[2.66,11.18]],"id":38185321}],"con":true,"img":false}]}
{"op":"mcm","clk":"5306584801","pt":1646101463022,"mc":[{"id":"1.195395424","rc":[{"atb":[[1.63,49.04]],"id":43154453},{"atb":[[2,26.51]],"id":40324448},{"atb":[[1.24,127.27]],"id":39133526},{"atb":[[2.68,12.31]],"id":38185321},{"atb":[[1.37,83.51]],"id":42248822},{"atb":[[1.59,52.37]],"id":40576811}],"con":true,"img":false}]}
{"op":"mcm","clk":"5306584837","pt":1646101463943,"mc":[{"id":"1.195395424","rc":[{"atb":[[1.57,0]],"id":40576811}],"con":true,"img":false}]}
{"op":"mcm","clk":"5306584927","pt":1646101465846,"mc":[{"id":"1.195395424","rc":[{"spn":3.0,"spf":"NaN","id":40324448},{"spn":1.65,"spf":"NaN","id":39133526},{"spn":18.4,"spf":"NaN","id":39318318},{"atb":[[2.66,9.51]],"id":38185321},{"spn":4.29,"spf":"NaN","id":38185321},{"spn":1.85,"spf":"NaN","id":42248822},{"spn":2.15,"spf":"NaN","id":40576811}],"con":true,"img":false}]}
{"op":"mcm","clk":"5306584935","pt":1646101465949,"mc":[{"id":"1.195395424","rc":[{"atb":[[1.66,12.64]],"id":43154453},{"atb":[[2.7,1.66]],"id":38185321},{"atb":[[1.39,21.4]],"id":42248822}],"con":true,"img":false}]}
{"op":"mcm","clk":"5306584969","pt":1646101466721,"mc":[{"id":"1.195395424","rc":[{"atb":[[1.23,0]],"id":39133526}],"con":true,"img":false}]}
{"op":"mcm","clk":"5306585061","pt":1646101468729,"mc":[{"id":"1.195395424","rc":[{"atl":[[2.3,0]],"id":39133526},{"atb":[[1.65,11.46]],"id":40576811}],"con":true,"img":false}]}
{"op":"mcm","clk":"5306585066","pt":1646101468831,"mc":[{"id":"1.195395424","rc":[{"atb":[[1.24,0]],"id":39133526},{"atl":[[2.08,32.79]],"id":39133526},{"atl":[[34,2.27],[30,4.43]],"id":39318318}],"con":true,"img":false}]}
{"op":"mcm","clk":"5306585105","pt":1646101469545,"mc":[{"id":"1.195395424","rc":[{"atb":[[1.62,36.49]],"id":40576811}],"con":true,"img":false}]}
{"op":"mcm","clk":"5306585163","pt":1646101470728,"mc":[{"id":"1.195395424","rc":[{"atl":[[5.5,8.32],[4.2,13.52]],"id":40324448}],"con":true,"img":false}]}
{"op":"mcm","clk":"5306585222","pt":1646101471960,"mc":[{"id":"1.195395424","rc":[{"atb":[[1.67,11.12]],"id":43154453},{"atb":[[1.4,46.99]],"id":42248822}],"con":true,"img":false}]}
{"op":"mcm","clk":"5306585262","pt":1646101472631,"mc":[{"id":"1.195395424","rc":[{"atb":[[1.23,63.63]],"id":39133526}],"con":true,"img":false}]}
{"op":"mcm","clk":"5306585266","pt":1646101472734,"mc":[{"id":"1.195395424","rc":[{"atb":[[1.15,0],[1.19,547.78]],"id":39133526}],"con":true,"img":false}]}
{"op":"mcm","clk":"5306585278","pt":1646101472941,"mc":[{"id":"1.195395424","rc":[{"atb":[[1.23,197.98]],"id":39133526},{"atb":[[1.59,0]],"id":40576811}],"con":true,"img":false}]}
{"op":"mcm","clk":"5306585372","pt":1646101474841,"mc":[{"id":"1.195395424","rc":[{"atl":[[12.5,0]],"id":40022793}],"con":true,"img":false}]}
{"op":"mcm","clk":"5306585377","pt":1646101474946,"mc":[{"id":"1.195395424","rc":[{"atb":[[1.63,0]],"id":43154453},{"atl":[[11.5,4.12]],"id":40022793}],"con":true,"img":false}]}
{"op":"mcm","clk":"5306585406","pt":1646101475662,"mc":[{"id":"1.195395424","rc":[{"atb":[[1.62,0]],"id":40576811}],"con":true,"img":false}]}
{"op":"mcm","clk":"5306585466","pt":1646101476745,"mc":[{"id":"1.195395424","rc":[{"atb":[[1.31,241.94]],"id":42248822},{"atb":[[1.65,24.3]],"id":40576811}],"con":true,"img":false}]}
{"op":"mcm","clk":"5306585471","pt":1646101476849,"mc":[{"id":"1.195395424","rc":[{"atb":[[1.34,137.43]],"id":42248822}],"con":true,"img":false}]}
{"op":"mcm","clk":"5306585481","pt":1646101477052,"mc":[{"id":"1.195395424","rc":[{"atb":[[1.66,22.92]],"id":40576811}],"con":true,"img":false}]}
{"op":"mcm","clk":"5306585527","pt":1646101477825,"mc":[{"id":"1.195395424","rc":[{"atb":[[1.67,0]],"id":43154453},{"atb":[[1.67,24.3]],"id":40576811}],"con":true,"img":false}]}
{"op":"mcm","clk":"5306585531","pt":1646101477926,"mc":[{"id":"1.195395424","rc":[{"atb":[[1.58,0]],"id":40576811}],"con":true,"img":false}]}
{"op":"mcm","clk":"5306585574","pt":1646101479155,"mc":[{"id":"1.195395424","rc":[{"atb":[[1.63,36.16]],"id":43154453}],"con":true,"img":false}]}
{"op":"mcm","clk":"5306585645","pt":1646101481157,"mc":[{"id":"1.195395424","rc":[{"atb":[[1.66,0]],"id":40576811}],"con":true,"img":false}]}
{"op":"mcm","clk":"5306585656","pt":1646101481466,"mc":[{"id":"1.195395424","rc":[{"atb":[[1.63,50.07]],"id":43154453}],"con":true,"img":false}]}
{"op":"mcm","clk":"5306585721","pt":1646101482855,"mc":[{"id":"1.195395424","rc":[{"atb":[[1.56,133.93]],"id":43154453}],"con":true,"img":false}]}
{"op":"mcm","clk":"5306585725","pt":1646101482957,"mc":[{"id":"1.195395424","rc":[{"atb":[[1.59,76.39]],"id":43154453},{"atb":[[1.67,0],[1.66,48.6]],"id":40576811}],"con":true,"img":false}]}
{"op":"mcm","clk":"5306585782","pt":1646101483931,"mc":[{"id":"1.195395424","rc":[{"atb":[[1.65,12.84]],"id":40576811}],"con":true,"img":false}]}
{"op":"mcm","clk":"5306585826","pt":1646101484854,"mc":[{"id":"1.195395424","rc":[{"atb":[[1.66,0]],"id":43154453},{"atl":[[6.4,0]],"id":40324448},{"atb":[[1.39,0],[1.36,0]],"id":42248822},{"atb":[[1.49,0]],"id":40576811}],"con":true,"img":false}]}
{"op":"mcm","clk":"5306585832","pt":1646101484954,"mc":[{"id":"1.195395424","rc":[{"atl":[[5.8,9.73]],"id":40324448},{"atb":[[1.38,85.46]],"id":42248822},{"atb":[[1.55,79.54]],"id":40576811}],"con":true,"img":false}]}
{"op":"mcm","clk":"5306585850","pt":1646101485364,"mc":[{"id":"1.195395424","rc":[{"atb":[[1.62,49.83]],"id":40576811}],"con":true,"img":false}]}
{"op":"mcm","clk":"5306585912","pt":1646101486748,"mc":[{"id":"1.195395424","rc":[{"atl":[[60,0]],"id":39318318},{"atb":[[2.58,0]],"id":38185321}],"con":true,"img":false}]}
{"op":"mcm","clk":"5306585918","pt":1646101486849,"mc":[{"id":"1.195395424","rc":[{"atl":[[36,2.7]],"id":39318318},{"atb":[[2.62,29.64]],"id":38185321},{"atb":[[1.4,28.35]],"id":42248822}],"con":true,"img":false}]}
{"op":"mcm","clk":"5306585954","pt":1646101487465,"mc":[{"id":"1.195395424","rc":[{"atb":[[1.63,13.91]],"id":43154453},{"atb":[[1.37,0]],"id":42248822}],"con":true,"img":false}]}
{"op":"mcm","clk":"5306586067","pt":1646101489870,"mc":[{"id":"1.195395424","rc":[{"atb":[[2.66,5.02]],"id":38185321},{"atb":[[1.7,10.65]],"id":40576811}],"con":true,"img":false}]}
{"op":"mcm","clk":"5306586107","pt":1646101490845,"mc":[{"id":"1.195395424","rc":[{"atl":[[32,0]],"id":39318318}],"con":true,"img":false}]}
{"op":"mcm","clk":"5306586112","pt":1646101490945,"mc":[{"id":"1.195395424","rc":[{"atl":[[34,5.3],[29,2.7]],"id":39318318}],"con":true,"img":false}]}
{"op":"mcm","clk":"5306586117","pt":1646101491048,"mc":[{"id":"1.195395424","rc":[{"atl":[[30,1.72]],"id":39318318}],"con":true,"img":false}]}
{"op":"mcm","clk":"5306586137","pt":1646101491662,"mc":[{"id":"1.195395424","rc":[{"atb":[[1.64,27.83]],"id":43154453},{"atb":[[1.36,85.83]],"id":42248822}],"con":true,"img":false}]}
{"op":"mcm","clk":"5306586162","pt":1646101492275,"mc":[{"id":"1.195395424","rc":[{"atb":[[1.4,0]],"id":42248822}],"con":true,"img":false}]}
{"op":"mcm","clk":"5306586193","pt":1646101492890,"mc":[{"id":"1.195395424","rc":[{"atb":[[1.41,18.17]],"id":42248822}],"con":true,"img":false}]}
{"op":"mcm","clk":"5306586241","pt":1646101493666,"mc":[{"id":"1.195395424","rc":[{"atb":[[1.62,0]],"id":40576811}],"con":true,"img":false}]}
{"op":"mcm","clk":"5306586307","pt":1646101494844,"mc":[{"id":"1.195395424","rc":[{"atb":[[1.38,0]],"id":42248822}],"con":true,"img":false}]}
{"op":"mcm","clk":"5306586311","pt":1646101494949,"mc":[{"id":"1.195395424","rc":[{"atb":[[1.37,85.46]],"id":42248822}],"con":true,"img":false}]}
{"op":"mcm","clk":"5306586327","pt":1646101495156,"mc":[{"id":"1.195395424","rc":[{"atb":[[1.65,0]],"id":40576811}],"con":true,"img":false}]}
{"op":"mcm","clk":"5306586355","pt":1646101495868,"mc":[{"id":"1.195395424","rc":[{"atb":[[1.66,11.29]],"id":43154453},{"atb":[[2.68,16.74]],"id":38185321},{"atb":[[1.41,0]],"id":42248822}],"con":true,"img":false}]}
{"op":"mcm","clk":"5306586385","pt":1646101496596,"mc":[{"id":"1.195395424","rc":[{"atb":[[1.71,48.6]],"id":40576811}],"con":true,"img":false}]}
{"op":"mcm","clk":"5306586391","pt":1646101496688,"mc":[{"id":"1.195395424","rc":[{"atb":[[1.66,0]],"id":40576811}],"con":true,"img":false}]}
{"op":"mcm","clk":"5306586397","pt":1646101496893,"mc":[{"id":"1.195395424","rc":[{"atl":[[11.5,0]],"id":40022793}],"con":true,"img":false}]}
{"op":"mcm","clk":"5306586400","pt":1646101496946,"mc":[{"id":"1.195395424","rc":[{"atl":[[11,4.12]],"id":40022793}],"con":true,"img":false}]}
{"op":"mcm","clk":"5306586425","pt":1646101497663,"mc":[{"id":"1.195395424","rc":[{"atb":[[1.39,18.17]],"id":42248822}],"con":true,"img":false}]}
{"op":"mcm","clk":"5306586434","pt":1646101497867,"mc":[{"id":"1.195395424","rc":[{"atb":[[1.36,0]],"id":42248822},{"atb":[[1.62,45.26]],"id":40576811}],"con":true,"img":false}]}
{"op":"mcm","clk":"5306586481","pt":1646101498892,"mc":[{"id":"1.195395424","rc":[{"atl":[[29,0]],"id":39318318},{"atb":[[1.7,0]],"id":40576811}],"con":true,"img":false}]}
{"op":"mcm","clk":"5306586486","pt":1646101498945,"mc":[{"id":"1.195395424","rc":[{"atl":[[32,2.7]],"id":39318318}],"con":true,"img":false}]}
{"op":"mcm","clk":"5306586538","pt":1646101499868,"mc":[{"id":"1.195395424","rc":[{"atb":[[1.64,0]],"id":43154453}],"con":true,"img":false}]}
{"op":"mcm","clk":"5306586556","pt":1646101500276,"mc":[{"id":"1.195395424","rc":[{"atb":[[1.63,0]],"id":43154453}],"con":true,"img":false}]}
{"op":"mcm","clk":"5306586576","pt":1646101500891,"mc":[{"id":"1.195395424","rc":[{"atb":[[1.66,23.94]],"id":43154453}],"con":true,"img":false}]}
{"op":"mcm","clk":"5306586612","pt":1646101501665,"mc":[{"id":"1.195395424","rc":[{"atb":[[1.63,97.2],[1.71,0]],"id":40576811}],"con":true,"img":false}]}
{"op":"mcm","clk":"5306586621","pt":1646101501870,"mc":[{"id":"1.195395424","rc":[{"atb":[[1.4,18.63]],"id":42248822}],"con":true,"img":false}]}
{"op":"mcm","clk":"5306586631","pt":1646101502075,"mc":[{"id":"1.195395424","rc":[{"atb":[[1.4,54.98]],"id":42248822}],"con":true,"img":false}]}
{"op":"mcm","clk":"5306586677","pt":1646101503150,"mc":[{"id":"1.195395424","rc":[{"atb":[[1.39,0]],"id":42248822}],"con":true,"img":false}]}
{"op":"mcm","clk":"5306586741","pt":1646101504280,"mc":[{"id":"1.195395424","rc":[{"atb":[[1.63,49.04]],"id":43154453}],"con":true,"img":false}]}
{"op":"mcm","clk":"5306586767","pt":1646101504997,"mc":[{"id":"1.195395424","rc":[{"atb":[[1.66,12.64]],"id":43154453}],"con":true,"img":false}]}
{"op":"mcm","clk":"5306586822","pt":1646101506178,"mc":[{"id":"1.195395424","rc":[{"atb":[[1.64,35.35]],"id":40576811}],"con":true,"img":false}]}
{"op":"mcm","clk":"5306586853","pt":1646101506895,"mc":[{"id":"1.195395424","rc":[{"atb":[[1.61,0]],"id":40576811}],"con":true,"img":false}]}
{"op":"mcm","clk":"5306586859","pt":1646101506997,"mc":[{"id":"1.195395424","rc":[{"atb":[[1.64,100.94]],"id":40576811}],"con":true,"img":false}]}
{"op":"mcm","clk":"5306586962","pt":1646101509200,"mc":[{"id":"1.195395424","rc":[{"atb":[[1.38,54.98]],"id":42248822}],"con":true,"img":false}]}
{"op":"mcm","clk":"5306586980","pt":1646101509565,"mc":[{"id":"1.195395424","rc":[{"atl":[[30,4.43]],"id":39318318}],"con":true,"img":false}]}
{"op":"mcm","clk":"5306586984","pt":1646101509666,"mc":[{"id":"1.195395424","rc":[{"atl":[[34,2.27]],"id":39318318}],"con":true,"img":false}]}
{"op":"mcm","clk":"5306587024","pt":1646101510381,"mc":[{"id":"1.195395424","rc":[{"atb":[[1.62,0]],"id":40576811}],"con":true,"img":false}]}
{"op":"mcm","clk":"5306587055","pt":1646101510892,"mc":[{"id":"1.195395424","rc":[{"atb":[[1.67,11.12]],"id":43154453},{"atb":[[1.4,36.35]],"id":42248822}],"con":true,"img":false}]}
{"op":"mcm","clk":"5306587100","pt":1646101511870,"mc":[{"id":"1.195395424","rc":[{"atl":[[2.06,0],[2.08,51.31]],"id":39133526}],"con":true,"img":false}]}
{"op":"mcm","clk":"5306587199","pt":1646101513926,"mc":[{"id":"1.195395424","rc":[{"atb":[[1.68,10.96]],"id":40576811}],"con":true,"img":false}]}
{"op":"mcm","clk":"5306587244","pt":1646101514495,"mc":[{"id":"1.195395424","rc":[{"atb":[[1.64,65.58]],"id":40576811}],"con":true,"img":false}]}
{"op":"mcm","clk":"5306587265","pt":1646101514802,"mc":[{"id":"1.195395424","rc":[{"atb":[[1.63,0]],"id":43154453},{"atb":[[1.57,54.21]],"id":40576811}],"con":true,"img":false}]}
{"op":"mcm","clk":"5306587318","pt":1646101515209,"mc":[{"id":"1.195395424","rc":[{"atb":[[1.4,57.23]],"id":42248822},{"atb":[[1.69,65.59],[1.63,0]],"id":40576811}],"con":true,"img":false}]}
{"op":"mcm","clk":"5306587395","pt":1646101517004,"mc":[{"id":"1.195395424","rc":[{"atb":[[1.67,0]],"id":43154453},{"atb":[[1.68,0]],"id":40576811}],"con":true,"img":false}]}
{"op":"mcm","clk":"5306587488","pt":1646101518898,"mc":[{"id":"1.195395424","rc":[{"atl":[[11,0]],"id":40022793}],"con":true,"img":false}]}
{"op":"mcm","clk":"5306587494","pt":1646101519000,"mc":[{"id":"1.195395424","rc":[{"atb":[[1.63,36.16]],"id":43154453},{"atl":[[10.5,4.12]],"id":40022793},{"atb":[[1.57,0]],"id":40576811}],"con":true,"img":false}]}
{"op":"mcm","clk":"5306587531","pt":1646101519874,"mc":[{"id":"1.195395424","rc":[{"atb":[[1.63,49.51]],"id":43154453}],"con":true,"img":false}]}
{"op":"mcm","clk":"5306587558","pt":1646101520287,"mc":[{"id":"1.195395424","rc":[{"atb":[[1.65,131.18],[1.69,0]],"id":40576811}],"con":true,"img":false}]}
{"op":"mcm","clk":"5306587645","pt":1646101521870,"mc":[{"id":"1.195395424","rc":[{"atl":[[2.12,44.64]],"id":39133526}],"con":true,"img":false}]}
{"op":"mcm","clk":"5306587687","pt":1646101522994,"mc":[{"id":"1.195395424","rc":[{"atb":[[1.43,17.33]],"id":42248822}],"con":true,"img":false}]}
{"op":"mcm","clk":"5306587692","pt":1646101523199,"mc":[{"id":"1.195395424","rc":[{"atb":[[1.57,54.21]],"id":40576811}],"con":true,"img":false}]}
{"op":"mcm","clk":"5306587721","pt":1646101524070,"mc":[{"id":"1.195395424","rc":[{"atl":[[2.18,0],[2.1,0],[2.14,0]],"id":39133526}],"con":true,"img":false}]}
{"op":"mcm","clk":"5306587776","pt":1646101525197,"mc":[{"id":"1.195395424","rc":[{"atb":[[1.66,0]],"id":43154453},{"atb":[[1.4,20.87]],"id":42248822}],"con":true,"img":false}]}
{"op":"mcm","clk":"5306587809","pt":1646101525918,"mc":[{"id":"1.195395424","rc":[{"atb":[[1.67,11.12]],"id":43154453},{"spn":2.24,"spf":"NaN","id":43154453},{"spn":1.65,"spf":"NaN","id":39133526},{"spn":4.3,"spf":"NaN","id":38185321},{"spn":1.86,"spf":"NaN","id":42248822},{"spn":2.17,"spf":"NaN","id":40576811}],"con":true,"img":false}]}
{"op":"mcm","clk":"5306587816","pt":1646101526021,"mc":[{"id":"1.195395424","rc":[{"atb":[[1.43,0]],"id":42248822}],"con":true,"img":false}]}
{"op":"mcm","clk":"5306587837","pt":1646101526385,"mc":[{"id":"1.195395424","rc":[{"atl":[[10.5,0]],"id":40022793}],"con":true,"img":false}]}
{"op":"mcm","clk":"5306587841","pt":1646101526487,"mc":[{"id":"1.195395424","rc":[{"atl":[[11.5,4.12]],"id":40022793}],"con":true,"img":false}]}
{"op":"mcm","clk":"5306587901","pt":1646101528179,"mc":[{"id":"1.195395424","rc":[{"atb":[[1.63,36.16]],"id":43154453},{"atb":[[1.38,0]],"id":42248822}],"con":true,"img":false}]}
{"op":"mcm","clk":"5306587925","pt":1646101528898,"mc":[{"id":"1.195395424","rc":[{"atb":[[1.67,0]],"id":43154453},{"atb":[[1.69,10.79]],"id":40576811}],"con":true,"img":false}]}
{"op":"mcm","clk":"5306587950","pt":1646101529410,"mc":[{"id":"1.195395424","rc":[{"atb":[[1.41,41.75]],"id":42248822}],"con":true,"img":false}]}
{"op":"mcm","clk":"5306587972","pt":1646101529921,"mc":[{"id":"1.195395424","rc":[{"atl":[[32,0]],"id":39318318}],"con":true,"img":false}]}
{"op":"mcm","clk":"5306587976","pt":1646101530023,"mc":[{"id":"1.195395424","rc":[{"atl":[[34,5.3],[29,2.7]],"id":39318318}],"con":true,"img":false}]}
{"op":"mcm","clk":"5306587983","pt":1646101530078,"mc":[{"id":"1.195395424","rc":[{"atl":[[30,1.72]],"id":39318318}],"con":true,"img":false}]}
{"op":"mcm","clk":"5306588036","pt":1646101531409,"mc":[{"id":"1.195395424","rc":[{"atb":[[1.63,0]],"id":43154453},{"atl":[[2.08,18.52]],"id":39133526},{"atb":[[1.57,0]],"id":40576811}],"con":true,"img":false}]}
{"op":"mcm","clk":"5306588041","pt":1646101531512,"mc":[{"id":"1.195395424","rc":[{"atl":[[2.1,32.79]],"id":39133526}],"con":true,"img":false}]}
{"op":"mcm","clk":"5306588052","pt":1646101531920,"mc":[{"id":"1.195395424","rc":[{"atl":[[2.16,64.66]],"id":39133526}],"con":true,"img":false}]}
{"op":"mcm","clk":"5306588137","pt":1646101534228,"mc":[{"id":"1.195395424","rc":[{"atb":[[1.64,25.31]],"id":43154453},{"atb":[[1.38,45.92]],"id":42248822}],"con":true,"img":false}]}
{"op":"mcm","clk":"5306588158","pt":1646101534897,"mc":[{"id":"1.195395424","rc":[{"atb":[[1.66,11.29]],"id":43154453},{"atb":[[1.4,39.5]],"id":42248822}],"con":true,"img":false}]}
{"op":"mcm","clk":"5306588191","pt":1646101535717,"mc":[{"id":"1.195395424","rc":[{"atb":[[1.63,49.04]],"id":43154453},{"atb":[[1.66,32.39]],"id":40576811}],"con":true,"img":false}]}
{"op":"mcm","clk":"5306588284","pt":1646101537918,"mc":[{"id":"1.195395424","rc":[{"atl":[[29,0]],"id":39318318},{"atb":[[1.64,0]],"id":40576811}],"con":true,"img":false}]}
{"op":"mcm","clk":"5306588287","pt":1646101538019,"mc":[{"id":"1.195395424","rc":[{"atb":[[1.66,0]],"id":43154453},{"atl":[[32,2.7]],"id":39318318},{"atb":[[1.66,97.98]],"id":40576811}],"con":true,"img":false}]}
{"op":"mcm","clk":"5306588311","pt":1646101538632,"mc":[{"id":"1.195395424","rc":[{"atb":[[1.7,97.99],[1.65,0]],"id":40576811}],"con":true,"img":false}]}
{"op":"mcm","clk":"5306588355","pt":1646101539813,"mc":[{"id":"1.195395424","rc":[{"atb":[[1.63,0]],"id":43154453}],"con":true,"img":false}]}
{"op":"mcm","clk":"5306588358","pt":1646101539915,"mc":[{"id":"1.195395424","rc":[{"atb":[[1.64,0]],"id":43154453}],"con":true,"img":false}]}
{"op":"mcm","clk":"5306588396","pt":1646101541196,"mc":[{"id":"1.195395424","rc":[{"atb":[[1.69,0]],"id":40576811}],"con":true,"img":false}]}
{"op":"mcm","clk":"5306588419","pt":1646101541814,"mc":[{"id":"1.195395424","rc":[{"atb":[[1.66,65.58]],"id":40576811}],"con":true,"img":false}]}
{"op":"mcm","clk":"5306588427","pt":1646101541916,"mc":[{"id":"1.195395424","rc":[{"atl":[[2.2,104.17]],"id":39133526}],"con":true,"img":false}]}
{"op":"mcm","clk":"5306588497","pt":1646101543709,"mc":[{"id":"1.195395424","rc":[{"atb":[[1.67,149.25],[1.7,0]],"id":40576811}],"con":true,"img":false}]}
{"op":"mcm","clk":"5306588509","pt":1646101544011,"mc":[{"id":"1.195395424","rc":[{"atb":[[1.63,49.04]],"id":43154453}],"con":true,"img":false}]}
{"op":"mcm","clk":"5306588562","pt":1646101545341,"mc":[{"id":"1.195395424","rc":[{"atb":[[1.63,84.96]],"id":43154453}],"con":true,"img":false}]}
