{"op":"mcm","clk":"5345985291","pt":1646174444251,"mc":[{"id":"1.195453620","marketDefinition":{"bspMarket":true,"turnInPlayEnabled":false,"persistenceEnabled":false,"marketBaseRate":7.0,"eventId":"31272494","eventTypeId":"4339","numberOfWinners":3,"bettingType":"ODDS","marketType":"PLACE","marketTime":"2022-03-02T10:11:00.000Z","suspendTime":"2022-03-02T10:11:00.000Z","bspReconciled":false,"complete":true,"inPlay":false,"crossMatching":false,"runnersVoidable":false,"numberOfActiveRunners":8,"betDelay":0,"status":"OPEN","runners":[{"status":"ACTIVE","sortPriority":1,"id":37208007,"name":"1. Alecia"},{"status":"ACTIVE","sortPriority":2,"id":37496564,"name":"2. Zachary"},{"status":"ACTIVE","sortPriority":3,"id":28447693,"name":"3. Ripplebrook Glen"},{"status":"ACTIVE","sortPriority":4,"id":42464658,"name":"4. Zipping Bronte"},{"status":"ACTIVE","sortPriority":5,"id":39791282,"name":"5. Shes Our Rocket"},{"status":"ACTIVE","sortPriority":6,"id":40310161,"name":"6. Lakeview Bonnie"},{"status":"ACTIVE","sortPriority":7,"id":40410470,"name":"8. Jet Like Rico"},{"status":"ACTIVE","sortPriority":8,"id":41574727,"name":"9. Center"}],"regulators":["MR_INT"],"venue":"Traralgon","countryCode":"AU","discountAllowed":true,"timezone":"Australia/Sydney","openDate":"2022-03-02T08:31:00.000Z","version":4382425365,"name":"To Be Placed","eventName":"Traralgon (AUS) 2nd Mar"},"rc":[],"con":true,"img":false}]}
{"op":"mcm","clk":"5346059516","pt":1646175786519,"mc":[{"id":"1.195453620","rc":[{"atb":[[1.25,398.8],[1.3,332.33],[1.35,284.86]],"id":40410470},{"atl":[[2.8,40.28],[3,36.25],[2.6,22.66]],"id":40410470},{"spn":1.97,"spf":"NaN","id":40410470},{"atb":[[1.7,142.42],[1.75,132.93],[1.65,153.38]],"id":28447693},{"atl":[[4,24.16],[5,18.12],[3.5,14.5]],"id":28447693},{"spn":2.62,"spf":"NaN","id":28447693},{"atb":[[1.01,19940.11],[1.03,3323.35]],"id":37496564},{"atl":[[2,36.25],[2.4,51.79],[2.2,60.42]],"id":37496564},{"spn":1.51,"spf":"NaN","id":37496564},{"atb":[[1.45,221.55],[1.55,181.27],[1.5,199.4]],"id":42464658},{"atl":[[2.82,19.91],[3.55,28.43],[3.05,35.37]],"id":42464658},{"spn":2.18,"spf":"NaN","id":42464658},{"atb":[[4.1,32.16],[3.8,35.6],[3.55,39.09]],"id":39791282},{"atl":[[19.5,3.91],[14.5,2.68],[29,2.59]],"id":39791282},{"spn":9.3,"spf":"NaN","id":39791282},{"atb":[[4.1,32.16],[3.8,35.6],[3.55,39.09]],"id":37208007},{"atl":[[19.5,3.91],[14.5,2.68],[29,2.59]],"id":37208007},{"spn":9.3,"spf":"NaN","id":37208007},{"atb":[[1.2,498.5],[1.25,398.8],[1.15,664.67]],"id":40310161},{"atl":[[2.44,25.17],[2.64,44.21],[2.84,39.4]],"id":40310161},{"spn":1.84,"spf":"NaN","id":40310161},{"atb":[[3.45,40.69],[3.95,33.79],[3.7,36.92]],"id":41574727},{"atl":[[18.5,4.14],[13.5,2.9],[27,2.78]],"id":41574727},{"spn":8.72,"spf":"NaN","id":41574727}],"con":true,"img":false}]}
{"op":"mcm","clk":"5346061998","pt":1646175839944,"mc":[{"id":"1.195453620","rc":[{"atb":[[1.25,0],[1.3,0],[1.35,0]],"id":40410470},{"atl":[[2.8,0],[3,0],[2.6,0]],"id":40410470},{"atb":[[1.7,0],[1.75,0],[1.65,0]],"id":28447693},{"atl":[[4,0],[5,0],[3.5,0]],"id":28447693},{"atb":[[1.01,0],[1.03,0]],"id":37496564},{"atl":[[2,0],[2.4,0],[2.2,0]],"id":37496564},{"atb":[[1.45,0],[1.55,0],[1.5,0]],"id":42464658},{"atl":[[2.82,0],[3.55,0],[3.05,0]],"id":42464658},{"atb":[[4.1,0],[3.8,0],[3.55,0]],"id":39791282},{"atl":[[19.5,0],[14.5,0],[29,0]],"id":39791282},{"atb":[[4.1,0],[3.8,0],[3.55,0]],"id":37208007},{"atl":[[19.5,0],[14.5,0],[29,0]],"id":37208007},{"atb":[[1.2,0],[1.25,0],[1.15,0]],"id":40310161},{"atl":[[2.44,0],[2.64,0],[2.84,0]],"id":40310161},{"atb":[[3.45,0],[3.95,0],[3.7,0]],"id":41574727},{"atl":[[18.5,0],[13.5,0],[27,0]],"id":41574727}],"con":true,"img":false}]}
{"op":"mcm","clk":"5346062134","pt":1646175843189,"mc":[{"id":"1.195453620","rc":[{"atb":[[1.25,398.8],[1.3,332.33],[1.35,284.86]],"id":40410470},{"atl":[[2.8,40.28],[3,36.25],[2.6,22.66]],"id":40410470},{"atb":[[1.7,142.42],[1.75,132.93],[1.65,153.38]],"id":28447693},{"atl":[[4,24.16],[5,18.12],[3.5,14.5]],"id":28447693},{"atb":[[1.01,19940.11],[1.03,3323.35]],"id":37496564},{"atl":[[2,36.25],[2.4,51.79],[2.2,60.42]],"id":37496564},{"atb":[[4.1,32.16],[3.8,35.6],[3.55,39.09]],"id":39791282},{"atl":[[19.5,3.91],[14.5,2.68],[29,2.59]],"id":39791282},{"atb":[[1.45,221.55],[1.55,181.27],[1.5,199.4]],"id":42464658},{"atl":[[2.82,19.91],[3.55,28.43],[3.05,35.37]],"id":42464658},{"atb":[[4.1,32.16],[3.8,35.6],[3.55,39.09]],"id":37208007},{"atl":[[19.5,3.91],[14.5,2.68],[29,2.59]],"id":37208007},{"atb":[[1.2,498.5],[1.25,398.8],[1.15,664.67]],"id":40310161},{"atl":[[2.44,25.17],[2.64,44.21],[2.84,39.4]],"id":40310161},{"atb":[[3.45,40.69],[3.95,33.79],[3.7,36.92]],"id":41574727},{"atl":[[18.5,4.14],[13.5,2.9],[27,2.78]],"id":41574727}],"con":true,"img":false}]}
{"op":"mcm","clk":"5346105180","pt":1646176602706,"mc":[{"id":"1.195453620","marketDefinition":{"bspMarket":true,"turnInPlayEnabled":false,"persistenceEnabled":false,"marketBaseRate":7.0,"eventId":"31272494","eventTypeId":"4339","numberOfWinners":3,"bettingType":"ODDS","marketType":"PLACE","marketTime":"2022-03-02T10:11:00.000Z","suspendTime":"2022-03-02T10:11:00.000Z","bspReconciled":false,"complete":true,"inPlay":false,"crossMatching":false,"runnersVoidable":false,"numberOfActiveRunners":8,"betDelay":0,"status":"OPEN","runners":[{"status":"ACTIVE","sortPriority":1,"id":37208007,"name":"1. Alecia"},{"status":"ACTIVE","sortPriority":2,"id":37496564,"name":"2. Zachary"},{"status":"ACTIVE","sortPriority":3,"id":28447693,"name":"3. Ripplebrook Glen"},{"status":"ACTIVE","sortPriority":4,"id":42464658,"name":"4. Zipping Bronte"},{"status":"ACTIVE","sortPriority":5,"id":39791282,"name":"5. Shes Our Rocket"},{"status":"ACTIVE","sortPriority":6,"id":40310161,"name":"6. Lakeview Bonnie"},{"status":"ACTIVE","sortPriority":7,"id":40410470,"name":"8. Jet Like Rico"},{"status":"ACTIVE","sortPriority":8,"id":41574727,"name":"9. Center"}],"regulators":["MR_INT"],"venue":"Traralgon","countryCode":"AU","discountAllowed":true,"timezone":"Australia/Sydney","openDate":"2022-03-02T08:31:00.000Z","version":4382425365,"name":"To Be Placed","eventName":"Traralgon (AUS) 2nd Mar"},"rc":[{"atb":[[1.25,398.8],[1.3,332.33],[1.35,284.86]],"id":40410470},{"atl":[[2.8,40.28],[3,36.25],[2.6,22.66]],"id":40410470},{"spn":1.97,"spf":"NaN","id":40410470},{"atb":[[1.7,142.42],[1.75,132.93],[1.65,153.38]],"id":28447693},{"atl":[[4,24.16],[5,18.12],[3.5,14.5]],"id":28447693},{"spn":2.62,"spf":"NaN","id":28447693},{"atb":[[1.01,19940.11],[1.03,3323.35]],"id":37496564},{"atl":[[2,36.25],[2.4,51.79],[2.2,60.42]],"id":37496564},{"spn":1.51,"spf":"NaN","id":37496564},{"atb":[[4.1,32.16],[3.8,35.6],[3.55,39.09]],"id":39791282},{"atl":[[19.5,3.91],[14.5,2.68],[29,2.59]],"id":39791282},{"spn":9.3,"spf":"NaN","id":39791282},{"atb":[[1.45,221.55],[1.55,181.27],[1.5,199.4]],"id":42464658},{"atl":[[2.82,19.91],[3.55,28.43],[3.05,35.37]],"id":42464658},{"spn":2.18,"spf":"NaN","id":42464658},{"atb":[[4.1,32.16],[3.8,35.6],[3.55,39.09]],"id":37208007},{"atl":[[19.5,3.91],[14.5,2.68],[29,2.59]],"id":37208007},{"spn":9.3,"spf":"NaN","id":37208007},{"atb":[[1.2,498.5],[1.25,398.8],[1.15,664.67]],"id":40310161},{"atl":[[2.44,25.17],[2.64,44.21],[2.84,39.4]],"id":40310161},{"spn":1.84,"spf":"NaN","id":40310161},{"atb":[[3.45,40.69],[3.95,33.79],[3.7,36.92]],"id":41574727},{"atl":[[18.5,4.14],[13.5,2.9],[27,2.78]],"id":41574727},{"spn":8.72,"spf":"NaN","id":41574727}],"con":true,"img":true}]}
{"op":"mcm","clk":"5346276524","pt":1646179997505,"mc":[{"id":"1.195453620","rc":[{"atb":[[1.25,398.84],[1.3,332.37],[1.35,284.89]],"id":40410470},{"atl":[[2.8,40.28],[3,36.25],[2.6,22.66]],"id":40410470},{"atb":[[1.7,142.44],[1.75,132.94],[1.65,153.4]],"id":28447693},{"spl":[[1.01,2.72]],"id":28447693},{"atl":[[4,24.17],[5,18.12],[3.5,14.5]],"id":28447693},{"spn":1.75,"spf":1.0,"id":28447693},{"atb":[[1.01,19942.29],[1.03,3323.71]],"id":37496564},{"atl":[[2,36.25],[2.4,51.79],[2.2,60.43]],"id":37496564},{"atb":[[4.1,32.16],[3.8,35.61],[3.55,39.1]],"id":39791282},{"atl":[[19.5,3.91],[14.5,2.68],[29,2.59]],"id":39791282},{"atb":[[1.45,221.58],[1.55,181.29],[1.5,199.42]],"id":42464658},{"atl":[[2.82,19.92],[3.55,28.44],[3.05,35.37]],"id":42464658},{"atb":[[4.1,32.16],[3.8,35.61],[3.55,39.1]],"id":37208007},{"atl":[[19.5,3.91],[14.5,2.68],[29,2.59]],"id":37208007},{"atb":[[1.2,498.55],[1.25,398.84],[1.15,664.74]],"id":40310161},{"atl":[[2.44,25.17],[2.64,44.21],[2.84,39.41]],"id":40310161},{"atb":[[3.45,40.7],[3.95,33.79],[3.7,36.92]],"id":41574727},{"atl":[[18.5,4.14],[13.5,2.9],[27,2.78]],"id":41574727}],"con":true,"img":false}]}
{"op":"mcm","clk":"5346767992","pt":1646187402735,"mc":[{"id":"1.195453620","marketDefinition":{"bspMarket":true,"turnInPlayEnabled":false,"persistenceEnabled":false,"marketBaseRate":7.0,"eventId":"31272494","eventTypeId":"4339","numberOfWinners":3,"bettingType":"ODDS","marketType":"PLACE","marketTime":"2022-03-02T10:11:00.000Z","suspendTime":"2022-03-02T10:11:00.000Z","bspReconciled":false,"complete":true,"inPlay":false,"crossMatching":false,"runnersVoidable":false,"numberOfActiveRunners":8,"betDelay":0,"status":"OPEN","runners":[{"status":"ACTIVE","sortPriority":1,"id":37208007,"name":"1. Alecia"},{"status":"ACTIVE","sortPriority":2,"id":37496564,"name":"2. Zachary"},{"status":"ACTIVE","sortPriority":3,"id":28447693,"name":"3. Ripplebrook Glen"},{"status":"ACTIVE","sortPriority":4,"id":42464658,"name":"4. Zipping Bronte"},{"status":"ACTIVE","sortPriority":5,"id":39791282,"name":"5. Shes Our Rocket"},{"status":"ACTIVE","sortPriority":6,"id":40310161,"name":"6. Lakeview Bonnie"},{"status":"ACTIVE","sortPriority":7,"id":40410470,"name":"8. Jet Like Rico"},{"status":"ACTIVE","sortPriority":8,"id":41574727,"name":"9. Center"}],"regulators":["MR_INT"],"venue":"Traralgon","countryCode":"AU","discountAllowed":true,"timezone":"Australia/Sydney","openDate":"2022-03-02T08:31:00.000Z","version":4382425365,"name":"To Be Placed","eventName":"Traralgon (AUS) 2nd Mar"},"rc":[{"atb":[[1.25,399.47],[1.3,332.89],[1.35,285.34]],"id":40410470},{"atl":[[2.8,40.35],[3,36.31],[2.6,22.7]],"id":40410470},{"spn":1.97,"spf":"NaN","id":40410470},{"atb":[[1.7,142.66],[1.75,133.15],[1.65,153.64]],"id":28447693},{"spl":[[1.01,2.72]],"id":28447693},{"atl":[[4,24.21],[5,18.15],[3.5,14.52]],"id":28447693},{"spn":1.75,"spf":1.0,"id":28447693},{"atb":[[1.01,19973.82],[1.03,3328.97]],"id":37496564},{"atl":[[2,36.31],[2.4,51.87],[2.2,60.52]],"id":37496564},{"spn":1.51,"spf":"NaN","id":37496564},{"atb":[[4.1,32.21],[3.8,35.66],[3.55,39.16]],"id":39791282},{"atl":[[19.5,3.92],[14.5,2.68],[29,2.59]],"id":39791282},{"spn":9.3,"spf":"NaN","id":39791282},{"atb":[[1.45,221.93],[1.55,181.58],[1.5,199.73]],"id":42464658},{"atl":[[2.82,19.95],[3.55,28.48],[3.05,35.43]],"id":42464658},{"spn":2.18,"spf":"NaN","id":42464658},{"atb":[[4.1,32.21],[3.8,35.66],[3.55,39.16]],"id":37208007},{"atl":[[19.5,3.92],[14.5,2.68],[29,2.59]],"id":37208007},{"spn":9.3,"spf":"NaN","id":37208007},{"atb":[[1.2,499.34],[1.25,399.47],[1.15,665.79]],"id":40310161},{"atl":[[2.44,25.21],[2.64,44.28],[2.84,39.47]],"id":40310161},{"spn":1.84,"spf":"NaN","id":40310161},{"atb":[[3.45,40.76],[3.95,33.85],[3.7,36.98]],"id":41574727},{"atl":[[18.5,4.14],[13.5,2.9],[27,2.79]],"id":41574727},{"spn":8.72,"spf":"NaN","id":41574727}],"con":true,"img":true}]}
{"op":"mcm","clk":"5347092543","pt":1646192802714,"mc":[{"id":"1.195453620","marketDefinition":{"bspMarket":true,"turnInPlayEnabled":false,"persistenceEnabled":false,"marketBaseRate":7.0,"eventId":"31272494","eventTypeId":"4339","numberOfWinners":3,"bettingType":"ODDS","marketType":"PLACE","marketTime":"2022-03-02T10:11:00.000Z","suspendTime":"2022-03-02T10:11:00.000Z","bspReconciled":false,"complete":true,"inPlay":false,"crossMatching":false,"runnersVoidable":false,"numberOfActiveRunners":8,"betDelay":0,"status":"OPEN","runners":[{"status":"ACTIVE","sortPriority":1,"id":37208007,"name":"1. Alecia"},{"status":"ACTIVE","sortPriority":2,"id":37496564,"name":"2. Zachary"},{"status":"ACTIVE","sortPriority":3,"id":28447693,"name":"3. Ripplebrook Glen"},{"status":"ACTIVE","sortPriority":4,"id":42464658,"name":"4. Zipping Bronte"},{"status":"ACTIVE","sortPriority":5,"id":39791282,"name":"5. Shes Our Rocket"},{"status":"ACTIVE","sortPriority":6,"id":40310161,"name":"6. Lakeview Bonnie"},{"status":"ACTIVE","sortPriority":7,"id":40410470,"name":"8. Jet Like Rico"},{"status":"ACTIVE","sortPriority":8,"id":41574727,"name":"9. Center"}],"regulators":["MR_INT"],"venue":"Traralgon","countryCode":"AU","discountAllowed":true,"timezone":"Australia/Sydney","openDate":"2022-03-02T08:31:00.000Z","version":4382425365,"name":"To Be Placed","eventName":"Traralgon (AUS) 2nd Mar"},"rc":[{"atb":[[1.25,400.15],[1.3,333.46],[1.35,285.82]],"id":40410470},{"atl":[[2.8,40.41],[3,36.37],[2.6,22.73]],"id":40410470},{"spn":1.97,"spf":"NaN","id":40410470},{"atb":[[1.7,142.91],[1.75,133.38],[1.65,153.9]],"id":28447693},{"spl":[[1.01,2.73]],"id":28447693},{"atl":[[4,24.25],[5,18.18],[3.5,14.55]],"id":28447693},{"spn":1.75,"spf":1.0,"id":28447693},{"atb":[[1.01,20007.64],[1.03,3334.6]],"id":37496564},{"atl":[[2,36.37],[2.4,51.96],[2.2,60.62]],"id":37496564},{"spn":1.51,"spf":"NaN","id":37496564},{"atb":[[4.1,32.27],[3.8,35.72],[3.55,39.22]],"id":39791282},{"atl":[[19.5,3.93],[14.5,2.69],[29,2.59]],"id":39791282},{"spn":9.3,"spf":"NaN","id":39791282},{"atb":[[1.45,222.3],[1.55,181.88],[1.5,200.07]],"id":42464658},{"atl":[[2.82,19.98],[3.55,28.53],[3.05,35.49]],"id":42464658},{"spn":2.18,"spf":"NaN","id":42464658},{"atb":[[4.1,32.27],[3.8,35.72],[3.55,39.22]],"id":37208007},{"atl":[[19.5,3.93],[14.5,2.69],[29,2.59]],"id":37208007},{"spn":9.3,"spf":"NaN","id":37208007},{"atb":[[1.2,500.19],[1.25,400.15],[1.15,666.92]],"id":40310161},{"atl":[[2.44,25.26],[2.64,44.36],[2.84,39.54]],"id":40310161},{"spn":1.84,"spf":"NaN","id":40310161},{"atb":[[3.45,40.83],[3.95,33.9],[3.7,37.04]],"id":41574727},{"atl":[[18.5,4.15],[13.5,2.91],[27,2.79]],"id":41574727},{"spn":8.72,"spf":"NaN","id":41574727}],"con":true,"img":true}]}
{"op":"mcm","clk":"5347381399","pt":1646198202731,"mc":[{"id":"1.195453620","marketDefinition":{"bspMarket":true,"turnInPlayEnabled":false,"persistenceEnabled":false,"marketBaseRate":7.0,"eventId":"31272494","eventTypeId":"4339","numberOfWinners":3,"bettingType":"ODDS","marketType":"PLACE","marketTime":"2022-03-02T10:11:00.000Z","suspendTime":"2022-03-02T10:11:00.000Z","bspReconciled":false,"complete":true,"inPlay":false,"crossMatching":false,"runnersVoidable":false,"numberOfActiveRunners":8,"betDelay":0,"status":"OPEN","runners":[{"status":"ACTIVE","sortPriority":1,"id":37208007,"name":"1. Alecia"},{"status":"ACTIVE","sortPriority":2,"id":37496564,"name":"2. Zachary"},{"status":"ACTIVE","sortPriority":3,"id":28447693,"name":"3. Ripplebrook Glen"},{"status":"ACTIVE","sortPriority":4,"id":42464658,"name":"4. Zipping Bronte"},{"status":"ACTIVE","sortPriority":5,"id":39791282,"name":"5. Shes Our Rocket"},{"status":"ACTIVE","sortPriority":6,"id":40310161,"name":"6. Lakeview Bonnie"},{"status":"ACTIVE","sortPriority":7,"id":40410470,"name":"8. Jet Like Rico"},{"status":"ACTIVE","sortPriority":8,"id":41574727,"name":"9. Center"}],"regulators":["MR_INT"],"venue":"Traralgon","countryCode":"AU","discountAllowed":true,"timezone":"Australia/Sydney","openDate":"2022-03-02T08:31:00.000Z","version":4382425365,"name":"To Be Placed","eventName":"Traralgon (AUS) 2nd Mar"},"rc":[{"atb":[[1.25,400],[1.3,333.33],[1.35,285.71]],"id":40410470},{"atl":[[2.8,40.4],[3,36.36],[2.6,22.73]],"id":40410470},{"spn":1.97,"spf":"NaN","id":40410470},{"atb":[[1.7,142.85],[1.75,133.33],[1.65,153.84]],"id":28447693},{"spl":[[1.01,2.73]],"id":28447693},{"atl":[[4,24.24],[5,18.18],[3.5,14.54]],"id":28447693},{"spn":1.75,"spf":1.0,"id":28447693},{"atb":[[1.01,20000],[1.03,3333.33]],"id":37496564},{"atl":[[2,36.36],[2.4,51.94],[2.2,60.6]],"id":37496564},{"spn":1.51,"spf":"NaN","id":37496564},{"atb":[[4.1,32.25],[3.8,35.71],[3.55,39.21]],"id":39791282},{"atl":[[19.5,3.93],[14.5,2.69],[29,2.59]],"id":39791282},{"spn":9.3,"spf":"NaN","id":39791282},{"atb":[[1.45,222.22],[1.55,181.81],[1.5,200]],"id":42464658},{"atl":[[2.82,19.97],[3.55,28.52],[3.05,35.47]],"id":42464658},{"spn":2.18,"spf":"NaN","id":42464658},{"atb":[[4.1,32.25],[3.8,35.71],[3.55,39.21]],"id":37208007},{"atl":[[19.5,3.93],[14.5,2.69],[29,2.59]],"id":37208007},{"spn":9.3,"spf":"NaN","id":37208007},{"atb":[[1.2,500],[1.25,400],[1.15,666.66]],"id":40310161},{"atl":[[2.44,25.25],[2.64,44.34],[2.84,39.52]],"id":40310161},{"spn":1.84,"spf":"NaN","id":40310161},{"atb":[[3.45,40.81],[3.95,33.89],[3.7,37.03]],"id":41574727},{"atl":[[18.5,4.15],[13.5,2.91],[27,2.79]],"id":41574727},{"spn":8.72,"spf":"NaN","id":41574727}],"con":true,"img":true}]}
{"op":"mcm","clk":"5347412419","pt":1646198874596,"mc":[{"id":"1.195453620","rc":[{"atb":[[1.25,0],[1.3,0],[1.35,0]],"id":40410470},{"atl":[[2.8,0],[3,0],[2.6,0]],"id":40410470},{"spn":"NaN","spf":"NaN","id":40410470},{"atb":[[1.7,0],[1.75,0],[1.65,0]],"id":28447693},{"spl":[[1.01,2.73]],"id":28447693},{"atl":[[4,0],[5,0],[3.5,0]],"id":28447693},{"spn":1.0,"spf":1.0,"id":28447693},{"atb":[[1.01,20000],[1.03,3333.33]],"id":37496564},{"atl":[[2,36.36],[2.4,51.94],[2.2,60.6]],"id":37496564},{"atb":[[4.1,0],[3.8,0],[3.55,0]],"id":39791282},{"atl":[[19.5,0],[14.5,0],[29,0]],"id":39791282},{"spn":"NaN","spf":"NaN","id":39791282},{"atb":[[1.45,0],[1.55,0],[1.5,0]],"id":42464658},{"atl":[[2.82,0],[3.55,0],[3.05,0]],"id":42464658},{"spn":"NaN","spf":"NaN","id":42464658},{"atb":[[4.1,0],[3.8,0],[3.55,0]],"id":37208007},{"atl":[[19.5,0],[14.5,0],[29,0]],"id":37208007},{"spn":"NaN","spf":"NaN","id":37208007},{"atb":[[1.2,0],[1.25,0],[1.15,0]],"id":40310161},{"atl":[[2.44,0],[2.64,0],[2.84,0]],"id":40310161},{"spn":"NaN","spf":"NaN","id":40310161},{"atb":[[3.45,0],[3.95,0],[3.7,0]],"id":41574727},{"atl":[[18.5,0],[13.5,0],[27,0]],"id":41574727},{"spn":"NaN","spf":"NaN","id":41574727}],"con":true,"img":false}]}
{"op":"mcm","clk":"5347413175","pt":1646198892094,"mc":[{"id":"1.195453620","rc":[{"atb":[[1.25,400],[1.3,333.33],[1.35,285.71]],"id":40410470},{"atl":[[2.8,40.4],[3,36.36],[2.6,22.73]],"id":40410470},{"atb":[[1.8,125],[1.85,117.64],[1.75,133.33]],"id":28447693},{"atl":[[4.5,20.78],[5.5,16.16],[3.75,13.22]],"id":28447693},{"atb":[[1.6,166.66],[1.55,181.81],[1.65,153.84]],"id":42464658},{"atl":[[3.45,29.68],[3.95,24.65],[2.98,18.36]],"id":42464658},{"atb":[[4,33.33],[4.5,28.57],[5,25]],"id":39791282},{"atl":[[17,2.27],[38,1.96],[24,3.16]],"id":39791282},{"atb":[[4.1,32.25],[3.8,35.71],[3.55,39.21]],"id":37208007},{"atl":[[19.5,3.93],[14.5,2.69],[29,2.59]],"id":37208007},{"atb":[[1.2,500],[1.25,400],[1.3,333.33]],"id":40310161},{"atl":[[2.54,23.61],[2.74,41.79],[2.94,37.48]],"id":40310161},{"atb":[[4.8,26.31],[5.8,20.83],[5.3,23.25]],"id":41574727},{"atl":[[19,2.02],[46,1.61],[28,2.69]],"id":41574727}],"con":true,"img":false}]}
{"op":"mcm","clk":"5347592859","pt":1646202936611,"mc":[{"id":"1.195453620","rc":[{"spn":1.97,"spf":"NaN","id":40410470},{"spn":1.85,"spf":1.0,"id":28447693},{"spl":[[1.22,30.03]],"id":37496564},{"spn":1.12,"spf":1.0,"id":37496564},{"spn":2.31,"spf":"NaN","id":42464658},{"spn":11.0,"spf":"NaN","id":39791282},{"spn":9.3,"spf":"NaN","id":37208007},{"spn":1.92,"spf":"NaN","id":40310161},{"spn":12.4,"spf":"NaN","id":41574727}],"con":true,"img":false}]}
{"op":"mcm","clk":"5347828702","pt":1646208742531,"mc":[{"id":"1.195453620","rc":[{"atb":[[1.25,399.89],[1.3,333.24],[1.35,285.63]],"id":40410470},{"atl":[[2.8,40.39],[3,36.35],[2.6,22.72]],"id":40410470},{"atb":[[1.8,124.96],[1.85,117.61],[1.75,133.29]],"id":28447693},{"spl":[[1.01,2.72]],"id":28447693},{"atl":[[4.5,20.77],[5.5,16.15],[3.75,13.22]],"id":28447693},{"atb":[[1.01,19994.54],[1.03,3332.42]],"id":37496564},{"spl":[[1.22,30.02]],"id":37496564},{"atl":[[2,36.35],[2.4,51.93],[2.2,60.58]],"id":37496564},{"atb":[[1.6,166.62],[1.55,181.76],[1.65,153.8]],"id":42464658},{"atl":[[3.45,29.67],[3.95,24.64],[2.98,18.36]],"id":42464658},{"atb":[[4,0],[4.5,0],[5,0]],"id":39791282},{"atl":[[17,0],[38,0],[24,0]],"id":39791282},{"spn":"NaN","spf":"NaN","id":39791282},{"atb":[[4.1,32.24],[3.8,35.7],[3.55,39.2]],"id":37208007},{"atl":[[19.5,3.93],[14.5,2.69],[29,2.59]],"id":37208007},{"atb":[[1.2,0],[1.25,0],[1.3,0]],"id":40310161},{"atl":[[2.54,0],[2.74,0],[2.94,0]],"id":40310161},{"spn":"NaN","spf":"NaN","id":40310161},{"atb":[[4.8,0],[5.8,0],[5.3,0]],"id":41574727},{"atl":[[19,0],[46,0],[28,0]],"id":41574727},{"spn":"NaN","spf":"NaN","id":41574727}],"con":true,"img":false}]}
{"op":"mcm","clk":"5347829386","pt":1646208757230,"mc":[{"id":"1.195453620","rc":[{"atb":[[4,33.32],[4.5,28.56],[3.75,36.35]],"id":39791282},{"atl":[[16,2.42],[34,2.2],[22,3.46]],"id":39791282},{"atb":[[1.2,499.86],[1.25,399.89],[1.3,333.24]],"id":40310161},{"atl":[[2.54,23.6],[2.74,41.78],[2.94,37.47]],"id":40310161},{"atb":[[4.5,28.56],[5,24.99],[5.5,22.21]],"id":41574727},{"atl":[[18.5,2.07],[44,1.69],[27,2.79]],"id":41574727}],"con":true,"img":false}]}
{"op":"mcm","clk":"5347849096","pt":1646209002736,"mc":[{"id":"1.195453620","marketDefinition":{"bspMarket":true,"turnInPlayEnabled":false,"persistenceEnabled":false,"marketBaseRate":7.0,"eventId":"31272494","eventTypeId":"4339","numberOfWinners":3,"bettingType":"ODDS","marketType":"PLACE","marketTime":"2022-03-02T10:11:00.000Z","suspendTime":"2022-03-02T10:11:00.000Z","bspReconciled":false,"complete":true,"inPlay":false,"crossMatching":false,"runnersVoidable":false,"numberOfActiveRunners":8,"betDelay":0,"status":"OPEN","runners":[{"status":"ACTIVE","sortPriority":1,"id":37208007,"name":"1. Alecia"},{"status":"ACTIVE","sortPriority":2,"id":37496564,"name":"2. Zachary"},{"status":"ACTIVE","sortPriority":3,"id":28447693,"name":"3. Ripplebrook Glen"},{"status":"ACTIVE","sortPriority":4,"id":42464658,"name":"4. Zipping Bronte"},{"status":"ACTIVE","sortPriority":5,"id":39791282,"name":"5. Shes Our Rocket"},{"status":"ACTIVE","sortPriority":6,"id":40310161,"name":"6. Lakeview Bonnie"},{"status":"ACTIVE","sortPriority":7,"id":40410470,"name":"8. Jet Like Rico"},{"status":"ACTIVE","sortPriority":8,"id":41574727,"name":"9. Center"}],"regulators":["MR_INT"],"venue":"Traralgon","countryCode":"AU","discountAllowed":true,"timezone":"Australia/Sydney","openDate":"2022-03-02T08:31:00.000Z","version":4382425365,"name":"To Be Placed","eventName":"Traralgon (AUS) 2nd Mar"},"rc":[{"atb":[[1.25,399.89],[1.3,333.24],[1.35,285.63]],"id":40410470},{"atl":[[2.8,40.39],[3,36.35],[2.6,22.72]],"id":40410470},{"spn":1.97,"spf":"NaN","id":40410470},{"atb":[[1.8,124.96],[1.85,117.61],[1.75,133.29]],"id":28447693},{"spl":[[1.01,2.72]],"id":28447693},{"atl":[[4.5,20.77],[5.5,16.15],[3.75,13.22]],"id":28447693},{"spn":1.85,"spf":1.0,"id":28447693},{"atb":[[1.01,19994.54],[1.03,3332.42]],"id":37496564},{"spl":[[1.22,30.02]],"id":37496564},{"atl":[[2,36.35],[2.4,51.93],[2.2,60.58]],"id":37496564},{"spn":1.12,"spf":1.0,"id":37496564},{"atb":[[4,33.32],[4.5,28.56],[3.75,36.35]],"id":39791282},{"atl":[[16,2.42],[34,2.2],[22,3.46]],"id":39791282},{"spn":10.25,"spf":"NaN","id":39791282},{"atb":[[1.6,166.62],[1.55,181.76],[1.65,153.8]],"id":42464658},{"atl":[[3.45,29.67],[3.95,24.64],[2.98,18.36]],"id":42464658},{"spn":2.31,"spf":"NaN","id":42464658},{"atb":[[4.1,32.24],[3.8,35.7],[3.55,39.2]],"id":37208007},{"atl":[[19.5,3.93],[14.5,2.69],[29,2.59]],"id":37208007},{"spn":9.3,"spf":"NaN","id":37208007},{"atb":[[1.2,499.86],[1.25,399.89],[1.3,333.24]],"id":40310161},{"atl":[[2.54,23.6],[2.74,41.78],[2.94,37.47]],"id":40310161},{"spn":1.92,"spf":"NaN","id":40310161},{"atb":[[4.5,28.56],[5,24.99],[5.5,22.21]],"id":41574727},{"atl":[[18.5,2.07],[44,1.69],[27,2.79]],"id":41574727},{"spn":12.0,"spf":"NaN","id":41574727}],"con":true,"img":true}]}
{"op":"mcm","clk":"5347921584","pt":1646210519994,"mc":[{"id":"1.195453620","rc":[{"atb":[[1.36,121.29],[1.31,135.37]],"id":40410470},{"atl":[[2.98,21.28],[2.78,24.53]],"id":40410470},{"spn":1.98,"spf":"NaN","id":40410470},{"atb":[[1.55,78.6],[1.67,65.17]],"id":28447693},{"atl":[[5.3,9.82],[4.4,12.84]],"id":28447693},{"atb":[[1.1,145.97],[1.08,466.24]],"id":37496564},{"atl":[[1.89,43.66],[2.08,31.61]],"id":37496564},{"spn":1.16,"spf":1.0,"id":37496564},{"atb":[[5.5,9.7],[4.7,11.09]],"id":39791282},{"atl":[[60,5.45]],"id":39791282},{"spn":10.75,"spf":"NaN","id":39791282},{"atb":[[1.42,87.51],[1.61,71.58]],"id":42464658},{"atl":[[3.4,18.19],[3.9,12.67]],"id":42464658},{"atb":[[4.3,13.23],[3.75,14.06]],"id":37208007},{"atl":[[42,2.72],[46,2.72]],"id":37208007},{"spn":9.4,"spf":"NaN","id":37208007},{"atb":[[1.26,165.93],[1.31,110.2]],"id":40310161},{"atl":[[2.72,25.1],[2.66,25.38]],"id":40310161},{"spn":1.92,"spf":"NaN","id":40310161},{"atb":[[5.8,9.09],[4.9,12]],"id":41574727},{"atl":[[65,5.45]],"id":41574727},{"spn":12.15,"spf":"NaN","id":41574727}],"con":true,"img":false}]}
{"op":"mcm","clk":"5347925104","pt":1646210604561,"mc":[{"id":"1.195453620","rc":[{"atl":[[2.78,0]],"id":40410470},{"atb":[[1.67,0]],"id":28447693},{"atl":[[4.4,0]],"id":28447693},{"atl":[[2.08,0]],"id":37496564},{"atb":[[1.61,0]],"id":42464658},{"atl":[[3.4,0]],"id":42464658},{"atb":[[3.75,0]],"id":37208007},{"atl":[[2.66,0]],"id":40310161},{"atb":[[4.9,0]],"id":41574727}],"con":true,"img":false}]}
{"op":"mcm","clk":"5347925111","pt":1646210604667,"mc":[{"id":"1.195453620","rc":[{"atl":[[2.58,24.53]],"id":40410470},{"atb":[[1.86,65.17]],"id":28447693},{"atl":[[3.7,12.84]],"id":28447693},{"atl":[[1.99,31.61]],"id":37496564},{"atb":[[1.66,71.58]],"id":42464658},{"atl":[[2.96,18.19]],"id":42464658},{"atb":[[3.85,14.06]],"id":37208007},{"atl":[[2.52,25.38]],"id":40310161},{"atb":[[5.1,12]],"id":41574727}],"con":true,"img":false}]}
{"op":"mcm","clk":"5347992527","pt":1646212016260,"mc":[{"id":"1.195453620","rc":[{"atb":[[1.36,121.1],[1.25,399.25],[1.3,332.71],[1.31,135.15],[1.35,285.18]],"id":40410470},{"atl":[[2.8,40.32],[3,36.29],[2.6,22.68],[2.58,24.49],[2.98,21.25]],"id":40410470},{"spn":1.97,"spf":"NaN","id":40410470},{"atb":[[1.8,124.76],[1.55,78.47],[1.85,117.42],[1.86,65.07],[1.75,133.08]],"id":28447693},{"spl":[[1.01,2.72]],"id":28447693},{"atl":[[4.5,20.74],[5.3,9.8],[5.5,16.13],[3.7,12.82],[3.75,13.19]],"id":28447693},{"spn":1.86,"spf":1.0,"id":28447693},{"atb":[[1.01,19962.94],[1.03,3327.15],[1.1,145.74],[1.08,465.51]],"id":37496564},{"spl":[[1.22,29.97]],"id":37496564},{"atl":[[2,36.29],[2.4,51.85],[1.99,31.56],[1.89,43.59],[2.2,60.49]],"id":37496564},{"atb":[[1.6,166.35],[1.55,181.48],[1.42,87.37],[1.66,71.47],[1.65,153.56]],"id":42464658},{"atl":[[3.45,29.63],[3.95,24.6],[2.98,18.33],[2.96,0],[3.9,12.65]],"id":42464658},{"spn":2.32,"spf":"NaN","id":42464658},{"atb":[[4,33.27],[4.5,28.51],[5.5,9.68],[3.75,36.29],[4.7,11.07]],"id":39791282},{"atl":[[16,2.41],[34,2.2],[22,3.45],[60,5.44]],"id":39791282},{"atb":[[4.3,13.21],[3.85,14.04],[4.1,32.19],[3.8,35.64],[3.55,39.14]],"id":37208007},{"atl":[[19.5,3.92],[42,2.72],[46,2.72],[14.5,2.68],[29,2.59]],"id":37208007},{"atb":[[1.2,499.07],[1.25,399.25],[1.26,165.67],[1.3,332.71],[1.31,110.02]],"id":40310161},{"atl":[[2.72,25.06],[2.54,23.57],[2.74,41.71],[2.52,25.34],[2.94,37.41]],"id":40310161},{"spn":1.91,"spf":"NaN","id":40310161},{"atb":[[5.1,11.98],[4.5,28.51],[5.8,9.08],[5,24.95],[5.5,22.18]],"id":41574727},{"atl":[[65,5.44],[18.5,2.07],[44,1.68],[27,2.79]],"id":41574727}],"con":true,"img":false}]}
{"op":"mcm","clk":"5347992531","pt":1646212016362,"mc":[{"id":"1.195453620","rc":[{"atl":[[3.4,18.16]],"id":42464658}],"con":true,"img":false}]}
{"op":"mcm","clk":"5347993694","pt":1646212038169,"mc":[{"id":"1.195453620","rc":[{"atl":[[3.7,0]],"id":28447693},{"atb":[[4.3,0]],"id":37208007}],"con":true,"img":false}]}
{"op":"mcm","clk":"5347993700","pt":1646212038271,"mc":[{"id":"1.195453620","rc":[{"atl":[[4.4,12.82]],"id":28447693},{"atb":[[5.6,13.21]],"id":37208007}],"con":true,"img":false}]}
{"op":"mcm","clk":"5347995867","pt":1646212080340,"mc":[{"id":"1.195453620","rc":[{"atb":[[4.8,9.6],[3.85,0]],"id":37208007},{"atl":[[46,0]],"id":37208007},{"spn":10.05,"spf":"NaN","id":37208007}],"con":true,"img":false}]}
{"op":"mcm","clk":"5347995871","pt":1646212080438,"mc":[{"id":"1.195453620","rc":[{"atl":[[50,2.72]],"id":37208007}],"con":true,"img":false}]}
{"op":"mcm","clk":"5347997007","pt":1646212101965,"mc":[{"id":"1.195453620","rc":[{"atl":[[3.4,0]],"id":42464658}],"con":true,"img":false}]}
{"op":"mcm","clk":"5347997014","pt":1646212102068,"mc":[{"id":"1.195453620","rc":[{"atl":[[2.96,18.16]],"id":42464658}],"con":true,"img":false}]}
{"op":"mcm","clk":"5348000197","pt":1646212165116,"mc":[{"id":"1.195453620","rc":[{"atl":[[4.4,0]],"id":28447693},{"spn":2.31,"spf":"NaN","id":42464658},{"atl":[[42,0]],"id":37208007}],"con":true,"img":false}]}
{"op":"mcm","clk":"5348000202","pt":1646212165221,"mc":[{"id":"1.195453620","rc":[{"atl":[[3.7,12.82]],"id":28447693},{"atl":[[36,2.72]],"id":37208007}],"con":true,"img":false}]}
{"op":"mcm","clk":"5348001259","pt":1646212185938,"mc":[{"id":"1.195453620","rc":[{"atl":[[50,0]],"id":37208007}],"con":true,"img":false}]}
{"op":"mcm","clk":"5348001267","pt":1646212186045,"mc":[{"id":"1.195453620","rc":[{"atl":[[38,2.72]],"id":37208007}],"con":true,"img":false}]}
{"op":"mcm","clk":"5348001919","pt":1646212200362,"mc":[{"id":"1.195453620","rc":[{"atl":[[60,2.72]],"id":39791282},{"atl":[[65,2.72]],"id":41574727}],"con":true,"img":false}]}
{"op":"mcm","clk":"5348001922","pt":1646212200470,"mc":[{"id":"1.195453620","rc":[{"atl":[[50,2.72]],"id":39791282},{"atl":[[55,2.72]],"id":41574727}],"con":true,"img":false}]}
{"op":"mcm","clk":"5348003112","pt":1646212223510,"mc":[{"id":"1.195453620","rc":[{"atl":[[36,0]],"id":37208007}],"con":true,"img":false}]}
{"op":"mcm","clk":"5348003118","pt":1646212223612,"mc":[{"id":"1.195453620","rc":[{"atl":[[30,2.72]],"id":37208007}],"con":true,"img":false}]}
{"op":"mcm","clk":"5348003584","pt":1646212233914,"mc":[{"id":"1.195453620","rc":[{"atb":[[1.31,0]],"id":40410470}],"con":true,"img":false}]}
{"op":"mcm","clk":"5348003588","pt":1646212234018,"mc":[{"id":"1.195453620","rc":[{"atb":[[1.36,256.26]],"id":40410470}],"con":true,"img":false}]}
{"op":"mcm","clk":"5348004637","pt":1646212255476,"mc":[{"id":"1.195453620","rc":[{"atl":[[50,0]],"id":39791282},{"atl":[[55,0]],"id":41574727}],"con":true,"img":false}]}
{"op":"mcm","clk":"5348004640","pt":1646212255576,"mc":[{"id":"1.195453620","rc":[{"atl":[[44,2.72]],"id":39791282},{"atl":[[48,2.72]],"id":41574727}],"con":true,"img":false}]}
{"op":"mcm","clk":"5348005200","pt":1646212265779,"mc":[{"id":"1.195453620","rc":[{"atb":[[1.26,0]],"id":40310161}],"con":true,"img":false}]}
{"op":"mcm","clk":"5348005207","pt":1646212265879,"mc":[{"id":"1.195453620","rc":[{"atb":[[1.31,275.7]],"id":40310161}],"con":true,"img":false}]}
{"op":"mcm","clk":"5348005213","pt":1646212265983,"mc":[{"id":"1.195453620","rc":[{"atb":[[1.32,165.68]],"id":40310161},{"atl":[[3.85,35.09]],"id":40310161}],"con":true,"img":false}]}
{"op":"mcm","clk":"5348005222","pt":1646212266193,"mc":[{"id":"1.195453620","rc":[{"atb":[[1.37,270.27]],"id":40410470},{"atl":[[4,33.33]],"id":40410470},{"atb":[[1.35,234.86]],"id":28447693},{"atl":[[3.95,26.02]],"id":28447693},{"atb":[[1.08,1715.51]],"id":37496564},{"atl":[[2.86,53.76]],"id":37496564},{"atb":[[2.4,57.04]],"id":39791282},{"atl":[[16,4.83]],"id":39791282},{"atl":[[6.6,17.86]],"id":42464658},{"atb":[[2.96,51.02]],"id":37208007},{"atl":[[36,2.86]],"id":37208007},{"atb":[[3.3,43.48]],"id":41574727},{"atl":[[30,3.45]],"id":41574727}],"con":true,"img":false}]}
{"op":"mcm","clk":"5348006406","pt":1646212288520,"mc":[{"id":"1.195453620","rc":[{"atl":[[3.45,16.89],[2.98,0]],"id":40410470},{"atl":[[3.7,0]],"id":28447693},{"atl":[[60,0]],"id":39791282},{"atb":[[5.1,0],[5.8,0]],"id":41574727},{"atl":[[65,0]],"id":41574727}],"con":true,"img":false}]}
{"op":"mcm","clk":"5348006409","pt":1646212288624,"mc":[{"id":"1.195453620","rc":[{"atl":[[3.9,12.82]],"id":28447693},{"atl":[[48,2.72]],"id":39791282},{"atb":[[5.6,9.08],[4.2,11.98]],"id":41574727},{"atl":[[26,2.72]],"id":41574727}],"con":true,"img":false}]}
{"op":"mcm","clk":"5348007092","pt":1646212303250,"mc":[{"id":"1.195453620","rc":[{"spn":1.97,"spf":"NaN","id":40410470},{"atb":[[1.46,217.39],[1.35,0]],"id":28447693},{"atb":[[3.15,46.51],[2.96,0]],"id":37208007},{"spn":1.92,"spf":"NaN","id":40310161},{"spn":12.05,"spf":"NaN","id":41574727}],"con":true,"img":false}]}
{"op":"mcm","clk":"5348007336","pt":1646212308366,"mc":[{"id":"1.195453620","rc":[{"atb":[[1.36,135.15]],"id":40410470},{"atl":[[30,0]],"id":37208007},{"atb":[[1.31,165.67]],"id":40310161},{"atl":[[48,0]],"id":41574727}],"con":true,"img":false}]}
{"op":"mcm","clk":"5348007341","pt":1646212308469,"mc":[{"id":"1.195453620","rc":[{"atb":[[1.38,121.1]],"id":40410470},{"atb":[[5.6,0],[4.8,0],[3.85,12.81]],"id":37208007},{"atl":[[29,5.31]],"id":37208007},{"atb":[[1.21,204.91],[1.33,110.02],[1.31,0]],"id":40310161},{"atl":[[2.72,0]],"id":40310161},{"atl":[[23,2.72]],"id":41574727}],"con":true,"img":false}]}
{"op":"mcm","clk":"5348007347","pt":1646212308524,"mc":[{"id":"1.195453620","rc":[{"atb":[[4.5,13.21]],"id":37208007},{"atl":[[2.92,25.06]],"id":40310161}],"con":true,"img":false}]}
{"op":"mcm","clk":"5348007351","pt":1646212308626,"mc":[{"id":"1.195453620","rc":[{"atb":[[1.37,0],[1.39,135.16]],"id":40410470},{"atb":[[1.32,0],[1.34,165.68]],"id":40310161}],"con":true,"img":false}]}
{"op":"mcm","clk":"5348007767","pt":1646212318377,"mc":[{"id":"1.195453620","rc":[{"atb":[[5.6,0]],"id":41574727}],"con":true,"img":false}]}
{"op":"mcm","clk":"5348007772","pt":1646212318480,"mc":[{"id":"1.195453620","rc":[{"atb":[[5,34.04]],"id":41574727}],"con":true,"img":false}]}
{"op":"mcm","clk":"5348008661","pt":1646212339889,"mc":[{"id":"1.195453620","rc":[{"atb":[[1.11,101.58],[1.1,0]],"id":37496564},{"atb":[[5.5,0]],"id":39791282},{"atl":[[2.96,0]],"id":42464658},{"atl":[[38,0]],"id":37208007},{"atb":[[1.33,0]],"id":40310161},{"atl":[[2.52,0]],"id":40310161}],"con":true,"img":false}]}
{"op":"mcm","clk":"5348008669","pt":1646212339982,"mc":[{"id":"1.195453620","rc":[{"atl":[[3.4,18.16]],"id":42464658},{"atb":[[5.7,9.68]],"id":39791282},{"atl":[[34,2.72]],"id":37208007},{"atb":[[1.26,110.02],[1.31,322.58]],"id":40310161},{"atl":[[2.72,25.34]],"id":40310161}],"con":true,"img":false}]}
{"op":"mcm","clk":"5348008674","pt":1646212340085,"mc":[{"id":"1.195453620","rc":[{"atb":[[1.34,0]],"id":40310161}],"con":true,"img":false}]}
{"op":"mcm","clk":"5348009053","pt":1646212347820,"mc":[{"id":"1.195453620","rc":[{"atb":[[1.4,80.53],[1.38,0]],"id":40410470},{"atb":[[5,24.95]],"id":41574727}],"con":true,"img":false}]}
{"op":"mcm","clk":"5348009061","pt":1646212347926,"mc":[{"id":"1.195453620","rc":[{"atb":[[5.6,9.08]],"id":41574727}],"con":true,"img":false}]}
{"op":"mcm","clk":"5348009066","pt":1646212347976,"mc":[{"id":"1.195453620","rc":[{"atb":[[1.41,135.16],[1.39,0]],"id":40410470}],"con":true,"img":false}]}
{"op":"mcm","clk":"5348009656","pt":1646212357706,"mc":[{"id":"1.195453620","rc":[{"atl":[[2.98,50.51]],"id":37496564}],"con":true,"img":false}]}
{"op":"mcm","clk":"5348009664","pt":1646212357811,"mc":[{"id":"1.195453620","rc":[{"atl":[[2.86,0]],"id":37496564}],"con":true,"img":false}]}
{"op":"mcm","clk":"5348009960","pt":1646212363843,"mc":[{"id":"1.195453620","rc":[{"spn":1.99,"spf":"NaN","id":40410470},{"atb":[[1.08,1250]],"id":37496564},{"spn":1.16,"spf":1.0,"id":37496564},{"spn":2.32,"spf":"NaN","id":42464658},{"spn":10.85,"spf":"NaN","id":39791282},{"spn":9.5,"spf":"NaN","id":37208007},{"spn":1.92,"spf":"NaN","id":40310161}],"con":true,"img":false}]}
{"op":"mcm","clk":"5348009968","pt":1646212363945,"mc":[{"id":"1.195453620","rc":[{"atb":[[1.09,465.51]],"id":37496564}],"con":true,"img":false}]}
{"op":"mcm","clk":"5348010898","pt":1646212381769,"mc":[{"id":"1.195453620","rc":[{"atb":[[1.4,0]],"id":40410470}],"con":true,"img":false}]}
{"op":"mcm","clk":"5348010903","pt":1646212381878,"mc":[{"id":"1.195453620","rc":[{"atb":[[1.42,80.53]],"id":40410470}],"con":true,"img":false}]}
{"op":"mcm","clk":"5348010909","pt":1646212381972,"mc":[{"id":"1.195453620","rc":[{"atb":[[1.41,0],[1.37,270.27]],"id":40410470}],"con":true,"img":false}]}
{"op":"mcm","clk":"5348011459","pt":1646212392773,"mc":[{"id":"1.195453620","rc":[{"atl":[[2.72,0]],"id":40310161}],"con":true,"img":false}]}
{"op":"mcm","clk":"5348011467","pt":1646212392877,"mc":[{"id":"1.195453620","rc":[{"atl":[[2.52,25.34]],"id":40310161}],"con":true,"img":false}]}
{"op":"mcm","clk":"5348012020","pt":1646212403467,"mc":[{"id":"1.195453620","rc":[{"atl":[[2.92,0]],"id":40310161}],"con":true,"img":false}]}
{"op":"mcm","clk":"5348012024","pt":1646212403569,"mc":[{"id":"1.195453620","rc":[{"atl":[[2.72,25.06]],"id":40310161}],"con":true,"img":false}]}
{"op":"mcm","clk":"5348012583","pt":1646212415006,"mc":[{"id":"1.195453620","rc":[{"atb":[[4.2,0]],"id":41574727}],"con":true,"img":false}]}
{"op":"mcm","clk":"5348012586","pt":1646212415104,"mc":[{"id":"1.195453620","rc":[{"atb":[[4.6,11.98]],"id":41574727}],"con":true,"img":false}]}
{"op":"mcm","clk":"5348012721","pt":1646212417901,"mc":[{"id":"1.195453620","rc":[{"atb":[[1.37,0],[1.43,135.16]],"id":40410470}],"con":true,"img":false}]}
{"op":"mcm","clk":"5348014862","pt":1646212458478,"mc":[{"id":"1.195453620","rc":[{"atb":[[1.42,0]],"id":40410470},{"spn":2.0,"spf":"NaN","id":40410470},{"spn":1.91,"spf":"NaN","id":40310161}],"con":true,"img":false}]}
{"op":"mcm","clk":"5348014868","pt":1646212458581,"mc":[{"id":"1.195453620","rc":[{"atb":[[1.44,80.53],[1.37,270.27]],"id":40410470}],"con":true,"img":false}]}
{"op":"mcm","clk":"5348014876","pt":1646212458684,"mc":[{"id":"1.195453620","rc":[{"atb":[[1.43,0],[1.37,0],[1.45,135.16]],"id":40410470}],"con":true,"img":false}]}
{"op":"mcm","clk":"5348016575","pt":1646212493305,"mc":[{"id":"1.195453620","rc":[{"atb":[[1.44,0]],"id":40410470},{"atl":[[29,2.59]],"id":37208007}],"con":true,"img":false}]}
{"op":"mcm","clk":"5348016583","pt":1646212493418,"mc":[{"id":"1.195453620","rc":[{"atb":[[1.46,80.53],[1.45,0],[1.37,270.27]],"id":40410470},{"atl":[[32,2.72]],"id":37208007}],"con":true,"img":false}]}
{"op":"mcm","clk":"5348017512","pt":1646212510070,"mc":[{"id":"1.195453620","rc":[{"atb":[[1.46,0]],"id":40410470}],"con":true,"img":false}]}
{"op":"mcm","clk":"5348017521","pt":1646212510173,"mc":[{"id":"1.195453620","rc":[{"atb":[[1.39,80.53]],"id":40410470}],"con":true,"img":false}]}
{"op":"mcm","clk":"5348018494","pt":1646212528256,"mc":[{"id":"1.195453620","rc":[{"atb":[[1.4,135.16],[1.37,0]],"id":40410470},{"spn":1.99,"spf":"NaN","id":40410470}],"con":true,"img":false}]}
{"op":"mcm","clk":"5348018561","pt":1646212529500,"mc":[{"id":"1.195453620","rc":[{"atl":[[48,0]],"id":39791282}],"con":true,"img":false}]}
{"op":"mcm","clk":"5348018568","pt":1646212529596,"mc":[{"id":"1.195453620","rc":[{"atl":[[50,2.72]],"id":39791282}],"con":true,"img":false}]}
{"op":"mcm","clk":"5348019154","pt":1646212541878,"mc":[{"id":"1.195453620","rc":[{"atl":[[32,0]],"id":37208007}],"con":true,"img":false}]}
{"op":"mcm","clk":"5348019162","pt":1646212541984,"mc":[{"id":"1.195453620","rc":[{"atl":[[30,2.72]],"id":37208007}],"con":true,"img":false}]}
{"op":"mcm","clk":"5348019841","pt":1646212557237,"mc":[{"id":"1.195453620","rc":[{"atb":[[1.39,0]],"id":40410470}],"con":true,"img":false}]}
{"op":"mcm","clk":"5348019850","pt":1646212557343,"mc":[{"id":"1.195453620","rc":[{"atb":[[1.41,80.53]],"id":40410470}],"con":true,"img":false}]}
{"op":"mcm","clk":"5348019858","pt":1646212557437,"mc":[{"id":"1.195453620","rc":[{"atb":[[1.4,0],[1.37,270.27]],"id":40410470}],"con":true,"img":false}]}
{"op":"mcm","clk":"5348021348","pt":1646212586743,"mc":[{"id":"1.195453620","rc":[{"atl":[[30,0]],"id":37208007}],"con":true,"img":false}]}
{"op":"mcm","clk":"5348021355","pt":1646212586847,"mc":[{"id":"1.195453620","rc":[{"atl":[[29,5.31]],"id":37208007}],"con":true,"img":false}]}
{"op":"mcm","clk":"5348021615","pt":1646212591690,"mc":[{"id":"1.195453620","rc":[{"atb":[[1.37,0],[1.42,135.16]],"id":40410470},{"spn":2.0,"spf":"NaN","id":40410470}],"con":true,"img":false}]}
{"op":"mcm","clk":"5348023736","pt":1646212626603,"mc":[{"id":"1.195453620","rc":[{"atb":[[1.41,0]],"id":40410470}],"con":true,"img":false}]}
{"op":"mcm","clk":"5348023744","pt":1646212626707,"mc":[{"id":"1.195453620","rc":[{"atb":[[1.43,80.53],[1.37,270.27],[1.42,0]],"id":40410470}],"con":true,"img":false}]}
{"op":"mcm","clk":"5348025360","pt":1646212654079,"mc":[{"id":"1.195453620","rc":[{"spn":2.0,"spf":"NaN","id":40410470},{"atb":[[1.26,0],[1.23,184.54]],"id":40310161}],"con":true,"img":false}]}
{"op":"mcm","clk":"5348025707","pt":1646212660166,"mc":[{"id":"1.195453620","rc":[{"atb":[[1.44,135.16],[1.37,0]],"id":40410470}],"con":true,"img":false}]}
{"op":"mcm","clk":"5348027602","pt":1646212695727,"mc":[{"id":"1.195453620","rc":[{"atb":[[1.43,0]],"id":40410470}],"con":true,"img":false}]}
{"op":"mcm","clk":"5348027606","pt":1646212695830,"mc":[{"id":"1.195453620","rc":[{"atb":[[1.45,80.53]],"id":40410470}],"con":true,"img":false}]}
{"op":"mcm","clk":"5348027611","pt":1646212695931,"mc":[{"id":"1.195453620","rc":[{"atb":[[1.44,0],[1.37,270.27]],"id":40410470}],"con":true,"img":false}]}
{"op":"mcm","clk":"5348028833","pt":1646212719343,"mc":[{"id":"1.195453620","rc":[{"atb":[[1.45,0]],"id":40410470},{"spn":1.97,"spf":"NaN","id":40410470}],"con":true,"img":false}]}
{"op":"mcm","clk":"5348028840","pt":1646212719506,"mc":[{"id":"1.195453620","rc":[{"atb":[[1.39,80.53]],"id":40410470}],"con":true,"img":false}]}
{"op":"mcm","clk":"5348029334","pt":1646212728797,"mc":[{"id":"1.195453620","rc":[{"atb":[[1.4,135.16],[1.37,0]],"id":40410470}],"con":true,"img":false}]}
{"op":"mcm","clk":"5348030693","pt":1646212754828,"mc":[{"id":"1.195453620","rc":[{"atl":[[3.95,0],[3.8,26.4]],"id":28447693},{"atb":[[2.4,0],[2.58,57.04]],"id":39791282},{"atl":[[3.6,38.46],[3.85,0]],"id":40310161},{"atb":[[3.55,39.22],[3.3,0]],"id":41574727}],"con":true,"img":false}]}
{"op":"mcm","clk":"5348030888","pt":1646212759223,"mc":[{"id":"1.195453620","rc":[{"atb":[[1.39,0]],"id":40410470},{"atl":[[29,2.59]],"id":37208007}],"con":true,"img":false}]}
{"op":"mcm","clk":"5348030897","pt":1646212759327,"mc":[{"id":"1.195453620","rc":[{"atb":[[1.41,80.53]],"id":40410470},{"atl":[[32,2.72]],"id":37208007}],"con":true,"img":false}]}
{"op":"mcm","clk":"5348030899","pt":1646212759429,"mc":[{"id":"1.195453620","rc":[{"atb":[[1.4,0],[1.37,270.27]],"id":40410470}],"con":true,"img":false}]}
{"op":"mcm","clk":"5348031627","pt":1646212773533,"mc":[{"id":"1.195453620","rc":[{"atb":[[1.23,0]],"id":40310161},{"atl":[[2.72,0]],"id":40310161}],"con":true,"img":false}]}
{"op":"mcm","clk":"5348031634","pt":1646212773634,"mc":[{"id":"1.195453620","rc":[{"atb":[[1.22,184.54]],"id":40310161},{"atl":[[2.92,25.06]],"id":40310161}],"con":true,"img":false}]}
{"op":"mcm","clk":"5348032322","pt":1646212786143,"mc":[{"id":"1.195453620","rc":[{"spn":1.99,"spf":"NaN","id":40410470},{"atl":[[3.9,0]],"id":28447693},{"atb":[[1.11,0]],"id":37496564},{"spn":1.15,"spf":1.0,"id":37496564}],"con":true,"img":false}]}
{"op":"mcm","clk":"5348032329","pt":1646212786251,"mc":[{"id":"1.195453620","rc":[{"atl":[[3.75,26.02]],"id":28447693},{"atb":[[1.12,101.58]],"id":37496564}],"con":true,"img":false}]}
{"op":"mcm","clk":"5348032640","pt":1646212791537,"mc":[{"id":"1.195453620","rc":[{"atb":[[1.42,135.16]],"id":40410470}],"con":true,"img":false}]}
{"op":"mcm","clk":"5348032645","pt":1646212791633,"mc":[{"id":"1.195453620","rc":[{"atb":[[1.37,0]],"id":40410470}],"con":true,"img":false}]}
{"op":"mcm","clk":"5348032819","pt":1646212794748,"mc":[{"id":"1.195453620","rc":[{"atl":[[3.8,0],[3.75,52.04]],"id":28447693}],"con":true,"img":false}]}
{"op":"mcm","clk":"5348032996","pt":1646212797965,"mc":[{"id":"1.195453620","rc":[{"atl":[[2.58,0]],"id":40410470},{"atl":[[2.52,0]],"id":40310161}],"con":true,"img":false}]}
{"op":"mcm","clk":"5348033003","pt":1646212798060,"mc":[{"id":"1.195453620","rc":[{"atl":[[2.78,24.49]],"id":40410470},{"atl":[[2.72,25.34]],"id":40310161}],"con":true,"img":false}]}
{"op":"mcm","clk":"5348033952","pt":1646212817393,"mc":[{"id":"1.195453620","rc":[{"atb":[[1.09,0],[1.1,372.4]],"id":37496564}],"con":true,"img":false}]}
{"op":"mcm","clk":"5348034720","pt":1646212829209,"mc":[{"id":"1.195453620","rc":[{"atb":[[1.41,0]],"id":40410470},{"atl":[[3.75,39.21]],"id":28447693},{"atl":[[2.92,0]],"id":40310161}],"con":true,"img":false}]}
{"op":"mcm","clk":"5348034731","pt":1646212829315,"mc":[{"id":"1.195453620","rc":[{"atb":[[1.43,80.53],[1.37,270.27],[1.42,0]],"id":40410470},{"atl":[[3.7,12.82]],"id":28447693},{"atl":[[2.72,50.41]],"id":40310161}],"con":true,"img":false}]}
{"op":"mcm","clk":"5348035254","pt":1646212837425,"mc":[{"id":"1.195453620","rc":[{"atl":[[32,0]],"id":37208007}],"con":true,"img":false}]}
{"op":"mcm","clk":"5348035261","pt":1646212837527,"mc":[{"id":"1.195453620","rc":[{"atl":[[30,2.72]],"id":37208007}],"con":true,"img":false}]}
{"op":"mcm","clk":"5348035934","pt":1646212848331,"mc":[{"id":"1.195453620","rc":[{"spn":2.01,"spf":"NaN","id":40410470},{"spn":1.17,"spf":1.0,"id":37496564},{"atb":[[5.7,0]],"id":39791282},{"atl":[[44,0],[50,0]],"id":39791282},{"spn":10.35,"spf":"NaN","id":39791282},{"atb":[[4.5,0]],"id":37208007},{"spn":9.3,"spf":"NaN","id":37208007},{"spn":1.92,"spf":"NaN","id":40310161}],"con":true,"img":false}]}
{"op":"mcm","clk":"5348035939","pt":1646212848424,"mc":[{"id":"1.195453620","rc":[{"atb":[[6,9.68]],"id":39791282},{"atl":[[50,2.72],[55,2.72]],"id":39791282},{"atb":[[4.7,13.21]],"id":37208007}],"con":true,"img":false}]}
{"op":"mcm","clk":"5348036588","pt":1646212860735,"mc":[{"id":"1.195453620","rc":[{"atb":[[1.44,135.16],[1.37,0]],"id":40410470}],"con":true,"img":false}]}
{"op":"mcm","clk":"5348036781","pt":1646212863440,"mc":[{"id":"1.195453620","rc":[{"atb":[[1.12,0],[1.1,0]],"id":37496564},{"atb":[[6,0]],"id":39791282},{"atb":[[5.6,0]],"id":41574727}],"con":true,"img":false}]}
{"op":"mcm","clk":"5348036784","pt":1646212863532,"mc":[{"id":"1.195453620","rc":[{"atb":[[1.09,372.4],[1.1,101.58],[1.08,0],[1.04,2500]],"id":37496564},{"atb":[[5.7,9.68]],"id":39791282},{"atb":[[5.1,9.08]],"id":41574727}],"con":true,"img":false}]}
{"op":"mcm","clk":"5348036915","pt":1646212865650,"mc":[{"id":"1.195453620","rc":[{"atl":[[30,0]],"id":37208007}],"con":true,"img":false}]}
{"op":"mcm","clk":"5348036923","pt":1646212865757,"mc":[{"id":"1.195453620","rc":[{"atl":[[29,5.31]],"id":37208007}],"con":true,"img":false}]}
{"op":"mcm","clk":"5348038239","pt":1646212889083,"mc":[{"id":"1.195453620","rc":[{"atb":[[1.32,85.42]],"id":40310161}],"con":true,"img":false}]}
{"op":"mcm","clk":"5348038245","pt":1646212889182,"mc":[{"id":"1.195453620","rc":[{"atb":[[1.22,0]],"id":40310161}],"con":true,"img":false}]}
{"op":"mcm","clk":"5348038252","pt":1646212889287,"mc":[{"id":"1.195453620","rc":[{"atb":[[1.33,303.03],[1.31,0]],"id":40310161}],"con":true,"img":false}]}
{"op":"mcm","clk":"5348038460","pt":1646212893211,"mc":[{"id":"1.195453620","rc":[{"atl":[[3.8,35.71],[3.75,13.19]],"id":28447693},{"atb":[[1.33,0],[1.32,397.92]],"id":40310161}],"con":true,"img":false}]}
{"op":"mcm","clk":"5348038482","pt":1646212893576,"mc":[{"id":"1.195453620","rc":[{"atb":[[1.43,0]],"id":40410470}],"con":true,"img":false}]}
{"op":"mcm","clk":"5348038491","pt":1646212893682,"mc":[{"id":"1.195453620","rc":[{"atb":[[1.45,80.53]],"id":40410470}],"con":true,"img":false}]}
{"op":"mcm","clk":"5348038503","pt":1646212893892,"mc":[{"id":"1.195453620","rc":[{"atb":[[1.46,135.16],[1.44,0]],"id":40410470}],"con":true,"img":false}]}
{"op":"mcm","clk":"5348038556","pt":1646212894667,"mc":[{"id":"1.195453620","rc":[{"atb":[[1.08,1250],[1.04,0]],"id":37496564}],"con":true,"img":false}]}
{"op":"mcm","clk":"5348039569","pt":1646212913924,"mc":[{"id":"1.195453620","rc":[{"spn":2.03,"spf":"NaN","id":40410470},{"atl":[[3.7,0]],"id":28447693},{"spn":1.16,"spf":1.0,"id":37496564},{"spn":10.85,"spf":"NaN","id":39791282},{"spn":9.6,"spf":"NaN","id":37208007},{"atb":[[1.32,312.5]],"id":40310161},{"spn":1.93,"spf":"NaN","id":40310161},{"spn":12.0,"spf":"NaN","id":41574727}],"con":true,"img":false}]}
{"op":"mcm","clk":"5348039574","pt":1646212914015,"mc":[{"id":"1.195453620","rc":[{"atl":[[3.75,26.02]],"id":28447693},{"atb":[[1.31,85.42]],"id":40310161}],"con":true,"img":false}]}
{"op":"mcm","clk":"5348039580","pt":1646212914119,"mc":[{"id":"1.195453620","rc":[{"atb":[[1.32,0],[1.31,408]],"id":40310161}],"con":true,"img":false}]}
{"op":"mcm","clk":"5348039681","pt":1646212916031,"mc":[{"id":"1.195453620","rc":[{"atb":[[1.08,0],[1.07,1428.57]],"id":37496564}],"con":true,"img":false}]}
{"op":"mcm","clk":"5348040103","pt":1646212924050,"mc":[{"id":"1.195453620","rc":[{"atl":[[3.8,0],[3.75,52.04]],"id":28447693}],"con":true,"img":false}]}
{"op":"mcm","clk":"5348040108","pt":1646212924154,"mc":[{"id":"1.195453620","rc":[{"atl":[[4.4,29.41]],"id":28447693}],"con":true,"img":false}]}
{"op":"mcm","clk":"5348040115","pt":1646212924204,"mc":[{"id":"1.195453620","rc":[{"atl":[[3.75,26.02]],"id":28447693}],"con":true,"img":false}]}
{"op":"mcm","clk":"5348040165","pt":1646212925236,"mc":[{"id":"1.195453620","rc":[{"atl":[[3.75,13.19]],"id":28447693},{"atb":[[5.7,0]],"id":39791282},{"atb":[[1.21,0],[1.26,165.67]],"id":40310161}],"con":true,"img":false}]}
{"op":"mcm","clk":"5348040169","pt":1646212925338,"mc":[{"id":"1.195453620","rc":[{"atl":[[4.3,12.82],[3.75,33.93]],"id":28447693},{"atb":[[5.9,9.68]],"id":39791282}],"con":true,"img":false}]}
{"op":"mcm","clk":"5348040177","pt":1646212925442,"mc":[{"id":"1.195453620","rc":[{"atl":[[4.4,0]],"id":28447693}],"con":true,"img":false}]}
{"op":"mcm","clk":"5348040592","pt":1646212933458,"mc":[{"id":"1.195453620","rc":[{"atb":[[1.45,0]],"id":40410470}],"con":true,"img":false}]}
{"op":"mcm","clk":"5348040600","pt":1646212933561,"mc":[{"id":"1.195453620","rc":[{"atb":[[1.47,80.53]],"id":40410470}],"con":true,"img":false}]}
{"op":"mcm","clk":"5348040606","pt":1646212933663,"mc":[{"id":"1.195453620","rc":[{"atb":[[1.46,0],[1.37,270.27]],"id":40410470}],"con":true,"img":false}]}
{"op":"mcm","clk":"5348040613","pt":1646212933768,"mc":[{"id":"1.195453620","rc":[{"atb":[[1.37,0],[1.48,135.16]],"id":40410470}],"con":true,"img":false}]}
{"op":"mcm","clk":"5348041131","pt":1646212943644,"mc":[{"id":"1.195453620","rc":[{"atb":[[1.31,322.58]],"id":40310161},{"atb":[[5.1,0]],"id":41574727}],"con":true,"img":false}]}
{"op":"mcm","clk":"5348041136","pt":1646212943749,"mc":[{"id":"1.195453620","rc":[{"atb":[[1.32,85.42]],"id":40310161},{"atb":[[5.6,9.08]],"id":41574727}],"con":true,"img":false}]}
{"op":"mcm","clk":"5348041144","pt":1646212943852,"mc":[{"id":"1.195453620","rc":[{"atb":[[1.33,303.03]],"id":40310161}],"con":true,"img":false}]}
{"op":"mcm","clk":"5348041149","pt":1646212943955,"mc":[{"id":"1.195453620","rc":[{"atb":[[1.31,0]],"id":40310161}],"con":true,"img":false}]}
{"op":"mcm","clk":"5348041287","pt":1646212946581,"mc":[{"id":"1.195453620","rc":[{"atb":[[1.08,1250]],"id":37496564}],"con":true,"img":false}]}
{"op":"mcm","clk":"5348041293","pt":1646212946633,"mc":[{"id":"1.195453620","rc":[{"atb":[[1.07,0]],"id":37496564}],"con":true,"img":false}]}
{"op":"mcm","clk":"5348041651","pt":1646212952764,"mc":[{"id":"1.195453620","rc":[{"atb":[[1.21,204.91]],"id":40310161}],"con":true,"img":false}]}
{"op":"mcm","clk":"5348041655","pt":1646212952868,"mc":[{"id":"1.195453620","rc":[{"atb":[[1.26,0]],"id":40310161}],"con":true,"img":false}]}
{"op":"mcm","clk":"5348041668","pt":1646212953178,"mc":[{"id":"1.195453620","rc":[{"atl":[[4,0],[3.65,37.74]],"id":40410470},{"atb":[[1.08,0],[1.07,1428.57]],"id":37496564},{"atl":[[5.7,21.28]],"id":42464658},{"atl":[[3.6,0],[3.3,43.48]],"id":40310161},{"atl":[[25,4.17],[30,0]],"id":41574727}],"con":true,"img":false}]}
{"op":"mcm","clk":"5348041672","pt":1646212953280,"mc":[{"id":"1.195453620","rc":[{"atl":[[6.6,0]],"id":42464658}],"con":true,"img":false}]}
{"op":"mcm","clk":"5348041876","pt":1646212956783,"mc":[{"id":"1.195453620","rc":[{"atb":[[1.32,0]],"id":40310161}],"con":true,"img":false}]}
{"op":"mcm","clk":"5348041879","pt":1646212956883,"mc":[{"id":"1.195453620","rc":[{"atb":[[1.27,85.42],[1.31,322.58]],"id":40310161}],"con":true,"img":false}]}
{"op":"mcm","clk":"5348041886","pt":1646212956987,"mc":[{"id":"1.195453620","rc":[{"atb":[[1.33,0]],"id":40310161}],"con":true,"img":false}]}
{"op":"mcm","clk":"5348042151","pt":1646212962899,"mc":[{"id":"1.195453620","rc":[{"atl":[[4.3,0]],"id":28447693},{"atl":[[2.72,25.06]],"id":40310161}],"con":true,"img":false}]}
{"op":"mcm","clk":"5348042155","pt":1646212963001,"mc":[{"id":"1.195453620","rc":[{"atl":[[3.7,12.82]],"id":28447693},{"atl":[[2.52,25.34]],"id":40310161}],"con":true,"img":false}]}
{"op":"mcm","clk":"5348042169","pt":1646212963209,"mc":[{"id":"1.195453620","rc":[{"atl":[[3.75,13.19],[3.65,20.74]],"id":28447693}],"con":true,"img":false}]}
{"op":"mcm","clk":"5348042448","pt":1646212968383,"mc":[{"id":"1.195453620","rc":[{"atb":[[4.6,0]],"id":41574727}],"con":true,"img":false}]}
{"op":"mcm","clk":"5348042453","pt":1646212968486,"mc":[{"id":"1.195453620","rc":[{"atb":[[4.1,11.98]],"id":41574727}],"con":true,"img":false}]}
{"op":"mcm","clk":"5348042720","pt":1646212972820,"mc":[{"id":"1.195453620","rc":[{"atb":[[1.47,0]],"id":40410470}],"con":true,"img":false}]}
{"op":"mcm","clk":"5348042723","pt":1646212972874,"mc":[{"id":"1.195453620","rc":[{"atb":[[1.49,80.53]],"id":40410470}],"con":true,"img":false}]}
{"op":"mcm","clk":"5348042727","pt":1646212972976,"mc":[{"id":"1.195453620","rc":[{"atb":[[1.37,270.27],[1.48,0]],"id":40410470}],"con":true,"img":false}]}
{"op":"mcm","clk":"5348042743","pt":1646212973289,"mc":[{"id":"1.195453620","rc":[{"atb":[[1.25,0],[1.3,0],[1.35,0]],"id":40410470},{"atl":[[2.8,0],[3,0],[2.6,0]],"id":40410470},{"atb":[[1.8,0],[1.85,0],[1.75,0]],"id":28447693},{"atl":[[4.5,0],[5.5,0],[3.75,0]],"id":28447693},{"atb":[[1.01,0],[1.03,0]],"id":37496564},{"atl":[[2,0],[2.4,0],[2.2,0]],"id":37496564},{"atb":[[1.6,0],[1.55,0],[1.65,0]],"id":42464658},{"atl":[[3.45,0],[3.95,0],[2.98,0]],"id":42464658},{"atb":[[4.1,0],[3.8,0],[3.55,0]],"id":37208007},{"atl":[[19.5,0],[14.5,0],[29,2.72]],"id":37208007},{"atb":[[4.5,0],[5,0],[5.5,0]],"id":41574727},{"atl":[[18.5,0],[44,0],[27,0]],"id":41574727}],"con":true,"img":false}]}
{"op":"mcm","clk":"5348042751","pt":1646212973394,"mc":[{"id":"1.195453620","rc":[{"atl":[[36,0],[29,5.44]],"id":37208007}],"con":true,"img":false}]}
{"op":"mcm","clk":"5348042823","pt":1646212974689,"mc":[{"id":"1.195453620","rc":[{"atl":[[2.78,0]],"id":40410470},{"spn":2.47,"spf":"NaN","id":40410470},{"atb":[[1.86,0]],"id":28447693},{"spn":1.55,"spf":1.0,"id":28447693},{"atl":[[1.99,0]],"id":37496564},{"atb":[[1.66,0]],"id":42464658},{"atl":[[4.5,10.48],[3.4,0]],"id":42464658},{"spn":2.66,"spf":"NaN","id":42464658},{"spn":10.95,"spf":"NaN","id":39791282},{"atl":[[34,0],[29,2.72]],"id":37208007},{"spn":16.85,"spf":"NaN","id":37208007},{"atb":[[1.27,0]],"id":40310161},{"spn":1.91,"spf":"NaN","id":40310161},{"atb":[[5.6,0]],"id":41574727},{"spn":13.55,"spf":"NaN","id":41574727}],"con":true,"img":false}]}
{"op":"mcm","clk":"5348042826","pt":1646212974786,"mc":[{"id":"1.195453620","rc":[{"atl":[[3.15,24.49]],"id":40410470},{"atb":[[1.46,0],[1.5,200],[1.69,65.07]],"id":28447693},{"atl":[[2.14,31.56]],"id":37496564},{"atb":[[1.55,71.47]],"id":42464658},{"atl":[[3.95,18.16],[3.9,0]],"id":42464658},{"atl":[[32,2.72],[38,2.72]],"id":37208007},{"atb":[[1.26,85.42]],"id":40310161},{"atb":[[4.8,9.08]],"id":41574727}],"con":true,"img":false}]}
{"op":"mcm","clk":"5348042831","pt":1646212974891,"mc":[{"id":"1.195453620","rc":[{"atl":[[3.7,0]],"id":28447693}],"con":true,"img":false}]}
{"op":"mcm","clk":"5348042835","pt":1646212974994,"mc":[{"id":"1.195453620","rc":[{"atl":[[5.2,23.81],[4.7,12.82]],"id":28447693}],"con":true,"img":false}]}
{"op":"mcm","clk":"5348042839","pt":1646212975096,"mc":[{"id":"1.195453620","rc":[{"atl":[[3.65,0]],"id":28447693}],"con":true,"img":false}]}
{"op":"mcm","clk":"5348043033","pt":1646212978608,"mc":[{"id":"1.195453620","rc":[{"atl":[[32,5.95],[29,0]],"id":37208007}],"con":true,"img":false}]}
{"op":"mcm","clk":"5348043121","pt":1646212980416,"mc":[{"id":"1.195453620","rc":[{"atb":[[4.7,0]],"id":37208007}],"con":true,"img":false}]}
{"op":"mcm","clk":"5348043125","pt":1646212980521,"mc":[{"id":"1.195453620","rc":[{"atb":[[4.8,13.21]],"id":37208007}],"con":true,"img":false}]}
{"op":"mcm","clk":"5348043277","pt":1646212983418,"mc":[{"id":"1.195453620","rc":[{"atb":[[1.07,0],[1.08,1250]],"id":37496564}],"con":true,"img":false}]}
{"op":"mcm","clk":"5348043280","pt":1646212983520,"mc":[{"id":"1.195453620","rc":[{"atb":[[1.41,114.73]],"id":40410470}],"con":true,"img":false}]}
{"op":"mcm","clk":"5348043284","pt":1646212983626,"mc":[{"id":"1.195453620","rc":[{"atb":[[1.49,0]],"id":40410470}],"con":true,"img":false}]}
{"op":"mcm","clk":"5348043367","pt":1646212985357,"mc":[{"id":"1.195453620","rc":[{"atb":[[1.4,249.53],[1.3,332.71],[1.35,285.18]],"id":40410470},{"atl":[[2.86,39.02],[2.66,21.86],[3.15,58.25]],"id":40410470},{"atb":[[1.8,124.76],[1.85,117.42],[1.75,133.08]],"id":28447693},{"atl":[[4.5,20.74],[5.5,16.13],[3.75,13.19]],"id":28447693},{"atb":[[1.01,29944.41]],"id":37496564},{"atl":[[2.36,53.37],[1.98,37.03],[2.16,62.58]],"id":37496564},{"atb":[[1.6,166.35],[1.55,252.95],[1.65,153.56]],"id":42464658},{"atl":[[3.45,29.63],[3.95,42.77],[2.98,18.33]],"id":42464658},{"atb":[[4,33.27],[4.5,28.51],[3.75,36.29]],"id":37208007},{"atl":[[16,2.41],[34,2.2],[22,3.45]],"id":37208007},{"atb":[[4.5,28.51],[5,24.95],[5.5,22.18]],"id":41574727},{"atl":[[18.5,2.07],[44,1.68],[27,2.79]],"id":41574727}],"con":true,"img":false}]}
{"op":"mcm","clk":"5348044071","pt":1646212998538,"mc":[{"id":"1.195453620","rc":[{"atb":[[5.9,0]],"id":39791282}],"con":true,"img":false}]}
{"op":"mcm","clk":"5348044078","pt":1646212998642,"mc":[{"id":"1.195453620","rc":[{"atb":[[5.5,9.68]],"id":39791282}],"con":true,"img":false}]}
{"op":"mcm","clk":"5348044294","pt":1646213002922,"mc":[{"id":"1.195453620","rc":[{"atl":[[32,3.23]],"id":37208007},{"atl":[[2.52,0]],"id":40310161}],"con":true,"img":false}]}
{"op":"mcm","clk":"5348044300","pt":1646213003026,"mc":[{"id":"1.195453620","rc":[{"atb":[[1.37,0],[1.42,238.1]],"id":40410470},{"atl":[[22,6.18]],"id":37208007},{"atl":[[2.72,50.41]],"id":40310161}],"con":true,"img":false}]}
{"op":"mcm","clk":"5348044409","pt":1646213005045,"mc":[{"id":"1.195453620","rc":[{"atl":[[3.7,13.2],[5.2,0]],"id":28447693}],"con":true,"img":false}]}
{"op":"mcm","clk":"5348045098","pt":1646213016850,"mc":[{"id":"1.195453620","rc":[{"atl":[[4,33.33],[3.65,0]],"id":40410470},{"atl":[[3.7,0],[3.8,26.4]],"id":28447693},{"atl":[[3.3,0],[3.65,37.74]],"id":40310161}],"con":true,"img":false}]}
{"op":"mcm","clk":"5348045289","pt":1646213019550,"mc":[{"id":"1.195453620","rc":[{"atl":[[3.15,33.76]],"id":40410470},{"atl":[[4.7,0]],"id":28447693},{"atl":[[3.95,24.6]],"id":42464658},{"atl":[[26,0]],"id":41574727}],"con":true,"img":false}]}
{"op":"mcm","clk":"5348045295","pt":1646213019655,"mc":[{"id":"1.195453620","rc":[{"atl":[[2.84,24.49]],"id":40410470},{"atl":[[4.4,12.82]],"id":28447693},{"atl":[[3.4,18.16]],"id":42464658},{"atl":[[24,2.72]],"id":41574727}],"con":true,"img":false}]}
{"op":"mcm","clk":"5348045532","pt":1646213023861,"mc":[{"id":"1.195453620","rc":[{"atb":[[1.69,0]],"id":28447693},{"atb":[[1.55,181.48]],"id":42464658}],"con":true,"img":false}]}
{"op":"mcm","clk":"5348045540","pt":1646213023965,"mc":[{"id":"1.195453620","rc":[{"atb":[[1.86,65.07]],"id":28447693},{"atb":[[1.66,71.47]],"id":42464658}],"con":true,"img":false}]}
{"op":"mcm","clk":"5348045779","pt":1646213028555,"mc":[{"id":"1.195453620","rc":[{"atb":[[1.41,216.64]],"id":40410470}],"con":true,"img":false}]}
{"op":"mcm","clk":"5348045785","pt":1646213028661,"mc":[{"id":"1.195453620","rc":[{"atb":[[1.36,0]],"id":40410470}],"con":true,"img":false}]}
{"op":"mcm","clk":"5348046196","pt":1646213035969,"mc":[{"id":"1.195453620","rc":[{"atb":[[1.41,101.91]],"id":40410470},{"spn":2.04,"spf":"NaN","id":40410470},{"spn":1.86,"spf":1.0,"id":28447693},{"spn":2.32,"spf":"NaN","id":42464658},{"spn":10.75,"spf":"NaN","id":39791282},{"spn":10.4,"spf":"NaN","id":37208007},{"spn":1.92,"spf":"NaN","id":40310161},{"atb":[[4.8,0]],"id":41574727},{"spn":12.0,"spf":"NaN","id":41574727}],"con":true,"img":false}]}
{"op":"mcm","clk":"5348046200","pt":1646213036073,"mc":[{"id":"1.195453620","rc":[{"atb":[[1.43,114.73]],"id":40410470},{"atb":[[5.1,9.08]],"id":41574727}],"con":true,"img":false}]}
{"op":"mcm","clk":"5348046205","pt":1646213036279,"mc":[{"id":"1.195453620","rc":[{"atb":[[1.44,114.74],[1.42,0]],"id":40410470}],"con":true,"img":false}]}
{"op":"mcm","clk":"5348046477","pt":1646213040576,"mc":[{"id":"1.195453620","rc":[{"atb":[[3.85,0]],"id":37208007}],"con":true,"img":false}]}
{"op":"mcm","clk":"5348046483","pt":1646213040681,"mc":[{"id":"1.195453620","rc":[{"atb":[[4.1,12.81]],"id":37208007}],"con":true,"img":false}]}
{"op":"mcm","clk":"5348046888","pt":1646213047393,"mc":[{"id":"1.195453620","rc":[{"atl":[[4.4,0]],"id":28447693},{"atl":[[1.97,38.39],[2.14,0]],"id":37496564},{"atb":[[1.56,65.52],[1.42,0]],"id":42464658},{"atl":[[4.5,0],[3.9,12.65]],"id":42464658},{"atl":[[38,0]],"id":37208007}],"con":true,"img":false}]}
{"op":"mcm","clk":"5348046892","pt":1646213047496,"mc":[{"id":"1.195453620","rc":[{"atl":[[3.75,26.02]],"id":28447693},{"atl":[[21,2.72]],"id":37208007}],"con":true,"img":false}]}
{"op":"mcm","clk":"5348047595","pt":1646213060775,"mc":[{"id":"1.195453620","rc":[{"atb":[[5.5,0]],"id":39791282}],"con":true,"img":false}]}
{"op":"mcm","clk":"5348047599","pt":1646213060879,"mc":[{"id":"1.195453620","rc":[{"atb":[[5.6,9.68]],"id":39791282}],"con":true,"img":false}]}
{"op":"mcm","clk":"5348048070","pt":1646213069302,"mc":[{"id":"1.195453620","rc":[{"atb":[[1.43,0],[1.45,77.76]],"id":40410470},{"atb":[[5.1,0]],"id":41574727}],"con":true,"img":false}]}
{"op":"mcm","clk":"5348048077","pt":1646213069406,"mc":[{"id":"1.195453620","rc":[{"atb":[[5.6,9.08]],"id":41574727}],"con":true,"img":false}]}
{"op":"mcm","clk":"5348048082","pt":1646213069504,"mc":[{"id":"1.195453620","rc":[{"atb":[[1.46,101.91],[1.44,0]],"id":40410470}],"con":true,"img":false}]}
{"op":"mcm","clk":"5348048285","pt":1646213073222,"mc":[{"id":"1.195453620","rc":[{"atl":[[3.95,33.9],[3.8,0]],"id":28447693},{"atb":[[2.4,61.79],[2.58,0]],"id":39791282},{"atl":[[5.7,0],[6.6,17.86]],"id":42464658}],"con":true,"img":false}]}
{"op":"mcm","clk":"5348048362","pt":1646213074720,"mc":[{"id":"1.195453620","rc":[{"atb":[[1.46,0],[1.45,281.58]],"id":40410470}],"con":true,"img":false}]}
{"op":"mcm","clk":"5348048570","pt":1646213077724,"mc":[{"id":"1.195453620","rc":[{"atb":[[1.08,0],[1.07,1428.57]],"id":37496564},{"atl":[[32,3.23]],"id":41574727}],"con":true,"img":false}]}
{"op":"mcm","clk":"5348048575","pt":1646213077828,"mc":[{"id":"1.195453620","rc":[{"atl":[[25,0]],"id":41574727}],"con":true,"img":false}]}
{"op":"mcm","clk":"5348048579","pt":1646213077929,"mc":[{"id":"1.195453620","rc":[{"atb":[[1.08,1250]],"id":37496564},{"atl":[[21,0]],"id":37208007}],"con":true,"img":false}]}
{"op":"mcm","clk":"5348048587","pt":1646213078033,"mc":[{"id":"1.195453620","rc":[{"atb":[[1.07,0]],"id":37496564},{"atl":[[26,2.72]],"id":37208007}],"con":true,"img":false}]}
{"op":"mcm","clk":"5348048795","pt":1646213081916,"mc":[{"id":"1.195453620","rc":[{"atl":[[24,0]],"id":41574727}],"con":true,"img":false}]}
{"op":"mcm","clk":"5348048799","pt":1646213082023,"mc":[{"id":"1.195453620","rc":[{"atl":[[26,2.72]],"id":41574727}],"con":true,"img":false}]}
{"op":"mcm","clk":"5348049254","pt":1646213090144,"mc":[{"id":"1.195453620","rc":[{"atl":[[3.75,13.19]],"id":28447693}],"con":true,"img":false}]}
{"op":"mcm","clk":"5348049260","pt":1646213090246,"mc":[{"id":"1.195453620","rc":[{"atl":[[3.9,12.82]],"id":28447693}],"con":true,"img":false}]}
{"op":"mcm","clk":"5348049927","pt":1646213102252,"mc":[{"id":"1.195453620","rc":[{"spn":2.05,"spf":"NaN","id":40410470},{"atl":[[3.95,0],[3.8,26.4]],"id":28447693},{"atb":[[2.4,0],[2.54,61.79]],"id":39791282},{"spn":10.8,"spf":"NaN","id":39791282},{"spn":12.05,"spf":"NaN","id":41574727}],"con":true,"img":false}]}
{"op":"mcm","clk":"5348051388","pt":1646213128092,"mc":[{"id":"1.195453620","rc":[{"atl":[[3.45,0]],"id":40410470},{"atl":[[2.72,25.06]],"id":40310161}],"con":true,"img":false}]}
{"op":"mcm","clk":"5348051393","pt":1646213128195,"mc":[{"id":"1.195453620","rc":[{"atl":[[3.1,16.89]],"id":40410470},{"atl":[[2.52,25.34]],"id":40310161}],"con":true,"img":false}]}
{"op":"mcm","clk":"5348051679","pt":1646213133202,"mc":[{"id":"1.195453620","rc":[{"atl":[[3.1,0]],"id":40410470},{"atl":[[3.9,0]],"id":28447693}],"con":true,"img":false}]}
{"op":"mcm","clk":"5348051686","pt":1646213133301,"mc":[{"id":"1.195453620","rc":[{"atl":[[3.6,16.89]],"id":40410470},{"atl":[[3.75,26.02]],"id":28447693}],"con":true,"img":false}]}
{"op":"mcm","clk":"5348051844","pt":1646213135619,"mc":[{"id":"1.195453620","rc":[{"atl":[[2.84,0]],"id":40410470},{"atb":[[4.1,0]],"id":41574727}],"con":true,"img":false}]}
{"op":"mcm","clk":"5348051850","pt":1646213135721,"mc":[{"id":"1.195453620","rc":[{"atl":[[2.64,24.49]],"id":40410470},{"atb":[[4.6,11.98]],"id":41574727}],"con":true,"img":false}]}
{"op":"mcm","clk":"5348052319","pt":1646213143116,"mc":[{"id":"1.195453620","rc":[{"atb":[[1.26,0]],"id":40310161}],"con":true,"img":false}]}
{"op":"mcm","clk":"5348052326","pt":1646213143222,"mc":[{"id":"1.195453620","rc":[{"atb":[[1.23,85.42]],"id":40310161}],"con":true,"img":false}]}
{"op":"mcm","clk":"5348053811","pt":1646213170952,"mc":[{"id":"1.195453620","rc":[{"spn":2.04,"spf":"NaN","id":40410470},{"atb":[[4.9,1.66]],"id":37208007},{"spn":10.45,"spf":"NaN","id":37208007},{"spn":1.91,"spf":"NaN","id":40310161}],"con":true,"img":false}]}
{"op":"mcm","clk":"5348054728","pt":1646213189155,"mc":[{"id":"1.195453620","rc":[{"atl":[[26,0]],"id":37208007}],"con":true,"img":false}]}
{"op":"mcm","clk":"5348054732","pt":1646213189307,"mc":[{"id":"1.195453620","rc":[{"atl":[[21,2.72]],"id":37208007}],"con":true,"img":false}]}
{"op":"mcm","clk":"5348054774","pt":1646213190132,"mc":[{"id":"1.195453620","marketDefinition":{"bspMarket":true,"turnInPlayEnabled":false,"persistenceEnabled":false,"marketBaseRate":7.0,"eventId":"31272494","eventTypeId":"4339","numberOfWinners":3,"bettingType":"ODDS","marketType":"PLACE","marketTime":"2022-03-02T10:11:00.000Z","suspendTime":"2022-03-02T10:11:00.000Z","bspReconciled":false,"complete":true,"inPlay":false,"crossMatching":true,"runnersVoidable":false,"numberOfActiveRunners":8,"betDelay":0,"status":"OPEN","runners":[{"status":"ACTIVE","sortPriority":1,"id":37208007,"name":"1. Alecia"},{"status":"ACTIVE","sortPriority":2,"id":37496564,"name":"2. Zachary"},{"status":"ACTIVE","sortPriority":3,"id":28447693,"name":"3. Ripplebrook Glen"},{"status":"ACTIVE","sortPriority":4,"id":42464658,"name":"4. Zipping Bronte"},{"status":"ACTIVE","sortPriority":5,"id":39791282,"name":"5. Shes Our Rocket"},{"status":"ACTIVE","sortPriority":6,"id":40310161,"name":"6. Lakeview Bonnie"},{"status":"ACTIVE","sortPriority":7,"id":40410470,"name":"8. Jet Like Rico"},{"status":"ACTIVE","sortPriority":8,"id":41574727,"name":"9. Center"}],"regulators":["MR_INT"],"venue":"Traralgon","countryCode":"AU","discountAllowed":true,"timezone":"Australia/Sydney","openDate":"2022-03-02T08:31:00.000Z","version":4382425365,"name":"To Be Placed","eventName":"Traralgon (AUS) 2nd Mar"},"rc":[],"con":true,"img":false}]}
{"op":"mcm","clk":"5348056927","pt":1646213227994,"mc":[{"id":"1.195453620","rc":[{"atb":[[2.54,0]],"id":39791282},{"atl":[[16,2.41]],"id":39791282},{"atb":[[1.31,0]],"id":40310161},{"atl":[[3.65,0]],"id":40310161},{"atb":[[3.55,0]],"id":41574727},{"atl":[[32,0]],"id":41574727}],"con":true,"img":false}]}
{"op":"mcm","clk":"5348056934","pt":1646213228105,"mc":[{"id":"1.195453620","rc":[{"atb":[[1.45,77.76]],"id":40410470},{"atl":[[4,0]],"id":40410470},{"atb":[[1.5,0]],"id":28447693},{"atl":[[3.8,0]],"id":28447693},{"atb":[[1.08,0]],"id":37496564},{"atl":[[2.98,0]],"id":37496564},{"atl":[[6.6,0]],"id":42464658},{"atb":[[3.15,0]],"id":37208007},{"atl":[[32,0]],"id":37208007}],"con":true,"img":false}]}
{"op":"mcm","clk":"5348056965","pt":1646213228729,"mc":[{"id":"1.195453620","rc":[{"atl":[[21,0]],"id":37208007}],"con":true,"img":false}]}
{"op":"mcm","clk":"5348056968","pt":1646213228834,"mc":[{"id":"1.195453620","rc":[{"atl":[[26,2.72]],"id":37208007}],"con":true,"img":false}]}
{"op":"mcm","clk":"5348057459","pt":1646213238514,"mc":[{"id":"1.195453620","rc":[{"atl":[[3.75,13.19]],"id":28447693},{"spn":1.91,"spf":"NaN","id":40310161}],"con":true,"img":false}]}
{"op":"mcm","clk":"5348057464","pt":1646213238617,"mc":[{"id":"1.195453620","rc":[{"atl":[[4.4,12.82]],"id":28447693}],"con":true,"img":false}]}
{"op":"mcm","clk":"5348058172","pt":1646213252735,"mc":[{"id":"1.195453620","rc":[{"atb":[[1.48,15.66]],"id":40410470},{"atb":[[1.9,8.35]],"id":28447693},{"atb":[[1.7,10.74]],"id":42464658}],"con":true,"img":false}]}
{"op":"mcm","clk":"5348058328","pt":1646213256060,"mc":[{"id":"1.195453620","rc":[{"atb":[[4.8,0]],"id":37208007}],"con":true,"img":false}]}
{"op":"mcm","clk":"5348058335","pt":1646213256164,"mc":[{"id":"1.195453620","rc":[{"atb":[[5,13.21]],"id":37208007}],"con":true,"img":false}]}
{"op":"mcm","clk":"5348058574","pt":1646213261552,"mc":[{"id":"1.195453620","rc":[{"atl":[[3.4,0]],"id":42464658}],"con":true,"img":false}]}
{"op":"mcm","clk":"5348058579","pt":1646213261654,"mc":[{"id":"1.195453620","rc":[{"atl":[[2.96,18.16]],"id":42464658}],"con":true,"img":false}]}
{"op":"mcm","clk":"5348058596","pt":1646213262068,"mc":[{"id":"1.195453620","rc":[{"atb":[[4.9,0]],"id":37208007}],"con":true,"img":false}]}
{"op":"mcm","clk":"5348058602","pt":1646213262171,"mc":[{"id":"1.195453620","rc":[{"atb":[[5.1,1.66]],"id":37208007}],"con":true,"img":false}]}
{"op":"mcm","clk":"5348059285","pt":1646213275278,"mc":[{"id":"1.195453620","rc":[{"atb":[[1.23,0]],"id":40310161}],"con":true,"img":false}]}
{"op":"mcm","clk":"5348059288","pt":1646213275382,"mc":[{"id":"1.195453620","rc":[{"atb":[[1.22,85.42]],"id":40310161}],"con":true,"img":false}]}
{"op":"mcm","clk":"5348059452","pt":1646213279392,"mc":[{"id":"1.195453620","rc":[{"atl":[[23,0]],"id":41574727}],"con":true,"img":false}]}
{"op":"mcm","clk":"5348059455","pt":1646213279444,"mc":[{"id":"1.195453620","rc":[{"atl":[[26,5.44]],"id":41574727}],"con":true,"img":false}]}
{"op":"mcm","clk":"5348059841","pt":1646213286769,"mc":[{"id":"1.195453620","rc":[{"atb":[[4.6,10.14],[4.1,0]],"id":37208007}],"con":true,"img":false}]}
{"op":"mcm","clk":"5348060097","pt":1646213292608,"mc":[{"id":"1.195453620","rc":[{"atl":[[4.4,0]],"id":28447693}],"con":true,"img":false}]}
{"op":"mcm","clk":"5348060099","pt":1646213292704,"mc":[{"id":"1.195453620","rc":[{"atl":[[3.7,12.82]],"id":28447693}],"con":true,"img":false}]}
{"op":"mcm","clk":"5348060254","pt":1646213296171,"mc":[{"id":"1.195453620","rc":[{"atl":[[26,0]],"id":37208007}],"con":true,"img":false}]}
{"op":"mcm","clk":"5348060259","pt":1646213296281,"mc":[{"id":"1.195453620","rc":[{"atl":[[28,2.72]],"id":37208007}],"con":true,"img":false}]}
{"op":"mcm","clk":"5348060476","pt":1646213300523,"mc":[{"id":"1.195453620","rc":[{"spn":2.06,"spf":"NaN","id":40410470},{"spn":1.9,"spf":1.0,"id":28447693},{"spn":2.33,"spf":"NaN","id":42464658},{"atl":[[22,3.45]],"id":37208007},{"spn":10.55,"spf":"NaN","id":37208007}],"con":true,"img":false}]}
{"op":"mcm","clk":"5348060480","pt":1646213300627,"mc":[{"id":"1.195453620","rc":[{"atl":[[25,2.72]],"id":37208007}],"con":true,"img":false}]}
{"op":"mcm","clk":"5348061212","pt":1646213314332,"mc":[{"id":"1.195453620","rc":[{"atl":[[3.6,0]],"id":40410470},{"atb":[[5.6,18.34],[4.6,0]],"id":41574727}],"con":true,"img":false}]}
{"op":"mcm","clk":"5348061220","pt":1646213314436,"mc":[{"id":"1.195453620","rc":[{"atl":[[3.1,16.89]],"id":40410470}],"con":true,"img":false}]}
{"op":"mcm","clk":"5348061364","pt":1646213317435,"mc":[{"id":"1.195453620","rc":[{"atl":[[26,2.72]],"id":41574727}],"con":true,"img":false}]}
{"op":"mcm","clk":"5348061371","pt":1646213317537,"mc":[{"id":"1.195453620","rc":[{"atl":[[30,2.72]],"id":41574727}],"con":true,"img":false}]}
{"op":"mcm","clk":"5348062183","pt":1646213332273,"mc":[{"id":"1.195453620","rc":[{"atb":[[5.6,9.26]],"id":41574727}],"con":true,"img":false}]}
{"op":"mcm","clk":"5348062187","pt":1646213332377,"mc":[{"id":"1.195453620","rc":[{"atb":[[6,9.08]],"id":41574727}],"con":true,"img":false}]}
{"op":"mcm","clk":"5348062368","pt":1646213335588,"mc":[{"id":"1.195453620","rc":[{"atb":[[1.56,0],[1.46,79.77]],"id":42464658}],"con":true,"img":false}]}
{"op":"mcm","clk":"5348062624","pt":1646213340292,"mc":[{"id":"1.195453620","rc":[{"atl":[[30,0]],"id":41574727}],"con":true,"img":false}]}
{"op":"mcm","clk":"5348062628","pt":1646213340389,"mc":[{"id":"1.195453620","rc":[{"atl":[[32,2.72]],"id":41574727}],"con":true,"img":false}]}
{"op":"mcm","clk":"5348063475","pt":1646213355684,"mc":[{"id":"1.195453620","rc":[{"atl":[[26,0]],"id":41574727}],"con":true,"img":false}]}
{"op":"mcm","clk":"5348063480","pt":1646213355787,"mc":[{"id":"1.195453620","rc":[{"atl":[[30,2.72]],"id":41574727}],"con":true,"img":false}]}
{"op":"mcm","clk":"5348063642","pt":1646213358787,"mc":[{"id":"1.195453620","rc":[{"atb":[[1.49,77.76]],"id":40410470},{"atl":[[4.2,31.25]],"id":40410470},{"atb":[[1.47,195.91]],"id":28447693},{"atl":[[3.65,13.2]],"id":28447693},{"atb":[[1.07,1428.57]],"id":37496564},{"atl":[[3.3,43.48]],"id":37496564},{"atl":[[5.9,20.41]],"id":42464658},{"atb":[[1.89,57.04]],"id":39791282},{"atl":[[16,4.83]],"id":39791282},{"atb":[[3.65,37.74]],"id":37208007},{"atl":[[36,2.86]],"id":37208007},{"atb":[[1.31,322.58]],"id":40310161},{"atl":[[2.98,50.51]],"id":40310161},{"atb":[[3.15,44.36]],"id":41574727},{"atl":[[29,3.57]],"id":41574727}],"con":true,"img":false}]}
{"op":"mcm","clk":"5348063718","pt":1646213360075,"mc":[{"id":"1.195453620","rc":[{"atb":[[5.6,0]],"id":41574727}],"con":true,"img":false}]}
{"op":"mcm","clk":"5348063725","pt":1646213360178,"mc":[{"id":"1.195453620","rc":[{"atb":[[5.1,9.26]],"id":41574727}],"con":true,"img":false}]}
{"op":"mcm","clk":"5348063785","pt":1646213361369,"mc":[{"id":"1.195453620","rc":[{"atb":[[1.48,0]],"id":40410470},{"spn":2.06,"spf":"NaN","id":40410470},{"spn":1.91,"spf":"NaN","id":40310161},{"spn":12.25,"spf":"NaN","id":41574727}],"con":true,"img":false}]}
{"op":"mcm","clk":"5348063847","pt":1646213362814,"mc":[{"id":"1.195453620","rc":[{"atb":[[1.4,0],[1.3,0],[1.35,0]],"id":40410470},{"atl":[[2.86,0],[2.66,0],[3.15,0]],"id":40410470},{"atb":[[1.8,0],[1.85,0],[1.75,0]],"id":28447693},{"atl":[[4.5,0],[5.5,0],[3.75,0]],"id":28447693},{"atb":[[1.6,0],[1.55,0],[1.65,0]],"id":42464658},{"atl":[[3.45,0],[3.95,0],[2.98,0]],"id":42464658},{"atb":[[1.2,0],[1.25,0],[1.3,0]],"id":40310161},{"atl":[[2.54,0],[2.74,0],[2.94,0]],"id":40310161},{"atb":[[4.5,0],[5,0],[5.5,0]],"id":41574727},{"atl":[[18.5,0],[44,0],[27,0]],"id":41574727}],"con":true,"img":false}]}
{"op":"mcm","clk":"5348063896","pt":1646213363806,"mc":[{"id":"1.195453620","rc":[{"atl":[[3.1,0]],"id":40410470},{"atb":[[6,0]],"id":41574727}],"con":true,"img":false}]}
{"op":"mcm","clk":"5348063903","pt":1646213363908,"mc":[{"id":"1.195453620","rc":[{"atb":[[1.46,155.52],[1.49,0]],"id":40410470},{"atl":[[3.6,16.89]],"id":40410470},{"atb":[[1.23,434.78],[1.31,0]],"id":40310161},{"atb":[[5.6,9.08]],"id":41574727},{"atl":[[29,0],[30,6.17]],"id":41574727}],"con":true,"img":false}]}
{"op":"mcm","clk":"5348064113","pt":1646213367652,"mc":[{"id":"1.195453620","rc":[{"atb":[[1.41,0]],"id":40410470},{"atl":[[2.64,0]],"id":40410470},{"atb":[[1.86,0]],"id":28447693},{"atl":[[3.7,0]],"id":28447693},{"atb":[[1.66,0]],"id":42464658},{"atl":[[4.5,10.48],[2.96,0],[3.9,0]],"id":42464658},{"atb":[[1.21,0],[1.17,253.41]],"id":40310161},{"atl":[[2.72,0]],"id":40310161}],"con":true,"img":false}]}
{"op":"mcm","clk":"5348064119","pt":1646213367726,"mc":[{"id":"1.195453620","rc":[{"atb":[[1.35,101.91]],"id":40410470},{"atl":[[3.2,24.49]],"id":40410470},{"atb":[[1.73,65.07]],"id":28447693},{"atl":[[4.7,12.82]],"id":28447693},{"atb":[[1.58,71.47]],"id":42464658},{"atl":[[3.95,18.16]],"id":42464658},{"atl":[[2.96,25.06]],"id":40310161}],"con":true,"img":false}]}
{"op":"mcm","clk":"5348064125","pt":1646213367786,"mc":[{"id":"1.195453620","rc":[{"atl":[[5.2,23.81],[3.65,0]],"id":28447693}],"con":true,"img":false}]}
{"op":"mcm","clk":"5348064270","pt":1646213370519,"mc":[{"id":"1.195453620","rc":[{"atb":[[1.9,0]],"id":28447693},{"atb":[[1.7,0]],"id":42464658}],"con":true,"img":false}]}
{"op":"mcm","clk":"5348064442","pt":1646213373318,"mc":[{"id":"1.195453620","rc":[{"atb":[[1.06,1666.67],[1.07,0]],"id":37496564},{"atl":[[3.6,38.46],[2.98,0]],"id":40310161}],"con":true,"img":false}]}
{"op":"mcm","clk":"5348064689","pt":1646213377916,"mc":[{"id":"1.195453620","rc":[{"atb":[[1.22,0]],"id":40310161}],"con":true,"img":false}]}
{"op":"mcm","clk":"5348064694","pt":1646213378019,"mc":[{"id":"1.195453620","rc":[{"atb":[[1.21,85.42]],"id":40310161}],"con":true,"img":false}]}
{"op":"mcm","clk":"5348064705","pt":1646213378233,"mc":[{"id":"1.195453620","rc":[{"atb":[[1.4,249.53],[1.3,332.71],[1.35,387.1]],"id":40410470},{"atl":[[2.86,39.02],[2.66,21.86],[3.15,33.76]],"id":40410470},{"atb":[[1.8,124.76],[1.85,117.42],[1.75,133.08]],"id":28447693},{"atl":[[4.5,20.74],[5.5,16.13],[3.75,13.19]],"id":28447693},{"atb":[[1.6,166.35],[1.55,181.48],[1.5,199.62]],"id":42464658},{"atl":[[2.88,19.3],[3.2,32.99],[3.7,26.88]],"id":42464658},{"atb":[[1.19,525.34],[1.14,712.95],[1.09,1109.05]],"id":40310161},{"atl":[[2.28,28.35],[2.68,43.21],[2.48,49.04]],"id":40310161},{"atb":[[4.5,28.51],[5,24.95],[5.5,22.18]],"id":41574727},{"atl":[[18.5,2.07],[44,1.68],[27,2.79]],"id":41574727}],"con":true,"img":false}]}
{"op":"mcm","clk":"5348064722","pt":1646213378500,"mc":[{"id":"1.195453620","rc":[{"atb":[[1.23,0],[1.22,454.55]],"id":40310161}],"con":true,"img":false}]}
{"op":"mcm","clk":"5348065069","pt":1646213385419,"mc":[{"id":"1.195453620","rc":[{"atb":[[1.49,15.34]],"id":40410470},{"atb":[[1.89,8.45]],"id":28447693},{"atb":[[1.64,11.74]],"id":42464658}],"con":true,"img":false}]}
{"op":"mcm","clk":"5348065215","pt":1646213388350,"mc":[{"id":"1.195453620","rc":[{"atb":[[1.45,0]],"id":40410470}],"con":true,"img":false}]}
{"op":"mcm","clk":"5348065220","pt":1646213388455,"mc":[{"id":"1.195453620","rc":[{"atb":[[1.47,77.76]],"id":40410470}],"con":true,"img":false}]}
{"op":"mcm","clk":"5348065306","pt":1646213390060,"mc":[{"id":"1.195453620","rc":[{"atb":[[1.46,0],[1.49,93.1]],"id":40410470}],"con":true,"img":false}]}
{"op":"mcm","clk":"5348065386","pt":1646213391564,"mc":[{"id":"1.195453620","rc":[{"atb":[[1.49,77.76]],"id":40410470}],"con":true,"img":false}]}
{"op":"mcm","clk":"5348065499","pt":1646213393842,"mc":[{"id":"1.195453620","rc":[{"atl":[[3.8,26.4],[5.2,0]],"id":28447693}],"con":true,"img":false}]}
{"op":"mcm","clk":"5348065573","pt":1646213395237,"mc":[{"id":"1.195453620","rc":[{"atb":[[1.49,0],[1.48,208.33]],"id":40410470}],"con":true,"img":false}]}
{"op":"mcm","clk":"5348065787","pt":1646213399335,"mc":[{"id":"1.195453620","rc":[{"atb":[[1.06,0],[1.08,1250]],"id":37496564}],"con":true,"img":false}]}
{"op":"mcm","clk":"5348066143","pt":1646213403558,"mc":[{"id":"1.195453620","rc":[{"atb":[[1.51,14.74]],"id":40410470}],"con":true,"img":false}]}
{"op":"mcm","clk":"5348066421","pt":1646213407045,"mc":[{"id":"1.195453620","rc":[{"atb":[[1.21,0]],"id":40310161}],"con":true,"img":false}]}
{"op":"mcm","clk":"5348066429","pt":1646213407145,"mc":[{"id":"1.195453620","rc":[{"atb":[[1.2,500],[1.23,85.42],[1.22,0]],"id":40310161}],"con":true,"img":false}]}
{"op":"mcm","clk":"5348066630","pt":1646213410456,"mc":[{"id":"1.195453620","rc":[{"atl":[[32,0]],"id":41574727}],"con":true,"img":false}]}
{"op":"mcm","clk":"5348066637","pt":1646213410569,"mc":[{"id":"1.195453620","rc":[{"atl":[[26,2.72]],"id":41574727}],"con":true,"img":false}]}
{"op":"mcm","clk":"5348066833","pt":1646213413671,"mc":[{"id":"1.195453620","rc":[{"atb":[[1.64,24.76]],"id":42464658}],"con":true,"img":false}]}
{"op":"mcm","clk":"5348066849","pt":1646213413979,"mc":[{"id":"1.195453620","rc":[{"atb":[[1.51,31.09]],"id":40410470},{"atb":[[1.89,17.82]],"id":28447693}],"con":true,"img":false}]}
{"op":"mcm","clk":"5348066861","pt":1646213414289,"mc":[{"id":"1.195453620","rc":[{"atl":[[3.2,0]],"id":40410470},{"atl":[[4.7,0]],"id":28447693},{"atl":[[2.52,0]],"id":40310161},{"atl":[[30,3.45]],"id":41574727}],"con":true,"img":false}]}
{"op":"mcm","clk":"5348066867","pt":1646213414396,"mc":[{"id":"1.195453620","rc":[{"atl":[[2.84,24.49]],"id":40410470},{"atl":[[3.75,26.02]],"id":28447693},{"atl":[[2.46,25.34]],"id":40310161},{"atl":[[25,2.72]],"id":41574727}],"con":true,"img":false}]}
{"op":"mcm","clk":"5348067099","pt":1646213418485,"mc":[{"id":"1.195453620","rc":[{"atb":[[1.73,0]],"id":28447693},{"atb":[[1.58,0]],"id":42464658},{"atl":[[3.95,0]],"id":42464658}],"con":true,"img":false}]}
{"op":"mcm","clk":"5348067105","pt":1646213418587,"mc":[{"id":"1.195453620","rc":[{"atb":[[1.86,65.07]],"id":28447693},{"atb":[[1.61,71.47]],"id":42464658},{"atl":[[3.15,18.16]],"id":42464658}],"con":true,"img":false}]}
{"op":"mcm","clk":"5348067140","pt":1646213419266,"mc":[{"id":"1.195453620","rc":[{"atb":[[1.47,0]],"id":40410470}],"con":true,"img":false}]}
{"op":"mcm","clk":"5348067147","pt":1646213419362,"mc":[{"id":"1.195453620","rc":[{"atb":[[1.49,77.76]],"id":40410470}],"con":true,"img":false}]}
{"op":"mcm","clk":"5348067244","pt":1646213420965,"mc":[{"id":"1.195453620","rc":[{"atb":[[1.48,0]],"id":40410470}],"con":true,"img":false}]}
{"op":"mcm","clk":"5348067248","pt":1646213421070,"mc":[{"id":"1.195453620","rc":[{"atb":[[1.49,281.84]],"id":40410470}],"con":true,"img":false}]}
{"op":"mcm","clk":"5348067267","pt":1646213421492,"mc":[{"id":"1.195453620","rc":[{"atb":[[1.51,16.34]],"id":40410470},{"spn":2.08,"spf":"NaN","id":40410470},{"atb":[[1.89,9.36]],"id":28447693},{"spn":1.89,"spf":1.0,"id":28447693},{"atb":[[1.64,13.02]],"id":42464658},{"spn":2.26,"spf":"NaN","id":42464658},{"spn":1.75,"spf":"NaN","id":40310161},{"spn":12.05,"spf":"NaN","id":41574727}],"con":true,"img":false}]}
{"op":"mcm","clk":"5348067325","pt":1646213422685,"mc":[{"id":"1.195453620","rc":[{"atb":[[1.23,0]],"id":40310161}],"con":true,"img":false}]}
{"op":"mcm","clk":"5348067331","pt":1646213422787,"mc":[{"id":"1.195453620","rc":[{"atb":[[1.21,85.42]],"id":40310161}],"con":true,"img":false}]}
{"op":"mcm","clk":"5348067390","pt":1646213423721,"mc":[{"id":"1.195453620","rc":[{"atb":[[1.4,0],[1.3,0],[1.35,101.91]],"id":40410470},{"atl":[[2.86,0],[2.66,0],[3.15,0]],"id":40410470},{"atb":[[1.8,0],[1.85,0],[1.75,0]],"id":28447693},{"atl":[[4.5,0],[5.5,0],[3.75,12.82]],"id":28447693},{"atb":[[1.01,0]],"id":37496564},{"atl":[[2.36,0],[1.98,0],[2.16,0]],"id":37496564},{"atb":[[1.6,0],[1.55,0],[1.5,0]],"id":42464658},{"atl":[[2.88,0],[3.2,0],[3.7,0]],"id":42464658},{"atb":[[1.19,0],[1.14,0],[1.09,0]],"id":40310161},{"atl":[[2.28,0],[2.68,0],[2.48,0]],"id":40310161},{"atb":[[4.5,0],[5,0],[5.5,0]],"id":41574727},{"atl":[[18.5,0],[44,0],[27,0]],"id":41574727}],"con":true,"img":false}]}
{"op":"mcm","clk":"5348067469","pt":1646213425286,"mc":[{"id":"1.195453620","rc":[{"atl":[[2.84,0]],"id":40410470},{"atb":[[1.86,0]],"id":28447693},{"atl":[[1.97,0]],"id":37496564},{"atl":[[3.15,0]],"id":42464658},{"atl":[[26,0]],"id":41574727}],"con":true,"img":false}]}
{"op":"mcm","clk":"5348067474","pt":1646213425390,"mc":[{"id":"1.195453620","rc":[{"atl":[[3.3,24.49]],"id":40410470},{"atb":[[1.7,65.07]],"id":28447693},{"atl":[[2.1,38.39]],"id":37496564},{"atl":[[4,18.16]],"id":42464658},{"atl":[[29,2.72]],"id":41574727}],"con":true,"img":false}]}
{"op":"mcm","clk":"5348067533","pt":1646213426786,"mc":[{"id":"1.195453620","rc":[{"atb":[[1.52,14.45]],"id":40410470},{"atb":[[1.65,11.56]],"id":42464658}],"con":true,"img":false}]}
{"op":"mcm","clk":"5348067579","pt":1646213427980,"mc":[{"id":"1.195453620","rc":[{"atb":[[5.1,0],[4.5,11.98]],"id":41574727}],"con":true,"img":false}]}
{"op":"mcm","clk":"5348067783","pt":1646213432246,"mc":[{"id":"1.195453620","rc":[{"atb":[[1.49,204.08],[1.35,0]],"id":40410470},{"atl":[[3.6,0],[3.3,0]],"id":40410470},{"atb":[[1.55,0],[1.7,0]],"id":28447693},{"atl":[[5.3,0],[3.75,0]],"id":28447693},{"atb":[[1.09,0],[1.1,0]],"id":37496564},{"atl":[[1.89,0],[2.1,0]],"id":37496564},{"atb":[[1.46,0],[1.61,0]],"id":42464658},{"atl":[[4,0],[4.5,0]],"id":42464658},{"atb":[[5.6,0],[4.7,0]],"id":39791282},{"atl":[[50,0],[55,0]],"id":39791282},{"atb":[[5,0],[4.6,0]],"id":37208007},{"atl":[[25,0],[28,0]],"id":37208007},{"atb":[[1.21,0],[1.17,0]],"id":40310161},{"atl":[[2.46,0],[2.96,0]],"id":40310161},{"atb":[[5.6,0],[4.5,0]],"id":41574727},{"atl":[[25,0],[29,0]],"id":41574727}],"con":true,"img":false}]}
{"op":"mcm","clk":"5348067796","pt":1646213432406,"mc":[{"id":"1.195453620","rc":[{"atl":[[6.2,19.23],[5.9,0]],"id":42464658}],"con":true,"img":false}]}
{"op":"mcm","clk":"5348067837","pt":1646213433017,"mc":[{"id":"1.195453620","rc":[{"atb":[[1.65,0]],"id":42464658}],"con":true,"img":false}]}
{"op":"mcm","clk":"5348067851","pt":1646213433283,"mc":[{"id":"1.195453620","rc":[{"atb":[[1.49,0],[1.47,32.7]],"id":40410470}],"con":true,"img":false}]}
{"op":"mcm","clk":"5348067987","pt":1646213435508,"mc":[{"id":"1.195453620","rc":[{"atb":[[1.51,0]],"id":40410470},{"atb":[[1.89,0]],"id":28447693},{"atb":[[1.64,0]],"id":42464658}],"con":true,"img":false}]}
{"op":"mcm","clk":"5348068015","pt":1646213435929,"mc":[{"id":"1.195453620","rc":[{"atb":[[1.52,0]],"id":40410470}],"con":true,"img":false}]}
{"op":"mcm","clk":"5348068078","pt":1646213437114,"mc":[{"id":"1.195453620","rc":[{"atb":[[5.1,0]],"id":37208007}],"con":true,"img":false}]}
{"op":"mcm","clk":"5348068085","pt":1646213437220,"mc":[{"id":"1.195453620","rc":[{"atb":[[4.6,1.66]],"id":39791282},{"atb":[[4.6,1.66]],"id":37208007},{"atb":[[3.2,1.66]],"id":41574727}],"con":true,"img":false}]}
{"op":"mcm","clk":"5348068380","pt":1646213442982,"mc":[{"id":"1.195453620","rc":[{"atb":[[1.25,399.25],[1.3,332.71],[1.35,285.18]],"id":40410470},{"atl":[[2.8,40.32],[3,36.29],[2.6,22.68]],"id":40410470},{"atb":[[1.8,124.76],[1.7,142.59],[1.75,133.08]],"id":28447693},{"atl":[[3.6,13.96],[5.2,17.28],[4.2,22.68]],"id":28447693},{"atb":[[1.01,19962.94],[1.02,4990.73]],"id":37496564},{"atl":[[1.99,36.66],[2.38,52.6],[2.18,61.51]],"id":37496564},{"atb":[[1.6,166.35],[1.7,142.59],[1.65,153.56]],"id":42464658},{"atl":[[3.2,16.49],[3.7,26.88],[4.4,21.35]],"id":42464658},{"atb":[[1.19,525.34],[1.14,712.95],[1.09,1109.05]],"id":40310161},{"atl":[[2.28,28.35],[2.68,43.21],[2.48,49.04]],"id":40310161},{"atb":[[4.8,26.26],[5.8,20.79],[5.3,23.21]],"id":41574727},{"atl":[[19,2.01],[46,1.61],[28,2.68]],"id":41574727}],"con":true,"img":false}]}
{"op":"mcm","clk":"5348068388","pt":1646213443139,"mc":[{"id":"1.195453620","rc":[{"atb":[[1.36,277.78]],"id":40410470},{"atb":[[1.03,3333.33],[1.08,0]],"id":37496564}],"con":true,"img":false}]}
{"op":"mcm","clk":"5348068392","pt":1646213443246,"mc":[{"id":"1.195453620","rc":[{"atb":[[1.47,0]],"id":40410470}],"con":true,"img":false}]}
{"op":"mcm","clk":"5348068441","pt":1646213444130,"mc":[{"id":"1.195453620","rc":[{"atb":[[3.2,0]],"id":41574727}],"con":true,"img":false}]}
{"op":"mcm","clk":"5348068625","pt":1646213447912,"mc":[{"id":"1.195453620","rc":[{"atb":[[5.2,10.38]],"id":37208007}],"con":true,"img":false}]}
{"op":"mcm","clk":"5348068808","pt":1646213451128,"mc":[{"id":"1.195453620","rc":[{"atb":[[4.6,0]],"id":37208007}],"con":true,"img":false}]}
{"op":"mcm","clk":"5348068816","pt":1646213451335,"mc":[{"id":"1.195453620","rc":[{"atb":[[5.3,1.66]],"id":37208007}],"con":true,"img":false}]}
{"op":"mcm","clk":"5348068952","pt":1646213453457,"mc":[{"id":"1.195453620","rc":[{"atb":[[1.44,99.08],[1.37,113.35]],"id":40410470},{"atl":[[3.6,16.34],[2.78,24.49]],"id":40410470},{"atb":[[1.72,60.55],[1.59,73.02]],"id":28447693},{"atl":[[5.1,10.35],[3.75,15.85]],"id":28447693},{"atb":[[1.1,140.25],[1.08,465.51]],"id":37496564},{"atl":[[1.9,43.59],[2.1,32.1]],"id":37496564},{"atb":[[1.62,70.31],[1.51,71.95]],"id":42464658},{"atl":[[4.3,11.11],[3.65,16.45]],"id":42464658},{"atb":[[4.6,13.04],[5.4,9.9]],"id":39791282},{"atl":[[44,2.72],[48,2.72]],"id":39791282},{"atb":[[4.6,10.14]],"id":37208007},{"atl":[[23,2.72],[26,2.72]],"id":37208007},{"atb":[[1.16,287.2],[1.21,207.61]],"id":40310161},{"atl":[[2.46,59.28]],"id":40310161},{"atb":[[5.6,9.47],[4.7,11.44]],"id":41574727},{"atl":[[25,2.72],[28,5.41]],"id":41574727}],"con":true,"img":false}]}
{"op":"mcm","clk":"5348068962","pt":1646213453616,"mc":[{"id":"1.195453620","rc":[{"atb":[[1.2,0],[1.22,454.55]],"id":40310161}],"con":true,"img":false}]}
{"op":"mcm","clk":"5348069139","pt":1646213456623,"mc":[{"id":"1.195453620","rc":[{"atl":[[25,0]],"id":41574727}],"con":true,"img":false}]}
{"op":"mcm","clk":"5348069142","pt":1646213456722,"mc":[{"id":"1.195453620","rc":[{"atl":[[28,8.13]],"id":41574727}],"con":true,"img":false}]}
{"op":"mcm","clk":"5348069218","pt":1646213458066,"mc":[{"id":"1.195453620","rc":[{"atl":[[2.46,29.85]],"id":40310161}],"con":true,"img":false}]}
{"op":"mcm","clk":"5348069223","pt":1646213458122,"mc":[{"id":"1.195453620","rc":[{"atb":[[4.6,11.37]],"id":39791282},{"atl":[[2.66,29.42]],"id":40310161}],"con":true,"img":false}]}
{"op":"mcm","clk":"5348069322","pt":1646213459931,"mc":[{"id":"1.195453620","rc":[{"atb":[[1.47,16]],"id":40410470},{"atb":[[1.84,8.94]],"id":28447693},{"atb":[[1.74,10.15]],"id":42464658}],"con":true,"img":false}]}
{"op":"mcm","clk":"5348069529","pt":1646213462529,"mc":[{"id":"1.195453620","rc":[{"atl":[[3.8,0],[3.75,43.77]],"id":28447693},{"atl":[[3.6,0],[3.3,43.48]],"id":40310161}],"con":true,"img":false}]}
{"op":"mcm","clk":"5348069844","pt":1646213468476,"mc":[{"id":"1.195453620","rc":[{"atb":[[1.36,0],[1.48,99.09]],"id":40410470},{"atb":[[1.03,0],[1.08,1715.51]],"id":37496564}],"con":true,"img":false}]}
{"op":"mcm","clk":"5348069872","pt":1646213468940,"mc":[{"id":"1.195453620","rc":[{"atb":[[1.47,0]],"id":40410470}],"con":true,"img":false}]}
{"op":"mcm","clk":"5348070016","pt":1646213471580,"mc":[{"id":"1.195453620","rc":[{"atb":[[1.74,21.41]],"id":42464658}],"con":true,"img":false}]}
{"op":"mcm","clk":"5348070034","pt":1646213471787,"mc":[{"id":"1.195453620","rc":[{"atb":[[1.84,18.86]],"id":28447693}],"con":true,"img":false}]}
{"op":"mcm","clk":"5348070127","pt":1646213473601,"mc":[{"id":"1.195453620","rc":[{"atb":[[1.45,198.18],[1.48,0]],"id":40410470}],"con":true,"img":false}]}
{"op":"mcm","clk":"5348070578","pt":1646213480897,"mc":[{"id":"1.195453620","rc":[{"atb":[[1.48,15.66]],"id":40410470}],"con":true,"img":false}]}
{"op":"mcm","clk":"5348070665","pt":1646213482783,"mc":[{"id":"1.195453620","rc":[{"spn":2.04,"spf":"NaN","id":40410470},{"spn":1.84,"spf":1.0,"id":28447693},{"atb":[[1.62,0]],"id":42464658},{"spn":2.47,"spf":"NaN","id":42464658},{"spn":10.7,"spf":"NaN","id":39791282},{"spn":10.65,"spf":"NaN","id":37208007},{"atb":[[1.23,91.67]],"id":40310161},{"spn":12.4,"spf":"NaN","id":41574727}],"con":true,"img":false}]}
{"op":"mcm","clk":"5348070667","pt":1646213482884,"mc":[{"id":"1.195453620","rc":[{"atb":[[1.71,70.31]],"id":42464658},{"atb":[[1.21,0],[1.22,0],[1.24,207.61]],"id":40310161}],"con":true,"img":false}]}
{"op":"mcm","clk":"5348070709","pt":1646213483867,"mc":[{"id":"1.195453620","rc":[{"atb":[[1.74,11.26]],"id":42464658}],"con":true,"img":false}]}
{"op":"mcm","clk":"5348070944","pt":1646213489072,"mc":[{"id":"1.195453620","rc":[{"atb":[[1.72,0]],"id":28447693},{"atb":[[5.4,0]],"id":39791282},{"atb":[[5.2,0]],"id":37208007},{"atl":[[2.46,0]],"id":40310161},{"atl":[[28,5.41]],"id":41574727}],"con":true,"img":false}]}
{"op":"mcm","clk":"5348070947","pt":1646213489175,"mc":[{"id":"1.195453620","rc":[{"atb":[[1.81,60.55]],"id":28447693},{"atb":[[5.5,9.9]],"id":39791282},{"atb":[[5.4,10.38]],"id":37208007},{"atl":[[2.26,29.85]],"id":40310161},{"atl":[[25,2.72]],"id":41574727}],"con":true,"img":false}]}
{"op":"mcm","clk":"5348070996","pt":1646213490211,"mc":[{"id":"1.195453620","rc":[{"atb":[[1.84,9.91]],"id":28447693},{"atb":[[1.75,10.02]],"id":42464658}],"con":true,"img":false}]}
{"op":"mcm","clk":"5348071138","pt":1646213493220,"mc":[{"id":"1.195453620","rc":[{"atb":[[5.3,0]],"id":37208007}],"con":true,"img":false}]}
{"op":"mcm","clk":"5348071166","pt":1646213493892,"mc":[{"id":"1.195453620","rc":[{"atl":[[4.2,0],[3.75,36.36]],"id":40410470},{"atl":[[3.55,22.69],[3.75,15.85]],"id":28447693},{"atl":[[3,50],[3.3,0]],"id":40310161},{"atl":[[26,4],[30,0]],"id":41574727}],"con":true,"img":false}]}
{"op":"mcm","clk":"5348071281","pt":1646213496420,"mc":[{"id":"1.195453620","rc":[{"atb":[[1.85,8.84]],"id":28447693}],"con":true,"img":false}]}
{"op":"mcm","clk":"5348071394","pt":1646213498584,"mc":[{"id":"1.195453620","rc":[{"atb":[[1.45,0],[1.49,99.09]],"id":40410470}],"con":true,"img":false}]}
{"op":"mcm","clk":"5348071410","pt":1646213498895,"mc":[{"id":"1.195453620","rc":[{"atb":[[5.6,0]],"id":41574727}],"con":true,"img":false}]}
{"op":"mcm","clk":"5348071415","pt":1646213498998,"mc":[{"id":"1.195453620","rc":[{"atb":[[5.9,9.47]],"id":41574727}],"con":true,"img":false}]}
{"op":"mcm","clk":"5348071421","pt":1646213499100,"mc":[{"id":"1.195453620","rc":[{"atb":[[1.48,0]],"id":40410470}],"con":true,"img":false}]}
{"op":"mcm","clk":"5348071426","pt":1646213499204,"mc":[{"id":"1.195453620","rc":[{"atb":[[1.45,198.18],[1.49,0]],"id":40410470}],"con":true,"img":false}]}
{"op":"mcm","clk":"5348071471","pt":1646213500132,"mc":[{"id":"1.195453620","rc":[{"atb":[[1.74,0]],"id":42464658}],"con":true,"img":false}]}
{"op":"mcm","clk":"5348071482","pt":1646213500290,"mc":[{"id":"1.195453620","rc":[{"atb":[[1.48,17.36]],"id":40410470}],"con":true,"img":false}]}
{"op":"mcm","clk":"5348071494","pt":1646213500496,"mc":[{"id":"1.195453620","rc":[{"atb":[[1.23,0]],"id":40310161},{"atl":[[2.26,0]],"id":40310161}],"con":true,"img":false}]}
{"op":"mcm","clk":"5348071499","pt":1646213500600,"mc":[{"id":"1.195453620","rc":[{"atb":[[1.2,500],[1.21,91.67],[1.24,0]],"id":40310161},{"atl":[[2.44,29.85]],"id":40310161}],"con":true,"img":false}]}
{"op":"mcm","clk":"5348071502","pt":1646213500703,"mc":[{"id":"1.195453620","rc":[{"atb":[[1.2,0],[1.22,454.55]],"id":40310161}],"con":true,"img":false}]}
{"op":"mcm","clk":"5348071524","pt":1646213501228,"mc":[{"id":"1.195453620","rc":[{"atb":[[1.44,0]],"id":40410470}],"con":true,"img":false}]}
{"op":"mcm","clk":"5348071530","pt":1646213501332,"mc":[{"id":"1.195453620","rc":[{"atb":[[1.46,99.08]],"id":40410470}],"con":true,"img":false}]}
{"op":"mcm","clk":"5348071845","pt":1646213507023,"mc":[{"id":"1.195453620","rc":[{"atl":[[4.1,32.26],[3.75,0]],"id":40410470},{"atl":[[3,0],[3.3,43.48]],"id":40310161}],"con":true,"img":false}]}
{"op":"mcm","clk":"5348071851","pt":1646213507125,"mc":[{"id":"1.195453620","rc":[{"atl":[[3.55,0],[3.75,52.21]],"id":28447693}],"con":true,"img":false}]}
{"op":"mcm","clk":"5348071894","pt":1646213508107,"mc":[{"id":"1.195453620","rc":[{"atl":[[2.1,0]],"id":37496564}],"con":true,"img":false}]}
{"op":"mcm","clk":"5348071896","pt":1646213508209,"mc":[{"id":"1.195453620","rc":[{"atl":[[1.98,32.1]],"id":37496564}],"con":true,"img":false}]}
{"op":"mcm","clk":"5348071901","pt":1646213508311,"mc":[{"id":"1.195453620","rc":[{"atb":[[1.49,15.34]],"id":40410470}],"con":true,"img":false}]}
{"op":"mcm","clk":"5348072061","pt":1646213511444,"mc":[{"id":"1.195453620","rc":[{"atb":[[1.51,0]],"id":42464658},{"atb":[[4.7,0]],"id":41574727}],"con":true,"img":false}]}
{"op":"mcm","clk":"5348072066","pt":1646213511546,"mc":[{"id":"1.195453620","rc":[{"atb":[[1.61,71.95]],"id":42464658},{"atb":[[4.9,11.44]],"id":41574727}],"con":true,"img":false}]}
{"op":"mcm","clk":"5348072139","pt":1646213512942,"mc":[{"id":"1.195453620","rc":[{"atb":[[1.84,0]],"id":28447693}],"con":true,"img":false}]}
{"op":"mcm","clk":"5348072143","pt":1646213513045,"mc":[{"id":"1.195453620","rc":[{"atb":[[1.75,21.13]],"id":42464658}],"con":true,"img":false}]}
{"op":"mcm","clk":"5348072200","pt":1646213514238,"mc":[{"id":"1.195453620","rc":[{"atb":[[4,0],[4.5,0],[3.75,0]],"id":37208007},{"atl":[[16,0],[34,0],[22,0]],"id":37208007}],"con":true,"img":false}]}
{"op":"mcm","clk":"5348072204","pt":1646213514344,"mc":[{"id":"1.195453620","rc":[{"atb":[[1.16,0],[1.23,186.93]],"id":40310161}],"con":true,"img":false}]}
{"op":"mcm","clk":"5348072205","pt":1646213514448,"mc":[{"id":"1.195453620","rc":[{"atl":[[2.66,0]],"id":40310161}],"con":true,"img":false}]}
{"op":"mcm","clk":"5348072209","pt":1646213514550,"mc":[{"id":"1.195453620","rc":[{"atb":[[1.22,0],[1.24,186.93]],"id":40310161},{"atl":[[2.46,29.42]],"id":40310161}],"con":true,"img":false}]}
{"op":"mcm","clk":"5348072506","pt":1646213521035,"mc":[{"id":"1.195453620","rc":[{"atl":[[28,2.68]],"id":41574727}],"con":true,"img":false}]}
{"op":"mcm","clk":"5348072512","pt":1646213521140,"mc":[{"id":"1.195453620","rc":[{"atl":[[25,5.44]],"id":41574727}],"con":true,"img":false}]}
{"op":"mcm","clk":"5348072638","pt":1646213523162,"mc":[{"id":"1.195453620","rc":[{"atb":[[3.75,2.73]],"id":37208007}],"con":true,"img":false}]}
{"op":"mcm","clk":"5348072665","pt":1646213523938,"mc":[{"id":"1.195453620","rc":[{"atb":[[1.45,0],[1.5,17.36]],"id":40410470}],"con":true,"img":false}]}
{"op":"mcm","clk":"5348072742","pt":1646213525438,"mc":[{"id":"1.195453620","rc":[{"atb":[[1.48,0]],"id":40410470}],"con":true,"img":false}]}
{"op":"mcm","clk":"5348072761","pt":1646213525748,"mc":[{"id":"1.195453620","rc":[{"atb":[[1.85,18.64]],"id":28447693}],"con":true,"img":false}]}
{"op":"mcm","clk":"5348072988","pt":1646213528762,"mc":[{"id":"1.195453620","rc":[{"atb":[[4,33.27],[4.5,28.51],[5,24.95]],"id":37208007},{"atl":[[17,2.26],[38,1.96],[24,3.15]],"id":37208007}],"con":true,"img":false}]}
{"op":"mcm","clk":"5348073026","pt":1646213529542,"mc":[{"id":"1.195453620","rc":[{"atb":[[3.75,0]],"id":37208007}],"con":true,"img":false}]}
{"op":"mcm","clk":"5348073133","pt":1646213531656,"mc":[{"id":"1.195453620","rc":[{"atl":[[4.1,0],[3.75,36.36]],"id":40410470},{"atl":[[3,50],[3.3,0]],"id":40310161}],"con":true,"img":false}]}
{"op":"mcm","clk":"5348073138","pt":1646213531759,"mc":[{"id":"1.195453620","rc":[{"atl":[[3.55,22.69],[3.75,15.85]],"id":28447693}],"con":true,"img":false}]}
{"op":"mcm","clk":"5348073234","pt":1646213533257,"mc":[{"id":"1.195453620","rc":[{"atb":[[1.21,0]],"id":40310161},{"atl":[[2.44,0]],"id":40310161}],"con":true,"img":false}]}
{"op":"mcm","clk":"5348073240","pt":1646213533360,"mc":[{"id":"1.195453620","rc":[{"atb":[[1.27,91.67]],"id":40310161},{"atl":[[2.26,29.85]],"id":40310161}],"con":true,"img":false}]}
{"op":"mcm","clk":"5348073468","pt":1646213537449,"mc":[{"id":"1.195453620","rc":[{"atb":[[1.49,32.35]],"id":40410470}],"con":true,"img":false}]}
{"op":"mcm","clk":"5348073539","pt":1646213539160,"mc":[{"id":"1.195453620","rc":[{"atb":[[1.28,186.93],[1.24,0]],"id":40310161}],"con":true,"img":false}]}
{"op":"mcm","clk":"5348073895","pt":1646213545369,"mc":[{"id":"1.195453620","rc":[{"spn":2.05,"spf":"NaN","id":40410470},{"spn":1.85,"spf":1.0,"id":28447693},{"spn":2.47,"spf":"NaN","id":42464658},{"spn":10.75,"spf":"NaN","id":39791282},{"spn":11.2,"spf":"NaN","id":37208007},{"atl":[[2.46,0]],"id":40310161},{"spn":1.77,"spf":"NaN","id":40310161},{"spn":12.45,"spf":"NaN","id":41574727}],"con":true,"img":false}]}
{"op":"mcm","clk":"5348073899","pt":1646213545472,"mc":[{"id":"1.195453620","rc":[{"atl":[[2.66,29.42]],"id":40310161}],"con":true,"img":false}]}
{"op":"mcm","clk":"5348075263","pt":1646213568538,"mc":[{"id":"1.195453620","rc":[{"atl":[[2.78,0]],"id":40410470},{"atl":[[3.75,0]],"id":28447693}],"con":true,"img":false}]}
{"op":"mcm","clk":"5348075271","pt":1646213568643,"mc":[{"id":"1.195453620","rc":[{"atl":[[2.58,24.49]],"id":40410470},{"atl":[[3.5,15.85]],"id":28447693}],"con":true,"img":false}]}
{"op":"mcm","clk":"5348075291","pt":1646213568861,"mc":[{"id":"1.195453620","rc":[{"atl":[[3.45,15.85],[3.55,0]],"id":28447693}],"con":true,"img":false}]}
{"op":"mcm","clk":"5348075526","pt":1646213572742,"mc":[{"id":"1.195453620","rc":[{"atb":[[1.27,0]],"id":40310161}],"con":true,"img":false}]}
{"op":"mcm","clk":"5348075530","pt":1646213572845,"mc":[{"id":"1.195453620","rc":[{"atb":[[1.29,91.67]],"id":40310161}],"con":true,"img":false}]}
{"op":"mcm","clk":"5348075531","pt":1646213572946,"mc":[{"id":"1.195453620","rc":[{"atb":[[1.28,0],[1.24,416.67]],"id":40310161}],"con":true,"img":false}]}
{"op":"mcm","clk":"5348075631","pt":1646213575051,"mc":[{"id":"1.195453620","rc":[{"atb":[[1.29,0]],"id":40310161}],"con":true,"img":false}]}
{"op":"mcm","clk":"5348075638","pt":1646213575155,"mc":[{"id":"1.195453620","rc":[{"atb":[[1.28,91.67]],"id":40310161}],"con":true,"img":false}]}
{"op":"mcm","clk":"5348076005","pt":1646213580736,"mc":[{"id":"1.195453620","rc":[{"atl":[[3.5,0]],"id":28447693}],"con":true,"img":false}]}
{"op":"mcm","clk":"5348076006","pt":1646213580835,"mc":[{"id":"1.195453620","rc":[{"atl":[[4.1,15.85]],"id":28447693}],"con":true,"img":false}]}
{"op":"mcm","clk":"5348076011","pt":1646213580944,"mc":[{"id":"1.195453620","rc":[{"atl":[[3.45,0],[3.55,31.7]],"id":28447693}],"con":true,"img":false}]}
{"op":"mcm","clk":"5348076129","pt":1646213582564,"mc":[{"id":"1.195453620","rc":[{"atb":[[1.08,465.51],[1.07,1428.57]],"id":37496564}],"con":true,"img":false}]}
{"op":"mcm","clk":"5348076716","pt":1646213590667,"mc":[{"id":"1.195453620","rc":[{"atb":[[4.6,0]],"id":37208007},{"atl":[[26,0]],"id":37208007}],"con":true,"img":false}]}
{"op":"mcm","clk":"5348076726","pt":1646213590776,"mc":[{"id":"1.195453620","rc":[{"atb":[[5.1,10.14]],"id":37208007},{"atl":[[23,5.44]],"id":37208007}],"con":true,"img":false}]}
{"op":"mcm","clk":"5348077016","pt":1646213593467,"mc":[{"id":"1.195453620","rc":[{"atb":[[5.1,0]],"id":37208007}],"con":true,"img":false}]}
{"op":"mcm","clk":"5348077022","pt":1646213593568,"mc":[{"id":"1.195453620","rc":[{"atb":[[4.6,10.14]],"id":37208007}],"con":true,"img":false}]}
{"op":"mcm","clk":"5348077260","pt":1646213596983,"mc":[{"id":"1.195453620","rc":[{"atb":[[1.29,186.93],[1.24,0]],"id":40310161}],"con":true,"img":false}]}
{"op":"mcm","clk":"5348078312","pt":1646213613218,"mc":[{"id":"1.195453620","rc":[{"atb":[[1.5,0],[1.49,131.44]],"id":40410470},{"spn":2.03,"spf":"NaN","id":40410470},{"atb":[[1.08,1715.51],[1.07,0]],"id":37496564},{"atl":[[5.6,21.74],[6.2,0]],"id":42464658},{"atl":[[3,0],[3.3,43.48]],"id":40310161},{"spn":1.77,"spf":"NaN","id":40310161}],"con":true,"img":false}]}
{"op":"mcm","clk":"5348078390","pt":1646213614415,"mc":[{"id":"1.195453620","rc":[{"atl":[[4.1,0]],"id":28447693}],"con":true,"img":false}]}
{"op":"mcm","clk":"5348078396","pt":1646213614510,"mc":[{"id":"1.195453620","rc":[{"atl":[[3.5,15.85]],"id":28447693}],"con":true,"img":false}]}
{"op":"mcm","clk":"5348078407","pt":1646213614722,"mc":[{"id":"1.195453620","rc":[{"atl":[[3.45,15.85],[3.55,0]],"id":28447693},{"atb":[[3.25,44.44],[3.65,0]],"id":37208007}],"con":true,"img":false}]}
{"op":"mcm","clk":"5348078537","pt":1646213616731,"mc":[{"id":"1.195453620","rc":[{"atb":[[1.49,116.1]],"id":40410470}],"con":true,"img":false}]}
{"op":"mcm","clk":"5348078983","pt":1646213622519,"mc":[{"id":"1.195453620","rc":[{"atb":[[1.52,14.45]],"id":40410470}],"con":true,"img":false}]}
{"op":"mcm","clk":"5348079245","pt":1646213627147,"mc":[{"id":"1.195453620","rc":[{"atl":[[3.5,0]],"id":28447693}],"con":true,"img":false}]}
{"op":"mcm","clk":"5348079250","pt":1646213627247,"mc":[{"id":"1.195453620","rc":[{"atl":[[4.1,15.85]],"id":28447693}],"con":true,"img":false}]}
{"op":"mcm","clk":"5348079254","pt":1646213627353,"mc":[{"id":"1.195453620","rc":[{"atl":[[3.45,0],[3.55,31.7]],"id":28447693}],"con":true,"img":false}]}
{"op":"mcm","clk":"5348079474","pt":1646213630569,"mc":[{"id":"1.195453620","rc":[{"atb":[[1.28,0]],"id":40310161}],"con":true,"img":false}]}
{"op":"mcm","clk":"5348079478","pt":1646213630629,"mc":[{"id":"1.195453620","rc":[{"atb":[[1.3,91.67]],"id":40310161}],"con":true,"img":false}]}
{"op":"mcm","clk":"5348079482","pt":1646213630728,"mc":[{"id":"1.195453620","rc":[{"atb":[[1.29,0],[1.24,416.67]],"id":40310161}],"con":true,"img":false}]}
{"op":"mcm","clk":"5348079499","pt":1646213631141,"mc":[{"id":"1.195453620","rc":[{"atb":[[1.3,0]],"id":40310161}],"con":true,"img":false}]}
{"op":"mcm","clk":"5348079505","pt":1646213631243,"mc":[{"id":"1.195453620","rc":[{"atb":[[1.28,91.67]],"id":40310161}],"con":true,"img":false}]}
{"op":"mcm","clk":"5348079771","pt":1646213635142,"mc":[{"id":"1.195453620","rc":[{"atb":[[5.5,1.66]],"id":37208007}],"con":true,"img":false}]}
{"op":"mcm","clk":"5348079881","pt":1646213636842,"mc":[{"id":"1.195453620","rc":[{"atb":[[1.49,17.01],[1.53,99.09]],"id":40410470}],"con":true,"img":false}]}
{"op":"mcm","clk":"5348079920","pt":1646213637474,"mc":[{"id":"1.195453620","rc":[{"atb":[[1.52,0]],"id":40410470}],"con":true,"img":false}]}
{"op":"mcm","clk":"5348079970","pt":1646213638348,"mc":[{"id":"1.195453620","rc":[{"atb":[[3.25,0],[3.65,37.74]],"id":37208007}],"con":true,"img":false}]}
{"op":"mcm","clk":"5348080193","pt":1646213642009,"mc":[{"id":"1.195453620","rc":[{"atb":[[1.5,198.18],[1.53,0]],"id":40410470}],"con":true,"img":false}]}
{"op":"mcm","clk":"5348080269","pt":1646213643058,"mc":[{"id":"1.195453620","rc":[{"atb":[[1.46,0]],"id":40410470}],"con":true,"img":false}]}
{"op":"mcm","clk":"5348080275","pt":1646213643156,"mc":[{"id":"1.195453620","rc":[{"atb":[[1.51,99.08]],"id":40410470}],"con":true,"img":false}]}
{"op":"mcm","clk":"5348080723","pt":1646213649761,"mc":[{"id":"1.195453620","rc":[{"atb":[[1.54,13.92]],"id":40410470}],"con":true,"img":false}]}
{"op":"mcm","clk":"5348080764","pt":1646213650586,"mc":[{"id":"1.195453620","rc":[{"atb":[[4.6,0]],"id":37208007}],"con":true,"img":false}]}
{"op":"mcm","clk":"5348080770","pt":1646213650690,"mc":[{"id":"1.195453620","rc":[{"atb":[[5.1,10.14]],"id":37208007}],"con":true,"img":false}]}
{"op":"mcm","clk":"5348080975","pt":1646213654171,"mc":[{"id":"1.195453620","rc":[{"atb":[[1.29,186.93],[1.24,0]],"id":40310161}],"con":true,"img":false}]}
{"op":"mcm","clk":"5348081464","pt":1646213661392,"mc":[{"id":"1.195453620","rc":[{"atl":[[4.1,0]],"id":28447693}],"con":true,"img":false}]}
{"op":"mcm","clk":"5348081471","pt":1646213661495,"mc":[{"id":"1.195453620","rc":[{"atl":[[3.5,15.85]],"id":28447693}],"con":true,"img":false}]}
{"op":"mcm","clk":"5348081485","pt":1646213661703,"mc":[{"id":"1.195453620","rc":[{"atl":[[3.45,15.85],[3.55,0]],"id":28447693}],"con":true,"img":false}]}
{"op":"mcm","clk":"5348081713","pt":1646213665274,"mc":[{"id":"1.195453620","rc":[{"atb":[[1.55,99.09],[1.5,0]],"id":40410470}],"con":true,"img":false}]}
{"op":"mcm","clk":"5348081844","pt":1646213667596,"mc":[{"id":"1.195453620","rc":[{"atb":[[1.54,0]],"id":40410470}],"con":true,"img":false}]}
{"op":"mcm","clk":"5348082055","pt":1646213670397,"mc":[{"id":"1.195453620","rc":[{"atb":[[1.55,0],[1.52,192.31]],"id":40410470}],"con":true,"img":false}]}
{"op":"mcm","clk":"5348082245","pt":1646213673514,"mc":[{"id":"1.195453620","rc":[{"spn":2.05,"spf":"NaN","id":40410470},{"atl":[[3.5,0]],"id":28447693},{"spn":11.25,"spf":"NaN","id":37208007}],"con":true,"img":false}]}
{"op":"mcm","clk":"5348082248","pt":1646213673620,"mc":[{"id":"1.195453620","rc":[{"atl":[[4.1,15.85]],"id":28447693}],"con":true,"img":false}]}
{"op":"mcm","clk":"5348082253","pt":1646213673720,"mc":[{"id":"1.195453620","rc":[{"atl":[[3.45,0],[3.55,31.7]],"id":28447693}],"con":true,"img":false}]}
{"op":"mcm","clk":"5348082560","pt":1646213679521,"mc":[{"id":"1.195453620","rc":[{"atb":[[1.55,13.66]],"id":40410470}],"con":true,"img":false}]}
{"op":"mcm","clk":"5348082856","pt":1646213684913,"mc":[{"id":"1.195453620","rc":[{"atb":[[1.28,0]],"id":40310161}],"con":true,"img":false}]}
{"op":"mcm","clk":"5348082863","pt":1646213685017,"mc":[{"id":"1.195453620","rc":[{"atb":[[1.3,91.67],[1.29,0],[1.24,416.67]],"id":40310161}],"con":true,"img":false}]}
{"op":"mcm","clk":"5348082866","pt":1646213685120,"mc":[{"id":"1.195453620","rc":[{"atb":[[1.31,186.93]],"id":40310161}],"con":true,"img":false}]}
{"op":"mcm","clk":"5348082872","pt":1646213685221,"mc":[{"id":"1.195453620","rc":[{"atb":[[1.24,0]],"id":40310161}],"con":true,"img":false}]}
{"op":"mcm","clk":"5348083040","pt":1646213688425,"mc":[{"id":"1.195453620","rc":[{"atb":[[1.55,112.75],[1.52,0]],"id":40410470}],"con":true,"img":false}]}
{"op":"mcm","clk":"5348083192","pt":1646213691532,"mc":[{"id":"1.195453620","rc":[{"atb":[[1.55,99.09]],"id":40410470}],"con":true,"img":false}]}
{"op":"mcm","clk":"5348083313","pt":1646213693552,"mc":[{"id":"1.195453620","rc":[{"atb":[[1.55,0],[1.52,192.31]],"id":40410470}],"con":true,"img":false}]}
{"op":"mcm","clk":"5348083527","pt":1646213697439,"mc":[{"id":"1.195453620","rc":[{"atb":[[1.51,0]],"id":40410470}],"con":true,"img":false}]}
{"op":"mcm","clk":"5348083533","pt":1646213697544,"mc":[{"id":"1.195453620","rc":[{"atb":[[1.53,99.08]],"id":40410470}],"con":true,"img":false}]}
{"op":"mcm","clk":"5348083724","pt":1646213700552,"mc":[{"id":"1.195453620","rc":[{"atb":[[1.3,0]],"id":40310161}],"con":true,"img":false}]}
{"op":"mcm","clk":"5348083732","pt":1646213700657,"mc":[{"id":"1.195453620","rc":[{"atb":[[1.26,91.67]],"id":40310161}],"con":true,"img":false}]}
{"op":"mcm","clk":"5348083739","pt":1646213700769,"mc":[{"id":"1.195453620","rc":[{"atb":[[1.31,0],[1.24,416.67]],"id":40310161}],"con":true,"img":false}]}
{"op":"mcm","clk":"5348083745","pt":1646213700859,"mc":[{"id":"1.195453620","rc":[{"atb":[[1.27,370.37],[1.24,0]],"id":40310161}],"con":true,"img":false}]}
{"op":"mcm","clk":"5348083895","pt":1646213703170,"mc":[{"id":"1.195453620","rc":[{"atb":[[1.49,221.09],[1.52,0]],"id":40410470},{"atb":[[1.07,1428.57]],"id":37496564}],"con":true,"img":false}]}
{"op":"mcm","clk":"5348083901","pt":1646213703272,"mc":[{"id":"1.195453620","rc":[{"atb":[[1.08,465.51]],"id":37496564}],"con":true,"img":false}]}
{"op":"mcm","clk":"5348083909","pt":1646213703479,"mc":[{"id":"1.195453620","rc":[{"atl":[[4.1,0]],"id":28447693}],"con":true,"img":false}]}
{"op":"mcm","clk":"5348083914","pt":1646213703582,"mc":[{"id":"1.195453620","rc":[{"atl":[[3.5,15.85]],"id":28447693}],"con":true,"img":false}]}
{"op":"mcm","clk":"5348083925","pt":1646213703742,"mc":[{"id":"1.195453620","rc":[{"atl":[[3.45,15.85],[3.55,0]],"id":28447693}],"con":true,"img":false}]}
{"op":"mcm","clk":"5348084063","pt":1646213706574,"mc":[{"id":"1.195453620","rc":[{"atb":[[1.57,13.18]],"id":40410470}],"con":true,"img":false}]}
{"op":"mcm","clk":"5348084426","pt":1646213712272,"mc":[{"id":"1.195453620","rc":[{"atb":[[1.53,0]],"id":40410470}],"con":true,"img":false}]}
{"op":"mcm","clk":"5348084431","pt":1646213712377,"mc":[{"id":"1.195453620","rc":[{"atb":[[1.5,99.08]],"id":40410470}],"con":true,"img":false}]}
{"op":"mcm","clk":"5348084447","pt":1646213712583,"mc":[{"id":"1.195453620","rc":[{"atb":[[1.57,0]],"id":40410470}],"con":true,"img":false}]}
{"op":"mcm","clk":"5348084591","pt":1646213715068,"mc":[{"id":"1.195453620","rc":[{"atl":[[3.5,0]],"id":28447693}],"con":true,"img":false}]}
{"op":"mcm","clk":"5348084596","pt":1646213715176,"mc":[{"id":"1.195453620","rc":[{"atl":[[4.1,15.85]],"id":28447693}],"con":true,"img":false}]}
{"op":"mcm","clk":"5348084600","pt":1646213715274,"mc":[{"id":"1.195453620","rc":[{"atl":[[3.45,0],[3.55,31.7]],"id":28447693}],"con":true,"img":false}]}
{"op":"mcm","clk":"5348084757","pt":1646213718282,"mc":[{"id":"1.195453620","rc":[{"atb":[[5.1,0],[5.4,0]],"id":37208007}],"con":true,"img":false}]}
{"op":"mcm","clk":"5348084762","pt":1646213718387,"mc":[{"id":"1.195453620","rc":[{"atb":[[4.6,10.14],[4.9,10.38]],"id":37208007}],"con":true,"img":false}]}
{"op":"mcm","clk":"5348084806","pt":1646213719209,"mc":[{"id":"1.195453620","rc":[{"atb":[[5.5,0]],"id":37208007}],"con":true,"img":false}]}
{"op":"mcm","clk":"5348084811","pt":1646213719372,"mc":[{"id":"1.195453620","rc":[{"atb":[[5.1,1.66]],"id":37208007}],"con":true,"img":false}]}
{"op":"mcm","clk":"5348084933","pt":1646213721701,"mc":[{"id":"1.195453620","rc":[{"atb":[[1.53,14.18]],"id":40410470}],"con":true,"img":false}]}
{"op":"mcm","clk":"5348085182","pt":1646213725901,"mc":[{"id":"1.195453620","rc":[{"atb":[[1.08,1715.51],[1.07,0]],"id":37496564}],"con":true,"img":false}]}
{"op":"mcm","clk":"5348085579","pt":1646213731690,"mc":[{"id":"1.195453620","rc":[{"atb":[[1.26,0]],"id":40310161}],"con":true,"img":false}]}
{"op":"mcm","clk":"5348085588","pt":1646213731793,"mc":[{"id":"1.195453620","rc":[{"atb":[[1.28,91.67],[1.27,0],[1.24,416.67]],"id":40310161}],"con":true,"img":false}]}
{"op":"mcm","clk":"5348085708","pt":1646213734031,"mc":[{"id":"1.195453620","rc":[{"atb":[[1.49,204.08]],"id":40410470},{"spn":2.05,"spf":"NaN","id":40410470},{"spn":11.05,"spf":"NaN","id":37208007},{"spn":1.77,"spf":"NaN","id":40310161}],"con":true,"img":false}]}
{"op":"mcm","clk":"5348085772","pt":1646213734500,"mc":[{"id":"1.195453620","rc":[{"atb":[[1.28,0]],"id":40310161}],"con":true,"img":false}]}
{"op":"mcm","clk":"5348085777","pt":1646213734608,"mc":[{"id":"1.195453620","rc":[{"atb":[[1.26,91.67]],"id":40310161}],"con":true,"img":false}]}
{"op":"mcm","clk":"5348086568","pt":1646213747558,"mc":[{"id":"1.195453620","rc":[{"atl":[[4.1,0]],"id":28447693}],"con":true,"img":false}]}
{"op":"mcm","clk":"5348086574","pt":1646213747613,"mc":[{"id":"1.195453620","rc":[{"atl":[[3.5,15.85]],"id":28447693}],"con":true,"img":false}]}
{"op":"mcm","clk":"5348086579","pt":1646213747716,"mc":[{"id":"1.195453620","rc":[{"atl":[[3.45,15.85]],"id":28447693}],"con":true,"img":false}]}
{"op":"mcm","clk":"5348086587","pt":1646213747818,"mc":[{"id":"1.195453620","rc":[{"atl":[[3.55,0]],"id":28447693}],"con":true,"img":false}]}
{"op":"mcm","clk":"5348086942","pt":1646213754249,"mc":[{"id":"1.195453620","rc":[{"atb":[[1.27,186.93],[1.24,0]],"id":40310161}],"con":true,"img":false}]}
{"op":"mcm","clk":"5348087027","pt":1646213755720,"mc":[{"id":"1.195453620","rc":[{"atb":[[1.53,29.91]],"id":40410470}],"con":true,"img":false}]}
{"op":"mcm","clk":"5348087451","pt":1646213762652,"mc":[{"id":"1.195453620","rc":[{"atl":[[3.5,0]],"id":28447693}],"con":true,"img":false}]}
{"op":"mcm","clk":"5348087463","pt":1646213762757,"mc":[{"id":"1.195453620","rc":[{"atl":[[3.45,0],[4.1,15.85],[3.55,31.7]],"id":28447693}],"con":true,"img":false}]}
{"op":"mcm","clk":"5348089032","pt":1646213788278,"mc":[{"id":"1.195453620","rc":[{"atb":[[1.26,0]],"id":40310161}],"con":true,"img":false}]}
{"op":"mcm","clk":"5348089037","pt":1646213788381,"mc":[{"id":"1.195453620","rc":[{"atb":[[1.28,91.67]],"id":40310161}],"con":true,"img":false}]}
{"op":"mcm","clk":"5348089418","pt":1646213795183,"mc":[{"id":"1.195453620","rc":[{"atl":[[4.1,0]],"id":28447693},{"atb":[[4.9,0]],"id":37208007},{"atl":[[2.66,0]],"id":40310161},{"atb":[[4.9,0]],"id":41574727}],"con":true,"img":false}]}
{"op":"mcm","clk":"5348089427","pt":1646213795284,"mc":[{"id":"1.195453620","rc":[{"atl":[[3.5,15.85]],"id":28447693},{"atb":[[5.1,12.04]],"id":37208007},{"atl":[[2.46,29.42]],"id":40310161},{"atb":[[5.4,11.44]],"id":41574727}],"con":true,"img":false}]}
{"op":"mcm","clk":"5348089702","pt":1646213799419,"mc":[{"id":"1.195453620","rc":[{"atl":[[3.45,15.85],[3.55,0]],"id":28447693},{"atb":[[1.27,0],[1.29,186.93]],"id":40310161}],"con":true,"img":false}]}
{"op":"mcm","clk":"5348089911","pt":1646213803227,"mc":[{"id":"1.195453620","rc":[{"atl":[[2.46,0]],"id":40310161}],"con":true,"img":false}]}
{"op":"mcm","clk":"5348089915","pt":1646213803329,"mc":[{"id":"1.195453620","rc":[{"atl":[[2.66,29.42]],"id":40310161}],"con":true,"img":false}]}
{"op":"mcm","clk":"5348090412","pt":1646213812718,"mc":[{"id":"1.195453620","rc":[{"atl":[[3.5,0]],"id":28447693},{"atb":[[1.28,0]],"id":40310161}],"con":true,"img":false}]}
{"op":"mcm","clk":"5348090418","pt":1646213812822,"mc":[{"id":"1.195453620","rc":[{"atl":[[4.1,15.85]],"id":28447693},{"atb":[[1.26,91.67]],"id":40310161}],"con":true,"img":false}]}
{"op":"mcm","clk":"5348090421","pt":1646213812923,"mc":[{"id":"1.195453620","rc":[{"atl":[[3.45,0],[3.55,31.7]],"id":28447693},{"atb":[[1.29,0],[1.24,416.67]],"id":40310161}],"con":true,"img":false}]}
{"op":"mcm","clk":"5348090929","pt":1646213821344,"mc":[{"id":"1.195453620","rc":[{"atb":[[1.27,186.93]],"id":40310161}],"con":true,"img":false}]}
{"op":"mcm","clk":"5348090934","pt":1646213821445,"mc":[{"id":"1.195453620","rc":[{"atb":[[1.24,0]],"id":40310161}],"con":true,"img":false}]}
{"op":"mcm","clk":"5348091028","pt":1646213823154,"mc":[{"id":"1.195453620","rc":[{"atb":[[1.46,217.39],[1.49,0]],"id":40410470},{"atl":[[3.6,52.42],[3.55,0]],"id":28447693},{"atb":[[1.08,465.51],[1.07,1428.57]],"id":37496564}],"con":true,"img":false}]}
{"op":"mcm","clk":"5348091048","pt":1646213823563,"mc":[{"id":"1.195453620","rc":[{"atb":[[1.23,0]],"id":40310161}],"con":true,"img":false}]}
{"op":"mcm","clk":"5348091055","pt":1646213823667,"mc":[{"id":"1.195453620","rc":[{"atb":[[1.2,186.93]],"id":40310161}],"con":true,"img":false}]}
{"op":"mcm","clk":"5348091426","pt":1646213829349,"mc":[{"id":"1.195453620","rc":[{"atb":[[1.1,0]],"id":37496564}],"con":true,"img":false}]}
{"op":"mcm","clk":"5348091434","pt":1646213829450,"mc":[{"id":"1.195453620","rc":[{"atb":[[1.09,140.25]],"id":37496564}],"con":true,"img":false}]}
{"op":"mcm","clk":"5348091897","pt":1646213837449,"mc":[{"id":"1.195453620","rc":[{"atl":[[2.58,0]],"id":40410470},{"atb":[[1.26,0]],"id":40310161}],"con":true,"img":false}]}
{"op":"mcm","clk":"5348091903","pt":1646213837552,"mc":[{"id":"1.195453620","rc":[{"atl":[[2.78,24.49]],"id":40410470},{"atb":[[1.21,476.19],[1.23,91.67]],"id":40310161}],"con":true,"img":false}]}
{"op":"mcm","clk":"5348091911","pt":1646213837655,"mc":[{"id":"1.195453620","rc":[{"atb":[[1.27,0]],"id":40310161}],"con":true,"img":false}]}
{"op":"mcm","clk":"5348092178","pt":1646213842902,"mc":[{"id":"1.195453620","rc":[{"atb":[[1.21,0],[1.24,186.93]],"id":40310161}],"con":true,"img":false}]}
{"op":"mcm","clk":"5348092321","pt":1646213845478,"mc":[{"id":"1.195453620","rc":[{"atl":[[4.1,0]],"id":28447693}],"con":true,"img":false}]}
{"op":"mcm","clk":"5348092330","pt":1646213845590,"mc":[{"id":"1.195453620","rc":[{"atl":[[3.55,15.85]],"id":28447693}],"con":true,"img":false}]}
{"op":"mcm","clk":"5348092858","pt":1646213855122,"mc":[{"id":"1.195453620","rc":[{"atb":[[5.5,0]],"id":39791282}],"con":true,"img":false}]}
{"op":"mcm","clk":"5348092863","pt":1646213855179,"mc":[{"id":"1.195453620","rc":[{"atb":[[5.7,9.9]],"id":39791282}],"con":true,"img":false}]}
{"op":"mcm","clk":"5348093759","pt":1646213871605,"mc":[{"id":"1.195453620","rc":[{"spn":2.06,"spf":"NaN","id":40410470},{"spn":1.15,"spf":1.0,"id":37496564},{"spn":10.85,"spf":"NaN","id":39791282},{"atl":[[2.66,0]],"id":40310161},{"spn":1.75,"spf":"NaN","id":40310161}],"con":true,"img":false}]}
{"op":"mcm","clk":"5348093763","pt":1646213871707,"mc":[{"id":"1.195453620","rc":[{"atl":[[2.46,29.42]],"id":40310161}],"con":true,"img":false}]}
{"op":"mcm","clk":"5348093961","pt":1646213875517,"mc":[{"id":"1.195453620","rc":[{"atb":[[1.23,0]],"id":40310161}],"con":true,"img":false}]}
{"op":"mcm","clk":"5348093968","pt":1646213875619,"mc":[{"id":"1.195453620","rc":[{"atb":[[1.25,91.67],[1.21,476.19]],"id":40310161}],"con":true,"img":false}]}
{"op":"mcm","clk":"5348093973","pt":1646213875721,"mc":[{"id":"1.195453620","rc":[{"atb":[[1.26,186.93],[1.24,0]],"id":40310161}],"con":true,"img":false}]}
{"op":"mcm","clk":"5348093976","pt":1646213875825,"mc":[{"id":"1.195453620","rc":[{"atb":[[1.21,0]],"id":40310161}],"con":true,"img":false}]}
{"op":"mcm","clk":"5348094228","pt":1646213880580,"mc":[{"id":"1.195453620","rc":[{"atb":[[4.6,0]],"id":37208007}],"con":true,"img":false}]}
{"op":"mcm","clk":"5348094232","pt":1646213880632,"mc":[{"id":"1.195453620","rc":[{"atb":[[5.1,22.19]],"id":37208007}],"con":true,"img":false}]}
{"op":"mcm","clk":"5348094893","pt":1646213891769,"mc":[{"id":"1.195453620","rc":[{"atb":[[1.25,0]],"id":40310161}],"con":true,"img":false}]}
{"op":"mcm","clk":"5348094897","pt":1646213891872,"mc":[{"id":"1.195453620","rc":[{"atb":[[1.23,91.67]],"id":40310161}],"con":true,"img":false}]}
{"op":"mcm","clk":"5348094901","pt":1646213891976,"mc":[{"id":"1.195453620","rc":[{"atb":[[1.21,476.19],[1.26,0]],"id":40310161}],"con":true,"img":false}]}
{"op":"mcm","clk":"5348096136","pt":1646213912810,"mc":[{"id":"1.195453620","rc":[{"atb":[[1.21,0],[1.24,186.93]],"id":40310161}],"con":true,"img":false}]}
{"op":"mcm","clk":"5348098076","pt":1646213945073,"mc":[{"id":"1.195453620","rc":[{"atb":[[1.23,0]],"id":40310161}],"con":true,"img":false}]}
{"op":"mcm","clk":"5348098082","pt":1646213945180,"mc":[{"id":"1.195453620","rc":[{"atb":[[1.25,91.67]],"id":40310161}],"con":true,"img":false}]}
{"op":"mcm","clk":"5348098088","pt":1646213945283,"mc":[{"id":"1.195453620","rc":[{"atb":[[1.21,476.19],[1.24,0]],"id":40310161}],"con":true,"img":false}]}
{"op":"mcm","clk":"5348098096","pt":1646213945438,"mc":[{"id":"1.195453620","rc":[{"atb":[[1.21,0],[1.26,186.93]],"id":40310161}],"con":true,"img":false}]}
{"op":"mcm","clk":"5348098607","pt":1646213954893,"mc":[{"id":"1.195453620","rc":[{"atb":[[1.46,0],[1.47,212.77]],"id":40410470},{"atl":[[3.6,13.96],[3.5,22.69]],"id":28447693},{"atb":[[1.08,1715.51],[1.07,0]],"id":37496564},{"atb":[[3.25,44.44],[3.65,0]],"id":37208007}],"con":true,"img":false}]}
{"op":"mcm","clk":"5348098614","pt":1646213954945,"mc":[{"id":"1.195453620","rc":[{"atb":[[1.54,99.09],[1.47,0]],"id":40410470},{"atb":[[3.25,0],[3.65,37.74]],"id":37208007}],"con":true,"img":false}]}
{"op":"mcm","clk":"5348098760","pt":1646213957166,"mc":[{"id":"1.195453620","rc":[{"atb":[[1.53,15.73]],"id":40410470}],"con":true,"img":false}]}
{"op":"mcm","clk":"5348098906","pt":1646213959701,"mc":[{"id":"1.195453620","rc":[{"atb":[[5.4,0]],"id":41574727}],"con":true,"img":false}]}
{"op":"mcm","clk":"5348098911","pt":1646213959799,"mc":[{"id":"1.195453620","rc":[{"atb":[[4.9,11.44]],"id":41574727}],"con":true,"img":false}]}
{"op":"mcm","clk":"5348099104","pt":1646213963094,"mc":[{"id":"1.195453620","rc":[{"atb":[[5.1,12.04]],"id":37208007},{"atb":[[1.25,0]],"id":40310161}],"con":true,"img":false}]}
{"op":"mcm","clk":"5348099109","pt":1646213963196,"mc":[{"id":"1.195453620","rc":[{"atb":[[4.6,10.14]],"id":37208007},{"atb":[[1.23,91.67]],"id":40310161}],"con":true,"img":false}]}
{"op":"mcm","clk":"5348099115","pt":1646213963299,"mc":[{"id":"1.195453620","rc":[{"atb":[[1.21,476.19],[1.26,0]],"id":40310161}],"con":true,"img":false}]}
{"op":"mcm","clk":"5348099233","pt":1646213965667,"mc":[{"id":"1.195453620","rc":[{"atb":[[1.58,12.96]],"id":40410470}],"con":true,"img":false}]}
{"op":"mcm","clk":"5348099240","pt":1646213965772,"mc":[{"id":"1.195453620","rc":[{"atb":[[1.54,0]],"id":40410470}],"con":true,"img":false}]}
{"op":"mcm","clk":"5348099247","pt":1646213965875,"mc":[{"id":"1.195453620","rc":[{"atb":[[1.55,99.09]],"id":40410470}],"con":true,"img":false}]}
{"op":"mcm","clk":"5348099397","pt":1646213968202,"mc":[{"id":"1.195453620","rc":[{"atb":[[1.58,0]],"id":40410470}],"con":true,"img":false}]}
{"op":"mcm","clk":"5348099559","pt":1646213971089,"mc":[{"id":"1.195453620","rc":[{"atb":[[1.55,0],[1.54,185.19]],"id":40410470}],"con":true,"img":false}]}
{"op":"mcm","clk":"5348099874","pt":1646213977137,"mc":[{"id":"1.195453620","rc":[{"atb":[[1.53,0]],"id":40410470}],"con":true,"img":false}]}
{"op":"mcm","clk":"5348099886","pt":1646213977339,"mc":[{"id":"1.195453620","rc":[{"atb":[[1.54,0],[1.51,196.08]],"id":40410470}],"con":true,"img":false}]}
{"op":"mcm","clk":"5348100245","pt":1646213983352,"mc":[{"id":"1.195453620","rc":[{"atb":[[1.24,186.93]],"id":40310161}],"con":true,"img":false}]}
{"op":"mcm","clk":"5348100253","pt":1646213983455,"mc":[{"id":"1.195453620","rc":[{"atb":[[1.21,0]],"id":40310161}],"con":true,"img":false}]}
{"op":"mcm","clk":"5348100449","pt":1646213986255,"mc":[{"id":"1.195453620","rc":[{"atb":[[1.54,13.92]],"id":40410470}],"con":true,"img":false}]}
{"op":"mcm","clk":"5348100623","pt":1646213989554,"mc":[{"id":"1.195453620","rc":[{"atb":[[1.5,0]],"id":40410470},{"atl":[[2.78,0]],"id":40410470},{"atl":[[3.55,0]],"id":28447693},{"atb":[[1.23,0]],"id":40310161}],"con":true,"img":false}]}
{"op":"mcm","clk":"5348100625","pt":1646213989658,"mc":[{"id":"1.195453620","rc":[{"atb":[[1.52,99.08]],"id":40410470},{"atl":[[2.58,24.49]],"id":40410470},{"atl":[[3.45,15.85]],"id":28447693},{"atb":[[1.22,91.67]],"id":40310161}],"con":true,"img":false}]}
{"op":"mcm","clk":"5348100631","pt":1646213989762,"mc":[{"id":"1.195453620","rc":[{"atl":[[3.55,39.22],[3.5,0]],"id":28447693},{"atb":[[1.21,476.19],[1.24,0]],"id":40310161}],"con":true,"img":false}]}
{"op":"mcm","clk":"5348100839","pt":1646213993335,"mc":[{"id":"1.195453620","rc":[{"atb":[[1.54,0]],"id":40410470}],"con":true,"img":false}]}
{"op":"mcm","clk":"5348101053","pt":1646213997389,"mc":[{"id":"1.195453620","rc":[{"atb":[[1.51,0],[1.53,113.36]],"id":40410470}],"con":true,"img":false}]}
{"op":"mcm","clk":"5348101229","pt":1646214000030,"mc":[{"id":"1.195453620","rc":[{"atl":[[3.45,0]],"id":28447693}],"con":true,"img":false}]}
{"op":"mcm","clk":"5348101237","pt":1646214000131,"mc":[{"id":"1.195453620","rc":[{"atl":[[3.5,15.85]],"id":28447693}],"con":true,"img":false}]}
{"op":"mcm","clk":"5348101520","pt":1646214004353,"mc":[{"id":"1.195453620","rc":[{"atb":[[1.57,13.18]],"id":40410470}],"con":true,"img":false}]}
{"op":"mcm","clk":"5348101885","pt":1646214009570,"mc":[{"id":"1.195453620","rc":[{"spn":2.07,"spf":"NaN","id":40410470},{"atl":[[3.45,15.85],[3.55,0]],"id":28447693},{"atb":[[1.21,0],[1.23,186.93]],"id":40310161},{"spn":1.74,"spf":"NaN","id":40310161}],"con":true,"img":false}]}
{"op":"mcm","clk":"5348102334","pt":1646214016571,"mc":[{"id":"1.195453620","rc":[{"atb":[[1.57,27.8]],"id":40410470}],"con":true,"img":false}]}
{"op":"mcm","clk":"5348102369","pt":1646214017202,"mc":[{"id":"1.195453620","rc":[{"atb":[[1.55,113.36],[1.53,0]],"id":40410470}],"con":true,"img":false}]}
{"op":"mcm","clk":"5348102497","pt":1646214019273,"mc":[{"id":"1.195453620","rc":[{"atb":[[1.57,14.62]],"id":40410470}],"con":true,"img":false}]}
{"op":"mcm","clk":"5348102828","pt":1646214024807,"mc":[{"id":"1.195453620","rc":[{"atb":[[1.21,164.09],[1.22,0]],"id":40310161}],"con":true,"img":false}]}
{"op":"mcm","clk":"5348102843","pt":1646214025008,"mc":[{"id":"1.195453620","rc":[{"atb":[[1.23,0],[1.22,373.86]],"id":40310161}],"con":true,"img":false}]}
{"op":"mcm","clk":"5348102861","pt":1646214025314,"mc":[{"id":"1.195453620","rc":[{"atb":[[1.59,12.74]],"id":40410470}],"con":true,"img":false}]}
{"op":"mcm","clk":"5348103047","pt":1646214028792,"mc":[{"id":"1.195453620","rc":[{"atb":[[1.52,0]],"id":40410470}],"con":true,"img":false}]}
{"op":"mcm","clk":"5348103053","pt":1646214028892,"mc":[{"id":"1.195453620","rc":[{"atb":[[1.56,99.08]],"id":40410470}],"con":true,"img":false}]}
{"op":"mcm","clk":"5348103195","pt":1646214031353,"mc":[{"id":"1.195453620","rc":[{"atb":[[1.59,0]],"id":40410470}],"con":true,"img":false}]}
{"op":"mcm","clk":"5348103509","pt":1646214037295,"mc":[{"id":"1.195453620","rc":[{"atb":[[1.6,12.53]],"id":40410470}],"con":true,"img":false}]}
{"op":"mcm","clk":"5348103790","pt":1646214042009,"mc":[{"id":"1.195453620","rc":[{"atl":[[3.5,0]],"id":28447693}],"con":true,"img":false}]}
{"op":"mcm","clk":"5348103795","pt":1646214042116,"mc":[{"id":"1.195453620","rc":[{"atl":[[3.4,15.85],[3.55,31.7]],"id":28447693}],"con":true,"img":false}]}
{"op":"mcm","clk":"5348103801","pt":1646214042220,"mc":[{"id":"1.195453620","rc":[{"atl":[[3.45,0]],"id":28447693}],"con":true,"img":false}]}
{"op":"mcm","clk":"5348104014","pt":1646214045836,"mc":[{"id":"1.195453620","rc":[{"atb":[[1.57,0]],"id":40410470}],"con":true,"img":false}]}
{"op":"mcm","clk":"5348104562","pt":1646214055964,"mc":[{"id":"1.195453620","rc":[{"atb":[[1.8,61.79],[1.89,0]],"id":39791282}],"con":true,"img":false}]}
{"op":"mcm","clk":"5348104647","pt":1646214057623,"mc":[{"id":"1.195453620","rc":[{"atl":[[3.4,0]],"id":28447693},{"atb":[[1.21,0],[1.23,114.05]],"id":40310161}],"con":true,"img":false}]}
{"op":"mcm","clk":"5348104652","pt":1646214057729,"mc":[{"id":"1.195453620","rc":[{"atl":[[3.5,15.85]],"id":28447693},{"atb":[[1.24,186.93]],"id":40310161}],"con":true,"img":false}]}
{"op":"mcm","clk":"5348104658","pt":1646214057830,"mc":[{"id":"1.195453620","rc":[{"atb":[[1.22,0]],"id":40310161}],"con":true,"img":false}]}
{"op":"mcm","clk":"5348104741","pt":1646214059539,"mc":[{"id":"1.195453620","rc":[{"atb":[[1.6,26.43]],"id":40410470}],"con":true,"img":false}]}
{"op":"mcm","clk":"5348104830","pt":1646214061454,"mc":[{"id":"1.195453620","rc":[{"atl":[[3.45,15.85],[3.55,0]],"id":28447693}],"con":true,"img":false}]}
{"op":"mcm","clk":"5348104851","pt":1646214061980,"mc":[{"id":"1.195453620","rc":[{"atb":[[1.46,108.7],[1.44,170.45],[1.42,250],[1.48,41.67]],"id":40410470},{"atl":[[4.3,37.88],[3.85,7.02],[3.95,16.95],[4.1,24.19]],"id":40410470},{"atb":[[1.72,27.78],[1.7,214.02],[1.68,110.29],[1.66,189.39]],"id":28447693},{"atl":[[3.45,66.87],[3.35,31.91],[3.15,9.3],[3.25,22.22]],"id":28447693},{"atb":[[1.01,20212.94],[1.03,250],[1.07,250],[1.05,250]],"id":37496564},{"atl":[[3.85,43.86],[3.55,7.84],[3.65,18.87],[3.75,27.27]],"id":37496564},{"atb":[[1.84,148.81],[1.88,56.82],[1.9,22.22],[1.86,87.21]],"id":39791282},{"atl":[[16.5,4.84],[17.5,7.58],[14.5,1.48],[15.5,3.45]],"id":39791282},{"atb":[[1.03,250],[1.09,222.22],[1.07,250],[1.05,250]],"id":42464658},{"atl":[[4,25],[3.8,7.14],[3.9,17.24],[4.2,39.06]],"id":42464658},{"atb":[[4,39.94],[3.7,46.3],[3.8,26.79],[3.9,17.24]],"id":37208007},{"atl":[[16,8.33],[13,1.67],[14,3.85],[15,5.36]],"id":37208007},{"atb":[[1.2,436.93],[1.26,76.92],[1.22,250],[1.24,395.26]],"id":40310161},{"atl":[[2.3,57.69],[2.22,16.39],[2.26,69.53],[2.34,93.28]],"id":40310161},{"atb":[[3.2,56.82],[3.4,20.83],[3.5,8],[3.3,32.61]],"id":41574727},{"atl":[[18.5,1.14],[19,3.12],[19.5,2.7],[20,2.63],[21,3.75],[22,3.57],[23,5.68],[24,5.43]],"id":41574727}],"con":true,"img":false}]}
{"op":"mcm","clk":"5348104865","pt":1646214062173,"mc":[{"id":"1.195453620","rc":[{"atl":[[3.45,51.02],[3.4,41.67]],"id":28447693},{"atl":[[16,2.41],[14.5,4.93]],"id":39791282},{"atl":[[18.5,0],[19.5,0],[21,0],[23,0]],"id":41574727}],"con":true,"img":false}]}
{"op":"mcm","clk":"5348104941","pt":1646214063475,"mc":[{"id":"1.195453620","rc":[{"atb":[[4.6,0]],"id":39791282},{"atb":[[4.6,0]],"id":37208007},{"atl":[[23,2.72]],"id":37208007}],"con":true,"img":false}]}
{"op":"mcm","clk":"5348104946","pt":1646214063575,"mc":[{"id":"1.195453620","rc":[{"atb":[[4.1,11.37]],"id":39791282},{"atb":[[4.1,10.14]],"id":37208007},{"atl":[[27,2.72]],"id":37208007}],"con":true,"img":false}]}
{"op":"mcm","clk":"5348105181","pt":1646214067266,"mc":[{"id":"1.195453620","rc":[{"atl":[[14.5,1.48],[15.5,10.35]],"id":39791282}],"con":true,"img":false}]}
{"op":"mcm","clk":"5348105331","pt":1646214069350,"mc":[{"id":"1.195453620","rc":[{"atl":[[2.58,0]],"id":40410470}],"con":true,"img":false}]}
{"op":"mcm","clk":"5348105340","pt":1646214069456,"mc":[{"id":"1.195453620","rc":[{"atl":[[2.78,24.49]],"id":40410470}],"con":true,"img":false}]}
{"op":"mcm","clk":"5348105481","pt":1646214071367,"mc":[{"id":"1.195453620","rc":[{"spn":2.1,"spf":"NaN","id":40410470},{"atb":[[5.7,0]],"id":39791282},{"spn":9.5,"spf":"NaN","id":39791282},{"spn":9.05,"spf":"NaN","id":37208007},{"spn":1.74,"spf":"NaN","id":40310161}],"con":true,"img":false}]}
{"op":"mcm","clk":"5348105487","pt":1646214071470,"mc":[{"id":"1.195453620","rc":[{"atb":[[4.8,9.9]],"id":39791282}],"con":true,"img":false}]}
{"op":"mcm","clk":"5348105682","pt":1646214074887,"mc":[{"id":"1.195453620","rc":[{"atb":[[1.55,0],[1.51,196.08]],"id":40410470},{"atl":[[3.55,39.22]],"id":28447693},{"atb":[[1.08,465.51],[1.07,1678.57]],"id":37496564}],"con":true,"img":false}]}
{"op":"mcm","clk":"5348105688","pt":1646214074992,"mc":[{"id":"1.195453620","rc":[{"atl":[[3.4,0]],"id":28447693}],"con":true,"img":false}]}
{"op":"mcm","clk":"5348105696","pt":1646214075093,"mc":[{"id":"1.195453620","rc":[{"atb":[[1.54,125.52]],"id":40410470},{"atb":[[1.08,931.02],[1.07,250]],"id":37496564},{"atl":[[3.7,34.29],[3.8,0]],"id":42464658},{"atl":[[13,0],[13.5,1.6]],"id":37208007},{"atl":[[2.22,0],[2.2,16.67],[3.3,0],[3.05,48.78]],"id":40310161}],"con":true,"img":false}]}
{"op":"mcm","clk":"5348105706","pt":1646214075193,"mc":[{"id":"1.195453620","rc":[{"atb":[[1.51,0]],"id":40410470}],"con":true,"img":false}]}
{"op":"mcm","clk":"5348105714","pt":1646214075296,"mc":[{"id":"1.195453620","rc":[{"atb":[[4.9,1.66]],"id":39791282}],"con":true,"img":false}]}
{"op":"mcm","clk":"5348105719","pt":1646214075400,"mc":[{"id":"1.195453620","rc":[{"atl":[[1.98,0]],"id":37496564}],"con":true,"img":false}]}
{"op":"mcm","clk":"5348105724","pt":1646214075503,"mc":[{"id":"1.195453620","rc":[{"atl":[[2.12,32.1]],"id":37496564}],"con":true,"img":false}]}
{"op":"mcm","clk":"5348106328","pt":1646214081506,"mc":[{"id":"1.195453620","rc":[{"atb":[[1.56,0]],"id":40410470}],"con":true,"img":false}]}
{"op":"mcm","clk":"5348106334","pt":1646214081609,"mc":[{"id":"1.195453620","rc":[{"atb":[[1.55,99.08]],"id":40410470}],"con":true,"img":false}]}
{"op":"mcm","clk":"5348106420","pt":1646214083131,"mc":[{"id":"1.195453620","rc":[{"atb":[[1.6,13.89]],"id":40410470}],"con":true,"img":false}]}
{"op":"mcm","clk":"5348106434","pt":1646214083421,"mc":[{"id":"1.195453620","rc":[{"atl":[[25,2.72]],"id":41574727}],"con":true,"img":false}]}
{"op":"mcm","clk":"5348106438","pt":1646214083476,"mc":[{"id":"1.195453620","rc":[{"atl":[[23,2.72]],"id":41574727}],"con":true,"img":false}]}
{"op":"mcm","clk":"5348106523","pt":1646214085131,"mc":[{"id":"1.195453620","rc":[{"atl":[[3.8,17.86]],"id":42464658},{"atl":[[14.5,3.7]],"id":37208007}],"con":true,"img":false}]}
{"op":"mcm","clk":"5348106537","pt":1646214085393,"mc":[{"id":"1.195453620","rc":[{"atl":[[3.5,0]],"id":28447693},{"atl":[[23,0]],"id":37208007}],"con":true,"img":false}]}
{"op":"mcm","clk":"5348106540","pt":1646214085493,"mc":[{"id":"1.195453620","rc":[{"atl":[[3.3,15.85]],"id":28447693},{"atl":[[15.5,2.72]],"id":37208007}],"con":true,"img":false}]}
{"op":"mcm","clk":"5348106652","pt":1646214087412,"mc":[{"id":"1.195453620","rc":[{"atl":[[44,0]],"id":39791282}],"con":true,"img":false}]}
{"op":"mcm","clk":"5348106659","pt":1646214087510,"mc":[{"id":"1.195453620","rc":[{"atl":[[15,2.72]],"id":39791282}],"con":true,"img":false}]}
{"op":"mcm","clk":"5348106752","pt":1646214089226,"mc":[{"id":"1.195453620","rc":[{"atl":[[4.2,0]],"id":42464658},{"atl":[[16,0],[14,0],[15,0]],"id":37208007}],"con":true,"img":false}]}
{"op":"mcm","clk":"5348106843","pt":1646214090900,"mc":[{"id":"1.195453620","rc":[{"atb":[[1.59,12.74]],"id":40410470}],"con":true,"img":false}]}
{"op":"mcm","clk":"5348106864","pt":1646214091418,"mc":[{"id":"1.195453620","rc":[{"atl":[[15.5,0]],"id":37208007}],"con":true,"img":false}]}
{"op":"mcm","clk":"5348106869","pt":1646214091524,"mc":[{"id":"1.195453620","rc":[{"atl":[[24,5.88]],"id":37208007}],"con":true,"img":false}]}
{"op":"mcm","clk":"5348106976","pt":1646214093235,"mc":[{"id":"1.195453620","rc":[{"atb":[[1.55,198.17],[1.54,0]],"id":40410470},{"atb":[[1.08,465.51],[1.07,1321.28]],"id":37496564},{"atl":[[3.7,26.88],[3.65,24]],"id":42464658},{"atl":[[2.24,16.13],[2.2,0]],"id":40310161}],"con":true,"img":false}]}
{"op":"mcm","clk":"5348106989","pt":1646214093437,"mc":[{"id":"1.195453620","rc":[{"atb":[[1.08,746.03],[1.07,250]],"id":37496564}],"con":true,"img":false}]}
{"op":"mcm","clk":"5348107013","pt":1646214093909,"mc":[{"id":"1.195453620","rc":[{"atl":[[3.4,39.22],[3.55,0]],"id":28447693}],"con":true,"img":false}]}
{"op":"mcm","clk":"5348107068","pt":1646214095101,"mc":[{"id":"1.195453620","rc":[{"atl":[[15.5,5.17]],"id":37208007}],"con":true,"img":false}]}
{"op":"mcm","clk":"5348107375","pt":1646214100234,"mc":[{"id":"1.195453620","rc":[{"atb":[[1.6,0]],"id":40410470}],"con":true,"img":false}]}
{"op":"mcm","clk":"5348107534","pt":1646214103236,"mc":[{"id":"1.195453620","rc":[{"atl":[[2.28,67.41]],"id":40310161}],"con":true,"img":false}]}
{"op":"mcm","clk":"5348107542","pt":1646214103343,"mc":[{"id":"1.195453620","rc":[{"atb":[[1.47,88.83]],"id":40410470}],"con":true,"img":false}]}
{"op":"mcm","clk":"5348107548","pt":1646214103446,"mc":[{"id":"1.195453620","rc":[{"atb":[[1.37,0]],"id":40410470},{"atb":[[1.59,0]],"id":28447693},{"atl":[[25,0]],"id":41574727}],"con":true,"img":false}]}
{"op":"mcm","clk":"5348107553","pt":1646214103549,"mc":[{"id":"1.195453620","rc":[{"atb":[[1.71,73.02]],"id":28447693},{"atl":[[23,5.44]],"id":41574727}],"con":true,"img":false}]}
{"op":"mcm","clk":"5348107642","pt":1646214105154,"mc":[{"id":"1.195453620","rc":[{"atl":[[16.5,8.06]],"id":37208007}],"con":true,"img":false}]}
{"op":"mcm","clk":"5348107754","pt":1646214107431,"mc":[{"id":"1.195453620","rc":[{"atl":[[48,0]],"id":39791282}],"con":true,"img":false}]}
{"op":"mcm","clk":"5348107757","pt":1646214107534,"mc":[{"id":"1.195453620","rc":[{"atl":[[21,2.72]],"id":39791282}],"con":true,"img":false}]}
{"op":"mcm","clk":"5348108023","pt":1646214113263,"mc":[{"id":"1.195453620","rc":[{"atl":[[2.3,0],[2.32,56.82],[2.26,29.85],[2.34,0]],"id":40310161}],"con":true,"img":false}]}
{"op":"mcm","clk":"5348108118","pt":1646214115446,"mc":[{"id":"1.195453620","rc":[{"atb":[[1.59,26.87]],"id":40410470}],"con":true,"img":false}]}
{"op":"mcm","clk":"5348108195","pt":1646214117359,"mc":[{"id":"1.195453620","rc":[{"atb":[[4.1,0]],"id":39791282},{"atl":[[24,3.15]],"id":37208007}],"con":true,"img":false}]}
{"op":"mcm","clk":"5348108201","pt":1646214117464,"mc":[{"id":"1.195453620","rc":[{"atb":[[4.6,11.37]],"id":39791282},{"atl":[[16,2.72]],"id":37208007}],"con":true,"img":false}]}
{"op":"mcm","clk":"5348108526","pt":1646214123267,"mc":[{"id":"1.195453620","rc":[{"atl":[[2.36,91.91]],"id":40310161}],"con":true,"img":false}]}
{"op":"mcm","clk":"5348108650","pt":1646214125443,"mc":[{"id":"1.195453620","rc":[{"atl":[[2.12,0]],"id":37496564}],"con":true,"img":false}]}
{"op":"mcm","clk":"5348108659","pt":1646214125546,"mc":[{"id":"1.195453620","rc":[{"atl":[[1.98,32.1]],"id":37496564}],"con":true,"img":false}]}
{"op":"mcm","clk":"5348109196","pt":1646214133413,"mc":[{"id":"1.195453620","rc":[{"spn":2.09,"spf":"NaN","id":40410470},{"spn":9.7,"spf":"NaN","id":39791282},{"atb":[[4.1,0]],"id":37208007},{"spn":9.3,"spf":"NaN","id":37208007},{"spn":1.75,"spf":"NaN","id":40310161},{"atb":[[4.9,0]],"id":41574727}],"con":true,"img":false}]}
{"op":"mcm","clk":"5348109202","pt":1646214133470,"mc":[{"id":"1.195453620","rc":[{"atb":[[4.6,10.14]],"id":37208007},{"atb":[[5.4,11.44]],"id":41574727}],"con":true,"img":false}]}
{"op":"mcm","clk":"5348109322","pt":1646214135379,"mc":[{"id":"1.195453620","rc":[{"atl":[[3.3,0]],"id":28447693},{"atb":[[1.66,55.59],[1.61,0]],"id":42464658}],"con":true,"img":false}]}
{"op":"mcm","clk":"5348109326","pt":1646214135481,"mc":[{"id":"1.195453620","rc":[{"atl":[[3.2,15.85]],"id":28447693}],"con":true,"img":false}]}
{"op":"mcm","clk":"5348109437","pt":1646214137392,"mc":[{"id":"1.195453620","rc":[{"atl":[[16,0],[27,0]],"id":37208007},{"atl":[[23,2.72]],"id":41574727}],"con":true,"img":false}]}
{"op":"mcm","clk":"5348109446","pt":1646214137496,"mc":[{"id":"1.195453620","rc":[{"atl":[[21,2.72],[15,2.72]],"id":37208007},{"atl":[[21,2.72]],"id":41574727}],"con":true,"img":false}]}
{"op":"mcm","clk":"5348109853","pt":1646214145416,"mc":[{"id":"1.195453620","rc":[{"atl":[[15,0]],"id":37208007}],"con":true,"img":false}]}
{"op":"mcm","clk":"5348109856","pt":1646214145470,"mc":[{"id":"1.195453620","rc":[{"atl":[[16,2.72]],"id":37208007}],"con":true,"img":false}]}
{"op":"mcm","clk":"5348110600","pt":1646214159441,"mc":[{"id":"1.195453620","rc":[{"atb":[[1.23,0]],"id":40310161}],"con":true,"img":false}]}
{"op":"mcm","clk":"5348110604","pt":1646214159494,"mc":[{"id":"1.195453620","rc":[{"atb":[[1.3,114.05]],"id":40310161}],"con":true,"img":false}]}
{"op":"mcm","clk":"5348110611","pt":1646214159601,"mc":[{"id":"1.195453620","rc":[{"atb":[[1.22,704.55],[1.24,208.33]],"id":40310161}],"con":true,"img":false}]}
{"op":"mcm","clk":"5348111634","pt":1646214177732,"mc":[{"id":"1.195453620","rc":[{"atb":[[1.22,250],[1.31,114.06]],"id":40310161}],"con":true,"img":false}]}
{"op":"mcm","clk":"5348111725","pt":1646214179380,"mc":[{"id":"1.195453620","rc":[{"atb":[[1.2,250]],"id":40310161}],"con":true,"img":false}]}
{"op":"mcm","clk":"5348111728","pt":1646214179431,"mc":[{"id":"1.195453620","rc":[{"atb":[[1.27,186.93]],"id":40310161}],"con":true,"img":false}]}
{"op":"mcm","clk":"5348112220","pt":1646214187394,"mc":[{"id":"1.195453620","rc":[{"atl":[[16,0]],"id":37208007}],"con":true,"img":false}]}
{"op":"mcm","clk":"5348112225","pt":1646214187497,"mc":[{"id":"1.195453620","rc":[{"atl":[[15,2.72]],"id":37208007}],"con":true,"img":false}]}
{"op":"mcm","clk":"5348112962","pt":1646214199418,"mc":[{"id":"1.195453620","rc":[{"atb":[[1.3,0]],"id":40310161},{"spn":1.77,"spf":"NaN","id":40310161}],"con":true,"img":false}]}
{"op":"mcm","clk":"5348112967","pt":1646214199474,"mc":[{"id":"1.195453620","rc":[{"atb":[[1.32,114.05]],"id":40310161}],"con":true,"img":false}]}
{"op":"mcm","clk":"5348112975","pt":1646214199573,"mc":[{"id":"1.195453620","rc":[{"atb":[[1.28,228.12],[1.31,0]],"id":40310161}],"con":true,"img":false}]}
{"op":"mcm","clk":"5348112979","pt":1646214199676,"mc":[{"id":"1.195453620","rc":[{"atb":[[1.28,0],[1.33,186.93]],"id":40310161}],"con":true,"img":false}]}
{"op":"mcm","clk":"5348113862","pt":1646214213212,"mc":[{"id":"1.195453620","rc":[{"atb":[[1.55,99.08],[1.51,196.08]],"id":40410470},{"atl":[[3.6,52.42],[3.4,0]],"id":28447693},{"atb":[[1.08,465.51],[1.07,1136.29]],"id":37496564}],"con":true,"img":false}]}
{"op":"mcm","clk":"5348114431","pt":1646214221352,"mc":[{"id":"1.195453620","rc":[{"atb":[[1.55,0]],"id":40410470},{"atl":[[4.3,0]],"id":42464658},{"atb":[[1.32,0]],"id":40310161}],"con":true,"img":false}]}
{"op":"mcm","clk":"5348114437","pt":1646214221455,"mc":[{"id":"1.195453620","rc":[{"atb":[[1.52,99.08]],"id":40410470},{"atl":[[3.95,11.11]],"id":42464658},{"atb":[[1.34,114.05]],"id":40310161}],"con":true,"img":false}]}
{"op":"mcm","clk":"5348114443","pt":1646214221558,"mc":[{"id":"1.195453620","rc":[{"atb":[[1.28,357.14],[1.33,0]],"id":40310161}],"con":true,"img":false}]}
{"op":"mcm","clk":"5348114451","pt":1646214221661,"mc":[{"id":"1.195453620","rc":[{"atb":[[1.28,0],[1.35,186.93]],"id":40310161}],"con":true,"img":false}]}
{"op":"mcm","clk":"5348114602","pt":1646214224336,"mc":[{"id":"1.195453620","rc":[{"atb":[[1.59,14.12]],"id":40410470}],"con":true,"img":false}]}
{"op":"mcm","clk":"5348114665","pt":1646214225319,"mc":[{"id":"1.195453620","rc":[{"atl":[[2.46,0]],"id":40310161}],"con":true,"img":false}]}
{"op":"mcm","clk":"5348114674","pt":1646214225423,"mc":[{"id":"1.195453620","rc":[{"atl":[[2.66,29.42]],"id":40310161}],"con":true,"img":false}]}
{"op":"mcm","clk":"5348114929","pt":1646214230070,"mc":[{"id":"1.195453620","rc":[{"atb":[[1.55,13.66]],"id":40410470},{"atb":[[1.38,19.78]],"id":40310161}],"con":true,"img":false}]}
{"op":"mcm","clk":"5348114941","pt":1646214230275,"mc":[{"id":"1.195453620","rc":[{"atb":[[1.36,186.93],[1.35,0]],"id":40310161}],"con":true,"img":false}]}
{"op":"mcm","clk":"5348114987","pt":1646214231357,"mc":[{"id":"1.195453620","rc":[{"atb":[[1.34,0]],"id":40310161}],"con":true,"img":false}]}
{"op":"mcm","clk":"5348114995","pt":1646214231460,"mc":[{"id":"1.195453620","rc":[{"atb":[[1.31,114.05]],"id":40310161}],"con":true,"img":false}]}
{"op":"mcm","clk":"5348115081","pt":1646214233166,"mc":[{"id":"1.195453620","rc":[{"atb":[[1.38,0]],"id":40310161}],"con":true,"img":false}]}
{"op":"mcm","clk":"5348115092","pt":1646214233375,"mc":[{"id":"1.195453620","rc":[{"atb":[[1.36,0],[1.32,312.5]],"id":40310161}],"con":true,"img":false}]}
{"op":"mcm","clk":"5348115775","pt":1646214244191,"mc":[{"id":"1.195453620","rc":[{"atb":[[1.59,0]],"id":40410470}],"con":true,"img":false}]}
{"op":"mcm","clk":"5348116331","pt":1646214253390,"mc":[{"id":"1.195453620","rc":[{"atb":[[1.31,0]],"id":40310161}],"con":true,"img":false}]}
{"op":"mcm","clk":"5348116337","pt":1646214253513,"mc":[{"id":"1.195453620","rc":[{"atb":[[1.28,357.14],[1.32,0],[1.33,114.05]],"id":40310161}],"con":true,"img":false}]}
{"op":"mcm","clk":"5348116449","pt":1646214255416,"mc":[{"id":"1.195453620","rc":[{"atb":[[1.55,112.75],[1.51,0]],"id":40410470},{"atl":[[3.6,13.96],[3.4,41.67]],"id":28447693},{"atb":[[1.08,931.02],[1.07,250]],"id":37496564},{"atl":[[3.95,0]],"id":42464658},{"atb":[[1.33,0]],"id":40310161}],"con":true,"img":false}]}
{"op":"mcm","clk":"5348116452","pt":1646214255509,"mc":[{"id":"1.195453620","rc":[{"atl":[[4.3,11.11]],"id":42464658},{"atb":[[1.3,114.05]],"id":40310161}],"con":true,"img":false}]}
{"op":"mcm","clk":"5348116716","pt":1646214260221,"mc":[{"id":"1.195453620","rc":[{"atb":[[1.55,99.09]],"id":40410470},{"spn":2.07,"spf":"NaN","id":40410470},{"spn":1.77,"spf":"NaN","id":40310161}],"con":true,"img":false}]}
{"op":"mcm","clk":"5348116743","pt":1646214260634,"mc":[{"id":"1.195453620","rc":[{"atb":[[1.55,0],[1.53,188.68]],"id":40410470}],"con":true,"img":false}]}
{"op":"mcm","clk":"5348117335","pt":1646214269248,"mc":[{"id":"1.195453620","rc":[{"atb":[[1.57,13.18]],"id":40410470}],"con":true,"img":false}]}
{"op":"mcm","clk":"5348117425","pt":1646214270750,"mc":[{"id":"1.195453620","rc":[{"atb":[[1.28,0],[1.31,186.93]],"id":40310161}],"con":true,"img":false}]}
{"op":"mcm","clk":"5348117548","pt":1646214272656,"mc":[{"id":"1.195453620","rc":[{"atb":[[1.55,99.09],[1.53,0]],"id":40410470}],"con":true,"img":false}]}
{"op":"mcm","clk":"5348117733","pt":1646214275380,"mc":[{"id":"1.195453620","rc":[{"atl":[[2.66,0]],"id":40310161}],"con":true,"img":false}]}
{"op":"mcm","clk":"5348117740","pt":1646214275440,"mc":[{"id":"1.195453620","rc":[{"atl":[[2.46,29.42]],"id":40310161}],"con":true,"img":false}]}
{"op":"mcm","clk":"5348117784","pt":1646214276060,"mc":[{"id":"1.195453620","rc":[{"atb":[[1.57,0]],"id":40410470}],"con":true,"img":false}]}
{"op":"mcm","clk":"5348117877","pt":1646214277362,"mc":[{"id":"1.195453620","rc":[{"atb":[[1.52,0]],"id":40410470}],"con":true,"img":false}]}
{"op":"mcm","clk":"5348117885","pt":1646214277470,"mc":[{"id":"1.195453620","rc":[{"atb":[[1.56,99.08]],"id":40410470}],"con":true,"img":false}]}
{"op":"mcm","clk":"5348118370","pt":1646214283966,"mc":[{"id":"1.195453620","rc":[{"atb":[[1.6,12.53]],"id":40410470}],"con":true,"img":false}]}
{"op":"mcm","clk":"5348118872","pt":1646214291384,"mc":[{"id":"1.195453620","rc":[{"atb":[[1.3,0]],"id":40310161}],"con":true,"img":false}]}
{"op":"mcm","clk":"5348118876","pt":1646214291483,"mc":[{"id":"1.195453620","rc":[{"atb":[[1.32,114.05]],"id":40310161}],"con":true,"img":false}]}
{"op":"mcm","clk":"5348118881","pt":1646214291582,"mc":[{"id":"1.195453620","rc":[{"atb":[[1.28,357.14],[1.31,0]],"id":40310161}],"con":true,"img":false}]}
{"op":"mcm","clk":"5348118888","pt":1646214291690,"mc":[{"id":"1.195453620","rc":[{"atb":[[1.28,0],[1.33,186.93]],"id":40310161}],"con":true,"img":false}]}
{"op":"mcm","clk":"5348118952","pt":1646214292668,"mc":[{"id":"1.195453620","rc":[{"atb":[[1.6,26.43]],"id":40410470}],"con":true,"img":false}]}
{"op":"mcm","clk":"5348120340","pt":1646214313316,"mc":[{"id":"1.195453620","rc":[{"atl":[[4.3,0]],"id":42464658},{"atb":[[1.32,0]],"id":40310161}],"con":true,"img":false}]}
{"op":"mcm","clk":"5348120348","pt":1646214313427,"mc":[{"id":"1.195453620","rc":[{"atl":[[3.95,11.11]],"id":42464658},{"atb":[[1.34,114.05]],"id":40310161}],"con":true,"img":false}]}
{"op":"mcm","clk":"5348120355","pt":1646214313530,"mc":[{"id":"1.195453620","rc":[{"atb":[[1.28,357.14],[1.33,0]],"id":40310161}],"con":true,"img":false}]}
{"op":"mcm","clk":"5348120516","pt":1646214315422,"mc":[{"id":"1.195453620","rc":[{"atb":[[1.34,0]],"id":40310161}],"con":true,"img":false}]}
{"op":"mcm","clk":"5348120528","pt":1646214315529,"mc":[{"id":"1.195453620","rc":[{"atb":[[1.3,114.05]],"id":40310161}],"con":true,"img":false}]}
{"op":"mcm","clk":"5348121593","pt":1646214330162,"mc":[{"id":"1.195453620","rc":[{"spn":2.1,"spf":"NaN","id":40410470},{"atb":[[1.28,0],[1.31,186.93]],"id":40310161},{"spn":1.77,"spf":"NaN","id":40310161}],"con":true,"img":false}]}
{"op":"mcm","clk":"5348123124","pt":1646214351279,"mc":[{"id":"1.195453620","rc":[{"atb":[[1.3,0]],"id":40310161}],"con":true,"img":false}]}
{"op":"mcm","clk":"5348123132","pt":1646214351382,"mc":[{"id":"1.195453620","rc":[{"atb":[[1.32,114.05]],"id":40310161}],"con":true,"img":false}]}
{"op":"mcm","clk":"5348123138","pt":1646214351487,"mc":[{"id":"1.195453620","rc":[{"atb":[[1.28,357.14],[1.31,0]],"id":40310161}],"con":true,"img":false}]}
{"op":"mcm","clk":"5348123146","pt":1646214351587,"mc":[{"id":"1.195453620","rc":[{"atb":[[1.33,186.93]],"id":40310161}],"con":true,"img":false}]}
{"op":"mcm","clk":"5348123149","pt":1646214351695,"mc":[{"id":"1.195453620","rc":[{"atb":[[1.28,0]],"id":40310161}],"con":true,"img":false}]}
{"op":"mcm","clk":"5348124539","pt":1646214373339,"mc":[{"id":"1.195453620","rc":[{"atb":[[1.32,0]],"id":40310161}],"con":true,"img":false}]}
{"op":"mcm","clk":"5348124547","pt":1646214373442,"mc":[{"id":"1.195453620","rc":[{"atb":[[1.34,114.05]],"id":40310161}],"con":true,"img":false}]}
{"op":"mcm","clk":"5348124557","pt":1646214373547,"mc":[{"id":"1.195453620","rc":[{"atb":[[1.28,357.14],[1.33,0]],"id":40310161}],"con":true,"img":false}]}
{"op":"mcm","clk":"5348124691","pt":1646214375361,"mc":[{"id":"1.195453620","rc":[{"atb":[[1.34,0]],"id":40310161}],"con":true,"img":false}]}
{"op":"mcm","clk":"5348124696","pt":1646214375420,"mc":[{"id":"1.195453620","rc":[{"atb":[[1.55,0],[1.52,192.31]],"id":40410470},{"atl":[[3.6,52.42],[3.4,0]],"id":28447693},{"atb":[[1.08,465.51],[1.07,1321.28]],"id":37496564},{"atb":[[1.3,114.05]],"id":40310161}],"con":true,"img":false}]}
{"op":"mcm","clk":"5348125252","pt":1646214383333,"mc":[{"id":"1.195453620","rc":[{"atb":[[1.56,0]],"id":40410470}],"con":true,"img":false}]}
{"op":"mcm","clk":"5348125262","pt":1646214383450,"mc":[{"id":"1.195453620","rc":[{"atb":[[1.53,99.08]],"id":40410470}],"con":true,"img":false}]}
{"op":"mcm","clk":"5348125439","pt":1646214386228,"mc":[{"id":"1.195453620","rc":[{"atb":[[1.6,13.89]],"id":40410470}],"con":true,"img":false}]}
{"op":"mcm","clk":"5348125645","pt":1646214389534,"mc":[{"id":"1.195453620","rc":[{"atb":[[1.28,0],[1.31,186.93]],"id":40310161}],"con":true,"img":false}]}
{"op":"mcm","clk":"5348125812","pt":1646214392443,"mc":[{"id":"1.195453620","rc":[{"atb":[[1.57,13.18]],"id":40410470}],"con":true,"img":false}]}
{"op":"mcm","clk":"5348135207","pt":1646214403178,"mc":[{"id":"1.195453620","rc":[{"atb":[[1.6,0]],"id":40410470}],"con":true,"img":false}]}
{"op":"mcm","clk":"5348135719","pt":1646214411407,"mc":[{"id":"1.195453620","rc":[{"atb":[[1.3,0]],"id":40310161}],"con":true,"img":false}]}
{"op":"mcm","clk":"5348135726","pt":1646214411511,"mc":[{"id":"1.195453620","rc":[{"atb":[[1.32,114.05]],"id":40310161}],"con":true,"img":false}]}
{"op":"mcm","clk":"5348135734","pt":1646214411616,"mc":[{"id":"1.195453620","rc":[{"atb":[[1.28,357.14],[1.31,0]],"id":40310161}],"con":true,"img":false}]}
{"op":"mcm","clk":"5348135890","pt":1646214413385,"mc":[{"id":"1.195453620","rc":[{"atl":[[3.95,0]],"id":42464658},{"atb":[[1.32,0]],"id":40310161}],"con":true,"img":false}]}
{"op":"mcm","clk":"5348135896","pt":1646214413493,"mc":[{"id":"1.195453620","rc":[{"atl":[[4.3,11.11]],"id":42464658},{"atb":[[1.3,114.05]],"id":40310161}],"con":true,"img":false}]}
{"op":"mcm","clk":"5348136004","pt":1646214415402,"mc":[{"id":"1.195453620","rc":[{"atb":[[1.57,27.8]],"id":40410470}],"con":true,"img":false}]}
{"op":"mcm","clk":"5348136807","pt":1646214427224,"mc":[{"id":"1.195453620","rc":[{"atb":[[1.31,186.93]],"id":40310161}],"con":true,"img":false}]}
{"op":"mcm","clk":"5348136816","pt":1646214427349,"mc":[{"id":"1.195453620","rc":[{"atb":[[1.28,0]],"id":40310161}],"con":true,"img":false}]}
{"op":"mcm","clk":"5348137382","pt":1646214435531,"mc":[{"id":"1.195453620","rc":[{"atb":[[1.55,99.09],[1.52,0]],"id":40410470},{"atl":[[3.6,13.96],[3.4,41.67]],"id":28447693}],"con":true,"img":false}]}
{"op":"mcm","clk":"5348137479","pt":1646214437156,"mc":[{"id":"1.195453620","rc":[{"atb":[[1.57,14.62]],"id":40410470}],"con":true,"img":false}]}
{"op":"mcm","clk":"5348137887","pt":1646214443159,"mc":[{"id":"1.195453620","rc":[{"atb":[[1.59,12.74]],"id":40410470}],"con":true,"img":false}]}
{"op":"mcm","clk":"5348138314","pt":1646214449383,"mc":[{"id":"1.195453620","rc":[{"atb":[[1.3,0]],"id":40310161}],"con":true,"img":false}]}
{"op":"mcm","clk":"5348138321","pt":1646214449487,"mc":[{"id":"1.195453620","rc":[{"atb":[[1.32,114.05]],"id":40310161}],"con":true,"img":false}]}
{"op":"mcm","clk":"5348138327","pt":1646214449545,"mc":[{"id":"1.195453620","rc":[{"atb":[[1.28,357.14],[1.31,0]],"id":40310161}],"con":true,"img":false}]}
{"op":"mcm","clk":"5348138336","pt":1646214449698,"mc":[{"id":"1.195453620","rc":[{"atb":[[1.28,0],[1.33,186.93]],"id":40310161}],"con":true,"img":false}]}
{"op":"mcm","clk":"5348138414","pt":1646214450994,"mc":[{"id":"1.195453620","rc":[{"atb":[[1.56,99.09],[1.55,0]],"id":40410470}],"con":true,"img":false}]}
{"op":"mcm","clk":"5348138512","pt":1646214452286,"mc":[{"id":"1.195453620","rc":[{"atb":[[1.59,0]],"id":40410470}],"con":true,"img":false}]}
{"op":"mcm","clk":"5348138872","pt":1646214457389,"mc":[{"id":"1.195453620","rc":[{"atb":[[1.53,0]],"id":40410470},{"spn":2.08,"spf":"NaN","id":40410470},{"spn":1.78,"spf":"NaN","id":40310161}],"con":true,"img":false}]}
{"op":"mcm","clk":"5348138877","pt":1646214457487,"mc":[{"id":"1.195453620","rc":[{"atb":[[1.57,113.71]],"id":40410470}],"con":true,"img":false}]}
{"op":"mcm","clk":"5348139058","pt":1646214459990,"mc":[{"id":"1.195453620","rc":[{"atb":[[1.57,99.08]],"id":40410470}],"con":true,"img":false}]}
{"op":"mcm","clk":"5348139366","pt":1646214464129,"mc":[{"id":"1.195453620","rc":[{"atb":[[1.61,12.32]],"id":40410470}],"con":true,"img":false}]}
{"op":"mcm","clk":"5348139704","pt":1646214468652,"mc":[{"id":"1.195453620","rc":[{"atb":[[1.08,931.02],[1.07,250]],"id":37496564},{"atl":[[3.6,7.69],[3.65,16.45]],"id":42464658},{"atl":[[13.5,0],[14,1.54]],"id":37208007}],"con":true,"img":false}]}
{"op":"mcm","clk":"5348139907","pt":1646214471336,"mc":[{"id":"1.195453620","rc":[{"atl":[[4.3,0]],"id":42464658},{"atb":[[1.32,0]],"id":40310161}],"con":true,"img":false}]}
{"op":"mcm","clk":"5348139918","pt":1646214471438,"mc":[{"id":"1.195453620","rc":[{"atl":[[3.95,11.11]],"id":42464658},{"atb":[[1.28,357.14],[1.34,114.05]],"id":40310161}],"con":true,"img":false}]}
{"op":"mcm","clk":"5348139924","pt":1646214471543,"mc":[{"id":"1.195453620","rc":[{"atb":[[1.28,0],[1.33,0],[1.35,186.93]],"id":40310161}],"con":true,"img":false}]}
{"op":"mcm","clk":"5348139941","pt":1646214471756,"mc":[{"id":"1.195453620","rc":[{"atb":[[1.58,13.55]],"id":40410470},{"atb":[[1.1,98.18]],"id":37496564},{"atb":[[1.28,84.69]],"id":40310161}],"con":true,"img":false}]}
{"op":"mcm","clk":"5348140032","pt":1646214473248,"mc":[{"id":"1.195453620","rc":[{"atb":[[1.61,25.98]],"id":40410470}],"con":true,"img":false}]}
{"op":"mcm","clk":"5348140167","pt":1646214475381,"mc":[{"id":"1.195453620","rc":[{"atl":[[2.46,0]],"id":40310161}],"con":true,"img":false}]}
{"op":"mcm","clk":"5348140173","pt":1646214475485,"mc":[{"id":"1.195453620","rc":[{"atl":[[2.66,29.42]],"id":40310161}],"con":true,"img":false}]}
{"op":"mcm","clk":"5348140377","pt":1646214478656,"mc":[{"id":"1.195453620","rc":[{"atl":[[3.7,45.4]],"id":42464658},{"atl":[[15,6.29]],"id":37208007}],"con":true,"img":false}]}
{"op":"mcm","clk":"5348140420","pt":1646214479270,"mc":[{"id":"1.195453620","rc":[{"atb":[[1.38,19.78]],"id":40310161}],"con":true,"img":false}]}
{"op":"mcm","clk":"5348140569","pt":1646214481348,"mc":[{"id":"1.195453620","rc":[{"atb":[[1.34,0]],"id":40310161}],"con":true,"img":false}]}
{"op":"mcm","clk":"5348140577","pt":1646214481503,"mc":[{"id":"1.195453620","rc":[{"atb":[[1.31,114.05]],"id":40310161}],"con":true,"img":false}]}
{"op":"mcm","clk":"5348140661","pt":1646214482694,"mc":[{"id":"1.195453620","rc":[{"atb":[[1.07,530.52]],"id":37496564}],"con":true,"img":false}]}
{"op":"mcm","clk":"5348140669","pt":1646214482796,"mc":[{"id":"1.195453620","rc":[{"atb":[[1.08,465.51]],"id":37496564},{"atl":[[4,0]],"id":42464658},{"atl":[[13.5,1.6],[14,0],[15,2.72]],"id":37208007}],"con":true,"img":false}]}
{"op":"mcm","clk":"5348140717","pt":1646214483366,"mc":[{"id":"1.195453620","rc":[{"atl":[[3.95,0]],"id":42464658}],"con":true,"img":false}]}
{"op":"mcm","clk":"5348140723","pt":1646214483469,"mc":[{"id":"1.195453620","rc":[{"atl":[[4.3,11.11]],"id":42464658}],"con":true,"img":false}]}
{"op":"mcm","clk":"5348140791","pt":1646214484294,"mc":[{"id":"1.195453620","rc":[{"atb":[[1.28,0]],"id":40310161}],"con":true,"img":false}]}
{"op":"mcm","clk":"5348140978","pt":1646214486575,"mc":[{"id":"1.195453620","rc":[{"atb":[[1.39,114.06],[1.35,0]],"id":40310161}],"con":true,"img":false}]}
{"op":"mcm","clk":"5348140989","pt":1646214486706,"mc":[{"id":"1.195453620","rc":[{"atb":[[1.38,41.73]],"id":40310161}],"con":true,"img":false}]}
{"op":"mcm","clk":"5348141101","pt":1646214488183,"mc":[{"id":"1.195453620","rc":[{"atb":[[1.38,21.94]],"id":40310161}],"con":true,"img":false}]}
{"op":"mcm","clk":"5348141134","pt":1646214488695,"mc":[{"id":"1.195453620","rc":[{"atl":[[3.8,26.79]],"id":42464658}],"con":true,"img":false}]}
{"op":"mcm","clk":"5348141227","pt":1646214489986,"mc":[{"id":"1.195453620","rc":[{"atb":[[1.32,74.11]],"id":40310161}],"con":true,"img":false}]}
{"op":"mcm","clk":"5348141603","pt":1646214494181,"mc":[{"id":"1.195453620","rc":[{"atb":[[1.42,17.9]],"id":40310161}],"con":true,"img":false}]}
{"op":"mcm","clk":"5348141883","pt":1646214497634,"mc":[{"id":"1.195453620","rc":[{"atb":[[1.32,0]],"id":40310161}],"con":true,"img":false}]}
{"op":"mcm","clk":"5348141954","pt":1646214498665,"mc":[{"id":"1.195453620","rc":[{"atl":[[3.9,43.1]],"id":42464658}],"con":true,"img":false}]}
{"op":"mcm","clk":"5348141984","pt":1646214498875,"mc":[{"id":"1.195453620","rc":[{"atb":[[1.08,931.02],[1.07,250]],"id":37496564},{"atl":[[13.5,0],[14,1.54]],"id":37208007}],"con":true,"img":false}]}
{"op":"mcm","clk":"5348142149","pt":1646214501455,"mc":[{"id":"1.195453620","rc":[{"atb":[[1.39,0],[1.4,114.06]],"id":40310161}],"con":true,"img":false}]}
{"op":"mcm","clk":"5348142275","pt":1646214503154,"mc":[{"id":"1.195453620","rc":[{"atb":[[1.42,0]],"id":40310161}],"con":true,"img":false}]}
{"op":"mcm","clk":"5348142291","pt":1646214503361,"mc":[{"id":"1.195453620","rc":[{"atb":[[1.43,12.53]],"id":40310161}],"con":true,"img":false}]}
{"op":"mcm","clk":"5348142712","pt":1646214508883,"mc":[{"id":"1.195453620","rc":[{"atl":[[15,6.29]],"id":37208007}],"con":true,"img":false}]}
{"op":"mcm","clk":"5348142735","pt":1646214509296,"mc":[{"id":"1.195453620","rc":[{"atb":[[1.43,30.02]],"id":40310161}],"con":true,"img":false}]}
{"op":"mcm","clk":"5348143085","pt":1646214513896,"mc":[{"id":"1.195453620","rc":[{"atb":[[1.08,465.51],[1.07,530.52]],"id":37496564},{"atb":[[1.39,144.08]],"id":40310161}],"con":true,"img":false}]}
{"op":"mcm","clk":"5348143094","pt":1646214514002,"mc":[{"id":"1.195453620","rc":[{"atl":[[16.5,0],[14.5,0],[15.5,0]],"id":37208007},{"atb":[[1.4,0]],"id":40310161}],"con":true,"img":false}]}
{"op":"mcm","clk":"5348143176","pt":1646214515186,"mc":[{"id":"1.195453620","rc":[{"atb":[[1.43,12.53]],"id":40310161}],"con":true,"img":false}]}
{"op":"mcm","clk":"5348143186","pt":1646214515392,"mc":[{"id":"1.195453620","rc":[{"atl":[[15,3.57]],"id":37208007}],"con":true,"img":false}]}
{"op":"mcm","clk":"5348143195","pt":1646214515522,"mc":[{"id":"1.195453620","rc":[{"atl":[[17.5,2.72]],"id":37208007}],"con":true,"img":false}]}
{"op":"mcm","clk":"5348143426","pt":1646214518745,"mc":[{"id":"1.195453620","rc":[{"spn":2.1,"spf":"NaN","id":40410470},{"spn":1.16,"spf":1.0,"id":37496564},{"spn":9.55,"spf":"NaN","id":37208007},{"atb":[[1.43,0]],"id":40310161},{"spn":1.81,"spf":"NaN","id":40310161}],"con":true,"img":false}]}
{"op":"mcm","clk":"5348143437","pt":1646214518900,"mc":[{"id":"1.195453620","rc":[{"atl":[[16,5]],"id":37208007},{"atb":[[1.38,0]],"id":40310161}],"con":true,"img":false}]}
{"op":"mcm","clk":"5348143445","pt":1646214519049,"mc":[{"id":"1.195453620","rc":[{"atb":[[1.32,288.16],[1.39,0]],"id":40310161}],"con":true,"img":false}]}
{"op":"mcm","clk":"5348143823","pt":1646214524427,"mc":[{"id":"1.195453620","rc":[{"atb":[[1.28,84.69]],"id":40310161}],"con":true,"img":false}]}
{"op":"mcm","clk":"5348144191","pt":1646214528948,"mc":[{"id":"1.195453620","rc":[{"atl":[[17,10.07]],"id":37208007}],"con":true,"img":false}]}
{"op":"mcm","clk":"5348144670","pt":1646214535361,"mc":[{"id":"1.195453620","rc":[{"atl":[[3.2,0]],"id":28447693}],"con":true,"img":false}]}
{"op":"mcm","clk":"5348144673","pt":1646214535412,"mc":[{"id":"1.195453620","rc":[{"atl":[[3.3,15.85]],"id":28447693}],"con":true,"img":false}]}
{"op":"mcm","clk":"5348144826","pt":1646214537336,"mc":[{"id":"1.195453620","rc":[{"atb":[[1.31,0]],"id":40310161}],"con":true,"img":false}]}
{"op":"mcm","clk":"5348144830","pt":1646214537437,"mc":[{"id":"1.195453620","rc":[{"atb":[[1.33,114.05]],"id":40310161}],"con":true,"img":false}]}
{"op":"mcm","clk":"5348144841","pt":1646214537541,"mc":[{"id":"1.195453620","rc":[{"atb":[[1.32,0],[1.29,344.83]],"id":40310161}],"con":true,"img":false}]}
{"op":"mcm","clk":"5348144849","pt":1646214537644,"mc":[{"id":"1.195453620","rc":[{"atb":[[1.34,114.06]],"id":40310161}],"con":true,"img":false}]}
{"op":"mcm","clk":"5348144854","pt":1646214537748,"mc":[{"id":"1.195453620","rc":[{"atb":[[1.29,0]],"id":40310161}],"con":true,"img":false}]}
{"op":"mcm","clk":"5348145184","pt":1646214542457,"mc":[{"id":"1.195453620","rc":[{"atb":[[1.28,0]],"id":40310161}],"con":true,"img":false}]}
{"op":"mcm","clk":"5348145401","pt":1646214545361,"mc":[{"id":"1.195453620","rc":[{"atl":[[17.5,0]],"id":37208007}],"con":true,"img":false}]}
{"op":"mcm","clk":"5348145406","pt":1646214545463,"mc":[{"id":"1.195453620","rc":[{"atl":[[15.5,2.72]],"id":37208007}],"con":true,"img":false}]}
{"op":"mcm","clk":"5348145545","pt":1646214547380,"mc":[{"id":"1.195453620","rc":[{"atb":[[1.33,0]],"id":40310161}],"con":true,"img":false}]}
{"op":"mcm","clk":"5348145554","pt":1646214547483,"mc":[{"id":"1.195453620","rc":[{"atb":[[1.31,114.05]],"id":40310161}],"con":true,"img":false}]}
{"op":"mcm","clk":"5348145560","pt":1646214547564,"mc":[{"id":"1.195453620","rc":[{"atb":[[1.28,228.12],[1.34,0]],"id":40310161}],"con":true,"img":false}]}
{"op":"mcm","clk":"5348145593","pt":1646214547959,"mc":[{"id":"1.195453620","rc":[{"atb":[[1.28,312.81]],"id":40310161}],"con":true,"img":false}]}
{"op":"mcm","clk":"5348145926","pt":1646214551991,"mc":[{"id":"1.195453620","rc":[{"atb":[[1.28,84.69],[1.32,186.93]],"id":40310161}],"con":true,"img":false}]}
{"op":"mcm","clk":"5348147061","pt":1646214567401,"mc":[{"id":"1.195453620","rc":[{"atl":[[3.3,0]],"id":28447693}],"con":true,"img":false}]}
{"op":"mcm","clk":"5348147069","pt":1646214567512,"mc":[{"id":"1.195453620","rc":[{"atl":[[3.2,15.85]],"id":28447693}],"con":true,"img":false}]}
{"op":"mcm","clk":"5348147524","pt":1646214573402,"mc":[{"id":"1.195453620","rc":[{"atb":[[1.31,0]],"id":40310161}],"con":true,"img":false}]}
{"op":"mcm","clk":"5348147531","pt":1646214573513,"mc":[{"id":"1.195453620","rc":[{"atb":[[1.33,114.05]],"id":40310161}],"con":true,"img":false}]}
{"op":"mcm","clk":"5348147537","pt":1646214573611,"mc":[{"id":"1.195453620","rc":[{"atb":[[1.32,0],[1.29,344.83]],"id":40310161}],"con":true,"img":false}]}
{"op":"mcm","clk":"5348147543","pt":1646214573711,"mc":[{"id":"1.195453620","rc":[{"atb":[[1.34,114.06]],"id":40310161}],"con":true,"img":false}]}
{"op":"mcm","clk":"5348147553","pt":1646214573819,"mc":[{"id":"1.195453620","rc":[{"atb":[[1.29,0]],"id":40310161}],"con":true,"img":false}]}
{"op":"mcm","clk":"5348147752","pt":1646214576926,"mc":[{"id":"1.195453620","rc":[{"atb":[[1.28,0]],"id":40310161}],"con":true,"img":false}]}
{"op":"mcm","clk":"5348148129","pt":1646214582641,"mc":[{"id":"1.195453620","rc":[{"atb":[[1.28,84.69]],"id":40310161},{"spn":1.79,"spf":"NaN","id":40310161}],"con":true,"img":false}]}
{"op":"mcm","clk":"5348148176","pt":1646214583408,"mc":[{"id":"1.195453620","rc":[{"atb":[[1.33,0]],"id":40310161}],"con":true,"img":false}]}
{"op":"mcm","clk":"5348148181","pt":1646214583510,"mc":[{"id":"1.195453620","rc":[{"atb":[[1.31,114.05]],"id":40310161}],"con":true,"img":false}]}
{"op":"mcm","clk":"5348148188","pt":1646214583616,"mc":[{"id":"1.195453620","rc":[{"atb":[[1.29,228.12],[1.34,0]],"id":40310161}],"con":true,"img":false}]}
{"op":"mcm","clk":"5348148200","pt":1646214583823,"mc":[{"id":"1.195453620","rc":[{"atb":[[1.32,228.12],[1.29,0]],"id":40310161}],"con":true,"img":false}]}
{"op":"mcm","clk":"5348148890","pt":1646214593313,"mc":[{"id":"1.195453620","rc":[{"atl":[[5.1,0]],"id":28447693}],"con":true,"img":false}]}
{"op":"mcm","clk":"5348148895","pt":1646214593417,"mc":[{"id":"1.195453620","rc":[{"atl":[[4.1,14.16]],"id":28447693}],"con":true,"img":false}]}
{"op":"mcm","clk":"5348148955","pt":1646214594504,"mc":[{"id":"1.195453620","rc":[{"atb":[[1.56,0],[1.57,198.17]],"id":40410470},{"atl":[[3.6,0],[3.55,7.84]],"id":42464658}],"con":true,"img":false}]}
{"op":"mcm","clk":"5348149543","pt":1646214603324,"mc":[{"id":"1.195453620","rc":[{"atb":[[1.31,0]],"id":40310161}],"con":true,"img":false}]}
{"op":"mcm","clk":"5348149550","pt":1646214603435,"mc":[{"id":"1.195453620","rc":[{"atb":[[1.33,114.05]],"id":40310161}],"con":true,"img":false}]}
{"op":"mcm","clk":"5348149558","pt":1646214603536,"mc":[{"id":"1.195453620","rc":[{"atb":[[1.32,0],[1.29,344.83]],"id":40310161}],"con":true,"img":false}]}
{"op":"mcm","clk":"5348149566","pt":1646214603642,"mc":[{"id":"1.195453620","rc":[{"atb":[[1.29,0],[1.34,114.06]],"id":40310161}],"con":true,"img":false}]}
{"op":"mcm","clk":"5348149941","pt":1646214608328,"mc":[{"id":"1.195453620","rc":[{"atb":[[1.28,0]],"id":40310161}],"con":true,"img":false}]}
{"op":"mcm","clk":"5348150126","pt":1646214610660,"mc":[{"id":"1.195453620","rc":[{"atb":[[1.56,88.83],[1.57,99.08]],"id":40410470}],"con":true,"img":false}]}
{"op":"mcm","clk":"5348150330","pt":1646214613383,"mc":[{"id":"1.195453620","rc":[{"atb":[[1.33,0]],"id":40310161}],"con":true,"img":false}]}
{"op":"mcm","clk":"5348150345","pt":1646214613587,"mc":[{"id":"1.195453620","rc":[{"atb":[[1.28,228.12],[1.31,114.05],[1.34,0]],"id":40310161}],"con":true,"img":false}]}
{"op":"mcm","clk":"5348150376","pt":1646214614049,"mc":[{"id":"1.195453620","rc":[{"atb":[[1.28,312.81]],"id":40310161}],"con":true,"img":false}]}
{"op":"mcm","clk":"5348150599","pt":1646214617363,"mc":[{"id":"1.195453620","rc":[{"atb":[[1.28,84.69],[1.32,186.93]],"id":40310161}],"con":true,"img":false}]}
{"op":"mcm","clk":"5348150890","pt":1646214621885,"mc":[{"id":"1.195453620","rc":[{"atb":[[1.28,0]],"id":40310161}],"con":true,"img":false}]}
{"op":"mcm","clk":"5348151038","pt":1646214624304,"mc":[{"id":"1.195453620","rc":[{"atb":[[1.56,0],[1.57,187.91]],"id":40410470}],"con":true,"img":false}]}
{"op":"mcm","clk":"5348151288","pt":1646214627400,"mc":[{"id":"1.195453620","rc":[{"atb":[[1.28,84.69]],"id":40310161}],"con":true,"img":false}]}
{"op":"mcm","clk":"5348151452","pt":1646214629483,"mc":[{"id":"1.195453620","rc":[{"atb":[[1.56,88.83],[1.57,99.08]],"id":40410470}],"con":true,"img":false}]}
{"op":"mcm","clk":"5348152200","pt":1646214639300,"mc":[{"id":"1.195453620","rc":[{"atb":[[1.31,0]],"id":40310161}],"con":true,"img":false}]}
{"op":"mcm","clk":"5348152210","pt":1646214639400,"mc":[{"id":"1.195453620","rc":[{"atb":[[1.33,114.05]],"id":40310161}],"con":true,"img":false}]}
{"op":"mcm","clk":"5348152216","pt":1646214639502,"mc":[{"id":"1.195453620","rc":[{"atb":[[1.32,0],[1.29,344.83]],"id":40310161}],"con":true,"img":false}]}
{"op":"mcm","clk":"5348152224","pt":1646214639606,"mc":[{"id":"1.195453620","rc":[{"atb":[[1.29,0],[1.34,114.06]],"id":40310161}],"con":true,"img":false}]}
{"op":"mcm","clk":"5348152374","pt":1646214641840,"mc":[{"id":"1.195453620","rc":[{"atl":[[15,5]],"id":37208007},{"atl":[[2.24,0],[3.35,42.55],[3.05,0]],"id":40310161},{"atl":[[24,9.78],[26,0]],"id":41574727}],"con":true,"img":false}]}
{"op":"mcm","clk":"5348152383","pt":1646214641941,"mc":[{"id":"1.195453620","rc":[{"atb":[[1.56,0],[1.35,570.89]],"id":40410470},{"atb":[[1.62,161.29],[1.47,0]],"id":28447693},{"atl":[[3.4,0],[3.15,25.15]],"id":28447693},{"atb":[[1.07,250],[1.05,855.77]],"id":37496564},{"atl":[[5.6,0],[5.1,24.39],[3.55,0],[3.5,8]],"id":42464658},{"atb":[[3.3,43.48],[3.65,0]],"id":37208007},{"atl":[[14,0],[15,1.43]],"id":37208007},{"atl":[[2.38,14.49]],"id":40310161}],"con":true,"img":false}]}
{"op":"mcm","clk":"5348152395","pt":1646214642102,"mc":[{"id":"1.195453620","rc":[{"atb":[[1.08,931.02],[1.05,250]],"id":37496564},{"atl":[[2.28,28.35]],"id":40310161}],"con":true,"img":false}]}
{"op":"mcm","clk":"5348152431","pt":1646214642513,"mc":[{"id":"1.195453620","rc":[{"atb":[[1.28,0]],"id":40310161}],"con":true,"img":false}]}
{"op":"mcm","clk":"5348152459","pt":1646214642875,"mc":[{"id":"1.195453620","rc":[{"atb":[[1.45,222.22],[1.35,285.18]],"id":40410470},{"spn":10.05,"spf":"NaN","id":37208007},{"spn":1.8,"spf":"NaN","id":40310161}],"con":true,"img":false}]}
{"op":"mcm","clk":"5348152487","pt":1646214643289,"mc":[{"id":"1.195453620","rc":[{"atb":[[1.57,0]],"id":40410470}],"con":true,"img":false}]}
{"op":"mcm","clk":"5348152497","pt":1646214643393,"mc":[{"id":"1.195453620","rc":[{"atb":[[1.51,99.08]],"id":40410470}],"con":true,"img":false}]}
{"op":"mcm","clk":"5348152571","pt":1646214644680,"mc":[{"id":"1.195453620","rc":[{"atb":[[1.61,13.66]],"id":40410470}],"con":true,"img":false}]}
{"op":"mcm","clk":"5348152645","pt":1646214645916,"mc":[{"id":"1.195453620","rc":[{"atl":[[2.32,0]],"id":40310161}],"con":true,"img":false}]}
{"op":"mcm","clk":"5348152758","pt":1646214647419,"mc":[{"id":"1.195453620","rc":[{"atl":[[2.36,0]],"id":40310161}],"con":true,"img":false}]}
{"op":"mcm","clk":"5348152849","pt":1646214648605,"mc":[{"id":"1.195453620","rc":[{"atb":[[1.58,0]],"id":40410470},{"atb":[[1.28,84.69]],"id":40310161}],"con":true,"img":false}]}
{"op":"mcm","clk":"5348152885","pt":1646214649325,"mc":[{"id":"1.195453620","rc":[{"atb":[[1.33,0]],"id":40310161},{"atl":[[2.26,0]],"id":40310161}],"con":true,"img":false}]}
{"op":"mcm","clk":"5348152892","pt":1646214649377,"mc":[{"id":"1.195453620","rc":[{"atb":[[1.31,114.05]],"id":40310161},{"atl":[[2.34,29.85]],"id":40310161}],"con":true,"img":false}]}
{"op":"mcm","clk":"5348152900","pt":1646214649481,"mc":[{"id":"1.195453620","rc":[{"atb":[[1.29,228.12],[1.34,0]],"id":40310161}],"con":true,"img":false}]}
{"op":"mcm","clk":"5348152964","pt":1646214650820,"mc":[{"id":"1.195453620","rc":[{"atb":[[1.54,13.92]],"id":40410470}],"con":true,"img":false}]}
{"op":"mcm","clk":"5348153021","pt":1646214651794,"mc":[{"id":"1.195453620","rc":[{"atl":[[3.6,19.23]],"id":42464658},{"atl":[[16,3.33]],"id":37208007},{"atl":[[2.42,35.21]],"id":40310161}],"con":true,"img":false}]}
{"op":"mcm","clk":"5348153068","pt":1646214652517,"mc":[{"id":"1.195453620","rc":[{"atl":[[3.9,0]],"id":42464658}],"con":true,"img":false}]}
{"op":"mcm","clk":"5348153109","pt":1646214653131,"mc":[{"id":"1.195453620","rc":[{"atl":[[3.5,0]],"id":42464658},{"atl":[[14.5,1.48]],"id":37208007},{"atl":[[2.4,14.29],[2.38,0]],"id":40310161}],"con":true,"img":false}]}
{"op":"mcm","clk":"5348153115","pt":1646214653232,"mc":[{"id":"1.195453620","rc":[{"atl":[[3.45,8.16]],"id":42464658}],"con":true,"img":false}]}
{"op":"mcm","clk":"5348153185","pt":1646214654223,"mc":[{"id":"1.195453620","rc":[{"atb":[[1.52,23.22]],"id":40410470}],"con":true,"img":false}]}
{"op":"mcm","clk":"5348153249","pt":1646214655143,"mc":[{"id":"1.195453620","rc":[{"atl":[[3.35,0],[2.84,54.35]],"id":40310161}],"con":true,"img":false}]}
{"op":"mcm","clk":"5348153254","pt":1646214655244,"mc":[{"id":"1.195453620","rc":[{"atl":[[23,7.27],[24,5.43]],"id":41574727}],"con":true,"img":false}]}
{"op":"mcm","clk":"5348153261","pt":1646214655300,"mc":[{"id":"1.195453620","rc":[{"atl":[[5.1,0],[4.4,50.76]],"id":42464658},{"atb":[[3.85,35.09]],"id":37208007}],"con":true,"img":false}]}
{"op":"mcm","clk":"5348153268","pt":1646214655403,"mc":[{"id":"1.195453620","rc":[{"atb":[[3.3,0]],"id":37208007}],"con":true,"img":false}]}
{"op":"mcm","clk":"5348153305","pt":1646214656021,"mc":[{"id":"1.195453620","rc":[{"atl":[[2.38,14.49]],"id":40310161}],"con":true,"img":false}]}
{"op":"mcm","clk":"5348153503","pt":1646214659327,"mc":[{"id":"1.195453620","rc":[{"atl":[[15.5,0]],"id":37208007}],"con":true,"img":false}]}
{"op":"mcm","clk":"5348153512","pt":1646214659420,"mc":[{"id":"1.195453620","rc":[{"atl":[[16.5,2.72]],"id":37208007}],"con":true,"img":false}]}
{"op":"mcm","clk":"5348153730","pt":1646214662719,"mc":[{"id":"1.195453620","rc":[{"atb":[[1.32,114.06],[1.29,0]],"id":40310161}],"con":true,"img":false}]}
{"op":"mcm","clk":"5348153749","pt":1646214663037,"mc":[{"id":"1.195453620","rc":[{"atb":[[1.46,0],[1.44,0],[1.45,0],[1.03,250],[1.48,0],[1.42,0]],"id":40410470},{"atl":[[3.85,0],[3.1,47.62],[2.26,15.87],[3.75,0]],"id":40410470},{"atb":[[1.72,0],[1.86,23.26]],"id":28447693},{"atl":[[3.85,0],[4.6,33.34],[3.55,0],[3.3,0],[3.65,0],[3.75,0]],"id":37496564},{"atb":[[1.36,55.56],[1.26,250],[1.09,0]],"id":42464658},{"atb":[[2.4,14.29],[2.24,56.82],[1.8,0],[1.9,0]],"id":39791282},{"atb":[[4,33.27],[4.9,5.13]],"id":37208007},{"atl":[[2.4,0],[2.42,0],[2.38,0],[2.76,11.36]],"id":40310161},{"atb":[[3.95,33.9],[4.1,6.45],[3.15,0],[3.5,0]],"id":41574727}],"con":true,"img":false}]}
{"op":"mcm","clk":"5348153769","pt":1646214663344,"mc":[{"id":"1.195453620","rc":[{"atb":[[1.47,0]],"id":40410470},{"atl":[[4.8,10.35],[3.2,0],[4.1,0]],"id":28447693}],"con":true,"img":false}]}
{"op":"mcm","clk":"5348153777","pt":1646214663442,"mc":[{"id":"1.195453620","rc":[{"atb":[[1.42,88.83]],"id":40410470},{"atl":[[3.1,15.85]],"id":28447693}],"con":true,"img":false}]}
{"op":"mcm","clk":"5348153780","pt":1646214663543,"mc":[{"id":"1.195453620","rc":[{"atl":[[3.35,74.46],[3.15,9.3]],"id":28447693}],"con":true,"img":false}]}
{"op":"mcm","clk":"5348154023","pt":1646214667161,"mc":[{"id":"1.195453620","rc":[{"atb":[[1.52,0]],"id":40410470},{"atb":[[1.28,0]],"id":40310161}],"con":true,"img":false}]}
{"op":"mcm","clk":"5348154121","pt":1646214668526,"mc":[{"id":"1.195453620","rc":[{"atb":[[3.85,0],[4.6,37.92]],"id":37208007}],"con":true,"img":false}]}
{"op":"mcm","clk":"5348154323","pt":1646214671361,"mc":[{"id":"1.195453620","rc":[{"atl":[[3.1,0]],"id":28447693}],"con":true,"img":false}]}
{"op":"mcm","clk":"5348154329","pt":1646214671415,"mc":[{"id":"1.195453620","rc":[{"atl":[[3.2,15.85]],"id":28447693}],"con":true,"img":false}]}
{"op":"mcm","clk":"5348154406","pt":1646214672452,"mc":[{"id":"1.195453620","rc":[{"atb":[[1.52,23.22]],"id":40410470},{"atb":[[1.28,84.69]],"id":40310161}],"con":true,"img":false}]}
{"op":"mcm","clk":"5348154467","pt":1646214673076,"mc":[{"id":"1.195453620","rc":[{"atl":[[2.3,38.46]],"id":40410470},{"atb":[[1.84,59.52]],"id":28447693},{"atl":[[4.8,13.16]],"id":37496564},{"atb":[[2.36,36.76]],"id":39791282},{"atb":[[1.34,147.06]],"id":42464658},{"atb":[[4.7,13.51]],"id":37208007},{"atl":[[15.5,3.45]],"id":37208007},{"atl":[[2.8,27.78]],"id":40310161},{"atb":[[3.95,50.85]],"id":41574727}],"con":true,"img":false}]}
{"op":"mcm","clk":"5348154483","pt":1646214673229,"mc":[{"id":"1.195453620","rc":[{"atb":[[1.61,0]],"id":40410470}],"con":true,"img":false}]}
{"op":"mcm","clk":"5348154494","pt":1646214673326,"mc":[{"id":"1.195453620","rc":[{"atl":[[4.3,0]],"id":40410470},{"atb":[[1.66,0]],"id":28447693},{"atb":[[1.84,0]],"id":39791282},{"atb":[[1.03,0],[1.07,0],[1.05,0]],"id":42464658},{"atl":[[3.65,0]],"id":42464658},{"atb":[[3.7,0],[3.8,0],[3.9,0]],"id":37208007},{"atl":[[16,0],[17,2.26],[15,0]],"id":37208007},{"atb":[[3.2,0],[3.4,0],[3.3,0]],"id":41574727}],"con":true,"img":false}]}
{"op":"mcm","clk":"5348154500","pt":1646214673436,"mc":[{"id":"1.195453620","rc":[{"atl":[[3.55,16.45]],"id":42464658}],"con":true,"img":false}]}
{"op":"mcm","clk":"5348154605","pt":1646214674826,"mc":[{"id":"1.195453620","rc":[{"atb":[[1.85,9.8]],"id":28447693}],"con":true,"img":false}]}
{"op":"mcm","clk":"5348154639","pt":1646214675347,"mc":[{"id":"1.195453620","rc":[{"atb":[[1.37,116.08],[1.42,0],[1.51,0]],"id":40410470}],"con":true,"img":false}]}
{"op":"mcm","clk":"5348154651","pt":1646214675442,"mc":[{"id":"1.195453620","rc":[{"atb":[[1.45,99.08]],"id":40410470}],"con":true,"img":false}]}
{"op":"mcm","clk":"5348154738","pt":1646214676628,"mc":[{"id":"1.195453620","rc":[{"atl":[[3.35,31.91],[3.15,25.15]],"id":28447693}],"con":true,"img":false}]}
{"op":"mcm","clk":"5348154803","pt":1646214677866,"mc":[{"id":"1.195453620","rc":[{"atb":[[1.54,0]],"id":40410470}],"con":true,"img":false}]}
{"op":"mcm","clk":"5348154975","pt":1646214680862,"mc":[{"id":"1.195453620","rc":[{"atb":[[1.52,0]],"id":40410470},{"atb":[[1.88,8.54]],"id":28447693}],"con":true,"img":false}]}
{"op":"mcm","clk":"5348155133","pt":1646214683075,"mc":[{"id":"1.195453620","rc":[{"atl":[[2.34,55.97]],"id":40410470},{"atb":[[1.82,91.46]],"id":28447693},{"atl":[[5,18.75]],"id":37496564},{"atb":[[1.32,234.37]],"id":42464658},{"atb":[[2.32,56.82]],"id":39791282},{"atb":[[4.5,49.94]],"id":37208007},{"atl":[[16.5,7.56]],"id":37208007},{"atl":[[2.84,95.11]],"id":40310161},{"atb":[[3.85,26.32]],"id":41574727}],"con":true,"img":false}]}
{"op":"mcm","clk":"5348155146","pt":1646214683283,"mc":[{"id":"1.195453620","rc":[{"atl":[[4.1,0]],"id":40410470},{"atb":[[1.68,0]],"id":28447693},{"atb":[[1.86,0]],"id":39791282}],"con":true,"img":false}]}
{"op":"mcm","clk":"5348155152","pt":1646214683430,"mc":[{"id":"1.195453620","rc":[{"atb":[[1.31,0]],"id":40310161}],"con":true,"img":false}]}
{"op":"mcm","clk":"5348155158","pt":1646214683485,"mc":[{"id":"1.195453620","rc":[{"atb":[[1.33,114.05]],"id":40310161}],"con":true,"img":false}]}
{"op":"mcm","clk":"5348155161","pt":1646214683585,"mc":[{"id":"1.195453620","rc":[{"atb":[[1.29,228.12]],"id":40310161}],"con":true,"img":false}]}
{"op":"mcm","clk":"5348155171","pt":1646214683695,"mc":[{"id":"1.195453620","rc":[{"atb":[[1.32,0]],"id":40310161}],"con":true,"img":false}]}
{"op":"mcm","clk":"5348155244","pt":1646214684867,"mc":[{"id":"1.195453620","rc":[{"atb":[[1.48,15.66]],"id":40410470}],"con":true,"img":false}]}
{"op":"mcm","clk":"5348155277","pt":1646214685381,"mc":[{"id":"1.195453620","rc":[{"atl":[[2.66,0]],"id":40310161}],"con":true,"img":false}]}
{"op":"mcm","clk":"5348155286","pt":1646214685493,"mc":[{"id":"1.195453620","rc":[{"atl":[[2.46,29.42]],"id":40310161}],"con":true,"img":false}]}
{"op":"mcm","clk":"5348155331","pt":1646214686261,"mc":[{"id":"1.195453620","rc":[{"atb":[[1.38,62.41]],"id":40410470}],"con":true,"img":false}]}
{"op":"mcm","clk":"5348155500","pt":1646214688990,"mc":[{"id":"1.195453620","rc":[{"atb":[[1.28,0]],"id":40310161}],"con":true,"img":false}]}
{"op":"mcm","clk":"5348155653","pt":1646214691367,"mc":[{"id":"1.195453620","rc":[{"atb":[[1.33,0]],"id":40310161}],"con":true,"img":false}]}
{"op":"mcm","clk":"5348155657","pt":1646214691467,"mc":[{"id":"1.195453620","rc":[{"atb":[[1.28,357.14],[1.3,114.05],[1.29,0]],"id":40310161}],"con":true,"img":false}]}
{"op":"mcm","clk":"5348155662","pt":1646214691571,"mc":[{"id":"1.195453620","rc":[{"atb":[[1.38,0]],"id":40410470}],"con":true,"img":false}]}
{"op":"mcm","clk":"5348155698","pt":1646214692088,"mc":[{"id":"1.195453620","rc":[{"atl":[[1.24,70.84]],"id":37496564}],"con":true,"img":false}]}
{"op":"mcm","clk":"5348155768","pt":1646214693066,"mc":[{"id":"1.195453620","rc":[{"atl":[[2.38,90.58]],"id":40410470},{"atb":[[1.8,281.01]],"id":28447693},{"atl":[[5.2,29.76]],"id":37496564},{"atb":[[2.28,97.66]],"id":39791282},{"atb":[[1.3,250]],"id":42464658},{"atb":[[4.3,37.88]],"id":37208007},{"atl":[[17.5,7.58]],"id":37208007},{"atl":[[2.88,66.49]],"id":40310161},{"atb":[[3.75,45.45]],"id":41574727}],"con":true,"img":false}]}
{"op":"mcm","clk":"5348155790","pt":1646214693376,"mc":[{"id":"1.195453620","rc":[{"atb":[[1.81,0]],"id":28447693}],"con":true,"img":false}]}
{"op":"mcm","clk":"5348155799","pt":1646214693480,"mc":[{"id":"1.195453620","rc":[{"atb":[[1.85,70.35]],"id":28447693}],"con":true,"img":false}]}
{"op":"mcm","clk":"5348155848","pt":1646214694399,"mc":[{"id":"1.195453620","rc":[{"atb":[[1.31,76.5]],"id":40310161}],"con":true,"img":false}]}
{"op":"mcm","clk":"5348155905","pt":1646214695283,"mc":[{"id":"1.195453620","rc":[{"atb":[[4.6,10.14],[4.9,30.77]],"id":37208007}],"con":true,"img":false}]}
{"op":"mcm","clk":"5348155932","pt":1646214695797,"mc":[{"id":"1.195453620","rc":[{"atb":[[1.88,0]],"id":28447693}],"con":true,"img":false}]}
{"op":"mcm","clk":"5348155997","pt":1646214696777,"mc":[{"id":"1.195453620","rc":[{"atl":[[3.95,0]],"id":40410470},{"atb":[[1.7,142.59]],"id":28447693},{"atb":[[1.88,0]],"id":39791282}],"con":true,"img":false}]}
{"op":"mcm","clk":"5348156022","pt":1646214697290,"mc":[{"id":"1.195453620","rc":[{"atb":[[1.38,28.18]],"id":40410470}],"con":true,"img":false}]}
{"op":"mcm","clk":"5348156028","pt":1646214697395,"mc":[{"id":"1.195453620","rc":[{"atl":[[2.78,0]],"id":40410470},{"atl":[[3.2,0]],"id":28447693}],"con":true,"img":false}]}
{"op":"mcm","clk":"5348156037","pt":1646214697499,"mc":[{"id":"1.195453620","rc":[{"atl":[[2.28,24.49]],"id":40410470},{"atl":[[3.1,15.85]],"id":28447693}],"con":true,"img":false}]}
{"op":"mcm","clk":"5348156046","pt":1646214697596,"mc":[{"id":"1.195453620","rc":[{"atl":[[3.35,74.46],[3.15,9.3]],"id":28447693}],"con":true,"img":false}]}
{"op":"mcm","clk":"5348156057","pt":1646214697705,"mc":[{"id":"1.195453620","rc":[{"atl":[[3.05,22.22]],"id":28447693}],"con":true,"img":false}]}
{"op":"mcm","clk":"5348156062","pt":1646214697803,"mc":[{"id":"1.195453620","rc":[{"atl":[[3.35,31.91]],"id":28447693}],"con":true,"img":false}]}
{"op":"mcm","clk":"5348156163","pt":1646214699400,"mc":[{"id":"1.195453620","rc":[{"atl":[[3.55,0]],"id":42464658}],"con":true,"img":false}]}
{"op":"mcm","clk":"5348156169","pt":1646214699501,"mc":[{"id":"1.195453620","rc":[{"atl":[[3.65,16.45]],"id":42464658}],"con":true,"img":false}]}
{"op":"mcm","clk":"5348156296","pt":1646214701872,"mc":[{"id":"1.195453620","rc":[{"atb":[[1.89,8.45]],"id":28447693}],"con":true,"img":false}]}
{"op":"mcm","clk":"5348156352","pt":1646214703109,"mc":[{"id":"1.195453620","rc":[{"atb":[[1.48,33.02]],"id":40410470},{"spn":1.87,"spf":"NaN","id":40410470},{"spn":1.89,"spf":1.0,"id":28447693},{"spn":9.8,"spf":"NaN","id":37208007},{"spn":1.79,"spf":"NaN","id":40310161}],"con":true,"img":false}]}
{"op":"mcm","clk":"5348156373","pt":1646214703471,"mc":[{"id":"1.195453620","rc":[{"atb":[[1.85,60.55]],"id":28447693}],"con":true,"img":false}]}
{"op":"mcm","clk":"5348156418","pt":1646214704299,"mc":[{"id":"1.195453620","rc":[{"atb":[[1.28,0],[1.32,114.06]],"id":40310161}],"con":true,"img":false}]}
{"op":"mcm","clk":"5348156476","pt":1646214705273,"mc":[{"id":"1.195453620","rc":[{"atl":[[4.1,14.16]],"id":28447693}],"con":true,"img":false}]}
{"op":"mcm","clk":"5348156484","pt":1646214705375,"mc":[{"id":"1.195453620","rc":[{"atl":[[4.8,0],[3.1,0]],"id":28447693}],"con":true,"img":false}]}
{"op":"mcm","clk":"5348156492","pt":1646214705481,"mc":[{"id":"1.195453620","rc":[{"atl":[[3.2,15.85],[3.25,54.13],[3.05,0]],"id":28447693}],"con":true,"img":false}]}
{"op":"mcm","clk":"5348156690","pt":1646214708419,"mc":[{"id":"1.195453620","rc":[{"atb":[[1.31,0]],"id":40310161}],"con":true,"img":false}]}
{"op":"mcm","clk":"5348156751","pt":1646214709498,"mc":[{"id":"1.195453620","rc":[{"atb":[[1.32,0],[1.31,228.12]],"id":40310161}],"con":true,"img":false}]}
{"op":"mcm","clk":"5348156967","pt":1646214713428,"mc":[{"id":"1.195453620","rc":[{"atl":[[1.9,0]],"id":37496564}],"con":true,"img":false}]}
{"op":"mcm","clk":"5348156975","pt":1646214713527,"mc":[{"id":"1.195453620","rc":[{"atl":[[1.89,43.59]],"id":37496564}],"con":true,"img":false}]}
{"op":"mcm","clk":"5348157042","pt":1646214714613,"mc":[{"id":"1.195453620","rc":[{"atb":[[1.28,84.69]],"id":40310161}],"con":true,"img":false}]}
{"op":"mcm","clk":"5348157088","pt":1646214715334,"mc":[{"id":"1.195453620","rc":[{"atl":[[3.6,0],[2.98,21.25]],"id":40410470}],"con":true,"img":false}]}
{"op":"mcm","clk":"5348157094","pt":1646214715435,"mc":[{"id":"1.195453620","rc":[{"atb":[[1.3,0]],"id":40310161}],"con":true,"img":false}]}
{"op":"mcm","clk":"5348157102","pt":1646214715537,"mc":[{"id":"1.195453620","rc":[{"atb":[[1.32,114.05]],"id":40310161},{"atb":[[5.9,18.19],[5.4,0]],"id":41574727}],"con":true,"img":false}]}
{"op":"mcm","clk":"5348157106","pt":1646214715591,"mc":[{"id":"1.195453620","rc":[{"atb":[[1.29,344.83],[1.31,0]],"id":40310161}],"con":true,"img":false}]}
{"op":"mcm","clk":"5348157292","pt":1646214718231,"mc":[{"id":"1.195453620","rc":[{"atl":[[3.15,25.15],[3.25,22.22]],"id":28447693}],"con":true,"img":false}]}
{"op":"mcm","clk":"5348157331","pt":1646214718845,"mc":[{"id":"1.195453620","rc":[{"atb":[[1.89,17.82]],"id":28447693}],"con":true,"img":false}]}
{"op":"mcm","clk":"5348157578","pt":1646214722419,"mc":[{"id":"1.195453620","rc":[{"atb":[[1.27,0]],"id":40310161}],"con":true,"img":false}]}
{"op":"mcm","clk":"5348157590","pt":1646214722523,"mc":[{"id":"1.195453620","rc":[{"atb":[[1.25,186.93]],"id":40310161}],"con":true,"img":false}]}
{"op":"mcm","clk":"5348157655","pt":1646214723352,"mc":[{"id":"1.195453620","rc":[{"atb":[[1.32,0]],"id":40310161}],"con":true,"img":false}]}
{"op":"mcm","clk":"5348157664","pt":1646214723448,"mc":[{"id":"1.195453620","rc":[{"atb":[[1.29,458.88]],"id":40310161}],"con":true,"img":false}]}
{"op":"mcm","clk":"5348157986","pt":1646214727914,"mc":[{"id":"1.195453620","rc":[{"atb":[[1.28,0]],"id":40310161}],"con":true,"img":false}]}
{"op":"mcm","clk":"5348158354","pt":1646214733658,"mc":[{"id":"1.195453620","rc":[{"atb":[[1.3,79.05]],"id":40310161}],"con":true,"img":false}]}
{"op":"mcm","clk":"5348158366","pt":1646214733863,"mc":[{"id":"1.195453620","rc":[{"atb":[[1.29,114.05],[1.31,79.05]],"id":40310161}],"con":true,"img":false}]}
{"op":"mcm","clk":"5348158469","pt":1646214735362,"mc":[{"id":"1.195453620","rc":[{"atl":[[1.89,0]],"id":37496564},{"atb":[[1.29,0]],"id":40310161}],"con":true,"img":false}]}
{"op":"mcm","clk":"5348158474","pt":1646214735462,"mc":[{"id":"1.195453620","rc":[{"atl":[[1.88,43.59]],"id":37496564},{"atb":[[1.27,114.05]],"id":40310161}],"con":true,"img":false}]}
{"op":"mcm","clk":"5348158712","pt":1646214738767,"mc":[{"id":"1.195453620","rc":[{"atb":[[1.3,0]],"id":40310161}],"con":true,"img":false}]}
{"op":"mcm","clk":"5348158732","pt":1646214739073,"mc":[{"id":"1.195453620","rc":[{"atb":[[1.28,158.1],[1.31,0]],"id":40310161}],"con":true,"img":false}]}
{"op":"mcm","clk":"5348158759","pt":1646214739486,"mc":[{"id":"1.195453620","rc":[{"atl":[[3.2,0]],"id":28447693}],"con":true,"img":false}]}
{"op":"mcm","clk":"5348158767","pt":1646214739545,"mc":[{"id":"1.195453620","rc":[{"atl":[[3.1,15.85]],"id":28447693}],"con":true,"img":false}]}
{"op":"mcm","clk":"5348158777","pt":1646214739647,"mc":[{"id":"1.195453620","rc":[{"atl":[[3.35,74.46],[3.15,9.3]],"id":28447693}],"con":true,"img":false}]}
{"op":"mcm","clk":"5348158881","pt":1646214741349,"mc":[{"id":"1.195453620","rc":[{"atb":[[5.9,9.47]],"id":41574727}],"con":true,"img":false}]}
{"op":"mcm","clk":"5348158886","pt":1646214741451,"mc":[{"id":"1.195453620","rc":[{"atb":[[5.4,8.71]],"id":41574727}],"con":true,"img":false}]}
{"op":"mcm","clk":"5348159081","pt":1646214744186,"mc":[{"id":"1.195453620","rc":[{"atb":[[1.29,81.78]],"id":40310161}],"con":true,"img":false}]}
{"op":"mcm","clk":"5348159309","pt":1646214747380,"mc":[{"id":"1.195453620","rc":[{"atl":[[3.1,0]],"id":28447693},{"atl":[[16.5,4.84]],"id":37208007}],"con":true,"img":false}]}
{"op":"mcm","clk":"5348159317","pt":1646214747484,"mc":[{"id":"1.195453620","rc":[{"atl":[[3.3,15.85]],"id":28447693},{"atl":[[17,4.99]],"id":37208007}],"con":true,"img":false}]}
{"op":"mcm","clk":"5348159590","pt":1646214751370,"mc":[{"id":"1.195453620","rc":[{"atb":[[1.28,0],[1.3,114.06]],"id":40310161}],"con":true,"img":false}]}
{"op":"mcm","clk":"5348159633","pt":1646214752094,"mc":[{"id":"1.195453620","rc":[{"atl":[[3.35,31.91],[3.25,44.44]],"id":28447693}],"con":true,"img":false}]}
{"op":"mcm","clk":"5348159781","pt":1646214754773,"mc":[{"id":"1.195453620","rc":[{"atb":[[1.29,0]],"id":40310161}],"con":true,"img":false}]}
{"op":"mcm","clk":"5348159790","pt":1646214754877,"mc":[{"id":"1.195453620","rc":[{"atb":[[1.28,228.12],[1.3,0]],"id":40310161}],"con":true,"img":false}]}
{"op":"mcm","clk":"5348159961","pt":1646214757298,"mc":[{"id":"1.195453620","rc":[{"atl":[[1.88,0]],"id":37496564}],"con":true,"img":false}]}
{"op":"mcm","clk":"5348159970","pt":1646214757400,"mc":[{"id":"1.195453620","rc":[{"atl":[[1.87,43.59]],"id":37496564}],"con":true,"img":false}]}
{"op":"mcm","clk":"5348160047","pt":1646214758604,"mc":[{"id":"1.195453620","rc":[{"atl":[[3.45,0],[3.4,8.33]],"id":42464658},{"atb":[[5,49.91],[4.9,5.13]],"id":37208007}],"con":true,"img":false}]}
{"op":"mcm","clk":"5348160179","pt":1646214760903,"mc":[{"id":"1.195453620","rc":[{"atb":[[1.29,81.78]],"id":40310161}],"con":true,"img":false}]}
{"op":"mcm","clk":"5348160350","pt":1646214763325,"mc":[{"id":"1.195453620","rc":[{"atl":[[4.8,10.35]],"id":28447693},{"spn":1.78,"spf":"NaN","id":40310161}],"con":true,"img":false}]}
{"op":"mcm","clk":"5348160361","pt":1646214763384,"mc":[{"id":"1.195453620","rc":[{"atl":[[4.1,0]],"id":28447693}],"con":true,"img":false}]}
{"op":"mcm","clk":"5348160606","pt":1646214767097,"mc":[{"id":"1.195453620","rc":[{"atb":[[1.28,0],[1.3,114.06]],"id":40310161}],"con":true,"img":false}]}
{"op":"mcm","clk":"5348160719","pt":1646214768599,"mc":[{"id":"1.195453620","rc":[{"atl":[[3.5,20]],"id":42464658}],"con":true,"img":false}]}
{"op":"mcm","clk":"5348160748","pt":1646214768904,"mc":[{"id":"1.195453620","rc":[{"atl":[[3.8,0]],"id":42464658}],"con":true,"img":false}]}
{"op":"mcm","clk":"5348160937","pt":1646214771623,"mc":[{"id":"1.195453620","rc":[{"atb":[[1.29,0]],"id":40310161}],"con":true,"img":false}]}
{"op":"mcm","clk":"5348160987","pt":1646214772301,"mc":[{"id":"1.195453620","rc":[{"atb":[[1.28,228.12],[1.3,0]],"id":40310161}],"con":true,"img":false}]}
{"op":"mcm","clk":"5348161047","pt":1646214773431,"mc":[{"id":"1.195453620","rc":[{"atl":[[3.3,0]],"id":28447693}],"con":true,"img":false}]}
{"op":"mcm","clk":"5348161053","pt":1646214773536,"mc":[{"id":"1.195453620","rc":[{"atl":[[3.2,15.85]],"id":28447693}],"con":true,"img":false}]}
{"op":"mcm","clk":"5348161059","pt":1646214773598,"mc":[{"id":"1.195453620","rc":[{"atl":[[3.35,74.46]],"id":28447693}],"con":true,"img":false}]}
{"op":"mcm","clk":"5348161065","pt":1646214773695,"mc":[{"id":"1.195453620","rc":[{"atl":[[3.25,22.22]],"id":28447693}],"con":true,"img":false}]}
{"op":"mcm","clk":"5348161256","pt":1646214777225,"mc":[{"id":"1.195453620","rc":[{"atb":[[1.29,81.78]],"id":40310161}],"con":true,"img":false}]}
{"op":"mcm","clk":"5348161334","pt":1646214778618,"mc":[{"id":"1.195453620","rc":[{"atl":[[3.6,28.85]],"id":42464658}],"con":true,"img":false}]}
{"op":"mcm","clk":"5348161385","pt":1646214779342,"mc":[{"id":"1.195453620","rc":[{"atl":[[1.98,0],[1.87,0]],"id":37496564}],"con":true,"img":false}]}
{"op":"mcm","clk":"5348161392","pt":1646214779441,"mc":[{"id":"1.195453620","rc":[{"atl":[[1.86,43.59],[2.14,32.1]],"id":37496564}],"con":true,"img":false}]}
{"op":"mcm","clk":"5348161516","pt":1646214781302,"mc":[{"id":"1.195453620","rc":[{"atl":[[3.2,0]],"id":28447693}],"con":true,"img":false}]}
{"op":"mcm","clk":"5348161527","pt":1646214781407,"mc":[{"id":"1.195453620","rc":[{"atl":[[3.3,15.85]],"id":28447693}],"con":true,"img":false}]}
{"op":"mcm","clk":"5348161723","pt":1646214784349,"mc":[{"id":"1.195453620","rc":[{"atb":[[1.28,0],[1.3,114.06]],"id":40310161}],"con":true,"img":false}]}
{"op":"mcm","clk":"5348161802","pt":1646214785645,"mc":[{"id":"1.195453620","rc":[{"atl":[[3.35,31.91],[3.25,44.44]],"id":28447693}],"con":true,"img":false}]}
{"op":"mcm","clk":"5348161954","pt":1646214788119,"mc":[{"id":"1.195453620","rc":[{"atb":[[1.29,0]],"id":40310161}],"con":true,"img":false}]}
{"op":"mcm","clk":"5348161984","pt":1646214788636,"mc":[{"id":"1.195453620","rc":[{"atl":[[3.7,73.18]],"id":42464658}],"con":true,"img":false}]}
{"op":"mcm","clk":"5348162060","pt":1646214789460,"mc":[{"id":"1.195453620","rc":[{"atb":[[1.28,228.12],[1.3,0]],"id":40310161}],"con":true,"img":false}]}
{"op":"mcm","clk":"5348162402","pt":1646214793941,"mc":[{"id":"1.195453620","rc":[{"atb":[[1.29,81.78]],"id":40310161}],"con":true,"img":false}]}
{"op":"mcm","clk":"5348162504","pt":1646214795227,"mc":[{"id":"1.195453620","rc":[{"atl":[[18.5,1.14]],"id":41574727}],"con":true,"img":false}]}
{"op":"mcm","clk":"5348162512","pt":1646214795331,"mc":[{"id":"1.195453620","rc":[{"atl":[[19,2.01]],"id":41574727}],"con":true,"img":false}]}
{"op":"mcm","clk":"5348162586","pt":1646214796259,"mc":[{"id":"1.195453620","rc":[{"atb":[[1.28,0],[1.3,114.06]],"id":40310161}],"con":true,"img":false}]}
{"op":"mcm","clk":"5348162796","pt":1646214799356,"mc":[{"id":"1.195453620","rc":[{"atl":[[3.65,0]],"id":42464658},{"atb":[[1.29,0]],"id":40310161}],"con":true,"img":false}]}
{"op":"mcm","clk":"5348162801","pt":1646214799458,"mc":[{"id":"1.195453620","rc":[{"atl":[[3.55,16.45]],"id":42464658}],"con":true,"img":false}]}
{"op":"mcm","clk":"5348162807","pt":1646214799561,"mc":[{"id":"1.195453620","rc":[{"atb":[[1.28,228.12],[1.3,0]],"id":40310161}],"con":true,"img":false}]}
{"op":"mcm","clk":"5348162924","pt":1646214801467,"mc":[{"id":"1.195453620","rc":[{"atl":[[1.86,0]],"id":37496564}],"con":true,"img":false}]}
{"op":"mcm","clk":"5348162932","pt":1646214801570,"mc":[{"id":"1.195453620","rc":[{"atl":[[1.85,43.59]],"id":37496564}],"con":true,"img":false}]}
{"op":"mcm","clk":"5348163163","pt":1646214805076,"mc":[{"id":"1.195453620","rc":[{"atb":[[1.29,81.78]],"id":40310161}],"con":true,"img":false}]}
{"op":"mcm","clk":"5348163299","pt":1646214807354,"mc":[{"id":"1.195453620","rc":[{"atl":[[3.3,0]],"id":28447693}],"con":true,"img":false}]}
{"op":"mcm","clk":"5348163305","pt":1646214807456,"mc":[{"id":"1.195453620","rc":[{"atl":[[3.2,15.85]],"id":28447693}],"con":true,"img":false}]}
{"op":"mcm","clk":"5348163314","pt":1646214807559,"mc":[{"id":"1.195453620","rc":[{"atl":[[3.35,74.46],[3.25,22.22]],"id":28447693}],"con":true,"img":false}]}
{"op":"mcm","clk":"5348163583","pt":1646214811267,"mc":[{"id":"1.195453620","rc":[{"atb":[[1.3,114.06]],"id":40310161}],"con":true,"img":false}]}
{"op":"mcm","clk":"5348163592","pt":1646214811372,"mc":[{"id":"1.195453620","rc":[{"atb":[[1.28,0]],"id":40310161}],"con":true,"img":false}]}
{"op":"mcm","clk":"5348163693","pt":1646214813178,"mc":[{"id":"1.195453620","rc":[{"atb":[[1.09,390.25],[1.08,465.51]],"id":37496564},{"atb":[[5,24.95],[4.2,31.25]],"id":37208007},{"atl":[[36,0],[27,3.85],[14.5,0]],"id":37208007}],"con":true,"img":false}]}
{"op":"mcm","clk":"5348163699","pt":1646214813278,"mc":[{"id":"1.195453620","rc":[{"atl":[[13.5,1.6]],"id":37208007}],"con":true,"img":false}]}
{"op":"mcm","clk":"5348163817","pt":1646214815387,"mc":[{"id":"1.195453620","rc":[{"atl":[[3.2,0]],"id":28447693}],"con":true,"img":false}]}
{"op":"mcm","clk":"5348163823","pt":1646214815486,"mc":[{"id":"1.195453620","rc":[{"atl":[[3.3,15.85]],"id":28447693}],"con":true,"img":false}]}
{"op":"mcm","clk":"5348163834","pt":1646214815695,"mc":[{"id":"1.195453620","rc":[{"atb":[[1.29,0]],"id":40310161}],"con":true,"img":false}]}
{"op":"mcm","clk":"5348163879","pt":1646214816378,"mc":[{"id":"1.195453620","rc":[{"atb":[[1.28,228.12]],"id":40310161}],"con":true,"img":false}]}
{"op":"mcm","clk":"5348163886","pt":1646214816472,"mc":[{"id":"1.195453620","rc":[{"atb":[[1.3,0]],"id":40310161}],"con":true,"img":false}]}
{"op":"mcm","clk":"5348164099","pt":1646214819202,"mc":[{"id":"1.195453620","rc":[{"atl":[[3.35,31.91],[3.25,44.44]],"id":28447693}],"con":true,"img":false}]}
{"op":"mcm","clk":"5348164245","pt":1646214821316,"mc":[{"id":"1.195453620","rc":[{"atb":[[1.29,81.78]],"id":40310161}],"con":true,"img":false}]}
{"op":"mcm","clk":"5348164381","pt":1646214823221,"mc":[{"id":"1.195453620","rc":[{"atl":[[14.5,3.7]],"id":37208007}],"con":true,"img":false}]}
{"op":"mcm","clk":"5348164393","pt":1646214823426,"mc":[{"id":"1.195453620","rc":[{"atl":[[1.85,0]],"id":37496564},{"atl":[[17.5,0]],"id":37208007},{"spn":9.3,"spf":"NaN","id":37208007},{"spn":12.2,"spf":"NaN","id":41574727}],"con":true,"img":false}]}
{"op":"mcm","clk":"5348164399","pt":1646214823532,"mc":[{"id":"1.195453620","rc":[{"atl":[[1.84,43.59]],"id":37496564}],"con":true,"img":false}]}
{"op":"mcm","clk":"5348164490","pt":1646214824782,"mc":[{"id":"1.195453620","rc":[{"atb":[[4.8,24.1],[4.2,0]],"id":37208007}],"con":true,"img":false}]}
{"op":"mcm","clk":"5348164714","pt":1646214828023,"mc":[{"id":"1.195453620","rc":[{"atb":[[1.28,0],[1.3,114.06]],"id":40310161}],"con":true,"img":false}]}
{"op":"mcm","clk":"5348165007","pt":1646214831702,"mc":[{"id":"1.195453620","rc":[{"atb":[[1.29,0]],"id":40310161}],"con":true,"img":false}]}
{"op":"mcm","clk":"5348165110","pt":1646214833238,"mc":[{"id":"1.195453620","rc":[{"atl":[[15.5,8.62]],"id":37208007},{"atb":[[1.28,228.12],[1.3,0]],"id":40310161}],"con":true,"img":false}]}
{"op":"mcm","clk":"5348165118","pt":1646214833338,"mc":[{"id":"1.195453620","rc":[{"atl":[[15.5,5.17]],"id":37208007}],"con":true,"img":false}]}
{"op":"mcm","clk":"5348165382","pt":1646214837416,"mc":[{"id":"1.195453620","rc":[{"atb":[[1.29,81.78]],"id":40310161}],"con":true,"img":false}]}
{"op":"mcm","clk":"5348165671","pt":1646214841342,"mc":[{"id":"1.195453620","rc":[{"atl":[[3.3,0]],"id":28447693}],"con":true,"img":false}]}
{"op":"mcm","clk":"5348165681","pt":1646214841445,"mc":[{"id":"1.195453620","rc":[{"atl":[[3.2,15.85]],"id":28447693}],"con":true,"img":false}]}
{"op":"mcm","clk":"5348165691","pt":1646214841549,"mc":[{"id":"1.195453620","rc":[{"atl":[[3.35,74.46],[3.25,22.22]],"id":28447693}],"con":true,"img":false}]}
{"op":"mcm","clk":"5348165808","pt":1646214843247,"mc":[{"id":"1.195453620","rc":[{"atl":[[16.5,8.06]],"id":37208007}],"con":true,"img":false}]}
{"op":"mcm","clk":"5348165891","pt":1646214844641,"mc":[{"id":"1.195453620","rc":[{"atb":[[1.3,114.06]],"id":40310161}],"con":true,"img":false}]}
{"op":"mcm","clk":"5348165900","pt":1646214844741,"mc":[{"id":"1.195453620","rc":[{"atb":[[1.28,0]],"id":40310161}],"con":true,"img":false}]}
{"op":"mcm","clk":"5348165945","pt":1646214845355,"mc":[{"id":"1.195453620","rc":[{"atl":[[1.84,0]],"id":37496564}],"con":true,"img":false}]}
{"op":"mcm","clk":"5348165952","pt":1646214845452,"mc":[{"id":"1.195453620","rc":[{"atl":[[1.83,43.59]],"id":37496564}],"con":true,"img":false}]}
{"op":"mcm","clk":"5348166119","pt":1646214847838,"mc":[{"id":"1.195453620","rc":[{"atb":[[1.29,0]],"id":40310161}],"con":true,"img":false}]}
{"op":"mcm","clk":"5348166230","pt":1646214849636,"mc":[{"id":"1.195453620","rc":[{"atl":[[3.2,0]],"id":28447693}],"con":true,"img":false}]}
{"op":"mcm","clk":"5348166238","pt":1646214849741,"mc":[{"id":"1.195453620","rc":[{"atl":[[3.3,15.85]],"id":28447693},{"atb":[[1.28,228.12],[1.3,0]],"id":40310161}],"con":true,"img":false}]}
{"op":"mcm","clk":"5348166322","pt":1646214851266,"mc":[{"id":"1.195453620","rc":[{"atb":[[1.31,76.5]],"id":40310161}],"con":true,"img":false}]}
{"op":"mcm","clk":"5348166378","pt":1646214852141,"mc":[{"id":"1.195453620","rc":[{"atl":[[3.45,8.16],[3.4,0]],"id":42464658}],"con":true,"img":false}]}
{"op":"mcm","clk":"5348166416","pt":1646214852859,"mc":[{"id":"1.195453620","rc":[{"atl":[[3.35,31.91],[3.25,44.44]],"id":28447693}],"con":true,"img":false}]}
