{"op":"mcm","clk":"5346195477","pt":1646178340818,"mc":[{"id":"1.195453760","marketDefinition":{"bspMarket":false,"turnInPlayEnabled":false,"persistenceEnabled":false,"marketBaseRate":7.0,"eventId":"31272494","eventTypeId":"4339","numberOfWinners":1,"bettingType":"ODDS","marketType":"QUINELLA","marketTime":"2022-03-02T12:04:00.000Z","suspendTime":"2022-03-02T12:04:00.000Z","bspReconciled":false,"complete":true,"inPlay":false,"crossMatching":false,"runnersVoidable":false,"numberOfActiveRunners":28,"betDelay":0,"status":"OPEN","runners":[{"status":"ACTIVE","sortPriority":1,"id":522741,"name":"1 - 2 / 2 - 1"},{"status":"ACTIVE","sortPriority":2,"id":522742,"name":"1 - 3 / 3 - 1"},{"status":"ACTIVE","sortPriority":3,"id":522743,"name":"1 - 4 / 4 - 1"},{"status":"ACTIVE","sortPriority":4,"id":7607472,"name":"1 - 5 / 5 - 1"},{"status":"ACTIVE","sortPriority":5,"id":522745,"name":"1 - 6 / 6 - 1"},{"status":"ACTIVE","sortPriority":6,"id":3805730,"name":"1 - 7 / 7 - 1"},{"status":"ACTIVE","sortPriority":7,"id":3805731,"name":"1 - 8 / 8 - 1"},{"status":"ACTIVE","sortPriority":8,"id":522746,"name":"2 - 3 / 3 - 2"},{"status":"ACTIVE","sortPriority":9,"id":522747,"name":"2 - 4 / 4 - 2"},{"status":"ACTIVE","sortPriority":10,"id":522748,"name":"2 - 5 / 5 - 2"},{"status":"ACTIVE","sortPriority":11,"id":522749,"name":"2 - 6 / 6 - 2"},{"status":"ACTIVE","sortPriority":12,"id":3805736,"name":"2 - 7 / 7 - 2"},{"status":"ACTIVE","sortPriority":13,"id":3805740,"name":"2 - 8 / 8 - 2"},{"status":"ACTIVE","sortPriority":14,"id":522750,"name":"3 - 4 / 4 - 3"},{"status":"ACTIVE","sortPriority":15,"id":522751,"name":"3 - 5 / 5 - 3"},{"status":"ACTIVE","sortPriority":16,"id":522752,"name":"3 - 6 / 6 - 3"},{"status":"ACTIVE","sortPriority":17,"id":3805746,"name":"3 - 7 / 7 - 3"},{"status":"ACTIVE","sortPriority":18,"id":3805747,"name":"3 - 8 / 8 - 3"},{"status":"ACTIVE","sortPriority":19,"id":522754,"name":"4 - 5 / 5 - 4"},{"status":"ACTIVE","sortPriority":20,"id":522753,"name":"4 - 6 / 6 - 4"},{"status":"ACTIVE","sortPriority":21,"id":3805755,"name":"4 - 7 / 7 - 4"},{"status":"ACTIVE","sortPriority":22,"id":3805762,"name":"4 - 8 / 8 - 4"},{"status":"ACTIVE","sortPriority":23,"id":522755,"name":"5 - 6 / 6 - 5"},{"status":"ACTIVE","sortPriority":24,"id":3805771,"name":"5 - 7 / 7 - 5"},{"status":"ACTIVE","sortPriority":25,"id":3805772,"name":"5 - 8 / 8 - 5"},{"status":"ACTIVE","sortPriority":26,"id":3805783,"name":"6 - 7 / 7 - 6"},{"status":"ACTIVE","sortPriority":27,"id":3805784,"name":"6 - 8 / 8 - 6"},{"status":"ACTIVE","sortPriority":28,"id":3805793,"name":"7 - 8 / 8 - 7"}],"regulators":["MR_INT"],"venue":"Traralgon","countryCode":"AU","discountAllowed":true,"timezone":"Australia/Sydney","openDate":"2022-03-02T08:31:00.000Z","version":4382480637,"name":"Quinella","eventName":"Traralgon (AUS) 2nd Mar"},"rc":[],"con":true,"img":false}]}
{"op":"mcm","clk":"5346200445","pt":1646178438495,"mc":[{"id":"1.195453760","rc":[{"atb":[[16.5,12.87],[9.6,23.2],[7.6,40.31]],"id":3805783},{"atb":[[4.6,55.43],[6.2,38.37],[3.8,95.02]],"id":3805746},{"atb":[[18.5,15.2],[27,7.67],[60,3.38]],"id":522754},{"atb":[[4.6,55.43],[3.55,78.25],[3.05,129.79]],"id":3805793},{"atb":[[9,33.26],[20,10.5],[12.5,17.35]],"id":3805736},{"atb":[[130,1.54],[46,4.43],[28,9.85]],"id":522747},{"atb":[[16,17.74],[44,4.64],[22,9.5]],"id":522749},{"atb":[[8.6,26.26],[14,15.35],[6.6,47.51]],"id":522751},{"atb":[[17,12.47],[12,24.19],[29,7.12]],"id":3805730},{"atb":[[70,2.89],[19.5,14.38],[29,7.12]],"id":522753},{"atb":[[130,1.54],[46,4.43],[28,9.85]],"id":522741},{"atb":[[310,0.64],[160,1.25],[80,3.36]],"id":522743},{"atb":[[7.2,42.91],[9.2,24.33],[15.5,13.76]],"id":3805740},{"atb":[[9,24.94],[7,44.34],[15,14.25]],"id":3805771},{"atb":[[18.5,15.2],[27,7.67],[60,3.38]],"id":7607472},{"atb":[[70,2.89],[19.5,14.38],[29,7.12]],"id":522745},{"atb":[[10,22.17],[5.5,59.12],[7,33.26]],"id":3805784},{"atb":[[4.3,60.47],[3.4,83.15],[2.96,135.75]],"id":3805747},{"atb":[[17,12.47],[12,24.19],[29,7.12]],"id":522755},{"atb":[[17,12.47],[12,24.19],[29,7.12]],"id":3805755},{"atb":[[19.5,10.78],[12,18.14],[8.8,34.11]],"id":522746},{"atb":[[40,5.11],[20,10.5],[15,19]],"id":522748},{"atb":[[16.5,12.87],[11.5,25.34],[28,7.39]],"id":522750},{"atb":[[9.2,32.44],[21,9.97],[13,16.63]],"id":3805731},{"atb":[[7.2,42.91],[9.2,24.33],[15.5,13.76]],"id":522752},{"atb":[[9.2,32.44],[21,9.97],[13,16.63]],"id":3805762},{"atb":[[16.5,12.87],[11.5,25.34],[28,7.39]],"id":522742},{"atb":[[5.1,64.89],[9.2,24.33],[6.2,38.37]],"id":3805772}],"con":true,"img":false}]}
{"op":"mcm","clk":"5346220478","pt":1646178834216,"mc":[{"id":"1.195453760","rc":[{"atb":[[16.5,0],[9.6,0],[7.6,0]],"id":3805783},{"atb":[[4.6,0],[6.2,0],[3.8,0]],"id":3805746},{"atb":[[18.5,0],[27,0],[60,0]],"id":522754},{"atb":[[4.6,0],[3.55,0],[3.05,0]],"id":3805793},{"atb":[[9,0],[20,0],[12.5,0]],"id":3805736},{"atb":[[130,0],[46,0],[28,0]],"id":522747},{"atb":[[16,0],[44,0],[22,0]],"id":522749},{"atb":[[8.6,0],[14,0],[6.6,0]],"id":522751},{"atb":[[17,0],[12,0],[29,0]],"id":3805730},{"atb":[[70,0],[19.5,0],[29,0]],"id":522753},{"atb":[[130,0],[46,0],[28,0]],"id":522741},{"atb":[[310,0],[160,0],[80,0]],"id":522743},{"atb":[[7.2,0],[9.2,0],[15.5,0]],"id":3805740},{"atb":[[9,0],[7,0],[15,0]],"id":3805771},{"atb":[[18.5,0],[27,0],[60,0]],"id":7607472},{"atb":[[70,0],[19.5,0],[29,0]],"id":522745},{"atb":[[10,0],[5.5,0],[7,0]],"id":3805784},{"atb":[[4.3,0],[3.4,0],[2.96,0]],"id":3805747},{"atb":[[17,0],[12,0],[29,0]],"id":522755},{"atb":[[17,0],[12,0],[29,0]],"id":3805755},{"atb":[[19.5,0],[12,0],[8.8,0]],"id":522746},{"atb":[[40,0],[20,0],[15,0]],"id":522748},{"atb":[[16.5,0],[11.5,0],[28,0]],"id":522750},{"atb":[[9.2,0],[21,0],[13,0]],"id":3805731},{"atb":[[7.2,0],[9.2,0],[15.5,0]],"id":522752},{"atb":[[9.2,0],[21,0],[13,0]],"id":3805762},{"atb":[[16.5,0],[11.5,0],[28,0]],"id":522742},{"atb":[[5.1,0],[9.2,0],[6.2,0]],"id":3805772}],"con":true,"img":false}]}
{"op":"mcm","clk":"5346221440","pt":1646178853461,"mc":[{"id":"1.195453760","rc":[{"atb":[[16,13.3],[7.4,41.57],[9.4,23.75]],"id":3805783},{"atb":[[3.7,98.55],[4.4,58.69],[5.9,40.72]],"id":3805746},{"atb":[[70,2.89],[19.5,14.38],[29,7.12]],"id":522754},{"atb":[[4.5,57.01],[3,133.04],[3.5,79.82]],"id":3805793},{"atb":[[9.6,30.94],[23,9.06],[14,15.35]],"id":3805736},{"atb":[[80,2.52],[42,6.48],[210,0.95]],"id":522747},{"atb":[[16.5,17.16],[46,4.43],[23,9.06]],"id":522749},{"atb":[[6.4,49.27],[13.5,15.96],[8.4,26.96]],"id":522751},{"atb":[[17.5,12.09],[12.5,23.13],[30,6.88]],"id":3805730},{"atb":[[32,6.43],[80,2.52],[21,13.3]],"id":522753},{"atb":[[80,2.52],[42,6.48],[210,0.95]],"id":522741},{"atb":[[290,0.69],[190,1.4],[440,0.45]],"id":522743},{"atb":[[17,12.47],[9.8,22.67],[7.8,39.12]],"id":3805740},{"atb":[[6.8,45.87],[8.8,25.58],[14.5,14.78]],"id":3805771},{"atb":[[70,2.89],[19.5,14.38],[29,7.12]],"id":7607472},{"atb":[[32,6.43],[80,2.52],[21,13.3]],"id":522745},{"atb":[[6.8,34.4],[9.8,22.67],[5.4,60.47]],"id":3805784},{"atb":[[4,66.52],[2.9,140.04],[3.25,88.69]],"id":3805747},{"atb":[[17,12.47],[12,24.19],[29,7.12]],"id":522755},{"atb":[[17.5,12.09],[12.5,23.13],[30,6.88]],"id":3805755},{"atb":[[9.2,32.44],[21,9.97],[13,16.63]],"id":522746},{"atb":[[16,17.74],[44,4.64],[22,9.5]],"id":522748},{"atb":[[17,12.47],[12,24.19],[29,7.12]],"id":522750},{"atb":[[9.6,30.94],[23,9.06],[14,15.35]],"id":3805731},{"atb":[[9,24.94],[7,44.34],[15,14.25]],"id":522752},{"atb":[[9.6,30.94],[23,9.06],[14,15.35]],"id":3805762},{"atb":[[17,12.47],[12,24.19],[29,7.12]],"id":522742},{"atb":[[9,24.94],[5,66.52],[6,39.91]],"id":3805772}],"con":true,"img":false}]}
{"op":"mcm","clk":"5346401341","pt":1646182002777,"mc":[{"id":"1.195453760","marketDefinition":{"bspMarket":false,"turnInPlayEnabled":false,"persistenceEnabled":false,"marketBaseRate":7.0,"eventId":"31272494","eventTypeId":"4339","numberOfWinners":1,"bettingType":"ODDS","marketType":"QUINELLA","marketTime":"2022-03-02T12:04:00.000Z","suspendTime":"2022-03-02T12:04:00.000Z","bspReconciled":false,"complete":true,"inPlay":false,"crossMatching":false,"runnersVoidable":false,"numberOfActiveRunners":28,"betDelay":0,"status":"OPEN","runners":[{"status":"ACTIVE","sortPriority":1,"id":522741,"name":"1 - 2 / 2 - 1"},{"status":"ACTIVE","sortPriority":2,"id":522742,"name":"1 - 3 / 3 - 1"},{"status":"ACTIVE","sortPriority":3,"id":522743,"name":"1 - 4 / 4 - 1"},{"status":"ACTIVE","sortPriority":4,"id":7607472,"name":"1 - 5 / 5 - 1"},{"status":"ACTIVE","sortPriority":5,"id":522745,"name":"1 - 6 / 6 - 1"},{"status":"ACTIVE","sortPriority":6,"id":3805730,"name":"1 - 7 / 7 - 1"},{"status":"ACTIVE","sortPriority":7,"id":3805731,"name":"1 - 8 / 8 - 1"},{"status":"ACTIVE","sortPriority":8,"id":522746,"name":"2 - 3 / 3 - 2"},{"status":"ACTIVE","sortPriority":9,"id":522747,"name":"2 - 4 / 4 - 2"},{"status":"ACTIVE","sortPriority":10,"id":522748,"name":"2 - 5 / 5 - 2"},{"status":"ACTIVE","sortPriority":11,"id":522749,"name":"2 - 6 / 6 - 2"},{"status":"ACTIVE","sortPriority":12,"id":3805736,"name":"2 - 7 / 7 - 2"},{"status":"ACTIVE","sortPriority":13,"id":3805740,"name":"2 - 8 / 8 - 2"},{"status":"ACTIVE","sortPriority":14,"id":522750,"name":"3 - 4 / 4 - 3"},{"status":"ACTIVE","sortPriority":15,"id":522751,"name":"3 - 5 / 5 - 3"},{"status":"ACTIVE","sortPriority":16,"id":522752,"name":"3 - 6 / 6 - 3"},{"status":"ACTIVE","sortPriority":17,"id":3805746,"name":"3 - 7 / 7 - 3"},{"status":"ACTIVE","sortPriority":18,"id":3805747,"name":"3 - 8 / 8 - 3"},{"status":"ACTIVE","sortPriority":19,"id":522754,"name":"4 - 5 / 5 - 4"},{"status":"ACTIVE","sortPriority":20,"id":522753,"name":"4 - 6 / 6 - 4"},{"status":"ACTIVE","sortPriority":21,"id":3805755,"name":"4 - 7 / 7 - 4"},{"status":"ACTIVE","sortPriority":22,"id":3805762,"name":"4 - 8 / 8 - 4"},{"status":"ACTIVE","sortPriority":23,"id":522755,"name":"5 - 6 / 6 - 5"},{"status":"ACTIVE","sortPriority":24,"id":3805771,"name":"5 - 7 / 7 - 5"},{"status":"ACTIVE","sortPriority":25,"id":3805772,"name":"5 - 8 / 8 - 5"},{"status":"ACTIVE","sortPriority":26,"id":3805783,"name":"6 - 7 / 7 - 6"},{"status":"ACTIVE","sortPriority":27,"id":3805784,"name":"6 - 8 / 8 - 6"},{"status":"ACTIVE","sortPriority":28,"id":3805793,"name":"7 - 8 / 8 - 7"}],"regulators":["MR_INT"],"venue":"Traralgon","countryCode":"AU","discountAllowed":true,"timezone":"Australia/Sydney","openDate":"2022-03-02T08:31:00.000Z","version":4382480637,"name":"Quinella","eventName":"Traralgon (AUS) 2nd Mar"},"rc":[{"atb":[[16,13.3],[7.4,41.58],[9.4,23.75]],"id":3805783},{"atb":[[3.7,98.56],[4.4,58.69],[5.9,40.73]],"id":3805746},{"atb":[[70,2.89],[19.5,14.38],[29,7.12]],"id":522754},{"atb":[[4.5,57.02],[3,133.05],[3.5,79.83]],"id":3805793},{"atb":[[9.6,30.94],[23,9.07],[14,15.35]],"id":3805736},{"atb":[[80,2.52],[42,6.48],[210,0.95]],"id":522747},{"atb":[[16.5,17.17],[46,4.43],[23,9.07]],"id":522749},{"atb":[[6.4,49.28],[13.5,15.96],[8.4,26.97]],"id":522751},{"atb":[[17.5,12.09],[12.5,23.13],[30,6.88]],"id":3805730},{"atb":[[32,6.44],[80,2.52],[21,13.3]],"id":522753},{"atb":[[80,2.52],[42,6.48],[210,0.95]],"id":522741},{"atb":[[290,0.69],[190,1.41],[440,0.45]],"id":522743},{"atb":[[17,12.47],[9.8,22.68],[7.8,39.13]],"id":3805740},{"atb":[[6.8,45.88],[8.8,25.58],[14.5,14.78]],"id":3805771},{"atb":[[70,2.89],[19.5,14.38],[29,7.12]],"id":7607472},{"atb":[[32,6.44],[80,2.52],[21,13.3]],"id":522745},{"atb":[[6.8,34.41],[9.8,22.68],[5.4,60.48]],"id":3805784},{"atb":[[4,66.52],[2.9,140.05],[3.25,88.7]],"id":3805747},{"atb":[[17,12.47],[12,24.19],[29,7.12]],"id":522755},{"atb":[[17.5,12.09],[12.5,23.13],[30,6.88]],"id":3805755},{"atb":[[9.2,32.45],[21,9.97],[13,16.63]],"id":522746},{"atb":[[16,17.74],[44,4.64],[22,9.5]],"id":522748},{"atb":[[17,12.47],[12,24.19],[29,7.12]],"id":522750},{"atb":[[9.6,30.94],[23,9.07],[14,15.35]],"id":3805731},{"atb":[[9,24.94],[7,44.35],[15,14.25]],"id":522752},{"atb":[[9.6,30.94],[23,9.07],[14,15.35]],"id":3805762},{"atb":[[17,12.47],[12,24.19],[29,7.12]],"id":522742},{"atb":[[9,24.94],[5,66.52],[6,39.91]],"id":3805772}],"con":true,"img":true}]}
{"op":"mcm","clk":"5346767701","pt":1646187402721,"mc":[{"id":"1.195453760","marketDefinition":{"bspMarket":false,"turnInPlayEnabled":false,"persistenceEnabled":false,"marketBaseRate":7.0,"eventId":"31272494","eventTypeId":"4339","numberOfWinners":1,"bettingType":"ODDS","marketType":"QUINELLA","marketTime":"2022-03-02T12:04:00.000Z","suspendTime":"2022-03-02T12:04:00.000Z","bspReconciled":false,"complete":true,"inPlay":false,"crossMatching":false,"runnersVoidable":false,"numberOfActiveRunners":28,"betDelay":0,"status":"OPEN","runners":[{"status":"ACTIVE","sortPriority":1,"id":522741,"name":"1 - 2 / 2 - 1"},{"status":"ACTIVE","sortPriority":2,"id":522742,"name":"1 - 3 / 3 - 1"},{"status":"ACTIVE","sortPriority":3,"id":522743,"name":"1 - 4 / 4 - 1"},{"status":"ACTIVE","sortPriority":4,"id":7607472,"name":"1 - 5 / 5 - 1"},{"status":"ACTIVE","sortPriority":5,"id":522745,"name":"1 - 6 / 6 - 1"},{"status":"ACTIVE","sortPriority":6,"id":3805730,"name":"1 - 7 / 7 - 1"},{"status":"ACTIVE","sortPriority":7,"id":3805731,"name":"1 - 8 / 8 - 1"},{"status":"ACTIVE","sortPriority":8,"id":522746,"name":"2 - 3 / 3 - 2"},{"status":"ACTIVE","sortPriority":9,"id":522747,"name":"2 - 4 / 4 - 2"},{"status":"ACTIVE","sortPriority":10,"id":522748,"name":"2 - 5 / 5 - 2"},{"status":"ACTIVE","sortPriority":11,"id":522749,"name":"2 - 6 / 6 - 2"},{"status":"ACTIVE","sortPriority":12,"id":3805736,"name":"2 - 7 / 7 - 2"},{"status":"ACTIVE","sortPriority":13,"id":3805740,"name":"2 - 8 / 8 - 2"},{"status":"ACTIVE","sortPriority":14,"id":522750,"name":"3 - 4 / 4 - 3"},{"status":"ACTIVE","sortPriority":15,"id":522751,"name":"3 - 5 / 5 - 3"},{"status":"ACTIVE","sortPriority":16,"id":522752,"name":"3 - 6 / 6 - 3"},{"status":"ACTIVE","sortPriority":17,"id":3805746,"name":"3 - 7 / 7 - 3"},{"status":"ACTIVE","sortPriority":18,"id":3805747,"name":"3 - 8 / 8 - 3"},{"status":"ACTIVE","sortPriority":19,"id":522754,"name":"4 - 5 / 5 - 4"},{"status":"ACTIVE","sortPriority":20,"id":522753,"name":"4 - 6 / 6 - 4"},{"status":"ACTIVE","sortPriority":21,"id":3805755,"name":"4 - 7 / 7 - 4"},{"status":"ACTIVE","sortPriority":22,"id":3805762,"name":"4 - 8 / 8 - 4"},{"status":"ACTIVE","sortPriority":23,"id":522755,"name":"5 - 6 / 6 - 5"},{"status":"ACTIVE","sortPriority":24,"id":3805771,"name":"5 - 7 / 7 - 5"},{"status":"ACTIVE","sortPriority":25,"id":3805772,"name":"5 - 8 / 8 - 5"},{"status":"ACTIVE","sortPriority":26,"id":3805783,"name":"6 - 7 / 7 - 6"},{"status":"ACTIVE","sortPriority":27,"id":3805784,"name":"6 - 8 / 8 - 6"},{"status":"ACTIVE","sortPriority":28,"id":3805793,"name":"7 - 8 / 8 - 7"}],"regulators":["MR_INT"],"venue":"Traralgon","countryCode":"AU","discountAllowed":true,"timezone":"Australia/Sydney","openDate":"2022-03-02T08:31:00.000Z","version":4382480637,"name":"Quinella","eventName":"Traralgon (AUS) 2nd Mar"},"rc":[{"atb":[[16,13.32],[7.4,41.64],[9.4,23.79]],"id":3805783},{"atb":[[3.7,98.71],[4.4,58.79],[5.9,40.79]],"id":3805746},{"atb":[[70,2.89],[19.5,14.4],[29,7.13]],"id":522754},{"atb":[[4.5,57.11],[3,133.26],[3.5,79.96]],"id":3805793},{"atb":[[9.6,30.99],[23,9.08],[14,15.37]],"id":3805736},{"atb":[[80,2.53],[42,6.49],[210,0.95]],"id":522747},{"atb":[[16.5,17.19],[46,4.44],[23,9.08]],"id":522749},{"atb":[[6.4,49.35],[13.5,15.99],[8.4,27.01]],"id":522751},{"atb":[[17.5,12.11],[12.5,23.17],[30,6.89]],"id":3805730},{"atb":[[32,6.45],[80,2.53],[21,13.32]],"id":522753},{"atb":[[80,2.53],[42,6.49],[210,0.95]],"id":522741},{"atb":[[290,0.69],[190,1.41],[440,0.45]],"id":522743},{"atb":[[17,12.49],[9.8,22.71],[7.8,39.19]],"id":3805740},{"atb":[[6.8,45.95],[8.8,25.62],[14.5,14.8]],"id":3805771},{"atb":[[70,2.89],[19.5,14.4],[29,7.13]],"id":7607472},{"atb":[[32,6.45],[80,2.53],[21,13.32]],"id":522745},{"atb":[[6.8,34.46],[9.8,22.71],[5.4,60.57]],"id":3805784},{"atb":[[4,66.63],[2.9,140.28],[3.25,88.84]],"id":3805747},{"atb":[[17,12.49],[12,24.23],[29,7.13]],"id":522755},{"atb":[[17.5,12.11],[12.5,23.17],[30,6.89]],"id":3805755},{"atb":[[9.2,32.5],[21,9.99],[13,16.65]],"id":522746},{"atb":[[16,17.77],[44,4.65],[22,9.52]],"id":522748},{"atb":[[17,12.49],[12,24.23],[29,7.13]],"id":522750},{"atb":[[9.6,30.99],[23,9.08],[14,15.37]],"id":3805731},{"atb":[[9,24.98],[7,44.42],[15,14.28]],"id":522752},{"atb":[[9.6,30.99],[23,9.08],[14,15.37]],"id":3805762},{"atb":[[17,12.49],[12,24.23],[29,7.13]],"id":522742},{"atb":[[9,24.98],[5,66.63],[6,39.98]],"id":3805772}],"con":true,"img":true}]}
{"op":"mcm","clk":"5347092265","pt":1646192802703,"mc":[{"id":"1.195453760","marketDefinition":{"bspMarket":false,"turnInPlayEnabled":false,"persistenceEnabled":false,"marketBaseRate":7.0,"eventId":"31272494","eventTypeId":"4339","numberOfWinners":1,"bettingType":"ODDS","marketType":"QUINELLA","marketTime":"2022-03-02T12:04:00.000Z","suspendTime":"2022-03-02T12:04:00.000Z","bspReconciled":false,"complete":true,"inPlay":false,"crossMatching":false,"runnersVoidable":false,"numberOfActiveRunners":28,"betDelay":0,"status":"OPEN","runners":[{"status":"ACTIVE","sortPriority":1,"id":522741,"name":"1 - 2 / 2 - 1"},{"status":"ACTIVE","sortPriority":2,"id":522742,"name":"1 - 3 / 3 - 1"},{"status":"ACTIVE","sortPriority":3,"id":522743,"name":"1 - 4 / 4 - 1"},{"status":"ACTIVE","sortPriority":4,"id":7607472,"name":"1 - 5 / 5 - 1"},{"status":"ACTIVE","sortPriority":5,"id":522745,"name":"1 - 6 / 6 - 1"},{"status":"ACTIVE","sortPriority":6,"id":3805730,"name":"1 - 7 / 7 - 1"},{"status":"ACTIVE","sortPriority":7,"id":3805731,"name":"1 - 8 / 8 - 1"},{"status":"ACTIVE","sortPriority":8,"id":522746,"name":"2 - 3 / 3 - 2"},{"status":"ACTIVE","sortPriority":9,"id":522747,"name":"2 - 4 / 4 - 2"},{"status":"ACTIVE","sortPriority":10,"id":522748,"name":"2 - 5 / 5 - 2"},{"status":"ACTIVE","sortPriority":11,"id":522749,"name":"2 - 6 / 6 - 2"},{"status":"ACTIVE","sortPriority":12,"id":3805736,"name":"2 - 7 / 7 - 2"},{"status":"ACTIVE","sortPriority":13,"id":3805740,"name":"2 - 8 / 8 - 2"},{"status":"ACTIVE","sortPriority":14,"id":522750,"name":"3 - 4 / 4 - 3"},{"status":"ACTIVE","sortPriority":15,"id":522751,"name":"3 - 5 / 5 - 3"},{"status":"ACTIVE","sortPriority":16,"id":522752,"name":"3 - 6 / 6 - 3"},{"status":"ACTIVE","sortPriority":17,"id":3805746,"name":"3 - 7 / 7 - 3"},{"status":"ACTIVE","sortPriority":18,"id":3805747,"name":"3 - 8 / 8 - 3"},{"status":"ACTIVE","sortPriority":19,"id":522754,"name":"4 - 5 / 5 - 4"},{"status":"ACTIVE","sortPriority":20,"id":522753,"name":"4 - 6 / 6 - 4"},{"status":"ACTIVE","sortPriority":21,"id":3805755,"name":"4 - 7 / 7 - 4"},{"status":"ACTIVE","sortPriority":22,"id":3805762,"name":"4 - 8 / 8 - 4"},{"status":"ACTIVE","sortPriority":23,"id":522755,"name":"5 - 6 / 6 - 5"},{"status":"ACTIVE","sortPriority":24,"id":3805771,"name":"5 - 7 / 7 - 5"},{"status":"ACTIVE","sortPriority":25,"id":3805772,"name":"5 - 8 / 8 - 5"},{"status":"ACTIVE","sortPriority":26,"id":3805783,"name":"6 - 7 / 7 - 6"},{"status":"ACTIVE","sortPriority":27,"id":3805784,"name":"6 - 8 / 8 - 6"},{"status":"ACTIVE","sortPriority":28,"id":3805793,"name":"7 - 8 / 8 - 7"}],"regulators":["MR_INT"],"venue":"Traralgon","countryCode":"AU","discountAllowed":true,"timezone":"Australia/Sydney","openDate":"2022-03-02T08:31:00.000Z","version":4382480637,"name":"Quinella","eventName":"Traralgon (AUS) 2nd Mar"},"rc":[{"atb":[[16,13.34],[7.4,41.71],[9.4,23.83]],"id":3805783},{"atb":[[3.7,98.88],[4.4,58.89],[5.9,40.86]],"id":3805746},{"atb":[[70,2.9],[19.5,14.43],[29,7.14]],"id":522754},{"atb":[[4.5,57.2],[3,133.49],[3.5,80.09]],"id":3805793},{"atb":[[9.6,31.04],[23,9.09],[14,15.4]],"id":3805736},{"atb":[[80,2.53],[42,6.51],[210,0.95]],"id":522747},{"atb":[[16.5,17.22],[46,4.45],[23,9.09]],"id":522749},{"atb":[[6.4,49.44],[13.5,16.02],[8.4,27.05]],"id":522751},{"atb":[[17.5,12.13],[12.5,23.21],[30,6.9]],"id":3805730},{"atb":[[32,6.46],[80,2.53],[21,13.34]],"id":522753},{"atb":[[80,2.53],[42,6.51],[210,0.95]],"id":522741},{"atb":[[290,0.69],[190,1.41],[440,0.45]],"id":522743},{"atb":[[17,12.51],[9.8,22.75],[7.8,39.26]],"id":3805740},{"atb":[[6.8,46.03],[8.8,25.67],[14.5,14.83]],"id":3805771},{"atb":[[70,2.9],[19.5,14.43],[29,7.14]],"id":7607472},{"atb":[[32,6.46],[80,2.53],[21,13.34]],"id":522745},{"atb":[[6.8,34.52],[9.8,22.75],[5.4,60.67]],"id":3805784},{"atb":[[4,66.74],[2.9,140.51],[3.25,88.99]],"id":3805747},{"atb":[[17,12.51],[12,24.27],[29,7.14]],"id":522755},{"atb":[[17.5,12.13],[12.5,23.21],[30,6.9]],"id":3805755},{"atb":[[9.2,32.55],[21,10.01],[13,16.68]],"id":522746},{"atb":[[16,17.8],[44,4.65],[22,9.53]],"id":522748},{"atb":[[17,12.51],[12,24.27],[29,7.14]],"id":522750},{"atb":[[9.6,31.04],[23,9.09],[14,15.4]],"id":3805731},{"atb":[[9,25.02],[7,44.49],[15,14.3]],"id":522752},{"atb":[[9.6,31.04],[23,9.09],[14,15.4]],"id":3805762},{"atb":[[17,12.51],[12,24.27],[29,7.14]],"id":522742},{"atb":[[9,25.02],[5,66.74],[6,40.04]],"id":3805772}],"con":true,"img":true}]}
{"op":"mcm","clk":"5347381138","pt":1646198202721,"mc":[{"id":"1.195453760","marketDefinition":{"bspMarket":false,"turnInPlayEnabled":false,"persistenceEnabled":false,"marketBaseRate":7.0,"eventId":"31272494","eventTypeId":"4339","numberOfWinners":1,"bettingType":"ODDS","marketType":"QUINELLA","marketTime":"2022-03-02T12:04:00.000Z","suspendTime":"2022-03-02T12:04:00.000Z","bspReconciled":false,"complete":true,"inPlay":false,"crossMatching":false,"runnersVoidable":false,"numberOfActiveRunners":28,"betDelay":0,"status":"OPEN","runners":[{"status":"ACTIVE","sortPriority":1,"id":522741,"name":"1 - 2 / 2 - 1"},{"status":"ACTIVE","sortPriority":2,"id":522742,"name":"1 - 3 / 3 - 1"},{"status":"ACTIVE","sortPriority":3,"id":522743,"name":"1 - 4 / 4 - 1"},{"status":"ACTIVE","sortPriority":4,"id":7607472,"name":"1 - 5 / 5 - 1"},{"status":"ACTIVE","sortPriority":5,"id":522745,"name":"1 - 6 / 6 - 1"},{"status":"ACTIVE","sortPriority":6,"id":3805730,"name":"1 - 7 / 7 - 1"},{"status":"ACTIVE","sortPriority":7,"id":3805731,"name":"1 - 8 / 8 - 1"},{"status":"ACTIVE","sortPriority":8,"id":522746,"name":"2 - 3 / 3 - 2"},{"status":"ACTIVE","sortPriority":9,"id":522747,"name":"2 - 4 / 4 - 2"},{"status":"ACTIVE","sortPriority":10,"id":522748,"name":"2 - 5 / 5 - 2"},{"status":"ACTIVE","sortPriority":11,"id":522749,"name":"2 - 6 / 6 - 2"},{"status":"ACTIVE","sortPriority":12,"id":3805736,"name":"2 - 7 / 7 - 2"},{"status":"ACTIVE","sortPriority":13,"id":3805740,"name":"2 - 8 / 8 - 2"},{"status":"ACTIVE","sortPriority":14,"id":522750,"name":"3 - 4 / 4 - 3"},{"status":"ACTIVE","sortPriority":15,"id":522751,"name":"3 - 5 / 5 - 3"},{"status":"ACTIVE","sortPriority":16,"id":522752,"name":"3 - 6 / 6 - 3"},{"status":"ACTIVE","sortPriority":17,"id":3805746,"name":"3 - 7 / 7 - 3"},{"status":"ACTIVE","sortPriority":18,"id":3805747,"name":"3 - 8 / 8 - 3"},{"status":"ACTIVE","sortPriority":19,"id":522754,"name":"4 - 5 / 5 - 4"},{"status":"ACTIVE","sortPriority":20,"id":522753,"name":"4 - 6 / 6 - 4"},{"status":"ACTIVE","sortPriority":21,"id":3805755,"name":"4 - 7 / 7 - 4"},{"status":"ACTIVE","sortPriority":22,"id":3805762,"name":"4 - 8 / 8 - 4"},{"status":"ACTIVE","sortPriority":23,"id":522755,"name":"5 - 6 / 6 - 5"},{"status":"ACTIVE","sortPriority":24,"id":3805771,"name":"5 - 7 / 7 - 5"},{"status":"ACTIVE","sortPriority":25,"id":3805772,"name":"5 - 8 / 8 - 5"},{"status":"ACTIVE","sortPriority":26,"id":3805783,"name":"6 - 7 / 7 - 6"},{"status":"ACTIVE","sortPriority":27,"id":3805784,"name":"6 - 8 / 8 - 6"},{"status":"ACTIVE","sortPriority":28,"id":3805793,"name":"7 - 8 / 8 - 7"}],"regulators":["MR_INT"],"venue":"Traralgon","countryCode":"AU","discountAllowed":true,"timezone":"Australia/Sydney","openDate":"2022-03-02T08:31:00.000Z","version":4382480637,"name":"Quinella","eventName":"Traralgon (AUS) 2nd Mar"},"rc":[{"atb":[[16,13.34],[7.4,41.7],[9.4,23.82]],"id":3805783},{"atb":[[3.7,98.84],[4.4,58.86],[5.9,40.85]],"id":3805746},{"atb":[[70,2.89],[19.5,14.42],[29,7.14]],"id":522754},{"atb":[[4.5,57.18],[3,133.44],[3.5,80.06]],"id":3805793},{"atb":[[9.6,31.03],[23,9.09],[14,15.39]],"id":3805736},{"atb":[[80,2.53],[42,6.5],[210,0.95]],"id":522747},{"atb":[[16.5,17.22],[46,4.44],[23,9.09]],"id":522749},{"atb":[[6.4,49.42],[13.5,16.01],[8.4,27.04]],"id":522751},{"atb":[[17.5,12.13],[12.5,23.2],[30,6.9]],"id":3805730},{"atb":[[32,6.45],[80,2.53],[21,13.34]],"id":522753},{"atb":[[80,2.53],[42,6.5],[210,0.95]],"id":522741},{"atb":[[290,0.69],[190,1.41],[440,0.45]],"id":522743},{"atb":[[17,12.5],[9.8,22.74],[7.8,39.24]],"id":3805740},{"atb":[[6.8,46.01],[8.8,25.66],[14.5,14.82]],"id":3805771},{"atb":[[70,2.89],[19.5,14.42],[29,7.14]],"id":7607472},{"atb":[[32,6.45],[80,2.53],[21,13.34]],"id":522745},{"atb":[[6.8,34.51],[9.8,22.74],[5.4,60.65]],"id":3805784},{"atb":[[4,66.72],[2.9,140.46],[3.25,88.95]],"id":3805747},{"atb":[[17,12.5],[12,24.26],[29,7.14]],"id":522755},{"atb":[[17.5,12.13],[12.5,23.2],[30,6.9]],"id":3805755},{"atb":[[9.2,32.54],[21,10],[13,16.68]],"id":522746},{"atb":[[16,17.79],[44,4.65],[22,9.53]],"id":522748},{"atb":[[17,12.5],[12,24.26],[29,7.14]],"id":522750},{"atb":[[9.6,31.03],[23,9.09],[14,15.39]],"id":3805731},{"atb":[[9,25.01],[7,44.48],[15,14.29]],"id":522752},{"atb":[[9.6,31.03],[23,9.09],[14,15.39]],"id":3805762},{"atb":[[17,12.5],[12,24.26],[29,7.14]],"id":522742},{"atb":[[9,25.01],[5,66.72],[6,40.03]],"id":3805772}],"con":true,"img":true}]}
{"op":"mcm","clk":"5347848822","pt":1646209002725,"mc":[{"id":"1.195453760","marketDefinition":{"bspMarket":false,"turnInPlayEnabled":false,"persistenceEnabled":false,"marketBaseRate":7.0,"eventId":"31272494","eventTypeId":"4339","numberOfWinners":1,"bettingType":"ODDS","marketType":"QUINELLA","marketTime":"2022-03-02T12:04:00.000Z","suspendTime":"2022-03-02T12:04:00.000Z","bspReconciled":false,"complete":true,"inPlay":false,"crossMatching":false,"runnersVoidable":false,"numberOfActiveRunners":28,"betDelay":0,"status":"OPEN","runners":[{"status":"ACTIVE","sortPriority":1,"id":522741,"name":"1 - 2 / 2 - 1"},{"status":"ACTIVE","sortPriority":2,"id":522742,"name":"1 - 3 / 3 - 1"},{"status":"ACTIVE","sortPriority":3,"id":522743,"name":"1 - 4 / 4 - 1"},{"status":"ACTIVE","sortPriority":4,"id":7607472,"name":"1 - 5 / 5 - 1"},{"status":"ACTIVE","sortPriority":5,"id":522745,"name":"1 - 6 / 6 - 1"},{"status":"ACTIVE","sortPriority":6,"id":3805730,"name":"1 - 7 / 7 - 1"},{"status":"ACTIVE","sortPriority":7,"id":3805731,"name":"1 - 8 / 8 - 1"},{"status":"ACTIVE","sortPriority":8,"id":522746,"name":"2 - 3 / 3 - 2"},{"status":"ACTIVE","sortPriority":9,"id":522747,"name":"2 - 4 / 4 - 2"},{"status":"ACTIVE","sortPriority":10,"id":522748,"name":"2 - 5 / 5 - 2"},{"status":"ACTIVE","sortPriority":11,"id":522749,"name":"2 - 6 / 6 - 2"},{"status":"ACTIVE","sortPriority":12,"id":3805736,"name":"2 - 7 / 7 - 2"},{"status":"ACTIVE","sortPriority":13,"id":3805740,"name":"2 - 8 / 8 - 2"},{"status":"ACTIVE","sortPriority":14,"id":522750,"name":"3 - 4 / 4 - 3"},{"status":"ACTIVE","sortPriority":15,"id":522751,"name":"3 - 5 / 5 - 3"},{"status":"ACTIVE","sortPriority":16,"id":522752,"name":"3 - 6 / 6 - 3"},{"status":"ACTIVE","sortPriority":17,"id":3805746,"name":"3 - 7 / 7 - 3"},{"status":"ACTIVE","sortPriority":18,"id":3805747,"name":"3 - 8 / 8 - 3"},{"status":"ACTIVE","sortPriority":19,"id":522754,"name":"4 - 5 / 5 - 4"},{"status":"ACTIVE","sortPriority":20,"id":522753,"name":"4 - 6 / 6 - 4"},{"status":"ACTIVE","sortPriority":21,"id":3805755,"name":"4 - 7 / 7 - 4"},{"status":"ACTIVE","sortPriority":22,"id":3805762,"name":"4 - 8 / 8 - 4"},{"status":"ACTIVE","sortPriority":23,"id":522755,"name":"5 - 6 / 6 - 5"},{"status":"ACTIVE","sortPriority":24,"id":3805771,"name":"5 - 7 / 7 - 5"},{"status":"ACTIVE","sortPriority":25,"id":3805772,"name":"5 - 8 / 8 - 5"},{"status":"ACTIVE","sortPriority":26,"id":3805783,"name":"6 - 7 / 7 - 6"},{"status":"ACTIVE","sortPriority":27,"id":3805784,"name":"6 - 8 / 8 - 6"},{"status":"ACTIVE","sortPriority":28,"id":3805793,"name":"7 - 8 / 8 - 7"}],"regulators":["MR_INT"],"venue":"Traralgon","countryCode":"AU","discountAllowed":true,"timezone":"Australia/Sydney","openDate":"2022-03-02T08:31:00.000Z","version":4382480637,"name":"Quinella","eventName":"Traralgon (AUS) 2nd Mar"},"rc":[{"atb":[[16,13.34],[7.4,41.69],[9.4,23.82]],"id":3805783},{"atb":[[3.7,98.82],[4.4,58.85],[5.9,40.84]],"id":3805746},{"atb":[[70,2.89],[19.5,14.42],[29,7.14]],"id":522754},{"atb":[[4.5,57.17],[3,133.4],[3.5,80.04]],"id":3805793},{"atb":[[9.6,31.02],[23,9.09],[14,15.39]],"id":3805736},{"atb":[[80,2.53],[42,6.5],[210,0.95]],"id":522747},{"atb":[[16.5,17.21],[46,4.44],[23,9.09]],"id":522749},{"atb":[[6.4,49.41],[13.5,16],[8.4,27.04]],"id":522751},{"atb":[[17.5,12.12],[12.5,23.19],[30,6.89]],"id":3805730},{"atb":[[32,6.45],[80,2.53],[21,13.34]],"id":522753},{"atb":[[80,2.53],[42,6.5],[210,0.95]],"id":522741},{"atb":[[290,0.69],[190,1.41],[440,0.45]],"id":522743},{"atb":[[17,12.5],[9.8,22.74],[7.8,39.23]],"id":3805740},{"atb":[[6.8,46],[8.8,25.65],[14.5,14.82]],"id":3805771},{"atb":[[70,2.89],[19.5,14.42],[29,7.14]],"id":7607472},{"atb":[[32,6.45],[80,2.53],[21,13.34]],"id":522745},{"atb":[[6.8,34.5],[9.8,22.74],[5.4,60.63]],"id":3805784},{"atb":[[4,66.7],[2.9,140.42],[3.25,88.93]],"id":3805747},{"atb":[[17,12.5],[12,24.25],[29,7.14]],"id":522755},{"atb":[[17.5,12.12],[12.5,23.19],[30,6.89]],"id":3805755},{"atb":[[9.2,32.53],[21,10],[13,16.67]],"id":522746},{"atb":[[16,17.78],[44,4.65],[22,9.53]],"id":522748},{"atb":[[17,12.5],[12,24.25],[29,7.14]],"id":522750},{"atb":[[9.6,31.02],[23,9.09],[14,15.39]],"id":3805731},{"atb":[[9,25.01],[7,44.47],[15,14.29]],"id":522752},{"atb":[[9.6,31.02],[23,9.09],[14,15.39]],"id":3805762},{"atb":[[17,12.5],[12,24.25],[29,7.14]],"id":522742},{"atb":[[9,25.01],[5,66.7],[6,40.02]],"id":3805772}],"con":true,"img":true}]}
{"op":"mcm","clk":"5348133005","pt":1646214402733,"mc":[{"id":"1.195453760","marketDefinition":{"bspMarket":false,"turnInPlayEnabled":false,"persistenceEnabled":false,"marketBaseRate":7.0,"eventId":"31272494","eventTypeId":"4339","numberOfWinners":1,"bettingType":"ODDS","marketType":"QUINELLA","marketTime":"2022-03-02T12:04:00.000Z","suspendTime":"2022-03-02T12:04:00.000Z","bspReconciled":false,"complete":true,"inPlay":false,"crossMatching":false,"runnersVoidable":false,"numberOfActiveRunners":28,"betDelay":0,"status":"OPEN","runners":[{"status":"ACTIVE","sortPriority":1,"id":522741,"name":"1 - 2 / 2 - 1"},{"status":"ACTIVE","sortPriority":2,"id":522742,"name":"1 - 3 / 3 - 1"},{"status":"ACTIVE","sortPriority":3,"id":522743,"name":"1 - 4 / 4 - 1"},{"status":"ACTIVE","sortPriority":4,"id":7607472,"name":"1 - 5 / 5 - 1"},{"status":"ACTIVE","sortPriority":5,"id":522745,"name":"1 - 6 / 6 - 1"},{"status":"ACTIVE","sortPriority":6,"id":3805730,"name":"1 - 7 / 7 - 1"},{"status":"ACTIVE","sortPriority":7,"id":3805731,"name":"1 - 8 / 8 - 1"},{"status":"ACTIVE","sortPriority":8,"id":522746,"name":"2 - 3 / 3 - 2"},{"status":"ACTIVE","sortPriority":9,"id":522747,"name":"2 - 4 / 4 - 2"},{"status":"ACTIVE","sortPriority":10,"id":522748,"name":"2 - 5 / 5 - 2"},{"status":"ACTIVE","sortPriority":11,"id":522749,"name":"2 - 6 / 6 - 2"},{"status":"ACTIVE","sortPriority":12,"id":3805736,"name":"2 - 7 / 7 - 2"},{"status":"ACTIVE","sortPriority":13,"id":3805740,"name":"2 - 8 / 8 - 2"},{"status":"ACTIVE","sortPriority":14,"id":522750,"name":"3 - 4 / 4 - 3"},{"status":"ACTIVE","sortPriority":15,"id":522751,"name":"3 - 5 / 5 - 3"},{"status":"ACTIVE","sortPriority":16,"id":522752,"name":"3 - 6 / 6 - 3"},{"status":"ACTIVE","sortPriority":17,"id":3805746,"name":"3 - 7 / 7 - 3"},{"status":"ACTIVE","sortPriority":18,"id":3805747,"name":"3 - 8 / 8 - 3"},{"status":"ACTIVE","sortPriority":19,"id":522754,"name":"4 - 5 / 5 - 4"},{"status":"ACTIVE","sortPriority":20,"id":522753,"name":"4 - 6 / 6 - 4"},{"status":"ACTIVE","sortPriority":21,"id":3805755,"name":"4 - 7 / 7 - 4"},{"status":"ACTIVE","sortPriority":22,"id":3805762,"name":"4 - 8 / 8 - 4"},{"status":"ACTIVE","sortPriority":23,"id":522755,"name":"5 - 6 / 6 - 5"},{"status":"ACTIVE","sortPriority":24,"id":3805771,"name":"5 - 7 / 7 - 5"},{"status":"ACTIVE","sortPriority":25,"id":3805772,"name":"5 - 8 / 8 - 5"},{"status":"ACTIVE","sortPriority":26,"id":3805783,"name":"6 - 7 / 7 - 6"},{"status":"ACTIVE","sortPriority":27,"id":3805784,"name":"6 - 8 / 8 - 6"},{"status":"ACTIVE","sortPriority":28,"id":3805793,"name":"7 - 8 / 8 - 7"}],"regulators":["MR_INT"],"venue":"Traralgon","countryCode":"AU","discountAllowed":true,"timezone":"Australia/Sydney","openDate":"2022-03-02T08:31:00.000Z","version":4382480637,"name":"Quinella","eventName":"Traralgon (AUS) 2nd Mar"},"rc":[{"atb":[[16,13.31],[7.4,41.62],[9.4,23.78]],"id":3805783},{"atb":[[3.7,98.66],[4.4,58.76],[5.9,40.77]],"id":3805746},{"atb":[[70,2.89],[19.5,14.39],[29,7.13]],"id":522754},{"atb":[[4.5,57.08],[3,133.19],[3.5,79.91]],"id":3805793},{"atb":[[9.6,30.97],[23,9.07],[14,15.36]],"id":3805736},{"atb":[[80,2.52],[42,6.49],[210,0.95]],"id":522747},{"atb":[[16.5,17.18],[46,4.44],[23,9.07]],"id":522749},{"atb":[[6.4,49.33],[13.5,15.98],[8.4,26.99]],"id":522751},{"atb":[[17.5,12.1],[12.5,23.16],[30,6.88]],"id":3805730},{"atb":[[32,6.44],[80,2.52],[21,13.31]],"id":522753},{"atb":[[80,2.52],[42,6.49],[210,0.95]],"id":522741},{"atb":[[290,0.69],[190,1.41],[440,0.45]],"id":522743},{"atb":[[17,12.48],[9.8,22.7],[7.8,39.17]],"id":3805740},{"atb":[[6.8,45.93],[8.8,25.61],[14.5,14.8]],"id":3805771},{"atb":[[70,2.89],[19.5,14.39],[29,7.13]],"id":7607472},{"atb":[[32,6.44],[80,2.52],[21,13.31]],"id":522745},{"atb":[[6.8,34.44],[9.8,22.7],[5.4,60.54]],"id":3805784},{"atb":[[4,66.59],[2.9,140.2],[3.25,88.79]],"id":3805747},{"atb":[[17,12.48],[12,24.21],[29,7.13]],"id":522755},{"atb":[[17.5,12.1],[12.5,23.16],[30,6.88]],"id":3805755},{"atb":[[9.2,32.48],[21,9.98],[13,16.64]],"id":522746},{"atb":[[16,17.76],[44,4.64],[22,9.51]],"id":522748},{"atb":[[17,12.48],[12,24.21],[29,7.13]],"id":522750},{"atb":[[9.6,30.97],[23,9.07],[14,15.36]],"id":3805731},{"atb":[[9,24.97],[7,44.4],[15,14.27]],"id":522752},{"atb":[[9.6,30.97],[23,9.07],[14,15.36]],"id":3805762},{"atb":[[17,12.48],[12,24.21],[29,7.13]],"id":522742},{"atb":[[9,24.97],[5,66.59],[6,39.95]],"id":3805772}],"con":true,"img":true}]}
{"op":"mcm","clk":"5348206578","pt":1646215440392,"mc":[{"id":"1.195453760","rc":[{"atb":[[16,13.31],[16.5,2.72],[7.4,41.62],[14,3.26],[9.4,23.78]],"id":3805783},{"atb":[[3.7,98.66],[4.4,58.76],[5.9,40.77]],"id":3805746},{"atb":[[70,2.89],[19.5,14.39],[29,7.13]],"id":522754},{"atb":[[5.6,2.72],[4.5,57.08],[5.1,3.26],[3,133.19],[3.5,79.91]],"id":3805793},{"atb":[[9.6,30.97],[23,9.07],[14,15.36]],"id":3805736},{"atb":[[70,2.72],[80,2.52],[42,6.49],[48,3.26],[210,0.95]],"id":522747},{"atb":[[16.5,17.18],[40,2.72],[46,4.44],[23,9.07],[30,3.26]],"id":522749},{"atb":[[6.4,49.33],[12,3.26],[13.5,15.98],[8.4,26.99],[14.5,2.72]],"id":522751},{"atb":[[17.5,12.1],[12.5,23.16],[30,6.88]],"id":3805730},{"atb":[[32,6.44],[80,2.52],[21,13.31]],"id":522753},{"atb":[[80,2.52],[42,6.49],[210,0.95]],"id":522741},{"atb":[[290,0.69],[190,1.41],[440,0.45]],"id":522743},{"atb":[[17,12.48],[9.8,22.7],[7.8,39.17]],"id":3805740},{"atb":[[9.6,3.26],[11.5,2.72],[6.8,45.93],[8.8,25.61],[14.5,14.8]],"id":3805771},{"atb":[[70,2.89],[19.5,14.39],[29,7.13]],"id":7607472},{"atb":[[32,6.44],[38,3.26],[80,2.52],[21,13.31],[48,2.72]],"id":522745},{"atb":[[9.6,3.26],[11.5,2.72],[6.8,34.44],[9.8,22.7],[5.4,60.54]],"id":3805784},{"atb":[[4,66.59],[4.8,3.26],[2.9,140.2],[5.3,2.72],[3.25,88.79]],"id":3805747},{"atb":[[17,12.48],[12,24.21],[29,7.13]],"id":522755},{"atb":[[17.5,12.1],[22,3.26],[12.5,23.16],[27,2.72],[30,6.88]],"id":3805755},{"atb":[[18,3.26],[9.2,32.48],[21,12.71],[13,16.64]],"id":522746},{"atb":[[16,17.76],[44,4.64],[22,9.51]],"id":522748},{"atb":[[17,12.48],[12,24.21],[29,7.13]],"id":522750},{"atb":[[9.6,30.97],[17.5,3.26],[20,2.72],[23,9.07],[14,15.36]],"id":3805731},{"atb":[[16,2.72],[9,24.97],[13.5,3.26],[7,44.4],[15,14.27]],"id":522752},{"atb":[[9.6,30.97],[23,9.07],[14,15.36]],"id":3805762},{"atb":[[17,12.48],[12,24.21],[29,7.13]],"id":522742},{"atb":[[9,24.97],[5,66.59],[6,39.95]],"id":3805772}],"con":true,"img":false}]}
{"op":"mcm","clk":"5348206585","pt":1646215440497,"mc":[{"id":"1.195453760","rc":[{"atb":[[7.6,2.72],[6.6,3.26]],"id":3805746},{"atb":[[36,3.26],[46,2.72]],"id":522754},{"atb":[[18.5,3.26],[22,2.72]],"id":3805736},{"atb":[[22,3.26],[27,2.72]],"id":3805730},{"atb":[[38,3.26],[48,2.72]],"id":522753},{"atb":[[65,2.72],[46,3.26]],"id":522741},{"atb":[[85,2.72],[60,3.26]],"id":522743},{"atb":[[17,15.21],[14.5,3.26]],"id":3805740},{"atb":[[36,3.26],[46,2.72]],"id":7607472},{"atb":[[22,3.26],[27,2.72]],"id":522755},{"atb":[[38,2.72],[29,3.26]],"id":522748},{"atb":[[21,3.26],[26,2.72]],"id":522750},{"atb":[[18,3.26],[21,2.72]],"id":3805762},{"atb":[[20,3.26],[25,2.72]],"id":522742},{"atb":[[9.2,3.26],[10.5,2.72]],"id":3805772}],"con":true,"img":false}]}
{"op":"mcm","clk":"5348219627","pt":1646215593384,"mc":[{"id":"1.195453760","rc":[{"atb":[[12,0],[14.5,0]],"id":522751},{"atb":[[22,0],[27,0]],"id":522755}],"con":true,"img":false}]}
{"op":"mcm","clk":"5348219690","pt":1646215594105,"mc":[{"id":"1.195453760","rc":[{"atb":[[11.5,3.26],[14,2.72]],"id":522751},{"atb":[[19.5,3.26],[24,2.72]],"id":522755}],"con":true,"img":false}]}
{"op":"mcm","clk":"5348284473","pt":1646216166034,"mc":[{"id":"1.195453760","rc":[{"atb":[[5.6,0]],"id":3805793},{"atb":[[5.3,0]],"id":3805747},{"atb":[[21,9.98]],"id":522746}],"con":true,"img":false}]}
{"op":"mcm","clk":"5348284486","pt":1646216166138,"mc":[{"id":"1.195453760","rc":[{"atb":[[36,0],[46,0]],"id":522754},{"atb":[[5.1,0]],"id":3805793},{"atb":[[38,0],[48,0]],"id":522753},{"atb":[[65,0],[46,0]],"id":522741},{"atb":[[9.6,0],[11.5,0]],"id":3805784},{"atb":[[4.8,0]],"id":3805747},{"atb":[[18,0]],"id":522746}],"con":true,"img":false}]}
{"op":"mcm","clk":"5348284498","pt":1646216166248,"mc":[{"id":"1.195453760","rc":[{"atb":[[18.5,0],[22,0]],"id":3805736},{"atb":[[20,0],[25,0]],"id":522742}],"con":true,"img":false}]}
{"op":"mcm","clk":"5348284573","pt":1646216166772,"mc":[{"id":"1.195453760","rc":[{"atb":[[5.7,2.72]],"id":3805793},{"atb":[[5.4,2.72]],"id":3805747},{"atb":[[22,2.72]],"id":522746}],"con":true,"img":false}]}
{"op":"mcm","clk":"5348284583","pt":1646216166830,"mc":[{"id":"1.195453760","rc":[{"atb":[[38,3.26],[48,2.72]],"id":522754},{"atb":[[5.2,3.26]],"id":3805793},{"atb":[[40,3.26]],"id":522753},{"atb":[[70,2.72],[48,3.26]],"id":522741},{"atb":[[12,2.72],[9.8,25.97]],"id":3805784},{"atb":[[4.9,3.26]],"id":3805747}],"con":true,"img":false}]}
{"op":"mcm","clk":"5348284594","pt":1646216166932,"mc":[{"id":"1.195453760","rc":[{"atb":[[19,3.26],[23,11.8]],"id":3805736},{"atb":[[50,2.72]],"id":522753},{"atb":[[18.5,3.26]],"id":522746},{"atb":[[21,3.26]],"id":522742}],"con":true,"img":false}]}
{"op":"mcm","clk":"5348284606","pt":1646216167037,"mc":[{"id":"1.195453760","rc":[{"atb":[[26,2.72]],"id":522742}],"con":true,"img":false}]}
{"op":"mcm","clk":"5348395031","pt":1646217242769,"mc":[{"id":"1.195453760","rc":[{"atb":[[11.5,0],[14,0]],"id":522751},{"atb":[[19.5,0],[24,0]],"id":522755}],"con":true,"img":false}]}
{"op":"mcm","clk":"5348395115","pt":1646217243454,"mc":[{"id":"1.195453760","rc":[{"atb":[[11.5,3.26],[14,2.72]],"id":522751},{"atb":[[19.5,3.26],[24,2.72]],"id":522755}],"con":true,"img":false}]}
{"op":"mcm","clk":"5348524671","pt":1646218455079,"mc":[{"id":"1.195453760","rc":[{"atb":[[11.5,0],[14,0]],"id":522751},{"atb":[[19.5,0],[24,0]],"id":522755}],"con":true,"img":false}]}
{"op":"mcm","clk":"5348524739","pt":1646218455752,"mc":[{"id":"1.195453760","rc":[{"atb":[[12,3.26],[14.5,2.72]],"id":522751},{"atb":[[22,3.26],[27,2.72]],"id":522755}],"con":true,"img":false}]}
{"op":"mcm","clk":"5348526532","pt":1646218473482,"mc":[{"id":"1.195453760","rc":[{"atb":[[12,0],[14.5,0]],"id":522751},{"atb":[[22,0],[27,0]],"id":522755}],"con":true,"img":false}]}
{"op":"mcm","clk":"5348526620","pt":1646218474212,"mc":[{"id":"1.195453760","rc":[{"atb":[[11.5,3.26],[14,2.72]],"id":522751}],"con":true,"img":false}]}
{"op":"mcm","clk":"5348526632","pt":1646218474267,"mc":[{"id":"1.195453760","rc":[{"atb":[[19.5,3.26],[24,2.72]],"id":522755}],"con":true,"img":false}]}
{"op":"mcm","clk":"5348581913","pt":1646219052625,"mc":[{"id":"1.195453760","rc":[{"atb":[[16.5,2.72],[16,13.32],[7.4,41.62],[3.8,26.64],[14,3.27],[9.4,23.78]],"id":3805783},{"atl":[[470,2]],"id":3805783},{"atb":[[3.7,98.67],[7.6,2.72],[4.4,58.76],[6.6,3.27],[3.3,43.48],[5.9,40.77]],"id":3805746},{"atl":[[430,2]],"id":3805746},{"atb":[[70,2.89],[38,3.27],[19.5,19.8],[48,2.72],[29,7.13]],"id":522754},{"atl":[[1000,2]],"id":522754},{"atb":[[4.5,57.08],[2.9,52.63],[3,133.2],[5.2,3.27],[5.7,2.72],[3.5,79.92]],"id":3805793},{"atl":[[230,2]],"id":3805793},{"atb":[[9.6,30.97],[7.2,16.13],[19,3.27],[23,11.8],[14,15.36]],"id":3805736},{"atl":[[650,2]],"id":3805736},{"atb":[[70,2.72],[80,2.52],[42,6.49],[48,3.27],[28,3.7]],"id":522747},{"atb":[[16.5,17.18],[40,2.72],[46,4.44],[23,9.08],[13,8.33],[30,3.27]],"id":522749},{"atl":[[980,2]],"id":522749},{"atb":[[3.6,31.96],[6.4,49.33],[11.5,3.27],[13.5,15.98],[14,2.72],[8.4,27]],"id":522751},{"atl":[[420,2]],"id":522751},{"atb":[[17.5,12.11],[22,3.27],[6.8,13.78],[12.5,23.16],[27,2.72],[30,6.88]],"id":3805730},{"atl":[[620,2]],"id":3805730},{"atb":[[32,6.44],[80,2.52],[40,3.27],[21,13.32],[50,2.72],[26,4]],"id":522753},{"atb":[[70,2.72],[80,2.52],[42,6.49],[48,3.27],[26,4]],"id":522741},{"atb":[[85,2.72],[28,2.82],[60,3.27]],"id":522743},{"atb":[[17,15.21],[6.8,17.24],[9.8,22.7],[7.8,39.17],[14.5,3.27]],"id":3805740},{"atl":[[620,2]],"id":3805740},{"atb":[[9.6,3.27],[11.5,2.72],[3.35,29.6],[6.8,45.93],[8.8,25.61],[14.5,14.8]],"id":3805771},{"atl":[[360,2]],"id":3805771},{"atb":[[70,2.89],[36,3.27],[19.5,14.39],[46,2.72],[7.6,6.54],[29,7.13]],"id":7607472},{"atl":[[730,2]],"id":7607472},{"atb":[[32,6.44],[38,3.27],[80,2.52],[21,13.32],[48,2.72],[7.6,6.54]],"id":522745},{"atl":[[940,2]],"id":522745},{"atb":[[12,2.72],[6.8,34.45],[9.8,25.97],[3.75,36.36],[5.4,60.54]],"id":3805784},{"atl":[[450,2]],"id":3805784},{"atb":[[4,66.6],[2.9,140.21],[3.4,41.67],[4.9,3.27],[3.25,88.79],[5.4,2.72]],"id":3805747},{"atl":[[310,2]],"id":3805747},{"atb":[[17,12.48],[19.5,3.27],[24,2.72],[12,24.22],[4.4,14.26],[29,7.13]],"id":522755},{"atl":[[520,2]],"id":522755},{"atb":[[17.5,12.11],[22,3.27],[12.5,31.86],[27,2.72],[30,6.88]],"id":3805755},{"atl":[[980,2]],"id":3805755},{"atb":[[18.5,3.27],[9.2,32.48],[21,9.99],[22,2.72],[7.4,15.62],[13,16.65]],"id":522746},{"atl":[[680,2]],"id":522746},{"atb":[[16,17.76],[7.2,9.3],[38,2.72],[44,4.64],[22,9.51],[29,3.27]],"id":522748},{"atl":[[780,2]],"id":522748},{"atb":[[16,6.67],[17,12.48],[21,3.27],[12,24.22],[26,2.72],[29,7.13]],"id":522750},{"atl":[[1000,2]],"id":522750},{"atb":[[9.6,30.97],[17.5,3.27],[20,2.72],[23,9.08],[14,15.36],[6.6,17.86]],"id":3805731},{"atl":[[590,2]],"id":3805731},{"atb":[[16,2.72],[9,24.97],[4.3,28.54],[13.5,3.27],[7,44.4],[15,14.27]],"id":522752},{"atl":[[520,2]],"id":522752},{"atb":[[9.6,30.97],[18,3.27],[21,2.72],[10.5,10.53],[23,9.08],[14,15.36]],"id":3805762},{"atl":[[920,2]],"id":3805762},{"atb":[[17,12.48],[7.2,14.26],[21,3.27],[12,24.22],[26,2.72],[29,7.13]],"id":522742},{"atl":[[660,2]],"id":522742},{"atb":[[9,24.97],[9.2,3.27],[5,66.6],[10.5,2.72],[6,39.96],[3.25,44.44]],"id":3805772},{"atl":[[340,2]],"id":3805772}],"con":true,"img":false}]}
{"op":"mcm","clk":"5348587443","pt":1646219101982,"mc":[{"id":"1.195453760","rc":[{"atb":[[17.5,0],[20,0]],"id":3805731}],"con":true,"img":false}]}
{"op":"mcm","clk":"5348587552","pt":1646219102825,"mc":[{"id":"1.195453760","rc":[{"atb":[[18,3.27],[21,2.72]],"id":3805731}],"con":true,"img":false}]}
{"op":"mcm","clk":"5348653806","pt":1646219654959,"mc":[{"id":"1.195453760","rc":[{"atb":[[4.1,26.64],[3.8,0]],"id":3805783},{"atl":[[460,2],[470,0]],"id":3805783},{"atl":[[170,2],[230,0]],"id":3805793},{"atl":[[650,0],[640,2]],"id":3805736},{"atb":[[18,5.88],[13,0]],"id":522749},{"atb":[[3.6,0],[3.85,31.98]],"id":522751},{"atl":[[590,2],[620,0]],"id":3805730},{"atl":[[620,0],[610,2]],"id":3805740},{"atl":[[940,0],[930,2]],"id":522745},{"atb":[[4,33.33],[3.75,0]],"id":3805784},{"atl":[[280,2],[310,0]],"id":3805747},{"atb":[[5.6,14.26],[4.4,0]],"id":522755},{"atl":[[910,2],[980,0]],"id":3805755},{"atb":[[7.4,0],[8.4,13.51]],"id":522746},{"atb":[[7.2,0],[8.6,9.3]],"id":522748},{"atl":[[990,2],[1000,0]],"id":522750},{"atl":[[560,2],[590,0]],"id":3805731},{"atb":[[4.3,0],[4.9,25.64]],"id":522752},{"atl":[[860,2],[920,0]],"id":3805762},{"atl":[[660,0],[640,2]],"id":522742},{"atl":[[320,2],[340,0]],"id":3805772}],"con":true,"img":false}]}
{"op":"mcm","clk":"5348653837","pt":1646219655266,"mc":[{"id":"1.195453760","rc":[{"atb":[[11.5,0],[14,0]],"id":522751}],"con":true,"img":false}]}
{"op":"mcm","clk":"5348653854","pt":1646219655373,"mc":[{"id":"1.195453760","rc":[{"atb":[[19.5,0],[24,0]],"id":522755}],"con":true,"img":false}]}
{"op":"mcm","clk":"5348653915","pt":1646219655949,"mc":[{"id":"1.195453760","rc":[{"atb":[[12,3.27],[14.5,2.72]],"id":522751}],"con":true,"img":false}]}
{"op":"mcm","clk":"5348653934","pt":1646219656155,"mc":[{"id":"1.195453760","rc":[{"atb":[[22,3.27],[27,2.72]],"id":522755}],"con":true,"img":false}]}
{"op":"mcm","clk":"5348655801","pt":1646219673202,"mc":[{"id":"1.195453760","rc":[{"atb":[[2.9,0],[3.05,48.78]],"id":3805793},{"atb":[[18,0],[14,7.69]],"id":522749},{"atl":[[930,2],[980,0]],"id":522749},{"atl":[[410,2],[420,0]],"id":522751},{"atl":[[590,0],[600,2]],"id":3805730},{"atl":[[1000,2]],"id":522741},{"atl":[[700,2],[730,0]],"id":7607472},{"atl":[[440,2],[450,0]],"id":3805784},{"atb":[[5.6,0],[4.8,19.62]],"id":522755},{"atl":[[520,0],[510,2]],"id":522755},{"atl":[[910,0],[930,2]],"id":3805755},{"atl":[[660,2],[680,0]],"id":522746},{"atl":[[750,2],[780,0]],"id":522748},{"atl":[[560,0],[570,2]],"id":3805731},{"atl":[[510,2]],"id":522752}],"con":true,"img":false}]}
{"op":"mcm","clk":"5348655818","pt":1646219673296,"mc":[{"id":"1.195453760","rc":[{"atl":[[520,0]],"id":522752}],"con":true,"img":false}]}
{"op":"mcm","clk":"5348655839","pt":1646219673468,"mc":[{"id":"1.195453760","rc":[{"atb":[[12,0],[14.5,0]],"id":522751},{"atb":[[22,0],[27,0]],"id":522755}],"con":true,"img":false}]}
{"op":"mcm","clk":"5348655926","pt":1646219674295,"mc":[{"id":"1.195453760","rc":[{"atb":[[11.5,3.27],[14,2.72]],"id":522751},{"atb":[[19.5,3.27],[24,2.72]],"id":522755}],"con":true,"img":false}]}
{"op":"mcm","clk":"5348657211","pt":1646219686038,"mc":[{"id":"1.195453760","rc":[{"atl":[[630,2],[640,0]],"id":3805736},{"atl":[[600,2],[610,0]],"id":3805740},{"atl":[[900,2],[930,0]],"id":522745},{"atl":[[990,0],[980,2]],"id":522750}],"con":true,"img":false}]}
{"op":"mcm","clk":"5348669583","pt":1646219793204,"mc":[{"id":"1.195453760","rc":[{"atb":[[2.9,52.63],[3.05,0]],"id":3805793},{"atl":[[1000,0]],"id":522741},{"atb":[[7.2,13.95],[8.6,0]],"id":522748},{"atb":[[4.3,30.3],[4.9,0]],"id":522752}],"con":true,"img":false}]}
{"op":"mcm","clk":"5348738124","pt":1646220266705,"mc":[{"id":"1.195453760","rc":[{"atb":[[28,0],[14.5,4.14]],"id":522743}],"con":true,"img":false}]}
{"op":"mcm","clk":"5348805253","pt":1646220843229,"mc":[{"id":"1.195453760","rc":[{"atl":[[350,2],[430,0]],"id":3805746},{"atb":[[2.9,0],[3.05,48.78]],"id":3805793},{"atb":[[9.8,6.54]],"id":522745}],"con":true,"img":false}]}
{"op":"mcm","clk":"5348805266","pt":1646220843336,"mc":[{"id":"1.195453760","rc":[{"atb":[[7.6,0]],"id":522745}],"con":true,"img":false}]}
{"op":"mcm","clk":"5348842451","pt":1646221154925,"mc":[{"id":"1.195453760","rc":[{"atl":[[350,0],[340,2]],"id":3805746},{"atl":[[150,2],[170,0]],"id":3805793},{"atb":[[18,5.88],[14,0]],"id":522749},{"atl":[[600,0],[590,2]],"id":3805730},{"atb":[[8.6,6.54],[7.6,0]],"id":7607472},{"atb":[[4.8,0],[5.6,19.62]],"id":522755},{"atl":[[910,2],[930,0]],"id":3805755},{"atb":[[7.2,0],[8.6,13.16]],"id":522748},{"atl":[[570,0],[560,2]],"id":3805731},{"atb":[[4.3,0],[5.3,23.26]],"id":522752}],"con":true,"img":false}]}
{"op":"mcm","clk":"5348842481","pt":1646221155239,"mc":[{"id":"1.195453760","rc":[{"atb":[[11.5,0],[14,0]],"id":522751},{"atb":[[19.5,0],[24,0]],"id":522755}],"con":true,"img":false}]}
{"op":"mcm","clk":"5348842564","pt":1646221155919,"mc":[{"id":"1.195453760","rc":[{"atb":[[12,3.27],[14.5,2.72]],"id":522751},{"atb":[[22,3.27],[27,2.72]],"id":522755}],"con":true,"img":false}]}
{"op":"mcm","clk":"5348844392","pt":1646221173124,"mc":[{"id":"1.195453760","rc":[{"atb":[[18,0],[14,7.69]],"id":522749},{"atl":[[1000,2]],"id":522741},{"atb":[[5.6,0],[4.8,19.62]],"id":522755},{"atl":[[490,2],[510,0]],"id":522752}],"con":true,"img":false}]}
{"op":"mcm","clk":"5348844426","pt":1646221173428,"mc":[{"id":"1.195453760","rc":[{"atb":[[12,0],[14.5,0]],"id":522751},{"atb":[[22,0],[27,0]],"id":522755}],"con":true,"img":false}]}
{"op":"mcm","clk":"5348844489","pt":1646221174111,"mc":[{"id":"1.195453760","rc":[{"atb":[[11.5,3.27],[14,2.72]],"id":522751},{"atb":[[19.5,3.27],[24,2.72]],"id":522755}],"con":true,"img":false}]}
{"op":"mcm","clk":"5348856755","pt":1646221292383,"mc":[{"id":"1.195453760","rc":[{"atb":[[7.6,0],[6.6,0]],"id":3805746},{"atb":[[38,0],[48,0]],"id":522754},{"atb":[[5.2,0],[5.7,0]],"id":3805793},{"atb":[[70,0],[48,0]],"id":522747},{"atb":[[40,0],[50,0]],"id":522753},{"atb":[[85,0],[60,0]],"id":522743},{"atb":[[36,0],[46,0]],"id":7607472},{"atb":[[4.9,0],[5.4,0]],"id":3805747},{"atb":[[22,0],[27,0]],"id":3805755},{"atb":[[21,0],[26,0]],"id":522750},{"atb":[[18,0],[21,0]],"id":3805762}],"con":true,"img":false}]}
{"op":"mcm","clk":"5348856778","pt":1646221292586,"mc":[{"id":"1.195453760","rc":[{"atb":[[3.6,38.46],[3.4,0]],"id":3805747}],"con":true,"img":false}]}
{"op":"mcm","clk":"5348856852","pt":1646221293069,"mc":[{"id":"1.195453760","rc":[{"atb":[[6.8,3.27],[7.8,2.72]],"id":3805746},{"atb":[[42,3.27],[55,2.72]],"id":522754},{"atb":[[5.6,2.72],[5.1,3.27]],"id":3805793},{"atb":[[75,2.72],[50,3.27]],"id":522747},{"atb":[[42,3.27],[55,2.72]],"id":522753},{"atl":[[1000,0]],"id":522741},{"atb":[[70,3.27],[95,2.72]],"id":522743},{"atb":[[38,3.27],[48,2.72]],"id":7607472},{"atb":[[5,3.27],[5.5,2.72]],"id":3805747},{"atb":[[25,3.27],[30,9.61]],"id":3805755},{"atb":[[7.2,14.17],[8.6,0]],"id":522748},{"atb":[[25,3.27],[30,2.72]],"id":522750},{"atb":[[4.6,27.78],[5.3,0]],"id":522752},{"atb":[[19,3.27],[23,11.8]],"id":3805762}],"con":true,"img":false}]}
{"op":"mcm","clk":"5348871822","pt":1646221444577,"mc":[{"id":"1.195453760","rc":[{"atb":[[19.5,4.14],[14.5,0]],"id":522743},{"atb":[[3.6,0],[3.2,45.45]],"id":3805747}],"con":true,"img":false}]}
{"op":"mcm","clk":"5348872849","pt":1646221455937,"mc":[{"id":"1.195453760","rc":[{"atb":[[38,0],[48,0]],"id":7607472}],"con":true,"img":false}]}
{"op":"mcm","clk":"5348872927","pt":1646221456768,"mc":[{"id":"1.195453760","rc":[{"atb":[[36,3.27],[46,2.72]],"id":7607472}],"con":true,"img":false}]}
{"op":"mcm","clk":"5348875290","pt":1646221482687,"mc":[{"id":"1.195453760","rc":[{"atb":[[6.8,0],[7.8,0]],"id":3805746},{"atb":[[5.6,0],[5.1,0]],"id":3805793},{"atb":[[25,0],[30,6.88]],"id":3805755}],"con":true,"img":false}]}
{"op":"mcm","clk":"5348875346","pt":1646221483368,"mc":[{"id":"1.195453760","rc":[{"atb":[[5.8,2.72],[5.3,3.27]],"id":3805793},{"atb":[[32,2.72],[26,3.27]],"id":3805755}],"con":true,"img":false}]}
{"op":"mcm","clk":"5348875355","pt":1646221483472,"mc":[{"id":"1.195453760","rc":[{"atb":[[8,2.72],[7,3.27]],"id":3805746}],"con":true,"img":false}]}
{"op":"mcm","clk":"5348877472","pt":1646221504894,"mc":[{"id":"1.195453760","rc":[{"atb":[[5.8,0],[5.3,0]],"id":3805793},{"atb":[[5,0],[5.5,0]],"id":3805747}],"con":true,"img":false}]}
{"op":"mcm","clk":"5348877562","pt":1646221505736,"mc":[{"id":"1.195453760","rc":[{"atb":[[5.2,3.27],[5.7,2.72]],"id":3805793},{"atb":[[4.9,3.27],[5.4,2.72]],"id":3805747}],"con":true,"img":false}]}
{"op":"mcm","clk":"5348886892","pt":1646221601057,"mc":[{"id":"1.195453760","rc":[{"atb":[[5.2,0],[5.7,0]],"id":3805793},{"atb":[[4.9,0],[5.4,0]],"id":3805747}],"con":true,"img":false}]}
{"op":"mcm","clk":"5348886956","pt":1646221601763,"mc":[{"id":"1.195453760","rc":[{"atb":[[5.2,2.72],[4.7,3.27]],"id":3805747}],"con":true,"img":false}]}
{"op":"mcm","clk":"5348886968","pt":1646221601831,"mc":[{"id":"1.195453760","rc":[{"atb":[[5,3.27],[5.5,2.72]],"id":3805793}],"con":true,"img":false}]}
{"op":"mcm","clk":"5348906211","pt":1646221801540,"mc":[{"id":"1.195453760","rc":[{"atb":[[16,0],[7.4,0],[9.4,0]],"id":3805783},{"atb":[[3.7,0],[4.4,0],[5.9,0]],"id":3805746},{"atb":[[70,0],[19.5,5.41],[29,0]],"id":522754},{"atb":[[4.5,0],[3,0],[3.5,0]],"id":3805793},{"atb":[[9.6,0],[23,2.72],[14,0]],"id":3805736},{"atb":[[80,0],[42,0],[210,0]],"id":522747},{"atb":[[16.5,0],[46,0],[23,0]],"id":522749},{"atb":[[6.4,0],[13.5,0],[8.4,0]],"id":522751},{"atb":[[17.5,0],[12.5,0],[30,0]],"id":3805730},{"atb":[[32,0],[80,0],[21,0]],"id":522753},{"atb":[[80,0],[42,0],[210,0]],"id":522741},{"atb":[[290,0],[190,0],[440,0]],"id":522743},{"atb":[[17,2.72],[9.8,0],[7.8,0]],"id":3805740},{"atb":[[6.8,0],[8.8,0],[14.5,0]],"id":3805771},{"atb":[[70,0],[19.5,0],[29,0]],"id":7607472},{"atb":[[32,0],[80,0],[21,0]],"id":522745},{"atb":[[6.8,0],[9.8,3.27],[5.4,0]],"id":3805784},{"atb":[[4,0],[2.9,0],[3.25,0]],"id":3805747},{"atb":[[17,0],[12,0],[29,0]],"id":522755},{"atb":[[17.5,0],[12.5,8.7],[30,0]],"id":3805755},{"atb":[[9.2,0],[21,0],[13,0]],"id":522746},{"atb":[[16,0],[44,0],[22,0]],"id":522748},{"atb":[[17,0],[12,0],[29,0]],"id":522750},{"atb":[[9.6,0],[23,0],[14,0]],"id":3805731},{"atb":[[9,0],[7,0],[15,0]],"id":522752},{"atb":[[9.6,0],[23,2.72],[14,0]],"id":3805762},{"atb":[[17,0],[12,0],[29,0]],"id":522742},{"atb":[[9,0],[5,0],[6,0]],"id":3805772}],"con":true,"img":false}]}
{"op":"mcm","clk":"5348906264","pt":1646221802166,"mc":[{"id":"1.195453760","rc":[{"atb":[[6.8,6.54]],"id":522746}],"con":true,"img":false}]}
{"op":"mcm","clk":"5348906274","pt":1646221802285,"mc":[{"id":"1.195453760","rc":[{"atb":[[8.4,0]],"id":522746}],"con":true,"img":false}]}
{"op":"mcm","clk":"5348906554","pt":1646221805607,"mc":[{"id":"1.195453760","rc":[{"atb":[[5.7,56.68],[9.4,15.86],[4.7,72]],"id":3805783},{"atb":[[3.2,121.09],[2.88,141.7],[4.4,39.17]],"id":3805746},{"atb":[[9.8,30.27],[29,4.75],[14.5,19.73]],"id":522754},{"atb":[[2.8,148],[2.6,166.5],[3.5,53.28]],"id":3805793},{"atb":[[5.8,55.49],[7.6,40.36],[14,10.24]],"id":3805736},{"atb":[[18,15.66],[80,1.68],[26,10.65]],"id":522747},{"atb":[[8.6,35.05],[23,6.05],[11.5,25.37]],"id":522749},{"atb":[[5.2,63.42],[8.4,18],[4.2,83.25]],"id":522751},{"atb":[[17.5,8.07],[9,33.3],[7,44.4]],"id":3805730},{"atb":[[32,4.29],[10.5,28.04],[15.5,18.37]],"id":522753},{"atb":[[18,15.66],[80,1.68],[26,14.65]],"id":522741},{"atb":[[290,0.46],[95,5.55],[48,5.66]],"id":522743},{"atb":[[9.8,15.13],[4.9,68.3],[5.9,54.37]],"id":3805740},{"atb":[[8.8,17.07],[4.4,78.35],[5.4,60.54]],"id":3805771},{"atb":[[9.8,30.27],[29,4.75],[14.5,19.73]],"id":7607472},{"atb":[[32,4.29],[10.5,28.04],[15.5,18.37]],"id":522745},{"atb":[[3.7,98.67],[6.8,22.96],[4.4,78.35]],"id":3805784},{"atb":[[2.5,177.6],[3.25,59.19],[2.7,156.7]],"id":3805747},{"atb":[[17,8.32],[6.8,45.93],[8.8,34.15]],"id":522755},{"atb":[[17.5,8.07],[9,33.3],[7,44.4]],"id":3805755},{"atb":[[5.6,57.91],[7.2,42.96],[13,11.1]],"id":522746},{"atb":[[22,6.34],[11,26.64],[8.4,35.99]],"id":522748},{"atb":[[17,8.32],[6.8,45.93],[8.8,34.15]],"id":522750},{"atb":[[5.8,55.49],[7.6,40.36],[14,10.24]],"id":3805731},{"atb":[[9,16.65],[4.5,76.11],[5.5,59.19]],"id":522752},{"atb":[[5.8,55.49],[7.6,40.36],[14,10.24]],"id":3805762},{"atb":[[17,8.32],[6.8,45.93],[8.8,34.15]],"id":522742},{"atb":[[4,88.79],[6,26.64],[3.5,106.56]],"id":3805772}],"con":true,"img":false}]}
{"op":"mcm","clk":"5348906651","pt":1646221806804,"mc":[{"id":"1.195453760","rc":[{"atl":[[340,0]],"id":3805746},{"atb":[[3.65,34.16]],"id":3805771},{"atb":[[3.25,0],[3.5,146.56]],"id":3805772}],"con":true,"img":false}]}
{"op":"mcm","clk":"5348906664","pt":1646221806923,"mc":[{"id":"1.195453760","rc":[{"atb":[[5,25],[4.1,0]],"id":3805783},{"atb":[[3.85,35.09],[3.3,0]],"id":3805746},{"atl":[[310,2]],"id":3805746},{"atb":[[19.5,0],[28,3.7]],"id":522754},{"atl":[[1000,0]],"id":522754},{"atb":[[3.55,39.22],[3.05,0]],"id":3805793},{"atl":[[130,2],[150,0]],"id":3805793},{"atb":[[7.2,0],[8.8,12.82]],"id":3805736},{"atb":[[36,2.86],[28,0]],"id":522747},{"atb":[[18.5,5.71],[14,0]],"id":522749},{"atl":[[860,2],[930,0]],"id":522749},{"atb":[[4.3,30.3],[3.85,0]],"id":522751},{"atl":[[370,2],[410,0]],"id":522751},{"atb":[[6.8,0],[8.4,13.51]],"id":3805730},{"atl":[[560,2],[590,0]],"id":3805730},{"atb":[[34,3.03],[26,10.65]],"id":522741},{"atl":[[1000,2]],"id":522741},{"atb":[[9.2,12.2],[6.8,0]],"id":3805740},{"atl":[[570,2],[600,0]],"id":3805740},{"atb":[[3.35,0]],"id":3805771},{"atb":[[8.6,0],[10,11.11]],"id":7607472},{"atl":[[700,0],[680,2]],"id":7607472},{"atl":[[840,2],[900,0]],"id":522745},{"atb":[[4,0],[4.8,26.32]],"id":3805784},{"atl":[[280,0],[250,2]],"id":3805747},{"atb":[[4.8,0],[5.4,19.62]],"id":522755},{"atb":[[9,12.5],[6.8,0]],"id":522746},{"atl":[[660,0],[640,2]],"id":522746},{"atb":[[7.2,0]],"id":522748},{"atl":[[750,0],[740,2]],"id":522748},{"atl":[[940,2],[980,0]],"id":522750},{"atl":[[530,2],[560,0]],"id":3805731},{"atb":[[4.6,0],[5.5,81.41]],"id":522752},{"atl":[[490,0],[480,2]],"id":522752},{"atb":[[10.5,0],[14.5,7.41]],"id":3805762},{"atl":[[590,2],[640,0]],"id":522742}],"con":true,"img":false}]}
{"op":"mcm","clk":"5348906673","pt":1646221807019,"mc":[{"id":"1.195453760","rc":[{"atb":[[4.2,31.25],[3.65,0]],"id":3805771},{"atb":[[9,12.5]],"id":522748},{"atb":[[4,122.12],[3.5,106.56]],"id":3805772}],"con":true,"img":false}]}
{"op":"mcm","clk":"5348906683","pt":1646221807123,"mc":[{"id":"1.195453760","rc":[{"atl":[[1000,2]],"id":522754},{"atb":[[9.6,0],[11.5,0]],"id":3805771}],"con":true,"img":false}]}
{"op":"mcm","clk":"5348906707","pt":1646221807386,"mc":[{"id":"1.195453760","rc":[{"atb":[[19.5,0],[24,0]],"id":522755},{"atb":[[9.2,0],[10.5,0]],"id":3805772}],"con":true,"img":false}]}
{"op":"mcm","clk":"5348906743","pt":1646221807801,"mc":[{"id":"1.195453760","rc":[{"atb":[[10,3.27],[12.5,2.72]],"id":3805771}],"con":true,"img":false}]}
{"op":"mcm","clk":"5348906787","pt":1646221808322,"mc":[{"id":"1.195453760","rc":[{"atb":[[22,3.27],[27,2.72]],"id":522755},{"atb":[[11,2.72],[9.4,3.27]],"id":3805772}],"con":true,"img":false}]}
{"op":"mcm","clk":"5348907125","pt":1646221812383,"mc":[{"id":"1.195453760","rc":[{"atl":[[630,0],[620,2]],"id":3805736},{"atl":[[860,0],[870,2]],"id":522749},{"atl":[[860,0],[850,2]],"id":3805762}],"con":true,"img":false}]}
{"op":"mcm","clk":"5348907491","pt":1646221816404,"mc":[{"id":"1.195453760","rc":[{"atl":[[620,2],[680,0]],"id":7607472},{"atl":[[220,2],[250,0]],"id":3805747},{"atl":[[530,0]],"id":3805731},{"atl":[[460,2]],"id":522752},{"atl":[[560,2],[590,0]],"id":522742}],"con":true,"img":false}]}
{"op":"mcm","clk":"5348907500","pt":1646221816509,"mc":[{"id":"1.195453760","rc":[{"atl":[[530,2],[560,0]],"id":3805730},{"atl":[[770,2],[840,0]],"id":522745},{"atb":[[6.4,18.52],[5.4,0]],"id":522755},{"atb":[[9,0],[11,36.64]],"id":522748},{"atl":[[500,2]],"id":3805731},{"atb":[[6.2,19.23],[5.5,59.19]],"id":522752},{"atl":[[480,0]],"id":522752}],"con":true,"img":false}]}
{"op":"mcm","clk":"5348908864","pt":1646221830213,"mc":[{"id":"1.195453760","rc":[{"atl":[[460,0],[470,2]],"id":522752}],"con":true,"img":false}]}
{"op":"mcm","clk":"5348909125","pt":1646221833131,"mc":[{"id":"1.195453760","rc":[{"atb":[[16.5,0],[14,0]],"id":3805783},{"atb":[[16,0],[13.5,0]],"id":522752}],"con":true,"img":false}]}
{"op":"mcm","clk":"5348909135","pt":1646221833237,"mc":[{"id":"1.195453760","rc":[{"atb":[[11,0],[9.4,0]],"id":3805772}],"con":true,"img":false}]}
{"op":"mcm","clk":"5348909196","pt":1646221833809,"mc":[{"id":"1.195453760","rc":[{"atb":[[17,2.72],[14.5,3.27]],"id":3805783},{"atb":[[16.5,2.72],[14,3.27]],"id":522752}],"con":true,"img":false}]}
{"op":"mcm","clk":"5348909211","pt":1646221834021,"mc":[{"id":"1.195453760","rc":[{"atb":[[9.2,3.27],[10.5,2.72]],"id":3805772}],"con":true,"img":false}]}
{"op":"mcm","clk":"5348911434","pt":1646221859060,"mc":[{"id":"1.195453760","rc":[{"atb":[[42,0],[55,0]],"id":522753}],"con":true,"img":false}]}
{"op":"mcm","clk":"5348911461","pt":1646221859265,"mc":[{"id":"1.195453760","rc":[{"atb":[[26,0],[28,3.7]],"id":522753}],"con":true,"img":false}]}
{"op":"mcm","clk":"5348911514","pt":1646221859761,"mc":[{"id":"1.195453760","rc":[{"atb":[[44,3.27],[60,2.72]],"id":522753}],"con":true,"img":false}]}
{"op":"mcm","clk":"5348914801","pt":1646221897300,"mc":[{"id":"1.195453760","rc":[{"atb":[[22,0],[27,0]],"id":522755}],"con":true,"img":false}]}
{"op":"mcm","clk":"5348914874","pt":1646221898178,"mc":[{"id":"1.195453760","rc":[{"atb":[[24,3.27],[29,2.72]],"id":522755}],"con":true,"img":false}]}
{"op":"mcm","clk":"5348915133","pt":1646221901504,"mc":[{"id":"1.195453760","rc":[{"atl":[[130,0],[120,2]],"id":3805793},{"atl":[[370,0],[380,2]],"id":522751}],"con":true,"img":false}]}
{"op":"mcm","clk":"5348915687","pt":1646221907293,"mc":[{"id":"1.195453760","rc":[{"atl":[[860,2],[870,0]],"id":522749},{"atl":[[760,2],[770,0]],"id":522745},{"atb":[[6.2,0],[5.5,81.41]],"id":522752}],"con":true,"img":false}]}
{"op":"mcm","clk":"5348915718","pt":1646221907603,"mc":[{"id":"1.195453760","rc":[{"atb":[[24,0],[29,0]],"id":522755}],"con":true,"img":false}]}
{"op":"mcm","clk":"5348915792","pt":1646221908393,"mc":[{"id":"1.195453760","rc":[{"atb":[[23,3.27],[28,2.72]],"id":522755}],"con":true,"img":false}]}
{"op":"mcm","clk":"5348916820","pt":1646221920448,"mc":[{"id":"1.195453760","rc":[{"atb":[[9.2,0],[10.5,0]],"id":3805772}],"con":true,"img":false}]}
{"op":"mcm","clk":"5348916899","pt":1646221921232,"mc":[{"id":"1.195453760","rc":[{"atb":[[11,2.72],[9.4,3.27]],"id":3805772}],"con":true,"img":false}]}
{"op":"mcm","clk":"5348917168","pt":1646221924132,"mc":[{"id":"1.195453760","rc":[{"atl":[[460,0],[450,2]],"id":3805783}],"con":true,"img":false}]}
{"op":"mcm","clk":"5348918702","pt":1646221940744,"mc":[{"id":"1.195453760","rc":[{"atb":[[17,0],[14.5,0]],"id":3805783},{"atb":[[23,0],[28,0]],"id":522755}],"con":true,"img":false}]}
{"op":"mcm","clk":"5348918764","pt":1646221941431,"mc":[{"id":"1.195453760","rc":[{"atb":[[16,2.72],[13.5,3.27]],"id":3805783},{"atb":[[22,3.27],[27,2.72]],"id":522755}],"con":true,"img":false}]}
{"op":"mcm","clk":"5348920941","pt":1646221966765,"mc":[{"id":"1.195453760","rc":[{"atb":[[5.2,0],[4.7,0]],"id":3805747}],"con":true,"img":false}]}
{"op":"mcm","clk":"5348920954","pt":1646221966869,"mc":[{"id":"1.195453760","rc":[{"atb":[[3.2,0],[3.3,43.48]],"id":3805747}],"con":true,"img":false}]}
{"op":"mcm","clk":"5348921017","pt":1646221967575,"mc":[{"id":"1.195453760","rc":[{"atb":[[4.8,3.27],[5.3,2.72]],"id":3805747}],"con":true,"img":false}]}
{"op":"mcm","clk":"5348921036","pt":1646221967777,"mc":[{"id":"1.195453760","rc":[{"atb":[[3.6,38.46],[3.3,0]],"id":3805747}],"con":true,"img":false}]}
{"op":"mcm","clk":"5348924000","pt":1646222001845,"mc":[{"id":"1.195453760","rc":[{"atl":[[1000,0]],"id":522754},{"atl":[[110,2],[120,0]],"id":3805793},{"atb":[[18.5,0],[24,4.35]],"id":522749},{"atl":[[860,0],[870,2]],"id":522749},{"atl":[[530,0],[520,2]],"id":3805730},{"atl":[[570,0],[600,2]],"id":3805740},{"atl":[[760,0],[750,2]],"id":522745},{"atl":[[210,2],[220,0]],"id":3805747},{"atb":[[6.4,0],[7.6,15.15]],"id":522755},{"atl":[[640,0],[660,2]],"id":522746},{"atb":[[11,26.64],[14,7.69]],"id":522748},{"atb":[[6.2,19.23],[5.5,59.19]],"id":522752},{"atl":[[540,2],[560,0]],"id":522742}],"con":true,"img":false}]}
{"op":"mcm","clk":"5348924022","pt":1646222002051,"mc":[{"id":"1.195453760","rc":[{"atb":[[8,0],[7,0]],"id":3805746},{"atb":[[11.5,0],[14,0]],"id":522751},{"atb":[[22,0],[27,0]],"id":3805730},{"atb":[[10,0],[12.5,0]],"id":3805771}],"con":true,"img":false}]}
{"op":"mcm","clk":"5348924080","pt":1646222002724,"mc":[{"id":"1.195453760","rc":[{"atb":[[6.8,3.27],[7.8,2.72]],"id":3805746},{"atb":[[12.5,3.27],[15,2.72]],"id":522751},{"atb":[[21,3.27],[26,2.72]],"id":3805730},{"atb":[[10,3.27],[12.5,2.72]],"id":3805771}],"con":true,"img":false}]}
{"op":"mcm","clk":"5348926268","pt":1646222028457,"mc":[{"id":"1.195453760","rc":[{"atb":[[11,0],[9.4,0]],"id":3805772}],"con":true,"img":false}]}
{"op":"mcm","clk":"5348926325","pt":1646222029186,"mc":[{"id":"1.195453760","rc":[{"atb":[[9.6,3.27],[11.5,2.72]],"id":3805772}],"con":true,"img":false}]}
{"op":"mcm","clk":"5348926694","pt":1646222033192,"mc":[{"id":"1.195453760","rc":[{"atb":[[3.2,0],[2.88,0],[4.4,0]],"id":3805746},{"atb":[[9.8,0],[29,0],[14.5,0]],"id":522754},{"atb":[[5.8,0],[7.6,0],[14,0]],"id":3805736},{"atb":[[18,0],[80,0],[26,0]],"id":522747},{"atb":[[8.6,0],[23,0],[11.5,0]],"id":522749},{"atb":[[5.2,0],[8.4,0],[4.2,0]],"id":522751},{"atb":[[17.5,0],[9,0],[7,0]],"id":3805730},{"atb":[[32,0],[10.5,0],[15.5,0]],"id":522753},{"atb":[[18,0],[80,0],[26,0]],"id":522741},{"atb":[[290,0],[95,2.72],[48,0]],"id":522743},{"atb":[[9.8,0],[4.9,0],[5.9,0]],"id":3805740},{"atb":[[32,0],[10.5,0],[15.5,0]],"id":522745},{"atb":[[2.5,0],[3.25,0],[2.7,0]],"id":3805747},{"atb":[[17,0],[6.8,0],[8.8,0]],"id":522755},{"atb":[[5.6,0],[7.2,0],[13,0]],"id":522746},{"atb":[[22,0],[11,0],[8.4,0]],"id":522748},{"atb":[[17,0],[6.8,0],[8.8,0]],"id":522750},{"atb":[[5.8,0],[7.6,0],[14,0]],"id":3805731},{"atb":[[9,0],[4.5,0],[5.5,0]],"id":522752},{"atb":[[17,0],[6.8,0],[8.8,0]],"id":522742}],"con":true,"img":false}]}
{"op":"mcm","clk":"5348926700","pt":1646222033253,"mc":[{"id":"1.195453760","rc":[{"atb":[[5.7,0],[9.4,0],[4.7,0]],"id":3805783},{"atb":[[2.8,0],[2.6,0],[3.5,0]],"id":3805793},{"atb":[[8.8,0],[4.4,0],[5.4,0]],"id":3805771},{"atb":[[9.8,0],[29,0],[14.5,0]],"id":7607472},{"atb":[[3.7,0],[6.8,0],[4.4,0]],"id":3805784},{"atb":[[17.5,0],[9,0],[7,0]],"id":3805755},{"atb":[[5.8,0],[7.6,0],[14,0]],"id":3805762},{"atb":[[4,33.33],[6,0],[3.5,0]],"id":3805772}],"con":true,"img":false}]}
{"op":"mcm","clk":"5348927335","pt":1646222040596,"mc":[{"id":"1.195453760","rc":[{"atb":[[4.8,0],[3.6,47.37],[5.3,8.91]],"id":3805747},{"atl":[[200,0.79],[230,5.34]],"id":3805747}],"con":true,"img":false}]}
{"op":"mcm","clk":"5348927367","pt":1646222040964,"mc":[{"id":"1.195453760","rc":[{"atb":[[24,6.89]],"id":3805736},{"atl":[[610,0.26]],"id":3805736},{"atb":[[160,4.95],[120,9.9]],"id":522747},{"atb":[[160,4.95],[120,9.9]],"id":522753},{"atb":[[160,4.95],[120,9.9]],"id":522743},{"atb":[[42,9.9],[50,4.95]],"id":522748},{"atl":[[110,4.95]],"id":522748}],"con":true,"img":false}]}
{"op":"mcm","clk":"5348927378","pt":1646222041108,"mc":[{"id":"1.195453760","rc":[{"atb":[[5,33.91],[11.5,9.9],[13.5,8.22]],"id":3805783},{"atl":[[25,4.95],[29,9.9],[470,2.61]],"id":3805783},{"atb":[[3.85,44],[7.8,16.59],[7,9.9]],"id":3805746},{"atl":[[300,0.52],[330,3.72],[11.5,4.95],[13.5,9.9]],"id":3805746},{"atb":[[130,4.95],[95,9.9],[28,13.42],[60,2.68]],"id":522754},{"atl":[[1000,0.15]],"id":522754},{"atb":[[5.8,4.95],[5.5,11.64],[3.55,48.13],[5.4,9.9]],"id":3805793},{"atl":[[9.6,9.9],[130,8.91],[100,1.6],[8.8,4.95]],"id":3805793},{"atb":[[32,4.95],[8.8,21.73],[27,9.9]],"id":3805736},{"atl":[[65,4.95],[640,1.91],[85,9.9]],"id":3805736},{"atb":[[36,11.36],[80,2]],"id":522747},{"atb":[[75,4.95],[42,3.86],[24,13.26],[55,9.9]],"id":522749},{"atl":[[150,4.95],[860,0.18],[890,1.37]],"id":522749},{"atb":[[4.3,39.21],[10,4.95],[9.2,9.9]],"id":522751},{"atl":[[370,0.43],[24,4.95],[400,3.07],[28,9.9]],"id":522751},{"atb":[[18.5,9.9],[21,8.22],[8.4,22.42]],"id":3805730},{"atl":[[540,2.27],[75,9.9],[55,4.95],[510,0.31]],"id":3805730},{"atb":[[65,2.47],[28,13.42]],"id":522753},{"atl":[[1000,0.15]],"id":522753},{"atb":[[34,11.59],[75,2.14],[85,9.9],[110,4.95]],"id":522741},{"atl":[[240,4.95],[990,0.15]],"id":522741},{"atb":[[19.5,13.86],[100,1.6]],"id":522743},{"atl":[[1000,0.15]],"id":522743},{"atb":[[21,9.9],[25,4.95]],"id":3805740},{"atl":[[80,9.9],[60,4.95]],"id":3805740},{"atb":[[9,9.9],[9.8,4.95],[4.2,40.16]],"id":3805771},{"atl":[[350,0.45],[380,3.23],[24,4.95],[28,9.9]],"id":3805771},{"atb":[[32,4.95],[10,20.02],[27,9.9]],"id":7607472},{"atl":[[140,4.95],[610,0.26],[640,1.91]],"id":7607472},{"atb":[[36,9.9],[44,4.95],[9.8,15.45]],"id":522745},{"atl":[[740,0.21],[770,1.59],[120,4.95]],"id":522745},{"atb":[[4.8,35.23],[10,9.9],[12,16.59]],"id":3805784},{"atl":[[23,4.95],[430,0.37],[27,9.9],[460,2.67]],"id":3805784},{"atb":[[6.6,4.95],[5.9,9.9]],"id":3805747},{"atl":[[10.5,4.95],[12.5,9.9]],"id":3805747},{"atb":[[17.5,9.9],[19.5,4.95],[7.6,24.06]],"id":522755},{"atl":[[530,2.31],[75,9.9],[55,4.95],[500,0.31]],"id":522755},{"atb":[[34,4.8],[75,4.95],[12.5,17.61],[55,9.9]],"id":3805755},{"atl":[[180,4.95],[900,0.17],[930,1.31]],"id":3805755},{"atb":[[9,21.41],[36,4.95],[23,7.2],[29,9.9]],"id":522746},{"atl":[[75,4.95],[650,0.24],[680,1.8],[95,9.9]],"id":522746},{"atb":[[40,4.06],[14,16.6]],"id":522748},{"atl":[[730,0.21],[760,1.61]],"id":522748},{"atb":[[16,15.58],[32,5.11],[80,4.95],[60,9.9]],"id":522750},{"atl":[[200,4.95],[930,0.16],[960,1.27]],"id":522750},{"atb":[[17.5,4.95],[6.6,26.77],[15.5,9.9]],"id":3805731},{"atl":[[520,2.35],[36,4.95],[44,9.9],[490,0.32]],"id":3805731},{"atb":[[16.5,11.64],[17,4.95],[15,9.9]],"id":522752},{"atl":[[36,9.9],[460,0.34],[29,4.95]],"id":522752},{"atb":[[42,9.9],[24,6.89],[50,4.95],[14.5,16.32]],"id":3805762},{"atl":[[140,4.95],[840,0.19],[870,1.4]],"id":3805762},{"atb":[[7.2,23.17],[19.5,9.9],[23,4.95]],"id":522742},{"atl":[[530,0.29],[560,2.19],[75,9.9],[55,4.95]],"id":522742},{"atb":[[4,42.24],[9,4.95],[8.2,9.9]],"id":3805772},{"atl":[[16,4.95],[18,9.9],[310,0.51],[340,3.61]],"id":3805772}],"con":true,"img":false}]}
{"op":"mcm","clk":"5348927386","pt":1646222041182,"mc":[{"id":"1.195453760","rc":[{"atl":[[440,0.35]],"id":3805783},{"atb":[[17.5,8.91],[9.2,21.11]],"id":3805740},{"atl":[[590,0.26],[620,1.97]],"id":3805740},{"atl":[[740,0],[400,2]],"id":522748}],"con":true,"img":false}]}
{"op":"mcm","clk":"5348927394","pt":1646222041272,"mc":[{"id":"1.195453760","rc":[{"atl":[[75,2],[450,0]],"id":3805783},{"atl":[[32,3.23],[310,0]],"id":3805746},{"atb":[[36,2.86],[28,9.72]],"id":522754},{"atl":[[110,0],[15.5,6.9]],"id":3805793},{"atl":[[620,0],[250,2]],"id":3805736},{"atl":[[870,0],[510,2]],"id":522749},{"atl":[[380,0],[50,2.04]],"id":522751},{"atl":[[520,0],[120,2]],"id":3805730},{"atl":[[860,2],[1000,0]],"id":522741},{"atl":[[600,0],[200,2]],"id":3805740},{"atl":[[360,0],[46,2.22]],"id":3805771},{"atl":[[620,0],[220,2]],"id":7607472},{"atl":[[350,2],[750,0]],"id":522745},{"atl":[[90,2],[440,0]],"id":3805784},{"atb":[[5,3.27],[5.5,2.72]],"id":3805747},{"atl":[[21,5],[210,0]],"id":3805747},{"atl":[[110,2],[510,0]],"id":522755},{"atl":[[530,2],[910,0]],"id":3805755},{"atl":[[290,2],[660,0]],"id":522746},{"atb":[[16,8.91],[30,6.17]],"id":522750},{"atl":[[610,2],[940,0]],"id":522750},{"atl":[[100,2],[500,0]],"id":3805731},{"atb":[[6.2,28.14]],"id":522752},{"atl":[[85,2],[470,0],[490,2.5]],"id":522752},{"atb":[[17.5,6.06],[14.5,8.91]],"id":3805762},{"atl":[[850,0],[480,2]],"id":3805762},{"atl":[[540,0],[140,2]],"id":522742},{"atl":[[38,2.7],[320,0]],"id":3805772}],"con":true,"img":false}]}
{"op":"mcm","clk":"5348927419","pt":1646222041589,"mc":[{"id":"1.195453760","rc":[{"atl":[[1000,1.22]],"id":522741},{"atl":[[610,2.26],[220,0]],"id":7607472}],"con":true,"img":false}]}
{"op":"mcm","clk":"5348927567","pt":1646222043408,"mc":[{"id":"1.195453760","rc":[{"atb":[[6.4,18.52],[5,8.91]],"id":3805783},{"atb":[[3.85,8.91],[4.6,27.78]],"id":3805746},{"atl":[[1000,2.15]],"id":522754},{"atb":[[4.3,30.3],[3.55,8.91]],"id":3805793},{"atb":[[12.5,8.7],[8.8,8.91]],"id":3805736},{"atb":[[24,8.91],[29,3.57]],"id":522749},{"atb":[[4.3,8.91],[5.7,21.28]],"id":522751},{"atb":[[10.5,10.53],[8.4,8.91]],"id":3805730},{"atb":[[34,8.56],[48,5.4]],"id":522741},{"atb":[[9.2,8.91],[14,7.69]],"id":3805740},{"atb":[[5.3,23.26],[4.2,8.91]],"id":3805771},{"atb":[[10,8.91],[14.5,7.41]],"id":7607472},{"atb":[[4.8,8.91],[6.2,19.23]],"id":3805784},{"atb":[[3.6,8.91],[3.85,35.09]],"id":3805747},{"atb":[[10.5,10.53],[7.6,8.91]],"id":522755},{"atb":[[9,8.91],[13,8.33]],"id":522746},{"atb":[[19.5,5.41],[14,8.91]],"id":522748},{"atb":[[8,14.29],[6.6,8.91]],"id":3805731},{"atb":[[8.6,13.16],[6.2,8.91]],"id":522752},{"atb":[[7.2,8.91],[10,11.11]],"id":522742},{"atb":[[4,8.91],[5,25]],"id":3805772}],"con":true,"img":false}]}
{"op":"mcm","clk":"5348927777","pt":1646222045707,"mc":[{"id":"1.195453760","rc":[{"atl":[[24,0],[25,4.95],[28,0],[29,9.9]],"id":522751}],"con":true,"img":false}]}
{"op":"mcm","clk":"5348927794","pt":1646222045860,"mc":[{"id":"1.195453760","rc":[{"atl":[[40,2.56],[50,0]],"id":522751}],"con":true,"img":false}]}
{"op":"mcm","clk":"5348927837","pt":1646222046287,"mc":[{"id":"1.195453760","rc":[{"atb":[[20,9.9],[21,0],[24,4.95],[25,0]],"id":3805740},{"atl":[[720,2],[400,0]],"id":522748}],"con":true,"img":false}]}
{"op":"mcm","clk":"5348927848","pt":1646222046390,"mc":[{"id":"1.195453760","rc":[{"atl":[[800,2],[510,0]],"id":522749},{"atl":[[860,0],[990,2.15]],"id":522741},{"atl":[[670,2]],"id":522745},{"atl":[[530,0],[820,2]],"id":3805755},{"atl":[[610,0]],"id":522750},{"atl":[[780,2],[480,0]],"id":3805762}],"con":true,"img":false}]}
{"op":"mcm","clk":"5348927853","pt":1646222046488,"mc":[{"id":"1.195453760","rc":[{"atl":[[350,0]],"id":522745},{"atl":[[890,2]],"id":522750}],"con":true,"img":false}]}
{"op":"mcm","clk":"5348927875","pt":1646222046697,"mc":[{"id":"1.195453760","rc":[{"atb":[[6.8,0],[7.8,13.87]],"id":3805746},{"atb":[[21,4.95],[26,0]],"id":3805730},{"atb":[[22,0],[27,0]],"id":522755},{"atb":[[38,0],[29,0]],"id":522748}],"con":true,"img":false}]}
{"op":"mcm","clk":"5348927893","pt":1646222046903,"mc":[{"id":"1.195453760","rc":[{"atb":[[70,4.95],[75,0],[50,9.9],[55,0]],"id":522749},{"atl":[[75,0],[80,9.9],[55,0],[60,4.95]],"id":522742}],"con":true,"img":false}]}
{"op":"mcm","clk":"5348927927","pt":1646222047176,"mc":[{"id":"1.195453760","rc":[{"atb":[[21,12.88]],"id":3805730},{"atb":[[19.5,13.52]],"id":522755}],"con":true,"img":false}]}
{"op":"mcm","clk":"5348927950","pt":1646222047390,"mc":[{"id":"1.195453760","rc":[{"atb":[[7.6,2.72],[6.6,3.27]],"id":3805746},{"atb":[[40,6.79],[30,3.27]],"id":522748}],"con":true,"img":false}]}
{"op":"mcm","clk":"5348927959","pt":1646222047501,"mc":[{"id":"1.195453760","rc":[{"atb":[[20,3.27],[25,2.72]],"id":3805730},{"atb":[[23,3.27],[28,2.72]],"id":522755}],"con":true,"img":false}]}
{"op":"mcm","clk":"5348928010","pt":1646222048209,"mc":[{"id":"1.195453760","rc":[{"atb":[[5.6,57.91],[9.2,16.24],[4.6,74]],"id":3805783},{"atb":[[3.1,126.85],[2.84,144.78],[4.2,41.62]],"id":3805746},{"atb":[[18.5,15.22],[44,3.09],[13.5,21.31]],"id":522754},{"atb":[[2.5,177.6],[3.25,59.19],[2.7,156.7]],"id":3805793},{"atb":[[7.8,39.17],[14.5,9.86],[5.9,54.37]],"id":3805736},{"atb":[[32,8.59],[210,0.63],[55,4.93]],"id":522747},{"atb":[[9,33.3],[25,5.54],[12.5,23.16]],"id":522749},{"atb":[[5.6,57.91],[9.2,26.14],[4.6,74]],"id":522751},{"atb":[[16,8.87],[6.4,49.33],[8.4,44.91]],"id":3805730},{"atb":[[18.5,15.22],[44,6.36],[13.5,21.31]],"id":522753},{"atb":[[70,4.65],[17,16.65],[24,11.58]],"id":522741},{"atb":[[300,0.44],[100,4.29],[50,5.43]],"id":522743},{"atb":[[5.1,64.97],[10.5,14.02],[6.2,51.23]],"id":3805740},{"atb":[[5.6,57.91],[9.2,16.24],[4.6,74]],"id":3805771},{"atb":[[9.6,30.97],[28,4.93],[14,20.49]],"id":7607472},{"atb":[[9.6,30.97],[28,4.93],[14,20.49]],"id":522745},{"atb":[[3.7,98.67],[6.8,22.96],[4.4,78.35]],"id":3805784},{"atb":[[2.5,177.6],[3.25,59.19],[2.7,156.7]],"id":3805747},{"atb":[[7.2,42.96],[18,7.83],[9.2,32.48]],"id":522755},{"atb":[[9.6,30.97],[19,7.4],[7.6,40.36]],"id":3805755},{"atb":[[7.8,39.17],[14.5,9.86],[5.9,54.37]],"id":522746},{"atb":[[9,33.3],[25,5.54],[12.5,23.16]],"id":522748},{"atb":[[9.6,30.97],[19,7.4],[7.6,40.36]],"id":522750},{"atb":[[12,12.11],[6.8,45.93],[5.4,60.54]],"id":3805731},{"atb":[[5.6,57.91],[9.2,16.24],[4.6,74]],"id":522752},{"atb":[[16,8.87],[6.4,49.33],[8.4,35.99]],"id":3805762},{"atb":[[16,8.87],[6.4,49.33],[8.4,35.99]],"id":522742},{"atb":[[3.7,98.67],[6.8,22.96],[4.4,78.35]],"id":3805772}],"con":true,"img":false}]}
{"op":"mcm","clk":"5348928035","pt":1646222048491,"mc":[{"id":"1.195453760","rc":[{"atb":[[36,0],[50,2.04]],"id":522754}],"con":true,"img":false}]}
{"op":"mcm","clk":"5348928060","pt":1646222048791,"mc":[{"id":"1.195453760","rc":[{"atl":[[240,0],[250,4.95]],"id":522741}],"con":true,"img":false}]}
{"op":"mcm","clk":"5348928302","pt":1646222051606,"mc":[{"id":"1.195453760","rc":[{"atb":[[34,4.95],[36,0],[28,9.9],[29,0]],"id":522746}],"con":true,"img":false}]}
{"op":"mcm","clk":"5348928376","pt":1646222052496,"mc":[{"id":"1.195453760","rc":[{"atl":[[16,0],[16.5,4.95],[18,0],[18.5,9.9]],"id":3805772}],"con":true,"img":false}]}
{"op":"mcm","clk":"5348928621","pt":1646222056307,"mc":[{"id":"1.195453760","rc":[{"atb":[[3.6,0],[5.5,17.51],[6.6,19.74]],"id":3805747},{"atl":[[10.5,19.74],[21,19.79],[230,0]],"id":3805747}],"con":true,"img":false}]}
{"op":"mcm","clk":"5348928635","pt":1646222056514,"mc":[{"id":"1.195453760","rc":[{"atl":[[17.5,6.06],[21,14.79]],"id":3805747}],"con":true,"img":false}]}
{"op":"mcm","clk":"5348928656","pt":1646222056820,"mc":[{"id":"1.195453760","rc":[{"atb":[[5,0],[11.5,29.48]],"id":3805783},{"atl":[[75,19.03],[470,0]],"id":3805783},{"atb":[[3.85,0],[7,31.99]],"id":3805746},{"atl":[[32,25.31],[330,0],[11.5,20.05]],"id":3805746},{"atb":[[130,6.18],[60,14.04]],"id":522754},{"atb":[[5.8,29.94],[3.55,0],[5.4,34.89]],"id":3805793},{"atl":[[130,0],[15.5,31.88]],"id":3805793},{"atb":[[32,10.06],[8.8,0]],"id":3805736},{"atl":[[65,7.43],[640,0],[250,7.1]],"id":3805736},{"atb":[[36,2.86],[220,0.72],[120,20.54]],"id":522747},{"atb":[[42,16.97],[24,0]],"id":522749},{"atl":[[150,6.01],[860,1.66],[890,0]],"id":522749},{"atb":[[4.3,0],[10,17.17]],"id":522751},{"atl":[[40,14.77],[25,11.55],[400,0]],"id":522751},{"atb":[[20,15.48],[8.4,35.99]],"id":3805730},{"atl":[[540,0],[50,3.23],[120,12.63]],"id":3805730},{"atb":[[65,13.52],[170,0.93],[28,3.7]],"id":522753},{"atb":[[34,0],[75,12.7]],"id":522741},{"atb":[[120,17.93]],"id":522743},{"atb":[[9.8,17.17],[4.2,0]],"id":3805771},{"atl":[[46,14.43],[23,7.2]],"id":3805771},{"atb":[[32,13.87],[10,0]],"id":7607472},{"atl":[[140,6.09]],"id":7607472},{"atb":[[9.8,6.54]],"id":522745},{"atl":[[770,0],[110,1.45]],"id":522745},{"atb":[[4.8,0],[9.8,25.35]],"id":3805784},{"atl":[[23,12.15]],"id":3805784},{"atb":[[19.5,25.74],[7.6,0]],"id":522755},{"atl":[[530,0],[55,7.89],[110,13.6]],"id":522755},{"atb":[[34,19.31],[75,7.09],[12.5,8.7]],"id":3805755},{"atl":[[180,5.84],[900,1.58],[930,0]],"id":3805755},{"atb":[[9,0],[24,6.89]],"id":522746},{"atl":[[75,7.09],[680,0]],"id":522746},{"atb":[[50,8.19],[14,0]],"id":522748},{"atl":[[760,0],[110,6.4]],"id":522748},{"atb":[[32,19.82],[16,0],[85,1.88]],"id":522750},{"atl":[[200,5.74],[930,1.53],[960,0]],"id":522750},{"atb":[[17.5,17.17],[6.6,0]],"id":3805731},{"atl":[[520,0],[36,9.48],[100,14.21]],"id":3805731},{"atb":[[17,14.86]],"id":522752},{"atl":[[29,10.61]],"id":522752},{"atb":[[24,21.6],[14.5,0]],"id":3805762},{"atl":[[140,6.09],[840,1.7],[870,0]],"id":3805762},{"atb":[[7.2,0],[21,15.48]],"id":522742},{"atl":[[140,11.11],[560,0],[55,2.93]],"id":522742},{"atb":[[4,0],[9,17.17]],"id":3805772},{"atl":[[38,14.91],[340,0]],"id":3805772}],"con":true,"img":false}]}
{"op":"mcm","clk":"5348928662","pt":1646222056889,"mc":[{"id":"1.195453760","rc":[{"atb":[[28,0]],"id":522754},{"atl":[[8.8,25.28]],"id":3805793},{"atb":[[24,24.49]],"id":3805736},{"atb":[[70,7.25]],"id":522749},{"atb":[[110,6.4]],"id":522741},{"atl":[[980,0.16]],"id":522741},{"atb":[[19.5,4.14]],"id":522743},{"atb":[[17.5,29.53],[9.2,0],[25,6.6]],"id":3805740},{"atl":[[620,0],[200,8.38],[60,7.64]],"id":3805740},{"atl":[[380,0]],"id":3805771},{"atb":[[38,12.18]],"id":522745},{"atl":[[740,1.92]],"id":522745},{"atl":[[90,16.19],[460,0]],"id":3805784},{"atb":[[23,25.27]],"id":522746},{"atl":[[290,6.39]],"id":522746},{"atb":[[40,21.5]],"id":522748},{"atl":[[730,1.95]],"id":522748},{"atb":[[50,8.19]],"id":3805762},{"atl":[[36,4.52]],"id":3805772}],"con":true,"img":false}]}
{"op":"mcm","clk":"5348928667","pt":1646222056987,"mc":[{"id":"1.195453760","rc":[{"atl":[[85,2],[120,10.63]],"id":3805730},{"atl":[[270,2],[670,0]],"id":522745},{"atb":[[5.3,0]],"id":3805747},{"atl":[[200,0]],"id":3805747},{"atb":[[6.2,0],[15,31.99]],"id":522752},{"atl":[[140,9.11],[110,2]],"id":522742}],"con":true,"img":false}]}
{"op":"mcm","clk":"5348928673","pt":1646222057094,"mc":[{"id":"1.195453760","rc":[{"atl":[[13,8.33],[15.5,24.98]],"id":3805793},{"atl":[[85,17.03],[490,0]],"id":522752}],"con":true,"img":false}]}
{"op":"mcm","clk":"5348928698","pt":1646222057403,"mc":[{"id":"1.195453760","rc":[{"atl":[[990,3.43],[1000,0]],"id":522741}],"con":true,"img":false}]}
{"op":"mcm","clk":"5348928708","pt":1646222057605,"mc":[{"id":"1.195453760","rc":[{"atl":[[300,0]],"id":3805746},{"atb":[[60,11.35]],"id":522754},{"atb":[[5.5,2.72]],"id":3805793},{"atb":[[24,17.59]],"id":3805736},{"atl":[[610,0]],"id":3805736},{"atb":[[80,0]],"id":522747},{"atl":[[860,1.47]],"id":522749},{"atl":[[370,0]],"id":522751},{"atl":[[510,0]],"id":3805730},{"atb":[[65,11.04]],"id":522753},{"atl":[[350,0]],"id":3805771},{"atl":[[610,2]],"id":7607472},{"atl":[[740,1.71]],"id":522745},{"atl":[[430,0]],"id":3805784},{"atl":[[500,0]],"id":522755},{"atb":[[34,14.5]],"id":3805755},{"atl":[[900,1.41]],"id":3805755},{"atb":[[23,18.07]],"id":522746},{"atl":[[650,0]],"id":522746},{"atb":[[40,17.44]],"id":522748},{"atl":[[730,1.73]],"id":522748},{"atb":[[32,14.71]],"id":522750},{"atl":[[930,1.36]],"id":522750},{"atl":[[490,0]],"id":3805731},{"atb":[[16.5,2.72]],"id":522752},{"atl":[[460,0]],"id":522752},{"atl":[[840,1.5]],"id":3805762},{"atl":[[530,0]],"id":522742}],"con":true,"img":false}]}
{"op":"mcm","clk":"5348928715","pt":1646222057711,"mc":[{"id":"1.195453760","rc":[{"atl":[[100,0]],"id":3805793},{"atb":[[42,13.1]],"id":522749},{"atb":[[75,10.56]],"id":522741},{"atl":[[990,3.28]],"id":522741},{"atb":[[17.5,20.61]],"id":3805740},{"atl":[[590,0]],"id":3805740},{"atb":[[24,14.71]],"id":3805762},{"atl":[[310,0]],"id":3805772}],"con":true,"img":false}]}
{"op":"mcm","clk":"5348928808","pt":1646222058915,"mc":[{"id":"1.195453760","rc":[{"atl":[[50,0]],"id":3805730},{"atl":[[23,0]],"id":3805771},{"atb":[[85,0]],"id":522750}],"con":true,"img":false}]}
{"op":"mcm","clk":"5348928871","pt":1646222059688,"mc":[{"id":"1.195453760","rc":[{"atl":[[70,2.29]],"id":3805730},{"atl":[[27,6.09]],"id":3805771},{"atb":[[85,1.88]],"id":522750}],"con":true,"img":false}]}
{"op":"mcm","clk":"5348929338","pt":1646222066409,"mc":[{"id":"1.195453760","rc":[{"atb":[[25,0]],"id":3805740},{"atb":[[85,0]],"id":522750}],"con":true,"img":false}]}
{"op":"mcm","clk":"5348929407","pt":1646222067187,"mc":[{"id":"1.195453760","rc":[{"atb":[[21,7.93]],"id":3805740},{"atb":[[80,6.95]],"id":522750}],"con":true,"img":false}]}
{"op":"mcm","clk":"5348929688","pt":1646222071698,"mc":[{"id":"1.195453760","rc":[{"atl":[[17.5,46.83],[21,0]],"id":3805747}],"con":true,"img":false}]}
{"op":"mcm","clk":"5348929721","pt":1646222072112,"mc":[{"id":"1.195453760","rc":[{"atl":[[13,60.63]],"id":3805793},{"atb":[[65,0],[120,18.66]],"id":522753},{"atl":[[140,0],[80,24.62]],"id":522742}],"con":true,"img":false}]}
{"op":"mcm","clk":"5348929726","pt":1646222072213,"mc":[{"id":"1.195453760","rc":[{"atl":[[15.5,0]],"id":3805793},{"atb":[[160,7.09],[120,9.9]],"id":522747},{"atl":[[75,27.51],[50,3.23]],"id":3805730},{"atl":[[250,5.59]],"id":522741},{"atb":[[17.5,0],[25,6.6]],"id":3805740},{"atl":[[46,2.22],[23,7.2],[28,26.33]],"id":3805771},{"atb":[[34,9.76],[23,0],[24,27.68]],"id":522746},{"atl":[[36,18.61],[38,2.7]],"id":3805772}],"con":true,"img":false}]}
{"op":"mcm","clk":"5348929734","pt":1646222072316,"mc":[{"id":"1.195453760","rc":[{"atl":[[120,0]],"id":3805730},{"atb":[[20,34.15]],"id":3805740},{"atl":[[270,6.88],[740,0]],"id":522745},{"atl":[[16.5,15.18]],"id":3805772}],"con":true,"img":false}]}
{"op":"mcm","clk":"5348929776","pt":1646222072934,"mc":[{"id":"1.195453760","rc":[{"atl":[[980,0]],"id":522741},{"atb":[[21,0]],"id":3805740},{"atl":[[27,0]],"id":3805771},{"atb":[[24,20.79]],"id":522746}],"con":true,"img":false}]}
{"op":"mcm","clk":"5348929785","pt":1646222073040,"mc":[{"id":"1.195453760","rc":[{"atl":[[70,0]],"id":3805730},{"atl":[[36,14.08]],"id":3805772}],"con":true,"img":false}]}
{"op":"mcm","clk":"5348929813","pt":1646222073312,"mc":[{"id":"1.195453760","rc":[{"atl":[[270,4.89],[990,2]],"id":522741}],"con":true,"img":false}]}
{"op":"mcm","clk":"5348929828","pt":1646222073520,"mc":[{"id":"1.195453760","rc":[{"atl":[[670,2],[990,0]],"id":522741}],"con":true,"img":false}]}
{"op":"mcm","clk":"5348929866","pt":1646222074029,"mc":[{"id":"1.195453760","rc":[{"atl":[[270,0]],"id":522741}],"con":true,"img":false}]}
{"op":"mcm","clk":"5348930014","pt":1646222076622,"mc":[{"id":"1.195453760","rc":[{"atl":[[23,0]],"id":3805771}],"con":true,"img":false}]}
{"op":"mcm","clk":"5348930069","pt":1646222077404,"mc":[{"id":"1.195453760","rc":[{"atl":[[27,6.09]],"id":3805771}],"con":true,"img":false}]}
{"op":"mcm","clk":"5348930184","pt":1646222079522,"mc":[{"id":"1.195453760","rc":[{"atb":[[36,0],[46,0]],"id":7607472}],"con":true,"img":false}]}
{"op":"mcm","clk":"5348930201","pt":1646222079831,"mc":[{"id":"1.195453760","rc":[{"atl":[[32,9.9],[25,0],[27,4.95],[29,0]],"id":522751},{"atl":[[50,0]],"id":3805730},{"atl":[[260,4.95],[250,0.63]],"id":522741},{"atb":[[25,0]],"id":3805740},{"atl":[[140,0],[150,4.95]],"id":7607472},{"atl":[[110,0]],"id":522745},{"atl":[[75,0],[80,9.9],[55,0],[60,4.95]],"id":522755},{"atl":[[110,0],[120,4.95]],"id":522748},{"atl":[[55,0]],"id":522742}],"con":true,"img":false}]}
{"op":"mcm","clk":"5348930215","pt":1646222080042,"mc":[{"id":"1.195453760","rc":[{"atb":[[32,10.06],[27,26.28]],"id":7607472},{"atl":[[610,0],[170,2]],"id":7607472},{"atl":[[85,2],[110,11.6]],"id":522755},{"atl":[[320,2],[720,0]],"id":522748}],"con":true,"img":false}]}
{"op":"mcm","clk":"5348930232","pt":1646222080252,"mc":[{"id":"1.195453760","rc":[{"atl":[[75,9.9],[85,17.8]],"id":3805730},{"atb":[[10,0],[12.5,0]],"id":3805771},{"atb":[[38,3.27],[48,2.72]],"id":7607472},{"atl":[[840,2],[890,0]],"id":522750},{"atb":[[7.2,16.13],[8.6,0]],"id":522752},{"atl":[[80,9.9]],"id":522742}],"con":true,"img":false}]}
{"op":"mcm","clk":"5348930237","pt":1646222080307,"mc":[{"id":"1.195453760","rc":[{"atb":[[17,26.53],[20,9.9]],"id":3805740},{"atl":[[110,14.21]],"id":522742}],"con":true,"img":false}]}
{"op":"mcm","clk":"5348930243","pt":1646222080418,"mc":[{"id":"1.195453760","rc":[{"atl":[[24,0],[25,4.95],[28,16.42],[29,9.9]],"id":3805771}],"con":true,"img":false}]}
{"op":"mcm","clk":"5348930251","pt":1646222080523,"mc":[{"id":"1.195453760","rc":[{"atl":[[1000,0.59]],"id":522747},{"atb":[[12.5,0],[15,0]],"id":522751},{"atl":[[32,0],[34,9.9],[27,0],[28,4.95],[30,5.46]],"id":522751},{"atl":[[70,2.29]],"id":3805730},{"atb":[[21,7.93]],"id":3805740},{"atl":[[150,6.01]],"id":7607472},{"atl":[[120,6.28]],"id":522745},{"atl":[[75,2.14],[85,14.21],[110,0]],"id":522755},{"atl":[[130,4.95],[310,0.51],[120,0]],"id":522748},{"atl":[[75,2.14]],"id":522742}],"con":true,"img":false}]}
{"op":"mcm","clk":"5348930262","pt":1646222080620,"mc":[{"id":"1.195453760","rc":[{"atb":[[9,48.77]],"id":3805771}],"con":true,"img":false}]}
{"op":"mcm","clk":"5348930270","pt":1646222080728,"mc":[{"id":"1.195453760","rc":[{"atl":[[1000,0.15]],"id":522754},{"atl":[[16,6.67],[13,52.3]],"id":3805793},{"atl":[[800,0],[860,3.47]],"id":522749},{"atl":[[38,2.7],[40,12.21]],"id":522751},{"atl":[[85,15.8],[110,2]],"id":3805730},{"atl":[[670,0],[830,2]],"id":522741},{"atb":[[9.8,21.38]],"id":3805771},{"atl":[[270,4.88],[340,2]],"id":522745},{"atl":[[17.5,40.77],[22,4.76]],"id":3805747},{"atl":[[820,0],[900,3.41]],"id":3805755},{"atl":[[320,0],[400,2]],"id":522748},{"atl":[[780,0],[840,3.5]],"id":3805762}],"con":true,"img":false}]}
{"op":"mcm","clk":"5348930286","pt":1646222080931,"mc":[{"id":"1.195453760","rc":[{"atb":[[5.7,61.52]],"id":522751},{"atl":[[34,49.49]],"id":522751},{"atb":[[10,3.27],[12.5,2.72]],"id":3805771},{"atl":[[320,4.19],[730,0]],"id":522748}],"con":true,"img":false}]}
{"op":"mcm","clk":"5348930293","pt":1646222081031,"mc":[{"id":"1.195453760","rc":[{"atb":[[10,12.31]],"id":522751},{"atl":[[40,0]],"id":522751}],"con":true,"img":false}]}
{"op":"mcm","clk":"5348930299","pt":1646222081132,"mc":[{"id":"1.195453760","rc":[{"atl":[[170,7.91],[860,2]],"id":522749},{"atl":[[270,0]],"id":522745},{"atl":[[160,8.4],[840,2]],"id":3805762}],"con":true,"img":false}]}
{"op":"mcm","clk":"5348930308","pt":1646222081234,"mc":[{"id":"1.195453760","rc":[{"atb":[[12,3.27],[14.5,2.72]],"id":522751},{"atl":[[340,5.95]],"id":522745},{"atl":[[200,6.72],[900,2]],"id":3805755}],"con":true,"img":false}]}
{"op":"mcm","clk":"5348930323","pt":1646222081441,"mc":[{"id":"1.195453760","rc":[{"atl":[[900,0],[510,2]],"id":3805755}],"con":true,"img":false}]}
{"op":"mcm","clk":"5348930331","pt":1646222081551,"mc":[{"id":"1.195453760","rc":[{"atb":[[170,0]],"id":522753},{"atb":[[9,9.9]],"id":3805771}],"con":true,"img":false}]}
{"op":"mcm","clk":"5348930342","pt":1646222081707,"mc":[{"id":"1.195453760","rc":[{"atb":[[5.7,21.28]],"id":522751}],"con":true,"img":false}]}
{"op":"mcm","clk":"5348930366","pt":1646222082017,"mc":[{"id":"1.195453760","rc":[{"atb":[[60,14.14]],"id":522753}],"con":true,"img":false}]}
{"op":"mcm","clk":"5348930377","pt":1646222082119,"mc":[{"id":"1.195453760","rc":[{"atb":[[120,9.9]],"id":522753}],"con":true,"img":false}]}
{"op":"mcm","clk":"5348930384","pt":1646222082227,"mc":[{"id":"1.195453760","rc":[{"atb":[[160,5.95]],"id":522753}],"con":true,"img":false}]}
{"op":"mcm","clk":"5348930397","pt":1646222082331,"mc":[{"id":"1.195453760","rc":[{"atb":[[25,6.6]],"id":3805740}],"con":true,"img":false}]}
{"op":"mcm","clk":"5348930447","pt":1646222083147,"mc":[{"id":"1.195453760","rc":[{"atb":[[21,0]],"id":3805740}],"con":true,"img":false}]}
{"op":"mcm","clk":"5348930483","pt":1646222083627,"mc":[{"id":"1.195453760","rc":[{"atb":[[65,4.95],[70,0],[48,9.9],[50,0]],"id":522749},{"atb":[[25,0]],"id":3805740}],"con":true,"img":false}]}
{"op":"mcm","clk":"5348930547","pt":1646222084451,"mc":[{"id":"1.195453760","rc":[{"atb":[[44,3.68]],"id":522749},{"atb":[[21,7.93]],"id":3805740}],"con":true,"img":false}]}
{"op":"mcm","clk":"5348930574","pt":1646222084928,"mc":[{"id":"1.195453760","rc":[{"atb":[[44,19.99]],"id":522749}],"con":true,"img":false}]}
{"op":"mcm","clk":"5348930580","pt":1646222085034,"mc":[{"id":"1.195453760","rc":[{"atb":[[42,0]],"id":522749}],"con":true,"img":false}]}
{"op":"mcm","clk":"5348930596","pt":1646222085242,"mc":[{"id":"1.195453760","rc":[{"atl":[[610,2],[170,0]],"id":7607472},{"atl":[[85,12.21],[110,2]],"id":522755}],"con":true,"img":false}]}
{"op":"mcm","clk":"5348930607","pt":1646222085459,"mc":[{"id":"1.195453760","rc":[{"atl":[[1000,2.15]],"id":522754},{"atl":[[18,5.88],[22,0]],"id":3805747},{"atl":[[840,0],[930,3.36]],"id":522750}],"con":true,"img":false}]}
{"op":"mcm","clk":"5348930643","pt":1646222085920,"mc":[{"id":"1.195453760","rc":[{"atl":[[220,6.17],[930,2]],"id":522750}],"con":true,"img":false}]}
{"op":"mcm","clk":"5348930729","pt":1646222087258,"mc":[{"id":"1.195453760","rc":[{"atl":[[85,0]],"id":3805730},{"atb":[[24,11.84]],"id":3805740},{"atl":[[24,6.89]],"id":3805771},{"atl":[[80,24.62],[110,2]],"id":522742}],"con":true,"img":false}]}
{"op":"mcm","clk":"5348930734","pt":1646222087321,"mc":[{"id":"1.195453760","rc":[{"atl":[[75,28.09],[50,3.23]],"id":3805730},{"atb":[[20,34.15]],"id":3805740},{"atl":[[140,9.73],[340,2]],"id":522745}],"con":true,"img":false}]}
{"op":"mcm","clk":"5348930740","pt":1646222087424,"mc":[{"id":"1.195453760","rc":[{"atl":[[800,2],[860,0]],"id":522749},{"atl":[[85,2]],"id":3805730},{"atl":[[670,2],[830,0]],"id":522741},{"atb":[[17,2.72]],"id":3805740},{"atl":[[270,2]],"id":522745}],"con":true,"img":false}]}
{"op":"mcm","clk":"5348930748","pt":1646222087533,"mc":[{"id":"1.195453760","rc":[{"atl":[[16,0],[13.5,8]],"id":3805793},{"atl":[[110,0]],"id":3805730},{"atl":[[340,0]],"id":522745},{"atl":[[320,6.19],[400,0]],"id":522748},{"atl":[[770,2],[840,0]],"id":3805762}],"con":true,"img":false}]}
{"op":"mcm","clk":"5348930763","pt":1646222087746,"mc":[{"id":"1.195453760","rc":[{"atl":[[27,22.52],[28,0]],"id":3805771}],"con":true,"img":false}]}
{"op":"mcm","clk":"5348930789","pt":1646222088044,"mc":[{"id":"1.195453760","rc":[{"atl":[[70,0]],"id":3805730},{"atb":[[21,0]],"id":3805740},{"atl":[[27,16.42]],"id":3805771}],"con":true,"img":false}]}
{"op":"mcm","clk":"5348930814","pt":1646222088456,"mc":[{"id":"1.195453760","rc":[{"atl":[[800,3.7]],"id":522749},{"atl":[[670,4.03]],"id":522741},{"atl":[[160,0],[770,3.76]],"id":3805762}],"con":true,"img":false}]}
{"op":"mcm","clk":"5348930820","pt":1646222088533,"mc":[{"id":"1.195453760","rc":[{"atl":[[170,0]],"id":522749},{"atl":[[270,7.05]],"id":522745},{"atl":[[510,4.67]],"id":3805755}],"con":true,"img":false}]}
{"op":"mcm","clk":"5348930829","pt":1646222088622,"mc":[{"id":"1.195453760","rc":[{"atl":[[140,0]],"id":522745},{"atl":[[200,0]],"id":3805755}],"con":true,"img":false}]}
{"op":"mcm","clk":"5348930864","pt":1646222089341,"mc":[{"id":"1.195453760","rc":[{"atl":[[800,2]],"id":522749},{"atl":[[270,2]],"id":522745},{"atl":[[510,2]],"id":3805755},{"atl":[[770,2]],"id":3805762}],"con":true,"img":false}]}
{"op":"mcm","clk":"5348931043","pt":1646222091953,"mc":[{"id":"1.195453760","rc":[{"atl":[[560,2],[610,0]],"id":7607472},{"atl":[[85,14.21],[110,0]],"id":522755}],"con":true,"img":false}]}
{"op":"mcm","clk":"5348931058","pt":1646222092154,"mc":[{"id":"1.195453760","rc":[{"atl":[[840,2],[930,0]],"id":522750}],"con":true,"img":false}]}
{"op":"mcm","clk":"5348931140","pt":1646222093154,"mc":[{"id":"1.195453760","rc":[{"atl":[[840,3.63],[220,0]],"id":522750}],"con":true,"img":false}]}
{"op":"mcm","clk":"5348931158","pt":1646222093461,"mc":[{"id":"1.195453760","rc":[{"atb":[[20,24.24],[24,0]],"id":3805740},{"atb":[[70,4.95],[75,0],[50,9.9],[55,0]],"id":3805755},{"atb":[[40,9.9],[42,0],[48,4.95],[50,0]],"id":3805762}],"con":true,"img":false}]}
{"op":"mcm","clk":"5348931166","pt":1646222093561,"mc":[{"id":"1.195453760","rc":[{"atb":[[19.5,9.9],[23,4.95]],"id":3805740}],"con":true,"img":false}]}
{"op":"mcm","clk":"5348931196","pt":1646222093944,"mc":[{"id":"1.195453760","rc":[{"atl":[[840,2]],"id":522750}],"con":true,"img":false}]}
{"op":"mcm","clk":"5348931212","pt":1646222094147,"mc":[{"id":"1.195453760","rc":[{"atb":[[21,7.93]],"id":3805740},{"atb":[[36,4.52]],"id":3805755},{"atb":[[25,5.94]],"id":3805762}],"con":true,"img":false}]}
{"op":"mcm","clk":"5348931242","pt":1646222094546,"mc":[{"id":"1.195453760","rc":[{"atb":[[19.5,37.09],[20,0]],"id":3805740},{"atb":[[34,0],[36,19.24]],"id":3805755},{"atb":[[25,23.63]],"id":3805762}],"con":true,"img":false}]}
{"op":"mcm","clk":"5348931246","pt":1646222094650,"mc":[{"id":"1.195453760","rc":[{"atb":[[24,0]],"id":3805762}],"con":true,"img":false}]}
{"op":"mcm","clk":"5348931262","pt":1646222094961,"mc":[{"id":"1.195453760","rc":[{"atb":[[27,9.9]],"id":7607472}],"con":true,"img":false}]}
{"op":"mcm","clk":"5348931267","pt":1646222095058,"mc":[{"id":"1.195453760","rc":[{"atb":[[32,18.98]],"id":7607472}],"con":true,"img":false}]}
{"op":"mcm","clk":"5348931298","pt":1646222095442,"mc":[{"id":"1.195453760","rc":[{"atl":[[27,6.09]],"id":522751},{"atb":[[23,12.15]],"id":3805740},{"atl":[[80,22.12],[85,2],[55,2.93]],"id":522755},{"atl":[[130,6.18]],"id":522748},{"atb":[[38,9.9],[40,0],[46,4.95],[48,0]],"id":3805762},{"atl":[[55,2.93]],"id":522742}],"con":true,"img":false}]}
{"op":"mcm","clk":"5348931303","pt":1646222095536,"mc":[{"id":"1.195453760","rc":[{"atb":[[9.8,38.97]],"id":3805771}],"con":true,"img":false}]}
{"op":"mcm","clk":"5348931320","pt":1646222095848,"mc":[{"id":"1.195453760","rc":[{"atl":[[280,4.95]],"id":522754},{"atb":[[10,27.8]],"id":522751},{"atl":[[34,9.9],[30,20.95]],"id":522751},{"atl":[[75,13.87],[80,9.9]],"id":522742}],"con":true,"img":false}]}
{"op":"mcm","clk":"5348931334","pt":1646222096055,"mc":[{"id":"1.195453760","rc":[{"atl":[[800,2],[1000,0.15]],"id":522754},{"atl":[[170,8.15]],"id":522749},{"atl":[[160,8.67]],"id":3805762}],"con":true,"img":false}]}
{"op":"mcm","clk":"5348931343","pt":1646222096159,"mc":[{"id":"1.195453760","rc":[{"atl":[[30,15.48]],"id":522751},{"atb":[[21,0]],"id":3805740},{"atl":[[140,9.91]],"id":522745},{"atl":[[75,0]],"id":522755},{"atl":[[200,6.93]],"id":3805755},{"atl":[[310,0]],"id":522748},{"atl":[[75,11.72]],"id":522742}],"con":true,"img":false}]}
{"op":"mcm","clk":"5348931350","pt":1646222096263,"mc":[{"id":"1.195453760","rc":[{"atl":[[1000,2.15]],"id":522754},{"atl":[[800,0],[400,2]],"id":522749},{"atl":[[370,2],[770,0]],"id":3805762}],"con":true,"img":false}]}
{"op":"mcm","clk":"5348931360","pt":1646222096364,"mc":[{"id":"1.195453760","rc":[{"atl":[[270,0.58],[800,0]],"id":522754},{"atl":[[410,2],[510,0]],"id":3805755}],"con":true,"img":false}]}
{"op":"mcm","clk":"5348931374","pt":1646222096562,"mc":[{"id":"1.195453760","rc":[{"atl":[[1000,3.53]],"id":522754}],"con":true,"img":false}]}
{"op":"mcm","clk":"5348931379","pt":1646222096665,"mc":[{"id":"1.195453760","rc":[{"atl":[[150,9.25]],"id":522748}],"con":true,"img":false}]}
{"op":"mcm","clk":"5348931384","pt":1646222096769,"mc":[{"id":"1.195453760","rc":[{"atl":[[320,2]],"id":522748}],"con":true,"img":false}]}
{"op":"mcm","clk":"5348931414","pt":1646222097148,"mc":[{"id":"1.195453760","rc":[{"atl":[[1000,3.37]],"id":522754}],"con":true,"img":false}]}
{"op":"mcm","clk":"5348931426","pt":1646222097347,"mc":[{"id":"1.195453760","rc":[{"atl":[[150,0]],"id":522748}],"con":true,"img":false}]}
{"op":"mcm","clk":"5348931438","pt":1646222097556,"mc":[{"id":"1.195453760","rc":[{"atb":[[7.2,0],[8.4,13.51]],"id":522752}],"con":true,"img":false}]}
{"op":"mcm","clk":"5348931543","pt":1646222099271,"mc":[{"id":"1.195453760","rc":[{"atb":[[65,7.43]],"id":522749}],"con":true,"img":false}]}
{"op":"mcm","clk":"5348931582","pt":1646222099950,"mc":[{"id":"1.195453760","rc":[{"atb":[[44,16.3]],"id":522749}],"con":true,"img":false}]}
{"op":"mcm","clk":"5348931633","pt":1646222100644,"mc":[{"id":"1.195453760","rc":[{"atl":[[220,6.36]],"id":522750}],"con":true,"img":false}]}
{"op":"mcm","clk":"5348931644","pt":1646222100843,"mc":[{"id":"1.195453760","rc":[{"atl":[[840,0],[440,2]],"id":522750}],"con":true,"img":false}]}
{"op":"mcm","clk":"5348931659","pt":1646222101053,"mc":[{"id":"1.195453760","rc":[{"atb":[[5.8,24.98],[5.5,12.63],[5.9,4.95],[5.4,24.98]],"id":3805793},{"atl":[[34,0],[26,4.95],[28,0],[30,25.39]],"id":522751},{"atl":[[65,9.9],[75,18.18],[48,4.95],[55,0]],"id":3805730},{"atl":[[260,0],[230,4.95]],"id":522741},{"atl":[[24,11.84],[25,0],[28,9.9],[29,0]],"id":3805771},{"atl":[[130,4.95],[150,1.06]],"id":7607472},{"atl":[[140,19.82],[100,4.95],[120,1.32]],"id":522745},{"atb":[[10,0],[10.5,9.9],[12,11.64],[12.5,4.95]],"id":3805784},{"atb":[[6.8,4.95],[6,9.9],[6.6,14.79],[5.9,0]],"id":3805747},{"atl":[[70,9.9],[80,12.21],[50,4.95],[60,0]],"id":522755},{"atl":[[160,4.95],[180,0.88]],"id":3805755},{"atb":[[34,4.8],[36,4.95],[28,0],[29,9.9]],"id":522746},{"atl":[[130,1.23],[110,4.95]],"id":522748},{"atl":[[180,4.95],[200,0.79]],"id":522750},{"atl":[[34,4.95],[36,4.52],[42,9.9],[44,0]],"id":3805731},{"atl":[[34,9.9],[36,0],[28,4.95],[29,5.66]],"id":522752},{"atb":[[38,0],[40,9.9],[46,0],[48,4.95]],"id":3805762},{"atl":[[75,21.63],[80,0],[55,7.89],[60,0]],"id":522742},{"atb":[[9,12.21],[9.2,4.95],[8.2,0],[8.4,9.9]],"id":3805772}],"con":true,"img":false}]}
{"op":"mcm","clk":"5348931674","pt":1646222101257,"mc":[{"id":"1.195453760","rc":[{"atl":[[560,0],[160,2]],"id":7607472}],"con":true,"img":false}]}
{"op":"mcm","clk":"5348931689","pt":1646222101475,"mc":[{"id":"1.195453760","rc":[{"atb":[[5.5,68.55],[5.4,0]],"id":3805793},{"atl":[[75,0],[48,8.32]],"id":3805730},{"atl":[[220,0.93]],"id":522741},{"atl":[[560,2.49]],"id":7607472},{"atl":[[100,6.55]],"id":522745},{"atb":[[9.8,3.27]],"id":3805784},{"atb":[[5.5,2.72],[7,26.42]],"id":3805747},{"atb":[[36,9.48],[24,0]],"id":522746},{"atl":[[42,23.99]],"id":3805731}],"con":true,"img":false}]}
{"op":"mcm","clk":"5348931697","pt":1646222101570,"mc":[{"id":"1.195453760","rc":[{"atb":[[6,31.7]],"id":3805793},{"atl":[[65,31.5]],"id":3805730},{"atl":[[27,0],[28,42.25]],"id":3805771},{"atl":[[130,6.18],[640,0]],"id":7607472},{"atb":[[10.5,41.93],[12.5,18.74]],"id":3805784},{"atb":[[6,46.62]],"id":3805747},{"atl":[[150,1.06]],"id":3805755},{"atb":[[29,29.97]],"id":522746},{"atl":[[170,0.93]],"id":522750},{"atl":[[100,2]],"id":3805731},{"atl":[[34,33.04],[85,2],[27,5.65]],"id":522752},{"atb":[[9,0],[9.2,27.04]],"id":3805772}],"con":true,"img":false}]}
{"op":"mcm","clk":"5348931717","pt":1646222101783,"mc":[{"id":"1.195453760","rc":[{"atb":[[17,29.91],[19.5,9.9]],"id":3805740},{"atl":[[130,4.95],[140,1.13]],"id":3805762},{"atl":[[16.5,10.22],[16,4.95],[18.5,0],[18,9.9]],"id":3805772}],"con":true,"img":false}]}
{"op":"mcm","clk":"5348931739","pt":1646222102054,"mc":[{"id":"1.195453760","rc":[{"atl":[[670,2]],"id":522741}],"con":true,"img":false}]}
{"op":"mcm","clk":"5348931752","pt":1646222102265,"mc":[{"id":"1.195453760","rc":[{"atb":[[5.8,0]],"id":3805793},{"atl":[[50,0]],"id":3805730},{"atl":[[250,0]],"id":522741},{"atl":[[120,0]],"id":522745},{"atb":[[12,2.72]],"id":3805784},{"atb":[[6.6,0]],"id":3805747},{"atb":[[34,0]],"id":522746},{"atl":[[34,9.9]],"id":522752},{"atl":[[120,1.78]],"id":3805762},{"atl":[[16,15.52],[18,31.99],[36,0]],"id":3805772}],"con":true,"img":false}]}
{"op":"mcm","clk":"5348931756","pt":1646222102372,"mc":[{"id":"1.195453760","rc":[{"atl":[[150,0]],"id":7607472},{"atl":[[180,0]],"id":3805755},{"atl":[[200,0]],"id":522750},{"atl":[[29,0]],"id":522752}],"con":true,"img":false}]}
{"op":"mcm","clk":"5348931781","pt":1646222102728,"mc":[{"id":"1.195453760","rc":[{"atb":[[38,0],[48,0]],"id":7607472},{"atb":[[7.2,16.13],[8.4,0]],"id":522752},{"atl":[[160,0]],"id":3805762}],"con":true,"img":false}]}
{"op":"mcm","clk":"5348931790","pt":1646222102887,"mc":[{"id":"1.195453760","rc":[{"atl":[[270,5.54]],"id":522754},{"atb":[[36,0],[42,4.95],[44,0]],"id":522745},{"atb":[[70,0],[75,4.95],[50,0],[55,9.9]],"id":3805755},{"atl":[[34,9.76]],"id":3805731}],"con":true,"img":false}]}
{"op":"mcm","clk":"5348931799","pt":1646222102953,"mc":[{"id":"1.195453760","rc":[{"atl":[[280,0]],"id":522754},{"atl":[[32,9.9],[26,0],[27,11.05],[30,15.48]],"id":522751},{"atb":[[150,4.95],[160,0],[110,9.9],[120,0]],"id":522753},{"atb":[[65,9.9],[80,2],[85,4.95],[60,0]],"id":522750},{"atl":[[140,0]],"id":3805762},{"atl":[[16.5,0]],"id":3805772}],"con":true,"img":false}]}
{"op":"mcm","clk":"5348931802","pt":1646222103059,"mc":[{"id":"1.195453760","rc":[{"atl":[[790,2],[1000,1.37]],"id":522754},{"atb":[[19.5,0],[19,9.9],[22,4.95],[23,0]],"id":3805740},{"atl":[[75,9.9],[110,14.79]],"id":522742}],"con":true,"img":false}]}
{"op":"mcm","clk":"5348931808","pt":1646222103163,"mc":[{"id":"1.195453760","rc":[{"atb":[[32,10.06],[27,26.43]],"id":7607472}],"con":true,"img":false}]}
{"op":"mcm","clk":"5348931815","pt":1646222103255,"mc":[{"id":"1.195453760","rc":[{"atl":[[170,0],[400,5.51]],"id":522749},{"atl":[[670,4.09]],"id":522741}],"con":true,"img":false}]}
{"op":"mcm","clk":"5348931824","pt":1646222103362,"mc":[{"id":"1.195453760","rc":[{"atl":[[30,0]],"id":522751},{"atl":[[270,7.21],[140,9.9]],"id":522745},{"atb":[[65,24.62],[32,0],[85,6.83]],"id":522750}],"con":true,"img":false}]}
{"op":"mcm","clk":"5348931835","pt":1646222103472,"mc":[{"id":"1.195453760","rc":[{"atl":[[1000,0]],"id":522754},{"atl":[[32,41.06]],"id":522751},{"atb":[[36,3.27],[46,2.72]],"id":7607472},{"atb":[[38,9.9],[40,0],[46,4.95],[48,0]],"id":3805762},{"atl":[[370,5.79]],"id":3805762}],"con":true,"img":false}]}
{"op":"mcm","clk":"5348931843","pt":1646222103563,"mc":[{"id":"1.195453760","rc":[{"atb":[[34,9.9]],"id":522745}],"con":true,"img":false}]}
{"op":"mcm","clk":"5348931849","pt":1646222103664,"mc":[{"id":"1.195453760","rc":[{"atl":[[36,0]],"id":3805731}],"con":true,"img":false}]}
{"op":"mcm","clk":"5348931859","pt":1646222103777,"mc":[{"id":"1.195453760","rc":[{"atb":[[65,0.26]],"id":522753},{"atb":[[17.5,9.6]],"id":3805740}],"con":true,"img":false}]}
{"op":"mcm","clk":"5348931864","pt":1646222103877,"mc":[{"id":"1.195453760","rc":[{"atb":[[10,9.9],[10.5,32.03],[12,7.67],[12.5,0]],"id":3805784},{"atb":[[70,4.95],[75,0],[50,9.9],[55,0]],"id":3805755}],"con":true,"img":false}]}
{"op":"mcm","clk":"5348931873","pt":1646222103977,"mc":[{"id":"1.195453760","rc":[{"atl":[[400,2]],"id":522749}],"con":true,"img":false}]}
{"op":"mcm","clk":"5348931888","pt":1646222104140,"mc":[{"id":"1.195453760","rc":[{"atb":[[80,0]],"id":522750}],"con":true,"img":false}]}
{"op":"mcm","clk":"5348931896","pt":1646222104250,"mc":[{"id":"1.195453760","rc":[{"atb":[[65,8],[60,2.72]],"id":522753}],"con":true,"img":false}]}
{"op":"mcm","clk":"5348931921","pt":1646222104673,"mc":[{"id":"1.195453760","rc":[{"atb":[[10.5,48.71]],"id":3805784}],"con":true,"img":false}]}
{"op":"mcm","clk":"5348931981","pt":1646222105672,"mc":[{"id":"1.195453760","rc":[{"atl":[[11.5,0],[12,4.95],[13.5,0],[14,9.9]],"id":3805746}],"con":true,"img":false}]}
{"op":"mcm","clk":"5348931990","pt":1646222105758,"mc":[{"id":"1.195453760","rc":[{"atb":[[65,4.95],[46,9.9],[60,4.95]],"id":522749}],"con":true,"img":false}]}
{"op":"mcm","clk":"5348931999","pt":1646222105873,"mc":[{"id":"1.195453760","rc":[{"atb":[[65,0],[48,0]],"id":522749},{"atb":[[36,9.9],[38,0],[44,4.95],[46,0]],"id":3805762}],"con":true,"img":false}]}
{"op":"mcm","clk":"5348932004","pt":1646222105966,"mc":[{"id":"1.195453760","rc":[{"atb":[[18.5,9.9],[19,0],[21,4.95],[22,0]],"id":3805740}],"con":true,"img":false}]}
{"op":"mcm","clk":"5348932022","pt":1646222106284,"mc":[{"id":"1.195453760","rc":[{"atb":[[44,0],[48,14.71]],"id":522749}],"con":true,"img":false}]}
{"op":"mcm","clk":"5348932032","pt":1646222106338,"mc":[{"id":"1.195453760","rc":[{"atl":[[30,5.46]],"id":3805746}],"con":true,"img":false}]}
{"op":"mcm","clk":"5348932037","pt":1646222106439,"mc":[{"id":"1.195453760","rc":[{"atb":[[60,7.64]],"id":522749},{"atl":[[560,4.49]],"id":7607472}],"con":true,"img":false}]}
{"op":"mcm","clk":"5348932041","pt":1646222106547,"mc":[{"id":"1.195453760","rc":[{"atl":[[11.5,4.95],[12,0],[13.5,9.9],[14,0]],"id":3805746},{"atb":[[65,4.95],[46,0],[48,24.62],[60,2.68]],"id":522749},{"atl":[[65,21.59],[70,9.9],[48,0],[50,4.95]],"id":3805730},{"atl":[[160,0]],"id":7607472},{"atb":[[65,14.71],[80,4.95],[85,0],[60,9.9]],"id":522750}],"con":true,"img":false}]}
{"op":"mcm","clk":"5348932053","pt":1646222106762,"mc":[{"id":"1.195453760","rc":[{"atb":[[150,0],[160,4.95],[110,0],[120,9.9]],"id":522753},{"atb":[[18.5,0],[19,9.9],[21,0],[22,4.95]],"id":3805740},{"atl":[[140,0],[100,0],[110,4.95]],"id":522745}],"con":true,"img":false}]}
{"op":"mcm","clk":"5348932057","pt":1646222106853,"mc":[{"id":"1.195453760","rc":[{"atl":[[32,3.23],[30,28.33]],"id":3805746},{"atl":[[75,0],[80,9.9],[55,2.93],[60,4.95]],"id":522742}],"con":true,"img":false}]}
{"op":"mcm","clk":"5348932061","pt":1646222106971,"mc":[{"id":"1.195453760","rc":[{"atl":[[32,31.15],[27,0]],"id":522751},{"atl":[[55,0]],"id":522742}],"con":true,"img":false}]}
{"op":"mcm","clk":"5348932070","pt":1646222107067,"mc":[{"id":"1.195453760","rc":[{"atb":[[48,9.9]],"id":522749},{"atl":[[34,9.9],[28,4.95]],"id":522751}],"con":true,"img":false}]}
{"op":"mcm","clk":"5348932084","pt":1646222107285,"mc":[{"id":"1.195453760","rc":[{"atb":[[32,0],[26,9.9],[27,0],[30,4.95]],"id":3805736},{"atb":[[80,6.95]],"id":522750}],"con":true,"img":false}]}
{"op":"mcm","clk":"5348932088","pt":1646222107372,"mc":[{"id":"1.195453760","rc":[{"atl":[[60,2.68]],"id":3805730}],"con":true,"img":false}]}
{"op":"mcm","clk":"5348932096","pt":1646222107479,"mc":[{"id":"1.195453760","rc":[{"atb":[[150,4.95],[160,0],[110,9.9],[120,0]],"id":522753},{"atl":[[1000,0.15]],"id":522745}],"con":true,"img":false}]}
{"op":"mcm","clk":"5348932112","pt":1646222107652,"mc":[{"id":"1.195453760","rc":[{"atl":[[36,2.86],[38,0],[30,5.46]],"id":522751},{"atl":[[270,5.21],[670,2]],"id":522745},{"atl":[[100,1.6]],"id":522742}],"con":true,"img":false}]}
{"op":"mcm","clk":"5348932128","pt":1646222107874,"mc":[{"id":"1.195453760","rc":[{"atb":[[12,9.9],[14,4.95]],"id":3805783},{"atl":[[80,0],[60,2.68]],"id":3805740},{"atb":[[9,0],[9.8,34.02]],"id":3805771},{"atb":[[36,9.9],[44,4.95]],"id":522745},{"atb":[[16,9.9],[18,8.22]],"id":3805731},{"atb":[[21,12.21],[26,0]],"id":522742}],"con":true,"img":false}]}
{"op":"mcm","clk":"5348932136","pt":1646222107974,"mc":[{"id":"1.195453760","rc":[{"atb":[[11.5,19.57],[13.5,3.27]],"id":3805783},{"atl":[[9.6,0],[10.5,9.9],[8.8,20.32],[9.4,4.95]],"id":3805793},{"atb":[[12,0],[14.5,0]],"id":522751},{"atl":[[230,0],[240,4.95]],"id":522741},{"atl":[[65,4.95],[85,9.9]],"id":3805740},{"atb":[[10,8.22],[9.2,26.14]],"id":3805771},{"atb":[[34,0],[42,0]],"id":522745},{"atb":[[34,4.95],[36,4.52],[28,9.9],[29,20.06]],"id":522746},{"atl":[[70,4.95],[75,2.14],[90,9.9],[95,0]],"id":522746},{"atb":[[17.5,12.21],[15.5,0]],"id":3805731},{"atl":[[34,4.95]],"id":3805731},{"atb":[[17,0],[15,22.08],[15.5,4.95]],"id":522752},{"atl":[[27,0]],"id":522752},{"atb":[[19.5,0],[21,17.17],[23,0]],"id":522742}],"con":true,"img":false}]}
{"op":"mcm","clk":"5348932144","pt":1646222108077,"mc":[{"id":"1.195453760","rc":[{"atb":[[32,4.95],[26,0],[27,16],[30,0]],"id":3805736},{"atl":[[65,2.47],[70,4.95],[85,0],[90,9.9]],"id":3805736}],"con":true,"img":false}]}
{"op":"mcm","clk":"5348932153","pt":1646222108167,"mc":[{"id":"1.195453760","rc":[{"atl":[[790,0],[1000,2]],"id":522754},{"atl":[[290,4.39],[210,2]],"id":522746}],"con":true,"img":false}]}
{"op":"mcm","clk":"5348932167","pt":1646222108376,"mc":[{"id":"1.195453760","rc":[{"atb":[[11.5,0],[13.5,22.84]],"id":3805783},{"atl":[[70,20.32],[200,2]],"id":3805740},{"atb":[[38,3.27],[42,14.71]],"id":522745},{"atb":[[19.5,22.08],[21,4.95],[23,7.2]],"id":522742}],"con":true,"img":false}]}
{"op":"mcm","clk":"5348932173","pt":1646222108474,"mc":[{"id":"1.195453760","rc":[{"atl":[[10.5,54.85],[13,0]],"id":3805793},{"atb":[[10,12.31],[5.7,91.77]],"id":522751},{"atl":[[65,2.47],[290,0],[90,24.62]],"id":522746}],"con":true,"img":false}]}
{"op":"mcm","clk":"5348932181","pt":1646222108573,"mc":[{"id":"1.195453760","rc":[{"atl":[[90,25.72],[250,2]],"id":3805736}],"con":true,"img":false}]}
{"op":"mcm","clk":"5348932189","pt":1646222108685,"mc":[{"id":"1.195453760","rc":[{"atb":[[11.5,3.27],[14,2.72]],"id":522751},{"atl":[[46,32.05],[28,9.9]],"id":3805771},{"atb":[[10,42.71],[10.5,16.68]],"id":3805784},{"atl":[[40,4.06],[42,9.9],[100,16.23]],"id":3805731},{"atb":[[15.5,15.88]],"id":522752},{"atl":[[32,5.11]],"id":522752},{"atb":[[18.5,9.9],[20,3.27],[25,2.72]],"id":522742}],"con":true,"img":false}]}
{"op":"mcm","clk":"5348932196","pt":1646222108740,"mc":[{"id":"1.195453760","rc":[{"atb":[[26,6.34]],"id":3805762}],"con":true,"img":false}]}
{"op":"mcm","clk":"5348932202","pt":1646222108854,"mc":[{"id":"1.195453760","rc":[{"atb":[[22,12.5]],"id":3805740},{"atb":[[38,4.28]],"id":3805755}],"con":true,"img":false}]}
{"op":"mcm","clk":"5348932210","pt":1646222108957,"mc":[{"id":"1.195453760","rc":[{"atb":[[5,0],[5.5,65.82]],"id":3805793},{"atb":[[5,0],[5.5,0]],"id":3805747},{"atb":[[9.6,0],[11.5,0]],"id":3805772}],"con":true,"img":false}]}
{"op":"mcm","clk":"5348932227","pt":1646222109176,"mc":[{"id":"1.195453760","rc":[{"atb":[[17.5,31.25],[17,2.72]],"id":3805740},{"atl":[[75,0],[90,9.9]],"id":522746},{"atb":[[25,5.94],[26,22.32]],"id":3805762}],"con":true,"img":false}]}
{"op":"mcm","clk":"5348932240","pt":1646222109363,"mc":[{"id":"1.195453760","rc":[{"atb":[[36,4.52],[38,18.99]],"id":3805755},{"atl":[[18,9.9],[38,30.63]],"id":3805772}],"con":true,"img":false}]}
{"op":"mcm","clk":"5348932249","pt":1646222109470,"mc":[{"id":"1.195453760","rc":[{"atb":[[9.2,24.29],[6.8,80.17]],"id":3805772}],"con":true,"img":false}]}
{"op":"mcm","clk":"5348932254","pt":1646222109570,"mc":[{"id":"1.195453760","rc":[{"atb":[[17.5,21.64]],"id":3805740},{"atb":[[36,0]],"id":3805755},{"atb":[[25,0]],"id":3805762}],"con":true,"img":false}]}
{"op":"mcm","clk":"5348932262","pt":1646222109676,"mc":[{"id":"1.195453760","rc":[{"atb":[[5.6,2.72],[5.1,3.27]],"id":3805793},{"atb":[[32,23.44],[27,9.9]],"id":7607472},{"atb":[[5.6,2.72],[5.1,3.27]],"id":3805747},{"atb":[[12,2.72],[9.8,3.27]],"id":3805772}],"con":true,"img":false}]}
{"op":"mcm","clk":"5348932292","pt":1646222110044,"mc":[{"id":"1.195453760","rc":[{"atl":[[27,6.09]],"id":522751},{"atl":[[70,22.12],[80,0],[48,3.37]],"id":522755},{"atl":[[110,6.4]],"id":522748},{"atl":[[60,7.64]],"id":522742}],"con":true,"img":false}]}
{"op":"mcm","clk":"5348932317","pt":1646222110466,"mc":[{"id":"1.195453760","rc":[{"atb":[[10,27.8],[5.7,21.28]],"id":522751},{"atl":[[30,20.95]],"id":522751},{"atl":[[270,0],[670,4.12]],"id":522745},{"atb":[[65,0],[60,29.71]],"id":522750},{"atl":[[100,15.89],[110,2]],"id":522742}],"con":true,"img":false}]}
{"op":"mcm","clk":"5348932325","pt":1646222110566,"mc":[{"id":"1.195453760","rc":[{"atl":[[32,0]],"id":522751}],"con":true,"img":false}]}
{"op":"mcm","clk":"5348932347","pt":1646222110787,"mc":[{"id":"1.195453760","rc":[{"atl":[[170,8.4]],"id":522749},{"atl":[[30,15.48]],"id":522751},{"atl":[[55,0]],"id":522755},{"atl":[[130,0]],"id":522748},{"atl":[[100,14.29]],"id":522742}],"con":true,"img":false}]}
{"op":"mcm","clk":"5348932403","pt":1646222111364,"mc":[{"id":"1.195453760","rc":[{"atl":[[130,11]],"id":522748}],"con":true,"img":false}]}
{"op":"mcm","clk":"5348932492","pt":1646222112469,"mc":[{"id":"1.195453760","rc":[{"atb":[[20,12.21],[25,0]],"id":3805730}],"con":true,"img":false}]}
{"op":"mcm","clk":"5348932527","pt":1646222112968,"mc":[{"id":"1.195453760","rc":[{"atb":[[18.5,42.8],[20,0]],"id":3805730}],"con":true,"img":false}]}
{"op":"mcm","clk":"5348932556","pt":1646222113285,"mc":[{"id":"1.195453760","rc":[{"atb":[[21,16.15],[26,2.72]],"id":3805730}],"con":true,"img":false}]}
{"op":"mcm","clk":"5348932603","pt":1646222113774,"mc":[{"id":"1.195453760","rc":[{"atb":[[65,7.43]],"id":522749}],"con":true,"img":false}]}
{"op":"mcm","clk":"5348932662","pt":1646222114483,"mc":[{"id":"1.195453760","rc":[{"atb":[[60,0]],"id":522749}],"con":true,"img":false}]}
{"op":"mcm","clk":"5348932703","pt":1646222115067,"mc":[{"id":"1.195453760","rc":[{"atl":[[48,0]],"id":522755}],"con":true,"img":false}]}
{"op":"mcm","clk":"5348932753","pt":1646222115840,"mc":[{"id":"1.195453760","rc":[{"atl":[[65,2.47]],"id":522755}],"con":true,"img":false}]}
{"op":"mcm","clk":"5348932758","pt":1646222115942,"mc":[{"id":"1.195453760","rc":[{"atb":[[5.6,40.3],[5.5,9.9]],"id":3805793},{"atl":[[50,8.19]],"id":3805730},{"atl":[[560,2],[150,9.62]],"id":7607472},{"atl":[[100,1.6]],"id":522745},{"atl":[[42,29.48],[100,2]],"id":3805731}],"con":true,"img":false}]}
{"op":"mcm","clk":"5348932767","pt":1646222116050,"mc":[{"id":"1.195453760","rc":[{"atl":[[560,0],[170,2]],"id":7607472},{"atb":[[12,22.09]],"id":3805784},{"atl":[[34,32.23]],"id":522752},{"atb":[[9.2,62.08],[6.8,22.96]],"id":3805772}],"con":true,"img":false}]}
{"op":"mcm","clk":"5348932772","pt":1646222116150,"mc":[{"id":"1.195453760","rc":[{"atl":[[270,2],[670,2.12]],"id":522745},{"atl":[[28,10.82]],"id":522752}],"con":true,"img":false}]}
{"op":"mcm","clk":"5348932813","pt":1646222116671,"mc":[{"id":"1.195453760","rc":[{"atl":[[60,0]],"id":3805730}],"con":true,"img":false}]}
{"op":"mcm","clk":"5348932818","pt":1646222116777,"mc":[{"id":"1.195453760","rc":[{"atl":[[1000,0]],"id":522745}],"con":true,"img":false}]}
{"op":"mcm","clk":"5348932825","pt":1646222116878,"mc":[{"id":"1.195453760","rc":[{"atb":[[10.5,0]],"id":3805784}],"con":true,"img":false}]}
{"op":"mcm","clk":"5348932833","pt":1646222116984,"mc":[{"id":"1.195453760","rc":[{"atl":[[32,0],[28,4.95]],"id":522752}],"con":true,"img":false}]}
{"op":"mcm","clk":"5348932844","pt":1646222117146,"mc":[{"id":"1.195453760","rc":[{"atl":[[65,0],[70,30.59]],"id":3805730}],"con":true,"img":false}]}
{"op":"mcm","clk":"5348932857","pt":1646222117353,"mc":[{"id":"1.195453760","rc":[{"atb":[[10,9.9],[9.8,45.41]],"id":3805784}],"con":true,"img":false}]}
{"op":"mcm","clk":"5348932862","pt":1646222117456,"mc":[{"id":"1.195453760","rc":[{"atb":[[30,24.83]],"id":522750}],"con":true,"img":false}]}
{"op":"mcm","clk":"5348932869","pt":1646222117562,"mc":[{"id":"1.195453760","rc":[{"atb":[[60,9.9]],"id":522750}],"con":true,"img":false}]}
{"op":"mcm","clk":"5348932879","pt":1646222117677,"mc":[{"id":"1.195453760","rc":[{"atl":[[11.5,0],[13.5,0]],"id":3805746}],"con":true,"img":false}]}
{"op":"mcm","clk":"5348932888","pt":1646222117767,"mc":[{"id":"1.195453760","rc":[{"atl":[[12,4.95],[14,9.9]],"id":3805746},{"atl":[[170,0],[400,5.61]],"id":522749},{"atl":[[270,7.36]],"id":522745},{"atl":[[32,5.11]],"id":522752}],"con":true,"img":false}]}
{"op":"mcm","clk":"5348932899","pt":1646222117897,"mc":[{"id":"1.195453760","rc":[{"atl":[[670,0]],"id":522745}],"con":true,"img":false}]}
{"op":"mcm","clk":"5348932915","pt":1646222118079,"mc":[{"id":"1.195453760","rc":[{"atb":[[11.5,0],[14,0]],"id":522751}],"con":true,"img":false}]}
{"op":"mcm","clk":"5348932923","pt":1646222118184,"mc":[{"id":"1.195453760","rc":[{"atl":[[34,41.23],[30,5.46]],"id":3805746},{"atl":[[70,20.68],[75,9.9],[50,0],[55,4.95]],"id":3805730},{"atl":[[24,0],[25,4.95],[28,0],[29,9.9]],"id":3805771}],"con":true,"img":false}]}
{"op":"mcm","clk":"5348932932","pt":1646222118290,"mc":[{"id":"1.195453760","rc":[{"atb":[[70,0.23]],"id":522753}],"con":true,"img":false}]}
{"op":"mcm","clk":"5348932947","pt":1646222118460,"mc":[{"id":"1.195453760","rc":[{"atl":[[130,0],[320,6.52]],"id":522748}],"con":true,"img":false}]}
{"op":"mcm","clk":"5348932954","pt":1646222118550,"mc":[{"id":"1.195453760","rc":[{"atl":[[400,2]],"id":522749},{"atb":[[10,12.31],[5.7,75.93]],"id":522751}],"con":true,"img":false}]}
{"op":"mcm","clk":"5348932966","pt":1646222118758,"mc":[{"id":"1.195453760","rc":[{"atb":[[11,3.27],[13.5,2.72]],"id":522751},{"atb":[[65,0.26],[70,7.95]],"id":522753}],"con":true,"img":false}]}
{"op":"mcm","clk":"5348932970","pt":1646222118856,"mc":[{"id":"1.195453760","rc":[{"atl":[[65,2.47]],"id":3805730},{"atl":[[44,3.68]],"id":3805771}],"con":true,"img":false}]}
{"op":"mcm","clk":"5348932985","pt":1646222119067,"mc":[{"id":"1.195453760","rc":[{"atb":[[65,0]],"id":522753}],"con":true,"img":false}]}
{"op":"mcm","clk":"5348933001","pt":1646222119283,"mc":[{"id":"1.195453760","rc":[{"atb":[[5.7,21.28]],"id":522751}],"con":true,"img":false}]}
{"op":"mcm","clk":"5348933008","pt":1646222119382,"mc":[{"id":"1.195453760","rc":[{"atl":[[44,23.26]],"id":3805771}],"con":true,"img":false}]}
{"op":"mcm","clk":"5348933014","pt":1646222119479,"mc":[{"id":"1.195453760","rc":[{"atl":[[46,2.22]],"id":3805771}],"con":true,"img":false}]}
{"op":"mcm","clk":"5348933100","pt":1646222120794,"mc":[{"id":"1.195453760","rc":[{"atl":[[12,19.36]],"id":3805746},{"atb":[[40,20.62]],"id":522749}],"con":true,"img":false}]}
{"op":"mcm","clk":"5348933140","pt":1646222121273,"mc":[{"id":"1.195453760","rc":[{"atl":[[34,0],[30,40.81]],"id":3805746}],"con":true,"img":false}]}
{"op":"mcm","clk":"5348933158","pt":1646222121475,"mc":[{"id":"1.195453760","rc":[{"atl":[[30,35.34]],"id":3805746}],"con":true,"img":false}]}
{"op":"mcm","clk":"5348933179","pt":1646222121782,"mc":[{"id":"1.195453760","rc":[{"atl":[[50,3.23]],"id":3805730}],"con":true,"img":false}]}
{"op":"mcm","clk":"5348933234","pt":1646222122452,"mc":[{"id":"1.195453760","rc":[{"atb":[[32,10.06]],"id":3805736}],"con":true,"img":false}]}
{"op":"mcm","clk":"5348933241","pt":1646222122550,"mc":[{"id":"1.195453760","rc":[{"atl":[[65,0]],"id":3805730}],"con":true,"img":false}]}
{"op":"mcm","clk":"5348933249","pt":1646222122652,"mc":[{"id":"1.195453760","rc":[{"atb":[[21,27.02]],"id":522742}],"con":true,"img":false}]}
{"op":"mcm","clk":"5348933257","pt":1646222122792,"mc":[{"id":"1.195453760","rc":[{"atb":[[10,28.73]],"id":522751},{"atl":[[90,24.62]],"id":522746},{"atb":[[19.5,0]],"id":522742}],"con":true,"img":false}]}
{"op":"mcm","clk":"5348933266","pt":1646222122839,"mc":[{"id":"1.195453760","rc":[{"atb":[[36,0]],"id":522746}],"con":true,"img":false}]}
{"op":"mcm","clk":"5348933273","pt":1646222122946,"mc":[{"id":"1.195453760","rc":[{"atl":[[150,0],[170,10.61]],"id":7607472},{"atb":[[16.5,12.95]],"id":522752},{"atl":[[28,10.82]],"id":522752}],"con":true,"img":false}]}
{"op":"mcm","clk":"5348933280","pt":1646222123051,"mc":[{"id":"1.195453760","rc":[{"atb":[[7.4,4.95],[6.6,13.17]],"id":3805746}],"con":true,"img":false}]}
{"op":"mcm","clk":"5348933290","pt":1646222123154,"mc":[{"id":"1.195453760","rc":[{"atb":[[7.8,8.91],[7,22.08]],"id":3805746},{"atb":[[27,9.9]],"id":3805736},{"atb":[[70,7.25]],"id":3805755},{"atb":[[46,3.52]],"id":3805762}],"con":true,"img":false}]}
{"op":"mcm","clk":"5348933296","pt":1646222123254,"mc":[{"id":"1.195453760","rc":[{"atb":[[28,31.99]],"id":522746}],"con":true,"img":false}]}
{"op":"mcm","clk":"5348933303","pt":1646222123361,"mc":[{"id":"1.195453760","rc":[{"atb":[[29,0]],"id":522746}],"con":true,"img":false}]}
{"op":"mcm","clk":"5348933316","pt":1646222123566,"mc":[{"id":"1.195453760","rc":[{"atb":[[7.4,40.29]],"id":3805746},{"atb":[[29,5.66]],"id":522746},{"atb":[[36,24.62]],"id":3805762}],"con":true,"img":false}]}
{"op":"mcm","clk":"5348933321","pt":1646222123669,"mc":[{"id":"1.195453760","rc":[{"atb":[[7,0]],"id":3805746},{"atb":[[26,6.34]],"id":3805762}],"con":true,"img":false}]}
{"op":"mcm","clk":"5348933331","pt":1646222123777,"mc":[{"id":"1.195453760","rc":[{"atb":[[15.5,4.95]],"id":522752},{"atl":[[32,0],[28,4.95]],"id":522752}],"con":true,"img":false}]}
{"op":"mcm","clk":"5348933338","pt":1646222123882,"mc":[{"id":"1.195453760","rc":[{"atb":[[38,14.71]],"id":3805755},{"atb":[[26,0]],"id":3805762}],"con":true,"img":false}]}
{"op":"mcm","clk":"5348933348","pt":1646222124090,"mc":[{"id":"1.195453760","rc":[{"atb":[[65,0],[46,9.9],[48,0],[60,4.95]],"id":522749}],"con":true,"img":false}]}
{"op":"mcm","clk":"5348933366","pt":1646222124302,"mc":[{"id":"1.195453760","rc":[{"atl":[[34,9.9],[85,19.27]],"id":522752}],"con":true,"img":false}]}
{"op":"mcm","clk":"5348933374","pt":1646222124349,"mc":[{"id":"1.195453760","rc":[{"atl":[[48,3.37]],"id":522755}],"con":true,"img":false}]}
{"op":"mcm","clk":"5348933380","pt":1646222124465,"mc":[{"id":"1.195453760","rc":[{"atl":[[32,5.11]],"id":522752}],"con":true,"img":false}]}
{"op":"mcm","clk":"5348933403","pt":1646222124766,"mc":[{"id":"1.195453760","rc":[{"atb":[[42,3.86]],"id":522749},{"atl":[[65,12.35]],"id":522755}],"con":true,"img":false}]}
{"op":"mcm","clk":"5348933408","pt":1646222124871,"mc":[{"id":"1.195453760","rc":[{"atl":[[70,9.9]],"id":522755}],"con":true,"img":false}]}
{"op":"mcm","clk":"5348933427","pt":1646222125079,"mc":[{"id":"1.195453760","rc":[{"atl":[[170,8.64]],"id":522749},{"atl":[[65,9.87]],"id":522755},{"atl":[[85,2]],"id":522752}],"con":true,"img":false}]}
{"op":"mcm","clk":"5348933472","pt":1646222125662,"mc":[{"id":"1.195453760","rc":[{"atl":[[130,11.32],[320,2]],"id":522748}],"con":true,"img":false}]}
{"op":"mcm","clk":"5348933505","pt":1646222126066,"mc":[{"id":"1.195453760","rc":[{"atl":[[50,0]],"id":3805730},{"atl":[[48,0]],"id":522755}],"con":true,"img":false}]}
{"op":"mcm","clk":"5348933543","pt":1646222126585,"mc":[{"id":"1.195453760","rc":[{"atl":[[70,0],[75,29.57]],"id":3805730}],"con":true,"img":false}]}
{"op":"mcm","clk":"5348933555","pt":1646222126740,"mc":[{"id":"1.195453760","rc":[{"atl":[[65,2.47]],"id":3805730},{"atl":[[60,2.68]],"id":522755}],"con":true,"img":false}]}
{"op":"mcm","clk":"5348933660","pt":1646222128094,"mc":[{"id":"1.195453760","rc":[{"atb":[[65,2.47]],"id":522749}],"con":true,"img":false}]}
{"op":"mcm","clk":"5348933708","pt":1646222128767,"mc":[{"id":"1.195453760","rc":[{"atb":[[42,0]],"id":522749}],"con":true,"img":false}]}
{"op":"mcm","clk":"5348933799","pt":1646222130176,"mc":[{"id":"1.195453760","rc":[{"atl":[[50,3.23]],"id":3805730},{"atl":[[150,9.89],[170,2]],"id":7607472},{"atl":[[48,3.37]],"id":522755}],"con":true,"img":false}]}
{"op":"mcm","clk":"5348933806","pt":1646222130280,"mc":[{"id":"1.195453760","rc":[{"atl":[[34,32.23]],"id":522752}],"con":true,"img":false}]}
{"op":"mcm","clk":"5348933813","pt":1646222130383,"mc":[{"id":"1.195453760","rc":[{"atl":[[28,10.82]],"id":522752}],"con":true,"img":false}]}
{"op":"mcm","clk":"5348933858","pt":1646222130857,"mc":[{"id":"1.195453760","rc":[{"atl":[[65,0]],"id":3805730},{"atl":[[60,0]],"id":522755}],"con":true,"img":false}]}
{"op":"mcm","clk":"5348933868","pt":1646222131064,"mc":[{"id":"1.195453760","rc":[{"atl":[[32,0],[28,4.95]],"id":522752}],"con":true,"img":false}]}
{"op":"mcm","clk":"5348933910","pt":1646222131584,"mc":[{"id":"1.195453760","rc":[{"atb":[[7,0]],"id":3805747},{"atl":[[48,0]],"id":522755},{"atl":[[34,9.9],[85,19.51]],"id":522752},{"atl":[[16,4.95],[16.5,4.95],[18.5,9.9]],"id":3805772}],"con":true,"img":false}]}
{"op":"mcm","clk":"5348933919","pt":1646222131691,"mc":[{"id":"1.195453760","rc":[{"atl":[[50,0]],"id":3805730},{"atl":[[16,0],[18,0]],"id":3805772}],"con":true,"img":false}]}
{"op":"mcm","clk":"5348933934","pt":1646222131892,"mc":[{"id":"1.195453760","rc":[{"atl":[[170,0],[400,5.71]],"id":522749},{"atl":[[32,5.11]],"id":522752}],"con":true,"img":false}]}
{"op":"mcm","clk":"5348933946","pt":1646222131949,"mc":[{"id":"1.195453760","rc":[{"atb":[[6,9.9]],"id":3805747},{"atl":[[70,31.19]],"id":522755},{"atl":[[38,2.7]],"id":3805772}],"con":true,"img":false}]}
{"op":"mcm","clk":"5348933952","pt":1646222132048,"mc":[{"id":"1.195453760","rc":[{"atl":[[65,0]],"id":522755},{"atl":[[18,14.71]],"id":3805772}],"con":true,"img":false}]}
{"op":"mcm","clk":"5348933960","pt":1646222132155,"mc":[{"id":"1.195453760","rc":[{"atb":[[5.6,46.81]],"id":3805747}],"con":true,"img":false}]}
{"op":"mcm","clk":"5348933973","pt":1646222132365,"mc":[{"id":"1.195453760","rc":[{"atb":[[6,41.61]],"id":3805747},{"atl":[[60,2.68]],"id":522755},{"atl":[[16.5,0],[18,23.63],[18.5,0]],"id":3805772}],"con":true,"img":false}]}
{"op":"mcm","clk":"5348933982","pt":1646222132472,"mc":[{"id":"1.195453760","rc":[{"atl":[[70,2.29]],"id":3805730},{"atb":[[150,6.01]],"id":522753}],"con":true,"img":false}]}
{"op":"mcm","clk":"5348933988","pt":1646222132570,"mc":[{"id":"1.195453760","rc":[{"atl":[[320,6.65]],"id":522748}],"con":true,"img":false}]}
{"op":"mcm","clk":"5348933996","pt":1646222132692,"mc":[{"id":"1.195453760","rc":[{"atl":[[130,0]],"id":522748}],"con":true,"img":false}]}
{"op":"mcm","clk":"5348934017","pt":1646222132972,"mc":[{"id":"1.195453760","rc":[{"atl":[[25,11.55]],"id":3805771}],"con":true,"img":false}]}
{"op":"mcm","clk":"5348934030","pt":1646222133173,"mc":[{"id":"1.195453760","rc":[{"atl":[[16,4.95],[18,33.54]],"id":3805772}],"con":true,"img":false}]}
{"op":"mcm","clk":"5348934043","pt":1646222133384,"mc":[{"id":"1.195453760","rc":[{"atb":[[70,7.71]],"id":522753},{"atl":[[320,2]],"id":522748}],"con":true,"img":false}]}
{"op":"mcm","clk":"5348934076","pt":1646222133849,"mc":[{"id":"1.195453760","rc":[{"atl":[[44,19.57]],"id":3805771}],"con":true,"img":false}]}
{"op":"mcm","clk":"5348934152","pt":1646222134997,"mc":[{"id":"1.195453760","rc":[{"atb":[[40,2.72],[46,26.91]],"id":522749}],"con":true,"img":false}]}
{"op":"mcm","clk":"5348934211","pt":1646222135879,"mc":[{"id":"1.195453760","rc":[{"atl":[[50,3.23]],"id":3805730}],"con":true,"img":false}]}
{"op":"mcm","clk":"5348934252","pt":1646222136605,"mc":[{"id":"1.195453760","rc":[{"atl":[[70,14.47],[75,9.9]],"id":3805730}],"con":true,"img":false}]}
{"op":"mcm","clk":"5348934277","pt":1646222136865,"mc":[{"id":"1.195453760","rc":[{"atl":[[70,12.17]],"id":3805730}],"con":true,"img":false}]}
{"op":"mcm","clk":"5348934301","pt":1646222137176,"mc":[{"id":"1.195453760","rc":[{"atl":[[170,10.84]],"id":7607472}],"con":true,"img":false}]}
{"op":"mcm","clk":"5348934309","pt":1646222137277,"mc":[{"id":"1.195453760","rc":[{"atl":[[150,0]],"id":7607472},{"atl":[[28,10.82]],"id":522752}],"con":true,"img":false}]}
{"op":"mcm","clk":"5348934364","pt":1646222137803,"mc":[{"id":"1.195453760","rc":[{"atl":[[32,3.23],[36,0]],"id":522751},{"atl":[[670,2.09],[730,2]],"id":522741},{"atl":[[170,8.84],[180,2]],"id":7607472},{"atb":[[8,0],[10,11.11]],"id":3805731},{"atb":[[10,0],[8.8,12.82]],"id":522742}],"con":true,"img":false}]}
{"op":"mcm","clk":"5348934371","pt":1646222137920,"mc":[{"id":"1.195453760","rc":[{"atl":[[170,0]],"id":7607472},{"atb":[[34,9.76]],"id":522746}],"con":true,"img":false}]}
{"op":"mcm","clk":"5348934393","pt":1646222138113,"mc":[{"id":"1.195453760","rc":[{"atb":[[16,13.29]],"id":3805783},{"atl":[[32,9.9],[25,6.43],[27,4.95],[29,0]],"id":3805783},{"atb":[[7.4,35.34],[7.8,0],[6.6,3.27],[7,4.95]],"id":3805746},{"atl":[[12.5,9.9],[9.4,0]],"id":3805793},{"atl":[[70,0],[75,4.95],[90,15.81],[95,9.9]],"id":3805736},{"atl":[[150,1.06],[160,4.95]],"id":522749},{"atb":[[11,0],[13.5,0]],"id":522751},{"atb":[[18.5,32.89],[19,9.9],[21,11.2],[22,4.95]],"id":3805730},{"atb":[[85,0],[110,1.45]],"id":522741},{"atl":[[240,0]],"id":522741},{"atl":[[70,0]],"id":3805740},{"atb":[[32,18.49],[34,4.95],[27,0],[28,14.84]],"id":7607472},{"atb":[[48,6.09]],"id":522745},{"atl":[[23,7.2],[24,4.95],[27,0],[28,9.9]],"id":3805784},{"atb":[[17.5,0],[18,17.74],[19.5,20.78],[20,4.95]],"id":522755},{"atb":[[21,10.65]],"id":3805731},{"atl":[[34,9.76]],"id":3805731},{"atb":[[16.5,2.72],[14.5,4.95],[15.5,0]],"id":522752},{"atl":[[32,0],[28,4.95]],"id":522752},{"atb":[[23,0]],"id":522742}],"con":true,"img":false}]}
{"op":"mcm","clk":"5348934409","pt":1646222138314,"mc":[{"id":"1.195453760","rc":[{"atb":[[90,9.9],[120,4.95]],"id":522741},{"atl":[[250,4.95]],"id":522741},{"atb":[[5.6,56.72],[6.8,0]],"id":3805747},{"atl":[[12.5,0],[9.4,4.95]],"id":3805747}],"con":true,"img":false}]}
{"op":"mcm","clk":"5348934415","pt":1646222138370,"mc":[{"id":"1.195453760","rc":[{"atl":[[34,40.72],[85,2]],"id":522752}],"con":true,"img":false}]}
{"op":"mcm","clk":"5348934423","pt":1646222138479,"mc":[{"id":"1.195453760","rc":[{"atl":[[18,0],[15.5,6.9]],"id":3805747},{"atl":[[65,2],[85,0]],"id":522752}],"con":true,"img":false}]}
{"op":"mcm","clk":"5348934430","pt":1646222138583,"mc":[{"id":"1.195453760","rc":[{"atl":[[32,34.19],[75,2]],"id":3805783},{"atb":[[7.4,0],[7,48.47]],"id":3805746},{"atl":[[10.5,9.9],[12.5,87.26]],"id":3805793},{"atb":[[10,12.31],[5.7,75.93]],"id":522751},{"atb":[[18.5,0],[21,25.91]],"id":3805730},{"atb":[[75,0]],"id":522741},{"atl":[[670,0]],"id":522741},{"atl":[[85,27.65]],"id":3805740},{"atb":[[32,5.11],[34,14.67]],"id":7607472},{"atl":[[90,2],[28,39.36]],"id":3805784},{"atb":[[19.5,8.56],[20,17.17]],"id":522755},{"atl":[[50,8.19]],"id":522755}],"con":true,"img":false}]}
{"op":"mcm","clk":"5348934437","pt":1646222138684,"mc":[{"id":"1.195453760","rc":[{"atb":[[70,10.73]],"id":522741},{"atl":[[730,4.06]],"id":522741},{"atb":[[29,0]],"id":522746},{"atb":[[14.5,27.04],[15,0]],"id":522752},{"atb":[[20,29.35],[21,4.95]],"id":522742}],"con":true,"img":false}]}
{"op":"mcm","clk":"5348934447","pt":1646222138794,"mc":[{"id":"1.195453760","rc":[{"atl":[[440,0]],"id":3805783},{"atb":[[10.5,3.27],[13,2.72]],"id":522751},{"atb":[[130,1.23]],"id":522741},{"atl":[[9.2,19.33]],"id":3805747},{"atl":[[32,5.11]],"id":522752}],"con":true,"img":false}]}
{"op":"mcm","clk":"5348934452","pt":1646222138913,"mc":[{"id":"1.195453760","rc":[{"atb":[[7.4,24.77]],"id":3805746},{"atb":[[48,2.72]],"id":522745},{"atl":[[40,0]],"id":3805731},{"atb":[[15,11.32]],"id":522752}],"con":true,"img":false}]}
{"op":"mcm","clk":"5348934472","pt":1646222139096,"mc":[{"id":"1.195453760","rc":[{"atb":[[5.6,12.63],[5.1,42.88]],"id":3805747},{"atl":[[17.5,0],[15.5,46.51]],"id":3805747},{"atl":[[18,18.82],[38,14.91]],"id":3805772}],"con":true,"img":false}]}
{"op":"mcm","clk":"5348934484","pt":1646222139207,"mc":[{"id":"1.195453760","rc":[{"atb":[[22,24.59],[28,9.9]],"id":522746}],"con":true,"img":false}]}
{"op":"mcm","clk":"5348934492","pt":1646222139309,"mc":[{"id":"1.195453760","rc":[{"atb":[[5.7,21.28]],"id":522751},{"atl":[[60,0]],"id":522755}],"con":true,"img":false}]}
{"op":"mcm","clk":"5348934502","pt":1646222139412,"mc":[{"id":"1.195453760","rc":[{"atl":[[42,9.9],[100,17.1]],"id":3805731}],"con":true,"img":false}]}
{"op":"mcm","clk":"5348934520","pt":1646222139573,"mc":[{"id":"1.195453760","rc":[{"atb":[[110,0]],"id":522741},{"atb":[[44,8.64]],"id":522745},{"atl":[[10.5,4.95]],"id":3805747}],"con":true,"img":false}]}
{"op":"mcm","clk":"5348934532","pt":1646222139679,"mc":[{"id":"1.195453760","rc":[{"atl":[[130,11.62]],"id":522748}],"con":true,"img":false}]}
{"op":"mcm","clk":"5348934545","pt":1646222139888,"mc":[{"id":"1.195453760","rc":[{"atl":[[70,9.9],[85,19.03]],"id":522755}],"con":true,"img":false}]}
{"op":"mcm","clk":"5348934745","pt":1646222142621,"mc":[{"id":"1.195453760","rc":[{"atb":[[12.5,0]],"id":3805771}],"con":true,"img":false}]}
{"op":"mcm","clk":"5348934764","pt":1646222142879,"mc":[{"id":"1.195453760","rc":[{"atb":[[10,4.95]],"id":3805771}],"con":true,"img":false}]}
{"op":"mcm","clk":"5348934771","pt":1646222142988,"mc":[{"id":"1.195453760","rc":[{"atl":[[16,0],[16.5,4.95],[18,8.91],[18.5,9.9]],"id":3805772}],"con":true,"img":false}]}
{"op":"mcm","clk":"5348934782","pt":1646222143190,"mc":[{"id":"1.195453760","rc":[{"atl":[[1000,0]],"id":522754},{"atl":[[18.5,5.71],[13.5,0]],"id":3805793},{"atl":[[520,2],[400,3.71]],"id":522749},{"atl":[[32,0],[40,2.56]],"id":522751},{"atl":[[130,2],[85,0]],"id":3805730},{"atl":[[730,2.06],[920,2]],"id":522741},{"atb":[[9.2,72.43],[9.8,16.42]],"id":3805771},{"atl":[[180,0],[240,2]],"id":7607472},{"atl":[[270,5.36],[360,2]],"id":522745},{"atl":[[530,2],[410,0]],"id":3805755},{"atl":[[320,0],[420,2]],"id":522748},{"atl":[[440,0],[510,2]],"id":522750},{"atl":[[370,3.79],[480,2]],"id":3805762}],"con":true,"img":false}]}
{"op":"mcm","clk":"5348934786","pt":1646222143289,"mc":[{"id":"1.195453760","rc":[{"atb":[[10,22.56]],"id":3805771}],"con":true,"img":false}]}
{"op":"mcm","clk":"5348934807","pt":1646222143602,"mc":[{"id":"1.195453760","rc":[{"atb":[[14,2.72]],"id":3805771}],"con":true,"img":false}]}
{"op":"mcm","clk":"5348934816","pt":1646222143703,"mc":[{"id":"1.195453760","rc":[{"atb":[[11.5,3.27]],"id":3805771},{"atl":[[16.5,0],[18.5,0]],"id":3805772}],"con":true,"img":false}]}
{"op":"mcm","clk":"5348934833","pt":1646222143909,"mc":[{"id":"1.195453760","rc":[{"atl":[[1000,2]],"id":522754},{"atl":[[18.5,0],[15,7.14]],"id":3805793},{"atl":[[520,0],[410,2]],"id":522749},{"atl":[[130,0],[95,2]],"id":3805730},{"atl":[[280,2],[360,0]],"id":522745},{"atl":[[530,0],[420,2]],"id":3805755},{"atl":[[330,2],[420,0]],"id":522748},{"atl":[[400,2],[510,0]],"id":522750},{"atl":[[380,2],[480,0]],"id":3805762}],"con":true,"img":false}]}
{"op":"mcm","clk":"5348934841","pt":1646222144016,"mc":[{"id":"1.195453760","rc":[{"atl":[[32,3.23],[40,0]],"id":522751},{"atl":[[730,4.06],[920,0]],"id":522741},{"atb":[[9.8,0]],"id":3805771}],"con":true,"img":false}]}
{"op":"mcm","clk":"5348934859","pt":1646222144379,"mc":[{"id":"1.195453760","rc":[{"atl":[[150,9.72]],"id":7607472},{"atl":[[28,10.82]],"id":522752}],"con":true,"img":false}]}
{"op":"mcm","clk":"5348934864","pt":1646222144479,"mc":[{"id":"1.195453760","rc":[{"atl":[[180,2],[240,0]],"id":7607472}],"con":true,"img":false}]}
{"op":"mcm","clk":"5348934870","pt":1646222144724,"mc":[{"id":"1.195453760","rc":[{"atl":[[16,4.95],[18,18.82]],"id":3805772}],"con":true,"img":false}]}
{"op":"mcm","clk":"5348934898","pt":1646222145093,"mc":[{"id":"1.195453760","rc":[{"atl":[[32,0],[28,4.95]],"id":522752}],"con":true,"img":false}]}
{"op":"mcm","clk":"5348934947","pt":1646222145716,"mc":[{"id":"1.195453760","rc":[{"atl":[[65,25.51],[34,9.9]],"id":522752}],"con":true,"img":false}]}
{"op":"mcm","clk":"5348934967","pt":1646222145979,"mc":[{"id":"1.195453760","rc":[{"atl":[[32,5.11]],"id":522752}],"con":true,"img":false}]}
{"op":"mcm","clk":"5348934992","pt":1646222146286,"mc":[{"id":"1.195453760","rc":[{"atl":[[16,15.52]],"id":3805772}],"con":true,"img":false}]}
{"op":"mcm","clk":"5348935017","pt":1646222146710,"mc":[{"id":"1.195453760","rc":[{"atl":[[130,0],[330,6.63]],"id":522748}],"con":true,"img":false}]}
{"op":"mcm","clk":"5348935033","pt":1646222147022,"mc":[{"id":"1.195453760","rc":[{"atl":[[18,9.9]],"id":3805772}],"con":true,"img":false}]}
{"op":"mcm","clk":"5348935062","pt":1646222147401,"mc":[{"id":"1.195453760","rc":[{"atl":[[330,2]],"id":522748}],"con":true,"img":false}]}
{"op":"mcm","clk":"5348935111","pt":1646222148112,"mc":[{"id":"1.195453760","rc":[{"atb":[[65,0]],"id":522749}],"con":true,"img":false}]}
{"op":"mcm","clk":"5348935154","pt":1646222148783,"mc":[{"id":"1.195453760","rc":[{"atb":[[40,15.61],[46,9.9]],"id":522749}],"con":true,"img":false}]}
{"op":"mcm","clk":"5348935174","pt":1646222149090,"mc":[{"id":"1.195453760","rc":[{"atb":[[65,2.47]],"id":522749}],"con":true,"img":false}]}
{"op":"mcm","clk":"5348935223","pt":1646222149916,"mc":[{"id":"1.195453760","rc":[{"atb":[[65,0]],"id":522749}],"con":true,"img":false}]}
{"op":"mcm","clk":"5348935273","pt":1646222150595,"mc":[{"id":"1.195453760","rc":[{"atb":[[60,7.64]],"id":522749}],"con":true,"img":false}]}
{"op":"mcm","clk":"5348935315","pt":1646222151242,"mc":[{"id":"1.195453760","rc":[{"atl":[[150,0],[180,10.57]],"id":7607472},{"atl":[[28,10.82]],"id":522752}],"con":true,"img":false}]}
{"op":"mcm","clk":"5348935369","pt":1646222151897,"mc":[{"id":"1.195453760","rc":[{"atb":[[48,6.09]],"id":522745}],"con":true,"img":false}]}
{"op":"mcm","clk":"5348935391","pt":1646222152199,"mc":[{"id":"1.195453760","rc":[{"atl":[[32,0],[65,2],[34,40.72],[28,4.95]],"id":522752}],"con":true,"img":false}]}
{"op":"mcm","clk":"5348935402","pt":1646222152304,"mc":[{"id":"1.195453760","rc":[{"atb":[[10,28.73]],"id":522751}],"con":true,"img":false}]}
{"op":"mcm","clk":"5348935420","pt":1646222152513,"mc":[{"id":"1.195453760","rc":[{"atb":[[70,4.65],[90,23.29]],"id":522741}],"con":true,"img":false}]}
{"op":"mcm","clk":"5348935435","pt":1646222152718,"mc":[{"id":"1.195453760","rc":[{"atb":[[44,4.95],[48,2.72]],"id":522745}],"con":true,"img":false}]}
{"op":"mcm","clk":"5348935441","pt":1646222152822,"mc":[{"id":"1.195453760","rc":[{"atl":[[10.5,52.47],[15.5,6.9]],"id":3805747}],"con":true,"img":false}]}
{"op":"mcm","clk":"5348935450","pt":1646222152922,"mc":[{"id":"1.195453760","rc":[{"atl":[[32,5.11]],"id":522752}],"con":true,"img":false}]}
{"op":"mcm","clk":"5348935454","pt":1646222153024,"mc":[{"id":"1.195453760","rc":[{"atl":[[34,9.9]],"id":522752}],"con":true,"img":false}]}
{"op":"mcm","clk":"5348935462","pt":1646222153230,"mc":[{"id":"1.195453760","rc":[{"atl":[[25,6.6],[26,4.95],[29,0],[30,9.9]],"id":3805771},{"atl":[[16,0],[16.5,4.95],[18,0],[18.5,9.9]],"id":3805772}],"con":true,"img":false}]}
{"op":"mcm","clk":"5348935483","pt":1646222153492,"mc":[{"id":"1.195453760","rc":[{"atl":[[25,0]],"id":3805771},{"atb":[[42,18.58]],"id":522745},{"atl":[[130,11.92]],"id":522748}],"con":true,"img":false}]}
{"op":"mcm","clk":"5348935500","pt":1646222153698,"mc":[{"id":"1.195453760","rc":[{"atl":[[44,0]],"id":3805771}],"con":true,"img":false}]}
{"op":"mcm","clk":"5348935508","pt":1646222153818,"mc":[{"id":"1.195453760","rc":[{"atl":[[30,27.09]],"id":3805771}],"con":true,"img":false}]}
{"op":"mcm","clk":"5348935517","pt":1646222153920,"mc":[{"id":"1.195453760","rc":[{"atl":[[16.5,0],[18.5,8.91]],"id":3805772}],"con":true,"img":false}]}
{"op":"mcm","clk":"5348935543","pt":1646222154215,"mc":[{"id":"1.195453760","rc":[{"atl":[[29,5.66]],"id":3805771}],"con":true,"img":false}]}
{"op":"mcm","clk":"5348935569","pt":1646222154526,"mc":[{"id":"1.195453760","rc":[{"atl":[[38,2.7],[19.5,26.51]],"id":3805772}],"con":true,"img":false}]}
{"op":"mcm","clk":"5348935593","pt":1646222154893,"mc":[{"id":"1.195453760","rc":[{"atl":[[16,4.95],[18,9.9]],"id":3805772}],"con":true,"img":false}]}
{"op":"mcm","clk":"5348935608","pt":1646222155208,"mc":[{"id":"1.195453760","rc":[{"atl":[[19.5,0]],"id":3805772}],"con":true,"img":false}]}
{"op":"mcm","clk":"5348935738","pt":1646222156906,"mc":[{"id":"1.195453760","rc":[{"atb":[[10,38.34],[9.2,26.14]],"id":3805771},{"atl":[[16,0],[16.5,4.95],[18,0],[18.5,18.82]],"id":3805772}],"con":true,"img":false}]}
{"op":"mcm","clk":"5348935806","pt":1646222158112,"mc":[{"id":"1.195453760","rc":[{"atb":[[6.4,4.95],[5.8,9.9],[5.5,0],[5.9,0]],"id":3805793},{"atl":[[70,22.08],[75,0],[50,8.19],[55,0]],"id":3805730},{"atl":[[25,4.95],[26,0],[29,15.57],[30,17.18]],"id":3805771},{"atl":[[150,10.42],[180,2]],"id":7607472},{"atl":[[140,9.9],[100,6.55],[110,0]],"id":522745},{"atb":[[10,0],[10.5,9.9],[12,17.14],[12.5,4.95]],"id":3805784},{"atl":[[150,4.95],[180,0]],"id":522750},{"atl":[[34,0],[24,4.95],[28,10.82]],"id":522752},{"atb":[[36,14.71],[42,9.9],[44,0],[50,4.95]],"id":3805762},{"atl":[[70,9.9],[80,0],[50,4.95],[60,2.68]],"id":522742},{"atb":[[10,4.95],[8.4,0]],"id":3805772}],"con":true,"img":false}]}
{"op":"mcm","clk":"5348935832","pt":1646222158320,"mc":[{"id":"1.195453760","rc":[{"atl":[[34,0],[25,4.95],[28,0],[29,9.9]],"id":522751},{"atl":[[95,2],[110,0]],"id":522742}],"con":true,"img":false}]}
{"op":"mcm","clk":"5348935843","pt":1646222158527,"mc":[{"id":"1.195453760","rc":[{"atb":[[5.6,2.72],[5.8,54.85]],"id":3805793},{"atl":[[70,9.9]],"id":3805730},{"atb":[[10.5,35.35],[12.5,18.74],[9.8,3.27]],"id":3805784},{"atl":[[140,1.22]],"id":522750},{"atb":[[42,22.91],[50,8.19]],"id":3805762},{"atl":[[70,24.62],[50,8.19],[100,0]],"id":522742},{"atb":[[9.2,24.29],[9.8,15.48]],"id":3805772}],"con":true,"img":false}]}
{"op":"mcm","clk":"5348935851","pt":1646222158626,"mc":[{"id":"1.195453760","rc":[{"atb":[[6.6,28.31]],"id":3805793},{"atl":[[95,18.47]],"id":3805730},{"atb":[[36,0]],"id":3805762}],"con":true,"img":false}]}
{"op":"mcm","clk":"5348935861","pt":1646222158733,"mc":[{"id":"1.195453760","rc":[{"atb":[[10,9.9],[10.5,25.44],[12,22.09],[12.5,13.78]],"id":3805784},{"atl":[[32,0]],"id":522752},{"atl":[[70,14.71],[75,9.9],[50,3.23],[55,4.95]],"id":522742},{"atl":[[16.5,0],[16,4.95],[18.5,8.91],[18,9.9]],"id":3805772}],"con":true,"img":false}]}
{"op":"mcm","clk":"5348935866","pt":1646222158834,"mc":[{"id":"1.195453760","rc":[{"atl":[[29,26.33]],"id":522751}],"con":true,"img":false}]}
{"op":"mcm","clk":"5348935872","pt":1646222158940,"mc":[{"id":"1.195453760","rc":[{"atl":[[30,0]],"id":522751}],"con":true,"img":false}]}
{"op":"mcm","clk":"5348935877","pt":1646222159040,"mc":[{"id":"1.195453760","rc":[{"atl":[[25,0],[26,4.95],[29,16.42],[30,9.9]],"id":522751},{"atl":[[170,10.14],[220,0]],"id":522750}],"con":true,"img":false}]}
{"op":"mcm","clk":"5348935891","pt":1646222159204,"mc":[{"id":"1.195453760","rc":[{"atb":[[12,7.67],[12.5,0]],"id":3805784},{"atl":[[170,9.21]],"id":522750},{"atb":[[46,0]],"id":3805762}],"con":true,"img":false}]}
{"op":"mcm","clk":"5348935900","pt":1646222159309,"mc":[{"id":"1.195453760","rc":[{"atb":[[6,0]],"id":3805793},{"atl":[[65,25.44]],"id":522752},{"atl":[[50,0],[60,0]],"id":522742}],"con":true,"img":false}]}
{"op":"mcm","clk":"5348935922","pt":1646222159515,"mc":[{"id":"1.195453760","rc":[{"atl":[[26,11.29]],"id":522751}],"con":true,"img":false}]}
{"op":"mcm","clk":"5348935931","pt":1646222159625,"mc":[{"id":"1.195453760","rc":[{"atl":[[16,0],[16.5,4.95],[18,0],[18.5,18.82]],"id":3805772}],"con":true,"img":false}]}
{"op":"mcm","clk":"5348935944","pt":1646222159722,"mc":[{"id":"1.195453760","rc":[{"atl":[[26,6.34],[30,0]],"id":522751},{"atb":[[70,2.29],[80,4.95],[50,0],[60,9.9]],"id":3805755}],"con":true,"img":false}]}
{"op":"mcm","clk":"5348935965","pt":1646222159928,"mc":[{"id":"1.195453760","rc":[{"atl":[[27,11.05]],"id":522751},{"atl":[[65,9.9],[70,0],[48,4.95],[50,3.23]],"id":522755},{"atl":[[16,10.56]],"id":3805772}],"con":true,"img":false}]}
{"op":"mcm","clk":"5348935975","pt":1646222160043,"mc":[{"id":"1.195453760","rc":[{"atb":[[10.5,42.13]],"id":3805784},{"atl":[[65,2.47]],"id":522742}],"con":true,"img":false}]}
{"op":"mcm","clk":"5348935986","pt":1646222160140,"mc":[{"id":"1.195453760","rc":[{"atl":[[12,0],[12.5,4.95],[14,0],[14.5,9.9]],"id":3805746},{"atl":[[270,0]],"id":522754},{"atb":[[6.4,0],[5.8,44.94],[6.6,0],[5.9,4.95]],"id":3805793},{"atl":[[29,0]],"id":522751},{"atl":[[70,0],[80,9.9],[50,0],[60,4.95]],"id":3805730},{"atl":[[220,0]],"id":522741},{"atb":[[18,9.9],[19,0],[20,4.95],[22,0]],"id":3805740},{"atl":[[36,9.9],[25,0]],"id":3805771},{"atl":[[130,0],[160,4.95]],"id":7607472},{"atl":[[140,0],[150,9.9],[100,0],[110,4.95]],"id":522745},{"atb":[[12,2.72]],"id":3805784},{"atl":[[50,0]],"id":522755},{"atb":[[38,0],[60,24.62]],"id":3805755},{"atl":[[130,4.95],[330,6.74],[110,0]],"id":522748},{"atl":[[65,7.43],[75,0],[85,9.9],[55,0]],"id":522742}],"con":true,"img":false}]}
{"op":"mcm","clk":"5348935996","pt":1646222160244,"mc":[{"id":"1.195453760","rc":[{"atb":[[85,1.88]],"id":3805755}],"con":true,"img":false}]}
{"op":"mcm","clk":"5348936015","pt":1646222160405,"mc":[{"id":"1.195453760","rc":[{"atl":[[65,22.12],[85,2]],"id":522755}],"con":true,"img":false}]}
{"op":"mcm","clk":"5348936028","pt":1646222160506,"mc":[{"id":"1.195453760","rc":[{"atl":[[26,0],[27,4.95]],"id":522751}],"con":true,"img":false}]}
{"op":"mcm","clk":"5348936041","pt":1646222160608,"mc":[{"id":"1.195453760","rc":[{"atl":[[730,2]],"id":522741},{"atl":[[36,47.78],[30,0]],"id":3805771}],"con":true,"img":false}]}
{"op":"mcm","clk":"5348936047","pt":1646222160709,"mc":[{"id":"1.195453760","rc":[{"atl":[[65,12.21],[70,9.9],[48,0],[50,4.95]],"id":522755},{"atl":[[18.5,9.9]],"id":3805772}],"con":true,"img":false}]}
{"op":"mcm","clk":"5348936056","pt":1646222160823,"mc":[{"id":"1.195453760","rc":[{"atl":[[29,5.66]],"id":3805746},{"atl":[[280,4.95],[990,0.15]],"id":522754},{"atb":[[5.8,67.03]],"id":3805793},{"atl":[[75,2.14]],"id":3805730},{"atl":[[250,5.59]],"id":522741},{"atb":[[18,0],[20,0]],"id":3805740},{"atl":[[130,4.95],[140,1.13],[160,0]],"id":7607472},{"atl":[[260,0.61]],"id":522745},{"atl":[[130,0],[320,0.49],[120,4.95]],"id":522748}],"con":true,"img":false}]}
{"op":"mcm","clk":"5348936067","pt":1646222160928,"mc":[{"id":"1.195453760","rc":[{"atb":[[18,9.32]],"id":3805740}],"con":true,"img":false}]}
{"op":"mcm","clk":"5348936077","pt":1646222161030,"mc":[{"id":"1.195453760","rc":[{"atl":[[840,2],[1000,0]],"id":522754},{"atb":[[14,0],[14.5,10.68]],"id":3805740},{"atb":[[70,0]],"id":3805755}],"con":true,"img":false}]}
{"op":"mcm","clk":"5348936085","pt":1646222161127,"mc":[{"id":"1.195453760","rc":[{"atl":[[50,8.19]],"id":522755}],"con":true,"img":false}]}
{"op":"mcm","clk":"5348936095","pt":1646222161235,"mc":[{"id":"1.195453760","rc":[{"atl":[[30,0]],"id":3805746},{"atl":[[840,0],[990,2.15],[1000,1.56]],"id":522754},{"atl":[[30,5.46]],"id":522751},{"atb":[[9.8,0],[13,8.33]],"id":522745},{"atb":[[8.6,13.16],[10,0]],"id":3805731}],"con":true,"img":false}]}
{"op":"mcm","clk":"5348936104","pt":1646222161337,"mc":[{"id":"1.195453760","rc":[{"atl":[[29,28.8]],"id":3805746},{"atb":[[17.5,0],[14.5,22.89]],"id":3805740},{"atl":[[260,6.65],[270,0]],"id":522745}],"con":true,"img":false}]}
{"op":"mcm","clk":"5348936113","pt":1646222161440,"mc":[{"id":"1.195453760","rc":[{"atb":[[85,0]],"id":3805755}],"con":true,"img":false}]}
{"op":"mcm","clk":"5348936122","pt":1646222161542,"mc":[{"id":"1.195453760","rc":[{"atb":[[19,9.9],[22,4.95]],"id":3805740}],"con":true,"img":false}]}
{"op":"mcm","clk":"5348936179","pt":1646222162326,"mc":[{"id":"1.195453760","rc":[{"atb":[[80,6.95]],"id":3805755}],"con":true,"img":false}]}
{"op":"mcm","clk":"5348936205","pt":1646222162618,"mc":[{"id":"1.195453760","rc":[{"atl":[[130,0],[140,6.09]],"id":7607472},{"atl":[[70,0],[75,9.9],[50,0],[55,4.95]],"id":522755}],"con":true,"img":false}]}
{"op":"mcm","clk":"5348936213","pt":1646222162723,"mc":[{"id":"1.195453760","rc":[{"atl":[[180,0],[190,2]],"id":7607472},{"atl":[[85,0],[100,2]],"id":522755},{"atl":[[150,2],[210,0]],"id":522746}],"con":true,"img":false}]}
{"op":"mcm","clk":"5348936229","pt":1646222162932,"mc":[{"id":"1.195453760","rc":[{"atb":[[40,14.71],[30,0]],"id":522748}],"con":true,"img":false}]}
{"op":"mcm","clk":"5348936235","pt":1646222163040,"mc":[{"id":"1.195453760","rc":[{"atb":[[7.6,0],[6.6,0]],"id":3805746},{"atl":[[70,4.95],[75,0],[90,25.72],[95,0]],"id":3805736},{"atl":[[150,6.01],[160,0]],"id":522749},{"atb":[[10.5,0],[13,0]],"id":522751},{"atb":[[11.5,0],[14,0]],"id":3805771},{"atb":[[34,4.8],[26,9.9],[28,0],[30,4.95]],"id":522746},{"atl":[[24,0],[25,4.95],[28,5.86],[29,9.9]],"id":522752},{"atb":[[18.5,0],[19,9.9],[21,0],[22,4.95]],"id":522742}],"con":true,"img":false}]}
{"op":"mcm","clk":"5348936256","pt":1646222163247,"mc":[{"id":"1.195453760","rc":[{"atb":[[26,9.06]],"id":3805730},{"atl":[[34,4.8],[40,4.95],[42,0],[48,9.9]],"id":3805731}],"con":true,"img":false}]}
{"op":"mcm","clk":"5348936262","pt":1646222163352,"mc":[{"id":"1.195453760","rc":[{"atl":[[11.5,4.95],[12.5,0],[13.5,9.9],[14.5,0]],"id":3805746},{"atl":[[280,0],[290,4.95]],"id":522754},{"atl":[[60,2.68]],"id":522755}],"con":true,"img":false}]}
{"op":"mcm","clk":"5348936287","pt":1646222163514,"mc":[{"id":"1.195453760","rc":[{"atb":[[4.6,105.89],[7,4.95]],"id":3805746},{"atb":[[10,12.31],[5.7,61.03]],"id":522751},{"atb":[[150,1.06],[160,4.95],[110,0],[120,9.9]],"id":522753},{"atb":[[5.6,153.77],[10,22.56]],"id":3805771}],"con":true,"img":false}]}
{"op":"mcm","clk":"5348936294","pt":1646222163613,"mc":[{"id":"1.195453760","rc":[{"atl":[[400,0],[410,5.84]],"id":522749},{"atb":[[22,2.72],[26,24.62]],"id":522746},{"atb":[[32,3.27],[42,12.63]],"id":522748}],"con":true,"img":false}]}
{"op":"mcm","clk":"5348936304","pt":1646222163718,"mc":[{"id":"1.195453760","rc":[{"atb":[[6.8,3.27],[7.8,2.72]],"id":3805746},{"atb":[[10,15.58],[12.5,2.72]],"id":522751},{"atb":[[11,3.27],[13.5,2.72]],"id":3805771},{"atl":[[48,36.85],[100,2]],"id":3805731},{"atl":[[29,15.57]],"id":522752}],"con":true,"img":false}]}
{"op":"mcm","clk":"5348936317","pt":1646222163821,"mc":[{"id":"1.195453760","rc":[{"atb":[[70,4.95],[46,0],[50,9.9],[60,2.68]],"id":522749}],"con":true,"img":false}]}
{"op":"mcm","clk":"5348936326","pt":1646222163926,"mc":[{"id":"1.195453760","rc":[{"atl":[[95,16.47],[120,2]],"id":3805730},{"atb":[[19,0],[19.5,9.9],[22,0],[23,4.95]],"id":3805740},{"atl":[[150,2],[200,0]],"id":3805740},{"atl":[[13.5,8],[15.5,0]],"id":3805747},{"atb":[[9.8,11.36],[8.8,0]],"id":522742}],"con":true,"img":false}]}
{"op":"mcm","clk":"5348936337","pt":1646222164031,"mc":[{"id":"1.195453760","rc":[{"atl":[[300,4.95]],"id":522754},{"atl":[[32,0],[34,3.03]],"id":522751},{"atb":[[21,17.98]],"id":3805730},{"atb":[[70,0],[170,0.93],[120,18.84]],"id":522753}],"con":true,"img":false}]}
{"op":"mcm","clk":"5348936347","pt":1646222164137,"mc":[{"id":"1.195453760","rc":[{"atb":[[7.2,4.95],[7,0]],"id":3805746},{"atl":[[290,0]],"id":522754},{"atl":[[260,4.95],[250,0.63]],"id":522741},{"atb":[[32,4.95],[26,14.71],[27,9.9],[30,0]],"id":522746},{"atl":[[40,0],[48,26.95]],"id":3805731},{"atb":[[14.5,22.08],[15,16.27]],"id":522752},{"atl":[[130,0],[120,6.74]],"id":3805762},{"atb":[[25,9.33]],"id":522742},{"atb":[[10,0],[9.2,19.33],[9.4,4.95]],"id":3805772}],"con":true,"img":false}]}
{"op":"mcm","clk":"5348936356","pt":1646222164240,"mc":[{"id":"1.195453760","rc":[{"atb":[[4.6,27.78]],"id":3805746},{"atl":[[10.5,0],[11.5,9.9],[12.5,77.35],[9.8,4.95]],"id":3805793},{"atb":[[70,7.25],[40,2.72]],"id":522749},{"atl":[[38,4.95],[46,9.9]],"id":3805731}],"con":true,"img":false}]}
{"op":"mcm","clk":"5348936365","pt":1646222164346,"mc":[{"id":"1.195453760","rc":[{"atb":[[50,27.26]],"id":522749},{"atb":[[42,2.72],[44,9.9],[50,3.23],[55,4.95]],"id":522748},{"atb":[[65,9.9],[80,2],[85,4.95],[60,0]],"id":522750},{"atb":[[21,2.72]],"id":3805731},{"atl":[[34,0]],"id":3805731}],"con":true,"img":false}]}
{"op":"mcm","clk":"5348936372","pt":1646222164448,"mc":[{"id":"1.195453760","rc":[{"atl":[[70,0],[75,4.95],[90,15.81],[95,9.9]],"id":3805736},{"atl":[[29,9.9]],"id":522752}],"con":true,"img":false}]}
{"op":"mcm","clk":"5348936379","pt":1646222164514,"mc":[{"id":"1.195453760","rc":[{"atb":[[12,0],[13,9.9],[14,0],[15,4.95]],"id":3805783},{"atl":[[150,1.06],[160,4.95]],"id":522749},{"atb":[[10,17.61],[9.2,16.24],[10.5,4.95],[9.4,9.9]],"id":3805771},{"atl":[[140,0],[150,4.95],[190,10.32]],"id":7607472},{"atb":[[36,0],[40,9.9],[44,0],[48,7.67]],"id":522745}],"con":true,"img":false}]}
{"op":"mcm","clk":"5348936387","pt":1646222164609,"mc":[{"id":"1.195453760","rc":[{"atl":[[730,4.15]],"id":522741},{"atl":[[370,0],[380,6.15]],"id":3805762}],"con":true,"img":false}]}
{"op":"mcm","clk":"5348936397","pt":1646222164711,"mc":[{"id":"1.195453760","rc":[{"atl":[[300,0],[310,4.95]],"id":522754},{"atl":[[11.5,31.99],[12.5,0]],"id":3805793},{"atb":[[150,0]],"id":522753}],"con":true,"img":false}]}
{"op":"mcm","clk":"5348936406","pt":1646222164816,"mc":[{"id":"1.195453760","rc":[{"atb":[[40,0],[44,24.62],[60,2.68]],"id":522748},{"atb":[[65,24.62],[90,1.78],[30,6.17]],"id":522750},{"atl":[[130,4.95],[120,1.78]],"id":3805762},{"atb":[[25,2.72]],"id":522742}],"con":true,"img":false}]}
{"op":"mcm","clk":"5348936413","pt":1646222164917,"mc":[{"id":"1.195453760","rc":[{"atb":[[40,36.05],[42,3.86]],"id":522745},{"atb":[[16,0],[16.5,9.9],[18,3.27],[18.5,4.95]],"id":3805731}],"con":true,"img":false}]}
{"op":"mcm","clk":"5348936421","pt":1646222165026,"mc":[{"id":"1.195453760","rc":[{"atb":[[5.6,24.81],[5.8,22.08]],"id":3805793},{"atb":[[60,0]],"id":522749},{"atb":[[10,35.35],[10.5,16.68]],"id":3805784},{"atb":[[18,12.59]],"id":3805731},{"atl":[[44,3.68]],"id":3805731},{"atb":[[42,9.9],[23,18.39]],"id":3805762},{"atb":[[9.8,3.27],[9.4,27.04]],"id":3805772}],"con":true,"img":false}]}
{"op":"mcm","clk":"5348936426","pt":1646222165127,"mc":[{"id":"1.195453760","rc":[{"atl":[[70,0],[85,28.53]],"id":522742}],"con":true,"img":false}]}
{"op":"mcm","clk":"5348936431","pt":1646222165235,"mc":[{"id":"1.195453760","rc":[{"atb":[[32,5.11],[34,4.95],[27,0],[28,9.9]],"id":3805736},{"atl":[[180,0.88]],"id":7607472}],"con":true,"img":false}]}
{"op":"mcm","clk":"5348936444","pt":1646222165439,"mc":[{"id":"1.195453760","rc":[{"atl":[[65,0],[80,9.9],[85,17.75],[60,7.64]],"id":3805740},{"atb":[[48,11.05]],"id":522745},{"atl":[[65,7.43],[70,0],[85,9.9],[90,14.71]],"id":522746},{"atb":[[65,14.71],[80,6.95],[85,0]],"id":522750},{"atl":[[140,0]],"id":522750},{"atb":[[17.5,0],[18,27.31]],"id":3805731}],"con":true,"img":false}]}
{"op":"mcm","clk":"5348936450","pt":1646222165501,"mc":[{"id":"1.195453760","rc":[{"atb":[[50,0],[60,0]],"id":522748},{"atb":[[80,4.95],[90,0]],"id":522750},{"atb":[[22,12.5]],"id":522742}],"con":true,"img":false}]}
{"op":"mcm","clk":"5348936454","pt":1646222165604,"mc":[{"id":"1.195453760","rc":[{"atb":[[36,4.52],[24,0],[28,24.86]],"id":3805736},{"atl":[[65,2],[29,33.36]],"id":522752}],"con":true,"img":false}]}
{"op":"mcm","clk":"5348936467","pt":1646222165809,"mc":[{"id":"1.195453760","rc":[{"atb":[[9.2,41.63],[5.7,21.28]],"id":522751}],"con":true,"img":false}]}
{"op":"mcm","clk":"5348936473","pt":1646222165912,"mc":[{"id":"1.195453760","rc":[{"atl":[[310,0],[320,4.95]],"id":522754},{"atl":[[170,0],[400,5.95]],"id":522750}],"con":true,"img":false}]}
{"op":"mcm","clk":"5348936496","pt":1646222166223,"mc":[{"id":"1.195453760","rc":[{"atb":[[42,0]],"id":522745},{"atb":[[55,7.89]],"id":522748},{"atb":[[32,5.11]],"id":522750}],"con":true,"img":false}]}
{"op":"mcm","clk":"5348936516","pt":1646222166432,"mc":[{"id":"1.195453760","rc":[{"atb":[[32,0]],"id":3805736},{"atl":[[150,6.01]],"id":522750}],"con":true,"img":false}]}
{"op":"mcm","clk":"5348936531","pt":1646222166641,"mc":[{"id":"1.195453760","rc":[{"atl":[[320,0]],"id":522754}],"con":true,"img":false}]}
{"op":"mcm","clk":"5348936540","pt":1646222166741,"mc":[{"id":"1.195453760","rc":[{"atb":[[32,20.4]],"id":3805755},{"atl":[[400,2]],"id":522750}],"con":true,"img":false}]}
{"op":"mcm","clk":"5348936552","pt":1646222166848,"mc":[{"id":"1.195453760","rc":[{"atl":[[990,0.15],[1000,3.56]],"id":522754},{"atb":[[60,9.9]],"id":3805755}],"con":true,"img":false}]}
{"op":"mcm","clk":"5348936586","pt":1646222167215,"mc":[{"id":"1.195453760","rc":[{"atl":[[1000,2]],"id":522754},{"atl":[[36,9.9],[46,14.43]],"id":3805771}],"con":true,"img":false}]}
{"op":"mcm","clk":"5348936613","pt":1646222167770,"mc":[{"id":"1.195453760","rc":[{"atl":[[65,4.95],[80,0],[85,27.65],[60,2.68]],"id":3805740}],"con":true,"img":false}]}
{"op":"mcm","clk":"5348936625","pt":1646222167942,"mc":[{"id":"1.195453760","rc":[{"atl":[[18.5,31.99]],"id":3805772}],"con":true,"img":false}]}
{"op":"mcm","clk":"5348936640","pt":1646222168150,"mc":[{"id":"1.195453760","rc":[{"atb":[[23,0],[28,0]],"id":522755}],"con":true,"img":false}]}
{"op":"mcm","clk":"5348936690","pt":1646222168619,"mc":[{"id":"1.195453760","rc":[{"atb":[[18,48.64],[20,13.29]],"id":522755}],"con":true,"img":false}]}
{"op":"mcm","clk":"5348936721","pt":1646222168928,"mc":[{"id":"1.195453760","rc":[{"atb":[[24,3.27],[29,2.72]],"id":522755}],"con":true,"img":false}]}
{"op":"mcm","clk":"5348936737","pt":1646222169137,"mc":[{"id":"1.195453760","rc":[{"atl":[[150,0],[160,4.95]],"id":7607472},{"atl":[[75,0],[55,0],[60,7.64]],"id":522755},{"atl":[[130,4.95],[120,0]],"id":522748},{"atl":[[16,0]],"id":3805772}],"con":true,"img":false}]}
{"op":"mcm","clk":"5348936744","pt":1646222169238,"mc":[{"id":"1.195453760","rc":[{"atl":[[160,0],[180,4.95]],"id":3805755}],"con":true,"img":false}]}
{"op":"mcm","clk":"5348936751","pt":1646222169345,"mc":[{"id":"1.195453760","rc":[{"atb":[[19.5,0]],"id":522755},{"atb":[[19,0],[20,34.3],[22,7.54]],"id":522742}],"con":true,"img":false}]}
{"op":"mcm","clk":"5348936758","pt":1646222169445,"mc":[{"id":"1.195453760","rc":[{"atl":[[150,0],[160,9.9],[110,0],[120,4.95]],"id":522745},{"atb":[[5.6,2.72],[5.5,9.9],[6,0],[5.9,4.95]],"id":3805747},{"atl":[[16.5,0],[17,4.95],[18.5,22.08],[19,9.9]],"id":3805772}],"con":true,"img":false}]}
{"op":"mcm","clk":"5348936762","pt":1646222169501,"mc":[{"id":"1.195453760","rc":[{"atb":[[6.8,0],[7.8,0]],"id":3805746}],"con":true,"img":false}]}
{"op":"mcm","clk":"5348936770","pt":1646222169606,"mc":[{"id":"1.195453760","rc":[{"atl":[[65,0],[100,17.96]],"id":522755}],"con":true,"img":false}]}
{"op":"mcm","clk":"5348936784","pt":1646222169808,"mc":[{"id":"1.195453760","rc":[{"atl":[[100,2],[120,0]],"id":3805730},{"atl":[[18.5,31.14]],"id":3805772}],"con":true,"img":false}]}
{"op":"mcm","clk":"5348936790","pt":1646222169913,"mc":[{"id":"1.195453760","rc":[{"atb":[[5.5,31.99]],"id":3805747}],"con":true,"img":false}]}
{"op":"mcm","clk":"5348936800","pt":1646222170017,"mc":[{"id":"1.195453760","rc":[{"atb":[[5.1,3.27]],"id":3805747}],"con":true,"img":false}]}
{"op":"mcm","clk":"5348936813","pt":1646222170224,"mc":[{"id":"1.195453760","rc":[{"atb":[[5.6,57.91],[10.5,27.04]],"id":3805771},{"atb":[[5.5,46.71]],"id":3805747}],"con":true,"img":false}]}
{"op":"mcm","clk":"5348936822","pt":1646222170322,"mc":[{"id":"1.195453760","rc":[{"atb":[[7.6,2.72],[6.6,3.27]],"id":3805746}],"con":true,"img":false}]}
{"op":"mcm","clk":"5348936827","pt":1646222170428,"mc":[{"id":"1.195453760","rc":[{"atl":[[36,0],[38,9.9],[29,5.66],[30,4.95]],"id":3805771}],"con":true,"img":false}]}
{"op":"mcm","clk":"5348936834","pt":1646222170532,"mc":[{"id":"1.195453760","rc":[{"atl":[[29,0]],"id":3805771},{"atb":[[5.8,4.95],[5.5,36.8],[5.9,0],[5.4,9.9]],"id":3805747},{"atb":[[34,0]],"id":522746}],"con":true,"img":false}]}
{"op":"mcm","clk":"5348936858","pt":1646222170943,"mc":[{"id":"1.195453760","rc":[{"atb":[[40,18.76],[50,9.9]],"id":522749}],"con":true,"img":false}]}
{"op":"mcm","clk":"5348936884","pt":1646222171205,"mc":[{"id":"1.195453760","rc":[{"atb":[[27,16]],"id":522746}],"con":true,"img":false}]}
{"op":"mcm","clk":"5348936890","pt":1646222171309,"mc":[{"id":"1.195453760","rc":[{"atl":[[44,3.68]],"id":3805771},{"atb":[[42,20.11]],"id":522748},{"atb":[[65,0],[32,20.3]],"id":522750}],"con":true,"img":false}]}
{"op":"mcm","clk":"5348936898","pt":1646222171413,"mc":[{"id":"1.195453760","rc":[{"atb":[[44,9.9]],"id":522748}],"con":true,"img":false}]}
{"op":"mcm","clk":"5348936913","pt":1646222171617,"mc":[{"id":"1.195453760","rc":[{"atb":[[38,27.88],[40,9.9]],"id":522745},{"atl":[[85,9.9],[95,18.86]],"id":522742}],"con":true,"img":false}]}
{"op":"mcm","clk":"5348936933","pt":1646222171930,"mc":[{"id":"1.195453760","rc":[{"atb":[[5.9,37.31]],"id":3805793},{"atb":[[12,17.14]],"id":3805784}],"con":true,"img":false}]}
{"op":"mcm","clk":"5348936939","pt":1646222172029,"mc":[{"id":"1.195453760","rc":[{"atl":[[80,29.94],[95,0]],"id":3805730}],"con":true,"img":false}]}
{"op":"mcm","clk":"5348936946","pt":1646222172138,"mc":[{"id":"1.195453760","rc":[{"atl":[[34,18.51]],"id":522751}],"con":true,"img":false}]}
{"op":"mcm","clk":"5348936966","pt":1646222172446,"mc":[{"id":"1.195453760","rc":[{"atl":[[170,9.43]],"id":522750}],"con":true,"img":false}]}
{"op":"mcm","clk":"5348937000","pt":1646222172813,"mc":[{"id":"1.195453760","rc":[{"atb":[[5.8,0]],"id":3805793},{"atb":[[10.5,0]],"id":3805784}],"con":true,"img":false}]}
{"op":"mcm","clk":"5348937017","pt":1646222173021,"mc":[{"id":"1.195453760","rc":[{"atl":[[26,6.34]],"id":522751}],"con":true,"img":false}]}
{"op":"mcm","clk":"5348937035","pt":1646222173236,"mc":[{"id":"1.195453760","rc":[{"atl":[[32,3.23],[34,15.48]],"id":522751}],"con":true,"img":false}]}
{"op":"mcm","clk":"5348937046","pt":1646222173340,"mc":[{"id":"1.195453760","rc":[{"atb":[[5.6,2.72],[5.1,70.36]],"id":3805793},{"atb":[[10,9.9],[9.8,39.46]],"id":3805784},{"atl":[[17,14.86]],"id":3805772}],"con":true,"img":false}]}
{"op":"mcm","clk":"5348937082","pt":1646222173754,"mc":[{"id":"1.195453760","rc":[{"atl":[[30,0]],"id":522751}],"con":true,"img":false}]}
{"op":"mcm","clk":"5348937110","pt":1646222174018,"mc":[{"id":"1.195453760","rc":[{"atl":[[44,16.53],[46,2.22]],"id":3805771},{"atl":[[70,22.71],[100,2]],"id":522755}],"con":true,"img":false}]}
{"op":"mcm","clk":"5348937120","pt":1646222174117,"mc":[{"id":"1.195453760","rc":[{"atl":[[11.5,20.05]],"id":3805746},{"atl":[[60,7.64]],"id":3805730},{"atl":[[110,1.45]],"id":522745},{"atl":[[130,6.18]],"id":522748},{"atl":[[18.5,22.08]],"id":3805772}],"con":true,"img":false}]}
{"op":"mcm","clk":"5348937134","pt":1646222174320,"mc":[{"id":"1.195453760","rc":[{"atb":[[24,6.89]],"id":3805740},{"atl":[[170,0.93]],"id":7607472}],"con":true,"img":false}]}
{"op":"mcm","clk":"5348937145","pt":1646222174428,"mc":[{"id":"1.195453760","rc":[{"atl":[[18.5,0],[19,46.72]],"id":3805772}],"con":true,"img":false}]}
{"op":"mcm","clk":"5348937157","pt":1646222174636,"mc":[{"id":"1.195453760","rc":[{"atl":[[65,4.95],[80,20.04],[85,9.9],[60,2.68]],"id":3805730},{"atb":[[18,30.55],[14.5,10.68]],"id":3805740},{"atl":[[260,0.61],[160,19.96]],"id":522745},{"atb":[[12,2.72]],"id":3805784}],"con":true,"img":false}]}
{"op":"mcm","clk":"5348937169","pt":1646222174843,"mc":[{"id":"1.195453760","rc":[{"atl":[[180,9.8],[190,2]],"id":7607472},{"atl":[[70,0]],"id":522755},{"atl":[[320,0]],"id":522748}],"con":true,"img":false}]}
{"op":"mcm","clk":"5348937176","pt":1646222174956,"mc":[{"id":"1.195453760","rc":[{"atl":[[29,23.14]],"id":3805746},{"atl":[[75,0]],"id":3805730},{"atl":[[260,0]],"id":522745}],"con":true,"img":false}]}
{"op":"mcm","clk":"5348937186","pt":1646222175047,"mc":[{"id":"1.195453760","rc":[{"atb":[[18,21.22]],"id":3805740},{"atl":[[180,8.91]],"id":7607472}],"con":true,"img":false}]}
{"op":"mcm","clk":"5348937217","pt":1646222175415,"mc":[{"id":"1.195453760","rc":[{"atb":[[10.5,16.68]],"id":3805784},{"atl":[[150,10.74],[330,2]],"id":522748}],"con":true,"img":false}]}
{"op":"mcm","clk":"5348937306","pt":1646222176655,"mc":[{"id":"1.195453760","rc":[{"atl":[[65,0],[70,4.95],[85,0],[60,0]],"id":3805730},{"atl":[[260,0],[300,4.95],[250,0]],"id":522741},{"atl":[[1000,0]],"id":522743},{"atl":[[36,4.95],[38,0],[44,26.43],[30,0]],"id":3805771},{"atl":[[160,0],[170,0],[180,0],[190,6.95]],"id":7607472},{"atl":[[130,4.95],[160,10.06],[110,0],[120,0]],"id":522745},{"atb":[[5.8,0],[5.5,0],[5.4,0]],"id":3805747},{"atl":[[65,4.95],[85,9.9],[60,0]],"id":522755},{"atl":[[150,0],[180,0],[190,4.95]],"id":3805755},{"atb":[[32,0],[26,24.62],[27,6.09],[30,4.95]],"id":522746},{"atl":[[130,0],[150,15.7]],"id":522748},{"atb":[[14.5,27.04],[15,0]],"id":522752},{"atl":[[17,0],[18,4.95],[19,36.81],[20,9.9]],"id":3805772}],"con":true,"img":false}]}
{"op":"mcm","clk":"5348937314","pt":1646222176711,"mc":[{"id":"1.195453760","rc":[{"atb":[[7.2,49.5]],"id":3805746},{"atl":[[160,0.99]],"id":7607472},{"atb":[[5.6,17.44]],"id":3805747}],"con":true,"img":false}]}
{"op":"mcm","clk":"5348937323","pt":1646222176818,"mc":[{"id":"1.195453760","rc":[{"atl":[[46,0],[55,2]],"id":3805771},{"atl":[[95,2],[100,0]],"id":522755}],"con":true,"img":false}]}
{"op":"mcm","clk":"5348937343","pt":1646222177030,"mc":[{"id":"1.195453760","rc":[{"atl":[[46,24.62],[48,0]],"id":3805731}],"con":true,"img":false}]}
{"op":"mcm","clk":"5348937364","pt":1646222177329,"mc":[{"id":"1.195453760","rc":[{"atl":[[70,0]],"id":3805730},{"atl":[[260,4.95],[300,5.48]],"id":522741},{"atl":[[1000,0.15]],"id":522743},{"atl":[[36,0],[44,16.53]],"id":3805771},{"atl":[[190,2]],"id":7607472},{"atl":[[270,0.58]],"id":522745},{"atb":[[3.85,71.19],[5.8,4.95],[5.4,9.9]],"id":3805747},{"atl":[[80,2]],"id":522755},{"atl":[[180,4.95],[190,0.83],[200,0],[420,5.84]],"id":3805755},{"atb":[[26,14.71],[30,0]],"id":522746},{"atl":[[140,1.13]],"id":522748},{"atb":[[14,19.35],[14.5,4.95]],"id":522752},{"atl":[[19,45.62]],"id":3805772}],"con":true,"img":false}]}
{"op":"mcm","clk":"5348937369","pt":1646222177431,"mc":[{"id":"1.195453760","rc":[{"atl":[[75,2.14]],"id":3805730}],"con":true,"img":false}]}
{"op":"mcm","clk":"5348937386","pt":1646222177744,"mc":[{"id":"1.195453760","rc":[{"atl":[[180,8.99]],"id":7607472},{"atb":[[32,5.11],[30,24.3]],"id":522750}],"con":true,"img":false}]}
{"op":"mcm","clk":"5348937390","pt":1646222177848,"mc":[{"id":"1.195453760","rc":[{"atb":[[22,28.49],[26,0]],"id":522746}],"con":true,"img":false}]}
{"op":"mcm","clk":"5348937404","pt":1646222178059,"mc":[{"id":"1.195453760","rc":[{"atl":[[65,4.95],[85,9.9]],"id":3805730},{"atl":[[160,5.95]],"id":7607472},{"atb":[[32,4.95],[27,16]],"id":522746},{"atb":[[80,6.95]],"id":522750}],"con":true,"img":false}]}
{"op":"mcm","clk":"5348937410","pt":1646222178114,"mc":[{"id":"1.195453760","rc":[{"atl":[[38,9.9],[30,4.95]],"id":3805771}],"con":true,"img":false}]}
{"op":"mcm","clk":"5348937417","pt":1646222178222,"mc":[{"id":"1.195453760","rc":[{"atb":[[9.8,3.27]],"id":3805784},{"atl":[[38,9.23]],"id":3805731}],"con":true,"img":false}]}
{"op":"mcm","clk":"5348937428","pt":1646222178330,"mc":[{"id":"1.195453760","rc":[{"atb":[[10,35.35]],"id":3805784},{"atb":[[21,10.65]],"id":3805731}],"con":true,"img":false}]}
{"op":"mcm","clk":"5348937435","pt":1646222178424,"mc":[{"id":"1.195453760","rc":[{"atl":[[80,0],[100,18.21]],"id":3805730}],"con":true,"img":false}]}
{"op":"mcm","clk":"5348937467","pt":1646222178837,"mc":[{"id":"1.195453760","rc":[{"atb":[[32,0]],"id":522750}],"con":true,"img":false}]}
{"op":"mcm","clk":"5348937475","pt":1646222178939,"mc":[{"id":"1.195453760","rc":[{"atb":[[5.8,0],[5.3,9.9],[5.7,4.95],[5.4,0]],"id":3805747},{"atl":[[170,0],[400,6.04]],"id":522750}],"con":true,"img":false}]}
{"op":"mcm","clk":"5348937484","pt":1646222179041,"mc":[{"id":"1.195453760","rc":[{"atl":[[44,0]],"id":3805731}],"con":true,"img":false}]}
{"op":"mcm","clk":"5348937491","pt":1646222179151,"mc":[{"id":"1.195453760","rc":[{"atl":[[730,2.15],[790,2]],"id":522741}],"con":true,"img":false}]}
{"op":"mcm","clk":"5348937498","pt":1646222179256,"mc":[{"id":"1.195453760","rc":[{"atl":[[32,4.95],[38,0],[40,9.9],[30,0]],"id":3805771},{"atb":[[18,17.98]],"id":3805731}],"con":true,"img":false}]}
{"op":"mcm","clk":"5348937514","pt":1646222179457,"mc":[{"id":"1.195453760","rc":[{"atb":[[16.5,0],[14,16.08]],"id":522752}],"con":true,"img":false}]}
{"op":"mcm","clk":"5348937532","pt":1646222179718,"mc":[{"id":"1.195453760","rc":[{"atl":[[400,2]],"id":522750}],"con":true,"img":false}]}
{"op":"mcm","clk":"5348937554","pt":1646222180030,"mc":[{"id":"1.195453760","rc":[{"atb":[[14.5,16.69]],"id":522752}],"con":true,"img":false}]}
{"op":"mcm","clk":"5348937580","pt":1646222180445,"mc":[{"id":"1.195453760","rc":[{"atb":[[16,2.72],[13.5,3.27]],"id":522752}],"con":true,"img":false}]}
{"op":"mcm","clk":"5348937603","pt":1646222180742,"mc":[{"id":"1.195453760","rc":[{"atl":[[25,11.55]],"id":522752}],"con":true,"img":false}]}
{"op":"mcm","clk":"5348937610","pt":1646222180840,"mc":[{"id":"1.195453760","rc":[{"atb":[[5.6,0],[5.1,67.09]],"id":3805793}],"con":true,"img":false}]}
{"op":"mcm","clk":"5348937629","pt":1646222181151,"mc":[{"id":"1.195453760","rc":[{"atl":[[270,6.61],[160,0]],"id":522745},{"atl":[[19,8.8],[20,31.99]],"id":3805772}],"con":true,"img":false}]}
{"op":"mcm","clk":"5348937648","pt":1646222181414,"mc":[{"id":"1.195453760","rc":[{"atb":[[5.1,0],[4.3,122.9]],"id":3805793},{"atl":[[32,0],[34,4.95],[40,0],[42,9.9]],"id":3805771},{"atl":[[180,0],[190,10.56]],"id":7607472},{"atb":[[5.6,22.39],[5.3,0],[5.2,9.9],[5.7,0]],"id":3805747}],"con":true,"img":false}]}
{"op":"mcm","clk":"5348937673","pt":1646222181730,"mc":[{"id":"1.195453760","rc":[{"atb":[[5.2,3.27],[5.7,2.72]],"id":3805793},{"atl":[[260,0],[270,4.95],[300,0.52]],"id":522741},{"atb":[[5.6,7.67]],"id":3805747},{"atb":[[18,17.74],[20,25.51]],"id":522755},{"atl":[[25,4.95],[28,0]],"id":522752}],"con":true,"img":false}]}
{"op":"mcm","clk":"5348937680","pt":1646222181828,"mc":[{"id":"1.195453760","rc":[{"atl":[[150,4.95],[330,6.93]],"id":522748}],"con":true,"img":false}]}
{"op":"mcm","clk":"5348937715","pt":1646222182346,"mc":[{"id":"1.195453760","rc":[{"atb":[[5.6,2.72],[5.1,13.17],[5.5,4.95],[5.2,0]],"id":3805747},{"atl":[[65,27.11],[29,9.9]],"id":522752}],"con":true,"img":false}]}
{"op":"mcm","clk":"5348937745","pt":1646222182765,"mc":[{"id":"1.195453760","rc":[{"atb":[[5.2,26.14]],"id":3805747},{"atl":[[85,22.12]],"id":522755},{"atl":[[29,15.57]],"id":522752}],"con":true,"img":false}]}
{"op":"mcm","clk":"5348937765","pt":1646222183027,"mc":[{"id":"1.195453760","rc":[{"atl":[[18,14.27]],"id":3805772}],"con":true,"img":false}]}
{"op":"mcm","clk":"5348937797","pt":1646222183342,"mc":[{"id":"1.195453760","rc":[{"atb":[[5.1,40.12],[3.85,35.09]],"id":3805747}],"con":true,"img":false}]}
{"op":"mcm","clk":"5348937830","pt":1646222183758,"mc":[{"id":"1.195453760","rc":[{"atl":[[46,9.9],[100,18.35]],"id":3805731}],"con":true,"img":false}]}
{"op":"mcm","clk":"5348937854","pt":1646222184024,"mc":[{"id":"1.195453760","rc":[{"atl":[[19,0]],"id":3805772}],"con":true,"img":false}]}
{"op":"mcm","clk":"5348937862","pt":1646222184129,"mc":[{"id":"1.195453760","rc":[{"atb":[[25,21.16],[30,6.17]],"id":522750}],"con":true,"img":false}]}
{"op":"mcm","clk":"5348937883","pt":1646222184439,"mc":[{"id":"1.195453760","rc":[{"atl":[[42,13.77]],"id":3805771},{"atb":[[32,10.06]],"id":522746}],"con":true,"img":false}]}
{"op":"mcm","clk":"5348937920","pt":1646222185063,"mc":[{"id":"1.195453760","rc":[{"atl":[[85,29.2],[100,2]],"id":3805730},{"atb":[[12,17.14]],"id":3805784}],"con":true,"img":false}]}
{"op":"mcm","clk":"5348937933","pt":1646222185225,"mc":[{"id":"1.195453760","rc":[{"atl":[[32,20.01],[34,0]],"id":522751},{"atl":[[44,12.84]],"id":3805771},{"atb":[[27,9.9]],"id":522746}],"con":true,"img":false}]}
{"op":"mcm","clk":"5348937957","pt":1646222185533,"mc":[{"id":"1.195453760","rc":[{"atl":[[170,9.65]],"id":522750}],"con":true,"img":false}]}
{"op":"mcm","clk":"5348937980","pt":1646222185951,"mc":[{"id":"1.195453760","rc":[{"atb":[[10.5,0]],"id":3805784}],"con":true,"img":false}]}
{"op":"mcm","clk":"5348938006","pt":1646222186422,"mc":[{"id":"1.195453760","rc":[{"atb":[[4.3,30.3]],"id":3805793}],"con":true,"img":false}]}
{"op":"mcm","clk":"5348938027","pt":1646222186731,"mc":[{"id":"1.195453760","rc":[{"atb":[[5.2,40.84]],"id":3805793},{"atb":[[10,9.9],[9.8,39.46]],"id":3805784}],"con":true,"img":false}]}
{"op":"mcm","clk":"5348938053","pt":1646222187043,"mc":[{"id":"1.195453760","rc":[{"atb":[[12,2.72]],"id":3805784}],"con":true,"img":false}]}
{"op":"mcm","clk":"5348938085","pt":1646222187455,"mc":[{"id":"1.195453760","rc":[{"atl":[[60,2.68]],"id":3805730},{"atb":[[24,0]],"id":3805740},{"atl":[[120,1.32]],"id":522745}],"con":true,"img":false}]}
{"op":"mcm","clk":"5348938099","pt":1646222187670,"mc":[{"id":"1.195453760","rc":[{"atb":[[18,0],[19.5,27.5]],"id":3805740},{"atl":[[270,0.58],[280,7.87]],"id":522745},{"atl":[[38,28.78],[20,9.9]],"id":3805772}],"con":true,"img":false}]}
{"op":"mcm","clk":"5348938125","pt":1646222187930,"mc":[{"id":"1.195453760","rc":[{"atl":[[180,9.15],[190,2]],"id":7607472},{"atb":[[10.5,16.68]],"id":3805784}],"con":true,"img":false}]}
{"op":"mcm","clk":"5348938141","pt":1646222188246,"mc":[{"id":"1.195453760","rc":[{"atl":[[75,0]],"id":3805730},{"atb":[[20,8.34]],"id":3805740},{"atl":[[270,0]],"id":522745}],"con":true,"img":false}]}
{"op":"mcm","clk":"5348938172","pt":1646222188661,"mc":[{"id":"1.195453760","rc":[{"atl":[[60,0]],"id":3805730},{"atb":[[19.5,9.9]],"id":3805740},{"atl":[[16.5,4.95],[18,9.32],[18.5,9.9],[20,0]],"id":3805772}],"con":true,"img":false}]}
{"op":"mcm","clk":"5348938204","pt":1646222189227,"mc":[{"id":"1.195453760","rc":[{"atl":[[16.5,15.18]],"id":3805772}],"con":true,"img":false}]}
{"op":"mcm","clk":"5348938244","pt":1646222189638,"mc":[{"id":"1.195453760","rc":[{"atl":[[65,7.43]],"id":3805730}],"con":true,"img":false}]}
{"op":"mcm","clk":"5348938263","pt":1646222189953,"mc":[{"id":"1.195453760","rc":[{"atb":[[7.6,26.74]],"id":3805746},{"atb":[[5.6,37.19]],"id":3805747}],"con":true,"img":false}]}
{"op":"mcm","clk":"5348938286","pt":1646222190273,"mc":[{"id":"1.195453760","rc":[{"atl":[[18,0]],"id":3805772}],"con":true,"img":false}]}
{"op":"mcm","clk":"5348938295","pt":1646222190376,"mc":[{"id":"1.195453760","rc":[{"atb":[[5.1,13.17],[5.2,62.25]],"id":3805747},{"atl":[[60,2.68]],"id":522755},{"atl":[[180,5.84]],"id":3805755}],"con":true,"img":false}]}
{"op":"mcm","clk":"5348938331","pt":1646222190643,"mc":[{"id":"1.195453760","rc":[{"atl":[[720,0.21]],"id":522741}],"con":true,"img":false}]}
{"op":"mcm","clk":"5348938356","pt":1646222190947,"mc":[{"id":"1.195453760","rc":[{"atb":[[7.4,0]],"id":3805746},{"atb":[[5.2,36.1]],"id":3805747},{"atl":[[80,10.92],[85,9.9]],"id":522755}],"con":true,"img":false}]}
{"op":"mcm","clk":"5348938362","pt":1646222191043,"mc":[{"id":"1.195453760","rc":[{"atl":[[80,8.91]],"id":522755}],"con":true,"img":false}]}
{"op":"mcm","clk":"5348938372","pt":1646222191150,"mc":[{"id":"1.195453760","rc":[{"atl":[[190,0]],"id":3805755}],"con":true,"img":false}]}
{"op":"mcm","clk":"5348938377","pt":1646222191248,"mc":[{"id":"1.195453760","rc":[{"atl":[[85,9.9],[100,18.57]],"id":3805730},{"atl":[[720,2.51],[730,0]],"id":522741},{"atb":[[10,35.35],[9.8,3.27]],"id":3805784}],"con":true,"img":false}]}
{"op":"mcm","clk":"5348938391","pt":1646222191459,"mc":[{"id":"1.195453760","rc":[{"atb":[[7.2,4.95],[6.6,67.48]],"id":3805746},{"atl":[[720,2.29]],"id":522741}],"con":true,"img":false}]}
{"op":"mcm","clk":"5348938395","pt":1646222191564,"mc":[{"id":"1.195453760","rc":[{"atl":[[200,8.28],[420,2]],"id":3805755}],"con":true,"img":false}]}
{"op":"mcm","clk":"5348938422","pt":1646222191929,"mc":[{"id":"1.195453760","rc":[{"atl":[[170,0],[400,6.14]],"id":522750}],"con":true,"img":false}]}
{"op":"mcm","clk":"5348938445","pt":1646222192242,"mc":[{"id":"1.195453760","rc":[{"atl":[[200,0]],"id":3805755}],"con":true,"img":false}]}
{"op":"mcm","clk":"5348938487","pt":1646222192649,"mc":[{"id":"1.195453760","rc":[{"atl":[[400,2]],"id":522750}],"con":true,"img":false}]}
{"op":"mcm","clk":"5348938527","pt":1646222193169,"mc":[{"id":"1.195453760","rc":[{"atb":[[19,0],[19.5,9.9],[22,0],[23,4.95]],"id":3805730},{"atl":[[9,4.95],[9.8,9.9]],"id":3805747},{"atb":[[18,7.83],[20,20.56]],"id":522755}],"con":true,"img":false}]}
{"op":"mcm","clk":"5348938535","pt":1646222193271,"mc":[{"id":"1.195453760","rc":[{"atl":[[10.5,47.52],[9.4,0]],"id":3805747},{"atb":[[18.5,9.9],[21,4.95]],"id":522755}],"con":true,"img":false}]}
{"op":"mcm","clk":"5348938581","pt":1646222193745,"mc":[{"id":"1.195453760","rc":[{"atl":[[10.5,0],[8.8,20.32],[9.4,36.1]],"id":3805747}],"con":true,"img":false}]}
{"op":"mcm","clk":"5348938615","pt":1646222194165,"mc":[{"id":"1.195453760","rc":[{"atl":[[180,0]],"id":7607472}],"con":true,"img":false}]}
{"op":"mcm","clk":"5348938637","pt":1646222194476,"mc":[{"id":"1.195453760","rc":[{"atl":[[190,10.76]],"id":7607472},{"atl":[[9.2,0]],"id":3805747}],"con":true,"img":false}]}
{"op":"mcm","clk":"5348938662","pt":1646222194841,"mc":[{"id":"1.195453760","rc":[{"atb":[[20,8.34],[21,17.17]],"id":522755}],"con":true,"img":false}]}
{"op":"mcm","clk":"5348938864","pt":1646222197385,"mc":[{"id":"1.195453760","rc":[{"atl":[[32,5.11],[36,4.95],[44,22.74]],"id":3805771},{"atl":[[160,0],[170,4.95]],"id":7607472},{"atb":[[5.6,2.72],[5.1,3.27],[5.5,0],[5.4,4.95]],"id":3805747},{"atb":[[32,0],[26,9.9],[27,0],[30,4.95]],"id":522746},{"atl":[[16.5,0],[17.5,4.95],[18.5,0],[19.5,9.9]],"id":3805772}],"con":true,"img":false}]}
{"op":"mcm","clk":"5348938906","pt":1646222197645,"mc":[{"id":"1.195453760","rc":[{"atl":[[34,0],[42,3.86]],"id":3805771}],"con":true,"img":false}]}
{"op":"mcm","clk":"5348938926","pt":1646222197853,"mc":[{"id":"1.195453760","rc":[{"atl":[[36,19.66],[44,9.9]],"id":3805771}],"con":true,"img":false}]}
{"op":"mcm","clk":"5348938942","pt":1646222198063,"mc":[{"id":"1.195453760","rc":[{"atl":[[170,5.89]],"id":7607472},{"atb":[[12,17.14]],"id":3805784},{"atb":[[5.2,50.82]],"id":3805747},{"atb":[[27,6.09]],"id":522746}],"con":true,"img":false}]}
{"op":"mcm","clk":"5348938953","pt":1646222198168,"mc":[{"id":"1.195453760","rc":[{"atl":[[32,0],[42,0]],"id":3805771},{"atl":[[36,4.52]],"id":3805772}],"con":true,"img":false}]}
{"op":"mcm","clk":"5348938970","pt":1646222198375,"mc":[{"id":"1.195453760","rc":[{"atl":[[170,9.86]],"id":522750}],"con":true,"img":false}]}
{"op":"mcm","clk":"5348938997","pt":1646222198647,"mc":[{"id":"1.195453760","rc":[{"atb":[[22,2.72],[26,35.68]],"id":522746},{"atl":[[36,18.61],[38,2.7]],"id":3805772}],"con":true,"img":false}]}
{"op":"mcm","clk":"5348939018","pt":1646222198846,"mc":[{"id":"1.195453760","rc":[{"atl":[[32,16.78],[34,3.03]],"id":522751}],"con":true,"img":false}]}
{"op":"mcm","clk":"5348939038","pt":1646222199053,"mc":[{"id":"1.195453760","rc":[{"atl":[[36,24.19]],"id":3805771},{"atb":[[10.5,0]],"id":3805784}],"con":true,"img":false}]}
{"op":"mcm","clk":"5348939060","pt":1646222199364,"mc":[{"id":"1.195453760","rc":[{"atl":[[25,11.55]],"id":522752}],"con":true,"img":false}]}
{"op":"mcm","clk":"5348939083","pt":1646222199672,"mc":[{"id":"1.195453760","rc":[{"atb":[[10,9.9],[9.8,39.46]],"id":3805784}],"con":true,"img":false}]}
{"op":"mcm","clk":"5348939111","pt":1646222199984,"mc":[{"id":"1.195453760","rc":[{"atl":[[16.5,4.95],[17.5,0],[18.5,9.9],[19.5,0]],"id":3805772}],"con":true,"img":false}]}
{"op":"mcm","clk":"5348939133","pt":1646222200255,"mc":[{"id":"1.195453760","rc":[{"atl":[[1000,0]],"id":522754},{"atl":[[190,8.76],[200,2]],"id":7607472},{"atl":[[90,2],[95,0]],"id":522755}],"con":true,"img":false}]}
{"op":"mcm","clk":"5348939142","pt":1646222200356,"mc":[{"id":"1.195453760","rc":[{"atl":[[160,4.95]],"id":522750},{"atl":[[29,9.9]],"id":522752}],"con":true,"img":false}]}
{"op":"mcm","clk":"5348939155","pt":1646222200575,"mc":[{"id":"1.195453760","rc":[{"atl":[[340,4.95]],"id":522754},{"atb":[[19.5,29.66]],"id":3805740},{"atb":[[34,9.72],[28,4.93]],"id":7607472},{"atl":[[23,12.15],[24,0],[27,9.9],[28,29.45]],"id":3805784},{"atl":[[25,4.95]],"id":522752},{"atl":[[130,0],[140,4.95]],"id":3805762}],"con":true,"img":false}]}
{"op":"mcm","clk":"5348939162","pt":1646222200659,"mc":[{"id":"1.195453760","rc":[{"atb":[[36,8.22]],"id":7607472},{"atl":[[150,1.06]],"id":522750}],"con":true,"img":false}]}
{"op":"mcm","clk":"5348939166","pt":1646222200760,"mc":[{"id":"1.195453760","rc":[{"atl":[[190,0],[200,10.41]],"id":7607472}],"con":true,"img":false}]}
{"op":"mcm","clk":"5348939176","pt":1646222200868,"mc":[{"id":"1.195453760","rc":[{"atb":[[12,2.72]],"id":3805784},{"atl":[[170,0]],"id":522750},{"atb":[[21,2.72]],"id":3805731}],"con":true,"img":false}]}
{"op":"mcm","clk":"5348939190","pt":1646222201075,"mc":[{"id":"1.195453760","rc":[{"atl":[[330,0.47]],"id":522754},{"atb":[[23,12.15]],"id":3805740}],"con":true,"img":false}]}
{"op":"mcm","clk":"5348939196","pt":1646222201176,"mc":[{"id":"1.195453760","rc":[{"atl":[[160,0],[170,4.95]],"id":522750}],"con":true,"img":false}]}
{"op":"mcm","clk":"5348939203","pt":1646222201281,"mc":[{"id":"1.195453760","rc":[{"atb":[[130,1.23],[140,4.95],[95,0],[100,9.9]],"id":522754},{"atl":[[60,2.68]],"id":522752}],"con":true,"img":false}]}
{"op":"mcm","clk":"5348939211","pt":1646222201385,"mc":[{"id":"1.195453760","rc":[{"atl":[[16.5,0],[17.5,4.95],[18.5,0],[19.5,9.9]],"id":3805772}],"con":true,"img":false}]}
{"op":"mcm","clk":"5348939228","pt":1646222201544,"mc":[{"id":"1.195453760","rc":[{"atl":[[990,1.85]],"id":522754}],"con":true,"img":false}]}
{"op":"mcm","clk":"5348939242","pt":1646222201647,"mc":[{"id":"1.195453760","rc":[{"atb":[[60,0]],"id":522754},{"atb":[[10,27.52]],"id":3805784},{"atb":[[18.5,14.01]],"id":3805731},{"atl":[[65,2]],"id":522752}],"con":true,"img":false}]}
{"op":"mcm","clk":"5348939251","pt":1646222201762,"mc":[{"id":"1.195453760","rc":[{"atb":[[150,1.06],[100,19.09]],"id":522754},{"atl":[[60,24.77]],"id":522752}],"con":true,"img":false}]}
{"op":"mcm","clk":"5348939261","pt":1646222201864,"mc":[{"id":"1.195453760","rc":[{"atl":[[330,0],[990,1.69]],"id":522754},{"atb":[[20,0]],"id":3805740}],"con":true,"img":false}]}
{"op":"mcm","clk":"5348939276","pt":1646222202063,"mc":[{"id":"1.195453760","rc":[{"atl":[[340,0]],"id":522754},{"atl":[[17.5,13.87]],"id":3805772}],"con":true,"img":false}]}
{"op":"mcm","clk":"5348939299","pt":1646222202377,"mc":[{"id":"1.195453760","rc":[{"atl":[[990,0]],"id":522754}],"con":true,"img":false}]}
{"op":"mcm","clk":"5348939315","pt":1646222202579,"mc":[{"id":"1.195453760","rc":[{"atb":[[130,0]],"id":522754},{"atl":[[980,0.16]],"id":522754}],"con":true,"img":false}]}
{"op":"mcm","clk":"5348939327","pt":1646222202787,"mc":[{"id":"1.195453760","rc":[{"atb":[[4.3,0],[2.7,215.52]],"id":3805793},{"atb":[[12.5,0],[15.5,6.9]],"id":3805736},{"atb":[[36,0],[55,6.93]],"id":522747},{"atb":[[42,2.44],[28,0]],"id":522753},{"atb":[[19.5,0],[30,3.45]],"id":522743},{"atb":[[6.4,18.52],[5.3,0]],"id":3805771},{"atb":[[5.6,37.19],[4.3,30.3],[3.85,0]],"id":3805747},{"atb":[[19.5,5.41],[12.5,0]],"id":3805755},{"atb":[[17.5,0],[23,22.94]],"id":3805762},{"atl":[[38,0],[55,2]],"id":3805772}],"con":true,"img":false}]}
{"op":"mcm","clk":"5348939341","pt":1646222202947,"mc":[{"id":"1.195453760","rc":[{"atl":[[36,14.08]],"id":3805772}],"con":true,"img":false}]}
{"op":"mcm","clk":"5348939379","pt":1646222203684,"mc":[{"id":"1.195453760","rc":[{"atl":[[270,5.54]],"id":522741}],"con":true,"img":false}]}
{"op":"mcm","clk":"5348939386","pt":1646222203781,"mc":[{"id":"1.195453760","rc":[{"atb":[[5.2,36.1]],"id":3805747}],"con":true,"img":false}]}
{"op":"mcm","clk":"5348939402","pt":1646222204053,"mc":[{"id":"1.195453760","rc":[{"atl":[[36,9.48],[55,21.59]],"id":3805771}],"con":true,"img":false}]}
{"op":"mcm","clk":"5348939420","pt":1646222204351,"mc":[{"id":"1.195453760","rc":[{"atl":[[300,0]],"id":522741},{"atl":[[200,8.46]],"id":3805755}],"con":true,"img":false}]}
{"op":"mcm","clk":"5348939442","pt":1646222204762,"mc":[{"id":"1.195453760","rc":[{"atl":[[400,6.22]],"id":522750}],"con":true,"img":false}]}
{"op":"mcm","clk":"5348939466","pt":1646222205074,"mc":[{"id":"1.195453760","rc":[{"atl":[[720,0],[790,4.13]],"id":522741}],"con":true,"img":false}]}
{"op":"mcm","clk":"5348939475","pt":1646222205197,"mc":[{"id":"1.195453760","rc":[{"atb":[[36,2.86]],"id":522749}],"con":true,"img":false}]}
{"op":"mcm","clk":"5348939483","pt":1646222205282,"mc":[{"id":"1.195453760","rc":[{"atb":[[29,0]],"id":522749}],"con":true,"img":false}]}
{"op":"mcm","clk":"5348939498","pt":1646222205456,"mc":[{"id":"1.195453760","rc":[{"atl":[[90,0],[110,2]],"id":522755}],"con":true,"img":false}]}
{"op":"mcm","clk":"5348939585","pt":1646222206692,"mc":[{"id":"1.195453760","rc":[{"atb":[[19.5,9.9]],"id":3805740}],"con":true,"img":false}]}
{"op":"mcm","clk":"5348939605","pt":1646222206946,"mc":[{"id":"1.195453760","rc":[{"atb":[[17,28.15]],"id":3805740}],"con":true,"img":false}]}
{"op":"mcm","clk":"5348939628","pt":1646222207309,"mc":[{"id":"1.195453760","rc":[{"atb":[[19,0],[23,0]],"id":3805736},{"atb":[[75,0],[50,0]],"id":522747},{"atb":[[40,16.03],[30,0]],"id":522749},{"atb":[[17,25.43],[14.5,7.41]],"id":3805740},{"atl":[[190,8.95],[200,2]],"id":7607472},{"atb":[[18.5,0],[22,0]],"id":522746},{"atb":[[12,0],[9.8,0]],"id":3805772}],"con":true,"img":false}]}
{"op":"mcm","clk":"5348939682","pt":1646222207879,"mc":[{"id":"1.195453760","rc":[{"atb":[[6.8,72.65],[9.4,23.82]],"id":3805772}],"con":true,"img":false}]}
{"op":"mcm","clk":"5348939692","pt":1646222207998,"mc":[{"id":"1.195453760","rc":[{"atb":[[20,3.27],[25,2.72]],"id":3805736},{"atb":[[80,2.72],[55,10.2]],"id":522747},{"atb":[[34,3.27],[44,2.72]],"id":522749},{"atb":[[18,2.72],[15.5,3.27]],"id":3805740},{"atb":[[19.5,3.27],[24,2.72]],"id":522746},{"atb":[[9.6,3.27],[11.5,2.72]],"id":3805772}],"con":true,"img":false}]}
{"op":"mcm","clk":"5348939741","pt":1646222208554,"mc":[{"id":"1.195453760","rc":[{"atb":[[40,0],[44,18.76]],"id":522749},{"atb":[[9.2,0],[6.8,22.96]],"id":3805772}],"con":true,"img":false}]}
{"op":"mcm","clk":"5348939774","pt":1646222208983,"mc":[{"id":"1.195453760","rc":[{"atl":[[16.5,4.95],[17.5,8.91],[18.5,9.9],[19.5,0]],"id":3805772}],"con":true,"img":false}]}
{"op":"mcm","clk":"5348939818","pt":1646222209578,"mc":[{"id":"1.195453760","rc":[{"atl":[[18.5,30.52],[36,0]],"id":3805772}],"con":true,"img":false}]}
{"op":"mcm","clk":"5348939908","pt":1646222210574,"mc":[{"id":"1.195453760","rc":[{"atl":[[200,0],[420,6.07]],"id":3805755}],"con":true,"img":false}]}
{"op":"mcm","clk":"5348939928","pt":1646222210884,"mc":[{"id":"1.195453760","rc":[{"atb":[[30,10.42]],"id":522746},{"atl":[[16.5,15.18]],"id":3805772}],"con":true,"img":false}]}
{"op":"mcm","clk":"5348939984","pt":1646222211509,"mc":[{"id":"1.195453760","rc":[{"atl":[[420,2]],"id":3805755}],"con":true,"img":false}]}
{"op":"mcm","clk":"5348939990","pt":1646222211571,"mc":[{"id":"1.195453760","rc":[{"atb":[[27,0]],"id":522746}],"con":true,"img":false}]}
{"op":"mcm","clk":"5348939996","pt":1646222211665,"mc":[{"id":"1.195453760","rc":[{"atl":[[17.5,0]],"id":3805772}],"con":true,"img":false}]}
{"op":"mcm","clk":"5348940011","pt":1646222211873,"mc":[{"id":"1.195453760","rc":[{"atl":[[25,11.55]],"id":522752}],"con":true,"img":false}]}
{"op":"mcm","clk":"5348940022","pt":1646222212077,"mc":[{"id":"1.195453760","rc":[{"atb":[[5.9,32.35]],"id":3805793},{"atb":[[9.4,18.87]],"id":3805772}],"con":true,"img":false}]}
{"op":"mcm","clk":"5348940028","pt":1646222212182,"mc":[{"id":"1.195453760","rc":[{"atb":[[6.2,4.95],[5.7,12.63]],"id":3805793},{"atl":[[23,4.95]],"id":522751},{"atl":[[130,0],[150,9.9],[110,4.95]],"id":522745},{"atb":[[10,17.61],[11.5,4.95],[9.8,49.37]],"id":3805784},{"atb":[[24,32.94],[26,9.9]],"id":522746},{"atl":[[24,4.95],[25,6.6],[28,9.9],[29,0]],"id":522752},{"atb":[[42,0],[46,9.9],[50,3.23],[60,4.95]],"id":3805762},{"atl":[[65,2.47],[85,0],[46,4.95],[60,9.9]],"id":522742},{"atb":[[9.6,8.22],[8.8,9.9]],"id":3805772}],"con":true,"img":false}]}
{"op":"mcm","clk":"5348940037","pt":1646222212297,"mc":[{"id":"1.195453760","rc":[{"atl":[[34,4.95],[36,4.52],[42,9.9],[44,0]],"id":3805771}],"con":true,"img":false}]}
{"op":"mcm","clk":"5348940054","pt":1646222212503,"mc":[{"id":"1.195453760","rc":[{"atl":[[34,7.98],[55,19.59]],"id":3805771}],"con":true,"img":false}]}
{"op":"mcm","clk":"5348940063","pt":1646222212599,"mc":[{"id":"1.195453760","rc":[{"atb":[[6.4,29.36],[5.2,3.27],[5.7,61.62]],"id":3805793},{"atl":[[32,0],[23,12.15],[27,21.73]],"id":522751},{"atl":[[280,2],[150,21.35],[110,6.4]],"id":522745},{"atb":[[10,50.41],[9.8,13.17]],"id":3805784},{"atl":[[60,22.08]],"id":522752},{"atb":[[46,24.62],[23,7.27],[60,7.64]],"id":3805762},{"atl":[[65,21.05],[95,2]],"id":522742}],"con":true,"img":false}]}
{"op":"mcm","clk":"5348940068","pt":1646222212702,"mc":[{"id":"1.195453760","rc":[{"atl":[[46,8.47]],"id":522742}],"con":true,"img":false}]}
{"op":"mcm","clk":"5348940077","pt":1646222212811,"mc":[{"id":"1.195453760","rc":[{"atl":[[34,12.79],[42,23.99],[55,0]],"id":3805771}],"con":true,"img":false}]}
{"op":"mcm","clk":"5348940101","pt":1646222213075,"mc":[{"id":"1.195453760","rc":[{"atb":[[3.1,0],[2.84,0],[4.2,0]],"id":3805746},{"atb":[[18.5,0],[44,0],[13.5,0]],"id":522754},{"atb":[[7.8,0],[14.5,0],[5.9,0]],"id":3805736},{"atb":[[32,0],[210,0],[55,5.27]],"id":522747},{"atb":[[9,0],[25,0],[12.5,0]],"id":522749},{"atb":[[5.6,0],[9.2,25.39],[4.6,0]],"id":522751},{"atb":[[16,0],[6.4,0],[8.4,0]],"id":3805730},{"atb":[[18.5,0],[44,3.27],[13.5,0]],"id":522753},{"atb":[[70,2.72],[17,0],[24,0]],"id":522741},{"atb":[[300,0],[100,1.6],[50,0]],"id":522743},{"atb":[[18,24.81],[5.1,0],[10.5,0],[6.2,0]],"id":3805740},{"atb":[[9.6,0],[28,0],[14,0]],"id":522745},{"atb":[[2.5,0],[3.25,0],[2.7,0]],"id":3805747},{"atb":[[7.2,0],[18,0],[9.2,0]],"id":522755},{"atb":[[7.8,0],[14.5,0],[5.9,0]],"id":522746},{"atb":[[9,0],[25,0],[12.5,0]],"id":522748},{"atb":[[9.6,0],[19,0],[7.6,0]],"id":522750},{"atb":[[12,0],[6.8,0],[5.4,0]],"id":3805731},{"atb":[[5.6,0],[9.2,0],[4.6,0]],"id":522752},{"atb":[[16,0],[6.4,0],[8.4,0]],"id":522742}],"con":true,"img":false}]}
{"op":"mcm","clk":"5348940114","pt":1646222213190,"mc":[{"id":"1.195453760","rc":[{"atb":[[5.6,0],[9.2,0],[4.6,0]],"id":3805783},{"atb":[[2.5,0],[3.25,0],[2.7,58.82]],"id":3805793},{"atl":[[23,7.2],[25,4.95],[27,16.78],[29,9.9]],"id":522751},{"atl":[[65,0],[70,4.95],[85,0],[90,9.9]],"id":3805730},{"atl":[[270,0.58],[280,4.95],[790,2]],"id":522741},{"atl":[[1000,0]],"id":522743},{"atb":[[17,0]],"id":3805740},{"atb":[[5.6,0],[9.2,0],[4.6,0]],"id":3805771},{"atl":[[34,7.83],[36,9.48],[42,14.08],[44,9.9]],"id":3805771},{"atb":[[9.6,0],[28,0],[14,0]],"id":7607472},{"atl":[[170,0],[180,4.95]],"id":7607472},{"atl":[[150,11.45],[160,9.9],[110,1.45],[120,6.28]],"id":522745},{"atb":[[10.5,4.95],[11.5,0],[3.7,0],[6.8,0],[9.8,3.27],[4.4,0]],"id":3805784},{"atb":[[5.6,2.72]],"id":3805747},{"atb":[[9.6,0],[19,0],[7.6,0]],"id":3805755},{"atb":[[16,0],[6.4,0],[8.4,0]],"id":3805762},{"atl":[[70,9.9],[46,3.52],[50,4.95],[60,0]],"id":522742},{"atb":[[3.7,0],[6.8,0],[4.4,0]],"id":3805772},{"atl":[[16.5,10.22],[16,4.95],[18.5,20.61],[18,9.9]],"id":3805772}],"con":true,"img":false}]}
{"op":"mcm","clk":"5348940120","pt":1646222213280,"mc":[{"id":"1.195453760","rc":[{"atl":[[23,0],[26,0]],"id":522751},{"atl":[[190,0],[200,10.59]],"id":7607472},{"atl":[[110,0],[120,4.95]],"id":522745},{"atb":[[50,0]],"id":3805762}],"con":true,"img":false}]}
{"op":"mcm","clk":"5348940131","pt":1646222213402,"mc":[{"id":"1.195453760","rc":[{"atb":[[5.9,0]],"id":3805793},{"atl":[[65,18.57],[46,0]],"id":522742}],"con":true,"img":false}]}
{"op":"mcm","clk":"5348940140","pt":1646222213492,"mc":[{"id":"1.195453760","rc":[{"atb":[[100,11.33]],"id":522743}],"con":true,"img":false}]}
{"op":"mcm","clk":"5348940148","pt":1646222213605,"mc":[{"id":"1.195453760","rc":[{"atb":[[160,4.95],[120,21.53]],"id":522747},{"atb":[[170,0.93],[120,9.9]],"id":522743},{"atl":[[34,3.03],[36,4.95]],"id":3805771},{"atl":[[18,36.85]],"id":3805772}],"con":true,"img":false}]}
{"op":"mcm","clk":"5348940156","pt":1646222213743,"mc":[{"id":"1.195453760","rc":[{"atl":[[18.5,0]],"id":3805772}],"con":true,"img":false}]}
{"op":"mcm","clk":"5348940173","pt":1646222213909,"mc":[{"id":"1.195453760","rc":[{"atl":[[25,0],[29,0]],"id":522751},{"atl":[[65,4.95],[70,0],[85,9.9],[90,0],[95,1.68]],"id":3805730},{"atl":[[1000,0.15]],"id":522743},{"atl":[[170,0.93]],"id":7607472},{"atb":[[10.5,0]],"id":3805784},{"atb":[[5.4,40.99]],"id":3805747},{"atb":[[70,9.9],[80,2],[90,4.95],[60,0]],"id":3805755},{"atl":[[70,0],[50,0]],"id":522742},{"atl":[[16,0],[16.5,15.18],[18,26.95],[18.5,9.9]],"id":3805772}],"con":true,"img":false}]}
{"op":"mcm","clk":"5348940182","pt":1646222214009,"mc":[{"id":"1.195453760","rc":[{"atl":[[160,0],[120,0]],"id":522745},{"atl":[[65,0],[75,9.9],[85,0],[55,4.95]],"id":522755}],"con":true,"img":false}]}
{"op":"mcm","clk":"5348940189","pt":1646222214064,"mc":[{"id":"1.195453760","rc":[{"atl":[[34,0],[36,2.86],[28,5.86]],"id":522751},{"atl":[[150,12.51]],"id":522745},{"atl":[[65,21.05]],"id":522742}],"con":true,"img":false}]}
{"op":"mcm","clk":"5348940195","pt":1646222214180,"mc":[{"id":"1.195453760","rc":[{"atl":[[1000,1.71]],"id":522754},{"atb":[[100,1.6]],"id":522743},{"atb":[[21,10.65]],"id":3805731},{"atl":[[28,34.46],[60,0]],"id":522752}],"con":true,"img":false}]}
{"op":"mcm","clk":"5348940216","pt":1646222214376,"mc":[{"id":"1.195453760","rc":[{"atl":[[95,19.82],[100,2]],"id":3805730},{"atb":[[100,0]],"id":522743},{"atl":[[40,4.06]],"id":3805771},{"atb":[[32,2.72],[70,24.62],[95,1.68]],"id":3805755},{"atl":[[18,0]],"id":3805772}],"con":true,"img":false}]}
{"op":"mcm","clk":"5348940225","pt":1646222214480,"mc":[{"id":"1.195453760","rc":[{"atl":[[75,22.12],[80,0],[55,7.89]],"id":522755}],"con":true,"img":false}]}
{"op":"mcm","clk":"5348940229","pt":1646222214614,"mc":[{"id":"1.195453760","rc":[{"atl":[[23,4.95],[27,26.68]],"id":522751},{"atb":[[11.5,4.95],[9.8,13.17]],"id":3805784},{"atl":[[46,4.95],[60,9.9]],"id":522742}],"con":true,"img":false}]}
{"op":"mcm","clk":"5348940242","pt":1646222214793,"mc":[{"id":"1.195453760","rc":[{"atl":[[150,22.42],[110,4.95]],"id":522745}],"con":true,"img":false}]}
{"op":"mcm","clk":"5348940249","pt":1646222214896,"mc":[{"id":"1.195453760","rc":[{"atl":[[160,4.95],[180,0]],"id":7607472},{"atl":[[150,0],[160,9.9],[120,4.95]],"id":522748}],"con":true,"img":false}]}
{"op":"mcm","clk":"5348940257","pt":1646222215002,"mc":[{"id":"1.195453760","rc":[{"atb":[[18.5,4.95]],"id":3805731}],"con":true,"img":false}]}
{"op":"mcm","clk":"5348940272","pt":1646222215170,"mc":[{"id":"1.195453760","rc":[{"atb":[[80,0]],"id":3805755}],"con":true,"img":false}]}
{"op":"mcm","clk":"5348940279","pt":1646222215264,"mc":[{"id":"1.195453760","rc":[{"atb":[[5.6,37.19]],"id":3805747},{"atl":[[60,0]],"id":522755},{"atl":[[160,20.68],[330,2],[120,6.28]],"id":522748}],"con":true,"img":false}]}
{"op":"mcm","clk":"5348940302","pt":1646222215577,"mc":[{"id":"1.195453760","rc":[{"atb":[[19.5,0],[20,9.9],[23,7.2],[24,4.95]],"id":3805740}],"con":true,"img":false}]}
{"op":"mcm","clk":"5348940341","pt":1646222216311,"mc":[{"id":"1.195453760","rc":[{"atb":[[24,11.84]],"id":3805740},{"atb":[[5.4,4.95]],"id":3805747},{"atl":[[140,0]],"id":522748}],"con":true,"img":false}]}
{"op":"mcm","clk":"5348940367","pt":1646222216569,"mc":[{"id":"1.195453760","rc":[{"atl":[[40,14.97],[42,0]],"id":3805771}],"con":true,"img":false}]}
{"op":"mcm","clk":"5348940387","pt":1646222216887,"mc":[{"id":"1.195453760","rc":[{"atl":[[200,8.64]],"id":3805755},{"atb":[[18.5,9.9],[20,29.35],[21,4.95]],"id":522742}],"con":true,"img":false}]}
{"op":"mcm","clk":"5348940401","pt":1646222217090,"mc":[{"id":"1.195453760","rc":[{"atb":[[23,0]],"id":3805740},{"atb":[[11,0],[13.5,0]],"id":3805771}],"con":true,"img":false}]}
{"op":"mcm","clk":"5348940407","pt":1646222217194,"mc":[{"id":"1.195453760","rc":[{"atl":[[10.5,4.95],[11.5,15.1],[12.5,9.9],[13.5,0]],"id":3805746}],"con":true,"img":false}]}
{"op":"mcm","clk":"5348940419","pt":1646222217403,"mc":[{"id":"1.195453760","rc":[{"atb":[[20,3.27],[21,23.53]],"id":522742}],"con":true,"img":false}]}
{"op":"mcm","clk":"5348940428","pt":1646222217463,"mc":[{"id":"1.195453760","rc":[{"atl":[[790,4.18]],"id":522741},{"atb":[[10.5,4.95],[9.4,46.9]],"id":3805771}],"con":true,"img":false}]}
{"op":"mcm","clk":"5348940444","pt":1646222217673,"mc":[{"id":"1.195453760","rc":[{"atl":[[10.5,21.64],[12.5,47.08],[29,0]],"id":3805746},{"atb":[[10.5,16.81]],"id":3805771},{"atl":[[34,0],[40,17.53]],"id":3805771}],"con":true,"img":false}]}
{"op":"mcm","clk":"5348940452","pt":1646222217776,"mc":[{"id":"1.195453760","rc":[{"atb":[[12,3.27]],"id":3805771}],"con":true,"img":false}]}
{"op":"mcm","clk":"5348940459","pt":1646222217879,"mc":[{"id":"1.195453760","rc":[{"atb":[[14.5,2.72]],"id":3805771}],"con":true,"img":false}]}
{"op":"mcm","clk":"5348940466","pt":1646222217974,"mc":[{"id":"1.195453760","rc":[{"atl":[[11.5,22.08],[9.8,0]],"id":3805793},{"atb":[[32,4.95],[26,0],[27,9.9],[30,5.46]],"id":522746},{"atl":[[36,4.95],[38,4.28],[44,9.9],[46,0]],"id":3805731}],"con":true,"img":false}]}
{"op":"mcm","clk":"5348940473","pt":1646222218076,"mc":[{"id":"1.195453760","rc":[{"atl":[[9.6,4.95],[11,9.9]],"id":3805793}],"con":true,"img":false}]}
{"op":"mcm","clk":"5348940481","pt":1646222218188,"mc":[{"id":"1.195453760","rc":[{"atb":[[70,9.9],[80,2],[90,4.95]],"id":522750}],"con":true,"img":false}]}
{"op":"mcm","clk":"5348940494","pt":1646222218394,"mc":[{"id":"1.195453760","rc":[{"atl":[[11.5,0]],"id":3805746},{"atl":[[11.5,0],[15,70.19]],"id":3805793},{"atb":[[10,0]],"id":3805771},{"atl":[[100,2]],"id":3805731}],"con":true,"img":false}]}
{"op":"mcm","clk":"5348940516","pt":1646222218491,"mc":[{"id":"1.195453760","rc":[{"atl":[[36,9.48],[44,31.99]],"id":3805731}],"con":true,"img":false}]}
{"op":"mcm","clk":"5348940522","pt":1646222218595,"mc":[{"id":"1.195453760","rc":[{"atl":[[27,9.9],[28,37.75]],"id":522751},{"atl":[[280,8.19],[150,10.97]],"id":522745},{"atb":[[23,27.25]],"id":3805762}],"con":true,"img":false}]}
{"op":"mcm","clk":"5348940534","pt":1646222218698,"mc":[{"id":"1.195453760","rc":[{"atb":[[70,24.62],[90,6.73],[25,3.27]],"id":522750},{"atb":[[46,9.9]],"id":3805762}],"con":true,"img":false}]}
{"op":"mcm","clk":"5348940539","pt":1646222218803,"mc":[{"id":"1.195453760","rc":[{"atl":[[40,6.62],[44,31.99]],"id":3805771}],"con":true,"img":false}]}
{"op":"mcm","clk":"5348940561","pt":1646222219066,"mc":[{"id":"1.195453760","rc":[{"atl":[[15,7.14]],"id":3805793}],"con":true,"img":false}]}
{"op":"mcm","clk":"5348940576","pt":1646222219281,"mc":[{"id":"1.195453760","rc":[{"atl":[[38,0]],"id":3805731}],"con":true,"img":false}]}
{"op":"mcm","clk":"5348940583","pt":1646222219372,"mc":[{"id":"1.195453760","rc":[{"atb":[[80,0]],"id":522750}],"con":true,"img":false}]}
{"op":"mcm","clk":"5348940666","pt":1646222220369,"mc":[{"id":"1.195453760","rc":[{"atl":[[75,9.9]],"id":522755},{"atb":[[9.4,45.82]],"id":3805772}],"con":true,"img":false}]}
{"op":"mcm","clk":"5348940681","pt":1646222220468,"mc":[{"id":"1.195453760","rc":[{"atl":[[110,17.82]],"id":522755}],"con":true,"img":false}]}
{"op":"mcm","clk":"5348940743","pt":1646222221313,"mc":[{"id":"1.195453760","rc":[{"atl":[[160,9.9],[330,7.27]],"id":522748}],"con":true,"img":false}]}
{"op":"mcm","clk":"5348940801","pt":1646222222001,"mc":[{"id":"1.195453760","rc":[{"atl":[[55,28.95]],"id":3805772}],"con":true,"img":false}]}
{"op":"mcm","clk":"5348940853","pt":1646222222615,"mc":[{"id":"1.195453760","rc":[{"atl":[[23,0],[27,0]],"id":522751},{"atl":[[130,4.95],[160,0],[170,9.9],[120,1.32]],"id":522748},{"atb":[[65,9.9],[70,14.71],[85,4.95],[90,0]],"id":522750},{"atl":[[65,30.96],[46,0],[48,4.95],[60,0]],"id":522742}],"con":true,"img":false}]}
{"op":"mcm","clk":"5348940859","pt":1646222222735,"mc":[{"id":"1.195453760","rc":[{"atl":[[24,4.95],[28,47.66]],"id":522751},{"atb":[[24,0],[29,0]],"id":522755}],"con":true,"img":false}]}
