{"op":"mcm","clk":"5317728506","pt":1646251399890,"mc":[{"id":"1.195532862","marketDefinition":{"bspMarket":true,"turnInPlayEnabled":false,"persistenceEnabled":false,"marketBaseRate":5.0,"eventId":"31275720","eventTypeId":"4339","numberOfWinners":1,"bettingType":"ODDS","marketType":"WIN","marketTime":"2022-03-03T15:28:00.000Z","suspendTime":"2022-03-03T15:28:00.000Z","bspReconciled":false,"complete":true,"inPlay":false,"crossMatching":false,"runnersVoidable":false,"numberOfActiveRunners":6,"betDelay":0,"status":"OPEN","runners":[{"status":"ACTIVE","sortPriority":1,"id":36042617,"name":"1. Newtown Freda"},{"status":"ACTIVE","sortPriority":2,"id":39693066,"name":"2. Olympic Sparrow"},{"status":"ACTIVE","sortPriority":3,"id":28603683,"name":"3. Droopys Diamante"},{"status":"ACTIVE","sortPriority":4,"id":35839928,"name":"4. Aero Abis"},{"status":"ACTIVE","sortPriority":5,"id":28691352,"name":"5. Award Winner"},{"status":"ACTIVE","sortPriority":6,"id":8668222,"name":"6. Made To Order"}],"regulators":["MR_INT"],"venue":"Romford","countryCode":"GB","discountAllowed":false,"timezone":"Europe/London","openDate":"2022-03-03T13:57:00.000Z","version":4384107314,"name":"S2 575m","eventName":"Romford 3rd Mar"},"rc":[],"con":true,"img":false}]}
{"op":"mcm","clk":"5317728862","pt":1646251401767,"mc":[{"id":"1.195532862","marketDefinition":{"bspMarket":true,"turnInPlayEnabled":false,"persistenceEnabled":false,"marketBaseRate":5.0,"eventId":"31275720","eventTypeId":"4339","numberOfWinners":1,"bettingType":"ODDS","marketType":"WIN","marketTime":"2022-03-03T15:28:00.000Z","suspendTime":"2022-03-03T15:28:00.000Z","bspReconciled":false,"complete":true,"inPlay":false,"crossMatching":false,"runnersVoidable":false,"numberOfActiveRunners":6,"betDelay":0,"status":"OPEN","runners":[{"status":"ACTIVE","sortPriority":1,"id":36042617,"name":"1. Newtown Freda"},{"status":"ACTIVE","sortPriority":2,"id":39693066,"name":"2. Olympic Sparrow"},{"status":"ACTIVE","sortPriority":3,"id":28603683,"name":"3. Droopys Diamante"},{"status":"ACTIVE","sortPriority":4,"id":35839928,"name":"4. Aero Abis"},{"status":"ACTIVE","sortPriority":5,"id":28691352,"name":"5. Award Winner"},{"status":"ACTIVE","sortPriority":6,"id":8668222,"name":"6. Made To Order"}],"regulators":["MR_INT"],"venue":"Romford","countryCode":"GB","discountAllowed":true,"timezone":"Europe/London","openDate":"2022-03-03T13:57:00.000Z","version":4384107314,"name":"S2 575m","eventName":"Romford 3rd Mar"},"rc":[],"con":true,"img":false}]}
{"op":"mcm","clk":"5318486178","pt":1646259098768,"mc":[{"id":"1.195532862","rc":[{"atl":[[370,3]],"id":36042617},{"spn":1.0,"spf":"NaN","id":36042617}],"con":true,"img":false}]}
{"op":"mcm","clk":"5318486189","pt":1646259098867,"mc":[{"id":"1.195532862","rc":[{"atl":[[560,3]],"id":28691352}],"con":true,"img":false}]}
{"op":"mcm","clk":"5318486195","pt":1646259098924,"mc":[{"id":"1.195532862","rc":[{"atb":[[1.12,30]],"id":36042617},{"atb":[[1.12,30]],"id":39693066},{"atl":[[390,3]],"id":39693066},{"atl":[[270,3]],"id":35839928},{"atb":[[1.12,30]],"id":28603683},{"atl":[[550,3]],"id":28603683},{"atl":[[500,3]],"id":8668222}],"con":true,"img":false}]}
{"op":"mcm","clk":"5318486206","pt":1646259099026,"mc":[{"id":"1.195532862","rc":[{"atb":[[1.12,30]],"id":35839928}],"con":true,"img":false}]}
{"op":"mcm","clk":"5318486216","pt":1646259099180,"mc":[{"id":"1.195532862","rc":[{"atb":[[1.14,30]],"id":8668222},{"atb":[[1.12,30]],"id":28691352}],"con":true,"img":false}]}
{"op":"mcm","clk":"5318509034","pt":1646259402463,"mc":[{"id":"1.195532862","marketDefinition":{"bspMarket":true,"turnInPlayEnabled":false,"persistenceEnabled":false,"marketBaseRate":5.0,"eventId":"31275720","eventTypeId":"4339","numberOfWinners":1,"bettingType":"ODDS","marketType":"WIN","marketTime":"2022-03-03T15:28:00.000Z","suspendTime":"2022-03-03T15:28:00.000Z","bspReconciled":false,"complete":true,"inPlay":false,"crossMatching":false,"runnersVoidable":false,"numberOfActiveRunners":6,"betDelay":0,"status":"OPEN","runners":[{"status":"ACTIVE","sortPriority":1,"id":36042617,"name":"1. Newtown Freda"},{"status":"ACTIVE","sortPriority":2,"id":39693066,"name":"2. Olympic Sparrow"},{"status":"ACTIVE","sortPriority":3,"id":28603683,"name":"3. Droopys Diamante"},{"status":"ACTIVE","sortPriority":4,"id":35839928,"name":"4. Aero Abis"},{"status":"ACTIVE","sortPriority":5,"id":28691352,"name":"5. Award Winner"},{"status":"ACTIVE","sortPriority":6,"id":8668222,"name":"6. Made To Order"}],"regulators":["MR_INT"],"venue":"Romford","countryCode":"GB","discountAllowed":true,"timezone":"Europe/London","openDate":"2022-03-03T13:57:00.000Z","version":4384107314,"name":"S2 575m","eventName":"Romford 3rd Mar"},"rc":[{"atb":[[1.12,30]],"id":39693066},{"atl":[[390,3]],"id":39693066},{"spn":195.56,"spf":"NaN","id":39693066},{"atb":[[1.12,30]],"id":36042617},{"atl":[[370,3]],"id":36042617},{"spn":185.56,"spf":"NaN","id":36042617},{"atb":[[1.12,30]],"id":35839928},{"atl":[[270,3]],"id":35839928},{"spn":135.56,"spf":"NaN","id":35839928},{"atb":[[1.12,30]],"id":28603683},{"atl":[[550,3]],"id":28603683},{"spn":275.56,"spf":"NaN","id":28603683},{"atb":[[1.14,30]],"id":8668222},{"atl":[[500,3]],"id":8668222},{"spn":250.57,"spf":"NaN","id":8668222},{"atb":[[1.12,30]],"id":28691352},{"atl":[[560,3]],"id":28691352},{"spn":280.56,"spf":"NaN","id":28691352}],"con":true,"img":true}]}
{"op":"mcm","clk":"5320139869","pt":1646287410747,"mc":[{"id":"1.195532862","rc":[{"atb":[[2.02,11.82]],"id":39693066},{"spn":196.01,"spf":"NaN","id":39693066},{"atb":[[2.06,12.05]],"id":36042617},{"spn":186.03,"spf":"NaN","id":36042617},{"atb":[[2,10.03]],"id":35839928},{"spn":136.0,"spf":"NaN","id":35839928},{"atb":[[2.1,8.77]],"id":28603683},{"spn":276.05,"spf":"NaN","id":28603683},{"atb":[[2,9.2]],"id":8668222},{"spn":251.0,"spf":"NaN","id":8668222},{"atb":[[2,12.54]],"id":28691352},{"spn":281.0,"spf":"NaN","id":28691352}],"con":true,"img":false}]}
{"op":"mcm","clk":"5320538789","pt":1646297202590,"mc":[{"id":"1.195532862","marketDefinition":{"bspMarket":true,"turnInPlayEnabled":false,"persistenceEnabled":false,"marketBaseRate":5.0,"eventId":"31275720","eventTypeId":"4339","numberOfWinners":1,"bettingType":"ODDS","marketType":"WIN","marketTime":"2022-03-03T15:28:00.000Z","suspendTime":"2022-03-03T15:28:00.000Z","bspReconciled":false,"complete":true,"inPlay":false,"crossMatching":false,"runnersVoidable":false,"numberOfActiveRunners":6,"betDelay":0,"status":"OPEN","runners":[{"status":"ACTIVE","sortPriority":1,"id":36042617,"name":"1. Newtown Freda"},{"status":"ACTIVE","sortPriority":2,"id":39693066,"name":"2. Olympic Sparrow"},{"status":"ACTIVE","sortPriority":3,"id":28603683,"name":"3. Droopys Diamante"},{"status":"ACTIVE","sortPriority":4,"id":35839928,"name":"4. Aero Abis"},{"status":"ACTIVE","sortPriority":5,"id":28691352,"name":"5. Award Winner"},{"status":"ACTIVE","sortPriority":6,"id":8668222,"name":"6. Made To Order"}],"regulators":["MR_INT"],"venue":"Romford","countryCode":"GB","discountAllowed":true,"timezone":"Europe/London","openDate":"2022-03-03T13:57:00.000Z","version":4384107314,"name":"S2 575m","eventName":"Romford 3rd Mar"},"rc":[{"atb":[[1.12,30],[2.06,12.06]],"id":36042617},{"atl":[[370,3]],"id":36042617},{"spn":186.03,"spf":"NaN","id":36042617},{"atb":[[1.12,30],[2.02,11.83]],"id":39693066},{"atl":[[390,3]],"id":39693066},{"spn":196.01,"spf":"NaN","id":39693066},{"atb":[[2,10.04],[1.12,30]],"id":35839928},{"atl":[[270,3]],"id":35839928},{"spn":136.0,"spf":"NaN","id":35839928},{"atb":[[1.12,30],[2.1,8.78]],"id":28603683},{"atl":[[550,3]],"id":28603683},{"spn":276.05,"spf":"NaN","id":28603683},{"atb":[[2,9.2],[1.14,30]],"id":8668222},{"atl":[[500,3]],"id":8668222},{"spn":251.0,"spf":"NaN","id":8668222},{"atb":[[2,12.55],[1.12,30]],"id":28691352},{"atl":[[560,3]],"id":28691352},{"spn":281.0,"spf":"NaN","id":28691352}],"con":true,"img":true}]}
{"op":"mcm","clk":"5320561989","pt":1646297560160,"mc":[{"id":"1.195532862","rc":[{"atb":[[2.06,12.06]],"id":36042617},{"atb":[[2.02,11.83]],"id":39693066},{"atb":[[2,10.04]],"id":35839928},{"atb":[[2.1,8.78]],"id":28603683},{"atb":[[2,9.2]],"id":8668222},{"spl":[[1.01,1]],"id":8668222},{"spn":2.0,"spf":1.0,"id":8668222},{"atb":[[2,12.55]],"id":28691352},{"spl":[[1.01,1]],"id":28691352},{"spn":2.0,"spf":1.0,"id":28691352}],"con":true,"img":false}]}
{"op":"mcm","clk":"5320654809","pt":1646299270764,"mc":[{"id":"1.195532862","rc":[{"spl":[[21,1]],"id":36042617},{"spn":11.53,"spf":1.0,"id":36042617},{"spl":[[21,1]],"id":39693066},{"spn":11.51,"spf":1.0,"id":39693066},{"spl":[[21,1]],"id":35839928},{"spn":11.5,"spf":1.0,"id":35839928},{"spl":[[21,1]],"id":28603683},{"spn":11.55,"spf":1.0,"id":28603683},{"spl":[[21,1]],"id":8668222},{"spl":[[21,1]],"id":28691352}],"con":true,"img":false}]}
{"op":"mcm","clk":"5320830262","pt":1646302602582,"mc":[{"id":"1.195532862","marketDefinition":{"bspMarket":true,"turnInPlayEnabled":false,"persistenceEnabled":false,"marketBaseRate":5.0,"eventId":"31275720","eventTypeId":"4339","numberOfWinners":1,"bettingType":"ODDS","marketType":"WIN","marketTime":"2022-03-03T15:28:00.000Z","suspendTime":"2022-03-03T15:28:00.000Z","bspReconciled":false,"complete":true,"inPlay":false,"crossMatching":false,"runnersVoidable":false,"numberOfActiveRunners":6,"betDelay":0,"status":"OPEN","runners":[{"status":"ACTIVE","sortPriority":1,"id":36042617,"name":"1. Newtown Freda"},{"status":"ACTIVE","sortPriority":2,"id":39693066,"name":"2. Olympic Sparrow"},{"status":"ACTIVE","sortPriority":3,"id":28603683,"name":"3. Droopys Diamante"},{"status":"ACTIVE","sortPriority":4,"id":35839928,"name":"4. Aero Abis"},{"status":"ACTIVE","sortPriority":5,"id":28691352,"name":"5. Award Winner"},{"status":"ACTIVE","sortPriority":6,"id":8668222,"name":"6. Made To Order"}],"regulators":["MR_INT"],"venue":"Romford","countryCode":"GB","discountAllowed":true,"timezone":"Europe/London","openDate":"2022-03-03T13:57:00.000Z","version":4384107314,"name":"S2 575m","eventName":"Romford 3rd Mar"},"rc":[{"atb":[[1.12,30],[2.02,11.82]],"id":39693066},{"spl":[[21,1]],"id":39693066},{"atl":[[390,3]],"id":39693066},{"spn":11.51,"spf":1.0,"id":39693066},{"atb":[[1.12,30],[2.06,12.05]],"id":36042617},{"spl":[[21,1]],"id":36042617},{"atl":[[370,3]],"id":36042617},{"spn":11.53,"spf":1.0,"id":36042617},{"atb":[[2,10.03],[1.12,30]],"id":35839928},{"spl":[[21,1]],"id":35839928},{"atl":[[270,3]],"id":35839928},{"spn":11.5,"spf":1.0,"id":35839928},{"atb":[[1.12,30],[2.1,8.77]],"id":28603683},{"spl":[[21,1]],"id":28603683},{"atl":[[550,3]],"id":28603683},{"spn":11.55,"spf":1.0,"id":28603683},{"atb":[[2,9.2],[1.14,30]],"id":8668222},{"spl":[[1.01,1],[21,1]],"id":8668222},{"atl":[[500,3]],"id":8668222},{"spn":2.0,"spf":1.0,"id":8668222},{"atb":[[2,12.54],[1.12,30]],"id":28691352},{"spl":[[1.01,1],[21,1]],"id":28691352},{"atl":[[560,3]],"id":28691352},{"spn":2.0,"spf":1.0,"id":28691352}],"con":true,"img":true}]}
{"op":"mcm","clk":"5321026285","pt":1646305297091,"mc":[{"id":"1.195532862","rc":[{"atb":[[2.02,11.83],[6.8,2]],"id":39693066},{"spn":13.9,"spf":1.0,"id":39693066},{"atb":[[2.06,12.06],[5.7,2]],"id":36042617},{"spn":13.35,"spf":1.0,"id":36042617},{"atb":[[2,10.04],[9.4,2]],"id":35839928},{"spn":15.2,"spf":1.0,"id":35839928},{"atb":[[5.2,2],[2.1,8.78]],"id":28603683},{"spn":13.1,"spf":1.0,"id":28603683},{"atb":[[2,9.2],[5,2]],"id":8668222},{"spn":5.0,"spf":1.0,"id":8668222},{"atb":[[2,12.55],[3.5,2]],"id":28691352},{"spn":3.5,"spf":1.0,"id":28691352}],"con":true,"img":false}]}
{"op":"mcm","clk":"5321028089","pt":1646305320255,"mc":[{"id":"1.195532862","marketDefinition":{"bspMarket":true,"turnInPlayEnabled":false,"persistenceEnabled":false,"marketBaseRate":5.0,"eventId":"31275720","eventTypeId":"4339","numberOfWinners":1,"bettingType":"ODDS","marketType":"WIN","marketTime":"2022-03-03T15:28:00.000Z","suspendTime":"2022-03-03T15:28:00.000Z","bspReconciled":false,"complete":true,"inPlay":false,"crossMatching":true,"runnersVoidable":false,"numberOfActiveRunners":6,"betDelay":0,"status":"OPEN","runners":[{"status":"ACTIVE","sortPriority":1,"id":36042617,"name":"1. Newtown Freda"},{"status":"ACTIVE","sortPriority":2,"id":39693066,"name":"2. Olympic Sparrow"},{"status":"ACTIVE","sortPriority":3,"id":28603683,"name":"3. Droopys Diamante"},{"status":"ACTIVE","sortPriority":4,"id":35839928,"name":"4. Aero Abis"},{"status":"ACTIVE","sortPriority":5,"id":28691352,"name":"5. Award Winner"},{"status":"ACTIVE","sortPriority":6,"id":8668222,"name":"6. Made To Order"}],"regulators":["MR_INT"],"venue":"Romford","countryCode":"GB","discountAllowed":true,"timezone":"Europe/London","openDate":"2022-03-03T13:57:00.000Z","version":4384107314,"name":"S2 575m","eventName":"Romford 3rd Mar"},"rc":[],"con":true,"img":false}]}
{"op":"mcm","clk":"5321075059","pt":1646305858089,"mc":[{"id":"1.195532862","rc":[{"spb":[[1000,25.61]],"id":28691352},{"spn":21.0,"spf":21.0,"id":28691352}],"con":true,"img":false}]}
{"op":"mcm","clk":"5321084603","pt":1646305982687,"mc":[{"id":"1.195532862","rc":[{"atb":[[4.8,2]],"id":36042617},{"atl":[[9.8,1.15]],"id":36042617},{"spn":7.75,"spf":1.0,"id":36042617},{"atb":[[5.6,2]],"id":39693066},{"atl":[[12,0.92]],"id":39693066},{"spn":9.4,"spf":1.0,"id":39693066},{"atb":[[4.4,2]],"id":28603683},{"atl":[[8.6,1.33]],"id":28603683},{"spn":6.9,"spf":1.0,"id":28603683},{"atb":[[3.15,2]],"id":28691352},{"atl":[[5.3,2]],"id":28691352},{"spn":9.49,"spf":21.0,"id":28691352}],"con":true,"img":false}]}
{"op":"mcm","clk":"5321084611","pt":1646305982794,"mc":[{"id":"1.195532862","rc":[{"atb":[[7.2,1.62]],"id":35839928},{"atl":[[19.5,0.55]],"id":35839928},{"atb":[[4.3,2]],"id":8668222},{"atl":[[8.4,1.36]],"id":8668222}],"con":true,"img":false}]}
{"op":"mcm","clk":"5321274902","pt":1646307931323,"mc":[{"id":"1.195532862","rc":[{"atl":[[1000,10]],"id":39693066},{"atl":[[1000,10]],"id":36042617},{"atl":[[1000,10]],"id":35839928},{"spn":14.45,"spf":1.0,"id":35839928},{"atl":[[1000,10]],"id":28603683},{"atl":[[1000,10]],"id":8668222},{"atl":[[1000,10]],"id":28691352}],"con":true,"img":false}]}
{"op":"mcm","clk":"5321274923","pt":1646307931487,"mc":[{"id":"1.195532862","rc":[{"atb":[[1.01,1000]],"id":39693066},{"atb":[[1.01,1000]],"id":36042617},{"atb":[[1.01,1000]],"id":35839928},{"atb":[[1.01,1000]],"id":28603683},{"atb":[[1.01,1000]],"id":8668222},{"atb":[[1.01,1000]],"id":28691352}],"con":true,"img":false}]}
{"op":"mcm","clk":"5321274945","pt":1646307931694,"mc":[{"id":"1.195532862","rc":[{"atb":[[1.01,11000]],"id":36042617},{"atb":[[1.01,11000]],"id":39693066},{"atb":[[1.01,11000]],"id":35839928},{"atb":[[1.01,11000]],"id":28603683},{"atb":[[1.01,11000]],"id":8668222},{"atb":[[1.01,11000]],"id":28691352}],"con":true,"img":false}]}
{"op":"mcm","clk":"5321275617","pt":1646307938824,"mc":[{"id":"1.195532862","rc":[{"atl":[[8.4,0]],"id":8668222}],"con":true,"img":false}]}
{"op":"mcm","clk":"5321275629","pt":1646307938926,"mc":[{"id":"1.195532862","rc":[{"atl":[[8.2,1.4]],"id":8668222}],"con":true,"img":false}]}
{"op":"mcm","clk":"5321418483","pt":1646309479659,"mc":[{"id":"1.195532862","rc":[{"spl":[[1.01,9.18]],"id":28691352},{"spn":3.78,"spf":3.78,"id":28691352}],"con":true,"img":false}]}
{"op":"mcm","clk":"5321538173","pt":1646310766779,"mc":[{"id":"1.195532862","rc":[{"atl":[[1000,12]],"id":36042617}],"con":true,"img":false}]}
{"op":"mcm","clk":"5321538310","pt":1646310768073,"mc":[{"id":"1.195532862","rc":[{"atl":[[1000,12.2]],"id":36042617}],"con":true,"img":false}]}
{"op":"mcm","clk":"5321538433","pt":1646310769470,"mc":[{"id":"1.195532862","rc":[{"atl":[[1000,12]],"id":36042617}],"con":true,"img":false}]}
{"op":"mcm","clk":"5321538445","pt":1646310769575,"mc":[{"id":"1.195532862","rc":[{"atl":[[13.5,0.2]],"id":36042617}],"con":true,"img":false}]}
{"op":"mcm","clk":"5321538579","pt":1646310770879,"mc":[{"id":"1.195532862","rc":[{"atl":[[1000,12]],"id":39693066}],"con":true,"img":false}]}
{"op":"mcm","clk":"5321538734","pt":1646310772298,"mc":[{"id":"1.195532862","rc":[{"atl":[[1000,12.2]],"id":39693066}],"con":true,"img":false}]}
{"op":"mcm","clk":"5321538849","pt":1646310773602,"mc":[{"id":"1.195532862","rc":[{"atl":[[1000,12]],"id":39693066}],"con":true,"img":false}]}
{"op":"mcm","clk":"5321538854","pt":1646310773704,"mc":[{"id":"1.195532862","rc":[{"atl":[[15,0.2]],"id":39693066}],"con":true,"img":false}]}
{"op":"mcm","clk":"5321538981","pt":1646310775003,"mc":[{"id":"1.195532862","rc":[{"atl":[[1000,12]],"id":28603683}],"con":true,"img":false}]}
{"op":"mcm","clk":"5321539123","pt":1646310776303,"mc":[{"id":"1.195532862","rc":[{"atl":[[1000,12.2]],"id":28603683}],"con":true,"img":false}]}
{"op":"mcm","clk":"5321539229","pt":1646310777606,"mc":[{"id":"1.195532862","rc":[{"atl":[[1000,12]],"id":28603683}],"con":true,"img":false}]}
{"op":"mcm","clk":"5321539238","pt":1646310777709,"mc":[{"id":"1.195532862","rc":[{"atl":[[12,0.2]],"id":28603683}],"con":true,"img":false}]}
{"op":"mcm","clk":"5321539350","pt":1646310779008,"mc":[{"id":"1.195532862","rc":[{"atl":[[1000,12]],"id":35839928}],"con":true,"img":false}]}
{"op":"mcm","clk":"5321539463","pt":1646310780302,"mc":[{"id":"1.195532862","rc":[{"atl":[[1000,12.2]],"id":35839928}],"con":true,"img":false}]}
{"op":"mcm","clk":"5321539605","pt":1646310781613,"mc":[{"id":"1.195532862","rc":[{"atl":[[1000,12]],"id":35839928}],"con":true,"img":false}]}
{"op":"mcm","clk":"5321539618","pt":1646310781716,"mc":[{"id":"1.195532862","rc":[{"atl":[[19.5,0.75]],"id":35839928}],"con":true,"img":false}]}
{"op":"mcm","clk":"5321539752","pt":1646310783025,"mc":[{"id":"1.195532862","rc":[{"atl":[[1000,12]],"id":28691352}],"con":true,"img":false}]}
{"op":"mcm","clk":"5321539882","pt":1646310784321,"mc":[{"id":"1.195532862","rc":[{"atl":[[1000,12.2]],"id":28691352}],"con":true,"img":false}]}
{"op":"mcm","clk":"5321540006","pt":1646310785722,"mc":[{"id":"1.195532862","rc":[{"atl":[[1000,12]],"id":28691352}],"con":true,"img":false}]}
{"op":"mcm","clk":"5321540015","pt":1646310785826,"mc":[{"id":"1.195532862","rc":[{"atl":[[8,0.2]],"id":28691352}],"con":true,"img":false}]}
{"op":"mcm","clk":"5321540137","pt":1646310787125,"mc":[{"id":"1.195532862","rc":[{"atl":[[1000,12]],"id":8668222}],"con":true,"img":false}]}
{"op":"mcm","clk":"5321540272","pt":1646310788424,"mc":[{"id":"1.195532862","rc":[{"atl":[[1000,12.2]],"id":8668222}],"con":true,"img":false}]}
{"op":"mcm","clk":"5321540421","pt":1646310789830,"mc":[{"id":"1.195532862","rc":[{"atl":[[1000,12]],"id":8668222}],"con":true,"img":false}]}
{"op":"mcm","clk":"5321540434","pt":1646310789935,"mc":[{"id":"1.195532862","rc":[{"atl":[[11.5,0.2]],"id":8668222}],"con":true,"img":false}]}
{"op":"mcm","clk":"5321809172","pt":1646313402548,"mc":[{"id":"1.195532862","marketDefinition":{"bspMarket":true,"turnInPlayEnabled":false,"persistenceEnabled":false,"marketBaseRate":5.0,"eventId":"31275720","eventTypeId":"4339","numberOfWinners":1,"bettingType":"ODDS","marketType":"WIN","marketTime":"2022-03-03T15:28:00.000Z","suspendTime":"2022-03-03T15:28:00.000Z","bspReconciled":false,"complete":true,"inPlay":false,"crossMatching":true,"runnersVoidable":false,"numberOfActiveRunners":6,"betDelay":0,"status":"OPEN","runners":[{"status":"ACTIVE","sortPriority":1,"id":36042617,"name":"1. Newtown Freda"},{"status":"ACTIVE","sortPriority":2,"id":39693066,"name":"2. Olympic Sparrow"},{"status":"ACTIVE","sortPriority":3,"id":28603683,"name":"3. Droopys Diamante"},{"status":"ACTIVE","sortPriority":4,"id":35839928,"name":"4. Aero Abis"},{"status":"ACTIVE","sortPriority":5,"id":28691352,"name":"5. Award Winner"},{"status":"ACTIVE","sortPriority":6,"id":8668222,"name":"6. Made To Order"}],"regulators":["MR_INT"],"venue":"Romford","countryCode":"GB","discountAllowed":true,"timezone":"Europe/London","openDate":"2022-03-03T13:57:00.000Z","version":4384107314,"name":"S2 575m","eventName":"Romford 3rd Mar"},"rc":[{"atb":[[5.6,2],[1.12,30],[2.02,11.82],[1.01,11000],[6.8,2]],"id":39693066},{"spl":[[21,1]],"id":39693066},{"atl":[[12,0.92],[390,3],[15,0.2],[1000,12]],"id":39693066},{"spn":9.4,"spf":1.0,"id":39693066},{"atb":[[4.8,2],[1.12,30],[1.01,11000],[2.06,12.05],[5.7,2]],"id":36042617},{"spl":[[21,1]],"id":36042617},{"atl":[[370,3],[9.8,1.15],[13.5,0.2],[1000,12]],"id":36042617},{"spn":7.75,"spf":1.0,"id":36042617},{"atb":[[2,10.03],[1.12,30],[7.2,1.62],[1.01,11000],[9.4,2]],"id":35839928},{"spl":[[21,1]],"id":35839928},{"atl":[[270,3],[19.5,0.75],[1000,12]],"id":35839928},{"spn":14.45,"spf":1.0,"id":35839928},{"atb":[[1.12,30],[1.01,11000],[5.2,2],[4.4,2],[2.1,8.77]],"id":28603683},{"spl":[[21,1]],"id":28603683},{"atl":[[550,3],[8.6,1.33],[12,0.2],[1000,12]],"id":28603683},{"spn":6.9,"spf":1.0,"id":28603683},{"atb":[[2,9.19],[4.3,2],[1.01,11000],[5,2],[1.14,30]],"id":8668222},{"spl":[[1.01,1],[21,1]],"id":8668222},{"atl":[[8.2,1.4],[11.5,0.2],[500,3],[1000,12]],"id":8668222},{"spn":5.0,"spf":1.0,"id":8668222},{"atb":[[2,12.54],[1.12,30],[1.01,11000],[3.15,2],[3.5,2]],"id":28691352},{"spl":[[1.01,9.19],[21,1]],"id":28691352},{"atl":[[8,0.2],[560,3],[5.3,2],[1000,12]],"id":28691352},{"spb":[[1000,25.61]],"id":28691352},{"spn":3.78,"spf":3.78,"id":28691352}],"con":true,"img":true}]}
{"op":"mcm","clk":"5321856985","pt":1646313813873,"mc":[{"id":"1.195532862","rc":[{"atb":[[2.02,11.82]],"id":39693066},{"atb":[[2.06,12.05]],"id":36042617},{"atb":[[2,10.03]],"id":35839928},{"atb":[[2.1,8.77]],"id":28603683},{"atb":[[2,9.19]],"id":8668222},{"atl":[[1000,12.3]],"id":8668222},{"atb":[[2,12.54]],"id":28691352},{"spl":[[1.01,9.19]],"id":28691352},{"spn":3.78,"spf":3.78,"id":28691352}],"con":true,"img":false}]}
{"op":"mcm","clk":"5321857007","pt":1646313814075,"mc":[{"id":"1.195532862","rc":[{"atl":[[1000,12]],"id":8668222}],"con":true,"img":false}]}
{"op":"mcm","clk":"5321857016","pt":1646313814181,"mc":[{"id":"1.195532862","rc":[{"atb":[[5,1.7]],"id":8668222},{"trd":[[5,0.6]],"ltp":5.0,"tv":0.6,"id":8668222}],"con":true,"img":false}]}
{"op":"mcm","clk":"5321857301","pt":1646313816944,"mc":[{"id":"1.195532862","rc":[{"atb":[[5,3.7]],"id":8668222}],"con":true,"img":false}]}
{"op":"mcm","clk":"5321857311","pt":1646313817038,"mc":[{"id":"1.195532862","rc":[{"atb":[[5,2]],"id":8668222}],"con":true,"img":false}]}
{"op":"mcm","clk":"5321879987","pt":1646314081529,"mc":[{"id":"1.195532862","rc":[{"atb":[[2.62,64.81]],"id":39693066},{"atb":[[2.62,64.81]],"id":36042617},{"atl":[[34,15.5]],"id":36042617},{"atb":[[2.62,64.81]],"id":35839928},{"atl":[[34,15.5]],"id":28603683},{"atl":[[34,15.5]],"id":8668222},{"atl":[[17,9.5],[34,15.5]],"id":28691352}],"con":true,"img":false}]}
{"op":"mcm","clk":"5321881650","pt":1646314100931,"mc":[{"id":"1.195532862","rc":[{"atl":[[8,1.65]],"id":8668222}],"con":true,"img":false}]}
{"op":"mcm","clk":"5321881803","pt":1646314102753,"mc":[{"id":"1.195532862","rc":[{"atl":[[18.5,15.2]],"id":8668222}],"con":true,"img":false}]}
{"op":"mcm","clk":"5321881812","pt":1646314102862,"mc":[{"id":"1.195532862","rc":[{"atl":[[14.5,9.2]],"id":8668222}],"con":true,"img":false}]}
{"op":"mcm","clk":"5322310725","pt":1646318724307,"mc":[{"id":"1.195532862","rc":[{"atl":[[12,0]],"id":39693066},{"spn":10.9,"spf":1.0,"id":39693066},{"atl":[[19.5,0.19]],"id":35839928},{"atb":[[4.4,0]],"id":28603683},{"atb":[[3.15,0]],"id":28691352}],"con":true,"img":false}]}
{"op":"mcm","clk":"5322310732","pt":1646318724412,"mc":[{"id":"1.195532862","rc":[{"atl":[[11,1.01]],"id":39693066},{"atl":[[14,0.78]],"id":35839928},{"atb":[[4.1,2]],"id":28603683},{"atb":[[3.25,2]],"id":28691352}],"con":true,"img":false}]}
{"op":"mcm","clk":"5322320299","pt":1646318802570,"mc":[{"id":"1.195532862","marketDefinition":{"bspMarket":true,"turnInPlayEnabled":false,"persistenceEnabled":false,"marketBaseRate":5.0,"eventId":"31275720","eventTypeId":"4339","numberOfWinners":1,"bettingType":"ODDS","marketType":"WIN","marketTime":"2022-03-03T15:28:00.000Z","suspendTime":"2022-03-03T15:28:00.000Z","bspReconciled":false,"complete":true,"inPlay":false,"crossMatching":true,"runnersVoidable":false,"numberOfActiveRunners":6,"betDelay":0,"status":"OPEN","runners":[{"status":"ACTIVE","sortPriority":1,"id":36042617,"name":"1. Newtown Freda"},{"status":"ACTIVE","sortPriority":2,"id":39693066,"name":"2. Olympic Sparrow"},{"status":"ACTIVE","sortPriority":3,"id":28603683,"name":"3. Droopys Diamante"},{"status":"ACTIVE","sortPriority":4,"id":35839928,"name":"4. Aero Abis"},{"status":"ACTIVE","sortPriority":5,"id":28691352,"name":"5. Award Winner"},{"status":"ACTIVE","sortPriority":6,"id":8668222,"name":"6. Made To Order"}],"regulators":["MR_INT"],"venue":"Romford","countryCode":"GB","discountAllowed":true,"timezone":"Europe/London","openDate":"2022-03-03T13:57:00.000Z","version":4384107314,"name":"S2 575m","eventName":"Romford 3rd Mar"},"rc":[{"atb":[[5.6,2],[1.12,30],[2.02,11.82],[1.01,11000],[6.8,2],[2.62,64.81]],"id":39693066},{"spl":[[21,1]],"id":39693066},{"atl":[[11,1.01],[390,3],[15,0.2],[1000,12]],"id":39693066},{"spn":8.9,"spf":1.0,"id":39693066},{"atb":[[4.8,2],[1.12,30],[1.01,11000],[2.06,12.05],[5.7,2],[2.62,64.81]],"id":36042617},{"spl":[[21,1]],"id":36042617},{"atl":[[34,15.5],[370,3],[9.8,1.15],[13.5,0.2],[1000,12]],"id":36042617},{"spn":7.75,"spf":1.0,"id":36042617},{"atb":[[2,10.03],[1.12,30],[7.2,1.62],[1.01,11000],[2.62,64.81],[9.4,2]],"id":35839928},{"spl":[[21,1]],"id":35839928},{"atl":[[270,3],[19.5,0.19],[14,0.78],[1000,12]],"id":35839928},{"spn":11.7,"spf":1.0,"id":35839928},{"atb":[[1.12,30],[1.01,11000],[4.1,2],[5.2,2],[2.1,8.77]],"id":28603683},{"spl":[[21,1]],"id":28603683},{"atl":[[34,15.5],[550,3],[8.6,1.33],[12,0.2],[1000,12]],"id":28603683},{"spn":6.9,"spf":1.0,"id":28603683},{"atb":[[2,9.19],[4.3,2],[1.01,11000],[5,2],[1.14,30]],"id":8668222},{"spl":[[1.01,1],[21,1]],"id":8668222},{"atl":[[8,1.65],[34,15.5],[18.5,15.2],[8.2,1.4],[11.5,0.2],[14.5,9.2],[500,3],[1000,12]],"id":8668222},{"trd":[[5,0.6]],"ltp":5.0,"tv":0.6,"id":8668222},{"spn":5.0,"spf":1.0,"id":8668222},{"atb":[[2,12.54],[1.12,30],[1.01,11000],[3.25,2],[3.5,2]],"id":28691352},{"spl":[[1.01,9.19],[21,1]],"id":28691352},{"atl":[[8,0.2],[17,9.5],[34,15.5],[560,3],[5.3,2],[1000,12]],"id":28691352},{"spb":[[1000,25.61]],"id":28691352},{"spn":3.78,"spf":3.78,"id":28691352}],"con":true,"img":true}]}
{"op":"mcm","clk":"5322377527","pt":1646319481723,"mc":[{"id":"1.195532862","rc":[{"atb":[[4,83.33],[4.6,11.11],[4.4,29.41],[4.2,46.88]],"id":39693066},{"atl":[[11,0],[12,3.64],[13,8.33],[14,11.54],[15,18.06]],"id":39693066},{"spn":9.4,"spf":1.0,"id":39693066},{"atb":[[4,50],[4.4,11.76],[3.9,86.21],[4.2,31.25]],"id":36042617},{"atl":[[10.5,4.21],[11.5,9.52],[12.5,13.04],[13.5,20.2]],"id":36042617},{"atb":[[6.2,7.69],[5.5,55.56],[5.7,31.91],[5.9,20.41]],"id":35839928},{"atl":[[16,6.67],[17,9.38],[18,14.71],[15,2.86]],"id":35839928},{"spn":11.7,"spf":1.0,"id":35839928},{"atb":[[4,13.33],[3.7,92.59],[3.8,53.57],[3.9,34.48]],"id":28603683},{"atl":[[9,5],[10.5,26.32],[9.8,17.05],[9.4,11.9]],"id":28603683},{"atb":[[3.85,35.09],[3.95,13.56],[3.75,54.55],[3.65,94.34]],"id":8668222},{"atl":[[9.6,29.07],[9.2,18.29],[8.8,12.82],[8.4,5.41]],"id":8668222},{"atb":[[2.9,131.58],[2.98,50.51],[2.94,77.32],[3.05,19.51]],"id":28691352},{"atl":[[6.2,48.08],[5.5,8.89],[5.7,21.28],[5.9,30.61]],"id":28691352}],"con":true,"img":false}]}
{"op":"mcm","clk":"5322377535","pt":1646319481820,"mc":[{"id":"1.195532862","rc":[{"atb":[[4.8,0]],"id":36042617}],"con":true,"img":false}]}
{"op":"mcm","clk":"5322377545","pt":1646319481928,"mc":[{"id":"1.195532862","rc":[{"atl":[[10.5,1.06]],"id":39693066}],"con":true,"img":false}]}
{"op":"mcm","clk":"5322377550","pt":1646319482032,"mc":[{"id":"1.195532862","rc":[{"atb":[[4.6,2]],"id":36042617}],"con":true,"img":false}]}
{"op":"mcm","clk":"5322377730","pt":1646319484645,"mc":[{"id":"1.195532862","rc":[{"atl":[[18,9.2]],"id":36042617},{"atl":[[15.5,9.2]],"id":28603683},{"atl":[[9.2,9.2]],"id":28691352}],"con":true,"img":false}]}
{"op":"mcm","clk":"5322377740","pt":1646319484776,"mc":[{"id":"1.195532862","rc":[{"atl":[[23,15.2]],"id":36042617},{"atl":[[20,15.2]],"id":28603683}],"con":true,"img":false}]}
{"op":"mcm","clk":"5322377747","pt":1646319484855,"mc":[{"id":"1.195532862","rc":[{"atl":[[12,15.2]],"id":28691352}],"con":true,"img":false}]}
{"op":"mcm","clk":"5322377799","pt":1646319485431,"mc":[{"id":"1.195532862","rc":[{"atl":[[11.5,3.81]],"id":39693066}],"con":true,"img":false}]}
{"op":"mcm","clk":"5322377809","pt":1646319485540,"mc":[{"id":"1.195532862","rc":[{"atl":[[12,0]],"id":39693066}],"con":true,"img":false}]}
{"op":"mcm","clk":"5322378528","pt":1646319496566,"mc":[{"id":"1.195532862","rc":[{"atb":[[2.98,20.2],[3.05,0]],"id":28691352}],"con":true,"img":false}]}
{"op":"mcm","clk":"5322378537","pt":1646319496619,"mc":[{"id":"1.195532862","rc":[{"atb":[[3.25,0]],"id":28691352}],"con":true,"img":false}]}
{"op":"mcm","clk":"5322378546","pt":1646319496837,"mc":[{"id":"1.195532862","rc":[{"atb":[[2.76,2]],"id":28691352}],"con":true,"img":false}]}
{"op":"mcm","clk":"5322378875","pt":1646319502284,"mc":[{"id":"1.195532862","rc":[{"atl":[[19.5,9.2],[25,15.2]],"id":39693066}],"con":true,"img":false}]}
{"op":"mcm","clk":"5322379137","pt":1646319506558,"mc":[{"id":"1.195532862","rc":[{"atb":[[2.94,51.55]],"id":28691352}],"con":true,"img":false}]}
{"op":"mcm","clk":"5322379811","pt":1646319516589,"mc":[{"id":"1.195532862","rc":[{"atb":[[2.9,78.95]],"id":28691352}],"con":true,"img":false}]}
{"op":"mcm","clk":"5322380584","pt":1646319526585,"mc":[{"id":"1.195532862","rc":[{"atb":[[2.86,134.41]],"id":28691352}],"con":true,"img":false}]}
{"op":"mcm","clk":"5322390241","pt":1646319654682,"mc":[{"id":"1.195532862","rc":[{"atb":[[2.02,11.83]],"id":39693066},{"spl":[[10,5]],"id":39693066},{"spn":8.4,"spf":1.0,"id":39693066},{"atb":[[2.06,12.07]],"id":36042617},{"spl":[[10,5]],"id":36042617},{"atb":[[2,10.04]],"id":35839928},{"spl":[[10,5]],"id":35839928},{"spn":9.7,"spf":1.0,"id":35839928},{"atb":[[2.1,8.78]],"id":28603683},{"spl":[[10,5]],"id":28603683},{"atb":[[2,9.21]],"id":8668222},{"spl":[[10,5]],"id":8668222},{"atl":[[8,1.65]],"id":8668222},{"atb":[[2,12.56]],"id":28691352},{"spl":[[1.01,9.24],[10,5]],"id":28691352},{"spn":3.77,"spf":3.77,"id":28691352}],"con":true,"img":false}]}
{"op":"mcm","clk":"5322407494","pt":1646319868317,"mc":[{"id":"1.195532862","rc":[{"atb":[[1.01,11002]],"id":36042617}],"con":true,"img":false}]}
{"op":"mcm","clk":"5322407506","pt":1646319868419,"mc":[{"id":"1.195532862","rc":[{"atb":[[1.01,11003.99]],"id":36042617}],"con":true,"img":false}]}
{"op":"mcm","clk":"5322407520","pt":1646319868627,"mc":[{"id":"1.195532862","rc":[{"atb":[[1.01,11002]],"id":36042617}],"con":true,"img":false}]}
{"op":"mcm","clk":"5322407533","pt":1646319868727,"mc":[{"id":"1.195532862","rc":[{"atb":[[1.02,1.99]],"id":36042617}],"con":true,"img":false}]}
{"op":"mcm","clk":"5322407549","pt":1646319868936,"mc":[{"id":"1.195532862","rc":[{"atb":[[1.01,11002]],"id":39693066}],"con":true,"img":false}]}
{"op":"mcm","clk":"5322407560","pt":1646319869143,"mc":[{"id":"1.195532862","rc":[{"atb":[[1.01,11003.99]],"id":39693066}],"con":true,"img":false}]}
{"op":"mcm","clk":"5322408335","pt":1646319879407,"mc":[{"id":"1.195532862","rc":[{"atb":[[1.01,11002]],"id":39693066}],"con":true,"img":false}]}
{"op":"mcm","clk":"5322408343","pt":1646319879511,"mc":[{"id":"1.195532862","rc":[{"atb":[[1.02,1.99]],"id":39693066}],"con":true,"img":false}]}
{"op":"mcm","clk":"5322408367","pt":1646319879769,"mc":[{"id":"1.195532862","rc":[{"atb":[[1.01,11002]],"id":28603683}],"con":true,"img":false}]}
{"op":"mcm","clk":"5322408374","pt":1646319879877,"mc":[{"id":"1.195532862","rc":[{"atb":[[1.01,11003.99]],"id":28603683}],"con":true,"img":false}]}
{"op":"mcm","clk":"5322408385","pt":1646319879991,"mc":[{"id":"1.195532862","rc":[{"atb":[[1.01,11002]],"id":28603683}],"con":true,"img":false}]}
{"op":"mcm","clk":"5322408392","pt":1646319880082,"mc":[{"id":"1.195532862","rc":[{"atb":[[1.02,1.99]],"id":28603683}],"con":true,"img":false}]}
{"op":"mcm","clk":"5322408407","pt":1646319880290,"mc":[{"id":"1.195532862","rc":[{"atb":[[1.01,11002]],"id":35839928}],"con":true,"img":false}]}
{"op":"mcm","clk":"5322408416","pt":1646319880393,"mc":[{"id":"1.195532862","rc":[{"atb":[[1.01,11003.99]],"id":35839928}],"con":true,"img":false}]}
{"op":"mcm","clk":"5322408804","pt":1646319885591,"mc":[{"id":"1.195532862","rc":[{"atb":[[1.01,11002]],"id":35839928}],"con":true,"img":false}]}
{"op":"mcm","clk":"5322408811","pt":1646319885696,"mc":[{"id":"1.195532862","rc":[{"atb":[[1.02,1.99]],"id":35839928}],"con":true,"img":false}]}
{"op":"mcm","clk":"5322408823","pt":1646319885901,"mc":[{"id":"1.195532862","rc":[{"atb":[[1.01,11002]],"id":28691352}],"con":true,"img":false}]}
{"op":"mcm","clk":"5322409209","pt":1646319890982,"mc":[{"id":"1.195532862","rc":[{"atb":[[1.01,11003.99]],"id":28691352}],"con":true,"img":false}]}
{"op":"mcm","clk":"5322409218","pt":1646319891085,"mc":[{"id":"1.195532862","rc":[{"atb":[[1.01,11002]],"id":28691352}],"con":true,"img":false}]}
{"op":"mcm","clk":"5322409224","pt":1646319891188,"mc":[{"id":"1.195532862","rc":[{"atb":[[1.02,1.99]],"id":28691352}],"con":true,"img":false}]}
{"op":"mcm","clk":"5322409650","pt":1646319896403,"mc":[{"id":"1.195532862","rc":[{"atb":[[1.01,11002]],"id":8668222}],"con":true,"img":false}]}
{"op":"mcm","clk":"5322410095","pt":1646319901615,"mc":[{"id":"1.195532862","rc":[{"atb":[[1.01,11003.99]],"id":8668222}],"con":true,"img":false}]}
{"op":"mcm","clk":"5322410119","pt":1646319902031,"mc":[{"id":"1.195532862","rc":[{"atb":[[1.01,11002]],"id":8668222}],"con":true,"img":false}]}
{"op":"mcm","clk":"5322410126","pt":1646319902134,"mc":[{"id":"1.195532862","rc":[{"atb":[[1.02,1.99]],"id":8668222}],"con":true,"img":false}]}
{"op":"mcm","clk":"5322444105","pt":1646320293193,"mc":[{"id":"1.195532862","rc":[{"atb":[[4.2,2.79]],"id":28603683},{"atb":[[4,4.39]],"id":8668222},{"atb":[[3,12.16]],"id":28691352}],"con":true,"img":false}]}
{"op":"mcm","clk":"5322444160","pt":1646320293409,"mc":[{"id":"1.195532862","rc":[{"atb":[[2.92,20.69]],"id":28691352}],"con":true,"img":false}]}
{"op":"mcm","clk":"5322444196","pt":1646320293608,"mc":[{"id":"1.195532862","rc":[{"atb":[[2.92,0]],"id":28691352}],"con":true,"img":false}]}
{"op":"mcm","clk":"5322455065","pt":1646320410891,"mc":[{"id":"1.195532862","rc":[{"atb":[[1.05,2.84]],"id":35839928}],"con":true,"img":false}]}
{"op":"mcm","clk":"5322455083","pt":1646320411100,"mc":[{"id":"1.195532862","rc":[{"atb":[[5.4,22.73]],"id":35839928},{"atl":[[22,4.76]],"id":35839928}],"con":true,"img":false}]}
{"op":"mcm","clk":"5322455099","pt":1646320411258,"mc":[{"id":"1.195532862","rc":[{"atb":[[1.05,0.09]],"id":35839928}],"con":true,"img":false}]}
{"op":"mcm","clk":"5322455141","pt":1646320411681,"mc":[{"id":"1.195532862","rc":[{"atb":[[1.05,0]],"id":35839928}],"con":true,"img":false}]}
{"op":"mcm","clk":"5322455148","pt":1646320411784,"mc":[{"id":"1.195532862","rc":[{"atl":[[14,0.68]],"id":35839928},{"trd":[[14,0.19]],"ltp":14.0,"tv":0.19,"id":35839928}],"con":true,"img":false}]}
{"op":"mcm","clk":"5322455378","pt":1646320414488,"mc":[{"id":"1.195532862","rc":[{"atb":[[2.66,6.76]],"id":36042617}],"con":true,"img":false}]}
{"op":"mcm","clk":"5322455384","pt":1646320414590,"mc":[{"id":"1.195532862","rc":[{"atb":[[4.4,32.71]],"id":39693066},{"atb":[[2.42,7.9]],"id":28603683}],"con":true,"img":false}]}
{"op":"mcm","clk":"5322455392","pt":1646320414692,"mc":[{"id":"1.195532862","rc":[{"atb":[[3.7,37.04]],"id":36042617},{"atl":[[11.5,19.04]],"id":36042617},{"atb":[[2.38,8.13]],"id":8668222},{"atb":[[2.8,6.23]],"id":28691352}],"con":true,"img":false}]}
{"op":"mcm","clk":"5322455398","pt":1646320414796,"mc":[{"id":"1.195532862","rc":[{"atb":[[4.2,78.13]],"id":39693066},{"atl":[[13,16.66]],"id":39693066},{"atb":[[3.5,26.66]],"id":28603683},{"atl":[[9.4,23.8]],"id":28603683}],"con":true,"img":false}]}
{"op":"mcm","clk":"5322455407","pt":1646320414899,"mc":[{"id":"1.195532862","rc":[{"atb":[[3.55,27.12]],"id":8668222},{"atl":[[8.4,18.23]],"id":8668222},{"atb":[[2.82,54.95]],"id":28691352},{"atl":[[5.7,42.56]],"id":28691352}],"con":true,"img":false}]}
{"op":"mcm","clk":"5322457613","pt":1646320440749,"mc":[{"id":"1.195532862","rc":[{"atb":[[1.04,2.86]],"id":36042617},{"atb":[[1.04,2.87]],"id":28603683},{"atb":[[1.04,2.87]],"id":8668222},{"atb":[[1.03,2.91]],"id":28691352}],"con":true,"img":false}]}
{"op":"mcm","clk":"5322457665","pt":1646320441272,"mc":[{"id":"1.195532862","rc":[{"atb":[[1.04,0.12]],"id":36042617},{"atb":[[1.04,0.12]],"id":28603683},{"atb":[[1.04,0.12]],"id":8668222},{"atb":[[1.03,0.17]],"id":28691352}],"con":true,"img":false}]}
{"op":"mcm","clk":"5322457693","pt":1646320441687,"mc":[{"id":"1.195532862","rc":[{"atb":[[1.04,0]],"id":8668222}],"con":true,"img":false}]}
{"op":"mcm","clk":"5322457699","pt":1646320441734,"mc":[{"id":"1.195532862","rc":[{"atb":[[1.04,0]],"id":36042617},{"atb":[[1.04,0]],"id":28603683},{"atb":[[4.2,0.12]],"id":8668222},{"atb":[[1.03,0]],"id":28691352}],"con":true,"img":false}]}
{"op":"mcm","clk":"5322457709","pt":1646320441844,"mc":[{"id":"1.195532862","rc":[{"atb":[[4.4,11.88]],"id":36042617},{"atb":[[4.2,2.92]],"id":28603683},{"atb":[[3.15,0.17]],"id":28691352}],"con":true,"img":false}]}
{"op":"mcm","clk":"5322457728","pt":1646320442051,"mc":[{"id":"1.195532862","rc":[{"atb":[[2.96,9.62]],"id":28691352}],"con":true,"img":false}]}
{"op":"mcm","clk":"5322457826","pt":1646320443142,"mc":[{"id":"1.195532862","rc":[{"atb":[[2.96,0]],"id":28691352}],"con":true,"img":false}]}
{"op":"mcm","clk":"5322459226","pt":1646320459292,"mc":[{"id":"1.195532862","rc":[{"atl":[[1000,13.65]],"id":36042617},{"atl":[[1000,13.65]],"id":39693066}],"con":true,"img":false}]}
{"op":"mcm","clk":"5322459240","pt":1646320459503,"mc":[{"id":"1.195532862","rc":[{"atl":[[1000,13.65]],"id":28603683},{"atl":[[1000,13.65]],"id":28691352}],"con":true,"img":false}]}
{"op":"mcm","clk":"5322459258","pt":1646320459660,"mc":[{"id":"1.195532862","rc":[{"atl":[[1000,12.41]],"id":39693066},{"atl":[[1000,13.65]],"id":8668222}],"con":true,"img":false}]}
{"op":"mcm","clk":"5322459270","pt":1646320459774,"mc":[{"id":"1.195532862","rc":[{"atl":[[1000,12.49]],"id":28603683}],"con":true,"img":false}]}
{"op":"mcm","clk":"5322459276","pt":1646320459872,"mc":[{"id":"1.195532862","rc":[{"atl":[[1000,12.43]],"id":36042617},{"atl":[[1000,12.79]],"id":28691352}],"con":true,"img":false}]}
{"op":"mcm","clk":"5322459295","pt":1646320460086,"mc":[{"id":"1.195532862","rc":[{"atl":[[1000,12]],"id":39693066}],"con":true,"img":false}]}
{"op":"mcm","clk":"5322459300","pt":1646320460183,"mc":[{"id":"1.195532862","rc":[{"atl":[[10,0.41]],"id":39693066}],"con":true,"img":false}]}
{"op":"mcm","clk":"5322459313","pt":1646320460299,"mc":[{"id":"1.195532862","rc":[{"atl":[[1000,12]],"id":28603683},{"atl":[[1000,12.53]],"id":8668222}],"con":true,"img":false}]}
{"op":"mcm","clk":"5322459319","pt":1646320460393,"mc":[{"id":"1.195532862","rc":[{"atl":[[12.5,8.7],[13,8.33]],"id":39693066},{"atl":[[8.4,0.49]],"id":28603683}],"con":true,"img":false}]}
{"op":"mcm","clk":"5322459341","pt":1646320460612,"mc":[{"id":"1.195532862","rc":[{"atl":[[1000,12]],"id":36042617},{"atl":[[9,17.5],[9.4,11.9]],"id":28603683}],"con":true,"img":false}]}
{"op":"mcm","clk":"5322459348","pt":1646320460704,"mc":[{"id":"1.195532862","rc":[{"atl":[[9.6,0.43]],"id":36042617}],"con":true,"img":false}]}
{"op":"mcm","clk":"5322459363","pt":1646320460873,"mc":[{"id":"1.195532862","rc":[{"atl":[[10.5,14.74],[11.5,9.52]],"id":36042617},{"atl":[[1000,12]],"id":28691352}],"con":true,"img":false}]}
{"op":"mcm","clk":"5322459371","pt":1646320460974,"mc":[{"id":"1.195532862","rc":[{"atl":[[5.2,0.79]],"id":28691352}],"con":true,"img":false}]}
{"op":"mcm","clk":"5322459379","pt":1646320461073,"mc":[{"id":"1.195532862","rc":[{"atl":[[1000,12]],"id":8668222},{"atl":[[5.5,31.11],[5.7,21.28]],"id":28691352}],"con":true,"img":false}]}
{"op":"mcm","clk":"5322459389","pt":1646320461190,"mc":[{"id":"1.195532862","rc":[{"atl":[[7.8,0.53]],"id":8668222}],"con":true,"img":false}]}
{"op":"mcm","clk":"5322459547","pt":1646320462802,"mc":[{"id":"1.195532862","rc":[{"atl":[[5.3,4.97]],"id":28691352}],"con":true,"img":false}]}
{"op":"mcm","clk":"5322464155","pt":1646320521537,"mc":[{"id":"1.195532862","rc":[{"spn":7.65,"spf":1.0,"id":36042617},{"spn":6.8,"spf":1.0,"id":28603683},{"atl":[[4.5,20]],"id":28691352}],"con":true,"img":false}]}
{"op":"mcm","clk":"5322464164","pt":1646320521640,"mc":[{"id":"1.195532862","rc":[{"atb":[[1.02,3.64]],"id":35839928}],"con":true,"img":false}]}
{"op":"mcm","clk":"5322464173","pt":1646320521745,"mc":[{"id":"1.195532862","rc":[{"atb":[[1.02,2.42]],"id":35839928},{"atl":[[5.6,4.45]],"id":28691352}],"con":true,"img":false}]}
{"op":"mcm","clk":"5322464184","pt":1646320521851,"mc":[{"id":"1.195532862","rc":[{"atb":[[1.02,1.99]],"id":35839928}],"con":true,"img":false}]}
{"op":"mcm","clk":"5322464192","pt":1646320521956,"mc":[{"id":"1.195532862","rc":[{"atb":[[9.6,0.43]],"id":35839928}],"con":true,"img":false}]}
{"op":"mcm","clk":"5322464202","pt":1646320522059,"mc":[{"id":"1.195532862","rc":[{"atl":[[5.6,0]],"id":28691352}],"con":true,"img":false}]}
{"op":"mcm","clk":"5322464254","pt":1646320522979,"mc":[{"id":"1.195532862","rc":[{"atl":[[5.3,2]],"id":28691352}],"con":true,"img":false}]}
{"op":"mcm","clk":"5322464764","pt":1646320528845,"mc":[{"id":"1.195532862","rc":[{"atl":[[4.4,2.95]],"id":28691352}],"con":true,"img":false}]}
{"op":"mcm","clk":"5322464781","pt":1646320529063,"mc":[{"id":"1.195532862","rc":[{"atb":[[4,83.33],[3.7,0]],"id":36042617},{"atl":[[10,4.44],[10.5,10.53]],"id":36042617},{"atb":[[4.9,25.64],[4.2,46.88]],"id":39693066},{"atl":[[11,4],[11.5,12.14],[12.5,0]],"id":39693066},{"atb":[[5.4,0],[6,20]],"id":35839928},{"atl":[[18.5,5.71],[22,0]],"id":35839928},{"atb":[[3.8,89.28],[3.5,0]],"id":28603683},{"atl":[[9,12.5],[8.8,5.13]],"id":28603683},{"atb":[[3.55,0],[3.9,34.48]],"id":8668222},{"atl":[[8,3.65],[8.2,6.96],[8.4,0]],"id":8668222},{"atl":[[4.9,22.95],[5.5,0],[4.7,10.81]],"id":28691352}],"con":true,"img":false}]}
{"op":"mcm","clk":"5322464792","pt":1646320529165,"mc":[{"id":"1.195532862","rc":[{"atl":[[11.5,8.33]],"id":39693066},{"atl":[[9.4,14.95]],"id":28603683}],"con":true,"img":false}]}
{"op":"mcm","clk":"5322464805","pt":1646320529281,"mc":[{"id":"1.195532862","rc":[{"atl":[[10.5,0],[11,4.21],[1000,13.65],[9.6,0],[9.8,5.59]],"id":36042617},{"atl":[[9,0],[9.4,11.9],[8.6,6.46]],"id":28603683}],"con":true,"img":false}]}
{"op":"mcm","clk":"5322464808","pt":1646320529372,"mc":[{"id":"1.195532862","rc":[{"atl":[[10,0],[1000,13.65]],"id":39693066}],"con":true,"img":false}]}
{"op":"mcm","clk":"5322464821","pt":1646320529477,"mc":[{"id":"1.195532862","rc":[{"atl":[[1000,12.43]],"id":36042617}],"con":true,"img":false}]}
{"op":"mcm","clk":"5322464835","pt":1646320529591,"mc":[{"id":"1.195532862","rc":[{"atl":[[1000,12]],"id":36042617},{"atl":[[1000,12.41]],"id":39693066}],"con":true,"img":false}]}
{"op":"mcm","clk":"5322464847","pt":1646320529700,"mc":[{"id":"1.195532862","rc":[{"atl":[[9.8,6.02]],"id":36042617}],"con":true,"img":false}]}
{"op":"mcm","clk":"5322464865","pt":1646320529908,"mc":[{"id":"1.195532862","rc":[{"atl":[[1000,12]],"id":39693066}],"con":true,"img":false}]}
{"op":"mcm","clk":"5322464870","pt":1646320530003,"mc":[{"id":"1.195532862","rc":[{"atl":[[10.5,1.47]],"id":39693066}],"con":true,"img":false}]}
{"op":"mcm","clk":"5322464884","pt":1646320530156,"mc":[{"id":"1.195532862","rc":[{"atl":[[11,0]],"id":36042617}],"con":true,"img":false}]}
{"op":"mcm","clk":"5322464927","pt":1646320530678,"mc":[{"id":"1.195532862","rc":[{"atl":[[1000,14.52]],"id":8668222}],"con":true,"img":false}]}
{"op":"mcm","clk":"5322464949","pt":1646320530896,"mc":[{"id":"1.195532862","rc":[{"atl":[[1000,14.1]],"id":8668222}],"con":true,"img":false}]}
{"op":"mcm","clk":"5322464963","pt":1646320531054,"mc":[{"id":"1.195532862","rc":[{"atl":[[1000,12]],"id":8668222}],"con":true,"img":false}]}
{"op":"mcm","clk":"5322464976","pt":1646320531161,"mc":[{"id":"1.195532862","rc":[{"atl":[[7.8,2.63]],"id":8668222}],"con":true,"img":false}]}
{"op":"mcm","clk":"5322465102","pt":1646320532785,"mc":[{"id":"1.195532862","rc":[{"atb":[[4.2,0.12]],"id":28603683},{"atb":[[3,0]],"id":28691352}],"con":true,"img":false}]}
{"op":"mcm","clk":"5322465114","pt":1646320532996,"mc":[{"id":"1.195532862","rc":[{"atb":[[2.98,28.54]],"id":28691352}],"con":true,"img":false}]}
{"op":"mcm","clk":"5322465217","pt":1646320534255,"mc":[{"id":"1.195532862","rc":[{"atb":[[2.98,20.2]],"id":28691352}],"con":true,"img":false}]}
{"op":"mcm","clk":"5322465228","pt":1646320534358,"mc":[{"id":"1.195532862","rc":[{"atl":[[11.5,19.04],[9.8,1.58]],"id":36042617},{"atl":[[8.6,1.33],[8.8,17.03]],"id":28603683}],"con":true,"img":false}]}
{"op":"mcm","clk":"5322465420","pt":1646320536668,"mc":[{"id":"1.195532862","rc":[{"atb":[[4.7,2.79]],"id":36042617},{"atb":[[4.2,3.01]],"id":28603683}],"con":true,"img":false}]}
{"op":"mcm","clk":"5322465432","pt":1646320536884,"mc":[{"id":"1.195532862","rc":[{"atb":[[4.3,5.89]],"id":36042617}],"con":true,"img":false}]}
{"op":"mcm","clk":"5322465491","pt":1646320537813,"mc":[{"id":"1.195532862","rc":[{"atl":[[17.5,6.06],[18.5,0]],"id":35839928},{"atl":[[4.9,0],[4.7,33.76]],"id":28691352}],"con":true,"img":false}]}
{"op":"mcm","clk":"5322465528","pt":1646320538335,"mc":[{"id":"1.195532862","rc":[{"atb":[[4.3,0]],"id":36042617}],"con":true,"img":false}]}
{"op":"mcm","clk":"5322465588","pt":1646320539073,"mc":[{"id":"1.195532862","rc":[{"atl":[[10,0],[10.5,4.21]],"id":36042617},{"atl":[[11,0],[11.5,12.14]],"id":39693066},{"atl":[[4.9,25.64]],"id":28691352}],"con":true,"img":false}]}
{"op":"mcm","clk":"5322465607","pt":1646320539284,"mc":[{"id":"1.195532862","rc":[{"atl":[[11.5,16.14]],"id":39693066}],"con":true,"img":false}]}
{"op":"mcm","clk":"5322465622","pt":1646320539491,"mc":[{"id":"1.195532862","rc":[{"atl":[[11.5,7.81],[13,16.66]],"id":39693066}],"con":true,"img":false}]}
{"op":"mcm","clk":"5322465683","pt":1646320540269,"mc":[{"id":"1.195532862","rc":[{"atl":[[11.5,3.81]],"id":39693066}],"con":true,"img":false}]}
{"op":"mcm","clk":"5322465890","pt":1646320542620,"mc":[{"id":"1.195532862","rc":[{"atb":[[4.7,0]],"id":36042617}],"con":true,"img":false}]}
{"op":"mcm","clk":"5322466237","pt":1646320546798,"mc":[{"id":"1.195532862","rc":[{"atb":[[4.7,2.79]],"id":36042617}],"con":true,"img":false}]}
{"op":"mcm","clk":"5322466411","pt":1646320549081,"mc":[{"id":"1.195532862","rc":[{"atl":[[5.1,36.59],[6.2,0]],"id":28691352}],"con":true,"img":false}]}
{"op":"mcm","clk":"5322466686","pt":1646320552223,"mc":[{"id":"1.195532862","rc":[{"atl":[[8,2]],"id":8668222}],"con":true,"img":false}]}
{"op":"mcm","clk":"5322466723","pt":1646320552586,"mc":[{"id":"1.195532862","rc":[{"atl":[[7.6,1.65]],"id":8668222}],"con":true,"img":false}]}
{"op":"mcm","clk":"5322466733","pt":1646320552689,"mc":[{"id":"1.195532862","rc":[{"atl":[[8,0],[1000,13.65],[7.6,3.65]],"id":8668222}],"con":true,"img":false}]}
{"op":"mcm","clk":"5322466744","pt":1646320552795,"mc":[{"id":"1.195532862","rc":[{"atl":[[7.8,2.1]],"id":8668222}],"con":true,"img":false}]}
{"op":"mcm","clk":"5322466753","pt":1646320552898,"mc":[{"id":"1.195532862","rc":[{"atl":[[1000,12.56]],"id":8668222}],"con":true,"img":false}]}
{"op":"mcm","clk":"5322466769","pt":1646320553108,"mc":[{"id":"1.195532862","rc":[{"atl":[[1000,12]],"id":8668222}],"con":true,"img":false}]}
{"op":"mcm","clk":"5322466775","pt":1646320553213,"mc":[{"id":"1.195532862","rc":[{"atl":[[7.4,0.56]],"id":8668222}],"con":true,"img":false}]}
{"op":"mcm","clk":"5322466829","pt":1646320553893,"mc":[{"id":"1.195532862","rc":[{"atl":[[7.8,0]],"id":8668222}],"con":true,"img":false}]}
{"op":"mcm","clk":"5322466965","pt":1646320555618,"mc":[{"id":"1.195532862","rc":[{"atl":[[1000,14.52]],"id":8668222}],"con":true,"img":false}]}
{"op":"mcm","clk":"5322466983","pt":1646320555826,"mc":[{"id":"1.195532862","rc":[{"atl":[[1000,14.1]],"id":8668222}],"con":true,"img":false}]}
{"op":"mcm","clk":"5322466995","pt":1646320555930,"mc":[{"id":"1.195532862","rc":[{"atl":[[1000,12]],"id":8668222}],"con":true,"img":false}]}
{"op":"mcm","clk":"5322467006","pt":1646320556035,"mc":[{"id":"1.195532862","rc":[{"atl":[[7.4,2.66]],"id":8668222}],"con":true,"img":false}]}
{"op":"mcm","clk":"5322467267","pt":1646320558729,"mc":[{"id":"1.195532862","rc":[{"atb":[[4,0]],"id":8668222}],"con":true,"img":false}]}
{"op":"mcm","clk":"5322467302","pt":1646320559100,"mc":[{"id":"1.195532862","rc":[{"atl":[[5.3,60.14]],"id":28691352}],"con":true,"img":false}]}
{"op":"mcm","clk":"5322467311","pt":1646320559253,"mc":[{"id":"1.195532862","rc":[{"atl":[[5.9,0]],"id":28691352}],"con":true,"img":false}]}
{"op":"mcm","clk":"5322467333","pt":1646320559416,"mc":[{"id":"1.195532862","rc":[{"atl":[[8.2,1.4],[7.8,5.88]],"id":8668222},{"atl":[[5.7,0]],"id":28691352}],"con":true,"img":false}]}
{"op":"mcm","clk":"5322467365","pt":1646320559737,"mc":[{"id":"1.195532862","rc":[{"atl":[[5.2,6.67]],"id":28691352}],"con":true,"img":false}]}
{"op":"mcm","clk":"5322467389","pt":1646320559957,"mc":[{"id":"1.195532862","rc":[{"atl":[[5.2,0.79]],"id":28691352}],"con":true,"img":false}]}
{"op":"mcm","clk":"5322467483","pt":1646320560937,"mc":[{"id":"1.195532862","rc":[{"atb":[[5,5.59]],"id":39693066}],"con":true,"img":false}]}
{"op":"mcm","clk":"5322468241","pt":1646320569416,"mc":[{"id":"1.195532862","rc":[{"atl":[[8.2,15.29]],"id":8668222}],"con":true,"img":false}]}
{"op":"mcm","clk":"5322469087","pt":1646320579459,"mc":[{"id":"1.195532862","rc":[{"atl":[[9.2,0],[9.6,0],[8.6,19.74],[8.8,0]],"id":8668222}],"con":true,"img":false}]}
{"op":"mcm","clk":"5322469896","pt":1646320589468,"mc":[{"id":"1.195532862","rc":[{"spn":7.75,"spf":1.0,"id":36042617},{"spn":9.8,"spf":1.0,"id":35839928},{"atl":[[9,31.25]],"id":8668222}],"con":true,"img":false}]}
{"op":"mcm","clk":"5322470154","pt":1646320592668,"mc":[{"id":"1.195532862","rc":[{"atb":[[4.5,3.68]],"id":39693066}],"con":true,"img":false}]}
{"op":"mcm","clk":"5322470166","pt":1646320592770,"mc":[{"id":"1.195532862","rc":[{"atb":[[4.5,0]],"id":39693066}],"con":true,"img":false}]}
{"op":"mcm","clk":"5322471870","pt":1646320614182,"mc":[{"id":"1.195532862","rc":[{"atl":[[4.4,1.47]],"id":28691352},{"trd":[[4.4,2.96]],"ltp":4.4,"tv":2.96,"id":28691352}],"con":true,"img":false}]}
{"op":"mcm","clk":"5322471882","pt":1646320614287,"mc":[{"id":"1.195532862","rc":[{"atb":[[3.55,2]],"id":28691352}],"con":true,"img":false}]}
{"op":"mcm","clk":"5322471892","pt":1646320614497,"mc":[{"id":"1.195532862","rc":[{"atb":[[2.96,4.66]],"id":28691352},{"atl":[[4.8,4.88]],"id":28691352}],"con":true,"img":false}]}
{"op":"mcm","clk":"5322471911","pt":1646320614703,"mc":[{"id":"1.195532862","rc":[{"atl":[[9.8,12.58]],"id":36042617}],"con":true,"img":false}]}
{"op":"mcm","clk":"5322471924","pt":1646320614908,"mc":[{"id":"1.195532862","rc":[{"atl":[[9.6,11.63],[11.5,9.52]],"id":36042617}],"con":true,"img":false}]}
{"op":"mcm","clk":"5322471931","pt":1646320615011,"mc":[{"id":"1.195532862","rc":[{"atl":[[4.8,0]],"id":28691352}],"con":true,"img":false}]}
{"op":"mcm","clk":"5322471940","pt":1646320615117,"mc":[{"id":"1.195532862","rc":[{"atl":[[12,6.64],[9.8,12.15],[1000,13.65]],"id":36042617}],"con":true,"img":false}]}
{"op":"mcm","clk":"5322471948","pt":1646320615221,"mc":[{"id":"1.195532862","rc":[{"atl":[[1000,12.43]],"id":36042617}],"con":true,"img":false}]}
{"op":"mcm","clk":"5322471955","pt":1646320615327,"mc":[{"id":"1.195532862","rc":[{"atl":[[12,0]],"id":36042617},{"atb":[[2.96,0]],"id":28691352}],"con":true,"img":false}]}
{"op":"mcm","clk":"5322471965","pt":1646320615431,"mc":[{"id":"1.195532862","rc":[{"atl":[[1000,12]],"id":36042617}],"con":true,"img":false}]}
{"op":"mcm","clk":"5322471973","pt":1646320615488,"mc":[{"id":"1.195532862","rc":[{"atl":[[9.4,0.43]],"id":36042617}],"con":true,"img":false}]}
{"op":"mcm","clk":"5322472027","pt":1646320616216,"mc":[{"id":"1.195532862","rc":[{"atb":[[3.6,1.48]],"id":28691352}],"con":true,"img":false}]}
{"op":"mcm","clk":"5322472114","pt":1646320617313,"mc":[{"id":"1.195532862","rc":[{"atb":[[4.7,0]],"id":36042617},{"atl":[[7.6,2]],"id":8668222}],"con":true,"img":false}]}
{"op":"mcm","clk":"5322472129","pt":1646320617522,"mc":[{"id":"1.195532862","rc":[{"atb":[[4.6,5.22]],"id":36042617},{"atb":[[3.55,0]],"id":28691352}],"con":true,"img":false}]}
{"op":"mcm","clk":"5322472169","pt":1646320617899,"mc":[{"id":"1.195532862","rc":[{"atl":[[7.2,1.65]],"id":8668222}],"con":true,"img":false}]}
{"op":"mcm","clk":"5322472232","pt":1646320618624,"mc":[{"id":"1.195532862","rc":[{"atl":[[7.4,0.56]],"id":8668222}],"con":true,"img":false}]}
{"op":"mcm","clk":"5322472302","pt":1646320619408,"mc":[{"id":"1.195532862","rc":[{"atb":[[4.6,2]],"id":36042617}],"con":true,"img":false}]}
{"op":"mcm","clk":"5322472319","pt":1646320619624,"mc":[{"id":"1.195532862","rc":[{"atl":[[10.5,0],[9.8,16.7]],"id":36042617},{"atl":[[17,15.63],[17.5,0]],"id":35839928},{"atl":[[7.4,3.88],[7.8,0],[7.6,6.06]],"id":8668222},{"atb":[[2.82,0],[2.92,52.08]],"id":28691352}],"con":true,"img":false}]}
{"op":"mcm","clk":"5322472338","pt":1646320619931,"mc":[{"id":"1.195532862","rc":[{"atl":[[8,4.94]],"id":8668222}],"con":true,"img":false}]}
{"op":"mcm","clk":"5322472346","pt":1646320620036,"mc":[{"id":"1.195532862","rc":[{"atl":[[9.6,0],[9.8,28.06]],"id":36042617}],"con":true,"img":false}]}
{"op":"mcm","clk":"5322472361","pt":1646320620245,"mc":[{"id":"1.195532862","rc":[{"atl":[[11.5,19.04],[9.8,16.7]],"id":36042617},{"atl":[[8,0]],"id":8668222}],"con":true,"img":false}]}
{"op":"mcm","clk":"5322472468","pt":1646320621551,"mc":[{"id":"1.195532862","rc":[{"atb":[[4.7,5.05]],"id":36042617}],"con":true,"img":false}]}
{"op":"mcm","clk":"5322472701","pt":1646320624649,"mc":[{"id":"1.195532862","rc":[{"atl":[[8,3.68]],"id":8668222}],"con":true,"img":false}]}
{"op":"mcm","clk":"5322472741","pt":1646320625115,"mc":[{"id":"1.195532862","rc":[{"atl":[[8,0]],"id":8668222}],"con":true,"img":false}]}
{"op":"mcm","clk":"5322472995","pt":1646320628202,"mc":[{"id":"1.195532862","rc":[{"atb":[[3.6,0]],"id":28691352}],"con":true,"img":false}]}
{"op":"mcm","clk":"5322473005","pt":1646320628309,"mc":[{"id":"1.195532862","rc":[{"atb":[[3.55,2]],"id":28691352}],"con":true,"img":false}]}
{"op":"mcm","clk":"5322473104","pt":1646320629611,"mc":[{"id":"1.195532862","rc":[{"atl":[[10.5,10.53]],"id":36042617}],"con":true,"img":false}]}
{"op":"mcm","clk":"5322473120","pt":1646320629823,"mc":[{"id":"1.195532862","rc":[{"atl":[[10,11.11],[11.5,9.52]],"id":36042617}],"con":true,"img":false}]}
{"op":"mcm","clk":"5322473137","pt":1646320630031,"mc":[{"id":"1.195532862","rc":[{"atl":[[13.5,0.2]],"id":36042617}],"con":true,"img":false}]}
{"op":"mcm","clk":"5322473255","pt":1646320631292,"mc":[{"id":"1.195532862","rc":[{"atb":[[3.6,1.48]],"id":28691352}],"con":true,"img":false}]}
{"op":"mcm","clk":"5322473275","pt":1646320631502,"mc":[{"id":"1.195532862","rc":[{"atb":[[3.55,0]],"id":28691352}],"con":true,"img":false}]}
{"op":"mcm","clk":"5322473319","pt":1646320632036,"mc":[{"id":"1.195532862","rc":[{"atb":[[4.7,0]],"id":36042617}],"con":true,"img":false}]}
{"op":"mcm","clk":"5322473681","pt":1646320636216,"mc":[{"id":"1.195532862","rc":[{"atb":[[4.7,2.79]],"id":36042617}],"con":true,"img":false}]}
{"op":"mcm","clk":"5322473955","pt":1646320639609,"mc":[{"id":"1.195532862","rc":[{"atl":[[11.5,14.29],[1000,13.65]],"id":36042617}],"con":true,"img":false}]}
{"op":"mcm","clk":"5322473965","pt":1646320639714,"mc":[{"id":"1.195532862","rc":[{"atl":[[9.4,0]],"id":36042617}],"con":true,"img":false}]}
{"op":"mcm","clk":"5322473972","pt":1646320639817,"mc":[{"id":"1.195532862","rc":[{"atl":[[10,0],[10.5,21.06],[1000,12.43]],"id":36042617}],"con":true,"img":false}]}
{"op":"mcm","clk":"5322473980","pt":1646320639921,"mc":[{"id":"1.195532862","rc":[{"atl":[[1000,12]],"id":36042617}],"con":true,"img":false}]}
{"op":"mcm","clk":"5322473989","pt":1646320640024,"mc":[{"id":"1.195532862","rc":[{"atl":[[9.6,0.43]],"id":36042617}],"con":true,"img":false}]}
{"op":"mcm","clk":"5322474175","pt":1646320642418,"mc":[{"id":"1.195532862","rc":[{"atb":[[4.7,0]],"id":36042617}],"con":true,"img":false}]}
{"op":"mcm","clk":"5322474237","pt":1646320643248,"mc":[{"id":"1.195532862","rc":[{"atb":[[3.6,0]],"id":28691352}],"con":true,"img":false}]}
{"op":"mcm","clk":"5322474252","pt":1646320643456,"mc":[{"id":"1.195532862","rc":[{"atb":[[3.55,2]],"id":28691352}],"con":true,"img":false}]}
{"op":"mcm","clk":"5322474269","pt":1646320643612,"mc":[{"id":"1.195532862","rc":[{"atl":[[10,4.44],[9.8,12.15]],"id":36042617}],"con":true,"img":false}]}
{"op":"mcm","clk":"5322474491","pt":1646320646335,"mc":[{"id":"1.195532862","rc":[{"atb":[[3.6,1.48]],"id":28691352}],"con":true,"img":false}]}
{"op":"mcm","clk":"5322474518","pt":1646320646647,"mc":[{"id":"1.195532862","rc":[{"atb":[[3.55,0]],"id":28691352}],"con":true,"img":false}]}
{"op":"mcm","clk":"5322474528","pt":1646320646752,"mc":[{"id":"1.195532862","rc":[{"atb":[[4.7,2.79]],"id":36042617}],"con":true,"img":false}]}
{"op":"mcm","clk":"5322474752","pt":1646320649560,"mc":[{"id":"1.195532862","rc":[{"atb":[[2.66,0]],"id":36042617},{"spn":7.65,"spf":1.0,"id":36042617},{"atb":[[2.42,0]],"id":28603683}],"con":true,"img":false}]}
{"op":"mcm","clk":"5322475084","pt":1646320653665,"mc":[{"id":"1.195532862","rc":[{"atl":[[11,10]],"id":36042617}],"con":true,"img":false}]}
{"op":"mcm","clk":"5322475096","pt":1646320653874,"mc":[{"id":"1.195532862","rc":[{"atl":[[10.5,10.53],[11.5,0],[12.5,0]],"id":36042617}],"con":true,"img":false}]}
{"op":"mcm","clk":"5322475431","pt":1646320658375,"mc":[{"id":"1.195532862","rc":[{"atb":[[3.6,0]],"id":28691352}],"con":true,"img":false}]}
{"op":"mcm","clk":"5322475450","pt":1646320658533,"mc":[{"id":"1.195532862","rc":[{"atb":[[3.55,2]],"id":28691352}],"con":true,"img":false}]}
{"op":"mcm","clk":"5322475474","pt":1646320658744,"mc":[{"id":"1.195532862","rc":[{"atb":[[2.96,5]],"id":28691352}],"con":true,"img":false}]}
{"op":"mcm","clk":"5322475517","pt":1646320659263,"mc":[{"id":"1.195532862","rc":[{"atb":[[2.96,0]],"id":28691352}],"con":true,"img":false}]}
{"op":"mcm","clk":"5322475688","pt":1646320661349,"mc":[{"id":"1.195532862","rc":[{"atb":[[2.9,5.9]],"id":36042617}],"con":true,"img":false}]}
{"op":"mcm","clk":"5322475697","pt":1646320661453,"mc":[{"id":"1.195532862","rc":[{"atb":[[2.78,6.3]],"id":28603683}],"con":true,"img":false}]}
{"op":"mcm","clk":"5322475864","pt":1646320663657,"mc":[{"id":"1.195532862","rc":[{"atl":[[12,13.64]],"id":36042617}],"con":true,"img":false}]}
{"op":"mcm","clk":"5322475943","pt":1646320664479,"mc":[{"id":"1.195532862","rc":[{"atb":[[3.6,1.48]],"id":28691352}],"con":true,"img":false}]}
{"op":"mcm","clk":"5322475964","pt":1646320664788,"mc":[{"id":"1.195532862","rc":[{"atb":[[3.55,0]],"id":28691352}],"con":true,"img":false}]}
{"op":"mcm","clk":"5322476174","pt":1646320667355,"mc":[{"id":"1.195532862","rc":[{"atb":[[1.05,2.84]],"id":35839928}],"con":true,"img":false}]}
{"op":"mcm","clk":"5322476210","pt":1646320667768,"mc":[{"id":"1.195532862","rc":[{"atb":[[1.05,0.09]],"id":35839928}],"con":true,"img":false}]}
{"op":"mcm","clk":"5322476238","pt":1646320668188,"mc":[{"id":"1.195532862","rc":[{"atb":[[1.05,0]],"id":35839928}],"con":true,"img":false}]}
{"op":"mcm","clk":"5322476247","pt":1646320668300,"mc":[{"id":"1.195532862","rc":[{"atl":[[14,0.58]],"id":35839928},{"trd":[[14,0.39]],"ltp":14.0,"tv":0.39,"id":35839928}],"con":true,"img":false}]}
{"op":"mcm","clk":"5322476373","pt":1646320669766,"mc":[{"id":"1.195532862","rc":[{"atl":[[7.4,3.32],[1000,13.65]],"id":8668222}],"con":true,"img":false}]}
{"op":"mcm","clk":"5322476429","pt":1646320670395,"mc":[{"id":"1.195532862","rc":[{"atl":[[1000,12.58]],"id":8668222}],"con":true,"img":false}]}
{"op":"mcm","clk":"5322476445","pt":1646320670556,"mc":[{"id":"1.195532862","rc":[{"atl":[[1000,12]],"id":8668222}],"con":true,"img":false}]}
{"op":"mcm","clk":"5322476454","pt":1646320670659,"mc":[{"id":"1.195532862","rc":[{"atl":[[7,0.58]],"id":8668222}],"con":true,"img":false}]}
{"op":"mcm","clk":"5322476694","pt":1646320673693,"mc":[{"id":"1.195532862","rc":[{"atl":[[13,20.83]],"id":36042617}],"con":true,"img":false}]}
{"op":"mcm","clk":"5322476798","pt":1646320674900,"mc":[{"id":"1.195532862","rc":[{"atl":[[7.4,9.57],[7.6,0]],"id":8668222}],"con":true,"img":false}]}
{"op":"mcm","clk":"5322476816","pt":1646320675108,"mc":[{"id":"1.195532862","rc":[{"atb":[[4,33.33],[3.9,0]],"id":8668222}],"con":true,"img":false}]}
{"op":"mcm","clk":"5322476924","pt":1646320676377,"mc":[{"id":"1.195532862","rc":[{"atb":[[3.6,0]],"id":28691352}],"con":true,"img":false}]}
{"op":"mcm","clk":"5322476935","pt":1646320676481,"mc":[{"id":"1.195532862","rc":[{"atb":[[3.55,2]],"id":28691352}],"con":true,"img":false}]}
{"op":"mcm","clk":"5322477196","pt":1646320679904,"mc":[{"id":"1.195532862","rc":[{"atl":[[7.8,3.79]],"id":8668222}],"con":true,"img":false}]}
{"op":"mcm","clk":"5322477242","pt":1646320680433,"mc":[{"id":"1.195532862","rc":[{"atl":[[7.8,0]],"id":8668222}],"con":true,"img":false}]}
{"op":"mcm","clk":"5322477263","pt":1646320680652,"mc":[{"id":"1.195532862","rc":[{"atl":[[1000,14]],"id":36042617},{"atl":[[1000,14]],"id":39693066},{"atl":[[1000,14]],"id":35839928},{"atl":[[1000,14]],"id":28603683},{"atl":[[1000,14]],"id":8668222},{"atl":[[1000,14]],"id":28691352}],"con":true,"img":false}]}
{"op":"mcm","clk":"5322477277","pt":1646320680802,"mc":[{"id":"1.195532862","rc":[{"atl":[[1000,13]],"id":39693066},{"atl":[[1000,13]],"id":36042617},{"atl":[[1000,13]],"id":35839928},{"atl":[[1000,13]],"id":28603683},{"atl":[[1000,13]],"id":8668222},{"atl":[[1000,13]],"id":28691352}],"con":true,"img":false}]}
{"op":"mcm","clk":"5322477293","pt":1646320681011,"mc":[{"id":"1.195532862","rc":[{"atl":[[1000,12]],"id":39693066},{"atl":[[1000,12]],"id":36042617},{"atl":[[1000,12]],"id":35839928},{"atl":[[1000,12]],"id":28603683},{"atl":[[1000,12]],"id":8668222},{"atl":[[1000,12]],"id":28691352}],"con":true,"img":false}]}
{"op":"mcm","clk":"5322477301","pt":1646320681116,"mc":[{"id":"1.195532862","rc":[{"atl":[[11,1]],"id":39693066},{"atl":[[9.6,1.43]],"id":36042617},{"atl":[[14.5,1]],"id":35839928},{"atl":[[8.6,2.33]],"id":28603683},{"atl":[[7,1.58]],"id":8668222},{"atl":[[4.4,2.47]],"id":28691352}],"con":true,"img":false}]}
{"op":"mcm","clk":"5322477328","pt":1646320681434,"mc":[{"id":"1.195532862","rc":[{"atl":[[9.6,5.87]],"id":36042617},{"atl":[[11.5,13.33]],"id":39693066}],"con":true,"img":false}]}
{"op":"mcm","clk":"5322477339","pt":1646320681536,"mc":[{"id":"1.195532862","rc":[{"atb":[[1.01,11003]],"id":36042617},{"atl":[[10,15.55],[10.5,0],[9.6,1.43]],"id":36042617},{"atl":[[13,8.33],[13.5,5]],"id":39693066},{"atl":[[9,3.21]],"id":28603683}],"con":true,"img":false}]}
{"op":"mcm","clk":"5322477347","pt":1646320681645,"mc":[{"id":"1.195532862","rc":[{"atl":[[9.6,7.31],[10,4.44]],"id":36042617},{"atl":[[9,0]],"id":28603683}],"con":true,"img":false}]}
{"op":"mcm","clk":"5322477353","pt":1646320681703,"mc":[{"id":"1.195532862","rc":[{"atl":[[9.6,1.43],[10,15.55]],"id":36042617},{"atl":[[13.5,0]],"id":39693066}],"con":true,"img":false}]}
{"op":"mcm","clk":"5322477521","pt":1646320683704,"mc":[{"id":"1.195532862","rc":[{"atl":[[7.2,0]],"id":8668222}],"con":true,"img":false}]}
{"op":"mcm","clk":"5322477543","pt":1646320684014,"mc":[{"id":"1.195532862","rc":[{"atl":[[7,0.58]],"id":8668222}],"con":true,"img":false}]}
{"op":"mcm","clk":"5322477552","pt":1646320684119,"mc":[{"id":"1.195532862","rc":[{"atb":[[1.05,2.83]],"id":35839928},{"atl":[[7.2,1],[8.2,29.18]],"id":8668222}],"con":true,"img":false}]}
{"op":"mcm","clk":"5322477561","pt":1646320684225,"mc":[{"id":"1.195532862","rc":[{"atl":[[7.4,6.25]],"id":8668222}],"con":true,"img":false}]}
{"op":"mcm","clk":"5322477569","pt":1646320684329,"mc":[{"id":"1.195532862","rc":[{"atl":[[8.2,15.29],[7.4,21.87],[8.4,3.75]],"id":8668222}],"con":true,"img":false}]}
{"op":"mcm","clk":"5322477591","pt":1646320684536,"mc":[{"id":"1.195532862","rc":[{"atb":[[1.05,0.08]],"id":35839928}],"con":true,"img":false}]}
{"op":"mcm","clk":"5322477607","pt":1646320684745,"mc":[{"id":"1.195532862","rc":[{"atb":[[4.2,0.12]],"id":28603683},{"atl":[[8.4,0]],"id":8668222}],"con":true,"img":false}]}
{"op":"mcm","clk":"5322477616","pt":1646320684851,"mc":[{"id":"1.195532862","rc":[{"atl":[[7.8,14.71]],"id":8668222}],"con":true,"img":false}]}
{"op":"mcm","clk":"5322477628","pt":1646320684905,"mc":[{"id":"1.195532862","rc":[{"atb":[[1.05,0]],"id":35839928}],"con":true,"img":false}]}
{"op":"mcm","clk":"5322477640","pt":1646320685009,"mc":[{"id":"1.195532862","rc":[{"atl":[[14,0.49]],"id":35839928},{"trd":[[14,0.57]],"ltp":14.0,"tv":0.57,"id":35839928}],"con":true,"img":false}]}
{"op":"mcm","clk":"5322477785","pt":1646320686528,"mc":[{"id":"1.195532862","rc":[{"atb":[[2.94,6.4]],"id":36042617}],"con":true,"img":false}]}
{"op":"mcm","clk":"5322477802","pt":1646320686735,"mc":[{"id":"1.195532862","rc":[{"atb":[[4.4,36.36]],"id":39693066}],"con":true,"img":false}]}
{"op":"mcm","clk":"5322477810","pt":1646320686844,"mc":[{"id":"1.195532862","rc":[{"atb":[[2.64,7.58]],"id":8668222}],"con":true,"img":false}]}
{"op":"mcm","clk":"5322477837","pt":1646320687113,"mc":[{"id":"1.195532862","rc":[{"atb":[[2.82,6.83]],"id":28603683}],"con":true,"img":false}]}
{"op":"mcm","clk":"5322477846","pt":1646320687217,"mc":[{"id":"1.195532862","rc":[{"atb":[[2.8,13.14]],"id":28691352}],"con":true,"img":false}]}
{"op":"mcm","clk":"5322477976","pt":1646320688843,"mc":[{"id":"1.195532862","rc":[{"atl":[[9.6,13.06]],"id":36042617}],"con":true,"img":false}]}
{"op":"mcm","clk":"5322477984","pt":1646320688948,"mc":[{"id":"1.195532862","rc":[{"atl":[[10,4.44]],"id":36042617}],"con":true,"img":false}]}
{"op":"mcm","clk":"5322477994","pt":1646320689001,"mc":[{"id":"1.195532862","rc":[{"atb":[[4.2,3.01]],"id":28603683}],"con":true,"img":false}]}
{"op":"mcm","clk":"5322478002","pt":1646320689156,"mc":[{"id":"1.195532862","rc":[{"atl":[[10.5,4.48]],"id":36042617}],"con":true,"img":false}]}
{"op":"mcm","clk":"5322478035","pt":1646320689524,"mc":[{"id":"1.195532862","rc":[{"atb":[[1.25,20]],"id":36042617},{"atl":[[10.5,0]],"id":36042617},{"atb":[[1.25,20]],"id":39693066},{"atb":[[1.25,20]],"id":35839928},{"atb":[[1.25,20]],"id":28603683},{"atb":[[1.25,20]],"id":8668222},{"atb":[[1.25,20]],"id":28691352}],"con":true,"img":false}]}
{"op":"mcm","clk":"5322478158","pt":1646320691034,"mc":[{"id":"1.195532862","rc":[{"atb":[[4.7,0]],"id":36042617}],"con":true,"img":false}]}
{"op":"mcm","clk":"5322478175","pt":1646320691245,"mc":[{"id":"1.195532862","rc":[{"atb":[[4.6,5.22]],"id":36042617}],"con":true,"img":false}]}
{"op":"mcm","clk":"5322478209","pt":1646320691607,"mc":[{"id":"1.195532862","rc":[{"atb":[[4.6,2]],"id":36042617}],"con":true,"img":false}]}
{"op":"mcm","clk":"5322478443","pt":1646320694747,"mc":[{"id":"1.195532862","rc":[{"atb":[[2.38,0]],"id":8668222}],"con":true,"img":false}]}
{"op":"mcm","clk":"5322478451","pt":1646320694850,"mc":[{"id":"1.195532862","rc":[{"atb":[[4.7,2.79]],"id":36042617}],"con":true,"img":false}]}
{"op":"mcm","clk":"5322478465","pt":1646320695008,"mc":[{"id":"1.195532862","rc":[{"atl":[[9.8,1.15]],"id":36042617}],"con":true,"img":false}]}
{"op":"mcm","clk":"5322478473","pt":1646320695113,"mc":[{"id":"1.195532862","rc":[{"atl":[[9.6,12.43],[10,15.55]],"id":36042617}],"con":true,"img":false}]}
{"op":"mcm","clk":"5322478526","pt":1646320695737,"mc":[{"id":"1.195532862","rc":[{"atl":[[8.2,36.12]],"id":8668222}],"con":true,"img":false}]}
{"op":"mcm","clk":"5322478535","pt":1646320695842,"mc":[{"id":"1.195532862","rc":[{"atb":[[5.8,1]],"id":36042617},{"atb":[[7,1]],"id":39693066},{"atb":[[5.3,1]],"id":28603683},{"atb":[[5.1,1]],"id":8668222},{"atl":[[9,0],[8.2,22.23]],"id":8668222},{"atb":[[3.6,1]],"id":28691352}],"con":true,"img":false}]}
{"op":"mcm","clk":"5322478552","pt":1646320696053,"mc":[{"id":"1.195532862","rc":[{"atb":[[3.55,0]],"id":28691352}],"con":true,"img":false}]}
{"op":"mcm","clk":"5322478626","pt":1646320696833,"mc":[{"id":"1.195532862","rc":[{"atb":[[3.6,0]],"id":28691352}],"con":true,"img":false}]}
{"op":"mcm","clk":"5322478637","pt":1646320696937,"mc":[{"id":"1.195532862","rc":[{"atb":[[3.55,3]],"id":28691352}],"con":true,"img":false}]}
{"op":"mcm","clk":"5322478669","pt":1646320697351,"mc":[{"id":"1.195532862","rc":[{"atl":[[1000,14.52]],"id":8668222}],"con":true,"img":false}]}
{"op":"mcm","clk":"5322478683","pt":1646320697511,"mc":[{"id":"1.195532862","rc":[{"atl":[[1000,14.1]],"id":8668222}],"con":true,"img":false}]}
{"op":"mcm","clk":"5322478699","pt":1646320697724,"mc":[{"id":"1.195532862","rc":[{"atl":[[1000,12]],"id":8668222}],"con":true,"img":false}]}
{"op":"mcm","clk":"5322478707","pt":1646320697829,"mc":[{"id":"1.195532862","rc":[{"atl":[[7,2.69]],"id":8668222}],"con":true,"img":false}]}
{"op":"mcm","clk":"5322478725","pt":1646320698037,"mc":[{"id":"1.195532862","rc":[{"atl":[[7.2,0]],"id":8668222}],"con":true,"img":false}]}
{"op":"mcm","clk":"5322478733","pt":1646320698139,"mc":[{"id":"1.195532862","rc":[{"atl":[[6.8,1]],"id":8668222}],"con":true,"img":false}]}
{"op":"mcm","clk":"5322478771","pt":1646320698610,"mc":[{"id":"1.195532862","rc":[{"atb":[[4.7,0]],"id":36042617},{"atb":[[4.2,0.12]],"id":28603683}],"con":true,"img":false}]}
{"op":"mcm","clk":"5322478945","pt":1646320700924,"mc":[{"id":"1.195532862","rc":[{"atb":[[3.8,5],[5.1,12]],"id":8668222},{"atl":[[7.2,6.45]],"id":8668222}],"con":true,"img":false}]}
{"op":"mcm","clk":"5322478950","pt":1646320701026,"mc":[{"id":"1.195532862","rc":[{"atl":[[7.4,15.62]],"id":8668222}],"con":true,"img":false}]}
{"op":"mcm","clk":"5322478960","pt":1646320701133,"mc":[{"id":"1.195532862","rc":[{"atb":[[3.8,0]],"id":8668222}],"con":true,"img":false}]}
{"op":"mcm","clk":"5322479033","pt":1646320702165,"mc":[{"id":"1.195532862","rc":[{"atl":[[9.6,24.06],[10,4.44]],"id":36042617}],"con":true,"img":false}]}
{"op":"mcm","clk":"5322479101","pt":1646320702848,"mc":[{"id":"1.195532862","rc":[{"atb":[[4.5,6]],"id":36042617},{"atb":[[4.1,7.7]],"id":28603683}],"con":true,"img":false}]}
{"op":"mcm","clk":"5322479235","pt":1646320704717,"mc":[{"id":"1.195532862","rc":[{"atl":[[7,0.58]],"id":8668222}],"con":true,"img":false}]}
{"op":"mcm","clk":"5322479247","pt":1646320704929,"mc":[{"id":"1.195532862","rc":[{"atb":[[5,0]],"id":8668222},{"atl":[[6.8,0]],"id":8668222}],"con":true,"img":false}]}
{"op":"mcm","clk":"5322479254","pt":1646320705034,"mc":[{"id":"1.195532862","rc":[{"atl":[[7,1.58]],"id":8668222}],"con":true,"img":false}]}
{"op":"mcm","clk":"5322479302","pt":1646320705969,"mc":[{"id":"1.195532862","rc":[{"atb":[[5.1,11]],"id":8668222}],"con":true,"img":false}]}
{"op":"mcm","clk":"5322479309","pt":1646320706072,"mc":[{"id":"1.195532862","rc":[{"atb":[[5.2,1]],"id":8668222}],"con":true,"img":false}]}
{"op":"mcm","clk":"5322479534","pt":1646320709356,"mc":[{"id":"1.195532862","rc":[{"atb":[[3.55,0]],"id":28691352},{"trd":[[3.55,6]],"ltp":3.55,"tv":6.0,"id":28691352}],"con":true,"img":false}]}
{"op":"mcm","clk":"5322479543","pt":1646320709459,"mc":[{"id":"1.195532862","rc":[{"atl":[[5,6.84]],"id":28691352}],"con":true,"img":false}]}
{"op":"mcm","clk":"5322479552","pt":1646320709563,"mc":[{"id":"1.195532862","rc":[{"spn":7.7,"spf":1.0,"id":36042617},{"spn":8.5,"spf":1.0,"id":39693066},{"spn":6.85,"spf":1.0,"id":28603683},{"spn":5.2,"spf":1.0,"id":8668222},{"atl":[[1000,13.65],[5.2,0]],"id":28691352}],"con":true,"img":false}]}
{"op":"mcm","clk":"5322479557","pt":1646320709669,"mc":[{"id":"1.195532862","rc":[{"atl":[[7.4,6.25],[7.2,0],[7.6,15.15]],"id":8668222}],"con":true,"img":false}]}
{"op":"mcm","clk":"5322479564","pt":1646320709770,"mc":[{"id":"1.195532862","rc":[{"atl":[[1000,12.96],[5,0]],"id":28691352}],"con":true,"img":false}]}
{"op":"mcm","clk":"5322479573","pt":1646320709875,"mc":[{"id":"1.195532862","rc":[{"atl":[[7,0.58]],"id":8668222},{"atl":[[4.3,1],[1000,12]],"id":28691352}],"con":true,"img":false}]}
{"op":"mcm","clk":"5322479581","pt":1646320709979,"mc":[{"id":"1.195532862","rc":[{"atl":[[7.2,1]],"id":8668222},{"atl":[[4.3,1.96]],"id":28691352}],"con":true,"img":false}]}
{"op":"mcm","clk":"5322479590","pt":1646320710031,"mc":[{"id":"1.195532862","rc":[{"atl":[[4.8,3.28],[1000,15.05]],"id":28691352}],"con":true,"img":false}]}
{"op":"mcm","clk":"5322479600","pt":1646320710135,"mc":[{"id":"1.195532862","rc":[{"atl":[[4.8,0],[4.4,1.47],[1000,12.3]],"id":28691352}],"con":true,"img":false}]}
{"op":"mcm","clk":"5322479607","pt":1646320710236,"mc":[{"id":"1.195532862","rc":[{"atl":[[1000,12],[4.2,1]],"id":28691352}],"con":true,"img":false}]}
{"op":"mcm","clk":"5322479612","pt":1646320710340,"mc":[{"id":"1.195532862","rc":[{"atl":[[4.5,20.3]],"id":28691352}],"con":true,"img":false}]}
{"op":"mcm","clk":"5322479653","pt":1646320710876,"mc":[{"id":"1.195532862","rc":[{"atl":[[4.3,0.96]],"id":28691352}],"con":true,"img":false}]}
{"op":"mcm","clk":"5322479660","pt":1646320710968,"mc":[{"id":"1.195532862","rc":[{"atl":[[4.4,2.47],[4.5,20]],"id":28691352}],"con":true,"img":false}]}
{"op":"mcm","clk":"5322479670","pt":1646320711070,"mc":[{"id":"1.195532862","rc":[{"atl":[[4.3,1.26],[4.2,0]],"id":28691352}],"con":true,"img":false}]}
{"op":"mcm","clk":"5322479678","pt":1646320711174,"mc":[{"id":"1.195532862","rc":[{"atl":[[4.4,3.47]],"id":28691352}],"con":true,"img":false}]}
{"op":"mcm","clk":"5322479778","pt":1646320712594,"mc":[{"id":"1.195532862","rc":[{"atl":[[4.4,2]],"id":28691352}],"con":true,"img":false}]}
{"op":"mcm","clk":"5322480231","pt":1646320720165,"mc":[{"id":"1.195532862","rc":[{"atl":[[8.6,32.89]],"id":8668222}],"con":true,"img":false}]}
{"op":"mcm","clk":"5322480242","pt":1646320720268,"mc":[{"id":"1.195532862","rc":[{"atb":[[7,4.63]],"id":39693066},{"atl":[[10.5,3.77]],"id":39693066},{"atb":[[9.6,2.96]],"id":35839928},{"atl":[[15.5,1.5]],"id":35839928},{"atb":[[5.3,6.07]],"id":28603683},{"atl":[[8.4,3.44]],"id":28603683},{"atl":[[7,4.22]],"id":8668222},{"atl":[[4.3,7.87]],"id":28691352}],"con":true,"img":false}]}
{"op":"mcm","clk":"5322480253","pt":1646320720373,"mc":[{"id":"1.195532862","rc":[{"atl":[[11,9.33],[11.5,3.81]],"id":39693066},{"atl":[[8.2,3.44],[8.8,5.13]],"id":28603683}],"con":true,"img":false}]}
{"op":"mcm","clk":"5322480261","pt":1646320720480,"mc":[{"id":"1.195532862","rc":[{"atb":[[3.15,11.17]],"id":28691352}],"con":true,"img":false}]}
{"op":"mcm","clk":"5322480269","pt":1646320720581,"mc":[{"id":"1.195532862","rc":[{"atl":[[11,8.33]],"id":39693066},{"atl":[[9.6,5.8],[8.6,1.33]],"id":28603683},{"atl":[[7.2,0]],"id":8668222},{"atl":[[4.4,1]],"id":28691352}],"con":true,"img":false}]}
{"op":"mcm","clk":"5322480276","pt":1646320720687,"mc":[{"id":"1.195532862","rc":[{"atl":[[10,1]],"id":39693066},{"atl":[[8.2,4.44]],"id":28603683},{"atl":[[6.8,1]],"id":8668222},{"atl":[[4.2,1]],"id":28691352}],"con":true,"img":false}]}
{"op":"mcm","clk":"5322480283","pt":1646320720792,"mc":[{"id":"1.195532862","rc":[{"atl":[[9.6,0]],"id":28603683}],"con":true,"img":false}]}
{"op":"mcm","clk":"5322480292","pt":1646320720896,"mc":[{"id":"1.195532862","rc":[{"atb":[[6,24.53]],"id":35839928},{"atl":[[9.2,3.12]],"id":28603683},{"atl":[[4.4,0]],"id":28691352}],"con":true,"img":false}]}
{"op":"mcm","clk":"5322480299","pt":1646320720958,"mc":[{"id":"1.195532862","rc":[{"atl":[[4.2,2]],"id":28691352}],"con":true,"img":false}]}
{"op":"mcm","clk":"5322480314","pt":1646320721157,"mc":[{"id":"1.195532862","rc":[{"atl":[[10.5,1.47]],"id":39693066},{"atl":[[7,0.58]],"id":8668222},{"atl":[[4.3,1.26]],"id":28691352}],"con":true,"img":false}]}
{"op":"mcm","clk":"5322480323","pt":1646320721260,"mc":[{"id":"1.195532862","rc":[{"atl":[[1000,13.65],[7,0]],"id":8668222}],"con":true,"img":false}]}
{"op":"mcm","clk":"5322480336","pt":1646320721468,"mc":[{"id":"1.195532862","rc":[{"atl":[[10,0]],"id":39693066},{"atb":[[6,20]],"id":35839928},{"atl":[[9.2,0]],"id":28603683},{"atl":[[6.8,0],[1000,12.58]],"id":8668222},{"atl":[[4.2,1]],"id":28691352}],"con":true,"img":false}]}
{"op":"mcm","clk":"5322480341","pt":1646320721573,"mc":[{"id":"1.195532862","rc":[{"atl":[[10.5,2.47]],"id":39693066},{"atl":[[7.2,1],[7.6,0],[7.8,29.42]],"id":8668222},{"atb":[[3.55,1.48]],"id":28691352},{"atl":[[4.4,1]],"id":28691352}],"con":true,"img":false}]}
{"op":"mcm","clk":"5322480355","pt":1646320721781,"mc":[{"id":"1.195532862","rc":[{"atl":[[7.8,36.12],[1000,12]],"id":8668222},{"atb":[[2.96,3.44]],"id":28691352}],"con":true,"img":false}]}
{"op":"mcm","clk":"5322480363","pt":1646320721884,"mc":[{"id":"1.195532862","rc":[{"atl":[[7.2,1.58]],"id":8668222}],"con":true,"img":false}]}
{"op":"mcm","clk":"5322480367","pt":1646320721988,"mc":[{"id":"1.195532862","rc":[{"atl":[[10.5,4.77]],"id":39693066},{"atb":[[7.2,9.62]],"id":35839928},{"atl":[[7.2,5.1]],"id":8668222},{"atl":[[4.2,6.81]],"id":28691352}],"con":true,"img":false}]}
{"op":"mcm","clk":"5322480378","pt":1646320722090,"mc":[{"id":"1.195532862","rc":[{"atl":[[4.4,2]],"id":28691352}],"con":true,"img":false}]}
{"op":"mcm","clk":"5322480384","pt":1646320722195,"mc":[{"id":"1.195532862","rc":[{"atl":[[4.4,1]],"id":28691352}],"con":true,"img":false}]}
{"op":"mcm","clk":"5322480396","pt":1646320722249,"mc":[{"id":"1.195532862","rc":[{"atl":[[7.8,29.42]],"id":8668222},{"atb":[[2.96,0]],"id":28691352},{"atl":[[4.1,1]],"id":28691352}],"con":true,"img":false}]}
{"op":"mcm","clk":"5322480419","pt":1646320722458,"mc":[{"id":"1.195532862","rc":[{"atb":[[5,0]],"id":39693066}],"con":true,"img":false}]}
{"op":"mcm","clk":"5322480441","pt":1646320722666,"mc":[{"id":"1.195532862","rc":[{"atb":[[1.01,11004.52]],"id":35839928}],"con":true,"img":false}]}
{"op":"mcm","clk":"5322480458","pt":1646320722879,"mc":[{"id":"1.195532862","rc":[{"atb":[[1.01,11003.68]],"id":35839928},{"atl":[[1000,14.52]],"id":8668222},{"atl":[[4.2,0]],"id":28691352}],"con":true,"img":false}]}
{"op":"mcm","clk":"5322480470","pt":1646320722983,"mc":[{"id":"1.195532862","rc":[{"atl":[[4.4,0]],"id":28691352}],"con":true,"img":false}]}
{"op":"mcm","clk":"5322480476","pt":1646320723087,"mc":[{"id":"1.195532862","rc":[{"atb":[[1.01,11002]],"id":35839928},{"atl":[[1000,14.1]],"id":8668222}],"con":true,"img":false}]}
{"op":"mcm","clk":"5322480484","pt":1646320723190,"mc":[{"id":"1.195532862","rc":[{"atb":[[9.8,1.68]],"id":35839928},{"atl":[[4.4,1]],"id":28691352}],"con":true,"img":false}]}
{"op":"mcm","clk":"5322480491","pt":1646320723296,"mc":[{"id":"1.195532862","rc":[{"atl":[[1000,12]],"id":8668222}],"con":true,"img":false}]}
{"op":"mcm","clk":"5322480500","pt":1646320723400,"mc":[{"id":"1.195532862","rc":[{"atl":[[7,2.1]],"id":8668222}],"con":true,"img":false}]}
{"op":"mcm","clk":"5322480524","pt":1646320723660,"mc":[{"id":"1.195532862","rc":[{"atl":[[7.2,4.1]],"id":8668222}],"con":true,"img":false}]}
{"op":"mcm","clk":"5322480533","pt":1646320723766,"mc":[{"id":"1.195532862","rc":[{"atl":[[6.8,1]],"id":8668222}],"con":true,"img":false}]}
{"op":"mcm","clk":"5322480542","pt":1646320723868,"mc":[{"id":"1.195532862","rc":[{"atb":[[9.6,2.91]],"id":35839928},{"atl":[[7.2,0.58]],"id":8668222},{"atl":[[4.1,0]],"id":28691352}],"con":true,"img":false}]}
{"op":"mcm","clk":"5322480553","pt":1646320723972,"mc":[{"id":"1.195532862","rc":[{"atl":[[4.4,2]],"id":28691352}],"con":true,"img":false}]}
{"op":"mcm","clk":"5322480561","pt":1646320724076,"mc":[{"id":"1.195532862","rc":[{"atb":[[9.6,0.43]],"id":35839928}],"con":true,"img":false}]}
{"op":"mcm","clk":"5322480572","pt":1646320724181,"mc":[{"id":"1.195532862","rc":[{"atb":[[9.8,4.16]],"id":35839928},{"atl":[[4.1,7.03]],"id":28691352}],"con":true,"img":false}]}
{"op":"mcm","clk":"5322480586","pt":1646320724389,"mc":[{"id":"1.195532862","rc":[{"atl":[[4.4,1]],"id":28691352}],"con":true,"img":false}]}
{"op":"mcm","clk":"5322480592","pt":1646320724493,"mc":[{"id":"1.195532862","rc":[{"atl":[[4,1]],"id":28691352}],"con":true,"img":false}]}
{"op":"mcm","clk":"5322480602","pt":1646320724597,"mc":[{"id":"1.195532862","rc":[{"atl":[[7,0]],"id":8668222}],"con":true,"img":false}]}
{"op":"mcm","clk":"5322480608","pt":1646320724701,"mc":[{"id":"1.195532862","rc":[{"atl":[[4.1,0]],"id":28691352}],"con":true,"img":false}]}
{"op":"mcm","clk":"5322480622","pt":1646320724860,"mc":[{"id":"1.195532862","rc":[{"atl":[[6.8,0]],"id":8668222}],"con":true,"img":false}]}
{"op":"mcm","clk":"5322480629","pt":1646320724963,"mc":[{"id":"1.195532862","rc":[{"atb":[[6.8,0]],"id":39693066},{"atb":[[9.4,0]],"id":35839928},{"atb":[[5.2,0]],"id":28603683},{"atl":[[7.2,1.58]],"id":8668222}],"con":true,"img":false}]}
{"op":"mcm","clk":"5322480638","pt":1646320725068,"mc":[{"id":"1.195532862","rc":[{"atl":[[6.8,3.75]],"id":8668222},{"atl":[[4.3,0.96]],"id":28691352}],"con":true,"img":false}]}
{"op":"mcm","clk":"5322480643","pt":1646320725172,"mc":[{"id":"1.195532862","rc":[{"atb":[[6.6,3.5]],"id":39693066},{"atb":[[9.2,3.5]],"id":35839928},{"atb":[[5.1,3.5]],"id":28603683},{"atl":[[4.1,0.3]],"id":28691352}],"con":true,"img":false}]}
{"op":"mcm","clk":"5322480653","pt":1646320725379,"mc":[{"id":"1.195532862","rc":[{"atl":[[8.6,6.59],[8.8,0]],"id":28603683},{"atl":[[7.2,7.03],[7.4,0]],"id":8668222},{"atl":[[4,0]],"id":28691352}],"con":true,"img":false}]}
{"op":"mcm","clk":"5322480657","pt":1646320725484,"mc":[{"id":"1.195532862","rc":[{"atb":[[6.6,0]],"id":39693066},{"atb":[[9.2,0]],"id":35839928},{"atb":[[5.1,0]],"id":28603683},{"atl":[[7.8,33.21],[6.6,1]],"id":8668222},{"atl":[[4.4,2],[4.2,6.81]],"id":28691352}],"con":true,"img":false}]}
{"op":"mcm","clk":"5322480668","pt":1646320725690,"mc":[{"id":"1.195532862","rc":[{"atl":[[4.4,1]],"id":28691352}],"con":true,"img":false}]}
{"op":"mcm","clk":"5322480675","pt":1646320725796,"mc":[{"id":"1.195532862","rc":[{"atl":[[4.1,1.3]],"id":28691352}],"con":true,"img":false}]}
{"op":"mcm","clk":"5322480686","pt":1646320726005,"mc":[{"id":"1.195532862","rc":[{"atb":[[7,3.63]],"id":39693066},{"atb":[[5.3,5.07]],"id":28603683},{"atl":[[7.8,29.42]],"id":8668222},{"atl":[[4.4,0]],"id":28691352}],"con":true,"img":false}]}
{"op":"mcm","clk":"5322480693","pt":1646320726059,"mc":[{"id":"1.195532862","rc":[{"atb":[[7.2,1]],"id":39693066},{"atb":[[5.4,1]],"id":28603683},{"atl":[[4.1,2.3]],"id":28691352}],"con":true,"img":false}]}
{"op":"mcm","clk":"5322480721","pt":1646320726558,"mc":[{"id":"1.195532862","rc":[{"atl":[[4,2.52]],"id":28691352}],"con":true,"img":false}]}
{"op":"mcm","clk":"5322480735","pt":1646320726764,"mc":[{"id":"1.195532862","rc":[{"atl":[[6.8,0]],"id":8668222},{"atl":[[4.1,1.3],[4.2,0]],"id":28691352}],"con":true,"img":false}]}
{"op":"mcm","clk":"5322480746","pt":1646320726868,"mc":[{"id":"1.195532862","rc":[{"atl":[[3.95,1]],"id":28691352}],"con":true,"img":false}]}
{"op":"mcm","clk":"5322480756","pt":1646320726973,"mc":[{"id":"1.195532862","rc":[{"atl":[[4.1,0.3]],"id":28691352}],"con":true,"img":false}]}
{"op":"mcm","clk":"5322480765","pt":1646320727076,"mc":[{"id":"1.195532862","rc":[{"atl":[[3.95,2]],"id":28691352}],"con":true,"img":false}]}
{"op":"mcm","clk":"5322480775","pt":1646320727285,"mc":[{"id":"1.195532862","rc":[{"atl":[[6.6,0]],"id":8668222}],"con":true,"img":false}]}
{"op":"mcm","clk":"5322480784","pt":1646320727389,"mc":[{"id":"1.195532862","rc":[{"atl":[[8.2,36.12],[7.8,14.71],[7,1]],"id":8668222}],"con":true,"img":false}]}
{"op":"mcm","clk":"5322480799","pt":1646320727597,"mc":[{"id":"1.195532862","rc":[{"atl":[[7,4.63]],"id":8668222},{"atl":[[3.95,9.39]],"id":28691352}],"con":true,"img":false}]}
{"op":"mcm","clk":"5322480810","pt":1646320727701,"mc":[{"id":"1.195532862","rc":[{"atl":[[4.1,0]],"id":28691352}],"con":true,"img":false}]}
{"op":"mcm","clk":"5322480818","pt":1646320727803,"mc":[{"id":"1.195532862","rc":[{"atl":[[4,2.83]],"id":28691352}],"con":true,"img":false}]}
{"op":"mcm","clk":"5322480852","pt":1646320728168,"mc":[{"id":"1.195532862","rc":[{"atl":[[1000,14.52]],"id":8668222}],"con":true,"img":false}]}
{"op":"mcm","clk":"5322480868","pt":1646320728373,"mc":[{"id":"1.195532862","rc":[{"atl":[[1000,14.1]],"id":8668222}],"con":true,"img":false}]}
{"op":"mcm","clk":"5322480882","pt":1646320728583,"mc":[{"id":"1.195532862","rc":[{"atl":[[1000,12]],"id":8668222}],"con":true,"img":false}]}
{"op":"mcm","clk":"5322480891","pt":1646320728687,"mc":[{"id":"1.195532862","rc":[{"atb":[[5,6.08]],"id":39693066},{"atl":[[6.8,2.1]],"id":8668222}],"con":true,"img":false}]}
{"op":"mcm","clk":"5322480908","pt":1646320728899,"mc":[{"id":"1.195532862","rc":[{"atl":[[7,3.63]],"id":8668222}],"con":true,"img":false}]}
{"op":"mcm","clk":"5322480917","pt":1646320729006,"mc":[{"id":"1.195532862","rc":[{"atl":[[6.6,1]],"id":8668222}],"con":true,"img":false}]}
{"op":"mcm","clk":"5322480943","pt":1646320729265,"mc":[{"id":"1.195532862","rc":[{"atl":[[7,0]],"id":8668222},{"atl":[[4,2.52]],"id":28691352}],"con":true,"img":false}]}
{"op":"mcm","clk":"5322480954","pt":1646320729370,"mc":[{"id":"1.195532862","rc":[{"atl":[[3.95,9.7]],"id":28691352}],"con":true,"img":false}]}
{"op":"mcm","clk":"5322481025","pt":1646320730207,"mc":[{"id":"1.195532862","rc":[{"atb":[[9.8,2.47]],"id":35839928}],"con":true,"img":false}]}
{"op":"mcm","clk":"5322481044","pt":1646320730364,"mc":[{"id":"1.195532862","rc":[{"atl":[[11,0],[11.5,13.33]],"id":39693066},{"atl":[[7.2,0.58],[6.6,4.89],[7,6.67]],"id":8668222}],"con":true,"img":false}]}
{"op":"mcm","clk":"5322481054","pt":1646320730471,"mc":[{"id":"1.195532862","rc":[{"atb":[[1.01,11004.52]],"id":35839928}],"con":true,"img":false}]}
{"op":"mcm","clk":"5322481062","pt":1646320730575,"mc":[{"id":"1.195532862","rc":[{"atl":[[11.5,16.33]],"id":39693066}],"con":true,"img":false}]}
{"op":"mcm","clk":"5322481068","pt":1646320730681,"mc":[{"id":"1.195532862","rc":[{"atb":[[1.01,11003.68]],"id":35839928}],"con":true,"img":false}]}
{"op":"mcm","clk":"5322481083","pt":1646320730891,"mc":[{"id":"1.195532862","rc":[{"atl":[[11.5,13.33]],"id":39693066},{"atb":[[1.01,11002]],"id":35839928}],"con":true,"img":false}]}
{"op":"mcm","clk":"5322481091","pt":1646320730996,"mc":[{"id":"1.195532862","rc":[{"atb":[[10,1.68]],"id":35839928}],"con":true,"img":false}]}
{"op":"mcm","clk":"5322481107","pt":1646320731204,"mc":[{"id":"1.195532862","rc":[{"atb":[[9.8,2.42]],"id":35839928}],"con":true,"img":false}]}
{"op":"mcm","clk":"5322481124","pt":1646320731363,"mc":[{"id":"1.195532862","rc":[{"atb":[[9.8,0]],"id":35839928}],"con":true,"img":false}]}
{"op":"mcm","clk":"5322481132","pt":1646320731463,"mc":[{"id":"1.195532862","rc":[{"atb":[[10,4.1]],"id":35839928}],"con":true,"img":false}]}
{"op":"mcm","clk":"5322481293","pt":1646320733609,"mc":[{"id":"1.195532862","rc":[{"atb":[[3.55,0]],"id":28691352}],"con":true,"img":false}]}
{"op":"mcm","clk":"5322481341","pt":1646320734180,"mc":[{"id":"1.195532862","rc":[{"atl":[[8.2,22.23],[7.4,15.62]],"id":8668222},{"atl":[[4,0]],"id":28691352}],"con":true,"img":false}]}
{"op":"mcm","clk":"5322481396","pt":1646320734995,"mc":[{"id":"1.195532862","rc":[{"atl":[[3.95,8.7]],"id":28691352}],"con":true,"img":false}]}
{"op":"mcm","clk":"5322481406","pt":1646320735093,"mc":[{"id":"1.195532862","rc":[{"atl":[[4.4,1]],"id":28691352}],"con":true,"img":false}]}
{"op":"mcm","clk":"5322481440","pt":1646320735565,"mc":[{"id":"1.195532862","rc":[{"atl":[[6.6,15.89]],"id":8668222}],"con":true,"img":false}]}
{"op":"mcm","clk":"5322481446","pt":1646320735670,"mc":[{"id":"1.195532862","rc":[{"atl":[[9,12.5]],"id":28603683}],"con":true,"img":false}]}
{"op":"mcm","clk":"5322481452","pt":1646320735774,"mc":[{"id":"1.195532862","rc":[{"atb":[[3.8,4.38]],"id":8668222},{"atl":[[7.4,0],[7.6,15.15]],"id":8668222},{"atb":[[2.8,68.7],[2.92,0]],"id":28691352}],"con":true,"img":false}]}
{"op":"mcm","clk":"5322481458","pt":1646320735878,"mc":[{"id":"1.195532862","rc":[{"atl":[[6.8,0]],"id":8668222}],"con":true,"img":false}]}
{"op":"mcm","clk":"5322481464","pt":1646320735983,"mc":[{"id":"1.195532862","rc":[{"atl":[[4.4,0]],"id":28691352}],"con":true,"img":false}]}
{"op":"mcm","clk":"5322481471","pt":1646320736088,"mc":[{"id":"1.195532862","rc":[{"atb":[[3.8,0]],"id":8668222},{"atl":[[3.9,1]],"id":28691352}],"con":true,"img":false}]}
{"op":"mcm","clk":"5322481480","pt":1646320736191,"mc":[{"id":"1.195532862","rc":[{"atl":[[1000,14.52]],"id":8668222}],"con":true,"img":false}]}
{"op":"mcm","clk":"5322481496","pt":1646320736398,"mc":[{"id":"1.195532862","rc":[{"atl":[[1000,14.1]],"id":8668222}],"con":true,"img":false}]}
{"op":"mcm","clk":"5322481512","pt":1646320736608,"mc":[{"id":"1.195532862","rc":[{"atl":[[6.4,2.9],[1000,12]],"id":8668222}],"con":true,"img":false}]}
{"op":"mcm","clk":"5322481520","pt":1646320736715,"mc":[{"id":"1.195532862","rc":[{"atl":[[6.4,5]],"id":8668222}],"con":true,"img":false}]}
{"op":"mcm","clk":"5322481528","pt":1646320736770,"mc":[{"id":"1.195532862","rc":[{"atl":[[6.6,11]],"id":8668222},{"atb":[[3.55,1.48]],"id":28691352},{"atl":[[3.95,1.3]],"id":28691352}],"con":true,"img":false}]}
{"op":"mcm","clk":"5322481534","pt":1646320736873,"mc":[{"id":"1.195532862","rc":[{"atl":[[6.2,1]],"id":8668222}],"con":true,"img":false}]}
{"op":"mcm","clk":"5322481555","pt":1646320737242,"mc":[{"id":"1.195532862","rc":[{"atl":[[3.95,0.3]],"id":28691352}],"con":true,"img":false}]}
{"op":"mcm","clk":"5322481564","pt":1646320737351,"mc":[{"id":"1.195532862","rc":[{"atl":[[4.4,1]],"id":28691352}],"con":true,"img":false}]}
{"op":"mcm","clk":"5322481588","pt":1646320737657,"mc":[{"id":"1.195532862","rc":[{"atb":[[10,2.42]],"id":35839928}],"con":true,"img":false}]}
{"op":"mcm","clk":"5322481601","pt":1646320737869,"mc":[{"id":"1.195532862","rc":[{"atl":[[6.2,5.19]],"id":8668222},{"atl":[[3.9,8.52]],"id":28691352}],"con":true,"img":false}]}
{"op":"mcm","clk":"5322481609","pt":1646320737978,"mc":[{"id":"1.195532862","rc":[{"atb":[[1.01,11004.52]],"id":35839928},{"atl":[[3.9,7.52]],"id":28691352}],"con":true,"img":false}]}
{"op":"mcm","clk":"5322481614","pt":1646320738078,"mc":[{"id":"1.195532862","rc":[{"atb":[[1.01,11003.68]],"id":35839928}],"con":true,"img":false}]}
{"op":"mcm","clk":"5322481625","pt":1646320738138,"mc":[{"id":"1.195532862","rc":[{"atl":[[3.85,1]],"id":28691352}],"con":true,"img":false}]}
{"op":"mcm","clk":"5322481635","pt":1646320738241,"mc":[{"id":"1.195532862","rc":[{"atb":[[1.01,11002]],"id":35839928}],"con":true,"img":false}]}
{"op":"mcm","clk":"5322481642","pt":1646320738345,"mc":[{"id":"1.195532862","rc":[{"atb":[[10.5,1.68]],"id":35839928}],"con":true,"img":false}]}
{"op":"mcm","clk":"5322481649","pt":1646320738447,"mc":[{"id":"1.195532862","rc":[{"atl":[[3.95,0]],"id":28691352}],"con":true,"img":false}]}
{"op":"mcm","clk":"5322481652","pt":1646320738554,"mc":[{"id":"1.195532862","rc":[{"atl":[[3.9,7.82]],"id":28691352}],"con":true,"img":false}]}
{"op":"mcm","clk":"5322481658","pt":1646320738657,"mc":[{"id":"1.195532862","rc":[{"atl":[[3.9,0.3]],"id":28691352}],"con":true,"img":false}]}
{"op":"mcm","clk":"5322481674","pt":1646320738869,"mc":[{"id":"1.195532862","rc":[{"atl":[[3.85,0]],"id":28691352}],"con":true,"img":false}]}
{"op":"mcm","clk":"5322481682","pt":1646320738972,"mc":[{"id":"1.195532862","rc":[{"atl":[[4.4,2]],"id":28691352}],"con":true,"img":false}]}
{"op":"mcm","clk":"5322481744","pt":1646320739770,"mc":[{"id":"1.195532862","rc":[{"atl":[[6.4,2.1]],"id":8668222}],"con":true,"img":false}]}
{"op":"mcm","clk":"5322481758","pt":1646320739970,"mc":[{"id":"1.195532862","rc":[{"atl":[[4.2,6.81]],"id":28691352}],"con":true,"img":false}]}
{"op":"mcm","clk":"5322481791","pt":1646320740341,"mc":[{"id":"1.195532862","rc":[{"atl":[[4.4,1]],"id":28691352}],"con":true,"img":false}]}
{"op":"mcm","clk":"5322481804","pt":1646320740452,"mc":[{"id":"1.195532862","rc":[{"atl":[[4.1,1]],"id":28691352}],"con":true,"img":false}]}
{"op":"mcm","clk":"5322481814","pt":1646320740554,"mc":[{"id":"1.195532862","rc":[{"atl":[[7.4,15.62]],"id":8668222}],"con":true,"img":false}]}
{"op":"mcm","clk":"5322481849","pt":1646320740979,"mc":[{"id":"1.195532862","rc":[{"atl":[[4.4,0]],"id":28691352}],"con":true,"img":false}]}
{"op":"mcm","clk":"5322481860","pt":1646320741036,"mc":[{"id":"1.195532862","rc":[{"atl":[[4.1,2]],"id":28691352}],"con":true,"img":false}]}
{"op":"mcm","clk":"5322481867","pt":1646320741140,"mc":[{"id":"1.195532862","rc":[{"atb":[[4.7,5.07]],"id":39693066},{"atb":[[4.1,5]],"id":36042617},{"atb":[[7.2,19.24],[6,0]],"id":35839928},{"atl":[[17,9.38],[18.5,5.71],[14,0]],"id":35839928},{"atl":[[10.5,0]],"id":28603683},{"atb":[[4,0],[4.2,13.68]],"id":8668222},{"atl":[[7.4,30.77],[8.6,0],[7.6,0]],"id":8668222},{"atb":[[2.8,13.14],[2.9,131.58]],"id":28691352}],"con":true,"img":false}]}
{"op":"mcm","clk":"5322481925","pt":1646320741701,"mc":[{"id":"1.195532862","rc":[{"atb":[[4.7,0]],"id":39693066},{"atb":[[4.1,0]],"id":36042617}],"con":true,"img":false}]}
{"op":"mcm","clk":"5322481945","pt":1646320741948,"mc":[{"id":"1.195532862","rc":[{"atb":[[1.02,4.96]],"id":36042617},{"atb":[[1.03,2.95]],"id":39693066},{"atb":[[1.04,2.88]],"id":35839928},{"atb":[[1.02,4.98]],"id":28603683},{"atb":[[1.02,4.97]],"id":8668222},{"atb":[[1.02,5.07]],"id":28691352}],"con":true,"img":false}]}
{"op":"mcm","clk":"5322481975","pt":1646320742477,"mc":[{"id":"1.195532862","rc":[{"atb":[[1.03,0.2]],"id":39693066},{"atb":[[1.02,2.21]],"id":36042617},{"atb":[[1.04,0.13]],"id":35839928},{"atb":[[1.02,2.23]],"id":28603683},{"atb":[[1.02,2.22]],"id":8668222},{"atb":[[1.02,2.33]],"id":28691352}],"con":true,"img":false}]}
{"op":"mcm","clk":"5322481999","pt":1646320742744,"mc":[{"id":"1.195532862","rc":[{"atl":[[4,2.52]],"id":28691352}],"con":true,"img":false}]}
{"op":"mcm","clk":"5322482006","pt":1646320742850,"mc":[{"id":"1.195532862","rc":[{"atb":[[1.02,1.99]],"id":36042617},{"atb":[[1.03,0]],"id":39693066},{"atb":[[1.04,0]],"id":35839928},{"atb":[[1.02,1.99]],"id":28603683},{"atb":[[1.02,1.99]],"id":8668222},{"atb":[[1.02,1.99]],"id":28691352}],"con":true,"img":false}]}
{"op":"mcm","clk":"5322482017","pt":1646320742953,"mc":[{"id":"1.195532862","rc":[{"atl":[[4.3,4.37],[4.1,1]],"id":28691352}],"con":true,"img":false}]}
{"op":"mcm","clk":"5322482025","pt":1646320743061,"mc":[{"id":"1.195532862","rc":[{"atb":[[4.9,0.22]],"id":36042617},{"atb":[[5.4,0.2]],"id":39693066},{"atb":[[8,0.13]],"id":35839928},{"atb":[[4.4,0.24]],"id":28603683},{"atb":[[4.6,0.23]],"id":8668222},{"atb":[[3.25,0.34]],"id":28691352},{"atl":[[3.95,1]],"id":28691352}],"con":true,"img":false}]}
{"op":"mcm","clk":"5322482032","pt":1646320743160,"mc":[{"id":"1.195532862","rc":[{"atl":[[6.4,0]],"id":8668222},{"atl":[[4.3,0.96]],"id":28691352}],"con":true,"img":false}]}
{"op":"mcm","clk":"5322482090","pt":1646320743948,"mc":[{"id":"1.195532862","rc":[{"atl":[[4.1,0]],"id":28691352}],"con":true,"img":false}]}
{"op":"mcm","clk":"5322482100","pt":1646320744048,"mc":[{"id":"1.195532862","rc":[{"atb":[[5.1,5.31]],"id":36042617},{"atl":[[3.95,2]],"id":28691352}],"con":true,"img":false}]}
{"op":"mcm","clk":"5322482144","pt":1646320744572,"mc":[{"id":"1.195532862","rc":[{"atl":[[1000,14.52]],"id":8668222},{"atl":[[4,0]],"id":28691352}],"con":true,"img":false}]}
{"op":"mcm","clk":"5322482160","pt":1646320744781,"mc":[{"id":"1.195532862","rc":[{"atl":[[1000,14.1]],"id":8668222}],"con":true,"img":false}]}
{"op":"mcm","clk":"5322482166","pt":1646320744887,"mc":[{"id":"1.195532862","rc":[{"atl":[[1000,12]],"id":8668222},{"atl":[[3.95,0]],"id":28691352}],"con":true,"img":false}]}
{"op":"mcm","clk":"5322482175","pt":1646320744943,"mc":[{"id":"1.195532862","rc":[{"atl":[[6,2.1]],"id":8668222},{"atl":[[4.1,2]],"id":28691352}],"con":true,"img":false}]}
{"op":"mcm","clk":"5322482189","pt":1646320745151,"mc":[{"id":"1.195532862","rc":[{"atl":[[6.2,4.19]],"id":8668222}],"con":true,"img":false}]}
{"op":"mcm","clk":"5322482196","pt":1646320745257,"mc":[{"id":"1.195532862","rc":[{"atl":[[5.9,1]],"id":8668222}],"con":true,"img":false}]}
{"op":"mcm","clk":"5322482241","pt":1646320745777,"mc":[{"id":"1.195532862","rc":[{"atl":[[9.4,17.86]],"id":28603683}],"con":true,"img":false}]}
{"op":"mcm","clk":"5322482250","pt":1646320745881,"mc":[{"id":"1.195532862","rc":[{"atl":[[15,0],[15.5,4.24]],"id":35839928}],"con":true,"img":false}]}
{"op":"mcm","clk":"5322482256","pt":1646320745984,"mc":[{"id":"1.195532862","rc":[{"atb":[[10,2.29]],"id":35839928},{"atl":[[6.2,0]],"id":8668222}],"con":true,"img":false}]}
{"op":"mcm","clk":"5322482267","pt":1646320746147,"mc":[{"id":"1.195532862","rc":[{"atl":[[14.5,0]],"id":35839928}],"con":true,"img":false}]}
{"op":"mcm","clk":"5322482274","pt":1646320746247,"mc":[{"id":"1.195532862","rc":[{"atl":[[15,1]],"id":35839928}],"con":true,"img":false}]}
{"op":"mcm","clk":"5322482281","pt":1646320746355,"mc":[{"id":"1.195532862","rc":[{"atb":[[10,0]],"id":35839928}],"con":true,"img":false}]}
{"op":"mcm","clk":"5322482290","pt":1646320746456,"mc":[{"id":"1.195532862","rc":[{"atb":[[10.5,3.98]],"id":35839928}],"con":true,"img":false}]}
{"op":"mcm","clk":"5322482309","pt":1646320746770,"mc":[{"id":"1.195532862","rc":[{"atb":[[4.5,0]],"id":36042617}],"con":true,"img":false}]}
{"op":"mcm","clk":"5322482317","pt":1646320746877,"mc":[{"id":"1.195532862","rc":[{"atl":[[5.9,5.45]],"id":8668222}],"con":true,"img":false}]}
{"op":"mcm","clk":"5322482409","pt":1646320748185,"mc":[{"id":"1.195532862","rc":[{"atl":[[4,2.52]],"id":28691352}],"con":true,"img":false}]}
{"op":"mcm","clk":"5322482425","pt":1646320748447,"mc":[{"id":"1.195532862","rc":[{"atl":[[4.1,1]],"id":28691352}],"con":true,"img":false}]}
{"op":"mcm","clk":"5322482439","pt":1646320748553,"mc":[{"id":"1.195532862","rc":[{"atb":[[10.5,2.29]],"id":35839928},{"atl":[[3.95,1]],"id":28691352}],"con":true,"img":false}]}
{"op":"mcm","clk":"5322482455","pt":1646320748760,"mc":[{"id":"1.195532862","rc":[{"atb":[[1.01,11004.52]],"id":35839928},{"atb":[[3.55,0]],"id":28691352}],"con":true,"img":false}]}
{"op":"mcm","clk":"5322482469","pt":1646320748968,"mc":[{"id":"1.195532862","rc":[{"atb":[[1.01,11003.68]],"id":35839928},{"atl":[[4.1,0]],"id":28691352}],"con":true,"img":false}]}
{"op":"mcm","clk":"5322482476","pt":1646320749077,"mc":[{"id":"1.195532862","rc":[{"atl":[[3.95,2]],"id":28691352}],"con":true,"img":false}]}
{"op":"mcm","clk":"5322482492","pt":1646320749180,"mc":[{"id":"1.195532862","rc":[{"atb":[[1.01,11002]],"id":35839928}],"con":true,"img":false}]}
{"op":"mcm","clk":"5322482499","pt":1646320749282,"mc":[{"id":"1.195532862","rc":[{"atb":[[11,1.68]],"id":35839928}],"con":true,"img":false}]}
{"op":"mcm","clk":"5322482530","pt":1646320749544,"mc":[{"id":"1.195532862","rc":[{"atl":[[4,0]],"id":28691352}],"con":true,"img":false}]}
{"op":"mcm","clk":"5322482548","pt":1646320749860,"mc":[{"id":"1.195532862","rc":[{"atl":[[3.95,0]],"id":28691352}],"con":true,"img":false}]}
{"op":"mcm","clk":"5322482559","pt":1646320749963,"mc":[{"id":"1.195532862","rc":[{"atl":[[4.1,2]],"id":28691352}],"con":true,"img":false}]}
{"op":"mcm","clk":"5322482601","pt":1646320750583,"mc":[{"id":"1.195532862","rc":[{"atl":[[7.8,22.06]],"id":8668222}],"con":true,"img":false}]}
{"op":"mcm","clk":"5322482680","pt":1646320751679,"mc":[{"id":"1.195532862","rc":[{"atl":[[6,0]],"id":8668222}],"con":true,"img":false}]}
{"op":"mcm","clk":"5322482699","pt":1646320751887,"mc":[{"id":"1.195532862","rc":[{"atl":[[6.2,3.56]],"id":8668222}],"con":true,"img":false}]}
{"op":"mcm","clk":"5322482714","pt":1646320752095,"mc":[{"id":"1.195532862","rc":[{"atl":[[16,9.32]],"id":35839928}],"con":true,"img":false}]}
{"op":"mcm","clk":"5322482723","pt":1646320752151,"mc":[{"id":"1.195532862","rc":[{"atl":[[16,2.65],[15.5,1.5]],"id":35839928}],"con":true,"img":false}]}
{"op":"mcm","clk":"5322482733","pt":1646320752257,"mc":[{"id":"1.195532862","rc":[{"atl":[[6.2,0]],"id":8668222}],"con":true,"img":false}]}
{"op":"mcm","clk":"5322482740","pt":1646320752358,"mc":[{"id":"1.195532862","rc":[{"atl":[[15,0]],"id":35839928}],"con":true,"img":false}]}
{"op":"mcm","clk":"5322482745","pt":1646320752465,"mc":[{"id":"1.195532862","rc":[{"atl":[[15.5,2.5]],"id":35839928}],"con":true,"img":false}]}
{"op":"mcm","clk":"5322482762","pt":1646320752674,"mc":[{"id":"1.195532862","rc":[{"atl":[[15.5,2.4]],"id":35839928}],"con":true,"img":false}]}
{"op":"mcm","clk":"5322482780","pt":1646320752894,"mc":[{"id":"1.195532862","rc":[{"atl":[[15.5,1]],"id":35839928}],"con":true,"img":false}]}
{"op":"mcm","clk":"5322482783","pt":1646320752985,"mc":[{"id":"1.195532862","rc":[{"atl":[[16.5,1.4]],"id":35839928}],"con":true,"img":false}]}
{"op":"mcm","clk":"5322482806","pt":1646320753352,"mc":[{"id":"1.195532862","rc":[{"atl":[[5.8,2.52]],"id":8668222}],"con":true,"img":false}]}
{"op":"mcm","clk":"5322482816","pt":1646320753561,"mc":[{"id":"1.195532862","rc":[{"atl":[[5.9,0]],"id":8668222}],"con":true,"img":false}]}
{"op":"mcm","clk":"5322482823","pt":1646320753663,"mc":[{"id":"1.195532862","rc":[{"atl":[[5.7,1]],"id":8668222}],"con":true,"img":false}]}
{"op":"mcm","clk":"5322482898","pt":1646320754656,"mc":[{"id":"1.195532862","rc":[{"atb":[[3.55,1.48]],"id":28691352}],"con":true,"img":false}]}
{"op":"mcm","clk":"5322482909","pt":1646320754862,"mc":[{"id":"1.195532862","rc":[{"atb":[[3.1,4.35]],"id":28691352}],"con":true,"img":false}]}
{"op":"mcm","clk":"5322482924","pt":1646320755077,"mc":[{"id":"1.195532862","rc":[{"atl":[[4,2.52]],"id":28691352}],"con":true,"img":false}]}
{"op":"mcm","clk":"5322482943","pt":1646320755285,"mc":[{"id":"1.195532862","rc":[{"atl":[[4.1,1]],"id":28691352}],"con":true,"img":false}]}
{"op":"mcm","clk":"5322482951","pt":1646320755387,"mc":[{"id":"1.195532862","rc":[{"atb":[[3.1,0]],"id":28691352},{"atl":[[3.95,1]],"id":28691352}],"con":true,"img":false}]}
{"op":"mcm","clk":"5322482978","pt":1646320755701,"mc":[{"id":"1.195532862","rc":[{"atl":[[9.8,28.41]],"id":28603683}],"con":true,"img":false}]}
{"op":"mcm","clk":"5322482995","pt":1646320755863,"mc":[{"id":"1.195532862","rc":[{"atb":[[4.5,7.5]],"id":36042617},{"atl":[[9.6,29.2]],"id":36042617},{"atb":[[7,5.38]],"id":39693066},{"atl":[[10.5,7.97]],"id":39693066},{"atb":[[10,3.85]],"id":35839928},{"atl":[[15,0.84]],"id":35839928},{"atb":[[5.3,13.02]],"id":28603683},{"atb":[[5.1,19.29]],"id":8668222},{"atl":[[4.1,0],[4.2,24.54]],"id":28691352}],"con":true,"img":false}]}
{"op":"mcm","clk":"5322483011","pt":1646320755971,"mc":[{"id":"1.195532862","rc":[{"atl":[[3.95,2]],"id":28691352}],"con":true,"img":false}]}
{"op":"mcm","clk":"5322483104","pt":1646320756902,"mc":[{"id":"1.195532862","rc":[{"atl":[[4,0]],"id":28691352}],"con":true,"img":false}]}
{"op":"mcm","clk":"5322483122","pt":1646320757059,"mc":[{"id":"1.195532862","rc":[{"atb":[[7,5.26]],"id":39693066},{"atb":[[5.3,12.9]],"id":28603683},{"atl":[[3.95,1]],"id":28691352}],"con":true,"img":false}]}
{"op":"mcm","clk":"5322483130","pt":1646320757164,"mc":[{"id":"1.195532862","rc":[{"atl":[[4.1,1]],"id":28691352}],"con":true,"img":false}]}
{"op":"mcm","clk":"5322483140","pt":1646320757268,"mc":[{"id":"1.195532862","rc":[{"atb":[[7,1.75]],"id":39693066},{"atb":[[5.3,7.95]],"id":28603683}],"con":true,"img":false}]}
{"op":"mcm","clk":"5322483149","pt":1646320757372,"mc":[{"id":"1.195532862","rc":[{"atb":[[7.2,4.51]],"id":39693066},{"atb":[[5.4,5.95]],"id":28603683}],"con":true,"img":false}]}
{"op":"mcm","clk":"5322483197","pt":1646320758004,"mc":[{"id":"1.195532862","rc":[{"atl":[[3.95,0]],"id":28691352}],"con":true,"img":false}]}
{"op":"mcm","clk":"5322483205","pt":1646320758060,"mc":[{"id":"1.195532862","rc":[{"atl":[[4.1,2]],"id":28691352}],"con":true,"img":false}]}
{"op":"mcm","clk":"5322483340","pt":1646320759695,"mc":[{"id":"1.195532862","rc":[{"atb":[[7,3.17]],"id":39693066},{"atl":[[10.5,11.45]],"id":39693066},{"atl":[[9.6,38.86]],"id":36042617},{"atb":[[10.5,6.07]],"id":35839928},{"atl":[[15.5,1.63]],"id":35839928},{"atb":[[5.3,15.59]],"id":28603683},{"atb":[[5.1,28.31]],"id":8668222},{"atl":[[4.2,39.09]],"id":28691352}],"con":true,"img":false}]}
{"op":"mcm","clk":"5322483386","pt":1646320760272,"mc":[{"id":"1.195532862","rc":[{"atb":[[5,0]],"id":39693066},{"atb":[[4.1,2]],"id":28603683}],"con":true,"img":false}]}
{"op":"mcm","clk":"5322483394","pt":1646320760377,"mc":[{"id":"1.195532862","rc":[{"atl":[[8.2,36.12]],"id":8668222},{"atl":[[4,2.52]],"id":28691352}],"con":true,"img":false}]}
{"op":"mcm","clk":"5322483409","pt":1646320760587,"mc":[{"id":"1.195532862","rc":[{"atl":[[5.8,0]],"id":8668222}],"con":true,"img":false}]}
{"op":"mcm","clk":"5322483417","pt":1646320760695,"mc":[{"id":"1.195532862","rc":[{"atl":[[4.1,1]],"id":28691352}],"con":true,"img":false}]}
{"op":"mcm","clk":"5322483428","pt":1646320760795,"mc":[{"id":"1.195532862","rc":[{"atl":[[3.95,1]],"id":28691352}],"con":true,"img":false}]}
{"op":"mcm","clk":"5322483447","pt":1646320761005,"mc":[{"id":"1.195532862","rc":[{"atl":[[5.7,0]],"id":8668222},{"atl":[[4.4,3.1],[4.1,0]],"id":28691352}],"con":true,"img":false}]}
{"op":"mcm","clk":"5322483455","pt":1646320761109,"mc":[{"id":"1.195532862","rc":[{"atl":[[6.4,1]],"id":8668222},{"atl":[[3.95,2]],"id":28691352}],"con":true,"img":false}]}
{"op":"mcm","clk":"5322483465","pt":1646320761164,"mc":[{"id":"1.195532862","rc":[{"atl":[[7.2,16.71]],"id":8668222}],"con":true,"img":false}]}
{"op":"mcm","clk":"5322483472","pt":1646320761266,"mc":[{"id":"1.195532862","rc":[{"atl":[[7.4,15.62]],"id":8668222}],"con":true,"img":false}]}
{"op":"mcm","clk":"5322483491","pt":1646320761475,"mc":[{"id":"1.195532862","rc":[{"atl":[[4.4,0]],"id":28691352}],"con":true,"img":false}]}
{"op":"mcm","clk":"5322483498","pt":1646320761579,"mc":[{"id":"1.195532862","rc":[{"atl":[[6.4,5.03]],"id":8668222}],"con":true,"img":false}]}
{"op":"mcm","clk":"5322483522","pt":1646320761891,"mc":[{"id":"1.195532862","rc":[{"atl":[[17,6.21]],"id":35839928}],"con":true,"img":false}]}
{"op":"mcm","clk":"5322483538","pt":1646320762099,"mc":[{"id":"1.195532862","rc":[{"atl":[[4,0]],"id":28691352}],"con":true,"img":false}]}
{"op":"mcm","clk":"5322483567","pt":1646320762367,"mc":[{"id":"1.195532862","rc":[{"atl":[[3.95,1]],"id":28691352}],"con":true,"img":false}]}
{"op":"mcm","clk":"5322483575","pt":1646320762469,"mc":[{"id":"1.195532862","rc":[{"atl":[[4.1,1]],"id":28691352}],"con":true,"img":false}]}
{"op":"mcm","clk":"5322483588","pt":1646320762575,"mc":[{"id":"1.195532862","rc":[{"atb":[[4.5,19.38]],"id":36042617}],"con":true,"img":false}]}
{"op":"mcm","clk":"5322483594","pt":1646320762680,"mc":[{"id":"1.195532862","rc":[{"atb":[[4,50]],"id":36042617}],"con":true,"img":false}]}
{"op":"mcm","clk":"5322483610","pt":1646320762885,"mc":[{"id":"1.195532862","rc":[{"atl":[[3.95,0]],"id":28691352}],"con":true,"img":false}]}
{"op":"mcm","clk":"5322483616","pt":1646320762990,"mc":[{"id":"1.195532862","rc":[{"atl":[[4.1,2]],"id":28691352}],"con":true,"img":false}]}
{"op":"mcm","clk":"5322483680","pt":1646320763869,"mc":[{"id":"1.195532862","rc":[{"atb":[[6,1]],"id":28603683}],"con":true,"img":false}]}
{"op":"mcm","clk":"5322483764","pt":1646320764968,"mc":[{"id":"1.195532862","rc":[{"atb":[[15.5,2.52]],"id":35839928},{"atl":[[15,0],[15.5,0]],"id":35839928},{"trd":[[15.5,3.26],[15,1.69]],"ltp":15.5,"tv":4.94,"id":35839928}],"con":true,"img":false}]}
{"op":"mcm","clk":"5322483772","pt":1646320765069,"mc":[{"id":"1.195532862","rc":[{"atb":[[10.5,5.84],[15.5,0]],"id":35839928},{"atl":[[15.5,2]],"id":35839928},{"trd":[[15.5,8.3]],"ltp":15.5,"tv":8.3,"id":35839928}],"con":true,"img":false}]}
{"op":"mcm","clk":"5322483787","pt":1646320765277,"mc":[{"id":"1.195532862","rc":[{"atb":[[10.5,3.77],[1.02,3.99]],"id":35839928}],"con":true,"img":false}]}
{"op":"mcm","clk":"5322483794","pt":1646320765385,"mc":[{"id":"1.195532862","rc":[{"atb":[[11.5,2.07]],"id":35839928}],"con":true,"img":false}]}
{"op":"mcm","clk":"5322483805","pt":1646320765488,"mc":[{"id":"1.195532862","rc":[{"atb":[[1.02,3.34]],"id":35839928}],"con":true,"img":false}]}
{"op":"mcm","clk":"5322483830","pt":1646320765801,"mc":[{"id":"1.195532862","rc":[{"atb":[[1.02,1.99]],"id":35839928}],"con":true,"img":false}]}
{"op":"mcm","clk":"5322483846","pt":1646320765906,"mc":[{"id":"1.195532862","rc":[{"atb":[[11.5,3.42]],"id":35839928}],"con":true,"img":false}]}
{"op":"mcm","clk":"5322483850","pt":1646320766012,"mc":[{"id":"1.195532862","rc":[{"atb":[[11.5,1.35]],"id":35839928}],"con":true,"img":false}]}
{"op":"mcm","clk":"5322483869","pt":1646320766278,"mc":[{"id":"1.195532862","rc":[{"atl":[[7.4,31.24],[7.2,0.58]],"id":8668222}],"con":true,"img":false}]}
{"op":"mcm","clk":"5322483908","pt":1646320766864,"mc":[{"id":"1.195532862","rc":[{"atb":[[11,0]],"id":35839928},{"atb":[[3.55,0]],"id":28691352},{"atl":[[4,2.52]],"id":28691352}],"con":true,"img":false}]}
{"op":"mcm","clk":"5322483912","pt":1646320766966,"mc":[{"id":"1.195532862","rc":[{"atb":[[10.5,6.07]],"id":35839928}],"con":true,"img":false}]}
{"op":"mcm","clk":"5322483919","pt":1646320767073,"mc":[{"id":"1.195532862","rc":[{"atb":[[11.5,0]],"id":35839928}],"con":true,"img":false}]}
{"op":"mcm","clk":"5322483935","pt":1646320767284,"mc":[{"id":"1.195532862","rc":[{"atl":[[4.1,1]],"id":28691352}],"con":true,"img":false}]}
{"op":"mcm","clk":"5322483940","pt":1646320767387,"mc":[{"id":"1.195532862","rc":[{"atl":[[3.95,1]],"id":28691352}],"con":true,"img":false}]}
{"op":"mcm","clk":"5322483953","pt":1646320767599,"mc":[{"id":"1.195532862","rc":[{"atl":[[11,10],[11.5,3.81]],"id":39693066},{"atb":[[7.2,9.62],[1.02,3.99]],"id":35839928},{"atl":[[16,0],[16.5,3.97]],"id":35839928},{"atb":[[3.95,7.14]],"id":28603683},{"atl":[[8.6,19.09],[8.2,1]],"id":28603683},{"atb":[[2.76,0],[2.9,78.95],[2.78,33.34]],"id":28691352}],"con":true,"img":false}]}
{"op":"mcm","clk":"5322483962","pt":1646320767700,"mc":[{"id":"1.195532862","rc":[{"atb":[[6.2,26.92],[7,3.28]],"id":35839928}],"con":true,"img":false}]}
{"op":"mcm","clk":"5322483969","pt":1646320767805,"mc":[{"id":"1.195532862","rc":[{"atl":[[13.5,3.67]],"id":39693066},{"atb":[[1.02,3.4]],"id":35839928},{"atl":[[8.6,23.51]],"id":28603683}],"con":true,"img":false}]}
{"op":"mcm","clk":"5322483984","pt":1646320768014,"mc":[{"id":"1.195532862","rc":[{"atb":[[1.02,1.99]],"id":35839928},{"atl":[[4.1,0]],"id":28691352}],"con":true,"img":false}]}
{"op":"mcm","clk":"5322483994","pt":1646320768071,"mc":[{"id":"1.195532862","rc":[{"atb":[[11,1.41]],"id":35839928},{"atb":[[3.95,0]],"id":28603683},{"atl":[[8.6,19.09]],"id":28603683},{"atl":[[3.95,2]],"id":28691352}],"con":true,"img":false}]}
{"op":"mcm","clk":"5322484015","pt":1646320768279,"mc":[{"id":"1.195532862","rc":[{"atl":[[13.5,0]],"id":39693066},{"atb":[[7,0]],"id":35839928}],"con":true,"img":false}]}
{"op":"mcm","clk":"5322484040","pt":1646320768596,"mc":[{"id":"1.195532862","rc":[{"atl":[[4,0]],"id":28691352}],"con":true,"img":false}]}
{"op":"mcm","clk":"5322484067","pt":1646320768910,"mc":[{"id":"1.195532862","rc":[{"atl":[[3.95,0]],"id":28691352}],"con":true,"img":false}]}
{"op":"mcm","clk":"5322484075","pt":1646320769014,"mc":[{"id":"1.195532862","rc":[{"atl":[[4.1,2]],"id":28691352}],"con":true,"img":false}]}
{"op":"mcm","clk":"5322484364","pt":1646320772678,"mc":[{"id":"1.195532862","rc":[{"spn":8.6,"spf":1.0,"id":39693066},{"spn":10.64,"spf":1.0,"id":35839928},{"spn":7.1,"spf":1.0,"id":28603683},{"atb":[[3.55,1.48]],"id":28691352}],"con":true,"img":false}]}
{"op":"mcm","clk":"5322484370","pt":1646320772781,"mc":[{"id":"1.195532862","rc":[{"atb":[[7,1.41]],"id":39693066},{"atb":[[4.5,11.88]],"id":36042617},{"atb":[[10,0]],"id":35839928},{"atb":[[5.3,7.64]],"id":28603683}],"con":true,"img":false}]}
{"op":"mcm","clk":"5322484390","pt":1646320773097,"mc":[{"id":"1.195532862","rc":[{"atb":[[4.5,0]],"id":36042617}],"con":true,"img":false}]}
{"op":"mcm","clk":"5322484396","pt":1646320773199,"mc":[{"id":"1.195532862","rc":[{"atb":[[5.1,10.32]],"id":36042617},{"atb":[[7.2,6.31]],"id":39693066},{"atb":[[11,3.8]],"id":35839928},{"atb":[[5.4,13.44]],"id":28603683}],"con":true,"img":false}]}
{"op":"mcm","clk":"5322484403","pt":1646320773307,"mc":[{"id":"1.195532862","rc":[{"atb":[[4.2,62.5]],"id":36042617}],"con":true,"img":false}]}
{"op":"mcm","clk":"5322484452","pt":1646320773884,"mc":[{"id":"1.195532862","rc":[{"atb":[[7.2,5.31]],"id":39693066},{"atl":[[4,2.52]],"id":28691352}],"con":true,"img":false}]}
{"op":"mcm","clk":"5322484460","pt":1646320773987,"mc":[{"id":"1.195532862","rc":[{"atb":[[7.4,1]],"id":39693066}],"con":true,"img":false}]}
{"op":"mcm","clk":"5322484464","pt":1646320774091,"mc":[{"id":"1.195532862","rc":[{"atl":[[4.1,1]],"id":28691352}],"con":true,"img":false}]}
{"op":"mcm","clk":"5322484472","pt":1646320774195,"mc":[{"id":"1.195532862","rc":[{"atl":[[3.95,1]],"id":28691352}],"con":true,"img":false}]}
{"op":"mcm","clk":"5322484483","pt":1646320774403,"mc":[{"id":"1.195532862","rc":[{"atb":[[7.2,5.2]],"id":39693066}],"con":true,"img":false}]}
{"op":"mcm","clk":"5322484493","pt":1646320774613,"mc":[{"id":"1.195532862","rc":[{"atb":[[7.2,1.79]],"id":39693066}],"con":true,"img":false}]}
{"op":"mcm","clk":"5322484497","pt":1646320774715,"mc":[{"id":"1.195532862","rc":[{"atb":[[7.4,4.4]],"id":39693066}],"con":true,"img":false}]}
{"op":"mcm","clk":"5322484520","pt":1646320774975,"mc":[{"id":"1.195532862","rc":[{"atl":[[4.1,0]],"id":28691352}],"con":true,"img":false}]}
{"op":"mcm","clk":"5322484529","pt":1646320775087,"mc":[{"id":"1.195532862","rc":[{"atl":[[3.95,2]],"id":28691352}],"con":true,"img":false}]}
{"op":"mcm","clk":"5322484562","pt":1646320775502,"mc":[{"id":"1.195532862","rc":[{"atb":[[7,0]],"id":39693066},{"atb":[[10.5,2.29]],"id":35839928},{"atb":[[5.3,0]],"id":28603683}],"con":true,"img":false}]}
{"op":"mcm","clk":"5322484578","pt":1646320775711,"mc":[{"id":"1.195532862","rc":[{"atb":[[6.8,3]],"id":39693066},{"atb":[[5.2,3.63]],"id":28603683},{"atl":[[4,0]],"id":28691352}],"con":true,"img":false}]}
{"op":"mcm","clk":"5322484587","pt":1646320775817,"mc":[{"id":"1.195532862","rc":[{"atb":[[11,6.88]],"id":35839928},{"atb":[[5.4,20.62]],"id":28603683}],"con":true,"img":false}]}
{"op":"mcm","clk":"5322484595","pt":1646320775921,"mc":[{"id":"1.195532862","rc":[{"atl":[[3.95,1],[4.1,3.77]],"id":28691352}],"con":true,"img":false}]}
{"op":"mcm","clk":"5322484603","pt":1646320775974,"mc":[{"id":"1.195532862","rc":[{"atl":[[4.1,4.77]],"id":28691352}],"con":true,"img":false}]}
{"op":"mcm","clk":"5322484618","pt":1646320776188,"mc":[{"id":"1.195532862","rc":[{"atl":[[4.1,1]],"id":28691352}],"con":true,"img":false}]}
{"op":"mcm","clk":"5322484626","pt":1646320776292,"mc":[{"id":"1.195532862","rc":[{"atb":[[6.8,0]],"id":39693066},{"atb":[[5.2,0]],"id":28603683}],"con":true,"img":false}]}
{"op":"mcm","clk":"5322484688","pt":1646320776973,"mc":[{"id":"1.195532862","rc":[{"atl":[[3.95,0]],"id":28691352}],"con":true,"img":false}]}
{"op":"mcm","clk":"5322484694","pt":1646320777078,"mc":[{"id":"1.195532862","rc":[{"atl":[[17.5,6.03]],"id":35839928},{"atl":[[4.1,2]],"id":28691352}],"con":true,"img":false}]}
{"op":"mcm","clk":"5322484773","pt":1646320778325,"mc":[{"id":"1.195532862","rc":[{"atb":[[7.2,0]],"id":39693066}],"con":true,"img":false}]}
{"op":"mcm","clk":"5322484788","pt":1646320778588,"mc":[{"id":"1.195532862","rc":[{"atb":[[7.4,1]],"id":39693066}],"con":true,"img":false}]}
{"op":"mcm","clk":"5322484803","pt":1646320778800,"mc":[{"id":"1.195532862","rc":[{"atl":[[11,0],[11.5,13.33]],"id":39693066},{"atl":[[7.4,15.62],[7.2,16.71]],"id":8668222}],"con":true,"img":false}]}
{"op":"mcm","clk":"5322484809","pt":1646320778903,"mc":[{"id":"1.195532862","rc":[{"atb":[[7.4,0]],"id":39693066},{"atl":[[15.5,2.23]],"id":35839928}],"con":true,"img":false}]}
{"op":"mcm","clk":"5322484818","pt":1646320779004,"mc":[{"id":"1.195532862","rc":[{"atb":[[5.7,1]],"id":39693066}],"con":true,"img":false}]}
{"op":"mcm","clk":"5322484843","pt":1646320779321,"mc":[{"id":"1.195532862","rc":[{"atb":[[4.2,7.73]],"id":28603683}],"con":true,"img":false}]}
{"op":"mcm","clk":"5322484850","pt":1646320779424,"mc":[{"id":"1.195532862","rc":[{"atb":[[1.01,11004.52]],"id":35839928}],"con":true,"img":false}]}
{"op":"mcm","clk":"5322484862","pt":1646320779478,"mc":[{"id":"1.195532862","rc":[{"atb":[[5.7,5.64]],"id":39693066},{"atl":[[4,2.52]],"id":28691352}],"con":true,"img":false}]}
{"op":"mcm","clk":"5322484871","pt":1646320779586,"mc":[{"id":"1.195532862","rc":[{"atb":[[1.01,11003.68]],"id":35839928}],"con":true,"img":false}]}
{"op":"mcm","clk":"5322484877","pt":1646320779687,"mc":[{"id":"1.195532862","rc":[{"atl":[[4.1,1]],"id":28691352}],"con":true,"img":false}]}
{"op":"mcm","clk":"5322484884","pt":1646320779788,"mc":[{"id":"1.195532862","rc":[{"atb":[[1.01,11002]],"id":35839928},{"atl":[[3.95,1]],"id":28691352}],"con":true,"img":false}]}
{"op":"mcm","clk":"5322484890","pt":1646320779894,"mc":[{"id":"1.195532862","rc":[{"atb":[[11.5,1.68]],"id":35839928},{"atl":[[4.1,0]],"id":28691352}],"con":true,"img":false}]}
{"op":"mcm","clk":"5322484896","pt":1646320779996,"mc":[{"id":"1.195532862","rc":[{"atl":[[3.95,2]],"id":28691352}],"con":true,"img":false}]}
{"op":"mcm","clk":"5322484913","pt":1646320780207,"mc":[{"id":"1.195532862","rc":[{"atb":[[6.8,2]],"id":39693066},{"atb":[[11,5.47]],"id":35839928}],"con":true,"img":false}]}
{"op":"mcm","clk":"5322484922","pt":1646320780313,"mc":[{"id":"1.195532862","rc":[{"atb":[[1.02,3.99]],"id":35839928}],"con":true,"img":false}]}
{"op":"mcm","clk":"5322484933","pt":1646320780522,"mc":[{"id":"1.195532862","rc":[{"atb":[[1.02,3.28]],"id":35839928}],"con":true,"img":false}]}
{"op":"mcm","clk":"5322484949","pt":1646320780683,"mc":[{"id":"1.195532862","rc":[{"atb":[[1.02,1.99]],"id":35839928},{"atb":[[3.55,0]],"id":28691352},{"atl":[[3.55,3.52]],"id":28691352},{"trd":[[3.55,8.96]],"ltp":3.55,"tv":8.96,"id":28691352}],"con":true,"img":false}]}
{"op":"mcm","clk":"5322484955","pt":1646320780787,"mc":[{"id":"1.195532862","rc":[{"atb":[[12,1.29]],"id":35839928},{"atb":[[3.5,0]],"id":28691352},{"trd":[[3.5,4]],"ltp":3.5,"tv":4.0,"id":28691352}],"con":true,"img":false}]}
{"op":"mcm","clk":"5322484968","pt":1646320780995,"mc":[{"id":"1.195532862","rc":[{"atb":[[5.7,4.64]],"id":39693066}],"con":true,"img":false}]}
{"op":"mcm","clk":"5322484977","pt":1646320781102,"mc":[{"id":"1.195532862","rc":[{"atb":[[7,1]],"id":39693066}],"con":true,"img":false}]}
{"op":"mcm","clk":"5322484987","pt":1646320781204,"mc":[{"id":"1.195532862","rc":[{"atb":[[5,4.19]],"id":39693066},{"atl":[[3.95,1]],"id":28691352}],"con":true,"img":false}]}
{"op":"mcm","clk":"5322484991","pt":1646320781312,"mc":[{"id":"1.195532862","rc":[{"atl":[[3.5,1]],"id":28691352}],"con":true,"img":false}]}
{"op":"mcm","clk":"5322484996","pt":1646320781412,"mc":[{"id":"1.195532862","rc":[{"atl":[[4,0],[3.9,0]],"id":28691352}],"con":true,"img":false}]}
{"op":"mcm","clk":"5322485002","pt":1646320781518,"mc":[{"id":"1.195532862","rc":[{"atl":[[3.55,3.82]],"id":28691352}],"con":true,"img":false}]}
{"op":"mcm","clk":"5322485010","pt":1646320781621,"mc":[{"id":"1.195532862","rc":[{"atb":[[2.82,5.93]],"id":28691352}],"con":true,"img":false}]}
{"op":"mcm","clk":"5322485019","pt":1646320781828,"mc":[{"id":"1.195532862","rc":[{"atb":[[3.2,3.36]],"id":28691352}],"con":true,"img":false}]}
{"op":"mcm","clk":"5322485023","pt":1646320781933,"mc":[{"id":"1.195532862","rc":[{"atl":[[3.95,0]],"id":28691352}],"con":true,"img":false}]}
{"op":"mcm","clk":"5322485033","pt":1646320781988,"mc":[{"id":"1.195532862","rc":[{"atb":[[5.7,3.63]],"id":39693066},{"atb":[[2.96,4.58]],"id":28691352},{"atl":[[3.5,2],[4.2,32.27]],"id":28691352}],"con":true,"img":false}]}
{"op":"mcm","clk":"5322485038","pt":1646320782092,"mc":[{"id":"1.195532862","rc":[{"atb":[[5.7,0]],"id":39693066}],"con":true,"img":false}]}
{"op":"mcm","clk":"5322485060","pt":1646320782412,"mc":[{"id":"1.195532862","rc":[{"atb":[[7,4.63]],"id":39693066}],"con":true,"img":false}]}
{"op":"mcm","clk":"5322485072","pt":1646320782533,"mc":[{"id":"1.195532862","rc":[{"atb":[[2.96,0]],"id":28691352}],"con":true,"img":false}]}
{"op":"mcm","clk":"5322485123","pt":1646320783315,"mc":[{"id":"1.195532862","rc":[{"atb":[[5,0]],"id":39693066}],"con":true,"img":false}]}
{"op":"mcm","clk":"5322485135","pt":1646320783521,"mc":[{"id":"1.195532862","rc":[{"atl":[[3.5,10.72]],"id":28691352}],"con":true,"img":false}]}
{"op":"mcm","clk":"5322485152","pt":1646320783739,"mc":[{"id":"1.195532862","rc":[{"atl":[[3.5,9.72]],"id":28691352}],"con":true,"img":false}]}
{"op":"mcm","clk":"5322485184","pt":1646320784039,"mc":[{"id":"1.195532862","rc":[{"atb":[[4.6,16.39]],"id":39693066},{"atl":[[11,10],[11.5,3.81]],"id":39693066},{"atb":[[4.1,6.67]],"id":36042617},{"atl":[[18.5,0],[22,4.76]],"id":35839928},{"atl":[[8.6,6.59],[8.8,12.82]],"id":28603683},{"atl":[[7.4,31.24],[7.2,0.58]],"id":8668222},{"atb":[[2.82,0],[3.2,8.58],[2.9,131.58],[3.15,0.17],[2.78,0]],"id":28691352}],"con":true,"img":false}]}
{"op":"mcm","clk":"5322485206","pt":1646320784211,"mc":[{"id":"1.195532862","rc":[{"atb":[[4.6,11.11]],"id":39693066},{"atb":[[4.1,0]],"id":36042617},{"atl":[[7.4,37.69]],"id":8668222},{"atb":[[2.9,78.95],[2.96,3.49]],"id":28691352}],"con":true,"img":false}]}
{"op":"mcm","clk":"5322485212","pt":1646320784306,"mc":[{"id":"1.195532862","rc":[{"atb":[[2.72,33.34]],"id":28691352},{"atl":[[3.55,3.52]],"id":28691352}],"con":true,"img":false}]}
{"op":"mcm","clk":"5322485223","pt":1646320784413,"mc":[{"id":"1.195532862","rc":[{"atl":[[3.5,10.03]],"id":28691352}],"con":true,"img":false}]}
{"op":"mcm","clk":"5322485238","pt":1646320784626,"mc":[{"id":"1.195532862","rc":[{"atl":[[7.4,31.24]],"id":8668222}],"con":true,"img":false}]}
{"op":"mcm","clk":"5322485258","pt":1646320784841,"mc":[{"id":"1.195532862","rc":[{"atb":[[2.96,0]],"id":28691352}],"con":true,"img":false}]}
{"op":"mcm","clk":"5322485292","pt":1646320785215,"mc":[{"id":"1.195532862","rc":[{"atb":[[3.25,2.34]],"id":28691352}],"con":true,"img":false}]}
{"op":"mcm","clk":"5322485299","pt":1646320785308,"mc":[{"id":"1.195532862","rc":[{"atb":[[6.8,0]],"id":39693066}],"con":true,"img":false}]}
{"op":"mcm","clk":"5322485346","pt":1646320785898,"mc":[{"id":"1.195532862","rc":[{"atb":[[7,3.63]],"id":39693066}],"con":true,"img":false}]}
{"op":"mcm","clk":"5322485355","pt":1646320786004,"mc":[{"id":"1.195532862","rc":[{"atb":[[7.2,1]],"id":39693066}],"con":true,"img":false}]}
{"op":"mcm","clk":"5322485393","pt":1646320786531,"mc":[{"id":"1.195532862","rc":[{"atb":[[11,3.07]],"id":35839928},{"atl":[[18.5,8.53]],"id":35839928}],"con":true,"img":false}]}
{"op":"mcm","clk":"5322485438","pt":1646320787014,"mc":[{"id":"1.195532862","rc":[{"atb":[[5.7,5.81]],"id":39693066},{"atb":[[11.5,3.45]],"id":35839928}],"con":true,"img":false}]}
{"op":"mcm","clk":"5322485455","pt":1646320787239,"mc":[{"id":"1.195532862","rc":[{"spl":[[1.01,5]],"id":36042617},{"atb":[[10.5,2.18],[11.5,1.76]],"id":35839928}],"con":true,"img":false}]}
{"op":"mcm","clk":"5322485464","pt":1646320787341,"mc":[{"id":"1.195532862","rc":[{"atb":[[5,6.08]],"id":39693066}],"con":true,"img":false}]}
{"op":"mcm","clk":"5322485481","pt":1646320787551,"mc":[{"id":"1.195532862","rc":[{"atl":[[10,0.82]],"id":39693066},{"atl":[[9.4,0.82]],"id":36042617},{"atb":[[10.5,0]],"id":35839928},{"atl":[[16,0.82]],"id":35839928},{"atl":[[8.2,1.82]],"id":28603683}],"con":true,"img":false}]}
{"op":"mcm","clk":"5322485492","pt":1646320787642,"mc":[{"id":"1.195532862","rc":[{"atb":[[11,5.25]],"id":35839928}],"con":true,"img":false}]}
{"op":"mcm","clk":"5322485530","pt":1646320788142,"mc":[{"id":"1.195532862","rc":[{"atl":[[11,14],[11.5,0]],"id":39693066},{"atl":[[10,0],[9.8,5.7]],"id":36042617},{"atl":[[5.3,58.88]],"id":28691352}],"con":true,"img":false}]}
{"op":"mcm","clk":"5322485543","pt":1646320788336,"mc":[{"id":"1.195532862","rc":[{"atl":[[9.4,3.42]],"id":36042617},{"atl":[[5,6.41]],"id":28691352}],"con":true,"img":false}]}
{"op":"mcm","clk":"5322485552","pt":1646320788441,"mc":[{"id":"1.195532862","rc":[{"atl":[[10.5,3.92],[9.4,3.05]],"id":36042617},{"atl":[[10,0.43]],"id":39693066},{"atl":[[16,0.48]],"id":35839928},{"atl":[[8.2,1.46]],"id":28603683}],"con":true,"img":false}]}
{"op":"mcm","clk":"5322485560","pt":1646320788508,"mc":[{"id":"1.195532862","rc":[{"atl":[[9.2,5.7],[9.6,27.23]],"id":36042617}],"con":true,"img":false}]}
{"op":"mcm","clk":"5322485567","pt":1646320788617,"mc":[{"id":"1.195532862","rc":[{"atb":[[5.2,1.69]],"id":36042617},{"atl":[[9.6,26.23]],"id":36042617},{"atb":[[5.5,1.61]],"id":28603683}],"con":true,"img":false}]}
{"op":"mcm","clk":"5322485576","pt":1646320788718,"mc":[{"id":"1.195532862","rc":[{"atl":[[9.2,6.7],[10.5,0]],"id":36042617}],"con":true,"img":false}]}
{"op":"mcm","clk":"5322485582","pt":1646320788821,"mc":[{"id":"1.195532862","rc":[{"atl":[[5,0]],"id":28691352}],"con":true,"img":false}]}
{"op":"mcm","clk":"5322485595","pt":1646320789031,"mc":[{"id":"1.195532862","rc":[{"atb":[[5.4,19.62]],"id":28603683},{"atb":[[3.2,5.22]],"id":28691352}],"con":true,"img":false}]}
{"op":"mcm","clk":"5322485601","pt":1646320789133,"mc":[{"id":"1.195532862","rc":[{"atb":[[5.6,1]],"id":28603683}],"con":true,"img":false}]}
{"op":"mcm","clk":"5322485607","pt":1646320789228,"mc":[{"id":"1.195532862","rc":[{"atl":[[9.4,0],[9.6,30.88],[9.8,1.15]],"id":36042617},{"atl":[[11,4],[11.5,9.52]],"id":39693066},{"atl":[[17,0],[18,0]],"id":35839928},{"atb":[[3.2,0]],"id":28691352}],"con":true,"img":false}]}
{"op":"mcm","clk":"5322485617","pt":1646320789356,"mc":[{"id":"1.195532862","rc":[{"atl":[[9,0.45]],"id":36042617}],"con":true,"img":false}]}
{"op":"mcm","clk":"5322485622","pt":1646320789445,"mc":[{"id":"1.195532862","rc":[{"atl":[[17.5,10.37]],"id":35839928}],"con":true,"img":false}]}
{"op":"mcm","clk":"5322485652","pt":1646320789845,"mc":[{"id":"1.195532862","rc":[{"atl":[[17.5,6.03]],"id":35839928}],"con":true,"img":false}]}
{"op":"mcm","clk":"5322485671","pt":1646320790017,"mc":[{"id":"1.195532862","rc":[{"atl":[[16.5,3.92]],"id":35839928}],"con":true,"img":false}]}
{"op":"mcm","clk":"5322485680","pt":1646320790124,"mc":[{"id":"1.195532862","rc":[{"atl":[[16,0]],"id":35839928}],"con":true,"img":false}]}
{"op":"mcm","clk":"5322485687","pt":1646320790227,"mc":[{"id":"1.195532862","rc":[{"atl":[[16.5,2.57],[1000,12.48]],"id":35839928}],"con":true,"img":false}]}
{"op":"mcm","clk":"5322485697","pt":1646320790318,"mc":[{"id":"1.195532862","rc":[{"atl":[[17,1.35]],"id":35839928}],"con":true,"img":false}]}
{"op":"mcm","clk":"5322485709","pt":1646320790432,"mc":[{"id":"1.195532862","rc":[{"atl":[[9,3.18]],"id":36042617}],"con":true,"img":false}]}
{"op":"mcm","clk":"5322485724","pt":1646320790640,"mc":[{"id":"1.195532862","rc":[{"atl":[[9.2,5.7]],"id":36042617}],"con":true,"img":false}]}
{"op":"mcm","clk":"5322485735","pt":1646320790748,"mc":[{"id":"1.195532862","rc":[{"atl":[[8.8,1]],"id":36042617}],"con":true,"img":false}]}
{"op":"mcm","clk":"5322485803","pt":1646320791533,"mc":[{"id":"1.195532862","rc":[{"atb":[[5,0]],"id":39693066},{"atb":[[4.2,0.12]],"id":28603683}],"con":true,"img":false}]}
{"op":"mcm","clk":"5322485854","pt":1646320791844,"mc":[{"id":"1.195532862","rc":[{"atl":[[9,0.45]],"id":36042617}],"con":true,"img":false}]}
{"op":"mcm","clk":"5322485869","pt":1646320792057,"mc":[{"id":"1.195532862","rc":[{"atl":[[8.8,0]],"id":36042617}],"con":true,"img":false}]}
{"op":"mcm","clk":"5322485879","pt":1646320792148,"mc":[{"id":"1.195532862","rc":[{"atl":[[9,1.45]],"id":36042617}],"con":true,"img":false}]}
{"op":"mcm","clk":"5322485937","pt":1646320792726,"mc":[{"id":"1.195532862","rc":[{"atb":[[5.5,0]],"id":28603683}],"con":true,"img":false}]}
{"op":"mcm","clk":"5322485949","pt":1646320792841,"mc":[{"id":"1.195532862","rc":[{"atl":[[9,4.18]],"id":36042617},{"atb":[[1.01,11003.61]],"id":28603683}],"con":true,"img":false}]}
{"op":"mcm","clk":"5322486051","pt":1646320793750,"mc":[{"id":"1.195532862","rc":[{"atl":[[9,48.18]],"id":36042617}],"con":true,"img":false}]}
{"op":"mcm","clk":"5322486057","pt":1646320793859,"mc":[{"id":"1.195532862","rc":[{"atb":[[11,2.18]],"id":35839928},{"atl":[[4.2,17.73]],"id":28691352}],"con":true,"img":false}]}
{"op":"mcm","clk":"5322486080","pt":1646320794152,"mc":[{"id":"1.195532862","rc":[{"atb":[[7,5.04]],"id":39693066},{"atb":[[11.5,4.21]],"id":35839928},{"atl":[[3.5,18.59]],"id":28691352}],"con":true,"img":false}]}
{"op":"mcm","clk":"5322486101","pt":1646320794324,"mc":[{"id":"1.195532862","rc":[{"atl":[[9.4,4.76],[9.6,26.23]],"id":36042617},{"atl":[[1000,12]],"id":35839928}],"con":true,"img":false}]}
{"op":"mcm","clk":"5322486107","pt":1646320794433,"mc":[{"id":"1.195532862","rc":[{"atl":[[16.5,3.05]],"id":35839928}],"con":true,"img":false}]}
{"op":"mcm","clk":"5322486116","pt":1646320794541,"mc":[{"id":"1.195532862","rc":[{"atl":[[8.8,5.7]],"id":36042617}],"con":true,"img":false}]}
{"op":"mcm","clk":"5322486127","pt":1646320794638,"mc":[{"id":"1.195532862","rc":[{"atl":[[9.2,0]],"id":36042617}],"con":true,"img":false}]}
{"op":"mcm","clk":"5322486143","pt":1646320794850,"mc":[{"id":"1.195532862","rc":[{"atl":[[9,44.45]],"id":36042617},{"atb":[[7,4.93]],"id":39693066}],"con":true,"img":false}]}
{"op":"mcm","clk":"5322486152","pt":1646320794954,"mc":[{"id":"1.195532862","rc":[{"atl":[[8.6,1]],"id":36042617}],"con":true,"img":false}]}
{"op":"mcm","clk":"5322486160","pt":1646320795055,"mc":[{"id":"1.195532862","rc":[{"atb":[[7,1.41]],"id":39693066}],"con":true,"img":false}]}
{"op":"mcm","clk":"5322486168","pt":1646320795162,"mc":[{"id":"1.195532862","rc":[{"atb":[[7.2,4.51]],"id":39693066},{"atl":[[9,44]],"id":36042617},{"atl":[[16.5,2.57]],"id":35839928}],"con":true,"img":false}]}
{"op":"mcm","clk":"5322486174","pt":1646320795266,"mc":[{"id":"1.195532862","rc":[{"atl":[[8.6,1.45]],"id":36042617},{"atl":[[1000,12.48]],"id":35839928},{"atb":[[4.2,7.73]],"id":28603683}],"con":true,"img":false}]}
{"op":"mcm","clk":"5322486184","pt":1646320795323,"mc":[{"id":"1.195532862","rc":[{"atb":[[6.8,2]],"id":39693066}],"con":true,"img":false}]}
{"op":"mcm","clk":"5322486200","pt":1646320795529,"mc":[{"id":"1.195532862","rc":[{"atl":[[8.6,4.32]],"id":36042617}],"con":true,"img":false}]}
{"op":"mcm","clk":"5322486214","pt":1646320795741,"mc":[{"id":"1.195532862","rc":[{"atl":[[19.5,13.64]],"id":35839928},{"atb":[[1.01,11002]],"id":28603683}],"con":true,"img":false}]}
{"op":"mcm","clk":"5322486224","pt":1646320795846,"mc":[{"id":"1.195532862","rc":[{"atb":[[5.5,1.61]],"id":28603683}],"con":true,"img":false}]}
{"op":"mcm","clk":"5322486232","pt":1646320795954,"mc":[{"id":"1.195532862","rc":[{"atl":[[9.6,21.09]],"id":36042617},{"atb":[[7.2,3.51],[5.7,0]],"id":39693066},{"atl":[[4.2,0]],"id":28691352}],"con":true,"img":false}]}
{"op":"mcm","clk":"5322486243","pt":1646320796050,"mc":[{"id":"1.195532862","rc":[{"atb":[[7.4,1]],"id":39693066}],"con":true,"img":false}]}
{"op":"mcm","clk":"5322486279","pt":1646320796454,"mc":[{"id":"1.195532862","rc":[{"atb":[[7,3.17]],"id":39693066},{"atl":[[9.2,4.71]],"id":36042617},{"atl":[[3.5,30.04]],"id":28691352}],"con":true,"img":false}]}
{"op":"mcm","clk":"5322486306","pt":1646320796723,"mc":[{"id":"1.195532862","rc":[{"atb":[[7.2,3.4]],"id":39693066}],"con":true,"img":false}]}
{"op":"mcm","clk":"5322486322","pt":1646320796936,"mc":[{"id":"1.195532862","rc":[{"atb":[[7.2,0]],"id":39693066}],"con":true,"img":false}]}
{"op":"mcm","clk":"5322486328","pt":1646320797039,"mc":[{"id":"1.195532862","rc":[{"atb":[[7.4,4.4]],"id":39693066},{"atl":[[9,5],[9.4,0]],"id":36042617}],"con":true,"img":false}]}
{"op":"mcm","clk":"5322486333","pt":1646320797135,"mc":[{"id":"1.195532862","rc":[{"spl":[[1.01,4.04]],"id":35839928}],"con":true,"img":false}]}
{"op":"mcm","clk":"5322486350","pt":1646320797355,"mc":[{"id":"1.195532862","rc":[{"atl":[[12,9.09]],"id":39693066}],"con":true,"img":false}]}
{"op":"mcm","clk":"5322486396","pt":1646320797933,"mc":[{"id":"1.195532862","rc":[{"atb":[[7.4,3.4]],"id":39693066}],"con":true,"img":false}]}
{"op":"mcm","clk":"5322486402","pt":1646320798031,"mc":[{"id":"1.195532862","rc":[{"atb":[[7.6,1]],"id":39693066}],"con":true,"img":false}]}
{"op":"mcm","clk":"5322486408","pt":1646320798138,"mc":[{"id":"1.195532862","rc":[{"atb":[[4.1,14.9]],"id":28603683}],"con":true,"img":false}]}
{"op":"mcm","clk":"5322486414","pt":1646320798240,"mc":[{"id":"1.195532862","rc":[{"atl":[[15,0.2]],"id":39693066},{"atb":[[4,0],[4.1,12.9]],"id":28603683}],"con":true,"img":false}]}
{"op":"mcm","clk":"5322486424","pt":1646320798347,"mc":[{"id":"1.195532862","rc":[{"atb":[[7.4,3.29]],"id":39693066},{"atb":[[4.5,2]],"id":28603683}],"con":true,"img":false}]}
{"op":"mcm","clk":"5322486438","pt":1646320798554,"mc":[{"id":"1.195532862","rc":[{"atb":[[7.4,0]],"id":39693066},{"atb":[[4.2,0.12]],"id":28603683}],"con":true,"img":false}]}
{"op":"mcm","clk":"5322486450","pt":1646320798658,"mc":[{"id":"1.195532862","rc":[{"atb":[[7.6,4.29]],"id":39693066}],"con":true,"img":false}]}
{"op":"mcm","clk":"5322486480","pt":1646320798961,"mc":[{"id":"1.195532862","rc":[{"atb":[[7.6,3.29]],"id":39693066},{"atl":[[8.6,15.32]],"id":36042617}],"con":true,"img":false}]}
{"op":"mcm","clk":"5322486487","pt":1646320799026,"mc":[{"id":"1.195532862","rc":[{"atb":[[7.8,1]],"id":39693066}],"con":true,"img":false}]}
{"op":"mcm","clk":"5322486549","pt":1646320799756,"mc":[{"id":"1.195532862","rc":[{"atb":[[5.5,0]],"id":28603683}],"con":true,"img":false}]}
{"op":"mcm","clk":"5322486558","pt":1646320799862,"mc":[{"id":"1.195532862","rc":[{"atb":[[1.01,11003.61]],"id":28603683}],"con":true,"img":false}]}
{"op":"mcm","clk":"5322486583","pt":1646320800118,"mc":[{"id":"1.195532862","rc":[{"atl":[[11.5,0],[12,18.18]],"id":39693066},{"atl":[[9,15.7]],"id":28603683}],"con":true,"img":false}]}
{"op":"mcm","clk":"5322486613","pt":1646320800445,"mc":[{"id":"1.195532862","rc":[{"atb":[[6.8,0]],"id":39693066},{"atl":[[9,12.5]],"id":28603683}],"con":true,"img":false}]}
{"op":"mcm","clk":"5322486626","pt":1646320800548,"mc":[{"id":"1.195532862","rc":[{"atl":[[8.4,5.7],[8.8,0]],"id":36042617}],"con":true,"img":false}]}
{"op":"mcm","clk":"5322486662","pt":1646320800760,"mc":[{"id":"1.195532862","rc":[{"atl":[[8.6,12.45]],"id":36042617}],"con":true,"img":false}]}
{"op":"mcm","clk":"5322486670","pt":1646320800849,"mc":[{"id":"1.195532862","rc":[{"atl":[[8.6,11.45]],"id":36042617}],"con":true,"img":false}]}
{"op":"mcm","clk":"5322486680","pt":1646320800953,"mc":[{"id":"1.195532862","rc":[{"atl":[[8.2,1]],"id":36042617}],"con":true,"img":false}]}
{"op":"mcm","clk":"5322486698","pt":1646320801121,"mc":[{"id":"1.195532862","rc":[{"atl":[[8.6,11]],"id":36042617}],"con":true,"img":false}]}
{"op":"mcm","clk":"5322486709","pt":1646320801231,"mc":[{"id":"1.195532862","rc":[{"atl":[[8.2,1.45]],"id":36042617}],"con":true,"img":false}]}
{"op":"mcm","clk":"5322486992","pt":1646320804846,"mc":[{"id":"1.195532862","rc":[{"atb":[[5.3,8],[5,12],[4.6,18],[4.1,39.9],[5.5,5]],"id":28603683}],"con":true,"img":false}]}
{"op":"mcm","clk":"5322487000","pt":1646320804948,"mc":[{"id":"1.195532862","rc":[{"atb":[[5.4,23.37],[4.5,6.5]],"id":28603683}],"con":true,"img":false}]}
{"op":"mcm","clk":"5322487005","pt":1646320805049,"mc":[{"id":"1.195532862","rc":[{"atl":[[8.2,4.48]],"id":36042617}],"con":true,"img":false}]}
{"op":"mcm","clk":"5322487013","pt":1646320805155,"mc":[{"id":"1.195532862","rc":[{"atb":[[5.4,19.62],[4.5,2]],"id":28603683}],"con":true,"img":false}]}
{"op":"mcm","clk":"5322487017","pt":1646320805262,"mc":[{"id":"1.195532862","rc":[{"atl":[[9,0],[8.6,16.26]],"id":36042617}],"con":true,"img":false}]}
{"op":"mcm","clk":"5322487024","pt":1646320805361,"mc":[{"id":"1.195532862","rc":[{"atl":[[1000,14]],"id":36042617},{"atl":[[1000,14]],"id":39693066},{"atl":[[1000,14]],"id":28603683},{"atl":[[1000,14]],"id":28691352}],"con":true,"img":false}]}
{"op":"mcm","clk":"5322487038","pt":1646320805568,"mc":[{"id":"1.195532862","rc":[{"atl":[[1000,12.2]],"id":36042617},{"atl":[[1000,12.1]],"id":39693066},{"atl":[[1000,12.2]],"id":28603683},{"atl":[[1000,12.1]],"id":28691352}],"con":true,"img":false}]}
{"op":"mcm","clk":"5322487043","pt":1646320805663,"mc":[{"id":"1.195532862","rc":[{"atl":[[1000,12]],"id":36042617},{"atl":[[1000,12]],"id":39693066},{"atl":[[1000,12]],"id":28603683},{"atl":[[1000,12]],"id":28691352}],"con":true,"img":false}]}
{"op":"mcm","clk":"5322487055","pt":1646320805724,"mc":[{"id":"1.195532862","rc":[{"atl":[[8.2,4.68]],"id":36042617},{"atl":[[10.5,11.55]],"id":39693066},{"atb":[[1.01,11002]],"id":28603683},{"atl":[[8.2,1.66]],"id":28603683},{"atl":[[3.65,0.1]],"id":28691352}],"con":true,"img":false}]}
{"op":"mcm","clk":"5322487064","pt":1646320805828,"mc":[{"id":"1.195532862","rc":[{"atb":[[5.6,2.61]],"id":28603683}],"con":true,"img":false}]}
{"op":"mcm","clk":"5322487104","pt":1646320806452,"mc":[{"id":"1.195532862","rc":[{"atl":[[13,12.5]],"id":39693066},{"atl":[[8,5.7],[8.4,0]],"id":36042617},{"atl":[[9.2,8],[11.5,18],[14,27],[9.8,40.41],[8.8,17.82]],"id":28603683}],"con":true,"img":false}]}
{"op":"mcm","clk":"5322487119","pt":1646320806667,"mc":[{"id":"1.195532862","rc":[{"atl":[[8.2,0.65]],"id":36042617}],"con":true,"img":false}]}
{"op":"mcm","clk":"5322487129","pt":1646320806772,"mc":[{"id":"1.195532862","rc":[{"atl":[[7.8,1]],"id":36042617}],"con":true,"img":false}]}
{"op":"mcm","clk":"5322487137","pt":1646320806864,"mc":[{"id":"1.195532862","rc":[{"atl":[[8,0],[8.6,29.42]],"id":36042617}],"con":true,"img":false}]}
{"op":"mcm","clk":"5322487153","pt":1646320807043,"mc":[{"id":"1.195532862","rc":[{"atb":[[2.62,0]],"id":36042617},{"atl":[[34,0],[7.8,0],[18,0],[23,0]],"id":36042617},{"atb":[[2.62,0]],"id":39693066},{"atl":[[19.5,0],[25,0]],"id":39693066},{"atb":[[2.62,0]],"id":35839928},{"atl":[[34,0],[15.5,0],[20,0]],"id":28603683},{"atl":[[34,0],[14.5,0],[18.5,0]],"id":8668222},{"atl":[[34,0],[9.2,0],[12,0],[17,0]],"id":28691352}],"con":true,"img":false}]}
{"op":"mcm","clk":"5322487160","pt":1646320807143,"mc":[{"id":"1.195532862","rc":[{"atl":[[8.2,0.2],[8.4,1]],"id":36042617}],"con":true,"img":false}]}
{"op":"mcm","clk":"5322487168","pt":1646320807250,"mc":[{"id":"1.195532862","rc":[{"atl":[[8.4,1.45]],"id":36042617}],"con":true,"img":false}]}
{"op":"mcm","clk":"5322487205","pt":1646320807674,"mc":[{"id":"1.195532862","rc":[{"atl":[[8.2,3.22]],"id":36042617}],"con":true,"img":false}]}
{"op":"mcm","clk":"5322487219","pt":1646320807866,"mc":[{"id":"1.195532862","rc":[{"atl":[[8.4,0.45]],"id":36042617}],"con":true,"img":false}]}
{"op":"mcm","clk":"5322487226","pt":1646320807968,"mc":[{"id":"1.195532862","rc":[{"atl":[[8,1]],"id":36042617}],"con":true,"img":false}]}
{"op":"mcm","clk":"5322487231","pt":1646320808030,"mc":[{"id":"1.195532862","rc":[{"atl":[[8.4,0]],"id":36042617}],"con":true,"img":false}]}
{"op":"mcm","clk":"5322487237","pt":1646320808138,"mc":[{"id":"1.195532862","rc":[{"atl":[[8,1.45]],"id":36042617}],"con":true,"img":false}]}
{"op":"mcm","clk":"5322487244","pt":1646320808239,"mc":[{"id":"1.195532862","rc":[{"atl":[[8.2,0.2]],"id":36042617}],"con":true,"img":false}]}
{"op":"mcm","clk":"5322487267","pt":1646320808559,"mc":[{"id":"1.195532862","rc":[{"atl":[[8,0.45]],"id":36042617}],"con":true,"img":false}]}
{"op":"mcm","clk":"5322487275","pt":1646320808666,"mc":[{"id":"1.195532862","rc":[{"atl":[[8.4,1]],"id":36042617}],"con":true,"img":false}]}
{"op":"mcm","clk":"5322487292","pt":1646320808857,"mc":[{"id":"1.195532862","rc":[{"atl":[[8,0]],"id":36042617}],"con":true,"img":false}]}
{"op":"mcm","clk":"5322487302","pt":1646320808959,"mc":[{"id":"1.195532862","rc":[{"atl":[[8.4,1.45]],"id":36042617}],"con":true,"img":false}]}
{"op":"mcm","clk":"5322487308","pt":1646320809077,"mc":[{"id":"1.195532862","rc":[{"atl":[[8.2,3.22]],"id":36042617}],"con":true,"img":false}]}
{"op":"mcm","clk":"5322487331","pt":1646320809338,"mc":[{"id":"1.195532862","rc":[{"atl":[[8.4,0.45]],"id":36042617}],"con":true,"img":false}]}
{"op":"mcm","clk":"5322487338","pt":1646320809445,"mc":[{"id":"1.195532862","rc":[{"atl":[[8,1]],"id":36042617}],"con":true,"img":false}]}
{"op":"mcm","clk":"5322487381","pt":1646320810066,"mc":[{"id":"1.195532862","rc":[{"atl":[[9.6,11.43]],"id":36042617},{"atb":[[7,1.75]],"id":39693066}],"con":true,"img":false}]}
{"op":"mcm","clk":"5322487398","pt":1646320810274,"mc":[{"id":"1.195532862","rc":[{"atl":[[8.2,0.2],[8.6,37.99]],"id":36042617}],"con":true,"img":false}]}
{"op":"mcm","clk":"5322487409","pt":1646320810378,"mc":[{"id":"1.195532862","rc":[{"atl":[[8.4,5.86],[8.6,32.73]],"id":36042617}],"con":true,"img":false}]}
{"op":"mcm","clk":"5322487425","pt":1646320810534,"mc":[{"id":"1.195532862","rc":[{"atl":[[8,0]],"id":36042617},{"atb":[[5.4,4.59]],"id":39693066}],"con":true,"img":false}]}
{"op":"mcm","clk":"5322487430","pt":1646320810628,"mc":[{"id":"1.195532862","rc":[{"atl":[[8.4,6.86]],"id":36042617}],"con":true,"img":false}]}
{"op":"mcm","clk":"5322487442","pt":1646320810741,"mc":[{"id":"1.195532862","rc":[{"atl":[[9.2,0]],"id":36042617},{"atb":[[7,0]],"id":39693066}],"con":true,"img":false}]}
{"op":"mcm","clk":"5322487458","pt":1646320810950,"mc":[{"id":"1.195532862","rc":[{"atl":[[8.6,36.72]],"id":36042617}],"con":true,"img":false}]}
{"op":"mcm","clk":"5322487474","pt":1646320811151,"mc":[{"id":"1.195532862","rc":[{"atl":[[8.2,3.22]],"id":36042617}],"con":true,"img":false}]}
{"op":"mcm","clk":"5322487490","pt":1646320811364,"mc":[{"id":"1.195532862","rc":[{"atl":[[8.4,5.86]],"id":36042617}],"con":true,"img":false}]}
{"op":"mcm","clk":"5322487499","pt":1646320811467,"mc":[{"id":"1.195532862","rc":[{"atl":[[8,1]],"id":36042617}],"con":true,"img":false}]}
{"op":"mcm","clk":"5322487513","pt":1646320811675,"mc":[{"id":"1.195532862","rc":[{"atb":[[1.04,2]],"id":8668222}],"con":true,"img":false}]}
{"op":"mcm","clk":"5322487526","pt":1646320811877,"mc":[{"id":"1.195532862","rc":[{"atb":[[1.04,0.2]],"id":8668222}],"con":true,"img":false}]}
{"op":"mcm","clk":"5322487538","pt":1646320812041,"mc":[{"id":"1.195532862","rc":[{"atl":[[8.2,0.2]],"id":36042617},{"atb":[[1.04,0]],"id":8668222}],"con":true,"img":false}]}
{"op":"mcm","clk":"5322487548","pt":1646320812144,"mc":[{"id":"1.195532862","rc":[{"atb":[[5.2,1.2]],"id":8668222}],"con":true,"img":false}]}
{"op":"mcm","clk":"5322487555","pt":1646320812247,"mc":[{"id":"1.195532862","rc":[{"atl":[[8,0]],"id":36042617}],"con":true,"img":false}]}
{"op":"mcm","clk":"5322487563","pt":1646320812345,"mc":[{"id":"1.195532862","rc":[{"atl":[[8.2,1.2]],"id":36042617}],"con":true,"img":false}]}
{"op":"mcm","clk":"5322487605","pt":1646320812758,"mc":[{"id":"1.195532862","rc":[{"atl":[[8.6,23.56],[8.2,7.07]],"id":36042617}],"con":true,"img":false}]}
{"op":"mcm","clk":"5322487624","pt":1646320812965,"mc":[{"id":"1.195532862","rc":[{"atl":[[8.2,10.09]],"id":36042617}],"con":true,"img":false}]}
{"op":"mcm","clk":"5322487757","pt":1646320814570,"mc":[{"id":"1.195532862","rc":[{"atl":[[8.6,14.99]],"id":36042617},{"atb":[[5.4,12.44]],"id":28603683}],"con":true,"img":false}]}
{"op":"mcm","clk":"5322487765","pt":1646320814675,"mc":[{"id":"1.195532862","rc":[{"atl":[[8.6,11]],"id":36042617},{"atb":[[5.4,4.95]],"id":28603683}],"con":true,"img":false}]}
{"op":"mcm","clk":"5322487772","pt":1646320814739,"mc":[{"id":"1.195532862","rc":[{"atl":[[8.4,14.18]],"id":36042617},{"atb":[[5.5,11.73]],"id":28603683}],"con":true,"img":false}]}
{"op":"mcm","clk":"5322487780","pt":1646320814844,"mc":[{"id":"1.195532862","rc":[{"atl":[[8.2,13.54]],"id":36042617},{"atb":[[5.5,18.76]],"id":28603683}],"con":true,"img":false}]}
{"op":"mcm","clk":"5322487814","pt":1646320815263,"mc":[{"id":"1.195532862","rc":[{"atl":[[14,19.23]],"id":39693066}],"con":true,"img":false}]}
{"op":"mcm","clk":"5322487841","pt":1646320815575,"mc":[{"id":"1.195532862","rc":[{"atl":[[8.6,16.26],[8.4,8.77]],"id":36042617}],"con":true,"img":false}]}
{"op":"mcm","clk":"5322488002","pt":1646320817357,"mc":[{"id":"1.195532862","rc":[{"atl":[[8.4,0.45]],"id":36042617}],"con":true,"img":false}]}
{"op":"mcm","clk":"5322488021","pt":1646320817565,"mc":[{"id":"1.195532862","rc":[{"atl":[[9.6,0.43],[8.6,20.3],[8.2,21.6]],"id":36042617}],"con":true,"img":false}]}
{"op":"mcm","clk":"5322488031","pt":1646320817668,"mc":[{"id":"1.195532862","rc":[{"atl":[[8.6,16.26]],"id":36042617}],"con":true,"img":false}]}
{"op":"mcm","clk":"5322488068","pt":1646320818188,"mc":[{"id":"1.195532862","rc":[{"atl":[[25,2]],"id":35839928}],"con":true,"img":false}]}
{"op":"mcm","clk":"5322488253","pt":1646320820264,"mc":[{"id":"1.195532862","rc":[{"atl":[[8.6,5.26]],"id":36042617}],"con":true,"img":false}]}
{"op":"mcm","clk":"5322488262","pt":1646320820369,"mc":[{"id":"1.195532862","rc":[{"atl":[[8.2,32.6]],"id":36042617}],"con":true,"img":false}]}
{"op":"mcm","clk":"5322488279","pt":1646320820580,"mc":[{"id":"1.195532862","rc":[{"atb":[[6,0.17]],"id":28603683},{"trd":[[6,1.65]],"ltp":6.0,"tv":1.65,"id":28603683}],"con":true,"img":false}]}
{"op":"mcm","clk":"5322488287","pt":1646320820685,"mc":[{"id":"1.195532862","rc":[{"atb":[[5.4,0.2]],"id":39693066}],"con":true,"img":false}]}
{"op":"mcm","clk":"5322488294","pt":1646320820781,"mc":[{"id":"1.195532862","rc":[{"atb":[[4.5,0]],"id":28603683},{"atl":[[8.4,2.94],[1000,13.65]],"id":28603683}],"con":true,"img":false}]}
{"op":"mcm","clk":"5322488301","pt":1646320820885,"mc":[{"id":"1.195532862","rc":[{"atl":[[1000,12.51]],"id":28603683}],"con":true,"img":false}]}
{"op":"mcm","clk":"5322488315","pt":1646320821051,"mc":[{"id":"1.195532862","rc":[{"atl":[[1000,12]],"id":28603683}],"con":true,"img":false}]}
{"op":"mcm","clk":"5322488322","pt":1646320821147,"mc":[{"id":"1.195532862","rc":[{"atl":[[8,0.51]],"id":28603683}],"con":true,"img":false}]}
{"op":"mcm","clk":"5322488517","pt":1646320823982,"mc":[{"id":"1.195532862","rc":[{"atl":[[10,2.43]],"id":39693066},{"atb":[[5.6,4.86]],"id":28603683},{"atb":[[5.2,4.2]],"id":8668222},{"atl":[[6.4,8.03]],"id":8668222},{"atb":[[3,3]],"id":28691352},{"atl":[[3.45,3]],"id":28691352}],"con":true,"img":false}]}
{"op":"mcm","clk":"5322488528","pt":1646320824182,"mc":[{"id":"1.195532862","rc":[{"atl":[[10.5,10.55]],"id":39693066},{"atb":[[2.96,7.5]],"id":28691352},{"atl":[[3.5,21.32]],"id":28691352}],"con":true,"img":false}]}
{"op":"mcm","clk":"5322488534","pt":1646320824297,"mc":[{"id":"1.195532862","rc":[{"atl":[[9.8,1]],"id":39693066},{"atl":[[9,12.5]],"id":36042617}],"con":true,"img":false}]}
{"op":"mcm","clk":"5322488544","pt":1646320824356,"mc":[{"id":"1.195532862","rc":[{"atl":[[3.6,3.94]],"id":28691352}],"con":true,"img":false}]}
{"op":"mcm","clk":"5322488551","pt":1646320824457,"mc":[{"id":"1.195532862","rc":[{"atl":[[3.5,21.01]],"id":28691352}],"con":true,"img":false}]}
{"op":"mcm","clk":"5322488561","pt":1646320824567,"mc":[{"id":"1.195532862","rc":[{"atl":[[3.45,3.3]],"id":28691352}],"con":true,"img":false}]}
{"op":"mcm","clk":"5322488569","pt":1646320824667,"mc":[{"id":"1.195532862","rc":[{"atl":[[3.6,0]],"id":28691352}],"con":true,"img":false}]}
{"op":"mcm","clk":"5322488582","pt":1646320824770,"mc":[{"id":"1.195532862","rc":[{"atl":[[10.5,7.35]],"id":39693066},{"atb":[[5.5,11.73]],"id":28603683},{"atb":[[5.1,20.02]],"id":8668222},{"atb":[[2.96,0]],"id":28691352}],"con":true,"img":false}]}
{"op":"mcm","clk":"5322488597","pt":1646320824979,"mc":[{"id":"1.195532862","rc":[{"atl":[[10,5.19]],"id":39693066},{"atb":[[5.6,11.47]],"id":28603683},{"atb":[[5.2,11.98]],"id":8668222},{"atl":[[3.5,20.01],[3.45,12.2]],"id":28691352}],"con":true,"img":false}]}
{"op":"mcm","clk":"5322488607","pt":1646320825086,"mc":[{"id":"1.195532862","rc":[{"atl":[[10.5,3.87]],"id":39693066},{"atb":[[5.5,5]],"id":28603683},{"atb":[[5.1,11]],"id":8668222},{"atl":[[3.4,1]],"id":28691352}],"con":true,"img":false}]}
{"op":"mcm","clk":"5322488624","pt":1646320825280,"mc":[{"id":"1.195532862","rc":[{"atl":[[10,8.22]],"id":39693066},{"atb":[[5.6,17.77]],"id":28603683},{"atb":[[5.2,20.49]],"id":8668222}],"con":true,"img":false}]}
{"op":"mcm","clk":"5322488648","pt":1646320825570,"mc":[{"id":"1.195532862","rc":[{"atl":[[11,0],[12,0],[13,0]],"id":36042617},{"atl":[[8.4,8.35],[8.6,1.33]],"id":28603683}],"con":true,"img":false}]}
{"op":"mcm","clk":"5322488655","pt":1646320825657,"mc":[{"id":"1.195532862","rc":[{"atl":[[10.5,8.08],[11,0]],"id":39693066}],"con":true,"img":false}]}
{"op":"mcm","clk":"5322488664","pt":1646320825768,"mc":[{"id":"1.195532862","rc":[{"atl":[[8.8,22.45]],"id":28603683},{"atl":[[3.45,3.3]],"id":28691352}],"con":true,"img":false}]}
{"op":"mcm","clk":"5322488670","pt":1646320825867,"mc":[{"id":"1.195532862","rc":[{"atl":[[10,7.78]],"id":39693066}],"con":true,"img":false}]}
{"op":"mcm","clk":"5322488678","pt":1646320825972,"mc":[{"id":"1.195532862","rc":[{"atl":[[1000,12.43]],"id":39693066},{"atl":[[8.8,17.82]],"id":28603683}],"con":true,"img":false}]}
{"op":"mcm","clk":"5322488891","pt":1646320828772,"mc":[{"id":"1.195532862","rc":[{"atb":[[5.3,12.49]],"id":28603683}],"con":true,"img":false}]}
{"op":"mcm","clk":"5322488902","pt":1646320828880,"mc":[{"id":"1.195532862","rc":[{"atl":[[3.4,10.08]],"id":28691352}],"con":true,"img":false}]}
{"op":"mcm","clk":"5322488934","pt":1646320829286,"mc":[{"id":"1.195532862","rc":[{"atl":[[3.45,3]],"id":28691352}],"con":true,"img":false}]}
{"op":"mcm","clk":"5322488943","pt":1646320829388,"mc":[{"id":"1.195532862","rc":[{"atl":[[10.5,7.98]],"id":39693066},{"atb":[[5.3,8]],"id":28603683},{"atl":[[3.4,10.39]],"id":28691352}],"con":true,"img":false}]}
{"op":"mcm","clk":"5322488953","pt":1646320829450,"mc":[{"id":"1.195532862","rc":[{"atl":[[9.8,1.1]],"id":39693066}],"con":true,"img":false}]}
{"op":"mcm","clk":"5322488998","pt":1646320829967,"mc":[{"id":"1.195532862","rc":[{"atl":[[3.5,8.56]],"id":28691352}],"con":true,"img":false}]}
{"op":"mcm","clk":"5322489012","pt":1646320830168,"mc":[{"id":"1.195532862","rc":[{"atl":[[3.4,20.65]],"id":28691352}],"con":true,"img":false}]}
{"op":"mcm","clk":"5322489021","pt":1646320830282,"mc":[{"id":"1.195532862","rc":[{"atl":[[3.5,0]],"id":28691352}],"con":true,"img":false}]}
{"op":"mcm","clk":"5322489037","pt":1646320830490,"mc":[{"id":"1.195532862","rc":[{"atl":[[3.4,28.07]],"id":28691352}],"con":true,"img":false}]}
{"op":"mcm","clk":"5322489190","pt":1646320832574,"mc":[{"id":"1.195532862","rc":[{"atl":[[18,1.5]],"id":28603683}],"con":true,"img":false}]}
{"op":"mcm","clk":"5322489209","pt":1646320832886,"mc":[{"id":"1.195532862","rc":[{"spn":8.8,"spf":1.0,"id":39693066},{"atl":[[9.4,17.86]],"id":36042617},{"spn":5.51,"spf":1.0,"id":36042617},{"spn":10.93,"spf":1.0,"id":35839928},{"spn":7.0,"spf":1.0,"id":28603683},{"spn":3.4,"spf":3.77,"id":28691352}],"con":true,"img":false}]}
{"op":"mcm","clk":"5322489278","pt":1646320833762,"mc":[{"id":"1.195532862","rc":[{"atb":[[5.2,0]],"id":36042617},{"atb":[[5.6,16.16]],"id":28603683}],"con":true,"img":false}]}
{"op":"mcm","clk":"5322489285","pt":1646320833865,"mc":[{"id":"1.195532862","rc":[{"atb":[[1.01,11004.69]],"id":36042617},{"atb":[[1.01,11003.61]],"id":28603683}],"con":true,"img":false}]}
{"op":"mcm","clk":"5322489296","pt":1646320833971,"mc":[{"id":"1.195532862","rc":[{"atb":[[5.4,4.59]],"id":39693066}],"con":true,"img":false}]}
{"op":"mcm","clk":"5322489466","pt":1646320836050,"mc":[{"id":"1.195532862","rc":[{"atb":[[5.6,13.91]],"id":28603683}],"con":true,"img":false}]}
{"op":"mcm","clk":"5322489474","pt":1646320836152,"mc":[{"id":"1.195532862","rc":[{"atb":[[5.7,2.65]],"id":28603683}],"con":true,"img":false}]}
{"op":"mcm","clk":"5322489534","pt":1646320836952,"mc":[{"id":"1.195532862","rc":[{"atb":[[5.6,12.91]],"id":28603683}],"con":true,"img":false}]}
{"op":"mcm","clk":"5322489543","pt":1646320837058,"mc":[{"id":"1.195532862","rc":[{"atb":[[5.8,1]],"id":28603683}],"con":true,"img":false}]}
{"op":"mcm","clk":"5322489747","pt":1646320839359,"mc":[{"id":"1.195532862","rc":[{"atb":[[5.4,0.2]],"id":39693066}],"con":true,"img":false}]}
{"op":"mcm","clk":"5322489910","pt":1646320841344,"mc":[{"id":"1.195532862","rc":[{"atl":[[9.8,29.56]],"id":36042617}],"con":true,"img":false}]}
{"op":"mcm","clk":"5322489928","pt":1646320841548,"mc":[{"id":"1.195532862","rc":[{"atl":[[3.55,0]],"id":28691352}],"con":true,"img":false}]}
{"op":"mcm","clk":"5322490093","pt":1646320843483,"mc":[{"id":"1.195532862","rc":[{"atl":[[3.4,23.07]],"id":28691352},{"trd":[[3.4,9.99]],"ltp":3.4,"tv":9.99,"id":28691352}],"con":true,"img":false}]}
{"op":"mcm","clk":"5322490786","pt":1646320851276,"mc":[{"id":"1.195532862","rc":[{"atb":[[5.3,11.32]],"id":28603683}],"con":true,"img":false}]}
{"op":"mcm","clk":"5322490867","pt":1646320852374,"mc":[{"id":"1.195532862","rc":[{"atb":[[5.6,20],[5.1,27],[6,12],[7,5],[6.6,8]],"id":39693066}],"con":true,"img":false}]}
{"op":"mcm","clk":"5322490892","pt":1646320852692,"mc":[{"id":"1.195532862","rc":[{"atb":[[6.8,3.13]],"id":39693066}],"con":true,"img":false}]}
{"op":"mcm","clk":"5322490909","pt":1646320852899,"mc":[{"id":"1.195532862","rc":[{"atb":[[6.8,0]],"id":39693066}],"con":true,"img":false}]}
{"op":"mcm","clk":"5322491010","pt":1646320854199,"mc":[{"id":"1.195532862","rc":[{"atl":[[17.5,18],[20,27],[13,17.5],[14,27.23],[15.5,12]],"id":39693066}],"con":true,"img":false}]}
{"op":"mcm","clk":"5322491112","pt":1646320855498,"mc":[{"id":"1.195532862","rc":[{"atb":[[5.3,8]],"id":28603683}],"con":true,"img":false}]}
{"op":"mcm","clk":"5322491204","pt":1646320856593,"mc":[{"id":"1.195532862","rc":[{"atl":[[3.4,35.07]],"id":28691352}],"con":true,"img":false}]}
{"op":"mcm","clk":"5322491883","pt":1646320864097,"mc":[{"id":"1.195532862","rc":[{"atl":[[8.4,4.65]],"id":36042617}],"con":true,"img":false}]}
{"op":"mcm","clk":"5322491933","pt":1646320864620,"mc":[{"id":"1.195532862","rc":[{"atl":[[8.4,0.45]],"id":36042617}],"con":true,"img":false}]}
{"op":"mcm","clk":"5322492232","pt":1646320867915,"mc":[{"id":"1.195532862","rc":[{"atl":[[5,6.68]],"id":28691352}],"con":true,"img":false}]}
{"op":"mcm","clk":"5322492268","pt":1646320868180,"mc":[{"id":"1.195532862","rc":[{"atl":[[5,0]],"id":28691352}],"con":true,"img":false}]}
{"op":"mcm","clk":"5322492286","pt":1646320868390,"mc":[{"id":"1.195532862","rc":[{"atb":[[3.25,0]],"id":28691352},{"atl":[[3.25,3.01]],"id":28691352},{"trd":[[3.25,4.67]],"ltp":3.25,"tv":4.67,"id":28691352}],"con":true,"img":false}]}
{"op":"mcm","clk":"5322492323","pt":1646320868811,"mc":[{"id":"1.195532862","rc":[{"atl":[[1000,15.17]],"id":28691352}],"con":true,"img":false}]}
{"op":"mcm","clk":"5322492334","pt":1646320869032,"mc":[{"id":"1.195532862","rc":[{"atl":[[1000,12.42]],"id":28691352}],"con":true,"img":false}]}
{"op":"mcm","clk":"5322492348","pt":1646320869226,"mc":[{"id":"1.195532862","rc":[{"atl":[[1000,12]],"id":28691352}],"con":true,"img":false}]}
{"op":"mcm","clk":"5322492356","pt":1646320869283,"mc":[{"id":"1.195532862","rc":[{"atl":[[3.25,3.44]],"id":28691352}],"con":true,"img":false}]}
{"op":"mcm","clk":"5322492364","pt":1646320869387,"mc":[{"id":"1.195532862","rc":[{"atl":[[12,9.09],[12.5,8.7]],"id":39693066},{"atl":[[9,25],[8.8,5]],"id":28603683},{"atl":[[7.4,15.62],[7.6,15.15]],"id":8668222},{"atb":[[2.98,0],[2.94,28.67],[3.05,6.19]],"id":28691352}],"con":true,"img":false}]}
{"op":"mcm","clk":"5322492374","pt":1646320869491,"mc":[{"id":"1.195532862","rc":[{"atl":[[8.2,36.17]],"id":36042617},{"atb":[[2.96,8.05]],"id":28691352}],"con":true,"img":false}]}
{"op":"mcm","clk":"5322492385","pt":1646320869706,"mc":[{"id":"1.195532862","rc":[{"atl":[[8.2,32.6]],"id":36042617},{"atb":[[2.94,20.62],[2.96,0]],"id":28691352}],"con":true,"img":false}]}
{"op":"mcm","clk":"5322492559","pt":1646320871831,"mc":[{"id":"1.195532862","rc":[{"atb":[[5.1,36.76],[4.6,0]],"id":39693066}],"con":true,"img":false}]}
{"op":"mcm","clk":"5322492567","pt":1646320871934,"mc":[{"id":"1.195532862","rc":[{"atb":[[4.9,0],[5.5,22.22]],"id":39693066}],"con":true,"img":false}]}
{"op":"mcm","clk":"5322492638","pt":1646320873199,"mc":[{"id":"1.195532862","rc":[{"atb":[[5.4,8.27]],"id":28603683}],"con":true,"img":false}]}
{"op":"mcm","clk":"5322492676","pt":1646320873547,"mc":[{"id":"1.195532862","rc":[{"atb":[[5.4,4.95]],"id":28603683}],"con":true,"img":false}]}
{"op":"mcm","clk":"5322492980","pt":1646320877213,"mc":[{"id":"1.195532862","rc":[{"atb":[[4.1,27],[4.2,12.61]],"id":28603683},{"atb":[[2.9,52.63]],"id":28691352}],"con":true,"img":false}]}
{"op":"mcm","clk":"5322493084","pt":1646320878524,"mc":[{"id":"1.195532862","rc":[{"atl":[[3.65,12.1]],"id":28691352}],"con":true,"img":false}]}
{"op":"mcm","clk":"5322493148","pt":1646320879513,"mc":[{"id":"1.195532862","rc":[{"atb":[[2.94,0],[2.86,0]],"id":28691352},{"atl":[[4.5,31.15]],"id":28691352}],"con":true,"img":false}]}
{"op":"mcm","clk":"5322493154","pt":1646320879616,"mc":[{"id":"1.195532862","rc":[{"atb":[[4.9,25.64]],"id":39693066},{"atl":[[11.5,9.52],[12.5,0]],"id":39693066},{"atb":[[4.4,18.55]],"id":36042617},{"atb":[[7.2,25.75],[6.2,7.69]],"id":35839928},{"atl":[[17.5,12.09],[22,0]],"id":35839928},{"atb":[[4.3,27],[5.3,0],[3.8,53.57],[5.5,0]],"id":28603683},{"atl":[[9,12.5],[8.2,3.66],[8.8,8.25]],"id":28603683},{"atl":[[7.2,16.66],[7.6,0]],"id":8668222},{"atb":[[2.72,0],[2.86,21.51],[3.05,9.28]],"id":28691352},{"atl":[[3.25,0.53],[3.4,23.07],[3.65,0.1],[4.7,22.95]],"id":28691352},{"trd":[[3.25,10.48]],"ltp":3.25,"tv":10.48,"id":28691352}],"con":true,"img":false}]}
{"op":"mcm","clk":"5322493170","pt":1646320879822,"mc":[{"id":"1.195532862","rc":[{"atb":[[4.4,11.88]],"id":36042617},{"atl":[[8.8,5]],"id":28603683},{"atb":[[3.1,1],[3.05,6.19]],"id":28691352},{"atl":[[1000,14]],"id":28691352}],"con":true,"img":false}]}
{"op":"mcm","clk":"5322493183","pt":1646320880034,"mc":[{"id":"1.195532862","rc":[{"atl":[[1000,13]],"id":28691352}],"con":true,"img":false}]}
{"op":"mcm","clk":"5322493194","pt":1646320880139,"mc":[{"id":"1.195532862","rc":[{"atl":[[8.2,26.73]],"id":36042617},{"atb":[[4.4,6.95],[4,0],[4.2,0]],"id":39693066},{"atb":[[7.2,32.2],[6.2,0]],"id":35839928},{"atl":[[16.5,0],[17,3.84],[17.5,6.03]],"id":35839928},{"atb":[[4.2,0.12]],"id":8668222},{"atl":[[7.2,23.11],[7,0]],"id":8668222},{"atb":[[2.64,24.39],[3.05,0],[2.9,0],[2.86,0]],"id":28691352},{"atl":[[4.4,11.62],[4,13.17],[4.5,20],[4.1,12.75],[4.2,12.35]],"id":28691352}],"con":true,"img":false}]}
{"op":"mcm","clk":"5322493201","pt":1646320880250,"mc":[{"id":"1.195532862","rc":[{"atl":[[8.4,13.96]],"id":36042617},{"atb":[[4.3,0]],"id":28603683},{"atb":[[4.1,6.18]],"id":8668222},{"atl":[[5.3,56.88],[1000,12]],"id":28691352}],"con":true,"img":false}]}
{"op":"mcm","clk":"5322493212","pt":1646320880349,"mc":[{"id":"1.195532862","rc":[{"atl":[[17,7.05],[23,4.55]],"id":35839928},{"atb":[[4,33.33]],"id":8668222},{"atb":[[2.8,26.28]],"id":28691352}],"con":true,"img":false}]}
{"op":"mcm","clk":"5322493216","pt":1646320880407,"mc":[{"id":"1.195532862","rc":[{"atb":[[4.1,59.26]],"id":28603683},{"atb":[[4.1,0]],"id":8668222},{"atl":[[7.2,27.13]],"id":8668222},{"atl":[[3.35,1]],"id":28691352}],"con":true,"img":false}]}
{"op":"mcm","clk":"5322493231","pt":1646320880622,"mc":[{"id":"1.195532862","rc":[{"atb":[[5.7,4.65]],"id":28603683}],"con":true,"img":false}]}
{"op":"mcm","clk":"5322493251","pt":1646320880827,"mc":[{"id":"1.195532862","rc":[{"atl":[[17,3.84]],"id":35839928},{"atl":[[7.2,23.11]],"id":8668222}],"con":true,"img":false}]}
{"op":"mcm","clk":"5322493267","pt":1646320880934,"mc":[{"id":"1.195532862","rc":[{"atb":[[3.1,0]],"id":28691352}],"con":true,"img":false}]}
{"op":"mcm","clk":"5322493274","pt":1646320881038,"mc":[{"id":"1.195532862","rc":[{"atb":[[3.05,1]],"id":28691352}],"con":true,"img":false}]}
{"op":"mcm","clk":"5322493287","pt":1646320881140,"mc":[{"id":"1.195532862","rc":[{"atb":[[1.72,2]],"id":28691352}],"con":true,"img":false}]}
{"op":"mcm","clk":"5322493389","pt":1646320882443,"mc":[{"id":"1.195532862","rc":[{"atb":[[4.4,0.12],[4.2,43.75]],"id":36042617},{"atl":[[8,13.97],[8.4,0.45]],"id":36042617},{"atl":[[10.5,3.77],[11,4],[11.5,0]],"id":39693066},{"atb":[[8,5.84],[7.2,25.75]],"id":35839928},{"atl":[[17,1.35],[21,1.99],[23,0]],"id":35839928},{"atb":[[3.75,14.55],[3.95,0]],"id":8668222},{"atl":[[7.2,16.66],[7,6.67]],"id":8668222},{"atb":[[2.52,26.32],[2.64,0]],"id":28691352},{"atl":[[3.85,13.86],[5.3,0],[4.9,0],[4.4,0],[4,0],[5.1,0],[4.1,0],[4.2,11.62],[4.7,0]],"id":28691352}],"con":true,"img":false}]}
{"op":"mcm","clk":"5322493405","pt":1646320882655,"mc":[{"id":"1.195532862","rc":[{"atl":[[8.6,0],[8.2,25.73],[8.4,5.86]],"id":36042617},{"atb":[[5.9,20],[5.5,0]],"id":39693066},{"atl":[[12,14.74],[13,25.83]],"id":39693066},{"atl":[[17.5,0],[29,3.57]],"id":35839928},{"atl":[[8.2,1.66],[9.6,11.63]],"id":28603683},{"atb":[[3.85,0]],"id":8668222},{"atl":[[7.2,4.68]],"id":8668222},{"atb":[[2.8,13.14]],"id":28691352}],"con":true,"img":false}]}
{"op":"mcm","clk":"5322493411","pt":1646320882757,"mc":[{"id":"1.195532862","rc":[{"atl":[[7.8,1]],"id":36042617},{"atl":[[8.6,4.71]],"id":28603683},{"atl":[[7.6,15.15]],"id":8668222},{"atb":[[2.64,12.56]],"id":28691352}],"con":true,"img":false}]}
{"op":"mcm","clk":"5322493429","pt":1646320882919,"mc":[{"id":"1.195532862","rc":[{"atl":[[7.2,0.58]],"id":8668222}],"con":true,"img":false}]}
{"op":"mcm","clk":"5322493435","pt":1646320883027,"mc":[{"id":"1.195532862","rc":[{"atl":[[12,9.09]],"id":39693066},{"atl":[[8.6,1.33]],"id":28603683}],"con":true,"img":false}]}
{"op":"mcm","clk":"5322493444","pt":1646320883230,"mc":[{"id":"1.195532862","rc":[{"atl":[[8.4,5.41]],"id":36042617},{"atl":[[1000,12]],"id":35839928}],"con":true,"img":false}]}
{"op":"mcm","clk":"5322493449","pt":1646320883336,"mc":[{"id":"1.195532862","rc":[{"atl":[[7.8,1.45]],"id":36042617},{"atl":[[18,0.48]],"id":35839928},{"atb":[[3,7.81]],"id":28691352}],"con":true,"img":false}]}
{"op":"mcm","clk":"5322493463","pt":1646320883548,"mc":[{"id":"1.195532862","rc":[{"atl":[[8.2,22.7]],"id":36042617}],"con":true,"img":false}]}
{"op":"mcm","clk":"5322493473","pt":1646320883755,"mc":[{"id":"1.195532862","rc":[{"atb":[[3,3]],"id":28691352}],"con":true,"img":false}]}
{"op":"mcm","clk":"5322493543","pt":1646320884855,"mc":[{"id":"1.195532862","rc":[{"atb":[[8.2,13.89],[7.2,9.62],[7,4.03]],"id":35839928}],"con":true,"img":false}]}
{"op":"mcm","clk":"5322493557","pt":1646320884949,"mc":[{"id":"1.195532862","rc":[{"atb":[[4,33.32]],"id":28603683}],"con":true,"img":false}]}
{"op":"mcm","clk":"5322493566","pt":1646320885057,"mc":[{"id":"1.195532862","rc":[{"atb":[[7,0]],"id":35839928}],"con":true,"img":false}]}
{"op":"mcm","clk":"5322493584","pt":1646320885269,"mc":[{"id":"1.195532862","rc":[{"atl":[[7.8,4.66],[8.4,8.83]],"id":36042617}],"con":true,"img":false}]}
{"op":"mcm","clk":"5322493599","pt":1646320885468,"mc":[{"id":"1.195532862","rc":[{"atl":[[8.4,5.41]],"id":36042617}],"con":true,"img":false}]}
{"op":"mcm","clk":"5322493661","pt":1646320886151,"mc":[{"id":"1.195532862","rc":[{"atb":[[5.7,2]],"id":28603683},{"atb":[[5.2,17.49]],"id":8668222},{"atb":[[3,0]],"id":28691352},{"atl":[[3.45,0]],"id":28691352}],"con":true,"img":false}]}
{"op":"mcm","clk":"5322493670","pt":1646320886299,"mc":[{"id":"1.195532862","rc":[{"atl":[[7.8,6.76]],"id":36042617},{"atb":[[5.8,3.54]],"id":28603683},{"atb":[[5.3,2]],"id":8668222},{"atb":[[2.96,2.97]],"id":28691352},{"atl":[[3.35,4]],"id":28691352}],"con":true,"img":false}]}
{"op":"mcm","clk":"5322493722","pt":1646320886874,"mc":[{"id":"1.195532862","rc":[{"atb":[[5.2,16.49]],"id":8668222},{"atb":[[3.05,0]],"id":28691352}],"con":true,"img":false}]}
{"op":"mcm","clk":"5322493731","pt":1646320886985,"mc":[{"id":"1.195532862","rc":[{"atb":[[5.4,1]],"id":8668222},{"atb":[[2.98,1]],"id":28691352}],"con":true,"img":false}]}
{"op":"mcm","clk":"5322493802","pt":1646320887762,"mc":[{"id":"1.195532862","rc":[{"atl":[[12.5,8.7],[13,17.5]],"id":39693066},{"atl":[[24,4.22]],"id":35839928},{"atl":[[9,25],[9.6,0]],"id":28603683}],"con":true,"img":false}]}
{"op":"mcm","clk":"5322493814","pt":1646320887873,"mc":[{"id":"1.195532862","rc":[{"atl":[[29,0]],"id":35839928},{"atl":[[1000,14.52]],"id":8668222}],"con":true,"img":false}]}
{"op":"mcm","clk":"5322493823","pt":1646320887969,"mc":[{"id":"1.195532862","rc":[{"atl":[[8,0],[8.2,28.26],[7.8,20.73],[8.4,0]],"id":36042617},{"atl":[[18.5,0]],"id":35839928},{"atb":[[3.7,0]],"id":28603683}],"con":true,"img":false}]}
{"op":"mcm","clk":"5322493832","pt":1646320888072,"mc":[{"id":"1.195532862","rc":[{"atl":[[1000,14.1]],"id":8668222}],"con":true,"img":false}]}
{"op":"mcm","clk":"5322493840","pt":1646320888188,"mc":[{"id":"1.195532862","rc":[{"atl":[[1000,12]],"id":8668222}],"con":true,"img":false}]}
{"op":"mcm","clk":"5322493848","pt":1646320888281,"mc":[{"id":"1.195532862","rc":[{"atl":[[6.2,2.1]],"id":8668222}],"con":true,"img":false}]}
{"op":"mcm","clk":"5322493861","pt":1646320888595,"mc":[{"id":"1.195532862","rc":[{"atl":[[18,0]],"id":35839928},{"atl":[[6.4,7.03]],"id":8668222}],"con":true,"img":false}]}
{"op":"mcm","clk":"5322493869","pt":1646320888651,"mc":[{"id":"1.195532862","rc":[{"atl":[[1000,12.48]],"id":35839928},{"atl":[[6,1]],"id":8668222}],"con":true,"img":false}]}
{"op":"mcm","clk":"5322493882","pt":1646320888752,"mc":[{"id":"1.195532862","rc":[{"atl":[[6.4,3]],"id":8668222}],"con":true,"img":false}]}
{"op":"mcm","clk":"5322493958","pt":1646320889846,"mc":[{"id":"1.195532862","rc":[{"atb":[[2.9,0]],"id":36042617},{"atb":[[4.4,3.65]],"id":39693066},{"atb":[[2.78,0]],"id":28603683},{"atb":[[2.8,6.9]],"id":28691352}],"con":true,"img":false}]}
{"op":"mcm","clk":"5322493991","pt":1646320889948,"mc":[{"id":"1.195532862","rc":[{"atl":[[6,5.36]],"id":8668222}],"con":true,"img":false}]}
{"op":"mcm","clk":"5322493999","pt":1646320890063,"mc":[{"id":"1.195532862","rc":[{"atl":[[8.2,28.06],[7.6,2.91]],"id":36042617},{"atb":[[4.7,40.54]],"id":39693066},{"atb":[[7.6,15.15]],"id":35839928},{"atl":[[19.5,0.2],[23,4.52]],"id":35839928},{"atb":[[3.65,37.74]],"id":8668222},{"atb":[[2.48,67.57],[2.52,29.59]],"id":28691352},{"atl":[[3.95,33.48]],"id":28691352}],"con":true,"img":false}]}
{"op":"mcm","clk":"5322494006","pt":1646320890158,"mc":[{"id":"1.195532862","rc":[{"atl":[[7.8,20.93]],"id":36042617}],"con":true,"img":false}]}
{"op":"mcm","clk":"5322494015","pt":1646320890264,"mc":[{"id":"1.195532862","rc":[{"atl":[[9.6,6.18],[7.8,19.93]],"id":36042617},{"atl":[[3.35,7.33]],"id":28691352}],"con":true,"img":false}]}
{"op":"mcm","clk":"5322494021","pt":1646320890365,"mc":[{"id":"1.195532862","rc":[{"atl":[[7.4,1]],"id":36042617}],"con":true,"img":false}]}
{"op":"mcm","clk":"5322494037","pt":1646320890583,"mc":[{"id":"1.195532862","rc":[{"atb":[[2.52,26.32]],"id":28691352}],"con":true,"img":false}]}
{"op":"mcm","clk":"5322494050","pt":1646320890780,"mc":[{"id":"1.195532862","rc":[{"atl":[[9.6,0.43]],"id":36042617}],"con":true,"img":false}]}
{"op":"mcm","clk":"5322494072","pt":1646320891091,"mc":[{"id":"1.195532862","rc":[{"atl":[[7.8,16.27]],"id":36042617},{"atl":[[6,5.19]],"id":8668222}],"con":true,"img":false}]}
{"op":"mcm","clk":"5322494084","pt":1646320891145,"mc":[{"id":"1.195532862","rc":[{"atl":[[7.6,3.36]],"id":36042617}],"con":true,"img":false}]}
{"op":"mcm","clk":"5322494090","pt":1646320891250,"mc":[{"id":"1.195532862","rc":[{"atl":[[6,1]],"id":8668222}],"con":true,"img":false}]}
{"op":"mcm","clk":"5322494104","pt":1646320891356,"mc":[{"id":"1.195532862","rc":[{"atl":[[6.2,6.3]],"id":8668222}],"con":true,"img":false}]}
{"op":"mcm","clk":"5322494164","pt":1646320892087,"mc":[{"id":"1.195532862","rc":[{"atb":[[7.2,8]],"id":35839928}],"con":true,"img":false}]}
{"op":"mcm","clk":"5322494177","pt":1646320892290,"mc":[{"id":"1.195532862","rc":[{"atl":[[7.4,4.4]],"id":36042617}],"con":true,"img":false}]}
{"op":"mcm","clk":"5322494195","pt":1646320892553,"mc":[{"id":"1.195532862","rc":[{"atl":[[8.2,24.61]],"id":36042617},{"atb":[[5.6,6.3],[3.9,51.7]],"id":28603683}],"con":true,"img":false}]}
{"op":"mcm","clk":"5322494220","pt":1646320892970,"mc":[{"id":"1.195532862","rc":[{"atl":[[8,3.15]],"id":36042617},{"spn":5.48,"spf":1.0,"id":36042617},{"spn":11.02,"spf":1.0,"id":35839928},{"atb":[[5.7,8.19]],"id":28603683},{"spn":5.4,"spf":1.0,"id":8668222},{"spn":3.31,"spf":3.77,"id":28691352}],"con":true,"img":false}]}
{"op":"mcm","clk":"5322494226","pt":1646320893072,"mc":[{"id":"1.195532862","rc":[{"atl":[[8.2,16.56],[7.6,0.45]],"id":36042617},{"atb":[[5.6,0]],"id":28603683}],"con":true,"img":false}]}
{"op":"mcm","clk":"5322494234","pt":1646320893174,"mc":[{"id":"1.195532862","rc":[{"atb":[[5.9,0],[5.5,0],[5.7,0]],"id":35839928},{"atb":[[3.15,0]],"id":28691352},{"atl":[[3.15,5.35]],"id":28691352},{"trd":[[3.15,0.34]],"ltp":3.15,"tv":0.34,"id":28691352}],"con":true,"img":false}]}
{"op":"mcm","clk":"5322494239","pt":1646320893278,"mc":[{"id":"1.195532862","rc":[{"atl":[[3.15,10.88]],"id":28691352}],"con":true,"img":false}]}
{"op":"mcm","clk":"5322494245","pt":1646320893381,"mc":[{"id":"1.195532862","rc":[{"atb":[[3.1,5.08]],"id":28691352}],"con":true,"img":false}]}
{"op":"mcm","clk":"5322494252","pt":1646320893487,"mc":[{"id":"1.195532862","rc":[{"atl":[[8,10.92]],"id":36042617},{"atb":[[5.7,14.09]],"id":28603683},{"atb":[[3.1,0]],"id":28691352},{"atl":[[3.35,6.33]],"id":28691352},{"trd":[[3.1,10.16]],"ltp":3.1,"tv":10.16,"id":28691352}],"con":true,"img":false}]}
{"op":"mcm","clk":"5322494271","pt":1646320893850,"mc":[{"id":"1.195532862","rc":[{"atb":[[2.66,93.37]],"id":36042617},{"atl":[[34,18.5]],"id":36042617},{"atb":[[2.66,93.37]],"id":39693066},{"atl":[[34,18.5]],"id":39693066},{"atb":[[4.3,77.27],[2.66,93.37]],"id":35839928},{"atb":[[2.66,93.37]],"id":28603683},{"atl":[[34,18.5]],"id":28603683},{"atl":[[34,18.5],[17,11.5]],"id":8668222},{"atl":[[34,18.5],[17,11.5]],"id":28691352}],"con":true,"img":false}]}
{"op":"mcm","clk":"5322494278","pt":1646320893953,"mc":[{"id":"1.195532862","rc":[{"atb":[[2.98,0]],"id":28691352},{"atl":[[3.25,0.11]],"id":28691352}],"con":true,"img":false}]}
{"op":"mcm","clk":"5322494285","pt":1646320894058,"mc":[{"id":"1.195532862","rc":[{"atl":[[3.15,11.3]],"id":28691352}],"con":true,"img":false}]}
{"op":"mcm","clk":"5322494375","pt":1646320894997,"mc":[{"id":"1.195532862","rc":[{"atb":[[2.94,0]],"id":36042617},{"atb":[[4.4,0]],"id":39693066},{"atb":[[2.82,0]],"id":28603683},{"atb":[[2.64,0]],"id":8668222},{"atl":[[6.2,4.19]],"id":8668222},{"atb":[[2.8,0]],"id":28691352}],"con":true,"img":false}]}
{"op":"mcm","clk":"5322494420","pt":1646320895473,"mc":[{"id":"1.195532862","rc":[{"atb":[[4,33.33]],"id":36042617},{"atl":[[8.6,13.16]],"id":36042617}],"con":true,"img":false}]}
{"op":"mcm","clk":"5322494443","pt":1646320895785,"mc":[{"id":"1.195532862","rc":[{"atb":[[5.7,12.09]],"id":28603683}],"con":true,"img":false}]}
{"op":"mcm","clk":"5322494451","pt":1646320895890,"mc":[{"id":"1.195532862","rc":[{"atb":[[3,4.81]],"id":28691352}],"con":true,"img":false}]}
{"op":"mcm","clk":"5322494471","pt":1646320896100,"mc":[{"id":"1.195532862","rc":[{"atl":[[3.35,3]],"id":28691352}],"con":true,"img":false}]}
{"op":"mcm","clk":"5322494618","pt":1646320897269,"mc":[{"id":"1.195532862","rc":[{"atb":[[8,7.28]],"id":35839928}],"con":true,"img":false}]}
{"op":"mcm","clk":"5322494657","pt":1646320897584,"mc":[{"id":"1.195532862","rc":[{"atb":[[4.5,71.43]],"id":39693066},{"atb":[[7.2,32.19]],"id":35839928},{"atl":[[25,8.22]],"id":35839928},{"atb":[[3.55,58.82]],"id":8668222},{"atb":[[2.44,103.32]],"id":28691352},{"atl":[[4.1,48.39]],"id":28691352}],"con":true,"img":false}]}
{"op":"mcm","clk":"5322494786","pt":1646320898583,"mc":[{"id":"1.195532862","rc":[{"atb":[[5.4,9.34]],"id":28603683}],"con":true,"img":false}]}
{"op":"mcm","clk":"5322494804","pt":1646320898793,"mc":[{"id":"1.195532862","rc":[{"atl":[[10.5,2.71]],"id":39693066},{"atl":[[8,24.08],[7.8,2.3],[9.8,1.15]],"id":36042617},{"atl":[[9,12.5],[9.2,20.2]],"id":28603683},{"atl":[[3.85,47.34],[4.2,0]],"id":28691352}],"con":true,"img":false}]}
{"op":"mcm","clk":"5322494917","pt":1646320900097,"mc":[{"id":"1.195532862","rc":[{"atb":[[3.8,89.24]],"id":28603683}],"con":true,"img":false}]}
{"op":"mcm","clk":"5322495126","pt":1646320902860,"mc":[{"id":"1.195532862","rc":[{"atb":[[3.9,137.93]],"id":36042617},{"atl":[[9,31.25]],"id":36042617},{"atl":[[3.25,8.11]],"id":28691352}],"con":true,"img":false}]}
{"op":"mcm","clk":"5322495131","pt":1646320902963,"mc":[{"id":"1.195532862","rc":[{"atb":[[3.9,51.72]],"id":36042617},{"atl":[[9,18.75]],"id":36042617}],"con":true,"img":false}]}
{"op":"mcm","clk":"5322495142","pt":1646320903067,"mc":[{"id":"1.195532862","rc":[{"atl":[[7.8,2.1]],"id":36042617},{"atb":[[3,0]],"id":28691352},{"atl":[[3,0.99],[3.5,3.58]],"id":28691352},{"trd":[[3,9.61]],"ltp":3.0,"tv":9.61,"id":28691352}],"con":true,"img":false}]}
{"op":"mcm","clk":"5322495155","pt":1646320903170,"mc":[{"id":"1.195532862","rc":[{"atl":[[7.4,4.6]],"id":36042617},{"atl":[[3.5,0]],"id":28691352}],"con":true,"img":false}]}
{"op":"mcm","clk":"5322495183","pt":1646320903587,"mc":[{"id":"1.195532862","rc":[{"atl":[[8,20.93]],"id":36042617},{"atb":[[5.7,5.9]],"id":28603683},{"atl":[[3.4,12.82]],"id":28691352}],"con":true,"img":false}]}
{"op":"mcm","clk":"5322495211","pt":1646320903901,"mc":[{"id":"1.195532862","rc":[{"atl":[[7.4,6.76]],"id":36042617},{"atb":[[5.8,9.34]],"id":28603683},{"atb":[[2.5,66.67],[2.64,0]],"id":28691352},{"atl":[[3.15,18.08]],"id":28691352}],"con":true,"img":false}]}
{"op":"mcm","clk":"5322495222","pt":1646320904003,"mc":[{"id":"1.195532862","rc":[{"atl":[[8,13.16]],"id":36042617},{"atb":[[5.7,0]],"id":28603683},{"atl":[[3.4,5.39]],"id":28691352}],"con":true,"img":false}]}
{"op":"mcm","clk":"5322495230","pt":1646320904062,"mc":[{"id":"1.195532862","rc":[{"atl":[[7.4,13.59]],"id":36042617},{"atb":[[5.8,14.85]],"id":28603683},{"atb":[[2.64,4.28]],"id":28691352},{"atl":[[3.15,22.19]],"id":28691352}],"con":true,"img":false}]}
{"op":"mcm","clk":"5322495237","pt":1646320904162,"mc":[{"id":"1.195532862","rc":[{"atl":[[10,5.78]],"id":39693066},{"atb":[[5.6,3.78]],"id":28603683},{"atl":[[6.4,0]],"id":8668222},{"atb":[[2.96,0]],"id":28691352}],"con":true,"img":false}]}
{"op":"mcm","clk":"5322495245","pt":1646320904267,"mc":[{"id":"1.195532862","rc":[{"atb":[[5.6,0]],"id":28603683},{"atb":[[2.7,3.5]],"id":28691352}],"con":true,"img":false}]}
{"op":"mcm","clk":"5322495254","pt":1646320904375,"mc":[{"id":"1.195532862","rc":[{"atl":[[1000,14]],"id":28691352}],"con":true,"img":false}]}
{"op":"mcm","clk":"5322495268","pt":1646320904586,"mc":[{"id":"1.195532862","rc":[{"atb":[[1.01,11003]],"id":36042617},{"atb":[[1.01,11002]],"id":28603683},{"atl":[[1000,13]],"id":28691352}],"con":true,"img":false}]}
{"op":"mcm","clk":"5322495280","pt":1646320904687,"mc":[{"id":"1.195532862","rc":[{"atb":[[5.2,1.69]],"id":36042617},{"atb":[[5.9,1.61]],"id":28603683}],"con":true,"img":false}]}
{"op":"mcm","clk":"5322495286","pt":1646320904792,"mc":[{"id":"1.195532862","rc":[{"atl":[[1000,12]],"id":28691352}],"con":true,"img":false}]}
{"op":"mcm","clk":"5322495297","pt":1646320904897,"mc":[{"id":"1.195532862","rc":[{"atl":[[6.2,4.03]],"id":8668222},{"atl":[[3.1,1]],"id":28691352}],"con":true,"img":false}]}
{"op":"mcm","clk":"5322495307","pt":1646320905000,"mc":[{"id":"1.195532862","rc":[{"atb":[[6.8,43.1]],"id":35839928},{"atl":[[27,9.56]],"id":35839928},{"atb":[[3.45,102.04]],"id":8668222},{"atb":[[2.72,1],[2.4,177.11]],"id":28691352},{"atl":[[4.3,76.72]],"id":28691352}],"con":true,"img":false}]}
{"op":"mcm","clk":"5322495316","pt":1646320905106,"mc":[{"id":"1.195532862","rc":[{"atl":[[6.2,0]],"id":8668222},{"atl":[[3.1,4.42]],"id":28691352}],"con":true,"img":false}]}
{"op":"mcm","clk":"5322495322","pt":1646320905163,"mc":[{"id":"1.195532862","rc":[{"atb":[[5.8,13.85]],"id":28603683},{"atl":[[6.4,4.03]],"id":8668222}],"con":true,"img":false}]}
{"op":"mcm","clk":"5322495330","pt":1646320905269,"mc":[{"id":"1.195532862","rc":[{"atl":[[1000,12]],"id":35839928},{"atb":[[6,1.17]],"id":28603683},{"atl":[[6,0]],"id":8668222}],"con":true,"img":false}]}
{"op":"mcm","clk":"5322495339","pt":1646320905374,"mc":[{"id":"1.195532862","rc":[{"atl":[[22,0.48]],"id":35839928},{"atl":[[6.4,5.03]],"id":8668222}],"con":true,"img":false}]}
{"op":"mcm","clk":"5322495360","pt":1646320905582,"mc":[{"id":"1.195532862","rc":[{"atl":[[3.15,21.77]],"id":28691352}],"con":true,"img":false}]}
{"op":"mcm","clk":"5322495370","pt":1646320905688,"mc":[{"id":"1.195532862","rc":[{"atl":[[3.1,4.84]],"id":28691352}],"con":true,"img":false}]}
{"op":"mcm","clk":"5322495379","pt":1646320905792,"mc":[{"id":"1.195532862","rc":[{"atb":[[5.4,8.75]],"id":28603683}],"con":true,"img":false}]}
{"op":"mcm","clk":"5322495398","pt":1646320906000,"mc":[{"id":"1.195532862","rc":[{"atb":[[5.4,4.39]],"id":28603683}],"con":true,"img":false}]}
{"op":"mcm","clk":"5322495405","pt":1646320906104,"mc":[{"id":"1.195532862","rc":[{"atb":[[6,5.53]],"id":28603683}],"con":true,"img":false}]}
{"op":"mcm","clk":"5322495488","pt":1646320906892,"mc":[{"id":"1.195532862","rc":[{"atl":[[1000,14.52]],"id":8668222}],"con":true,"img":false}]}
{"op":"mcm","clk":"5322495508","pt":1646320907111,"mc":[{"id":"1.195532862","rc":[{"atl":[[1000,14.1]],"id":8668222}],"con":true,"img":false}]}
{"op":"mcm","clk":"5322495532","pt":1646320907311,"mc":[{"id":"1.195532862","rc":[{"atl":[[1000,12]],"id":8668222}],"con":true,"img":false}]}
{"op":"mcm","clk":"5322495542","pt":1646320907368,"mc":[{"id":"1.195532862","rc":[{"atl":[[6.2,2.1]],"id":8668222}],"con":true,"img":false}]}
{"op":"mcm","clk":"5322495567","pt":1646320907707,"mc":[{"id":"1.195532862","rc":[{"atl":[[6.4,4.03]],"id":8668222}],"con":true,"img":false}]}
{"op":"mcm","clk":"5322495579","pt":1646320907809,"mc":[{"id":"1.195532862","rc":[{"atl":[[6,1]],"id":8668222}],"con":true,"img":false}]}
{"op":"mcm","clk":"5322495634","pt":1646320908594,"mc":[{"id":"1.195532862","rc":[{"atl":[[6.2,0]],"id":8668222}],"con":true,"img":false}]}
{"op":"mcm","clk":"5322495645","pt":1646320908703,"mc":[{"id":"1.195532862","rc":[{"atb":[[5.4,0]],"id":28603683}],"con":true,"img":false}]}
{"op":"mcm","clk":"5322495658","pt":1646320908808,"mc":[{"id":"1.195532862","rc":[{"atl":[[6,0]],"id":8668222}],"con":true,"img":false}]}
{"op":"mcm","clk":"5322495667","pt":1646320908907,"mc":[{"id":"1.195532862","rc":[{"atl":[[6.2,1]],"id":8668222}],"con":true,"img":false}]}
{"op":"mcm","clk":"5322495683","pt":1646320909073,"mc":[{"id":"1.195532862","rc":[{"atl":[[8,0],[8.2,33.97]],"id":36042617}],"con":true,"img":false}]}
{"op":"mcm","clk":"5322495697","pt":1646320909283,"mc":[{"id":"1.195532862","rc":[{"atl":[[8.2,30.45]],"id":36042617}],"con":true,"img":false}]}
{"op":"mcm","clk":"5322495710","pt":1646320909488,"mc":[{"id":"1.195532862","rc":[{"atb":[[5.9,0]],"id":28603683}],"con":true,"img":false}]}
{"op":"mcm","clk":"5322495717","pt":1646320909591,"mc":[{"id":"1.195532862","rc":[{"atb":[[6.2,1.61]],"id":28603683}],"con":true,"img":false}]}
{"op":"mcm","clk":"5322495757","pt":1646320910011,"mc":[{"id":"1.195532862","rc":[{"atb":[[6,4.53]],"id":28603683}],"con":true,"img":false}]}
{"op":"mcm","clk":"5322495766","pt":1646320910124,"mc":[{"id":"1.195532862","rc":[{"atb":[[6.4,1]],"id":28603683}],"con":true,"img":false}]}
{"op":"mcm","clk":"5322495771","pt":1646320910220,"mc":[{"id":"1.195532862","rc":[{"atb":[[3.8,89.29]],"id":36042617},{"atl":[[9.4,29.76]],"id":36042617}],"con":true,"img":false}]}
{"op":"mcm","clk":"5322495884","pt":1646320911592,"mc":[{"id":"1.195532862","rc":[{"atl":[[1000,14.52]],"id":28603683}],"con":true,"img":false}]}
{"op":"mcm","clk":"5322495899","pt":1646320911796,"mc":[{"id":"1.195532862","rc":[{"atb":[[6,4.2]],"id":28603683},{"atl":[[1000,14.1]],"id":28603683}],"con":true,"img":false}]}
{"op":"mcm","clk":"5322495911","pt":1646320911901,"mc":[{"id":"1.195532862","rc":[{"atb":[[6,0.17]],"id":28603683},{"atl":[[1000,12]],"id":28603683}],"con":true,"img":false}]}
{"op":"mcm","clk":"5322495921","pt":1646320912003,"mc":[{"id":"1.195532862","rc":[{"atb":[[6.4,5.03]],"id":28603683},{"atl":[[8,2.61]],"id":28603683}],"con":true,"img":false}]}
{"op":"mcm","clk":"5322495932","pt":1646320912213,"mc":[{"id":"1.195532862","rc":[{"atl":[[8.2,0.66]],"id":28603683}],"con":true,"img":false}]}
{"op":"mcm","clk":"5322495942","pt":1646320912318,"mc":[{"id":"1.195532862","rc":[{"atl":[[7.8,1]],"id":28603683}],"con":true,"img":false}]}
{"op":"mcm","clk":"5322495952","pt":1646320912375,"mc":[{"id":"1.195532862","rc":[{"atl":[[8.2,0.2]],"id":28603683}],"con":true,"img":false}]}
{"op":"mcm","clk":"5322495967","pt":1646320912475,"mc":[{"id":"1.195532862","rc":[{"atl":[[1000,12.46]],"id":28603683}],"con":true,"img":false}]}
{"op":"mcm","clk":"5322496094","pt":1646320913585,"mc":[{"id":"1.195532862","rc":[{"atb":[[2.48,77.3]],"id":28691352}],"con":true,"img":false}]}
{"op":"mcm","clk":"5322496108","pt":1646320913685,"mc":[{"id":"1.195532862","rc":[{"atb":[[2.48,67.57]],"id":28691352}],"con":true,"img":false}]}
{"op":"mcm","clk":"5322496150","pt":1646320914206,"mc":[{"id":"1.195532862","rc":[{"atl":[[3,4.99]],"id":28691352}],"con":true,"img":false}]}
{"op":"mcm","clk":"5322496166","pt":1646320914416,"mc":[{"id":"1.195532862","rc":[{"atl":[[8.2,5.76],[8.6,0],[9.8,51.77]],"id":28603683},{"atl":[[3.1,3.84]],"id":28691352}],"con":true,"img":false}]}
{"op":"mcm","clk":"5322496174","pt":1646320914519,"mc":[{"id":"1.195532862","rc":[{"atl":[[9.2,8],[8.2,5.56],[8.4,2.94]],"id":28603683},{"atl":[[2.98,1]],"id":28691352}],"con":true,"img":false}]}
{"op":"mcm","clk":"5322496181","pt":1646320914580,"mc":[{"id":"1.195532862","rc":[{"atl":[[7.8,1.2]],"id":28603683},{"atl":[[3.1,3.42]],"id":28691352}],"con":true,"img":false}]}
{"op":"mcm","clk":"5322496191","pt":1646320914678,"mc":[{"id":"1.195532862","rc":[{"atb":[[5.8,8.34]],"id":28603683},{"atl":[[3,5.41]],"id":28691352}],"con":true,"img":false}]}
{"op":"mcm","clk":"5322496219","pt":1646320915092,"mc":[{"id":"1.195532862","rc":[{"atb":[[6,4.94]],"id":28603683}],"con":true,"img":false}]}
{"op":"mcm","clk":"5322496248","pt":1646320915503,"mc":[{"id":"1.195532862","rc":[{"atb":[[5.8,2.54]],"id":28603683}],"con":true,"img":false}]}
{"op":"mcm","clk":"5322496276","pt":1646320915921,"mc":[{"id":"1.195532862","rc":[{"atb":[[6,10.01]],"id":28603683}],"con":true,"img":false}]}
{"op":"mcm","clk":"5322496296","pt":1646320916083,"mc":[{"id":"1.195532862","rc":[{"atb":[[6.2,0]],"id":28603683}],"con":true,"img":false}]}
{"op":"mcm","clk":"5322496312","pt":1646320916192,"mc":[{"id":"1.195532862","rc":[{"atb":[[1.01,11003.61]],"id":28603683}],"con":true,"img":false}]}
{"op":"mcm","clk":"5322496384","pt":1646320916975,"mc":[{"id":"1.195532862","rc":[{"atb":[[6.4,4.03]],"id":28603683}],"con":true,"img":false}]}
{"op":"mcm","clk":"5322496394","pt":1646320917078,"mc":[{"id":"1.195532862","rc":[{"atb":[[6.6,1]],"id":28603683},{"atl":[[3.1,0]],"id":28691352}],"con":true,"img":false}]}
{"op":"mcm","clk":"5322496422","pt":1646320917387,"mc":[{"id":"1.195532862","rc":[{"atb":[[9.6,8.43]],"id":35839928}],"con":true,"img":false}]}
{"op":"mcm","clk":"5322496437","pt":1646320917597,"mc":[{"id":"1.195532862","rc":[{"atb":[[5.5,4.29]],"id":28603683}],"con":true,"img":false}]}
{"op":"mcm","clk":"5322496448","pt":1646320917700,"mc":[{"id":"1.195532862","rc":[{"atb":[[2.66,93.37]],"id":8668222}],"con":true,"img":false}]}
{"op":"mcm","clk":"5322496559","pt":1646320918906,"mc":[{"id":"1.195532862","rc":[{"atl":[[8,0.51]],"id":28603683}],"con":true,"img":false}]}
{"op":"mcm","clk":"5322496576","pt":1646320919105,"mc":[{"id":"1.195532862","rc":[{"atl":[[7.4,24.59]],"id":36042617},{"atb":[[6.4,3.89]],"id":28603683},{"atl":[[7.8,0.2]],"id":28603683}],"con":true,"img":false}]}
{"op":"mcm","clk":"5322496586","pt":1646320919211,"mc":[{"id":"1.195532862","rc":[{"atl":[[8,1.51]],"id":28603683}],"con":true,"img":false}]}
{"op":"mcm","clk":"5322496598","pt":1646320919314,"mc":[{"id":"1.195532862","rc":[{"atb":[[6.4,0]],"id":28603683}],"con":true,"img":false}]}
{"op":"mcm","clk":"5322496606","pt":1646320919419,"mc":[{"id":"1.195532862","rc":[{"atb":[[6.6,4.89]],"id":28603683},{"atb":[[2.5,0]],"id":28691352}],"con":true,"img":false}]}
{"op":"mcm","clk":"5322496616","pt":1646320919525,"mc":[{"id":"1.195532862","rc":[{"atb":[[2.42,52.64]],"id":28691352}],"con":true,"img":false}]}
{"op":"mcm","clk":"5322496659","pt":1646320919996,"mc":[{"id":"1.195532862","rc":[{"atl":[[7.2,2.92]],"id":36042617},{"atb":[[6.6,3.89]],"id":28603683}],"con":true,"img":false}]}
{"op":"mcm","clk":"5322496670","pt":1646320920100,"mc":[{"id":"1.195532862","rc":[{"atl":[[7.4,21.18]],"id":36042617},{"atl":[[22,1.44]],"id":35839928},{"atb":[[6.8,1]],"id":28603683}],"con":true,"img":false}]}
{"op":"mcm","clk":"5322496680","pt":1646320920205,"mc":[{"id":"1.195532862","rc":[{"atl":[[7.4,20.18]],"id":36042617},{"atb":[[8.8,0.42]],"id":35839928},{"atb":[[2.58,0.71]],"id":28691352}],"con":true,"img":false}]}
{"op":"mcm","clk":"5322496689","pt":1646320920313,"mc":[{"id":"1.195532862","rc":[{"atl":[[7,1]],"id":36042617}],"con":true,"img":false}]}
{"op":"mcm","clk":"5322496699","pt":1646320920418,"mc":[{"id":"1.195532862","rc":[{"atl":[[7,4.31]],"id":36042617}],"con":true,"img":false}]}
{"op":"mcm","clk":"5322496744","pt":1646320920891,"mc":[{"id":"1.195532862","rc":[{"atl":[[17,11.5]],"id":36042617}],"con":true,"img":false}]}
{"op":"mcm","clk":"5322496759","pt":1646320921105,"mc":[{"id":"1.195532862","rc":[{"atb":[[6.6,3.75]],"id":28603683}],"con":true,"img":false}]}
{"op":"mcm","clk":"5322496775","pt":1646320921312,"mc":[{"id":"1.195532862","rc":[{"atb":[[6.6,0]],"id":28603683}],"con":true,"img":false}]}
{"op":"mcm","clk":"5322496782","pt":1646320921420,"mc":[{"id":"1.195532862","rc":[{"atl":[[7,7.94]],"id":36042617},{"atb":[[6.8,4.75]],"id":28603683}],"con":true,"img":false}]}
{"op":"mcm","clk":"5322496788","pt":1646320921526,"mc":[{"id":"1.195532862","rc":[{"atl":[[8.6,13.16]],"id":28603683}],"con":true,"img":false}]}
{"op":"mcm","clk":"5322496825","pt":1646320922001,"mc":[{"id":"1.195532862","rc":[{"atb":[[6.8,3.75]],"id":28603683}],"con":true,"img":false}]}
{"op":"mcm","clk":"5322496831","pt":1646320922108,"mc":[{"id":"1.195532862","rc":[{"atb":[[7,1]],"id":28603683}],"con":true,"img":false}]}
{"op":"mcm","clk":"5322496838","pt":1646320922209,"mc":[{"id":"1.195532862","rc":[{"atb":[[6.8,0]],"id":28603683}],"con":true,"img":false}]}
{"op":"mcm","clk":"5322496846","pt":1646320922317,"mc":[{"id":"1.195532862","rc":[{"atl":[[7.8,0]],"id":36042617},{"atb":[[5.8,0]],"id":28603683},{"atb":[[2.7,0]],"id":28691352},{"atl":[[3.35,0]],"id":28691352}],"con":true,"img":false}]}
{"op":"mcm","clk":"5322496870","pt":1646320922628,"mc":[{"id":"1.195532862","rc":[{"atb":[[5.8,1.25]],"id":36042617},{"atl":[[7,10.64]],"id":36042617},{"atb":[[7.8,5.89]],"id":39693066},{"atb":[[12,6.78]],"id":35839928},{"atl":[[8,5.49]],"id":28603683},{"atb":[[5.4,1.53]],"id":8668222},{"atl":[[6.2,2.67]],"id":8668222},{"atl":[[2.98,6.49]],"id":28691352}],"con":true,"img":false}]}
{"op":"mcm","clk":"5322496905","pt":1646320923047,"mc":[{"id":"1.195532862","rc":[{"atb":[[7,0]],"id":28603683},{"atb":[[2.72,0]],"id":28691352}],"con":true,"img":false}]}
{"op":"mcm","clk":"5322496914","pt":1646320923101,"mc":[{"id":"1.195532862","rc":[{"atl":[[7.2,0]],"id":36042617},{"atb":[[6.2,1]],"id":28603683},{"atb":[[2.66,1]],"id":28691352}],"con":true,"img":false}]}
{"op":"mcm","clk":"5322496926","pt":1646320923255,"mc":[{"id":"1.195532862","rc":[{"atl":[[1000,12]],"id":28603683}],"con":true,"img":false}]}
{"op":"mcm","clk":"5322496936","pt":1646320923313,"mc":[{"id":"1.195532862","rc":[{"atl":[[7.4,24.14]],"id":36042617},{"atb":[[1.01,11004.52]],"id":35839928}],"con":true,"img":false}]}
{"op":"mcm","clk":"5322496946","pt":1646320923410,"mc":[{"id":"1.195532862","rc":[{"atl":[[7.8,0.66]],"id":28603683}],"con":true,"img":false}]}
{"op":"mcm","clk":"5322496952","pt":1646320923517,"mc":[{"id":"1.195532862","rc":[{"atb":[[1.01,11003.68]],"id":35839928}],"con":true,"img":false}]}
{"op":"mcm","clk":"5322496959","pt":1646320923619,"mc":[{"id":"1.195532862","rc":[{"atl":[[7.4,20.18]],"id":36042617}],"con":true,"img":false}]}
{"op":"mcm","clk":"5322496970","pt":1646320923724,"mc":[{"id":"1.195532862","rc":[{"atb":[[1.01,11002]],"id":35839928}],"con":true,"img":false}]}
{"op":"mcm","clk":"5322496977","pt":1646320923827,"mc":[{"id":"1.195532862","rc":[{"atb":[[12.5,1.68]],"id":35839928}],"con":true,"img":false}]}
{"op":"mcm","clk":"5322497011","pt":1646320923987,"mc":[{"id":"1.195532862","rc":[{"atb":[[12,5.49]],"id":35839928},{"atb":[[6.2,5.19]],"id":28603683}],"con":true,"img":false}]}
{"op":"mcm","clk":"5322497081","pt":1646320924199,"mc":[{"id":"1.195532862","rc":[{"atb":[[1.01,11004]],"id":35839928}],"con":true,"img":false}]}
{"op":"mcm","clk":"5322497090","pt":1646320924306,"mc":[{"id":"1.195532862","rc":[{"atb":[[12,0]],"id":35839928},{"atl":[[3,4.99]],"id":28691352}],"con":true,"img":false}]}
{"op":"mcm","clk":"5322497098","pt":1646320924415,"mc":[{"id":"1.195532862","rc":[{"atb":[[1.01,11003.19]],"id":35839928},{"atl":[[2.98,6.91]],"id":28691352}],"con":true,"img":false}]}
{"op":"mcm","clk":"5322497106","pt":1646320924516,"mc":[{"id":"1.195532862","rc":[{"atl":[[8,14.29],[8.2,16.56]],"id":36042617},{"atl":[[9.8,23.36]],"id":28603683},{"atl":[[8.2,50.01],[7.6,0],[6.6,0]],"id":8668222}],"con":true,"img":false}]}
{"op":"mcm","clk":"5322497112","pt":1646320924619,"mc":[{"id":"1.195532862","rc":[{"atb":[[1.01,11002]],"id":35839928}],"con":true,"img":false}]}
{"op":"mcm","clk":"5322497118","pt":1646320924721,"mc":[{"id":"1.195532862","rc":[{"atb":[[13,1.19]],"id":35839928}],"con":true,"img":false}]}
{"op":"mcm","clk":"5322497128","pt":1646320924931,"mc":[{"id":"1.195532862","rc":[{"atl":[[7.8,0.2]],"id":28603683}],"con":true,"img":false}]}
{"op":"mcm","clk":"5322497137","pt":1646320924994,"mc":[{"id":"1.195532862","rc":[{"atl":[[1000,12.46]],"id":28603683}],"con":true,"img":false}]}
{"op":"mcm","clk":"5322497169","pt":1646320925505,"mc":[{"id":"1.195532862","rc":[{"atl":[[7.4,19.98]],"id":36042617},{"atl":[[7.8,0]],"id":28603683}],"con":true,"img":false}]}
{"op":"mcm","clk":"5322497175","pt":1646320925607,"mc":[{"id":"1.195532862","rc":[{"atl":[[7,10.84]],"id":36042617},{"atl":[[8,5.69]],"id":28603683}],"con":true,"img":false}]}
{"op":"mcm","clk":"5322497179","pt":1646320925714,"mc":[{"id":"1.195532862","rc":[{"atl":[[17,1.28]],"id":35839928}],"con":true,"img":false}]}
{"op":"mcm","clk":"5322497187","pt":1646320925819,"mc":[{"id":"1.195532862","rc":[{"atb":[[5.8,0.25]],"id":36042617},{"trd":[[5.8,2]],"ltp":5.8,"tv":2.0,"id":36042617}],"con":true,"img":false}]}
{"op":"mcm","clk":"5322497194","pt":1646320925922,"mc":[{"id":"1.195532862","rc":[{"atl":[[17,0]],"id":35839928}],"con":true,"img":false}]}
{"op":"mcm","clk":"5322497200","pt":1646320926025,"mc":[{"id":"1.195532862","rc":[{"atl":[[18,1.28]],"id":35839928}],"con":true,"img":false}]}
{"op":"mcm","clk":"5322497224","pt":1646320926288,"mc":[{"id":"1.195532862","rc":[{"atb":[[5.8,0]],"id":36042617}],"con":true,"img":false}]}
{"op":"mcm","clk":"5322497232","pt":1646320926396,"mc":[{"id":"1.195532862","rc":[{"atl":[[6.8,2.78]],"id":36042617},{"atl":[[10.5,3.51]],"id":39693066},{"atl":[[8,6.82]],"id":28603683},{"atl":[[6.8,1.95]],"id":8668222}],"con":true,"img":false}]}
{"op":"mcm","clk":"5322497242","pt":1646320926553,"mc":[{"id":"1.195532862","rc":[{"atb":[[6.4,0.4]],"id":39693066},{"atb":[[4.5,1.39]],"id":36042617},{"atb":[[4.9,0.4]],"id":28603683}],"con":true,"img":false}]}
{"op":"mcm","clk":"5322497252","pt":1646320926613,"mc":[{"id":"1.195532862","rc":[{"atl":[[7,9.84]],"id":36042617},{"atl":[[17.5,1.65]],"id":35839928}],"con":true,"img":false}]}
{"op":"mcm","clk":"5322497261","pt":1646320926712,"mc":[{"id":"1.195532862","rc":[{"atl":[[6.6,1]],"id":36042617}],"con":true,"img":false}]}
{"op":"mcm","clk":"5322497271","pt":1646320926815,"mc":[{"id":"1.195532862","rc":[{"atl":[[20,3.7]],"id":35839928},{"atb":[[5.5,0]],"id":28603683}],"con":true,"img":false}]}
{"op":"mcm","clk":"5322497282","pt":1646320927025,"mc":[{"id":"1.195532862","rc":[{"atl":[[6.6,2],[7,7.14]],"id":36042617},{"atb":[[5.4,5.09]],"id":28603683}],"con":true,"img":false}]}
{"op":"mcm","clk":"5322497298","pt":1646320927337,"mc":[{"id":"1.195532862","rc":[{"atl":[[20,0]],"id":35839928},{"atb":[[5.4,0]],"id":28603683}],"con":true,"img":false}]}
{"op":"mcm","clk":"5322497309","pt":1646320927401,"mc":[{"id":"1.195532862","rc":[{"atb":[[5.2,0]],"id":36042617}],"con":true,"img":false}]}
{"op":"mcm","clk":"5322497315","pt":1646320927495,"mc":[{"id":"1.195532862","rc":[{"atb":[[1.01,11004.69]],"id":36042617},{"atl":[[7,3.51]],"id":36042617}],"con":true,"img":false}]}
{"op":"mcm","clk":"5322497395","pt":1646320928537,"mc":[{"id":"1.195532862","rc":[{"atl":[[8.2,0],[8.4,8.35]],"id":28603683}],"con":true,"img":false}]}
{"op":"mcm","clk":"5322497411","pt":1646320928704,"mc":[{"id":"1.195532862","rc":[{"atl":[[8.4,3.47],[6.6,5.89]],"id":36042617},{"atl":[[8.4,11.39]],"id":28603683}],"con":true,"img":false}]}
{"op":"mcm","clk":"5322497417","pt":1646320928802,"mc":[{"id":"1.195532862","rc":[{"atl":[[8.4,0]],"id":36042617}],"con":true,"img":false}]}
{"op":"mcm","clk":"5322497430","pt":1646320928906,"mc":[{"id":"1.195532862","rc":[{"atl":[[6.6,4.89]],"id":36042617},{"atb":[[15.5,0.25]],"id":35839928},{"atl":[[15.5,0]],"id":35839928},{"trd":[[15.5,12.76]],"ltp":15.5,"tv":12.76,"id":35839928},{"atl":[[8.4,8.35]],"id":28603683}],"con":true,"img":false}]}
{"op":"mcm","clk":"5322497441","pt":1646320929011,"mc":[{"id":"1.195532862","rc":[{"atb":[[15.5,0]],"id":35839928},{"trd":[[15.5,13.27]],"ltp":15.5,"tv":13.27,"id":35839928}],"con":true,"img":false}]}
{"op":"mcm","clk":"5322497518","pt":1646320929992,"mc":[{"id":"1.195532862","rc":[{"atl":[[7,0.2]],"id":36042617}],"con":true,"img":false}]}
{"op":"mcm","clk":"5322497528","pt":1646320930095,"mc":[{"id":"1.195532862","rc":[{"atl":[[6.4,3.31]],"id":36042617}],"con":true,"img":false}]}
{"op":"mcm","clk":"5322497535","pt":1646320930207,"mc":[{"id":"1.195532862","rc":[{"atl":[[8,0],[7.6,14.74]],"id":36042617},{"atb":[[8,10.75],[11,1.89]],"id":35839928},{"atl":[[18,1.24]],"id":35839928}],"con":true,"img":false}]}
{"op":"mcm","clk":"5322497554","pt":1646320930511,"mc":[{"id":"1.195532862","rc":[{"atb":[[8,7.28],[11,0]],"id":35839928},{"atl":[[18,0]],"id":35839928}],"con":true,"img":false}]}
{"op":"mcm","clk":"5322497560","pt":1646320930617,"mc":[{"id":"1.195532862","rc":[{"atb":[[12.5,3.58]],"id":35839928},{"atl":[[18.5,1.24]],"id":35839928}],"con":true,"img":false}]}
{"op":"mcm","clk":"5322497581","pt":1646320930836,"mc":[{"id":"1.195532862","rc":[{"atb":[[12.5,1.89]],"id":35839928}],"con":true,"img":false}]}
{"op":"mcm","clk":"5322497598","pt":1646320931032,"mc":[{"id":"1.195532862","rc":[{"atl":[[6.6,0]],"id":36042617}],"con":true,"img":false}]}
{"op":"mcm","clk":"5322497602","pt":1646320931135,"mc":[{"id":"1.195532862","rc":[{"atl":[[6.2,1]],"id":36042617}],"con":true,"img":false}]}
{"op":"mcm","clk":"5322497783","pt":1646320933741,"mc":[{"id":"1.195532862","rc":[{"atl":[[6.4,0]],"id":36042617}],"con":true,"img":false}]}
{"op":"mcm","clk":"5322497789","pt":1646320933798,"mc":[{"id":"1.195532862","rc":[{"atb":[[6,4.94]],"id":28603683}],"con":true,"img":false}]}
{"op":"mcm","clk":"5322497801","pt":1646320933900,"mc":[{"id":"1.195532862","rc":[{"atl":[[1000,14],[6.2,5.19]],"id":36042617}],"con":true,"img":false}]}
{"op":"mcm","clk":"5322497808","pt":1646320934007,"mc":[{"id":"1.195532862","rc":[{"atl":[[6.2,4.19]],"id":36042617}],"con":true,"img":false}]}
{"op":"mcm","clk":"5322497815","pt":1646320934113,"mc":[{"id":"1.195532862","rc":[{"atl":[[1000,13],[6.6,1]],"id":36042617}],"con":true,"img":false}]}
{"op":"mcm","clk":"5322497824","pt":1646320934211,"mc":[{"id":"1.195532862","rc":[{"atl":[[2.9,0.54]],"id":28691352}],"con":true,"img":false}]}
{"op":"mcm","clk":"5322497829","pt":1646320934317,"mc":[{"id":"1.195532862","rc":[{"atl":[[1000,12]],"id":36042617}],"con":true,"img":false}]}
{"op":"mcm","clk":"5322497840","pt":1646320934420,"mc":[{"id":"1.195532862","rc":[{"atl":[[6.6,2]],"id":36042617}],"con":true,"img":false}]}
{"op":"mcm","clk":"5322497855","pt":1646320934625,"mc":[{"id":"1.195532862","rc":[{"atl":[[22,0.96]],"id":35839928}],"con":true,"img":false}]}
{"op":"mcm","clk":"5322497864","pt":1646320934781,"mc":[{"id":"1.195532862","rc":[{"atl":[[6.6,1]],"id":36042617},{"atl":[[1000,12.48]],"id":35839928}],"con":true,"img":false}]}
{"op":"mcm","clk":"5322497874","pt":1646320934892,"mc":[{"id":"1.195532862","rc":[{"atb":[[1.01,11003.48]],"id":8668222}],"con":true,"img":false}]}
{"op":"mcm","clk":"5322497881","pt":1646320934991,"mc":[{"id":"1.195532862","rc":[{"atl":[[6.6,0]],"id":36042617},{"atb":[[6.4,3.75]],"id":28603683}],"con":true,"img":false}]}
{"op":"mcm","clk":"5322497889","pt":1646320935042,"mc":[{"id":"1.195532862","rc":[{"atl":[[6,1]],"id":36042617}],"con":true,"img":false}]}
{"op":"mcm","clk":"5322497905","pt":1646320935260,"mc":[{"id":"1.195532862","rc":[{"atb":[[4.6,0]],"id":36042617},{"atl":[[24,0]],"id":35839928}],"con":true,"img":false}]}
{"op":"mcm","clk":"5322497914","pt":1646320935358,"mc":[{"id":"1.195532862","rc":[{"atl":[[28,3.7]],"id":35839928},{"atl":[[8.8,17.82]],"id":28603683}],"con":true,"img":false}]}
{"op":"mcm","clk":"5322497938","pt":1646320935672,"mc":[{"id":"1.195532862","rc":[{"atb":[[1.01,11002.74]],"id":8668222}],"con":true,"img":false}]}
{"op":"mcm","clk":"5322497945","pt":1646320935777,"mc":[{"id":"1.195532862","rc":[{"atb":[[5.5,4.29]],"id":28603683}],"con":true,"img":false}]}
{"op":"mcm","clk":"5322497954","pt":1646320935882,"mc":[{"id":"1.195532862","rc":[{"atl":[[6.2,0]],"id":36042617},{"atb":[[6.2,5.03]],"id":28603683}],"con":true,"img":false}]}
{"op":"mcm","clk":"5322497971","pt":1646320936087,"mc":[{"id":"1.195532862","rc":[{"atl":[[1000,14]],"id":36042617},{"atb":[[6.2,0]],"id":28603683}],"con":true,"img":false}]}
{"op":"mcm","clk":"5322497977","pt":1646320936191,"mc":[{"id":"1.195532862","rc":[{"atb":[[6.4,7.79],[6.6,1]],"id":28603683}],"con":true,"img":false}]}
{"op":"mcm","clk":"5322497982","pt":1646320936294,"mc":[{"id":"1.195532862","rc":[{"atl":[[1000,13]],"id":36042617},{"atb":[[1.01,11002]],"id":8668222}],"con":true,"img":false}]}
{"op":"mcm","clk":"5322497989","pt":1646320936347,"mc":[{"id":"1.195532862","rc":[{"atb":[[5,5]],"id":36042617},{"atl":[[6.6,3.57]],"id":36042617},{"atb":[[4.8,5.26]],"id":8668222},{"atl":[[6.8,5.4],[6.2,1.93]],"id":8668222},{"trd":[[6.2,1.48]],"ltp":6.2,"tv":1.48,"id":8668222},{"atb":[[2.42,66.72]],"id":28691352},{"atl":[[3.1,9.52]],"id":28691352}],"con":true,"img":false}]}
{"op":"mcm","clk":"5322497995","pt":1646320936451,"mc":[{"id":"1.195532862","rc":[{"atl":[[1000,12]],"id":36042617}],"con":true,"img":false}]}
{"op":"mcm","clk":"5322498003","pt":1646320936559,"mc":[{"id":"1.195532862","rc":[{"atl":[[6.6,4.57]],"id":36042617}],"con":true,"img":false}]}
{"op":"mcm","clk":"5322498013","pt":1646320936659,"mc":[{"id":"1.195532862","rc":[{"atb":[[6.4,7.65]],"id":28603683}],"con":true,"img":false}]}
{"op":"mcm","clk":"5322498022","pt":1646320936763,"mc":[{"id":"1.195532862","rc":[{"atl":[[17.5,0]],"id":35839928}],"con":true,"img":false}]}
{"op":"mcm","clk":"5322498031","pt":1646320936867,"mc":[{"id":"1.195532862","rc":[{"atl":[[6.6,3.57]],"id":36042617},{"atb":[[6.4,3.75]],"id":28603683}],"con":true,"img":false}]}
{"op":"mcm","clk":"5322498037","pt":1646320936970,"mc":[{"id":"1.195532862","rc":[{"atl":[[6,4.36]],"id":36042617},{"atb":[[6.6,4.89]],"id":28603683}],"con":true,"img":false}]}
{"op":"mcm","clk":"5322498045","pt":1646320937074,"mc":[{"id":"1.195532862","rc":[{"atl":[[6.4,1]],"id":36042617},{"atb":[[1.01,11004]],"id":8668222}],"con":true,"img":false}]}
{"op":"mcm","clk":"5322498069","pt":1646320937387,"mc":[{"id":"1.195532862","rc":[{"atb":[[1.01,11002.83]],"id":8668222}],"con":true,"img":false}]}
{"op":"mcm","clk":"5322498079","pt":1646320937490,"mc":[{"id":"1.195532862","rc":[{"atl":[[7,0]],"id":36042617}],"con":true,"img":false}]}
{"op":"mcm","clk":"5322498090","pt":1646320937543,"mc":[{"id":"1.195532862","rc":[{"atl":[[6,4.56]],"id":36042617},{"atb":[[1.01,11002]],"id":8668222}],"con":true,"img":false}]}
{"op":"mcm","clk":"5322498098","pt":1646320937647,"mc":[{"id":"1.195532862","rc":[{"atb":[[5.5,0.83]],"id":8668222}],"con":true,"img":false}]}
{"op":"mcm","clk":"5322498113","pt":1646320937855,"mc":[{"id":"1.195532862","rc":[{"atb":[[6,0.17]],"id":28603683}],"con":true,"img":false}]}
{"op":"mcm","clk":"5322498124","pt":1646320938065,"mc":[{"id":"1.195532862","rc":[{"atl":[[6.4,0]],"id":36042617}],"con":true,"img":false}]}
{"op":"mcm","clk":"5322498134","pt":1646320938169,"mc":[{"id":"1.195532862","rc":[{"atl":[[5.9,1]],"id":36042617}],"con":true,"img":false}]}
{"op":"mcm","clk":"5322498148","pt":1646320938377,"mc":[{"id":"1.195532862","rc":[{"atl":[[6,0.2]],"id":36042617}],"con":true,"img":false}]}
{"op":"mcm","clk":"5322498173","pt":1646320938795,"mc":[{"id":"1.195532862","rc":[{"atl":[[6.6,0]],"id":36042617},{"atb":[[4.8,0]],"id":8668222}],"con":true,"img":false}]}
