{"op":"mcm","clk":"5345985290","pt":1646174444251,"mc":[{"id":"1.195453615","marketDefinition":{"bspMarket":true,"turnInPlayEnabled":false,"persistenceEnabled":false,"marketBaseRate":7.0,"eventId":"31272494","eventTypeId":"4339","numberOfWinners":1,"bettingType":"ODDS","marketType":"WIN","marketTime":"2022-03-02T09:33:00.000Z","suspendTime":"2022-03-02T09:33:00.000Z","bspReconciled":false,"complete":true,"inPlay":false,"crossMatching":false,"runnersVoidable":false,"numberOfActiveRunners":6,"betDelay":0,"status":"OPEN","runners":[{"status":"ACTIVE","sortPriority":1,"id":26503913,"name":"1. Callum Ari"},{"status":"ACTIVE","sortPriority":2,"id":36036864,"name":"2. Ripplebrook Rory"},{"status":"ACTIVE","sortPriority":3,"id":37456368,"name":"3. Shes So Lovable"},{"status":"ACTIVE","sortPriority":4,"id":39784359,"name":"4. Nicholas Rose"},{"status":"ACTIVE","sortPriority":5,"id":39980001,"name":"7. Elmo Rose"},{"status":"ACTIVE","sortPriority":6,"id":28755739,"name":"8. Perfect Colour"}],"regulators":["MR_INT"],"venue":"Traralgon","countryCode":"AU","discountAllowed":true,"timezone":"Australia/Sydney","openDate":"2022-03-02T08:31:00.000Z","version":4382425352,"name":"R4 395m Gr4/5","eventName":"Traralgon (AUS) 2nd Mar"},"rc":[],"con":true,"img":false}]}
{"op":"mcm","clk":"5346059516","pt":1646175786519,"mc":[{"id":"1.195453615","rc":[{"atb":[[4.5,11.66],[3,81.65],[3.25,36.29],[3.5,32.66],[3.75,14.84]],"id":26503913},{"atl":[[16,8.86],[18.5,7.6],[22,9.5],[27,7.67]],"id":26503913},{"spn":10.25,"spf":"NaN","id":26503913},{"atb":[[2,81.65],[2.3,31.4],[1.9,181.45],[1.95,85.94],[2.1,37.11]],"id":28755739},{"atl":[[5.6,28.92],[7.2,32.18],[6.2,25.58],[8.2,27.71]],"id":28755739},{"spn":3.95,"spf":"NaN","id":28755739},{"atb":[[2.74,46.92],[3.35,17.37],[2.64,99.58],[2.84,44.37],[2.94,21.04]],"id":37456368},{"atl":[[12,18.14],[9.8,15.11],[8.8,17.05],[14.5,14.78]],"id":37456368},{"spn":6.07,"spf":"NaN","id":37456368},{"atb":[[4,54.43],[4.5,23.33],[5,20.41],[5.5,9.07],[7,6.8]],"id":36036864},{"atl":[[70,2.89],[38,3.59],[48,4.24],[29,4.75]],"id":36036864},{"spn":18.0,"spf":"NaN","id":36036864},{"atb":[[6.4,15.12],[7.4,6.37],[5.2,38.88],[5.7,17.37],[9.4,4.86]],"id":39784359},{"atl":[[80,1.68],[160,1.25],[55,2.46],[110,1.82]],"id":39784359},{"spn":32.2,"spf":"NaN","id":39784359},{"atb":[[2.82,44.86],[2.92,42.53],[2.72,94.94],[3.55,16],[3.05,19.91]],"id":39980001},{"atl":[[17,12.47],[12,12.09],[9.8,15.11],[14.5,14.78]],"id":39980001},{"spn":6.67,"spf":"NaN","id":39980001}],"con":true,"img":false}]}
{"op":"mcm","clk":"5346061998","pt":1646175839944,"mc":[{"id":"1.195453615","rc":[{"atb":[[4.5,0],[3,0],[3.25,0],[3.5,0],[3.75,0]],"id":26503913},{"atl":[[16,0],[18.5,0],[22,0],[27,0]],"id":26503913},{"atb":[[2,0],[2.3,0],[1.9,0],[1.95,0],[2.1,0]],"id":28755739},{"atl":[[5.6,0],[7.2,0],[6.2,0],[8.2,0]],"id":28755739},{"atb":[[2.74,0],[3.35,0],[2.64,0],[2.84,0],[2.94,0]],"id":37456368},{"atl":[[12,0],[9.8,0],[8.8,0],[14.5,0]],"id":37456368},{"atb":[[4,0],[4.5,0],[5,0],[5.5,0],[7,0]],"id":36036864},{"atl":[[70,0],[38,0],[48,0],[29,0]],"id":36036864},{"atb":[[6.4,0],[7.4,0],[5.2,0],[5.7,0],[9.4,0]],"id":39784359},{"atl":[[80,0],[160,0],[55,0],[110,0]],"id":39784359},{"atb":[[2.82,0],[2.92,0],[2.72,0],[3.55,0],[3.05,0]],"id":39980001},{"atl":[[17,0],[12,0],[9.8,0],[14.5,0]],"id":39980001}],"con":true,"img":false}]}
{"op":"mcm","clk":"5346062134","pt":1646175843189,"mc":[{"id":"1.195453615","rc":[{"atb":[[4.5,11.66],[3,81.65],[3.25,36.29],[3.5,32.66],[3.75,14.84]],"id":26503913},{"atl":[[16,8.86],[18.5,7.6],[22,9.5],[27,7.67]],"id":26503913},{"atb":[[2,81.65],[2.3,31.4],[1.9,181.45],[1.95,85.94],[2.1,37.11]],"id":28755739},{"atl":[[5.6,28.92],[7.2,32.18],[6.2,25.58],[8.2,27.71]],"id":28755739},{"atb":[[2.74,46.92],[3.35,17.37],[2.64,99.58],[2.84,44.37],[2.94,21.04]],"id":37456368},{"atl":[[12,18.14],[9.8,15.11],[8.8,17.05],[14.5,14.78]],"id":37456368},{"atb":[[4,54.43],[4.5,23.33],[5,20.41],[5.5,9.07],[7,6.8]],"id":36036864},{"atl":[[70,2.89],[38,3.59],[48,4.24],[29,4.75]],"id":36036864},{"atb":[[6.4,15.12],[7.4,6.37],[5.2,38.88],[5.7,17.37],[9.4,4.86]],"id":39784359},{"atl":[[80,1.68],[160,1.25],[55,2.46],[110,1.82]],"id":39784359},{"atb":[[2.82,44.86],[2.92,42.53],[2.72,94.94],[3.55,16],[3.05,19.91]],"id":39980001},{"atl":[[17,12.47],[12,12.09],[9.8,15.11],[14.5,14.78]],"id":39980001}],"con":true,"img":false}]}
{"op":"mcm","clk":"5346105154","pt":1646176602701,"mc":[{"id":"1.195453615","marketDefinition":{"bspMarket":true,"turnInPlayEnabled":false,"persistenceEnabled":false,"marketBaseRate":7.0,"eventId":"31272494","eventTypeId":"4339","numberOfWinners":1,"bettingType":"ODDS","marketType":"WIN","marketTime":"2022-03-02T09:33:00.000Z","suspendTime":"2022-03-02T09:33:00.000Z","bspReconciled":false,"complete":true,"inPlay":false,"crossMatching":false,"runnersVoidable":false,"numberOfActiveRunners":6,"betDelay":0,"status":"OPEN","runners":[{"status":"ACTIVE","sortPriority":1,"id":26503913,"name":"1. Callum Ari"},{"status":"ACTIVE","sortPriority":2,"id":36036864,"name":"2. Ripplebrook Rory"},{"status":"ACTIVE","sortPriority":3,"id":37456368,"name":"3. Shes So Lovable"},{"status":"ACTIVE","sortPriority":4,"id":39784359,"name":"4. Nicholas Rose"},{"status":"ACTIVE","sortPriority":5,"id":39980001,"name":"7. Elmo Rose"},{"status":"ACTIVE","sortPriority":6,"id":28755739,"name":"8. Perfect Colour"}],"regulators":["MR_INT"],"venue":"Traralgon","countryCode":"AU","discountAllowed":true,"timezone":"Australia/Sydney","openDate":"2022-03-02T08:31:00.000Z","version":4382425352,"name":"R4 395m Gr4/5","eventName":"Traralgon (AUS) 2nd Mar"},"rc":[{"atb":[[4.5,11.66],[3,81.65],[3.25,36.29],[3.5,32.66],[3.75,14.84]],"id":26503913},{"atl":[[16,8.86],[18.5,7.6],[22,9.5],[27,7.67]],"id":26503913},{"spn":10.25,"spf":"NaN","id":26503913},{"atb":[[2,81.65],[2.3,31.4],[1.9,181.45],[1.95,85.94],[2.1,37.11]],"id":28755739},{"atl":[[5.6,28.92],[7.2,32.18],[6.2,25.58],[8.2,27.71]],"id":28755739},{"spn":3.95,"spf":"NaN","id":28755739},{"atb":[[2.74,46.92],[3.35,17.37],[2.64,99.58],[2.84,44.37],[2.94,21.04]],"id":37456368},{"atl":[[12,18.14],[9.8,15.11],[8.8,17.05],[14.5,14.78]],"id":37456368},{"spn":6.07,"spf":"NaN","id":37456368},{"atb":[[4,54.43],[4.5,23.33],[5,20.41],[5.5,9.07],[7,6.8]],"id":36036864},{"atl":[[70,2.89],[38,3.59],[48,4.24],[29,4.75]],"id":36036864},{"spn":18.0,"spf":"NaN","id":36036864},{"atb":[[6.4,15.12],[7.4,6.37],[5.2,38.88],[5.7,17.37],[9.4,4.86]],"id":39784359},{"atl":[[80,1.68],[160,1.25],[55,2.46],[110,1.82]],"id":39784359},{"spn":32.2,"spf":"NaN","id":39784359},{"atb":[[2.82,44.86],[2.92,42.53],[2.72,94.94],[3.55,16],[3.05,19.91]],"id":39980001},{"atl":[[17,12.47],[12,12.09],[9.8,15.11],[14.5,14.78]],"id":39980001},{"spn":6.67,"spf":"NaN","id":39980001}],"con":true,"img":true}]}
{"op":"mcm","clk":"5346269954","pt":1646179879415,"mc":[{"id":"1.195453615","rc":[{"atb":[[4.5,11.66],[3,81.66],[3.25,36.29],[3.5,32.66],[3.75,14.84]],"id":26503913},{"atl":[[16,8.86],[18.5,7.6],[22,9.5],[27,7.67]],"id":26503913},{"atb":[[2,81.66],[2.3,31.4],[1.9,181.47],[1.95,85.95],[2.1,37.11]],"id":28755739},{"atl":[[5.6,28.92],[7.2,32.19],[6.2,25.58],[8.2,27.72]],"id":28755739},{"atb":[[2.74,46.93],[3.35,17.37],[2.64,99.59],[2.84,44.38],[2.94,21.04]],"id":37456368},{"atl":[[12,18.14],[9.8,15.11],[8.8,17.05],[14.5,14.78]],"id":37456368},{"atb":[[4,54.44],[4.5,23.33],[5,20.41],[5.5,9.07],[7,6.8]],"id":36036864},{"atl":[[70,2.89],[38,3.59],[48,4.24],[29,4.75]],"id":36036864},{"atb":[[6.4,15.12],[7.4,6.38],[5.2,38.88],[5.7,17.37],[9.4,4.86]],"id":39784359},{"spl":[[1.01,2.72]],"id":39784359},{"atl":[[80,1.68],[160,1.25],[55,2.46],[110,1.82]],"id":39784359},{"spn":9.4,"spf":1.0,"id":39784359},{"atb":[[2.82,44.87],[2.92,42.53],[2.72,94.95],[3.55,16.01],[3.05,19.92]],"id":39980001},{"atl":[[17,12.47],[12,12.09],[9.8,15.11],[14.5,14.78]],"id":39980001}],"con":true,"img":false}]}
{"op":"mcm","clk":"5346270365","pt":1646179886556,"mc":[{"id":"1.195453615","rc":[{"spl":[[1.01,2.72]],"id":36036864}],"con":true,"img":false}]}
{"op":"mcm","clk":"5346357877","pt":1646181416512,"mc":[{"id":"1.195453615","rc":[{"atl":[[3.9,8.16]],"id":28755739},{"spn":3.1,"spf":"NaN","id":28755739},{"spn":7.0,"spf":1.0,"id":36036864}],"con":true,"img":false}]}
{"op":"mcm","clk":"5346480392","pt":1646183121862,"mc":[{"id":"1.195453615","rc":[{"atb":[[4.5,0],[3,0],[3.25,0],[3.5,0],[3.75,0]],"id":26503913},{"atl":[[16,0],[18.5,0],[22,0],[27,0]],"id":26503913},{"spn":"NaN","spf":"NaN","id":26503913},{"atb":[[2,81.79],[2.3,31.45],[1.9,181.76],[1.95,86.09],[2.1,37.17]],"id":28755739},{"atl":[[5.6,28.97],[7.2,32.24],[6.2,25.62],[8.2,27.76],[3.9,8.17]],"id":28755739},{"atb":[[2.74,47],[3.35,17.4],[2.64,99.74],[2.84,44.45],[2.94,21.08]],"id":37456368},{"atl":[[12,18.17],[9.8,15.14],[8.8,17.08],[14.5,14.8]],"id":37456368},{"atb":[[4,0],[4.5,0],[5,0],[5.5,0],[7,0]],"id":36036864},{"spl":[[1.01,2.72]],"id":36036864},{"atl":[[70,0],[38,0],[48,0],[29,0]],"id":36036864},{"spn":1.0,"spf":1.0,"id":36036864},{"atb":[[6.4,0],[7.4,0],[5.2,0],[5.7,0],[9.4,0]],"id":39784359},{"spl":[[1.01,2.72]],"id":39784359},{"atl":[[80,0],[160,0],[55,0],[110,0]],"id":39784359},{"spn":1.0,"spf":1.0,"id":39784359},{"atb":[[2.82,44.94],[2.92,42.6],[2.72,95.1],[3.55,16.03],[3.05,19.95]],"id":39980001},{"atl":[[17,12.49],[12,12.11],[9.8,15.14],[14.5,14.8]],"id":39980001}],"con":true,"img":false}]}
{"op":"mcm","clk":"5346480908","pt":1646183129149,"mc":[{"id":"1.195453615","rc":[{"atb":[[4.8,10.76],[4.3,24.78],[5.8,8.52],[3.9,28.2],[3.65,61.73]],"id":26503913},{"atl":[[36,5.7],[19,7.4],[23,6.05],[28,7.4]],"id":26503913},{"atb":[[4,54.52],[4.5,23.37],[5,20.44],[5.5,9.08],[7,6.81]],"id":36036864},{"atl":[[70,2.89],[38,3.6],[48,4.25],[29,4.76]],"id":36036864},{"atb":[[8,11.68],[9,5.11],[6,32.71],[12.5,3.55],[7,13.63]],"id":39784359},{"atl":[[150,0.89],[100,1.34],[200,1],[250,0.8]],"id":39784359}],"con":true,"img":false}]}
{"op":"mcm","clk":"5346580843","pt":1646184717540,"mc":[{"id":"1.195453615","rc":[{"spn":12.4,"spf":"NaN","id":26503913},{"atl":[[3.9,0]],"id":28755739},{"spn":3.95,"spf":"NaN","id":28755739},{"spn":7.0,"spf":1.0,"id":36036864},{"spn":12.5,"spf":1.0,"id":39784359}],"con":true,"img":false}]}
{"op":"mcm","clk":"5346580850","pt":1646184717644,"mc":[{"id":"1.195453615","rc":[{"atl":[[3.8,8.17]],"id":28755739}],"con":true,"img":false}]}
{"op":"mcm","clk":"5346767966","pt":1646187402733,"mc":[{"id":"1.195453615","marketDefinition":{"bspMarket":true,"turnInPlayEnabled":false,"persistenceEnabled":false,"marketBaseRate":7.0,"eventId":"31272494","eventTypeId":"4339","numberOfWinners":1,"bettingType":"ODDS","marketType":"WIN","marketTime":"2022-03-02T09:33:00.000Z","suspendTime":"2022-03-02T09:33:00.000Z","bspReconciled":false,"complete":true,"inPlay":false,"crossMatching":false,"runnersVoidable":false,"numberOfActiveRunners":6,"betDelay":0,"status":"OPEN","runners":[{"status":"ACTIVE","sortPriority":1,"id":26503913,"name":"1. Callum Ari"},{"status":"ACTIVE","sortPriority":2,"id":36036864,"name":"2. Ripplebrook Rory"},{"status":"ACTIVE","sortPriority":3,"id":37456368,"name":"3. Shes So Lovable"},{"status":"ACTIVE","sortPriority":4,"id":39784359,"name":"4. Nicholas Rose"},{"status":"ACTIVE","sortPriority":5,"id":39980001,"name":"7. Elmo Rose"},{"status":"ACTIVE","sortPriority":6,"id":28755739,"name":"8. Perfect Colour"}],"regulators":["MR_INT"],"venue":"Traralgon","countryCode":"AU","discountAllowed":true,"timezone":"Australia/Sydney","openDate":"2022-03-02T08:31:00.000Z","version":4382425352,"name":"R4 395m Gr4/5","eventName":"Traralgon (AUS) 2nd Mar"},"rc":[{"atb":[[4.8,10.76],[4.3,24.78],[5.8,8.52],[3.9,28.2],[3.65,61.73]],"id":26503913},{"atl":[[36,5.7],[19,7.4],[23,6.05],[28,7.4]],"id":26503913},{"spn":12.4,"spf":"NaN","id":26503913},{"atb":[[2,81.79],[2.3,31.45],[1.9,181.76],[1.95,86.09],[2.1,37.17]],"id":28755739},{"atl":[[5.6,28.97],[7.2,32.24],[6.2,25.62],[8.2,27.76],[3.8,8.17]],"id":28755739},{"spn":3.05,"spf":"NaN","id":28755739},{"atb":[[2.74,47],[3.35,17.4],[2.64,99.74],[2.84,44.45],[2.94,21.08]],"id":37456368},{"atl":[[12,18.17],[9.8,15.14],[8.8,17.08],[14.5,14.8]],"id":37456368},{"spn":6.07,"spf":"NaN","id":37456368},{"atb":[[4,54.52],[4.5,23.37],[5,20.44],[5.5,9.08],[7,6.81]],"id":36036864},{"spl":[[1.01,2.72]],"id":36036864},{"atl":[[70,2.89],[38,3.6],[48,4.25],[29,4.76]],"id":36036864},{"spn":7.0,"spf":1.0,"id":36036864},{"atb":[[8,11.68],[9,5.11],[6,32.71],[12.5,3.55],[7,13.63]],"id":39784359},{"spl":[[1.01,2.72]],"id":39784359},{"atl":[[150,0.89],[100,1.34],[200,1],[250,0.8]],"id":39784359},{"spn":12.5,"spf":1.0,"id":39784359},{"atb":[[2.82,44.94],[2.92,42.6],[2.72,95.1],[3.55,16.03],[3.05,19.95]],"id":39980001},{"atl":[[17,12.49],[12,12.11],[9.8,15.14],[14.5,14.8]],"id":39980001},{"spn":6.67,"spf":"NaN","id":39980001}],"con":true,"img":true}]}
{"op":"mcm","clk":"5347092517","pt":1646192802713,"mc":[{"id":"1.195453615","marketDefinition":{"bspMarket":true,"turnInPlayEnabled":false,"persistenceEnabled":false,"marketBaseRate":7.0,"eventId":"31272494","eventTypeId":"4339","numberOfWinners":1,"bettingType":"ODDS","marketType":"WIN","marketTime":"2022-03-02T09:33:00.000Z","suspendTime":"2022-03-02T09:33:00.000Z","bspReconciled":false,"complete":true,"inPlay":false,"crossMatching":false,"runnersVoidable":false,"numberOfActiveRunners":6,"betDelay":0,"status":"OPEN","runners":[{"status":"ACTIVE","sortPriority":1,"id":26503913,"name":"1. Callum Ari"},{"status":"ACTIVE","sortPriority":2,"id":36036864,"name":"2. Ripplebrook Rory"},{"status":"ACTIVE","sortPriority":3,"id":37456368,"name":"3. Shes So Lovable"},{"status":"ACTIVE","sortPriority":4,"id":39784359,"name":"4. Nicholas Rose"},{"status":"ACTIVE","sortPriority":5,"id":39980001,"name":"7. Elmo Rose"},{"status":"ACTIVE","sortPriority":6,"id":28755739,"name":"8. Perfect Colour"}],"regulators":["MR_INT"],"venue":"Traralgon","countryCode":"AU","discountAllowed":true,"timezone":"Australia/Sydney","openDate":"2022-03-02T08:31:00.000Z","version":4382425352,"name":"R4 395m Gr4/5","eventName":"Traralgon (AUS) 2nd Mar"},"rc":[{"atb":[[4.8,10.78],[4.3,24.82],[5.8,8.53],[3.9,28.24],[3.65,61.83]],"id":26503913},{"atl":[[36,5.71],[19,7.41],[23,6.06],[28,7.41]],"id":26503913},{"spn":12.4,"spf":"NaN","id":26503913},{"atb":[[2,81.93],[2.3,31.51],[1.9,182.06],[1.95,86.24],[2.1,37.24]],"id":28755739},{"atl":[[5.6,29.02],[7.2,32.29],[6.2,25.67],[8.2,27.81],[3.8,8.19]],"id":28755739},{"spn":3.05,"spf":"NaN","id":28755739},{"atb":[[2.74,47.08],[3.35,17.42],[2.64,99.91],[2.84,44.52],[2.94,21.11]],"id":37456368},{"atl":[[12,18.2],[9.8,15.16],[8.8,17.11],[14.5,14.83]],"id":37456368},{"spn":6.07,"spf":"NaN","id":37456368},{"atb":[[4,54.62],[4.5,23.41],[5,20.48],[5.5,9.1],[7,6.82]],"id":36036864},{"spl":[[1.01,2.73]],"id":36036864},{"atl":[[70,2.9],[38,3.61],[48,4.26],[29,4.76]],"id":36036864},{"spn":7.0,"spf":1.0,"id":36036864},{"atb":[[8,11.7],[9,5.12],[6,32.77],[12.5,3.56],[7,13.65]],"id":39784359},{"spl":[[1.01,2.73]],"id":39784359},{"atl":[[150,0.89],[100,1.34],[200,1],[250,0.8]],"id":39784359},{"spn":12.5,"spf":1.0,"id":39784359},{"atb":[[2.82,45.01],[2.92,42.67],[2.72,95.26],[3.55,16.06],[3.05,19.98]],"id":39980001},{"atl":[[17,12.51],[12,12.13],[9.8,15.16],[14.5,14.83]],"id":39980001},{"spn":6.67,"spf":"NaN","id":39980001}],"con":true,"img":true}]}
{"op":"mcm","clk":"5347334789","pt":1646197289705,"mc":[{"id":"1.195453615","rc":[{"atb":[[4.8,10.77],[4.3,24.81],[5.8,8.53],[3.9,28.23],[3.65,61.81]],"id":26503913},{"atl":[[36,5.71],[19,7.41],[23,6.06],[28,7.41]],"id":26503913},{"atb":[[2,81.9],[2.3,31.49],[1.9,181.99],[1.95,86.2],[2.1,37.22]],"id":28755739},{"atl":[[5.6,29],[7.2,32.28],[6.2,25.66],[8.2,27.8],[3.8,8.19],[3,4.92]],"id":28755739},{"spn":2.65,"spf":"NaN","id":28755739},{"atb":[[2.74,47.07],[3.35,17.42],[2.64,99.87],[2.84,44.5],[2.94,21.1]],"id":37456368},{"atl":[[12,18.19],[9.8,15.16],[8.8,17.1],[14.5,14.82]],"id":37456368},{"atb":[[4,54.6],[4.5,23.4],[5,20.47],[5.5,9.1],[7,6.82]],"id":36036864},{"spl":[[1.01,2.73]],"id":36036864},{"atl":[[70,2.89],[38,3.6],[48,4.25],[29,4.76]],"id":36036864},{"atb":[[8,11.7],[9,5.12],[6,32.76],[12.5,3.55],[7,13.65]],"id":39784359},{"spl":[[1.01,2.73]],"id":39784359},{"atl":[[150,0.89],[100,1.34],[200,1],[250,0.8]],"id":39784359},{"atb":[[2.82,45],[2.92,42.65],[2.72,95.23],[3.55,16.05],[3.05,19.97]],"id":39980001},{"atl":[[17,12.5],[12,12.13],[9.8,15.16],[14.5,14.82]],"id":39980001}],"con":true,"img":false}]}
{"op":"mcm","clk":"5347351054","pt":1646197662469,"mc":[{"id":"1.195453615","rc":[{"spl":[[1.01,156.15]],"id":28755739},{"spn":2.08,"spf":1.0,"id":28755739}],"con":true,"img":false}]}
{"op":"mcm","clk":"5347663534","pt":1646204663202,"mc":[{"id":"1.195453615","rc":[{"atb":[[4.8,10.77],[4.3,24.8],[5.8,8.53],[4.4,2.97],[3.9,28.23],[3.65,61.79]],"id":26503913},{"atl":[[36,5.71],[19,7.41],[23,6.06],[28,7.41]],"id":26503913},{"atb":[[2,81.87],[2.3,31.49],[1.9,181.94],[1.95,86.18],[2.1,37.21]],"id":28755739},{"spl":[[1.01,156.11]],"id":28755739},{"atl":[[5.6,29],[7.2,32.27],[6.2,25.65],[8.2,27.79],[3,4.93],[3.8,8.18]],"id":28755739},{"atb":[[2.74,47.05],[3.35,17.41],[2.64,99.85],[2.84,44.49],[2.94,21.1]],"id":37456368},{"atl":[[12,18.19],[9.8,15.15],[8.8,17.1],[14.5,14.82]],"id":37456368},{"atb":[[4,54.58],[4.5,23.39],[5.1,2.46],[5,20.46],[5.5,9.09],[7,6.82]],"id":36036864},{"spl":[[1.01,2.72]],"id":36036864},{"atl":[[70,2.89],[38,3.6],[48,4.25],[29,4.76]],"id":36036864},{"atb":[[8,11.69],[9,5.12],[6,32.75],[12.5,3.55],[7,13.64]],"id":39784359},{"spl":[[1.01,2.72]],"id":39784359},{"atl":[[150,0.89],[100,1.34],[200,1],[250,0.8]],"id":39784359},{"atb":[[2.82,44.98],[2.92,42.64],[2.72,95.2],[3.55,16.05],[3.05,19.97]],"id":39980001},{"atl":[[17,12.5],[12,12.12],[9.8,15.15],[14.5,14.82]],"id":39980001}],"con":true,"img":false}]}
{"op":"mcm","clk":"5347663542","pt":1646204663510,"mc":[{"id":"1.195453615","rc":[{"atb":[[2.04,9.72]],"id":28755739},{"atb":[[2.96,5.15]],"id":39980001}],"con":true,"img":false}]}
{"op":"mcm","clk":"5347663553","pt":1646204663817,"mc":[{"id":"1.195453615","rc":[{"atb":[[2.88,5.37]],"id":37456368}],"con":true,"img":false}]}
{"op":"mcm","clk":"5347664591","pt":1646204699527,"mc":[{"id":"1.195453615","marketDefinition":{"bspMarket":true,"turnInPlayEnabled":false,"persistenceEnabled":false,"marketBaseRate":7.0,"eventId":"31272494","eventTypeId":"4339","numberOfWinners":1,"bettingType":"ODDS","marketType":"WIN","marketTime":"2022-03-02T09:33:00.000Z","suspendTime":"2022-03-02T09:33:00.000Z","bspReconciled":false,"complete":true,"inPlay":false,"crossMatching":true,"runnersVoidable":false,"numberOfActiveRunners":6,"betDelay":0,"status":"OPEN","runners":[{"status":"ACTIVE","sortPriority":1,"id":26503913,"name":"1. Callum Ari"},{"status":"ACTIVE","sortPriority":2,"id":36036864,"name":"2. Ripplebrook Rory"},{"status":"ACTIVE","sortPriority":3,"id":37456368,"name":"3. Shes So Lovable"},{"status":"ACTIVE","sortPriority":4,"id":39784359,"name":"4. Nicholas Rose"},{"status":"ACTIVE","sortPriority":5,"id":39980001,"name":"7. Elmo Rose"},{"status":"ACTIVE","sortPriority":6,"id":28755739,"name":"8. Perfect Colour"}],"regulators":["MR_INT"],"venue":"Traralgon","countryCode":"AU","discountAllowed":true,"timezone":"Australia/Sydney","openDate":"2022-03-02T08:31:00.000Z","version":4382425352,"name":"R4 395m Gr4/5","eventName":"Traralgon (AUS) 2nd Mar"},"rc":[],"con":true,"img":false}]}
{"op":"mcm","clk":"5347667332","pt":1646204789228,"mc":[{"id":"1.195453615","rc":[{"spn":2.08,"spf":1.0,"id":28755739},{"atb":[[1.01,2.25]],"id":36036864},{"atb":[[2.96,8.99]],"id":39980001}],"con":true,"img":false}]}
{"op":"mcm","clk":"5347667334","pt":1646204789329,"mc":[{"id":"1.195453615","rc":[{"atb":[[1.01,2.25]],"id":26503913},{"atb":[[2.34,5.61]],"id":28755739},{"atb":[[2.88,9.38]],"id":37456368}],"con":true,"img":false}]}
{"op":"mcm","clk":"5347667339","pt":1646204789434,"mc":[{"id":"1.195453615","rc":[{"atb":[[1.01,1.83]],"id":36036864}],"con":true,"img":false}]}
{"op":"mcm","clk":"5347667341","pt":1646204789534,"mc":[{"id":"1.195453615","rc":[{"atb":[[1.01,2.21]],"id":26503913}],"con":true,"img":false}]}
{"op":"mcm","clk":"5347667345","pt":1646204789636,"mc":[{"id":"1.195453615","rc":[{"atb":[[1.01,0]],"id":36036864}],"con":true,"img":false}]}
{"op":"mcm","clk":"5347667347","pt":1646204789738,"mc":[{"id":"1.195453615","rc":[{"atb":[[5.1,4.3]],"id":36036864}],"con":true,"img":false}]}
{"op":"mcm","clk":"5347667356","pt":1646204790046,"mc":[{"id":"1.195453615","rc":[{"atb":[[1.01,0]],"id":26503913}],"con":true,"img":false}]}
{"op":"mcm","clk":"5347667358","pt":1646204790148,"mc":[{"id":"1.195453615","rc":[{"atb":[[4.4,5.18]],"id":26503913}],"con":true,"img":false}]}
{"op":"mcm","clk":"5347724362","pt":1646206380075,"mc":[{"id":"1.195453615","rc":[{"atb":[[6.6,1.8]],"id":26503913},{"spn":12.8,"spf":"NaN","id":26503913},{"atb":[[2.16,2]],"id":28755739},{"spn":2.1,"spf":1.0,"id":28755739},{"atb":[[3.85,2]],"id":37456368},{"spn":6.32,"spf":"NaN","id":37456368},{"atb":[[9.2,1.23]],"id":36036864},{"spn":7.99,"spf":1.0,"id":36036864},{"atb":[[14,0.78]],"id":39784359},{"spn":12.92,"spf":1.0,"id":39784359},{"atb":[[3.75,2]],"id":39980001},{"spn":6.77,"spf":"NaN","id":39980001}],"con":true,"img":false}]}
{"op":"mcm","clk":"5347727751","pt":1646206473606,"mc":[{"id":"1.195453615","rc":[{"atb":[[4.9,10.11]],"id":26503913}],"con":true,"img":false}]}
{"op":"mcm","clk":"5347727758","pt":1646206473811,"mc":[{"id":"1.195453615","rc":[{"atb":[[5.6,8.55]],"id":36036864}],"con":true,"img":false}]}
{"op":"mcm","clk":"5347731793","pt":1646206594997,"mc":[{"id":"1.195453615","rc":[{"atb":[[4.9,0]],"id":26503913}],"con":true,"img":false}]}
{"op":"mcm","clk":"5347731798","pt":1646206595200,"mc":[{"id":"1.195453615","rc":[{"atb":[[5.9,8.08]],"id":26503913}],"con":true,"img":false}]}
{"op":"mcm","clk":"5347733861","pt":1646206657934,"mc":[{"id":"1.195453615","rc":[{"atb":[[5.6,0]],"id":36036864}],"con":true,"img":false}]}
{"op":"mcm","clk":"5347733869","pt":1646206658088,"mc":[{"id":"1.195453615","rc":[{"atb":[[5.2,9.41]],"id":36036864}],"con":true,"img":false}]}
{"op":"mcm","clk":"5347736562","pt":1646206718114,"mc":[{"id":"1.195453615","rc":[{"atb":[[5.2,0]],"id":36036864}],"con":true,"img":false}]}
{"op":"mcm","clk":"5347736566","pt":1646206718317,"mc":[{"id":"1.195453615","rc":[{"atb":[[5.7,8.4]],"id":36036864}],"con":true,"img":false}]}
{"op":"mcm","clk":"5347738902","pt":1646206779017,"mc":[{"id":"1.195453615","rc":[{"atb":[[5.7,0]],"id":36036864}],"con":true,"img":false}]}
{"op":"mcm","clk":"5347738910","pt":1646206779222,"mc":[{"id":"1.195453615","rc":[{"atb":[[5.6,8.55]],"id":36036864}],"con":true,"img":false}]}
{"op":"mcm","clk":"5347743677","pt":1646206901511,"mc":[{"id":"1.195453615","rc":[{"atb":[[5.6,0]],"id":36036864}],"con":true,"img":false}]}
{"op":"mcm","clk":"5347743682","pt":1646206901716,"mc":[{"id":"1.195453615","rc":[{"atb":[[5.2,9.41]],"id":36036864}],"con":true,"img":false}]}
{"op":"mcm","clk":"5347746220","pt":1646206962382,"mc":[{"id":"1.195453615","rc":[{"atb":[[5.2,0]],"id":36036864}],"con":true,"img":false}]}
{"op":"mcm","clk":"5347746231","pt":1646206962580,"mc":[{"id":"1.195453615","rc":[{"atb":[[5.7,8.4]],"id":36036864}],"con":true,"img":false}]}
{"op":"mcm","clk":"5347751162","pt":1646207087390,"mc":[{"id":"1.195453615","rc":[{"atb":[[5.7,0]],"id":36036864}],"con":true,"img":false}]}
{"op":"mcm","clk":"5347751174","pt":1646207087596,"mc":[{"id":"1.195453615","rc":[{"atb":[[5.2,9.41]],"id":36036864}],"con":true,"img":false}]}
{"op":"mcm","clk":"5347754241","pt":1646207148209,"mc":[{"id":"1.195453615","rc":[{"atb":[[5.2,0]],"id":36036864}],"con":true,"img":false}]}
{"op":"mcm","clk":"5347754256","pt":1646207148370,"mc":[{"id":"1.195453615","rc":[{"atb":[[5.6,8.55]],"id":36036864}],"con":true,"img":false}]}
{"op":"mcm","clk":"5347761466","pt":1646207269657,"mc":[{"id":"1.195453615","rc":[{"atb":[[5.6,0]],"id":36036864}],"con":true,"img":false}]}
{"op":"mcm","clk":"5347761476","pt":1646207269865,"mc":[{"id":"1.195453615","rc":[{"atb":[[5.2,9.41]],"id":36036864}],"con":true,"img":false}]}
{"op":"mcm","clk":"5347764588","pt":1646207330171,"mc":[{"id":"1.195453615","rc":[{"atb":[[5.2,0]],"id":36036864}],"con":true,"img":false}]}
{"op":"mcm","clk":"5347764596","pt":1646207330377,"mc":[{"id":"1.195453615","rc":[{"atb":[[5.7,8.4]],"id":36036864}],"con":true,"img":false}]}
{"op":"mcm","clk":"5347765988","pt":1646207359133,"mc":[{"id":"1.195453615","rc":[{"atb":[[2.3,9.81],[2.34,0]],"id":28755739},{"trd":[[2.3,43.35],[2.34,11.23]],"ltp":2.3,"tv":54.58,"id":28755739}],"con":true,"img":false}]}
{"op":"mcm","clk":"5347766001","pt":1646207359337,"mc":[{"id":"1.195453615","rc":[{"atb":[[2.16,0],[2.34,5.61]],"id":28755739},{"atl":[[2.68,4.89]],"id":28755739}],"con":true,"img":false}]}
{"op":"mcm","clk":"5347766152","pt":1646207362530,"mc":[{"id":"1.195453615","rc":[{"atb":[[2.34,0]],"id":28755739}],"con":true,"img":false}]}
{"op":"mcm","clk":"5347766519","pt":1646207370936,"mc":[{"id":"1.195453615","rc":[{"atb":[[3.4,1.34]],"id":37456368},{"atb":[[3.6,1.3]],"id":39980001}],"con":true,"img":false}]}
{"op":"mcm","clk":"5347767432","pt":1646207391152,"mc":[{"id":"1.195453615","rc":[{"spn":2.03,"spf":1.0,"id":28755739},{"atb":[[5.7,0]],"id":36036864}],"con":true,"img":false}]}
{"op":"mcm","clk":"5347767444","pt":1646207391358,"mc":[{"id":"1.195453615","rc":[{"atb":[[5.2,9.41]],"id":36036864}],"con":true,"img":false}]}
{"op":"mcm","clk":"5347768416","pt":1646207410492,"mc":[{"id":"1.195453615","rc":[{"atl":[[2.68,0]],"id":28755739}],"con":true,"img":false}]}
{"op":"mcm","clk":"5347768424","pt":1646207410695,"mc":[{"id":"1.195453615","rc":[{"atl":[[2.38,5.51]],"id":28755739}],"con":true,"img":false}]}
{"op":"mcm","clk":"5347768430","pt":1646207410798,"mc":[{"id":"1.195453615","rc":[{"atb":[[2.32,1.37]],"id":28755739}],"con":true,"img":false}]}
{"op":"mcm","clk":"5347768479","pt":1646207411674,"mc":[{"id":"1.195453615","rc":[{"atb":[[2.32,0]],"id":28755739}],"con":true,"img":false}]}
{"op":"mcm","clk":"5347768485","pt":1646207411775,"mc":[{"id":"1.195453615","rc":[{"atb":[[1.01,1.37]],"id":28755739}],"con":true,"img":false}]}
{"op":"mcm","clk":"5347768859","pt":1646207419898,"mc":[{"id":"1.195453615","rc":[{"atb":[[2.04,0]],"id":28755739}],"con":true,"img":false}]}
{"op":"mcm","clk":"5347768863","pt":1646207419999,"mc":[{"id":"1.195453615","rc":[{"atb":[[1.38,2]],"id":28755739}],"con":true,"img":false}]}
{"op":"mcm","clk":"5347770506","pt":1646207452322,"mc":[{"id":"1.195453615","rc":[{"spn":2.03,"spf":1.0,"id":28755739},{"atb":[[5.2,0]],"id":36036864}],"con":true,"img":false}]}
{"op":"mcm","clk":"5347770520","pt":1646207452525,"mc":[{"id":"1.195453615","rc":[{"atb":[[5.6,8.55]],"id":36036864}],"con":true,"img":false}]}
{"op":"mcm","clk":"5347777282","pt":1646207573388,"mc":[{"id":"1.195453615","rc":[{"atb":[[5.6,0]],"id":36036864}],"con":true,"img":false}]}
{"op":"mcm","clk":"5347777294","pt":1646207573593,"mc":[{"id":"1.195453615","rc":[{"atb":[[5.2,9.41]],"id":36036864}],"con":true,"img":false}]}
{"op":"mcm","clk":"5347780628","pt":1646207634829,"mc":[{"id":"1.195453615","rc":[{"atb":[[5.2,0]],"id":36036864}],"con":true,"img":false}]}
{"op":"mcm","clk":"5347780642","pt":1646207635036,"mc":[{"id":"1.195453615","rc":[{"atb":[[5.7,8.4]],"id":36036864}],"con":true,"img":false}]}
{"op":"mcm","clk":"5347786672","pt":1646207756196,"mc":[{"id":"1.195453615","rc":[{"atb":[[5.7,0]],"id":36036864}],"con":true,"img":false}]}
{"op":"mcm","clk":"5347786682","pt":1646207756349,"mc":[{"id":"1.195453615","rc":[{"atb":[[5.2,9.41]],"id":36036864}],"con":true,"img":false}]}
{"op":"mcm","clk":"5347788340","pt":1646207789624,"mc":[{"id":"1.195453615","rc":[{"atl":[[18.5,2.68]],"id":26503913},{"atl":[[8.6,2.6]],"id":37456368},{"atl":[[990,2.66]],"id":39784359},{"atl":[[9.6,2.74]],"id":39980001}],"con":true,"img":false}]}
{"op":"mcm","clk":"5347789603","pt":1646207817023,"mc":[{"id":"1.195453615","rc":[{"spn":12.55,"spf":"NaN","id":26503913},{"spn":6.22,"spf":"NaN","id":37456368},{"atb":[[5.2,0]],"id":36036864},{"spn":6.67,"spf":"NaN","id":39980001}],"con":true,"img":false}]}
{"op":"mcm","clk":"5347789615","pt":1646207817228,"mc":[{"id":"1.195453615","rc":[{"atb":[[5.6,8.55]],"id":36036864}],"con":true,"img":false}]}
{"op":"mcm","clk":"5347792428","pt":1646207877813,"mc":[{"id":"1.195453615","rc":[{"atb":[[5.6,0]],"id":36036864}],"con":true,"img":false}]}
{"op":"mcm","clk":"5347792440","pt":1646207878008,"mc":[{"id":"1.195453615","rc":[{"atb":[[5.2,9.41]],"id":36036864}],"con":true,"img":false}]}
{"op":"mcm","clk":"5347794836","pt":1646207938808,"mc":[{"id":"1.195453615","rc":[{"atb":[[5.2,0]],"id":36036864}],"con":true,"img":false}]}
{"op":"mcm","clk":"5347794845","pt":1646207938962,"mc":[{"id":"1.195453615","rc":[{"atb":[[5.6,8.55]],"id":36036864}],"con":true,"img":false}]}
{"op":"mcm","clk":"5347797281","pt":1646207999470,"mc":[{"id":"1.195453615","rc":[{"atb":[[5.6,0]],"id":36036864}],"con":true,"img":false}]}
{"op":"mcm","clk":"5347797291","pt":1646207999677,"mc":[{"id":"1.195453615","rc":[{"atb":[[5.2,9.41]],"id":36036864}],"con":true,"img":false}]}
{"op":"mcm","clk":"5347799868","pt":1646208060264,"mc":[{"id":"1.195453615","rc":[{"atb":[[5.2,0]],"id":36036864}],"con":true,"img":false}]}
{"op":"mcm","clk":"5347799875","pt":1646208060470,"mc":[{"id":"1.195453615","rc":[{"atb":[[5.7,8.4]],"id":36036864}],"con":true,"img":false}]}
{"op":"mcm","clk":"5347802153","pt":1646208120972,"mc":[{"id":"1.195453615","rc":[{"atb":[[5.7,0]],"id":36036864}],"con":true,"img":false}]}
{"op":"mcm","clk":"5347802166","pt":1646208121179,"mc":[{"id":"1.195453615","rc":[{"atb":[[5.2,9.41]],"id":36036864}],"con":true,"img":false}]}
{"op":"mcm","clk":"5347804592","pt":1646208181618,"mc":[{"id":"1.195453615","rc":[{"atb":[[5.2,0]],"id":36036864}],"con":true,"img":false}]}
{"op":"mcm","clk":"5347804606","pt":1646208181824,"mc":[{"id":"1.195453615","rc":[{"atb":[[5.8,8.24]],"id":36036864}],"con":true,"img":false}]}
{"op":"mcm","clk":"5347804629","pt":1646208182231,"mc":[{"id":"1.195453615","rc":[{"atb":[[6,1.57]],"id":26503913},{"atb":[[3.4,3]],"id":37456368},{"atb":[[7.2,1.49]],"id":36036864},{"atb":[[3.6,2.8]],"id":39980001}],"con":true,"img":false}]}
{"op":"mcm","clk":"5347804642","pt":1646208182440,"mc":[{"id":"1.195453615","rc":[{"atb":[[3.45,29.39],[2.46,56.16]],"id":26503913},{"atl":[[46,8.2]],"id":26503913},{"atb":[[1.59,122.03],[1.35,234.29]],"id":28755739},{"atb":[[4,78.58],[2.8,45.56]],"id":36036864},{"atl":[[70,11.09]],"id":36036864},{"atb":[[4.4,24.12],[6.6,12.86]],"id":39784359},{"atl":[[17.5,8.2]],"id":39980001}],"con":true,"img":false}]}
{"op":"mcm","clk":"5347804650","pt":1646208182541,"mc":[{"id":"1.195453615","rc":[{"atl":[[4.2,8.2]],"id":28755739},{"atl":[[15.5,8.2]],"id":37456368}],"con":true,"img":false}]}
{"op":"mcm","clk":"5347804656","pt":1646208182645,"mc":[{"id":"1.195453615","rc":[{"atb":[[2.62,46.3]],"id":26503913},{"atl":[[60,14.2]],"id":26503913},{"atl":[[17,8.5],[34,13.5],[5.1,14.2]],"id":28755739},{"atl":[[34,13.5],[20,14.2]],"id":37456368},{"atb":[[2.62,46.3]],"id":36036864},{"atl":[[95,14.2]],"id":36036864},{"atb":[[2.62,46.3],[4.2,26.56]],"id":39784359},{"atl":[[34,13.5],[23,14.2]],"id":39980001}],"con":true,"img":false}]}
{"op":"mcm","clk":"5347806411","pt":1646208225980,"mc":[{"id":"1.195453615","rc":[{"atb":[[6.4,10.84],[6,27.22]],"id":26503913},{"atl":[[18.5,9.77],[15.5,4.03]],"id":26503913},{"atb":[[2.02,119.07],[2.12,52.27]],"id":28755739},{"atl":[[3.5,23.41],[4.6,30.36]],"id":28755739},{"atb":[[3.4,47.58],[3.55,22.95]],"id":37456368},{"atl":[[8.6,16.68],[7,9.75]],"id":37456368},{"atb":[[7.2,21.26],[8.4,7.9]],"id":36036864},{"atl":[[22,2.78],[28,4.53]],"id":36036864},{"atb":[[12,5.32],[9.8,14.74]],"id":39784359},{"atl":[[36,2.72],[50,2.72]],"id":39784359},{"atb":[[3.6,25.32],[3.1,55.23]],"id":39980001},{"atl":[[9.6,16.23],[7,9.75]],"id":39980001}],"con":true,"img":false}]}
{"op":"mcm","clk":"5347806426","pt":1646208226390,"mc":[{"id":"1.195453615","rc":[{"atb":[[6.6,3.1]],"id":26503913},{"atl":[[8.6,14.07]],"id":37456368}],"con":true,"img":false}]}
{"op":"mcm","clk":"5347806432","pt":1646208226495,"mc":[{"id":"1.195453615","rc":[{"atb":[[3.4,46.24]],"id":37456368},{"atl":[[6.8,2.6]],"id":37456368}],"con":true,"img":false}]}
{"op":"mcm","clk":"5347806436","pt":1646208226596,"mc":[{"id":"1.195453615","rc":[{"atb":[[3.6,1.34]],"id":37456368}],"con":true,"img":false}]}
{"op":"mcm","clk":"5347806457","pt":1646208227108,"mc":[{"id":"1.195453615","rc":[{"atb":[[13,1.67]],"id":39784359}],"con":true,"img":false}]}
{"op":"mcm","clk":"5347806459","pt":1646208227162,"mc":[{"id":"1.195453615","rc":[{"atb":[[6,25.65]],"id":26503913},{"atb":[[3.4,44.57]],"id":37456368},{"atb":[[7.2,19.76]],"id":36036864}],"con":true,"img":false}]}
{"op":"mcm","clk":"5347806460","pt":1646208227266,"mc":[{"id":"1.195453615","rc":[{"atb":[[6.8,1.57]],"id":26503913},{"atb":[[3.6,3]],"id":37456368},{"atb":[[8.6,1.49]],"id":36036864}],"con":true,"img":false}]}
{"op":"mcm","clk":"5347806653","pt":1646208232609,"mc":[{"id":"1.195453615","rc":[{"atb":[[4.4,2.97]],"id":26503913},{"atb":[[2.88,5.37]],"id":37456368},{"atb":[[5.1,2.46]],"id":36036864},{"atb":[[2.96,5.15]],"id":39980001}],"con":true,"img":false}]}
{"op":"mcm","clk":"5347807017","pt":1646208241612,"mc":[{"id":"1.195453615","rc":[{"atb":[[1.01,2.25]],"id":26503913},{"atb":[[3.6,5.9]],"id":37456368},{"atb":[[3.65,2.83]],"id":39980001}],"con":true,"img":false}]}
{"op":"mcm","clk":"5347807024","pt":1646208241819,"mc":[{"id":"1.195453615","rc":[{"atb":[[1.01,1.44]],"id":26503913},{"spn":11.15,"spf":"NaN","id":26503913},{"spn":2.09,"spf":1.0,"id":28755739},{"spn":5.32,"spf":"NaN","id":37456368},{"spn":8.87,"spf":1.0,"id":36036864},{"spn":13.23,"spf":1.0,"id":39784359},{"spn":5.37,"spf":"NaN","id":39980001}],"con":true,"img":false}]}
{"op":"mcm","clk":"5347807030","pt":1646208241921,"mc":[{"id":"1.195453615","rc":[{"atb":[[1.01,0]],"id":26503913}],"con":true,"img":false}]}
{"op":"mcm","clk":"5347807034","pt":1646208242021,"mc":[{"id":"1.195453615","rc":[{"atb":[[6.2,1.44]],"id":26503913}],"con":true,"img":false}]}
{"op":"mcm","clk":"5347807039","pt":1646208242124,"mc":[{"id":"1.195453615","rc":[{"atb":[[3.6,23.81]],"id":39980001}],"con":true,"img":false}]}
{"op":"mcm","clk":"5347807045","pt":1646208242227,"mc":[{"id":"1.195453615","rc":[{"atb":[[3.7,1.5]],"id":39980001}],"con":true,"img":false}]}
{"op":"mcm","clk":"5347807055","pt":1646208242383,"mc":[{"id":"1.195453615","rc":[{"atb":[[5.8,0]],"id":36036864}],"con":true,"img":false}]}
{"op":"mcm","clk":"5347807065","pt":1646208242586,"mc":[{"id":"1.195453615","rc":[{"atb":[[5.2,9.41]],"id":36036864}],"con":true,"img":false}]}
{"op":"mcm","clk":"5347807087","pt":1646208242999,"mc":[{"id":"1.195453615","rc":[{"atb":[[2.36,52.94],[1.82,100]],"id":39980001}],"con":true,"img":false}]}
{"op":"mcm","clk":"5347808544","pt":1646208278338,"mc":[{"id":"1.195453615","rc":[{"atb":[[4.4,0]],"id":26503913},{"atb":[[2.88,0]],"id":37456368},{"atb":[[5.1,0]],"id":36036864},{"atb":[[2.96,0]],"id":39980001}],"con":true,"img":false}]}
{"op":"mcm","clk":"5347809004","pt":1646208289290,"mc":[{"id":"1.195453615","rc":[{"atl":[[18.5,2.68]],"id":26503913},{"atl":[[4.6,0],[4.1,39.17]],"id":28755739}],"con":true,"img":false}]}
{"op":"mcm","clk":"5347809011","pt":1646208289347,"mc":[{"id":"1.195453615","rc":[{"atl":[[18,7.09]],"id":26503913}],"con":true,"img":false}]}
{"op":"mcm","clk":"5347809019","pt":1646208289451,"mc":[{"id":"1.195453615","rc":[{"atl":[[3.8,0]],"id":28755739}],"con":true,"img":false}]}
{"op":"mcm","clk":"5347809063","pt":1646208290247,"mc":[{"id":"1.195453615","rc":[{"atb":[[6.2,3.38]],"id":26503913}],"con":true,"img":false}]}
{"op":"mcm","clk":"5347809076","pt":1646208290453,"mc":[{"id":"1.195453615","rc":[{"atb":[[3.6,9.79]],"id":37456368},{"atb":[[3.65,6.64]],"id":39980001}],"con":true,"img":false}]}
{"op":"mcm","clk":"5347809103","pt":1646208290962,"mc":[{"id":"1.195453615","rc":[{"atb":[[3.6,22.51]],"id":39980001}],"con":true,"img":false}]}
{"op":"mcm","clk":"5347809107","pt":1646208291065,"mc":[{"id":"1.195453615","rc":[{"atb":[[3.65,7.94]],"id":39980001}],"con":true,"img":false}]}
{"op":"mcm","clk":"5347809446","pt":1646208299799,"mc":[{"id":"1.195453615","rc":[{"atb":[[5.9,0]],"id":26503913}],"con":true,"img":false}]}
{"op":"mcm","clk":"5347809452","pt":1646208299960,"mc":[{"id":"1.195453615","rc":[{"atb":[[6.6,10.18]],"id":26503913}],"con":true,"img":false}]}
{"op":"mcm","clk":"5347809584","pt":1646208303077,"mc":[{"id":"1.195453615","rc":[{"atb":[[5.2,0]],"id":36036864}],"con":true,"img":false}]}
{"op":"mcm","clk":"5347809649","pt":1646208304573,"mc":[{"id":"1.195453615","rc":[{"atb":[[6,0]],"id":26503913}],"con":true,"img":false}]}
{"op":"mcm","clk":"5347809654","pt":1646208304676,"mc":[{"id":"1.195453615","rc":[{"atb":[[5.9,25.65]],"id":26503913}],"con":true,"img":false}]}
{"op":"mcm","clk":"5347810001","pt":1646208313705,"mc":[{"id":"1.195453615","rc":[{"atb":[[6.2,1.93]],"id":26503913}],"con":true,"img":false}]}
{"op":"mcm","clk":"5347810323","pt":1646208322692,"mc":[{"id":"1.195453615","rc":[{"atb":[[1.01,2.25]],"id":26503913}],"con":true,"img":false}]}
{"op":"mcm","clk":"5347810331","pt":1646208322898,"mc":[{"id":"1.195453615","rc":[{"atb":[[1.01,1.5]],"id":26503913}],"con":true,"img":false}]}
{"op":"mcm","clk":"5347810339","pt":1646208323102,"mc":[{"id":"1.195453615","rc":[{"atb":[[1.01,0]],"id":26503913}],"con":true,"img":false}]}
{"op":"mcm","clk":"5347810344","pt":1646208323201,"mc":[{"id":"1.195453615","rc":[{"atb":[[6,1.5]],"id":26503913}],"con":true,"img":false}]}
{"op":"mcm","clk":"5347810476","pt":1646208326501,"mc":[{"id":"1.195453615","rc":[{"atb":[[6.2,0]],"id":26503913}],"con":true,"img":false}]}
{"op":"mcm","clk":"5347811533","pt":1646208349162,"mc":[{"id":"1.195453615","rc":[{"atb":[[6.4,0]],"id":26503913}],"con":true,"img":false}]}
{"op":"mcm","clk":"5347811539","pt":1646208349265,"mc":[{"id":"1.195453615","rc":[{"atb":[[6.8,12.41]],"id":26503913}],"con":true,"img":false}]}
{"op":"mcm","clk":"5347811583","pt":1646208350148,"mc":[{"id":"1.195453615","rc":[{"atb":[[6.6,8.87]],"id":26503913}],"con":true,"img":false}]}
{"op":"mcm","clk":"5347811591","pt":1646208350253,"mc":[{"id":"1.195453615","rc":[{"atb":[[7,1.3]],"id":26503913}],"con":true,"img":false}]}
{"op":"mcm","clk":"5347811855","pt":1646208355870,"mc":[{"id":"1.195453615","rc":[{"atb":[[6,0]],"id":26503913}],"con":true,"img":false}]}
{"op":"mcm","clk":"5347812096","pt":1646208360453,"mc":[{"id":"1.195453615","rc":[{"atb":[[6.6,1.8]],"id":26503913}],"con":true,"img":false}]}
{"op":"mcm","clk":"5347812118","pt":1646208360759,"mc":[{"id":"1.195453615","rc":[{"atb":[[6,7.85]],"id":26503913}],"con":true,"img":false}]}
{"op":"mcm","clk":"5347812124","pt":1646208360856,"mc":[{"id":"1.195453615","rc":[{"atb":[[2.3,4.21]],"id":28755739},{"trd":[[2.3,54.55]],"ltp":2.3,"tv":54.55,"id":28755739}],"con":true,"img":false}]}
{"op":"mcm","clk":"5347812191","pt":1646208362257,"mc":[{"id":"1.195453615","rc":[{"atb":[[6.8,1.57]],"id":26503913}],"con":true,"img":false}]}
{"op":"mcm","clk":"5347812196","pt":1646208362358,"mc":[{"id":"1.195453615","rc":[{"atb":[[6.4,10.84]],"id":26503913}],"con":true,"img":false}]}
{"op":"mcm","clk":"5347812218","pt":1646208362971,"mc":[{"id":"1.195453615","rc":[{"atb":[[6.8,0]],"id":26503913}],"con":true,"img":false}]}
{"op":"mcm","clk":"5347812224","pt":1646208363076,"mc":[{"id":"1.195453615","rc":[{"atb":[[6.6,3.37]],"id":26503913}],"con":true,"img":false}]}
{"op":"mcm","clk":"5347812229","pt":1646208363180,"mc":[{"id":"1.195453615","rc":[{"atb":[[7,0]],"id":26503913},{"spn":11.05,"spf":"NaN","id":26503913},{"spn":2.08,"spf":1.0,"id":28755739}],"con":true,"img":false}]}
{"op":"mcm","clk":"5347812234","pt":1646208363279,"mc":[{"id":"1.195453615","rc":[{"atb":[[6.6,4.67]],"id":26503913}],"con":true,"img":false}]}
{"op":"mcm","clk":"5347813158","pt":1646208385779,"mc":[{"id":"1.195453615","rc":[{"atb":[[1.01,2.25]],"id":26503913}],"con":true,"img":false}]}
{"op":"mcm","clk":"5347813164","pt":1646208385983,"mc":[{"id":"1.195453615","rc":[{"atb":[[1.01,1.5]],"id":26503913}],"con":true,"img":false}]}
{"op":"mcm","clk":"5347813172","pt":1646208386190,"mc":[{"id":"1.195453615","rc":[{"atb":[[1.01,0]],"id":26503913}],"con":true,"img":false}]}
{"op":"mcm","clk":"5347813177","pt":1646208386297,"mc":[{"id":"1.195453615","rc":[{"atb":[[6,9.36]],"id":26503913}],"con":true,"img":false}]}
{"op":"mcm","clk":"5347813686","pt":1646208398016,"mc":[{"id":"1.195453615","rc":[{"spl":[[1.01,8.18]],"id":39784359}],"con":true,"img":false}]}
{"op":"mcm","clk":"5347814495","pt":1646208417355,"mc":[{"id":"1.195453615","rc":[{"atb":[[5.9,0]],"id":26503913}],"con":true,"img":false}]}
{"op":"mcm","clk":"5347814498","pt":1646208417431,"mc":[{"id":"1.195453615","rc":[{"atb":[[6.2,25.65]],"id":26503913}],"con":true,"img":false}]}
{"op":"mcm","clk":"5347814613","pt":1646208421344,"mc":[{"id":"1.195453615","rc":[{"atb":[[6,1.5]],"id":26503913}],"con":true,"img":false}]}
{"op":"mcm","clk":"5347814622","pt":1646208421552,"mc":[{"id":"1.195453615","rc":[{"atb":[[6.6,11.75]],"id":26503913}],"con":true,"img":false}]}
{"op":"mcm","clk":"5347814729","pt":1646208423833,"mc":[{"id":"1.195453615","rc":[{"atb":[[6.2,0]],"id":26503913},{"spn":12.61,"spf":1.0,"id":39784359}],"con":true,"img":false}]}
{"op":"mcm","clk":"5347814735","pt":1646208423939,"mc":[{"id":"1.195453615","rc":[{"atb":[[5.9,25.65]],"id":26503913}],"con":true,"img":false}]}
{"op":"mcm","clk":"5347814781","pt":1646208424976,"mc":[{"id":"1.195453615","rc":[{"atb":[[6,0]],"id":26503913}],"con":true,"img":false}]}
{"op":"mcm","clk":"5347815284","pt":1646208436889,"mc":[{"id":"1.195453615","rc":[{"atb":[[1.01,2.25]],"id":26503913}],"con":true,"img":false}]}
{"op":"mcm","clk":"5347815288","pt":1646208436992,"mc":[{"id":"1.195453615","rc":[{"atb":[[1.01,1.29]],"id":26503913}],"con":true,"img":false}]}
{"op":"mcm","clk":"5347815300","pt":1646208437195,"mc":[{"id":"1.195453615","rc":[{"atb":[[1.01,0]],"id":26503913}],"con":true,"img":false}]}
{"op":"mcm","clk":"5347815303","pt":1646208437298,"mc":[{"id":"1.195453615","rc":[{"atb":[[6.8,1.29]],"id":26503913}],"con":true,"img":false}]}
{"op":"mcm","clk":"5347816259","pt":1646208459883,"mc":[{"id":"1.195453615","rc":[{"atb":[[6.4,0]],"id":26503913}],"con":true,"img":false}]}
{"op":"mcm","clk":"5347816263","pt":1646208459985,"mc":[{"id":"1.195453615","rc":[{"atb":[[6.8,12.13]],"id":26503913}],"con":true,"img":false}]}
{"op":"mcm","clk":"5347816286","pt":1646208460603,"mc":[{"id":"1.195453615","rc":[{"atb":[[6.6,10.44]],"id":26503913}],"con":true,"img":false}]}
{"op":"mcm","clk":"5347816294","pt":1646208460706,"mc":[{"id":"1.195453615","rc":[{"atb":[[7,1.3]],"id":26503913}],"con":true,"img":false}]}
{"op":"mcm","clk":"5347816444","pt":1646208463949,"mc":[{"id":"1.195453615","rc":[{"atb":[[6.6,8.87]],"id":26503913}],"con":true,"img":false}]}
{"op":"mcm","clk":"5347816450","pt":1646208464002,"mc":[{"id":"1.195453615","rc":[{"atb":[[7,2.87]],"id":26503913}],"con":true,"img":false}]}
{"op":"mcm","clk":"5347816595","pt":1646208467039,"mc":[{"id":"1.195453615","rc":[{"atb":[[6.8,10.84]],"id":26503913}],"con":true,"img":false}]}
{"op":"mcm","clk":"5347818485","pt":1646208510963,"mc":[{"id":"1.195453615","rc":[{"spn":11.25,"spf":"NaN","id":26503913},{"spl":[[1.01,167.03]],"id":28755739},{"spn":2.07,"spf":1.0,"id":28755739}],"con":true,"img":false}]}
{"op":"mcm","clk":"5347819561","pt":1646208535450,"mc":[{"id":"1.195453615","rc":[{"atb":[[2.8,0]],"id":36036864}],"con":true,"img":false}]}
{"op":"mcm","clk":"5347820101","pt":1646208548591,"mc":[{"id":"1.195453615","rc":[{"atb":[[6,2.02]],"id":26503913}],"con":true,"img":false}]}
{"op":"mcm","clk":"5347822375","pt":1646208603593,"mc":[{"id":"1.195453615","rc":[{"atb":[[6.6,1.8]],"id":26503913}],"con":true,"img":false}]}
{"op":"mcm","clk":"5347822382","pt":1646208603763,"mc":[{"id":"1.195453615","rc":[{"atb":[[7,9.48]],"id":26503913}],"con":true,"img":false}]}
{"op":"mcm","clk":"5347824322","pt":1646208644311,"mc":[{"id":"1.195453615","rc":[{"atb":[[6.8,0]],"id":26503913}],"con":true,"img":false}]}
{"op":"mcm","clk":"5347824328","pt":1646208644410,"mc":[{"id":"1.195453615","rc":[{"atb":[[7.2,10.84]],"id":26503913}],"con":true,"img":false}]}
{"op":"mcm","clk":"5347824350","pt":1646208644815,"mc":[{"id":"1.195453615","rc":[{"atb":[[7,8.18]],"id":26503913}],"con":true,"img":false}]}
{"op":"mcm","clk":"5347824356","pt":1646208644917,"mc":[{"id":"1.195453615","rc":[{"atb":[[7.4,1.3]],"id":26503913}],"con":true,"img":false}]}
{"op":"mcm","clk":"5347824373","pt":1646208645328,"mc":[{"id":"1.195453615","rc":[{"atb":[[7,6.61]],"id":26503913}],"con":true,"img":false}]}
{"op":"mcm","clk":"5347824377","pt":1646208645387,"mc":[{"id":"1.195453615","rc":[{"atb":[[7.4,2.87]],"id":26503913}],"con":true,"img":false}]}
{"op":"mcm","clk":"5347825199","pt":1646208664140,"mc":[{"id":"1.195453615","rc":[{"atb":[[7,0]],"id":26503913},{"spn":11.45,"spf":"NaN","id":26503913}],"con":true,"img":false}]}
{"op":"mcm","clk":"5347825220","pt":1646208664543,"mc":[{"id":"1.195453615","rc":[{"atb":[[7.4,1.57]],"id":26503913}],"con":true,"img":false}]}
{"op":"mcm","clk":"5347825225","pt":1646208664645,"mc":[{"id":"1.195453615","rc":[{"atb":[[1.02,1.3]],"id":26503913}],"con":true,"img":false}]}
{"op":"mcm","clk":"5347825563","pt":1646208672519,"mc":[{"id":"1.195453615","rc":[{"atb":[[7.2,0]],"id":26503913}],"con":true,"img":false}]}
{"op":"mcm","clk":"5347825568","pt":1646208672621,"mc":[{"id":"1.195453615","rc":[{"atb":[[6.4,10.84]],"id":26503913}],"con":true,"img":false}]}
{"op":"mcm","clk":"5347825591","pt":1646208673033,"mc":[{"id":"1.195453615","rc":[{"atb":[[1.02,0]],"id":26503913}],"con":true,"img":false}]}
{"op":"mcm","clk":"5347825596","pt":1646208673131,"mc":[{"id":"1.195453615","rc":[{"atb":[[6.6,3.1]],"id":26503913}],"con":true,"img":false}]}
{"op":"mcm","clk":"5347825608","pt":1646208673340,"mc":[{"id":"1.195453615","rc":[{"atb":[[7.4,0]],"id":26503913}],"con":true,"img":false}]}
{"op":"mcm","clk":"5347825614","pt":1646208673442,"mc":[{"id":"1.195453615","rc":[{"atb":[[6.6,4.67]],"id":26503913}],"con":true,"img":false}]}
{"op":"mcm","clk":"5347826275","pt":1646208689474,"mc":[{"id":"1.195453615","rc":[{"atb":[[1.01,2.25]],"id":26503913}],"con":true,"img":false}]}
{"op":"mcm","clk":"5347826280","pt":1646208689679,"mc":[{"id":"1.195453615","rc":[{"atb":[[1.01,1.5]],"id":26503913}],"con":true,"img":false}]}
{"op":"mcm","clk":"5347826289","pt":1646208689844,"mc":[{"id":"1.195453615","rc":[{"atb":[[1.01,0]],"id":26503913}],"con":true,"img":false}]}
{"op":"mcm","clk":"5347826294","pt":1646208689948,"mc":[{"id":"1.195453615","rc":[{"atb":[[6,3.52]],"id":26503913}],"con":true,"img":false}]}
{"op":"mcm","clk":"5347832488","pt":1646208820835,"mc":[{"id":"1.195453615","rc":[{"spl":[[1.01,4]],"id":26503913},{"spn":6.6,"spf":1.0,"id":26503913},{"spl":[[1.01,6.72]],"id":36036864},{"spn":8.59,"spf":1.0,"id":36036864},{"spl":[[1.01,12.18]],"id":39784359},{"spn":12.25,"spf":1.0,"id":39784359}],"con":true,"img":false}]}
{"op":"mcm","clk":"5347859251","pt":1646209141870,"mc":[{"id":"1.195453615","rc":[{"atl":[[130,8.2],[150,15.09]],"id":39784359}],"con":true,"img":false}]}
{"op":"mcm","clk":"5347863334","pt":1646209221007,"mc":[{"id":"1.195453615","rc":[{"atb":[[12,0]],"id":39784359},{"spn":11.29,"spf":1.0,"id":39784359}],"con":true,"img":false}]}
{"op":"mcm","clk":"5347863340","pt":1646209221109,"mc":[{"id":"1.195453615","rc":[{"atb":[[10.5,5.32]],"id":39784359}],"con":true,"img":false}]}
{"op":"mcm","clk":"5347863363","pt":1646209221618,"mc":[{"id":"1.195453615","rc":[{"atb":[[13,0]],"id":39784359}],"con":true,"img":false}]}
{"op":"mcm","clk":"5347863371","pt":1646209221721,"mc":[{"id":"1.195453615","rc":[{"atb":[[1.01,1.67]],"id":39784359}],"con":true,"img":false}]}
{"op":"mcm","clk":"5347864930","pt":1646209252254,"mc":[{"id":"1.195453615","rc":[{"atl":[[36,0]],"id":39784359}],"con":true,"img":false}]}
{"op":"mcm","clk":"5347864938","pt":1646209252356,"mc":[{"id":"1.195453615","rc":[{"atl":[[34,2.72]],"id":39784359}],"con":true,"img":false}]}
{"op":"mcm","clk":"5347867941","pt":1646209307704,"mc":[{"id":"1.195453615","rc":[{"atb":[[10.5,0]],"id":39784359},{"spn":10.85,"spf":1.0,"id":39784359}],"con":true,"img":false}]}
{"op":"mcm","clk":"5347867948","pt":1646209307806,"mc":[{"id":"1.195453615","rc":[{"atb":[[11,5.32]],"id":39784359}],"con":true,"img":false}]}
{"op":"mcm","clk":"5347869343","pt":1646209335893,"mc":[{"id":"1.195453615","rc":[{"atb":[[1.38,0]],"id":28755739}],"con":true,"img":false}]}
{"op":"mcm","clk":"5347900324","pt":1646209982458,"mc":[{"id":"1.195453615","rc":[{"atb":[[6.6,0]],"id":26503913},{"trd":[[6.6,9.34]],"ltp":6.6,"tv":9.34,"id":26503913},{"spn":6.4,"spf":1.0,"id":26503913},{"atl":[[2.38,0]],"id":28755739},{"trd":[[2.38,11.03]],"ltp":2.38,"tv":11.03,"id":28755739},{"atb":[[14,0]],"id":39784359},{"trd":[[14,1.56]],"ltp":14.0,"tv":1.56,"id":39784359},{"spn":11.11,"spf":1.0,"id":39784359}],"con":true,"img":false}]}
{"op":"mcm","clk":"5347900332","pt":1646209982561,"mc":[{"id":"1.195453615","rc":[{"atb":[[4.3,53.03]],"id":26503913},{"atl":[[34,3.03]],"id":26503913},{"atb":[[5.6,21.74]],"id":39784359},{"atl":[[80,2]],"id":39784359}],"con":true,"img":false}]}
{"op":"mcm","clk":"5347900338","pt":1646209982666,"mc":[{"id":"1.195453615","rc":[{"atb":[[1.62,161.29]],"id":28755739},{"atl":[[3.5,46.83]],"id":28755739},{"atb":[[3.05,44.5]],"id":37456368},{"atl":[[14,7.69]],"id":37456368},{"atb":[[3.15,46.3]],"id":36036864},{"atl":[[46,2.22]],"id":36036864},{"atb":[[2.72,153.34]],"id":39980001},{"atl":[[8.8,12.82]],"id":39980001}],"con":true,"img":false}]}
{"op":"mcm","clk":"5347900365","pt":1646209983132,"mc":[{"id":"1.195453615","rc":[{"atl":[[15.5,5.5]],"id":26503913}],"con":true,"img":false}]}
{"op":"mcm","clk":"5347900374","pt":1646209983339,"mc":[{"id":"1.195453615","rc":[{"atl":[[18.5,0]],"id":26503913},{"atl":[[9.6,13.48]],"id":39980001}],"con":true,"img":false}]}
{"op":"mcm","clk":"5347900379","pt":1646209983443,"mc":[{"id":"1.195453615","rc":[{"atl":[[15,2.68]],"id":26503913},{"atl":[[6.8,2.74]],"id":39980001}],"con":true,"img":false}]}
{"op":"mcm","clk":"5347900416","pt":1646209984164,"mc":[{"id":"1.195453615","rc":[{"atl":[[15.5,4.03]],"id":26503913}],"con":true,"img":false}]}
{"op":"mcm","clk":"5347900422","pt":1646209984267,"mc":[{"id":"1.195453615","rc":[{"atl":[[14.5,1.46]],"id":26503913}],"con":true,"img":false}]}
{"op":"mcm","clk":"5347900441","pt":1646209984634,"mc":[{"id":"1.195453615","rc":[{"atl":[[15,0]],"id":26503913}],"con":true,"img":false}]}
{"op":"mcm","clk":"5347900448","pt":1646209984732,"mc":[{"id":"1.195453615","rc":[{"atl":[[1000,2.68]],"id":26503913}],"con":true,"img":false}]}
{"op":"mcm","clk":"5347900468","pt":1646209985041,"mc":[{"id":"1.195453615","rc":[{"atl":[[15,1.08]],"id":26503913}],"con":true,"img":false}]}
{"op":"mcm","clk":"5347900473","pt":1646209985144,"mc":[{"id":"1.195453615","rc":[{"atb":[[2.32,5.61]],"id":28755739},{"atl":[[3.45,4.36]],"id":28755739}],"con":true,"img":false}]}
{"op":"mcm","clk":"5347900510","pt":1646209986072,"mc":[{"id":"1.195453615","rc":[{"atl":[[3.45,10.22]],"id":28755739}],"con":true,"img":false}]}
{"op":"mcm","clk":"5347900594","pt":1646209987569,"mc":[{"id":"1.195453615","rc":[{"atb":[[1.01,0]],"id":28755739}],"con":true,"img":false}]}
{"op":"mcm","clk":"5347900602","pt":1646209987672,"mc":[{"id":"1.195453615","rc":[{"atb":[[2.32,6.99]],"id":28755739}],"con":true,"img":false}]}
{"op":"mcm","clk":"5347900709","pt":1646209989539,"mc":[{"id":"1.195453615","rc":[{"atl":[[18,0]],"id":26503913}],"con":true,"img":false}]}
{"op":"mcm","clk":"5347900715","pt":1646209989642,"mc":[{"id":"1.195453615","rc":[{"atl":[[18.5,7.09]],"id":26503913}],"con":true,"img":false}]}
{"op":"mcm","clk":"5347900959","pt":1646209995878,"mc":[{"id":"1.195453615","rc":[{"atb":[[6.4,0]],"id":26503913}],"con":true,"img":false}]}
{"op":"mcm","clk":"5347900966","pt":1646209995982,"mc":[{"id":"1.195453615","rc":[{"atb":[[6,14.36]],"id":26503913}],"con":true,"img":false}]}
{"op":"mcm","clk":"5347901067","pt":1646209997945,"mc":[{"id":"1.195453615","rc":[{"atb":[[2.16,8.71]],"id":28755739}],"con":true,"img":false}]}
{"op":"mcm","clk":"5347901174","pt":1646210000678,"mc":[{"id":"1.195453615","rc":[{"atb":[[3.15,0],[2.78,46.3]],"id":36036864}],"con":true,"img":false}]}
{"op":"mcm","clk":"5347901210","pt":1646210001455,"mc":[{"id":"1.195453615","rc":[{"atb":[[12.5,0]],"id":39784359},{"trd":[[12.5,7.11]],"ltp":12.5,"tv":7.11,"id":39784359}],"con":true,"img":false}]}
{"op":"mcm","clk":"5347901213","pt":1646210001552,"mc":[{"id":"1.195453615","rc":[{"atb":[[12.5,0.88]],"id":39784359}],"con":true,"img":false}]}
{"op":"mcm","clk":"5347901273","pt":1646210003155,"mc":[{"id":"1.195453615","rc":[{"atb":[[6,12.86]],"id":26503913}],"con":true,"img":false}]}
{"op":"mcm","clk":"5347901655","pt":1646210012104,"mc":[{"id":"1.195453615","rc":[{"atb":[[1.01,2.25]],"id":26503913}],"con":true,"img":false}]}
{"op":"mcm","clk":"5347901663","pt":1646210012311,"mc":[{"id":"1.195453615","rc":[{"atb":[[1.01,1.44]],"id":26503913}],"con":true,"img":false}]}
{"op":"mcm","clk":"5347901671","pt":1646210012467,"mc":[{"id":"1.195453615","rc":[{"atb":[[1.01,0]],"id":26503913}],"con":true,"img":false}]}
{"op":"mcm","clk":"5347901676","pt":1646210012571,"mc":[{"id":"1.195453615","rc":[{"atb":[[6.2,1.44]],"id":26503913}],"con":true,"img":false}]}
{"op":"mcm","clk":"5347901888","pt":1646210018383,"mc":[{"id":"1.195453615","rc":[{"atb":[[12.5,0]],"id":39784359},{"trd":[[12.5,8.87]],"ltp":12.5,"tv":8.87,"id":39784359}],"con":true,"img":false}]}
{"op":"mcm","clk":"5347901962","pt":1646210019820,"mc":[{"id":"1.195453615","rc":[{"atb":[[1.62,0],[1.8,125]],"id":28755739}],"con":true,"img":false}]}
{"op":"mcm","clk":"5347902102","pt":1646210023582,"mc":[{"id":"1.195453615","rc":[{"atb":[[6,14.86]],"id":26503913}],"con":true,"img":false}]}
{"op":"mcm","clk":"5347902467","pt":1646210033842,"mc":[{"id":"1.195453615","rc":[{"atb":[[2.12,0]],"id":28755739}],"con":true,"img":false}]}
{"op":"mcm","clk":"5347902473","pt":1646210033945,"mc":[{"id":"1.195453615","rc":[{"atb":[[2.18,52.27]],"id":28755739}],"con":true,"img":false}]}
{"op":"mcm","clk":"5347902671","pt":1646210039324,"mc":[{"id":"1.195453615","rc":[{"atl":[[9.6,0]],"id":39980001}],"con":true,"img":false}]}
{"op":"mcm","clk":"5347902676","pt":1646210039428,"mc":[{"id":"1.195453615","rc":[{"atl":[[8.6,13.48]],"id":39980001}],"con":true,"img":false}]}
{"op":"mcm","clk":"5347902852","pt":1646210043340,"mc":[{"id":"1.195453615","rc":[{"atb":[[4.3,24.8],[3.85,35.09]],"id":26503913},{"spn":6.07,"spf":1.0,"id":26503913},{"spn":2.11,"spf":1.0,"id":28755739},{"atb":[[2.82,54.95],[3.05,0]],"id":37456368},{"atb":[[4.9,25.64],[5.6,0]],"id":39784359},{"spn":10.32,"spf":1.0,"id":39784359},{"atb":[[2.72,95.2],[2.54,64.94]],"id":39980001},{"spn":5.27,"spf":"NaN","id":39980001}],"con":true,"img":false}]}
{"op":"mcm","clk":"5347903563","pt":1646210059243,"mc":[{"id":"1.195453615","rc":[{"atb":[[12,0.92]],"id":39784359}],"con":true,"img":false}]}
{"op":"mcm","clk":"5347903626","pt":1646210060939,"mc":[{"id":"1.195453615","rc":[{"atb":[[2.16,0]],"id":28755739}],"con":true,"img":false}]}
{"op":"mcm","clk":"5347904021","pt":1646210070882,"mc":[{"id":"1.195453615","rc":[{"atb":[[2.18,0]],"id":28755739}],"con":true,"img":false}]}
{"op":"mcm","clk":"5347904023","pt":1646210070984,"mc":[{"id":"1.195453615","rc":[{"atb":[[2.12,52.27]],"id":28755739}],"con":true,"img":false}]}
{"op":"mcm","clk":"5347904552","pt":1646210086002,"mc":[{"id":"1.195453615","rc":[{"atb":[[2.16,8.71]],"id":28755739}],"con":true,"img":false}]}
{"op":"mcm","clk":"5347905097","pt":1646210102423,"mc":[{"id":"1.195453615","rc":[{"atl":[[3.45,5.86]],"id":28755739}],"con":true,"img":false}]}
{"op":"mcm","clk":"5347905216","pt":1646210105407,"mc":[{"id":"1.195453615","rc":[{"atl":[[3.45,10.22]],"id":28755739},{"spn":2.09,"spf":1.0,"id":28755739},{"spn":10.49,"spf":1.0,"id":39784359}],"con":true,"img":false}]}
{"op":"mcm","clk":"5347905332","pt":1646210109311,"mc":[{"id":"1.195453615","rc":[{"atl":[[3.45,4.36]],"id":28755739}],"con":true,"img":false}]}
{"op":"mcm","clk":"5347905521","pt":1646210114814,"mc":[{"id":"1.195453615","rc":[{"atb":[[2.12,0]],"id":28755739}],"con":true,"img":false}]}
{"op":"mcm","clk":"5347905524","pt":1646210114914,"mc":[{"id":"1.195453615","rc":[{"atb":[[2.18,52.27]],"id":28755739}],"con":true,"img":false}]}
{"op":"mcm","clk":"5347905737","pt":1646210121443,"mc":[{"id":"1.195453615","rc":[{"atl":[[3.45,10.22]],"id":28755739}],"con":true,"img":false}]}
{"op":"mcm","clk":"5347905905","pt":1646210126741,"mc":[{"id":"1.195453615","rc":[{"atb":[[1.02,2.25]],"id":36036864},{"atl":[[1000,2.25]],"id":39784359}],"con":true,"img":false}]}
{"op":"mcm","clk":"5347905909","pt":1646210126840,"mc":[{"id":"1.195453615","rc":[{"atb":[[1.02,0.39]],"id":36036864}],"con":true,"img":false}]}
{"op":"mcm","clk":"5347905911","pt":1646210126943,"mc":[{"id":"1.195453615","rc":[{"atl":[[1000,0.12]],"id":39784359}],"con":true,"img":false}]}
{"op":"mcm","clk":"5347905915","pt":1646210127046,"mc":[{"id":"1.195453615","rc":[{"atb":[[1.02,0]],"id":36036864}],"con":true,"img":false}]}
{"op":"mcm","clk":"5347905918","pt":1646210127149,"mc":[{"id":"1.195453615","rc":[{"atb":[[9.4,0.39]],"id":36036864}],"con":true,"img":false}]}
{"op":"mcm","clk":"5347905923","pt":1646210127355,"mc":[{"id":"1.195453615","rc":[{"atl":[[1000,0]],"id":39784359}],"con":true,"img":false}]}
{"op":"mcm","clk":"5347905926","pt":1646210127455,"mc":[{"id":"1.195453615","rc":[{"atl":[[32,0.12]],"id":39784359}],"con":true,"img":false}]}
{"op":"mcm","clk":"5347906160","pt":1646210133568,"mc":[{"id":"1.195453615","rc":[{"atb":[[2.16,0]],"id":28755739}],"con":true,"img":false}]}
{"op":"mcm","clk":"5347906213","pt":1646210134855,"mc":[{"id":"1.195453615","rc":[{"atb":[[11,0]],"id":39784359}],"con":true,"img":false}]}
{"op":"mcm","clk":"5347906218","pt":1646210134958,"mc":[{"id":"1.195453615","rc":[{"atb":[[11.5,5.32]],"id":39784359}],"con":true,"img":false}]}
{"op":"mcm","clk":"5347906566","pt":1646210144384,"mc":[{"id":"1.195453615","rc":[{"atb":[[2.18,0]],"id":28755739}],"con":true,"img":false}]}
{"op":"mcm","clk":"5347906570","pt":1646210144436,"mc":[{"id":"1.195453615","rc":[{"atb":[[2.12,52.27]],"id":28755739}],"con":true,"img":false}]}
{"op":"mcm","clk":"5347907038","pt":1646210157396,"mc":[{"id":"1.195453615","rc":[{"atb":[[2.16,8.71]],"id":28755739}],"con":true,"img":false}]}
{"op":"mcm","clk":"5347908476","pt":1646210189023,"mc":[{"id":"1.195453615","rc":[{"atb":[[2.12,0]],"id":28755739},{"spn":2.06,"spf":1.0,"id":28755739},{"spn":8.64,"spf":1.0,"id":36036864},{"spn":10.7,"spf":1.0,"id":39784359}],"con":true,"img":false}]}
{"op":"mcm","clk":"5347908484","pt":1646210189126,"mc":[{"id":"1.195453615","rc":[{"atb":[[2.18,52.27]],"id":28755739}],"con":true,"img":false}]}
{"op":"mcm","clk":"5347909313","pt":1646210205392,"mc":[{"id":"1.195453615","rc":[{"atb":[[2.16,0]],"id":28755739}],"con":true,"img":false}]}
{"op":"mcm","clk":"5347909794","pt":1646210216433,"mc":[{"id":"1.195453615","rc":[{"atb":[[2.18,0]],"id":28755739}],"con":true,"img":false}]}
{"op":"mcm","clk":"5347909800","pt":1646210216536,"mc":[{"id":"1.195453615","rc":[{"atb":[[2.12,52.27]],"id":28755739}],"con":true,"img":false}]}
{"op":"mcm","clk":"5347910101","pt":1646210222863,"mc":[{"id":"1.195453615","rc":[{"atl":[[3.45,5.86]],"id":28755739}],"con":true,"img":false}]}
{"op":"mcm","clk":"5347910217","pt":1646210225645,"mc":[{"id":"1.195453615","rc":[{"atl":[[3.45,10.22]],"id":28755739}],"con":true,"img":false}]}
{"op":"mcm","clk":"5347910369","pt":1646210229355,"mc":[{"id":"1.195453615","rc":[{"atb":[[2.16,8.71]],"id":28755739}],"con":true,"img":false}]}
{"op":"mcm","clk":"5347910785","pt":1646210238872,"mc":[{"id":"1.195453615","rc":[{"atl":[[3.45,4.36]],"id":28755739}],"con":true,"img":false}]}
{"op":"mcm","clk":"5347911186","pt":1646210247668,"mc":[{"id":"1.195453615","rc":[{"atl":[[3.45,10.22]],"id":28755739}],"con":true,"img":false}]}
{"op":"mcm","clk":"5347911672","pt":1646210258274,"mc":[{"id":"1.195453615","rc":[{"atb":[[2.12,0]],"id":28755739}],"con":true,"img":false}]}
{"op":"mcm","clk":"5347911677","pt":1646210258375,"mc":[{"id":"1.195453615","rc":[{"atb":[[2.18,52.27]],"id":28755739}],"con":true,"img":false}]}
{"op":"mcm","clk":"5347912720","pt":1646210280933,"mc":[{"id":"1.195453615","rc":[{"atb":[[2.16,0]],"id":28755739}],"con":true,"img":false}]}
{"op":"mcm","clk":"5347913196","pt":1646210292533,"mc":[{"id":"1.195453615","rc":[{"atb":[[2.22,8.28]],"id":28755739}],"con":true,"img":false}]}
{"op":"mcm","clk":"5347913331","pt":1646210295524,"mc":[{"id":"1.195453615","rc":[{"atb":[[2.18,0]],"id":28755739}],"con":true,"img":false}]}
{"op":"mcm","clk":"5347913335","pt":1646210295627,"mc":[{"id":"1.195453615","rc":[{"atb":[[2.12,52.27]],"id":28755739}],"con":true,"img":false}]}
{"op":"mcm","clk":"5347914023","pt":1646210311549,"mc":[{"id":"1.195453615","rc":[{"atl":[[6,87.33]],"id":37456368}],"con":true,"img":false}]}
{"op":"mcm","clk":"5347914045","pt":1646210312167,"mc":[{"id":"1.195453615","rc":[{"atl":[[6.8,0]],"id":37456368}],"con":true,"img":false}]}
{"op":"mcm","clk":"5347914052","pt":1646210312270,"mc":[{"id":"1.195453615","rc":[{"atl":[[5.9,2.6]],"id":37456368}],"con":true,"img":false}]}
{"op":"mcm","clk":"5347914239","pt":1646210316968,"mc":[{"id":"1.195453615","rc":[{"atb":[[2.22,0]],"id":28755739}],"con":true,"img":false}]}
{"op":"mcm","clk":"5347914495","pt":1646210325661,"mc":[{"id":"1.195453615","rc":[{"atb":[[2.16,8.71]],"id":28755739},{"spn":2.09,"spf":1.0,"id":28755739},{"spn":4.87,"spf":"NaN","id":37456368}],"con":true,"img":false}]}
{"op":"mcm","clk":"5347915058","pt":1646210342872,"mc":[{"id":"1.195453615","rc":[{"atl":[[3.45,5.86]],"id":28755739}],"con":true,"img":false}]}
{"op":"mcm","clk":"5347915908","pt":1646210365297,"mc":[{"id":"1.195453615","rc":[{"atl":[[3.45,0]],"id":28755739}],"con":true,"img":false}]}
{"op":"mcm","clk":"5347916557","pt":1646210384216,"mc":[{"id":"1.195453615","rc":[{"atb":[[2.12,0]],"id":28755739}],"con":true,"img":false}]}
{"op":"mcm","clk":"5347916561","pt":1646210384319,"mc":[{"id":"1.195453615","rc":[{"atb":[[2.18,52.27]],"id":28755739}],"con":true,"img":false}]}
{"op":"mcm","clk":"5347917000","pt":1646210398420,"mc":[{"id":"1.195453615","rc":[{"atb":[[2.16,0]],"id":28755739},{"spn":2.1,"spf":1.0,"id":28755739}],"con":true,"img":false}]}
{"op":"mcm","clk":"5347917400","pt":1646210408245,"mc":[{"id":"1.195453615","rc":[{"atb":[[2.22,8.28]],"id":28755739}],"con":true,"img":false}]}
{"op":"mcm","clk":"5347917443","pt":1646210409763,"mc":[{"id":"1.195453615","rc":[{"atb":[[2.18,0]],"id":28755739}],"con":true,"img":false}]}
{"op":"mcm","clk":"5347917446","pt":1646210409867,"mc":[{"id":"1.195453615","rc":[{"atb":[[2.12,52.27]],"id":28755739}],"con":true,"img":false}]}
{"op":"mcm","clk":"5347917649","pt":1646210416594,"mc":[{"id":"1.195453615","rc":[{"atb":[[12,0]],"id":39784359}],"con":true,"img":false}]}
{"op":"mcm","clk":"5347917659","pt":1646210416749,"mc":[{"id":"1.195453615","rc":[{"atb":[[13,0.84]],"id":39784359}],"con":true,"img":false}]}
{"op":"mcm","clk":"5347917737","pt":1646210419953,"mc":[{"id":"1.195453615","rc":[{"atb":[[13,0]],"id":39784359},{"trd":[[13,1.68]],"ltp":13.0,"tv":1.68,"id":39784359}],"con":true,"img":false}]}
{"op":"mcm","clk":"5347917752","pt":1646210420833,"mc":[{"id":"1.195453615","rc":[{"atl":[[4.6,30.36]],"id":28755739}],"con":true,"img":false}]}
{"op":"mcm","clk":"5347917755","pt":1646210420935,"mc":[{"id":"1.195453615","rc":[{"atl":[[4.1,0]],"id":28755739}],"con":true,"img":false}]}
{"op":"mcm","clk":"5347918355","pt":1646210437450,"mc":[{"id":"1.195453615","rc":[{"atb":[[2.22,0]],"id":28755739}],"con":true,"img":false}]}
{"op":"mcm","clk":"5347918721","pt":1646210446490,"mc":[{"id":"1.195453615","rc":[{"atb":[[2.16,8.71]],"id":28755739}],"con":true,"img":false}]}
{"op":"mcm","clk":"5347918983","pt":1646210455089,"mc":[{"id":"1.195453615","rc":[{"atb":[[2.12,0]],"id":28755739}],"con":true,"img":false}]}
{"op":"mcm","clk":"5347918988","pt":1646210455192,"mc":[{"id":"1.195453615","rc":[{"atb":[[2.18,52.27]],"id":28755739}],"con":true,"img":false}]}
{"op":"mcm","clk":"5347919051","pt":1646210456692,"mc":[{"id":"1.195453615","rc":[{"atb":[[12.5,0.88]],"id":39784359}],"con":true,"img":false}]}
{"op":"mcm","clk":"5347919073","pt":1646210457093,"mc":[{"id":"1.195453615","rc":[{"atb":[[12.5,0]],"id":39784359}],"con":true,"img":false}]}
{"op":"mcm","clk":"5347919080","pt":1646210457196,"mc":[{"id":"1.195453615","rc":[{"atb":[[13,0.84]],"id":39784359}],"con":true,"img":false}]}
{"op":"mcm","clk":"5347919173","pt":1646210459511,"mc":[{"id":"1.195453615","rc":[{"spn":2.11,"spf":1.0,"id":28755739},{"atb":[[13,0]],"id":39784359},{"trd":[[13,3.36]],"ltp":13.0,"tv":3.36,"id":39784359},{"spn":10.54,"spf":1.0,"id":39784359}],"con":true,"img":false}]}
{"op":"mcm","clk":"5347919178","pt":1646210459723,"mc":[{"id":"1.195453615","rc":[{"atl":[[32,1.49]],"id":39784359}],"con":true,"img":false}]}
{"op":"mcm","clk":"5347919905","pt":1646210479498,"mc":[{"id":"1.195453615","rc":[{"atb":[[2.16,0]],"id":28755739}],"con":true,"img":false}]}
{"op":"mcm","clk":"5347920282","pt":1646210489229,"mc":[{"id":"1.195453615","rc":[{"atb":[[2.18,0]],"id":28755739}],"con":true,"img":false}]}
{"op":"mcm","clk":"5347920287","pt":1646210489332,"mc":[{"id":"1.195453615","rc":[{"atb":[[2.12,52.27]],"id":28755739}],"con":true,"img":false}]}
{"op":"mcm","clk":"5347920570","pt":1646210495828,"mc":[{"id":"1.195453615","rc":[{"atb":[[12.5,0.88]],"id":39784359}],"con":true,"img":false}]}
{"op":"mcm","clk":"5347921185","pt":1646210510154,"mc":[{"id":"1.195453615","rc":[{"atb":[[12.5,0]],"id":39784359},{"trd":[[12.5,10.63]],"ltp":12.5,"tv":10.63,"id":39784359}],"con":true,"img":false}]}
{"op":"mcm","clk":"5347921292","pt":1646210512780,"mc":[{"id":"1.195453615","rc":[{"atb":[[2.16,8.71]],"id":28755739}],"con":true,"img":false}]}
{"op":"mcm","clk":"5347922554","pt":1646210542919,"mc":[{"id":"1.195453615","rc":[{"atb":[[2.12,0]],"id":28755739},{"spn":2.06,"spf":1.0,"id":28755739}],"con":true,"img":false}]}
{"op":"mcm","clk":"5347922558","pt":1646210542978,"mc":[{"id":"1.195453615","rc":[{"atb":[[2.18,52.27]],"id":28755739}],"con":true,"img":false}]}
{"op":"mcm","clk":"5347922676","pt":1646210546009,"mc":[{"id":"1.195453615","rc":[{"atb":[[12.5,0.88]],"id":39784359}],"con":true,"img":false}]}
{"op":"mcm","clk":"5347923368","pt":1646210563758,"mc":[{"id":"1.195453615","rc":[{"atb":[[2.16,0]],"id":28755739}],"con":true,"img":false}]}
{"op":"mcm","clk":"5347923468","pt":1646210566514,"mc":[{"id":"1.195453615","rc":[{"atb":[[12.5,0]],"id":39784359},{"trd":[[12.5,12.39]],"ltp":12.5,"tv":12.39,"id":39784359}],"con":true,"img":false}]}
{"op":"mcm","clk":"5347923775","pt":1646210573722,"mc":[{"id":"1.195453615","rc":[{"atb":[[2.18,0]],"id":28755739}],"con":true,"img":false}]}
{"op":"mcm","clk":"5347923781","pt":1646210573825,"mc":[{"id":"1.195453615","rc":[{"atb":[[2.12,52.27]],"id":28755739}],"con":true,"img":false}]}
{"op":"mcm","clk":"5347924548","pt":1646210593286,"mc":[{"id":"1.195453615","rc":[{"atb":[[2.16,8.71]],"id":28755739}],"con":true,"img":false}]}
{"op":"mcm","clk":"5347924975","pt":1646210601768,"mc":[{"id":"1.195453615","rc":[{"atb":[[12.5,0.88]],"id":39784359}],"con":true,"img":false}]}
{"op":"mcm","clk":"5347925432","pt":1646210611685,"mc":[{"id":"1.195453615","rc":[{"spn":2.09,"spf":1.0,"id":28755739},{"atb":[[12.5,0]],"id":39784359},{"trd":[[12.5,14.15]],"ltp":12.5,"tv":14.15,"id":39784359}],"con":true,"img":false}]}
{"op":"mcm","clk":"5347926131","pt":1646210627389,"mc":[{"id":"1.195453615","rc":[{"atb":[[2.12,0]],"id":28755739}],"con":true,"img":false}]}
{"op":"mcm","clk":"5347926135","pt":1646210627490,"mc":[{"id":"1.195453615","rc":[{"atb":[[2.18,52.27]],"id":28755739}],"con":true,"img":false}]}
{"op":"mcm","clk":"5347926824","pt":1646210644217,"mc":[{"id":"1.195453615","rc":[{"atb":[[2.16,0]],"id":28755739}],"con":true,"img":false}]}
{"op":"mcm","clk":"5347926950","pt":1646210646541,"mc":[{"id":"1.195453615","rc":[{"atb":[[12.5,0.88]],"id":39784359}],"con":true,"img":false}]}
{"op":"mcm","clk":"5347927272","pt":1646210654238,"mc":[{"id":"1.195453615","rc":[{"atb":[[2.22,8.28]],"id":28755739}],"con":true,"img":false}]}
{"op":"mcm","clk":"5347927407","pt":1646210656783,"mc":[{"id":"1.195453615","rc":[{"atb":[[2.18,0]],"id":28755739}],"con":true,"img":false}]}
{"op":"mcm","clk":"5347927414","pt":1646210656878,"mc":[{"id":"1.195453615","rc":[{"atb":[[2.12,52.27]],"id":28755739}],"con":true,"img":false}]}
{"op":"mcm","clk":"5347928445","pt":1646210679210,"mc":[{"id":"1.195453615","rc":[{"spn":2.09,"spf":1.0,"id":28755739},{"atb":[[12.5,0]],"id":39784359},{"trd":[[12.5,15.91]],"ltp":12.5,"tv":15.91,"id":39784359}],"con":true,"img":false}]}
{"op":"mcm","clk":"5347928621","pt":1646210683608,"mc":[{"id":"1.195453615","rc":[{"atb":[[2.22,0]],"id":28755739}],"con":true,"img":false}]}
{"op":"mcm","clk":"5347929162","pt":1646210695391,"mc":[{"id":"1.195453615","rc":[{"atb":[[2.16,8.71]],"id":28755739}],"con":true,"img":false}]}
{"op":"mcm","clk":"5347929454","pt":1646210702342,"mc":[{"id":"1.195453615","rc":[{"atb":[[1.04,1.67]],"id":28755739},{"atb":[[1.04,1.67]],"id":37456368},{"atb":[[1.04,1.67]],"id":39980001}],"con":true,"img":false}]}
{"op":"mcm","clk":"5347929458","pt":1646210702501,"mc":[{"id":"1.195453615","rc":[{"atb":[[1.04,1.66]],"id":28755739},{"atb":[[1.04,1.66]],"id":37456368},{"atb":[[1.04,1.66]],"id":39980001}],"con":true,"img":false}]}
{"op":"mcm","clk":"5347929466","pt":1646210702707,"mc":[{"id":"1.195453615","rc":[{"atb":[[1.04,0]],"id":28755739},{"atb":[[1.04,0]],"id":37456368},{"atb":[[1.04,0]],"id":39980001}],"con":true,"img":false}]}
{"op":"mcm","clk":"5347929472","pt":1646210702812,"mc":[{"id":"1.195453615","rc":[{"atb":[[2.36,1.66]],"id":28755739},{"atb":[[3.75,1.66]],"id":37456368},{"atb":[[3.8,1.66]],"id":39980001}],"con":true,"img":false}]}
{"op":"mcm","clk":"5347929922","pt":1646210713348,"mc":[{"id":"1.195453615","rc":[{"atb":[[12.5,0.88]],"id":39784359}],"con":true,"img":false}]}
{"op":"mcm","clk":"5347929964","pt":1646210714334,"mc":[{"id":"1.195453615","rc":[{"atb":[[12.5,0]],"id":39784359},{"trd":[[12.5,17.67]],"ltp":12.5,"tv":17.67,"id":39784359}],"con":true,"img":false}]}
{"op":"mcm","clk":"5347930597","pt":1646210728855,"mc":[{"id":"1.195453615","rc":[{"atb":[[2.12,0]],"id":28755739}],"con":true,"img":false}]}
{"op":"mcm","clk":"5347930600","pt":1646210728945,"mc":[{"id":"1.195453615","rc":[{"atb":[[2.18,52.27]],"id":28755739}],"con":true,"img":false}]}
{"op":"mcm","clk":"5347931223","pt":1646210743589,"mc":[{"id":"1.195453615","rc":[{"atb":[[2.16,0]],"id":28755739},{"spn":2.11,"spf":1.0,"id":28755739},{"spn":5.3,"spf":"NaN","id":39980001}],"con":true,"img":false}]}
{"op":"mcm","clk":"5347931413","pt":1646210748171,"mc":[{"id":"1.195453615","rc":[{"atb":[[12.5,0.88]],"id":39784359}],"con":true,"img":false}]}
{"op":"mcm","clk":"5347931488","pt":1646210750080,"mc":[{"id":"1.195453615","rc":[{"atb":[[12.5,0]],"id":39784359},{"trd":[[12.5,19.42]],"ltp":12.5,"tv":19.42,"id":39784359}],"con":true,"img":false}]}
{"op":"mcm","clk":"5347931719","pt":1646210755928,"mc":[{"id":"1.195453615","rc":[{"atb":[[2.22,8.28]],"id":28755739}],"con":true,"img":false}]}
{"op":"mcm","clk":"5347931725","pt":1646210756085,"mc":[{"id":"1.195453615","rc":[{"atb":[[2.18,0]],"id":28755739}],"con":true,"img":false}]}
{"op":"mcm","clk":"5347931728","pt":1646210756188,"mc":[{"id":"1.195453615","rc":[{"atb":[[2.12,52.27]],"id":28755739}],"con":true,"img":false}]}
{"op":"mcm","clk":"5347932789","pt":1646210780752,"mc":[{"id":"1.195453615","rc":[{"atb":[[2.22,0]],"id":28755739}],"con":true,"img":false}]}
{"op":"mcm","clk":"5347932932","pt":1646210783543,"mc":[{"id":"1.195453615","rc":[{"atb":[[12.5,0.88]],"id":39784359}],"con":true,"img":false}]}
{"op":"mcm","clk":"5347933347","pt":1646210792249,"mc":[{"id":"1.195453615","rc":[{"atb":[[2.16,8.71]],"id":28755739}],"con":true,"img":false}]}
{"op":"mcm","clk":"5347934052","pt":1646210807754,"mc":[{"id":"1.195453615","rc":[{"spn":2.09,"spf":1.0,"id":28755739},{"atb":[[12.5,0]],"id":39784359},{"trd":[[12.5,21.18]],"ltp":12.5,"tv":21.18,"id":39784359}],"con":true,"img":false}]}
{"op":"mcm","clk":"5347934802","pt":1646210824234,"mc":[{"id":"1.195453615","rc":[{"atb":[[2.12,0]],"id":28755739}],"con":true,"img":false}]}
{"op":"mcm","clk":"5347934807","pt":1646210824334,"mc":[{"id":"1.195453615","rc":[{"atb":[[2.18,52.27]],"id":28755739}],"con":true,"img":false}]}
{"op":"mcm","clk":"5347935505","pt":1646210839928,"mc":[{"id":"1.195453615","rc":[{"atb":[[2.16,0]],"id":28755739}],"con":true,"img":false}]}
{"op":"mcm","clk":"5347935543","pt":1646210840648,"mc":[{"id":"1.195453615","rc":[{"atb":[[12.5,0.88]],"id":39784359}],"con":true,"img":false}]}
{"op":"mcm","clk":"5347936087","pt":1646210852565,"mc":[{"id":"1.195453615","rc":[{"atb":[[2.22,8.28]],"id":28755739}],"con":true,"img":false}]}
{"op":"mcm","clk":"5347936158","pt":1646210853754,"mc":[{"id":"1.195453615","rc":[{"atb":[[12.5,0]],"id":39784359},{"trd":[[12.5,22.94]],"ltp":12.5,"tv":22.94,"id":39784359}],"con":true,"img":false}]}
{"op":"mcm","clk":"5347936281","pt":1646210856066,"mc":[{"id":"1.195453615","rc":[{"atb":[[2.18,0]],"id":28755739}],"con":true,"img":false}]}
{"op":"mcm","clk":"5347936284","pt":1646210856170,"mc":[{"id":"1.195453615","rc":[{"atb":[[2.12,52.27]],"id":28755739}],"con":true,"img":false}]}
{"op":"mcm","clk":"5347937417","pt":1646210876296,"mc":[{"id":"1.195453615","rc":[{"atb":[[2.22,0]],"id":28755739},{"spn":2.09,"spf":1.0,"id":28755739}],"con":true,"img":false}]}
{"op":"mcm","clk":"5347937605","pt":1646210880598,"mc":[{"id":"1.195453615","rc":[{"atb":[[1.03,1.67]],"id":26503913},{"atb":[[1.01,1.67]],"id":28755739},{"atb":[[1.02,1.67]],"id":37456368},{"atb":[[1.04,1.67]],"id":36036864},{"atb":[[1.06,1.67]],"id":39784359},{"atb":[[1.02,1.67]],"id":39980001}],"con":true,"img":false}]}
{"op":"mcm","clk":"5347937611","pt":1646210880812,"mc":[{"id":"1.195453615","rc":[{"atb":[[1.03,0.25]],"id":26503913},{"atb":[[1.01,0.7]],"id":28755739},{"atb":[[1.02,0.42]],"id":37456368},{"atb":[[1.04,0.17]],"id":36036864},{"atb":[[1.06,0.13]],"id":39784359},{"atb":[[1.02,0.42]],"id":39980001}],"con":true,"img":false}]}
{"op":"mcm","clk":"5347937620","pt":1646210881013,"mc":[{"id":"1.195453615","rc":[{"atb":[[1.03,0]],"id":26503913},{"atb":[[1.01,0]],"id":28755739},{"atb":[[1.02,0]],"id":37456368},{"atb":[[1.04,0]],"id":36036864},{"atb":[[1.06,0]],"id":39784359},{"atb":[[1.02,0]],"id":39980001}],"con":true,"img":false}]}
{"op":"mcm","clk":"5347937624","pt":1646210881116,"mc":[{"id":"1.195453615","rc":[{"atb":[[6.4,0.25]],"id":26503913},{"atb":[[2.38,0.7]],"id":28755739},{"atb":[[3.9,0.42]],"id":37456368},{"atb":[[9.4,0.57]],"id":36036864},{"atb":[[12,0.13]],"id":39784359},{"atb":[[3.85,0.42]],"id":39980001}],"con":true,"img":false}]}
{"op":"mcm","clk":"5347937882","pt":1646210886242,"mc":[{"id":"1.195453615","rc":[{"atb":[[12.5,0.88]],"id":39784359}],"con":true,"img":false}]}
{"op":"mcm","clk":"5347938000","pt":1646210888524,"mc":[{"id":"1.195453615","rc":[{"atb":[[2.16,8.71]],"id":28755739}],"con":true,"img":false}]}
{"op":"mcm","clk":"5347939485","pt":1646210918154,"mc":[{"id":"1.195453615","rc":[{"atb":[[12.5,0]],"id":39784359},{"trd":[[12.5,24.7]],"ltp":12.5,"tv":24.7,"id":39784359}],"con":true,"img":false}]}
{"op":"mcm","clk":"5347939516","pt":1646210918670,"mc":[{"id":"1.195453615","rc":[{"atb":[[2.12,0]],"id":28755739}],"con":true,"img":false}]}
{"op":"mcm","clk":"5347939522","pt":1646210918773,"mc":[{"id":"1.195453615","rc":[{"atb":[[2.18,52.27]],"id":28755739}],"con":true,"img":false}]}
{"op":"mcm","clk":"5347940356","pt":1646210934800,"mc":[{"id":"1.195453615","rc":[{"atl":[[17,8.5]],"id":37456368}],"con":true,"img":false}]}
{"op":"mcm","clk":"5347940443","pt":1646210936696,"mc":[{"id":"1.195453615","rc":[{"spn":6.09,"spf":1.0,"id":26503913},{"atb":[[2.16,0]],"id":28755739},{"spn":2.11,"spf":1.0,"id":28755739},{"spn":4.9,"spf":"NaN","id":37456368},{"spn":8.67,"spf":1.0,"id":36036864},{"spn":10.56,"spf":1.0,"id":39784359},{"spn":5.32,"spf":"NaN","id":39980001}],"con":true,"img":false}]}
{"op":"mcm","clk":"5347941012","pt":1646210948051,"mc":[{"id":"1.195453615","rc":[{"atb":[[2.22,8.28]],"id":28755739}],"con":true,"img":false}]}
{"op":"mcm","clk":"5347941113","pt":1646210949941,"mc":[{"id":"1.195453615","rc":[{"atb":[[12.5,0.88]],"id":39784359}],"con":true,"img":false}]}
{"op":"mcm","clk":"5347941135","pt":1646210950401,"mc":[{"id":"1.195453615","rc":[{"atb":[[2.18,0]],"id":28755739}],"con":true,"img":false}]}
{"op":"mcm","clk":"5347941139","pt":1646210950556,"mc":[{"id":"1.195453615","rc":[{"atb":[[2.12,52.27]],"id":28755739}],"con":true,"img":false}]}
{"op":"mcm","clk":"5347941918","pt":1646210966079,"mc":[{"id":"1.195453615","rc":[{"atb":[[12.5,0]],"id":39784359},{"trd":[[12.5,26.46]],"ltp":12.5,"tv":26.46,"id":39784359}],"con":true,"img":false}]}
{"op":"mcm","clk":"5347942256","pt":1646210972243,"mc":[{"id":"1.195453615","rc":[{"atb":[[2.22,0]],"id":28755739}],"con":true,"img":false}]}
{"op":"mcm","clk":"5347947717","pt":1646211074819,"mc":[{"id":"1.195453615","rc":[{"atb":[[2.16,8.71]],"id":28755739},{"spn":2.1,"spf":1.0,"id":28755739}],"con":true,"img":false}]}
{"op":"mcm","clk":"5347949134","pt":1646211100075,"mc":[{"id":"1.195453615","rc":[{"atb":[[3.85,0],[3.35,42.55]],"id":26503913},{"atb":[[2.82,0],[2.98,44.5]],"id":37456368},{"atb":[[4.9,0],[4.2,53.12]],"id":39784359},{"atb":[[2.54,0],[2.66,60.24]],"id":39980001}],"con":true,"img":false}]}
{"op":"mcm","clk":"5347949529","pt":1646211108695,"mc":[{"id":"1.195453615","rc":[{"atb":[[2.12,0]],"id":28755739}],"con":true,"img":false}]}
{"op":"mcm","clk":"5347949534","pt":1646211108799,"mc":[{"id":"1.195453615","rc":[{"atb":[[2.18,52.27]],"id":28755739}],"con":true,"img":false}]}
{"op":"mcm","clk":"5347950362","pt":1646211126004,"mc":[{"id":"1.195453615","rc":[{"atb":[[3.35,0],[4.1,29.39]],"id":26503913},{"atb":[[5.4,22.73],[4.2,26.56]],"id":39784359}],"con":true,"img":false}]}
{"op":"mcm","clk":"5347950385","pt":1646211126509,"mc":[{"id":"1.195453615","rc":[{"atb":[[2.16,0]],"id":28755739}],"con":true,"img":false}]}
{"op":"mcm","clk":"5347950904","pt":1646211137649,"mc":[{"id":"1.195453615","rc":[{"atb":[[2.18,0]],"id":28755739},{"spn":2.06,"spf":1.0,"id":28755739}],"con":true,"img":false}]}
{"op":"mcm","clk":"5347950909","pt":1646211137700,"mc":[{"id":"1.195453615","rc":[{"atb":[[2.12,52.27]],"id":28755739}],"con":true,"img":false}]}
{"op":"mcm","clk":"5347950927","pt":1646211138007,"mc":[{"id":"1.195453615","rc":[{"atb":[[2.22,8.28]],"id":28755739}],"con":true,"img":false}]}
{"op":"mcm","clk":"5347955858","pt":1646211243283,"mc":[{"id":"1.195453615","rc":[{"spn":2.1,"spf":1.0,"id":28755739},{"atb":[[2.82,54.95],[2.98,0]],"id":37456368},{"atb":[[2.54,64.94],[2.66,0]],"id":39980001}],"con":true,"img":false}]}
{"op":"mcm","clk":"5347960059","pt":1646211327477,"mc":[{"id":"1.195453615","rc":[{"atb":[[2.22,0]],"id":28755739},{"spn":2.09,"spf":1.0,"id":28755739}],"con":true,"img":false}]}
{"op":"mcm","clk":"5347960072","pt":1646211327791,"mc":[{"id":"1.195453615","rc":[{"atb":[[1.01,0]],"id":39784359}],"con":true,"img":false}]}
{"op":"mcm","clk":"5347960076","pt":1646211327894,"mc":[{"id":"1.195453615","rc":[{"atb":[[12,1.8]],"id":39784359}],"con":true,"img":false}]}
{"op":"mcm","clk":"5347960735","pt":1646211342304,"mc":[{"id":"1.195453615","rc":[{"atb":[[2.16,8.71]],"id":28755739}],"con":true,"img":false}]}
{"op":"mcm","clk":"5347962018","pt":1646211372239,"mc":[{"id":"1.195453615","rc":[{"atb":[[2.12,0]],"id":28755739}],"con":true,"img":false}]}
{"op":"mcm","clk":"5347962024","pt":1646211372341,"mc":[{"id":"1.195453615","rc":[{"atb":[[2.18,52.27]],"id":28755739}],"con":true,"img":false}]}
{"op":"mcm","clk":"5347963205","pt":1646211397287,"mc":[{"id":"1.195453615","rc":[{"atb":[[2.16,0]],"id":28755739},{"spn":2.11,"spf":1.0,"id":28755739},{"spn":10.86,"spf":1.0,"id":39784359}],"con":true,"img":false}]}
{"op":"mcm","clk":"5347963731","pt":1646211408020,"mc":[{"id":"1.195453615","rc":[{"atb":[[2.18,0]],"id":28755739}],"con":true,"img":false}]}
{"op":"mcm","clk":"5347963738","pt":1646211408123,"mc":[{"id":"1.195453615","rc":[{"atb":[[2.12,52.27]],"id":28755739}],"con":true,"img":false}]}
{"op":"mcm","clk":"5347963940","pt":1646211411995,"mc":[{"id":"1.195453615","rc":[{"atl":[[11,48.03]],"id":28755739}],"con":true,"img":false}]}
{"op":"mcm","clk":"5347964615","pt":1646211423898,"mc":[{"id":"1.195453615","rc":[{"atb":[[2.16,8.71]],"id":28755739}],"con":true,"img":false}]}
{"op":"mcm","clk":"5347966235","pt":1646211455733,"mc":[{"id":"1.195453615","rc":[{"atb":[[2.12,0]],"id":28755739}],"con":true,"img":false}]}
{"op":"mcm","clk":"5347966240","pt":1646211455840,"mc":[{"id":"1.195453615","rc":[{"atb":[[2.18,52.27]],"id":28755739}],"con":true,"img":false}]}
{"op":"mcm","clk":"5347966892","pt":1646211472168,"mc":[{"id":"1.195453615","rc":[{"atb":[[2.16,0]],"id":28755739}],"con":true,"img":false}]}
{"op":"mcm","clk":"5347967278","pt":1646211481584,"mc":[{"id":"1.195453615","rc":[{"atb":[[2.18,0]],"id":28755739}],"con":true,"img":false}]}
{"op":"mcm","clk":"5347967284","pt":1646211481681,"mc":[{"id":"1.195453615","rc":[{"atb":[[2.12,52.27]],"id":28755739}],"con":true,"img":false}]}
{"op":"mcm","clk":"5347967864","pt":1646211496229,"mc":[{"id":"1.195453615","rc":[{"atb":[[2.16,8.71]],"id":28755739}],"con":true,"img":false}]}
{"op":"mcm","clk":"5347968980","pt":1646211525476,"mc":[{"id":"1.195453615","rc":[{"atb":[[2.12,0]],"id":28755739}],"con":true,"img":false}]}
{"op":"mcm","clk":"5347968983","pt":1646211525577,"mc":[{"id":"1.195453615","rc":[{"atb":[[2.18,52.27]],"id":28755739}],"con":true,"img":false}]}
{"op":"mcm","clk":"5347969812","pt":1646211547293,"mc":[{"id":"1.195453615","rc":[{"atb":[[2.16,0]],"id":28755739}],"con":true,"img":false}]}
{"op":"mcm","clk":"5347970210","pt":1646211556799,"mc":[{"id":"1.195453615","rc":[{"atb":[[2.18,0]],"id":28755739}],"con":true,"img":false}]}
{"op":"mcm","clk":"5347970215","pt":1646211556895,"mc":[{"id":"1.195453615","rc":[{"atb":[[2.12,52.27]],"id":28755739}],"con":true,"img":false}]}
{"op":"mcm","clk":"5347970823","pt":1646211571425,"mc":[{"id":"1.195453615","rc":[{"atb":[[2.16,8.71]],"id":28755739}],"con":true,"img":false}]}
{"op":"mcm","clk":"5347972344","pt":1646211603310,"mc":[{"id":"1.195453615","rc":[{"atb":[[4.8,10.75],[4.3,24.76],[6.4,0.25],[5.8,8.51],[5.9,25.61],[6.2,1.44],[6,14.84],[3.9,28.18],[3.65,61.69]],"id":26503913},{"atl":[[18.5,7.08],[36,5.7],[19,7.4],[23,6.05],[28,7.4],[14.5,1.46],[15,1.08],[15.5,4.03],[1000,2.67]],"id":26503913},{"trd":[[6.6,9.33]],"ltp":6.6,"tv":9.33,"id":26503913},{"atb":[[2,81.74],[2.32,6.98],[2.3,4.2],[2.12,0],[1.95,86.04],[2.1,37.15],[2.36,1.65],[2.02,118.88],[2.38,0.7],[1.9,181.66],[2.16,8.69]],"id":28755739},{"spl":[[1.01,166.76]],"id":28755739},{"atl":[[5.6,28.95],[7.2,32.22],[4.6,30.31],[6.2,25.61],[8.2,27.75],[11,47.95],[3,4.93],[3.5,46.8]],"id":28755739},{"trd":[[2.38,11.02],[2.3,54.46],[2.34,11.21]],"ltp":2.38,"tv":76.69,"id":28755739},{"atb":[[3.6,9.78],[2.74,46.98],[3.35,17.39],[3.4,44.5],[2.64,99.69],[3.55,22.92],[2.84,44.42],[3.9,0.42],[2.94,21.06],[3.75,1.65]],"id":37456368},{"atl":[[12,18.16],[5.9,2.6],[14.5,14.8],[8.6,14.05],[6,87.19],[9.8,15.13],[8.8,17.07],[7,9.74]],"id":37456368},{"atb":[[4,78.49],[7.2,19.73],[8.6,1.49],[4.5,23.35],[5,20.43],[5.5,9.08],[7,6.81],[8.4,7.89],[9.4,0.57]],"id":36036864},{"spl":[[1.01,6.72]],"id":36036864},{"atl":[[70,11.09],[38,3.6],[22,2.78],[48,4.25],[28,4.52],[29,4.75]],"id":36036864},{"atb":[[8,11.67],[9,5.11],[11.5,5.31],[12,1.8],[6,32.69],[9.8,14.72],[7,13.62]],"id":39784359},{"spl":[[1.01,12.17]],"id":39784359},{"atl":[[32,1.49],[34,2.72],[150,15.09],[50,2.72],[100,1.34],[200,1],[990,2.65],[250,0.8]],"id":39784359},{"trd":[[12.5,26.43],[13,3.35],[14,1.55]],"ltp":12.5,"tv":31.33,"id":39784359},{"atb":[[2.82,44.91],[3.6,22.48],[2.72,95.05],[3.85,0.42],[3.1,55.14],[3.8,1.65],[3.55,16.02],[3.05,19.94],[2.92,42.57],[3.7,1.5],[3.65,7.93]],"id":39980001},{"atl":[[17,12.48],[8.6,13.46],[6.8,2.74],[12,12.1],[9.8,15.13],[7,9.74],[14.5,14.8]],"id":39980001}],"con":true,"img":false}]}
{"op":"mcm","clk":"5347972350","pt":1646211603413,"mc":[{"id":"1.195453615","rc":[{"atb":[[2.18,52.18]],"id":28755739}],"con":true,"img":false}]}
{"op":"mcm","clk":"5347972356","pt":1646211603518,"mc":[{"id":"1.195453615","rc":[{"atb":[[9.4,0.17],[1.02,2.25]],"id":36036864}],"con":true,"img":false}]}
{"op":"mcm","clk":"5347972369","pt":1646211603674,"mc":[{"id":"1.195453615","rc":[{"atb":[[1.02,0.39]],"id":36036864}],"con":true,"img":false}]}
{"op":"mcm","clk":"5347972378","pt":1646211603883,"mc":[{"id":"1.195453615","rc":[{"atb":[[1.02,0]],"id":36036864}],"con":true,"img":false}]}
{"op":"mcm","clk":"5347972387","pt":1646211603990,"mc":[{"id":"1.195453615","rc":[{"atb":[[8.8,0.39]],"id":36036864}],"con":true,"img":false}]}
{"op":"mcm","clk":"5347973432","pt":1646211622434,"mc":[{"id":"1.195453615","rc":[{"spn":6.09,"spf":1.0,"id":26503913},{"atb":[[2.16,0]],"id":28755739},{"spn":8.64,"spf":1.0,"id":36036864},{"spn":10.86,"spf":1.0,"id":39784359}],"con":true,"img":false}]}
{"op":"mcm","clk":"5347973976","pt":1646211633741,"mc":[{"id":"1.195453615","rc":[{"atb":[[2.22,8.26]],"id":28755739}],"con":true,"img":false}]}
{"op":"mcm","clk":"5347974026","pt":1646211634565,"mc":[{"id":"1.195453615","rc":[{"atb":[[2.18,0]],"id":28755739}],"con":true,"img":false}]}
{"op":"mcm","clk":"5347974032","pt":1646211634668,"mc":[{"id":"1.195453615","rc":[{"atb":[[2.12,52.18]],"id":28755739}],"con":true,"img":false}]}
{"op":"mcm","clk":"5347975133","pt":1646211657553,"mc":[{"id":"1.195453615","rc":[{"atb":[[2.22,0]],"id":28755739}],"con":true,"img":false}]}
{"op":"mcm","clk":"5347975794","pt":1646211669880,"mc":[{"id":"1.195453615","rc":[{"atb":[[2.16,8.69]],"id":28755739}],"con":true,"img":false}]}
{"op":"mcm","clk":"5347976742","pt":1646211686219,"mc":[{"id":"1.195453615","rc":[{"spn":2.1,"spf":1.0,"id":28755739},{"atb":[[1.02,2.25],[8.8,0]],"id":36036864},{"spn":8.61,"spf":1.0,"id":36036864}],"con":true,"img":false}]}
{"op":"mcm","clk":"5347976753","pt":1646211686425,"mc":[{"id":"1.195453615","rc":[{"atb":[[1.02,0.39]],"id":36036864}],"con":true,"img":false}]}
{"op":"mcm","clk":"5347976765","pt":1646211686529,"mc":[{"id":"1.195453615","rc":[{"atb":[[1.02,0]],"id":36036864}],"con":true,"img":false}]}
{"op":"mcm","clk":"5347976770","pt":1646211686633,"mc":[{"id":"1.195453615","rc":[{"atb":[[9.6,0.39]],"id":36036864}],"con":true,"img":false}]}
{"op":"mcm","clk":"5347977533","pt":1646211702076,"mc":[{"id":"1.195453615","rc":[{"atb":[[2.12,0]],"id":28755739}],"con":true,"img":false}]}
{"op":"mcm","clk":"5347977538","pt":1646211702179,"mc":[{"id":"1.195453615","rc":[{"atb":[[2.18,52.18]],"id":28755739}],"con":true,"img":false}]}
{"op":"mcm","clk":"5347978404","pt":1646211721307,"mc":[{"id":"1.195453615","rc":[{"atb":[[2.16,0]],"id":28755739}],"con":true,"img":false}]}
{"op":"mcm","clk":"5347978928","pt":1646211733095,"mc":[{"id":"1.195453615","rc":[{"atb":[[2.22,8.26]],"id":28755739}],"con":true,"img":false}]}
{"op":"mcm","clk":"5347979024","pt":1646211735823,"mc":[{"id":"1.195453615","rc":[{"atb":[[2.18,0]],"id":28755739}],"con":true,"img":false}]}
{"op":"mcm","clk":"5347979028","pt":1646211735928,"mc":[{"id":"1.195453615","rc":[{"atb":[[2.12,52.18]],"id":28755739}],"con":true,"img":false}]}
{"op":"mcm","clk":"5347979843","pt":1646211757151,"mc":[{"id":"1.195453615","rc":[{"atb":[[2.22,0]],"id":28755739},{"spn":2.09,"spf":1.0,"id":28755739},{"spn":8.68,"spf":1.0,"id":36036864}],"con":true,"img":false}]}
{"op":"mcm","clk":"5347980375","pt":1646211769181,"mc":[{"id":"1.195453615","rc":[{"atb":[[2.16,8.69]],"id":28755739}],"con":true,"img":false}]}
{"op":"mcm","clk":"5347981004","pt":1646211781941,"mc":[{"id":"1.195453615","rc":[{"atb":[[3.85,0]],"id":37456368}],"con":true,"img":false}]}
{"op":"mcm","clk":"5347981010","pt":1646211782005,"mc":[{"id":"1.195453615","rc":[{"atb":[[3.9,2.42]],"id":37456368}],"con":true,"img":false}]}
{"op":"mcm","clk":"5347981049","pt":1646211782731,"mc":[{"id":"1.195453615","rc":[{"atl":[[2.98,5.44]],"id":28755739}],"con":true,"img":false}]}
{"op":"mcm","clk":"5347981068","pt":1646211783139,"mc":[{"id":"1.195453615","rc":[{"atb":[[5.8,18.61],[5.4,27.53],[5.6,15.8],[6,18.72]],"id":26503913},{"atl":[[23,7.05],[25,2.08],[27,2.88],[29,4.46]],"id":26503913},{"atb":[[1.84,148.81],[1.88,56.82],[1.9,203.88],[1.86,87.21]],"id":28755739},{"atl":[[2.98,68.57],[2.94,38.66],[2.86,10.75],[2.9,26.32]],"id":28755739},{"atb":[[2.82,0],[3.35,70.58],[3.55,42.53],[3.45,30.61],[2.96,44.43],[3.65,7.55]],"id":37456368},{"atl":[[11,2],[12,22.71],[13,6.25],[14,17.31]],"id":37456368},{"atb":[[2.84,67.93],[2.92,26.04],[2.88,39.89],[2.96,10.2]],"id":36036864},{"atl":[[18,1.18],[19,2.78],[20,3.95],[22,8.73]],"id":36036864},{"atb":[[7.4,4.7],[7.8,1.77],[7,21.14],[6.6,26.28]],"id":39784359},{"atl":[[32,2.49],[36,1.43],[40,1.92],[44,2.91]],"id":39784359},{"atb":[[2.54,0],[2.64,60.98],[3.5,8],[3.3,32.61],[3.2,56.82],[3.4,20.83]],"id":39980001},{"atl":[[10,5.56],[11,7.5],[12,23.46],[9.6,2.33]],"id":39980001}],"con":true,"img":false}]}
{"op":"mcm","clk":"5347981093","pt":1646211783616,"mc":[{"id":"1.195453615","rc":[{"atb":[[6,16.72]],"id":26503913},{"atb":[[2.32,5.6]],"id":28755739},{"atb":[[3.6,8.43]],"id":37456368}],"con":true,"img":false}]}
{"op":"mcm","clk":"5347981096","pt":1646211783712,"mc":[{"id":"1.195453615","rc":[{"atb":[[6.2,3.37]],"id":26503913},{"atb":[[1.01,1.37]],"id":28755739},{"atb":[[3.7,1.34]],"id":37456368}],"con":true,"img":false}]}
{"op":"mcm","clk":"5347981109","pt":1646211784023,"mc":[{"id":"1.195453615","rc":[{"atl":[[2.84,6.53]],"id":28755739}],"con":true,"img":false}]}
{"op":"mcm","clk":"5347981132","pt":1646211784527,"mc":[{"id":"1.195453615","rc":[{"atb":[[6.4,2.75]],"id":26503913},{"atb":[[3.95,2.5]],"id":37456368},{"atb":[[9.4,2.67]],"id":36036864},{"atb":[[12.5,2.08]],"id":39784359},{"atb":[[3.85,2.92]],"id":39980001}],"con":true,"img":false}]}
{"op":"mcm","clk":"5347981155","pt":1646211784950,"mc":[{"id":"1.195453615","rc":[{"atb":[[3.6,6.77]],"id":37456368}],"con":true,"img":false}]}
{"op":"mcm","clk":"5347981162","pt":1646211785043,"mc":[{"id":"1.195453615","rc":[{"atb":[[3.95,4.15]],"id":37456368}],"con":true,"img":false}]}
{"op":"mcm","clk":"5347981293","pt":1646211787337,"mc":[{"id":"1.195453615","rc":[{"atb":[[1.88,93.18],[2.46,49.32]],"id":37456368}],"con":true,"img":false}]}
{"op":"mcm","clk":"5347981397","pt":1646211789248,"mc":[{"id":"1.195453615","rc":[{"atb":[[4.1,0],[4.7,27.03]],"id":26503913},{"atl":[[14,1.54],[23,6.05]],"id":26503913},{"atb":[[2,101.74],[1.9,181.66]],"id":28755739},{"atl":[[11,0],[12,18.16],[12.5,1.74]],"id":37456368},{"atb":[[2.86,10.75],[2.96,0]],"id":36036864},{"atb":[[7.8,0],[8.8,1.54]],"id":39784359},{"atl":[[10,0],[11,12],[9.6,0],[8.8,0]],"id":39980001}],"con":true,"img":false}]}
{"op":"mcm","clk":"5347981426","pt":1646211790163,"mc":[{"id":"1.195453615","rc":[{"atl":[[14.5,0]],"id":26503913}],"con":true,"img":false}]}
{"op":"mcm","clk":"5347981430","pt":1646211790238,"mc":[{"id":"1.195453615","rc":[{"atl":[[13.5,1.46]],"id":26503913}],"con":true,"img":false}]}
{"op":"mcm","clk":"5347981454","pt":1646211790644,"mc":[{"id":"1.195453615","rc":[{"atb":[[2.12,0]],"id":28755739}],"con":true,"img":false}]}
{"op":"mcm","clk":"5347981461","pt":1646211790747,"mc":[{"id":"1.195453615","rc":[{"atb":[[2.18,52.18]],"id":28755739}],"con":true,"img":false}]}
{"op":"mcm","clk":"5347981736","pt":1646211795135,"mc":[{"id":"1.195453615","rc":[{"atl":[[2.98,63.13]],"id":28755739}],"con":true,"img":false}]}
{"op":"mcm","clk":"5347981747","pt":1646211795447,"mc":[{"id":"1.195453615","rc":[{"atl":[[2.82,5.44]],"id":28755739}],"con":true,"img":false}]}
{"op":"mcm","clk":"5347981792","pt":1646211796438,"mc":[{"id":"1.195453615","rc":[{"atl":[[2.84,0]],"id":28755739}],"con":true,"img":false}]}
{"op":"mcm","clk":"5347981859","pt":1646211797430,"mc":[{"id":"1.195453615","rc":[{"atl":[[2.8,6.53]],"id":28755739}],"con":true,"img":false}]}
{"op":"mcm","clk":"5347981965","pt":1646211799235,"mc":[{"id":"1.195453615","rc":[{"atl":[[15,4.65]],"id":26503913},{"atb":[[1.98,51.02]],"id":28755739},{"atl":[[13.5,4]],"id":37456368},{"atb":[[2.82,27.47],[2.92,0]],"id":36036864},{"atb":[[8.4,4.06]],"id":39784359},{"atl":[[12,16.65]],"id":39980001}],"con":true,"img":false}]}
{"op":"mcm","clk":"5347981981","pt":1646211799547,"mc":[{"id":"1.195453615","rc":[{"atl":[[1000,0]],"id":26503913}],"con":true,"img":false}]}
{"op":"mcm","clk":"5347981988","pt":1646211799654,"mc":[{"id":"1.195453615","rc":[{"atl":[[14.5,2.67]],"id":26503913}],"con":true,"img":false}]}
{"op":"mcm","clk":"5347982073","pt":1646211801251,"mc":[{"id":"1.195453615","rc":[{"atl":[[15,3.57]],"id":26503913}],"con":true,"img":false}]}
{"op":"mcm","clk":"5347982077","pt":1646211801352,"mc":[{"id":"1.195453615","rc":[{"atl":[[14.5,3.75]],"id":26503913}],"con":true,"img":false}]}
{"op":"mcm","clk":"5347982135","pt":1646211802241,"mc":[{"id":"1.195453615","rc":[{"atb":[[2.76,56.82]],"id":39980001}],"con":true,"img":false}]}
{"op":"mcm","clk":"5347982144","pt":1646211802336,"mc":[{"id":"1.195453615","rc":[{"atb":[[2.64,0]],"id":39980001}],"con":true,"img":false}]}
{"op":"mcm","clk":"5347982203","pt":1646211803563,"mc":[{"id":"1.195453615","rc":[{"atb":[[6.4,0]],"id":26503913},{"trd":[[6.4,5.51]],"ltp":6.4,"tv":5.51,"id":26503913},{"atb":[[12.5,1.78]],"id":39784359},{"trd":[[12.5,27.03]],"ltp":12.5,"tv":27.03,"id":39784359}],"con":true,"img":false}]}
{"op":"mcm","clk":"5347982247","pt":1646211804755,"mc":[{"id":"1.195453615","rc":[{"atb":[[5.9,0]],"id":26503913}],"con":true,"img":false}]}
{"op":"mcm","clk":"5347982251","pt":1646211804865,"mc":[{"id":"1.195453615","rc":[{"atb":[[5.7,25.61]],"id":26503913}],"con":true,"img":false}]}
{"op":"mcm","clk":"5347982274","pt":1646211805270,"mc":[{"id":"1.195453615","rc":[{"atb":[[6,14.7]],"id":26503913},{"atb":[[2.16,0]],"id":28755739}],"con":true,"img":false}]}
{"op":"mcm","clk":"5347982284","pt":1646211805474,"mc":[{"id":"1.195453615","rc":[{"atb":[[3.9,2]],"id":37456368},{"atb":[[12,1.66]],"id":39784359}],"con":true,"img":false}]}
{"op":"mcm","clk":"5347982290","pt":1646211805578,"mc":[{"id":"1.195453615","rc":[{"atb":[[4,0.42]],"id":37456368},{"atb":[[13,0.13]],"id":39784359}],"con":true,"img":false}]}
{"op":"mcm","clk":"5347982331","pt":1646211806561,"mc":[{"id":"1.195453615","rc":[{"atb":[[3.95,2.5]],"id":37456368}],"con":true,"img":false}]}
{"op":"mcm","clk":"5347982335","pt":1646211806661,"mc":[{"id":"1.195453615","rc":[{"atl":[[3.5,23.42]],"id":28755739},{"atb":[[1.01,1.65]],"id":37456368}],"con":true,"img":false}]}
{"op":"mcm","clk":"5347982343","pt":1646211806766,"mc":[{"id":"1.195453615","rc":[{"atl":[[3.45,23.38]],"id":28755739}],"con":true,"img":false}]}
{"op":"mcm","clk":"5347982395","pt":1646211807554,"mc":[{"id":"1.195453615","rc":[{"atl":[[2.82,0]],"id":28755739}],"con":true,"img":false}]}
{"op":"mcm","clk":"5347982423","pt":1646211807972,"mc":[{"id":"1.195453615","rc":[{"atl":[[2.78,5.44]],"id":28755739}],"con":true,"img":false}]}
{"op":"mcm","clk":"5347982483","pt":1646211809252,"mc":[{"id":"1.195453615","rc":[{"atl":[[16,5],[25,0],[27,0],[29,0]],"id":26503913},{"atb":[[1.84,0],[1.96,78.12]],"id":28755739},{"atl":[[14.5,20.36]],"id":37456368},{"atb":[[2.88,0],[2.78,88.43]],"id":36036864},{"atb":[[8,18.11],[7.4,0],[7,13.62],[6.6,12.86]],"id":39784359},{"atl":[[13,6.25]],"id":39980001}],"con":true,"img":false}]}
{"op":"mcm","clk":"5347982525","pt":1646211809979,"mc":[{"id":"1.195453615","rc":[{"atl":[[2.8,0]],"id":28755739}],"con":true,"img":false}]}
{"op":"mcm","clk":"5347982574","pt":1646211810755,"mc":[{"id":"1.195453615","rc":[{"atl":[[2.76,6.53]],"id":28755739}],"con":true,"img":false}]}
{"op":"mcm","clk":"5347982662","pt":1646211812458,"mc":[{"id":"1.195453615","rc":[{"atb":[[2.32,0]],"id":28755739}],"con":true,"img":false}]}
{"op":"mcm","clk":"5347982672","pt":1646211812663,"mc":[{"id":"1.195453615","rc":[{"atb":[[2.18,0]],"id":28755739}],"con":true,"img":false}]}
{"op":"mcm","clk":"5347982679","pt":1646211812765,"mc":[{"id":"1.195453615","rc":[{"atb":[[2.12,52.18]],"id":28755739}],"con":true,"img":false}]}
{"op":"mcm","clk":"5347982848","pt":1646211815498,"mc":[{"id":"1.195453615","rc":[{"atb":[[2.36,0],[1.04,1.66]],"id":28755739}],"con":true,"img":false}]}
{"op":"mcm","clk":"5347982857","pt":1646211815704,"mc":[{"id":"1.195453615","rc":[{"atb":[[1.04,1.65]],"id":28755739}],"con":true,"img":false}]}
{"op":"mcm","clk":"5347982865","pt":1646211815863,"mc":[{"id":"1.195453615","rc":[{"atb":[[1.04,0]],"id":28755739}],"con":true,"img":false}]}
{"op":"mcm","clk":"5347982872","pt":1646211815966,"mc":[{"id":"1.195453615","rc":[{"atb":[[2.18,1.65]],"id":28755739}],"con":true,"img":false}]}
{"op":"mcm","clk":"5347982942","pt":1646211817310,"mc":[{"id":"1.195453615","rc":[{"atb":[[6.2,5.3]],"id":26503913},{"spn":6.2,"spf":1.0,"id":26503913},{"spn":2.07,"spf":1.0,"id":28755739},{"spn":4.95,"spf":"NaN","id":37456368},{"spn":9.05,"spf":1.0,"id":36036864},{"spn":11.27,"spf":1.0,"id":39784359}],"con":true,"img":false}]}
{"op":"mcm","clk":"5347983045","pt":1646211819271,"mc":[{"id":"1.195453615","rc":[{"atl":[[17,7.81]],"id":26503913},{"atb":[[1.94,132.98],[1.86,0]],"id":28755739},{"atl":[[13,0],[14,7.69],[15.5,16.81]],"id":37456368},{"atb":[[2.74,71.84]],"id":36036864},{"atb":[[7.6,11.39]],"id":39784359},{"atl":[[14,9.62]],"id":39980001}],"con":true,"img":false}]}
{"op":"mcm","clk":"5347983086","pt":1646211820194,"mc":[{"id":"1.195453615","rc":[{"atl":[[2.78,0]],"id":28755739}],"con":true,"img":false}]}
{"op":"mcm","clk":"5347983118","pt":1646211820710,"mc":[{"id":"1.195453615","rc":[{"atl":[[34,0]],"id":39784359}],"con":true,"img":false}]}
{"op":"mcm","clk":"5347983124","pt":1646211820815,"mc":[{"id":"1.195453615","rc":[{"atl":[[32,5.21]],"id":39784359}],"con":true,"img":false}]}
{"op":"mcm","clk":"5347983195","pt":1646211822212,"mc":[{"id":"1.195453615","rc":[{"atl":[[2.74,5.44]],"id":28755739}],"con":true,"img":false}]}
{"op":"mcm","clk":"5347983221","pt":1646211822629,"mc":[{"id":"1.195453615","rc":[{"atb":[[3.4,0]],"id":37456368}],"con":true,"img":false}]}
{"op":"mcm","clk":"5347983230","pt":1646211822687,"mc":[{"id":"1.195453615","rc":[{"atb":[[3.5,44.5]],"id":37456368}],"con":true,"img":false}]}
{"op":"mcm","clk":"5347983252","pt":1646211823198,"mc":[{"id":"1.195453615","rc":[{"atl":[[2.76,0]],"id":28755739}],"con":true,"img":false}]}
{"op":"mcm","clk":"5347983269","pt":1646211823507,"mc":[{"id":"1.195453615","rc":[{"atl":[[2.74,0]],"id":28755739},{"trd":[[2.74,10.89]],"ltp":2.74,"tv":10.89,"id":28755739}],"con":true,"img":false}]}
{"op":"mcm","clk":"5347983293","pt":1646211823922,"mc":[{"id":"1.195453615","rc":[{"atl":[[2.72,6.53]],"id":28755739}],"con":true,"img":false}]}
{"op":"mcm","clk":"5347983330","pt":1646211824598,"mc":[{"id":"1.195453615","rc":[{"atl":[[15.5,0]],"id":26503913},{"atl":[[50,0]],"id":39784359}],"con":true,"img":false}]}
{"op":"mcm","clk":"5347983336","pt":1646211824699,"mc":[{"id":"1.195453615","rc":[{"atl":[[14,5.57]],"id":26503913},{"atl":[[38,2.72]],"id":39784359}],"con":true,"img":false}]}
{"op":"mcm","clk":"5347983340","pt":1646211824799,"mc":[{"id":"1.195453615","rc":[{"atb":[[2.38,0]],"id":28755739}],"con":true,"img":false}]}
{"op":"mcm","clk":"5347983345","pt":1646211824901,"mc":[{"id":"1.195453615","rc":[{"atb":[[2.32,0.7]],"id":28755739}],"con":true,"img":false}]}
{"op":"mcm","clk":"5347983355","pt":1646211825106,"mc":[{"id":"1.195453615","rc":[{"atl":[[14.5,2.67]],"id":26503913}],"con":true,"img":false}]}
{"op":"mcm","clk":"5347983360","pt":1646211825210,"mc":[{"id":"1.195453615","rc":[{"atl":[[13.5,2.55]],"id":26503913}],"con":true,"img":false}]}
{"op":"mcm","clk":"5347983428","pt":1646211826602,"mc":[{"id":"1.195453615","rc":[{"atb":[[3.1,0]],"id":39980001}],"con":true,"img":false}]}
{"op":"mcm","clk":"5347983432","pt":1646211826701,"mc":[{"id":"1.195453615","rc":[{"atb":[[3.45,55.14]],"id":39980001}],"con":true,"img":false}]}
{"op":"mcm","clk":"5347983579","pt":1646211829332,"mc":[{"id":"1.195453615","rc":[{"atb":[[1.88,0]],"id":28755739},{"atb":[[2.84,0]],"id":36036864}],"con":true,"img":false}]}
{"op":"mcm","clk":"5347983593","pt":1646211829495,"mc":[{"id":"1.195453615","rc":[{"atb":[[2.16,8.69]],"id":28755739}],"con":true,"img":false}]}
{"op":"mcm","clk":"5347983613","pt":1646211829855,"mc":[{"id":"1.195453615","rc":[{"atl":[[14.5,0]],"id":26503913}],"con":true,"img":false}]}
{"op":"mcm","clk":"5347983622","pt":1646211829912,"mc":[{"id":"1.195453615","rc":[{"atl":[[13,2.67]],"id":26503913}],"con":true,"img":false}]}
{"op":"mcm","clk":"5347983656","pt":1646211830529,"mc":[{"id":"1.195453615","rc":[{"atl":[[13.5,1.46]],"id":26503913},{"atb":[[2.16,15.17]],"id":28755739}],"con":true,"img":false}]}
{"op":"mcm","clk":"5347983665","pt":1646211830634,"mc":[{"id":"1.195453615","rc":[{"atl":[[13,3.75]],"id":26503913}],"con":true,"img":false}]}
{"op":"mcm","clk":"5347983676","pt":1646211830840,"mc":[{"id":"1.195453615","rc":[{"atl":[[13.5,0]],"id":26503913}],"con":true,"img":false}]}
{"op":"mcm","clk":"5347983683","pt":1646211830895,"mc":[{"id":"1.195453615","rc":[{"atl":[[12.5,1.46],[13,1.08]],"id":26503913}],"con":true,"img":false}]}
{"op":"mcm","clk":"5347983693","pt":1646211831000,"mc":[{"id":"1.195453615","rc":[{"atl":[[13.5,2.67]],"id":26503913}],"con":true,"img":false}]}
{"op":"mcm","clk":"5347983716","pt":1646211831309,"mc":[{"id":"1.195453615","rc":[{"atl":[[13,0]],"id":26503913}],"con":true,"img":false}]}
{"op":"mcm","clk":"5347983725","pt":1646211831408,"mc":[{"id":"1.195453615","rc":[{"atl":[[13.5,3.75]],"id":26503913}],"con":true,"img":false}]}
{"op":"mcm","clk":"5347983815","pt":1646211832715,"mc":[{"id":"1.195453615","rc":[{"atb":[[2.32,6.15]],"id":28755739}],"con":true,"img":false}]}
{"op":"mcm","clk":"5347983998","pt":1646211835640,"mc":[{"id":"1.195453615","rc":[{"atb":[[2.18,0],[1.04,1.66]],"id":28755739}],"con":true,"img":false}]}
{"op":"mcm","clk":"5347984007","pt":1646211835798,"mc":[{"id":"1.195453615","rc":[{"atb":[[1.04,1.65]],"id":28755739}],"con":true,"img":false}]}
{"op":"mcm","clk":"5347984016","pt":1646211836003,"mc":[{"id":"1.195453615","rc":[{"atb":[[1.04,0]],"id":28755739}],"con":true,"img":false}]}
{"op":"mcm","clk":"5347984020","pt":1646211836106,"mc":[{"id":"1.195453615","rc":[{"atb":[[2.36,1.65]],"id":28755739}],"con":true,"img":false}]}
{"op":"mcm","clk":"5347984035","pt":1646211836413,"mc":[{"id":"1.195453615","rc":[{"atl":[[2.72,0]],"id":28755739}],"con":true,"img":false}]}
{"op":"mcm","clk":"5347984071","pt":1646211837233,"mc":[{"id":"1.195453615","rc":[{"atl":[[2.84,6.53]],"id":28755739}],"con":true,"img":false}]}
{"op":"mcm","clk":"5347984141","pt":1646211838734,"mc":[{"id":"1.195453615","rc":[{"atl":[[14,1.54]],"id":26503913}],"con":true,"img":false}]}
{"op":"mcm","clk":"5347984148","pt":1646211838829,"mc":[{"id":"1.195453615","rc":[{"atl":[[15.5,4.03]],"id":26503913}],"con":true,"img":false}]}
{"op":"mcm","clk":"5347984152","pt":1646211838933,"mc":[{"id":"1.195453615","rc":[{"atl":[[13.5,2.67]],"id":26503913}],"con":true,"img":false}]}
{"op":"mcm","clk":"5347984157","pt":1646211839035,"mc":[{"id":"1.195453615","rc":[{"atl":[[990,1.08]],"id":26503913}],"con":true,"img":false}]}
{"op":"mcm","clk":"5347984175","pt":1646211839448,"mc":[{"id":"1.195453615","rc":[{"atl":[[13.5,0]],"id":26503913}],"con":true,"img":false}]}
{"op":"mcm","clk":"5347984182","pt":1646211839559,"mc":[{"id":"1.195453615","rc":[{"atl":[[14.5,2.67]],"id":26503913}],"con":true,"img":false}]}
{"op":"mcm","clk":"5347984236","pt":1646211840433,"mc":[{"id":"1.195453615","rc":[{"atl":[[990,0]],"id":26503913}],"con":true,"img":false}]}
{"op":"mcm","clk":"5347984241","pt":1646211840535,"mc":[{"id":"1.195453615","rc":[{"atl":[[14.5,3.75]],"id":26503913}],"con":true,"img":false}]}
{"op":"mcm","clk":"5347984449","pt":1646211844913,"mc":[{"id":"1.195453615","rc":[{"atb":[[2.32,0.7]],"id":28755739}],"con":true,"img":false}]}
{"op":"mcm","clk":"5347984457","pt":1646211845115,"mc":[{"id":"1.195453615","rc":[{"atb":[[2.38,5.44]],"id":28755739}],"con":true,"img":false}]}
{"op":"mcm","clk":"5347984667","pt":1646211849740,"mc":[{"id":"1.195453615","rc":[{"atl":[[2.84,0]],"id":28755739}],"con":true,"img":false}]}
{"op":"mcm","clk":"5347984707","pt":1646211850557,"mc":[{"id":"1.195453615","rc":[{"atl":[[2.84,6.53]],"id":28755739}],"con":true,"img":false}]}
{"op":"mcm","clk":"5347984720","pt":1646211850764,"mc":[{"id":"1.195453615","rc":[{"atl":[[18.5,0]],"id":26503913}],"con":true,"img":false}]}
{"op":"mcm","clk":"5347984725","pt":1646211850866,"mc":[{"id":"1.195453615","rc":[{"atl":[[16.5,7.08]],"id":26503913}],"con":true,"img":false}]}
{"op":"mcm","clk":"5347984728","pt":1646211850976,"mc":[{"id":"1.195453615","rc":[{"atl":[[12.5,0]],"id":26503913}],"con":true,"img":false}]}
{"op":"mcm","clk":"5347984733","pt":1646211851023,"mc":[{"id":"1.195453615","rc":[{"atl":[[13.5,1.46]],"id":26503913}],"con":true,"img":false}]}
{"op":"mcm","clk":"5347984824","pt":1646211852770,"mc":[{"id":"1.195453615","rc":[{"atb":[[2.12,0]],"id":28755739}],"con":true,"img":false}]}
{"op":"mcm","clk":"5347984832","pt":1646211852871,"mc":[{"id":"1.195453615","rc":[{"atb":[[2.18,52.18]],"id":28755739}],"con":true,"img":false}]}
{"op":"mcm","clk":"5347984921","pt":1646211854667,"mc":[{"id":"1.195453615","rc":[{"atb":[[2.16,8.69]],"id":28755739}],"con":true,"img":false}]}
{"op":"mcm","clk":"5347985046","pt":1646211857338,"mc":[{"id":"1.195453615","rc":[{"atb":[[2.38,0]],"id":28755739}],"con":true,"img":false}]}
{"op":"mcm","clk":"5347985147","pt":1646211859138,"mc":[{"id":"1.195453615","rc":[{"atb":[[2.38,5.44]],"id":28755739}],"con":true,"img":false}]}
{"op":"mcm","clk":"5347985198","pt":1646211860677,"mc":[{"id":"1.195453615","rc":[{"atl":[[15.5,0]],"id":26503913}],"con":true,"img":false}]}
{"op":"mcm","clk":"5347985206","pt":1646211860775,"mc":[{"id":"1.195453615","rc":[{"atl":[[14,5.57]],"id":26503913}],"con":true,"img":false}]}
{"op":"mcm","clk":"5347985235","pt":1646211861289,"mc":[{"id":"1.195453615","rc":[{"atl":[[14.5,0]],"id":26503913}],"con":true,"img":false}]}
{"op":"mcm","clk":"5347985242","pt":1646211861391,"mc":[{"id":"1.195453615","rc":[{"atl":[[13.5,5.22]],"id":26503913}],"con":true,"img":false}]}
{"op":"mcm","clk":"5347985334","pt":1646211862953,"mc":[{"id":"1.195453615","rc":[{"atl":[[2.84,0]],"id":28755739}],"con":true,"img":false}]}
{"op":"mcm","clk":"5347985375","pt":1646211863773,"mc":[{"id":"1.195453615","rc":[{"atl":[[2.82,6.53]],"id":28755739}],"con":true,"img":false}]}
{"op":"mcm","clk":"5347985463","pt":1646211865267,"mc":[{"id":"1.195453615","rc":[{"atb":[[2.16,0]],"id":28755739}],"con":true,"img":false}]}
{"op":"mcm","clk":"5347985667","pt":1646211869693,"mc":[{"id":"1.195453615","rc":[{"atb":[[2.22,6.16]],"id":28755739}],"con":true,"img":false}]}
{"op":"mcm","clk":"5347985723","pt":1646211870672,"mc":[{"id":"1.195453615","rc":[{"atl":[[14,1.54]],"id":26503913}],"con":true,"img":false}]}
{"op":"mcm","clk":"5347985729","pt":1646211870774,"mc":[{"id":"1.195453615","rc":[{"atl":[[15.5,4.03]],"id":26503913}],"con":true,"img":false}]}
{"op":"mcm","clk":"5347985739","pt":1646211870981,"mc":[{"id":"1.195453615","rc":[{"atl":[[13.5,2.55]],"id":26503913}],"con":true,"img":false}]}
{"op":"mcm","clk":"5347985746","pt":1646211871091,"mc":[{"id":"1.195453615","rc":[{"atl":[[1000,2.67]],"id":26503913}],"con":true,"img":false}]}
{"op":"mcm","clk":"5347985760","pt":1646211871390,"mc":[{"id":"1.195453615","rc":[{"atb":[[2.38,0]],"id":28755739}],"con":true,"img":false}]}
{"op":"mcm","clk":"5347985776","pt":1646211871698,"mc":[{"id":"1.195453615","rc":[{"atl":[[13.5,1.46]],"id":26503913},{"atb":[[2.4,5.44]],"id":28755739}],"con":true,"img":false}]}
{"op":"mcm","clk":"5347985780","pt":1646211871802,"mc":[{"id":"1.195453615","rc":[{"atl":[[14.5,1.08]],"id":26503913}],"con":true,"img":false}]}
{"op":"mcm","clk":"5347985827","pt":1646211872680,"mc":[{"id":"1.195453615","rc":[{"atb":[[2.18,0]],"id":28755739}],"con":true,"img":false}]}
{"op":"mcm","clk":"5347985832","pt":1646211872784,"mc":[{"id":"1.195453615","rc":[{"atb":[[2.12,52.18]],"id":28755739}],"con":true,"img":false}]}
{"op":"mcm","clk":"5347985993","pt":1646211876285,"mc":[{"id":"1.195453615","rc":[{"atl":[[2.82,0]],"id":28755739}],"con":true,"img":false}]}
{"op":"mcm","clk":"5347986032","pt":1646211877005,"mc":[{"id":"1.195453615","rc":[{"atl":[[1000,0]],"id":26503913}],"con":true,"img":false}]}
{"op":"mcm","clk":"5347986038","pt":1646211877107,"mc":[{"id":"1.195453615","rc":[{"atl":[[14.5,3.75]],"id":26503913},{"atl":[[2.84,6.53]],"id":28755739}],"con":true,"img":false}]}
{"op":"mcm","clk":"5347986215","pt":1646211881688,"mc":[{"id":"1.195453615","rc":[{"atb":[[2.22,0]],"id":28755739},{"spn":2.09,"spf":1.0,"id":28755739}],"con":true,"img":false}]}
{"op":"mcm","clk":"5347986330","pt":1646211883908,"mc":[{"id":"1.195453615","rc":[{"atb":[[2.4,0]],"id":28755739}],"con":true,"img":false}]}
{"op":"mcm","clk":"5347986350","pt":1646211884322,"mc":[{"id":"1.195453615","rc":[{"atb":[[2.36,0],[1.04,1.66]],"id":28755739}],"con":true,"img":false}]}
{"op":"mcm","clk":"5347986355","pt":1646211884425,"mc":[{"id":"1.195453615","rc":[{"atb":[[1.04,1.65]],"id":28755739}],"con":true,"img":false}]}
{"op":"mcm","clk":"5347986367","pt":1646211884631,"mc":[{"id":"1.195453615","rc":[{"atb":[[1.04,0]],"id":28755739}],"con":true,"img":false}]}
{"op":"mcm","clk":"5347986373","pt":1646211884735,"mc":[{"id":"1.195453615","rc":[{"atb":[[2.18,1.65]],"id":28755739}],"con":true,"img":false}]}
{"op":"mcm","clk":"5347986402","pt":1646211885100,"mc":[{"id":"1.195453615","rc":[{"atb":[[2.32,6.15]],"id":28755739}],"con":true,"img":false}]}
{"op":"mcm","clk":"5347986654","pt":1646211889636,"mc":[{"id":"1.195453615","rc":[{"atl":[[2.84,0]],"id":28755739}],"con":true,"img":false}]}
{"op":"mcm","clk":"5347986660","pt":1646211889737,"mc":[{"id":"1.195453615","rc":[{"atb":[[2.16,8.69]],"id":28755739}],"con":true,"img":false}]}
{"op":"mcm","clk":"5347986704","pt":1646211890406,"mc":[{"id":"1.195453615","rc":[{"atl":[[2.82,6.53]],"id":28755739}],"con":true,"img":false}]}
{"op":"mcm","clk":"5347986721","pt":1646211890614,"mc":[{"id":"1.195453615","rc":[{"atl":[[15.5,12.75]],"id":26503913}],"con":true,"img":false}]}
{"op":"mcm","clk":"5347986730","pt":1646211890714,"mc":[{"id":"1.195453615","rc":[{"atl":[[16.5,0]],"id":26503913}],"con":true,"img":false}]}
{"op":"mcm","clk":"5347986735","pt":1646211890816,"mc":[{"id":"1.195453615","rc":[{"atb":[[2.16,15.17]],"id":28755739}],"con":true,"img":false}]}
{"op":"mcm","clk":"5347986828","pt":1646211892719,"mc":[{"id":"1.195453615","rc":[{"atl":[[15.5,8.71]],"id":26503913}],"con":true,"img":false}]}
{"op":"mcm","clk":"5347986836","pt":1646211892820,"mc":[{"id":"1.195453615","rc":[{"atl":[[14,5.57]],"id":26503913}],"con":true,"img":false}]}
{"op":"mcm","clk":"5347986850","pt":1646211893128,"mc":[{"id":"1.195453615","rc":[{"atl":[[14.5,2.67]],"id":26503913}],"con":true,"img":false}]}
{"op":"mcm","clk":"5347986854","pt":1646211893231,"mc":[{"id":"1.195453615","rc":[{"atl":[[13.5,2.55]],"id":26503913}],"con":true,"img":false}]}
{"op":"mcm","clk":"5347986858","pt":1646211893335,"mc":[{"id":"1.195453615","rc":[{"atl":[[14.5,0]],"id":26503913}],"con":true,"img":false}]}
{"op":"mcm","clk":"5347986863","pt":1646211893440,"mc":[{"id":"1.195453615","rc":[{"atl":[[13.5,5.22]],"id":26503913}],"con":true,"img":false}]}
{"op":"mcm","clk":"5347987021","pt":1646211896424,"mc":[{"id":"1.195453615","rc":[{"atb":[[2.18,0],[1.04,1.66]],"id":28755739}],"con":true,"img":false}]}
{"op":"mcm","clk":"5347987034","pt":1646211896630,"mc":[{"id":"1.195453615","rc":[{"atb":[[1.04,1.65]],"id":28755739}],"con":true,"img":false}]}
{"op":"mcm","clk":"5347987044","pt":1646211896843,"mc":[{"id":"1.195453615","rc":[{"atb":[[1.04,0]],"id":28755739}],"con":true,"img":false}]}
{"op":"mcm","clk":"5347987047","pt":1646211896945,"mc":[{"id":"1.195453615","rc":[{"atb":[[2.36,1.65]],"id":28755739}],"con":true,"img":false}]}
{"op":"mcm","clk":"5347987078","pt":1646211897505,"mc":[{"id":"1.195453615","rc":[{"atb":[[2.32,0.7]],"id":28755739}],"con":true,"img":false}]}
{"op":"mcm","clk":"5347987085","pt":1646211897710,"mc":[{"id":"1.195453615","rc":[{"atb":[[2.34,5.44]],"id":28755739}],"con":true,"img":false}]}
{"op":"mcm","clk":"5347987288","pt":1646211902714,"mc":[{"id":"1.195453615","rc":[{"atl":[[14,1.54]],"id":26503913}],"con":true,"img":false}]}
{"op":"mcm","clk":"5347987292","pt":1646211902819,"mc":[{"id":"1.195453615","rc":[{"atl":[[15.5,12.75]],"id":26503913},{"atl":[[2.82,0]],"id":28755739}],"con":true,"img":false}]}
{"op":"mcm","clk":"5347987300","pt":1646211902923,"mc":[{"id":"1.195453615","rc":[{"atl":[[13.5,2.55]],"id":26503913}],"con":true,"img":false}]}
{"op":"mcm","clk":"5347987307","pt":1646211903028,"mc":[{"id":"1.195453615","rc":[{"atl":[[1000,2.67]],"id":26503913}],"con":true,"img":false}]}
{"op":"mcm","clk":"5347987311","pt":1646211903129,"mc":[{"id":"1.195453615","rc":[{"atb":[[2.62,61.73],[2.76,0]],"id":39980001}],"con":true,"img":false}]}
{"op":"mcm","clk":"5347987330","pt":1646211903438,"mc":[{"id":"1.195453615","rc":[{"atl":[[13.5,1.46]],"id":26503913}],"con":true,"img":false}]}
{"op":"mcm","clk":"5347987337","pt":1646211903541,"mc":[{"id":"1.195453615","rc":[{"atl":[[14.5,1.08]],"id":26503913}],"con":true,"img":false}]}
{"op":"mcm","clk":"5347987343","pt":1646211903646,"mc":[{"id":"1.195453615","rc":[{"atl":[[2.8,6.53]],"id":28755739}],"con":true,"img":false}]}
{"op":"mcm","clk":"5347987657","pt":1646211909938,"mc":[{"id":"1.195453615","rc":[{"atb":[[2.34,0]],"id":28755739}],"con":true,"img":false}]}
{"op":"mcm","clk":"5347987687","pt":1646211910451,"mc":[{"id":"1.195453615","rc":[{"atl":[[2.8,6.22]],"id":28755739},{"trd":[[2.8,0.62]],"ltp":2.8,"tv":0.62,"id":28755739}],"con":true,"img":false}]}
{"op":"mcm","clk":"5347987750","pt":1646211911745,"mc":[{"id":"1.195453615","rc":[{"atb":[[2.38,5.44]],"id":28755739}],"con":true,"img":false}]}
{"op":"mcm","clk":"5347987796","pt":1646211912670,"mc":[{"id":"1.195453615","rc":[{"atb":[[2.12,0]],"id":28755739}],"con":true,"img":false}]}
{"op":"mcm","clk":"5347987800","pt":1646211912773,"mc":[{"id":"1.195453615","rc":[{"atb":[[2.18,52.18]],"id":28755739}],"con":true,"img":false}]}
{"op":"mcm","clk":"5347987965","pt":1646211916178,"mc":[{"id":"1.195453615","rc":[{"atl":[[2.8,0]],"id":28755739}],"con":true,"img":false}]}
{"op":"mcm","clk":"5347988000","pt":1646211916852,"mc":[{"id":"1.195453615","rc":[{"atl":[[1000,0]],"id":26503913}],"con":true,"img":false}]}
{"op":"mcm","clk":"5347988002","pt":1646211916955,"mc":[{"id":"1.195453615","rc":[{"atl":[[14.5,3.75]],"id":26503913}],"con":true,"img":false}]}
{"op":"mcm","clk":"5347988054","pt":1646211918081,"mc":[{"id":"1.195453615","rc":[{"atb":[[1.04,2.72]],"id":28755739}],"con":true,"img":false}]}
{"op":"mcm","clk":"5347988076","pt":1646211918544,"mc":[{"id":"1.195453615","rc":[{"atb":[[1.04,0.31]],"id":28755739}],"con":true,"img":false}]}
{"op":"mcm","clk":"5347988096","pt":1646211918957,"mc":[{"id":"1.195453615","rc":[{"atb":[[1.04,0]],"id":28755739}],"con":true,"img":false}]}
{"op":"mcm","clk":"5347988100","pt":1646211919061,"mc":[{"id":"1.195453615","rc":[{"atb":[[2.4,0.31]],"id":28755739}],"con":true,"img":false}]}
{"op":"mcm","clk":"5347988205","pt":1646211920762,"mc":[{"id":"1.195453615","rc":[{"atb":[[2.16,8.69]],"id":28755739}],"con":true,"img":false}]}
{"op":"mcm","clk":"5347988361","pt":1646211924057,"mc":[{"id":"1.195453615","rc":[{"atb":[[2.38,0]],"id":28755739}],"con":true,"img":false}]}
{"op":"mcm","clk":"5347988383","pt":1646211924667,"mc":[{"id":"1.195453615","rc":[{"atl":[[15.5,8.71]],"id":26503913}],"con":true,"img":false}]}
{"op":"mcm","clk":"5347988386","pt":1646211924772,"mc":[{"id":"1.195453615","rc":[{"atl":[[14,5.57]],"id":26503913}],"con":true,"img":false}]}
{"op":"mcm","clk":"5347988389","pt":1646211924880,"mc":[{"id":"1.195453615","rc":[{"atb":[[2.36,0],[1.04,1.66]],"id":28755739}],"con":true,"img":false}]}
{"op":"mcm","clk":"5347988394","pt":1646211924984,"mc":[{"id":"1.195453615","rc":[{"atb":[[1.04,1.65]],"id":28755739}],"con":true,"img":false}]}
{"op":"mcm","clk":"5347988405","pt":1646211925189,"mc":[{"id":"1.195453615","rc":[{"atb":[[1.04,0]],"id":28755739}],"con":true,"img":false}]}
{"op":"mcm","clk":"5347988409","pt":1646211925292,"mc":[{"id":"1.195453615","rc":[{"atb":[[2.24,1.65]],"id":28755739}],"con":true,"img":false}]}
{"op":"mcm","clk":"5347988428","pt":1646211925769,"mc":[{"id":"1.195453615","rc":[{"atb":[[2.16,0]],"id":28755739}],"con":true,"img":false}]}
{"op":"mcm","clk":"5347988432","pt":1646211925879,"mc":[{"id":"1.195453615","rc":[{"atl":[[14.5,2.67]],"id":26503913}],"con":true,"img":false}]}
{"op":"mcm","clk":"5347988437","pt":1646211925965,"mc":[{"id":"1.195453615","rc":[{"atl":[[13.5,2.55]],"id":26503913}],"con":true,"img":false}]}
{"op":"mcm","clk":"5347988460","pt":1646211926491,"mc":[{"id":"1.195453615","rc":[{"atl":[[14.5,0],[1000,2.25]],"id":26503913}],"con":true,"img":false}]}
{"op":"mcm","clk":"5347988469","pt":1646211926589,"mc":[{"id":"1.195453615","rc":[{"atl":[[13,2.67]],"id":26503913}],"con":true,"img":false}]}
{"op":"mcm","clk":"5347988474","pt":1646211926688,"mc":[{"id":"1.195453615","rc":[{"atl":[[1000,0.28]],"id":26503913}],"con":true,"img":false}]}
{"op":"mcm","clk":"5347988486","pt":1646211926996,"mc":[{"id":"1.195453615","rc":[{"atb":[[2.34,5.44]],"id":28755739}],"con":true,"img":false}]}
{"op":"mcm","clk":"5347988488","pt":1646211927101,"mc":[{"id":"1.195453615","rc":[{"atl":[[1000,0]],"id":26503913}],"con":true,"img":false}]}
{"op":"mcm","clk":"5347988495","pt":1646211927155,"mc":[{"id":"1.195453615","rc":[{"atl":[[13,2.96]],"id":26503913}],"con":true,"img":false}]}
{"op":"mcm","clk":"5347988506","pt":1646211927360,"mc":[{"id":"1.195453615","rc":[{"atl":[[13.5,1.08]],"id":26503913}],"con":true,"img":false}]}
{"op":"mcm","clk":"5347988511","pt":1646211927463,"mc":[{"id":"1.195453615","rc":[{"atl":[[12.5,1.46]],"id":26503913}],"con":true,"img":false}]}
{"op":"mcm","clk":"5347988522","pt":1646211927670,"mc":[{"id":"1.195453615","rc":[{"atl":[[13,0.28]],"id":26503913}],"con":true,"img":false}]}
{"op":"mcm","clk":"5347988527","pt":1646211927770,"mc":[{"id":"1.195453615","rc":[{"atl":[[13.5,3.75]],"id":26503913}],"con":true,"img":false}]}
{"op":"mcm","clk":"5347988534","pt":1646211927975,"mc":[{"id":"1.195453615","rc":[{"atl":[[13.5,2.67]],"id":26503913}],"con":true,"img":false}]}
{"op":"mcm","clk":"5347988537","pt":1646211928080,"mc":[{"id":"1.195453615","rc":[{"atl":[[13,1.36]],"id":26503913}],"con":true,"img":false}]}
{"op":"mcm","clk":"5347988553","pt":1646211928592,"mc":[{"id":"1.195453615","rc":[{"atl":[[13,0.28]],"id":26503913}],"con":true,"img":false}]}
{"op":"mcm","clk":"5347988556","pt":1646211928695,"mc":[{"id":"1.195453615","rc":[{"atl":[[13.5,3.75]],"id":26503913}],"con":true,"img":false}]}
{"op":"mcm","clk":"5347988583","pt":1646211929373,"mc":[{"id":"1.195453615","rc":[{"atl":[[12.5,0]],"id":26503913}],"con":true,"img":false}]}
{"op":"mcm","clk":"5347988586","pt":1646211929476,"mc":[{"id":"1.195453615","rc":[{"atl":[[13,1.75]],"id":26503913}],"con":true,"img":false}]}
{"op":"mcm","clk":"5347988605","pt":1646211930000,"mc":[{"id":"1.195453615","rc":[{"atl":[[13.5,2.67]],"id":26503913}],"con":true,"img":false}]}
{"op":"mcm","clk":"5347988610","pt":1646211930102,"mc":[{"id":"1.195453615","rc":[{"atl":[[13,2.83]],"id":26503913}],"con":true,"img":false}]}
{"op":"mcm","clk":"5347988635","pt":1646211930677,"mc":[{"id":"1.195453615","rc":[{"atb":[[2.18,0]],"id":28755739}],"con":true,"img":false}]}
{"op":"mcm","clk":"5347988639","pt":1646211930785,"mc":[{"id":"1.195453615","rc":[{"atb":[[2.12,52.18]],"id":28755739}],"con":true,"img":false}]}
{"op":"mcm","clk":"5347988689","pt":1646211931877,"mc":[{"id":"1.195453615","rc":[{"atb":[[2.4,0]],"id":28755739}],"con":true,"img":false}]}
{"op":"mcm","clk":"5347988733","pt":1646211932706,"mc":[{"id":"1.195453615","rc":[{"atl":[[14,1.54]],"id":26503913}],"con":true,"img":false}]}
{"op":"mcm","clk":"5347988740","pt":1646211932806,"mc":[{"id":"1.195453615","rc":[{"atl":[[15.5,12.75]],"id":26503913}],"con":true,"img":false}]}
{"op":"mcm","clk":"5347988756","pt":1646211933168,"mc":[{"id":"1.195453615","rc":[{"atl":[[13.5,0]],"id":26503913}],"con":true,"img":false}]}
{"op":"mcm","clk":"5347988760","pt":1646211933275,"mc":[{"id":"1.195453615","rc":[{"atl":[[1000,2.67]],"id":26503913}],"con":true,"img":false}]}
{"op":"mcm","clk":"5347988816","pt":1646211934502,"mc":[{"id":"1.195453615","rc":[{"atl":[[13,1.75]],"id":26503913}],"con":true,"img":false}]}
{"op":"mcm","clk":"5347988823","pt":1646211934604,"mc":[{"id":"1.195453615","rc":[{"atl":[[990,1.08]],"id":26503913}],"con":true,"img":false}]}
{"op":"mcm","clk":"5347988849","pt":1646211935174,"mc":[{"id":"1.195453615","rc":[{"atl":[[13,0.28]],"id":26503913}],"con":true,"img":false}]}
{"op":"mcm","clk":"5347988854","pt":1646211935277,"mc":[{"id":"1.195453615","rc":[{"atl":[[13.5,1.46]],"id":26503913}],"con":true,"img":false}]}
{"op":"mcm","clk":"5347988915","pt":1646211936979,"mc":[{"id":"1.195453615","rc":[{"atb":[[2.24,0],[1.04,1.66]],"id":28755739}],"con":true,"img":false}]}
{"op":"mcm","clk":"5347988926","pt":1646211937186,"mc":[{"id":"1.195453615","rc":[{"atb":[[1.04,1.65]],"id":28755739}],"con":true,"img":false}]}
{"op":"mcm","clk":"5347988934","pt":1646211937383,"mc":[{"id":"1.195453615","rc":[{"atb":[[1.04,0]],"id":28755739}],"con":true,"img":false}]}
{"op":"mcm","clk":"5347988937","pt":1646211937484,"mc":[{"id":"1.195453615","rc":[{"atb":[[2.36,1.65]],"id":28755739}],"con":true,"img":false}]}
{"op":"mcm","clk":"5347988955","pt":1646211938411,"mc":[{"id":"1.195453615","rc":[{"atb":[[1.04,2.72]],"id":28755739}],"con":true,"img":false}]}
{"op":"mcm","clk":"5347988967","pt":1646211938882,"mc":[{"id":"1.195453615","rc":[{"atb":[[1.04,0.31]],"id":28755739}],"con":true,"img":false}]}
{"op":"mcm","clk":"5347988979","pt":1646211939190,"mc":[{"id":"1.195453615","rc":[{"atb":[[2.34,0]],"id":28755739}],"con":true,"img":false}]}
{"op":"mcm","clk":"5347988987","pt":1646211939394,"mc":[{"id":"1.195453615","rc":[{"atb":[[2.36,7.1],[1.04,0]],"id":28755739}],"con":true,"img":false}]}
{"op":"mcm","clk":"5347988991","pt":1646211939506,"mc":[{"id":"1.195453615","rc":[{"atb":[[2.38,0.31]],"id":28755739}],"con":true,"img":false}]}
{"op":"mcm","clk":"5347989327","pt":1646211947804,"mc":[{"id":"1.195453615","rc":[{"atb":[[2.16,6.48]],"id":28755739},{"spn":2.09,"spf":1.0,"id":28755739}],"con":true,"img":false}]}
{"op":"mcm","clk":"5347989437","pt":1646211949914,"mc":[{"id":"1.195453615","rc":[{"atb":[[2.16,15.17]],"id":28755739}],"con":true,"img":false}]}
{"op":"mcm","clk":"5347989540","pt":1646211951623,"mc":[{"id":"1.195453615","rc":[{"atb":[[2.36,1.65]],"id":28755739}],"con":true,"img":false}]}
{"op":"mcm","clk":"5347989567","pt":1646211951987,"mc":[{"id":"1.195453615","rc":[{"atb":[[2.38,0]],"id":28755739}],"con":true,"img":false}]}
{"op":"mcm","clk":"5347989624","pt":1646211953017,"mc":[{"id":"1.195453615","rc":[{"atb":[[2.36,0],[1.04,1.66]],"id":28755739}],"con":true,"img":false}]}
{"op":"mcm","clk":"5347989628","pt":1646211953120,"mc":[{"id":"1.195453615","rc":[{"atb":[[1.04,1.65]],"id":28755739}],"con":true,"img":false}]}
{"op":"mcm","clk":"5347989632","pt":1646211953223,"mc":[{"id":"1.195453615","rc":[{"atb":[[1.04,0]],"id":28755739}],"con":true,"img":false}]}
{"op":"mcm","clk":"5347989636","pt":1646211953326,"mc":[{"id":"1.195453615","rc":[{"atb":[[2.32,6.15],[2.22,1.65]],"id":28755739}],"con":true,"img":false}]}
{"op":"mcm","clk":"5347989872","pt":1646211958637,"mc":[{"id":"1.195453615","rc":[{"atl":[[15.5,8.71]],"id":26503913},{"atb":[[1.04,2.72]],"id":28755739}],"con":true,"img":false}]}
{"op":"mcm","clk":"5347989874","pt":1646211958739,"mc":[{"id":"1.195453615","rc":[{"atl":[[14.5,4.03]],"id":26503913}],"con":true,"img":false}]}
{"op":"mcm","clk":"5347989890","pt":1646211959049,"mc":[{"id":"1.195453615","rc":[{"atb":[[1.04,0.31]],"id":28755739}],"con":true,"img":false}]}
{"op":"mcm","clk":"5347989902","pt":1646211959208,"mc":[{"id":"1.195453615","rc":[{"atl":[[990,0]],"id":26503913}],"con":true,"img":false}]}
{"op":"mcm","clk":"5347989908","pt":1646211959314,"mc":[{"id":"1.195453615","rc":[{"atl":[[13.5,2.55]],"id":26503913}],"con":true,"img":false}]}
{"op":"mcm","clk":"5347989914","pt":1646211959413,"mc":[{"id":"1.195453615","rc":[{"atb":[[1.04,0]],"id":28755739}],"con":true,"img":false}]}
{"op":"mcm","clk":"5347989917","pt":1646211959520,"mc":[{"id":"1.195453615","rc":[{"atl":[[1000,0]],"id":26503913},{"atb":[[2.34,0.31]],"id":28755739}],"con":true,"img":false}]}
{"op":"mcm","clk":"5347989920","pt":1646211959622,"mc":[{"id":"1.195453615","rc":[{"atl":[[14,4.21]],"id":26503913}],"con":true,"img":false}]}
{"op":"mcm","clk":"5347990201","pt":1646211965257,"mc":[{"id":"1.195453615","rc":[{"atb":[[2.22,0],[1.04,1.66]],"id":28755739}],"con":true,"img":false}]}
{"op":"mcm","clk":"5347990208","pt":1646211965417,"mc":[{"id":"1.195453615","rc":[{"atb":[[1.04,1.65]],"id":28755739}],"con":true,"img":false}]}
{"op":"mcm","clk":"5347990211","pt":1646211965521,"mc":[{"id":"1.195453615","rc":[{"atb":[[2.32,0.7],[1.04,0]],"id":28755739}],"con":true,"img":false}]}
{"op":"mcm","clk":"5347990214","pt":1646211965623,"mc":[{"id":"1.195453615","rc":[{"atb":[[2.36,1.65]],"id":28755739}],"con":true,"img":false}]}
{"op":"mcm","clk":"5347990216","pt":1646211965729,"mc":[{"id":"1.195453615","rc":[{"atb":[[2.34,5.76]],"id":28755739}],"con":true,"img":false}]}
{"op":"mcm","clk":"5347990356","pt":1646211968629,"mc":[{"id":"1.195453615","rc":[{"atb":[[2.12,0]],"id":28755739}],"con":true,"img":false}]}
{"op":"mcm","clk":"5347990362","pt":1646211968731,"mc":[{"id":"1.195453615","rc":[{"atb":[[2.18,52.18]],"id":28755739}],"con":true,"img":false}]}
{"op":"mcm","clk":"5347990506","pt":1646211972245,"mc":[{"id":"1.195453615","rc":[{"atb":[[2.34,5.44]],"id":28755739}],"con":true,"img":false}]}
{"op":"mcm","clk":"5347990541","pt":1646211973020,"mc":[{"id":"1.195453615","rc":[{"atb":[[1.04,2.72]],"id":28755739}],"con":true,"img":false}]}
{"op":"mcm","clk":"5347990560","pt":1646211973436,"mc":[{"id":"1.195453615","rc":[{"atb":[[1.04,0.31]],"id":28755739}],"con":true,"img":false}]}
{"op":"mcm","clk":"5347990583","pt":1646211973951,"mc":[{"id":"1.195453615","rc":[{"atb":[[1.04,0]],"id":28755739}],"con":true,"img":false}]}
{"op":"mcm","clk":"5347990585","pt":1646211974055,"mc":[{"id":"1.195453615","rc":[{"atb":[[2.38,0.31]],"id":28755739}],"con":true,"img":false}]}
{"op":"mcm","clk":"5347990617","pt":1646211974675,"mc":[{"id":"1.195453615","rc":[{"atl":[[14,1.54]],"id":26503913}],"con":true,"img":false}]}
{"op":"mcm","clk":"5347990623","pt":1646211974776,"mc":[{"id":"1.195453615","rc":[{"atl":[[13,2.96]],"id":26503913}],"con":true,"img":false}]}
{"op":"mcm","clk":"5347990636","pt":1646211975094,"mc":[{"id":"1.195453615","rc":[{"atl":[[13.5,1.08]],"id":26503913}],"con":true,"img":false}]}
{"op":"mcm","clk":"5347990641","pt":1646211975143,"mc":[{"id":"1.195453615","rc":[{"atl":[[12.5,1.46]],"id":26503913}],"con":true,"img":false}]}
{"op":"mcm","clk":"5347990707","pt":1646211976184,"mc":[{"id":"1.195453615","rc":[{"atl":[[13.5,0]],"id":26503913}],"con":true,"img":false}]}
{"op":"mcm","clk":"5347990714","pt":1646211976237,"mc":[{"id":"1.195453615","rc":[{"atl":[[13,4.04]],"id":26503913}],"con":true,"img":false}]}
{"op":"mcm","clk":"5347990780","pt":1646211977885,"mc":[{"id":"1.195453615","rc":[{"atb":[[2.16,8.69]],"id":28755739}],"con":true,"img":false}]}
{"op":"mcm","clk":"5347990785","pt":1646211977941,"mc":[{"id":"1.195453615","rc":[{"atb":[[2.34,0]],"id":28755739}],"con":true,"img":false}]}
{"op":"mcm","clk":"5347990903","pt":1646211980160,"mc":[{"id":"1.195453615","rc":[{"atb":[[2.38,5.76]],"id":28755739}],"con":true,"img":false}]}
{"op":"mcm","clk":"5347991019","pt":1646211982684,"mc":[{"id":"1.195453615","rc":[{"atl":[[14.5,0]],"id":26503913}],"con":true,"img":false}]}
{"op":"mcm","clk":"5347991024","pt":1646211982787,"mc":[{"id":"1.195453615","rc":[{"atl":[[15.5,12.75]],"id":26503913}],"con":true,"img":false}]}
{"op":"mcm","clk":"5347991094","pt":1646211984694,"mc":[{"id":"1.195453615","rc":[{"atl":[[15.5,4.03]],"id":26503913}],"con":true,"img":false}]}
{"op":"mcm","clk":"5347991103","pt":1646211984799,"mc":[{"id":"1.195453615","rc":[{"atl":[[16.5,8.71]],"id":26503913}],"con":true,"img":false}]}
{"op":"mcm","clk":"5347991113","pt":1646211984954,"mc":[{"id":"1.195453615","rc":[{"atl":[[13,1.36]],"id":26503913}],"con":true,"img":false}]}
{"op":"mcm","clk":"5347991117","pt":1646211985057,"mc":[{"id":"1.195453615","rc":[{"atl":[[14,4.21]],"id":26503913}],"con":true,"img":false}]}
{"op":"mcm","clk":"5347991131","pt":1646211985365,"mc":[{"id":"1.195453615","rc":[{"atl":[[14,1.54]],"id":26503913}],"con":true,"img":false}]}
{"op":"mcm","clk":"5347991136","pt":1646211985471,"mc":[{"id":"1.195453615","rc":[{"atl":[[14.5,2.67]],"id":26503913}],"con":true,"img":false}]}
{"op":"mcm","clk":"5347991151","pt":1646211985678,"mc":[{"id":"1.195453615","rc":[{"atl":[[13,0.28]],"id":26503913}],"con":true,"img":false}]}
{"op":"mcm","clk":"5347991157","pt":1646211985782,"mc":[{"id":"1.195453615","rc":[{"atl":[[14.5,3.75]],"id":26503913}],"con":true,"img":false}]}
{"op":"mcm","clk":"5347991182","pt":1646211986298,"mc":[{"id":"1.195453615","rc":[{"atl":[[14.5,2.67]],"id":26503913}],"con":true,"img":false}]}
{"op":"mcm","clk":"5347991186","pt":1646211986399,"mc":[{"id":"1.195453615","rc":[{"atl":[[14,2.62]],"id":26503913}],"con":true,"img":false}]}
{"op":"mcm","clk":"5347991190","pt":1646211986502,"mc":[{"id":"1.195453615","rc":[{"atb":[[2.38,5.44]],"id":28755739}],"con":true,"img":false}]}
{"op":"mcm","clk":"5347991194","pt":1646211986605,"mc":[{"id":"1.195453615","rc":[{"atb":[[1.03,2.25]],"id":39784359}],"con":true,"img":false}]}
{"op":"mcm","clk":"5347991201","pt":1646211986663,"mc":[{"id":"1.195453615","rc":[{"atb":[[1.03,0.27]],"id":39784359}],"con":true,"img":false}]}
{"op":"mcm","clk":"5347991213","pt":1646211986870,"mc":[{"id":"1.195453615","rc":[{"atb":[[2.22,6.16]],"id":28755739}],"con":true,"img":false}]}
{"op":"mcm","clk":"5347991243","pt":1646211987387,"mc":[{"id":"1.195453615","rc":[{"atb":[[1.04,2.72]],"id":28755739},{"atb":[[1.03,0]],"id":39784359}],"con":true,"img":false}]}
{"op":"mcm","clk":"5347991246","pt":1646211987495,"mc":[{"id":"1.195453615","rc":[{"atb":[[13.5,0.27]],"id":39784359}],"con":true,"img":false}]}
{"op":"mcm","clk":"5347991263","pt":1646211987797,"mc":[{"id":"1.195453615","rc":[{"atb":[[1.04,0.31]],"id":28755739}],"con":true,"img":false}]}
{"op":"mcm","clk":"5347991282","pt":1646211988208,"mc":[{"id":"1.195453615","rc":[{"atb":[[1.04,0]],"id":28755739}],"con":true,"img":false}]}
{"op":"mcm","clk":"5347991287","pt":1646211988312,"mc":[{"id":"1.195453615","rc":[{"atb":[[2.4,0.31]],"id":28755739}],"con":true,"img":false}]}
{"op":"mcm","clk":"5347991311","pt":1646211988774,"mc":[{"id":"1.195453615","rc":[{"atb":[[2.16,0]],"id":28755739}],"con":true,"img":false}]}
{"op":"mcm","clk":"5347991443","pt":1646211992383,"mc":[{"id":"1.195453615","rc":[{"atb":[[2.38,0]],"id":28755739}],"con":true,"img":false}]}
{"op":"mcm","clk":"5347991451","pt":1646211992594,"mc":[{"id":"1.195453615","rc":[{"atl":[[14.5,0]],"id":26503913}],"con":true,"img":false}]}
{"op":"mcm","clk":"5347991457","pt":1646211992695,"mc":[{"id":"1.195453615","rc":[{"atl":[[13.5,2.67]],"id":26503913}],"con":true,"img":false}]}
{"op":"mcm","clk":"5347991470","pt":1646211992900,"mc":[{"id":"1.195453615","rc":[{"atl":[[14,1.54]],"id":26503913}],"con":true,"img":false}]}
{"op":"mcm","clk":"5347991473","pt":1646211993003,"mc":[{"id":"1.195453615","rc":[{"atl":[[13.5,3.75]],"id":26503913}],"con":true,"img":false}]}
{"op":"mcm","clk":"5347991483","pt":1646211993309,"mc":[{"id":"1.195453615","rc":[{"atl":[[13.5,1.08]],"id":26503913}],"con":true,"img":false}]}
{"op":"mcm","clk":"5347991487","pt":1646211993411,"mc":[{"id":"1.195453615","rc":[{"atl":[[14.5,2.67]],"id":26503913}],"con":true,"img":false}]}
{"op":"mcm","clk":"5347991493","pt":1646211993518,"mc":[{"id":"1.195453615","rc":[{"atl":[[12.5,0],[13.5,0]],"id":26503913}],"con":true,"img":false}]}
{"op":"mcm","clk":"5347991496","pt":1646211993574,"mc":[{"id":"1.195453615","rc":[{"atl":[[13,1.75],[14.5,3.75]],"id":26503913}],"con":true,"img":false}]}
{"op":"mcm","clk":"5347991633","pt":1646211996710,"mc":[{"id":"1.195453615","rc":[{"atb":[[2.18,0]],"id":28755739}],"con":true,"img":false}]}
{"op":"mcm","clk":"5347991637","pt":1646211996813,"mc":[{"id":"1.195453615","rc":[{"atb":[[2.12,52.18]],"id":28755739}],"con":true,"img":false}]}
{"op":"mcm","clk":"5347991693","pt":1646211997795,"mc":[{"id":"1.195453615","rc":[{"atb":[[2.38,5.44]],"id":28755739}],"con":true,"img":false}]}
{"op":"mcm","clk":"5347991811","pt":1646212000925,"mc":[{"id":"1.195453615","rc":[{"atb":[[2.4,0]],"id":28755739}],"con":true,"img":false}]}
{"op":"mcm","clk":"5347991873","pt":1646212002726,"mc":[{"id":"1.195453615","rc":[{"atl":[[2.86,14.55]],"id":28755739}],"con":true,"img":false}]}
{"op":"mcm","clk":"5347991884","pt":1646212002937,"mc":[{"id":"1.195453615","rc":[{"atl":[[5.9,5.57]],"id":37456368}],"con":true,"img":false}]}
{"op":"mcm","clk":"5347991983","pt":1646212004994,"mc":[{"id":"1.195453615","rc":[{"atb":[[2.22,0]],"id":28755739}],"con":true,"img":false}]}
{"op":"mcm","clk":"5347992046","pt":1646212006588,"mc":[{"id":"1.195453615","rc":[{"atl":[[15.5,0]],"id":26503913}],"con":true,"img":false}]}
{"op":"mcm","clk":"5347992051","pt":1646212006690,"mc":[{"id":"1.195453615","rc":[{"atl":[[14,5.57]],"id":26503913}],"con":true,"img":false}]}
{"op":"mcm","clk":"5347992066","pt":1646212007000,"mc":[{"id":"1.195453615","rc":[{"atb":[[1.04,2.72]],"id":28755739}],"con":true,"img":false}]}
{"op":"mcm","clk":"5347992084","pt":1646212007411,"mc":[{"id":"1.195453615","rc":[{"atl":[[14.5,2.67]],"id":26503913}],"con":true,"img":false}]}
{"op":"mcm","clk":"5347992088","pt":1646212007514,"mc":[{"id":"1.195453615","rc":[{"atl":[[13,2.83]],"id":26503913},{"atb":[[1.04,0.31]],"id":28755739}],"con":true,"img":false}]}
{"op":"mcm","clk":"5347992111","pt":1646212008036,"mc":[{"id":"1.195453615","rc":[{"atb":[[1.04,0]],"id":28755739},{"spn":2.09,"spf":1.0,"id":28755739},{"spn":11.35,"spf":1.0,"id":39784359}],"con":true,"img":false}]}
{"op":"mcm","clk":"5347992116","pt":1646212008142,"mc":[{"id":"1.195453615","rc":[{"atb":[[2.4,0.31]],"id":28755739}],"con":true,"img":false}]}
{"op":"mcm","clk":"5347992198","pt":1646212010039,"mc":[{"id":"1.195453615","rc":[{"atb":[[2.38,0]],"id":28755739}],"con":true,"img":false}]}
{"op":"mcm","clk":"5347992363","pt":1646212012937,"mc":[{"id":"1.195453615","rc":[{"atb":[[2.16,8.69]],"id":28755739}],"con":true,"img":false}]}
{"op":"mcm","clk":"5347992370","pt":1646212013042,"mc":[{"id":"1.195453615","rc":[{"atb":[[2.38,5.44]],"id":28755739}],"con":true,"img":false}]}
{"op":"mcm","clk":"5347992418","pt":1646212013925,"mc":[{"id":"1.195453615","rc":[{"atb":[[2.16,15.17]],"id":28755739}],"con":true,"img":false}]}
{"op":"mcm","clk":"5347992548","pt":1646212016626,"mc":[{"id":"1.195453615","rc":[{"atb":[[11.5,0]],"id":39784359}],"con":true,"img":false}]}
{"op":"mcm","clk":"5347992553","pt":1646212016738,"mc":[{"id":"1.195453615","rc":[{"atb":[[12.5,7.09]],"id":39784359}],"con":true,"img":false}]}
{"op":"mcm","clk":"5347992594","pt":1646212017552,"mc":[{"id":"1.195453615","rc":[{"atb":[[12,0]],"id":39784359}],"con":true,"img":false}]}
{"op":"mcm","clk":"5347992598","pt":1646212017652,"mc":[{"id":"1.195453615","rc":[{"atb":[[13,1.8]],"id":39784359}],"con":true,"img":false}]}
{"op":"mcm","clk":"5347992680","pt":1646212019561,"mc":[{"id":"1.195453615","rc":[{"atb":[[12.5,5.31]],"id":39784359}],"con":true,"img":false}]}
{"op":"mcm","clk":"5347992734","pt":1646212020649,"mc":[{"id":"1.195453615","rc":[{"atb":[[2.4,0]],"id":28755739},{"atb":[[12.5,0]],"id":39784359}],"con":true,"img":false}]}
{"op":"mcm","clk":"5347992740","pt":1646212020759,"mc":[{"id":"1.195453615","rc":[{"atb":[[11.5,5.31]],"id":39784359}],"con":true,"img":false}]}
{"op":"mcm","clk":"5347992775","pt":1646212021533,"mc":[{"id":"1.195453615","rc":[{"atb":[[13,0.13]],"id":39784359}],"con":true,"img":false}]}
{"op":"mcm","clk":"5347992779","pt":1646212021638,"mc":[{"id":"1.195453615","rc":[{"atb":[[12,1.66]],"id":39784359}],"con":true,"img":false}]}
{"op":"mcm","clk":"5347992989","pt":1646212025272,"mc":[{"id":"1.195453615","rc":[{"atb":[[2.38,0]],"id":28755739}],"con":true,"img":false}]}
{"op":"mcm","clk":"5347993009","pt":1646212025567,"mc":[{"id":"1.195453615","rc":[{"atb":[[2.4,5.44]],"id":28755739}],"con":true,"img":false}]}
{"op":"mcm","clk":"5347993062","pt":1646212026654,"mc":[{"id":"1.195453615","rc":[{"atb":[[1.04,2.72]],"id":28755739}],"con":true,"img":false}]}
{"op":"mcm","clk":"5347993081","pt":1646212027067,"mc":[{"id":"1.195453615","rc":[{"atb":[[1.04,0.31]],"id":28755739}],"con":true,"img":false}]}
{"op":"mcm","clk":"5347993104","pt":1646212027584,"mc":[{"id":"1.195453615","rc":[{"atb":[[1.04,0]],"id":28755739}],"con":true,"img":false}]}
{"op":"mcm","clk":"5347993109","pt":1646212027645,"mc":[{"id":"1.195453615","rc":[{"atb":[[2.42,0.31]],"id":28755739}],"con":true,"img":false}]}
{"op":"mcm","clk":"5347993479","pt":1646212034655,"mc":[{"id":"1.195453615","rc":[{"atb":[[2.12,0]],"id":28755739}],"con":true,"img":false}]}
{"op":"mcm","clk":"5347993486","pt":1646212034764,"mc":[{"id":"1.195453615","rc":[{"atb":[[2.18,52.18]],"id":28755739}],"con":true,"img":false}]}
{"op":"mcm","clk":"5347993527","pt":1646212035580,"mc":[{"id":"1.195453615","rc":[{"atl":[[14.5,0]],"id":26503913}],"con":true,"img":false}]}
{"op":"mcm","clk":"5347993531","pt":1646212035680,"mc":[{"id":"1.195453615","rc":[{"atl":[[12.5,2.67]],"id":26503913}],"con":true,"img":false}]}
{"op":"mcm","clk":"5347993586","pt":1646212036565,"mc":[{"id":"1.195453615","rc":[{"atl":[[13,1.36]],"id":26503913}],"con":true,"img":false}]}
{"op":"mcm","clk":"5347993595","pt":1646212036669,"mc":[{"id":"1.195453615","rc":[{"atl":[[12,1.46]],"id":26503913}],"con":true,"img":false}]}
{"op":"mcm","clk":"5347993611","pt":1646212036873,"mc":[{"id":"1.195453615","rc":[{"atl":[[13,0.28]],"id":26503913}],"con":true,"img":false}]}
{"op":"mcm","clk":"5347993615","pt":1646212036977,"mc":[{"id":"1.195453615","rc":[{"atl":[[12.5,3.75]],"id":26503913}],"con":true,"img":false}]}
{"op":"mcm","clk":"5347993631","pt":1646212037182,"mc":[{"id":"1.195453615","rc":[{"atl":[[12.5,2.67]],"id":26503913}],"con":true,"img":false}]}
{"op":"mcm","clk":"5347993639","pt":1646212037292,"mc":[{"id":"1.195453615","rc":[{"atl":[[13.5,1.08]],"id":26503913}],"con":true,"img":false}]}
{"op":"mcm","clk":"5347993646","pt":1646212037387,"mc":[{"id":"1.195453615","rc":[{"atl":[[12.5,0]],"id":26503913}],"con":true,"img":false}]}
{"op":"mcm","clk":"5347993650","pt":1646212037489,"mc":[{"id":"1.195453615","rc":[{"atl":[[13.5,3.75]],"id":26503913}],"con":true,"img":false}]}
{"op":"mcm","clk":"5347993666","pt":1646212037751,"mc":[{"id":"1.195453615","rc":[{"atb":[[2.4,0]],"id":28755739}],"con":true,"img":false}]}
{"op":"mcm","clk":"5347993694","pt":1646212038169,"mc":[{"id":"1.195453615","rc":[{"atb":[[2.36,0],[1.04,1.66]],"id":28755739}],"con":true,"img":false}]}
{"op":"mcm","clk":"5347993707","pt":1646212038374,"mc":[{"id":"1.195453615","rc":[{"atb":[[1.04,1.65]],"id":28755739}],"con":true,"img":false}]}
{"op":"mcm","clk":"5347993712","pt":1646212038483,"mc":[{"id":"1.195453615","rc":[{"atb":[[1.04,0]],"id":28755739}],"con":true,"img":false}]}
{"op":"mcm","clk":"5347993716","pt":1646212038580,"mc":[{"id":"1.195453615","rc":[{"atb":[[2.24,1.65]],"id":28755739}],"con":true,"img":false}]}
{"op":"mcm","clk":"5347993790","pt":1646212040173,"mc":[{"id":"1.195453615","rc":[{"atb":[[2.42,0]],"id":28755739}],"con":true,"img":false}]}
{"op":"mcm","clk":"5347993798","pt":1646212040380,"mc":[{"id":"1.195453615","rc":[{"atb":[[2.34,5.44]],"id":28755739}],"con":true,"img":false}]}
{"op":"mcm","clk":"5347993891","pt":1646212041977,"mc":[{"id":"1.195453615","rc":[{"atb":[[2.16,8.69]],"id":28755739}],"con":true,"img":false}]}
{"op":"mcm","clk":"5347994035","pt":1646212044699,"mc":[{"id":"1.195453615","rc":[{"atl":[[14,1.54]],"id":26503913}],"con":true,"img":false}]}
{"op":"mcm","clk":"5347994039","pt":1646212044801,"mc":[{"id":"1.195453615","rc":[{"atl":[[14.5,4.03]],"id":26503913}],"con":true,"img":false}]}
{"op":"mcm","clk":"5347994056","pt":1646212045170,"mc":[{"id":"1.195453615","rc":[{"atl":[[13.5,1.08]],"id":26503913}],"con":true,"img":false}]}
{"op":"mcm","clk":"5347994060","pt":1646212045272,"mc":[{"id":"1.195453615","rc":[{"atl":[[14,4.21]],"id":26503913}],"con":true,"img":false}]}
{"op":"mcm","clk":"5347994160","pt":1646212047280,"mc":[{"id":"1.195453615","rc":[{"atb":[[1.04,2.72]],"id":28755739}],"con":true,"img":false}]}
{"op":"mcm","clk":"5347994187","pt":1646212047697,"mc":[{"id":"1.195453615","rc":[{"atb":[[1.04,0.31]],"id":28755739}],"con":true,"img":false}]}
{"op":"mcm","clk":"5347994215","pt":1646212048202,"mc":[{"id":"1.195453615","rc":[{"atb":[[1.04,0]],"id":28755739}],"con":true,"img":false}]}
{"op":"mcm","clk":"5347994221","pt":1646212048305,"mc":[{"id":"1.195453615","rc":[{"atb":[[2.36,0.31]],"id":28755739}],"con":true,"img":false}]}
{"op":"mcm","clk":"5347994342","pt":1646212050383,"mc":[{"id":"1.195453615","rc":[{"atb":[[2.24,0],[1.04,1.66]],"id":28755739}],"con":true,"img":false}]}
{"op":"mcm","clk":"5347994350","pt":1646212050593,"mc":[{"id":"1.195453615","rc":[{"atb":[[1.04,1.65]],"id":28755739}],"con":true,"img":false}]}
{"op":"mcm","clk":"5347994362","pt":1646212050797,"mc":[{"id":"1.195453615","rc":[{"atb":[[1.04,0]],"id":28755739}],"con":true,"img":false}]}
{"op":"mcm","clk":"5347994368","pt":1646212050899,"mc":[{"id":"1.195453615","rc":[{"atb":[[2.36,1.96]],"id":28755739}],"con":true,"img":false}]}
{"op":"mcm","clk":"5347994424","pt":1646212051882,"mc":[{"id":"1.195453615","rc":[{"atb":[[2.16,0]],"id":28755739}],"con":true,"img":false}]}
{"op":"mcm","clk":"5347994459","pt":1646212052602,"mc":[{"id":"1.195453615","rc":[{"atb":[[2.34,0]],"id":28755739}],"con":true,"img":false}]}
{"op":"mcm","clk":"5347994470","pt":1646212052807,"mc":[{"id":"1.195453615","rc":[{"atb":[[2.38,5.44]],"id":28755739}],"con":true,"img":false}]}
{"op":"mcm","clk":"5347994477","pt":1646212053011,"mc":[{"id":"1.195453615","rc":[{"atb":[[2.22,6.16]],"id":28755739}],"con":true,"img":false}]}
{"op":"mcm","clk":"5347994719","pt":1646212057497,"mc":[{"id":"1.195453615","rc":[{"atl":[[2.82,5.71]],"id":28755739}],"con":true,"img":false}]}
{"op":"mcm","clk":"5347994782","pt":1646212058696,"mc":[{"id":"1.195453615","rc":[{"atb":[[2.18,0]],"id":28755739}],"con":true,"img":false}]}
{"op":"mcm","clk":"5347994784","pt":1646212058794,"mc":[{"id":"1.195453615","rc":[{"atb":[[2.12,52.18]],"id":28755739}],"con":true,"img":false}]}
{"op":"mcm","clk":"5347994822","pt":1646212059830,"mc":[{"id":"1.195453615","rc":[{"atl":[[2.86,10.75]],"id":28755739}],"con":true,"img":false}]}
{"op":"mcm","clk":"5347994869","pt":1646212060820,"mc":[{"id":"1.195453615","rc":[{"atb":[[2.36,1.65]],"id":28755739}],"con":true,"img":false}]}
{"op":"mcm","clk":"5347994914","pt":1646212061594,"mc":[{"id":"1.195453615","rc":[{"atb":[[1.04,2.72]],"id":28755739}],"con":true,"img":false}]}
{"op":"mcm","clk":"5347994936","pt":1646212062007,"mc":[{"id":"1.195453615","rc":[{"atb":[[1.04,0.31]],"id":28755739}],"con":true,"img":false}]}
{"op":"mcm","clk":"5347994966","pt":1646212062526,"mc":[{"id":"1.195453615","rc":[{"atb":[[1.04,0]],"id":28755739}],"con":true,"img":false}]}
{"op":"mcm","clk":"5347994976","pt":1646212062634,"mc":[{"id":"1.195453615","rc":[{"atb":[[2.4,0.31]],"id":28755739}],"con":true,"img":false}]}
{"op":"mcm","clk":"5347995078","pt":1646212065019,"mc":[{"id":"1.195453615","rc":[{"atb":[[2.38,0]],"id":28755739}],"con":true,"img":false}]}
{"op":"mcm","clk":"5347995184","pt":1646212066932,"mc":[{"id":"1.195453615","rc":[{"atb":[[2.38,5.44]],"id":28755739}],"con":true,"img":false}]}
{"op":"mcm","clk":"5347995225","pt":1646212067810,"mc":[{"id":"1.195453615","rc":[{"atl":[[12,0]],"id":26503913}],"con":true,"img":false}]}
{"op":"mcm","clk":"5347995229","pt":1646212067913,"mc":[{"id":"1.195453615","rc":[{"atl":[[13,1.75]],"id":26503913}],"con":true,"img":false}]}
{"op":"mcm","clk":"5347995237","pt":1646212068121,"mc":[{"id":"1.195453615","rc":[{"atb":[[2.22,0]],"id":28755739},{"spn":2.09,"spf":1.0,"id":28755739},{"spn":10.96,"spf":1.0,"id":39784359}],"con":true,"img":false}]}
{"op":"mcm","clk":"5347995270","pt":1646212068738,"mc":[{"id":"1.195453615","rc":[{"atl":[[13.5,0]],"id":26503913}],"con":true,"img":false}]}
{"op":"mcm","clk":"5347995275","pt":1646212068842,"mc":[{"id":"1.195453615","rc":[{"atl":[[13,2.83]],"id":26503913}],"con":true,"img":false}]}
{"op":"mcm","clk":"5347995304","pt":1646212069315,"mc":[{"id":"1.195453615","rc":[{"atl":[[13,1.75]],"id":26503913}],"con":true,"img":false}]}
{"op":"mcm","clk":"5347995310","pt":1646212069418,"mc":[{"id":"1.195453615","rc":[{"atl":[[13.5,1.08]],"id":26503913}],"con":true,"img":false}]}
{"op":"mcm","clk":"5347995341","pt":1646212070138,"mc":[{"id":"1.195453615","rc":[{"atl":[[13.5,0]],"id":26503913}],"con":true,"img":false}]}
{"op":"mcm","clk":"5347995346","pt":1646212070240,"mc":[{"id":"1.195453615","rc":[{"atl":[[13,2.83]],"id":26503913}],"con":true,"img":false}]}
{"op":"mcm","clk":"5347995383","pt":1646212070822,"mc":[{"id":"1.195453615","rc":[{"atl":[[13,1.75]],"id":26503913}],"con":true,"img":false}]}
{"op":"mcm","clk":"5347995388","pt":1646212070925,"mc":[{"id":"1.195453615","rc":[{"atl":[[13.5,1.08]],"id":26503913}],"con":true,"img":false}]}
{"op":"mcm","clk":"5347995414","pt":1646212071641,"mc":[{"id":"1.195453615","rc":[{"atl":[[13.5,0]],"id":26503913}],"con":true,"img":false}]}
{"op":"mcm","clk":"5347995419","pt":1646212071743,"mc":[{"id":"1.195453615","rc":[{"atl":[[13,2.83]],"id":26503913}],"con":true,"img":false}]}
{"op":"mcm","clk":"5347995616","pt":1646212075013,"mc":[{"id":"1.195453615","rc":[{"atb":[[2.4,0]],"id":28755739}],"con":true,"img":false}]}
{"op":"mcm","clk":"5347995685","pt":1646212076657,"mc":[{"id":"1.195453615","rc":[{"atl":[[16.5,0]],"id":26503913}],"con":true,"img":false}]}
{"op":"mcm","clk":"5347995690","pt":1646212076758,"mc":[{"id":"1.195453615","rc":[{"atl":[[15.5,8.71]],"id":26503913}],"con":true,"img":false}]}
{"op":"mcm","clk":"5347995713","pt":1646212077119,"mc":[{"id":"1.195453615","rc":[{"atb":[[2.16,6.48]],"id":28755739}],"con":true,"img":false}]}
{"op":"mcm","clk":"5347995795","pt":1646212079040,"mc":[{"id":"1.195453615","rc":[{"atb":[[2.16,15.17]],"id":28755739}],"con":true,"img":false}]}
{"op":"mcm","clk":"5347995804","pt":1646212079149,"mc":[{"id":"1.195453615","rc":[{"atb":[[2.38,0]],"id":28755739}],"con":true,"img":false}]}
{"op":"mcm","clk":"5347995816","pt":1646212079455,"mc":[{"id":"1.195453615","rc":[{"atb":[[2.4,5.44]],"id":28755739}],"con":true,"img":false}]}
{"op":"mcm","clk":"5347995916","pt":1646212081367,"mc":[{"id":"1.195453615","rc":[{"atb":[[1.04,2.72]],"id":28755739}],"con":true,"img":false}]}
{"op":"mcm","clk":"5347995942","pt":1646212081835,"mc":[{"id":"1.195453615","rc":[{"atb":[[1.04,0.31]],"id":28755739}],"con":true,"img":false}]}
{"op":"mcm","clk":"5347995962","pt":1646212082347,"mc":[{"id":"1.195453615","rc":[{"atb":[[1.04,0]],"id":28755739}],"con":true,"img":false}]}
{"op":"mcm","clk":"5347995967","pt":1646212082452,"mc":[{"id":"1.195453615","rc":[{"atb":[[2.42,0.31]],"id":28755739}],"con":true,"img":false}]}
{"op":"mcm","clk":"5347996469","pt":1646212091558,"mc":[{"id":"1.195453615","rc":[{"atb":[[2.4,0]],"id":28755739}],"con":true,"img":false}]}
{"op":"mcm","clk":"5347996610","pt":1646212094354,"mc":[{"id":"1.195453615","rc":[{"atb":[[2.38,5.44]],"id":28755739}],"con":true,"img":false}]}
{"op":"mcm","clk":"5347996645","pt":1646212094867,"mc":[{"id":"1.195453615","rc":[{"atb":[[2.42,0]],"id":28755739}],"con":true,"img":false}]}
{"op":"mcm","clk":"5347996825","pt":1646212098662,"mc":[{"id":"1.195453615","rc":[{"atb":[[2.12,0]],"id":28755739}],"con":true,"img":false}]}
{"op":"mcm","clk":"5347996831","pt":1646212098771,"mc":[{"id":"1.195453615","rc":[{"atb":[[2.18,52.18]],"id":28755739}],"con":true,"img":false}]}
{"op":"mcm","clk":"5347996945","pt":1646212100778,"mc":[{"id":"1.195453615","rc":[{"atb":[[1.04,2.72]],"id":28755739}],"con":true,"img":false}]}
{"op":"mcm","clk":"5347996971","pt":1646212101291,"mc":[{"id":"1.195453615","rc":[{"atb":[[1.04,0.31]],"id":28755739}],"con":true,"img":false}]}
{"op":"mcm","clk":"5347996996","pt":1646212101806,"mc":[{"id":"1.195453615","rc":[{"atb":[[1.04,0]],"id":28755739}],"con":true,"img":false}]}
{"op":"mcm","clk":"5347997003","pt":1646212101909,"mc":[{"id":"1.195453615","rc":[{"atb":[[2.4,0.31]],"id":28755739}],"con":true,"img":false}]}
{"op":"mcm","clk":"5347997229","pt":1646212106715,"mc":[{"id":"1.195453615","rc":[{"atb":[[2.38,0]],"id":28755739}],"con":true,"img":false}]}
{"op":"mcm","clk":"5347997243","pt":1646212106977,"mc":[{"id":"1.195453615","rc":[{"atb":[[2.4,5.76]],"id":28755739}],"con":true,"img":false}]}
{"op":"mcm","clk":"5347997251","pt":1646212107077,"mc":[{"id":"1.195453615","rc":[{"atb":[[2.36,0],[1.04,1.66]],"id":28755739}],"con":true,"img":false}]}
{"op":"mcm","clk":"5347997257","pt":1646212107180,"mc":[{"id":"1.195453615","rc":[{"atb":[[2.16,8.69]],"id":28755739}],"con":true,"img":false}]}
{"op":"mcm","clk":"5347997264","pt":1646212107287,"mc":[{"id":"1.195453615","rc":[{"atb":[[1.04,1.65]],"id":28755739}],"con":true,"img":false}]}
{"op":"mcm","clk":"5347997276","pt":1646212107491,"mc":[{"id":"1.195453615","rc":[{"atb":[[1.04,0]],"id":28755739}],"con":true,"img":false}]}
{"op":"mcm","clk":"5347997285","pt":1646212107594,"mc":[{"id":"1.195453615","rc":[{"atb":[[2.24,1.65]],"id":28755739}],"con":true,"img":false}]}
{"op":"mcm","clk":"5347997354","pt":1646212108679,"mc":[{"id":"1.195453615","rc":[{"atl":[[32,2.49]],"id":39784359}],"con":true,"img":false}]}
{"op":"mcm","clk":"5347997360","pt":1646212108784,"mc":[{"id":"1.195453615","rc":[{"atl":[[32,1.12],[34,2.72]],"id":39784359}],"con":true,"img":false}]}
{"op":"mcm","clk":"5347997370","pt":1646212108990,"mc":[{"id":"1.195453615","rc":[{"atl":[[32,3.84]],"id":39784359}],"con":true,"img":false}]}
{"op":"mcm","clk":"5347997631","pt":1646212114319,"mc":[{"id":"1.195453615","rc":[{"atb":[[2.4,5.44]],"id":28755739}],"con":true,"img":false}]}
{"op":"mcm","clk":"5347997669","pt":1646212115091,"mc":[{"id":"1.195453615","rc":[{"atb":[[1.04,2.72]],"id":28755739}],"con":true,"img":false}]}
{"op":"mcm","clk":"5347997689","pt":1646212115504,"mc":[{"id":"1.195453615","rc":[{"atb":[[1.04,0.31]],"id":28755739}],"con":true,"img":false}]}
{"op":"mcm","clk":"5347997713","pt":1646212115921,"mc":[{"id":"1.195453615","rc":[{"atb":[[1.04,0]],"id":28755739}],"con":true,"img":false}]}
{"op":"mcm","clk":"5347997722","pt":1646212116028,"mc":[{"id":"1.195453615","rc":[{"atb":[[2.42,0.31]],"id":28755739}],"con":true,"img":false}]}
{"op":"mcm","clk":"5347997727","pt":1646212116129,"mc":[{"id":"1.195453615","rc":[{"atb":[[2.22,6.16]],"id":28755739}],"con":true,"img":false}]}
{"op":"mcm","clk":"5347997743","pt":1646212116285,"mc":[{"id":"1.195453615","rc":[{"atb":[[2.16,0]],"id":28755739}],"con":true,"img":false}]}
{"op":"mcm","clk":"5347997903","pt":1646212119199,"mc":[{"id":"1.195453615","rc":[{"atb":[[2.4,0],[2.24,0],[1.04,1.66]],"id":28755739}],"con":true,"img":false}]}
{"op":"mcm","clk":"5347997911","pt":1646212119298,"mc":[{"id":"1.195453615","rc":[{"atb":[[1.04,1.65]],"id":28755739}],"con":true,"img":false}]}
{"op":"mcm","clk":"5347997919","pt":1646212119506,"mc":[{"id":"1.195453615","rc":[{"atb":[[1.04,0]],"id":28755739}],"con":true,"img":false}]}
{"op":"mcm","clk":"5347997924","pt":1646212119607,"mc":[{"id":"1.195453615","rc":[{"atb":[[2.36,1.65]],"id":28755739}],"con":true,"img":false}]}
{"op":"mcm","clk":"5347997947","pt":1646212120129,"mc":[{"id":"1.195453615","rc":[{"atb":[[2.38,5.44]],"id":28755739}],"con":true,"img":false}]}
{"op":"mcm","clk":"5347998087","pt":1646212122609,"mc":[{"id":"1.195453615","rc":[{"atl":[[14.5,0]],"id":26503913}],"con":true,"img":false}]}
{"op":"mcm","clk":"5347998094","pt":1646212122718,"mc":[{"id":"1.195453615","rc":[{"atl":[[13.5,4.03]],"id":26503913}],"con":true,"img":false}]}
{"op":"mcm","clk":"5347998112","pt":1646212123027,"mc":[{"id":"1.195453615","rc":[{"atl":[[14,1.54]],"id":26503913}],"con":true,"img":false}]}
{"op":"mcm","clk":"5347998116","pt":1646212123131,"mc":[{"id":"1.195453615","rc":[{"atl":[[12.5,2.67]],"id":26503913}],"con":true,"img":false}]}
{"op":"mcm","clk":"5347998145","pt":1646212123794,"mc":[{"id":"1.195453615","rc":[{"atl":[[13,1.36]],"id":26503913}],"con":true,"img":false}]}
{"op":"mcm","clk":"5347998150","pt":1646212123906,"mc":[{"id":"1.195453615","rc":[{"atl":[[12,1.46]],"id":26503913}],"con":true,"img":false}]}
{"op":"mcm","clk":"5347998176","pt":1646212124257,"mc":[{"id":"1.195453615","rc":[{"atl":[[12.5,0],[13,0.28]],"id":26503913}],"con":true,"img":false}]}
{"op":"mcm","clk":"5347998181","pt":1646212124359,"mc":[{"id":"1.195453615","rc":[{"atl":[[12.5,1.08],[1000,2.67]],"id":26503913}],"con":true,"img":false}]}
{"op":"mcm","clk":"5347998194","pt":1646212124513,"mc":[{"id":"1.195453615","rc":[{"atl":[[12.5,0]],"id":26503913}],"con":true,"img":false}]}
{"op":"mcm","clk":"5347998202","pt":1646212124615,"mc":[{"id":"1.195453615","rc":[{"atl":[[13,1.36]],"id":26503913}],"con":true,"img":false}]}
{"op":"mcm","clk":"5347998206","pt":1646212124721,"mc":[{"id":"1.195453615","rc":[{"atb":[[2.18,0]],"id":28755739}],"con":true,"img":false}]}
{"op":"mcm","clk":"5347998210","pt":1646212124821,"mc":[{"id":"1.195453615","rc":[{"atb":[[2.12,52.18]],"id":28755739}],"con":true,"img":false}]}
{"op":"mcm","clk":"5347998298","pt":1646212126610,"mc":[{"id":"1.195453615","rc":[{"atl":[[13.5,0]],"id":26503913}],"con":true,"img":false}]}
{"op":"mcm","clk":"5347998303","pt":1646212126715,"mc":[{"id":"1.195453615","rc":[{"atl":[[15,7.6]],"id":26503913}],"con":true,"img":false}]}
{"op":"mcm","clk":"5347998337","pt":1646212127243,"mc":[{"id":"1.195453615","rc":[{"atl":[[1000,0]],"id":26503913}],"con":true,"img":false}]}
{"op":"mcm","clk":"5347998344","pt":1646212127349,"mc":[{"id":"1.195453615","rc":[{"atl":[[14.5,2.67]],"id":26503913}],"con":true,"img":false}]}
{"op":"mcm","clk":"5347998368","pt":1646212127708,"mc":[{"id":"1.195453615","rc":[{"atl":[[13,0.28]],"id":26503913}],"con":true,"img":false}]}
{"op":"mcm","clk":"5347998375","pt":1646212127811,"mc":[{"id":"1.195453615","rc":[{"atl":[[14.5,3.75]],"id":26503913}],"con":true,"img":false}]}
{"op":"mcm","clk":"5347998402","pt":1646212128324,"mc":[{"id":"1.195453615","rc":[{"atl":[[14.5,2.67]],"id":26503913},{"spn":2.1,"spf":1.0,"id":28755739}],"con":true,"img":false}]}
{"op":"mcm","clk":"5347998406","pt":1646212128427,"mc":[{"id":"1.195453615","rc":[{"atl":[[14,2.62]],"id":26503913}],"con":true,"img":false}]}
{"op":"mcm","clk":"5347998411","pt":1646212128528,"mc":[{"id":"1.195453615","rc":[{"atb":[[2.42,0]],"id":28755739}],"con":true,"img":false}]}
{"op":"mcm","clk":"5347998451","pt":1646212129511,"mc":[{"id":"1.195453615","rc":[{"atb":[[10,2.63]],"id":39784359}],"con":true,"img":false}]}
{"op":"mcm","clk":"5347998516","pt":1646212131111,"mc":[{"id":"1.195453615","rc":[{"atb":[[2.22,0]],"id":28755739}],"con":true,"img":false}]}
{"op":"mcm","clk":"5347998585","pt":1646212132268,"mc":[{"id":"1.195453615","rc":[{"atb":[[2.38,0]],"id":28755739}],"con":true,"img":false}]}
{"op":"mcm","clk":"5347998614","pt":1646212132664,"mc":[{"id":"1.195453615","rc":[{"atl":[[14.5,0]],"id":26503913}],"con":true,"img":false}]}
{"op":"mcm","clk":"5347998617","pt":1646212132757,"mc":[{"id":"1.195453615","rc":[{"atl":[[13.5,2.67]],"id":26503913}],"con":true,"img":false}]}
{"op":"mcm","clk":"5347998707","pt":1646212134048,"mc":[{"id":"1.195453615","rc":[{"atl":[[14,1.54]],"id":26503913}],"con":true,"img":false}]}
{"op":"mcm","clk":"5347998721","pt":1646212134256,"mc":[{"id":"1.195453615","rc":[{"atl":[[13.5,3.75]],"id":26503913}],"con":true,"img":false}]}
{"op":"mcm","clk":"5347998732","pt":1646212134411,"mc":[{"id":"1.195453615","rc":[{"atl":[[13.5,1.08]],"id":26503913}],"con":true,"img":false}]}
{"op":"mcm","clk":"5347998737","pt":1646212134516,"mc":[{"id":"1.195453615","rc":[{"atl":[[14.5,2.67]],"id":26503913}],"con":true,"img":false}]}
{"op":"mcm","clk":"5347998741","pt":1646212134617,"mc":[{"id":"1.195453615","rc":[{"atl":[[34,0]],"id":39784359}],"con":true,"img":false}]}
{"op":"mcm","clk":"5347998748","pt":1646212134722,"mc":[{"id":"1.195453615","rc":[{"atl":[[32,1.12],[30,2.72]],"id":39784359}],"con":true,"img":false}]}
{"op":"mcm","clk":"5347998800","pt":1646212135238,"mc":[{"id":"1.195453615","rc":[{"atb":[[2.38,5.44]],"id":28755739}],"con":true,"img":false}]}
{"op":"mcm","clk":"5347998812","pt":1646212135442,"mc":[{"id":"1.195453615","rc":[{"atb":[[2.36,0],[1.04,4.39]],"id":28755739}],"con":true,"img":false}]}
{"op":"mcm","clk":"5347998819","pt":1646212135647,"mc":[{"id":"1.195453615","rc":[{"atb":[[1.04,4.38]],"id":28755739}],"con":true,"img":false}]}
{"op":"mcm","clk":"5347998832","pt":1646212135855,"mc":[{"id":"1.195453615","rc":[{"atl":[[13.5,0]],"id":26503913},{"atb":[[1.04,0.31]],"id":28755739}],"con":true,"img":false}]}
{"op":"mcm","clk":"5347998837","pt":1646212135959,"mc":[{"id":"1.195453615","rc":[{"atl":[[14.5,3.75]],"id":26503913},{"atb":[[2.18,1.65]],"id":28755739}],"con":true,"img":false}]}
{"op":"mcm","clk":"5347998849","pt":1646212136225,"mc":[{"id":"1.195453615","rc":[{"atb":[[1.04,0]],"id":28755739}],"con":true,"img":false}]}
{"op":"mcm","clk":"5347998853","pt":1646212136321,"mc":[{"id":"1.195453615","rc":[{"atb":[[2.38,5.76]],"id":28755739}],"con":true,"img":false}]}
{"op":"mcm","clk":"5347998871","pt":1646212136739,"mc":[{"id":"1.195453615","rc":[{"atl":[[14.5,2.67]],"id":26503913}],"con":true,"img":false}]}
{"op":"mcm","clk":"5347998876","pt":1646212136844,"mc":[{"id":"1.195453615","rc":[{"atl":[[14,2.62]],"id":26503913}],"con":true,"img":false}]}
{"op":"mcm","clk":"5347999098","pt":1646212140359,"mc":[{"id":"1.195453615","rc":[{"atb":[[2.16,8.69]],"id":28755739}],"con":true,"img":false}]}
{"op":"mcm","clk":"5347999154","pt":1646212141443,"mc":[{"id":"1.195453615","rc":[{"atl":[[29,2.68]],"id":39784359}],"con":true,"img":false}]}
{"op":"mcm","clk":"5347999203","pt":1646212142641,"mc":[{"id":"1.195453615","rc":[{"atl":[[30,0]],"id":39784359}],"con":true,"img":false}]}
{"op":"mcm","clk":"5347999206","pt":1646212142744,"mc":[{"id":"1.195453615","rc":[{"atl":[[34,2.72]],"id":39784359}],"con":true,"img":false}]}
{"op":"mcm","clk":"5347999224","pt":1646212143156,"mc":[{"id":"1.195453615","rc":[{"atb":[[2.16,15.17]],"id":28755739}],"con":true,"img":false}]}
{"op":"mcm","clk":"5347999408","pt":1646212147434,"mc":[{"id":"1.195453615","rc":[{"atb":[[2.38,0.31]],"id":28755739}],"con":true,"img":false}]}
{"op":"mcm","clk":"5347999412","pt":1646212147541,"mc":[{"id":"1.195453615","rc":[{"atb":[[2.18,0],[1.04,1.66]],"id":28755739}],"con":true,"img":false}]}
{"op":"mcm","clk":"5347999413","pt":1646212147639,"mc":[{"id":"1.195453615","rc":[{"atb":[[2.4,5.44]],"id":28755739}],"con":true,"img":false}]}
{"op":"mcm","clk":"5347999418","pt":1646212147743,"mc":[{"id":"1.195453615","rc":[{"atb":[[1.04,1.65]],"id":28755739}],"con":true,"img":false}]}
{"op":"mcm","clk":"5347999421","pt":1646212147952,"mc":[{"id":"1.195453615","rc":[{"atb":[[1.04,0]],"id":28755739}],"con":true,"img":false}]}
{"op":"mcm","clk":"5347999427","pt":1646212148054,"mc":[{"id":"1.195453615","rc":[{"atb":[[2.36,1.65]],"id":28755739}],"con":true,"img":false}]}
{"op":"mcm","clk":"5347999450","pt":1646212148771,"mc":[{"id":"1.195453615","rc":[{"atb":[[2.38,0]],"id":28755739}],"con":true,"img":false}]}
{"op":"mcm","clk":"5347999621","pt":1646212152653,"mc":[{"id":"1.195453615","rc":[{"atl":[[15,3.57]],"id":26503913}],"con":true,"img":false}]}
{"op":"mcm","clk":"5347999627","pt":1646212152759,"mc":[{"id":"1.195453615","rc":[{"atl":[[14,6.65]],"id":26503913}],"con":true,"img":false}]}
{"op":"mcm","clk":"5347999682","pt":1646212153888,"mc":[{"id":"1.195453615","rc":[{"atl":[[12,0]],"id":26503913}],"con":true,"img":false}]}
{"op":"mcm","clk":"5347999690","pt":1646212153993,"mc":[{"id":"1.195453615","rc":[{"atl":[[13.5,1.46]],"id":26503913}],"con":true,"img":false}]}
{"op":"mcm","clk":"5347999727","pt":1646212154762,"mc":[{"id":"1.195453615","rc":[{"atl":[[14,5.57]],"id":26503913}],"con":true,"img":false}]}
{"op":"mcm","clk":"5347999731","pt":1646212154867,"mc":[{"id":"1.195453615","rc":[{"atl":[[13.5,2.55]],"id":26503913}],"con":true,"img":false}]}
{"op":"mcm","clk":"5347999783","pt":1646212155906,"mc":[{"id":"1.195453615","rc":[{"atb":[[1.04,2.72]],"id":28755739}],"con":true,"img":false}]}
{"op":"mcm","clk":"5347999798","pt":1646212156257,"mc":[{"id":"1.195453615","rc":[{"atb":[[1.04,0.31]],"id":28755739}],"con":true,"img":false}]}
{"op":"mcm","clk":"5347999831","pt":1646212156774,"mc":[{"id":"1.195453615","rc":[{"atb":[[1.04,0]],"id":28755739}],"con":true,"img":false}]}
{"op":"mcm","clk":"5347999835","pt":1646212156876,"mc":[{"id":"1.195453615","rc":[{"atb":[[2.42,0.31]],"id":28755739}],"con":true,"img":false}]}
{"op":"mcm","clk":"5347999961","pt":1646212159765,"mc":[{"id":"1.195453615","rc":[{"atb":[[2.4,0]],"id":28755739}],"con":true,"img":false}]}
{"op":"mcm","clk":"5348000035","pt":1646212161408,"mc":[{"id":"1.195453615","rc":[{"atb":[[2.38,5.44]],"id":28755739}],"con":true,"img":false}]}
{"op":"mcm","clk":"5348000087","pt":1646212162699,"mc":[{"id":"1.195453615","rc":[{"atb":[[2.12,0]],"id":28755739}],"con":true,"img":false}]}
{"op":"mcm","clk":"5348000089","pt":1646212162802,"mc":[{"id":"1.195453615","rc":[{"atb":[[2.18,52.18]],"id":28755739}],"con":true,"img":false}]}
{"op":"mcm","clk":"5348000283","pt":1646212166709,"mc":[{"id":"1.195453615","rc":[{"atl":[[34,0]],"id":39784359}],"con":true,"img":false}]}
{"op":"mcm","clk":"5348000287","pt":1646212166809,"mc":[{"id":"1.195453615","rc":[{"atl":[[32,3.84]],"id":39784359}],"con":true,"img":false}]}
{"op":"mcm","clk":"5348000292","pt":1646212166916,"mc":[{"id":"1.195453615","rc":[{"atl":[[29,0]],"id":39784359}],"con":true,"img":false}]}
{"op":"mcm","clk":"5348000408","pt":1646212169282,"mc":[{"id":"1.195453615","rc":[{"atb":[[2.42,0]],"id":28755739}],"con":true,"img":false}]}
{"op":"mcm","clk":"5348000504","pt":1646212171300,"mc":[{"id":"1.195453615","rc":[{"atb":[[2.16,8.69]],"id":28755739}],"con":true,"img":false}]}
{"op":"mcm","clk":"5348000609","pt":1646212173203,"mc":[{"id":"1.195453615","rc":[{"atl":[[30,2.68]],"id":39784359}],"con":true,"img":false}]}
{"op":"mcm","clk":"5348000627","pt":1646212173612,"mc":[{"id":"1.195453615","rc":[{"atb":[[2.38,0]],"id":28755739}],"con":true,"img":false}]}
{"op":"mcm","clk":"5348000634","pt":1646212173818,"mc":[{"id":"1.195453615","rc":[{"atb":[[2.4,5.44]],"id":28755739}],"con":true,"img":false}]}
{"op":"mcm","clk":"5348000672","pt":1646212174700,"mc":[{"id":"1.195453615","rc":[{"atl":[[32,1.12]],"id":39784359}],"con":true,"img":false}]}
{"op":"mcm","clk":"5348000676","pt":1646212174801,"mc":[{"id":"1.195453615","rc":[{"atl":[[34,2.72]],"id":39784359}],"con":true,"img":false}]}
{"op":"mcm","clk":"5348000725","pt":1646212176134,"mc":[{"id":"1.195453615","rc":[{"atb":[[1.04,2.72]],"id":28755739}],"con":true,"img":false}]}
{"op":"mcm","clk":"5348000738","pt":1646212176441,"mc":[{"id":"1.195453615","rc":[{"atb":[[2.16,0]],"id":28755739}],"con":true,"img":false}]}
{"op":"mcm","clk":"5348000744","pt":1646212176499,"mc":[{"id":"1.195453615","rc":[{"atb":[[1.04,0.31]],"id":28755739}],"con":true,"img":false}]}
{"op":"mcm","clk":"5348000762","pt":1646212177016,"mc":[{"id":"1.195453615","rc":[{"atb":[[1.04,0]],"id":28755739}],"con":true,"img":false}]}
{"op":"mcm","clk":"5348000767","pt":1646212177115,"mc":[{"id":"1.195453615","rc":[{"atb":[[2.42,0.31]],"id":28755739}],"con":true,"img":false}]}
{"op":"mcm","clk":"5348000899","pt":1646212179330,"mc":[{"id":"1.195453615","rc":[{"atb":[[2.22,6.16]],"id":28755739}],"con":true,"img":false}]}
{"op":"mcm","clk":"5348001063","pt":1646212182639,"mc":[{"id":"1.195453615","rc":[{"atb":[[2.18,0]],"id":28755739}],"con":true,"img":false}]}
{"op":"mcm","clk":"5348001070","pt":1646212182742,"mc":[{"id":"1.195453615","rc":[{"atb":[[2.12,52.18]],"id":28755739}],"con":true,"img":false}]}
{"op":"mcm","clk":"5348001106","pt":1646212183313,"mc":[{"id":"1.195453615","rc":[{"atl":[[14.5,0]],"id":26503913}],"con":true,"img":false}]}
{"op":"mcm","clk":"5348001112","pt":1646212183417,"mc":[{"id":"1.195453615","rc":[{"atl":[[13,2.96]],"id":26503913}],"con":true,"img":false}]}
{"op":"mcm","clk":"5348001162","pt":1646212184139,"mc":[{"id":"1.195453615","rc":[{"atl":[[13.5,0]],"id":26503913}],"con":true,"img":false}]}
{"op":"mcm","clk":"5348001168","pt":1646212184243,"mc":[{"id":"1.195453615","rc":[{"atl":[[12.5,1.46],[13,4.04]],"id":26503913}],"con":true,"img":false}]}
{"op":"mcm","clk":"5348001191","pt":1646212184606,"mc":[{"id":"1.195453615","rc":[{"atl":[[13,1.36]],"id":26503913}],"con":true,"img":false}]}
{"op":"mcm","clk":"5348001200","pt":1646212184757,"mc":[{"id":"1.195453615","rc":[{"atl":[[13.5,2.67]],"id":26503913}],"con":true,"img":false}]}
{"op":"mcm","clk":"5348001267","pt":1646212186045,"mc":[{"id":"1.195453615","rc":[{"atb":[[2.4,0]],"id":28755739}],"con":true,"img":false}]}
{"op":"mcm","clk":"5348001425","pt":1646212189649,"mc":[{"id":"1.195453615","rc":[{"atb":[[2.42,0]],"id":28755739},{"spn":2.08,"spf":1.0,"id":28755739},{"spn":11.0,"spf":1.0,"id":39784359}],"con":true,"img":false}]}
{"op":"mcm","clk":"5348001450","pt":1646212190218,"mc":[{"id":"1.195453615","rc":[{"atb":[[2.38,5.44]],"id":28755739}],"con":true,"img":false}]}
{"op":"mcm","clk":"5348001500","pt":1646212191344,"mc":[{"id":"1.195453615","rc":[{"atb":[[2.22,0]],"id":28755739}],"con":true,"img":false}]}
{"op":"mcm","clk":"5348001703","pt":1646212195532,"mc":[{"id":"1.195453615","rc":[{"atb":[[1.04,2.72]],"id":28755739}],"con":true,"img":false}]}
{"op":"mcm","clk":"5348001724","pt":1646212195949,"mc":[{"id":"1.195453615","rc":[{"atb":[[1.04,0.31]],"id":28755739}],"con":true,"img":false}]}
{"op":"mcm","clk":"5348001741","pt":1646212196464,"mc":[{"id":"1.195453615","rc":[{"atb":[[1.04,0]],"id":28755739}],"con":true,"img":false}]}
{"op":"mcm","clk":"5348001747","pt":1646212196573,"mc":[{"id":"1.195453615","rc":[{"atb":[[2.4,0.31]],"id":28755739}],"con":true,"img":false}]}
{"op":"mcm","clk":"5348001862","pt":1646212199160,"mc":[{"id":"1.195453615","rc":[{"atb":[[2.16,8.69]],"id":28755739}],"con":true,"img":false}]}
{"op":"mcm","clk":"5348002008","pt":1646212202448,"mc":[{"id":"1.195453615","rc":[{"atb":[[2.38,0]],"id":28755739}],"con":true,"img":false}]}
{"op":"mcm","clk":"5348002017","pt":1646212202650,"mc":[{"id":"1.195453615","rc":[{"atb":[[2.4,5.76]],"id":28755739}],"con":true,"img":false}]}
{"op":"mcm","clk":"5348002047","pt":1646212203374,"mc":[{"id":"1.195453615","rc":[{"atb":[[2.16,15.17]],"id":28755739}],"con":true,"img":false}]}
{"op":"mcm","clk":"5348002089","pt":1646212204357,"mc":[{"id":"1.195453615","rc":[{"atl":[[30,0]],"id":39784359}],"con":true,"img":false}]}
{"op":"mcm","clk":"5348002094","pt":1646212204460,"mc":[{"id":"1.195453615","rc":[{"atl":[[32,3.8]],"id":39784359}],"con":true,"img":false}]}
{"op":"mcm","clk":"5348002101","pt":1646212204669,"mc":[{"id":"1.195453615","rc":[{"atl":[[14,1.54]],"id":26503913}],"con":true,"img":false}]}
{"op":"mcm","clk":"5348002105","pt":1646212204768,"mc":[{"id":"1.195453615","rc":[{"atl":[[13.5,6.7]],"id":26503913}],"con":true,"img":false}]}
{"op":"mcm","clk":"5348002317","pt":1646212208998,"mc":[{"id":"1.195453615","rc":[{"atb":[[2.4,5.44]],"id":28755739}],"con":true,"img":false}]}
{"op":"mcm","clk":"5348002324","pt":1646212209161,"mc":[{"id":"1.195453615","rc":[{"atl":[[13.5,4.03]],"id":26503913}],"con":true,"img":false}]}
{"op":"mcm","clk":"5348002326","pt":1646212209268,"mc":[{"id":"1.195453615","rc":[{"atl":[[1000,2.67]],"id":26503913}],"con":true,"img":false}]}
{"op":"mcm","clk":"5348002365","pt":1646212210086,"mc":[{"id":"1.195453615","rc":[{"atb":[[1.04,2.72]],"id":28755739}],"con":true,"img":false}]}
{"op":"mcm","clk":"5348002387","pt":1646212210499,"mc":[{"id":"1.195453615","rc":[{"atb":[[1.04,0.31]],"id":28755739}],"con":true,"img":false}]}
{"op":"mcm","clk":"5348002396","pt":1646212210661,"mc":[{"id":"1.195453615","rc":[{"atl":[[13.5,0]],"id":26503913}],"con":true,"img":false}]}
{"op":"mcm","clk":"5348002400","pt":1646212210763,"mc":[{"id":"1.195453615","rc":[{"atl":[[15,7.6]],"id":26503913}],"con":true,"img":false}]}
{"op":"mcm","clk":"5348002405","pt":1646212210867,"mc":[{"id":"1.195453615","rc":[{"atb":[[1.04,0]],"id":28755739}],"con":true,"img":false}]}
{"op":"mcm","clk":"5348002409","pt":1646212210970,"mc":[{"id":"1.195453615","rc":[{"atl":[[1000,0]],"id":26503913},{"atb":[[2.42,0.31]],"id":28755739}],"con":true,"img":false}]}
{"op":"mcm","clk":"5348002416","pt":1646212211074,"mc":[{"id":"1.195453615","rc":[{"atl":[[14.5,2.67]],"id":26503913}],"con":true,"img":false}]}
{"op":"mcm","clk":"5348002443","pt":1646212211688,"mc":[{"id":"1.195453615","rc":[{"atl":[[13,0.28]],"id":26503913}],"con":true,"img":false}]}
{"op":"mcm","clk":"5348002449","pt":1646212211791,"mc":[{"id":"1.195453615","rc":[{"atl":[[14.5,3.75]],"id":26503913}],"con":true,"img":false}]}
{"op":"mcm","clk":"5348002482","pt":1646212212673,"mc":[{"id":"1.195453615","rc":[{"atl":[[14.5,2.67]],"id":26503913}],"con":true,"img":false}]}
{"op":"mcm","clk":"5348002489","pt":1646212212778,"mc":[{"id":"1.195453615","rc":[{"atl":[[14,2.62]],"id":26503913}],"con":true,"img":false}]}
{"op":"mcm","clk":"5348002521","pt":1646212213391,"mc":[{"id":"1.195453615","rc":[{"atl":[[14.5,0]],"id":26503913}],"con":true,"img":false}]}
{"op":"mcm","clk":"5348002526","pt":1646212213497,"mc":[{"id":"1.195453615","rc":[{"atl":[[13.5,2.67]],"id":26503913}],"con":true,"img":false}]}
{"op":"mcm","clk":"5348002561","pt":1646212214173,"mc":[{"id":"1.195453615","rc":[{"atl":[[12.5,0]],"id":26503913}],"con":true,"img":false}]}
{"op":"mcm","clk":"5348002567","pt":1646212214275,"mc":[{"id":"1.195453615","rc":[{"atl":[[13,1.75]],"id":26503913}],"con":true,"img":false}]}
{"op":"mcm","clk":"5348002578","pt":1646212214480,"mc":[{"id":"1.195453615","rc":[{"atl":[[14,1.54]],"id":26503913}],"con":true,"img":false}]}
{"op":"mcm","clk":"5348002583","pt":1646212214587,"mc":[{"id":"1.195453615","rc":[{"atl":[[13.5,3.75]],"id":26503913}],"con":true,"img":false}]}
{"op":"mcm","clk":"5348002597","pt":1646212214890,"mc":[{"id":"1.195453615","rc":[{"atb":[[2.4,0]],"id":28755739}],"con":true,"img":false}]}
{"op":"mcm","clk":"5348002613","pt":1646212215199,"mc":[{"id":"1.195453615","rc":[{"atl":[[13.5,1.08]],"id":26503913}],"con":true,"img":false}]}
{"op":"mcm","clk":"5348002620","pt":1646212215305,"mc":[{"id":"1.195453615","rc":[{"atl":[[14.5,2.67]],"id":26503913}],"con":true,"img":false}]}
{"op":"mcm","clk":"5348002626","pt":1646212215405,"mc":[{"id":"1.195453615","rc":[{"atl":[[13.5,0]],"id":26503913}],"con":true,"img":false}]}
{"op":"mcm","clk":"5348002631","pt":1646212215507,"mc":[{"id":"1.195453615","rc":[{"atl":[[13,2.83]],"id":26503913}],"con":true,"img":false}]}
{"op":"mcm","clk":"5348002664","pt":1646212216186,"mc":[{"id":"1.195453615","rc":[{"atb":[[2.36,0],[1.04,1.66]],"id":28755739}],"con":true,"img":false}]}
{"op":"mcm","clk":"5348002670","pt":1646212216286,"mc":[{"id":"1.195453615","rc":[{"atl":[[13,1.75]],"id":26503913}],"con":true,"img":false}]}
{"op":"mcm","clk":"5348002678","pt":1646212216390,"mc":[{"id":"1.195453615","rc":[{"atl":[[14.5,3.75]],"id":26503913},{"atb":[[1.04,1.65]],"id":28755739}],"con":true,"img":false}]}
{"op":"mcm","clk":"5348002682","pt":1646212216490,"mc":[{"id":"1.195453615","rc":[{"atb":[[2.34,5.44]],"id":28755739}],"con":true,"img":false}]}
{"op":"mcm","clk":"5348002686","pt":1646212216598,"mc":[{"id":"1.195453615","rc":[{"atb":[[1.04,0]],"id":28755739}],"con":true,"img":false}]}
{"op":"mcm","clk":"5348002691","pt":1646212216700,"mc":[{"id":"1.195453615","rc":[{"atb":[[2.22,1.65]],"id":28755739}],"con":true,"img":false}]}
{"op":"mcm","clk":"5348002696","pt":1646212216799,"mc":[{"id":"1.195453615","rc":[{"atl":[[14.5,2.67]],"id":26503913}],"con":true,"img":false}]}
{"op":"mcm","clk":"5348002700","pt":1646212216905,"mc":[{"id":"1.195453615","rc":[{"atl":[[13,2.83]],"id":26503913}],"con":true,"img":false}]}
{"op":"mcm","clk":"5348002715","pt":1646212217267,"mc":[{"id":"1.195453615","rc":[{"atl":[[13,1.75]],"id":26503913}],"con":true,"img":false}]}
{"op":"mcm","clk":"5348002718","pt":1646212217364,"mc":[{"id":"1.195453615","rc":[{"atl":[[14,2.62]],"id":26503913}],"con":true,"img":false}]}
{"op":"mcm","clk":"5348002756","pt":1646212218195,"mc":[{"id":"1.195453615","rc":[{"atl":[[13,0.28]],"id":26503913}],"con":true,"img":false}]}
{"op":"mcm","clk":"5348002768","pt":1646212218296,"mc":[{"id":"1.195453615","rc":[{"atl":[[13.5,1.46]],"id":26503913}],"con":true,"img":false}]}
{"op":"mcm","clk":"5348002779","pt":1646212218606,"mc":[{"id":"1.195453615","rc":[{"atb":[[2.18,7.3]],"id":28755739}],"con":true,"img":false}]}
{"op":"mcm","clk":"5348003063","pt":1646212222906,"mc":[{"id":"1.195453615","rc":[{"atb":[[2.18,0]],"id":28755739}],"con":true,"img":false}]}
{"op":"mcm","clk":"5348003108","pt":1646212223415,"mc":[{"id":"1.195453615","rc":[{"atb":[[2.42,0]],"id":28755739}],"con":true,"img":false}]}
{"op":"mcm","clk":"5348003160","pt":1646212224702,"mc":[{"id":"1.195453615","rc":[{"atb":[[2.12,0]],"id":28755739},{"atl":[[34,0]],"id":39784359}],"con":true,"img":false}]}
{"op":"mcm","clk":"5348003162","pt":1646212224804,"mc":[{"id":"1.195453615","rc":[{"atb":[[2.18,52.18]],"id":28755739},{"atl":[[30,2.72]],"id":39784359}],"con":true,"img":false}]}
{"op":"mcm","clk":"5348003167","pt":1646212224906,"mc":[{"id":"1.195453615","rc":[{"atl":[[32,1.12]],"id":39784359}],"con":true,"img":false}]}
{"op":"mcm","clk":"5348003171","pt":1646212225110,"mc":[{"id":"1.195453615","rc":[{"atl":[[14,1.54]],"id":26503913}],"con":true,"img":false}]}
{"op":"mcm","clk":"5348003176","pt":1646212225212,"mc":[{"id":"1.195453615","rc":[{"atl":[[13.5,2.55]],"id":26503913}],"con":true,"img":false}]}
{"op":"mcm","clk":"5348003338","pt":1646212228518,"mc":[{"id":"1.195453615","rc":[{"atb":[[2.22,0],[1.04,1.66]],"id":28755739}],"con":true,"img":false}]}
{"op":"mcm","clk":"5348003343","pt":1646212228625,"mc":[{"id":"1.195453615","rc":[{"atb":[[1.04,1.65]],"id":28755739}],"con":true,"img":false}]}
{"op":"mcm","clk":"5348003346","pt":1646212228723,"mc":[{"id":"1.195453615","rc":[{"atb":[[2.34,0]],"id":28755739}],"con":true,"img":false}]}
{"op":"mcm","clk":"5348003348","pt":1646212228823,"mc":[{"id":"1.195453615","rc":[{"atb":[[1.04,0]],"id":28755739}],"con":true,"img":false}]}
{"op":"mcm","clk":"5348003357","pt":1646212228884,"mc":[{"id":"1.195453615","rc":[{"atb":[[2.36,1.65]],"id":28755739}],"con":true,"img":false}]}
{"op":"mcm","clk":"5348003401","pt":1646212230015,"mc":[{"id":"1.195453615","rc":[{"atb":[[1.04,2.72]],"id":28755739}],"con":true,"img":false}]}
{"op":"mcm","clk":"5348003419","pt":1646212230425,"mc":[{"id":"1.195453615","rc":[{"atb":[[1.04,0.31]],"id":28755739}],"con":true,"img":false}]}
{"op":"mcm","clk":"5348003444","pt":1646212230896,"mc":[{"id":"1.195453615","rc":[{"atb":[[1.04,0]],"id":28755739}],"con":true,"img":false}]}
{"op":"mcm","clk":"5348003449","pt":1646212230999,"mc":[{"id":"1.195453615","rc":[{"atb":[[2.38,0.31]],"id":28755739}],"con":true,"img":false}]}
{"op":"mcm","clk":"5348003463","pt":1646212231307,"mc":[{"id":"1.195453615","rc":[{"atb":[[2.2,6.38]],"id":28755739}],"con":true,"img":false}]}
{"op":"mcm","clk":"5348003493","pt":1646212232027,"mc":[{"id":"1.195453615","rc":[{"atb":[[2.38,5.76]],"id":28755739}],"con":true,"img":false}]}
{"op":"mcm","clk":"5348003526","pt":1646212232612,"mc":[{"id":"1.195453615","rc":[{"atl":[[30,0]],"id":39784359}],"con":true,"img":false}]}
{"op":"mcm","clk":"5348003534","pt":1646212232717,"mc":[{"id":"1.195453615","rc":[{"atl":[[34,2.72]],"id":39784359}],"con":true,"img":false}]}
{"op":"mcm","clk":"5348003564","pt":1646212233441,"mc":[{"id":"1.195453615","rc":[{"atb":[[2.16,8.69]],"id":28755739}],"con":true,"img":false}]}
{"op":"mcm","clk":"5348003568","pt":1646212233504,"mc":[{"id":"1.195453615","rc":[{"atb":[[2.2,0]],"id":28755739}],"con":true,"img":false}]}
{"op":"mcm","clk":"5348003632","pt":1646212235002,"mc":[{"id":"1.195453615","rc":[{"atl":[[32,3.8]],"id":39784359}],"con":true,"img":false}]}
{"op":"mcm","clk":"5348003699","pt":1646212236707,"mc":[{"id":"1.195453615","rc":[{"atl":[[15,3.57]],"id":26503913}],"con":true,"img":false}]}
{"op":"mcm","clk":"5348003706","pt":1646212236812,"mc":[{"id":"1.195453615","rc":[{"atl":[[14,5.57]],"id":26503913}],"con":true,"img":false}]}
{"op":"mcm","clk":"5348003713","pt":1646212237014,"mc":[{"id":"1.195453615","rc":[{"atl":[[13,0],[1000,2.25]],"id":26503913}],"con":true,"img":false}]}
{"op":"mcm","clk":"5348003719","pt":1646212237117,"mc":[{"id":"1.195453615","rc":[{"atl":[[1000,0.28]],"id":26503913}],"con":true,"img":false}]}
{"op":"mcm","clk":"5348003724","pt":1646212237224,"mc":[{"id":"1.195453615","rc":[{"atl":[[1000,0]],"id":26503913}],"con":true,"img":false}]}
{"op":"mcm","clk":"5348003727","pt":1646212237321,"mc":[{"id":"1.195453615","rc":[{"atl":[[13.5,2.83]],"id":26503913}],"con":true,"img":false}]}
{"op":"mcm","clk":"5348003997","pt":1646212242445,"mc":[{"id":"1.195453615","rc":[{"atb":[[2.22,6.16]],"id":28755739}],"con":true,"img":false}]}
{"op":"mcm","clk":"5348004069","pt":1646212243531,"mc":[{"id":"1.195453615","rc":[{"atb":[[2.38,5.44]],"id":28755739}],"con":true,"img":false}]}
{"op":"mcm","clk":"5348004115","pt":1646212244255,"mc":[{"id":"1.195453615","rc":[{"atb":[[2.38,0]],"id":28755739}],"con":true,"img":false}]}
{"op":"mcm","clk":"5348004121","pt":1646212244308,"mc":[{"id":"1.195453615","rc":[{"atb":[[1.04,2.72]],"id":28755739}],"con":true,"img":false}]}
{"op":"mcm","clk":"5348004127","pt":1646212244412,"mc":[{"id":"1.195453615","rc":[{"atb":[[2.4,5.44]],"id":28755739}],"con":true,"img":false}]}
{"op":"mcm","clk":"5348004143","pt":1646212244724,"mc":[{"id":"1.195453615","rc":[{"atb":[[1.04,0.31]],"id":28755739}],"con":true,"img":false}]}
{"op":"mcm","clk":"5348004158","pt":1646212245148,"mc":[{"id":"1.195453615","rc":[{"atb":[[1.04,0]],"id":28755739}],"con":true,"img":false}]}
{"op":"mcm","clk":"5348004164","pt":1646212245246,"mc":[{"id":"1.195453615","rc":[{"atb":[[2.4,5.76]],"id":28755739}],"con":true,"img":false}]}
{"op":"mcm","clk":"5348004260","pt":1646212247512,"mc":[{"id":"1.195453615","rc":[{"atb":[[2.16,0]],"id":28755739}],"con":true,"img":false}]}
{"op":"mcm","clk":"5348004414","pt":1646212250622,"mc":[{"id":"1.195453615","rc":[{"atb":[[2.18,0]],"id":28755739},{"spn":2.07,"spf":1.0,"id":28755739}],"con":true,"img":false}]}
{"op":"mcm","clk":"5348004420","pt":1646212250725,"mc":[{"id":"1.195453615","rc":[{"atb":[[2.12,52.18]],"id":28755739}],"con":true,"img":false}]}
{"op":"mcm","clk":"5348004433","pt":1646212251035,"mc":[{"id":"1.195453615","rc":[{"atl":[[14.5,0]],"id":26503913}],"con":true,"img":false}]}
{"op":"mcm","clk":"5348004438","pt":1646212251140,"mc":[{"id":"1.195453615","rc":[{"atl":[[13,2.67]],"id":26503913}],"con":true,"img":false}]}
{"op":"mcm","clk":"5348004463","pt":1646212251859,"mc":[{"id":"1.195453615","rc":[{"atl":[[13.5,1.36]],"id":26503913}],"con":true,"img":false}]}
{"op":"mcm","clk":"5348004467","pt":1646212251963,"mc":[{"id":"1.195453615","rc":[{"atl":[[12.5,1.46]],"id":26503913}],"con":true,"img":false}]}
{"op":"mcm","clk":"5348004471","pt":1646212252065,"mc":[{"id":"1.195453615","rc":[{"atl":[[13.5,0.28]],"id":26503913}],"con":true,"img":false}]}
{"op":"mcm","clk":"5348004473","pt":1646212252166,"mc":[{"id":"1.195453615","rc":[{"atl":[[13,3.75]],"id":26503913}],"con":true,"img":false}]}
{"op":"mcm","clk":"5348004475","pt":1646212252220,"mc":[{"id":"1.195453615","rc":[{"atl":[[13,1.08]],"id":26503913}],"con":true,"img":false}]}
{"op":"mcm","clk":"5348004478","pt":1646212252323,"mc":[{"id":"1.195453615","rc":[{"atl":[[13.5,2.96]],"id":26503913}],"con":true,"img":false}]}
{"op":"mcm","clk":"5348004514","pt":1646212252841,"mc":[{"id":"1.195453615","rc":[{"atl":[[13,0]],"id":26503913}],"con":true,"img":false}]}
{"op":"mcm","clk":"5348004521","pt":1646212252946,"mc":[{"id":"1.195453615","rc":[{"atl":[[13.5,4.04]],"id":26503913}],"con":true,"img":false}]}
{"op":"mcm","clk":"5348004704","pt":1646212256564,"mc":[{"id":"1.195453615","rc":[{"atb":[[2.4,0.31]],"id":28755739}],"con":true,"img":false}]}
{"op":"mcm","clk":"5348004754","pt":1646212257442,"mc":[{"id":"1.195453615","rc":[{"atb":[[2.22,0]],"id":28755739}],"con":true,"img":false}]}
{"op":"mcm","clk":"5348004774","pt":1646212257754,"mc":[{"id":"1.195453615","rc":[{"atb":[[2.4,0]],"id":28755739}],"con":true,"img":false}]}
{"op":"mcm","clk":"5348004803","pt":1646212258376,"mc":[{"id":"1.195453615","rc":[{"atb":[[2.38,5.44]],"id":28755739}],"con":true,"img":false}]}
{"op":"mcm","clk":"5348004807","pt":1646212258477,"mc":[{"id":"1.195453615","rc":[{"atb":[[1.04,2.72]],"id":28755739}],"con":true,"img":false}]}
{"op":"mcm","clk":"5348004839","pt":1646212258948,"mc":[{"id":"1.195453615","rc":[{"atb":[[1.04,0.31]],"id":28755739}],"con":true,"img":false}]}
{"op":"mcm","clk":"5348004869","pt":1646212259464,"mc":[{"id":"1.195453615","rc":[{"atb":[[1.04,0]],"id":28755739}],"con":true,"img":false}]}
{"op":"mcm","clk":"5348004874","pt":1646212259574,"mc":[{"id":"1.195453615","rc":[{"atb":[[2.38,5.76]],"id":28755739}],"con":true,"img":false}]}
{"op":"mcm","clk":"5348004917","pt":1646212260654,"mc":[{"id":"1.195453615","rc":[{"atl":[[14,1.54]],"id":26503913},{"atl":[[34,0]],"id":39784359}],"con":true,"img":false}]}
{"op":"mcm","clk":"5348004925","pt":1646212260758,"mc":[{"id":"1.195453615","rc":[{"atl":[[15,7.6]],"id":26503913},{"atl":[[32,1.12],[30,2.72]],"id":39784359}],"con":true,"img":false}]}
{"op":"mcm","clk":"5348004970","pt":1646212261482,"mc":[{"id":"1.195453615","rc":[{"atl":[[13.5,1.36]],"id":26503913}],"con":true,"img":false}]}
{"op":"mcm","clk":"5348004977","pt":1646212261583,"mc":[{"id":"1.195453615","rc":[{"atl":[[14.5,2.67]],"id":26503913}],"con":true,"img":false}]}
{"op":"mcm","clk":"5348005010","pt":1646212262267,"mc":[{"id":"1.195453615","rc":[{"atl":[[13.5,0.28]],"id":26503913}],"con":true,"img":false}]}
{"op":"mcm","clk":"5348005018","pt":1646212262364,"mc":[{"id":"1.195453615","rc":[{"atl":[[14.5,3.75]],"id":26503913}],"con":true,"img":false}]}
{"op":"mcm","clk":"5348005034","pt":1646212262675,"mc":[{"id":"1.195453615","rc":[{"atl":[[30,0]],"id":39784359}],"con":true,"img":false}]}
{"op":"mcm","clk":"5348005041","pt":1646212262777,"mc":[{"id":"1.195453615","rc":[{"atl":[[34,2.72]],"id":39784359}],"con":true,"img":false}]}
{"op":"mcm","clk":"5348005046","pt":1646212262880,"mc":[{"id":"1.195453615","rc":[{"atl":[[14.5,2.67]],"id":26503913}],"con":true,"img":false}]}
{"op":"mcm","clk":"5348005054","pt":1646212262983,"mc":[{"id":"1.195453615","rc":[{"atl":[[14,2.62]],"id":26503913}],"con":true,"img":false}]}
{"op":"mcm","clk":"5348005153","pt":1646212264948,"mc":[{"id":"1.195453615","rc":[{"atl":[[32,3.8]],"id":39784359}],"con":true,"img":false}]}
{"op":"mcm","clk":"5348005400","pt":1646212269507,"mc":[{"id":"1.195453615","rc":[{"atb":[[2.16,6.48]],"id":28755739}],"con":true,"img":false}]}
{"op":"mcm","clk":"5348005455","pt":1646212270594,"mc":[{"id":"1.195453615","rc":[{"atb":[[2.38,0.31]],"id":28755739}],"con":true,"img":false}]}
{"op":"mcm","clk":"5348005491","pt":1646212271377,"mc":[{"id":"1.195453615","rc":[{"atb":[[2.16,15.17]],"id":28755739}],"con":true,"img":false}]}
{"op":"mcm","clk":"5348005523","pt":1646212272095,"mc":[{"id":"1.195453615","rc":[{"atb":[[2.38,0]],"id":28755739}],"con":true,"img":false}]}
{"op":"mcm","clk":"5348005557","pt":1646212272972,"mc":[{"id":"1.195453615","rc":[{"atb":[[2.36,0]],"id":28755739}],"con":true,"img":false}]}
{"op":"mcm","clk":"5348005563","pt":1646212273075,"mc":[{"id":"1.195453615","rc":[{"atb":[[1.04,1.66]],"id":28755739}],"con":true,"img":false}]}
{"op":"mcm","clk":"5348005574","pt":1646212273281,"mc":[{"id":"1.195453615","rc":[{"atb":[[1.04,1.65]],"id":28755739}],"con":true,"img":false}]}
{"op":"mcm","clk":"5348005587","pt":1646212273491,"mc":[{"id":"1.195453615","rc":[{"atb":[[1.04,0]],"id":28755739}],"con":true,"img":false}]}
{"op":"mcm","clk":"5348005593","pt":1646212273594,"mc":[{"id":"1.195453615","rc":[{"atb":[[2.32,6.15],[2.22,1.65]],"id":28755739}],"con":true,"img":false}]}
{"op":"mcm","clk":"5348005877","pt":1646212278823,"mc":[{"id":"1.195453615","rc":[{"atb":[[1.04,2.72]],"id":28755739}],"con":true,"img":false}]}
{"op":"mcm","clk":"5348005906","pt":1646212279284,"mc":[{"id":"1.195453615","rc":[{"atb":[[1.04,0.31]],"id":28755739}],"con":true,"img":false}]}
{"op":"mcm","clk":"5348005930","pt":1646212279695,"mc":[{"id":"1.195453615","rc":[{"atb":[[1.04,0]],"id":28755739}],"con":true,"img":false}]}
{"op":"mcm","clk":"5348005937","pt":1646212279800,"mc":[{"id":"1.195453615","rc":[{"atb":[[2.34,0.31]],"id":28755739}],"con":true,"img":false}]}
{"op":"mcm","clk":"5348005970","pt":1646212280416,"mc":[{"id":"1.195453615","rc":[{"atl":[[14.5,0]],"id":26503913}],"con":true,"img":false}]}
{"op":"mcm","clk":"5348005975","pt":1646212280528,"mc":[{"id":"1.195453615","rc":[{"atl":[[13.5,2.96]],"id":26503913}],"con":true,"img":false}]}
{"op":"mcm","clk":"5348005988","pt":1646212280725,"mc":[{"id":"1.195453615","rc":[{"atl":[[15,3.57]],"id":26503913}],"con":true,"img":false}]}
{"op":"mcm","clk":"5348005996","pt":1646212280829,"mc":[{"id":"1.195453615","rc":[{"atl":[[14.5,4.03]],"id":26503913}],"con":true,"img":false}]}
{"op":"mcm","clk":"5348006043","pt":1646212281707,"mc":[{"id":"1.195453615","rc":[{"atl":[[14,1.54]],"id":26503913}],"con":true,"img":false}]}
{"op":"mcm","clk":"5348006048","pt":1646212281808,"mc":[{"id":"1.195453615","rc":[{"atl":[[13.5,4.04]],"id":26503913}],"con":true,"img":false}]}
{"op":"mcm","clk":"5348006070","pt":1646212282222,"mc":[{"id":"1.195453615","rc":[{"atl":[[13.5,1.36]],"id":26503913}],"con":true,"img":false}]}
{"op":"mcm","clk":"5348006079","pt":1646212282325,"mc":[{"id":"1.195453615","rc":[{"atl":[[14,4.21]],"id":26503913}],"con":true,"img":false}]}
{"op":"mcm","clk":"5348006089","pt":1646212282537,"mc":[{"id":"1.195453615","rc":[{"atl":[[13.5,0.28]],"id":26503913}],"con":true,"img":false}]}
{"op":"mcm","clk":"5348006096","pt":1646212282582,"mc":[{"id":"1.195453615","rc":[{"atl":[[14,5.29]],"id":26503913}],"con":true,"img":false}]}
{"op":"mcm","clk":"5348006222","pt":1646212285111,"mc":[{"id":"1.195453615","rc":[{"atb":[[2.22,0],[1.04,1.66]],"id":28755739}],"con":true,"img":false}]}
{"op":"mcm","clk":"5348006233","pt":1646212285319,"mc":[{"id":"1.195453615","rc":[{"atb":[[1.04,1.65]],"id":28755739}],"con":true,"img":false}]}
{"op":"mcm","clk":"5348006243","pt":1646212285527,"mc":[{"id":"1.195453615","rc":[{"atb":[[1.04,0]],"id":28755739}],"con":true,"img":false}]}
{"op":"mcm","clk":"5348006250","pt":1646212285626,"mc":[{"id":"1.195453615","rc":[{"atb":[[2.36,1.65]],"id":28755739}],"con":true,"img":false}]}
{"op":"mcm","clk":"5348006259","pt":1646212285833,"mc":[{"id":"1.195453615","rc":[{"atb":[[2.32,0.7]],"id":28755739}],"con":true,"img":false}]}
{"op":"mcm","clk":"5348006267","pt":1646212285988,"mc":[{"id":"1.195453615","rc":[{"atb":[[2.34,5.76]],"id":28755739}],"con":true,"img":false}]}
{"op":"mcm","clk":"5348006492","pt":1646212290600,"mc":[{"id":"1.195453615","rc":[{"atb":[[2.12,0]],"id":28755739},{"atl":[[34,0]],"id":39784359}],"con":true,"img":false}]}
{"op":"mcm","clk":"5348006495","pt":1646212290702,"mc":[{"id":"1.195453615","rc":[{"atb":[[2.18,52.18]],"id":28755739},{"atl":[[30,2.72]],"id":39784359}],"con":true,"img":false}]}
{"op":"mcm","clk":"5348006500","pt":1646212290805,"mc":[{"id":"1.195453615","rc":[{"atl":[[32,1.12]],"id":39784359}],"con":true,"img":false}]}
{"op":"mcm","clk":"5348006574","pt":1646212292224,"mc":[{"id":"1.195453615","rc":[{"atb":[[2.34,5.44]],"id":28755739}],"con":true,"img":false}]}
{"op":"mcm","clk":"5348006598","pt":1646212292636,"mc":[{"id":"1.195453615","rc":[{"atl":[[30,0]],"id":39784359}],"con":true,"img":false}]}
{"op":"mcm","clk":"5348006602","pt":1646212292736,"mc":[{"id":"1.195453615","rc":[{"atl":[[34,2.72]],"id":39784359}],"con":true,"img":false}]}
{"op":"mcm","clk":"5348006617","pt":1646212293045,"mc":[{"id":"1.195453615","rc":[{"atb":[[1.04,2.72]],"id":28755739}],"con":true,"img":false}]}
{"op":"mcm","clk":"5348006651","pt":1646212293522,"mc":[{"id":"1.195453615","rc":[{"atb":[[1.04,0.31]],"id":28755739}],"con":true,"img":false}]}
{"op":"mcm","clk":"5348006680","pt":1646212294031,"mc":[{"id":"1.195453615","rc":[{"atb":[[1.04,0]],"id":28755739}],"con":true,"img":false}]}
{"op":"mcm","clk":"5348006688","pt":1646212294140,"mc":[{"id":"1.195453615","rc":[{"atb":[[2.38,0.31]],"id":28755739}],"con":true,"img":false}]}
{"op":"mcm","clk":"5348006696","pt":1646212294242,"mc":[{"id":"1.195453615","rc":[{"atl":[[32,3.8]],"id":39784359}],"con":true,"img":false}]}
{"op":"mcm","clk":"5348006902","pt":1646212298206,"mc":[{"id":"1.195453615","rc":[{"atb":[[2.34,0]],"id":28755739}],"con":true,"img":false}]}
{"op":"mcm","clk":"5348006969","pt":1646212299748,"mc":[{"id":"1.195453615","rc":[{"atb":[[2.38,5.76]],"id":28755739}],"con":true,"img":false}]}
{"op":"mcm","clk":"5348007062","pt":1646212302530,"mc":[{"id":"1.195453615","rc":[{"atb":[[2.16,8.69]],"id":28755739}],"con":true,"img":false}]}
{"op":"mcm","clk":"5348007251","pt":1646212306660,"mc":[{"id":"1.195453615","rc":[{"atb":[[2.38,5.44]],"id":28755739}],"con":true,"img":false}]}
{"op":"mcm","clk":"5348007319","pt":1646212307852,"mc":[{"id":"1.195453615","rc":[{"atb":[[1.04,2.72]],"id":28755739}],"con":true,"img":false}]}
{"op":"mcm","clk":"5348007334","pt":1646212308263,"mc":[{"id":"1.195453615","rc":[{"atb":[[1.04,0.31]],"id":28755739}],"con":true,"img":false}]}
{"op":"mcm","clk":"5348007351","pt":1646212308626,"mc":[{"id":"1.195453615","rc":[{"atb":[[1.04,0]],"id":28755739}],"con":true,"img":false}]}
{"op":"mcm","clk":"5348007356","pt":1646212308731,"mc":[{"id":"1.195453615","rc":[{"atb":[[2.4,0.31]],"id":28755739}],"con":true,"img":false}]}
{"op":"mcm","clk":"5348007482","pt":1646212311559,"mc":[{"id":"1.195453615","rc":[{"atb":[[2.22,6.16]],"id":28755739},{"spn":2.12,"spf":1.0,"id":28755739}],"con":true,"img":false}]}
{"op":"mcm","clk":"5348007499","pt":1646212311966,"mc":[{"id":"1.195453615","rc":[{"atb":[[2.38,0]],"id":28755739}],"con":true,"img":false}]}
{"op":"mcm","clk":"5348007510","pt":1646212312121,"mc":[{"id":"1.195453615","rc":[{"atb":[[2.4,5.76]],"id":28755739}],"con":true,"img":false}]}
{"op":"mcm","clk":"5348007543","pt":1646212312843,"mc":[{"id":"1.195453615","rc":[{"atb":[[2.16,0]],"id":28755739}],"con":true,"img":false}]}
{"op":"mcm","clk":"5348007785","pt":1646212318643,"mc":[{"id":"1.195453615","rc":[{"atl":[[34,0]],"id":39784359}],"con":true,"img":false}]}
{"op":"mcm","clk":"5348007789","pt":1646212318746,"mc":[{"id":"1.195453615","rc":[{"atl":[[30,2.72]],"id":39784359}],"con":true,"img":false}]}
{"op":"mcm","clk":"5348007794","pt":1646212318850,"mc":[{"id":"1.195453615","rc":[{"atl":[[32,1.12]],"id":39784359}],"con":true,"img":false}]}
{"op":"mcm","clk":"5348007856","pt":1646212320658,"mc":[{"id":"1.195453615","rc":[{"atb":[[2.18,0]],"id":28755739},{"atl":[[30,0]],"id":39784359}],"con":true,"img":false}]}
{"op":"mcm","clk":"5348007863","pt":1646212320765,"mc":[{"id":"1.195453615","rc":[{"atb":[[2.12,52.18]],"id":28755739},{"atl":[[34,2.72]],"id":39784359}],"con":true,"img":false}]}
{"op":"mcm","clk":"5348007878","pt":1646212321282,"mc":[{"id":"1.195453615","rc":[{"atb":[[2.4,5.44]],"id":28755739}],"con":true,"img":false}]}
{"op":"mcm","clk":"5348007910","pt":1646212321952,"mc":[{"id":"1.195453615","rc":[{"atb":[[1.04,2.72]],"id":28755739}],"con":true,"img":false}]}
{"op":"mcm","clk":"5348007935","pt":1646212322474,"mc":[{"id":"1.195453615","rc":[{"atb":[[1.04,0.31]],"id":28755739}],"con":true,"img":false}]}
{"op":"mcm","clk":"5348007957","pt":1646212322985,"mc":[{"id":"1.195453615","rc":[{"atb":[[1.04,0]],"id":28755739},{"atl":[[32,3.8]],"id":39784359}],"con":true,"img":false}]}
{"op":"mcm","clk":"5348007960","pt":1646212323093,"mc":[{"id":"1.195453615","rc":[{"atb":[[2.42,0.31]],"id":28755739}],"con":true,"img":false}]}
{"op":"mcm","clk":"5348008014","pt":1646212324377,"mc":[{"id":"1.195453615","rc":[{"atb":[[2.4,0]],"id":28755739}],"con":true,"img":false}]}
{"op":"mcm","clk":"5348008086","pt":1646212325980,"mc":[{"id":"1.195453615","rc":[{"atb":[[2.38,5.44]],"id":28755739}],"con":true,"img":false}]}
{"op":"mcm","clk":"5348008242","pt":1646212329583,"mc":[{"id":"1.195453615","rc":[{"atb":[[2.22,0]],"id":28755739}],"con":true,"img":false}]}
{"op":"mcm","clk":"5348008508","pt":1646212335614,"mc":[{"id":"1.195453615","rc":[{"atb":[[2.42,0]],"id":28755739}],"con":true,"img":false}]}
{"op":"mcm","clk":"5348008529","pt":1646212336178,"mc":[{"id":"1.195453615","rc":[{"atb":[[2.16,8.69]],"id":28755739}],"con":true,"img":false}]}
{"op":"mcm","clk":"5348008592","pt":1646212338183,"mc":[{"id":"1.195453615","rc":[{"atb":[[2.38,0]],"id":28755739}],"con":true,"img":false}]}
{"op":"mcm","clk":"5348008596","pt":1646212338390,"mc":[{"id":"1.195453615","rc":[{"atb":[[2.4,5.44]],"id":28755739}],"con":true,"img":false}]}
{"op":"mcm","clk":"5348008609","pt":1646212338596,"mc":[{"id":"1.195453615","rc":[{"atb":[[2.16,15.17]],"id":28755739}],"con":true,"img":false}]}
{"op":"mcm","clk":"5348008793","pt":1646212342404,"mc":[{"id":"1.195453615","rc":[{"atb":[[1.04,2.72]],"id":28755739}],"con":true,"img":false}]}
{"op":"mcm","clk":"5348008812","pt":1646212342918,"mc":[{"id":"1.195453615","rc":[{"atb":[[1.04,0.31]],"id":28755739}],"con":true,"img":false}]}
{"op":"mcm","clk":"5348008829","pt":1646212343277,"mc":[{"id":"1.195453615","rc":[{"atb":[[1.04,0]],"id":28755739}],"con":true,"img":false}]}
{"op":"mcm","clk":"5348008833","pt":1646212343380,"mc":[{"id":"1.195453615","rc":[{"atb":[[2.42,0.31]],"id":28755739}],"con":true,"img":false}]}
{"op":"mcm","clk":"5348009105","pt":1646212348697,"mc":[{"id":"1.195453615","rc":[{"atl":[[34,0]],"id":39784359}],"con":true,"img":false}]}
{"op":"mcm","clk":"5348009111","pt":1646212348799,"mc":[{"id":"1.195453615","rc":[{"atl":[[30,2.72]],"id":39784359}],"con":true,"img":false}]}
{"op":"mcm","clk":"5348009116","pt":1646212348903,"mc":[{"id":"1.195453615","rc":[{"atl":[[32,1.12]],"id":39784359}],"con":true,"img":false}]}
{"op":"mcm","clk":"5348009178","pt":1646212350607,"mc":[{"id":"1.195453615","rc":[{"atb":[[2.4,0]],"id":28755739}],"con":true,"img":false}]}
{"op":"mcm","clk":"5348009185","pt":1646212350709,"mc":[{"id":"1.195453615","rc":[{"atl":[[30,0]],"id":39784359}],"con":true,"img":false}]}
{"op":"mcm","clk":"5348009190","pt":1646212350813,"mc":[{"id":"1.195453615","rc":[{"atl":[[34,2.72]],"id":39784359}],"con":true,"img":false}]}
{"op":"mcm","clk":"5348009199","pt":1646212351123,"mc":[{"id":"1.195453615","rc":[{"atl":[[32,3.8]],"id":39784359}],"con":true,"img":false}]}
{"op":"mcm","clk":"5348009341","pt":1646212353824,"mc":[{"id":"1.195453615","rc":[{"atb":[[3.95,33.9],[4.7,0]],"id":26503913},{"atl":[[13.5,1.88],[14,3.75]],"id":26503913},{"atb":[[1.89,112.36],[1.8,0]],"id":28755739},{"atb":[[5.4,0],[4.6,26.56]],"id":39784359},{"atb":[[2.72,153.19],[2.62,0]],"id":39980001}],"con":true,"img":false}]}
{"op":"mcm","clk":"5348009347","pt":1646212353929,"mc":[{"id":"1.195453615","rc":[{"atb":[[4.6,27.78]],"id":26503913},{"atb":[[2.38,5.44]],"id":28755739},{"atb":[[5.5,22.22]],"id":39784359}],"con":true,"img":false}]}
{"op":"mcm","clk":"5348009376","pt":1646212354036,"mc":[{"id":"1.195453615","rc":[{"atb":[[3.95,0]],"id":26503913},{"atb":[[2.36,0],[1.04,1.66]],"id":28755739},{"atb":[[4.6,0]],"id":39784359}],"con":true,"img":false}]}
{"op":"mcm","clk":"5348009430","pt":1646212354245,"mc":[{"id":"1.195453615","rc":[{"atb":[[1.04,1.65]],"id":28755739}],"con":true,"img":false}]}
{"op":"mcm","clk":"5348009461","pt":1646212354298,"mc":[{"id":"1.195453615","rc":[{"atl":[[14,2.67]],"id":26503913}],"con":true,"img":false}]}
{"op":"mcm","clk":"5348009471","pt":1646212354403,"mc":[{"id":"1.195453615","rc":[{"atl":[[13.5,2.96]],"id":26503913},{"atb":[[1.04,0]],"id":28755739}],"con":true,"img":false}]}
{"op":"mcm","clk":"5348009485","pt":1646212354507,"mc":[{"id":"1.195453615","rc":[{"atb":[[2.22,1.65]],"id":28755739}],"con":true,"img":false}]}
{"op":"mcm","clk":"5348009527","pt":1646212355129,"mc":[{"id":"1.195453615","rc":[{"atl":[[14,0]],"id":26503913}],"con":true,"img":false}]}
{"op":"mcm","clk":"5348009531","pt":1646212355229,"mc":[{"id":"1.195453615","rc":[{"atl":[[13,2.67]],"id":26503913}],"con":true,"img":false}]}
{"op":"mcm","clk":"5348009552","pt":1646212355696,"mc":[{"id":"1.195453615","rc":[{"atl":[[13.5,1.88]],"id":26503913}],"con":true,"img":false}]}
{"op":"mcm","clk":"5348009555","pt":1646212355798,"mc":[{"id":"1.195453615","rc":[{"atl":[[13,3.75]],"id":26503913}],"con":true,"img":false}]}
{"op":"mcm","clk":"5348009558","pt":1646212355902,"mc":[{"id":"1.195453615","rc":[{"atb":[[2.42,0]],"id":28755739}],"con":true,"img":false}]}
{"op":"mcm","clk":"5348009589","pt":1646212356520,"mc":[{"id":"1.195453615","rc":[{"atl":[[13,1.08]],"id":26503913}],"con":true,"img":false}]}
{"op":"mcm","clk":"5348009594","pt":1646212356622,"mc":[{"id":"1.195453615","rc":[{"atl":[[14,2.67]],"id":26503913}],"con":true,"img":false}]}
{"op":"mcm","clk":"5348009599","pt":1646212356726,"mc":[{"id":"1.195453615","rc":[{"atb":[[2.12,0]],"id":28755739}],"con":true,"img":false}]}
{"op":"mcm","clk":"5348009608","pt":1646212356828,"mc":[{"id":"1.195453615","rc":[{"atb":[[2.18,52.18]],"id":28755739}],"con":true,"img":false}]}
{"op":"mcm","clk":"5348009879","pt":1646212362253,"mc":[{"id":"1.195453615","rc":[{"atb":[[1.04,2.72]],"id":28755739}],"con":true,"img":false}]}
{"op":"mcm","clk":"5348009908","pt":1646212362712,"mc":[{"id":"1.195453615","rc":[{"atb":[[1.04,0.31]],"id":28755739}],"con":true,"img":false}]}
{"op":"mcm","clk":"5348009929","pt":1646212363123,"mc":[{"id":"1.195453615","rc":[{"atb":[[1.04,0]],"id":28755739}],"con":true,"img":false}]}
{"op":"mcm","clk":"5348009933","pt":1646212363224,"mc":[{"id":"1.195453615","rc":[{"atb":[[2.4,0.31]],"id":28755739}],"con":true,"img":false}]}
{"op":"mcm","clk":"5348010060","pt":1646212365603,"mc":[{"id":"1.195453615","rc":[{"atb":[[2.16,8.69]],"id":28755739}],"con":true,"img":false}]}
{"op":"mcm","clk":"5348010081","pt":1646212366119,"mc":[{"id":"1.195453615","rc":[{"atb":[[2.38,0]],"id":28755739}],"con":true,"img":false}]}
{"op":"mcm","clk":"5348010088","pt":1646212366224,"mc":[{"id":"1.195453615","rc":[{"atb":[[2.22,0],[1.04,1.66]],"id":28755739}],"con":true,"img":false}]}
{"op":"mcm","clk":"5348010099","pt":1646212366429,"mc":[{"id":"1.195453615","rc":[{"atb":[[1.04,1.65]],"id":28755739}],"con":true,"img":false}]}
{"op":"mcm","clk":"5348010113","pt":1646212366636,"mc":[{"id":"1.195453615","rc":[{"atb":[[1.04,0]],"id":28755739}],"con":true,"img":false}]}
{"op":"mcm","clk":"5348010123","pt":1646212366736,"mc":[{"id":"1.195453615","rc":[{"atb":[[2.36,1.65]],"id":28755739}],"con":true,"img":false}]}
{"op":"mcm","clk":"5348010237","pt":1646212368843,"mc":[{"id":"1.195453615","rc":[{"atb":[[2.2,6.78]],"id":28755739}],"con":true,"img":false}]}
{"op":"mcm","clk":"5348010246","pt":1646212369051,"mc":[{"id":"1.195453615","rc":[{"atb":[[2.38,5.44]],"id":28755739}],"con":true,"img":false}]}
{"op":"mcm","clk":"5348010426","pt":1646212372627,"mc":[{"id":"1.195453615","rc":[{"atb":[[2.18,0]],"id":28755739},{"spn":2.07,"spf":1.0,"id":28755739}],"con":true,"img":false}]}
{"op":"mcm","clk":"5348010433","pt":1646212372729,"mc":[{"id":"1.195453615","rc":[{"atb":[[2.12,52.18]],"id":28755739}],"con":true,"img":false}]}
