{"op":"mcm","clk":"5345904399","pt":1646079078743,"mc":[{"id":"1.195395454","marketDefinition":{"bspMarket":false,"turnInPlayEnabled":false,"persistenceEnabled":false,"marketBaseRate":5.0,"eventId":"31270459","eventTypeId":"4339","numberOfWinners":3,"bettingType":"ODDS","marketType":"PLACE","marketTime":"2022-03-01T01:45:00.000Z","suspendTime":"2022-03-01T01:45:00.000Z","bspReconciled":false,"complete":true,"inPlay":false,"crossMatching":false,"runnersVoidable":false,"numberOfActiveRunners":8,"betDelay":0,"status":"OPEN","runners":[{"status":"ACTIVE","sortPriority":1,"id":39586887,"name":"1. Homebush Bun"},{"status":"ACTIVE","sortPriority":2,"id":42901530,"name":"2. Wild Thyme"},{"status":"ACTIVE","sortPriority":3,"id":40612296,"name":"3. Opawa Duchess"},{"status":"ACTIVE","sortPriority":4,"id":37076607,"name":"4. Opawa Ruby"},{"status":"ACTIVE","sortPriority":5,"id":42845264,"name":"5. Opawa Dragon"},{"status":"ACTIVE","sortPriority":6,"id":43154432,"name":"6. Iced Mocha"},{"status":"ACTIVE","sortPriority":7,"id":43066392,"name":"7. Go Hazel"},{"status":"ACTIVE","sortPriority":8,"id":40324412,"name":"8. Goldstar Charm"}],"regulators":["MR_INT"],"venue":"Addington","countryCode":"NZ","discountAllowed":false,"timezone":"NZ","openDate":"2022-02-28T23:02:00.000Z","version":4380660681,"name":"To Be Placed","eventName":"Addington (NZL) 1st Mar"},"rc":[],"con":true,"img":false}]}
{"op":"mcm","clk":"5345904622","pt":1646079080740,"mc":[{"id":"1.195395454","marketDefinition":{"bspMarket":false,"turnInPlayEnabled":false,"persistenceEnabled":false,"marketBaseRate":5.0,"eventId":"31270459","eventTypeId":"4339","numberOfWinners":3,"bettingType":"ODDS","marketType":"PLACE","marketTime":"2022-03-01T01:45:00.000Z","suspendTime":"2022-03-01T01:45:00.000Z","bspReconciled":false,"complete":true,"inPlay":false,"crossMatching":false,"runnersVoidable":false,"numberOfActiveRunners":8,"betDelay":0,"status":"OPEN","runners":[{"status":"ACTIVE","sortPriority":1,"id":39586887,"name":"1. Homebush Bun"},{"status":"ACTIVE","sortPriority":2,"id":42901530,"name":"2. Wild Thyme"},{"status":"ACTIVE","sortPriority":3,"id":40612296,"name":"3. Opawa Duchess"},{"status":"ACTIVE","sortPriority":4,"id":37076607,"name":"4. Opawa Ruby"},{"status":"ACTIVE","sortPriority":5,"id":42845264,"name":"5. Opawa Dragon"},{"status":"ACTIVE","sortPriority":6,"id":43154432,"name":"6. Iced Mocha"},{"status":"ACTIVE","sortPriority":7,"id":43066392,"name":"7. Go Hazel"},{"status":"ACTIVE","sortPriority":8,"id":40324412,"name":"8. Goldstar Charm"}],"regulators":["MR_INT"],"venue":"Addington","countryCode":"NZ","discountAllowed":true,"timezone":"NZ","openDate":"2022-02-28T23:02:00.000Z","version":4380660681,"name":"To Be Placed","eventName":"Addington (NZL) 1st Mar"},"rc":[],"con":true,"img":false}]}
{"op":"mcm","clk":"5346133847","pt":1646081622893,"mc":[{"id":"1.195395454","rc":[{"atb":[[2.8,66.75],[2.9,31.62],[2.7,70.68]],"id":37076607},{"atl":[[19.5,1.29],[9.8,1.36],[7.8,1.76],[14.5,1.78],[29,1.71]],"id":37076607},{"atb":[[2.8,66.75],[2.9,31.62],[2.7,70.68]],"id":42901530},{"atl":[[19.5,1.29],[9.8,1.36],[7.8,1.76],[14.5,1.78],[29,1.71]],"id":42901530},{"atb":[[2,60.08],[1.9,133.52],[1.95,126.49]],"id":40612296},{"atl":[[5.1,2.92],[6.2,2.31],[10.5,2.52],[8.2,3.33],[15.5,3.31]],"id":40612296},{"atb":[[2,120.16],[2.2,50.07],[2.1,109.24]],"id":40324412},{"atl":[[17.5,2.91],[9,3],[5.5,2.66],[12.5,2.08],[7,2]],"id":40324412},{"atb":[[1.6,200.28],[1.7,85.83],[1.65,184.87]],"id":43066392},{"atl":[[3.2,5.46],[3.7,4.44],[6.8,8.28],[4.4,7.06],[5.4,5.46]],"id":43066392},{"atb":[[1.01,30042.22]],"id":42845264},{"atl":[[2.72,27.94],[2.32,18.2],[2.52,15.81],[2.12,10.72],[1.96,12.52]],"id":42845264},{"atb":[[2,60.08],[1.9,133.52],[1.95,126.49]],"id":43154432},{"atl":[[5.1,2.92],[6.2,2.31],[10.5,2.52],[8.2,3.33],[15.5,3.31]],"id":43154432},{"atb":[[2.5,80.11],[2.6,75.1],[2.7,35.34]],"id":39586887},{"atl":[[16.5,1.54],[8.6,1.58],[11.5,2.28],[23,2.18],[6.6,2.14]],"id":39586887}],"con":true,"img":false}]}
{"op":"mcm","clk":"5346134834","pt":1646081638177,"mc":[{"id":"1.195395454","rc":[{"atb":[[2.8,0],[2.9,0],[2.7,0]],"id":37076607},{"atl":[[19.5,0],[9.8,0],[7.8,0],[14.5,0],[29,0]],"id":37076607},{"atb":[[2.8,0],[2.9,0],[2.7,0]],"id":42901530},{"atl":[[19.5,0],[9.8,0],[7.8,0],[14.5,0],[29,0]],"id":42901530},{"atb":[[2,0],[1.9,0],[1.95,0]],"id":40612296},{"atl":[[5.1,0],[6.2,0],[10.5,0],[8.2,0],[15.5,0]],"id":40612296},{"atb":[[2,0],[2.2,0],[2.1,0]],"id":40324412},{"atl":[[17.5,0],[9,0],[5.5,0],[12.5,0],[7,0]],"id":40324412},{"atb":[[1.6,0],[1.7,0],[1.65,0]],"id":43066392},{"atl":[[3.2,0],[3.7,0],[6.8,0],[4.4,0],[5.4,0]],"id":43066392},{"atb":[[1.01,0]],"id":42845264},{"atl":[[2.72,0],[2.32,0],[2.52,0],[2.12,0],[1.96,0]],"id":42845264},{"atb":[[2,0],[1.9,0],[1.95,0]],"id":43154432},{"atl":[[5.1,0],[6.2,0],[10.5,0],[8.2,0],[15.5,0]],"id":43154432},{"atb":[[2.5,0],[2.6,0],[2.7,0]],"id":39586887},{"atl":[[16.5,0],[8.6,0],[11.5,0],[23,0],[6.6,0]],"id":39586887}],"con":true,"img":false}]}
{"op":"mcm","clk":"5346135981","pt":1646081656756,"mc":[{"id":"1.195395454","rc":[{"atb":[[2.8,66.75],[2.9,31.62],[2.7,70.68]],"id":37076607},{"atl":[[19.5,1.29],[9.8,1.36],[7.8,1.76],[14.5,1.78],[29,1.71]],"id":37076607},{"atb":[[2.8,66.75],[2.9,31.62],[2.7,70.68]],"id":42901530},{"atl":[[19.5,1.29],[9.8,1.36],[7.8,1.76],[14.5,1.78],[29,1.71]],"id":42901530},{"atb":[[2,60.08],[1.9,133.52],[1.95,126.49]],"id":40612296},{"atl":[[5.1,2.92],[6.2,2.31],[10.5,2.52],[8.2,3.33],[15.5,3.31]],"id":40612296},{"atb":[[2,120.16],[2.2,50.07],[2.1,109.24]],"id":40324412},{"atl":[[17.5,2.91],[9,3],[5.5,2.66],[12.5,2.08],[7,2]],"id":40324412},{"atb":[[1.6,200.28],[1.7,85.83],[1.65,184.87]],"id":43066392},{"atl":[[3.2,5.46],[3.7,4.44],[6.8,8.28],[4.4,7.06],[5.4,5.46]],"id":43066392},{"atb":[[1.01,30042.22]],"id":42845264},{"atl":[[2.72,27.94],[2.32,18.2],[2.52,15.81],[2.12,10.72],[1.96,12.52]],"id":42845264},{"atb":[[2,60.08],[1.9,133.52],[1.95,126.49]],"id":43154432},{"atl":[[5.1,2.92],[6.2,2.31],[10.5,2.52],[8.2,3.33],[15.5,3.31]],"id":43154432},{"atb":[[2.5,80.11],[2.6,75.1],[2.7,35.34]],"id":39586887},{"atl":[[16.5,1.54],[8.6,1.58],[11.5,2.28],[23,2.18],[6.6,2.14]],"id":39586887}],"con":true,"img":false}]}
{"op":"mcm","clk":"5346138731","pt":1646081696060,"mc":[{"id":"1.195395454","rc":[{"atb":[[2.8,0],[2.9,0],[2.7,0]],"id":37076607},{"atl":[[19.5,0],[9.8,0],[7.8,0],[14.5,0],[29,0]],"id":37076607},{"atb":[[2.8,0],[2.9,0],[2.7,0]],"id":42901530},{"atl":[[19.5,0],[9.8,0],[7.8,0],[14.5,0],[29,0]],"id":42901530},{"atb":[[2,0],[1.9,0],[1.95,0]],"id":40612296},{"atl":[[5.1,0],[6.2,0],[10.5,0],[8.2,0],[15.5,0]],"id":40612296},{"atb":[[2,0],[2.2,0],[2.1,0]],"id":40324412},{"atl":[[17.5,0],[9,0],[5.5,0],[12.5,0],[7,0]],"id":40324412},{"atb":[[1.6,0],[1.7,0],[1.65,0]],"id":43066392},{"atl":[[3.2,0],[3.7,0],[6.8,0],[4.4,0],[5.4,0]],"id":43066392},{"atb":[[1.01,0]],"id":42845264},{"atl":[[2.72,0],[2.32,0],[2.52,0],[2.12,0],[1.96,0]],"id":42845264},{"atb":[[2,0],[1.9,0],[1.95,0]],"id":43154432},{"atl":[[5.1,0],[6.2,0],[10.5,0],[8.2,0],[15.5,0]],"id":43154432},{"atb":[[2.5,0],[2.6,0],[2.7,0]],"id":39586887},{"atl":[[16.5,0],[8.6,0],[11.5,0],[23,0],[6.6,0]],"id":39586887}],"con":true,"img":false}]}
{"op":"mcm","clk":"5346140410","pt":1646081720446,"mc":[{"id":"1.195395454","rc":[{"atb":[[2.8,66.75],[2.9,31.62],[2.7,70.68]],"id":37076607},{"atl":[[19.5,1.29],[9.8,1.36],[7.8,1.76],[14.5,1.78],[29,1.71]],"id":37076607},{"atb":[[2.8,66.75],[2.9,31.62],[2.7,70.68]],"id":42901530},{"atl":[[19.5,1.29],[9.8,1.36],[7.8,1.76],[14.5,1.78],[29,1.71]],"id":42901530},{"atb":[[1.7,171.66],[1.75,80.11],[1.65,184.87]],"id":40612296},{"atl":[[4,4],[8,6.86],[5,6],[6,4.8],[3.5,4.8]],"id":40612296},{"atb":[[2,120.16],[2.2,50.07],[2.1,109.24]],"id":40324412},{"atl":[[17.5,2.91],[9,3],[5.5,2.66],[12.5,2.08],[7,2]],"id":40324412},{"atb":[[1.4,300.42],[1.45,133.52],[1.35,343.34]],"id":43066392},{"atl":[[4.5,13.73],[2.9,6.32],[3.25,10.67],[3.75,8.74],[2.7,7.06]],"id":43066392},{"atb":[[1.01,30042.22]],"id":42845264},{"atl":[[2.06,11.33],[2.46,16.46],[2.66,28.95],[2.26,19.07],[1.93,12.92]],"id":42845264},{"atb":[[2,60.08],[1.9,133.52],[1.95,126.49]],"id":43154432},{"atl":[[5.1,2.92],[6.2,2.31],[10.5,2.52],[8.2,3.33],[15.5,3.31]],"id":43154432},{"atb":[[2.5,80.11],[2.6,75.1],[2.7,35.34]],"id":39586887},{"atl":[[16.5,1.54],[8.6,1.58],[11.5,2.28],[23,2.18],[6.6,2.14]],"id":39586887}],"con":true,"img":false}]}
{"op":"mcm","clk":"5346183415","pt":1646082292968,"mc":[{"id":"1.195395454","rc":[{"atb":[[2.8,0],[2.9,0],[2.7,0]],"id":37076607},{"atl":[[19.5,0],[9.8,0],[7.8,0],[14.5,0],[29,0]],"id":37076607},{"atb":[[1.7,0],[1.75,0],[1.65,0]],"id":40612296},{"atl":[[4,0],[8,0],[5,0],[6,0],[3.5,0]],"id":40612296},{"atb":[[2,0],[2.2,0],[2.1,0]],"id":40324412},{"atl":[[17.5,0],[9,0],[5.5,0],[12.5,0],[7,0]],"id":40324412},{"atb":[[1.4,0],[1.45,0],[1.35,0]],"id":43066392},{"atl":[[4.5,0],[2.9,0],[3.25,0],[3.75,0],[2.7,0]],"id":43066392},{"atb":[[1.01,0]],"id":42845264},{"atl":[[2.06,0],[2.46,0],[2.66,0],[2.26,0],[1.93,0]],"id":42845264}],"con":true,"img":false}]}
{"op":"mcm","clk":"5346184036","pt":1646082300481,"mc":[{"id":"1.195395454","rc":[{"atb":[[3.4,50.07],[3.15,55.89],[3.65,22.67]],"id":37076607},{"atl":[[32,0.77],[10.5,1.26],[21,1.2],[55,0.88],[15.5,0.82]],"id":37076607},{"atb":[[1.6,100.14],[1.55,218.49],[1.5,240.33]],"id":40612296},{"atl":[[2.88,6.39],[3.2,5.46],[3.7,8.89],[4.4,7.06],[5.4,10.92]],"id":40612296},{"atb":[[2.4,85.83],[2.5,80.11],[2.6,37.55]],"id":40324412},{"atl":[[6.2,2.31],[10.5,2.52],[21,2.4],[8.2,1.66],[15.5,1.65]],"id":40324412},{"atb":[[1.2,600.84],[1.25,480.67],[1.3,200.28]],"id":43066392},{"atl":[[2.54,7.8],[3.85,16.86],[2.74,6.9],[3.35,10.22],[2.94,12.39]],"id":43066392},{"atb":[[1.01,30042.22]],"id":42845264},{"atl":[[2.06,11.33],[2.46,16.46],[2.66,28.95],[2.26,19.07],[1.93,12.92]],"id":42845264}],"con":true,"img":false}]}
{"op":"mcm","clk":"5346223628","pt":1646082746274,"mc":[{"id":"1.195395454","rc":[{"atb":[[2.6,0]],"id":40324412},{"atl":[[6.2,0],[10.5,0],[15.5,0]],"id":40324412}],"con":true,"img":false}]}
{"op":"mcm","clk":"5346223638","pt":1646082746379,"mc":[{"id":"1.195395454","rc":[{"atb":[[3.4,0],[3.15,0],[3.65,0]],"id":37076607},{"atl":[[32,0],[10.5,0],[21,0],[55,0],[15.5,0]],"id":37076607},{"atb":[[2.8,0],[2.9,0],[2.7,0]],"id":42901530},{"atl":[[19.5,0],[9.8,0],[7.8,0],[14.5,0],[29,0]],"id":42901530},{"atb":[[1.6,0],[1.55,0],[1.5,0]],"id":40612296},{"atl":[[2.88,0],[3.2,0],[3.7,0],[4.4,0],[5.4,0]],"id":40612296},{"atb":[[2.4,0],[2.5,0]],"id":40324412},{"atl":[[21,0],[8.2,0]],"id":40324412},{"atb":[[1.2,0],[1.25,0],[1.3,0]],"id":43066392},{"atl":[[2.54,0],[3.85,0],[2.74,0],[3.35,0],[2.94,0]],"id":43066392},{"atb":[[1.01,0]],"id":42845264},{"atl":[[2.06,0],[2.46,0],[2.66,0],[2.26,0],[1.93,0]],"id":42845264},{"atb":[[2,0],[1.9,0],[1.95,0]],"id":43154432},{"atl":[[5.1,0],[6.2,0],[10.5,0],[8.2,0],[15.5,0]],"id":43154432},{"atb":[[2.5,0],[2.6,0],[2.7,0]],"id":39586887},{"atl":[[16.5,0],[8.6,0],[11.5,0],[23,0],[6.6,0]],"id":39586887}],"con":true,"img":false}]}
{"op":"mcm","clk":"5346226108","pt":1646082775530,"mc":[{"id":"1.195395454","rc":[{"atb":[[2.8,66.75],[2.9,31.62],[2.7,70.68]],"id":37076607},{"atl":[[19.5,1.29],[9.8,1.36],[7.8,1.76],[14.5,1.78],[29,1.71]],"id":37076607},{"atb":[[2.8,66.75],[2.9,31.62],[2.7,70.68]],"id":42901530},{"atl":[[19.5,1.29],[9.8,1.36],[7.8,1.76],[14.5,1.78],[29,1.71]],"id":42901530},{"atb":[[1.45,267.04],[1.55,109.24],[1.5,240.33]],"id":40612296},{"atl":[[2.82,6.6],[5.1,11.72],[4.1,7.75],[3.55,9.42],[3.05,5.86]],"id":40612296},{"atb":[[2,120.16],[2.2,50.07],[2.1,109.24]],"id":40324412},{"atl":[[17.5,2.91],[9,3],[5.5,2.66],[12.5,2.08],[7,2]],"id":40324412},{"atb":[[1.2,600.84],[1.25,480.67],[1.3,200.28]],"id":43066392},{"atl":[[2.54,7.8],[3.85,16.86],[2.74,6.9],[3.35,10.22],[2.94,12.39]],"id":43066392},{"atb":[[1.01,30042.22]],"id":42845264},{"atl":[[2.06,11.33],[2.46,16.46],[2.66,28.95],[2.26,19.07],[1.93,12.92]],"id":42845264},{"atb":[[2,60.08],[1.9,133.52],[1.95,126.49]],"id":43154432},{"atl":[[5.1,2.92],[6.2,2.31],[10.5,2.52],[8.2,3.33],[15.5,3.31]],"id":43154432},{"atb":[[2.5,80.11],[2.6,75.1],[2.7,35.34]],"id":39586887},{"atl":[[16.5,1.54],[8.6,1.58],[11.5,2.28],[23,2.18],[6.6,2.14]],"id":39586887}],"con":true,"img":false}]}
{"op":"mcm","clk":"5346502885","pt":1646088402669,"mc":[{"id":"1.195395454","marketDefinition":{"bspMarket":false,"turnInPlayEnabled":false,"persistenceEnabled":false,"marketBaseRate":5.0,"eventId":"31270459","eventTypeId":"4339","numberOfWinners":3,"bettingType":"ODDS","marketType":"PLACE","marketTime":"2022-03-01T01:45:00.000Z","suspendTime":"2022-03-01T01:45:00.000Z","bspReconciled":false,"complete":true,"inPlay":false,"crossMatching":false,"runnersVoidable":false,"numberOfActiveRunners":8,"betDelay":0,"status":"OPEN","runners":[{"status":"ACTIVE","sortPriority":1,"id":39586887,"name":"1. Homebush Bun"},{"status":"ACTIVE","sortPriority":2,"id":42901530,"name":"2. Wild Thyme"},{"status":"ACTIVE","sortPriority":3,"id":40612296,"name":"3. Opawa Duchess"},{"status":"ACTIVE","sortPriority":4,"id":37076607,"name":"4. Opawa Ruby"},{"status":"ACTIVE","sortPriority":5,"id":42845264,"name":"5. Opawa Dragon"},{"status":"ACTIVE","sortPriority":6,"id":43154432,"name":"6. Iced Mocha"},{"status":"ACTIVE","sortPriority":7,"id":43066392,"name":"7. Go Hazel"},{"status":"ACTIVE","sortPriority":8,"id":40324412,"name":"8. Goldstar Charm"}],"regulators":["MR_INT"],"venue":"Addington","countryCode":"NZ","discountAllowed":true,"timezone":"NZ","openDate":"2022-02-28T23:02:00.000Z","version":4380660681,"name":"To Be Placed","eventName":"Addington (NZL) 1st Mar"},"rc":[{"atb":[[2.8,66.74],[2.9,31.61],[2.7,70.67]],"id":37076607},{"atl":[[19.5,1.29],[9.8,1.36],[7.8,1.76],[14.5,1.78],[29,1.71]],"id":37076607},{"atb":[[2.8,66.74],[2.9,31.61],[2.7,70.67]],"id":42901530},{"atl":[[19.5,1.29],[9.8,1.36],[7.8,1.76],[14.5,1.78],[29,1.71]],"id":42901530},{"atb":[[1.45,266.99],[1.55,109.22],[1.5,240.29]],"id":40612296},{"atl":[[2.82,6.6],[5.1,11.72],[4.1,7.75],[3.55,9.42],[3.05,5.86]],"id":40612296},{"atb":[[2,120.14],[2.2,50.06],[2.1,109.22]],"id":40324412},{"atl":[[17.5,2.91],[9,3],[5.5,2.66],[12.5,2.08],[7,2]],"id":40324412},{"atb":[[1.2,600.74],[1.25,480.59],[1.3,200.24]],"id":43066392},{"atl":[[2.54,7.8],[3.85,16.86],[2.74,6.9],[3.35,10.22],[2.94,12.38]],"id":43066392},{"atb":[[1.01,30037.34]],"id":42845264},{"atl":[[2.06,11.33],[2.46,16.45],[2.66,28.94],[2.26,19.07],[1.93,12.91]],"id":42845264},{"atb":[[2,60.07],[1.9,133.5],[1.95,126.47]],"id":43154432},{"atl":[[5.1,2.92],[6.2,2.31],[10.5,2.52],[8.2,3.33],[15.5,3.31]],"id":43154432},{"atb":[[2.5,80.09],[2.6,75.09],[2.7,35.33]],"id":39586887},{"atl":[[16.5,1.54],[8.6,1.58],[11.5,2.28],[23,2.18],[6.6,2.14]],"id":39586887}],"con":true,"img":true}]}
{"op":"mcm","clk":"5346671088","pt":1646093802653,"mc":[{"id":"1.195395454","marketDefinition":{"bspMarket":false,"turnInPlayEnabled":false,"persistenceEnabled":false,"marketBaseRate":5.0,"eventId":"31270459","eventTypeId":"4339","numberOfWinners":3,"bettingType":"ODDS","marketType":"PLACE","marketTime":"2022-03-01T01:45:00.000Z","suspendTime":"2022-03-01T01:45:00.000Z","bspReconciled":false,"complete":true,"inPlay":false,"crossMatching":false,"runnersVoidable":false,"numberOfActiveRunners":8,"betDelay":0,"status":"OPEN","runners":[{"status":"ACTIVE","sortPriority":1,"id":39586887,"name":"1. Homebush Bun"},{"status":"ACTIVE","sortPriority":2,"id":42901530,"name":"2. Wild Thyme"},{"status":"ACTIVE","sortPriority":3,"id":40612296,"name":"3. Opawa Duchess"},{"status":"ACTIVE","sortPriority":4,"id":37076607,"name":"4. Opawa Ruby"},{"status":"ACTIVE","sortPriority":5,"id":42845264,"name":"5. Opawa Dragon"},{"status":"ACTIVE","sortPriority":6,"id":43154432,"name":"6. Iced Mocha"},{"status":"ACTIVE","sortPriority":7,"id":43066392,"name":"7. Go Hazel"},{"status":"ACTIVE","sortPriority":8,"id":40324412,"name":"8. Goldstar Charm"}],"regulators":["MR_INT"],"venue":"Addington","countryCode":"NZ","discountAllowed":true,"timezone":"NZ","openDate":"2022-02-28T23:02:00.000Z","version":4380660681,"name":"To Be Placed","eventName":"Addington (NZL) 1st Mar"},"rc":[{"atb":[[2.8,66.7],[2.9,31.59],[2.7,70.63]],"id":37076607},{"atl":[[19.5,1.29],[9.8,1.36],[7.8,1.76],[14.5,1.77],[29,1.71]],"id":37076607},{"atb":[[2.8,66.7],[2.9,31.59],[2.7,70.63]],"id":42901530},{"atl":[[19.5,1.29],[9.8,1.36],[7.8,1.76],[14.5,1.77],[29,1.71]],"id":42901530},{"atb":[[1.45,266.82],[1.55,109.15],[1.5,240.14]],"id":40612296},{"atl":[[2.82,6.59],[5.1,11.71],[4.1,7.74],[3.55,9.41],[3.05,5.85]],"id":40612296},{"atb":[[2,120.07],[2.2,50.02],[2.1,109.15]],"id":40324412},{"atl":[[17.5,2.9],[9,3],[5.5,2.66],[12.5,2.08],[7,2]],"id":40324412},{"atb":[[1.2,600.35],[1.25,480.28],[1.3,200.11]],"id":43066392},{"atl":[[2.54,7.79],[3.85,16.85],[2.74,6.9],[3.35,10.21],[2.94,12.38]],"id":43066392},{"atb":[[1.01,30017.84]],"id":42845264},{"atl":[[2.06,11.32],[2.46,16.44],[2.66,28.93],[2.26,19.05],[1.93,12.91]],"id":42845264},{"atb":[[2,60.03],[1.9,133.41],[1.95,126.38]],"id":43154432},{"atl":[[5.1,2.92],[6.2,2.3],[10.5,2.52],[8.2,3.33],[15.5,3.31]],"id":43154432},{"atb":[[2.5,80.04],[2.6,75.04],[2.7,35.31]],"id":39586887},{"atl":[[16.5,1.54],[8.6,1.57],[11.5,2.28],[23,2.18],[6.6,2.14]],"id":39586887}],"con":true,"img":true}]}
{"op":"mcm","clk":"5346673531","pt":1646093831172,"mc":[{"id":"1.195395454","rc":[{"atb":[[2.8,66.7],[3.6,15.6],[2.72,20.65],[2.9,31.59],[2.7,70.63]],"id":37076607},{"atl":[[17.5,2.46],[19.5,1.29],[9.8,1.36],[27,2.7],[7.8,1.76],[14.5,1.77],[29,1.71]],"id":37076607},{"atb":[[2.8,66.7],[2.72,20.9],[2.9,31.59],[3.35,17.25],[2.7,70.63]],"id":42901530},{"atl":[[16,2.7],[19.5,1.29],[24,2.7],[9.8,1.36],[7.8,1.76],[14.5,1.77],[29,1.71]],"id":42901530},{"atb":[[1.46,85.63],[1.45,266.82],[1.55,109.15],[1.54,40.56],[1.5,240.14]],"id":40612296},{"atl":[[2.82,6.59],[5.1,11.71],[5,9.84],[4.1,7.74],[3.55,9.41],[3.5,16.22],[3.05,5.85]],"id":40612296},{"atb":[[2,120.07],[2.02,38.17],[2.3,31.2],[2.2,50.02],[2.1,109.15]],"id":40324412},{"atl":[[17.5,2.9],[9,8.07],[5.5,2.66],[12.5,2.08],[13.5,3.11],[7,2]],"id":40324412},{"atb":[[1.2,600.35],[1.25,480.28],[1.26,151.51],[1.3,200.11],[1.33,40.56]],"id":43066392},{"atl":[[2.92,20.51],[2.54,7.79],[3.85,16.85],[2.74,6.9],[3.35,10.21],[2.52,26.68],[2.94,12.38]],"id":43066392},{"atb":[[1.01,30017.84],[1.02,1924.56]],"id":42845264},{"atl":[[2.06,11.32],[2.46,16.44],[2.66,28.93],[1.42,40.56],[2.26,19.05],[1.93,12.91],[1.69,54.61]],"id":42845264},{"atb":[[2,60.03],[1.9,133.41],[1.91,44.28],[1.95,126.38],[2.08,37.55]],"id":43154432},{"atl":[[5.1,2.92],[10,4.47],[6.2,2.3],[10.5,2.52],[8.2,3.33],[7.4,6.33],[15.5,3.31]],"id":43154432},{"atb":[[2.5,80.04],[2.9,21.34],[2.52,23.72],[2.6,75.04],[2.7,35.31]],"id":39586887},{"atl":[[16.5,1.54],[8.6,1.57],[19.5,2.7],[11.5,2.28],[23,2.18],[13,3.38],[6.6,2.14]],"id":39586887}],"con":true,"img":false}]}
{"op":"mcm","clk":"5346676335","pt":1646093911696,"mc":[{"id":"1.195395454","rc":[{"atb":[[2.72,0]],"id":37076607},{"atb":[[2.72,0]],"id":42901530},{"atb":[[1.46,0],[1.54,0]],"id":40612296},{"atb":[[2.02,0]],"id":40324412},{"atb":[[1.26,0]],"id":43066392},{"atb":[[1.91,0]],"id":43154432},{"atb":[[2.52,0]],"id":39586887}],"con":true,"img":false}]}
{"op":"mcm","clk":"5346676339","pt":1646093911800,"mc":[{"id":"1.195395454","rc":[{"atb":[[2.82,20.65]],"id":37076607},{"atb":[[2.82,20.9]],"id":42901530},{"atb":[[1.56,40.56],[1.51,85.63]],"id":40612296},{"atb":[[2.22,38.17]],"id":40324412},{"atb":[[1.31,151.51]],"id":43066392},{"atb":[[2.02,44.28]],"id":43154432},{"atb":[[2.62,23.72]],"id":39586887}],"con":true,"img":false}]}
{"op":"mcm","clk":"5346679170","pt":1646093989527,"mc":[{"id":"1.195395454","rc":[{"atb":[[2.82,0]],"id":37076607},{"atb":[[2.82,0]],"id":42901530},{"atb":[[2.62,0]],"id":39586887}],"con":true,"img":false}]}
{"op":"mcm","clk":"5346679173","pt":1646093989629,"mc":[{"id":"1.195395454","rc":[{"atb":[[2.92,20.65]],"id":37076607},{"atb":[[2.92,20.9]],"id":42901530},{"atb":[[2.72,23.72]],"id":39586887}],"con":true,"img":false}]}
{"op":"mcm","clk":"5346736055","pt":1646095530250,"mc":[{"id":"1.195395454","rc":[{"atb":[[3.65,20.65]],"id":37076607},{"atl":[[150,2]],"id":37076607},{"atb":[[1.35,63.2]],"id":42901530},{"atl":[[14,3.12]],"id":42901530},{"atb":[[1.37,218.32]],"id":40612296},{"atl":[[5.2,18.84]],"id":40612296},{"atb":[[2.2,133.35]],"id":40324412},{"atl":[[8.8,4.67]],"id":40324412},{"atb":[[1.34,151.51]],"id":43066392},{"atl":[[3.45,22.6]],"id":43066392},{"atb":[[1.02,6924.56]],"id":42845264},{"atl":[[1.54,81.12]],"id":42845264},{"atb":[[1.08,120.08]],"id":43154432},{"atl":[[5.1,5.85]],"id":43154432},{"atb":[[1.62,70.62]],"id":39586887},{"atl":[[23,6.61]],"id":39586887}],"con":true,"img":false}]}
{"op":"mcm","clk":"5346736263","pt":1646095535037,"mc":[{"id":"1.195395454","rc":[{"atb":[[2.02,0]],"id":43154432},{"atb":[[2.72,0]],"id":39586887}],"con":true,"img":false}]}
{"op":"mcm","clk":"5346736267","pt":1646095535139,"mc":[{"id":"1.195395454","rc":[{"atb":[[1.96,44.28]],"id":43154432},{"atb":[[2.62,23.72]],"id":39586887}],"con":true,"img":false}]}
{"op":"mcm","clk":"5346737356","pt":1646095563814,"mc":[{"id":"1.195395454","rc":[{"atb":[[3.6,0],[2.92,0],[2.84,22.28]],"id":37076607},{"atl":[[17.5,0],[11.5,3.86]],"id":37076607},{"atb":[[2.92,0],[2.02,35.26],[3.35,0]],"id":42901530},{"atl":[[16,0],[10.5,4.26]],"id":42901530},{"atb":[[2.3,0],[2.22,0]],"id":40324412},{"atl":[[9,3]],"id":40324412},{"atb":[[1.33,0]],"id":43066392},{"atl":[[2.92,0],[2.52,0],[3.4,16.41]],"id":43066392},{"atl":[[2.04,36.23],[1.42,0],[1.69,0]],"id":42845264},{"atl":[[7.4,0]],"id":43154432},{"atb":[[2.9,0],[2.62,0],[1.95,37.95]],"id":39586887},{"atl":[[13,0],[9.4,4.82]],"id":39586887}],"con":true,"img":false}]}
{"op":"mcm","clk":"5346737361","pt":1646095563919,"mc":[{"id":"1.195395454","rc":[{"atb":[[2.72,20.65]],"id":37076607},{"atb":[[2.82,17.25]],"id":42901530},{"atb":[[2.02,38.17],[2.22,31.2]],"id":40324412},{"atl":[[7.4,5.07]],"id":40324412},{"atb":[[1.35,40.56]],"id":43066392},{"atl":[[2.92,26.68]],"id":43066392},{"atl":[[1.92,40.56]],"id":42845264},{"atl":[[6.8,6.33]],"id":43154432},{"atb":[[2.62,21.34]],"id":39586887}],"con":true,"img":false}]}
{"op":"mcm","clk":"5346737367","pt":1646095564022,"mc":[{"id":"1.195395454","rc":[{"atb":[[2.92,41.3],[3.65,0]],"id":37076607},{"atb":[[1.32,303.02],[1.34,0]],"id":43066392},{"atl":[[1.92,149.26],[1.54,0]],"id":42845264}],"con":true,"img":false}]}
{"op":"mcm","clk":"5346737500","pt":1646095567110,"mc":[{"id":"1.195395454","rc":[{"atb":[[2.22,113.17],[2.2,50.02]],"id":40324412}],"con":true,"img":false}]}
{"op":"mcm","clk":"5346738631","pt":1646095592655,"mc":[{"id":"1.195395454","rc":[{"atl":[[13.5,0]],"id":40324412},{"atb":[[1.31,0]],"id":43066392}],"con":true,"img":false}]}
{"op":"mcm","clk":"5346738636","pt":1646095592760,"mc":[{"id":"1.195395454","rc":[{"atl":[[27,0]],"id":37076607},{"atl":[[24,0]],"id":42901530},{"atl":[[8.8,9.66]],"id":40324412},{"atb":[[1.33,119.37]],"id":43066392},{"atl":[[1.92,108.7],[2.04,0]],"id":42845264},{"atl":[[19.5,0]],"id":39586887}],"con":true,"img":false}]}
{"op":"mcm","clk":"5346738640","pt":1646095592865,"mc":[{"id":"1.195395454","rc":[{"atl":[[17.5,2.7]],"id":37076607},{"atl":[[15.5,2.7]],"id":42901530},{"atl":[[11,3.89],[8.8,4.67]],"id":40324412},{"atl":[[2.24,36.23],[1.91,40.56]],"id":42845264},{"atl":[[14.5,2.7]],"id":39586887}],"con":true,"img":false}]}
{"op":"mcm","clk":"5346738983","pt":1646095600477,"mc":[{"id":"1.195395454","rc":[{"atb":[[1.32,0],[1.35,159.93]],"id":43066392},{"atl":[[1.92,0],[1.9,40.56]],"id":42845264}],"con":true,"img":false}]}
{"op":"mcm","clk":"5346738985","pt":1646095600580,"mc":[{"id":"1.195395454","rc":[{"atb":[[1.34,200.12]],"id":43066392}],"con":true,"img":false}]}
{"op":"mcm","clk":"5346738989","pt":1646095600682,"mc":[{"id":"1.195395454","rc":[{"atb":[[1.35,40.56]],"id":43066392}],"con":true,"img":false}]}
{"op":"mcm","clk":"5346738994","pt":1646095600787,"mc":[{"id":"1.195395454","rc":[{"atb":[[1.34,0],[1.35,200.49]],"id":43066392}],"con":true,"img":false}]}
{"op":"mcm","clk":"5346739854","pt":1646095620613,"mc":[{"id":"1.195395454","rc":[{"atb":[[2.84,0]],"id":37076607},{"atb":[[2.22,81.97]],"id":40324412},{"atb":[[1.33,0]],"id":43066392}],"con":true,"img":false}]}
{"op":"mcm","clk":"5346739857","pt":1646095620717,"mc":[{"id":"1.195395454","rc":[{"atb":[[2.94,22.28]],"id":37076607},{"atb":[[2.24,31.2]],"id":40324412},{"atb":[[1.31,119.37]],"id":43066392}],"con":true,"img":false}]}
{"op":"mcm","clk":"5346739860","pt":1646095620819,"mc":[{"id":"1.195395454","rc":[{"atb":[[2.92,0],[2.96,31.6]],"id":37076607}],"con":true,"img":false}]}
{"op":"mcm","clk":"5346740922","pt":1646095648642,"mc":[{"id":"1.195395454","rc":[{"atl":[[15.5,0]],"id":42901530},{"atl":[[11,0],[8.8,9.66]],"id":40324412},{"atl":[[1.91,0]],"id":42845264}],"con":true,"img":false}]}
{"op":"mcm","clk":"5346740925","pt":1646095648743,"mc":[{"id":"1.195395454","rc":[{"atl":[[14,5.82]],"id":42901530},{"atl":[[10.5,4.09],[8.8,4.67]],"id":40324412},{"atl":[[1.92,81.12],[1.89,40.56],[1.9,0]],"id":42845264}],"con":true,"img":false}]}
{"op":"mcm","clk":"5346741692","pt":1646095676308,"mc":[{"id":"1.195395454","rc":[{"atl":[[1.89,0]],"id":42845264}],"con":true,"img":false}]}
{"op":"mcm","clk":"5346741694","pt":1646095676410,"mc":[{"id":"1.195395454","rc":[{"atl":[[1.91,40.56]],"id":42845264}],"con":true,"img":false}]}
{"op":"mcm","clk":"5346741910","pt":1646095684421,"mc":[{"id":"1.195395454","rc":[{"atl":[[1.92,0],[1.9,40.56]],"id":42845264}],"con":true,"img":false}]}
{"op":"mcm","clk":"5346742478","pt":1646095703785,"mc":[{"id":"1.195395454","rc":[{"atl":[[10.5,0],[8.8,9.66]],"id":40324412}],"con":true,"img":false}]}
{"op":"mcm","clk":"5346742483","pt":1646095703888,"mc":[{"id":"1.195395454","rc":[{"atl":[[8.8,4.67]],"id":40324412}],"con":true,"img":false}]}
{"op":"mcm","clk":"5346742489","pt":1646095703941,"mc":[{"id":"1.195395454","rc":[{"atl":[[10,4.99]],"id":40324412}],"con":true,"img":false}]}
{"op":"mcm","clk":"5346743225","pt":1646095731006,"mc":[{"id":"1.195395454","rc":[{"atl":[[1.91,0]],"id":42845264}],"con":true,"img":false}]}
{"op":"mcm","clk":"5346743231","pt":1646095731111,"mc":[{"id":"1.195395454","rc":[{"atl":[[1.92,81.12],[1.89,40.56]],"id":42845264}],"con":true,"img":false}]}
{"op":"mcm","clk":"5346743234","pt":1646095731214,"mc":[{"id":"1.195395454","rc":[{"atl":[[1.88,40.56],[1.9,0]],"id":42845264}],"con":true,"img":false}]}
{"op":"mcm","clk":"5346743239","pt":1646095731320,"mc":[{"id":"1.195395454","rc":[{"atl":[[1.92,0]],"id":42845264}],"con":true,"img":false}]}
{"op":"mcm","clk":"5346744009","pt":1646095757945,"mc":[{"id":"1.195395454","rc":[{"atl":[[10,0]],"id":40324412}],"con":true,"img":false}]}
{"op":"mcm","clk":"5346744012","pt":1646095758046,"mc":[{"id":"1.195395454","rc":[{"atl":[[8.8,9.66]],"id":40324412}],"con":true,"img":false}]}
{"op":"mcm","clk":"5346744752","pt":1646095784498,"mc":[{"id":"1.195395454","rc":[{"atl":[[1.89,0]],"id":42845264}],"con":true,"img":false}]}
{"op":"mcm","clk":"5346744756","pt":1646095784600,"mc":[{"id":"1.195395454","rc":[{"atl":[[1.92,81.12],[1.87,40.56]],"id":42845264}],"con":true,"img":false}]}
{"op":"mcm","clk":"5346744757","pt":1646095784702,"mc":[{"id":"1.195395454","rc":[{"atl":[[1.88,0]],"id":42845264}],"con":true,"img":false}]}
{"op":"mcm","clk":"5346745602","pt":1646095811176,"mc":[{"id":"1.195395454","rc":[{"atl":[[1.87,0]],"id":42845264}],"con":true,"img":false}]}
{"op":"mcm","clk":"5346745603","pt":1646095811278,"mc":[{"id":"1.195395454","rc":[{"atl":[[1.91,40.56]],"id":42845264}],"con":true,"img":false}]}
{"op":"mcm","clk":"5346745839","pt":1646095818975,"mc":[{"id":"1.195395454","rc":[{"atl":[[1.9,40.56]],"id":42845264}],"con":true,"img":false}]}
{"op":"mcm","clk":"5346745843","pt":1646095819077,"mc":[{"id":"1.195395454","rc":[{"atl":[[1.92,0]],"id":42845264}],"con":true,"img":false}]}
{"op":"mcm","clk":"5346748012","pt":1646095888689,"mc":[{"id":"1.195395454","rc":[{"atl":[[1.91,0]],"id":42845264}],"con":true,"img":false}]}
{"op":"mcm","clk":"5346748016","pt":1646095888792,"mc":[{"id":"1.195395454","rc":[{"atl":[[1.92,81.12],[1.89,40.56]],"id":42845264}],"con":true,"img":false}]}
{"op":"mcm","clk":"5346748020","pt":1646095888894,"mc":[{"id":"1.195395454","rc":[{"atl":[[1.9,0]],"id":42845264}],"con":true,"img":false}]}
{"op":"mcm","clk":"5346748549","pt":1646095904060,"mc":[{"id":"1.195395454","rc":[{"atb":[[2.22,0],[2.26,50.03]],"id":40324412},{"atb":[[1.33,303.03],[1.35,40.56]],"id":43066392}],"con":true,"img":false}]}
{"op":"mcm","clk":"5346748833","pt":1646095913655,"mc":[{"id":"1.195395454","rc":[{"atl":[[1.89,0]],"id":42845264}],"con":true,"img":false}]}
{"op":"mcm","clk":"5346748836","pt":1646095913764,"mc":[{"id":"1.195395454","rc":[{"atl":[[1.91,40.56]],"id":42845264}],"con":true,"img":false}]}
{"op":"mcm","clk":"5346749069","pt":1646095922102,"mc":[{"id":"1.195395454","rc":[{"atl":[[1.92,0],[1.89,40.56]],"id":42845264}],"con":true,"img":false}]}
{"op":"mcm","clk":"5346750142","pt":1646095958530,"mc":[{"id":"1.195395454","rc":[{"atl":[[1.89,0],[1.9,81.12]],"id":42845264}],"con":true,"img":false}]}
{"op":"mcm","clk":"5346750266","pt":1646095963651,"mc":[{"id":"1.195395454","rc":[{"atb":[[2.24,0]],"id":40324412},{"atb":[[1.31,0]],"id":43066392}],"con":true,"img":false}]}
{"op":"mcm","clk":"5346750269","pt":1646095963754,"mc":[{"id":"1.195395454","rc":[{"atb":[[2.22,81.97],[2.28,31.2],[2.26,0]],"id":40324412},{"atb":[[1.34,119.37]],"id":43066392}],"con":true,"img":false}]}
{"op":"mcm","clk":"5346750274","pt":1646095963856,"mc":[{"id":"1.195395454","rc":[{"atb":[[2.22,0],[2.26,79.37]],"id":40324412}],"con":true,"img":false}]}
{"op":"mcm","clk":"5346750442","pt":1646095969387,"mc":[{"id":"1.195395454","rc":[{"atb":[[1.37,0],[1.54,185.19]],"id":40612296},{"atb":[[1.23,434.78],[1.33,0]],"id":43066392}],"con":true,"img":false}]}
{"op":"mcm","clk":"5346750982","pt":1646095988305,"mc":[{"id":"1.195395454","rc":[{"atb":[[1.34,0]],"id":43066392},{"atl":[[1.91,0]],"id":42845264}],"con":true,"img":false}]}
{"op":"mcm","clk":"5346750985","pt":1646095988407,"mc":[{"id":"1.195395454","rc":[{"atb":[[1.31,119.37]],"id":43066392},{"atl":[[1.89,40.56]],"id":42845264}],"con":true,"img":false}]}
{"op":"mcm","clk":"5346751066","pt":1646095991129,"mc":[{"id":"1.195395454","rc":[{"atl":[[1.83,40.56],[1.9,0]],"id":42845264}],"con":true,"img":false}]}
{"op":"mcm","clk":"5346751212","pt":1646095996325,"mc":[{"id":"1.195395454","rc":[{"atb":[[2.28,81.23]],"id":40324412}],"con":true,"img":false}]}
{"op":"mcm","clk":"5346751215","pt":1646095996427,"mc":[{"id":"1.195395454","rc":[{"atb":[[2.26,0]],"id":40324412}],"con":true,"img":false}]}
{"op":"mcm","clk":"5346751941","pt":1646096019650,"mc":[{"id":"1.195395454","rc":[{"atb":[[1.55,218.31],[1.54,0]],"id":40612296}],"con":true,"img":false}]}
{"op":"mcm","clk":"5346752095","pt":1646096024773,"mc":[{"id":"1.195395454","rc":[{"atb":[[1.55,109.15],[1.54,185.19]],"id":40612296}],"con":true,"img":false}]}
{"op":"mcm","clk":"5346752433","pt":1646096037103,"mc":[{"id":"1.195395454","rc":[{"atb":[[1.51,0]],"id":40612296}],"con":true,"img":false}]}
{"op":"mcm","clk":"5346752437","pt":1646096037195,"mc":[{"id":"1.195395454","rc":[{"atb":[[1.55,194.79]],"id":40612296}],"con":true,"img":false}]}
{"op":"mcm","clk":"5346753243","pt":1646096061249,"mc":[{"id":"1.195395454","rc":[{"atl":[[1.89,0]],"id":42845264}],"con":true,"img":false}]}
{"op":"mcm","clk":"5346753245","pt":1646096061352,"mc":[{"id":"1.195395454","rc":[{"atl":[[1.82,40.56]],"id":42845264}],"con":true,"img":false}]}
{"op":"mcm","clk":"5346753249","pt":1646096061454,"mc":[{"id":"1.195395454","rc":[{"atl":[[1.81,40.56]],"id":42845264}],"con":true,"img":false}]}
{"op":"mcm","clk":"5346753253","pt":1646096061557,"mc":[{"id":"1.195395454","rc":[{"atl":[[1.83,0]],"id":42845264}],"con":true,"img":false}]}
{"op":"mcm","clk":"5346753954","pt":1646096081288,"mc":[{"id":"1.195395454","rc":[{"atb":[[1.55,376.61],[1.54,0]],"id":40612296}],"con":true,"img":false}]}
{"op":"mcm","clk":"5346753959","pt":1646096081391,"mc":[{"id":"1.195395454","rc":[{"atb":[[1.55,194.79],[1.54,185.19]],"id":40612296}],"con":true,"img":false}]}
{"op":"mcm","clk":"5346754071","pt":1646096083806,"mc":[{"id":"1.195395454","rc":[{"atl":[[3.45,0],[2.54,15.59]],"id":43066392},{"atb":[[1.08,0],[1.17,120.08]],"id":43154432}],"con":true,"img":false}]}
{"op":"mcm","clk":"5346754122","pt":1646096085097,"mc":[{"id":"1.195395454","rc":[{"atl":[[3.4,0]],"id":43066392}],"con":true,"img":false}]}
{"op":"mcm","clk":"5346754127","pt":1646096085199,"mc":[{"id":"1.195395454","rc":[{"atl":[[3.8,16.41]],"id":43066392}],"con":true,"img":false}]}
{"op":"mcm","clk":"5346755901","pt":1646096132051,"mc":[{"id":"1.195395454","rc":[{"atl":[[1.82,0]],"id":42845264}],"con":true,"img":false}]}
{"op":"mcm","clk":"5346755907","pt":1646096132154,"mc":[{"id":"1.195395454","rc":[{"atl":[[1.8,40.56],[1.92,81.12],[1.81,0]],"id":42845264}],"con":true,"img":false}]}
{"op":"mcm","clk":"5346756277","pt":1646096142645,"mc":[{"id":"1.195395454","rc":[{"atb":[[1.55,376.61],[1.54,0]],"id":40612296}],"con":true,"img":false}]}
{"op":"mcm","clk":"5346756280","pt":1646096142746,"mc":[{"id":"1.195395454","rc":[{"atb":[[1.54,185.19]],"id":40612296}],"con":true,"img":false}]}
{"op":"mcm","clk":"5346756283","pt":1646096142850,"mc":[{"id":"1.195395454","rc":[{"atb":[[1.55,194.79]],"id":40612296}],"con":true,"img":false}]}
{"op":"mcm","clk":"5346756681","pt":1646096155181,"mc":[{"id":"1.195395454","rc":[{"atl":[[1.8,0]],"id":42845264}],"con":true,"img":false}]}
{"op":"mcm","clk":"5346756684","pt":1646096155281,"mc":[{"id":"1.195395454","rc":[{"atl":[[1.91,40.56]],"id":42845264}],"con":true,"img":false}]}
{"op":"mcm","clk":"5346756955","pt":1646096162909,"mc":[{"id":"1.195395454","rc":[{"atl":[[1.92,0],[1.9,40.56]],"id":42845264}],"con":true,"img":false}]}
{"op":"mcm","clk":"5346758366","pt":1646096204272,"mc":[{"id":"1.195395454","rc":[{"atb":[[1.55,376.61],[1.54,0]],"id":40612296}],"con":true,"img":false}]}
{"op":"mcm","clk":"5346758590","pt":1646096209514,"mc":[{"id":"1.195395454","rc":[{"atb":[[1.55,194.79],[1.54,185.19]],"id":40612296}],"con":true,"img":false}]}
{"op":"mcm","clk":"5346759224","pt":1646096223411,"mc":[{"id":"1.195395454","rc":[{"atl":[[1.91,0]],"id":42845264}],"con":true,"img":false}]}
{"op":"mcm","clk":"5346759230","pt":1646096223513,"mc":[{"id":"1.195395454","rc":[{"atl":[[1.89,40.56]],"id":42845264}],"con":true,"img":false}]}
{"op":"mcm","clk":"5346759235","pt":1646096223617,"mc":[{"id":"1.195395454","rc":[{"atl":[[1.92,81.12],[1.9,0]],"id":42845264}],"con":true,"img":false}]}
{"op":"mcm","clk":"5346760282","pt":1646096245953,"mc":[{"id":"1.195395454","rc":[{"atl":[[1.89,0]],"id":42845264}],"con":true,"img":false}]}
{"op":"mcm","clk":"5346760289","pt":1646096246050,"mc":[{"id":"1.195395454","rc":[{"atl":[[1.91,40.56]],"id":42845264}],"con":true,"img":false}]}
{"op":"mcm","clk":"5346760630","pt":1646096253548,"mc":[{"id":"1.195395454","rc":[{"atl":[[1.9,40.56]],"id":42845264}],"con":true,"img":false}]}
{"op":"mcm","clk":"5346760634","pt":1646096253651,"mc":[{"id":"1.195395454","rc":[{"atl":[[1.92,0]],"id":42845264}],"con":true,"img":false}]}
{"op":"mcm","clk":"5346761145","pt":1646096266190,"mc":[{"id":"1.195395454","rc":[{"atb":[[1.55,376.61],[1.54,0]],"id":40612296}],"con":true,"img":false}]}
{"op":"mcm","clk":"5346761205","pt":1646096267580,"mc":[{"id":"1.195395454","rc":[{"atb":[[1.55,290.97]],"id":40612296},{"atb":[[2.28,50.03]],"id":40324412}],"con":true,"img":false}]}
{"op":"mcm","clk":"5346761210","pt":1646096267685,"mc":[{"id":"1.195395454","rc":[{"atb":[[1.51,85.63]],"id":40612296},{"atb":[[2.22,81.97],[2.28,0],[2.12,31.2]],"id":40324412}],"con":true,"img":false}]}
{"op":"mcm","clk":"5346761352","pt":1646096271280,"mc":[{"id":"1.195395454","rc":[{"atb":[[1.54,185.19]],"id":40612296}],"con":true,"img":false}]}
{"op":"mcm","clk":"5346761357","pt":1646096271378,"mc":[{"id":"1.195395454","rc":[{"atb":[[1.55,109.15]],"id":40612296}],"con":true,"img":false}]}
{"op":"mcm","clk":"5346762832","pt":1646096311658,"mc":[{"id":"1.195395454","rc":[{"atl":[[1.91,0]],"id":42845264}],"con":true,"img":false}]}
{"op":"mcm","clk":"5346762836","pt":1646096311762,"mc":[{"id":"1.195395454","rc":[{"atl":[[1.92,81.12],[1.89,40.56]],"id":42845264}],"con":true,"img":false}]}
{"op":"mcm","clk":"5346762839","pt":1646096311863,"mc":[{"id":"1.195395454","rc":[{"atl":[[1.9,0]],"id":42845264}],"con":true,"img":false}]}
{"op":"mcm","clk":"5346763243","pt":1646096326994,"mc":[{"id":"1.195395454","rc":[{"atb":[[1.55,218.31],[1.54,0]],"id":40612296}],"con":true,"img":false}]}
{"op":"mcm","clk":"5346763245","pt":1646096327098,"mc":[{"id":"1.195395454","rc":[{"atb":[[1.55,109.15],[1.54,185.19]],"id":40612296}],"con":true,"img":false}]}
{"op":"mcm","clk":"5346763417","pt":1646096333615,"mc":[{"id":"1.195395454","rc":[{"atb":[[1.51,0]],"id":40612296},{"atb":[[2.12,0]],"id":40324412},{"atl":[[1.89,0]],"id":42845264}],"con":true,"img":false}]}
{"op":"mcm","clk":"5346763420","pt":1646096333718,"mc":[{"id":"1.195395454","rc":[{"atb":[[1.55,194.79]],"id":40612296},{"atb":[[2.24,31.2]],"id":40324412},{"atl":[[1.91,40.56]],"id":42845264}],"con":true,"img":false}]}
{"op":"mcm","clk":"5346763424","pt":1646096333821,"mc":[{"id":"1.195395454","rc":[{"atb":[[2.26,50.03]],"id":40324412}],"con":true,"img":false}]}
{"op":"mcm","clk":"5346763427","pt":1646096333923,"mc":[{"id":"1.195395454","rc":[{"atb":[[2.22,0]],"id":40324412}],"con":true,"img":false}]}
{"op":"mcm","clk":"5346763604","pt":1646096340799,"mc":[{"id":"1.195395454","rc":[{"atl":[[1.92,0],[1.9,40.56]],"id":42845264}],"con":true,"img":false}]}
{"op":"mcm","clk":"5346764989","pt":1646096387799,"mc":[{"id":"1.195395454","rc":[{"atb":[[1.55,376.61],[1.54,0]],"id":40612296}],"con":true,"img":false}]}
{"op":"mcm","clk":"5346764995","pt":1646096388006,"mc":[{"id":"1.195395454","rc":[{"atb":[[1.55,194.79],[1.54,185.19]],"id":40612296}],"con":true,"img":false}]}
{"op":"mcm","clk":"5346765263","pt":1646096397232,"mc":[{"id":"1.195395454","rc":[{"atb":[[2.24,0]],"id":40324412},{"atl":[[1.91,0]],"id":42845264}],"con":true,"img":false}]}
{"op":"mcm","clk":"5346765267","pt":1646096397335,"mc":[{"id":"1.195395454","rc":[{"atb":[[2.28,31.2]],"id":40324412},{"atl":[[1.89,40.56]],"id":42845264}],"con":true,"img":false}]}
{"op":"mcm","clk":"5346765272","pt":1646096397390,"mc":[{"id":"1.195395454","rc":[{"atb":[[2.22,81.97],[2.26,0]],"id":40324412},{"atl":[[1.92,81.12],[1.9,0]],"id":42845264}],"con":true,"img":false}]}
{"op":"mcm","clk":"5346766008","pt":1646096418368,"mc":[{"id":"1.195395454","rc":[{"atb":[[2.28,0]],"id":40324412},{"atl":[[1.89,0]],"id":42845264}],"con":true,"img":false}]}
{"op":"mcm","clk":"5346766011","pt":1646096418422,"mc":[{"id":"1.195395454","rc":[{"atb":[[2.24,31.2]],"id":40324412},{"atl":[[1.91,40.56]],"id":42845264}],"con":true,"img":false}]}
{"op":"mcm","clk":"5346766263","pt":1646096425576,"mc":[{"id":"1.195395454","rc":[{"atb":[[2.22,0],[2.26,50.03]],"id":40324412},{"atl":[[1.92,0],[1.9,40.56]],"id":42845264}],"con":true,"img":false}]}
{"op":"mcm","clk":"5346767136","pt":1646096448803,"mc":[{"id":"1.195395454","rc":[{"atb":[[1.55,376.61],[1.54,0]],"id":40612296}],"con":true,"img":false}]}
{"op":"mcm","clk":"5346767297","pt":1646096453888,"mc":[{"id":"1.195395454","rc":[{"atb":[[1.54,185.19]],"id":40612296}],"con":true,"img":false}]}
{"op":"mcm","clk":"5346767300","pt":1646096453987,"mc":[{"id":"1.195395454","rc":[{"atb":[[1.55,194.79]],"id":40612296}],"con":true,"img":false}]}
{"op":"mcm","clk":"5346768312","pt":1646096480453,"mc":[{"id":"1.195395454","rc":[{"atb":[[2.24,0]],"id":40324412},{"atl":[[1.91,0]],"id":42845264}],"con":true,"img":false}]}
{"op":"mcm","clk":"5346768318","pt":1646096480555,"mc":[{"id":"1.195395454","rc":[{"atb":[[2.28,31.2]],"id":40324412},{"atl":[[1.92,81.12],[1.89,40.56],[1.9,0]],"id":42845264}],"con":true,"img":false}]}
{"op":"mcm","clk":"5346768325","pt":1646096480661,"mc":[{"id":"1.195395454","rc":[{"atb":[[2.22,81.97],[2.26,0]],"id":40324412}],"con":true,"img":false}]}
{"op":"mcm","clk":"5346769143","pt":1646096500559,"mc":[{"id":"1.195395454","rc":[{"atb":[[2.28,0]],"id":40324412},{"atl":[[1.89,0]],"id":42845264}],"con":true,"img":false}]}
{"op":"mcm","clk":"5346769146","pt":1646096500661,"mc":[{"id":"1.195395454","rc":[{"atb":[[2.24,31.2]],"id":40324412},{"atl":[[1.91,40.56]],"id":42845264}],"con":true,"img":false}]}
{"op":"mcm","clk":"5346769414","pt":1646096507890,"mc":[{"id":"1.195395454","rc":[{"atl":[[1.92,0],[1.9,40.56]],"id":42845264}],"con":true,"img":false}]}
{"op":"mcm","clk":"5346769416","pt":1646096507994,"mc":[{"id":"1.195395454","rc":[{"atb":[[2.22,0],[2.26,50.03]],"id":40324412}],"con":true,"img":false}]}
{"op":"mcm","clk":"5346769469","pt":1646096509479,"mc":[{"id":"1.195395454","rc":[{"atb":[[1.55,376.61]],"id":40612296}],"con":true,"img":false}]}
{"op":"mcm","clk":"5346769470","pt":1646096509582,"mc":[{"id":"1.195395454","rc":[{"atb":[[1.54,0]],"id":40612296}],"con":true,"img":false}]}
{"op":"mcm","clk":"5346769475","pt":1646096509683,"mc":[{"id":"1.195395454","rc":[{"atb":[[1.54,185.19]],"id":40612296}],"con":true,"img":false}]}
{"op":"mcm","clk":"5346769480","pt":1646096509790,"mc":[{"id":"1.195395454","rc":[{"atb":[[1.55,194.79]],"id":40612296}],"con":true,"img":false}]}
{"op":"mcm","clk":"5346771231","pt":1646096561178,"mc":[{"id":"1.195395454","rc":[{"atb":[[2.24,0]],"id":40324412},{"atl":[[1.91,0]],"id":42845264}],"con":true,"img":false}]}
{"op":"mcm","clk":"5346771234","pt":1646096561283,"mc":[{"id":"1.195395454","rc":[{"atb":[[2.22,81.97],[2.28,31.2],[2.26,0]],"id":40324412},{"atl":[[1.92,81.12],[1.89,40.56],[1.9,0]],"id":42845264}],"con":true,"img":false}]}
{"op":"mcm","clk":"5346771350","pt":1646096564567,"mc":[{"id":"1.195395454","rc":[{"atb":[[1.55,376.61]],"id":40612296}],"con":true,"img":false}]}
{"op":"mcm","clk":"5346771353","pt":1646096564670,"mc":[{"id":"1.195395454","rc":[{"atb":[[1.54,0]],"id":40612296}],"con":true,"img":false}]}
{"op":"mcm","clk":"5346771981","pt":1646096580571,"mc":[{"id":"1.195395454","rc":[{"atb":[[1.55,290.97]],"id":40612296},{"atb":[[2.28,0]],"id":40324412},{"atl":[[1.89,0]],"id":42845264}],"con":true,"img":false}]}
{"op":"mcm","clk":"5346771985","pt":1646096580726,"mc":[{"id":"1.195395454","rc":[{"atb":[[1.51,85.63]],"id":40612296},{"atb":[[2.24,31.2]],"id":40324412},{"atl":[[1.91,40.56]],"id":42845264}],"con":true,"img":false}]}
{"op":"mcm","clk":"5346772232","pt":1646096587804,"mc":[{"id":"1.195395454","rc":[{"atb":[[2.24,81.23],[2.22,0]],"id":40324412},{"atl":[[1.92,0],[1.9,40.56]],"id":42845264}],"con":true,"img":false}]}
{"op":"mcm","clk":"5346774314","pt":1646096638801,"mc":[{"id":"1.195395454","rc":[{"atb":[[2.24,50.03]],"id":40324412},{"atl":[[1.91,0]],"id":42845264}],"con":true,"img":false}]}
{"op":"mcm","clk":"5346774317","pt":1646096638904,"mc":[{"id":"1.195395454","rc":[{"atb":[[2.26,31.2]],"id":40324412},{"atl":[[1.92,81.12],[1.89,40.56]],"id":42845264}],"con":true,"img":false}]}
{"op":"mcm","clk":"5346774321","pt":1646096639007,"mc":[{"id":"1.195395454","rc":[{"atb":[[2.24,0],[2.22,81.97]],"id":40324412},{"atl":[[1.9,0]],"id":42845264}],"con":true,"img":false}]}
{"op":"mcm","clk":"5346774323","pt":1646096639110,"mc":[{"id":"1.195395454","rc":[{"atb":[[2.24,62.4]],"id":40324412}],"con":true,"img":false}]}
{"op":"mcm","clk":"5346774326","pt":1646096639162,"mc":[{"id":"1.195395454","rc":[{"atb":[[2.22,0]],"id":40324412}],"con":true,"img":false}]}
{"op":"mcm","clk":"5346774978","pt":1646096658108,"mc":[{"id":"1.195395454","rc":[{"atl":[[1.89,0]],"id":42845264}],"con":true,"img":false}]}
{"op":"mcm","clk":"5346774982","pt":1646096658214,"mc":[{"id":"1.195395454","rc":[{"atl":[[1.91,40.56]],"id":42845264}],"con":true,"img":false}]}
{"op":"mcm","clk":"5346775229","pt":1646096664609,"mc":[{"id":"1.195395454","rc":[{"atl":[[1.92,0],[1.9,40.56]],"id":42845264}],"con":true,"img":false}]}
{"op":"mcm","clk":"5346777165","pt":1646096714685,"mc":[{"id":"1.195395454","rc":[{"atl":[[1.91,0]],"id":42845264}],"con":true,"img":false}]}
{"op":"mcm","clk":"5346777169","pt":1646096714791,"mc":[{"id":"1.195395454","rc":[{"atl":[[1.92,81.12],[1.89,40.56],[1.9,0]],"id":42845264}],"con":true,"img":false}]}
{"op":"mcm","clk":"5346777872","pt":1646096733353,"mc":[{"id":"1.195395454","rc":[{"atl":[[1.89,0]],"id":42845264}],"con":true,"img":false}]}
{"op":"mcm","clk":"5346777876","pt":1646096733455,"mc":[{"id":"1.195395454","rc":[{"atl":[[1.91,40.56]],"id":42845264}],"con":true,"img":false}]}
{"op":"mcm","clk":"5346778081","pt":1646096739734,"mc":[{"id":"1.195395454","rc":[{"atl":[[1.92,0],[1.9,40.56]],"id":42845264}],"con":true,"img":false}]}
{"op":"mcm","clk":"5346778448","pt":1646096751551,"mc":[{"id":"1.195395454","rc":[{"atb":[[1.55,109.15],[1.51,281.71]],"id":40612296},{"atb":[[2.24,0],[2.16,86.21]],"id":40324412}],"con":true,"img":false}]}
{"op":"mcm","clk":"5346778458","pt":1646096751856,"mc":[{"id":"1.195395454","rc":[{"atb":[[2.26,0]],"id":40324412}],"con":true,"img":false}]}
{"op":"mcm","clk":"5346778462","pt":1646096751956,"mc":[{"id":"1.195395454","rc":[{"atb":[[2.22,31.2]],"id":40324412}],"con":true,"img":false}]}
{"op":"mcm","clk":"5346778584","pt":1646096756061,"mc":[{"id":"1.195395454","rc":[{"atb":[[2.24,50.03]],"id":40324412}],"con":true,"img":false}]}
{"op":"mcm","clk":"5346778588","pt":1646096756163,"mc":[{"id":"1.195395454","rc":[{"atb":[[2.16,0]],"id":40324412}],"con":true,"img":false}]}
{"op":"mcm","clk":"5346779160","pt":1646096776230,"mc":[{"id":"1.195395454","rc":[{"atb":[[1.55,290.97],[1.51,85.63]],"id":40612296}],"con":true,"img":false}]}
{"op":"mcm","clk":"5346779503","pt":1646096788444,"mc":[{"id":"1.195395454","rc":[{"atl":[[1.91,0]],"id":42845264}],"con":true,"img":false}]}
{"op":"mcm","clk":"5346779506","pt":1646096788549,"mc":[{"id":"1.195395454","rc":[{"atl":[[1.92,81.12],[1.89,40.56]],"id":42845264}],"con":true,"img":false}]}
{"op":"mcm","clk":"5346779509","pt":1646096788650,"mc":[{"id":"1.195395454","rc":[{"atl":[[1.9,0]],"id":42845264}],"con":true,"img":false}]}
{"op":"mcm","clk":"5346779925","pt":1646096806667,"mc":[{"id":"1.195395454","rc":[{"atb":[[2.22,0]],"id":40324412},{"atl":[[1.89,0]],"id":42845264}],"con":true,"img":false}]}
{"op":"mcm","clk":"5346779928","pt":1646096806769,"mc":[{"id":"1.195395454","rc":[{"atb":[[2.24,0],[2.22,81.97],[2.26,31.2]],"id":40324412},{"atl":[[1.91,40.56]],"id":42845264}],"con":true,"img":false}]}
{"op":"mcm","clk":"5346780053","pt":1646096812762,"mc":[{"id":"1.195395454","rc":[{"atl":[[1.92,0],[1.9,40.56]],"id":42845264}],"con":true,"img":false}]}
{"op":"mcm","clk":"5346780094","pt":1646096814762,"mc":[{"id":"1.195395454","rc":[{"atb":[[1.44,227.27],[1.55,109.15]],"id":40612296},{"atb":[[2.22,0],[2.2,133.35]],"id":40324412},{"atb":[[1.27,370.37],[1.23,0]],"id":43066392}],"con":true,"img":false}]}
{"op":"mcm","clk":"5346780388","pt":1646096824774,"mc":[{"id":"1.195395454","rc":[{"atb":[[2.26,0]],"id":40324412}],"con":true,"img":false}]}
{"op":"mcm","clk":"5346780391","pt":1646096824876,"mc":[{"id":"1.195395454","rc":[{"atb":[[2.22,31.2]],"id":40324412}],"con":true,"img":false}]}
{"op":"mcm","clk":"5346781548","pt":1646096860733,"mc":[{"id":"1.195395454","rc":[{"atl":[[1.91,0]],"id":42845264}],"con":true,"img":false}]}
{"op":"mcm","clk":"5346781552","pt":1646096860835,"mc":[{"id":"1.195395454","rc":[{"atl":[[1.92,81.12],[1.89,40.56],[1.9,0]],"id":42845264}],"con":true,"img":false}]}
{"op":"mcm","clk":"5346782176","pt":1646096878364,"mc":[{"id":"1.195395454","rc":[{"atl":[[1.89,0]],"id":42845264}],"con":true,"img":false}]}
{"op":"mcm","clk":"5346782180","pt":1646096878468,"mc":[{"id":"1.195395454","rc":[{"atl":[[1.91,40.56]],"id":42845264}],"con":true,"img":false}]}
{"op":"mcm","clk":"5346782412","pt":1646096884382,"mc":[{"id":"1.195395454","rc":[{"atl":[[1.92,0],[1.9,40.56]],"id":42845264}],"con":true,"img":false}]}
{"op":"mcm","clk":"5346784051","pt":1646096930994,"mc":[{"id":"1.195395454","rc":[{"atl":[[1.91,0]],"id":42845264}],"con":true,"img":false}]}
{"op":"mcm","clk":"5346784055","pt":1646096931096,"mc":[{"id":"1.195395454","rc":[{"atl":[[1.92,81.12],[1.89,40.56],[1.9,0]],"id":42845264}],"con":true,"img":false}]}
{"op":"mcm","clk":"5346784702","pt":1646096948185,"mc":[{"id":"1.195395454","rc":[{"atl":[[1.89,0]],"id":42845264}],"con":true,"img":false}]}
{"op":"mcm","clk":"5346784710","pt":1646096948288,"mc":[{"id":"1.195395454","rc":[{"atl":[[1.91,40.56]],"id":42845264}],"con":true,"img":false}]}
{"op":"mcm","clk":"5346784966","pt":1646096953945,"mc":[{"id":"1.195395454","rc":[{"atl":[[1.92,0],[1.9,40.56]],"id":42845264}],"con":true,"img":false}]}
{"op":"mcm","clk":"5346786739","pt":1646096997611,"mc":[{"id":"1.195395454","rc":[{"atb":[[2.12,89.29],[2.2,50.02]],"id":40324412},{"atl":[[2.54,7.79],[2.62,31.2]],"id":43066392}],"con":true,"img":false}]}
{"op":"mcm","clk":"5346786786","pt":1646096999098,"mc":[{"id":"1.195395454","rc":[{"atl":[[1.91,0]],"id":42845264}],"con":true,"img":false}]}
{"op":"mcm","clk":"5346786791","pt":1646096999201,"mc":[{"id":"1.195395454","rc":[{"atl":[[1.89,40.56]],"id":42845264}],"con":true,"img":false}]}
{"op":"mcm","clk":"5346786794","pt":1646096999303,"mc":[{"id":"1.195395454","rc":[{"atl":[[1.92,81.12]],"id":42845264}],"con":true,"img":false}]}
{"op":"mcm","clk":"5346786798","pt":1646096999405,"mc":[{"id":"1.195395454","rc":[{"atl":[[1.9,0]],"id":42845264}],"con":true,"img":false}]}
{"op":"mcm","clk":"5346787368","pt":1646097016102,"mc":[{"id":"1.195395454","rc":[{"atl":[[1.89,0]],"id":42845264}],"con":true,"img":false}]}
{"op":"mcm","clk":"5346787370","pt":1646097016206,"mc":[{"id":"1.195395454","rc":[{"atl":[[1.91,40.56]],"id":42845264}],"con":true,"img":false}]}
{"op":"mcm","clk":"5346787529","pt":1646097021446,"mc":[{"id":"1.195395454","rc":[{"atl":[[1.9,40.56]],"id":42845264}],"con":true,"img":false}]}
{"op":"mcm","clk":"5346787534","pt":1646097021499,"mc":[{"id":"1.195395454","rc":[{"atl":[[1.92,0]],"id":42845264}],"con":true,"img":false}]}
{"op":"mcm","clk":"5346789106","pt":1646097065603,"mc":[{"id":"1.195395454","rc":[{"atl":[[1.91,0]],"id":42845264}],"con":true,"img":false}]}
{"op":"mcm","clk":"5346789108","pt":1646097065708,"mc":[{"id":"1.195395454","rc":[{"atl":[[1.92,81.12],[1.89,40.56]],"id":42845264}],"con":true,"img":false}]}
{"op":"mcm","clk":"5346789111","pt":1646097065814,"mc":[{"id":"1.195395454","rc":[{"atl":[[1.9,0]],"id":42845264}],"con":true,"img":false}]}
{"op":"mcm","clk":"5346789671","pt":1646097081331,"mc":[{"id":"1.195395454","rc":[{"atl":[[1.89,0]],"id":42845264}],"con":true,"img":false}]}
{"op":"mcm","clk":"5346789675","pt":1646097081443,"mc":[{"id":"1.195395454","rc":[{"atl":[[1.91,40.56]],"id":42845264}],"con":true,"img":false}]}
{"op":"mcm","clk":"5346789870","pt":1646097087251,"mc":[{"id":"1.195395454","rc":[{"atl":[[1.9,40.56]],"id":42845264}],"con":true,"img":false}]}
{"op":"mcm","clk":"5346789878","pt":1646097087354,"mc":[{"id":"1.195395454","rc":[{"atl":[[1.92,0]],"id":42845264}],"con":true,"img":false}]}
{"op":"mcm","clk":"5346791582","pt":1646097130296,"mc":[{"id":"1.195395454","rc":[{"atl":[[1.91,0]],"id":42845264}],"con":true,"img":false}]}
{"op":"mcm","clk":"5346791588","pt":1646097130399,"mc":[{"id":"1.195395454","rc":[{"atl":[[1.92,81.12],[1.89,40.56],[1.9,0]],"id":42845264}],"con":true,"img":false}]}
{"op":"mcm","clk":"5346792230","pt":1646097146318,"mc":[{"id":"1.195395454","rc":[{"atl":[[1.89,0]],"id":42845264}],"con":true,"img":false}]}
{"op":"mcm","clk":"5346792236","pt":1646097146420,"mc":[{"id":"1.195395454","rc":[{"atl":[[1.91,40.56]],"id":42845264}],"con":true,"img":false}]}
{"op":"mcm","clk":"5346792392","pt":1646097151256,"mc":[{"id":"1.195395454","rc":[{"atl":[[1.92,0],[1.9,40.56]],"id":42845264}],"con":true,"img":false}]}
{"op":"mcm","clk":"5346792883","pt":1646097163650,"mc":[{"id":"1.195395454","rc":[{"atb":[[2.2,133.35]],"id":40324412}],"con":true,"img":false}]}
{"op":"mcm","clk":"5346792891","pt":1646097163753,"mc":[{"id":"1.195395454","rc":[{"atb":[[2.12,0]],"id":40324412},{"atl":[[2.54,15.59],[2.62,0]],"id":43066392}],"con":true,"img":false}]}
{"op":"mcm","clk":"5346794173","pt":1646097193715,"mc":[{"id":"1.195395454","rc":[{"atl":[[1.91,0]],"id":42845264}],"con":true,"img":false}]}
{"op":"mcm","clk":"5346794175","pt":1646097193817,"mc":[{"id":"1.195395454","rc":[{"atl":[[1.92,81.12],[1.89,40.56],[1.9,0]],"id":42845264}],"con":true,"img":false}]}
{"op":"mcm","clk":"5346794182","pt":1646097193920,"mc":[{"id":"1.195395454","rc":[{"atl":[[1.92,0],[1.88,40.56]],"id":42845264}],"con":true,"img":false}]}
{"op":"mcm","clk":"5346796054","pt":1646097240375,"mc":[{"id":"1.195395454","rc":[{"atl":[[1.89,0]],"id":42845264}],"con":true,"img":false}]}
{"op":"mcm","clk":"5346796059","pt":1646097240477,"mc":[{"id":"1.195395454","rc":[{"atl":[[1.92,81.12],[1.88,0],[1.87,40.56]],"id":42845264}],"con":true,"img":false}]}
{"op":"mcm","clk":"5346796244","pt":1646097245575,"mc":[{"id":"1.195395454","rc":[{"atb":[[1.53,70.52],[1.35,0]],"id":42901530},{"atl":[[2.54,7.79],[2.76,22.5]],"id":43066392},{"atb":[[1.17,0]],"id":43154432},{"atb":[[1.89,75.92],[1.62,0]],"id":39586887}],"con":true,"img":false}]}
{"op":"mcm","clk":"5346796656","pt":1646097255702,"mc":[{"id":"1.195395454","rc":[{"atl":[[1.87,0]],"id":42845264}],"con":true,"img":false}]}
{"op":"mcm","clk":"5346796662","pt":1646097255807,"mc":[{"id":"1.195395454","rc":[{"atl":[[1.91,40.56]],"id":42845264}],"con":true,"img":false}]}
{"op":"mcm","clk":"5346796873","pt":1646097260229,"mc":[{"id":"1.195395454","rc":[{"atl":[[1.9,40.56]],"id":42845264}],"con":true,"img":false}]}
{"op":"mcm","clk":"5346796879","pt":1646097260331,"mc":[{"id":"1.195395454","rc":[{"atl":[[1.92,0]],"id":42845264}],"con":true,"img":false}]}
{"op":"mcm","clk":"5346797344","pt":1646097270631,"mc":[{"id":"1.195395454","rc":[{"atl":[[2.92,0]],"id":43066392}],"con":true,"img":false}]}
{"op":"mcm","clk":"5346797348","pt":1646097270731,"mc":[{"id":"1.195395454","rc":[{"atl":[[2.74,33.58]],"id":43066392}],"con":true,"img":false}]}
{"op":"mcm","clk":"5346798512","pt":1646097303618,"mc":[{"id":"1.195395454","rc":[{"atb":[[3.45,20.41],[3.35,31.91],[3.55,7.84],[3.25,55.56]],"id":37076607},{"atl":[[42,1],[46,1.11],[50,1.53],[60,2.12]],"id":37076607},{"atb":[[1.59,127.12],[1.63,31.75],[1.57,219.3],[1.61,81.97]],"id":42901530},{"atl":[[7.4,11.72],[7.8,20.14],[6.6,3.57],[7,8.33]],"id":42901530},{"atb":[[1.56,76.27],[1.54,92.59],[1.5,490.14],[1.52,144.23]],"id":40612296},{"atl":[[5.1,16.59],[5.3,11.63],[5.5,16.67],[5.7,26.6]],"id":40612296},{"atb":[[2.42,35.21],[2.38,54.35],[2.46,13.7],[2.34,93.28]],"id":40324412},{"atl":[[9.6,2.33],[10,5.56],[11,7.5],[12,11.36]],"id":40324412},{"atb":[[1.33,151.52],[1.29,250],[1.31,361.31],[1.35,97.7]],"id":43066392},{"atl":[[2.8,27.78],[2.88,66.49],[2.84,40.76],[2.76,33.86]],"id":43066392},{"atb":[[1.02,7174.56]],"id":42845264},{"atl":[[1.56,89.29],[1.6,208.33],[1.58,129.31],[1.54,37.04]],"id":42845264},{"atb":[[1.03,250],[1.09,222.22],[1.07,250],[1.05,250]],"id":43154432},{"atl":[[4,25],[3.8,7.14],[3.9,17.24],[4.2,39.06]],"id":43154432},{"atb":[[2,20],[1.98,51.02],[1.96,78.12],[1.94,132.98]],"id":39586887},{"atl":[[10.5,7.89],[11.5,14.18],[9.8,5.68],[9.4,7.2]],"id":39586887}],"con":true,"img":false}]}
{"op":"mcm","clk":"5346798514","pt":1646097303674,"mc":[{"id":"1.195395454","rc":[{"atl":[[10,5.56],[11,7.5],[12,11.36],[9.6,2.33]],"id":39586887}],"con":true,"img":false}]}
{"op":"mcm","clk":"5346798518","pt":1646097303775,"mc":[{"id":"1.195395454","rc":[{"atb":[[3.6,20.41],[2.96,0]],"id":37076607},{"atl":[[1.54,126.33],[1.9,0]],"id":42845264},{"atl":[[5.1,2.92],[4.1,32.26]],"id":43154432}],"con":true,"img":false}]}
{"op":"mcm","clk":"5346798631","pt":1646097306183,"mc":[{"id":"1.195395454","rc":[{"atl":[[10,0],[11,0],[12,0],[9.6,0]],"id":39586887}],"con":true,"img":false}]}
{"op":"mcm","clk":"5346798701","pt":1646097308131,"mc":[{"id":"1.195395454","rc":[{"atl":[[5,0],[3.5,0]],"id":40612296},{"atl":[[8.8,4.67]],"id":40324412},{"atl":[[3.8,0]],"id":43066392},{"atl":[[2.24,0],[1.91,0]],"id":42845264}],"con":true,"img":false}]}
{"op":"mcm","clk":"5346798707","pt":1646097308186,"mc":[{"id":"1.195395454","rc":[{"atl":[[5.1,26.44],[4.3,16.22]],"id":40612296},{"atl":[[1.89,40.56]],"id":42845264}],"con":true,"img":false}]}
{"op":"mcm","clk":"5346798743","pt":1646097308901,"mc":[{"id":"1.195395454","rc":[{"atb":[[3.6,0],[3.45,52.32]],"id":37076607},{"atl":[[1.58,301.72],[1.54,37.04]],"id":42845264}],"con":true,"img":false}]}
{"op":"mcm","clk":"5346798941","pt":1646097314030,"mc":[{"id":"1.195395454","rc":[{"atb":[[3.45,20.41],[3.35,74.46]],"id":37076607}],"con":true,"img":false}]}
{"op":"mcm","clk":"5346798953","pt":1646097314399,"mc":[{"id":"1.195395454","rc":[{"atl":[[9.6,2.33],[9.4,4.82]],"id":39586887}],"con":true,"img":false}]}
{"op":"mcm","clk":"5346798960","pt":1646097314598,"mc":[{"id":"1.195395454","rc":[{"atl":[[9.6,0],[9.4,7.2]],"id":39586887}],"con":true,"img":false}]}
{"op":"mcm","clk":"5346799078","pt":1646097318028,"mc":[{"id":"1.195395454","rc":[{"atl":[[11.5,0],[17.5,0],[22,1.93]],"id":37076607},{"atl":[[7.4,0]],"id":40324412},{"atb":[[1.54,74.61],[1.96,0],[2.08,0]],"id":43154432},{"atl":[[9.4,2.38]],"id":39586887}],"con":true,"img":false}]}
{"op":"mcm","clk":"5346799082","pt":1646097318133,"mc":[{"id":"1.195395454","rc":[{"atl":[[32,2.7]],"id":37076607},{"atl":[[9,8.07]],"id":40324412},{"atb":[[1.96,37.55]],"id":43154432},{"atl":[[11,4.82]],"id":39586887}],"con":true,"img":false}]}
{"op":"mcm","clk":"5346799429","pt":1646097326702,"mc":[{"id":"1.195395454","rc":[{"atl":[[9.6,2.33],[9.4,0]],"id":39586887}],"con":true,"img":false}]}
{"op":"mcm","clk":"5346799430","pt":1646097326804,"mc":[{"id":"1.195395454","rc":[{"atl":[[9.4,2.38]],"id":39586887}],"con":true,"img":false}]}
{"op":"mcm","clk":"5346799436","pt":1646097326907,"mc":[{"id":"1.195395454","rc":[{"atl":[[9.6,0]],"id":39586887}],"con":true,"img":false}]}
{"op":"mcm","clk":"5346799484","pt":1646097327832,"mc":[{"id":"1.195395454","rc":[{"atl":[[6.8,3.45],[6.6,0]],"id":42901530}],"con":true,"img":false}]}
{"op":"mcm","clk":"5346799489","pt":1646097327938,"mc":[{"id":"1.195395454","rc":[{"atl":[[10.5,4.09]],"id":40324412},{"atb":[[1.31,241.94]],"id":43066392},{"atl":[[3.8,14.06]],"id":43066392},{"atl":[[1.98,38.44]],"id":42845264}],"con":true,"img":false}]}
{"op":"mcm","clk":"5346799495","pt":1646097328039,"mc":[{"id":"1.195395454","rc":[{"atb":[[1.34,119.37]],"id":43066392}],"con":true,"img":false}]}
{"op":"mcm","clk":"5346799878","pt":1646097337837,"mc":[{"id":"1.195395454","rc":[{"atl":[[7.2,8.06]],"id":42901530}],"con":true,"img":false}]}
{"op":"mcm","clk":"5346799882","pt":1646097337938,"mc":[{"id":"1.195395454","rc":[{"atb":[[3.6,15.6],[2.94,0]],"id":37076607},{"atl":[[5.3,9.43],[6.8,0]],"id":43154432},{"atb":[[2.62,43.6],[1.95,0]],"id":39586887}],"con":true,"img":false}]}
{"op":"mcm","clk":"5346799887","pt":1646097338042,"mc":[{"id":"1.195395454","rc":[{"atb":[[3.35,31.91],[3.65,15.6]],"id":37076607},{"atl":[[4.3,0]],"id":40612296},{"atb":[[2.22,0]],"id":40324412},{"atl":[[1.89,0]],"id":42845264},{"atb":[[2.62,22.25]],"id":39586887}],"con":true,"img":false}]}
{"op":"mcm","clk":"5346799890","pt":1646097338143,"mc":[{"id":"1.195395454","rc":[{"atl":[[3.85,16.22]],"id":40612296},{"atb":[[2.36,31.2]],"id":40324412},{"atl":[[1.55,40.56]],"id":42845264},{"atb":[[2.8,21.34]],"id":39586887}],"con":true,"img":false}]}
{"op":"mcm","clk":"5346799894","pt":1646097338247,"mc":[{"id":"1.195395454","rc":[{"atl":[[1.58,129.31],[1.54,77.6]],"id":42845264}],"con":true,"img":false}]}
{"op":"mcm","clk":"5346799920","pt":1646097338814,"mc":[{"id":"1.195395454","rc":[{"atl":[[7.4,0],[7,0],[7.8,1.76]],"id":42901530},{"atl":[[9.6,2.33],[9.4,0]],"id":39586887}],"con":true,"img":false}]}
{"op":"mcm","clk":"5346799927","pt":1646097338918,"mc":[{"id":"1.195395454","rc":[{"atl":[[9.6,0],[9.4,2.38]],"id":39586887}],"con":true,"img":false}]}
{"op":"mcm","clk":"5346800257","pt":1646097347854,"mc":[{"id":"1.195395454","rc":[{"atl":[[7.6,11.36]],"id":42901530}],"con":true,"img":false}]}
{"op":"mcm","clk":"5346800266","pt":1646097347955,"mc":[{"id":"1.195395454","rc":[{"atl":[[5.1,16.59]],"id":40612296}],"con":true,"img":false}]}
{"op":"mcm","clk":"5346800269","pt":1646097348058,"mc":[{"id":"1.195395454","rc":[{"atl":[[5,9.84]],"id":40612296}],"con":true,"img":false}]}
{"op":"mcm","clk":"5346800400","pt":1646097351237,"mc":[{"id":"1.195395454","rc":[{"atl":[[9.6,2.33],[9.4,0]],"id":39586887}],"con":true,"img":false}]}
{"op":"mcm","clk":"5346800411","pt":1646097351444,"mc":[{"id":"1.195395454","rc":[{"atl":[[9.6,0],[9.4,2.38]],"id":39586887}],"con":true,"img":false}]}
{"op":"mcm","clk":"5346800602","pt":1646097356889,"mc":[{"id":"1.195395454","rc":[{"atb":[[2.72,0],[3.4,14.79]],"id":37076607},{"atb":[[2.02,0]],"id":40324412}],"con":true,"img":false}]}
{"op":"mcm","clk":"5346800609","pt":1646097356990,"mc":[{"id":"1.195395454","rc":[{"atb":[[2.22,38.17]],"id":40324412}],"con":true,"img":false}]}
{"op":"mcm","clk":"5346800650","pt":1646097357869,"mc":[{"id":"1.195395454","rc":[{"atl":[[8,17.86]],"id":42901530}],"con":true,"img":false}]}
{"op":"mcm","clk":"5346800657","pt":1646097357972,"mc":[{"id":"1.195395454","rc":[{"atb":[[2.36,0]],"id":40324412}],"con":true,"img":false}]}
{"op":"mcm","clk":"5346800662","pt":1646097358074,"mc":[{"id":"1.195395454","rc":[{"atb":[[2.4,31.2]],"id":40324412}],"con":true,"img":false}]}
{"op":"mcm","clk":"5346800857","pt":1646097364180,"mc":[{"id":"1.195395454","rc":[{"atl":[[9.6,2.33]],"id":39586887}],"con":true,"img":false}]}
{"op":"mcm","clk":"5346800861","pt":1646097364282,"mc":[{"id":"1.195395454","rc":[{"atl":[[9.4,0]],"id":39586887}],"con":true,"img":false}]}
{"op":"mcm","clk":"5346800868","pt":1646097364487,"mc":[{"id":"1.195395454","rc":[{"atb":[[3.55,0],[3.5,8]],"id":37076607},{"atl":[[7.2,3.23],[6.8,0]],"id":42901530},{"atl":[[9.6,0],[9.4,2.38]],"id":39586887}],"con":true,"img":false}]}
{"op":"mcm","clk":"5346801002","pt":1646097367980,"mc":[{"id":"1.195395454","rc":[{"atl":[[1.55,0]],"id":42845264},{"atb":[[1.96,0]],"id":43154432}],"con":true,"img":false}]}
{"op":"mcm","clk":"5346801006","pt":1646097368088,"mc":[{"id":"1.195395454","rc":[{"atl":[[1.58,296.2],[1.54,37.04],[1.53,40.56]],"id":42845264},{"atb":[[2.02,37.55]],"id":43154432}],"con":true,"img":false}]}
{"op":"mcm","clk":"5346801011","pt":1646097368185,"mc":[{"id":"1.195395454","rc":[{"atl":[[1.54,126.33]],"id":42845264}],"con":true,"img":false}]}
{"op":"mcm","clk":"5346801014","pt":1646097368286,"mc":[{"id":"1.195395454","rc":[{"atl":[[1.58,129.31]],"id":42845264}],"con":true,"img":false}]}
{"op":"mcm","clk":"5346801245","pt":1646097374512,"mc":[{"id":"1.195395454","rc":[{"atb":[[3.4,35.62]],"id":37076607},{"atl":[[7.6,18.94]],"id":42901530}],"con":true,"img":false}]}
{"op":"mcm","clk":"5346801249","pt":1646097374612,"mc":[{"id":"1.195395454","rc":[{"atl":[[7.6,7.58]],"id":42901530}],"con":true,"img":false}]}
{"op":"mcm","clk":"5346801286","pt":1646097375689,"mc":[{"id":"1.195395454","rc":[{"atb":[[3.45,0],[3.35,0],[3.25,0]],"id":37076607},{"atl":[[9.6,2.33],[9.4,0]],"id":39586887}],"con":true,"img":false}]}
{"op":"mcm","clk":"5346801289","pt":1646097375790,"mc":[{"id":"1.195395454","rc":[{"atl":[[9.4,2.38]],"id":39586887}],"con":true,"img":false}]}
{"op":"mcm","clk":"5346801292","pt":1646097375894,"mc":[{"id":"1.195395454","rc":[{"atl":[[9.6,0]],"id":39586887}],"con":true,"img":false}]}
{"op":"mcm","clk":"5346801361","pt":1646097377997,"mc":[{"id":"1.195395454","rc":[{"atb":[[2.92,18.49],[3.4,20.83]],"id":37076607}],"con":true,"img":false}]}
{"op":"mcm","clk":"5346801591","pt":1646097384528,"mc":[{"id":"1.195395454","rc":[{"atb":[[3.3,32.61]],"id":37076607},{"atl":[[8,28.57]],"id":42901530}],"con":true,"img":false}]}
{"op":"mcm","clk":"5346801595","pt":1646097384583,"mc":[{"id":"1.195395454","rc":[{"atl":[[8,10.71]],"id":42901530}],"con":true,"img":false}]}
{"op":"mcm","clk":"5346801702","pt":1646097387503,"mc":[{"id":"1.195395454","rc":[{"atl":[[9.6,2.33],[9.4,0]],"id":39586887}],"con":true,"img":false}]}
{"op":"mcm","clk":"5346801708","pt":1646097387605,"mc":[{"id":"1.195395454","rc":[{"atl":[[9.6,0],[9.4,2.38]],"id":39586887}],"con":true,"img":false}]}
{"op":"mcm","clk":"5346801726","pt":1646097388015,"mc":[{"id":"1.195395454","rc":[{"atl":[[22,0]],"id":37076607},{"atb":[[2.72,20.9],[2.02,0]],"id":42901530}],"con":true,"img":false}]}
{"op":"mcm","clk":"5346801730","pt":1646097388117,"mc":[{"id":"1.195395454","rc":[{"atl":[[21,1.93]],"id":37076607}],"con":true,"img":false}]}
{"op":"mcm","clk":"5346801976","pt":1646097394537,"mc":[{"id":"1.195395454","rc":[{"atb":[[3.2,56.82]],"id":37076607},{"atl":[[8.4,16.89]],"id":42901530}],"con":true,"img":false}]}
{"op":"mcm","clk":"5346802163","pt":1646097399725,"mc":[{"id":"1.195395454","rc":[{"atl":[[9.6,2.33],[9.4,0]],"id":39586887}],"con":true,"img":false}]}
{"op":"mcm","clk":"5346802167","pt":1646097399828,"mc":[{"id":"1.195395454","rc":[{"atl":[[9.6,0],[9.4,2.38]],"id":39586887}],"con":true,"img":false}]}
{"op":"mcm","clk":"5346802645","pt":1646097411827,"mc":[{"id":"1.195395454","rc":[{"atl":[[9.6,2.33]],"id":39586887}],"con":true,"img":false}]}
{"op":"mcm","clk":"5346802649","pt":1646097411930,"mc":[{"id":"1.195395454","rc":[{"atl":[[9.4,0]],"id":39586887}],"con":true,"img":false}]}
{"op":"mcm","clk":"5346802696","pt":1646097413669,"mc":[{"id":"1.195395454","rc":[{"atl":[[9.6,0],[9.4,2.38]],"id":39586887}],"con":true,"img":false}]}
{"op":"mcm","clk":"5346803091","pt":1646097424254,"mc":[{"id":"1.195395454","rc":[{"atl":[[9.6,2.33],[9.4,0]],"id":39586887}],"con":true,"img":false}]}
{"op":"mcm","clk":"5346803136","pt":1646097424869,"mc":[{"id":"1.195395454","rc":[{"atl":[[9.6,0],[9.4,2.38]],"id":39586887}],"con":true,"img":false}]}
{"op":"mcm","clk":"5346803271","pt":1646097427957,"mc":[{"id":"1.195395454","rc":[{"atb":[[2.92,0],[3.35,15.11]],"id":37076607}],"con":true,"img":false}]}
{"op":"mcm","clk":"5346803975","pt":1646097448815,"mc":[{"id":"1.195395454","rc":[{"atl":[[9.6,2.33],[9.4,0]],"id":39586887}],"con":true,"img":false}]}
{"op":"mcm","clk":"5346803999","pt":1646097449431,"mc":[{"id":"1.195395454","rc":[{"atl":[[9.6,0],[9.4,2.38]],"id":39586887}],"con":true,"img":false}]}
{"op":"mcm","clk":"5346804425","pt":1646097460438,"mc":[{"id":"1.195395454","rc":[{"atl":[[9.6,2.33]],"id":39586887}],"con":true,"img":false}]}
{"op":"mcm","clk":"5346804429","pt":1646097460537,"mc":[{"id":"1.195395454","rc":[{"atl":[[9.4,0]],"id":39586887}],"con":true,"img":false}]}
{"op":"mcm","clk":"5346804434","pt":1646097460745,"mc":[{"id":"1.195395454","rc":[{"atl":[[9.6,0],[9.4,2.38]],"id":39586887}],"con":true,"img":false}]}
{"op":"mcm","clk":"5346804850","pt":1646097472856,"mc":[{"id":"1.195395454","rc":[{"atl":[[9.6,2.33],[9.4,0]],"id":39586887}],"con":true,"img":false}]}
{"op":"mcm","clk":"5346804863","pt":1646097473060,"mc":[{"id":"1.195395454","rc":[{"atl":[[9.6,0],[9.4,2.38]],"id":39586887}],"con":true,"img":false}]}
{"op":"mcm","clk":"5346805285","pt":1646097484877,"mc":[{"id":"1.195395454","rc":[{"atl":[[9.6,2.33],[9.4,0]],"id":39586887}],"con":true,"img":false}]}
{"op":"mcm","clk":"5346805294","pt":1646097485029,"mc":[{"id":"1.195395454","rc":[{"atl":[[9.6,0],[9.4,2.38]],"id":39586887}],"con":true,"img":false}]}
{"op":"mcm","clk":"5346805751","pt":1646097496794,"mc":[{"id":"1.195395454","rc":[{"atl":[[9.6,2.33],[9.4,0]],"id":39586887}],"con":true,"img":false}]}
{"op":"mcm","clk":"5346805761","pt":1646097496999,"mc":[{"id":"1.195395454","rc":[{"atl":[[9.4,2.38]],"id":39586887}],"con":true,"img":false}]}
{"op":"mcm","clk":"5346805765","pt":1646097497103,"mc":[{"id":"1.195395454","rc":[{"atl":[[9.6,0]],"id":39586887}],"con":true,"img":false}]}
{"op":"mcm","clk":"5346806248","pt":1646097509186,"mc":[{"id":"1.195395454","rc":[{"atl":[[9.6,2.33]],"id":39586887}],"con":true,"img":false}]}
{"op":"mcm","clk":"5346806250","pt":1646097509288,"mc":[{"id":"1.195395454","rc":[{"atl":[[9.4,0]],"id":39586887}],"con":true,"img":false}]}
{"op":"mcm","clk":"5346806255","pt":1646097509392,"mc":[{"id":"1.195395454","rc":[{"atl":[[9.6,0]],"id":39586887}],"con":true,"img":false}]}
{"op":"mcm","clk":"5346806332","pt":1646097511395,"mc":[{"id":"1.195395454","rc":[{"atl":[[9.4,2.38]],"id":39586887}],"con":true,"img":false}]}
{"op":"mcm","clk":"5346807161","pt":1646097534742,"mc":[{"id":"1.195395454","rc":[{"atb":[[1.27,0],[1.3,471]],"id":43066392}],"con":true,"img":false}]}
{"op":"mcm","clk":"5346813226","pt":1646097713813,"mc":[{"id":"1.195395454","rc":[{"atl":[[42,0],[44,1]],"id":37076607}],"con":true,"img":false}]}
{"op":"mcm","clk":"5346813594","pt":1646097723824,"mc":[{"id":"1.195395454","rc":[{"atl":[[48,1.06]],"id":37076607}],"con":true,"img":false}]}
{"op":"mcm","clk":"5346813827","pt":1646097730436,"mc":[{"id":"1.195395454","rc":[{"atl":[[46,0],[50,0],[60,0]],"id":37076607}],"con":true,"img":false}]}
{"op":"mcm","clk":"5346813939","pt":1646097733869,"mc":[{"id":"1.195395454","rc":[{"atl":[[55,1.39]],"id":37076607}],"con":true,"img":false}]}
{"op":"mcm","clk":"5346814278","pt":1646097743863,"mc":[{"id":"1.195395454","rc":[{"atl":[[65,1.95]],"id":37076607}],"con":true,"img":false}]}
{"op":"mcm","clk":"5346814957","pt":1646097764093,"mc":[{"id":"1.195395454","rc":[{"atl":[[9.2,2.44],[9.4,0]],"id":39586887}],"con":true,"img":false}]}
{"op":"mcm","clk":"5346815353","pt":1646097775417,"mc":[{"id":"1.195395454","rc":[{"atl":[[9.2,0],[9.4,2.38]],"id":39586887}],"con":true,"img":false}]}
{"op":"mcm","clk":"5346815359","pt":1646097775622,"mc":[{"id":"1.195395454","rc":[{"atl":[[9.2,2.44],[9.4,0]],"id":39586887}],"con":true,"img":false}]}
{"op":"mcm","clk":"5346815789","pt":1646097787739,"mc":[{"id":"1.195395454","rc":[{"atl":[[9.2,0],[9.4,2.38]],"id":39586887}],"con":true,"img":false}]}
{"op":"mcm","clk":"5346815797","pt":1646097787948,"mc":[{"id":"1.195395454","rc":[{"atl":[[9.2,2.44],[9.4,0]],"id":39586887}],"con":true,"img":false}]}
{"op":"mcm","clk":"5346816187","pt":1646097799140,"mc":[{"id":"1.195395454","rc":[{"atl":[[9.2,0],[9.4,2.38]],"id":39586887}],"con":true,"img":false}]}
{"op":"mcm","clk":"5346816193","pt":1646097799346,"mc":[{"id":"1.195395454","rc":[{"atl":[[9.2,2.44],[9.4,0]],"id":39586887}],"con":true,"img":false}]}
{"op":"mcm","clk":"5346816586","pt":1646097810382,"mc":[{"id":"1.195395454","rc":[{"atl":[[9.2,0],[9.4,2.38]],"id":39586887}],"con":true,"img":false}]}
{"op":"mcm","clk":"5346816591","pt":1646097810587,"mc":[{"id":"1.195395454","rc":[{"atl":[[9.2,2.44],[9.4,0]],"id":39586887}],"con":true,"img":false}]}
{"op":"mcm","clk":"5346817493","pt":1646097834075,"mc":[{"id":"1.195395454","rc":[{"atb":[[1.3,200.11],[1.31,491.94]],"id":43066392},{"atl":[[9.2,0],[9.4,2.38]],"id":39586887}],"con":true,"img":false}]}
{"op":"mcm","clk":"5346818255","pt":1646097853234,"mc":[{"id":"1.195395454","rc":[{"atb":[[3.2,0],[2.88,53.19],[3.4,0],[3.5,0],[3.3,0],[3.65,0],[3.05,9.76]],"id":37076607},{"atb":[[1.8,81.97],[1.63,0],[1.9,22.22],[1.53,0]],"id":42901530},{"atl":[[5.1,11.71],[5.2,0],[3.55,29.71]],"id":40612296},{"atl":[[9.6,0],[9.8,2.27]],"id":40324412},{"atb":[[1.31,241.94],[1.34,314.77]],"id":43066392},{"atl":[[2.42,14.08],[2.58,33.59],[2.76,0]],"id":43066392},{"atl":[[1.54,0],[1.65,184.62]],"id":42845264},{"atb":[[1.18,111.11],[1.09,0],[1.08,250]],"id":43154432},{"atb":[[2,0],[1.89,0],[2.3,15.38],[2.16,70.62]],"id":39586887}],"con":true,"img":false}]}
{"op":"mcm","clk":"5346818266","pt":1646097853442,"mc":[{"id":"1.195395454","rc":[{"atl":[[1.56,0]],"id":42845264}],"con":true,"img":false}]}
{"op":"mcm","clk":"5346818434","pt":1646097857960,"mc":[{"id":"1.195395454","rc":[{"atb":[[2.9,50.28],[3.35,0]],"id":37076607},{"atl":[[1.53,0]],"id":42845264}],"con":true,"img":false}]}
{"op":"mcm","clk":"5346818437","pt":1646097858011,"mc":[{"id":"1.195395454","rc":[{"atl":[[1.57,40.56]],"id":42845264}],"con":true,"img":false}]}
{"op":"mcm","clk":"5346818469","pt":1646097858732,"mc":[{"id":"1.195395454","rc":[{"atl":[[1.58,0]],"id":42845264}],"con":true,"img":false}]}
{"op":"mcm","clk":"5346818479","pt":1646097858935,"mc":[{"id":"1.195395454","rc":[{"atl":[[1.6,0]],"id":42845264}],"con":true,"img":false}]}
{"op":"mcm","clk":"5346818670","pt":1646097863268,"mc":[{"id":"1.195395454","rc":[{"atb":[[2.98,25.25]],"id":37076607},{"atb":[[1.88,56.82]],"id":42901530},{"atl":[[3.65,18.87]],"id":40612296},{"atl":[[10.5,9.35]],"id":40324412},{"atl":[[2.46,34.25]],"id":43066392},{"atl":[[1.67,74.63]],"id":42845264},{"atb":[[1.16,250]],"id":43154432},{"atb":[[2.26,39.68]],"id":39586887}],"con":true,"img":false}]}
{"op":"mcm","clk":"5346818785","pt":1646097866041,"mc":[{"id":"1.195395454","rc":[{"atb":[[1.59,0],[1.57,0],[1.61,0]],"id":42901530},{"atl":[[5.7,0]],"id":40612296},{"atl":[[10,0],[11,0],[12,0]],"id":40324412},{"atl":[[2.8,0],[2.88,0],[2.84,0]],"id":43066392},{"atb":[[1.03,0],[1.07,0],[1.05,0]],"id":43154432},{"atb":[[1.98,0],[1.96,0],[1.94,0]],"id":39586887}],"con":true,"img":false}]}
{"op":"mcm","clk":"5346818874","pt":1646097867940,"mc":[{"id":"1.195395454","rc":[{"atb":[[2.02,0]],"id":43154432}],"con":true,"img":false}]}
{"op":"mcm","clk":"5346818877","pt":1646097868042,"mc":[{"id":"1.195395454","rc":[{"atb":[[1.96,37.55]],"id":43154432}],"con":true,"img":false}]}
{"op":"mcm","clk":"5346819079","pt":1646097873281,"mc":[{"id":"1.195395454","rc":[{"atb":[[2.94,38.66]],"id":37076607},{"atb":[[1.86,87.21]],"id":42901530},{"atl":[[3.75,27.27]],"id":40612296},{"atl":[[11.5,7.14]],"id":40324412},{"atl":[[2.5,50]],"id":43066392},{"atl":[[1.69,108.7]],"id":42845264},{"atb":[[1.14,250]],"id":43154432},{"atb":[[2.22,61.48]],"id":39586887}],"con":true,"img":false}]}
{"op":"mcm","clk":"5346819231","pt":1646097877086,"mc":[{"id":"1.195395454","rc":[{"atl":[[5.5,0]],"id":40612296}],"con":true,"img":false}]}
{"op":"mcm","clk":"5346819495","pt":1646097883264,"mc":[{"id":"1.195395454","rc":[{"atb":[[2.9,116.07]],"id":37076607},{"atb":[[1.84,148.81]],"id":42901530},{"atl":[[3.85,60.08]],"id":40612296},{"atl":[[12.5,12.95]],"id":40324412},{"atl":[[2.54,88.96]],"id":43066392},{"atl":[[1.71,176.06]],"id":42845264},{"atb":[[1.12,250]],"id":43154432},{"atb":[[2.18,105.93]],"id":39586887}],"con":true,"img":false}]}
{"op":"mcm","clk":"5346819685","pt":1646097888004,"mc":[{"id":"1.195395454","rc":[{"atl":[[3.85,43.86]],"id":40612296},{"atl":[[10.5,5.26]],"id":40324412},{"atl":[[2.74,6.9]],"id":43066392}],"con":true,"img":false}]}
{"op":"mcm","clk":"5346819691","pt":1646097888061,"mc":[{"id":"1.195395454","rc":[{"atl":[[3.5,16.22]],"id":40612296},{"atl":[[12,4.09]],"id":40324412},{"atl":[[2.48,26.68]],"id":43066392}],"con":true,"img":false}]}
{"op":"mcm","clk":"5346819718","pt":1646097888673,"mc":[{"id":"1.195395454","rc":[{"atl":[[5.3,0]],"id":40612296}],"con":true,"img":false}]}
{"op":"mcm","clk":"5346819957","pt":1646097894512,"mc":[{"id":"1.195395454","rc":[{"atl":[[42,1],[44,0]],"id":37076607},{"atl":[[9.2,2.44]],"id":39586887}],"con":true,"img":false}]}
{"op":"mcm","clk":"5346819960","pt":1646097894615,"mc":[{"id":"1.195395454","rc":[{"atl":[[9.4,0]],"id":39586887}],"con":true,"img":false}]}
{"op":"mcm","clk":"5346820090","pt":1646097898007,"mc":[{"id":"1.195395454","rc":[{"atl":[[1.64,58.87],[1.98,0]],"id":42845264}],"con":true,"img":false}]}
{"op":"mcm","clk":"5346820445","pt":1646097906513,"mc":[{"id":"1.195395454","rc":[{"atb":[[1.34,119.37],[1.35,249.22]],"id":43066392},{"atl":[[9.2,0],[9.4,2.38]],"id":39586887}],"con":true,"img":false}]}
{"op":"mcm","clk":"5346820458","pt":1646097906719,"mc":[{"id":"1.195395454","rc":[{"atb":[[1.34,413.49],[1.35,97.7]],"id":43066392}],"con":true,"img":false}]}
{"op":"mcm","clk":"5346820520","pt":1646097908008,"mc":[{"id":"1.195395454","rc":[{"atb":[[2.9,97.38]],"id":37076607},{"atl":[[1.57,0]],"id":42845264}],"con":true,"img":false}]}
{"op":"mcm","clk":"5346820525","pt":1646097908111,"mc":[{"id":"1.195395454","rc":[{"atb":[[2.96,18.69]],"id":37076607},{"atl":[[1.62,40.56]],"id":42845264}],"con":true,"img":false}]}
{"op":"mcm","clk":"5346820564","pt":1646097908931,"mc":[{"id":"1.195395454","rc":[{"atl":[[9.2,2.44],[9.4,0]],"id":39586887}],"con":true,"img":false}]}
{"op":"mcm","clk":"5346820982","pt":1646097919255,"mc":[{"id":"1.195395454","rc":[{"atl":[[9.2,0],[9.4,2.38]],"id":39586887}],"con":true,"img":false}]}
{"op":"mcm","clk":"5346821000","pt":1646097919818,"mc":[{"id":"1.195395454","rc":[{"atl":[[5,0],[3.8,14.06]],"id":40612296}],"con":true,"img":false}]}
{"op":"mcm","clk":"5346821172","pt":1646097924039,"mc":[{"id":"1.195395454","rc":[{"atl":[[9.2,2.44],[9.4,0]],"id":39586887}],"con":true,"img":false}]}
{"op":"mcm","clk":"5346821338","pt":1646097927947,"mc":[{"id":"1.195395454","rc":[{"atl":[[12,0]],"id":40324412}],"con":true,"img":false}]}
{"op":"mcm","clk":"5346821341","pt":1646097928049,"mc":[{"id":"1.195395454","rc":[{"atl":[[11,4.09]],"id":40324412}],"con":true,"img":false}]}
{"op":"mcm","clk":"5346821877","pt":1646097943548,"mc":[{"id":"1.195395454","rc":[{"atl":[[42,0],[44,1]],"id":37076607},{"atb":[[1.38,253.39]],"id":40612296},{"atb":[[1.36,151.52],[1.34,119.37]],"id":43066392},{"atl":[[2.74,64.37],[2.58,0]],"id":43066392},{"atl":[[9.2,0],[9.4,2.38]],"id":39586887}],"con":true,"img":false}]}
{"op":"mcm","clk":"5346821882","pt":1646097943653,"mc":[{"id":"1.195395454","rc":[{"atb":[[1.44,0]],"id":40612296}],"con":true,"img":false}]}
{"op":"mcm","clk":"5346822073","pt":1646097948073,"mc":[{"id":"1.195395454","rc":[{"atl":[[11,0]],"id":40324412}],"con":true,"img":false}]}
{"op":"mcm","clk":"5346822080","pt":1646097948174,"mc":[{"id":"1.195395454","rc":[{"atl":[[12,4.09]],"id":40324412}],"con":true,"img":false}]}
{"op":"mcm","clk":"5346822338","pt":1646097955104,"mc":[{"id":"1.195395454","rc":[{"atl":[[44,0],[46,1]],"id":37076607}],"con":true,"img":false}]}
{"op":"mcm","clk":"5346822448","pt":1646097957878,"mc":[{"id":"1.195395454","rc":[{"atl":[[44,1],[46,0]],"id":37076607}],"con":true,"img":false}]}
{"op":"mcm","clk":"5346822459","pt":1646097958084,"mc":[{"id":"1.195395454","rc":[{"atl":[[2.48,0]],"id":43066392}],"con":true,"img":false}]}
{"op":"mcm","clk":"5346822466","pt":1646097958186,"mc":[{"id":"1.195395454","rc":[{"atl":[[2.44,26.68]],"id":43066392}],"con":true,"img":false}]}
{"op":"mcm","clk":"5346822789","pt":1646097967332,"mc":[{"id":"1.195395454","rc":[{"atl":[[44,0],[46,1]],"id":37076607}],"con":true,"img":false}]}
{"op":"mcm","clk":"5346822820","pt":1646097968102,"mc":[{"id":"1.195395454","rc":[{"atb":[[1.35,57.13]],"id":43066392},{"atb":[[1.96,0]],"id":43154432}],"con":true,"img":false}]}
{"op":"mcm","clk":"5346822825","pt":1646097968216,"mc":[{"id":"1.195395454","rc":[{"atb":[[1.37,40.56],[1.35,342.84]],"id":43066392},{"atb":[[2.02,37.55]],"id":43154432}],"con":true,"img":false}]}
{"op":"mcm","clk":"5346822831","pt":1646097968307,"mc":[{"id":"1.195395454","rc":[{"atb":[[1.36,0]],"id":43066392}],"con":true,"img":false}]}
{"op":"mcm","clk":"5346822881","pt":1646097969228,"mc":[{"id":"1.195395454","rc":[{"atl":[[44,1],[46,0]],"id":37076607}],"con":true,"img":false}]}
{"op":"mcm","clk":"5346823199","pt":1646097978107,"mc":[{"id":"1.195395454","rc":[{"atb":[[1.37,0]],"id":43066392}],"con":true,"img":false}]}
{"op":"mcm","clk":"5346823201","pt":1646097978209,"mc":[{"id":"1.195395454","rc":[{"atb":[[1.36,40.56]],"id":43066392}],"con":true,"img":false}]}
{"op":"mcm","clk":"5346823241","pt":1646097979799,"mc":[{"id":"1.195395454","rc":[{"atl":[[44,0],[46,1]],"id":37076607}],"con":true,"img":false}]}
{"op":"mcm","clk":"5346823286","pt":1646097980621,"mc":[{"id":"1.195395454","rc":[{"atb":[[1.37,119.37],[1.35,57.13]],"id":43066392}],"con":true,"img":false}]}
{"op":"mcm","clk":"5346823451","pt":1646097986122,"mc":[{"id":"1.195395454","rc":[{"atl":[[44,1]],"id":37076607}],"con":true,"img":false}]}
{"op":"mcm","clk":"5346823452","pt":1646097986226,"mc":[{"id":"1.195395454","rc":[{"atl":[[46,0]],"id":37076607}],"con":true,"img":false}]}
{"op":"mcm","clk":"5346823655","pt":1646097991659,"mc":[{"id":"1.195395454","rc":[{"atl":[[44,0],[46,1]],"id":37076607}],"con":true,"img":false}]}
{"op":"mcm","clk":"5346823891","pt":1646097998735,"mc":[{"id":"1.195395454","rc":[{"atl":[[44,1]],"id":37076607}],"con":true,"img":false}]}
{"op":"mcm","clk":"5346823894","pt":1646097998837,"mc":[{"id":"1.195395454","rc":[{"atl":[[46,0]],"id":37076607}],"con":true,"img":false}]}
{"op":"mcm","clk":"5346824046","pt":1646098003055,"mc":[{"id":"1.195395454","rc":[{"atl":[[44,0],[46,1]],"id":37076607}],"con":true,"img":false}]}
{"op":"mcm","clk":"5346824223","pt":1646098008033,"mc":[{"id":"1.195395454","rc":[{"atb":[[1.36,0]],"id":43066392}],"con":true,"img":false}]}
{"op":"mcm","clk":"5346824226","pt":1646098008135,"mc":[{"id":"1.195395454","rc":[{"atb":[[1.37,0],[1.35,295.87],[1.38,40.56]],"id":43066392}],"con":true,"img":false}]}
{"op":"mcm","clk":"5346824232","pt":1646098008239,"mc":[{"id":"1.195395454","rc":[{"atb":[[1.37,151.52],[1.35,57.13]],"id":43066392}],"con":true,"img":false}]}
{"op":"mcm","clk":"5346824322","pt":1646098010340,"mc":[{"id":"1.195395454","rc":[{"atl":[[44,1],[46,0]],"id":37076607}],"con":true,"img":false}]}
{"op":"mcm","clk":"5346824466","pt":1646098014759,"mc":[{"id":"1.195395454","rc":[{"atl":[[44,0],[46,1]],"id":37076607}],"con":true,"img":false}]}
{"op":"mcm","clk":"5346824641","pt":1646098021279,"mc":[{"id":"1.195395454","rc":[{"atl":[[44,1],[46,0]],"id":37076607}],"con":true,"img":false}]}
{"op":"mcm","clk":"5346824680","pt":1646098022565,"mc":[{"id":"1.195395454","rc":[{"atb":[[1.57,54.22]],"id":40612296},{"atb":[[2.48,20.88]],"id":40324412},{"atb":[[1.39,79.24]],"id":43066392},{"atb":[[1.96,32.19]],"id":43154432},{"atb":[[2.64,18.84]],"id":39586887}],"con":true,"img":false}]}
{"op":"mcm","clk":"5346824812","pt":1646098026366,"mc":[{"id":"1.195395454","rc":[{"atl":[[44,0],[46,1]],"id":37076607}],"con":true,"img":false}]}
{"op":"mcm","clk":"5346824844","pt":1646098027798,"mc":[{"id":"1.195395454","rc":[{"atl":[[44,1],[46,0]],"id":37076607}],"con":true,"img":false}]}
{"op":"mcm","clk":"5346825164","pt":1646098038112,"mc":[{"id":"1.195395454","rc":[{"atl":[[2.44,0]],"id":43066392}],"con":true,"img":false}]}
{"op":"mcm","clk":"5346825167","pt":1646098038216,"mc":[{"id":"1.195395454","rc":[{"atl":[[2.48,26.68]],"id":43066392}],"con":true,"img":false}]}
{"op":"mcm","clk":"5346825516","pt":1646098048002,"mc":[{"id":"1.195395454","rc":[{"atb":[[1.38,0]],"id":43066392}],"con":true,"img":false}]}
{"op":"mcm","clk":"5346825522","pt":1646098048105,"mc":[{"id":"1.195395454","rc":[{"atb":[[1.4,40.56]],"id":43066392}],"con":true,"img":false}]}
{"op":"mcm","clk":"5346825544","pt":1646098048718,"mc":[{"id":"1.195395454","marketDefinition":{"bspMarket":false,"turnInPlayEnabled":false,"persistenceEnabled":false,"marketBaseRate":5.0,"eventId":"31270459","eventTypeId":"4339","numberOfWinners":3,"bettingType":"ODDS","marketType":"PLACE","marketTime":"2022-03-01T01:45:00.000Z","suspendTime":"2022-03-01T01:45:00.000Z","bspReconciled":false,"complete":true,"inPlay":false,"crossMatching":true,"runnersVoidable":false,"numberOfActiveRunners":8,"betDelay":0,"status":"OPEN","runners":[{"status":"ACTIVE","sortPriority":1,"id":39586887,"name":"1. Homebush Bun"},{"status":"ACTIVE","sortPriority":2,"id":42901530,"name":"2. Wild Thyme"},{"status":"ACTIVE","sortPriority":3,"id":40612296,"name":"3. Opawa Duchess"},{"status":"ACTIVE","sortPriority":4,"id":37076607,"name":"4. Opawa Ruby"},{"status":"ACTIVE","sortPriority":5,"id":42845264,"name":"5. Opawa Dragon"},{"status":"ACTIVE","sortPriority":6,"id":43154432,"name":"6. Iced Mocha"},{"status":"ACTIVE","sortPriority":7,"id":43066392,"name":"7. Go Hazel"},{"status":"ACTIVE","sortPriority":8,"id":40324412,"name":"8. Goldstar Charm"}],"regulators":["MR_INT"],"venue":"Addington","countryCode":"NZ","discountAllowed":true,"timezone":"NZ","openDate":"2022-02-28T23:02:00.000Z","version":4380660681,"name":"To Be Placed","eventName":"Addington (NZL) 1st Mar"},"rc":[],"con":true,"img":false}]}
{"op":"mcm","clk":"5346825621","pt":1646098050107,"mc":[{"id":"1.195395454","rc":[{"atb":[[1.39,0]],"id":43066392}],"con":true,"img":false}]}
{"op":"mcm","clk":"5346825658","pt":1646098051131,"mc":[{"id":"1.195395454","rc":[{"atl":[[44,0],[46,1]],"id":37076607}],"con":true,"img":false}]}
{"op":"mcm","clk":"5346825764","pt":1646098053804,"mc":[{"id":"1.195395454","rc":[{"atb":[[1.38,81.33]],"id":43066392}],"con":true,"img":false}]}
{"op":"mcm","clk":"5346825856","pt":1646098056420,"mc":[{"id":"1.195395454","rc":[{"atl":[[44,1],[46,0]],"id":37076607}],"con":true,"img":false}]}
{"op":"mcm","clk":"5346825933","pt":1646098058017,"mc":[{"id":"1.195395454","rc":[{"atb":[[1.4,0]],"id":43066392},{"atb":[[2.62,0]],"id":39586887}],"con":true,"img":false}]}
{"op":"mcm","clk":"5346825937","pt":1646098058116,"mc":[{"id":"1.195395454","rc":[{"atb":[[1.39,40.56]],"id":43066392},{"atb":[[2.66,22.25]],"id":39586887}],"con":true,"img":false}]}
{"op":"mcm","clk":"5346826068","pt":1646098061247,"mc":[{"id":"1.195395454","rc":[{"atb":[[2.64,0]],"id":39586887}],"con":true,"img":false}]}
{"op":"mcm","clk":"5346826126","pt":1646098062640,"mc":[{"id":"1.195395454","rc":[{"atl":[[44,0],[46,1]],"id":37076607}],"con":true,"img":false}]}
{"op":"mcm","clk":"5346826219","pt":1646098064953,"mc":[{"id":"1.195395454","rc":[{"atb":[[2.72,17.96]],"id":39586887}],"con":true,"img":false}]}
{"op":"mcm","clk":"5346826369","pt":1646098068655,"mc":[{"id":"1.195395454","rc":[{"atl":[[44,1]],"id":37076607}],"con":true,"img":false}]}
{"op":"mcm","clk":"5346826375","pt":1646098068757,"mc":[{"id":"1.195395454","rc":[{"atl":[[46,0]],"id":37076607}],"con":true,"img":false}]}
{"op":"mcm","clk":"5346826645","pt":1646098074728,"mc":[{"id":"1.195395454","rc":[{"atl":[[46,1]],"id":37076607}],"con":true,"img":false}]}
{"op":"mcm","clk":"5346826648","pt":1646098074831,"mc":[{"id":"1.195395454","rc":[{"atl":[[44,0]],"id":37076607}],"con":true,"img":false}]}
{"op":"mcm","clk":"5346826924","pt":1646098081659,"mc":[{"id":"1.195395454","rc":[{"atl":[[44,1],[46,0]],"id":37076607}],"con":true,"img":false}]}
{"op":"mcm","clk":"5346827132","pt":1646098086746,"mc":[{"id":"1.195395454","rc":[{"atl":[[44,0],[46,1]],"id":37076607}],"con":true,"img":false}]}
{"op":"mcm","clk":"5346827173","pt":1646098087470,"mc":[{"id":"1.195395454","rc":[{"atl":[[44,1],[46,0]],"id":37076607}],"con":true,"img":false}]}
{"op":"mcm","clk":"5346827207","pt":1646098088081,"mc":[{"id":"1.195395454","rc":[{"atl":[[1.64,0]],"id":42845264}],"con":true,"img":false}]}
{"op":"mcm","clk":"5346827212","pt":1646098088185,"mc":[{"id":"1.195395454","rc":[{"atl":[[1.66,58.87]],"id":42845264}],"con":true,"img":false}]}
{"op":"mcm","clk":"5346827668","pt":1646098098071,"mc":[{"id":"1.195395454","rc":[{"atb":[[2.66,0]],"id":39586887}],"con":true,"img":false}]}
{"op":"mcm","clk":"5346827672","pt":1646098098174,"mc":[{"id":"1.195395454","rc":[{"atb":[[2.72,40.22]],"id":39586887}],"con":true,"img":false}]}
{"op":"mcm","clk":"5346828121","pt":1646098107976,"mc":[{"id":"1.195395454","rc":[{"atb":[[1.39,0]],"id":43066392}],"con":true,"img":false}]}
{"op":"mcm","clk":"5346828126","pt":1646098108078,"mc":[{"id":"1.195395454","rc":[{"atb":[[1.38,121.89]],"id":43066392}],"con":true,"img":false}]}
{"op":"mcm","clk":"5346828614","pt":1646098122710,"mc":[{"id":"1.195395454","rc":[{"atl":[[44,0],[46,1]],"id":37076607}],"con":true,"img":false}]}
{"op":"mcm","clk":"5346828797","pt":1646098129022,"mc":[{"id":"1.195395454","rc":[{"atl":[[44,1]],"id":37076607}],"con":true,"img":false}]}
{"op":"mcm","clk":"5346828804","pt":1646098129125,"mc":[{"id":"1.195395454","rc":[{"atl":[[46,0]],"id":37076607}],"con":true,"img":false}]}
{"op":"mcm","clk":"5346828975","pt":1646098135328,"mc":[{"id":"1.195395454","rc":[{"atl":[[44,0],[46,1]],"id":37076607}],"con":true,"img":false}]}
{"op":"mcm","clk":"5346829127","pt":1646098140163,"mc":[{"id":"1.195395454","rc":[{"atl":[[44,1],[46,0]],"id":37076607},{"atl":[[3.85,7.02],[3.55,21.87],[3.65,0],[3.75,0]],"id":40612296},{"atl":[[2.54,7.79],[2.5,0],[2.42,0],[2.46,0],[2.64,12.2]],"id":43066392}],"con":true,"img":false}]}
{"op":"mcm","clk":"5346829140","pt":1646098140419,"mc":[{"id":"1.195395454","rc":[{"atl":[[2.64,0]],"id":43066392}],"con":true,"img":false}]}
{"op":"mcm","clk":"5346829147","pt":1646098140628,"mc":[{"id":"1.195395454","rc":[{"atl":[[2.72,43.6],[2.64,12.2],[2.68,29.76],[2.76,71.02]],"id":43066392}],"con":true,"img":false}]}
{"op":"mcm","clk":"5346829386","pt":1646098147658,"mc":[{"id":"1.195395454","rc":[{"atl":[[46,1]],"id":37076607}],"con":true,"img":false}]}
{"op":"mcm","clk":"5346829389","pt":1646098147760,"mc":[{"id":"1.195395454","rc":[{"atl":[[44,0]],"id":37076607},{"atl":[[2.64,0]],"id":43066392}],"con":true,"img":false}]}
{"op":"mcm","clk":"5346829396","pt":1646098147965,"mc":[{"id":"1.195395454","rc":[{"atl":[[3.8,0],[3.5,0],[5.4,8.95]],"id":40612296},{"atl":[[2.48,0]],"id":43066392}],"con":true,"img":false}]}
{"op":"mcm","clk":"5346829400","pt":1646098148068,"mc":[{"id":"1.195395454","rc":[{"atl":[[3.8,16.22]],"id":40612296},{"atl":[[2.66,26.68]],"id":43066392}],"con":true,"img":false}]}
{"op":"mcm","clk":"5346829488","pt":1646098150685,"mc":[{"id":"1.195395454","rc":[{"atl":[[2.64,12.2]],"id":43066392}],"con":true,"img":false}]}
{"op":"mcm","clk":"5346829507","pt":1646098151149,"mc":[{"id":"1.195395454","rc":[{"atl":[[44,1],[46,0]],"id":37076607}],"con":true,"img":false}]}
{"op":"mcm","clk":"5346829518","pt":1646098151458,"mc":[{"id":"1.195395454","rc":[{"atl":[[2.64,0]],"id":43066392}],"con":true,"img":false}]}
{"op":"mcm","clk":"5346829565","pt":1646098152950,"mc":[{"id":"1.195395454","rc":[{"atl":[[2.64,12.2]],"id":43066392}],"con":true,"img":false}]}
{"op":"mcm","clk":"5346829784","pt":1646098160189,"mc":[{"id":"1.195395454","rc":[{"atl":[[3.95,16.95]],"id":40612296}],"con":true,"img":false}]}
{"op":"mcm","clk":"5346829788","pt":1646098160396,"mc":[{"id":"1.195395454","rc":[{"atl":[[46,1]],"id":37076607}],"con":true,"img":false}]}
{"op":"mcm","clk":"5346829792","pt":1646098160499,"mc":[{"id":"1.195395454","rc":[{"atl":[[44,0]],"id":37076607},{"atl":[[2.64,0]],"id":43066392}],"con":true,"img":false}]}
{"op":"mcm","clk":"5346829818","pt":1646098161167,"mc":[{"id":"1.195395454","rc":[{"atl":[[44,1],[46,0]],"id":37076607},{"atl":[[2.64,12.2]],"id":43066392}],"con":true,"img":false}]}
{"op":"mcm","clk":"5346829924","pt":1646098164706,"mc":[{"id":"1.195395454","rc":[{"atl":[[2.64,0]],"id":43066392}],"con":true,"img":false}]}
{"op":"mcm","clk":"5346830078","pt":1646098170191,"mc":[{"id":"1.195395454","rc":[{"atl":[[4.1,31.93]],"id":40612296}],"con":true,"img":false}]}
{"op":"mcm","clk":"5346830111","pt":1646098171214,"mc":[{"id":"1.195395454","rc":[{"atl":[[2.64,12.2]],"id":43066392}],"con":true,"img":false}]}
{"op":"mcm","clk":"5346830149","pt":1646098172601,"mc":[{"id":"1.195395454","rc":[{"atl":[[46,1]],"id":37076607}],"con":true,"img":false}]}
{"op":"mcm","clk":"5346830154","pt":1646098172703,"mc":[{"id":"1.195395454","rc":[{"atl":[[44,0]],"id":37076607},{"atl":[[2.64,0]],"id":43066392}],"con":true,"img":false}]}
{"op":"mcm","clk":"5346830242","pt":1646098176411,"mc":[{"id":"1.195395454","rc":[{"atl":[[44,1],[46,0]],"id":37076607},{"atl":[[2.64,12.2]],"id":43066392}],"con":true,"img":false}]}
{"op":"mcm","clk":"5346830296","pt":1646098178006,"mc":[{"id":"1.195395454","rc":[{"atl":[[12,0]],"id":40324412}],"con":true,"img":false}]}
{"op":"mcm","clk":"5346830301","pt":1646098178108,"mc":[{"id":"1.195395454","rc":[{"atl":[[11,4.09]],"id":40324412}],"con":true,"img":false}]}
{"op":"mcm","clk":"5346830322","pt":1646098178726,"mc":[{"id":"1.195395454","rc":[{"atl":[[44,0],[46,1]],"id":37076607},{"atb":[[2.2,50.02],[2.26,79.37]],"id":40324412},{"atl":[[2.64,0]],"id":43066392},{"atl":[[9.6,2.33],[9.4,0]],"id":39586887}],"con":true,"img":false}]}
{"op":"mcm","clk":"5346830363","pt":1646098180217,"mc":[{"id":"1.195395454","rc":[{"atl":[[4.3,37.88]],"id":40612296}],"con":true,"img":false}]}
{"op":"mcm","clk":"5346830472","pt":1646098184438,"mc":[{"id":"1.195395454","rc":[{"atl":[[2.64,12.2]],"id":43066392}],"con":true,"img":false}]}
{"op":"mcm","clk":"5346830541","pt":1646098186799,"mc":[{"id":"1.195395454","rc":[{"atl":[[2.64,0]],"id":43066392}],"con":true,"img":false}]}
{"op":"mcm","clk":"5346830612","pt":1646098188701,"mc":[{"id":"1.195395454","rc":[{"atl":[[50,1.02]],"id":37076607},{"atl":[[2.64,12.2]],"id":43066392},{"atl":[[10,5.56]],"id":39586887}],"con":true,"img":false}]}
{"op":"mcm","clk":"5346830749","pt":1646098193740,"mc":[{"id":"1.195395454","rc":[{"atl":[[48,0],[55,0],[65,0]],"id":37076607},{"atl":[[2.64,0]],"id":43066392},{"atl":[[10.5,0],[11.5,2.28],[9.8,0]],"id":39586887}],"con":true,"img":false}]}
{"op":"mcm","clk":"5346830822","pt":1646098196830,"mc":[{"id":"1.195395454","rc":[{"atl":[[2.64,12.2]],"id":43066392}],"con":true,"img":false}]}
{"op":"mcm","clk":"5346830865","pt":1646098198733,"mc":[{"id":"1.195395454","rc":[{"atl":[[60,1.27]],"id":37076607},{"atl":[[11,12.32]],"id":39586887}],"con":true,"img":false}]}
{"op":"mcm","clk":"5346830914","pt":1646098200431,"mc":[{"id":"1.195395454","rc":[{"atl":[[2.64,0]],"id":43066392}],"con":true,"img":false}]}
{"op":"mcm","clk":"5346830939","pt":1646098201152,"mc":[{"id":"1.195395454","rc":[{"atl":[[2.64,12.2]],"id":43066392}],"con":true,"img":false}]}
{"op":"mcm","clk":"5346831112","pt":1646098205335,"mc":[{"id":"1.195395454","rc":[{"atl":[[2.64,0]],"id":43066392}],"con":true,"img":false}]}
{"op":"mcm","clk":"5346831180","pt":1646098207955,"mc":[{"id":"1.195395454","rc":[{"atl":[[3.9,13.58],[5.4,0]],"id":40612296}],"con":true,"img":false}]}
{"op":"mcm","clk":"5346831210","pt":1646098208777,"mc":[{"id":"1.195395454","rc":[{"atl":[[12,11.36]],"id":39586887}],"con":true,"img":false}]}
{"op":"mcm","clk":"5346831221","pt":1646098209035,"mc":[{"id":"1.195395454","rc":[{"atl":[[70,1.81]],"id":37076607}],"con":true,"img":false}]}
{"op":"mcm","clk":"5346831229","pt":1646098209292,"mc":[{"id":"1.195395454","rc":[{"atb":[[2.88,0],[3.4,31.2],[3.5,8],[3.05,0]],"id":37076607},{"atb":[[2.4,14.29],[2.24,63.2],[1.8,0],[1.9,0]],"id":42901530},{"atl":[[4,31.94],[4.3,0],[3.85,0],[3.95,0],[4.1,7.74],[3.55,9.41],[4.4,5.88]],"id":40612296},{"atl":[[9.8,0],[8.8,0],[7,10.67]],"id":40324412},{"atb":[[1.37,0],[1.34,363.17]],"id":43066392},{"atl":[[2.72,0],[3.85,51.94],[2.74,6.9],[2.68,0],[4.2,6.25],[2.76,0]],"id":43066392},{"atb":[[1.02,2174.56]],"id":42845264},{"atl":[[1.65,30.77]],"id":42845264},{"atb":[[1.18,0],[1.08,0],[1.74,120.08],[2.16,17.24]],"id":43154432},{"atb":[[2.3,0],[2.6,137.54],[2.78,11.24],[2.16,0]],"id":39586887}],"con":true,"img":false}]}
{"op":"mcm","clk":"5346831238","pt":1646098209548,"mc":[{"id":"1.195395454","rc":[{"atl":[[4.2,0]],"id":43066392}],"con":true,"img":false}]}
{"op":"mcm","clk":"5346831290","pt":1646098211344,"mc":[{"id":"1.195395454","rc":[{"atl":[[4.8,32.89],[4.6,20.83],[4.4,14.71],[4.2,6.25]],"id":43066392}],"con":true,"img":false}]}
{"op":"mcm","clk":"5346831311","pt":1646098212166,"mc":[{"id":"1.195395454","rc":[{"atb":[[1.38,40.56]],"id":43066392},{"atb":[[1.96,0]],"id":43154432},{"atb":[[2.72,22.25]],"id":39586887}],"con":true,"img":false}]}
{"op":"mcm","clk":"5346831351","pt":1646098213658,"mc":[{"id":"1.195395454","rc":[{"atl":[[4.2,0]],"id":43066392},{"atb":[[2.14,17.54]],"id":43154432}],"con":true,"img":false}]}
{"op":"mcm","clk":"5346831355","pt":1646098213759,"mc":[{"id":"1.195395454","rc":[{"atb":[[2.16,0]],"id":43154432}],"con":true,"img":false}]}
{"op":"mcm","clk":"5346831425","pt":1646098216074,"mc":[{"id":"1.195395454","rc":[{"atb":[[1.39,79.24]],"id":43066392},{"atb":[[2.04,29.71]],"id":43154432},{"atb":[[2.74,17.76]],"id":39586887}],"con":true,"img":false}]}
{"op":"mcm","clk":"5346831456","pt":1646098217253,"mc":[{"id":"1.195395454","rc":[{"atl":[[4.2,6.25]],"id":43066392},{"atb":[[2.16,17.24]],"id":43154432}],"con":true,"img":false}]}
{"op":"mcm","clk":"5346831460","pt":1646098217354,"mc":[{"id":"1.195395454","rc":[{"atb":[[2.14,0]],"id":43154432}],"con":true,"img":false}]}
{"op":"mcm","clk":"5346831482","pt":1646098218071,"mc":[{"id":"1.195395454","rc":[{"atl":[[3.9,0]],"id":40612296},{"atl":[[2.66,0]],"id":43066392}],"con":true,"img":false}]}
{"op":"mcm","clk":"5346831484","pt":1646098218175,"mc":[{"id":"1.195395454","rc":[{"atl":[[3.95,13.58]],"id":40612296},{"atl":[[2.98,26.68]],"id":43066392}],"con":true,"img":false}]}
{"op":"mcm","clk":"5346831518","pt":1646098219254,"mc":[{"id":"1.195395454","rc":[{"atb":[[3.4,52.03]],"id":37076607},{"atb":[[2.36,36.76]],"id":42901530},{"atl":[[4.6,13.89]],"id":40612296},{"atl":[[7.4,7.81]],"id":40324412},{"atb":[[2.74,46.5]],"id":39586887}],"con":true,"img":false}]}
{"op":"mcm","clk":"5346831579","pt":1646098221459,"mc":[{"id":"1.195395454","rc":[{"atb":[[1.39,0]],"id":43066392}],"con":true,"img":false}]}
{"op":"mcm","clk":"5346831600","pt":1646098222394,"mc":[{"id":"1.195395454","rc":[{"atb":[[2.9,31.59],[2.98,0],[2.94,0]],"id":37076607},{"atb":[[1.84,0]],"id":42901530},{"atl":[[12.5,2.08]],"id":40324412},{"atl":[[4.2,0]],"id":43066392},{"atb":[[2.16,0],[2.14,17.54]],"id":43154432},{"atb":[[2.18,0]],"id":39586887}],"con":true,"img":false}]}
{"op":"mcm","clk":"5346831712","pt":1646098225378,"mc":[{"id":"1.195395454","rc":[{"atb":[[1.39,79.24]],"id":43066392}],"con":true,"img":false}]}
{"op":"mcm","clk":"5346831725","pt":1646098225789,"mc":[{"id":"1.195395454","rc":[{"atl":[[4.2,6.25]],"id":43066392},{"atb":[[2.14,0],[2.16,17.24]],"id":43154432}],"con":true,"img":false}]}
{"op":"mcm","clk":"5346831784","pt":1646098227997,"mc":[{"id":"1.195395454","rc":[{"atb":[[2.22,0],[2.28,30.42]],"id":40324412}],"con":true,"img":false}]}
{"op":"mcm","clk":"5346831826","pt":1646098229277,"mc":[{"id":"1.195395454","rc":[{"atb":[[3.3,32.61]],"id":37076607},{"atb":[[2.32,56.82]],"id":42901530},{"atl":[[4.8,19.74]],"id":40612296},{"atl":[[7.8,11.03]],"id":40324412},{"atb":[[2.7,79.43]],"id":39586887}],"con":true,"img":false}]}
{"op":"mcm","clk":"5346831954","pt":1646098233798,"mc":[{"id":"1.195395454","rc":[{"atb":[[1.86,0]],"id":42901530},{"atl":[[11.5,0]],"id":40324412},{"atl":[[4.2,0]],"id":43066392},{"atb":[[2.22,0]],"id":39586887}],"con":true,"img":false}]}
{"op":"mcm","clk":"5346832014","pt":1646098235699,"mc":[{"id":"1.195395454","rc":[{"atl":[[4.2,6.25]],"id":43066392}],"con":true,"img":false}]}
{"op":"mcm","clk":"5346832019","pt":1646098235801,"mc":[{"id":"1.195395454","rc":[{"atb":[[2.12,44.64]],"id":43154432}],"con":true,"img":false}]}
{"op":"mcm","clk":"5346832068","pt":1646098237999,"mc":[{"id":"1.195395454","rc":[{"atb":[[1.56,35.71]],"id":40612296},{"atb":[[2.4,0]],"id":40324412},{"atl":[[9,3]],"id":40324412},{"atb":[[1.38,0]],"id":43066392}],"con":true,"img":false}]}
{"op":"mcm","clk":"5346832074","pt":1646098238101,"mc":[{"id":"1.195395454","rc":[{"atb":[[1.58,40.56]],"id":40612296},{"atb":[[2.44,31.2]],"id":40324412},{"atl":[[8.2,5.07]],"id":40324412},{"atb":[[1.4,40.56]],"id":43066392}],"con":true,"img":false}]}
{"op":"mcm","clk":"5346832078","pt":1646098238305,"mc":[{"id":"1.195395454","rc":[{"atb":[[2.04,0]],"id":43154432}],"con":true,"img":false}]}
{"op":"mcm","clk":"5346832093","pt":1646098238821,"mc":[{"id":"1.195395454","rc":[{"atl":[[4.2,0]],"id":43066392},{"atb":[[2.16,0],[2.14,17.54]],"id":43154432}],"con":true,"img":false}]}
{"op":"mcm","clk":"5346832098","pt":1646098238922,"mc":[{"id":"1.195395454","rc":[{"atb":[[1.12,0]],"id":43154432}],"con":true,"img":false}]}
{"op":"mcm","clk":"5346832109","pt":1646098239328,"mc":[{"id":"1.195395454","rc":[{"atb":[[3.2,56.82]],"id":37076607},{"atb":[[2.28,97.66]],"id":42901530},{"atl":[[5,31.25]],"id":40612296},{"atl":[[8.2,22.43]],"id":40324412},{"atb":[[2.66,75.3]],"id":39586887}],"con":true,"img":false}]}
{"op":"mcm","clk":"5346832130","pt":1646098240100,"mc":[{"id":"1.195395454","rc":[{"atb":[[1.57,0]],"id":40612296},{"atb":[[1.39,0]],"id":43066392}],"con":true,"img":false}]}
{"op":"mcm","clk":"5346832170","pt":1646098241430,"mc":[{"id":"1.195395454","rc":[{"atb":[[1.88,0]],"id":42901530},{"atl":[[10.5,0]],"id":40324412},{"atl":[[4.2,6.25]],"id":43066392},{"atb":[[2.14,0],[2.16,17.24]],"id":43154432},{"atb":[[2.26,0]],"id":39586887}],"con":true,"img":false}]}
{"op":"mcm","clk":"5346832185","pt":1646098241998,"mc":[{"id":"1.195395454","rc":[{"atb":[[2.04,29.71]],"id":43154432}],"con":true,"img":false}]}
{"op":"mcm","clk":"5346832244","pt":1646098244095,"mc":[{"id":"1.195395454","rc":[{"atb":[[1.59,52.38]],"id":40612296},{"atb":[[1.36,85.84]],"id":43066392}],"con":true,"img":false}]}
{"op":"mcm","clk":"5346832331","pt":1646098246718,"mc":[{"id":"1.195395454","rc":[{"atl":[[4.2,0]],"id":43066392},{"atb":[[2.16,0],[2.14,17.54]],"id":43154432}],"con":true,"img":false}]}
{"op":"mcm","clk":"5346832386","pt":1646098248103,"mc":[{"id":"1.195395454","rc":[{"atb":[[2.82,0]],"id":42901530},{"atb":[[1.4,0]],"id":43066392}],"con":true,"img":false}]}
{"op":"mcm","clk":"5346832391","pt":1646098248205,"mc":[{"id":"1.195395454","rc":[{"atb":[[2.92,17.25]],"id":42901530},{"atb":[[1.37,40.56]],"id":43066392}],"con":true,"img":false}]}
{"op":"mcm","clk":"5346832434","pt":1646098249747,"mc":[{"id":"1.195395454","rc":[{"atl":[[4.2,6.25]],"id":43066392},{"atb":[[2.04,0],[2.14,0],[2.16,17.24]],"id":43154432}],"con":true,"img":false}]}
{"op":"mcm","clk":"5346832541","pt":1646098253441,"mc":[{"id":"1.195395454","rc":[{"atb":[[2.04,29.71]],"id":43154432}],"con":true,"img":false}]}
{"op":"mcm","clk":"5346832562","pt":1646098254110,"mc":[{"id":"1.195395454","rc":[{"atl":[[4.2,0]],"id":43066392},{"atb":[[2.14,17.54]],"id":43154432}],"con":true,"img":false}]}
{"op":"mcm","clk":"5346832564","pt":1646098254210,"mc":[{"id":"1.195395454","rc":[{"atb":[[2.16,0]],"id":43154432}],"con":true,"img":false}]}
{"op":"mcm","clk":"5346832640","pt":1646098257751,"mc":[{"id":"1.195395454","rc":[{"atl":[[4.2,6.25]],"id":43066392},{"atb":[[2.14,0],[2.16,17.24]],"id":43154432}],"con":true,"img":false}]}
{"op":"mcm","clk":"5346832647","pt":1646098257952,"mc":[{"id":"1.195395454","rc":[{"atb":[[3.45,14.49]],"id":37076607},{"atb":[[1.75,53.72]],"id":43154432},{"atl":[[11.5,5.72]],"id":39586887}],"con":true,"img":false}]}
{"op":"mcm","clk":"5346832649","pt":1646098258054,"mc":[{"id":"1.195395454","rc":[{"atb":[[2.96,0]],"id":37076607},{"atb":[[1.58,0]],"id":40612296},{"atb":[[1.54,0]],"id":43154432},{"atb":[[2.72,0]],"id":39586887},{"atl":[[14.5,0]],"id":39586887}],"con":true,"img":false}]}
{"op":"mcm","clk":"5346832652","pt":1646098258157,"mc":[{"id":"1.195395454","rc":[{"atb":[[1.56,76.27]],"id":40612296},{"atb":[[2.76,22.25]],"id":39586887}],"con":true,"img":false}]}
{"op":"mcm","clk":"5346832730","pt":1646098260822,"mc":[{"id":"1.195395454","rc":[{"atb":[[1.59,0]],"id":40612296},{"atb":[[2.04,0]],"id":43154432},{"atb":[[2.74,28.74]],"id":39586887}],"con":true,"img":false}]}
{"op":"mcm","clk":"5346832752","pt":1646098261536,"mc":[{"id":"1.195395454","rc":[{"atl":[[4.2,0]],"id":43066392}],"con":true,"img":false}]}
{"op":"mcm","clk":"5346832762","pt":1646098261948,"mc":[{"id":"1.195395454","rc":[{"atl":[[4.2,6.25]],"id":43066392},{"atb":[[2.16,0],[2.14,17.54]],"id":43154432}],"con":true,"img":false}]}
{"op":"mcm","clk":"5346832876","pt":1646098264819,"mc":[{"id":"1.195395454","rc":[{"atb":[[1.57,54.22]],"id":40612296},{"atb":[[2.04,29.71]],"id":43154432},{"atb":[[2.82,16.97]],"id":39586887}],"con":true,"img":false}]}
{"op":"mcm","clk":"5346832881","pt":1646098265025,"mc":[{"id":"1.195395454","rc":[{"atl":[[4.2,0]],"id":43066392},{"atb":[[2.14,0],[2.16,17.24]],"id":43154432}],"con":true,"img":false}]}
{"op":"mcm","clk":"5346832927","pt":1646098266667,"mc":[{"id":"1.195395454","rc":[{"atl":[[4.2,6.25]],"id":43066392}],"con":true,"img":false}]}
{"op":"mcm","clk":"5346832981","pt":1646098268054,"mc":[{"id":"1.195395454","rc":[{"atl":[[8.2,17.36]],"id":40324412},{"atb":[[2.02,0]],"id":43154432},{"atb":[[2.76,0]],"id":39586887}],"con":true,"img":false}]}
{"op":"mcm","clk":"5346832984","pt":1646098268166,"mc":[{"id":"1.195395454","rc":[{"atl":[[8,5.07]],"id":40324412},{"atb":[[2.14,37.55]],"id":43154432},{"atb":[[2.72,22.25]],"id":39586887}],"con":true,"img":false}]}
{"op":"mcm","clk":"5346833024","pt":1646098269031,"mc":[{"id":"1.195395454","rc":[{"atl":[[4.2,0]],"id":43066392}],"con":true,"img":false}]}
{"op":"mcm","clk":"5346833037","pt":1646098269462,"mc":[{"id":"1.195395454","rc":[{"atl":[[4.2,6.25]],"id":43066392},{"atb":[[2.16,0],[2.14,55.09]],"id":43154432}],"con":true,"img":false}]}
{"op":"mcm","clk":"5346833062","pt":1646098270333,"mc":[{"id":"1.195395454","rc":[{"atb":[[2.04,0]],"id":43154432}],"con":true,"img":false}]}
{"op":"mcm","clk":"5346833154","pt":1646098272850,"mc":[{"id":"1.195395454","rc":[{"atb":[[2.14,37.55]],"id":43154432}],"con":true,"img":false}]}
{"op":"mcm","clk":"5346833159","pt":1646098272952,"mc":[{"id":"1.195395454","rc":[{"atl":[[4.2,0]],"id":43066392},{"atb":[[2.16,17.24]],"id":43154432}],"con":true,"img":false}]}
{"op":"mcm","clk":"5346833190","pt":1646098274033,"mc":[{"id":"1.195395454","rc":[{"atb":[[2.02,30.29]],"id":43154432}],"con":true,"img":false}]}
{"op":"mcm","clk":"5346833283","pt":1646098276849,"mc":[{"id":"1.195395454","rc":[{"atl":[[4.2,6.25]],"id":43066392}],"con":true,"img":false}]}
{"op":"mcm","clk":"5346833293","pt":1646098277155,"mc":[{"id":"1.195395454","rc":[{"atb":[[2.14,55.09]],"id":43154432}],"con":true,"img":false}]}
{"op":"mcm","clk":"5346833296","pt":1646098277258,"mc":[{"id":"1.195395454","rc":[{"atl":[[4.2,0]],"id":43066392},{"atb":[[2.16,0]],"id":43154432}],"con":true,"img":false}]}
{"op":"mcm","clk":"5346833319","pt":1646098277977,"mc":[{"id":"1.195395454","rc":[{"atb":[[2.02,0]],"id":43154432}],"con":true,"img":false}]}
{"op":"mcm","clk":"5346833325","pt":1646098278080,"mc":[{"id":"1.195395454","rc":[{"atl":[[10.5,0]],"id":42901530}],"con":true,"img":false}]}
{"op":"mcm","clk":"5346833329","pt":1646098278182,"mc":[{"id":"1.195395454","rc":[{"atl":[[8.2,4.26]],"id":42901530}],"con":true,"img":false}]}
{"op":"mcm","clk":"5346833395","pt":1646098280648,"mc":[{"id":"1.195395454","rc":[{"atl":[[4.2,6.25]],"id":43066392},{"atb":[[2.14,37.55],[2.16,17.24]],"id":43154432}],"con":true,"img":false}]}
{"op":"mcm","clk":"5346833416","pt":1646098281471,"mc":[{"id":"1.195395454","rc":[{"atl":[[4.2,0]],"id":43066392}],"con":true,"img":false}]}
{"op":"mcm","clk":"5346833421","pt":1646098281777,"mc":[{"id":"1.195395454","rc":[{"atb":[[2.02,30.29]],"id":43154432}],"con":true,"img":false}]}
{"op":"mcm","clk":"5346833486","pt":1646098284391,"mc":[{"id":"1.195395454","rc":[{"atl":[[4.2,6.25]],"id":43066392},{"atb":[[2.16,0],[2.14,55.09]],"id":43154432}],"con":true,"img":false}]}
{"op":"mcm","clk":"5346833524","pt":1646098285572,"mc":[{"id":"1.195395454","rc":[{"atb":[[2.02,0]],"id":43154432}],"con":true,"img":false}]}
{"op":"mcm","clk":"5346833592","pt":1646098287984,"mc":[{"id":"1.195395454","rc":[{"atb":[[2.44,0]],"id":40324412},{"atl":[[8,10.63],[11,0]],"id":40324412}],"con":true,"img":false}]}
{"op":"mcm","clk":"5346833597","pt":1646098288085,"mc":[{"id":"1.195395454","rc":[{"atb":[[2.4,31.2]],"id":40324412}],"con":true,"img":false}]}
{"op":"mcm","clk":"5346833603","pt":1646098288290,"mc":[{"id":"1.195395454","rc":[{"atl":[[4.2,0]],"id":43066392},{"atb":[[2.16,17.24]],"id":43154432}],"con":true,"img":false}]}
{"op":"mcm","clk":"5346833608","pt":1646098288394,"mc":[{"id":"1.195395454","rc":[{"atb":[[2.14,37.55]],"id":43154432}],"con":true,"img":false}]}
{"op":"mcm","clk":"5346833620","pt":1646098288699,"mc":[{"id":"1.195395454","rc":[{"atl":[[4.2,6.25]],"id":43066392}],"con":true,"img":false}]}
{"op":"mcm","clk":"5346833650","pt":1646098289265,"mc":[{"id":"1.195395454","rc":[{"atb":[[2.02,30.29]],"id":43154432}],"con":true,"img":false}]}
{"op":"mcm","clk":"5346833686","pt":1646098289982,"mc":[{"id":"1.195395454","rc":[{"atl":[[4.2,0]],"id":43066392}],"con":true,"img":false}]}
{"op":"mcm","clk":"5346833775","pt":1646098293108,"mc":[{"id":"1.195395454","rc":[{"atb":[[2.02,0]],"id":43154432}],"con":true,"img":false}]}
{"op":"mcm","clk":"5346833778","pt":1646098293211,"mc":[{"id":"1.195395454","rc":[{"atl":[[4.2,6.25]],"id":43066392},{"atb":[[2.14,55.09]],"id":43154432}],"con":true,"img":false}]}
{"op":"mcm","clk":"5346833782","pt":1646098293266,"mc":[{"id":"1.195395454","rc":[{"atb":[[2.16,0]],"id":43154432}],"con":true,"img":false}]}
{"op":"mcm","clk":"5346833882","pt":1646098296393,"mc":[{"id":"1.195395454","rc":[{"atl":[[4.2,0]],"id":43066392},{"atb":[[2.14,37.55],[2.16,17.24]],"id":43154432}],"con":true,"img":false}]}
{"op":"mcm","clk":"5346833896","pt":1646098296904,"mc":[{"id":"1.195395454","rc":[{"atb":[[2.02,30.29]],"id":43154432}],"con":true,"img":false}]}
{"op":"mcm","clk":"5346833899","pt":1646098297006,"mc":[{"id":"1.195395454","rc":[{"atl":[[4.2,6.25]],"id":43066392}],"con":true,"img":false}]}
{"op":"mcm","clk":"5346833922","pt":1646098297780,"mc":[{"id":"1.195395454","rc":[{"atl":[[4.2,0]],"id":43066392}],"con":true,"img":false}]}
{"op":"mcm","clk":"5346833953","pt":1646098298599,"mc":[{"id":"1.195395454","rc":[{"atl":[[150,0],[42,2.44],[46,0],[15,1.43]],"id":37076607},{"atl":[[10.5,8.54],[14,2.7]],"id":42901530},{"atb":[[1.52,313.09]],"id":40612296},{"atb":[[1.34,119.37],[1.38,57.14]],"id":43066392},{"atl":[[4.2,6.25]],"id":43066392},{"atb":[[2.06,18.87],[1.74,0],[1.66,151.52]],"id":43154432},{"atl":[[3.8,0],[3.95,6.78],[3.9,0]],"id":43154432},{"atl":[[9.6,0],[6.4,3.7],[23,2.18],[12.5,8.7]],"id":39586887}],"con":true,"img":false}]}
{"op":"mcm","clk":"5346833957","pt":1646098298701,"mc":[{"id":"1.195395454","rc":[{"atb":[[1.38,0]],"id":40612296},{"atb":[[2.16,0]],"id":43154432},{"atl":[[3.95,39.04]],"id":43154432}],"con":true,"img":false}]}
{"op":"mcm","clk":"5346833960","pt":1646098298806,"mc":[{"id":"1.195395454","rc":[{"atl":[[4.1,0]],"id":43154432}],"con":true,"img":false}]}
{"op":"mcm","clk":"5346833988","pt":1646098299623,"mc":[{"id":"1.195395454","rc":[{"atl":[[14.5,3.25]],"id":37076607},{"atl":[[4.2,0]],"id":43066392},{"atb":[[2.12,0],[2.08,18.52]],"id":43154432}],"con":true,"img":false}]}
{"op":"mcm","clk":"5346833991","pt":1646098299676,"mc":[{"id":"1.195395454","rc":[{"atl":[[15,0]],"id":37076607}],"con":true,"img":false}]}
{"op":"mcm","clk":"5346834024","pt":1646098300702,"mc":[{"id":"1.195395454","rc":[{"atb":[[2.02,0]],"id":43154432}],"con":true,"img":false}]}
{"op":"mcm","clk":"5346834056","pt":1646098301828,"mc":[{"id":"1.195395454","rc":[{"atl":[[4.2,6.25]],"id":43066392}],"con":true,"img":false}]}
{"op":"mcm","clk":"5346834061","pt":1646098301928,"mc":[{"id":"1.195395454","rc":[{"atb":[[2.08,0]],"id":43154432}],"con":true,"img":false}]}
{"op":"mcm","clk":"5346834080","pt":1646098302493,"mc":[{"id":"1.195395454","rc":[{"atb":[[1.36,0]],"id":43066392}],"con":true,"img":false}]}
{"op":"mcm","clk":"5346834132","pt":1646098303825,"mc":[{"id":"1.195395454","rc":[{"atl":[[3.95,6.78],[4.2,70.31]],"id":43154432}],"con":true,"img":false}]}
{"op":"mcm","clk":"5346834157","pt":1646098304394,"mc":[{"id":"1.195395454","rc":[{"atb":[[2.02,30.29]],"id":43154432}],"con":true,"img":false}]}
{"op":"mcm","clk":"5346834170","pt":1646098304701,"mc":[{"id":"1.195395454","rc":[{"atl":[[4.2,0]],"id":43066392},{"atb":[[2.08,18.52]],"id":43154432}],"con":true,"img":false}]}
{"op":"mcm","clk":"5346834182","pt":1646098305008,"mc":[{"id":"1.195395454","rc":[{"atl":[[4.2,6.25]],"id":43066392}],"con":true,"img":false}]}
{"op":"mcm","clk":"5346834229","pt":1646098306289,"mc":[{"id":"1.195395454","rc":[{"atb":[[1.39,79.24]],"id":43066392}],"con":true,"img":false}]}
{"op":"mcm","clk":"5346834282","pt":1646098307723,"mc":[{"id":"1.195395454","rc":[{"atb":[[1.4,57.14]],"id":43066392}],"con":true,"img":false}]}
{"op":"mcm","clk":"5346834286","pt":1646098307825,"mc":[{"id":"1.195395454","rc":[{"atb":[[1.38,0]],"id":43066392}],"con":true,"img":false}]}
{"op":"mcm","clk":"5346834293","pt":1646098308029,"mc":[{"id":"1.195395454","rc":[{"atb":[[1.75,0],[2.14,0]],"id":43154432}],"con":true,"img":false}]}
{"op":"mcm","clk":"5346834296","pt":1646098308131,"mc":[{"id":"1.195395454","rc":[{"atb":[[2.02,67.85],[1.67,53.72]],"id":43154432}],"con":true,"img":false}]}
{"op":"mcm","clk":"5346834304","pt":1646098308338,"mc":[{"id":"1.195395454","rc":[{"atb":[[2.02,37.55]],"id":43154432}],"con":true,"img":false}]}
{"op":"mcm","clk":"5346834317","pt":1646098308493,"mc":[{"id":"1.195395454","rc":[{"atl":[[6.8,8.62]],"id":39586887}],"con":true,"img":false}]}
{"op":"mcm","clk":"5346834342","pt":1646098309413,"mc":[{"id":"1.195395454","rc":[{"atb":[[1.53,188.68]],"id":40612296},{"atl":[[4.2,0]],"id":43066392},{"atb":[[2.08,0]],"id":43154432},{"atl":[[12,0]],"id":39586887}],"con":true,"img":false}]}
{"op":"mcm","clk":"5346834348","pt":1646098309517,"mc":[{"id":"1.195395454","rc":[{"atb":[[1.52,144.23]],"id":40612296}],"con":true,"img":false}]}
{"op":"mcm","clk":"5346834354","pt":1646098309619,"mc":[{"id":"1.195395454","rc":[{"atl":[[15.5,3.45]],"id":37076607}],"con":true,"img":false}]}
{"op":"mcm","clk":"5346834372","pt":1646098310235,"mc":[{"id":"1.195395454","rc":[{"atb":[[1.39,0]],"id":43066392}],"con":true,"img":false}]}
{"op":"mcm","clk":"5346834444","pt":1646098312129,"mc":[{"id":"1.195395454","rc":[{"atb":[[2.08,28.61]],"id":43154432}],"con":true,"img":false}]}
{"op":"mcm","clk":"5346834462","pt":1646098312641,"mc":[{"id":"1.195395454","rc":[{"atl":[[70,0],[50,0],[60,0]],"id":37076607},{"atl":[[4.2,6.25]],"id":43066392},{"atb":[[2.08,47.13]],"id":43154432}],"con":true,"img":false}]}
{"op":"mcm","clk":"5346834475","pt":1646098312798,"mc":[{"id":"1.195395454","rc":[{"atb":[[1.4,0],[1.38,114.28]],"id":43066392}],"con":true,"img":false}]}
{"op":"mcm","clk":"5346834511","pt":1646098314028,"mc":[{"id":"1.195395454","rc":[{"atb":[[1.38,195.61]],"id":43066392}],"con":true,"img":false}]}
{"op":"mcm","clk":"5346834533","pt":1646098314538,"mc":[{"id":"1.195395454","rc":[{"atb":[[1.52,329.41]],"id":40612296}],"con":true,"img":false}]}
{"op":"mcm","clk":"5346834537","pt":1646098314641,"mc":[{"id":"1.195395454","rc":[{"atb":[[1.53,0]],"id":40612296}],"con":true,"img":false}]}
{"op":"mcm","clk":"5346834668","pt":1646098318035,"mc":[{"id":"1.195395454","rc":[{"atl":[[1.62,0]],"id":42845264},{"atl":[[11.5,2.28]],"id":39586887}],"con":true,"img":false}]}
{"op":"mcm","clk":"5346834672","pt":1646098318139,"mc":[{"id":"1.195395454","rc":[{"atl":[[1.66,99.43]],"id":42845264},{"atl":[[12,3.43]],"id":39586887}],"con":true,"img":false}]}
{"op":"mcm","clk":"5346834690","pt":1646098318501,"mc":[{"id":"1.195395454","rc":[{"atl":[[7.2,12.1]],"id":39586887}],"con":true,"img":false}]}
{"op":"mcm","clk":"5346834727","pt":1646098319628,"mc":[{"id":"1.195395454","rc":[{"atl":[[16.5,4.84]],"id":37076607}],"con":true,"img":false}]}
{"op":"mcm","clk":"5346834756","pt":1646098320753,"mc":[{"id":"1.195395454","rc":[{"atb":[[2.4,0],[2.24,0],[2.5,13.33],[2.34,63.2]],"id":42901530},{"atl":[[7,2],[6.6,14.24]],"id":40324412},{"atl":[[4.2,0]],"id":43066392},{"atl":[[11,4.82]],"id":39586887}],"con":true,"img":false}]}
{"op":"mcm","clk":"5346834782","pt":1646098321425,"mc":[{"id":"1.195395454","rc":[{"atl":[[4.2,6.25]],"id":43066392}],"con":true,"img":false}]}
{"op":"mcm","clk":"5346834822","pt":1646098322613,"mc":[{"id":"1.195395454","rc":[{"atb":[[2.04,48.08]],"id":43154432},{"atl":[[4.1,16.13]],"id":43154432}],"con":true,"img":false}]}
{"op":"mcm","clk":"5346834910","pt":1646098325626,"mc":[{"id":"1.195395454","rc":[{"atb":[[1.53,188.68],[1.52,144.23]],"id":40612296},{"atl":[[4.2,0]],"id":43066392},{"atb":[[2.08,28.61]],"id":43154432}],"con":true,"img":false}]}
{"op":"mcm","clk":"5346834913","pt":1646098325751,"mc":[{"id":"1.195395454","rc":[{"atb":[[2.06,0]],"id":43154432}],"con":true,"img":false}]}
{"op":"mcm","clk":"5346834920","pt":1646098325937,"mc":[{"id":"1.195395454","rc":[{"atl":[[4.2,6.25]],"id":43066392},{"atb":[[2.08,47.13]],"id":43154432}],"con":true,"img":false}]}
{"op":"mcm","clk":"5346834938","pt":1646098326445,"mc":[{"id":"1.195395454","rc":[{"atl":[[4.2,0]],"id":43066392}],"con":true,"img":false}]}
{"op":"mcm","clk":"5346835000","pt":1646098327940,"mc":[{"id":"1.195395454","rc":[{"atl":[[8.2,0],[14,0]],"id":42901530},{"atb":[[1.37,0]],"id":43066392},{"atl":[[1.66,40.56]],"id":42845264},{"atb":[[2.8,0],[2.72,0]],"id":39586887}],"con":true,"img":false}]}
{"op":"mcm","clk":"5346835007","pt":1646098328042,"mc":[{"id":"1.195395454","rc":[{"atl":[[17,2.7],[10.5,12.8]],"id":42901530},{"atl":[[8,5.07],[12.5,5.47]],"id":40324412},{"atb":[[1.39,40.56]],"id":43066392},{"atl":[[2.98,0],[3.15,18.86]],"id":43066392},{"atl":[[1.7,58.87]],"id":42845264},{"atb":[[2.72,21.34],[2.52,22.25]],"id":39586887}],"con":true,"img":false}]}
{"op":"mcm","clk":"5346835011","pt":1646098328143,"mc":[{"id":"1.195395454","rc":[{"atb":[[1.4,57.14],[1.38,81.33]],"id":43066392}],"con":true,"img":false}]}
{"op":"mcm","clk":"5346835030","pt":1646098328453,"mc":[{"id":"1.195395454","rc":[{"atl":[[4.2,6.25]],"id":43066392}],"con":true,"img":false}]}
{"op":"mcm","clk":"5346835036","pt":1646098328555,"mc":[{"id":"1.195395454","rc":[{"atl":[[7.6,18.94]],"id":39586887}],"con":true,"img":false}]}
{"op":"mcm","clk":"5346835077","pt":1646098329632,"mc":[{"id":"1.195395454","rc":[{"atl":[[17.5,7.58]],"id":37076607}],"con":true,"img":false}]}
{"op":"mcm","clk":"5346835121","pt":1646098330759,"mc":[{"id":"1.195395454","rc":[{"atb":[[2.46,34.25]],"id":42901530},{"atl":[[7,10.33]],"id":40324412},{"atb":[[1.38,0]],"id":43066392},{"atb":[[2.82,0]],"id":39586887}],"con":true,"img":false}]}
{"op":"mcm","clk":"5346835126","pt":1646098330862,"mc":[{"id":"1.195395454","rc":[{"atb":[[1.53,0],[1.52,329.41]],"id":40612296}],"con":true,"img":false}]}
{"op":"mcm","clk":"5346835142","pt":1646098331428,"mc":[{"id":"1.195395454","rc":[{"atb":[[2.36,0],[2.32,0],[2.28,0]],"id":42901530},{"atl":[[8.2,0]],"id":40324412},{"atl":[[10,0]],"id":39586887}],"con":true,"img":false}]}
{"op":"mcm","clk":"5346835217","pt":1646098333129,"mc":[{"id":"1.195395454","rc":[{"atl":[[4.2,0]],"id":43066392},{"atb":[[2.06,18.87],[2.08,28.61]],"id":43154432}],"con":true,"img":false}]}
{"op":"mcm","clk":"5346835248","pt":1646098334047,"mc":[{"id":"1.195395454","rc":[{"atl":[[4.2,6.25]],"id":43066392},{"atb":[[2.06,0],[2.08,47.13]],"id":43154432}],"con":true,"img":false}]}
{"op":"mcm","clk":"5346835278","pt":1646098334866,"mc":[{"id":"1.195395454","rc":[{"atb":[[1.36,85.84]],"id":43066392},{"atb":[[2.8,17.17]],"id":39586887}],"con":true,"img":false}]}
{"op":"mcm","clk":"5346835359","pt":1646098336868,"mc":[{"id":"1.195395454","rc":[{"atl":[[4.2,0]],"id":43066392}],"con":true,"img":false}]}
{"op":"mcm","clk":"5346835394","pt":1646098337950,"mc":[{"id":"1.195395454","rc":[{"atb":[[1.39,0]],"id":43066392},{"atl":[[12,0],[14.5,2.7]],"id":39586887}],"con":true,"img":false}]}
{"op":"mcm","clk":"5346835399","pt":1646098338053,"mc":[{"id":"1.195395454","rc":[{"atb":[[1.37,154.84]],"id":43066392},{"atb":[[2.02,0]],"id":43154432},{"atl":[[11,0]],"id":39586887}],"con":true,"img":false}]}
{"op":"mcm","clk":"5346835404","pt":1646098338156,"mc":[{"id":"1.195395454","rc":[{"atb":[[1.4,0]],"id":43066392},{"atb":[[2.1,37.55]],"id":43154432},{"atl":[[9.8,4.82]],"id":39586887}],"con":true,"img":false}]}
{"op":"mcm","clk":"5346835489","pt":1646098340468,"mc":[{"id":"1.195395454","rc":[{"atb":[[2.08,18.52]],"id":43154432}],"con":true,"img":false}]}
{"op":"mcm","clk":"5346835503","pt":1646098340773,"mc":[{"id":"1.195395454","rc":[{"atb":[[2.42,52.82]],"id":42901530},{"atb":[[1.53,188.68],[1.52,144.23]],"id":40612296},{"atl":[[7.4,11.72]],"id":40324412},{"atl":[[4.2,6.25]],"id":43066392},{"atb":[[2.06,18.87],[2.08,0]],"id":43154432}],"con":true,"img":false}]}
{"op":"mcm","clk":"5346835633","pt":1646098344178,"mc":[{"id":"1.195395454","rc":[{"atb":[[2.12,27.59]],"id":43154432}],"con":true,"img":false}]}
{"op":"mcm","clk":"5346835676","pt":1646098345264,"mc":[{"id":"1.195395454","rc":[{"atl":[[4.2,0]],"id":43066392},{"atb":[[2.06,0],[2.08,18.52]],"id":43154432}],"con":true,"img":false}]}
{"op":"mcm","clk":"5346835698","pt":1646098345872,"mc":[{"id":"1.195395454","rc":[{"atb":[[1.53,0],[1.52,329.41]],"id":40612296}],"con":true,"img":false}]}
{"op":"mcm","clk":"5346835794","pt":1646098347982,"mc":[{"id":"1.195395454","rc":[{"atl":[[16,2.7]],"id":37076607}],"con":true,"img":false}]}
{"op":"mcm","clk":"5346835799","pt":1646098348082,"mc":[{"id":"1.195395454","rc":[{"atl":[[21,0]],"id":37076607},{"atb":[[2.1,0]],"id":43154432}],"con":true,"img":false}]}
{"op":"mcm","clk":"5346835807","pt":1646098348184,"mc":[{"id":"1.195395454","rc":[{"atb":[[2.06,37.55]],"id":43154432}],"con":true,"img":false}]}
{"op":"mcm","clk":"5346835831","pt":1646098348750,"mc":[{"id":"1.195395454","rc":[{"atl":[[4.2,6.25]],"id":43066392},{"atb":[[2.06,56.42],[2.08,0]],"id":43154432}],"con":true,"img":false}]}
{"op":"mcm","clk":"5346835899","pt":1646098350749,"mc":[{"id":"1.195395454","rc":[{"atb":[[2.38,90.58]],"id":42901530},{"atl":[[7.8,18.38]],"id":40324412}],"con":true,"img":false}]}
{"op":"mcm","clk":"5346835938","pt":1646098351670,"mc":[{"id":"1.195395454","rc":[{"atb":[[2.12,0]],"id":43154432}],"con":true,"img":false}]}
{"op":"mcm","clk":"5346836020","pt":1646098353776,"mc":[{"id":"1.195395454","rc":[{"atl":[[4.2,0]],"id":43066392},{"atb":[[2.06,37.55],[2.08,18.52]],"id":43154432}],"con":true,"img":false}]}
{"op":"mcm","clk":"5346836071","pt":1646098355367,"mc":[{"id":"1.195395454","rc":[{"atb":[[2.08,47.13]],"id":43154432}],"con":true,"img":false}]}
{"op":"mcm","clk":"5346836122","pt":1646098356494,"mc":[{"id":"1.195395454","rc":[{"atb":[[1.53,188.68],[1.52,144.23]],"id":40612296},{"atl":[[4.2,6.25]],"id":43066392},{"atb":[[2.06,56.42],[2.08,28.61]],"id":43154432}],"con":true,"img":false}]}
{"op":"mcm","clk":"5346836129","pt":1646098356596,"mc":[{"id":"1.195395454","rc":[{"atb":[[1.53,0],[1.52,336.54]],"id":40612296},{"atb":[[2.06,37.55],[2.08,47.13]],"id":43154432}],"con":true,"img":false}]}
{"op":"mcm","clk":"5346836136","pt":1646098356698,"mc":[{"id":"1.195395454","rc":[{"atl":[[4.2,0]],"id":43066392}],"con":true,"img":false}]}
{"op":"mcm","clk":"5346836180","pt":1646098358085,"mc":[{"id":"1.195395454","rc":[{"atb":[[1.51,0]],"id":40612296}],"con":true,"img":false}]}
{"op":"mcm","clk":"5346836187","pt":1646098358188,"mc":[{"id":"1.195395454","rc":[{"atb":[[1.53,85.63]],"id":40612296}],"con":true,"img":false}]}
{"op":"mcm","clk":"5346836294","pt":1646098361061,"mc":[{"id":"1.195395454","rc":[{"atl":[[4.2,6.25]],"id":43066392}],"con":true,"img":false}]}
{"op":"mcm","clk":"5346836329","pt":1646098362086,"mc":[{"id":"1.195395454","rc":[{"atb":[[1.48,208.33],[1.52,144.23]],"id":40612296},{"atl":[[4.2,0]],"id":43066392},{"atb":[[2.1,18.18],[2.08,28.61]],"id":43154432}],"con":true,"img":false}]}
{"op":"mcm","clk":"5346836399","pt":1646098363675,"mc":[{"id":"1.195395454","rc":[{"atl":[[4.2,6.25]],"id":43066392}],"con":true,"img":false}]}
{"op":"mcm","clk":"5346836424","pt":1646098364396,"mc":[{"id":"1.195395454","rc":[{"atl":[[14.5,1.77],[15,1.43]],"id":37076607},{"atl":[[4.2,0]],"id":43066392},{"atb":[[2.06,56.42],[2.1,0]],"id":43154432}],"con":true,"img":false}]}
{"op":"mcm","clk":"5346836441","pt":1646098364707,"mc":[{"id":"1.195395454","rc":[{"atb":[[2.08,0]],"id":43154432}],"con":true,"img":false}]}
{"op":"mcm","clk":"5346836584","pt":1646098368094,"mc":[{"id":"1.195395454","rc":[{"atl":[[32,0]],"id":37076607},{"atb":[[2.72,0]],"id":42901530},{"atb":[[1.37,114.28]],"id":43066392},{"atl":[[9.8,0]],"id":39586887}],"con":true,"img":false}]}
{"op":"mcm","clk":"5346836589","pt":1646098368197,"mc":[{"id":"1.195395454","rc":[{"atl":[[17,2.7]],"id":37076607},{"atb":[[2.82,20.9]],"id":42901530},{"atb":[[1.38,40.56]],"id":43066392},{"atl":[[7.4,4.82]],"id":39586887}],"con":true,"img":false}]}
{"op":"mcm","clk":"5346836594","pt":1646098368301,"mc":[{"id":"1.195395454","rc":[{"atb":[[1.39,85.85]],"id":43066392}],"con":true,"img":false}]}
{"op":"mcm","clk":"5346836598","pt":1646098368402,"mc":[{"id":"1.195395454","rc":[{"atb":[[1.37,0]],"id":43066392},{"atb":[[2.08,28.61]],"id":43154432}],"con":true,"img":false}]}
{"op":"mcm","clk":"5346836613","pt":1646098368710,"mc":[{"id":"1.195395454","rc":[{"atl":[[14.5,3.25],[15,0]],"id":37076607},{"atl":[[4.2,6.25]],"id":43066392},{"atb":[[2.06,37.55],[2.1,18.18]],"id":43154432}],"con":true,"img":false}]}
{"op":"mcm","clk":"5346836661","pt":1646098370304,"mc":[{"id":"1.195395454","rc":[{"atb":[[1.36,0]],"id":43066392}],"con":true,"img":false}]}
{"op":"mcm","clk":"5346836731","pt":1646098372104,"mc":[{"id":"1.195395454","rc":[{"atb":[[2.08,0]],"id":43154432}],"con":true,"img":false}]}
{"op":"mcm","clk":"5346836755","pt":1646098372823,"mc":[{"id":"1.195395454","rc":[{"atl":[[14.5,1.77],[15,1.43]],"id":37076607},{"atl":[[4.2,0]],"id":43066392},{"atb":[[2.06,56.42],[2.1,0]],"id":43154432}],"con":true,"img":false}]}
{"op":"mcm","clk":"5346836799","pt":1646098374007,"mc":[{"id":"1.195395454","rc":[{"atb":[[1.36,85.84]],"id":43066392}],"con":true,"img":false}]}
{"op":"mcm","clk":"5346836860","pt":1646098375915,"mc":[{"id":"1.195395454","rc":[{"atb":[[2.08,28.61]],"id":43154432}],"con":true,"img":false}]}
{"op":"mcm","clk":"5346836900","pt":1646098376791,"mc":[{"id":"1.195395454","rc":[{"atl":[[14.5,3.25],[15,0]],"id":37076607},{"atl":[[4.2,6.25]],"id":43066392},{"atb":[[2.1,18.18]],"id":43154432}],"con":true,"img":false}]}
{"op":"mcm","clk":"5346836904","pt":1646098376895,"mc":[{"id":"1.195395454","rc":[{"atb":[[2.06,37.55]],"id":43154432}],"con":true,"img":false}]}
{"op":"mcm","clk":"5346836950","pt":1646098378026,"mc":[{"id":"1.195395454","rc":[{"atl":[[8,0]],"id":40324412}],"con":true,"img":false}]}
{"op":"mcm","clk":"5346836957","pt":1646098378129,"mc":[{"id":"1.195395454","rc":[{"atl":[[7.6,5.07]],"id":40324412}],"con":true,"img":false}]}
{"op":"mcm","clk":"5346837024","pt":1646098379722,"mc":[{"id":"1.195395454","rc":[{"atb":[[2.08,0]],"id":43154432}],"con":true,"img":false}]}
{"op":"mcm","clk":"5346837089","pt":1646098381320,"mc":[{"id":"1.195395454","rc":[{"atb":[[3.45,36.38],[3.65,10.94]],"id":37076607},{"atl":[[15,1.43]],"id":37076607},{"atb":[[2.82,58.16],[3.25,10],[2.92,35.88],[3.45,5],[3.65,2.5]],"id":42901530},{"atl":[[8,13.21],[7.2,16.13],[7.8,30.7]],"id":42901530},{"atb":[[1.57,101.95],[1.55,204.61],[1.7,2.5],[1.62,10],[1.66,5]],"id":40612296},{"atl":[[2.82,50.55],[3.55,73.01],[3.75,2.5]],"id":40612296},{"atb":[[2.5,10],[2.58,5],[2.48,41.84],[2.42,77.12],[2.66,2.5]],"id":40324412},{"atl":[[6.4,10],[5.8,5],[7,42.58],[5.4,20.68]],"id":40324412},{"atb":[[1.7,2.5],[1.62,10],[1.39,125.56],[1.36,165.25],[1.66,5]],"id":43066392},{"atl":[[2.54,47.5],[2.94,89.18],[4.2,0]],"id":43066392},{"atb":[[1.02,2286.5],[1.08,2.5],[1.04,5]],"id":42845264},{"atl":[[1.67,209.84],[1.65,142.71]],"id":42845264},{"atb":[[2.06,56.42],[2.04,112.85],[2.1,0]],"id":43154432},{"atl":[[4.1,71.2],[3.9,27.59]],"id":43154432},{"atb":[[2.8,32.07],[2.92,10],[3.2,2.5],[2.74,58.53],[3,5]],"id":39586887},{"atl":[[6.4,18.51],[6.8,38.41]],"id":39586887}],"con":true,"img":false}]}
{"op":"mcm","clk":"5346837092","pt":1646098381421,"mc":[{"id":"1.195395454","rc":[{"atl":[[14.5,1.77]],"id":37076607},{"atb":[[1.46,125.56],[1.39,39.71]],"id":43066392},{"atb":[[1.02,2508.01]],"id":42845264},{"atb":[[2.06,92.16]],"id":43154432},{"atl":[[3.85,25],[4.2,39.06]],"id":43154432}],"con":true,"img":false}]}
{"op":"mcm","clk":"5346837097","pt":1646098381523,"mc":[{"id":"1.195395454","rc":[{"atl":[[14.5,3.25]],"id":37076607},{"atl":[[4.2,6.25]],"id":43066392},{"atl":[[3.85,0],[4,58.33]],"id":43154432}],"con":true,"img":false}]}
{"op":"mcm","clk":"5346837105","pt":1646098381626,"mc":[{"id":"1.195395454","rc":[{"atl":[[15,0]],"id":37076607},{"atb":[[2.06,73.29],[2.1,18.18]],"id":43154432}],"con":true,"img":false}]}
{"op":"mcm","clk":"5346837184","pt":1646098383731,"mc":[{"id":"1.195395454","rc":[{"atb":[[1.57,47.73]],"id":40612296},{"atb":[[2.48,20.96]],"id":40324412},{"atb":[[1.36,79.41]],"id":43066392},{"atb":[[1.05,7.5]],"id":42845264},{"atb":[[2.08,28.61]],"id":43154432},{"atb":[[2.8,14.9]],"id":39586887}],"con":true,"img":false}]}
{"op":"mcm","clk":"5346837209","pt":1646098384402,"mc":[{"id":"1.195395454","rc":[{"atl":[[4.2,0]],"id":43066392}],"con":true,"img":false}]}
{"op":"mcm","clk":"5346837355","pt":1646098387933,"mc":[{"id":"1.195395454","rc":[{"atb":[[1.63,10.01]],"id":40612296},{"atb":[[2.52,10.01]],"id":40324412},{"atb":[[1.63,10.01]],"id":43066392},{"atb":[[2.08,0]],"id":43154432},{"atb":[[3.05,7.5]],"id":39586887}],"con":true,"img":false}]}
{"op":"mcm","clk":"5346837359","pt":1646098387986,"mc":[{"id":"1.195395454","rc":[{"atl":[[17,0]],"id":37076607}],"con":true,"img":false}]}
{"op":"mcm","clk":"5346837363","pt":1646098388089,"mc":[{"id":"1.195395454","rc":[{"atl":[[19,2.7]],"id":37076607}],"con":true,"img":false}]}
{"op":"mcm","clk":"5346837401","pt":1646098388912,"mc":[{"id":"1.195395454","rc":[{"atb":[[3.55,2.92]],"id":37076607},{"atb":[[2.98,3.76]],"id":42901530},{"atb":[[1.61,12.21]],"id":40612296},{"atb":[[1.49,15.2]],"id":43066392},{"atb":[[2.1,24.95]],"id":43154432}],"con":true,"img":false}]}
{"op":"mcm","clk":"5346837435","pt":1646098389832,"mc":[{"id":"1.195395454","rc":[{"atl":[[14.5,1.77],[15,1.43]],"id":37076607},{"atl":[[4.2,6.25]],"id":43066392},{"atb":[[2.06,92.16],[2.1,6.77]],"id":43154432}],"con":true,"img":false}]}
{"op":"mcm","clk":"5346837511","pt":1646098391732,"mc":[{"id":"1.195395454","rc":[{"atb":[[2.12,27.59]],"id":43154432}],"con":true,"img":false}]}
{"op":"mcm","clk":"5346837523","pt":1646098391934,"mc":[{"id":"1.195395454","rc":[{"atb":[[2.48,25.99]],"id":40324412},{"atb":[[2.8,19.04]],"id":39586887}],"con":true,"img":false}]}
{"op":"mcm","clk":"5346837550","pt":1646098392609,"mc":[{"id":"1.195395454","rc":[{"atl":[[14.5,3.25],[15,0]],"id":37076607},{"atl":[[4.2,0]],"id":43066392},{"atb":[[2.06,73.29],[2.1,24.95]],"id":43154432}],"con":true,"img":false}]}
{"op":"mcm","clk":"5346837639","pt":1646098395021,"mc":[{"id":"1.195395454","rc":[{"atb":[[2.98,7.98]],"id":42901530}],"con":true,"img":false}]}
{"op":"mcm","clk":"5346837644","pt":1646098395121,"mc":[{"id":"1.195395454","rc":[{"atb":[[3.55,6.19]],"id":37076607}],"con":true,"img":false}]}
{"op":"mcm","clk":"5346837646","pt":1646098395222,"mc":[{"id":"1.195395454","rc":[{"atb":[[1.49,32.25]],"id":43066392}],"con":true,"img":false}]}
{"op":"mcm","clk":"5346837651","pt":1646098395426,"mc":[{"id":"1.195395454","rc":[{"atb":[[2.1,32.54]],"id":43154432}],"con":true,"img":false}]}
{"op":"mcm","clk":"5346837714","pt":1646098397838,"mc":[{"id":"1.195395454","rc":[{"atl":[[14.5,1.77],[15,1.43]],"id":37076607},{"atl":[[4.2,6.25]],"id":43066392},{"atb":[[2.06,92.16]],"id":43154432}],"con":true,"img":false}]}
{"op":"mcm","clk":"5346837718","pt":1646098397942,"mc":[{"id":"1.195395454","rc":[{"atb":[[2.1,14.36]],"id":43154432}],"con":true,"img":false}]}
{"op":"mcm","clk":"5346837726","pt":1646098398043,"mc":[{"id":"1.195395454","rc":[{"atb":[[1.56,35.71]],"id":40612296},{"atb":[[2.4,0],[2.28,0]],"id":40324412},{"atb":[[1.38,0]],"id":43066392},{"atl":[[3.15,0]],"id":43066392}],"con":true,"img":false}]}
{"op":"mcm","clk":"5346837729","pt":1646098398098,"mc":[{"id":"1.195395454","rc":[{"atb":[[1.58,40.56]],"id":40612296},{"atb":[[2.22,30.42],[2.44,31.2]],"id":40324412},{"atb":[[1.4,40.56]],"id":43066392},{"atl":[[3.45,18.86]],"id":43066392}],"con":true,"img":false}]}
{"op":"mcm","clk":"5346837750","pt":1646098398822,"mc":[{"id":"1.195395454","rc":[{"atb":[[3.45,19.49],[3.55,18.16]],"id":37076607},{"atb":[[2.82,20.9],[3.25,36.37],[3.65,15.68]],"id":42901530},{"atb":[[1.7,14.4],[1.63,33.81],[1.55,109.15]],"id":40612296},{"atb":[[2.52,25.01],[2.66,10]],"id":40324412},{"atl":[[5.8,20],[7,10.33]],"id":40324412},{"atb":[[1.7,15.18],[1.36,0],[1.63,35.37]],"id":43066392},{"atb":[[1.08,38.55]],"id":42845264},{"atb":[[2.06,174.93],[2.04,48.08]],"id":43154432},{"atl":[[4,117.91],[4.1,16.13]],"id":43154432},{"atb":[[3,23.76],[3.2,11.88],[2.74,28.74]],"id":39586887}],"con":true,"img":false}]}
{"op":"mcm","clk":"5346837755","pt":1646098398925,"mc":[{"id":"1.195395454","rc":[{"atb":[[2.42,35.21]],"id":40324412},{"atb":[[1.02,2286.5],[1.04,77.1]],"id":42845264}],"con":true,"img":false}]}
{"op":"mcm","clk":"5346837761","pt":1646098399030,"mc":[{"id":"1.195395454","rc":[{"atb":[[2.92,17.25]],"id":42901530},{"atb":[[1.57,0]],"id":40612296},{"atb":[[2.48,5.03]],"id":40324412},{"atb":[[1.39,0]],"id":43066392},{"atb":[[1.02,2174.56]],"id":42845264},{"atb":[[2.8,4.14]],"id":39586887}],"con":true,"img":false}]}
{"op":"mcm","clk":"5346837823","pt":1646098400524,"mc":[{"id":"1.195395454","rc":[{"atl":[[14.5,3.25],[15,0]],"id":37076607},{"atl":[[4.2,0]],"id":43066392},{"atb":[[2.06,156.06],[2.1,32.54]],"id":43154432}],"con":true,"img":false}]}
{"op":"mcm","clk":"5346837836","pt":1646098400932,"mc":[{"id":"1.195395454","rc":[{"atb":[[3.55,15.24]],"id":37076607},{"atb":[[2.98,4.21]],"id":42901530},{"atb":[[1.61,0]],"id":40612296},{"atb":[[2.48,0]],"id":40324412},{"atb":[[2.8,0]],"id":39586887}],"con":true,"img":false}]}
{"op":"mcm","clk":"5346837839","pt":1646098401034,"mc":[{"id":"1.195395454","rc":[{"atb":[[2.48,5.64]],"id":40324412}],"con":true,"img":false}]}
{"op":"mcm","clk":"5346837980","pt":1646098405855,"mc":[{"id":"1.195395454","rc":[{"atl":[[14.5,1.77],[15,1.43]],"id":37076607},{"atl":[[4.2,6.25]],"id":43066392},{"atb":[[2.06,174.93],[2.1,14.36]],"id":43154432}],"con":true,"img":false}]}
{"op":"mcm","clk":"5346838017","pt":1646098406938,"mc":[{"id":"1.195395454","rc":[{"atb":[[3.5,10.97]],"id":37076607},{"atb":[[3.3,3.24]],"id":42901530},{"atb":[[1.59,12.62]],"id":40612296},{"atb":[[2.5,14.96]],"id":40324412}],"con":true,"img":false}]}
{"op":"mcm","clk":"5346838022","pt":1646098407041,"mc":[{"id":"1.195395454","rc":[{"atb":[[3.05,11.14]],"id":39586887}],"con":true,"img":false}]}
{"op":"mcm","clk":"5346838054","pt":1646098408063,"mc":[{"id":"1.195395454","rc":[{"atb":[[3.45,5],[3.35,25.59]],"id":37076607},{"atl":[[19,0],[23,11.88]],"id":37076607},{"atb":[[2.82,0],[2.72,40.35]],"id":42901530},{"atl":[[17,0],[10.5,8.54],[21,12.86]],"id":42901530},{"atb":[[1.51,60.05],[1.53,0]],"id":40612296},{"atl":[[3.8,0],[4.5,37.16],[3.95,0]],"id":40612296},{"atb":[[2.22,0],[2.12,45.85]],"id":40324412},{"atl":[[12.5,23.27]],"id":40324412},{"atb":[[1.34,0],[1.4,0],[1.32,73.63]],"id":43066392},{"atb":[[1.02,946.86]],"id":42845264},{"atl":[[1.7,0],[2.44,100.9],[1.66,0]],"id":42845264},{"atb":[[2.06,137.38],[1.67,85.99]],"id":43154432},{"atb":[[2.72,0]],"id":39586887}],"con":true,"img":false}]}
{"op":"mcm","clk":"5346838057","pt":1646098408120,"mc":[{"id":"1.195395454","rc":[{"atl":[[10,4.26]],"id":42901530},{"atl":[[3.5,16.22]],"id":40612296},{"atb":[[1.37,40.56]],"id":43066392},{"atl":[[1.64,40.56]],"id":42845264},{"atb":[[2.14,37.55]],"id":43154432},{"atb":[[2.82,21.34]],"id":39586887}],"con":true,"img":false}]}
{"op":"mcm","clk":"5346838062","pt":1646098408224,"mc":[{"id":"1.195395454","rc":[{"atl":[[3.55,9.41],[3.5,62.17]],"id":40612296},{"atl":[[1.64,128.8],[1.67,74.63],[1.69,253.69]],"id":42845264},{"atb":[[2.06,54.61]],"id":43154432}],"con":true,"img":false}]}
{"op":"mcm","clk":"5346838067","pt":1646098408426,"mc":[{"id":"1.195395454","rc":[{"atl":[[1.65,30.77]],"id":42845264}],"con":true,"img":false}]}
{"op":"mcm","clk":"5346838080","pt":1646098408760,"mc":[{"id":"1.195395454","rc":[{"atl":[[14.5,3.25],[15,0]],"id":37076607},{"atb":[[2.06,35.74],[2.1,32.54]],"id":43154432}],"con":true,"img":false}]}
{"op":"mcm","clk":"5346838083","pt":1646098408858,"mc":[{"id":"1.195395454","rc":[{"atl":[[4.2,0]],"id":43066392}],"con":true,"img":false}]}
{"op":"mcm","clk":"5346838106","pt":1646098409322,"mc":[{"id":"1.195395454","rc":[{"atl":[[3.35,12.71],[4.2,6.25]],"id":43066392}],"con":true,"img":false}]}
{"op":"mcm","clk":"5346838132","pt":1646098409938,"mc":[{"id":"1.195395454","rc":[{"atb":[[2.1,25.77]],"id":43154432}],"con":true,"img":false}]}
{"op":"mcm","clk":"5346838139","pt":1646098410141,"mc":[{"id":"1.195395454","rc":[{"atl":[[4.2,0]],"id":43066392}],"con":true,"img":false}]}
{"op":"mcm","clk":"5346838148","pt":1646098410550,"mc":[{"id":"1.195395454","rc":[{"atb":[[2.12,0]],"id":43154432}],"con":true,"img":false}]}
{"op":"mcm","clk":"5346838246","pt":1646098413131,"mc":[{"id":"1.195395454","rc":[{"atl":[[14.5,1.77],[15,1.43]],"id":37076607},{"atl":[[4.2,6.25]],"id":43066392},{"atb":[[2.06,54.61],[2.1,7.59]],"id":43154432}],"con":true,"img":false}]}
{"op":"mcm","clk":"5346838253","pt":1646098413334,"mc":[{"id":"1.195395454","rc":[{"atb":[[3.55,11.97]],"id":37076607},{"atb":[[2.98,0]],"id":42901530},{"atb":[[2.76,4.74]],"id":39586887}],"con":true,"img":false}]}
{"op":"mcm","clk":"5346838260","pt":1646098413537,"mc":[{"id":"1.195395454","rc":[{"atb":[[1.59,26.78]],"id":40612296}],"con":true,"img":false}]}
{"op":"mcm","clk":"5346838294","pt":1646098414459,"mc":[{"id":"1.195395454","rc":[{"atb":[[2.16,26.64]],"id":43154432}],"con":true,"img":false}]}
{"op":"mcm","clk":"5346838317","pt":1646098415128,"mc":[{"id":"1.195395454","rc":[{"atl":[[14.5,3.25],[15,0]],"id":37076607},{"atb":[[2.06,35.74],[2.1,25.77]],"id":43154432}],"con":true,"img":false}]}
{"op":"mcm","clk":"5346838344","pt":1646098415951,"mc":[{"id":"1.195395454","rc":[{"atb":[[3.3,38.13]],"id":42901530},{"atb":[[2.18,6.31]],"id":43154432}],"con":true,"img":false}]}
{"op":"mcm","clk":"5346838348","pt":1646098416052,"mc":[{"id":"1.195395454","rc":[{"atb":[[3.25,10]],"id":42901530}],"con":true,"img":false}]}
{"op":"mcm","clk":"5346838371","pt":1646098416668,"mc":[{"id":"1.195395454","rc":[{"atl":[[4.2,0]],"id":43066392}],"con":true,"img":false}]}
{"op":"mcm","clk":"5346838418","pt":1646098417954,"mc":[{"id":"1.195395454","rc":[{"atb":[[2.44,0]],"id":40324412},{"atl":[[4.5,57.25],[3.8,0]],"id":43066392},{"atl":[[7.4,0],[14.5,15.58]],"id":39586887}],"con":true,"img":false}]}
{"op":"mcm","clk":"5346838422","pt":1646098418055,"mc":[{"id":"1.195395454","rc":[{"atb":[[2.48,36.85]],"id":40324412},{"atl":[[8.8,4.82]],"id":39586887}],"con":true,"img":false}]}
{"op":"mcm","clk":"5346838428","pt":1646098418259,"mc":[{"id":"1.195395454","rc":[{"atb":[[2.16,0]],"id":43154432}],"con":true,"img":false}]}
{"op":"mcm","clk":"5346838442","pt":1646098418674,"mc":[{"id":"1.195395454","rc":[{"atl":[[4.2,6.25]],"id":43066392},{"atb":[[2.1,7.59],[2.08,18.52]],"id":43154432}],"con":true,"img":false}]}
{"op":"mcm","clk":"5346838460","pt":1646098419029,"mc":[{"id":"1.195395454","rc":[{"atb":[[3.5,14.32]],"id":37076607},{"atb":[[3.3,34.89]],"id":42901530},{"atb":[[2.5,10]],"id":40324412}],"con":true,"img":false}]}
{"op":"mcm","clk":"5346838475","pt":1646098419539,"mc":[{"id":"1.195395454","rc":[{"atl":[[10.5,0],[8.6,13.16]],"id":42901530},{"atl":[[4.2,0]],"id":43066392},{"atb":[[2.12,17.86],[2.1,60.36],[2.08,0]],"id":43154432}],"con":true,"img":false}]}
{"op":"mcm","clk":"5346838479","pt":1646098419641,"mc":[{"id":"1.195395454","rc":[{"atb":[[2.1,7.59]],"id":43154432}],"con":true,"img":false}]}
{"op":"mcm","clk":"5346838483","pt":1646098419744,"mc":[{"id":"1.195395454","rc":[{"atl":[[4.2,6.25]],"id":43066392}],"con":true,"img":false}]}
{"op":"mcm","clk":"5346838503","pt":1646098420256,"mc":[{"id":"1.195395454","rc":[{"atl":[[4.2,0]],"id":43066392}],"con":true,"img":false}]}
{"op":"mcm","clk":"5346838507","pt":1646098420359,"mc":[{"id":"1.195395454","rc":[{"atl":[[4.2,6.25]],"id":43066392}],"con":true,"img":false}]}
{"op":"mcm","clk":"5346838519","pt":1646098420666,"mc":[{"id":"1.195395454","rc":[{"atb":[[2.08,18.52]],"id":43154432}],"con":true,"img":false}]}
{"op":"mcm","clk":"5346838526","pt":1646098420768,"mc":[{"id":"1.195395454","rc":[{"atl":[[4.2,0]],"id":43066392},{"atb":[[2.12,0]],"id":43154432}],"con":true,"img":false}]}
{"op":"mcm","clk":"5346838534","pt":1646098420971,"mc":[{"id":"1.195395454","rc":[{"atb":[[1.14,0]],"id":43154432}],"con":true,"img":false}]}
{"op":"mcm","clk":"5346838588","pt":1646098422154,"mc":[{"id":"1.195395454","rc":[{"atb":[[2.2,12.62]],"id":43154432}],"con":true,"img":false}]}
{"op":"mcm","clk":"5346838596","pt":1646098422361,"mc":[{"id":"1.195395454","rc":[{"atl":[[4.2,6.25]],"id":43066392},{"atb":[[2.12,17.86]],"id":43154432}],"con":true,"img":false}]}
{"op":"mcm","clk":"5346838696","pt":1646098424465,"mc":[{"id":"1.195395454","rc":[{"atl":[[4.2,0]],"id":43066392}],"con":true,"img":false}]}
{"op":"mcm","clk":"5346838717","pt":1646098424873,"mc":[{"id":"1.195395454","rc":[{"atb":[[3.4,3.1]],"id":42901530},{"atb":[[2.54,4.83]],"id":40324412}],"con":true,"img":false}]}
{"op":"mcm","clk":"5346838727","pt":1646098425078,"mc":[{"id":"1.195395454","rc":[{"atb":[[2.54,27.33],[2.52,10.01]],"id":40324412}],"con":true,"img":false}]}
{"op":"mcm","clk":"5346838737","pt":1646098425282,"mc":[{"id":"1.195395454","rc":[{"atl":[[1.67,228.64],[1.69,108.7]],"id":42845264},{"atb":[[2.1,0]],"id":43154432}],"con":true,"img":false}]}
{"op":"mcm","clk":"5346838823","pt":1646098427853,"mc":[{"id":"1.195395454","rc":[{"atb":[[2.52,0]],"id":40324412}],"con":true,"img":false}]}
{"op":"mcm","clk":"5346838828","pt":1646098427954,"mc":[{"id":"1.195395454","rc":[{"atl":[[16,0]],"id":37076607},{"atb":[[2.92,0]],"id":42901530},{"atb":[[1.58,0]],"id":40612296},{"atl":[[3.5,45.95]],"id":40612296},{"atb":[[2.82,0]],"id":39586887}],"con":true,"img":false}]}
{"op":"mcm","clk":"5346838830","pt":1646098428056,"mc":[{"id":"1.195395454","rc":[{"atl":[[15,2.7]],"id":37076607},{"atb":[[3.35,17.25]],"id":42901530},{"atb":[[1.6,40.56]],"id":40612296},{"atl":[[3.45,16.22]],"id":40612296},{"atb":[[3.05,32.49]],"id":39586887}],"con":true,"img":false}]}
{"op":"mcm","clk":"5346838835","pt":1646098428158,"mc":[{"id":"1.195395454","rc":[{"atl":[[3.5,0],[3.45,62.17]],"id":40612296}],"con":true,"img":false}]}
{"op":"mcm","clk":"5346838876","pt":1646098428877,"mc":[{"id":"1.195395454","rc":[{"atl":[[4.2,6.25]],"id":43066392}],"con":true,"img":false}]}
{"op":"mcm","clk":"5346838882","pt":1646098428980,"mc":[{"id":"1.195395454","rc":[{"atb":[[2.12,0]],"id":43154432}],"con":true,"img":false}]}
{"op":"mcm","clk":"5346838973","pt":1646098431081,"mc":[{"id":"1.195395454","rc":[{"atb":[[3.05,28.85]],"id":39586887}],"con":true,"img":false}]}
{"op":"mcm","clk":"5346838976","pt":1646098431184,"mc":[{"id":"1.195395454","rc":[{"atb":[[3.4,6.59]],"id":42901530}],"con":true,"img":false}]}
{"op":"mcm","clk":"5346838982","pt":1646098431386,"mc":[{"id":"1.195395454","rc":[{"atb":[[2.18,13.38]],"id":43154432}],"con":true,"img":false}]}
{"op":"mcm","clk":"5346838995","pt":1646098431749,"mc":[{"id":"1.195395454","rc":[{"atb":[[2.6,19.31]],"id":40324412}],"con":true,"img":false}]}
{"op":"mcm","clk":"5346839021","pt":1646098432365,"mc":[{"id":"1.195395454","rc":[{"atb":[[2.12,17.86]],"id":43154432},{"atl":[[4.3,22.73]],"id":43154432}],"con":true,"img":false}]}
{"op":"mcm","clk":"5346839028","pt":1646098432469,"mc":[{"id":"1.195395454","rc":[{"atb":[[3.5,6.32],[3.3,0],[3.05,9.76],[3.2,0],[2.88,53.19],[3.4,0]],"id":37076607},{"atl":[[4.4,0],[3.75,9.77],[4,0],[3.45,102.99]],"id":40612296},{"atl":[[6,24],[6.6,0]],"id":40324412},{"atb":[[1.46,0],[1.51,40.56]],"id":43066392},{"atl":[[3.85,16.85],[3,50],[3.15,9.3],[4.2,0]],"id":43066392},{"atb":[[2.6,75.04],[2.78,35.64],[2.96,10.2]],"id":39586887}],"con":true,"img":false}]}
{"op":"mcm","clk":"5346839041","pt":1646098432776,"mc":[{"id":"1.195395454","rc":[{"atb":[[3.4,41.48]],"id":42901530},{"atl":[[4,92.91],[4.2,0]],"id":43154432}],"con":true,"img":false}]}
{"op":"mcm","clk":"5346839046","pt":1646098432879,"mc":[{"id":"1.195395454","rc":[{"atb":[[3.3,0]],"id":42901530}],"con":true,"img":false}]}
{"op":"mcm","clk":"5346839096","pt":1646098434157,"mc":[{"id":"1.195395454","rc":[{"atb":[[3.5,3.34]],"id":37076607},{"atb":[[3.4,38.37]],"id":42901530},{"atb":[[1.49,17.05]],"id":43066392}],"con":true,"img":false}]}
{"op":"mcm","clk":"5346839164","pt":1646098435958,"mc":[{"id":"1.195395454","rc":[{"atb":[[3.1,3.54]],"id":39586887}],"con":true,"img":false}]}
{"op":"mcm","clk":"5346839167","pt":1646098436059,"mc":[{"id":"1.195395454","rc":[{"atb":[[3.05,74.43]],"id":39586887}],"con":true,"img":false}]}
{"op":"mcm","clk":"5346839173","pt":1646098436162,"mc":[{"id":"1.195395454","rc":[{"atb":[[3,4.99]],"id":39586887}],"con":true,"img":false}]}
{"op":"mcm","clk":"5346839203","pt":1646098436882,"mc":[{"id":"1.195395454","rc":[{"atb":[[2.12,0]],"id":43154432}],"con":true,"img":false}]}
{"op":"mcm","clk":"5346839256","pt":1646098437963,"mc":[{"id":"1.195395454","rc":[{"atb":[[2.94,36.35]],"id":37076607},{"atl":[[8.6,24.77]],"id":43154432},{"atb":[[2.62,35.72]],"id":39586887}],"con":true,"img":false}]}
{"op":"mcm","clk":"5346839260","pt":1646098438064,"mc":[{"id":"1.195395454","rc":[{"atb":[[3.35,0]],"id":37076607},{"atl":[[10,0]],"id":42901530},{"atl":[[4.5,0]],"id":40612296},{"atl":[[1.64,88.24]],"id":42845264},{"atb":[[2.14,0]],"id":43154432},{"atl":[[10,0]],"id":43154432},{"atb":[[2.52,0]],"id":39586887}],"con":true,"img":false}]}
{"op":"mcm","clk":"5346839265","pt":1646098438168,"mc":[{"id":"1.195395454","rc":[{"atl":[[8.4,21.15]],"id":42901530},{"atl":[[4.7,37.16]],"id":40612296},{"atl":[[1.63,40.56]],"id":42845264},{"atb":[[2.1,37.55],[2.08,66.38]],"id":43154432}],"con":true,"img":false}]}
{"op":"mcm","clk":"5346839268","pt":1646098438269,"mc":[{"id":"1.195395454","rc":[{"atl":[[1.63,99.89]],"id":42845264}],"con":true,"img":false}]}
{"op":"mcm","clk":"5346839274","pt":1646098438475,"mc":[{"id":"1.195395454","rc":[{"atl":[[1.64,0]],"id":42845264}],"con":true,"img":false}]}
{"op":"mcm","clk":"5346839303","pt":1646098439192,"mc":[{"id":"1.195395454","rc":[{"atb":[[2.18,7.07]],"id":43154432}],"con":true,"img":false}]}
{"op":"mcm","clk":"5346839310","pt":1646098439394,"mc":[{"id":"1.195395454","rc":[{"atb":[[3.05,66.92]],"id":39586887}],"con":true,"img":false}]}
{"op":"mcm","clk":"5346839388","pt":1646098441297,"mc":[{"id":"1.195395454","rc":[{"atb":[[2.12,17.86],[2.2,0]],"id":43154432}],"con":true,"img":false}]}
{"op":"mcm","clk":"5346839407","pt":1646098441707,"mc":[{"id":"1.195395454","rc":[{"atb":[[2.54,4.83],[2.58,48.98]],"id":40324412}],"con":true,"img":false}]}
{"op":"mcm","clk":"5346839426","pt":1646098442071,"mc":[{"id":"1.195395454","rc":[{"atb":[[3.5,2.97]],"id":42901530},{"atb":[[2.54,0]],"id":40324412}],"con":true,"img":false}]}
{"op":"mcm","clk":"5346839451","pt":1646098442481,"mc":[{"id":"1.195395454","rc":[{"atb":[[2.98,25.25]],"id":37076607},{"atl":[[3.85,17.54]],"id":40612296},{"atl":[[6.4,19.26]],"id":40324412},{"atl":[[3.25,22.22]],"id":43066392},{"atb":[[2.92,36.04]],"id":39586887}],"con":true,"img":false}]}
{"op":"mcm","clk":"5346839487","pt":1646098443300,"mc":[{"id":"1.195395454","rc":[{"atb":[[3.25,13.73],[2.76,0]],"id":39586887}],"con":true,"img":false}]}
{"op":"mcm","clk":"5346839491","pt":1646098443404,"mc":[{"id":"1.195395454","rc":[{"atb":[[3.25,32.95]],"id":39586887}],"con":true,"img":false}]}
{"op":"mcm","clk":"5346839496","pt":1646098443507,"mc":[{"id":"1.195395454","rc":[{"atb":[[3.2,2.49]],"id":39586887}],"con":true,"img":false}]}
{"op":"mcm","clk":"5346839550","pt":1646098444586,"mc":[{"id":"1.195395454","rc":[{"atl":[[4.8,0],[4.6,0],[5,0]],"id":40612296},{"atl":[[7.4,0],[7,2],[7.8,0]],"id":40324412},{"atl":[[4.8,0],[4.4,0],[4.6,0]],"id":43066392},{"atb":[[2.12,0],[2.08,18.52]],"id":43154432},{"atb":[[2.74,0],[2.66,0],[2.7,35.31]],"id":39586887}],"con":true,"img":false}]}
{"op":"mcm","clk":"5346839574","pt":1646098445099,"mc":[{"id":"1.195395454","rc":[{"atb":[[2.14,6.53]],"id":43154432}],"con":true,"img":false}]}
{"op":"mcm","clk":"5346839579","pt":1646098445200,"mc":[{"id":"1.195395454","rc":[{"atb":[[3.1,0]],"id":39586887}],"con":true,"img":false}]}
{"op":"mcm","clk":"5346839586","pt":1646098445304,"mc":[{"id":"1.195395454","rc":[{"atb":[[2.2,14.15]],"id":43154432}],"con":true,"img":false}]}
{"op":"mcm","clk":"5346839670","pt":1646098447199,"mc":[{"id":"1.195395454","rc":[{"atl":[[8,10.71],[7.6,10.08]],"id":42901530},{"atb":[[2.54,10],[2.5,0],[2.58,43.98],[2.62,5],[2.66,7.5],[2.7,2.5]],"id":40324412},{"atb":[[1.71,2.5],[1.63,45.37],[1.67,5]],"id":43066392},{"atb":[[2.92,26.04],[3.2,0],[3,0],[3.25,35.45],[3.05,71.92]],"id":39586887}],"con":true,"img":false}]}
{"op":"mcm","clk":"5346839674","pt":1646098447302,"mc":[{"id":"1.195395454","rc":[{"atb":[[1.7,12.68],[1.62,0],[1.66,0]],"id":43066392}],"con":true,"img":false}]}
{"op":"mcm","clk":"5346839679","pt":1646098447405,"mc":[{"id":"1.195395454","rc":[{"atb":[[2.7,11.88]],"id":40324412},{"atb":[[1.71,19.06],[1.63,20.01],[1.67,38.12]],"id":43066392},{"atb":[[2.96,91.15],[3.05,26.34]],"id":39586887}],"con":true,"img":false}]}
{"op":"mcm","clk":"5346839688","pt":1646098447609,"mc":[{"id":"1.195395454","rc":[{"atb":[[2.66,0]],"id":40324412},{"atb":[[1.7,0]],"id":43066392}],"con":true,"img":false}]}
{"op":"mcm","clk":"5346839711","pt":1646098448076,"mc":[{"id":"1.195395454","rc":[{"atb":[[3.6,0]],"id":37076607},{"atb":[[2.72,0],[3.35,0]],"id":42901530},{"atl":[[3.45,86.77]],"id":40612296},{"atb":[[2.64,4.54]],"id":40324412},{"atb":[[3.05,5]],"id":39586887},{"atl":[[8.8,0]],"id":39586887}],"con":true,"img":false}]}
{"op":"mcm","clk":"5346839718","pt":1646098448180,"mc":[{"id":"1.195395454","rc":[{"atb":[[3.7,15.6]],"id":37076607},{"atb":[[2.82,40.35],[3.45,22.25]],"id":42901530},{"atl":[[3.4,16.22]],"id":40612296},{"atb":[[2.98,21.34]],"id":39586887},{"atl":[[7.4,4.82]],"id":39586887}],"con":true,"img":false}]}
{"op":"mcm","clk":"5346839724","pt":1646098448286,"mc":[{"id":"1.195395454","rc":[{"atb":[[3.55,0],[3.5,13.24],[3.75,10.65]],"id":37076607},{"atl":[[3.4,62.17]],"id":40612296}],"con":true,"img":false}]}
{"op":"mcm","clk":"5346839730","pt":1646098448384,"mc":[{"id":"1.195395454","rc":[{"atl":[[3.45,40.82]],"id":40612296}],"con":true,"img":false}]}
{"op":"mcm","clk":"5346839733","pt":1646098448490,"mc":[{"id":"1.195395454","rc":[{"atb":[[3.65,2.5]],"id":37076607}],"con":true,"img":false}]}
{"op":"mcm","clk":"5346839772","pt":1646098449310,"mc":[{"id":"1.195395454","rc":[{"atb":[[3.45,69.97],[3.4,3.48]],"id":42901530},{"atb":[[2.12,17.86]],"id":43154432}],"con":true,"img":false}]}
{"op":"mcm","clk":"5346839781","pt":1646098449514,"mc":[{"id":"1.195395454","rc":[{"atb":[[3.5,9.9]],"id":37076607},{"atb":[[3.4,0]],"id":42901530},{"atb":[[1.49,0]],"id":43066392}],"con":true,"img":false}]}
{"op":"mcm","clk":"5346839842","pt":1646098451102,"mc":[{"id":"1.195395454","rc":[{"atb":[[3.05,13.39]],"id":37076607},{"atb":[[3.5,0]],"id":42901530},{"atb":[[3.3,3.24]],"id":39586887}],"con":true,"img":false}]}
{"op":"mcm","clk":"5346839851","pt":1646098451307,"mc":[{"id":"1.195395454","rc":[{"atb":[[2.6,0]],"id":40324412},{"atb":[[1.63,10]],"id":43066392},{"atb":[[3.25,21.72]],"id":39586887}],"con":true,"img":false}]}
{"op":"mcm","clk":"5346839908","pt":1646098452491,"mc":[{"id":"1.195395454","rc":[{"atb":[[2.94,75.01]],"id":37076607},{"atl":[[3.95,25.42]],"id":40612296},{"atl":[[6.8,12.93]],"id":40324412},{"atl":[[3.35,44.62]],"id":43066392},{"atb":[[2.88,39.89],[2.96,10.19],[3.05,40.26]],"id":39586887}],"con":true,"img":false}]}
{"op":"mcm","clk":"5346839921","pt":1646098452696,"mc":[{"id":"1.195395454","rc":[{"atb":[[2.12,0]],"id":43154432}],"con":true,"img":false}]}
{"op":"mcm","clk":"5346839976","pt":1646098453821,"mc":[{"id":"1.195395454","rc":[{"atb":[[2.12,17.86]],"id":43154432}],"con":true,"img":false}]}
{"op":"mcm","clk":"5346839989","pt":1646098454183,"mc":[{"id":"1.195395454","rc":[{"atb":[[3.3,0]],"id":39586887}],"con":true,"img":false}]}
{"op":"mcm","clk":"5346840031","pt":1646098455105,"mc":[{"id":"1.195395454","rc":[{"atb":[[1.63,95.77],[1.67,5]],"id":43066392},{"atb":[[2.98,85.94],[3.05,5]],"id":39586887}],"con":true,"img":false}]}
{"op":"mcm","clk":"5346840038","pt":1646098455311,"mc":[{"id":"1.195395454","rc":[{"atb":[[2.72,17.96]],"id":40324412},{"atb":[[1.64,48.29]],"id":43066392},{"atb":[[3.35,6.48]],"id":39586887}],"con":true,"img":false}]}
{"op":"mcm","clk":"5346840059","pt":1646098455823,"mc":[{"id":"1.195395454","rc":[{"atb":[[3,4.17]],"id":37076607}],"con":true,"img":false}]}
{"op":"mcm","clk":"5346840072","pt":1646098456085,"mc":[{"id":"1.195395454","rc":[{"atb":[[2.48,31.2]],"id":40324412},{"atb":[[2.18,0]],"id":43154432}],"con":true,"img":false}]}
{"op":"mcm","clk":"5346840115","pt":1646098456905,"mc":[{"id":"1.195395454","rc":[{"atb":[[3.45,22.25],[3.25,57.72]],"id":42901530}],"con":true,"img":false}]}
{"op":"mcm","clk":"5346840124","pt":1646098457113,"mc":[{"id":"1.195395454","rc":[{"atb":[[3.55,2.92]],"id":42901530}],"con":true,"img":false}]}
{"op":"mcm","clk":"5346840173","pt":1646098458031,"mc":[{"id":"1.195395454","rc":[{"atb":[[3.45,5]],"id":42901530},{"atb":[[2.64,49.32],[2.58,0],[2.48,0]],"id":40324412},{"atl":[[3.45,0]],"id":43066392},{"atl":[[7.4,0]],"id":39586887}],"con":true,"img":false}]}
{"op":"mcm","clk":"5346840179","pt":1646098458084,"mc":[{"id":"1.195395454","rc":[{"atb":[[3.3,17.25]],"id":42901530},{"atb":[[2.44,31.2]],"id":40324412},{"atl":[[3.2,18.86]],"id":43066392},{"atl":[[9,4.82]],"id":39586887}],"con":true,"img":false}]}
{"op":"mcm","clk":"5346840227","pt":1646098459109,"mc":[{"id":"1.195395454","rc":[{"atb":[[2.2,0]],"id":43154432}],"con":true,"img":false}]}
{"op":"mcm","clk":"5346840232","pt":1646098459210,"mc":[{"id":"1.195395454","rc":[{"atb":[[2.1,105.73]],"id":43154432}],"con":true,"img":false}]}
{"op":"mcm","clk":"5346840250","pt":1646098459620,"mc":[{"id":"1.195395454","rc":[{"atb":[[3.35,25.22]],"id":39586887}],"con":true,"img":false}]}
{"op":"mcm","clk":"5346840257","pt":1646098459824,"mc":[{"id":"1.195395454","rc":[{"atb":[[3.25,2.5]],"id":39586887}],"con":true,"img":false}]}
{"op":"mcm","clk":"5346840281","pt":1646098460231,"mc":[{"id":"1.195395454","rc":[{"atb":[[3.55,0]],"id":42901530},{"atb":[[2.64,44.78]],"id":40324412}],"con":true,"img":false}]}
{"op":"mcm","clk":"5346840328","pt":1646098461416,"mc":[{"id":"1.195395454","rc":[{"atb":[[2.12,0],[2.1,37.55]],"id":43154432}],"con":true,"img":false}]}
{"op":"mcm","clk":"5346840346","pt":1646098461824,"mc":[{"id":"1.195395454","rc":[{"atb":[[2.12,17.86]],"id":43154432}],"con":true,"img":false}]}
{"op":"mcm","clk":"5346840384","pt":1646098462492,"mc":[{"id":"1.195395454","rc":[{"atb":[[2.9,97.38]],"id":37076607},{"atl":[[4.1,48.06]],"id":40612296},{"atl":[[7.2,20.16]],"id":40324412},{"atl":[[3.45,51.02]],"id":43066392},{"atb":[[2.84,67.93]],"id":39586887}],"con":true,"img":false}]}
{"op":"mcm","clk":"5346840405","pt":1646098463010,"mc":[{"id":"1.195395454","rc":[{"atb":[[2.16,13.06]],"id":43154432}],"con":true,"img":false}]}
{"op":"mcm","clk":"5346840408","pt":1646098463113,"mc":[{"id":"1.195395454","rc":[{"atb":[[1.68,10.95]],"id":43066392}],"con":true,"img":false}]}
{"op":"mcm","clk":"5346840429","pt":1646098463628,"mc":[{"id":"1.195395454","rc":[{"atb":[[2.72,46.44]],"id":40324412},{"atb":[[1.67,50.03]],"id":43066392},{"atb":[[2.98,21.34],[3.05,40.26]],"id":39586887}],"con":true,"img":false}]}
{"op":"mcm","clk":"5346840433","pt":1646098463731,"mc":[{"id":"1.195395454","rc":[{"atb":[[1.63,10]],"id":43066392}],"con":true,"img":false}]}
{"op":"mcm","clk":"5346840438","pt":1646098463835,"mc":[{"id":"1.195395454","rc":[{"atb":[[2.7,2.49]],"id":40324412}],"con":true,"img":false}]}
{"op":"mcm","clk":"5346840470","pt":1646098464503,"mc":[{"id":"1.195395454","rc":[{"atb":[[3.65,11.14]],"id":37076607}],"con":true,"img":false}]}
{"op":"mcm","clk":"5346840473","pt":1646098464606,"mc":[{"id":"1.195395454","rc":[{"atb":[[3.5,0]],"id":37076607}],"con":true,"img":false}]}
{"op":"mcm","clk":"5346840501","pt":1646098465430,"mc":[{"id":"1.195395454","rc":[{"atb":[[3.3,64.97]],"id":42901530}],"con":true,"img":false}]}
{"op":"mcm","clk":"5346840505","pt":1646098465534,"mc":[{"id":"1.195395454","rc":[{"atb":[[3.25,10]],"id":42901530}],"con":true,"img":false}]}
{"op":"mcm","clk":"5346840538","pt":1646098466104,"mc":[{"id":"1.195395454","rc":[{"atb":[[1.68,0]],"id":43066392},{"atb":[[3.45,3.03]],"id":39586887}],"con":true,"img":false}]}
{"op":"mcm","clk":"5346840572","pt":1646098466926,"mc":[{"id":"1.195395454","rc":[{"atb":[[1.64,0]],"id":43066392}],"con":true,"img":false}]}
{"op":"mcm","clk":"5346840650","pt":1646098468109,"mc":[{"id":"1.195395454","rc":[{"atl":[[3.4,45.95]],"id":40612296},{"atl":[[1.63,59.33]],"id":42845264},{"atb":[[2.98,0]],"id":39586887}],"con":true,"img":false}]}
{"op":"mcm","clk":"5346840655","pt":1646098468209,"mc":[{"id":"1.195395454","rc":[{"atl":[[3.35,16.22]],"id":40612296},{"atl":[[1.62,40.56]],"id":42845264},{"atb":[[3.1,21.34]],"id":39586887}],"con":true,"img":false}]}
{"op":"mcm","clk":"5346840659","pt":1646098468312,"mc":[{"id":"1.195395454","rc":[{"atl":[[3.35,62.17],[3.4,0]],"id":40612296},{"atl":[[1.63,0],[1.67,74.63],[1.62,99.89],[1.65,149.43]],"id":42845264}],"con":true,"img":false}]}
{"op":"mcm","clk":"5346840668","pt":1646098468518,"mc":[{"id":"1.195395454","rc":[{"atl":[[1.65,30.77]],"id":42845264}],"con":true,"img":false}]}
{"op":"mcm","clk":"5346840672","pt":1646098468620,"mc":[{"id":"1.195395454","rc":[{"atb":[[3.25,34.83],[3.05,5]],"id":39586887}],"con":true,"img":false}]}
{"op":"mcm","clk":"5346840677","pt":1646098468721,"mc":[{"id":"1.195395454","rc":[{"atb":[[3.35,18.74]],"id":39586887}],"con":true,"img":false}]}
{"op":"mcm","clk":"5346840696","pt":1646098469235,"mc":[{"id":"1.195395454","rc":[{"atb":[[3.45,0]],"id":39586887}],"con":true,"img":false}]}
{"op":"mcm","clk":"5346840703","pt":1646098469439,"mc":[{"id":"1.195395454","rc":[{"atb":[[3.35,0]],"id":39586887}],"con":true,"img":false}]}
{"op":"mcm","clk":"5346840705","pt":1646098469540,"mc":[{"id":"1.195395454","rc":[{"atb":[[3.25,64.9]],"id":39586887}],"con":true,"img":false}]}
{"op":"mcm","clk":"5346840712","pt":1646098469801,"mc":[{"id":"1.195395454","rc":[{"atb":[[2.12,0]],"id":43154432}],"con":true,"img":false}]}
{"op":"mcm","clk":"5346840742","pt":1646098470723,"mc":[{"id":"1.195395454","rc":[{"atb":[[1.64,48.29]],"id":43066392}],"con":true,"img":false}]}
{"op":"mcm","clk":"5346840752","pt":1646098471134,"mc":[{"id":"1.195395454","rc":[{"atb":[[1.64,191.99],[1.67,5]],"id":43066392},{"atb":[[3.05,64.79]],"id":39586887}],"con":true,"img":false}]}
{"op":"mcm","clk":"5346840755","pt":1646098471238,"mc":[{"id":"1.195395454","rc":[{"atb":[[3.25,32.57]],"id":39586887}],"con":true,"img":false}]}
{"op":"mcm","clk":"5346840763","pt":1646098471445,"mc":[{"id":"1.195395454","rc":[{"atb":[[2.8,0],[2.9,65.79],[2.7,0]],"id":37076607},{"atl":[[19.5,0],[9.8,0],[7.8,0],[14.5,1.48],[29,0]],"id":37076607},{"atb":[[2.8,0],[2.9,0],[2.7,0]],"id":42901530},{"atl":[[19.5,0],[9.8,0],[7.8,28.94],[14.5,0],[29,0]],"id":42901530},{"atb":[[1.45,0],[1.55,0],[1.5,250]],"id":40612296},{"atl":[[2.82,43.96],[5.1,0],[4.1,40.32],[3.55,0],[3.05,0]],"id":40612296},{"atb":[[2,0],[2.1,0],[2.2,0]],"id":40324412},{"atl":[[17.5,0],[9,0],[5.5,0],[12.5,21.19],[7,0]],"id":40324412},{"atb":[[1.2,0],[1.25,0],[1.3,0]],"id":43066392},{"atl":[[2.54,39.71],[3.85,0],[2.74,0],[3.35,34.41],[2.94,76.8]],"id":43066392},{"atb":[[1.01,0]],"id":42845264},{"atl":[[2.06,0],[2.46,0],[2.66,0],[2.26,0],[1.93,0]],"id":42845264},{"atb":[[2,0],[1.9,0],[1.95,0]],"id":43154432},{"atl":[[5.1,0],[6.2,0],[10.5,0],[8.2,0],[15.5,0]],"id":43154432},{"atb":[[2.5,0],[2.6,0],[2.7,0]],"id":39586887},{"atl":[[16.5,0],[8.6,0],[11.5,0],[23,0],[6.6,0]],"id":39586887}],"con":true,"img":false}]}
{"op":"mcm","clk":"5346840770","pt":1646098471649,"mc":[{"id":"1.195395454","rc":[{"atl":[[14.5,7.41],[15.5,22.17]],"id":37076607},{"atl":[[2.82,0]],"id":40612296},{"atl":[[5.8,5],[6,72.38]],"id":40324412},{"atl":[[2.54,0],[3,146.77],[2.94,0]],"id":43066392},{"atl":[[7.2,52.41],[6.8,8.62]],"id":39586887}],"con":true,"img":false}]}
{"op":"mcm","clk":"5346840774","pt":1646098471705,"mc":[{"id":"1.195395454","rc":[{"atl":[[3.3,34.78]],"id":40612296},{"atl":[[3,186.77]],"id":43066392}],"con":true,"img":false}]}
{"op":"mcm","clk":"5346840778","pt":1646098471808,"mc":[{"id":"1.195395454","rc":[{"atl":[[3,136.77],[3.15,55.81]],"id":43066392},{"atb":[[2.12,17.86]],"id":43154432},{"atl":[[4.5,35.71]],"id":43154432}],"con":true,"img":false}]}
{"op":"mcm","clk":"5346840792","pt":1646098472116,"mc":[{"id":"1.195395454","rc":[{"atb":[[3.4,3.1]],"id":42901530},{"atb":[[1.59,14.16]],"id":40612296},{"atb":[[2.78,4.18]],"id":40324412}],"con":true,"img":false}]}
{"op":"mcm","clk":"5346840816","pt":1646098472830,"mc":[{"id":"1.195395454","rc":[{"atb":[[3.15,14.37]],"id":39586887}],"con":true,"img":false}]}
{"op":"mcm","clk":"5346840820","pt":1646098472934,"mc":[{"id":"1.195395454","rc":[{"atb":[[3.4,41.74],[3.3,17.25]],"id":42901530}],"con":true,"img":false}]}
{"op":"mcm","clk":"5346840874","pt":1646098474015,"mc":[{"id":"1.195395454","rc":[{"atb":[[2.64,0],[2.7,41.02]],"id":40324412}],"con":true,"img":false}]}
{"op":"mcm","clk":"5346840879","pt":1646098474122,"mc":[{"id":"1.195395454","rc":[{"atb":[[2.8,66.7],[2.9,97.38],[2.7,70.63]],"id":37076607},{"atl":[[9.8,0.05],[7.8,0.08],[14.5,7.72]],"id":37076607},{"atb":[[2.8,66.7],[2.9,31.59],[2.7,70.63]],"id":42901530},{"atl":[[9.8,0.05],[7.8,29.02],[14.5,0.31]],"id":42901530},{"atb":[[1.45,266.82],[1.55,109.15],[1.5,490.14]],"id":40612296},{"atl":[[2.82,0.29],[3.55,1.69],[3.05,0.26]],"id":40612296},{"atb":[[2,120.07],[2.1,109.15],[2.2,50.02]],"id":40324412},{"atl":[[9,0.54],[5.5,0.11],[7,0.09]],"id":40324412},{"atb":[[1.2,600.35],[1.25,480.28],[1.3,200.11]],"id":43066392},{"atl":[[2.54,0.35],[2.74,0.3],[2.94,2.22]],"id":43066392},{"atb":[[1.01,30017.84]],"id":42845264},{"atl":[[2.06,0.5],[2.26,3.43],[1.93,0.58]],"id":42845264},{"atb":[[2,60.03],[1.95,126.38],[1.9,133.41]],"id":43154432},{"atl":[[5.1,0.12],[6.2,0.1],[8.2,0.6]],"id":43154432},{"atb":[[2.5,80.04],[2.6,75.04],[2.7,35.31]],"id":39586887},{"atl":[[8.6,0.07],[11.5,0.41],[6.6,0.09]],"id":39586887}],"con":true,"img":false}]}
{"op":"mcm","clk":"5346840905","pt":1646098474738,"mc":[{"id":"1.195395454","rc":[{"atb":[[1.63,23.8]],"id":40612296},{"atb":[[2.72,28.48]],"id":40324412}],"con":true,"img":false}]}
{"op":"mcm","clk":"5346840924","pt":1646098475150,"mc":[{"id":"1.195395454","rc":[{"atb":[[3.4,38.64]],"id":42901530},{"atb":[[3.3,3.24]],"id":39586887}],"con":true,"img":false}]}
{"op":"mcm","clk":"5346840942","pt":1646098475511,"mc":[{"id":"1.195395454","rc":[{"atb":[[3.3,20.48]],"id":39586887}],"con":true,"img":false}]}
{"op":"mcm","clk":"5346840948","pt":1646098475717,"mc":[{"id":"1.195395454","rc":[{"atl":[[3.45,125.83]],"id":40612296},{"atb":[[3.25,2.5]],"id":39586887}],"con":true,"img":false}]}
{"op":"mcm","clk":"5346840952","pt":1646098475816,"mc":[{"id":"1.195395454","rc":[{"atl":[[3.35,16.22]],"id":40612296}],"con":true,"img":false}]}
{"op":"mcm","clk":"5346840987","pt":1646098476634,"mc":[{"id":"1.195395454","rc":[{"atb":[[1.64,143.7]],"id":43066392}],"con":true,"img":false}]}
{"op":"mcm","clk":"5346841051","pt":1646098478023,"mc":[{"id":"1.195395454","rc":[{"atb":[[2.94,38.66]],"id":37076607},{"atb":[[3.3,0]],"id":42901530},{"atb":[[2.1,0]],"id":43154432}],"con":true,"img":false}]}
{"op":"mcm","clk":"5346841054","pt":1646098478127,"mc":[{"id":"1.195395454","rc":[{"atb":[[3.05,49.74]],"id":37076607},{"atb":[[3.45,22.25]],"id":42901530},{"atb":[[1.68,10.95]],"id":43066392},{"atb":[[2.14,44.09]],"id":43154432},{"atb":[[3.3,17.24]],"id":39586887}],"con":true,"img":false}]}
{"op":"mcm","clk":"5346841068","pt":1646098478329,"mc":[{"id":"1.195395454","rc":[{"atb":[[2.12,0]],"id":43154432}],"con":true,"img":false}]}
{"op":"mcm","clk":"5346841072","pt":1646098478434,"mc":[{"id":"1.195395454","rc":[{"atb":[[2.08,87.68]],"id":43154432}],"con":true,"img":false}]}
{"op":"mcm","clk":"5346841092","pt":1646098478944,"mc":[{"id":"1.195395454","rc":[{"atb":[[1.64,48.29]],"id":40612296},{"atb":[[2.8,8.37]],"id":40324412},{"atb":[[3.15,0]],"id":39586887}],"con":true,"img":false}]}
{"op":"mcm","clk":"5346841096","pt":1646098479045,"mc":[{"id":"1.195395454","rc":[{"atb":[[1.64,125.66],[1.63,0]],"id":40612296},{"atl":[[3,40],[3.15,100.84]],"id":43066392}],"con":true,"img":false}]}
{"op":"mcm","clk":"5346841108","pt":1646098479455,"mc":[{"id":"1.195395454","rc":[{"atb":[[2.8,18.4]],"id":40324412},{"atb":[[1.64,0],[1.67,50.03]],"id":43066392},{"atb":[[3.1,74.96],[3.05,5]],"id":39586887}],"con":true,"img":false}]}
{"op":"mcm","clk":"5346841116","pt":1646098479614,"mc":[{"id":"1.195395454","rc":[{"atb":[[2.72,0]],"id":40324412}],"con":true,"img":false}]}
{"op":"mcm","clk":"5346841159","pt":1646098480841,"mc":[{"id":"1.195395454","rc":[{"atb":[[1.72,38.11]],"id":43066392},{"atb":[[2.16,0]],"id":43154432}],"con":true,"img":false}]}
{"op":"mcm","clk":"5346841162","pt":1646098480942,"mc":[{"id":"1.195395454","rc":[{"atb":[[1.72,48]],"id":43066392}],"con":true,"img":false}]}
{"op":"mcm","clk":"5346841167","pt":1646098481148,"mc":[{"id":"1.195395454","rc":[{"atb":[[1.71,2.5]],"id":43066392}],"con":true,"img":false}]}
{"op":"mcm","clk":"5346841169","pt":1646098481251,"mc":[{"id":"1.195395454","rc":[{"atb":[[3.05,46.11]],"id":37076607},{"atb":[[2.78,0]],"id":40324412},{"atb":[[1.68,0]],"id":43066392},{"atb":[[2.14,37.55]],"id":43154432}],"con":true,"img":false}]}
{"op":"mcm","clk":"5346841179","pt":1646098481456,"mc":[{"id":"1.195395454","rc":[{"atb":[[2.62,63.62],[2.7,2.49]],"id":40324412}],"con":true,"img":false}]}
{"op":"mcm","clk":"5346841192","pt":1646098481765,"mc":[{"id":"1.195395454","rc":[{"atb":[[2.12,17.86]],"id":43154432}],"con":true,"img":false}]}
{"op":"mcm","clk":"5346841243","pt":1646098482946,"mc":[{"id":"1.195395454","rc":[{"atb":[[3.35,13.14]],"id":39586887}],"con":true,"img":false}]}
{"op":"mcm","clk":"5346841288","pt":1646098484127,"mc":[{"id":"1.195395454","rc":[{"atl":[[1.67,244.4]],"id":42845264}],"con":true,"img":false}]}
{"op":"mcm","clk":"5346841299","pt":1646098484432,"mc":[{"id":"1.195395454","rc":[{"atb":[[3.1,21.34],[3.25,48.08]],"id":39586887}],"con":true,"img":false}]}
{"op":"mcm","clk":"5346841323","pt":1646098485148,"mc":[{"id":"1.195395454","rc":[{"atb":[[2.8,10.03]],"id":40324412},{"atb":[[2.16,26.64]],"id":43154432}],"con":true,"img":false}]}
{"op":"mcm","clk":"5346841327","pt":1646098485250,"mc":[{"id":"1.195395454","rc":[{"atb":[[3.35,35.93]],"id":39586887}],"con":true,"img":false}]}
{"op":"mcm","clk":"5346841331","pt":1646098485354,"mc":[{"id":"1.195395454","rc":[{"atb":[[2.8,0]],"id":40324412}],"con":true,"img":false}]}
{"op":"mcm","clk":"5346841335","pt":1646098485456,"mc":[{"id":"1.195395454","rc":[{"atb":[[1.59,0]],"id":40612296},{"atb":[[2.7,13.76]],"id":40324412},{"atb":[[3.3,0]],"id":39586887}],"con":true,"img":false}]}
{"op":"mcm","clk":"5346841370","pt":1646098486435,"mc":[{"id":"1.195395454","rc":[{"atb":[[2.12,0],[2.08,18.52]],"id":43154432}],"con":true,"img":false}]}
{"op":"mcm","clk":"5346841381","pt":1646098486744,"mc":[{"id":"1.195395454","rc":[{"atb":[[3.1,107.28],[3.25,2.5]],"id":39586887}],"con":true,"img":false}]}
{"op":"mcm","clk":"5346841399","pt":1646098487155,"mc":[{"id":"1.195395454","rc":[{"atb":[[3.1,3.54]],"id":37076607},{"atb":[[3.55,2.92]],"id":42901530},{"atb":[[1.68,10.95]],"id":40612296},{"atb":[[2.18,6.31]],"id":43154432}],"con":true,"img":false}]}
{"op":"mcm","clk":"5346841404","pt":1646098487258,"mc":[{"id":"1.195395454","rc":[{"atb":[[3.45,69.97]],"id":42901530}],"con":true,"img":false}]}
{"op":"mcm","clk":"5346841409","pt":1646098487359,"mc":[{"id":"1.195395454","rc":[{"atb":[[3.4,0]],"id":42901530}],"con":true,"img":false}]}
{"op":"mcm","clk":"5346841412","pt":1646098487461,"mc":[{"id":"1.195395454","rc":[{"atl":[[3.25,11.97]],"id":40612296},{"atl":[[2.94,5.77]],"id":43066392}],"con":true,"img":false}]}
{"op":"mcm","clk":"5346841416","pt":1646098487564,"mc":[{"id":"1.195395454","rc":[{"atl":[[3.35,56.63],[3.3,0]],"id":40612296},{"atl":[[3,0]],"id":43066392}],"con":true,"img":false}]}
{"op":"mcm","clk":"5346841419","pt":1646098487666,"mc":[{"id":"1.195395454","rc":[{"atl":[[3.45,40.82]],"id":40612296}],"con":true,"img":false}]}
{"op":"mcm","clk":"5346841424","pt":1646098487770,"mc":[{"id":"1.195395454","rc":[{"atl":[[3.35,16.22]],"id":40612296},{"atl":[[3.2,113.18],[3.15,55.81]],"id":43066392}],"con":true,"img":false}]}
{"op":"mcm","clk":"5346841441","pt":1646098488031,"mc":[{"id":"1.195395454","rc":[{"atb":[[1.6,0]],"id":40612296},{"atl":[[3.35,0]],"id":40612296},{"atl":[[3.2,94.32]],"id":43066392}],"con":true,"img":false}]}
{"op":"mcm","clk":"5346841446","pt":1646098488133,"mc":[{"id":"1.195395454","rc":[{"atb":[[1.58,40.56]],"id":40612296},{"atl":[[3.4,16.22]],"id":40612296},{"atl":[[3.1,18.86]],"id":43066392}],"con":true,"img":false}]}
{"op":"mcm","clk":"5346841467","pt":1646098488747,"mc":[{"id":"1.195395454","rc":[{"atb":[[2.54,61.68],[2.62,5]],"id":40324412}],"con":true,"img":false}]}
{"op":"mcm","clk":"5346841489","pt":1646098489161,"mc":[{"id":"1.195395454","rc":[{"atb":[[2.56,19.8]],"id":40324412},{"atb":[[3.35,22.79]],"id":39586887}],"con":true,"img":false}]}
{"op":"mcm","clk":"5346841503","pt":1646098489364,"mc":[{"id":"1.195395454","rc":[{"atb":[[3.35,0]],"id":39586887}],"con":true,"img":false}]}
{"op":"mcm","clk":"5346841510","pt":1646098489466,"mc":[{"id":"1.195395454","rc":[{"atb":[[3.25,22.85]],"id":39586887}],"con":true,"img":false}]}
{"op":"mcm","clk":"5346841517","pt":1646098489672,"mc":[{"id":"1.195395454","rc":[{"atb":[[2.56,70.17]],"id":40324412},{"atb":[[2.12,17.86]],"id":43154432}],"con":true,"img":false}]}
{"op":"mcm","clk":"5346841522","pt":1646098489724,"mc":[{"id":"1.195395454","rc":[{"atb":[[2.54,10]],"id":40324412}],"con":true,"img":false}]}
{"op":"mcm","clk":"5346841533","pt":1646098490240,"mc":[{"id":"1.195395454","rc":[{"atb":[[1.76,9.8]],"id":43066392}],"con":true,"img":false}]}
{"op":"mcm","clk":"5346841537","pt":1646098490339,"mc":[{"id":"1.195395454","rc":[{"atb":[[1.71,45.5],[1.67,5]],"id":43066392}],"con":true,"img":false}]}
{"op":"mcm","clk":"5346841558","pt":1646098491059,"mc":[{"id":"1.195395454","rc":[{"atb":[[1.64,77.37]],"id":40612296},{"atb":[[1.72,9.89]],"id":43066392},{"atb":[[2.16,0]],"id":43154432}],"con":true,"img":false}]}
{"op":"mcm","clk":"5346841571","pt":1646098491368,"mc":[{"id":"1.195395454","rc":[{"atl":[[3.45,81.23]],"id":40612296}],"con":true,"img":false}]}
{"op":"mcm","clk":"5346841584","pt":1646098491676,"mc":[{"id":"1.195395454","rc":[{"atb":[[3,0]],"id":37076607},{"atb":[[2.18,13.38]],"id":43154432}],"con":true,"img":false}]}
{"op":"mcm","clk":"5346841588","pt":1646098491736,"mc":[{"id":"1.195395454","rc":[{"atb":[[3.1,21.34],[3.05,67.04]],"id":39586887}],"con":true,"img":false}]}
{"op":"mcm","clk":"5346841622","pt":1646098493068,"mc":[{"id":"1.195395454","rc":[{"atb":[[3.15,14.37]],"id":39586887}],"con":true,"img":false}]}
{"op":"mcm","clk":"5346841670","pt":1646098494049,"mc":[{"id":"1.195395454","rc":[{"atb":[[2.12,86.04]],"id":43154432}],"con":true,"img":false}]}
{"op":"mcm","clk":"5346841675","pt":1646098494149,"mc":[{"id":"1.195395454","rc":[{"atb":[[1.76,0]],"id":43066392}],"con":true,"img":false}]}
{"op":"mcm","clk":"5346841691","pt":1646098494561,"mc":[{"id":"1.195395454","rc":[{"atb":[[1.66,45.41]],"id":40612296},{"atl":[[3.2,0],[3.15,98.95]],"id":43066392}],"con":true,"img":false}]}
{"op":"mcm","clk":"5346841695","pt":1646098494662,"mc":[{"id":"1.195395454","rc":[{"atb":[[1.64,0]],"id":40612296}],"con":true,"img":false}]}
{"op":"mcm","clk":"5346841704","pt":1646098494973,"mc":[{"id":"1.195395454","rc":[{"atb":[[3.1,81.13],[3.05,5]],"id":39586887}],"con":true,"img":false}]}
{"op":"mcm","clk":"5346841715","pt":1646098495348,"mc":[{"id":"1.195395454","rc":[{"atb":[[1.71,28.8]],"id":40612296},{"atb":[[1.73,29.41]],"id":43066392},{"atb":[[2.2,25.75]],"id":43154432}],"con":true,"img":false}]}
{"op":"mcm","clk":"5346841721","pt":1646098495441,"mc":[{"id":"1.195395454","rc":[{"atb":[[1.71,46]],"id":40612296},{"atb":[[2.12,17.85]],"id":43154432}],"con":true,"img":false}]}
{"op":"mcm","clk":"5346841730","pt":1646098495645,"mc":[{"id":"1.195395454","rc":[{"atb":[[1.7,2.5]],"id":40612296}],"con":true,"img":false}]}
{"op":"mcm","clk":"5346841759","pt":1646098496463,"mc":[{"id":"1.195395454","rc":[{"atb":[[1.73,41.16]],"id":43066392}],"con":true,"img":false}]}
{"op":"mcm","clk":"5346841765","pt":1646098496669,"mc":[{"id":"1.195395454","rc":[{"atb":[[1.72,0]],"id":43066392}],"con":true,"img":false}]}
{"op":"mcm","clk":"5346841782","pt":1646098497182,"mc":[{"id":"1.195395454","rc":[{"atb":[[1.68,0]],"id":40612296},{"atb":[[2.62,9.59]],"id":40324412},{"atb":[[3.3,3.24]],"id":39586887}],"con":true,"img":false}]}
{"op":"mcm","clk":"5346841792","pt":1646098497342,"mc":[{"id":"1.195395454","rc":[{"atb":[[3.3,20.48]],"id":39586887}],"con":true,"img":false}]}
{"op":"mcm","clk":"5346841797","pt":1646098497441,"mc":[{"id":"1.195395454","rc":[{"atb":[[3.1,7.52]],"id":37076607}],"con":true,"img":false}]}
{"op":"mcm","clk":"5346841801","pt":1646098497545,"mc":[{"id":"1.195395454","rc":[{"atb":[[1.67,95.04]],"id":43066392},{"atb":[[3.25,2.49]],"id":39586887}],"con":true,"img":false}]}
{"op":"mcm","clk":"5346841807","pt":1646098497646,"mc":[{"id":"1.195395454","rc":[{"atb":[[1.71,2.5]],"id":43066392}],"con":true,"img":false}]}
{"op":"mcm","clk":"5346841815","pt":1646098497955,"mc":[{"id":"1.195395454","rc":[{"atb":[[3.45,52.72]],"id":42901530},{"atl":[[7.6,0],[6.6,7.24]],"id":40324412},{"atl":[[1.62,59.33]],"id":42845264}],"con":true,"img":false}]}
{"op":"mcm","clk":"5346841820","pt":1646098498061,"mc":[{"id":"1.195395454","rc":[{"atb":[[3.5,17.25]],"id":42901530},{"atl":[[1.61,40.56]],"id":42845264}],"con":true,"img":false}]}
{"op":"mcm","clk":"5346841824","pt":1646098498161,"mc":[{"id":"1.195395454","rc":[{"atb":[[3.5,64.97],[3.45,5]],"id":42901530},{"atl":[[1.62,0],[1.61,99.89]],"id":42845264}],"con":true,"img":false}]}
{"op":"mcm","clk":"5346841862","pt":1646098499140,"mc":[{"id":"1.195395454","rc":[{"atb":[[1.73,11.75]],"id":43066392}],"con":true,"img":false}]}
{"op":"mcm","clk":"5346841872","pt":1646098499348,"mc":[{"id":"1.195395454","rc":[{"atb":[[1.73,0]],"id":43066392}],"con":true,"img":false}]}
{"op":"mcm","clk":"5346841879","pt":1646098499451,"mc":[{"id":"1.195395454","rc":[{"atb":[[1.71,8.71]],"id":43066392}],"con":true,"img":false}]}
{"op":"mcm","clk":"5346841889","pt":1646098499655,"mc":[{"id":"1.195395454","rc":[{"atb":[[2.08,46.3]],"id":43154432}],"con":true,"img":false}]}
{"op":"mcm","clk":"5346841895","pt":1646098499860,"mc":[{"id":"1.195395454","rc":[{"atb":[[3.1,21.34],[3.15,63.69]],"id":39586887}],"con":true,"img":false}]}
{"op":"mcm","clk":"5346841904","pt":1646098500270,"mc":[{"id":"1.195395454","rc":[{"atb":[[3.55,0]],"id":42901530},{"atb":[[3.3,17.24]],"id":39586887}],"con":true,"img":false}]}
{"op":"mcm","clk":"5346841936","pt":1646098501045,"mc":[{"id":"1.195395454","rc":[{"atb":[[1.71,17.2]],"id":40612296},{"atb":[[3.15,49.32]],"id":39586887}],"con":true,"img":false}]}
{"op":"mcm","clk":"5346841943","pt":1646098501249,"mc":[{"id":"1.195395454","rc":[{"atb":[[1.01,1]],"id":39586887}],"con":true,"img":false}]}
{"op":"mcm","clk":"5346841998","pt":1646098502742,"mc":[{"id":"1.195395454","rc":[{"atl":[[3.2,10.85]],"id":40612296}],"con":true,"img":false}]}
{"op":"mcm","clk":"5346842003","pt":1646098502952,"mc":[{"id":"1.195395454","rc":[{"atl":[[3.45,40.82],[3.4,58.52],[3.25,0]],"id":40612296},{"atb":[[1.64,34.83]],"id":43066392}],"con":true,"img":false}]}
{"op":"mcm","clk":"5346842012","pt":1646098503255,"mc":[{"id":"1.195395454","rc":[{"atb":[[2.08,64.82]],"id":43154432}],"con":true,"img":false}]}
{"op":"mcm","clk":"5346842016","pt":1646098503361,"mc":[{"id":"1.195395454","rc":[{"atb":[[2.12,0],[2.08,18.52]],"id":43154432}],"con":true,"img":false}]}
{"op":"mcm","clk":"5346842029","pt":1646098503869,"mc":[{"id":"1.195395454","rc":[{"atb":[[2.12,17.86]],"id":43154432}],"con":true,"img":false}]}
{"op":"mcm","clk":"5346842033","pt":1646098503975,"mc":[{"id":"1.195395454","rc":[{"atb":[[2.62,14.75]],"id":40324412}],"con":true,"img":false}]}
{"op":"mcm","clk":"5346842053","pt":1646098504745,"mc":[{"id":"1.195395454","rc":[{"atb":[[1.64,115.4],[1.67,5]],"id":43066392}],"con":true,"img":false}]}
{"op":"mcm","clk":"5346842064","pt":1646098505054,"mc":[{"id":"1.195395454","rc":[{"atb":[[1.67,46.12]],"id":40612296},{"atb":[[3.35,13.14]],"id":39586887}],"con":true,"img":false}]}
{"op":"mcm","clk":"5346842067","pt":1646098505156,"mc":[{"id":"1.195395454","rc":[{"atb":[[3.35,29.47],[3.25,48.08],[3.15,0]],"id":39586887}],"con":true,"img":false}]}
{"op":"mcm","clk":"5346842071","pt":1646098505258,"mc":[{"id":"1.195395454","rc":[{"atb":[[3.6,2.86]],"id":42901530},{"atb":[[3.2,3.38]],"id":39586887}],"con":true,"img":false}]}
{"op":"mcm","clk":"5346842075","pt":1646098505361,"mc":[{"id":"1.195395454","rc":[{"atb":[[3.45,52.72]],"id":42901530},{"atb":[[3.3,0]],"id":39586887}],"con":true,"img":false}]}
{"op":"mcm","clk":"5346842080","pt":1646098505465,"mc":[{"id":"1.195395454","rc":[{"atb":[[3.5,17.25]],"id":42901530}],"con":true,"img":false}]}
{"op":"mcm","clk":"5346842082","pt":1646098505564,"mc":[{"id":"1.195395454","rc":[{"atb":[[3.45,5]],"id":42901530}],"con":true,"img":false}]}
{"op":"mcm","clk":"5346842132","pt":1646098506959,"mc":[{"id":"1.195395454","rc":[{"atb":[[3.25,2.5],[3.2,75.36]],"id":39586887}],"con":true,"img":false}]}
{"op":"mcm","clk":"5346842164","pt":1646098508083,"mc":[{"id":"1.195395454","rc":[{"atb":[[3.5,0]],"id":42901530},{"atl":[[4.7,0]],"id":40612296},{"atb":[[2.14,0]],"id":43154432},{"atb":[[3.1,0]],"id":39586887}],"con":true,"img":false}]}
{"op":"mcm","clk":"5346842168","pt":1646098508187,"mc":[{"id":"1.195395454","rc":[{"atb":[[3.3,17.25]],"id":42901530},{"atl":[[5.4,37.16]],"id":40612296},{"atb":[[2.22,37.55]],"id":43154432},{"atb":[[2.98,21.34]],"id":39586887}],"con":true,"img":false}]}
{"op":"mcm","clk":"5346842197","pt":1646098509268,"mc":[{"id":"1.195395454","rc":[{"atb":[[3.6,0]],"id":42901530},{"atb":[[2.18,7.07]],"id":43154432},{"atb":[[3.2,71.98]],"id":39586887}],"con":true,"img":false}]}
{"op":"mcm","clk":"5346842216","pt":1646098509878,"mc":[{"id":"1.195395454","rc":[{"atb":[[1.67,133.15]],"id":40612296}],"con":true,"img":false}]}
{"op":"mcm","clk":"5346842219","pt":1646098509981,"mc":[{"id":"1.195395454","rc":[{"atb":[[1.59,14.16],[1.66,5]],"id":40612296}],"con":true,"img":false}]}
{"op":"mcm","clk":"5346842221","pt":1646098510086,"mc":[{"id":"1.195395454","rc":[{"atl":[[3.45,127.85],[3.4,16.22]],"id":40612296}],"con":true,"img":false}]}
{"op":"mcm","clk":"5346842249","pt":1646098510859,"mc":[{"id":"1.195395454","rc":[{"atb":[[2.2,0]],"id":43154432}],"con":true,"img":false}]}
{"op":"mcm","clk":"5346842253","pt":1646098510961,"mc":[{"id":"1.195395454","rc":[{"atb":[[2.12,86.04]],"id":43154432}],"con":true,"img":false}]}
{"op":"mcm","clk":"5346842263","pt":1646098511163,"mc":[{"id":"1.195395454","rc":[{"atb":[[1.68,10.95]],"id":43066392}],"con":true,"img":false}]}
{"op":"mcm","clk":"5346842273","pt":1646098511268,"mc":[{"id":"1.195395454","rc":[{"atb":[[1.67,34.51]],"id":43066392}],"con":true,"img":false}]}
{"op":"mcm","clk":"5346842279","pt":1646098511370,"mc":[{"id":"1.195395454","rc":[{"atb":[[1.64,34.83]],"id":43066392}],"con":true,"img":false}]}
{"op":"mcm","clk":"5346842352","pt":1646098513369,"mc":[{"id":"1.195395454","rc":[{"atb":[[3.3,64.97]],"id":42901530}],"con":true,"img":false}]}
{"op":"mcm","clk":"5346842383","pt":1646098514293,"mc":[{"id":"1.195395454","rc":[{"atb":[[1.71,27.68]],"id":40612296},{"atb":[[1.68,0]],"id":43066392},{"atb":[[2.28,5.81]],"id":43154432},{"atb":[[3.45,3.03]],"id":39586887}],"con":true,"img":false}]}
{"op":"mcm","clk":"5346842387","pt":1646098514396,"mc":[{"id":"1.195395454","rc":[{"atb":[[1.64,114.9],[1.67,5]],"id":43066392},{"atb":[[2.12,17.85]],"id":43154432},{"atb":[[3.25,43.34],[3.45,11.78],[3.2,0]],"id":39586887}],"con":true,"img":false}]}
{"op":"mcm","clk":"5346842400","pt":1646098514602,"mc":[{"id":"1.195395454","rc":[{"atb":[[3.35,13.14]],"id":39586887}],"con":true,"img":false}]}
{"op":"mcm","clk":"5346842410","pt":1646098514864,"mc":[{"id":"1.195395454","rc":[{"atb":[[1.64,80.07]],"id":43066392},{"atb":[[2.14,27.11],[2.08,46.3]],"id":43154432}],"con":true,"img":false}]}
{"op":"mcm","clk":"5346842479","pt":1646098516765,"mc":[{"id":"1.195395454","rc":[{"atb":[[3.35,0]],"id":39586887}],"con":true,"img":false}]}
{"op":"mcm","clk":"5346842494","pt":1646098517071,"mc":[{"id":"1.195395454","rc":[{"atl":[[8.6,0],[8.2,13.89]],"id":42901530},{"atl":[[2.92,18.87],[3.15,52.44]],"id":43066392},{"atb":[[2.12,0],[2.08,18.52]],"id":43154432}],"con":true,"img":false}]}
{"op":"mcm","clk":"5346842498","pt":1646098517173,"mc":[{"id":"1.195395454","rc":[{"atl":[[2.92,29.15],[3.1,60.23],[3.15,9.3]],"id":43066392},{"atb":[[3.45,8.75]],"id":39586887}],"con":true,"img":false}]}
{"op":"mcm","clk":"5346842507","pt":1646098517376,"mc":[{"id":"1.195395454","rc":[{"atl":[[2.94,2.22]],"id":43066392},{"atb":[[3.45,0]],"id":39586887}],"con":true,"img":false}]}
{"op":"mcm","clk":"5346842509","pt":1646098517479,"mc":[{"id":"1.195395454","rc":[{"atb":[[3.25,53.56]],"id":39586887}],"con":true,"img":false}]}
{"op":"mcm","clk":"5346842518","pt":1646098517788,"mc":[{"id":"1.195395454","rc":[{"atb":[[2.12,17.86]],"id":43154432}],"con":true,"img":false}]}
{"op":"mcm","clk":"5346842522","pt":1646098517891,"mc":[{"id":"1.195395454","rc":[{"atl":[[3.15,10.01]],"id":40612296}],"con":true,"img":false}]}
{"op":"mcm","clk":"5346842528","pt":1646098518094,"mc":[{"id":"1.195395454","rc":[{"atl":[[3.45,40.82],[3.2,0],[3.4,56.84]],"id":40612296},{"atl":[[6.6,0]],"id":40324412},{"atb":[[2.22,0]],"id":43154432}],"con":true,"img":false}]}
{"op":"mcm","clk":"5346842530","pt":1646098518196,"mc":[{"id":"1.195395454","rc":[{"atl":[[5.9,7.24]],"id":40324412},{"atb":[[2.16,37.55]],"id":43154432}],"con":true,"img":false}]}
{"op":"mcm","clk":"5346842533","pt":1646098518299,"mc":[{"id":"1.195395454","rc":[{"atl":[[6,24],[5.9,50.02]],"id":40324412}],"con":true,"img":false}]}
{"op":"mcm","clk":"5346842555","pt":1646098518869,"mc":[{"id":"1.195395454","rc":[{"atb":[[1.65,32.66]],"id":43066392},{"atb":[[2.14,0]],"id":43154432}],"con":true,"img":false}]}
{"op":"mcm","clk":"5346842584","pt":1646098519790,"mc":[{"id":"1.195395454","rc":[{"atb":[[1.64,0],[1.65,90.44]],"id":43066392}],"con":true,"img":false}]}
{"op":"mcm","clk":"5346842597","pt":1646098520203,"mc":[{"id":"1.195395454","rc":[{"atb":[[3.4,3.1]],"id":42901530}],"con":true,"img":false}]}
{"op":"mcm","clk":"5346842602","pt":1646098520303,"mc":[{"id":"1.195395454","rc":[{"atb":[[2.28,0]],"id":43154432}],"con":true,"img":false}]}
{"op":"mcm","clk":"5346842604","pt":1646098520405,"mc":[{"id":"1.195395454","rc":[{"atb":[[3.3,17.25],[3.4,41.74]],"id":42901530}],"con":true,"img":false}]}
{"op":"mcm","clk":"5346842629","pt":1646098520972,"mc":[{"id":"1.195395454","rc":[{"atb":[[1.67,87.03]],"id":40612296},{"atb":[[3.1,14.71]],"id":39586887}],"con":true,"img":false}]}
{"op":"mcm","clk":"5346842641","pt":1646098521384,"mc":[{"id":"1.195395454","rc":[{"atb":[[3.25,12.71],[3.05,54.83]],"id":39586887}],"con":true,"img":false}]}
{"op":"mcm","clk":"5346842645","pt":1646098521485,"mc":[{"id":"1.195395454","rc":[{"atb":[[2.18,0]],"id":43154432}],"con":true,"img":false}]}
{"op":"mcm","clk":"5346842694","pt":1646098522975,"mc":[{"id":"1.195395454","rc":[{"atb":[[2.2,14.15]],"id":43154432}],"con":true,"img":false}]}
{"op":"mcm","clk":"5346842704","pt":1646098523280,"mc":[{"id":"1.195395454","rc":[{"atb":[[3.4,38.64]],"id":42901530}],"con":true,"img":false}]}
{"op":"mcm","clk":"5346842719","pt":1646098523689,"mc":[{"id":"1.195395454","rc":[{"atb":[[2.12,0]],"id":43154432}],"con":true,"img":false}]}
{"op":"mcm","clk":"5346842728","pt":1646098523899,"mc":[{"id":"1.195395454","rc":[{"atb":[[2.12,17.86]],"id":43154432}],"con":true,"img":false}]}
{"op":"mcm","clk":"5346842760","pt":1646098525078,"mc":[{"id":"1.195395454","rc":[{"atb":[[1.68,45.44]],"id":40612296},{"atl":[[3.45,136.03],[3.4,16.22]],"id":40612296}],"con":true,"img":false}]}
{"op":"mcm","clk":"5346842765","pt":1646098525183,"mc":[{"id":"1.195395454","rc":[{"atb":[[1.68,111.32]],"id":40612296}],"con":true,"img":false}]}
{"op":"mcm","clk":"5346842771","pt":1646098525290,"mc":[{"id":"1.195395454","rc":[{"atb":[[1.67,0]],"id":40612296}],"con":true,"img":false}]}
{"op":"mcm","clk":"5346842791","pt":1646098525902,"mc":[{"id":"1.195395454","rc":[{"atb":[[2.12,86.04]],"id":43154432}],"con":true,"img":false}]}
{"op":"mcm","clk":"5346842803","pt":1646098526210,"mc":[{"id":"1.195395454","rc":[{"atb":[[1.69,10.79]],"id":43066392},{"atb":[[2.2,20.36]],"id":43154432}],"con":true,"img":false}]}
{"op":"mcm","clk":"5346842806","pt":1646098526313,"mc":[{"id":"1.195395454","rc":[{"atb":[[1.71,17.2]],"id":40612296}],"con":true,"img":false}]}
{"op":"mcm","clk":"5346842811","pt":1646098526417,"mc":[{"id":"1.195395454","rc":[{"atb":[[1.67,34.25],[1.65,32.66]],"id":43066392}],"con":true,"img":false}]}
{"op":"mcm","clk":"5346842842","pt":1646098527393,"mc":[{"id":"1.195395454","rc":[{"atb":[[1.59,0]],"id":40612296}],"con":true,"img":false}]}
{"op":"mcm","clk":"5346842867","pt":1646098528011,"mc":[{"id":"1.195395454","rc":[{"atb":[[3.3,0]],"id":42901530},{"atl":[[8.2,19.89],[8.4,16.89]],"id":42901530},{"atl":[[4.5,0]],"id":43066392},{"atl":[[1.61,59.33]],"id":42845264},{"atl":[[5.3,0]],"id":43154432}],"con":true,"img":false}]}
{"op":"mcm","clk":"5346842875","pt":1646098528113,"mc":[{"id":"1.195395454","rc":[{"atb":[[3.45,22.25]],"id":42901530},{"atl":[[5.1,57.25]],"id":43066392},{"atl":[[1.6,40.56],[1.61,0]],"id":42845264},{"atl":[[4.4,9.43]],"id":43154432}],"con":true,"img":false}]}
{"op":"mcm","clk":"5346842879","pt":1646098528215,"mc":[{"id":"1.195395454","rc":[{"atl":[[1.65,104.18]],"id":42845264}],"con":true,"img":false}]}
{"op":"mcm","clk":"5346842917","pt":1646098528992,"mc":[{"id":"1.195395454","rc":[{"atl":[[8,15.71],[7.2,18.63],[7.6,7.58]],"id":42901530},{"atb":[[1.65,0]],"id":43066392},{"atb":[[1.09,2.5],[1.08,36.05],[1.05,12.5],[1.04,72.1]],"id":42845264}],"con":true,"img":false}]}
{"op":"mcm","clk":"5346842920","pt":1646098529095,"mc":[{"id":"1.195395454","rc":[{"atb":[[1.09,59.96],[1.05,127.42]],"id":42845264}],"con":true,"img":false}]}
{"op":"mcm","clk":"5346842928","pt":1646098529198,"mc":[{"id":"1.195395454","rc":[{"atb":[[1.69,0]],"id":43066392},{"atb":[[1.04,0]],"id":42845264},{"atb":[[3.1,18.25]],"id":39586887}],"con":true,"img":false}]}
{"op":"mcm","clk":"5346842932","pt":1646098529301,"mc":[{"id":"1.195395454","rc":[{"atb":[[1.63,69.72],[1.67,5]],"id":43066392},{"atb":[[1.08,0]],"id":42845264}],"con":true,"img":false}]}
{"op":"mcm","clk":"5346842959","pt":1646098530025,"mc":[{"id":"1.195395454","rc":[{"atb":[[2.12,0]],"id":43154432}],"con":true,"img":false}]}
{"op":"mcm","clk":"5346842984","pt":1646098530593,"mc":[{"id":"1.195395454","rc":[{"atb":[[2.12,17.86]],"id":43154432}],"con":true,"img":false}]}
{"op":"mcm","clk":"5346843050","pt":1646098532187,"mc":[{"id":"1.195395454","rc":[{"atb":[[1.72,10.34]],"id":40612296}],"con":true,"img":false}]}
{"op":"mcm","clk":"5346843057","pt":1646098532292,"mc":[{"id":"1.195395454","rc":[{"atb":[[1.72,19.72]],"id":40612296}],"con":true,"img":false}]}
{"op":"mcm","clk":"5346843067","pt":1646098532494,"mc":[{"id":"1.195395454","rc":[{"atb":[[1.71,0]],"id":40612296},{"atb":[[2.1,18.18]],"id":43154432},{"atl":[[3.85,7.02]],"id":43154432}],"con":true,"img":false}]}
{"op":"mcm","clk":"5346843072","pt":1646098532594,"mc":[{"id":"1.195395454","rc":[{"atb":[[2.12,0]],"id":43154432},{"atl":[[3.8,35.59],[4,0],[3.95,57.33]],"id":43154432}],"con":true,"img":false}]}
{"op":"mcm","clk":"5346843074","pt":1646098532700,"mc":[{"id":"1.195395454","rc":[{"atl":[[3.1,2.1]],"id":40612296},{"atl":[[3.9,0]],"id":43154432}],"con":true,"img":false}]}
{"op":"mcm","clk":"5346843078","pt":1646098532802,"mc":[{"id":"1.195395454","rc":[{"atl":[[3.75,7.27]],"id":40612296},{"atb":[[3.45,2.5]],"id":39586887}],"con":true,"img":false}]}
{"op":"mcm","clk":"5346843085","pt":1646098532903,"mc":[{"id":"1.195395454","rc":[{"atl":[[3.45,40.82],[3.4,55.58],[3.15,0]],"id":40612296},{"atb":[[1.64,34.83]],"id":43066392},{"atb":[[1.05,119.92]],"id":42845264},{"atb":[[3.1,64.72],[3.05,5],[3.45,18.5]],"id":39586887}],"con":true,"img":false}]}
{"op":"mcm","clk":"5346843094","pt":1646098533107,"mc":[{"id":"1.195395454","rc":[{"atb":[[3.25,2.49]],"id":39586887}],"con":true,"img":false}]}
{"op":"mcm","clk":"5346843104","pt":1646098533415,"mc":[{"id":"1.195395454","rc":[{"atb":[[3.5,3.34]],"id":42901530}],"con":true,"img":false}]}
{"op":"mcm","clk":"5346843109","pt":1646098533519,"mc":[{"id":"1.195395454","rc":[{"atb":[[3.45,73.71],[3.4,0]],"id":42901530}],"con":true,"img":false}]}
{"op":"mcm","clk":"5346843116","pt":1646098533622,"mc":[{"id":"1.195395454","rc":[{"atb":[[2.2,27.32]],"id":43154432}],"con":true,"img":false}]}
{"op":"mcm","clk":"5346843149","pt":1646098534496,"mc":[{"id":"1.195395454","rc":[{"atb":[[1.64,92.61],[1.63,10]],"id":43066392}],"con":true,"img":false}]}
{"op":"mcm","clk":"5346843158","pt":1646098534802,"mc":[{"id":"1.195395454","rc":[{"atb":[[1.68,65.88]],"id":40612296},{"atb":[[2.2,13.16]],"id":43154432},{"atb":[[3.1,50.01]],"id":39586887}],"con":true,"img":false}]}
{"op":"mcm","clk":"5346843168","pt":1646098535211,"mc":[{"id":"1.195395454","rc":[{"atb":[[3.55,2.92]],"id":42901530},{"atb":[[3.1,46.47]],"id":39586887}],"con":true,"img":false}]}
{"op":"mcm","clk":"5346843171","pt":1646098535316,"mc":[{"id":"1.195395454","rc":[{"atb":[[3.5,38.23],[3.45,22.25]],"id":42901530}],"con":true,"img":false}]}
{"op":"mcm","clk":"5346843194","pt":1646098535928,"mc":[{"id":"1.195395454","rc":[{"atb":[[1.02,1276.55],[1.05,5]],"id":42845264}],"con":true,"img":false}]}
{"op":"mcm","clk":"5346843234","pt":1646098536800,"mc":[{"id":"1.195395454","rc":[{"atb":[[1.03,224.83]],"id":42845264}],"con":true,"img":false}]}
{"op":"mcm","clk":"5346843272","pt":1646098537728,"mc":[{"id":"1.195395454","rc":[{"atl":[[3.95,91.23],[3.8,28.57]],"id":43154432}],"con":true,"img":false}]}
{"op":"mcm","clk":"5346843281","pt":1646098537992,"mc":[{"id":"1.195395454","rc":[{"atb":[[2.82,0]],"id":42901530},{"atl":[[3.1,41.37]],"id":43066392},{"atl":[[1.6,0]],"id":42845264},{"atb":[[2.16,0]],"id":43154432},{"atb":[[2.98,0],[2.62,0]],"id":39586887}],"con":true,"img":false}]}
{"op":"mcm","clk":"5346843284","pt":1646098538093,"mc":[{"id":"1.195395454","rc":[{"atb":[[2.72,40.35]],"id":42901530},{"atl":[[3.2,18.86]],"id":43066392},{"atl":[[1.64,40.56],[1.69,308.61]],"id":42845264},{"atb":[[2.12,37.55]],"id":43154432},{"atb":[[2.52,35.72],[3.15,21.34]],"id":39586887}],"con":true,"img":false}]}
{"op":"mcm","clk":"5346843287","pt":1646098538194,"mc":[{"id":"1.195395454","rc":[{"atb":[[3.55,0]],"id":42901530},{"atl":[[1.67,74.63]],"id":42845264},{"atb":[[3.15,76.86]],"id":39586887}],"con":true,"img":false}]}
{"op":"mcm","clk":"5346843292","pt":1646098538297,"mc":[{"id":"1.195395454","rc":[{"atl":[[1.69,108.7]],"id":42845264},{"atb":[[3.1,0]],"id":39586887}],"con":true,"img":false}]}
{"op":"mcm","clk":"5346843314","pt":1646098539014,"mc":[{"id":"1.195395454","rc":[{"atb":[[1.73,39.45]],"id":40612296},{"atb":[[2.12,65.15]],"id":43154432},{"atb":[[3.3,13.43]],"id":39586887}],"con":true,"img":false}]}
{"op":"mcm","clk":"5346843328","pt":1646098539528,"mc":[{"id":"1.195395454","rc":[{"atb":[[2.06,54.61],[2.1,0]],"id":43154432},{"atl":[[3.85,0],[3.75,7.27]],"id":43154432}],"con":true,"img":false}]}
{"op":"mcm","clk":"5346843333","pt":1646098539629,"mc":[{"id":"1.195395454","rc":[{"atl":[[32,3.23],[42,0],[14,1.54],[14.5,6.24]],"id":37076607},{"atb":[[1.66,0],[1.71,140.85],[2.08,0]],"id":43154432},{"atl":[[6.4,14.81],[6.6,3.66]],"id":39586887}],"con":true,"img":false}]}
{"op":"mcm","clk":"5346843337","pt":1646098539731,"mc":[{"id":"1.195395454","rc":[{"atl":[[14,6.63],[15.5,3.45]],"id":37076607},{"atl":[[8.2,6],[8.4,30.4]],"id":42901530},{"atb":[[1.72,31.33]],"id":40612296},{"atl":[[3.45,129.59],[3.4,16.22]],"id":40612296},{"atl":[[6.8,36.54]],"id":39586887}],"con":true,"img":false}]}
{"op":"mcm","clk":"5346843343","pt":1646098539835,"mc":[{"id":"1.195395454","rc":[{"atb":[[1.7,91.27],[1.68,0]],"id":40612296},{"atl":[[7.2,12.1]],"id":39586887}],"con":true,"img":false}]}
{"op":"mcm","clk":"5346843347","pt":1646098539938,"mc":[{"id":"1.195395454","rc":[{"atl":[[14.5,0.31]],"id":37076607}],"con":true,"img":false}]}
{"op":"mcm","clk":"5346843351","pt":1646098539994,"mc":[{"id":"1.195395454","rc":[{"atl":[[15.5,25.33]],"id":37076607}],"con":true,"img":false}]}
{"op":"mcm","clk":"5346843364","pt":1646098540299,"mc":[{"id":"1.195395454","rc":[{"atb":[[3.5,3.34],[3.45,83.59]],"id":42901530}],"con":true,"img":false}]}
{"op":"mcm","clk":"5346843369","pt":1646098540501,"mc":[{"id":"1.195395454","rc":[{"atb":[[2.06,179.38]],"id":43154432}],"con":true,"img":false}]}
{"op":"mcm","clk":"5346843379","pt":1646098540810,"mc":[{"id":"1.195395454","rc":[{"atl":[[14.5,1.79]],"id":37076607}],"con":true,"img":false}]}
{"op":"mcm","clk":"5346843386","pt":1646098540914,"mc":[{"id":"1.195395454","rc":[{"atl":[[14,5.09]],"id":37076607},{"atl":[[6.6,0.09]],"id":39586887}],"con":true,"img":false}]}
{"op":"mcm","clk":"5346843391","pt":1646098541017,"mc":[{"id":"1.195395454","rc":[{"atl":[[15.5,3.45]],"id":37076607}],"con":true,"img":false}]}
{"op":"mcm","clk":"5346843399","pt":1646098541219,"mc":[{"id":"1.195395454","rc":[{"atb":[[1.72,20.98]],"id":40612296},{"atb":[[1.68,10.95]],"id":43066392},{"atb":[[2.2,6.95]],"id":43154432}],"con":true,"img":false}]}
{"op":"mcm","clk":"5346843404","pt":1646098541321,"mc":[{"id":"1.195395454","rc":[{"atb":[[1.64,34.83],[1.67,34.51]],"id":43066392}],"con":true,"img":false}]}
{"op":"mcm","clk":"5346843445","pt":1646098542298,"mc":[{"id":"1.195395454","rc":[{"atl":[[14.5,0.31],[15,4.13]],"id":37076607}],"con":true,"img":false}]}
{"op":"mcm","clk":"5346843462","pt":1646098542809,"mc":[{"id":"1.195395454","rc":[{"atl":[[1.64,141.5]],"id":42845264},{"atb":[[2.12,37.55]],"id":43154432}],"con":true,"img":false}]}
{"op":"mcm","clk":"5346843468","pt":1646098543013,"mc":[{"id":"1.195395454","rc":[{"atl":[[1.65,30.77]],"id":42845264}],"con":true,"img":false}]}
{"op":"mcm","clk":"5346843497","pt":1646098543627,"mc":[{"id":"1.195395454","rc":[{"atb":[[1.03,426.71],[1.02,946.86]],"id":42845264}],"con":true,"img":false}]}
{"op":"mcm","clk":"5346843523","pt":1646098544341,"mc":[{"id":"1.195395454","rc":[{"atb":[[1.68,0]],"id":43066392}],"con":true,"img":false}]}
{"op":"mcm","clk":"5346843537","pt":1646098544702,"mc":[{"id":"1.195395454","rc":[{"atb":[[1.64,0]],"id":43066392}],"con":true,"img":false}]}
{"op":"mcm","clk":"5346843568","pt":1646098545319,"mc":[{"id":"1.195395454","rc":[{"atl":[[14.5,1.79]],"id":37076607}],"con":true,"img":false}]}
{"op":"mcm","clk":"5346843572","pt":1646098545422,"mc":[{"id":"1.195395454","rc":[{"atl":[[15,2.7]],"id":37076607}],"con":true,"img":false}]}
{"op":"mcm","clk":"5346843605","pt":1646098546446,"mc":[{"id":"1.195395454","rc":[{"atl":[[7.2,54.48],[6.8,3.45]],"id":39586887}],"con":true,"img":false}]}
{"op":"mcm","clk":"5346843615","pt":1646098546704,"mc":[{"id":"1.195395454","rc":[{"atb":[[2.08,26.09]],"id":43154432}],"con":true,"img":false}]}
{"op":"mcm","clk":"5346843619","pt":1646098546807,"mc":[{"id":"1.195395454","rc":[{"atb":[[1.73,56.76]],"id":40612296}],"con":true,"img":false}]}
{"op":"mcm","clk":"5346843630","pt":1646098547011,"mc":[{"id":"1.195395454","rc":[{"atb":[[1.72,11.6]],"id":40612296}],"con":true,"img":false}]}
{"op":"mcm","clk":"5346843632","pt":1646098547112,"mc":[{"id":"1.195395454","rc":[{"atl":[[3.7,29.63]],"id":43154432}],"con":true,"img":false}]}
{"op":"mcm","clk":"5346843640","pt":1646098547218,"mc":[{"id":"1.195395454","rc":[{"atb":[[3.55,2.92]],"id":42901530},{"atl":[[3.05,10.53]],"id":40612296},{"atb":[[2.16,6.42]],"id":43154432},{"atl":[[3.95,57.33],[3.8,110.57]],"id":43154432},{"atb":[[3.2,3.38]],"id":39586887}],"con":true,"img":false}]}
{"op":"mcm","clk":"5346843644","pt":1646098547317,"mc":[{"id":"1.195395454","rc":[{"atl":[[3.95,0]],"id":43154432}],"con":true,"img":false}]}
{"op":"mcm","clk":"5346843651","pt":1646098547419,"mc":[{"id":"1.195395454","rc":[{"atl":[[3.45,40.82],[3.1,0],[3.4,57.96]],"id":40612296},{"atb":[[3.25,44.87],[3.15,21.34]],"id":39586887}],"con":true,"img":false}]}
{"op":"mcm","clk":"5346843660","pt":1646098547625,"mc":[{"id":"1.195395454","rc":[{"atl":[[3.4,16.22]],"id":40612296}],"con":true,"img":false}]}
{"op":"mcm","clk":"5346843669","pt":1646098547828,"mc":[{"id":"1.195395454","rc":[{"atl":[[14.5,0.31],[15,4.13]],"id":37076607}],"con":true,"img":false}]}
{"op":"mcm","clk":"5346843673","pt":1646098547934,"mc":[{"id":"1.195395454","rc":[{"atb":[[3.5,38.23],[3.45,22.25]],"id":42901530}],"con":true,"img":false}]}
{"op":"mcm","clk":"5346843678","pt":1646098548033,"mc":[{"id":"1.195395454","rc":[{"atl":[[15,1.43]],"id":37076607},{"atb":[[1.63,69.72]],"id":43066392},{"atb":[[2.12,0]],"id":43154432},{"atb":[[3.15,0]],"id":39586887}],"con":true,"img":false}]}
{"op":"mcm","clk":"5346843682","pt":1646098548136,"mc":[{"id":"1.195395454","rc":[{"atl":[[14,7.79]],"id":37076607},{"atb":[[1.67,5]],"id":43066392},{"atb":[[2.1,37.55]],"id":43154432},{"atb":[[2.98,21.34]],"id":39586887}],"con":true,"img":false}]}
{"op":"mcm","clk":"5346843690","pt":1646098548344,"mc":[{"id":"1.195395454","rc":[{"atl":[[14.5,1.79],[15,0]],"id":37076607}],"con":true,"img":false}]}
{"op":"mcm","clk":"5346843706","pt":1646098548701,"mc":[{"id":"1.195395454","rc":[{"atb":[[1.64,34.83]],"id":43066392}],"con":true,"img":false}]}
{"op":"mcm","clk":"5346843714","pt":1646098549009,"mc":[{"id":"1.195395454","rc":[{"atb":[[1.64,92.61],[1.63,10]],"id":43066392}],"con":true,"img":false}]}
{"op":"mcm","clk":"5346843733","pt":1646098549827,"mc":[{"id":"1.195395454","rc":[{"atb":[[2.02,49.02]],"id":43154432},{"atl":[[3.85,17.54]],"id":43154432}],"con":true,"img":false}]}
{"op":"mcm","clk":"5346843742","pt":1646098550032,"mc":[{"id":"1.195395454","rc":[{"atl":[[7.2,62.54]],"id":39586887}],"con":true,"img":false}]}
{"op":"mcm","clk":"5346843747","pt":1646098550134,"mc":[{"id":"1.195395454","rc":[{"atl":[[7.2,50.44]],"id":39586887}],"con":true,"img":false}]}
{"op":"mcm","clk":"5346843755","pt":1646098550340,"mc":[{"id":"1.195395454","rc":[{"atb":[[3.55,0]],"id":42901530},{"atb":[[2.16,0]],"id":43154432},{"atb":[[3.2,0]],"id":39586887}],"con":true,"img":false}]}
{"op":"mcm","clk":"5346843771","pt":1646098550753,"mc":[{"id":"1.195395454","rc":[{"atb":[[2.08,0]],"id":43154432}],"con":true,"img":false}]}
{"op":"mcm","clk":"5346843780","pt":1646098550908,"mc":[{"id":"1.195395454","rc":[{"atl":[[4.5,0]],"id":43154432}],"con":true,"img":false}]}
{"op":"mcm","clk":"5346843807","pt":1646098551727,"mc":[{"id":"1.195395454","rc":[{"atb":[[3.5,34.89]],"id":42901530},{"atb":[[2.2,0]],"id":43154432}],"con":true,"img":false}]}
{"op":"mcm","clk":"5346843813","pt":1646098551826,"mc":[{"id":"1.195395454","rc":[{"atb":[[2.06,54.61],[2.04,176.54],[2.1,77.43]],"id":43154432}],"con":true,"img":false}]}
{"op":"mcm","clk":"5346843817","pt":1646098552031,"mc":[{"id":"1.195395454","rc":[{"atb":[[2.06,18.87]],"id":43154432}],"con":true,"img":false}]}
{"op":"mcm","clk":"5346843827","pt":1646098552544,"mc":[{"id":"1.195395454","rc":[{"atl":[[1.67,276.51]],"id":42845264}],"con":true,"img":false}]}
{"op":"mcm","clk":"5346843836","pt":1646098553234,"mc":[{"id":"1.195395454","rc":[{"atb":[[1.77,9.67]],"id":40612296}],"con":true,"img":false}]}
{"op":"mcm","clk":"5346843871","pt":1646098554051,"mc":[{"id":"1.195395454","rc":[{"atl":[[3.45,82.56]],"id":40612296}],"con":true,"img":false}]}
{"op":"mcm","clk":"5346843875","pt":1646098554155,"mc":[{"id":"1.195395454","rc":[{"atb":[[1.7,2.5],[1.72,53.34]],"id":40612296}],"con":true,"img":false}]}
{"op":"mcm","clk":"5346843878","pt":1646098554208,"mc":[{"id":"1.195395454","rc":[{"atl":[[15,1.43]],"id":37076607}],"con":true,"img":false}]}
{"op":"mcm","clk":"5346843882","pt":1646098554311,"mc":[{"id":"1.195395454","rc":[{"atl":[[14.5,0.31]],"id":37076607}],"con":true,"img":false}]}
{"op":"mcm","clk":"5346843887","pt":1646098554414,"mc":[{"id":"1.195395454","rc":[{"atl":[[15.5,25.99]],"id":37076607}],"con":true,"img":false}]}
{"op":"mcm","clk":"5346843893","pt":1646098554617,"mc":[{"id":"1.195395454","rc":[{"atb":[[3.5,0],[3.45,83.59]],"id":42901530},{"atb":[[2.12,27.59]],"id":43154432}],"con":true,"img":false}]}
{"op":"mcm","clk":"5346843896","pt":1646098554823,"mc":[{"id":"1.195395454","rc":[{"atb":[[2.06,104.7],[2.04,48.08]],"id":43154432}],"con":true,"img":false}]}
