{"op":"mcm","clk":"5346195399","pt":1646178339833,"mc":[{"id":"1.195453752","marketDefinition":{"bspMarket":false,"turnInPlayEnabled":false,"persistenceEnabled":false,"marketBaseRate":7.0,"eventId":"31272494","eventTypeId":"4339","numberOfWinners":1,"bettingType":"ODDS","marketType":"QUINELLA","marketTime":"2022-03-02T09:33:00.000Z","suspendTime":"2022-03-02T09:33:00.000Z","bspReconciled":false,"complete":true,"inPlay":false,"crossMatching":false,"runnersVoidable":false,"numberOfActiveRunners":15,"betDelay":0,"status":"OPEN","runners":[{"status":"ACTIVE","sortPriority":1,"id":522741,"name":"1 - 2 / 2 - 1"},{"status":"ACTIVE","sortPriority":2,"id":522742,"name":"1 - 3 / 3 - 1"},{"status":"ACTIVE","sortPriority":3,"id":522743,"name":"1 - 4 / 4 - 1"},{"status":"ACTIVE","sortPriority":4,"id":3805730,"name":"1 - 7 / 7 - 1"},{"status":"ACTIVE","sortPriority":5,"id":3805731,"name":"1 - 8 / 8 - 1"},{"status":"ACTIVE","sortPriority":6,"id":522746,"name":"2 - 3 / 3 - 2"},{"status":"ACTIVE","sortPriority":7,"id":522747,"name":"2 - 4 / 4 - 2"},{"status":"ACTIVE","sortPriority":8,"id":3805736,"name":"2 - 7 / 7 - 2"},{"status":"ACTIVE","sortPriority":9,"id":3805740,"name":"2 - 8 / 8 - 2"},{"status":"ACTIVE","sortPriority":10,"id":522750,"name":"3 - 4 / 4 - 3"},{"status":"ACTIVE","sortPriority":11,"id":3805746,"name":"3 - 7 / 7 - 3"},{"status":"ACTIVE","sortPriority":12,"id":3805747,"name":"3 - 8 / 8 - 3"},{"status":"ACTIVE","sortPriority":13,"id":3805755,"name":"4 - 7 / 7 - 4"},{"status":"ACTIVE","sortPriority":14,"id":3805762,"name":"4 - 8 / 8 - 4"},{"status":"ACTIVE","sortPriority":15,"id":3805793,"name":"7 - 8 / 8 - 7"}],"regulators":["MR_INT"],"venue":"Traralgon","countryCode":"AU","discountAllowed":true,"timezone":"Australia/Sydney","openDate":"2022-03-02T08:31:00.000Z","version":4382480621,"name":"Quinella","eventName":"Traralgon (AUS) 2nd Mar"},"rc":[],"con":true,"img":false}]}
{"op":"mcm","clk":"5346200440","pt":1646178438338,"mc":[{"id":"1.195453752","rc":[{"atb":[[4.6,55.43],[3.55,78.25],[3.05,129.79]],"id":3805747},{"atb":[[7.2,32.18],[5.1,48.67],[4.1,85.83]],"id":3805746},{"atb":[[4.8,52.51],[3.15,123.76],[3.65,75.3]],"id":3805793},{"atb":[[8.6,35.01],[19,11.08],[11.5,19]],"id":3805755},{"atb":[[6.8,45.87],[8.8,25.58],[14.5,14.78]],"id":522746},{"atb":[[9,24.94],[7,44.34],[15,14.25]],"id":3805736},{"atb":[[32,6.43],[18,11.73],[13,22.17]],"id":522747},{"atb":[[18.5,11.4],[11,19.95],[8.4,35.95]],"id":522750},{"atb":[[3.7,98.55],[4.4,58.69],[5.9,40.72]],"id":3805731},{"atb":[[8,28.5],[6,53.21],[12.5,17.35]],"id":3805762},{"atb":[[9,24.94],[5,66.52],[6,39.91]],"id":3805730},{"atb":[[18.5,11.4],[11,19.95],[8.4,35.95]],"id":522741},{"atb":[[4.9,68.22],[8.8,25.58],[5.9,40.72]],"id":522742},{"atb":[[24,8.67],[9.8,30.23],[14.5,14.78]],"id":522743},{"atb":[[4.9,68.22],[8.8,25.58],[5.9,40.72]],"id":3805740}],"con":true,"img":false}]}
{"op":"mcm","clk":"5346401309","pt":1646182002776,"mc":[{"id":"1.195453752","marketDefinition":{"bspMarket":false,"turnInPlayEnabled":false,"persistenceEnabled":false,"marketBaseRate":7.0,"eventId":"31272494","eventTypeId":"4339","numberOfWinners":1,"bettingType":"ODDS","marketType":"QUINELLA","marketTime":"2022-03-02T09:33:00.000Z","suspendTime":"2022-03-02T09:33:00.000Z","bspReconciled":false,"complete":true,"inPlay":false,"crossMatching":false,"runnersVoidable":false,"numberOfActiveRunners":15,"betDelay":0,"status":"OPEN","runners":[{"status":"ACTIVE","sortPriority":1,"id":522741,"name":"1 - 2 / 2 - 1"},{"status":"ACTIVE","sortPriority":2,"id":522742,"name":"1 - 3 / 3 - 1"},{"status":"ACTIVE","sortPriority":3,"id":522743,"name":"1 - 4 / 4 - 1"},{"status":"ACTIVE","sortPriority":4,"id":3805730,"name":"1 - 7 / 7 - 1"},{"status":"ACTIVE","sortPriority":5,"id":3805731,"name":"1 - 8 / 8 - 1"},{"status":"ACTIVE","sortPriority":6,"id":522746,"name":"2 - 3 / 3 - 2"},{"status":"ACTIVE","sortPriority":7,"id":522747,"name":"2 - 4 / 4 - 2"},{"status":"ACTIVE","sortPriority":8,"id":3805736,"name":"2 - 7 / 7 - 2"},{"status":"ACTIVE","sortPriority":9,"id":3805740,"name":"2 - 8 / 8 - 2"},{"status":"ACTIVE","sortPriority":10,"id":522750,"name":"3 - 4 / 4 - 3"},{"status":"ACTIVE","sortPriority":11,"id":3805746,"name":"3 - 7 / 7 - 3"},{"status":"ACTIVE","sortPriority":12,"id":3805747,"name":"3 - 8 / 8 - 3"},{"status":"ACTIVE","sortPriority":13,"id":3805755,"name":"4 - 7 / 7 - 4"},{"status":"ACTIVE","sortPriority":14,"id":3805762,"name":"4 - 8 / 8 - 4"},{"status":"ACTIVE","sortPriority":15,"id":3805793,"name":"7 - 8 / 8 - 7"}],"regulators":["MR_INT"],"venue":"Traralgon","countryCode":"AU","discountAllowed":true,"timezone":"Australia/Sydney","openDate":"2022-03-02T08:31:00.000Z","version":4382480621,"name":"Quinella","eventName":"Traralgon (AUS) 2nd Mar"},"rc":[{"atb":[[4.6,55.43],[3.55,78.26],[3.05,129.81]],"id":3805747},{"atb":[[7.2,32.19],[5.1,48.67],[4.1,85.84]],"id":3805746},{"atb":[[4.8,52.52],[3.15,123.77],[3.65,75.31]],"id":3805793},{"atb":[[8.6,35.01],[19,11.08],[11.5,19]],"id":3805755},{"atb":[[6.8,45.88],[8.8,25.58],[14.5,14.78]],"id":522746},{"atb":[[9,24.94],[7,44.35],[15,14.25]],"id":3805736},{"atb":[[32,6.44],[18,11.73],[13,22.17]],"id":522747},{"atb":[[18.5,11.4],[11,19.95],[8.4,35.95]],"id":522750},{"atb":[[3.7,98.56],[4.4,58.69],[5.9,40.73]],"id":3805731},{"atb":[[8,28.51],[6,53.22],[12.5,17.35]],"id":3805762},{"atb":[[9,24.94],[5,66.52],[6,39.91]],"id":3805730},{"atb":[[18.5,11.4],[11,19.95],[8.4,35.95]],"id":522741},{"atb":[[4.9,68.23],[8.8,25.58],[5.9,40.73]],"id":522742},{"atb":[[24,8.67],[9.8,30.24],[14.5,14.78]],"id":522743},{"atb":[[4.9,68.23],[8.8,25.58],[5.9,40.73]],"id":3805740}],"con":true,"img":true}]}
{"op":"mcm","clk":"5346480412","pt":1646183122136,"mc":[{"id":"1.195453752","rc":[{"atb":[[4.6,0],[3.55,0],[3.05,0]],"id":3805747},{"atb":[[7.2,0],[5.1,0],[4.1,0]],"id":3805746},{"atb":[[4.8,0],[3.15,0],[3.65,0]],"id":3805793},{"atb":[[8.6,0],[19,0],[11.5,0]],"id":3805755},{"atb":[[6.8,0],[8.8,0],[14.5,0]],"id":522746},{"atb":[[9,0],[7,0],[15,0]],"id":3805736},{"atb":[[32,0],[18,0],[13,0]],"id":522747},{"atb":[[18.5,0],[11,0],[8.4,0]],"id":522750},{"atb":[[3.7,0],[4.4,0],[5.9,0]],"id":3805731},{"atb":[[8,0],[6,0],[12.5,0]],"id":3805762},{"atb":[[9,0],[5,0],[6,0]],"id":3805730},{"atb":[[18.5,0],[11,0],[8.4,0]],"id":522741},{"atb":[[4.9,0],[8.8,0],[5.9,0]],"id":522742},{"atb":[[24,0],[9.8,0],[14.5,0]],"id":522743},{"atb":[[4.9,0],[8.8,0],[5.9,0]],"id":3805740}],"con":true,"img":false}]}
{"op":"mcm","clk":"5346480902","pt":1646183129046,"mc":[{"id":"1.195453752","rc":[{"atb":[[3.2,90.86],[2.88,141.77],[3.95,67.76]],"id":3805747},{"atb":[[4.6,55.52],[6.2,38.44],[3.8,95.19]],"id":3805746},{"atb":[[3.35,85.06],[4.2,62.46],[2.94,137.39]],"id":3805793},{"atb":[[9.2,32.5],[21,9.99],[13,16.65]],"id":3805755},{"atb":[[6.2,51.25],[8.2,27.76],[13,16.65]],"id":522746},{"atb":[[6.4,49.35],[13.5,15.99],[8.4,27.01]],"id":3805736},{"atb":[[38,5.4],[19.5,10.8],[14.5,19.74]],"id":522747},{"atb":[[9,33.31],[20,10.51],[12.5,17.38]],"id":522750},{"atb":[[7.2,32.24],[5.1,48.75],[4.1,85.98]],"id":3805731},{"atb":[[5.6,57.94],[7.2,32.24],[10.5,21.04]],"id":3805730},{"atb":[[9,24.98],[7,44.42],[15,14.28]],"id":3805762},{"atb":[[9,33.31],[20,10.51],[12.5,17.38]],"id":522741},{"atb":[[6.8,34.46],[9.8,22.71],[5.4,60.57]],"id":522742},{"atb":[[32,6.45],[18,11.75],[13,22.2]],"id":522743},{"atb":[[5.6,43.45],[4.6,74.03],[8.2,27.76]],"id":3805740}],"con":true,"img":false}]}
{"op":"mcm","clk":"5347092234","pt":1646192802702,"mc":[{"id":"1.195453752","marketDefinition":{"bspMarket":false,"turnInPlayEnabled":false,"persistenceEnabled":false,"marketBaseRate":7.0,"eventId":"31272494","eventTypeId":"4339","numberOfWinners":1,"bettingType":"ODDS","marketType":"QUINELLA","marketTime":"2022-03-02T09:33:00.000Z","suspendTime":"2022-03-02T09:33:00.000Z","bspReconciled":false,"complete":true,"inPlay":false,"crossMatching":false,"runnersVoidable":false,"numberOfActiveRunners":15,"betDelay":0,"status":"OPEN","runners":[{"status":"ACTIVE","sortPriority":1,"id":522741,"name":"1 - 2 / 2 - 1"},{"status":"ACTIVE","sortPriority":2,"id":522742,"name":"1 - 3 / 3 - 1"},{"status":"ACTIVE","sortPriority":3,"id":522743,"name":"1 - 4 / 4 - 1"},{"status":"ACTIVE","sortPriority":4,"id":3805730,"name":"1 - 7 / 7 - 1"},{"status":"ACTIVE","sortPriority":5,"id":3805731,"name":"1 - 8 / 8 - 1"},{"status":"ACTIVE","sortPriority":6,"id":522746,"name":"2 - 3 / 3 - 2"},{"status":"ACTIVE","sortPriority":7,"id":522747,"name":"2 - 4 / 4 - 2"},{"status":"ACTIVE","sortPriority":8,"id":3805736,"name":"2 - 7 / 7 - 2"},{"status":"ACTIVE","sortPriority":9,"id":3805740,"name":"2 - 8 / 8 - 2"},{"status":"ACTIVE","sortPriority":10,"id":522750,"name":"3 - 4 / 4 - 3"},{"status":"ACTIVE","sortPriority":11,"id":3805746,"name":"3 - 7 / 7 - 3"},{"status":"ACTIVE","sortPriority":12,"id":3805747,"name":"3 - 8 / 8 - 3"},{"status":"ACTIVE","sortPriority":13,"id":3805755,"name":"4 - 7 / 7 - 4"},{"status":"ACTIVE","sortPriority":14,"id":3805762,"name":"4 - 8 / 8 - 4"},{"status":"ACTIVE","sortPriority":15,"id":3805793,"name":"7 - 8 / 8 - 7"}],"regulators":["MR_INT"],"venue":"Traralgon","countryCode":"AU","discountAllowed":true,"timezone":"Australia/Sydney","openDate":"2022-03-02T08:31:00.000Z","version":4382480621,"name":"Quinella","eventName":"Traralgon (AUS) 2nd Mar"},"rc":[{"atb":[[3.2,91.02],[2.88,142.01],[3.95,67.87]],"id":3805747},{"atb":[[4.6,55.62],[6.2,38.5],[3.8,95.35]],"id":3805746},{"atb":[[3.35,85.2],[4.2,62.57],[2.94,137.62]],"id":3805793},{"atb":[[9.2,32.55],[21,10.01],[13,16.68]],"id":3805755},{"atb":[[6.2,51.34],[8.2,27.81],[13,16.68]],"id":522746},{"atb":[[6.4,49.44],[13.5,16.02],[8.4,27.05]],"id":3805736},{"atb":[[38,5.41],[19.5,10.82],[14.5,19.77]],"id":522747},{"atb":[[9,33.37],[20,10.53],[12.5,17.41]],"id":522750},{"atb":[[7.2,32.29],[5.1,48.83],[4.1,86.12]],"id":3805731},{"atb":[[5.6,58.04],[7.2,32.29],[10.5,21.07]],"id":3805730},{"atb":[[9,25.02],[7,44.49],[15,14.3]],"id":3805762},{"atb":[[9,33.37],[20,10.53],[12.5,17.41]],"id":522741},{"atb":[[6.8,34.52],[9.8,22.75],[5.4,60.67]],"id":522742},{"atb":[[32,6.46],[18,11.77],[13,22.24]],"id":522743},{"atb":[[5.6,43.53],[4.6,74.16],[8.2,27.81]],"id":3805740}],"con":true,"img":true}]}
{"op":"mcm","clk":"5347381107","pt":1646198202720,"mc":[{"id":"1.195453752","marketDefinition":{"bspMarket":false,"turnInPlayEnabled":false,"persistenceEnabled":false,"marketBaseRate":7.0,"eventId":"31272494","eventTypeId":"4339","numberOfWinners":1,"bettingType":"ODDS","marketType":"QUINELLA","marketTime":"2022-03-02T09:33:00.000Z","suspendTime":"2022-03-02T09:33:00.000Z","bspReconciled":false,"complete":true,"inPlay":false,"crossMatching":false,"runnersVoidable":false,"numberOfActiveRunners":15,"betDelay":0,"status":"OPEN","runners":[{"status":"ACTIVE","sortPriority":1,"id":522741,"name":"1 - 2 / 2 - 1"},{"status":"ACTIVE","sortPriority":2,"id":522742,"name":"1 - 3 / 3 - 1"},{"status":"ACTIVE","sortPriority":3,"id":522743,"name":"1 - 4 / 4 - 1"},{"status":"ACTIVE","sortPriority":4,"id":3805730,"name":"1 - 7 / 7 - 1"},{"status":"ACTIVE","sortPriority":5,"id":3805731,"name":"1 - 8 / 8 - 1"},{"status":"ACTIVE","sortPriority":6,"id":522746,"name":"2 - 3 / 3 - 2"},{"status":"ACTIVE","sortPriority":7,"id":522747,"name":"2 - 4 / 4 - 2"},{"status":"ACTIVE","sortPriority":8,"id":3805736,"name":"2 - 7 / 7 - 2"},{"status":"ACTIVE","sortPriority":9,"id":3805740,"name":"2 - 8 / 8 - 2"},{"status":"ACTIVE","sortPriority":10,"id":522750,"name":"3 - 4 / 4 - 3"},{"status":"ACTIVE","sortPriority":11,"id":3805746,"name":"3 - 7 / 7 - 3"},{"status":"ACTIVE","sortPriority":12,"id":3805747,"name":"3 - 8 / 8 - 3"},{"status":"ACTIVE","sortPriority":13,"id":3805755,"name":"4 - 7 / 7 - 4"},{"status":"ACTIVE","sortPriority":14,"id":3805762,"name":"4 - 8 / 8 - 4"},{"status":"ACTIVE","sortPriority":15,"id":3805793,"name":"7 - 8 / 8 - 7"}],"regulators":["MR_INT"],"venue":"Traralgon","countryCode":"AU","discountAllowed":true,"timezone":"Australia/Sydney","openDate":"2022-03-02T08:31:00.000Z","version":4382480621,"name":"Quinella","eventName":"Traralgon (AUS) 2nd Mar"},"rc":[{"atb":[[3.2,90.98],[2.88,141.96],[3.95,67.85]],"id":3805747},{"atb":[[4.6,55.59],[6.2,38.49],[3.8,95.31]],"id":3805746},{"atb":[[3.35,85.17],[4.2,62.54],[2.94,137.57]],"id":3805793},{"atb":[[9.2,32.54],[21,10],[13,16.68]],"id":3805755},{"atb":[[6.2,51.32],[8.2,27.8],[13,16.68]],"id":522746},{"atb":[[6.4,49.42],[13.5,16.01],[8.4,27.04]],"id":3805736},{"atb":[[38,5.41],[19.5,10.82],[14.5,19.77]],"id":522747},{"atb":[[9,33.36],[20,10.53],[12.5,17.4]],"id":522750},{"atb":[[7.2,32.28],[5.1,48.81],[4.1,86.09]],"id":3805731},{"atb":[[5.6,58.01],[7.2,32.28],[10.5,21.07]],"id":3805730},{"atb":[[9,25.01],[7,44.48],[15,14.29]],"id":3805762},{"atb":[[9,33.36],[20,10.53],[12.5,17.4]],"id":522741},{"atb":[[6.8,34.51],[9.8,22.74],[5.4,60.65]],"id":522742},{"atb":[[32,6.45],[18,11.77],[13,22.23]],"id":522743},{"atb":[[5.6,43.51],[4.6,74.13],[8.2,27.8]],"id":3805740}],"con":true,"img":true}]}
{"op":"mcm","clk":"5347724377","pt":1646206380384,"mc":[{"id":"1.195453752","rc":[{"atb":[[3.2,90.96],[2.88,141.92],[3.95,67.83]],"id":3805747},{"atb":[[4.6,55.58],[6.2,38.48],[3.8,95.28],[6.8,3.27],[7.8,2.72]],"id":3805746},{"atb":[[3.35,85.15],[4.2,62.53],[2.94,137.53]],"id":3805793},{"atb":[[9.2,32.53],[21,10],[13,16.67]],"id":3805755},{"atb":[[6.2,51.31],[8.2,27.79],[13,16.67]],"id":522746},{"atb":[[6.4,49.41],[12,3.27],[13.5,16],[8.4,27.04],[14.5,2.72]],"id":3805736},{"atb":[[38,5.4],[19.5,10.81],[14.5,19.76]],"id":522747},{"atb":[[16,3.27],[9,33.35],[18.5,2.72],[20,10.52],[12.5,17.4]],"id":522750},{"atb":[[7.2,32.27],[5.1,48.8],[4.1,86.06]],"id":3805731},{"atb":[[5.6,58],[7.2,32.27],[10.5,21.06]],"id":3805730},{"atb":[[9,25.01],[7,44.47],[15,14.29]],"id":3805762},{"atb":[[9,33.35],[20,10.52],[12.5,17.4]],"id":522741},{"atb":[[6.8,34.5],[12,2.72],[9.8,26.01],[5.4,60.63]],"id":522742},{"atb":[[32,6.45],[18,11.76],[13,22.23]],"id":522743},{"atb":[[5.6,43.5],[4.6,74.11],[8.2,27.79],[8.4,3.27],[9.4,2.72]],"id":3805740}],"con":true,"img":false}]}
{"op":"mcm","clk":"5347724381","pt":1646206380483,"mc":[{"id":"1.195453752","rc":[{"atb":[[4.6,2.72],[4.1,3.27]],"id":3805793},{"atb":[[12,3.27],[14.5,2.72]],"id":522746},{"atb":[[34,2.72],[27,3.27]],"id":522747},{"atb":[[6.4,3.27],[7.4,2.72]],"id":3805731},{"atb":[[12,2.72],[9.8,3.27]],"id":3805730},{"atb":[[12,2.72],[9.8,3.27]],"id":3805762}],"con":true,"img":false}]}
{"op":"mcm","clk":"5347724389","pt":1646206380686,"mc":[{"id":"1.195453752","rc":[{"atb":[[4.2,3.27],[4.7,2.72]],"id":3805747},{"atb":[[18,2.72],[15.5,3.27]],"id":3805755},{"atb":[[18,3.27],[21,2.72]],"id":522741},{"atb":[[22,3.27],[27,2.72]],"id":522743}],"con":true,"img":false}]}
{"op":"mcm","clk":"5347876539","pt":1646209488540,"mc":[{"id":"1.195453752","rc":[{"atb":[[4.2,0],[4.7,0]],"id":3805747},{"atb":[[6.8,0],[7.8,0]],"id":3805746}],"con":true,"img":false}]}
{"op":"mcm","clk":"5347876547","pt":1646209488646,"mc":[{"id":"1.195453752","rc":[{"atb":[[4.6,0],[4.1,0]],"id":3805793},{"atb":[[8.4,0],[9.4,0]],"id":3805740}],"con":true,"img":false}]}
{"op":"mcm","clk":"5347876584","pt":1646209489271,"mc":[{"id":"1.195453752","rc":[{"atb":[[4.8,2.72],[4.3,3.27]],"id":3805747},{"atb":[[8,2.72],[7,3.27]],"id":3805746}],"con":true,"img":false}]}
{"op":"mcm","clk":"5347876589","pt":1646209489365,"mc":[{"id":"1.195453752","rc":[{"atb":[[4.2,65.8],[4.7,2.72]],"id":3805793},{"atb":[[9.6,2.72],[8.6,3.27]],"id":3805740}],"con":true,"img":false}]}
{"op":"mcm","clk":"5347900374","pt":1646209983339,"mc":[{"id":"1.195453752","rc":[{"atb":[[2.62,61.73]],"id":3805747},{"atl":[[60,2]],"id":3805747},{"atb":[[3.55,39.22]],"id":3805746},{"atl":[[340,2]],"id":3805746},{"atb":[[2.76,56.82]],"id":3805793},{"atl":[[110,2]],"id":3805793},{"atb":[[4.5,28.57]],"id":522746},{"atl":[[470,2]],"id":522746},{"atb":[[5.2,23.81]],"id":3805736},{"atl":[[510,2]],"id":3805736},{"atb":[[10.5,10.53]],"id":522747},{"atl":[[850,2]],"id":522747},{"atb":[[6.4,18.52]],"id":522750},{"atl":[[540,2]],"id":522750},{"atb":[[3.45,40.82]],"id":3805731},{"atl":[[260,2]],"id":3805731},{"atb":[[4.4,29.41]],"id":3805730},{"atl":[[490,2]],"id":3805730},{"atb":[[4,28.6]],"id":3805762},{"atl":[[440,2]],"id":3805762},{"atb":[[7.4,15.62]],"id":522741},{"atl":[[590,2]],"id":522741},{"atb":[[4.3,30.3]],"id":522742},{"atl":[[440,2]],"id":522742},{"atb":[[3.45,40.82]],"id":3805740},{"atl":[[330,2]],"id":3805740}],"con":true,"img":false}]}
{"op":"mcm","clk":"5347900379","pt":1646209983443,"mc":[{"id":"1.195453752","rc":[{"atb":[[7.2,16.13]],"id":3805755},{"atl":[[580,2]],"id":3805755},{"atb":[[8.8,12.82]],"id":522743},{"atl":[[810,2]],"id":522743}],"con":true,"img":false}]}
{"op":"mcm","clk":"5347902852","pt":1646210043340,"mc":[{"id":"1.195453752","rc":[{"atb":[[2.5,66.67],[2.62,0]],"id":3805747},{"atb":[[2.64,60.98],[2.76,0]],"id":3805793}],"con":true,"img":false}]}
{"op":"mcm","clk":"5347905825","pt":1646210124227,"mc":[{"id":"1.195453752","rc":[{"atb":[[4.3,0],[3.8,35.71]],"id":522742}],"con":true,"img":false}]}
{"op":"mcm","clk":"5347949134","pt":1646211100075,"mc":[{"id":"1.195453752","rc":[{"atb":[[2.5,0],[2.64,60.98]],"id":3805747},{"atl":[[330,2],[340,0]],"id":3805746},{"atl":[[570,2],[580,0]],"id":3805755},{"atl":[[800,2],[850,0]],"id":522747},{"atl":[[260,0],[250,2]],"id":3805731},{"atl":[[790,2],[810,0]],"id":522743}],"con":true,"img":false}]}
{"op":"mcm","clk":"5347953213","pt":1646211186078,"mc":[{"id":"1.195453752","rc":[{"atb":[[2.64,0],[2.76,56.82]],"id":3805793},{"atb":[[4.3,30.3],[3.8,0]],"id":522742}],"con":true,"img":false}]}
{"op":"mcm","clk":"5347955858","pt":1646211243283,"mc":[{"id":"1.195453752","rc":[{"atb":[[2.5,66.67],[2.64,0]],"id":3805747},{"atb":[[2.64,60.98],[2.76,0]],"id":3805793}],"con":true,"img":false}]}
{"op":"mcm","clk":"5347981020","pt":1646211782214,"mc":[{"id":"1.195453752","rc":[{"atb":[[4.8,2.72],[4.3,3.26],[3.2,90.81],[2.88,141.69],[3.95,67.72]],"id":3805747},{"atb":[[8,2.72],[4.6,55.49],[6.2,38.42],[3.8,95.13],[7,3.26]],"id":3805746},{"atb":[[3.35,85.01],[4.2,65.7],[2.94,137.31],[4.7,2.72]],"id":3805793},{"atb":[[18,2.72],[9.2,32.48],[21,9.98],[13,16.64],[15.5,3.26]],"id":3805755},{"atb":[[6.2,51.22],[8.2,27.75],[12,0],[13,16.64],[14.5,0]],"id":522746},{"atb":[[6.4,49.33],[12,3.26],[13.5,15.98],[14.5,2.72],[8.4,26.99]],"id":3805736},{"atb":[[34,2.72],[38,5.4],[19.5,10.8],[27,3.26],[14.5,19.73]],"id":522747},{"atb":[[16,3.26],[18.5,2.72],[9,33.29],[20,10.51],[12.5,17.37]],"id":522750},{"atb":[[7.2,32.22],[5.1,48.72],[6.4,3.26],[4.1,85.93],[7.4,2.72]],"id":3805731},{"atb":[[9,24.97],[12,2.72],[9.8,3.26],[7,44.4],[15,14.27]],"id":3805762},{"atb":[[5.6,57.91],[7.2,32.22],[10.5,21.03],[12,2.72],[9.8,3.26]],"id":3805730},{"atb":[[18,3.26],[9,33.29],[20,10.51],[21,2.72],[12.5,17.37]],"id":522741},{"atb":[[12,2.72],[6.8,34.44],[9.8,25.97],[5.4,60.54]],"id":522742},{"atb":[[32,6.44],[18,11.74],[22,3.26],[13,22.19],[27,2.72]],"id":522743},{"atb":[[9.6,2.72],[5.6,43.43],[8.6,3.26],[4.6,73.99],[8.2,27.75]],"id":3805740}],"con":true,"img":false}]}
{"op":"mcm","clk":"5347981062","pt":1646211783033,"mc":[{"id":"1.195453752","rc":[{"atb":[[12.5,3.26],[15,2.72]],"id":522746}],"con":true,"img":false}]}
{"op":"mcm","clk":"5347981068","pt":1646211783139,"mc":[{"id":"1.195453752","rc":[{"atb":[[2.5,0],[2.62,61.73]],"id":3805747},{"atb":[[3.8,130.84],[3.55,0]],"id":3805746},{"atb":[[2.64,0],[2.76,56.82]],"id":3805793},{"atl":[[330,0],[320,2]],"id":3805740}],"con":true,"img":false}]}
{"op":"mcm","clk":"5347987311","pt":1646211903129,"mc":[{"id":"1.195453752","rc":[{"atb":[[2.64,60.98],[2.76,0]],"id":3805793},{"atb":[[6.2,19.23],[7.4,0]],"id":522741}],"con":true,"img":false}]}
{"op":"mcm","clk":"5347987343","pt":1646211903646,"mc":[{"id":"1.195453752","rc":[{"atb":[[4.2,62.43],[4.7,0]],"id":3805793}],"con":true,"img":false}]}
{"op":"mcm","clk":"5347987395","pt":1646211904425,"mc":[{"id":"1.195453752","rc":[{"atb":[[4.6,2.72],[4.1,3.26]],"id":3805793}],"con":true,"img":false}]}
{"op":"mcm","clk":"5348009334","pt":1646212353720,"mc":[{"id":"1.195453752","rc":[{"atl":[[430,2]],"id":522742}],"con":true,"img":false}]}
{"op":"mcm","clk":"5348009341","pt":1646212353824,"mc":[{"id":"1.195453752","rc":[{"atl":[[440,0]],"id":522742}],"con":true,"img":false}]}
{"op":"mcm","clk":"5348013314","pt":1646212429547,"mc":[{"id":"1.195453752","rc":[{"atb":[[9.6,0],[8.6,0]],"id":3805740}],"con":true,"img":false}]}
{"op":"mcm","clk":"5348013337","pt":1646212429963,"mc":[{"id":"1.195453752","rc":[{"atb":[[12,0],[9.8,22.7]],"id":522742}],"con":true,"img":false}]}
{"op":"mcm","clk":"5348013352","pt":1646212430217,"mc":[{"id":"1.195453752","rc":[{"atb":[[8.4,3.26],[9.4,2.72]],"id":3805740}],"con":true,"img":false}]}
{"op":"mcm","clk":"5348013404","pt":1646212431045,"mc":[{"id":"1.195453752","rc":[{"atb":[[10,3.26],[12.5,2.72]],"id":522742}],"con":true,"img":false}]}
{"op":"mcm","clk":"5348013417","pt":1646212431259,"mc":[{"id":"1.195453752","rc":[{"atb":[[4.8,0],[4.3,0]],"id":3805747},{"atb":[[4.6,0],[4.1,0]],"id":3805793}],"con":true,"img":false}]}
{"op":"mcm","clk":"5348013463","pt":1646212432233,"mc":[{"id":"1.195453752","rc":[{"atb":[[4.2,3.26],[4.7,2.72]],"id":3805747},{"atb":[[4.2,65.7],[4.7,2.72]],"id":3805793}],"con":true,"img":false}]}
{"op":"mcm","clk":"5348013559","pt":1646212433472,"mc":[{"id":"1.195453752","rc":[{"atb":[[3.2,0],[2.88,0],[3.95,0]],"id":3805747},{"atb":[[4.6,0],[6.2,0],[3.8,35.71]],"id":3805746},{"atb":[[3.35,0],[4.2,3.26],[2.94,0]],"id":3805793},{"atb":[[9.2,0],[21,0],[13,0]],"id":3805755},{"atb":[[6.2,0],[8.2,0],[13,0]],"id":522746},{"atb":[[6.4,0],[13.5,0],[8.4,0]],"id":3805736},{"atb":[[38,0],[19.5,0],[14.5,0]],"id":522747},{"atb":[[9,0],[20,0],[12.5,0]],"id":522750},{"atb":[[7.2,0],[5.1,0],[4.1,0]],"id":3805731},{"atb":[[9,0],[7,0],[15,0]],"id":3805762},{"atb":[[5.6,0],[7.2,0],[10.5,0]],"id":3805730},{"atb":[[9,0],[20,0],[12.5,0]],"id":522741},{"atb":[[6.8,0],[9.8,0],[5.4,0]],"id":522742},{"atb":[[32,0],[18,0],[13,0]],"id":522743},{"atb":[[5.6,0],[4.6,0],[8.2,0]],"id":3805740}],"con":true,"img":false}]}
{"op":"mcm","clk":"5348014046","pt":1646212443198,"mc":[{"id":"1.195453752","rc":[{"atb":[[2.86,143.22],[3.15,92.92],[3.9,68.89]],"id":3805747},{"atb":[[4.6,55.49],[6.2,38.42],[3.8,130.84]],"id":3805746},{"atb":[[3.85,70.1],[3.1,95.13],[2.84,144.77]],"id":3805793},{"atb":[[9,33.29],[20,10.51],[12.5,17.37]],"id":3805755},{"atb":[[7.2,42.96],[9.2,24.36],[15.5,13.77]],"id":522746},{"atb":[[7.2,42.96],[9.2,24.36],[15.5,13.77]],"id":3805736},{"atb":[[42,4.87],[21,9.98],[15.5,18.37]],"id":522747},{"atb":[[9,33.29],[20,10.51],[12.5,17.37]],"id":522750},{"atb":[[4,88.79],[5,49.94],[7,33.29]],"id":3805731},{"atb":[[6.4,49.33],[13.5,15.98],[8.4,26.99]],"id":3805762},{"atb":[[10,22.19],[5.5,59.19],[7,33.29]],"id":3805730},{"atb":[[10,29.59],[25,8.32],[15,14.27]],"id":522741},{"atb":[[5.6,57.91],[7.2,32.22],[10.5,21.03]],"id":522742},{"atb":[[17.5,12.1],[12.5,23.16],[30,6.88]],"id":522743},{"atb":[[4.9,68.3],[8.8,25.61],[5.9,40.77]],"id":3805740}],"con":true,"img":false}]}
{"op":"mcm","clk":"5348014343","pt":1646212448498,"mc":[{"id":"1.195453752","rc":[{"atb":[[2.62,0],[2.76,56.82]],"id":3805747},{"atb":[[4.1,32.26],[3.8,95.13]],"id":3805746},{"atl":[[570,0],[550,2]],"id":3805755},{"atl":[[490,2],[510,0]],"id":3805736},{"atb":[[10.5,0],[8.4,13.51]],"id":522747},{"atl":[[690,2],[800,0]],"id":522747},{"atl":[[200,2],[250,0]],"id":3805731},{"atl":[[490,0],[480,2]],"id":3805730},{"atl":[[410,2],[440,0]],"id":3805762},{"atl":[[550,2],[590,0]],"id":522741},{"atb":[[7.2,16.13],[8.8,0]],"id":522743},{"atl":[[670,2],[790,0]],"id":522743},{"atl":[[290,2],[320,0]],"id":3805740}],"con":true,"img":false}]}
{"op":"mcm","clk":"5348014344","pt":1646212448558,"mc":[{"id":"1.195453752","rc":[{"atl":[[100,2],[110,0]],"id":3805793},{"atb":[[7.2,0],[8.2,13.89]],"id":3805755},{"atb":[[5.6,21.74],[4.5,0]],"id":522746},{"atl":[[450,2],[470,0]],"id":522746},{"atb":[[6,20],[5.2,0]],"id":3805736},{"atb":[[8,14.29],[6.4,0]],"id":522750},{"atl":[[540,0],[520,2]],"id":522750},{"atb":[[4.9,25.64],[4.4,0]],"id":3805730},{"atb":[[4.3,0],[5.2,23.81]],"id":522742},{"atl":[[430,0],[420,2]],"id":522742},{"atb":[[3.45,0],[3.75,36.36]],"id":3805740}],"con":true,"img":false}]}
{"op":"mcm","clk":"5348014973","pt":1646212460998,"mc":[{"id":"1.195453752","rc":[{"atb":[[3.05,48.78],[2.76,0]],"id":3805747},{"atb":[[4.8,26.32],[4.1,0]],"id":3805746},{"atl":[[530,2],[550,0]],"id":3805755},{"atl":[[460,2],[490,0]],"id":3805736},{"atb":[[10,11.11],[8.4,0]],"id":522747},{"atl":[[640,2],[690,0]],"id":522747},{"atl":[[140,2],[200,0]],"id":3805731},{"atl":[[450,2],[480,0]],"id":3805730},{"atl":[[380,2],[410,0]],"id":3805762},{"atl":[[520,2],[550,0]],"id":522741},{"atb":[[7.2,0],[8.8,12.82]],"id":522743},{"atl":[[620,2],[670,0]],"id":522743},{"atl":[[290,0],[250,2]],"id":3805740}],"con":true,"img":false}]}
{"op":"mcm","clk":"5348015736","pt":1646212477423,"mc":[{"id":"1.195453752","rc":[{"atl":[[100,0],[110,2]],"id":3805793},{"atl":[[440,2],[450,0]],"id":522746},{"atl":[[630,2],[640,0]],"id":522747},{"atl":[[380,0],[370,2]],"id":3805762},{"atl":[[520,0],[510,2]],"id":522741},{"atl":[[620,0],[610,2]],"id":522743},{"atl":[[230,2],[250,0]],"id":3805740}],"con":true,"img":false}]}
{"op":"mcm","clk":"5348015753","pt":1646212477726,"mc":[{"id":"1.195453752","rc":[{"atl":[[130,2],[140,0]],"id":3805731}],"con":true,"img":false}]}
{"op":"mcm","clk":"5348015767","pt":1646212478031,"mc":[{"id":"1.195453752","rc":[{"atb":[[8.4,0],[9.4,0]],"id":3805740}],"con":true,"img":false}]}
{"op":"mcm","clk":"5348015844","pt":1646212479019,"mc":[{"id":"1.195453752","rc":[{"atb":[[8,3.26],[9,2.72]],"id":3805740}],"con":true,"img":false}]}
{"op":"mcm","clk":"5348017252","pt":1646212505474,"mc":[{"id":"1.195453752","rc":[{"atl":[[100,2],[110,0]],"id":3805793},{"atl":[[530,0],[520,2]],"id":3805755},{"atl":[[130,0],[120,2]],"id":3805731},{"atl":[[600,2],[610,0]],"id":522743}],"con":true,"img":false}]}
{"op":"mcm","clk":"5348017791","pt":1646212515690,"mc":[{"id":"1.195453752","rc":[{"atb":[[7.2,16.13],[6.2,0]],"id":522741}],"con":true,"img":false}]}
{"op":"mcm","clk":"5348021813","pt":1646212594860,"mc":[{"id":"1.195453752","rc":[{"atb":[[8,0],[9,0]],"id":3805740}],"con":true,"img":false}]}
{"op":"mcm","clk":"5348021857","pt":1646212595891,"mc":[{"id":"1.195453752","rc":[{"atb":[[9.6,2.72],[8.6,3.26]],"id":3805740}],"con":true,"img":false}]}
{"op":"mcm","clk":"5348024231","pt":1646212634344,"mc":[{"id":"1.195453752","rc":[{"atb":[[4.2,0],[4.7,0]],"id":3805747}],"con":true,"img":false}]}
{"op":"mcm","clk":"5348024290","pt":1646212635325,"mc":[{"id":"1.195453752","rc":[{"atb":[[4.8,2.72],[4.3,3.26]],"id":3805747}],"con":true,"img":false}]}
{"op":"mcm","clk":"5348024718","pt":1646212642567,"mc":[{"id":"1.195453752","rc":[{"atl":[[100,0]],"id":3805793},{"atl":[[490,2]],"id":3805755},{"atl":[[430,2],[440,0]],"id":522746},{"atl":[[440,2],[460,0]],"id":3805736},{"atl":[[610,2]],"id":522747},{"atl":[[520,0]],"id":522750},{"atl":[[80,2],[120,0]],"id":3805731},{"atl":[[420,2],[450,0]],"id":3805730},{"atl":[[370,2]],"id":522742},{"atl":[[600,0]],"id":522743},{"atl":[[220,2],[230,0]],"id":3805740}],"con":true,"img":false}]}
{"op":"mcm","clk":"5348024722","pt":1646212642662,"mc":[{"id":"1.195453752","rc":[{"atl":[[80,2]],"id":3805793},{"atl":[[520,0]],"id":3805755},{"atl":[[630,0]],"id":522747},{"atl":[[480,2]],"id":522750},{"atl":[[420,0]],"id":522742},{"atl":[[560,2]],"id":522743}],"con":true,"img":false}]}
{"op":"mcm","clk":"5348025313","pt":1646212653281,"mc":[{"id":"1.195453752","rc":[{"atl":[[330,0],[320,2]],"id":3805746},{"atl":[[490,0],[480,2]],"id":3805755},{"atl":[[600,2],[610,0]],"id":522747},{"atl":[[470,2],[480,0]],"id":522750},{"atl":[[560,0],[550,2]],"id":522743}],"con":true,"img":false}]}
{"op":"mcm","clk":"5348025767","pt":1646212661295,"mc":[{"id":"1.195453752","rc":[{"atl":[[430,0],[420,2]],"id":522746},{"atl":[[360,2],[370,0]],"id":522742}],"con":true,"img":false}]}
{"op":"mcm","clk":"5348025796","pt":1646212661757,"mc":[{"id":"1.195453752","rc":[{"atb":[[6.4,0],[7.4,0]],"id":3805731}],"con":true,"img":false}]}
{"op":"mcm","clk":"5348025837","pt":1646212662582,"mc":[{"id":"1.195453752","rc":[{"atb":[[7.6,2.72],[6.6,3.26]],"id":3805731}],"con":true,"img":false}]}
{"op":"mcm","clk":"5348027079","pt":1646212686512,"mc":[{"id":"1.195453752","rc":[{"atl":[[310,2],[320,0]],"id":3805746},{"atl":[[460,2],[470,0]],"id":522750}],"con":true,"img":false}]}
{"op":"mcm","clk":"5348027838","pt":1646212700153,"mc":[{"id":"1.195453752","rc":[{"atb":[[9.6,0],[8.6,0]],"id":3805740}],"con":true,"img":false}]}
{"op":"mcm","clk":"5348027902","pt":1646212701135,"mc":[{"id":"1.195453752","rc":[{"atb":[[9.8,2.72],[8.8,28.88]],"id":3805740}],"con":true,"img":false}]}
{"op":"mcm","clk":"5348028589","pt":1646212715060,"mc":[{"id":"1.195453752","rc":[{"atb":[[12,0],[9.8,0]],"id":3805730},{"atb":[[18,0],[21,0]],"id":522741},{"atb":[[22,0],[27,0]],"id":522743}],"con":true,"img":false}]}
{"op":"mcm","clk":"5348028593","pt":1646212715161,"mc":[{"id":"1.195453752","rc":[{"atb":[[9.8,0],[8.8,25.61]],"id":3805740}],"con":true,"img":false}]}
{"op":"mcm","clk":"5348028633","pt":1646212715733,"mc":[{"id":"1.195453752","rc":[{"atb":[[10,25.46],[12.5,2.72]],"id":3805730},{"atb":[[18.5,3.26],[22,2.72]],"id":522741},{"atb":[[23,3.26],[28,2.72]],"id":522743}],"con":true,"img":false}]}
{"op":"mcm","clk":"5348028642","pt":1646212715833,"mc":[{"id":"1.195453752","rc":[{"atb":[[9.6,2.72],[8.6,3.26]],"id":3805740}],"con":true,"img":false}]}
{"op":"mcm","clk":"5348028719","pt":1646212717073,"mc":[{"id":"1.195453752","rc":[{"atb":[[4.8,0],[4.3,0]],"id":3805747}],"con":true,"img":false}]}
{"op":"mcm","clk":"5348028750","pt":1646212717747,"mc":[{"id":"1.195453752","rc":[{"atb":[[4.2,3.26],[4.7,2.72]],"id":3805747}],"con":true,"img":false}]}
{"op":"mcm","clk":"5348030024","pt":1646212741587,"mc":[{"id":"1.195453752","rc":[{"atl":[[48,2],[60,0]],"id":3805747},{"atb":[[2.24,80.65],[2.64,0]],"id":3805793},{"atb":[[4.9,0],[5.4,22.73]],"id":3805730},{"atl":[[410,2],[420,0]],"id":3805730}],"con":true,"img":false}]}
{"op":"mcm","clk":"5348030137","pt":1646212743627,"mc":[{"id":"1.195453752","rc":[{"atb":[[2.86,0],[3.15,0],[3.9,0]],"id":3805747},{"atb":[[4.6,0],[6.2,0],[3.8,0]],"id":3805746},{"atb":[[3.85,0],[3.1,0],[2.84,0]],"id":3805793},{"atb":[[9,0],[20,0],[12.5,0]],"id":3805755},{"atb":[[7.2,0],[9.2,0],[15.5,0]],"id":522746},{"atb":[[7.2,0],[9.2,0],[15.5,0]],"id":3805736},{"atb":[[42,0],[21,0],[15.5,0]],"id":522747},{"atb":[[9,0],[20,0],[12.5,0]],"id":522750},{"atb":[[4,0],[5,0],[7,0]],"id":3805731},{"atb":[[10,3.26],[5.5,0],[7,0]],"id":3805730},{"atb":[[6.4,0],[13.5,0],[8.4,0]],"id":3805762},{"atb":[[10,0],[25,0],[15,0]],"id":522741},{"atb":[[5.6,0],[7.2,0],[10.5,0]],"id":522742},{"atb":[[17.5,0],[12.5,0],[30,0]],"id":522743},{"atb":[[4.9,0],[8.8,0],[5.9,0]],"id":3805740}],"con":true,"img":false}]}
{"op":"mcm","clk":"5348030362","pt":1646212748419,"mc":[{"id":"1.195453752","rc":[{"atb":[[2.46,182.45],[2.66,160.47],[3.15,61.94]],"id":3805747},{"atb":[[2.92,138.74],[4.6,36.99],[3.3,115.82]],"id":3805746},{"atb":[[3.1,63.42],[2.64,162.43],[2.44,184.99]],"id":3805793},{"atb":[[5.5,59.19],[12.5,11.58],[7,44.4]],"id":3805755},{"atb":[[5.6,79.65],[9.2,16.24],[4.6,73.99]],"id":522746},{"atb":[[5.6,57.91],[9.2,16.24],[4.6,73.99]],"id":3805736},{"atb":[[21,6.65],[10.5,28.03],[8.2,36.99]],"id":522747},{"atb":[[5.5,59.19],[12.5,11.58],[7,44.4]],"id":522750},{"atb":[[5,33.29],[3,133.19],[3.5,106.55]],"id":3805731},{"atb":[[5.2,63.42],[8.4,18],[4.2,83.24]],"id":3805762},{"atb":[[4.5,76.11],[7,22.19],[3.75,96.87]],"id":3805730},{"atb":[[8,38.05],[6,53.27],[15,9.51]],"id":522741},{"atb":[[7.2,21.48],[4.6,73.99],[3.8,95.13]],"id":522742},{"atb":[[17.5,8.07],[9,33.29],[7,44.4]],"id":522743},{"atb":[[3.45,108.73],[3.95,90.29],[5.9,27.18]],"id":3805740}],"con":true,"img":false}]}
{"op":"mcm","clk":"5348030756","pt":1646212756588,"mc":[{"id":"1.195453752","rc":[{"atb":[[4.8,26.32]],"id":3805730}],"con":true,"img":false}]}
{"op":"mcm","clk":"5348030760","pt":1646212756690,"mc":[{"id":"1.195453752","rc":[{"atb":[[5.4,0]],"id":3805730}],"con":true,"img":false}]}
{"op":"mcm","clk":"5348033743","pt":1646212812987,"mc":[{"id":"1.195453752","rc":[{"atb":[[9.6,0],[8.6,0]],"id":3805740}],"con":true,"img":false}]}
{"op":"mcm","clk":"5348033791","pt":1646212813866,"mc":[{"id":"1.195453752","rc":[{"atb":[[8.4,3.26],[9.4,2.72]],"id":3805740}],"con":true,"img":false}]}
{"op":"mcm","clk":"5348035454","pt":1646212841134,"mc":[{"id":"1.195453752","rc":[{"atb":[[5.6,57.91],[6.2,19.23]],"id":522746}],"con":true,"img":false}]}
{"op":"mcm","clk":"5348035719","pt":1646212845014,"mc":[{"id":"1.195453752","rc":[{"atb":[[7.6,0],[6.6,0]],"id":3805731}],"con":true,"img":false}]}
{"op":"mcm","clk":"5348035778","pt":1646212846042,"mc":[{"id":"1.195453752","rc":[{"atb":[[6.4,3.26],[7.4,2.72]],"id":3805731}],"con":true,"img":false}]}
{"op":"mcm","clk":"5348036982","pt":1646212866684,"mc":[{"id":"1.195453752","rc":[{"atb":[[2.24,0],[2.34,74.63]],"id":3805793},{"atb":[[4.8,0],[5.3,23.26]],"id":3805730}],"con":true,"img":false}]}
{"op":"mcm","clk":"5348038639","pt":1646212896212,"mc":[{"id":"1.195453752","rc":[{"atb":[[8.4,0],[9.4,0]],"id":3805740}],"con":true,"img":false}]}
{"op":"mcm","clk":"5348038696","pt":1646212896984,"mc":[{"id":"1.195453752","rc":[{"atb":[[9.6,2.72],[8.6,3.26]],"id":3805740}],"con":true,"img":false}]}
{"op":"mcm","clk":"5348043125","pt":1646212980521,"mc":[{"id":"1.195453752","rc":[{"atb":[[9.2,25.14]],"id":522746},{"atl":[[440,2.79]],"id":522746}],"con":true,"img":false}]}
{"op":"mcm","clk":"5348043133","pt":1646212980626,"mc":[{"id":"1.195453752","rc":[{"atb":[[5,4.95],[4.6,9.9],[3.15,70.85],[4.7,11.63]],"id":3805747},{"atl":[[8.2,9.9],[7.4,4.95],[46,3.52],[55,8.9]],"id":3805747},{"atb":[[8,11.63],[4.8,35.22],[10,4.95],[9.2,9.9]],"id":3805746},{"atl":[[18.5,4.95],[300,0.52],[330,3.72],[21,9.9]],"id":3805746},{"atb":[[5.8,4.95],[3.1,72.33],[4.7,11.63],[5.4,9.9]],"id":3805793},{"atl":[[75,2.14],[9.2,9.9],[90,8.9],[8.4,4.95]],"id":3805793},{"atb":[[18,11.63],[18.5,9.9],[21,4.95],[12.5,20.48]],"id":3805755},{"atl":[[38,4.95],[46,9.9],[470,0.33],[500,2.45]],"id":3805755},{"atb":[[12.5,13.17],[14.5,4.95],[15,11.63]],"id":522746},{"atl":[[38,9.9],[410,0.38],[30,4.95]],"id":522746},{"atb":[[16,4.95],[14,9.9],[14.5,11.63]],"id":3805736},{"atl":[[32,4.95],[40,9.9],[430,0.37]],"id":3805736},{"atb":[[34,7.53],[21,15.56],[26,9.9],[30,4.95]],"id":522747},{"atl":[[590,0.26],[620,1.97],[85,4.95],[110,9.9]],"id":522747},{"atb":[[17,9.9],[18.5,11.63],[19,4.95],[12.5,20.48]],"id":522750},{"atl":[[38,4.95],[46,9.9],[450,0.35],[480,2.55]],"id":522750},{"atb":[[5,42.2],[6.2,4.95],[5.7,9.9]],"id":3805731},{"atl":[[9.6,4.95],[75,2.14],[11,9.9],[90,8.9]],"id":3805731},{"atb":[[11.5,9.9],[12.5,11.63],[13.5,4.95],[7,31.1]],"id":3805730},{"atl":[[23,4.95],[400,0.39],[430,2.85],[27,9.9]],"id":3805730},{"atb":[[10.5,4.95],[8.4,26.9],[9.4,9.9]],"id":3805762},{"atl":[[17,4.95],[19,9.9],[360,0.44],[390,3.15]],"id":3805762},{"atb":[[18,9.9],[20,4.95],[22,10.27],[15,18.42]],"id":522741},{"atl":[[530,2.31],[42,4.95],[50,9.9],[500,0.31]],"id":522741},{"atb":[[7.2,30.38],[10.5,9.9],[12.5,16.58]],"id":522742},{"atl":[[350,0.45],[22,4.95],[380,3.23],[26,9.9]],"id":522742},{"atb":[[17.5,16.97],[21,9.9],[25,4.95],[28,8.59]],"id":522743},{"atl":[[540,0.29],[570,2.15],[75,9.9],[55,4.95]],"id":522743},{"atb":[[8,4.95],[7.2,9.9],[5.9,36.08]],"id":3805740},{"atl":[[16,9.9],[210,0.75],[14,4.95],[240,5.12]],"id":3805740}],"con":true,"img":false}]}
{"op":"mcm","clk":"5348043136","pt":1646212980679,"mc":[{"id":"1.195453752","rc":[{"atl":[[420,0],[440,4.79]],"id":522746}],"con":true,"img":false}]}
{"op":"mcm","clk":"5348043142","pt":1646212980835,"mc":[{"id":"1.195453752","rc":[{"atl":[[48,0],[12,9.09]],"id":3805747},{"atl":[[310,0],[42,2.44]],"id":3805746},{"atl":[[80,0],[15,7.14]],"id":3805793},{"atl":[[110,2],[480,0]],"id":3805755},{"atb":[[9.2,25.14]],"id":3805736},{"atl":[[90,2],[440,0],[460,2.67]],"id":3805736},{"atl":[[600,0],[290,2]],"id":522747},{"atl":[[110,2],[460,0]],"id":522750},{"atl":[[16,6.67],[80,0]],"id":3805731},{"atl":[[65,2],[410,0]],"id":3805730},{"atl":[[85,2],[370,0]],"id":3805762},{"atl":[[130,2],[510,0]],"id":522741},{"atl":[[65,2],[360,0]],"id":522742},{"atl":[[550,0],[180,2]],"id":522743},{"atl":[[220,0],[30,3.45]],"id":3805740}],"con":true,"img":false}]}
{"op":"mcm","clk":"5348043170","pt":1646212981301,"mc":[{"id":"1.195453752","rc":[{"atb":[[4,33.33],[3.05,0]],"id":3805747},{"atb":[[4.8,8.9],[6.8,17.24]],"id":3805746},{"atb":[[8.2,0],[11.5,9.52]],"id":3805755},{"atb":[[9.2,37.34],[6.2,0]],"id":522746},{"atb":[[6,0],[9.8,11.36]],"id":3805736},{"atb":[[10,0],[14,7.69]],"id":522747},{"atb":[[8,0],[11,10]],"id":522750},{"atb":[[3.45,0],[4.6,27.78]],"id":3805731},{"atb":[[4,0],[5.8,20.83]],"id":3805762},{"atb":[[5.3,0],[7.6,15.15]],"id":3805730},{"atb":[[7.2,0],[10,11.11]],"id":522741},{"atb":[[6.4,18.52],[5.2,0]],"id":522742},{"atb":[[12,9.09],[8.8,0]],"id":522743},{"atb":[[5.1,24.39],[3.75,0]],"id":3805740}],"con":true,"img":false}]}
{"op":"mcm","clk":"5348043977","pt":1646212996219,"mc":[{"id":"1.195453752","rc":[{"atb":[[9.2,28.44],[12.5,35.26]],"id":522746}],"con":true,"img":false}]}
{"op":"mcm","clk":"5348043983","pt":1646212996323,"mc":[{"id":"1.195453752","rc":[{"atb":[[8,33.71],[4.8,0]],"id":3805746},{"atl":[[330,0],[42,24.52]],"id":3805746},{"atl":[[8.4,26.37],[15,32.48]],"id":3805793},{"atb":[[12.5,11.58]],"id":3805755},{"atl":[[410,3.48],[440,2]],"id":522746},{"atb":[[21,6.65],[27,17.98]],"id":522747},{"atb":[[17,31.99]],"id":522750},{"atl":[[480,0]],"id":522750},{"atl":[[9.6,19.66]],"id":3805731},{"atb":[[13.5,17.63]],"id":3805730},{"atl":[[23,12.15]],"id":3805730},{"atl":[[22,12.5]],"id":522742},{"atl":[[55,7.89]],"id":522743},{"atb":[[8,17.43],[5.9,27.18]],"id":3805740},{"atl":[[14,17.15],[30,15.93],[240,0]],"id":3805740}],"con":true,"img":false}]}
{"op":"mcm","clk":"5348043989","pt":1646212996430,"mc":[{"id":"1.195453752","rc":[{"atb":[[5,33.19],[4.6,38.14],[3.15,61.94]],"id":3805747},{"atl":[[7.4,29.72],[12,37.33],[55,0]],"id":3805747},{"atb":[[10,22.56]],"id":3805746},{"atl":[[18.5,14.01]],"id":3805746},{"atb":[[5.8,30.29],[3.1,63.42],[4.7,36.97]],"id":3805793},{"atl":[[90,0]],"id":3805793},{"atb":[[18,33.71],[21,12.88]],"id":3805755},{"atl":[[38,9.23],[110,13.59],[500,0]],"id":3805755},{"atl":[[30,10.42]],"id":522746},{"atb":[[16,15.52]],"id":3805736},{"atl":[[32,10.06]],"id":3805736},{"atl":[[290,6.39],[620,0]],"id":522747},{"atb":[[19,13.76],[12.5,11.58]],"id":522750},{"atl":[[38,9.23],[110,13.59]],"id":522750},{"atb":[[5,33.29],[6.2,19.66]],"id":3805731},{"atl":[[16,14.71],[90,0],[13.5,8]],"id":3805731},{"atb":[[11.5,31.99],[7,22.19]],"id":3805730},{"atl":[[65,21.63],[430,0]],"id":3805730},{"atb":[[9.8,15.48],[8.4,18]],"id":3805762},{"atl":[[17,14.86],[85,14.21],[390,0]],"id":3805762},{"atb":[[18.5,17.98],[15,9.51]],"id":522741},{"atl":[[130,11.8],[530,0],[42,8.82]],"id":522741},{"atb":[[7.2,21.48],[10,25.35]],"id":522742},{"atl":[[65,21.63],[380,0]],"id":522742},{"atb":[[17.5,8.07],[23,17.98]],"id":522743},{"atl":[[570,0],[180,9.08]],"id":522743},{"atl":[[25,4.17],[30,12.48]],"id":3805740}],"con":true,"img":false}]}
{"op":"mcm","clk":"5348043995","pt":1646212996531,"mc":[{"id":"1.195453752","rc":[{"atb":[[14,31.99]],"id":3805736},{"atl":[[90,16.18],[460,0]],"id":3805736}],"con":true,"img":false}]}
{"op":"mcm","clk":"5348044002","pt":1646212996637,"mc":[{"id":"1.195453752","rc":[{"atl":[[65,2],[440,0]],"id":522746},{"atb":[[9.2,16.24]],"id":3805736}],"con":true,"img":false}]}
{"op":"mcm","clk":"5348044025","pt":1646212997100,"mc":[{"id":"1.195453752","rc":[{"atl":[[75,0]],"id":3805793},{"atl":[[75,0]],"id":3805731},{"atb":[[12.5,2.72]],"id":3805730},{"atl":[[400,0]],"id":3805730},{"atl":[[350,0]],"id":522742},{"atl":[[210,0]],"id":3805740}],"con":true,"img":false}]}
{"op":"mcm","clk":"5348044028","pt":1646212997203,"mc":[{"id":"1.195453752","rc":[{"atb":[[4.7,2.72]],"id":3805747},{"atl":[[46,0]],"id":3805747},{"atb":[[8,24.81]],"id":3805746},{"atl":[[300,0]],"id":3805746},{"atb":[[4.7,28.06]],"id":3805793},{"atb":[[18,24.81]],"id":3805755},{"atl":[[470,0]],"id":3805755},{"atl":[[410,3.1]],"id":522746},{"atb":[[14.5,2.72]],"id":3805736},{"atl":[[430,0]],"id":3805736},{"atl":[[85,6.83]],"id":522747},{"atb":[[18.5,2.72]],"id":522750},{"atl":[[450,0]],"id":522750},{"atl":[[360,0]],"id":3805762},{"atl":[[500,0]],"id":522741},{"atl":[[540,0]],"id":522743}],"con":true,"img":false}]}
{"op":"mcm","clk":"5348044055","pt":1646212998026,"mc":[{"id":"1.195453752","rc":[{"atl":[[590,0]],"id":522747}],"con":true,"img":false}]}
{"op":"mcm","clk":"5348044788","pt":1646213011421,"mc":[{"id":"1.195453752","rc":[{"atl":[[17,4.95]],"id":3805762}],"con":true,"img":false}]}
{"op":"mcm","clk":"5348044814","pt":1646213011734,"mc":[{"id":"1.195453752","rc":[{"atl":[[65,22.3],[410,0]],"id":522746},{"atl":[[25,25.09],[30,0]],"id":3805740}],"con":true,"img":false}]}
{"op":"mcm","clk":"5348044824","pt":1646213011839,"mc":[{"id":"1.195453752","rc":[{"atl":[[16,0],[13.5,34.62]],"id":3805731}],"con":true,"img":false}]}
{"op":"mcm","clk":"5348044844","pt":1646213012146,"mc":[{"id":"1.195453752","rc":[{"atl":[[19,18.71]],"id":3805762}],"con":true,"img":false}]}
{"op":"mcm","clk":"5348045951","pt":1646213031351,"mc":[{"id":"1.195453752","rc":[{"atb":[[5.8,4.95]],"id":3805793}],"con":true,"img":false}]}
{"op":"mcm","clk":"5348045972","pt":1646213031761,"mc":[{"id":"1.195453752","rc":[{"atb":[[5.8,0],[5.3,9.9],[5.7,4.95],[5.4,0]],"id":3805793}],"con":true,"img":false}]}
{"op":"mcm","clk":"5348045987","pt":1646213032076,"mc":[{"id":"1.195453752","rc":[{"atb":[[5.4,36.03]],"id":3805793}],"con":true,"img":false}]}
{"op":"mcm","clk":"5348046021","pt":1646213032771,"mc":[{"id":"1.195453752","rc":[{"atb":[[5.6,4.95],[5.3,53.93],[5.2,9.9],[5.7,0],[4.7,2.72]],"id":3805793}],"con":true,"img":false}]}
{"op":"mcm","clk":"5348046176","pt":1646213035557,"mc":[{"id":"1.195453752","rc":[{"atb":[[5.5,4.95]],"id":3805793}],"con":true,"img":false}]}
{"op":"mcm","clk":"5348046181","pt":1646213035659,"mc":[{"id":"1.195453752","rc":[{"atb":[[5.6,0],[5.2,0]],"id":3805793},{"atl":[[16,0],[14,0]],"id":3805740}],"con":true,"img":false}]}
{"op":"mcm","clk":"5348046187","pt":1646213035764,"mc":[{"id":"1.195453752","rc":[{"atl":[[16.5,9.9],[14.5,4.95]],"id":3805740}],"con":true,"img":false}]}
{"op":"mcm","clk":"5348046202","pt":1646213036176,"mc":[{"id":"1.195453752","rc":[{"atl":[[25,4.17],[27,30.78]],"id":3805740}],"con":true,"img":false}]}
{"op":"mcm","clk":"5348046214","pt":1646213036497,"mc":[{"id":"1.195453752","rc":[{"atb":[[5.1,9.9]],"id":3805793},{"atl":[[16,8.9]],"id":3805740}],"con":true,"img":false}]}
{"op":"mcm","clk":"5348046477","pt":1646213040576,"mc":[{"id":"1.195453752","rc":[{"atb":[[5.1,4.95],[5,28.24],[4.6,28.24],[4.7,12.63]],"id":3805747},{"atl":[[18.5,9.05],[18,4.95],[20,9.9],[21,0]],"id":3805746},{"atl":[[36,9.9],[38,0],[29,4.95],[30,5.46]],"id":522746},{"atl":[[32,5.11],[38,9.9],[40,0],[30,4.95]],"id":3805736},{"atb":[[17,22.08],[17.5,9.9],[19,8.8],[19.5,4.95]],"id":522750},{"atb":[[6.4,8.22],[5.8,9.9],[6.2,14.71],[5.7,0]],"id":3805731},{"atb":[[9.6,9.9],[10.5,0],[11,4.95],[9.4,0]],"id":3805762},{"atl":[[22,4.95],[23,7.2],[26,9.9],[27,0]],"id":3805730}],"con":true,"img":false}]}
{"op":"mcm","clk":"5348046489","pt":1646213040777,"mc":[{"id":"1.195453752","rc":[{"atl":[[32,3.23],[42,22.08]],"id":3805746},{"atl":[[65,2],[90,14.18]],"id":3805736},{"atl":[[65,19.63],[46,2.22]],"id":3805730}],"con":true,"img":false}]}
{"op":"mcm","clk":"5348046504","pt":1646213040986,"mc":[{"id":"1.195453752","rc":[{"atb":[[4.6,0],[5.2,37.74],[4.7,73.37]],"id":3805747},{"atl":[[20,39.36]],"id":3805746},{"atl":[[65,2]],"id":522746},{"atl":[[21,7.9],[26,35.33]],"id":3805730}],"con":true,"img":false}]}
{"op":"mcm","clk":"5348046510","pt":1646213041088,"mc":[{"id":"1.195453752","rc":[{"atl":[[17.5,9.6],[42,0]],"id":3805746},{"atl":[[36,32.77],[29,10.61]],"id":522746},{"atl":[[38,32.23],[90,0],[29,5.66]],"id":3805736},{"atb":[[17,0],[18.5,29.55],[20,8.34]],"id":522750},{"atl":[[65,0]],"id":3805730}],"con":true,"img":false}]}
{"op":"mcm","clk":"5348046555","pt":1646213041770,"mc":[{"id":"1.195453752","rc":[{"atb":[[5,0]],"id":3805747}],"con":true,"img":false}]}
{"op":"mcm","clk":"5348046564","pt":1646213041874,"mc":[{"id":"1.195453752","rc":[{"atl":[[18.5,0]],"id":3805746},{"atl":[[30,0]],"id":522746},{"atl":[[32,0]],"id":3805736},{"atb":[[19,0]],"id":522750}],"con":true,"img":false}]}
{"op":"mcm","clk":"5348046610","pt":1646213042554,"mc":[{"id":"1.195453752","rc":[{"atl":[[23,0]],"id":3805730}],"con":true,"img":false}]}
{"op":"mcm","clk":"5348046827","pt":1646213046411,"mc":[{"id":"1.195453752","rc":[{"atb":[[5.5,0],[5.3,0],[5.4,0]],"id":3805793},{"atl":[[34,4.95],[36,22.86],[42,9.9],[29,0]],"id":522746},{"atl":[[130,9.9],[85,0],[95,4.95],[110,0]],"id":522747},{"atl":[[38,4.28],[40,4.95],[46,0],[48,9.9]],"id":522750},{"atl":[[17,0],[17.5,4.95],[19,8.8],[19.5,9.9]],"id":3805762},{"atl":[[42,0],[46,4.95],[50,0],[60,9.9]],"id":522741},{"atl":[[16.5,0],[17,9.9],[14.5,0],[15,4.95]],"id":3805740}],"con":true,"img":false}]}
{"op":"mcm","clk":"5348046834","pt":1646213046494,"mc":[{"id":"1.195453752","rc":[{"atb":[[5.5,35.23]],"id":3805793}],"con":true,"img":false}]}
{"op":"mcm","clk":"5348046842","pt":1646213046571,"mc":[{"id":"1.195453752","rc":[{"atl":[[290,4.39],[220,2]],"id":522747},{"atl":[[80,2],[110,11.59]],"id":522750}],"con":true,"img":false}]}
{"op":"mcm","clk":"5348046854","pt":1646213046779,"mc":[{"id":"1.195453752","rc":[{"atl":[[48,29.66],[110,0]],"id":522750},{"atl":[[17.5,14.56],[19.5,30.36]],"id":3805762}],"con":true,"img":false}]}
{"op":"mcm","clk":"5348046858","pt":1646213046882,"mc":[{"id":"1.195453752","rc":[{"atb":[[4.2,32.72]],"id":3805793}],"con":true,"img":false}]}
{"op":"mcm","clk":"5348046863","pt":1646213046985,"mc":[{"id":"1.195453752","rc":[{"atl":[[85,2]],"id":3805762}],"con":true,"img":false}]}
{"op":"mcm","clk":"5348046868","pt":1646213047088,"mc":[{"id":"1.195453752","rc":[{"atb":[[5.5,40.18]],"id":3805793},{"atl":[[34,9.76]],"id":522746},{"atl":[[130,0],[290,0],[85,4.95],[90,1.78],[95,0],[220,8.44],[110,9.9]],"id":522747},{"atl":[[38,9.23],[40,0],[46,9.9],[48,19.75]],"id":522750},{"atl":[[42,4.95],[46,0],[50,9.9],[60,0],[120,1.32]],"id":522741},{"atl":[[16.5,9.9],[17,0],[14.5,4.95],[15,0]],"id":3805740}],"con":true,"img":false}]}
{"op":"mcm","clk":"5348046892","pt":1646213047496,"mc":[{"id":"1.195453752","rc":[{"atl":[[19,0]],"id":3805762},{"atl":[[120,13.16]],"id":522741}],"con":true,"img":false}]}
{"op":"mcm","clk":"5348046899","pt":1646213047601,"mc":[{"id":"1.195453752","rc":[{"atl":[[130,2]],"id":522741}],"con":true,"img":false}]}
{"op":"mcm","clk":"5348046946","pt":1646213048378,"mc":[{"id":"1.195453752","rc":[{"atl":[[42,41.92]],"id":522746}],"con":true,"img":false}]}
{"op":"mcm","clk":"5348046951","pt":1646213048480,"mc":[{"id":"1.195453752","rc":[{"atl":[[36,0]],"id":522746}],"con":true,"img":false}]}
{"op":"mcm","clk":"5348047000","pt":1646213049197,"mc":[{"id":"1.195453752","rc":[{"atb":[[22,9.9],[26,4.95]],"id":522743}],"con":true,"img":false}]}
{"op":"mcm","clk":"5348047009","pt":1646213049298,"mc":[{"id":"1.195453752","rc":[{"atl":[[9,9.9],[9.2,0],[8.2,4.95],[8.4,21.42]],"id":3805793},{"atb":[[21,0],[25,0]],"id":522743}],"con":true,"img":false}]}
{"op":"mcm","clk":"5348047015","pt":1646213049405,"mc":[{"id":"1.195453752","rc":[{"atb":[[5.5,4.95]],"id":3805793},{"atl":[[42,0],[50,0]],"id":522741}],"con":true,"img":false}]}
{"op":"mcm","clk":"5348047024","pt":1646213049504,"mc":[{"id":"1.195453752","rc":[{"atl":[[12.5,8.7],[15,25.34]],"id":3805793},{"atl":[[44,4.95],[55,9.9]],"id":522741}],"con":true,"img":false}]}
{"op":"mcm","clk":"5348047038","pt":1646213049672,"mc":[{"id":"1.195453752","rc":[{"atl":[[9,39.36]],"id":3805793},{"atb":[[23,3.26],[25,24.49]],"id":522743}],"con":true,"img":false}]}
{"op":"mcm","clk":"5348047047","pt":1646213049772,"mc":[{"id":"1.195453752","rc":[{"atl":[[8,22.64],[15,0]],"id":3805793}],"con":true,"img":false}]}
{"op":"mcm","clk":"5348047068","pt":1646213050183,"mc":[{"id":"1.195453752","rc":[{"atb":[[5.1,31.99]],"id":3805793}],"con":true,"img":false}]}
{"op":"mcm","clk":"5348047079","pt":1646213050389,"mc":[{"id":"1.195453752","rc":[{"atb":[[5.1,22.08],[5,9.9],[5.5,0],[5.4,4.95]],"id":3805793}],"con":true,"img":false}]}
{"op":"mcm","clk":"5348047095","pt":1646213050690,"mc":[{"id":"1.195453752","rc":[{"atl":[[8.4,0]],"id":3805793}],"con":true,"img":false}]}
{"op":"mcm","clk":"5348047108","pt":1646213050897,"mc":[{"id":"1.195453752","rc":[{"atl":[[16.5,30.5],[27,0]],"id":3805740}],"con":true,"img":false}]}
{"op":"mcm","clk":"5348047128","pt":1646213051204,"mc":[{"id":"1.195453752","rc":[{"atl":[[14.5,16.69]],"id":3805740}],"con":true,"img":false}]}
{"op":"mcm","clk":"5348047176","pt":1646213052090,"mc":[{"id":"1.195453752","rc":[{"atl":[[16,0]],"id":3805740}],"con":true,"img":false}]}
{"op":"mcm","clk":"5348047259","pt":1646213053885,"mc":[{"id":"1.195453752","rc":[{"atl":[[85,18.92]],"id":3805762}],"con":true,"img":false}]}
{"op":"mcm","clk":"5348047267","pt":1646213053989,"mc":[{"id":"1.195453752","rc":[{"atl":[[19.5,9.9]],"id":3805762}],"con":true,"img":false}]}
{"op":"mcm","clk":"5348047295","pt":1646213054584,"mc":[{"id":"1.195453752","rc":[{"atb":[[5.3,4.95],[4.9,9.9]],"id":3805793},{"atl":[[85,0],[90,6.73],[110,0],[120,9.9]],"id":522747}],"con":true,"img":false}]}
{"op":"mcm","clk":"5348047302","pt":1646213054689,"mc":[{"id":"1.195453752","rc":[{"atb":[[5,0],[5.4,0]],"id":3805793}],"con":true,"img":false}]}
{"op":"mcm","clk":"5348047343","pt":1646213055503,"mc":[{"id":"1.195453752","rc":[{"atl":[[65,24.2],[42,9.9]],"id":522746}],"con":true,"img":false}]}
{"op":"mcm","clk":"5348047463","pt":1646213058098,"mc":[{"id":"1.195453752","rc":[{"atl":[[16.5,9.9],[25,35.19]],"id":3805740}],"con":true,"img":false}]}
{"op":"mcm","clk":"5348047620","pt":1646213061293,"mc":[{"id":"1.195453752","rc":[{"atb":[[4.9,57.46],[4.2,3.26]],"id":3805793}],"con":true,"img":false}]}
{"op":"mcm","clk":"5348047628","pt":1646213061495,"mc":[{"id":"1.195453752","rc":[{"atl":[[210,0.75]],"id":522747}],"con":true,"img":false}]}
{"op":"mcm","clk":"5348047633","pt":1646213061600,"mc":[{"id":"1.195453752","rc":[{"atl":[[110,1.45]],"id":522741}],"con":true,"img":false}]}
{"op":"mcm","clk":"5348047637","pt":1646213061703,"mc":[{"id":"1.195453752","rc":[{"atb":[[5.3,41.82]],"id":3805793}],"con":true,"img":false}]}
{"op":"mcm","clk":"5348047648","pt":1646213062007,"mc":[{"id":"1.195453752","rc":[{"atl":[[210,7.71],[220,2]],"id":522747}],"con":true,"img":false}]}
{"op":"mcm","clk":"5348047654","pt":1646213062107,"mc":[{"id":"1.195453752","rc":[{"atl":[[110,14.74],[120,1.32]],"id":522741}],"con":true,"img":false}]}
{"op":"mcm","clk":"5348047661","pt":1646213062313,"mc":[{"id":"1.195453752","rc":[{"atl":[[210,6.95]],"id":522747}],"con":true,"img":false}]}
{"op":"mcm","clk":"5348047667","pt":1646213062417,"mc":[{"id":"1.195453752","rc":[{"atb":[[5.1,0]],"id":3805793}],"con":true,"img":false}]}
{"op":"mcm","clk":"5348047670","pt":1646213062520,"mc":[{"id":"1.195453752","rc":[{"atl":[[120,0]],"id":522741}],"con":true,"img":false}]}
{"op":"mcm","clk":"5348047986","pt":1646213068211,"mc":[{"id":"1.195453752","rc":[{"atb":[[4.9,9.9],[4.7,94.89]],"id":3805793}],"con":true,"img":false}]}
{"op":"mcm","clk":"5348048450","pt":1646213075913,"mc":[{"id":"1.195453752","rc":[{"atl":[[44,8.64]],"id":522741}],"con":true,"img":false}]}
{"op":"mcm","clk":"5348048513","pt":1646213076734,"mc":[{"id":"1.195453752","rc":[{"atb":[[5.8,20.83],[6.8,0]],"id":3805746},{"atl":[[110,13.28]],"id":522741}],"con":true,"img":false}]}
{"op":"mcm","clk":"5348048534","pt":1646213077045,"mc":[{"id":"1.195453752","rc":[{"atb":[[11,9.9],[13,4.95]],"id":522742}],"con":true,"img":false}]}
{"op":"mcm","clk":"5348048542","pt":1646213077107,"mc":[{"id":"1.195453752","rc":[{"atb":[[10.5,0],[12.5,11.63]],"id":522742}],"con":true,"img":false}]}
{"op":"mcm","clk":"5348048561","pt":1646213077519,"mc":[{"id":"1.195453752","rc":[{"atb":[[10,3.26],[11,43.21],[13.5,12.68]],"id":522742}],"con":true,"img":false}]}
{"op":"mcm","clk":"5348048603","pt":1646213078441,"mc":[{"id":"1.195453752","rc":[{"atb":[[12.5,2.72]],"id":522742}],"con":true,"img":false}]}
{"op":"mcm","clk":"5348049031","pt":1646213085841,"mc":[{"id":"1.195453752","rc":[{"atl":[[23,4.95],[27,9.9]],"id":3805730}],"con":true,"img":false}]}
{"op":"mcm","clk":"5348049040","pt":1646213085945,"mc":[{"id":"1.195453752","rc":[{"atl":[[22,0],[26,25.42]],"id":3805730}],"con":true,"img":false}]}
{"op":"mcm","clk":"5348049077","pt":1646213086443,"mc":[{"id":"1.195453752","rc":[{"atl":[[26,0]],"id":3805730}],"con":true,"img":false}]}
{"op":"mcm","clk":"5348049109","pt":1646213087053,"mc":[{"id":"1.195453752","rc":[{"atl":[[27,36.39]],"id":3805730}],"con":true,"img":false}]}
{"op":"mcm","clk":"5348049312","pt":1646213091336,"mc":[{"id":"1.195453752","rc":[{"atb":[[11,9.9],[12.5,36.03]],"id":522742}],"con":true,"img":false}]}
{"op":"mcm","clk":"5348049663","pt":1646213097555,"mc":[{"id":"1.195453752","rc":[{"atl":[[17.5,14.56],[18,0],[19.5,9.9],[20,29.45]],"id":3805746},{"atl":[[34,4.8],[36,9.9],[42,0],[29,4.95]],"id":522746},{"atb":[[6.4,3.26],[5.8,0],[6.8,4.95],[6,9.9]],"id":3805731}],"con":true,"img":false}]}
{"op":"mcm","clk":"5348049680","pt":1646213097961,"mc":[{"id":"1.195453752","rc":[{"atl":[[65,2],[36,31.99],[29,10.61]],"id":522746},{"atb":[[6.4,25.35],[6.2,0]],"id":3805731}],"con":true,"img":false}]}
{"op":"mcm","clk":"5348049717","pt":1646213098641,"mc":[{"id":"1.195453752","rc":[{"atl":[[34,0]],"id":522746}],"con":true,"img":false}]}
{"op":"mcm","clk":"5348049826","pt":1646213100861,"mc":[{"id":"1.195453752","rc":[{"atb":[[6.4,0],[7.4,15.62]],"id":522742}],"con":true,"img":false}]}
{"op":"mcm","clk":"5348050010","pt":1646213103749,"mc":[{"id":"1.195453752","rc":[{"atb":[[5.8,4.95],[5.3,36.86],[4.9,0],[5.4,9.9]],"id":3805793},{"atl":[[75,4.95],[90,1.78],[95,9.9],[120,0]],"id":522747},{"atl":[[42,4.95],[44,3.68],[50,9.9],[55,0]],"id":522741},{"atl":[[16.5,0],[16,9.9],[14,4.95],[14.5,11.74]],"id":3805740}],"con":true,"img":false}]}
{"op":"mcm","clk":"5348050033","pt":1646213104163,"mc":[{"id":"1.195453752","rc":[{"atb":[[5.8,37.98],[5.3,85.26],[4.7,2.72]],"id":3805793},{"atl":[[70,2.29],[95,26.55],[210,0]],"id":522747},{"atl":[[40,4.06],[50,31.99],[110,0]],"id":522741},{"atl":[[16,31.99],[25,4.17],[14,17.15]],"id":3805740}],"con":true,"img":false}]}
{"op":"mcm","clk":"5348050047","pt":1646213104465,"mc":[{"id":"1.195453752","rc":[{"atb":[[5.8,33.03],[5.7,4.95],[5.4,0]],"id":3805793},{"atl":[[65,26.33],[36,9.9]],"id":522746}],"con":true,"img":false}]}
{"op":"mcm","clk":"5348050068","pt":1646213104979,"mc":[{"id":"1.195453752","rc":[{"atb":[[5.3,48.39]],"id":3805793},{"atl":[[44,0]],"id":522741}],"con":true,"img":false}]}
{"op":"mcm","clk":"5348050072","pt":1646213105037,"mc":[{"id":"1.195453752","rc":[{"atl":[[90,0]],"id":522747},{"atl":[[14.5,0]],"id":3805740}],"con":true,"img":false}]}
{"op":"mcm","clk":"5348050139","pt":1646213106479,"mc":[{"id":"1.195453752","rc":[{"atb":[[11.5,22.08],[12,9.9],[13.5,12.68],[14,4.95]],"id":3805730}],"con":true,"img":false}]}
{"op":"mcm","clk":"5348050145","pt":1646213106583,"mc":[{"id":"1.195453752","rc":[{"atl":[[8.2,0],[7.4,24.76]],"id":3805747}],"con":true,"img":false}]}
{"op":"mcm","clk":"5348050154","pt":1646213106844,"mc":[{"id":"1.195453752","rc":[{"atl":[[8,9.9],[7.2,4.95]],"id":3805747}],"con":true,"img":false}]}
{"op":"mcm","clk":"5348050160","pt":1646213106950,"mc":[{"id":"1.195453752","rc":[{"atb":[[11.5,0],[12.5,21.83],[14.5,11.74]],"id":3805730}],"con":true,"img":false}]}
{"op":"mcm","clk":"5348050164","pt":1646213107049,"mc":[{"id":"1.195453752","rc":[{"atl":[[12,9.09],[7.8,110.97]],"id":3805747}],"con":true,"img":false}]}
{"op":"mcm","clk":"5348050179","pt":1646213107360,"mc":[{"id":"1.195453752","rc":[{"atl":[[7,26.42]],"id":3805747},{"atb":[[5.8,0]],"id":3805793},{"atl":[[70,0]],"id":522747},{"atl":[[16,22.08],[16.5,9.9],[14,0],[14.5,4.95]],"id":3805740}],"con":true,"img":false}]}
{"op":"mcm","clk":"5348050195","pt":1646213107674,"mc":[{"id":"1.195453752","rc":[{"atb":[[13.5,0]],"id":3805730}],"con":true,"img":false}]}
{"op":"mcm","clk":"5348050217","pt":1646213108179,"mc":[{"id":"1.195453752","rc":[{"atl":[[7.4,0]],"id":3805747},{"atb":[[5.3,85.26]],"id":3805793},{"atl":[[75,7.09]],"id":522747},{"atl":[[16,32.65]],"id":3805740}],"con":true,"img":false}]}
{"op":"mcm","clk":"5348050339","pt":1646213110693,"mc":[{"id":"1.195453752","rc":[{"atb":[[5.3,36.86],[4.7,43.74]],"id":3805793},{"atl":[[95,9.9],[220,9.26]],"id":522747},{"atl":[[16,10.56],[16.5,31.99]],"id":3805740}],"con":true,"img":false}]}
{"op":"mcm","clk":"5348050460","pt":1646213112975,"mc":[{"id":"1.195453752","rc":[{"atl":[[75,2.14],[80,4.95],[95,0],[100,9.9]],"id":522747}],"con":true,"img":false}]}
{"op":"mcm","clk":"5348050518","pt":1646213113892,"mc":[{"id":"1.195453752","rc":[{"atl":[[80,0],[100,0]],"id":522747}],"con":true,"img":false}]}
{"op":"mcm","clk":"5348050579","pt":1646213114681,"mc":[{"id":"1.195453752","rc":[{"atl":[[75,7.09],[95,9.9]],"id":522747}],"con":true,"img":false}]}
{"op":"mcm","clk":"5348050768","pt":1646213117468,"mc":[{"id":"1.195453752","rc":[{"atb":[[5.7,38.68]],"id":3805793},{"atl":[[14.5,16.69]],"id":3805740}],"con":true,"img":false}]}
{"op":"mcm","clk":"5348050801","pt":1646213118185,"mc":[{"id":"1.195453752","rc":[{"atb":[[5.3,0]],"id":3805793},{"atl":[[75,2.14],[80,4.95],[95,0],[100,9.9]],"id":522747},{"atl":[[16,0]],"id":3805740}],"con":true,"img":false}]}
{"op":"mcm","clk":"5348050826","pt":1646213118697,"mc":[{"id":"1.195453752","rc":[{"atb":[[4.2,94.44],[4.7,2.72]],"id":3805793},{"atl":[[100,26.12],[220,2]],"id":522747},{"atl":[[16.5,9.9],[25,35.19]],"id":3805740}],"con":true,"img":false}]}
{"op":"mcm","clk":"5348051181","pt":1646213124503,"mc":[{"id":"1.195453752","rc":[{"atl":[[9.8,11.36]],"id":3805747}],"con":true,"img":false}]}
{"op":"mcm","clk":"5348051190","pt":1646213124594,"mc":[{"id":"1.195453752","rc":[{"atl":[[12,0]],"id":3805747}],"con":true,"img":false}]}
{"op":"mcm","clk":"5348051213","pt":1646213124891,"mc":[{"id":"1.195453752","rc":[{"atb":[[22,0],[23,13.17],[26,0],[27,4.95]],"id":522743}],"con":true,"img":false}]}
{"op":"mcm","clk":"5348051227","pt":1646213125193,"mc":[{"id":"1.195453752","rc":[{"atb":[[12.5,31.99],[15,8.9]],"id":522746},{"atb":[[12,0],[14.5,0]],"id":3805736},{"atb":[[34,4.8],[27,14.71]],"id":522747},{"atb":[[18.5,14.71],[22,7.54]],"id":522741},{"atb":[[9.6,0],[8.6,0]],"id":3805740}],"con":true,"img":false}]}
{"op":"mcm","clk":"5348051252","pt":1646213125605,"mc":[{"id":"1.195453752","rc":[{"atb":[[9.8,51.31],[14,9.9]],"id":3805736},{"atb":[[8,40.08],[5.9,77.92]],"id":3805740}],"con":true,"img":false}]}
{"op":"mcm","clk":"5348051255","pt":1646213125669,"mc":[{"id":"1.195453752","rc":[{"atb":[[8,27.6]],"id":3805740}],"con":true,"img":false}]}
{"op":"mcm","clk":"5348051269","pt":1646213125877,"mc":[{"id":"1.195453752","rc":[{"atb":[[13,3.26],[15.5,2.72]],"id":522746},{"atb":[[12.5,3.26],[15,2.72]],"id":3805736},{"atb":[[36,2.72],[28,3.26]],"id":522747},{"atb":[[19,3.26],[23,2.72]],"id":522741},{"atb":[[9,3.26],[10,2.72]],"id":3805740}],"con":true,"img":false}]}
{"op":"mcm","clk":"5348051294","pt":1646213126287,"mc":[{"id":"1.195453752","rc":[{"atb":[[16,10.56],[12.5,9.9],[14.5,32.92]],"id":522746},{"atb":[[38,4.28],[27,0],[30,19.46]],"id":522747},{"atb":[[18.5,0],[20,19.66],[24,6.89]],"id":522741},{"atb":[[5.9,27.18]],"id":3805740}],"con":true,"img":false}]}
{"op":"mcm","clk":"5348051341","pt":1646213127105,"mc":[{"id":"1.195453752","rc":[{"atb":[[15,0]],"id":522746},{"atb":[[34,0]],"id":522747},{"atb":[[22,0]],"id":522741}],"con":true,"img":false}]}
{"op":"mcm","clk":"5348051827","pt":1646213135413,"mc":[{"id":"1.195453752","rc":[{"atb":[[6.4,22.08],[7.4,0]],"id":3805731}],"con":true,"img":false}]}
{"op":"mcm","clk":"5348051865","pt":1646213135985,"mc":[{"id":"1.195453752","rc":[{"atb":[[6.4,0],[6.8,32.29],[6,53.87]],"id":3805731}],"con":true,"img":false}]}
{"op":"mcm","clk":"5348051870","pt":1646213136098,"mc":[{"id":"1.195453752","rc":[{"atb":[[7.6,2.72],[6.6,3.26]],"id":3805731}],"con":true,"img":false}]}
{"op":"mcm","clk":"5348052000","pt":1646213138412,"mc":[{"id":"1.195453752","rc":[{"atb":[[9.8,11.36],[14,33.04]],"id":3805736}],"con":true,"img":false}]}
{"op":"mcm","clk":"5348052003","pt":1646213138520,"mc":[{"id":"1.195453752","rc":[{"atb":[[8,67.15]],"id":3805740}],"con":true,"img":false}]}
{"op":"mcm","clk":"5348052093","pt":1646213140049,"mc":[{"id":"1.195453752","rc":[{"atb":[[18.5,0],[19,9.9],[21,7.92],[22,4.95]],"id":3805755}],"con":true,"img":false}]}
{"op":"mcm","clk":"5348052143","pt":1646213140626,"mc":[{"id":"1.195453752","rc":[{"atb":[[18,2.72],[19,38.37],[23,7.2]],"id":3805755},{"atl":[[36,4.95],[38,4.28],[44,9.9],[46,0]],"id":522750},{"atl":[[23,0],[24,4.95],[27,26.48],[28,9.9]],"id":3805730},{"atb":[[9.6,0],[10.5,4.95],[11,0]],"id":3805762}],"con":true,"img":false}]}
{"op":"mcm","clk":"5348052174","pt":1646213141093,"mc":[{"id":"1.195453752","rc":[{"atl":[[36,9.48],[44,29.66],[48,0]],"id":522750}],"con":true,"img":false}]}
{"op":"mcm","clk":"5348052190","pt":1646213141407,"mc":[{"id":"1.195453752","rc":[{"atb":[[21,0]],"id":3805755},{"atb":[[9.4,9.9]],"id":3805762}],"con":true,"img":false}]}
{"op":"mcm","clk":"5348052203","pt":1646213141616,"mc":[{"id":"1.195453752","rc":[{"atb":[[2.6,62.5],[2.34,0]],"id":3805793},{"atb":[[5.8,0],[6.6,17.86]],"id":3805762}],"con":true,"img":false}]}
{"op":"mcm","clk":"5348052215","pt":1646213141815,"mc":[{"id":"1.195453752","rc":[{"atl":[[38,0]],"id":522750}],"con":true,"img":false}]}
{"op":"mcm","clk":"5348052233","pt":1646213142119,"mc":[{"id":"1.195453752","rc":[{"atb":[[9.6,9.9],[11,4.95]],"id":3805762}],"con":true,"img":false}]}
{"op":"mcm","clk":"5348052241","pt":1646213142224,"mc":[{"id":"1.195453752","rc":[{"atb":[[10.5,0],[9.4,0]],"id":3805762}],"con":true,"img":false}]}
{"op":"mcm","clk":"5348052280","pt":1646213142639,"mc":[{"id":"1.195453752","rc":[{"atb":[[10.5,22.08],[9.8,3.26]],"id":3805762}],"con":true,"img":false}]}
{"op":"mcm","clk":"5348052564","pt":1646213147240,"mc":[{"id":"1.195453752","rc":[{"atl":[[80,23.28],[44,9.9]],"id":522750}],"con":true,"img":false}]}
{"op":"mcm","clk":"5348052636","pt":1646213148628,"mc":[{"id":"1.195453752","rc":[{"atb":[[6,9.9],[6.6,47.23]],"id":3805731}],"con":true,"img":false}]}
{"op":"mcm","clk":"5348052644","pt":1646213148835,"mc":[{"id":"1.195453752","rc":[{"atb":[[18,0],[15.5,0]],"id":3805755},{"atb":[[16,0],[18.5,26.82]],"id":522750}],"con":true,"img":false}]}
{"op":"mcm","clk":"5348052676","pt":1646213149514,"mc":[{"id":"1.195453752","rc":[{"atb":[[16,3.26],[18.5,2.72]],"id":3805755},{"atb":[[16.5,3.26],[19,2.72]],"id":522750}],"con":true,"img":false}]}
{"op":"mcm","clk":"5348052701","pt":1646213150022,"mc":[{"id":"1.195453752","rc":[{"atb":[[18.5,0],[19,29.21]],"id":522750}],"con":true,"img":false}]}
{"op":"mcm","clk":"5348052704","pt":1646213150125,"mc":[{"id":"1.195453752","rc":[{"atb":[[7.6,0],[6.6,43.96]],"id":3805731}],"con":true,"img":false}]}
{"op":"mcm","clk":"5348052744","pt":1646213151008,"mc":[{"id":"1.195453752","rc":[{"atb":[[6.4,3.26],[7.4,2.72]],"id":3805731}],"con":true,"img":false}]}
{"op":"mcm","clk":"5348052773","pt":1646213151730,"mc":[{"id":"1.195453752","rc":[{"atl":[[32,9.9],[36,0],[27,4.95],[29,5.66]],"id":522746}],"con":true,"img":false}]}
{"op":"mcm","clk":"5348052787","pt":1646213152030,"mc":[{"id":"1.195453752","rc":[{"atb":[[8,22.08],[7,0]],"id":3805746}],"con":true,"img":false}]}
{"op":"mcm","clk":"5348052794","pt":1646213152235,"mc":[{"id":"1.195453752","rc":[{"atl":[[32,33.04],[65,2],[27,11.05]],"id":522746}],"con":true,"img":false}]}
{"op":"mcm","clk":"5348052820","pt":1646213152752,"mc":[{"id":"1.195453752","rc":[{"atb":[[2.46,0],[2.66,0],[3.15,0]],"id":3805747},{"atb":[[2.92,0],[4.6,0],[3.3,0]],"id":3805746},{"atb":[[3.1,0],[2.64,0],[2.44,0]],"id":3805793},{"atb":[[5.5,0],[12.5,0],[7,0]],"id":3805755},{"atb":[[5.6,0],[9.2,12.2],[4.6,0]],"id":522746},{"atb":[[5.6,0],[9.2,0],[4.6,0]],"id":3805736},{"atb":[[21,0],[10.5,0],[8.2,0]],"id":522747},{"atb":[[5.5,0],[12.5,0],[7,0]],"id":522750},{"atb":[[5,0],[3,0],[3.5,0]],"id":3805731},{"atb":[[5.2,0],[8.4,0],[4.2,0]],"id":3805762},{"atb":[[4.5,0],[7,0],[3.75,0]],"id":3805730},{"atb":[[8,0],[6,0],[15,0]],"id":522741},{"atb":[[7.2,0],[4.6,0],[3.8,0]],"id":522742},{"atb":[[17.5,0],[9,0],[7,0]],"id":522743},{"atb":[[3.45,0],[3.95,0],[5.9,0]],"id":3805740}],"con":true,"img":false}]}
{"op":"mcm","clk":"5348052826","pt":1646213152817,"mc":[{"id":"1.195453752","rc":[{"atb":[[7.2,3.26],[8.2,2.72]],"id":3805746}],"con":true,"img":false}]}
{"op":"mcm","clk":"5348052843","pt":1646213153123,"mc":[{"id":"1.195453752","rc":[{"atl":[[29,0]],"id":522746}],"con":true,"img":false}]}
{"op":"mcm","clk":"5348052850","pt":1646213153231,"mc":[{"id":"1.195453752","rc":[{"atb":[[8,0],[8.2,39.09]],"id":3805746}],"con":true,"img":false}]}
{"op":"mcm","clk":"5348053098","pt":1646213157628,"mc":[{"id":"1.195453752","rc":[{"atb":[[5.5,9.9],[5.7,33.73],[5.9,4.95]],"id":3805793},{"atl":[[75,7.09],[80,0],[95,9.9],[100,16.21]],"id":522747},{"atl":[[40,9.01],[42,0],[48,9.9],[50,22.08]],"id":522741},{"atl":[[13.5,4.95],[15.5,9.9]],"id":3805740}],"con":true,"img":false}]}
{"op":"mcm","clk":"5348053104","pt":1646213157729,"mc":[{"id":"1.195453752","rc":[{"atl":[[16.5,0],[14.5,11.74]],"id":3805740}],"con":true,"img":false}]}
{"op":"mcm","clk":"5348053119","pt":1646213158038,"mc":[{"id":"1.195453752","rc":[{"atb":[[5.5,58.3],[6,31.7],[4.2,3.26]],"id":3805793},{"atl":[[25,4.17],[13,13.21],[15.5,31.99]],"id":3805740}],"con":true,"img":false}]}
{"op":"mcm","clk":"5348053132","pt":1646213158242,"mc":[{"id":"1.195453752","rc":[{"atl":[[32,9.9],[65,28.68]],"id":522746}],"con":true,"img":false}]}
{"op":"mcm","clk":"5348053170","pt":1646213158922,"mc":[{"id":"1.195453752","rc":[{"atb":[[5.7,0]],"id":3805793},{"atl":[[14.5,0]],"id":3805740}],"con":true,"img":false}]}
{"op":"mcm","clk":"5348053387","pt":1646213162943,"mc":[{"id":"1.195453752","rc":[{"atb":[[9,16.64],[4.5,76.11],[5.5,59.19]],"id":522746},{"atb":[[21,6.65],[10.5,28.03],[8.2,36.99]],"id":522747},{"atb":[[3.6,102.45],[3.1,126.85],[5.2,31.71]],"id":3805731},{"atb":[[4.8,70.1],[7.6,35.33],[3.9,91.85]],"id":3805730},{"atb":[[6.2,51.22],[8.2,36.99],[15.5,9.18]],"id":522741},{"atb":[[3.95,90.29],[4.9,68.3],[7.8,19.58]],"id":522742},{"atb":[[18.5,7.61],[7.4,41.62],[9.4,31.71]],"id":522743}],"con":true,"img":false}]}
{"op":"mcm","clk":"5348053395","pt":1646213163046,"mc":[{"id":"1.195453752","rc":[{"atb":[[3.1,63.42],[2.64,162.43],[2.44,184.99]],"id":3805747},{"atb":[[4.5,38.05],[2.9,140.2],[3.25,118.39]],"id":3805746},{"atb":[[2.42,187.6],[2.62,164.43],[3.05,64.97]],"id":3805793},{"atb":[[12,12.1],[6.8,45.93],[5.4,60.54]],"id":3805755},{"atb":[[8.8,17.07],[4.4,78.34],[5.4,60.54]],"id":3805736},{"atb":[[5.5,59.19],[12.5,11.58],[7,44.4]],"id":522750},{"atb":[[5.2,63.42],[8.4,18],[4.2,83.24]],"id":3805762},{"atb":[[5.8,27.75],[3.4,110.99],[3.9,91.85]],"id":3805740}],"con":true,"img":false}]}
{"op":"mcm","clk":"5348053560","pt":1646213166459,"mc":[{"id":"1.195453752","rc":[{"atb":[[12,0],[14,0]],"id":3805730}],"con":true,"img":false}]}
{"op":"mcm","clk":"5348053574","pt":1646213166662,"mc":[{"id":"1.195453752","rc":[{"atb":[[12.5,31.74],[14.5,16.69]],"id":3805730}],"con":true,"img":false}]}
{"op":"mcm","clk":"5348053595","pt":1646213166928,"mc":[{"id":"1.195453752","rc":[{"atb":[[10,32.47],[12.5,12.63]],"id":3805730}],"con":true,"img":false}]}
{"op":"mcm","clk":"5348053657","pt":1646213167958,"mc":[{"id":"1.195453752","rc":[{"atl":[[70,4.95],[75,2.14],[90,9.9],[95,0]],"id":522747}],"con":true,"img":false}]}
{"op":"mcm","clk":"5348053683","pt":1646213168421,"mc":[{"id":"1.195453752","rc":[{"atl":[[65,2.47],[90,23.62]],"id":522747}],"con":true,"img":false}]}
{"op":"mcm","clk":"5348053687","pt":1646213168528,"mc":[{"id":"1.195453752","rc":[{"atl":[[100,0]],"id":522747}],"con":true,"img":false}]}
{"op":"mcm","clk":"5348053725","pt":1646213169248,"mc":[{"id":"1.195453752","rc":[{"atl":[[75,0]],"id":522747}],"con":true,"img":false}]}
{"op":"mcm","clk":"5348053833","pt":1646213171358,"mc":[{"id":"1.195453752","rc":[{"atl":[[9.8,0]],"id":3805747}],"con":true,"img":false}]}
{"op":"mcm","clk":"5348053838","pt":1646213171461,"mc":[{"id":"1.195453752","rc":[{"atl":[[9.2,12.2]],"id":3805747}],"con":true,"img":false}]}
{"op":"mcm","clk":"5348054131","pt":1646213176942,"mc":[{"id":"1.195453752","rc":[{"atb":[[13,0],[15.5,0]],"id":522746},{"atb":[[12.5,0]],"id":3805736},{"atb":[[36,0],[28,0]],"id":522747},{"atb":[[10,29.2],[12.5,9.9]],"id":3805730},{"atb":[[19,0],[23,0]],"id":522741},{"atb":[[10,0],[12.5,33.3]],"id":522742},{"atb":[[23,9.9],[28,5.86]],"id":522743}],"con":true,"img":false}]}
{"op":"mcm","clk":"5348054134","pt":1646213177046,"mc":[{"id":"1.195453752","rc":[{"atb":[[15,0]],"id":3805736}],"con":true,"img":false}]}
{"op":"mcm","clk":"5348054144","pt":1646213177354,"mc":[{"id":"1.195453752","rc":[{"atb":[[12.5,42.04],[14.5,4.95]],"id":522746},{"atb":[[26,31.99],[30,4.95]],"id":522747},{"atb":[[18,39.36],[20,4.95]],"id":522741}],"con":true,"img":false}]}
{"op":"mcm","clk":"5348054158","pt":1646213177665,"mc":[{"id":"1.195453752","rc":[{"atb":[[16,13.29],[13.5,3.26]],"id":522746},{"atb":[[9.8,51.31],[13,3.26],[14,9.9]],"id":3805736},{"atb":[[38,7],[29,3.26]],"id":522747},{"atb":[[10.5,3.26],[13,2.72]],"id":3805730},{"atb":[[20,8.22],[25,2.72]],"id":522741},{"atb":[[25,27.76],[30,2.72]],"id":522743}],"con":true,"img":false}]}
{"op":"mcm","clk":"5348054167","pt":1646213177876,"mc":[{"id":"1.195453752","rc":[{"atb":[[15.5,2.72]],"id":3805736},{"atb":[[10.5,3.26],[13,7.67]],"id":522742}],"con":true,"img":false}]}
{"op":"mcm","clk":"5348054174","pt":1646213178073,"mc":[{"id":"1.195453752","rc":[{"atb":[[25,9.33]],"id":522741},{"atb":[[32,5.11],[25,3.26]],"id":522743}],"con":true,"img":false}]}
{"op":"mcm","clk":"5348054178","pt":1646213178178,"mc":[{"id":"1.195453752","rc":[{"atb":[[27,25.4]],"id":522743}],"con":true,"img":false}]}
{"op":"mcm","clk":"5348054215","pt":1646213178957,"mc":[{"id":"1.195453752","rc":[{"atb":[[24,0]],"id":522741},{"atb":[[28,0]],"id":522743}],"con":true,"img":false}]}
{"op":"mcm","clk":"5348054219","pt":1646213179058,"mc":[{"id":"1.195453752","rc":[{"atb":[[10,0],[12.5,36.39]],"id":3805730}],"con":true,"img":false}]}
{"op":"mcm","clk":"5348054359","pt":1646213182071,"mc":[{"id":"1.195453752","rc":[{"atb":[[25,2.72]],"id":522741},{"atl":[[40,4.95]],"id":522741}],"con":true,"img":false}]}
{"op":"mcm","clk":"5348054376","pt":1646213182480,"mc":[{"id":"1.195453752","rc":[{"atl":[[130,0],[95,2]],"id":522741}],"con":true,"img":false}]}
{"op":"mcm","clk":"5348054390","pt":1646213182751,"mc":[{"id":"1.195453752","rc":[{"atb":[[20,16.56]],"id":522741},{"atl":[[48,13.28]],"id":522741}],"con":true,"img":false}]}
{"op":"mcm","clk":"5348056060","pt":1646213212411,"mc":[{"id":"1.195453752","rc":[{"atb":[[3.1,0],[2.64,0],[2.44,0]],"id":3805747},{"atb":[[4.5,0],[2.9,0],[3.25,0]],"id":3805746},{"atb":[[2.42,0],[2.62,0],[3.05,0]],"id":3805793},{"atb":[[12,0],[6.8,0],[5.4,0]],"id":3805755},{"atb":[[9,0],[4.5,0],[5.5,0]],"id":522746},{"atb":[[8.8,0],[4.4,0],[5.4,0]],"id":3805736},{"atb":[[21,0],[10.5,0],[8.2,0]],"id":522747},{"atb":[[5.5,0],[12.5,0],[7,0]],"id":522750},{"atb":[[3.6,0],[3.1,0],[5.2,0]],"id":3805731},{"atb":[[4.8,0],[7.6,15.15],[3.9,0]],"id":3805730},{"atb":[[5.2,0],[8.4,0],[4.2,0]],"id":3805762},{"atb":[[6.2,0],[8.2,0],[15.5,0]],"id":522741},{"atb":[[3.95,0],[4.9,0],[7.8,0]],"id":522742},{"atb":[[18.5,0],[7.4,0],[9.4,0]],"id":522743},{"atb":[[5.8,0],[3.4,0],[3.9,0]],"id":3805740}],"con":true,"img":false}]}
{"op":"mcm","clk":"5348056078","pt":1646213212778,"mc":[{"id":"1.195453752","rc":[{"atb":[[4,0]],"id":3805747},{"atl":[[9.2,0]],"id":3805747},{"atb":[[4.6,0]],"id":3805731},{"atl":[[13.5,26.62]],"id":3805731},{"atb":[[6.6,0]],"id":3805762},{"atl":[[85,16.92]],"id":3805762}],"con":true,"img":false}]}
{"op":"mcm","clk":"5348056082","pt":1646213212878,"mc":[{"id":"1.195453752","rc":[{"atb":[[5.8,0]],"id":3805746},{"atl":[[32,0]],"id":3805746}],"con":true,"img":false}]}
{"op":"mcm","clk":"5348056086","pt":1646213212983,"mc":[{"id":"1.195453752","rc":[{"atb":[[2.6,0]],"id":3805793},{"atl":[[12.5,0]],"id":3805793},{"atb":[[11.5,0]],"id":3805755},{"atl":[[110,11.59]],"id":3805755},{"atb":[[9.2,0]],"id":522746},{"atl":[[65,26.68]],"id":522746},{"atb":[[7.6,0]],"id":3805730},{"atl":[[46,0]],"id":3805730},{"atb":[[10,0]],"id":522741},{"atl":[[95,0]],"id":522741}],"con":true,"img":false}]}
{"op":"mcm","clk":"5348056091","pt":1646213213087,"mc":[{"id":"1.195453752","rc":[{"atb":[[9.8,39.95]],"id":3805736},{"atl":[[65,0]],"id":3805736},{"atb":[[14,0]],"id":522747},{"atl":[[220,0]],"id":522747},{"atb":[[11,0]],"id":522750},{"atl":[[80,21.28]],"id":522750},{"atb":[[7.4,0]],"id":522742},{"atl":[[65,19.63]],"id":522742},{"atb":[[12,0]],"id":522743},{"atl":[[180,7.08]],"id":522743},{"atb":[[5.1,0]],"id":3805740},{"atl":[[25,0]],"id":3805740}],"con":true,"img":false}]}
{"op":"mcm","clk":"5348056209","pt":1646213215224,"mc":[{"id":"1.195453752","rc":[{"atb":[[4.8,12.63],[5.1,0],[4.3,3.26],[5.2,4.95],[3.9,2.72],[4.2,0],[4.7,0]],"id":3805747},{"atl":[[9.6,1.9],[7,0],[7.8,0]],"id":3805747},{"atb":[[5.6,2.72],[7.2,0],[10,0],[9.2,0],[10.5,4.95],[8.2,0],[9.4,9.9]],"id":3805746},{"atl":[[17.5,4.95],[36,0.47],[20,0]],"id":3805746},{"atb":[[2.56,2.72],[4.6,2.72],[5.5,9.9],[4.1,3.26],[6,0],[4.2,0],[4.7,0]],"id":3805793},{"atl":[[8,4.95],[9,0],[8.2,0],[8.8,9.9],[13.5,1.31]],"id":3805793},{"atb":[[16,0],[18.5,0],[19,9.9],[10.5,1.72]],"id":3805755},{"atl":[[130,0.13],[110,0]],"id":3805755},{"atb":[[16,0],[12.5,9.9],[13.5,0],[8.8,2.1]],"id":522746},{"atl":[[32,0],[65,0],[36,9.9],[75,0.22],[27,0],[29,4.95]],"id":522746},{"atb":[[6.4,0],[1.01,2.72],[7.4,0],[6.8,4.95],[7.6,2.72],[4.4,2.72],[6.6,3.26]],"id":3805731},{"atl":[[9.6,0],[10.5,9.9],[11,0],[13.5,0],[14.5,1.21],[9.4,4.95]],"id":3805731},{"atb":[[10.5,0],[13,0]],"id":3805730},{"atb":[[9.6,0],[1.01,2.72],[10.5,0],[6.2,2.72],[11,0],[12,0],[9.8,0]],"id":3805762},{"atl":[[16,4.95],[17.5,0],[18,9.9],[19.5,0],[85,0],[95,0.17]],"id":3805762}],"con":true,"img":false}]}
{"op":"mcm","clk":"5348056222","pt":1646213215532,"mc":[{"id":"1.195453752","rc":[{"atb":[[18,2.72],[15.5,3.26]],"id":3805755},{"atb":[[16,0],[16.5,4.95],[9.8,0],[13,0],[14,0],[14.5,9.9],[15.5,0],[9.4,1.95]],"id":3805736},{"atl":[[75,0.22],[38,9.9],[29,0]],"id":3805736},{"atb":[[32,4.95],[36,2.72],[38,4.28],[26,0],[13,1.36],[27,9.9],[28,3.26],[29,0],[30,0]],"id":522747},{"atl":[[65,0],[90,9.9],[240,0.07]],"id":522747},{"atb":[[16.5,0],[19,0],[10,1.82]],"id":522750},{"atl":[[80,0],[90,0.19]],"id":522750},{"atb":[[7.2,2.64],[10,3.26],[11.5,9.9],[12.5,2.72],[13.5,4.95],[14.5,11.74]],"id":3805730},{"atl":[[23,4.95],[24,0],[50,0.33],[27,9.9],[28,0]],"id":3805730},{"atb":[[9.6,1.9],[18,9.9],[19.5,3.26],[1.01,2.72],[20,13.29],[24,2.72],[25,0]],"id":522741},{"atl":[[40,0],[44,4.95],[48,3.37],[50,0],[55,9.9],[110,0.15],[1000,0.02]],"id":522741},{"atb":[[10.5,0],[12.5,0],[13,4.95],[13.5,0],[7,2.72]],"id":522742},{"atl":[[65,0],[75,0.22],[21,4.95],[22,0],[25,9.9],[26,0]],"id":522742},{"atb":[[11,1.64],[23,13.17],[25,0],[27,4.95],[28,2.72],[30,0]],"id":522743},{"atl":[[180,0],[200,0.08]],"id":522743},{"atb":[[8,4.95],[7.2,0],[9,0],[1.01,2.72],[10,0],[4.9,2.72],[8.8,4.95]],"id":3805740},{"atl":[[13,4.95],[13.5,0],[27,0.63],[15,9.9],[15.5,0]],"id":3805740}],"con":true,"img":false}]}
{"op":"mcm","clk":"5348056238","pt":1646213215851,"mc":[{"id":"1.195453752","rc":[{"atl":[[9.2,11.4]],"id":3805731}],"con":true,"img":false}]}
{"op":"mcm","clk":"5348056244","pt":1646213215943,"mc":[{"id":"1.195453752","rc":[{"atl":[[15.5,1.13]],"id":3805762}],"con":true,"img":false}]}
{"op":"mcm","clk":"5348056253","pt":1646213216117,"mc":[{"id":"1.195453752","rc":[{"atb":[[4.8,19.99]],"id":3805747},{"atl":[[8,17.26]],"id":3805747},{"atb":[[7.2,3.26],[8.2,2.72]],"id":3805746},{"atl":[[19.5,18.47]],"id":3805746},{"atb":[[5.6,4.95],[5.5,14.71],[5.2,9.9],[5.9,0]],"id":3805793},{"atl":[[8.8,24.62]],"id":3805793},{"atb":[[16,2.72],[12.5,11.33],[13.5,3.26]],"id":522746},{"atl":[[70,0.23]],"id":522746},{"atb":[[1.01,0]],"id":3805731},{"atb":[[8.6,9.9],[12,2.72],[9.8,3.26],[9.4,4.95]],"id":3805762},{"atl":[[20,7.35]],"id":522742}],"con":true,"img":false}]}
{"op":"mcm","clk":"5348056259","pt":1646213216222,"mc":[{"id":"1.195453752","rc":[{"atb":[[13,3.26],[15.5,2.72]],"id":3805736},{"atl":[[70,2.29]],"id":3805736},{"atl":[[70,2.29],[75,4.95],[90,0],[95,9.9]],"id":522747},{"atb":[[16.5,3.26],[19,2.72]],"id":522750},{"atb":[[7.2,0]],"id":3805730},{"atl":[[50,0]],"id":3805730},{"atb":[[9.6,0],[1.01,0]],"id":522741},{"atl":[[1000,0]],"id":522741},{"atb":[[11,17.26]],"id":522742},{"atb":[[9,3.26],[1.01,0],[10,2.72]],"id":3805740},{"atl":[[16,9.9],[13,0],[14,4.95],[15,0]],"id":3805740}],"con":true,"img":false}]}
{"op":"mcm","clk":"5348056266","pt":1646213216279,"mc":[{"id":"1.195453752","rc":[{"atb":[[10.5,3.26],[13,7.67]],"id":522742},{"atl":[[15,7.35]],"id":3805740}],"con":true,"img":false}]}
{"op":"mcm","clk":"5348056282","pt":1646213216593,"mc":[{"id":"1.195453752","rc":[{"atb":[[11,14.71]],"id":3805746}],"con":true,"img":false}]}
{"op":"mcm","clk":"5348056302","pt":1646213216898,"mc":[{"id":"1.195453752","rc":[{"atb":[[17,7.35]],"id":3805736}],"con":true,"img":false}]}
{"op":"mcm","clk":"5348056356","pt":1646213217776,"mc":[{"id":"1.195453752","rc":[{"atl":[[34,9.9],[36,0],[28,4.95],[29,0]],"id":522746}],"con":true,"img":false}]}
{"op":"mcm","clk":"5348056362","pt":1646213217881,"mc":[{"id":"1.195453752","rc":[{"atl":[[70,7.25],[75,0],[90,9.9],[95,0]],"id":522747}],"con":true,"img":false}]}
{"op":"mcm","clk":"5348056506","pt":1646213220881,"mc":[{"id":"1.195453752","rc":[{"atb":[[7.6,0],[6.6,0]],"id":3805731}],"con":true,"img":false}]}
{"op":"mcm","clk":"5348056519","pt":1646213221138,"mc":[{"id":"1.195453752","rc":[{"atb":[[3.1,63.42],[2.64,162.43],[2.44,184.99]],"id":3805747},{"atb":[[4.5,38.05],[2.9,140.2],[3.25,118.39]],"id":3805746},{"atb":[[2.42,187.6],[2.62,164.43],[3.05,64.97]],"id":3805793},{"atb":[[12,12.1],[6.8,45.93],[5.4,60.54]],"id":3805755},{"atb":[[9,16.64],[4.5,76.11],[5.5,59.19]],"id":522746},{"atb":[[8.8,17.07],[4.4,78.34],[5.4,60.54]],"id":3805736},{"atb":[[21,6.65],[10.5,28.03],[8.2,36.99]],"id":522747},{"atb":[[5.5,59.19],[12.5,11.58],[7,44.4]],"id":522750},{"atb":[[3.6,102.45],[3.1,126.85],[5.2,31.71]],"id":3805731},{"atb":[[4.8,70.1],[7.6,20.18],[3.9,91.85]],"id":3805730},{"atb":[[5.2,63.42],[8.4,18],[4.2,83.24]],"id":3805762},{"atb":[[6.2,51.22],[8.2,36.99],[15.5,9.18]],"id":522741},{"atb":[[3.95,90.29],[4.9,68.3],[7.8,19.58]],"id":522742},{"atb":[[18.5,7.61],[7.4,41.62],[9.4,31.71]],"id":522743},{"atb":[[5.8,27.75],[3.4,110.99],[3.9,91.85]],"id":3805740}],"con":true,"img":false}]}
{"op":"mcm","clk":"5348056541","pt":1646213221505,"mc":[{"id":"1.195453752","rc":[{"atb":[[5.9,20.41]],"id":3805746},{"atl":[[38,2.7]],"id":3805746},{"atb":[[7.4,15.62]],"id":522742},{"atl":[[44,2.33]],"id":522742},{"atb":[[5.7,21.28]],"id":3805740},{"atl":[[22,4.76]],"id":3805740}],"con":true,"img":false}]}
{"op":"mcm","clk":"5348056547","pt":1646213221611,"mc":[{"id":"1.195453752","rc":[{"atb":[[4,33.33]],"id":3805747},{"atl":[[10,9.9]],"id":3805747},{"atb":[[2.7,58.82]],"id":3805793},{"atl":[[13.5,9.31]],"id":3805793},{"atb":[[11.5,9.52]],"id":3805755},{"atl":[[130,2.13]],"id":3805755},{"atb":[[8.8,14.92]],"id":522746},{"atl":[[70,2.23]],"id":522746},{"atb":[[9.8,11.36]],"id":3805736},{"atl":[[70,4.29]],"id":3805736},{"atb":[[13.5,8]],"id":522747},{"atl":[[240,2.07]],"id":522747},{"atb":[[10.5,10.53]],"id":522750},{"atl":[[90,2.19]],"id":522750},{"atb":[[4.8,26.32],[6.4,3.26],[7.4,2.72]],"id":3805731},{"atl":[[14.5,8.62]],"id":3805731},{"atb":[[6.4,18.52]],"id":3805762},{"atl":[[29,3.57]],"id":3805762},{"atb":[[6.6,17.86]],"id":3805730},{"atl":[[60,2]],"id":3805730},{"atb":[[10.5,10.53]],"id":522741},{"atl":[[110,2.15]],"id":522741},{"atb":[[12,9.09]],"id":522743},{"atl":[[200,2.08]],"id":522743}],"con":true,"img":false}]}
{"op":"mcm","clk":"5348056616","pt":1646213222804,"mc":[{"id":"1.195453752","rc":[{"atb":[[12,0]],"id":3805762}],"con":true,"img":false}]}
{"op":"mcm","clk":"5348056618","pt":1646213222905,"mc":[{"id":"1.195453752","rc":[{"atb":[[9.8,0]],"id":3805762}],"con":true,"img":false}]}
{"op":"mcm","clk":"5348056654","pt":1646213223479,"mc":[{"id":"1.195453752","rc":[{"atb":[[11.5,2.72]],"id":3805762}],"con":true,"img":false}]}
{"op":"mcm","clk":"5348056660","pt":1646213223582,"mc":[{"id":"1.195453752","rc":[{"atb":[[9.6,3.26]],"id":3805762}],"con":true,"img":false}]}
{"op":"mcm","clk":"5348056819","pt":1646213226182,"mc":[{"id":"1.195453752","rc":[{"atb":[[4.3,17.98],[3.9,0]],"id":3805747},{"atb":[[5.6,0],[9.4,31.99]],"id":3805746},{"atb":[[2.56,0],[5.2,38.47]],"id":3805793},{"atb":[[19,34.34],[10.5,0]],"id":3805755},{"atb":[[13.5,15.48],[8.8,12.82]],"id":522746},{"atl":[[70,14.45],[75,0]],"id":522746},{"atb":[[6.4,17.98],[4.4,0]],"id":3805731},{"atl":[[10.5,24.62],[14.5,7.41]],"id":3805731},{"atb":[[6.2,0],[9.4,17.17]],"id":3805762},{"atl":[[18,22.12],[95,0]],"id":3805762}],"con":true,"img":false}]}
{"op":"mcm","clk":"5348056837","pt":1646213226492,"mc":[{"id":"1.195453752","rc":[{"atb":[[15.5,17.43],[9.4,0]],"id":3805736},{"atl":[[70,19.01],[75,0]],"id":3805736},{"atb":[[32,18.67],[13,0]],"id":522747},{"atb":[[19,22.48],[10,0]],"id":522750},{"atb":[[12.5,21.83]],"id":3805730},{"atl":[[27,29.02]],"id":3805730},{"atb":[[19.5,15.63],[24,9.61]],"id":522741},{"atl":[[44,8.64],[55,22.27],[110,2]],"id":522741},{"atb":[[10.5,25.62],[7,0]],"id":522742},{"atl":[[75,0],[25,32.26]],"id":522742},{"atb":[[11,0],[27,19.9]],"id":522743},{"atb":[[8.8,19.66]],"id":3805740},{"atl":[[16,24.62],[27,0]],"id":3805740}],"con":true,"img":false}]}
{"op":"mcm","clk":"5348056842","pt":1646213226596,"mc":[{"id":"1.195453752","rc":[{"atb":[[4.9,0]],"id":3805740}],"con":true,"img":false}]}
{"op":"mcm","clk":"5348056896","pt":1646213227422,"mc":[{"id":"1.195453752","rc":[{"atb":[[20,4.95]],"id":522741},{"atl":[[48,0]],"id":522741}],"con":true,"img":false}]}
{"op":"mcm","clk":"5348056934","pt":1646213228105,"mc":[{"id":"1.195453752","rc":[{"atb":[[5.2,37.98]],"id":3805747},{"atl":[[7.2,30.52]],"id":3805747},{"atl":[[17.5,14.56]],"id":3805746},{"atb":[[5.6,39.41]],"id":3805793},{"atl":[[8,27.6]],"id":3805793},{"atb":[[16,13.29]],"id":522746},{"atl":[[28,10.82]],"id":522746},{"atl":[[30,10.42]],"id":3805736},{"atb":[[13,20.88]],"id":522742},{"atl":[[14,17.15]],"id":3805740}],"con":true,"img":false}]}
{"op":"mcm","clk":"5348056968","pt":1646213228834,"mc":[{"id":"1.195453752","rc":[{"atb":[[4.8,12.63]],"id":3805747},{"atl":[[8,9.9]],"id":3805747},{"atl":[[19.5,9.9]],"id":3805746},{"atb":[[5.5,0]],"id":3805793},{"atl":[[8.8,9.9]],"id":3805793},{"atb":[[12.5,9.9]],"id":522746},{"atl":[[70,14.21],[28,4.95]],"id":522746},{"atl":[[70,16.71]],"id":3805736},{"atb":[[11,9.9]],"id":522742},{"atl":[[15,0]],"id":3805740}],"con":true,"img":false}]}
{"op":"mcm","clk":"5348056994","pt":1646213229511,"mc":[{"id":"1.195453752","rc":[{"atl":[[32,5.11]],"id":522746}],"con":true,"img":false}]}
{"op":"mcm","clk":"5348057112","pt":1646213231689,"mc":[{"id":"1.195453752","rc":[{"atb":[[4.6,58.47],[5.2,9.9]],"id":3805793},{"atl":[[55,9.9]],"id":522741},{"atl":[[22,37.32]],"id":3805740}],"con":true,"img":false}]}
{"op":"mcm","clk":"5348057114","pt":1646213231790,"mc":[{"id":"1.195453752","rc":[{"atl":[[110,19.65]],"id":522741},{"atl":[[16,9.9]],"id":3805740}],"con":true,"img":false}]}
{"op":"mcm","clk":"5348057149","pt":1646213232616,"mc":[{"id":"1.195453752","rc":[{"atb":[[11,0]],"id":3805746},{"atb":[[5.6,0],[5.1,9.9],[5.5,4.95],[5.2,0]],"id":3805793},{"atl":[[34,0],[38,9.9],[28,0],[30,4.95]],"id":522746},{"atl":[[75,4.95],[95,9.9]],"id":522747},{"atl":[[16,0],[16.5,9.9],[14,0],[14.5,4.95]],"id":3805740}],"con":true,"img":false}]}
{"op":"mcm","clk":"5348057154","pt":1646213232719,"mc":[{"id":"1.195453752","rc":[{"atl":[[70,0],[90,0]],"id":522747}],"con":true,"img":false}]}
{"op":"mcm","clk":"5348057161","pt":1646213232821,"mc":[{"id":"1.195453752","rc":[{"atl":[[70,12.21],[55,2]],"id":522746}],"con":true,"img":false}]}
{"op":"mcm","clk":"5348057171","pt":1646213233028,"mc":[{"id":"1.195453752","rc":[{"atb":[[8.2,24.81]],"id":3805746},{"atb":[[18.5,4.95],[19,24.43],[22,0]],"id":3805755},{"atl":[[90,18.13]],"id":522747},{"atb":[[18,0],[18.5,9.9],[20,0],[21,4.95]],"id":522741}],"con":true,"img":false}]}
{"op":"mcm","clk":"5348057175","pt":1646213233132,"mc":[{"id":"1.195453752","rc":[{"atb":[[9.4,9.9]],"id":3805746},{"atl":[[240,2]],"id":522747}],"con":true,"img":false}]}
{"op":"mcm","clk":"5348057183","pt":1646213233337,"mc":[{"id":"1.195453752","rc":[{"atb":[[9.4,28.78]],"id":3805746},{"atb":[[5.1,31.1]],"id":3805793},{"atl":[[38,0],[30,0]],"id":522746},{"atl":[[75,0],[95,0]],"id":522747},{"atl":[[16,8.9]],"id":3805740}],"con":true,"img":false}]}
{"op":"mcm","clk":"5348057187","pt":1646213233390,"mc":[{"id":"1.195453752","rc":[{"atl":[[75,2.14]],"id":522747}],"con":true,"img":false}]}
{"op":"mcm","clk":"5348057200","pt":1646213233598,"mc":[{"id":"1.195453752","rc":[{"atb":[[18.5,29.39],[19,0]],"id":3805755}],"con":true,"img":false}]}
{"op":"mcm","clk":"5348057204","pt":1646213233703,"mc":[{"id":"1.195453752","rc":[{"atl":[[90,0]],"id":522747}],"con":true,"img":false}]}
{"op":"mcm","clk":"5348057221","pt":1646213234011,"mc":[{"id":"1.195453752","rc":[{"atl":[[34,9.9],[28,4.95]],"id":522746},{"atl":[[70,4.95],[90,9.9]],"id":522747}],"con":true,"img":false}]}
{"op":"mcm","clk":"5348057383","pt":1646213237020,"mc":[{"id":"1.195453752","rc":[{"atl":[[34,32.23]],"id":522746}],"con":true,"img":false}]}
{"op":"mcm","clk":"5348057386","pt":1646213237121,"mc":[{"id":"1.195453752","rc":[{"atl":[[70,0]],"id":522746}],"con":true,"img":false}]}
{"op":"mcm","clk":"5348057394","pt":1646213237327,"mc":[{"id":"1.195453752","rc":[{"atl":[[16.5,30.5],[22,4.76]],"id":3805740}],"con":true,"img":false}]}
{"op":"mcm","clk":"5348057439","pt":1646213238103,"mc":[{"id":"1.195453752","rc":[{"atb":[[5.6,4.95],[5.1,21.19],[5.5,0],[5.2,9.9]],"id":3805793},{"atb":[[17,9.9],[18.5,24.43],[19,4.95]],"id":3805755}],"con":true,"img":false}]}
{"op":"mcm","clk":"5348057459","pt":1646213238514,"mc":[{"id":"1.195453752","rc":[{"atb":[[5.1,50.65],[4.6,2.72]],"id":3805793},{"atl":[[70,0],[75,7.09],[90,0],[95,9.9]],"id":522747}],"con":true,"img":false}]}
{"op":"mcm","clk":"5348057464","pt":1646213238617,"mc":[{"id":"1.195453752","rc":[{"atl":[[34,22.32],[36,9.9],[28,0],[29,4.95]],"id":522746}],"con":true,"img":false}]}
{"op":"mcm","clk":"5348057476","pt":1646213238924,"mc":[{"id":"1.195453752","rc":[{"atb":[[5.6,33.52]],"id":3805793},{"atl":[[14.5,16.69]],"id":3805740}],"con":true,"img":false}]}
{"op":"mcm","clk":"5348057481","pt":1646213239132,"mc":[{"id":"1.195453752","rc":[{"atl":[[29,10.61]],"id":522746}],"con":true,"img":false}]}
{"op":"mcm","clk":"5348057510","pt":1646213239652,"mc":[{"id":"1.195453752","rc":[{"atb":[[5.1,29.45]],"id":3805793},{"atl":[[16,0]],"id":3805740}],"con":true,"img":false}]}
{"op":"mcm","clk":"5348057520","pt":1646213239810,"mc":[{"id":"1.195453752","rc":[{"atl":[[32,0]],"id":522746}],"con":true,"img":false}]}
{"op":"mcm","clk":"5348057641","pt":1646213242149,"mc":[{"id":"1.195453752","rc":[{"atl":[[34,0]],"id":522746}],"con":true,"img":false}]}
{"op":"mcm","clk":"5348057644","pt":1646213242247,"mc":[{"id":"1.195453752","rc":[{"atl":[[36,45.44]],"id":522746}],"con":true,"img":false}]}
{"op":"mcm","clk":"5348057658","pt":1646213242456,"mc":[{"id":"1.195453752","rc":[{"atl":[[22,36.65]],"id":3805740}],"con":true,"img":false}]}
{"op":"mcm","clk":"5348057677","pt":1646213242821,"mc":[{"id":"1.195453752","rc":[{"atb":[[3.1,0],[2.64,0],[2.44,0]],"id":3805747},{"atb":[[4.5,0],[2.9,0],[3.25,0]],"id":3805746},{"atb":[[2.42,0],[2.62,0],[3.05,0]],"id":3805793},{"atb":[[12,0],[6.8,0],[5.4,0]],"id":3805755},{"atb":[[9,0],[4.5,0],[5.5,0]],"id":522746},{"atb":[[8.8,0],[4.4,0],[5.4,0]],"id":3805736},{"atb":[[21,0],[10.5,0],[8.2,0]],"id":522747},{"atb":[[5.5,0],[12.5,0],[7,0]],"id":522750},{"atb":[[3.6,0],[3.1,0],[5.2,0]],"id":3805731},{"atb":[[4.8,0],[7.6,0],[3.9,0]],"id":3805730},{"atb":[[5.2,0],[8.4,0],[4.2,0]],"id":3805762},{"atb":[[6.2,0],[8.2,0],[15.5,0]],"id":522741},{"atb":[[3.95,0],[4.9,0],[7.8,0]],"id":522742},{"atb":[[18.5,0],[7.4,0],[9.4,0]],"id":522743},{"atb":[[5.8,0],[3.4,0],[3.9,0]],"id":3805740}],"con":true,"img":false}]}
{"op":"mcm","clk":"5348057691","pt":1646213243238,"mc":[{"id":"1.195453752","rc":[{"atl":[[16.5,9.9]],"id":3805740}],"con":true,"img":false}]}
{"op":"mcm","clk":"5348057710","pt":1646213243753,"mc":[{"id":"1.195453752","rc":[{"atl":[[240,10.22]],"id":522747}],"con":true,"img":false}]}
{"op":"mcm","clk":"5348057717","pt":1646213243914,"mc":[{"id":"1.195453752","rc":[{"atb":[[10.5,21.64]],"id":3805746}],"con":true,"img":false}]}
{"op":"mcm","clk":"5348057773","pt":1646213244843,"mc":[{"id":"1.195453752","rc":[{"atb":[[9.4,9.9]],"id":3805746}],"con":true,"img":false}]}
{"op":"mcm","clk":"5348057830","pt":1646213246025,"mc":[{"id":"1.195453752","rc":[{"atb":[[9.6,0],[11.5,0]],"id":3805762}],"con":true,"img":false}]}
{"op":"mcm","clk":"5348057844","pt":1646213246435,"mc":[{"id":"1.195453752","rc":[{"atb":[[6.4,58.76],[9.4,13.98]],"id":3805762}],"con":true,"img":false}]}
{"op":"mcm","clk":"5348057868","pt":1646213246948,"mc":[{"id":"1.195453752","rc":[{"atb":[[11,2.72],[9.4,17.25]],"id":3805762}],"con":true,"img":false}]}
{"op":"mcm","clk":"5348057889","pt":1646213247256,"mc":[{"id":"1.195453752","rc":[{"atb":[[1.01,0]],"id":3805762}],"con":true,"img":false}]}
{"op":"mcm","clk":"5348057895","pt":1646213247309,"mc":[{"id":"1.195453752","rc":[{"atl":[[36,9.9],[55,37.53]],"id":522746}],"con":true,"img":false}]}
{"op":"mcm","clk":"5348058363","pt":1646213256583,"mc":[{"id":"1.195453752","rc":[{"atb":[[3.1,63.42],[2.64,162.43],[2.44,184.99]],"id":3805747},{"atb":[[2.92,138.74],[4.6,36.99],[3.3,115.82]],"id":3805746},{"atb":[[2.4,190.27],[3,66.59],[2.6,166.49]],"id":3805793},{"atb":[[5.3,61.94],[11.5,22.2],[6.6,47.57]],"id":3805755},{"atb":[[9.6,15.48],[4.8,70.1],[5.8,55.49]],"id":522746},{"atb":[[9.6,15.48],[4.8,70.1],[5.8,55.49]],"id":3805736},{"atb":[[21,6.65],[10.5,28.03],[8.2,36.99]],"id":522747},{"atb":[[5.3,61.94],[11.5,12.68],[6.6,47.57]],"id":522750},{"atb":[[5.1,32.48],[3.55,104.46],[3.05,129.94]],"id":3805731},{"atb":[[3.95,90.29],[4.9,68.3],[7.8,19.58]],"id":3805762},{"atb":[[3.85,93.47],[7.4,20.81],[4.7,71.99]],"id":3805730},{"atb":[[16,8.87],[6.4,49.33],[8.4,35.99]],"id":522741},{"atb":[[4.8,70.1],[7.6,20.18],[3.9,91.85]],"id":522742},{"atb":[[17.5,8.07],[9,33.29],[7,44.4]],"id":522743},{"atb":[[6.2,25.61],[4.1,85.93],[3.55,104.46]],"id":3805740}],"con":true,"img":false}]}
{"op":"mcm","clk":"5348058370","pt":1646213256642,"mc":[{"id":"1.195453752","rc":[{"atb":[[8,0],[8.6,4.95],[8.8,14.71]],"id":3805740}],"con":true,"img":false}]}
{"op":"mcm","clk":"5348058381","pt":1646213256849,"mc":[{"id":"1.195453752","rc":[{"atb":[[8.6,31.99],[6.4,18.52],[11,18.57]],"id":3805762}],"con":true,"img":false}]}
{"op":"mcm","clk":"5348058435","pt":1646213257732,"mc":[{"id":"1.195453752","rc":[{"atb":[[4.8,9.9],[4.3,14.71]],"id":3805747},{"atb":[[9.4,8.22]],"id":3805762}],"con":true,"img":false}]}
{"op":"mcm","clk":"5348058475","pt":1646213258766,"mc":[{"id":"1.195453752","rc":[{"atb":[[4.9,2.72],[4.4,3.26]],"id":3805747}],"con":true,"img":false}]}
{"op":"mcm","clk":"5348058493","pt":1646213259125,"mc":[{"id":"1.195453752","rc":[{"atb":[[9,0],[10,0]],"id":3805740}],"con":true,"img":false}]}
{"op":"mcm","clk":"5348058506","pt":1646213259434,"mc":[{"id":"1.195453752","rc":[{"atb":[[4.8,39.36],[4.3,0]],"id":3805747}],"con":true,"img":false}]}
{"op":"mcm","clk":"5348058513","pt":1646213259742,"mc":[{"id":"1.195453752","rc":[{"atb":[[6.2,72.29],[8.8,20.32]],"id":3805740}],"con":true,"img":false}]}
{"op":"mcm","clk":"5348058525","pt":1646213260156,"mc":[{"id":"1.195453752","rc":[{"atb":[[9.2,3.26],[10.5,2.72]],"id":3805740}],"con":true,"img":false}]}
{"op":"mcm","clk":"5348058574","pt":1646213261552,"mc":[{"id":"1.195453752","rc":[{"atl":[[8,22.64],[8.6,9.9],[8.8,0],[7.8,4.95]],"id":3805793},{"atb":[[8.6,0]],"id":3805740}],"con":true,"img":false}]}
{"op":"mcm","clk":"5348058587","pt":1646213261761,"mc":[{"id":"1.195453752","rc":[{"atl":[[16.5,0],[14.5,11.74]],"id":3805740}],"con":true,"img":false}]}
{"op":"mcm","clk":"5348058590","pt":1646213261862,"mc":[{"id":"1.195453752","rc":[{"atl":[[13.5,4.95],[15.5,9.9]],"id":3805740}],"con":true,"img":false}]}
{"op":"mcm","clk":"5348058596","pt":1646213262068,"mc":[{"id":"1.195453752","rc":[{"atl":[[8.6,58.3],[7.6,24.02],[13.5,8]],"id":3805793}],"con":true,"img":false}]}
{"op":"mcm","clk":"5348058607","pt":1646213262275,"mc":[{"id":"1.195453752","rc":[{"atl":[[22,4.76],[15.5,44.8]],"id":3805740}],"con":true,"img":false}]}
{"op":"mcm","clk":"5348058610","pt":1646213262327,"mc":[{"id":"1.195453752","rc":[{"atl":[[13.5,17.63]],"id":3805740}],"con":true,"img":false}]}
{"op":"mcm","clk":"5348058621","pt":1646213262536,"mc":[{"id":"1.195453752","rc":[{"atb":[[7.6,9.9],[8.4,4.95]],"id":3805740}],"con":true,"img":false}]}
{"op":"mcm","clk":"5348058643","pt":1646213262848,"mc":[{"id":"1.195453752","rc":[{"atl":[[8,0]],"id":3805793}],"con":true,"img":false}]}
{"op":"mcm","clk":"5348058661","pt":1646213263157,"mc":[{"id":"1.195453752","rc":[{"atl":[[14.5,0]],"id":3805740}],"con":true,"img":false}]}
{"op":"mcm","clk":"5348058679","pt":1646213263468,"mc":[{"id":"1.195453752","rc":[{"atb":[[4.8,29.45],[5.3,4.95],[5.2,33.02],[4.9,12.63]],"id":3805747}],"con":true,"img":false}]}
{"op":"mcm","clk":"5348058698","pt":1646213263778,"mc":[{"id":"1.195453752","rc":[{"atl":[[16,9.9],[13.5,0],[14,4.95],[15.5,34.9]],"id":3805740}],"con":true,"img":false}]}
{"op":"mcm","clk":"5348058708","pt":1646213263932,"mc":[{"id":"1.195453752","rc":[{"atl":[[19.5,5.41],[22,0]],"id":3805740}],"con":true,"img":false}]}
{"op":"mcm","clk":"5348058717","pt":1646213264139,"mc":[{"id":"1.195453752","rc":[{"atb":[[5.4,33.5]],"id":3805747}],"con":true,"img":false}]}
{"op":"mcm","clk":"5348058730","pt":1646213264448,"mc":[{"id":"1.195453752","rc":[{"atl":[[15.5,45.83]],"id":3805740}],"con":true,"img":false}]}
{"op":"mcm","clk":"5348058767","pt":1646213265070,"mc":[{"id":"1.195453752","rc":[{"atb":[[5.2,0]],"id":3805747}],"con":true,"img":false}]}
{"op":"mcm","clk":"5348058826","pt":1646213265963,"mc":[{"id":"1.195453752","rc":[{"atl":[[70,4.95],[75,2.14],[90,9.9],[95,0]],"id":522747},{"atb":[[9.2,0],[10.5,0]],"id":3805740}],"con":true,"img":false}]}
{"op":"mcm","clk":"5348058847","pt":1646213266469,"mc":[{"id":"1.195453752","rc":[{"atl":[[65,2.47],[90,23.62],[240,2]],"id":522747}],"con":true,"img":false}]}
{"op":"mcm","clk":"5348058859","pt":1646213266781,"mc":[{"id":"1.195453752","rc":[{"atb":[[10,2.72]],"id":3805740}],"con":true,"img":false}]}
{"op":"mcm","clk":"5348058862","pt":1646213266834,"mc":[{"id":"1.195453752","rc":[{"atb":[[9,3.26]],"id":3805740}],"con":true,"img":false}]}
{"op":"mcm","clk":"5348058874","pt":1646213267143,"mc":[{"id":"1.195453752","rc":[{"atl":[[75,0]],"id":522747},{"atl":[[16,39.36],[15.5,10.93]],"id":3805740}],"con":true,"img":false}]}
{"op":"mcm","clk":"5348058890","pt":1646213267454,"mc":[{"id":"1.195453752","rc":[{"atb":[[7.2,0],[8.2,22.08]],"id":3805746},{"atb":[[4.6,0],[4.1,0]],"id":3805793}],"con":true,"img":false}]}
{"op":"mcm","clk":"5348058920","pt":1646213268286,"mc":[{"id":"1.195453752","rc":[{"atb":[[7.4,3.26],[8.4,2.72]],"id":3805746},{"atb":[[4.2,3.26],[4.7,2.72]],"id":3805793}],"con":true,"img":false}]}
{"op":"mcm","clk":"5348058932","pt":1646213268485,"mc":[{"id":"1.195453752","rc":[{"atl":[[34,9.9],[36,0],[28,4.95],[29,5.66]],"id":522746}],"con":true,"img":false}]}
{"op":"mcm","clk":"5348058949","pt":1646213268743,"mc":[{"id":"1.195453752","rc":[{"atb":[[8.2,0],[8.4,32.18]],"id":3805746}],"con":true,"img":false}]}
{"op":"mcm","clk":"5348058963","pt":1646213269052,"mc":[{"id":"1.195453752","rc":[{"atl":[[34,33.04],[55,2],[27,6.09]],"id":522746}],"con":true,"img":false}]}
{"op":"mcm","clk":"5348058992","pt":1646213269774,"mc":[{"id":"1.195453752","rc":[{"atb":[[4.8,0],[4.9,46.13]],"id":3805747}],"con":true,"img":false}]}
{"op":"mcm","clk":"5348058997","pt":1646213269879,"mc":[{"id":"1.195453752","rc":[{"atl":[[27,0],[29,0]],"id":522746}],"con":true,"img":false}]}
{"op":"mcm","clk":"5348059008","pt":1646213270084,"mc":[{"id":"1.195453752","rc":[{"atb":[[6.2,25.61],[8.8,43.93]],"id":3805740}],"con":true,"img":false}]}
{"op":"mcm","clk":"5348059045","pt":1646213270839,"mc":[{"id":"1.195453752","rc":[{"atl":[[34,37.85]],"id":522746}],"con":true,"img":false}]}
{"op":"mcm","clk":"5348059125","pt":1646213272386,"mc":[{"id":"1.195453752","rc":[{"atl":[[14,17.15]],"id":3805740}],"con":true,"img":false}]}
{"op":"mcm","clk":"5348059167","pt":1646213273054,"mc":[{"id":"1.195453752","rc":[{"atl":[[15.5,0]],"id":3805740}],"con":true,"img":false}]}
{"op":"mcm","clk":"5348059186","pt":1646213273365,"mc":[{"id":"1.195453752","rc":[{"atl":[[8,4.95],[8.6,48.39],[8.8,9.9],[7.8,0]],"id":3805793}],"con":true,"img":false}]}
{"op":"mcm","clk":"5348059202","pt":1646213273781,"mc":[{"id":"1.195453752","rc":[{"atl":[[16,9.9],[19.5,38.94]],"id":3805740}],"con":true,"img":false}]}
{"op":"mcm","clk":"5348059218","pt":1646213274092,"mc":[{"id":"1.195453752","rc":[{"atl":[[34,14.71],[55,29.11]],"id":522746}],"con":true,"img":false}]}
{"op":"mcm","clk":"5348059421","pt":1646213278673,"mc":[{"id":"1.195453752","rc":[{"atl":[[22,4.95],[26,9.9]],"id":522742}],"con":true,"img":false}]}
{"op":"mcm","clk":"5348059426","pt":1646213278775,"mc":[{"id":"1.195453752","rc":[{"atl":[[21,0],[25,22.35]],"id":522742}],"con":true,"img":false}]}
{"op":"mcm","clk":"5348059436","pt":1646213278981,"mc":[{"id":"1.195453752","rc":[{"atl":[[28,10.82]],"id":522746}],"con":true,"img":false}]}
{"op":"mcm","clk":"5348059452","pt":1646213279392,"mc":[{"id":"1.195453752","rc":[{"atl":[[22,30.62],[25,0]],"id":522742}],"con":true,"img":false}]}
{"op":"mcm","clk":"5348059479","pt":1646213279958,"mc":[{"id":"1.195453752","rc":[{"atl":[[34,9.9],[28,4.95]],"id":522746}],"con":true,"img":false}]}
{"op":"mcm","clk":"5348059492","pt":1646213280267,"mc":[{"id":"1.195453752","rc":[{"atl":[[22,4.95]],"id":522742}],"con":true,"img":false}]}
{"op":"mcm","clk":"5348059512","pt":1646213280679,"mc":[{"id":"1.195453752","rc":[{"atl":[[34,14.71]],"id":522746}],"con":true,"img":false}]}
{"op":"mcm","clk":"5348059525","pt":1646213281090,"mc":[{"id":"1.195453752","rc":[{"atb":[[6.6,0],[7.8,14.71]],"id":3805730}],"con":true,"img":false}]}
{"op":"mcm","clk":"5348059657","pt":1646213283467,"mc":[{"id":"1.195453752","rc":[{"atl":[[34,4.8],[36,9.9],[28,0],[29,4.95]],"id":522746}],"con":true,"img":false}]}
{"op":"mcm","clk":"5348059679","pt":1646213283878,"mc":[{"id":"1.195453752","rc":[{"atl":[[55,2]],"id":522746}],"con":true,"img":false}]}
{"op":"mcm","clk":"5348059693","pt":1646213284188,"mc":[{"id":"1.195453752","rc":[{"atl":[[36,22.08],[29,0]],"id":522746}],"con":true,"img":false}]}
{"op":"mcm","clk":"5348059699","pt":1646213284290,"mc":[{"id":"1.195453752","rc":[{"atl":[[34,14.71],[28,4.95]],"id":522746}],"con":true,"img":false}]}
{"op":"mcm","clk":"5348059901","pt":1646213288062,"mc":[{"id":"1.195453752","rc":[{"atb":[[5.9,0]],"id":3805746}],"con":true,"img":false}]}
{"op":"mcm","clk":"5348059906","pt":1646213288165,"mc":[{"id":"1.195453752","rc":[{"atb":[[6.8,17.24]],"id":3805746}],"con":true,"img":false}]}
{"op":"mcm","clk":"5348059926","pt":1646213288676,"mc":[{"id":"1.195453752","rc":[{"atl":[[24,4.95],[28,9.9]],"id":3805730}],"con":true,"img":false}]}
{"op":"mcm","clk":"5348059929","pt":1646213288783,"mc":[{"id":"1.195453752","rc":[{"atl":[[23,0],[27,19.11]],"id":3805730}],"con":true,"img":false}]}
{"op":"mcm","clk":"5348059940","pt":1646213288986,"mc":[{"id":"1.195453752","rc":[{"atl":[[28,10.82]],"id":522746}],"con":true,"img":false}]}
{"op":"mcm","clk":"5348059958","pt":1646213289402,"mc":[{"id":"1.195453752","rc":[{"atl":[[24,24.06],[27,0]],"id":3805730},{"atl":[[26,39.36]],"id":522742}],"con":true,"img":false}]}
{"op":"mcm","clk":"5348059972","pt":1646213289672,"mc":[{"id":"1.195453752","rc":[{"atl":[[34,9.9],[28,4.95]],"id":522746}],"con":true,"img":false}]}
{"op":"mcm","clk":"5348059990","pt":1646213290076,"mc":[{"id":"1.195453752","rc":[{"atl":[[24,4.95]],"id":3805730}],"con":true,"img":false}]}
{"op":"mcm","clk":"5348060025","pt":1646213290803,"mc":[{"id":"1.195453752","rc":[{"atl":[[34,14.71]],"id":522746}],"con":true,"img":false}]}
{"op":"mcm","clk":"5348060385","pt":1646213298519,"mc":[{"id":"1.195453752","rc":[{"atl":[[28,10.82]],"id":522746}],"con":true,"img":false}]}
{"op":"mcm","clk":"5348060425","pt":1646213299188,"mc":[{"id":"1.195453752","rc":[{"atl":[[28,36.39]],"id":3805730}],"con":true,"img":false}]}
{"op":"mcm","clk":"5348060440","pt":1646213299500,"mc":[{"id":"1.195453752","rc":[{"atl":[[34,9.9],[28,4.95]],"id":522746}],"con":true,"img":false}]}
{"op":"mcm","clk":"5348060466","pt":1646213300218,"mc":[{"id":"1.195453752","rc":[{"atl":[[34,14.71]],"id":522746}],"con":true,"img":false}]}
{"op":"mcm","clk":"5348060634","pt":1646213303235,"mc":[{"id":"1.195453752","rc":[{"atb":[[3.1,0],[2.64,0],[2.44,0]],"id":3805747},{"atb":[[2.92,0],[4.6,0],[3.3,0]],"id":3805746},{"atb":[[2.4,0],[3,0],[2.6,0]],"id":3805793},{"atb":[[5.3,0],[11.5,9.52],[6.6,0]],"id":3805755},{"atb":[[9.6,0],[4.8,0],[5.8,0]],"id":522746},{"atb":[[9.6,0],[4.8,0],[5.8,0]],"id":3805736},{"atb":[[21,0],[10.5,0],[8.2,0]],"id":522747},{"atb":[[5.3,0],[11.5,0],[6.6,0]],"id":522750},{"atb":[[5.1,0],[3.55,0],[3.05,0]],"id":3805731},{"atb":[[3.85,0],[7.4,0],[4.7,0]],"id":3805730},{"atb":[[3.95,0],[4.9,0],[7.8,0]],"id":3805762},{"atb":[[16,0],[6.4,0],[8.4,0]],"id":522741},{"atb":[[4.8,0],[7.6,0],[3.9,0]],"id":522742},{"atb":[[17.5,0],[9,0],[7,0]],"id":522743},{"atb":[[6.2,0],[4.1,0],[3.55,0]],"id":3805740}],"con":true,"img":false}]}
{"op":"mcm","clk":"5348060649","pt":1646213303491,"mc":[{"id":"1.195453752","rc":[{"atb":[[11.5,0],[12,9.9],[13.5,0],[14,4.95]],"id":3805730}],"con":true,"img":false}]}
{"op":"mcm","clk":"5348060690","pt":1646213304222,"mc":[{"id":"1.195453752","rc":[{"atl":[[34,4.8],[28,0]],"id":522746}],"con":true,"img":false}]}
{"op":"mcm","clk":"5348060694","pt":1646213304323,"mc":[{"id":"1.195453752","rc":[{"atl":[[36,31.99],[29,4.95]],"id":522746}],"con":true,"img":false}]}
{"op":"mcm","clk":"5348060732","pt":1646213304892,"mc":[{"id":"1.195453752","rc":[{"atl":[[55,29.11]],"id":522746}],"con":true,"img":false}]}
{"op":"mcm","clk":"5348060737","pt":1646213304993,"mc":[{"id":"1.195453752","rc":[{"atl":[[36,9.9]],"id":522746}],"con":true,"img":false}]}
{"op":"mcm","clk":"5348060772","pt":1646213305718,"mc":[{"id":"1.195453752","rc":[{"atl":[[55,2]],"id":522746}],"con":true,"img":false}]}
{"op":"mcm","clk":"5348060848","pt":1646213307517,"mc":[{"id":"1.195453752","rc":[{"atl":[[8,0],[8.8,0]],"id":3805793}],"con":true,"img":false}]}
{"op":"mcm","clk":"5348060860","pt":1646213307730,"mc":[{"id":"1.195453752","rc":[{"atl":[[13,4.95],[15,9.9]],"id":3805740}],"con":true,"img":false}]}
{"op":"mcm","clk":"5348060865","pt":1646213307832,"mc":[{"id":"1.195453752","rc":[{"atl":[[8.6,58.3],[7.8,4.95]],"id":3805793},{"atl":[[16,0],[14,12.19]],"id":3805740}],"con":true,"img":false}]}
{"op":"mcm","clk":"5348060875","pt":1646213308032,"mc":[{"id":"1.195453752","rc":[{"atl":[[8.6,9.9],[13.5,87.48]],"id":3805793},{"atl":[[29,10.61]],"id":522746}],"con":true,"img":false}]}
{"op":"mcm","clk":"5348060895","pt":1646213308350,"mc":[{"id":"1.195453752","rc":[{"atl":[[19.5,5.41],[13,18.16],[15,31.99]],"id":3805740}],"con":true,"img":false}]}
{"op":"mcm","clk":"5348060923","pt":1646213308711,"mc":[{"id":"1.195453752","rc":[{"atl":[[13.5,8]],"id":3805793},{"atl":[[34,0]],"id":522746},{"atb":[[32,13.71],[34,4.95],[27,0],[28,13.17]],"id":522747}],"con":true,"img":false}]}
{"op":"mcm","clk":"5348060949","pt":1646213309117,"mc":[{"id":"1.195453752","rc":[{"atl":[[14,0]],"id":3805740}],"con":true,"img":false}]}
{"op":"mcm","clk":"5348060952","pt":1646213309221,"mc":[{"id":"1.195453752","rc":[{"atb":[[32,0],[34,18.67]],"id":522747}],"con":true,"img":false}]}
{"op":"mcm","clk":"5348060974","pt":1646213309738,"mc":[{"id":"1.195453752","rc":[{"atl":[[13.5,4.95],[15.5,9.9]],"id":3805740}],"con":true,"img":false}]}
{"op":"mcm","clk":"5348060980","pt":1646213309840,"mc":[{"id":"1.195453752","rc":[{"atl":[[13,0],[15,22.08]],"id":3805740}],"con":true,"img":false}]}
{"op":"mcm","clk":"5348061026","pt":1646213310624,"mc":[{"id":"1.195453752","rc":[{"atl":[[15,33.41]],"id":3805740}],"con":true,"img":false}]}
{"op":"mcm","clk":"5348061135","pt":1646213312839,"mc":[{"id":"1.195453752","rc":[{"atl":[[15,11.32],[15.5,31.99]],"id":3805740}],"con":true,"img":false}]}
{"op":"mcm","clk":"5348061209","pt":1646213314228,"mc":[{"id":"1.195453752","rc":[{"atl":[[55,32.51]],"id":522746}],"con":true,"img":false}]}
{"op":"mcm","clk":"5348061232","pt":1646213314641,"mc":[{"id":"1.195453752","rc":[{"atl":[[34,9.9],[36,0],[28,4.95],[29,5.66]],"id":522746}],"con":true,"img":false}]}
{"op":"mcm","clk":"5348061261","pt":1646213315217,"mc":[{"id":"1.195453752","rc":[{"atb":[[2.5,177.59],[3.25,59.19],[2.7,156.7]],"id":3805747},{"atb":[[3.45,108.73],[4.9,34.15],[2.98,134.54]],"id":3805746},{"atb":[[2.46,182.45],[2.66,160.47],[3.15,61.94]],"id":3805793},{"atb":[[5.1,64.97],[10.5,14.02],[6.2,51.22]],"id":3805755},{"atb":[[10,14.8],[5,66.59],[6,53.27]],"id":522746},{"atb":[[9.8,26.49],[4.9,68.3],[5.9,54.36]],"id":3805736},{"atb":[[8,38.05],[20,7],[10,29.59]],"id":522747},{"atb":[[6.4,49.33],[11,13.31],[5.2,63.42]],"id":522750},{"atb":[[3.35,113.35],[2.94,137.31],[4.7,35.99]],"id":3805731},{"atb":[[3.7,98.66],[6.8,22.96],[4.4,78.34]],"id":3805730},{"atb":[[4.5,76.11],[7,22.19],[3.75,96.87]],"id":3805762},{"atb":[[6.2,51.22],[8.2,36.99],[15.5,9.18]],"id":522741},{"atb":[[4.5,76.11],[7,22.19],[3.75,96.87]],"id":522742},{"atb":[[16,8.87],[6.4,49.33],[8.4,35.99]],"id":522743},{"atb":[[3.6,102.45],[6.4,24.66],[4.2,83.24]],"id":3805740}],"con":true,"img":false}]}
{"op":"mcm","clk":"5348061266","pt":1646213315317,"mc":[{"id":"1.195453752","rc":[{"atl":[[28,10.82]],"id":522746}],"con":true,"img":false}]}
{"op":"mcm","clk":"5348061283","pt":1646213315725,"mc":[{"id":"1.195453752","rc":[{"atl":[[34,0],[36,9.9],[28,5.86],[29,10.61]],"id":522746}],"con":true,"img":false}]}
{"op":"mcm","clk":"5348061296","pt":1646213316035,"mc":[{"id":"1.195453752","rc":[{"atl":[[29,4.95]],"id":522746}],"con":true,"img":false}]}
{"op":"mcm","clk":"5348061335","pt":1646213316813,"mc":[{"id":"1.195453752","rc":[{"atb":[[6.8,0]],"id":3805746}],"con":true,"img":false}]}
{"op":"mcm","clk":"5348061341","pt":1646213316918,"mc":[{"id":"1.195453752","rc":[{"atb":[[5.9,20.41]],"id":3805746}],"con":true,"img":false}]}
{"op":"mcm","clk":"5348061345","pt":1646213317020,"mc":[{"id":"1.195453752","rc":[{"atl":[[8,4.95],[8.6,0],[8.8,9.9],[7.8,0]],"id":3805793},{"atb":[[7.6,0],[8.4,0]],"id":3805740}],"con":true,"img":false}]}
{"op":"mcm","clk":"5348061362","pt":1646213317329,"mc":[{"id":"1.195453752","rc":[{"atl":[[8.6,50.43]],"id":3805793},{"atb":[[8.6,4.95]],"id":3805740}],"con":true,"img":false}]}
{"op":"mcm","clk":"5348061377","pt":1646213317638,"mc":[{"id":"1.195453752","rc":[{"atl":[[13.5,17.63]],"id":3805740}],"con":true,"img":false}]}
{"op":"mcm","clk":"5348061404","pt":1646213318209,"mc":[{"id":"1.195453752","rc":[{"atl":[[28,0]],"id":522746}],"con":true,"img":false}]}
{"op":"mcm","clk":"5348061414","pt":1646213318518,"mc":[{"id":"1.195453752","rc":[{"atl":[[15,0]],"id":3805740}],"con":true,"img":false}]}
{"op":"mcm","clk":"5348061445","pt":1646213319047,"mc":[{"id":"1.195453752","rc":[{"atl":[[34,4.8]],"id":522746},{"atl":[[19.5,39.66],[15.5,9.9]],"id":3805740}],"con":true,"img":false}]}
{"op":"mcm","clk":"5348061586","pt":1646213321647,"mc":[{"id":"1.195453752","rc":[{"atl":[[34,9.76],[36,0],[42,9.9],[29,0]],"id":522746},{"atl":[[13.5,4.95]],"id":3805740}],"con":true,"img":false}]}
{"op":"mcm","clk":"5348061591","pt":1646213321751,"mc":[{"id":"1.195453752","rc":[{"atl":[[65,0],[70,0],[75,4.95],[90,13.71],[95,9.9]],"id":522747},{"atl":[[16,9.9],[13.5,0],[14,4.95],[15.5,0]],"id":3805740}],"con":true,"img":false}]}
{"op":"mcm","clk":"5348061600","pt":1646213321952,"mc":[{"id":"1.195453752","rc":[{"atl":[[44,0],[46,4.95],[55,0],[60,9.9]],"id":522741}],"con":true,"img":false}]}
{"op":"mcm","clk":"5348061622","pt":1646213322311,"mc":[{"id":"1.195453752","rc":[{"atl":[[90,0],[95,31.8]],"id":522747},{"atl":[[15.5,8.9]],"id":3805740}],"con":true,"img":false}]}
{"op":"mcm","clk":"5348061644","pt":1646213322662,"mc":[{"id":"1.195453752","rc":[{"atl":[[90,1.78]],"id":522747},{"atl":[[55,2.93]],"id":522741}],"con":true,"img":false}]}
{"op":"mcm","clk":"5348061650","pt":1646213322729,"mc":[{"id":"1.195453752","rc":[{"atl":[[70,4.95],[75,0],[90,11.69],[95,21.89]],"id":522747}],"con":true,"img":false}]}
{"op":"mcm","clk":"5348061671","pt":1646213323044,"mc":[{"id":"1.195453752","rc":[{"atl":[[16,30.5],[19.5,5.41]],"id":3805740}],"con":true,"img":false}]}
{"op":"mcm","clk":"5348061681","pt":1646213323144,"mc":[{"id":"1.195453752","rc":[{"atl":[[110,2],[60,31.56]],"id":522741}],"con":true,"img":false}]}
{"op":"mcm","clk":"5348061750","pt":1646213324328,"mc":[{"id":"1.195453752","rc":[{"atb":[[8.6,0]],"id":3805740}],"con":true,"img":false}]}
{"op":"mcm","clk":"5348061772","pt":1646213324743,"mc":[{"id":"1.195453752","rc":[{"atb":[[7.6,9.9],[8.4,4.95]],"id":3805740}],"con":true,"img":false}]}
{"op":"mcm","clk":"5348061875","pt":1646213326650,"mc":[{"id":"1.195453752","rc":[{"atl":[[14,17.15]],"id":3805740}],"con":true,"img":false}]}
{"op":"mcm","clk":"5348061905","pt":1646213327377,"mc":[{"id":"1.195453752","rc":[{"atl":[[70,0],[75,4.95],[90,1.78],[95,31.8]],"id":522747},{"atl":[[65,9.9],[46,0],[48,4.95],[60,21.65]],"id":522741},{"atl":[[15.5,0]],"id":3805740}],"con":true,"img":false}]}
{"op":"mcm","clk":"5348061948","pt":1646213327940,"mc":[{"id":"1.195453752","rc":[{"atl":[[16,9.9],[19.5,38.94]],"id":3805740}],"con":true,"img":false}]}
{"op":"mcm","clk":"5348061953","pt":1646213328046,"mc":[{"id":"1.195453752","rc":[{"atl":[[65,0],[46,4.95],[48,0],[60,31.56]],"id":522741}],"con":true,"img":false}]}
{"op":"mcm","clk":"5348061957","pt":1646213328150,"mc":[{"id":"1.195453752","rc":[{"atl":[[75,0],[95,21.89]],"id":522747}],"con":true,"img":false}]}
{"op":"mcm","clk":"5348061989","pt":1646213328664,"mc":[{"id":"1.195453752","rc":[{"atl":[[95,0],[240,10.65]],"id":522747}],"con":true,"img":false}]}
{"op":"mcm","clk":"5348062013","pt":1646213329071,"mc":[{"id":"1.195453752","rc":[{"atl":[[32,4.95],[34,4.8],[40,9.9],[42,0]],"id":522746},{"atl":[[70,4.95],[90,11.69]],"id":522747}],"con":true,"img":false}]}
{"op":"mcm","clk":"5348062047","pt":1646213329640,"mc":[{"id":"1.195453752","rc":[{"atl":[[32,10.06],[40,31.99],[55,2]],"id":522746}],"con":true,"img":false}]}
{"op":"mcm","clk":"5348062093","pt":1646213330468,"mc":[{"id":"1.195453752","rc":[{"atl":[[34,0]],"id":522746}],"con":true,"img":false}]}
{"op":"mcm","clk":"5348062156","pt":1646213331659,"mc":[{"id":"1.195453752","rc":[{"atl":[[70,7.25]],"id":522747},{"atl":[[46,8.47]],"id":522741}],"con":true,"img":false}]}
{"op":"mcm","clk":"5348062187","pt":1646213332377,"mc":[{"id":"1.195453752","rc":[{"atl":[[32,0],[34,4.95],[40,22.08],[42,9.9]],"id":522746},{"atl":[[55,0]],"id":522741}],"con":true,"img":false}]}
{"op":"mcm","clk":"5348062194","pt":1646213332433,"mc":[{"id":"1.195453752","rc":[{"atl":[[90,9.9]],"id":522747}],"con":true,"img":false}]}
{"op":"mcm","clk":"5348062217","pt":1646213332949,"mc":[{"id":"1.195453752","rc":[{"atl":[[110,20.9],[60,9.9]],"id":522741}],"con":true,"img":false}]}
{"op":"mcm","clk":"5348062236","pt":1646213333363,"mc":[{"id":"1.195453752","rc":[{"atl":[[38,4.28]],"id":522746}],"con":true,"img":false}]}
{"op":"mcm","clk":"5348062286","pt":1646213334397,"mc":[{"id":"1.195453752","rc":[{"atb":[[5.6,0],[5.1,39.36],[5.5,4.95],[5.2,0]],"id":3805793},{"atl":[[70,0],[80,4.95],[90,0],[100,9.9]],"id":522747},{"atl":[[70,9.9],[46,0],[50,4.95],[60,0]],"id":522741}],"con":true,"img":false}]}
{"op":"mcm","clk":"5348062292","pt":1646213334463,"mc":[{"id":"1.195453752","rc":[{"atb":[[17.5,0],[19.5,0]],"id":522750}],"con":true,"img":false}]}
{"op":"mcm","clk":"5348062305","pt":1646213334658,"mc":[{"id":"1.195453752","rc":[{"atb":[[18,9.9],[20,13.29]],"id":522750}],"con":true,"img":false}]}
{"op":"mcm","clk":"5348062317","pt":1646213334864,"mc":[{"id":"1.195453752","rc":[{"atb":[[5.1,9.9],[4.7,45.78]],"id":3805793},{"atb":[[16.5,29.75],[19,2.72]],"id":522750}],"con":true,"img":false}]}
{"op":"mcm","clk":"5348062334","pt":1646213335071,"mc":[{"id":"1.195453752","rc":[{"atb":[[5.1,24.62]],"id":3805793},{"atl":[[80,6.95]],"id":522747},{"atl":[[100,1.6]],"id":522741}],"con":true,"img":false}]}
{"op":"mcm","clk":"5348062454","pt":1646213336983,"mc":[{"id":"1.195453752","rc":[{"atl":[[20,0]],"id":522742}],"con":true,"img":false}]}
{"op":"mcm","clk":"5348062494","pt":1646213337669,"mc":[{"id":"1.195453752","rc":[{"atl":[[44,48.1],[26,9.9]],"id":522742}],"con":true,"img":false}]}
{"op":"mcm","clk":"5348062507","pt":1646213337967,"mc":[{"id":"1.195453752","rc":[{"atl":[[26,16.25]],"id":522742}],"con":true,"img":false}]}
{"op":"mcm","clk":"5348062551","pt":1646213338747,"mc":[{"id":"1.195453752","rc":[{"atl":[[34,9.76]],"id":522746}],"con":true,"img":false}]}
{"op":"mcm","clk":"5348062597","pt":1646213339772,"mc":[{"id":"1.195453752","rc":[{"atl":[[38,0]],"id":522746}],"con":true,"img":false}]}
{"op":"mcm","clk":"5348062628","pt":1646213340389,"mc":[{"id":"1.195453752","rc":[{"atl":[[40,0],[42,44.38]],"id":522746},{"atl":[[50,8.19]],"id":522741}],"con":true,"img":false}]}
{"op":"mcm","clk":"5348062644","pt":1646213340654,"mc":[{"id":"1.195453752","rc":[{"atb":[[4,0],[3.65,37.74]],"id":3805747},{"atb":[[11.5,0]],"id":3805755},{"atb":[[9.8,15.13]],"id":3805736},{"atb":[[5.6,21.74]],"id":3805762},{"atb":[[7.4,0],[2.78,44.4]],"id":522742},{"atb":[[5,25],[5.7,0]],"id":3805740}],"con":true,"img":false}]}
{"op":"mcm","clk":"5348062648","pt":1646213340761,"mc":[{"id":"1.195453752","rc":[{"atb":[[3.85,35.09],[2.7,0]],"id":3805793},{"atl":[[11,10],[13.5,0]],"id":3805793},{"atb":[[8.4,13.51]],"id":3805736},{"atb":[[17,6.25],[13.5,0]],"id":522747},{"atb":[[6.4,0]],"id":3805762}],"con":true,"img":false}]}
{"op":"mcm","clk":"5348062654","pt":1646213340864,"mc":[{"id":"1.195453752","rc":[{"atb":[[9.8,11.36]],"id":3805755}],"con":true,"img":false}]}
{"op":"mcm","clk":"5348062686","pt":1646213341487,"mc":[{"id":"1.195453752","rc":[{"atl":[[100,0]],"id":522741}],"con":true,"img":false}]}
{"op":"mcm","clk":"5348062699","pt":1646213341688,"mc":[{"id":"1.195453752","rc":[{"atl":[[100,20.79],[110,2]],"id":522741}],"con":true,"img":false}]}
{"op":"mcm","clk":"5348062713","pt":1646213341849,"mc":[{"id":"1.195453752","rc":[{"atl":[[95,2],[110,0]],"id":522741}],"con":true,"img":false}]}
{"op":"mcm","clk":"5348062747","pt":1646213342371,"mc":[{"id":"1.195453752","rc":[{"atb":[[4.9,43.4],[4.4,0]],"id":3805747}],"con":true,"img":false}]}
{"op":"mcm","clk":"5348062810","pt":1646213343356,"mc":[{"id":"1.195453752","rc":[{"atb":[[4.8,2.72],[4.3,3.26]],"id":3805747}],"con":true,"img":false}]}
{"op":"mcm","clk":"5348062820","pt":1646213343568,"mc":[{"id":"1.195453752","rc":[{"atb":[[16.5,3.26],[18,38.72]],"id":522750}],"con":true,"img":false}]}
{"op":"mcm","clk":"5348062825","pt":1646213343674,"mc":[{"id":"1.195453752","rc":[{"atb":[[5.5,40.18]],"id":3805793},{"atl":[[34,4.95]],"id":522746},{"atl":[[34,4.95],[38,0],[42,9.9],[30,5.46]],"id":3805736}],"con":true,"img":false}]}
{"op":"mcm","clk":"5348062830","pt":1646213343776,"mc":[{"id":"1.195453752","rc":[{"atl":[[34,0],[38,4.95],[42,34.48],[46,9.9]],"id":522746},{"atl":[[30,0]],"id":3805736},{"atl":[[70,0],[75,9.9],[50,0],[55,4.95]],"id":522741},{"atl":[[16,0],[16.5,9.9],[14,0],[14.5,4.95]],"id":3805740}],"con":true,"img":false}]}
{"op":"mcm","clk":"5348062850","pt":1646213344188,"mc":[{"id":"1.195453752","rc":[{"atl":[[70,2],[42,28.97]],"id":3805736}],"con":true,"img":false}]}
{"op":"mcm","clk":"5348062864","pt":1646213344496,"mc":[{"id":"1.195453752","rc":[{"atb":[[5.1,9.9]],"id":3805793},{"atl":[[40,4.06],[42,0],[46,44.38]],"id":522746},{"atl":[[32,4.95],[65,2.47],[34,0],[40,9.9],[42,19.06]],"id":3805736},{"atl":[[70,2.29]],"id":522741},{"atl":[[19,8.8]],"id":3805740}],"con":true,"img":false}]}
{"op":"mcm","clk":"5348062893","pt":1646213344978,"mc":[{"id":"1.195453752","rc":[{"atl":[[19,29.26],[19.5,5.41]],"id":3805740}],"con":true,"img":false}]}
{"op":"mcm","clk":"5348062910","pt":1646213345279,"mc":[{"id":"1.195453752","rc":[{"atb":[[16,10.56],[13.5,12.21]],"id":522746},{"atb":[[13,0],[15.5,14.71]],"id":3805736},{"atb":[[6.4,14.71],[7.4,0]],"id":3805731}],"con":true,"img":false}]}
{"op":"mcm","clk":"5348062915","pt":1646213345385,"mc":[{"id":"1.195453752","rc":[{"atb":[[19.5,12.36],[24,6.89]],"id":522741}],"con":true,"img":false}]}
{"op":"mcm","clk":"5348062944","pt":1646213345800,"mc":[{"id":"1.195453752","rc":[{"atb":[[6.4,0],[6.8,29.25],[6,41.58]],"id":3805731}],"con":true,"img":false}]}
{"op":"mcm","clk":"5348062955","pt":1646213346010,"mc":[{"id":"1.195453752","rc":[{"atb":[[17,2.72],[14.5,8.22]],"id":522746},{"atb":[[16.5,7.67],[14,3.26]],"id":3805736},{"atb":[[7.2,2.72],[6.2,3.26]],"id":3805731}],"con":true,"img":false}]}
{"op":"mcm","clk":"5348062963","pt":1646213346072,"mc":[{"id":"1.195453752","rc":[{"atb":[[20,3.26],[25,2.72]],"id":522741}],"con":true,"img":false}]}
{"op":"mcm","clk":"5348062982","pt":1646213346374,"mc":[{"id":"1.195453752","rc":[{"atb":[[17.5,9.6],[13.5,0],[14.5,27.79]],"id":522746}],"con":true,"img":false}]}
{"op":"mcm","clk":"5348062988","pt":1646213346476,"mc":[{"id":"1.195453752","rc":[{"atb":[[21,19.66],[26,6.34]],"id":522741},{"atl":[[22,12.5]],"id":522742}],"con":true,"img":false}]}
{"op":"mcm","clk":"5348062994","pt":1646213346575,"mc":[{"id":"1.195453752","rc":[{"atb":[[19.5,0]],"id":522741}],"con":true,"img":false}]}
{"op":"mcm","clk":"5348063032","pt":1646213347093,"mc":[{"id":"1.195453752","rc":[{"atb":[[16,0]],"id":522746}],"con":true,"img":false}]}
{"op":"mcm","clk":"5348063051","pt":1646213347396,"mc":[{"id":"1.195453752","rc":[{"atl":[[36,4.52]],"id":522746}],"con":true,"img":false}]}
{"op":"mcm","clk":"5348063058","pt":1646213347505,"mc":[{"id":"1.195453752","rc":[{"atb":[[24,0]],"id":522741},{"atl":[[26,9.9]],"id":522742}],"con":true,"img":false}]}
{"op":"mcm","clk":"5348063102","pt":1646213348279,"mc":[{"id":"1.195453752","rc":[{"atl":[[40,0]],"id":522746}],"con":true,"img":false}]}
{"op":"mcm","clk":"5348063126","pt":1646213348894,"mc":[{"id":"1.195453752","rc":[{"atl":[[50,3.23]],"id":522741}],"con":true,"img":false}]}
{"op":"mcm","clk":"5348063141","pt":1646213349365,"mc":[{"id":"1.195453752","rc":[{"atb":[[9,12.5],[10.5,0]],"id":522750}],"con":true,"img":false}]}
{"op":"mcm","clk":"5348063150","pt":1646213349572,"mc":[{"id":"1.195453752","rc":[{"atl":[[70,0]],"id":522741}],"con":true,"img":false}]}
{"op":"mcm","clk":"5348063153","pt":1646213349678,"mc":[{"id":"1.195453752","rc":[{"atb":[[5.1,4.95],[5.3,0],[4.9,33.5]],"id":3805747},{"atb":[[16.5,2.72],[17,12.31],[14.5,0],[15,9.9]],"id":3805736}],"con":true,"img":false}]}
{"op":"mcm","clk":"5348063169","pt":1646213350192,"mc":[{"id":"1.195453752","rc":[{"atl":[[75,26.68],[100,0]],"id":522741}],"con":true,"img":false}]}
{"op":"mcm","clk":"5348063228","pt":1646213351287,"mc":[{"id":"1.195453752","rc":[{"atl":[[16.5,0],[16,9.9],[14,4.95],[14.5,0]],"id":3805740}],"con":true,"img":false}]}
{"op":"mcm","clk":"5348063293","pt":1646213352262,"mc":[{"id":"1.195453752","rc":[{"atl":[[50,0]],"id":522741}],"con":true,"img":false}]}
{"op":"mcm","clk":"5348063327","pt":1646213352877,"mc":[{"id":"1.195453752","rc":[{"atl":[[14,17.15]],"id":3805740}],"con":true,"img":false}]}
{"op":"mcm","clk":"5348063332","pt":1646213352981,"mc":[{"id":"1.195453752","rc":[{"atl":[[32,10.06]],"id":3805736}],"con":true,"img":false}]}
{"op":"mcm","clk":"5348063347","pt":1646213353289,"mc":[{"id":"1.195453752","rc":[{"atl":[[70,2.29]],"id":522741}],"con":true,"img":false}]}
{"op":"mcm","clk":"5348063370","pt":1646213353705,"mc":[{"id":"1.195453752","rc":[{"atl":[[9.2,0]],"id":3805731},{"atl":[[19,20.45]],"id":3805740}],"con":true,"img":false}]}
{"op":"mcm","clk":"5348063388","pt":1646213353973,"mc":[{"id":"1.195453752","rc":[{"atl":[[65,0]],"id":3805736}],"con":true,"img":false}]}
{"op":"mcm","clk":"5348063407","pt":1646213354284,"mc":[{"id":"1.195453752","rc":[{"atl":[[10.5,9.9],[14.5,25.78]],"id":3805731}],"con":true,"img":false}]}
{"op":"mcm","clk":"5348063427","pt":1646213354699,"mc":[{"id":"1.195453752","rc":[{"atb":[[6.2,21.64],[6,9.9]],"id":3805731},{"atl":[[10.5,22.12]],"id":3805731}],"con":true,"img":false}]}
{"op":"mcm","clk":"5348063569","pt":1646213357595,"mc":[{"id":"1.195453752","rc":[{"atl":[[50,3.23]],"id":522741}],"con":true,"img":false}]}
{"op":"mcm","clk":"5348063574","pt":1646213357697,"mc":[{"id":"1.195453752","rc":[{"atl":[[36,14.43],[29,4.95]],"id":522746}],"con":true,"img":false}]}
{"op":"mcm","clk":"5348063581","pt":1646213357800,"mc":[{"id":"1.195453752","rc":[{"atl":[[38,0],[46,34.48]],"id":522746},{"atb":[[9,0],[10,0]],"id":3805740}],"con":true,"img":false}]}
{"op":"mcm","clk":"5348063607","pt":1646213358267,"mc":[{"id":"1.195453752","rc":[{"atl":[[38,21.64],[46,0],[29,10.61]],"id":522746}],"con":true,"img":false}]}
{"op":"mcm","clk":"5348063615","pt":1646213358372,"mc":[{"id":"1.195453752","rc":[{"atl":[[70,0]],"id":522741},{"atb":[[7.6,50.12],[8.8,20.32]],"id":3805740}],"con":true,"img":false}]}
{"op":"mcm","clk":"5348063622","pt":1646213358480,"mc":[{"id":"1.195453752","rc":[{"atl":[[36,4.52],[29,5.66],[30,4.95]],"id":522746},{"atb":[[9.8,2.72],[8.8,23.59]],"id":3805740}],"con":true,"img":false}]}
{"op":"mcm","clk":"5348063632","pt":1646213358584,"mc":[{"id":"1.195453752","rc":[{"atl":[[70,12.17],[75,9.9]],"id":522741}],"con":true,"img":false}]}
{"op":"mcm","clk":"5348063658","pt":1646213359095,"mc":[{"id":"1.195453752","rc":[{"atl":[[36,0]],"id":522746}],"con":true,"img":false}]}
{"op":"mcm","clk":"5348063699","pt":1646213359710,"mc":[{"id":"1.195453752","rc":[{"atb":[[7.2,27.99]],"id":3805731}],"con":true,"img":false}]}
{"op":"mcm","clk":"5348063734","pt":1646213360388,"mc":[{"id":"1.195453752","rc":[{"atl":[[29,0]],"id":522746},{"atb":[[6.8,4.95]],"id":3805731}],"con":true,"img":false}]}
{"op":"mcm","clk":"5348063765","pt":1646213361113,"mc":[{"id":"1.195453752","rc":[{"atb":[[4.8,0],[4.3,0]],"id":3805747},{"atb":[[11,15.85],[9.4,4.95]],"id":3805762}],"con":true,"img":false}]}
{"op":"mcm","clk":"5348063794","pt":1646213361470,"mc":[{"id":"1.195453752","rc":[{"atl":[[36,4.52]],"id":522746}],"con":true,"img":false}]}
{"op":"mcm","clk":"5348063807","pt":1646213361780,"mc":[{"id":"1.195453752","rc":[{"atb":[[4.2,3.26],[4.7,2.72]],"id":3805747},{"atb":[[9.2,3.26],[10.5,2.72]],"id":3805762}],"con":true,"img":false}]}
{"op":"mcm","clk":"5348063834","pt":1646213362503,"mc":[{"id":"1.195453752","rc":[{"atb":[[8.6,9.9],[9.4,19.66]],"id":3805762}],"con":true,"img":false}]}
{"op":"mcm","clk":"5348063861","pt":1646213363182,"mc":[{"id":"1.195453752","rc":[{"atl":[[9.4,23.82]],"id":3805731}],"con":true,"img":false}]}
{"op":"mcm","clk":"5348063866","pt":1646213363289,"mc":[{"id":"1.195453752","rc":[{"atb":[[2.5,0],[3.25,0],[2.7,0]],"id":3805747},{"atb":[[3.45,0],[4.9,0],[2.98,0]],"id":3805746},{"atb":[[2.46,0],[2.66,0],[3.15,0]],"id":3805793},{"atb":[[5.1,0],[10.5,0],[6.2,0]],"id":3805755},{"atb":[[10,0],[5,0],[6,0]],"id":522746},{"atb":[[9.8,0],[4.9,0],[5.9,0]],"id":3805736},{"atb":[[8,0],[20,0],[10,0]],"id":522747},{"atb":[[6.4,0],[11,0],[5.2,0]],"id":522750},{"atb":[[3.35,0],[2.94,0],[4.7,0]],"id":3805731},{"atb":[[4.5,0],[7,0],[3.75,0]],"id":3805762},{"atb":[[3.7,0],[6.8,0],[4.4,0]],"id":3805730},{"atb":[[6.2,0],[8.2,0],[15.5,0]],"id":522741},{"atb":[[4.5,0],[7,0],[3.75,0]],"id":522742},{"atb":[[16,0],[6.4,0],[8.4,0]],"id":522743},{"atb":[[3.6,0],[6.4,0],[4.2,0]],"id":3805740}],"con":true,"img":false}]}
{"op":"mcm","clk":"5348063920","pt":1646213364217,"mc":[{"id":"1.195453752","rc":[{"atl":[[10.5,9.9]],"id":3805731}],"con":true,"img":false}]}
{"op":"mcm","clk":"5348063964","pt":1646213364996,"mc":[{"id":"1.195453752","rc":[{"atb":[[8.6,4.95],[7.6,40.22],[7.8,9.9],[8.4,0]],"id":3805740}],"con":true,"img":false}]}
{"op":"mcm","clk":"5348064014","pt":1646213365717,"mc":[{"id":"1.195453752","rc":[{"atl":[[80,2],[100,0]],"id":522747}],"con":true,"img":false}]}
{"op":"mcm","clk":"5348064018","pt":1646213365814,"mc":[{"id":"1.195453752","rc":[{"atl":[[70,4.95],[90,9.9]],"id":522747}],"con":true,"img":false}]}
{"op":"mcm","clk":"5348064030","pt":1646213366021,"mc":[{"id":"1.195453752","rc":[{"atl":[[170,2],[240,8.65]],"id":522747}],"con":true,"img":false}]}
{"op":"mcm","clk":"5348064047","pt":1646213366389,"mc":[{"id":"1.195453752","rc":[{"atl":[[30,10.42]],"id":522746},{"atl":[[65,2.47],[90,22.63],[240,0]],"id":522747}],"con":true,"img":false}]}
{"op":"mcm","clk":"5348064069","pt":1646213366800,"mc":[{"id":"1.195453752","rc":[{"atb":[[8.6,45.17],[7.6,0]],"id":3805740}],"con":true,"img":false}]}
{"op":"mcm","clk":"5348064083","pt":1646213367109,"mc":[{"id":"1.195453752","rc":[{"atl":[[80,0]],"id":522747}],"con":true,"img":false}]}
{"op":"mcm","clk":"5348064086","pt":1646213367210,"mc":[{"id":"1.195453752","rc":[{"atl":[[36,0]],"id":522746}],"con":true,"img":false}]}
{"op":"mcm","clk":"5348064125","pt":1646213367786,"mc":[{"id":"1.195453752","rc":[{"atl":[[38,0],[55,31.77]],"id":522746}],"con":true,"img":false}]}
{"op":"mcm","clk":"5348064260","pt":1646213370415,"mc":[{"id":"1.195453752","rc":[{"atb":[[5.1,0],[5.3,4.95],[4.9,43.4]],"id":3805747},{"atb":[[9.6,9.9],[10.5,16.68],[11,4.95],[7.4,0],[8.4,29.45],[9.4,0]],"id":3805746},{"atl":[[17.5,9.6],[23,9.9]],"id":3805746},{"atl":[[36,4.95],[38,4.28],[44,9.9],[46,0]],"id":3805755},{"atb":[[7.2,2.72]],"id":3805731},{"atb":[[11,0]],"id":3805762},{"atl":[[16,0],[17,9.9],[18,12.21],[15,4.95]],"id":3805762},{"atb":[[11,0],[11.5,9.9],[13,15.93],[13.5,4.95]],"id":522742},{"atb":[[32,0]],"id":522743},{"atl":[[70,9.9],[75,0],[50,4.95],[55,2.93]],"id":522743},{"atb":[[8.6,40.22],[7.8,0],[8.4,4.95]],"id":3805740}],"con":true,"img":false}]}
{"op":"mcm","clk":"5348064277","pt":1646213370622,"mc":[{"id":"1.195453752","rc":[{"atl":[[130,0.13],[85,2]],"id":3805755},{"atl":[[130,2],[200,0.08]],"id":522743}],"con":true,"img":false}]}
{"op":"mcm","clk":"5348064282","pt":1646213370723,"mc":[{"id":"1.195453752","rc":[{"atl":[[75,0],[44,4.95]],"id":522741}],"con":true,"img":false}]}
{"op":"mcm","clk":"5348064290","pt":1646213370825,"mc":[{"id":"1.195453752","rc":[{"atl":[[130,0],[36,9.48]],"id":3805755},{"atb":[[9.2,15.48],[9.4,4.95]],"id":3805762},{"atl":[[17,22.12],[18,0],[14.5,5.72]],"id":3805762},{"atb":[[10.5,3.26],[11.5,43.21]],"id":522742},{"atb":[[23,35.26]],"id":522743},{"atl":[[70,31.99]],"id":522743}],"con":true,"img":false}]}
{"op":"mcm","clk":"5348064294","pt":1646213370932,"mc":[{"id":"1.195453752","rc":[{"atb":[[9.6,39.36],[11.5,15.1],[8.4,0]],"id":3805746},{"atl":[[36,0],[23,39.36]],"id":3805746},{"atl":[[44,27.96]],"id":3805755},{"atb":[[14,12.19]],"id":522742},{"atb":[[27,4.95]],"id":522743},{"atl":[[200,0]],"id":522743}],"con":true,"img":false}]}
{"op":"mcm","clk":"5348064305","pt":1646213371098,"mc":[{"id":"1.195453752","rc":[{"atb":[[8.6,2.72],[7.6,3.26]],"id":3805746},{"atb":[[6.8,32.29]],"id":3805731},{"atb":[[9.4,10.67]],"id":3805762},{"atb":[[27,11.05]],"id":522743}],"con":true,"img":false}]}
{"op":"mcm","clk":"5348064316","pt":1646213371300,"mc":[{"id":"1.195453752","rc":[{"atl":[[42,3.86]],"id":522741},{"atl":[[50,8.19]],"id":522743}],"con":true,"img":false}]}
{"op":"mcm","clk":"5348064321","pt":1646213371405,"mc":[{"id":"1.195453752","rc":[{"atl":[[70,0],[55,19.66]],"id":522741}],"con":true,"img":false}]}
{"op":"mcm","clk":"5348064325","pt":1646213371508,"mc":[{"id":"1.195453752","rc":[{"atl":[[65,7.43],[70,0],[85,9.9],[90,12.72]],"id":522747}],"con":true,"img":false}]}
{"op":"mcm","clk":"5348064332","pt":1646213371611,"mc":[{"id":"1.195453752","rc":[{"atl":[[38,0]],"id":3805755},{"atl":[[36,9.9],[29,4.95],[30,5.46]],"id":522746},{"atl":[[15.5,0]],"id":3805762}],"con":true,"img":false}]}
{"op":"mcm","clk":"5348064335","pt":1646213371713,"mc":[{"id":"1.195453752","rc":[{"atb":[[10.5,0]],"id":3805746},{"atb":[[13,2.72]],"id":522742}],"con":true,"img":false}]}
{"op":"mcm","clk":"5348064362","pt":1646213372124,"mc":[{"id":"1.195453752","rc":[{"atl":[[50,0]],"id":522741},{"atl":[[55,0]],"id":522743}],"con":true,"img":false}]}
{"op":"mcm","clk":"5348064383","pt":1646213372388,"mc":[{"id":"1.195453752","rc":[{"atl":[[29,10.61]],"id":522746},{"atb":[[10.5,0],[13,0]],"id":522742}],"con":true,"img":false}]}
{"op":"mcm","clk":"5348064442","pt":1646213373318,"mc":[{"id":"1.195453752","rc":[{"atl":[[30,0]],"id":522746},{"atb":[[11,3.26],[13.5,7.67]],"id":522742}],"con":true,"img":false}]}
{"op":"mcm","clk":"5348064519","pt":1646213374714,"mc":[{"id":"1.195453752","rc":[{"atl":[[130,17.99],[70,9.9]],"id":522743}],"con":true,"img":false}]}
{"op":"mcm","clk":"5348064524","pt":1646213374820,"mc":[{"id":"1.195453752","rc":[{"atl":[[85,26.46],[44,9.9]],"id":3805755}],"con":true,"img":false}]}
{"op":"mcm","clk":"5348064538","pt":1646213375128,"mc":[{"id":"1.195453752","rc":[{"atb":[[17,0],[14.5,24.52]],"id":522746},{"atb":[[7.2,0]],"id":3805731}],"con":true,"img":false}]}
{"op":"mcm","clk":"5348064543","pt":1646213375228,"mc":[{"id":"1.195453752","rc":[{"atb":[[6.2,18.37]],"id":3805731},{"atb":[[20,0],[25,0]],"id":522741}],"con":true,"img":false}]}
{"op":"mcm","clk":"5348064577","pt":1646213375704,"mc":[{"id":"1.195453752","rc":[{"atb":[[12.5,40.42],[14.5,4.95]],"id":522746},{"atb":[[6.2,0],[6,77.49]],"id":3805731},{"atb":[[18.5,34.06],[21,4.95]],"id":522741}],"con":true,"img":false}]}
{"op":"mcm","clk":"5348064585","pt":1646213375807,"mc":[{"id":"1.195453752","rc":[{"atb":[[18,2.72],[15.5,3.26]],"id":522746},{"atb":[[7.6,2.72]],"id":3805731}],"con":true,"img":false}]}
{"op":"mcm","clk":"5348064589","pt":1646213375910,"mc":[{"id":"1.195453752","rc":[{"atb":[[6.6,3.26]],"id":3805731},{"atb":[[21,8.22]],"id":522741}],"con":true,"img":false}]}
{"op":"mcm","clk":"5348064592","pt":1646213376012,"mc":[{"id":"1.195453752","rc":[{"atb":[[26,9.06]],"id":522741}],"con":true,"img":false}]}
{"op":"mcm","clk":"5348064610","pt":1646213376319,"mc":[{"id":"1.195453752","rc":[{"atb":[[18.5,9.05]],"id":522746}],"con":true,"img":false}]}
{"op":"mcm","clk":"5348064619","pt":1646213376527,"mc":[{"id":"1.195453752","rc":[{"atb":[[12.5,9.9]],"id":522746}],"con":true,"img":false}]}
{"op":"mcm","clk":"5348064645","pt":1646213376989,"mc":[{"id":"1.195453752","rc":[{"atb":[[17.5,0]],"id":522746}],"con":true,"img":false}]}
{"op":"mcm","clk":"5348064701","pt":1646213378124,"mc":[{"id":"1.195453752","rc":[{"atb":[[6.4,49.33],[11,13.31],[5.2,63.42]],"id":522746},{"atb":[[21,6.65],[10.5,28.03],[8.2,36.99]],"id":522747},{"atb":[[4.3,40.36],[2.86,143.22],[3.15,123.9]],"id":3805731},{"atb":[[3.85,93.47],[7.4,20.81],[4.7,71.99]],"id":3805730},{"atb":[[6.2,51.22],[8.2,36.99],[15.5,9.18]],"id":522741},{"atl":[[42,0]],"id":522741},{"atb":[[3.95,90.29],[4.9,68.3],[7.8,19.58]],"id":522742},{"atb":[[16,8.87],[6.4,49.33],[8.4,35.99]],"id":522743}],"con":true,"img":false}]}
{"op":"mcm","clk":"5348064705","pt":1646213378233,"mc":[{"id":"1.195453752","rc":[{"atb":[[2.46,182.45],[2.66,160.47],[3.15,61.94]],"id":3805747},{"atb":[[5.3,30.97],[3.15,123.9],[3.65,100.52]],"id":3805746},{"atb":[[2.42,187.6],[2.62,164.43],[3.05,64.97]],"id":3805793},{"atb":[[6.4,49.33],[11,13.31],[5.2,63.42]],"id":3805755},{"atb":[[5.1,64.97],[10.5,14.02],[6.2,51.22]],"id":3805736},{"atb":[[5.3,61.94],[11.5,12.68],[6.6,47.57]],"id":522750},{"atb":[[4.3,80.72],[6.6,23.78],[3.65,100.52]],"id":3805762},{"atb":[[4,88.79],[6,26.63],[3.5,106.55]],"id":3805740}],"con":true,"img":false}]}
{"op":"mcm","clk":"5348064738","pt":1646213378811,"mc":[{"id":"1.195453752","rc":[{"atl":[[95,23.89]],"id":522741}],"con":true,"img":false}]}
{"op":"mcm","clk":"5348064743","pt":1646213378904,"mc":[{"id":"1.195453752","rc":[{"atl":[[55,4.95]],"id":522741}],"con":true,"img":false}]}
{"op":"mcm","clk":"5348064747","pt":1646213379013,"mc":[{"id":"1.195453752","rc":[{"atb":[[10.5,19.41]],"id":3805762},{"atl":[[50,3.23]],"id":522741},{"atb":[[28,8.59]],"id":522743}],"con":true,"img":false}]}
{"op":"mcm","clk":"5348064778","pt":1646213379736,"mc":[{"id":"1.195453752","rc":[{"atl":[[95,2]],"id":522741}],"con":true,"img":false}]}
{"op":"mcm","clk":"5348064786","pt":1646213379898,"mc":[{"id":"1.195453752","rc":[{"atb":[[9.4,4.95]],"id":3805762},{"atb":[[27,4.95]],"id":522743}],"con":true,"img":false}]}
{"op":"mcm","clk":"5348064828","pt":1646213380823,"mc":[{"id":"1.195453752","rc":[{"atb":[[7.6,0],[6.6,0]],"id":3805731}],"con":true,"img":false}]}
{"op":"mcm","clk":"5348064859","pt":1646213381446,"mc":[{"id":"1.195453752","rc":[{"atb":[[15,4.95]],"id":522746},{"atb":[[4.8,103.75],[6,9.9]],"id":3805731},{"atb":[[10.5,2.72]],"id":3805762}],"con":true,"img":false}]}
{"op":"mcm","clk":"5348064862","pt":1646213381549,"mc":[{"id":"1.195453752","rc":[{"atb":[[12.5,0],[14.5,0]],"id":522746},{"atb":[[6.4,3.26],[7.4,2.72]],"id":3805731}],"con":true,"img":false}]}
{"op":"mcm","clk":"5348064894","pt":1646213382222,"mc":[{"id":"1.195453752","rc":[{"atb":[[4.8,26.32]],"id":3805731},{"atb":[[9.4,20.81]],"id":3805762}],"con":true,"img":false}]}
{"op":"mcm","clk":"5348064913","pt":1646213382533,"mc":[{"id":"1.195453752","rc":[{"atb":[[5.6,4.95],[5.1,0],[5.5,35.23],[5.2,9.9]],"id":3805793},{"atb":[[6.4,8.22],[6.8,27.33],[6,0]],"id":3805731},{"atl":[[9.2,4.95],[10,9.9],[10.5,0],[9.4,18.87]],"id":3805731},{"atb":[[11.5,33.3],[12.5,4.95],[13.5,2.72]],"id":522742},{"atl":[[21,4.95],[22,7.54],[25,9.9],[26,0]],"id":522742}],"con":true,"img":false}]}
{"op":"mcm","clk":"5348064936","pt":1646213382930,"mc":[{"id":"1.195453752","rc":[{"atb":[[5.2,60.34],[5.7,33.73],[4.7,2.72]],"id":3805793},{"atl":[[9,19.81],[10,36.85],[14.5,7.41]],"id":3805731},{"atb":[[11.5,0],[12.5,23.53]],"id":522742},{"atl":[[21,12.88],[44,2.33],[25,28.48]],"id":522742}],"con":true,"img":false}]}
{"op":"mcm","clk":"5348064976","pt":1646213383651,"mc":[{"id":"1.195453752","rc":[{"atb":[[15.5,31.46]],"id":522746},{"atb":[[6.4,48.48]],"id":3805731}],"con":true,"img":false}]}
{"op":"mcm","clk":"5348064991","pt":1646213383918,"mc":[{"id":"1.195453752","rc":[{"atb":[[5.5,0]],"id":3805793},{"atl":[[9.4,0]],"id":3805731},{"atl":[[22,0]],"id":522742}],"con":true,"img":false}]}
{"op":"mcm","clk":"5348065012","pt":1646213384323,"mc":[{"id":"1.195453752","rc":[{"atl":[[85,2],[95,0]],"id":522741}],"con":true,"img":false}]}
{"op":"mcm","clk":"5348065044","pt":1646213384941,"mc":[{"id":"1.195453752","rc":[{"atl":[[8,0],[8.2,4.95],[8.8,0]],"id":3805793}],"con":true,"img":false}]}
{"op":"mcm","clk":"5348065101","pt":1646213385927,"mc":[{"id":"1.195453752","rc":[{"atl":[[9,9.9]],"id":3805793}],"con":true,"img":false}]}
{"op":"mcm","clk":"5348065118","pt":1646213386235,"mc":[{"id":"1.195453752","rc":[{"atb":[[7,16.67],[5.9,0]],"id":3805746},{"atb":[[3.85,0],[4.4,29.41]],"id":3805793},{"atb":[[7.6,15.15],[8.8,0]],"id":522746},{"atb":[[10,11.11],[8.4,0]],"id":3805736},{"atb":[[17,0],[13.5,8]],"id":522747},{"atb":[[6.4,18.52],[7.8,0]],"id":3805730},{"atb":[[2.78,0],[3.65,37.74]],"id":522742},{"atl":[[19.5,0],[26,4]],"id":3805740}],"con":true,"img":false}]}
{"op":"mcm","clk":"5348065123","pt":1646213386340,"mc":[{"id":"1.195453752","rc":[{"atb":[[9.8,0],[8.8,20.32]],"id":3805740}],"con":true,"img":false}]}
{"op":"mcm","clk":"5348065135","pt":1646213386647,"mc":[{"id":"1.195453752","rc":[{"atl":[[55,24.52]],"id":522741},{"atl":[[44,39.6]],"id":522742}],"con":true,"img":false}]}
{"op":"mcm","clk":"5348065138","pt":1646213386749,"mc":[{"id":"1.195453752","rc":[{"atl":[[25,9.9]],"id":522742}],"con":true,"img":false}]}
{"op":"mcm","clk":"5348065153","pt":1646213387017,"mc":[{"id":"1.195453752","rc":[{"atb":[[10.5,19.41]],"id":3805762},{"atl":[[44,8.64]],"id":522741},{"atb":[[8.6,0],[8.4,60.66]],"id":3805740}],"con":true,"img":false}]}
{"op":"mcm","clk":"5348065168","pt":1646213387326,"mc":[{"id":"1.195453752","rc":[{"atb":[[9,3.26],[10,2.72]],"id":3805740}],"con":true,"img":false}]}
{"op":"mcm","clk":"5348065202","pt":1646213388041,"mc":[{"id":"1.195453752","rc":[{"atb":[[9.4,4.95]],"id":3805762},{"atl":[[50,0]],"id":522741}],"con":true,"img":false}]}
{"op":"mcm","clk":"5348065264","pt":1646213389334,"mc":[{"id":"1.195453752","rc":[{"atb":[[4.2,0],[4.7,0]],"id":3805747}],"con":true,"img":false}]}
{"op":"mcm","clk":"5348065314","pt":1646213390119,"mc":[{"id":"1.195453752","rc":[{"atb":[[5.1,2.72],[4.6,3.26]],"id":3805747}],"con":true,"img":false}]}
{"op":"mcm","clk":"5348065326","pt":1646213390325,"mc":[{"id":"1.195453752","rc":[{"atl":[[55,4.95]],"id":522741}],"con":true,"img":false}]}
{"op":"mcm","clk":"5348065333","pt":1646213390425,"mc":[{"id":"1.195453752","rc":[{"atl":[[85,26.46]],"id":522741}],"con":true,"img":false}]}
{"op":"mcm","clk":"5348065351","pt":1646213390733,"mc":[{"id":"1.195453752","rc":[{"atb":[[5.1,24.81],[4.9,9.9]],"id":3805747}],"con":true,"img":false}]}
{"op":"mcm","clk":"5348065370","pt":1646213391148,"mc":[{"id":"1.195453752","rc":[{"atl":[[65,2.47],[70,4.95],[85,0],[90,22.63]],"id":522747},{"atl":[[44,0],[46,4.95],[55,0],[60,9.9]],"id":522741}],"con":true,"img":false}]}
{"op":"mcm","clk":"5348065403","pt":1646213391927,"mc":[{"id":"1.195453752","rc":[{"atl":[[55,2.93]],"id":522741}],"con":true,"img":false}]}
{"op":"mcm","clk":"5348065448","pt":1646213392859,"mc":[{"id":"1.195453752","rc":[{"atl":[[16,0],[12.5,4.95],[14,12.19],[14.5,9.9]],"id":3805740}],"con":true,"img":false}]}
{"op":"mcm","clk":"5348065469","pt":1646213393338,"mc":[{"id":"1.195453752","rc":[{"atl":[[19,0],[12,14.41],[14.5,31.99]],"id":3805740}],"con":true,"img":false}]}
{"op":"mcm","clk":"5348065515","pt":1646213394153,"mc":[{"id":"1.195453752","rc":[{"atl":[[14,0]],"id":3805740}],"con":true,"img":false}]}
{"op":"mcm","clk":"5348065527","pt":1646213394360,"mc":[{"id":"1.195453752","rc":[{"atl":[[85,2],[60,35.6]],"id":522741}],"con":true,"img":false}]}
{"op":"mcm","clk":"5348065544","pt":1646213394668,"mc":[{"id":"1.195453752","rc":[{"atl":[[13,8.33],[14.5,0]],"id":3805731},{"atl":[[46,8.47]],"id":522741},{"atb":[[8.8,45.81],[8.4,4.95]],"id":3805740}],"con":true,"img":false}]}
{"op":"mcm","clk":"5348065559","pt":1646213394930,"mc":[{"id":"1.195453752","rc":[{"atl":[[36,4.52],[38,4.95],[44,0],[46,9.9]],"id":3805755},{"atb":[[17,7.35],[15,0]],"id":3805736}],"con":true,"img":false}]}
{"op":"mcm","clk":"5348065573","pt":1646213395237,"mc":[{"id":"1.195453752","rc":[{"atb":[[17.5,4.95],[15.5,24.62]],"id":3805736}],"con":true,"img":false}]}
{"op":"mcm","clk":"5348065586","pt":1646213395444,"mc":[{"id":"1.195453752","rc":[{"atl":[[85,2],[46,27.96]],"id":3805755},{"atl":[[55,0]],"id":522741}],"con":true,"img":false}]}
{"op":"mcm","clk":"5348065598","pt":1646213395650,"mc":[{"id":"1.195453752","rc":[{"atb":[[8.6,13.16],[10,0]],"id":3805736},{"atl":[[42,2.44]],"id":3805762},{"atb":[[4.3,30.3],[3.65,0]],"id":522742}],"con":true,"img":false}]}
{"op":"mcm","clk":"5348065603","pt":1646213395755,"mc":[{"id":"1.195453752","rc":[{"atl":[[10,0]],"id":3805747},{"atb":[[7,0]],"id":3805746},{"atb":[[16.5,28.39],[18,9.32],[15.5,9.9]],"id":3805736},{"atl":[[29,0]],"id":3805762}],"con":true,"img":false}]}
{"op":"mcm","clk":"5348065605","pt":1646213395857,"mc":[{"id":"1.195453752","rc":[{"atl":[[12,9.09]],"id":3805747},{"atb":[[6,20]],"id":3805746},{"atb":[[9.6,11.63],[8.6,0]],"id":3805736}],"con":true,"img":false}]}
{"op":"mcm","clk":"5348065616","pt":1646213396067,"mc":[{"id":"1.195453752","rc":[{"atl":[[7.2,25.57],[8.8,9.9]],"id":3805747},{"atl":[[8,4.95],[9,0],[8.2,0],[8.8,9.9]],"id":3805793},{"atl":[[23,4.95],[24,0],[27,9.9],[28,26.48]],"id":3805730}],"con":true,"img":false}]}
{"op":"mcm","clk":"5348065619","pt":1646213396125,"mc":[{"id":"1.195453752","rc":[{"atb":[[26,2.72]],"id":522741}],"con":true,"img":false}]}
{"op":"mcm","clk":"5348065636","pt":1646213396533,"mc":[{"id":"1.195453752","rc":[{"atl":[[9.6,0],[8.8,61.51]],"id":3805747},{"atb":[[17,0]],"id":3805736},{"atl":[[27,36.39],[28,0]],"id":3805730}],"con":true,"img":false}]}
{"op":"mcm","clk":"5348065651","pt":1646213396843,"mc":[{"id":"1.195453752","rc":[{"atb":[[21,16.15]],"id":522741}],"con":true,"img":false}]}
{"op":"mcm","clk":"5348065693","pt":1646213397624,"mc":[{"id":"1.195453752","rc":[{"atb":[[8.6,0],[7.6,0]],"id":3805746}],"con":true,"img":false}]}
{"op":"mcm","clk":"5348065711","pt":1646213397929,"mc":[{"id":"1.195453752","rc":[{"atl":[[85,26.46],[60,9.9]],"id":522741}],"con":true,"img":false}]}
{"op":"mcm","clk":"5348065750","pt":1646213398653,"mc":[{"id":"1.195453752","rc":[{"atb":[[8.6,2.72],[7.6,3.26]],"id":3805746}],"con":true,"img":false}]}
{"op":"mcm","clk":"5348066042","pt":1646213402464,"mc":[{"id":"1.195453752","rc":[{"atb":[[9.2,12.21],[10.5,16.68]],"id":3805762}],"con":true,"img":false}]}
{"op":"mcm","clk":"5348066120","pt":1646213403245,"mc":[{"id":"1.195453752","rc":[{"atb":[[9,3.26],[10,2.72]],"id":3805762}],"con":true,"img":false}]}
{"op":"mcm","clk":"5348066161","pt":1646213403769,"mc":[{"id":"1.195453752","rc":[{"atb":[[9.2,0]],"id":3805762}],"con":true,"img":false}]}
{"op":"mcm","clk":"5348066170","pt":1646213403873,"mc":[{"id":"1.195453752","rc":[{"atb":[[9.4,20.81]],"id":3805762}],"con":true,"img":false}]}
{"op":"mcm","clk":"5348066353","pt":1646213405850,"mc":[{"id":"1.195453752","rc":[{"atb":[[8.6,4.95],[8.4,0]],"id":3805740}],"con":true,"img":false}]}
{"op":"mcm","clk":"5348066389","pt":1646213406470,"mc":[{"id":"1.195453752","rc":[{"atb":[[18,0],[15.5,28.19]],"id":522746}],"con":true,"img":false}]}
{"op":"mcm","clk":"5348066393","pt":1646213406573,"mc":[{"id":"1.195453752","rc":[{"atb":[[11,0],[13.5,0]],"id":522742}],"con":true,"img":false}]}
{"op":"mcm","clk":"5348066407","pt":1646213406836,"mc":[{"id":"1.195453752","rc":[{"atb":[[15.5,0]],"id":522746}],"con":true,"img":false}]}
{"op":"mcm","clk":"5348066429","pt":1646213407145,"mc":[{"id":"1.195453752","rc":[{"atb":[[16,3.26],[18.5,11.78],[15,35.46]],"id":522746},{"atb":[[12.5,4.95],[7.8,67.84]],"id":522742}],"con":true,"img":false}]}
{"op":"mcm","clk":"5348066452","pt":1646213407457,"mc":[{"id":"1.195453752","rc":[{"atb":[[11.5,3.26],[14,14.92]],"id":522742}],"con":true,"img":false}]}
{"op":"mcm","clk":"5348066594","pt":1646213409943,"mc":[{"id":"1.195453752","rc":[{"atl":[[65,7.43],[70,0],[85,9.9],[90,12.72]],"id":522747}],"con":true,"img":false}]}
{"op":"mcm","clk":"5348066630","pt":1646213410456,"mc":[{"id":"1.195453752","rc":[{"atl":[[21,0]],"id":3805730}],"con":true,"img":false}]}
{"op":"mcm","clk":"5348066658","pt":1646213410871,"mc":[{"id":"1.195453752","rc":[{"atl":[[36,9.48],[44,9.9]],"id":3805755},{"atl":[[27,9.9]],"id":3805730}],"con":true,"img":false}]}
{"op":"mcm","clk":"5348066663","pt":1646213410974,"mc":[{"id":"1.195453752","rc":[{"atb":[[5,9.9],[5.3,0],[4.9,0],[5.4,38.45]],"id":3805747},{"atl":[[38,0],[46,18.06]],"id":3805755},{"atl":[[60,26.8]],"id":3805730}],"con":true,"img":false}]}
{"op":"mcm","clk":"5348066683","pt":1646213411285,"mc":[{"id":"1.195453752","rc":[{"atl":[[27,16]],"id":3805730}],"con":true,"img":false}]}
{"op":"mcm","clk":"5348066702","pt":1646213411555,"mc":[{"id":"1.195453752","rc":[{"atb":[[5.1,2.72],[5,84.78]],"id":3805747},{"atl":[[44,34.69],[46,0]],"id":3805755}],"con":true,"img":false}]}
{"op":"mcm","clk":"5348066759","pt":1646213412376,"mc":[{"id":"1.195453752","rc":[{"atl":[[44,9.9]],"id":3805755}],"con":true,"img":false}]}
{"op":"mcm","clk":"5348066802","pt":1646213413055,"mc":[{"id":"1.195453752","rc":[{"atb":[[6,0],[7,16.67]],"id":3805746}],"con":true,"img":false}]}
{"op":"mcm","clk":"5348066867","pt":1646213414396,"mc":[{"id":"1.195453752","rc":[{"atb":[[11.5,37.14]],"id":522742}],"con":true,"img":false}]}
{"op":"mcm","clk":"5348066879","pt":1646213414453,"mc":[{"id":"1.195453752","rc":[{"atb":[[7.8,19.58]],"id":522742}],"con":true,"img":false}]}
{"op":"mcm","clk":"5348066982","pt":1646213416055,"mc":[{"id":"1.195453752","rc":[{"atb":[[5.5,5.66]],"id":3805747},{"atb":[[12,2.6]],"id":3805746},{"atl":[[17,1.02]],"id":3805746},{"atb":[[5.8,4.7]],"id":3805793},{"atb":[[23,8.12]],"id":3805755},{"atl":[[34,0.81]],"id":3805755},{"atb":[[19,1.97]],"id":522746},{"atl":[[28,0.59]],"id":522746},{"atb":[[18.5,2.51]],"id":3805736},{"atl":[[30,0.71]],"id":3805736},{"atl":[[60,0.75]],"id":522747},{"atb":[[21,1.61]],"id":522750},{"atl":[[34,0.85]],"id":522750},{"atb":[[7.6,2.85]],"id":3805731},{"atb":[[15,1.99]],"id":3805730},{"atl":[[22,0.99]],"id":3805730},{"atb":[[10.5,19.13]],"id":3805762},{"atl":[[14.5,7.02]],"id":3805762},{"atl":[[44,1.08]],"id":522741},{"atb":[[14.5,2.37]],"id":522742},{"atl":[[21,13.7]],"id":522742},{"atl":[[48,0.98]],"id":522743},{"atb":[[10.5,1.81]],"id":3805740}],"con":true,"img":false}]}
{"op":"mcm","clk":"5348066999","pt":1646213416464,"mc":[{"id":"1.195453752","rc":[{"atb":[[5.6,34.46]],"id":3805747},{"atb":[[9.6,9.9],[11,26.59],[12.5,13.78]],"id":3805746},{"atl":[[16.5,7.69],[19.5,31.54],[23,9.9]],"id":3805746},{"atb":[[5.6,48.01],[5.2,9.9],[5.9,32.35]],"id":3805793},{"atl":[[32,4.58]],"id":3805755},{"atb":[[16,22.86],[19,10.77],[15,4.95]],"id":522746},{"atl":[[36,29.5],[55,2]],"id":522746},{"atb":[[16.5,2.72],[17.5,26.16],[19,8.8]],"id":3805736},{"atl":[[40,31.11],[42,0],[30,6.17]],"id":3805736},{"atl":[[85,27.31],[90,0]],"id":522747},{"atb":[[18,9.9],[19,20.85],[22,7.54]],"id":522750},{"atl":[[32,5.1],[44,28.03],[90,2]],"id":522750},{"atb":[[6.4,8.22],[6.8,64.15]],"id":3805731},{"atb":[[12.5,2.72],[14,19.66],[15.5,10.93]],"id":3805730},{"atl":[[85,2],[60,37.22]],"id":522741},{"atb":[[14.5,14.11]],"id":522742},{"atl":[[130,2],[70,34.84],[46,3.52]],"id":522743},{"atb":[[9,15.48],[8.8,20.32]],"id":3805740}],"con":true,"img":false}]}
{"op":"mcm","clk":"5348067005","pt":1646213416672,"mc":[{"id":"1.195453752","rc":[{"atb":[[5.5,0]],"id":3805747},{"atb":[[12,0]],"id":3805746},{"atb":[[5.8,0]],"id":3805793},{"atb":[[19,8.8]],"id":522746},{"atl":[[30,5.46]],"id":3805736},{"atb":[[14.5,11.74]],"id":522742}],"con":true,"img":false}]}
{"op":"mcm","clk":"5348067009","pt":1646213416774,"mc":[{"id":"1.195453752","rc":[{"atb":[[5.7,5.66]],"id":3805747},{"atb":[[12.5,16.38]],"id":3805746},{"atb":[[6,4.7]],"id":3805793},{"atb":[[19.5,1.97]],"id":522746},{"atl":[[29,0.71]],"id":3805736},{"atb":[[15,2.37]],"id":522742}],"con":true,"img":false}]}
{"op":"mcm","clk":"5348067014","pt":1646213416879,"mc":[{"id":"1.195453752","rc":[{"atl":[[60,3.43]],"id":522747}],"con":true,"img":false}]}
{"op":"mcm","clk":"5348067019","pt":1646213416982,"mc":[{"id":"1.195453752","rc":[{"atl":[[28,6.45]],"id":522746}],"con":true,"img":false}]}
{"op":"mcm","clk":"5348067026","pt":1646213417188,"mc":[{"id":"1.195453752","rc":[{"atb":[[5.4,4.95]],"id":3805747},{"atb":[[11.5,0]],"id":3805746},{"atl":[[17.5,0],[19.5,9.9]],"id":3805746},{"atb":[[5.7,0]],"id":3805793},{"atl":[[36,4.95]],"id":3805755},{"atb":[[18,0]],"id":3805736},{"atl":[[32,4.95]],"id":3805736},{"atb":[[20,4.95]],"id":522750},{"atl":[[36,4.95]],"id":522750},{"atb":[[14.5,0]],"id":3805730},{"atb":[[14,2.72]],"id":522742},{"atl":[[70,9.9],[50,4.95]],"id":522743}],"con":true,"img":false}]}
{"op":"mcm","clk":"5348067032","pt":1646213417291,"mc":[{"id":"1.195453752","rc":[{"atb":[[18.5,2.72]],"id":522746}],"con":true,"img":false}]}
{"op":"mcm","clk":"5348067047","pt":1646213417602,"mc":[{"id":"1.195453752","rc":[{"atl":[[65,4.95],[60,0.75]],"id":522747}],"con":true,"img":false}]}
{"op":"mcm","clk":"5348067058","pt":1646213417758,"mc":[{"id":"1.195453752","rc":[{"atl":[[28,0.59],[29,4.95]],"id":522746}],"con":true,"img":false}]}
{"op":"mcm","clk":"5348067082","pt":1646213418174,"mc":[{"id":"1.195453752","rc":[{"atl":[[27,39.6],[60,2]],"id":3805730}],"con":true,"img":false}]}
{"op":"mcm","clk":"5348067092","pt":1646213418381,"mc":[{"id":"1.195453752","rc":[{"atb":[[12.5,13.78]],"id":3805746},{"atl":[[28,0]],"id":522746},{"atl":[[65,7.43]],"id":522747},{"atl":[[22,8.53]],"id":3805730},{"atl":[[14.5,5.72]],"id":3805762},{"atl":[[21,12.88]],"id":522742},{"atb":[[10.5,0]],"id":3805740}],"con":true,"img":false}]}
{"op":"mcm","clk":"5348067099","pt":1646213418485,"mc":[{"id":"1.195453752","rc":[{"atb":[[13,2.6]],"id":3805746},{"atl":[[34,4.8],[29,5.54]],"id":522746},{"atl":[[14,1.3]],"id":3805762}],"con":true,"img":false}]}
{"op":"mcm","clk":"5348067110","pt":1646213418691,"mc":[{"id":"1.195453752","rc":[{"atb":[[10,5.13]],"id":3805740}],"con":true,"img":false}]}
{"op":"mcm","clk":"5348067117","pt":1646213418793,"mc":[{"id":"1.195453752","rc":[{"atb":[[5,9.9],[5.4,57.68]],"id":3805747},{"atl":[[36,19.66]],"id":3805755}],"con":true,"img":false}]}
{"op":"mcm","clk":"5348067121","pt":1646213418896,"mc":[{"id":"1.195453752","rc":[{"atb":[[10,2.72]],"id":3805740}],"con":true,"img":false}]}
{"op":"mcm","clk":"5348067128","pt":1646213419058,"mc":[{"id":"1.195453752","rc":[{"atl":[[16.5,0]],"id":3805746},{"atl":[[17,9.9],[13.5,10.56],[15,20.81]],"id":3805762},{"atb":[[10,5.13]],"id":3805740}],"con":true,"img":false}]}
{"op":"mcm","clk":"5348067147","pt":1646213419362,"mc":[{"id":"1.195453752","rc":[{"atl":[[17,0]],"id":3805746},{"atl":[[27,33.51]],"id":3805730}],"con":true,"img":false}]}
{"op":"mcm","clk":"5348067159","pt":1646213419570,"mc":[{"id":"1.195453752","rc":[{"atl":[[19,1.44]],"id":3805746}],"con":true,"img":false}]}
{"op":"mcm","clk":"5348067178","pt":1646213419776,"mc":[{"id":"1.195453752","rc":[{"atl":[[22,7.54]],"id":3805730},{"atl":[[14.5,0]],"id":3805762}],"con":true,"img":false}]}
{"op":"mcm","clk":"5348067180","pt":1646213419877,"mc":[{"id":"1.195453752","rc":[{"atl":[[21,0.99]],"id":3805730}],"con":true,"img":false}]}
{"op":"mcm","clk":"5348067191","pt":1646213420086,"mc":[{"id":"1.195453752","rc":[{"atl":[[19.5,18.47]],"id":3805746},{"atb":[[9,3.26],[8.8,64.77]],"id":3805740}],"con":true,"img":false}]}
{"op":"mcm","clk":"5348067215","pt":1646213420498,"mc":[{"id":"1.195453752","rc":[{"atb":[[19,0]],"id":522746},{"atl":[[65,9.9],[70,0],[48,5.93],[50,0]],"id":522743}],"con":true,"img":false}]}
{"op":"mcm","clk":"5348067231","pt":1646213420763,"mc":[{"id":"1.195453752","rc":[{"atb":[[19.5,0]],"id":522746}],"con":true,"img":false}]}
{"op":"mcm","clk":"5348067244","pt":1646213420965,"mc":[{"id":"1.195453752","rc":[{"atb":[[19,2.27]],"id":522746}],"con":true,"img":false}]}
{"op":"mcm","clk":"5348067267","pt":1646213421492,"mc":[{"id":"1.195453752","rc":[{"atb":[[16,3.26],[18.5,11.78],[15,20.54]],"id":522746},{"atb":[[11.5,3.26],[14,34.9]],"id":522742}],"con":true,"img":false}]}
{"op":"mcm","clk":"5348067283","pt":1646213421803,"mc":[{"id":"1.195453752","rc":[{"atl":[[34,0]],"id":3805755},{"atb":[[18.5,0]],"id":3805736},{"atb":[[21,0]],"id":522750},{"atl":[[34,0]],"id":522750},{"atb":[[15,0]],"id":3805730},{"atl":[[48,4.95]],"id":522743}],"con":true,"img":false}]}
{"op":"mcm","clk":"5348067288","pt":1646213421905,"mc":[{"id":"1.195453752","rc":[{"atl":[[32,5.39]],"id":3805755},{"atb":[[19.5,2.51]],"id":3805736},{"atb":[[23,1.61]],"id":522750},{"atl":[[32,5.95]],"id":522750},{"atb":[[16,1.99]],"id":3805730},{"atl":[[44,0.98]],"id":522743}],"con":true,"img":false}]}
{"op":"mcm","clk":"5348067304","pt":1646213422268,"mc":[{"id":"1.195453752","rc":[{"atl":[[36,4.95],[44,36.7]],"id":3805755},{"atb":[[16.5,18.21],[17.5,4.95]],"id":3805736},{"atb":[[12.5,21.3],[14,4.95]],"id":3805730}],"con":true,"img":false}]}
{"op":"mcm","clk":"5348067314","pt":1646213422475,"mc":[{"id":"1.195453752","rc":[{"atb":[[8.6,0],[7.6,0]],"id":3805746},{"atl":[[29,4.95]],"id":522746},{"atl":[[32,0.85]],"id":522750},{"atb":[[7.6,0]],"id":3805731},{"atb":[[16,0]],"id":3805730},{"atl":[[22,0]],"id":3805730}],"con":true,"img":false}]}
{"op":"mcm","clk":"5348067321","pt":1646213422582,"mc":[{"id":"1.195453752","rc":[{"atb":[[15.5,12.92]],"id":3805730}],"con":true,"img":false}]}
{"op":"mcm","clk":"5348067331","pt":1646213422787,"mc":[{"id":"1.195453752","rc":[{"atl":[[32,0]],"id":522750},{"atb":[[7.4,5.72]],"id":3805731},{"atl":[[21,0]],"id":3805730}],"con":true,"img":false}]}
{"op":"mcm","clk":"5348067336","pt":1646213422890,"mc":[{"id":"1.195453752","rc":[{"atl":[[34,0.85]],"id":522750}],"con":true,"img":false}]}
{"op":"mcm","clk":"5348067349","pt":1646213423096,"mc":[{"id":"1.195453752","rc":[{"atl":[[22,1.03]],"id":3805730}],"con":true,"img":false}]}
{"op":"mcm","clk":"5348067352","pt":1646213423199,"mc":[{"id":"1.195453752","rc":[{"atb":[[6.4,49.89]],"id":3805731},{"atl":[[21,7.21]],"id":3805730}],"con":true,"img":false}]}
{"op":"mcm","clk":"5348067358","pt":1646213423304,"mc":[{"id":"1.195453752","rc":[{"atb":[[6.8,27.33]],"id":3805731}],"con":true,"img":false}]}
{"op":"mcm","clk":"5348067363","pt":1646213423408,"mc":[{"id":"1.195453752","rc":[{"atb":[[8,3.26],[9,2.72]],"id":3805746},{"atl":[[36,9.48],[90,16.71]],"id":522750},{"atl":[[27,9.9],[60,28.56]],"id":3805730}],"con":true,"img":false}]}
{"op":"mcm","clk":"5348067365","pt":1646213423512,"mc":[{"id":"1.195453752","rc":[{"atb":[[5.8,31.88]],"id":3805747},{"atl":[[18.5,9.05],[23,45.13]],"id":3805746},{"atb":[[6,36.4]],"id":3805793},{"atb":[[16,17.77],[15,4.95]],"id":522746},{"atb":[[16.5,2.72],[17.5,19.66],[19.5,11.07]],"id":3805736},{"atl":[[32,19.66],[40,9.9]],"id":3805736},{"atb":[[19,2.72],[20,19.66]],"id":522750},{"atl":[[44,9.9]],"id":522750},{"atl":[[22,0]],"id":3805730},{"atl":[[42,2.92]],"id":522743}],"con":true,"img":false}]}
{"op":"mcm","clk":"5348067368","pt":1646213423615,"mc":[{"id":"1.195453752","rc":[{"atl":[[21,8.24]],"id":3805730}],"con":true,"img":false}]}
{"op":"mcm","clk":"5348067394","pt":1646213423776,"mc":[{"id":"1.195453752","rc":[{"atb":[[5.7,0]],"id":3805747},{"atb":[[19.5,8.56]],"id":3805736},{"atl":[[60,3.43]],"id":522747}],"con":true,"img":false}]}
{"op":"mcm","clk":"5348067399","pt":1646213423878,"mc":[{"id":"1.195453752","rc":[{"atb":[[5.9,5.66]],"id":3805747},{"atl":[[29,5.55]],"id":522746},{"atb":[[20,2.51]],"id":3805736},{"atb":[[7.4,2.72]],"id":3805731},{"atb":[[15.5,10.93]],"id":3805730}],"con":true,"img":false}]}
{"op":"mcm","clk":"5348067401","pt":1646213423982,"mc":[{"id":"1.195453752","rc":[{"atb":[[7.6,3]],"id":3805731},{"atb":[[16,1.99]],"id":3805730}],"con":true,"img":false}]}
{"op":"mcm","clk":"5348067407","pt":1646213424085,"mc":[{"id":"1.195453752","rc":[{"atl":[[29,11.21]],"id":522746}],"con":true,"img":false}]}
{"op":"mcm","clk":"5348067410","pt":1646213424190,"mc":[{"id":"1.195453752","rc":[{"atl":[[90,2]],"id":522750}],"con":true,"img":false}]}
{"op":"mcm","clk":"5348067419","pt":1646213424397,"mc":[{"id":"1.195453752","rc":[{"atb":[[5.6,0],[2.46,0],[2.66,0],[3.15,0]],"id":3805747},{"atb":[[5.3,0],[3.15,0],[3.65,0]],"id":3805746},{"atl":[[19.5,9.9]],"id":3805746},{"atb":[[2.42,0],[2.62,0],[5.9,0],[3.05,0]],"id":3805793},{"atb":[[6.4,0],[11,0],[5.2,0]],"id":3805755},{"atb":[[6.4,0],[11,0],[5.2,0]],"id":522746},{"atb":[[5.1,0],[19,0],[10.5,0],[6.2,0]],"id":3805736},{"atb":[[21,0],[10.5,0],[8.2,0]],"id":522747},{"atb":[[5.3,0],[11.5,0],[6.6,0]],"id":522750},{"atb":[[4.3,0],[2.86,0],[3.15,0]],"id":3805731},{"atb":[[3.85,0],[7.4,0],[12.5,2.72],[14,24.55],[4.7,0]],"id":3805730},{"atl":[[21,1.03]],"id":3805730},{"atb":[[4.3,0],[6.6,0],[3.65,0]],"id":3805762},{"atb":[[6.2,0],[8.2,0],[15.5,0]],"id":522741},{"atb":[[3.95,0],[4.9,0],[7.8,0]],"id":522742},{"atb":[[16,0],[6.4,0],[8.4,0]],"id":522743},{"atl":[[46,0]],"id":522743},{"atb":[[4,0],[6,0],[3.5,0]],"id":3805740}],"con":true,"img":false}]}
{"op":"mcm","clk":"5348067421","pt":1646213424501,"mc":[{"id":"1.195453752","rc":[{"atl":[[65,4.95]],"id":522747}],"con":true,"img":false}]}
{"op":"mcm","clk":"5348067430","pt":1646213424709,"mc":[{"id":"1.195453752","rc":[{"atl":[[21,0]],"id":3805730}],"con":true,"img":false}]}
{"op":"mcm","clk":"5348067435","pt":1646213424815,"mc":[{"id":"1.195453752","rc":[{"atl":[[34,0]],"id":522746},{"atl":[[22,1.03]],"id":3805730}],"con":true,"img":false}]}
{"op":"mcm","clk":"5348067453","pt":1646213425076,"mc":[{"id":"1.195453752","rc":[{"atb":[[5.6,4.95],[5.2,99.72]],"id":3805793},{"atl":[[27,31.99]],"id":3805730}],"con":true,"img":false}]}
{"op":"mcm","clk":"5348067461","pt":1646213425185,"mc":[{"id":"1.195453752","rc":[{"atl":[[23,12.15],[60,2]],"id":3805730}],"con":true,"img":false}]}
{"op":"mcm","clk":"5348067474","pt":1646213425390,"mc":[{"id":"1.195453752","rc":[{"atl":[[36,9.9],[55,36.18]],"id":522746}],"con":true,"img":false}]}
{"op":"mcm","clk":"5348067492","pt":1646213425712,"mc":[{"id":"1.195453752","rc":[{"atb":[[19,11.07]],"id":522746}],"con":true,"img":false}]}
{"op":"mcm","clk":"5348067498","pt":1646213425815,"mc":[{"id":"1.195453752","rc":[{"atb":[[26,9.06]],"id":522741}],"con":true,"img":false}]}
{"op":"mcm","clk":"5348067505","pt":1646213426013,"mc":[{"id":"1.195453752","rc":[{"atb":[[5.8,0]],"id":3805747},{"atb":[[19,8.8]],"id":522746},{"atb":[[4.3,0],[5,25]],"id":522742}],"con":true,"img":false}]}
{"op":"mcm","clk":"5348067507","pt":1646213426066,"mc":[{"id":"1.195453752","rc":[{"atb":[[19.5,2.27]],"id":522746}],"con":true,"img":false}]}
{"op":"mcm","clk":"5348067518","pt":1646213426374,"mc":[{"id":"1.195453752","rc":[{"atb":[[5.9,0]],"id":3805747},{"atb":[[18.5,2.72]],"id":522746}],"con":true,"img":false}]}
{"op":"mcm","clk":"5348067524","pt":1646213426478,"mc":[{"id":"1.195453752","rc":[{"atb":[[5.1,55.45],[5.4,4.95]],"id":3805747},{"atb":[[21,8.22]],"id":522741}],"con":true,"img":false}]}
{"op":"mcm","clk":"5348067529","pt":1646213426683,"mc":[{"id":"1.195453752","rc":[{"atb":[[5.5,6.07]],"id":3805747}],"con":true,"img":false}]}
{"op":"mcm","clk":"5348067549","pt":1646213427098,"mc":[{"id":"1.195453752","rc":[{"atb":[[5.4,40.98]],"id":3805747}],"con":true,"img":false}]}
{"op":"mcm","clk":"5348067560","pt":1646213427408,"mc":[{"id":"1.195453752","rc":[{"atl":[[60,0.75]],"id":522747},{"atl":[[70,9.9],[46,0],[50,4.95],[60,27.32]],"id":522741},{"atl":[[42,0]],"id":522743}],"con":true,"img":false}]}
{"op":"mcm","clk":"5348067565","pt":1646213427514,"mc":[{"id":"1.195453752","rc":[{"atl":[[32,0],[34,4.95],[40,0],[30,0]],"id":3805736},{"atl":[[65,0],[70,4.95],[85,17.4],[90,9.9]],"id":522747}],"con":true,"img":false}]}
{"op":"mcm","clk":"5348067572","pt":1646213427722,"mc":[{"id":"1.195453752","rc":[{"atb":[[6,4.7]],"id":3805793},{"atl":[[36,0],[38,9.9],[29,0.6],[30,4.95]],"id":522746},{"atl":[[44,0]],"id":522741},{"atl":[[44,0]],"id":522743}],"con":true,"img":false}]}
{"op":"mcm","clk":"5348067574","pt":1646213427774,"mc":[{"id":"1.195453752","rc":[{"atl":[[29,0]],"id":3805736},{"atl":[[60,0]],"id":522747},{"atl":[[46,0.98]],"id":522743}],"con":true,"img":false}]}
{"op":"mcm","clk":"5348067579","pt":1646213427980,"mc":[{"id":"1.195453752","rc":[{"atb":[[6,0]],"id":3805793},{"atl":[[29,0]],"id":522746},{"atl":[[70,13.09]],"id":3805736},{"atb":[[16,0]],"id":3805730},{"atl":[[48,1.17]],"id":522741},{"atl":[[65,30.03]],"id":522743}],"con":true,"img":false}]}
{"op":"mcm","clk":"5348067582","pt":1646213428083,"mc":[{"id":"1.195453752","rc":[{"atl":[[32,0.88]],"id":3805736},{"atl":[[65,0.79],[70,7.25]],"id":522747},{"atb":[[15.5,12.92]],"id":3805730},{"atl":[[70,38.11]],"id":522741},{"atl":[[48,8.32]],"id":522743}],"con":true,"img":false}]}
{"op":"mcm","clk":"5348067587","pt":1646213428188,"mc":[{"id":"1.195453752","rc":[{"atl":[[65,9.9],[70,28.2],[48,6.12],[50,3.23],[60,0]],"id":522741}],"con":true,"img":false}]}
{"op":"mcm","clk":"5348067595","pt":1646213428346,"mc":[{"id":"1.195453752","rc":[{"atb":[[5.7,5.17]],"id":3805793},{"atl":[[30,5.62]],"id":522746},{"atl":[[34,9.76]],"id":3805736},{"atl":[[85,0],[90,31.99]],"id":522747},{"atl":[[21,0],[22,4.95],[25,0],[26,9.9]],"id":522742}],"con":true,"img":false}]}
{"op":"mcm","clk":"5348067608","pt":1646213428400,"mc":[{"id":"1.195453752","rc":[{"atb":[[5.6,39.41],[5.2,9.9],[4.7,45.78]],"id":3805793},{"atb":[[16,3.26],[18.5,14.12]],"id":522746},{"atl":[[32,4.95],[38,0],[40,9.9],[30,0.67]],"id":522746},{"atb":[[14,4.95]],"id":3805730}],"con":true,"img":false}]}
{"op":"mcm","clk":"5348067617","pt":1646213428504,"mc":[{"id":"1.195453752","rc":[{"atb":[[12.5,37.04]],"id":3805730},{"atl":[[48,4.95]],"id":522741}],"con":true,"img":false}]}
{"op":"mcm","clk":"5348067624","pt":1646213428609,"mc":[{"id":"1.195453752","rc":[{"atl":[[22,5.87]],"id":522742}],"con":true,"img":false}]}
{"op":"mcm","clk":"5348067630","pt":1646213428712,"mc":[{"id":"1.195453752","rc":[{"atl":[[46,1.17]],"id":522741}],"con":true,"img":false}]}
{"op":"mcm","clk":"5348067646","pt":1646213429022,"mc":[{"id":"1.195453752","rc":[{"atl":[[19,0]],"id":3805746},{"atl":[[22,0.92],[26,0]],"id":522742}],"con":true,"img":false}]}
{"op":"mcm","clk":"5348067649","pt":1646213429073,"mc":[{"id":"1.195453752","rc":[{"atl":[[18,1.44]],"id":3805746},{"atl":[[32,0],[34,4.95],[40,0],[42,9.9]],"id":522746},{"atl":[[70,0]],"id":522741},{"atl":[[23,4.95],[26,6.34],[27,9.9]],"id":522742}],"con":true,"img":false}]}
{"op":"mcm","clk":"5348067657","pt":1646213429290,"mc":[{"id":"1.195453752","rc":[{"atl":[[7.6,26.34]],"id":3805793},{"atl":[[30,0]],"id":522746},{"atb":[[7.6,0]],"id":3805731},{"atb":[[15.5,10.93]],"id":3805730}],"con":true,"img":false}]}
{"op":"mcm","clk":"5348067661","pt":1646213429389,"mc":[{"id":"1.195453752","rc":[{"atb":[[7.4,5.72]],"id":3805731},{"atb":[[16,1.99]],"id":3805730}],"con":true,"img":false}]}
{"op":"mcm","clk":"5348067664","pt":1646213429491,"mc":[{"id":"1.195453752","rc":[{"atb":[[10.5,2.45]],"id":3805762},{"atl":[[44,2.33],[24,34.9]],"id":522742}],"con":true,"img":false}]}
{"op":"mcm","clk":"5348067670","pt":1646213429595,"mc":[{"id":"1.195453752","rc":[{"atl":[[32,0.79]],"id":522746}],"con":true,"img":false}]}
{"op":"mcm","clk":"5348067672","pt":1646213429698,"mc":[{"id":"1.195453752","rc":[{"atl":[[18,10.76]],"id":3805746}],"con":true,"img":false}]}
{"op":"mcm","clk":"5348067678","pt":1646213429801,"mc":[{"id":"1.195453752","rc":[{"atl":[[34,0],[36,4.95],[42,0],[44,9.9],[50,3.23]],"id":522746}],"con":true,"img":false}]}
{"op":"mcm","clk":"5348067689","pt":1646213430115,"mc":[{"id":"1.195453752","rc":[{"atl":[[32,0]],"id":522746}],"con":true,"img":false}]}
{"op":"mcm","clk":"5348067693","pt":1646213430217,"mc":[{"id":"1.195453752","rc":[{"atl":[[65,5.74],[70,2.29],[85,9.9],[90,22.08]],"id":522747}],"con":true,"img":false}]}
{"op":"mcm","clk":"5348067698","pt":1646213430321,"mc":[{"id":"1.195453752","rc":[{"atl":[[23,9.9]],"id":3805746},{"atb":[[5.7,38.9]],"id":3805793},{"atl":[[44,35.22]],"id":522750},{"atb":[[10,20.33]],"id":3805762}],"con":true,"img":false}]}
{"op":"mcm","clk":"5348067702","pt":1646213430377,"mc":[{"id":"1.195453752","rc":[{"atb":[[5.6,34.46]],"id":3805747},{"atl":[[18.5,0],[19.5,40.62]],"id":3805746},{"atl":[[34,0.92]],"id":522746},{"atl":[[44,3.32]],"id":522743}],"con":true,"img":false}]}
{"op":"mcm","clk":"5348067707","pt":1646213430490,"mc":[{"id":"1.195453752","rc":[{"atb":[[13,15.81]],"id":3805746},{"atl":[[34,5.87],[36,0],[42,9.9],[44,0]],"id":522746},{"atb":[[20,10.85]],"id":3805736},{"atb":[[23,8.81]],"id":522750},{"atl":[[32,4.61]],"id":522750},{"atl":[[23,4.95]],"id":3805730},{"atb":[[12.5,0],[13,4.95]],"id":522742},{"atl":[[65,20.12],[70,9.9],[48,3.37],[50,4.95]],"id":522743},{"atb":[[8.6,0]],"id":3805740}],"con":true,"img":false}]}
{"op":"mcm","clk":"5348067712","pt":1646213430579,"mc":[{"id":"1.195453752","rc":[{"atb":[[5.5,0]],"id":3805747},{"atb":[[5.7,33.73]],"id":3805793}],"con":true,"img":false}]}
{"op":"mcm","clk":"5348067715","pt":1646213430684,"mc":[{"id":"1.195453752","rc":[{"atb":[[5.7,6.07]],"id":3805747},{"atl":[[18,9.32]],"id":3805746},{"atb":[[5.8,5.17]],"id":3805793},{"atb":[[23,7.2]],"id":3805755},{"atl":[[65,8.22]],"id":522747},{"atb":[[10.5,0]],"id":3805762},{"atl":[[14,0]],"id":3805762}],"con":true,"img":false}]}
{"op":"mcm","clk":"5348067718","pt":1646213430790,"mc":[{"id":"1.195453752","rc":[{"atb":[[13,13.21]],"id":3805746},{"atb":[[24,0.92]],"id":3805755},{"atb":[[23,7.2]],"id":522750},{"atl":[[13.5,11.86]],"id":3805762},{"atl":[[65,0]],"id":522743}],"con":true,"img":false}]}
{"op":"mcm","clk":"5348067723","pt":1646213430892,"mc":[{"id":"1.195453752","rc":[{"atb":[[13.5,2.6]],"id":3805746},{"atb":[[24,1.61]],"id":522750}],"con":true,"img":false}]}
{"op":"mcm","clk":"5348067729","pt":1646213430996,"mc":[{"id":"1.195453752","rc":[{"atl":[[34,10.68]],"id":522746},{"atb":[[10,22.84]],"id":3805762},{"atb":[[7.6,9.9],[8.4,4.95]],"id":3805740}],"con":true,"img":false}]}
{"op":"mcm","clk":"5348067735","pt":1646213431100,"mc":[{"id":"1.195453752","rc":[{"atb":[[5.4,4.95]],"id":3805747},{"atb":[[5.6,4.95]],"id":3805793},{"atb":[[9,49.21],[9.4,4.95]],"id":3805762},{"atl":[[17,55.85],[15,4.95]],"id":3805762},{"atl":[[48,0]],"id":522743}],"con":true,"img":false}]}
{"op":"mcm","clk":"5348067739","pt":1646213431203,"mc":[{"id":"1.195453752","rc":[{"atb":[[12.5,0]],"id":3805746},{"atb":[[18.5,0],[19,20.33]],"id":3805755},{"atb":[[12.5,2.72],[14,19.66]],"id":3805730}],"con":true,"img":false}]}
{"op":"mcm","clk":"5348067741","pt":1646213431308,"mc":[{"id":"1.195453752","rc":[{"atb":[[11,4.95],[12.5,34.36]],"id":3805746},{"atl":[[18,0]],"id":3805746},{"atl":[[32,0.81]],"id":3805755},{"atb":[[19.5,0]],"id":3805736},{"atb":[[20,4.95],[22,17.55]],"id":522750},{"atl":[[32,0],[36,4.95]],"id":522750}],"con":true,"img":false}]}
{"op":"mcm","clk":"5348067747","pt":1646213431514,"mc":[{"id":"1.195453752","rc":[{"atl":[[70,0]],"id":522747}],"con":true,"img":false}]}
{"op":"mcm","clk":"5348067751","pt":1646213431618,"mc":[{"id":"1.195453752","rc":[{"atl":[[19,1.16]],"id":3805746},{"atl":[[32,0]],"id":3805755}],"con":true,"img":false}]}
{"op":"mcm","clk":"5348067753","pt":1646213431678,"mc":[{"id":"1.195453752","rc":[{"atl":[[34,0.81],[70,2],[85,0]],"id":3805755}],"con":true,"img":false}]}
{"op":"mcm","clk":"5348067758","pt":1646213431775,"mc":[{"id":"1.195453752","rc":[{"atl":[[50,0]],"id":522746},{"atb":[[16.5,33.35],[17.5,4.95]],"id":3805736}],"con":true,"img":false}]}
{"op":"mcm","clk":"5348067769","pt":1646213431981,"mc":[{"id":"1.195453752","rc":[{"atl":[[19.5,49.19]],"id":3805746},{"atb":[[5.6,51.79],[4.7,2.72]],"id":3805793},{"atl":[[36,9.48]],"id":3805755},{"atl":[[44,38.91]],"id":522750},{"atb":[[28,9.28]],"id":522743}],"con":true,"img":false}]}
{"op":"mcm","clk":"5348067775","pt":1646213432084,"mc":[{"id":"1.195453752","rc":[{"atl":[[85,18.06],[44,9.9]],"id":3805755}],"con":true,"img":false}]}
{"op":"mcm","clk":"5348067789","pt":1646213432296,"mc":[{"id":"1.195453752","rc":[{"atl":[[50,27.82],[55,2]],"id":522746}],"con":true,"img":false}]}
{"op":"mcm","clk":"5348067847","pt":1646213433225,"mc":[{"id":"1.195453752","rc":[{"atl":[[32,5.83],[34,4.8],[40,9.9]],"id":3805736}],"con":true,"img":false}]}
{"op":"mcm","clk":"5348067856","pt":1646213433381,"mc":[{"id":"1.195453752","rc":[{"atb":[[28,8.59]],"id":522743}],"con":true,"img":false}]}
{"op":"mcm","clk":"5348067859","pt":1646213433485,"mc":[{"id":"1.195453752","rc":[{"atb":[[5.1,2.72],[5.4,57.68]],"id":3805747}],"con":true,"img":false}]}
{"op":"mcm","clk":"5348067863","pt":1646213433587,"mc":[{"id":"1.195453752","rc":[{"atl":[[19.5,18.47],[23,44.26]],"id":3805746},{"atb":[[16.5,30.63],[14,0]],"id":3805736},{"atb":[[10,0],[12.5,0]],"id":3805730}],"con":true,"img":false}]}
{"op":"mcm","clk":"5348067871","pt":1646213433793,"mc":[{"id":"1.195453752","rc":[{"atl":[[70,2],[40,33.3]],"id":3805736}],"con":true,"img":false}]}
{"op":"mcm","clk":"5348067879","pt":1646213433897,"mc":[{"id":"1.195453752","rc":[{"atb":[[5.8,30.45]],"id":3805747}],"con":true,"img":false}]}
{"op":"mcm","clk":"5348067896","pt":1646213434206,"mc":[{"id":"1.195453752","rc":[{"atb":[[5.7,0]],"id":3805747}],"con":true,"img":false}]}
{"op":"mcm","clk":"5348067901","pt":1646213434310,"mc":[{"id":"1.195453752","rc":[{"atb":[[5.9,6.07]],"id":3805747},{"atb":[[17,2.72],[14.5,3.26]],"id":3805736},{"atb":[[10.5,3.26],[13,2.72]],"id":3805730}],"con":true,"img":false}]}
{"op":"mcm","clk":"5348067915","pt":1646213434518,"mc":[{"id":"1.195453752","rc":[{"atl":[[32,0.88],[34,9.76],[40,23.39],[42,9.9]],"id":3805736}],"con":true,"img":false}]}
{"op":"mcm","clk":"5348067923","pt":1646213434623,"mc":[{"id":"1.195453752","rc":[{"atb":[[5.6,0]],"id":3805747}],"con":true,"img":false}]}
{"op":"mcm","clk":"5348067938","pt":1646213434832,"mc":[{"id":"1.195453752","rc":[{"atb":[[7.4,2.72]],"id":3805731}],"con":true,"img":false}]}
{"op":"mcm","clk":"5348067946","pt":1646213434886,"mc":[{"id":"1.195453752","rc":[{"atl":[[70,0],[60,2]],"id":3805736},{"atl":[[50,22.81]],"id":522741}],"con":true,"img":false}]}
{"op":"mcm","clk":"5348067958","pt":1646213434990,"mc":[{"id":"1.195453752","rc":[{"atl":[[46,4.69]],"id":522741}],"con":true,"img":false}]}
{"op":"mcm","clk":"5348067965","pt":1646213435095,"mc":[{"id":"1.195453752","rc":[{"atb":[[5.8,38.2]],"id":3805793}],"con":true,"img":false}]}
{"op":"mcm","clk":"5348067973","pt":1646213435202,"mc":[{"id":"1.195453752","rc":[{"atl":[[46,3.52]],"id":522741}],"con":true,"img":false}]}
{"op":"mcm","clk":"5348067977","pt":1646213435301,"mc":[{"id":"1.195453752","rc":[{"atb":[[5.8,33.03]],"id":3805793},{"atl":[[44,1.17]],"id":522741}],"con":true,"img":false}]}
{"op":"mcm","clk":"5348067984","pt":1646213435404,"mc":[{"id":"1.195453752","rc":[{"atb":[[5.9,5.17]],"id":3805793}],"con":true,"img":false}]}
{"op":"mcm","clk":"5348067994","pt":1646213435614,"mc":[{"id":"1.195453752","rc":[{"atb":[[20,2.51]],"id":3805736}],"con":true,"img":false}]}
{"op":"mcm","clk":"5348068010","pt":1646213435825,"mc":[{"id":"1.195453752","rc":[{"atb":[[5.7,0]],"id":3805793},{"atl":[[50,19.57]],"id":522741}],"con":true,"img":false}]}
{"op":"mcm","clk":"5348068015","pt":1646213435929,"mc":[{"id":"1.195453752","rc":[{"atb":[[20,0]],"id":3805736},{"atl":[[50,0]],"id":522741},{"atl":[[46,0]],"id":522743}],"con":true,"img":false}]}
{"op":"mcm","clk":"5348068020","pt":1646213435980,"mc":[{"id":"1.195453752","rc":[{"atb":[[5.6,4.95],[5.7,88.24]],"id":3805793},{"atl":[[42,0.98]],"id":522743}],"con":true,"img":false}]}
{"op":"mcm","clk":"5348068032","pt":1646213436186,"mc":[{"id":"1.195453752","rc":[{"atb":[[21,1.57]],"id":3805736},{"atb":[[24,0]],"id":522750},{"atb":[[7.4,5.24]],"id":3805731},{"atl":[[22,0]],"id":3805730},{"atl":[[46,0]],"id":522741},{"atb":[[28,9.29]],"id":522743}],"con":true,"img":false}]}
{"op":"mcm","clk":"5348068039","pt":1646213436289,"mc":[{"id":"1.195453752","rc":[{"atb":[[17.5,14.56]],"id":3805736},{"atb":[[23,8.81]],"id":522750},{"atl":[[23,5.98]],"id":3805730},{"atl":[[70,30.03]],"id":522743}],"con":true,"img":false}]}
{"op":"mcm","clk":"5348068045","pt":1646213436392,"mc":[{"id":"1.195453752","rc":[{"atb":[[9,45.94],[10,20.12]],"id":3805762}],"con":true,"img":false}]}
{"op":"mcm","clk":"5348068048","pt":1646213436494,"mc":[{"id":"1.195453752","rc":[{"atl":[[18.5,9.05]],"id":3805746},{"atb":[[21,0]],"id":3805736},{"atl":[[44,0]],"id":522741},{"atl":[[42,3.74]],"id":522743}],"con":true,"img":false}]}
{"op":"mcm","clk":"5348068052","pt":1646213436598,"mc":[{"id":"1.195453752","rc":[{"atb":[[20,23.01],[22,0]],"id":522750},{"atl":[[27,9.9],[60,25.6]],"id":3805730},{"atl":[[46,1.17]],"id":522741}],"con":true,"img":false}]}
{"op":"mcm","clk":"5348068058","pt":1646213436702,"mc":[{"id":"1.195453752","rc":[{"atl":[[34,0.92],[36,4.95],[42,0],[44,9.9]],"id":522746}],"con":true,"img":false}]}
{"op":"mcm","clk":"5348068061","pt":1646213436805,"mc":[{"id":"1.195453752","rc":[{"atl":[[19,0]],"id":3805746},{"atb":[[18,3.35]],"id":3805736}],"con":true,"img":false}]}
{"op":"mcm","clk":"5348068068","pt":1646213436907,"mc":[{"id":"1.195453752","rc":[{"atl":[[18.5,10.21]],"id":3805746},{"atb":[[5.8,0]],"id":3805793}],"con":true,"img":false}]}
{"op":"mcm","clk":"5348068072","pt":1646213437011,"mc":[{"id":"1.195453752","rc":[{"atl":[[48,8.32]],"id":522741},{"atl":[[70,9.9]],"id":522743}],"con":true,"img":false}]}
{"op":"mcm","clk":"5348068078","pt":1646213437114,"mc":[{"id":"1.195453752","rc":[{"atl":[[19.5,51.57],[23,9.9]],"id":3805746},{"atb":[[9.8,2.72],[8.8,3.26]],"id":3805762}],"con":true,"img":false}]}
{"op":"mcm","clk":"5348068085","pt":1646213437220,"mc":[{"id":"1.195453752","rc":[{"atl":[[19.5,43.01]],"id":3805746},{"atb":[[5.9,0]],"id":3805793}],"con":true,"img":false}]}
{"op":"mcm","clk":"5348068090","pt":1646213437330,"mc":[{"id":"1.195453752","rc":[{"atb":[[5.8,5.17]],"id":3805793},{"atb":[[18.5,9.05]],"id":3805736},{"atl":[[32,4.63]],"id":522750},{"atl":[[44,0]],"id":522743}],"con":true,"img":false}]}
{"op":"mcm","clk":"5348068098","pt":1646213437428,"mc":[{"id":"1.195453752","rc":[{"atl":[[36,9.48]],"id":522746}],"con":true,"img":false}]}
{"op":"mcm","clk":"5348068116","pt":1646213437684,"mc":[{"id":"1.195453752","rc":[{"atb":[[5.7,121.97]],"id":3805793}],"con":true,"img":false}]}
{"op":"mcm","clk":"5348068122","pt":1646213437790,"mc":[{"id":"1.195453752","rc":[{"atb":[[9,0],[9.4,29.95]],"id":3805762}],"con":true,"img":false}]}
{"op":"mcm","clk":"5348068124","pt":1646213437892,"mc":[{"id":"1.195453752","rc":[{"atb":[[5.8,0]],"id":3805747},{"atl":[[8,0],[8.6,9.9],[8.8,51.6],[7.8,4.95]],"id":3805747},{"atb":[[13,0]],"id":3805746},{"atl":[[8,0],[8.6,60.34],[8.8,0],[7.8,4.95]],"id":3805793},{"atl":[[36,4.95]],"id":3805755},{"atb":[[19.5,10.83]],"id":522746},{"atl":[[36,19.2],[44,13.59]],"id":522750},{"atb":[[16,12.55]],"id":3805730},{"atl":[[23,8.23],[24,4.95],[27,0],[28,9.9]],"id":3805730}],"con":true,"img":false}]}
{"op":"mcm","clk":"5348068129","pt":1646213437995,"mc":[{"id":"1.195453752","rc":[{"atb":[[17.5,4.95]],"id":3805736}],"con":true,"img":false}]}
{"op":"mcm","clk":"5348068136","pt":1646213438099,"mc":[{"id":"1.195453752","rc":[{"atl":[[44,9.9]],"id":522750}],"con":true,"img":false}]}
{"op":"mcm","clk":"5348068139","pt":1646213438204,"mc":[{"id":"1.195453752","rc":[{"atb":[[5.9,0]],"id":3805747},{"atb":[[13.5,0]],"id":3805746},{"atb":[[19.5,8.56]],"id":522746},{"atb":[[16,10.56]],"id":3805730}],"con":true,"img":false}]}
{"op":"mcm","clk":"5348068143","pt":1646213438306,"mc":[{"id":"1.195453752","rc":[{"atb":[[5.1,26.47],[5.5,6.07],[5.4,4.95]],"id":3805747},{"atl":[[8.6,33.65],[8.8,0]],"id":3805747},{"atb":[[11,34.87],[12.5,0],[13,2.6]],"id":3805746},{"atb":[[20,2.27]],"id":522746},{"atb":[[16.5,1.99]],"id":3805730},{"atl":[[42,0.98]],"id":522743}],"con":true,"img":false}]}
{"op":"mcm","clk":"5348068151","pt":1646213438513,"mc":[{"id":"1.195453752","rc":[{"atb":[[16.5,0],[17.5,25.77]],"id":3805736},{"atl":[[65,3.26],[70,4.95],[85,0],[90,31.99]],"id":522747},{"atl":[[23,0],[24,39.85],[27,0]],"id":522742}],"con":true,"img":false}]}
{"op":"mcm","clk":"5348068156","pt":1646213438618,"mc":[{"id":"1.195453752","rc":[{"atb":[[13,0]],"id":3805746},{"atb":[[19,0]],"id":522746},{"atb":[[15.5,0]],"id":3805730},{"atl":[[42,0]],"id":522743}],"con":true,"img":false}]}
{"op":"mcm","clk":"5348068161","pt":1646213438722,"mc":[{"id":"1.195453752","rc":[{"atb":[[5.4,34.41]],"id":3805747},{"atb":[[12.5,13.78]],"id":3805746},{"atb":[[5.7,88.24]],"id":3805793},{"atl":[[85,0]],"id":3805755},{"atb":[[18.5,2.72],[19,25.83]],"id":522746},{"atb":[[14,4.95],[15.5,26.96]],"id":3805730},{"atl":[[23,1.03]],"id":3805730},{"atl":[[48,0.98]],"id":522743}],"con":true,"img":false}]}
{"op":"mcm","clk":"5348068164","pt":1646213438825,"mc":[{"id":"1.195453752","rc":[{"atl":[[44,27.96]],"id":3805755}],"con":true,"img":false}]}
{"op":"mcm","clk":"5348068168","pt":1646213438928,"mc":[{"id":"1.195453752","rc":[{"atb":[[11.5,4.54]],"id":3805746},{"atl":[[22,0]],"id":522742}],"con":true,"img":false}]}
{"op":"mcm","clk":"5348068171","pt":1646213439038,"mc":[{"id":"1.195453752","rc":[{"atl":[[44,35.74],[50,0]],"id":522746},{"atl":[[24,4.95],[26,33.21]],"id":522742},{"atl":[[50,8.19]],"id":522743}],"con":true,"img":false}]}
{"op":"mcm","clk":"5348068180","pt":1646213439188,"mc":[{"id":"1.195453752","rc":[{"atl":[[23,1]],"id":522742}],"con":true,"img":false}]}
{"op":"mcm","clk":"5348068189","pt":1646213439290,"mc":[{"id":"1.195453752","rc":[{"atb":[[5.6,51.79],[5.7,0]],"id":3805793},{"atl":[[28,9.9]],"id":522742}],"con":true,"img":false}]}
{"op":"mcm","clk":"5348068193","pt":1646213439398,"mc":[{"id":"1.195453752","rc":[{"atl":[[24,11.84]],"id":3805730},{"atl":[[24,11.84]],"id":522742}],"con":true,"img":false}]}
{"op":"mcm","clk":"5348068200","pt":1646213439499,"mc":[{"id":"1.195453752","rc":[{"atb":[[5.8,0]],"id":3805793}],"con":true,"img":false}]}
{"op":"mcm","clk":"5348068207","pt":1646213439603,"mc":[{"id":"1.195453752","rc":[{"atb":[[5.7,5.17]],"id":3805793}],"con":true,"img":false}]}
{"op":"mcm","clk":"5348068214","pt":1646213439707,"mc":[{"id":"1.195453752","rc":[{"atl":[[65,0],[70,9.9],[48,0],[50,4.95]],"id":522741}],"con":true,"img":false}]}
{"op":"mcm","clk":"5348068217","pt":1646213439810,"mc":[{"id":"1.195453752","rc":[{"atb":[[19,22.71],[20,4.95]],"id":522750}],"con":true,"img":false}]}
{"op":"mcm","clk":"5348068226","pt":1646213439914,"mc":[{"id":"1.195453752","rc":[{"atl":[[46,0]],"id":522741}],"con":true,"img":false}]}
{"op":"mcm","clk":"5348068229","pt":1646213440017,"mc":[{"id":"1.195453752","rc":[{"atb":[[5.6,86.25]],"id":3805793},{"atl":[[48,1.17]],"id":522741}],"con":true,"img":false}]}
{"op":"mcm","clk":"5348068234","pt":1646213440120,"mc":[{"id":"1.195453752","rc":[{"atl":[[34,0],[36,4.95],[42,0]],"id":3805736},{"atl":[[26,26.87]],"id":522742}],"con":true,"img":false}]}
{"op":"mcm","clk":"5348068237","pt":1646213440223,"mc":[{"id":"1.195453752","rc":[{"atl":[[18.5,9.05]],"id":3805746},{"atb":[[23,7.2]],"id":522750},{"atl":[[32,0]],"id":522750},{"atb":[[7.4,2.72]],"id":3805731},{"atb":[[10,2.72]],"id":3805740}],"con":true,"img":false}]}
{"op":"mcm","clk":"5348068242","pt":1646213440327,"mc":[{"id":"1.195453752","rc":[{"atl":[[19.5,9.9],[23,45.59]],"id":3805746},{"atb":[[24,1.61]],"id":522750},{"atb":[[9,0],[10,0]],"id":3805740}],"con":true,"img":false}]}
{"op":"mcm","clk":"5348068247","pt":1646213440436,"mc":[{"id":"1.195453752","rc":[{"atl":[[32,0]],"id":3805736}],"con":true,"img":false}]}
{"op":"mcm","clk":"5348068252","pt":1646213440536,"mc":[{"id":"1.195453752","rc":[{"atl":[[34,0.88]],"id":3805736},{"atl":[[80,2]],"id":522741}],"con":true,"img":false}]}
{"op":"mcm","clk":"5348068256","pt":1646213440640,"mc":[{"id":"1.195453752","rc":[{"atb":[[5.6,33.87]],"id":3805747},{"atb":[[9,3.51]],"id":3805740}],"con":true,"img":false}]}
{"op":"mcm","clk":"5348068271","pt":1646213440798,"mc":[{"id":"1.195453752","rc":[{"atb":[[15,0]],"id":522746},{"atl":[[16.5,9.9],[17,45.94],[14.5,4.95],[15,0]],"id":3805762},{"atb":[[19,9.9],[22,4.95]],"id":522741},{"atb":[[15,13.69]],"id":522742},{"atb":[[7.6,46.05],[8.8,20.32]],"id":3805740}],"con":true,"img":false}]}
{"op":"mcm","clk":"5348068276","pt":1646213440900,"mc":[{"id":"1.195453752","rc":[{"atb":[[5.5,0]],"id":3805747},{"atl":[[36,9.48],[40,0],[60,22.82]],"id":3805736},{"atl":[[36,23.73]],"id":522750},{"atb":[[18.5,24.15],[21,3.26]],"id":522741}],"con":true,"img":false}]}
{"op":"mcm","clk":"5348068282","pt":1646213441004,"mc":[{"id":"1.195453752","rc":[{"atb":[[5.7,6.07]],"id":3805747},{"atb":[[9,6.77],[10,2.72]],"id":3805740}],"con":true,"img":false}]}
{"op":"mcm","clk":"5348068287","pt":1646213441106,"mc":[{"id":"1.195453752","rc":[{"atb":[[5.1,2.72],[5.4,122.44]],"id":3805747},{"atl":[[36,9.48],[44,27.96]],"id":522750},{"atb":[[15,11.32]],"id":522742}],"con":true,"img":false}]}
{"op":"mcm","clk":"5348068294","pt":1646213441212,"mc":[{"id":"1.195453752","rc":[{"atl":[[16.5,42.28],[17,0]],"id":3805762},{"atb":[[15.5,2.37]],"id":522742}],"con":true,"img":false}]}
{"op":"mcm","clk":"5348068297","pt":1646213441315,"mc":[{"id":"1.195453752","rc":[{"atb":[[18.5,0],[21,22.84]],"id":522741}],"con":true,"img":false}]}
{"op":"mcm","clk":"5348068301","pt":1646213441419,"mc":[{"id":"1.195453752","rc":[{"atb":[[5.4,92.99]],"id":3805747}],"con":true,"img":false}]}
{"op":"mcm","clk":"5348068304","pt":1646213441522,"mc":[{"id":"1.195453752","rc":[{"atl":[[24,4.95]],"id":3805730},{"atl":[[70,24.62]],"id":522741},{"atb":[[14.5,0]],"id":522742},{"atb":[[7.6,9.9]],"id":3805740}],"con":true,"img":false}]}
{"op":"mcm","clk":"5348068314","pt":1646213441730,"mc":[{"id":"1.195453752","rc":[{"atl":[[7.6,24.02]],"id":3805793},{"atl":[[13.5,10.56]],"id":3805762},{"atb":[[14,2.72],[14.5,34.27]],"id":522742}],"con":true,"img":false}]}
{"op":"mcm","clk":"5348068319","pt":1646213441834,"mc":[{"id":"1.195453752","rc":[{"atl":[[7.4,2.32]],"id":3805793},{"atl":[[13,1.3]],"id":3805762}],"con":true,"img":false}]}
{"op":"mcm","clk":"5348068345","pt":1646213442195,"mc":[{"id":"1.195453752","rc":[{"atb":[[5.1,0],[4.6,0]],"id":3805747},{"atb":[[6.4,46.62],[7.4,0]],"id":3805731}],"con":true,"img":false}]}
{"op":"mcm","clk":"5348068355","pt":1646213442402,"mc":[{"id":"1.195453752","rc":[{"atb":[[5.6,39.41],[5.2,32.32]],"id":3805793},{"atl":[[8.6,9.9],[7.4,24.73],[7.8,27.36]],"id":3805793},{"atb":[[7,3.17]],"id":3805731},{"atl":[[12.5,9.26]],"id":3805762}],"con":true,"img":false}]}
{"op":"mcm","clk":"5348068360","pt":1646213442504,"mc":[{"id":"1.195453752","rc":[{"atl":[[70,0],[75,9.9],[50,3.23],[55,4.95]],"id":522743}],"con":true,"img":false}]}
{"op":"mcm","clk":"5348068371","pt":1646213442712,"mc":[{"id":"1.195453752","rc":[{"atb":[[4.8,106.07],[6.4,4.95]],"id":3805731}],"con":true,"img":false}]}
{"op":"mcm","clk":"5348068374","pt":1646213442820,"mc":[{"id":"1.195453752","rc":[{"atb":[[2.72,154.88],[2.52,175.25],[3.3,57.91]],"id":3805747},{"atb":[[3.2,121.08],[3.7,98.66],[5.4,30.27]],"id":3805746},{"atb":[[2.4,190.27],[3,66.59],[2.6,166.49]],"id":3805793},{"atb":[[5.1,64.97],[10.5,14.02],[6.2,51.22]],"id":3805755},{"atb":[[5.3,61.94],[11.5,12.68],[6.6,47.57]],"id":522746},{"atb":[[5.1,64.97],[10.5,14.02],[6.2,51.22]],"id":3805736},{"atb":[[19.5,7.19],[9.8,30.27],[7.8,39.17]],"id":522747},{"atb":[[5.3,61.94],[11.5,12.68],[6.6,47.57]],"id":522750},{"atb":[[4.3,40.36],[2.86,143.22],[3.15,123.9]],"id":3805731},{"atb":[[4,88.79],[6,26.63],[3.5,106.55]],"id":3805762},{"atb":[[7.2,21.48],[4.6,73.99],[3.8,95.13]],"id":3805730},{"atb":[[6.2,51.22],[8.2,36.99],[15.5,9.18]],"id":522741},{"atb":[[5.1,64.97],[8.2,18.49],[4.1,85.93]],"id":522742},{"atb":[[6.2,51.22],[8.2,36.99],[15.5,9.18]],"id":522743},{"atb":[[4,88.79],[6,26.63],[3.5,106.55]],"id":3805740}],"con":true,"img":false}]}
{"op":"mcm","clk":"5348068380","pt":1646213442982,"mc":[{"id":"1.195453752","rc":[{"atb":[[7,29.59]],"id":3805731},{"atb":[[9.8,0],[8.8,0]],"id":3805762}],"con":true,"img":false}]}
{"op":"mcm","clk":"5348068386","pt":1646213443034,"mc":[{"id":"1.195453752","rc":[{"atb":[[4.9,2.72],[4.4,3.26]],"id":3805747},{"atb":[[18,0]],"id":3805736},{"atb":[[7.2,2.72],[6.2,3.26]],"id":3805731},{"atl":[[70,25.97]],"id":522743}],"con":true,"img":false}]}
{"op":"mcm","clk":"5348068388","pt":1646213443139,"mc":[{"id":"1.195453752","rc":[{"atl":[[7.6,0]],"id":3805793},{"atb":[[19,3.35]],"id":3805736},{"atl":[[13.5,0]],"id":3805762},{"atl":[[46,3.16]],"id":522743}],"con":true,"img":false}]}
{"op":"mcm","clk":"5348068392","pt":1646213443246,"mc":[{"id":"1.195453752","rc":[{"atb":[[19,2.72],[20,23.01]],"id":522750},{"atl":[[28,31.99],[60,2]],"id":3805730}],"con":true,"img":false}]}
{"op":"mcm","clk":"5348068405","pt":1646213443435,"mc":[{"id":"1.195453752","rc":[{"atb":[[4.8,26.32]],"id":3805731},{"atb":[[8.6,40.34],[9.4,4.95]],"id":3805762}],"con":true,"img":false}]}
{"op":"mcm","clk":"5348068412","pt":1646213443506,"mc":[{"id":"1.195453752","rc":[{"atl":[[36,0],[38,4.95],[44,25.83],[46,9.9]],"id":522746},{"atb":[[17.5,4.95],[17,30.27]],"id":3805736},{"atb":[[10,2.51]],"id":3805762},{"atl":[[24,0],[25,4.95],[28,0]],"id":522742}],"con":true,"img":false}]}
{"op":"mcm","clk":"5348068419","pt":1646213443611,"mc":[{"id":"1.195453752","rc":[{"atb":[[19.5,8.56]],"id":3805736}],"con":true,"img":false}]}
{"op":"mcm","clk":"5348068426","pt":1646213443715,"mc":[{"id":"1.195453752","rc":[{"atl":[[34,0]],"id":522746},{"atb":[[10,0]],"id":3805762},{"atl":[[23,0]],"id":522742}],"con":true,"img":false}]}
{"op":"mcm","clk":"5348068430","pt":1646213443821,"mc":[{"id":"1.195453752","rc":[{"atb":[[6.8,0]],"id":3805731},{"atb":[[8.4,3.26],[9.4,7.67]],"id":3805762},{"atl":[[70,0],[50,0]],"id":522743}],"con":true,"img":false}]}
{"op":"mcm","clk":"5348068435","pt":1646213443924,"mc":[{"id":"1.195453752","rc":[{"atb":[[5.6,0],[5,9.9],[5.2,22.41],[5.4,4.95]],"id":3805793},{"atl":[[70,2],[55,0]],"id":522746}],"con":true,"img":false}]}
{"op":"mcm","clk":"5348068436","pt":1646213444027,"mc":[{"id":"1.195453752","rc":[{"atl":[[36,1]],"id":522746},{"atb":[[9.6,2.7]],"id":3805762},{"atl":[[24,1.05]],"id":522742}],"con":true,"img":false}]}
{"op":"mcm","clk":"5348068441","pt":1646213444130,"mc":[{"id":"1.195453752","rc":[{"atl":[[48,4.54]],"id":522741}],"con":true,"img":false}]}
{"op":"mcm","clk":"5348068447","pt":1646213444237,"mc":[{"id":"1.195453752","rc":[{"atb":[[5.7,0]],"id":3805793},{"atl":[[42,3.86],[44,0],[46,37.37]],"id":522746},{"atb":[[8.6,55.06]],"id":3805762},{"atl":[[44,26.51],[26,6.34]],"id":522742}],"con":true,"img":false}]}
{"op":"mcm","clk":"5348068449","pt":1646213444340,"mc":[{"id":"1.195453752","rc":[{"atb":[[5.5,5.17]],"id":3805793},{"atl":[[9,21.7]],"id":3805731},{"atb":[[26,9.81]],"id":522741}],"con":true,"img":false}]}
{"op":"mcm","clk":"5348068453","pt":1646213444394,"mc":[{"id":"1.195453752","rc":[{"atb":[[11.5,0]],"id":3805746},{"atb":[[5.7,22.41]],"id":3805793},{"atl":[[34,0]],"id":3805755},{"atb":[[20,10.61]],"id":522746},{"atb":[[18.5,0]],"id":3805736},{"atl":[[23,0]],"id":3805730},{"atl":[[48,3.37]],"id":522741},{"atl":[[24,6],[25,0],[28,9.9]],"id":522742}],"con":true,"img":false}]}
{"op":"mcm","clk":"5348068457","pt":1646213444496,"mc":[{"id":"1.195453752","rc":[{"atb":[[13,4.54]],"id":3805746},{"atl":[[36,5.76]],"id":3805755},{"atl":[[24,5.98]],"id":3805730},{"atl":[[46,1.17]],"id":522741}],"con":true,"img":false}]}
{"op":"mcm","clk":"5348068460","pt":1646213444606,"mc":[{"id":"1.195453752","rc":[{"atb":[[5.5,0]],"id":3805793},{"atl":[[24,4.95]],"id":522742}],"con":true,"img":false}]}
{"op":"mcm","clk":"5348068465","pt":1646213444703,"mc":[{"id":"1.195453752","rc":[{"atb":[[8,0],[9,0]],"id":3805746},{"atb":[[5.7,27.58]],"id":3805793},{"atl":[[23,1.05]],"id":522742}],"con":true,"img":false}]}
{"op":"mcm","clk":"5348068470","pt":1646213444808,"mc":[{"id":"1.195453752","rc":[{"atb":[[9.6,45.13],[11,4.95]],"id":3805746},{"atl":[[70,20.06],[36,10.29],[44,9.9]],"id":3805755},{"atl":[[80,0]],"id":522741}],"con":true,"img":false}]}
{"op":"mcm","clk":"5348068482","pt":1646213445117,"mc":[{"id":"1.195453752","rc":[{"atb":[[19.5,0]],"id":522746},{"atl":[[46,9.9]],"id":522746},{"atb":[[17.5,25.04],[17,2.72]],"id":3805736}],"con":true,"img":false}]}
{"op":"mcm","clk":"5348068495","pt":1646213445430,"mc":[{"id":"1.195453752","rc":[{"atb":[[8.4,3.26]],"id":3805746},{"atl":[[8.6,80]],"id":3805793}],"con":true,"img":false}]}
{"op":"mcm","clk":"5348068499","pt":1646213445532,"mc":[{"id":"1.195453752","rc":[{"atb":[[9.4,2.72]],"id":3805746},{"atl":[[7.8,4.95]],"id":3805793}],"con":true,"img":false}]}
{"op":"mcm","clk":"5348068502","pt":1646213445636,"mc":[{"id":"1.195453752","rc":[{"atb":[[18.5,15.83]],"id":522746},{"atl":[[42,16.97]],"id":522746},{"atl":[[26,23.12]],"id":522742}],"con":true,"img":false}]}
{"op":"mcm","clk":"5348068509","pt":1646213445740,"mc":[{"id":"1.195453752","rc":[{"atb":[[5.7,22.41]],"id":3805793},{"atb":[[19,0]],"id":522746},{"atl":[[44,2.33]],"id":522742}],"con":true,"img":false}]}
{"op":"mcm","clk":"5348068516","pt":1646213445843,"mc":[{"id":"1.195453752","rc":[{"atb":[[5.8,5.17]],"id":3805793}],"con":true,"img":false}]}
{"op":"mcm","clk":"5348068532","pt":1646213446202,"mc":[{"id":"1.195453752","rc":[{"atb":[[13.5,9.9],[15.5,4.95]],"id":522746}],"con":true,"img":false}]}
{"op":"mcm","clk":"5348068533","pt":1646213446305,"mc":[{"id":"1.195453752","rc":[{"atb":[[5.2,0],[5.4,45.96]],"id":3805793}],"con":true,"img":false}]}
{"op":"mcm","clk":"5348068540","pt":1646213446522,"mc":[{"id":"1.195453752","rc":[{"atl":[[28,9.9],[60,26.6]],"id":3805730}],"con":true,"img":false}]}
{"op":"mcm","clk":"5348068571","pt":1646213447135,"mc":[{"id":"1.195453752","rc":[{"atl":[[7.4,22.41]],"id":3805793},{"atb":[[9.6,0]],"id":3805762},{"atl":[[13,0]],"id":3805762},{"atb":[[26,9.06]],"id":522741}],"con":true,"img":false}]}
{"op":"mcm","clk":"5348068577","pt":1646213447241,"mc":[{"id":"1.195453752","rc":[{"atb":[[9.4,10.37]],"id":3805762}],"con":true,"img":false}]}
{"op":"mcm","clk":"5348068591","pt":1646213447443,"mc":[{"id":"1.195453752","rc":[{"atl":[[12.5,10.74]],"id":3805762}],"con":true,"img":false}]}
{"op":"mcm","clk":"5348068598","pt":1646213447547,"mc":[{"id":"1.195453752","rc":[{"atl":[[34,5.68]],"id":3805736},{"atb":[[8.6,24.62],[8.4,28.44]],"id":3805762},{"atl":[[70,9.9]],"id":522741},{"atb":[[15.5,13.3]],"id":522742}],"con":true,"img":false}]}
{"op":"mcm","clk":"5348068607","pt":1646213447600,"mc":[{"id":"1.195453752","rc":[{"atb":[[8.8,51.82]],"id":3805740}],"con":true,"img":false}]}
{"op":"mcm","clk":"5348068622","pt":1646213447821,"mc":[{"id":"1.195453752","rc":[{"atb":[[15.5,10.93]],"id":522742}],"con":true,"img":false}]}
{"op":"mcm","clk":"5348068625","pt":1646213447912,"mc":[{"id":"1.195453752","rc":[{"atb":[[16,2.37]],"id":522742}],"con":true,"img":false}]}
{"op":"mcm","clk":"5348068643","pt":1646213448224,"mc":[{"id":"1.195453752","rc":[{"atb":[[5.8,38.2]],"id":3805793}],"con":true,"img":false}]}
{"op":"mcm","clk":"5348068645","pt":1646213448327,"mc":[{"id":"1.195453752","rc":[{"atl":[[34,0.88],[36,4.95]],"id":3805736},{"atl":[[65,8.22],[70,0],[85,9.9],[90,22.08]],"id":522747},{"atb":[[14.5,0],[15,0]],"id":522742}],"con":true,"img":false}]}
{"op":"mcm","clk":"5348068653","pt":1646213448430,"mc":[{"id":"1.195453752","rc":[{"atb":[[4.8,0],[4,33.33]],"id":3805731},{"atb":[[15,23.6]],"id":522742}],"con":true,"img":false}]}
{"op":"mcm","clk":"5348068658","pt":1646213448541,"mc":[{"id":"1.195453752","rc":[{"atl":[[7.4,24.74]],"id":3805793}],"con":true,"img":false}]}
{"op":"mcm","clk":"5348068673","pt":1646213448749,"mc":[{"id":"1.195453752","rc":[{"atb":[[16,26.39],[18.5,2.72]],"id":522746},{"atl":[[48,0]],"id":522743}],"con":true,"img":false}]}
{"op":"mcm","clk":"5348068680","pt":1646213448846,"mc":[{"id":"1.195453752","rc":[{"atl":[[44,0.98]],"id":522743}],"con":true,"img":false}]}
{"op":"mcm","clk":"5348068691","pt":1646213449060,"mc":[{"id":"1.195453752","rc":[{"atb":[[5.7,0]],"id":3805793}],"con":true,"img":false}]}
{"op":"mcm","clk":"5348068697","pt":1646213449111,"mc":[{"id":"1.195453752","rc":[{"atl":[[55,2.93]],"id":3805736}],"con":true,"img":false}]}
{"op":"mcm","clk":"5348068705","pt":1646213449206,"mc":[{"id":"1.195453752","rc":[{"atb":[[19,0]],"id":3805736},{"atb":[[6.4,44.58]],"id":3805731}],"con":true,"img":false}]}
{"op":"mcm","clk":"5348068711","pt":1646213449318,"mc":[{"id":"1.195453752","rc":[{"atb":[[20,3.35]],"id":3805736},{"atl":[[42,0.4]],"id":522743}],"con":true,"img":false}]}
{"op":"mcm","clk":"5348068720","pt":1646213449523,"mc":[{"id":"1.195453752","rc":[{"atb":[[5.4,4.95]],"id":3805793},{"atl":[[55,19.66]],"id":522743}],"con":true,"img":false}]}
{"op":"mcm","clk":"5348068725","pt":1646213449629,"mc":[{"id":"1.195453752","rc":[{"atb":[[5,103.47]],"id":3805793},{"atl":[[55,15.27],[60,2]],"id":3805736},{"atl":[[44,0]],"id":522743}],"con":true,"img":false}]}
{"op":"mcm","clk":"5348068732","pt":1646213449724,"mc":[{"id":"1.195453752","rc":[{"atb":[[17.5,4.95],[17,14.45]],"id":3805736},{"atl":[[42,1.38]],"id":522743}],"con":true,"img":false}]}
{"op":"mcm","clk":"5348068738","pt":1646213449825,"mc":[{"id":"1.195453752","rc":[{"atb":[[5.8,33.03]],"id":3805793},{"atb":[[38,4.78]],"id":522747},{"atb":[[9.4,7.67]],"id":3805762},{"atl":[[24,4.95]],"id":3805730},{"atb":[[26,9.94]],"id":522741}],"con":true,"img":false}]}
{"op":"mcm","clk":"5348068743","pt":1646213449930,"mc":[{"id":"1.195453752","rc":[{"atb":[[9.6,2.7]],"id":3805762},{"atl":[[23,1.03]],"id":3805730}],"con":true,"img":false}]}
{"op":"mcm","clk":"5348068747","pt":1646213450033,"mc":[{"id":"1.195453752","rc":[{"atb":[[5.8,0]],"id":3805793},{"atl":[[48,0]],"id":522741}],"con":true,"img":false}]}
{"op":"mcm","clk":"5348068750","pt":1646213450135,"mc":[{"id":"1.195453752","rc":[{"atb":[[20,11.69]],"id":3805736}],"con":true,"img":false}]}
{"op":"mcm","clk":"5348068754","pt":1646213450238,"mc":[{"id":"1.195453752","rc":[{"atl":[[46,0]],"id":522743}],"con":true,"img":false}]}
{"op":"mcm","clk":"5348068761","pt":1646213450343,"mc":[{"id":"1.195453752","rc":[{"atb":[[5.5,4.62]],"id":3805793},{"atb":[[8.6,52]],"id":3805762},{"atl":[[28,31.99],[60,2]],"id":3805730},{"atl":[[46,0]],"id":522741}],"con":true,"img":false}]}
{"op":"mcm","clk":"5348068766","pt":1646213450445,"mc":[{"id":"1.195453752","rc":[{"atb":[[17,2.72]],"id":3805736},{"atb":[[8.4,3.26]],"id":3805762},{"atl":[[48,1.17]],"id":522741}],"con":true,"img":false}]}
{"op":"mcm","clk":"5348068771","pt":1646213450550,"mc":[{"id":"1.195453752","rc":[{"atl":[[85,0],[100,2]],"id":522741}],"con":true,"img":false}]}
{"op":"mcm","clk":"5348068780","pt":1646213450755,"mc":[{"id":"1.195453752","rc":[{"atl":[[36,5.52]],"id":522746},{"atb":[[9.6,21.13]],"id":3805762},{"atl":[[70,31.99]],"id":522741}],"con":true,"img":false}]}
{"op":"mcm","clk":"5348068786","pt":1646213450863,"mc":[{"id":"1.195453752","rc":[{"atb":[[5.7,33.92]],"id":3805747},{"atb":[[5,143.1]],"id":3805793},{"atl":[[50,8.19]],"id":522741},{"atb":[[15.5,0]],"id":522742}],"con":true,"img":false}]}
{"op":"mcm","clk":"5348068802","pt":1646213451028,"mc":[{"id":"1.195453752","rc":[{"atb":[[19.5,0]],"id":3805736}],"con":true,"img":false}]}
{"op":"mcm","clk":"5348068808","pt":1646213451128,"mc":[{"id":"1.195453752","rc":[{"atb":[[5.7,27.85]],"id":3805747},{"atb":[[16,0]],"id":522742}],"con":true,"img":false}]}
{"op":"mcm","clk":"5348068812","pt":1646213451232,"mc":[{"id":"1.195453752","rc":[{"atb":[[5.8,6.07]],"id":3805747},{"atb":[[9.6,9.9],[11,33.15]],"id":3805746},{"atl":[[23,0]],"id":522742}],"con":true,"img":false}]}
{"op":"mcm","clk":"5348068816","pt":1646213451335,"mc":[{"id":"1.195453752","rc":[{"atl":[[24,6]],"id":522742}],"con":true,"img":false}]}
{"op":"mcm","clk":"5348068825","pt":1646213451439,"mc":[{"id":"1.195453752","rc":[{"atl":[[42,13.1]],"id":522746},{"atb":[[8.6,37.28]],"id":3805762},{"atb":[[14,14.12],[15,0],[15.5,2.55]],"id":522742}],"con":true,"img":false}]}
{"op":"mcm","clk":"5348068831","pt":1646213451541,"mc":[{"id":"1.195453752","rc":[{"atb":[[17,17.43]],"id":3805736}],"con":true,"img":false}]}
{"op":"mcm","clk":"5348068844","pt":1646213451750,"mc":[{"id":"1.195453752","rc":[{"atb":[[5.6,79.39],[5.4,4.95]],"id":3805747},{"atb":[[15,11.32],[15.5,0]],"id":522742},{"atl":[[24,12.89],[26,6.34],[28,31.99]],"id":522742}],"con":true,"img":false}]}
{"op":"mcm","clk":"5348068867","pt":1646213452009,"mc":[{"id":"1.195453752","rc":[{"atb":[[15.5,2.55]],"id":522742}],"con":true,"img":false}]}
{"op":"mcm","clk":"5348068881","pt":1646213452221,"mc":[{"id":"1.195453752","rc":[{"atb":[[7.2,0],[6.2,0]],"id":3805731},{"atb":[[9,3.51],[10,0]],"id":3805740}],"con":true,"img":false}]}
{"op":"mcm","clk":"5348068903","pt":1646213452530,"mc":[{"id":"1.195453752","rc":[{"atb":[[7,26.42]],"id":3805731}],"con":true,"img":false}]}
{"op":"mcm","clk":"5348068910","pt":1646213452631,"mc":[{"id":"1.195453752","rc":[{"atb":[[5.8,0]],"id":3805747},{"atl":[[9,19.81]],"id":3805731},{"atl":[[12.5,9.26]],"id":3805762},{"atb":[[26,9.06]],"id":522741},{"atl":[[24,11.84],[26,0]],"id":522742},{"atl":[[75,37.64],[55,4.95]],"id":522743}],"con":true,"img":false}]}
{"op":"mcm","clk":"5348068916","pt":1646213452734,"mc":[{"id":"1.195453752","rc":[{"atb":[[5.7,33.92]],"id":3805747},{"atb":[[27,0.88]],"id":522741},{"atl":[[23,1.05]],"id":522742}],"con":true,"img":false}]}
{"op":"mcm","clk":"5348068920","pt":1646213452837,"mc":[{"id":"1.195453752","rc":[{"atb":[[7,29.33]],"id":3805731}],"con":true,"img":false}]}
{"op":"mcm","clk":"5348068924","pt":1646213452941,"mc":[{"id":"1.195453752","rc":[{"atb":[[4.3,139.13],[6.4,4.95]],"id":3805731},{"atb":[[9,23.32],[8.8,20.32],[8.4,33.72]],"id":3805740}],"con":true,"img":false}]}
{"op":"mcm","clk":"5348068935","pt":1646213453147,"mc":[{"id":"1.195453752","rc":[{"atb":[[6.8,2.72],[5.9,3.26]],"id":3805731}],"con":true,"img":false}]}
{"op":"mcm","clk":"5348068943","pt":1646213453251,"mc":[{"id":"1.195453752","rc":[{"atb":[[21,3.26],[22,24.48],[28,5.86]],"id":522741},{"atb":[[9.6,2.72],[9,19.81],[8.6,3.26]],"id":3805740}],"con":true,"img":false}]}
{"op":"mcm","clk":"5348068957","pt":1646213453508,"mc":[{"id":"1.195453752","rc":[{"atb":[[9.2,3.57]],"id":3805740}],"con":true,"img":false}]}
{"op":"mcm","clk":"5348068969","pt":1646213453818,"mc":[{"id":"1.195453752","rc":[{"atb":[[4.3,40.36]],"id":3805731},{"atb":[[8.8,0]],"id":3805740}],"con":true,"img":false}]}
{"op":"mcm","clk":"5348068983","pt":1646213454027,"mc":[{"id":"1.195453752","rc":[{"atl":[[9,21.69]],"id":3805731},{"atl":[[12.5,10.59]],"id":3805762},{"atl":[[23,0]],"id":3805730}],"con":true,"img":false}]}
{"op":"mcm","clk":"5348068991","pt":1646213454127,"mc":[{"id":"1.195453752","rc":[{"atl":[[24,5.98]],"id":3805730},{"atb":[[9,48.59],[8.4,4.95]],"id":3805740}],"con":true,"img":false}]}
{"op":"mcm","clk":"5348068997","pt":1646213454229,"mc":[{"id":"1.195453752","rc":[{"atb":[[26,2.72]],"id":522741}],"con":true,"img":false}]}
{"op":"mcm","clk":"5348069018","pt":1646213454546,"mc":[{"id":"1.195453752","rc":[{"atl":[[28,9.9],[60,25.06]],"id":3805730}],"con":true,"img":false}]}
{"op":"mcm","clk":"5348069030","pt":1646213454748,"mc":[{"id":"1.195453752","rc":[{"atb":[[5.6,0],[5.4,92.99]],"id":3805747},{"atb":[[5.6,34.46]],"id":3805793}],"con":true,"img":false}]}
{"op":"mcm","clk":"5348069051","pt":1646213455060,"mc":[{"id":"1.195453752","rc":[{"atl":[[34,5.68]],"id":3805736}],"con":true,"img":false}]}
{"op":"mcm","clk":"5348069058","pt":1646213455118,"mc":[{"id":"1.195453752","rc":[{"atb":[[5.5,0]],"id":3805793}],"con":true,"img":false}]}
{"op":"mcm","clk":"5348069064","pt":1646213455215,"mc":[{"id":"1.195453752","rc":[{"atb":[[5.7,4.62]],"id":3805793}],"con":true,"img":false}]}
{"op":"mcm","clk":"5348069070","pt":1646213455324,"mc":[{"id":"1.195453752","rc":[{"atb":[[5,49.54],[5.4,49.09]],"id":3805793},{"atl":[[7.4,22.41]],"id":3805793},{"atb":[[38,4.28]],"id":522747},{"atl":[[9,19.81]],"id":3805731},{"atl":[[12.5,9.26]],"id":3805762}],"con":true,"img":false}]}
{"op":"mcm","clk":"5348069077","pt":1646213455525,"mc":[{"id":"1.195453752","rc":[{"atb":[[5,9.9]],"id":3805793},{"atb":[[6.4,44.56]],"id":3805731}],"con":true,"img":false}]}
{"op":"mcm","clk":"5348069088","pt":1646213455731,"mc":[{"id":"1.195453752","rc":[{"atl":[[34,0.88],[55,12.33]],"id":3805736}],"con":true,"img":false}]}
{"op":"mcm","clk":"5348069104","pt":1646213456051,"mc":[{"id":"1.195453752","rc":[{"atb":[[9.6,11.63],[7.6,0]],"id":522746},{"atl":[[70,0],[60,2]],"id":522746},{"atb":[[9.6,0],[8.4,13.51]],"id":3805736},{"atl":[[21,5],[26,0]],"id":3805740}],"con":true,"img":false}]}
{"op":"mcm","clk":"5348069135","pt":1646213456563,"mc":[{"id":"1.195453752","rc":[{"atl":[[36,9.48]],"id":3805736}],"con":true,"img":false}]}
{"op":"mcm","clk":"5348069142","pt":1646213456722,"mc":[{"id":"1.195453752","rc":[{"atb":[[5.7,27.85]],"id":3805747},{"atl":[[24,4.95]],"id":3805730}],"con":true,"img":false}]}
{"op":"mcm","clk":"5348069148","pt":1646213456824,"mc":[{"id":"1.195453752","rc":[{"atb":[[5.8,6.07]],"id":3805747},{"atl":[[23,1.03]],"id":3805730}],"con":true,"img":false}]}
{"op":"mcm","clk":"5348069164","pt":1646213457134,"mc":[{"id":"1.195453752","rc":[{"atb":[[5.8,33.03]],"id":3805793},{"atl":[[48,4.54]],"id":522741}],"con":true,"img":false}]}
{"op":"mcm","clk":"5348069169","pt":1646213457235,"mc":[{"id":"1.195453752","rc":[{"atl":[[28,31.99],[60,2]],"id":3805730}],"con":true,"img":false}]}
