{"op":"mcm","clk":"5346195480","pt":1646178340819,"mc":[{"id":"1.195453758","marketDefinition":{"bspMarket":false,"turnInPlayEnabled":false,"persistenceEnabled":false,"marketBaseRate":7.0,"eventId":"31272494","eventTypeId":"4339","numberOfWinners":1,"bettingType":"ODDS","marketType":"QUINELLA","marketTime":"2022-03-02T11:32:00.000Z","suspendTime":"2022-03-02T11:32:00.000Z","bspReconciled":false,"complete":true,"inPlay":false,"crossMatching":false,"runnersVoidable":false,"numberOfActiveRunners":15,"betDelay":0,"status":"OPEN","runners":[{"status":"ACTIVE","sortPriority":1,"id":522741,"name":"1 - 2 / 2 - 1"},{"status":"ACTIVE","sortPriority":2,"id":522743,"name":"1 - 4 / 4 - 1"},{"status":"ACTIVE","sortPriority":3,"id":522745,"name":"1 - 6 / 6 - 1"},{"status":"ACTIVE","sortPriority":4,"id":3805730,"name":"1 - 7 / 7 - 1"},{"status":"ACTIVE","sortPriority":5,"id":3805731,"name":"1 - 8 / 8 - 1"},{"status":"ACTIVE","sortPriority":6,"id":522747,"name":"2 - 4 / 4 - 2"},{"status":"ACTIVE","sortPriority":7,"id":522749,"name":"2 - 6 / 6 - 2"},{"status":"ACTIVE","sortPriority":8,"id":3805736,"name":"2 - 7 / 7 - 2"},{"status":"ACTIVE","sortPriority":9,"id":3805740,"name":"2 - 8 / 8 - 2"},{"status":"ACTIVE","sortPriority":10,"id":522753,"name":"4 - 6 / 6 - 4"},{"status":"ACTIVE","sortPriority":11,"id":3805755,"name":"4 - 7 / 7 - 4"},{"status":"ACTIVE","sortPriority":12,"id":3805762,"name":"4 - 8 / 8 - 4"},{"status":"ACTIVE","sortPriority":13,"id":3805783,"name":"6 - 7 / 7 - 6"},{"status":"ACTIVE","sortPriority":14,"id":3805784,"name":"6 - 8 / 8 - 6"},{"status":"ACTIVE","sortPriority":15,"id":3805793,"name":"7 - 8 / 8 - 7"}],"regulators":["MR_INT"],"venue":"Traralgon","countryCode":"AU","discountAllowed":true,"timezone":"Australia/Sydney","openDate":"2022-03-02T08:31:00.000Z","version":4382480630,"name":"Quinella","eventName":"Traralgon (AUS) 2nd Mar"},"rc":[],"con":true,"img":false}]}
{"op":"mcm","clk":"5346200445","pt":1646178438495,"mc":[{"id":"1.195453758","rc":[{"atb":[[4.5,57.01],[6,39.91],[3.75,96.76]],"id":3805736},{"atb":[[8.6,35.01],[19,11.08],[11.5,19]],"id":3805784},{"atb":[[8,28.5],[6,53.21],[12.5,17.35]],"id":3805783},{"atb":[[8.6,26.26],[14,15.35],[6.6,47.51]],"id":522753},{"atb":[[9.6,30.94],[23,9.06],[14,15.35]],"id":3805762},{"atb":[[9.2,32.44],[21,9.97],[13,16.63]],"id":3805793},{"atb":[[6.4,36.95],[5.2,63.35],[9.4,23.75]],"id":3805740},{"atb":[[7.2,42.91],[9.2,24.33],[15.5,13.76]],"id":3805755}],"con":true,"img":false}]}
{"op":"mcm","clk":"5346200455","pt":1646178438649,"mc":[{"id":"1.195453758","rc":[{"atb":[[4,88.69],[5,49.89],[7,33.26]],"id":522747},{"atb":[[3.45,108.6],[3.95,67.64],[5.4,45.35]],"id":522749},{"atb":[[17,12.47],[9.8,22.67],[7.8,39.12]],"id":3805731},{"atb":[[6.4,36.95],[5.2,63.35],[9.4,23.75]],"id":3805730},{"atb":[[3.6,76.75],[3.1,126.7],[4.7,53.93]],"id":522741},{"atb":[[5.6,57.84],[7.2,32.18],[10.5,21]],"id":522743},{"atb":[[4.8,70.02],[8.6,26.26],[5.8,41.57]],"id":522745}],"con":true,"img":false}]}
{"op":"mcm","clk":"5346316494","pt":1646180692934,"mc":[{"id":"1.195453758","rc":[{"atb":[[8.6,0],[19,0],[11.5,0]],"id":3805784},{"atb":[[8,0],[6,0],[12.5,0]],"id":3805783},{"atb":[[9.2,0],[21,0],[13,0]],"id":3805793},{"atb":[[7.2,0],[9.2,0],[15.5,0]],"id":3805755},{"atb":[[4.5,0],[6,0],[3.75,0]],"id":3805736},{"atb":[[4,0],[5,0],[7,0]],"id":522747},{"atb":[[3.45,0],[3.95,0],[5.4,0]],"id":522749},{"atb":[[17,0],[9.8,0],[7.8,0]],"id":3805731},{"atb":[[6.4,0],[5.2,0],[9.4,0]],"id":3805730},{"atb":[[9.6,0],[23,0],[14,0]],"id":3805762},{"atb":[[8.6,0],[14,0],[6.6,0]],"id":522753},{"atb":[[3.6,0],[3.1,0],[4.7,0]],"id":522741},{"atb":[[5.6,0],[7.2,0],[10.5,0]],"id":522743},{"atb":[[6.4,0],[5.2,0],[9.4,0]],"id":3805740},{"atb":[[4.8,0],[8.6,0],[5.8,0]],"id":522745}],"con":true,"img":false}]}
{"op":"mcm","clk":"5346317047","pt":1646180703260,"mc":[{"id":"1.195453758","rc":[{"atb":[[4,88.7],[5,49.89],[7,33.26]],"id":522747},{"atb":[[3.45,108.61],[3.95,67.65],[5.4,45.36]],"id":522749},{"atb":[[17,12.47],[9.8,22.68],[7.8,39.13]],"id":3805731},{"atb":[[6.4,36.96],[5.2,63.36],[9.4,23.75]],"id":3805730},{"atb":[[3.6,76.76],[3.1,126.72],[4.7,53.94]],"id":522741},{"atb":[[5.6,57.85],[7.2,32.19],[10.5,21]],"id":522743},{"atb":[[4.8,70.02],[8.6,26.26],[5.8,41.58]],"id":522745}],"con":true,"img":false}]}
{"op":"mcm","clk":"5346317059","pt":1646180703371,"mc":[{"id":"1.195453758","rc":[{"atb":[[8.6,35.01],[19,11.08],[11.5,19]],"id":3805784},{"atb":[[8,28.51],[6,53.22],[12.5,17.35]],"id":3805783},{"atb":[[9.2,32.45],[21,9.97],[13,16.63]],"id":3805793},{"atb":[[7.2,42.92],[9.2,24.34],[15.5,13.76]],"id":3805755},{"atb":[[4.5,57.02],[6,39.91],[3.75,96.77]],"id":3805736},{"atb":[[9.6,30.94],[23,9.07],[14,15.35]],"id":3805762},{"atb":[[8.6,26.26],[14,15.35],[6.6,47.52]],"id":522753},{"atb":[[6.4,36.96],[5.2,63.36],[9.4,23.75]],"id":3805740}],"con":true,"img":false}]}
{"op":"mcm","clk":"5346591739","pt":1646184894725,"mc":[{"id":"1.195453758","rc":[{"atb":[[8.6,0],[19,0],[11.5,0]],"id":3805784},{"atb":[[8,0],[6,0],[12.5,0]],"id":3805783},{"atb":[[9.2,0],[21,0],[13,0]],"id":3805793},{"atb":[[7.2,0],[9.2,0],[15.5,0]],"id":3805755},{"atb":[[4.5,0],[6,0],[3.75,0]],"id":3805736},{"atb":[[4,0],[5,0],[7,0]],"id":522747},{"atb":[[3.45,0],[3.95,0],[5.4,0]],"id":522749},{"atb":[[17,0],[9.8,0],[7.8,0]],"id":3805731},{"atb":[[9.6,0],[23,0],[14,0]],"id":3805762},{"atb":[[6.4,0],[5.2,0],[9.4,0]],"id":3805730},{"atb":[[8.6,0],[14,0],[6.6,0]],"id":522753},{"atb":[[3.6,0],[3.1,0],[4.7,0]],"id":522741},{"atb":[[5.6,0],[7.2,0],[10.5,0]],"id":522743},{"atb":[[6.4,0],[5.2,0],[9.4,0]],"id":3805740},{"atb":[[4.8,0],[8.6,0],[5.8,0]],"id":522745}],"con":true,"img":false}]}
{"op":"mcm","clk":"5346593216","pt":1646184920641,"mc":[{"id":"1.195453758","rc":[{"atb":[[8.6,35.07],[19,11.1],[11.5,19.03]],"id":3805784},{"atb":[[8,28.55],[6,53.3],[12.5,17.38]],"id":3805783},{"atb":[[9.2,32.5],[21,9.99],[13,16.65]],"id":3805793},{"atb":[[7.2,42.99],[9.2,24.37],[15.5,13.78]],"id":3805755},{"atb":[[4.5,57.11],[6,39.98],[3.75,96.92]],"id":3805736},{"atb":[[4,88.84],[5,49.97],[7,33.31]],"id":522747},{"atb":[[3.45,108.79],[3.95,67.76],[5.4,45.43]],"id":522749},{"atb":[[17,12.49],[9.8,22.71],[7.8,39.19]],"id":3805731},{"atb":[[9.6,30.99],[23,9.08],[14,15.37]],"id":3805762},{"atb":[[6.4,37.01],[5.2,63.46],[9.4,23.79]],"id":3805730},{"atb":[[8.6,26.3],[14,15.37],[6.6,47.59]],"id":522753},{"atb":[[3.6,76.88],[3.1,126.92],[4.7,54.02]],"id":522741},{"atb":[[5.6,57.94],[7.2,32.24],[10.5,21.04]],"id":522743},{"atb":[[6.4,37.01],[5.2,63.46],[9.4,23.79]],"id":3805740},{"atb":[[4.8,70.14],[8.6,26.3],[5.8,41.64]],"id":522745}],"con":true,"img":false}]}
{"op":"mcm","clk":"5347092220","pt":1646192802701,"mc":[{"id":"1.195453758","marketDefinition":{"bspMarket":false,"turnInPlayEnabled":false,"persistenceEnabled":false,"marketBaseRate":7.0,"eventId":"31272494","eventTypeId":"4339","numberOfWinners":1,"bettingType":"ODDS","marketType":"QUINELLA","marketTime":"2022-03-02T11:32:00.000Z","suspendTime":"2022-03-02T11:32:00.000Z","bspReconciled":false,"complete":true,"inPlay":false,"crossMatching":false,"runnersVoidable":false,"numberOfActiveRunners":15,"betDelay":0,"status":"OPEN","runners":[{"status":"ACTIVE","sortPriority":1,"id":522741,"name":"1 - 2 / 2 - 1"},{"status":"ACTIVE","sortPriority":2,"id":522743,"name":"1 - 4 / 4 - 1"},{"status":"ACTIVE","sortPriority":3,"id":522745,"name":"1 - 6 / 6 - 1"},{"status":"ACTIVE","sortPriority":4,"id":3805730,"name":"1 - 7 / 7 - 1"},{"status":"ACTIVE","sortPriority":5,"id":3805731,"name":"1 - 8 / 8 - 1"},{"status":"ACTIVE","sortPriority":6,"id":522747,"name":"2 - 4 / 4 - 2"},{"status":"ACTIVE","sortPriority":7,"id":522749,"name":"2 - 6 / 6 - 2"},{"status":"ACTIVE","sortPriority":8,"id":3805736,"name":"2 - 7 / 7 - 2"},{"status":"ACTIVE","sortPriority":9,"id":3805740,"name":"2 - 8 / 8 - 2"},{"status":"ACTIVE","sortPriority":10,"id":522753,"name":"4 - 6 / 6 - 4"},{"status":"ACTIVE","sortPriority":11,"id":3805755,"name":"4 - 7 / 7 - 4"},{"status":"ACTIVE","sortPriority":12,"id":3805762,"name":"4 - 8 / 8 - 4"},{"status":"ACTIVE","sortPriority":13,"id":3805783,"name":"6 - 7 / 7 - 6"},{"status":"ACTIVE","sortPriority":14,"id":3805784,"name":"6 - 8 / 8 - 6"},{"status":"ACTIVE","sortPriority":15,"id":3805793,"name":"7 - 8 / 8 - 7"}],"regulators":["MR_INT"],"venue":"Traralgon","countryCode":"AU","discountAllowed":true,"timezone":"Australia/Sydney","openDate":"2022-03-02T08:31:00.000Z","version":4382480630,"name":"Quinella","eventName":"Traralgon (AUS) 2nd Mar"},"rc":[{"atb":[[8.6,35.13],[19,11.12],[11.5,19.06]],"id":3805784},{"atb":[[8,28.6],[6,53.39],[12.5,17.41]],"id":3805783},{"atb":[[9.2,32.55],[21,10.01],[13,16.68]],"id":3805793},{"atb":[[7.2,43.06],[9.2,24.42],[15.5,13.8]],"id":3805755},{"atb":[[4.5,57.2],[6,40.04],[3.75,97.08]],"id":3805736},{"atb":[[4,88.99],[5,50.06],[7,33.37]],"id":522747},{"atb":[[3.45,108.97],[3.95,67.87],[5.4,45.51]],"id":522749},{"atb":[[17,12.51],[9.8,22.75],[7.8,39.26]],"id":3805731},{"atb":[[6.4,37.08],[5.2,63.56],[9.4,23.83]],"id":3805730},{"atb":[[9.6,31.04],[23,9.09],[14,15.4]],"id":3805762},{"atb":[[8.6,26.34],[14,15.4],[6.6,47.67]],"id":522753},{"atb":[[3.6,77.01],[3.1,127.13],[4.7,54.11]],"id":522741},{"atb":[[5.6,58.04],[7.2,32.29],[10.5,21.07]],"id":522743},{"atb":[[6.4,37.08],[5.2,63.56],[9.4,23.83]],"id":3805740},{"atb":[[4.8,70.25],[8.6,26.34],[5.8,41.71]],"id":522745}],"con":true,"img":true}]}
{"op":"mcm","clk":"5347381093","pt":1646198202719,"mc":[{"id":"1.195453758","marketDefinition":{"bspMarket":false,"turnInPlayEnabled":false,"persistenceEnabled":false,"marketBaseRate":7.0,"eventId":"31272494","eventTypeId":"4339","numberOfWinners":1,"bettingType":"ODDS","marketType":"QUINELLA","marketTime":"2022-03-02T11:32:00.000Z","suspendTime":"2022-03-02T11:32:00.000Z","bspReconciled":false,"complete":true,"inPlay":false,"crossMatching":false,"runnersVoidable":false,"numberOfActiveRunners":15,"betDelay":0,"status":"OPEN","runners":[{"status":"ACTIVE","sortPriority":1,"id":522741,"name":"1 - 2 / 2 - 1"},{"status":"ACTIVE","sortPriority":2,"id":522743,"name":"1 - 4 / 4 - 1"},{"status":"ACTIVE","sortPriority":3,"id":522745,"name":"1 - 6 / 6 - 1"},{"status":"ACTIVE","sortPriority":4,"id":3805730,"name":"1 - 7 / 7 - 1"},{"status":"ACTIVE","sortPriority":5,"id":3805731,"name":"1 - 8 / 8 - 1"},{"status":"ACTIVE","sortPriority":6,"id":522747,"name":"2 - 4 / 4 - 2"},{"status":"ACTIVE","sortPriority":7,"id":522749,"name":"2 - 6 / 6 - 2"},{"status":"ACTIVE","sortPriority":8,"id":3805736,"name":"2 - 7 / 7 - 2"},{"status":"ACTIVE","sortPriority":9,"id":3805740,"name":"2 - 8 / 8 - 2"},{"status":"ACTIVE","sortPriority":10,"id":522753,"name":"4 - 6 / 6 - 4"},{"status":"ACTIVE","sortPriority":11,"id":3805755,"name":"4 - 7 / 7 - 4"},{"status":"ACTIVE","sortPriority":12,"id":3805762,"name":"4 - 8 / 8 - 4"},{"status":"ACTIVE","sortPriority":13,"id":3805783,"name":"6 - 7 / 7 - 6"},{"status":"ACTIVE","sortPriority":14,"id":3805784,"name":"6 - 8 / 8 - 6"},{"status":"ACTIVE","sortPriority":15,"id":3805793,"name":"7 - 8 / 8 - 7"}],"regulators":["MR_INT"],"venue":"Traralgon","countryCode":"AU","discountAllowed":true,"timezone":"Australia/Sydney","openDate":"2022-03-02T08:31:00.000Z","version":4382480630,"name":"Quinella","eventName":"Traralgon (AUS) 2nd Mar"},"rc":[{"atb":[[8.6,35.11],[19,11.12],[11.5,19.06]],"id":3805784},{"atb":[[8,28.59],[6,53.37],[12.5,17.4]],"id":3805783},{"atb":[[9.2,32.54],[21,10],[13,16.68]],"id":3805793},{"atb":[[7.2,43.04],[9.2,24.41],[15.5,13.8]],"id":3805755},{"atb":[[4.5,57.18],[6,40.03],[3.75,97.05]],"id":3805736},{"atb":[[4,88.95],[5,50.04],[7,33.36]],"id":522747},{"atb":[[3.45,108.93],[3.95,67.85],[5.4,45.49]],"id":522749},{"atb":[[17,12.5],[9.8,22.74],[7.8,39.24]],"id":3805731},{"atb":[[6.4,37.06],[5.2,63.54],[9.4,23.82]],"id":3805730},{"atb":[[9.6,31.03],[23,9.09],[14,15.39]],"id":3805762},{"atb":[[8.6,26.33],[14,15.39],[6.6,47.66]],"id":522753},{"atb":[[3.6,76.98],[3.1,127.08],[4.7,54.09]],"id":522741},{"atb":[[5.6,58.01],[7.2,32.28],[10.5,21.07]],"id":522743},{"atb":[[6.4,37.06],[5.2,63.54],[9.4,23.82]],"id":3805740},{"atb":[[4.8,70.23],[8.6,26.33],[5.8,41.7]],"id":522745}],"con":true,"img":true}]}
{"op":"mcm","clk":"5347848778","pt":1646209002723,"mc":[{"id":"1.195453758","marketDefinition":{"bspMarket":false,"turnInPlayEnabled":false,"persistenceEnabled":false,"marketBaseRate":7.0,"eventId":"31272494","eventTypeId":"4339","numberOfWinners":1,"bettingType":"ODDS","marketType":"QUINELLA","marketTime":"2022-03-02T11:32:00.000Z","suspendTime":"2022-03-02T11:32:00.000Z","bspReconciled":false,"complete":true,"inPlay":false,"crossMatching":false,"runnersVoidable":false,"numberOfActiveRunners":15,"betDelay":0,"status":"OPEN","runners":[{"status":"ACTIVE","sortPriority":1,"id":522741,"name":"1 - 2 / 2 - 1"},{"status":"ACTIVE","sortPriority":2,"id":522743,"name":"1 - 4 / 4 - 1"},{"status":"ACTIVE","sortPriority":3,"id":522745,"name":"1 - 6 / 6 - 1"},{"status":"ACTIVE","sortPriority":4,"id":3805730,"name":"1 - 7 / 7 - 1"},{"status":"ACTIVE","sortPriority":5,"id":3805731,"name":"1 - 8 / 8 - 1"},{"status":"ACTIVE","sortPriority":6,"id":522747,"name":"2 - 4 / 4 - 2"},{"status":"ACTIVE","sortPriority":7,"id":522749,"name":"2 - 6 / 6 - 2"},{"status":"ACTIVE","sortPriority":8,"id":3805736,"name":"2 - 7 / 7 - 2"},{"status":"ACTIVE","sortPriority":9,"id":3805740,"name":"2 - 8 / 8 - 2"},{"status":"ACTIVE","sortPriority":10,"id":522753,"name":"4 - 6 / 6 - 4"},{"status":"ACTIVE","sortPriority":11,"id":3805755,"name":"4 - 7 / 7 - 4"},{"status":"ACTIVE","sortPriority":12,"id":3805762,"name":"4 - 8 / 8 - 4"},{"status":"ACTIVE","sortPriority":13,"id":3805783,"name":"6 - 7 / 7 - 6"},{"status":"ACTIVE","sortPriority":14,"id":3805784,"name":"6 - 8 / 8 - 6"},{"status":"ACTIVE","sortPriority":15,"id":3805793,"name":"7 - 8 / 8 - 7"}],"regulators":["MR_INT"],"venue":"Traralgon","countryCode":"AU","discountAllowed":true,"timezone":"Australia/Sydney","openDate":"2022-03-02T08:31:00.000Z","version":4382480630,"name":"Quinella","eventName":"Traralgon (AUS) 2nd Mar"},"rc":[{"atb":[[8.6,35.1],[19,11.11],[11.5,19.05]],"id":3805784},{"atb":[[8,28.58],[6,53.36],[12.5,17.4]],"id":3805783},{"atb":[[9.2,32.53],[21,10],[13,16.67]],"id":3805793},{"atb":[[7.2,43.03],[9.2,24.4],[15.5,13.79]],"id":3805755},{"atb":[[4.5,57.17],[6,40.02],[3.75,97.02]],"id":3805736},{"atb":[[4,88.93],[5,50.02],[7,33.35]],"id":522747},{"atb":[[3.45,108.9],[3.95,67.83],[5.4,45.48]],"id":522749},{"atb":[[17,12.5],[9.8,22.74],[7.8,39.23]],"id":3805731},{"atb":[[6.4,37.05],[5.2,63.52],[9.4,23.82]],"id":3805730},{"atb":[[9.6,31.02],[23,9.09],[14,15.39]],"id":3805762},{"atb":[[8.6,26.33],[14,15.39],[6.6,47.64]],"id":522753},{"atb":[[3.6,76.96],[3.1,127.05],[4.7,54.08]],"id":522741},{"atb":[[5.6,58],[7.2,32.27],[10.5,21.06]],"id":522743},{"atb":[[6.4,37.05],[5.2,63.52],[9.4,23.82]],"id":3805740},{"atb":[[4.8,70.21],[8.6,26.33],[5.8,41.69]],"id":522745}],"con":true,"img":true}]}
{"op":"mcm","clk":"5348049372","pt":1646213092676,"mc":[{"id":"1.195453758","rc":[{"atb":[[8.6,0],[19,0],[11.5,0]],"id":3805784},{"atb":[[8,0],[6,0],[12.5,0]],"id":3805783},{"atb":[[9.2,0],[21,0],[13,0]],"id":3805793},{"atb":[[7.2,0],[9.2,0],[15.5,0]],"id":3805755},{"atb":[[4.5,0],[6,0],[3.75,0]],"id":3805736},{"atb":[[4,0],[5,0],[7,0]],"id":522747},{"atb":[[3.45,0],[3.95,0],[5.4,0]],"id":522749},{"atb":[[17,0],[9.8,0],[7.8,0]],"id":3805731},{"atb":[[6.4,0],[5.2,0],[9.4,0]],"id":3805730},{"atb":[[9.6,0],[23,0],[14,0]],"id":3805762},{"atb":[[8.6,0],[14,0],[6.6,0]],"id":522753},{"atb":[[3.6,0],[3.1,0],[4.7,0]],"id":522741},{"atb":[[5.6,0],[7.2,0],[10.5,0]],"id":522743},{"atb":[[6.4,0],[5.2,0],[9.4,0]],"id":3805740},{"atb":[[4.8,0],[8.6,0],[5.8,0]],"id":522745}],"con":true,"img":false}]}
{"op":"mcm","clk":"5348049914","pt":1646213102040,"mc":[{"id":"1.195453758","rc":[{"atb":[[8.6,35.05],[19,11.1],[11.5,19.02]],"id":3805784},{"atb":[[8,28.54],[6,53.27],[12.5,17.37]],"id":3805783},{"atb":[[9,33.29],[20,10.51],[12.5,17.37]],"id":3805793},{"atb":[[9,24.97],[7,44.4],[15,14.27]],"id":3805755},{"atb":[[4.6,55.49],[6.2,38.42],[3.8,95.13]],"id":3805736},{"atb":[[7.2,32.22],[5.1,48.72],[4.1,85.93]],"id":522747},{"atb":[[4,66.59],[5.5,44.4],[3.5,106.55]],"id":522749},{"atb":[[16.5,12.88],[9.6,23.23],[7.6,40.36]],"id":3805731},{"atb":[[9.6,30.97],[23,9.07],[14,15.36]],"id":3805762},{"atb":[[6.4,36.99],[5.2,63.42],[9.4,23.78]],"id":3805730},{"atb":[[6.4,49.33],[13.5,15.98],[8.4,26.99]],"id":522753},{"atb":[[3.6,76.84],[3.1,126.85],[4.7,53.99]],"id":522741},{"atb":[[10,22.19],[5.5,59.19],[7,33.29]],"id":522743},{"atb":[[9.6,23.23],[5.3,61.94],[6.6,35.67]],"id":3805740},{"atb":[[4.8,70.1],[8.6,26.29],[5.8,41.62]],"id":522745}],"con":true,"img":false}]}
{"op":"mcm","clk":"5348072487","pt":1646213520464,"mc":[{"id":"1.195453758","rc":[{"atb":[[18,3.26],[21,2.72]],"id":3805784},{"atb":[[10,3.26],[12.5,20.09]],"id":3805783},{"atb":[[19.5,3.26],[24,2.72]],"id":3805793},{"atb":[[11,3.26],[13.5,2.72]],"id":3805755},{"atb":[[6,3.26],[7,2.72]],"id":3805736},{"atb":[[6.4,2.72],[5.7,3.26]],"id":522747},{"atb":[[5.8,2.72],[5.3,3.26]],"id":522749},{"atb":[[16.5,16.15],[19,2.72]],"id":3805731},{"atb":[[18.5,3.26],[22,2.72]],"id":3805762},{"atb":[[9.6,3.26],[11.5,2.72]],"id":3805730},{"atb":[[12,2.72],[9.8,3.26]],"id":522753},{"atb":[[5.2,2.72],[4.7,57.26]],"id":522741},{"atb":[[11,2.72],[9.4,3.26]],"id":522743},{"atb":[[10,3.26],[12.5,2.72]],"id":3805740},{"atb":[[9.2,3.26],[10.5,2.72]],"id":522745}],"con":true,"img":false}]}
{"op":"mcm","clk":"5348115914","pt":1646214246098,"mc":[{"id":"1.195453758","rc":[{"atb":[[18,0],[21,0]],"id":3805784},{"atb":[[10,0],[12.5,17.37]],"id":3805783},{"atb":[[5.2,0],[4.7,53.99]],"id":522741}],"con":true,"img":false}]}
{"op":"mcm","clk":"5348115959","pt":1646214246767,"mc":[{"id":"1.195453758","rc":[{"atb":[[18.5,3.26],[22,2.72]],"id":3805784}],"con":true,"img":false}]}
{"op":"mcm","clk":"5348115963","pt":1646214246868,"mc":[{"id":"1.195453758","rc":[{"atb":[[10.5,3.26],[13,2.72]],"id":3805783},{"atb":[[4.8,3.26],[5.3,2.72]],"id":522741}],"con":true,"img":false}]}
{"op":"mcm","clk":"5348201063","pt":1646215369232,"mc":[{"id":"1.195453758","rc":[{"atb":[[4.8,0],[5.3,0]],"id":522741}],"con":true,"img":false}]}
{"op":"mcm","clk":"5348201105","pt":1646215370004,"mc":[{"id":"1.195453758","rc":[{"atb":[[5.2,2.72],[4.7,57.26]],"id":522741}],"con":true,"img":false}]}
{"op":"mcm","clk":"5348204440","pt":1646215413477,"mc":[{"id":"1.195453758","rc":[{"atb":[[5.2,0],[4.7,53.99]],"id":522741}],"con":true,"img":false}]}
{"op":"mcm","clk":"5348204529","pt":1646215414157,"mc":[{"id":"1.195453758","rc":[{"atb":[[4.8,3.26],[5.3,2.72]],"id":522741}],"con":true,"img":false}]}
{"op":"mcm","clk":"5348341330","pt":1646216655104,"mc":[{"id":"1.195453758","rc":[{"atb":[[4.8,0],[5.3,0]],"id":522741}],"con":true,"img":false}]}
{"op":"mcm","clk":"5348341382","pt":1646216655788,"mc":[{"id":"1.195453758","rc":[{"atb":[[5.2,2.72],[4.7,57.26]],"id":522741}],"con":true,"img":false}]}
{"op":"mcm","clk":"5348350137","pt":1646216748952,"mc":[{"id":"1.195453758","rc":[{"atb":[[6,0],[7,0]],"id":3805736}],"con":true,"img":false}]}
{"op":"mcm","clk":"5348350202","pt":1646216749630,"mc":[{"id":"1.195453758","rc":[{"atb":[[6.8,2.72],[5.9,3.26]],"id":3805736}],"con":true,"img":false}]}
{"op":"mcm","clk":"5348351471","pt":1646216763477,"mc":[{"id":"1.195453758","rc":[{"atb":[[5.2,0],[4.7,53.99]],"id":522741}],"con":true,"img":false}]}
{"op":"mcm","clk":"5348351555","pt":1646216764260,"mc":[{"id":"1.195453758","rc":[{"atb":[[4.8,3.26],[5.3,2.72]],"id":522741}],"con":true,"img":false}]}
{"op":"mcm","clk":"5348385854","pt":1646217138969,"mc":[{"id":"1.195453758","rc":[{"atb":[[7,16.67]],"id":3805784},{"atl":[[740,2]],"id":3805784},{"atb":[[4.1,32.26]],"id":3805783},{"atl":[[460,2]],"id":3805783},{"atb":[[2.7,21.02]],"id":3805793},{"atl":[[930,2]],"id":3805793},{"atb":[[5.6,21.74]],"id":3805755},{"atl":[[540,2]],"id":3805755},{"atb":[[3.05,48.78]],"id":3805736},{"atl":[[270,2]],"id":3805736},{"atb":[[3,50]],"id":522747},{"atl":[[360,2]],"id":522747},{"atb":[[2.56,64.1]],"id":522749},{"atl":[[190,2]],"id":522749},{"atb":[[7.4,15.62]],"id":3805731},{"atl":[[810,2]],"id":3805731},{"atb":[[4.3,30.3]],"id":3805730},{"atl":[[490,2]],"id":3805730},{"atb":[[11,10]],"id":3805762},{"atl":[[940,2]],"id":3805762},{"atb":[[4.1,31.96]],"id":522753},{"atl":[[460,2]],"id":522753},{"atb":[[2.58,63.29]],"id":522741},{"atl":[[75,2]],"id":522741},{"atb":[[3.85,35.09]],"id":522743},{"atl":[[480,2]],"id":522743},{"atb":[[5.3,85.2]],"id":3805740},{"atl":[[530,2]],"id":3805740},{"atb":[[3.45,40.82]],"id":522745},{"atl":[[390,2]],"id":522745}],"con":true,"img":false}]}
{"op":"mcm","clk":"5348389779","pt":1646217184019,"mc":[{"id":"1.195453758","rc":[{"atb":[[6.8,0],[5.9,0]],"id":3805736}],"con":true,"img":false}]}
{"op":"mcm","clk":"5348389849","pt":1646217184706,"mc":[{"id":"1.195453758","rc":[{"atb":[[6,3.26],[7,2.72]],"id":3805736}],"con":true,"img":false}]}
{"op":"mcm","clk":"5348412965","pt":1646217436149,"mc":[{"id":"1.195453758","rc":[{"atb":[[9.2,12.2],[7,0]],"id":3805784},{"atl":[[720,2],[740,0]],"id":3805784},{"atb":[[4.1,0],[4.7,27.03]],"id":3805783},{"atl":[[440,2],[460,0]],"id":3805783},{"atl":[[700,2],[930,0]],"id":3805793},{"atb":[[5.6,0],[4.5,28.57]],"id":3805755},{"atl":[[540,0],[500,2]],"id":3805755},{"atb":[[3.6,38.46],[3.05,0]],"id":3805736},{"atl":[[270,0],[260,2]],"id":3805736},{"atb":[[3,0],[3.5,40]],"id":522747},{"atb":[[2.56,0],[3.1,47.62]],"id":522749},{"atb":[[9,12.5],[7.4,0]],"id":3805731},{"atl":[[600,2],[810,0]],"id":3805731},{"atb":[[4.8,26.32],[4.3,0]],"id":3805730},{"atl":[[410,2],[490,0]],"id":3805730},{"atb":[[11,0],[8.4,13.51]],"id":3805762},{"atl":[[710,2],[940,0]],"id":3805762},{"atb":[[4.1,0],[5.4,22.73]],"id":522753},{"atl":[[440,2],[460,0]],"id":522753},{"atb":[[2.74,57.47],[2.58,0]],"id":522741},{"atl":[[75,0],[60,2]],"id":522741},{"atb":[[3.85,0],[4.4,29.41]],"id":522743},{"atl":[[410,2],[480,0]],"id":522743},{"atb":[[5.3,61.94],[6,20]],"id":3805740},{"atl":[[530,0],[500,2]],"id":3805740},{"atb":[[3.45,0],[3.8,35.71]],"id":522745},{"atl":[[370,2],[390,0]],"id":522745}],"con":true,"img":false}]}
{"op":"mcm","clk":"5348412983","pt":1646217436357,"mc":[{"id":"1.195453758","rc":[{"atl":[[650,2],[700,0]],"id":3805793}],"con":true,"img":false}]}
{"op":"mcm","clk":"5348412990","pt":1646217436414,"mc":[{"id":"1.195453758","rc":[{"atb":[[5.8,0],[5.3,0]],"id":522749}],"con":true,"img":false}]}
{"op":"mcm","clk":"5348413076","pt":1646217437407,"mc":[{"id":"1.195453758","rc":[{"atb":[[5.6,3.26],[6.2,2.72]],"id":522749}],"con":true,"img":false}]}
{"op":"mcm","clk":"5348416112","pt":1646217470204,"mc":[{"id":"1.195453758","rc":[{"atb":[[5.6,21.74]],"id":3805783},{"atb":[[4.5,0]],"id":3805755},{"atl":[[470,2],[500,0]],"id":3805755},{"atl":[[260,0],[230,2]],"id":3805736},{"atb":[[3.1,0],[3.5,146.55]],"id":522749},{"atl":[[560,2],[600,0]],"id":3805731},{"atl":[[410,0]],"id":3805730},{"atb":[[8.4,0]],"id":3805762},{"atb":[[2.74,0],[3.05,48.78]],"id":522741},{"atl":[[380,2],[410,0]],"id":522743},{"atl":[[500,0]],"id":3805740},{"atb":[[4.3,30.3],[3.8,0]],"id":522745}],"con":true,"img":false}]}
{"op":"mcm","clk":"5348416121","pt":1646217470263,"mc":[{"id":"1.195453758","rc":[{"atl":[[670,2],[720,0]],"id":3805784},{"atb":[[4.7,0]],"id":3805783},{"atb":[[5.2,23.81]],"id":3805755},{"atb":[[10.5,10.53]],"id":3805762},{"atl":[[650,2],[710,0]],"id":3805762},{"atl":[[370,2]],"id":3805730},{"atl":[[460,2]],"id":3805740}],"con":true,"img":false}]}
{"op":"mcm","clk":"5348424121","pt":1646217556094,"mc":[{"id":"1.195453758","rc":[{"atl":[[670,0],[690,2]],"id":3805784},{"atl":[[230,0],[240,2]],"id":3805736},{"atl":[[650,0],[680,2]],"id":3805762},{"atl":[[440,0],[450,2]],"id":522753},{"atb":[[2.88,53.19],[3.05,0]],"id":522741}],"con":true,"img":false}]}
{"op":"mcm","clk":"5348449536","pt":1646217817484,"mc":[{"id":"1.195453758","rc":[{"atl":[[640,2],[690,0]],"id":3805784},{"atl":[[430,2],[440,0]],"id":3805783},{"atl":[[630,2],[650,0]],"id":3805793},{"atl":[[460,2],[470,0]],"id":3805755},{"atl":[[220,2],[240,0]],"id":3805736},{"atl":[[640,2],[680,0]],"id":3805762},{"atl":[[430,2],[450,0]],"id":522753},{"atb":[[2.88,0],[3.15,46.51]],"id":522741}],"con":true,"img":false}]}
{"op":"mcm","clk":"5348453671","pt":1646217854880,"mc":[{"id":"1.195453758","rc":[{"atl":[[640,0],[660,2]],"id":3805784},{"atl":[[430,0],[440,2]],"id":3805783},{"atl":[[630,0],[650,2]],"id":3805793},{"atl":[[460,0],[470,2]],"id":3805755},{"atl":[[640,0],[660,2]],"id":3805762},{"atl":[[360,2],[370,0]],"id":3805730},{"atl":[[430,0],[440,2]],"id":522753},{"atl":[[360,2],[370,0]],"id":522745}],"con":true,"img":false}]}
{"op":"mcm","clk":"5348459102","pt":1646217903008,"mc":[{"id":"1.195453758","rc":[{"atl":[[430,2]],"id":3805783},{"atl":[[640,2]],"id":3805762}],"con":true,"img":false}]}
{"op":"mcm","clk":"5348459110","pt":1646217903112,"mc":[{"id":"1.195453758","rc":[{"atl":[[660,0],[640,2]],"id":3805784},{"atl":[[440,0]],"id":3805783},{"atl":[[630,2],[650,0]],"id":3805793},{"atl":[[460,2],[470,0]],"id":3805755},{"atl":[[660,0]],"id":3805762},{"atl":[[430,2],[440,0]],"id":522753}],"con":true,"img":false}]}
{"op":"mcm","clk":"5348473677","pt":1646218023156,"mc":[{"id":"1.195453758","rc":[{"atb":[[8,14.29],[9.2,0]],"id":3805784},{"atb":[[5.6,0],[4.8,26.32]],"id":3805783},{"atb":[[4.8,26.32],[5.4,0]],"id":522753},{"atb":[[6,0],[5.4,22.73]],"id":3805740}],"con":true,"img":false}]}
{"op":"mcm","clk":"5348495121","pt":1646218197386,"mc":[{"id":"1.195453758","rc":[{"atl":[[620,2],[640,0]],"id":3805784},{"atb":[[4.8,0],[5.3,23.26]],"id":3805783},{"atl":[[630,0],[610,2]],"id":3805793},{"atl":[[560,0],[550,2]],"id":3805731},{"atl":[[620,2],[640,0]],"id":3805762},{"atb":[[4.8,0],[5.3,23.26]],"id":522753},{"atl":[[460,0],[450,2]],"id":3805740}],"con":true,"img":false}]}
{"op":"mcm","clk":"5348511708","pt":1646218328077,"mc":[{"id":"1.195453758","rc":[{"atb":[[9,0],[7.8,14.71]],"id":3805731},{"atb":[[9,12.5],[10.5,0]],"id":3805762}],"con":true,"img":false}]}
{"op":"mcm","clk":"5348511850","pt":1646218329380,"mc":[{"id":"1.195453758","rc":[{"atl":[[360,0],[230,2]],"id":522747}],"con":true,"img":false}]}
{"op":"mcm","clk":"5348527019","pt":1646218478382,"mc":[{"id":"1.195453758","rc":[{"atl":[[220,2],[230,0]],"id":522747},{"atb":[[8.8,12.82],[7.8,0]],"id":3805731},{"atb":[[9,0],[10,11.11]],"id":3805762},{"atb":[[4.9,25.64],[4.4,0]],"id":522743}],"con":true,"img":false}]}
{"op":"mcm","clk":"5348559151","pt":1646218829094,"mc":[{"id":"1.195453758","rc":[{"atb":[[18.5,3.27],[8.6,35.05],[19,11.1],[22,2.72],[11.5,19.02]],"id":3805784},{"atb":[[8,28.54],[10.5,3.27],[6,53.28],[12.5,17.37],[13,2.72]],"id":3805783},{"atb":[[9,33.3],[19.5,3.27],[20,10.51],[24,2.72],[12.5,17.37]],"id":3805793},{"atb":[[9,24.97],[11,3.27],[13.5,2.72],[7,44.4],[15,14.27]],"id":3805755},{"atb":[[4.6,55.49],[6.2,38.42],[6,3.27],[3.8,95.14],[7,2.72]],"id":3805736},{"atb":[[7.2,32.22],[5.1,48.73],[6.4,2.72],[4.1,85.93],[5.7,3.27]],"id":522747},{"atb":[[5.6,3.27],[4,66.6],[6.2,2.72],[5.5,44.4],[3.5,146.56]],"id":522749},{"atb":[[16.5,16.15],[9.6,23.23],[19,2.72],[7.6,40.36]],"id":3805731},{"atb":[[9.6,30.97],[18.5,3.27],[22,2.72],[23,9.08],[14,15.36]],"id":3805762},{"atb":[[9.6,3.27],[6.4,37],[11.5,2.72],[5.2,63.42],[9.4,23.78]],"id":3805730},{"atb":[[6.4,49.33],[12,2.72],[9.8,3.27],[13.5,15.98],[8.4,27]],"id":522753},{"atb":[[4.8,3.27],[3.6,76.84],[3.1,126.85],[5.3,2.72],[4.7,54]],"id":522741},{"atb":[[10,22.19],[11,2.72],[5.5,59.19],[7,33.3],[9.4,3.27]],"id":522743},{"atl":[[380,0],[370,2]],"id":522743},{"atb":[[9.6,23.23],[10,3.27],[5.3,61.95],[12.5,2.72],[6.6,35.67]],"id":3805740},{"atb":[[4.8,70.1],[8.6,26.29],[9.2,3.27],[5.8,41.62],[10.5,2.72]],"id":522745}],"con":true,"img":false}]}
{"op":"mcm","clk":"5348566302","pt":1646218905891,"mc":[{"id":"1.195453758","rc":[{"atl":[[360,2],[370,0]],"id":522743}],"con":true,"img":false}]}
{"op":"mcm","clk":"5348570165","pt":1646218936118,"mc":[{"id":"1.195453758","rc":[{"atb":[[2.96,21.02],[2.7,0]],"id":3805793},{"atl":[[180,2],[190,0]],"id":522749}],"con":true,"img":false}]}
{"op":"mcm","clk":"5348599284","pt":1646219195223,"mc":[{"id":"1.195453758","rc":[{"atb":[[19.5,0],[24,0]],"id":3805793},{"atb":[[11,0],[13.5,0]],"id":3805755},{"atb":[[6,0],[7,0]],"id":3805736},{"atb":[[6.4,0],[5.7,0]],"id":522747},{"atb":[[16.5,12.88],[19,0]],"id":3805731},{"atb":[[18.5,0],[22,0]],"id":3805762},{"atb":[[12,0],[9.8,0]],"id":522753},{"atb":[[4.8,0],[5.3,0]],"id":522741},{"atb":[[11,0],[9.4,0]],"id":522743},{"atb":[[10,0],[12.5,0]],"id":3805740}],"con":true,"img":false}]}
{"op":"mcm","clk":"5348599360","pt":1646219195963,"mc":[{"id":"1.195453758","rc":[{"atb":[[20,13.78],[25,2.72]],"id":3805793},{"atb":[[12,3.27],[14.5,2.72]],"id":3805755},{"atb":[[7.2,2.72],[6.2,41.69]],"id":3805736},{"atb":[[6,3.27],[7,2.72]],"id":522747},{"atb":[[17,3.27],[19.5,2.72]],"id":3805731},{"atb":[[19.5,3.27],[24,2.72]],"id":3805762},{"atb":[[10.5,3.27],[13,2.72]],"id":522753},{"atb":[[4.9,3.27],[5.4,2.72]],"id":522741},{"atb":[[9.6,3.27],[11.5,2.72]],"id":522743},{"atb":[[10.5,3.27],[13,2.72]],"id":3805740}],"con":true,"img":false}]}
{"op":"mcm","clk":"5348614977","pt":1646219324344,"mc":[{"id":"1.195453758","rc":[{"atb":[[5.3,0],[4.4,29.41]],"id":522753}],"con":true,"img":false}]}
{"op":"mcm","clk":"5348618701","pt":1646219354891,"mc":[{"id":"1.195453758","rc":[{"atb":[[8,0],[9,12.5]],"id":3805784},{"atb":[[4.4,0]],"id":522753},{"atb":[[5.9,20.41]],"id":3805740}],"con":true,"img":false}]}
{"op":"mcm","clk":"5348618713","pt":1646219354991,"mc":[{"id":"1.195453758","rc":[{"atb":[[5.3,23.26]],"id":522753}],"con":true,"img":false}]}
{"op":"mcm","clk":"5348618724","pt":1646219355099,"mc":[{"id":"1.195453758","rc":[{"atb":[[5.4,0]],"id":3805740}],"con":true,"img":false}]}
{"op":"mcm","clk":"5348650166","pt":1646219622797,"mc":[{"id":"1.195453758","rc":[{"atb":[[5.3,0],[4.4,29.41]],"id":522753},{"atb":[[5.2,23.81],[5.9,0]],"id":3805740}],"con":true,"img":false}]}
{"op":"mcm","clk":"5348650608","pt":1646219627088,"mc":[{"id":"1.195453758","rc":[{"atl":[[170,2],[180,0]],"id":522749}],"con":true,"img":false}]}
{"op":"mcm","clk":"5348651496","pt":1646219634941,"mc":[{"id":"1.195453758","rc":[{"atb":[[5.8,20.83],[5.2,0]],"id":3805740}],"con":true,"img":false}]}
{"op":"mcm","clk":"5348670462","pt":1646219798120,"mc":[{"id":"1.195453758","rc":[{"atl":[[160,2],[170,0]],"id":522749}],"con":true,"img":false}]}
{"op":"mcm","clk":"5348689576","pt":1646219879585,"mc":[{"id":"1.195453758","rc":[{"atb":[[8.6,0],[19,0],[11.5,0]],"id":3805784},{"atb":[[8,0],[6,0],[12.5,0]],"id":3805783},{"atb":[[9,0],[20,3.27],[12.5,0]],"id":3805793},{"atb":[[9,0],[7,0],[15,0]],"id":3805755},{"atb":[[4.6,0],[6.2,3.27],[3.8,0]],"id":3805736},{"atb":[[7.2,0],[5.1,0],[4.1,0]],"id":522747},{"atb":[[4,0],[5.5,0],[3.5,40]],"id":522749},{"atb":[[16.5,0],[9.6,0],[7.6,0]],"id":3805731},{"atb":[[9.6,0],[23,0],[14,0]],"id":3805762},{"atb":[[6.4,0],[5.2,0],[9.4,0]],"id":3805730},{"atb":[[6.4,0],[13.5,0],[8.4,0]],"id":522753},{"atb":[[3.6,0],[3.1,0],[4.7,0]],"id":522741},{"atb":[[10,0],[5.5,0],[7,0]],"id":522743},{"atb":[[9.6,0],[5.3,0],[6.6,0]],"id":3805740},{"atb":[[4.8,0],[8.6,0],[5.8,0]],"id":522745}],"con":true,"img":false}]}
{"op":"mcm","clk":"5348690076","pt":1646219883170,"mc":[{"id":"1.195453758","rc":[{"atb":[[5.3,61.95],[11.5,12.68],[6.6,47.57]],"id":3805784},{"atb":[[8,19.02],[4,88.79],[5,66.6]],"id":3805783},{"atb":[[5.5,59.19],[12.5,11.58],[7,44.4]],"id":3805793},{"atb":[[9,16.65],[4.5,76.11],[5.5,59.19]],"id":3805755},{"atb":[[2.92,138.75],[4.6,37],[3.3,115.82]],"id":3805736},{"atb":[[5.1,32.48],[3.55,104.47],[3.05,129.95]],"id":522747},{"atb":[[4,44.4],[2.8,148],[3,133.2]],"id":522749},{"atb":[[9.6,15.48],[4.8,70.1],[5.8,55.49]],"id":3805731},{"atb":[[3.6,102.46],[6.4,24.66],[4.2,83.25]],"id":3805730},{"atb":[[5.8,55.49],[7.6,40.36],[14,10.24]],"id":3805762},{"atb":[[5.2,63.42],[8.4,18],[4.2,83.25]],"id":522753},{"atb":[[3.6,51.23],[2.64,162.44],[2.84,144.78]],"id":522741},{"atb":[[4.5,76.11],[7,22.19],[3.75,96.87]],"id":522743},{"atb":[[4.3,80.72],[6.6,23.78],[3.65,100.52]],"id":3805740},{"atb":[[5.8,27.75],[3.4,111],[3.9,91.86]],"id":522745}],"con":true,"img":false}]}
{"op":"mcm","clk":"5348719290","pt":1646220112290,"mc":[{"id":"1.195453758","rc":[{"atl":[[140,2],[160,0]],"id":522749}],"con":true,"img":false}]}
{"op":"mcm","clk":"5348720494","pt":1646220121482,"mc":[{"id":"1.195453758","rc":[{"atb":[[34,4.95],[23,7.2],[28,9.9]],"id":3805784},{"atl":[[70,4.95],[610,0.26],[90,9.9]],"id":3805784},{"atb":[[8,27.94],[12.5,9.9],[13,11.64],[14.5,4.95]],"id":3805783},{"atl":[[25,4.95],[420,0.37],[450,2.73],[29,9.9]],"id":3805783},{"atb":[[12.5,20.49],[26,6.34]],"id":3805793},{"atl":[[600,0.26],[630,1.95]],"id":3805793},{"atb":[[9,25.56],[12.5,9.9],[14.5,16.59]],"id":3805755},{"atl":[[32,9.9],[27,4.95],[450,0.35],[480,2.56]],"id":3805755},{"atb":[[6.8,4.95],[6,9.9]],"id":3805736},{"atl":[[10.5,4.95],[12.5,9.9]],"id":3805736},{"atb":[[5.6,9.9],[6,8.22]],"id":522747},{"atl":[[10.5,4.95],[12.5,9.9],[210,0.75]],"id":522747},{"atb":[[4,52.51],[6.2,10.84],[5.5,9.9],[5.9,4.95]],"id":522749},{"atl":[[130,1.23],[160,7.7],[10.5,4.95],[12.5,9.9]],"id":522749},{"atb":[[9.6,24.4],[20,8.34]],"id":3805731},{"atl":[[540,0.29],[570,2.15]],"id":3805731},{"atb":[[25,6.6],[26,9.9],[30,4.95]],"id":3805762},{"atl":[[75,4.95],[610,0.26],[95,9.9]],"id":3805762},{"atl":[[350,0.45]],"id":3805730},{"atb":[[13,11.64]],"id":522753},{"atl":[[420,0.37]],"id":522753},{"atb":[[3.6,60.14]],"id":522741},{"atl":[[70,8.91],[55,2.93]],"id":522741},{"atb":[[11.5,11.64],[7,31.11]],"id":522743},{"atl":[[350,0.45],[380,3.23]],"id":522743},{"atb":[[11.5,9.9],[13,11.64],[13.5,4.95],[6.6,32.7]],"id":3805740},{"atl":[[32,9.9],[27,4.95],[440,0.35],[470,2.61]],"id":3805740},{"atb":[[5.8,36.66],[10.5,11.64]],"id":522745},{"atl":[[350,0.45],[380,3.23]],"id":522745}],"con":true,"img":false}]}
{"op":"mcm","clk":"5348720510","pt":1646220121595,"mc":[{"id":"1.195453758","rc":[{"atb":[[11.5,21.6]],"id":3805784},{"atl":[[640,1.91]],"id":3805784},{"atb":[[26,16.25],[30,4.95]],"id":3805793},{"atl":[[75,4.95],[95,9.9]],"id":3805793},{"atb":[[7.2,11.64],[4.6,45.91]],"id":3805736},{"atl":[[210,0.75],[240,5.13]],"id":3805736},{"atb":[[5.1,41.4]],"id":522747},{"atl":[[240,5.13]],"id":522747},{"atb":[[24,9.9],[28,4.95]],"id":3805731},{"atl":[[65,4.95],[85,9.9]],"id":3805731},{"atb":[[14,19.16]],"id":3805762},{"atl":[[640,1.91]],"id":3805762},{"atb":[[9.6,13.17],[6.4,33.58],[11,4.95]],"id":3805730},{"atl":[[22,4.95],[380,3.23],[26,9.9]],"id":3805730},{"atb":[[11.5,9.9],[13.5,4.95],[8.4,26.91]],"id":522753},{"atl":[[24,4.95],[28,9.9],[450,2.73]],"id":522753},{"atb":[[5,4.95],[4.6,9.9]],"id":522741},{"atl":[[8.2,9.9],[7.4,4.95]],"id":522741},{"atb":[[10.5,4.95],[9.4,9.9]],"id":522743},{"atl":[[19.5,4.95],[23,9.9]],"id":522743},{"atb":[[9.6,9.9],[11,4.95]],"id":522745},{"atl":[[18.5,4.95],[21,9.9]],"id":522745}],"con":true,"img":false}]}
{"op":"mcm","clk":"5348720523","pt":1646220121681,"mc":[{"id":"1.195453758","rc":[{"atl":[[260,2],[620,0]],"id":3805784},{"atl":[[80,2],[430,0]],"id":3805783},{"atl":[[610,0],[620,2]],"id":3805793},{"atl":[[85,2],[460,0]],"id":3805755},{"atl":[[25,4.17],[220,0]],"id":3805736},{"atl":[[25,4.17],[220,0]],"id":522747},{"atl":[[140,0],[17,6.25]],"id":522749},{"atl":[[550,0],[560,2]],"id":3805731},{"atl":[[620,0],[250,2]],"id":3805762},{"atl":[[360,0],[370,2]],"id":522743},{"atl":[[75,2],[450,0]],"id":3805740},{"atl":[[360,0],[370,2]],"id":522745}],"con":true,"img":false}]}
{"op":"mcm","clk":"5348720539","pt":1646220121795,"mc":[{"id":"1.195453758","rc":[{"atl":[[360,0],[55,2]],"id":3805730},{"atl":[[70,2],[430,0]],"id":522753},{"atl":[[12,9.09],[60,0]],"id":522741}],"con":true,"img":false}]}
{"op":"mcm","clk":"5348720577","pt":1646220122089,"mc":[{"id":"1.195453758","rc":[{"atb":[[9,0],[12.5,8.7]],"id":3805784},{"atb":[[6.4,18.52],[5.3,0]],"id":3805783},{"atb":[[7,16.67]],"id":3805755},{"atb":[[3.6,0],[4.3,30.3]],"id":3805736},{"atb":[[3.95,33.9],[3.5,0]],"id":522749},{"atb":[[6.8,17.24]],"id":3805730},{"atb":[[10,0],[15.5,6.9]],"id":3805762},{"atb":[[6.2,19.23]],"id":522753},{"atb":[[4.9,0]],"id":522743},{"atb":[[4.3,0],[5.5,22.22]],"id":522745}],"con":true,"img":false}]}
{"op":"mcm","clk":"5348720588","pt":1646220122166,"mc":[{"id":"1.195453758","rc":[{"atb":[[5.2,0]],"id":3805755},{"atb":[[4,33.33],[3.5,0]],"id":522747},{"atb":[[11.5,9.52],[8.8,0]],"id":3805731},{"atb":[[4.8,0]],"id":3805730},{"atb":[[4.4,0]],"id":522753},{"atb":[[3.8,35.71],[3.15,0]],"id":522741},{"atb":[[5.8,20.83]],"id":522743},{"atb":[[8,14.29],[5.8,0]],"id":3805740}],"con":true,"img":false}]}
{"op":"mcm","clk":"5348720627","pt":1646220122485,"mc":[{"id":"1.195453758","rc":[{"atb":[[9.6,3.27],[10.5,4.95],[11,0],[9.4,9.9]],"id":3805730}],"con":true,"img":false}]}
{"op":"mcm","clk":"5348721238","pt":1646220127478,"mc":[{"id":"1.195453758","rc":[{"atl":[[10.5,0],[11,4.95],[12.5,0],[13,9.9]],"id":522749}],"con":true,"img":false}]}
{"op":"mcm","clk":"5348722481","pt":1646220137218,"mc":[{"id":"1.195453758","rc":[{"atb":[[14.5,16.69]],"id":3805783},{"atl":[[25,11.55]],"id":3805783},{"atl":[[600,2.38],[630,0]],"id":3805793},{"atb":[[9,16.65]],"id":3805755},{"atb":[[5.6,19.92],[4,44.4]],"id":522749},{"atl":[[16.5,10.22]],"id":522749},{"atb":[[9.6,15.48]],"id":3805731},{"atl":[[22,12.5]],"id":3805730},{"atb":[[32,5.11]],"id":3805762},{"atl":[[24,11.84]],"id":522753},{"atl":[[7.4,19.66]],"id":522741},{"atb":[[7,22.19]],"id":522743},{"atl":[[19.5,13.52],[350,4.09],[380,0]],"id":522743},{"atb":[[9.6,31.99]],"id":522745},{"atl":[[18.5,14.01]],"id":522745}],"con":true,"img":false}]}
{"op":"mcm","clk":"5348722491","pt":1646220137316,"mc":[{"id":"1.195453758","rc":[{"atb":[[34,9.76],[23,25.27],[11.5,12.68]],"id":3805784},{"atl":[[260,6.91],[70,7.25],[640,0]],"id":3805784},{"atb":[[8,19.02],[12.5,31.99]],"id":3805783},{"atl":[[80,17.97],[450,0]],"id":3805783},{"atb":[[25,17.44],[12.5,11.58],[30,10.42]],"id":3805793},{"atl":[[75,7.09]],"id":3805793},{"atb":[[12,25.35]],"id":3805755},{"atl":[[85,17.03],[27,11.05],[480,0]],"id":3805755},{"atb":[[4.6,37],[6.2,17.98]],"id":3805736},{"atl":[[10.5,19.66],[240,0]],"id":3805736},{"atb":[[5.6,29.48],[5.1,32.48]],"id":522747},{"atl":[[10.5,21.64],[25,23.74],[240,0]],"id":522747},{"atl":[[160,0]],"id":522749},{"atb":[[20,28.1],[28,10.82]],"id":3805731},{"atl":[[65,7.43],[540,2.65],[570,0]],"id":3805731},{"atb":[[25,23.79],[14,10.24]],"id":3805762},{"atl":[[75,7.09],[640,0],[250,7.1]],"id":3805762},{"atb":[[9.6,15.48],[6.4,24.66]],"id":3805730},{"atl":[[380,0],[55,14.21]],"id":3805730},{"atb":[[13.5,17.63],[8.4,18]],"id":522753},{"atl":[[70,20.26],[450,0]],"id":522753},{"atb":[[3.6,51.23],[4.9,17.98]],"id":522741},{"atl":[[70,0]],"id":522741},{"atb":[[9.6,17.98]],"id":522743},{"atb":[[11.5,31.99],[13.5,17.63],[6.6,23.78]],"id":3805740},{"atl":[[75,19.04],[27,11.05],[470,0]],"id":3805740},{"atb":[[5.8,27.75],[11,20.8]],"id":522745},{"atl":[[350,4.09],[380,0]],"id":522745}],"con":true,"img":false}]}
{"op":"mcm","clk":"5348722504","pt":1646220137381,"mc":[{"id":"1.195453758","rc":[{"atl":[[25,18.88]],"id":3805736},{"atl":[[12,23.8]],"id":522741},{"atl":[[44,2.33],[370,0]],"id":522743},{"atl":[[40,2.56],[370,0]],"id":522745}],"con":true,"img":false}]}
{"op":"mcm","clk":"5348722514","pt":1646220137477,"mc":[{"id":"1.195453758","rc":[{"atl":[[17,22.9]],"id":522749}],"con":true,"img":false}]}
{"op":"mcm","clk":"5348722564","pt":1646220137897,"mc":[{"id":"1.195453758","rc":[{"atb":[[13,2.72]],"id":3805783},{"atl":[[350,3.64]],"id":522743},{"atl":[[350,3.64]],"id":522745}],"con":true,"img":false}]}
{"op":"mcm","clk":"5348722577","pt":1646220138008,"mc":[{"id":"1.195453758","rc":[{"atb":[[23,18.07]],"id":3805784},{"atl":[[610,0]],"id":3805784},{"atl":[[420,0]],"id":3805783},{"atl":[[600,2.12]],"id":3805793},{"atl":[[450,0]],"id":3805755},{"atl":[[210,0]],"id":3805736},{"atl":[[210,0]],"id":522747},{"atl":[[130,0]],"id":522749},{"atl":[[540,2.35]],"id":3805731},{"atl":[[350,0]],"id":3805730},{"atb":[[25,17.18]],"id":3805762},{"atl":[[420,0]],"id":522753},{"atl":[[55,0]],"id":522741},{"atb":[[13,2.72]],"id":3805740},{"atl":[[440,0]],"id":3805740},{"atb":[[10.5,2.72]],"id":522745}],"con":true,"img":false}]}
{"op":"mcm","clk":"5348722592","pt":1646220138106,"mc":[{"id":"1.195453758","rc":[{"atb":[[26,9.9]],"id":3805793},{"atb":[[20,19.75],[28,4.95]],"id":3805731},{"atl":[[610,0]],"id":3805762},{"atb":[[11.5,31.99],[13,2.72]],"id":522753}],"con":true,"img":false}]}
{"op":"mcm","clk":"5348722703","pt":1646220138887,"mc":[{"id":"1.195453758","rc":[{"atb":[[25,6.6]],"id":3805731}],"con":true,"img":false}]}
{"op":"mcm","clk":"5348724291","pt":1646220151399,"mc":[{"id":"1.195453758","rc":[{"atb":[[11.5,17.82]],"id":3805730}],"con":true,"img":false}]}
{"op":"mcm","clk":"5348724451","pt":1646220152635,"mc":[{"id":"1.195453758","rc":[{"atl":[[10.5,16.68]],"id":522749},{"atb":[[25,0]],"id":3805762},{"atl":[[350,0],[44,32.37]],"id":522743},{"atl":[[40,35.62],[350,0]],"id":522745}],"con":true,"img":false}]}
{"op":"mcm","clk":"5348724465","pt":1646220152704,"mc":[{"id":"1.195453758","rc":[{"atb":[[20,0],[24,30.77]],"id":3805731},{"atb":[[26,31.02]],"id":3805762}],"con":true,"img":false}]}
{"op":"mcm","clk":"5348724492","pt":1646220152925,"mc":[{"id":"1.195453758","rc":[{"atl":[[16.5,40.16],[17,6.25]],"id":522749},{"atb":[[28,10.82]],"id":3805731}],"con":true,"img":false}]}
{"op":"mcm","clk":"5348724554","pt":1646220153470,"mc":[{"id":"1.195453758","rc":[{"atl":[[16.5,29.93]],"id":522749}],"con":true,"img":false}]}
{"op":"mcm","clk":"5348724583","pt":1646220153628,"mc":[{"id":"1.195453758","rc":[{"atb":[[25,0],[28,4.95]],"id":3805731}],"con":true,"img":false}]}
{"op":"mcm","clk":"5348724680","pt":1646220154318,"mc":[{"id":"1.195453758","rc":[{"atb":[[25,6.6]],"id":3805731}],"con":true,"img":false}]}
{"op":"mcm","clk":"5348724790","pt":1646220155343,"mc":[{"id":"1.195453758","rc":[{"atb":[[18.5,0],[22,0]],"id":3805784},{"atb":[[20,0],[25,14.71]],"id":3805793},{"atb":[[7.2,8.91],[6.2,14.71]],"id":3805736},{"atb":[[6,4.95],[7,0]],"id":522747},{"atb":[[17,0],[19.5,0]],"id":3805731},{"atb":[[4.9,14.71],[5.4,0]],"id":522741}],"con":true,"img":false}]}
{"op":"mcm","clk":"5348724828","pt":1646220155615,"mc":[{"id":"1.195453758","rc":[{"atb":[[19.5,0],[24,0]],"id":3805762}],"con":true,"img":false}]}
{"op":"mcm","clk":"5348724854","pt":1646220155827,"mc":[{"id":"1.195453758","rc":[{"atb":[[5.6,9.9],[6,36.66]],"id":522747}],"con":true,"img":false}]}
{"op":"mcm","clk":"5348724866","pt":1646220155930,"mc":[{"id":"1.195453758","rc":[{"atb":[[5.1,99.95]],"id":522747},{"atb":[[5,41.56],[4.6,46.51],[4.9,0]],"id":522741}],"con":true,"img":false}]}
{"op":"mcm","clk":"5348724877","pt":1646220156032,"mc":[{"id":"1.195453758","rc":[{"atb":[[19,3.27],[23,20.79]],"id":3805784},{"atb":[[21,3.27],[26,12.63]],"id":3805793},{"atb":[[6,13.17],[7,2.72]],"id":3805736},{"atb":[[6.8,2.72],[5.9,3.27]],"id":522747},{"atb":[[17.5,3.27],[20,2.72]],"id":3805731},{"atb":[[5.2,2.72],[4.7,3.27]],"id":522741}],"con":true,"img":false}]}
{"op":"mcm","clk":"5348724913","pt":1646220156338,"mc":[{"id":"1.195453758","rc":[{"atb":[[20,3.27],[25,2.72]],"id":3805762}],"con":true,"img":false}]}
{"op":"mcm","clk":"5348724938","pt":1646220156541,"mc":[{"id":"1.195453758","rc":[{"atb":[[6.2,0],[6.8,32.94]],"id":3805736}],"con":true,"img":false}]}
{"op":"mcm","clk":"5348726389","pt":1646220168135,"mc":[{"id":"1.195453758","rc":[{"atl":[[16.5,0],[13,40.75]],"id":522749},{"atb":[[28,10.82]],"id":3805731}],"con":true,"img":false}]}
{"op":"mcm","clk":"5348726518","pt":1646220169031,"mc":[{"id":"1.195453758","rc":[{"atb":[[25,0],[28,4.95]],"id":3805731}],"con":true,"img":false}]}
{"op":"mcm","clk":"5348726577","pt":1646220169546,"mc":[{"id":"1.195453758","rc":[{"atb":[[20,21.12],[24,9.9]],"id":3805731}],"con":true,"img":false}]}
{"op":"mcm","clk":"5348726609","pt":1646220169850,"mc":[{"id":"1.195453758","rc":[{"atb":[[25,6.6]],"id":3805731}],"con":true,"img":false}]}
{"op":"mcm","clk":"5348726740","pt":1646220170950,"mc":[{"id":"1.195453758","rc":[{"atb":[[5.1,32.48],[5.9,50.16]],"id":522747},{"atb":[[4.6,9.9],[5.2,36.54],[4.7,47.23]],"id":522741}],"con":true,"img":false}]}
{"op":"mcm","clk":"5348726831","pt":1646220171655,"mc":[{"id":"1.195453758","rc":[{"atb":[[5,4.95]],"id":522741}],"con":true,"img":false}]}
{"op":"mcm","clk":"5348727079","pt":1646220173566,"mc":[{"id":"1.195453758","rc":[{"atb":[[5.3,0],[11.5,0],[6.6,0]],"id":3805784},{"atb":[[8,0],[4,0],[5,0]],"id":3805783},{"atb":[[5.5,0],[12.5,0],[7,0]],"id":3805793},{"atb":[[9,0],[4.5,0],[5.5,0]],"id":3805755},{"atb":[[2.92,0],[4.6,0],[3.3,0]],"id":3805736},{"atb":[[5.1,0],[3.55,0],[3.05,0]],"id":522747},{"atb":[[4,0],[2.8,0],[3,0]],"id":522749},{"atb":[[9.6,0],[4.8,0],[5.8,0]],"id":3805731},{"atb":[[5.8,0],[7.6,0],[14,0]],"id":3805762},{"atb":[[3.6,0],[6.4,0],[4.2,0]],"id":3805730},{"atb":[[5.2,0],[8.4,0],[4.2,0]],"id":522753},{"atb":[[3.6,0],[2.64,0],[2.84,0]],"id":522741},{"atb":[[4.5,0],[7,0],[3.75,0]],"id":522743},{"atb":[[4.3,0],[6.6,0],[3.65,0]],"id":3805740},{"atb":[[5.8,0],[3.4,0],[3.9,0]],"id":522745}],"con":true,"img":false}]}
{"op":"mcm","clk":"5348727514","pt":1646220177065,"mc":[{"id":"1.195453758","rc":[{"atb":[[5.2,33.82],[4.7,43.96]],"id":522741}],"con":true,"img":false}]}
{"op":"mcm","clk":"5348727593","pt":1646220177655,"mc":[{"id":"1.195453758","rc":[{"atb":[[10.5,0],[13,0]],"id":3805783}],"con":true,"img":false}]}
{"op":"mcm","clk":"5348727616","pt":1646220177857,"mc":[{"id":"1.195453758","rc":[{"atb":[[5.1,2.72],[4.6,13.17]],"id":522741}],"con":true,"img":false}]}
{"op":"mcm","clk":"5348727653","pt":1646220178167,"mc":[{"id":"1.195453758","rc":[{"atb":[[6.4,70.06],[12.5,9.9]],"id":3805783}],"con":true,"img":false}]}
{"op":"mcm","clk":"5348727706","pt":1646220178553,"mc":[{"id":"1.195453758","rc":[{"atb":[[11,3.27],[13.5,2.72]],"id":3805783}],"con":true,"img":false}]}
{"op":"mcm","clk":"5348728018","pt":1646220181366,"mc":[{"id":"1.195453758","rc":[{"atb":[[12.5,0],[13,9.9],[14.5,11.74],[15,4.95]],"id":3805783},{"atl":[[9.6,4.95],[10.5,16.68],[11,9.9],[12.5,0]],"id":522747},{"atl":[[11,0],[11.5,9.9],[9.8,4.95],[13,30.84]],"id":522749},{"atb":[[10.5,0],[11.5,22.78],[9.8,9.9],[9.4,0]],"id":3805730},{"atl":[[8.2,0],[7.4,14.71]],"id":522741}],"con":true,"img":false}]}
{"op":"mcm","clk":"5348728044","pt":1646220181570,"mc":[{"id":"1.195453758","rc":[{"atl":[[8,9.9],[7.2,4.95]],"id":522741}],"con":true,"img":false}]}
{"op":"mcm","clk":"5348728072","pt":1646220181777,"mc":[{"id":"1.195453758","rc":[{"atb":[[15.5,10.93]],"id":3805783},{"atl":[[11,49.44]],"id":522747},{"atl":[[12,14.71],[9.8,11.36]],"id":522741}],"con":true,"img":false}]}
{"op":"mcm","clk":"5348728082","pt":1646220181887,"mc":[{"id":"1.195453758","rc":[{"atl":[[9.6,23.39],[25,4.17]],"id":522747},{"atl":[[9.8,22.97]],"id":522749},{"atl":[[7.8,43.75]],"id":522741}],"con":true,"img":false}]}
{"op":"mcm","clk":"5348728093","pt":1646220181948,"mc":[{"id":"1.195453758","rc":[{"atl":[[12,0]],"id":522741}],"con":true,"img":false}]}
{"op":"mcm","clk":"5348728105","pt":1646220182047,"mc":[{"id":"1.195453758","rc":[{"atl":[[7,22.08]],"id":522741}],"con":true,"img":false}]}
{"op":"mcm","clk":"5348728166","pt":1646220182563,"mc":[{"id":"1.195453758","rc":[{"atb":[[14.5,0]],"id":3805783}],"con":true,"img":false}]}
{"op":"mcm","clk":"5348728176","pt":1646220182666,"mc":[{"id":"1.195453758","rc":[{"atl":[[10.5,0]],"id":522747},{"atl":[[10.5,0]],"id":522749}],"con":true,"img":false}]}
{"op":"mcm","clk":"5348728198","pt":1646220182880,"mc":[{"id":"1.195453758","rc":[{"atl":[[7.4,0]],"id":522741}],"con":true,"img":false}]}
{"op":"mcm","clk":"5348728233","pt":1646220183190,"mc":[{"id":"1.195453758","rc":[{"atl":[[11.5,50.82],[13,0]],"id":522749},{"atb":[[28,10.82]],"id":3805731}],"con":true,"img":false}]}
{"op":"mcm","clk":"5348728329","pt":1646220183868,"mc":[{"id":"1.195453758","rc":[{"atb":[[24,0],[25,9.9],[28,0],[29,4.95]],"id":3805731}],"con":true,"img":false}]}
{"op":"mcm","clk":"5348728353","pt":1646220184080,"mc":[{"id":"1.195453758","rc":[{"atl":[[11.5,9.9]],"id":522749}],"con":true,"img":false}]}
{"op":"mcm","clk":"5348728378","pt":1646220184287,"mc":[{"id":"1.195453758","rc":[{"atb":[[20,2.72],[24,25.77]],"id":3805731}],"con":true,"img":false}]}
{"op":"mcm","clk":"5348728391","pt":1646220184388,"mc":[{"id":"1.195453758","rc":[{"atb":[[29,10.61]],"id":3805731}],"con":true,"img":false}]}
{"op":"mcm","clk":"5348728545","pt":1646220185755,"mc":[{"id":"1.195453758","rc":[{"atb":[[4.7,0]],"id":522741}],"con":true,"img":false}]}
{"op":"mcm","clk":"5348728555","pt":1646220185861,"mc":[{"id":"1.195453758","rc":[{"atb":[[5,45.14]],"id":522741}],"con":true,"img":false}]}
{"op":"mcm","clk":"5348728638","pt":1646220186557,"mc":[{"id":"1.195453758","rc":[{"atb":[[24,35.68],[25,0],[28,4.95],[29,0]],"id":3805731}],"con":true,"img":false}]}
{"op":"mcm","clk":"5348728722","pt":1646220187275,"mc":[{"id":"1.195453758","rc":[{"atb":[[6.4,49.33],[11,13.32],[5.2,63.42]],"id":3805784},{"atb":[[4.8,70.1],[7.6,20.18],[3.9,91.86]],"id":3805783},{"atb":[[5.5,59.19],[12.5,11.58],[7,44.4]],"id":3805793},{"atb":[[8.8,17.07],[4.4,78.35],[5.4,60.54]],"id":3805755},{"atb":[[3.2,121.09],[2.88,141.7],[4.4,39.17]],"id":3805736},{"atb":[[3.45,108.73],[4.9,34.15],[2.98,134.54]],"id":522747},{"atb":[[3.9,45.93],[2.96,135.92],[2.76,151.36]],"id":522749},{"atb":[[5.1,64.97],[10.5,14.02],[6.2,51.23],[25,6.6]],"id":3805731},{"atb":[[3.7,98.67],[6.8,40.2],[4.4,78.35]],"id":3805730},{"atb":[[7.4,41.62],[13.5,10.65],[5.7,56.68]],"id":3805762},{"atb":[[5.1,64.97],[8.2,18.49],[4.1,85.93]],"id":522753},{"atb":[[2.9,140.21],[3.75,48.43],[2.7,156.7]],"id":522741},{"atb":[[4.8,70.1],[7.6,20.18],[3.9,91.86]],"id":522743},{"atb":[[6.2,25.61],[4.1,85.93],[3.55,104.47]],"id":3805740},{"atb":[[4,88.79],[6,26.64],[3.5,106.56]],"id":522745}],"con":true,"img":false}]}
{"op":"mcm","clk":"5348728784","pt":1646220187787,"mc":[{"id":"1.195453758","rc":[{"atl":[[23,4.95],[24,6.89],[27,9.9],[28,0]],"id":522753}],"con":true,"img":false}]}
{"op":"mcm","clk":"5348728829","pt":1646220188165,"mc":[{"id":"1.195453758","rc":[{"atl":[[70,2],[27,34.88]],"id":522753}],"con":true,"img":false}]}
{"op":"mcm","clk":"5348728843","pt":1646220188270,"mc":[{"id":"1.195453758","rc":[{"atl":[[23,12.15]],"id":522753}],"con":true,"img":false}]}
{"op":"mcm","clk":"5348728920","pt":1646220188986,"mc":[{"id":"1.195453758","rc":[{"atl":[[11,9.9],[25,61.17]],"id":522747},{"atl":[[24,0]],"id":522753}],"con":true,"img":false}]}
{"op":"mcm","clk":"5348729142","pt":1646220190988,"mc":[{"id":"1.195453758","rc":[{"atl":[[25,0],[26,4.95],[29,0],[30,9.9]],"id":3805783},{"atl":[[23,0],[24,4.95],[27,24.97],[28,9.9]],"id":522753}],"con":true,"img":false}]}
{"op":"mcm","clk":"5348729178","pt":1646220191290,"mc":[{"id":"1.195453758","rc":[{"atb":[[5.2,0]],"id":522741}],"con":true,"img":false}]}
{"op":"mcm","clk":"5348729233","pt":1646220191674,"mc":[{"id":"1.195453758","rc":[{"atl":[[27,31.07]],"id":522753}],"con":true,"img":false}]}
{"op":"mcm","clk":"5348729249","pt":1646220191766,"mc":[{"id":"1.195453758","rc":[{"atl":[[75,2.14]],"id":3805783},{"atb":[[6.8,0],[5.9,46.89]],"id":522747},{"atb":[[5.6,16.65],[6.2,8.11]],"id":522749},{"atb":[[5.1,0],[4.6,9.9]],"id":522741}],"con":true,"img":false}]}
{"op":"mcm","clk":"5348729278","pt":1646220191992,"mc":[{"id":"1.195453758","rc":[{"atb":[[3.95,33.9],[3.8,0]],"id":522741}],"con":true,"img":false}]}
{"op":"mcm","clk":"5348729290","pt":1646220192082,"mc":[{"id":"1.195453758","rc":[{"atb":[[5,84.78]],"id":522741}],"con":true,"img":false}]}
{"op":"mcm","clk":"5348729322","pt":1646220192283,"mc":[{"id":"1.195453758","rc":[{"atl":[[75,16.85],[80,2]],"id":3805783},{"atb":[[5.6,99.16],[5.9,0]],"id":522747}],"con":true,"img":false}]}
{"op":"mcm","clk":"5348729351","pt":1646220192489,"mc":[{"id":"1.195453758","rc":[{"atb":[[5.8,3.27],[6.6,2.72]],"id":522747},{"atb":[[5.9,7.67],[5.4,3.27]],"id":522749},{"atb":[[4.9,2.72],[4.4,3.27]],"id":522741}],"con":true,"img":false}]}
{"op":"mcm","clk":"5348729376","pt":1646220192696,"mc":[{"id":"1.195453758","rc":[{"atb":[[13.5,17.44]],"id":3805783},{"atb":[[12.5,0],[13,9.9],[14.5,11.64],[15,4.95]],"id":3805755},{"atl":[[32,0],[34,9.9],[27,6.09],[28,4.95]],"id":3805755}],"con":true,"img":false}]}
{"op":"mcm","clk":"5348729390","pt":1646220192764,"mc":[{"id":"1.195453758","rc":[{"atb":[[6.4,18.52]],"id":3805783}],"con":true,"img":false}]}
{"op":"mcm","clk":"5348729419","pt":1646220192973,"mc":[{"id":"1.195453758","rc":[{"atb":[[5,44.59],[3.95,117.12]],"id":522741}],"con":true,"img":false}]}
{"op":"mcm","clk":"5348729446","pt":1646220193177,"mc":[{"id":"1.195453758","rc":[{"atb":[[12,3.27],[13,33.7],[15.5,10.93]],"id":3805755},{"atl":[[34,33.7],[85,2]],"id":3805755}],"con":true,"img":false}]}
{"op":"mcm","clk":"5348729553","pt":1646220193996,"mc":[{"id":"1.195453758","rc":[{"atb":[[14.5,2.72]],"id":3805755}],"con":true,"img":false}]}
{"op":"mcm","clk":"5348729717","pt":1646220195408,"mc":[{"id":"1.195453758","rc":[{"atl":[[27,6.09],[28,50.86]],"id":522753}],"con":true,"img":false}]}
{"op":"mcm","clk":"5348730001","pt":1646220197701,"mc":[{"id":"1.195453758","rc":[{"atl":[[17,33.04]],"id":522749},{"atb":[[28,10.82]],"id":3805731}],"con":true,"img":false}]}
{"op":"mcm","clk":"5348730100","pt":1646220198592,"mc":[{"id":"1.195453758","rc":[{"atb":[[25,0],[28,4.95]],"id":3805731}],"con":true,"img":false}]}
{"op":"mcm","clk":"5348730164","pt":1646220199214,"mc":[{"id":"1.195453758","rc":[{"atb":[[20,21.12]],"id":3805731}],"con":true,"img":false}]}
{"op":"mcm","clk":"5348730175","pt":1646220199274,"mc":[{"id":"1.195453758","rc":[{"atb":[[24,9.9]],"id":3805731}],"con":true,"img":false}]}
{"op":"mcm","clk":"5348730194","pt":1646220199486,"mc":[{"id":"1.195453758","rc":[{"atb":[[25,6.6]],"id":3805731}],"con":true,"img":false}]}
{"op":"mcm","clk":"5348730244","pt":1646220199994,"mc":[{"id":"1.195453758","rc":[{"atb":[[20,2.72]],"id":3805731}],"con":true,"img":false}]}
{"op":"mcm","clk":"5348730269","pt":1646220200199,"mc":[{"id":"1.195453758","rc":[{"atb":[[4.6,57.47],[3.95,33.9]],"id":522741}],"con":true,"img":false}]}
{"op":"mcm","clk":"5348730288","pt":1646220200435,"mc":[{"id":"1.195453758","rc":[{"atl":[[24,0],[25,4.95],[28,40.95],[29,9.9]],"id":522753}],"con":true,"img":false}]}
{"op":"mcm","clk":"5348730438","pt":1646220201674,"mc":[{"id":"1.195453758","rc":[{"atb":[[28,10.82]],"id":3805731}],"con":true,"img":false}]}
{"op":"mcm","clk":"5348730556","pt":1646220202603,"mc":[{"id":"1.195453758","rc":[{"atb":[[25,0],[28,4.95]],"id":3805731}],"con":true,"img":false}]}
{"op":"mcm","clk":"5348730675","pt":1646220203577,"mc":[{"id":"1.195453758","rc":[{"atb":[[21,7.93]],"id":3805731}],"con":true,"img":false}]}
{"op":"mcm","clk":"5348730994","pt":1646220206183,"mc":[{"id":"1.195453758","rc":[{"atl":[[26,11.29]],"id":3805783}],"con":true,"img":false}]}
{"op":"mcm","clk":"5348731042","pt":1646220206589,"mc":[{"id":"1.195453758","rc":[{"atb":[[5.6,9.9],[5.8,52.76]],"id":522747}],"con":true,"img":false}]}
{"op":"mcm","clk":"5348731078","pt":1646220206905,"mc":[{"id":"1.195453758","rc":[{"atl":[[75,14.71]],"id":3805783}],"con":true,"img":false}]}
{"op":"mcm","clk":"5348731150","pt":1646220207489,"mc":[{"id":"1.195453758","rc":[{"atb":[[13,9.9],[14.5,19.15]],"id":3805755}],"con":true,"img":false}]}
{"op":"mcm","clk":"5348731696","pt":1646220212020,"mc":[{"id":"1.195453758","rc":[{"atb":[[28,10.82]],"id":3805731}],"con":true,"img":false}]}
{"op":"mcm","clk":"5348731790","pt":1646220212802,"mc":[{"id":"1.195453758","rc":[{"atb":[[21,0],[28,4.95]],"id":3805731}],"con":true,"img":false}]}
{"op":"mcm","clk":"5348731845","pt":1646220213322,"mc":[{"id":"1.195453758","rc":[{"atb":[[20,21.12]],"id":3805731}],"con":true,"img":false}]}
{"op":"mcm","clk":"5348731869","pt":1646220213489,"mc":[{"id":"1.195453758","rc":[{"atb":[[25,6.6]],"id":3805731}],"con":true,"img":false}]}
{"op":"mcm","clk":"5348732179","pt":1646220215796,"mc":[{"id":"1.195453758","rc":[{"atb":[[28,10.82]],"id":3805731}],"con":true,"img":false}]}
{"op":"mcm","clk":"5348732264","pt":1646220216622,"mc":[{"id":"1.195453758","rc":[{"atb":[[25,0],[28,4.95]],"id":3805731}],"con":true,"img":false}]}
{"op":"mcm","clk":"5348732346","pt":1646220217308,"mc":[{"id":"1.195453758","rc":[{"atb":[[6.8,22.96],[7.8,14.71]],"id":3805730},{"atb":[[3.95,0],[4.1,32.26]],"id":522741}],"con":true,"img":false}]}
{"op":"mcm","clk":"5348732369","pt":1646220217516,"mc":[{"id":"1.195453758","rc":[{"atl":[[65,4.95],[70,2.29],[85,9.9],[90,0]],"id":3805784},{"atl":[[32,9.9],[34,23.79],[27,11.05],[28,0]],"id":3805755},{"atb":[[7.2,13.87],[6.4,9.9],[6.8,27.98],[6,3.27]],"id":3805736},{"atb":[[6.2,0]],"id":522749},{"atb":[[21,7.93]],"id":3805731},{"atl":[[80,9.9],[60,4.95]],"id":3805731},{"atl":[[22,7.54],[25,4.95],[26,0],[29,9.9]],"id":3805730},{"atl":[[70,4.95],[75,2.14],[90,9.9],[95,0]],"id":3805762},{"atb":[[5.1,4.95],[5,39.63],[4.6,47.56],[4.7,9.9]],"id":522741},{"atl":[[8,0],[7.2,0],[7.6,4.95]],"id":522741},{"atl":[[32,0],[26,4.95],[27,6.09],[30,9.9]],"id":3805740}],"con":true,"img":false}]}
{"op":"mcm","clk":"5348732384","pt":1646220217616,"mc":[{"id":"1.195453758","rc":[{"atl":[[65,2.47],[85,0]],"id":3805731}],"con":true,"img":false}]}
{"op":"mcm","clk":"5348732395","pt":1646220217720,"mc":[{"id":"1.195453758","rc":[{"atl":[[260,4.91],[190,2]],"id":3805784},{"atl":[[560,0],[170,2]],"id":3805731},{"atl":[[170,2],[250,5.1]],"id":3805762}],"con":true,"img":false}]}
{"op":"mcm","clk":"5348732416","pt":1646220217928,"mc":[{"id":"1.195453758","rc":[{"atl":[[80,28.74]],"id":3805731},{"atb":[[4.6,0]],"id":522741},{"atl":[[25,6.6]],"id":3805740}],"con":true,"img":false}]}
{"op":"mcm","clk":"5348732424","pt":1646220218040,"mc":[{"id":"1.195453758","rc":[{"atl":[[260,0],[85,27.63],[60,2.68]],"id":3805784},{"atb":[[5.6,0]],"id":522749},{"atl":[[540,0],[55,2.93]],"id":3805731},{"atl":[[65,2.47],[90,24.86],[250,0]],"id":3805762},{"atl":[[55,2],[29,39.36]],"id":3805730},{"atb":[[5.1,19.66],[4.9,42.92]],"id":522741}],"con":true,"img":false}]}
{"op":"mcm","clk":"5348732447","pt":1646220218203,"mc":[{"id":"1.195453758","rc":[{"atb":[[5.6,34.46],[5.5,49.38]],"id":522749},{"atl":[[75,2],[30,33.7]],"id":3805740}],"con":true,"img":false}]}
{"op":"mcm","clk":"5348732513","pt":1646220218717,"mc":[{"id":"1.195453758","rc":[{"atl":[[65,0]],"id":3805731},{"atl":[[27,0]],"id":3805740}],"con":true,"img":false}]}
{"op":"mcm","clk":"5348732522","pt":1646220218816,"mc":[{"id":"1.195453758","rc":[{"atl":[[70,0]],"id":3805784},{"atb":[[5,0]],"id":522741}],"con":true,"img":false}]}
{"op":"mcm","clk":"5348732533","pt":1646220218921,"mc":[{"id":"1.195453758","rc":[{"atl":[[75,0]],"id":3805762}],"con":true,"img":false}]}
{"op":"mcm","clk":"5348732641","pt":1646220219711,"mc":[{"id":"1.195453758","rc":[{"atl":[[60,0]],"id":3805784},{"atb":[[5.1,4.95],[5,4.95],[4.6,9.9]],"id":522741}],"con":true,"img":false}]}
{"op":"mcm","clk":"5348732678","pt":1646220220017,"mc":[{"id":"1.195453758","rc":[{"atb":[[5.1,0],[4.7,0]],"id":522741}],"con":true,"img":false}]}
{"op":"mcm","clk":"5348732741","pt":1646220220498,"mc":[{"id":"1.195453758","rc":[{"atl":[[65,7.43]],"id":3805784},{"atb":[[5,39.63],[4.6,0]],"id":522741}],"con":true,"img":false}]}
{"op":"mcm","clk":"5348732844","pt":1646220221321,"mc":[{"id":"1.195453758","rc":[{"atb":[[5.1,4.95],[4.7,9.9]],"id":522741}],"con":true,"img":false}]}
{"op":"mcm","clk":"5348732907","pt":1646220221810,"mc":[{"id":"1.195453758","rc":[{"atl":[[19.5,8.56],[19,4.95],[22,9.9],[23,0]],"id":522743}],"con":true,"img":false}]}
{"op":"mcm","clk":"5348732962","pt":1646220222218,"mc":[{"id":"1.195453758","rc":[{"atl":[[22,37.37]],"id":522743}],"con":true,"img":false}]}
{"op":"mcm","clk":"5348732973","pt":1646220222322,"mc":[{"id":"1.195453758","rc":[{"atl":[[18.5,9.05],[44,2.33]],"id":522743}],"con":true,"img":false}]}
{"op":"mcm","clk":"5348733067","pt":1646220223120,"mc":[{"id":"1.195453758","rc":[{"atl":[[19.5,0]],"id":522743}],"con":true,"img":false}]}
{"op":"mcm","clk":"5348733281","pt":1646220224845,"mc":[{"id":"1.195453758","rc":[{"atl":[[85,9.9],[190,10.02]],"id":3805784}],"con":true,"img":false}]}
{"op":"mcm","clk":"5348733404","pt":1646220225935,"mc":[{"id":"1.195453758","rc":[{"atb":[[28,10.82]],"id":3805731}],"con":true,"img":false}]}
{"op":"mcm","clk":"5348733502","pt":1646220226832,"mc":[{"id":"1.195453758","rc":[{"atb":[[21,0],[28,4.95]],"id":3805731}],"con":true,"img":false}]}
{"op":"mcm","clk":"5348733538","pt":1646220227137,"mc":[{"id":"1.195453758","rc":[{"atl":[[25,4.95],[26,6.34],[29,9.9],[30,0]],"id":3805783},{"atb":[[20,2.72],[21,26.51]],"id":3805731}],"con":true,"img":false}]}
{"op":"mcm","clk":"5348733595","pt":1646220227548,"mc":[{"id":"1.195453758","rc":[{"atb":[[24,16.8]],"id":3805731}],"con":true,"img":false}]}
{"op":"mcm","clk":"5348733616","pt":1646220227716,"mc":[{"id":"1.195453758","rc":[{"atl":[[75,0],[24,6.63],[29,34.06]],"id":3805783}],"con":true,"img":false}]}
{"op":"mcm","clk":"5348733698","pt":1646220228439,"mc":[{"id":"1.195453758","rc":[{"atl":[[29,9.9]],"id":3805783}],"con":true,"img":false}]}
{"op":"mcm","clk":"5348733710","pt":1646220228543,"mc":[{"id":"1.195453758","rc":[{"atl":[[26,0]],"id":3805783}],"con":true,"img":false}]}
{"op":"mcm","clk":"5348733875","pt":1646220229952,"mc":[{"id":"1.195453758","rc":[{"atb":[[28,10.82]],"id":3805731}],"con":true,"img":false}]}
{"op":"mcm","clk":"5348734003","pt":1646220230951,"mc":[{"id":"1.195453758","rc":[{"atb":[[24,9.9],[28,4.95]],"id":3805731}],"con":true,"img":false}]}
{"op":"mcm","clk":"5348734076","pt":1646220231642,"mc":[{"id":"1.195453758","rc":[{"atb":[[22,7.54]],"id":3805731}],"con":true,"img":false}]}
{"op":"mcm","clk":"5348734091","pt":1646220231850,"mc":[{"id":"1.195453758","rc":[{"atb":[[5.1,43.62]],"id":522741}],"con":true,"img":false}]}
{"op":"mcm","clk":"5348734116","pt":1646220232022,"mc":[{"id":"1.195453758","rc":[{"atb":[[5.9,40.03]],"id":522749}],"con":true,"img":false}]}
{"op":"mcm","clk":"5348734189","pt":1646220232738,"mc":[{"id":"1.195453758","rc":[{"atb":[[5,0]],"id":522741}],"con":true,"img":false}]}
{"op":"mcm","clk":"5348734201","pt":1646220232844,"mc":[{"id":"1.195453758","rc":[{"atb":[[5.6,0]],"id":522749}],"con":true,"img":false}]}
{"op":"mcm","clk":"5348734244","pt":1646220233264,"mc":[{"id":"1.195453758","rc":[{"atb":[[4.9,2.72],[4.7,106.54]],"id":522741}],"con":true,"img":false}]}
{"op":"mcm","clk":"5348734270","pt":1646220233473,"mc":[{"id":"1.195453758","rc":[{"atb":[[5.5,9.9],[5.4,86.53]],"id":522749}],"con":true,"img":false}]}
{"op":"mcm","clk":"5348734365","pt":1646220234358,"mc":[{"id":"1.195453758","rc":[{"atb":[[32,4.95],[34,4.8],[27,9.9],[28,0]],"id":3805784},{"atb":[[10.5,13.17],[11.5,22.08],[12.5,4.95],[13.5,12.68]],"id":522753},{"atl":[[26,6.34]],"id":522753}],"con":true,"img":false}]}
{"op":"mcm","clk":"5348734419","pt":1646220234831,"mc":[{"id":"1.195453758","rc":[{"atb":[[23,2.72],[27,35.68]],"id":3805784},{"atb":[[11.5,0],[12.5,21.38]],"id":522753},{"atl":[[27,22.52],[28,0]],"id":522753}],"con":true,"img":false}]}
{"op":"mcm","clk":"5348734454","pt":1646220235148,"mc":[{"id":"1.195453758","rc":[{"atl":[[27,16.42]],"id":522753}],"con":true,"img":false}]}
{"op":"mcm","clk":"5348734802","pt":1646220238358,"mc":[{"id":"1.195453758","rc":[{"atl":[[9.6,18.43],[9.2,9.9],[11,0],[8.4,4.95]],"id":522747},{"atb":[[10,9.9],[11.5,17.82],[12,4.95],[9.8,0]],"id":3805730}],"con":true,"img":false}]}
{"op":"mcm","clk":"5348734843","pt":1646220238659,"mc":[{"id":"1.195453758","rc":[{"atl":[[9,9.9],[8.2,4.95],[11.5,0],[9.8,18.01]],"id":522749}],"con":true,"img":false}]}
{"op":"mcm","clk":"5348734870","pt":1646220238870,"mc":[{"id":"1.195453758","rc":[{"atl":[[9.6,60.57],[8.2,22.01],[25,4.17]],"id":522747},{"atb":[[9.6,3.27],[10,35.86],[12.5,13.78]],"id":3805730}],"con":true,"img":false}]}
{"op":"mcm","clk":"5348734897","pt":1646220239031,"mc":[{"id":"1.195453758","rc":[{"atl":[[8.2,26.97],[9.8,59.53]],"id":522749}],"con":true,"img":false}]}
{"op":"mcm","clk":"5348734908","pt":1646220239143,"mc":[{"id":"1.195453758","rc":[{"atl":[[17,6.25]],"id":522749}],"con":true,"img":false}]}
{"op":"mcm","clk":"5348734958","pt":1646220239552,"mc":[{"id":"1.195453758","rc":[{"atl":[[9.6,42.14]],"id":522747},{"atb":[[11.5,2.72]],"id":3805730}],"con":true,"img":false}]}
{"op":"mcm","clk":"5348734971","pt":1646220239669,"mc":[{"id":"1.195453758","rc":[{"atb":[[28,10.82]],"id":3805731}],"con":true,"img":false}]}
{"op":"mcm","clk":"5348734992","pt":1646220239863,"mc":[{"id":"1.195453758","rc":[{"atl":[[9.8,41.51]],"id":522749}],"con":true,"img":false}]}
{"op":"mcm","clk":"5348735018","pt":1646220240078,"mc":[{"id":"1.195453758","rc":[{"atl":[[9,0],[8.6,4.95],[8.2,0],[9.4,9.9]],"id":522749}],"con":true,"img":false}]}
{"op":"mcm","clk":"5348735071","pt":1646220240447,"mc":[{"id":"1.195453758","rc":[{"atb":[[22,0],[28,4.95]],"id":3805731}],"con":true,"img":false}]}
{"op":"mcm","clk":"5348735095","pt":1646220240675,"mc":[{"id":"1.195453758","rc":[{"atb":[[25,9.9],[29,4.95]],"id":3805731}],"con":true,"img":false}]}
{"op":"mcm","clk":"5348735112","pt":1646220240766,"mc":[{"id":"1.195453758","rc":[{"atb":[[24,0],[28,0]],"id":3805731}],"con":true,"img":false}]}
{"op":"mcm","clk":"5348735148","pt":1646220241069,"mc":[{"id":"1.195453758","rc":[{"atl":[[9.4,28.78]],"id":522749},{"atb":[[21,0],[22,25.95]],"id":3805731}],"con":true,"img":false}]}
{"op":"mcm","clk":"5348735161","pt":1646220241170,"mc":[{"id":"1.195453758","rc":[{"atb":[[30,5.46]],"id":3805731}],"con":true,"img":false}]}
{"op":"mcm","clk":"5348735187","pt":1646220241345,"mc":[{"id":"1.195453758","rc":[{"atl":[[29,34.49]],"id":3805783}],"con":true,"img":false}]}
{"op":"mcm","clk":"5348735554","pt":1646220244359,"mc":[{"id":"1.195453758","rc":[{"atl":[[22,4.95],[25,0],[26,16.25],[29,0]],"id":522753}],"con":true,"img":false}]}
{"op":"mcm","clk":"5348735961","pt":1646220247756,"mc":[{"id":"1.195453758","rc":[{"atl":[[22,12.5]],"id":522753}],"con":true,"img":false}]}
{"op":"mcm","clk":"5348736051","pt":1646220248561,"mc":[{"id":"1.195453758","rc":[{"atl":[[26,9.9]],"id":522753}],"con":true,"img":false}]}
{"op":"mcm","clk":"5348736314","pt":1646220250865,"mc":[{"id":"1.195453758","rc":[{"atb":[[4.4,0]],"id":522741}],"con":true,"img":false}]}
{"op":"mcm","clk":"5348736325","pt":1646220250966,"mc":[{"id":"1.195453758","rc":[{"atb":[[4.9,0]],"id":522741}],"con":true,"img":false}]}
{"op":"mcm","clk":"5348736389","pt":1646220251543,"mc":[{"id":"1.195453758","rc":[{"atb":[[4.1,145.05],[4.7,9.9]],"id":522741}],"con":true,"img":false}]}
{"op":"mcm","clk":"5348736418","pt":1646220251760,"mc":[{"id":"1.195453758","rc":[{"atb":[[5.1,46.34],[4.6,3.27]],"id":522741}],"con":true,"img":false}]}
{"op":"mcm","clk":"5348736464","pt":1646220252202,"mc":[{"id":"1.195453758","rc":[{"atb":[[10,9.9],[11.5,21.3]],"id":3805730}],"con":true,"img":false}]}
{"op":"mcm","clk":"5348736479","pt":1646220252277,"mc":[{"id":"1.195453758","rc":[{"atl":[[9.6,0],[9.2,57.36]],"id":522747}],"con":true,"img":false}]}
{"op":"mcm","clk":"5348736492","pt":1646220252381,"mc":[{"id":"1.195453758","rc":[{"atl":[[8.6,25.81]],"id":522749}],"con":true,"img":false}]}
{"op":"mcm","clk":"5348736536","pt":1646220252795,"mc":[{"id":"1.195453758","rc":[{"atl":[[22,0],[23,4.95],[26,0],[27,26.33]],"id":522753}],"con":true,"img":false}]}
{"op":"mcm","clk":"5348736584","pt":1646220253164,"mc":[{"id":"1.195453758","rc":[{"atl":[[9.4,9.9]],"id":522749}],"con":true,"img":false}]}
{"op":"mcm","clk":"5348736597","pt":1646220253265,"mc":[{"id":"1.195453758","rc":[{"atl":[[70,24.95],[27,9.9]],"id":522753}],"con":true,"img":false}]}
{"op":"mcm","clk":"5348736617","pt":1646220253479,"mc":[{"id":"1.195453758","rc":[{"atl":[[27,16]],"id":522753}],"con":true,"img":false}]}
{"op":"mcm","clk":"5348736683","pt":1646220254059,"mc":[{"id":"1.195453758","rc":[{"atl":[[24,0]],"id":3805783}],"con":true,"img":false}]}
{"op":"mcm","clk":"5348736714","pt":1646220254365,"mc":[{"id":"1.195453758","rc":[{"atb":[[25,25.39]],"id":3805731}],"con":true,"img":false}]}
{"op":"mcm","clk":"5348736723","pt":1646220254466,"mc":[{"id":"1.195453758","rc":[{"atb":[[22,0]],"id":3805731}],"con":true,"img":false}]}
{"op":"mcm","clk":"5348736743","pt":1646220254677,"mc":[{"id":"1.195453758","rc":[{"atl":[[80,22.13],[29,9.9]],"id":3805783}],"con":true,"img":false}]}
{"op":"mcm","clk":"5348736766","pt":1646220254889,"mc":[{"id":"1.195453758","rc":[{"atl":[[29,15.57]],"id":3805783}],"con":true,"img":false}]}
{"op":"mcm","clk":"5348737215","pt":1646220258602,"mc":[{"id":"1.195453758","rc":[{"atl":[[9.6,9.9],[9.2,47.46],[8.2,0],[8.8,4.95],[8.4,0]],"id":522747},{"atl":[[8.6,0],[9,4.95],[9.8,51.42],[9.4,0]],"id":522749},{"atl":[[23,0],[24,4.95],[27,6.09],[28,9.9]],"id":522753}],"con":true,"img":false}]}
{"op":"mcm","clk":"5348737273","pt":1646220259073,"mc":[{"id":"1.195453758","rc":[{"atl":[[9.6,79.13],[9.2,0]],"id":522747},{"atl":[[17,80.49],[9.8,9.9]],"id":522749}],"con":true,"img":false}]}
{"op":"mcm","clk":"5348737296","pt":1646220259282,"mc":[{"id":"1.195453758","rc":[{"atl":[[9.2,11.41]],"id":522747},{"atl":[[9,0],[9.8,18.01]],"id":522749}],"con":true,"img":false}]}
{"op":"mcm","clk":"5348737407","pt":1646220260280,"mc":[{"id":"1.195453758","rc":[{"atl":[[9.6,9.9],[8.8,4.95]],"id":522749}],"con":true,"img":false}]}
{"op":"mcm","clk":"5348737914","pt":1646220264702,"mc":[{"id":"1.195453758","rc":[{"atb":[[4.6,50.83],[4.1,32.26]],"id":522741}],"con":true,"img":false}]}
{"op":"mcm","clk":"5348738012","pt":1646220265605,"mc":[{"id":"1.195453758","rc":[{"atl":[[8.8,25.28]],"id":522749}],"con":true,"img":false}]}
{"op":"mcm","clk":"5348738085","pt":1646220266362,"mc":[{"id":"1.195453758","rc":[{"atl":[[9.8,0]],"id":522749}],"con":true,"img":false}]}
{"op":"mcm","clk":"5348738115","pt":1646220266652,"mc":[{"id":"1.195453758","rc":[{"atl":[[70,2],[28,33.7]],"id":522753}],"con":true,"img":false}]}
{"op":"mcm","clk":"5348738170","pt":1646220267078,"mc":[{"id":"1.195453758","rc":[{"atl":[[24,11.84]],"id":522753}],"con":true,"img":false}]}
{"op":"mcm","clk":"5348738258","pt":1646220267818,"mc":[{"id":"1.195453758","rc":[{"atb":[[32,0],[34,9.76],[27,25.77],[28,9.9]],"id":3805784},{"atl":[[65,2.47],[75,4.95],[85,0],[95,9.9]],"id":3805784},{"atb":[[32,4.95],[26,2.72],[27,9.9],[30,5.46]],"id":3805793},{"atl":[[75,2.14],[85,4.95],[95,0],[110,9.9]],"id":3805793},{"atl":[[70,4.95],[80,18.83],[90,9.9],[60,0]],"id":3805731},{"atl":[[24,4.95],[25,0],[28,9.9],[29,29.45]],"id":3805730},{"atl":[[70,0],[80,4.95],[90,14.95],[100,9.9]],"id":3805762},{"atb":[[10.5,3.27],[11,9.9],[12.5,16.42],[13,7.67]],"id":522753},{"atl":[[27,0]],"id":522753},{"atl":[[8.2,9.9],[7.4,4.95],[7.6,0]],"id":522741},{"atb":[[8,0],[9,12.5],[11.5,22.08],[12,9.9],[13.5,12.68],[14,4.95]],"id":3805740},{"atl":[[36,9.9],[26,0],[29,4.95],[30,23.79]],"id":3805740}],"con":true,"img":false}]}
{"op":"mcm","clk":"5348738270","pt":1646220267868,"mc":[{"id":"1.195453758","rc":[{"atl":[[25,11.55]],"id":3805783}],"con":true,"img":false}]}
{"op":"mcm","clk":"5348738280","pt":1646220267974,"mc":[{"id":"1.195453758","rc":[{"atl":[[620,0],[250,2]],"id":3805793}],"con":true,"img":false}]}
{"op":"mcm","clk":"5348738312","pt":1646220268284,"mc":[{"id":"1.195453758","rc":[{"atl":[[95,27.26],[190,2]],"id":3805784},{"atb":[[34,4.8],[25,0],[27,25.39]],"id":3805793},{"atl":[[600,0],[110,24.9]],"id":3805793},{"atl":[[28,35.86],[29,0]],"id":3805730},{"atb":[[11.5,0],[13,19.9],[14.5,11.74]],"id":3805740}],"con":true,"img":false}]}
{"op":"mcm","clk":"5348738357","pt":1646220268702,"mc":[{"id":"1.195453758","rc":[{"atl":[[29,9.9]],"id":3805783}],"con":true,"img":false}]}
{"op":"mcm","clk":"5348738401","pt":1646220269116,"mc":[{"id":"1.195453758","rc":[{"atb":[[30,0]],"id":3805793},{"atb":[[13.5,0]],"id":3805740}],"con":true,"img":false}]}
{"op":"mcm","clk":"5348738616","pt":1646220271313,"mc":[{"id":"1.195453758","rc":[{"atl":[[9.6,69.22],[9,4.95],[9.8,9.9],[8.8,0]],"id":522747},{"atl":[[9.6,0],[9.2,4.95],[10,9.9],[8.8,0]],"id":522749},{"atl":[[24,0],[25,4.95],[28,23.79],[29,9.9]],"id":522753}],"con":true,"img":false}]}
{"op":"mcm","clk":"5348738681","pt":1646220271996,"mc":[{"id":"1.195453758","rc":[{"atl":[[16.5,10.22]],"id":522749},{"atl":[[27,6.09]],"id":522753}],"con":true,"img":false}]}
{"op":"mcm","clk":"5348738717","pt":1646220272410,"mc":[{"id":"1.195453758","rc":[{"atl":[[16.5,40.16]],"id":522749}],"con":true,"img":false}]}
{"op":"mcm","clk":"5348738727","pt":1646220272519,"mc":[{"id":"1.195453758","rc":[{"atl":[[17,6.25]],"id":522749}],"con":true,"img":false}]}
{"op":"mcm","clk":"5348739105","pt":1646220275891,"mc":[{"id":"1.195453758","rc":[{"atl":[[25,0],[26,4.95],[29,0]],"id":522753}],"con":true,"img":false}]}
{"op":"mcm","clk":"5348739367","pt":1646220278402,"mc":[{"id":"1.195453758","rc":[{"atl":[[9.2,24.29]],"id":522749}],"con":true,"img":false}]}
{"op":"mcm","clk":"5348739395","pt":1646220278716,"mc":[{"id":"1.195453758","rc":[{"atl":[[9,0],[9.2,16.37],[9.8,0]],"id":522747}],"con":true,"img":false}]}
{"op":"mcm","clk":"5348739433","pt":1646220279133,"mc":[{"id":"1.195453758","rc":[{"atl":[[9.6,0]],"id":522747},{"atl":[[16.5,29.93]],"id":522749}],"con":true,"img":false}]}
{"op":"mcm","clk":"5348739458","pt":1646220279405,"mc":[{"id":"1.195453758","rc":[{"atl":[[25,71.4]],"id":522747}],"con":true,"img":false}]}
{"op":"mcm","clk":"5348739469","pt":1646220279500,"mc":[{"id":"1.195453758","rc":[{"atl":[[85,0],[110,14.99]],"id":3805793}],"con":true,"img":false}]}
{"op":"mcm","clk":"5348739479","pt":1646220279615,"mc":[{"id":"1.195453758","rc":[{"atl":[[75,0],[95,17.35]],"id":3805784},{"atl":[[34,9.9],[36,0],[28,4.95],[29,0]],"id":3805740}],"con":true,"img":false}]}
{"op":"mcm","clk":"5348739493","pt":1646220279730,"mc":[{"id":"1.195453758","rc":[{"atl":[[70,4.95],[90,9.9]],"id":3805784},{"atl":[[80,4.95],[100,9.9]],"id":3805793},{"atl":[[65,4.95],[70,0],[85,9.9],[90,0]],"id":3805731}],"con":true,"img":false}]}
{"op":"mcm","clk":"5348739547","pt":1646220280136,"mc":[{"id":"1.195453758","rc":[{"atl":[[95,0],[190,10.85]],"id":3805784},{"atl":[[110,0],[250,8.72]],"id":3805793}],"con":true,"img":false}]}
{"op":"mcm","clk":"5348739592","pt":1646220280506,"mc":[{"id":"1.195453758","rc":[{"atb":[[6.4,0]],"id":3805783},{"atb":[[2.96,0],[5.4,21.02]],"id":3805793},{"atl":[[46,2.22],[25,14.71]],"id":3805736},{"atl":[[17,0],[30,3.45]],"id":522749},{"atb":[[1.8,19.04],[11.5,0]],"id":3805731},{"atb":[[5.5,0],[6.8,17.24]],"id":522745}],"con":true,"img":false}]}
{"op":"mcm","clk":"5348739604","pt":1646220280622,"mc":[{"id":"1.195453758","rc":[{"atb":[[8.2,13.89]],"id":3805783}],"con":true,"img":false}]}
{"op":"mcm","clk":"5348739652","pt":1646220281129,"mc":[{"id":"1.195453758","rc":[{"atl":[[90,28.63],[190,2]],"id":3805784},{"atl":[[100,24.62],[250,2]],"id":3805793}],"con":true,"img":false}]}
{"op":"mcm","clk":"5348739974","pt":1646220283812,"mc":[{"id":"1.195453758","rc":[{"atl":[[9.6,4.95],[9.2,0],[11,9.9]],"id":522747},{"atl":[[65,0]],"id":3805762}],"con":true,"img":false}]}
{"op":"mcm","clk":"5348740041","pt":1646220284333,"mc":[{"id":"1.195453758","rc":[{"atl":[[25,4.17]],"id":522747},{"atl":[[90,0],[100,26.85]],"id":3805762}],"con":true,"img":false}]}
{"op":"mcm","clk":"5348740064","pt":1646220284501,"mc":[{"id":"1.195453758","rc":[{"atl":[[9.6,0],[11,0],[11.5,9.9],[9.8,4.95]],"id":522747},{"atl":[[80,6.95]],"id":3805762}],"con":true,"img":false}]}
{"op":"mcm","clk":"5348740073","pt":1646220284597,"mc":[{"id":"1.195453758","rc":[{"atl":[[10.5,16.68]],"id":522747}],"con":true,"img":false}]}
{"op":"mcm","clk":"5348740262","pt":1646220286234,"mc":[{"id":"1.195453758","rc":[{"atb":[[12.5,0]],"id":3805730}],"con":true,"img":false}]}
{"op":"mcm","clk":"5348740322","pt":1646220286745,"mc":[{"id":"1.195453758","rc":[{"atb":[[10,35.86],[11.5,2.72]],"id":3805730}],"con":true,"img":false}]}
{"op":"mcm","clk":"5348740354","pt":1646220287048,"mc":[{"id":"1.195453758","rc":[{"atb":[[11.5,17.82]],"id":3805730}],"con":true,"img":false}]}
{"op":"mcm","clk":"5348740617","pt":1646220289339,"mc":[{"id":"1.195453758","rc":[{"atl":[[18.5,9.05],[18,4.95],[20,9.9],[21,0]],"id":522745}],"con":true,"img":false}]}
{"op":"mcm","clk":"5348740675","pt":1646220289807,"mc":[{"id":"1.195453758","rc":[{"atl":[[18,14.27],[20,38.1],[40,2.56]],"id":522745}],"con":true,"img":false}]}
{"op":"mcm","clk":"5348740757","pt":1646220290542,"mc":[{"id":"1.195453758","rc":[{"atl":[[170,12.06],[100,9.9]],"id":3805762}],"con":true,"img":false}]}
{"op":"mcm","clk":"5348740780","pt":1646220290754,"mc":[{"id":"1.195453758","rc":[{"atl":[[18.5,0]],"id":522745}],"con":true,"img":false}]}
{"op":"mcm","clk":"5348740892","pt":1646220291642,"mc":[{"id":"1.195453758","rc":[{"atl":[[10,4.95],[11.5,0],[12,9.9],[9.8,0]],"id":522747}],"con":true,"img":false}]}
{"op":"mcm","clk":"5348740922","pt":1646220291955,"mc":[{"id":"1.195453758","rc":[{"atl":[[11.5,39.54]],"id":522747}],"con":true,"img":false}]}
{"op":"mcm","clk":"5348740966","pt":1646220292412,"mc":[{"id":"1.195453758","rc":[{"atl":[[8.4,4.95]],"id":522749},{"atb":[[5.1,43.62],[4.6,47.56]],"id":522741}],"con":true,"img":false}]}
{"op":"mcm","clk":"5348740978","pt":1646220292526,"mc":[{"id":"1.195453758","rc":[{"atl":[[10,0]],"id":522749}],"con":true,"img":false}]}
{"op":"mcm","clk":"5348741027","pt":1646220292934,"mc":[{"id":"1.195453758","rc":[{"atl":[[16.5,0],[10,50.83],[8.4,26.37]],"id":522749}],"con":true,"img":false}]}
{"op":"mcm","clk":"5348741051","pt":1646220293160,"mc":[{"id":"1.195453758","rc":[{"atb":[[4.9,2.72],[4.4,3.27]],"id":522741}],"con":true,"img":false}]}
{"op":"mcm","clk":"5348741082","pt":1646220293408,"mc":[{"id":"1.195453758","rc":[{"atb":[[6.4,0],[11,0],[5.2,0]],"id":3805784},{"atb":[[4.8,0],[7.6,0],[3.9,0]],"id":3805783},{"atb":[[5.5,0],[12.5,0],[7,0]],"id":3805793},{"atb":[[8.8,0],[4.4,0],[5.4,0]],"id":3805755},{"atb":[[3.2,0],[2.88,0],[4.4,0]],"id":3805736},{"atb":[[3.45,0],[4.9,0],[2.98,0]],"id":522747},{"atb":[[3.9,0],[2.96,0],[2.76,0]],"id":522749},{"atb":[[5.1,0],[10.5,0],[6.2,0]],"id":3805731},{"atb":[[7.4,0],[13.5,0],[5.7,0]],"id":3805762},{"atb":[[3.7,0],[6.8,0],[4.4,0]],"id":3805730},{"atb":[[5.1,0],[8.2,0],[4.1,0]],"id":522753},{"atb":[[2.9,0],[3.75,0],[2.7,0]],"id":522741},{"atb":[[4.8,0],[7.6,0],[3.9,0]],"id":522743},{"atb":[[6.2,0],[4.1,0],[3.55,0]],"id":3805740},{"atb":[[4,0],[6,0],[3.5,0]],"id":522745}],"con":true,"img":false}]}
{"op":"mcm","clk":"5348741095","pt":1646220293613,"mc":[{"id":"1.195453758","rc":[{"atb":[[4.6,0],[4.7,57.47]],"id":522741}],"con":true,"img":false}]}
{"op":"mcm","clk":"5348741105","pt":1646220293718,"mc":[{"id":"1.195453758","rc":[{"atl":[[9.2,4.95]],"id":522749}],"con":true,"img":false}]}
{"op":"mcm","clk":"5348741127","pt":1646220293933,"mc":[{"id":"1.195453758","rc":[{"atl":[[26,11.29]],"id":522753}],"con":true,"img":false}]}
{"op":"mcm","clk":"5348741173","pt":1646220294357,"mc":[{"id":"1.195453758","rc":[{"atl":[[24,4.95],[25,6.6],[28,9.9],[29,0]],"id":3805783}],"con":true,"img":false}]}
{"op":"mcm","clk":"5348741190","pt":1646220294549,"mc":[{"id":"1.195453758","rc":[{"atl":[[80,20.13],[55,2]],"id":3805783}],"con":true,"img":false}]}
{"op":"mcm","clk":"5348741198","pt":1646220294653,"mc":[{"id":"1.195453758","rc":[{"atb":[[25,15.48],[26,9.9],[29,0],[30,10.42]],"id":3805731}],"con":true,"img":false}]}
{"op":"mcm","clk":"5348741214","pt":1646220294814,"mc":[{"id":"1.195453758","rc":[{"atl":[[27,0]],"id":522753}],"con":true,"img":false}]}
{"op":"mcm","clk":"5348741226","pt":1646220294919,"mc":[{"id":"1.195453758","rc":[{"atl":[[80,0],[28,34.46]],"id":3805783}],"con":true,"img":false}]}
{"op":"mcm","clk":"5348741236","pt":1646220295022,"mc":[{"id":"1.195453758","rc":[{"atl":[[23,6.82]],"id":3805783}],"con":true,"img":false}]}
{"op":"mcm","clk":"5348741266","pt":1646220295332,"mc":[{"id":"1.195453758","rc":[{"atl":[[70,26.65],[28,0]],"id":522753}],"con":true,"img":false}]}
{"op":"mcm","clk":"5348741319","pt":1646220295852,"mc":[{"id":"1.195453758","rc":[{"atl":[[25,0],[28,9.9]],"id":3805783},{"atl":[[20,9.9],[40,45.75]],"id":522745}],"con":true,"img":false}]}
{"op":"mcm","clk":"5348741328","pt":1646220295954,"mc":[{"id":"1.195453758","rc":[{"atl":[[8.6,4.95],[9.2,0],[8.4,0],[9.4,9.9]],"id":522749}],"con":true,"img":false}]}
{"op":"mcm","clk":"5348741336","pt":1646220296007,"mc":[{"id":"1.195453758","rc":[{"atl":[[70,2]],"id":522753}],"con":true,"img":false}]}
{"op":"mcm","clk":"5348741346","pt":1646220296110,"mc":[{"id":"1.195453758","rc":[{"atl":[[10,0],[10.5,21.64],[12,0]],"id":522747}],"con":true,"img":false}]}
{"op":"mcm","clk":"5348741399","pt":1646220296629,"mc":[{"id":"1.195453758","rc":[{"atl":[[9.4,28.78]],"id":522749}],"con":true,"img":false}]}
{"op":"mcm","clk":"5348741563","pt":1646220298030,"mc":[{"id":"1.195453758","rc":[{"atl":[[11.5,0],[25,73.52]],"id":522747}],"con":true,"img":false}]}
{"op":"mcm","clk":"5348741578","pt":1646220298137,"mc":[{"id":"1.195453758","rc":[{"atl":[[24,4.95],[26,6.34],[28,9.9]],"id":522753}],"con":true,"img":false}]}
{"op":"mcm","clk":"5348741721","pt":1646220299444,"mc":[{"id":"1.195453758","rc":[{"atb":[[13,0],[14.5,4.95],[15,0]],"id":3805783},{"atb":[[12,19.36]],"id":3805730}],"con":true,"img":false}]}
{"op":"mcm","clk":"5348741786","pt":1646220300121,"mc":[{"id":"1.195453758","rc":[{"atb":[[12.5,9.9]],"id":3805783},{"atb":[[11.5,2.72]],"id":3805730}],"con":true,"img":false}]}
{"op":"mcm","clk":"5348742030","pt":1646220302586,"mc":[{"id":"1.195453758","rc":[{"atb":[[16.5,8.59],[8.6,35.05],[6.6,47.57]],"id":3805784},{"atb":[[3.85,93.47],[7.4,20.81],[4.7,72]],"id":3805783},{"atb":[[16.5,8.59],[8.6,35.05],[6.6,47.57]],"id":3805793},{"atb":[[5.1,64.97],[8.2,18.49],[4.1,85.93]],"id":3805755},{"atb":[[3.95,45.15],[2.98,134.54],[2.78,149.66]],"id":3805736},{"atb":[[17,8.32],[6.8,45.93],[8.8,34.15]],"id":3805762},{"atb":[[5.1,64.97],[8.2,18.49],[4.1,85.93]],"id":522753},{"atb":[[5.6,57.91],[9.2,16.24],[4.6,74]],"id":3805740}],"con":true,"img":false}]}
{"op":"mcm","clk":"5348742038","pt":1646220302686,"mc":[{"id":"1.195453758","rc":[{"atb":[[4.3,40.36],[2.86,143.23],[3.15,123.9]],"id":522747},{"atb":[[3.95,79.05],[2.98,134.54],[2.78,149.66]],"id":522749},{"atb":[[8,38.05],[6,53.28],[15,9.51]],"id":3805731},{"atb":[[3.45,108.73],[3.95,90.3],[5.9,27.18]],"id":3805730},{"atb":[[2.82,146.37],[3.55,52.23],[2.62,164.44]],"id":522741},{"atb":[[3.6,102.46],[6.4,24.66],[4.2,83.25]],"id":522743},{"atb":[[3.45,108.73],[3.95,90.3],[5.9,27.18]],"id":522745}],"con":true,"img":false}]}
{"op":"mcm","clk":"5348742172","pt":1646220304037,"mc":[{"id":"1.195453758","rc":[{"atl":[[9.6,9.9],[8.6,0],[8.8,4.95],[9.4,18.87]],"id":522749}],"con":true,"img":false}]}
{"op":"mcm","clk":"5348742179","pt":1646220304149,"mc":[{"id":"1.195453758","rc":[{"atl":[[10.5,16.68],[11.5,9.9],[9.8,4.95]],"id":522747}],"con":true,"img":false}]}
{"op":"mcm","clk":"5348742191","pt":1646220304244,"mc":[{"id":"1.195453758","rc":[{"atl":[[11.5,118.89],[25,4.17]],"id":522747}],"con":true,"img":false}]}
{"op":"mcm","clk":"5348742234","pt":1646220304665,"mc":[{"id":"1.195453758","rc":[{"atl":[[9.8,22.97]],"id":522747}],"con":true,"img":false}]}
{"op":"mcm","clk":"5348742303","pt":1646220305234,"mc":[{"id":"1.195453758","rc":[{"atl":[[9.6,52.68],[10,0]],"id":522749}],"con":true,"img":false}]}
{"op":"mcm","clk":"5348742322","pt":1646220305469,"mc":[{"id":"1.195453758","rc":[{"atl":[[10.5,0]],"id":522747}],"con":true,"img":false}]}
{"op":"mcm","clk":"5348742339","pt":1646220305676,"mc":[{"id":"1.195453758","rc":[{"atl":[[9.6,42.77],[9,4.95],[9.8,9.9],[8.8,0]],"id":522749},{"atl":[[24,0],[25,4.95],[28,0],[29,9.9]],"id":522753}],"con":true,"img":false}]}
{"op":"mcm","clk":"5348742384","pt":1646220306146,"mc":[{"id":"1.195453758","rc":[{"atl":[[9,24.77]],"id":522749}],"con":true,"img":false}]}
{"op":"mcm","clk":"5348742396","pt":1646220306251,"mc":[{"id":"1.195453758","rc":[{"atl":[[25,11.55]],"id":522753}],"con":true,"img":false}]}
{"op":"mcm","clk":"5348742458","pt":1646220306983,"mc":[{"id":"1.195453758","rc":[{"atl":[[9.4,0]],"id":522749}],"con":true,"img":false}]}
{"op":"mcm","clk":"5348742466","pt":1646220307035,"mc":[{"id":"1.195453758","rc":[{"atl":[[26,0]],"id":522753}],"con":true,"img":false}]}
{"op":"mcm","clk":"5348742488","pt":1646220307249,"mc":[{"id":"1.195453758","rc":[{"atl":[[28,34.78]],"id":3805783}],"con":true,"img":false}]}
{"op":"mcm","clk":"5348742514","pt":1646220307560,"mc":[{"id":"1.195453758","rc":[{"atl":[[70,27.15]],"id":522753}],"con":true,"img":false}]}
{"op":"mcm","clk":"5348742766","pt":1646220310285,"mc":[{"id":"1.195453758","rc":[{"atl":[[11.5,9.9],[25,74.9]],"id":522747}],"con":true,"img":false}]}
{"op":"mcm","clk":"5348742864","pt":1646220311184,"mc":[{"id":"1.195453758","rc":[{"atl":[[9.6,0],[9.8,106.24]],"id":522749}],"con":true,"img":false}]}
{"op":"mcm","clk":"5348743026","pt":1646220312695,"mc":[{"id":"1.195453758","rc":[{"atl":[[10,4.95],[11.5,0],[12,9.9],[9.8,0]],"id":522747}],"con":true,"img":false}]}
{"op":"mcm","clk":"5348743097","pt":1646220313375,"mc":[{"id":"1.195453758","rc":[{"atl":[[24,6.89]],"id":522747}],"con":true,"img":false}]}
{"op":"mcm","clk":"5348743393","pt":1646220316260,"mc":[{"id":"1.195453758","rc":[{"atl":[[24,31.86],[25,4.17]],"id":522747}],"con":true,"img":false}]}
{"op":"mcm","clk":"5348743436","pt":1646220316784,"mc":[{"id":"1.195453758","rc":[{"atl":[[10,22.56]],"id":522747}],"con":true,"img":false}]}
{"op":"mcm","clk":"5348743455","pt":1646220316995,"mc":[{"id":"1.195453758","rc":[{"atl":[[9.8,9.9]],"id":522749}],"con":true,"img":false}]}
{"op":"mcm","clk":"5348743464","pt":1646220317096,"mc":[{"id":"1.195453758","rc":[{"atl":[[30,63.04]],"id":522749}],"con":true,"img":false}]}
{"op":"mcm","clk":"5348743507","pt":1646220317466,"mc":[{"id":"1.195453758","rc":[{"atl":[[24,24.97]],"id":522747}],"con":true,"img":false}]}
{"op":"mcm","clk":"5348744111","pt":1646220323570,"mc":[{"id":"1.195453758","rc":[{"atb":[[19,0],[23,0]],"id":3805784},{"atb":[[17.5,0],[20,0]],"id":3805731},{"atb":[[20,0],[25,0]],"id":3805762},{"atb":[[10.5,0],[13,17.18]],"id":3805740}],"con":true,"img":false}]}
{"op":"mcm","clk":"5348744192","pt":1646220324302,"mc":[{"id":"1.195453758","rc":[{"atb":[[19.5,3.27],[24,2.72]],"id":3805784},{"atb":[[18,3.27],[21,2.72]],"id":3805731},{"atb":[[11,3.27],[13.5,2.72]],"id":3805740}],"con":true,"img":false}]}
{"op":"mcm","clk":"5348744198","pt":1646220324415,"mc":[{"id":"1.195453758","rc":[{"atb":[[22,3.27],[27,2.72]],"id":3805762}],"con":true,"img":false}]}
{"op":"mcm","clk":"5348744239","pt":1646220324782,"mc":[{"id":"1.195453758","rc":[{"atb":[[13,0],[13.5,19.9]],"id":3805740}],"con":true,"img":false}]}
{"op":"mcm","clk":"5348744247","pt":1646220324886,"mc":[{"id":"1.195453758","rc":[{"atb":[[26,9.9],[27,20.66]],"id":3805762}],"con":true,"img":false}]}
{"op":"mcm","clk":"5348744388","pt":1646220326294,"mc":[{"id":"1.195453758","rc":[{"atb":[[21,0],[26,0]],"id":3805793},{"atb":[[5.9,37.31],[5.4,83.26]],"id":522749}],"con":true,"img":false}]}
{"op":"mcm","clk":"5348744456","pt":1646220326973,"mc":[{"id":"1.195453758","rc":[{"atb":[[23,3.27],[28,2.72]],"id":3805793},{"atb":[[5.8,2.72],[5.3,3.27]],"id":522749}],"con":true,"img":false}]}
{"op":"mcm","clk":"5348744472","pt":1646220327182,"mc":[{"id":"1.195453758","rc":[{"atl":[[10,0],[10.5,4.95],[12,0],[12.5,9.9]],"id":522747},{"atl":[[9,0],[9.2,4.95],[10,9.9],[9.8,0]],"id":522749},{"atb":[[10,25.95],[11.5,7.67],[12,14.41],[9.8,9.9]],"id":3805730},{"atl":[[25,0],[26,4.95],[29,0],[30,9.9]],"id":522753}],"con":true,"img":false}]}
{"op":"mcm","clk":"5348744481","pt":1646220327286,"mc":[{"id":"1.195453758","rc":[{"atb":[[12,0]],"id":3805730}],"con":true,"img":false}]}
{"op":"mcm","clk":"5348744500","pt":1646220327495,"mc":[{"id":"1.195453758","rc":[{"atb":[[27,9.9],[28,17.23]],"id":3805793},{"atb":[[5.5,61.45],[5.4,0]],"id":522749}],"con":true,"img":false}]}
{"op":"mcm","clk":"5348744531","pt":1646220327809,"mc":[{"id":"1.195453758","rc":[{"atb":[[9.8,36.05]],"id":3805730}],"con":true,"img":false}]}
{"op":"mcm","clk":"5348744541","pt":1646220327863,"mc":[{"id":"1.195453758","rc":[{"atb":[[10,0]],"id":3805730}],"con":true,"img":false}]}
{"op":"mcm","clk":"5348744557","pt":1646220328022,"mc":[{"id":"1.195453758","rc":[{"atl":[[23,7.2]],"id":522747},{"atl":[[29,5.66]],"id":522749},{"atb":[[10,17.61]],"id":3805730},{"atl":[[65,2.47]],"id":522753}],"con":true,"img":false}]}
{"op":"mcm","clk":"5348744613","pt":1646220328495,"mc":[{"id":"1.195453758","rc":[{"atl":[[23,32.65],[24,0]],"id":522747},{"atl":[[29,28.8],[30,3.45]],"id":522749},{"atl":[[65,28.62],[70,2]],"id":522753}],"con":true,"img":false}]}
{"op":"mcm","clk":"5348744839","pt":1646220330384,"mc":[{"id":"1.195453758","rc":[{"atb":[[4.9,0],[4.4,0]],"id":522741}],"con":true,"img":false}]}
{"op":"mcm","clk":"5348744890","pt":1646220330910,"mc":[{"id":"1.195453758","rc":[{"atb":[[4.1,145.05]],"id":522741}],"con":true,"img":false}]}
{"op":"mcm","clk":"5348744903","pt":1646220330966,"mc":[{"id":"1.195453758","rc":[{"atb":[[4.7,9.9]],"id":522741}],"con":true,"img":false}]}
{"op":"mcm","clk":"5348744912","pt":1646220331071,"mc":[{"id":"1.195453758","rc":[{"atb":[[4.8,2.72],[4.3,3.27]],"id":522741}],"con":true,"img":false}]}
{"op":"mcm","clk":"5348744959","pt":1646220331703,"mc":[{"id":"1.195453758","rc":[{"atb":[[4.1,32.26]],"id":522741}],"con":true,"img":false}]}
{"op":"mcm","clk":"5348745626","pt":1646220337578,"mc":[{"id":"1.195453758","rc":[{"atb":[[3.65,37.74]],"id":522741}],"con":true,"img":false}]}
{"op":"mcm","clk":"5348745634","pt":1646220337680,"mc":[{"id":"1.195453758","rc":[{"atb":[[4.1,0]],"id":522741}],"con":true,"img":false}]}
{"op":"mcm","clk":"5348745658","pt":1646220337894,"mc":[{"id":"1.195453758","rc":[{"atb":[[12.5,0],[13,9.9],[14.5,0],[15,4.95]],"id":3805783},{"atl":[[24,0],[25,4.95],[28,24.88],[29,9.9]],"id":3805783},{"atl":[[65,0],[80,28.74],[85,0],[60,4.95]],"id":3805731},{"atl":[[23,4.95],[24,0],[27,9.9],[28,25.95]],"id":3805730},{"atl":[[18.5,14.01],[19,0],[21,9.9],[22,27.46]],"id":522743}],"con":true,"img":false}]}
{"op":"mcm","clk":"5348745701","pt":1646220338304,"mc":[{"id":"1.195453758","rc":[{"atl":[[28,0]],"id":3805730}],"con":true,"img":false}]}
{"op":"mcm","clk":"5348745713","pt":1646220338409,"mc":[{"id":"1.195453758","rc":[{"atl":[[27,36.05]],"id":3805730}],"con":true,"img":false}]}
{"op":"mcm","clk":"5348745787","pt":1646220339091,"mc":[{"id":"1.195453758","rc":[{"atb":[[18,5.88],[15.5,0]],"id":3805762}],"con":true,"img":false}]}
{"op":"mcm","clk":"5348745818","pt":1646220339404,"mc":[{"id":"1.195453758","rc":[{"atb":[[34,4.8],[36,4.95],[28,0],[29,9.9]],"id":3805784},{"atl":[[70,0],[75,4.95],[90,18.72],[95,9.9]],"id":3805784},{"atb":[[32,0],[34,9.76],[27,0],[28,27.14]],"id":3805793},{"atl":[[80,0],[90,4.95],[100,14.71],[120,9.9]],"id":3805793},{"atb":[[32,10.06],[26,0],[27,30.57],[30,0]],"id":3805762},{"atb":[[12,0],[13,9.9],[14,0],[15,4.95]],"id":3805740},{"atl":[[34,0],[28,0],[30,28.74]],"id":3805740}],"con":true,"img":false}]}
{"op":"mcm","clk":"5348745840","pt":1646220339617,"mc":[{"id":"1.195453758","rc":[{"atl":[[10.5,21.64]],"id":522747},{"atl":[[9.2,24.29]],"id":522749},{"atb":[[11.5,22.78]],"id":3805730},{"atl":[[26,11.29]],"id":522753}],"con":true,"img":false}]}
{"op":"mcm","clk":"5348745858","pt":1646220339827,"mc":[{"id":"1.195453758","rc":[{"atb":[[38,4.28],[27,0],[29,24.62]],"id":3805784},{"atb":[[27,12.63]],"id":3805762},{"atb":[[15.5,10.93]],"id":3805740},{"atl":[[75,26.69]],"id":3805740}],"con":true,"img":false}]}
{"op":"mcm","clk":"5348745867","pt":1646220339880,"mc":[{"id":"1.195453758","rc":[{"atb":[[23,25.13],[28,12.63]],"id":3805793},{"atl":[[30,4.95]],"id":3805740}],"con":true,"img":false}]}
{"op":"mcm","clk":"5348745891","pt":1646220340091,"mc":[{"id":"1.195453758","rc":[{"atb":[[22,32.96]],"id":3805762}],"con":true,"img":false}]}
{"op":"mcm","clk":"5348745910","pt":1646220340297,"mc":[{"id":"1.195453758","rc":[{"atl":[[23,25.44]],"id":522747},{"atl":[[29,23.14]],"id":522749},{"atb":[[10,0]],"id":3805730},{"atl":[[65,26.14]],"id":522753},{"atb":[[13.5,2.72],[14.5,45.45]],"id":3805740}],"con":true,"img":false}]}
{"op":"mcm","clk":"5348745931","pt":1646220340507,"mc":[{"id":"1.195453758","rc":[{"atb":[[34,0]],"id":3805784},{"atb":[[14.5,33.7]],"id":3805740}],"con":true,"img":false}]}
{"op":"mcm","clk":"5348745961","pt":1646220340818,"mc":[{"id":"1.195453758","rc":[{"atb":[[9.6,48.35],[9.8,9.9]],"id":3805730}],"con":true,"img":false}]}
{"op":"mcm","clk":"5348745993","pt":1646220341129,"mc":[{"id":"1.195453758","rc":[{"atl":[[17.5,4.95],[18,9.32],[19.5,9.9],[20,0]],"id":522745}],"con":true,"img":false}]}
{"op":"mcm","clk":"5348746002","pt":1646220341182,"mc":[{"id":"1.195453758","rc":[{"atl":[[9.2,0],[10,0],[10.5,9.9],[9.4,4.95]],"id":522749}],"con":true,"img":false}]}
{"op":"mcm","clk":"5348746039","pt":1646220341596,"mc":[{"id":"1.195453758","rc":[{"atl":[[17,9.9],[19.5,38.5],[40,2.56]],"id":522745}],"con":true,"img":false}]}
{"op":"mcm","clk":"5348746087","pt":1646220342118,"mc":[{"id":"1.195453758","rc":[{"atl":[[9.2,4.95],[10,9.9],[10.5,0],[28,5.86],[9.4,0]],"id":522749}],"con":true,"img":false}]}
{"op":"mcm","clk":"5348746121","pt":1646220342435,"mc":[{"id":"1.195453758","rc":[{"atb":[[4.7,57.47]],"id":522741},{"atl":[[18,0]],"id":522745}],"con":true,"img":false}]}
{"op":"mcm","clk":"5348746139","pt":1646220342588,"mc":[{"id":"1.195453758","rc":[{"atl":[[28,29.32],[29,0]],"id":522749}],"con":true,"img":false}]}
{"op":"mcm","clk":"5348746431","pt":1646220345724,"mc":[{"id":"1.195453758","rc":[{"atl":[[24,4.95],[25,0],[28,34.78],[29,0]],"id":3805783}],"con":true,"img":false}]}
{"op":"mcm","clk":"5348746553","pt":1646220347032,"mc":[{"id":"1.195453758","rc":[{"atb":[[4,33.33],[3.65,0]],"id":522741}],"con":true,"img":false}]}
{"op":"mcm","clk":"5348746597","pt":1646220347399,"mc":[{"id":"1.195453758","rc":[{"atb":[[13,0],[14.5,4.95],[15,0]],"id":3805783}],"con":true,"img":false}]}
{"op":"mcm","clk":"5348746622","pt":1646220347608,"mc":[{"id":"1.195453758","rc":[{"atl":[[9,4.95],[9.8,9.9]],"id":522749}],"con":true,"img":false}]}
{"op":"mcm","clk":"5348746632","pt":1646220347712,"mc":[{"id":"1.195453758","rc":[{"atl":[[9.2,0],[10,0]],"id":522749}],"con":true,"img":false}]}
{"op":"mcm","clk":"5348746781","pt":1646220349335,"mc":[{"id":"1.195453758","rc":[{"atl":[[24,4.95],[26,6.34],[28,9.9],[30,0]],"id":522753}],"con":true,"img":false}]}
{"op":"mcm","clk":"5348746831","pt":1646220349806,"mc":[{"id":"1.195453758","rc":[{"atl":[[65,0],[28,36.05]],"id":522753}],"con":true,"img":false}]}
{"op":"mcm","clk":"5348746947","pt":1646220351006,"mc":[{"id":"1.195453758","rc":[{"atl":[[9,24.77]],"id":522749},{"atl":[[24,11.84]],"id":522753}],"con":true,"img":false}]}
{"op":"mcm","clk":"5348747010","pt":1646220351834,"mc":[{"id":"1.195453758","rc":[{"atl":[[26,0]],"id":522753}],"con":true,"img":false}]}
{"op":"mcm","clk":"5348747019","pt":1646220351946,"mc":[{"id":"1.195453758","rc":[{"atl":[[28,23.45]],"id":522749}],"con":true,"img":false}]}
{"op":"mcm","clk":"5348747055","pt":1646220352304,"mc":[{"id":"1.195453758","rc":[{"atb":[[4,0],[3.65,37.74]],"id":522741}],"con":true,"img":false}]}
{"op":"mcm","clk":"5348747287","pt":1646220354802,"mc":[{"id":"1.195453758","rc":[{"atl":[[9.6,4.95],[11,9.9]],"id":522747}],"con":true,"img":false}]}
{"op":"mcm","clk":"5348747297","pt":1646220354908,"mc":[{"id":"1.195453758","rc":[{"atl":[[10.5,16.68],[12.5,0]],"id":522747}],"con":true,"img":false}]}
{"op":"mcm","clk":"5348747326","pt":1646220355227,"mc":[{"id":"1.195453758","rc":[{"atl":[[9.6,23.39],[11,56.8],[23,0]],"id":522747},{"atl":[[70,29.08],[28,9.9]],"id":522753}],"con":true,"img":false}]}
{"op":"mcm","clk":"5348747386","pt":1646220355896,"mc":[{"id":"1.195453758","rc":[{"atl":[[10.5,0]],"id":522747}],"con":true,"img":false}]}
{"op":"mcm","clk":"5348747799","pt":1646220360676,"mc":[{"id":"1.195453758","rc":[{"atl":[[11,9.9],[25,80.62]],"id":522747}],"con":true,"img":false}]}
{"op":"mcm","clk":"5348747947","pt":1646220361551,"mc":[{"id":"1.195453758","rc":[{"atb":[[17,6.25],[12.5,0]],"id":3805784},{"atb":[[4.6,27.78],[5.4,0]],"id":3805793},{"atl":[[46,0],[28,3.7]],"id":3805736},{"atb":[[1.8,0],[2.16,20.33]],"id":3805731},{"atb":[[18,0],[14.5,7.41]],"id":3805762},{"atl":[[170,10.06],[250,2]],"id":3805762},{"atb":[[5.8,0],[6.8,17.24]],"id":522743}],"con":true,"img":false}]}
{"op":"mcm","clk":"5348749537","pt":1646220374656,"mc":[{"id":"1.195453758","rc":[{"atb":[[18,0],[21,0]],"id":3805731},{"atb":[[22,29.69],[27,9.9]],"id":3805762},{"atb":[[11,0],[13.5,0]],"id":3805740}],"con":true,"img":false}]}
{"op":"mcm","clk":"5348749556","pt":1646220374866,"mc":[{"id":"1.195453758","rc":[{"atb":[[19.5,0],[24,0]],"id":3805784},{"atb":[[23,21.86],[28,9.9]],"id":3805793}],"con":true,"img":false}]}
{"op":"mcm","clk":"5348749619","pt":1646220375340,"mc":[{"id":"1.195453758","rc":[{"atb":[[18.5,3.27],[22,2.72]],"id":3805731},{"atb":[[23,3.27],[28,2.72]],"id":3805762},{"atb":[[11.5,3.27],[14,2.72]],"id":3805740}],"con":true,"img":false}]}
{"op":"mcm","clk":"5348749638","pt":1646220375546,"mc":[{"id":"1.195453758","rc":[{"atb":[[20,3.27],[25,2.72]],"id":3805784},{"atb":[[24,3.27],[29,2.72]],"id":3805793}],"con":true,"img":false}]}
{"op":"mcm","clk":"5348749674","pt":1646220375861,"mc":[{"id":"1.195453758","rc":[{"atb":[[22,0],[27,39.36]],"id":3805762},{"atb":[[4.8,0],[4.3,0]],"id":522741}],"con":true,"img":false}]}
{"op":"mcm","clk":"5348749697","pt":1646220376073,"mc":[{"id":"1.195453758","rc":[{"atb":[[23,0],[28,31.77]],"id":3805793}],"con":true,"img":false}]}
{"op":"mcm","clk":"5348749725","pt":1646220376233,"mc":[{"id":"1.195453758","rc":[{"atb":[[3.65,158.67]],"id":522741}],"con":true,"img":false}]}
{"op":"mcm","clk":"5348749739","pt":1646220376339,"mc":[{"id":"1.195453758","rc":[{"atl":[[9.6,18.43],[11,0],[11.5,9.9],[9.8,4.95]],"id":522747},{"atb":[[4.7,9.9]],"id":522741}],"con":true,"img":false}]}
{"op":"mcm","clk":"5348749754","pt":1646220376443,"mc":[{"id":"1.195453758","rc":[{"atl":[[9.6,0]],"id":522747}],"con":true,"img":false}]}
{"op":"mcm","clk":"5348749767","pt":1646220376548,"mc":[{"id":"1.195453758","rc":[{"atb":[[4.4,3.27]],"id":522741}],"con":true,"img":false}]}
{"op":"mcm","clk":"5348749776","pt":1646220376654,"mc":[{"id":"1.195453758","rc":[{"atb":[[4.9,2.72]],"id":522741}],"con":true,"img":false}]}
{"op":"mcm","clk":"5348749798","pt":1646220376862,"mc":[{"id":"1.195453758","rc":[{"atl":[[11.5,52.04],[25,4.17]],"id":522747}],"con":true,"img":false}]}
{"op":"mcm","clk":"5348749831","pt":1646220377182,"mc":[{"id":"1.195453758","rc":[{"atl":[[24,6.89]],"id":522747}],"con":true,"img":false}]}
{"op":"mcm","clk":"5348750053","pt":1646220379244,"mc":[{"id":"1.195453758","rc":[{"atb":[[6.6,28.71]],"id":522747}],"con":true,"img":false}]}
{"op":"mcm","clk":"5348750139","pt":1646220380079,"mc":[{"id":"1.195453758","rc":[{"atb":[[6,4.95]],"id":522747}],"con":true,"img":false}]}
{"op":"mcm","clk":"5348750166","pt":1646220380341,"mc":[{"id":"1.195453758","rc":[{"atl":[[9,0],[9.2,4.95],[10,9.9],[9.8,0]],"id":522749}],"con":true,"img":false}]}
{"op":"mcm","clk":"5348750181","pt":1646220380550,"mc":[{"id":"1.195453758","rc":[{"atl":[[10,4.95],[11.5,42.14],[12,9.9],[9.8,0]],"id":522747}],"con":true,"img":false}]}
{"op":"mcm","clk":"5348750231","pt":1646220381071,"mc":[{"id":"1.195453758","rc":[{"atl":[[10,21.32]],"id":522749}],"con":true,"img":false}]}
{"op":"mcm","clk":"5348750325","pt":1646220382061,"mc":[{"id":"1.195453758","rc":[{"atl":[[11.5,0]],"id":522747}],"con":true,"img":false}]}
{"op":"mcm","clk":"5348750336","pt":1646220382173,"mc":[{"id":"1.195453758","rc":[{"atl":[[12,67.32]],"id":522747}],"con":true,"img":false}]}
{"op":"mcm","clk":"5348750374","pt":1646220382590,"mc":[{"id":"1.195453758","rc":[{"atb":[[16.5,0],[8.6,0],[6.6,0]],"id":3805784},{"atb":[[3.85,0],[7.4,0],[4.7,0]],"id":3805783},{"atb":[[16.5,0],[8.6,0],[6.6,0]],"id":3805793},{"atb":[[5.1,0],[8.2,0],[4.1,0]],"id":3805755},{"atb":[[3.95,0],[2.98,0],[2.78,0]],"id":3805736},{"atb":[[4.3,0],[2.86,0],[3.15,0]],"id":522747},{"atb":[[3.95,33.9],[2.98,0],[2.78,0]],"id":522749},{"atb":[[8,0],[6,0],[15,0]],"id":3805731},{"atb":[[17,0],[6.8,0],[8.8,0]],"id":3805762},{"atb":[[3.45,0],[3.95,0],[5.9,0]],"id":3805730},{"atb":[[5.1,0],[8.2,0],[4.1,0]],"id":522753},{"atb":[[2.82,0],[3.55,0],[2.62,0]],"id":522741},{"atb":[[3.6,0],[6.4,0],[4.2,0]],"id":522743},{"atb":[[5.6,0],[9.2,0],[4.6,0]],"id":3805740},{"atb":[[3.45,0],[3.95,0],[5.9,0]],"id":522745}],"con":true,"img":false}]}
{"op":"mcm","clk":"5348750537","pt":1646220383969,"mc":[{"id":"1.195453758","rc":[{"atb":[[4,33.33],[3.65,120.93]],"id":522741}],"con":true,"img":false}]}
{"op":"mcm","clk":"5348750858","pt":1646220386973,"mc":[{"id":"1.195453758","rc":[{"atb":[[3.65,0],[4.7,57.47]],"id":522741}],"con":true,"img":false}]}
{"op":"mcm","clk":"5348750905","pt":1646220387387,"mc":[{"id":"1.195453758","rc":[{"atl":[[12,9.9],[24,59.82]],"id":522747}],"con":true,"img":false}]}
{"op":"mcm","clk":"5348750953","pt":1646220387758,"mc":[{"id":"1.195453758","rc":[{"atl":[[10,22.56]],"id":522747}],"con":true,"img":false}]}
{"op":"mcm","clk":"5348751040","pt":1646220388497,"mc":[{"id":"1.195453758","rc":[{"atl":[[24,52.93]],"id":522747}],"con":true,"img":false}]}
{"op":"mcm","clk":"5348751325","pt":1646220391012,"mc":[{"id":"1.195453758","rc":[{"atl":[[9,4.95],[9.2,0],[10,11.41],[9.8,9.9]],"id":522749}],"con":true,"img":false}]}
{"op":"mcm","clk":"5348751402","pt":1646220391589,"mc":[{"id":"1.195453758","rc":[{"atl":[[9.2,19.33]],"id":522749}],"con":true,"img":false}]}
{"op":"mcm","clk":"5348751410","pt":1646220391701,"mc":[{"id":"1.195453758","rc":[{"atl":[[10,43.12],[28,0]],"id":522749}],"con":true,"img":false}]}
{"op":"mcm","clk":"5348751495","pt":1646220392367,"mc":[{"id":"1.195453758","rc":[{"atl":[[10,31.7]],"id":522749}],"con":true,"img":false}]}
{"op":"mcm","clk":"5348751634","pt":1646220393786,"mc":[{"id":"1.195453758","rc":[{"atb":[[5.8,0],[5.3,0]],"id":522749}],"con":true,"img":false}]}
{"op":"mcm","clk":"5348751677","pt":1646220394197,"mc":[{"id":"1.195453758","rc":[{"atb":[[5.5,9.9]],"id":522749}],"con":true,"img":false}]}
{"op":"mcm","clk":"5348751687","pt":1646220394305,"mc":[{"id":"1.195453758","rc":[{"atb":[[3.95,113.03]],"id":522749}],"con":true,"img":false}]}
{"op":"mcm","clk":"5348751704","pt":1646220394522,"mc":[{"id":"1.195453758","rc":[{"atb":[[5.9,40.03],[5.4,3.27]],"id":522749}],"con":true,"img":false}]}
{"op":"mcm","clk":"5348751744","pt":1646220394772,"mc":[{"id":"1.195453758","rc":[{"atl":[[10,4.95]],"id":522747}],"con":true,"img":false}]}
{"op":"mcm","clk":"5348751755","pt":1646220394878,"mc":[{"id":"1.195453758","rc":[{"atl":[[10,0],[10.5,4.95],[12,0],[12.5,9.9]],"id":522747}],"con":true,"img":false}]}
{"op":"mcm","clk":"5348751773","pt":1646220395091,"mc":[{"id":"1.195453758","rc":[{"atb":[[17,14.57],[6.8,45.93],[8.8,34.15]],"id":3805784},{"atb":[[4.8,70.1],[7.6,20.18],[3.9,91.86]],"id":3805783},{"atb":[[17,8.32],[6.8,45.93],[8.8,34.15]],"id":3805793},{"atb":[[5.1,64.97],[8.2,18.49],[4.1,85.93]],"id":3805755},{"atb":[[3.9,45.93],[2.96,135.92],[2.76,151.36]],"id":3805736},{"atb":[[3.1,126.85],[2.84,144.78],[4.2,41.62]],"id":522747},{"atb":[[3.9,45.93],[2.96,135.92],[2.76,151.36]],"id":522749},{"atb":[[6.2,51.23],[8.2,37],[15.5,9.18]],"id":3805731},{"atb":[[4,88.79],[6,26.64],[3.5,106.56]],"id":3805730},{"atb":[[17.5,8.07],[9,33.3],[7,44.4]],"id":3805762},{"atb":[[5.1,64.97],[8.2,18.49],[4.1,85.93]],"id":522753},{"atb":[[2.8,148],[2.6,166.5],[3.5,53.28]],"id":522741},{"atb":[[4.3,80.72],[6.6,23.78],[3.65,100.52]],"id":522743},{"atb":[[9.6,15.48],[4.8,70.1],[5.8,55.49]],"id":3805740},{"atb":[[4,88.79],[6,26.64],[3.5,106.56]],"id":522745}],"con":true,"img":false}]}
{"op":"mcm","clk":"5348751808","pt":1646220395518,"mc":[{"id":"1.195453758","rc":[{"atl":[[12,14.41]],"id":522747}],"con":true,"img":false}]}
{"op":"mcm","clk":"5348751857","pt":1646220395999,"mc":[{"id":"1.195453758","rc":[{"atl":[[24,0],[12.5,46.07]],"id":522747}],"con":true,"img":false}]}
{"op":"mcm","clk":"5348751906","pt":1646220396520,"mc":[{"id":"1.195453758","rc":[{"atb":[[4,0],[3.6,38.46]],"id":522741},{"atl":[[34,3.03],[44,0]],"id":522743}],"con":true,"img":false}]}
{"op":"mcm","clk":"5348751938","pt":1646220396838,"mc":[{"id":"1.195453758","rc":[{"atb":[[13,9.9],[14.5,0],[15,4.95]],"id":3805783},{"atl":[[24,0],[25,4.95],[28,24.88],[29,9.9]],"id":3805783},{"atb":[[34,4.8],[36,4.95],[28,21.86],[29,12.63]],"id":3805793},{"atb":[[6.6,2.72]],"id":522747},{"atl":[[8,9.9],[7.2,4.95],[8.2,0],[7.4,0]],"id":522741},{"atl":[[18.5,9.05],[18,4.95],[20,9.9],[21,0]],"id":522743},{"atb":[[13,0],[15,0],[15.5,15.88]],"id":3805740}],"con":true,"img":false}]}
{"op":"mcm","clk":"5348751965","pt":1646220396993,"mc":[{"id":"1.195453758","rc":[{"atl":[[9.6,9.9],[9,0],[9.8,0],[8.8,4.95]],"id":522749}],"con":true,"img":false}]}
{"op":"mcm","clk":"5348752017","pt":1646220397513,"mc":[{"id":"1.195453758","rc":[{"atb":[[38,4.28],[28,0],[29,27.34]],"id":3805793},{"atb":[[6,33.74]],"id":522747},{"atl":[[17.5,9.6],[20,38.1],[22,0]],"id":522743},{"atb":[[14,36.16],[14.5,0]],"id":3805740}],"con":true,"img":false}]}
{"op":"mcm","clk":"5348752037","pt":1646220397725,"mc":[{"id":"1.195453758","rc":[{"atl":[[9.6,0],[9.2,24.29],[10,41.61],[8.8,0]],"id":522749}],"con":true,"img":false}]}
{"op":"mcm","clk":"5348752054","pt":1646220397882,"mc":[{"id":"1.195453758","rc":[{"atl":[[22,4.95],[24,6.89],[26,9.9],[28,0]],"id":522753}],"con":true,"img":false}]}
{"op":"mcm","clk":"5348752078","pt":1646220398095,"mc":[{"id":"1.195453758","rc":[{"atl":[[10.5,21.64]],"id":522747}],"con":true,"img":false}]}
{"op":"mcm","clk":"5348752091","pt":1646220398199,"mc":[{"id":"1.195453758","rc":[{"atb":[[34,0]],"id":3805793},{"atl":[[10,9.9],[30,54.28]],"id":522749},{"atl":[[18.5,0]],"id":522743}],"con":true,"img":false}]}
{"op":"mcm","clk":"5348752101","pt":1646220398304,"mc":[{"id":"1.195453758","rc":[{"atl":[[70,2],[26,36.05]],"id":522753}],"con":true,"img":false}]}
{"op":"mcm","clk":"5348752114","pt":1646220398409,"mc":[{"id":"1.195453758","rc":[{"atl":[[22,12.5]],"id":522753}],"con":true,"img":false}]}
{"op":"mcm","clk":"5348752173","pt":1646220398987,"mc":[{"id":"1.195453758","rc":[{"atl":[[12,0]],"id":522747}],"con":true,"img":false}]}
{"op":"mcm","clk":"5348752186","pt":1646220399088,"mc":[{"id":"1.195453758","rc":[{"atl":[[24,0]],"id":522753}],"con":true,"img":false}]}
{"op":"mcm","clk":"5348752263","pt":1646220399829,"mc":[{"id":"1.195453758","rc":[{"atb":[[9,0],[10,11.11]],"id":3805740}],"con":true,"img":false}]}
{"op":"mcm","clk":"5348752288","pt":1646220400040,"mc":[{"id":"1.195453758","rc":[{"atl":[[32,0],[26,4.95],[27,6.09],[30,9.9]],"id":3805755},{"atl":[[34,4.95],[42,9.9],[30,0]],"id":3805740}],"con":true,"img":false}]}
{"op":"mcm","clk":"5348752351","pt":1646220400504,"mc":[{"id":"1.195453758","rc":[{"atl":[[34,0],[25,6.6],[30,33.7]],"id":3805755},{"atl":[[75,2],[42,34.46],[25,0]],"id":3805740}],"con":true,"img":false}]}
{"op":"mcm","clk":"5348752364","pt":1646220400615,"mc":[{"id":"1.195453758","rc":[{"atl":[[190,0]],"id":3805784},{"atl":[[9.2,0],[10,0],[10.5,9.9],[9.4,4.95]],"id":522749},{"atl":[[42,2.44],[55,0]],"id":3805730}],"con":true,"img":false}]}
{"op":"mcm","clk":"5348752375","pt":1646220400715,"mc":[{"id":"1.195453758","rc":[{"atl":[[250,2]],"id":3805784}],"con":true,"img":false}]}
{"op":"mcm","clk":"5348752401","pt":1646220400935,"mc":[{"id":"1.195453758","rc":[{"atb":[[36,0],[38,9.23],[29,14.71],[30,9.9]],"id":3805784},{"atl":[[75,0],[80,4.95],[95,0]],"id":3805784},{"atb":[[13,0],[14,4.95],[15,0]],"id":3805783},{"atl":[[23,11.78],[25,0],[27,9.9],[29,0]],"id":3805783},{"atb":[[6,0],[7,0]],"id":3805736},{"atl":[[22,12.5],[23,0],[26,9.9],[27,26.14]],"id":3805730},{"atb":[[32,5.11],[34,4.95],[27,29.45],[28,12.63]],"id":3805762},{"atl":[[80,2],[90,4.95],[100,0],[120,9.9]],"id":3805762}],"con":true,"img":false}]}
{"op":"mcm","clk":"5348752411","pt":1646220401029,"mc":[{"id":"1.195453758","rc":[{"atl":[[85,4.95],[90,0],[110,9.9],[120,0]],"id":3805793},{"atl":[[12.5,9.9],[25,85.19]],"id":522747}],"con":true,"img":false}]}
{"op":"mcm","clk":"5348752435","pt":1646220401189,"mc":[{"id":"1.195453758","rc":[{"atl":[[27,0]],"id":3805755},{"atl":[[40,4.06],[42,9.9]],"id":3805740}],"con":true,"img":false}]}
{"op":"mcm","clk":"5348752444","pt":1646220401292,"mc":[{"id":"1.195453758","rc":[{"atb":[[5.6,9.9],[5.5,0],[6,4.95],[5.9,35.08]],"id":522749},{"atl":[[9.6,4.95],[10.5,0],[11,9.9],[29,5.66],[9.4,0]],"id":522749}],"con":true,"img":false}]}
{"op":"mcm","clk":"5348752461","pt":1646220401398,"mc":[{"id":"1.195453758","rc":[{"atb":[[6.4,52.4],[6.8,0]],"id":3805736},{"atb":[[36,4.52],[27,0],[28,27.58]],"id":3805762},{"atl":[[170,0],[120,24.86]],"id":3805762}],"con":true,"img":false}]}
{"op":"mcm","clk":"5348752482","pt":1646220401603,"mc":[{"id":"1.195453758","rc":[{"atl":[[100,9.9]],"id":3805784},{"atb":[[12,9.9]],"id":3805783},{"atb":[[5.6,3.27],[6.2,2.72]],"id":3805736},{"atb":[[4,33.33],[3.6,0]],"id":522741}],"con":true,"img":false}]}
{"op":"mcm","clk":"5348752501","pt":1646220401821,"mc":[{"id":"1.195453758","rc":[{"atb":[[6.2,14.71]],"id":522749}],"con":true,"img":false}]}
{"op":"mcm","clk":"5348752521","pt":1646220402018,"mc":[{"id":"1.195453758","rc":[{"atl":[[85,0],[60,2]],"id":3805755},{"atl":[[29,28.8],[30,3.45]],"id":522749}],"con":true,"img":false}]}
{"op":"mcm","clk":"5348752535","pt":1646220402125,"mc":[{"id":"1.195453758","rc":[{"atb":[[32,0]],"id":3805762}],"con":true,"img":false}]}
{"op":"mcm","clk":"5348752569","pt":1646220402366,"mc":[{"id":"1.195453758","rc":[{"atb":[[15,0]],"id":3805755}],"con":true,"img":false}]}
{"op":"mcm","clk":"5348752586","pt":1646220402426,"mc":[{"id":"1.195453758","rc":[{"atb":[[11.5,25.35]],"id":3805740}],"con":true,"img":false}]}
{"op":"mcm","clk":"5348752608","pt":1646220402535,"mc":[{"id":"1.195453758","rc":[{"atb":[[14,2.72]],"id":3805740}],"con":true,"img":false}]}
{"op":"mcm","clk":"5348752618","pt":1646220402667,"mc":[{"id":"1.195453758","rc":[{"atb":[[5.9,2.72]],"id":522749}],"con":true,"img":false}]}
{"op":"mcm","clk":"5348752660","pt":1646220402903,"mc":[{"id":"1.195453758","rc":[{"atb":[[13,40.88],[14.5,2.72]],"id":3805755}],"con":true,"img":false}]}
{"op":"mcm","clk":"5348752696","pt":1646220403229,"mc":[{"id":"1.195453758","rc":[{"atl":[[10.5,16.68],[11.5,9.9],[12.5,0],[9.8,4.95]],"id":522747}],"con":true,"img":false}]}
{"op":"mcm","clk":"5348752706","pt":1646220403330,"mc":[{"id":"1.195453758","rc":[{"atl":[[70,31.02],[26,9.9]],"id":522753}],"con":true,"img":false}]}
{"op":"mcm","clk":"5348752877","pt":1646220404529,"mc":[{"id":"1.195453758","rc":[{"atb":[[3.95,33.9],[5.9,24.81]],"id":522749}],"con":true,"img":false}]}
{"op":"mcm","clk":"5348752913","pt":1646220404804,"mc":[{"id":"1.195453758","rc":[{"atb":[[6.8,0]],"id":522743}],"con":true,"img":false}]}
{"op":"mcm","clk":"5348752935","pt":1646220405002,"mc":[{"id":"1.195453758","rc":[{"atb":[[5.9,20.41]],"id":522743}],"con":true,"img":false}]}
{"op":"mcm","clk":"5348752944","pt":1646220405104,"mc":[{"id":"1.195453758","rc":[{"atl":[[85,4.95],[90,0],[110,9.9],[120,14.95]],"id":3805762},{"atb":[[4.8,9.9],[5.1,38.66],[5.2,4.95],[4.7,47.56]],"id":522741}],"con":true,"img":false}]}
{"op":"mcm","clk":"5348752955","pt":1646220405209,"mc":[{"id":"1.195453758","rc":[{"atl":[[9.6,0],[11,0],[11.5,9.9],[9.8,4.95]],"id":522749}],"con":true,"img":false}]}
{"op":"mcm","clk":"5348753007","pt":1646220405629,"mc":[{"id":"1.195453758","rc":[{"atb":[[5.3,36.87],[4.9,42.92],[4.7,0]],"id":522741}],"con":true,"img":false}]}
{"op":"mcm","clk":"5348753017","pt":1646220405729,"mc":[{"id":"1.195453758","rc":[{"atl":[[9.8,22.97]],"id":522747}],"con":true,"img":false}]}
{"op":"mcm","clk":"5348753092","pt":1646220406322,"mc":[{"id":"1.195453758","rc":[{"atb":[[6.4,9.9],[6.2,45.22]],"id":3805736},{"atl":[[11.5,68.85],[25,4.17]],"id":522747}],"con":true,"img":false}]}
{"op":"mcm","clk":"5348753098","pt":1646220406424,"mc":[{"id":"1.195453758","rc":[{"atb":[[5.1,0]],"id":522741}],"con":true,"img":false}]}
{"op":"mcm","clk":"5348753123","pt":1646220406637,"mc":[{"id":"1.195453758","rc":[{"atl":[[10.5,0]],"id":522747}],"con":true,"img":false}]}
{"op":"mcm","clk":"5348753241","pt":1646220407735,"mc":[{"id":"1.195453758","rc":[{"atb":[[6.6,29.59]],"id":522747}],"con":true,"img":false}]}
{"op":"mcm","clk":"5348753325","pt":1646220408416,"mc":[{"id":"1.195453758","rc":[{"atb":[[6,4.95]],"id":522747}],"con":true,"img":false}]}
{"op":"mcm","clk":"5348753585","pt":1646220410633,"mc":[{"id":"1.195453758","rc":[{"atl":[[10,4.95],[12,9.9]],"id":522749},{"atl":[[42,31.99]],"id":3805740}],"con":true,"img":false}]}
{"op":"mcm","clk":"5348753595","pt":1646220410729,"mc":[{"id":"1.195453758","rc":[{"atl":[[11.5,0],[9.8,0]],"id":522749}],"con":true,"img":false}]}
{"op":"mcm","clk":"5348753627","pt":1646220411145,"mc":[{"id":"1.195453758","rc":[{"atl":[[11.5,22.08],[29,5.66]],"id":522749}],"con":true,"img":false}]}
{"op":"mcm","clk":"5348753634","pt":1646220411203,"mc":[{"id":"1.195453758","rc":[{"atl":[[11.5,9.9],[25,82.29]],"id":522747}],"con":true,"img":false}]}
{"op":"mcm","clk":"5348753652","pt":1646220411413,"mc":[{"id":"1.195453758","rc":[{"atl":[[10,19.66]],"id":522749},{"atl":[[34,9.76]],"id":3805740}],"con":true,"img":false}]}
{"op":"mcm","clk":"5348753665","pt":1646220411518,"mc":[{"id":"1.195453758","rc":[{"atl":[[110,24.62],[120,0]],"id":3805762}],"con":true,"img":false}]}
{"op":"mcm","clk":"5348753727","pt":1646220412349,"mc":[{"id":"1.195453758","rc":[{"atl":[[29,0]],"id":522749},{"atl":[[40,0]],"id":3805740}],"con":true,"img":false}]}
{"op":"mcm","clk":"5348754005","pt":1646220415446,"mc":[{"id":"1.195453758","rc":[{"atl":[[75,29.55],[42,9.9]],"id":3805740}],"con":true,"img":false}]}
{"op":"mcm","clk":"5348754019","pt":1646220415559,"mc":[{"id":"1.195453758","rc":[{"atb":[[18.5,0],[22,0]],"id":3805731},{"atb":[[23,0],[28,24.86]],"id":3805762},{"atb":[[11.5,22.08],[14,0]],"id":3805740}],"con":true,"img":false}]}
{"op":"mcm","clk":"5348754056","pt":1646220415827,"mc":[{"id":"1.195453758","rc":[{"atb":[[20,0],[25,0]],"id":3805784}],"con":true,"img":false}]}
{"op":"mcm","clk":"5348754094","pt":1646220416048,"mc":[{"id":"1.195453758","rc":[{"atl":[[11.5,0],[12,61.02]],"id":522749},{"atb":[[10,51.24],[11.5,0]],"id":3805740}],"con":true,"img":false}]}
{"op":"mcm","clk":"5348754142","pt":1646220416277,"mc":[{"id":"1.195453758","rc":[{"atb":[[19,3.27],[23,2.72]],"id":3805731},{"atb":[[24,3.27],[29,2.72]],"id":3805762},{"atb":[[12,3.27],[14.5,2.72]],"id":3805740}],"con":true,"img":false}]}
{"op":"mcm","clk":"5348754248","pt":1646220416575,"mc":[{"id":"1.195453758","rc":[{"atb":[[21,3.27]],"id":3805784}],"con":true,"img":false}]}
{"op":"mcm","clk":"5348754279","pt":1646220416796,"mc":[{"id":"1.195453758","rc":[{"atb":[[26,2.72]],"id":3805784},{"atb":[[29,16.81]],"id":3805762},{"atb":[[4.9,40.19],[4.4,0]],"id":522741}],"con":true,"img":false}]}
{"op":"mcm","clk":"5348754290","pt":1646220416854,"mc":[{"id":"1.195453758","rc":[{"atb":[[28,9.9]],"id":3805762}],"con":true,"img":false}]}
{"op":"mcm","clk":"5348754387","pt":1646220417571,"mc":[{"id":"1.195453758","rc":[{"atb":[[4.5,3.27],[5,2.72]],"id":522741}],"con":true,"img":false}]}
{"op":"mcm","clk":"5348754466","pt":1646220418025,"mc":[{"id":"1.195453758","rc":[{"atb":[[5,42.92],[4.9,0]],"id":522741}],"con":true,"img":false}]}
{"op":"mcm","clk":"5348754994","pt":1646220420846,"mc":[{"id":"1.195453758","rc":[{"atl":[[12,9.9],[30,54.56]],"id":522749}],"con":true,"img":false}]}
{"op":"mcm","clk":"5348755007","pt":1646220420950,"mc":[{"id":"1.195453758","rc":[{"atb":[[4.6,0],[5.5,22.22]],"id":3805793},{"atb":[[2.6,20.33]],"id":3805731},{"atb":[[4,0],[3.7,37.04]],"id":522741},{"atb":[[10,40.13],[7.4,15.62]],"id":3805740}],"con":true,"img":false}]}
{"op":"mcm","clk":"5348755028","pt":1646220421064,"mc":[{"id":"1.195453758","rc":[{"atb":[[2.16,0]],"id":3805731}],"con":true,"img":false}]}
{"op":"mcm","clk":"5348755807","pt":1646220425893,"mc":[{"id":"1.195453758","rc":[{"atb":[[10,0],[12,32.51]],"id":3805740}],"con":true,"img":false}]}
{"op":"mcm","clk":"5348756074","pt":1646220427279,"mc":[{"id":"1.195453758","rc":[{"atb":[[4.5,0],[5,40.19]],"id":522741}],"con":true,"img":false}]}
{"op":"mcm","clk":"5348756187","pt":1646220427960,"mc":[{"id":"1.195453758","rc":[{"atb":[[4.8,12.63],[4.3,3.27]],"id":522741}],"con":true,"img":false}]}
{"op":"mcm","clk":"5348759276","pt":1646220442383,"mc":[{"id":"1.195453758","rc":[{"atl":[[10,14.71],[11.5,9.9],[12,0],[9.8,4.95]],"id":522749}],"con":true,"img":false}]}
{"op":"mcm","clk":"5348759383","pt":1646220442869,"mc":[{"id":"1.195453758","rc":[{"atl":[[11.5,46.51],[9.8,22.97],[30,3.45]],"id":522749}],"con":true,"img":false}]}
{"op":"mcm","clk":"5348759406","pt":1646220442982,"mc":[{"id":"1.195453758","rc":[{"atl":[[17.5,14.56],[18,0],[19.5,9.9],[20,28.19]],"id":522743},{"atb":[[16.5,4.95],[14.5,12.63],[15.5,10.93]],"id":3805740}],"con":true,"img":false}]}
{"op":"mcm","clk":"5348759510","pt":1646220443360,"mc":[{"id":"1.195453758","rc":[{"atb":[[17,9.9],[12,3.27],[14.5,43.61]],"id":3805740}],"con":true,"img":false}]}
{"op":"mcm","clk":"5348759550","pt":1646220443575,"mc":[{"id":"1.195453758","rc":[{"atl":[[10,0]],"id":522749}],"con":true,"img":false}]}
{"op":"mcm","clk":"5348759644","pt":1646220444110,"mc":[{"id":"1.195453758","rc":[{"atb":[[15.5,0]],"id":3805740}],"con":true,"img":false}]}
{"op":"mcm","clk":"5348760004","pt":1646220446117,"mc":[{"id":"1.195453758","rc":[{"atl":[[24,4.95],[26,0],[28,9.9],[30,23.79]],"id":3805755}],"con":true,"img":false}]}
{"op":"mcm","clk":"5348760146","pt":1646220446613,"mc":[{"id":"1.195453758","rc":[{"atl":[[24,11.84],[28,34.46],[30,0]],"id":3805755}],"con":true,"img":false}]}
{"op":"mcm","clk":"5348760226","pt":1646220446990,"mc":[{"id":"1.195453758","rc":[{"atl":[[21,4.95],[22,7.54],[25,9.9],[26,0]],"id":3805730}],"con":true,"img":false}]}
{"op":"mcm","clk":"5348760349","pt":1646220447379,"mc":[{"id":"1.195453758","rc":[{"atl":[[25,0]],"id":3805755},{"atl":[[11.5,9.9],[30,59.47]],"id":522749}],"con":true,"img":false}]}
{"op":"mcm","clk":"5348760382","pt":1646220447492,"mc":[{"id":"1.195453758","rc":[{"atl":[[20,8.34],[25,39.36],[27,0]],"id":3805730}],"con":true,"img":false}]}
{"op":"mcm","clk":"5348760618","pt":1646220448311,"mc":[{"id":"1.195453758","rc":[{"atl":[[22,0]],"id":3805730}],"con":true,"img":false}]}
{"op":"mcm","clk":"5348760775","pt":1646220449024,"mc":[{"id":"1.195453758","rc":[{"atl":[[9.6,4.95],[11,9.9],[11.5,0],[9.8,18.01]],"id":522747}],"con":true,"img":false}]}
{"op":"mcm","clk":"5348760861","pt":1646220449520,"mc":[{"id":"1.195453758","rc":[{"atl":[[9.6,23.39],[11,51.42],[25,4.17]],"id":522747}],"con":true,"img":false}]}
{"op":"mcm","clk":"5348761008","pt":1646220450287,"mc":[{"id":"1.195453758","rc":[{"atl":[[9.8,0]],"id":522747}],"con":true,"img":false}]}
{"op":"mcm","clk":"5348761057","pt":1646220450516,"mc":[{"id":"1.195453758","rc":[{"atb":[[5.6,0],[6.2,42.49]],"id":3805736}],"con":true,"img":false}]}
{"op":"mcm","clk":"5348761167","pt":1646220451104,"mc":[{"id":"1.195453758","rc":[{"atl":[[28,9.9],[60,35.86]],"id":3805755}],"con":true,"img":false}]}
{"op":"mcm","clk":"5348761202","pt":1646220451275,"mc":[{"id":"1.195453758","rc":[{"atb":[[5.8,3.27],[6.6,2.72]],"id":3805736}],"con":true,"img":false}]}
{"op":"mcm","clk":"5348761286","pt":1646220451708,"mc":[{"id":"1.195453758","rc":[{"atb":[[6.2,0]],"id":3805736},{"atl":[[9.6,4.95],[11,9.9]],"id":522749}],"con":true,"img":false}]}
{"op":"mcm","clk":"5348761310","pt":1646220451819,"mc":[{"id":"1.195453758","rc":[{"atb":[[6.4,45.25]],"id":3805736},{"atl":[[11.5,0],[9.8,18.01]],"id":522749}],"con":true,"img":false}]}
{"op":"mcm","clk":"5348761402","pt":1646220452213,"mc":[{"id":"1.195453758","rc":[{"atl":[[9.6,23.39],[11,46.51],[30,3.45]],"id":522749}],"con":true,"img":false}]}
{"op":"mcm","clk":"5348761611","pt":1646220452988,"mc":[{"id":"1.195453758","rc":[{"atl":[[9.8,0]],"id":522749}],"con":true,"img":false}]}
{"op":"mcm","clk":"5348761841","pt":1646220453899,"mc":[{"id":"1.195453758","rc":[{"atl":[[25,82.91]],"id":522747}],"con":true,"img":false}]}
{"op":"mcm","clk":"5348761859","pt":1646220454007,"mc":[{"id":"1.195453758","rc":[{"atl":[[11,9.9]],"id":522747}],"con":true,"img":false}]}
{"op":"mcm","clk":"5348762148","pt":1646220456107,"mc":[{"id":"1.195453758","rc":[{"atb":[[6.6,2.72]],"id":522747}],"con":true,"img":false}]}
{"op":"mcm","clk":"5348762237","pt":1646220456691,"mc":[{"id":"1.195453758","rc":[{"atl":[[11,9.9],[30,60.09]],"id":522749}],"con":true,"img":false}]}
{"op":"mcm","clk":"5348762248","pt":1646220456798,"mc":[{"id":"1.195453758","rc":[{"atb":[[6,36.66]],"id":522747}],"con":true,"img":false}]}
{"op":"mcm","clk":"5348762279","pt":1646220457009,"mc":[{"id":"1.195453758","rc":[{"atl":[[23,6.82],[27,0]],"id":3805783},{"atl":[[32,4.95],[34,4.8],[40,9.9],[42,0]],"id":3805740}],"con":true,"img":false}]}
{"op":"mcm","clk":"5348762290","pt":1646220457107,"mc":[{"id":"1.195453758","rc":[{"atl":[[24,4.95],[28,34.78]],"id":3805783},{"atb":[[9.6,14.71],[11.5,8.91]],"id":522743}],"con":true,"img":false}]}
{"op":"mcm","clk":"5348762304","pt":1646220457216,"mc":[{"id":"1.195453758","rc":[{"atb":[[6,31.7]],"id":522747},{"atl":[[70,4.95],[80,18.83],[90,9.9],[60,0]],"id":3805731},{"atl":[[17.5,0],[19.5,28.59],[19,4.95],[22,9.9]],"id":522745}],"con":true,"img":false}]}
{"op":"mcm","clk":"5348762316","pt":1646220457277,"mc":[{"id":"1.195453758","rc":[{"atb":[[32,9.9],[38,4.28],[40,4.95],[30,0]],"id":3805784}],"con":true,"img":false}]}
{"op":"mcm","clk":"5348762368","pt":1646220457693,"mc":[{"id":"1.195453758","rc":[{"atb":[[32,24.62],[42,3.86],[29,0]],"id":3805784},{"atl":[[32,10.06],[75,2],[40,31.99]],"id":3805740}],"con":true,"img":false}]}
{"op":"mcm","clk":"5348762379","pt":1646220457795,"mc":[{"id":"1.195453758","rc":[{"atb":[[12,0],[14,0]],"id":3805783},{"atb":[[11,2.72],[9.4,13.17]],"id":522743}],"con":true,"img":false}]}
{"op":"mcm","clk":"5348762386","pt":1646220457909,"mc":[{"id":"1.195453758","rc":[{"atb":[[12.5,9.9],[14.5,4.95]],"id":3805783}],"con":true,"img":false}]}
{"op":"mcm","clk":"5348762423","pt":1646220458175,"mc":[{"id":"1.195453758","rc":[{"atb":[[13.5,2.72]],"id":3805783}],"con":true,"img":false}]}
{"op":"mcm","clk":"5348762436","pt":1646220458279,"mc":[{"id":"1.195453758","rc":[{"atb":[[11,29.67]],"id":3805783},{"atb":[[9.6,0],[10.5,32.94]],"id":522743}],"con":true,"img":false}]}
{"op":"mcm","clk":"5348762445","pt":1646220458381,"mc":[{"id":"1.195453758","rc":[{"atb":[[38,0]],"id":3805784},{"atl":[[34,0]],"id":3805740}],"con":true,"img":false}]}
{"op":"mcm","clk":"5348762709","pt":1646220460703,"mc":[{"id":"1.195453758","rc":[{"atb":[[5.6,0],[5.8,57.72]],"id":522747},{"atl":[[21,4.95],[22,7.54],[25,9.9],[26,0]],"id":522753},{"atl":[[8,0],[7.2,0],[7.6,4.95]],"id":522741},{"atl":[[18,4.95],[19,0],[20,9.9],[22,0]],"id":522745}],"con":true,"img":false}]}
{"op":"mcm","clk":"5348762765","pt":1646220461179,"mc":[{"id":"1.195453758","rc":[{"atl":[[70,2],[21,12.88],[25,36.05]],"id":522753}],"con":true,"img":false}]}
{"op":"mcm","clk":"5348762879","pt":1646220461967,"mc":[{"id":"1.195453758","rc":[{"atl":[[22,0]],"id":522753}],"con":true,"img":false}]}
{"op":"mcm","clk":"5348762893","pt":1646220462076,"mc":[{"id":"1.195453758","rc":[{"atl":[[75,29.73],[40,9.9]],"id":3805740}],"con":true,"img":false}]}
{"op":"mcm","clk":"5348763325","pt":1646220465499,"mc":[{"id":"1.195453758","rc":[{"atl":[[70,31.71],[25,9.9]],"id":522753}],"con":true,"img":false}]}
{"op":"mcm","clk":"5348763511","pt":1646220467182,"mc":[{"id":"1.195453758","rc":[{"atb":[[11,3.27]],"id":3805783}],"con":true,"img":false}]}
{"op":"mcm","clk":"5348763524","pt":1646220467288,"mc":[{"id":"1.195453758","rc":[{"atb":[[13.5,20.23]],"id":3805783},{"atb":[[4.8,9.9],[4.3,0]],"id":522741}],"con":true,"img":false}]}
{"op":"mcm","clk":"5348763598","pt":1646220468028,"mc":[{"id":"1.195453758","rc":[{"atb":[[4.5,3.27],[5,42.92]],"id":522741}],"con":true,"img":false}]}
{"op":"mcm","clk":"5348763781","pt":1646220469911,"mc":[{"id":"1.195453758","rc":[{"atl":[[9.6,0],[11,0],[11.5,9.9],[9.8,4.95]],"id":522749}],"con":true,"img":false}]}
{"op":"mcm","clk":"5348763852","pt":1646220470594,"mc":[{"id":"1.195453758","rc":[{"atl":[[29,5.66]],"id":522749}],"con":true,"img":false}]}
{"op":"mcm","clk":"5348763887","pt":1646220471012,"mc":[{"id":"1.195453758","rc":[{"atl":[[9.8,0]],"id":522741}],"con":true,"img":false}]}
{"op":"mcm","clk":"5348763901","pt":1646220471223,"mc":[{"id":"1.195453758","rc":[{"atb":[[12.5,0],[14,4.95],[14.5,0]],"id":3805783},{"atl":[[23,11.78],[24,0],[27,9.9],[28,24.88]],"id":3805783},{"atl":[[29,28.8],[30,3.45]],"id":522749},{"atb":[[4.8,0],[5.2,0]],"id":522741},{"atl":[[11.5,9.52]],"id":522741}],"con":true,"img":false}]}
{"op":"mcm","clk":"5348763910","pt":1646220471325,"mc":[{"id":"1.195453758","rc":[{"atb":[[5.6,0],[6.2,19.66],[6,0],[5.7,9.9]],"id":522749},{"atb":[[5.3,41.82],[4.9,9.9]],"id":522741}],"con":true,"img":false}]}
{"op":"mcm","clk":"5348763950","pt":1646220471696,"mc":[{"id":"1.195453758","rc":[{"atb":[[4.5,90.9],[5,2.72]],"id":522741}],"con":true,"img":false}]}
{"op":"mcm","clk":"5348763959","pt":1646220471802,"mc":[{"id":"1.195453758","rc":[{"atb":[[5.7,53.87],[5.9,2.72]],"id":522749}],"con":true,"img":false}]}
{"op":"mcm","clk":"5348763980","pt":1646220472010,"mc":[{"id":"1.195453758","rc":[{"atb":[[12,9.9]],"id":3805783}],"con":true,"img":false}]}
{"op":"mcm","clk":"5348764434","pt":1646220476523,"mc":[{"id":"1.195453758","rc":[{"atl":[[10,4.95],[11.5,0],[12,9.9],[9.8,0]],"id":522749}],"con":true,"img":false}]}
{"op":"mcm","clk":"5348764499","pt":1646220477113,"mc":[{"id":"1.195453758","rc":[{"atl":[[9.6,0],[10.5,4.95],[11,0],[12.5,9.9]],"id":522747},{"atl":[[21,0],[23,4.95],[25,0],[27,9.9]],"id":522753}],"con":true,"img":false}]}
{"op":"mcm","clk":"5348764581","pt":1646220477842,"mc":[{"id":"1.195453758","rc":[{"atl":[[12,11.41]],"id":522747},{"atl":[[22,4.95],[23,0],[26,16.25],[27,0]],"id":522753}],"con":true,"img":false}]}
{"op":"mcm","clk":"5348764646","pt":1646220478315,"mc":[{"id":"1.195453758","rc":[{"atl":[[12.5,41.61],[25,4.17]],"id":522747}],"con":true,"img":false}]}
{"op":"mcm","clk":"5348764657","pt":1646220478416,"mc":[{"id":"1.195453758","rc":[{"atb":[[9.6,58.26],[11,4.95],[11.5,2.72],[9.8,0]],"id":3805730}],"con":true,"img":false}]}
{"op":"mcm","clk":"5348764666","pt":1646220478526,"mc":[{"id":"1.195453758","rc":[{"atl":[[22,0],[23,4.95],[26,6.34],[27,9.9]],"id":522753}],"con":true,"img":false}]}
{"op":"mcm","clk":"5348764725","pt":1646220478994,"mc":[{"id":"1.195453758","rc":[{"atl":[[70,2],[27,36.05]],"id":522753}],"con":true,"img":false}]}
{"op":"mcm","clk":"5348764745","pt":1646220479204,"mc":[{"id":"1.195453758","rc":[{"atb":[[11,19.66]],"id":3805730}],"con":true,"img":false}]}
{"op":"mcm","clk":"5348764773","pt":1646220479411,"mc":[{"id":"1.195453758","rc":[{"atl":[[28,5.86]],"id":522749}],"con":true,"img":false}]}
{"op":"mcm","clk":"5348764827","pt":1646220479930,"mc":[{"id":"1.195453758","rc":[{"atl":[[28,29.32],[29,5.66]],"id":522749}],"con":true,"img":false}]}
{"op":"mcm","clk":"5348764887","pt":1646220480404,"mc":[{"id":"1.195453758","rc":[{"atl":[[29,0]],"id":522749}],"con":true,"img":false}]}
{"op":"mcm","clk":"5348764895","pt":1646220480505,"mc":[{"id":"1.195453758","rc":[{"atb":[[4.5,3.27],[4.9,57.47]],"id":522741}],"con":true,"img":false}]}
{"op":"mcm","clk":"5348764986","pt":1646220481400,"mc":[{"id":"1.195453758","rc":[{"atb":[[32,4.95],[26,0],[27,9.9],[30,5.46]],"id":3805731}],"con":true,"img":false}]}
{"op":"mcm","clk":"5348765030","pt":1646220481829,"mc":[{"id":"1.195453758","rc":[{"atb":[[8.2,0],[6.6,17.86]],"id":3805783},{"atb":[[4.3,0],[5,25]],"id":3805736},{"atb":[[2.88,20.33],[2.6,0],[27,25.39]],"id":3805731}],"con":true,"img":false}]}
{"op":"mcm","clk":"5348765038","pt":1646220481930,"mc":[{"id":"1.195453758","rc":[{"atb":[[32,10.06],[25,0]],"id":3805731}],"con":true,"img":false}]}
{"op":"mcm","clk":"5348765125","pt":1646220482617,"mc":[{"id":"1.195453758","rc":[{"atb":[[30,0]],"id":3805731}],"con":true,"img":false}]}
{"op":"mcm","clk":"5348765521","pt":1646220485936,"mc":[{"id":"1.195453758","rc":[{"atb":[[23,25.04],[27,9.9]],"id":3805731}],"con":true,"img":false}]}
{"op":"mcm","clk":"5348765555","pt":1646220486351,"mc":[{"id":"1.195453758","rc":[{"atb":[[15.5,0]],"id":3805755},{"atl":[[10,17.61]],"id":522747},{"atl":[[10,0],[10.5,9.9],[12,0],[9.4,4.95]],"id":522749},{"atl":[[23,12.15]],"id":522753}],"con":true,"img":false}]}
{"op":"mcm","clk":"5348765605","pt":1646220486827,"mc":[{"id":"1.195453758","rc":[{"atb":[[12,35.61],[13,9.9]],"id":3805755},{"atl":[[17.5,9.6],[17,4.95],[19.5,0],[19,9.9]],"id":522743}],"con":true,"img":false}]}
{"op":"mcm","clk":"5348765617","pt":1646220486919,"mc":[{"id":"1.195453758","rc":[{"atl":[[12,54.56],[12.5,9.9]],"id":522747}],"con":true,"img":false}]}
{"op":"mcm","clk":"5348765629","pt":1646220487032,"mc":[{"id":"1.195453758","rc":[{"atb":[[13,23.11]],"id":3805755},{"atl":[[12,43.14]],"id":522747},{"atl":[[26,0]],"id":522753}],"con":true,"img":false}]}
{"op":"mcm","clk":"5348765662","pt":1646220487331,"mc":[{"id":"1.195453758","rc":[{"atl":[[16.5,10.22],[19,37.45],[20,0]],"id":522743}],"con":true,"img":false}]}
{"op":"mcm","clk":"5348765675","pt":1646220487543,"mc":[{"id":"1.195453758","rc":[{"atl":[[70,31.71],[27,9.9]],"id":522753}],"con":true,"img":false}]}
{"op":"mcm","clk":"5348765696","pt":1646220487706,"mc":[{"id":"1.195453758","rc":[{"atb":[[11.5,17.82]],"id":3805730}],"con":true,"img":false}]}
{"op":"mcm","clk":"5348765712","pt":1646220487912,"mc":[{"id":"1.195453758","rc":[{"atl":[[9.4,23.82]],"id":522749}],"con":true,"img":false}]}
{"op":"mcm","clk":"5348765737","pt":1646220488124,"mc":[{"id":"1.195453758","rc":[{"atl":[[17.5,0]],"id":522743}],"con":true,"img":false}]}
{"op":"mcm","clk":"5348765761","pt":1646220488435,"mc":[{"id":"1.195453758","rc":[{"atb":[[11,4.95]],"id":3805730}],"con":true,"img":false}]}
{"op":"mcm","clk":"5348765789","pt":1646220488744,"mc":[{"id":"1.195453758","rc":[{"atl":[[28,23.45]],"id":522749}],"con":true,"img":false}]}
{"op":"mcm","clk":"5348765919","pt":1646220489844,"mc":[{"id":"1.195453758","rc":[{"atl":[[23,4.95],[24,6.89],[27,9.9],[28,0]],"id":3805755}],"con":true,"img":false}]}
{"op":"mcm","clk":"5348765976","pt":1646220490371,"mc":[{"id":"1.195453758","rc":[{"atl":[[23,12.15],[27,34.88],[60,2]],"id":3805755}],"con":true,"img":false}]}
{"op":"mcm","clk":"5348766069","pt":1646220491149,"mc":[{"id":"1.195453758","rc":[{"atl":[[24,0]],"id":3805755}],"con":true,"img":false}]}
{"op":"mcm","clk":"5348766196","pt":1646220492615,"mc":[{"id":"1.195453758","rc":[{"atl":[[10,22.56],[10.5,0],[12,53.05],[12.5,0]],"id":522747}],"con":true,"img":false}]}
{"op":"mcm","clk":"5348766232","pt":1646220493033,"mc":[{"id":"1.195453758","rc":[{"atl":[[12,9.9],[25,84.85]],"id":522747}],"con":true,"img":false}]}
{"op":"mcm","clk":"5348766337","pt":1646220494334,"mc":[{"id":"1.195453758","rc":[{"atl":[[60,36.67]],"id":3805755}],"con":true,"img":false}]}
{"op":"mcm","clk":"5348766346","pt":1646220494437,"mc":[{"id":"1.195453758","rc":[{"atl":[[27,9.9]],"id":3805755}],"con":true,"img":false}]}
{"op":"mcm","clk":"5348766419","pt":1646220495410,"mc":[{"id":"1.195453758","rc":[{"atb":[[14.5,14.47]],"id":3805755}],"con":true,"img":false}]}
{"op":"mcm","clk":"5348766502","pt":1646220496237,"mc":[{"id":"1.195453758","rc":[{"atb":[[13,9.9]],"id":3805755}],"con":true,"img":false}]}
{"op":"mcm","clk":"5348766541","pt":1646220496762,"mc":[{"id":"1.195453758","rc":[{"atl":[[10,0],[10.5,4.95],[12,0],[12.5,9.9]],"id":522747}],"con":true,"img":false}]}
{"op":"mcm","clk":"5348766601","pt":1646220497429,"mc":[{"id":"1.195453758","rc":[{"atl":[[24,6.89]],"id":522747}],"con":true,"img":false}]}
{"op":"mcm","clk":"5348766640","pt":1646220497949,"mc":[{"id":"1.195453758","rc":[{"atl":[[24,31.86],[25,4.17]],"id":522747}],"con":true,"img":false}]}
{"op":"mcm","clk":"5348766866","pt":1646220500430,"mc":[{"id":"1.195453758","rc":[{"atl":[[9.2,4.95],[10,9.9],[10.5,0],[9.4,18.87]],"id":522749}],"con":true,"img":false}]}
{"op":"mcm","clk":"5348766910","pt":1646220500950,"mc":[{"id":"1.195453758","rc":[{"atl":[[9.2,24.29],[10,52.68],[28,0]],"id":522749}],"con":true,"img":false}]}
{"op":"mcm","clk":"5348766975","pt":1646220501731,"mc":[{"id":"1.195453758","rc":[{"atl":[[9.4,0]],"id":522749}],"con":true,"img":false}]}
{"op":"mcm","clk":"5348767143","pt":1646220503469,"mc":[{"id":"1.195453758","rc":[{"atb":[[4.5,0],[5,0]],"id":522741},{"atb":[[11,0],[9.4,9.9]],"id":522743}],"con":true,"img":false}]}
{"op":"mcm","clk":"5348767168","pt":1646220503674,"mc":[{"id":"1.195453758","rc":[{"atb":[[7.2,8.91],[6.4,35.34],[6.6,7.67],[5.9,9.9]],"id":3805736},{"atl":[[10,4.95],[10.5,14.71],[12,9.9],[12.5,0]],"id":3805736},{"atb":[[9.6,22.08],[11,15.85],[11.5,4.95],[9.8,9.9]],"id":522745},{"atl":[[18,0],[19,4.95],[20,0]],"id":522745}],"con":true,"img":false}]}
{"op":"mcm","clk":"5348767177","pt":1646220503726,"mc":[{"id":"1.195453758","rc":[{"atl":[[22,4.95],[23,7.2],[26,9.9],[27,0]],"id":522753}],"con":true,"img":false}]}
{"op":"mcm","clk":"5348767185","pt":1646220503832,"mc":[{"id":"1.195453758","rc":[{"atl":[[28,0],[15.5,6.9]],"id":3805736},{"atb":[[3.7,154.25]],"id":522741},{"atb":[[10.5,4.95],[9.4,39.84]],"id":522743}],"con":true,"img":false}]}
{"op":"mcm","clk":"5348767196","pt":1646220503937,"mc":[{"id":"1.195453758","rc":[{"atb":[[4.9,9.9]],"id":522741}],"con":true,"img":false}]}
{"op":"mcm","clk":"5348767215","pt":1646220504149,"mc":[{"id":"1.195453758","rc":[{"atl":[[12,37.89],[25,0],[9.8,18.01]],"id":3805736},{"atb":[[5.1,2.72],[4.6,3.27]],"id":522741},{"atb":[[9.6,3.27],[11.5,11.64]],"id":522743},{"atb":[[9.6,0],[10.5,24.81],[12,14.41]],"id":522745}],"con":true,"img":false}]}
{"op":"mcm","clk":"5348767224","pt":1646220504251,"mc":[{"id":"1.195453758","rc":[{"atl":[[70,2],[22,12.5],[26,36.05]],"id":522753}],"con":true,"img":false}]}
{"op":"mcm","clk":"5348767257","pt":1646220504623,"mc":[{"id":"1.195453758","rc":[{"atb":[[3.7,37.04]],"id":522741}],"con":true,"img":false}]}
{"op":"mcm","clk":"5348767270","pt":1646220504830,"mc":[{"id":"1.195453758","rc":[{"atl":[[10,9.9],[30,68.79]],"id":522749},{"atb":[[11,0]],"id":522745}],"con":true,"img":false}]}
{"op":"mcm","clk":"5348767276","pt":1646220504931,"mc":[{"id":"1.195453758","rc":[{"atl":[[10.5,0]],"id":3805736}],"con":true,"img":false}]}
{"op":"mcm","clk":"5348767282","pt":1646220505038,"mc":[{"id":"1.195453758","rc":[{"atl":[[23,0]],"id":522753}],"con":true,"img":false}]}
{"op":"mcm","clk":"5348767329","pt":1646220505662,"mc":[{"id":"1.195453758","rc":[{"atl":[[10.5,21.64]],"id":522747}],"con":true,"img":false}]}
{"op":"mcm","clk":"5348767401","pt":1646220506448,"mc":[{"id":"1.195453758","rc":[{"atl":[[24,24.97]],"id":522747}],"con":true,"img":false}]}
{"op":"mcm","clk":"5348767576","pt":1646220508172,"mc":[{"id":"1.195453758","rc":[{"atl":[[70,31.71],[26,9.9]],"id":522753}],"con":true,"img":false}]}
{"op":"mcm","clk":"5348767976","pt":1646220511835,"mc":[{"id":"1.195453758","rc":[{"atb":[[4.9,57.47]],"id":522741},{"atb":[[9.6,25.83],[9.4,9.9]],"id":522743}],"con":true,"img":false}]}
{"op":"mcm","clk":"5348768414","pt":1646220516572,"mc":[{"id":"1.195453758","rc":[{"atl":[[23,7.2],[25,4.95],[27,0],[29,9.9]],"id":3805755},{"atb":[[6.8,4.95],[6,9.9],[6.6,2.72],[5.9,0]],"id":3805736},{"atb":[[5.8,52.76],[5.5,9.9],[5.9,4.95]],"id":522747},{"atb":[[34,0],[36,9.48],[28,0],[29,26.72]],"id":3805762},{"atl":[[8.2,9.9],[7.4,4.95],[7.6,0]],"id":522741},{"atl":[[18.5,4.95],[19,0],[21,9.9]],"id":522745}],"con":true,"img":false}]}
{"op":"mcm","clk":"5348768449","pt":1646220516940,"mc":[{"id":"1.195453758","rc":[{"atb":[[6.6,23.34]],"id":3805736}],"con":true,"img":false}]}
{"op":"mcm","clk":"5348768457","pt":1646220517046,"mc":[{"id":"1.195453758","rc":[{"atl":[[29,39.36],[60,2]],"id":3805755},{"atb":[[6.4,0]],"id":3805736},{"atb":[[5.8,3.27],[5.9,51.85]],"id":522747},{"atb":[[24,24.71],[29,12.63]],"id":3805762}],"con":true,"img":false}]}
{"op":"mcm","clk":"5348768747","pt":1646220519766,"mc":[{"id":"1.195453758","rc":[{"atl":[[14.5,7.41],[15.5,0]],"id":3805736},{"atb":[[17,6.25],[14.5,0]],"id":3805762}],"con":true,"img":false}]}
{"op":"mcm","clk":"5348768763","pt":1646220519978,"mc":[{"id":"1.195453758","rc":[{"atl":[[85,4.95]],"id":3805784},{"atl":[[17,0],[19,27.54]],"id":522743}],"con":true,"img":false}]}
{"op":"mcm","clk":"5348768774","pt":1646220520091,"mc":[{"id":"1.195453758","rc":[{"atl":[[80,0],[100,0]],"id":3805784},{"atb":[[5.8,0],[6.6,20.61]],"id":3805736},{"atl":[[130,9.9],[85,0],[95,4.95],[110,14.71]],"id":3805762},{"atl":[[18,4.95],[20,9.9]],"id":522743}],"con":true,"img":false}]}
{"op":"mcm","clk":"5348768800","pt":1646220520355,"mc":[{"id":"1.195453758","rc":[{"atl":[[34,35.54]],"id":522743}],"con":true,"img":false}]}
{"op":"mcm","clk":"5348768811","pt":1646220520462,"mc":[{"id":"1.195453758","rc":[{"atl":[[90,0]],"id":3805784},{"atl":[[19,0]],"id":522743}],"con":true,"img":false}]}
{"op":"mcm","clk":"5348768845","pt":1646220520778,"mc":[{"id":"1.195453758","rc":[{"atl":[[110,9.9]],"id":3805784},{"atb":[[5.8,2.72],[5.3,3.27]],"id":3805736}],"con":true,"img":false}]}
{"op":"mcm","clk":"5348768862","pt":1646220520987,"mc":[{"id":"1.195453758","rc":[{"atb":[[17,8.32],[21,8.27]],"id":3805784},{"atl":[[250,10.31]],"id":3805784},{"atl":[[32,3.23]],"id":522747},{"atl":[[170,0]],"id":3805731},{"atl":[[70,29.71],[100,2]],"id":522753}],"con":true,"img":false}]}
{"op":"mcm","clk":"5348768871","pt":1646220521092,"mc":[{"id":"1.195453758","rc":[{"atl":[[25,0]],"id":522747},{"atl":[[230,2]],"id":3805731}],"con":true,"img":false}]}
{"op":"mcm","clk":"5348768880","pt":1646220521196,"mc":[{"id":"1.195453758","rc":[{"atl":[[22,0],[23,4.95],[26,0],[27,9.9]],"id":522753}],"con":true,"img":false}]}
{"op":"mcm","clk":"5348768894","pt":1646220521304,"mc":[{"id":"1.195453758","rc":[{"atb":[[36,0],[38,9.23],[29,17.44],[30,9.9]],"id":3805793},{"atl":[[85,0],[100,19.66],[110,0]],"id":3805793},{"atl":[[70,0],[80,23.79],[90,0],[55,0]],"id":3805731},{"atb":[[16.5,0],[17.5,4.95],[14.5,33.7],[15.5,9.9]],"id":3805740},{"atl":[[32,5.11],[38,4.95],[40,0],[46,9.9]],"id":3805740}],"con":true,"img":false}]}
{"op":"mcm","clk":"5348768902","pt":1646220521353,"mc":[{"id":"1.195453758","rc":[{"atl":[[65,0]],"id":3805784}],"con":true,"img":false}]}
{"op":"mcm","clk":"5348768913","pt":1646220521462,"mc":[{"id":"1.195453758","rc":[{"atb":[[32,14.71],[36,9.9],[40,0],[44,4.95]],"id":3805784},{"atl":[[85,0],[90,4.95],[110,0],[120,9.9]],"id":3805784}],"con":true,"img":false}]}
{"op":"mcm","clk":"5348768935","pt":1646220521773,"mc":[{"id":"1.195453758","rc":[{"atl":[[100,4.95],[250,10.31]],"id":3805793},{"atl":[[80,4.95],[90,23.11]],"id":3805731},{"atb":[[18,9.32],[14.5,2.72],[15.5,32.23]],"id":3805740},{"atl":[[75,2],[46,32.23]],"id":3805740}],"con":true,"img":false}]}
{"op":"mcm","clk":"5348768945","pt":1646220521879,"mc":[{"id":"1.195453758","rc":[{"atb":[[32,0],[46,3.52]],"id":3805784},{"atl":[[23,0],[27,6.09]],"id":522753}],"con":true,"img":false}]}
{"op":"mcm","clk":"5348768955","pt":1646220521989,"mc":[{"id":"1.195453758","rc":[{"atb":[[36,31.99]],"id":3805784},{"atl":[[9.2,0],[10,0],[10.5,9.9],[9.4,4.95]],"id":522749},{"atl":[[80,6.95],[100,9.9]],"id":3805731}],"con":true,"img":false}]}
{"op":"mcm","clk":"5348768958","pt":1646220522088,"mc":[{"id":"1.195453758","rc":[{"atl":[[90,6.73]],"id":3805784}],"con":true,"img":false}]}
{"op":"mcm","clk":"5348769013","pt":1646220522516,"mc":[{"id":"1.195453758","rc":[{"atl":[[70,0],[100,22.79]],"id":522753}],"con":true,"img":false}]}
{"op":"mcm","clk":"5348769019","pt":1646220522613,"mc":[{"id":"1.195453758","rc":[{"atb":[[42,0]],"id":3805784},{"atl":[[22,4.95],[26,9.9]],"id":522753},{"atb":[[17,0]],"id":3805740}],"con":true,"img":false}]}
{"op":"mcm","clk":"5348769030","pt":1646220522668,"mc":[{"id":"1.195453758","rc":[{"atb":[[36,9.9]],"id":3805784},{"atl":[[10.5,11.41],[9.4,0]],"id":522749}],"con":true,"img":false}]}
{"op":"mcm","clk":"5348769062","pt":1646220523083,"mc":[{"id":"1.195453758","rc":[{"atl":[[11.5,58.47]],"id":522749}],"con":true,"img":false}]}
{"op":"mcm","clk":"5348769068","pt":1646220523193,"mc":[{"id":"1.195453758","rc":[{"atl":[[30,3.45]],"id":522749},{"atl":[[100,2]],"id":522753}],"con":true,"img":false}]}
{"op":"mcm","clk":"5348769090","pt":1646220523400,"mc":[{"id":"1.195453758","rc":[{"atl":[[9.2,4.95],[10,9.9]],"id":522749}],"con":true,"img":false}]}
{"op":"mcm","clk":"5348769128","pt":1646220523827,"mc":[{"id":"1.195453758","rc":[{"atl":[[11.5,0]],"id":522749}],"con":true,"img":false}]}
{"op":"mcm","clk":"5348769189","pt":1646220524298,"mc":[{"id":"1.195453758","rc":[{"atb":[[46,0]],"id":3805784}],"con":true,"img":false}]}
{"op":"mcm","clk":"5348769249","pt":1646220525014,"mc":[{"id":"1.195453758","rc":[{"atb":[[38,4.28]],"id":3805784}],"con":true,"img":false}]}
{"op":"mcm","clk":"5348769292","pt":1646220525388,"mc":[{"id":"1.195453758","rc":[{"atl":[[90,0]],"id":3805731}],"con":true,"img":false}]}
{"op":"mcm","clk":"5348769298","pt":1646220525498,"mc":[{"id":"1.195453758","rc":[{"atl":[[100,30.7]],"id":3805731}],"con":true,"img":false}]}
{"op":"mcm","clk":"5348769527","pt":1646220528019,"mc":[{"id":"1.195453758","rc":[{"atl":[[9,4.95],[9.2,0],[10,0],[9.8,9.9]],"id":522749}],"con":true,"img":false}]}
{"op":"mcm","clk":"5348769536","pt":1646220528114,"mc":[{"id":"1.195453758","rc":[{"atl":[[34,3.03],[20,39.84]],"id":522743}],"con":true,"img":false}]}
{"op":"mcm","clk":"5348769639","pt":1646220529114,"mc":[{"id":"1.195453758","rc":[{"atl":[[100,9.9],[230,11.03]],"id":3805731}],"con":true,"img":false}]}
{"op":"mcm","clk":"5348769682","pt":1646220529524,"mc":[{"id":"1.195453758","rc":[{"atb":[[44,8.64]],"id":3805784},{"atl":[[22,12.5]],"id":522753}],"con":true,"img":false}]}
{"op":"mcm","clk":"5348769702","pt":1646220529689,"mc":[{"id":"1.195453758","rc":[{"atb":[[36,34.65]],"id":3805784}],"con":true,"img":false}]}
{"op":"mcm","clk":"5348769710","pt":1646220529796,"mc":[{"id":"1.195453758","rc":[{"atb":[[32,5.11],[34,4.95],[27,0],[28,9.9]],"id":3805731}],"con":true,"img":false}]}
{"op":"mcm","clk":"5348769755","pt":1646220530220,"mc":[{"id":"1.195453758","rc":[{"atb":[[38,0]],"id":3805784},{"atl":[[27,33.31]],"id":522753}],"con":true,"img":false}]}
{"op":"mcm","clk":"5348769761","pt":1646220530312,"mc":[{"id":"1.195453758","rc":[{"atb":[[34,9.76],[28,34.98]],"id":3805731}],"con":true,"img":false}]}
{"op":"mcm","clk":"5348769767","pt":1646220530419,"mc":[{"id":"1.195453758","rc":[{"atl":[[9,24.77]],"id":522749},{"atb":[[23,2.72]],"id":3805731}],"con":true,"img":false}]}
{"op":"mcm","clk":"5348769795","pt":1646220530787,"mc":[{"id":"1.195453758","rc":[{"atl":[[10.5,43.12]],"id":522749}],"con":true,"img":false}]}
{"op":"mcm","clk":"5348769818","pt":1646220531097,"mc":[{"id":"1.195453758","rc":[{"atb":[[32,0]],"id":3805731}],"con":true,"img":false}]}
{"op":"mcm","clk":"5348769821","pt":1646220531231,"mc":[{"id":"1.195453758","rc":[{"atl":[[10.5,31.7]],"id":522749}],"con":true,"img":false}]}
{"op":"mcm","clk":"5348769981","pt":1646220533035,"mc":[{"id":"1.195453758","rc":[{"atb":[[17,0],[6.8,0],[8.8,0]],"id":3805784},{"atb":[[4.8,0],[7.6,0],[3.9,0]],"id":3805783},{"atb":[[17,0],[6.8,0],[8.8,0]],"id":3805793},{"atb":[[5.1,0],[8.2,0],[4.1,0]],"id":3805755},{"atb":[[3.9,0],[2.96,0],[2.76,0]],"id":3805736},{"atb":[[3.1,0],[2.84,0],[4.2,0]],"id":522747},{"atb":[[3.9,0],[2.96,0],[2.76,0]],"id":522749},{"atb":[[6.2,0],[8.2,0],[15.5,0]],"id":3805731},{"atb":[[17.5,0],[9,0],[7,0]],"id":3805762},{"atb":[[4,0],[6,0],[3.5,0]],"id":3805730},{"atb":[[5.1,0],[8.2,0],[4.1,0]],"id":522753},{"atb":[[2.8,0],[2.6,0],[3.5,0]],"id":522741},{"atb":[[4.3,0],[6.6,0],[3.65,0]],"id":522743},{"atb":[[9.6,0],[4.8,0],[5.8,0]],"id":3805740},{"atb":[[4,0],[6,0],[3.5,0]],"id":522745}],"con":true,"img":false}]}
{"op":"mcm","clk":"5348770029","pt":1646220533418,"mc":[{"id":"1.195453758","rc":[{"atb":[[36,9.9],[26,30.29]],"id":3805784}],"con":true,"img":false}]}
{"op":"mcm","clk":"5348770100","pt":1646220534029,"mc":[{"id":"1.195453758","rc":[{"atl":[[10,4.95],[12,9.9]],"id":522747},{"atb":[[23,31.96],[28,9.9]],"id":3805731}],"con":true,"img":false}]}
{"op":"mcm","clk":"5348770110","pt":1646220534095,"mc":[{"id":"1.195453758","rc":[{"atl":[[10.5,16.68],[12.5,0]],"id":522747}],"con":true,"img":false}]}
{"op":"mcm","clk":"5348770159","pt":1646220534507,"mc":[{"id":"1.195453758","rc":[{"atl":[[10,22.56],[12,56.8],[24,0]],"id":522747}],"con":true,"img":false}]}
{"op":"mcm","clk":"5348770225","pt":1646220535193,"mc":[{"id":"1.195453758","rc":[{"atl":[[10.5,0]],"id":522747}],"con":true,"img":false}]}
{"op":"mcm","clk":"5348770496","pt":1646220538143,"mc":[{"id":"1.195453758","rc":[{"atl":[[32,68.25],[12,9.9]],"id":522747}],"con":true,"img":false}]}
{"op":"mcm","clk":"5348770587","pt":1646220538915,"mc":[{"id":"1.195453758","rc":[{"atb":[[21,5],[26,27.57]],"id":3805784},{"atb":[[5.8,0],[6.6,0]],"id":522747},{"atb":[[5.9,0],[5.4,0]],"id":522749},{"atb":[[24,21.44],[29,9.9]],"id":3805762},{"atb":[[10.5,0],[13,4.95]],"id":522753},{"atb":[[9.6,22.56],[11.5,8.91]],"id":522743},{"atb":[[9.2,0],[10.5,22.08]],"id":522745}],"con":true,"img":false}]}
{"op":"mcm","clk":"5348770628","pt":1646220539331,"mc":[{"id":"1.195453758","rc":[{"atb":[[5.5,90.59],[5.9,4.95]],"id":522747},{"atb":[[3.95,117.83],[5.7,9.9]],"id":522749}],"con":true,"img":false}]}
{"op":"mcm","clk":"5348770662","pt":1646220539641,"mc":[{"id":"1.195453758","rc":[{"atb":[[23,3.27],[28,2.72]],"id":3805784},{"atb":[[6.8,2.72],[5.9,8.22]],"id":522747},{"atb":[[6.4,2.72],[5.7,13.17]],"id":522749},{"atb":[[25,3.27],[30,2.72]],"id":3805762},{"atb":[[12,3.27],[14.5,2.72]],"id":522753},{"atb":[[12,2.72],[9.8,3.27]],"id":522743},{"atb":[[9.6,3.27],[11.5,7.67]],"id":522745}],"con":true,"img":false}]}
{"op":"mcm","clk":"5348770705","pt":1646220540053,"mc":[{"id":"1.195453758","rc":[{"atb":[[9.6,0]],"id":522743}],"con":true,"img":false}]}
{"op":"mcm","clk":"5348770716","pt":1646220540150,"mc":[{"id":"1.195453758","rc":[{"atb":[[26,0],[28,30.29]],"id":3805784},{"atb":[[6.4,32.08]],"id":522749},{"atb":[[24,0],[29,31.35]],"id":3805762},{"atb":[[12.5,0],[13,38.26],[14.5,14.47]],"id":522753},{"atb":[[10.5,25.57],[12.5,13.78]],"id":522743},{"atl":[[16.5,0]],"id":522743}],"con":true,"img":false}]}
{"op":"mcm","clk":"5348770768","pt":1646220540633,"mc":[{"id":"1.195453758","rc":[{"atl":[[34,23.64],[20,9.9]],"id":522743}],"con":true,"img":false}]}
{"op":"mcm","clk":"5348770792","pt":1646220540838,"mc":[{"id":"1.195453758","rc":[{"atb":[[6.2,4.95]],"id":522749},{"atb":[[13.5,0]],"id":522753},{"atb":[[11.5,0]],"id":522743},{"atl":[[20,18.25]],"id":522743}],"con":true,"img":false}]}
{"op":"mcm","clk":"5348770856","pt":1646220541415,"mc":[{"id":"1.195453758","rc":[{"atl":[[9,19.81],[9.2,9.9],[9.8,0],[8.4,4.95]],"id":522749}],"con":true,"img":false}]}
{"op":"mcm","clk":"5348770901","pt":1646220541935,"mc":[{"id":"1.195453758","rc":[{"atl":[[9.2,44.22],[10.5,0],[8.4,26.37]],"id":522749}],"con":true,"img":false}]}
{"op":"mcm","clk":"5348770941","pt":1646220542338,"mc":[{"id":"1.195453758","rc":[{"atl":[[8.6,4.95],[9.2,34.31],[8.4,21.42],[9.4,9.9]],"id":522749}],"con":true,"img":false}]}
{"op":"mcm","clk":"5348770965","pt":1646220542608,"mc":[{"id":"1.195453758","rc":[{"atl":[[9,0]],"id":522749}],"con":true,"img":false}]}
{"op":"mcm","clk":"5348771069","pt":1646220543645,"mc":[{"id":"1.195453758","rc":[{"atb":[[12,43.35],[13,4.95]],"id":522753}],"con":true,"img":false}]}
{"op":"mcm","clk":"5348771148","pt":1646220544538,"mc":[{"id":"1.195453758","rc":[{"atl":[[10,0],[11.5,9.9],[12,27.98],[9.8,22.97]],"id":3805736}],"con":true,"img":false}]}
{"op":"mcm","clk":"5348771189","pt":1646220545159,"mc":[{"id":"1.195453758","rc":[{"atb":[[18.5,7.61],[7.4,41.62],[9.4,31.71]],"id":3805784},{"atb":[[4.8,70.1],[7.6,20.18],[3.9,91.86]],"id":3805783},{"atb":[[7.2,42.96],[18,7.83],[9.2,32.48]],"id":3805793},{"atb":[[5.1,64.97],[8.2,18.49],[4.1,85.93]],"id":3805755},{"atb":[[2.9,140.21],[3.75,48.43],[2.7,156.7]],"id":3805736},{"atb":[[19.5,7.19],[9.8,30.27],[7.8,39.17]],"id":3805762},{"atb":[[8.6,17.52],[4.3,80.72],[5.3,61.95]],"id":522753},{"atb":[[5.1,64.97],[10.5,14.02],[6.2,51.23]],"id":3805740}],"con":true,"img":false}]}
{"op":"mcm","clk":"5348771196","pt":1646220545222,"mc":[{"id":"1.195453758","rc":[{"atb":[[3.1,126.85],[2.84,144.78],[4.2,41.62]],"id":522747},{"atb":[[3.9,45.93],[2.96,135.92],[2.76,151.36]],"id":522749},{"atb":[[16.5,8.59],[8.6,35.05],[6.6,47.57]],"id":3805731},{"atb":[[5.8,27.75],[3.4,111],[3.9,91.86]],"id":3805730},{"atb":[[2.54,172.98],[2.74,153.1],[3.35,56.68]],"id":522741},{"atb":[[4.5,76.11],[7,22.19],[3.75,96.87]],"id":522743},{"atb":[[3.6,102.46],[6.4,24.66],[4.2,83.25]],"id":522745}],"con":true,"img":false}]}
{"op":"mcm","clk":"5348771323","pt":1646220546731,"mc":[{"id":"1.195453758","rc":[{"atb":[[5.9,56.5]],"id":522747},{"atb":[[3.95,33.9],[5.7,64.6]],"id":522749}],"con":true,"img":false}]}
{"op":"mcm","clk":"5348771331","pt":1646220546845,"mc":[{"id":"1.195453758","rc":[{"atb":[[5.5,9.9]],"id":522747}],"con":true,"img":false}]}
{"op":"mcm","clk":"5348771419","pt":1646220548144,"mc":[{"id":"1.195453758","rc":[{"atl":[[18,14.27]],"id":522743}],"con":true,"img":false}]}
{"op":"mcm","clk":"5348771494","pt":1646220548975,"mc":[{"id":"1.195453758","rc":[{"atl":[[20,9.9]],"id":522743}],"con":true,"img":false}]}
{"op":"mcm","clk":"5348772226","pt":1646220556758,"mc":[{"id":"1.195453758","rc":[{"atb":[[32,9.9],[36,4.52],[40,4.95],[29,21.44]],"id":3805762}],"con":true,"img":false}]}
{"op":"mcm","clk":"5348772283","pt":1646220557278,"mc":[{"id":"1.195453758","rc":[{"atb":[[32,24.62],[42,3.86],[29,0]],"id":3805762}],"con":true,"img":false}]}
{"op":"mcm","clk":"5348772343","pt":1646220558081,"mc":[{"id":"1.195453758","rc":[{"atb":[[36,0]],"id":3805762}],"con":true,"img":false}]}
{"op":"mcm","clk":"5348772658","pt":1646220561250,"mc":[{"id":"1.195453758","rc":[{"atb":[[32,9.9],[38,4.28],[40,4.95],[30,0]],"id":3805793}],"con":true,"img":false}]}
{"op":"mcm","clk":"5348772690","pt":1646220561665,"mc":[{"id":"1.195453758","rc":[{"atb":[[32,24.62],[40,9.02],[29,2.72]],"id":3805793}],"con":true,"img":false}]}
{"op":"mcm","clk":"5348772727","pt":1646220562180,"mc":[{"id":"1.195453758","rc":[{"atb":[[18.5,0],[7.4,0],[9.4,0]],"id":3805784},{"atb":[[4.8,0],[7.6,0],[3.9,0]],"id":3805783},{"atb":[[7.2,0],[18,0],[9.2,0]],"id":3805793},{"atb":[[5.1,0],[8.2,0],[4.1,0]],"id":3805755},{"atb":[[2.9,0],[3.75,0],[2.7,0]],"id":3805736},{"atb":[[3.1,0],[2.84,0],[4.2,0]],"id":522747},{"atb":[[3.9,0],[2.96,0],[2.76,0]],"id":522749},{"atb":[[16.5,0],[8.6,0],[6.6,0]],"id":3805731},{"atb":[[19.5,0],[9.8,0],[7.8,0]],"id":3805762},{"atb":[[5.8,0],[3.4,0],[3.9,0]],"id":3805730},{"atb":[[8.6,0],[4.3,0],[5.3,0]],"id":522753},{"atb":[[2.54,0],[2.74,0],[3.35,0]],"id":522741},{"atb":[[4.5,0],[7,0],[3.75,0]],"id":522743},{"atb":[[5.1,0],[10.5,0],[6.2,0]],"id":3805740},{"atb":[[3.6,0],[6.4,0],[4.2,0]],"id":522745}],"con":true,"img":false}]}
{"op":"mcm","clk":"5348772745","pt":1646220562352,"mc":[{"id":"1.195453758","rc":[{"atb":[[38,0]],"id":3805793}],"con":true,"img":false}]}
{"op":"mcm","clk":"5348772822","pt":1646220563242,"mc":[{"id":"1.195453758","rc":[{"atl":[[9.2,44.22],[8.4,26.37]],"id":522749}],"con":true,"img":false}]}
{"op":"mcm","clk":"5348772828","pt":1646220563347,"mc":[{"id":"1.195453758","rc":[{"atl":[[8.6,0],[9.4,0]],"id":522749}],"con":true,"img":false}]}
{"op":"mcm","clk":"5348772875","pt":1646220563866,"mc":[{"id":"1.195453758","rc":[{"atl":[[9.2,9.9],[30,72.8]],"id":522749}],"con":true,"img":false}]}
{"op":"mcm","clk":"5348772888","pt":1646220564070,"mc":[{"id":"1.195453758","rc":[{"atb":[[17,0],[19.5,5.41]],"id":3805762}],"con":true,"img":false}]}
{"op":"mcm","clk":"5348772916","pt":1646220564335,"mc":[{"id":"1.195453758","rc":[{"atb":[[5.8,4.95],[5.4,9.9]],"id":522749}],"con":true,"img":false}]}
{"op":"mcm","clk":"5348772923","pt":1646220564443,"mc":[{"id":"1.195453758","rc":[{"atb":[[6.2,0],[5.7,54.69]],"id":522749}],"con":true,"img":false}]}
{"op":"mcm","clk":"5348772945","pt":1646220564752,"mc":[{"id":"1.195453758","rc":[{"atb":[[5.8,58.89],[5.7,3.27]],"id":522749}],"con":true,"img":false}]}
{"op":"mcm","clk":"5348772959","pt":1646220564962,"mc":[{"id":"1.195453758","rc":[{"atb":[[32,9.9],[29,23.49]],"id":3805793}],"con":true,"img":false}]}
{"op":"mcm","clk":"5348773003","pt":1646220565435,"mc":[{"id":"1.195453758","rc":[{"atb":[[16,9.9],[17.5,0],[18,14.27],[15.5,22.32]],"id":3805740}],"con":true,"img":false}]}
{"op":"mcm","clk":"5348773123","pt":1646220566648,"mc":[{"id":"1.195453758","rc":[{"atb":[[8.2,13.89]],"id":3805755},{"atb":[[3.05,20.33]],"id":3805731},{"atb":[[8.6,13.16],[7.4,0]],"id":3805740}],"con":true,"img":false}]}
{"op":"mcm","clk":"5348773134","pt":1646220566750,"mc":[{"id":"1.195453758","rc":[{"atb":[[17.5,6.06],[21,0]],"id":3805784},{"atb":[[5.5,0],[6,20]],"id":3805793},{"atb":[[7,0]],"id":3805755},{"atb":[[2.88,0]],"id":3805731}],"con":true,"img":false}]}
{"op":"mcm","clk":"5348773229","pt":1646220567862,"mc":[{"id":"1.195453758","rc":[{"atb":[[46,0.67]],"id":3805784},{"atl":[[85,0.49]],"id":3805784},{"atl":[[22,1.31]],"id":3805783},{"atb":[[42,1.09]],"id":3805793},{"atl":[[70,0.33]],"id":3805793},{"atb":[[15,1.47]],"id":3805755},{"atl":[[22,1.23]],"id":3805755},{"atb":[[7.2,11.61]],"id":3805736},{"atl":[[9.6,2.19]],"id":3805736},{"atb":[[7,4.29]],"id":522747},{"atl":[[9.8,1.94]],"id":522747},{"atb":[[6.6,5.69]],"id":522749},{"atb":[[36,1.1]],"id":3805731},{"atl":[[75,0.63]],"id":3805731},{"atb":[[44,0.82]],"id":3805762},{"atl":[[75,0.42]],"id":3805762},{"atb":[[12,2.18]],"id":3805730},{"atl":[[19.5,1.83]],"id":3805730},{"atb":[[15,1.3]],"id":522753},{"atl":[[21,1.14]],"id":522753},{"atb":[[5.4,7.34]],"id":522741},{"atl":[[17.5,1.45]],"id":522743},{"atb":[[18.5,3.43]],"id":3805740},{"atl":[[32,5.67]],"id":3805740},{"atb":[[12,16.45]],"id":522745},{"atl":[[16.5,1.14]],"id":522745}],"con":true,"img":false}]}
{"op":"mcm","clk":"5348773244","pt":1646220568065,"mc":[{"id":"1.195453758","rc":[{"atb":[[5.8,4.95],[5.7,90.17]],"id":522749}],"con":true,"img":false}]}
{"op":"mcm","clk":"5348773276","pt":1646220568373,"mc":[{"id":"1.195453758","rc":[{"atb":[[36,32.77],[46,4.19],[28,2.72]],"id":3805784},{"atl":[[80,2.33],[120,27.24],[250,2]],"id":3805784},{"atl":[[21,6.64],[27,40.88],[28,0]],"id":3805783},{"atl":[[250,2]],"id":3805793},{"atb":[[12,3.27],[13,27.98],[15.5,10.93]],"id":3805755},{"atl":[[21,3.27],[25,23.02],[29,9.9]],"id":3805755},{"atl":[[11.5,41.91],[12,0],[9.4,18.87]],"id":3805736},{"atb":[[6,52.81],[5.9,8.22]],"id":522747},{"atl":[[32,3.23],[12,31.01]],"id":522747},{"atb":[[36,5.62],[23,2.72],[28,34.76]],"id":3805731},{"atl":[[70,2.3],[100,30.7],[230,2]],"id":3805731},{"atb":[[9.6,13.17],[11,19.66],[12.5,13.78]],"id":3805730},{"atl":[[19,7.5],[21,19.66],[25,9.9]],"id":3805730},{"atb":[[32,9.9],[40,13.69],[46,3.52]],"id":3805762},{"atl":[[75,0.64],[110,0]],"id":3805762},{"atb":[[12,3.27],[13,27.04]],"id":522753},{"atl":[[26,31.99],[27,0]],"id":522753},{"atb":[[5.1,46.46],[5.5,35.03],[4.9,9.9]],"id":522741},{"atl":[[34,3.03],[20,45.13]],"id":522743},{"atb":[[16,33.06],[19,8.8],[15.5,0]],"id":3805740},{"atl":[[16,7.49],[18.5,31.09],[19.5,0]],"id":522745}],"con":true,"img":false}]}
{"op":"mcm","clk":"5348773293","pt":1646220568579,"mc":[{"id":"1.195453758","rc":[{"atb":[[32,20.44],[29,2.72]],"id":3805793}],"con":true,"img":false}]}
{"op":"mcm","clk":"5348773300","pt":1646220568655,"mc":[{"id":"1.195453758","rc":[{"atb":[[46,3.52]],"id":3805784},{"atl":[[9.6,0]],"id":3805736},{"atl":[[10,0],[10.5,4.95],[12,21.1],[12.5,9.9]],"id":522747},{"atb":[[12,0]],"id":3805730},{"atb":[[5.4,0]],"id":522741}],"con":true,"img":false}]}
{"op":"mcm","clk":"5348773309","pt":1646220568753,"mc":[{"id":"1.195453758","rc":[{"atb":[[48,0.67]],"id":3805784},{"atl":[[9.4,21.06]],"id":3805736},{"atb":[[12.5,15.96]],"id":3805730},{"atb":[[5.6,7.34]],"id":522741}],"con":true,"img":false}]}
{"op":"mcm","clk":"5348773316","pt":1646220568859,"mc":[{"id":"1.195453758","rc":[{"atb":[[42,4.95]],"id":3805793},{"atb":[[5.7,3.27]],"id":522749}],"con":true,"img":false}]}
{"op":"mcm","clk":"5348773324","pt":1646220568958,"mc":[{"id":"1.195453758","rc":[{"atl":[[9.8,0]],"id":522747}],"con":true,"img":false}]}
{"op":"mcm","clk":"5348773332","pt":1646220569067,"mc":[{"id":"1.195453758","rc":[{"atl":[[120,9.9]],"id":3805784},{"atl":[[25,4.95]],"id":3805755},{"atb":[[34,4.95]],"id":3805731},{"atl":[[80,4.95]],"id":3805731},{"atl":[[21,4.95]],"id":3805730},{"atb":[[42,0]],"id":3805762},{"atl":[[80,0]],"id":3805762},{"atb":[[18,4.95]],"id":3805740}],"con":true,"img":false}]}
{"op":"mcm","clk":"5348773337","pt":1646220569172,"mc":[{"id":"1.195453758","rc":[{"atb":[[44,4.95],[46,0]],"id":3805784},{"atl":[[90,4.95]],"id":3805784},{"atl":[[27,9.9]],"id":3805783},{"atb":[[42,3.86]],"id":3805793},{"atb":[[14.5,2.72]],"id":3805755},{"atl":[[23,0]],"id":3805755},{"atl":[[9.8,4.95],[13.5,8],[14.5,0]],"id":3805736},{"atl":[[100,9.9]],"id":3805731},{"atb":[[11.5,2.72]],"id":3805730},{"atl":[[20,0]],"id":3805730},{"atb":[[5.3,4.95]],"id":522741},{"atl":[[17,0],[18.5,4.95],[40,0],[30,3.45]],"id":522745}],"con":true,"img":false}]}
{"op":"mcm","clk":"5348773345","pt":1646220569270,"mc":[{"id":"1.195453758","rc":[{"atb":[[36,9.9]],"id":3805784},{"atl":[[23,4.95]],"id":3805783},{"atb":[[44,1.09]],"id":3805793},{"atl":[[18,0],[18.5,4.95],[20,35.22],[21,9.9]],"id":522743}],"con":true,"img":false}]}
{"op":"mcm","clk":"5348773355","pt":1646220569373,"mc":[{"id":"1.195453758","rc":[{"atl":[[10,2.15]],"id":522747}],"con":true,"img":false}]}
{"op":"mcm","clk":"5348773366","pt":1646220569480,"mc":[{"id":"1.195453758","rc":[{"atb":[[48,0]],"id":3805784},{"atl":[[10.5,21.64]],"id":522747},{"atl":[[9,9.9],[9.2,0],[8.2,4.95],[8.4,21.42]],"id":522749},{"atl":[[75,0.22]],"id":3805762},{"atl":[[18.5,0],[21,0]],"id":522745}],"con":true,"img":false}]}
{"op":"mcm","clk":"5348773378","pt":1646220569575,"mc":[{"id":"1.195453758","rc":[{"atb":[[46,0.67]],"id":3805784},{"atb":[[40,4.95]],"id":3805793},{"atb":[[5.8,0],[5.3,0]],"id":3805736},{"atb":[[6.8,0],[5.9,4.95]],"id":522747},{"atb":[[6.4,29.36],[5.7,0]],"id":522749},{"atl":[[130,12.58],[95,0],[110,4.95]],"id":3805762},{"atb":[[12,0],[14.5,11.74]],"id":522753},{"atl":[[17.5,0]],"id":522743},{"atl":[[18,4.95]],"id":522745}],"con":true,"img":false}]}
{"op":"mcm","clk":"5348773397","pt":1646220569743,"mc":[{"id":"1.195453758","rc":[{"atb":[[32,9.9]],"id":3805793},{"atl":[[90,0.53]],"id":3805762}],"con":true,"img":false}]}
{"op":"mcm","clk":"5348773399","pt":1646220569851,"mc":[{"id":"1.195453758","rc":[{"atl":[[18,1.58]],"id":522743}],"con":true,"img":false}]}
{"op":"mcm","clk":"5348773407","pt":1646220569959,"mc":[{"id":"1.195453758","rc":[{"atb":[[44,8.64]],"id":3805784},{"atl":[[8,22.65]],"id":522749}],"con":true,"img":false}]}
{"op":"mcm","clk":"5348773415","pt":1646220570056,"mc":[{"id":"1.195453758","rc":[{"atb":[[7,0]],"id":522747},{"atl":[[18.5,14.01]],"id":522743}],"con":true,"img":false}]}
{"op":"mcm","clk":"5348773425","pt":1646220570161,"mc":[{"id":"1.195453758","rc":[{"atl":[[90,0]],"id":3805762}],"con":true,"img":false}]}
{"op":"mcm","clk":"5348773433","pt":1646220570268,"mc":[{"id":"1.195453758","rc":[{"atb":[[5.9,2.72],[5.4,3.27]],"id":3805736}],"con":true,"img":false}]}
{"op":"mcm","clk":"5348773437","pt":1646220570369,"mc":[{"id":"1.195453758","rc":[{"atb":[[15,0]],"id":3805755},{"atl":[[22,0]],"id":3805755},{"atl":[[9.4,18.87]],"id":3805736},{"atb":[[6,56.08],[7,2.72]],"id":522747},{"atb":[[5.5,3.27],[6,2.72]],"id":522749},{"atb":[[12.5,13.78]],"id":3805730},{"atb":[[11.5,3.27],[14,2.72]],"id":522753},{"atl":[[32,5.11]],"id":3805740},{"atl":[[16.5,0]],"id":522745}],"con":true,"img":false}]}
{"op":"mcm","clk":"5348773448","pt":1646220570470,"mc":[{"id":"1.195453758","rc":[{"atl":[[21,4.5]],"id":3805755},{"atb":[[6.2,8.96]],"id":522747}],"con":true,"img":false}]}
{"op":"mcm","clk":"5348773461","pt":1646220570571,"mc":[{"id":"1.195453758","rc":[{"atl":[[100,0.53]],"id":3805762}],"con":true,"img":false}]}
{"op":"mcm","clk":"5348773468","pt":1646220570669,"mc":[{"id":"1.195453758","rc":[{"atb":[[15.5,12.41]],"id":3805755},{"atl":[[16,8.72]],"id":522745}],"con":true,"img":false}]}
{"op":"mcm","clk":"5348773479","pt":1646220570775,"mc":[{"id":"1.195453758","rc":[{"atl":[[8.4,40.29],[30,3.45]],"id":522749}],"con":true,"img":false}]}
{"op":"mcm","clk":"5348773490","pt":1646220570883,"mc":[{"id":"1.195453758","rc":[{"atb":[[34,9.9],[36,0],[42,4.95],[44,0]],"id":3805784},{"atb":[[15.5,0]],"id":3805783}],"con":true,"img":false}]}
{"op":"mcm","clk":"5348773520","pt":1646220571198,"mc":[{"id":"1.195453758","rc":[{"atb":[[17,8.32],[6.8,45.93],[8.8,34.15]],"id":3805784},{"atb":[[3.85,93.47],[7.4,20.81],[14.5,1.82],[4.7,72]],"id":3805783},{"atb":[[16,8.87],[6.4,49.33],[8.4,35.99]],"id":3805793},{"atb":[[5.1,64.97],[8.2,32.38],[4.1,85.93]],"id":3805755},{"atb":[[3.85,46.73],[2.74,153.1],[2.94,137.32]],"id":3805736},{"atb":[[3.2,121.09],[2.88,141.7],[4.4,39.17]],"id":522747},{"atb":[[4,44.4],[2.8,148],[3,133.2]],"id":522749},{"atb":[[8,38.05],[6,53.28],[15,9.51]],"id":3805731},{"atb":[[17.5,8.07],[9,33.3],[7,44.4]],"id":3805762},{"atb":[[5.8,27.75],[3.4,111],[3.9,91.86]],"id":3805730},{"atb":[[8.6,17.52],[4.3,80.72],[5.3,61.95]],"id":522753},{"atb":[[2.8,148],[2.6,166.5],[3.5,53.28]],"id":522741},{"atb":[[3.7,98.67],[6.8,22.96],[4.4,78.35]],"id":522743},{"atb":[[5.6,57.91],[9.2,16.24],[4.6,74]],"id":3805740},{"atb":[[6.2,25.61],[4.1,85.93],[3.55,104.47]],"id":522745}],"con":true,"img":false}]}
{"op":"mcm","clk":"5348773540","pt":1646220571371,"mc":[{"id":"1.195453758","rc":[{"atb":[[46,0]],"id":3805784},{"atb":[[12,27.13],[13.5,2.72]],"id":3805783}],"con":true,"img":false}]}
{"op":"mcm","clk":"5348773557","pt":1646220571571,"mc":[{"id":"1.195453758","rc":[{"atb":[[13.5,15.4]],"id":3805783},{"atb":[[6,44.84]],"id":522749}],"con":true,"img":false}]}
{"op":"mcm","clk":"5348773564","pt":1646220571672,"mc":[{"id":"1.195453758","rc":[{"atb":[[44,0.98]],"id":3805784}],"con":true,"img":false}]}
{"op":"mcm","clk":"5348773580","pt":1646220571881,"mc":[{"id":"1.195453758","rc":[{"atb":[[42,8.82]],"id":3805784},{"atl":[[9.4,20.71]],"id":3805736},{"atb":[[12,14.41]],"id":522745},{"atl":[[16,7.49]],"id":522745}],"con":true,"img":false}]}
{"op":"mcm","clk":"5348773588","pt":1646220571949,"mc":[{"id":"1.195453758","rc":[{"atl":[[15.5,1.23]],"id":522745}],"con":true,"img":false}]}
{"op":"mcm","clk":"5348773776","pt":1646220574291,"mc":[{"id":"1.195453758","rc":[{"atl":[[21,9.07]],"id":522753},{"atl":[[18.5,0],[21,0]],"id":522743}],"con":true,"img":false}]}
{"op":"mcm","clk":"5348773789","pt":1646220574357,"mc":[{"id":"1.195453758","rc":[{"atl":[[19,4.95]],"id":522743}],"con":true,"img":false}]}
{"op":"mcm","clk":"5348773800","pt":1646220574467,"mc":[{"id":"1.195453758","rc":[{"atl":[[85,0]],"id":3805784},{"atl":[[22,0]],"id":3805783},{"atl":[[75,0]],"id":3805731},{"atb":[[44,0]],"id":3805762},{"atl":[[19.5,0]],"id":3805730},{"atb":[[18.5,0]],"id":3805740}],"con":true,"img":false}]}
{"op":"mcm","clk":"5348773807","pt":1646220574569,"mc":[{"id":"1.195453758","rc":[{"atl":[[75,0.49]],"id":3805784},{"atl":[[20,1.31]],"id":3805783},{"atb":[[6.4,0]],"id":522749},{"atl":[[65,0.63]],"id":3805731},{"atb":[[9.6,3.27],[11,14.71],[11.5,7.67],[9.8,9.9]],"id":3805730},{"atl":[[18.5,1.83]],"id":3805730},{"atb":[[48,0.82]],"id":3805762},{"atl":[[18,0]],"id":522743},{"atb":[[19.5,3.43]],"id":3805740}],"con":true,"img":false}]}
{"op":"mcm","clk":"5348773833","pt":1646220574878,"mc":[{"id":"1.195453758","rc":[{"atb":[[6.6,0]],"id":522749},{"atl":[[18.5,1.9]],"id":522743}],"con":true,"img":false}]}
{"op":"mcm","clk":"5348773842","pt":1646220574977,"mc":[{"id":"1.195453758","rc":[{"atb":[[32,22.49],[40,4.95]],"id":3805762}],"con":true,"img":false}]}
{"op":"mcm","clk":"5348773853","pt":1646220575073,"mc":[{"id":"1.195453758","rc":[{"atb":[[34,20.74]],"id":3805784},{"atl":[[70,0.23]],"id":3805784},{"atl":[[19.5,3.49],[23,19.66]],"id":3805783},{"atl":[[29,31.99]],"id":3805755},{"atb":[[5.8,47.07],[6,2.72]],"id":522749},{"atb":[[50,3.23]],"id":3805762},{"atb":[[13,4.95],[14,33.67]],"id":522753},{"atl":[[22,4.95]],"id":522753},{"atb":[[5.1,2.72],[5.3,48.69]],"id":522741},{"atl":[[34,30.88],[19,13.76],[20,0]],"id":522743},{"atb":[[16,9.9]],"id":3805740},{"atl":[[15,1.17]],"id":522745}],"con":true,"img":false}]}
{"op":"mcm","clk":"5348773862","pt":1646220575179,"mc":[{"id":"1.195453758","rc":[{"atb":[[6.2,7.52]],"id":522749},{"atl":[[60,0.28]],"id":3805731},{"atl":[[18,3.56],[21,27.51]],"id":3805730},{"atb":[[5.6,39.39]],"id":522741},{"atb":[[18,19.9],[20,8.34]],"id":3805740},{"atl":[[18,27.51]],"id":522745}],"con":true,"img":false}]}
{"op":"mcm","clk":"5348773881","pt":1646220575374,"mc":[{"id":"1.195453758","rc":[{"atl":[[20,0]],"id":3805783},{"atb":[[6,34.43]],"id":522749},{"atb":[[48,0]],"id":3805762}],"con":true,"img":false}]}
{"op":"mcm","clk":"5348773889","pt":1646220575452,"mc":[{"id":"1.195453758","rc":[{"atl":[[19.5,4.8]],"id":3805783},{"atb":[[50,4.05]],"id":3805762},{"atb":[[5.6,32.05]],"id":522741}],"con":true,"img":false}]}
{"op":"mcm","clk":"5348773901","pt":1646220575555,"mc":[{"id":"1.195453758","rc":[{"atb":[[5.7,7.34]],"id":522741}],"con":true,"img":false}]}
{"op":"mcm","clk":"5348773921","pt":1646220575761,"mc":[{"id":"1.195453758","rc":[{"atl":[[80,0]],"id":3805784},{"atl":[[21,0],[23,4.95]],"id":3805783},{"atb":[[32,9.9],[46,0]],"id":3805762},{"atl":[[16,0]],"id":522745}],"con":true,"img":false}]}
{"op":"mcm","clk":"5348773931","pt":1646220575865,"mc":[{"id":"1.195453758","rc":[{"atl":[[21,4.95]],"id":3805730}],"con":true,"img":false}]}
{"op":"mcm","clk":"5348773947","pt":1646220575981,"mc":[{"id":"1.195453758","rc":[{"atl":[[70,0]],"id":3805731},{"atl":[[19,0]],"id":3805730},{"atb":[[5.5,0]],"id":522741},{"atb":[[19,0]],"id":3805740},{"atl":[[18,4.95]],"id":522745}],"con":true,"img":false}]}
{"op":"mcm","clk":"5348773962","pt":1646220576081,"mc":[{"id":"1.195453758","rc":[{"atl":[[75,0]],"id":3805784}],"con":true,"img":false}]}
{"op":"mcm","clk":"5348773969","pt":1646220576171,"mc":[{"id":"1.195453758","rc":[{"atl":[[85,0.49]],"id":3805784},{"atb":[[15.5,10.93]],"id":3805755},{"atl":[[10,0]],"id":522747}],"con":true,"img":false}]}
{"op":"mcm","clk":"5348773988","pt":1646220576281,"mc":[{"id":"1.195453758","rc":[{"atb":[[16,1.48]],"id":3805755},{"atl":[[10.5,23.79]],"id":522747},{"atl":[[130,0],[110,18.34]],"id":3805762}],"con":true,"img":false}]}
{"op":"mcm","clk":"5348773996","pt":1646220576385,"mc":[{"id":"1.195453758","rc":[{"atl":[[65,0]],"id":3805731}],"con":true,"img":false}]}
{"op":"mcm","clk":"5348774006","pt":1646220576489,"mc":[{"id":"1.195453758","rc":[{"atb":[[6.2,0]],"id":522747}],"con":true,"img":false}]}
{"op":"mcm","clk":"5348774015","pt":1646220576545,"mc":[{"id":"1.195453758","rc":[{"atl":[[120,27.24]],"id":3805784},{"atb":[[7.2,8.96]],"id":522747}],"con":true,"img":false}]}
{"op":"mcm","clk":"5348774024","pt":1646220576662,"mc":[{"id":"1.195453758","rc":[{"atl":[[12,0],[12.5,56.01]],"id":522747},{"atl":[[75,0.64]],"id":3805731}],"con":true,"img":false}]}
{"op":"mcm","clk":"5348774035","pt":1646220576759,"mc":[{"id":"1.195453758","rc":[{"atb":[[16.5,10.22],[14.5,16.77]],"id":3805755}],"con":true,"img":false}]}
{"op":"mcm","clk":"5348774042","pt":1646220576871,"mc":[{"id":"1.195453758","rc":[{"atb":[[13,9.9]],"id":3805755},{"atb":[[7.2,4.46]],"id":522747},{"atl":[[100,25.63]],"id":3805731}],"con":true,"img":false}]}
{"op":"mcm","clk":"5348774050","pt":1646220576975,"mc":[{"id":"1.195453758","rc":[{"atb":[[6,34.97],[5.9,51.06]],"id":522747}],"con":true,"img":false}]}
{"op":"mcm","clk":"5348774060","pt":1646220577079,"mc":[{"id":"1.195453758","rc":[{"atb":[[12,17.22],[13.5,20.36],[14,0]],"id":3805783},{"atl":[[22,4.95],[23,0],[26,9.9],[27,0]],"id":3805783},{"atl":[[100,13.88]],"id":3805793},{"atl":[[36,4.95],[44,9.9]],"id":3805740}],"con":true,"img":false}]}
{"op":"mcm","clk":"5348774070","pt":1646220577183,"mc":[{"id":"1.195453758","rc":[{"atl":[[38,0],[46,22.32]],"id":3805740}],"con":true,"img":false}]}
{"op":"mcm","clk":"5348774089","pt":1646220577377,"mc":[{"id":"1.195453758","rc":[{"atl":[[120,9.9]],"id":3805784},{"atb":[[14.5,0]],"id":3805783},{"atl":[[7,0]],"id":522741}],"con":true,"img":false}]}
{"op":"mcm","clk":"5348774097","pt":1646220577481,"mc":[{"id":"1.195453758","rc":[{"atb":[[15.5,0]],"id":3805755},{"atl":[[38,14.95],[46,0]],"id":3805740}],"con":true,"img":false}]}
{"op":"mcm","clk":"5348774105","pt":1646220577585,"mc":[{"id":"1.195453758","rc":[{"atb":[[12,15.99]],"id":522745}],"con":true,"img":false}]}
{"op":"mcm","clk":"5348774113","pt":1646220577644,"mc":[{"id":"1.195453758","rc":[{"atb":[[14,1.87]],"id":3805783}],"con":true,"img":false}]}
{"op":"mcm","clk":"5348774122","pt":1646220577798,"mc":[{"id":"1.195453758","rc":[{"atb":[[5.9,4.95]],"id":522747}],"con":true,"img":false}]}
{"op":"mcm","clk":"5348774145","pt":1646220578002,"mc":[{"id":"1.195453758","rc":[{"atb":[[11,25.35],[12,0]],"id":3805783},{"atl":[[8.2,72.28],[7.8,0]],"id":522741}],"con":true,"img":false}]}
{"op":"mcm","clk":"5348774158","pt":1646220578111,"mc":[{"id":"1.195453758","rc":[{"atl":[[7.8,23.31]],"id":522741},{"atl":[[19,4.95]],"id":522743}],"con":true,"img":false}]}
{"op":"mcm","clk":"5348774174","pt":1646220578202,"mc":[{"id":"1.195453758","rc":[{"atl":[[19,0],[19.5,4.95],[23,9.9]],"id":522743}],"con":true,"img":false}]}
{"op":"mcm","clk":"5348774188","pt":1646220578274,"mc":[{"id":"1.195453758","rc":[{"atb":[[14.5,11.74]],"id":3805783}],"con":true,"img":false}]}
{"op":"mcm","clk":"5348774218","pt":1646220578584,"mc":[{"id":"1.195453758","rc":[{"atb":[[14,0]],"id":3805783},{"atl":[[18.5,0]],"id":522743}],"con":true,"img":false}]}
{"op":"mcm","clk":"5348774227","pt":1646220578682,"mc":[{"id":"1.195453758","rc":[{"atb":[[14.5,13.61]],"id":3805783},{"atl":[[19,1.9]],"id":522743}],"con":true,"img":false}]}
{"op":"mcm","clk":"5348774238","pt":1646220578789,"mc":[{"id":"1.195453758","rc":[{"atb":[[8.2,18.49],[6.8,17.24]],"id":3805755}],"con":true,"img":false}]}
{"op":"mcm","clk":"5348774262","pt":1646220578997,"mc":[{"id":"1.195453758","rc":[{"atb":[[14.5,11.74]],"id":3805783},{"atl":[[19.5,3.49]],"id":3805783},{"atl":[[21,3.27]],"id":3805755},{"atl":[[9.4,18.87]],"id":3805736},{"atb":[[12.5,15.37]],"id":3805730},{"atb":[[15,0]],"id":522753},{"atb":[[12,14.41]],"id":522745}],"con":true,"img":false}]}
{"op":"mcm","clk":"5348774268","pt":1646220579063,"mc":[{"id":"1.195453758","rc":[{"atb":[[13.5,7.67]],"id":3805783},{"atl":[[19,1.31]],"id":3805783},{"atl":[[19.5,13.52]],"id":522743}],"con":true,"img":false}]}
{"op":"mcm","clk":"5348774275","pt":1646220579164,"mc":[{"id":"1.195453758","rc":[{"atb":[[16.5,0]],"id":3805755},{"atl":[[21,0]],"id":3805755},{"atl":[[100,9.9]],"id":3805731}],"con":true,"img":false}]}
{"op":"mcm","clk":"5348774280","pt":1646220579265,"mc":[{"id":"1.195453758","rc":[{"atb":[[5.5,0],[6,39.93],[5.9,0]],"id":522747},{"atb":[[14.5,13.36]],"id":522753}],"con":true,"img":false}]}
{"op":"mcm","clk":"5348774297","pt":1646220579481,"mc":[{"id":"1.195453758","rc":[{"atb":[[16,0]],"id":3805755},{"atl":[[24,1.28]],"id":3805755},{"atb":[[13,35.9],[14,2.72]],"id":522753}],"con":true,"img":false}]}
{"op":"mcm","clk":"5348774315","pt":1646220579679,"mc":[{"id":"1.195453758","rc":[{"atl":[[29,9.9],[60,24.08]],"id":3805755}],"con":true,"img":false}]}
{"op":"mcm","clk":"5348774327","pt":1646220579778,"mc":[{"id":"1.195453758","rc":[{"atb":[[15,2]],"id":3805755}],"con":true,"img":false}]}
{"op":"mcm","clk":"5348774336","pt":1646220579880,"mc":[{"id":"1.195453758","rc":[{"atb":[[14.5,26.32]],"id":3805755},{"atl":[[29,15.57]],"id":3805755},{"atl":[[32,45.22],[12.5,9.9]],"id":522747}],"con":true,"img":false}]}
{"op":"mcm","clk":"5348774356","pt":1646220580091,"mc":[{"id":"1.195453758","rc":[{"atb":[[12,25.35],[14.5,12.28]],"id":3805755},{"atl":[[19,6.85],[19.5,8.56],[22,9.9],[23,0]],"id":522743}],"con":true,"img":false}]}
{"op":"mcm","clk":"5348774384","pt":1646220580365,"mc":[{"id":"1.195453758","rc":[{"atb":[[32,9.9],[34,10.83],[40,4.95],[42,0]],"id":3805784},{"atb":[[14.5,11.74]],"id":522753},{"atl":[[19,4.95]],"id":522743}],"con":true,"img":false}]}
{"op":"mcm","clk":"5348774392","pt":1646220580468,"mc":[{"id":"1.195453758","rc":[{"atb":[[15,1.62]],"id":522753},{"atl":[[18.5,1.9]],"id":522743}],"con":true,"img":false}]}
{"op":"mcm","clk":"5348774406","pt":1646220580679,"mc":[{"id":"1.195453758","rc":[{"atb":[[44,0]],"id":3805784}],"con":true,"img":false}]}
{"op":"mcm","clk":"5348774424","pt":1646220580978,"mc":[{"id":"1.195453758","rc":[{"atb":[[42,1.06]],"id":3805784}],"con":true,"img":false}]}
{"op":"mcm","clk":"5348774433","pt":1646220581085,"mc":[{"id":"1.195453758","rc":[{"atb":[[32,0],[34,20.74],[40,0],[42,6.01]],"id":3805784}],"con":true,"img":false}]}
{"op":"mcm","clk":"5348774440","pt":1646220581189,"mc":[{"id":"1.195453758","rc":[{"atb":[[32,14.71],[34,9.9],[40,4.06]],"id":3805784},{"atl":[[18.5,0]],"id":3805730},{"atb":[[19.5,0]],"id":3805740}],"con":true,"img":false}]}
{"op":"mcm","clk":"5348774451","pt":1646220581294,"mc":[{"id":"1.195453758","rc":[{"atl":[[17.5,1.83]],"id":3805730},{"atb":[[21,3.43]],"id":3805740}],"con":true,"img":false}]}
{"op":"mcm","clk":"5348774457","pt":1646220581361,"mc":[{"id":"1.195453758","rc":[{"atb":[[42,4.95]],"id":3805784},{"atl":[[19,0],[19.5,13.52],[22,0]],"id":522743}],"con":true,"img":false}]}
{"op":"mcm","clk":"5348774466","pt":1646220581474,"mc":[{"id":"1.195453758","rc":[{"atb":[[44,1.06]],"id":3805784},{"atb":[[4,33.33],[3.7,0]],"id":522741}],"con":true,"img":false}]}
{"op":"mcm","clk":"5348774470","pt":1646220581570,"mc":[{"id":"1.195453758","rc":[{"atb":[[32,23.29]],"id":3805762}],"con":true,"img":false}]}
{"op":"mcm","clk":"5348774478","pt":1646220581679,"mc":[{"id":"1.195453758","rc":[{"atb":[[14.5,13.11]],"id":3805783},{"atl":[[18.5,0.93],[19,0]],"id":3805783},{"atl":[[70,0]],"id":3805793},{"atl":[[29,37.66],[60,2]],"id":3805755},{"atl":[[9.4,20.76]],"id":3805736},{"atb":[[13,4.95],[14,23.56]],"id":522753},{"atb":[[12.5,15.46]],"id":522743},{"atl":[[34,3.03],[18.5,0],[19.5,33.61]],"id":522743},{"atb":[[16,37.03],[18,4.95]],"id":3805740}],"con":true,"img":false}]}
{"op":"mcm","clk":"5348774486","pt":1646220581777,"mc":[{"id":"1.195453758","rc":[{"atl":[[19.5,4.8]],"id":3805783},{"atl":[[75,2.47]],"id":3805793},{"atl":[[17,1.02],[21,23.73]],"id":3805730},{"atb":[[5.7,36.48]],"id":522741},{"atl":[[19,1.9]],"id":522743},{"atl":[[18,23.73]],"id":522745}],"con":true,"img":false}]}
{"op":"mcm","clk":"5348774492","pt":1646220581884,"mc":[{"id":"1.195453758","rc":[{"atb":[[32,0]],"id":3805784}],"con":true,"img":false}]}
{"op":"mcm","clk":"5348774501","pt":1646220581978,"mc":[{"id":"1.195453758","rc":[{"atb":[[6.2,38]],"id":522749}],"con":true,"img":false}]}
{"op":"mcm","clk":"5348774507","pt":1646220582090,"mc":[{"id":"1.195453758","rc":[{"atl":[[100,4.95],[250,10.31]],"id":3805793},{"atl":[[17.5,0]],"id":3805730},{"atb":[[5.7,29.14]],"id":522741}],"con":true,"img":false}]}
{"op":"mcm","clk":"5348774518","pt":1646220582194,"mc":[{"id":"1.195453758","rc":[{"atl":[[17,2.85]],"id":3805730},{"atb":[[5.8,7.34]],"id":522741}],"con":true,"img":false}]}
{"op":"mcm","clk":"5348774534","pt":1646220582396,"mc":[{"id":"1.195453758","rc":[{"atl":[[19.5,1.31]],"id":3805783},{"atb":[[6.2,30.48]],"id":522749},{"atl":[[19.5,13.52]],"id":522743}],"con":true,"img":false}]}
{"op":"mcm","clk":"5348774548","pt":1646220582499,"mc":[{"id":"1.195453758","rc":[{"atb":[[6.4,7.52]],"id":522749},{"atl":[[21,4.95]],"id":3805730},{"atb":[[5.6,0]],"id":522741},{"atl":[[19.5,0],[20,4.95],[24,9.9]],"id":522743}],"con":true,"img":false}]}
{"op":"mcm","clk":"5348774559","pt":1646220582561,"mc":[{"id":"1.195453758","rc":[{"atl":[[18,0]],"id":3805730}],"con":true,"img":false}]}
{"op":"mcm","clk":"5348774569","pt":1646220582671,"mc":[{"id":"1.195453758","rc":[{"atb":[[5.6,77.99],[5.3,4.95]],"id":522741}],"con":true,"img":false}]}
{"op":"mcm","clk":"5348774576","pt":1646220582768,"mc":[{"id":"1.195453758","rc":[{"atb":[[6,2.72]],"id":522749},{"atl":[[11.5,0],[9.4,11.9]],"id":522741},{"atl":[[19,0]],"id":522743}],"con":true,"img":false}]}
{"op":"mcm","clk":"5348774584","pt":1646220582874,"mc":[{"id":"1.195453758","rc":[{"atl":[[19.5,1.9]],"id":522743}],"con":true,"img":false}]}
{"op":"mcm","clk":"5348774594","pt":1646220582977,"mc":[{"id":"1.195453758","rc":[{"atb":[[5.8,4.95],[6,81.71]],"id":522749}],"con":true,"img":false}]}
{"op":"mcm","clk":"5348774602","pt":1646220583075,"mc":[{"id":"1.195453758","rc":[{"atl":[[9.4,18.87]],"id":3805736},{"atl":[[17,1.02]],"id":3805730},{"atb":[[12.5,13.78]],"id":522743}],"con":true,"img":false}]}
{"op":"mcm","clk":"5348774611","pt":1646220583184,"mc":[{"id":"1.195453758","rc":[{"atl":[[16.5,1.83]],"id":3805730},{"atl":[[20,13.29]],"id":522743}],"con":true,"img":false}]}
{"op":"mcm","clk":"5348774621","pt":1646220583291,"mc":[{"id":"1.195453758","rc":[{"atl":[[9.6,4.95],[11,9.9],[11.5,32],[9.8,0]],"id":3805736}],"con":true,"img":false}]}
{"op":"mcm","clk":"5348774633","pt":1646220583388,"mc":[{"id":"1.195453758","rc":[{"atb":[[12,3.27],[13,31.99],[15.5,10.93]],"id":3805755}],"con":true,"img":false}]}
{"op":"mcm","clk":"5348774655","pt":1646220583594,"mc":[{"id":"1.195453758","rc":[{"atb":[[6,90.02]],"id":522747}],"con":true,"img":false}]}
{"op":"mcm","clk":"5348774689","pt":1646220583867,"mc":[{"id":"1.195453758","rc":[{"atl":[[11,41.91],[11.5,0]],"id":3805736}],"con":true,"img":false}]}
{"op":"mcm","clk":"5348774712","pt":1646220584069,"mc":[{"id":"1.195453758","rc":[{"atb":[[14.5,2.72]],"id":3805755}],"con":true,"img":false}]}
{"op":"mcm","clk":"5348774751","pt":1646220584479,"mc":[{"id":"1.195453758","rc":[{"atl":[[19.5,0]],"id":3805783},{"atb":[[15,0]],"id":3805755},{"atl":[[9.4,20.75]],"id":3805736},{"atl":[[16.5,0]],"id":3805730},{"atb":[[12.5,15.34]],"id":522743},{"atb":[[12,15.98]],"id":522745}],"con":true,"img":false}]}
{"op":"mcm","clk":"5348774760","pt":1646220584582,"mc":[{"id":"1.195453758","rc":[{"atl":[[19,1.31]],"id":3805783},{"atb":[[15.5,12.93]],"id":3805755},{"atl":[[17,2.85]],"id":3805730}],"con":true,"img":false}]}
{"op":"mcm","clk":"5348774777","pt":1646220584786,"mc":[{"id":"1.195453758","rc":[{"atl":[[7.4,29.72]],"id":522741}],"con":true,"img":false}]}
{"op":"mcm","clk":"5348774806","pt":1646220585098,"mc":[{"id":"1.195453758","rc":[{"atl":[[26,36.05]],"id":3805783}],"con":true,"img":false}]}
{"op":"mcm","clk":"5348774862","pt":1646220585579,"mc":[{"id":"1.195453758","rc":[{"atl":[[7.8,0]],"id":522741}],"con":true,"img":false}]}
{"op":"mcm","clk":"5348774876","pt":1646220585883,"mc":[{"id":"1.195453758","rc":[{"atl":[[26,9.9]],"id":3805783}],"con":true,"img":false}]}
{"op":"mcm","clk":"5348774890","pt":1646220585991,"mc":[{"id":"1.195453758","rc":[{"atl":[[21,1.14]],"id":522753}],"con":true,"img":false}]}
{"op":"mcm","clk":"5348774899","pt":1646220586089,"mc":[{"id":"1.195453758","rc":[{"atb":[[40,9.02]],"id":3805784},{"atl":[[8.2,9.9],[9.4,99.41]],"id":522741},{"atl":[[20,4.95]],"id":522743}],"con":true,"img":false}]}
{"op":"mcm","clk":"5348774910","pt":1646220586194,"mc":[{"id":"1.195453758","rc":[{"atb":[[34,0],[42,0]],"id":3805784},{"atl":[[20,0],[21,4.95],[24,0],[25,9.9]],"id":522743}],"con":true,"img":false}]}
{"op":"mcm","clk":"5348774939","pt":1646220586464,"mc":[{"id":"1.195453758","rc":[{"atb":[[44,0]],"id":3805784},{"atl":[[23,7.2]],"id":3805755},{"atl":[[19.5,0]],"id":522743}],"con":true,"img":false}]}
{"op":"mcm","clk":"5348774954","pt":1646220586674,"mc":[{"id":"1.195453758","rc":[{"atb":[[42,1.1]],"id":3805784},{"atl":[[20,1.91]],"id":522743}],"con":true,"img":false}]}
{"op":"mcm","clk":"5348774963","pt":1646220586778,"mc":[{"id":"1.195453758","rc":[{"atl":[[22,12.5]],"id":522753}],"con":true,"img":false}]}
{"op":"mcm","clk":"5348774972","pt":1646220586880,"mc":[{"id":"1.195453758","rc":[{"atb":[[32,9.9]],"id":3805784},{"atl":[[25,23.02],[29,15.57]],"id":3805755},{"atl":[[21,12.88]],"id":522743}],"con":true,"img":false}]}
{"op":"mcm","clk":"5348775001","pt":1646220587186,"mc":[{"id":"1.195453758","rc":[{"atl":[[29,9.9]],"id":3805755}],"con":true,"img":false}]}
{"op":"mcm","clk":"5348775008","pt":1646220587292,"mc":[{"id":"1.195453758","rc":[{"atb":[[15.5,10.93]],"id":3805755}],"con":true,"img":false}]}
{"op":"mcm","clk":"5348775017","pt":1646220587396,"mc":[{"id":"1.195453758","rc":[{"atb":[[16,2]],"id":3805755}],"con":true,"img":false}]}
{"op":"mcm","clk":"5348775047","pt":1646220587704,"mc":[{"id":"1.195453758","rc":[{"atb":[[32,18.9]],"id":3805784}],"con":true,"img":false}]}
{"op":"mcm","clk":"5348775074","pt":1646220587971,"mc":[{"id":"1.195453758","rc":[{"atb":[[16,12.56],[13,9.9],[14.5,17.5]],"id":3805755}],"con":true,"img":false}]}
{"op":"mcm","clk":"5348775088","pt":1646220588175,"mc":[{"id":"1.195453758","rc":[{"atl":[[25,43.78]],"id":522743},{"atb":[[16,9.9],[18,19.9]],"id":3805740}],"con":true,"img":false}]}
{"op":"mcm","clk":"5348775118","pt":1646220588496,"mc":[{"id":"1.195453758","rc":[{"atl":[[25,36.05]],"id":3805730}],"con":true,"img":false}]}
{"op":"mcm","clk":"5348775130","pt":1646220588587,"mc":[{"id":"1.195453758","rc":[{"atb":[[16,10.56]],"id":3805755}],"con":true,"img":false}]}
{"op":"mcm","clk":"5348775154","pt":1646220588793,"mc":[{"id":"1.195453758","rc":[{"atb":[[15.5,0]],"id":3805755}],"con":true,"img":false}]}
{"op":"mcm","clk":"5348775193","pt":1646220589210,"mc":[{"id":"1.195453758","rc":[{"atb":[[42,0]],"id":3805793}],"con":true,"img":false}]}
{"op":"mcm","clk":"5348775217","pt":1646220589479,"mc":[{"id":"1.195453758","rc":[{"atb":[[44,0]],"id":3805793}],"con":true,"img":false}]}
{"op":"mcm","clk":"5348775244","pt":1646220589786,"mc":[{"id":"1.195453758","rc":[{"atb":[[32,24.62],[42,1.3]],"id":3805793}],"con":true,"img":false}]}
{"op":"mcm","clk":"5348775261","pt":1646220590017,"mc":[{"id":"1.195453758","rc":[{"atl":[[90,13.94]],"id":3805784},{"atb":[[40,9.02]],"id":3805793},{"atb":[[7.2,2.7]],"id":3805736},{"atl":[[8,27.6],[9,0],[8.2,0],[8.8,9.9]],"id":522749},{"atl":[[75,0]],"id":3805762}],"con":true,"img":false}]}
{"op":"mcm","clk":"5348775272","pt":1646220590096,"mc":[{"id":"1.195453758","rc":[{"atl":[[85,5.44],[90,8.99],[110,9.9],[120,0]],"id":3805784}],"con":true,"img":false}]}
{"op":"mcm","clk":"5348775296","pt":1646220590405,"mc":[{"id":"1.195453758","rc":[{"atb":[[7.2,0]],"id":3805736}],"con":true,"img":false}]}
{"op":"mcm","clk":"5348775314","pt":1646220590572,"mc":[{"id":"1.195453758","rc":[{"atl":[[8.8,96.26],[8.4,0]],"id":522749},{"atl":[[110,4.95],[250,10.31]],"id":3805762}],"con":true,"img":false}]}
{"op":"mcm","clk":"5348775326","pt":1646220590684,"mc":[{"id":"1.195453758","rc":[{"atb":[[7,3.31]],"id":3805736}],"con":true,"img":false}]}
{"op":"mcm","clk":"5348775334","pt":1646220590789,"mc":[{"id":"1.195453758","rc":[{"atb":[[6,55.28]],"id":3805736},{"atl":[[95,1.68]],"id":3805762}],"con":true,"img":false}]}
{"op":"mcm","clk":"5348775345","pt":1646220590888,"mc":[{"id":"1.195453758","rc":[{"atb":[[6.6,28.31]],"id":3805736}],"con":true,"img":false}]}
{"op":"mcm","clk":"5348775357","pt":1646220590988,"mc":[{"id":"1.195453758","rc":[{"atb":[[13,40.34],[14.5,2.72]],"id":3805755}],"con":true,"img":false}]}
{"op":"mcm","clk":"5348775391","pt":1646220591300,"mc":[{"id":"1.195453758","rc":[{"atb":[[14.5,11.74]],"id":3805783},{"atl":[[250,2]],"id":3805762}],"con":true,"img":false}]}
{"op":"mcm","clk":"5348775400","pt":1646220591402,"mc":[{"id":"1.195453758","rc":[{"atb":[[16,11.73]],"id":3805755}],"con":true,"img":false}]}
{"op":"mcm","clk":"5348775426","pt":1646220591613,"mc":[{"id":"1.195453758","rc":[{"atl":[[22,23.73]],"id":3805783},{"atb":[[6,9.9]],"id":3805736}],"con":true,"img":false}]}
{"op":"mcm","clk":"5348775449","pt":1646220591884,"mc":[{"id":"1.195453758","rc":[{"atl":[[24,0]],"id":3805755}],"con":true,"img":false}]}
{"op":"mcm","clk":"5348775463","pt":1646220591989,"mc":[{"id":"1.195453758","rc":[{"atl":[[22,1.28]],"id":3805755}],"con":true,"img":false}]}
{"op":"mcm","clk":"5348775503","pt":1646220592398,"mc":[{"id":"1.195453758","rc":[{"atl":[[25,4.95],[29,42.09]],"id":3805755}],"con":true,"img":false}]}
{"op":"mcm","clk":"5348775531","pt":1646220592708,"mc":[{"id":"1.195453758","rc":[{"atb":[[14.5,13.09]],"id":3805783},{"atb":[[16,10.56]],"id":3805755},{"atl":[[9.4,18.87]],"id":3805736},{"atb":[[12.5,13.78]],"id":3805730},{"atl":[[17,1.02]],"id":3805730}],"con":true,"img":false}]}
{"op":"mcm","clk":"5348775538","pt":1646220592812,"mc":[{"id":"1.195453758","rc":[{"atl":[[9.2,1.88]],"id":3805736},{"atb":[[13,1.59]],"id":3805730}],"con":true,"img":false}]}
{"op":"mcm","clk":"5348775558","pt":1646220592981,"mc":[{"id":"1.195453758","rc":[{"atl":[[22,6.78]],"id":3805755}],"con":true,"img":false}]}
{"op":"mcm","clk":"5348775570","pt":1646220593133,"mc":[{"id":"1.195453758","rc":[{"atl":[[29,9.9]],"id":3805755}],"con":true,"img":false}]}
{"op":"mcm","clk":"5348775580","pt":1646220593191,"mc":[{"id":"1.195453758","rc":[{"atl":[[22,5.5]],"id":3805755}],"con":true,"img":false}]}
{"op":"mcm","clk":"5348775588","pt":1646220593300,"mc":[{"id":"1.195453758","rc":[{"atl":[[21,1.28],[25,23.02]],"id":3805755},{"atl":[[9.6,19.66],[9,14.71],[11,9.9]],"id":3805736},{"atb":[[11,0],[11.5,26.45],[13.5,12.68]],"id":3805730}],"con":true,"img":false}]}
{"op":"mcm","clk":"5348775627","pt":1646220593698,"mc":[{"id":"1.195453758","rc":[{"atl":[[8.8,9.9],[30,72.8]],"id":522749}],"con":true,"img":false}]}
{"op":"mcm","clk":"5348775649","pt":1646220593904,"mc":[{"id":"1.195453758","rc":[{"atl":[[23,0]],"id":3805755}],"con":true,"img":false}]}
{"op":"mcm","clk":"5348775665","pt":1646220594082,"mc":[{"id":"1.195453758","rc":[{"atb":[[16,11.77]],"id":3805755},{"atl":[[25,4.95]],"id":3805755},{"atl":[[9.4,0]],"id":3805736},{"atb":[[12.5,0]],"id":3805730},{"atl":[[17,2.02]],"id":3805730}],"con":true,"img":false}]}
{"op":"mcm","clk":"5348775775","pt":1646220595010,"mc":[{"id":"1.195453758","rc":[{"atb":[[32,13.39],[34,9.9],[40,0],[42,4.95]],"id":3805762}],"con":true,"img":false}]}
{"op":"mcm","clk":"5348775786","pt":1646220595121,"mc":[{"id":"1.195453758","rc":[{"atb":[[8.2,32.38],[6.8,0]],"id":3805755}],"con":true,"img":false}]}
{"op":"mcm","clk":"5348775823","pt":1646220595373,"mc":[{"id":"1.195453758","rc":[{"atb":[[13,30.43],[13.5,4.95]],"id":3805755},{"atl":[[32,5.62]],"id":3805740}],"con":true,"img":false}]}
{"op":"mcm","clk":"5348775834","pt":1646220595494,"mc":[{"id":"1.195453758","rc":[{"atb":[[32,0],[34,23.29]],"id":3805762}],"con":true,"img":false}]}
{"op":"mcm","clk":"5348775875","pt":1646220595904,"mc":[{"id":"1.195453758","rc":[{"atb":[[13,0],[13.5,19.66]],"id":3805755}],"con":true,"img":false}]}
{"op":"mcm","clk":"5348775914","pt":1646220596300,"mc":[{"id":"1.195453758","rc":[{"atl":[[100,0]],"id":3805762}],"con":true,"img":false}]}
{"op":"mcm","clk":"5348775926","pt":1646220596415,"mc":[{"id":"1.195453758","rc":[{"atb":[[42,5.16]],"id":3805793},{"atl":[[90,0.53]],"id":3805762}],"con":true,"img":false}]}
{"op":"mcm","clk":"5348775964","pt":1646220596783,"mc":[{"id":"1.195453758","rc":[{"atb":[[42,3.86]],"id":3805793}],"con":true,"img":false}]}
{"op":"mcm","clk":"5348775974","pt":1646220596881,"mc":[{"id":"1.195453758","rc":[{"atb":[[44,1.3]],"id":3805793}],"con":true,"img":false}]}
{"op":"mcm","clk":"5348775989","pt":1646220597092,"mc":[{"id":"1.195453758","rc":[{"atb":[[6.6,57.55]],"id":3805736},{"atl":[[85,2.66],[110,18.34]],"id":3805762}],"con":true,"img":false}]}
{"op":"mcm","clk":"5348775999","pt":1646220597200,"mc":[{"id":"1.195453758","rc":[{"atb":[[40,4.95]],"id":3805793},{"atb":[[7,15.58]],"id":3805736}],"con":true,"img":false}]}
{"op":"mcm","clk":"5348776026","pt":1646220597500,"mc":[{"id":"1.195453758","rc":[{"atb":[[14.5,1.35]],"id":3805783},{"atb":[[32,9.9],[42,0]],"id":3805793}],"con":true,"img":false}]}
{"op":"mcm","clk":"5348776058","pt":1646220597914,"mc":[{"id":"1.195453758","rc":[{"atb":[[14.5,0]],"id":3805783},{"atb":[[44,0]],"id":3805793},{"atl":[[95,0],[110,4.95]],"id":3805762}],"con":true,"img":false}]}
{"op":"mcm","clk":"5348776065","pt":1646220597980,"mc":[{"id":"1.195453758","rc":[{"atb":[[6.6,29.24]],"id":3805736}],"con":true,"img":false}]}
{"op":"mcm","clk":"5348776079","pt":1646220598185,"mc":[{"id":"1.195453758","rc":[{"atb":[[13.5,20.36],[14,1.72]],"id":3805783},{"atb":[[32,24.62],[42,1.32]],"id":3805793},{"atb":[[16,10.56]],"id":3805755},{"atb":[[7,12.27]],"id":3805736},{"atl":[[17,1.02]],"id":3805730}],"con":true,"img":false}]}
{"op":"mcm","clk":"5348776088","pt":1646220598295,"mc":[{"id":"1.195453758","rc":[{"atb":[[7.2,3.31]],"id":3805736}],"con":true,"img":false}]}
{"op":"mcm","clk":"5348776096","pt":1646220598397,"mc":[{"id":"1.195453758","rc":[{"atb":[[11,3.27],[7.4,63.16]],"id":3805783},{"atb":[[40,9.02]],"id":3805793}],"con":true,"img":false}]}
{"op":"mcm","clk":"5348776125","pt":1646220598700,"mc":[{"id":"1.195453758","rc":[{"atl":[[25,20.48]],"id":3805755}],"con":true,"img":false}]}
{"op":"mcm","clk":"5348776150","pt":1646220598955,"mc":[{"id":"1.195453758","marketDefinition":{"bspMarket":false,"turnInPlayEnabled":false,"persistenceEnabled":false,"marketBaseRate":7.0,"eventId":"31272494","eventTypeId":"4339","numberOfWinners":1,"bettingType":"ODDS","marketType":"QUINELLA","marketTime":"2022-03-02T11:32:00.000Z","suspendTime":"2022-03-02T11:32:00.000Z","bspReconciled":false,"complete":true,"inPlay":false,"crossMatching":true,"runnersVoidable":false,"numberOfActiveRunners":15,"betDelay":0,"status":"OPEN","runners":[{"status":"ACTIVE","sortPriority":1,"id":522741,"name":"1 - 2 / 2 - 1"},{"status":"ACTIVE","sortPriority":2,"id":522743,"name":"1 - 4 / 4 - 1"},{"status":"ACTIVE","sortPriority":3,"id":522745,"name":"1 - 6 / 6 - 1"},{"status":"ACTIVE","sortPriority":4,"id":3805730,"name":"1 - 7 / 7 - 1"},{"status":"ACTIVE","sortPriority":5,"id":3805731,"name":"1 - 8 / 8 - 1"},{"status":"ACTIVE","sortPriority":6,"id":522747,"name":"2 - 4 / 4 - 2"},{"status":"ACTIVE","sortPriority":7,"id":522749,"name":"2 - 6 / 6 - 2"},{"status":"ACTIVE","sortPriority":8,"id":3805736,"name":"2 - 7 / 7 - 2"},{"status":"ACTIVE","sortPriority":9,"id":3805740,"name":"2 - 8 / 8 - 2"},{"status":"ACTIVE","sortPriority":10,"id":522753,"name":"4 - 6 / 6 - 4"},{"status":"ACTIVE","sortPriority":11,"id":3805755,"name":"4 - 7 / 7 - 4"},{"status":"ACTIVE","sortPriority":12,"id":3805762,"name":"4 - 8 / 8 - 4"},{"status":"ACTIVE","sortPriority":13,"id":3805783,"name":"6 - 7 / 7 - 6"},{"status":"ACTIVE","sortPriority":14,"id":3805784,"name":"6 - 8 / 8 - 6"},{"status":"ACTIVE","sortPriority":15,"id":3805793,"name":"7 - 8 / 8 - 7"}],"regulators":["MR_INT"],"venue":"Traralgon","countryCode":"AU","discountAllowed":true,"timezone":"Australia/Sydney","openDate":"2022-03-02T08:31:00.000Z","version":4382480630,"name":"Quinella","eventName":"Traralgon (AUS) 2nd Mar"},"rc":[],"con":true,"img":false}]}
{"op":"mcm","clk":"5348776168","pt":1646220599119,"mc":[{"id":"1.195453758","rc":[{"atl":[[10.5,18.83],[11,4.95],[12.5,0],[13,9.9]],"id":522747},{"atl":[[21,0],[22,4.95],[25,33.87],[26,9.9]],"id":522743}],"con":true,"img":false}]}
{"op":"mcm","clk":"5348776179","pt":1646220599215,"mc":[{"id":"1.195453758","rc":[{"atb":[[40,4.95]],"id":3805793},{"atl":[[10.5,2.15]],"id":522747}],"con":true,"img":false}]}
{"op":"mcm","clk":"5348776189","pt":1646220599280,"mc":[{"id":"1.195453758","rc":[{"atb":[[32,14.71],[38,4.95],[40,0],[30,9.9]],"id":3805793},{"atl":[[21,4.22]],"id":3805755}],"con":true,"img":false}]}
{"op":"mcm","clk":"5348776199","pt":1646220599398,"mc":[{"id":"1.195453758","rc":[{"atl":[[20,0]],"id":522743}],"con":true,"img":false}]}
{"op":"mcm","clk":"5348776214","pt":1646220599587,"mc":[{"id":"1.195453758","rc":[{"atb":[[16,11.93]],"id":3805755},{"atl":[[32,3.23],[13,31.99]],"id":522747},{"atl":[[17,2.02]],"id":3805730}],"con":true,"img":false}]}
{"op":"mcm","clk":"5348776224","pt":1646220599697,"mc":[{"id":"1.195453758","rc":[{"atb":[[42,0]],"id":3805793},{"atl":[[21,2.94]],"id":3805755},{"atb":[[12.5,13.78]],"id":522743},{"atl":[[21,2.08]],"id":522743},{"atl":[[32,5.11]],"id":3805740}],"con":true,"img":false}]}
{"op":"mcm","clk":"5348776237","pt":1646220599794,"mc":[{"id":"1.195453758","rc":[{"atl":[[25,0],[26,47.45]],"id":522743}],"con":true,"img":false}]}
{"op":"mcm","clk":"5348776241","pt":1646220599894,"mc":[{"id":"1.195453758","rc":[{"atb":[[7,16.67]],"id":3805755},{"atl":[[22,12.5]],"id":522743}],"con":true,"img":false}]}
{"op":"mcm","clk":"5348776246","pt":1646220599998,"mc":[{"id":"1.195453758","rc":[{"atb":[[40,1.61]],"id":3805793},{"atb":[[8.2,18.49]],"id":3805755}],"con":true,"img":false}]}
{"op":"mcm","clk":"5348776251","pt":1646220600101,"mc":[{"id":"1.195453758","rc":[{"atl":[[22,0]],"id":3805755},{"atl":[[11,15.64]],"id":522747}],"con":true,"img":false}]}
{"op":"mcm","clk":"5348776259","pt":1646220600210,"mc":[{"id":"1.195453758","rc":[{"atb":[[17.5,0],[11,10]],"id":3805784},{"atl":[[320,2],[250,0]],"id":3805784},{"atb":[[5,25],[6.6,0]],"id":3805783},{"atb":[[38,9.23]],"id":3805793},{"atl":[[340,2],[250,8.31]],"id":3805793},{"atb":[[7,0]],"id":3805755},{"atb":[[5,0],[3.8,35.71]],"id":3805736},{"atl":[[16.5,6.45],[13.5,0]],"id":3805736},{"atb":[[4,0],[3.4,41.67]],"id":522747},{"atb":[[3.95,0],[3.3,43.48]],"id":522749},{"atl":[[300,2],[230,0]],"id":3805731},{"atb":[[7.8,0],[5.4,22.73]],"id":3805730},{"atb":[[19.5,0],[14,7.69]],"id":3805762},{"atl":[[370,2],[250,0]],"id":3805762},{"atb":[[6.2,0],[4.9,25.64]],"id":522753},{"atb":[[4,0],[3.35,42.55]],"id":522741},{"atl":[[12,9.09],[9.4,87.51]],"id":522741},{"atb":[[5.9,0],[4.7,27.03]],"id":522743},{"atl":[[34,0],[55,2]],"id":522743},{"atb":[[8.6,0],[6.8,17.24]],"id":3805740},{"atl":[[75,0],[110,2]],"id":3805740},{"atb":[[5.1,24.39],[6.8,0]],"id":522745},{"atl":[[42,2.44],[30,0]],"id":522745}],"con":true,"img":false}]}
{"op":"mcm","clk":"5348776281","pt":1646220600417,"mc":[{"id":"1.195453758","rc":[{"atb":[[5.2,23.81]],"id":3805755}],"con":true,"img":false}]}
{"op":"mcm","clk":"5348776356","pt":1646220601029,"mc":[{"id":"1.195453758","rc":[{"atb":[[7.2,0]],"id":3805736}],"con":true,"img":false}]}
{"op":"mcm","clk":"5348776373","pt":1646220601122,"mc":[{"id":"1.195453758","rc":[{"atb":[[7,15.58]],"id":3805736}],"con":true,"img":false}]}
{"op":"mcm","clk":"5348776456","pt":1646220601699,"mc":[{"id":"1.195453758","rc":[{"atl":[[25,4.95],[29,42.38]],"id":3805755}],"con":true,"img":false}]}
{"op":"mcm","clk":"5348776541","pt":1646220602417,"mc":[{"id":"1.195453758","rc":[{"atb":[[12,0],[12.5,15.38],[9.8,0]],"id":522743}],"con":true,"img":false}]}
{"op":"mcm","clk":"5348776552","pt":1646220602521,"mc":[{"id":"1.195453758","rc":[{"atb":[[5.1,0],[4.6,0]],"id":522741}],"con":true,"img":false}]}
{"op":"mcm","clk":"5348776582","pt":1646220602697,"mc":[{"id":"1.195453758","rc":[{"atl":[[21,0]],"id":3805755}],"con":true,"img":false}]}
{"op":"mcm","clk":"5348776591","pt":1646220602801,"mc":[{"id":"1.195453758","rc":[{"atl":[[90,0]],"id":3805762}],"con":true,"img":false}]}
{"op":"mcm","clk":"5348776606","pt":1646220602918,"mc":[{"id":"1.195453758","rc":[{"atl":[[80,0.53]],"id":3805762},{"atb":[[10.5,4.95],[9.4,51.36]],"id":522743}],"con":true,"img":false}]}
{"op":"mcm","clk":"5348776615","pt":1646220603012,"mc":[{"id":"1.195453758","rc":[{"atl":[[24,1.24]],"id":3805755}],"con":true,"img":false}]}
{"op":"mcm","clk":"5348776626","pt":1646220603108,"mc":[{"id":"1.195453758","rc":[{"atb":[[10,3.27],[12.5,18.11]],"id":522743}],"con":true,"img":false}]}
{"op":"mcm","clk":"5348776652","pt":1646220603318,"mc":[{"id":"1.195453758","rc":[{"atl":[[110,18.34]],"id":3805762},{"atb":[[5.2,2.72],[4.7,3.27]],"id":522741}],"con":true,"img":false}]}
{"op":"mcm","clk":"5348776665","pt":1646220603424,"mc":[{"id":"1.195453758","rc":[{"atl":[[29,48.04]],"id":3805755},{"atl":[[80,0.74]],"id":3805762}],"con":true,"img":false}]}
{"op":"mcm","clk":"5348776720","pt":1646220603800,"mc":[{"id":"1.195453758","rc":[{"atl":[[19,0]],"id":3805783},{"atb":[[12.5,16.51]],"id":522743}],"con":true,"img":false}]}
{"op":"mcm","clk":"5348776734","pt":1646220603906,"mc":[{"id":"1.195453758","rc":[{"atl":[[18.5,2.24]],"id":3805783}],"con":true,"img":false}]}
{"op":"mcm","clk":"5348776777","pt":1646220604212,"mc":[{"id":"1.195453758","rc":[{"atb":[[6.8,0],[6,0]],"id":3805736}],"con":true,"img":false}]}
{"op":"mcm","clk":"5348776795","pt":1646220604317,"mc":[{"id":"1.195453758","rc":[{"atl":[[22,4.95],[26,29.5]],"id":3805783},{"atb":[[34,0],[36,10.58],[28,24.85],[29,9.9]],"id":3805731},{"atl":[[85,0]],"id":3805762}],"con":true,"img":false}]}
{"op":"mcm","clk":"5348776803","pt":1646220604421,"mc":[{"id":"1.195453758","rc":[{"atb":[[6.2,4.95]],"id":3805736}],"con":true,"img":false}]}
{"op":"mcm","clk":"5348776831","pt":1646220604588,"mc":[{"id":"1.195453758","rc":[{"atb":[[11,22.86],[7.4,20.81]],"id":3805783},{"atl":[[80,0.21]],"id":3805762}],"con":true,"img":false}]}
{"op":"mcm","clk":"5348776842","pt":1646220604693,"mc":[{"id":"1.195453758","rc":[{"atb":[[14,13.91]],"id":3805783},{"atb":[[6.6,0],[5.9,47.77]],"id":3805736},{"atl":[[100,0.53]],"id":3805762}],"con":true,"img":false}]}
{"op":"mcm","clk":"5348776862","pt":1646220604904,"mc":[{"id":"1.195453758","rc":[{"atb":[[32,24.62],[38,4.28],[40,10.63],[30,0]],"id":3805793},{"atb":[[20,0]],"id":3805740}],"con":true,"img":false}]}
{"op":"mcm","clk":"5348776874","pt":1646220605010,"mc":[{"id":"1.195453758","rc":[{"atb":[[32,8.99],[38,4.95],[40,0],[30,9.9]],"id":3805784}],"con":true,"img":false}]}
{"op":"mcm","clk":"5348776889","pt":1646220605104,"mc":[{"id":"1.195453758","rc":[{"atl":[[18.5,0.93]],"id":3805783},{"atb":[[12.5,18.04]],"id":522743}],"con":true,"img":false}]}
{"op":"mcm","clk":"5348776903","pt":1646220605207,"mc":[{"id":"1.195453758","rc":[{"atb":[[21,0]],"id":3805740}],"con":true,"img":false}]}
{"op":"mcm","clk":"5348776909","pt":1646220605312,"mc":[{"id":"1.195453758","rc":[{"atb":[[42,0]],"id":3805784},{"atl":[[90,0]],"id":3805784},{"atb":[[18,4.95]],"id":3805740}],"con":true,"img":false}]}
{"op":"mcm","clk":"5348776920","pt":1646220605416,"mc":[{"id":"1.195453758","rc":[{"atl":[[21,1.43]],"id":3805783},{"atb":[[16,32.23]],"id":3805740}],"con":true,"img":false}]}
{"op":"mcm","clk":"5348776931","pt":1646220605522,"mc":[{"id":"1.195453758","rc":[{"atb":[[40,1.41]],"id":3805784},{"atb":[[18.5,3.71]],"id":3805740}],"con":true,"img":false}]}
{"op":"mcm","clk":"5348776939","pt":1646220605626,"mc":[{"id":"1.195453758","rc":[{"atb":[[13.5,7.67],[14,1.72]],"id":3805783},{"atb":[[32,14.71],[38,4.95],[40,1.61],[30,9.9]],"id":3805793},{"atl":[[23,7.2]],"id":3805755}],"con":true,"img":false}]}
{"op":"mcm","clk":"5348776948","pt":1646220605699,"mc":[{"id":"1.195453758","rc":[{"atb":[[32,0],[38,9.23],[30,31.35]],"id":3805784},{"atl":[[110,28.81]],"id":3805784},{"atb":[[18,14.27]],"id":3805740}],"con":true,"img":false}]}
{"op":"mcm","clk":"5348777009","pt":1646220606313,"mc":[{"id":"1.195453758","rc":[{"atl":[[25,23.02],[29,15.57]],"id":3805755}],"con":true,"img":false}]}
{"op":"mcm","clk":"5348777022","pt":1646220606417,"mc":[{"id":"1.195453758","rc":[{"atb":[[11,32.77]],"id":3805783},{"atb":[[32,19.82]],"id":3805793},{"atl":[[29,9.9]],"id":3805755}],"con":true,"img":false}]}
{"op":"mcm","clk":"5348777119","pt":1646220607212,"mc":[{"id":"1.195453758","rc":[{"atb":[[36,4.95],[38,0],[30,0]],"id":3805793}],"con":true,"img":false}]}
{"op":"mcm","clk":"5348777152","pt":1646220607518,"mc":[{"id":"1.195453758","rc":[{"atb":[[40,0]],"id":3805793}],"con":true,"img":false}]}
{"op":"mcm","clk":"5348777186","pt":1646220607825,"mc":[{"id":"1.195453758","rc":[{"atb":[[38,1.9]],"id":3805793},{"atl":[[22,0],[23,4.95],[26,37.54],[27,9.9]],"id":522743}],"con":true,"img":false}]}
{"op":"mcm","clk":"5348777200","pt":1646220607895,"mc":[{"id":"1.195453758","rc":[{"atb":[[29,12.63]],"id":3805793},{"atb":[[16,10.56]],"id":3805755},{"atb":[[7,12.27]],"id":3805736},{"atl":[[9.2,0]],"id":3805736}],"con":true,"img":false}]}
{"op":"mcm","clk":"5348777209","pt":1646220608001,"mc":[{"id":"1.195453758","rc":[{"atb":[[32,5.11],[29,27.34]],"id":3805793}],"con":true,"img":false}]}
{"op":"mcm","clk":"5348777225","pt":1646220608207,"mc":[{"id":"1.195453758","rc":[{"atl":[[9,16.66]],"id":3805736},{"atl":[[21,0]],"id":522743}],"con":true,"img":false}]}
