{"op":"mcm","clk":"5351767847","pt":1646175389004,"mc":[{"id":"1.195453766","marketDefinition":{"bspMarket":true,"turnInPlayEnabled":false,"persistenceEnabled":false,"marketBaseRate":7.0,"eventId":"31272499","eventTypeId":"4339","numberOfWinners":1,"bettingType":"ODDS","marketType":"WIN","marketTime":"2022-03-02T09:14:00.000Z","suspendTime":"2022-03-02T09:14:00.000Z","bspReconciled":false,"complete":true,"inPlay":false,"crossMatching":false,"runnersVoidable":false,"numberOfActiveRunners":7,"betDelay":0,"status":"OPEN","runners":[{"status":"ACTIVE","sortPriority":1,"id":43167133,"name":"1. Sunset Sienna"},{"status":"ACTIVE","sortPriority":2,"id":42154339,"name":"3. Foxy One"},{"status":"ACTIVE","sortPriority":3,"id":42688787,"name":"4. Double Espresso"},{"status":"ACTIVE","sortPriority":4,"id":41818763,"name":"5. Dr Kammi"},{"status":"ACTIVE","sortPriority":5,"id":39637621,"name":"6. Katara Love"},{"status":"ACTIVE","sortPriority":6,"id":42162698,"name":"7. Black Petunia"},{"status":"ACTIVE","sortPriority":7,"id":41910350,"name":"8. Big Time Money"}],"regulators":["MR_INT"],"venue":"Rockhampton","countryCode":"AU","discountAllowed":true,"timezone":"Australia/Queensland","openDate":"2022-03-02T08:34:00.000Z","version":4382437843,"name":"R3 510m Mdn/Nvce","eventName":"Rockhampton (AUS) 2nd Mar"},"rc":[],"con":true,"img":false}]}
{"op":"mcm","clk":"5351829775","pt":1646176640937,"mc":[{"id":"1.195453766","rc":[{"atb":[[16.5,6.63],[19,5.71],[11.5,9.78],[14,7.9]],"id":42162698},{"atl":[[140,0.95],[290,0.69],[190,0.7],[240,0.83]],"id":42162698},{"spn":79.5,"spf":"NaN","id":42162698},{"atb":[[4.8,27.03],[4.3,31.13],[3.9,35.43],[3.65,38.77]],"id":39637621},{"atl":[[18,7.82],[21,9.97],[26,7.98],[15.5,9.17]],"id":39637621},{"spn":10.15,"spf":"NaN","id":39637621},{"atb":[[4,34.25],[4.5,29.35],[5,25.68],[3.75,37.36]],"id":41818763},{"atl":[[16,8.86],[18.5,7.6],[22,9.5],[27,7.67]],"id":41818763},{"spn":10.5,"spf":"NaN","id":41818763},{"atb":[[17,6.42],[12,9.34],[9.8,11.67],[14.5,7.61]],"id":41910350},{"atl":[[270,0.74],[170,0.78],[220,0.9],[120,1.11]],"id":41910350},{"spn":68.5,"spf":"NaN","id":41910350},{"atb":[[5,25.68],[5.5,22.83],[6,20.54],[7,17.12]],"id":43167133},{"atl":[[19.5,7.19],[38,5.39],[24,5.78],[29,7.12]],"id":43167133},{"spn":13.25,"spf":"NaN","id":43167133},{"atb":[[1.6,171.24],[1.7,146.78],[1.75,137],[1.65,158.07]],"id":42154339},{"atl":[[3.45,54.3],[3.2,60.47],[3.95,67.64],[3.7,73.91]],"id":42154339},{"spn":2.47,"spf":"NaN","id":42154339},{"atb":[[4.5,29.35],[5,25.68],[5.5,22.83],[6,20.54]],"id":42688787},{"atl":[[34,6.04],[18.5,7.6],[22,6.33],[27,7.67]],"id":42688787},{"spn":12.25,"spf":"NaN","id":42688787}],"con":true,"img":false}]}
{"op":"mcm","clk":"5351831301","pt":1646176678079,"mc":[{"id":"1.195453766","rc":[{"atb":[[16.5,0],[19,0],[11.5,0],[14,0]],"id":42162698},{"atl":[[140,0],[290,0],[190,0],[240,0]],"id":42162698},{"atb":[[4.8,0],[4.3,0],[3.9,0],[3.65,0]],"id":39637621},{"atl":[[18,0],[21,0],[26,0],[15.5,0]],"id":39637621},{"atb":[[4,0],[4.5,0],[5,0],[3.75,0]],"id":41818763},{"atl":[[16,0],[18.5,0],[22,0],[27,0]],"id":41818763},{"atb":[[17,0],[12,0],[9.8,0],[14.5,0]],"id":41910350},{"atl":[[270,0],[170,0],[220,0],[120,0]],"id":41910350},{"atb":[[5,0],[5.5,0],[6,0],[7,0]],"id":43167133},{"atl":[[19.5,0],[38,0],[24,0],[29,0]],"id":43167133},{"atb":[[1.6,0],[1.7,0],[1.75,0],[1.65,0]],"id":42154339},{"atl":[[3.45,0],[3.2,0],[3.95,0],[3.7,0]],"id":42154339},{"atb":[[4.5,0],[5,0],[5.5,0],[6,0]],"id":42688787},{"atl":[[34,0],[18.5,0],[22,0],[27,0]],"id":42688787}],"con":true,"img":false}]}
{"op":"mcm","clk":"5351831838","pt":1646176692680,"mc":[{"id":"1.195453766","rc":[{"atl":[[30,0.18]],"id":41910350}],"con":true,"img":false}]}
{"op":"mcm","clk":"5351832836","pt":1646176717930,"mc":[{"id":"1.195453766","rc":[{"atb":[[9.6,11.94],[8.6,13.52],[11.5,9.78],[14,7.9]],"id":42162698},{"atl":[[130,1.02],[90,1.49],[180,1.11],[230,0.87]],"id":42162698},{"spn":52.0,"spf":"NaN","id":42162698},{"atb":[[3.4,42.81],[3.15,47.78],[3.9,35.43],[3.65,38.77]],"id":39637621},{"atl":[[18,11.73],[10.5,14],[13,11.08],[15.5,13.76]],"id":39637621},{"spn":7.2,"spf":"NaN","id":39637621},{"atb":[[4.6,28.54],[4.1,33.14],[3.8,36.69],[3.55,40.29]],"id":41818763},{"atl":[[17,8.31],[19.5,10.78],[24,8.67],[14.5,9.85]],"id":41818763},{"spn":9.55,"spf":"NaN","id":41818763},{"atb":[[18,6.04],[21,5.13],[26,4.1],[15.5,7.08]],"id":41910350},{"atl":[[300,0.66],[350,0.57],[200,0.66],[250,0.53]],"id":41910350},{"spn":28.0,"spf":"NaN","id":41910350},{"atb":[[5.8,21.4],[5.3,23.89],[7.6,15.56],[6.6,18.35]],"id":43167133},{"atl":[[38,5.39],[24,5.78],[48,4.24],[29,4.75]],"id":43167133},{"spn":15.8,"spf":"NaN","id":43167133},{"atb":[[1.8,128.43],[1.85,120.88],[1.7,146.78],[1.75,137]],"id":42154339},{"atl":[[3.6,51.17],[3.85,46.67],[4.2,62.36],[4.7,53.93]],"id":42154339},{"spn":2.72,"spf":"NaN","id":42154339},{"atb":[[4.5,29.35],[5,25.68],[5.5,22.83],[6,20.54]],"id":42688787},{"atl":[[34,6.04],[18.5,7.6],[22,6.33],[27,7.67]],"id":42688787}],"con":true,"img":false}]}
{"op":"mcm","clk":"5351835002","pt":1646176767877,"mc":[{"id":"1.195453766","rc":[{"atb":[[9.6,0],[8.6,0],[11.5,0],[14,0]],"id":42162698},{"atl":[[130,0],[90,0],[180,0],[230,0]],"id":42162698},{"atb":[[3.4,0],[3.15,0],[3.9,0],[3.65,0]],"id":39637621},{"atl":[[18,0],[10.5,0],[13,0],[15.5,0]],"id":39637621},{"atb":[[4.6,0],[4.1,0],[3.8,0],[3.55,0]],"id":41818763},{"atl":[[17,0],[19.5,0],[24,0],[14.5,0]],"id":41818763},{"atb":[[18,0],[21,0],[26,0],[15.5,0]],"id":41910350},{"atl":[[300,0],[350,0],[200,0],[250,0]],"id":41910350},{"atb":[[5.8,0],[5.3,0],[7.6,0],[6.6,0]],"id":43167133},{"atl":[[38,0],[24,0],[48,0],[29,0]],"id":43167133},{"atb":[[1.8,0],[1.85,0],[1.7,0],[1.75,0]],"id":42154339},{"atl":[[3.6,0],[3.85,0],[4.2,0],[4.7,0]],"id":42154339},{"atb":[[4.5,0],[5,0],[5.5,0],[6,0]],"id":42688787},{"atl":[[34,0],[18.5,0],[22,0],[27,0]],"id":42688787}],"con":true,"img":false}]}
{"op":"mcm","clk":"5351835810","pt":1646176785738,"mc":[{"id":"1.195453766","rc":[{"atb":[[9.2,12.53],[10.5,10.81],[8.2,14.27],[13,8.56]],"id":42162698},{"atl":[[80,1.68],[160,1.25],[210,0.95],[110,1.21]],"id":42162698},{"spn":46.5,"spf":"NaN","id":42162698},{"atb":[[3.4,42.81],[3.15,47.78],[3.9,35.43],[3.65,38.77]],"id":39637621},{"atl":[[18,11.73],[10.5,14],[13,11.08],[15.5,13.76]],"id":39637621},{"atb":[[4,34.25],[4.5,29.35],[5,25.68],[3.75,37.36]],"id":41818763},{"atl":[[16,8.86],[18.5,7.6],[22,9.5],[27,7.67]],"id":41818763},{"spn":10.5,"spf":"NaN","id":41818763},{"atb":[[9.2,12.53],[10.5,10.81],[8.2,14.27],[13,8.56]],"id":41910350},{"atl":[[80,1.68],[160,1.25],[210,0.95],[110,1.21]],"id":41910350},{"spn":21.5,"spf":"NaN","id":41910350},{"atb":[[8.6,13.52],[5.8,21.4],[7.6,15.56],[6.6,18.35]],"id":43167133},{"atl":[[65,3.11],[36,3.79],[90,2.24],[46,2.95]],"id":43167133},{"spn":22.3,"spf":"NaN","id":43167133},{"atb":[[1.8,128.43],[1.85,120.88],[1.7,146.78],[1.75,137]],"id":42154339},{"atl":[[3.6,51.17],[3.85,46.67],[4.2,62.36],[4.7,53.93]],"id":42154339},{"atb":[[4.8,27.03],[5.8,21.4],[5.3,23.89],[6.6,18.35]],"id":42688787},{"atl":[[36,5.69],[19,7.39],[23,6.04],[28,7.39]],"id":42688787},{"spn":12.8,"spf":"NaN","id":42688787}],"con":true,"img":false}]}
{"op":"mcm","clk":"5352004156","pt":1646180202639,"mc":[{"id":"1.195453766","marketDefinition":{"bspMarket":true,"turnInPlayEnabled":false,"persistenceEnabled":false,"marketBaseRate":7.0,"eventId":"31272499","eventTypeId":"4339","numberOfWinners":1,"bettingType":"ODDS","marketType":"WIN","marketTime":"2022-03-02T09:14:00.000Z","suspendTime":"2022-03-02T09:14:00.000Z","bspReconciled":false,"complete":true,"inPlay":false,"crossMatching":false,"runnersVoidable":false,"numberOfActiveRunners":7,"betDelay":0,"status":"OPEN","runners":[{"status":"ACTIVE","sortPriority":1,"id":43167133,"name":"1. Sunset Sienna"},{"status":"ACTIVE","sortPriority":2,"id":42154339,"name":"3. Foxy One"},{"status":"ACTIVE","sortPriority":3,"id":42688787,"name":"4. Double Espresso"},{"status":"ACTIVE","sortPriority":4,"id":41818763,"name":"5. Dr Kammi"},{"status":"ACTIVE","sortPriority":5,"id":39637621,"name":"6. Katara Love"},{"status":"ACTIVE","sortPriority":6,"id":42162698,"name":"7. Black Petunia"},{"status":"ACTIVE","sortPriority":7,"id":41910350,"name":"8. Big Time Money"}],"regulators":["MR_INT"],"venue":"Rockhampton","countryCode":"AU","discountAllowed":true,"timezone":"Australia/Queensland","openDate":"2022-03-02T08:34:00.000Z","version":4382437843,"name":"R3 510m Mdn/Nvce","eventName":"Rockhampton (AUS) 2nd Mar"},"rc":[{"atb":[[9.2,12.53],[10.5,10.81],[8.2,14.27],[13,8.56]],"id":42162698},{"atl":[[80,1.68],[160,1.25],[210,0.95],[110,1.21]],"id":42162698},{"spn":46.5,"spf":"NaN","id":42162698},{"atb":[[3.4,42.81],[3.15,47.79],[3.9,35.43],[3.65,38.77]],"id":39637621},{"atl":[[18,11.73],[10.5,14],[13,11.08],[15.5,13.76]],"id":39637621},{"spn":7.2,"spf":"NaN","id":39637621},{"atb":[[4,34.25],[4.5,29.36],[5,25.69],[3.75,37.36]],"id":41818763},{"atl":[[16,8.86],[18.5,7.6],[22,9.5],[27,7.67]],"id":41818763},{"spn":10.5,"spf":"NaN","id":41818763},{"atb":[[9.2,12.53],[10.5,10.81],[8.2,14.27],[13,8.56]],"id":41910350},{"atl":[[80,1.68],[160,1.25],[210,0.95],[110,1.21],[30,0.18]],"id":41910350},{"spn":21.5,"spf":"NaN","id":41910350},{"atb":[[8.6,13.52],[5.8,21.4],[7.6,15.57],[6.6,18.35]],"id":43167133},{"atl":[[65,3.11],[36,3.8],[90,2.24],[46,2.95]],"id":43167133},{"spn":22.3,"spf":"NaN","id":43167133},{"atb":[[1.8,128.45],[1.85,120.89],[1.7,146.79],[1.75,137.01]],"id":42154339},{"atl":[[3.6,51.17],[3.85,46.68],[4.2,62.36],[4.7,53.94]],"id":42154339},{"spn":2.72,"spf":"NaN","id":42154339},{"atb":[[4.8,27.04],[5.8,21.4],[5.3,23.9],[6.6,18.35]],"id":42688787},{"atl":[[36,5.7],[19,7.39],[23,6.04],[28,7.39]],"id":42688787},{"spn":12.8,"spf":"NaN","id":42688787}],"con":true,"img":true}]}
{"op":"mcm","clk":"5352086368","pt":1646182161026,"mc":[{"id":"1.195453766","rc":[{"atb":[[9.2,0],[10.5,0],[8.2,0],[13,0]],"id":42162698},{"atl":[[80,0],[160,0],[210,0],[110,0]],"id":42162698},{"spn":"NaN","spf":"NaN","id":42162698},{"atb":[[3.4,0],[3.15,0],[3.9,0],[3.65,0]],"id":39637621},{"atl":[[18,0],[10.5,0],[13,0],[15.5,0]],"id":39637621},{"spn":"NaN","spf":"NaN","id":39637621},{"atb":[[4,0],[4.5,0],[5,0],[3.75,0]],"id":41818763},{"atl":[[16,0],[18.5,0],[22,0],[27,0]],"id":41818763},{"spn":"NaN","spf":"NaN","id":41818763},{"atb":[[9.2,12.53],[10.5,10.81],[8.2,14.27],[13,8.56]],"id":41910350},{"atl":[[80,1.68],[160,1.25],[210,0.95],[110,1.21]],"id":41910350},{"atb":[[8.6,0],[5.8,0],[7.6,0],[6.6,0]],"id":43167133},{"atl":[[65,0],[36,0],[90,0],[46,0]],"id":43167133},{"spn":"NaN","spf":"NaN","id":43167133},{"atb":[[1.8,0],[1.85,0],[1.7,0],[1.75,0]],"id":42154339},{"atl":[[3.6,0],[3.85,0],[4.2,0],[4.7,0]],"id":42154339},{"spn":"NaN","spf":"NaN","id":42154339},{"atb":[[4.8,0],[5.8,0],[5.3,0],[6.6,0]],"id":42688787},{"atl":[[36,0],[19,0],[23,0],[28,0]],"id":42688787},{"spn":"NaN","spf":"NaN","id":42688787}],"con":true,"img":false}]}
{"op":"mcm","clk":"5352086552","pt":1646182166438,"mc":[{"id":"1.195453766","rc":[{"atb":[[9.6,11.95],[8.6,13.52],[11.5,9.78],[14,7.9]],"id":42162698},{"atl":[[130,1.02],[90,1.49],[180,1.11],[230,0.87]],"id":42162698},{"atb":[[2.9,54.08],[3,51.38],[3.25,45.67],[3.5,41.1]],"id":39637621},{"atl":[[11,19.95],[13.5,15.96],[8.4,17.98],[9.4,15.84]],"id":39637621},{"atb":[[4,34.25],[4.5,29.36],[5,25.69],[3.75,37.36]],"id":41818763},{"atl":[[16,8.86],[18.5,7.6],[22,9.5],[27,7.67]],"id":41818763},{"atb":[[8.6,13.52],[5.8,21.4],[7.6,15.57],[6.6,18.35]],"id":43167133},{"atl":[[65,3.11],[36,3.8],[90,2.24],[46,2.95]],"id":43167133},{"atb":[[1.8,128.45],[1.85,120.89],[1.7,146.79],[1.75,137.01]],"id":42154339},{"atl":[[3.6,51.17],[3.85,46.68],[4.2,62.36],[4.7,53.94]],"id":42154339},{"atb":[[5.8,21.4],[5.3,23.9],[7.6,15.57],[6.6,18.35]],"id":42688787},{"atl":[[38,5.39],[24,5.78],[48,4.24],[29,4.75]],"id":42688787}],"con":true,"img":false}]}
{"op":"mcm","clk":"5352146199","pt":1646183572653,"mc":[{"id":"1.195453766","marketDefinition":{"bspMarket":true,"turnInPlayEnabled":false,"persistenceEnabled":false,"marketBaseRate":7.0,"eventId":"31272499","eventTypeId":"4339","numberOfWinners":1,"bettingType":"ODDS","marketType":"WIN","marketTime":"2022-03-02T09:14:00.000Z","suspendTime":"2022-03-02T09:14:00.000Z","bspReconciled":false,"complete":true,"inPlay":false,"crossMatching":false,"runnersVoidable":false,"numberOfActiveRunners":7,"betDelay":0,"status":"OPEN","runners":[{"status":"ACTIVE","sortPriority":1,"id":43167133,"name":"1. Sunset Sienna"},{"status":"ACTIVE","sortPriority":2,"id":42154339,"name":"3. Foxy One"},{"status":"ACTIVE","sortPriority":3,"id":42688787,"name":"4. Double Espresso"},{"status":"ACTIVE","sortPriority":4,"id":41818763,"name":"5. Dr Kammi"},{"status":"ACTIVE","sortPriority":5,"id":39637621,"name":"6. Katara Love"},{"status":"ACTIVE","sortPriority":6,"id":42162698,"name":"7. Black Petunia"},{"status":"ACTIVE","sortPriority":7,"id":41910350,"name":"8. Big Time Money"}],"regulators":["MR_INT"],"venue":"Rockhampton","countryCode":"AU","discountAllowed":true,"timezone":"Australia/Queensland","openDate":"2022-03-02T08:28:00.000Z","version":4382597824,"name":"R3 510m Mdn/Nvce","eventName":"Rockhampton (AUS) 2nd Mar"},"rc":[],"con":true,"img":false}]}
{"op":"mcm","clk":"5352153362","pt":1646183774091,"mc":[{"id":"1.195453766","marketDefinition":{"bspMarket":true,"turnInPlayEnabled":false,"persistenceEnabled":false,"marketBaseRate":7.0,"eventId":"31272499","eventTypeId":"4339","numberOfWinners":1,"bettingType":"ODDS","marketType":"WIN","marketTime":"2022-03-02T09:08:00.000Z","suspendTime":"2022-03-02T09:08:00.000Z","bspReconciled":false,"complete":true,"inPlay":false,"crossMatching":false,"runnersVoidable":false,"numberOfActiveRunners":7,"betDelay":0,"status":"OPEN","runners":[{"status":"ACTIVE","sortPriority":1,"id":43167133,"name":"1. Sunset Sienna"},{"status":"ACTIVE","sortPriority":2,"id":42154339,"name":"3. Foxy One"},{"status":"ACTIVE","sortPriority":3,"id":42688787,"name":"4. Double Espresso"},{"status":"ACTIVE","sortPriority":4,"id":41818763,"name":"5. Dr Kammi"},{"status":"ACTIVE","sortPriority":5,"id":39637621,"name":"6. Katara Love"},{"status":"ACTIVE","sortPriority":6,"id":42162698,"name":"7. Black Petunia"},{"status":"ACTIVE","sortPriority":7,"id":41910350,"name":"8. Big Time Money"}],"regulators":["MR_INT"],"venue":"Rockhampton","countryCode":"AU","discountAllowed":true,"timezone":"Australia/Queensland","openDate":"2022-03-02T08:28:00.000Z","version":4382601056,"name":"R3 510m Mdn/Nvce","eventName":"Rockhampton (AUS) 2nd Mar"},"rc":[],"con":true,"img":false}]}
{"op":"mcm","clk":"5352238281","pt":1646185602674,"mc":[{"id":"1.195453766","marketDefinition":{"bspMarket":true,"turnInPlayEnabled":false,"persistenceEnabled":false,"marketBaseRate":7.0,"eventId":"31272499","eventTypeId":"4339","numberOfWinners":1,"bettingType":"ODDS","marketType":"WIN","marketTime":"2022-03-02T09:08:00.000Z","suspendTime":"2022-03-02T09:08:00.000Z","bspReconciled":false,"complete":true,"inPlay":false,"crossMatching":false,"runnersVoidable":false,"numberOfActiveRunners":7,"betDelay":0,"status":"OPEN","runners":[{"status":"ACTIVE","sortPriority":1,"id":43167133,"name":"1. Sunset Sienna"},{"status":"ACTIVE","sortPriority":2,"id":42154339,"name":"3. Foxy One"},{"status":"ACTIVE","sortPriority":3,"id":42688787,"name":"4. Double Espresso"},{"status":"ACTIVE","sortPriority":4,"id":41818763,"name":"5. Dr Kammi"},{"status":"ACTIVE","sortPriority":5,"id":39637621,"name":"6. Katara Love"},{"status":"ACTIVE","sortPriority":6,"id":42162698,"name":"7. Black Petunia"},{"status":"ACTIVE","sortPriority":7,"id":41910350,"name":"8. Big Time Money"}],"regulators":["MR_INT"],"venue":"Rockhampton","countryCode":"AU","discountAllowed":true,"timezone":"Australia/Queensland","openDate":"2022-03-02T08:28:00.000Z","version":4382601056,"name":"R3 510m Mdn/Nvce","eventName":"Rockhampton (AUS) 2nd Mar"},"rc":[{"atb":[[9.6,11.96],[8.6,13.54],[11.5,9.8],[14,7.91]],"id":42162698},{"atl":[[130,1.03],[90,1.49],[180,1.11],[230,0.87]],"id":42162698},{"spn":52.0,"spf":"NaN","id":42162698},{"atb":[[2.9,54.16],[3,51.46],[3.25,45.74],[3.5,41.16]],"id":39637621},{"atl":[[11,19.99],[13.5,15.99],[8.4,18.01],[9.4,15.86]],"id":39637621},{"spn":5.95,"spf":"NaN","id":39637621},{"atb":[[4,34.3],[4.5,29.4],[5,25.73],[3.75,37.42]],"id":41818763},{"atl":[[16,8.88],[18.5,7.61],[22,9.52],[27,7.68]],"id":41818763},{"spn":10.5,"spf":"NaN","id":41818763},{"atb":[[9.2,12.55],[10.5,10.83],[8.2,14.29],[13,8.57]],"id":41910350},{"atl":[[80,1.68],[160,1.25],[210,0.95],[110,1.22],[30,0.18]],"id":41910350},{"spn":21.5,"spf":"NaN","id":41910350},{"atb":[[8.6,13.54],[5.8,21.44],[7.6,15.59],[6.6,18.38]],"id":43167133},{"atl":[[65,3.12],[36,3.8],[90,2.24],[46,2.96]],"id":43167133},{"spn":22.3,"spf":"NaN","id":43167133},{"atb":[[1.8,128.65],[1.85,121.08],[1.7,147.03],[1.75,137.23]],"id":42154339},{"atl":[[3.6,51.25],[3.85,46.75],[4.2,62.46],[4.7,54.02]],"id":42154339},{"spn":2.72,"spf":"NaN","id":42154339},{"atb":[[5.8,21.44],[5.3,23.93],[7.6,15.59],[6.6,18.38]],"id":42688787},{"atl":[[38,5.4],[24,5.79],[48,4.25],[29,4.76]],"id":42688787},{"spn":15.8,"spf":"NaN","id":42688787}],"con":true,"img":true}]}
{"op":"mcm","clk":"5352465578","pt":1646191002622,"mc":[{"id":"1.195453766","marketDefinition":{"bspMarket":true,"turnInPlayEnabled":false,"persistenceEnabled":false,"marketBaseRate":7.0,"eventId":"31272499","eventTypeId":"4339","numberOfWinners":1,"bettingType":"ODDS","marketType":"WIN","marketTime":"2022-03-02T09:08:00.000Z","suspendTime":"2022-03-02T09:08:00.000Z","bspReconciled":false,"complete":true,"inPlay":false,"crossMatching":false,"runnersVoidable":false,"numberOfActiveRunners":7,"betDelay":0,"status":"OPEN","runners":[{"status":"ACTIVE","sortPriority":1,"id":43167133,"name":"1. Sunset Sienna"},{"status":"ACTIVE","sortPriority":2,"id":42154339,"name":"3. Foxy One"},{"status":"ACTIVE","sortPriority":3,"id":42688787,"name":"4. Double Espresso"},{"status":"ACTIVE","sortPriority":4,"id":41818763,"name":"5. Dr Kammi"},{"status":"ACTIVE","sortPriority":5,"id":39637621,"name":"6. Katara Love"},{"status":"ACTIVE","sortPriority":6,"id":42162698,"name":"7. Black Petunia"},{"status":"ACTIVE","sortPriority":7,"id":41910350,"name":"8. Big Time Money"}],"regulators":["MR_INT"],"venue":"Rockhampton","countryCode":"AU","discountAllowed":true,"timezone":"Australia/Queensland","openDate":"2022-03-02T08:28:00.000Z","version":4382601056,"name":"R3 510m Mdn/Nvce","eventName":"Rockhampton (AUS) 2nd Mar"},"rc":[{"atb":[[9.6,11.98],[8.6,13.56],[11.5,9.82],[14,7.93]],"id":42162698},{"atl":[[130,1.03],[90,1.5],[180,1.11],[230,0.87]],"id":42162698},{"spn":52.0,"spf":"NaN","id":42162698},{"atb":[[2.9,54.26],[3,51.55],[3.25,45.82],[3.5,41.23]],"id":39637621},{"atl":[[11,20.02],[13.5,16.02],[8.4,18.04],[9.4,15.89]],"id":39637621},{"spn":5.95,"spf":"NaN","id":39637621},{"atb":[[4,34.36],[4.5,29.45],[5,25.77],[3.75,37.49]],"id":41818763},{"atl":[[16,8.89],[18.5,7.63],[22,9.53],[27,7.7]],"id":41818763},{"spn":10.5,"spf":"NaN","id":41818763},{"atb":[[9.2,12.57],[10.5,10.85],[8.2,14.32],[13,8.59]],"id":41910350},{"atl":[[80,1.68],[160,1.26],[210,0.95],[110,1.22],[30,0.18]],"id":41910350},{"spn":21.5,"spf":"NaN","id":41910350},{"atb":[[8.6,13.56],[5.8,21.47],[7.6,15.62],[6.6,18.41]],"id":43167133},{"atl":[[65,3.12],[36,3.81],[90,2.25],[46,2.96]],"id":43167133},{"spn":22.3,"spf":"NaN","id":43167133},{"atb":[[1.8,128.87],[1.85,121.29],[1.7,147.27],[1.75,137.46]],"id":42154339},{"atl":[[3.6,51.34],[3.85,46.83],[4.2,62.57],[4.7,54.11]],"id":42154339},{"spn":2.72,"spf":"NaN","id":42154339},{"atb":[[5.8,21.47],[5.3,23.97],[7.6,15.62],[6.6,18.41]],"id":42688787},{"atl":[[38,5.41],[24,5.8],[48,4.26],[29,4.76]],"id":42688787},{"spn":15.8,"spf":"NaN","id":42688787}],"con":true,"img":true}]}
{"op":"mcm","clk":"5352601727","pt":1646194734259,"mc":[{"id":"1.195453766","rc":[{"atb":[[9.6,0],[8.6,0],[11.5,0],[14,0]],"id":42162698},{"atl":[[130,0],[90,0],[180,0],[230,0]],"id":42162698},{"atb":[[2.9,0],[3,0],[3.25,0],[3.5,0]],"id":39637621},{"atl":[[11,0],[13.5,0],[8.4,0],[9.4,0]],"id":39637621},{"atb":[[4,0],[4.5,0],[5,0],[3.75,0]],"id":41818763},{"atl":[[16,0],[18.5,0],[22,0],[27,0]],"id":41818763},{"atb":[[9.2,12.57],[10.5,10.85],[8.2,14.32],[13,8.59]],"id":41910350},{"atl":[[80,1.68],[160,1.26],[210,0.95],[110,1.22],[30,0.18]],"id":41910350},{"atb":[[8.6,0],[5.8,0],[7.6,0],[6.6,0]],"id":43167133},{"atl":[[65,0],[36,0],[90,0],[46,0]],"id":43167133},{"atb":[[1.8,128.87],[1.85,121.29],[1.7,147.27],[1.75,137.46]],"id":42154339},{"atl":[[3.6,51.34],[3.85,46.83],[4.2,62.57],[4.7,54.11]],"id":42154339},{"spn":2.72,"spf":"NaN","id":42154339},{"atb":[[5.8,21.47],[5.3,23.97],[7.6,15.62],[6.6,18.41]],"id":42688787},{"atl":[[38,5.41],[24,5.8],[48,4.26],[29,4.76]],"id":42688787},{"spn":15.8,"spf":"NaN","id":42688787}],"con":true,"img":false}]}
{"op":"mcm","clk":"5352602393","pt":1646194751778,"mc":[{"id":"1.195453766","rc":[{"atb":[[17.5,6.24],[20,5.42],[12.5,8.96],[15,7.36]],"id":42162698},{"atl":[[150,0.89],[300,0.67],[200,0.67],[250,0.8]],"id":42162698},{"atb":[[2.9,54.26],[3,51.55],[3.25,45.82],[3.5,41.23]],"id":39637621},{"atl":[[11,20.02],[13.5,16.02],[8.4,18.04],[9.4,15.89]],"id":39637621},{"atb":[[4,34.36],[4.5,29.45],[5,25.77],[3.75,37.49]],"id":41818763},{"atl":[[16,8.89],[18.5,7.63],[22,9.53],[27,7.7]],"id":41818763},{"atb":[[8.6,13.56],[5.8,21.47],[7.6,15.62],[6.6,18.41]],"id":43167133},{"atl":[[65,3.12],[36,3.81],[90,2.25],[46,2.96]],"id":43167133}],"con":true,"img":false}]}
{"op":"mcm","clk":"5352603663","pt":1646194791993,"mc":[{"id":"1.195453766","rc":[{"atb":[[17.5,0],[20,0],[12.5,0],[15,0]],"id":42162698},{"atl":[[150,0],[300,0],[200,0],[250,0]],"id":42162698}],"con":true,"img":false}]}
{"op":"mcm","clk":"5352603860","pt":1646194797989,"mc":[{"id":"1.195453766","rc":[{"atb":[[17.5,6.24],[20,5.42],[12.5,8.96],[15,7.36]],"id":42162698},{"atl":[[150,0.89],[300,0.67],[200,0.67],[250,0.8]],"id":42162698},{"spn":85.0,"spf":"NaN","id":42162698},{"spn":5.95,"spf":"NaN","id":39637621},{"spn":10.5,"spf":"NaN","id":41818763},{"spn":22.3,"spf":"NaN","id":43167133}],"con":true,"img":false}]}
{"op":"mcm","clk":"5352693690","pt":1646197219722,"mc":[{"id":"1.195453766","rc":[{"atb":[[17.5,6.24],[20,5.42],[12.5,8.95],[15,7.36]],"id":42162698},{"atl":[[150,0.89],[300,0.67],[200,0.67],[250,0.8]],"id":42162698},{"atb":[[2.9,54.23],[3,51.53],[3.25,45.8],[3.5,41.22]],"id":39637621},{"atl":[[11,20.01],[13.5,16.01],[8.4,18.03],[9.4,15.88]],"id":39637621},{"atb":[[4,34.35],[4.5,29.44],[5,25.76],[3.75,37.47]],"id":41818763},{"atl":[[16,8.89],[18.5,7.62],[22,9.53],[27,7.69]],"id":41818763},{"atb":[[9.2,12.56],[10.5,10.84],[8.2,14.31],[13,8.58]],"id":41910350},{"atl":[[80,1.68],[160,1.26],[210,0.95],[110,1.22]],"id":41910350},{"atb":[[8.6,13.56],[5.8,21.46],[7.6,15.61],[6.6,18.4]],"id":43167133},{"atl":[[65,3.12],[36,3.81],[90,2.24],[46,2.96]],"id":43167133},{"atb":[[1.8,128.82],[1.85,121.24],[1.7,147.22],[1.75,137.41]],"id":42154339},{"atl":[[2.4,6.2],[3.6,51.32],[3.85,46.81],[4.2,62.54],[4.7,54.09]],"id":42154339},{"spn":2.12,"spf":"NaN","id":42154339},{"atb":[[5.8,21.46],[5.3,23.96],[7.6,15.61],[6.6,18.4]],"id":42688787},{"atl":[[38,5.41],[24,5.8],[48,4.25],[29,4.76]],"id":42688787}],"con":true,"img":false}]}
{"op":"mcm","clk":"5352693883","pt":1646197225720,"mc":[{"id":"1.195453766","rc":[{"atl":[[2.6,8.52]],"id":42154339}],"con":true,"img":false}]}
{"op":"mcm","clk":"5352696179","pt":1646197292729,"mc":[{"id":"1.195453766","rc":[{"atb":[[1.85,120.27]],"id":42154339},{"trd":[[1.85,1.93]],"ltp":1.85,"tv":1.93,"id":42154339}],"con":true,"img":false}]}
{"op":"mcm","clk":"5352870687","pt":1646203288433,"mc":[{"id":"1.195453766","rc":[{"atb":[[3.55,3.23]],"id":39637621},{"spn":5.97,"spf":"NaN","id":39637621},{"atb":[[1.01,2.25]],"id":41818763},{"atb":[[1.88,9.39]],"id":42154339},{"spn":2.14,"spf":"NaN","id":42154339}],"con":true,"img":false}]}
{"op":"mcm","clk":"5352870694","pt":1646203288585,"mc":[{"id":"1.195453766","rc":[{"atb":[[1.01,2.01]],"id":41818763}],"con":true,"img":false}]}
{"op":"mcm","clk":"5352870721","pt":1646203289305,"mc":[{"id":"1.195453766","rc":[{"atb":[[1.01,0]],"id":41818763}],"con":true,"img":false}]}
{"op":"mcm","clk":"5352870727","pt":1646203289408,"mc":[{"id":"1.195453766","rc":[{"atb":[[5.1,2.01]],"id":41818763}],"con":true,"img":false}]}
{"op":"mcm","clk":"5352871811","pt":1646203319708,"mc":[{"id":"1.195453766","marketDefinition":{"bspMarket":true,"turnInPlayEnabled":false,"persistenceEnabled":false,"marketBaseRate":7.0,"eventId":"31272499","eventTypeId":"4339","numberOfWinners":1,"bettingType":"ODDS","marketType":"WIN","marketTime":"2022-03-02T09:08:00.000Z","suspendTime":"2022-03-02T09:08:00.000Z","bspReconciled":false,"complete":true,"inPlay":false,"crossMatching":true,"runnersVoidable":false,"numberOfActiveRunners":7,"betDelay":0,"status":"OPEN","runners":[{"status":"ACTIVE","sortPriority":1,"id":43167133,"name":"1. Sunset Sienna"},{"status":"ACTIVE","sortPriority":2,"id":42154339,"name":"3. Foxy One"},{"status":"ACTIVE","sortPriority":3,"id":42688787,"name":"4. Double Espresso"},{"status":"ACTIVE","sortPriority":4,"id":41818763,"name":"5. Dr Kammi"},{"status":"ACTIVE","sortPriority":5,"id":39637621,"name":"6. Katara Love"},{"status":"ACTIVE","sortPriority":6,"id":42162698,"name":"7. Black Petunia"},{"status":"ACTIVE","sortPriority":7,"id":41910350,"name":"8. Big Time Money"}],"regulators":["MR_INT"],"venue":"Rockhampton","countryCode":"AU","discountAllowed":true,"timezone":"Australia/Queensland","openDate":"2022-03-02T08:28:00.000Z","version":4382601056,"name":"R3 510m Mdn/Nvce","eventName":"Rockhampton (AUS) 2nd Mar"},"rc":[],"con":true,"img":false}]}
{"op":"mcm","clk":"5352876647","pt":1646203452939,"mc":[{"id":"1.195453766","rc":[{"atb":[[3.55,7.19]],"id":39637621},{"spn":10.55,"spf":"NaN","id":41818763}],"con":true,"img":false}]}
{"op":"mcm","clk":"5352876658","pt":1646203453145,"mc":[{"id":"1.195453766","rc":[{"atb":[[5.1,4.47]],"id":41818763}],"con":true,"img":false}]}
{"op":"mcm","clk":"5352876662","pt":1646203453246,"mc":[{"id":"1.195453766","rc":[{"atb":[[1.88,20.87]],"id":42154339}],"con":true,"img":false}]}
{"op":"mcm","clk":"5352926850","pt":1646204880192,"mc":[{"id":"1.195453766","rc":[{"atb":[[17.5,6.24],[19.5,0.55],[20,5.42],[12.5,8.95],[15,7.35]],"id":42162698},{"atl":[[150,0.89],[300,0.67],[200,0.67],[250,0.8]],"id":42162698},{"atb":[[2.9,54.22],[3,51.51],[3.55,7.2],[3.25,45.79],[3.5,43.21]],"id":39637621},{"atl":[[11,20.01],[13.5,16],[8.4,18.02],[9.4,15.88]],"id":39637621},{"atb":[[4,34.34],[5.1,6.48],[4.5,29.43],[5,25.75],[3.75,37.46]],"id":41818763},{"atl":[[16,8.89],[18.5,7.62],[22,9.53],[27,7.69]],"id":41818763},{"atb":[[17,0.64],[9.2,12.56],[10.5,10.84],[8.2,14.31],[13,8.58]],"id":41910350},{"atl":[[80,1.68],[160,1.26],[210,0.95],[110,1.22]],"id":41910350},{"spn":23.5,"spf":"NaN","id":41910350},{"atb":[[9.6,1.17],[8.6,13.55],[5.8,21.46],[7.6,15.61],[6.6,18.4]],"id":43167133},{"atl":[[65,3.12],[36,3.81],[90,2.24],[46,2.96]],"id":43167133},{"spn":22.8,"spf":"NaN","id":43167133},{"atb":[[1.8,128.78],[1.03,2],[1.88,20.89],[1.85,120.24],[1.7,147.18],[1.75,137.37]],"id":42154339},{"atl":[[2.4,6.21],[3.6,51.31],[3.85,46.8],[2.6,8.54],[4.2,62.53],[4.7,54.08]],"id":42154339},{"trd":[[1.85,1.93]],"ltp":1.85,"tv":1.93,"id":42154339},{"atb":[[7.2,1.62],[5.8,21.46],[5.3,23.96],[7.6,15.61],[6.6,18.4]],"id":42688787},{"atl":[[38,5.4],[24,5.8],[48,4.25],[29,4.76]],"id":42688787}],"con":true,"img":false}]}
{"op":"mcm","clk":"5352929642","pt":1646204947864,"mc":[{"id":"1.195453766","rc":[{"atb":[[17,0]],"id":41910350},{"spn":21.5,"spf":"NaN","id":41910350}],"con":true,"img":false}]}
{"op":"mcm","clk":"5352929646","pt":1646204947968,"mc":[{"id":"1.195453766","rc":[{"atb":[[18,0.6]],"id":41910350}],"con":true,"img":false}]}
{"op":"mcm","clk":"5352931513","pt":1646204992250,"mc":[{"id":"1.195453766","rc":[{"atb":[[2.9,0],[3,0],[3.25,0],[3.5,2]],"id":39637621},{"atl":[[11,0],[13.5,0],[8.4,0],[9.4,0]],"id":39637621},{"atb":[[5.8,0],[5.3,0],[7.6,0],[6.6,0]],"id":42688787},{"atl":[[38,0],[24,0],[48,0],[29,0]],"id":42688787}],"con":true,"img":false}]}
{"op":"mcm","clk":"5352931827","pt":1646204998938,"mc":[{"id":"1.195453766","rc":[{"atb":[[3.45,42.15],[3.2,46.94],[3.7,38.24],[2.98,52.15]],"id":39637621},{"atl":[[16,13.31],[11,13.31],[13.5,15.98],[9.4,15.85]],"id":39637621},{"atb":[[5.8,21.51],[5.3,24.01],[7.6,15.64],[6.6,18.43]],"id":42688787},{"atl":[[38,5.39],[24,5.79],[48,4.25],[29,4.75]],"id":42688787}],"con":true,"img":false}]}
{"op":"mcm","clk":"5352931869","pt":1646204999962,"mc":[{"id":"1.195453766","rc":[{"atb":[[3.55,3.95]],"id":39637621}],"con":true,"img":false}]}
{"op":"mcm","clk":"5352932487","pt":1646205014978,"mc":[{"id":"1.195453766","rc":[{"atb":[[3.75,2.73]],"id":39637621},{"spn":6.57,"spf":"NaN","id":39637621},{"spn":24.0,"spf":"NaN","id":41910350}],"con":true,"img":false}]}
{"op":"mcm","clk":"5352932709","pt":1646205020107,"mc":[{"id":"1.195453766","rc":[{"atb":[[3.55,0]],"id":39637621}],"con":true,"img":false}]}
{"op":"mcm","clk":"5352933024","pt":1646205028783,"mc":[{"id":"1.195453766","rc":[{"atb":[[3.75,6.41]],"id":39637621}],"con":true,"img":false}]}
{"op":"mcm","clk":"5352954541","pt":1646205550339,"mc":[{"id":"1.195453766","rc":[{"atb":[[1.03,0]],"id":42154339}],"con":true,"img":false}]}
{"op":"mcm","clk":"5352954548","pt":1646205550542,"mc":[{"id":"1.195453766","rc":[{"atb":[[1.05,2]],"id":42154339}],"con":true,"img":false}]}
{"op":"mcm","clk":"5352956455","pt":1646205609456,"mc":[{"id":"1.195453766","rc":[{"atb":[[19.5,0]],"id":42162698},{"atb":[[3.4,2],[3.5,0]],"id":39637621},{"atb":[[5.1,4.48],[4.9,2]],"id":41818763},{"atb":[[16.5,0.66],[18,0]],"id":41910350},{"atb":[[9.6,0],[10.5,1.06]],"id":43167133},{"atb":[[1.19,2],[1.05,0]],"id":42154339},{"atb":[[7.2,0]],"id":42688787}],"con":true,"img":false}]}
{"op":"mcm","clk":"5352956459","pt":1646205609559,"mc":[{"id":"1.195453766","rc":[{"atb":[[19.5,0.55]],"id":42162698},{"atb":[[7.2,1.62]],"id":42688787}],"con":true,"img":false}]}
{"op":"mcm","clk":"5352974468","pt":1646206127827,"mc":[{"id":"1.195453766","rc":[{"spn":23.25,"spf":"NaN","id":41910350},{"spn":23.25,"spf":"NaN","id":43167133},{"atl":[[3.1,8.18]],"id":42154339}],"con":true,"img":false}]}
{"op":"mcm","clk":"5352980078","pt":1646206261656,"mc":[{"id":"1.195453766","rc":[{"atb":[[3.4,0]],"id":39637621}],"con":true,"img":false}]}
{"op":"mcm","clk":"5352980083","pt":1646206261808,"mc":[{"id":"1.195453766","rc":[{"atb":[[3.45,44.15]],"id":39637621}],"con":true,"img":false}]}
{"op":"mcm","clk":"5353000125","pt":1646206725358,"mc":[{"id":"1.195453766","rc":[{"atb":[[18,3.44],[15.5,8.73]],"id":42162698},{"atl":[[70,2.72],[90,2.72]],"id":42162698},{"spn":45.0,"spf":"NaN","id":42162698},{"atb":[[3,60.72],[3.5,23.41]],"id":39637621},{"atl":[[8.6,14.8],[6.4,10.84]],"id":39637621},{"spn":5.07,"spf":"NaN","id":39637621},{"atb":[[4.6,16.26],[4.1,42.57]],"id":41818763},{"atl":[[9.8,6.65],[13.5,9.27]],"id":41818763},{"spn":7.45,"spf":"NaN","id":41818763},{"atb":[[13.5,9.23],[14.5,4.33]],"id":41910350},{"atl":[[65,2.72],[48,2.72]],"id":41910350},{"atb":[[9,7.31],[8.8,16.37]],"id":43167133},{"atl":[[34,3.82],[24,2.72]],"id":43167133},{"spn":17.25,"spf":"NaN","id":43167133},{"atb":[[1.56,227.07],[1.86,68.07]],"id":42154339},{"atl":[[3.25,26.02],[3.55,49.67]],"id":42154339},{"atb":[[6.8,20.89],[7.8,8.6]],"id":42688787},{"atl":[[18.5,3.34],[23,5.5]],"id":42688787},{"spn":13.15,"spf":"NaN","id":42688787}],"con":true,"img":false}]}
{"op":"mcm","clk":"5353000447","pt":1646206732578,"mc":[{"id":"1.195453766","rc":[{"atb":[[1.88,11.48]],"id":42154339}],"con":true,"img":false}]}
{"op":"mcm","clk":"5353000855","pt":1646206741584,"mc":[{"id":"1.195453766","rc":[{"atb":[[1.89,8.45]],"id":42154339}],"con":true,"img":false}]}
{"op":"mcm","clk":"5353001249","pt":1646206751393,"mc":[{"id":"1.195453766","rc":[{"atb":[[1.88,0]],"id":42154339}],"con":true,"img":false}]}
{"op":"mcm","clk":"5353001650","pt":1646206760690,"mc":[{"id":"1.195453766","rc":[{"atb":[[1.89,19.81]],"id":42154339}],"con":true,"img":false}]}
{"op":"mcm","clk":"5353002400","pt":1646206779632,"mc":[{"id":"1.195453766","rc":[{"atb":[[3.5,0]],"id":39637621}],"con":true,"img":false}]}
{"op":"mcm","clk":"5353002406","pt":1646206779735,"mc":[{"id":"1.195453766","rc":[{"atb":[[3.25,23.41]],"id":39637621}],"con":true,"img":false}]}
{"op":"mcm","clk":"5353003389","pt":1646206803156,"mc":[{"id":"1.195453766","rc":[{"atb":[[2.04,2.72]],"id":42154339},{"spn":2.22,"spf":"NaN","id":42154339}],"con":true,"img":false}]}
{"op":"mcm","clk":"5353004743","pt":1646206837144,"mc":[{"id":"1.195453766","rc":[{"atb":[[1.86,0]],"id":42154339}],"con":true,"img":false}]}
{"op":"mcm","clk":"5353004747","pt":1646206837243,"mc":[{"id":"1.195453766","rc":[{"atb":[[1.9,68.07]],"id":42154339}],"con":true,"img":false}]}
{"op":"mcm","clk":"5353005008","pt":1646206843954,"mc":[{"id":"1.195453766","rc":[{"atb":[[1.89,11.35]],"id":42154339}],"con":true,"img":false}]}
{"op":"mcm","clk":"5353005339","pt":1646206852766,"mc":[{"id":"1.195453766","rc":[{"atb":[[1.93,8.09]],"id":42154339}],"con":true,"img":false}]}
{"op":"mcm","clk":"5353005473","pt":1646206856877,"mc":[{"id":"1.195453766","rc":[{"atb":[[1.89,0]],"id":42154339}],"con":true,"img":false}]}
{"op":"mcm","clk":"5353005761","pt":1646206863491,"mc":[{"id":"1.195453766","rc":[{"atb":[[1.9,0]],"id":42154339}],"con":true,"img":false}]}
{"op":"mcm","clk":"5353005766","pt":1646206863582,"mc":[{"id":"1.195453766","rc":[{"atb":[[1.86,68.07]],"id":42154339}],"con":true,"img":false}]}
{"op":"mcm","clk":"5353006081","pt":1646206870993,"mc":[{"id":"1.195453766","rc":[{"atb":[[1.93,0]],"id":42154339}],"con":true,"img":false}]}
{"op":"mcm","clk":"5353006471","pt":1646206879898,"mc":[{"id":"1.195453766","rc":[{"atb":[[1.89,8.45]],"id":42154339}],"con":true,"img":false}]}
{"op":"mcm","clk":"5353006724","pt":1646206886517,"mc":[{"id":"1.195453766","rc":[{"atb":[[1.89,19.81]],"id":42154339}],"con":true,"img":false}]}
{"op":"mcm","clk":"5353009308","pt":1646206949514,"mc":[{"id":"1.195453766","rc":[{"atb":[[1.86,0]],"id":42154339}],"con":true,"img":false}]}
{"op":"mcm","clk":"5353009315","pt":1646206949620,"mc":[{"id":"1.195453766","rc":[{"atb":[[1.9,68.07]],"id":42154339}],"con":true,"img":false}]}
{"op":"mcm","clk":"5353009561","pt":1646206955577,"mc":[{"id":"1.195453766","rc":[{"spl":[[1.01,10.91]],"id":42154339}],"con":true,"img":false}]}
{"op":"mcm","clk":"5353009661","pt":1646206958099,"mc":[{"id":"1.195453766","rc":[{"atb":[[1.89,11.35]],"id":42154339}],"con":true,"img":false}]}
{"op":"mcm","clk":"5353010029","pt":1646206967013,"mc":[{"id":"1.195453766","rc":[{"atb":[[1.93,8.09]],"id":42154339}],"con":true,"img":false}]}
{"op":"mcm","clk":"5353010082","pt":1646206968307,"mc":[{"id":"1.195453766","rc":[{"atb":[[1.9,0]],"id":42154339}],"con":true,"img":false}]}
{"op":"mcm","clk":"5353010087","pt":1646206968406,"mc":[{"id":"1.195453766","rc":[{"atb":[[1.87,68.07]],"id":42154339}],"con":true,"img":false}]}
{"op":"mcm","clk":"5353010429","pt":1646206976230,"mc":[{"id":"1.195453766","rc":[{"atb":[[1.93,0]],"id":42154339}],"con":true,"img":false}]}
{"op":"mcm","clk":"5353010448","pt":1646206976802,"mc":[{"id":"1.195453766","rc":[{"atb":[[1.89,0]],"id":42154339}],"con":true,"img":false}]}
{"op":"mcm","clk":"5353010791","pt":1646206985123,"mc":[{"id":"1.195453766","rc":[{"atb":[[1.9,8.36]],"id":42154339}],"con":true,"img":false}]}
{"op":"mcm","clk":"5353011350","pt":1646206997634,"mc":[{"id":"1.195453766","rc":[{"atb":[[1.9,19.58]],"id":42154339}],"con":true,"img":false}]}
{"op":"mcm","clk":"5353011657","pt":1646207004564,"mc":[{"id":"1.195453766","rc":[{"atb":[[1.87,0]],"id":42154339}],"con":true,"img":false}]}
{"op":"mcm","clk":"5353011660","pt":1646207004666,"mc":[{"id":"1.195453766","rc":[{"atb":[[1.86,68.07]],"id":42154339}],"con":true,"img":false}]}
{"op":"mcm","clk":"5353011992","pt":1646207012271,"mc":[{"id":"1.195453766","rc":[{"atb":[[1.9,11.22]],"id":42154339},{"spn":1.93,"spf":1.0,"id":42154339}],"con":true,"img":false}]}
{"op":"mcm","clk":"5353012361","pt":1646207021180,"mc":[{"id":"1.195453766","rc":[{"atb":[[1.89,8.45]],"id":42154339}],"con":true,"img":false}]}
{"op":"mcm","clk":"5353012400","pt":1646207022007,"mc":[{"id":"1.195453766","rc":[{"atb":[[1.9,0]],"id":42154339}],"con":true,"img":false}]}
{"op":"mcm","clk":"5353012903","pt":1646207034296,"mc":[{"id":"1.195453766","rc":[{"atb":[[1.89,19.81]],"id":42154339}],"con":true,"img":false}]}
{"op":"mcm","clk":"5353013221","pt":1646207042329,"mc":[{"id":"1.195453766","rc":[{"atb":[[10.5,7.58]],"id":42162698},{"atb":[[2.36,52.94]],"id":39637621},{"atb":[[3.05,35.12]],"id":41818763},{"atb":[[7.6,10.91]],"id":41910350},{"atb":[[5,18]],"id":43167133},{"atb":[[4.4,21.18]],"id":42688787}],"con":true,"img":false}]}
{"op":"mcm","clk":"5353013227","pt":1646207042431,"mc":[{"id":"1.195453766","rc":[{"atb":[[6.6,14.64],[2.62,46.3],[4.2,26.56]],"id":42162698},{"atb":[[1.82,100]],"id":39637621},{"atl":[[11.5,8.2]],"id":39637621},{"atb":[[2.22,67.21]],"id":41818763},{"atl":[[18,8.2]],"id":41818763},{"atb":[[5,20.5],[2.62,46.3]],"id":41910350},{"atb":[[3.4,34.17],[2.62,46.3]],"id":43167133},{"atl":[[75,14.2],[60,8.2]],"id":43167133},{"atl":[[4.3,8.2],[5.1,14.2]],"id":42154339},{"atb":[[3,41],[2.62,46.3]],"id":42688787},{"atl":[[46,8.2],[60,14.2]],"id":42688787}],"con":true,"img":false}]}
{"op":"mcm","clk":"5353013238","pt":1646207042635,"mc":[{"id":"1.195453766","rc":[{"atl":[[34,13.5],[14.5,14.2]],"id":39637621},{"atl":[[23,14.2]],"id":41818763},{"atl":[[34,13.5],[17,8.5]],"id":42154339}],"con":true,"img":false}]}
{"op":"mcm","clk":"5353013271","pt":1646207043408,"mc":[{"id":"1.195453766","rc":[{"atb":[[4.2,26.56]],"id":41910350}],"con":true,"img":false}]}
{"op":"mcm","clk":"5353016221","pt":1646207109850,"mc":[{"id":"1.195453766","rc":[{"atb":[[1.28,292.86],[1.47,153.19]],"id":42154339},{"spn":1.92,"spf":1.0,"id":42154339}],"con":true,"img":false}]}
{"op":"mcm","clk":"5353016547","pt":1646207117056,"mc":[{"id":"1.195453766","rc":[{"atb":[[1.86,0]],"id":42154339}],"con":true,"img":false}]}
{"op":"mcm","clk":"5353016553","pt":1646207117169,"mc":[{"id":"1.195453766","rc":[{"atb":[[1.9,68.07]],"id":42154339}],"con":true,"img":false}]}
{"op":"mcm","clk":"5353016991","pt":1646207126464,"mc":[{"id":"1.195453766","rc":[{"atb":[[1.89,11.35]],"id":42154339}],"con":true,"img":false}]}
{"op":"mcm","clk":"5353017137","pt":1646207130173,"mc":[{"id":"1.195453766","rc":[{"atb":[[1.89,0]],"id":42154339}],"con":true,"img":false}]}
{"op":"mcm","clk":"5353017401","pt":1646207135265,"mc":[{"id":"1.195453766","rc":[{"atb":[[1.93,8.09]],"id":42154339}],"con":true,"img":false}]}
{"op":"mcm","clk":"5353017734","pt":1646207139182,"mc":[{"id":"1.195453766","rc":[{"atb":[[1.93,18.95]],"id":42154339}],"con":true,"img":false}]}
{"op":"mcm","clk":"5353027762","pt":1646207202701,"mc":[{"id":"1.195453766","marketDefinition":{"bspMarket":true,"turnInPlayEnabled":false,"persistenceEnabled":false,"marketBaseRate":7.0,"eventId":"31272499","eventTypeId":"4339","numberOfWinners":1,"bettingType":"ODDS","marketType":"WIN","marketTime":"2022-03-02T09:08:00.000Z","suspendTime":"2022-03-02T09:08:00.000Z","bspReconciled":false,"complete":true,"inPlay":false,"crossMatching":true,"runnersVoidable":false,"numberOfActiveRunners":7,"betDelay":0,"status":"OPEN","runners":[{"status":"ACTIVE","sortPriority":1,"id":43167133,"name":"1. Sunset Sienna"},{"status":"ACTIVE","sortPriority":2,"id":42154339,"name":"3. Foxy One"},{"status":"ACTIVE","sortPriority":3,"id":42688787,"name":"4. Double Espresso"},{"status":"ACTIVE","sortPriority":4,"id":41818763,"name":"5. Dr Kammi"},{"status":"ACTIVE","sortPriority":5,"id":39637621,"name":"6. Katara Love"},{"status":"ACTIVE","sortPriority":6,"id":42162698,"name":"7. Black Petunia"},{"status":"ACTIVE","sortPriority":7,"id":41910350,"name":"8. Big Time Money"}],"regulators":["MR_INT"],"venue":"Rockhampton","countryCode":"AU","discountAllowed":true,"timezone":"Australia/Queensland","openDate":"2022-03-02T08:28:00.000Z","version":4382601056,"name":"R3 510m Mdn/Nvce","eventName":"Rockhampton (AUS) 2nd Mar"},"rc":[{"atb":[[17.5,6.24],[18,3.44],[19.5,0.55],[20,5.42],[10.5,7.58],[12.5,8.95],[6.6,14.64],[2.62,46.3],[4.2,26.56],[15,7.35],[15.5,8.73]],"id":42162698},{"atl":[[70,2.72],[150,0.89],[300,0.67],[90,2.72],[200,0.67],[250,0.8]],"id":42162698},{"spn":45.0,"spf":"NaN","id":42162698},{"atb":[[2.36,52.94],[3.45,44.15],[1.82,100],[3.2,46.94],[3.7,38.24],[3,60.72],[3.25,23.41],[2.98,52.15],[3.75,6.41]],"id":39637621},{"atl":[[16,13.31],[34,13.5],[8.6,14.8],[6.4,10.84],[11,13.31],[11.5,8.2],[13.5,15.98],[14.5,14.2],[9.4,15.85]],"id":39637621},{"spn":5.07,"spf":"NaN","id":39637621},{"atb":[[4,34.34],[5.1,4.48],[4.5,29.43],[5,25.75],[4.6,16.26],[2.22,67.21],[4.1,42.57],[4.9,2],[3.75,37.46],[3.05,35.12]],"id":41818763},{"atl":[[16,8.89],[18,8.2],[18.5,7.62],[22,9.53],[23,14.2],[9.8,6.65],[13.5,9.27],[27,7.69]],"id":41818763},{"spn":7.45,"spf":"NaN","id":41818763},{"atb":[[16.5,0.66],[9.2,12.56],[5,20.5],[10.5,10.84],[8.2,14.31],[7.6,10.91],[13,8.58],[13.5,9.23],[2.62,46.3],[14.5,4.33],[4.2,26.56]],"id":41910350},{"atl":[[65,2.72],[80,1.68],[160,1.26],[48,2.72],[210,0.95],[110,1.22],[30,0.18]],"id":41910350},{"spn":23.25,"spf":"NaN","id":41910350},{"atb":[[9,7.31],[8.6,13.55],[5.8,21.46],[5,18],[10.5,1.06],[7.6,15.61],[3.4,34.17],[8.8,16.37],[6.6,18.4],[2.62,46.3]],"id":43167133},{"atl":[[65,3.12],[34,3.82],[36,3.81],[75,14.2],[90,2.24],[46,2.96],[24,2.72],[60,8.2]],"id":43167133},{"spn":17.25,"spf":"NaN","id":43167133},{"atb":[[1.56,227.07],[1.28,292.86],[1.8,128.78],[2.04,2.72],[1.85,120.24],[1.19,2],[1.9,68.07],[1.7,147.18],[1.93,18.95],[1.75,137.37],[1.47,153.19]],"id":42154339},{"spl":[[1.01,10.91]],"id":42154339},{"atl":[[3.6,51.31],[34,13.5],[4.3,8.2],[3.85,46.8],[3.1,8.18],[2.6,8.54],[3.25,26.02],[3.55,49.67],[2.4,6.21],[17,8.5],[5.1,14.2],[4.2,62.53],[4.7,54.08]],"id":42154339},{"trd":[[1.85,1.93]],"ltp":1.85,"tv":1.93,"id":42154339},{"spn":1.95,"spf":1.0,"id":42154339},{"atb":[[7.2,1.62],[5.8,21.51],[5.3,24.01],[7.6,15.64],[6.8,20.89],[3,41],[4.4,21.18],[7.8,8.6],[6.6,18.43],[2.62,46.3]],"id":42688787},{"atl":[[18.5,3.34],[38,5.39],[23,5.5],[46,8.2],[24,5.79],[48,4.25],[29,4.75],[60,14.2]],"id":42688787},{"spn":13.15,"spf":"NaN","id":42688787}],"con":true,"img":true}]}
{"op":"mcm","clk":"5353032781","pt":1646207253771,"mc":[{"id":"1.195453766","rc":[{"atb":[[1.9,0]],"id":42154339},{"spn":1.95,"spf":1.0,"id":42154339}],"con":true,"img":false}]}
{"op":"mcm","clk":"5353032786","pt":1646207253874,"mc":[{"id":"1.195453766","rc":[{"atb":[[1.94,68.07]],"id":42154339}],"con":true,"img":false}]}
{"op":"mcm","clk":"5353033158","pt":1646207261690,"mc":[{"id":"1.195453766","rc":[{"atb":[[1.93,10.86]],"id":42154339}],"con":true,"img":false}]}
{"op":"mcm","clk":"5353033548","pt":1646207270626,"mc":[{"id":"1.195453766","rc":[{"atb":[[1.97,7.75]],"id":42154339},{"spn":1.98,"spf":1.0,"id":42154339}],"con":true,"img":false}]}
{"op":"mcm","clk":"5353034109","pt":1646207283712,"mc":[{"id":"1.195453766","rc":[{"atb":[[1.93,0]],"id":42154339}],"con":true,"img":false}]}
{"op":"mcm","clk":"5353034648","pt":1646207295534,"mc":[{"id":"1.195453766","rc":[{"atb":[[1.97,18.18]],"id":42154339}],"con":true,"img":false}]}
{"op":"mcm","clk":"5353035154","pt":1646207308181,"mc":[{"id":"1.195453766","rc":[{"atb":[[1.94,0]],"id":42154339}],"con":true,"img":false}]}
{"op":"mcm","clk":"5353035159","pt":1646207308283,"mc":[{"id":"1.195453766","rc":[{"atb":[[1.86,68.07]],"id":42154339}],"con":true,"img":false}]}
{"op":"mcm","clk":"5353035497","pt":1646207315764,"mc":[{"id":"1.195453766","rc":[{"atb":[[1.97,10.42]],"id":42154339}],"con":true,"img":false}]}
{"op":"mcm","clk":"5353035894","pt":1646207324714,"mc":[{"id":"1.195453766","rc":[{"atb":[[1.89,8.45]],"id":42154339}],"con":true,"img":false}]}
{"op":"mcm","clk":"5353036061","pt":1646207328678,"mc":[{"id":"1.195453766","rc":[{"atb":[[1.97,0]],"id":42154339}],"con":true,"img":false}]}
{"op":"mcm","clk":"5353036470","pt":1646207336916,"mc":[{"id":"1.195453766","rc":[{"atl":[[17,8.5]],"id":39637621},{"atl":[[34,13.5]],"id":41818763},{"spn":1.92,"spf":1.0,"id":42154339}],"con":true,"img":false}]}
{"op":"mcm","clk":"5353036816","pt":1646207343521,"mc":[{"id":"1.195453766","rc":[{"atb":[[1.89,19.81]],"id":42154339}],"con":true,"img":false}]}
{"op":"mcm","clk":"5353040335","pt":1646207419228,"mc":[{"id":"1.195453766","rc":[{"atl":[[70,0]],"id":42162698},{"spn":55.0,"spf":"NaN","id":42162698},{"atl":[[48,0]],"id":41910350},{"atb":[[1.86,0]],"id":42154339}],"con":true,"img":false}]}
{"op":"mcm","clk":"5353040341","pt":1646207419331,"mc":[{"id":"1.195453766","rc":[{"atl":[[65,2.72]],"id":42162698},{"atl":[[46,2.72]],"id":41910350},{"atb":[[1.9,68.07]],"id":42154339}],"con":true,"img":false}]}
{"op":"mcm","clk":"5353040684","pt":1646207427067,"mc":[{"id":"1.195453766","rc":[{"atb":[[1.89,11.35]],"id":42154339}],"con":true,"img":false}]}
{"op":"mcm","clk":"5353041028","pt":1646207435973,"mc":[{"id":"1.195453766","rc":[{"atb":[[1.93,8.09]],"id":42154339}],"con":true,"img":false}]}
{"op":"mcm","clk":"5353041055","pt":1646207436744,"mc":[{"id":"1.195453766","rc":[{"atb":[[1.89,0]],"id":42154339}],"con":true,"img":false}]}
{"op":"mcm","clk":"5353041373","pt":1646207445995,"mc":[{"id":"1.195453766","rc":[{"atb":[[1.9,0]],"id":42154339}],"con":true,"img":false}]}
{"op":"mcm","clk":"5353041375","pt":1646207446098,"mc":[{"id":"1.195453766","rc":[{"atb":[[1.86,68.07]],"id":42154339}],"con":true,"img":false}]}
{"op":"mcm","clk":"5353041637","pt":1646207454008,"mc":[{"id":"1.195453766","rc":[{"atb":[[1.93,0]],"id":42154339}],"con":true,"img":false}]}
{"op":"mcm","clk":"5353041976","pt":1646207463005,"mc":[{"id":"1.195453766","rc":[{"atb":[[1.89,8.45]],"id":42154339}],"con":true,"img":false}]}
{"op":"mcm","clk":"5353042094","pt":1646207466606,"mc":[{"id":"1.195453766","rc":[{"atb":[[1.89,19.81]],"id":42154339}],"con":true,"img":false}]}
{"op":"mcm","clk":"5353043944","pt":1646207523271,"mc":[{"id":"1.195453766","rc":[{"spn":42.5,"spf":"NaN","id":42162698},{"atb":[[1.86,0]],"id":42154339}],"con":true,"img":false}]}
{"op":"mcm","clk":"5353043950","pt":1646207523374,"mc":[{"id":"1.195453766","rc":[{"atb":[[1.9,68.07]],"id":42154339}],"con":true,"img":false}]}
{"op":"mcm","clk":"5353044284","pt":1646207532265,"mc":[{"id":"1.195453766","rc":[{"atb":[[1.89,11.35]],"id":42154339}],"con":true,"img":false}]}
{"op":"mcm","clk":"5353044636","pt":1646207541195,"mc":[{"id":"1.195453766","rc":[{"atb":[[1.93,8.09]],"id":42154339}],"con":true,"img":false}]}
{"op":"mcm","clk":"5353044759","pt":1646207545002,"mc":[{"id":"1.195453766","rc":[{"atb":[[1.89,0]],"id":42154339}],"con":true,"img":false}]}
{"op":"mcm","clk":"5353044853","pt":1646207548391,"mc":[{"id":"1.195453766","rc":[{"atb":[[1.9,0]],"id":42154339}],"con":true,"img":false}]}
{"op":"mcm","clk":"5353044855","pt":1646207548493,"mc":[{"id":"1.195453766","rc":[{"atb":[[1.86,68.07]],"id":42154339}],"con":true,"img":false}]}
{"op":"mcm","clk":"5353045192","pt":1646207556220,"mc":[{"id":"1.195453766","rc":[{"atb":[[1.93,0]],"id":42154339}],"con":true,"img":false}]}
{"op":"mcm","clk":"5353045608","pt":1646207568247,"mc":[{"id":"1.195453766","rc":[{"atb":[[1.89,8.45]],"id":42154339}],"con":true,"img":false}]}
{"op":"mcm","clk":"5353045737","pt":1646207571920,"mc":[{"id":"1.195453766","rc":[{"atb":[[1.89,19.81]],"id":42154339}],"con":true,"img":false}]}
{"op":"mcm","clk":"5353047536","pt":1646207623788,"mc":[{"id":"1.195453766","rc":[{"atb":[[1.86,0]],"id":42154339}],"con":true,"img":false}]}
{"op":"mcm","clk":"5353047539","pt":1646207623890,"mc":[{"id":"1.195453766","rc":[{"atb":[[1.9,68.07]],"id":42154339}],"con":true,"img":false}]}
{"op":"mcm","clk":"5353047789","pt":1646207631391,"mc":[{"id":"1.195453766","rc":[{"atb":[[1.89,11.35]],"id":42154339}],"con":true,"img":false}]}
{"op":"mcm","clk":"5353048052","pt":1646207640134,"mc":[{"id":"1.195453766","rc":[{"atl":[[190,14.2]],"id":41910350}],"con":true,"img":false}]}
{"op":"mcm","clk":"5353048055","pt":1646207640395,"mc":[{"id":"1.195453766","rc":[{"atb":[[1.93,8.09]],"id":42154339}],"con":true,"img":false}]}
{"op":"mcm","clk":"5353048071","pt":1646207641016,"mc":[{"id":"1.195453766","rc":[{"atb":[[1.89,0]],"id":42154339}],"con":true,"img":false}]}
{"op":"mcm","clk":"5353048280","pt":1646207648522,"mc":[{"id":"1.195453766","rc":[{"atb":[[1.9,0]],"id":42154339}],"con":true,"img":false}]}
{"op":"mcm","clk":"5353048284","pt":1646207648625,"mc":[{"id":"1.195453766","rc":[{"atb":[[1.86,68.07]],"id":42154339}],"con":true,"img":false}]}
{"op":"mcm","clk":"5353048529","pt":1646207655514,"mc":[{"id":"1.195453766","rc":[{"atb":[[1.93,0]],"id":42154339}],"con":true,"img":false}]}
{"op":"mcm","clk":"5353048830","pt":1646207664441,"mc":[{"id":"1.195453766","rc":[{"atb":[[1.89,8.45]],"id":42154339}],"con":true,"img":false}]}
{"op":"mcm","clk":"5353048847","pt":1646207665260,"mc":[{"id":"1.195453766","rc":[{"atb":[[1.89,19.81]],"id":42154339}],"con":true,"img":false}]}
{"op":"mcm","clk":"5353050534","pt":1646207713800,"mc":[{"id":"1.195453766","rc":[{"atb":[[4.9,0]],"id":41818763}],"con":true,"img":false}]}
{"op":"mcm","clk":"5353050539","pt":1646207713902,"mc":[{"id":"1.195453766","rc":[{"atb":[[5,27.75]],"id":41818763}],"con":true,"img":false}]}
{"op":"mcm","clk":"5353050831","pt":1646207721513,"mc":[{"id":"1.195453766","rc":[{"atb":[[1.86,0]],"id":42154339}],"con":true,"img":false}]}
{"op":"mcm","clk":"5353050834","pt":1646207721616,"mc":[{"id":"1.195453766","rc":[{"atb":[[1.9,68.07]],"id":42154339}],"con":true,"img":false}]}
{"op":"mcm","clk":"5353051193","pt":1646207730706,"mc":[{"id":"1.195453766","rc":[{"atb":[[1.89,11.35]],"id":42154339}],"con":true,"img":false}]}
{"op":"mcm","clk":"5353051347","pt":1646207734353,"mc":[{"id":"1.195453766","rc":[{"atb":[[1.89,0]],"id":42154339}],"con":true,"img":false}]}
{"op":"mcm","clk":"5353051533","pt":1646207739634,"mc":[{"id":"1.195453766","rc":[{"atb":[[1.93,8.09]],"id":42154339}],"con":true,"img":false}]}
{"op":"mcm","clk":"5353051751","pt":1646207745431,"mc":[{"id":"1.195453766","rc":[{"atb":[[1.9,0]],"id":42154339}],"con":true,"img":false}]}
{"op":"mcm","clk":"5353051757","pt":1646207745535,"mc":[{"id":"1.195453766","rc":[{"atb":[[1.86,68.07]],"id":42154339}],"con":true,"img":false}]}
{"op":"mcm","clk":"5353052077","pt":1646207754657,"mc":[{"id":"1.195453766","rc":[{"atb":[[1.93,0]],"id":42154339}],"con":true,"img":false}]}
{"op":"mcm","clk":"5353052199","pt":1646207758243,"mc":[{"id":"1.195453766","rc":[{"atb":[[1.89,11.35]],"id":42154339}],"con":true,"img":false}]}
{"op":"mcm","clk":"5353052411","pt":1646207763899,"mc":[{"id":"1.195453766","rc":[{"atb":[[1.89,19.81]],"id":42154339}],"con":true,"img":false}]}
{"op":"mcm","clk":"5353054423","pt":1646207816557,"mc":[{"id":"1.195453766","rc":[{"atb":[[1.86,0]],"id":42154339}],"con":true,"img":false}]}
{"op":"mcm","clk":"5353054428","pt":1646207816610,"mc":[{"id":"1.195453766","rc":[{"atb":[[1.9,68.07]],"id":42154339}],"con":true,"img":false}]}
{"op":"mcm","clk":"5353054663","pt":1646207823963,"mc":[{"id":"1.195453766","rc":[{"atb":[[1.89,11.35]],"id":42154339}],"con":true,"img":false}]}
{"op":"mcm","clk":"5353054916","pt":1646207830445,"mc":[{"id":"1.195453766","rc":[{"atb":[[1.89,0]],"id":42154339}],"con":true,"img":false}]}
{"op":"mcm","clk":"5353055025","pt":1646207832867,"mc":[{"id":"1.195453766","rc":[{"atb":[[1.93,8.09]],"id":42154339}],"con":true,"img":false}]}
{"op":"mcm","clk":"5353055303","pt":1646207839551,"mc":[{"id":"1.195453766","rc":[{"atb":[[1.9,0]],"id":42154339}],"con":true,"img":false}]}
{"op":"mcm","clk":"5353055307","pt":1646207839655,"mc":[{"id":"1.195453766","rc":[{"atb":[[1.86,68.07]],"id":42154339}],"con":true,"img":false}]}
{"op":"mcm","clk":"5353055572","pt":1646207847887,"mc":[{"id":"1.195453766","rc":[{"atb":[[1.93,0]],"id":42154339}],"con":true,"img":false}]}
{"op":"mcm","clk":"5353055821","pt":1646207854464,"mc":[{"id":"1.195453766","rc":[{"atb":[[1.89,11.35]],"id":42154339}],"con":true,"img":false}]}
{"op":"mcm","clk":"5353055907","pt":1646207856876,"mc":[{"id":"1.195453766","rc":[{"atb":[[1.89,19.81]],"id":42154339}],"con":true,"img":false}]}
{"op":"mcm","clk":"5353058092","pt":1646207909037,"mc":[{"id":"1.195453766","rc":[{"atb":[[1.86,0]],"id":42154339}],"con":true,"img":false}]}
{"op":"mcm","clk":"5353058097","pt":1646207909141,"mc":[{"id":"1.195453766","rc":[{"atb":[[1.9,68.07]],"id":42154339}],"con":true,"img":false}]}
{"op":"mcm","clk":"5353058472","pt":1646207918178,"mc":[{"id":"1.195453766","rc":[{"atb":[[1.89,11.35]],"id":42154339}],"con":true,"img":false}]}
{"op":"mcm","clk":"5353058814","pt":1646207925991,"mc":[{"id":"1.195453766","rc":[{"atb":[[1.93,8.09]],"id":42154339}],"con":true,"img":false}]}
{"op":"mcm","clk":"5353059109","pt":1646207932792,"mc":[{"id":"1.195453766","rc":[{"atb":[[1.89,0]],"id":42154339}],"con":true,"img":false}]}
{"op":"mcm","clk":"5353059555","pt":1646207944710,"mc":[{"id":"1.195453766","rc":[{"atb":[[1.93,18.95]],"id":42154339}],"con":true,"img":false}]}
{"op":"mcm","clk":"5353062203","pt":1646208005485,"mc":[{"id":"1.195453766","rc":[{"atb":[[1.9,0]],"id":42154339},{"spn":1.95,"spf":1.0,"id":42154339}],"con":true,"img":false}]}
{"op":"mcm","clk":"5353062208","pt":1646208005586,"mc":[{"id":"1.195453766","rc":[{"atb":[[1.94,68.07]],"id":42154339}],"con":true,"img":false}]}
{"op":"mcm","clk":"5353062574","pt":1646208013296,"mc":[{"id":"1.195453766","rc":[{"atb":[[1.93,10.86]],"id":42154339}],"con":true,"img":false}]}
{"op":"mcm","clk":"5353063143","pt":1646208022197,"mc":[{"id":"1.195453766","rc":[{"atb":[[1.97,7.75]],"id":42154339}],"con":true,"img":false}]}
{"op":"mcm","clk":"5353063475","pt":1646208029439,"mc":[{"id":"1.195453766","rc":[{"atb":[[1.93,0]],"id":42154339}],"con":true,"img":false}]}
{"op":"mcm","clk":"5353063992","pt":1646208041437,"mc":[{"id":"1.195453766","rc":[{"atb":[[1.97,18.18]],"id":42154339}],"con":true,"img":false}]}
{"op":"mcm","clk":"5353064322","pt":1646208049851,"mc":[{"id":"1.195453766","rc":[{"atb":[[1.94,0]],"id":42154339}],"con":true,"img":false}]}
{"op":"mcm","clk":"5353064326","pt":1646208049956,"mc":[{"id":"1.195453766","rc":[{"atb":[[1.86,68.07]],"id":42154339}],"con":true,"img":false}]}
{"op":"mcm","clk":"5353064686","pt":1646208058363,"mc":[{"id":"1.195453766","rc":[{"atb":[[1.97,10.42]],"id":42154339}],"con":true,"img":false}]}
{"op":"mcm","clk":"5353064951","pt":1646208065488,"mc":[{"id":"1.195453766","rc":[{"atb":[[1.97,0]],"id":42154339},{"spn":1.9,"spf":1.0,"id":42154339}],"con":true,"img":false}]}
{"op":"mcm","clk":"5353065039","pt":1646208067289,"mc":[{"id":"1.195453766","rc":[{"atb":[[1.89,8.45]],"id":42154339}],"con":true,"img":false}]}
{"op":"mcm","clk":"5353065395","pt":1646208074491,"mc":[{"id":"1.195453766","rc":[{"atb":[[1.89,19.81]],"id":42154339}],"con":true,"img":false}]}
{"op":"mcm","clk":"5353068470","pt":1646208146501,"mc":[{"id":"1.195453766","rc":[{"atb":[[1.86,0]],"id":42154339},{"spn":1.92,"spf":1.0,"id":42154339}],"con":true,"img":false}]}
{"op":"mcm","clk":"5353068477","pt":1646208146608,"mc":[{"id":"1.195453766","rc":[{"atb":[[1.9,68.07]],"id":42154339}],"con":true,"img":false}]}
{"op":"mcm","clk":"5353068788","pt":1646208154480,"mc":[{"id":"1.195453766","rc":[{"atb":[[1.89,11.35]],"id":42154339}],"con":true,"img":false}]}
{"op":"mcm","clk":"5353069288","pt":1646208164617,"mc":[{"id":"1.195453766","rc":[{"atb":[[1.93,8.09]],"id":42154339}],"con":true,"img":false}]}
{"op":"mcm","clk":"5353073762","pt":1646208261051,"mc":[{"id":"1.195453766","rc":[{"atb":[[1.89,0]],"id":42154339},{"spn":1.95,"spf":1.0,"id":42154339}],"con":true,"img":false}]}
{"op":"mcm","clk":"5353074468","pt":1646208274337,"mc":[{"id":"1.195453766","rc":[{"atb":[[1.9,0]],"id":42154339}],"con":true,"img":false}]}
{"op":"mcm","clk":"5353074476","pt":1646208274441,"mc":[{"id":"1.195453766","rc":[{"atb":[[1.86,68.07]],"id":42154339}],"con":true,"img":false}]}
{"op":"mcm","clk":"5353074772","pt":1646208280863,"mc":[{"id":"1.195453766","rc":[{"atb":[[1.93,0]],"id":42154339}],"con":true,"img":false}]}
{"op":"mcm","clk":"5353075208","pt":1646208289757,"mc":[{"id":"1.195453766","rc":[{"atb":[[1.89,8.45]],"id":42154339}],"con":true,"img":false}]}
{"op":"mcm","clk":"5353075291","pt":1646208291373,"mc":[{"id":"1.195453766","rc":[{"atb":[[1.89,19.81]],"id":42154339}],"con":true,"img":false}]}
{"op":"mcm","clk":"5353077764","pt":1646208342317,"mc":[{"id":"1.195453766","rc":[{"atb":[[1.86,0]],"id":42154339},{"spn":1.92,"spf":1.0,"id":42154339}],"con":true,"img":false}]}
{"op":"mcm","clk":"5353077769","pt":1646208342417,"mc":[{"id":"1.195453766","rc":[{"atb":[[1.9,68.07]],"id":42154339}],"con":true,"img":false}]}
{"op":"mcm","clk":"5353078133","pt":1646208349939,"mc":[{"id":"1.195453766","rc":[{"atb":[[1.89,11.35]],"id":42154339}],"con":true,"img":false}]}
{"op":"mcm","clk":"5353078466","pt":1646208356625,"mc":[{"id":"1.195453766","rc":[{"atl":[[280,14.2]],"id":42162698}],"con":true,"img":false}]}
{"op":"mcm","clk":"5353078584","pt":1646208358954,"mc":[{"id":"1.195453766","rc":[{"atb":[[1.93,8.09]],"id":42154339}],"con":true,"img":false}]}
{"op":"mcm","clk":"5353079290","pt":1646208373100,"mc":[{"id":"1.195453766","rc":[{"atb":[[5.1,0]],"id":41818763},{"trd":[[5.1,8.96]],"ltp":5.1,"tv":8.96,"id":41818763},{"atl":[[2.4,0]],"id":42154339},{"trd":[[2.4,12.42]],"ltp":2.4,"tv":12.42,"id":42154339}],"con":true,"img":false}]}
{"op":"mcm","clk":"5353079336","pt":1646208373980,"mc":[{"id":"1.195453766","rc":[{"atl":[[1000,2.25]],"id":41818763}],"con":true,"img":false}]}
{"op":"mcm","clk":"5353079349","pt":1646208374185,"mc":[{"id":"1.195453766","rc":[{"atl":[[1000,1.65]],"id":41818763}],"con":true,"img":false}]}
{"op":"mcm","clk":"5353079360","pt":1646208374392,"mc":[{"id":"1.195453766","rc":[{"atl":[[1000,0]],"id":41818763}],"con":true,"img":false}]}
{"op":"mcm","clk":"5353079365","pt":1646208374495,"mc":[{"id":"1.195453766","rc":[{"atl":[[6.2,1.65]],"id":41818763}],"con":true,"img":false}]}
{"op":"mcm","clk":"5353079663","pt":1646208380668,"mc":[{"id":"1.195453766","rc":[{"atl":[[2.6,0]],"id":42154339},{"trd":[[2.6,17.08]],"ltp":2.6,"tv":17.08,"id":42154339}],"con":true,"img":false}]}
{"op":"mcm","clk":"5353079773","pt":1646208382895,"mc":[{"id":"1.195453766","rc":[{"atl":[[3.2,4.7]],"id":42154339}],"con":true,"img":false}]}
{"op":"mcm","clk":"5353080419","pt":1646208396828,"mc":[{"id":"1.195453766","rc":[{"atb":[[1.9,0]],"id":42154339}],"con":true,"img":false}]}
{"op":"mcm","clk":"5353080425","pt":1646208396930,"mc":[{"id":"1.195453766","rc":[{"atb":[[1.93,76.16]],"id":42154339}],"con":true,"img":false}]}
{"op":"mcm","clk":"5353080767","pt":1646208404101,"mc":[{"id":"1.195453766","rc":[{"spn":5.6,"spf":"NaN","id":41818763},{"atb":[[1.93,68.07]],"id":42154339},{"spn":1.95,"spf":1.0,"id":42154339}],"con":true,"img":false}]}
{"op":"mcm","clk":"5353081190","pt":1646208413044,"mc":[{"id":"1.195453766","rc":[{"atb":[[1.96,7.84]],"id":42154339}],"con":true,"img":false}]}
{"op":"mcm","clk":"5353082305","pt":1646208435557,"mc":[{"id":"1.195453766","rc":[{"atb":[[1.56,0],[1.86,147.92]],"id":42154339}],"con":true,"img":false}]}
{"op":"mcm","clk":"5353084573","pt":1646208488224,"mc":[{"id":"1.195453766","rc":[{"atl":[[6.2,0]],"id":41818763},{"spn":7.4,"spf":"NaN","id":41818763},{"spn":1.97,"spf":1.0,"id":42154339}],"con":true,"img":false}]}
{"op":"mcm","clk":"5353084577","pt":1646208488328,"mc":[{"id":"1.195453766","rc":[{"atb":[[7,16.67]],"id":42162698},{"atl":[[200,2.67]],"id":42162698},{"atb":[[3,110.72]],"id":39637621},{"atl":[[15,7.14]],"id":39637621},{"atb":[[3,50]],"id":41818763},{"atl":[[15,7.14],[1000,2.25]],"id":41818763},{"atb":[[5.7,21.28]],"id":41910350},{"atl":[[140,2]],"id":41910350},{"atb":[[3.8,35.71]],"id":43167133},{"atl":[[46,5.18]],"id":43167133},{"atb":[[1.35,249.04]],"id":42154339},{"atl":[[3.7,37.04]],"id":42154339},{"atb":[[3.65,37.74]],"id":42688787},{"atl":[[28,3.7]],"id":42688787}],"con":true,"img":false}]}
{"op":"mcm","clk":"5353084585","pt":1646208488536,"mc":[{"id":"1.195453766","rc":[{"atl":[[1000,0.85]],"id":41818763}],"con":true,"img":false}]}
{"op":"mcm","clk":"5353084595","pt":1646208488743,"mc":[{"id":"1.195453766","rc":[{"atl":[[1000,0]],"id":41818763}],"con":true,"img":false}]}
{"op":"mcm","clk":"5353084599","pt":1646208488844,"mc":[{"id":"1.195453766","rc":[{"atl":[[12,0.85]],"id":41818763}],"con":true,"img":false}]}
{"op":"mcm","clk":"5353084698","pt":1646208491159,"mc":[{"id":"1.195453766","rc":[{"atl":[[12,0]],"id":41818763}],"con":true,"img":false}]}
{"op":"mcm","clk":"5353084701","pt":1646208491219,"mc":[{"id":"1.195453766","rc":[{"atl":[[1000,2.25]],"id":41818763}],"con":true,"img":false}]}
{"op":"mcm","clk":"5353084709","pt":1646208491419,"mc":[{"id":"1.195453766","rc":[{"atl":[[1000,1.06]],"id":41818763}],"con":true,"img":false}]}
{"op":"mcm","clk":"5353084717","pt":1646208491626,"mc":[{"id":"1.195453766","rc":[{"atl":[[1000,0]],"id":41818763}],"con":true,"img":false}]}
{"op":"mcm","clk":"5353084722","pt":1646208491730,"mc":[{"id":"1.195453766","rc":[{"atl":[[9.6,1.06]],"id":41818763}],"con":true,"img":false}]}
{"op":"mcm","clk":"5353085058","pt":1646208500162,"mc":[{"id":"1.195453766","rc":[{"atl":[[3.2,0]],"id":42154339}],"con":true,"img":false}]}
{"op":"mcm","clk":"5353085159","pt":1646208503146,"mc":[{"id":"1.195453766","rc":[{"atl":[[3.2,4.7]],"id":42154339}],"con":true,"img":false}]}
{"op":"mcm","clk":"5353085178","pt":1646208503559,"mc":[{"id":"1.195453766","rc":[{"atl":[[3.05,1.42]],"id":42154339},{"atl":[[18,1.29]],"id":42688787}],"con":true,"img":false}]}
{"op":"mcm","clk":"5353085200","pt":1646208504175,"mc":[{"id":"1.195453766","rc":[{"atb":[[21,1.49]],"id":42162698},{"atb":[[3.8,1.68]],"id":39637621},{"atb":[[5.1,1.62]],"id":41818763},{"atb":[[15,1.66]],"id":41910350},{"atb":[[9.2,1.5]],"id":43167133},{"atb":[[8,1.65]],"id":42688787}],"con":true,"img":false}]}
{"op":"mcm","clk":"5353086123","pt":1646208525698,"mc":[{"id":"1.195453766","rc":[{"atb":[[5.1,0]],"id":41818763},{"trd":[[5.1,12.2]],"ltp":5.1,"tv":12.2,"id":41818763}],"con":true,"img":false}]}
{"op":"mcm","clk":"5353086151","pt":1646208526270,"mc":[{"id":"1.195453766","rc":[{"atl":[[9.6,2.58]],"id":41818763}],"con":true,"img":false}]}
{"op":"mcm","clk":"5353086180","pt":1646208526989,"mc":[{"id":"1.195453766","rc":[{"atl":[[9.4,1.36]],"id":41818763}],"con":true,"img":false}]}
{"op":"mcm","clk":"5353086215","pt":1646208527887,"mc":[{"id":"1.195453766","rc":[{"atl":[[9.6,1.06]],"id":41818763}],"con":true,"img":false}]}
{"op":"mcm","clk":"5353086216","pt":1646208527972,"mc":[{"id":"1.195453766","rc":[{"atl":[[9.2,1.51]],"id":41818763}],"con":true,"img":false}]}
{"op":"mcm","clk":"5353086226","pt":1646208528281,"mc":[{"id":"1.195453766","rc":[{"atl":[[9.4,0]],"id":41818763}],"con":true,"img":false}]}
{"op":"mcm","clk":"5353086230","pt":1646208528383,"mc":[{"id":"1.195453766","rc":[{"atl":[[1000,1.36]],"id":41818763}],"con":true,"img":false}]}
{"op":"mcm","clk":"5353086240","pt":1646208528690,"mc":[{"id":"1.195453766","rc":[{"atl":[[9.2,0]],"id":41818763}],"con":true,"img":false}]}
{"op":"mcm","clk":"5353086244","pt":1646208528793,"mc":[{"id":"1.195453766","rc":[{"atl":[[9.4,1.51]],"id":41818763}],"con":true,"img":false}]}
{"op":"mcm","clk":"5353086807","pt":1646208542802,"mc":[{"id":"1.195453766","rc":[{"atb":[[14.5,0]],"id":41910350},{"atl":[[3.25,0]],"id":42154339}],"con":true,"img":false}]}
{"op":"mcm","clk":"5353086810","pt":1646208542906,"mc":[{"id":"1.195453766","rc":[{"atb":[[14,4.33]],"id":41910350},{"atl":[[3.15,26.02]],"id":42154339}],"con":true,"img":false}]}
{"op":"mcm","clk":"5353086840","pt":1646208543784,"mc":[{"id":"1.195453766","rc":[{"atb":[[15,0]],"id":41910350}],"con":true,"img":false}]}
{"op":"mcm","clk":"5353086846","pt":1646208543889,"mc":[{"id":"1.195453766","rc":[{"atb":[[14.5,1.66]],"id":41910350}],"con":true,"img":false}]}
{"op":"mcm","clk":"5353087052","pt":1646208549208,"mc":[{"id":"1.195453766","rc":[{"spn":43.0,"spf":"NaN","id":42162698},{"spn":5.1,"spf":"NaN","id":39637621},{"atl":[[6.2,2.02]],"id":41818763},{"spn":5.6,"spf":"NaN","id":41818763},{"spn":13.0,"spf":"NaN","id":42688787}],"con":true,"img":false}]}
{"op":"mcm","clk":"5353087067","pt":1646208549517,"mc":[{"id":"1.195453766","rc":[{"atl":[[3.45,5.86]],"id":42154339}],"con":true,"img":false}]}
{"op":"mcm","clk":"5353087701","pt":1646208564216,"mc":[{"id":"1.195453766","rc":[{"atb":[[1.89,0]],"id":42154339}],"con":true,"img":false}]}
{"op":"mcm","clk":"5353088048","pt":1646208571533,"mc":[{"id":"1.195453766","rc":[{"atb":[[10.5,0]],"id":43167133}],"con":true,"img":false}]}
{"op":"mcm","clk":"5353088053","pt":1646208571636,"mc":[{"id":"1.195453766","rc":[{"atb":[[10,1.12]],"id":43167133}],"con":true,"img":false}]}
{"op":"mcm","clk":"5353088287","pt":1646208576634,"mc":[{"id":"1.195453766","rc":[{"atb":[[1.96,18.37]],"id":42154339}],"con":true,"img":false}]}
{"op":"mcm","clk":"5353088397","pt":1646208578743,"mc":[{"id":"1.195453766","rc":[{"atb":[[3.25,0]],"id":39637621},{"atl":[[46,0]],"id":41910350}],"con":true,"img":false}]}
{"op":"mcm","clk":"5353088403","pt":1646208578845,"mc":[{"id":"1.195453766","rc":[{"atb":[[3.5,23.41]],"id":39637621},{"atl":[[44,2.72]],"id":41910350}],"con":true,"img":false}]}
{"op":"mcm","clk":"5353088844","pt":1646208588645,"mc":[{"id":"1.195453766","rc":[{"atl":[[2.8,8.54]],"id":42154339}],"con":true,"img":false}]}
{"op":"mcm","clk":"5353088862","pt":1646208589055,"mc":[{"id":"1.195453766","rc":[{"atl":[[3.05,0]],"id":42154339}],"con":true,"img":false}]}
{"op":"mcm","clk":"5353088867","pt":1646208589159,"mc":[{"id":"1.195453766","rc":[{"atl":[[2.78,1.42]],"id":42154339}],"con":true,"img":false}]}
{"op":"mcm","clk":"5353089360","pt":1646208599662,"mc":[{"id":"1.195453766","rc":[{"atl":[[2.7,8.54]],"id":42154339}],"con":true,"img":false}]}
{"op":"mcm","clk":"5353089377","pt":1646208600074,"mc":[{"id":"1.195453766","rc":[{"atl":[[2.78,0],[2.7,4.96]],"id":42154339},{"trd":[[2.7,7.15]],"ltp":2.7,"tv":7.15,"id":42154339}],"con":true,"img":false}]}
{"op":"mcm","clk":"5353089382","pt":1646208600177,"mc":[{"id":"1.195453766","rc":[{"atl":[[2.68,1.42]],"id":42154339}],"con":true,"img":false}]}
{"op":"mcm","clk":"5353089818","pt":1646208609765,"mc":[{"id":"1.195453766","rc":[{"spn":17.0,"spf":"NaN","id":43167133},{"atl":[[2.68,0],[2.7,4.25]],"id":42154339},{"trd":[[2.7,8.58],[2.68,2.85]],"ltp":2.7,"tv":11.43,"id":42154339},{"spn":1.98,"spf":1.0,"id":42154339}],"con":true,"img":false}]}
{"op":"mcm","clk":"5353089837","pt":1646208610180,"mc":[{"id":"1.195453766","rc":[{"atb":[[1.96,20.38]],"id":42154339}],"con":true,"img":false}]}
{"op":"mcm","clk":"5353090336","pt":1646208620501,"mc":[{"id":"1.195453766","rc":[{"atl":[[3.2,0]],"id":42154339}],"con":true,"img":false}]}
{"op":"mcm","clk":"5353090660","pt":1646208627280,"mc":[{"id":"1.195453766","rc":[{"atl":[[1000,2.25]],"id":42162698},{"atb":[[1.02,2.25]],"id":42688787}],"con":true,"img":false}]}
{"op":"mcm","clk":"5353090669","pt":1646208627481,"mc":[{"id":"1.195453766","rc":[{"atl":[[1000,0.06]],"id":42162698},{"atb":[[1.02,0.45]],"id":42688787}],"con":true,"img":false}]}
{"op":"mcm","clk":"5353090681","pt":1646208627687,"mc":[{"id":"1.195453766","rc":[{"atl":[[2.6,8.54]],"id":42154339}],"con":true,"img":false}]}
{"op":"mcm","clk":"5353090694","pt":1646208627995,"mc":[{"id":"1.195453766","rc":[{"atl":[[1000,0]],"id":42162698}],"con":true,"img":false}]}
{"op":"mcm","clk":"5353090697","pt":1646208628099,"mc":[{"id":"1.195453766","rc":[{"atl":[[60,0.06]],"id":42162698}],"con":true,"img":false}]}
{"op":"mcm","clk":"5353090722","pt":1646208628612,"mc":[{"id":"1.195453766","rc":[{"atb":[[1.02,0]],"id":42688787}],"con":true,"img":false}]}
{"op":"mcm","clk":"5353090728","pt":1646208628715,"mc":[{"id":"1.195453766","rc":[{"atb":[[8.2,0.45]],"id":42688787}],"con":true,"img":false}]}
{"op":"mcm","clk":"5353090784","pt":1646208629796,"mc":[{"id":"1.195453766","rc":[{"atl":[[2.6,6.46]],"id":42154339},{"trd":[[2.6,21.24]],"ltp":2.6,"tv":21.24,"id":42154339}],"con":true,"img":false}]}
{"op":"mcm","clk":"5353090931","pt":1646208632910,"mc":[{"id":"1.195453766","rc":[{"atl":[[3.15,0]],"id":42154339}],"con":true,"img":false}]}
{"op":"mcm","clk":"5353090937","pt":1646208633013,"mc":[{"id":"1.195453766","rc":[{"atl":[[3.05,26.02]],"id":42154339}],"con":true,"img":false}]}
{"op":"mcm","clk":"5353091441","pt":1646208644248,"mc":[{"id":"1.195453766","rc":[{"atl":[[3.05,0]],"id":42154339}],"con":true,"img":false}]}
{"op":"mcm","clk":"5353091445","pt":1646208644311,"mc":[{"id":"1.195453766","rc":[{"atl":[[3.25,26.02]],"id":42154339}],"con":true,"img":false}]}
{"op":"mcm","clk":"5353091553","pt":1646208646821,"mc":[{"id":"1.195453766","rc":[{"atb":[[1.93,0]],"id":42154339}],"con":true,"img":false}]}
{"op":"mcm","clk":"5353091558","pt":1646208646925,"mc":[{"id":"1.195453766","rc":[{"atb":[[1.97,68.07]],"id":42154339}],"con":true,"img":false}]}
{"op":"mcm","clk":"5353091595","pt":1646208647748,"mc":[{"id":"1.195453766","rc":[{"atb":[[1.96,18.37]],"id":42154339}],"con":true,"img":false}]}
{"op":"mcm","clk":"5353091598","pt":1646208647851,"mc":[{"id":"1.195453766","rc":[{"atb":[[1.98,2.01]],"id":42154339}],"con":true,"img":false}]}
{"op":"mcm","clk":"5353091701","pt":1646208650630,"mc":[{"id":"1.195453766","rc":[{"atb":[[2.24,21.74]],"id":42154339}],"con":true,"img":false}]}
{"op":"mcm","clk":"5353091735","pt":1646208651351,"mc":[{"id":"1.195453766","rc":[{"atb":[[1.98,1.76]],"id":42154339}],"con":true,"img":false}]}
{"op":"mcm","clk":"5353091768","pt":1646208651921,"mc":[{"id":"1.195453766","rc":[{"atb":[[1.98,0]],"id":42154339}],"con":true,"img":false}]}
{"op":"mcm","clk":"5353091775","pt":1646208652024,"mc":[{"id":"1.195453766","rc":[{"atb":[[2.26,1.76]],"id":42154339}],"con":true,"img":false}]}
{"op":"mcm","clk":"5353091839","pt":1646208653665,"mc":[{"id":"1.195453766","rc":[{"atb":[[1.96,10.53]],"id":42154339}],"con":true,"img":false}]}
{"op":"mcm","clk":"5353092018","pt":1646208657469,"mc":[{"id":"1.195453766","rc":[{"atb":[[1.04,2.25]],"id":42162698},{"atb":[[1.02,2.25]],"id":43167133}],"con":true,"img":false}]}
{"op":"mcm","clk":"5353092025","pt":1646208657634,"mc":[{"id":"1.195453766","rc":[{"atb":[[1.04,0.17]],"id":42162698},{"atb":[[1.02,0.36]],"id":43167133}],"con":true,"img":false}]}
{"op":"mcm","clk":"5353092031","pt":1646208657839,"mc":[{"id":"1.195453766","rc":[{"atb":[[1.04,0]],"id":42162698}],"con":true,"img":false}]}
{"op":"mcm","clk":"5353092037","pt":1646208657933,"mc":[{"id":"1.195453766","rc":[{"atb":[[22,0.17]],"id":42162698}],"con":true,"img":false}]}
{"op":"mcm","clk":"5353092058","pt":1646208658447,"mc":[{"id":"1.195453766","rc":[{"atb":[[1.02,0]],"id":43167133}],"con":true,"img":false}]}
{"op":"mcm","clk":"5353092062","pt":1646208658549,"mc":[{"id":"1.195453766","rc":[{"atb":[[10.5,0.36]],"id":43167133}],"con":true,"img":false}]}
{"op":"mcm","clk":"5353092133","pt":1646208660348,"mc":[{"id":"1.195453766","rc":[{"atb":[[1.96,0]],"id":42154339}],"con":true,"img":false}]}
{"op":"mcm","clk":"5353092250","pt":1646208662476,"mc":[{"id":"1.195453766","rc":[{"atb":[[2,7.52]],"id":42154339}],"con":true,"img":false}]}
{"op":"mcm","clk":"5353092759","pt":1646208672357,"mc":[{"id":"1.195453766","rc":[{"spn":41.0,"spf":"NaN","id":42162698},{"spn":17.25,"spf":"NaN","id":43167133},{"atb":[[2,17.63]],"id":42154339},{"spn":2.24,"spf":1.0,"id":42154339},{"spn":13.1,"spf":"NaN","id":42688787}],"con":true,"img":false}]}
{"op":"mcm","clk":"5353092778","pt":1646208672664,"mc":[{"id":"1.195453766","rc":[{"atl":[[3.45,0]],"id":42154339}],"con":true,"img":false}]}
{"op":"mcm","clk":"5353093314","pt":1646208684579,"mc":[{"id":"1.195453766","rc":[{"atl":[[6.2,0]],"id":41818763}],"con":true,"img":false}]}
{"op":"mcm","clk":"5353093324","pt":1646208684886,"mc":[{"id":"1.195453766","rc":[{"atl":[[1000,3.03]],"id":41818763}],"con":true,"img":false}]}
{"op":"mcm","clk":"5353093351","pt":1646208685459,"mc":[{"id":"1.195453766","rc":[{"atl":[[1000,2.75]],"id":41818763}],"con":true,"img":false}]}
{"op":"mcm","clk":"5353093405","pt":1646208686793,"mc":[{"id":"1.195453766","rc":[{"atl":[[1000,1.36]],"id":41818763}],"con":true,"img":false}]}
{"op":"mcm","clk":"5353093410","pt":1646208686898,"mc":[{"id":"1.195453766","rc":[{"atl":[[9,1.39]],"id":41818763}],"con":true,"img":false}]}
{"op":"mcm","clk":"5353096014","pt":1646208743355,"mc":[{"id":"1.195453766","rc":[{"spl":[[1.01,7]],"id":42162698},{"spn":20.26,"spf":1.0,"id":42162698},{"spn":7.0,"spf":"NaN","id":41818763},{"spl":[[1.01,7]],"id":41910350},{"spn":14.32,"spf":1.0,"id":41910350},{"spl":[[1.01,7]],"id":43167133},{"spn":9.28,"spf":1.0,"id":43167133},{"spl":[[1.01,7]],"id":42688787},{"spn":7.87,"spf":1.0,"id":42688787}],"con":true,"img":false}]}
{"op":"mcm","clk":"5353099507","pt":1646208816814,"mc":[{"id":"1.195453766","rc":[{"atl":[[9,0]],"id":41818763},{"spn":7.2,"spf":"NaN","id":41818763}],"con":true,"img":false}]}
{"op":"mcm","clk":"5353099523","pt":1646208817072,"mc":[{"id":"1.195453766","rc":[{"atl":[[1000,3.03]],"id":41818763}],"con":true,"img":false}]}
{"op":"mcm","clk":"5353099535","pt":1646208817335,"mc":[{"id":"1.195453766","rc":[{"atl":[[1000,2.72]],"id":41818763}],"con":true,"img":false}]}
{"op":"mcm","clk":"5353099559","pt":1646208817949,"mc":[{"id":"1.195453766","rc":[{"atl":[[1000,1.36]],"id":41818763}],"con":true,"img":false}]}
{"op":"mcm","clk":"5353099563","pt":1646208818053,"mc":[{"id":"1.195453766","rc":[{"atl":[[9.2,1.36]],"id":41818763}],"con":true,"img":false}]}
{"op":"mcm","clk":"5353099582","pt":1646208818569,"mc":[{"id":"1.195453766","rc":[{"atl":[[9.4,0]],"id":41818763}],"con":true,"img":false}]}
{"op":"mcm","clk":"5353099589","pt":1646208818672,"mc":[{"id":"1.195453766","rc":[{"atl":[[9,1.51]],"id":41818763}],"con":true,"img":false}]}
{"op":"mcm","clk":"5353100090","pt":1646208828966,"mc":[{"id":"1.195453766","rc":[{"atl":[[9.2,0]],"id":41818763}],"con":true,"img":false}]}
{"op":"mcm","clk":"5353100107","pt":1646208829377,"mc":[{"id":"1.195453766","rc":[{"atl":[[1000,3.03]],"id":41818763}],"con":true,"img":false}]}
{"op":"mcm","clk":"5353100114","pt":1646208829583,"mc":[{"id":"1.195453766","rc":[{"atl":[[9,0]],"id":41818763}],"con":true,"img":false}]}
{"op":"mcm","clk":"5353100119","pt":1646208829687,"mc":[{"id":"1.195453766","rc":[{"atl":[[9.4,1.51]],"id":41818763}],"con":true,"img":false}]}
{"op":"mcm","clk":"5353100134","pt":1646208829952,"mc":[{"id":"1.195453766","rc":[{"atl":[[1000,2.78]],"id":41818763}],"con":true,"img":false}]}
{"op":"mcm","clk":"5353100174","pt":1646208830672,"mc":[{"id":"1.195453766","rc":[{"atl":[[1000,1.36]],"id":41818763}],"con":true,"img":false}]}
{"op":"mcm","clk":"5353100178","pt":1646208830775,"mc":[{"id":"1.195453766","rc":[{"atl":[[8.8,1.41]],"id":41818763}],"con":true,"img":false}]}
{"op":"mcm","clk":"5353106324","pt":1646208961524,"mc":[{"id":"1.195453766","rc":[{"atl":[[8.8,0]],"id":41818763}],"con":true,"img":false}]}
{"op":"mcm","clk":"5353106339","pt":1646208961831,"mc":[{"id":"1.195453766","rc":[{"atl":[[1000,3.03]],"id":41818763}],"con":true,"img":false}]}
{"op":"mcm","clk":"5353106359","pt":1646208962241,"mc":[{"id":"1.195453766","rc":[{"atl":[[1000,2.72]],"id":41818763}],"con":true,"img":false}]}
{"op":"mcm","clk":"5353106377","pt":1646208962652,"mc":[{"id":"1.195453766","rc":[{"atl":[[1000,1.36]],"id":41818763}],"con":true,"img":false}]}
{"op":"mcm","clk":"5353106385","pt":1646208962709,"mc":[{"id":"1.195453766","rc":[{"atl":[[9.2,1.36]],"id":41818763}],"con":true,"img":false}]}
{"op":"mcm","clk":"5353106398","pt":1646208963016,"mc":[{"id":"1.195453766","rc":[{"atl":[[9.4,0]],"id":41818763}],"con":true,"img":false}]}
{"op":"mcm","clk":"5353106403","pt":1646208963119,"mc":[{"id":"1.195453766","rc":[{"atl":[[9,1.51]],"id":41818763}],"con":true,"img":false}]}
{"op":"mcm","clk":"5353106527","pt":1646208966412,"mc":[{"id":"1.195453766","rc":[{"atb":[[1.28,0]],"id":42154339}],"con":true,"img":false}]}
{"op":"mcm","clk":"5353106798","pt":1646208973245,"mc":[{"id":"1.195453766","rc":[{"atl":[[9.2,0]],"id":41818763}],"con":true,"img":false}]}
{"op":"mcm","clk":"5353106810","pt":1646208973553,"mc":[{"id":"1.195453766","rc":[{"atl":[[1000,3.03]],"id":41818763}],"con":true,"img":false}]}
{"op":"mcm","clk":"5353106820","pt":1646208973864,"mc":[{"id":"1.195453766","rc":[{"atl":[[9,0],[1000,2.78]],"id":41818763}],"con":true,"img":false}]}
{"op":"mcm","clk":"5353106827","pt":1646208973968,"mc":[{"id":"1.195453766","rc":[{"atl":[[9.4,1.51]],"id":41818763}],"con":true,"img":false}]}
{"op":"mcm","clk":"5353106837","pt":1646208974225,"mc":[{"id":"1.195453766","rc":[{"atl":[[1000,1.36]],"id":41818763}],"con":true,"img":false}]}
{"op":"mcm","clk":"5353106841","pt":1646208974328,"mc":[{"id":"1.195453766","rc":[{"atl":[[8.8,1.41]],"id":41818763}],"con":true,"img":false}]}
{"op":"mcm","clk":"5353111877","pt":1646209096328,"mc":[{"id":"1.195453766","rc":[{"atl":[[8.8,0]],"id":41818763}],"con":true,"img":false}]}
{"op":"mcm","clk":"5353111887","pt":1646209096584,"mc":[{"id":"1.195453766","rc":[{"atl":[[1000,3.03]],"id":41818763}],"con":true,"img":false}]}
{"op":"mcm","clk":"5353111904","pt":1646209096995,"mc":[{"id":"1.195453766","rc":[{"atl":[[1000,2.72]],"id":41818763}],"con":true,"img":false}]}
{"op":"mcm","clk":"5353111925","pt":1646209097616,"mc":[{"id":"1.195453766","rc":[{"atl":[[1000,1.36]],"id":41818763}],"con":true,"img":false}]}
{"op":"mcm","clk":"5353111930","pt":1646209097725,"mc":[{"id":"1.195453766","rc":[{"atl":[[9.2,1.36]],"id":41818763}],"con":true,"img":false}]}
{"op":"mcm","clk":"5353111963","pt":1646209098711,"mc":[{"id":"1.195453766","rc":[{"atl":[[9.4,0]],"id":41818763}],"con":true,"img":false}]}
{"op":"mcm","clk":"5353111967","pt":1646209098817,"mc":[{"id":"1.195453766","rc":[{"atl":[[9,1.51]],"id":41818763}],"con":true,"img":false}]}
{"op":"mcm","clk":"5353112349","pt":1646209108316,"mc":[{"id":"1.195453766","rc":[{"atl":[[9.2,0]],"id":41818763}],"con":true,"img":false}]}
{"op":"mcm","clk":"5353112360","pt":1646209108626,"mc":[{"id":"1.195453766","rc":[{"atl":[[1000,3.03]],"id":41818763}],"con":true,"img":false}]}
{"op":"mcm","clk":"5353112364","pt":1646209108934,"mc":[{"id":"1.195453766","rc":[{"atl":[[1000,2.78]],"id":41818763}],"con":true,"img":false}]}
{"op":"mcm","clk":"5353112384","pt":1646209109294,"mc":[{"id":"1.195453766","rc":[{"atl":[[1000,1.36]],"id":41818763}],"con":true,"img":false}]}
{"op":"mcm","clk":"5353112387","pt":1646209109398,"mc":[{"id":"1.195453766","rc":[{"atl":[[8.8,1.41]],"id":41818763}],"con":true,"img":false}]}
{"op":"mcm","clk":"5353114299","pt":1646209154588,"mc":[{"id":"1.195453766","rc":[{"atb":[[9.4,11.9],[7,0]],"id":42162698},{"atb":[[3,60.72],[3.5,63.41]],"id":39637621},{"atb":[[3,0],[3.5,40]],"id":41818763},{"atb":[[7.2,16.13],[5.7,0]],"id":41910350},{"atb":[[3.8,0],[4.4,29.41]],"id":43167133},{"atb":[[1.35,0],[1.27,249.04]],"id":42154339},{"atl":[[3.05,26.02],[3.7,0]],"id":42154339},{"atb":[[4.3,30.3],[3.65,0]],"id":42688787}],"con":true,"img":false}]}
{"op":"mcm","clk":"5353114304","pt":1646209154689,"mc":[{"id":"1.195453766","rc":[{"atb":[[1.35,240.5],[1.27,0]],"id":42154339}],"con":true,"img":false}]}
{"op":"mcm","clk":"5353118005","pt":1646209239414,"mc":[{"id":"1.195453766","rc":[{"spn":6.9,"spf":"NaN","id":41818763},{"atl":[[3.1,0]],"id":42154339}],"con":true,"img":false}]}
{"op":"mcm","clk":"5353122610","pt":1646209342852,"mc":[{"id":"1.195453766","rc":[{"atb":[[5,23.93]],"id":41818763},{"trd":[[5,7.64]],"ltp":5.0,"tv":7.64,"id":41818763}],"con":true,"img":false}]}
{"op":"mcm","clk":"5353123194","pt":1646209353251,"mc":[{"id":"1.195453766","rc":[{"atb":[[3.5,23.41],[3.3,43.48]],"id":39637621}],"con":true,"img":false}]}
{"op":"mcm","clk":"5353123199","pt":1646209353351,"mc":[{"id":"1.195453766","rc":[{"atl":[[3.05,34.2]],"id":42154339}],"con":true,"img":false}]}
{"op":"mcm","clk":"5353131842","pt":1646209515981,"mc":[{"id":"1.195453766","rc":[{"atb":[[7.8,14.71],[9.4,0]],"id":42162698},{"atb":[[7.2,0],[6,20]],"id":41910350},{"atb":[[4.9,25.64],[4.4,0]],"id":43167133}],"con":true,"img":false}]}
{"op":"mcm","clk":"5353131851","pt":1646209516190,"mc":[{"id":"1.195453766","rc":[{"atb":[[7.8,0],[9.6,11.63]],"id":42162698}],"con":true,"img":false}]}
{"op":"mcm","clk":"5353132768","pt":1646209531022,"mc":[{"id":"1.195453766","rc":[{"atb":[[4.3,30.3],[4.9,0]],"id":43167133}],"con":true,"img":false}]}
{"op":"mcm","clk":"5353133411","pt":1646209542822,"mc":[{"id":"1.195453766","rc":[{"atb":[[7.4,15.62],[6,0]],"id":41910350}],"con":true,"img":false}]}
{"op":"mcm","clk":"5353134821","pt":1646209568654,"mc":[{"id":"1.195453766","rc":[{"atb":[[1.43,232.56],[1.35,0]],"id":42154339}],"con":true,"img":false}]}
{"op":"mcm","clk":"5353139418","pt":1646209651059,"mc":[{"id":"1.195453766","rc":[{"atl":[[15,0],[18.5,13.33]],"id":41818763},{"atl":[[3.35,42.55],[3.05,8.18]],"id":42154339}],"con":true,"img":false}]}
{"op":"mcm","clk":"5353142730","pt":1646209707606,"mc":[{"id":"1.195453766","rc":[{"atl":[[3.55,0]],"id":42154339}],"con":true,"img":false}]}
{"op":"mcm","clk":"5353142736","pt":1646209707711,"mc":[{"id":"1.195453766","rc":[{"atl":[[3.3,49.67]],"id":42154339}],"con":true,"img":false}]}
{"op":"mcm","clk":"5353143992","pt":1646209731360,"mc":[{"id":"1.195453766","rc":[{"atl":[[140,2]],"id":42162698},{"atb":[[3.8,8.09],[3.3,0]],"id":39637621},{"atl":[[15,0]],"id":39637621},{"atl":[[16,15.56],[18.5,7.62]],"id":41818763},{"atb":[[7.4,0]],"id":41910350},{"atb":[[4.3,0]],"id":43167133},{"atb":[[4.3,0],[2.74,46.3]],"id":42688787},{"atl":[[38,8.09],[28,0]],"id":42688787}],"con":true,"img":false}]}
{"op":"mcm","clk":"5353143999","pt":1646209731459,"mc":[{"id":"1.195453766","rc":[{"atb":[[8.2,13.89],[9.6,0]],"id":42162698},{"atl":[[200,0.67]],"id":42162698},{"atl":[[12,9.09]],"id":39637621},{"atb":[[4.4,29.41],[3.5,0]],"id":41818763},{"atl":[[12.5,8.7]],"id":41818763},{"atb":[[6,20]],"id":41910350},{"atl":[[140,0],[70,2]],"id":41910350},{"atb":[[1.62,32.76]],"id":43167133},{"atl":[[2.72,10.71],[3.35,0]],"id":42154339},{"atb":[[4.6,27.78]],"id":42688787},{"atl":[[27,3.85]],"id":42688787}],"con":true,"img":false}]}
{"op":"mcm","clk":"5353144005","pt":1646209731516,"mc":[{"id":"1.195453766","rc":[{"atl":[[16,8.89]],"id":41818763},{"atb":[[2.74,0]],"id":42688787},{"atl":[[38,5.39]],"id":42688787}],"con":true,"img":false}]}
{"op":"mcm","clk":"5353144027","pt":1646209731926,"mc":[{"id":"1.195453766","rc":[{"atl":[[1000,0]],"id":41818763}],"con":true,"img":false}]}
{"op":"mcm","clk":"5353144032","pt":1646209732030,"mc":[{"id":"1.195453766","rc":[{"atl":[[9.6,2.43]],"id":41818763}],"con":true,"img":false}]}
{"op":"mcm","clk":"5353144114","pt":1646209733827,"mc":[{"id":"1.195453766","rc":[{"atl":[[3.3,0]],"id":42154339}],"con":true,"img":false}]}
{"op":"mcm","clk":"5353144122","pt":1646209733931,"mc":[{"id":"1.195453766","rc":[{"atl":[[3.55,49.67]],"id":42154339}],"con":true,"img":false}]}
{"op":"mcm","clk":"5353145259","pt":1646209756066,"mc":[{"id":"1.195453766","rc":[{"atb":[[8.2,0],[12,9.09]],"id":42162698},{"atl":[[9.6,11.63],[12,0]],"id":39637621},{"atb":[[9.2,24.76],[6,0]],"id":41910350},{"atb":[[1.62,0],[4,33.33]],"id":43167133}],"con":true,"img":false}]}
{"op":"mcm","clk":"5353145671","pt":1646209764588,"mc":[{"id":"1.195453766","rc":[{"atl":[[9.8,0]],"id":41818763}],"con":true,"img":false}]}
{"op":"mcm","clk":"5353145678","pt":1646209764691,"mc":[{"id":"1.195453766","rc":[{"atl":[[9.4,6.65]],"id":41818763}],"con":true,"img":false}]}
{"op":"mcm","clk":"5353145690","pt":1646209764996,"mc":[{"id":"1.195453766","rc":[{"atl":[[9.6,1.06]],"id":41818763}],"con":true,"img":false}]}
{"op":"mcm","clk":"5353145694","pt":1646209765099,"mc":[{"id":"1.195453766","rc":[{"atl":[[1000,1.36]],"id":41818763}],"con":true,"img":false}]}
{"op":"mcm","clk":"5353145726","pt":1646209765819,"mc":[{"id":"1.195453766","rc":[{"atl":[[9.6,0]],"id":41818763}],"con":true,"img":false}]}
{"op":"mcm","clk":"5353145738","pt":1646209765975,"mc":[{"id":"1.195453766","rc":[{"atl":[[1000,3.61]],"id":41818763}],"con":true,"img":false}]}
{"op":"mcm","clk":"5353145747","pt":1646209766182,"mc":[{"id":"1.195453766","rc":[{"atl":[[1000,2.47]],"id":41818763}],"con":true,"img":false}]}
{"op":"mcm","clk":"5353145757","pt":1646209766388,"mc":[{"id":"1.195453766","rc":[{"atl":[[1000,1.36]],"id":41818763}],"con":true,"img":false}]}
{"op":"mcm","clk":"5353145762","pt":1646209766498,"mc":[{"id":"1.195453766","rc":[{"atl":[[9.2,1.11]],"id":41818763}],"con":true,"img":false}]}
{"op":"mcm","clk":"5353145802","pt":1646209767416,"mc":[{"id":"1.195453766","rc":[{"atl":[[9,0]],"id":41818763}],"con":true,"img":false}]}
{"op":"mcm","clk":"5353145807","pt":1646209767518,"mc":[{"id":"1.195453766","rc":[{"atl":[[8.6,1.51]],"id":41818763}],"con":true,"img":false}]}
{"op":"mcm","clk":"5353145825","pt":1646209767985,"mc":[{"id":"1.195453766","rc":[{"atl":[[9.4,0]],"id":41818763}],"con":true,"img":false}]}
{"op":"mcm","clk":"5353145830","pt":1646209768087,"mc":[{"id":"1.195453766","rc":[{"atl":[[9.8,6.65]],"id":41818763}],"con":true,"img":false}]}
{"op":"mcm","clk":"5353145850","pt":1646209768703,"mc":[{"id":"1.195453766","rc":[{"atl":[[1000,0]],"id":41818763}],"con":true,"img":false}]}
{"op":"mcm","clk":"5353145858","pt":1646209768806,"mc":[{"id":"1.195453766","rc":[{"atl":[[9.6,1.36]],"id":41818763}],"con":true,"img":false}]}
{"op":"mcm","clk":"5353146126","pt":1646209773303,"mc":[{"id":"1.195453766","rc":[{"atl":[[8.8,0]],"id":41818763}],"con":true,"img":false}]}
{"op":"mcm","clk":"5353146140","pt":1646209773611,"mc":[{"id":"1.195453766","rc":[{"atl":[[1000,1.67]],"id":41818763}],"con":true,"img":false}]}
{"op":"mcm","clk":"5353146158","pt":1646209773919,"mc":[{"id":"1.195453766","rc":[{"atl":[[1000,1.48]],"id":41818763}],"con":true,"img":false}]}
{"op":"mcm","clk":"5353146175","pt":1646209774227,"mc":[{"id":"1.195453766","rc":[{"atl":[[1000,0]],"id":41818763}],"con":true,"img":false}]}
{"op":"mcm","clk":"5353146181","pt":1646209774330,"mc":[{"id":"1.195453766","rc":[{"atl":[[8.4,1.48]],"id":41818763}],"con":true,"img":false}]}
{"op":"mcm","clk":"5353146642","pt":1646209784119,"mc":[{"id":"1.195453766","rc":[{"atl":[[12,12]],"id":41818763}],"con":true,"img":false}]}
{"op":"mcm","clk":"5353146651","pt":1646209784220,"mc":[{"id":"1.195453766","rc":[{"atb":[[4.1,0]],"id":41818763},{"atl":[[13.5,0]],"id":41818763}],"con":true,"img":false}]}
{"op":"mcm","clk":"5353146657","pt":1646209784323,"mc":[{"id":"1.195453766","rc":[{"atb":[[4.5,72.01]],"id":41818763}],"con":true,"img":false}]}
{"op":"mcm","clk":"5353151834","pt":1646209879969,"mc":[{"id":"1.195453766","rc":[{"atl":[[9.2,0]],"id":41818763},{"spn":6.7,"spf":"NaN","id":41818763}],"con":true,"img":false}]}
{"op":"mcm","clk":"5353151844","pt":1646209880073,"mc":[{"id":"1.195453766","rc":[{"atl":[[1000,2.25]],"id":41818763}],"con":true,"img":false}]}
{"op":"mcm","clk":"5353151852","pt":1646209880177,"mc":[{"id":"1.195453766","rc":[{"atl":[[3.05,0]],"id":42154339}],"con":true,"img":false}]}
{"op":"mcm","clk":"5353151858","pt":1646209880282,"mc":[{"id":"1.195453766","rc":[{"atl":[[1000,1.06]],"id":41818763}],"con":true,"img":false}]}
{"op":"mcm","clk":"5353151868","pt":1646209880444,"mc":[{"id":"1.195453766","rc":[{"atl":[[1000,0]],"id":41818763}],"con":true,"img":false}]}
{"op":"mcm","clk":"5353151875","pt":1646209880540,"mc":[{"id":"1.195453766","rc":[{"atl":[[9.6,2.43]],"id":41818763}],"con":true,"img":false}]}
{"op":"mcm","clk":"5353153097","pt":1646209904382,"mc":[{"id":"1.195453766","rc":[{"atb":[[3.8,1.68],[3.55,39.22]],"id":39637621},{"atb":[[4,67.67],[4.4,0]],"id":41818763},{"atb":[[9.2,12.56],[7.8,14.71]],"id":41910350},{"atb":[[2.94,46.3],[4,0]],"id":43167133},{"atl":[[2.72,0],[2.88,49.67]],"id":42154339},{"atb":[[3.75,36.36],[4.6,0]],"id":42688787}],"con":true,"img":false}]}
{"op":"mcm","clk":"5353153353","pt":1646209909694,"mc":[{"id":"1.195453766","rc":[{"atb":[[4.5,29.43]],"id":41818763}],"con":true,"img":false}]}
{"op":"mcm","clk":"5353153362","pt":1646209909796,"mc":[{"id":"1.195453766","rc":[{"atb":[[4.1,42.57]],"id":41818763}],"con":true,"img":false}]}
{"op":"mcm","clk":"5353157023","pt":1646209981473,"mc":[{"id":"1.195453766","rc":[{"atb":[[1.03,2.88]],"id":42162698},{"atb":[[1.02,3.39]],"id":39637621},{"atb":[[1.02,3.22]],"id":41818763},{"atb":[[1.03,2.92]],"id":41910350},{"atb":[[1.02,3]],"id":43167133},{"atb":[[1.02,3.04]],"id":42688787}],"con":true,"img":false}]}
{"op":"mcm","clk":"5353157028","pt":1646209981575,"mc":[{"id":"1.195453766","rc":[{"atb":[[1.02,3.85]],"id":42154339}],"con":true,"img":false}]}
{"op":"mcm","clk":"5353157054","pt":1646209981991,"mc":[{"id":"1.195453766","rc":[{"atb":[[1.03,0.15]],"id":42162698},{"atb":[[1.02,0.66]],"id":39637621},{"atb":[[1.02,0.49]],"id":41818763},{"atb":[[1.03,0.19]],"id":41910350},{"atb":[[1.02,0.27]],"id":43167133},{"atb":[[1.02,1.12]],"id":42154339},{"atb":[[1.02,0.31]],"id":42688787}],"con":true,"img":false}]}
{"op":"mcm","clk":"5353157072","pt":1646209982407,"mc":[{"id":"1.195453766","rc":[{"atb":[[1.03,0]],"id":42162698},{"atb":[[1.02,0]],"id":39637621},{"atb":[[1.02,0]],"id":41818763},{"atb":[[1.03,0]],"id":41910350},{"atb":[[1.02,0]],"id":43167133},{"atb":[[1.02,0]],"id":42154339},{"atb":[[1.02,0]],"id":42688787}],"con":true,"img":false}]}
{"op":"mcm","clk":"5353157079","pt":1646209982508,"mc":[{"id":"1.195453766","rc":[{"atb":[[17.5,6.4]],"id":42162698},{"atb":[[4.1,0.66]],"id":39637621},{"atb":[[5.6,0.49]],"id":41818763},{"atb":[[14.5,1.85]],"id":41910350},{"atb":[[9.8,0.27]],"id":43167133},{"atb":[[2.42,1.12]],"id":42154339},{"atb":[[8.6,0.31]],"id":42688787}],"con":true,"img":false}]}
{"op":"mcm","clk":"5353157695","pt":1646209993404,"mc":[{"id":"1.195453766","rc":[{"atl":[[2.8,34.56],[2.88,0]],"id":42154339}],"con":true,"img":false}]}
{"op":"mcm","clk":"5353157713","pt":1646209993611,"mc":[{"id":"1.195453766","rc":[{"atb":[[3.8,8.09],[3.55,0]],"id":39637621},{"atb":[[9,12.5],[7.8,0]],"id":41910350},{"atb":[[2.94,0],[4.2,31.25]],"id":43167133},{"atl":[[38,2.7],[46,2.96]],"id":43167133},{"atl":[[2.8,8.54],[2.62,26.02]],"id":42154339},{"atb":[[4.6,27.78]],"id":42688787},{"atl":[[25,4.17]],"id":42688787}],"con":true,"img":false}]}
{"op":"mcm","clk":"5353157721","pt":1646209993712,"mc":[{"id":"1.195453766","rc":[{"atb":[[3.75,0]],"id":42688787},{"atl":[[27,0]],"id":42688787}],"con":true,"img":false}]}
{"op":"mcm","clk":"5353164119","pt":1646210113636,"mc":[{"id":"1.195453766","rc":[{"atb":[[3.55,39.22]],"id":39637621},{"spn":5.25,"spf":"NaN","id":39637621},{"spn":7.0,"spf":"NaN","id":41818763},{"atb":[[9,0],[7.8,14.71]],"id":41910350},{"spn":14.35,"spf":1.0,"id":41910350},{"atb":[[4.2,0]],"id":43167133},{"spn":9.31,"spf":1.0,"id":43167133},{"atl":[[2.62,0]],"id":42154339},{"spn":2.26,"spf":1.0,"id":42154339},{"atb":[[3.8,35.71]],"id":42688787},{"spn":7.9,"spf":1.0,"id":42688787}],"con":true,"img":false}]}
{"op":"mcm","clk":"5353164124","pt":1646210113737,"mc":[{"id":"1.195453766","rc":[{"atb":[[3.8,1.68]],"id":39637621},{"atb":[[3.15,46.3]],"id":43167133},{"atl":[[2.8,34.56]],"id":42154339},{"atb":[[4.6,0]],"id":42688787}],"con":true,"img":false}]}
{"op":"mcm","clk":"5353164129","pt":1646210113837,"mc":[{"id":"1.195453766","rc":[{"atl":[[3.05,8.18]],"id":42154339}],"con":true,"img":false}]}
{"op":"mcm","clk":"5353171977","pt":1646210260697,"mc":[{"id":"1.195453766","rc":[{"atb":[[3.8,8.09],[3.55,0]],"id":39637621},{"atb":[[9.2,24.76],[7.8,0]],"id":41910350},{"atb":[[4.5,28.57],[3.15,0]],"id":43167133},{"atl":[[2.8,8.54],[2.64,12.92]],"id":42154339},{"atb":[[4.8,26.32]],"id":42688787}],"con":true,"img":false}]}
{"op":"mcm","clk":"5353171982","pt":1646210260798,"mc":[{"id":"1.195453766","rc":[{"atb":[[3.8,0]],"id":42688787}],"con":true,"img":false}]}
{"op":"mcm","clk":"5353171988","pt":1646210260902,"mc":[{"id":"1.195453766","rc":[{"atl":[[3.05,0]],"id":42154339}],"con":true,"img":false}]}
{"op":"mcm","clk":"5353172245","pt":1646210265993,"mc":[{"id":"1.195453766","rc":[{"atl":[[34,6.85],[38,0]],"id":43167133}],"con":true,"img":false}]}
{"op":"mcm","clk":"5353172983","pt":1646210280053,"mc":[{"id":"1.195453766","rc":[{"atb":[[5.6,21.74],[4.5,0]],"id":43167133}],"con":true,"img":false}]}
{"op":"mcm","clk":"5353173176","pt":1646210283053,"mc":[{"id":"1.195453766","rc":[{"atb":[[11,12.5],[12,15.91],[13,4.17],[14,1.54]],"id":42162698},{"atl":[[290,1],[310,1],[330,1],[350,1]],"id":42162698},{"atb":[[3.1,59.52],[3.3,21.74],[3.2,81.03],[3.4,8.33]],"id":39637621},{"atl":[[8.2,17.36],[7.4,7.81],[7.8,11.03],[7,3.33]],"id":39637621},{"atb":[[4.5,50.86],[4.3,37.88],[4.9,5.13],[4.7,13.51]],"id":41818763},{"atl":[[10,5.56],[11,7.5],[12,23.36],[9.6,4.76]],"id":41818763},{"atb":[[10,13.89],[11,7.5],[12,4.55],[13,10.25]],"id":41910350},{"atl":[[190,15.2],[210,1.95],[230,1],[250,1]],"id":41910350},{"atb":[[8.2,2.78],[7.4,11.72],[7.8,7.35],[7,20.83]],"id":43167133},{"atl":[[21,1],[23,2.27],[25,3.12],[27,4.81]],"id":43167133},{"atb":[[1.48,250],[1.54,37.04],[1.5,150],[1.52,96.15]],"id":42154339},{"atl":[[2.44,13.89],[2.48,33.78],[2.56,80.13],[2.52,49.34]],"id":42154339},{"atb":[[6.4,3.7],[5.8,37.13],[5.6,27.17],[6,10]],"id":42688787},{"atl":[[15.5,1.38],[16.5,3.23],[17.5,4.55],[18.5,10.48]],"id":42688787}],"con":true,"img":false}]}
{"op":"mcm","clk":"5353173216","pt":1646210283624,"mc":[{"id":"1.195453766","rc":[{"atl":[[6.2,1.27]],"id":39637621},{"atl":[[23,3.56]],"id":43167133}],"con":true,"img":false}]}
{"op":"mcm","clk":"5353173221","pt":1646210283727,"mc":[{"id":"1.195453766","rc":[{"atl":[[18,0]],"id":42688787}],"con":true,"img":false}]}
{"op":"mcm","clk":"5353173226","pt":1646210283834,"mc":[{"id":"1.195453766","rc":[{"atl":[[16,1.29]],"id":42688787}],"con":true,"img":false}]}
{"op":"mcm","clk":"5353173408","pt":1646210286929,"mc":[{"id":"1.195453766","rc":[{"atl":[[9.6,3.69]],"id":41818763},{"atb":[[2,10.1]],"id":42154339}],"con":true,"img":false}]}
{"op":"mcm","clk":"5353173411","pt":1646210287030,"mc":[{"id":"1.195453766","rc":[{"atl":[[1000,2.25]],"id":41818763}],"con":true,"img":false}]}
{"op":"mcm","clk":"5353173417","pt":1646210287134,"mc":[{"id":"1.195453766","rc":[{"atl":[[15,1.43],[15.5,0]],"id":42688787}],"con":true,"img":false}]}
{"op":"mcm","clk":"5353173429","pt":1646210287340,"mc":[{"id":"1.195453766","rc":[{"atl":[[1000,1.09]],"id":41818763}],"con":true,"img":false}]}
{"op":"mcm","clk":"5353173441","pt":1646210287547,"mc":[{"id":"1.195453766","rc":[{"atl":[[1000,0]],"id":41818763}],"con":true,"img":false}]}
{"op":"mcm","clk":"5353173446","pt":1646210287649,"mc":[{"id":"1.195453766","rc":[{"atl":[[9.4,1.09]],"id":41818763}],"con":true,"img":false}]}
{"op":"mcm","clk":"5353173739","pt":1646210293461,"mc":[{"id":"1.195453766","rc":[{"atb":[[2,0]],"id":42154339}],"con":true,"img":false}]}
{"op":"mcm","clk":"5353174345","pt":1646210304335,"mc":[{"id":"1.195453766","rc":[{"atb":[[4.6,0]],"id":41818763}],"con":true,"img":false}]}
{"op":"mcm","clk":"5353174354","pt":1646210304447,"mc":[{"id":"1.195453766","rc":[{"atb":[[4.8,16.26]],"id":41818763}],"con":true,"img":false}]}
{"op":"mcm","clk":"5353174465","pt":1646210306350,"mc":[{"id":"1.195453766","rc":[{"atl":[[9.8,0]],"id":41818763}],"con":true,"img":false}]}
{"op":"mcm","clk":"5353174469","pt":1646210306450,"mc":[{"id":"1.195453766","rc":[{"atl":[[9.4,7.74]],"id":41818763}],"con":true,"img":false}]}
{"op":"mcm","clk":"5353174480","pt":1646210306659,"mc":[{"id":"1.195453766","rc":[{"atl":[[9.6,2.33]],"id":41818763}],"con":true,"img":false}]}
{"op":"mcm","clk":"5353174487","pt":1646210306764,"mc":[{"id":"1.195453766","rc":[{"atl":[[9.2,1.36]],"id":41818763}],"con":true,"img":false}]}
{"op":"mcm","clk":"5353174494","pt":1646210306862,"mc":[{"id":"1.195453766","rc":[{"atl":[[9.4,6.65]],"id":41818763}],"con":true,"img":false}]}
{"op":"mcm","clk":"5353174502","pt":1646210306971,"mc":[{"id":"1.195453766","rc":[{"atl":[[1000,2.25]],"id":41818763}],"con":true,"img":false}]}
{"op":"mcm","clk":"5353174508","pt":1646210307169,"mc":[{"id":"1.195453766","rc":[{"atl":[[1000,1.11]],"id":41818763}],"con":true,"img":false}]}
{"op":"mcm","clk":"5353174528","pt":1646210307480,"mc":[{"id":"1.195453766","rc":[{"atl":[[1000,0]],"id":41818763}],"con":true,"img":false}]}
{"op":"mcm","clk":"5353174537","pt":1646210307582,"mc":[{"id":"1.195453766","rc":[{"atl":[[9.2,2.47]],"id":41818763}],"con":true,"img":false}]}
{"op":"mcm","clk":"5353174687","pt":1646210310468,"mc":[{"id":"1.195453766","rc":[{"atl":[[24,0]],"id":43167133},{"atl":[[18.5,7.14]],"id":42688787}],"con":true,"img":false}]}
{"op":"mcm","clk":"5353174694","pt":1646210310572,"mc":[{"id":"1.195453766","rc":[{"atl":[[22,2.72]],"id":43167133},{"atl":[[17,3.34]],"id":42688787}],"con":true,"img":false}]}
{"op":"mcm","clk":"5353174713","pt":1646210310878,"mc":[{"id":"1.195453766","rc":[{"atl":[[23,2.27]],"id":43167133}],"con":true,"img":false}]}
{"op":"mcm","clk":"5353174719","pt":1646210310981,"mc":[{"id":"1.195453766","rc":[{"atl":[[21,2.29]],"id":43167133}],"con":true,"img":false}]}
{"op":"mcm","clk":"5353175294","pt":1646210321083,"mc":[{"id":"1.195453766","rc":[{"spn":5.15,"spf":"NaN","id":39637621},{"atl":[[2.44,13.27]],"id":42154339},{"trd":[[2.44,1.23]],"ltp":2.44,"tv":1.23,"id":42154339}],"con":true,"img":false}]}
{"op":"mcm","clk":"5353175301","pt":1646210321291,"mc":[{"id":"1.195453766","rc":[{"atl":[[2.5,13.28],[2.44,0],[2.48,0],[2.56,0],[2.52,0]],"id":42154339}],"con":true,"img":false}]}
{"op":"mcm","clk":"5353175305","pt":1646210321388,"mc":[{"id":"1.195453766","rc":[{"atl":[[2.62,61.73]],"id":42154339}],"con":true,"img":false}]}
{"op":"mcm","clk":"5353175310","pt":1646210321490,"mc":[{"id":"1.195453766","rc":[{"atl":[[2.64,0]],"id":42154339}],"con":true,"img":false}]}
{"op":"mcm","clk":"5353175433","pt":1646210324374,"mc":[{"id":"1.195453766","rc":[{"atb":[[3,0]],"id":39637621},{"atl":[[7.2,19.59],[8.6,0]],"id":39637621},{"atb":[[4.1,0]],"id":41818763},{"atl":[[12,11.36],[9.8,14.73]],"id":41818763}],"con":true,"img":false}]}
{"op":"mcm","clk":"5353175439","pt":1646210324477,"mc":[{"id":"1.195453766","rc":[{"atb":[[3.15,60.72]],"id":39637621},{"atb":[[4.4,42.57]],"id":41818763}],"con":true,"img":false}]}
{"op":"mcm","clk":"5353175525","pt":1646210326385,"mc":[{"id":"1.195453766","rc":[{"atl":[[34,3.03],[24,5.45]],"id":43167133}],"con":true,"img":false}]}
{"op":"mcm","clk":"5353175641","pt":1646210328450,"mc":[{"id":"1.195453766","rc":[{"atl":[[9.4,0]],"id":41818763}],"con":true,"img":false}]}
{"op":"mcm","clk":"5353175647","pt":1646210328553,"mc":[{"id":"1.195453766","rc":[{"atl":[[9,6.65]],"id":41818763}],"con":true,"img":false}]}
{"op":"mcm","clk":"5353175664","pt":1646210328966,"mc":[{"id":"1.195453766","rc":[{"atl":[[9.2,1.11]],"id":41818763}],"con":true,"img":false}]}
{"op":"mcm","clk":"5353175671","pt":1646210329069,"mc":[{"id":"1.195453766","rc":[{"atl":[[8.8,1.36]],"id":41818763}],"con":true,"img":false}]}
{"op":"mcm","clk":"5353175766","pt":1646210330970,"mc":[{"id":"1.195453766","rc":[{"atl":[[9.2,0]],"id":41818763}],"con":true,"img":false}]}
{"op":"mcm","clk":"5353175775","pt":1646210331175,"mc":[{"id":"1.195453766","rc":[{"atl":[[1000,2.25],[8.6,0]],"id":41818763}],"con":true,"img":false}]}
{"op":"mcm","clk":"5353175780","pt":1646210331278,"mc":[{"id":"1.195453766","rc":[{"atl":[[8.2,1.51]],"id":41818763},{"atl":[[2.54,32.34]],"id":42154339}],"con":true,"img":false}]}
{"op":"mcm","clk":"5353175784","pt":1646210331380,"mc":[{"id":"1.195453766","rc":[{"atl":[[1000,1.16]],"id":41818763}],"con":true,"img":false}]}
{"op":"mcm","clk":"5353175799","pt":1646210331686,"mc":[{"id":"1.195453766","rc":[{"atl":[[1000,0]],"id":41818763}],"con":true,"img":false}]}
{"op":"mcm","clk":"5353175806","pt":1646210331790,"mc":[{"id":"1.195453766","rc":[{"atl":[[8.8,2.52]],"id":41818763}],"con":true,"img":false}]}
{"op":"mcm","clk":"5353175971","pt":1646210335358,"mc":[{"id":"1.195453766","rc":[{"atl":[[8.4,0]],"id":41818763}],"con":true,"img":false}]}
{"op":"mcm","clk":"5353175990","pt":1646210335668,"mc":[{"id":"1.195453766","rc":[{"atl":[[1000,1.67]],"id":41818763}],"con":true,"img":false}]}
{"op":"mcm","clk":"5353176026","pt":1646210336388,"mc":[{"id":"1.195453766","rc":[{"atl":[[1000,1.56]],"id":41818763}],"con":true,"img":false}]}
{"op":"mcm","clk":"5353176043","pt":1646210336798,"mc":[{"id":"1.195453766","rc":[{"atl":[[1000,0]],"id":41818763}],"con":true,"img":false}]}
{"op":"mcm","clk":"5353176046","pt":1646210336899,"mc":[{"id":"1.195453766","rc":[{"atl":[[8,1.56]],"id":41818763}],"con":true,"img":false}]}
{"op":"mcm","clk":"5353176198","pt":1646210340400,"mc":[{"id":"1.195453766","rc":[{"atl":[[9,0]],"id":41818763}],"con":true,"img":false}]}
{"op":"mcm","clk":"5353176203","pt":1646210340504,"mc":[{"id":"1.195453766","rc":[{"atl":[[9.4,6.65]],"id":41818763}],"con":true,"img":false}]}
{"op":"mcm","clk":"5353176231","pt":1646210340969,"mc":[{"id":"1.195453766","rc":[{"atl":[[8.8,1.16]],"id":41818763}],"con":true,"img":false}]}
{"op":"mcm","clk":"5353176233","pt":1646210341073,"mc":[{"id":"1.195453766","rc":[{"atl":[[9.2,1.36]],"id":41818763}],"con":true,"img":false}]}
{"op":"mcm","clk":"5353176247","pt":1646210341279,"mc":[{"id":"1.195453766","rc":[{"atl":[[2.58,47.28]],"id":42154339}],"con":true,"img":false}]}
{"op":"mcm","clk":"5353176786","pt":1646210351277,"mc":[{"id":"1.195453766","rc":[{"atl":[[2.62,138.59]],"id":42154339}],"con":true,"img":false}]}
{"op":"mcm","clk":"5353177095","pt":1646210357822,"mc":[{"id":"1.195453766","rc":[{"atb":[[8.8,0]],"id":43167133}],"con":true,"img":false}]}
{"op":"mcm","clk":"5353177100","pt":1646210357923,"mc":[{"id":"1.195453766","rc":[{"atb":[[8,16.37]],"id":43167133}],"con":true,"img":false}]}
{"op":"mcm","clk":"5353177126","pt":1646210358389,"mc":[{"id":"1.195453766","rc":[{"atl":[[9.4,0]],"id":41818763}],"con":true,"img":false}]}
{"op":"mcm","clk":"5353177133","pt":1646210358502,"mc":[{"id":"1.195453766","rc":[{"atl":[[9.8,21.39]],"id":41818763}],"con":true,"img":false}]}
{"op":"mcm","clk":"5353177178","pt":1646210359215,"mc":[{"id":"1.195453766","rc":[{"atl":[[9.2,0]],"id":41818763}],"con":true,"img":false}]}
{"op":"mcm","clk":"5353177183","pt":1646210359318,"mc":[{"id":"1.195453766","rc":[{"atl":[[9.6,3.69]],"id":41818763}],"con":true,"img":false}]}
{"op":"mcm","clk":"5353177251","pt":1646210360507,"mc":[{"id":"1.195453766","rc":[{"atl":[[22,0]],"id":43167133}],"con":true,"img":false}]}
{"op":"mcm","clk":"5353177258","pt":1646210360609,"mc":[{"id":"1.195453766","rc":[{"atl":[[23,4.99]],"id":43167133}],"con":true,"img":false}]}
{"op":"mcm","clk":"5353177274","pt":1646210360919,"mc":[{"id":"1.195453766","rc":[{"atl":[[21,1]],"id":43167133}],"con":true,"img":false}]}
{"op":"mcm","clk":"5353177279","pt":1646210361022,"mc":[{"id":"1.195453766","rc":[{"atl":[[22,1.29]],"id":43167133}],"con":true,"img":false}]}
{"op":"mcm","clk":"5353177467","pt":1646210364423,"mc":[{"id":"1.195453766","rc":[{"atb":[[9,0]],"id":43167133}],"con":true,"img":false}]}
{"op":"mcm","clk":"5353177473","pt":1646210364524,"mc":[{"id":"1.195453766","rc":[{"atb":[[8.8,7.31]],"id":43167133}],"con":true,"img":false}]}
{"op":"mcm","clk":"5353177686","pt":1646210368540,"mc":[{"id":"1.195453766","rc":[{"atb":[[9.2,0]],"id":43167133}],"con":true,"img":false}]}
{"op":"mcm","clk":"5353177690","pt":1646210368644,"mc":[{"id":"1.195453766","rc":[{"atb":[[9,1.5]],"id":43167133}],"con":true,"img":false}]}
{"op":"mcm","clk":"5353177698","pt":1646210368748,"mc":[{"id":"1.195453766","rc":[{"atb":[[10.5,0],[1.02,2.25]],"id":43167133}],"con":true,"img":false}]}
{"op":"mcm","clk":"5353177708","pt":1646210368850,"mc":[{"id":"1.195453766","rc":[{"atb":[[1.02,0.36]],"id":43167133}],"con":true,"img":false}]}
{"op":"mcm","clk":"5353177714","pt":1646210369006,"mc":[{"id":"1.195453766","rc":[{"atb":[[1.02,0]],"id":43167133}],"con":true,"img":false}]}
{"op":"mcm","clk":"5353177719","pt":1646210369109,"mc":[{"id":"1.195453766","rc":[{"atb":[[9,1.86]],"id":43167133}],"con":true,"img":false}]}
{"op":"mcm","clk":"5353182074","pt":1646210454315,"mc":[{"id":"1.195453766","rc":[{"atl":[[8.8,0]],"id":41818763},{"spn":6.8,"spf":"NaN","id":41818763},{"spn":9.08,"spf":1.0,"id":43167133}],"con":true,"img":false}]}
{"op":"mcm","clk":"5353182084","pt":1646210454518,"mc":[{"id":"1.195453766","rc":[{"atl":[[1000,2.25]],"id":41818763},{"atl":[[2.5,0],[2.46,13.64]],"id":42154339}],"con":true,"img":false}]}
{"op":"mcm","clk":"5353182099","pt":1646210454727,"mc":[{"id":"1.195453766","rc":[{"atl":[[1000,1.09]],"id":41818763}],"con":true,"img":false}]}
{"op":"mcm","clk":"5353182111","pt":1646210454934,"mc":[{"id":"1.195453766","rc":[{"atl":[[1000,0]],"id":41818763}],"con":true,"img":false}]}
{"op":"mcm","clk":"5353182118","pt":1646210455037,"mc":[{"id":"1.195453766","rc":[{"atl":[[9.4,1.09]],"id":41818763}],"con":true,"img":false}]}
{"op":"mcm","clk":"5353182260","pt":1646210457351,"mc":[{"id":"1.195453766","rc":[{"atb":[[9,1.5],[1.02,2.25]],"id":43167133}],"con":true,"img":false}]}
{"op":"mcm","clk":"5353182267","pt":1646210457556,"mc":[{"id":"1.195453766","rc":[{"atb":[[1.02,0.36]],"id":43167133}],"con":true,"img":false}]}
{"op":"mcm","clk":"5353182277","pt":1646210457710,"mc":[{"id":"1.195453766","rc":[{"atb":[[1.02,0]],"id":43167133}],"con":true,"img":false}]}
{"op":"mcm","clk":"5353182281","pt":1646210457815,"mc":[{"id":"1.195453766","rc":[{"atb":[[10.5,0.36]],"id":43167133}],"con":true,"img":false}]}
{"op":"mcm","clk":"5353182649","pt":1646210464567,"mc":[{"id":"1.195453766","rc":[{"atl":[[2.44,13.83],[2.46,0]],"id":42154339}],"con":true,"img":false}]}
{"op":"mcm","clk":"5353183207","pt":1646210474549,"mc":[{"id":"1.195453766","rc":[{"atl":[[2.48,33.65]],"id":42154339}],"con":true,"img":false}]}
{"op":"mcm","clk":"5353183707","pt":1646210484588,"mc":[{"id":"1.195453766","rc":[{"atl":[[2.54,0],[2.58,0],[2.62,61.73],[2.52,49.15]],"id":42154339}],"con":true,"img":false}]}
{"op":"mcm","clk":"5353184259","pt":1646210494590,"mc":[{"id":"1.195453766","rc":[{"atl":[[2.56,79.81]],"id":42154339}],"con":true,"img":false}]}
{"op":"mcm","clk":"5353185093","pt":1646210508406,"mc":[{"id":"1.195453766","rc":[{"atl":[[23,2.27]],"id":43167133}],"con":true,"img":false}]}
{"op":"mcm","clk":"5353185100","pt":1646210508507,"mc":[{"id":"1.195453766","rc":[{"atl":[[22,4.02]],"id":43167133}],"con":true,"img":false}]}
{"op":"mcm","clk":"5353188278","pt":1646210564497,"mc":[{"id":"1.195453766","rc":[{"atl":[[44,0]],"id":41910350},{"spn":9.16,"spf":1.0,"id":43167133}],"con":true,"img":false}]}
{"op":"mcm","clk":"5353188279","pt":1646210564549,"mc":[{"id":"1.195453766","rc":[{"atl":[[46,2.72]],"id":41910350}],"con":true,"img":false}]}
{"op":"mcm","clk":"5353189263","pt":1646210584827,"mc":[{"id":"1.195453766","rc":[{"atb":[[3.8,1.68],[3.65,23.42]],"id":39637621},{"atb":[[5.6,0],[4.7,27.03]],"id":43167133},{"atl":[[2.8,64.1],[2.62,0]],"id":42154339},{"atb":[[4.8,0],[4,33.33]],"id":42688787}],"con":true,"img":false}]}
{"op":"mcm","clk":"5353190480","pt":1646210606425,"mc":[{"id":"1.195453766","rc":[{"atl":[[9.8,14.73]],"id":41818763}],"con":true,"img":false}]}
{"op":"mcm","clk":"5353190486","pt":1646210606525,"mc":[{"id":"1.195453766","rc":[{"atl":[[9.4,7.74]],"id":41818763}],"con":true,"img":false}]}
{"op":"mcm","clk":"5353190510","pt":1646210606939,"mc":[{"id":"1.195453766","rc":[{"atl":[[9.6,2.33]],"id":41818763}],"con":true,"img":false}]}
{"op":"mcm","clk":"5353190514","pt":1646210607042,"mc":[{"id":"1.195453766","rc":[{"atl":[[9.2,1.36]],"id":41818763}],"con":true,"img":false}]}
{"op":"mcm","clk":"5353190533","pt":1646210607453,"mc":[{"id":"1.195453766","rc":[{"atl":[[9.4,6.65]],"id":41818763}],"con":true,"img":false}]}
{"op":"mcm","clk":"5353190540","pt":1646210607616,"mc":[{"id":"1.195453766","rc":[{"atl":[[1000,2.25]],"id":41818763}],"con":true,"img":false}]}
{"op":"mcm","clk":"5353190552","pt":1646210607924,"mc":[{"id":"1.195453766","rc":[{"atl":[[1000,1.11]],"id":41818763}],"con":true,"img":false}]}
{"op":"mcm","clk":"5353190556","pt":1646210608028,"mc":[{"id":"1.195453766","rc":[{"atl":[[1000,0]],"id":41818763}],"con":true,"img":false}]}
{"op":"mcm","clk":"5353190558","pt":1646210608131,"mc":[{"id":"1.195453766","rc":[{"atl":[[9.2,2.47]],"id":41818763}],"con":true,"img":false}]}
{"op":"mcm","clk":"5353192113","pt":1646210643082,"mc":[{"id":"1.195453766","rc":[{"atb":[[2.28,6]],"id":42154339},{"spn":2.28,"spf":1.0,"id":42154339}],"con":true,"img":false}]}
{"op":"mcm","clk":"5353192137","pt":1646210643595,"mc":[{"id":"1.195453766","rc":[{"atb":[[2.26,0]],"id":42154339}],"con":true,"img":false}]}
{"op":"mcm","clk":"5353192145","pt":1646210643694,"mc":[{"id":"1.195453766","rc":[{"atb":[[2.3,1.76]],"id":42154339}],"con":true,"img":false}]}
{"op":"mcm","clk":"5353192209","pt":1646210644995,"mc":[{"id":"1.195453766","rc":[{"atb":[[22,1.84]],"id":42162698},{"atb":[[3.85,2.5]],"id":39637621},{"atb":[[5.1,2.5]],"id":41818763},{"atb":[[15,2.08]],"id":41910350},{"atb":[[8.2,2.96]],"id":42688787}],"con":true,"img":false}]}
{"op":"mcm","clk":"5353192550","pt":1646210653003,"mc":[{"id":"1.195453766","rc":[{"atb":[[2.04,0]],"id":42154339}],"con":true,"img":false}]}
{"op":"mcm","clk":"5353192555","pt":1646210653106,"mc":[{"id":"1.195453766","rc":[{"atb":[[2.16,2.72]],"id":42154339}],"con":true,"img":false}]}
{"op":"mcm","clk":"5353192649","pt":1646210654811,"mc":[{"id":"1.195453766","rc":[{"atb":[[3.85,5.01],[3.65,0]],"id":39637621},{"atb":[[5.7,21.28],[4.7,0]],"id":43167133},{"atl":[[2.8,8.54],[2.62,61.73]],"id":42154339},{"atb":[[4.8,26.32],[4,0]],"id":42688787},{"atl":[[15,0],[15.5,1.38]],"id":42688787}],"con":true,"img":false}]}
{"op":"mcm","clk":"5353192741","pt":1646210656413,"mc":[{"id":"1.195453766","rc":[{"atl":[[22,1.29]],"id":43167133}],"con":true,"img":false}]}
{"op":"mcm","clk":"5353192745","pt":1646210656516,"mc":[{"id":"1.195453766","rc":[{"atl":[[23,4.99]],"id":43167133}],"con":true,"img":false}]}
{"op":"mcm","clk":"5353193059","pt":1646210662404,"mc":[{"id":"1.195453766","rc":[{"atl":[[9.4,0]],"id":41818763}],"con":true,"img":false}]}
{"op":"mcm","clk":"5353193064","pt":1646210662511,"mc":[{"id":"1.195453766","rc":[{"atl":[[9.8,21.39]],"id":41818763}],"con":true,"img":false}]}
{"op":"mcm","clk":"5353193079","pt":1646210662719,"mc":[{"id":"1.195453766","rc":[{"atl":[[9.2,1.11]],"id":41818763}],"con":true,"img":false}]}
{"op":"mcm","clk":"5353193084","pt":1646210662815,"mc":[{"id":"1.195453766","rc":[{"atl":[[9.6,3.69]],"id":41818763}],"con":true,"img":false}]}
{"op":"mcm","clk":"5353193590","pt":1646210672722,"mc":[{"id":"1.195453766","rc":[{"atb":[[5.6,0],[5.1,0]],"id":41818763},{"trd":[[5.1,17.21],[5.6,0.98]],"ltp":5.1,"tv":18.19,"id":41818763}],"con":true,"img":false}]}
{"op":"mcm","clk":"5353193596","pt":1646210672822,"mc":[{"id":"1.195453766","rc":[{"atb":[[4.4,71.98]],"id":41818763}],"con":true,"img":false}]}
{"op":"mcm","clk":"5353193602","pt":1646210672925,"mc":[{"id":"1.195453766","rc":[{"atb":[[4,34.34]],"id":41818763}],"con":true,"img":false}]}
{"op":"mcm","clk":"5353193608","pt":1646210673032,"mc":[{"id":"1.195453766","rc":[{"atb":[[3.85,6.31]],"id":39637621},{"atb":[[5.1,1.33]],"id":41818763},{"atb":[[8.8,8.54]],"id":43167133},{"atb":[[8,2.92]],"id":42688787}],"con":true,"img":false}]}
{"op":"mcm","clk":"5353194850","pt":1646210699066,"mc":[{"id":"1.195453766","rc":[{"atb":[[5.1,0]],"id":41818763},{"trd":[[5.1,19.88]],"ltp":5.1,"tv":19.88,"id":41818763}],"con":true,"img":false}]}
{"op":"mcm","clk":"5353194883","pt":1646210699683,"mc":[{"id":"1.195453766","rc":[{"atl":[[9.6,4.86]],"id":41818763}],"con":true,"img":false}]}
{"op":"mcm","clk":"5353195245","pt":1646210706387,"mc":[{"id":"1.195453766","rc":[{"atb":[[1.11,1.67]],"id":42162698},{"spn":20.74,"spf":1.0,"id":42162698},{"atb":[[1.02,1.67]],"id":39637621},{"atb":[[1.03,1.67]],"id":41818763},{"spn":6.5,"spf":"NaN","id":41818763},{"atb":[[1.07,1.67]],"id":41910350},{"spn":14.66,"spf":1.0,"id":41910350},{"atb":[[1.05,1.67]],"id":43167133},{"atb":[[1.01,1.67]],"id":42154339},{"spn":2.29,"spf":1.0,"id":42154339},{"atb":[[1.04,1.67]],"id":42688787},{"spn":8.08,"spf":1.0,"id":42688787}],"con":true,"img":false}]}
{"op":"mcm","clk":"5353195254","pt":1646210706696,"mc":[{"id":"1.195453766","rc":[{"atb":[[1.11,0.06]],"id":42162698},{"atb":[[1.02,0.42]],"id":39637621},{"atb":[[1.03,0.32]],"id":41818763},{"atb":[[1.07,0.1]],"id":41910350},{"atb":[[1.05,0.15]],"id":43167133},{"atb":[[1.01,0.68]],"id":42154339},{"atb":[[1.04,0.19]],"id":42688787}],"con":true,"img":false}]}
{"op":"mcm","clk":"5353195271","pt":1646210707108,"mc":[{"id":"1.195453766","rc":[{"atb":[[1.11,0]],"id":42162698},{"atb":[[1.02,0]],"id":39637621},{"atb":[[1.03,0]],"id":41818763},{"atb":[[1.07,0]],"id":41910350},{"atb":[[1.05,0]],"id":43167133},{"atb":[[1.01,0]],"id":42154339},{"atb":[[1.04,0]],"id":42688787}],"con":true,"img":false}]}
{"op":"mcm","clk":"5353195275","pt":1646210707212,"mc":[{"id":"1.195453766","rc":[{"atb":[[23,0.06]],"id":42162698},{"atb":[[3.9,0.42]],"id":39637621},{"atb":[[5.1,0.32]],"id":41818763},{"atb":[[15.5,0.1]],"id":41910350},{"atb":[[10.5,0.51]],"id":43167133},{"atb":[[2.42,1.81]],"id":42154339},{"atb":[[8.4,0.19]],"id":42688787}],"con":true,"img":false}]}
{"op":"mcm","clk":"5353195365","pt":1646210708708,"mc":[{"id":"1.195453766","rc":[{"atb":[[3.85,3.8]],"id":39637621}],"con":true,"img":false}]}
{"op":"mcm","clk":"5353195385","pt":1646210709275,"mc":[{"id":"1.195453766","rc":[{"atb":[[3.85,2.51]],"id":39637621}],"con":true,"img":false}]}
{"op":"mcm","clk":"5353195389","pt":1646210709377,"mc":[{"id":"1.195453766","rc":[{"atb":[[3.75,7.7]],"id":39637621}],"con":true,"img":false}]}
{"op":"mcm","clk":"5353195490","pt":1646210711186,"mc":[{"id":"1.195453766","rc":[{"atb":[[3.95,2.5]],"id":39637621}],"con":true,"img":false}]}
{"op":"mcm","clk":"5353195496","pt":1646210711289,"mc":[{"id":"1.195453766","rc":[{"atb":[[3.85,0],[3.95,5.01]],"id":39637621}],"con":true,"img":false}]}
{"op":"mcm","clk":"5353195516","pt":1646210711701,"mc":[{"id":"1.195453766","rc":[{"atb":[[3.75,6.41]],"id":39637621}],"con":true,"img":false}]}
{"op":"mcm","clk":"5353195522","pt":1646210711803,"mc":[{"id":"1.195453766","rc":[{"atb":[[3.95,6.31]],"id":39637621}],"con":true,"img":false}]}
{"op":"mcm","clk":"5353195822","pt":1646210717997,"mc":[{"id":"1.195453766","rc":[{"atl":[[9.8,6.65]],"id":41818763}],"con":true,"img":false}]}
{"op":"mcm","clk":"5353195827","pt":1646210718100,"mc":[{"id":"1.195453766","rc":[{"atl":[[10.5,14.73]],"id":41818763}],"con":true,"img":false}]}
{"op":"mcm","clk":"5353195926","pt":1646210720426,"mc":[{"id":"1.195453766","rc":[{"atl":[[9.8,0]],"id":41818763}],"con":true,"img":false}]}
{"op":"mcm","clk":"5353195931","pt":1646210720525,"mc":[{"id":"1.195453766","rc":[{"atl":[[9.4,6.65]],"id":41818763}],"con":true,"img":false}]}
{"op":"mcm","clk":"5353195939","pt":1646210720734,"mc":[{"id":"1.195453766","rc":[{"atl":[[9.6,3.69]],"id":41818763}],"con":true,"img":false}]}
{"op":"mcm","clk":"5353195943","pt":1646210720785,"mc":[{"id":"1.195453766","rc":[{"atl":[[9.2,2.28]],"id":41818763}],"con":true,"img":false}]}
{"op":"mcm","clk":"5353195953","pt":1646210721097,"mc":[{"id":"1.195453766","rc":[{"atl":[[9.6,2.33]],"id":41818763}],"con":true,"img":false}]}
{"op":"mcm","clk":"5353195956","pt":1646210721199,"mc":[{"id":"1.195453766","rc":[{"atl":[[9.2,3.64]],"id":41818763}],"con":true,"img":false}]}
{"op":"mcm","clk":"5353195971","pt":1646210721610,"mc":[{"id":"1.195453766","rc":[{"atl":[[9.2,2.53]],"id":41818763}],"con":true,"img":false}]}
{"op":"mcm","clk":"5353195977","pt":1646210721716,"mc":[{"id":"1.195453766","rc":[{"atl":[[1000,2.25]],"id":41818763}],"con":true,"img":false}]}
{"op":"mcm","clk":"5353195981","pt":1646210721818,"mc":[{"id":"1.195453766","rc":[{"atl":[[1000,1.13]],"id":41818763}],"con":true,"img":false}]}
{"op":"mcm","clk":"5353195986","pt":1646210722026,"mc":[{"id":"1.195453766","rc":[{"atl":[[1000,0]],"id":41818763}],"con":true,"img":false}]}
{"op":"mcm","clk":"5353195990","pt":1646210722129,"mc":[{"id":"1.195453766","rc":[{"atl":[[9,1.13]],"id":41818763}],"con":true,"img":false}]}
{"op":"mcm","clk":"5353196947","pt":1646210744457,"mc":[{"id":"1.195453766","rc":[{"atl":[[23,2.27]],"id":43167133}],"con":true,"img":false}]}
{"op":"mcm","clk":"5353196954","pt":1646210744561,"mc":[{"id":"1.195453766","rc":[{"atl":[[22,4.02]],"id":43167133}],"con":true,"img":false}]}
{"op":"mcm","clk":"5353197390","pt":1646210753553,"mc":[{"id":"1.195453766","rc":[{"atb":[[4.3,3.01]],"id":39637621}],"con":true,"img":false}]}
{"op":"mcm","clk":"5353197397","pt":1646210753760,"mc":[{"id":"1.195453766","rc":[{"atb":[[4,3.68],[3.95,3.8]],"id":39637621}],"con":true,"img":false}]}
{"op":"mcm","clk":"5353197477","pt":1646210755566,"mc":[{"id":"1.195453766","rc":[{"atb":[[3.95,1.29]],"id":39637621}],"con":true,"img":false}]}
{"op":"mcm","clk":"5353197526","pt":1646210756548,"mc":[{"id":"1.195453766","rc":[{"atb":[[4.4,2.5]],"id":39637621}],"con":true,"img":false}]}
{"op":"mcm","clk":"5353199187","pt":1646210788021,"mc":[{"id":"1.195453766","rc":[{"atb":[[22,1.67],[1.04,2.25]],"id":42162698},{"spn":20.71,"spf":1.0,"id":42162698},{"spn":5.3,"spf":"NaN","id":39637621},{"spn":6.55,"spf":"NaN","id":41818763},{"spn":14.68,"spf":1.0,"id":41910350},{"spn":9.2,"spf":1.0,"id":43167133},{"spn":2.3,"spf":1.0,"id":42154339},{"spn":8.1,"spf":1.0,"id":42688787}],"con":true,"img":false}]}
{"op":"mcm","clk":"5353199198","pt":1646210788227,"mc":[{"id":"1.195453766","rc":[{"atb":[[1.04,0.15]],"id":42162698}],"con":true,"img":false}]}
{"op":"mcm","clk":"5353199206","pt":1646210788382,"mc":[{"id":"1.195453766","rc":[{"atb":[[1.04,0]],"id":42162698}],"con":true,"img":false}]}
{"op":"mcm","clk":"5353199210","pt":1646210788486,"mc":[{"id":"1.195453766","rc":[{"atb":[[24,0.15]],"id":42162698}],"con":true,"img":false}]}
{"op":"mcm","clk":"5353199932","pt":1646210804435,"mc":[{"id":"1.195453766","rc":[{"atb":[[8,0]],"id":43167133}],"con":true,"img":false}]}
{"op":"mcm","clk":"5353199937","pt":1646210804536,"mc":[{"id":"1.195453766","rc":[{"atb":[[8.8,24.92]],"id":43167133}],"con":true,"img":false}]}
{"op":"mcm","clk":"5353203247","pt":1646210873138,"mc":[{"id":"1.195453766","rc":[{"atb":[[12,6.82],[14.5,5.11]],"id":42162698},{"atl":[[140,0],[210,1],[290,0],[120,2]],"id":42162698},{"spn":20.8,"spf":1.0,"id":42162698},{"atb":[[4.8,0],[3.95,33.9]],"id":42688787}],"con":true,"img":false}]}
{"op":"mcm","clk":"5353203253","pt":1646210873243,"mc":[{"id":"1.195453766","rc":[{"atl":[[200,1.67]],"id":42162698},{"atl":[[7.2,22.82],[7,0]],"id":39637621},{"atl":[[15,1.43],[15.5,0]],"id":42688787}],"con":true,"img":false}]}
{"op":"mcm","clk":"5353203731","pt":1646210883342,"mc":[{"id":"1.195453766","rc":[{"atb":[[23,2.06]],"id":42162698},{"atl":[[210,0],[220,1],[65,4.72],[310,0],[330,0],[350,0]],"id":42162698},{"atl":[[7.6,7.58]],"id":39637621}],"con":true,"img":false}]}
{"op":"mcm","clk":"5353203743","pt":1646210883652,"mc":[{"id":"1.195453766","rc":[{"atl":[[8.2,0],[7.4,0],[7.8,0]],"id":39637621},{"atb":[[16,2]],"id":41910350},{"atb":[[10,3.12]],"id":43167133},{"atl":[[21,3]],"id":43167133},{"atb":[[8.4,2.19]],"id":42688787},{"atl":[[14.5,1.48],[15,0]],"id":42688787}],"con":true,"img":false}]}
{"op":"mcm","clk":"5353203752","pt":1646210883704,"mc":[{"id":"1.195453766","rc":[{"atb":[[10,1.12],[9.2,2]],"id":43167133},{"atb":[[8.2,4.96],[8.4,0.19]],"id":42688787}],"con":true,"img":false}]}
{"op":"mcm","clk":"5353203758","pt":1646210883909,"mc":[{"id":"1.195453766","rc":[{"atl":[[22,2.72]],"id":43167133}],"con":true,"img":false}]}
{"op":"mcm","clk":"5353203762","pt":1646210884016,"mc":[{"id":"1.195453766","rc":[{"atb":[[22,0]],"id":42162698},{"atb":[[10,3.12],[9.2,0]],"id":43167133},{"atl":[[20,1.29],[21,1],[22,4.72]],"id":43167133}],"con":true,"img":false}]}
{"op":"mcm","clk":"5353203777","pt":1646210884328,"mc":[{"id":"1.195453766","rc":[{"atb":[[8,1.65]],"id":42688787}],"con":true,"img":false}]}
{"op":"mcm","clk":"5353203780","pt":1646210884431,"mc":[{"id":"1.195453766","rc":[{"atl":[[7.2,3.23]],"id":39637621},{"atl":[[22,2]],"id":43167133},{"atb":[[8.2,6.23]],"id":42688787}],"con":true,"img":false}]}
{"op":"mcm","clk":"5353203784","pt":1646210884537,"mc":[{"id":"1.195453766","rc":[{"atl":[[7.4,19.59]],"id":39637621},{"atl":[[20,0],[23,4.99]],"id":43167133}],"con":true,"img":false}]}
{"op":"mcm","clk":"5353203786","pt":1646210884638,"mc":[{"id":"1.195453766","rc":[{"atl":[[21,2.29]],"id":43167133}],"con":true,"img":false}]}
{"op":"mcm","clk":"5353203806","pt":1646210885007,"mc":[{"id":"1.195453766","rc":[{"atb":[[24,1.82]],"id":42162698}],"con":true,"img":false}]}
{"op":"mcm","clk":"5353203861","pt":1646210886295,"mc":[{"id":"1.195453766","rc":[{"atl":[[100,2],[120,0]],"id":42162698},{"atb":[[5.1,24.39],[3.95,0]],"id":42688787}],"con":true,"img":false}]}
{"op":"mcm","clk":"5353203889","pt":1646210887016,"mc":[{"id":"1.195453766","rc":[{"atb":[[15,0]],"id":41910350}],"con":true,"img":false}]}
{"op":"mcm","clk":"5353203935","pt":1646210888004,"mc":[{"id":"1.195453766","rc":[{"atb":[[16.5,2.74]],"id":41910350}],"con":true,"img":false}]}
{"op":"mcm","clk":"5353204168","pt":1646210893227,"mc":[{"id":"1.195453766","rc":[{"atl":[[240,1]],"id":42162698},{"atl":[[8,10.71]],"id":39637621}],"con":true,"img":false}]}
{"op":"mcm","clk":"5353204180","pt":1646210893640,"mc":[{"id":"1.195453766","rc":[{"atl":[[15.5,3.45]],"id":42688787}],"con":true,"img":false}]}
{"op":"mcm","clk":"5353204195","pt":1646210894156,"mc":[{"id":"1.195453766","rc":[{"atl":[[16,0]],"id":42688787}],"con":true,"img":false}]}
{"op":"mcm","clk":"5353204200","pt":1646210894211,"mc":[{"id":"1.195453766","rc":[{"atl":[[15,1.29]],"id":42688787}],"con":true,"img":false}]}
{"op":"mcm","clk":"5353204581","pt":1646210902669,"mc":[{"id":"1.195453766","rc":[{"atb":[[1.2,2.25]],"id":41910350}],"con":true,"img":false}]}
{"op":"mcm","clk":"5353204592","pt":1646210902925,"mc":[{"id":"1.195453766","rc":[{"atb":[[1.2,1.69]],"id":41910350}],"con":true,"img":false}]}
{"op":"mcm","clk":"5353204600","pt":1646210903131,"mc":[{"id":"1.195453766","rc":[{"atb":[[1.2,0]],"id":41910350}],"con":true,"img":false}]}
{"op":"mcm","clk":"5353204604","pt":1646210903236,"mc":[{"id":"1.195453766","rc":[{"atl":[[260,1]],"id":42162698},{"atl":[[8.4,16.89]],"id":39637621},{"atb":[[15,1.69]],"id":41910350}],"con":true,"img":false}]}
{"op":"mcm","clk":"5353204619","pt":1646210903645,"mc":[{"id":"1.195453766","rc":[{"atl":[[16.5,4.84],[18.5,0]],"id":42688787}],"con":true,"img":false}]}
{"op":"mcm","clk":"5353204939","pt":1646210910362,"mc":[{"id":"1.195453766","rc":[{"atl":[[65,2]],"id":42162698}],"con":true,"img":false}]}
{"op":"mcm","clk":"5353204945","pt":1646210910469,"mc":[{"id":"1.195453766","rc":[{"atl":[[65,0],[90,4.72],[60,2.78]],"id":42162698}],"con":true,"img":false}]}
{"op":"mcm","clk":"5353205099","pt":1646210913665,"mc":[{"id":"1.195453766","rc":[{"atl":[[17.5,7.58]],"id":42688787}],"con":true,"img":false}]}
{"op":"mcm","clk":"5353205179","pt":1646210915679,"mc":[{"id":"1.195453766","rc":[{"atl":[[90,2.72],[60,4.78]],"id":42162698}],"con":true,"img":false}]}
{"op":"mcm","clk":"5353205185","pt":1646210915785,"mc":[{"id":"1.195453766","rc":[{"atl":[[90,4.72],[60,2.78]],"id":42162698}],"con":true,"img":false}]}
{"op":"mcm","clk":"5353205188","pt":1646210915886,"mc":[{"id":"1.195453766","rc":[{"atl":[[60,4.78]],"id":42162698}],"con":true,"img":false}]}
{"op":"mcm","clk":"5353205192","pt":1646210915991,"mc":[{"id":"1.195453766","rc":[{"atl":[[90,2.72]],"id":42162698}],"con":true,"img":false}]}
{"op":"mcm","clk":"5353207009","pt":1646210968439,"mc":[{"id":"1.195453766","rc":[{"spn":22.14,"spf":1.0,"id":42162698},{"atl":[[10.5,0]],"id":41818763},{"spn":15.84,"spf":1.0,"id":41910350},{"spn":9.54,"spf":1.0,"id":43167133},{"spn":8.21,"spf":1.0,"id":42688787}],"con":true,"img":false}]}
{"op":"mcm","clk":"5353207013","pt":1646210968541,"mc":[{"id":"1.195453766","rc":[{"atl":[[9.8,14.73]],"id":41818763}],"con":true,"img":false}]}
{"op":"mcm","clk":"5353207949","pt":1646210994693,"mc":[{"id":"1.195453766","rc":[{"atb":[[4.6,3.01]],"id":39637621}],"con":true,"img":false}]}
{"op":"mcm","clk":"5353207957","pt":1646210994905,"mc":[{"id":"1.195453766","rc":[{"atb":[[4,0],[4.1,6.68]],"id":39637621}],"con":true,"img":false}]}
{"op":"mcm","clk":"5353207981","pt":1646210995573,"mc":[{"id":"1.195453766","rc":[{"atb":[[3.95,0]],"id":39637621}],"con":true,"img":false}]}
{"op":"mcm","clk":"5353207985","pt":1646210995679,"mc":[{"id":"1.195453766","rc":[{"atb":[[4.1,7.98]],"id":39637621}],"con":true,"img":false}]}
{"op":"mcm","clk":"5353208001","pt":1646210996090,"mc":[{"id":"1.195453766","rc":[{"atb":[[4.4,0]],"id":39637621}],"con":true,"img":false}]}
{"op":"mcm","clk":"5353208273","pt":1646211004193,"mc":[{"id":"1.195453766","rc":[{"atl":[[2.44,16.55]],"id":42154339}],"con":true,"img":false}]}
{"op":"mcm","clk":"5353208515","pt":1646211011002,"mc":[{"id":"1.195453766","rc":[{"atl":[[2.44,13.83]],"id":42154339}],"con":true,"img":false}]}
{"op":"mcm","clk":"5353208521","pt":1646211011105,"mc":[{"id":"1.195453766","rc":[{"atb":[[2.42,0]],"id":42154339},{"atl":[[2.34,0.91]],"id":42154339},{"trd":[[2.42,3.62]],"ltp":2.42,"tv":3.62,"id":42154339}],"con":true,"img":false}]}
{"op":"mcm","clk":"5353208556","pt":1646211011827,"mc":[{"id":"1.195453766","rc":[{"atl":[[1000,2.25]],"id":41818763}],"con":true,"img":false}]}
{"op":"mcm","clk":"5353208749","pt":1646211017529,"mc":[{"id":"1.195453766","rc":[{"atl":[[2.34,0]],"id":42154339}],"con":true,"img":false}]}
{"op":"mcm","clk":"5353208753","pt":1646211017632,"mc":[{"id":"1.195453766","rc":[{"atb":[[2.3,0.84]],"id":42154339},{"trd":[[2.3,1.83]],"ltp":2.3,"tv":1.83,"id":42154339}],"con":true,"img":false}]}
{"op":"mcm","clk":"5353208759","pt":1646211017836,"mc":[{"id":"1.195453766","rc":[{"atb":[[4,6.02],[4.1,1.96]],"id":39637621},{"atl":[[7.4,22.71],[7.2,0]],"id":39637621},{"atl":[[2.58,63.29],[2.62,0],[2.36,14.65]],"id":42154339},{"atl":[[14.5,0],[15,2.72]],"id":42688787}],"con":true,"img":false}]}
{"op":"mcm","clk":"5353208764","pt":1646211017938,"mc":[{"id":"1.195453766","rc":[{"atl":[[2.44,0]],"id":42154339}],"con":true,"img":false}]}
{"op":"mcm","clk":"5353208780","pt":1646211018399,"mc":[{"id":"1.195453766","rc":[{"atl":[[1000,0.15]],"id":41818763}],"con":true,"img":false}]}
{"op":"mcm","clk":"5353208783","pt":1646211018502,"mc":[{"id":"1.195453766","rc":[{"atl":[[9.8,0]],"id":41818763}],"con":true,"img":false}]}
{"op":"mcm","clk":"5353208788","pt":1646211018606,"mc":[{"id":"1.195453766","rc":[{"atl":[[10.5,14.73],[1000,0]],"id":41818763}],"con":true,"img":false}]}
{"op":"mcm","clk":"5353208791","pt":1646211018708,"mc":[{"id":"1.195453766","rc":[{"atl":[[9.2,2.68]],"id":41818763}],"con":true,"img":false}]}
{"op":"mcm","clk":"5353208828","pt":1646211019735,"mc":[{"id":"1.195453766","rc":[{"atl":[[2.36,12.92]],"id":42154339},{"trd":[[2.36,3.46]],"ltp":2.36,"tv":3.46,"id":42154339}],"con":true,"img":false}]}
{"op":"mcm","clk":"5353208831","pt":1646211019838,"mc":[{"id":"1.195453766","rc":[{"atl":[[2.48,0],[2.36,0],[2.56,0],[2.42,13.88],[2.52,0]],"id":42154339}],"con":true,"img":false}]}
{"op":"mcm","clk":"5353208982","pt":1646211024211,"mc":[{"id":"1.195453766","rc":[{"atb":[[3.9,0.35]],"id":39637621}],"con":true,"img":false}]}
{"op":"mcm","clk":"5353208995","pt":1646211024521,"mc":[{"id":"1.195453766","rc":[{"atb":[[23,2]],"id":42162698},{"atb":[[3.9,0]],"id":39637621},{"atb":[[15.5,0]],"id":41910350},{"atb":[[8.4,0]],"id":42688787}],"con":true,"img":false}]}
{"op":"mcm","clk":"5353209000","pt":1646211024624,"mc":[{"id":"1.195453766","rc":[{"atb":[[25,0.06]],"id":42162698},{"atb":[[4.7,0.35]],"id":39637621},{"atb":[[17,0.1]],"id":41910350},{"atb":[[8.4,0.19]],"id":42688787}],"con":true,"img":false}]}
{"op":"mcm","clk":"5353209106","pt":1646211027829,"mc":[{"id":"1.195453766","rc":[{"atl":[[7.8,7.35]],"id":39637621},{"atl":[[16,3.33]],"id":42688787}],"con":true,"img":false}]}
{"op":"mcm","clk":"5353209192","pt":1646211029844,"mc":[{"id":"1.195453766","rc":[{"spn":22.16,"spf":1.0,"id":42162698},{"spn":5.45,"spf":"NaN","id":39637621},{"spn":15.87,"spf":1.0,"id":41910350},{"atl":[[2.46,33.75]],"id":42154339},{"spn":2.26,"spf":1.0,"id":42154339}],"con":true,"img":false}]}
{"op":"mcm","clk":"5353209207","pt":1646211030155,"mc":[{"id":"1.195453766","rc":[{"atl":[[8,0],[8.4,0],[7.6,0]],"id":39637621},{"atl":[[15.5,0],[16.5,0],[17.5,0]],"id":42688787}],"con":true,"img":false}]}
{"op":"mcm","clk":"5353209217","pt":1646211030464,"mc":[{"id":"1.195453766","rc":[{"atl":[[7.4,3.12]],"id":39637621}],"con":true,"img":false}]}
{"op":"mcm","clk":"5353209220","pt":1646211030516,"mc":[{"id":"1.195453766","rc":[{"atl":[[7.6,19.59]],"id":39637621}],"con":true,"img":false}]}
{"op":"mcm","clk":"5353209228","pt":1646211030723,"mc":[{"id":"1.195453766","rc":[{"atl":[[15,1.43]],"id":42688787}],"con":true,"img":false}]}
{"op":"mcm","clk":"5353209235","pt":1646211030826,"mc":[{"id":"1.195453766","rc":[{"atl":[[1000,1.29]],"id":42688787}],"con":true,"img":false}]}
{"op":"mcm","clk":"5353209462","pt":1646211036453,"mc":[{"id":"1.195453766","rc":[{"atl":[[17,0]],"id":42688787}],"con":true,"img":false}]}
{"op":"mcm","clk":"5353209465","pt":1646211036557,"mc":[{"id":"1.195453766","rc":[{"atl":[[18,3.34]],"id":42688787}],"con":true,"img":false}]}
{"op":"mcm","clk":"5353209512","pt":1646211037844,"mc":[{"id":"1.195453766","rc":[{"atl":[[8.2,10.42]],"id":39637621},{"atl":[[17,4.69]],"id":42688787}],"con":true,"img":false}]}
{"op":"mcm","clk":"5353209537","pt":1646211038542,"mc":[{"id":"1.195453766","rc":[{"atl":[[1000,0]],"id":42688787}],"con":true,"img":false}]}
{"op":"mcm","clk":"5353209541","pt":1646211038645,"mc":[{"id":"1.195453766","rc":[{"atl":[[15.5,1.29]],"id":42688787}],"con":true,"img":false}]}
{"op":"mcm","clk":"5353209582","pt":1646211039883,"mc":[{"id":"1.195453766","rc":[{"atl":[[2.5,49.27]],"id":42154339}],"con":true,"img":false}]}
{"op":"mcm","clk":"5353209680","pt":1646211042477,"mc":[{"id":"1.195453766","rc":[{"atl":[[23,2.27]],"id":43167133}],"con":true,"img":false}]}
{"op":"mcm","clk":"5353209685","pt":1646211042580,"mc":[{"id":"1.195453766","rc":[{"atl":[[22,4.72]],"id":43167133}],"con":true,"img":false}]}
{"op":"mcm","clk":"5353209890","pt":1646211047887,"mc":[{"id":"1.195453766","rc":[{"atl":[[8.6,16.45]],"id":39637621},{"atl":[[18,10.69]],"id":42688787}],"con":true,"img":false}]}
{"op":"mcm","clk":"5353209904","pt":1646211048455,"mc":[{"id":"1.195453766","rc":[{"atl":[[22,2]],"id":43167133}],"con":true,"img":false}]}
{"op":"mcm","clk":"5353209908","pt":1646211048559,"mc":[{"id":"1.195453766","rc":[{"atl":[[23,4.99]],"id":43167133}],"con":true,"img":false}]}
{"op":"mcm","clk":"5353209950","pt":1646211049852,"mc":[{"id":"1.195453766","rc":[{"atl":[[2.54,79.99]],"id":42154339}],"con":true,"img":false}]}
{"op":"mcm","clk":"5353210194","pt":1646211056355,"mc":[{"id":"1.195453766","rc":[{"atl":[[9.4,0]],"id":41818763}],"con":true,"img":false}]}
{"op":"mcm","clk":"5353210198","pt":1646211056458,"mc":[{"id":"1.195453766","rc":[{"atl":[[9.8,6.65]],"id":41818763}],"con":true,"img":false}]}
{"op":"mcm","clk":"5353210206","pt":1646211056766,"mc":[{"id":"1.195453766","rc":[{"atl":[[9.2,1.51]],"id":41818763}],"con":true,"img":false}]}
{"op":"mcm","clk":"5353210209","pt":1646211056868,"mc":[{"id":"1.195453766","rc":[{"atl":[[9.6,3.49]],"id":41818763}],"con":true,"img":false}]}
{"op":"mcm","clk":"5353210216","pt":1646211057178,"mc":[{"id":"1.195453766","rc":[{"atl":[[9.2,0]],"id":41818763}],"con":true,"img":false}]}
{"op":"mcm","clk":"5353210219","pt":1646211057282,"mc":[{"id":"1.195453766","rc":[{"atl":[[9.4,1.36],[9.6,3.64]],"id":41818763}],"con":true,"img":false}]}
{"op":"mcm","clk":"5353210253","pt":1646211058367,"mc":[{"id":"1.195453766","rc":[{"atl":[[18,7.35]],"id":42688787}],"con":true,"img":false}]}
{"op":"mcm","clk":"5353210258","pt":1646211058470,"mc":[{"id":"1.195453766","rc":[{"atl":[[16.5,3.34]],"id":42688787}],"con":true,"img":false}]}
{"op":"mcm","clk":"5353210670","pt":1646211068516,"mc":[{"id":"1.195453766","rc":[{"atl":[[6.4,0]],"id":39637621}],"con":true,"img":false}]}
{"op":"mcm","clk":"5353210675","pt":1646211068623,"mc":[{"id":"1.195453766","rc":[{"atl":[[6.6,10.84]],"id":39637621}],"con":true,"img":false}]}
{"op":"mcm","clk":"5353210688","pt":1646211068829,"mc":[{"id":"1.195453766","rc":[{"atl":[[6.2,0]],"id":39637621}],"con":true,"img":false}]}
{"op":"mcm","clk":"5353210694","pt":1646211068880,"mc":[{"id":"1.195453766","rc":[{"atl":[[7.2,1.27]],"id":39637621}],"con":true,"img":false}]}
{"op":"mcm","clk":"5353210721","pt":1646211069398,"mc":[{"id":"1.195453766","rc":[{"atl":[[7.2,0]],"id":39637621}],"con":true,"img":false}]}
{"op":"mcm","clk":"5353210724","pt":1646211069501,"mc":[{"id":"1.195453766","rc":[{"atl":[[6.4,1.27]],"id":39637621}],"con":true,"img":false}]}
{"op":"mcm","clk":"5353210762","pt":1646211070428,"mc":[{"id":"1.195453766","rc":[{"atb":[[4.7,2.86]],"id":39637621}],"con":true,"img":false}]}
{"op":"mcm","clk":"5353210920","pt":1646211073836,"mc":[{"id":"1.195453766","rc":[{"atb":[[1.82,0]],"id":39637621}],"con":true,"img":false}]}
{"op":"mcm","clk":"5353211568","pt":1646211088355,"mc":[{"id":"1.195453766","rc":[{"atb":[[24,1.67],[1.05,2.25]],"id":42162698}],"con":true,"img":false}]}
{"op":"mcm","clk":"5353211576","pt":1646211088560,"mc":[{"id":"1.195453766","rc":[{"atb":[[1.05,0.14]],"id":42162698},{"atl":[[2.36,14.49]],"id":42154339}],"con":true,"img":false}]}
{"op":"mcm","clk":"5353211581","pt":1646211088612,"mc":[{"id":"1.195453766","rc":[{"atl":[[2.42,0]],"id":42154339}],"con":true,"img":false}]}
{"op":"mcm","clk":"5353211589","pt":1646211088818,"mc":[{"id":"1.195453766","rc":[{"atb":[[1.05,0]],"id":42162698}],"con":true,"img":false}]}
{"op":"mcm","clk":"5353211595","pt":1646211088920,"mc":[{"id":"1.195453766","rc":[{"atb":[[26,0.14]],"id":42162698}],"con":true,"img":false}]}
{"op":"mcm","clk":"5353211599","pt":1646211089023,"mc":[{"id":"1.195453766","rc":[{"atb":[[23,0],[25,2.06]],"id":42162698}],"con":true,"img":false}]}
{"op":"mcm","clk":"5353211604","pt":1646211089128,"mc":[{"id":"1.195453766","rc":[{"atb":[[25,0.06]],"id":42162698}],"con":true,"img":false}]}
{"op":"mcm","clk":"5353211608","pt":1646211089229,"mc":[{"id":"1.195453766","rc":[{"atb":[[24,3.67]],"id":42162698}],"con":true,"img":false}]}
{"op":"mcm","clk":"5353211652","pt":1646211090310,"mc":[{"id":"1.195453766","rc":[{"spn":22.48,"spf":1.0,"id":42162698},{"spn":5.55,"spf":"NaN","id":39637621},{"atl":[[9.8,0]],"id":41818763}],"con":true,"img":false}]}
{"op":"mcm","clk":"5353211656","pt":1646211090412,"mc":[{"id":"1.195453766","rc":[{"atl":[[9.4,8.01]],"id":41818763}],"con":true,"img":false}]}
{"op":"mcm","clk":"5353211671","pt":1646211090727,"mc":[{"id":"1.195453766","rc":[{"atl":[[9.6,2.48]],"id":41818763}],"con":true,"img":false}]}
{"op":"mcm","clk":"5353211677","pt":1646211090830,"mc":[{"id":"1.195453766","rc":[{"atl":[[9.2,1.16],[9.6,2.33]],"id":41818763}],"con":true,"img":false}]}
{"op":"mcm","clk":"5353211680","pt":1646211090934,"mc":[{"id":"1.195453766","rc":[{"atl":[[9.4,8.16]],"id":41818763}],"con":true,"img":false}]}
{"op":"mcm","clk":"5353211979","pt":1646211098530,"mc":[{"id":"1.195453766","rc":[{"atl":[[2.4,35.2]],"id":42154339}],"con":true,"img":false}]}
{"op":"mcm","clk":"5353211990","pt":1646211098737,"mc":[{"id":"1.195453766","rc":[{"atl":[[2.54,0],[2.5,0],[2.46,0]],"id":42154339}],"con":true,"img":false}]}
{"op":"mcm","clk":"5353212321","pt":1646211108540,"mc":[{"id":"1.195453766","rc":[{"atl":[[2.44,51.33]],"id":42154339}],"con":true,"img":false}]}
{"op":"mcm","clk":"5353212649","pt":1646211118605,"mc":[{"id":"1.195453766","rc":[{"atl":[[2.48,83.23]],"id":42154339}],"con":true,"img":false}]}
{"op":"mcm","clk":"5353212700","pt":1646211120088,"mc":[{"id":"1.195453766","rc":[{"atl":[[10,0],[10.5,16.84],[9.6,0]],"id":41818763}],"con":true,"img":false}]}
{"op":"mcm","clk":"5353212702","pt":1646211120187,"mc":[{"id":"1.195453766","rc":[{"atb":[[3.3,8.7],[3.4,0]],"id":39637621},{"atb":[[6.4,0],[6.2,3.85]],"id":42688787}],"con":true,"img":false}]}
{"op":"mcm","clk":"5353212717","pt":1646211120602,"mc":[{"id":"1.195453766","rc":[{"atl":[[9.4,1.51]],"id":41818763}],"con":true,"img":false}]}
{"op":"mcm","clk":"5353212722","pt":1646211120701,"mc":[{"id":"1.195453766","rc":[{"atl":[[10,6.65]],"id":41818763}],"con":true,"img":false}]}
{"op":"mcm","clk":"5353212736","pt":1646211121008,"mc":[{"id":"1.195453766","rc":[{"atl":[[9.2,0]],"id":41818763}],"con":true,"img":false}]}
{"op":"mcm","clk":"5353212741","pt":1646211121062,"mc":[{"id":"1.195453766","rc":[{"atl":[[9.4,0.15],[9.8,1.16]],"id":41818763}],"con":true,"img":false}]}
{"op":"mcm","clk":"5353212746","pt":1646211121164,"mc":[{"id":"1.195453766","rc":[{"atl":[[9.8,2.53]],"id":41818763}],"con":true,"img":false}]}
{"op":"mcm","clk":"5353212752","pt":1646211121374,"mc":[{"id":"1.195453766","rc":[{"atl":[[9.4,0]],"id":41818763}],"con":true,"img":false}]}
{"op":"mcm","clk":"5353212757","pt":1646211121474,"mc":[{"id":"1.195453766","rc":[{"atl":[[10,6.8]],"id":41818763}],"con":true,"img":false}]}
{"op":"mcm","clk":"5353212779","pt":1646211121990,"mc":[{"id":"1.195453766","rc":[{"atl":[[10,6.65]],"id":41818763}],"con":true,"img":false}]}
{"op":"mcm","clk":"5353212785","pt":1646211122091,"mc":[{"id":"1.195453766","rc":[{"atl":[[9.8,2.68]],"id":41818763}],"con":true,"img":false}]}
{"op":"mcm","clk":"5353213071","pt":1646211130098,"mc":[{"id":"1.195453766","rc":[{"atl":[[11.5,4.76]],"id":41818763}],"con":true,"img":false}]}
{"op":"mcm","clk":"5353213076","pt":1646211130200,"mc":[{"id":"1.195453766","rc":[{"atb":[[3.2,69.67]],"id":39637621},{"atb":[[5.9,10.2]],"id":42688787}],"con":true,"img":false}]}
{"op":"mcm","clk":"5353213416","pt":1646211140111,"mc":[{"id":"1.195453766","rc":[{"atl":[[12.5,15.22]],"id":41818763},{"atb":[[5.8,21.51],[5.6,0],[6,0],[5.7,15.96]],"id":42688787}],"con":true,"img":false}]}
{"op":"mcm","clk":"5353213422","pt":1646211140212,"mc":[{"id":"1.195453766","rc":[{"atb":[[3.1,35.71]],"id":39637621}],"con":true,"img":false}]}
{"op":"mcm","clk":"5353213741","pt":1646211150236,"mc":[{"id":"1.195453766","rc":[{"atb":[[3,62.5]],"id":39637621},{"atl":[[13.5,10]],"id":41818763},{"atb":[[5.5,27.78]],"id":42688787}],"con":true,"img":false}]}
{"op":"mcm","clk":"5353213745","pt":1646211150339,"mc":[{"id":"1.195453766","rc":[{"atl":[[11,0],[12,0]],"id":41818763}],"con":true,"img":false}]}
{"op":"mcm","clk":"5353213815","pt":1646211152397,"mc":[{"id":"1.195453766","rc":[{"atl":[[10.5,2.11]],"id":41818763}],"con":true,"img":false}]}
{"op":"mcm","clk":"5353213819","pt":1646211152499,"mc":[{"id":"1.195453766","rc":[{"atl":[[11,14.73]],"id":41818763}],"con":true,"img":false}]}
{"op":"mcm","clk":"5353213968","pt":1646211156615,"mc":[{"id":"1.195453766","rc":[{"atl":[[20,1.24]],"id":43167133}],"con":true,"img":false}]}
{"op":"mcm","clk":"5353213972","pt":1646211156719,"mc":[{"id":"1.195453766","rc":[{"atl":[[15,2.67]],"id":42688787}],"con":true,"img":false}]}
{"op":"mcm","clk":"5353213976","pt":1646211156821,"mc":[{"id":"1.195453766","rc":[{"atl":[[55,1.24]],"id":42162698},{"atl":[[1000,1.24]],"id":39637621},{"atl":[[1000,1.24]],"id":41818763},{"atl":[[44,1.24]],"id":41910350}],"con":true,"img":false}]}
{"op":"mcm","clk":"5353213986","pt":1646211157026,"mc":[{"id":"1.195453766","rc":[{"atl":[[1000,0]],"id":39637621},{"atl":[[1000,0]],"id":41818763}],"con":true,"img":false}]}
{"op":"mcm","clk":"5353213991","pt":1646211157130,"mc":[{"id":"1.195453766","rc":[{"atl":[[6.4,2.52]],"id":39637621},{"atl":[[8,2.8]],"id":41818763}],"con":true,"img":false}]}
{"op":"mcm","clk":"5353213999","pt":1646211157335,"mc":[{"id":"1.195453766","rc":[{"atl":[[15.5,0]],"id":42688787}],"con":true,"img":false}]}
{"op":"mcm","clk":"5353214006","pt":1646211157440,"mc":[{"id":"1.195453766","rc":[{"atl":[[14.5,1.29]],"id":42688787}],"con":true,"img":false}]}
{"op":"mcm","clk":"5353214035","pt":1646211158263,"mc":[{"id":"1.195453766","rc":[{"atl":[[8.2,0]],"id":41818763}],"con":true,"img":false}]}
{"op":"mcm","clk":"5353214039","pt":1646211158315,"mc":[{"id":"1.195453766","rc":[{"atl":[[7.8,1.51]],"id":41818763}],"con":true,"img":false}]}
{"op":"mcm","clk":"5353214125","pt":1646211160336,"mc":[{"id":"1.195453766","rc":[{"atl":[[9,0]],"id":41818763},{"atl":[[46,0]],"id":41910350}],"con":true,"img":false}]}
{"op":"mcm","clk":"5353214132","pt":1646211160438,"mc":[{"id":"1.195453766","rc":[{"atl":[[48,2.72]],"id":41910350}],"con":true,"img":false}]}
{"op":"mcm","clk":"5353214139","pt":1646211160541,"mc":[{"id":"1.195453766","rc":[{"atl":[[1000,2.25]],"id":41818763}],"con":true,"img":false}]}
{"op":"mcm","clk":"5353214144","pt":1646211160644,"mc":[{"id":"1.195453766","rc":[{"atl":[[1000,1.3]],"id":41818763}],"con":true,"img":false}]}
{"op":"mcm","clk":"5353214151","pt":1646211160747,"mc":[{"id":"1.195453766","rc":[{"atl":[[1000,0]],"id":41818763}],"con":true,"img":false}]}
{"op":"mcm","clk":"5353214157","pt":1646211160849,"mc":[{"id":"1.195453766","rc":[{"atl":[[7.8,2.82]],"id":41818763}],"con":true,"img":false}]}
{"op":"mcm","clk":"5353214179","pt":1646211161416,"mc":[{"id":"1.195453766","rc":[{"atl":[[9.8,1.31]],"id":41818763}],"con":true,"img":false}]}
{"op":"mcm","clk":"5353214187","pt":1646211161520,"mc":[{"id":"1.195453766","rc":[{"atl":[[7.6,1.36]],"id":41818763}],"con":true,"img":false}]}
{"op":"mcm","clk":"5353214211","pt":1646211162031,"mc":[{"id":"1.195453766","rc":[{"atl":[[7.8,1.3]],"id":41818763}],"con":true,"img":false}]}
{"op":"mcm","clk":"5353214218","pt":1646211162136,"mc":[{"id":"1.195453766","rc":[{"atl":[[7.4,1.51]],"id":41818763}],"con":true,"img":false}]}
{"op":"mcm","clk":"5353214239","pt":1646211162750,"mc":[{"id":"1.195453766","rc":[{"atl":[[7.6,0]],"id":41818763}],"con":true,"img":false}]}
{"op":"mcm","clk":"5353214246","pt":1646211162854,"mc":[{"id":"1.195453766","rc":[{"atb":[[3.3,0],[3.4,8.33]],"id":39637621},{"atl":[[1000,1.36]],"id":41818763},{"atl":[[2.44,0],[2.36,0],[2.4,0],[2.46,13.5]],"id":42154339},{"atb":[[6.4,3.7],[6.2,0]],"id":42688787}],"con":true,"img":false}]}
{"op":"mcm","clk":"5353214253","pt":1646211162956,"mc":[{"id":"1.195453766","rc":[{"atl":[[2.6,68.96],[2.58,0]],"id":42154339}],"con":true,"img":false}]}
{"op":"mcm","clk":"5353214290","pt":1646211163724,"mc":[{"id":"1.195453766","rc":[{"atb":[[15,0]],"id":41910350}],"con":true,"img":false}]}
{"op":"mcm","clk":"5353214405","pt":1646211167173,"mc":[{"id":"1.195453766","rc":[{"atb":[[3.3,8.7],[3.4,0]],"id":39637621},{"atl":[[2.36,14.49]],"id":42154339},{"atb":[[6.4,0],[6.2,3.85]],"id":42688787}],"con":true,"img":false}]}
{"op":"mcm","clk":"5353214439","pt":1646211167839,"mc":[{"id":"1.195453766","rc":[{"atb":[[1.2,2.25]],"id":41910350}],"con":true,"img":false}]}
{"op":"mcm","clk":"5353214453","pt":1646211168148,"mc":[{"id":"1.195453766","rc":[{"atb":[[1.2,1.69]],"id":41910350}],"con":true,"img":false}]}
{"op":"mcm","clk":"5353214465","pt":1646211168455,"mc":[{"id":"1.195453766","rc":[{"atb":[[1.2,0]],"id":41910350}],"con":true,"img":false}]}
{"op":"mcm","clk":"5353214472","pt":1646211168559,"mc":[{"id":"1.195453766","rc":[{"atb":[[15,1.69]],"id":41910350}],"con":true,"img":false}]}
{"op":"mcm","clk":"5353214803","pt":1646211177164,"mc":[{"id":"1.195453766","rc":[{"atl":[[2.4,35.2]],"id":42154339}],"con":true,"img":false}]}
{"op":"mcm","clk":"5353214951","pt":1646211181484,"mc":[{"id":"1.195453766","rc":[{"atl":[[5.6,3]],"id":39637621},{"atb":[[6.4,3]],"id":41818763},{"atl":[[9.8,2]],"id":42688787}],"con":true,"img":false}]}
{"op":"mcm","clk":"5353215000","pt":1646211182564,"mc":[{"id":"1.195453766","rc":[{"atb":[[8,0]],"id":42688787}],"con":true,"img":false}]}
{"op":"mcm","clk":"5353215006","pt":1646211182668,"mc":[{"id":"1.195453766","rc":[{"atb":[[4.7,0.35]],"id":39637621},{"atb":[[1.01,1.65],[8.2,3.72]],"id":42688787}],"con":true,"img":false}]}
{"op":"mcm","clk":"5353215015","pt":1646211182880,"mc":[{"id":"1.195453766","rc":[{"atb":[[4,0],[4.1,7.98]],"id":39637621},{"atl":[[7.4,0],[5.6,0],[7.2,3.23],[5.5,2]],"id":39637621},{"atb":[[6.6,4]],"id":41818763},{"atl":[[14.5,2.77],[15,1.24],[9.6,3]],"id":42688787}],"con":true,"img":false}]}
{"op":"mcm","clk":"5353215035","pt":1646211183286,"mc":[{"id":"1.195453766","rc":[{"atb":[[8.2,2.45]],"id":42688787}],"con":true,"img":false}]}
{"op":"mcm","clk":"5353215038","pt":1646211183390,"mc":[{"id":"1.195453766","rc":[{"atb":[[1.02,1.26]],"id":42688787}],"con":true,"img":false}]}
{"op":"mcm","clk":"5353215093","pt":1646211184278,"mc":[{"id":"1.195453766","rc":[{"atb":[[10.5,2.6]],"id":43167133}],"con":true,"img":false}]}
{"op":"mcm","clk":"5353215096","pt":1646211184383,"mc":[{"id":"1.195453766","rc":[{"atb":[[3.75,3.67]],"id":39637621}],"con":true,"img":false}]}
{"op":"mcm","clk":"5353215180","pt":1646211186128,"mc":[{"id":"1.195453766","rc":[{"atb":[[3.3,0],[3.4,8.33]],"id":39637621},{"atl":[[5.5,0]],"id":39637621},{"atb":[[6.8,4]],"id":41818763},{"atb":[[1.65,3]],"id":42154339},{"atl":[[2.36,0],[2.4,0]],"id":42154339},{"atb":[[6.4,3.7],[6.2,0]],"id":42688787},{"atl":[[9.6,0],[9.8,0]],"id":42688787}],"con":true,"img":false}]}
{"op":"mcm","clk":"5353215195","pt":1646211186291,"mc":[{"id":"1.195453766","rc":[{"atb":[[7,2]],"id":41818763},{"atb":[[1.57,4],[1.65,0]],"id":42154339},{"atb":[[7.4,2]],"id":42688787},{"atl":[[14.5,1.29],[15,2.67]],"id":42688787}],"con":true,"img":false}]}
{"op":"mcm","clk":"5353215212","pt":1646211186700,"mc":[{"id":"1.195453766","rc":[{"atl":[[6.2,2.5]],"id":39637621}],"con":true,"img":false}]}
{"op":"mcm","clk":"5353215226","pt":1646211187009,"mc":[{"id":"1.195453766","rc":[{"atl":[[8,1.56]],"id":41818763}],"con":true,"img":false}]}
{"op":"mcm","clk":"5353215236","pt":1646211187222,"mc":[{"id":"1.195453766","rc":[{"atl":[[2.5,32.85]],"id":42154339}],"con":true,"img":false}]}
{"op":"mcm","clk":"5353215240","pt":1646211187316,"mc":[{"id":"1.195453766","rc":[{"atl":[[6.4,1.24]],"id":39637621},{"atl":[[1000,0]],"id":41818763}],"con":true,"img":false}]}
{"op":"mcm","clk":"5353215244","pt":1646211187421,"mc":[{"id":"1.195453766","rc":[{"atl":[[6,1.27]],"id":39637621},{"atl":[[9.8,2.68]],"id":41818763}],"con":true,"img":false}]}
{"op":"mcm","clk":"5353215263","pt":1646211188089,"mc":[{"id":"1.195453766","rc":[{"atl":[[6.2,0]],"id":39637621}],"con":true,"img":false}]}
{"op":"mcm","clk":"5353215286","pt":1646211188605,"mc":[{"id":"1.195453766","rc":[{"atl":[[6,0]],"id":39637621}],"con":true,"img":false}]}
{"op":"mcm","clk":"5353215290","pt":1646211188713,"mc":[{"id":"1.195453766","rc":[{"atl":[[6.4,2.52]],"id":39637621}],"con":true,"img":false}]}
{"op":"mcm","clk":"5353215305","pt":1646211189023,"mc":[{"id":"1.195453766","rc":[{"atl":[[7.4,3.12],[7.2,0]],"id":39637621},{"atb":[[1.58,4],[1.57,0]],"id":42154339},{"atl":[[2.6,6.46],[2.58,63.29]],"id":42154339},{"atb":[[7.4,0],[7.6,18.64]],"id":42688787},{"atl":[[14.5,2.77],[15,1.24]],"id":42688787}],"con":true,"img":false}]}
{"op":"mcm","clk":"5353215342","pt":1646211189802,"mc":[{"id":"1.195453766","rc":[{"atl":[[14.5,1.48]],"id":42688787}],"con":true,"img":false}]}
{"op":"mcm","clk":"5353215345","pt":1646211189909,"mc":[{"id":"1.195453766","rc":[{"atl":[[15.5,1.29]],"id":42688787}],"con":true,"img":false}]}
{"op":"mcm","clk":"5353215367","pt":1646211190421,"mc":[{"id":"1.195453766","rc":[{"atb":[[5,3.01]],"id":39637621}],"con":true,"img":false}]}
{"op":"mcm","clk":"5353215374","pt":1646211190623,"mc":[{"id":"1.195453766","rc":[{"atl":[[6.2,2.5]],"id":39637621}],"con":true,"img":false}]}
{"op":"mcm","clk":"5353215449","pt":1646211192219,"mc":[{"id":"1.195453766","rc":[{"atl":[[6.2,0]],"id":39637621}],"con":true,"img":false}]}
{"op":"mcm","clk":"5353215626","pt":1646211197207,"mc":[{"id":"1.195453766","rc":[{"atl":[[2.54,47.99]],"id":42154339}],"con":true,"img":false}]}
{"op":"mcm","clk":"5353215632","pt":1646211197434,"mc":[{"id":"1.195453766","rc":[{"atb":[[1.58,0],[1.65,3]],"id":42154339},{"atb":[[7.6,15.64]],"id":42688787}],"con":true,"img":false}]}
{"op":"mcm","clk":"5353215658","pt":1646211198023,"mc":[{"id":"1.195453766","rc":[{"atb":[[8.8,8.54]],"id":43167133}],"con":true,"img":false}]}
{"op":"mcm","clk":"5353215663","pt":1646211198128,"mc":[{"id":"1.195453766","rc":[{"atb":[[8,16.37]],"id":43167133}],"con":true,"img":false}]}
{"op":"mcm","clk":"5353215697","pt":1646211199000,"mc":[{"id":"1.195453766","rc":[{"atb":[[3.3,21.74]],"id":39637621}],"con":true,"img":false}]}
{"op":"mcm","clk":"5353215824","pt":1646211202337,"mc":[{"id":"1.195453766","rc":[{"atl":[[6.4,1.27]],"id":39637621}],"con":true,"img":false}]}
{"op":"mcm","clk":"5353215847","pt":1646211202904,"mc":[{"id":"1.195453766","rc":[{"atb":[[1.02,0]],"id":42688787}],"con":true,"img":false}]}
{"op":"mcm","clk":"5353215855","pt":1646211203010,"mc":[{"id":"1.195453766","rc":[{"atb":[[8,1.26]],"id":42688787}],"con":true,"img":false}]}
{"op":"mcm","clk":"5353215943","pt":1646211205216,"mc":[{"id":"1.195453766","rc":[{"atb":[[5,0]],"id":39637621},{"trd":[[5,6.02]],"ltp":5.0,"tv":6.02,"id":39637621},{"atb":[[7,0]],"id":41818763},{"trd":[[7,3.99]],"ltp":7.0,"tv":3.99,"id":41818763}],"con":true,"img":false}]}
{"op":"mcm","clk":"5353215954","pt":1646211205422,"mc":[{"id":"1.195453766","rc":[{"atb":[[6.4,0],[6.8,0],[6.6,0]],"id":41818763}],"con":true,"img":false}]}
{"op":"mcm","clk":"5353215962","pt":1646211205521,"mc":[{"id":"1.195453766","rc":[{"atb":[[4.5,79.43],[4.4,42.57]],"id":41818763}],"con":true,"img":false}]}
{"op":"mcm","clk":"5353216018","pt":1646211206914,"mc":[{"id":"1.195453766","rc":[{"atb":[[4.7,2.86]],"id":39637621},{"atb":[[8.4,2.69]],"id":42688787}],"con":true,"img":false}]}
{"op":"mcm","clk":"5353216029","pt":1646211207223,"mc":[{"id":"1.195453766","rc":[{"atl":[[2.58,141.26]],"id":42154339}],"con":true,"img":false}]}
{"op":"mcm","clk":"5353216039","pt":1646211207530,"mc":[{"id":"1.195453766","rc":[{"atb":[[4.3,74.38]],"id":41818763},{"atb":[[1.66,3]],"id":42154339}],"con":true,"img":false}]}
{"op":"mcm","clk":"5353216043","pt":1646211207634,"mc":[{"id":"1.195453766","rc":[{"atb":[[4.3,36.49]],"id":41818763}],"con":true,"img":false}]}
{"op":"mcm","clk":"5353216048","pt":1646211207736,"mc":[{"id":"1.195453766","rc":[{"atb":[[3.85,6.02],[3,0],[4.1,1.96]],"id":39637621},{"atl":[[7.4,0],[6.8,3.45]],"id":39637621},{"atb":[[4.5,50.86],[4.2,31.25]],"id":41818763},{"atl":[[10.5,0],[9.6,2.33]],"id":41818763},{"atb":[[1.67,3]],"id":42154339},{"atl":[[2.48,0]],"id":42154339},{"atl":[[14.5,0],[15,2.67]],"id":42688787}],"con":true,"img":false}]}
{"op":"mcm","clk":"5353216073","pt":1646211208403,"mc":[{"id":"1.195453766","rc":[{"atl":[[9.8,1.31]],"id":41818763},{"atl":[[15.5,0]],"id":42688787}],"con":true,"img":false}]}
{"op":"mcm","clk":"5353216076","pt":1646211208506,"mc":[{"id":"1.195453766","rc":[{"atb":[[4.1,0.66]],"id":39637621},{"atl":[[9.6,3.69]],"id":41818763},{"atl":[[14.5,1.29]],"id":42688787}],"con":true,"img":false}]}
{"op":"mcm","clk":"5353216081","pt":1646211208612,"mc":[{"id":"1.195453766","rc":[{"atb":[[3.85,7.31]],"id":39637621}],"con":true,"img":false}]}
{"op":"mcm","clk":"5353216090","pt":1646211208815,"mc":[{"id":"1.195453766","rc":[{"atl":[[9.8,0.15]],"id":41818763}],"con":true,"img":false}]}
{"op":"mcm","clk":"5353216098","pt":1646211208926,"mc":[{"id":"1.195453766","rc":[{"atl":[[9.6,4.86]],"id":41818763}],"con":true,"img":false}]}
{"op":"mcm","clk":"5353216115","pt":1646211209230,"mc":[{"id":"1.195453766","rc":[{"atl":[[9.8,0]],"id":41818763}],"con":true,"img":false}]}
{"op":"mcm","clk":"5353216124","pt":1646211209332,"mc":[{"id":"1.195453766","rc":[{"atl":[[9.6,5.01]],"id":41818763}],"con":true,"img":false}]}
{"op":"mcm","clk":"5353216168","pt":1646211210415,"mc":[{"id":"1.195453766","rc":[{"atl":[[11,0]],"id":41818763},{"spn":6.25,"spf":"NaN","id":41818763},{"spn":10.03,"spf":1.0,"id":43167133},{"spn":8.24,"spf":1.0,"id":42688787}],"con":true,"img":false}]}
{"op":"mcm","clk":"5353216188","pt":1646211210925,"mc":[{"id":"1.195453766","rc":[{"atl":[[9.6,4.86]],"id":41818763}],"con":true,"img":false}]}
{"op":"mcm","clk":"5353216196","pt":1646211211028,"mc":[{"id":"1.195453766","rc":[{"atl":[[990,0.15]],"id":41818763}],"con":true,"img":false}]}
{"op":"mcm","clk":"5353216271","pt":1646211212418,"mc":[{"id":"1.195453766","rc":[{"atb":[[4.6,0]],"id":39637621}],"con":true,"img":false}]}
{"op":"mcm","clk":"5353216277","pt":1646211212523,"mc":[{"id":"1.195453766","rc":[{"atb":[[4.9,3.01]],"id":39637621}],"con":true,"img":false}]}
{"op":"mcm","clk":"5353216316","pt":1646211213451,"mc":[{"id":"1.195453766","rc":[{"atb":[[4.7,0.35]],"id":39637621}],"con":true,"img":false}]}
{"op":"mcm","clk":"5353216332","pt":1646211213755,"mc":[{"id":"1.195453766","rc":[{"atb":[[1.68,2]],"id":42154339}],"con":true,"img":false}]}
{"op":"mcm","clk":"5353216460","pt":1646211216238,"mc":[{"id":"1.195453766","rc":[{"atb":[[4.9,0]],"id":39637621}],"con":true,"img":false}]}
{"op":"mcm","clk":"5353216466","pt":1646211216386,"mc":[{"id":"1.195453766","rc":[{"atb":[[4.7,3.36]],"id":39637621}],"con":true,"img":false}]}
{"op":"mcm","clk":"5353216471","pt":1646211216445,"mc":[{"id":"1.195453766","rc":[{"atl":[[10,0]],"id":41818763}],"con":true,"img":false}]}
{"op":"mcm","clk":"5353216475","pt":1646211216547,"mc":[{"id":"1.195453766","rc":[{"atl":[[9.8,6.65]],"id":41818763}],"con":true,"img":false}]}
{"op":"mcm","clk":"5353216514","pt":1646211217466,"mc":[{"id":"1.195453766","rc":[{"atl":[[1000,1.24]],"id":41818763}],"con":true,"img":false}]}
{"op":"mcm","clk":"5353216527","pt":1646211217729,"mc":[{"id":"1.195453766","rc":[{"atb":[[3.2,81.03]],"id":39637621},{"atl":[[7.2,8.06]],"id":39637621},{"atl":[[10,5.56],[1000,0]],"id":41818763}],"con":true,"img":false}]}
{"op":"mcm","clk":"5353216534","pt":1646211217830,"mc":[{"id":"1.195453766","rc":[{"atl":[[7.6,1.24]],"id":41818763}],"con":true,"img":false}]}
{"op":"mcm","clk":"5353216548","pt":1646211218141,"mc":[{"id":"1.195453766","rc":[{"atl":[[4.8,3.01]],"id":39637621}],"con":true,"img":false}]}
{"op":"mcm","clk":"5353216565","pt":1646211218447,"mc":[{"id":"1.195453766","rc":[{"atl":[[990,0]],"id":41818763}],"con":true,"img":false}]}
{"op":"mcm","clk":"5353216569","pt":1646211218552,"mc":[{"id":"1.195453766","rc":[{"atl":[[9.6,5.01]],"id":41818763}],"con":true,"img":false}]}
{"op":"mcm","clk":"5353216579","pt":1646211218758,"mc":[{"id":"1.195453766","rc":[{"atl":[[6.8,0],[7.2,0],[6.6,14.41]],"id":39637621},{"atb":[[1.68,0],[1.67,0],[1.66,0],[1.65,0]],"id":42154339},{"atl":[[2.36,14.49],[2.46,0]],"id":42154339}],"con":true,"img":false}]}
{"op":"mcm","clk":"5353216585","pt":1646211218862,"mc":[{"id":"1.195453766","rc":[{"atb":[[3.85,6.02]],"id":39637621},{"atl":[[11.5,0],[12.5,8.7],[13.5,0]],"id":41818763},{"atl":[[2.58,77.97],[2.62,61.73]],"id":42154339}],"con":true,"img":false}]}
{"op":"mcm","clk":"5353216590","pt":1646211218963,"mc":[{"id":"1.195453766","rc":[{"atb":[[3.8,0],[1.02,1.29]],"id":39637621}],"con":true,"img":false}]}
{"op":"mcm","clk":"5353216594","pt":1646211219060,"mc":[{"id":"1.195453766","rc":[{"atb":[[1.01,1.68]],"id":39637621}],"con":true,"img":false}]}
{"op":"mcm","clk":"5353216616","pt":1646211219528,"mc":[{"id":"1.195453766","rc":[{"atb":[[4.7,0.35]],"id":39637621}],"con":true,"img":false}]}
{"op":"mcm","clk":"5353216623","pt":1646211219633,"mc":[{"id":"1.195453766","rc":[{"atl":[[9.6,4.86]],"id":41818763}],"con":true,"img":false}]}
{"op":"mcm","clk":"5353216629","pt":1646211219735,"mc":[{"id":"1.195453766","rc":[{"atl":[[990,0.15]],"id":41818763}],"con":true,"img":false}]}
{"op":"mcm","clk":"5353216640","pt":1646211220044,"mc":[{"id":"1.195453766","rc":[{"atl":[[4.8,0]],"id":39637621}],"con":true,"img":false}]}
{"op":"mcm","clk":"5353216671","pt":1646211220869,"mc":[{"id":"1.195453766","rc":[{"atb":[[1.02,0]],"id":39637621}],"con":true,"img":false}]}
{"op":"mcm","clk":"5353216678","pt":1646211220964,"mc":[{"id":"1.195453766","rc":[{"atb":[[3.85,7.31],[4.7,3.36]],"id":39637621}],"con":true,"img":false}]}
{"op":"mcm","clk":"5353216930","pt":1646211227761,"mc":[{"id":"1.195453766","rc":[{"atl":[[11,7.5]],"id":41818763}],"con":true,"img":false}]}
{"op":"mcm","clk":"5353216942","pt":1646211227964,"mc":[{"id":"1.195453766","rc":[{"atl":[[6.8,3.45],[6.6,10.84]],"id":39637621},{"atb":[[1.65,2]],"id":42154339},{"atl":[[2.36,0],[2.46,13.5]],"id":42154339}],"con":true,"img":false}]}
{"op":"mcm","clk":"5353216947","pt":1646211228065,"mc":[{"id":"1.195453766","rc":[{"atl":[[2.6,68.96]],"id":42154339}],"con":true,"img":false}]}
{"op":"mcm","clk":"5353216950","pt":1646211228168,"mc":[{"id":"1.195453766","rc":[{"atl":[[2.62,0]],"id":42154339}],"con":true,"img":false}]}
{"op":"mcm","clk":"5353216961","pt":1646211228379,"mc":[{"id":"1.195453766","rc":[{"atl":[[990,0],[9.8,21.39]],"id":41818763}],"con":true,"img":false}]}
{"op":"mcm","clk":"5353216965","pt":1646211228471,"mc":[{"id":"1.195453766","rc":[{"atl":[[9.6,5.01]],"id":41818763}],"con":true,"img":false}]}
{"op":"mcm","clk":"5353217200","pt":1646211235194,"mc":[{"id":"1.195453766","rc":[{"atb":[[2.26,6.68]],"id":42154339}],"con":true,"img":false}]}
{"op":"mcm","clk":"5353217210","pt":1646211235351,"mc":[{"id":"1.195453766","rc":[{"atb":[[1.66,3]],"id":42154339}],"con":true,"img":false}]}
{"op":"mcm","clk":"5353217226","pt":1646211235617,"mc":[{"id":"1.195453766","rc":[{"atb":[[12.5,0],[15,0],[17.5,0.15],[20,0]],"id":42162698},{"atl":[[150,0],[300,0],[200,1],[250,0]],"id":42162698},{"atb":[[2.98,0],[3.45,2],[3.2,34.09],[3.7,0]],"id":39637621},{"atl":[[11,0],[13.5,0],[9.4,0],[16,0]],"id":39637621},{"atb":[[3.75,0],[4,0],[4.5,21.43],[5,2]],"id":41818763},{"atl":[[16,0],[18.5,0],[22,0],[27,0]],"id":41818763},{"atb":[[9.2,12.2],[10.5,0],[8.2,0],[13,1.67]],"id":41910350},{"atl":[[80,0],[160,0],[210,1],[110,0]],"id":41910350},{"atb":[[5.8,0],[8.6,0],[7.6,0],[6.6,0]],"id":43167133},{"atl":[[36,0],[46,0],[65,0],[90,0]],"id":43167133},{"atb":[[1.85,0],[1.7,0],[1.8,0],[1.75,0]],"id":42154339},{"atl":[[3.6,0],[3.85,0],[4.2,0],[4.7,0]],"id":42154339},{"atb":[[5.8,0],[5.3,0],[7.6,0],[6.6,0]],"id":42688787},{"atl":[[38,0],[48,0],[24,0],[29,0]],"id":42688787}],"con":true,"img":false}]}
{"op":"mcm","clk":"5353217243","pt":1646211236082,"mc":[{"id":"1.195453766","rc":[{"atb":[[8,0]],"id":42688787}],"con":true,"img":false}]}
{"op":"mcm","clk":"5353217248","pt":1646211236184,"mc":[{"id":"1.195453766","rc":[{"atb":[[1.02,1.26]],"id":42688787}],"con":true,"img":false}]}
{"op":"mcm","clk":"5353217251","pt":1646211236285,"mc":[{"id":"1.195453766","rc":[{"atb":[[21,0]],"id":42162698}],"con":true,"img":false}]}
{"op":"mcm","clk":"5353217257","pt":1646211236387,"mc":[{"id":"1.195453766","rc":[{"atb":[[1.01,1.49]],"id":42162698},{"atb":[[13.5,0]],"id":41910350},{"atb":[[1.86,0]],"id":42154339},{"atl":[[4.3,39.85],[3.55,0]],"id":42154339},{"atb":[[7.8,0]],"id":42688787}],"con":true,"img":false}]}
{"op":"mcm","clk":"5353217261","pt":1646211236490,"mc":[{"id":"1.195453766","rc":[{"atb":[[12.5,9.23]],"id":41910350},{"atb":[[1.74,147.92]],"id":42154339},{"atb":[[7.4,8.6]],"id":42688787}],"con":true,"img":false}]}
{"op":"mcm","clk":"5353217270","pt":1646211236693,"mc":[{"id":"1.195453766","rc":[{"atb":[[1.02,0]],"id":42688787}],"con":true,"img":false}]}
{"op":"mcm","clk":"5353217275","pt":1646211236796,"mc":[{"id":"1.195453766","rc":[{"atb":[[7,1.26]],"id":42688787}],"con":true,"img":false}]}
{"op":"mcm","clk":"5353217323","pt":1646211237777,"mc":[{"id":"1.195453766","rc":[{"atl":[[12,11.36]],"id":41818763}],"con":true,"img":false}]}
{"op":"mcm","clk":"5353217333","pt":1646211237981,"mc":[{"id":"1.195453766","rc":[{"atb":[[3.1,59.52]],"id":39637621},{"atl":[[7.2,8.06]],"id":39637621}],"con":true,"img":false}]}
{"op":"mcm","clk":"5353217372","pt":1646211239115,"mc":[{"id":"1.195453766","rc":[{"atb":[[12.5,9.06],[15,7.44],[17.5,6.47],[20,5.48]],"id":42162698},{"atl":[[150,0.88],[300,0.66],[200,1.66],[250,0.79]],"id":42162698},{"atb":[[2.98,52.64],[3.45,44.54],[3.2,81.46],[3.7,38.6]],"id":39637621},{"atl":[[11,13.24],[13.5,15.89],[9.4,15.76],[16,13.24]],"id":39637621},{"atb":[[3.75,36.16],[4,33.14],[4.5,49.84],[5,26.86]],"id":41818763},{"atl":[[16,9.08],[18.5,7.78],[22,9.73],[27,7.86]],"id":41818763},{"atb":[[9.2,24.91],[10.5,10.97],[8.2,14.47],[13,10.35]],"id":41910350},{"atl":[[80,1.67],[160,1.25],[210,1.94],[110,1.21]],"id":41910350},{"atb":[[5.8,21.71],[8.6,13.71],[7.6,15.79],[6.6,18.61]],"id":43167133},{"atl":[[36,3.78],[46,2.94],[65,3.1],[90,2.23]],"id":43167133},{"atb":[[1.85,122.09],[1.7,148.25],[1.8,129.72],[1.75,138.37]],"id":42154339},{"atl":[[3.6,51.08],[3.85,46.59],[4.2,62.25],[4.7,53.84]],"id":42154339},{"atb":[[5.8,21.71],[5.3,24.24],[7.6,15.79],[6.6,18.61]],"id":42688787},{"atl":[[38,5.37],[48,4.22],[24,5.75],[29,4.73]],"id":42688787}],"con":true,"img":false}]}
{"op":"mcm","clk":"5353217378","pt":1646211239273,"mc":[{"id":"1.195453766","rc":[{"atb":[[26,0],[1.05,2.25]],"id":42162698}],"con":true,"img":false}]}
{"op":"mcm","clk":"5353217383","pt":1646211239474,"mc":[{"id":"1.195453766","rc":[{"atb":[[1.05,0.14]],"id":42162698}],"con":true,"img":false}]}
{"op":"mcm","clk":"5353217393","pt":1646211239682,"mc":[{"id":"1.195453766","rc":[{"atb":[[1.05,0]],"id":42162698}],"con":true,"img":false}]}
{"op":"mcm","clk":"5353217394","pt":1646211239783,"mc":[{"id":"1.195453766","rc":[{"atb":[[21,0.14]],"id":42162698}],"con":true,"img":false}]}
{"op":"mcm","clk":"5353217403","pt":1646211239991,"mc":[{"id":"1.195453766","rc":[{"atb":[[7,0]],"id":42688787}],"con":true,"img":false}]}
{"op":"mcm","clk":"5353217408","pt":1646211240096,"mc":[{"id":"1.195453766","rc":[{"atb":[[7.8,1.26]],"id":42688787}],"con":true,"img":false}]}
{"op":"mcm","clk":"5353217465","pt":1646211241281,"mc":[{"id":"1.195453766","rc":[{"atb":[[1.02,3.19]],"id":42154339},{"atb":[[1.04,2.86]],"id":42688787}],"con":true,"img":false}]}
{"op":"mcm","clk":"5353217467","pt":1646211241380,"mc":[{"id":"1.195453766","rc":[{"atb":[[1.02,3]],"id":39637621},{"atb":[[1.03,2.93]],"id":41818763}],"con":true,"img":false}]}
{"op":"mcm","clk":"5353217475","pt":1646211241491,"mc":[{"id":"1.195453766","rc":[{"atb":[[1.67,3]],"id":42154339}],"con":true,"img":false}]}
{"op":"mcm","clk":"5353217484","pt":1646211241592,"mc":[{"id":"1.195453766","rc":[{"atl":[[8.2,0],[7.8,0],[8.6,0]],"id":39637621}],"con":true,"img":false}]}
{"op":"mcm","clk":"5353217493","pt":1646211241792,"mc":[{"id":"1.195453766","rc":[{"atb":[[1.02,0.46]],"id":42154339},{"atl":[[2.8,0]],"id":42154339},{"atb":[[1.04,0.13]],"id":42688787}],"con":true,"img":false}]}
{"op":"mcm","clk":"5353217499","pt":1646211241896,"mc":[{"id":"1.195453766","rc":[{"atb":[[1.02,0.27]],"id":39637621},{"atb":[[1.03,0.2]],"id":41818763}],"con":true,"img":false}]}
{"op":"mcm","clk":"5353217515","pt":1646211242309,"mc":[{"id":"1.195453766","rc":[{"atb":[[1.02,0]],"id":39637621},{"atb":[[1.02,0]],"id":42154339},{"atb":[[1.04,0]],"id":42688787}],"con":true,"img":false}]}
{"op":"mcm","clk":"5353217520","pt":1646211242411,"mc":[{"id":"1.195453766","rc":[{"atb":[[3.8,0.27]],"id":39637621},{"atb":[[1.03,0]],"id":41818763},{"atb":[[2.3,1.3]],"id":42154339},{"atb":[[7.8,1.4]],"id":42688787}],"con":true,"img":false}]}
{"op":"mcm","clk":"5353217525","pt":1646211242510,"mc":[{"id":"1.195453766","rc":[{"atb":[[5.1,0.53]],"id":41818763}],"con":true,"img":false}]}
{"op":"mcm","clk":"5353217659","pt":1646211246017,"mc":[{"id":"1.195453766","rc":[{"atb":[[1.01,2.53]],"id":41818763},{"atl":[[2.44,4.23]],"id":42154339}],"con":true,"img":false}]}
{"op":"mcm","clk":"5353217671","pt":1646211246220,"mc":[{"id":"1.195453766","rc":[{"atb":[[1.01,2.11]],"id":41818763}],"con":true,"img":false}]}
{"op":"mcm","clk":"5353217678","pt":1646211246420,"mc":[{"id":"1.195453766","rc":[{"atb":[[1.01,0]],"id":41818763}],"con":true,"img":false}]}
{"op":"mcm","clk":"5353217682","pt":1646211246524,"mc":[{"id":"1.195453766","rc":[{"atb":[[5.1,2.64]],"id":41818763}],"con":true,"img":false}]}
{"op":"mcm","clk":"5353217693","pt":1646211246682,"mc":[{"id":"1.195453766","rc":[{"atb":[[1.68,2]],"id":42154339}],"con":true,"img":false}]}
{"op":"mcm","clk":"5353217741","pt":1646211248020,"mc":[{"id":"1.195453766","rc":[{"atl":[[7.6,30.95]],"id":39637621}],"con":true,"img":false}]}
{"op":"mcm","clk":"5353217762","pt":1646211248828,"mc":[{"id":"1.195453766","rc":[{"atl":[[2.7,0]],"id":42154339}],"con":true,"img":false}]}
{"op":"mcm","clk":"5353217836","pt":1646211250528,"mc":[{"id":"1.195453766","rc":[{"atl":[[9.8,6.65]],"id":41818763}],"con":true,"img":false}]}
{"op":"mcm","clk":"5353217842","pt":1646211250630,"mc":[{"id":"1.195453766","rc":[{"atl":[[10.5,14.73]],"id":41818763}],"con":true,"img":false}]}
{"op":"mcm","clk":"5353217916","pt":1646211252731,"mc":[{"id":"1.195453766","rc":[{"atl":[[2.6,62.5]],"id":42154339}],"con":true,"img":false}]}
{"op":"mcm","clk":"5353218107","pt":1646211258013,"mc":[{"id":"1.195453766","rc":[{"atl":[[8,17.86]],"id":39637621}],"con":true,"img":false}]}
{"op":"mcm","clk":"5353218352","pt":1646211264548,"mc":[{"id":"1.195453766","rc":[{"atb":[[1.01,2]],"id":42154339}],"con":true,"img":false}]}
{"op":"mcm","clk":"5353218365","pt":1646211264855,"mc":[{"id":"1.195453766","rc":[{"atb":[[1.01,3.99]],"id":42154339}],"con":true,"img":false}]}
{"op":"mcm","clk":"5353218375","pt":1646211265117,"mc":[{"id":"1.195453766","rc":[{"atb":[[1.01,2]],"id":42154339}],"con":true,"img":false}]}
{"op":"mcm","clk":"5353218379","pt":1646211265219,"mc":[{"id":"1.195453766","rc":[{"atb":[[1.02,1.99]],"id":42154339}],"con":true,"img":false}]}
{"op":"mcm","clk":"5353218422","pt":1646211266144,"mc":[{"id":"1.195453766","rc":[{"atb":[[1.01,3.65]],"id":42688787}],"con":true,"img":false}]}
{"op":"mcm","clk":"5353218426","pt":1646211266246,"mc":[{"id":"1.195453766","rc":[{"atb":[[1.01,5.64]],"id":42688787}],"con":true,"img":false}]}
{"op":"mcm","clk":"5353218436","pt":1646211266450,"mc":[{"id":"1.195453766","rc":[{"atb":[[1.01,3.65],[7.4,0]],"id":42688787}],"con":true,"img":false}]}
{"op":"mcm","clk":"5353218442","pt":1646211266555,"mc":[{"id":"1.195453766","rc":[{"atb":[[7.8,10.01],[8.6,2.3]],"id":42688787}],"con":true,"img":false}]}
{"op":"mcm","clk":"5353218449","pt":1646211266658,"mc":[{"id":"1.195453766","rc":[{"atb":[[8.2,0.45],[8.6,4.3]],"id":42688787}],"con":true,"img":false}]}
{"op":"mcm","clk":"5353218457","pt":1646211266864,"mc":[{"id":"1.195453766","rc":[{"atb":[[8.6,2.3]],"id":42688787}],"con":true,"img":false}]}
{"op":"mcm","clk":"5353218463","pt":1646211266928,"mc":[{"id":"1.195453766","rc":[{"atb":[[8.6,4.3]],"id":42688787}],"con":true,"img":false}]}
{"op":"mcm","clk":"5353218499","pt":1646211267647,"mc":[{"id":"1.195453766","rc":[{"atb":[[1.01,2]],"id":41818763}],"con":true,"img":false}]}
{"op":"mcm","clk":"5353218514","pt":1646211267846,"mc":[{"id":"1.195453766","rc":[{"atb":[[1.01,3.99]],"id":41818763},{"atb":[[8.4,0.19]],"id":42688787}],"con":true,"img":false}]}
{"op":"mcm","clk":"5353218533","pt":1646211268155,"mc":[{"id":"1.195453766","rc":[{"atb":[[1.01,2]],"id":41818763}],"con":true,"img":false}]}
{"op":"mcm","clk":"5353218543","pt":1646211268256,"mc":[{"id":"1.195453766","rc":[{"atb":[[1.02,1.99]],"id":41818763}],"con":true,"img":false}]}
{"op":"mcm","clk":"5353218591","pt":1646211269034,"mc":[{"id":"1.195453766","rc":[{"atb":[[1.01,3.68]],"id":39637621}],"con":true,"img":false}]}
{"op":"mcm","clk":"5353218600","pt":1646211269239,"mc":[{"id":"1.195453766","rc":[{"atb":[[1.01,5.67]],"id":39637621}],"con":true,"img":false}]}
{"op":"mcm","clk":"5353218618","pt":1646211269643,"mc":[{"id":"1.195453766","rc":[{"atb":[[1.01,3.68]],"id":39637621}],"con":true,"img":false}]}
{"op":"mcm","clk":"5353218628","pt":1646211269753,"mc":[{"id":"1.195453766","rc":[{"atb":[[1.02,1.99]],"id":39637621}],"con":true,"img":false}]}
{"op":"mcm","clk":"5353219016","pt":1646211278452,"mc":[{"id":"1.195453766","rc":[{"spn":22.16,"spf":1.0,"id":42162698},{"atl":[[7.6,11.36]],"id":39637621},{"spn":2.27,"spf":1.0,"id":42154339},{"spn":8.33,"spf":1.0,"id":42688787}],"con":true,"img":false}]}
{"op":"mcm","clk":"5353219019","pt":1646211278560,"mc":[{"id":"1.195453766","rc":[{"atl":[[7,19.59]],"id":39637621}],"con":true,"img":false}]}
{"op":"mcm","clk":"5353219024","pt":1646211278654,"mc":[{"id":"1.195453766","rc":[{"atb":[[1.01,3.67]],"id":41818763},{"atb":[[1.01,1.67]],"id":43167133}],"con":true,"img":false}]}
{"op":"mcm","clk":"5353219029","pt":1646211278761,"mc":[{"id":"1.195453766","rc":[{"atb":[[1.03,1.67]],"id":42162698},{"atb":[[1.02,1.67]],"id":41910350}],"con":true,"img":false}]}
{"op":"mcm","clk":"5353219036","pt":1646211278960,"mc":[{"id":"1.195453766","rc":[{"atb":[[1.01,3.6]],"id":41818763}],"con":true,"img":false}]}
{"op":"mcm","clk":"5353219039","pt":1646211279061,"mc":[{"id":"1.195453766","rc":[{"atb":[[1.01,0.76]],"id":43167133}],"con":true,"img":false}]}
{"op":"mcm","clk":"5353219043","pt":1646211279164,"mc":[{"id":"1.195453766","rc":[{"atb":[[1.03,0.31]],"id":42162698},{"atb":[[1.01,2]],"id":41818763}],"con":true,"img":false}]}
{"op":"mcm","clk":"5353219047","pt":1646211279266,"mc":[{"id":"1.195453766","rc":[{"atb":[[5.2,1.6]],"id":41818763},{"atb":[[1.02,0.47]],"id":41910350}],"con":true,"img":false}]}
{"op":"mcm","clk":"5353219054","pt":1646211279472,"mc":[{"id":"1.195453766","rc":[{"atb":[[1.01,0]],"id":43167133}],"con":true,"img":false}]}
{"op":"mcm","clk":"5353219059","pt":1646211279575,"mc":[{"id":"1.195453766","rc":[{"atb":[[5.1,0.53]],"id":41818763},{"atb":[[11,0.76]],"id":43167133}],"con":true,"img":false}]}
{"op":"mcm","clk":"5353219069","pt":1646211279746,"mc":[{"id":"1.195453766","rc":[{"atb":[[1.03,0]],"id":42162698}],"con":true,"img":false}]}
{"op":"mcm","clk":"5353219074","pt":1646211279845,"mc":[{"id":"1.195453766","rc":[{"atb":[[26,0.31]],"id":42162698},{"atb":[[1.01,4.53]],"id":41818763}],"con":true,"img":false}]}
{"op":"mcm","clk":"5353219077","pt":1646211279949,"mc":[{"id":"1.195453766","rc":[{"atb":[[1.01,4.11]],"id":41818763},{"atb":[[1.02,0]],"id":41910350}],"con":true,"img":false}]}
{"op":"mcm","clk":"5353219082","pt":1646211280052,"mc":[{"id":"1.195453766","rc":[{"atb":[[17.5,0.47]],"id":41910350}],"con":true,"img":false}]}
{"op":"mcm","clk":"5353219088","pt":1646211280142,"mc":[{"id":"1.195453766","rc":[{"atb":[[1.01,2]],"id":41818763},{"atb":[[17,2.1]],"id":41910350}],"con":true,"img":false}]}
{"op":"mcm","clk":"5353219094","pt":1646211280250,"mc":[{"id":"1.195453766","rc":[{"atb":[[5.3,2.11]],"id":41818763},{"atb":[[16,0],[17,0.1]],"id":41910350}],"con":true,"img":false}]}
{"op":"mcm","clk":"5353219099","pt":1646211280349,"mc":[{"id":"1.195453766","rc":[{"atb":[[17,2.1]],"id":41910350},{"atb":[[1.74,0]],"id":42154339},{"atl":[[4.3,8.2],[3.55,49.67]],"id":42154339}],"con":true,"img":false}]}
{"op":"mcm","clk":"5353219103","pt":1646211280452,"mc":[{"id":"1.195453766","rc":[{"atb":[[1.01,3.67],[5.2,0]],"id":41818763},{"atb":[[1.86,147.92]],"id":42154339}],"con":true,"img":false}]}
{"op":"mcm","clk":"5353219128","pt":1646211280860,"mc":[{"id":"1.195453766","rc":[{"atb":[[1.01,3.6]],"id":41818763}],"con":true,"img":false}]}
{"op":"mcm","clk":"5353219139","pt":1646211281065,"mc":[{"id":"1.195453766","rc":[{"atb":[[1.01,2]],"id":41818763}],"con":true,"img":false}]}
{"op":"mcm","clk":"5353219147","pt":1646211281169,"mc":[{"id":"1.195453766","rc":[{"atb":[[5.1,2.13]],"id":41818763}],"con":true,"img":false}]}
{"op":"mcm","clk":"5353219192","pt":1646211282460,"mc":[{"id":"1.195453766","rc":[{"atb":[[12.5,0]],"id":41910350}],"con":true,"img":false}]}
{"op":"mcm","clk":"5353219195","pt":1646211282564,"mc":[{"id":"1.195453766","rc":[{"atb":[[13.5,9.23]],"id":41910350}],"con":true,"img":false}]}
{"op":"mcm","clk":"5353219203","pt":1646211282875,"mc":[{"id":"1.195453766","rc":[{"atb":[[16.5,0.66]],"id":41910350}],"con":true,"img":false}]}
{"op":"mcm","clk":"5353219215","pt":1646211283181,"mc":[{"id":"1.195453766","rc":[{"atb":[[15,0]],"id":41910350}],"con":true,"img":false}]}
{"op":"mcm","clk":"5353219303","pt":1646211285145,"mc":[{"id":"1.195453766","rc":[{"atb":[[36,6.36]],"id":41910350},{"atl":[[30,0]],"id":41910350},{"trd":[[30,0.37]],"ltp":30.0,"tv":0.37,"id":41910350}],"con":true,"img":false}]}
{"op":"mcm","clk":"5353219311","pt":1646211285350,"mc":[{"id":"1.195453766","rc":[{"atl":[[1000,1.67]],"id":42162698},{"atl":[[14.5,2.77],[15,1.24]],"id":42688787}],"con":true,"img":false}]}
{"op":"mcm","clk":"5353219320","pt":1646211285557,"mc":[{"id":"1.195453766","rc":[{"atl":[[1000,0.16]],"id":42162698}],"con":true,"img":false}]}
{"op":"mcm","clk":"5353219326","pt":1646211285659,"mc":[{"id":"1.195453766","rc":[{"atl":[[1000,0]],"id":42162698},{"atb":[[8.6,2.31]],"id":42688787},{"atl":[[14.5,1.48]],"id":42688787}],"con":true,"img":false}]}
{"op":"mcm","clk":"5353219329","pt":1646211285762,"mc":[{"id":"1.195453766","rc":[{"atl":[[50,0.16]],"id":42162698},{"atb":[[1.02,1.99]],"id":42688787},{"atl":[[15.5,1.29]],"id":42688787}],"con":true,"img":false}]}
{"op":"mcm","clk":"5353219333","pt":1646211285865,"mc":[{"id":"1.195453766","rc":[{"atb":[[8.2,2.45],[8.6,0.31]],"id":42688787}],"con":true,"img":false}]}
{"op":"mcm","clk":"5353219337","pt":1646211285966,"mc":[{"id":"1.195453766","rc":[{"atb":[[8,2]],"id":42688787}],"con":true,"img":false}]}
{"op":"mcm","clk":"5353219342","pt":1646211286075,"mc":[{"id":"1.195453766","rc":[{"atb":[[8.2,0.45]],"id":42688787}],"con":true,"img":false}]}
{"op":"mcm","clk":"5353219380","pt":1646211287051,"mc":[{"id":"1.195453766","rc":[{"atb":[[5.3,0]],"id":41818763}],"con":true,"img":false}]}
{"op":"mcm","clk":"5353219401","pt":1646211287471,"mc":[{"id":"1.195453766","rc":[{"atb":[[1.01,4.53]],"id":41818763}],"con":true,"img":false}]}
{"op":"mcm","clk":"5353219413","pt":1646211287670,"mc":[{"id":"1.195453766","rc":[{"atb":[[1.01,4.11]],"id":41818763}],"con":true,"img":false}]}
{"op":"mcm","clk":"5353219422","pt":1646211287875,"mc":[{"id":"1.195453766","rc":[{"atb":[[1.01,2]],"id":41818763}],"con":true,"img":false}]}
{"op":"mcm","clk":"5353219429","pt":1646211287975,"mc":[{"id":"1.195453766","rc":[{"atb":[[5.4,2.11]],"id":41818763},{"atl":[[7.2,2.5]],"id":41818763}],"con":true,"img":false}]}
{"op":"mcm","clk":"5353219451","pt":1646211288385,"mc":[{"id":"1.195453766","rc":[{"atl":[[48,0]],"id":41910350}],"con":true,"img":false}]}
{"op":"mcm","clk":"5353219456","pt":1646211288488,"mc":[{"id":"1.195453766","rc":[{"atl":[[60,2.72]],"id":41910350}],"con":true,"img":false}]}
{"op":"mcm","clk":"5353219468","pt":1646211288651,"mc":[{"id":"1.195453766","rc":[{"atl":[[7.4,0]],"id":41818763}],"con":true,"img":false}]}
{"op":"mcm","clk":"5353219474","pt":1646211288754,"mc":[{"id":"1.195453766","rc":[{"atl":[[7,1.51]],"id":41818763}],"con":true,"img":false}]}
{"op":"mcm","clk":"5353219509","pt":1646211289572,"mc":[{"id":"1.195453766","rc":[{"atl":[[7.2,0]],"id":41818763}],"con":true,"img":false}]}
{"op":"mcm","clk":"5353219518","pt":1646211289675,"mc":[{"id":"1.195453766","rc":[{"atl":[[7.8,0]],"id":41818763}],"con":true,"img":false}]}
{"op":"mcm","clk":"5353219529","pt":1646211289882,"mc":[{"id":"1.195453766","rc":[{"atl":[[1000,2.25]],"id":41818763}],"con":true,"img":false}]}
{"op":"mcm","clk":"5353219539","pt":1646211290191,"mc":[{"id":"1.195453766","rc":[{"atl":[[1000,1.45]],"id":41818763}],"con":true,"img":false}]}
{"op":"mcm","clk":"5353219544","pt":1646211290290,"mc":[{"id":"1.195453766","rc":[{"atl":[[1000,0]],"id":41818763}],"con":true,"img":false}]}
{"op":"mcm","clk":"5353219548","pt":1646211290350,"mc":[{"id":"1.195453766","rc":[{"atl":[[7,2.97]],"id":41818763}],"con":true,"img":false}]}
{"op":"mcm","clk":"5353219649","pt":1646211293584,"mc":[{"id":"1.195453766","rc":[{"atl":[[44,0]],"id":41910350}],"con":true,"img":false}]}
{"op":"mcm","clk":"5353219662","pt":1646211293788,"mc":[{"id":"1.195453766","rc":[{"atl":[[95,2],[60,4.72]],"id":41910350}],"con":true,"img":false}]}
{"op":"mcm","clk":"5353219666","pt":1646211293889,"mc":[{"id":"1.195453766","rc":[{"atl":[[70,0]],"id":41910350}],"con":true,"img":false}]}
{"op":"mcm","clk":"5353219685","pt":1646211294356,"mc":[{"id":"1.195453766","rc":[{"atb":[[5.4,0]],"id":41818763},{"atl":[[65,0]],"id":41910350}],"con":true,"img":false}]}
{"op":"mcm","clk":"5353219691","pt":1646211294464,"mc":[{"id":"1.195453766","rc":[{"atl":[[75,2.72]],"id":41910350}],"con":true,"img":false}]}
{"op":"mcm","clk":"5353219700","pt":1646211294670,"mc":[{"id":"1.195453766","rc":[{"atb":[[1.01,4.53]],"id":41818763}],"con":true,"img":false}]}
{"op":"mcm","clk":"5353219705","pt":1646211294775,"mc":[{"id":"1.195453766","rc":[{"atb":[[1.01,4.11]],"id":41818763}],"con":true,"img":false}]}
{"op":"mcm","clk":"5353219717","pt":1646211294980,"mc":[{"id":"1.195453766","rc":[{"atb":[[1.01,2]],"id":41818763}],"con":true,"img":false}]}
{"op":"mcm","clk":"5353219721","pt":1646211295080,"mc":[{"id":"1.195453766","rc":[{"atb":[[5.5,2.11]],"id":41818763}],"con":true,"img":false}]}
{"op":"mcm","clk":"5353220013","pt":1646211302386,"mc":[{"id":"1.195453766","rc":[{"atb":[[5.5,0]],"id":41818763}],"con":true,"img":false}]}
{"op":"mcm","clk":"5353220025","pt":1646211302696,"mc":[{"id":"1.195453766","rc":[{"atl":[[7,1.45]],"id":41818763},{"atb":[[9,0]],"id":43167133},{"atb":[[1.01,2]],"id":42688787}],"con":true,"img":false}]}
{"op":"mcm","clk":"5353220031","pt":1646211302794,"mc":[{"id":"1.195453766","rc":[{"atb":[[1.01,4.53]],"id":41818763},{"atl":[[7.4,1.51]],"id":41818763},{"atb":[[11,2.26]],"id":43167133},{"atb":[[8.2,2.11]],"id":42688787}],"con":true,"img":false}]}
{"op":"mcm","clk":"5353220042","pt":1646211303000,"mc":[{"id":"1.195453766","rc":[{"atb":[[1.01,4.11]],"id":41818763},{"atb":[[10,1.12],[11,4.26]],"id":43167133},{"atb":[[8,0],[8.4,2.19]],"id":42688787}],"con":true,"img":false}]}
{"op":"mcm","clk":"5353220049","pt":1646211303103,"mc":[{"id":"1.195453766","rc":[{"atb":[[10.5,4.6],[11,2.26]],"id":43167133},{"atb":[[8.2,4.11]],"id":42688787}],"con":true,"img":false}]}
{"op":"mcm","clk":"5353220056","pt":1646211303207,"mc":[{"id":"1.195453766","rc":[{"atb":[[1.01,2]],"id":41818763},{"atb":[[8.4,0.19]],"id":42688787}],"con":true,"img":false}]}
{"op":"mcm","clk":"5353220058","pt":1646211303311,"mc":[{"id":"1.195453766","rc":[{"atb":[[5.6,2.11]],"id":41818763}],"con":true,"img":false}]}
{"op":"mcm","clk":"5353220077","pt":1646211303577,"mc":[{"id":"1.195453766","rc":[{"atb":[[11,0.76]],"id":43167133}],"con":true,"img":false}]}
{"op":"mcm","clk":"5353220083","pt":1646211303681,"mc":[{"id":"1.195453766","rc":[{"atb":[[1.01,1.5]],"id":43167133}],"con":true,"img":false}]}
{"op":"mcm","clk":"5353220094","pt":1646211303986,"mc":[{"id":"1.195453766","rc":[{"atb":[[10.5,2.51]],"id":43167133}],"con":true,"img":false}]}
{"op":"mcm","clk":"5353220099","pt":1646211304087,"mc":[{"id":"1.195453766","rc":[{"atb":[[7.8,8.74]],"id":42688787}],"con":true,"img":false}]}
{"op":"mcm","clk":"5353220104","pt":1646211304192,"mc":[{"id":"1.195453766","rc":[{"atb":[[8.2,5.38]],"id":42688787}],"con":true,"img":false}]}
{"op":"mcm","clk":"5353220265","pt":1646211308410,"mc":[{"id":"1.195453766","rc":[{"atb":[[5.6,0]],"id":41818763},{"trd":[[5.6,5.21]],"ltp":5.6,"tv":5.21,"id":41818763},{"atb":[[36,0]],"id":41910350},{"trd":[[36,12.72]],"ltp":36.0,"tv":12.72,"id":41910350}],"con":true,"img":false}]}
{"op":"mcm","clk":"5353220271","pt":1646211308512,"mc":[{"id":"1.195453766","rc":[{"atb":[[16.5,2.66]],"id":41910350}],"con":true,"img":false}]}
{"op":"mcm","clk":"5353220277","pt":1646211308615,"mc":[{"id":"1.195453766","rc":[{"atb":[[1.01,4.53],[4.4,71.98],[4.2,0]],"id":41818763},{"atb":[[17,0.1]],"id":41910350},{"atb":[[1.01,3.67]],"id":42688787},{"atl":[[14.5,0],[15,2.67]],"id":42688787}],"con":true,"img":false}]}
{"op":"mcm","clk":"5353220288","pt":1646211308820,"mc":[{"id":"1.195453766","rc":[{"atl":[[7.6,0]],"id":41818763},{"atl":[[55,1.24]],"id":41910350},{"atb":[[1.01,2.95],[1.02,0]],"id":42688787}],"con":true,"img":false}]}
{"op":"mcm","clk":"5353220292","pt":1646211308880,"mc":[{"id":"1.195453766","rc":[{"atb":[[1.01,4.11]],"id":41818763},{"atb":[[8.4,2.18]],"id":42688787}],"con":true,"img":false}]}
{"op":"mcm","clk":"5353220296","pt":1646211308989,"mc":[{"id":"1.195453766","rc":[{"atb":[[1.01,2]],"id":42688787}],"con":true,"img":false}]}
{"op":"mcm","clk":"5353220300","pt":1646211309084,"mc":[{"id":"1.195453766","rc":[{"atb":[[1.01,2]],"id":41818763},{"atl":[[55,2.63]],"id":41910350},{"atb":[[8.8,0.95]],"id":42688787}],"con":true,"img":false}]}
{"op":"mcm","clk":"5353220304","pt":1646211309190,"mc":[{"id":"1.195453766","rc":[{"atb":[[5.7,2.11]],"id":41818763},{"atb":[[17.5,2.56]],"id":41910350},{"atb":[[11,2.84]],"id":43167133},{"atb":[[8.2,1.72],[8.4,4.68],[8.6,2.31]],"id":42688787}],"con":true,"img":false}]}
{"op":"mcm","clk":"5353220309","pt":1646211309289,"mc":[{"id":"1.195453766","rc":[{"atb":[[8.4,6.34]],"id":42688787}],"con":true,"img":false}]}
{"op":"mcm","clk":"5353220314","pt":1646211309391,"mc":[{"id":"1.195453766","rc":[{"atb":[[8.4,4.35]],"id":42688787}],"con":true,"img":false}]}
{"op":"mcm","clk":"5353220318","pt":1646211309492,"mc":[{"id":"1.195453766","rc":[{"atb":[[1.02,1.99]],"id":42688787}],"con":true,"img":false}]}
{"op":"mcm","clk":"5353220337","pt":1646211310109,"mc":[{"id":"1.195453766","rc":[{"atb":[[14.5,0.19]],"id":41910350},{"atb":[[1.01,0]],"id":43167133},{"atb":[[8.4,2.69]],"id":42688787}],"con":true,"img":false}]}
{"op":"mcm","clk":"5353220340","pt":1646211310212,"mc":[{"id":"1.195453766","rc":[{"atb":[[18,1.66]],"id":41910350},{"atb":[[11.5,1.5]],"id":43167133},{"atb":[[8.8,2.6]],"id":42688787}],"con":true,"img":false}]}
{"op":"mcm","clk":"5353220345","pt":1646211310314,"mc":[{"id":"1.195453766","rc":[{"atb":[[10.5,0.51],[11.5,3.5]],"id":43167133},{"atb":[[8.2,0.45]],"id":42688787}],"con":true,"img":false}]}
{"op":"mcm","clk":"5353220350","pt":1646211310417,"mc":[{"id":"1.195453766","rc":[{"atb":[[1.01,1.67],[11,2.08]],"id":43167133},{"atb":[[8,1.26]],"id":42688787}],"con":true,"img":false}]}
{"op":"mcm","clk":"5353220356","pt":1646211310476,"mc":[{"id":"1.195453766","rc":[{"atb":[[11.5,1.5]],"id":43167133}],"con":true,"img":false}]}
{"op":"mcm","clk":"5353220363","pt":1646211310580,"mc":[{"id":"1.195453766","rc":[{"atb":[[1.01,0.69],[11,4.08]],"id":43167133}],"con":true,"img":false}]}
{"op":"mcm","clk":"5353220369","pt":1646211310784,"mc":[{"id":"1.195453766","rc":[{"atb":[[1.01,0]],"id":43167133}],"con":true,"img":false}]}
{"op":"mcm","clk":"5353220373","pt":1646211310884,"mc":[{"id":"1.195453766","rc":[{"atb":[[12,0.69]],"id":43167133},{"atb":[[8.4,0.19]],"id":42688787}],"con":true,"img":false}]}
{"op":"mcm","clk":"5353220381","pt":1646211311039,"mc":[{"id":"1.195453766","rc":[{"atb":[[11.5,0]],"id":43167133}],"con":true,"img":false}]}
{"op":"mcm","clk":"5353220384","pt":1646211311101,"mc":[{"id":"1.195453766","rc":[{"atb":[[1.01,1.5]],"id":43167133}],"con":true,"img":false}]}
{"op":"mcm","clk":"5353220432","pt":1646211311917,"mc":[{"id":"1.195453766","rc":[{"atb":[[17.5,0.47]],"id":41910350}],"con":true,"img":false}]}
{"op":"mcm","clk":"5353220441","pt":1646211312020,"mc":[{"id":"1.195453766","rc":[{"atb":[[8.8,0.95]],"id":42688787}],"con":true,"img":false}]}
{"op":"mcm","clk":"5353220450","pt":1646211312126,"mc":[{"id":"1.195453766","rc":[{"atb":[[5.1,1.81]],"id":41818763},{"atb":[[17,0]],"id":41910350},{"atb":[[10.5,0.36]],"id":43167133},{"atb":[[1.01,3.65],[8.4,0]],"id":42688787}],"con":true,"img":false}]}
{"op":"mcm","clk":"5353220456","pt":1646211312184,"mc":[{"id":"1.195453766","rc":[{"atb":[[5.8,0.32]],"id":41818763},{"atb":[[18.5,0.1]],"id":41910350},{"atb":[[11.5,0.15]],"id":43167133},{"atb":[[9,0.19]],"id":42688787}],"con":true,"img":false}]}
{"op":"mcm","clk":"5353220492","pt":1646211312902,"mc":[{"id":"1.195453766","rc":[{"atb":[[18,0]],"id":41910350}],"con":true,"img":false}]}
{"op":"mcm","clk":"5353220499","pt":1646211313006,"mc":[{"id":"1.195453766","rc":[{"atb":[[1.01,1.66]],"id":41910350}],"con":true,"img":false}]}
{"op":"mcm","clk":"5353220526","pt":1646211313721,"mc":[{"id":"1.195453766","rc":[{"atb":[[11,2]],"id":43167133}],"con":true,"img":false}]}
{"op":"mcm","clk":"5353220532","pt":1646211313928,"mc":[{"id":"1.195453766","rc":[{"atb":[[5.1,24.39],[5.7,0]],"id":43167133}],"con":true,"img":false}]}
{"op":"mcm","clk":"5353220569","pt":1646211314710,"mc":[{"id":"1.195453766","rc":[{"atb":[[1.2,2.25]],"id":41910350}],"con":true,"img":false}]}
{"op":"mcm","clk":"5353220580","pt":1646211315012,"mc":[{"id":"1.195453766","rc":[{"atb":[[1.2,1.75]],"id":41910350}],"con":true,"img":false}]}
{"op":"mcm","clk":"5353220598","pt":1646211315321,"mc":[{"id":"1.195453766","rc":[{"atl":[[8,0]],"id":41818763},{"atb":[[1.2,0]],"id":41910350}],"con":true,"img":false}]}
{"op":"mcm","clk":"5353220603","pt":1646211315423,"mc":[{"id":"1.195453766","rc":[{"atb":[[14.5,1.94]],"id":41910350}],"con":true,"img":false}]}
{"op":"mcm","clk":"5353220620","pt":1646211315630,"mc":[{"id":"1.195453766","rc":[{"atl":[[6.8,1.83]],"id":41818763}],"con":true,"img":false}]}
{"op":"mcm","clk":"5353220626","pt":1646211315733,"mc":[{"id":"1.195453766","rc":[{"atb":[[10.5,2.36]],"id":43167133}],"con":true,"img":false}]}
{"op":"mcm","clk":"5353220633","pt":1646211315836,"mc":[{"id":"1.195453766","rc":[{"atb":[[11,0]],"id":43167133}],"con":true,"img":false}]}
{"op":"mcm","clk":"5353220637","pt":1646211315895,"mc":[{"id":"1.195453766","rc":[{"atb":[[5.8,0],[5.7,0]],"id":41818763},{"trd":[[5.7,4.22],[5.8,0.65]],"ltp":5.7,"tv":4.87,"id":41818763}],"con":true,"img":false}]}
{"op":"mcm","clk":"5353220642","pt":1646211316000,"mc":[{"id":"1.195453766","rc":[{"atb":[[4.4,42.57],[4.5,78.41]],"id":41818763}],"con":true,"img":false}]}
{"op":"mcm","clk":"5353220648","pt":1646211316204,"mc":[{"id":"1.195453766","rc":[{"atb":[[1.02,0]],"id":42688787}],"con":true,"img":false}]}
{"op":"mcm","clk":"5353220653","pt":1646211316310,"mc":[{"id":"1.195453766","rc":[{"atb":[[8.8,2.94]],"id":42688787}],"con":true,"img":false}]}
{"op":"mcm","clk":"5353220658","pt":1646211316411,"mc":[{"id":"1.195453766","rc":[{"atl":[[60,2]],"id":41910350}],"con":true,"img":false}]}
{"op":"mcm","clk":"5353220661","pt":1646211316506,"mc":[{"id":"1.195453766","rc":[{"atl":[[46,2.72]],"id":41910350}],"con":true,"img":false}]}
{"op":"mcm","clk":"5353220670","pt":1646211316712,"mc":[{"id":"1.195453766","rc":[{"atl":[[7.4,0]],"id":41818763},{"atb":[[1.01,2]],"id":42688787}],"con":true,"img":false}]}
{"op":"mcm","clk":"5353220673","pt":1646211316815,"mc":[{"id":"1.195453766","rc":[{"atl":[[6.6,1.51]],"id":41818763},{"atb":[[9,1.84]],"id":42688787}],"con":true,"img":false}]}
{"op":"mcm","clk":"5353220677","pt":1646211316918,"mc":[{"id":"1.195453766","rc":[{"atb":[[9,3.84],[8.6,0.31]],"id":42688787}],"con":true,"img":false}]}
{"op":"mcm","clk":"5353220688","pt":1646211317331,"mc":[{"id":"1.195453766","rc":[{"atb":[[1.01,4.53]],"id":41818763},{"atb":[[8.8,0.95]],"id":42688787}],"con":true,"img":false}]}
{"op":"mcm","clk":"5353220691","pt":1646211317434,"mc":[{"id":"1.195453766","rc":[{"atb":[[9.2,1.99]],"id":42688787}],"con":true,"img":false}]}
{"op":"mcm","clk":"5353220694","pt":1646211317538,"mc":[{"id":"1.195453766","rc":[{"atb":[[1.01,4.11]],"id":41818763}],"con":true,"img":false}]}
{"op":"mcm","clk":"5353220699","pt":1646211317597,"mc":[{"id":"1.195453766","rc":[{"atb":[[9,2.19]],"id":42688787}],"con":true,"img":false}]}
{"op":"mcm","clk":"5353220702","pt":1646211317705,"mc":[{"id":"1.195453766","rc":[{"atb":[[1.01,2]],"id":41818763},{"atb":[[12,2.78]],"id":43167133},{"atb":[[8,2.92],[9,4.69]],"id":42688787}],"con":true,"img":false}]}
{"op":"mcm","clk":"5353220709","pt":1646211317807,"mc":[{"id":"1.195453766","rc":[{"atb":[[5.2,2.11]],"id":41818763}],"con":true,"img":false}]}
{"op":"mcm","clk":"5353220728","pt":1646211318209,"mc":[{"id":"1.195453766","rc":[{"atb":[[9.2,0]],"id":42688787}],"con":true,"img":false}]}
{"op":"mcm","clk":"5353220732","pt":1646211318313,"mc":[{"id":"1.195453766","rc":[{"atb":[[1.02,1.99]],"id":42688787}],"con":true,"img":false}]}
{"op":"mcm","clk":"5353220743","pt":1646211318722,"mc":[{"id":"1.195453766","rc":[{"atb":[[9,2.19]],"id":42688787}],"con":true,"img":false}]}
{"op":"mcm","clk":"5353220807","pt":1646211320319,"mc":[{"id":"1.195453766","rc":[{"atb":[[9.2,2.5]],"id":42688787}],"con":true,"img":false}]}
{"op":"mcm","clk":"5353220813","pt":1646211320525,"mc":[{"id":"1.195453766","rc":[{"atb":[[9.2,12.71],[11,17.5]],"id":41910350},{"atl":[[80,3.67],[95,0]],"id":41910350}],"con":true,"img":false}]}
{"op":"mcm","clk":"5353220826","pt":1646211320838,"mc":[{"id":"1.195453766","rc":[{"atb":[[12,4.78]],"id":43167133}],"con":true,"img":false}]}
{"op":"mcm","clk":"5353220832","pt":1646211320940,"mc":[{"id":"1.195453766","rc":[{"atb":[[10.5,0.36],[12,2.78]],"id":43167133}],"con":true,"img":false}]}
{"op":"mcm","clk":"5353220836","pt":1646211320997,"mc":[{"id":"1.195453766","rc":[{"atb":[[12,4.78]],"id":43167133}],"con":true,"img":false}]}
{"op":"mcm","clk":"5353221150","pt":1646211328628,"mc":[{"id":"1.195453766","rc":[{"atl":[[6.8,0]],"id":41818763}],"con":true,"img":false}]}
{"op":"mcm","clk":"5353221167","pt":1646211328930,"mc":[{"id":"1.195453766","rc":[{"atl":[[6.4,1.95]],"id":41818763}],"con":true,"img":false}]}
{"op":"mcm","clk":"5353221567","pt":1646211338375,"mc":[{"id":"1.195453766","rc":[{"atl":[[75,0]],"id":41910350}],"con":true,"img":false}]}
{"op":"mcm","clk":"5353221571","pt":1646211338434,"mc":[{"id":"1.195453766","rc":[{"atl":[[55,5.36]],"id":41910350}],"con":true,"img":false}]}
{"op":"mcm","clk":"5353221580","pt":1646211338640,"mc":[{"id":"1.195453766","rc":[{"spn":22.43,"spf":1.0,"id":42162698},{"spn":5.8,"spf":"NaN","id":41818763},{"atl":[[55,3.97]],"id":41910350},{"spn":15.39,"spf":1.0,"id":41910350},{"spn":11.36,"spf":1.0,"id":43167133},{"atl":[[15.5,0]],"id":42688787},{"spn":8.89,"spf":1.0,"id":42688787}],"con":true,"img":false}]}
{"op":"mcm","clk":"5353221587","pt":1646211338743,"mc":[{"id":"1.195453766","rc":[{"atb":[[17.5,0],[1.02,1.67]],"id":41910350},{"atl":[[44,1.38]],"id":41910350},{"atl":[[14.5,1.29]],"id":42688787}],"con":true,"img":false}]}
{"op":"mcm","clk":"5353221592","pt":1646211338839,"mc":[{"id":"1.195453766","rc":[{"atb":[[16.5,0.66],[16,2],[1.02,0.44]],"id":41910350}],"con":true,"img":false}]}
{"op":"mcm","clk":"5353221600","pt":1646211339046,"mc":[{"id":"1.195453766","rc":[{"atb":[[1.02,0]],"id":41910350}],"con":true,"img":false}]}
{"op":"mcm","clk":"5353221606","pt":1646211339149,"mc":[{"id":"1.195453766","rc":[{"atb":[[19,0.44]],"id":41910350}],"con":true,"img":false}]}
{"op":"mcm","clk":"5353221612","pt":1646211339250,"mc":[{"id":"1.195453766","rc":[{"atl":[[55,2.72]],"id":41910350}],"con":true,"img":false}]}
{"op":"mcm","clk":"5353221617","pt":1646211339354,"mc":[{"id":"1.195453766","rc":[{"atb":[[1.02,1.67]],"id":41910350}],"con":true,"img":false}]}
{"op":"mcm","clk":"5353221620","pt":1646211339456,"mc":[{"id":"1.195453766","rc":[{"atb":[[19,0]],"id":41910350}],"con":true,"img":false}]}
{"op":"mcm","clk":"5353221624","pt":1646211339560,"mc":[{"id":"1.195453766","rc":[{"atb":[[1.02,0.44]],"id":41910350}],"con":true,"img":false}]}
{"op":"mcm","clk":"5353221629","pt":1646211339663,"mc":[{"id":"1.195453766","rc":[{"atb":[[1.02,0]],"id":41910350}],"con":true,"img":false}]}
{"op":"mcm","clk":"5353221633","pt":1646211339766,"mc":[{"id":"1.195453766","rc":[{"atb":[[16.5,1.1]],"id":41910350}],"con":true,"img":false}]}
{"op":"mcm","clk":"5353221643","pt":1646211339972,"mc":[{"id":"1.195453766","rc":[{"atb":[[16.5,0.66],[1.02,1.67]],"id":41910350}],"con":true,"img":false}]}
{"op":"mcm","clk":"5353221646","pt":1646211340043,"mc":[{"id":"1.195453766","rc":[{"atb":[[1.01,0]],"id":41910350}],"con":true,"img":false}]}
{"op":"mcm","clk":"5353221655","pt":1646211340138,"mc":[{"id":"1.195453766","rc":[{"atb":[[14.5,3.6],[1.02,0.44]],"id":41910350}],"con":true,"img":false}]}
{"op":"mcm","clk":"5353221664","pt":1646211340342,"mc":[{"id":"1.195453766","rc":[{"atb":[[16.5,2.74],[1.02,0]],"id":41910350}],"con":true,"img":false}]}
{"op":"mcm","clk":"5353221672","pt":1646211340450,"mc":[{"id":"1.195453766","rc":[{"atb":[[19,0.44]],"id":41910350}],"con":true,"img":false}]}
{"op":"mcm","clk":"5353221680","pt":1646211340650,"mc":[{"id":"1.195453766","rc":[{"atb":[[16,0],[17,2]],"id":41910350}],"con":true,"img":false}]}
{"op":"mcm","clk":"5353221684","pt":1646211340754,"mc":[{"id":"1.195453766","rc":[{"atb":[[17,0]],"id":41910350}],"con":true,"img":false}]}
{"op":"mcm","clk":"5353221689","pt":1646211340856,"mc":[{"id":"1.195453766","rc":[{"atb":[[14.5,1.94],[17,2]],"id":41910350}],"con":true,"img":false}]}
{"op":"mcm","clk":"5353221695","pt":1646211340959,"mc":[{"id":"1.195453766","rc":[{"atb":[[17.5,1.66]],"id":41910350}],"con":true,"img":false}]}
{"op":"mcm","clk":"5353221731","pt":1646211341846,"mc":[{"id":"1.195453766","rc":[{"atb":[[16.5,0.66],[17.5,0]],"id":41910350}],"con":true,"img":false}]}
{"op":"mcm","clk":"5353221736","pt":1646211341947,"mc":[{"id":"1.195453766","rc":[{"atb":[[1.01,1.66]],"id":41910350}],"con":true,"img":false}]}
{"op":"mcm","clk":"5353221754","pt":1646211342456,"mc":[{"id":"1.195453766","rc":[{"atl":[[46,0]],"id":41910350}],"con":true,"img":false}]}
{"op":"mcm","clk":"5353221757","pt":1646211342561,"mc":[{"id":"1.195453766","rc":[{"atl":[[50,2.72]],"id":41910350}],"con":true,"img":false}]}
{"op":"mcm","clk":"5353221776","pt":1646211342972,"mc":[{"id":"1.195453766","rc":[{"atl":[[44,0]],"id":41910350}],"con":true,"img":false}]}
{"op":"mcm","clk":"5353221779","pt":1646211343075,"mc":[{"id":"1.195453766","rc":[{"atl":[[48,1.38],[50,4.72],[60,0]],"id":41910350}],"con":true,"img":false}]}
{"op":"mcm","clk":"5353221784","pt":1646211343282,"mc":[{"id":"1.195453766","rc":[{"atb":[[11,22.5],[14.5,0]],"id":42162698},{"atb":[[3.3,8.7],[3.4,0]],"id":39637621},{"atl":[[5.3,4]],"id":39637621},{"atl":[[10,2.22],[9.6,2.68]],"id":41818763},{"atb":[[1.43,0],[1.68,0],[1.67,0],[1.86,149.92],[1.66,0],[1.65,0],[1.59,96.15],[1.72,27.78],[1.54,0]],"id":42154339},{"atl":[[2.36,14.49],[2.46,0]],"id":42154339},{"atb":[[6.4,0],[6.2,3.85]],"id":42688787},{"atl":[[11,4]],"id":42688787}],"con":true,"img":false}]}
{"op":"mcm","clk":"5353221787","pt":1646211343338,"mc":[{"id":"1.195453766","rc":[{"atl":[[15,1.24],[15.5,1.38]],"id":42688787}],"con":true,"img":false}]}
{"op":"mcm","clk":"5353221792","pt":1646211343449,"mc":[{"id":"1.195453766","rc":[{"atl":[[5.2,4]],"id":39637621},{"atb":[[1.48,0],[1.86,147.92]],"id":42154339},{"atl":[[10.5,4]],"id":42688787}],"con":true,"img":false}]}
{"op":"mcm","clk":"5353221795","pt":1646211343544,"mc":[{"id":"1.195453766","rc":[{"atb":[[8,1.65]],"id":42688787}],"con":true,"img":false}]}
{"op":"mcm","clk":"5353221802","pt":1646211343646,"mc":[{"id":"1.195453766","rc":[{"atl":[[6.8,0],[5.1,2],[6.6,14.41]],"id":39637621},{"atl":[[2.36,0],[2.38,14.28]],"id":42154339},{"atb":[[8,0],[1.02,3.25]],"id":42688787},{"atl":[[10,2],[14.5,2.77],[15.5,0]],"id":42688787}],"con":true,"img":false}]}
{"op":"mcm","clk":"5353221806","pt":1646211343748,"mc":[{"id":"1.195453766","rc":[{"atb":[[1.01,3.65]],"id":42688787}],"con":true,"img":false}]}
{"op":"mcm","clk":"5353221821","pt":1646211344054,"mc":[{"id":"1.195453766","rc":[{"atb":[[14.5,0.19]],"id":41910350}],"con":true,"img":false}]}
{"op":"mcm","clk":"5353221826","pt":1646211344259,"mc":[{"id":"1.195453766","rc":[{"atb":[[3.85,6.02]],"id":39637621},{"atl":[[2.44,0]],"id":42154339}],"con":true,"img":false}]}
{"op":"mcm","clk":"5353221829","pt":1646211344363,"mc":[{"id":"1.195453766","rc":[{"atb":[[1.02,3.28]],"id":39637621},{"atl":[[55,0]],"id":41910350}],"con":true,"img":false}]}
{"op":"mcm","clk":"5353221832","pt":1646211344464,"mc":[{"id":"1.195453766","rc":[{"atb":[[17.5,2.08]],"id":41910350},{"atl":[[75,2.72]],"id":41910350}],"con":true,"img":false}]}
{"op":"mcm","clk":"5353221837","pt":1646211344567,"mc":[{"id":"1.195453766","rc":[{"atb":[[9.2,0]],"id":42688787}],"con":true,"img":false}]}
{"op":"mcm","clk":"5353221841","pt":1646211344670,"mc":[{"id":"1.195453766","rc":[{"atl":[[48,0]],"id":41910350},{"atb":[[9,0.19],[8.6,2.31]],"id":42688787}],"con":true,"img":false}]}
{"op":"mcm","clk":"5353221845","pt":1646211344772,"mc":[{"id":"1.195453766","rc":[{"atl":[[1000,1.38]],"id":41910350}],"con":true,"img":false}]}
{"op":"mcm","clk":"5353221848","pt":1646211344876,"mc":[{"id":"1.195453766","rc":[{"atb":[[8.2,2.45],[8.6,0.31]],"id":42688787}],"con":true,"img":false}]}
{"op":"mcm","clk":"5353221852","pt":1646211345081,"mc":[{"id":"1.195453766","rc":[{"atb":[[1.01,5.32],[8.2,0.45],[8.8,0]],"id":42688787}],"con":true,"img":false}]}
{"op":"mcm","clk":"5353221856","pt":1646211345185,"mc":[{"id":"1.195453766","rc":[{"atb":[[8.6,2.31]],"id":42688787}],"con":true,"img":false}]}
{"op":"mcm","clk":"5353221860","pt":1646211345240,"mc":[{"id":"1.195453766","rc":[{"atb":[[1.01,4.6]],"id":42688787}],"con":true,"img":false}]}
{"op":"mcm","clk":"5353221864","pt":1646211345345,"mc":[{"id":"1.195453766","rc":[{"atb":[[1.02,1.26]],"id":42688787}],"con":true,"img":false}]}
{"op":"mcm","clk":"5353221868","pt":1646211345446,"mc":[{"id":"1.195453766","rc":[{"atb":[[8,1.99],[1.01,3.65]],"id":42688787}],"con":true,"img":false}]}
{"op":"mcm","clk":"5353221874","pt":1646211345548,"mc":[{"id":"1.195453766","rc":[{"atb":[[8.4,0.95]],"id":42688787}],"con":true,"img":false}]}
{"op":"mcm","clk":"5353221893","pt":1646211345953,"mc":[{"id":"1.195453766","rc":[{"atb":[[17,0],[18,2]],"id":41910350}],"con":true,"img":false}]}
{"op":"mcm","clk":"5353221909","pt":1646211346467,"mc":[{"id":"1.195453766","rc":[{"atl":[[50,2]],"id":41910350}],"con":true,"img":false}]}
{"op":"mcm","clk":"5353221913","pt":1646211346571,"mc":[{"id":"1.195453766","rc":[{"atb":[[3.4,8.33]],"id":39637621},{"atl":[[5.3,0],[5.1,0],[5.2,0]],"id":39637621},{"atb":[[1.2,2.25]],"id":41910350},{"atl":[[55,2.72]],"id":41910350},{"atb":[[6.4,3.7],[6.2,0]],"id":42688787},{"atl":[[10,0],[10.5,0],[11,0]],"id":42688787}],"con":true,"img":false}]}
{"op":"mcm","clk":"5353221920","pt":1646211346775,"mc":[{"id":"1.195453766","rc":[{"atb":[[1.2,1.75]],"id":41910350}],"con":true,"img":false}]}
{"op":"mcm","clk":"5353221940","pt":1646211347086,"mc":[{"id":"1.195453766","rc":[{"atb":[[1.2,0],[13.5,0]],"id":41910350},{"atb":[[8,0]],"id":42688787},{"atl":[[14.5,1.48]],"id":42688787}],"con":true,"img":false}]}
{"op":"mcm","clk":"5353221947","pt":1646211347189,"mc":[{"id":"1.195453766","rc":[{"atb":[[12.5,9.23],[14.5,1.94],[17.5,0]],"id":41910350},{"atb":[[1.02,3.25]],"id":42688787},{"atl":[[15.5,1.29]],"id":42688787}],"con":true,"img":false}]}
{"op":"mcm","clk":"5353221956","pt":1646211347356,"mc":[{"id":"1.195453766","rc":[{"atb":[[16.5,2.66],[18,0]],"id":41910350}],"con":true,"img":false}]}
{"op":"mcm","clk":"5353222006","pt":1646211348279,"mc":[{"id":"1.195453766","rc":[{"atl":[[50,0],[55,4.72]],"id":41910350}],"con":true,"img":false}]}
{"op":"mcm","clk":"5353222012","pt":1646211348381,"mc":[{"id":"1.195453766","rc":[{"atl":[[55,2.72]],"id":41910350}],"con":true,"img":false}]}
{"op":"mcm","clk":"5353222020","pt":1646211348484,"mc":[{"id":"1.195453766","rc":[{"atl":[[55,4.72]],"id":41910350}],"con":true,"img":false}]}
{"op":"mcm","clk":"5353222028","pt":1646211348544,"mc":[{"id":"1.195453766","rc":[{"atb":[[8.8,2.5]],"id":42688787}],"con":true,"img":false}]}
{"op":"mcm","clk":"5353222032","pt":1646211348690,"mc":[{"id":"1.195453766","rc":[{"atl":[[6.8,3.45],[6.6,10.84]],"id":39637621},{"atl":[[2.36,14.49]],"id":42154339},{"atl":[[14.5,0],[15,2.67]],"id":42688787}],"con":true,"img":false}]}
{"op":"mcm","clk":"5353222037","pt":1646211348749,"mc":[{"id":"1.195453766","rc":[{"atl":[[2.38,0]],"id":42154339}],"con":true,"img":false}]}
{"op":"mcm","clk":"5353222198","pt":1646211352494,"mc":[{"id":"1.195453766","rc":[{"atb":[[14,0]],"id":41910350}],"con":true,"img":false}]}
{"op":"mcm","clk":"5353222203","pt":1646211352597,"mc":[{"id":"1.195453766","rc":[{"atb":[[13.5,4.33]],"id":41910350}],"con":true,"img":false}]}
{"op":"mcm","clk":"5353222232","pt":1646211353162,"mc":[{"id":"1.195453766","rc":[{"atb":[[10,0]],"id":43167133}],"con":true,"img":false}]}
{"op":"mcm","clk":"5353222238","pt":1646211353264,"mc":[{"id":"1.195453766","rc":[{"atl":[[11,12.5]],"id":41818763},{"atb":[[10.5,1.42]],"id":43167133}],"con":true,"img":false}]}
{"op":"mcm","clk":"5353222245","pt":1646211353367,"mc":[{"id":"1.195453766","rc":[{"atl":[[11,5]],"id":41818763}],"con":true,"img":false}]}
{"op":"mcm","clk":"5353222309","pt":1646211355065,"mc":[{"id":"1.195453766","rc":[{"atb":[[14.5,0.19]],"id":41910350}],"con":true,"img":false}]}
{"op":"mcm","clk":"5353222319","pt":1646211355270,"mc":[{"id":"1.195453766","rc":[{"atb":[[1.86,149.92]],"id":42154339},{"atl":[[2.36,0],[2.46,13.5]],"id":42154339}],"con":true,"img":false}]}
