{"op":"mcm","clk":"5346220771","pt":1646178839802,"mc":[{"id":"1.195453653","marketDefinition":{"bspMarket":false,"turnInPlayEnabled":false,"persistenceEnabled":false,"marketBaseRate":7.0,"eventId":"31272494","eventTypeId":"4339","numberOfWinners":1,"bettingType":"ODDS","marketType":"MATCH_BET","marketTime":"2022-03-02T09:11:00.000Z","suspendTime":"2022-03-02T09:11:00.000Z","bspReconciled":false,"complete":true,"inPlay":false,"crossMatching":true,"runnersVoidable":false,"numberOfActiveRunners":2,"betDelay":0,"status":"OPEN","runners":[{"status":"ACTIVE","sortPriority":1,"id":37326143,"name":"2. Lee Will"},{"status":"ACTIVE","sortPriority":2,"id":35772529,"name":"4. Bombers Smokey"}],"regulators":["MR_INT"],"venue":"Traralgon","countryCode":"AU","discountAllowed":true,"timezone":"Australia/Sydney","openDate":"2022-03-02T08:31:00.000Z","version":4382489937,"name":"Lee Will v Bombers Smokey","eventName":"Traralgon (AUS) 2nd Mar"},"rc":[],"con":true,"img":false}]}
{"op":"mcm","clk":"5346224660","pt":1646178919306,"mc":[{"id":"1.195453653","rc":[{"atb":[[1.55,9.79],[1.75,7.18],[1.65,8.29]],"id":35772529},{"atb":[[1.73,7.38],[1.83,6.49],[1.63,8.55]],"id":37326143}],"con":true,"img":false}]}
{"op":"mcm","clk":"5346401474","pt":1646182002783,"mc":[{"id":"1.195453653","marketDefinition":{"bspMarket":false,"turnInPlayEnabled":false,"persistenceEnabled":false,"marketBaseRate":7.0,"eventId":"31272494","eventTypeId":"4339","numberOfWinners":1,"bettingType":"ODDS","marketType":"MATCH_BET","marketTime":"2022-03-02T09:11:00.000Z","suspendTime":"2022-03-02T09:11:00.000Z","bspReconciled":false,"complete":true,"inPlay":false,"crossMatching":true,"runnersVoidable":false,"numberOfActiveRunners":2,"betDelay":0,"status":"OPEN","runners":[{"status":"ACTIVE","sortPriority":1,"id":37326143,"name":"2. Lee Will"},{"status":"ACTIVE","sortPriority":2,"id":35772529,"name":"4. Bombers Smokey"}],"regulators":["MR_INT"],"venue":"Traralgon","countryCode":"AU","discountAllowed":true,"timezone":"Australia/Sydney","openDate":"2022-03-02T08:31:00.000Z","version":4382489937,"name":"Lee Will v Bombers Smokey","eventName":"Traralgon (AUS) 2nd Mar"},"rc":[{"atb":[[1.55,9.79],[1.75,7.18],[1.65,8.29]],"id":35772529},{"atb":[[1.73,7.38],[1.83,6.49],[1.63,8.55]],"id":37326143}],"con":true,"img":true}]}
{"op":"mcm","clk":"5346767829","pt":1646187402727,"mc":[{"id":"1.195453653","marketDefinition":{"bspMarket":false,"turnInPlayEnabled":false,"persistenceEnabled":false,"marketBaseRate":7.0,"eventId":"31272494","eventTypeId":"4339","numberOfWinners":1,"bettingType":"ODDS","marketType":"MATCH_BET","marketTime":"2022-03-02T09:11:00.000Z","suspendTime":"2022-03-02T09:11:00.000Z","bspReconciled":false,"complete":true,"inPlay":false,"crossMatching":true,"runnersVoidable":false,"numberOfActiveRunners":2,"betDelay":0,"status":"OPEN","runners":[{"status":"ACTIVE","sortPriority":1,"id":37326143,"name":"2. Lee Will"},{"status":"ACTIVE","sortPriority":2,"id":35772529,"name":"4. Bombers Smokey"}],"regulators":["MR_INT"],"venue":"Traralgon","countryCode":"AU","discountAllowed":true,"timezone":"Australia/Sydney","openDate":"2022-03-02T08:31:00.000Z","version":4382489937,"name":"Lee Will v Bombers Smokey","eventName":"Traralgon (AUS) 2nd Mar"},"rc":[{"atb":[[1.55,9.81],[1.75,7.19],[1.65,8.3]],"id":35772529},{"atb":[[1.73,7.39],[1.83,6.5],[1.63,8.56]],"id":37326143}],"con":true,"img":true}]}
{"op":"mcm","clk":"5347092380","pt":1646192802707,"mc":[{"id":"1.195453653","marketDefinition":{"bspMarket":false,"turnInPlayEnabled":false,"persistenceEnabled":false,"marketBaseRate":7.0,"eventId":"31272494","eventTypeId":"4339","numberOfWinners":1,"bettingType":"ODDS","marketType":"MATCH_BET","marketTime":"2022-03-02T09:11:00.000Z","suspendTime":"2022-03-02T09:11:00.000Z","bspReconciled":false,"complete":true,"inPlay":false,"crossMatching":true,"runnersVoidable":false,"numberOfActiveRunners":2,"betDelay":0,"status":"OPEN","runners":[{"status":"ACTIVE","sortPriority":1,"id":37326143,"name":"2. Lee Will"},{"status":"ACTIVE","sortPriority":2,"id":35772529,"name":"4. Bombers Smokey"}],"regulators":["MR_INT"],"venue":"Traralgon","countryCode":"AU","discountAllowed":true,"timezone":"Australia/Sydney","openDate":"2022-03-02T08:31:00.000Z","version":4382489937,"name":"Lee Will v Bombers Smokey","eventName":"Traralgon (AUS) 2nd Mar"},"rc":[{"atb":[[1.55,9.83],[1.75,7.2],[1.65,8.31]],"id":35772529},{"atb":[[1.73,7.4],[1.83,6.51],[1.63,8.58]],"id":37326143}],"con":true,"img":true}]}
{"op":"mcm","clk":"5347381241","pt":1646198202725,"mc":[{"id":"1.195453653","marketDefinition":{"bspMarket":false,"turnInPlayEnabled":false,"persistenceEnabled":false,"marketBaseRate":7.0,"eventId":"31272494","eventTypeId":"4339","numberOfWinners":1,"bettingType":"ODDS","marketType":"MATCH_BET","marketTime":"2022-03-02T09:11:00.000Z","suspendTime":"2022-03-02T09:11:00.000Z","bspReconciled":false,"complete":true,"inPlay":false,"crossMatching":true,"runnersVoidable":false,"numberOfActiveRunners":2,"betDelay":0,"status":"OPEN","runners":[{"status":"ACTIVE","sortPriority":1,"id":37326143,"name":"2. Lee Will"},{"status":"ACTIVE","sortPriority":2,"id":35772529,"name":"4. Bombers Smokey"}],"regulators":["MR_INT"],"venue":"Traralgon","countryCode":"AU","discountAllowed":true,"timezone":"Australia/Sydney","openDate":"2022-03-02T08:31:00.000Z","version":4382489937,"name":"Lee Will v Bombers Smokey","eventName":"Traralgon (AUS) 2nd Mar"},"rc":[{"atb":[[1.55,9.82],[1.75,7.2],[1.65,8.31]],"id":35772529},{"atb":[[1.73,7.4],[1.83,6.51],[1.63,8.57]],"id":37326143}],"con":true,"img":true}]}
{"op":"mcm","clk":"5347433872","pt":1646199293450,"mc":[{"id":"1.195453653","rc":[{"atb":[[1.55,0],[1.75,0],[1.65,0]],"id":35772529},{"atb":[[1.73,0],[1.83,0],[1.63,0]],"id":37326143}],"con":true,"img":false}]}
{"op":"mcm","clk":"5347434503","pt":1646199305807,"mc":[{"id":"1.195453653","rc":[{"atb":[[1.82,6.59],[1.72,7.5],[1.92,5.87]],"id":35772529},{"atb":[[1.62,8.71],[1.42,12.86],[1.52,10.39]],"id":37326143}],"con":true,"img":false}]}
{"op":"mcm","clk":"5347848913","pt":1646209002729,"mc":[{"id":"1.195453653","marketDefinition":{"bspMarket":false,"turnInPlayEnabled":false,"persistenceEnabled":false,"marketBaseRate":7.0,"eventId":"31272494","eventTypeId":"4339","numberOfWinners":1,"bettingType":"ODDS","marketType":"MATCH_BET","marketTime":"2022-03-02T09:11:00.000Z","suspendTime":"2022-03-02T09:11:00.000Z","bspReconciled":false,"complete":true,"inPlay":false,"crossMatching":true,"runnersVoidable":false,"numberOfActiveRunners":2,"betDelay":0,"status":"OPEN","runners":[{"status":"ACTIVE","sortPriority":1,"id":37326143,"name":"2. Lee Will"},{"status":"ACTIVE","sortPriority":2,"id":35772529,"name":"4. Bombers Smokey"}],"regulators":["MR_INT"],"venue":"Traralgon","countryCode":"AU","discountAllowed":true,"timezone":"Australia/Sydney","openDate":"2022-03-02T08:31:00.000Z","version":4382489937,"name":"Lee Will v Bombers Smokey","eventName":"Traralgon (AUS) 2nd Mar"},"rc":[{"atb":[[1.82,6.58],[1.72,7.5],[1.92,5.87]],"id":35772529},{"atb":[[1.62,8.71],[1.42,12.86],[1.52,10.39]],"id":37326143}],"con":true,"img":true}]}
{"op":"mcm","clk":"5347952079","pt":1646211162085,"mc":[{"id":"1.195453653","rc":[{"atb":[[1.82,6.58],[1.72,7.5],[1.92,5.87],[1.95,2]],"id":35772529},{"atl":[[2.96,2]],"id":35772529},{"atb":[[1.62,8.71],[1.42,12.86],[1.48,2],[1.52,10.39]],"id":37326143},{"atl":[[2.08,2]],"id":37326143}],"con":true,"img":false}]}
{"op":"mcm","clk":"5347954862","pt":1646211222154,"mc":[{"id":"1.195453653","rc":[{"atb":[[1.95,0]],"id":35772529},{"atl":[[2.96,0]],"id":35772529},{"atb":[[1.48,0]],"id":37326143},{"atl":[[2.08,0]],"id":37326143}],"con":true,"img":false}]}
{"op":"mcm","clk":"5347955854","pt":1646211243180,"mc":[{"id":"1.195453653","rc":[{"atb":[[1.95,2]],"id":35772529},{"atl":[[3.1,2]],"id":35772529},{"atb":[[1.46,2]],"id":37326143},{"atl":[[2.08,2]],"id":37326143}],"con":true,"img":false}]}
{"op":"mcm","clk":"5347958717","pt":1646211297334,"mc":[{"id":"1.195453653","rc":[{"atl":[[2.06,2],[2.08,0]],"id":37326143}],"con":true,"img":false}]}
{"op":"mcm","clk":"5347959008","pt":1646211303260,"mc":[{"id":"1.195453653","rc":[{"atb":[[1.95,0]],"id":35772529},{"atl":[[3.1,0]],"id":35772529},{"atb":[[1.46,0]],"id":37326143},{"atl":[[2.06,0]],"id":37326143}],"con":true,"img":false}]}
{"op":"mcm","clk":"5347959124","pt":1646211305583,"mc":[{"id":"1.195453653","rc":[{"atb":[[1.95,13.18]],"id":35772529},{"atl":[[2.88,13.18]],"id":35772529},{"atb":[[1.48,2]],"id":37326143},{"atl":[[2.06,2]],"id":37326143}],"con":true,"img":false}]}
{"op":"mcm","clk":"5347959601","pt":1646211316309,"mc":[{"id":"1.195453653","rc":[{"atb":[[1.94,13.18],[1.95,0]],"id":35772529}],"con":true,"img":false}]}
{"op":"mcm","clk":"5347959807","pt":1646211321403,"mc":[{"id":"1.195453653","rc":[{"atb":[[1.93,13.18]],"id":35772529}],"con":true,"img":false}]}
{"op":"mcm","clk":"5347959813","pt":1646211321506,"mc":[{"id":"1.195453653","rc":[{"atb":[[1.94,0]],"id":35772529}],"con":true,"img":false}]}
{"op":"mcm","clk":"5347961444","pt":1646211360426,"mc":[{"id":"1.195453653","rc":[{"atb":[[1.93,0]],"id":35772529},{"atl":[[2.04,20.78]],"id":37326143}],"con":true,"img":false}]}
{"op":"mcm","clk":"5347961450","pt":1646211360529,"mc":[{"id":"1.195453653","rc":[{"atb":[[1.98,13.18]],"id":35772529},{"atl":[[2.06,0]],"id":37326143}],"con":true,"img":false}]}
{"op":"mcm","clk":"5347961704","pt":1646211365640,"mc":[{"id":"1.195453653","rc":[{"atb":[[1.98,0],[1.94,13.18]],"id":35772529}],"con":true,"img":false}]}
{"op":"mcm","clk":"5347961950","pt":1646211370745,"mc":[{"id":"1.195453653","rc":[{"atb":[[1.94,0],[1.93,13.18]],"id":35772529}],"con":true,"img":false}]}
{"op":"mcm","clk":"5347964361","pt":1646211419440,"mc":[{"id":"1.195453653","rc":[{"atb":[[1.82,0],[1.72,0],[1.92,0]],"id":35772529},{"atb":[[1.62,0],[1.42,0],[1.52,0]],"id":37326143}],"con":true,"img":false}]}
{"op":"mcm","clk":"5347964539","pt":1646211422597,"mc":[{"id":"1.195453653","rc":[{"atb":[[1.82,6.58],[1.72,7.5],[1.92,5.87]],"id":35772529},{"atb":[[1.62,8.71],[1.42,12.86],[1.52,10.39]],"id":37326143}],"con":true,"img":false}]}
{"op":"mcm","clk":"5347971275","pt":1646211580839,"mc":[{"id":"1.195453653","rc":[{"atb":[[1.96,2],[1.93,0]],"id":35772529}],"con":true,"img":false}]}
{"op":"mcm","clk":"5347971694","pt":1646211590278,"mc":[{"id":"1.195453653","rc":[{"atb":[[1.96,0],[1.95,2]],"id":35772529}],"con":true,"img":false}]}
{"op":"mcm","clk":"5347971915","pt":1646211595503,"mc":[{"id":"1.195453653","rc":[{"atb":[[1.96,2],[1.95,0]],"id":35772529}],"con":true,"img":false}]}
{"op":"mcm","clk":"5347972988","pt":1646211613915,"mc":[{"id":"1.195453653","rc":[{"atb":[[1.82,6.57],[1.72,7.49],[1.92,5.86],[1.96,0],[1.95,2]],"id":35772529},{"atb":[[1.62,8.7],[1.42,12.84],[1.52,10.37]],"id":37326143}],"con":true,"img":false}]}
{"op":"mcm","clk":"5347973526","pt":1646211624755,"mc":[{"id":"1.195453653","rc":[{"atb":[[1.94,2],[1.95,0]],"id":35772529}],"con":true,"img":false}]}
{"op":"mcm","clk":"5347973801","pt":1646211630215,"mc":[{"id":"1.195453653","rc":[{"atb":[[1.98,2],[1.94,0]],"id":35772529}],"con":true,"img":false}]}
{"op":"mcm","clk":"5347974236","pt":1646211638656,"mc":[{"id":"1.195453653","rc":[{"atb":[[2,2],[1.98,0]],"id":35772529}],"con":true,"img":false}]}
{"op":"mcm","clk":"5347974814","pt":1646211649966,"mc":[{"id":"1.195453653","rc":[{"atb":[[2,0],[1.99,2]],"id":35772529}],"con":true,"img":false}]}
{"op":"mcm","clk":"5347975094","pt":1646211656675,"mc":[{"id":"1.195453653","rc":[{"atb":[[2,2],[1.99,0]],"id":35772529}],"con":true,"img":false}]}
{"op":"mcm","clk":"5347975452","pt":1646211663692,"mc":[{"id":"1.195453653","rc":[{"atl":[[2.02,2],[2.04,0]],"id":37326143}],"con":true,"img":false}]}
{"op":"mcm","clk":"5347976185","pt":1646211676452,"mc":[{"id":"1.195453653","rc":[{"atb":[[2,0],[2.04,2]],"id":35772529},{"atl":[[2,2],[2.02,0]],"id":37326143}],"con":true,"img":false}]}
{"op":"mcm","clk":"5347976491","pt":1646211681509,"mc":[{"id":"1.195453653","rc":[{"atb":[[2.06,2],[2.04,0]],"id":35772529},{"atl":[[2,0],[1.98,2]],"id":37326143}],"con":true,"img":false}]}
{"op":"mcm","clk":"5347976770","pt":1646211686633,"mc":[{"id":"1.195453653","rc":[{"atb":[[2.06,0]],"id":35772529},{"atl":[[1.98,0],[1.94,2]],"id":37326143}],"con":true,"img":false}]}
{"op":"mcm","clk":"5347976779","pt":1646211686736,"mc":[{"id":"1.195453653","rc":[{"atb":[[2.12,2]],"id":35772529}],"con":true,"img":false}]}
{"op":"mcm","clk":"5347977165","pt":1646211694370,"mc":[{"id":"1.195453653","rc":[{"atb":[[2.12,0],[2.14,2]],"id":35772529},{"atl":[[1.94,0],[1.93,2]],"id":37326143}],"con":true,"img":false}]}
{"op":"mcm","clk":"5347977413","pt":1646211699531,"mc":[{"id":"1.195453653","rc":[{"atb":[[2.14,0],[2.08,2]],"id":35772529}],"con":true,"img":false}]}
{"op":"mcm","clk":"5347977469","pt":1646211700778,"mc":[{"id":"1.195453653","rc":[{"atb":[[2.04,2],[2.08,0]],"id":35772529}],"con":true,"img":false}]}
{"op":"mcm","clk":"5347977473","pt":1646211700878,"mc":[{"id":"1.195453653","rc":[{"atb":[[2.06,2],[2.04,0]],"id":35772529}],"con":true,"img":false}]}
{"op":"mcm","clk":"5347977485","pt":1646211701188,"mc":[{"id":"1.195453653","rc":[{"atb":[[2.06,0],[2.08,2]],"id":35772529}],"con":true,"img":false}]}
{"op":"mcm","clk":"5347977489","pt":1646211701255,"mc":[{"id":"1.195453653","rc":[{"atb":[[2.06,2]],"id":35772529}],"con":true,"img":false}]}
{"op":"mcm","clk":"5347977493","pt":1646211701347,"mc":[{"id":"1.195453653","rc":[{"atb":[[2.08,0]],"id":35772529}],"con":true,"img":false}]}
{"op":"mcm","clk":"5347977508","pt":1646211701660,"mc":[{"id":"1.195453653","rc":[{"atl":[[2.88,0],[2.9,2]],"id":35772529}],"con":true,"img":false}]}
{"op":"mcm","clk":"5347977574","pt":1646211702750,"mc":[{"id":"1.195453653","rc":[{"atl":[[1.92,2]],"id":37326143}],"con":true,"img":false}]}
{"op":"mcm","clk":"5347977581","pt":1646211702853,"mc":[{"id":"1.195453653","rc":[{"atl":[[1.93,0]],"id":37326143}],"con":true,"img":false}]}
{"op":"mcm","clk":"5347977769","pt":1646211706466,"mc":[{"id":"1.195453653","rc":[{"atb":[[2.06,0],[2.04,2]],"id":35772529}],"con":true,"img":false}]}
{"op":"mcm","clk":"5347977851","pt":1646211707959,"mc":[{"id":"1.195453653","rc":[{"atl":[[1.92,0],[1.93,2]],"id":37326143}],"con":true,"img":false}]}
{"op":"mcm","clk":"5347978027","pt":1646211711617,"mc":[{"id":"1.195453653","rc":[{"atb":[[2.04,0],[1.96,2]],"id":35772529}],"con":true,"img":false}]}
{"op":"mcm","clk":"5347978223","pt":1646211717173,"mc":[{"id":"1.195453653","rc":[{"atb":[[1.97,2],[1.96,0]],"id":35772529}],"con":true,"img":false}]}
{"op":"mcm","clk":"5347978288","pt":1646211718766,"mc":[{"id":"1.195453653","rc":[{"atb":[[1.99,2]],"id":35772529}],"con":true,"img":false}]}
{"op":"mcm","clk":"5347978290","pt":1646211718866,"mc":[{"id":"1.195453653","rc":[{"atb":[[1.97,0]],"id":35772529}],"con":true,"img":false}]}
{"op":"mcm","clk":"5347979200","pt":1646211740413,"mc":[{"id":"1.195453653","rc":[{"atb":[[1.99,0],[1.98,2]],"id":35772529}],"con":true,"img":false}]}
{"op":"mcm","clk":"5347979485","pt":1646211747963,"mc":[{"id":"1.195453653","rc":[{"atb":[[1.98,0],[1.97,2]],"id":35772529}],"con":true,"img":false}]}
{"op":"mcm","clk":"5347979673","pt":1646211753278,"mc":[{"id":"1.195453653","rc":[{"atb":[[2.02,2],[1.97,0]],"id":35772529}],"con":true,"img":false}]}
{"op":"mcm","clk":"5347979901","pt":1646211758395,"mc":[{"id":"1.195453653","rc":[{"atb":[[2,2],[2.02,0]],"id":35772529}],"con":true,"img":false}]}
{"op":"mcm","clk":"5347980143","pt":1646211763492,"mc":[{"id":"1.195453653","rc":[{"atb":[[2,0],[2.06,2]],"id":35772529}],"con":true,"img":false}]}
{"op":"mcm","clk":"5347980466","pt":1646211771495,"mc":[{"id":"1.195453653","rc":[{"atb":[[2.06,0],[2.04,2]],"id":35772529}],"con":true,"img":false}]}
{"op":"mcm","clk":"5347980922","pt":1646211780297,"mc":[{"id":"1.195453653","rc":[{"atb":[[2.02,2],[2.04,0]],"id":35772529}],"con":true,"img":false}]}
{"op":"mcm","clk":"5347981185","pt":1646211785412,"mc":[{"id":"1.195453653","rc":[{"atb":[[1.99,2]],"id":35772529}],"con":true,"img":false}]}
{"op":"mcm","clk":"5347981191","pt":1646211785524,"mc":[{"id":"1.195453653","rc":[{"atb":[[2.02,0]],"id":35772529}],"con":true,"img":false}]}
{"op":"mcm","clk":"5347981197","pt":1646211785620,"mc":[{"id":"1.195453653","rc":[{"atb":[[1.99,0],[1.97,2]],"id":35772529}],"con":true,"img":false}]}
{"op":"mcm","clk":"5347982241","pt":1646211804546,"mc":[{"id":"1.195453653","rc":[{"atl":[[2.9,0],[2.84,2]],"id":35772529}],"con":true,"img":false}]}
{"op":"mcm","clk":"5347983134","pt":1646211820970,"mc":[{"id":"1.195453653","rc":[{"atb":[[1.97,0],[1.93,2]],"id":35772529}],"con":true,"img":false}]}
{"op":"mcm","clk":"5347983800","pt":1646211832500,"mc":[{"id":"1.195453653","rc":[{"atl":[[2.24,8],[2.3,11],[2.22,7],[2.28,10],[2.18,5],[2.2,6],[2.26,9]],"id":37326143}],"con":true,"img":false}]}
{"op":"mcm","clk":"5347983808","pt":1646211832602,"mc":[{"id":"1.195453653","rc":[{"atl":[[1.93,0],[2.1,2]],"id":37326143}],"con":true,"img":false}]}
{"op":"mcm","clk":"5347984108","pt":1646211837804,"mc":[{"id":"1.195453653","rc":[{"atl":[[2.12,2],[2.1,0]],"id":37326143}],"con":true,"img":false}]}
{"op":"mcm","clk":"5347984345","pt":1646211842439,"mc":[{"id":"1.195453653","rc":[{"atb":[[1.95,1.42]],"id":35772529},{"atl":[[14.5,1.42]],"id":35772529},{"atl":[[14.5,1.42]],"id":37326143}],"con":true,"img":false}]}
{"op":"mcm","clk":"5347984355","pt":1646211842644,"mc":[{"id":"1.195453653","rc":[{"atb":[[1.95,3.42],[1.93,0]],"id":35772529},{"atl":[[2.12,0],[2.1,2]],"id":37326143}],"con":true,"img":false}]}
{"op":"mcm","clk":"5347984359","pt":1646211842747,"mc":[{"id":"1.195453653","rc":[{"atb":[[1.93,2]],"id":35772529}],"con":true,"img":false}]}
{"op":"mcm","clk":"5347984365","pt":1646211842850,"mc":[{"id":"1.195453653","rc":[{"atb":[[1.95,1.42]],"id":35772529}],"con":true,"img":false}]}
{"op":"mcm","clk":"5347984372","pt":1646211843056,"mc":[{"id":"1.195453653","rc":[{"atb":[[1.95,3.42],[1.93,0]],"id":35772529}],"con":true,"img":false}]}
{"op":"mcm","clk":"5347984390","pt":1646211843522,"mc":[{"id":"1.195453653","rc":[{"atb":[[1.97,1.42]],"id":35772529},{"atl":[[15,1.42]],"id":35772529},{"atl":[[2.12,2],[2.1,0],[15,1.42]],"id":37326143}],"con":true,"img":false}]}
{"op":"mcm","clk":"5347984420","pt":1646211844241,"mc":[{"id":"1.195453653","rc":[{"atb":[[1.95,2]],"id":35772529}],"con":true,"img":false}]}
{"op":"mcm","clk":"5347984449","pt":1646211844913,"mc":[{"id":"1.195453653","rc":[{"atb":[[1.97,2.84]],"id":35772529},{"atl":[[15,2.84]],"id":35772529},{"atl":[[15,2.84]],"id":37326143}],"con":true,"img":false}]}
{"op":"mcm","clk":"5347984516","pt":1646211846354,"mc":[{"id":"1.195453653","rc":[{"atb":[[1.96,1.42]],"id":35772529},{"atl":[[15.5,1.42]],"id":35772529},{"atl":[[15.5,1.42]],"id":37326143}],"con":true,"img":false}]}
{"op":"mcm","clk":"5347984571","pt":1646211847328,"mc":[{"id":"1.195453653","rc":[{"atl":[[14.5,0]],"id":35772529}],"con":true,"img":false}]}
{"op":"mcm","clk":"5347984605","pt":1646211848148,"mc":[{"id":"1.195453653","rc":[{"atb":[[1.97,4.84]],"id":35772529}],"con":true,"img":false}]}
{"op":"mcm","clk":"5347984607","pt":1646211848250,"mc":[{"id":"1.195453653","rc":[{"atb":[[1.96,3.42],[1.95,0]],"id":35772529}],"con":true,"img":false}]}
{"op":"mcm","clk":"5347984609","pt":1646211848352,"mc":[{"id":"1.195453653","rc":[{"atb":[[1.97,2.84]],"id":35772529}],"con":true,"img":false}]}
{"op":"mcm","clk":"5347984613","pt":1646211848455,"mc":[{"id":"1.195453653","rc":[{"atb":[[1.97,0]],"id":35772529}],"con":true,"img":false}]}
{"op":"mcm","clk":"5347984648","pt":1646211849329,"mc":[{"id":"1.195453653","rc":[{"atl":[[2.12,0],[2.1,2]],"id":37326143}],"con":true,"img":false}]}
{"op":"mcm","clk":"5347984654","pt":1646211849431,"mc":[{"id":"1.195453653","rc":[{"atb":[[1.99,1.42]],"id":35772529},{"atl":[[16,1.42]],"id":35772529},{"atl":[[16,1.42]],"id":37326143}],"con":true,"img":false}]}
{"op":"mcm","clk":"5347984657","pt":1646211849533,"mc":[{"id":"1.195453653","rc":[{"atb":[[1.99,3.42],[1.96,1.42]],"id":35772529}],"con":true,"img":false}]}
{"op":"mcm","clk":"5347984672","pt":1646211849841,"mc":[{"id":"1.195453653","rc":[{"atb":[[1.96,0]],"id":35772529}],"con":true,"img":false}]}
{"op":"mcm","clk":"5347984728","pt":1646211850976,"mc":[{"id":"1.195453653","rc":[{"atb":[[1.97,1.42]],"id":35772529},{"atl":[[16.5,1.42]],"id":35772529},{"atl":[[16.5,1.42]],"id":37326143}],"con":true,"img":false}]}
{"op":"mcm","clk":"5347984770","pt":1646211851743,"mc":[{"id":"1.195453653","rc":[{"atb":[[1.99,2]],"id":35772529}],"con":true,"img":false}]}
{"op":"mcm","clk":"5347984786","pt":1646211851946,"mc":[{"id":"1.195453653","rc":[{"atb":[[1.99,0],[1.97,3.42]],"id":35772529}],"con":true,"img":false}]}
{"op":"mcm","clk":"5347984798","pt":1646211852151,"mc":[{"id":"1.195453653","rc":[{"atl":[[16.5,2.84]],"id":35772529},{"atl":[[16.5,2.84]],"id":37326143}],"con":true,"img":false}]}
{"op":"mcm","clk":"5347984836","pt":1646211853028,"mc":[{"id":"1.195453653","rc":[{"atb":[[1.97,2]],"id":35772529}],"con":true,"img":false}]}
{"op":"mcm","clk":"5347984873","pt":1646211853847,"mc":[{"id":"1.195453653","rc":[{"atl":[[17,1.42]],"id":35772529},{"atl":[[17,1.42]],"id":37326143}],"con":true,"img":false}]}
{"op":"mcm","clk":"5347984882","pt":1646211854051,"mc":[{"id":"1.195453653","rc":[{"atl":[[2.82,2],[2.84,0]],"id":35772529}],"con":true,"img":false}]}
{"op":"mcm","clk":"5347984940","pt":1646211854974,"mc":[{"id":"1.195453653","rc":[{"atl":[[17.5,1.42]],"id":35772529},{"atl":[[17.5,1.42]],"id":37326143}],"con":true,"img":false}]}
{"op":"mcm","clk":"5347984988","pt":1646211856155,"mc":[{"id":"1.195453653","rc":[{"atl":[[18,1.42]],"id":35772529},{"atl":[[18,1.42]],"id":37326143}],"con":true,"img":false}]}
{"op":"mcm","clk":"5347985027","pt":1646211857085,"mc":[{"id":"1.195453653","rc":[{"atb":[[1.97,0],[1.93,2]],"id":35772529}],"con":true,"img":false}]}
{"op":"mcm","clk":"5347985034","pt":1646211857132,"mc":[{"id":"1.195453653","rc":[{"atl":[[18.5,1.42]],"id":35772529},{"atl":[[18.5,1.42]],"id":37326143}],"con":true,"img":false}]}
{"op":"mcm","clk":"5347985064","pt":1646211857650,"mc":[{"id":"1.195453653","rc":[{"atl":[[2.12,2],[2.1,0]],"id":37326143}],"con":true,"img":false}]}
{"op":"mcm","clk":"5347985096","pt":1646211858264,"mc":[{"id":"1.195453653","rc":[{"atl":[[18.5,2.84]],"id":35772529},{"atl":[[18.5,2.84]],"id":37326143}],"con":true,"img":false}]}
{"op":"mcm","clk":"5347985153","pt":1646211859241,"mc":[{"id":"1.195453653","rc":[{"atl":[[2.82,0],[2.84,2]],"id":35772529}],"con":true,"img":false}]}
{"op":"mcm","clk":"5347985213","pt":1646211860878,"mc":[{"id":"1.195453653","rc":[{"atb":[[1.95,1.42]],"id":35772529},{"atl":[[19,1.42]],"id":35772529}],"con":true,"img":false}]}
{"op":"mcm","clk":"5347985219","pt":1646211860981,"mc":[{"id":"1.195453653","rc":[{"atb":[[1.95,3.42]],"id":35772529}],"con":true,"img":false}]}
{"op":"mcm","clk":"5347985224","pt":1646211861084,"mc":[{"id":"1.195453653","rc":[{"atb":[[1.93,0]],"id":35772529}],"con":true,"img":false}]}
{"op":"mcm","clk":"5347985278","pt":1646211861959,"mc":[{"id":"1.195453653","rc":[{"atb":[[1.82,0],[1.72,0],[1.92,0]],"id":35772529},{"atb":[[1.62,0],[1.42,0],[1.52,0]],"id":37326143}],"con":true,"img":false}]}
{"op":"mcm","clk":"5347985285","pt":1646211862066,"mc":[{"id":"1.195453653","rc":[{"atb":[[1.49,2],[1.48,0]],"id":37326143}],"con":true,"img":false}]}
{"op":"mcm","clk":"5347985296","pt":1646211862272,"mc":[{"id":"1.195453653","rc":[{"atb":[[1.94,1.42]],"id":35772529},{"atl":[[19.5,1.42]],"id":35772529}],"con":true,"img":false}]}
{"op":"mcm","clk":"5347985321","pt":1646211862790,"mc":[{"id":"1.195453653","rc":[{"atb":[[1.95,2]],"id":35772529},{"atl":[[2.14,2]],"id":37326143}],"con":true,"img":false}]}
{"op":"mcm","clk":"5347985329","pt":1646211862894,"mc":[{"id":"1.195453653","rc":[{"atl":[[2.12,0]],"id":37326143}],"con":true,"img":false}]}
{"op":"mcm","clk":"5347985334","pt":1646211862953,"mc":[{"id":"1.195453653","rc":[{"atb":[[1.94,3.42],[1.95,0]],"id":35772529}],"con":true,"img":false}]}
{"op":"mcm","clk":"5347985375","pt":1646211863773,"mc":[{"id":"1.195453653","rc":[{"atb":[[1.97,1.42]],"id":35772529}],"con":true,"img":false}]}
{"op":"mcm","clk":"5347985413","pt":1646211864390,"mc":[{"id":"1.195453653","rc":[{"atl":[[2.9,2],[2.84,0]],"id":35772529}],"con":true,"img":false}]}
{"op":"mcm","clk":"5347985441","pt":1646211864965,"mc":[{"id":"1.195453653","rc":[{"atb":[[1.96,1.42]],"id":35772529},{"atl":[[13.5,1.42]],"id":37326143}],"con":true,"img":false}]}
{"op":"mcm","clk":"5347985466","pt":1646211865367,"mc":[{"id":"1.195453653","rc":[{"atb":[[1.97,0]],"id":35772529}],"con":true,"img":false}]}
{"op":"mcm","clk":"5347985507","pt":1646211866294,"mc":[{"id":"1.195453653","rc":[{"atl":[[14.5,1.42]],"id":35772529},{"atl":[[13,1.42]],"id":37326143}],"con":true,"img":false}]}
{"op":"mcm","clk":"5347985567","pt":1646211867579,"mc":[{"id":"1.195453653","rc":[{"atb":[[1.97,1.42]],"id":35772529},{"atl":[[14,1.42]],"id":35772529},{"atl":[[12.5,1.42]],"id":37326143}],"con":true,"img":false}]}
{"op":"mcm","clk":"5347985590","pt":1646211868092,"mc":[{"id":"1.195453653","rc":[{"atb":[[1.97,3.42]],"id":35772529}],"con":true,"img":false}]}
{"op":"mcm","clk":"5347985593","pt":1646211868193,"mc":[{"id":"1.195453653","rc":[{"atb":[[1.94,1.42]],"id":35772529}],"con":true,"img":false}]}
{"op":"mcm","clk":"5347985618","pt":1646211868916,"mc":[{"id":"1.195453653","rc":[{"atl":[[13.5,1.42]],"id":35772529},{"atl":[[14,1.42]],"id":37326143}],"con":true,"img":false}]}
{"op":"mcm","clk":"5347985622","pt":1646211869020,"mc":[{"id":"1.195453653","rc":[{"atb":[[1.82,6.57],[1.72,7.49],[1.92,5.86]],"id":35772529},{"atb":[[1.62,8.7],[1.42,12.84],[1.52,10.37]],"id":37326143}],"con":true,"img":false}]}
{"op":"mcm","clk":"5347985653","pt":1646211869484,"mc":[{"id":"1.195453653","rc":[{"atb":[[1.97,2]],"id":35772529},{"atl":[[2.84,2],[2.9,0]],"id":35772529}],"con":true,"img":false}]}
{"op":"mcm","clk":"5347985685","pt":1646211870104,"mc":[{"id":"1.195453653","rc":[{"atb":[[1.98,1.42]],"id":35772529},{"atl":[[13.5,2.84]],"id":35772529},{"atl":[[12,1.42]],"id":37326143}],"con":true,"img":false}]}
{"op":"mcm","clk":"5347985864","pt":1646211873298,"mc":[{"id":"1.195453653","rc":[{"atb":[[2,1.42]],"id":35772529},{"atl":[[13,1.42]],"id":35772529}],"con":true,"img":false}]}
{"op":"mcm","clk":"5347985874","pt":1646211873503,"mc":[{"id":"1.195453653","rc":[{"atb":[[2,3.42],[1.97,0]],"id":35772529}],"con":true,"img":false}]}
{"op":"mcm","clk":"5347985880","pt":1646211873607,"mc":[{"id":"1.195453653","rc":[{"atb":[[2,1.42],[1.98,3.42]],"id":35772529}],"con":true,"img":false}]}
{"op":"mcm","clk":"5347985890","pt":1646211873709,"mc":[{"id":"1.195453653","rc":[{"atb":[[2,3.42],[1.98,1.42]],"id":35772529}],"con":true,"img":false}]}
{"op":"mcm","clk":"5347985917","pt":1646211874279,"mc":[{"id":"1.195453653","rc":[{"atb":[[1.99,1.42]],"id":35772529}],"con":true,"img":false}]}
{"op":"mcm","clk":"5347985949","pt":1646211874992,"mc":[{"id":"1.195453653","rc":[{"atb":[[1.94,0]],"id":35772529},{"atl":[[13,0]],"id":35772529},{"atl":[[12,0]],"id":37326143}],"con":true,"img":false}]}
{"op":"mcm","clk":"5347986007","pt":1646211876487,"mc":[{"id":"1.195453653","rc":[{"atb":[[2,2],[1.99,0],[1.98,0],[1.96,0]],"id":35772529}],"con":true,"img":false}]}
{"op":"mcm","clk":"5347986051","pt":1646211877314,"mc":[{"id":"1.195453653","rc":[{"atb":[[2.02,1.42]],"id":35772529}],"con":true,"img":false}]}
{"op":"mcm","clk":"5347986062","pt":1646211877623,"mc":[{"id":"1.195453653","rc":[{"atl":[[13.5,0]],"id":35772529}],"con":true,"img":false}]}
{"op":"mcm","clk":"5347986092","pt":1646211878599,"mc":[{"id":"1.195453653","rc":[{"atl":[[12.5,0]],"id":37326143}],"con":true,"img":false}]}
{"op":"mcm","clk":"5347986162","pt":1646211880400,"mc":[{"id":"1.195453653","rc":[{"atl":[[14,0]],"id":35772529},{"atl":[[13,0]],"id":37326143}],"con":true,"img":false}]}
{"op":"mcm","clk":"5347986175","pt":1646211880708,"mc":[{"id":"1.195453653","rc":[{"atl":[[2.82,2],[2.84,0]],"id":35772529}],"con":true,"img":false}]}
{"op":"mcm","clk":"5347986220","pt":1646211881790,"mc":[{"id":"1.195453653","rc":[{"atl":[[14.5,0],[15,0]],"id":35772529},{"atl":[[13.5,0]],"id":37326143}],"con":true,"img":false}]}
{"op":"mcm","clk":"5347986258","pt":1646211882614,"mc":[{"id":"1.195453653","rc":[{"atl":[[20,1.42]],"id":35772529}],"con":true,"img":false}]}
{"op":"mcm","clk":"5347986284","pt":1646211882923,"mc":[{"id":"1.195453653","rc":[{"atl":[[15.5,0]],"id":35772529},{"atl":[[14,0]],"id":37326143}],"con":true,"img":false}]}
{"op":"mcm","clk":"5347986307","pt":1646211883439,"mc":[{"id":"1.195453653","rc":[{"atl":[[2.12,2],[2.14,0]],"id":37326143}],"con":true,"img":false}]}
{"op":"mcm","clk":"5347986319","pt":1646211883704,"mc":[{"id":"1.195453653","rc":[{"atl":[[21,1.42]],"id":35772529},{"atl":[[19,1.42]],"id":37326143}],"con":true,"img":false}]}
{"op":"mcm","clk":"5347986355","pt":1646211884425,"mc":[{"id":"1.195453653","rc":[{"atl":[[14.5,0]],"id":37326143}],"con":true,"img":false}]}
{"op":"mcm","clk":"5347986402","pt":1646211885100,"mc":[{"id":"1.195453653","rc":[{"atl":[[19.5,1.42]],"id":37326143}],"con":true,"img":false}]}
{"op":"mcm","clk":"5347986460","pt":1646211886242,"mc":[{"id":"1.195453653","rc":[{"atl":[[19.5,2.84]],"id":37326143}],"con":true,"img":false}]}
{"op":"mcm","clk":"5347986531","pt":1646211887526,"mc":[{"id":"1.195453653","rc":[{"atl":[[16,0]],"id":35772529}],"con":true,"img":false}]}
{"op":"mcm","clk":"5347986547","pt":1646211887731,"mc":[{"id":"1.195453653","rc":[{"atl":[[22,1.42]],"id":35772529}],"con":true,"img":false}]}
{"op":"mcm","clk":"5347986588","pt":1646211888507,"mc":[{"id":"1.195453653","rc":[{"atl":[[2.12,0],[2.06,2]],"id":37326143}],"con":true,"img":false}]}
{"op":"mcm","clk":"5347987195","pt":1646211900437,"mc":[{"id":"1.195453653","rc":[{"atb":[[2,0],[2.02,3.42]],"id":35772529},{"atl":[[2.02,2],[2.06,0]],"id":37326143}],"con":true,"img":false}]}
{"op":"mcm","clk":"5347987202","pt":1646211900538,"mc":[{"id":"1.195453653","rc":[{"atl":[[2.02,11.67]],"id":37326143}],"con":true,"img":false}]}
{"op":"mcm","clk":"5347987206","pt":1646211900639,"mc":[{"id":"1.195453653","rc":[{"atb":[[2.04,8.52]],"id":35772529},{"atl":[[2.82,10.52]],"id":35772529},{"atb":[[1.63,10.06]],"id":37326143}],"con":true,"img":false}]}
{"op":"mcm","clk":"5347987211","pt":1646211900746,"mc":[{"id":"1.195453653","rc":[{"atb":[[2.02,1.42],[2.06,2]],"id":35772529}],"con":true,"img":false}]}
{"op":"mcm","clk":"5347987292","pt":1646211902819,"mc":[{"id":"1.195453653","rc":[{"atb":[[2.02,0]],"id":35772529},{"atl":[[15,0]],"id":37326143}],"con":true,"img":false}]}
{"op":"mcm","clk":"5347987307","pt":1646211903028,"mc":[{"id":"1.195453653","rc":[{"atb":[[2.06,10.5]],"id":35772529}],"con":true,"img":false}]}
{"op":"mcm","clk":"5347987364","pt":1646211903963,"mc":[{"id":"1.195453653","rc":[{"atl":[[15.5,1.42]],"id":35772529},{"atl":[[20,1.42]],"id":37326143}],"con":true,"img":false}]}
{"op":"mcm","clk":"5347987499","pt":1646211906433,"mc":[{"id":"1.195453653","rc":[{"atl":[[15.5,0]],"id":35772529}],"con":true,"img":false}]}
{"op":"mcm","clk":"5347987581","pt":1646211908133,"mc":[{"id":"1.195453653","rc":[{"atl":[[15.5,0]],"id":37326143}],"con":true,"img":false}]}
{"op":"mcm","clk":"5347987623","pt":1646211909057,"mc":[{"id":"1.195453653","rc":[{"atb":[[2.2,1.42]],"id":35772529},{"atl":[[16,1.42]],"id":35772529},{"atl":[[21,1.42]],"id":37326143}],"con":true,"img":false}]}
{"op":"mcm","clk":"5347987631","pt":1646211909261,"mc":[{"id":"1.195453653","rc":[{"atb":[[2.06,8.5],[2.2,3.42]],"id":35772529}],"con":true,"img":false}]}
{"op":"mcm","clk":"5347987687","pt":1646211910451,"mc":[{"id":"1.195453653","rc":[{"atb":[[2.2,4.84]],"id":35772529},{"atl":[[16,2.84]],"id":35772529},{"atl":[[21,2.84]],"id":37326143}],"con":true,"img":false}]}
{"op":"mcm","clk":"5347987750","pt":1646211911745,"mc":[{"id":"1.195453653","rc":[{"atb":[[2.2,3.42]],"id":35772529},{"atl":[[16,1.42]],"id":35772529},{"atl":[[16,0]],"id":37326143}],"con":true,"img":false}]}
{"op":"mcm","clk":"5347987849","pt":1646211913857,"mc":[{"id":"1.195453653","rc":[{"atb":[[2.2,2]],"id":35772529},{"atl":[[16,0],[16.5,0],[17,0]],"id":35772529},{"atl":[[16.5,0]],"id":37326143}],"con":true,"img":false}]}
{"op":"mcm","clk":"5347987871","pt":1646211914372,"mc":[{"id":"1.195453653","rc":[{"atb":[[2.2,0],[2.08,2]],"id":35772529}],"con":true,"img":false}]}
{"op":"mcm","clk":"5347987886","pt":1646211914786,"mc":[{"id":"1.195453653","rc":[{"atb":[[2.24,1.42]],"id":35772529},{"atl":[[23,1.42]],"id":35772529},{"atl":[[22,1.42]],"id":37326143}],"con":true,"img":false}]}
{"op":"mcm","clk":"5347987897","pt":1646211914943,"mc":[{"id":"1.195453653","rc":[{"atb":[[2.24,3.42],[2.08,8.51]],"id":35772529}],"con":true,"img":false}]}
{"op":"mcm","clk":"5347987919","pt":1646211915463,"mc":[{"id":"1.195453653","rc":[{"atl":[[17.5,0],[18,0],[18.5,0],[19,0]],"id":35772529},{"atl":[[17,0],[17.5,0]],"id":37326143}],"con":true,"img":false}]}
{"op":"mcm","clk":"5347987976","pt":1646211916384,"mc":[{"id":"1.195453653","rc":[{"atb":[[2.22,1.42]],"id":35772529},{"atl":[[23,2.84]],"id":35772529},{"atl":[[22,2.84]],"id":37326143}],"con":true,"img":false}]}
{"op":"mcm","clk":"5347988002","pt":1646211916955,"mc":[{"id":"1.195453653","rc":[{"atb":[[2.24,2]],"id":35772529},{"atl":[[19.5,0],[20,0]],"id":35772529},{"atl":[[18,0]],"id":37326143}],"con":true,"img":false}]}
{"op":"mcm","clk":"5347988039","pt":1646211917774,"mc":[{"id":"1.195453653","rc":[{"atb":[[2.16,1.42]],"id":35772529},{"atl":[[24,1.42]],"id":35772529},{"atl":[[23,1.42]],"id":37326143}],"con":true,"img":false}]}
{"op":"mcm","clk":"5347988086","pt":1646211918752,"mc":[{"id":"1.195453653","rc":[{"atl":[[21,0]],"id":35772529},{"atl":[[18.5,0],[19,0]],"id":37326143}],"con":true,"img":false}]}
{"op":"mcm","clk":"5347988152","pt":1646211919986,"mc":[{"id":"1.195453653","rc":[{"atb":[[2.14,1.42]],"id":35772529},{"atl":[[25,1.42]],"id":35772529},{"atl":[[24,1.42]],"id":37326143}],"con":true,"img":false}]}
{"op":"mcm","clk":"5347988167","pt":1646211920194,"mc":[{"id":"1.195453653","rc":[{"atb":[[2.24,0],[2.22,3.42]],"id":35772529}],"con":true,"img":false}]}
{"op":"mcm","clk":"5347988217","pt":1646211921070,"mc":[{"id":"1.195453653","rc":[{"atl":[[22,0]],"id":35772529},{"atl":[[19.5,0],[20,0]],"id":37326143}],"con":true,"img":false}]}
{"op":"mcm","clk":"5347988272","pt":1646211922152,"mc":[{"id":"1.195453653","rc":[{"atb":[[2.12,1.42]],"id":35772529},{"atl":[[26,1.42]],"id":35772529},{"atl":[[26,1.42]],"id":37326143}],"con":true,"img":false}]}
{"op":"mcm","clk":"5347988313","pt":1646211922974,"mc":[{"id":"1.195453653","rc":[{"atb":[[2.22,2]],"id":35772529},{"atl":[[23,0]],"id":35772529}],"con":true,"img":false}]}
{"op":"mcm","clk":"5347988358","pt":1646211923954,"mc":[{"id":"1.195453653","rc":[{"atb":[[2.1,1.42]],"id":35772529},{"atl":[[27,1.42]],"id":35772529},{"atl":[[27,1.42]],"id":37326143}],"con":true,"img":false}]}
{"op":"mcm","clk":"5347988377","pt":1646211924361,"mc":[{"id":"1.195453653","rc":[{"atl":[[24,0]],"id":35772529},{"atl":[[21,0]],"id":37326143}],"con":true,"img":false}]}
{"op":"mcm","clk":"5347988409","pt":1646211925292,"mc":[{"id":"1.195453653","rc":[{"atb":[[2.22,0],[2.16,3.42]],"id":35772529}],"con":true,"img":false}]}
{"op":"mcm","clk":"5347988412","pt":1646211925396,"mc":[{"id":"1.195453653","rc":[{"atl":[[28,1.42]],"id":35772529},{"atl":[[28,1.42]],"id":37326143}],"con":true,"img":false}]}
{"op":"mcm","clk":"5347988432","pt":1646211925879,"mc":[{"id":"1.195453653","rc":[{"atl":[[25,0]],"id":35772529},{"atl":[[22,0]],"id":37326143}],"con":true,"img":false}]}
{"op":"mcm","clk":"5347988444","pt":1646211926168,"mc":[{"id":"1.195453653","rc":[{"atb":[[2.1,9.84]],"id":35772529}],"con":true,"img":false}]}
{"op":"mcm","clk":"5347988480","pt":1646211926892,"mc":[{"id":"1.195453653","rc":[{"atl":[[29,1.42]],"id":35772529},{"atl":[[29,1.42]],"id":37326143}],"con":true,"img":false}]}
{"op":"mcm","clk":"5347988486","pt":1646211926996,"mc":[{"id":"1.195453653","rc":[{"atl":[[2,2],[2.02,9.67]],"id":37326143}],"con":true,"img":false}]}
{"op":"mcm","clk":"5347988511","pt":1646211927463,"mc":[{"id":"1.195453653","rc":[{"atb":[[2.16,2]],"id":35772529},{"atl":[[23,0]],"id":37326143}],"con":true,"img":false}]}
{"op":"mcm","clk":"5347988531","pt":1646211927873,"mc":[{"id":"1.195453653","rc":[{"atl":[[29,2.84]],"id":35772529},{"atl":[[30,1.42]],"id":37326143}],"con":true,"img":false}]}
{"op":"mcm","clk":"5347988596","pt":1646211929791,"mc":[{"id":"1.195453653","rc":[{"atb":[[2.2,1.42]],"id":35772529},{"atl":[[30,1.42]],"id":35772529},{"atl":[[30,2.84]],"id":37326143}],"con":true,"img":false}]}
{"op":"mcm","clk":"5347988605","pt":1646211930000,"mc":[{"id":"1.195453653","rc":[{"atl":[[2,11.96]],"id":37326143}],"con":true,"img":false}]}
{"op":"mcm","clk":"5347988622","pt":1646211930369,"mc":[{"id":"1.195453653","rc":[{"atb":[[2.2,3.42],[2.16,0]],"id":35772529}],"con":true,"img":false}]}
{"op":"mcm","clk":"5347988625","pt":1646211930470,"mc":[{"id":"1.195453653","rc":[{"atb":[[2.2,1.42],[2.16,2]],"id":35772529}],"con":true,"img":false}]}
{"op":"mcm","clk":"5347988629","pt":1646211930574,"mc":[{"id":"1.195453653","rc":[{"atb":[[2.2,3.42],[2.16,0]],"id":35772529}],"con":true,"img":false}]}
{"op":"mcm","clk":"5347988702","pt":1646211932291,"mc":[{"id":"1.195453653","rc":[{"atl":[[2,9.96],[1.97,2]],"id":37326143}],"con":true,"img":false}]}
{"op":"mcm","clk":"5347988714","pt":1646211932499,"mc":[{"id":"1.195453653","rc":[{"atb":[[2.2,2]],"id":35772529}],"con":true,"img":false}]}
{"op":"mcm","clk":"5347988733","pt":1646211932706,"mc":[{"id":"1.195453653","rc":[{"atb":[[2.2,0],[2.14,3.42]],"id":35772529}],"con":true,"img":false}]}
{"op":"mcm","clk":"5347988782","pt":1646211933780,"mc":[{"id":"1.195453653","rc":[{"atb":[[2.24,1.42]],"id":35772529},{"atl":[[32,1.42]],"id":35772529},{"atl":[[32,1.42]],"id":37326143}],"con":true,"img":false}]}
{"op":"mcm","clk":"5347988791","pt":1646211933986,"mc":[{"id":"1.195453653","rc":[{"atl":[[1.97,12]],"id":37326143}],"con":true,"img":false}]}
{"op":"mcm","clk":"5347988801","pt":1646211934194,"mc":[{"id":"1.195453653","rc":[{"atb":[[2.14,2]],"id":35772529}],"con":true,"img":false}]}
{"op":"mcm","clk":"5347988849","pt":1646211935174,"mc":[{"id":"1.195453653","rc":[{"atl":[[34,1.42]],"id":35772529},{"atl":[[34,1.42]],"id":37326143}],"con":true,"img":false}]}
{"op":"mcm","clk":"5347988864","pt":1646211935496,"mc":[{"id":"1.195453653","rc":[{"atb":[[2.24,0]],"id":35772529}],"con":true,"img":false}]}
{"op":"mcm","clk":"5347988899","pt":1646211936405,"mc":[{"id":"1.195453653","rc":[{"atl":[[34,2.84]],"id":35772529},{"atl":[[34,2.84]],"id":37326143}],"con":true,"img":false}]}
{"op":"mcm","clk":"5347988934","pt":1646211937383,"mc":[{"id":"1.195453653","rc":[{"atl":[[1.96,2],[1.97,10]],"id":37326143}],"con":true,"img":false}]}
{"op":"mcm","clk":"5347988939","pt":1646211937586,"mc":[{"id":"1.195453653","rc":[{"atl":[[32,0],[34,1.42],[24,0],[26,0],[27,0],[28,0],[29,0],[30,0]],"id":37326143}],"con":true,"img":false}]}
{"op":"mcm","clk":"5347988946","pt":1646211937792,"mc":[{"id":"1.195453653","rc":[{"atb":[[2.12,3.42],[2.14,0]],"id":35772529}],"con":true,"img":false}]}
{"op":"mcm","clk":"5347988948","pt":1646211937998,"mc":[{"id":"1.195453653","rc":[{"atb":[[2.22,1.42]],"id":35772529},{"atl":[[36,1.42]],"id":35772529}],"con":true,"img":false}]}
{"op":"mcm","clk":"5347988952","pt":1646211938205,"mc":[{"id":"1.195453653","rc":[{"atl":[[1.96,12.01]],"id":37326143}],"con":true,"img":false}]}
{"op":"mcm","clk":"5347988998","pt":1646211939611,"mc":[{"id":"1.195453653","rc":[{"atb":[[2.16,1.42]],"id":35772529}],"con":true,"img":false}]}
{"op":"mcm","clk":"5347989006","pt":1646211939808,"mc":[{"id":"1.195453653","rc":[{"atb":[[2.22,0]],"id":35772529},{"atl":[[34,0]],"id":37326143}],"con":true,"img":false}]}
{"op":"mcm","clk":"5347989065","pt":1646211940997,"mc":[{"id":"1.195453653","rc":[{"atb":[[2.24,1.42]],"id":35772529}],"con":true,"img":false}]}
{"op":"mcm","clk":"5347989074","pt":1646211941204,"mc":[{"id":"1.195453653","rc":[{"atb":[[2.04,0],[2.12,11.76]],"id":35772529}],"con":true,"img":false}]}
{"op":"mcm","clk":"5347989132","pt":1646211942395,"mc":[{"id":"1.195453653","rc":[{"atb":[[2.24,2.84]],"id":35772529},{"atl":[[1.84,1.42]],"id":37326143}],"con":true,"img":false}]}
{"op":"mcm","clk":"5347989136","pt":1646211942495,"mc":[{"id":"1.195453653","rc":[{"atl":[[1.84,3.42],[1.96,10.01]],"id":37326143}],"con":true,"img":false}]}
{"op":"mcm","clk":"5347989157","pt":1646211942908,"mc":[{"id":"1.195453653","rc":[{"atb":[[2.24,3.42],[2.12,9.76]],"id":35772529}],"con":true,"img":false}]}
{"op":"mcm","clk":"5347989169","pt":1646211943217,"mc":[{"id":"1.195453653","rc":[{"atb":[[2.06,0],[2.16,9.52]],"id":35772529}],"con":true,"img":false}]}
{"op":"mcm","clk":"5347989178","pt":1646211943523,"mc":[{"id":"1.195453653","rc":[{"atb":[[2.14,1.42]],"id":35772529},{"atl":[[1.83,1.42]],"id":37326143}],"con":true,"img":false}]}
{"op":"mcm","clk":"5347989216","pt":1646211944812,"mc":[{"id":"1.195453653","rc":[{"atb":[[2.24,2]],"id":35772529}],"con":true,"img":false}]}
{"op":"mcm","clk":"5347989231","pt":1646211945223,"mc":[{"id":"1.195453653","rc":[{"atb":[[2.2,1.42]],"id":35772529},{"atl":[[38,1.42]],"id":35772529},{"atl":[[1.86,1.42]],"id":37326143}],"con":true,"img":false}]}
{"op":"mcm","clk":"5347989261","pt":1646211946104,"mc":[{"id":"1.195453653","rc":[{"atl":[[1.86,11.81]],"id":37326143}],"con":true,"img":false}]}
{"op":"mcm","clk":"5347989265","pt":1646211946204,"mc":[{"id":"1.195453653","rc":[{"atl":[[2.02,0]],"id":37326143}],"con":true,"img":false}]}
{"op":"mcm","clk":"5347989277","pt":1646211946622,"mc":[{"id":"1.195453653","rc":[{"atl":[[2.64,15]],"id":35772529}],"con":true,"img":false}]}
{"op":"mcm","clk":"5347989287","pt":1646211946823,"mc":[{"id":"1.195453653","rc":[{"atb":[[2.2,9.33],[2.08,0]],"id":35772529},{"atl":[[2,0],[1.83,12.13]],"id":37326143}],"con":true,"img":false}]}
{"op":"mcm","clk":"5347989289","pt":1646211946926,"mc":[{"id":"1.195453653","rc":[{"atb":[[2.28,1.42]],"id":35772529},{"atl":[[38,2.84]],"id":35772529},{"atl":[[1.86,13.23]],"id":37326143}],"con":true,"img":false}]}
{"op":"mcm","clk":"5347989309","pt":1646211947290,"mc":[{"id":"1.195453653","rc":[{"atl":[[2.22,9],[2.26,11],[2.24,10],[2.28,12],[2.18,7],[2.2,8],[2.16,2]],"id":37326143}],"con":true,"img":false}]}
{"op":"mcm","clk":"5347989317","pt":1646211947599,"mc":[{"id":"1.195453653","rc":[{"atl":[[1.84,1.42],[1.82,2]],"id":37326143}],"con":true,"img":false}]}
{"op":"mcm","clk":"5347989332","pt":1646211947907,"mc":[{"id":"1.195453653","rc":[{"atb":[[2.14,0]],"id":35772529}],"con":true,"img":false}]}
{"op":"mcm","clk":"5347989341","pt":1646211948109,"mc":[{"id":"1.195453653","rc":[{"atb":[[2.24,0],[2.28,3.42]],"id":35772529},{"atl":[[1.82,12.77]],"id":37326143}],"con":true,"img":false}]}
{"op":"mcm","clk":"5347989344","pt":1646211948213,"mc":[{"id":"1.195453653","rc":[{"atb":[[2.22,2],[2.28,1.42]],"id":35772529},{"atl":[[1.97,0]],"id":37326143}],"con":true,"img":false}]}
{"op":"mcm","clk":"5347989349","pt":1646211948314,"mc":[{"id":"1.195453653","rc":[{"atb":[[2.3,1.42]],"id":35772529},{"atl":[[23,1.42]],"id":35772529},{"atl":[[1.85,1.42]],"id":37326143}],"con":true,"img":false}]}
{"op":"mcm","clk":"5347989354","pt":1646211948416,"mc":[{"id":"1.195453653","rc":[{"atb":[[2.22,7.84],[2.28,3.42]],"id":35772529}],"con":true,"img":false}]}
{"op":"mcm","clk":"5347989363","pt":1646211948622,"mc":[{"id":"1.195453653","rc":[{"atb":[[2.1,1.42]],"id":35772529}],"con":true,"img":false}]}
{"op":"mcm","clk":"5347989408","pt":1646211949504,"mc":[{"id":"1.195453653","rc":[{"atb":[[2.28,2],[2.12,8.33],[2.1,0]],"id":35772529},{"atl":[[1.86,10.39]],"id":37326143}],"con":true,"img":false}]}
{"op":"mcm","clk":"5347989458","pt":1646211950225,"mc":[{"id":"1.195453653","rc":[{"atb":[[2.34,1.42]],"id":35772529},{"atl":[[1.76,1.42]],"id":37326143}],"con":true,"img":false}]}
{"op":"mcm","clk":"5347989469","pt":1646211950431,"mc":[{"id":"1.195453653","rc":[{"atb":[[2.3,3.42],[2.28,0]],"id":35772529}],"con":true,"img":false}]}
{"op":"mcm","clk":"5347989524","pt":1646211951414,"mc":[{"id":"1.195453653","rc":[{"atb":[[2.16,8.09]],"id":35772529},{"atl":[[23,0]],"id":35772529},{"atl":[[1.84,0],[1.85,0]],"id":37326143}],"con":true,"img":false}]}
{"op":"mcm","clk":"5347989609","pt":1646211952712,"mc":[{"id":"1.195453653","rc":[{"atl":[[1.82,10.77],[1.79,2]],"id":37326143}],"con":true,"img":false}]}
{"op":"mcm","clk":"5347989647","pt":1646211953689,"mc":[{"id":"1.195453653","rc":[{"atb":[[1.82,0],[1.72,0],[1.92,0]],"id":35772529},{"atb":[[1.62,0],[1.42,0],[1.52,0]],"id":37326143}],"con":true,"img":false}]}
{"op":"mcm","clk":"5347989670","pt":1646211954210,"mc":[{"id":"1.195453653","rc":[{"atb":[[2.24,1.42]],"id":35772529},{"atl":[[1.8,1.42]],"id":37326143}],"con":true,"img":false}]}
{"op":"mcm","clk":"5347989673","pt":1646211954345,"mc":[{"id":"1.195453653","rc":[{"atl":[[1.83,10.71]],"id":37326143}],"con":true,"img":false}]}
{"op":"mcm","clk":"5347989719","pt":1646211955296,"mc":[{"id":"1.195453653","rc":[{"atl":[[40,1.42]],"id":35772529}],"con":true,"img":false}]}
{"op":"mcm","clk":"5347989723","pt":1646211955399,"mc":[{"id":"1.195453653","rc":[{"atl":[[26,0]],"id":35772529}],"con":true,"img":false}]}
{"op":"mcm","clk":"5347989767","pt":1646211956426,"mc":[{"id":"1.195453653","rc":[{"atl":[[42,1.42]],"id":35772529}],"con":true,"img":false}]}
{"op":"mcm","clk":"5347989776","pt":1646211956633,"mc":[{"id":"1.195453653","rc":[{"atl":[[27,0],[28,0]],"id":35772529},{"atl":[[1.76,0]],"id":37326143}],"con":true,"img":false}]}
{"op":"mcm","clk":"5347989785","pt":1646211956838,"mc":[{"id":"1.195453653","rc":[{"atl":[[1.8,3.42],[1.79,0]],"id":37326143}],"con":true,"img":false}]}
{"op":"mcm","clk":"5347989797","pt":1646211957044,"mc":[{"id":"1.195453653","rc":[{"atb":[[2.24,9.26],[2.12,0]],"id":35772529}],"con":true,"img":false}]}
{"op":"mcm","clk":"5347989842","pt":1646211957818,"mc":[{"id":"1.195453653","rc":[{"atl":[[44,1.42]],"id":35772529}],"con":true,"img":false}]}
{"op":"mcm","clk":"5347989849","pt":1646211958024,"mc":[{"id":"1.195453653","rc":[{"atb":[[2.2,7.9]],"id":35772529}],"con":true,"img":false}]}
{"op":"mcm","clk":"5347989902","pt":1646211959208,"mc":[{"id":"1.195453653","rc":[{"atl":[[46,1.42]],"id":35772529}],"con":true,"img":false}]}
{"op":"mcm","clk":"5347989920","pt":1646211959622,"mc":[{"id":"1.195453653","rc":[{"atl":[[29,0]],"id":35772529}],"con":true,"img":false}]}
{"op":"mcm","clk":"5347989973","pt":1646211960553,"mc":[{"id":"1.195453653","rc":[{"atl":[[46,2.84]],"id":35772529}],"con":true,"img":false}]}
{"op":"mcm","clk":"5347989989","pt":1646211960811,"mc":[{"id":"1.195453653","rc":[{"atl":[[30,0]],"id":35772529}],"con":true,"img":false}]}
{"op":"mcm","clk":"5347989999","pt":1646211961015,"mc":[{"id":"1.195453653","rc":[{"atl":[[2.62,7.83]],"id":35772529}],"con":true,"img":false}]}
{"op":"mcm","clk":"5347990056","pt":1646211962043,"mc":[{"id":"1.195453653","rc":[{"atl":[[48,1.42]],"id":35772529}],"con":true,"img":false}]}
{"op":"mcm","clk":"5347990116","pt":1646211963635,"mc":[{"id":"1.195453653","rc":[{"atl":[[32,0]],"id":35772529}],"con":true,"img":false}]}
{"op":"mcm","clk":"5347990216","pt":1646211965729,"mc":[{"id":"1.195453653","rc":[{"atl":[[50,1.42]],"id":35772529}],"con":true,"img":false}]}
{"op":"mcm","clk":"5347990244","pt":1646211966342,"mc":[{"id":"1.195453653","rc":[{"atb":[[2.24,1.42],[2.22,0],[2.2,0],[2.16,0]],"id":35772529},{"atl":[[1.83,0],[1.82,0],[1.86,0]],"id":37326143}],"con":true,"img":false}]}
{"op":"mcm","clk":"5347990278","pt":1646211967119,"mc":[{"id":"1.195453653","rc":[{"atb":[[1.99,5.44],[1.79,6.82],[1.89,6.06]],"id":35772529},{"atb":[[1.43,12.54],[1.33,16.34],[1.53,10.18]],"id":37326143}],"con":true,"img":false}]}
{"op":"mcm","clk":"5347990299","pt":1646211967641,"mc":[{"id":"1.195453653","rc":[{"atl":[[55,1.42]],"id":35772529}],"con":true,"img":false}]}
{"op":"mcm","clk":"5347990316","pt":1646211967951,"mc":[{"id":"1.195453653","rc":[{"atb":[[2.24,0],[2.3,2]],"id":35772529},{"atl":[[1.8,2]],"id":37326143}],"con":true,"img":false}]}
{"op":"mcm","clk":"5347990328","pt":1646211968159,"mc":[{"id":"1.195453653","rc":[{"atl":[[1.8,0],[1.95,2]],"id":37326143}],"con":true,"img":false}]}
{"op":"mcm","clk":"5347990356","pt":1646211968629,"mc":[{"id":"1.195453653","rc":[{"atb":[[2,8.19]],"id":35772529},{"atl":[[1.95,12.25]],"id":37326143}],"con":true,"img":false}]}
{"op":"mcm","clk":"5347990362","pt":1646211968731,"mc":[{"id":"1.195453653","rc":[{"atl":[[46,1.42]],"id":37326143}],"con":true,"img":false}]}
{"op":"mcm","clk":"5347990429","pt":1646211970338,"mc":[{"id":"1.195453653","rc":[{"atl":[[48,1.42]],"id":37326143}],"con":true,"img":false}]}
{"op":"mcm","clk":"5347990477","pt":1646211971517,"mc":[{"id":"1.195453653","rc":[{"atl":[[50,1.42]],"id":37326143}],"con":true,"img":false}]}
{"op":"mcm","clk":"5347990531","pt":1646211972869,"mc":[{"id":"1.195453653","rc":[{"atl":[[55,1.42]],"id":37326143}],"con":true,"img":false}]}
{"op":"mcm","clk":"5347990590","pt":1646211974158,"mc":[{"id":"1.195453653","rc":[{"atl":[[55,2.84],[1.95,10.25],[1.93,2]],"id":37326143}],"con":true,"img":false}]}
{"op":"mcm","clk":"5347990718","pt":1646211976392,"mc":[{"id":"1.195453653","rc":[{"atl":[[1.93,12.67]],"id":37326143}],"con":true,"img":false}]}
{"op":"mcm","clk":"5347990741","pt":1646211976855,"mc":[{"id":"1.195453653","rc":[{"atb":[[2.3,0],[2.32,2]],"id":35772529}],"con":true,"img":false}]}
{"op":"mcm","clk":"5347990810","pt":1646211978457,"mc":[{"id":"1.195453653","rc":[{"atb":[[2.08,1.42]],"id":35772529}],"con":true,"img":false}]}
{"op":"mcm","clk":"5347991047","pt":1646211983459,"mc":[{"id":"1.195453653","rc":[{"atb":[[2.08,9.4]],"id":35772529}],"con":true,"img":false}]}
{"op":"mcm","clk":"5347991177","pt":1646211986193,"mc":[{"id":"1.195453653","rc":[{"atb":[[2.1,1.42]],"id":35772529}],"con":true,"img":false}]}
{"op":"mcm","clk":"5347991235","pt":1646211987181,"mc":[{"id":"1.195453653","rc":[{"atb":[[2.32,0],[2.3,2]],"id":35772529}],"con":true,"img":false}]}
{"op":"mcm","clk":"5347991483","pt":1646211993309,"mc":[{"id":"1.195453653","rc":[{"atb":[[2.1,9.6]],"id":35772529}],"con":true,"img":false}]}
{"op":"mcm","clk":"5347991591","pt":1646211995993,"mc":[{"id":"1.195453653","rc":[{"atb":[[2.12,1.42]],"id":35772529}],"con":true,"img":false}]}
{"op":"mcm","clk":"5347991605","pt":1646211996203,"mc":[{"id":"1.195453653","rc":[{"atb":[[2.3,0],[2.32,2]],"id":35772529}],"con":true,"img":false}]}
{"op":"mcm","clk":"5347991834","pt":1646212001596,"mc":[{"id":"1.195453653","rc":[{"atb":[[2.12,9.73]],"id":35772529}],"con":true,"img":false}]}
{"op":"mcm","clk":"5347991920","pt":1646212003814,"mc":[{"id":"1.195453653","rc":[{"atl":[[46,0],[48,0],[50,0],[55,0]],"id":37326143}],"con":true,"img":false}]}
{"op":"mcm","clk":"5347991945","pt":1646212004325,"mc":[{"id":"1.195453653","rc":[{"atb":[[2.14,1.42]],"id":35772529},{"atl":[[1.89,1.42]],"id":37326143}],"con":true,"img":false}]}
{"op":"mcm","clk":"5347991955","pt":1646212004531,"mc":[{"id":"1.195453653","rc":[{"atl":[[1.89,3.42],[1.93,10.67]],"id":37326143}],"con":true,"img":false}]}
{"op":"mcm","clk":"5347992039","pt":1646212006429,"mc":[{"id":"1.195453653","rc":[{"atb":[[2.08,7.98]],"id":35772529}],"con":true,"img":false}]}
{"op":"mcm","clk":"5347992247","pt":1646212011121,"mc":[{"id":"1.195453653","rc":[{"atl":[[1.89,13.59]],"id":37326143}],"con":true,"img":false}]}
{"op":"mcm","clk":"5347992355","pt":1646212012834,"mc":[{"id":"1.195453653","rc":[{"atb":[[1.99,0],[1.79,0],[1.89,0]],"id":35772529},{"atb":[[1.43,0],[1.33,0],[1.53,0]],"id":37326143}],"con":true,"img":false}]}
{"op":"mcm","clk":"5347992374","pt":1646212013141,"mc":[{"id":"1.195453653","rc":[{"atb":[[2.1,8.18]],"id":35772529}],"con":true,"img":false}]}
{"op":"mcm","clk":"5347992467","pt":1646212014824,"mc":[{"id":"1.195453653","rc":[{"atl":[[1.89,12.17]],"id":37326143}],"con":true,"img":false}]}
{"op":"mcm","clk":"5347992587","pt":1646212017345,"mc":[{"id":"1.195453653","rc":[{"atl":[[46,1.42]],"id":37326143}],"con":true,"img":false}]}
{"op":"mcm","clk":"5347992663","pt":1646212018843,"mc":[{"id":"1.195453653","rc":[{"atl":[[46,2.84]],"id":37326143}],"con":true,"img":false}]}
{"op":"mcm","clk":"5347992669","pt":1646212019148,"mc":[{"id":"1.195453653","rc":[{"atb":[[2,0],[2.14,9.66]],"id":35772529}],"con":true,"img":false}]}
{"op":"mcm","clk":"5347992799","pt":1646212022056,"mc":[{"id":"1.195453653","rc":[{"atl":[[48,1.42]],"id":37326143}],"con":true,"img":false}]}
{"op":"mcm","clk":"5347992864","pt":1646212023349,"mc":[{"id":"1.195453653","rc":[{"atl":[[48,2.84]],"id":37326143}],"con":true,"img":false}]}
{"op":"mcm","clk":"5347992995","pt":1646212025361,"mc":[{"id":"1.195453653","rc":[{"atl":[[50,1.42]],"id":37326143}],"con":true,"img":false}]}
{"op":"mcm","clk":"5347993014","pt":1646212025668,"mc":[{"id":"1.195453653","rc":[{"atl":[[46,0],[48,0]],"id":37326143}],"con":true,"img":false}]}
{"op":"mcm","clk":"5347993069","pt":1646212026858,"mc":[{"id":"1.195453653","rc":[{"atb":[[1.99,5.44],[1.79,6.82],[1.89,6.06]],"id":35772529},{"atb":[[1.43,12.54],[1.33,16.34],[1.53,10.18]],"id":37326143}],"con":true,"img":false}]}
{"op":"mcm","clk":"5347993104","pt":1646212027584,"mc":[{"id":"1.195453653","rc":[{"atl":[[50,0]],"id":37326143}],"con":true,"img":false}]}
{"op":"mcm","clk":"5347993287","pt":1646212030985,"mc":[{"id":"1.195453653","rc":[{"atb":[[2.16,1.42]],"id":35772529},{"atl":[[1.87,1.42]],"id":37326143}],"con":true,"img":false}]}
{"op":"mcm","clk":"5347993297","pt":1646212031148,"mc":[{"id":"1.195453653","rc":[{"atl":[[1.89,10.17],[1.87,3.42]],"id":37326143}],"con":true,"img":false}]}
{"op":"mcm","clk":"5347993358","pt":1646212032281,"mc":[{"id":"1.195453653","rc":[{"atb":[[2.16,2.84]],"id":35772529},{"atl":[[1.87,4.84]],"id":37326143}],"con":true,"img":false}]}
{"op":"mcm","clk":"5347993517","pt":1646212035272,"mc":[{"id":"1.195453653","rc":[{"atl":[[1.86,1.42]],"id":37326143}],"con":true,"img":false}]}
{"op":"mcm","clk":"5347993615","pt":1646212036977,"mc":[{"id":"1.195453653","rc":[{"atl":[[1.86,2.84]],"id":37326143}],"con":true,"img":false}]}
{"op":"mcm","clk":"5347993907","pt":1646212042290,"mc":[{"id":"1.195453653","rc":[{"atl":[[1.85,10.45]],"id":37326143}],"con":true,"img":false}]}
{"op":"mcm","clk":"5347993913","pt":1646212042396,"mc":[{"id":"1.195453653","rc":[{"atb":[[2.18,8.08],[2.08,0]],"id":35772529},{"atl":[[1.96,0]],"id":37326143}],"con":true,"img":false}]}
{"op":"mcm","clk":"5347993920","pt":1646212042489,"mc":[{"id":"1.195453653","rc":[{"atl":[[1.84,2],[1.87,2.84]],"id":37326143}],"con":true,"img":false}]}
{"op":"mcm","clk":"5347993988","pt":1646212043780,"mc":[{"id":"1.195453653","rc":[{"atl":[[1.84,12.58]],"id":37326143}],"con":true,"img":false}]}
{"op":"mcm","clk":"5347994003","pt":1646212043985,"mc":[{"id":"1.195453653","rc":[{"atl":[[1.95,0]],"id":37326143}],"con":true,"img":false}]}
{"op":"mcm","clk":"5347994009","pt":1646212044089,"mc":[{"id":"1.195453653","rc":[{"atb":[[2.12,8.31]],"id":35772529}],"con":true,"img":false}]}
{"op":"mcm","clk":"5347994099","pt":1646212046097,"mc":[{"id":"1.195453653","rc":[{"atb":[[2.14,8.24]],"id":35772529},{"atl":[[1.87,0],[1.86,0]],"id":37326143}],"con":true,"img":false}]}
{"op":"mcm","clk":"5347994173","pt":1646212047487,"mc":[{"id":"1.195453653","rc":[{"atb":[[2.16,0]],"id":35772529}],"con":true,"img":false}]}
{"op":"mcm","clk":"5347995322","pt":1646212069730,"mc":[{"id":"1.195453653","rc":[{"atl":[[2.64,0]],"id":35772529}],"con":true,"img":false}]}
{"op":"mcm","clk":"5347995696","pt":1646212076820,"mc":[{"id":"1.195453653","rc":[{"atb":[[2.32,9.57]],"id":35772529}],"con":true,"img":false}]}
{"op":"mcm","clk":"5347995701","pt":1646212076927,"mc":[{"id":"1.195453653","rc":[{"atb":[[2.1,0]],"id":35772529}],"con":true,"img":false}]}
{"op":"mcm","clk":"5347995748","pt":1646212078050,"mc":[{"id":"1.195453653","rc":[{"atb":[[2.2,1.42]],"id":35772529}],"con":true,"img":false}]}
{"op":"mcm","clk":"5347996130","pt":1646212085759,"mc":[{"id":"1.195453653","rc":[{"atb":[[2.34,8.75]],"id":35772529}],"con":true,"img":false}]}
{"op":"mcm","clk":"5347996133","pt":1646212085863,"mc":[{"id":"1.195453653","rc":[{"atb":[[2.12,0]],"id":35772529}],"con":true,"img":false}]}
{"op":"mcm","clk":"5347996173","pt":1646212085966,"mc":[{"id":"1.195453653","rc":[{"atb":[[2.36,2],[2.32,7.57]],"id":35772529}],"con":true,"img":false}]}
{"op":"mcm","clk":"5347996270","pt":1646212087471,"mc":[{"id":"1.195453653","rc":[{"atb":[[2.2,0]],"id":35772529}],"con":true,"img":false}]}
{"op":"mcm","clk":"5347996307","pt":1646212088142,"mc":[{"id":"1.195453653","rc":[{"atb":[[2.36,9.33],[2.14,0]],"id":35772529}],"con":true,"img":false}]}
{"op":"mcm","clk":"5347996403","pt":1646212090160,"mc":[{"id":"1.195453653","rc":[{"atb":[[2.34,7.33]],"id":35772529}],"con":true,"img":false}]}
{"op":"mcm","clk":"5347996678","pt":1646212095670,"mc":[{"id":"1.195453653","rc":[{"atl":[[60,1.42]],"id":35772529}],"con":true,"img":false}]}
{"op":"mcm","clk":"5347996688","pt":1646212095880,"mc":[{"id":"1.195453653","rc":[{"atl":[[34,0]],"id":35772529}],"con":true,"img":false}]}
{"op":"mcm","clk":"5347997468","pt":1646212111105,"mc":[{"id":"1.195453653","rc":[{"atb":[[2.34,29.1]],"id":35772529},{"atb":[[1.54,54.02]],"id":37326143}],"con":true,"img":false}]}
{"op":"mcm","clk":"5347997522","pt":1646212112191,"mc":[{"id":"1.195453653","rc":[{"atl":[[2.62,18.38]],"id":35772529},{"atb":[[1.63,25.51]],"id":37326143}],"con":true,"img":false}]}
{"op":"mcm","clk":"5347997547","pt":1646212112605,"mc":[{"id":"1.195453653","rc":[{"atb":[[1.62,47.05]],"id":37326143}],"con":true,"img":false}]}
{"op":"mcm","clk":"5347997611","pt":1646212113904,"mc":[{"id":"1.195453653","rc":[{"atl":[[36,0],[38,0],[40,0],[42,0],[44,0],[46,0],[48,0],[50,0],[55,0],[60,0]],"id":35772529}],"con":true,"img":false}]}
{"op":"mcm","clk":"5347997651","pt":1646212114727,"mc":[{"id":"1.195453653","rc":[{"atl":[[1.84,19.11]],"id":37326143}],"con":true,"img":false}]}
{"op":"mcm","clk":"5347997656","pt":1646212114887,"mc":[{"id":"1.195453653","rc":[{"atl":[[1.83,11.7]],"id":37326143}],"con":true,"img":false}]}
{"op":"mcm","clk":"5347997662","pt":1646212114989,"mc":[{"id":"1.195453653","rc":[{"atl":[[1.93,0],[1.82,2]],"id":37326143}],"con":true,"img":false}]}
{"op":"mcm","clk":"5347997669","pt":1646212115091,"mc":[{"id":"1.195453653","rc":[{"atl":[[2.56,1.42]],"id":35772529},{"atb":[[1.64,1.42]],"id":37326143},{"atl":[[1.84,17.11]],"id":37326143}],"con":true,"img":false}]}
{"op":"mcm","clk":"5347997685","pt":1646212115403,"mc":[{"id":"1.195453653","rc":[{"atl":[[2.62,7.83]],"id":35772529},{"atb":[[1.63,10.06]],"id":37326143},{"atl":[[1.89,0],[1.82,13.71]],"id":37326143}],"con":true,"img":false}]}
{"op":"mcm","clk":"5347997689","pt":1646212115504,"mc":[{"id":"1.195453653","rc":[{"atl":[[2.56,11.97]],"id":35772529},{"atb":[[1.64,16.87]],"id":37326143}],"con":true,"img":false}]}
{"op":"mcm","clk":"5347997713","pt":1646212115921,"mc":[{"id":"1.195453653","rc":[{"atl":[[2.56,1.42]],"id":35772529},{"atb":[[1.64,1.42]],"id":37326143}],"con":true,"img":false}]}
{"op":"mcm","clk":"5347997722","pt":1646212116028,"mc":[{"id":"1.195453653","rc":[{"atl":[[2.62,18.38]],"id":35772529},{"atb":[[1.63,25.51]],"id":37326143}],"con":true,"img":false}]}
{"op":"mcm","clk":"5347997727","pt":1646212116129,"mc":[{"id":"1.195453653","rc":[{"atb":[[1.62,0]],"id":37326143}],"con":true,"img":false}]}
{"op":"mcm","clk":"5347997748","pt":1646212116390,"mc":[{"id":"1.195453653","rc":[{"atl":[[2.62,7.83]],"id":35772529},{"atb":[[1.63,10.06]],"id":37326143}],"con":true,"img":false}]}
{"op":"mcm","clk":"5347997754","pt":1646212116494,"mc":[{"id":"1.195453653","rc":[{"atl":[[2.56,11.97]],"id":35772529},{"atb":[[1.64,16.87]],"id":37326143}],"con":true,"img":false}]}
{"op":"mcm","clk":"5347997768","pt":1646212116700,"mc":[{"id":"1.195453653","rc":[{"atb":[[2.38,1.42]],"id":35772529},{"atl":[[2.54,7.29],[50,1.42]],"id":35772529},{"atb":[[1.65,1.42]],"id":37326143}],"con":true,"img":false}]}
{"op":"mcm","clk":"5347997776","pt":1646212116902,"mc":[{"id":"1.195453653","rc":[{"atl":[[2.56,1.42]],"id":35772529},{"atb":[[1.64,1.42]],"id":37326143},{"atl":[[1.84,10.58]],"id":37326143}],"con":true,"img":false}]}
{"op":"mcm","clk":"5347997835","pt":1646212117790,"mc":[{"id":"1.195453653","rc":[{"atl":[[2.56,0]],"id":35772529},{"atb":[[1.64,0],[1.65,0]],"id":37326143}],"con":true,"img":false}]}
{"op":"mcm","clk":"5347997866","pt":1646212118521,"mc":[{"id":"1.195453653","rc":[{"atl":[[55,1.42]],"id":35772529}],"con":true,"img":false}]}
{"op":"mcm","clk":"5347997935","pt":1646212119921,"mc":[{"id":"1.195453653","rc":[{"atl":[[60,1.42]],"id":35772529}],"con":true,"img":false}]}
{"op":"mcm","clk":"5347998048","pt":1646212121939,"mc":[{"id":"1.195453653","rc":[{"atl":[[65,1.42]],"id":35772529}],"con":true,"img":false}]}
{"op":"mcm","clk":"5347998081","pt":1646212122506,"mc":[{"id":"1.195453653","rc":[{"atl":[[2.54,14.32]],"id":35772529},{"atb":[[1.63,23.26]],"id":37326143}],"con":true,"img":false}]}
{"op":"mcm","clk":"5347998116","pt":1646212123131,"mc":[{"id":"1.195453653","rc":[{"atb":[[1.62,47.05]],"id":37326143}],"con":true,"img":false}]}
{"op":"mcm","clk":"5347998132","pt":1646212123539,"mc":[{"id":"1.195453653","rc":[{"atl":[[70,1.42]],"id":35772529}],"con":true,"img":false}]}
{"op":"mcm","clk":"5347998160","pt":1646212124000,"mc":[{"id":"1.195453653","rc":[{"atl":[[65,0],[50,0],[55,0],[60,0]],"id":35772529}],"con":true,"img":false}]}
{"op":"mcm","clk":"5347998190","pt":1646212124411,"mc":[{"id":"1.195453653","rc":[{"atl":[[2.54,7.29]],"id":35772529},{"atb":[[1.63,10.06]],"id":37326143}],"con":true,"img":false}]}
{"op":"mcm","clk":"5347998206","pt":1646212124721,"mc":[{"id":"1.195453653","rc":[{"atl":[[70,0]],"id":35772529}],"con":true,"img":false}]}
{"op":"mcm","clk":"5347998215","pt":1646212124924,"mc":[{"id":"1.195453653","rc":[{"atb":[[1.57,1.42]],"id":37326143}],"con":true,"img":false}]}
{"op":"mcm","clk":"5347998221","pt":1646212125128,"mc":[{"id":"1.195453653","rc":[{"atb":[[1.62,0]],"id":37326143}],"con":true,"img":false}]}
{"op":"mcm","clk":"5347998257","pt":1646212125932,"mc":[{"id":"1.195453653","rc":[{"atb":[[1.57,0]],"id":37326143}],"con":true,"img":false}]}
{"op":"mcm","clk":"5347998268","pt":1646212126138,"mc":[{"id":"1.195453653","rc":[{"atl":[[75,1.42]],"id":35772529}],"con":true,"img":false}]}
{"op":"mcm","clk":"5347998375","pt":1646212127811,"mc":[{"id":"1.195453653","rc":[{"atl":[[80,1.42]],"id":35772529}],"con":true,"img":false}]}
{"op":"mcm","clk":"5347998439","pt":1646212129149,"mc":[{"id":"1.195453653","rc":[{"atb":[[2.36,7.33],[2.32,9.57]],"id":35772529}],"con":true,"img":false}]}
{"op":"mcm","clk":"5347998493","pt":1646212130443,"mc":[{"id":"1.195453653","rc":[{"atl":[[2.54,16.66]],"id":35772529},{"atb":[[1.63,26.9]],"id":37326143}],"con":true,"img":false}]}
{"op":"mcm","clk":"5347998516","pt":1646212131111,"mc":[{"id":"1.195453653","rc":[{"atl":[[2.54,7.29]],"id":35772529},{"atb":[[1.64,45.59],[1.63,10.06]],"id":37326143}],"con":true,"img":false}]}
{"op":"mcm","clk":"5347998523","pt":1646212131213,"mc":[{"id":"1.195453653","rc":[{"atb":[[1.64,57.44]],"id":37326143}],"con":true,"img":false}]}
{"op":"mcm","clk":"5347998546","pt":1646212131625,"mc":[{"id":"1.195453653","rc":[{"atb":[[1.64,11.85]],"id":37326143}],"con":true,"img":false}]}
{"op":"mcm","clk":"5347998864","pt":1646212136541,"mc":[{"id":"1.195453653","rc":[{"atl":[[2.54,16.18]],"id":35772529},{"atb":[[1.64,26.69]],"id":37326143}],"con":true,"img":false}]}
{"op":"mcm","clk":"5347998893","pt":1646212137153,"mc":[{"id":"1.195453653","rc":[{"atb":[[2.32,31.68],[2.34,7.33]],"id":35772529},{"atb":[[1.65,44.88]],"id":37326143}],"con":true,"img":false}]}
{"op":"mcm","clk":"5347998914","pt":1646212137464,"mc":[{"id":"1.195453653","rc":[{"atb":[[1.64,11.85]],"id":37326143}],"con":true,"img":false}]}
{"op":"mcm","clk":"5347998920","pt":1646212137576,"mc":[{"id":"1.195453653","rc":[{"atb":[[1.54,0],[1.65,59.72]],"id":37326143}],"con":true,"img":false}]}
{"op":"mcm","clk":"5347998930","pt":1646212137677,"mc":[{"id":"1.195453653","rc":[{"atb":[[2.38,8.77],[2.18,0]],"id":35772529}],"con":true,"img":false}]}
{"op":"mcm","clk":"5347998952","pt":1646212137939,"mc":[{"id":"1.195453653","rc":[{"atl":[[75,0],[80,0]],"id":35772529}],"con":true,"img":false}]}
{"op":"mcm","clk":"5347998963","pt":1646212138144,"mc":[{"id":"1.195453653","rc":[{"atb":[[2.34,29.1]],"id":35772529}],"con":true,"img":false}]}
{"op":"mcm","clk":"5347998999","pt":1646212138755,"mc":[{"id":"1.195453653","rc":[{"atl":[[75,1.42]],"id":35772529}],"con":true,"img":false}]}
{"op":"mcm","clk":"5347999021","pt":1646212139075,"mc":[{"id":"1.195453653","rc":[{"atl":[[2.54,7.29]],"id":35772529},{"atb":[[1.65,44.88]],"id":37326143}],"con":true,"img":false}]}
{"op":"mcm","clk":"5347999049","pt":1646212139533,"mc":[{"id":"1.195453653","rc":[{"atb":[[1.55,53.05],[1.65,0]],"id":37326143}],"con":true,"img":false}]}
{"op":"mcm","clk":"5347999057","pt":1646212139641,"mc":[{"id":"1.195453653","rc":[{"atl":[[2.54,16.19]],"id":35772529},{"atb":[[1.65,13.62]],"id":37326143}],"con":true,"img":false}]}
{"op":"mcm","clk":"5347999073","pt":1646212139940,"mc":[{"id":"1.195453653","rc":[{"atb":[[1.65,0]],"id":37326143}],"con":true,"img":false}]}
{"op":"mcm","clk":"5347999087","pt":1646212140151,"mc":[{"id":"1.195453653","rc":[{"atb":[[2.22,1.42]],"id":35772529},{"atl":[[80,1.39]],"id":35772529},{"atb":[[1.65,1.42]],"id":37326143}],"con":true,"img":false}]}
{"op":"mcm","clk":"5347999092","pt":1646212140263,"mc":[{"id":"1.195453653","rc":[{"atb":[[2.38,14.6]],"id":35772529},{"atl":[[2.54,7.29]],"id":35772529},{"atl":[[1.82,30.07]],"id":37326143}],"con":true,"img":false}]}
{"op":"mcm","clk":"5347999108","pt":1646212140569,"mc":[{"id":"1.195453653","rc":[{"atb":[[2.38,35.75]],"id":35772529},{"atb":[[1.62,47.05]],"id":37326143}],"con":true,"img":false}]}
{"op":"mcm","clk":"5347999139","pt":1646212141032,"mc":[{"id":"1.195453653","rc":[{"atl":[[1.81,11.64]],"id":37326143}],"con":true,"img":false}]}
{"op":"mcm","clk":"5347999143","pt":1646212141132,"mc":[{"id":"1.195453653","rc":[{"atl":[[75,0],[80,0]],"id":35772529},{"atl":[[1.85,0],[1.82,28.07],[1.8,2]],"id":37326143}],"con":true,"img":false}]}
{"op":"mcm","clk":"5347999152","pt":1646212141336,"mc":[{"id":"1.195453653","rc":[{"atl":[[1.82,11.71]],"id":37326143}],"con":true,"img":false}]}
{"op":"mcm","clk":"5347999154","pt":1646212141443,"mc":[{"id":"1.195453653","rc":[{"atl":[[1.81,28]],"id":37326143}],"con":true,"img":false}]}
{"op":"mcm","clk":"5347999169","pt":1646212141745,"mc":[{"id":"1.195453653","rc":[{"atl":[[1.81,11.64]],"id":37326143}],"con":true,"img":false}]}
{"op":"mcm","clk":"5347999173","pt":1646212141848,"mc":[{"id":"1.195453653","rc":[{"atl":[[1.8,18.36]],"id":37326143}],"con":true,"img":false}]}
{"op":"mcm","clk":"5347999177","pt":1646212141956,"mc":[{"id":"1.195453653","rc":[{"atb":[[2.38,29.92]],"id":35772529},{"atl":[[2.54,14.62]],"id":35772529},{"atb":[[1.65,4.26]],"id":37326143}],"con":true,"img":false}]}
{"op":"mcm","clk":"5347999183","pt":1646212142156,"mc":[{"id":"1.195453653","rc":[{"atb":[[2.28,1.42]],"id":35772529},{"atb":[[1.57,1.42]],"id":37326143},{"atl":[[1.78,1.42],[1.8,2]],"id":37326143}],"con":true,"img":false}]}
{"op":"mcm","clk":"5347999191","pt":1646212142366,"mc":[{"id":"1.195453653","rc":[{"atl":[[1.78,3.42],[1.8,0]],"id":37326143}],"con":true,"img":false}]}
{"op":"mcm","clk":"5347999194","pt":1646212142465,"mc":[{"id":"1.195453653","rc":[{"atl":[[1.78,1.42],[1.8,2]],"id":37326143}],"con":true,"img":false}]}
{"op":"mcm","clk":"5347999199","pt":1646212142588,"mc":[{"id":"1.195453653","rc":[{"atb":[[1.64,57.44]],"id":37326143},{"atl":[[1.78,3.42],[1.8,0]],"id":37326143}],"con":true,"img":false}]}
{"op":"mcm","clk":"5347999203","pt":1646212142641,"mc":[{"id":"1.195453653","rc":[{"atb":[[2.38,8.77]],"id":35772529},{"atl":[[1.78,1.42],[1.8,2]],"id":37326143}],"con":true,"img":false}]}
{"op":"mcm","clk":"5347999206","pt":1646212142744,"mc":[{"id":"1.195453653","rc":[{"atl":[[1.78,3.42],[1.8,0]],"id":37326143}],"con":true,"img":false}]}
{"op":"mcm","clk":"5347999209","pt":1646212142844,"mc":[{"id":"1.195453653","rc":[{"atl":[[1.78,1.42],[1.8,2]],"id":37326143}],"con":true,"img":false}]}
{"op":"mcm","clk":"5347999212","pt":1646212142948,"mc":[{"id":"1.195453653","rc":[{"atl":[[1.78,3.42],[1.8,0]],"id":37326143}],"con":true,"img":false}]}
{"op":"mcm","clk":"5347999233","pt":1646212143260,"mc":[{"id":"1.195453653","rc":[{"atl":[[1.78,2]],"id":37326143}],"con":true,"img":false}]}
{"op":"mcm","clk":"5347999255","pt":1646212143873,"mc":[{"id":"1.195453653","rc":[{"atb":[[2.26,1.42]],"id":35772529},{"atl":[[2.52,1.42]],"id":35772529},{"atb":[[1.58,1.42]],"id":37326143}],"con":true,"img":false}]}
{"op":"mcm","clk":"5347999261","pt":1646212144139,"mc":[{"id":"1.195453653","rc":[{"atl":[[2.54,0]],"id":35772529},{"atl":[[1.78,13.82]],"id":37326143}],"con":true,"img":false}]}
{"op":"mcm","clk":"5347999265","pt":1646212144233,"mc":[{"id":"1.195453653","rc":[{"atl":[[2.52,8.75]],"id":35772529},{"atb":[[1.64,45.59]],"id":37326143},{"atl":[[1.84,0]],"id":37326143}],"con":true,"img":false}]}
{"op":"mcm","clk":"5347999277","pt":1646212144544,"mc":[{"id":"1.195453653","rc":[{"atl":[[2.52,4.26]],"id":35772529}],"con":true,"img":false}]}
{"op":"mcm","clk":"5347999282","pt":1646212144645,"mc":[{"id":"1.195453653","rc":[{"atb":[[1.64,0],[1.62,0]],"id":37326143}],"con":true,"img":false}]}
{"op":"mcm","clk":"5347999307","pt":1646212145161,"mc":[{"id":"1.195453653","rc":[{"atb":[[2.24,1.42]],"id":35772529},{"atl":[[2.56,1.42]],"id":35772529}],"con":true,"img":false}]}
{"op":"mcm","clk":"5347999329","pt":1646212145576,"mc":[{"id":"1.195453653","rc":[{"atb":[[1.58,0],[1.57,0]],"id":37326143}],"con":true,"img":false}]}
{"op":"mcm","clk":"5347999360","pt":1646212146152,"mc":[{"id":"1.195453653","rc":[{"atl":[[2.56,0]],"id":35772529}],"con":true,"img":false}]}
{"op":"mcm","clk":"5347999380","pt":1646212146658,"mc":[{"id":"1.195453653","rc":[{"atl":[[75,0.88]],"id":35772529}],"con":true,"img":false}]}
{"op":"mcm","clk":"5347999430","pt":1646212148154,"mc":[{"id":"1.195453653","rc":[{"atl":[[80,0.88]],"id":35772529}],"con":true,"img":false}]}
{"op":"mcm","clk":"5347999477","pt":1646212149488,"mc":[{"id":"1.195453653","rc":[{"atl":[[85,0.85]],"id":35772529}],"con":true,"img":false}]}
{"op":"mcm","clk":"5347999532","pt":1646212150888,"mc":[{"id":"1.195453653","rc":[{"atl":[[90,0.85]],"id":35772529}],"con":true,"img":false}]}
{"op":"mcm","clk":"5347999987","pt":1646212160171,"mc":[{"id":"1.195453653","rc":[{"atb":[[2.38,13.95]],"id":35772529},{"atl":[[2.52,1.42]],"id":35772529},{"atb":[[1.65,1.42]],"id":37326143},{"atl":[[1.78,26.04]],"id":37326143}],"con":true,"img":false}]}
{"op":"mcm","clk":"5347999991","pt":1646212160273,"mc":[{"id":"1.195453653","rc":[{"atl":[[2.52,0]],"id":35772529},{"trd":[[2.52,2.84]],"ltp":2.52,"tv":2.84,"id":35772529}],"con":true,"img":false}]}
{"op":"mcm","clk":"5347999994","pt":1646212160376,"mc":[{"id":"1.195453653","rc":[{"atb":[[2.4,7.3],[2.32,24.1]],"id":35772529},{"atl":[[1.83,0],[1.77,11.76]],"id":37326143}],"con":true,"img":false}]}
{"op":"mcm","clk":"5348000001","pt":1646212160583,"mc":[{"id":"1.195453653","rc":[{"atb":[[2.4,28.14]],"id":35772529},{"atb":[[1.55,0],[1.54,54.02]],"id":37326143}],"con":true,"img":false}]}
{"op":"mcm","clk":"5348000004","pt":1646212160682,"mc":[{"id":"1.195453653","rc":[{"atl":[[1.78,13.82]],"id":37326143}],"con":true,"img":false}]}
{"op":"mcm","clk":"5348000010","pt":1646212160784,"mc":[{"id":"1.195453653","rc":[{"atl":[[1.77,23.98]],"id":37326143}],"con":true,"img":false}]}
{"op":"mcm","clk":"5348000038","pt":1646212161507,"mc":[{"id":"1.195453653","rc":[{"atb":[[1.65,0]],"id":37326143}],"con":true,"img":false}]}
{"op":"mcm","clk":"5348000048","pt":1646212161768,"mc":[{"id":"1.195453653","rc":[{"atb":[[2.3,1.42]],"id":35772529}],"con":true,"img":false}]}
{"op":"mcm","clk":"5348000052","pt":1646212161871,"mc":[{"id":"1.195453653","rc":[{"atl":[[2.62,15.26]],"id":35772529},{"atb":[[1.63,20.49]],"id":37326143},{"atl":[[1.77,11.76]],"id":37326143}],"con":true,"img":false}]}
{"op":"mcm","clk":"5348000075","pt":1646212162391,"mc":[{"id":"1.195453653","rc":[{"atl":[[2.6,7.26]],"id":35772529},{"atb":[[1.64,11.94]],"id":37326143}],"con":true,"img":false}]}
{"op":"mcm","clk":"5348000087","pt":1646212162699,"mc":[{"id":"1.195453653","rc":[{"atl":[[2.62,7.83]],"id":35772529},{"atb":[[1.63,10.06]],"id":37326143}],"con":true,"img":false}]}
{"op":"mcm","clk":"5348000089","pt":1646212162802,"mc":[{"id":"1.195453653","rc":[{"atl":[[2.6,14.69]],"id":35772529},{"atb":[[1.64,22.37]],"id":37326143}],"con":true,"img":false}]}
{"op":"mcm","clk":"5348000099","pt":1646212163108,"mc":[{"id":"1.195453653","rc":[{"atb":[[2.4,7.3],[2.38,35.1]],"id":35772529},{"atb":[[1.63,56.38]],"id":37326143}],"con":true,"img":false}]}
{"op":"mcm","clk":"5348000121","pt":1646212163578,"mc":[{"id":"1.195453653","rc":[{"atb":[[2.42,1.42]],"id":35772529},{"atl":[[1.71,1.42]],"id":37326143}],"con":true,"img":false}]}
{"op":"mcm","clk":"5348000158","pt":1646212164397,"mc":[{"id":"1.195453653","rc":[{"atl":[[75,0],[80,0],[85,0],[90,0],[2.58,7.28]],"id":35772529}],"con":true,"img":false}]}
{"op":"mcm","clk":"5348000169","pt":1646212164604,"mc":[{"id":"1.195453653","rc":[{"atl":[[2.56,1.42]],"id":35772529}],"con":true,"img":false}]}
{"op":"mcm","clk":"5348000174","pt":1646212164709,"mc":[{"id":"1.195453653","rc":[{"atl":[[2.6,7.26]],"id":35772529}],"con":true,"img":false}]}
{"op":"mcm","clk":"5348000180","pt":1646212164808,"mc":[{"id":"1.195453653","rc":[{"atb":[[2.4,0]],"id":35772529},{"atl":[[2.56,8.74],[2.58,14.71]],"id":35772529},{"atb":[[1.65,11.84]],"id":37326143}],"con":true,"img":false}]}
{"op":"mcm","clk":"5348000184","pt":1646212164912,"mc":[{"id":"1.195453653","rc":[{"atl":[[2.82,2]],"id":35772529}],"con":true,"img":false}]}
{"op":"mcm","clk":"5348000197","pt":1646212165116,"mc":[{"id":"1.195453653","rc":[{"atb":[[2.36,28.78],[2.38,13.95]],"id":35772529},{"atl":[[2.58,7.28]],"id":35772529},{"atb":[[1.64,57.53]],"id":37326143}],"con":true,"img":false}]}
{"op":"mcm","clk":"5348000202","pt":1646212165221,"mc":[{"id":"1.195453653","rc":[{"atl":[[2.56,16.17]],"id":35772529},{"atb":[[1.65,22.27]],"id":37326143}],"con":true,"img":false}]}
{"op":"mcm","clk":"5348000205","pt":1646212165274,"mc":[{"id":"1.195453653","rc":[{"atb":[[2.36,21.45],[2.38,6.6]],"id":35772529}],"con":true,"img":false}]}
{"op":"mcm","clk":"5348000210","pt":1646212165376,"mc":[{"id":"1.195453653","rc":[{"atl":[[2.54,7.42]],"id":35772529},{"atb":[[1.66,11.62]],"id":37326143}],"con":true,"img":false}]}
{"op":"mcm","clk":"5348000217","pt":1646212165482,"mc":[{"id":"1.195453653","rc":[{"atl":[[2.62,0]],"id":35772529}],"con":true,"img":false}]}
{"op":"mcm","clk":"5348000224","pt":1646212165581,"mc":[{"id":"1.195453653","rc":[{"atb":[[2.32,2],[2.34,7.33],[2.36,0]],"id":35772529},{"atl":[[2.56,8.74]],"id":35772529},{"atb":[[1.54,0],[1.65,11.84]],"id":37326143}],"con":true,"img":false}]}
{"op":"mcm","clk":"5348000230","pt":1646212165685,"mc":[{"id":"1.195453653","rc":[{"atl":[[2.54,14.85]],"id":35772529},{"atb":[[1.66,22.05]],"id":37326143}],"con":true,"img":false}]}
{"op":"mcm","clk":"5348000242","pt":1646212165888,"mc":[{"id":"1.195453653","rc":[{"atb":[[2.32,0],[2.34,9.33]],"id":35772529}],"con":true,"img":false}]}
{"op":"mcm","clk":"5348000255","pt":1646212166096,"mc":[{"id":"1.195453653","rc":[{"atb":[[2.3,23.86]],"id":35772529},{"atb":[[1.64,11.94],[1.63,10.06],[1.62,47.05]],"id":37326143}],"con":true,"img":false}]}
{"op":"mcm","clk":"5348000266","pt":1646212166401,"mc":[{"id":"1.195453653","rc":[{"atb":[[2.24,0],[2.4,1.42],[2.3,22.44],[2.22,0],[2.38,5.18],[2.28,0],[2.26,0]],"id":35772529},{"atl":[[1.72,1.42]],"id":37326143}],"con":true,"img":false}]}
{"op":"mcm","clk":"5348000309","pt":1646212167277,"mc":[{"id":"1.195453653","rc":[{"atb":[[2.4,0],[2.42,0]],"id":35772529},{"atl":[[2.56,7.31]],"id":35772529},{"atl":[[1.71,0],[1.72,0]],"id":37326143}],"con":true,"img":false}]}
{"op":"mcm","clk":"5348000315","pt":1646212167380,"mc":[{"id":"1.195453653","rc":[{"atl":[[2.52,7.41],[2.6,0]],"id":35772529}],"con":true,"img":false}]}
{"op":"mcm","clk":"5348000324","pt":1646212167587,"mc":[{"id":"1.195453653","rc":[{"atb":[[1.66,66.26]],"id":37326143}],"con":true,"img":false}]}
{"op":"mcm","clk":"5348000329","pt":1646212167686,"mc":[{"id":"1.195453653","rc":[{"atb":[[2.38,0]],"id":35772529},{"atl":[[2.54,7.42]],"id":35772529}],"con":true,"img":false}]}
{"op":"mcm","clk":"5348000341","pt":1646212167996,"mc":[{"id":"1.195453653","rc":[{"atl":[[2.52,15.36]],"id":35772529}],"con":true,"img":false}]}
{"op":"mcm","clk":"5348000365","pt":1646212168508,"mc":[{"id":"1.195453653","rc":[{"atl":[[2.52,7.41]],"id":35772529},{"atb":[[1.66,55.83]],"id":37326143},{"atl":[[1.77,20.62]],"id":37326143}],"con":true,"img":false}]}
{"op":"mcm","clk":"5348000392","pt":1646212169020,"mc":[{"id":"1.195453653","rc":[{"atl":[[2.5,1.42]],"id":35772529}],"con":true,"img":false}]}
{"op":"mcm","clk":"5348000397","pt":1646212169127,"mc":[{"id":"1.195453653","rc":[{"atb":[[1.66,11.62]],"id":37326143}],"con":true,"img":false}]}
{"op":"mcm","clk":"5348000426","pt":1646212169589,"mc":[{"id":"1.195453653","rc":[{"atb":[[1.65,56.73]],"id":37326143}],"con":true,"img":false}]}
{"op":"mcm","clk":"5348000447","pt":1646212170209,"mc":[{"id":"1.195453653","rc":[{"atb":[[2.34,15.57]],"id":35772529}],"con":true,"img":false}]}
{"op":"mcm","clk":"5348000469","pt":1646212170725,"mc":[{"id":"1.195453653","rc":[{"atl":[[80,0.88]],"id":35772529}],"con":true,"img":false}]}
{"op":"mcm","clk":"5348000481","pt":1646212171030,"mc":[{"id":"1.195453653","rc":[{"atb":[[2.32,2],[2.34,13.57]],"id":35772529}],"con":true,"img":false}]}
{"op":"mcm","clk":"5348000518","pt":1646212171501,"mc":[{"id":"1.195453653","rc":[{"atl":[[80,0]],"id":35772529}],"con":true,"img":false}]}
{"op":"mcm","clk":"5348000564","pt":1646212172432,"mc":[{"id":"1.195453653","rc":[{"atl":[[2.48,1.42]],"id":35772529}],"con":true,"img":false}]}
{"op":"mcm","clk":"5348000572","pt":1646212172529,"mc":[{"id":"1.195453653","rc":[{"atb":[[2.36,7.44]],"id":35772529},{"atl":[[2.5,8.83],[2.58,0]],"id":35772529},{"atl":[[1.76,11.47],[1.82,0]],"id":37326143}],"con":true,"img":false}]}
{"op":"mcm","clk":"5348000593","pt":1646212172894,"mc":[{"id":"1.195453653","rc":[{"atb":[[2.34,7.33]],"id":35772529},{"atl":[[1.77,11.76]],"id":37326143}],"con":true,"img":false}]}
{"op":"mcm","clk":"5348000597","pt":1646212172998,"mc":[{"id":"1.195453653","rc":[{"atb":[[2.36,13.68]],"id":35772529}],"con":true,"img":false}]}
{"op":"mcm","clk":"5348000601","pt":1646212173102,"mc":[{"id":"1.195453653","rc":[{"atb":[[2.32,24.1]],"id":35772529},{"atl":[[2.48,0]],"id":35772529}],"con":true,"img":false}]}
{"op":"mcm","clk":"5348000609","pt":1646212173203,"mc":[{"id":"1.195453653","rc":[{"atl":[[1.76,21.37]],"id":37326143}],"con":true,"img":false}]}
{"op":"mcm","clk":"5348000619","pt":1646212173414,"mc":[{"id":"1.195453653","rc":[{"atb":[[2.36,7.44]],"id":35772529}],"con":true,"img":false}]}
{"op":"mcm","clk":"5348000630","pt":1646212173716,"mc":[{"id":"1.195453653","rc":[{"atl":[[2.48,1.42]],"id":35772529}],"con":true,"img":false}]}
{"op":"mcm","clk":"5348000647","pt":1646212174138,"mc":[{"id":"1.195453653","rc":[{"atb":[[2.36,0]],"id":35772529}],"con":true,"img":false}]}
{"op":"mcm","clk":"5348000655","pt":1646212174333,"mc":[{"id":"1.195453653","rc":[{"atl":[[2.48,0]],"id":35772529}],"con":true,"img":false}]}
{"op":"mcm","clk":"5348000659","pt":1646212174431,"mc":[{"id":"1.195453653","rc":[{"atb":[[2.34,12.59]],"id":35772529}],"con":true,"img":false}]}
{"op":"mcm","clk":"5348000686","pt":1646212175002,"mc":[{"id":"1.195453653","rc":[{"atl":[[1.81,0],[1.75,11.47]],"id":37326143}],"con":true,"img":false}]}
{"op":"mcm","clk":"5348000691","pt":1646212175207,"mc":[{"id":"1.195453653","rc":[{"atb":[[2.34,7.33]],"id":35772529}],"con":true,"img":false}]}
{"op":"mcm","clk":"5348000694","pt":1646212175414,"mc":[{"id":"1.195453653","rc":[{"atl":[[2.56,0]],"id":35772529},{"atb":[[1.64,0],[1.65,44.88]],"id":37326143}],"con":true,"img":false}]}
{"op":"mcm","clk":"5348000697","pt":1646212175517,"mc":[{"id":"1.195453653","rc":[{"atl":[[2.54,0],[2.5,1.42],[2.52,0]],"id":35772529},{"atb":[[1.66,0]],"id":37326143}],"con":true,"img":false}]}
{"op":"mcm","clk":"5348000725","pt":1646212176134,"mc":[{"id":"1.195453653","rc":[{"atb":[[2.32,2],[2.3,0]],"id":35772529},{"atb":[[1.62,0],[1.65,0]],"id":37326143}],"con":true,"img":false}]}
{"op":"mcm","clk":"5348000738","pt":1646212176441,"mc":[{"id":"1.195453653","rc":[{"atl":[[75,0.88]],"id":35772529}],"con":true,"img":false}]}
{"op":"mcm","clk":"5348000754","pt":1646212176814,"mc":[{"id":"1.195453653","rc":[{"atb":[[2.34,13.8]],"id":35772529},{"atl":[[1.76,11.47]],"id":37326143}],"con":true,"img":false}]}
{"op":"mcm","clk":"5348000757","pt":1646212176908,"mc":[{"id":"1.195453653","rc":[{"atl":[[1.75,21.37]],"id":37326143}],"con":true,"img":false}]}
{"op":"mcm","clk":"5348000762","pt":1646212177016,"mc":[{"id":"1.195453653","rc":[{"atl":[[2.5,0]],"id":35772529}],"con":true,"img":false}]}
{"op":"mcm","clk":"5348000767","pt":1646212177115,"mc":[{"id":"1.195453653","rc":[{"atb":[[2.34,7.33]],"id":35772529}],"con":true,"img":false}]}
{"op":"mcm","clk":"5348000780","pt":1646212177325,"mc":[{"id":"1.195453653","rc":[{"atl":[[2.82,6]],"id":35772529}],"con":true,"img":false}]}
{"op":"mcm","clk":"5348000787","pt":1646212177429,"mc":[{"id":"1.195453653","rc":[{"atb":[[2.34,13.8]],"id":35772529}],"con":true,"img":false}]}
{"op":"mcm","clk":"5348000792","pt":1646212177528,"mc":[{"id":"1.195453653","rc":[{"atl":[[2.82,4],[3.2,2]],"id":35772529}],"con":true,"img":false}]}
{"op":"mcm","clk":"5348000800","pt":1646212177630,"mc":[{"id":"1.195453653","rc":[{"atb":[[2.26,23.15]],"id":35772529}],"con":true,"img":false}]}
{"op":"mcm","clk":"5348000810","pt":1646212177730,"mc":[{"id":"1.195453653","rc":[{"atl":[[2.82,6],[3.2,0]],"id":35772529}],"con":true,"img":false}]}
{"op":"mcm","clk":"5348000814","pt":1646212177840,"mc":[{"id":"1.195453653","rc":[{"atl":[[2.82,2]],"id":35772529}],"con":true,"img":false}]}
{"op":"mcm","clk":"5348000821","pt":1646212177986,"mc":[{"id":"1.195453653","rc":[{"atl":[[70,0.74]],"id":35772529}],"con":true,"img":false}]}
{"op":"mcm","clk":"5348000828","pt":1646212178094,"mc":[{"id":"1.195453653","rc":[{"atb":[[2.26,0]],"id":35772529},{"atl":[[2.82,6]],"id":35772529}],"con":true,"img":false}]}
{"op":"mcm","clk":"5348000846","pt":1646212178503,"mc":[{"id":"1.195453653","rc":[{"atb":[[2.34,7.33]],"id":35772529},{"atl":[[2.8,7.21]],"id":35772529},{"atb":[[1.63,17.96]],"id":37326143},{"atl":[[1.75,11.47]],"id":37326143}],"con":true,"img":false}]}
{"op":"mcm","clk":"5348000858","pt":1646212178612,"mc":[{"id":"1.195453653","rc":[{"atb":[[2.26,23.15]],"id":35772529}],"con":true,"img":false}]}
{"op":"mcm","clk":"5348000869","pt":1646212178814,"mc":[{"id":"1.195453653","rc":[{"atl":[[2.82,2]],"id":35772529}],"con":true,"img":false}]}
{"op":"mcm","clk":"5348000886","pt":1646212179123,"mc":[{"id":"1.195453653","rc":[{"atl":[[2.8,17.22]],"id":35772529}],"con":true,"img":false}]}
{"op":"mcm","clk":"5348000899","pt":1646212179330,"mc":[{"id":"1.195453653","rc":[{"atl":[[55,0.88]],"id":35772529}],"con":true,"img":false}]}
{"op":"mcm","clk":"5348000915","pt":1646212179633,"mc":[{"id":"1.195453653","rc":[{"atb":[[2.32,24.1]],"id":35772529},{"atb":[[1.55,53.05]],"id":37326143}],"con":true,"img":false}]}
{"op":"mcm","clk":"5348000936","pt":1646212180105,"mc":[{"id":"1.195453653","rc":[{"atl":[[2.78,7.21]],"id":35772529}],"con":true,"img":false}]}
{"op":"mcm","clk":"5348000950","pt":1646212180412,"mc":[{"id":"1.195453653","rc":[{"atl":[[2.8,7.21]],"id":35772529}],"con":true,"img":false}]}
{"op":"mcm","clk":"5348000957","pt":1646212180517,"mc":[{"id":"1.195453653","rc":[{"atl":[[2.78,17.22]],"id":35772529}],"con":true,"img":false}]}
{"op":"mcm","clk":"5348000962","pt":1646212180618,"mc":[{"id":"1.195453653","rc":[{"atb":[[1.55,0],[1.54,54.02]],"id":37326143}],"con":true,"img":false}]}
{"op":"mcm","clk":"5348000971","pt":1646212180828,"mc":[{"id":"1.195453653","rc":[{"atb":[[2.36,1.42]],"id":35772529},{"atl":[[50,1.13]],"id":35772529}],"con":true,"img":false}]}
{"op":"mcm","clk":"5348000995","pt":1646212181237,"mc":[{"id":"1.195453653","rc":[{"atl":[[2.76,7.22]],"id":35772529}],"con":true,"img":false}]}
{"op":"mcm","clk":"5348001012","pt":1646212181599,"mc":[{"id":"1.195453653","rc":[{"atb":[[1.57,51.18]],"id":37326143}],"con":true,"img":false}]}
{"op":"mcm","clk":"5348001017","pt":1646212181705,"mc":[{"id":"1.195453653","rc":[{"atb":[[2.36,8.68]],"id":35772529},{"atl":[[2.78,7.21]],"id":35772529},{"atb":[[1.63,10.06]],"id":37326143}],"con":true,"img":false}]}
{"op":"mcm","clk":"5348001037","pt":1646212182118,"mc":[{"id":"1.195453653","rc":[{"atb":[[1.57,0]],"id":37326143}],"con":true,"img":false}]}
{"op":"mcm","clk":"5348001048","pt":1646212182328,"mc":[{"id":"1.195453653","rc":[{"atl":[[2.76,17.36]],"id":35772529},{"atb":[[1.63,19.59]],"id":37326143}],"con":true,"img":false}]}
{"op":"mcm","clk":"5348001060","pt":1646212182537,"mc":[{"id":"1.195453653","rc":[{"atb":[[2.4,1.42]],"id":35772529},{"atl":[[46,1.2]],"id":35772529},{"atl":[[1.73,1.42]],"id":37326143}],"con":true,"img":false}]}
{"op":"mcm","clk":"5348001063","pt":1646212182639,"mc":[{"id":"1.195453653","rc":[{"atb":[[1.57,51.18]],"id":37326143}],"con":true,"img":false}]}
{"op":"mcm","clk":"5348001093","pt":1646212183152,"mc":[{"id":"1.195453653","rc":[{"atb":[[2.4,8.67]],"id":35772529},{"atl":[[1.73,13.31],[1.78,2]],"id":37326143}],"con":true,"img":false}]}
{"op":"mcm","clk":"5348001119","pt":1646212183518,"mc":[{"id":"1.195453653","rc":[{"atb":[[2.4,16.98]],"id":35772529},{"atl":[[2.76,7.22]],"id":35772529},{"atb":[[1.63,10.06]],"id":37326143},{"atl":[[1.73,26.46]],"id":37326143}],"con":true,"img":false}]}
{"op":"mcm","clk":"5348001122","pt":1646212183624,"mc":[{"id":"1.195453653","rc":[{"atb":[[2.38,21.14]],"id":35772529}],"con":true,"img":false}]}
{"op":"mcm","clk":"5348001127","pt":1646212183729,"mc":[{"id":"1.195453653","rc":[{"atl":[[70,0],[75,0],[46,0],[50,0],[55,0]],"id":35772529}],"con":true,"img":false}]}
{"op":"mcm","clk":"5348001162","pt":1646212184139,"mc":[{"id":"1.195453653","rc":[{"atb":[[1.57,0]],"id":37326143}],"con":true,"img":false}]}
{"op":"mcm","clk":"5348001168","pt":1646212184243,"mc":[{"id":"1.195453653","rc":[{"atb":[[2.38,22.56]],"id":35772529},{"atl":[[2.56,1.42]],"id":35772529}],"con":true,"img":false}]}
{"op":"mcm","clk":"5348001178","pt":1646212184444,"mc":[{"id":"1.195453653","rc":[{"atl":[[2.56,0]],"id":35772529},{"trd":[[2.56,2.84]],"ltp":2.56,"tv":2.84,"id":35772529}],"con":true,"img":false}]}
{"op":"mcm","clk":"5348001191","pt":1646212184606,"mc":[{"id":"1.195453653","rc":[{"atb":[[2.42,7.25]],"id":35772529},{"atb":[[1.56,52.1]],"id":37326143},{"atl":[[1.72,11.9]],"id":37326143}],"con":true,"img":false}]}
{"op":"mcm","clk":"5348001200","pt":1646212184757,"mc":[{"id":"1.195453653","rc":[{"atl":[[1.77,0]],"id":37326143}],"con":true,"img":false}]}
{"op":"mcm","clk":"5348001215","pt":1646212185016,"mc":[{"id":"1.195453653","rc":[{"atb":[[2.4,8.67]],"id":35772529},{"atl":[[1.73,13.31]],"id":37326143}],"con":true,"img":false}]}
{"op":"mcm","clk":"5348001220","pt":1646212185121,"mc":[{"id":"1.195453653","rc":[{"atb":[[2.42,15.56],[2.26,0]],"id":35772529},{"atb":[[1.56,0]],"id":37326143},{"atl":[[1.72,25.05]],"id":37326143}],"con":true,"img":false}]}
{"op":"mcm","clk":"5348001223","pt":1646212185220,"mc":[{"id":"1.195453653","rc":[{"atb":[[2.42,16.98]],"id":35772529},{"atl":[[55,1.13],[2.76,18.76]],"id":35772529},{"atb":[[1.63,22.01]],"id":37326143},{"atl":[[1.71,1.42]],"id":37326143}],"con":true,"img":false}]}
{"op":"mcm","clk":"5348001231","pt":1646212185429,"mc":[{"id":"1.195453653","rc":[{"atb":[[2.42,8.67]],"id":35772529},{"atl":[[1.72,11.9]],"id":37326143}],"con":true,"img":false}]}
{"op":"mcm","clk":"5348001242","pt":1646212185632,"mc":[{"id":"1.195453653","rc":[{"atb":[[2.42,29.22]],"id":35772529},{"atb":[[1.57,51.18]],"id":37326143}],"con":true,"img":false}]}
{"op":"mcm","clk":"5348001275","pt":1646212186149,"mc":[{"id":"1.195453653","rc":[{"atb":[[2.42,8.67]],"id":35772529}],"con":true,"img":false}]}
{"op":"mcm","clk":"5348001288","pt":1646212186407,"mc":[{"id":"1.195453653","rc":[{"atl":[[55,0]],"id":35772529}],"con":true,"img":false}]}
{"op":"mcm","clk":"5348001310","pt":1646212186918,"mc":[{"id":"1.195453653","rc":[{"atb":[[2.44,1.42]],"id":35772529},{"atl":[[2.58,1.42]],"id":35772529},{"atl":[[1.7,1.42]],"id":37326143}],"con":true,"img":false}]}
{"op":"mcm","clk":"5348001316","pt":1646212187025,"mc":[{"id":"1.195453653","rc":[{"atl":[[1.73,11.89]],"id":37326143}],"con":true,"img":false}]}
{"op":"mcm","clk":"5348001342","pt":1646212187644,"mc":[{"id":"1.195453653","rc":[{"atb":[[2.44,0]],"id":35772529},{"atl":[[1.7,0]],"id":37326143}],"con":true,"img":false}]}
{"op":"mcm","clk":"5348001367","pt":1646212188254,"mc":[{"id":"1.195453653","rc":[{"atl":[[2.58,8.63],[2.7,1.42]],"id":35772529},{"atl":[[1.71,13.32],[1.76,0],[1.77,1.42]],"id":37326143}],"con":true,"img":false}]}
{"op":"mcm","clk":"5348001389","pt":1646212188825,"mc":[{"id":"1.195453653","rc":[{"atl":[[1.77,0]],"id":37326143}],"con":true,"img":false}]}
{"op":"mcm","clk":"5348001393","pt":1646212188930,"mc":[{"id":"1.195453653","rc":[{"atl":[[2.76,7.22]],"id":35772529},{"atb":[[1.63,10.06]],"id":37326143}],"con":true,"img":false}]}
{"op":"mcm","clk":"5348001421","pt":1646212189549,"mc":[{"id":"1.195453653","rc":[{"atl":[[2.58,14.99]],"id":35772529},{"atb":[[1.63,20.47]],"id":37326143}],"con":true,"img":false}]}
{"op":"mcm","clk":"5348001425","pt":1646212189649,"mc":[{"id":"1.195453653","rc":[{"atb":[[2.42,29.22]],"id":35772529}],"con":true,"img":false}]}
{"op":"mcm","clk":"5348001435","pt":1646212189855,"mc":[{"id":"1.195453653","rc":[{"atb":[[2.3,1.42]],"id":35772529},{"atl":[[2.56,1.42],[2.7,0]],"id":35772529}],"con":true,"img":false}]}
{"op":"mcm","clk":"5348001447","pt":1646212190115,"mc":[{"id":"1.195453653","rc":[{"atb":[[2.42,8.67]],"id":35772529},{"atl":[[2.58,8.63]],"id":35772529}],"con":true,"img":false}]}
{"op":"mcm","clk":"5348001450","pt":1646212190218,"mc":[{"id":"1.195453653","rc":[{"atl":[[2.56,7.78]],"id":35772529}],"con":true,"img":false}]}
{"op":"mcm","clk":"5348001466","pt":1646212190527,"mc":[{"id":"1.195453653","rc":[{"atl":[[2.56,1.42]],"id":35772529}],"con":true,"img":false}]}
{"op":"mcm","clk":"5348001469","pt":1646212190624,"mc":[{"id":"1.195453653","rc":[{"atl":[[2.56,0]],"id":35772529},{"atb":[[1.63,66.79]],"id":37326143}],"con":true,"img":false}]}
{"op":"mcm","clk":"5348001482","pt":1646212190934,"mc":[{"id":"1.195453653","rc":[{"atl":[[2.58,13.65]],"id":35772529}],"con":true,"img":false}]}
{"op":"mcm","clk":"5348001490","pt":1646212191140,"mc":[{"id":"1.195453653","rc":[{"atb":[[1.63,20.47]],"id":37326143}],"con":true,"img":false}]}
{"op":"mcm","clk":"5348001518","pt":1646212191651,"mc":[{"id":"1.195453653","rc":[{"atb":[[2.42,29.22]],"id":35772529}],"con":true,"img":false}]}
{"op":"mcm","clk":"5348001530","pt":1646212191808,"mc":[{"id":"1.195453653","rc":[{"atl":[[2.56,1.42]],"id":35772529}],"con":true,"img":false}]}
{"op":"mcm","clk":"5348001550","pt":1646212192121,"mc":[{"id":"1.195453653","rc":[{"atl":[[2.58,8.63]],"id":35772529}],"con":true,"img":false}]}
{"op":"mcm","clk":"5348001555","pt":1646212192225,"mc":[{"id":"1.195453653","rc":[{"atl":[[2.56,6.44]],"id":35772529}],"con":true,"img":false}]}
{"op":"mcm","clk":"5348001573","pt":1646212192531,"mc":[{"id":"1.195453653","rc":[{"atl":[[2.56,5.02]],"id":35772529}],"con":true,"img":false}]}
{"op":"mcm","clk":"5348001586","pt":1646212192740,"mc":[{"id":"1.195453653","rc":[{"atb":[[1.99,0],[1.79,0],[1.89,0]],"id":35772529},{"atb":[[1.43,0],[1.33,0],[1.53,0]],"id":37326143}],"con":true,"img":false}]}
{"op":"mcm","clk":"5348001594","pt":1646212192845,"mc":[{"id":"1.195453653","rc":[{"atl":[[2.56,0],[2.72,1.42]],"id":35772529}],"con":true,"img":false}]}
{"op":"mcm","clk":"5348001607","pt":1646212193155,"mc":[{"id":"1.195453653","rc":[{"atl":[[2.58,14.93]],"id":35772529}],"con":true,"img":false}]}
{"op":"mcm","clk":"5348001645","pt":1646212194343,"mc":[{"id":"1.195453653","rc":[{"atl":[[2.56,1.42]],"id":35772529}],"con":true,"img":false}]}
{"op":"mcm","clk":"5348001659","pt":1646212194652,"mc":[{"id":"1.195453653","rc":[{"atb":[[1.59,49.44]],"id":37326143}],"con":true,"img":false}]}
{"op":"mcm","clk":"5348001695","pt":1646212195328,"mc":[{"id":"1.195453653","rc":[{"atl":[[2.58,8.63]],"id":35772529}],"con":true,"img":false}]}
{"op":"mcm","clk":"5348001699","pt":1646212195426,"mc":[{"id":"1.195453653","rc":[{"atl":[[2.56,6.3]],"id":35772529}],"con":true,"img":false}]}
{"op":"mcm","clk":"5348001708","pt":1646212195639,"mc":[{"id":"1.195453653","rc":[{"atl":[[2.66,1.42]],"id":35772529},{"atb":[[1.59,0]],"id":37326143}],"con":true,"img":false}]}
{"op":"mcm","clk":"5348001713","pt":1646212195742,"mc":[{"id":"1.195453653","rc":[{"atl":[[2.56,0]],"id":35772529}],"con":true,"img":false}]}
{"op":"mcm","clk":"5348001731","pt":1646212196052,"mc":[{"id":"1.195453653","rc":[{"atl":[[2.56,6.08]],"id":35772529}],"con":true,"img":false}]}
{"op":"mcm","clk":"5348001741","pt":1646212196464,"mc":[{"id":"1.195453653","rc":[{"atl":[[2.56,0]],"id":35772529}],"con":true,"img":false}]}
{"op":"mcm","clk":"5348001752","pt":1646212196668,"mc":[{"id":"1.195453653","rc":[{"atb":[[1.59,49.44]],"id":37326143}],"con":true,"img":false}]}
{"op":"mcm","clk":"5348001764","pt":1646212196833,"mc":[{"id":"1.195453653","rc":[{"atl":[[2.58,15.26]],"id":35772529}],"con":true,"img":false}]}
{"op":"mcm","clk":"5348001773","pt":1646212197031,"mc":[{"id":"1.195453653","rc":[{"atl":[[2.72,0],[2.66,0]],"id":35772529}],"con":true,"img":false}]}
{"op":"mcm","clk":"5348001777","pt":1646212197134,"mc":[{"id":"1.195453653","rc":[{"atl":[[80,0.88]],"id":35772529},{"atb":[[1.54,0]],"id":37326143}],"con":true,"img":false}]}
{"op":"mcm","clk":"5348001789","pt":1646212197658,"mc":[{"id":"1.195453653","rc":[{"atl":[[2.58,8.63]],"id":35772529},{"atb":[[1.59,0],[1.63,10.06]],"id":37326143}],"con":true,"img":false}]}
{"op":"mcm","clk":"5348001802","pt":1646212197973,"mc":[{"id":"1.195453653","rc":[{"atb":[[2.32,22.1],[2.34,9.33]],"id":35772529}],"con":true,"img":false}]}
{"op":"mcm","clk":"5348001808","pt":1646212198067,"mc":[{"id":"1.195453653","rc":[{"atl":[[80,0]],"id":35772529}],"con":true,"img":false}]}
{"op":"mcm","clk":"5348001815","pt":1646212198172,"mc":[{"id":"1.195453653","rc":[{"atl":[[2.56,1.42]],"id":35772529},{"atb":[[1.57,0]],"id":37326143}],"con":true,"img":false}]}
{"op":"mcm","clk":"5348001819","pt":1646212198274,"mc":[{"id":"1.195453653","rc":[{"atl":[[2.58,13.7]],"id":35772529},{"atb":[[1.63,18.43]],"id":37326143}],"con":true,"img":false}]}
{"op":"mcm","clk":"5348001843","pt":1646212198639,"mc":[{"id":"1.195453653","rc":[{"atb":[[1.57,51.18]],"id":37326143}],"con":true,"img":false}]}
{"op":"mcm","clk":"5348001849","pt":1646212198846,"mc":[{"id":"1.195453653","rc":[{"atl":[[2.56,0],[2.58,12.28]],"id":35772529}],"con":true,"img":false}]}
{"op":"mcm","clk":"5348001881","pt":1646212199530,"mc":[{"id":"1.195453653","rc":[{"atb":[[2.44,7.2],[2.34,2]],"id":35772529},{"atl":[[2.58,5.07]],"id":35772529},{"atb":[[1.63,8.37]],"id":37326143}],"con":true,"img":false}]}
{"op":"mcm","clk":"5348001891","pt":1646212199737,"mc":[{"id":"1.195453653","rc":[{"atl":[[80,0.88]],"id":35772529}],"con":true,"img":false}]}
{"op":"mcm","clk":"5348001895","pt":1646212199843,"mc":[{"id":"1.195453653","rc":[{"atl":[[2.58,0]],"id":35772529},{"atb":[[1.63,0]],"id":37326143}],"con":true,"img":false}]}
{"op":"mcm","clk":"5348001912","pt":1646212200153,"mc":[{"id":"1.195453653","rc":[{"atb":[[2.32,0],[2.42,8.67],[2.38,1.42]],"id":35772529},{"atb":[[1.57,0]],"id":37326143}],"con":true,"img":false}]}
{"op":"mcm","clk":"5348001916","pt":1646212200266,"mc":[{"id":"1.195453653","rc":[{"atl":[[2.76,16.67]],"id":35772529},{"atb":[[1.57,16.38]],"id":37326143}],"con":true,"img":false}]}
{"op":"mcm","clk":"5348001919","pt":1646212200362,"mc":[{"id":"1.195453653","rc":[{"atb":[[1.58,12.13]],"id":37326143}],"con":true,"img":false}]}
{"op":"mcm","clk":"5348001929","pt":1646212200668,"mc":[{"id":"1.195453653","rc":[{"atb":[[1.57,0]],"id":37326143}],"con":true,"img":false}]}
{"op":"mcm","clk":"5348001931","pt":1646212200777,"mc":[{"id":"1.195453653","rc":[{"atb":[[1.49,18.38]],"id":37326143}],"con":true,"img":false}]}
{"op":"mcm","clk":"5348001949","pt":1646212201142,"mc":[{"id":"1.195453653","rc":[{"atb":[[2.4,7.25],[2.36,7.25],[2.3,0],[2.42,27.8],[2.38,0]],"id":35772529},{"atb":[[1.57,51.18]],"id":37326143},{"atl":[[1.71,11.9]],"id":37326143}],"con":true,"img":false}]}
{"op":"mcm","clk":"5348001957","pt":1646212201353,"mc":[{"id":"1.195453653","rc":[{"atl":[[70,0.97],[2.74,7.11]],"id":35772529}],"con":true,"img":false}]}
{"op":"mcm","clk":"5348001972","pt":1646212201764,"mc":[{"id":"1.195453653","rc":[{"atl":[[2.76,7.22]],"id":35772529}],"con":true,"img":false}]}
{"op":"mcm","clk":"5348001978","pt":1646212201870,"mc":[{"id":"1.195453653","rc":[{"atl":[[2.74,16.56]],"id":35772529}],"con":true,"img":false}]}
{"op":"mcm","clk":"5348001990","pt":1646212202075,"mc":[{"id":"1.195453653","rc":[{"atl":[[2.72,7.1]],"id":35772529}],"con":true,"img":false}]}
{"op":"mcm","clk":"5348002000","pt":1646212202286,"mc":[{"id":"1.195453653","rc":[{"atb":[[2,5.39],[1.8,6.74],[1.9,5.99]],"id":35772529},{"atb":[[1.32,16.86],[1.42,12.84],[1.52,10.37]],"id":37326143}],"con":true,"img":false}]}
{"op":"mcm","clk":"5348002004","pt":1646212202343,"mc":[{"id":"1.195453653","rc":[{"atl":[[2.8,0]],"id":35772529}],"con":true,"img":false}]}
{"op":"mcm","clk":"5348002015","pt":1646212202548,"mc":[{"id":"1.195453653","rc":[{"atl":[[2.74,7.11]],"id":35772529}],"con":true,"img":false}]}
{"op":"mcm","clk":"5348002017","pt":1646212202650,"mc":[{"id":"1.195453653","rc":[{"atl":[[2.72,16.55]],"id":35772529},{"atl":[[1.78,0],[1.77,2]],"id":37326143}],"con":true,"img":false}]}
{"op":"mcm","clk":"5348002027","pt":1646212202858,"mc":[{"id":"1.195453653","rc":[{"atl":[[60,1.02]],"id":35772529}],"con":true,"img":false}]}
{"op":"mcm","clk":"5348002071","pt":1646212203941,"mc":[{"id":"1.195453653","rc":[{"atl":[[2.7,7.12]],"id":35772529}],"con":true,"img":false}]}
{"op":"mcm","clk":"5348002079","pt":1646212204151,"mc":[{"id":"1.195453653","rc":[{"atl":[[2.78,0]],"id":35772529}],"con":true,"img":false}]}
{"op":"mcm","clk":"5348002089","pt":1646212204357,"mc":[{"id":"1.195453653","rc":[{"atb":[[2.46,1.42]],"id":35772529},{"atl":[[2.72,7.1],[50,1.13]],"id":35772529}],"con":true,"img":false}]}
{"op":"mcm","clk":"5348002096","pt":1646212204562,"mc":[{"id":"1.195453653","rc":[{"atb":[[2.36,0],[2.46,8.54]],"id":35772529}],"con":true,"img":false}]}
{"op":"mcm","clk":"5348002105","pt":1646212204768,"mc":[{"id":"1.195453653","rc":[{"atl":[[2.7,17.25]],"id":35772529}],"con":true,"img":false}]}
{"op":"mcm","clk":"5348002160","pt":1646212205752,"mc":[{"id":"1.195453653","rc":[{"atb":[[2.48,1.42]],"id":35772529},{"atl":[[46,1.2],[2.68,7.06],[2.76,0]],"id":35772529}],"con":true,"img":false}]}
{"op":"mcm","clk":"5348002182","pt":1646212206063,"mc":[{"id":"1.195453653","rc":[{"atl":[[2.7,7.12]],"id":35772529}],"con":true,"img":false}]}
{"op":"mcm","clk":"5348002185","pt":1646212206167,"mc":[{"id":"1.195453653","rc":[{"atl":[[2.68,17.19]],"id":35772529},{"atb":[[1.59,49.44]],"id":37326143}],"con":true,"img":false}]}
{"op":"mcm","clk":"5348002204","pt":1646212206477,"mc":[{"id":"1.195453653","rc":[{"atb":[[2.48,0]],"id":35772529},{"atl":[[70,0],[2.74,0],[80,0],[46,0],[50,0],[2.66,7.09],[60,0]],"id":35772529},{"atb":[[1.6,12.25]],"id":37326143}],"con":true,"img":false}]}
{"op":"mcm","clk":"5348002231","pt":1646212206984,"mc":[{"id":"1.195453653","rc":[{"atl":[[2.68,7.06]],"id":35772529}],"con":true,"img":false}]}
{"op":"mcm","clk":"5348002235","pt":1646212207089,"mc":[{"id":"1.195453653","rc":[{"atl":[[2.66,17.22],[2.62,1.42]],"id":35772529}],"con":true,"img":false}]}
{"op":"mcm","clk":"5348002253","pt":1646212207455,"mc":[{"id":"1.195453653","rc":[{"atl":[[2.66,7.09]],"id":35772529}],"con":true,"img":false}]}
{"op":"mcm","clk":"5348002256","pt":1646212207557,"mc":[{"id":"1.195453653","rc":[{"atl":[[2.62,11.55]],"id":35772529}],"con":true,"img":false}]}
{"op":"mcm","clk":"5348002264","pt":1646212207762,"mc":[{"id":"1.195453653","rc":[{"atb":[[2.36,2],[2.34,0]],"id":35772529}],"con":true,"img":false}]}
{"op":"mcm","clk":"5348002275","pt":1646212207970,"mc":[{"id":"1.195453653","rc":[{"atl":[[2.62,4.26]],"id":35772529}],"con":true,"img":false}]}
{"op":"mcm","clk":"5348002289","pt":1646212208278,"mc":[{"id":"1.195453653","rc":[{"atl":[[2.62,1.42]],"id":35772529},{"atb":[[1.49,2]],"id":37326143}],"con":true,"img":false}]}
{"op":"mcm","clk":"5348002314","pt":1646212208851,"mc":[{"id":"1.195453653","rc":[{"atl":[[2.6,1.42]],"id":35772529}],"con":true,"img":false}]}
{"op":"mcm","clk":"5348002317","pt":1646212208998,"mc":[{"id":"1.195453653","rc":[{"atb":[[1.6,25.76]],"id":37326143}],"con":true,"img":false}]}
{"op":"mcm","clk":"5348002324","pt":1646212209161,"mc":[{"id":"1.195453653","rc":[{"atl":[[2.62,8.55]],"id":35772529},{"atb":[[1.61,12.18]],"id":37326143}],"con":true,"img":false}]}
{"op":"mcm","clk":"5348002330","pt":1646212209367,"mc":[{"id":"1.195453653","rc":[{"atl":[[2.72,0]],"id":35772529}],"con":true,"img":false}]}
{"op":"mcm","clk":"5348002335","pt":1646212209474,"mc":[{"id":"1.195453653","rc":[{"atb":[[1.6,12.25]],"id":37326143}],"con":true,"img":false}]}
{"op":"mcm","clk":"5348002340","pt":1646212209572,"mc":[{"id":"1.195453653","rc":[{"atb":[[1.61,25.69]],"id":37326143}],"con":true,"img":false}]}
{"op":"mcm","clk":"5348002344","pt":1646212209672,"mc":[{"id":"1.195453653","rc":[{"atl":[[2.6,0],[2.66,0],[2.62,1.42],[2.68,0],[2.7,0]],"id":35772529},{"atb":[[1.6,0],[1.61,13.51]],"id":37326143}],"con":true,"img":false}]}
{"op":"mcm","clk":"5348002365","pt":1646212210086,"mc":[{"id":"1.195453653","rc":[{"atb":[[2.38,21.14]],"id":35772529},{"atb":[[1.61,0]],"id":37326143}],"con":true,"img":false}]}
{"op":"mcm","clk":"5348002370","pt":1646212210191,"mc":[{"id":"1.195453653","rc":[{"atb":[[2.42,7.25]],"id":35772529},{"atl":[[2.6,1.42]],"id":35772529},{"atb":[[1.59,0],[1.57,0]],"id":37326143}],"con":true,"img":false}]}
{"op":"mcm","clk":"5348002380","pt":1646212210395,"mc":[{"id":"1.195453653","rc":[{"atl":[[2.82,8.89]],"id":35772529}],"con":true,"img":false}]}
{"op":"mcm","clk":"5348002392","pt":1646212210603,"mc":[{"id":"1.195453653","rc":[{"atb":[[1.59,36.59]],"id":37326143}],"con":true,"img":false}]}
{"op":"mcm","clk":"5348002400","pt":1646212210763,"mc":[{"id":"1.195453653","rc":[{"atb":[[1.58,0]],"id":37326143}],"con":true,"img":false}]}
{"op":"mcm","clk":"5348002409","pt":1646212210970,"mc":[{"id":"1.195453653","rc":[{"atb":[[1.59,0],[1.53,12.83]],"id":37326143}],"con":true,"img":false}]}
{"op":"mcm","clk":"5348002416","pt":1646212211074,"mc":[{"id":"1.195453653","rc":[{"atb":[[2.44,27.46]],"id":35772529},{"atb":[[1.55,53.05]],"id":37326143}],"con":true,"img":false}]}
{"op":"mcm","clk":"5348002418","pt":1646212211178,"mc":[{"id":"1.195453653","rc":[{"atb":[[1.5,2],[1.49,0]],"id":37326143}],"con":true,"img":false}]}
{"op":"mcm","clk":"5348002422","pt":1646212211277,"mc":[{"id":"1.195453653","rc":[{"atl":[[2.6,0],[2.62,0]],"id":35772529}],"con":true,"img":false}]}
{"op":"mcm","clk":"5348002429","pt":1646212211382,"mc":[{"id":"1.195453653","rc":[{"atl":[[75,0.88]],"id":35772529},{"atb":[[1.53,38.51]],"id":37326143}],"con":true,"img":false}]}
{"op":"mcm","clk":"5348002439","pt":1646212211585,"mc":[{"id":"1.195453653","rc":[{"atl":[[1.76,2],[1.77,0]],"id":37326143}],"con":true,"img":false}]}
{"op":"mcm","clk":"5348002443","pt":1646212211688,"mc":[{"id":"1.195453653","rc":[{"atb":[[1.55,0]],"id":37326143}],"con":true,"img":false}]}
{"op":"mcm","clk":"5348002455","pt":1646212211893,"mc":[{"id":"1.195453653","rc":[{"atb":[[1.53,12.83]],"id":37326143}],"con":true,"img":false}]}
{"op":"mcm","clk":"5348002464","pt":1646212212158,"mc":[{"id":"1.195453653","rc":[{"atb":[[2.38,0]],"id":35772529},{"atb":[[1.53,31.76]],"id":37326143}],"con":true,"img":false}]}
{"op":"mcm","clk":"5348002489","pt":1646212212778,"mc":[{"id":"1.195453653","rc":[{"atb":[[2.52,1.42]],"id":35772529},{"atl":[[60,0.85]],"id":35772529}],"con":true,"img":false}]}
{"op":"mcm","clk":"5348002496","pt":1646212212878,"mc":[{"id":"1.195453653","rc":[{"atb":[[2.36,0],[2.38,2]],"id":35772529}],"con":true,"img":false}]}
{"op":"mcm","clk":"5348002508","pt":1646212213085,"mc":[{"id":"1.195453653","rc":[{"atb":[[1.53,86.82]],"id":37326143}],"con":true,"img":false}]}
{"op":"mcm","clk":"5348002512","pt":1646212213185,"mc":[{"id":"1.195453653","rc":[{"atb":[[2.52,8.3]],"id":35772529}],"con":true,"img":false}]}
{"op":"mcm","clk":"5348002518","pt":1646212213289,"mc":[{"id":"1.195453653","rc":[{"atb":[[2.4,0]],"id":35772529}],"con":true,"img":false}]}
{"op":"mcm","clk":"5348002526","pt":1646212213497,"mc":[{"id":"1.195453653","rc":[{"atb":[[2.52,6.87]],"id":35772529}],"con":true,"img":false}]}
{"op":"mcm","clk":"5348002537","pt":1646212213699,"mc":[{"id":"1.195453653","rc":[{"atl":[[1.71,19.64]],"id":37326143}],"con":true,"img":false}]}
{"op":"mcm","clk":"5348002549","pt":1646212213956,"mc":[{"id":"1.195453653","rc":[{"atl":[[2.82,15.47],[38,1.13]],"id":35772529},{"atb":[[1.54,12.9]],"id":37326143}],"con":true,"img":false}]}
{"op":"mcm","clk":"5348002567","pt":1646212214275,"mc":[{"id":"1.195453653","rc":[{"atl":[[1.7,12.89],[1.75,0]],"id":37326143}],"con":true,"img":false}]}
{"op":"mcm","clk":"5348002574","pt":1646212214379,"mc":[{"id":"1.195453653","rc":[{"atl":[[2.8,6.83]],"id":35772529},{"atb":[[1.53,67.89]],"id":37326143}],"con":true,"img":false}]}
{"op":"mcm","clk":"5348002578","pt":1646212214480,"mc":[{"id":"1.195453653","rc":[{"atb":[[1.54,31.83]],"id":37326143}],"con":true,"img":false}]}
{"op":"mcm","clk":"5348002593","pt":1646212214825,"mc":[{"id":"1.195453653","rc":[{"atb":[[1.55,12.82]],"id":37326143}],"con":true,"img":false}]}
{"op":"mcm","clk":"5348002597","pt":1646212214890,"mc":[{"id":"1.195453653","rc":[{"atl":[[2.82,8.89]],"id":35772529}],"con":true,"img":false}]}
{"op":"mcm","clk":"5348002603","pt":1646212214993,"mc":[{"id":"1.195453653","rc":[{"atb":[[2.52,0]],"id":35772529},{"atl":[[2.8,13.41]],"id":35772529}],"con":true,"img":false}]}
{"op":"mcm","clk":"5348002609","pt":1646212215099,"mc":[{"id":"1.195453653","rc":[{"atb":[[1.55,65.88]],"id":37326143}],"con":true,"img":false}]}
{"op":"mcm","clk":"5348002620","pt":1646212215305,"mc":[{"id":"1.195453653","rc":[{"atl":[[2.78,7.05]],"id":35772529},{"atb":[[1.54,12.9]],"id":37326143}],"con":true,"img":false}]}
{"op":"mcm","clk":"5348002626","pt":1646212215405,"mc":[{"id":"1.195453653","rc":[{"atb":[[1.55,84.81]],"id":37326143},{"atl":[[1.71,11.9]],"id":37326143}],"con":true,"img":false}]}
{"op":"mcm","clk":"5348002631","pt":1646212215507,"mc":[{"id":"1.195453653","rc":[{"atb":[[2.5,1.42],[2.46,15.49]],"id":35772529},{"atl":[[2.8,6.83],[42,1.36]],"id":35772529},{"atb":[[1.56,12.36]],"id":37326143},{"atl":[[1.68,1.42]],"id":37326143}],"con":true,"img":false}]}
{"op":"mcm","clk":"5348002652","pt":1646212215976,"mc":[{"id":"1.195453653","rc":[{"atb":[[2.46,8.54]],"id":35772529},{"atb":[[1.55,65.88]],"id":37326143}],"con":true,"img":false}]}
{"op":"mcm","clk":"5348002656","pt":1646212216078,"mc":[{"id":"1.195453653","rc":[{"atl":[[75,0],[38,0],[42,0],[60,0]],"id":35772529}],"con":true,"img":false}]}
{"op":"mcm","clk":"5348002678","pt":1646212216390,"mc":[{"id":"1.195453653","rc":[{"atl":[[1.73,0],[1.68,13.61]],"id":37326143}],"con":true,"img":false}]}
{"op":"mcm","clk":"5348002682","pt":1646212216490,"mc":[{"id":"1.195453653","rc":[{"atb":[[2.52,1.42]],"id":35772529},{"atl":[[2.7,1.42]],"id":35772529}],"con":true,"img":false}]}
{"op":"mcm","clk":"5348002686","pt":1646212216598,"mc":[{"id":"1.195453653","rc":[{"atl":[[1.68,16.45]],"id":37326143}],"con":true,"img":false}]}
{"op":"mcm","clk":"5348002703","pt":1646212217009,"mc":[{"id":"1.195453653","rc":[{"atl":[[2.7,4.26]],"id":35772529},{"atb":[[1.56,37.1]],"id":37326143},{"atl":[[1.68,13.61]],"id":37326143}],"con":true,"img":false}]}
{"op":"mcm","clk":"5348002708","pt":1646212217107,"mc":[{"id":"1.195453653","rc":[{"atb":[[2.48,19.71]],"id":35772529}],"con":true,"img":false}]}
{"op":"mcm","clk":"5348002710","pt":1646212217160,"mc":[{"id":"1.195453653","rc":[{"atb":[[2.52,0]],"id":35772529},{"atl":[[2.7,2.84]],"id":35772529}],"con":true,"img":false}]}
{"op":"mcm","clk":"5348002724","pt":1646212217471,"mc":[{"id":"1.195453653","rc":[{"atl":[[2.7,0]],"id":35772529}],"con":true,"img":false}]}
{"op":"mcm","clk":"5348002728","pt":1646212217575,"mc":[{"id":"1.195453653","rc":[{"atb":[[2.48,0]],"id":35772529}],"con":true,"img":false}]}
{"op":"mcm","clk":"5348002734","pt":1646212217681,"mc":[{"id":"1.195453653","rc":[{"atb":[[2.52,1.42],[2.46,7.12]],"id":35772529},{"atl":[[2.68,1.42]],"id":35772529}],"con":true,"img":false}]}
{"op":"mcm","clk":"5348002737","pt":1646212217784,"mc":[{"id":"1.195453653","rc":[{"atl":[[2.78,21.15]],"id":35772529}],"con":true,"img":false}]}
{"op":"mcm","clk":"5348002756","pt":1646212218195,"mc":[{"id":"1.195453653","rc":[{"atb":[[1.57,51.18]],"id":37326143}],"con":true,"img":false}]}
{"op":"mcm","clk":"5348002773","pt":1646212218397,"mc":[{"id":"1.195453653","rc":[{"atb":[[1.58,12.33],[1.53,55.05]],"id":37326143}],"con":true,"img":false}]}
{"op":"mcm","clk":"5348002779","pt":1646212218606,"mc":[{"id":"1.195453653","rc":[{"atb":[[1.56,12.36]],"id":37326143}],"con":true,"img":false}]}
{"op":"mcm","clk":"5348002782","pt":1646212218708,"mc":[{"id":"1.195453653","rc":[{"atb":[[2.52,0]],"id":35772529},{"atl":[[2.68,0]],"id":35772529}],"con":true,"img":false}]}
{"op":"mcm","clk":"5348002796","pt":1646212218975,"mc":[{"id":"1.195453653","rc":[{"atb":[[1.58,26.46]],"id":37326143}],"con":true,"img":false}]}
{"op":"mcm","clk":"5348002823","pt":1646212219282,"mc":[{"id":"1.195453653","rc":[{"atl":[[2.68,1.42]],"id":35772529}],"con":true,"img":false}]}
{"op":"mcm","clk":"5348002836","pt":1646212219488,"mc":[{"id":"1.195453653","rc":[{"atl":[[1.68,12.19]],"id":37326143}],"con":true,"img":false}]}
{"op":"mcm","clk":"5348002846","pt":1646212219591,"mc":[{"id":"1.195453653","rc":[{"atl":[[2.68,8.52]],"id":35772529},{"atb":[[1.59,12.27],[1.54,0]],"id":37326143},{"atl":[[1.68,0]],"id":37326143}],"con":true,"img":false}]}
{"op":"mcm","clk":"5348002874","pt":1646212219900,"mc":[{"id":"1.195453653","rc":[{"atb":[[1.58,12.33]],"id":37326143}],"con":true,"img":false}]}
{"op":"mcm","clk":"5348002883","pt":1646212220011,"mc":[{"id":"1.195453653","rc":[{"atl":[[2.68,7.1]],"id":35772529},{"atb":[[1.59,26.4]],"id":37326143}],"con":true,"img":false}]}
{"op":"mcm","clk":"5348002888","pt":1646212220105,"mc":[{"id":"1.195453653","rc":[{"atb":[[2.46,0]],"id":35772529}],"con":true,"img":false}]}
{"op":"mcm","clk":"5348002902","pt":1646212220315,"mc":[{"id":"1.195453653","rc":[{"atb":[[2.46,7.16]],"id":35772529},{"atl":[[2.66,1.42]],"id":35772529}],"con":true,"img":false}]}
{"op":"mcm","clk":"5348002921","pt":1646212220673,"mc":[{"id":"1.195453653","rc":[{"atb":[[1.53,0]],"id":37326143}],"con":true,"img":false}]}
{"op":"mcm","clk":"5348002935","pt":1646212220882,"mc":[{"id":"1.195453653","rc":[{"atb":[[2.5,0]],"id":35772529}],"con":true,"img":false}]}
{"op":"mcm","clk":"5348002939","pt":1646212220985,"mc":[{"id":"1.195453653","rc":[{"atb":[[2.36,2]],"id":35772529}],"con":true,"img":false}]}
{"op":"mcm","clk":"5348002945","pt":1646212221090,"mc":[{"id":"1.195453653","rc":[{"atb":[[2.38,0]],"id":35772529},{"atb":[[1.59,75.85]],"id":37326143}],"con":true,"img":false}]}
{"op":"mcm","clk":"5348002976","pt":1646212221497,"mc":[{"id":"1.195453653","rc":[{"atl":[[2.62,1.42]],"id":35772529}],"con":true,"img":false}]}
{"op":"mcm","clk":"5348002979","pt":1646212221600,"mc":[{"id":"1.195453653","rc":[{"atb":[[2.46,0],[2.44,20.26]],"id":35772529},{"atl":[[2.82,2],[2.66,8.61]],"id":35772529},{"atb":[[1.6,12.04],[1.55,53.05]],"id":37326143}],"con":true,"img":false}]}
{"op":"mcm","clk":"5348002984","pt":1646212221700,"mc":[{"id":"1.195453653","rc":[{"atl":[[2.8,0],[2.62,8.62]],"id":35772529}],"con":true,"img":false}]}
{"op":"mcm","clk":"5348002990","pt":1646212221813,"mc":[{"id":"1.195453653","rc":[{"atb":[[2.42,0]],"id":35772529},{"atl":[[1.7,0]],"id":37326143}],"con":true,"img":false}]}
{"op":"mcm","clk":"5348002999","pt":1646212222022,"mc":[{"id":"1.195453653","rc":[{"atb":[[1.59,61.72]],"id":37326143},{"atl":[[1.71,0]],"id":37326143}],"con":true,"img":false}]}
{"op":"mcm","clk":"5348003003","pt":1646212222112,"mc":[{"id":"1.195453653","rc":[{"atb":[[2.36,9.32],[2.02,28.6],[2.44,0]],"id":35772529},{"atb":[[1.59,12.27]],"id":37326143}],"con":true,"img":false}]}
{"op":"mcm","clk":"5348003020","pt":1646212222283,"mc":[{"id":"1.195453653","rc":[{"atb":[[2.36,7.32],[2.38,2]],"id":35772529},{"atl":[[1.75,2],[1.76,0]],"id":37326143}],"con":true,"img":false}]}
{"op":"mcm","clk":"5348003035","pt":1646212222529,"mc":[{"id":"1.195453653","rc":[{"atb":[[1.6,28.42]],"id":37326143}],"con":true,"img":false}]}
{"op":"mcm","clk":"5348003039","pt":1646212222591,"mc":[{"id":"1.195453653","rc":[{"atl":[[2.6,1.42]],"id":35772529}],"con":true,"img":false}]}
{"op":"mcm","clk":"5348003072","pt":1646212223104,"mc":[{"id":"1.195453653","rc":[{"atb":[[1.58,62.63]],"id":37326143}],"con":true,"img":false}]}
{"op":"mcm","clk":"5348003112","pt":1646212223510,"mc":[{"id":"1.195453653","rc":[{"atl":[[2.6,0]],"id":35772529},{"atb":[[1.56,0],[1.61,11.94]],"id":37326143}],"con":true,"img":false}]}
{"op":"mcm","clk":"5348003121","pt":1646212223668,"mc":[{"id":"1.195453653","rc":[{"atb":[[2.38,9.25]],"id":35772529}],"con":true,"img":false}]}
{"op":"mcm","clk":"5348003127","pt":1646212223871,"mc":[{"id":"1.195453653","rc":[{"atb":[[1.6,12.04]],"id":37326143}],"con":true,"img":false}]}
{"op":"mcm","clk":"5348003131","pt":1646212223979,"mc":[{"id":"1.195453653","rc":[{"atl":[[2.56,1.42]],"id":35772529},{"atb":[[1.61,28.32]],"id":37326143},{"atl":[[60,1.2]],"id":37326143}],"con":true,"img":false}]}
{"op":"mcm","clk":"5348003136","pt":1646212224080,"mc":[{"id":"1.195453653","rc":[{"atb":[[2.02,0],[2.32,22.1]],"id":35772529},{"atb":[[1.55,0]],"id":37326143}],"con":true,"img":false}]}
{"op":"mcm","clk":"5348003146","pt":1646212224389,"mc":[{"id":"1.195453653","rc":[{"atb":[[1.58,50.3],[1.62,12.03]],"id":37326143}],"con":true,"img":false}]}
{"op":"mcm","clk":"5348003162","pt":1646212224804,"mc":[{"id":"1.195453653","rc":[{"atl":[[2.56,0]],"id":35772529},{"atb":[[1.61,11.94]],"id":37326143}],"con":true,"img":false}]}
{"op":"mcm","clk":"5348003167","pt":1646212224906,"mc":[{"id":"1.195453653","rc":[{"atb":[[1.62,28.41]],"id":37326143}],"con":true,"img":false}]}
{"op":"mcm","clk":"5348003171","pt":1646212225110,"mc":[{"id":"1.195453653","rc":[{"atb":[[2.38,30.39]],"id":35772529},{"atb":[[1.62,75.47]],"id":37326143}],"con":true,"img":false}]}
{"op":"mcm","clk":"5348003180","pt":1646212225311,"mc":[{"id":"1.195453653","rc":[{"atl":[[2.54,1.42],[2.46,8.17]],"id":35772529},{"atl":[[65,1.26]],"id":37326143}],"con":true,"img":false}]}
{"op":"mcm","clk":"5348003182","pt":1646212225417,"mc":[{"id":"1.195453653","rc":[{"atb":[[1.59,0],[1.63,12.03]],"id":37326143}],"con":true,"img":false}]}
{"op":"mcm","clk":"5348003190","pt":1646212225574,"mc":[{"id":"1.195453653","rc":[{"atb":[[2.38,9.25]],"id":35772529},{"atl":[[60,0]],"id":37326143}],"con":true,"img":false}]}
{"op":"mcm","clk":"5348003200","pt":1646212225783,"mc":[{"id":"1.195453653","rc":[{"atb":[[1.62,59.09]],"id":37326143}],"con":true,"img":false}]}
{"op":"mcm","clk":"5348003206","pt":1646212225887,"mc":[{"id":"1.195453653","rc":[{"atb":[[1.63,28.41]],"id":37326143}],"con":true,"img":false}]}
{"op":"mcm","clk":"5348003212","pt":1646212225989,"mc":[{"id":"1.195453653","rc":[{"atb":[[1.64,11.91],[1.6,0]],"id":37326143}],"con":true,"img":false}]}
{"op":"mcm","clk":"5348003220","pt":1646212226092,"mc":[{"id":"1.195453653","rc":[{"atb":[[2.36,28.78]],"id":35772529}],"con":true,"img":false}]}
{"op":"mcm","clk":"5348003240","pt":1646212226502,"mc":[{"id":"1.195453653","rc":[{"atl":[[2.56,1.42]],"id":35772529},{"atb":[[1.63,12.03]],"id":37326143},{"atl":[[70,1.2]],"id":37326143}],"con":true,"img":false}]}
{"op":"mcm","clk":"5348003247","pt":1646212226606,"mc":[{"id":"1.195453653","rc":[{"atb":[[1.64,28.29],[1.57,0]],"id":37326143}],"con":true,"img":false}]}
{"op":"mcm","clk":"5348003259","pt":1646212226910,"mc":[{"id":"1.195453653","rc":[{"atl":[[65,0]],"id":37326143}],"con":true,"img":false}]}
{"op":"mcm","clk":"5348003262","pt":1646212227017,"mc":[{"id":"1.195453653","rc":[{"atb":[[1.64,19.35]],"id":37326143},{"atl":[[1.75,0],[1.71,2]],"id":37326143}],"con":true,"img":false}]}
{"op":"mcm","clk":"5348003268","pt":1646212227123,"mc":[{"id":"1.195453653","rc":[{"atb":[[1.64,64.94]],"id":37326143}],"con":true,"img":false}]}
{"op":"mcm","clk":"5348003292","pt":1646212227486,"mc":[{"id":"1.195453653","rc":[{"atl":[[70,0]],"id":37326143}],"con":true,"img":false}]}
{"op":"mcm","clk":"5348003343","pt":1646212228625,"mc":[{"id":"1.195453653","rc":[{"atl":[[2.52,1.42]],"id":35772529}],"con":true,"img":false}]}
{"op":"mcm","clk":"5348003348","pt":1646212228823,"mc":[{"id":"1.195453653","rc":[{"atl":[[2.56,8.66],[2.78,14.1]],"id":35772529},{"atb":[[1.64,57.5]],"id":37326143}],"con":true,"img":false}]}
{"op":"mcm","clk":"5348003419","pt":1646212230425,"mc":[{"id":"1.195453653","rc":[{"atl":[[2.78,0]],"id":35772529}],"con":true,"img":false}]}
{"op":"mcm","clk":"5348003493","pt":1646212232027,"mc":[{"id":"1.195453653","rc":[{"atl":[[2.54,8.7],[2.68,0]],"id":35772529}],"con":true,"img":false}]}
{"op":"mcm","clk":"5348003499","pt":1646212232135,"mc":[{"id":"1.195453653","rc":[{"atb":[[2.38,26.67]],"id":35772529},{"atl":[[1.71,6]],"id":37326143}],"con":true,"img":false}]}
{"op":"mcm","clk":"5348003534","pt":1646212232717,"mc":[{"id":"1.195453653","rc":[{"atb":[[2.38,9.25]],"id":35772529},{"atl":[[1.71,2]],"id":37326143}],"con":true,"img":false}]}
{"op":"mcm","clk":"5348003538","pt":1646212232820,"mc":[{"id":"1.195453653","rc":[{"atl":[[1.72,0]],"id":37326143}],"con":true,"img":false}]}
{"op":"mcm","clk":"5348003541","pt":1646212232924,"mc":[{"id":"1.195453653","rc":[{"atl":[[2.42,10.89]],"id":35772529}],"con":true,"img":false}]}
{"op":"mcm","clk":"5348003546","pt":1646212233030,"mc":[{"id":"1.195453653","rc":[{"atl":[[1.82,2],[1.71,0]],"id":37326143}],"con":true,"img":false}]}
{"op":"mcm","clk":"5348003550","pt":1646212233128,"mc":[{"id":"1.195453653","rc":[{"atb":[[2.36,7.32],[2.32,0],[1.04,1.45]],"id":35772529},{"atl":[[2.68,1.42]],"id":35772529},{"atb":[[1.65,11.83]],"id":37326143}],"con":true,"img":false}]}
{"op":"mcm","clk":"5348003555","pt":1646212233232,"mc":[{"id":"1.195453653","rc":[{"atl":[[2.52,8.76],[2.66,1.42]],"id":35772529},{"atb":[[1.61,0]],"id":37326143}],"con":true,"img":false}]}
{"op":"mcm","clk":"5348003560","pt":1646212233337,"mc":[{"id":"1.195453653","rc":[{"atb":[[1.04,0.05]],"id":35772529},{"atl":[[2.54,1.42]],"id":35772529},{"atb":[[1.65,0]],"id":37326143},{"atl":[[1.82,13.76]],"id":37326143}],"con":true,"img":false}]}
{"op":"mcm","clk":"5348003564","pt":1646212233441,"mc":[{"id":"1.195453653","rc":[{"atl":[[2.52,1.42]],"id":35772529}],"con":true,"img":false}]}
{"op":"mcm","clk":"5348003568","pt":1646212233504,"mc":[{"id":"1.195453653","rc":[{"atb":[[1.04,0]],"id":35772529}],"con":true,"img":false}]}
{"op":"mcm","clk":"5348003573","pt":1646212233604,"mc":[{"id":"1.195453653","rc":[{"atb":[[2.22,23.91]],"id":35772529},{"atl":[[2.42,10.83]],"id":35772529},{"trd":[[2.42,0.11]],"ltp":2.42,"tv":0.11,"id":35772529}],"con":true,"img":false}]}
{"op":"mcm","clk":"5348003605","pt":1646212234430,"mc":[{"id":"1.195453653","rc":[{"atl":[[2.64,1.42]],"id":35772529}],"con":true,"img":false}]}
{"op":"mcm","clk":"5348003665","pt":1646212235823,"mc":[{"id":"1.195453653","rc":[{"atb":[[1.65,11.82]],"id":37326143}],"con":true,"img":false}]}
{"op":"mcm","clk":"5348003684","pt":1646212236336,"mc":[{"id":"1.195453653","rc":[{"atl":[[2.56,1.42]],"id":35772529},{"atb":[[1.65,0]],"id":37326143}],"con":true,"img":false}]}
{"op":"mcm","clk":"5348003727","pt":1646212237321,"mc":[{"id":"1.195453653","rc":[{"atb":[[2.38,17.39]],"id":35772529},{"atl":[[1.82,33.21]],"id":37326143}],"con":true,"img":false}]}
{"op":"mcm","clk":"5348003739","pt":1646212237633,"mc":[{"id":"1.195453653","rc":[{"atb":[[2.32,22.1],[2.38,11.49]],"id":35772529},{"atl":[[1.82,13.76]],"id":37326143}],"con":true,"img":false}]}
{"op":"mcm","clk":"5348003743","pt":1646212237736,"mc":[{"id":"1.195453653","rc":[{"atl":[[2.16,21.45]],"id":37326143}],"con":true,"img":false}]}
{"op":"mcm","clk":"5348003771","pt":1646212238144,"mc":[{"id":"1.195453653","rc":[{"atb":[[2.32,0]],"id":35772529}],"con":true,"img":false}]}
{"op":"mcm","clk":"5348003778","pt":1646212238202,"mc":[{"id":"1.195453653","rc":[{"atl":[[2.52,8.76]],"id":35772529},{"atb":[[1.65,11.72]],"id":37326143}],"con":true,"img":false}]}
{"op":"mcm","clk":"5348003784","pt":1646212238305,"mc":[{"id":"1.195453653","rc":[{"atb":[[2.38,4.24]],"id":35772529}],"con":true,"img":false}]}
{"op":"mcm","clk":"5348003796","pt":1646212238619,"mc":[{"id":"1.195453653","rc":[{"atb":[[1.58,0]],"id":37326143}],"con":true,"img":false}]}
{"op":"mcm","clk":"5348003811","pt":1646212238823,"mc":[{"id":"1.195453653","rc":[{"atb":[[2.38,1.99]],"id":35772529},{"atl":[[2.16,2]],"id":37326143}],"con":true,"img":false}]}
{"op":"mcm","clk":"5348003823","pt":1646212239133,"mc":[{"id":"1.195453653","rc":[{"atb":[[2.22,0]],"id":35772529}],"con":true,"img":false}]}
{"op":"mcm","clk":"5348003843","pt":1646212239441,"mc":[{"id":"1.195453653","rc":[{"atl":[[1.82,28.94]],"id":37326143}],"con":true,"img":false}]}
{"op":"mcm","clk":"5348003850","pt":1646212239647,"mc":[{"id":"1.195453653","rc":[{"atb":[[2.22,23.91]],"id":35772529},{"atb":[[1.66,44.2]],"id":37326143}],"con":true,"img":false}]}
{"op":"mcm","clk":"5348003881","pt":1646212240332,"mc":[{"id":"1.195453653","rc":[{"atb":[[2.38,6]],"id":35772529}],"con":true,"img":false}]}
{"op":"mcm","clk":"5348003890","pt":1646212240527,"mc":[{"id":"1.195453653","rc":[{"atl":[[1.81,11.59]],"id":37326143}],"con":true,"img":false}]}
{"op":"mcm","clk":"5348003894","pt":1646212240630,"mc":[{"id":"1.195453653","rc":[{"atl":[[2.46,0]],"id":35772529}],"con":true,"img":false}]}
{"op":"mcm","clk":"5348003905","pt":1646212240735,"mc":[{"id":"1.195453653","rc":[{"atl":[[2.42,19.01]],"id":35772529},{"atl":[[1.82,26.94],[1.8,2]],"id":37326143}],"con":true,"img":false}]}
{"op":"mcm","clk":"5348003912","pt":1646212240850,"mc":[{"id":"1.195453653","rc":[{"atb":[[2.38,13.37]],"id":35772529},{"atl":[[2.52,1.42]],"id":35772529}],"con":true,"img":false}]}
{"op":"mcm","clk":"5348003919","pt":1646212240941,"mc":[{"id":"1.195453653","rc":[{"atl":[[1.82,11.76]],"id":37326143}],"con":true,"img":false}]}
{"op":"mcm","clk":"5348003925","pt":1646212241045,"mc":[{"id":"1.195453653","rc":[{"atb":[[2.38,6]],"id":35772529}],"con":true,"img":false}]}
{"op":"mcm","clk":"5348003929","pt":1646212241150,"mc":[{"id":"1.195453653","rc":[{"atl":[[2.52,8.77]],"id":35772529},{"atb":[[1.66,0]],"id":37326143},{"atl":[[1.8,13.63]],"id":37326143}],"con":true,"img":false}]}
{"op":"mcm","clk":"5348003936","pt":1646212241302,"mc":[{"id":"1.195453653","rc":[{"atl":[[1.8,17.63]],"id":37326143}],"con":true,"img":false}]}
{"op":"mcm","clk":"5348003959","pt":1646212241615,"mc":[{"id":"1.195453653","rc":[{"atb":[[2.26,23.15]],"id":35772529},{"atb":[[1.66,44.2]],"id":37326143}],"con":true,"img":false}]}
{"op":"mcm","clk":"5348004078","pt":1646212243636,"mc":[{"id":"1.195453653","rc":[{"atb":[[2.38,2]],"id":35772529},{"atl":[[1.8,13.63]],"id":37326143}],"con":true,"img":false}]}
{"op":"mcm","clk":"5348004093","pt":1646212243843,"mc":[{"id":"1.195453653","rc":[{"atb":[[2.38,9.36]],"id":35772529},{"atl":[[2.52,1.42]],"id":35772529}],"con":true,"img":false}]}
{"op":"mcm","clk":"5348004109","pt":1646212244152,"mc":[{"id":"1.195453653","rc":[{"atb":[[1.66,0]],"id":37326143}],"con":true,"img":false}]}
{"op":"mcm","clk":"5348004130","pt":1646212244516,"mc":[{"id":"1.195453653","rc":[{"atl":[[2.54,8.73]],"id":35772529}],"con":true,"img":false}]}
{"op":"mcm","clk":"5348004158","pt":1646212245148,"mc":[{"id":"1.195453653","rc":[{"atl":[[2.54,1.42]],"id":35772529}],"con":true,"img":false}]}
{"op":"mcm","clk":"5348004169","pt":1646212245347,"mc":[{"id":"1.195453653","rc":[{"atb":[[2.36,0],[2.38,2]],"id":35772529},{"atl":[[2.52,8.82]],"id":35772529}],"con":true,"img":false}]}
{"op":"mcm","clk":"5348004178","pt":1646212245552,"mc":[{"id":"1.195453653","rc":[{"atb":[[2.34,2]],"id":35772529}],"con":true,"img":false}]}
{"op":"mcm","clk":"5348004182","pt":1646212245655,"mc":[{"id":"1.195453653","rc":[{"atb":[[2.38,0],[2.26,0]],"id":35772529}],"con":true,"img":false}]}
{"op":"mcm","clk":"5348004185","pt":1646212245707,"mc":[{"id":"1.195453653","rc":[{"atb":[[2.34,9.44]],"id":35772529}],"con":true,"img":false}]}
{"op":"mcm","clk":"5348004204","pt":1646212246121,"mc":[{"id":"1.195453653","rc":[{"atb":[[1.66,44.2]],"id":37326143}],"con":true,"img":false}]}
{"op":"mcm","clk":"5348004294","pt":1646212248134,"mc":[{"id":"1.195453653","rc":[{"atl":[[2.42,8.17]],"id":35772529}],"con":true,"img":false}]}
{"op":"mcm","clk":"5348004300","pt":1646212248237,"mc":[{"id":"1.195453653","rc":[{"atl":[[2.38,10.83]],"id":35772529}],"con":true,"img":false}]}
{"op":"mcm","clk":"5348004311","pt":1646212248445,"mc":[{"id":"1.195453653","rc":[{"atb":[[1.67,11.54]],"id":37326143}],"con":true,"img":false}]}
{"op":"mcm","clk":"5348004321","pt":1646212248651,"mc":[{"id":"1.195453653","rc":[{"atb":[[1.62,47.05]],"id":37326143}],"con":true,"img":false}]}
{"op":"mcm","clk":"5348004363","pt":1646212249736,"mc":[{"id":"1.195453653","rc":[{"atl":[[1000,1.69]],"id":35772529}],"con":true,"img":false}]}
{"op":"mcm","clk":"5348004368","pt":1646212249842,"mc":[{"id":"1.195453653","rc":[{"atl":[[1000,0.02]],"id":35772529},{"atl":[[1000,1.76]],"id":37326143}],"con":true,"img":false}]}
{"op":"mcm","clk":"5348004375","pt":1646212249945,"mc":[{"id":"1.195453653","rc":[{"atl":[[1000,0]],"id":35772529},{"atl":[[1000,0.1]],"id":37326143}],"con":true,"img":false}]}
{"op":"mcm","clk":"5348004382","pt":1646212250049,"mc":[{"id":"1.195453653","rc":[{"atl":[[2.44,0.02]],"id":35772529}],"con":true,"img":false}]}
{"op":"mcm","clk":"5348004389","pt":1646212250152,"mc":[{"id":"1.195453653","rc":[{"atl":[[1000,0]],"id":37326143}],"con":true,"img":false}]}
{"op":"mcm","clk":"5348004393","pt":1646212250259,"mc":[{"id":"1.195453653","rc":[{"atl":[[1.77,0.1]],"id":37326143}],"con":true,"img":false}]}
{"op":"mcm","clk":"5348004398","pt":1646212250360,"mc":[{"id":"1.195453653","rc":[{"atl":[[2.38,1.43],[2.52,1.42]],"id":35772529},{"trd":[[2.38,18.81]],"ltp":2.38,"tv":18.81,"id":35772529},{"atb":[[1.67,0]],"id":37326143}],"con":true,"img":false}]}
{"op":"mcm","clk":"5348004410","pt":1646212250568,"mc":[{"id":"1.195453653","rc":[{"atb":[[1.67,11.77]],"id":37326143}],"con":true,"img":false}]}
{"op":"mcm","clk":"5348004414","pt":1646212250622,"mc":[{"id":"1.195453653","rc":[{"atb":[[1.66,0]],"id":37326143}],"con":true,"img":false}]}
{"op":"mcm","clk":"5348004420","pt":1646212250725,"mc":[{"id":"1.195453653","rc":[{"atl":[[2.38,0]],"id":35772529},{"trd":[[2.38,21.67]],"ltp":2.38,"tv":21.67,"id":35772529},{"atl":[[1.77,11.81]],"id":37326143}],"con":true,"img":false}]}
{"op":"mcm","clk":"5348004425","pt":1646212250830,"mc":[{"id":"1.195453653","rc":[{"atb":[[1.67,0],[1.65,0]],"id":37326143},{"atl":[[1.76,2],[1.8,11.63]],"id":37326143}],"con":true,"img":false}]}
{"op":"mcm","clk":"5348004438","pt":1646212251140,"mc":[{"id":"1.195453653","rc":[{"atb":[[1.64,11.91]],"id":37326143}],"con":true,"img":false}]}
{"op":"mcm","clk":"5348004443","pt":1646212251244,"mc":[{"id":"1.195453653","rc":[{"atl":[[2.56,0],[2.54,0],[2.52,0],[2.64,0],[2.66,0],[2.62,7.2],[2.68,0]],"id":35772529}],"con":true,"img":false}]}
{"op":"mcm","clk":"5348004453","pt":1646212251551,"mc":[{"id":"1.195453653","rc":[{"atl":[[1.76,13.84]],"id":37326143}],"con":true,"img":false}]}
{"op":"mcm","clk":"5348004455","pt":1646212251659,"mc":[{"id":"1.195453653","rc":[{"atb":[[2.26,23.15]],"id":35772529},{"atl":[[1.82,0]],"id":37326143}],"con":true,"img":false}]}
{"op":"mcm","clk":"5348004521","pt":1646212252946,"mc":[{"id":"1.195453653","rc":[{"atb":[[2,0],[1.8,0],[1.9,0]],"id":35772529},{"atb":[[1.32,0],[1.42,0],[1.52,0]],"id":37326143}],"con":true,"img":false}]}
{"op":"mcm","clk":"5348004580","pt":1646212254237,"mc":[{"id":"1.195453653","rc":[{"atb":[[1.64,0]],"id":37326143}],"con":true,"img":false}]}
{"op":"mcm","clk":"5348004596","pt":1646212254648,"mc":[{"id":"1.195453653","rc":[{"atb":[[2.22,0],[2.26,0]],"id":35772529},{"atb":[[1.63,0],[1.62,0]],"id":37326143}],"con":true,"img":false}]}
{"op":"mcm","clk":"5348004605","pt":1646212254854,"mc":[{"id":"1.195453653","rc":[{"atb":[[2.36,2],[2.34,7.44]],"id":35772529}],"con":true,"img":false}]}
{"op":"mcm","clk":"5348004626","pt":1646212255269,"mc":[{"id":"1.195453653","rc":[{"atl":[[2.62,0]],"id":35772529}],"con":true,"img":false}]}
{"op":"mcm","clk":"5348004655","pt":1646212255886,"mc":[{"id":"1.195453653","rc":[{"atl":[[2.82,9.15]],"id":35772529},{"atb":[[1.43,5.63],[1.5,14.11]],"id":37326143}],"con":true,"img":false}]}
{"op":"mcm","clk":"5348004685","pt":1646212256251,"mc":[{"id":"1.195453653","rc":[{"atl":[[140,0.33]],"id":35772529}],"con":true,"img":false}]}
{"op":"mcm","clk":"5348004760","pt":1646212257547,"mc":[{"id":"1.195453653","rc":[{"atl":[[150,0.43]],"id":35772529}],"con":true,"img":false}]}
{"op":"mcm","clk":"5348004839","pt":1646212258948,"mc":[{"id":"1.195453653","rc":[{"atl":[[160,0.43]],"id":35772529}],"con":true,"img":false}]}
{"op":"mcm","clk":"5348004865","pt":1646212259362,"mc":[{"id":"1.195453653","rc":[{"atb":[[2.36,0],[2.34,4]],"id":35772529},{"trd":[[2.34,6.89],[2.36,4]],"ltp":2.34,"tv":10.89,"id":35772529}],"con":true,"img":false}]}
{"op":"mcm","clk":"5348004893","pt":1646212260187,"mc":[{"id":"1.195453653","rc":[{"atl":[[170,0.4]],"id":35772529}],"con":true,"img":false}]}
{"op":"mcm","clk":"5348004970","pt":1646212261482,"mc":[{"id":"1.195453653","rc":[{"atl":[[140,0],[150,0],[160,0],[170,0]],"id":35772529}],"con":true,"img":false}]}
{"op":"mcm","clk":"5348005018","pt":1646212262364,"mc":[{"id":"1.195453653","rc":[{"atl":[[2.82,7.15]],"id":35772529},{"atb":[[1.5,12.11],[1.48,2]],"id":37326143}],"con":true,"img":false}]}
{"op":"mcm","clk":"5348005023","pt":1646212262466,"mc":[{"id":"1.195453653","rc":[{"atl":[[2.92,2]],"id":35772529}],"con":true,"img":false}]}
{"op":"mcm","clk":"5348005059","pt":1646212263084,"mc":[{"id":"1.195453653","rc":[{"atl":[[1.74,4.15]],"id":37326143}],"con":true,"img":false}]}
{"op":"mcm","clk":"5348005070","pt":1646212263299,"mc":[{"id":"1.195453653","rc":[{"atl":[[1.73,2],[1.76,11.84]],"id":37326143}],"con":true,"img":false}]}
{"op":"mcm","clk":"5348005213","pt":1646212265983,"mc":[{"id":"1.195453653","rc":[{"atb":[[1.98,5.5],[1.88,6.13],[1.78,6.91]],"id":35772529},{"atb":[[1.44,12.26],[1.54,9.98],[1.34,15.87]],"id":37326143}],"con":true,"img":false}]}
{"op":"mcm","clk":"5348005222","pt":1646212266193,"mc":[{"id":"1.195453653","rc":[{"atb":[[2.28,22.79]],"id":35772529}],"con":true,"img":false}]}
{"op":"mcm","clk":"5348005253","pt":1646212266661,"mc":[{"id":"1.195453653","rc":[{"atl":[[1.73,13.84],[1.81,0]],"id":37326143}],"con":true,"img":false}]}
{"op":"mcm","clk":"5348005290","pt":1646212267182,"mc":[{"id":"1.195453653","rc":[{"atb":[[1.49,59.54]],"id":37326143}],"con":true,"img":false}]}
{"op":"mcm","clk":"5348005324","pt":1646212268006,"mc":[{"id":"1.195453653","rc":[{"atb":[[1.55,12.01]],"id":37326143}],"con":true,"img":false}]}
{"op":"mcm","clk":"5348005364","pt":1646212268681,"mc":[{"id":"1.195453653","rc":[{"atb":[[1.49,0],[1.51,57.21]],"id":37326143}],"con":true,"img":false}]}
{"op":"mcm","clk":"5348005410","pt":1646212269664,"mc":[{"id":"1.195453653","rc":[{"atb":[[1.04,2.86]],"id":35772529}],"con":true,"img":false}]}
{"op":"mcm","clk":"5348005419","pt":1646212269872,"mc":[{"id":"1.195453653","rc":[{"atb":[[1.04,0.14]],"id":35772529}],"con":true,"img":false}]}
{"op":"mcm","clk":"5348005430","pt":1646212270078,"mc":[{"id":"1.195453653","rc":[{"atb":[[1.04,0]],"id":35772529}],"con":true,"img":false}]}
{"op":"mcm","clk":"5348005435","pt":1646212270184,"mc":[{"id":"1.195453653","rc":[{"atl":[[2.42,8.03]],"id":35772529},{"trd":[[2.42,0.4]],"ltp":2.42,"tv":0.4,"id":35772529}],"con":true,"img":false}]}
{"op":"mcm","clk":"5348005440","pt":1646212270287,"mc":[{"id":"1.195453653","rc":[{"atl":[[2.42,2.88]],"id":35772529},{"trd":[[2.42,10.7]],"ltp":2.42,"tv":10.7,"id":35772529}],"con":true,"img":false}]}
{"op":"mcm","clk":"5348005451","pt":1646212270493,"mc":[{"id":"1.195453653","rc":[{"atb":[[2.38,2]],"id":35772529},{"atl":[[2.42,0]],"id":35772529},{"trd":[[2.42,13.58]],"ltp":2.42,"tv":13.58,"id":35772529},{"trd":[[1.7,4.09]],"ltp":1.7,"tv":4.09,"id":37326143}],"con":true,"img":false}]}
{"op":"mcm","clk":"5348005460","pt":1646212270702,"mc":[{"id":"1.195453653","rc":[{"atl":[[2.42,0],[2.44,0]],"id":35772529},{"trd":[[2.44,0.05],[2.42,13.59]],"ltp":2.44,"tv":13.64,"id":35772529}],"con":true,"img":false}]}
{"op":"mcm","clk":"5348005484","pt":1646212271164,"mc":[{"id":"1.195453653","rc":[{"atb":[[1.51,0]],"id":37326143}],"con":true,"img":false}]}
{"op":"mcm","clk":"5348005501","pt":1646212271681,"mc":[{"id":"1.195453653","rc":[{"atb":[[2.32,22.1]],"id":35772529},{"atb":[[1.04,2.86]],"id":37326143}],"con":true,"img":false}]}
{"op":"mcm","clk":"5348005512","pt":1646212271889,"mc":[{"id":"1.195453653","rc":[{"atb":[[1.04,0.14]],"id":37326143}],"con":true,"img":false}]}
{"op":"mcm","clk":"5348005523","pt":1646212272095,"mc":[{"id":"1.195453653","rc":[{"atb":[[2.38,0]],"id":35772529},{"atl":[[2.36,7.85]],"id":35772529},{"trd":[[2.36,14.15],[2.38,25.67]],"ltp":2.36,"tv":39.82,"id":35772529},{"atb":[[1.04,0]],"id":37326143},{"atl":[[1.73,0]],"id":37326143},{"trd":[[1.73,13.84]],"ltp":1.73,"tv":13.84,"id":37326143}],"con":true,"img":false}]}
{"op":"mcm","clk":"5348005529","pt":1646212272197,"mc":[{"id":"1.195453653","rc":[{"atl":[[2.36,0]],"id":35772529},{"trd":[[2.36,29.85]],"ltp":2.36,"tv":29.85,"id":35772529},{"atb":[[1.73,0.14]],"id":37326143}],"con":true,"img":false}]}
{"op":"mcm","clk":"5348005533","pt":1646212272299,"mc":[{"id":"1.195453653","rc":[{"atb":[[1.73,0]],"id":37326143},{"trd":[[1.73,14.12]],"ltp":1.73,"tv":14.12,"id":37326143}],"con":true,"img":false}]}
{"op":"mcm","clk":"5348005546","pt":1646212272661,"mc":[{"id":"1.195453653","rc":[{"atb":[[2.32,0]],"id":35772529}],"con":true,"img":false}]}
{"op":"mcm","clk":"5348005549","pt":1646212272823,"mc":[{"id":"1.195453653","rc":[{"atl":[[2.8,3.39]],"id":35772529}],"con":true,"img":false}]}
{"op":"mcm","clk":"5348005610","pt":1646212273902,"mc":[{"id":"1.195453653","rc":[{"atl":[[2.78,7.1]],"id":35772529}],"con":true,"img":false}]}
{"op":"mcm","clk":"5348005628","pt":1646212274212,"mc":[{"id":"1.195453653","rc":[{"atb":[[1.55,65.06]],"id":37326143}],"con":true,"img":false}]}
{"op":"mcm","clk":"5348005640","pt":1646212274369,"mc":[{"id":"1.195453653","rc":[{"atb":[[1.56,24.41]],"id":37326143}],"con":true,"img":false}]}
{"op":"mcm","clk":"5348005703","pt":1646212275811,"mc":[{"id":"1.195453653","rc":[{"atl":[[2.8,0]],"id":35772529}],"con":true,"img":false}]}
{"op":"mcm","clk":"5348005708","pt":1646212275954,"mc":[{"id":"1.195453653","rc":[{"atl":[[2.76,3.43]],"id":35772529}],"con":true,"img":false}]}
{"op":"mcm","clk":"5348005747","pt":1646212276694,"mc":[{"id":"1.195453653","rc":[{"atl":[[2.74,14.09]],"id":35772529}],"con":true,"img":false}]}
{"op":"mcm","clk":"5348005782","pt":1646212277211,"mc":[{"id":"1.195453653","rc":[{"atb":[[1.57,51.18]],"id":37326143}],"con":true,"img":false}]}
{"op":"mcm","clk":"5348005802","pt":1646212277518,"mc":[{"id":"1.195453653","rc":[{"atb":[[1.58,24.7]],"id":37326143}],"con":true,"img":false}]}
{"op":"mcm","clk":"5348005852","pt":1646212278302,"mc":[{"id":"1.195453653","rc":[{"atb":[[1.43,0]],"id":37326143}],"con":true,"img":false}]}
{"op":"mcm","clk":"5348005858","pt":1646212278403,"mc":[{"id":"1.195453653","rc":[{"atb":[[1.4,5.63]],"id":37326143}],"con":true,"img":false}]}
{"op":"mcm","clk":"5348005877","pt":1646212278823,"mc":[{"id":"1.195453653","rc":[{"atl":[[2.72,3.49],[2.76,0]],"id":35772529}],"con":true,"img":false}]}
{"op":"mcm","clk":"5348005930","pt":1646212279695,"mc":[{"id":"1.195453653","rc":[{"atl":[[2.7,7.01]],"id":35772529}],"con":true,"img":false}]}
{"op":"mcm","clk":"5348006005","pt":1646212280984,"mc":[{"id":"1.195453653","rc":[{"atl":[[2.7,10.52]],"id":35772529}],"con":true,"img":false}]}
{"op":"mcm","clk":"5348006011","pt":1646212281090,"mc":[{"id":"1.195453653","rc":[{"atl":[[2.72,0]],"id":35772529}],"con":true,"img":false}]}
{"op":"mcm","clk":"5348006016","pt":1646212281193,"mc":[{"id":"1.195453653","rc":[{"atl":[[2.68,14.1]],"id":35772529}],"con":true,"img":false}]}
{"op":"mcm","clk":"5348006028","pt":1646212281396,"mc":[{"id":"1.195453653","rc":[{"atl":[[2.82,0]],"id":35772529}],"con":true,"img":false}]}
{"op":"mcm","clk":"5348006048","pt":1646212281808,"mc":[{"id":"1.195453653","rc":[{"atl":[[2.68,17.64],[2.7,7.01]],"id":35772529}],"con":true,"img":false}]}
{"op":"mcm","clk":"5348006065","pt":1646212282120,"mc":[{"id":"1.195453653","rc":[{"atl":[[2.66,7.06]],"id":35772529}],"con":true,"img":false}]}
{"op":"mcm","clk":"5348006070","pt":1646212282222,"mc":[{"id":"1.195453653","rc":[{"atb":[[1.59,49.44]],"id":37326143}],"con":true,"img":false}]}
{"op":"mcm","clk":"5348006106","pt":1646212282791,"mc":[{"id":"1.195453653","rc":[{"atb":[[1.6,12.28]],"id":37326143}],"con":true,"img":false}]}
{"op":"mcm","clk":"5348006117","pt":1646212282997,"mc":[{"id":"1.195453653","rc":[{"atb":[[1.5,0]],"id":37326143}],"con":true,"img":false}]}
{"op":"mcm","clk":"5348006151","pt":1646212283922,"mc":[{"id":"1.195453653","rc":[{"atl":[[2.68,14.1]],"id":35772529}],"con":true,"img":false}]}
{"op":"mcm","clk":"5348006330","pt":1646212287230,"mc":[{"id":"1.195453653","rc":[{"atb":[[2.4,2]],"id":35772529},{"atl":[[1.73,2]],"id":37326143}],"con":true,"img":false}]}
{"op":"mcm","clk":"5348006561","pt":1646212291940,"mc":[{"id":"1.195453653","rc":[{"atb":[[1.6,11.45]],"id":37326143},{"trd":[[1.6,1.66]],"ltp":1.6,"tv":1.66,"id":37326143}],"con":true,"img":false}]}
{"op":"mcm","clk":"5348006587","pt":1646212292429,"mc":[{"id":"1.195453653","rc":[{"atb":[[2.4,0],[2.42,2]],"id":35772529}],"con":true,"img":false}]}
{"op":"mcm","clk":"5348006628","pt":1646212293202,"mc":[{"id":"1.195453653","rc":[{"atl":[[1.74,0]],"id":37326143}],"con":true,"img":false}]}
{"op":"mcm","clk":"5348006640","pt":1646212293309,"mc":[{"id":"1.195453653","rc":[{"atl":[[1.73,0],[1.75,2]],"id":37326143}],"con":true,"img":false}]}
{"op":"mcm","clk":"5348006745","pt":1646212295227,"mc":[{"id":"1.195453653","marketDefinition":{"bspMarket":false,"turnInPlayEnabled":false,"persistenceEnabled":false,"marketBaseRate":7.0,"eventId":"31272494","eventTypeId":"4339","numberOfWinners":1,"bettingType":"ODDS","marketType":"MATCH_BET","marketTime":"2022-03-02T09:11:00.000Z","suspendTime":"2022-03-02T09:11:00.000Z","bspReconciled":false,"complete":true,"inPlay":false,"crossMatching":true,"runnersVoidable":false,"numberOfActiveRunners":2,"betDelay":0,"status":"SUSPENDED","runners":[{"status":"ACTIVE","sortPriority":1,"id":37326143,"name":"2. Lee Will"},{"status":"ACTIVE","sortPriority":2,"id":35772529,"name":"4. Bombers Smokey"}],"regulators":["MR_INT"],"venue":"Traralgon","countryCode":"AU","discountAllowed":true,"timezone":"Australia/Sydney","openDate":"2022-03-02T08:31:00.000Z","version":4382874247,"name":"Lee Will v Bombers Smokey","eventName":"Traralgon (AUS) 2nd Mar"},"rc":[],"con":true,"img":false}]}
{"op":"mcm","clk":"5348006745","pt":1646212295227,"mc":[{"id":"1.195453653","rc":[{"atb":[[1.98,0],[2.42,0],[1.88,0],[2.28,0],[1.78,0],[2.34,0]],"id":35772529},{"atl":[[2.92,0],[2.74,0],[2.66,0],[2.78,0],[2.68,0],[2.7,0]],"id":35772529},{"atb":[[1.56,0],[1.4,0],[1.59,0],[1.6,0],[1.44,0],[1.58,0],[1.57,0],[1.55,0],[1.54,0],[1.48,0],[1.34,0]],"id":37326143},{"atl":[[2.24,0],[1.8,0],[2.3,0],[2.22,0],[2.28,0],[2.18,0],[1.77,0],[2.2,0],[2.26,0],[1.75,0],[2.16,0],[1.76,0]],"id":37326143}],"con":true,"img":false}]}
{"op":"mcm","clk":"5348016442","pt":1646212490831,"mc":[{"id":"1.195453653","rc":[{"trd":[[2.36,0],[2.56,0],[2.42,0],[2.38,0],[2.52,0],[2.44,0],[2.34,0]],"ltp":2.36,"tv":0.0,"id":35772529},{"trd":[[1.73,0],[1.6,0],[1.7,0]],"ltp":1.73,"tv":0.0,"id":37326143}],"con":true,"img":false}]}
{"op":"mcm","clk":"5348016483","pt":1646212491755,"mc":[{"id":"1.195453653","marketDefinition":{"bspMarket":false,"turnInPlayEnabled":false,"persistenceEnabled":false,"marketBaseRate":7.0,"eventId":"31272494","eventTypeId":"4339","numberOfWinners":1,"bettingType":"ODDS","marketType":"MATCH_BET","marketTime":"2022-03-02T09:11:00.000Z","suspendTime":"2022-03-02T09:11:00.000Z","bspReconciled":false,"complete":true,"inPlay":false,"crossMatching":false,"runnersVoidable":false,"numberOfActiveRunners":0,"betDelay":0,"status":"CLOSED","settledTime":"2022-03-02T09:14:48.000Z","runners":[{"status":"WINNER","sortPriority":1,"id":37326143,"name":"2. Lee Will"},{"status":"LOSER","sortPriority":2,"id":35772529,"name":"4. Bombers Smokey"}],"regulators":["MR_INT"],"venue":"Traralgon","countryCode":"AU","discountAllowed":true,"timezone":"Australia/Sydney","openDate":"2022-03-02T08:31:00.000Z","version":4382874596,"name":"Lee Will v Bombers Smokey","eventName":"Traralgon (AUS) 2nd Mar"},"rc":[],"con":true,"img":false}]}
