{"op":"mcm","clk":"5317728457","pt":1646251399797,"mc":[{"id":"1.195532856","marketDefinition":{"bspMarket":true,"turnInPlayEnabled":false,"persistenceEnabled":false,"marketBaseRate":5.0,"eventId":"31275720","eventTypeId":"4339","numberOfWinners":1,"bettingType":"ODDS","marketType":"WIN","marketTime":"2022-03-03T14:32:00.000Z","suspendTime":"2022-03-03T14:32:00.000Z","bspReconciled":false,"complete":true,"inPlay":false,"crossMatching":false,"runnersVoidable":false,"numberOfActiveRunners":6,"betDelay":0,"status":"OPEN","runners":[{"status":"ACTIVE","sortPriority":1,"id":43189000,"name":"1. Kenzo"},{"status":"ACTIVE","sortPriority":2,"id":42931075,"name":"2. Ayle Of Freedom"},{"status":"ACTIVE","sortPriority":3,"id":43189001,"name":"3. Puttfor Keely"},{"status":"ACTIVE","sortPriority":4,"id":41555102,"name":"4. Boars Hill Tiger"},{"status":"ACTIVE","sortPriority":5,"id":39330606,"name":"5. Mandeville Dizzy"},{"status":"ACTIVE","sortPriority":6,"id":42609837,"name":"6. Kingdom Diamond"}],"regulators":["MR_INT"],"venue":"Romford","countryCode":"GB","discountAllowed":false,"timezone":"Europe/London","openDate":"2022-03-03T13:57:00.000Z","version":4384107296,"name":"A9 400m","eventName":"Romford 3rd Mar"},"rc":[],"con":true,"img":false}]}
{"op":"mcm","clk":"5317728853","pt":1646251401761,"mc":[{"id":"1.195532856","marketDefinition":{"bspMarket":true,"turnInPlayEnabled":false,"persistenceEnabled":false,"marketBaseRate":5.0,"eventId":"31275720","eventTypeId":"4339","numberOfWinners":1,"bettingType":"ODDS","marketType":"WIN","marketTime":"2022-03-03T14:32:00.000Z","suspendTime":"2022-03-03T14:32:00.000Z","bspReconciled":false,"complete":true,"inPlay":false,"crossMatching":false,"runnersVoidable":false,"numberOfActiveRunners":6,"betDelay":0,"status":"OPEN","runners":[{"status":"ACTIVE","sortPriority":1,"id":43189000,"name":"1. Kenzo"},{"status":"ACTIVE","sortPriority":2,"id":42931075,"name":"2. Ayle Of Freedom"},{"status":"ACTIVE","sortPriority":3,"id":43189001,"name":"3. Puttfor Keely"},{"status":"ACTIVE","sortPriority":4,"id":41555102,"name":"4. Boars Hill Tiger"},{"status":"ACTIVE","sortPriority":5,"id":39330606,"name":"5. Mandeville Dizzy"},{"status":"ACTIVE","sortPriority":6,"id":42609837,"name":"6. Kingdom Diamond"}],"regulators":["MR_INT"],"venue":"Romford","countryCode":"GB","discountAllowed":true,"timezone":"Europe/London","openDate":"2022-03-03T13:57:00.000Z","version":4384107296,"name":"A9 400m","eventName":"Romford 3rd Mar"},"rc":[],"con":true,"img":false}]}
{"op":"mcm","clk":"5318486058","pt":1646259097170,"mc":[{"id":"1.195532856","rc":[{"atb":[[1.12,30]],"id":43189000},{"atl":[[370,3]],"id":43189000},{"spn":185.56,"spf":"NaN","id":43189000},{"atl":[[550,3]],"id":43189001},{"spn":1.0,"spf":"NaN","id":43189001},{"atl":[[270,3]],"id":41555102},{"spn":1.0,"spf":"NaN","id":41555102},{"atb":[[1.12,30]],"id":42931075},{"atl":[[390,3]],"id":42931075},{"spn":195.56,"spf":"NaN","id":42931075},{"atl":[[560,3]],"id":39330606},{"spn":1.0,"spf":"NaN","id":39330606},{"atl":[[500,3]],"id":42609837},{"spn":1.0,"spf":"NaN","id":42609837}],"con":true,"img":false}]}
{"op":"mcm","clk":"5318486101","pt":1646259097738,"mc":[{"id":"1.195532856","rc":[{"atb":[[1.12,30]],"id":43189001},{"atb":[[1.12,30]],"id":41555102},{"atb":[[1.12,30]],"id":39330606},{"atb":[[1.14,30]],"id":42609837}],"con":true,"img":false}]}
{"op":"mcm","clk":"5318509042","pt":1646259402464,"mc":[{"id":"1.195532856","marketDefinition":{"bspMarket":true,"turnInPlayEnabled":false,"persistenceEnabled":false,"marketBaseRate":5.0,"eventId":"31275720","eventTypeId":"4339","numberOfWinners":1,"bettingType":"ODDS","marketType":"WIN","marketTime":"2022-03-03T14:32:00.000Z","suspendTime":"2022-03-03T14:32:00.000Z","bspReconciled":false,"complete":true,"inPlay":false,"crossMatching":false,"runnersVoidable":false,"numberOfActiveRunners":6,"betDelay":0,"status":"OPEN","runners":[{"status":"ACTIVE","sortPriority":1,"id":43189000,"name":"1. Kenzo"},{"status":"ACTIVE","sortPriority":2,"id":42931075,"name":"2. Ayle Of Freedom"},{"status":"ACTIVE","sortPriority":3,"id":43189001,"name":"3. Puttfor Keely"},{"status":"ACTIVE","sortPriority":4,"id":41555102,"name":"4. Boars Hill Tiger"},{"status":"ACTIVE","sortPriority":5,"id":39330606,"name":"5. Mandeville Dizzy"},{"status":"ACTIVE","sortPriority":6,"id":42609837,"name":"6. Kingdom Diamond"}],"regulators":["MR_INT"],"venue":"Romford","countryCode":"GB","discountAllowed":true,"timezone":"Europe/London","openDate":"2022-03-03T13:57:00.000Z","version":4384107296,"name":"A9 400m","eventName":"Romford 3rd Mar"},"rc":[{"atb":[[1.12,30]],"id":43189000},{"atl":[[370,3]],"id":43189000},{"spn":185.56,"spf":"NaN","id":43189000},{"atb":[[1.12,30]],"id":43189001},{"atl":[[550,3]],"id":43189001},{"spn":275.56,"spf":"NaN","id":43189001},{"atb":[[1.12,30]],"id":41555102},{"atl":[[270,3]],"id":41555102},{"spn":135.56,"spf":"NaN","id":41555102},{"atb":[[1.12,30]],"id":42931075},{"atl":[[390,3]],"id":42931075},{"spn":195.56,"spf":"NaN","id":42931075},{"atb":[[1.12,30]],"id":39330606},{"atl":[[560,3]],"id":39330606},{"spn":280.56,"spf":"NaN","id":39330606},{"atb":[[1.14,30]],"id":42609837},{"atl":[[500,3]],"id":42609837},{"spn":250.57,"spf":"NaN","id":42609837}],"con":true,"img":true}]}
{"op":"mcm","clk":"5320139804","pt":1646287409058,"mc":[{"id":"1.195532856","rc":[{"atb":[[2.02,8.44]],"id":43189000},{"spn":186.01,"spf":"NaN","id":43189000},{"atb":[[2.02,10.13]],"id":43189001},{"spn":276.01,"spf":"NaN","id":43189001},{"atb":[[2,12.54]],"id":41555102},{"spn":136.0,"spf":"NaN","id":41555102},{"atb":[[2.08,10.43]],"id":42931075},{"spn":196.04,"spf":"NaN","id":42931075},{"atb":[[2.06,11.19]],"id":39330606},{"spn":281.03,"spf":"NaN","id":39330606},{"atb":[[2.04,10.23]],"id":42609837},{"spn":251.02,"spf":"NaN","id":42609837}],"con":true,"img":false}]}
{"op":"mcm","clk":"5320456681","pt":1646295894304,"mc":[{"id":"1.195532856","rc":[{"atb":[[2.02,8.45]],"id":43189000},{"atb":[[2.02,10.14]],"id":43189001},{"spl":[[10,10]],"id":43189001},{"spn":6.01,"spf":1.0,"id":43189001},{"atb":[[2,12.55]],"id":41555102},{"spl":[[10,10]],"id":41555102},{"spn":6.0,"spf":1.0,"id":41555102},{"atb":[[2.08,10.43]],"id":42931075},{"spl":[[36,10]],"id":42931075},{"spn":19.04,"spf":1.0,"id":42931075},{"atb":[[2.06,11.2]],"id":39330606},{"spl":[[5.2,10]],"id":39330606},{"spn":3.63,"spf":1.0,"id":39330606},{"atb":[[2.04,10.24]],"id":42609837},{"spl":[[6.4,10]],"id":42609837},{"spn":4.22,"spf":1.0,"id":42609837}],"con":true,"img":false}]}
{"op":"mcm","clk":"5320554976","pt":1646297426995,"mc":[{"id":"1.195532856","rc":[{"spl":[[21,1]],"id":43189000},{"spn":11.51,"spf":1.0,"id":43189000},{"spl":[[21,1]],"id":43189001},{"spl":[[21,1]],"id":41555102},{"spl":[[21,1]],"id":42931075},{"spn":11.54,"spf":1.0,"id":42931075},{"spl":[[21,1]],"id":39330606},{"spl":[[21,1]],"id":42609837}],"con":true,"img":false}]}
{"op":"mcm","clk":"5320612114","pt":1646298547028,"mc":[{"id":"1.195532856","rc":[{"atl":[[44,1]],"id":43189000},{"atl":[[44,1]],"id":43189001},{"atl":[[44,1]],"id":41555102},{"atl":[[44,1]],"id":42609837}],"con":true,"img":false}]}
{"op":"mcm","clk":"5320613172","pt":1646298567780,"mc":[{"id":"1.195532856","rc":[{"atl":[[44,1.1]],"id":43189000},{"atl":[[44,1.1]],"id":43189001},{"atl":[[44,1.1]],"id":41555102},{"atl":[[44,1.1]],"id":42609837}],"con":true,"img":false}]}
{"op":"mcm","clk":"5320614236","pt":1646298587437,"mc":[{"id":"1.195532856","rc":[{"atl":[[44,0.1]],"id":43189000},{"atl":[[44,0.1]],"id":43189001},{"atl":[[44,0.1]],"id":41555102},{"atl":[[44,0.1]],"id":42609837}],"con":true,"img":false}]}
{"op":"mcm","clk":"5320830271","pt":1646302602586,"mc":[{"id":"1.195532856","marketDefinition":{"bspMarket":true,"turnInPlayEnabled":false,"persistenceEnabled":false,"marketBaseRate":5.0,"eventId":"31275720","eventTypeId":"4339","numberOfWinners":1,"bettingType":"ODDS","marketType":"WIN","marketTime":"2022-03-03T14:32:00.000Z","suspendTime":"2022-03-03T14:32:00.000Z","bspReconciled":false,"complete":true,"inPlay":false,"crossMatching":false,"runnersVoidable":false,"numberOfActiveRunners":6,"betDelay":0,"status":"OPEN","runners":[{"status":"ACTIVE","sortPriority":1,"id":43189000,"name":"1. Kenzo"},{"status":"ACTIVE","sortPriority":2,"id":42931075,"name":"2. Ayle Of Freedom"},{"status":"ACTIVE","sortPriority":3,"id":43189001,"name":"3. Puttfor Keely"},{"status":"ACTIVE","sortPriority":4,"id":41555102,"name":"4. Boars Hill Tiger"},{"status":"ACTIVE","sortPriority":5,"id":39330606,"name":"5. Mandeville Dizzy"},{"status":"ACTIVE","sortPriority":6,"id":42609837,"name":"6. Kingdom Diamond"}],"regulators":["MR_INT"],"venue":"Romford","countryCode":"GB","discountAllowed":true,"timezone":"Europe/London","openDate":"2022-03-03T13:57:00.000Z","version":4384107296,"name":"A9 400m","eventName":"Romford 3rd Mar"},"rc":[{"atb":[[1.12,30],[2.02,8.44]],"id":43189000},{"spl":[[21,1]],"id":43189000},{"atl":[[44,0.1],[370,3]],"id":43189000},{"spn":11.51,"spf":1.0,"id":43189000},{"atb":[[1.12,30],[2.02,10.13]],"id":43189001},{"spl":[[10,10],[21,1]],"id":43189001},{"atl":[[550,3],[44,0.1]],"id":43189001},{"spn":6.01,"spf":1.0,"id":43189001},{"atb":[[2,12.54],[1.12,30]],"id":41555102},{"spl":[[10,10],[21,1]],"id":41555102},{"atl":[[270,3],[44,0.1]],"id":41555102},{"spn":6.0,"spf":1.0,"id":41555102},{"atb":[[1.12,30],[2.08,10.43]],"id":42931075},{"spl":[[36,10],[21,1]],"id":42931075},{"atl":[[390,3]],"id":42931075},{"spn":11.54,"spf":1.0,"id":42931075},{"atb":[[1.12,30],[2.06,11.19]],"id":39330606},{"spl":[[21,1],[5.2,10]],"id":39330606},{"atl":[[560,3]],"id":39330606},{"spn":3.63,"spf":1.0,"id":39330606},{"atb":[[2.04,10.23],[1.14,30]],"id":42609837},{"spl":[[6.4,10],[21,1]],"id":42609837},{"atl":[[44,0.1],[500,3]],"id":42609837},{"spn":4.22,"spf":1.0,"id":42609837}],"con":true,"img":true}]}
{"op":"mcm","clk":"5320956339","pt":1646304333789,"mc":[{"id":"1.195532856","rc":[{"atb":[[2.02,8.44]],"id":43189000},{"atl":[[1000,2.5]],"id":43189000},{"atb":[[2.02,10.13]],"id":43189001},{"atl":[[1000,2.5]],"id":43189001},{"atb":[[2,12.54]],"id":41555102},{"atl":[[1000,2.5]],"id":41555102},{"atb":[[2.08,10.43]],"id":42931075},{"atl":[[1000,2.5]],"id":42931075},{"atb":[[2.06,11.19]],"id":39330606},{"atl":[[1000,2.5]],"id":39330606},{"atb":[[2.04,10.23]],"id":42609837},{"atl":[[1000,2.5]],"id":42609837}],"con":true,"img":false}]}
{"op":"mcm","clk":"5320956349","pt":1646304334006,"mc":[{"id":"1.195532856","rc":[{"atl":[[1000,12.5]],"id":43189000},{"atl":[[1000,12.5]],"id":43189001},{"atl":[[1000,12.5]],"id":41555102},{"atl":[[1000,12.5]],"id":42931075},{"atl":[[1000,12.5]],"id":39330606},{"atl":[[1000,12.5]],"id":42609837}],"con":true,"img":false}]}
{"op":"mcm","clk":"5320956367","pt":1646304334306,"mc":[{"id":"1.195532856","rc":[{"atb":[[1.01,1000]],"id":43189000},{"atb":[[1.01,1000]],"id":43189001},{"atb":[[1.01,1000]],"id":41555102},{"atb":[[1.01,1000]],"id":42931075},{"atb":[[1.01,1000]],"id":39330606},{"atb":[[1.01,1000]],"id":42609837}],"con":true,"img":false}]}
{"op":"mcm","clk":"5320956388","pt":1646304334613,"mc":[{"id":"1.195532856","rc":[{"atb":[[1.01,11000]],"id":43189000},{"atb":[[1.01,11000]],"id":43189001},{"atb":[[1.01,11000]],"id":41555102},{"atb":[[1.01,11000]],"id":42931075},{"atb":[[1.01,11000]],"id":39330606},{"atb":[[1.01,11000]],"id":42609837}],"con":true,"img":false}]}
{"op":"mcm","clk":"5320958064","pt":1646304359377,"mc":[{"id":"1.195532856","marketDefinition":{"bspMarket":true,"turnInPlayEnabled":false,"persistenceEnabled":false,"marketBaseRate":5.0,"eventId":"31275720","eventTypeId":"4339","numberOfWinners":1,"bettingType":"ODDS","marketType":"WIN","marketTime":"2022-03-03T14:32:00.000Z","suspendTime":"2022-03-03T14:32:00.000Z","bspReconciled":false,"complete":true,"inPlay":false,"crossMatching":true,"runnersVoidable":false,"numberOfActiveRunners":6,"betDelay":0,"status":"OPEN","runners":[{"status":"ACTIVE","sortPriority":1,"id":43189000,"name":"1. Kenzo"},{"status":"ACTIVE","sortPriority":2,"id":42931075,"name":"2. Ayle Of Freedom"},{"status":"ACTIVE","sortPriority":3,"id":43189001,"name":"3. Puttfor Keely"},{"status":"ACTIVE","sortPriority":4,"id":41555102,"name":"4. Boars Hill Tiger"},{"status":"ACTIVE","sortPriority":5,"id":39330606,"name":"5. Mandeville Dizzy"},{"status":"ACTIVE","sortPriority":6,"id":42609837,"name":"6. Kingdom Diamond"}],"regulators":["MR_INT"],"venue":"Romford","countryCode":"GB","discountAllowed":true,"timezone":"Europe/London","openDate":"2022-03-03T13:57:00.000Z","version":4384107296,"name":"A9 400m","eventName":"Romford 3rd Mar"},"rc":[],"con":true,"img":false}]}
{"op":"mcm","clk":"5321025560","pt":1646305286949,"mc":[{"id":"1.195532856","rc":[{"atb":[[2.02,8.45],[5.2,2]],"id":43189000},{"spn":13.1,"spf":1.0,"id":43189000},{"atb":[[2.02,10.14],[6.8,2]],"id":43189001},{"spn":8.4,"spf":1.0,"id":43189001},{"atb":[[2,12.55],[3.6,2]],"id":41555102},{"spn":6.8,"spf":1.0,"id":41555102},{"atb":[[9.8,2],[2.08,10.43]],"id":42931075},{"spn":15.4,"spf":1.0,"id":42931075},{"atb":[[2.06,11.2],[6,2]],"id":39330606},{"spn":5.2,"spf":1.0,"id":39330606},{"atb":[[2.04,10.23],[4.2,2]],"id":42609837},{"spn":5.3,"spf":1.0,"id":42609837}],"con":true,"img":false}]}
{"op":"mcm","clk":"5321025822","pt":1646305290869,"mc":[{"id":"1.195532856","rc":[{"atb":[[4.4,2]],"id":43189000},{"atl":[[8.8,1.29]],"id":43189000},{"atb":[[5.6,2]],"id":43189001},{"atl":[[12,0.92]],"id":43189001},{"atb":[[3.25,2]],"id":41555102},{"atl":[[5.4,2]],"id":41555102},{"atb":[[7.6,1.53]],"id":42931075},{"atl":[[22,0.49]],"id":42931075},{"atb":[[5.1,2]],"id":39330606},{"atl":[[10.5,1.06]],"id":39330606},{"atb":[[3.8,2]],"id":42609837},{"atl":[[6.8,1.73]],"id":42609837}],"con":true,"img":false}]}
{"op":"mcm","clk":"5321039313","pt":1646305449085,"mc":[{"id":"1.195532856","marketDefinition":{"bspMarket":true,"turnInPlayEnabled":false,"persistenceEnabled":false,"marketBaseRate":5.0,"eventId":"31275720","eventTypeId":"4339","numberOfWinners":1,"bettingType":"ODDS","marketType":"WIN","marketTime":"2022-03-03T14:32:00.000Z","suspendTime":"2022-03-03T14:32:00.000Z","bspReconciled":false,"complete":true,"inPlay":false,"crossMatching":true,"runnersVoidable":false,"numberOfActiveRunners":6,"betDelay":0,"status":"OPEN","runners":[{"status":"ACTIVE","sortPriority":1,"id":43189000,"name":"1. Kenzo"},{"status":"ACTIVE","sortPriority":2,"id":42931075,"name":"2. Ayle Of Freedom"},{"status":"ACTIVE","sortPriority":3,"id":43189001,"name":"3. Puttfor Keely"},{"status":"ACTIVE","sortPriority":4,"id":41555102,"name":"4. Boars Hill Tiger"},{"status":"ACTIVE","sortPriority":5,"id":39330606,"name":"5. Mandeville Dizzy"},{"status":"ACTIVE","sortPriority":6,"id":42609837,"name":"6. Kingdom Diamond"}],"regulators":["MR_INT"],"venue":"Romford","countryCode":"GB","discountAllowed":true,"timezone":"Europe/London","openDate":"2022-03-03T13:57:00.000Z","version":4384107296,"name":"A9 400m","eventName":"Romford 3rd Mar"},"rc":[{"atb":[[1.12,30],[2.02,8.45],[1.01,11000],[5.2,2],[4.4,2]],"id":43189000},{"spl":[[21,1]],"id":43189000},{"atl":[[44,0.1],[370,3],[8.8,1.29],[1000,12.5]],"id":43189000},{"spn":7.0,"spf":1.0,"id":43189000},{"atb":[[5.6,2],[1.12,30],[2.02,10.14],[1.01,11000],[6.8,2]],"id":43189001},{"spl":[[10,10],[21,1]],"id":43189001},{"atl":[[550,3],[44,0.1],[12,0.92],[1000,12.5]],"id":43189001},{"spn":8.4,"spf":1.0,"id":43189001},{"atb":[[2,12.55],[1.12,30],[3.6,2],[1.01,11000],[3.25,2]],"id":41555102},{"spl":[[10,10],[21,1]],"id":41555102},{"atl":[[270,3],[44,0.1],[5.4,2],[1000,12.5]],"id":41555102},{"spn":4.5,"spf":1.0,"id":41555102},{"atb":[[1.12,30],[1.01,11000],[7.6,1.53],[9.8,2],[2.08,10.43]],"id":42931075},{"spl":[[36,10],[21,1]],"id":42931075},{"atl":[[22,0.49],[390,3],[1000,12.5]],"id":42931075},{"spn":15.4,"spf":1.0,"id":42931075},{"atb":[[1.12,30],[5.1,2],[1.01,11000],[2.06,11.2],[6,2]],"id":39330606},{"spl":[[21,1],[5.2,10]],"id":39330606},{"atl":[[560,3],[10.5,1.06],[1000,12.5]],"id":39330606},{"spn":5.2,"spf":1.0,"id":39330606},{"atb":[[1.01,11000],[2.04,10.23],[3.8,2],[1.14,30],[4.2,2]],"id":42609837},{"spl":[[6.4,10],[21,1]],"id":42609837},{"atl":[[44,0.1],[6.8,1.73],[500,3],[1000,12.5]],"id":42609837},{"spn":5.3,"spf":1.0,"id":42609837}],"con":true,"img":true}]}
{"op":"mcm","clk":"5321104156","pt":1646306208178,"mc":[{"id":"1.195532856","rc":[{"spn":7.0,"spf":1.0,"id":43189000},{"atb":[[5.6,0]],"id":43189001},{"spn":4.5,"spf":1.0,"id":41555102}],"con":true,"img":false}]}
{"op":"mcm","clk":"5321152953","pt":1646306623954,"mc":[{"id":"1.195532856","rc":[{"atb":[[6,1]],"id":39330606},{"trd":[[6,2]],"ltp":6.0,"tv":2.0,"id":39330606}],"con":true,"img":false}]}
{"op":"mcm","clk":"5321153026","pt":1646306624530,"mc":[{"id":"1.195532856","rc":[{"atb":[[6,0]],"id":39330606}],"con":true,"img":false}]}
{"op":"mcm","clk":"5321153142","pt":1646306625464,"mc":[{"id":"1.195532856","rc":[{"atb":[[2.28,8.75]],"id":43189000}],"con":true,"img":false}]}
{"op":"mcm","clk":"5321153156","pt":1646306625519,"mc":[{"id":"1.195532856","rc":[{"atb":[[2.7,6.59]],"id":42931075}],"con":true,"img":false}]}
{"op":"mcm","clk":"5321153176","pt":1646306625625,"mc":[{"id":"1.195532856","rc":[{"atb":[[2.44,7.78]],"id":43189001}],"con":true,"img":false}]}
{"op":"mcm","clk":"5321153186","pt":1646306625726,"mc":[{"id":"1.195532856","rc":[{"atb":[[2.38,8.12]],"id":39330606}],"con":true,"img":false}]}
{"op":"mcm","clk":"5321153194","pt":1646306625836,"mc":[{"id":"1.195532856","rc":[{"atb":[[2.04,10.77]],"id":41555102}],"con":true,"img":false}]}
{"op":"mcm","clk":"5321153223","pt":1646306626044,"mc":[{"id":"1.195532856","rc":[{"atb":[[2.12,10]],"id":42609837}],"con":true,"img":false}]}
{"op":"mcm","clk":"5321154400","pt":1646306635859,"mc":[{"id":"1.195532856","rc":[{"atb":[[6.8,0]],"id":43189001},{"trd":[[6.8,4]],"ltp":6.8,"tv":4.0,"id":43189001}],"con":true,"img":false}]}
{"op":"mcm","clk":"5321154797","pt":1646306639559,"mc":[{"id":"1.195532856","rc":[{"atb":[[6,2]],"id":39330606}],"con":true,"img":false}]}
{"op":"mcm","clk":"5321155677","pt":1646306646563,"mc":[{"id":"1.195532856","rc":[{"atb":[[2.32,9.41]],"id":43189000}],"con":true,"img":false}]}
{"op":"mcm","clk":"5321155695","pt":1646306646762,"mc":[{"id":"1.195532856","rc":[{"atb":[[2.74,7.14]],"id":42931075}],"con":true,"img":false}]}
{"op":"mcm","clk":"5321155709","pt":1646306646866,"mc":[{"id":"1.195532856","rc":[{"atb":[[2.42,8.74]],"id":39330606}],"con":true,"img":false}]}
{"op":"mcm","clk":"5321155740","pt":1646306647178,"mc":[{"id":"1.195532856","rc":[{"atb":[[2.08,11.5]],"id":41555102}],"con":true,"img":false}]}
{"op":"mcm","clk":"5321155762","pt":1646306647386,"mc":[{"id":"1.195532856","rc":[{"atb":[[2.16,10.71]],"id":42609837}],"con":true,"img":false}]}
{"op":"mcm","clk":"5321157689","pt":1646306664594,"mc":[{"id":"1.195532856","rc":[{"atb":[[2.44,12.45]],"id":43189001}],"con":true,"img":false}]}
{"op":"mcm","clk":"5321159078","pt":1646306676921,"mc":[{"id":"1.195532856","rc":[{"atb":[[2.12,6]],"id":41555102},{"atb":[[2.2,5.6]],"id":42609837}],"con":true,"img":false}]}
{"op":"mcm","clk":"5321159654","pt":1646306682126,"mc":[{"id":"1.195532856","rc":[{"atb":[[2.48,6.09]],"id":43189001}],"con":true,"img":false}]}
{"op":"mcm","clk":"5321160481","pt":1646306688535,"mc":[{"id":"1.195532856","rc":[{"atb":[[2.44,7.78]],"id":43189001},{"spn":6.24,"spf":1.0,"id":43189001}],"con":true,"img":false}]}
{"op":"mcm","clk":"5321161761","pt":1646306700509,"mc":[{"id":"1.195532856","rc":[{"atb":[[2.06,11.72]],"id":43189001}],"con":true,"img":false}]}
{"op":"mcm","clk":"5321162836","pt":1646306709877,"mc":[{"id":"1.195532856","rc":[{"atb":[[2.52,4.42]],"id":43189001}],"con":true,"img":false}]}
{"op":"mcm","clk":"5321164061","pt":1646306722102,"mc":[{"id":"1.195532856","rc":[{"atb":[[2.16,7.77]],"id":41555102}],"con":true,"img":false}]}
{"op":"mcm","clk":"5321164098","pt":1646306722413,"mc":[{"id":"1.195532856","rc":[{"atb":[[2.24,7.27]],"id":42609837}],"con":true,"img":false}]}
{"op":"mcm","clk":"5321165272","pt":1646306734239,"mc":[{"id":"1.195532856","rc":[{"atb":[[2.12,0]],"id":41555102},{"atb":[[2.2,0]],"id":42609837}],"con":true,"img":false}]}
{"op":"mcm","clk":"5321165912","pt":1646306739511,"mc":[{"id":"1.195532856","rc":[{"atb":[[2.48,0]],"id":43189001}],"con":true,"img":false}]}
{"op":"mcm","clk":"5321166617","pt":1646306746032,"mc":[{"id":"1.195532856","rc":[{"atb":[[2.52,0]],"id":43189001}],"con":true,"img":false}]}
{"op":"mcm","clk":"5321167555","pt":1646306754663,"mc":[{"id":"1.195532856","rc":[{"spn":6.22,"spf":1.0,"id":43189001},{"atb":[[2.2,5.6]],"id":41555102}],"con":true,"img":false}]}
{"op":"mcm","clk":"5321167567","pt":1646306754763,"mc":[{"id":"1.195532856","rc":[{"atb":[[2.28,5.25]],"id":42609837}],"con":true,"img":false}]}
{"op":"mcm","clk":"5321167926","pt":1646306758658,"mc":[{"id":"1.195532856","rc":[{"atb":[[2.16,0]],"id":41555102},{"atb":[[2.24,0]],"id":42609837}],"con":true,"img":false}]}
{"op":"mcm","clk":"5321168679","pt":1646306766802,"mc":[{"id":"1.195532856","rc":[{"atb":[[2.2,0]],"id":41555102},{"atb":[[2.28,0]],"id":42609837}],"con":true,"img":false}]}
{"op":"mcm","clk":"5321168707","pt":1646306767011,"mc":[{"id":"1.195532856","rc":[{"atb":[[2.44,12.45]],"id":43189001}],"con":true,"img":false}]}
{"op":"mcm","clk":"5321170847","pt":1646306789983,"mc":[{"id":"1.195532856","rc":[{"atb":[[2.48,6.09]],"id":43189001}],"con":true,"img":false}]}
{"op":"mcm","clk":"5321170931","pt":1646306790980,"mc":[{"id":"1.195532856","rc":[{"atb":[[2.12,6]],"id":41555102}],"con":true,"img":false}]}
{"op":"mcm","clk":"5321170957","pt":1646306791189,"mc":[{"id":"1.195532856","rc":[{"atb":[[2.2,5.6]],"id":42609837}],"con":true,"img":false}]}
{"op":"mcm","clk":"5321171466","pt":1646306797110,"mc":[{"id":"1.195532856","rc":[{"atb":[[2.44,7.78]],"id":43189001}],"con":true,"img":false}]}
{"op":"mcm","clk":"5321173440","pt":1646306820951,"mc":[{"id":"1.195532856","rc":[{"atb":[[2.52,4.42]],"id":43189001},{"spn":6.26,"spf":1.0,"id":43189001}],"con":true,"img":false}]}
{"op":"mcm","clk":"5321174798","pt":1646306836863,"mc":[{"id":"1.195532856","rc":[{"atb":[[2.48,0]],"id":43189001},{"atb":[[2.24,7.27]],"id":42609837}],"con":true,"img":false}]}
{"op":"mcm","clk":"5321174824","pt":1646306837172,"mc":[{"id":"1.195532856","rc":[{"atb":[[2.16,7.77]],"id":41555102}],"con":true,"img":false}]}
{"op":"mcm","clk":"5321175772","pt":1646306848385,"mc":[{"id":"1.195532856","rc":[{"atb":[[2.52,0]],"id":43189001},{"atb":[[2.12,0]],"id":41555102},{"atb":[[2.2,0]],"id":42609837}],"con":true,"img":false}]}
{"op":"mcm","clk":"5321177245","pt":1646306869325,"mc":[{"id":"1.195532856","rc":[{"atb":[[2.44,0]],"id":43189001},{"atb":[[2.2,5.6]],"id":41555102}],"con":true,"img":false}]}
{"op":"mcm","clk":"5321177254","pt":1646306869429,"mc":[{"id":"1.195532856","rc":[{"atb":[[2.28,5.25]],"id":42609837}],"con":true,"img":false}]}
{"op":"mcm","clk":"5321177659","pt":1646306874208,"mc":[{"id":"1.195532856","rc":[{"atb":[[2.16,0]],"id":41555102},{"atb":[[2.24,0]],"id":42609837}],"con":true,"img":false}]}
{"op":"mcm","clk":"5321178310","pt":1646306881539,"mc":[{"id":"1.195532856","rc":[{"atb":[[2.28,0]],"id":43189000},{"spn":6.03,"spf":1.0,"id":43189001},{"atb":[[2.04,0]],"id":41555102},{"atb":[[2.7,0]],"id":42931075},{"atb":[[2.38,0]],"id":39330606},{"atb":[[2.12,0]],"id":42609837}],"con":true,"img":false}]}
{"op":"mcm","clk":"5321178349","pt":1646306881907,"mc":[{"id":"1.195532856","rc":[{"atb":[[2.2,0]],"id":41555102},{"atb":[[2.28,0]],"id":42609837}],"con":true,"img":false}]}
{"op":"mcm","clk":"5321178964","pt":1646306888250,"mc":[{"id":"1.195532856","rc":[{"atb":[[2.12,10]],"id":41555102}],"con":true,"img":false}]}
{"op":"mcm","clk":"5321178987","pt":1646306888409,"mc":[{"id":"1.195532856","rc":[{"atb":[[2.36,8.24]],"id":43189000}],"con":true,"img":false}]}
{"op":"mcm","clk":"5321179002","pt":1646306888520,"mc":[{"id":"1.195532856","rc":[{"atb":[[2.78,6.29]],"id":42931075},{"atb":[[2.2,9.34]],"id":42609837}],"con":true,"img":false}]}
{"op":"mcm","clk":"5321179024","pt":1646306888726,"mc":[{"id":"1.195532856","rc":[{"atb":[[2.46,7.67]],"id":39330606}],"con":true,"img":false}]}
{"op":"mcm","clk":"5321180118","pt":1646306902132,"mc":[{"id":"1.195532856","rc":[{"atb":[[2.02,0]],"id":43189000},{"atb":[[2.02,0]],"id":43189001},{"atb":[[2,0]],"id":41555102},{"atb":[[2.04,0]],"id":42609837}],"con":true,"img":false}]}
{"op":"mcm","clk":"5321180128","pt":1646306902234,"mc":[{"id":"1.195532856","rc":[{"atb":[[2.34,8.45]],"id":43189000},{"atb":[[2.08,10.14]],"id":43189001},{"atb":[[2.1,12.55]],"id":41555102},{"atb":[[2.18,10.23]],"id":42609837}],"con":true,"img":false}]}
{"op":"mcm","clk":"5321180434","pt":1646306905362,"mc":[{"id":"1.195532856","rc":[{"atb":[[2.44,4.67]],"id":43189001}],"con":true,"img":false}]}
{"op":"mcm","clk":"5321181910","pt":1646306921168,"mc":[{"id":"1.195532856","rc":[{"atb":[[2.16,7.77]],"id":41555102}],"con":true,"img":false}]}
{"op":"mcm","clk":"5321181951","pt":1646306921581,"mc":[{"id":"1.195532856","rc":[{"atb":[[2.08,0]],"id":41555102},{"atb":[[2.16,0]],"id":42609837}],"con":true,"img":false}]}
{"op":"mcm","clk":"5321183051","pt":1646306935806,"mc":[{"id":"1.195532856","rc":[{"atb":[[2.22,5.51]],"id":42609837}],"con":true,"img":false}]}
{"op":"mcm","clk":"5321183120","pt":1646306936694,"mc":[{"id":"1.195532856","rc":[{"atb":[[2.16,18.49]],"id":41555102}],"con":true,"img":false}]}
{"op":"mcm","clk":"5321183133","pt":1646306936799,"mc":[{"id":"1.195532856","rc":[{"atb":[[2.48,6.09]],"id":43189001}],"con":true,"img":false}]}
{"op":"mcm","clk":"5321183159","pt":1646306937106,"mc":[{"id":"1.195532856","rc":[{"atb":[[2.24,10.02]],"id":42609837}],"con":true,"img":false}]}
{"op":"mcm","clk":"5321183182","pt":1646306937414,"mc":[{"id":"1.195532856","rc":[{"atb":[[2.24,17.29]],"id":42609837}],"con":true,"img":false}]}
{"op":"mcm","clk":"5321184003","pt":1646306947034,"mc":[{"id":"1.195532856","rc":[{"atb":[[2.44,0]],"id":43189001},{"spn":6.24,"spf":1.0,"id":43189001},{"atb":[[2.22,0]],"id":42609837}],"con":true,"img":false}]}
{"op":"mcm","clk":"5321184293","pt":1646306950348,"mc":[{"id":"1.195532856","rc":[{"atb":[[2.2,5.6]],"id":41555102}],"con":true,"img":false}]}
{"op":"mcm","clk":"5321186214","pt":1646306971149,"mc":[{"id":"1.195532856","rc":[{"atb":[[2.52,4.42]],"id":43189001}],"con":true,"img":false}]}
{"op":"mcm","clk":"5321186229","pt":1646306971248,"mc":[{"id":"1.195532856","rc":[{"atb":[[2.28,5.25]],"id":42609837}],"con":true,"img":false}]}
{"op":"mcm","clk":"5321186732","pt":1646306976858,"mc":[{"id":"1.195532856","rc":[{"atb":[[2.48,0]],"id":43189001},{"atb":[[2.16,10.71]],"id":41555102}],"con":true,"img":false}]}
{"op":"mcm","clk":"5321186846","pt":1646306978157,"mc":[{"id":"1.195532856","rc":[{"atb":[[2.12,10]],"id":43189001}],"con":true,"img":false}]}
{"op":"mcm","clk":"5321187337","pt":1646306983995,"mc":[{"id":"1.195532856","rc":[{"atb":[[2.52,0]],"id":43189001}],"con":true,"img":false}]}
{"op":"mcm","clk":"5321187993","pt":1646306991215,"mc":[{"id":"1.195532856","rc":[{"atb":[[2.06,0]],"id":43189001}],"con":true,"img":false}]}
{"op":"mcm","clk":"5321188004","pt":1646306991376,"mc":[{"id":"1.195532856","rc":[{"atb":[[2.24,10.02]],"id":42609837}],"con":true,"img":false}]}
{"op":"mcm","clk":"5321188025","pt":1646306991693,"mc":[{"id":"1.195532856","rc":[{"atb":[[2.24,7.27]],"id":41555102}],"con":true,"img":false}]}
{"op":"mcm","clk":"5321188909","pt":1646307002925,"mc":[{"id":"1.195532856","rc":[{"atb":[[2.2,0]],"id":41555102}],"con":true,"img":false}]}
{"op":"mcm","clk":"5321189353","pt":1646307007947,"mc":[{"id":"1.195532856","rc":[{"atb":[[2.44,4.67]],"id":43189001},{"spn":6.22,"spf":1.0,"id":43189001}],"con":true,"img":false}]}
{"op":"mcm","clk":"5321189435","pt":1646307008834,"mc":[{"id":"1.195532856","rc":[{"atb":[[2.32,6.83]],"id":42609837}],"con":true,"img":false}]}
{"op":"mcm","clk":"5321190459","pt":1646307019432,"mc":[{"id":"1.195532856","rc":[{"atb":[[2.28,0]],"id":42609837}],"con":true,"img":false}]}
{"op":"mcm","clk":"5321190700","pt":1646307021872,"mc":[{"id":"1.195532856","rc":[{"atb":[[2.28,5.25]],"id":41555102}],"con":true,"img":false}]}
{"op":"mcm","clk":"5321190834","pt":1646307022965,"mc":[{"id":"1.195532856","rc":[{"atb":[[2.24,0]],"id":41555102}],"con":true,"img":false}]}
{"op":"mcm","clk":"5321191587","pt":1646307030956,"mc":[{"id":"1.195532856","rc":[{"atb":[[2.28,0]],"id":41555102}],"con":true,"img":false}]}
{"op":"mcm","clk":"5321192207","pt":1646307037663,"mc":[{"id":"1.195532856","rc":[{"atb":[[2.32,0]],"id":42609837}],"con":true,"img":false}]}
{"op":"mcm","clk":"5321192218","pt":1646307037764,"mc":[{"id":"1.195532856","rc":[{"atb":[[2.16,18.49]],"id":41555102}],"con":true,"img":false}]}
{"op":"mcm","clk":"5321192233","pt":1646307037968,"mc":[{"id":"1.195532856","rc":[{"atb":[[2.48,6.09]],"id":43189001}],"con":true,"img":false}]}
{"op":"mcm","clk":"5321193192","pt":1646307049371,"mc":[{"id":"1.195532856","rc":[{"atb":[[2.44,0]],"id":43189001}],"con":true,"img":false}]}
{"op":"mcm","clk":"5321193628","pt":1646307054393,"mc":[{"id":"1.195532856","rc":[{"atb":[[2.24,17.29]],"id":42609837}],"con":true,"img":false}]}
{"op":"mcm","clk":"5321193692","pt":1646307055216,"mc":[{"id":"1.195532856","rc":[{"atb":[[2.2,5.6]],"id":41555102}],"con":true,"img":false}]}
{"op":"mcm","clk":"5321194889","pt":1646307066944,"mc":[{"id":"1.195532856","rc":[{"atb":[[2.52,4.42]],"id":43189001}],"con":true,"img":false}]}
{"op":"mcm","clk":"5321194910","pt":1646307067108,"mc":[{"id":"1.195532856","rc":[{"atb":[[2.28,5.25]],"id":42609837}],"con":true,"img":false}]}
{"op":"mcm","clk":"5321195151","pt":1646307069334,"mc":[{"id":"1.195532856","rc":[{"atb":[[2.12,21.09]],"id":43189001},{"spn":6.26,"spf":1.0,"id":43189001}],"con":true,"img":false}]}
{"op":"mcm","clk":"5321195162","pt":1646307069438,"mc":[{"id":"1.195532856","rc":[{"atb":[[2.48,0]],"id":43189001}],"con":true,"img":false}]}
{"op":"mcm","clk":"5321196020","pt":1646307079438,"mc":[{"id":"1.195532856","rc":[{"atb":[[2.52,0]],"id":43189001}],"con":true,"img":false}]}
{"op":"mcm","clk":"5321196505","pt":1646307084379,"mc":[{"id":"1.195532856","rc":[{"atb":[[2.16,10.71]],"id":41555102},{"atb":[[2.24,10.02]],"id":42609837}],"con":true,"img":false}]}
{"op":"mcm","clk":"5321198067","pt":1646307100995,"mc":[{"id":"1.195532856","rc":[{"atb":[[2.24,7.27]],"id":41555102}],"con":true,"img":false}]}
{"op":"mcm","clk":"5321198078","pt":1646307101099,"mc":[{"id":"1.195532856","rc":[{"atb":[[2.44,4.67]],"id":43189001}],"con":true,"img":false}]}
{"op":"mcm","clk":"5321198108","pt":1646307101362,"mc":[{"id":"1.195532856","rc":[{"atb":[[2.32,6.83]],"id":42609837}],"con":true,"img":false}]}
{"op":"mcm","clk":"5321199230","pt":1646307113403,"mc":[{"id":"1.195532856","rc":[{"atb":[[2.2,0]],"id":41555102},{"atb":[[2.28,0]],"id":42609837}],"con":true,"img":false}]}
{"op":"mcm","clk":"5321200003","pt":1646307122000,"mc":[{"id":"1.195532856","rc":[{"atb":[[3.8,0]],"id":42609837}],"con":true,"img":false}]}
{"op":"mcm","clk":"5321200016","pt":1646307122098,"mc":[{"id":"1.195532856","rc":[{"atb":[[3.75,2]],"id":42609837}],"con":true,"img":false}]}
{"op":"mcm","clk":"5321200970","pt":1646307132426,"mc":[{"id":"1.195532856","rc":[{"atb":[[2.32,0]],"id":43189000},{"spn":6.22,"spf":1.0,"id":43189001},{"atb":[[2.24,0]],"id":41555102},{"atb":[[2.74,0]],"id":42931075},{"atb":[[2.42,0]],"id":39330606},{"atb":[[2.32,0]],"id":42609837}],"con":true,"img":false}]}
{"op":"mcm","clk":"5321201546","pt":1646307139406,"mc":[{"id":"1.195532856","rc":[{"atb":[[2.36,0]],"id":43189000},{"atb":[[2.12,0]],"id":41555102},{"atb":[[2.2,0]],"id":42609837}],"con":true,"img":false}]}
{"op":"mcm","clk":"5321201817","pt":1646307142614,"mc":[{"id":"1.195532856","rc":[{"atb":[[2.2,9.34]],"id":41555102},{"atb":[[2.28,8.75]],"id":42609837}],"con":true,"img":false}]}
{"op":"mcm","clk":"5321201829","pt":1646307142718,"mc":[{"id":"1.195532856","rc":[{"atb":[[2.38,8.12]],"id":43189000}],"con":true,"img":false}]}
{"op":"mcm","clk":"5321202414","pt":1646307149234,"mc":[{"id":"1.195532856","rc":[{"atb":[[2.48,6.09]],"id":43189001}],"con":true,"img":false}]}
{"op":"mcm","clk":"5321202435","pt":1646307149440,"mc":[{"id":"1.195532856","rc":[{"atb":[[2.82,6.82]],"id":42931075}],"con":true,"img":false}]}
{"op":"mcm","clk":"5321202442","pt":1646307149545,"mc":[{"id":"1.195532856","rc":[{"atb":[[2.5,8.28]],"id":39330606}],"con":true,"img":false}]}
{"op":"mcm","clk":"5321202473","pt":1646307149854,"mc":[{"id":"1.195532856","rc":[{"atb":[[2.42,8.74]],"id":43189000}],"con":true,"img":false}]}
{"op":"mcm","clk":"5321203081","pt":1646307157138,"mc":[{"id":"1.195532856","rc":[{"atb":[[2.44,0]],"id":43189001}],"con":true,"img":false}]}
{"op":"mcm","clk":"5321203383","pt":1646307160149,"mc":[{"id":"1.195532856","rc":[{"atb":[[2.2,14.94]],"id":41555102}],"con":true,"img":false}]}
{"op":"mcm","clk":"5321203407","pt":1646307160359,"mc":[{"id":"1.195532856","rc":[{"atb":[[2.28,14.01]],"id":42609837}],"con":true,"img":false}]}
{"op":"mcm","clk":"5321205503","pt":1646307178585,"mc":[{"id":"1.195532856","rc":[{"atb":[[2.52,4.42]],"id":43189001}],"con":true,"img":false}]}
{"op":"mcm","clk":"5321205633","pt":1646307179994,"mc":[{"id":"1.195532856","rc":[{"atb":[[2.48,0]],"id":43189001}],"con":true,"img":false}]}
{"op":"mcm","clk":"5321205656","pt":1646307180308,"mc":[{"id":"1.195532856","rc":[{"atb":[[2.24,7.27]],"id":41555102},{"atb":[[2.32,6.83]],"id":42609837}],"con":true,"img":false}]}
{"op":"mcm","clk":"5321206445","pt":1646307188017,"mc":[{"id":"1.195532856","rc":[{"atb":[[2.52,0]],"id":43189001},{"atb":[[2.2,9.34]],"id":41555102},{"atb":[[2.28,8.75]],"id":42609837}],"con":true,"img":false}]}
{"op":"mcm","clk":"5321207020","pt":1646307195362,"mc":[{"id":"1.195532856","rc":[{"spn":6.06,"spf":1.0,"id":43189001},{"atb":[[2.16,0]],"id":41555102}],"con":true,"img":false}]}
{"op":"mcm","clk":"5321207641","pt":1646307201136,"mc":[{"id":"1.195532856","rc":[{"atb":[[2.08,0]],"id":43189001},{"atb":[[2.1,0]],"id":41555102},{"atb":[[2.18,0]],"id":42609837}],"con":true,"img":false}]}
{"op":"mcm","clk":"5321207651","pt":1646307201241,"mc":[{"id":"1.195532856","rc":[{"atb":[[2.14,10.14]],"id":43189001},{"atb":[[2.26,12.55]],"id":41555102},{"atb":[[2.34,10.23]],"id":42609837}],"con":true,"img":false}]}
{"op":"mcm","clk":"5321208357","pt":1646307209157,"mc":[{"id":"1.195532856","rc":[{"atb":[[2.44,4.67]],"id":43189001}],"con":true,"img":false}]}
{"op":"mcm","clk":"5321208794","pt":1646307213961,"mc":[{"id":"1.195532856","rc":[{"atb":[[2.24,0]],"id":42609837}],"con":true,"img":false}]}
{"op":"mcm","clk":"5321208829","pt":1646307214273,"mc":[{"id":"1.195532856","rc":[{"atb":[[2.3,9.56]],"id":41555102}],"con":true,"img":false}]}
{"op":"mcm","clk":"5321209428","pt":1646307221062,"mc":[{"id":"1.195532856","rc":[{"atb":[[2.12,11.09]],"id":43189001}],"con":true,"img":false}]}
{"op":"mcm","clk":"5321210034","pt":1646307227794,"mc":[{"id":"1.195532856","rc":[{"atb":[[2.38,4.87]],"id":42609837}],"con":true,"img":false}]}
{"op":"mcm","clk":"5321210165","pt":1646307229094,"mc":[{"id":"1.195532856","rc":[{"atb":[[2.24,0]],"id":41555102},{"atb":[[2.32,0]],"id":42609837}],"con":true,"img":false}]}
{"op":"mcm","clk":"5321210196","pt":1646307229407,"mc":[{"id":"1.195532856","rc":[{"atb":[[2.42,8.74]],"id":42609837}],"con":true,"img":false}]}
{"op":"mcm","clk":"5321211116","pt":1646307238908,"mc":[{"id":"1.195532856","rc":[{"atb":[[2.38,0]],"id":42609837}],"con":true,"img":false}]}
{"op":"mcm","clk":"5321211401","pt":1646307241923,"mc":[{"id":"1.195532856","rc":[{"atb":[[2.34,5.02]],"id":41555102}],"con":true,"img":false}]}
{"op":"mcm","clk":"5321211724","pt":1646307245221,"mc":[{"id":"1.195532856","rc":[{"atb":[[2.48,6.09]],"id":43189001}],"con":true,"img":false}]}
{"op":"mcm","clk":"5321212310","pt":1646307251337,"mc":[{"id":"1.195532856","rc":[{"atb":[[2.44,0]],"id":43189001}],"con":true,"img":false}]}
{"op":"mcm","clk":"5321213182","pt":1646307260144,"mc":[{"id":"1.195532856","rc":[{"spn":6.24,"spf":1.0,"id":43189001},{"atb":[[2.46,4.6]],"id":42609837}],"con":true,"img":false}]}
{"op":"mcm","clk":"5321214317","pt":1646307272167,"mc":[{"id":"1.195532856","rc":[{"atb":[[2.52,4.42]],"id":43189001}],"con":true,"img":false}]}
{"op":"mcm","clk":"5321214633","pt":1646307275498,"mc":[{"id":"1.195532856","rc":[{"atb":[[2.38,6.53]],"id":41555102}],"con":true,"img":false}]}
{"op":"mcm","clk":"5321214669","pt":1646307275864,"mc":[{"id":"1.195532856","rc":[{"atb":[[2.48,0]],"id":43189001}],"con":true,"img":false}]}
{"op":"mcm","clk":"5321215405","pt":1646307284096,"mc":[{"id":"1.195532856","rc":[{"atb":[[2.52,0]],"id":43189001},{"atb":[[2.34,0]],"id":41555102}],"con":true,"img":false}]}
{"op":"mcm","clk":"5321217488","pt":1646307303436,"mc":[{"id":"1.195532856","rc":[{"atb":[[2.38,0]],"id":41555102},{"atb":[[2.5,6.01]],"id":42609837}],"con":true,"img":false}]}
{"op":"mcm","clk":"5321217656","pt":1646307305043,"mc":[{"id":"1.195532856","rc":[{"atb":[[2.44,4.67]],"id":43189001}],"con":true,"img":false}]}
{"op":"mcm","clk":"5321218235","pt":1646307310927,"mc":[{"id":"1.195532856","rc":[{"atl":[[8.8,0]],"id":43189000},{"atb":[[2.46,0]],"id":42609837},{"atl":[[6.8,0]],"id":42609837}],"con":true,"img":false}]}
{"op":"mcm","clk":"5321218251","pt":1646307311031,"mc":[{"id":"1.195532856","rc":[{"atl":[[8.6,1.33]],"id":43189000},{"atl":[[6.6,1.8]],"id":42609837}],"con":true,"img":false}]}
{"op":"mcm","clk":"5321218964","pt":1646307317942,"mc":[{"id":"1.195532856","rc":[{"atb":[[2.12,0]],"id":43189001},{"atb":[[2.3,16.49]],"id":41555102}],"con":true,"img":false}]}
{"op":"mcm","clk":"5321219151","pt":1646307320026,"mc":[{"id":"1.195532856","rc":[{"atb":[[2.44,0]],"id":43189001}],"con":true,"img":false}]}
{"op":"mcm","clk":"5321220893","pt":1646307334943,"mc":[{"id":"1.195532856","rc":[{"spn":6.9,"spf":1.0,"id":43189000},{"spn":6.07,"spf":1.0,"id":43189001},{"atb":[[2.34,5.02]],"id":41555102}],"con":true,"img":false}]}
{"op":"mcm","clk":"5321220908","pt":1646307335047,"mc":[{"id":"1.195532856","rc":[{"atb":[[2.56,4.31]],"id":42609837}],"con":true,"img":false}]}
{"op":"mcm","clk":"5321220935","pt":1646307335255,"mc":[{"id":"1.195532856","rc":[{"atb":[[2.5,0]],"id":42609837}],"con":true,"img":false}]}
{"op":"mcm","clk":"5321221624","pt":1646307341287,"mc":[{"id":"1.195532856","rc":[{"atb":[[2.5,4.48]],"id":43189001}],"con":true,"img":false}]}
{"op":"mcm","clk":"5321221946","pt":1646307344096,"mc":[{"id":"1.195532856","rc":[{"atb":[[2.56,0]],"id":42609837}],"con":true,"img":false}]}
{"op":"mcm","clk":"5321223106","pt":1646307354205,"mc":[{"id":"1.195532856","rc":[{"atb":[[2.38,6.53]],"id":42609837}],"con":true,"img":false}]}
{"op":"mcm","clk":"5321224206","pt":1646307364737,"mc":[{"id":"1.195532856","rc":[{"atb":[[2.78,0]],"id":42931075},{"atb":[[2.46,0]],"id":39330606}],"con":true,"img":false}]}
{"op":"mcm","clk":"5321224553","pt":1646307367658,"mc":[{"id":"1.195532856","rc":[{"atb":[[2.86,6.02]],"id":42931075}],"con":true,"img":false}]}
{"op":"mcm","clk":"5321224568","pt":1646307367776,"mc":[{"id":"1.195532856","rc":[{"atb":[[2.54,7.27]],"id":39330606}],"con":true,"img":false}]}
{"op":"mcm","clk":"5321224604","pt":1646307368026,"mc":[{"id":"1.195532856","rc":[{"atb":[[2.46,4.6]],"id":42609837}],"con":true,"img":false}]}
{"op":"mcm","clk":"5321225060","pt":1646307372029,"mc":[{"id":"1.195532856","rc":[{"atb":[[2.3,9.56]],"id":41555102}],"con":true,"img":false}]}
{"op":"mcm","clk":"5321226245","pt":1646307383278,"mc":[{"id":"1.195532856","rc":[{"atb":[[2.38,0]],"id":43189000}],"con":true,"img":false}]}
{"op":"mcm","clk":"5321226618","pt":1646307386657,"mc":[{"id":"1.195532856","rc":[{"atb":[[2.46,7.67]],"id":43189000}],"con":true,"img":false}]}
{"op":"mcm","clk":"5321226639","pt":1646307386864,"mc":[{"id":"1.195532856","rc":[{"atb":[[2.38,0]],"id":42609837}],"con":true,"img":false}]}
{"op":"mcm","clk":"5321226666","pt":1646307387073,"mc":[{"id":"1.195532856","rc":[{"atb":[[2.38,6.53]],"id":41555102}],"con":true,"img":false}]}
{"op":"mcm","clk":"5321226679","pt":1646307387178,"mc":[{"id":"1.195532856","rc":[{"atb":[[2.56,5.78]],"id":43189001}],"con":true,"img":false}]}
{"op":"mcm","clk":"5321227847","pt":1646307398096,"mc":[{"id":"1.195532856","rc":[{"atb":[[2.5,0]],"id":43189001},{"spn":6.28,"spf":1.0,"id":43189001},{"atb":[[2.34,0]],"id":41555102}],"con":true,"img":false}]}
{"op":"mcm","clk":"5321228509","pt":1646307404175,"mc":[{"id":"1.195532856","rc":[{"atb":[[2.5,6.01]],"id":42609837}],"con":true,"img":false}]}
{"op":"mcm","clk":"5321229336","pt":1646307412591,"mc":[{"id":"1.195532856","rc":[{"atb":[[2.2,0]],"id":41555102},{"atb":[[2.28,0]],"id":42609837}],"con":true,"img":false}]}
{"op":"mcm","clk":"5321229352","pt":1646307412801,"mc":[{"id":"1.195532856","rc":[{"atb":[[2.46,0]],"id":42609837}],"con":true,"img":false}]}
{"op":"mcm","clk":"5321229633","pt":1646307415804,"mc":[{"id":"1.195532856","rc":[{"atb":[[2.42,7.89]],"id":41555102}],"con":true,"img":false}]}
{"op":"mcm","clk":"5321229641","pt":1646307415909,"mc":[{"id":"1.195532856","rc":[{"atb":[[2.54,7.27]],"id":42609837}],"con":true,"img":false}]}
{"op":"mcm","clk":"5321229834","pt":1646307418696,"mc":[{"id":"1.195532856","rc":[{"atb":[[2.62,4.15]],"id":43189001}],"con":true,"img":false}]}
{"op":"mcm","clk":"5321229844","pt":1646307418801,"mc":[{"id":"1.195532856","rc":[{"atb":[[2.42,12.62]],"id":41555102}],"con":true,"img":false}]}
{"op":"mcm","clk":"5321230212","pt":1646307422382,"mc":[{"id":"1.195532856","rc":[{"atb":[[2.56,0],[2.18,10.52]],"id":43189001},{"atb":[[2.38,0]],"id":41555102}],"con":true,"img":false}]}
{"op":"mcm","clk":"5321230462","pt":1646307424825,"mc":[{"id":"1.195532856","rc":[{"atb":[[2.22,9.19]],"id":43189001}],"con":true,"img":false}]}
{"op":"mcm","clk":"5321231182","pt":1646307432132,"mc":[{"id":"1.195532856","rc":[{"atb":[[2.62,0]],"id":43189001},{"atb":[[2.42,7.89]],"id":41555102}],"con":true,"img":false}]}
{"op":"mcm","clk":"5321231200","pt":1646307432237,"mc":[{"id":"1.195532856","rc":[{"atb":[[2.56,4.31]],"id":42609837}],"con":true,"img":false}]}
{"op":"mcm","clk":"5321232181","pt":1646307442233,"mc":[{"id":"1.195532856","rc":[{"atb":[[2.5,0]],"id":42609837}],"con":true,"img":false}]}
{"op":"mcm","clk":"5321232842","pt":1646307449468,"mc":[{"id":"1.195532856","rc":[{"atb":[[2.56,0]],"id":42609837}],"con":true,"img":false}]}
{"op":"mcm","clk":"5321233408","pt":1646307456180,"mc":[{"id":"1.195532856","rc":[{"atb":[[2.5,4.48]],"id":43189001}],"con":true,"img":false}]}
{"op":"mcm","clk":"5321233429","pt":1646307456387,"mc":[{"id":"1.195532856","rc":[{"atb":[[2.34,5.02]],"id":41555102}],"con":true,"img":false}]}
{"op":"mcm","clk":"5321233598","pt":1646307458108,"mc":[{"id":"1.195532856","rc":[{"spn":6.25,"spf":1.0,"id":43189001},{"atb":[[2.46,6.17]],"id":41555102}],"con":true,"img":false}]}
{"op":"mcm","clk":"5321234504","pt":1646307467025,"mc":[{"id":"1.195532856","rc":[{"atb":[[2.34,0]],"id":41555102}],"con":true,"img":false}]}
{"op":"mcm","clk":"5321234824","pt":1646307469822,"mc":[{"id":"1.195532856","rc":[{"atb":[[2.46,4.6]],"id":42609837}],"con":true,"img":false}]}
{"op":"mcm","clk":"5321236697","pt":1646307486127,"mc":[{"id":"1.195532856","rc":[{"atb":[[2.56,5.78]],"id":43189001}],"con":true,"img":false}]}
{"op":"mcm","clk":"5321236733","pt":1646307486441,"mc":[{"id":"1.195532856","rc":[{"atb":[[2.3,0]],"id":41555102},{"atb":[[2.42,0],[2.6,5.63]],"id":42609837}],"con":true,"img":false}]}
{"op":"mcm","clk":"5321236884","pt":1646307487831,"mc":[{"id":"1.195532856","rc":[{"atb":[[2.5,4.48]],"id":41555102}],"con":true,"img":false}]}
{"op":"mcm","clk":"5321237547","pt":1646307493860,"mc":[{"id":"1.195532856","rc":[{"atb":[[2.5,0]],"id":43189001},{"atb":[[2.46,0]],"id":42609837}],"con":true,"img":false}]}
{"op":"mcm","clk":"5321238291","pt":1646307500971,"mc":[{"id":"1.195532856","rc":[{"atb":[[2.58,7.86]],"id":42609837}],"con":true,"img":false}]}
{"op":"mcm","clk":"5321238311","pt":1646307501181,"mc":[{"id":"1.195532856","rc":[{"atb":[[2.54,8.06]],"id":41555102}],"con":true,"img":false}]}
{"op":"mcm","clk":"5321238341","pt":1646307501446,"mc":[{"id":"1.195532856","rc":[{"atb":[[2.14,0]],"id":43189001},{"atb":[[2.26,0]],"id":41555102}],"con":true,"img":false}]}
{"op":"mcm","clk":"5321238352","pt":1646307501554,"mc":[{"id":"1.195532856","rc":[{"atb":[[2.24,10.14]],"id":43189001},{"atb":[[2.32,12.55]],"id":41555102}],"con":true,"img":false}]}
{"op":"mcm","clk":"5321239335","pt":1646307512104,"mc":[{"id":"1.195532856","rc":[{"atb":[[2.5,0]],"id":41555102}],"con":true,"img":false}]}
{"op":"mcm","clk":"5321239654","pt":1646307515290,"mc":[{"id":"1.195532856","rc":[{"atb":[[2.62,4.15]],"id":43189001},{"atb":[[2.66,4.05]],"id":42609837}],"con":true,"img":false}]}
{"op":"mcm","clk":"5321239727","pt":1646307515958,"mc":[{"id":"1.195532856","rc":[{"atb":[[2.56,0]],"id":43189001}],"con":true,"img":false}]}
{"op":"mcm","clk":"5321240457","pt":1646307523893,"mc":[{"id":"1.195532856","rc":[{"atb":[[2.62,0]],"id":43189001},{"spn":6.12,"spf":1.0,"id":43189001}],"con":true,"img":false}]}
{"op":"mcm","clk":"5321241081","pt":1646307530135,"mc":[{"id":"1.195532856","rc":[{"atb":[[2.6,4.19]],"id":41555102}],"con":true,"img":false}]}
{"op":"mcm","clk":"5321241680","pt":1646307535656,"mc":[{"id":"1.195532856","rc":[{"atb":[[2.5,6.01]],"id":43189001}],"con":true,"img":false}]}
{"op":"mcm","clk":"5321241702","pt":1646307535919,"mc":[{"id":"1.195532856","rc":[{"atb":[[2.46,0]],"id":41555102}],"con":true,"img":false}]}
{"op":"mcm","clk":"5321243145","pt":1646307550661,"mc":[{"id":"1.195532856","rc":[{"atb":[[2.6,0]],"id":42609837}],"con":true,"img":false}]}
{"op":"mcm","clk":"5321244076","pt":1646307560056,"mc":[{"id":"1.195532856","rc":[{"atb":[[2.66,0]],"id":42609837}],"con":true,"img":false}]}
{"op":"mcm","clk":"5321244470","pt":1646307564376,"mc":[{"id":"1.195532856","rc":[{"atb":[[2.66,5.43]],"id":41555102}],"con":true,"img":false}]}
{"op":"mcm","clk":"5321244739","pt":1646307566668,"mc":[{"id":"1.195532856","rc":[{"atb":[[2.56,4.31]],"id":43189001}],"con":true,"img":false}]}
{"op":"mcm","clk":"5321245548","pt":1646307575618,"mc":[{"id":"1.195532856","rc":[{"atb":[[2.6,0]],"id":41555102}],"con":true,"img":false}]}
{"op":"mcm","clk":"5321246140","pt":1646307581418,"mc":[{"id":"1.195532856","rc":[{"atb":[[2.64,4.1]],"id":42609837}],"con":true,"img":false}]}
{"op":"mcm","clk":"5321247277","pt":1646307593310,"mc":[{"id":"1.195532856","rc":[{"spn":6.28,"spf":1.0,"id":43189001},{"atb":[[2.72,3.9]],"id":41555102}],"con":true,"img":false}]}
{"op":"mcm","clk":"5321247316","pt":1646307593932,"mc":[{"id":"1.195532856","rc":[{"atb":[[2.5,0]],"id":43189001},{"atb":[[2.66,0]],"id":41555102}],"con":true,"img":false}]}
{"op":"mcm","clk":"5321247931","pt":1646307602453,"mc":[{"id":"1.195532856","rc":[{"atb":[[2.56,0]],"id":43189001},{"atb":[[2.72,0]],"id":41555102}],"con":true,"img":false}]}
{"op":"mcm","clk":"5321248514","pt":1646307611814,"mc":[{"id":"1.195532856","rc":[{"atb":[[2.82,0]],"id":42931075},{"atb":[[2.5,0]],"id":39330606}],"con":true,"img":false}]}
{"op":"mcm","clk":"5321248545","pt":1646307612084,"mc":[{"id":"1.195532856","rc":[{"atb":[[2.46,6.17]],"id":41555102}],"con":true,"img":false}]}
{"op":"mcm","clk":"5321249431","pt":1646307624126,"mc":[{"id":"1.195532856","rc":[{"atb":[[2.6,4.19]],"id":41555102}],"con":true,"img":false}]}
{"op":"mcm","clk":"5321249437","pt":1646307624231,"mc":[{"id":"1.195532856","rc":[{"atb":[[2.5,4.48]],"id":43189001}],"con":true,"img":false}]}
{"op":"mcm","clk":"5321249827","pt":1646307629723,"mc":[{"id":"1.195532856","rc":[{"atb":[[2.7,5.3]],"id":42609837}],"con":true,"img":false}]}
{"op":"mcm","clk":"5321249854","pt":1646307630035,"mc":[{"id":"1.195532856","rc":[{"atb":[[2.9,6.53]],"id":42931075}],"con":true,"img":false}]}
{"op":"mcm","clk":"5321249863","pt":1646307630138,"mc":[{"id":"1.195532856","rc":[{"atb":[[2.42,0]],"id":43189000}],"con":true,"img":false}]}
{"op":"mcm","clk":"5321249875","pt":1646307630344,"mc":[{"id":"1.195532856","rc":[{"atb":[[2.58,7.86]],"id":39330606}],"con":true,"img":false}]}
{"op":"mcm","clk":"5321250774","pt":1646307642329,"mc":[{"id":"1.195532856","rc":[{"atb":[[2.64,0]],"id":42609837}],"con":true,"img":false}]}
{"op":"mcm","clk":"5321250852","pt":1646307643194,"mc":[{"id":"1.195532856","rc":[{"atb":[[2.5,8.28]],"id":43189000},{"atb":[[2.46,0]],"id":41555102}],"con":true,"img":false}]}
{"op":"mcm","clk":"5321252375","pt":1646307659579,"mc":[{"id":"1.195532856","rc":[{"spn":6.25,"spf":1.0,"id":43189001},{"atb":[[2.76,3.81]],"id":42609837}],"con":true,"img":false}]}
{"op":"mcm","clk":"5321252389","pt":1646307659740,"mc":[{"id":"1.195532856","rc":[{"atb":[[2.42,0]],"id":41555102}],"con":true,"img":false}]}
{"op":"mcm","clk":"5321252423","pt":1646307660152,"mc":[{"id":"1.195532856","rc":[{"atb":[[2.7,0]],"id":42609837}],"con":true,"img":false}]}
{"op":"mcm","clk":"5321252447","pt":1646307660461,"mc":[{"id":"1.195532856","rc":[{"atb":[[2.66,5.43]],"id":41555102}],"con":true,"img":false}]}
{"op":"mcm","clk":"5321252500","pt":1646307661249,"mc":[{"id":"1.195532856","rc":[{"atb":[[2.56,5.78]],"id":43189001}],"con":true,"img":false}]}
{"op":"mcm","clk":"5321252624","pt":1646307662905,"mc":[{"id":"1.195532856","rc":[{"atb":[[2.7,6.59]],"id":41555102}],"con":true,"img":false}]}
{"op":"mcm","clk":"5321253075","pt":1646307668585,"mc":[{"id":"1.195532856","rc":[{"atb":[[2.5,0]],"id":43189001},{"atb":[[2.6,0]],"id":41555102},{"atb":[[2.76,0]],"id":42609837}],"con":true,"img":false}]}
{"op":"mcm","clk":"5321253082","pt":1646307668691,"mc":[{"id":"1.195532856","rc":[{"atb":[[2.22,0]],"id":43189001}],"con":true,"img":false}]}
{"op":"mcm","clk":"5321253516","pt":1646307674811,"mc":[{"id":"1.195532856","rc":[{"atb":[[2.54,0]],"id":42609837}],"con":true,"img":false}]}
{"op":"mcm","clk":"5321253708","pt":1646307676838,"mc":[{"id":"1.195532856","rc":[{"atb":[[2.18,0]],"id":43189001}],"con":true,"img":false}]}
{"op":"mcm","clk":"5321253762","pt":1646307677455,"mc":[{"id":"1.195532856","rc":[{"atb":[[2.62,6.91]],"id":42609837}],"con":true,"img":false}]}
{"op":"mcm","clk":"5321254713","pt":1646307689761,"mc":[{"id":"1.195532856","rc":[{"atb":[[2.62,4.15]],"id":43189001},{"atb":[[2.72,3.9]],"id":41555102}],"con":true,"img":false}]}
{"op":"mcm","clk":"5321254725","pt":1646307689864,"mc":[{"id":"1.195532856","rc":[{"atb":[[2.64,4.1]],"id":42609837}],"con":true,"img":false}]}
{"op":"mcm","clk":"5321255223","pt":1646307695266,"mc":[{"id":"1.195532856","rc":[{"atb":[[2.56,0]],"id":43189001},{"atb":[[2.66,0]],"id":41555102}],"con":true,"img":false}]}
{"op":"mcm","clk":"5321256004","pt":1646307704995,"mc":[{"id":"1.195532856","rc":[{"atb":[[2.62,0]],"id":43189001},{"atb":[[2.72,0]],"id":41555102}],"con":true,"img":false}]}
{"op":"mcm","clk":"5321257677","pt":1646307725733,"mc":[{"id":"1.195532856","rc":[{"atb":[[2.5,4.48]],"id":43189001}],"con":true,"img":false}]}
{"op":"mcm","clk":"5321257686","pt":1646307725838,"mc":[{"id":"1.195532856","rc":[{"atb":[[2.6,4.19]],"id":41555102}],"con":true,"img":false}]}
{"op":"mcm","clk":"5321257997","pt":1646307729016,"mc":[{"id":"1.195532856","rc":[{"atb":[[2.7,5.83]],"id":42609837}],"con":true,"img":false}]}
{"op":"mcm","clk":"5321258916","pt":1646307739236,"mc":[{"id":"1.195532856","rc":[{"atb":[[2.64,0]],"id":42609837}],"con":true,"img":false}]}
{"op":"mcm","clk":"5321259068","pt":1646307740701,"mc":[{"id":"1.195532856","rc":[{"atb":[[2.76,5.63]],"id":41555102}],"con":true,"img":false}]}
{"op":"mcm","clk":"5321259756","pt":1646307749647,"mc":[{"id":"1.195532856","rc":[{"atb":[[2.6,0]],"id":41555102}],"con":true,"img":false}]}
{"op":"mcm","clk":"5321260263","pt":1646307755518,"mc":[{"id":"1.195532856","rc":[{"atb":[[2.56,6.36]],"id":43189001}],"con":true,"img":false}]}
{"op":"mcm","clk":"5321260293","pt":1646307755828,"mc":[{"id":"1.195532856","rc":[{"atb":[[2.54,0]],"id":41555102},{"atb":[[2.7,0]],"id":42609837}],"con":true,"img":false}]}
{"op":"mcm","clk":"5321260788","pt":1646307761855,"mc":[{"id":"1.195532856","rc":[{"atb":[[2.5,0]],"id":43189001}],"con":true,"img":false}]}
{"op":"mcm","clk":"5321261368","pt":1646307771163,"mc":[{"id":"1.195532856","rc":[{"atb":[[2.82,3.69]],"id":41555102}],"con":true,"img":false}]}
{"op":"mcm","clk":"5321261377","pt":1646307771266,"mc":[{"id":"1.195532856","rc":[{"atb":[[2.68,5.9]],"id":42609837}],"con":true,"img":false}]}
{"op":"mcm","clk":"5321261387","pt":1646307771576,"mc":[{"id":"1.195532856","rc":[{"atb":[[2.74,7.14]],"id":41555102},{"atb":[[2.58,0]],"id":42609837}],"con":true,"img":false}]}
{"op":"mcm","clk":"5321262290","pt":1646307783161,"mc":[{"id":"1.195532856","rc":[{"atb":[[2.62,4.15]],"id":43189001}],"con":true,"img":false}]}
{"op":"mcm","clk":"5321262635","pt":1646307787064,"mc":[{"id":"1.195532856","rc":[{"atb":[[2.56,0]],"id":43189001},{"spn":6.31,"spf":1.0,"id":43189001},{"atb":[[2.66,7.48]],"id":42609837}],"con":true,"img":false}]}
{"op":"mcm","clk":"5321263420","pt":1646307798192,"mc":[{"id":"1.195532856","rc":[{"atb":[[2.62,0]],"id":43189001}],"con":true,"img":false}]}
{"op":"mcm","clk":"5321263605","pt":1646307800803,"mc":[{"id":"1.195532856","rc":[{"atb":[[2.74,3.86]],"id":42609837}],"con":true,"img":false}]}
{"op":"mcm","clk":"5321263827","pt":1646307803714,"mc":[{"id":"1.195532856","rc":[{"atb":[[2.76,0]],"id":41555102}],"con":true,"img":false}]}
{"op":"mcm","clk":"5321264839","pt":1646307816019,"mc":[{"id":"1.195532856","rc":[{"atb":[[2.82,0]],"id":41555102}],"con":true,"img":false}]}
{"op":"mcm","clk":"5321264847","pt":1646307816121,"mc":[{"id":"1.195532856","rc":[{"atb":[[2.5,4.48]],"id":43189001}],"con":true,"img":false}]}
{"op":"mcm","clk":"5321265313","pt":1646307821139,"mc":[{"id":"1.195532856","rc":[{"atb":[[2.68,0]],"id":42609837}],"con":true,"img":false}]}
{"op":"mcm","clk":"5321265932","pt":1646307828018,"mc":[{"id":"1.195532856","rc":[{"atb":[[2.74,0]],"id":42609837}],"con":true,"img":false}]}
{"op":"mcm","clk":"5321266447","pt":1646307834160,"mc":[{"id":"1.195532856","rc":[{"atb":[[2.8,3.73]],"id":41555102}],"con":true,"img":false}]}
{"op":"mcm","clk":"5321267430","pt":1646307845913,"mc":[{"id":"1.195532856","rc":[{"atb":[[2.86,0]],"id":42931075},{"atb":[[2.54,0]],"id":39330606}],"con":true,"img":false}]}
{"op":"mcm","clk":"5321267749","pt":1646307849379,"mc":[{"id":"1.195532856","rc":[{"spn":6.25,"spf":1.0,"id":43189001},{"atb":[[2.94,5.77]],"id":42931075},{"atb":[[2.62,6.91]],"id":39330606}],"con":true,"img":false}]}
{"op":"mcm","clk":"5321267772","pt":1646307849587,"mc":[{"id":"1.195532856","rc":[{"atb":[[2.72,3.9]],"id":42609837}],"con":true,"img":false}]}
{"op":"mcm","clk":"5321267971","pt":1646307851707,"mc":[{"id":"1.195532856","rc":[{"atb":[[2.56,6.36]],"id":43189001}],"con":true,"img":false}]}
{"op":"mcm","clk":"5321268788","pt":1646307860989,"mc":[{"id":"1.195532856","rc":[{"atb":[[2.5,0]],"id":43189001}],"con":true,"img":false}]}
{"op":"mcm","clk":"5321269141","pt":1646307865032,"mc":[{"id":"1.195532856","rc":[{"atb":[[2.46,0]],"id":43189000}],"con":true,"img":false}]}
{"op":"mcm","clk":"5321269574","pt":1646307870426,"mc":[{"id":"1.195532856","rc":[{"atb":[[2.54,7.27]],"id":43189000}],"con":true,"img":false}]}
{"op":"mcm","clk":"5321270258","pt":1646307878835,"mc":[{"id":"1.195532856","rc":[{"atb":[[2.78,5.57]],"id":42609837}],"con":true,"img":false}]}
{"op":"mcm","clk":"5321270294","pt":1646307879147,"mc":[{"id":"1.195532856","rc":[{"atb":[[2.86,5.33]],"id":41555102}],"con":true,"img":false}]}
{"op":"mcm","clk":"5321270310","pt":1646307879308,"mc":[{"id":"1.195532856","rc":[{"atb":[[2.56,0]],"id":43189001}],"con":true,"img":false}]}
{"op":"mcm","clk":"5321270803","pt":1646307884960,"mc":[{"id":"1.195532856","rc":[{"atb":[[2.72,0]],"id":42609837}],"con":true,"img":false}]}
{"op":"mcm","clk":"5321271082","pt":1646307888175,"mc":[{"id":"1.195532856","rc":[{"atb":[[2.8,0]],"id":41555102}],"con":true,"img":false}]}
{"op":"mcm","clk":"5321271582","pt":1646307893935,"mc":[{"id":"1.195532856","rc":[{"atb":[[2.5,6.61]],"id":43189001}],"con":true,"img":false}]}
{"op":"mcm","clk":"5321272627","pt":1646307905882,"mc":[{"id":"1.195532856","rc":[{"atb":[[2.84,3.65]],"id":42609837}],"con":true,"img":false}]}
{"op":"mcm","clk":"5321273193","pt":1646307912307,"mc":[{"id":"1.195532856","rc":[{"atb":[[2.92,3.5]],"id":41555102}],"con":true,"img":false}]}
{"op":"mcm","clk":"5321273428","pt":1646307914706,"mc":[{"id":"1.195532856","rc":[{"atb":[[2.86,0]],"id":41555102},{"atb":[[2.78,0]],"id":42609837}],"con":true,"img":false}]}
{"op":"mcm","clk":"5321274061","pt":1646307921400,"mc":[{"id":"1.195532856","rc":[{"atb":[[2.92,0]],"id":41555102},{"atb":[[2.84,0]],"id":42609837}],"con":true,"img":false}]}
{"op":"mcm","clk":"5321274284","pt":1646307924091,"mc":[{"id":"1.195532856","rc":[{"atb":[[2.56,4.31]],"id":43189001}],"con":true,"img":false}]}
{"op":"mcm","clk":"5321274820","pt":1646307930286,"mc":[{"id":"1.195532856","rc":[{"atb":[[2.7,0]],"id":41555102}],"con":true,"img":false}]}
{"op":"mcm","clk":"5321275124","pt":1646307933522,"mc":[{"id":"1.195532856","rc":[{"atb":[[2.78,6.29]],"id":41555102}],"con":true,"img":false}]}
{"op":"mcm","clk":"5321275904","pt":1646307942235,"mc":[{"id":"1.195532856","rc":[{"atb":[[2.72,3.9]],"id":42609837}],"con":true,"img":false}]}
{"op":"mcm","clk":"5321276133","pt":1646307945022,"mc":[{"id":"1.195532856","rc":[{"atb":[[2.8,3.73]],"id":41555102}],"con":true,"img":false}]}
{"op":"mcm","clk":"5321276383","pt":1646307947761,"mc":[{"id":"1.195532856","rc":[{"atb":[[2.5,0]],"id":43189001}],"con":true,"img":false}]}
{"op":"mcm","clk":"5321276948","pt":1646307954443,"mc":[{"id":"1.195532856","rc":[{"atb":[[2.56,0]],"id":43189001}],"con":true,"img":false}]}
{"op":"mcm","clk":"5321277742","pt":1646307963652,"mc":[{"id":"1.195532856","rc":[{"atb":[[2.62,0]],"id":42609837}],"con":true,"img":false}]}
{"op":"mcm","clk":"5321278031","pt":1646307967152,"mc":[{"id":"1.195532856","rc":[{"atb":[[2.7,6.59]],"id":42609837}],"con":true,"img":false}]}
{"op":"mcm","clk":"5321278827","pt":1646307976577,"mc":[{"id":"1.195532856","rc":[{"spn":6.12,"spf":1.0,"id":43189001},{"atb":[[2.78,5.57]],"id":42609837}],"con":true,"img":false}]}
{"op":"mcm","clk":"5321279056","pt":1646307979061,"mc":[{"id":"1.195532856","rc":[{"atb":[[2.5,4.48]],"id":43189001}],"con":true,"img":false}]}
{"op":"mcm","clk":"5321279501","pt":1646307984385,"mc":[{"id":"1.195532856","rc":[{"atb":[[2.72,0]],"id":42609837}],"con":true,"img":false}]}
{"op":"mcm","clk":"5321280261","pt":1646307992714,"mc":[{"id":"1.195532856","rc":[{"atb":[[2.86,5.33]],"id":41555102}],"con":true,"img":false}]}
{"op":"mcm","clk":"5321289062","pt":1646308003049,"mc":[{"id":"1.195532856","rc":[{"atb":[[2.8,0]],"id":41555102}],"con":true,"img":false}]}
{"op":"mcm","clk":"5321289490","pt":1646308008345,"mc":[{"id":"1.195532856","rc":[{"atb":[[2.84,3.65]],"id":42609837}],"con":true,"img":false}]}
{"op":"mcm","clk":"5321289577","pt":1646308009332,"mc":[{"id":"1.195532856","rc":[{"atb":[[2.78,0]],"id":42609837}],"con":true,"img":false}]}
{"op":"mcm","clk":"5321290224","pt":1646308017343,"mc":[{"id":"1.195532856","rc":[{"atb":[[2.84,0]],"id":42609837}],"con":true,"img":false}]}
{"op":"mcm","clk":"5321290747","pt":1646308023988,"mc":[{"id":"1.195532856","rc":[{"atb":[[2.92,3.5]],"id":41555102}],"con":true,"img":false}]}
{"op":"mcm","clk":"5321290793","pt":1646308024575,"mc":[{"id":"1.195532856","rc":[{"atb":[[2.56,6.36]],"id":43189001},{"atb":[[2.86,0]],"id":41555102}],"con":true,"img":false}]}
{"op":"mcm","clk":"5321290813","pt":1646308024881,"mc":[{"id":"1.195532856","rc":[{"atb":[[2.76,5.63]],"id":42609837}],"con":true,"img":false}]}
{"op":"mcm","clk":"5321291760","pt":1646308035594,"mc":[{"id":"1.195532856","rc":[{"atb":[[2.5,0]],"id":43189001},{"atb":[[2.92,0]],"id":41555102}],"con":true,"img":false}]}
{"op":"mcm","clk":"5321291910","pt":1646308037298,"mc":[{"id":"1.195532856","rc":[{"spn":6.28,"spf":1.0,"id":43189001},{"atb":[[2.84,5.39]],"id":41555102}],"con":true,"img":false}]}
{"op":"mcm","clk":"5321291936","pt":1646308037568,"mc":[{"id":"1.195532856","rc":[{"atb":[[2.74,0]],"id":41555102},{"atb":[[2.66,0]],"id":42609837}],"con":true,"img":false}]}
{"op":"mcm","clk":"5321293420","pt":1646308054914,"mc":[{"id":"1.195532856","rc":[{"atb":[[2.82,6.82]],"id":41555102}],"con":true,"img":false}]}
{"op":"mcm","clk":"5321293459","pt":1646308055325,"mc":[{"id":"1.195532856","rc":[{"atb":[[2.74,7.14]],"id":42609837}],"con":true,"img":false}]}
{"op":"mcm","clk":"5321293495","pt":1646308055690,"mc":[{"id":"1.195532856","rc":[{"atb":[[2.56,0]],"id":43189001}],"con":true,"img":false}]}
{"op":"mcm","clk":"5321293604","pt":1646308056824,"mc":[{"id":"1.195532856","rc":[{"atb":[[2.82,3.69]],"id":42609837}],"con":true,"img":false}]}
{"op":"mcm","clk":"5321294415","pt":1646308065701,"mc":[{"id":"1.195532856","rc":[{"atb":[[2.9,3.54]],"id":41555102}],"con":true,"img":false}]}
{"op":"mcm","clk":"5321294773","pt":1646308069629,"mc":[{"id":"1.195532856","rc":[{"atb":[[2.5,6.61]],"id":43189001}],"con":true,"img":false}]}
{"op":"mcm","clk":"5321295952","pt":1646308082727,"mc":[{"id":"1.195532856","rc":[{"atb":[[2.84,0]],"id":41555102},{"atb":[[2.76,0]],"id":42609837}],"con":true,"img":false}]}
{"op":"mcm","clk":"5321295989","pt":1646308083045,"mc":[{"id":"1.195532856","rc":[{"atb":[[2.9,0]],"id":42931075},{"atb":[[2.58,0]],"id":39330606}],"con":true,"img":false}]}
{"op":"mcm","clk":"5321296525","pt":1646308089535,"mc":[{"id":"1.195532856","rc":[{"atb":[[2.9,0]],"id":41555102},{"atb":[[2.82,0]],"id":42609837}],"con":true,"img":false}]}
{"op":"mcm","clk":"5321297463","pt":1646308102274,"mc":[{"id":"1.195532856","rc":[{"atb":[[2.56,4.31]],"id":43189001}],"con":true,"img":false}]}
{"op":"mcm","clk":"5321297508","pt":1646308102686,"mc":[{"id":"1.195532856","rc":[{"atb":[[2.98,6.27]],"id":42931075}],"con":true,"img":false}]}
{"op":"mcm","clk":"5321297540","pt":1646308102996,"mc":[{"id":"1.195532856","rc":[{"atb":[[2.66,7.48]],"id":39330606}],"con":true,"img":false}]}
{"op":"mcm","clk":"5321298214","pt":1646308110696,"mc":[{"id":"1.195532856","rc":[{"atb":[[2.88,3.57]],"id":41555102},{"atb":[[2.8,3.73]],"id":42609837}],"con":true,"img":false}]}
{"op":"mcm","clk":"5321298653","pt":1646308116177,"mc":[{"id":"1.195532856","rc":[{"atb":[[2.5,0]],"id":43189000}],"con":true,"img":false}]}
{"op":"mcm","clk":"5321299752","pt":1646308130525,"mc":[{"id":"1.195532856","rc":[{"atb":[[2.58,7.86]],"id":43189000},{"atb":[[2.5,0]],"id":43189001}],"con":true,"img":false}]}
{"op":"mcm","clk":"5321300321","pt":1646308138125,"mc":[{"id":"1.195532856","rc":[{"atb":[[2.56,0]],"id":43189001}],"con":true,"img":false}]}
{"op":"mcm","clk":"5321300949","pt":1646308145657,"mc":[{"id":"1.195532856","rc":[{"atb":[[2.94,5.11]],"id":41555102},{"atb":[[2.86,5.33]],"id":42609837}],"con":true,"img":false}]}
{"op":"mcm","clk":"5321301752","pt":1646308156073,"mc":[{"id":"1.195532856","rc":[{"atb":[[2.88,0]],"id":41555102},{"atb":[[2.8,0]],"id":42609837}],"con":true,"img":false}]}
{"op":"mcm","clk":"5321301984","pt":1646308158873,"mc":[{"id":"1.195532856","rc":[{"atb":[[2.5,4.48]],"id":43189001}],"con":true,"img":false}]}
{"op":"mcm","clk":"5321303572","pt":1646308177082,"mc":[{"id":"1.195532856","rc":[{"spn":6.25,"spf":1.0,"id":43189001},{"atb":[[3,3.36]],"id":41555102}],"con":true,"img":false}]}
{"op":"mcm","clk":"5321303582","pt":1646308177185,"mc":[{"id":"1.195532856","rc":[{"atb":[[2.94,0]],"id":41555102},{"atb":[[2.92,3.5],[2.86,0]],"id":42609837}],"con":true,"img":false}]}
{"op":"mcm","clk":"5321304784","pt":1646308190127,"mc":[{"id":"1.195532856","rc":[{"atb":[[3,0]],"id":41555102},{"atb":[[2.92,0]],"id":42609837}],"con":true,"img":false}]}
{"op":"mcm","clk":"5321305230","pt":1646308194905,"mc":[{"id":"1.195532856","rc":[{"atb":[[2.76,5.63]],"id":42609837}],"con":true,"img":false}]}
{"op":"mcm","clk":"5321305264","pt":1646308195216,"mc":[{"id":"1.195532856","rc":[{"atb":[[2.84,5.39]],"id":41555102}],"con":true,"img":false}]}
{"op":"mcm","clk":"5321306536","pt":1646308209745,"mc":[{"id":"1.195532856","rc":[{"atb":[[2.7,0]],"id":42609837}],"con":true,"img":false}]}
{"op":"mcm","clk":"5321306548","pt":1646308209848,"mc":[{"id":"1.195532856","rc":[{"atb":[[2.56,6.36]],"id":43189001}],"con":true,"img":false}]}
{"op":"mcm","clk":"5321306805","pt":1646308212749,"mc":[{"id":"1.195532856","rc":[{"atb":[[2.8,6.22]],"id":42609837}],"con":true,"img":false}]}
{"op":"mcm","clk":"5321307350","pt":1646308218696,"mc":[{"id":"1.195532856","rc":[{"atb":[[2.5,0]],"id":43189001}],"con":true,"img":false}]}
{"op":"mcm","clk":"5321307871","pt":1646308224588,"mc":[{"id":"1.195532856","rc":[{"atb":[[2.9,3.54]],"id":41555102}],"con":true,"img":false}]}
{"op":"mcm","clk":"5321307886","pt":1646308224818,"mc":[{"id":"1.195532856","rc":[{"atb":[[2.82,3.69]],"id":42609837}],"con":true,"img":false}]}
{"op":"mcm","clk":"5321308600","pt":1646308233092,"mc":[{"id":"1.195532856","rc":[{"atb":[[2.56,0]],"id":43189001},{"atb":[[2.76,0]],"id":42609837}],"con":true,"img":false}]}
{"op":"mcm","clk":"5321309231","pt":1646308239619,"mc":[{"id":"1.195532856","rc":[{"spn":6.12,"spf":1.0,"id":43189001},{"atb":[[2.82,0]],"id":42609837}],"con":true,"img":false}]}
{"op":"mcm","clk":"5321309916","pt":1646308245713,"mc":[{"id":"1.195532856","rc":[{"atb":[[2.84,0]],"id":41555102}],"con":true,"img":false}]}
{"op":"mcm","clk":"5321310707","pt":1646308254612,"mc":[{"id":"1.195532856","rc":[{"atb":[[2.9,0]],"id":41555102}],"con":true,"img":false}]}
{"op":"mcm","clk":"5321311069","pt":1646308258244,"mc":[{"id":"1.195532856","rc":[{"atb":[[2.5,6.61]],"id":43189001}],"con":true,"img":false}]}
{"op":"mcm","clk":"5321311247","pt":1646308260413,"mc":[{"id":"1.195532856","rc":[{"atb":[[2.8,9.96]],"id":42609837}],"con":true,"img":false}]}
{"op":"mcm","clk":"5321312032","pt":1646308269536,"mc":[{"id":"1.195532856","rc":[{"atb":[[2.78,0]],"id":41555102}],"con":true,"img":false}]}
{"op":"mcm","clk":"5321312314","pt":1646308272644,"mc":[{"id":"1.195532856","rc":[{"atb":[[2.36,8.24]],"id":41555102}],"con":true,"img":false}]}
{"op":"mcm","clk":"5321312327","pt":1646308272845,"mc":[{"id":"1.195532856","rc":[{"atb":[[2.86,5.33]],"id":42609837}],"con":true,"img":false}]}
{"op":"mcm","clk":"5321312549","pt":1646308275633,"mc":[{"id":"1.195532856","rc":[{"atb":[[2.88,3.57]],"id":41555102}],"con":true,"img":false}]}
{"op":"mcm","clk":"5321313110","pt":1646308281545,"mc":[{"id":"1.195532856","rc":[{"atb":[[2.8,6.22]],"id":42609837}],"con":true,"img":false}]}
{"op":"mcm","clk":"5321313708","pt":1646308287563,"mc":[{"id":"1.195532856","rc":[{"atb":[[2.56,4.31]],"id":43189001}],"con":true,"img":false}]}
{"op":"mcm","clk":"5321314803","pt":1646308300182,"mc":[{"id":"1.195532856","rc":[{"spn":6.28,"spf":1.0,"id":43189001},{"atb":[[2.74,0]],"id":42609837}],"con":true,"img":false}]}
{"op":"mcm","clk":"5321314848","pt":1646308300694,"mc":[{"id":"1.195532856","rc":[{"atb":[[2.92,3.5]],"id":42609837}],"con":true,"img":false}]}
{"op":"mcm","clk":"5321316250","pt":1646308317705,"mc":[{"id":"1.195532856","rc":[{"atb":[[2.94,0]],"id":42931075},{"atb":[[2.62,0]],"id":39330606}],"con":true,"img":false}]}
{"op":"mcm","clk":"5321316577","pt":1646308321623,"mc":[{"id":"1.195532856","rc":[{"atb":[[2.96,6.33]],"id":42609837}],"con":true,"img":false}]}
{"op":"mcm","clk":"5321316612","pt":1646308321937,"mc":[{"id":"1.195532856","rc":[{"atb":[[2.94,5.11]],"id":41555102},{"atb":[[2.7,6.59]],"id":39330606}],"con":true,"img":false}]}
{"op":"mcm","clk":"5321316621","pt":1646308322039,"mc":[{"id":"1.195532856","rc":[{"atb":[[3.05,5.47]],"id":42931075}],"con":true,"img":false}]}
{"op":"mcm","clk":"5321316633","pt":1646308322139,"mc":[{"id":"1.195532856","rc":[{"atb":[[2.5,0]],"id":43189001}],"con":true,"img":false}]}
{"op":"mcm","clk":"5321317534","pt":1646308332825,"mc":[{"id":"1.195532856","rc":[{"atb":[[2.56,0]],"id":43189001},{"atb":[[2.88,0]],"id":41555102},{"atb":[[2.92,0]],"id":42609837}],"con":true,"img":false}]}
{"op":"mcm","clk":"5321319224","pt":1646308351759,"mc":[{"id":"1.195532856","rc":[{"atb":[[2.94,0]],"id":41555102}],"con":true,"img":false}]}
{"op":"mcm","clk":"5321319406","pt":1646308353766,"mc":[{"id":"1.195532856","rc":[{"atb":[[2.54,0]],"id":43189000}],"con":true,"img":false}]}
{"op":"mcm","clk":"5321319431","pt":1646308354075,"mc":[{"id":"1.195532856","rc":[{"atb":[[3,3.36]],"id":42609837}],"con":true,"img":false}]}
{"op":"mcm","clk":"5321319439","pt":1646308354125,"mc":[{"id":"1.195532856","rc":[{"atb":[[2.5,4.48]],"id":43189001}],"con":true,"img":false}]}
{"op":"mcm","clk":"5321319720","pt":1646308357196,"mc":[{"id":"1.195532856","rc":[{"atb":[[2.62,6.91]],"id":43189000}],"con":true,"img":false}]}
{"op":"mcm","clk":"5321320806","pt":1646308368536,"mc":[{"id":"1.195532856","rc":[{"spn":6.25,"spf":1.0,"id":43189001},{"atb":[[2.4,7.09]],"id":41555102}],"con":true,"img":false}]}
{"op":"mcm","clk":"5321320818","pt":1646308368640,"mc":[{"id":"1.195532856","rc":[{"atb":[[2.86,0]],"id":42609837}],"con":true,"img":false}]}
{"op":"mcm","clk":"5321321895","pt":1646308380747,"mc":[{"id":"1.195532856","rc":[{"atb":[[2.88,3.57]],"id":41555102}],"con":true,"img":false}]}
{"op":"mcm","clk":"5321323978","pt":1646308402578,"mc":[{"id":"1.195532856","rc":[{"atb":[[3.05,4.83]],"id":42609837}],"con":true,"img":false}]}
{"op":"mcm","clk":"5321323996","pt":1646308402787,"mc":[{"id":"1.195532856","rc":[{"atb":[[2.4,0]],"id":41555102}],"con":true,"img":false}]}
{"op":"mcm","clk":"5321324008","pt":1646308402890,"mc":[{"id":"1.195532856","rc":[{"atb":[[2.56,6.36]],"id":43189001}],"con":true,"img":false}]}
{"op":"mcm","clk":"5321324780","pt":1646308411078,"mc":[{"id":"1.195532856","rc":[{"atb":[[2.5,0]],"id":43189001},{"atb":[[3,0]],"id":42609837}],"con":true,"img":false}]}
{"op":"mcm","clk":"5321325499","pt":1646308418393,"mc":[{"id":"1.195532856","rc":[{"atb":[[2.94,5.11]],"id":41555102}],"con":true,"img":false}]}
{"op":"mcm","clk":"5321326196","pt":1646308426117,"mc":[{"id":"1.195532856","rc":[{"atb":[[2.88,0]],"id":41555102}],"con":true,"img":false}]}
{"op":"mcm","clk":"5321326798","pt":1646308431935,"mc":[{"id":"1.195532856","rc":[{"spn":6.28,"spf":1.0,"id":43189001},{"atb":[[3.1,3.2]],"id":42609837}],"con":true,"img":false}]}
{"op":"mcm","clk":"5321326811","pt":1646308432029,"mc":[{"id":"1.195532856","rc":[{"atb":[[2.62,4.15]],"id":43189001}],"con":true,"img":false}]}
{"op":"mcm","clk":"5321326873","pt":1646308432710,"mc":[{"id":"1.195532856","rc":[{"atb":[[2.56,0]],"id":43189001},{"atb":[[3.05,0]],"id":42609837}],"con":true,"img":false}]}
{"op":"mcm","clk":"5321327582","pt":1646308440962,"mc":[{"id":"1.195532856","rc":[{"atb":[[2.62,0]],"id":43189001},{"atb":[[3.1,0]],"id":42609837}],"con":true,"img":false}]}
{"op":"mcm","clk":"5321328651","pt":1646308447162,"mc":[{"id":"1.195532856","rc":[{"atb":[[3,3.36]],"id":41555102}],"con":true,"img":false}]}
{"op":"mcm","clk":"5321328807","pt":1646308448566,"mc":[{"id":"1.195532856","rc":[{"atb":[[2.86,5.33]],"id":42609837}],"con":true,"img":false}]}
{"op":"mcm","clk":"5321328815","pt":1646308448668,"mc":[{"id":"1.195532856","rc":[{"atb":[[2.5,6.61]],"id":43189001}],"con":true,"img":false}]}
{"op":"mcm","clk":"5321328850","pt":1646308448981,"mc":[{"id":"1.195532856","rc":[{"atb":[[2.94,0]],"id":41555102}],"con":true,"img":false}]}
{"op":"mcm","clk":"5321329514","pt":1646308456103,"mc":[{"id":"1.195532856","rc":[{"atb":[[3,0]],"id":41555102}],"con":true,"img":false}]}
{"op":"mcm","clk":"5321330075","pt":1646308462076,"mc":[{"id":"1.195532856","rc":[{"atb":[[3,3.36]],"id":42609837}],"con":true,"img":false}]}
{"op":"mcm","clk":"5321330219","pt":1646308463690,"mc":[{"id":"1.195532856","rc":[{"atb":[[2.4,7.09]],"id":41555102}],"con":true,"img":false}]}
{"op":"mcm","clk":"5321330331","pt":1646308464793,"mc":[{"id":"1.195532856","rc":[{"atb":[[2.8,0]],"id":42609837}],"con":true,"img":false}]}
{"op":"mcm","clk":"5321330659","pt":1646308468100,"mc":[{"id":"1.195532856","rc":[{"atb":[[3,8.96]],"id":42609837}],"con":true,"img":false}]}
{"op":"mcm","clk":"5321331396","pt":1646308477022,"mc":[{"id":"1.195532856","rc":[{"atb":[[2.56,4.31]],"id":43189001}],"con":true,"img":false}]}
{"op":"mcm","clk":"5321331627","pt":1646308479514,"mc":[{"id":"1.195532856","rc":[{"atb":[[2.86,0]],"id":42609837}],"con":true,"img":false}]}
{"op":"mcm","clk":"5321331685","pt":1646308480129,"mc":[{"id":"1.195532856","rc":[{"atb":[[2.88,3.57]],"id":41555102}],"con":true,"img":false}]}
{"op":"mcm","clk":"5321333713","pt":1646308496758,"mc":[{"id":"1.195532856","rc":[{"atb":[[3.05,4.83]],"id":42609837}],"con":true,"img":false}]}
{"op":"mcm","clk":"5321334640","pt":1646308504604,"mc":[{"id":"1.195532856","rc":[{"atb":[[3,5.6]],"id":42609837}],"con":true,"img":false}]}
{"op":"mcm","clk":"5321335418","pt":1646308510840,"mc":[{"id":"1.195532856","rc":[{"atb":[[2.5,0]],"id":43189001},{"atb":[[2.4,0]],"id":41555102}],"con":true,"img":false}]}
{"op":"mcm","clk":"5321335429","pt":1646308510940,"mc":[{"id":"1.195532856","rc":[{"atb":[[2.82,0]],"id":41555102}],"con":true,"img":false}]}
{"op":"mcm","clk":"5321336422","pt":1646308519073,"mc":[{"id":"1.195532856","rc":[{"atb":[[2.56,0]],"id":43189001},{"atb":[[2.88,0]],"id":41555102}],"con":true,"img":false}]}
{"op":"mcm","clk":"5321337062","pt":1646308525762,"mc":[{"id":"1.195532856","rc":[{"atb":[[3.1,3.2]],"id":42609837}],"con":true,"img":false}]}
{"op":"mcm","clk":"5321337154","pt":1646308526690,"mc":[{"id":"1.195532856","rc":[{"atb":[[2.4,8.87]],"id":41555102}],"con":true,"img":false}]}
{"op":"mcm","clk":"5321338610","pt":1646308539091,"mc":[{"id":"1.195532856","rc":[{"atb":[[2.5,4.48]],"id":43189001}],"con":true,"img":false}]}
{"op":"mcm","clk":"5321340769","pt":1646308556618,"mc":[{"id":"1.195532856","rc":[{"atb":[[2.98,0]],"id":42931075},{"atb":[[2.66,0]],"id":39330606}],"con":true,"img":false}]}
{"op":"mcm","clk":"5321340813","pt":1646308557026,"mc":[{"id":"1.195532856","rc":[{"spn":6.25,"spf":1.0,"id":43189001},{"atb":[[2.4,15.96]],"id":41555102}],"con":true,"img":false}]}
{"op":"mcm","clk":"5321340936","pt":1646308558019,"mc":[{"id":"1.195532856","rc":[{"atb":[[2.44,4.67]],"id":41555102}],"con":true,"img":false}]}
{"op":"mcm","clk":"5321342662","pt":1646308572808,"mc":[{"id":"1.195532856","rc":[{"atb":[[2.56,6.36]],"id":43189001},{"atb":[[3.15,5.78]],"id":42931075}],"con":true,"img":false}]}
{"op":"mcm","clk":"5321342758","pt":1646308573645,"mc":[{"id":"1.195532856","rc":[{"atb":[[2.96,0]],"id":42609837}],"con":true,"img":false}]}
{"op":"mcm","clk":"5321342772","pt":1646308573746,"mc":[{"id":"1.195532856","rc":[{"atb":[[2.74,7.14]],"id":39330606}],"con":true,"img":false}]}
{"op":"mcm","clk":"5321343615","pt":1646308582355,"mc":[{"id":"1.195532856","rc":[{"atb":[[2.5,0]],"id":43189001}],"con":true,"img":false}]}
{"op":"mcm","clk":"5321344507","pt":1646308590986,"mc":[{"id":"1.195532856","rc":[{"atb":[[2.4,8.87]],"id":41555102}],"con":true,"img":false}]}
{"op":"mcm","clk":"5321344530","pt":1646308591298,"mc":[{"id":"1.195532856","rc":[{"atb":[[3.1,9.12]],"id":42609837}],"con":true,"img":false}]}
{"op":"mcm","clk":"5321345385","pt":1646308600572,"mc":[{"id":"1.195532856","rc":[{"atb":[[2.36,0]],"id":41555102},{"atb":[[3.1,5.91]],"id":42609837}],"con":true,"img":false}]}
{"op":"mcm","clk":"5321345674","pt":1646308603624,"mc":[{"id":"1.195532856","rc":[{"atb":[[2.44,12.45]],"id":41555102}],"con":true,"img":false}]}
{"op":"mcm","clk":"5321345678","pt":1646308603675,"mc":[{"id":"1.195532856","rc":[{"atb":[[2.56,0],[2.62,4.15]],"id":43189001}],"con":true,"img":false}]}
{"op":"mcm","clk":"5321345691","pt":1646308603795,"mc":[{"id":"1.195532856","rc":[{"atb":[[2.48,6.7]],"id":41555102}],"con":true,"img":false}]}
{"op":"mcm","clk":"5321345716","pt":1646308603991,"mc":[{"id":"1.195532856","rc":[{"atb":[[2.58,0]],"id":43189000}],"con":true,"img":false}]}
{"op":"mcm","clk":"5321346408","pt":1646308612244,"mc":[{"id":"1.195532856","rc":[{"atb":[[2.62,0]],"id":43189001},{"atb":[[2.44,7.78]],"id":41555102}],"con":true,"img":false}]}
{"op":"mcm","clk":"5321347006","pt":1646308619611,"mc":[{"id":"1.195532856","rc":[{"spn":6.12,"spf":1.0,"id":43189001},{"atb":[[3.15,3.13]],"id":42609837}],"con":true,"img":false}]}
{"op":"mcm","clk":"5321347076","pt":1646308620450,"mc":[{"id":"1.195532856","rc":[{"atb":[[2.66,7.48]],"id":43189000}],"con":true,"img":false}]}
{"op":"mcm","clk":"5321347108","pt":1646308620722,"mc":[{"id":"1.195532856","rc":[{"atb":[[2.5,6.61]],"id":43189001}],"con":true,"img":false}]}
{"op":"mcm","clk":"5321348305","pt":1646308633470,"mc":[{"id":"1.195532856","rc":[{"atb":[[2.52,4.42]],"id":41555102}],"con":true,"img":false}]}
{"op":"mcm","clk":"5321349706","pt":1646308651360,"mc":[{"id":"1.195532856","rc":[{"atb":[[2.56,4.31]],"id":43189001}],"con":true,"img":false}]}
{"op":"mcm","clk":"5321350146","pt":1646308656395,"mc":[{"id":"1.195532856","rc":[{"atb":[[2.48,0]],"id":41555102}],"con":true,"img":false}]}
{"op":"mcm","clk":"5321350823","pt":1646308664186,"mc":[{"id":"1.195532856","rc":[{"atb":[[2.52,0]],"id":41555102}],"con":true,"img":false}]}
{"op":"mcm","clk":"5321351740","pt":1646308674037,"mc":[{"id":"1.195532856","rc":[{"atb":[[2.5,0]],"id":43189001}],"con":true,"img":false}]}
{"op":"mcm","clk":"5321352383","pt":1646308681323,"mc":[{"id":"1.195532856","rc":[{"atb":[[2.56,0]],"id":43189001}],"con":true,"img":false}]}
{"op":"mcm","clk":"5321352648","pt":1646308684645,"mc":[{"id":"1.195532856","rc":[{"atb":[[2.44,12.45]],"id":41555102}],"con":true,"img":false}]}
{"op":"mcm","clk":"5321354160","pt":1646308702857,"mc":[{"id":"1.195532856","rc":[{"atb":[[2.5,4.48]],"id":43189001}],"con":true,"img":false}]}
{"op":"mcm","clk":"5321354229","pt":1646308703737,"mc":[{"id":"1.195532856","rc":[{"atb":[[2.48,6.7]],"id":41555102}],"con":true,"img":false}]}
{"op":"mcm","clk":"5321354867","pt":1646308711875,"mc":[{"id":"1.195532856","rc":[{"atb":[[2.44,7.78]],"id":41555102}],"con":true,"img":false}]}
{"op":"mcm","clk":"5321356982","pt":1646308732704,"mc":[{"id":"1.195532856","rc":[{"atb":[[2.52,4.42]],"id":41555102}],"con":true,"img":false}]}
{"op":"mcm","clk":"5321358431","pt":1646308750335,"mc":[{"id":"1.195532856","rc":[{"atb":[[2.56,6.36]],"id":43189001},{"spn":6.28,"spf":1.0,"id":43189001}],"con":true,"img":false}]}
{"op":"mcm","clk":"5321358458","pt":1646308750647,"mc":[{"id":"1.195532856","rc":[{"atb":[[2.48,0]],"id":41555102}],"con":true,"img":false}]}
{"op":"mcm","clk":"5321359228","pt":1646308759557,"mc":[{"id":"1.195532856","rc":[{"atb":[[2.5,0]],"id":43189001},{"atb":[[2.52,0]],"id":41555102}],"con":true,"img":false}]}
{"op":"mcm","clk":"5321360958","pt":1646308778592,"mc":[{"id":"1.195532856","rc":[{"atb":[[2.56,0]],"id":43189001}],"con":true,"img":false}]}
{"op":"mcm","clk":"5321361132","pt":1646308780498,"mc":[{"id":"1.195532856","rc":[{"atb":[[2.44,12.45]],"id":41555102}],"con":true,"img":false}]}
{"op":"mcm","clk":"5321362009","pt":1646308790005,"mc":[{"id":"1.195532856","rc":[{"atb":[[3.05,0]],"id":42931075},{"atb":[[2.7,0]],"id":39330606}],"con":true,"img":false}]}
{"op":"mcm","clk":"5321362289","pt":1646308793014,"mc":[{"id":"1.195532856","rc":[{"atb":[[3.25,4.98]],"id":42931075}],"con":true,"img":false}]}
{"op":"mcm","clk":"5321362316","pt":1646308793314,"mc":[{"id":"1.195532856","rc":[{"atb":[[2.78,6.29]],"id":39330606}],"con":true,"img":false}]}
{"op":"mcm","clk":"5321362530","pt":1646308795739,"mc":[{"id":"1.195532856","rc":[{"atb":[[2.5,6.61]],"id":43189001}],"con":true,"img":false}]}
{"op":"mcm","clk":"5321362546","pt":1646308796046,"mc":[{"id":"1.195532856","rc":[{"atb":[[2.48,6.7]],"id":41555102}],"con":true,"img":false}]}
{"op":"mcm","clk":"5321363469","pt":1646308805539,"mc":[{"id":"1.195532856","rc":[{"atb":[[2.44,7.78]],"id":41555102}],"con":true,"img":false}]}
{"op":"mcm","clk":"5321364009","pt":1646308811160,"mc":[{"id":"1.195532856","rc":[{"spn":6.25,"spf":1.0,"id":43189001},{"atb":[[3,0]],"id":42609837}],"con":true,"img":false}]}
{"op":"mcm","clk":"5321364115","pt":1646308812454,"mc":[{"id":"1.195532856","rc":[{"atb":[[2.4,0]],"id":41555102}],"con":true,"img":false}]}
{"op":"mcm","clk":"5321364355","pt":1646308814942,"mc":[{"id":"1.195532856","rc":[{"atb":[[2.38,8.12]],"id":42609837}],"con":true,"img":false}]}
{"op":"mcm","clk":"5321365368","pt":1646308826367,"mc":[{"id":"1.195532856","rc":[{"atb":[[2.52,4.42]],"id":41555102}],"con":true,"img":false}]}
{"op":"mcm","clk":"5321365378","pt":1646308826469,"mc":[{"id":"1.195532856","rc":[{"atb":[[2.56,4.31]],"id":43189001}],"con":true,"img":false}]}
{"op":"mcm","clk":"5321365395","pt":1646308826672,"mc":[{"id":"1.195532856","rc":[{"atb":[[2.48,15.1]],"id":41555102}],"con":true,"img":false}]}
{"op":"mcm","clk":"5321365405","pt":1646308826783,"mc":[{"id":"1.195532856","rc":[{"atb":[[3.05,0]],"id":42609837}],"con":true,"img":false}]}
{"op":"mcm","clk":"5321366469","pt":1646308837790,"mc":[{"id":"1.195532856","rc":[{"atb":[[2.62,0]],"id":43189000},{"atb":[[2.44,0]],"id":41555102}],"con":true,"img":false}]}
{"op":"mcm","clk":"5321366771","pt":1646308841201,"mc":[{"id":"1.195532856","rc":[{"atb":[[2.7,6.59]],"id":43189000},{"atb":[[2.52,11.79]],"id":41555102}],"con":true,"img":false}]}
{"op":"mcm","clk":"5321368361","pt":1646308859539,"mc":[{"id":"1.195532856","rc":[{"atb":[[2.5,0]],"id":43189001},{"atb":[[2.48,8.4]],"id":41555102}],"con":true,"img":false}]}
{"op":"mcm","clk":"5321368375","pt":1646308859749,"mc":[{"id":"1.195532856","rc":[{"atb":[[2.42,6.99]],"id":42609837}],"con":true,"img":false}]}
{"op":"mcm","clk":"5321369363","pt":1646308871854,"mc":[{"id":"1.195532856","rc":[{"atb":[[2.56,0]],"id":43189001},{"spn":6.12,"spf":1.0,"id":43189001}],"con":true,"img":false}]}
{"op":"mcm","clk":"5321369812","pt":1646308877199,"mc":[{"id":"1.195532856","rc":[{"atb":[[2.58,6.28]],"id":41555102}],"con":true,"img":false}]}
{"op":"mcm","clk":"5321370885","pt":1646308889536,"mc":[{"id":"1.195532856","rc":[{"atb":[[2.52,7.37]],"id":41555102}],"con":true,"img":false}]}
{"op":"mcm","clk":"5321370916","pt":1646308889843,"mc":[{"id":"1.195532856","rc":[{"atb":[[2.5,4.48]],"id":43189001}],"con":true,"img":false}]}
{"op":"mcm","clk":"5321372610","pt":1646308910270,"mc":[{"id":"1.195532856","rc":[{"atb":[[2.64,4.1]],"id":41555102}],"con":true,"img":false}]}
{"op":"mcm","clk":"5321380236","pt":1646309002755,"mc":[{"id":"1.195532856","rc":[{"atb":[[2.56,6.36]],"id":43189001},{"spn":6.28,"spf":1.0,"id":43189001}],"con":true,"img":false}]}
{"op":"mcm","clk":"5321380755","pt":1646309009339,"mc":[{"id":"1.195532856","rc":[{"atb":[[2.5,0]],"id":43189001}],"con":true,"img":false}]}
{"op":"mcm","clk":"5321381921","pt":1646309023050,"mc":[{"id":"1.195532856","rc":[{"atb":[[2.58,0]],"id":41555102}],"con":true,"img":false}]}
{"op":"mcm","clk":"5321382526","pt":1646309030404,"mc":[{"id":"1.195532856","rc":[{"atb":[[2.62,4.15]],"id":43189001},{"atb":[[2.64,0]],"id":41555102}],"con":true,"img":false}]}
{"op":"mcm","clk":"5321383294","pt":1646309039504,"mc":[{"id":"1.195532856","rc":[{"atb":[[2.56,0]],"id":43189001}],"con":true,"img":false}]}
{"op":"mcm","clk":"5321383321","pt":1646309039767,"mc":[{"id":"1.195532856","rc":[{"atb":[[3.15,0]],"id":42931075},{"atb":[[2.74,0]],"id":39330606}],"con":true,"img":false}]}
{"op":"mcm","clk":"5321384137","pt":1646309049786,"mc":[{"id":"1.195532856","rc":[{"atb":[[2.52,11.79]],"id":41555102}],"con":true,"img":false}]}
{"op":"mcm","clk":"5321384146","pt":1646309049885,"mc":[{"id":"1.195532856","rc":[{"atb":[[2.62,0]],"id":43189001}],"con":true,"img":false}]}
{"op":"mcm","clk":"5321384595","pt":1646309056222,"mc":[{"id":"1.195532856","rc":[{"atb":[[3.1,0]],"id":42609837}],"con":true,"img":false}]}
{"op":"mcm","clk":"5321384636","pt":1646309056739,"mc":[{"id":"1.195532856","rc":[{"atb":[[3.35,5.28]],"id":42931075}],"con":true,"img":false}]}
{"op":"mcm","clk":"5321384666","pt":1646309057102,"mc":[{"id":"1.195532856","rc":[{"atb":[[2.82,6.82]],"id":39330606}],"con":true,"img":false}]}
{"op":"mcm","clk":"5321385266","pt":1646309064422,"mc":[{"id":"1.195532856","rc":[{"spn":6.12,"spf":1.0,"id":43189001},{"atb":[[3.15,0]],"id":42609837}],"con":true,"img":false}]}
{"op":"mcm","clk":"5321385689","pt":1646309069645,"mc":[{"id":"1.195532856","rc":[{"atb":[[2.5,4.48]],"id":43189001}],"con":true,"img":false}]}
{"op":"mcm","clk":"5321386832","pt":1646309084205,"mc":[{"id":"1.195532856","rc":[{"atb":[[2.46,4.6]],"id":42609837}],"con":true,"img":false}]}
{"op":"mcm","clk":"5321387789","pt":1646309096331,"mc":[{"id":"1.195532856","rc":[{"atb":[[2.38,0]],"id":42609837}],"con":true,"img":false}]}
{"op":"mcm","clk":"5321388047","pt":1646309099517,"mc":[{"id":"1.195532856","rc":[{"atb":[[2.46,12.27]],"id":42609837}],"con":true,"img":false}]}
{"op":"mcm","clk":"5321400182","pt":1646309242153,"mc":[{"id":"1.195532856","rc":[{"spn":6.25,"spf":1.0,"id":43189001},{"atb":[[2.58,6.28]],"id":41555102}],"con":true,"img":false}]}
{"op":"mcm","clk":"5321400207","pt":1646309242415,"mc":[{"id":"1.195532856","rc":[{"atb":[[2.66,0]],"id":43189000},{"atb":[[2.48,0]],"id":41555102}],"con":true,"img":false}]}
{"op":"mcm","clk":"5321400247","pt":1646309242931,"mc":[{"id":"1.195532856","rc":[{"atb":[[2.5,8.28]],"id":42609837}],"con":true,"img":false}]}
{"op":"mcm","clk":"5321400442","pt":1646309245427,"mc":[{"id":"1.195532856","rc":[{"atb":[[2.56,7.96]],"id":41555102}],"con":true,"img":false}]}
{"op":"mcm","clk":"5321400449","pt":1646309245529,"mc":[{"id":"1.195532856","rc":[{"atb":[[2.74,7.14]],"id":43189000}],"con":true,"img":false}]}
{"op":"mcm","clk":"5321400551","pt":1646309247029,"mc":[{"id":"1.195532856","rc":[{"atb":[[2.52,4.42]],"id":41555102}],"con":true,"img":false}]}
{"op":"mcm","clk":"5321400968","pt":1646309252759,"mc":[{"id":"1.195532856","rc":[{"atb":[[2.62,6.91]],"id":41555102}],"con":true,"img":false}]}
{"op":"mcm","clk":"5321400989","pt":1646309253022,"mc":[{"id":"1.195532856","rc":[{"atb":[[2.52,0]],"id":41555102},{"atb":[[2.46,7.67]],"id":42609837}],"con":true,"img":false}]}
{"op":"mcm","clk":"5321402520","pt":1646309270084,"mc":[{"id":"1.195532856","rc":[{"atb":[[2.42,0]],"id":42609837}],"con":true,"img":false}]}
{"op":"mcm","clk":"5321402561","pt":1646309270498,"mc":[{"id":"1.195532856","rc":[{"atb":[[2.56,6.36]],"id":43189001}],"con":true,"img":false}]}
{"op":"mcm","clk":"5321402813","pt":1646309273496,"mc":[{"id":"1.195532856","rc":[{"atb":[[3.25,0]],"id":42931075},{"atb":[[2.78,0]],"id":39330606}],"con":true,"img":false}]}
{"op":"mcm","clk":"5321402856","pt":1646309273976,"mc":[{"id":"1.195532856","rc":[{"atb":[[2.56,4.31]],"id":42609837}],"con":true,"img":false}]}
{"op":"mcm","clk":"5321402867","pt":1646309274081,"mc":[{"id":"1.195532856","rc":[{"atb":[[2.64,4.1]],"id":41555102}],"con":true,"img":false}]}
{"op":"mcm","clk":"5321403130","pt":1646309277004,"mc":[{"id":"1.195532856","rc":[{"atb":[[3.45,4.57]],"id":42931075}],"con":true,"img":false}]}
{"op":"mcm","clk":"5321403149","pt":1646309277205,"mc":[{"id":"1.195532856","rc":[{"atb":[[2.86,6.02]],"id":39330606}],"con":true,"img":false}]}
{"op":"mcm","clk":"5321403606","pt":1646309282621,"mc":[{"id":"1.195532856","rc":[{"atb":[[2.5,0]],"id":43189001}],"con":true,"img":false}]}
{"op":"mcm","clk":"5321405121","pt":1646309300922,"mc":[{"id":"1.195532856","rc":[{"atb":[[2.58,0]],"id":41555102}],"con":true,"img":false}]}
{"op":"mcm","clk":"5321405131","pt":1646309301026,"mc":[{"id":"1.195532856","rc":[{"atb":[[2.62,4.15]],"id":43189001}],"con":true,"img":false}]}
{"op":"mcm","clk":"5321405900","pt":1646309309760,"mc":[{"id":"1.195532856","rc":[{"spn":6.31,"spf":1.0,"id":43189001},{"atb":[[2.64,0]],"id":41555102}],"con":true,"img":false}]}
{"op":"mcm","clk":"5321406529","pt":1646309317489,"mc":[{"id":"1.195532856","rc":[{"atb":[[2.56,0]],"id":43189001}],"con":true,"img":false}]}
{"op":"mcm","clk":"5321407216","pt":1646309324964,"mc":[{"id":"1.195532856","rc":[{"atb":[[2.62,0]],"id":43189001}],"con":true,"img":false}]}
{"op":"mcm","clk":"5321407767","pt":1646309330888,"mc":[{"id":"1.195532856","rc":[{"atb":[[2.62,11.07]],"id":41555102}],"con":true,"img":false}]}
{"op":"mcm","clk":"5321407886","pt":1646309332185,"mc":[{"id":"1.195532856","rc":[{"atb":[[2.62,6.13]],"id":42609837}],"con":true,"img":false}]}
{"op":"mcm","clk":"5321408506","pt":1646309339923,"mc":[{"id":"1.195532856","rc":[{"atb":[[2.56,0]],"id":42609837}],"con":true,"img":false}]}
{"op":"mcm","clk":"5321409077","pt":1646309347114,"mc":[{"id":"1.195532856","rc":[{"atb":[[2.68,5.9]],"id":41555102}],"con":true,"img":false}]}
{"op":"mcm","clk":"5321409218","pt":1646309348790,"mc":[{"id":"1.195532856","rc":[{"atb":[[2.5,4.48]],"id":43189001}],"con":true,"img":false}]}
{"op":"mcm","clk":"5321409678","pt":1646309354912,"mc":[{"id":"1.195532856","rc":[{"atb":[[2.62,6.91]],"id":41555102}],"con":true,"img":false}]}
{"op":"mcm","clk":"5321409999","pt":1646309358722,"mc":[{"id":"1.195532856","rc":[{"atb":[[2.68,4]],"id":42609837}],"con":true,"img":false}]}
{"op":"mcm","clk":"5321410301","pt":1646309362398,"mc":[{"id":"1.195532856","rc":[{"atb":[[2.62,0]],"id":42609837}],"con":true,"img":false}]}
{"op":"mcm","clk":"5321411032","pt":1646309373012,"mc":[{"id":"1.195532856","rc":[{"spn":6.25,"spf":1.0,"id":43189001},{"atb":[[2.68,0]],"id":42609837}],"con":true,"img":false}]}
{"op":"mcm","clk":"5321411228","pt":1646309375953,"mc":[{"id":"1.195532856","rc":[{"atb":[[2.74,3.86]],"id":41555102}],"con":true,"img":false}]}
{"op":"mcm","clk":"5321412096","pt":1646309389545,"mc":[{"id":"1.195532856","rc":[{"atb":[[2.68,0]],"id":41555102}],"con":true,"img":false}]}
{"op":"mcm","clk":"5321412104","pt":1646309389656,"mc":[{"id":"1.195532856","rc":[{"atb":[[2.56,6.36]],"id":43189001}],"con":true,"img":false}]}
{"op":"mcm","clk":"5321412176","pt":1646309390743,"mc":[{"id":"1.195532856","rc":[{"atb":[[2.56,4.31]],"id":42609837}],"con":true,"img":false}]}
{"op":"mcm","clk":"5321412570","pt":1646309397039,"mc":[{"id":"1.195532856","rc":[{"atb":[[2.5,0]],"id":43189001},{"atb":[[2.74,0]],"id":41555102}],"con":true,"img":false}]}
{"op":"mcm","clk":"5321414004","pt":1646309417887,"mc":[{"id":"1.195532856","rc":[{"atb":[[2.62,4.15]],"id":43189001},{"atb":[[2.62,11.07]],"id":41555102}],"con":true,"img":false}]}
{"op":"mcm","clk":"5321414103","pt":1646309419280,"mc":[{"id":"1.195532856","rc":[{"atb":[[2.56,0]],"id":43189001}],"con":true,"img":false}]}
{"op":"mcm","clk":"5321414651","pt":1646309426900,"mc":[{"id":"1.195532856","rc":[{"atb":[[2.62,0]],"id":43189001}],"con":true,"img":false}]}
{"op":"mcm","clk":"5321414960","pt":1646309431396,"mc":[{"id":"1.195532856","rc":[{"atb":[[2.68,5.9]],"id":41555102}],"con":true,"img":false}]}
{"op":"mcm","clk":"5321414968","pt":1646309431500,"mc":[{"id":"1.195532856","rc":[{"atb":[[2.62,6.13]],"id":42609837}],"con":true,"img":false}]}
{"op":"mcm","clk":"5321415504","pt":1646309438840,"mc":[{"id":"1.195532856","rc":[{"spn":6.12,"spf":1.0,"id":43189001},{"atb":[[2.62,6.91]],"id":41555102},{"atb":[[2.56,0]],"id":42609837}],"con":true,"img":false}]}
{"op":"mcm","clk":"5321416306","pt":1646309450840,"mc":[{"id":"1.195532856","rc":[{"atb":[[2.5,4.48]],"id":43189001}],"con":true,"img":false}]}
{"op":"mcm","clk":"5321416956","pt":1646309459949,"mc":[{"id":"1.195532856","rc":[{"atb":[[2.68,4]],"id":42609837}],"con":true,"img":false}]}
{"op":"mcm","clk":"5321416970","pt":1646309460126,"mc":[{"id":"1.195532856","rc":[{"atb":[[2.74,3.86]],"id":41555102}],"con":true,"img":false}]}
{"op":"mcm","clk":"5321417068","pt":1646309461627,"mc":[{"id":"1.195532856","rc":[{"atb":[[2.62,0]],"id":42609837}],"con":true,"img":false}]}
{"op":"mcm","clk":"5321417636","pt":1646309469019,"mc":[{"id":"1.195532856","rc":[{"atb":[[2.68,0]],"id":42609837}],"con":true,"img":false}]}
{"op":"mcm","clk":"5321418248","pt":1646309476654,"mc":[{"id":"1.195532856","rc":[{"atb":[[2.68,0]],"id":41555102}],"con":true,"img":false}]}
{"op":"mcm","clk":"5321418494","pt":1646309479715,"mc":[{"id":"1.195532856","rc":[{"atb":[[2.7,0]],"id":43189000},{"atb":[[2.46,0]],"id":42609837}],"con":true,"img":false}]}
{"op":"mcm","clk":"5321419109","pt":1646309487184,"mc":[{"id":"1.195532856","rc":[{"atb":[[2.74,0]],"id":41555102}],"con":true,"img":false}]}
{"op":"mcm","clk":"5321419143","pt":1646309487452,"mc":[{"id":"1.195532856","rc":[{"atb":[[2.78,6.29]],"id":43189000}],"con":true,"img":false}]}
{"op":"mcm","clk":"5321419194","pt":1646309488072,"mc":[{"id":"1.195532856","rc":[{"atb":[[2.54,7.27]],"id":42609837}],"con":true,"img":false}]}
{"op":"mcm","clk":"5321419341","pt":1646309489941,"mc":[{"id":"1.195532856","rc":[{"atb":[[2.56,4.31]],"id":42609837}],"con":true,"img":false}]}
{"op":"mcm","clk":"5321419987","pt":1646309498485,"mc":[{"id":"1.195532856","rc":[{"atb":[[2.56,6.36]],"id":43189001}],"con":true,"img":false}]}
{"op":"mcm","clk":"5321420510","pt":1646309505291,"mc":[{"id":"1.195532856","rc":[{"spn":6.28,"spf":1.0,"id":43189001},{"atb":[[2.62,11.07]],"id":41555102}],"con":true,"img":false}]}
{"op":"mcm","clk":"5321420722","pt":1646309508101,"mc":[{"id":"1.195532856","rc":[{"atb":[[2.5,0]],"id":43189001}],"con":true,"img":false}]}
{"op":"mcm","clk":"5321421338","pt":1646309515739,"mc":[{"id":"1.195532856","rc":[{"atb":[[2.56,0]],"id":41555102}],"con":true,"img":false}]}
{"op":"mcm","clk":"5321422002","pt":1646309524438,"mc":[{"id":"1.195532856","rc":[{"atb":[[2.62,6.91]],"id":41555102}],"con":true,"img":false}]}
{"op":"mcm","clk":"5321422390","pt":1646309529534,"mc":[{"id":"1.195532856","rc":[{"atb":[[2.62,4.15]],"id":43189001}],"con":true,"img":false}]}
{"op":"mcm","clk":"5321422665","pt":1646309533840,"mc":[{"id":"1.195532856","rc":[{"atb":[[2.68,5.9]],"id":41555102}],"con":true,"img":false}]}
{"op":"mcm","clk":"5321422699","pt":1646309534248,"mc":[{"id":"1.195532856","rc":[{"atb":[[2.56,0]],"id":43189001},{"atb":[[3.35,0]],"id":42931075},{"atb":[[2.82,0]],"id":39330606},{"atb":[[2.5,0]],"id":42609837}],"con":true,"img":false}]}
{"op":"mcm","clk":"5321422741","pt":1646309534828,"mc":[{"id":"1.195532856","rc":[{"atb":[[2.66,7.48]],"id":41555102}],"con":true,"img":false}]}
{"op":"mcm","clk":"5321422765","pt":1646309535136,"mc":[{"id":"1.195532856","rc":[{"atb":[[2.62,6.13]],"id":42609837}],"con":true,"img":false}]}
{"op":"mcm","clk":"5321422892","pt":1646309536744,"mc":[{"id":"1.195532856","rc":[{"atb":[[2.62,0]],"id":41555102}],"con":true,"img":false}]}
{"op":"mcm","clk":"5321423430","pt":1646309542438,"mc":[{"id":"1.195532856","rc":[{"atb":[[2.62,0]],"id":43189001},{"atb":[[2.56,0]],"id":42609837}],"con":true,"img":false}]}
{"op":"mcm","clk":"5321423439","pt":1646309542540,"mc":[{"id":"1.195532856","rc":[{"atb":[[2.72,6.51]],"id":41555102}],"con":true,"img":false}]}
{"op":"mcm","clk":"5321424470","pt":1646309554866,"mc":[{"id":"1.195532856","rc":[{"atb":[[3.55,4.87]],"id":42931075}],"con":true,"img":false}]}
{"op":"mcm","clk":"5321424507","pt":1646309555133,"mc":[{"id":"1.195532856","rc":[{"atb":[[2.9,6.53]],"id":39330606},{"atb":[[2.58,7.86]],"id":42609837}],"con":true,"img":false}]}
{"op":"mcm","clk":"5321425095","pt":1646309562351,"mc":[{"id":"1.195532856","rc":[{"atb":[[2.5,4.48]],"id":43189001}],"con":true,"img":false}]}
{"op":"mcm","clk":"5321425120","pt":1646309562563,"mc":[{"id":"1.195532856","rc":[{"atb":[[2.74,3.86]],"id":41555102},{"atb":[[2.68,4]],"id":42609837}],"con":true,"img":false}]}
{"op":"mcm","clk":"5321425670","pt":1646309569873,"mc":[{"id":"1.195532856","rc":[{"spn":6.25,"spf":1.0,"id":43189001},{"atb":[[2.68,0]],"id":41555102},{"atb":[[2.62,0]],"id":42609837}],"con":true,"img":false}]}
{"op":"mcm","clk":"5321426234","pt":1646309577863,"mc":[{"id":"1.195532856","rc":[{"atb":[[2.74,0]],"id":41555102},{"atb":[[2.68,0]],"id":42609837}],"con":true,"img":false}]}
{"op":"mcm","clk":"5321427540","pt":1646309596784,"mc":[{"id":"1.195532856","rc":[{"atb":[[2.56,6.36]],"id":43189001}],"con":true,"img":false}]}
{"op":"mcm","clk":"5321427680","pt":1646309598701,"mc":[{"id":"1.195532856","rc":[{"atb":[[2.64,4.1]],"id":42609837}],"con":true,"img":false}]}
{"op":"mcm","clk":"5321427690","pt":1646309598908,"mc":[{"id":"1.195532856","rc":[{"atb":[[2.72,10.42]],"id":41555102}],"con":true,"img":false}]}
{"op":"mcm","clk":"5321428106","pt":1646309604632,"mc":[{"id":"1.195532856","rc":[{"atb":[[2.5,0]],"id":43189001}],"con":true,"img":false}]}
{"op":"mcm","clk":"5321428851","pt":1646309615416,"mc":[{"id":"1.195532856","rc":[{"atb":[[2.78,5.57]],"id":41555102}],"con":true,"img":false}]}
{"op":"mcm","clk":"5321429398","pt":1646309623331,"mc":[{"id":"1.195532856","rc":[{"atb":[[2.72,6.51]],"id":41555102}],"con":true,"img":false}]}
{"op":"mcm","clk":"5321429563","pt":1646309625963,"mc":[{"id":"1.195532856","rc":[{"atb":[[2.62,4.15]],"id":43189001}],"con":true,"img":false}]}
{"op":"mcm","clk":"5321429877","pt":1646309630052,"mc":[{"id":"1.195532856","rc":[{"atb":[[2.56,0]],"id":43189001},{"spn":6.31,"spf":1.0,"id":43189001}],"con":true,"img":false}]}
{"op":"mcm","clk":"5321430561","pt":1646309638473,"mc":[{"id":"1.195532856","rc":[{"atb":[[2.62,0]],"id":43189001}],"con":true,"img":false}]}
{"op":"mcm","clk":"5321431090","pt":1646309643895,"mc":[{"id":"1.195532856","rc":[{"atb":[[2.84,3.65]],"id":41555102}],"con":true,"img":false}]}
{"op":"mcm","clk":"5321431273","pt":1646309645562,"mc":[{"id":"1.195532856","rc":[{"atb":[[2.7,5.83]],"id":42609837}],"con":true,"img":false}]}
{"op":"mcm","clk":"5321432133","pt":1646309652604,"mc":[{"id":"1.195532856","rc":[{"atb":[[2.64,0]],"id":42609837}],"con":true,"img":false}]}
{"op":"mcm","clk":"5321433112","pt":1646309660940,"mc":[{"id":"1.195532856","rc":[{"atb":[[2.78,0]],"id":41555102}],"con":true,"img":false}]}
{"op":"mcm","clk":"5321433988","pt":1646309667833,"mc":[{"id":"1.195532856","rc":[{"atb":[[2.84,0]],"id":41555102}],"con":true,"img":false}]}
{"op":"mcm","clk":"5321434807","pt":1646309675104,"mc":[{"id":"1.195532856","rc":[{"atb":[[2.5,6.61]],"id":43189001}],"con":true,"img":false}]}
{"op":"mcm","clk":"5321434857","pt":1646309675623,"mc":[{"id":"1.195532856","rc":[{"atb":[[2.7,0]],"id":42609837}],"con":true,"img":false}]}
{"op":"mcm","clk":"5321436127","pt":1646309690169,"mc":[{"id":"1.195532856","rc":[{"spn":6.25,"spf":1.0,"id":43189001},{"atb":[[2.6,6.19]],"id":42609837}],"con":true,"img":false}]}
{"op":"mcm","clk":"5321437176","pt":1646309702458,"mc":[{"id":"1.195532856","rc":[{"atb":[[2.78,5.57]],"id":41555102}],"con":true,"img":false}]}
{"op":"mcm","clk":"5321437964","pt":1646309711193,"mc":[{"id":"1.195532856","rc":[{"atb":[[2.56,4.31]],"id":43189001}],"con":true,"img":false}]}
{"op":"mcm","clk":"5321439135","pt":1646309723224,"mc":[{"id":"1.195532856","rc":[{"atb":[[2.66,4.05]],"id":42609837}],"con":true,"img":false}]}
{"op":"mcm","clk":"5321440043","pt":1646309731450,"mc":[{"id":"1.195532856","rc":[{"atb":[[2.84,3.65]],"id":41555102}],"con":true,"img":false}]}
{"op":"mcm","clk":"5321440546","pt":1646309735966,"mc":[{"id":"1.195532856","rc":[{"atb":[[2.5,0]],"id":43189001}],"con":true,"img":false}]}
{"op":"mcm","clk":"5321440601","pt":1646309736439,"mc":[{"id":"1.195532856","rc":[{"atb":[[2.74,0]],"id":43189000}],"con":true,"img":false}]}
{"op":"mcm","clk":"5321441581","pt":1646309745372,"mc":[{"id":"1.195532856","rc":[{"atb":[[2.56,0]],"id":43189001}],"con":true,"img":false}]}
{"op":"mcm","clk":"5321442886","pt":1646309756379,"mc":[{"id":"1.195532856","rc":[{"spn":6.12,"spf":1.0,"id":43189001},{"atb":[[2.78,0]],"id":41555102},{"atb":[[2.6,0]],"id":42609837}],"con":true,"img":false}]}
{"op":"mcm","clk":"5321442938","pt":1646309756785,"mc":[{"id":"1.195532856","rc":[{"atb":[[2.82,6.82]],"id":43189000}],"con":true,"img":false}]}
{"op":"mcm","clk":"5321443739","pt":1646309763985,"mc":[{"id":"1.195532856","rc":[{"atb":[[2.5,4.48]],"id":43189001}],"con":true,"img":false}]}
{"op":"mcm","clk":"5321443770","pt":1646309764194,"mc":[{"id":"1.195532856","rc":[{"atb":[[2.84,0]],"id":41555102},{"atb":[[2.66,0]],"id":42609837}],"con":true,"img":false}]}
{"op":"mcm","clk":"5321444080","pt":1646309767225,"mc":[{"id":"1.195532856","rc":[{"atb":[[3.45,0]],"id":42931075},{"atb":[[2.86,0]],"id":39330606},{"atb":[[2.54,0]],"id":42609837}],"con":true,"img":false}]}
{"op":"mcm","clk":"5321444668","pt":1646309773132,"mc":[{"id":"1.195532856","rc":[{"atb":[[3.65,4.22]],"id":42931075}],"con":true,"img":false}]}
{"op":"mcm","clk":"5321444678","pt":1646309773234,"mc":[{"id":"1.195532856","rc":[{"atb":[[2.94,5.77]],"id":39330606},{"atb":[[2.62,6.91]],"id":42609837}],"con":true,"img":false}]}
{"op":"mcm","clk":"5321445859","pt":1646309784961,"mc":[{"id":"1.195532856","rc":[{"atb":[[2.64,4.1]],"id":42609837}],"con":true,"img":false}]}
{"op":"mcm","clk":"5321445938","pt":1646309785850,"mc":[{"id":"1.195532856","rc":[{"atb":[[2.72,10.42]],"id":41555102}],"con":true,"img":false}]}
{"op":"mcm","clk":"5321447187","pt":1646309796363,"mc":[{"id":"1.195532856","rc":[{"atb":[[2.66,0]],"id":41555102}],"con":true,"img":false}]}
{"op":"mcm","clk":"5321447862","pt":1646309803785,"mc":[{"id":"1.195532856","rc":[{"atb":[[2.72,3.9]],"id":41555102}],"con":true,"img":false}]}
{"op":"mcm","clk":"5321448347","pt":1646309809005,"mc":[{"id":"1.195532856","rc":[{"atb":[[2.36,8.24]],"id":41555102}],"con":true,"img":false}]}
{"op":"mcm","clk":"5321448369","pt":1646309809169,"mc":[{"id":"1.195532856","rc":[{"atb":[[2.72,0]],"id":41555102}],"con":true,"img":false}]}
{"op":"mcm","clk":"5321448523","pt":1646309810583,"mc":[{"id":"1.195532856","rc":[{"atb":[[2.4,8.87]],"id":41555102}],"con":true,"img":false}]}
{"op":"mcm","clk":"5321448559","pt":1646309810901,"mc":[{"id":"1.195532856","rc":[{"atb":[[2.56,6.36]],"id":43189001}],"con":true,"img":false}]}
{"op":"mcm","clk":"5321448588","pt":1646309811180,"mc":[{"id":"1.195532856","rc":[{"atb":[[2.58,0]],"id":42609837}],"con":true,"img":false}]}
{"op":"mcm","clk":"5321449772","pt":1646309821986,"mc":[{"id":"1.195532856","rc":[{"atb":[[2.5,0]],"id":43189001},{"spn":6.28,"spf":1.0,"id":43189001},{"atb":[[2.64,0]],"id":42609837}],"con":true,"img":false}]}
{"op":"mcm","clk":"5321450134","pt":1646309825432,"mc":[{"id":"1.195532856","rc":[{"atb":[[2.66,7.48]],"id":42609837}],"con":true,"img":false}]}
{"op":"mcm","clk":"5321451860","pt":1646309840869,"mc":[{"id":"1.195532856","rc":[{"atb":[[2.56,0]],"id":43189001}],"con":true,"img":false}]}
{"op":"mcm","clk":"5321451883","pt":1646309841177,"mc":[{"id":"1.195532856","rc":[{"atb":[[2.4,15.96]],"id":41555102}],"con":true,"img":false}]}
{"op":"mcm","clk":"5321451989","pt":1646309844417,"mc":[{"id":"1.195532856","rc":[{"atb":[[2.44,4.67]],"id":41555102}],"con":true,"img":false}]}
{"op":"mcm","clk":"5321453031","pt":1646309854493,"mc":[{"id":"1.195532856","rc":[{"atb":[[2.72,3.9]],"id":42609837}],"con":true,"img":false}]}
{"op":"mcm","clk":"5321453109","pt":1646309855278,"mc":[{"id":"1.195532856","rc":[{"atb":[[2.68,5.9]],"id":42609837}],"con":true,"img":false}]}
{"op":"mcm","clk":"5321453147","pt":1646309855695,"mc":[{"id":"1.195532856","rc":[{"atb":[[2.5,6.61]],"id":43189001}],"con":true,"img":false}]}
{"op":"mcm","clk":"5321454245","pt":1646309866306,"mc":[{"id":"1.195532856","rc":[{"atb":[[2.72,0]],"id":42609837}],"con":true,"img":false}]}
{"op":"mcm","clk":"5321454842","pt":1646309873606,"mc":[{"id":"1.195532856","rc":[{"atb":[[2.4,8.87]],"id":41555102}],"con":true,"img":false}]}
{"op":"mcm","clk":"5321456057","pt":1646309887444,"mc":[{"id":"1.195532856","rc":[{"atb":[[2.56,4.31]],"id":43189001}],"con":true,"img":false}]}
{"op":"mcm","clk":"5321456066","pt":1646309887542,"mc":[{"id":"1.195532856","rc":[{"atb":[[2.74,3.86]],"id":42609837}],"con":true,"img":false}]}
{"op":"mcm","clk":"5321456130","pt":1646309888216,"mc":[{"id":"1.195532856","rc":[{"atb":[[2.48,6.7]],"id":41555102}],"con":true,"img":false}]}
{"op":"mcm","clk":"5321456976","pt":1646309899525,"mc":[{"id":"1.195532856","rc":[{"atb":[[2.44,0]],"id":41555102}],"con":true,"img":false}]}
{"op":"mcm","clk":"5321457272","pt":1646309903451,"mc":[{"id":"1.195532856","rc":[{"atb":[[2.5,0]],"id":43189001},{"atb":[[2.68,0]],"id":42609837}],"con":true,"img":false}]}
{"op":"mcm","clk":"5321457973","pt":1646309911890,"mc":[{"id":"1.195532856","rc":[{"atb":[[2.56,0]],"id":43189001},{"atb":[[2.74,0]],"id":42609837}],"con":true,"img":false}]}
{"op":"mcm","clk":"5321458808","pt":1646309920091,"mc":[{"id":"1.195532856","rc":[{"atb":[[2.52,4.42]],"id":41555102}],"con":true,"img":false}]}
{"op":"mcm","clk":"5321459277","pt":1646309924984,"mc":[{"id":"1.195532856","rc":[{"atb":[[2.48,0]],"id":41555102}],"con":true,"img":false}]}
{"op":"mcm","clk":"5321459917","pt":1646309932483,"mc":[{"id":"1.195532856","rc":[{"atb":[[2.5,4.48]],"id":43189001}],"con":true,"img":false}]}
{"op":"mcm","clk":"5321459930","pt":1646309932685,"mc":[{"id":"1.195532856","rc":[{"atb":[[2.52,0]],"id":41555102}],"con":true,"img":false}]}
{"op":"mcm","clk":"5321459952","pt":1646309932894,"mc":[{"id":"1.195532856","rc":[{"atb":[[2.72,3.9]],"id":42609837}],"con":true,"img":false}]}
{"op":"mcm","clk":"5321461825","pt":1646309953410,"mc":[{"id":"1.195532856","rc":[{"spn":6.25,"spf":1.0,"id":43189001},{"atb":[[2.44,4.67]],"id":41555102}],"con":true,"img":false}]}
{"op":"mcm","clk":"5321463639","pt":1646309972147,"mc":[{"id":"1.195532856","rc":[{"atb":[[2.78,0]],"id":43189000}],"con":true,"img":false}]}
{"op":"mcm","clk":"5321463755","pt":1646309973442,"mc":[{"id":"1.195532856","rc":[{"atb":[[2.78,5.57]],"id":42609837}],"con":true,"img":false}]}
{"op":"mcm","clk":"5321463777","pt":1646309973649,"mc":[{"id":"1.195532856","rc":[{"atb":[[2.56,6.36]],"id":43189001}],"con":true,"img":false}]}
{"op":"mcm","clk":"5321464089","pt":1646309977783,"mc":[{"id":"1.195532856","rc":[{"atb":[[2.86,6.02]],"id":43189000}],"con":true,"img":false}]}
{"op":"mcm","clk":"5321464608","pt":1646309983967,"mc":[{"id":"1.195532856","rc":[{"atb":[[2.5,0]],"id":43189001},{"atb":[[2.72,0]],"id":42609837}],"con":true,"img":false}]}
{"op":"mcm","clk":"5321465450","pt":1646309991076,"mc":[{"id":"1.195532856","rc":[{"atb":[[2.48,6.7]],"id":41555102}],"con":true,"img":false}]}
{"op":"mcm","clk":"5321466307","pt":1646309999907,"mc":[{"id":"1.195532856","rc":[{"atb":[[2.44,0]],"id":41555102}],"con":true,"img":false}]}
{"op":"mcm","clk":"5321466783","pt":1646310004786,"mc":[{"id":"1.195532856","rc":[{"atb":[[2.62,4.15]],"id":43189001}],"con":true,"img":false}]}
{"op":"mcm","clk":"5321466803","pt":1646310004992,"mc":[{"id":"1.195532856","rc":[{"atb":[[2.84,3.65]],"id":42609837}],"con":true,"img":false}]}
{"op":"mcm","clk":"5321466950","pt":1646310006503,"mc":[{"id":"1.195532856","rc":[{"atb":[[2.56,0]],"id":43189001},{"atb":[[2.78,0]],"id":42609837}],"con":true,"img":false}]}
{"op":"mcm","clk":"5321468013","pt":1646310017312,"mc":[{"id":"1.195532856","rc":[{"atb":[[2.62,0]],"id":43189001},{"spn":6.12,"spf":1.0,"id":43189001},{"atb":[[2.84,0]],"id":42609837}],"con":true,"img":false}]}
{"op":"mcm","clk":"5321468333","pt":1646310020628,"mc":[{"id":"1.195532856","rc":[{"atb":[[3.55,0]],"id":42931075},{"atb":[[2.9,0]],"id":39330606}],"con":true,"img":false}]}
{"op":"mcm","clk":"5321468341","pt":1646310020731,"mc":[{"id":"1.195532856","rc":[{"atb":[[2.48,0]],"id":41555102}],"con":true,"img":false}]}
{"op":"mcm","clk":"5321469988","pt":1646310036629,"mc":[{"id":"1.195532856","rc":[{"atb":[[2.4,15.96]],"id":41555102}],"con":true,"img":false}]}
{"op":"mcm","clk":"5321470010","pt":1646310036837,"mc":[{"id":"1.195532856","rc":[{"atb":[[3.75,4.51]],"id":42931075}],"con":true,"img":false}]}
{"op":"mcm","clk":"5321470081","pt":1646310037356,"mc":[{"id":"1.195532856","rc":[{"atb":[[2.72,3.9]],"id":42609837}],"con":true,"img":false}]}
{"op":"mcm","clk":"5321470092","pt":1646310037454,"mc":[{"id":"1.195532856","rc":[{"atb":[[2.98,6.27]],"id":39330606}],"con":true,"img":false}]}
{"op":"mcm","clk":"5321470102","pt":1646310037558,"mc":[{"id":"1.195532856","rc":[{"atb":[[2.5,4.48]],"id":43189001}],"con":true,"img":false}]}
{"op":"mcm","clk":"5321470793","pt":1646310043936,"mc":[{"id":"1.195532856","rc":[{"atb":[[2.36,0]],"id":41555102},{"atb":[[2.62,0]],"id":42609837}],"con":true,"img":false}]}
{"op":"mcm","clk":"5321471051","pt":1646310046343,"mc":[{"id":"1.195532856","rc":[{"atb":[[2.44,7.78]],"id":41555102}],"con":true,"img":false}]}
{"op":"mcm","clk":"5321471076","pt":1646310046550,"mc":[{"id":"1.195532856","rc":[{"atb":[[2.7,6.59]],"id":42609837}],"con":true,"img":false}]}
{"op":"mcm","clk":"5321471557","pt":1646310049949,"mc":[{"id":"1.195532856","rc":[{"atb":[[2.44,12.45]],"id":41555102}],"con":true,"img":false}]}
{"op":"mcm","clk":"5321473886","pt":1646310070011,"mc":[{"id":"1.195532856","rc":[{"atb":[[2.4,8.87]],"id":41555102}],"con":true,"img":false}]}
{"op":"mcm","clk":"5321475454","pt":1646310084326,"mc":[{"id":"1.195532856","rc":[{"spn":6.25,"spf":1.0,"id":43189001},{"atb":[[2.78,5.57]],"id":42609837}],"con":true,"img":false}]}
{"op":"mcm","clk":"5321475467","pt":1646310084428,"mc":[{"id":"1.195532856","rc":[{"atb":[[2.48,6.7]],"id":41555102}],"con":true,"img":false}]}
{"op":"mcm","clk":"5321475492","pt":1646310084634,"mc":[{"id":"1.195532856","rc":[{"atb":[[2.56,6.36]],"id":43189001}],"con":true,"img":false}]}
{"op":"mcm","clk":"5321476227","pt":1646310091548,"mc":[{"id":"1.195532856","rc":[{"atb":[[2.5,0]],"id":43189001},{"atb":[[2.44,7.78]],"id":41555102},{"atb":[[2.72,0]],"id":42609837}],"con":true,"img":false}]}
{"op":"mcm","clk":"5321476872","pt":1646310096944,"mc":[{"id":"1.195532856","rc":[{"atl":[[1000,14.5]],"id":43189000}],"con":true,"img":false}]}
{"op":"mcm","clk":"5321477021","pt":1646310098238,"mc":[{"id":"1.195532856","rc":[{"atl":[[1000,14.7]],"id":43189000}],"con":true,"img":false}]}
{"op":"mcm","clk":"5321477107","pt":1646310098963,"mc":[{"id":"1.195532856","rc":[{"atb":[[2.4,0]],"id":41555102}],"con":true,"img":false}]}
{"op":"mcm","clk":"5321477173","pt":1646310099579,"mc":[{"id":"1.195532856","rc":[{"atl":[[1000,14.5]],"id":43189000}],"con":true,"img":false}]}
{"op":"mcm","clk":"5321477187","pt":1646310099685,"mc":[{"id":"1.195532856","rc":[{"atl":[[11.5,0.2]],"id":43189000}],"con":true,"img":false}]}
{"op":"mcm","clk":"5321477321","pt":1646310100983,"mc":[{"id":"1.195532856","rc":[{"atl":[[1000,14.5]],"id":42931075}],"con":true,"img":false}]}
{"op":"mcm","clk":"5321477454","pt":1646310102278,"mc":[{"id":"1.195532856","rc":[{"atl":[[1000,14.7]],"id":42931075}],"con":true,"img":false}]}
{"op":"mcm","clk":"5321478625","pt":1646310112731,"mc":[{"id":"1.195532856","rc":[{"atb":[[2.52,4.42]],"id":41555102}],"con":true,"img":false}]}
{"op":"mcm","clk":"5321478665","pt":1646310113034,"mc":[{"id":"1.195532856","rc":[{"atb":[[2.62,4.15]],"id":43189001},{"atb":[[2.84,3.65]],"id":42609837}],"con":true,"img":false}]}
{"op":"mcm","clk":"5321478831","pt":1646310114802,"mc":[{"id":"1.195532856","rc":[{"atb":[[2.56,0]],"id":43189001},{"atb":[[2.78,0]],"id":42609837}],"con":true,"img":false}]}
{"op":"mcm","clk":"5321478863","pt":1646310115115,"mc":[{"id":"1.195532856","rc":[{"atb":[[2.56,7.96]],"id":41555102}],"con":true,"img":false}]}
{"op":"mcm","clk":"5321479862","pt":1646310124741,"mc":[{"id":"1.195532856","rc":[{"atb":[[2.62,0]],"id":43189001},{"atb":[[2.52,0]],"id":41555102},{"atb":[[2.84,0]],"id":42609837}],"con":true,"img":false}]}
{"op":"mcm","clk":"5321480618","pt":1646310132660,"mc":[{"id":"1.195532856","rc":[{"atb":[[2.66,0]],"id":42609837}],"con":true,"img":false}]}
{"op":"mcm","clk":"5321481792","pt":1646310145655,"mc":[{"id":"1.195532856","rc":[{"atb":[[2.5,4.48]],"id":43189001}],"con":true,"img":false}]}
{"op":"mcm","clk":"5321481797","pt":1646310145797,"mc":[{"id":"1.195532856","rc":[{"atb":[[2.62,4.15]],"id":41555102}],"con":true,"img":false}]}
{"op":"mcm","clk":"5321481911","pt":1646310147191,"mc":[{"id":"1.195532856","rc":[{"atb":[[2.48,0]],"id":41555102}],"con":true,"img":false}]}
{"op":"mcm","clk":"5321481954","pt":1646310147668,"mc":[{"id":"1.195532856","rc":[{"atb":[[2.74,7.14]],"id":42609837}],"con":true,"img":false}]}
{"op":"mcm","clk":"5321482981","pt":1646310159212,"mc":[{"id":"1.195532856","rc":[{"atl":[[1000,14.5]],"id":42931075}],"con":true,"img":false}]}
{"op":"mcm","clk":"5321482986","pt":1646310159315,"mc":[{"id":"1.195532856","rc":[{"atl":[[21,0.2]],"id":42931075}],"con":true,"img":false}]}
{"op":"mcm","clk":"5321483098","pt":1646310160611,"mc":[{"id":"1.195532856","rc":[{"atl":[[1000,14.5]],"id":43189001}],"con":true,"img":false}]}
{"op":"mcm","clk":"5321483231","pt":1646310161907,"mc":[{"id":"1.195532856","rc":[{"atl":[[1000,14.7]],"id":43189001}],"con":true,"img":false}]}
{"op":"mcm","clk":"5321483346","pt":1646310163200,"mc":[{"id":"1.195532856","rc":[{"atl":[[1000,14.5]],"id":43189001}],"con":true,"img":false}]}
{"op":"mcm","clk":"5321483354","pt":1646310163300,"mc":[{"id":"1.195532856","rc":[{"atl":[[15,0.2]],"id":43189001}],"con":true,"img":false}]}
{"op":"mcm","clk":"5321483380","pt":1646310163608,"mc":[{"id":"1.195532856","rc":[{"atb":[[2.76,5.63]],"id":42609837}],"con":true,"img":false}]}
{"op":"mcm","clk":"5321483464","pt":1646310164634,"mc":[{"id":"1.195532856","rc":[{"atl":[[1000,14.5]],"id":41555102}],"con":true,"img":false}]}
{"op":"mcm","clk":"5321483581","pt":1646310165929,"mc":[{"id":"1.195532856","rc":[{"atl":[[1000,14.7]],"id":41555102}],"con":true,"img":false}]}
{"op":"mcm","clk":"5321483705","pt":1646310167230,"mc":[{"id":"1.195532856","rc":[{"atl":[[1000,14.5]],"id":41555102}],"con":true,"img":false}]}
{"op":"mcm","clk":"5321483718","pt":1646310167332,"mc":[{"id":"1.195532856","rc":[{"atl":[[8.8,0.2]],"id":41555102}],"con":true,"img":false}]}
{"op":"mcm","clk":"5321483850","pt":1646310168624,"mc":[{"id":"1.195532856","rc":[{"atl":[[1000,14.5]],"id":39330606}],"con":true,"img":false}]}
{"op":"mcm","clk":"5321483969","pt":1646310169924,"mc":[{"id":"1.195532856","rc":[{"atl":[[1000,14.7]],"id":39330606}],"con":true,"img":false}]}
{"op":"mcm","clk":"5321484082","pt":1646310171236,"mc":[{"id":"1.195532856","rc":[{"atl":[[1000,14.5]],"id":39330606}],"con":true,"img":false}]}
{"op":"mcm","clk":"5321484096","pt":1646310171337,"mc":[{"id":"1.195532856","rc":[{"atl":[[13.5,0.2]],"id":39330606}],"con":true,"img":false}]}
{"op":"mcm","clk":"5321484219","pt":1646310172637,"mc":[{"id":"1.195532856","rc":[{"atl":[[1000,14.5]],"id":42609837}],"con":true,"img":false}]}
{"op":"mcm","clk":"5321484345","pt":1646310173926,"mc":[{"id":"1.195532856","rc":[{"atl":[[1000,14.7]],"id":42609837}],"con":true,"img":false}]}
{"op":"mcm","clk":"5321484481","pt":1646310175214,"mc":[{"id":"1.195532856","rc":[{"atl":[[1000,14.5]],"id":42609837}],"con":true,"img":false}]}
{"op":"mcm","clk":"5321484491","pt":1646310175337,"mc":[{"id":"1.195532856","rc":[{"atl":[[9.4,0.2]],"id":42609837}],"con":true,"img":false}]}
{"op":"mcm","clk":"5321484638","pt":1646310176939,"mc":[{"id":"1.195532856","rc":[{"atb":[[2.68,5.9]],"id":41555102}],"con":true,"img":false}]}
{"op":"mcm","clk":"5321484662","pt":1646310177151,"mc":[{"id":"1.195532856","rc":[{"atb":[[2.56,6.36]],"id":43189001}],"con":true,"img":false}]}
{"op":"mcm","clk":"5321485443","pt":1646310184946,"mc":[{"id":"1.195532856","rc":[{"atb":[[2.5,0]],"id":43189001},{"atb":[[2.62,0]],"id":41555102}],"con":true,"img":false}]}
{"op":"mcm","clk":"5321486307","pt":1646310193966,"mc":[{"id":"1.195532856","rc":[{"atb":[[2.82,3.69]],"id":42609837}],"con":true,"img":false}]}
{"op":"mcm","clk":"5321487443","pt":1646310204600,"mc":[{"id":"1.195532856","rc":[{"atb":[[2.56,0]],"id":43189001},{"atb":[[2.68,0]],"id":41555102}],"con":true,"img":false}]}
{"op":"mcm","clk":"5321487498","pt":1646310205113,"mc":[{"id":"1.195532856","rc":[{"atb":[[2.82,0]],"id":43189000}],"con":true,"img":false}]}
{"op":"mcm","clk":"5321489926","pt":1646310228638,"mc":[{"id":"1.195532856","rc":[{"spn":6.12,"spf":1.0,"id":43189001},{"atb":[[2.48,6.7]],"id":41555102}],"con":true,"img":false}]}
{"op":"mcm","clk":"5321489993","pt":1646310229357,"mc":[{"id":"1.195532856","rc":[{"atb":[[2.5,6.61]],"id":43189001}],"con":true,"img":false}]}
{"op":"mcm","clk":"5321490002","pt":1646310229416,"mc":[{"id":"1.195532856","rc":[{"atb":[[2.76,0]],"id":42609837}],"con":true,"img":false}]}
{"op":"mcm","clk":"5321490027","pt":1646310229621,"mc":[{"id":"1.195532856","rc":[{"atb":[[2.9,6.53]],"id":43189000}],"con":true,"img":false}]}
{"op":"mcm","clk":"5321490733","pt":1646310237043,"mc":[{"id":"1.195532856","rc":[{"atb":[[2.82,0]],"id":42609837}],"con":true,"img":false}]}
{"op":"mcm","clk":"5321490757","pt":1646310237251,"mc":[{"id":"1.195532856","rc":[{"atb":[[2.62,4.15]],"id":41555102}],"con":true,"img":false}]}
{"op":"mcm","clk":"5321492276","pt":1646310254062,"mc":[{"id":"1.195532856","rc":[{"atb":[[3.65,0]],"id":42931075},{"atb":[[2.94,0]],"id":39330606}],"con":true,"img":false}]}
{"op":"mcm","clk":"5321492565","pt":1646310257281,"mc":[{"id":"1.195532856","rc":[{"atb":[[2.8,3.73]],"id":42609837}],"con":true,"img":false}]}
{"op":"mcm","clk":"5321492573","pt":1646310257385,"mc":[{"id":"1.195532856","rc":[{"atb":[[3.85,3.93]],"id":42931075}],"con":true,"img":false}]}
{"op":"mcm","clk":"5321492584","pt":1646310257489,"mc":[{"id":"1.195532856","rc":[{"atb":[[2.56,4.31]],"id":43189001}],"con":true,"img":false}]}
{"op":"mcm","clk":"5321492596","pt":1646310257592,"mc":[{"id":"1.195532856","rc":[{"atb":[[3.05,5.47]],"id":39330606}],"con":true,"img":false}]}
{"op":"mcm","clk":"5321493234","pt":1646310264701,"mc":[{"id":"1.195532856","rc":[{"atb":[[2.48,0]],"id":41555102}],"con":true,"img":false}]}
{"op":"mcm","clk":"5321494893","pt":1646310283077,"mc":[{"id":"1.195532856","rc":[{"atb":[[2.5,0]],"id":43189001}],"con":true,"img":false}]}
{"op":"mcm","clk":"5321494912","pt":1646310283232,"mc":[{"id":"1.195532856","rc":[{"atb":[[2.68,5.9]],"id":41555102}],"con":true,"img":false}]}
{"op":"mcm","clk":"5321495536","pt":1646310290359,"mc":[{"id":"1.195532856","rc":[{"atb":[[2.56,0]],"id":43189001},{"atb":[[2.62,0]],"id":41555102}],"con":true,"img":false}]}
{"op":"mcm","clk":"5321496199","pt":1646310298363,"mc":[{"id":"1.195532856","rc":[{"atb":[[2.86,5.33]],"id":42609837}],"con":true,"img":false}]}
{"op":"mcm","clk":"5321496750","pt":1646310305111,"mc":[{"id":"1.195532856","rc":[{"atb":[[2.8,0]],"id":42609837}],"con":true,"img":false}]}
{"op":"mcm","clk":"5321497239","pt":1646310310814,"mc":[{"id":"1.195532856","rc":[{"atb":[[2.5,4.48]],"id":43189001}],"con":true,"img":false}]}
{"op":"mcm","clk":"5321497255","pt":1646310311052,"mc":[{"id":"1.195532856","rc":[{"atb":[[2.74,3.86]],"id":41555102}],"con":true,"img":false}]}
{"op":"mcm","clk":"5321497380","pt":1646310312710,"mc":[{"id":"1.195532856","rc":[{"atb":[[2.68,0]],"id":41555102}],"con":true,"img":false}]}
{"op":"mcm","clk":"5321497682","pt":1646310316939,"mc":[{"id":"1.195532856","rc":[{"atb":[[2.44,0]],"id":41555102},{"atb":[[2.7,0]],"id":42609837}],"con":true,"img":false}]}
{"op":"mcm","clk":"5321497979","pt":1646310320004,"mc":[{"id":"1.195532856","rc":[{"atb":[[2.6,7]],"id":41555102},{"atb":[[2.9,5.89]],"id":42609837}],"con":true,"img":false}]}
{"op":"mcm","clk":"5321498262","pt":1646310323011,"mc":[{"id":"1.195532856","rc":[{"atb":[[2.74,0]],"id":41555102}],"con":true,"img":false}]}
{"op":"mcm","clk":"5321498497","pt":1646310325813,"mc":[{"id":"1.195532856","rc":[{"atb":[[2.92,3.5]],"id":42609837}],"con":true,"img":false}]}
{"op":"mcm","clk":"5321498641","pt":1646310327631,"mc":[{"id":"1.195532856","rc":[{"atb":[[2.86,0]],"id":42609837}],"con":true,"img":false}]}
{"op":"mcm","clk":"5321499260","pt":1646310335026,"mc":[{"id":"1.195532856","rc":[{"atb":[[2.92,0]],"id":42609837}],"con":true,"img":false}]}
{"op":"mcm","clk":"5321499759","pt":1646310340367,"mc":[{"id":"1.195532856","rc":[{"atb":[[2.56,6.36]],"id":43189001}],"con":true,"img":false}]}
{"op":"mcm","clk":"5321500055","pt":1646310343772,"mc":[{"id":"1.195532856","rc":[{"atb":[[2.62,4.15]],"id":41555102}],"con":true,"img":false}]}
{"op":"mcm","clk":"5321500366","pt":1646310347187,"mc":[{"id":"1.195532856","rc":[{"atb":[[2.5,0]],"id":43189001}],"con":true,"img":false}]}
{"op":"mcm","clk":"5321501364","pt":1646310358866,"mc":[{"id":"1.195532856","rc":[{"spn":6.28,"spf":1.0,"id":43189001},{"atb":[[2.8,3.73]],"id":42609837}],"con":true,"img":false}]}
{"op":"mcm","clk":"5321501694","pt":1646310363484,"mc":[{"id":"1.195532856","rc":[{"atb":[[2.56,0]],"id":43189001}],"con":true,"img":false}]}
{"op":"mcm","clk":"5321501725","pt":1646310364003,"mc":[{"id":"1.195532856","rc":[{"atb":[[2.56,0]],"id":41555102}],"con":true,"img":false}]}
{"op":"mcm","clk":"5321502557","pt":1646310374077,"mc":[{"id":"1.195532856","rc":[{"atb":[[2.62,0]],"id":41555102}],"con":true,"img":false}]}
{"op":"mcm","clk":"5321502935","pt":1646310378901,"mc":[{"id":"1.195532856","rc":[{"atb":[[2.5,6.61]],"id":43189001}],"con":true,"img":false}]}
{"op":"mcm","clk":"5321502946","pt":1646310379004,"mc":[{"id":"1.195532856","rc":[{"atb":[[2.64,7.58]],"id":41555102}],"con":true,"img":false}]}
{"op":"mcm","clk":"5321502959","pt":1646310379210,"mc":[{"id":"1.195532856","rc":[{"atb":[[2.96,5.06]],"id":42609837}],"con":true,"img":false}]}
{"op":"mcm","clk":"5321503507","pt":1646310386043,"mc":[{"id":"1.195532856","rc":[{"atb":[[2.8,0]],"id":42609837}],"con":true,"img":false}]}
{"op":"mcm","clk":"5321505067","pt":1646310406473,"mc":[{"id":"1.195532856","rc":[{"atb":[[2.66,5.97]],"id":41555102}],"con":true,"img":false}]}
{"op":"mcm","clk":"5321507499","pt":1646310436594,"mc":[{"id":"1.195532856","rc":[{"spn":6.25,"spf":1.0,"id":43189001},{"atb":[[2.74,0]],"id":42609837}],"con":true,"img":false}]}
{"op":"mcm","clk":"5321507594","pt":1646310437840,"mc":[{"id":"1.195532856","rc":[{"atb":[[2.86,0]],"id":43189000}],"con":true,"img":false}]}
{"op":"mcm","clk":"5321508404","pt":1646310448707,"mc":[{"id":"1.195532856","rc":[{"atb":[[2.94,6.4]],"id":42609837}],"con":true,"img":false}]}
{"op":"mcm","clk":"5321512699","pt":1646310504603,"mc":[{"id":"1.195532856","rc":[{"atb":[[3.75,0]],"id":42931075},{"atb":[[2.98,0]],"id":39330606}],"con":true,"img":false}]}
{"op":"mcm","clk":"5321513977","pt":1646310520811,"mc":[{"id":"1.195532856","rc":[{"atb":[[3.95,4.2]],"id":42931075},{"atb":[[3.15,5.78]],"id":39330606}],"con":true,"img":false}]}
{"op":"mcm","clk":"5321517042","pt":1646310560509,"mc":[{"id":"1.195532856","rc":[{"atb":[[2.9,0]],"id":42609837}],"con":true,"img":false}]}
{"op":"mcm","clk":"5321518836","pt":1646310583444,"mc":[{"id":"1.195532856","rc":[{"atb":[[2.96,0]],"id":42609837}],"con":true,"img":false}]}
{"op":"mcm","clk":"5321520254","pt":1646310599657,"mc":[{"id":"1.195532856","rc":[{"atb":[[2.6,0]],"id":41555102}],"con":true,"img":false}]}
{"op":"mcm","clk":"5321521076","pt":1646310607964,"mc":[{"id":"1.195532856","rc":[{"atb":[[2.38,7.19]],"id":42609837}],"con":true,"img":false}]}
{"op":"mcm","clk":"5321521136","pt":1646310608641,"mc":[{"id":"1.195532856","rc":[{"atb":[[2.7,6.59]],"id":41555102}],"con":true,"img":false}]}
{"op":"mcm","clk":"5321521170","pt":1646310608946,"mc":[{"id":"1.195532856","rc":[{"atb":[[2.98,5.66]],"id":42609837}],"con":true,"img":false}]}
{"op":"mcm","clk":"5321521206","pt":1646310609460,"mc":[{"id":"1.195532856","rc":[{"atb":[[2.72,3.9]],"id":41555102}],"con":true,"img":false}]}
{"op":"mcm","clk":"5321521378","pt":1646310611176,"mc":[{"id":"1.195532856","rc":[{"atb":[[2.94,5.77]],"id":43189000}],"con":true,"img":false}]}
{"op":"mcm","clk":"5321521393","pt":1646310611280,"mc":[{"id":"1.195532856","rc":[{"atb":[[2.56,4.31]],"id":43189001}],"con":true,"img":false}]}
{"op":"mcm","clk":"5321522175","pt":1646310619068,"mc":[{"id":"1.195532856","rc":[{"atb":[[3,3.36]],"id":42609837}],"con":true,"img":false}]}
{"op":"mcm","clk":"5321522227","pt":1646310619637,"mc":[{"id":"1.195532856","rc":[{"atb":[[2.66,0]],"id":41555102}],"con":true,"img":false}]}
{"op":"mcm","clk":"5321523326","pt":1646310630897,"mc":[{"id":"1.195532856","rc":[{"atb":[[2.72,0]],"id":41555102}],"con":true,"img":false}]}
{"op":"mcm","clk":"5321523389","pt":1646310631674,"mc":[{"id":"1.195532856","rc":[{"atb":[[2.5,0]],"id":43189001},{"atb":[[2.38,0]],"id":42609837}],"con":true,"img":false}]}
{"op":"mcm","clk":"5321524455","pt":1646310641788,"mc":[{"id":"1.195532856","rc":[{"atb":[[2.56,0]],"id":43189001}],"con":true,"img":false}]}
{"op":"mcm","clk":"5321525385","pt":1646310651437,"mc":[{"id":"1.195532856","rc":[{"spn":6.12,"spf":1.0,"id":43189001},{"atb":[[2.7,10.54]],"id":41555102}],"con":true,"img":false}]}
{"op":"mcm","clk":"5321526371","pt":1646310662943,"mc":[{"id":"1.195532856","rc":[{"atb":[[2.5,4.48]],"id":43189001}],"con":true,"img":false}]}
{"op":"mcm","clk":"5321527117","pt":1646310670649,"mc":[{"id":"1.195532856","rc":[{"atb":[[2.76,5.63]],"id":41555102}],"con":true,"img":false}]}
{"op":"mcm","clk":"5321527143","pt":1646310670956,"mc":[{"id":"1.195532856","rc":[{"atb":[[3.05,4.83]],"id":42609837}],"con":true,"img":false}]}
{"op":"mcm","clk":"5321527957","pt":1646310677665,"mc":[{"id":"1.195532856","rc":[{"atb":[[2.7,6.59]],"id":41555102},{"atb":[[3,0]],"id":42609837}],"con":true,"img":false}]}
{"op":"mcm","clk":"5321529783","pt":1646310686992,"mc":[{"id":"1.195532856","rc":[{"atb":[[2.9,0]],"id":43189000}],"con":true,"img":false}]}
{"op":"mcm","clk":"5321531397","pt":1646310700122,"mc":[{"id":"1.195532856","rc":[{"atb":[[3.1,3.2]],"id":42609837}],"con":true,"img":false}]}
{"op":"mcm","clk":"5321531487","pt":1646310700792,"mc":[{"id":"1.195532856","rc":[{"atb":[[2.82,3.69]],"id":41555102}],"con":true,"img":false}]}
{"op":"mcm","clk":"5321531835","pt":1646310703908,"mc":[{"id":"1.195532856","rc":[{"atb":[[2.56,6.36]],"id":43189001}],"con":true,"img":false}]}
{"op":"mcm","clk":"5321531845","pt":1646310704009,"mc":[{"id":"1.195532856","rc":[{"atb":[[2.98,6.27]],"id":43189000}],"con":true,"img":false}]}
{"op":"mcm","clk":"5321532564","pt":1646310711034,"mc":[{"id":"1.195532856","rc":[{"atb":[[2.5,0]],"id":43189001}],"con":true,"img":false}]}
{"op":"mcm","clk":"5321533727","pt":1646310722334,"mc":[{"id":"1.195532856","rc":[{"spn":6.28,"spf":1.0,"id":43189001},{"atb":[[2.76,0]],"id":41555102}],"con":true,"img":false}]}
{"op":"mcm","clk":"5321534536","pt":1646310728934,"mc":[{"id":"1.195532856","rc":[{"atb":[[2.82,0]],"id":41555102}],"con":true,"img":false}]}
{"op":"mcm","clk":"5321534869","pt":1646310732148,"mc":[{"id":"1.195532856","rc":[{"atb":[[2.62,4.15]],"id":43189001}],"con":true,"img":false}]}
{"op":"mcm","clk":"5321534939","pt":1646310732821,"mc":[{"id":"1.195532856","rc":[{"atl":[[34,15.5]],"id":43189000},{"atl":[[17,9.5],[34,15.5]],"id":41555102},{"atb":[[2.62,64.81]],"id":42931075},{"atb":[[2.62,64.81]],"id":39330606},{"atl":[[34,15.5]],"id":39330606},{"atl":[[34,15.5]],"id":42609837}],"con":true,"img":false}]}
{"op":"mcm","clk":"5321535440","pt":1646310737744,"mc":[{"id":"1.195532856","rc":[{"atb":[[2.56,0]],"id":43189001}],"con":true,"img":false}]}
{"op":"mcm","clk":"5321535486","pt":1646310738261,"mc":[{"id":"1.195532856","rc":[{"atb":[[3.85,0]],"id":42931075},{"atb":[[3.05,0]],"id":39330606}],"con":true,"img":false}]}
{"op":"mcm","clk":"5321535622","pt":1646310739655,"mc":[{"id":"1.195532856","rc":[{"atl":[[8.4,1.65]],"id":43189000}],"con":true,"img":false}]}
{"op":"mcm","clk":"5321535631","pt":1646310739761,"mc":[{"id":"1.195532856","rc":[{"atb":[[2.64,1.65]],"id":43189001}],"con":true,"img":false}]}
{"op":"mcm","clk":"5321535742","pt":1646310740948,"mc":[{"id":"1.195532856","rc":[{"atb":[[4.1,3.61]],"id":42931075},{"atb":[[3.25,4.98]],"id":39330606}],"con":true,"img":false}]}
{"op":"mcm","clk":"5321536389","pt":1646310747576,"mc":[{"id":"1.195532856","rc":[{"atb":[[2.62,0]],"id":43189001}],"con":true,"img":false}]}
{"op":"mcm","clk":"5321536647","pt":1646310750057,"mc":[{"id":"1.195532856","rc":[{"atb":[[2.7,10.54]],"id":41555102}],"con":true,"img":false}]}
{"op":"mcm","clk":"5321538009","pt":1646310765062,"mc":[{"id":"1.195532856","rc":[{"atb":[[2.76,5.63]],"id":41555102}],"con":true,"img":false}]}
{"op":"mcm","clk":"5321538320","pt":1646310768179,"mc":[{"id":"1.195532856","rc":[{"atb":[[2.28,5.25]],"id":43189001}],"con":true,"img":false}]}
{"op":"mcm","clk":"5321538885","pt":1646310773965,"mc":[{"id":"1.195532856","rc":[{"atb":[[2.7,6.59]],"id":41555102}],"con":true,"img":false}]}
{"op":"mcm","clk":"5321540946","pt":1646310795028,"mc":[{"id":"1.195532856","rc":[{"spn":6.8,"spf":1.0,"id":43189000},{"spn":6.32,"spf":1.0,"id":43189001},{"atb":[[2.82,3.69]],"id":41555102}],"con":true,"img":false}]}
{"op":"mcm","clk":"5321541215","pt":1646310797946,"mc":[{"id":"1.195532856","rc":[{"atb":[[2.24,0]],"id":43189001}],"con":true,"img":false}]}
{"op":"mcm","clk":"5321541223","pt":1646310798051,"mc":[{"id":"1.195532856","rc":[{"atb":[[2.3,10.14]],"id":43189001}],"con":true,"img":false}]}
{"op":"mcm","clk":"5321542198","pt":1646310807058,"mc":[{"id":"1.195532856","rc":[{"atb":[[2.28,0]],"id":43189001}],"con":true,"img":false}]}
{"op":"mcm","clk":"5321542902","pt":1646310813121,"mc":[{"id":"1.195532856","rc":[{"atb":[[2.76,0]],"id":41555102}],"con":true,"img":false}]}
{"op":"mcm","clk":"5321542938","pt":1646310813434,"mc":[{"id":"1.195532856","rc":[{"atb":[[2.94,0]],"id":42609837}],"con":true,"img":false}]}
{"op":"mcm","clk":"5321543861","pt":1646310822211,"mc":[{"id":"1.195532856","rc":[{"atb":[[2.82,0]],"id":41555102}],"con":true,"img":false}]}
{"op":"mcm","clk":"5321544554","pt":1646310828237,"mc":[{"id":"1.195532856","rc":[{"atb":[[2.34,5.02]],"id":43189001}],"con":true,"img":false}]}
{"op":"mcm","clk":"5321544568","pt":1646310828338,"mc":[{"id":"1.195532856","rc":[{"atb":[[2.34,12.42]],"id":43189001}],"con":true,"img":false}]}
{"op":"mcm","clk":"5321544578","pt":1646310828444,"mc":[{"id":"1.195532856","rc":[{"atb":[[3.05,10.9]],"id":42609837}],"con":true,"img":false}]}
{"op":"mcm","clk":"5321545563","pt":1646310838143,"mc":[{"id":"1.195532856","rc":[{"atb":[[2.34,7.4]],"id":43189001}],"con":true,"img":false}]}
{"op":"mcm","clk":"5321546022","pt":1646310842863,"mc":[{"id":"1.195532856","rc":[{"atb":[[2.64,0]],"id":41555102}],"con":true,"img":false}]}
{"op":"mcm","clk":"5321546051","pt":1646310843173,"mc":[{"id":"1.195532856","rc":[{"atb":[[2.7,10.54]],"id":41555102}],"con":true,"img":false}]}
{"op":"mcm","clk":"5321547157","pt":1646310852160,"mc":[{"id":"1.195532856","rc":[{"atb":[[2.7,6.59]],"id":41555102}],"con":true,"img":false}]}
{"op":"mcm","clk":"5321547536","pt":1646310855071,"mc":[{"id":"1.195532856","rc":[{"atb":[[2.7,0]],"id":41555102}],"con":true,"img":false}]}
{"op":"mcm","clk":"5321547887","pt":1646310857875,"mc":[{"id":"1.195532856","rc":[{"atb":[[2.36,9.13]],"id":41555102}],"con":true,"img":false}]}
{"op":"mcm","clk":"5321547904","pt":1646310858106,"mc":[{"id":"1.195532856","rc":[{"atb":[[2.36,17.38]],"id":41555102}],"con":true,"img":false}]}
{"op":"mcm","clk":"5321548243","pt":1646310861299,"mc":[{"id":"1.195532856","rc":[{"atb":[[2.38,4.87]],"id":43189001}],"con":true,"img":false}]}
{"op":"mcm","clk":"5321551304","pt":1646310884950,"mc":[{"id":"1.195532856","rc":[{"atb":[[2.34,0]],"id":43189001}],"con":true,"img":false}]}
{"op":"mcm","clk":"5321551815","pt":1646310889055,"mc":[{"id":"1.195532856","rc":[{"atb":[[2.4,4.8]],"id":41555102}],"con":true,"img":false}]}
{"op":"mcm","clk":"5321552467","pt":1646310894252,"mc":[{"id":"1.195532856","rc":[{"atb":[[2.38,0]],"id":43189001}],"con":true,"img":false}]}
{"op":"mcm","clk":"5321554578","pt":1646310915773,"mc":[{"id":"1.195532856","rc":[{"atb":[[2.34,5.02]],"id":43189001}],"con":true,"img":false}]}
{"op":"mcm","clk":"5321555187","pt":1646310921803,"mc":[{"id":"1.195532856","rc":[{"atb":[[2.94,0]],"id":43189000}],"con":true,"img":false}]}
{"op":"mcm","clk":"5321555498","pt":1646310924774,"mc":[{"id":"1.195532856","rc":[{"atb":[[3.05,5.47]],"id":43189000}],"con":true,"img":false}]}
{"op":"mcm","clk":"5321555512","pt":1646310924981,"mc":[{"id":"1.195532856","rc":[{"atb":[[2.44,6.89]],"id":41555102}],"con":true,"img":false}]}
{"op":"mcm","clk":"5321556569","pt":1646310936393,"mc":[{"id":"1.195532856","rc":[{"atb":[[2.4,0]],"id":41555102}],"con":true,"img":false}]}
{"op":"mcm","clk":"5321558311","pt":1646310954313,"mc":[{"id":"1.195532856","rc":[{"atb":[[2.44,0]],"id":41555102}],"con":true,"img":false}]}
{"op":"mcm","clk":"5321558326","pt":1646310954516,"mc":[{"id":"1.195532856","rc":[{"atb":[[2.38,7.19]],"id":43189001}],"con":true,"img":false}]}
{"op":"mcm","clk":"5321559439","pt":1646310966861,"mc":[{"id":"1.195532856","rc":[{"atb":[[2.34,0]],"id":43189001}],"con":true,"img":false}]}
{"op":"mcm","clk":"5321559616","pt":1646310968736,"mc":[{"id":"1.195532856","rc":[{"atb":[[2.4,7.09]],"id":41555102}],"con":true,"img":false}]}
{"op":"mcm","clk":"5321560728","pt":1646310981459,"mc":[{"id":"1.195532856","rc":[{"atb":[[2.38,0]],"id":43189001}],"con":true,"img":false}]}
{"op":"mcm","clk":"5321561916","pt":1646310995989,"mc":[{"id":"1.195532856","rc":[{"atb":[[2.34,7.4]],"id":43189001}],"con":true,"img":false}]}
{"op":"mcm","clk":"5321561940","pt":1646310996400,"mc":[{"id":"1.195532856","rc":[{"atb":[[3.95,0]],"id":42931075},{"atb":[[3.15,0]],"id":39330606}],"con":true,"img":false}]}
{"op":"mcm","clk":"5321561956","pt":1646310996604,"mc":[{"id":"1.195532856","rc":[{"atb":[[2.44,4.67]],"id":41555102}],"con":true,"img":false}]}
{"op":"mcm","clk":"5321564029","pt":1646311010650,"mc":[{"id":"1.195532856","rc":[{"atb":[[4.3,3.76]],"id":42931075}],"con":true,"img":false}]}
{"op":"mcm","clk":"5321564040","pt":1646311010706,"mc":[{"id":"1.195532856","rc":[{"atb":[[3.35,5.28]],"id":39330606}],"con":true,"img":false}]}
{"op":"mcm","clk":"5321566170","pt":1646311024460,"mc":[{"id":"1.195532856","rc":[{"atb":[[2.38,4.87]],"id":43189001}],"con":true,"img":false}]}
{"op":"mcm","clk":"5321566296","pt":1646311025763,"mc":[{"id":"1.195532856","rc":[{"atb":[[2.4,0]],"id":41555102}],"con":true,"img":false}]}
{"op":"mcm","clk":"5321567278","pt":1646311035564,"mc":[{"id":"1.195532856","rc":[{"atb":[[2.44,0]],"id":41555102}],"con":true,"img":false}]}
{"op":"mcm","clk":"5321567695","pt":1646311040793,"mc":[{"id":"1.195532856","rc":[{"atb":[[2.34,0]],"id":43189001}],"con":true,"img":false}]}
{"op":"mcm","clk":"5321568329","pt":1646311047475,"mc":[{"id":"1.195532856","rc":[{"atb":[[2.98,0]],"id":42609837}],"con":true,"img":false}]}
{"op":"mcm","clk":"5321568342","pt":1646311047578,"mc":[{"id":"1.195532856","rc":[{"atb":[[2.38,0]],"id":43189001}],"con":true,"img":false}]}
{"op":"mcm","clk":"5321568645","pt":1646311050799,"mc":[{"id":"1.195532856","rc":[{"atb":[[2.38,8.12]],"id":42609837}],"con":true,"img":false}]}
{"op":"mcm","clk":"5321569186","pt":1646311056823,"mc":[{"id":"1.195532856","rc":[{"atb":[[2.4,4.8]],"id":41555102}],"con":true,"img":false}]}
{"op":"mcm","clk":"5321570150","pt":1646311068662,"mc":[{"id":"1.195532856","rc":[{"atb":[[2.34,5.02]],"id":43189001}],"con":true,"img":false}]}
{"op":"mcm","clk":"5321570383","pt":1646311071869,"mc":[{"id":"1.195532856","rc":[{"atb":[[3.05,6.06]],"id":42609837}],"con":true,"img":false}]}
{"op":"mcm","clk":"5321571426","pt":1646311084192,"mc":[{"id":"1.195532856","rc":[{"atb":[[2.42,6.99]],"id":42609837}],"con":true,"img":false}]}
{"op":"mcm","clk":"5321572304","pt":1646311093311,"mc":[{"id":"1.195532856","rc":[{"atb":[[2.36,9.13]],"id":41555102}],"con":true,"img":false}]}
{"op":"mcm","clk":"5321572722","pt":1646311098322,"mc":[{"id":"1.195532856","rc":[{"atb":[[2.3,0]],"id":43189001}],"con":true,"img":false}]}
{"op":"mcm","clk":"5321572731","pt":1646311098388,"mc":[{"id":"1.195532856","rc":[{"atb":[[2.36,10.14]],"id":43189001}],"con":true,"img":false}]}
{"op":"mcm","clk":"5321572774","pt":1646311098901,"mc":[{"id":"1.195532856","rc":[{"atb":[[2.4,12.8]],"id":41555102}],"con":true,"img":false}]}
{"op":"mcm","clk":"5321573351","pt":1646311104804,"mc":[{"id":"1.195532856","rc":[{"atb":[[2.34,0]],"id":43189001}],"con":true,"img":false}]}
{"op":"mcm","clk":"5321573552","pt":1646311107135,"mc":[{"id":"1.195532856","rc":[{"atb":[[2.36,0]],"id":41555102}],"con":true,"img":false}]}
{"op":"mcm","clk":"5321573569","pt":1646311107303,"mc":[{"id":"1.195532856","rc":[{"atb":[[2.44,6.89]],"id":41555102}],"con":true,"img":false}]}
{"op":"mcm","clk":"5321574114","pt":1646311113841,"mc":[{"id":"1.195532856","rc":[{"atb":[[2.4,8]],"id":41555102}],"con":true,"img":false}]}
{"op":"mcm","clk":"5321574652","pt":1646311118940,"mc":[{"id":"1.195532856","rc":[{"atb":[[2.44,15.52]],"id":41555102}],"con":true,"img":false}]}
{"op":"mcm","clk":"5321575268","pt":1646311125844,"mc":[{"id":"1.195532856","rc":[{"atb":[[2.4,4.8]],"id":43189001}],"con":true,"img":false}]}
{"op":"mcm","clk":"5321576037","pt":1646311135053,"mc":[{"id":"1.195532856","rc":[{"atb":[[2.48,4.54]],"id":41555102}],"con":true,"img":false}]}
{"op":"mcm","clk":"5321578881","pt":1646311164361,"mc":[{"id":"1.195532856","rc":[{"atb":[[2.98,0]],"id":43189000},{"atb":[[2.44,6.89]],"id":43189001}],"con":true,"img":false}]}
{"op":"mcm","clk":"5321578945","pt":1646311164939,"mc":[{"id":"1.195532856","rc":[{"atb":[[2.44,8.63]],"id":41555102}],"con":true,"img":false}]}
{"op":"mcm","clk":"5321580349","pt":1646311175490,"mc":[{"id":"1.195532856","rc":[{"atb":[[2.4,0]],"id":43189001}],"con":true,"img":false}]}
{"op":"mcm","clk":"5321581160","pt":1646311182360,"mc":[{"id":"1.195532856","rc":[{"atb":[[3.15,5.78]],"id":43189000},{"atb":[[2.52,6.52]],"id":41555102}],"con":true,"img":false}]}
{"op":"mcm","clk":"5321581978","pt":1646311189192,"mc":[{"id":"1.195532856","rc":[{"atb":[[2.48,0]],"id":41555102}],"con":true,"img":false}]}
{"op":"mcm","clk":"5321582933","pt":1646311195107,"mc":[{"id":"1.195532856","rc":[{"atb":[[2.48,4.54]],"id":43189001}],"con":true,"img":false}]}
{"op":"mcm","clk":"5321583277","pt":1646311198019,"mc":[{"id":"1.195532856","rc":[{"atb":[[2.44,0]],"id":43189001}],"con":true,"img":false}]}
{"op":"mcm","clk":"5321584023","pt":1646311209439,"mc":[{"id":"1.195532856","rc":[{"atb":[[2.52,0]],"id":41555102}],"con":true,"img":false}]}
{"op":"mcm","clk":"5321584070","pt":1646311210113,"mc":[{"id":"1.195532856","rc":[{"atb":[[2.48,0]],"id":43189001}],"con":true,"img":false}]}
{"op":"mcm","clk":"5321585170","pt":1646311228044,"mc":[{"id":"1.195532856","rc":[{"atb":[[2.4,4.8]],"id":43189001}],"con":true,"img":false}]}
{"op":"mcm","clk":"5321585381","pt":1646311231247,"mc":[{"id":"1.195532856","rc":[{"atb":[[4.1,0]],"id":42931075},{"atb":[[3.25,0]],"id":39330606}],"con":true,"img":false}]}
{"op":"mcm","clk":"5321585537","pt":1646311233975,"mc":[{"id":"1.195532856","rc":[{"atb":[[4.5,3.2]],"id":42931075},{"atb":[[3.45,4.57]],"id":39330606}],"con":true,"img":false}]}
{"op":"mcm","clk":"5321585680","pt":1646311236446,"mc":[{"id":"1.195532856","rc":[{"atb":[[2.44,15.52]],"id":41555102}],"con":true,"img":false}]}
{"op":"mcm","clk":"5321585762","pt":1646311237374,"mc":[{"id":"1.195532856","rc":[{"atb":[[2.48,4.54]],"id":41555102}],"con":true,"img":false}]}
{"op":"mcm","clk":"5321587188","pt":1646311260089,"mc":[{"id":"1.195532856","rc":[{"atb":[[2.44,8.63]],"id":41555102}],"con":true,"img":false}]}
{"op":"mcm","clk":"5321588047","pt":1646311272189,"mc":[{"id":"1.195532856","rc":[{"atb":[[2.44,6.89]],"id":43189001}],"con":true,"img":false}]}
{"op":"mcm","clk":"5321588526","pt":1646311278996,"mc":[{"id":"1.195532856","rc":[{"atb":[[2.4,0]],"id":43189001}],"con":true,"img":false}]}
{"op":"mcm","clk":"5321588841","pt":1646311284901,"mc":[{"id":"1.195532856","rc":[{"atb":[[2.52,6.52]],"id":41555102}],"con":true,"img":false}]}
{"op":"mcm","clk":"5321589899","pt":1646311294045,"mc":[{"id":"1.195532856","rc":[{"atb":[[2.48,0]],"id":41555102}],"con":true,"img":false}]}
{"op":"mcm","clk":"5321590492","pt":1646311299410,"mc":[{"id":"1.195532856","rc":[{"atb":[[3.05,0]],"id":42609837}],"con":true,"img":false}]}
{"op":"mcm","clk":"5321590559","pt":1646311299741,"mc":[{"id":"1.195532856","rc":[{"atb":[[2.44,0]],"id":43189001}],"con":true,"img":false}]}
{"op":"mcm","clk":"5321590596","pt":1646311300158,"mc":[{"id":"1.195532856","rc":[{"atb":[[2.48,4.54]],"id":43189001}],"con":true,"img":false}]}
{"op":"mcm","clk":"5321591217","pt":1646311306455,"mc":[{"id":"1.195532856","rc":[{"atb":[[3.1,0]],"id":42609837}],"con":true,"img":false}]}
{"op":"mcm","clk":"5321591490","pt":1646311309020,"mc":[{"id":"1.195532856","rc":[{"atb":[[2.48,0]],"id":43189001}],"con":true,"img":false}]}
{"op":"mcm","clk":"5321591760","pt":1646311312046,"mc":[{"id":"1.195532856","rc":[{"atb":[[2.4,7.09]],"id":43189001},{"atb":[[2.42,15.74]],"id":42609837}],"con":true,"img":false}]}
{"op":"mcm","clk":"5321591777","pt":1646311312257,"mc":[{"id":"1.195532856","rc":[{"atb":[[2.52,0]],"id":41555102}],"con":true,"img":false}]}
{"op":"mcm","clk":"5321592040","pt":1646311315171,"mc":[{"id":"1.195532856","rc":[{"atb":[[2.38,0]],"id":42609837}],"con":true,"img":false}]}
{"op":"mcm","clk":"5321592734","pt":1646311321191,"mc":[{"id":"1.195532856","rc":[{"atb":[[2.46,7.67]],"id":42609837}],"con":true,"img":false}]}
{"op":"mcm","clk":"5321593365","pt":1646311326527,"mc":[{"id":"1.195532856","rc":[{"atb":[[2.44,15.52]],"id":41555102}],"con":true,"img":false}]}
{"op":"mcm","clk":"5321593466","pt":1646311327187,"mc":[{"id":"1.195532856","rc":[{"atb":[[2.46,12.27]],"id":42609837}],"con":true,"img":false}]}
{"op":"mcm","clk":"5321594775","pt":1646311339398,"mc":[{"id":"1.195532856","rc":[{"atb":[[2.4,0]],"id":41555102}],"con":true,"img":false}]}
{"op":"mcm","clk":"5321595043","pt":1646311342336,"mc":[{"id":"1.195532856","rc":[{"atb":[[2.44,4.67]],"id":43189001},{"atb":[[2.48,7.57]],"id":41555102}],"con":true,"img":false}]}
{"op":"mcm","clk":"5321595068","pt":1646311342495,"mc":[{"id":"1.195532856","rc":[{"atb":[[2.48,12.12]],"id":41555102}],"con":true,"img":false}]}
{"op":"mcm","clk":"5321595079","pt":1646311342599,"mc":[{"id":"1.195532856","rc":[{"atb":[[2.42,8.74]],"id":42609837}],"con":true,"img":false}]}
{"op":"mcm","clk":"5321596295","pt":1646311356826,"mc":[{"id":"1.195532856","rc":[{"atb":[[2.5,6.61]],"id":42609837}],"con":true,"img":false}]}
{"op":"mcm","clk":"5321596346","pt":1646311357444,"mc":[{"id":"1.195532856","rc":[{"atb":[[2.44,8.63]],"id":41555102}],"con":true,"img":false}]}
{"op":"mcm","clk":"5321597214","pt":1646311366372,"mc":[{"id":"1.195532856","rc":[{"atb":[[2.46,7.67]],"id":42609837}],"con":true,"img":false}]}
{"op":"mcm","clk":"5321597439","pt":1646311368572,"mc":[{"id":"1.195532856","rc":[{"atb":[[2.4,0]],"id":43189001}],"con":true,"img":false}]}
{"op":"mcm","clk":"5321598081","pt":1646311375677,"mc":[{"id":"1.195532856","rc":[{"atb":[[2.44,0]],"id":43189001}],"con":true,"img":false}]}
{"op":"mcm","clk":"5321598530","pt":1646311380601,"mc":[{"id":"1.195532856","rc":[{"atb":[[2.44,0]],"id":41555102}],"con":true,"img":false}]}
{"op":"mcm","clk":"5321599152","pt":1646311387118,"mc":[{"id":"1.195532856","rc":[{"atb":[[2.48,7.57]],"id":41555102},{"atb":[[2.56,4.31]],"id":42609837}],"con":true,"img":false}]}
{"op":"mcm","clk":"5321599617","pt":1646311392509,"mc":[{"id":"1.195532856","rc":[{"atb":[[2.52,6.52]],"id":41555102}],"con":true,"img":false}]}
{"op":"mcm","clk":"5321599627","pt":1646311392609,"mc":[{"id":"1.195532856","rc":[{"atb":[[2.52,14.7]],"id":41555102}],"con":true,"img":false}]}
{"op":"mcm","clk":"5321599910","pt":1646311396210,"mc":[{"id":"1.195532856","rc":[{"atb":[[2.4,4.8]],"id":43189001}],"con":true,"img":false}]}
{"op":"mcm","clk":"5321600227","pt":1646311399909,"mc":[{"id":"1.195532856","rc":[{"atb":[[3.05,0]],"id":43189000}],"con":true,"img":false}]}
{"op":"mcm","clk":"5321600624","pt":1646311405134,"mc":[{"id":"1.195532856","rc":[{"atb":[[2.5,0]],"id":42609837}],"con":true,"img":false}]}
{"op":"mcm","clk":"5321600656","pt":1646311405450,"mc":[{"id":"1.195532856","rc":[{"atb":[[3.25,4.98]],"id":43189000}],"con":true,"img":false}]}
{"op":"mcm","clk":"5321601863","pt":1646311420851,"mc":[{"id":"1.195532856","rc":[{"atb":[[2.56,0]],"id":42609837}],"con":true,"img":false}]}
{"op":"mcm","clk":"5321601869","pt":1646311420954,"mc":[{"id":"1.195532856","rc":[{"atb":[[2.58,4.25]],"id":41555102}],"con":true,"img":false}]}
{"op":"mcm","clk":"5321603056","pt":1646311434961,"mc":[{"id":"1.195532856","rc":[{"atb":[[2.44,6.89]],"id":43189001}],"con":true,"img":false}]}
{"op":"mcm","clk":"5321603664","pt":1646311442380,"mc":[{"id":"1.195532856","rc":[{"atb":[[2.46,12.27]],"id":42609837}],"con":true,"img":false}]}
{"op":"mcm","clk":"5321603681","pt":1646311442589,"mc":[{"id":"1.195532856","rc":[{"atb":[[2.4,0]],"id":43189001}],"con":true,"img":false}]}
{"op":"mcm","clk":"5321604442","pt":1646311451308,"mc":[{"id":"1.195532856","rc":[{"atb":[[2.52,8.17]],"id":41555102}],"con":true,"img":false}]}
{"op":"mcm","clk":"5321605803","pt":1646311467831,"mc":[{"id":"1.195532856","rc":[{"atb":[[2.5,6.61]],"id":42609837}],"con":true,"img":false}]}
{"op":"mcm","clk":"5321605864","pt":1646311468608,"mc":[{"id":"1.195532856","rc":[{"atb":[[2.44,0]],"id":43189001},{"atb":[[4.3,0]],"id":42931075},{"atb":[[3.35,0]],"id":39330606}],"con":true,"img":false}]}
{"op":"mcm","clk":"5321605885","pt":1646311468917,"mc":[{"id":"1.195532856","rc":[{"atb":[[2.64,6.05]],"id":41555102}],"con":true,"img":false}]}
{"op":"mcm","clk":"5321606309","pt":1646311474662,"mc":[{"id":"1.195532856","rc":[{"atb":[[2.46,7.67]],"id":42609837}],"con":true,"img":false}]}
{"op":"mcm","clk":"5321606564","pt":1646311477347,"mc":[{"id":"1.195532856","rc":[{"atb":[[2.58,0]],"id":41555102}],"con":true,"img":false}]}
{"op":"mcm","clk":"5321607151","pt":1646311484465,"mc":[{"id":"1.195532856","rc":[{"atb":[[3.55,4.87]],"id":39330606}],"con":true,"img":false}]}
{"op":"mcm","clk":"5321607169","pt":1646311484676,"mc":[{"id":"1.195532856","rc":[{"atb":[[4.7,3.35]],"id":42931075}],"con":true,"img":false}]}
{"op":"mcm","clk":"5321607198","pt":1646311484983,"mc":[{"id":"1.195532856","rc":[{"atb":[[2.4,7.09]],"id":43189001}],"con":true,"img":false}]}
{"op":"mcm","clk":"5321608700","pt":1646311502268,"mc":[{"id":"1.195532856","rc":[{"atb":[[2.7,3.95]],"id":41555102}],"con":true,"img":false}]}
{"op":"mcm","clk":"5321608734","pt":1646311502578,"mc":[{"id":"1.195532856","rc":[{"atb":[[2.56,4.31]],"id":42609837}],"con":true,"img":false}]}
{"op":"mcm","clk":"5321609907","pt":1646311513809,"mc":[{"id":"1.195532856","rc":[{"atb":[[2.44,4.67]],"id":43189001}],"con":true,"img":false}]}
{"op":"mcm","clk":"5321617597","pt":1646311591644,"mc":[{"id":"1.195532856","rc":[{"atb":[[2.46,0]],"id":42609837}],"con":true,"img":false}]}
{"op":"mcm","clk":"5321617895","pt":1646311594654,"mc":[{"id":"1.195532856","rc":[{"atb":[[2.54,7.27]],"id":42609837}],"con":true,"img":false}]}
{"op":"mcm","clk":"5321617954","pt":1646311595376,"mc":[{"id":"1.195532856","rc":[{"atb":[[2.42,0]],"id":42609837}],"con":true,"img":false}]}
{"op":"mcm","clk":"5321618014","pt":1646311595953,"mc":[{"id":"1.195532856","rc":[{"atb":[[2.64,0]],"id":41555102}],"con":true,"img":false}]}
{"op":"mcm","clk":"5321618774","pt":1646311603662,"mc":[{"id":"1.195532856","rc":[{"atb":[[2.7,0]],"id":41555102}],"con":true,"img":false}]}
{"op":"mcm","clk":"5321620001","pt":1646311613201,"mc":[{"id":"1.195532856","rc":[{"atb":[[2.48,0]],"id":41555102}],"con":true,"img":false}]}
{"op":"mcm","clk":"5321620282","pt":1646311615885,"mc":[{"id":"1.195532856","rc":[{"atb":[[2.56,7.18]],"id":41555102}],"con":true,"img":false}]}
{"op":"mcm","clk":"5321620415","pt":1646311617184,"mc":[{"id":"1.195532856","rc":[{"atb":[[2.6,7.77]],"id":42609837}],"con":true,"img":false}]}
{"op":"mcm","clk":"5321620446","pt":1646311617496,"mc":[{"id":"1.195532856","rc":[{"atb":[[2.4,0]],"id":43189001},{"atb":[[2.5,0]],"id":42609837}],"con":true,"img":false}]}
{"op":"mcm","clk":"5321621131","pt":1646311624887,"mc":[{"id":"1.195532856","rc":[{"atb":[[2.44,0]],"id":43189001},{"atb":[[2.56,0]],"id":42609837}],"con":true,"img":false}]}
{"op":"mcm","clk":"5321621166","pt":1646311625303,"mc":[{"id":"1.195532856","rc":[{"atb":[[2.58,4.25]],"id":41555102}],"con":true,"img":false}]}
{"op":"mcm","clk":"5321622356","pt":1646311636525,"mc":[{"id":"1.195532856","rc":[{"atb":[[3.15,0]],"id":43189000}],"con":true,"img":false}]}
{"op":"mcm","clk":"5321623445","pt":1646311646839,"mc":[{"id":"1.195532856","rc":[{"atb":[[2.4,4.8]],"id":43189001},{"atb":[[2.66,4.05]],"id":42609837}],"con":true,"img":false}]}
{"op":"mcm","clk":"5321623839","pt":1646311650835,"mc":[{"id":"1.195532856","rc":[{"atb":[[3.35,5.28]],"id":43189000}],"con":true,"img":false}]}
{"op":"mcm","clk":"5321629167","pt":1646311704626,"mc":[{"id":"1.195532856","rc":[{"atb":[[4.5,0]],"id":42931075},{"atb":[[3.45,0]],"id":39330606}],"con":true,"img":false}]}
{"op":"mcm","clk":"5321629611","pt":1646311709240,"mc":[{"id":"1.195532856","rc":[{"atb":[[3.65,4.22]],"id":39330606}],"con":true,"img":false}]}
{"op":"mcm","clk":"5321638546","pt":1646311803945,"mc":[{"id":"1.195532856","rc":[{"atb":[[2.64,6.05]],"id":41555102}],"con":true,"img":false}]}
{"op":"mcm","clk":"5321638595","pt":1646311804362,"mc":[{"id":"1.195532856","rc":[{"atb":[[2.52,0]],"id":41555102}],"con":true,"img":false}]}
{"op":"mcm","clk":"5321639323","pt":1646311811584,"mc":[{"id":"1.195532856","rc":[{"atb":[[2.58,0]],"id":41555102}],"con":true,"img":false}]}
{"op":"mcm","clk":"5321642378","pt":1646311829033,"mc":[{"id":"1.195532856","rc":[{"atb":[[2.72,5.76]],"id":42609837}],"con":true,"img":false}]}
{"op":"mcm","clk":"5321642580","pt":1646311830342,"mc":[{"id":"1.195532856","rc":[{"atb":[[2.44,6.89]],"id":43189001}],"con":true,"img":false}]}
{"op":"mcm","clk":"5321642981","pt":1646311832693,"mc":[{"id":"1.195532856","rc":[{"atb":[[2.7,3.95]],"id":41555102}],"con":true,"img":false}]}
{"op":"mcm","clk":"5321643802","pt":1646311837919,"mc":[{"id":"1.195532856","rc":[{"atb":[[2.74,7.14]],"id":41555102}],"con":true,"img":false}]}
{"op":"mcm","clk":"5321643908","pt":1646311838547,"mc":[{"id":"1.195532856","rc":[{"atb":[[2.4,0]],"id":43189001},{"atb":[[2.66,0]],"id":42609837}],"con":true,"img":false}]}
{"op":"mcm","clk":"5321644900","pt":1646311844744,"mc":[{"id":"1.195532856","rc":[{"atb":[[2.7,0]],"id":41555102}],"con":true,"img":false}]}
{"op":"mcm","clk":"5321645636","pt":1646311850455,"mc":[{"id":"1.195532856","rc":[{"atb":[[2.54,0]],"id":42609837}],"con":true,"img":false}]}
{"op":"mcm","clk":"5321646136","pt":1646311854243,"mc":[{"id":"1.195532856","rc":[{"atb":[[2.76,6.36]],"id":42609837}],"con":true,"img":false}]}
{"op":"mcm","clk":"5321646751","pt":1646311859892,"mc":[{"id":"1.195532856","rc":[{"atb":[[2.78,3.78]],"id":42609837}],"con":true,"img":false}]}
{"op":"mcm","clk":"5321646770","pt":1646311860052,"mc":[{"id":"1.195532856","rc":[{"atb":[[2.48,4.54]],"id":43189001}],"con":true,"img":false}]}
{"op":"mcm","clk":"5321646953","pt":1646311861685,"mc":[{"id":"1.195532856","rc":[{"atb":[[2.64,0]],"id":41555102}],"con":true,"img":false}]}
{"op":"mcm","clk":"5321647401","pt":1646311865789,"mc":[{"id":"1.195532856","rc":[{"atb":[[2.8,3.73]],"id":41555102}],"con":true,"img":false}]}
{"op":"mcm","clk":"5321648330","pt":1646311874984,"mc":[{"id":"1.195532856","rc":[{"atb":[[3.25,0]],"id":43189000}],"con":true,"img":false}]}
{"op":"mcm","clk":"5321648479","pt":1646311876484,"mc":[{"id":"1.195532856","rc":[{"atb":[[2.44,0]],"id":43189001},{"atb":[[2.72,0]],"id":42609837}],"con":true,"img":false}]}
{"op":"mcm","clk":"5321648527","pt":1646311876998,"mc":[{"id":"1.195532856","rc":[{"atb":[[2.6,0]],"id":42609837}],"con":true,"img":false}]}
{"op":"mcm","clk":"5321649014","pt":1646311881483,"mc":[{"id":"1.195532856","rc":[{"atb":[[3.45,4.57]],"id":43189000}],"con":true,"img":false}]}
{"op":"mcm","clk":"5321649928","pt":1646311887718,"mc":[{"id":"1.195532856","rc":[{"atb":[[2.48,0]],"id":43189001},{"atb":[[2.78,0]],"id":42609837}],"con":true,"img":false}]}
{"op":"mcm","clk":"5321650345","pt":1646311891427,"mc":[{"id":"1.195532856","rc":[{"atb":[[2.8,6.9]],"id":42609837}],"con":true,"img":false}]}
{"op":"mcm","clk":"5321651704","pt":1646311904331,"mc":[{"id":"1.195532856","rc":[{"atb":[[2.86,5.33]],"id":41555102}],"con":true,"img":false}]}
{"op":"mcm","clk":"5321651970","pt":1646311907225,"mc":[{"id":"1.195532856","rc":[{"atb":[[2.4,4.8]],"id":43189001}],"con":true,"img":false}]}
{"op":"mcm","clk":"5321652509","pt":1646311913477,"mc":[{"id":"1.195532856","rc":[{"atb":[[2.8,0]],"id":41555102}],"con":true,"img":false}]}
{"op":"mcm","clk":"5321653109","pt":1646311919368,"mc":[{"id":"1.195532856","rc":[{"atb":[[2.86,3.61]],"id":42609837}],"con":true,"img":false}]}
{"op":"mcm","clk":"5321653165","pt":1646311919935,"mc":[{"id":"1.195532856","rc":[{"atb":[[2.82,5.45]],"id":42609837}],"con":true,"img":false}]}
{"op":"mcm","clk":"5321654191","pt":1646311928351,"mc":[{"id":"1.195532856","rc":[{"atb":[[2.86,0]],"id":42609837}],"con":true,"img":false}]}
{"op":"mcm","clk":"5321655103","pt":1646311934692,"mc":[{"id":"1.195532856","rc":[{"atb":[[2.92,3.5]],"id":41555102}],"con":true,"img":false}]}
{"op":"mcm","clk":"5321655344","pt":1646311936877,"mc":[{"id":"1.195532856","rc":[{"atb":[[2.86,0]],"id":41555102}],"con":true,"img":false}]}
{"op":"mcm","clk":"5321656546","pt":1646311947543,"mc":[{"id":"1.195532856","rc":[{"atb":[[2.92,0]],"id":41555102}],"con":true,"img":false}]}
{"op":"mcm","clk":"5321656745","pt":1646311949552,"mc":[{"id":"1.195532856","rc":[{"atb":[[2.88,3.57]],"id":42609837}],"con":true,"img":false}]}
{"op":"mcm","clk":"5321657368","pt":1646311955269,"mc":[{"id":"1.195532856","rc":[{"atb":[[2.44,6.89]],"id":43189001}],"con":true,"img":false}]}
{"op":"mcm","clk":"5321658444","pt":1646311964681,"mc":[{"id":"1.195532856","rc":[{"atb":[[2.4,0]],"id":43189001}],"con":true,"img":false}]}
{"op":"mcm","clk":"5321658767","pt":1646311967487,"mc":[{"id":"1.195532856","rc":[{"atb":[[2.8,3.73]],"id":41555102}],"con":true,"img":false}]}
{"op":"mcm","clk":"5321658778","pt":1646311967590,"mc":[{"id":"1.195532856","rc":[{"atb":[[2.82,0]],"id":42609837}],"con":true,"img":false}]}
{"op":"mcm","clk":"5321660073","pt":1646311979392,"mc":[{"id":"1.195532856","rc":[{"atb":[[2.44,0]],"id":43189001}],"con":true,"img":false}]}
{"op":"mcm","clk":"5321660128","pt":1646311979910,"mc":[{"id":"1.195532856","rc":[{"atb":[[2.88,0]],"id":42609837}],"con":true,"img":false}]}
{"op":"mcm","clk":"5321662232","pt":1646311999149,"mc":[{"id":"1.195532856","rc":[{"atb":[[2.86,3.61]],"id":42609837}],"con":true,"img":false}]}
{"op":"mcm","clk":"5321662789","pt":1646312003881,"mc":[{"id":"1.195532856","rc":[{"atb":[[2.4,7.09]],"id":43189001}],"con":true,"img":false}]}
{"op":"mcm","clk":"5321664696","pt":1646312016173,"mc":[{"id":"1.195532856","rc":[{"atb":[[2.86,5.33]],"id":41555102}],"con":true,"img":false}]}
{"op":"mcm","clk":"5321665957","pt":1646312025239,"mc":[{"id":"1.195532856","rc":[{"atb":[[2.8,0]],"id":41555102}],"con":true,"img":false}]}
{"op":"mcm","clk":"5321666714","pt":1646312031267,"mc":[{"id":"1.195532856","rc":[{"atb":[[2.92,5.16]],"id":42609837}],"con":true,"img":false}]}
{"op":"mcm","clk":"5321667388","pt":1646312037182,"mc":[{"id":"1.195532856","rc":[{"atb":[[2.56,0]],"id":41555102}],"con":true,"img":false}]}
{"op":"mcm","clk":"5321667398","pt":1646312037287,"mc":[{"id":"1.195532856","rc":[{"atb":[[2.44,4.67]],"id":43189001}],"con":true,"img":false}]}
{"op":"mcm","clk":"5321667747","pt":1646312040357,"mc":[{"id":"1.195532856","rc":[{"atb":[[2.86,0]],"id":42609837}],"con":true,"img":false}]}
{"op":"mcm","clk":"5321667759","pt":1646312040460,"mc":[{"id":"1.195532856","rc":[{"atb":[[2.78,6.29]],"id":41555102}],"con":true,"img":false}]}
{"op":"mcm","clk":"5321668415","pt":1646312046380,"mc":[{"id":"1.195532856","rc":[{"atb":[[2.92,3.5]],"id":41555102}],"con":true,"img":false}]}
{"op":"mcm","clk":"5321668510","pt":1646312047113,"mc":[{"id":"1.195532856","rc":[{"atb":[[4.7,0]],"id":42931075},{"atb":[[3.55,0]],"id":39330606}],"con":true,"img":false}]}
{"op":"mcm","clk":"5321668594","pt":1646312047695,"mc":[{"id":"1.195532856","rc":[{"atb":[[2.86,0]],"id":41555102}],"con":true,"img":false}]}
{"op":"mcm","clk":"5321668765","pt":1646312049090,"mc":[{"id":"1.195532856","rc":[{"atb":[[2.76,6.36]],"id":42931075}],"con":true,"img":false}]}
{"op":"mcm","clk":"5321669465","pt":1646312055081,"mc":[{"id":"1.195532856","rc":[{"atb":[[2.92,0]],"id":41555102}],"con":true,"img":false}]}
{"op":"mcm","clk":"5321670394","pt":1646312063619,"mc":[{"id":"1.195532856","rc":[{"atb":[[2.4,0]],"id":43189001},{"atb":[[2.92,0]],"id":42609837}],"con":true,"img":false}]}
{"op":"mcm","clk":"5321670425","pt":1646312063930,"mc":[{"id":"1.195532856","rc":[{"atb":[[3.75,4.51]],"id":39330606}],"con":true,"img":false}]}
{"op":"mcm","clk":"5321670457","pt":1646312064184,"mc":[{"id":"1.195532856","rc":[{"atb":[[2.8,6.9]],"id":42931075}],"con":true,"img":false}]}
{"op":"mcm","clk":"5321671242","pt":1646312071431,"mc":[{"id":"1.195532856","rc":[{"atb":[[2.44,0]],"id":43189001}],"con":true,"img":false}]}
{"op":"mcm","clk":"5321672306","pt":1646312082449,"mc":[{"id":"1.195532856","rc":[{"atb":[[2.84,5.39]],"id":41555102}],"con":true,"img":false}]}
{"op":"mcm","clk":"5321672333","pt":1646312082756,"mc":[{"id":"1.195532856","rc":[{"atb":[[2.8,3.73]],"id":41555102}],"con":true,"img":false}]}
{"op":"mcm","clk":"5321672345","pt":1646312082862,"mc":[{"id":"1.195532856","rc":[{"atb":[[2.82,5.45]],"id":42609837}],"con":true,"img":false}]}
{"op":"mcm","clk":"5321673189","pt":1646312091534,"mc":[{"id":"1.195532856","rc":[{"atb":[[2.4,4.8]],"id":43189001}],"con":true,"img":false}]}
{"op":"mcm","clk":"5321673427","pt":1646312094086,"mc":[{"id":"1.195532856","rc":[{"atb":[[2.8,0]],"id":41555102}],"con":true,"img":false}]}
{"op":"mcm","clk":"5321673733","pt":1646312096961,"mc":[{"id":"1.195532856","rc":[{"atb":[[2.74,0]],"id":41555102}],"con":true,"img":false}]}
{"op":"mcm","clk":"5321675125","pt":1646312111997,"mc":[{"id":"1.195532856","rc":[{"atb":[[2.76,0]],"id":42609837}],"con":true,"img":false}]}
{"op":"mcm","clk":"5321675367","pt":1646312115167,"mc":[{"id":"1.195532856","rc":[{"atb":[[2.88,3.57]],"id":42609837}],"con":true,"img":false}]}
{"op":"mcm","clk":"5321675387","pt":1646312115482,"mc":[{"id":"1.195532856","rc":[{"atb":[[2.9,3.54]],"id":41555102},{"atb":[[2.86,6.02]],"id":42609837}],"con":true,"img":false}]}
{"op":"mcm","clk":"5321675454","pt":1646312116204,"mc":[{"id":"1.195532856","rc":[{"atb":[[2.82,6.82]],"id":41555102}],"con":true,"img":false}]}
{"op":"mcm","clk":"5321675481","pt":1646312116473,"mc":[{"id":"1.195532856","rc":[{"atb":[[3.35,0]],"id":43189000}],"con":true,"img":false}]}
{"op":"mcm","clk":"5321677444","pt":1646312138307,"mc":[{"id":"1.195532856","rc":[{"atb":[[2.82,0]],"id":42609837}],"con":true,"img":false}]}
{"op":"mcm","clk":"5321677468","pt":1646312138622,"mc":[{"id":"1.195532856","rc":[{"atb":[[3.55,4.87]],"id":43189000},{"atb":[[2.44,6.89]],"id":43189001}],"con":true,"img":false}]}
{"op":"mcm","clk":"5321678002","pt":1646312144945,"mc":[{"id":"1.195532856","rc":[{"atb":[[2.4,0]],"id":43189001},{"atb":[[2.88,0]],"id":42609837}],"con":true,"img":false}]}
{"op":"mcm","clk":"5321679074","pt":1646312157799,"mc":[{"id":"1.195532856","rc":[{"atb":[[2.84,0]],"id":41555102}],"con":true,"img":false}]}
{"op":"mcm","clk":"5321679768","pt":1646312166581,"mc":[{"id":"1.195532856","rc":[{"atb":[[2.48,4.54]],"id":43189001}],"con":true,"img":false}]}
{"op":"mcm","clk":"5321679774","pt":1646312166683,"mc":[{"id":"1.195532856","rc":[{"atb":[[2.86,9.63]],"id":42609837}],"con":true,"img":false}]}
{"op":"mcm","clk":"5321679786","pt":1646312166889,"mc":[{"id":"1.195532856","rc":[{"atb":[[2.9,0]],"id":41555102}],"con":true,"img":false}]}
{"op":"mcm","clk":"5321680204","pt":1646312171976,"mc":[{"id":"1.195532856","rc":[{"atb":[[2.44,0]],"id":43189001}],"con":true,"img":false}]}
{"op":"mcm","clk":"5321680982","pt":1646312179300,"mc":[{"id":"1.195532856","rc":[{"atb":[[2.48,0]],"id":43189001}],"con":true,"img":false}]}
{"op":"mcm","clk":"5321681626","pt":1646312184408,"mc":[{"id":"1.195532856","rc":[{"atb":[[2.92,5.16]],"id":42609837}],"con":true,"img":false}]}
{"op":"mcm","clk":"5321681869","pt":1646312187107,"mc":[{"id":"1.195532856","rc":[{"atb":[[2.88,3.57]],"id":41555102}],"con":true,"img":false}]}
{"op":"mcm","clk":"5321682385","pt":1646312193045,"mc":[{"id":"1.195532856","rc":[{"atb":[[2.86,6.02]],"id":42609837}],"con":true,"img":false}]}
{"op":"mcm","clk":"5321682920","pt":1646312199134,"mc":[{"id":"1.195532856","rc":[{"atb":[[2.4,4.8]],"id":43189001}],"con":true,"img":false}]}
{"op":"mcm","clk":"5321682940","pt":1646312199342,"mc":[{"id":"1.195532856","rc":[{"atb":[[2.8,0]],"id":42609837}],"con":true,"img":false}]}
{"op":"mcm","clk":"5321683968","pt":1646312211041,"mc":[{"id":"1.195532856","rc":[{"atb":[[2.9,6.53]],"id":42609837}],"con":true,"img":false}]}
{"op":"mcm","clk":"5321684238","pt":1646312214151,"mc":[{"id":"1.195532856","rc":[{"atb":[[2.98,3.4]],"id":42609837}],"con":true,"img":false}]}
{"op":"mcm","clk":"5321686289","pt":1646312238811,"mc":[{"id":"1.195532856","rc":[{"atb":[[2.92,0]],"id":42609837}],"con":true,"img":false}]}
{"op":"mcm","clk":"5321686299","pt":1646312238913,"mc":[{"id":"1.195532856","rc":[{"atb":[[2.44,6.89]],"id":43189001}],"con":true,"img":false}]}
{"op":"mcm","clk":"5321686313","pt":1646312239118,"mc":[{"id":"1.195532856","rc":[{"atb":[[2.94,5.11]],"id":41555102}],"con":true,"img":false}]}
{"op":"mcm","clk":"5321687064","pt":1646312247742,"mc":[{"id":"1.195532856","rc":[{"atb":[[2.4,0]],"id":43189001},{"atb":[[2.88,0]],"id":41555102},{"atb":[[2.98,0]],"id":42609837}],"con":true,"img":false}]}
{"op":"mcm","clk":"5321688371","pt":1646312265440,"mc":[{"id":"1.195532856","rc":[{"atb":[[2.44,0]],"id":43189001},{"atb":[[2.94,0]],"id":41555102}],"con":true,"img":false}]}
{"op":"mcm","clk":"5321688588","pt":1646312268153,"mc":[{"id":"1.195532856","rc":[{"atb":[[2.96,3.42]],"id":42609837}],"con":true,"img":false}]}
{"op":"mcm","clk":"5321689526","pt":1646312280703,"mc":[{"id":"1.195532856","rc":[{"atb":[[3.65,0]],"id":39330606}],"con":true,"img":false}]}
{"op":"mcm","clk":"5321689742","pt":1646312283516,"mc":[{"id":"1.195532856","rc":[{"atb":[[3.85,3.93]],"id":39330606}],"con":true,"img":false}]}
{"op":"mcm","clk":"5321690272","pt":1646312290216,"mc":[{"id":"1.195532856","rc":[{"atb":[[2.4,7.09]],"id":43189001}],"con":true,"img":false}]}
{"op":"mcm","clk":"5321690326","pt":1646312290937,"mc":[{"id":"1.195532856","rc":[{"atb":[[2.84,5.39]],"id":41555102}],"con":true,"img":false}]}
{"op":"mcm","clk":"5321690750","pt":1646312295841,"mc":[{"id":"1.195532856","rc":[{"atb":[[2.76,0]],"id":42931075}],"con":true,"img":false}]}
{"op":"mcm","clk":"5321690960","pt":1646312298234,"mc":[{"id":"1.195532856","rc":[{"atb":[[2.84,6.09]],"id":42931075}],"con":true,"img":false}]}
{"op":"mcm","clk":"5321691454","pt":1646312304952,"mc":[{"id":"1.195532856","rc":[{"atb":[[3,4.96]],"id":42609837}],"con":true,"img":false}]}
{"op":"mcm","clk":"5321692042","pt":1646312313672,"mc":[{"id":"1.195532856","rc":[{"atb":[[2.96,0]],"id":42609837}],"con":true,"img":false}]}
{"op":"mcm","clk":"5321693202","pt":1646312327580,"mc":[{"id":"1.195532856","rc":[{"atb":[[2.9,3.54]],"id":41555102}],"con":true,"img":false}]}
{"op":"mcm","clk":"5321693235","pt":1646312327989,"mc":[{"id":"1.195532856","rc":[{"atb":[[2.44,4.67]],"id":43189001}],"con":true,"img":false}]}
{"op":"mcm","clk":"5321693547","pt":1646312331614,"mc":[{"id":"1.195532856","rc":[{"atb":[[2.78,0]],"id":41555102}],"con":true,"img":false}]}
{"op":"mcm","clk":"5321693765","pt":1646312334813,"mc":[{"id":"1.195532856","rc":[{"atb":[[3.05,3.28]],"id":42609837}],"con":true,"img":false}]}
{"op":"mcm","clk":"5321693790","pt":1646312335079,"mc":[{"id":"1.195532856","rc":[{"atb":[[2.36,8.24]],"id":41555102}],"con":true,"img":false}]}
{"op":"mcm","clk":"5321694089","pt":1646312339211,"mc":[{"id":"1.195532856","rc":[{"atb":[[3,0]],"id":42609837}],"con":true,"img":false}]}
{"op":"mcm","clk":"5321694872","pt":1646312346948,"mc":[{"id":"1.195532856","rc":[{"atb":[[3.05,0]],"id":42609837}],"con":true,"img":false}]}
{"op":"mcm","clk":"5321695123","pt":1646312349450,"mc":[{"id":"1.195532856","rc":[{"atb":[[3.45,0]],"id":43189000}],"con":true,"img":false}]}
{"op":"mcm","clk":"5321695419","pt":1646312352437,"mc":[{"id":"1.195532856","rc":[{"atb":[[2.4,0]],"id":43189001},{"atb":[[2.84,0]],"id":41555102}],"con":true,"img":false}]}
{"op":"mcm","clk":"5321696294","pt":1646312361854,"mc":[{"id":"1.195532856","rc":[{"atb":[[2.44,0]],"id":43189001},{"atb":[[2.9,0]],"id":41555102}],"con":true,"img":false}]}
{"op":"mcm","clk":"5321697137","pt":1646312370562,"mc":[{"id":"1.195532856","rc":[{"atb":[[2.86,0]],"id":42609837}],"con":true,"img":false}]}
{"op":"mcm","clk":"5321699321","pt":1646312392622,"mc":[{"id":"1.195532856","rc":[{"atb":[[2.4,7.09]],"id":43189001}],"con":true,"img":false}]}
{"op":"mcm","clk":"5321699393","pt":1646312393308,"mc":[{"id":"1.195532856","rc":[{"atb":[[2.4,7.09]],"id":41555102}],"con":true,"img":false}]}
{"op":"mcm","clk":"5321700276","pt":1646312401201,"mc":[{"id":"1.195532856","rc":[{"atb":[[2.38,8.12]],"id":43189000}],"con":true,"img":false}]}
{"op":"mcm","clk":"5321700296","pt":1646312401359,"mc":[{"id":"1.195532856","rc":[{"atb":[[2.88,3.57]],"id":41555102},{"atb":[[2.94,5.77]],"id":42609837}],"con":true,"img":false}]}
{"op":"mcm","clk":"5321700372","pt":1646312401939,"mc":[{"id":"1.195532856","rc":[{"atb":[[2.96,3.42]],"id":42609837}],"con":true,"img":false}]}
{"op":"mcm","clk":"5321702476","pt":1646312421766,"mc":[{"id":"1.195532856","rc":[{"atb":[[2.38,8.12],[3.55,4.86],[2.34,8.44]],"id":43189000},{"atl":[[8.4,1.65]],"id":43189000},{"atb":[[2.4,7.08],[2.36,10.13],[2.64,1.65],[2.44,4.67]],"id":43189001},{"atb":[[2.82,6.82],[2.4,7.08],[2.36,8.24],[2.88,3.58],[2.32,12.54]],"id":41555102},{"atb":[[2.8,6.89],[2.84,6.09],[2.08,10.43]],"id":42931075},{"atb":[[3.85,3.93],[2.06,11.19],[3.75,4.51]],"id":39330606},{"atb":[[2.9,6.53],[2.96,3.43],[2.94,5.77],[2.34,10.23]],"id":42609837}],"con":true,"img":false}]}
{"op":"mcm","clk":"5321702499","pt":1646312422073,"mc":[{"id":"1.195532856","rc":[{"atb":[[2.4,0]],"id":41555102}],"con":true,"img":false}]}
{"op":"mcm","clk":"5321703863","pt":1646312437210,"mc":[{"id":"1.195532856","rc":[{"atb":[[2.94,5.11]],"id":41555102}],"con":true,"img":false}]}
{"op":"mcm","clk":"5321703905","pt":1646312437629,"mc":[{"id":"1.195532856","rc":[{"atb":[[3,4.95]],"id":42609837}],"con":true,"img":false}]}
{"op":"mcm","clk":"5321704651","pt":1646312445752,"mc":[{"id":"1.195532856","rc":[{"atb":[[2.88,0]],"id":41555102},{"atb":[[2.96,0]],"id":42609837}],"con":true,"img":false}]}
{"op":"mcm","clk":"5321705204","pt":1646312451944,"mc":[{"id":"1.195532856","rc":[{"atb":[[2.4,0]],"id":43189001}],"con":true,"img":false}]}
{"op":"mcm","clk":"5321705872","pt":1646312460749,"mc":[{"id":"1.195532856","rc":[{"atb":[[2.44,0]],"id":43189001}],"con":true,"img":false}]}
{"op":"mcm","clk":"5321706141","pt":1646312464263,"mc":[{"id":"1.195532856","rc":[{"atb":[[2.9,0]],"id":42609837}],"con":true,"img":false}]}
{"op":"mcm","clk":"5321706160","pt":1646312464467,"mc":[{"id":"1.195532856","rc":[{"atb":[[2.94,0]],"id":41555102}],"con":true,"img":false}]}
{"op":"mcm","clk":"5321706346","pt":1646312466952,"mc":[{"id":"1.195532856","rc":[{"atb":[[3.05,3.28]],"id":42609837}],"con":true,"img":false}]}
{"op":"mcm","clk":"5321707338","pt":1646312478402,"mc":[{"id":"1.195532856","rc":[{"atb":[[2.4,7.08]],"id":41555102}],"con":true,"img":false}]}
{"op":"mcm","clk":"5321707347","pt":1646312478494,"mc":[{"id":"1.195532856","rc":[{"atb":[[2.98,6.27]],"id":42609837}],"con":true,"img":false}]}
{"op":"mcm","clk":"5321707675","pt":1646312481897,"mc":[{"id":"1.195532856","rc":[{"atb":[[2.4,4.8]],"id":43189001}],"con":true,"img":false}]}
{"op":"mcm","clk":"5321708716","pt":1646312493901,"mc":[{"id":"1.195532856","rc":[{"atb":[[2.88,3.58]],"id":41555102}],"con":true,"img":false}]}
{"op":"mcm","clk":"5321708807","pt":1646312494724,"mc":[{"id":"1.195532856","rc":[{"atb":[[3,0]],"id":42609837}],"con":true,"img":false}]}
{"op":"mcm","clk":"5321710358","pt":1646312509914,"mc":[{"id":"1.195532856","rc":[{"atb":[[2.4,0]],"id":41555102},{"atb":[[3.1,4.72]],"id":42609837}],"con":true,"img":false}]}
{"op":"mcm","clk":"5321711134","pt":1646312518226,"mc":[{"id":"1.195532856","rc":[{"atb":[[3.05,0]],"id":42609837}],"con":true,"img":false}]}
{"op":"mcm","clk":"5321711923","pt":1646312526534,"mc":[{"id":"1.195532856","rc":[{"atb":[[2.44,6.88]],"id":43189001}],"con":true,"img":false}]}
{"op":"mcm","clk":"5321711949","pt":1646312526845,"mc":[{"id":"1.195532856","rc":[{"atb":[[3.75,0]],"id":39330606}],"con":true,"img":false}]}
{"op":"mcm","clk":"5321711998","pt":1646312527365,"mc":[{"id":"1.195532856","rc":[{"atb":[[2.94,5.11]],"id":41555102}],"con":true,"img":false}]}
{"op":"mcm","clk":"5321712879","pt":1646312536279,"mc":[{"id":"1.195532856","rc":[{"atb":[[2.4,0]],"id":43189001},{"atb":[[2.88,0]],"id":41555102}],"con":true,"img":false}]}
{"op":"mcm","clk":"5321713122","pt":1646312538783,"mc":[{"id":"1.195532856","rc":[{"atb":[[3.15,3.13]],"id":42609837}],"con":true,"img":false}]}
{"op":"mcm","clk":"5321713445","pt":1646312541873,"mc":[{"id":"1.195532856","rc":[{"atb":[[3.95,4.2]],"id":39330606}],"con":true,"img":false}]}
{"op":"mcm","clk":"5321713501","pt":1646312542489,"mc":[{"id":"1.195532856","rc":[{"atb":[[2.8,0]],"id":42931075}],"con":true,"img":false}]}
{"op":"mcm","clk":"5321713515","pt":1646312542697,"mc":[{"id":"1.195532856","rc":[{"atb":[[3.1,0]],"id":42609837}],"con":true,"img":false}]}
{"op":"mcm","clk":"5321714303","pt":1646312551473,"mc":[{"id":"1.195532856","rc":[{"atb":[[3.15,0]],"id":42609837}],"con":true,"img":false}]}
{"op":"mcm","clk":"5321714797","pt":1646312557275,"mc":[{"id":"1.195532856","rc":[{"atb":[[3,3.36]],"id":41555102}],"con":true,"img":false}]}
{"op":"mcm","clk":"5321714816","pt":1646312557483,"mc":[{"id":"1.195532856","rc":[{"atb":[[2.44,0]],"id":43189001},{"atb":[[2.94,0]],"id":41555102}],"con":true,"img":false}]}
{"op":"mcm","clk":"5321714845","pt":1646312557801,"mc":[{"id":"1.195532856","rc":[{"atb":[[2.48,4.54]],"id":43189001},{"atb":[[3,4.95]],"id":42609837}],"con":true,"img":false}]}
{"op":"mcm","clk":"5321714869","pt":1646312558002,"mc":[{"id":"1.195532856","rc":[{"atb":[[2.88,6.6]],"id":42931075}],"con":true,"img":false}]}
{"op":"mcm","clk":"5321716062","pt":1646312572305,"mc":[{"id":"1.195532856","rc":[{"atb":[[2.48,0]],"id":43189001},{"atb":[[3,0]],"id":41555102}],"con":true,"img":false}]}
{"op":"mcm","clk":"5321716137","pt":1646312573138,"mc":[{"id":"1.195532856","rc":[{"atb":[[2.82,0]],"id":41555102}],"con":true,"img":false}]}
{"op":"mcm","clk":"5321717658","pt":1646312589840,"mc":[{"id":"1.195532856","rc":[{"atb":[[2.4,4.8]],"id":43189001}],"con":true,"img":false}]}
{"op":"mcm","clk":"5321717668","pt":1646312589890,"mc":[{"id":"1.195532856","rc":[{"atb":[[3.05,3.28]],"id":42609837}],"con":true,"img":false}]}
{"op":"mcm","clk":"5321718114","pt":1646312594835,"mc":[{"id":"1.195532856","rc":[{"atb":[[3.55,0]],"id":43189000}],"con":true,"img":false}]}
{"op":"mcm","clk":"5321718126","pt":1646312594938,"mc":[{"id":"1.195532856","rc":[{"atb":[[2.4,8.86]],"id":41555102}],"con":true,"img":false}]}
{"op":"mcm","clk":"5321719838","pt":1646312614430,"mc":[{"id":"1.195532856","rc":[{"atb":[[3,0]],"id":42609837}],"con":true,"img":false}]}
{"op":"mcm","clk":"5321719869","pt":1646312614740,"mc":[{"id":"1.195532856","rc":[{"atb":[[2.42,8.74]],"id":43189000}],"con":true,"img":false}]}
{"op":"mcm","clk":"5321720671","pt":1646312623346,"mc":[{"id":"1.195532856","rc":[{"atb":[[2.44,4.67]],"id":41555102}],"con":true,"img":false}]}
{"op":"mcm","clk":"5321720908","pt":1646312625749,"mc":[{"id":"1.195532856","rc":[{"atb":[[2.36,0]],"id":41555102}],"con":true,"img":false}]}
{"op":"mcm","clk":"5321721191","pt":1646312628880,"mc":[{"id":"1.195532856","rc":[{"atb":[[2.44,12.46]],"id":41555102}],"con":true,"img":false}]}
{"op":"mcm","clk":"5321721542","pt":1646312632788,"mc":[{"id":"1.195532856","rc":[{"atb":[[2.44,6.88]],"id":43189001}],"con":true,"img":false}]}
{"op":"mcm","clk":"5321721634","pt":1646312633680,"mc":[{"id":"1.195532856","rc":[{"atb":[[3.1,4.72]],"id":42609837}],"con":true,"img":false}]}
{"op":"mcm","clk":"5321722765","pt":1646312644501,"mc":[{"id":"1.195532856","rc":[{"atb":[[2.4,0]],"id":43189001},{"atb":[[3.05,0]],"id":42609837}],"con":true,"img":false}]}
{"op":"mcm","clk":"5321724281","pt":1646312659159,"mc":[{"id":"1.195532856","rc":[{"atb":[[2.44,0]],"id":43189001},{"atb":[[3.1,0]],"id":42609837}],"con":true,"img":false}]}
{"op":"mcm","clk":"5321724292","pt":1646312659214,"mc":[{"id":"1.195532856","rc":[{"atb":[[2.48,6.69]],"id":41555102}],"con":true,"img":false}]}
{"op":"mcm","clk":"5321725248","pt":1646312668237,"mc":[{"id":"1.195532856","rc":[{"atb":[[2.44,7.79]],"id":41555102}],"con":true,"img":false}]}
{"op":"mcm","clk":"5321725563","pt":1646312671149,"mc":[{"id":"1.195532856","rc":[{"atb":[[2.94,0]],"id":42609837}],"con":true,"img":false}]}
{"op":"mcm","clk":"5321725824","pt":1646312673945,"mc":[{"id":"1.195532856","rc":[{"atb":[[3.05,5.47]],"id":42609837}],"con":true,"img":false}]}
{"op":"mcm","clk":"5321726866","pt":1646312683797,"mc":[{"id":"1.195532856","rc":[{"atb":[[2.4,7.08]],"id":43189001}],"con":true,"img":false}]}
{"op":"mcm","clk":"5321727445","pt":1646312689204,"mc":[{"id":"1.195532856","rc":[{"atb":[[2.52,4.42]],"id":41555102}],"con":true,"img":false}]}
{"op":"mcm","clk":"5321727469","pt":1646312689411,"mc":[{"id":"1.195532856","rc":[{"atb":[[3.05,8.75]],"id":42609837}],"con":true,"img":false}]}
{"op":"mcm","clk":"5321729858","pt":1646312710926,"mc":[{"id":"1.195532856","rc":[{"atb":[[3.1,4.72]],"id":42609837}],"con":true,"img":false}]}
{"op":"mcm","clk":"5321729872","pt":1646312710973,"mc":[{"id":"1.195532856","rc":[{"atb":[[2.48,0]],"id":41555102}],"con":true,"img":false}]}
{"op":"mcm","clk":"5321730160","pt":1646312713734,"mc":[{"id":"1.195532856","rc":[{"atb":[[2.44,4.67]],"id":43189001}],"con":true,"img":false}]}
{"op":"mcm","clk":"5321730764","pt":1646312719415,"mc":[{"id":"1.195532856","rc":[{"atb":[[2.52,0]],"id":41555102},{"atb":[[3.05,5.47]],"id":42609837}],"con":true,"img":false}]}
{"op":"mcm","clk":"5321732449","pt":1646312735933,"mc":[{"id":"1.195532856","rc":[{"atb":[[2.4,0]],"id":43189001}],"con":true,"img":false}]}
{"op":"mcm","clk":"5321732460","pt":1646312736037,"mc":[{"id":"1.195532856","rc":[{"atb":[[2.98,0]],"id":42609837}],"con":true,"img":false}]}
{"op":"mcm","clk":"5321732890","pt":1646312740217,"mc":[{"id":"1.195532856","rc":[{"atb":[[2.44,12.46]],"id":41555102}],"con":true,"img":false}]}
{"op":"mcm","clk":"5321732900","pt":1646312740372,"mc":[{"id":"1.195532856","rc":[{"atb":[[3.15,3.13]],"id":42609837}],"con":true,"img":false}]}
{"op":"mcm","clk":"5321733259","pt":1646312743643,"mc":[{"id":"1.195532856","rc":[{"atb":[[2.44,0]],"id":43189001}],"con":true,"img":false}]}
{"op":"mcm","clk":"5321733953","pt":1646312749975,"mc":[{"id":"1.195532856","rc":[{"atb":[[2.48,6.69]],"id":41555102}],"con":true,"img":false}]}
{"op":"mcm","clk":"5321733985","pt":1646312750282,"mc":[{"id":"1.195532856","rc":[{"atb":[[2.38,8.99]],"id":42609837}],"con":true,"img":false}]}
{"op":"mcm","clk":"5321734889","pt":1646312758478,"mc":[{"id":"1.195532856","rc":[{"atb":[[2.44,7.79]],"id":41555102}],"con":true,"img":false}]}
{"op":"mcm","clk":"5321735190","pt":1646312761184,"mc":[{"id":"1.195532856","rc":[{"atb":[[3.85,0]],"id":39330606}],"con":true,"img":false}]}
{"op":"mcm","clk":"5321735525","pt":1646312764272,"mc":[{"id":"1.195532856","rc":[{"atb":[[2.66,6.75]],"id":39330606}],"con":true,"img":false}]}
{"op":"mcm","clk":"5321735559","pt":1646312764583,"mc":[{"id":"1.195532856","rc":[{"atb":[[2.4,4.8]],"id":43189001}],"con":true,"img":false}]}
{"op":"mcm","clk":"5321736906","pt":1646312777119,"mc":[{"id":"1.195532856","rc":[{"atb":[[2.84,0]],"id":42931075}],"con":true,"img":false}]}
{"op":"mcm","clk":"5321737450","pt":1646312782541,"mc":[{"id":"1.195532856","rc":[{"atb":[[2.52,4.42]],"id":41555102}],"con":true,"img":false}]}
{"op":"mcm","clk":"5321737469","pt":1646312782740,"mc":[{"id":"1.195532856","rc":[{"atb":[[2.92,5.83]],"id":42931075}],"con":true,"img":false}]}
{"op":"mcm","clk":"5321738778","pt":1646312795239,"mc":[{"id":"1.195532856","rc":[{"atb":[[2.44,6.88]],"id":43189001}],"con":true,"img":false}]}
{"op":"mcm","clk":"5321739737","pt":1646312805851,"mc":[{"id":"1.195532856","rc":[{"atb":[[2.4,0]],"id":43189001}],"con":true,"img":false}]}
{"op":"mcm","clk":"5321740180","pt":1646312810568,"mc":[{"id":"1.195532856","rc":[{"atb":[[2.48,0]],"id":41555102}],"con":true,"img":false}]}
{"op":"mcm","clk":"5321741367","pt":1646312819043,"mc":[{"id":"1.195532856","rc":[{"atb":[[2.52,0]],"id":41555102}],"con":true,"img":false}]}
{"op":"mcm","clk":"5321741974","pt":1646312824756,"mc":[{"id":"1.195532856","rc":[{"atb":[[2.48,4.54]],"id":43189001}],"con":true,"img":false}]}
{"op":"mcm","clk":"5321742038","pt":1646312825378,"mc":[{"id":"1.195532856","rc":[{"atb":[[2.44,0]],"id":43189001}],"con":true,"img":false}]}
{"op":"mcm","clk":"5321743024","pt":1646312833904,"mc":[{"id":"1.195532856","rc":[{"atb":[[2.48,0]],"id":43189001}],"con":true,"img":false}]}
{"op":"mcm","clk":"5321743871","pt":1646312840143,"mc":[{"id":"1.195532856","rc":[{"atb":[[2.44,12.46]],"id":41555102}],"con":true,"img":false}]}
{"op":"mcm","clk":"5321743937","pt":1646312840648,"mc":[{"id":"1.195532856","rc":[{"atb":[[2.4,7.08]],"id":43189001}],"con":true,"img":false}]}
{"op":"mcm","clk":"5321745095","pt":1646312848641,"mc":[{"id":"1.195532856","rc":[{"atb":[[2.38,0]],"id":43189000}],"con":true,"img":false}]}
{"op":"mcm","clk":"5321745496","pt":1646312851963,"mc":[{"id":"1.195532856","rc":[{"atb":[[2.46,7.67]],"id":43189000}],"con":true,"img":false}]}
{"op":"mcm","clk":"5321745636","pt":1646312853059,"mc":[{"id":"1.195532856","rc":[{"atb":[[2.48,6.69]],"id":41555102}],"con":true,"img":false}]}
{"op":"mcm","clk":"5321746898","pt":1646312861151,"mc":[{"id":"1.195532856","rc":[{"atb":[[2.44,7.79]],"id":41555102}],"con":true,"img":false}]}
{"op":"mcm","clk":"5321747970","pt":1646312869780,"mc":[{"id":"1.195532856","rc":[{"atb":[[2.44,4.67]],"id":43189001}],"con":true,"img":false}]}
{"op":"mcm","clk":"5321747987","pt":1646312869981,"mc":[{"id":"1.195532856","rc":[{"atb":[[2.4,0]],"id":41555102}],"con":true,"img":false}]}
{"op":"mcm","clk":"5321749126","pt":1646312881764,"mc":[{"id":"1.195532856","rc":[{"atb":[[2.52,4.42]],"id":41555102}],"con":true,"img":false}]}
{"op":"mcm","clk":"5321749514","pt":1646312885817,"mc":[{"id":"1.195532856","rc":[{"atb":[[2.56,7.96]],"id":41555102}],"con":true,"img":false}]}
{"op":"mcm","clk":"5321750336","pt":1646312894133,"mc":[{"id":"1.195532856","rc":[{"atb":[[2.44,0]],"id":41555102}],"con":true,"img":false}]}
{"op":"mcm","clk":"5321750367","pt":1646312894351,"mc":[{"id":"1.195532856","rc":[{"atb":[[2.52,0]],"id":41555102}],"con":true,"img":false}]}
{"op":"mcm","clk":"5321750793","pt":1646312897013,"mc":[{"id":"1.195532856","rc":[{"atb":[[2.6,7.01]],"id":41555102}],"con":true,"img":false}]}
{"op":"mcm","clk":"5321751192","pt":1646312900041,"mc":[{"id":"1.195532856","rc":[{"atb":[[2.4,0]],"id":43189001},{"atb":[[2.48,0]],"id":41555102}],"con":true,"img":false}]}
{"op":"mcm","clk":"5321752319","pt":1646312909127,"mc":[{"id":"1.195532856","rc":[{"atb":[[2.44,0]],"id":43189001}],"con":true,"img":false}]}
{"op":"mcm","clk":"5321753204","pt":1646312916364,"mc":[{"id":"1.195532856","rc":[{"atb":[[2.62,4.15]],"id":41555102}],"con":true,"img":false}]}
{"op":"mcm","clk":"5321754496","pt":1646312927096,"mc":[{"id":"1.195532856","rc":[{"atb":[[2.4,4.8]],"id":43189001}],"con":true,"img":false}]}
{"op":"mcm","clk":"5321757987","pt":1646312956812,"mc":[{"id":"1.195532856","rc":[{"atb":[[2.44,6.88]],"id":43189001}],"con":true,"img":false}]}
{"op":"mcm","clk":"5321758027","pt":1646312957015,"mc":[{"id":"1.195532856","rc":[{"atb":[[2.68,5.9]],"id":41555102}],"con":true,"img":false}]}
{"op":"mcm","clk":"5321759865","pt":1646312969093,"mc":[{"id":"1.195532856","rc":[{"atb":[[3.05,0]],"id":42609837}],"con":true,"img":false}]}
{"op":"mcm","clk":"5321759877","pt":1646312969148,"mc":[{"id":"1.195532856","rc":[{"atb":[[2.4,0]],"id":43189001},{"atb":[[2.62,0]],"id":41555102}],"con":true,"img":false}]}
{"op":"mcm","clk":"5321760264","pt":1646312972277,"mc":[{"id":"1.195532856","rc":[{"atb":[[2.42,7.89]],"id":42609837}],"con":true,"img":false}]}
{"op":"mcm","clk":"5321761948","pt":1646312986984,"mc":[{"id":"1.195532856","rc":[{"atb":[[2.48,4.54]],"id":43189001}],"con":true,"img":false}]}
{"op":"mcm","clk":"5321761973","pt":1646312987186,"mc":[{"id":"1.195532856","rc":[{"atb":[[2.74,3.86]],"id":41555102}],"con":true,"img":false}]}
{"op":"mcm","clk":"5321762118","pt":1646312988324,"mc":[{"id":"1.195532856","rc":[{"atb":[[2.44,0]],"id":43189001},{"atb":[[2.68,0]],"id":41555102},{"atb":[[3.1,0]],"id":42609837}],"con":true,"img":false}]}
{"op":"mcm","clk":"5321763082","pt":1646312996601,"mc":[{"id":"1.195532856","rc":[{"atb":[[2.48,0]],"id":43189001},{"atb":[[2.74,0]],"id":41555102},{"atb":[[3.15,0]],"id":42609837}],"con":true,"img":false}]}
{"op":"mcm","clk":"5321764258","pt":1646313005834,"mc":[{"id":"1.195532856","rc":[{"atb":[[3.95,0]],"id":39330606}],"con":true,"img":false}]}
{"op":"mcm","clk":"5321764278","pt":1646313006033,"mc":[{"id":"1.195532856","rc":[{"atb":[[2.66,5.96]],"id":41555102}],"con":true,"img":false}]}
{"op":"mcm","clk":"5321764288","pt":1646313006143,"mc":[{"id":"1.195532856","rc":[{"atb":[[2.4,7.08]],"id":43189001}],"con":true,"img":false}]}
{"op":"mcm","clk":"5321765733","pt":1646313018168,"mc":[{"id":"1.195532856","rc":[{"atb":[[2.42,12.63]],"id":42609837}],"con":true,"img":false}]}
{"op":"mcm","clk":"5321766034","pt":1646313020967,"mc":[{"id":"1.195532856","rc":[{"atb":[[2.7,7.3]],"id":39330606},{"atb":[[2.46,6.78]],"id":42609837}],"con":true,"img":false}]}
{"op":"mcm","clk":"5321766105","pt":1646313021535,"mc":[{"id":"1.195532856","rc":[{"atb":[[2.88,0]],"id":42931075}],"con":true,"img":false}]}
{"op":"mcm","clk":"5321767116","pt":1646313029579,"mc":[{"id":"1.195532856","rc":[{"atb":[[2.42,7.89]],"id":42609837}],"con":true,"img":false}]}
{"op":"mcm","clk":"5321767773","pt":1646313035380,"mc":[{"id":"1.195532856","rc":[{"atb":[[2.72,3.9]],"id":41555102}],"con":true,"img":false}]}
{"op":"mcm","clk":"5321767793","pt":1646313035488,"mc":[{"id":"1.195532856","rc":[{"atb":[[2.44,4.67]],"id":43189001}],"con":true,"img":false}]}
{"op":"mcm","clk":"5321767819","pt":1646313035690,"mc":[{"id":"1.195532856","rc":[{"atb":[[2.96,6.33]],"id":42931075}],"con":true,"img":false}]}
{"op":"mcm","clk":"5321769506","pt":1646313050496,"mc":[{"id":"1.195532856","rc":[{"atb":[[2.5,4.48]],"id":42609837}],"con":true,"img":false}]}
{"op":"mcm","clk":"5321771292","pt":1646313065583,"mc":[{"id":"1.195532856","rc":[{"atb":[[2.4,0]],"id":43189001},{"atb":[[2.66,0]],"id":41555102}],"con":true,"img":false}]}
{"op":"mcm","clk":"5321772208","pt":1646313074249,"mc":[{"id":"1.195532856","rc":[{"atb":[[2.44,0]],"id":43189001},{"atb":[[2.72,0]],"id":41555102}],"con":true,"img":false}]}
{"op":"mcm","clk":"5321773194","pt":1646313083553,"mc":[{"id":"1.195532856","rc":[{"atb":[[2.46,0]],"id":42609837}],"con":true,"img":false}]}
{"op":"mcm","clk":"5321773204","pt":1646313083655,"mc":[{"id":"1.195532856","rc":[{"atb":[[2.42,0]],"id":43189000}],"con":true,"img":false}]}
{"op":"mcm","clk":"5321774019","pt":1646313092365,"mc":[{"id":"1.195532856","rc":[{"atb":[[2.5,0]],"id":42609837}],"con":true,"img":false}]}
{"op":"mcm","clk":"5321774358","pt":1646313095853,"mc":[{"id":"1.195532856","rc":[{"atb":[[2.4,4.8]],"id":43189001}],"con":true,"img":false}]}
{"op":"mcm","clk":"5321774371","pt":1646313095958,"mc":[{"id":"1.195532856","rc":[{"atb":[[2.62,4.15]],"id":41555102}],"con":true,"img":false}]}
{"op":"mcm","clk":"5321774754","pt":1646313099752,"mc":[{"id":"1.195532856","rc":[{"atb":[[2.5,8.27]],"id":43189000}],"con":true,"img":false}]}
{"op":"mcm","clk":"5321777197","pt":1646313113390,"mc":[{"id":"1.195532856","rc":[{"atb":[[2.42,12.63]],"id":42609837}],"con":true,"img":false}]}
{"op":"mcm","clk":"5321779586","pt":1646313131399,"mc":[{"id":"1.195532856","rc":[{"atb":[[2.44,6.88]],"id":43189001}],"con":true,"img":false}]}
{"op":"mcm","clk":"5321779599","pt":1646313131496,"mc":[{"id":"1.195532856","rc":[{"atb":[[2.56,0]],"id":41555102}],"con":true,"img":false}]}
{"op":"mcm","clk":"5321779621","pt":1646313131711,"mc":[{"id":"1.195532856","rc":[{"atb":[[2.46,6.78]],"id":42609837}],"con":true,"img":false}]}
{"op":"mcm","clk":"5321779629","pt":1646313131816,"mc":[{"id":"1.195532856","rc":[{"atb":[[2.68,5.9]],"id":41555102}],"con":true,"img":false}]}
{"op":"mcm","clk":"5321780971","pt":1646313143716,"mc":[{"id":"1.195532856","rc":[{"atb":[[2.4,0]],"id":43189001},{"atb":[[2.62,0]],"id":41555102},{"atb":[[2.42,7.89]],"id":42609837}],"con":true,"img":false}]}
{"op":"mcm","clk":"5321781320","pt":1646313146949,"mc":[{"id":"1.195532856","rc":[{"atb":[[2.64,7.57]],"id":41555102}],"con":true,"img":false}]}
{"op":"mcm","clk":"5321782778","pt":1646313161459,"mc":[{"id":"1.195532856","rc":[{"atb":[[2.44,0]],"id":43189001},{"atb":[[2.68,0]],"id":41555102}],"con":true,"img":false}]}
{"op":"mcm","clk":"5321782787","pt":1646313161560,"mc":[{"id":"1.195532856","rc":[{"atb":[[2.48,4.54]],"id":43189001},{"atb":[[2.74,3.86]],"id":41555102}],"con":true,"img":false}]}
{"op":"mcm","clk":"5321782810","pt":1646313161766,"mc":[{"id":"1.195532856","rc":[{"atb":[[2.5,4.48]],"id":42609837}],"con":true,"img":false}]}
{"op":"mcm","clk":"5321783735","pt":1646313170580,"mc":[{"id":"1.195532856","rc":[{"atb":[[2.48,0]],"id":43189001},{"atb":[[2.74,0]],"id":41555102}],"con":true,"img":false}]}
{"op":"mcm","clk":"5321784072","pt":1646313173979,"mc":[{"id":"1.195532856","rc":[{"atb":[[2.4,7.08]],"id":43189001}],"con":true,"img":false}]}
{"op":"mcm","clk":"5321784108","pt":1646313174290,"mc":[{"id":"1.195532856","rc":[{"atb":[[2.66,5.96]],"id":41555102}],"con":true,"img":false}]}
{"op":"mcm","clk":"5321785188","pt":1646313186129,"mc":[{"id":"1.195532856","rc":[{"atb":[[2.46,0]],"id":42609837}],"con":true,"img":false}]}
{"op":"mcm","clk":"5321785709","pt":1646313191631,"mc":[{"id":"1.195532856","rc":[{"atb":[[2.6,0]],"id":41555102}],"con":true,"img":false}]}
{"op":"mcm","clk":"5321785961","pt":1646313194535,"mc":[{"id":"1.195532856","rc":[{"atb":[[2.7,6.59]],"id":41555102}],"con":true,"img":false}]}
{"op":"mcm","clk":"5321785996","pt":1646313194938,"mc":[{"id":"1.195532856","rc":[{"atb":[[2.5,0]],"id":42609837}],"con":true,"img":false}]}
{"op":"mcm","clk":"5321786885","pt":1646313203639,"mc":[{"id":"1.195532856","rc":[{"atb":[[2.44,4.67]],"id":43189001}],"con":true,"img":false}]}
{"op":"mcm","clk":"5321786901","pt":1646313203848,"mc":[{"id":"1.195532856","rc":[{"atb":[[2.72,3.9]],"id":41555102}],"con":true,"img":false}]}
{"op":"mcm","clk":"5321787751","pt":1646313213163,"mc":[{"id":"1.195532856","rc":[{"atb":[[2.66,0]],"id":41555102}],"con":true,"img":false}]}
{"op":"mcm","clk":"5321788075","pt":1646313216355,"mc":[{"id":"1.195532856","rc":[{"atb":[[2.42,12.63]],"id":42609837}],"con":true,"img":false}]}
{"op":"mcm","clk":"5321788942","pt":1646313225076,"mc":[{"id":"1.195532856","rc":[{"atb":[[2.72,0]],"id":41555102}],"con":true,"img":false}]}
{"op":"mcm","clk":"5321788966","pt":1646313225282,"mc":[{"id":"1.195532856","rc":[{"atb":[[2.4,0]],"id":43189001}],"con":true,"img":false}]}
{"op":"mcm","clk":"5321788976","pt":1646313225384,"mc":[{"id":"1.195532856","rc":[{"atb":[[2.38,0]],"id":42609837}],"con":true,"img":false}]}
{"op":"mcm","clk":"5321789005","pt":1646313225655,"mc":[{"id":"1.195532856","rc":[{"atb":[[2.46,6.78]],"id":42609837}],"con":true,"img":false}]}
{"op":"mcm","clk":"5321789836","pt":1646313233882,"mc":[{"id":"1.195532856","rc":[{"atb":[[2.44,0]],"id":43189001},{"atb":[[2.42,7.89]],"id":42609837}],"con":true,"img":false}]}
{"op":"mcm","clk":"5321790741","pt":1646313240886,"mc":[{"id":"1.195532856","rc":[{"atb":[[2.46,15.29]],"id":42609837}],"con":true,"img":false}]}
{"op":"mcm","clk":"5321791103","pt":1646313243123,"mc":[{"id":"1.195532856","rc":[{"atb":[[2.7,10.54]],"id":41555102}],"con":true,"img":false}]}
{"op":"mcm","clk":"5321792446","pt":1646313254636,"mc":[{"id":"1.195532856","rc":[{"atb":[[2.4,4.8]],"id":43189001},{"atb":[[2.92,0]],"id":42931075},{"atb":[[2.66,0]],"id":39330606},{"atb":[[2.42,0]],"id":42609837}],"con":true,"img":false}]}
{"op":"mcm","clk":"5321792465","pt":1646313254837,"mc":[{"id":"1.195532856","rc":[{"atb":[[2.5,4.48]],"id":42609837}],"con":true,"img":false}]}
{"op":"mcm","clk":"5321792751","pt":1646313257716,"mc":[{"id":"1.195532856","rc":[{"atb":[[3,5.6]],"id":42931075},{"atb":[[2.5,11.96]],"id":42609837}],"con":true,"img":false}]}
{"op":"mcm","clk":"5321792758","pt":1646313257816,"mc":[{"id":"1.195532856","rc":[{"atb":[[2.74,6.44]],"id":39330606}],"con":true,"img":false}]}
{"op":"mcm","clk":"5321794042","pt":1646313270148,"mc":[{"id":"1.195532856","rc":[{"atb":[[2.76,5.63]],"id":41555102}],"con":true,"img":false}]}
{"op":"mcm","clk":"5321794880","pt":1646313279464,"mc":[{"id":"1.195532856","rc":[{"atb":[[2.7,6.59]],"id":41555102}],"con":true,"img":false}]}
{"op":"mcm","clk":"5321795880","pt":1646313289581,"mc":[{"id":"1.195532856","rc":[{"atb":[[2.46,8.5]],"id":42609837}],"con":true,"img":false}]}
{"op":"mcm","clk":"5321797137","pt":1646313303190,"mc":[{"id":"1.195532856","rc":[{"atb":[[2.44,6.88]],"id":43189001}],"con":true,"img":false}]}
{"op":"mcm","clk":"5321797158","pt":1646313303396,"mc":[{"id":"1.195532856","rc":[{"atb":[[2.56,6.35]],"id":42609837}],"con":true,"img":false}]}
{"op":"mcm","clk":"5321797237","pt":1646313304072,"mc":[{"id":"1.195532856","rc":[{"atb":[[2.82,3.7]],"id":41555102}],"con":true,"img":false}]}
{"op":"mcm","clk":"5321797862","pt":1646313310323,"mc":[{"id":"1.195532856","rc":[{"atb":[[2.4,0]],"id":43189001}],"con":true,"img":false}]}
{"op":"mcm","clk":"5321798327","pt":1646313315823,"mc":[{"id":"1.195532856","rc":[{"atb":[[2.5,7.47]],"id":42609837}],"con":true,"img":false}]}
{"op":"mcm","clk":"5321798837","pt":1646313321016,"mc":[{"id":"1.195532856","rc":[{"atb":[[2.46,0]],"id":43189000}],"con":true,"img":false}]}
{"op":"mcm","clk":"5321799148","pt":1646313324123,"mc":[{"id":"1.195532856","rc":[{"atb":[[2.54,7.28]],"id":43189000}],"con":true,"img":false}]}
{"op":"mcm","clk":"5321799751","pt":1646313330239,"mc":[{"id":"1.195532856","rc":[{"atb":[[2.48,4.54]],"id":43189001}],"con":true,"img":false}]}
{"op":"mcm","clk":"5321799773","pt":1646313330503,"mc":[{"id":"1.195532856","rc":[{"atb":[[2.44,0]],"id":43189001},{"atb":[[2.76,0]],"id":41555102}],"con":true,"img":false}]}
{"op":"mcm","clk":"5321800242","pt":1646313335845,"mc":[{"id":"1.195532856","rc":[{"atb":[[2.62,4.15]],"id":42609837}],"con":true,"img":false}]}
{"op":"mcm","clk":"5321800531","pt":1646313338849,"mc":[{"id":"1.195532856","rc":[{"atb":[[2.48,0]],"id":43189001},{"atb":[[2.82,0]],"id":41555102}],"con":true,"img":false}]}
{"op":"mcm","clk":"5321801200","pt":1646313346759,"mc":[{"id":"1.195532856","rc":[{"atb":[[2.4,7.08]],"id":43189001}],"con":true,"img":false}]}
{"op":"mcm","clk":"5321802781","pt":1646313360586,"mc":[{"id":"1.195532856","rc":[{"atb":[[2.56,0]],"id":42609837}],"con":true,"img":false}]}
{"op":"mcm","clk":"5321802879","pt":1646313361302,"mc":[{"id":"1.195532856","rc":[{"atb":[[2.7,10.54]],"id":41555102}],"con":true,"img":false}]}
{"op":"mcm","clk":"5321804045","pt":1646313370405,"mc":[{"id":"1.195532856","rc":[{"atb":[[2.62,0]],"id":42609837}],"con":true,"img":false}]}
{"op":"mcm","clk":"5321804572","pt":1646313375596,"mc":[{"id":"1.195532856","rc":[{"atb":[[2.44,4.67]],"id":43189001}],"con":true,"img":false}]}
{"op":"mcm","clk":"5321804646","pt":1646313376112,"mc":[{"id":"1.195532856","rc":[{"atb":[[2.76,5.63]],"id":41555102}],"con":true,"img":false}]}
{"op":"mcm","clk":"5321805517","pt":1646313384819,"mc":[{"id":"1.195532856","rc":[{"atb":[[2.7,6.59]],"id":41555102}],"con":true,"img":false}]}
{"op":"mcm","clk":"5321805750","pt":1646313387103,"mc":[{"id":"1.195532856","rc":[{"atb":[[2.5,11.96]],"id":42609837}],"con":true,"img":false}]}
{"op":"mcm","clk":"5321815864","pt":1646313405225,"mc":[{"id":"1.195532856","rc":[{"atb":[[2.82,3.7]],"id":41555102}],"con":true,"img":false}]}
{"op":"mcm","clk":"5321815887","pt":1646313405536,"mc":[{"id":"1.195532856","rc":[{"atb":[[2.64,0]],"id":41555102},{"atb":[[2.56,6.35]],"id":42609837}],"con":true,"img":false}]}
{"op":"mcm","clk":"5321815911","pt":1646313405849,"mc":[{"id":"1.195532856","rc":[{"atb":[[2.4,0]],"id":43189001}],"con":true,"img":false}]}
{"op":"mcm","clk":"5321816804","pt":1646313414253,"mc":[{"id":"1.195532856","rc":[{"atb":[[2.44,0]],"id":43189001},{"atb":[[2.5,7.47]],"id":42609837}],"con":true,"img":false}]}
{"op":"mcm","clk":"5321817360","pt":1646313420743,"mc":[{"id":"1.195532856","rc":[{"atb":[[2.74,7.13]],"id":41555102}],"con":true,"img":false}]}
{"op":"mcm","clk":"5321818752","pt":1646313435177,"mc":[{"id":"1.195532856","rc":[{"atb":[[2.4,4.8]],"id":43189001}],"con":true,"img":false}]}
{"op":"mcm","clk":"5321818776","pt":1646313435385,"mc":[{"id":"1.195532856","rc":[{"atb":[[2.62,4.15]],"id":42609837}],"con":true,"img":false}]}
{"op":"mcm","clk":"5321818799","pt":1646313435586,"mc":[{"id":"1.195532856","rc":[{"atb":[[2.76,0]],"id":41555102}],"con":true,"img":false}]}
{"op":"mcm","clk":"5321819850","pt":1646313447273,"mc":[{"id":"1.195532856","rc":[{"atb":[[2.7,0]],"id":41555102}],"con":true,"img":false}]}
{"op":"mcm","clk":"5321819868","pt":1646313447479,"mc":[{"id":"1.195532856","rc":[{"atb":[[2.82,0]],"id":41555102}],"con":true,"img":false}]}
{"op":"mcm","clk":"5321819879","pt":1646313447574,"mc":[{"id":"1.195532856","rc":[{"atb":[[2.88,5.28]],"id":41555102}],"con":true,"img":false}]}
{"op":"mcm","clk":"5321820113","pt":1646313450176,"mc":[{"id":"1.195532856","rc":[{"atb":[[2.78,6.3]],"id":41555102}],"con":true,"img":false}]}
{"op":"mcm","clk":"5321821046","pt":1646313460391,"mc":[{"id":"1.195532856","rc":[{"atb":[[2.56,0]],"id":42609837}],"con":true,"img":false}]}
{"op":"mcm","clk":"5321821811","pt":1646313468324,"mc":[{"id":"1.195532856","rc":[{"atb":[[2.62,0]],"id":42609837}],"con":true,"img":false}]}
{"op":"mcm","clk":"5321822224","pt":1646313472414,"mc":[{"id":"1.195532856","rc":[{"atb":[[2.88,0]],"id":41555102}],"con":true,"img":false}]}
{"op":"mcm","clk":"5321823729","pt":1646313489306,"mc":[{"id":"1.195532856","rc":[{"atb":[[2.5,11.96]],"id":42609837}],"con":true,"img":false}]}
{"op":"mcm","clk":"5321823861","pt":1646313490750,"mc":[{"id":"1.195532856","rc":[{"atb":[[2.44,6.88]],"id":43189001}],"con":true,"img":false}]}
{"op":"mcm","clk":"5321823877","pt":1646313490856,"mc":[{"id":"1.195532856","rc":[{"atb":[[2.84,5.38]],"id":41555102}],"con":true,"img":false}]}
{"op":"mcm","clk":"5321824715","pt":1646313499325,"mc":[{"id":"1.195532856","rc":[{"atb":[[2.4,0]],"id":43189001}],"con":true,"img":false}]}
{"op":"mcm","clk":"5321825318","pt":1646313505550,"mc":[{"id":"1.195532856","rc":[{"atb":[[2.56,6.35]],"id":42609837}],"con":true,"img":false}]}
{"op":"mcm","clk":"5321825347","pt":1646313505861,"mc":[{"id":"1.195532856","rc":[{"atb":[[2.96,0]],"id":42931075},{"atb":[[2.7,0]],"id":39330606},{"atb":[[2.46,0]],"id":42609837}],"con":true,"img":false}]}
{"op":"mcm","clk":"5321826046","pt":1646313514175,"mc":[{"id":"1.195532856","rc":[{"atb":[[2.5,7.47]],"id":42609837}],"con":true,"img":false}]}
{"op":"mcm","clk":"5321826339","pt":1646313517765,"mc":[{"id":"1.195532856","rc":[{"atb":[[2.48,4.54]],"id":43189001},{"atb":[[2.9,3.54]],"id":41555102}],"con":true,"img":false}]}
{"op":"mcm","clk":"5321826609","pt":1646313520373,"mc":[{"id":"1.195532856","rc":[{"atb":[[3.1,5.91]],"id":42931075}],"con":true,"img":false}]}
{"op":"mcm","clk":"5321826618","pt":1646313520478,"mc":[{"id":"1.195532856","rc":[{"atb":[[2.78,6.97]],"id":39330606}],"con":true,"img":false}]}
{"op":"mcm","clk":"5321826638","pt":1646313520683,"mc":[{"id":"1.195532856","rc":[{"atb":[[2.54,8.06]],"id":42609837}],"con":true,"img":false}]}
{"op":"mcm","clk":"5321826690","pt":1646313521153,"mc":[{"id":"1.195532856","rc":[{"atb":[[2.44,0]],"id":43189001}],"con":true,"img":false}]}
{"op":"mcm","clk":"5321827354","pt":1646313528191,"mc":[{"id":"1.195532856","rc":[{"atb":[[2.48,0]],"id":43189001}],"con":true,"img":false}]}
{"op":"mcm","clk":"5321827946","pt":1646313535190,"mc":[{"id":"1.195532856","rc":[{"atb":[[2.62,4.15]],"id":42609837}],"con":true,"img":false}]}
{"op":"mcm","clk":"5321828209","pt":1646313538009,"mc":[{"id":"1.195532856","rc":[{"atb":[[2.84,0]],"id":41555102}],"con":true,"img":false}]}
{"op":"mcm","clk":"5321828414","pt":1646313540608,"mc":[{"id":"1.195532856","rc":[{"atb":[[2.5,0]],"id":42609837}],"con":true,"img":false}]}
{"op":"mcm","clk":"5321828738","pt":1646313543985,"mc":[{"id":"1.195532856","rc":[{"atb":[[2.6,7.01]],"id":42609837}],"con":true,"img":false}]}
{"op":"mcm","clk":"5321829066","pt":1646313546750,"mc":[{"id":"1.195532856","rc":[{"atb":[[2.9,0]],"id":41555102}],"con":true,"img":false}]}
{"op":"mcm","clk":"5321829394","pt":1646313549515,"mc":[{"id":"1.195532856","rc":[{"atb":[[2.4,4.8]],"id":43189001}],"con":true,"img":false}]}
{"op":"mcm","clk":"5321829893","pt":1646313554726,"mc":[{"id":"1.195532856","rc":[{"atb":[[2.56,0]],"id":42609837}],"con":true,"img":false}]}
{"op":"mcm","clk":"5321830795","pt":1646313563265,"mc":[{"id":"1.195532856","rc":[{"atb":[[2.62,0]],"id":42609837}],"con":true,"img":false}]}
{"op":"mcm","clk":"5321831369","pt":1646313568671,"mc":[{"id":"1.195532856","rc":[{"atb":[[2.8,3.73]],"id":41555102}],"con":true,"img":false}]}
{"op":"mcm","clk":"5321831688","pt":1646313571365,"mc":[{"id":"1.195532856","rc":[{"atb":[[2.5,0]],"id":43189000}],"con":true,"img":false}]}
{"op":"mcm","clk":"5321832830","pt":1646313582559,"mc":[{"id":"1.195532856","rc":[{"atb":[[2.6,11.21]],"id":42609837}],"con":true,"img":false}]}
{"op":"mcm","clk":"5321833250","pt":1646313586156,"mc":[{"id":"1.195532856","rc":[{"atb":[[2.58,7.85]],"id":43189000}],"con":true,"img":false}]}
{"op":"mcm","clk":"5321833279","pt":1646313586468,"mc":[{"id":"1.195532856","rc":[{"atb":[[2.44,6.88]],"id":43189001}],"con":true,"img":false}]}
{"op":"mcm","clk":"5321834145","pt":1646313594477,"mc":[{"id":"1.195532856","rc":[{"atb":[[2.4,0]],"id":43189001}],"con":true,"img":false}]}
{"op":"mcm","clk":"5321834853","pt":1646313600798,"mc":[{"id":"1.195532856","rc":[{"atb":[[2.86,5.33]],"id":41555102}],"con":true,"img":false}]}
{"op":"mcm","clk":"5321834883","pt":1646313601112,"mc":[{"id":"1.195532856","rc":[{"atb":[[2.66,5.96]],"id":42609837}],"con":true,"img":false}]}
{"op":"mcm","clk":"5321835864","pt":1646313609737,"mc":[{"id":"1.195532856","rc":[{"atb":[[2.8,0]],"id":41555102},{"atb":[[2.6,7.01]],"id":42609837}],"con":true,"img":false}]}
{"op":"mcm","clk":"5321836511","pt":1646313615823,"mc":[{"id":"1.195532856","rc":[{"atb":[[2.48,4.54]],"id":43189001}],"con":true,"img":false}]}
{"op":"mcm","clk":"5321836562","pt":1646313616237,"mc":[{"id":"1.195532856","rc":[{"atb":[[2.44,0]],"id":43189001}],"con":true,"img":false}]}
{"op":"mcm","clk":"5321837507","pt":1646313624729,"mc":[{"id":"1.195532856","rc":[{"atb":[[2.48,0]],"id":43189001}],"con":true,"img":false}]}
{"op":"mcm","clk":"5321838157","pt":1646313630481,"mc":[{"id":"1.195532856","rc":[{"atb":[[2.92,3.5]],"id":41555102}],"con":true,"img":false}]}
{"op":"mcm","clk":"5321838169","pt":1646313630583,"mc":[{"id":"1.195532856","rc":[{"atb":[[2.72,3.9]],"id":42609837}],"con":true,"img":false}]}
{"op":"mcm","clk":"5321838196","pt":1646313630748,"mc":[{"id":"1.195532856","rc":[{"atb":[[2.86,0]],"id":41555102}],"con":true,"img":false}]}
{"op":"mcm","clk":"5321838228","pt":1646313631059,"mc":[{"id":"1.195532856","rc":[{"atb":[[2.4,7.08]],"id":43189001}],"con":true,"img":false}]}
{"op":"mcm","clk":"5321839196","pt":1646313639495,"mc":[{"id":"1.195532856","rc":[{"atb":[[2.92,0]],"id":41555102}],"con":true,"img":false}]}
{"op":"mcm","clk":"5321839659","pt":1646313643668,"mc":[{"id":"1.195532856","rc":[{"atb":[[2.84,5.38]],"id":41555102}],"con":true,"img":false}]}
{"op":"mcm","clk":"5321841535","pt":1646313660703,"mc":[{"id":"1.195532856","rc":[{"atb":[[2.44,4.67]],"id":43189001}],"con":true,"img":false}]}
{"op":"mcm","clk":"5321841598","pt":1646313661432,"mc":[{"id":"1.195532856","rc":[{"atb":[[2.66,0]],"id":42609837}],"con":true,"img":false}]}
{"op":"mcm","clk":"5321842547","pt":1646313669644,"mc":[{"id":"1.195532856","rc":[{"atb":[[2.72,0]],"id":42609837}],"con":true,"img":false}]}
{"op":"mcm","clk":"5321842883","pt":1646313672831,"mc":[{"id":"1.195532856","rc":[{"atb":[[2.9,3.54]],"id":41555102}],"con":true,"img":false}]}
{"op":"mcm","clk":"5321843243","pt":1646313676526,"mc":[{"id":"1.195532856","rc":[{"atb":[[2.74,0]],"id":41555102}],"con":true,"img":false}]}
{"op":"mcm","clk":"5321844673","pt":1646313691055,"mc":[{"id":"1.195532856","rc":[{"atb":[[2.6,11.21]],"id":42609837}],"con":true,"img":false}]}
{"op":"mcm","clk":"5321844693","pt":1646313691262,"mc":[{"id":"1.195532856","rc":[{"atb":[[2.4,0]],"id":43189001},{"atb":[[2.84,0]],"id":41555102}],"con":true,"img":false}]}
