{"op":"mcm","clk":"5345985294","pt":1646174444251,"mc":[{"id":"1.195453616","marketDefinition":{"bspMarket":true,"turnInPlayEnabled":false,"persistenceEnabled":false,"marketBaseRate":7.0,"eventId":"31272494","eventTypeId":"4339","numberOfWinners":2,"bettingType":"ODDS","marketType":"PLACE","marketTime":"2022-03-02T09:33:00.000Z","suspendTime":"2022-03-02T09:33:00.000Z","bspReconciled":false,"complete":true,"inPlay":false,"crossMatching":false,"runnersVoidable":false,"numberOfActiveRunners":6,"betDelay":0,"status":"OPEN","runners":[{"status":"ACTIVE","sortPriority":1,"id":26503913,"name":"1. Callum Ari"},{"status":"ACTIVE","sortPriority":2,"id":36036864,"name":"2. Ripplebrook Rory"},{"status":"ACTIVE","sortPriority":3,"id":37456368,"name":"3. Shes So Lovable"},{"status":"ACTIVE","sortPriority":4,"id":39784359,"name":"4. Nicholas Rose"},{"status":"ACTIVE","sortPriority":5,"id":39980001,"name":"7. Elmo Rose"},{"status":"ACTIVE","sortPriority":6,"id":28755739,"name":"8. Perfect Colour"}],"regulators":["MR_INT"],"venue":"Traralgon","countryCode":"AU","discountAllowed":true,"timezone":"Australia/Sydney","openDate":"2022-03-02T08:31:00.000Z","version":4382425369,"name":"To Be Placed","eventName":"Traralgon (AUS) 2nd Mar"},"rc":[],"con":true,"img":false}]}
{"op":"mcm","clk":"5346059516","pt":1646175786519,"mc":[{"id":"1.195453616","rc":[{"atb":[[2,99.7],[2.2,83.08],[2.1,90.63]],"id":26503913},{"atl":[[9,9.06],[5.5,8.05],[7,12.08]],"id":26503913},{"spn":3.85,"spf":"NaN","id":26503913},{"atb":[[1.2,498.5],[1.25,398.8],[1.3,332.33]],"id":28755739},{"atl":[[2.54,23.54],[2.74,41.67],[2.94,37.37]],"id":28755739},{"spn":1.92,"spf":"NaN","id":28755739},{"atb":[[1.8,124.62],[1.85,117.29],[1.75,132.93]],"id":37456368},{"atl":[[4.5,20.71],[5.5,16.11],[3.75,13.18]],"id":37456368},{"spn":2.8,"spf":"NaN","id":37456368},{"atb":[[2.82,54.77],[2.92,51.92],[3.05,48.63]],"id":36036864},{"atl":[[10.5,7.63],[8.2,5.03],[15.5,5]],"id":36036864},{"spn":5.62,"spf":"NaN","id":36036864},{"atb":[[3.6,38.34],[3.85,34.98],[3.35,42.42]],"id":39784359},{"atl":[[17.5,4.39],[12.5,3.15],[25,3.02]],"id":39784359},{"spn":8.17,"spf":"NaN","id":39784359},{"atb":[[1.8,124.62],[1.85,117.29],[1.75,132.93]],"id":39980001},{"atl":[[4.5,20.71],[5.5,16.11],[3.75,13.18]],"id":39980001},{"spn":2.8,"spf":"NaN","id":39980001}],"con":true,"img":false}]}
{"op":"mcm","clk":"5346061998","pt":1646175839944,"mc":[{"id":"1.195453616","rc":[{"atb":[[2,0],[2.2,0],[2.1,0]],"id":26503913},{"atl":[[9,0],[5.5,0],[7,0]],"id":26503913},{"atb":[[1.2,0],[1.25,0],[1.3,0]],"id":28755739},{"atl":[[2.54,0],[2.74,0],[2.94,0]],"id":28755739},{"atb":[[1.8,0],[1.85,0],[1.75,0]],"id":37456368},{"atl":[[4.5,0],[5.5,0],[3.75,0]],"id":37456368},{"atb":[[2.82,0],[2.92,0],[3.05,0]],"id":36036864},{"atl":[[10.5,0],[8.2,0],[15.5,0]],"id":36036864},{"atb":[[3.6,0],[3.85,0],[3.35,0]],"id":39784359},{"atl":[[17.5,0],[12.5,0],[25,0]],"id":39784359},{"atb":[[1.8,0],[1.85,0],[1.75,0]],"id":39980001},{"atl":[[4.5,0],[5.5,0],[3.75,0]],"id":39980001}],"con":true,"img":false}]}
{"op":"mcm","clk":"5346062130","pt":1646175843036,"mc":[{"id":"1.195453616","rc":[{"atb":[[2,99.7],[2.2,83.08],[2.1,90.63]],"id":26503913},{"atl":[[9,9.06],[5.5,8.05],[7,12.08]],"id":26503913},{"atb":[[1.2,498.5],[1.25,398.8],[1.3,332.33]],"id":28755739},{"atl":[[2.54,23.54],[2.74,41.67],[2.94,37.37]],"id":28755739},{"atb":[[1.8,124.62],[1.85,117.29],[1.75,132.93]],"id":37456368},{"atl":[[4.5,20.71],[5.5,16.11],[3.75,13.18]],"id":37456368},{"atb":[[2.82,54.77],[2.92,51.92],[3.05,48.63]],"id":36036864},{"atl":[[10.5,7.63],[8.2,5.03],[15.5,5]],"id":36036864},{"atb":[[3.6,38.34],[3.85,34.98],[3.35,42.42]],"id":39784359},{"atl":[[17.5,4.39],[12.5,3.15],[25,3.02]],"id":39784359},{"atb":[[1.8,124.62],[1.85,117.29],[1.75,132.93]],"id":39980001},{"atl":[[4.5,20.71],[5.5,16.11],[3.75,13.18]],"id":39980001}],"con":true,"img":false}]}
{"op":"mcm","clk":"5346105153","pt":1646176602701,"mc":[{"id":"1.195453616","marketDefinition":{"bspMarket":true,"turnInPlayEnabled":false,"persistenceEnabled":false,"marketBaseRate":7.0,"eventId":"31272494","eventTypeId":"4339","numberOfWinners":2,"bettingType":"ODDS","marketType":"PLACE","marketTime":"2022-03-02T09:33:00.000Z","suspendTime":"2022-03-02T09:33:00.000Z","bspReconciled":false,"complete":true,"inPlay":false,"crossMatching":false,"runnersVoidable":false,"numberOfActiveRunners":6,"betDelay":0,"status":"OPEN","runners":[{"status":"ACTIVE","sortPriority":1,"id":26503913,"name":"1. Callum Ari"},{"status":"ACTIVE","sortPriority":2,"id":36036864,"name":"2. Ripplebrook Rory"},{"status":"ACTIVE","sortPriority":3,"id":37456368,"name":"3. Shes So Lovable"},{"status":"ACTIVE","sortPriority":4,"id":39784359,"name":"4. Nicholas Rose"},{"status":"ACTIVE","sortPriority":5,"id":39980001,"name":"7. Elmo Rose"},{"status":"ACTIVE","sortPriority":6,"id":28755739,"name":"8. Perfect Colour"}],"regulators":["MR_INT"],"venue":"Traralgon","countryCode":"AU","discountAllowed":true,"timezone":"Australia/Sydney","openDate":"2022-03-02T08:31:00.000Z","version":4382425369,"name":"To Be Placed","eventName":"Traralgon (AUS) 2nd Mar"},"rc":[{"atb":[[2,99.7],[2.2,83.08],[2.1,90.63]],"id":26503913},{"atl":[[9,9.06],[5.5,8.05],[7,12.08]],"id":26503913},{"spn":3.85,"spf":"NaN","id":26503913},{"atb":[[1.2,498.5],[1.25,398.8],[1.3,332.33]],"id":28755739},{"atl":[[2.54,23.54],[2.74,41.67],[2.94,37.37]],"id":28755739},{"spn":1.92,"spf":"NaN","id":28755739},{"atb":[[1.8,124.62],[1.85,117.29],[1.75,132.93]],"id":37456368},{"atl":[[4.5,20.71],[5.5,16.11],[3.75,13.18]],"id":37456368},{"spn":2.8,"spf":"NaN","id":37456368},{"atb":[[2.82,54.77],[2.92,51.92],[3.05,48.63]],"id":36036864},{"atl":[[10.5,7.63],[8.2,5.03],[15.5,5]],"id":36036864},{"spn":5.62,"spf":"NaN","id":36036864},{"atb":[[3.6,38.34],[3.85,34.98],[3.35,42.42]],"id":39784359},{"atl":[[17.5,4.39],[12.5,3.15],[25,3.02]],"id":39784359},{"spn":8.17,"spf":"NaN","id":39784359},{"atb":[[1.8,124.62],[1.85,117.29],[1.75,132.93]],"id":39980001},{"atl":[[4.5,20.71],[5.5,16.11],[3.75,13.18]],"id":39980001},{"spn":2.8,"spf":"NaN","id":39980001}],"con":true,"img":true}]}
{"op":"mcm","clk":"5346270949","pt":1646179896940,"mc":[{"id":"1.195453616","rc":[{"atb":[[2,99.71],[2.2,83.09],[2.1,90.64]],"id":26503913},{"atl":[[9,9.06],[5.5,8.05],[7,12.08]],"id":26503913},{"atb":[[1.2,498.55],[1.25,398.84],[1.3,332.37]],"id":28755739},{"atl":[[2.54,23.54],[2.74,41.67],[2.94,37.38]],"id":28755739},{"atb":[[1.8,124.64],[1.85,117.3],[1.75,132.94]],"id":37456368},{"atl":[[4.5,20.72],[5.5,16.11],[3.75,13.18]],"id":37456368},{"atb":[[2.82,54.78],[2.92,51.93],[3.05,48.63]],"id":36036864},{"spl":[[1.01,2.72]],"id":36036864},{"atl":[[10.5,7.63],[8.2,5.03],[15.5,5]],"id":36036864},{"spn":3.05,"spf":1.0,"id":36036864},{"atb":[[3.6,38.34],[3.85,34.98],[3.35,42.43]],"id":39784359},{"atl":[[17.5,4.39],[12.5,3.15],[25,3.02]],"id":39784359},{"atb":[[1.8,124.64],[1.85,117.3],[1.75,132.94]],"id":39980001},{"atl":[[4.5,20.72],[5.5,16.11],[3.75,13.18]],"id":39980001}],"con":true,"img":false}]}
{"op":"mcm","clk":"5346271458","pt":1646179905588,"mc":[{"id":"1.195453616","rc":[{"spl":[[1.01,2.72]],"id":39784359}],"con":true,"img":false}]}
{"op":"mcm","clk":"5346401611","pt":1646182002788,"mc":[{"id":"1.195453616","marketDefinition":{"bspMarket":true,"turnInPlayEnabled":false,"persistenceEnabled":false,"marketBaseRate":7.0,"eventId":"31272494","eventTypeId":"4339","numberOfWinners":2,"bettingType":"ODDS","marketType":"PLACE","marketTime":"2022-03-02T09:33:00.000Z","suspendTime":"2022-03-02T09:33:00.000Z","bspReconciled":false,"complete":true,"inPlay":false,"crossMatching":false,"runnersVoidable":false,"numberOfActiveRunners":6,"betDelay":0,"status":"OPEN","runners":[{"status":"ACTIVE","sortPriority":1,"id":26503913,"name":"1. Callum Ari"},{"status":"ACTIVE","sortPriority":2,"id":36036864,"name":"2. Ripplebrook Rory"},{"status":"ACTIVE","sortPriority":3,"id":37456368,"name":"3. Shes So Lovable"},{"status":"ACTIVE","sortPriority":4,"id":39784359,"name":"4. Nicholas Rose"},{"status":"ACTIVE","sortPriority":5,"id":39980001,"name":"7. Elmo Rose"},{"status":"ACTIVE","sortPriority":6,"id":28755739,"name":"8. Perfect Colour"}],"regulators":["MR_INT"],"venue":"Traralgon","countryCode":"AU","discountAllowed":true,"timezone":"Australia/Sydney","openDate":"2022-03-02T08:31:00.000Z","version":4382425369,"name":"To Be Placed","eventName":"Traralgon (AUS) 2nd Mar"},"rc":[{"atb":[[2,99.71],[2.2,83.09],[2.1,90.64]],"id":26503913},{"atl":[[9,9.06],[5.5,8.05],[7,12.08]],"id":26503913},{"spn":3.85,"spf":"NaN","id":26503913},{"atb":[[1.2,498.55],[1.25,398.84],[1.3,332.37]],"id":28755739},{"atl":[[2.54,23.54],[2.74,41.67],[2.94,37.38]],"id":28755739},{"spn":1.92,"spf":"NaN","id":28755739},{"atb":[[1.8,124.64],[1.85,117.3],[1.75,132.94]],"id":37456368},{"atl":[[4.5,20.72],[5.5,16.11],[3.75,13.18]],"id":37456368},{"spn":2.8,"spf":"NaN","id":37456368},{"atb":[[2.82,54.78],[2.92,51.93],[3.05,48.63]],"id":36036864},{"spl":[[1.01,2.72]],"id":36036864},{"atl":[[10.5,7.63],[8.2,5.03],[15.5,5]],"id":36036864},{"spn":3.05,"spf":1.0,"id":36036864},{"atb":[[3.6,38.34],[3.85,34.98],[3.35,42.43]],"id":39784359},{"spl":[[1.01,2.72]],"id":39784359},{"atl":[[17.5,4.39],[12.5,3.15],[25,3.02]],"id":39784359},{"spn":3.85,"spf":1.0,"id":39784359},{"atb":[[1.8,124.64],[1.85,117.3],[1.75,132.94]],"id":39980001},{"atl":[[4.5,20.72],[5.5,16.11],[3.75,13.18]],"id":39980001},{"spn":2.8,"spf":"NaN","id":39980001}],"con":true,"img":true}]}
{"op":"mcm","clk":"5346480392","pt":1646183121862,"mc":[{"id":"1.195453616","rc":[{"atb":[[2,0],[2.2,0],[2.1,0]],"id":26503913},{"atl":[[9,0],[5.5,0],[7,0]],"id":26503913},{"spn":"NaN","spf":"NaN","id":26503913},{"atb":[[1.2,499.34],[1.25,399.47],[1.3,332.89]],"id":28755739},{"atl":[[2.54,23.58],[2.74,41.74],[2.94,37.43]],"id":28755739},{"atb":[[1.8,124.83],[1.85,117.49],[1.75,133.15]],"id":37456368},{"atl":[[4.5,20.75],[5.5,16.14],[3.75,13.2]],"id":37456368},{"atb":[[2.82,0],[2.92,0],[3.05,0]],"id":36036864},{"spl":[[1.01,2.72]],"id":36036864},{"atl":[[10.5,0],[8.2,0],[15.5,0]],"id":36036864},{"spn":1.0,"spf":1.0,"id":36036864},{"atb":[[3.6,0],[3.85,0],[3.35,0]],"id":39784359},{"spl":[[1.01,2.72]],"id":39784359},{"atl":[[17.5,0],[12.5,0],[25,0]],"id":39784359},{"spn":1.0,"spf":1.0,"id":39784359},{"atb":[[1.8,124.83],[1.85,117.49],[1.75,133.15]],"id":39980001},{"atl":[[4.5,20.75],[5.5,16.14],[3.75,13.2]],"id":39980001}],"con":true,"img":false}]}
{"op":"mcm","clk":"5346480902","pt":1646183129046,"mc":[{"id":"1.195453616","rc":[{"atb":[[2.5,66.57],[2.6,62.41],[2.7,58.74]],"id":26503913},{"atl":[[8.6,9.55],[11.5,6.91],[6.6,6.48]],"id":26503913},{"atb":[[2.82,54.87],[2.92,52.01],[3.05,48.71]],"id":36036864},{"atl":[[10.5,7.64],[8.2,5.04],[15.5,5.01]],"id":36036864},{"atb":[[3.45,40.76],[3.95,33.85],[3.7,36.98]],"id":39784359},{"atl":[[18.5,4.14],[13.5,2.9],[27,2.79]],"id":39784359}],"con":true,"img":false}]}
{"op":"mcm","clk":"5346767965","pt":1646187402733,"mc":[{"id":"1.195453616","marketDefinition":{"bspMarket":true,"turnInPlayEnabled":false,"persistenceEnabled":false,"marketBaseRate":7.0,"eventId":"31272494","eventTypeId":"4339","numberOfWinners":2,"bettingType":"ODDS","marketType":"PLACE","marketTime":"2022-03-02T09:33:00.000Z","suspendTime":"2022-03-02T09:33:00.000Z","bspReconciled":false,"complete":true,"inPlay":false,"crossMatching":false,"runnersVoidable":false,"numberOfActiveRunners":6,"betDelay":0,"status":"OPEN","runners":[{"status":"ACTIVE","sortPriority":1,"id":26503913,"name":"1. Callum Ari"},{"status":"ACTIVE","sortPriority":2,"id":36036864,"name":"2. Ripplebrook Rory"},{"status":"ACTIVE","sortPriority":3,"id":37456368,"name":"3. Shes So Lovable"},{"status":"ACTIVE","sortPriority":4,"id":39784359,"name":"4. Nicholas Rose"},{"status":"ACTIVE","sortPriority":5,"id":39980001,"name":"7. Elmo Rose"},{"status":"ACTIVE","sortPriority":6,"id":28755739,"name":"8. Perfect Colour"}],"regulators":["MR_INT"],"venue":"Traralgon","countryCode":"AU","discountAllowed":true,"timezone":"Australia/Sydney","openDate":"2022-03-02T08:31:00.000Z","version":4382425369,"name":"To Be Placed","eventName":"Traralgon (AUS) 2nd Mar"},"rc":[{"atb":[[2.5,66.57],[2.6,62.41],[2.7,58.74]],"id":26503913},{"atl":[[8.6,9.55],[11.5,6.91],[6.6,6.48]],"id":26503913},{"spn":4.65,"spf":"NaN","id":26503913},{"atb":[[1.2,499.34],[1.25,399.47],[1.3,332.89]],"id":28755739},{"atl":[[2.54,23.58],[2.74,41.74],[2.94,37.43]],"id":28755739},{"spn":1.92,"spf":"NaN","id":28755739},{"atb":[[1.8,124.83],[1.85,117.49],[1.75,133.15]],"id":37456368},{"atl":[[4.5,20.75],[5.5,16.14],[3.75,13.2]],"id":37456368},{"spn":2.8,"spf":"NaN","id":37456368},{"atb":[[2.82,54.87],[2.92,52.01],[3.05,48.71]],"id":36036864},{"spl":[[1.01,2.72]],"id":36036864},{"atl":[[10.5,7.64],[8.2,5.04],[15.5,5.01]],"id":36036864},{"spn":3.05,"spf":1.0,"id":36036864},{"atb":[[3.45,40.76],[3.95,33.85],[3.7,36.98]],"id":39784359},{"spl":[[1.01,2.72]],"id":39784359},{"atl":[[18.5,4.14],[13.5,2.9],[27,2.79]],"id":39784359},{"spn":3.95,"spf":1.0,"id":39784359},{"atb":[[1.8,124.83],[1.85,117.49],[1.75,133.15]],"id":39980001},{"atl":[[4.5,20.75],[5.5,16.14],[3.75,13.2]],"id":39980001},{"spn":2.8,"spf":"NaN","id":39980001}],"con":true,"img":true}]}
{"op":"mcm","clk":"5347092516","pt":1646192802712,"mc":[{"id":"1.195453616","marketDefinition":{"bspMarket":true,"turnInPlayEnabled":false,"persistenceEnabled":false,"marketBaseRate":7.0,"eventId":"31272494","eventTypeId":"4339","numberOfWinners":2,"bettingType":"ODDS","marketType":"PLACE","marketTime":"2022-03-02T09:33:00.000Z","suspendTime":"2022-03-02T09:33:00.000Z","bspReconciled":false,"complete":true,"inPlay":false,"crossMatching":false,"runnersVoidable":false,"numberOfActiveRunners":6,"betDelay":0,"status":"OPEN","runners":[{"status":"ACTIVE","sortPriority":1,"id":26503913,"name":"1. Callum Ari"},{"status":"ACTIVE","sortPriority":2,"id":36036864,"name":"2. Ripplebrook Rory"},{"status":"ACTIVE","sortPriority":3,"id":37456368,"name":"3. Shes So Lovable"},{"status":"ACTIVE","sortPriority":4,"id":39784359,"name":"4. Nicholas Rose"},{"status":"ACTIVE","sortPriority":5,"id":39980001,"name":"7. Elmo Rose"},{"status":"ACTIVE","sortPriority":6,"id":28755739,"name":"8. Perfect Colour"}],"regulators":["MR_INT"],"venue":"Traralgon","countryCode":"AU","discountAllowed":true,"timezone":"Australia/Sydney","openDate":"2022-03-02T08:31:00.000Z","version":4382425369,"name":"To Be Placed","eventName":"Traralgon (AUS) 2nd Mar"},"rc":[{"atb":[[2.5,66.69],[2.6,62.52],[2.7,58.84]],"id":26503913},{"atl":[[8.6,9.57],[11.5,6.93],[6.6,6.49]],"id":26503913},{"spn":4.65,"spf":"NaN","id":26503913},{"atb":[[1.2,500.19],[1.25,400.15],[1.3,333.46]],"id":28755739},{"atl":[[2.54,23.62],[2.74,41.81],[2.94,37.5]],"id":28755739},{"spn":1.92,"spf":"NaN","id":28755739},{"atb":[[1.8,125.04],[1.85,117.69],[1.75,133.38]],"id":37456368},{"atl":[[4.5,20.78],[5.5,16.16],[3.75,13.22]],"id":37456368},{"spn":2.8,"spf":"NaN","id":37456368},{"atb":[[2.82,54.96],[2.92,52.1],[3.05,48.79]],"id":36036864},{"spl":[[1.01,2.73]],"id":36036864},{"atl":[[10.5,7.65],[8.2,5.05],[15.5,5.01]],"id":36036864},{"spn":3.05,"spf":1.0,"id":36036864},{"atb":[[3.45,40.83],[3.95,33.9],[3.7,37.04]],"id":39784359},{"spl":[[1.01,2.73]],"id":39784359},{"atl":[[18.5,4.15],[13.5,2.91],[27,2.79]],"id":39784359},{"spn":3.95,"spf":1.0,"id":39784359},{"atb":[[1.8,125.04],[1.85,117.69],[1.75,133.38]],"id":39980001},{"atl":[[4.5,20.78],[5.5,16.16],[3.75,13.22]],"id":39980001},{"spn":2.8,"spf":"NaN","id":39980001}],"con":true,"img":true}]}
{"op":"mcm","clk":"5347381372","pt":1646198202730,"mc":[{"id":"1.195453616","marketDefinition":{"bspMarket":true,"turnInPlayEnabled":false,"persistenceEnabled":false,"marketBaseRate":7.0,"eventId":"31272494","eventTypeId":"4339","numberOfWinners":2,"bettingType":"ODDS","marketType":"PLACE","marketTime":"2022-03-02T09:33:00.000Z","suspendTime":"2022-03-02T09:33:00.000Z","bspReconciled":false,"complete":true,"inPlay":false,"crossMatching":false,"runnersVoidable":false,"numberOfActiveRunners":6,"betDelay":0,"status":"OPEN","runners":[{"status":"ACTIVE","sortPriority":1,"id":26503913,"name":"1. Callum Ari"},{"status":"ACTIVE","sortPriority":2,"id":36036864,"name":"2. Ripplebrook Rory"},{"status":"ACTIVE","sortPriority":3,"id":37456368,"name":"3. Shes So Lovable"},{"status":"ACTIVE","sortPriority":4,"id":39784359,"name":"4. Nicholas Rose"},{"status":"ACTIVE","sortPriority":5,"id":39980001,"name":"7. Elmo Rose"},{"status":"ACTIVE","sortPriority":6,"id":28755739,"name":"8. Perfect Colour"}],"regulators":["MR_INT"],"venue":"Traralgon","countryCode":"AU","discountAllowed":true,"timezone":"Australia/Sydney","openDate":"2022-03-02T08:31:00.000Z","version":4382425369,"name":"To Be Placed","eventName":"Traralgon (AUS) 2nd Mar"},"rc":[{"atb":[[2.5,66.66],[2.6,62.5],[2.7,58.82]],"id":26503913},{"atl":[[8.6,9.57],[11.5,6.92],[6.6,6.49]],"id":26503913},{"spn":4.65,"spf":"NaN","id":26503913},{"atb":[[1.2,500],[1.25,400],[1.3,333.33]],"id":28755739},{"atl":[[2.54,23.61],[2.74,41.79],[2.94,37.48]],"id":28755739},{"spn":1.92,"spf":"NaN","id":28755739},{"atb":[[1.8,125],[1.85,117.64],[1.75,133.33]],"id":37456368},{"atl":[[4.5,20.78],[5.5,16.16],[3.75,13.22]],"id":37456368},{"spn":2.8,"spf":"NaN","id":37456368},{"atb":[[2.82,54.94],[2.92,52.08],[3.05,48.77]],"id":36036864},{"spl":[[1.01,2.73]],"id":36036864},{"atl":[[10.5,7.65],[8.2,5.05],[15.5,5.01]],"id":36036864},{"spn":3.05,"spf":1.0,"id":36036864},{"atb":[[3.45,40.81],[3.95,33.89],[3.7,37.03]],"id":39784359},{"spl":[[1.01,2.73]],"id":39784359},{"atl":[[18.5,4.15],[13.5,2.91],[27,2.79]],"id":39784359},{"spn":3.95,"spf":1.0,"id":39784359},{"atb":[[1.8,125],[1.85,117.64],[1.75,133.33]],"id":39980001},{"atl":[[4.5,20.78],[5.5,16.16],[3.75,13.22]],"id":39980001},{"spn":2.8,"spf":"NaN","id":39980001}],"con":true,"img":true}]}
{"op":"mcm","clk":"5347806453","pt":1646208227008,"mc":[{"id":"1.195453616","rc":[{"atb":[[2.5,66.64],[2.12,55.67],[2.6,62.48],[2.62,26.95],[2.7,58.81]],"id":26503913},{"atl":[[9.6,5.07],[8.6,9.56],[10.5,6],[11.5,6.92],[6.6,6.49]],"id":26503913},{"spn":4.65,"spf":"NaN","id":26503913},{"atb":[[1.2,499.86],[1.25,399.89],[1.26,235.13],[1.3,333.24],[1.31,86.21]],"id":28755739},{"atl":[[2.72,60.93],[2.54,23.6],[2.74,41.78],[2.94,37.47]],"id":28755739},{"spn":1.92,"spf":"NaN","id":28755739},{"atb":[[1.8,124.96],[1.81,53.91],[1.55,110.66],[1.85,117.61],[1.75,133.29]],"id":37456368},{"atl":[[4.5,20.77],[5.5,16.15],[4.4,12.84],[3.75,13.22],[5.4,13.83]],"id":37456368},{"atb":[[2.82,54.92],[2.92,52.06],[3.2,20.79],[2.94,33.29],[3.05,48.76]],"id":36036864},{"spl":[[1.01,2.72]],"id":36036864},{"atl":[[10.5,7.65],[8.2,5.04],[15,7.48],[15.5,5.01]],"id":36036864},{"spn":3.2,"spf":1.0,"id":36036864},{"atb":[[3.45,40.8],[3.95,33.88],[3.7,37.02],[3.8,20.98],[4.4,12.84]],"id":39784359},{"spl":[[1.01,2.72]],"id":39784359},{"atl":[[18.5,4.15],[23,2.72],[25,2.72],[13.5,2.9],[27,2.79]],"id":39784359},{"spn":4.4,"spf":1.0,"id":39784359},{"atb":[[1.8,124.96],[1.55,104.45],[1.85,117.61],[1.86,50.77],[1.75,133.29]],"id":39980001},{"atl":[[4.5,20.77],[5.5,16.15],[4.4,12.84],[3.75,13.22],[5.4,13.05]],"id":39980001},{"spn":2.8,"spf":"NaN","id":39980001}],"con":true,"img":false}]}
{"op":"mcm","clk":"5347808619","pt":1646208280348,"mc":[{"id":"1.195453616","rc":[{"atl":[[2.72,35.54]],"id":28755739}],"con":true,"img":false}]}
{"op":"mcm","clk":"5347808623","pt":1646208280453,"mc":[{"id":"1.195453616","rc":[{"atl":[[2.52,25.38]],"id":28755739}],"con":true,"img":false}]}
{"op":"mcm","clk":"5347809278","pt":1646208295316,"mc":[{"id":"1.195453616","rc":[{"spn":1.91,"spf":"NaN","id":28755739},{"atb":[[2.94,0]],"id":36036864},{"atb":[[3.8,0]],"id":39784359}],"con":true,"img":false}]}
{"op":"mcm","clk":"5347809282","pt":1646208295375,"mc":[{"id":"1.195453616","rc":[{"atb":[[3.1,33.29]],"id":36036864},{"atb":[[4,20.98]],"id":39784359}],"con":true,"img":false}]}
{"op":"mcm","clk":"5347814075","pt":1646208407033,"mc":[{"id":"1.195453616","rc":[{"spl":[[1.01,8.18]],"id":39784359}],"con":true,"img":false}]}
{"op":"mcm","clk":"5347831614","pt":1646208802204,"mc":[{"id":"1.195453616","rc":[{"atb":[[2.12,0],[2.62,0]],"id":26503913},{"atl":[[9.6,0],[10.5,0]],"id":26503913},{"atb":[[1.26,0],[1.31,0]],"id":28755739},{"atl":[[2.72,0],[2.52,0]],"id":28755739},{"spn":1.92,"spf":"NaN","id":28755739},{"atb":[[1.81,0],[1.55,0]],"id":37456368},{"atl":[[4.4,0],[5.4,0]],"id":37456368},{"atb":[[3.2,0],[3.1,0]],"id":36036864},{"atl":[[15,0]],"id":36036864},{"spn":3.05,"spf":1.0,"id":36036864},{"atb":[[4,0],[4.4,0]],"id":39784359},{"atl":[[23,0],[25,0]],"id":39784359},{"spn":3.95,"spf":1.0,"id":39784359},{"atb":[[1.55,0],[1.86,0]],"id":39980001},{"atl":[[4.4,0],[5.4,0]],"id":39980001},{"spn":2.8,"spf":"NaN","id":39980001}],"con":true,"img":false}]}
{"op":"mcm","clk":"5347835217","pt":1646208872005,"mc":[{"id":"1.195453616","rc":[{"atb":[[2.62,26.95],[2.16,54.03]],"id":26503913},{"atl":[[11,10.37]],"id":26503913},{"atb":[[1.26,235.13],[1.31,86.21]],"id":28755739},{"atl":[[2.72,35.54],[2.68,25.38]],"id":28755739},{"spn":1.92,"spf":"NaN","id":28755739},{"atb":[[1.81,53.91],[1.48,126.79]],"id":37456368},{"atl":[[4.4,30.74]],"id":37456368},{"atb":[[3.6,16.79],[3.1,33.29]],"id":36036864},{"atl":[[18.5,2.72],[20,3.27]],"id":36036864},{"spn":3.6,"spf":1.0,"id":36036864},{"atb":[[3.8,20.98],[4.4,12.84]],"id":39784359},{"atl":[[32,2.72],[28,2.72]],"id":39784359},{"spn":4.4,"spf":1.0,"id":39784359},{"atb":[[1.86,50.77],[1.49,117.24]],"id":39980001},{"atl":[[4.4,29.74]],"id":39980001},{"spn":2.8,"spf":"NaN","id":39980001}],"con":true,"img":false}]}
{"op":"mcm","clk":"5347837931","pt":1646208921948,"mc":[{"id":"1.195453616","rc":[{"atl":[[2.68,0]],"id":28755739}],"con":true,"img":false}]}
{"op":"mcm","clk":"5347837936","pt":1646208922055,"mc":[{"id":"1.195453616","rc":[{"atl":[[2.52,25.38]],"id":28755739}],"con":true,"img":false}]}
{"op":"mcm","clk":"5347839027","pt":1646208940062,"mc":[{"id":"1.195453616","rc":[{"spn":1.91,"spf":"NaN","id":28755739},{"atb":[[3.8,0]],"id":39784359}],"con":true,"img":false}]}
{"op":"mcm","clk":"5347839030","pt":1646208940165,"mc":[{"id":"1.195453616","rc":[{"atb":[[4,20.98]],"id":39784359}],"con":true,"img":false}]}
{"op":"mcm","clk":"5347842030","pt":1646208993849,"mc":[{"id":"1.195453616","rc":[{"atl":[[4.4,12.84]],"id":37456368},{"atl":[[4.4,12.84]],"id":39980001}],"con":true,"img":false}]}
{"op":"mcm","clk":"5347851671","pt":1646209015585,"mc":[{"id":"1.195453616","rc":[{"atl":[[11,6]],"id":26503913},{"atb":[[3.6,0]],"id":36036864},{"atl":[[18.5,0]],"id":36036864},{"atl":[[28,0]],"id":39784359}],"con":true,"img":false}]}
{"op":"mcm","clk":"5347851678","pt":1646209015689,"mc":[{"id":"1.195453616","rc":[{"atl":[[9.6,4.36]],"id":26503913},{"atb":[[3.2,16.79]],"id":36036864},{"atl":[[15,2.72]],"id":36036864},{"atl":[[23,2.72]],"id":39784359}],"con":true,"img":false}]}
{"op":"mcm","clk":"5347852272","pt":1646209025098,"mc":[{"id":"1.195453616","rc":[{"atl":[[5.4,13.83]],"id":37456368},{"atl":[[5.4,13.05]],"id":39980001}],"con":true,"img":false}]}
{"op":"mcm","clk":"5347853372","pt":1646209043721,"mc":[{"id":"1.195453616","rc":[{"atl":[[9.6,0]],"id":26503913},{"atl":[[15,0]],"id":36036864},{"atl":[[32,0],[23,0]],"id":39784359}],"con":true,"img":false}]}
{"op":"mcm","clk":"5347853380","pt":1646209043826,"mc":[{"id":"1.195453616","rc":[{"atl":[[12,4.36]],"id":26503913},{"atl":[[18,2.72]],"id":36036864},{"atl":[[26,2.72],[27,5.52]],"id":39784359}],"con":true,"img":false}]}
{"op":"mcm","clk":"5347854860","pt":1646209068976,"mc":[{"id":"1.195453616","rc":[{"atb":[[3.2,0]],"id":36036864},{"spn":3.1,"spf":1.0,"id":36036864}],"con":true,"img":false}]}
{"op":"mcm","clk":"5347854867","pt":1646209069085,"mc":[{"id":"1.195453616","rc":[{"atb":[[3.55,16.79]],"id":36036864}],"con":true,"img":false}]}
{"op":"mcm","clk":"5347856799","pt":1646209099132,"mc":[{"id":"1.195453616","rc":[{"atl":[[4.4,30.74],[5.4,0]],"id":37456368},{"atl":[[4.4,29.74],[5.4,0]],"id":39980001}],"con":true,"img":false}]}
{"op":"mcm","clk":"5347860655","pt":1646209168736,"mc":[{"id":"1.195453616","rc":[{"atl":[[11,0]],"id":26503913},{"spn":3.55,"spf":1.0,"id":36036864}],"con":true,"img":false}]}
{"op":"mcm","clk":"5347860657","pt":1646209168838,"mc":[{"id":"1.195453616","rc":[{"atl":[[13,6]],"id":26503913}],"con":true,"img":false}]}
{"op":"mcm","clk":"5347863334","pt":1646209221007,"mc":[{"id":"1.195453616","rc":[{"atl":[[4.4,12.84],[5.4,13.83]],"id":37456368},{"atb":[[3.55,0]],"id":36036864},{"atl":[[4.4,12.84],[5.4,13.05]],"id":39980001}],"con":true,"img":false}]}
{"op":"mcm","clk":"5347863340","pt":1646209221109,"mc":[{"id":"1.195453616","rc":[{"atb":[[3.25,16.79]],"id":36036864}],"con":true,"img":false}]}
{"op":"mcm","clk":"5347863888","pt":1646209231135,"mc":[{"id":"1.195453616","rc":[{"atb":[[1.26,396.28]],"id":28755739},{"spn":3.25,"spf":1.0,"id":36036864}],"con":true,"img":false}]}
{"op":"mcm","clk":"5347863893","pt":1646209231238,"mc":[{"id":"1.195453616","rc":[{"atb":[[1.31,0]],"id":28755739}],"con":true,"img":false}]}
{"op":"mcm","clk":"5347864607","pt":1646209245438,"mc":[{"id":"1.195453616","rc":[{"atl":[[13,0]],"id":26503913}],"con":true,"img":false}]}
{"op":"mcm","clk":"5347864612","pt":1646209245541,"mc":[{"id":"1.195453616","rc":[{"atl":[[10.5,6]],"id":26503913}],"con":true,"img":false}]}
{"op":"mcm","clk":"5347864796","pt":1646209250006,"mc":[{"id":"1.195453616","rc":[{"atb":[[2.62,0]],"id":26503913},{"atl":[[12,0]],"id":26503913},{"atb":[[1.81,0]],"id":37456368},{"atl":[[18,0]],"id":36036864},{"atb":[[4.4,0]],"id":39784359},{"atl":[[27,2.79]],"id":39784359}],"con":true,"img":false}]}
{"op":"mcm","clk":"5347864802","pt":1646209250040,"mc":[{"id":"1.195453616","rc":[{"atb":[[2.72,26.95]],"id":26503913},{"atl":[[9.6,4.36]],"id":26503913},{"atb":[[1.86,53.91]],"id":37456368},{"atl":[[14.5,2.72]],"id":36036864},{"atb":[[4.5,12.84]],"id":39784359},{"atl":[[23,2.72]],"id":39784359}],"con":true,"img":false}]}
{"op":"mcm","clk":"5347865794","pt":1646209267859,"mc":[{"id":"1.195453616","rc":[{"atl":[[9.6,0],[10.5,0]],"id":26503913},{"atl":[[14.5,0]],"id":36036864},{"atl":[[23,0]],"id":39784359}],"con":true,"img":false}]}
{"op":"mcm","clk":"5347865799","pt":1646209267964,"mc":[{"id":"1.195453616","rc":[{"atl":[[11,6],[12,4.36]],"id":26503913},{"atl":[[17.5,2.72]],"id":36036864},{"atl":[[28,2.72]],"id":39784359}],"con":true,"img":false}]}
{"op":"mcm","clk":"5347867665","pt":1646209301909,"mc":[{"id":"1.195453616","rc":[{"spn":4.66,"spf":"NaN","id":26503913},{"spn":1.91,"spf":"NaN","id":28755739},{"spn":2.8,"spf":"NaN","id":37456368},{"atb":[[3.25,0]],"id":36036864},{"spn":3.1,"spf":1.0,"id":36036864},{"atb":[[4.5,0]],"id":39784359},{"spn":4.0,"spf":1.0,"id":39784359}],"con":true,"img":false}]}
{"op":"mcm","clk":"5347867670","pt":1646209302006,"mc":[{"id":"1.195453616","rc":[{"atb":[[3.55,16.79]],"id":36036864},{"atb":[[4.6,12.84]],"id":39784359}],"con":true,"img":false}]}
{"op":"mcm","clk":"5347869211","pt":1646209333165,"mc":[{"id":"1.195453616","rc":[{"atb":[[2.52,40.93],[2.16,0]],"id":26503913},{"atl":[[4.4,30.74],[5.4,0]],"id":37456368},{"atl":[[4.4,29.74],[5.4,0]],"id":39980001}],"con":true,"img":false}]}
{"op":"mcm","clk":"5347871047","pt":1646209370031,"mc":[{"id":"1.195453616","rc":[{"atb":[[2.18,52.94]],"id":26503913},{"atl":[[5.4,13.83]],"id":37456368},{"atb":[[3.55,0]],"id":36036864},{"spn":4.6,"spf":1.0,"id":39784359},{"atl":[[5.4,13.05]],"id":39980001}],"con":true,"img":false}]}
{"op":"mcm","clk":"5347871053","pt":1646209370135,"mc":[{"id":"1.195453616","rc":[{"atb":[[2.52,0]],"id":26503913},{"atl":[[4.4,12.84]],"id":37456368},{"atb":[[3.25,16.79]],"id":36036864},{"atl":[[4.4,12.84]],"id":39980001}],"con":true,"img":false}]}
{"op":"mcm","clk":"5347872250","pt":1646209397525,"mc":[{"id":"1.195453616","rc":[{"atl":[[12,0]],"id":26503913},{"atl":[[17.5,0]],"id":36036864},{"atl":[[28,0]],"id":39784359}],"con":true,"img":false}]}
{"op":"mcm","clk":"5347872252","pt":1646209397626,"mc":[{"id":"1.195453616","rc":[{"atl":[[9.6,4.36]],"id":26503913},{"atl":[[14.5,2.72]],"id":36036864},{"atl":[[23,2.72]],"id":39784359}],"con":true,"img":false}]}
{"op":"mcm","clk":"5347873202","pt":1646209423880,"mc":[{"id":"1.195453616","rc":[{"atl":[[9.6,0],[11,0]],"id":26503913},{"atl":[[14.5,0]],"id":36036864}],"con":true,"img":false}]}
{"op":"mcm","clk":"5347873209","pt":1646209423981,"mc":[{"id":"1.195453616","rc":[{"atl":[[12,4.36],[13,6]],"id":26503913},{"atl":[[17,2.72]],"id":36036864}],"con":true,"img":false}]}
{"op":"mcm","clk":"5347874653","pt":1646209451996,"mc":[{"id":"1.195453616","rc":[{"atb":[[3.25,0]],"id":36036864}],"con":true,"img":false}]}
{"op":"mcm","clk":"5347874659","pt":1646209452101,"mc":[{"id":"1.195453616","rc":[{"atb":[[3.5,16.79]],"id":36036864}],"con":true,"img":false}]}
{"op":"mcm","clk":"5347874971","pt":1646209457531,"mc":[{"id":"1.195453616","rc":[{"atl":[[23,0]],"id":39784359}],"con":true,"img":false}]}
{"op":"mcm","clk":"5347874976","pt":1646209457633,"mc":[{"id":"1.195453616","rc":[{"atl":[[26,5.45]],"id":39784359}],"con":true,"img":false}]}
{"op":"mcm","clk":"5347876199","pt":1646209481630,"mc":[{"id":"1.195453616","rc":[{"atl":[[4.4,30.74],[5.4,0]],"id":37456368},{"atl":[[4.4,29.74],[5.4,0]],"id":39980001}],"con":true,"img":false}]}
{"op":"mcm","clk":"5347876478","pt":1646209487551,"mc":[{"id":"1.195453616","rc":[{"atb":[[2.52,40.93],[2.18,0]],"id":26503913},{"atl":[[13,0]],"id":26503913}],"con":true,"img":false}]}
{"op":"mcm","clk":"5347876486","pt":1646209487662,"mc":[{"id":"1.195453616","rc":[{"atl":[[11,6]],"id":26503913}],"con":true,"img":false}]}
{"op":"mcm","clk":"5347878374","pt":1646209526001,"mc":[{"id":"1.195453616","rc":[{"atb":[[3.5,0]],"id":36036864}],"con":true,"img":false}]}
{"op":"mcm","clk":"5347878379","pt":1646209526105,"mc":[{"id":"1.195453616","rc":[{"atb":[[3.6,16.79]],"id":36036864}],"con":true,"img":false}]}
{"op":"mcm","clk":"5347880011","pt":1646209558077,"mc":[{"id":"1.195453616","rc":[{"atl":[[11,0]],"id":26503913}],"con":true,"img":false}]}
{"op":"mcm","clk":"5347880019","pt":1646209558130,"mc":[{"id":"1.195453616","rc":[{"atl":[[13,6]],"id":26503913}],"con":true,"img":false}]}
{"op":"mcm","clk":"5347880222","pt":1646209562652,"mc":[{"id":"1.195453616","rc":[{"atb":[[2.52,0],[2.18,52.94]],"id":26503913},{"atl":[[4.4,12.84],[5.4,13.83]],"id":37456368},{"atb":[[3.6,0]],"id":36036864},{"atl":[[4.4,12.84],[5.4,13.05]],"id":39980001}],"con":true,"img":false}]}
{"op":"mcm","clk":"5347880228","pt":1646209562754,"mc":[{"id":"1.195453616","rc":[{"atb":[[3.25,16.79]],"id":36036864}],"con":true,"img":false}]}
{"op":"mcm","clk":"5347883382","pt":1646209626316,"mc":[{"id":"1.195453616","rc":[{"atl":[[13,0]],"id":26503913},{"atl":[[17,0]],"id":36036864},{"spn":3.25,"spf":1.0,"id":36036864},{"atl":[[26,2.72]],"id":39784359}],"con":true,"img":false}]}
{"op":"mcm","clk":"5347883384","pt":1646209626412,"mc":[{"id":"1.195453616","rc":[{"atl":[[10.5,6]],"id":26503913},{"atl":[[14.5,2.72]],"id":36036864},{"atl":[[23,2.72]],"id":39784359}],"con":true,"img":false}]}
{"op":"mcm","clk":"5347883712","pt":1646209633212,"mc":[{"id":"1.195453616","rc":[{"atl":[[12,0]],"id":26503913}],"con":true,"img":false}]}
{"op":"mcm","clk":"5347883718","pt":1646209633318,"mc":[{"id":"1.195453616","rc":[{"atl":[[9.6,4.36]],"id":26503913}],"con":true,"img":false}]}
{"op":"mcm","clk":"5347884755","pt":1646209651583,"mc":[{"id":"1.195453616","rc":[{"atl":[[9.6,0],[10.5,0]],"id":26503913},{"atl":[[14.5,0]],"id":36036864}],"con":true,"img":false}]}
{"op":"mcm","clk":"5347884760","pt":1646209651672,"mc":[{"id":"1.195453616","rc":[{"atl":[[11,6],[12,4.36]],"id":26503913},{"atl":[[17,2.72]],"id":36036864}],"con":true,"img":false}]}
{"op":"mcm","clk":"5347886176","pt":1646209682478,"mc":[{"id":"1.195453616","rc":[{"atb":[[3.25,0]],"id":36036864}],"con":true,"img":false}]}
{"op":"mcm","clk":"5347886183","pt":1646209682579,"mc":[{"id":"1.195453616","rc":[{"atb":[[3.5,16.79]],"id":36036864}],"con":true,"img":false}]}
{"op":"mcm","clk":"5347886551","pt":1646209689367,"mc":[{"id":"1.195453616","rc":[{"spn":3.5,"spf":1.0,"id":36036864},{"atl":[[23,0]],"id":39784359}],"con":true,"img":false}]}
{"op":"mcm","clk":"5347886555","pt":1646209689475,"mc":[{"id":"1.195453616","rc":[{"atl":[[26,5.45]],"id":39784359}],"con":true,"img":false}]}
{"op":"mcm","clk":"5347887712","pt":1646209712629,"mc":[{"id":"1.195453616","rc":[{"atb":[[2.52,40.93]],"id":26503913},{"atl":[[4.4,30.74]],"id":37456368},{"atl":[[4.4,29.74]],"id":39980001}],"con":true,"img":false}]}
{"op":"mcm","clk":"5347887718","pt":1646209712726,"mc":[{"id":"1.195453616","rc":[{"atb":[[2.18,0]],"id":26503913},{"atl":[[5.4,0]],"id":37456368},{"atl":[[5.4,0]],"id":39980001}],"con":true,"img":false}]}
{"op":"mcm","clk":"5347890860","pt":1646209775158,"mc":[{"id":"1.195453616","rc":[{"atb":[[3.5,0]],"id":36036864},{"spn":3.1,"spf":1.0,"id":36036864}],"con":true,"img":false}]}
{"op":"mcm","clk":"5347890865","pt":1646209775266,"mc":[{"id":"1.195453616","rc":[{"atb":[[3.6,16.79]],"id":36036864}],"con":true,"img":false}]}
{"op":"mcm","clk":"5347891448","pt":1646209787115,"mc":[{"id":"1.195453616","rc":[{"atb":[[2.52,0],[2.18,52.94]],"id":26503913},{"atl":[[4.4,12.84],[5.4,13.83]],"id":37456368},{"atb":[[3.6,0]],"id":36036864},{"atl":[[4.4,12.84],[5.4,13.05]],"id":39980001}],"con":true,"img":false}]}
{"op":"mcm","clk":"5347891455","pt":1646209787218,"mc":[{"id":"1.195453616","rc":[{"atb":[[3.25,16.79]],"id":36036864}],"con":true,"img":false}]}
{"op":"mcm","clk":"5347892465","pt":1646209807440,"mc":[{"id":"1.195453616","rc":[{"atl":[[12,0]],"id":26503913},{"atl":[[17,0]],"id":36036864},{"atl":[[26,2.72]],"id":39784359}],"con":true,"img":false}]}
{"op":"mcm","clk":"5347892474","pt":1646209807543,"mc":[{"id":"1.195453616","rc":[{"atl":[[9.6,4.36]],"id":26503913},{"atl":[[14.5,2.72]],"id":36036864},{"atl":[[23,2.72]],"id":39784359}],"con":true,"img":false}]}
{"op":"mcm","clk":"5347893707","pt":1646209831862,"mc":[{"id":"1.195453616","rc":[{"atl":[[9.6,0]],"id":26503913},{"atl":[[14.5,0]],"id":36036864}],"con":true,"img":false}]}
{"op":"mcm","clk":"5347893711","pt":1646209831965,"mc":[{"id":"1.195453616","rc":[{"atl":[[12,4.36]],"id":26503913},{"atl":[[16.5,2.72]],"id":36036864}],"con":true,"img":false}]}
{"op":"mcm","clk":"5347895274","pt":1646209863989,"mc":[{"id":"1.195453616","rc":[{"atb":[[3.25,0]],"id":36036864}],"con":true,"img":false}]}
{"op":"mcm","clk":"5347895279","pt":1646209864140,"mc":[{"id":"1.195453616","rc":[{"atb":[[3.45,16.79]],"id":36036864}],"con":true,"img":false}]}
{"op":"mcm","clk":"5347896656","pt":1646209891744,"mc":[{"id":"1.195453616","rc":[{"atl":[[4.4,30.74],[5.4,0]],"id":37456368},{"atl":[[4.4,29.74],[5.4,0]],"id":39980001}],"con":true,"img":false}]}
{"op":"mcm","clk":"5347896856","pt":1646209897141,"mc":[{"id":"1.195453616","rc":[{"atb":[[2.52,40.93],[2.18,0]],"id":26503913},{"atl":[[23,0]],"id":39784359}],"con":true,"img":false}]}
{"op":"mcm","clk":"5347896858","pt":1646209897244,"mc":[{"id":"1.195453616","rc":[{"atl":[[26,5.45]],"id":39784359}],"con":true,"img":false}]}
{"op":"mcm","clk":"5347898242","pt":1646209931697,"mc":[{"id":"1.195453616","rc":[{"atl":[[11,0]],"id":26503913},{"spn":3.45,"spf":1.0,"id":36036864}],"con":true,"img":false}]}
{"op":"mcm","clk":"5347898249","pt":1646209931801,"mc":[{"id":"1.195453616","rc":[{"atl":[[13,6]],"id":26503913}],"con":true,"img":false}]}
{"op":"mcm","clk":"5347898434","pt":1646209936895,"mc":[{"id":"1.195453616","rc":[{"atb":[[3.45,0]],"id":36036864}],"con":true,"img":false}]}
{"op":"mcm","clk":"5347898437","pt":1646209936997,"mc":[{"id":"1.195453616","rc":[{"atb":[[3.6,16.79]],"id":36036864}],"con":true,"img":false}]}
{"op":"mcm","clk":"5347900374","pt":1646209983339,"mc":[{"id":"1.195453616","rc":[{"atb":[[2.34,74.63]],"id":26503913},{"atl":[[7.8,12.98]],"id":26503913},{"atb":[[1.28,357.14]],"id":28755739},{"atl":[[2.56,49]],"id":28755739},{"atb":[[1.64,156.25]],"id":37456368},{"atl":[[3.8,26.44]],"id":37456368},{"atb":[[2.54,64.94]],"id":36036864},{"atl":[[9.2,10.1]],"id":36036864},{"atb":[[2.06,67.78]],"id":39784359},{"atl":[[18.5,9.86]],"id":39784359},{"atb":[[1.8,249.96]],"id":39980001},{"atl":[[4.5,49.34]],"id":39980001}],"con":true,"img":false}]}
{"op":"mcm","clk":"5347900910","pt":1646209994846,"mc":[{"id":"1.195453616","rc":[{"atb":[[2.52,0]],"id":26503913},{"atl":[[2.72,0]],"id":28755739},{"atl":[[5.3,13.83],[4.4,12.84]],"id":37456368},{"atb":[[2.56,40.93],[3.1,0]],"id":36036864},{"spn":3.6,"spf":1.0,"id":36036864},{"atb":[[4,0]],"id":39784359},{"atl":[[4.4,12.84],[5.4,13.05]],"id":39980001}],"con":true,"img":false}]}
{"op":"mcm","clk":"5347900915","pt":1646209994948,"mc":[{"id":"1.195453616","rc":[{"atb":[[2.36,40.93]],"id":26503913},{"atl":[[2.92,35.54]],"id":28755739},{"atb":[[3.75,20.98]],"id":39784359}],"con":true,"img":false}]}
{"op":"mcm","clk":"5347901188","pt":1646210000986,"mc":[{"id":"1.195453616","rc":[{"atb":[[1.28,0],[1.25,799.89]],"id":28755739},{"atl":[[2.56,0],[2.86,53.76]],"id":28755739},{"atb":[[1.64,0],[1.44,227.27]],"id":37456368}],"con":true,"img":false}]}
{"op":"mcm","clk":"5347901195","pt":1646210001090,"mc":[{"id":"1.195453616","rc":[{"atl":[[2.52,0]],"id":28755739},{"atb":[[3.6,0]],"id":36036864},{"atb":[[4.6,0]],"id":39784359}],"con":true,"img":false}]}
{"op":"mcm","clk":"5347901198","pt":1646210001144,"mc":[{"id":"1.195453616","rc":[{"atl":[[2.54,48.99]],"id":28755739},{"atb":[[3.1,16.79]],"id":36036864},{"atb":[[4,12.84]],"id":39784359}],"con":true,"img":false}]}
{"op":"mcm","clk":"5347901522","pt":1646210008477,"mc":[{"id":"1.195453616","rc":[{"atl":[[13,0],[8.4,8.18]],"id":26503913}],"con":true,"img":false}]}
{"op":"mcm","clk":"5347901702","pt":1646210013084,"mc":[{"id":"1.195453616","rc":[{"atl":[[2.54,23.6]],"id":28755739}],"con":true,"img":false}]}
{"op":"mcm","clk":"5347901707","pt":1646210013189,"mc":[{"id":"1.195453616","rc":[{"atl":[[2.72,25.38]],"id":28755739}],"con":true,"img":false}]}
{"op":"mcm","clk":"5347901923","pt":1646210018998,"mc":[{"id":"1.195453616","rc":[{"atl":[[12,0],[7.6,6.61]],"id":26503913},{"atl":[[4.4,0]],"id":37456368},{"atl":[[16.5,0],[9,5.45]],"id":36036864},{"atl":[[26,2.72]],"id":39784359}],"con":true,"img":false}]}
{"op":"mcm","clk":"5347901929","pt":1646210019102,"mc":[{"id":"1.195453616","rc":[{"atl":[[3.75,26.06]],"id":37456368},{"atl":[[17.5,2.72]],"id":39784359}],"con":true,"img":false}]}
{"op":"mcm","clk":"5347901987","pt":1646210020493,"mc":[{"id":"1.195453616","rc":[{"atb":[[2.5,133.31],[2.34,0]],"id":26503913},{"atb":[[2.06,0],[2.52,65.79]],"id":39784359},{"atb":[[1.8,124.96],[1.87,114.94]],"id":39980001}],"con":true,"img":false}]}
{"op":"mcm","clk":"5347902156","pt":1646210024707,"mc":[{"id":"1.195453616","rc":[{"atb":[[2.36,0]],"id":26503913}],"con":true,"img":false}]}
{"op":"mcm","clk":"5347902163","pt":1646210024810,"mc":[{"id":"1.195453616","rc":[{"atb":[[2.14,54.58]],"id":26503913}],"con":true,"img":false}]}
{"op":"mcm","clk":"5347902852","pt":1646210043340,"mc":[{"id":"1.195453616","rc":[{"atb":[[2.5,66.64],[2.38,72.46]],"id":26503913},{"atl":[[4,33.33],[3.8,0]],"id":37456368},{"atb":[[2.4,71.43],[2.54,0]],"id":36036864},{"atl":[[9.2,0],[9.8,10.92]],"id":36036864}],"con":true,"img":false}]}
{"op":"mcm","clk":"5347902969","pt":1646210046021,"mc":[{"id":"1.195453616","rc":[{"atb":[[1.48,0]],"id":37456368},{"atl":[[12.5,5.45]],"id":36036864},{"atl":[[18,3.39]],"id":39784359},{"atb":[[1.6,95.75]],"id":39980001}],"con":true,"img":false}]}
{"op":"mcm","clk":"5347902976","pt":1646210046124,"mc":[{"id":"1.195453616","rc":[{"atb":[[1.57,126.79]],"id":37456368},{"atl":[[20,0]],"id":36036864},{"atl":[[26,0]],"id":39784359},{"atb":[[1.49,0]],"id":39980001}],"con":true,"img":false}]}
{"op":"mcm","clk":"5347903538","pt":1646210058779,"mc":[{"id":"1.195453616","rc":[{"atl":[[2.92,0]],"id":28755739},{"spn":1.92,"spf":"NaN","id":28755739},{"atl":[[3.75,13.22]],"id":37456368},{"atl":[[9,0]],"id":36036864},{"spn":3.1,"spf":1.0,"id":36036864},{"spn":4.0,"spf":1.0,"id":39784359},{"atb":[[1.86,0]],"id":39980001},{"spn":2.81,"spf":"NaN","id":39980001}],"con":true,"img":false}]}
{"op":"mcm","clk":"5347903542","pt":1646210058881,"mc":[{"id":"1.195453616","rc":[{"atl":[[2.84,35.54]],"id":28755739},{"atl":[[3.95,12.84]],"id":37456368},{"atl":[[9.6,5.45]],"id":36036864},{"atb":[[1.88,50.77]],"id":39980001}],"con":true,"img":false}]}
{"op":"mcm","clk":"5347903547","pt":1646210058985,"mc":[{"id":"1.195453616","rc":[{"atb":[[1.86,116.28],[1.87,0]],"id":39980001}],"con":true,"img":false}]}
{"op":"mcm","clk":"5347904096","pt":1646210073201,"mc":[{"id":"1.195453616","rc":[{"atb":[[1.88,0]],"id":39980001}],"con":true,"img":false}]}
{"op":"mcm","clk":"5347904102","pt":1646210073292,"mc":[{"id":"1.195453616","rc":[{"atb":[[1.87,50.77]],"id":39980001}],"con":true,"img":false}]}
{"op":"mcm","clk":"5347904847","pt":1646210095294,"mc":[{"id":"1.195453616","rc":[{"atb":[[1.88,113.64],[1.86,0]],"id":39980001}],"con":true,"img":false}]}
{"op":"mcm","clk":"5347905232","pt":1646210106124,"mc":[{"id":"1.195453616","rc":[{"atb":[[3.75,0]],"id":39784359}],"con":true,"img":false}]}
{"op":"mcm","clk":"5347905238","pt":1646210106228,"mc":[{"id":"1.195453616","rc":[{"atb":[[3.5,20.98]],"id":39784359}],"con":true,"img":false}]}
{"op":"mcm","clk":"5347905369","pt":1646210110651,"mc":[{"id":"1.195453616","rc":[{"atb":[[2.72,0]],"id":26503913},{"atb":[[1.86,0]],"id":37456368}],"con":true,"img":false}]}
{"op":"mcm","clk":"5347905372","pt":1646210110697,"mc":[{"id":"1.195453616","rc":[{"atb":[[2.62,26.95]],"id":26503913},{"atb":[[1.81,53.91]],"id":37456368}],"con":true,"img":false}]}
{"op":"mcm","clk":"5347905846","pt":1646210124941,"mc":[{"id":"1.195453616","rc":[{"spn":4.65,"spf":"NaN","id":26503913},{"spn":2.8,"spf":"NaN","id":37456368},{"atb":[[1.87,0]],"id":39980001},{"spn":2.81,"spf":"NaN","id":39980001}],"con":true,"img":false}]}
{"op":"mcm","clk":"5347905849","pt":1646210125041,"mc":[{"id":"1.195453616","rc":[{"atb":[[1.89,50.77],[1.86,116.28]],"id":39980001}],"con":true,"img":false}]}
{"op":"mcm","clk":"5347905856","pt":1646210125150,"mc":[{"id":"1.195453616","rc":[{"atb":[[1.88,0]],"id":39980001}],"con":true,"img":false}]}
{"op":"mcm","clk":"5347905970","pt":1646210128940,"mc":[{"id":"1.195453616","rc":[{"atb":[[1.26,235.13],[1.33,84.91]],"id":28755739}],"con":true,"img":false}]}
{"op":"mcm","clk":"5347906068","pt":1646210131255,"mc":[{"id":"1.195453616","rc":[{"atb":[[1.9,111.11],[1.86,0]],"id":39980001}],"con":true,"img":false}]}
{"op":"mcm","clk":"5347906853","pt":1646210151981,"mc":[{"id":"1.195453616","rc":[{"atb":[[1.89,0]],"id":39980001}],"con":true,"img":false}]}
{"op":"mcm","clk":"5347906858","pt":1646210152095,"mc":[{"id":"1.195453616","rc":[{"atb":[[1.91,50.77]],"id":39980001}],"con":true,"img":false}]}
{"op":"mcm","clk":"5347906865","pt":1646210152172,"mc":[{"id":"1.195453616","rc":[{"atb":[[1.9,0],[1.86,116.28]],"id":39980001}],"con":true,"img":false}]}
{"op":"mcm","clk":"5347906980","pt":1646210155696,"mc":[{"id":"1.195453616","rc":[{"atb":[[1.26,0]],"id":28755739}],"con":true,"img":false}]}
{"op":"mcm","clk":"5347906984","pt":1646210155749,"mc":[{"id":"1.195453616","rc":[{"atb":[[1.31,235.13]],"id":28755739}],"con":true,"img":false}]}
{"op":"mcm","clk":"5347907582","pt":1646210169898,"mc":[{"id":"1.195453616","rc":[{"atb":[[1.91,0]],"id":39980001}],"con":true,"img":false}]}
{"op":"mcm","clk":"5347907587","pt":1646210170000,"mc":[{"id":"1.195453616","rc":[{"atb":[[1.87,50.77]],"id":39980001}],"con":true,"img":false}]}
{"op":"mcm","clk":"5347908326","pt":1646210185513,"mc":[{"id":"1.195453616","rc":[{"spn":1.93,"spf":"NaN","id":28755739},{"atb":[[3.5,0]],"id":39784359},{"spn":2.81,"spf":"NaN","id":39980001}],"con":true,"img":false}]}
{"op":"mcm","clk":"5347908331","pt":1646210185617,"mc":[{"id":"1.195453616","rc":[{"atb":[[3.75,20.98]],"id":39784359}],"con":true,"img":false}]}
{"op":"mcm","clk":"5347908431","pt":1646210187586,"mc":[{"id":"1.195453616","rc":[{"atb":[[1.88,113.64],[1.86,0]],"id":39980001}],"con":true,"img":false}]}
{"op":"mcm","clk":"5347909866","pt":1646210218130,"mc":[{"id":"1.195453616","rc":[{"atb":[[1.87,0]],"id":39980001}],"con":true,"img":false}]}
{"op":"mcm","clk":"5347909870","pt":1646210218233,"mc":[{"id":"1.195453616","rc":[{"atb":[[1.89,50.77],[1.88,0],[1.86,116.28]],"id":39980001}],"con":true,"img":false}]}
{"op":"mcm","clk":"5347910089","pt":1646210222657,"mc":[{"id":"1.195453616","rc":[{"atb":[[1.9,111.11],[1.86,0]],"id":39980001}],"con":true,"img":false}]}
{"op":"mcm","clk":"5347911526","pt":1646210255499,"mc":[{"id":"1.195453616","rc":[{"atb":[[1.89,0]],"id":39980001},{"spn":2.82,"spf":"NaN","id":39980001}],"con":true,"img":false}]}
{"op":"mcm","clk":"5347911532","pt":1646210255594,"mc":[{"id":"1.195453616","rc":[{"atb":[[1.91,50.77]],"id":39980001}],"con":true,"img":false}]}
{"op":"mcm","clk":"5347911536","pt":1646210255646,"mc":[{"id":"1.195453616","rc":[{"atb":[[1.9,0],[1.86,116.28]],"id":39980001}],"con":true,"img":false}]}
{"op":"mcm","clk":"5347911627","pt":1646210257356,"mc":[{"id":"1.195453616","rc":[{"atb":[[1.92,108.7],[1.86,0]],"id":39980001}],"con":true,"img":false}]}
{"op":"mcm","clk":"5347913098","pt":1646210290119,"mc":[{"id":"1.195453616","rc":[{"atb":[[1.91,0]],"id":39980001}],"con":true,"img":false}]}
{"op":"mcm","clk":"5347913101","pt":1646210290221,"mc":[{"id":"1.195453616","rc":[{"atb":[[1.86,116.28],[1.93,50.77]],"id":39980001}],"con":true,"img":false}]}
{"op":"mcm","clk":"5347913106","pt":1646210290323,"mc":[{"id":"1.195453616","rc":[{"atb":[[1.92,0]],"id":39980001}],"con":true,"img":false}]}
{"op":"mcm","clk":"5347913161","pt":1646210291712,"mc":[{"id":"1.195453616","rc":[{"atb":[[1.86,0],[1.93,158.3]],"id":39980001}],"con":true,"img":false}]}
{"op":"mcm","clk":"5347913165","pt":1646210291814,"mc":[{"id":"1.195453616","rc":[{"atb":[[1.86,116.28],[1.93,50.77]],"id":39980001}],"con":true,"img":false}]}
{"op":"mcm","clk":"5347913168","pt":1646210291917,"mc":[{"id":"1.195453616","rc":[{"atb":[[1.86,0],[1.93,158.3]],"id":39980001}],"con":true,"img":false}]}
{"op":"mcm","clk":"5347913173","pt":1646210292020,"mc":[{"id":"1.195453616","rc":[{"atb":[[1.86,116.28],[1.93,50.77]],"id":39980001}],"con":true,"img":false}]}
{"op":"mcm","clk":"5347913178","pt":1646210292123,"mc":[{"id":"1.195453616","rc":[{"atb":[[1.86,0],[1.93,158.3]],"id":39980001}],"con":true,"img":false}]}
{"op":"mcm","clk":"5347913181","pt":1646210292232,"mc":[{"id":"1.195453616","rc":[{"atb":[[1.86,116.28],[1.93,50.77]],"id":39980001}],"con":true,"img":false}]}
{"op":"mcm","clk":"5347913188","pt":1646210292328,"mc":[{"id":"1.195453616","rc":[{"atb":[[1.86,0],[1.93,158.3]],"id":39980001}],"con":true,"img":false}]}
{"op":"mcm","clk":"5347914509","pt":1646210326433,"mc":[{"id":"1.195453616","rc":[{"atb":[[1.93,107.53]],"id":39980001},{"spn":2.84,"spf":"NaN","id":39980001}],"con":true,"img":false}]}
{"op":"mcm","clk":"5347914514","pt":1646210326537,"mc":[{"id":"1.195453616","rc":[{"atb":[[1.86,116.28],[1.94,50.77],[1.93,0]],"id":39980001}],"con":true,"img":false}]}
{"op":"mcm","clk":"5347914521","pt":1646210326640,"mc":[{"id":"1.195453616","rc":[{"atb":[[1.86,0],[1.93,107.53]],"id":39980001}],"con":true,"img":false}]}
{"op":"mcm","clk":"5347938283","pt":1646210894054,"mc":[{"id":"1.195453616","rc":[{"atb":[[2.72,1.67]],"id":26503913},{"spn":4.66,"spf":"NaN","id":26503913},{"atb":[[3.15,1.67]],"id":36036864},{"spn":3.13,"spf":1.0,"id":36036864},{"atb":[[4.1,1.67]],"id":39784359},{"spn":4.02,"spf":1.0,"id":39784359},{"spn":2.84,"spf":"NaN","id":39980001}],"con":true,"img":false}]}
{"op":"mcm","clk":"5347939212","pt":1646210912579,"mc":[{"id":"1.195453616","marketDefinition":{"bspMarket":true,"turnInPlayEnabled":false,"persistenceEnabled":false,"marketBaseRate":7.0,"eventId":"31272494","eventTypeId":"4339","numberOfWinners":2,"bettingType":"ODDS","marketType":"PLACE","marketTime":"2022-03-02T09:33:00.000Z","suspendTime":"2022-03-02T09:33:00.000Z","bspReconciled":false,"complete":true,"inPlay":false,"crossMatching":true,"runnersVoidable":false,"numberOfActiveRunners":6,"betDelay":0,"status":"OPEN","runners":[{"status":"ACTIVE","sortPriority":1,"id":26503913,"name":"1. Callum Ari"},{"status":"ACTIVE","sortPriority":2,"id":36036864,"name":"2. Ripplebrook Rory"},{"status":"ACTIVE","sortPriority":3,"id":37456368,"name":"3. Shes So Lovable"},{"status":"ACTIVE","sortPriority":4,"id":39784359,"name":"4. Nicholas Rose"},{"status":"ACTIVE","sortPriority":5,"id":39980001,"name":"7. Elmo Rose"},{"status":"ACTIVE","sortPriority":6,"id":28755739,"name":"8. Perfect Colour"}],"regulators":["MR_INT"],"venue":"Traralgon","countryCode":"AU","discountAllowed":true,"timezone":"Australia/Sydney","openDate":"2022-03-02T08:31:00.000Z","version":4382425369,"name":"To Be Placed","eventName":"Traralgon (AUS) 2nd Mar"},"rc":[],"con":true,"img":false}]}
{"op":"mcm","clk":"5347948735","pt":1646211092469,"mc":[{"id":"1.195453616","rc":[{"atl":[[2.86,0],[3.1,47.62]],"id":28755739},{"atb":[[1.44,0],[1.53,188.68]],"id":37456368},{"atb":[[2.52,0],[2.16,67.78]],"id":39784359}],"con":true,"img":false}]}
{"op":"mcm","clk":"5347948812","pt":1646211093758,"mc":[{"id":"1.195453616","rc":[{"atl":[[2.84,0]],"id":28755739}],"con":true,"img":false}]}
{"op":"mcm","clk":"5347948823","pt":1646211093862,"mc":[{"id":"1.195453616","rc":[{"atl":[[2.92,35.54]],"id":28755739}],"con":true,"img":false}]}
{"op":"mcm","clk":"5347949134","pt":1646211100075,"mc":[{"id":"1.195453616","rc":[{"atl":[[7.6,19.59],[7.8,0]],"id":26503913},{"atl":[[4,0],[3.8,26.44]],"id":37456368},{"atb":[[2.4,0],[2.54,64.94]],"id":36036864},{"atl":[[9.8,0],[9.4,10.1]],"id":36036864},{"atb":[[1.93,0],[1.95,105.26]],"id":39980001}],"con":true,"img":false}]}
{"op":"mcm","clk":"5347949992","pt":1646211119215,"mc":[{"id":"1.195453616","rc":[{"atb":[[3.1,20.77]],"id":36036864}],"con":true,"img":false}]}
{"op":"mcm","clk":"5347949997","pt":1646211119318,"mc":[{"id":"1.195453616","rc":[{"atb":[[1.99,8.43]],"id":39980001}],"con":true,"img":false}]}
{"op":"mcm","clk":"5347950003","pt":1646211119426,"mc":[{"id":"1.195453616","rc":[{"atb":[[2.76,4.74]],"id":26503913}],"con":true,"img":false}]}
{"op":"mcm","clk":"5347950022","pt":1646211119681,"mc":[{"id":"1.195453616","rc":[{"atb":[[1.36,23.2]],"id":28755739}],"con":true,"img":false}]}
{"op":"mcm","clk":"5347950037","pt":1646211119986,"mc":[{"id":"1.195453616","rc":[{"atb":[[1.89,9.38]],"id":37456368}],"con":true,"img":false}]}
{"op":"mcm","clk":"5347950040","pt":1646211120090,"mc":[{"id":"1.195453616","rc":[{"atb":[[2.72,0]],"id":26503913}],"con":true,"img":false}]}
{"op":"mcm","clk":"5347950045","pt":1646211120194,"mc":[{"id":"1.195453616","rc":[{"atb":[[2.78,1.67]],"id":26503913}],"con":true,"img":false}]}
{"op":"mcm","clk":"5347950111","pt":1646211121626,"mc":[{"id":"1.195453616","rc":[{"atl":[[2.72,0]],"id":28755739}],"con":true,"img":false}]}
{"op":"mcm","clk":"5347950120","pt":1646211121730,"mc":[{"id":"1.195453616","rc":[{"atl":[[2.52,25.38]],"id":28755739}],"con":true,"img":false}]}
{"op":"mcm","clk":"5347950209","pt":1646211123320,"mc":[{"id":"1.195453616","rc":[{"atb":[[2.5,133.29],[2.38,0]],"id":26503913},{"atl":[[7.6,6.61],[6.8,12.98]],"id":26503913},{"atl":[[16,5.82],[18.5,4.15]],"id":39784359},{"atl":[[4.5,20.77],[4.1,26.44]],"id":39980001}],"con":true,"img":false}]}
{"op":"mcm","clk":"5347950362","pt":1646211126004,"mc":[{"id":"1.195453616","rc":[{"atl":[[3.7,13.22],[3.8,0]],"id":37456368},{"atl":[[8.2,10.5],[9.4,0]],"id":36036864},{"atb":[[1.99,59.21],[1.95,0]],"id":39980001}],"con":true,"img":false}]}
{"op":"mcm","clk":"5347950443","pt":1646211127689,"mc":[{"id":"1.195453616","rc":[{"atl":[[3.95,0]],"id":37456368},{"atl":[[9.6,0]],"id":36036864}],"con":true,"img":false}]}
{"op":"mcm","clk":"5347950446","pt":1646211127790,"mc":[{"id":"1.195453616","rc":[{"atl":[[4.4,12.84]],"id":37456368},{"atl":[[11.5,5.45]],"id":36036864}],"con":true,"img":false}]}
{"op":"mcm","clk":"5347950468","pt":1646211128422,"mc":[{"id":"1.195453616","rc":[{"atl":[[7,16.67]],"id":26503913},{"atl":[[16.5,6.45]],"id":39784359}],"con":true,"img":false}]}
{"op":"mcm","clk":"5347950473","pt":1646211128510,"mc":[{"id":"1.195453616","rc":[{"atl":[[6.8,0]],"id":26503913},{"atl":[[16,0]],"id":39784359}],"con":true,"img":false}]}
{"op":"mcm","clk":"5347950716","pt":1646211133640,"mc":[{"id":"1.195453616","rc":[{"atb":[[1.94,0]],"id":39980001}],"con":true,"img":false}]}
{"op":"mcm","clk":"5347950721","pt":1646211133748,"mc":[{"id":"1.195453616","rc":[{"atb":[[1.86,50.77]],"id":39980001}],"con":true,"img":false}]}
{"op":"mcm","clk":"5347951002","pt":1646211139456,"mc":[{"id":"1.195453616","rc":[{"atl":[[2.52,0]],"id":28755739}],"con":true,"img":false}]}
{"op":"mcm","clk":"5347951005","pt":1646211139555,"mc":[{"id":"1.195453616","rc":[{"atl":[[2.72,25.38]],"id":28755739}],"con":true,"img":false}]}
{"op":"mcm","clk":"5347951890","pt":1646211158061,"mc":[{"id":"1.195453616","rc":[{"atl":[[7.6,0]],"id":26503913},{"spn":4.69,"spf":"NaN","id":26503913},{"spn":1.95,"spf":"NaN","id":28755739},{"spn":2.79,"spf":"NaN","id":37456368},{"atl":[[17.5,0]],"id":39784359},{"atl":[[4.4,0]],"id":39980001},{"spn":2.87,"spf":"NaN","id":39980001}],"con":true,"img":false}]}
{"op":"mcm","clk":"5347951898","pt":1646211158166,"mc":[{"id":"1.195453616","rc":[{"atl":[[6.8,6.61]],"id":26503913},{"atl":[[16,2.72]],"id":39784359},{"atl":[[4,12.84]],"id":39980001}],"con":true,"img":false}]}
{"op":"mcm","clk":"5347952007","pt":1646211160446,"mc":[{"id":"1.195453616","rc":[{"atb":[[2.76,9.01]],"id":26503913},{"atb":[[1.36,44.1]],"id":28755739},{"atb":[[1.89,17.84]],"id":37456368},{"atb":[[3.1,24.35]],"id":36036864},{"atb":[[2.04,7.23]],"id":39980001}],"con":true,"img":false}]}
{"op":"mcm","clk":"5347952079","pt":1646211162085,"mc":[{"id":"1.195453616","rc":[{"atb":[[2.06,1.67]],"id":39980001}],"con":true,"img":false}]}
{"op":"mcm","clk":"5347952452","pt":1646211170264,"mc":[{"id":"1.195453616","rc":[{"atb":[[1.6,0]],"id":39980001}],"con":true,"img":false}]}
{"op":"mcm","clk":"5347952945","pt":1646211180300,"mc":[{"id":"1.195453616","rc":[{"atb":[[2.56,0]],"id":36036864}],"con":true,"img":false}]}
{"op":"mcm","clk":"5347953318","pt":1646211188401,"mc":[{"id":"1.195453616","rc":[{"atl":[[12.5,0],[13.5,4.36]],"id":36036864}],"con":true,"img":false}]}
{"op":"mcm","clk":"5347953937","pt":1646211202643,"mc":[{"id":"1.195453616","rc":[{"atb":[[1.62,92.66]],"id":39980001}],"con":true,"img":false}]}
{"op":"mcm","clk":"5347954057","pt":1646211205522,"mc":[{"id":"1.195453616","rc":[{"atb":[[2.94,33.29]],"id":36036864}],"con":true,"img":false}]}
{"op":"mcm","clk":"5347955236","pt":1646211230372,"mc":[{"id":"1.195453616","rc":[{"atl":[[11.5,0],[13,3.64]],"id":36036864},{"spn":2.9,"spf":"NaN","id":39980001}],"con":true,"img":false}]}
{"op":"mcm","clk":"5347955364","pt":1646211233252,"mc":[{"id":"1.195453616","rc":[{"atl":[[13.5,0]],"id":36036864}],"con":true,"img":false}]}
{"op":"mcm","clk":"5347955371","pt":1646211233352,"mc":[{"id":"1.195453616","rc":[{"atl":[[14.5,4.36]],"id":36036864}],"con":true,"img":false}]}
{"op":"mcm","clk":"5347955858","pt":1646211243283,"mc":[{"id":"1.195453616","rc":[{"atb":[[2.5,66.64],[2.38,72.46]],"id":26503913},{"atl":[[7.4,13.24],[7,0]],"id":26503913},{"atb":[[2.4,71.43],[2.54,0]],"id":36036864},{"atl":[[8.6,13.16],[8.2,5.04]],"id":36036864},{"atb":[[1.99,8.43],[1.93,107.53]],"id":39980001}],"con":true,"img":false}]}
{"op":"mcm","clk":"5347955943","pt":1646211244677,"mc":[{"id":"1.195453616","rc":[{"atb":[[2.04,0]],"id":39980001}],"con":true,"img":false}]}
{"op":"mcm","clk":"5347956011","pt":1646211246059,"mc":[{"id":"1.195453616","rc":[{"atb":[[2.06,0]],"id":39980001}],"con":true,"img":false}]}
{"op":"mcm","clk":"5347956049","pt":1646211246883,"mc":[{"id":"1.195453616","rc":[{"atl":[[18,0]],"id":39784359}],"con":true,"img":false}]}
{"op":"mcm","clk":"5347956054","pt":1646211246985,"mc":[{"id":"1.195453616","rc":[{"atl":[[16,6.12]],"id":39784359}],"con":true,"img":false}]}
{"op":"mcm","clk":"5347956223","pt":1646211250579,"mc":[{"id":"1.195453616","rc":[{"atb":[[1.97,7.75]],"id":39980001}],"con":true,"img":false}]}
{"op":"mcm","clk":"5347958690","pt":1646211296769,"mc":[{"id":"1.195453616","rc":[{"atl":[[6.8,0]],"id":26503913},{"atl":[[2.72,0]],"id":28755739},{"atb":[[2.94,0],[2.48,45.3]],"id":36036864},{"atl":[[13,0],[8.4,5.9]],"id":36036864},{"atl":[[16,2.72]],"id":39784359},{"atb":[[1.86,0]],"id":39980001},{"spn":2.87,"spf":"NaN","id":39980001}],"con":true,"img":false}]}
{"op":"mcm","clk":"5347958695","pt":1646211296821,"mc":[{"id":"1.195453616","rc":[{"atl":[[7.2,6.61]],"id":26503913},{"atl":[[2.52,25.38]],"id":28755739},{"atl":[[18,3.39]],"id":39784359},{"atb":[[1.94,50.77]],"id":39980001}],"con":true,"img":false}]}
{"op":"mcm","clk":"5347958782","pt":1646211298828,"mc":[{"id":"1.195453616","rc":[{"atb":[[1.97,0]],"id":39980001}],"con":true,"img":false}]}
{"op":"mcm","clk":"5347959015","pt":1646211303363,"mc":[{"id":"1.195453616","rc":[{"atl":[[12,6]],"id":36036864},{"atb":[[3.75,0]],"id":39784359},{"atb":[[1.76,75.59]],"id":39980001}],"con":true,"img":false}]}
{"op":"mcm","clk":"5347959023","pt":1646211303467,"mc":[{"id":"1.195453616","rc":[{"atl":[[14.5,0]],"id":36036864},{"atb":[[4,33.83]],"id":39784359},{"atb":[[1.62,0]],"id":39980001}],"con":true,"img":false}]}
{"op":"mcm","clk":"5347959108","pt":1646211305267,"mc":[{"id":"1.195453616","rc":[{"atb":[[1.98,7.67]],"id":39980001}],"con":true,"img":false}]}
{"op":"mcm","clk":"5347960825","pt":1646211345030,"mc":[{"id":"1.195453616","rc":[{"atb":[[1.99,0]],"id":39980001}],"con":true,"img":false}]}
{"op":"mcm","clk":"5347960947","pt":1646211348126,"mc":[{"id":"1.195453616","rc":[{"atb":[[1.62,92.66],[1.76,0]],"id":39980001}],"con":true,"img":false}]}
{"op":"mcm","clk":"5347961479","pt":1646211361047,"mc":[{"id":"1.195453616","rc":[{"spn":1.94,"spf":"NaN","id":28755739},{"atb":[[1.98,16.19]],"id":39980001},{"spn":2.86,"spf":"NaN","id":39980001}],"con":true,"img":false}]}
{"op":"mcm","clk":"5347968378","pt":1646211510042,"mc":[{"id":"1.195453616","rc":[{"atb":[[4,12.84]],"id":39784359}],"con":true,"img":false}]}
{"op":"mcm","clk":"5347968382","pt":1646211510143,"mc":[{"id":"1.195453616","rc":[{"atb":[[3.75,20.98]],"id":39784359}],"con":true,"img":false}]}
{"op":"mcm","clk":"5347975623","pt":1646211666581,"mc":[{"id":"1.195453616","rc":[{"atb":[[2.4,44.68],[2.5,66.54],[2.6,62.38],[2.78,1.66],[2.62,26.91],[2.14,0],[2.76,9],[2.7,58.71]],"id":26503913},{"atl":[[7.2,6.6],[8.6,9.55],[11.5,6.91],[6.6,6.47],[8.4,8.17]],"id":26503913},{"atb":[[1.2,499.07],[1.36,44.04],[1.25,799.25],[1.33,84.77],[1.3,332.71],[1.31,234.76]],"id":28755739},{"atl":[[2.92,35.48],[2.54,23.57],[2.74,41.71],[2.52,25.34],[2.94,37.41]],"id":28755739},{"atb":[[1.8,124.76],[1.89,17.82],[1.81,53.82],[1.57,126.59],[1.85,117.42],[1.75,133.08]],"id":37456368},{"atl":[[4.5,20.74],[5.3,13.81],[5.5,16.13],[4.4,12.82],[3.75,13.19]],"id":37456368},{"atb":[[2.82,54.84],[2.92,51.98],[3.1,24.31],[3.15,1.66],[3.05,48.68],[2.48,45.23]],"id":36036864},{"spl":[[1.01,2.72]],"id":36036864},{"atl":[[10.5,7.64],[8.2,5.04],[12,5.99],[8.4,5.89],[15.5,5]],"id":36036864},{"atb":[[4,12.82],[3.45,40.74],[3.95,33.83],[4.1,1.66],[3.7,36.96],[3.75,20.95]],"id":39784359},{"spl":[[1.01,8.17]],"id":39784359},{"atl":[[16,2.72],[18,3.38],[18.5,4.14],[13.5,2.9],[27,2.79]],"id":39784359},{"atb":[[1.8,124.76],[1.98,16.17],[1.85,117.42],[1.62,92.51],[1.94,50.69],[1.75,133.08]],"id":39980001},{"atl":[[4,12.82],[4.5,20.74],[5.5,16.13],[3.75,13.19],[5.4,13.03]],"id":39980001}],"con":true,"img":false}]}
{"op":"mcm","clk":"5347980000","pt":1646211759993,"mc":[{"id":"1.195453616","rc":[{"atb":[[1.44,103.41],[2.38,0]],"id":26503913},{"atl":[[7.4,0],[7.8,13.22]],"id":26503913},{"atl":[[2.5,25.35],[3.1,0]],"id":28755739},{"spn":1.93,"spf":"NaN","id":28755739},{"atb":[[1.59,169.49],[1.53,0]],"id":37456368},{"atb":[[2.16,0],[3.05,48.78]],"id":39784359}],"con":true,"img":false}]}
{"op":"mcm","clk":"5347980046","pt":1646211761173,"mc":[{"id":"1.195453616","rc":[{"atb":[[2.4,0],[2.14,54.49]],"id":26503913}],"con":true,"img":false}]}
{"op":"mcm","clk":"5347980607","pt":1646211774212,"mc":[{"id":"1.195453616","rc":[{"atl":[[7.2,0]],"id":26503913}],"con":true,"img":false}]}
{"op":"mcm","clk":"5347980613","pt":1646211774310,"mc":[{"id":"1.195453616","rc":[{"atl":[[7.6,6.6]],"id":26503913}],"con":true,"img":false}]}
{"op":"mcm","clk":"5347980992","pt":1646211781736,"mc":[{"id":"1.195453616","rc":[{"atl":[[2.52,0]],"id":28755739}],"con":true,"img":false}]}
{"op":"mcm","clk":"5347980998","pt":1646211781793,"mc":[{"id":"1.195453616","rc":[{"atl":[[2.48,25.34]],"id":28755739}],"con":true,"img":false}]}
{"op":"mcm","clk":"5347981004","pt":1646211781941,"mc":[{"id":"1.195453616","rc":[{"atb":[[1.54,37.04],[1.5,150],[1.48,250],[1.52,96.15]],"id":26503913},{"atl":[[5.1,18.29],[5.3,29.07],[4.9,12.82],[4.7,5.41]],"id":26503913},{"atb":[[1.33,236.29],[1.29,250],[1.31,476.7],[1.35,57.14]],"id":28755739},{"atl":[[1.92,81.52],[2.5,0],[1.88,22.73],[2.52,50.7],[1.9,55.56],[1.94,132.98]],"id":28755739},{"atb":[[1.8,187.26],[1.82,24.39],[1.78,96.15],[1.76,164.47]],"id":37456368},{"atl":[[2.86,10.75],[2.9,26.32],[2.98,63.13],[2.94,38.66]],"id":37456368},{"atb":[[3.2,22.73],[3.1,60.02],[3,62.5],[3.3,8.7]],"id":36036864},{"atl":[[7.2,12.1],[6.4,3.7],[6.8,8.62],[7.6,18.94]],"id":36036864},{"atb":[[3.2,22.73],[3.1,35.71],[3,62.5],[3.3,8.7]],"id":39784359},{"atl":[[10.5,5.26],[11.5,7.14],[9.8,2.27],[12.5,10.87]],"id":39784359},{"atb":[[1.72,173.61],[1.74,101.35],[1.78,25.64],[1.76,65.79]],"id":39980001},{"atl":[[4.8,32.89],[4.6,20.83],[4.4,14.71],[4.2,6.25]],"id":39980001}],"con":true,"img":false}]}
{"op":"mcm","clk":"5347981013","pt":1646211782107,"mc":[{"id":"1.195453616","rc":[{"atl":[[3.7,0],[3.65,13.2]],"id":37456368}],"con":true,"img":false}]}
{"op":"mcm","clk":"5347981030","pt":1646211782422,"mc":[{"id":"1.195453616","rc":[{"atb":[[1.28,357.14],[1.25,399.25]],"id":28755739},{"atb":[[1.64,156.25],[1.59,0]],"id":37456368},{"atb":[[2.4,0],[2.54,64.94]],"id":36036864},{"atb":[[1.99,50.69],[1.93,0]],"id":39980001}],"con":true,"img":false}]}
{"op":"mcm","clk":"5347981068","pt":1646211783139,"mc":[{"id":"1.195453616","rc":[{"atl":[[4.6,5.56],[4.7,0]],"id":26503913},{"atb":[[1.36,23.15]],"id":28755739},{"atl":[[1.88,0],[1.87,22.99]],"id":28755739},{"atb":[[3.1,56.44]],"id":36036864},{"atl":[[8,14.29],[8.6,0]],"id":36036864},{"atb":[[1.98,8.5]],"id":39980001},{"atl":[[4.1,0],[4.4,40.73]],"id":39980001}],"con":true,"img":false}]}
{"op":"mcm","clk":"5347981093","pt":1646211783616,"mc":[{"id":"1.195453616","rc":[{"atl":[[8.4,0]],"id":26503913},{"atl":[[18,0]],"id":39784359}],"con":true,"img":false}]}
{"op":"mcm","clk":"5347981096","pt":1646211783712,"mc":[{"id":"1.195453616","rc":[{"atl":[[9.4,8.17]],"id":26503913},{"atl":[[19.5,3.38]],"id":39784359}],"con":true,"img":false}]}
{"op":"mcm","clk":"5347981304","pt":1646211787536,"mc":[{"id":"1.195453616","rc":[{"atb":[[3.15,0]],"id":36036864}],"con":true,"img":false}]}
{"op":"mcm","clk":"5347981320","pt":1646211787747,"mc":[{"id":"1.195453616","rc":[{"atb":[[3.35,1.66]],"id":36036864}],"con":true,"img":false}]}
{"op":"mcm","clk":"5347981381","pt":1646211788964,"mc":[{"id":"1.195453616","rc":[{"atb":[[1.38,19.78]],"id":28755739},{"atb":[[3.25,3.33]],"id":36036864},{"atb":[[2.04,7.23]],"id":39980001}],"con":true,"img":false}]}
{"op":"mcm","clk":"5347981415","pt":1646211789717,"mc":[{"id":"1.195453616","rc":[{"atl":[[4,0]],"id":39980001}],"con":true,"img":false}]}
{"op":"mcm","clk":"5347981419","pt":1646211789822,"mc":[{"id":"1.195453616","rc":[{"atl":[[4.3,12.82]],"id":39980001}],"con":true,"img":false}]}
{"op":"mcm","clk":"5347981660","pt":1646211793646,"mc":[{"id":"1.195453616","rc":[{"atb":[[1.94,0]],"id":39980001}],"con":true,"img":false}]}
{"op":"mcm","clk":"5347981665","pt":1646211793741,"mc":[{"id":"1.195453616","rc":[{"atb":[[1.88,50.69]],"id":39980001}],"con":true,"img":false}]}
{"op":"mcm","clk":"5347981711","pt":1646211794518,"mc":[{"id":"1.195453616","rc":[{"atb":[[2.06,1.66]],"id":39980001}],"con":true,"img":false}]}
{"op":"mcm","clk":"5347981988","pt":1646211799654,"mc":[{"id":"1.195453616","rc":[{"atb":[[1.57,0],[1.65,93.48]],"id":37456368}],"con":true,"img":false}]}
{"op":"mcm","clk":"5347982062","pt":1646211801045,"mc":[{"id":"1.195453616","rc":[{"atl":[[2.32,75.76],[2.52,0]],"id":28755739}],"con":true,"img":false}]}
{"op":"mcm","clk":"5347982092","pt":1646211801558,"mc":[{"id":"1.195453616","rc":[{"atb":[[1.28,0],[1.3,665.43]],"id":28755739},{"atb":[[1.64,0],[1.72,138.89]],"id":37456368},{"atb":[[2.54,0],[2.68,59.52]],"id":36036864},{"atb":[[1.99,0],[2.06,8.89]],"id":39980001}],"con":true,"img":false}]}
{"op":"mcm","clk":"5347982099","pt":1646211801662,"mc":[{"id":"1.195453616","rc":[{"atb":[[3.1,52.47]],"id":36036864},{"atb":[[1.98,0]],"id":39980001}],"con":true,"img":false}]}
{"op":"mcm","clk":"5347982135","pt":1646211802241,"mc":[{"id":"1.195453616","rc":[{"atl":[[4.4,14.71],[4.2,32.65]],"id":39980001}],"con":true,"img":false}]}
{"op":"mcm","clk":"5347982208","pt":1646211803670,"mc":[{"id":"1.195453616","rc":[{"atl":[[2.3,46.95]],"id":28755739}],"con":true,"img":false}]}
{"op":"mcm","clk":"5347982210","pt":1646211803770,"mc":[{"id":"1.195453616","rc":[{"atl":[[2.92,0]],"id":28755739},{"atb":[[1.65,0]],"id":37456368},{"atb":[[3.75,0]],"id":39784359}],"con":true,"img":false}]}
{"op":"mcm","clk":"5347982211","pt":1646211803873,"mc":[{"id":"1.195453616","rc":[{"atb":[[1.57,93.48]],"id":37456368},{"atb":[[4,33.77]],"id":39784359}],"con":true,"img":false}]}
{"op":"mcm","clk":"5347982217","pt":1646211804078,"mc":[{"id":"1.195453616","rc":[{"atb":[[2.04,0]],"id":39980001}],"con":true,"img":false}]}
{"op":"mcm","clk":"5347982292","pt":1646211805679,"mc":[{"id":"1.195453616","rc":[{"atl":[[5,10.89],[7.6,0]],"id":26503913},{"atl":[[1.89,43.59],[2.48,0]],"id":28755739},{"atl":[[2.92,22.7],[4.4,0]],"id":37456368},{"atb":[[4,20.95]],"id":39784359},{"atl":[[16,0],[12,3.96]],"id":39784359}],"con":true,"img":false}]}
{"op":"mcm","clk":"5347982294","pt":1646211805783,"mc":[{"id":"1.195453616","rc":[{"atb":[[4.3,12.82]],"id":39784359}],"con":true,"img":false}]}
{"op":"mcm","clk":"5347982402","pt":1646211807651,"mc":[{"id":"1.195453616","rc":[{"atl":[[8.4,0]],"id":36036864}],"con":true,"img":false}]}
{"op":"mcm","clk":"5347982411","pt":1646211807753,"mc":[{"id":"1.195453616","rc":[{"atl":[[7.4,5.89]],"id":36036864}],"con":true,"img":false}]}
{"op":"mcm","clk":"5347982452","pt":1646211808577,"mc":[{"id":"1.195453616","rc":[{"atb":[[4.1,0]],"id":39784359}],"con":true,"img":false}]}
{"op":"mcm","clk":"5347982465","pt":1646211808786,"mc":[{"id":"1.195453616","rc":[{"atb":[[4.4,1.66]],"id":39784359}],"con":true,"img":false}]}
{"op":"mcm","clk":"5347982525","pt":1646211809979,"mc":[{"id":"1.195453616","rc":[{"atb":[[1.92,8.17]],"id":39980001}],"con":true,"img":false}]}
{"op":"mcm","clk":"5347982781","pt":1646211814267,"mc":[{"id":"1.195453616","rc":[{"atb":[[3.15,3.87]],"id":36036864}],"con":true,"img":false}]}
{"op":"mcm","clk":"5347983367","pt":1646211825312,"mc":[{"id":"1.195453616","rc":[{"spn":3.69,"spf":"NaN","id":26503913},{"spn":1.62,"spf":"NaN","id":28755739},{"spn":2.37,"spf":"NaN","id":37456368},{"spn":3.33,"spf":1.0,"id":36036864},{"spn":4.32,"spf":1.0,"id":39784359},{"atb":[[1.92,17.23]],"id":39980001},{"spn":2.9,"spf":"NaN","id":39980001}],"con":true,"img":false}]}
{"op":"mcm","clk":"5347983385","pt":1646211825723,"mc":[{"id":"1.195453616","rc":[{"atl":[[9.4,0]],"id":26503913},{"atl":[[12,0]],"id":36036864},{"atl":[[19.5,0]],"id":39784359},{"atb":[[1.62,0],[1.86,66.69]],"id":39980001},{"atl":[[4.3,0],[4.4,31.58],[5.4,0]],"id":39980001}],"con":true,"img":false}]}
{"op":"mcm","clk":"5347983390","pt":1646211825826,"mc":[{"id":"1.195453616","rc":[{"atl":[[7.2,8.17]],"id":26503913},{"atl":[[10,5.99]],"id":36036864},{"atl":[[15.5,3.38]],"id":39784359},{"atl":[[4.1,12.82]],"id":39980001}],"con":true,"img":false}]}
{"op":"mcm","clk":"5347983396","pt":1646211825929,"mc":[{"id":"1.195453616","rc":[{"atb":[[2.94,33.24],[2.48,0]],"id":36036864}],"con":true,"img":false}]}
{"op":"mcm","clk":"5347983481","pt":1646211827624,"mc":[{"id":"1.195453616","rc":[{"atl":[[5.3,0],[3.7,22.5]],"id":37456368},{"atl":[[7.4,0]],"id":36036864}],"con":true,"img":false}]}
{"op":"mcm","clk":"5347983485","pt":1646211827729,"mc":[{"id":"1.195453616","rc":[{"atl":[[7,5.89]],"id":36036864}],"con":true,"img":false}]}
{"op":"mcm","clk":"5347984584","pt":1646211847636,"mc":[{"id":"1.195453616","rc":[{"atb":[[1.33,151.52]],"id":28755739}],"con":true,"img":false}]}
{"op":"mcm","clk":"5347984589","pt":1646211847739,"mc":[{"id":"1.195453616","rc":[{"atb":[[1.36,107.93]],"id":28755739}],"con":true,"img":false}]}
{"op":"mcm","clk":"5347984641","pt":1646211849126,"mc":[{"id":"1.195453616","rc":[{"atb":[[1.38,0]],"id":28755739}],"con":true,"img":false}]}
{"op":"mcm","clk":"5347984940","pt":1646211854974,"mc":[{"id":"1.195453616","rc":[{"atb":[[1.39,19.27]],"id":28755739}],"con":true,"img":false}]}
{"op":"mcm","clk":"5347984968","pt":1646211855746,"mc":[{"id":"1.195453616","rc":[{"atb":[[1.36,23.15]],"id":28755739}],"con":true,"img":false}]}
{"op":"mcm","clk":"5347984972","pt":1646211855850,"mc":[{"id":"1.195453616","rc":[{"atb":[[1.34,84.77]],"id":28755739}],"con":true,"img":false}]}
{"op":"mcm","clk":"5347985083","pt":1646211858058,"mc":[{"id":"1.195453616","rc":[{"atb":[[1.39,0]],"id":28755739}],"con":true,"img":false}]}
{"op":"mcm","clk":"5347985393","pt":1646211864082,"mc":[{"id":"1.195453616","rc":[{"atb":[[1.38,19.78]],"id":28755739}],"con":true,"img":false}]}
{"op":"mcm","clk":"5347985622","pt":1646211869020,"mc":[{"id":"1.195453616","rc":[{"atb":[[1.36,0]],"id":28755739}],"con":true,"img":false}]}
{"op":"mcm","clk":"5347986162","pt":1646211880400,"mc":[{"id":"1.195453616","rc":[{"atb":[[1.37,22.53]],"id":28755739}],"con":true,"img":false}]}
{"op":"mcm","clk":"5347986428","pt":1646211885716,"mc":[{"id":"1.195453616","rc":[{"atb":[[1.34,0]],"id":28755739}],"con":true,"img":false}]}
{"op":"mcm","clk":"5347986432","pt":1646211885819,"mc":[{"id":"1.195453616","rc":[{"atb":[[1.36,84.77]],"id":28755739}],"con":true,"img":false}]}
{"op":"mcm","clk":"5347986575","pt":1646211888198,"mc":[{"id":"1.195453616","rc":[{"atb":[[1.38,0]],"id":28755739}],"con":true,"img":false}]}
{"op":"mcm","clk":"5347986906","pt":1646211894112,"mc":[{"id":"1.195453616","rc":[{"atb":[[1.39,19.27]],"id":28755739}],"con":true,"img":false}]}
{"op":"mcm","clk":"5347986987","pt":1646211895602,"mc":[{"id":"1.195453616","rc":[{"atb":[[1.36,0]],"id":28755739}],"con":true,"img":false}]}
{"op":"mcm","clk":"5347986991","pt":1646211895705,"mc":[{"id":"1.195453616","rc":[{"atb":[[1.34,84.77]],"id":28755739}],"con":true,"img":false}]}
{"op":"mcm","clk":"5347987056","pt":1646211897144,"mc":[{"id":"1.195453616","rc":[{"atb":[[1.39,0]],"id":28755739}],"con":true,"img":false}]}
{"op":"mcm","clk":"5347987311","pt":1646211903129,"mc":[{"id":"1.195453616","rc":[{"atb":[[1.27,370.37],[1.3,332.71],[1.38,19.78]],"id":28755739},{"atl":[[2.32,0],[2.44,69.44]],"id":28755739},{"atb":[[1.72,0],[1.66,151.52]],"id":37456368},{"atb":[[2.54,64.94],[2.68,0]],"id":36036864},{"atb":[[2,50.69],[2.06,1.66]],"id":39980001}],"con":true,"img":false}]}
{"op":"mcm","clk":"5347987343","pt":1646211903646,"mc":[{"id":"1.195453616","rc":[{"atl":[[2.3,0]],"id":28755739}],"con":true,"img":false}]}
{"op":"mcm","clk":"5347987350","pt":1646211903748,"mc":[{"id":"1.195453616","rc":[{"atl":[[2.42,46.95]],"id":28755739}],"con":true,"img":false}]}
{"op":"mcm","clk":"5347987503","pt":1646211906535,"mc":[{"id":"1.195453616","rc":[{"atb":[[1.92,9.06]],"id":39980001}],"con":true,"img":false}]}
{"op":"mcm","clk":"5347987507","pt":1646211906641,"mc":[{"id":"1.195453616","rc":[{"atb":[[2.06,0]],"id":39980001}],"con":true,"img":false}]}
{"op":"mcm","clk":"5347987508","pt":1646211906737,"mc":[{"id":"1.195453616","rc":[{"atb":[[2.02,1.66]],"id":39980001}],"con":true,"img":false}]}
{"op":"mcm","clk":"5347987772","pt":1646211912154,"mc":[{"id":"1.195453616","rc":[{"atb":[[2.04,7.23]],"id":39980001}],"con":true,"img":false}]}
{"op":"mcm","clk":"5347987878","pt":1646211914579,"mc":[{"id":"1.195453616","rc":[{"atb":[[2.02,0]],"id":39980001}],"con":true,"img":false}]}
{"op":"mcm","clk":"5347987882","pt":1646211914683,"mc":[{"id":"1.195453616","rc":[{"atb":[[2.06,1.66]],"id":39980001}],"con":true,"img":false}]}
{"op":"mcm","clk":"5347988272","pt":1646211922152,"mc":[{"id":"1.195453616","rc":[{"atb":[[1.92,0]],"id":39980001}],"con":true,"img":false}]}
{"op":"mcm","clk":"5347988340","pt":1646211923692,"mc":[{"id":"1.195453616","rc":[{"atb":[[1.34,0]],"id":28755739}],"con":true,"img":false}]}
{"op":"mcm","clk":"5347988345","pt":1646211923745,"mc":[{"id":"1.195453616","rc":[{"atb":[[1.36,84.77]],"id":28755739}],"con":true,"img":false}]}
{"op":"mcm","clk":"5347988361","pt":1646211924057,"mc":[{"id":"1.195453616","rc":[{"atb":[[1.38,0]],"id":28755739}],"con":true,"img":false}]}
{"op":"mcm","clk":"5347988614","pt":1646211930158,"mc":[{"id":"1.195453616","rc":[{"atb":[[1.39,19.27]],"id":28755739}],"con":true,"img":false}]}
{"op":"mcm","clk":"5347988837","pt":1646211934865,"mc":[{"id":"1.195453616","rc":[{"atb":[[2.04,15.25]],"id":39980001}],"con":true,"img":false}]}
{"op":"mcm","clk":"5347989182","pt":1646211943683,"mc":[{"id":"1.195453616","rc":[{"atb":[[1.57,0]],"id":37456368}],"con":true,"img":false}]}
{"op":"mcm","clk":"5347989187","pt":1646211943784,"mc":[{"id":"1.195453616","rc":[{"atb":[[1.67,93.48]],"id":37456368}],"con":true,"img":false}]}
{"op":"mcm","clk":"5347989246","pt":1646211945690,"mc":[{"id":"1.195453616","rc":[{"atb":[[1.37,0]],"id":28755739}],"con":true,"img":false}]}
{"op":"mcm","clk":"5347989740","pt":1646211955709,"mc":[{"id":"1.195453616","rc":[{"spn":1.63,"spf":"NaN","id":28755739},{"atb":[[3.1,35.71]],"id":36036864}],"con":true,"img":false}]}
{"op":"mcm","clk":"5347989749","pt":1646211955812,"mc":[{"id":"1.195453616","rc":[{"atb":[[3.25,20.1]],"id":36036864}],"con":true,"img":false}]}
{"op":"mcm","clk":"5347989902","pt":1646211959208,"mc":[{"id":"1.195453616","rc":[{"atb":[[1.39,40.65]],"id":28755739}],"con":true,"img":false}]}
{"op":"mcm","clk":"5348009341","pt":1646212353824,"mc":[{"id":"1.195453616","rc":[{"atl":[[4.5,5.71],[4.6,0]],"id":26503913},{"spn":3.64,"spf":"NaN","id":26503913},{"atb":[[1.27,0],[1.31,799.28]],"id":28755739},{"atl":[[1.9,22.22],[1.87,0]],"id":28755739},{"spn":1.64,"spf":"NaN","id":28755739},{"atb":[[1.72,138.89],[1.66,0]],"id":37456368},{"atb":[[2.54,0],[2.64,60.98]],"id":36036864},{"atb":[[2,0],[2.06,16.91]],"id":39980001}],"con":true,"img":false}]}
{"op":"mcm","clk":"5348009552","pt":1646212355696,"mc":[{"id":"1.195453616","rc":[{"atb":[[1.67,0]],"id":37456368}],"con":true,"img":false}]}
{"op":"mcm","clk":"5348009555","pt":1646212355798,"mc":[{"id":"1.195453616","rc":[{"atb":[[1.57,93.48]],"id":37456368}],"con":true,"img":false}]}
{"op":"mcm","clk":"5348009673","pt":1646212358016,"mc":[{"id":"1.195453616","rc":[{"atb":[[2.04,8.01]],"id":39980001}],"con":true,"img":false}]}
{"op":"mcm","clk":"5348009844","pt":1646212361629,"mc":[{"id":"1.195453616","rc":[{"atl":[[1.89,0]],"id":28755739}],"con":true,"img":false}]}
{"op":"mcm","clk":"5348009850","pt":1646212361739,"mc":[{"id":"1.195453616","rc":[{"atl":[[1.91,43.59]],"id":28755739}],"con":true,"img":false}]}
{"op":"mcm","clk":"5348009960","pt":1646212363843,"mc":[{"id":"1.195453616","rc":[{"atl":[[4.7,13.51]],"id":26503913},{"atl":[[1.92,54.35]],"id":28755739}],"con":true,"img":false}]}
{"op":"mcm","clk":"5348010069","pt":1646212365810,"mc":[{"id":"1.195453616","rc":[{"atb":[[1.92,8.17]],"id":39980001}],"con":true,"img":false}]}
{"op":"mcm","clk":"5348010492","pt":1646212373826,"mc":[{"id":"1.195453616","rc":[{"atl":[[5.3,0],[4.9,19.23]],"id":26503913},{"atl":[[1.94,79.79]],"id":28755739}],"con":true,"img":false}]}
{"op":"mcm","clk":"5348010763","pt":1646212378969,"mc":[{"id":"1.195453616","rc":[{"atb":[[3.1,0],[3,0],[2.6,62.5],[3.3,0],[3.05,0],[3.2,0],[2.78,11.24]],"id":39784359},{"atb":[[2,50.69],[2.06,1.66]],"id":39980001},{"atl":[[4.4,22.75],[4.2,26.4]],"id":39980001}],"con":true,"img":false}]}
{"op":"mcm","clk":"5348010771","pt":1646212379072,"mc":[{"id":"1.195453616","rc":[{"atb":[[2.04,0]],"id":39980001}],"con":true,"img":false}]}
{"op":"mcm","clk":"5348010862","pt":1646212380838,"mc":[{"id":"1.195453616","rc":[{"atb":[[1.92,0]],"id":39980001}],"con":true,"img":false}]}
{"op":"mcm","clk":"5348010955","pt":1646212382951,"mc":[{"id":"1.195453616","rc":[{"atb":[[2.06,0]],"id":39980001}],"con":true,"img":false}]}
{"op":"mcm","clk":"5348010961","pt":1646212383053,"mc":[{"id":"1.195453616","rc":[{"atb":[[2,0],[2.02,1.66],[1.89,101.38]],"id":39980001}],"con":true,"img":false}]}
{"op":"mcm","clk":"5348011005","pt":1646212383778,"mc":[{"id":"1.195453616","rc":[{"atl":[[5.1,0]],"id":26503913},{"atl":[[1.96,130.21]],"id":28755739}],"con":true,"img":false}]}
{"op":"mcm","clk":"5348011008","pt":1646212383889,"mc":[{"id":"1.195453616","rc":[{"atl":[[5.1,30.49]],"id":26503913}],"con":true,"img":false}]}
{"op":"mcm","clk":"5348011273","pt":1646212388951,"mc":[{"id":"1.195453616","rc":[{"atb":[[2.74,28.74]],"id":39784359},{"atl":[[4.6,13.89]],"id":39980001}],"con":true,"img":false}]}
{"op":"mcm","clk":"5348011314","pt":1646212389876,"mc":[{"id":"1.195453616","rc":[{"atb":[[2.02,0],[1.93,8.08]],"id":39980001}],"con":true,"img":false}]}
{"op":"mcm","clk":"5348011467","pt":1646212392877,"mc":[{"id":"1.195453616","rc":[{"atb":[[3.3,0],[3.4,8.33]],"id":36036864}],"con":true,"img":false}]}
{"op":"mcm","clk":"5348011472","pt":1646212392980,"mc":[{"id":"1.195453616","rc":[{"atl":[[4.5,0],[4.6,5.56]],"id":26503913},{"atl":[[6.4,0],[6.6,3.57]],"id":36036864},{"atl":[[9.6,2.33],[9.8,0]],"id":39784359}],"con":true,"img":false}]}
{"op":"mcm","clk":"5348011639","pt":1646212396183,"mc":[{"id":"1.195453616","rc":[{"atb":[[1.89,0],[1.94,50.69]],"id":39980001}],"con":true,"img":false}]}
{"op":"mcm","clk":"5348011668","pt":1646212396852,"mc":[{"id":"1.195453616","rc":[{"atb":[[3.35,0]],"id":36036864}],"con":true,"img":false}]}
{"op":"mcm","clk":"5348011679","pt":1646212397058,"mc":[{"id":"1.195453616","rc":[{"atb":[[3.45,1.66]],"id":36036864}],"con":true,"img":false}]}
{"op":"mcm","clk":"5348011758","pt":1646212398961,"mc":[{"id":"1.195453616","rc":[{"atb":[[1.93,0]],"id":39980001},{"atl":[[4.8,19.74]],"id":39980001}],"con":true,"img":false}]}
{"op":"mcm","clk":"5348011763","pt":1646212399066,"mc":[{"id":"1.195453616","rc":[{"atb":[[1.89,101.38],[1.94,0]],"id":39980001}],"con":true,"img":false}]}
{"op":"mcm","clk":"5348011771","pt":1646212399170,"mc":[{"id":"1.195453616","rc":[{"atl":[[4.6,0],[4.7,5.41]],"id":26503913},{"atl":[[1.89,22.47],[1.9,0]],"id":28755739}],"con":true,"img":false}]}
{"op":"mcm","clk":"5348011995","pt":1646212402999,"mc":[{"id":"1.195453616","rc":[{"atb":[[3.3,21.74]],"id":36036864},{"atl":[[7,14.22]],"id":36036864},{"atb":[[2.7,44.12]],"id":39784359}],"con":true,"img":false}]}
{"op":"mcm","clk":"5348012024","pt":1646212403569,"mc":[{"id":"1.195453616","rc":[{"atb":[[1.93,8.96]],"id":39980001}],"con":true,"img":false}]}
{"op":"mcm","clk":"5348012029","pt":1646212403671,"mc":[{"id":"1.195453616","rc":[{"atb":[[1.89,0],[1.94,50.69]],"id":39980001}],"con":true,"img":false}]}
{"op":"mcm","clk":"5348012038","pt":1646212403878,"mc":[{"id":"1.195453616","rc":[{"atb":[[3,0]],"id":36036864},{"atl":[[7.2,0],[6.8,0],[7.6,0]],"id":36036864}],"con":true,"img":false}]}
{"op":"mcm","clk":"5348012088","pt":1646212404908,"mc":[{"id":"1.195453616","rc":[{"atb":[[3.25,16.76]],"id":36036864}],"con":true,"img":false}]}
{"op":"mcm","clk":"5348012119","pt":1646212405681,"mc":[{"id":"1.195453616","rc":[{"atb":[[1.36,0]],"id":28755739}],"con":true,"img":false}]}
{"op":"mcm","clk":"5348012125","pt":1646212405784,"mc":[{"id":"1.195453616","rc":[{"atb":[[1.34,84.77]],"id":28755739}],"con":true,"img":false}]}
{"op":"mcm","clk":"5348012248","pt":1646212407985,"mc":[{"id":"1.195453616","rc":[{"atb":[[1.39,21.37]],"id":28755739}],"con":true,"img":false}]}
{"op":"mcm","clk":"5348012304","pt":1646212409015,"mc":[{"id":"1.195453616","rc":[{"atl":[[5,31.25]],"id":39980001}],"con":true,"img":false}]}
{"op":"mcm","clk":"5348012316","pt":1646212409223,"mc":[{"id":"1.195453616","rc":[{"atl":[[4.9,12.82]],"id":26503913}],"con":true,"img":false}]}
{"op":"mcm","clk":"5348012409","pt":1646212410936,"mc":[{"id":"1.195453616","rc":[{"atb":[[3.4,11.46]],"id":36036864},{"atb":[[1.98,7.66]],"id":39980001}],"con":true,"img":false}]}
{"op":"mcm","clk":"5348012419","pt":1646212411082,"mc":[{"id":"1.195453616","rc":[{"atb":[[1.94,0],[1.99,8.96]],"id":39980001}],"con":true,"img":false}]}
{"op":"mcm","clk":"5348012438","pt":1646212411702,"mc":[{"id":"1.195453616","rc":[{"atl":[[7,8.33]],"id":36036864}],"con":true,"img":false}]}
{"op":"mcm","clk":"5348012442","pt":1646212411804,"mc":[{"id":"1.195453616","rc":[{"atl":[[7.8,5.89]],"id":36036864}],"con":true,"img":false}]}
{"op":"mcm","clk":"5348012494","pt":1646212412993,"mc":[{"id":"1.195453616","rc":[{"atb":[[3.2,34.09]],"id":36036864},{"atl":[[7.4,11.72]],"id":36036864},{"atb":[[2.66,75.3]],"id":39784359}],"con":true,"img":false}]}
{"op":"mcm","clk":"5348012503","pt":1646212413200,"mc":[{"id":"1.195453616","rc":[{"atl":[[4.6,5.56]],"id":26503913},{"atl":[[1.89,0],[2.44,0],[1.87,22.99],[2.34,74.63]],"id":28755739}],"con":true,"img":false}]}
{"op":"mcm","clk":"5348012544","pt":1646212414228,"mc":[{"id":"1.195453616","rc":[{"spn":3.69,"spf":"NaN","id":26503913},{"atb":[[1.38,19.78]],"id":28755739},{"spn":1.63,"spf":"NaN","id":28755739},{"spn":3.43,"spf":1.0,"id":36036864},{"atb":[[1.98,0]],"id":39980001},{"spn":2.87,"spf":"NaN","id":39980001}],"con":true,"img":false}]}
{"op":"mcm","clk":"5348012632","pt":1646212416192,"mc":[{"id":"1.195453616","rc":[{"atb":[[1.94,50.69]],"id":39980001}],"con":true,"img":false}]}
{"op":"mcm","clk":"5348012636","pt":1646212416296,"mc":[{"id":"1.195453616","rc":[{"atb":[[1.99,0]],"id":39980001}],"con":true,"img":false}]}
{"op":"mcm","clk":"5348012994","pt":1646212422905,"mc":[{"id":"1.195453616","rc":[{"atb":[[3.1,59.52]],"id":36036864},{"atl":[[7.8,24.27]],"id":36036864},{"atb":[[1.98,7.66]],"id":39980001}],"con":true,"img":false}]}
{"op":"mcm","clk":"5348013009","pt":1646212423217,"mc":[{"id":"1.195453616","rc":[{"atl":[[4.8,13.16]],"id":26503913},{"atl":[[1.89,56.18]],"id":28755739}],"con":true,"img":false}]}
{"op":"mcm","clk":"5348013030","pt":1646212423521,"mc":[{"id":"1.195453616","rc":[{"atl":[[5.1,0],[4.9,0],[4.7,0]],"id":26503913},{"atl":[[1.92,0],[1.96,0],[1.94,0]],"id":28755739}],"con":true,"img":false}]}
{"op":"mcm","clk":"5348013118","pt":1646212425635,"mc":[{"id":"1.195453616","rc":[{"atl":[[5,0]],"id":26503913},{"atb":[[1.34,0]],"id":28755739}],"con":true,"img":false}]}
{"op":"mcm","clk":"5348013120","pt":1646212425739,"mc":[{"id":"1.195453616","rc":[{"atl":[[6.2,10.89]],"id":26503913},{"atb":[[1.36,84.77]],"id":28755739}],"con":true,"img":false}]}
{"op":"mcm","clk":"5348013217","pt":1646212427643,"mc":[{"id":"1.195453616","rc":[{"atb":[[3.25,0]],"id":36036864}],"con":true,"img":false}]}
{"op":"mcm","clk":"5348013224","pt":1646212427752,"mc":[{"id":"1.195453616","rc":[{"atb":[[3.35,16.76]],"id":36036864}],"con":true,"img":false}]}
{"op":"mcm","clk":"5348013284","pt":1646212428931,"mc":[{"id":"1.195453616","rc":[{"atb":[[3.15,0]],"id":36036864},{"atb":[[1.93,0]],"id":39980001}],"con":true,"img":false}]}
{"op":"mcm","clk":"5348013290","pt":1646212429035,"mc":[{"id":"1.195453616","rc":[{"atb":[[1.38,0]],"id":28755739},{"atb":[[1.99,8.96],[1.94,0]],"id":39980001}],"con":true,"img":false}]}
{"op":"mcm","clk":"5348013448","pt":1646212431921,"mc":[{"id":"1.195453616","rc":[{"atb":[[1.98,0]],"id":39980001}],"con":true,"img":false}]}
{"op":"mcm","clk":"5348013521","pt":1646212433058,"mc":[{"id":"1.195453616","rc":[{"atb":[[2.5,0],[2.6,0],[2.7,0]],"id":26503913},{"atl":[[8.6,0],[11.5,0],[6.6,0]],"id":26503913},{"atb":[[1.8,62.5],[1.85,0],[1.75,0]],"id":37456368},{"atl":[[4.5,0],[5.5,0],[3.75,0]],"id":37456368},{"atb":[[2.82,0],[2.92,0],[3.05,0]],"id":36036864},{"atl":[[10.5,0],[8.2,0],[15.5,0]],"id":36036864}],"con":true,"img":false}]}
{"op":"mcm","clk":"5348013541","pt":1646212433266,"mc":[{"id":"1.195453616","rc":[{"atl":[[5,18.75]],"id":26503913},{"atl":[[1.91,126.01]],"id":28755739}],"con":true,"img":false}]}
{"op":"mcm","clk":"5348013574","pt":1646212433631,"mc":[{"id":"1.195453616","rc":[{"atb":[[2.62,0]],"id":26503913},{"atl":[[3.7,0]],"id":37456368},{"atb":[[2.94,0]],"id":36036864}],"con":true,"img":false}]}
{"op":"mcm","clk":"5348013580","pt":1646212433736,"mc":[{"id":"1.195453616","rc":[{"atb":[[2.42,26.91]],"id":26503913},{"atl":[[4,22.5]],"id":37456368},{"atb":[[2.66,33.24]],"id":36036864}],"con":true,"img":false}]}
{"op":"mcm","clk":"5348013598","pt":1646212434144,"mc":[{"id":"1.195453616","rc":[{"atb":[[1.99,0],[1.89,66.7]],"id":39980001}],"con":true,"img":false}]}
{"op":"mcm","clk":"5348013652","pt":1646212434928,"mc":[{"id":"1.195453616","rc":[{"atb":[[1.39,40.65]],"id":28755739}],"con":true,"img":false}]}
{"op":"mcm","clk":"5348013655","pt":1646212435028,"mc":[{"id":"1.195453616","rc":[{"atb":[[2.76,4.73]],"id":26503913},{"atb":[[1.89,9.36]],"id":37456368}],"con":true,"img":false}]}
{"op":"mcm","clk":"5348013784","pt":1646212437775,"mc":[{"id":"1.195453616","rc":[{"atl":[[7.8,18.38]],"id":36036864}],"con":true,"img":false}]}
{"op":"mcm","clk":"5348013787","pt":1646212437852,"mc":[{"id":"1.195453616","rc":[{"atl":[[7.2,5.89]],"id":36036864}],"con":true,"img":false}]}
{"op":"mcm","clk":"5348013944","pt":1646212440831,"mc":[{"id":"1.195453616","rc":[{"atb":[[3.25,3.7]],"id":36036864}],"con":true,"img":false}]}
{"op":"mcm","clk":"5348013949","pt":1646212440935,"mc":[{"id":"1.195453616","rc":[{"atb":[[1.85,8.84]],"id":37456368},{"atb":[[1.93,8.08]],"id":39980001}],"con":true,"img":false}]}
{"op":"mcm","clk":"5348013976","pt":1646212441658,"mc":[{"id":"1.195453616","rc":[{"atb":[[1.89,0],[1.94,50.69]],"id":39980001}],"con":true,"img":false}]}
{"op":"mcm","clk":"5348014046","pt":1646212443198,"mc":[{"id":"1.195453616","rc":[{"atb":[[2.5,66.54],[2.6,62.38],[2.7,58.71]],"id":26503913},{"atl":[[8.6,9.55],[11.5,6.91],[6.6,6.47]],"id":26503913},{"atb":[[1.8,187.26],[1.85,126.27],[1.75,133.08]],"id":37456368},{"atl":[[4.5,20.74],[5.5,16.13],[3.75,13.19]],"id":37456368},{"atb":[[3.55,39.14],[3.3,65.13],[3.05,48.68]],"id":36036864},{"atl":[[19.5,3.92],[9.8,4.12],[14.5,5.37]],"id":36036864}],"con":true,"img":false}]}
{"op":"mcm","clk":"5348014051","pt":1646212443256,"mc":[{"id":"1.195453616","rc":[{"atl":[[5.2,29.76]],"id":26503913},{"atl":[[1.93,134.41]],"id":28755739}],"con":true,"img":false}]}
{"op":"mcm","clk":"5348014063","pt":1646212443464,"mc":[{"id":"1.195453616","rc":[{"atl":[[1.91,82.42]],"id":28755739}],"con":true,"img":false}]}
{"op":"mcm","clk":"5348014067","pt":1646212443563,"mc":[{"id":"1.195453616","rc":[{"atl":[[1.88,43.59]],"id":28755739}],"con":true,"img":false}]}
{"op":"mcm","clk":"5348014087","pt":1646212444073,"mc":[{"id":"1.195453616","rc":[{"atb":[[1.85,117.42]],"id":37456368},{"atb":[[3.4,8.33]],"id":36036864},{"atb":[[1.93,0]],"id":39980001}],"con":true,"img":false}]}
{"op":"mcm","clk":"5348014198","pt":1646212445978,"mc":[{"id":"1.195453616","rc":[{"atb":[[3.45,0]],"id":36036864}],"con":true,"img":false}]}
{"op":"mcm","clk":"5348014212","pt":1646212446167,"mc":[{"id":"1.195453616","rc":[{"atb":[[3.6,1.66]],"id":36036864}],"con":true,"img":false}]}
{"op":"mcm","clk":"5348014247","pt":1646212446758,"mc":[{"id":"1.195453616","rc":[{"atb":[[1.89,101.38],[1.94,0]],"id":39980001}],"con":true,"img":false}]}
{"op":"mcm","clk":"5348014343","pt":1646212448498,"mc":[{"id":"1.195453616","rc":[{"atl":[[1.89,22.47],[1.87,0]],"id":28755739},{"atl":[[16.5,0],[14,7.69]],"id":39784359}],"con":true,"img":false}]}
{"op":"mcm","clk":"5348014344","pt":1646212448558,"mc":[{"id":"1.195453616","rc":[{"atl":[[6.6,24.33],[7.8,0]],"id":26503913},{"atb":[[1.31,476.7],[1.38,84.78]],"id":28755739},{"atl":[[2.12,89.29],[2.34,0]],"id":28755739},{"atb":[[1.72,0],[1.59,169.49]],"id":37456368},{"atl":[[2.86,0],[4.1,32.26],[3.25,8.89],[3.65,0]],"id":37456368},{"atb":[[3,50],[2.64,0]],"id":36036864},{"atl":[[8,0],[7.2,17.79]],"id":36036864},{"atl":[[4.5,49.31],[4.2,0]],"id":39980001}],"con":true,"img":false}]}
{"op":"mcm","clk":"5348014414","pt":1646212449681,"mc":[{"id":"1.195453616","rc":[{"atl":[[2.9,0]],"id":37456368}],"con":true,"img":false}]}
{"op":"mcm","clk":"5348014429","pt":1646212450045,"mc":[{"id":"1.195453616","rc":[{"atb":[[2.76,9]],"id":26503913},{"atb":[[1.39,21.37]],"id":28755739},{"atb":[[1.89,17.82]],"id":37456368},{"atb":[[3.65,2.83]],"id":36036864}],"con":true,"img":false}]}
{"op":"mcm","clk":"5348014440","pt":1646212450250,"mc":[{"id":"1.195453616","rc":[{"atl":[[2.94,0]],"id":37456368}],"con":true,"img":false}]}
{"op":"mcm","clk":"5348014445","pt":1646212450458,"mc":[{"id":"1.195453616","rc":[{"atl":[[2.98,0]],"id":37456368}],"con":true,"img":false}]}
{"op":"mcm","clk":"5348014503","pt":1646212451752,"mc":[{"id":"1.195453616","rc":[{"atb":[[1.36,0]],"id":28755739},{"atl":[[2.92,0]],"id":37456368}],"con":true,"img":false}]}
{"op":"mcm","clk":"5348014509","pt":1646212451853,"mc":[{"id":"1.195453616","rc":[{"atb":[[1.34,84.77]],"id":28755739},{"atl":[[3.5,22.7]],"id":37456368}],"con":true,"img":false}]}
{"op":"mcm","clk":"5348014560","pt":1646212452975,"mc":[{"id":"1.195453616","rc":[{"atb":[[3.6,0]],"id":36036864}],"con":true,"img":false}]}
{"op":"mcm","clk":"5348014564","pt":1646212453078,"mc":[{"id":"1.195453616","rc":[{"atb":[[3.7,1.66]],"id":36036864}],"con":true,"img":false}]}
{"op":"mcm","clk":"5348014667","pt":1646212455078,"mc":[{"id":"1.195453616","rc":[{"atb":[[1.36,106.15],[1.38,0]],"id":28755739}],"con":true,"img":false}]}
{"op":"mcm","clk":"5348014682","pt":1646212455487,"mc":[{"id":"1.195453616","rc":[{"atb":[[1.88,0]],"id":39980001}],"con":true,"img":false}]}
{"op":"mcm","clk":"5348014688","pt":1646212455591,"mc":[{"id":"1.195453616","rc":[{"atb":[[1.9,50.69]],"id":39980001}],"con":true,"img":false}]}
{"op":"mcm","clk":"5348014692","pt":1646212455694,"mc":[{"id":"1.195453616","rc":[{"atb":[[1.89,0],[1.87,114.94]],"id":39980001}],"con":true,"img":false}]}
{"op":"mcm","clk":"5348014821","pt":1646212457659,"mc":[{"id":"1.195453616","rc":[{"atl":[[1.88,0]],"id":28755739}],"con":true,"img":false}]}
{"op":"mcm","clk":"5348014825","pt":1646212457762,"mc":[{"id":"1.195453616","rc":[{"atl":[[1.9,43.59]],"id":28755739}],"con":true,"img":false}]}
{"op":"mcm","clk":"5348014862","pt":1646212458478,"mc":[{"id":"1.195453616","rc":[{"atl":[[1.91,54.95]],"id":28755739},{"atl":[[3.35,21.28]],"id":37456368}],"con":true,"img":false}]}
{"op":"mcm","clk":"5348014919","pt":1646212459769,"mc":[{"id":"1.195453616","rc":[{"atl":[[6.2,0]],"id":26503913}],"con":true,"img":false}]}
{"op":"mcm","clk":"5348014925","pt":1646212459878,"mc":[{"id":"1.195453616","rc":[{"atl":[[4.9,10.89]],"id":26503913}],"con":true,"img":false}]}
{"op":"mcm","clk":"5348014973","pt":1646212460998,"mc":[{"id":"1.195453616","rc":[{"atl":[[12.5,19.57],[14,0]],"id":39784359}],"con":true,"img":false}]}
{"op":"mcm","clk":"5348014978","pt":1646212461097,"mc":[{"id":"1.195453616","rc":[{"atb":[[1.73,136.99]],"id":37456368},{"atl":[[4.1,0],[3.7,37.04]],"id":37456368}],"con":true,"img":false}]}
{"op":"mcm","clk":"5348014981","pt":1646212461201,"mc":[{"id":"1.195453616","rc":[{"atb":[[1.59,0]],"id":37456368}],"con":true,"img":false}]}
{"op":"mcm","clk":"5348015008","pt":1646212462079,"mc":[{"id":"1.195453616","rc":[{"atb":[[1.39,40.65]],"id":28755739},{"atb":[[1.94,8]],"id":39980001}],"con":true,"img":false}]}
{"op":"mcm","clk":"5348015080","pt":1646212463699,"mc":[{"id":"1.195453616","rc":[{"atb":[[1.9,0]],"id":39980001}],"con":true,"img":false}]}
{"op":"mcm","clk":"5348015084","pt":1646212463774,"mc":[{"id":"1.195453616","rc":[{"atb":[[1.88,50.69]],"id":39980001}],"con":true,"img":false}]}
{"op":"mcm","clk":"5348015130","pt":1646212465106,"mc":[{"id":"1.195453616","rc":[{"atb":[[1.94,0]],"id":39980001}],"con":true,"img":false}]}
{"op":"mcm","clk":"5348015158","pt":1646212465676,"mc":[{"id":"1.195453616","rc":[{"atb":[[3.35,0]],"id":36036864}],"con":true,"img":false}]}
{"op":"mcm","clk":"5348015162","pt":1646212465781,"mc":[{"id":"1.195453616","rc":[{"atb":[[3.6,16.76]],"id":36036864}],"con":true,"img":false}]}
{"op":"mcm","clk":"5348015266","pt":1646212468099,"mc":[{"id":"1.195453616","rc":[{"atb":[[1.89,66.7],[1.87,0]],"id":39980001}],"con":true,"img":false}]}
{"op":"mcm","clk":"5348015286","pt":1646212468503,"mc":[{"id":"1.195453616","rc":[{"atl":[[1.93,80.65]],"id":28755739},{"atl":[[3.45,30.61]],"id":37456368}],"con":true,"img":false}]}
{"op":"mcm","clk":"5348015402","pt":1646212471122,"mc":[{"id":"1.195453616","rc":[{"atb":[[3.25,0]],"id":36036864}],"con":true,"img":false}]}
{"op":"mcm","clk":"5348015420","pt":1646212471394,"mc":[{"id":"1.195453616","rc":[{"atb":[[2.42,0]],"id":26503913}],"con":true,"img":false}]}
{"op":"mcm","clk":"5348015426","pt":1646212471490,"mc":[{"id":"1.195453616","rc":[{"atb":[[2.62,26.91]],"id":26503913}],"con":true,"img":false}]}
{"op":"mcm","clk":"5348015645","pt":1646212475621,"mc":[{"id":"1.195453616","rc":[{"atb":[[1.34,0]],"id":28755739},{"spn":1.64,"spf":"NaN","id":28755739},{"spn":2.57,"spf":"NaN","id":37456368},{"spn":3.68,"spf":1.0,"id":36036864},{"atl":[[12,0]],"id":39784359},{"spn":2.82,"spf":"NaN","id":39980001}],"con":true,"img":false}]}
{"op":"mcm","clk":"5348015650","pt":1646212475722,"mc":[{"id":"1.195453616","rc":[{"atb":[[1.37,84.77]],"id":28755739},{"atl":[[11,3.96]],"id":39784359}],"con":true,"img":false}]}
{"op":"mcm","clk":"5348015718","pt":1646212477214,"mc":[{"id":"1.195453616","rc":[{"atb":[[1.39,21.37]],"id":28755739},{"atb":[[1.93,8.08]],"id":39980001}],"con":true,"img":false}]}
{"op":"mcm","clk":"5348015736","pt":1646212477423,"mc":[{"id":"1.195453616","rc":[{"atb":[[2.86,53.76],[3,0]],"id":36036864},{"atl":[[12,9.09],[12.5,10.87]],"id":39784359}],"con":true,"img":false}]}
{"op":"mcm","clk":"5348015801","pt":1646212478502,"mc":[{"id":"1.195453616","rc":[{"atl":[[1.95,131.58]],"id":28755739},{"atl":[[3.55,49.02]],"id":37456368}],"con":true,"img":false}]}
{"op":"mcm","clk":"5348015905","pt":1646212480304,"mc":[{"id":"1.195453616","rc":[{"atb":[[1.89,0],[1.94,50.69]],"id":39980001}],"con":true,"img":false}]}
{"op":"mcm","clk":"5348016080","pt":1646212483240,"mc":[{"id":"1.195453616","rc":[{"atb":[[1.4,18.79]],"id":28755739},{"atb":[[1.93,0]],"id":39980001}],"con":true,"img":false}]}
{"op":"mcm","clk":"5348016138","pt":1646212484318,"mc":[{"id":"1.195453616","rc":[{"atb":[[3.65,5.97]],"id":36036864}],"con":true,"img":false}]}
{"op":"mcm","clk":"5348016143","pt":1646212484421,"mc":[{"id":"1.195453616","rc":[{"atb":[[1.39,0]],"id":28755739}],"con":true,"img":false}]}
{"op":"mcm","clk":"5348016185","pt":1646212485398,"mc":[{"id":"1.195453616","rc":[{"atb":[[1.89,101.38],[1.94,0]],"id":39980001}],"con":true,"img":false}]}
{"op":"mcm","clk":"5348016193","pt":1646212485604,"mc":[{"id":"1.195453616","rc":[{"atb":[[2.66,0]],"id":36036864}],"con":true,"img":false}]}
{"op":"mcm","clk":"5348016198","pt":1646212485708,"mc":[{"id":"1.195453616","rc":[{"atb":[[2.88,33.24]],"id":36036864}],"con":true,"img":false}]}
{"op":"mcm","clk":"5348016384","pt":1646212489628,"mc":[{"id":"1.195453616","rc":[{"atl":[[7.2,0],[6.4,11.44]],"id":26503913}],"con":true,"img":false}]}
{"op":"mcm","clk":"5348016389","pt":1646212489742,"mc":[{"id":"1.195453616","rc":[{"atb":[[1.88,0]],"id":39980001}],"con":true,"img":false}]}
{"op":"mcm","clk":"5348016393","pt":1646212489845,"mc":[{"id":"1.195453616","rc":[{"atb":[[1.9,50.69]],"id":39980001}],"con":true,"img":false}]}
{"op":"mcm","clk":"5348016529","pt":1646212492486,"mc":[{"id":"1.195453616","rc":[{"atb":[[1.41,13.15]],"id":28755739},{"atb":[[1.83,24.94]],"id":37456368},{"atb":[[1.9,90.17]],"id":39980001}],"con":true,"img":false}]}
{"op":"mcm","clk":"5348016813","pt":1646212497528,"mc":[{"id":"1.195453616","rc":[{"atb":[[1.89,0],[1.91,90.18]],"id":39980001}],"con":true,"img":false}]}
{"op":"mcm","clk":"5348016816","pt":1646212497632,"mc":[{"id":"1.195453616","rc":[{"atb":[[2.62,0]],"id":26503913}],"con":true,"img":false}]}
{"op":"mcm","clk":"5348016822","pt":1646212497734,"mc":[{"id":"1.195453616","rc":[{"atb":[[2.72,26.91]],"id":26503913}],"con":true,"img":false}]}
{"op":"mcm","clk":"5348016850","pt":1646212498249,"mc":[{"id":"1.195453616","rc":[{"atb":[[2.76,4.73]],"id":26503913}],"con":true,"img":false}]}
{"op":"mcm","clk":"5348016967","pt":1646212500668,"mc":[{"id":"1.195453616","rc":[{"atb":[[1.9,50.69]],"id":39980001}],"con":true,"img":false}]}
{"op":"mcm","clk":"5348017027","pt":1646212501655,"mc":[{"id":"1.195453616","rc":[{"atl":[[4,0],[3.5,0]],"id":37456368}],"con":true,"img":false}]}
{"op":"mcm","clk":"5348017031","pt":1646212501760,"mc":[{"id":"1.195453616","rc":[{"atl":[[3.4,22.7],[3.65,22.5]],"id":37456368}],"con":true,"img":false}]}
{"op":"mcm","clk":"5348017038","pt":1646212501864,"mc":[{"id":"1.195453616","rc":[{"atb":[[1.44,2.16]],"id":28755739},{"atb":[[1.92,2.16]],"id":37456368},{"atb":[[1.94,2.16]],"id":39980001}],"con":true,"img":false}]}
{"op":"mcm","clk":"5348017130","pt":1646212503254,"mc":[{"id":"1.195453616","rc":[{"atb":[[1.87,40.84]],"id":39980001}],"con":true,"img":false}]}
{"op":"mcm","clk":"5348017170","pt":1646212504130,"mc":[{"id":"1.195453616","rc":[{"atb":[[2.78,5.89]],"id":26503913},{"atb":[[1.95,7.91]],"id":39980001}],"con":true,"img":false}]}
{"op":"mcm","clk":"5348017252","pt":1646212505474,"mc":[{"id":"1.195453616","rc":[{"atl":[[5.8,20.83],[6.6,6.47]],"id":26503913},{"atl":[[1.89,0],[1.86,23.26]],"id":28755739},{"atb":[[2.86,0],[3.05,97.46]],"id":36036864}],"con":true,"img":false}]}
{"op":"mcm","clk":"5348017265","pt":1646212505776,"mc":[{"id":"1.195453616","rc":[{"atl":[[6.4,0]],"id":26503913}],"con":true,"img":false}]}
{"op":"mcm","clk":"5348017270","pt":1646212505828,"mc":[{"id":"1.195453616","rc":[{"atl":[[7.2,11.44]],"id":26503913}],"con":true,"img":false}]}
{"op":"mcm","clk":"5348017369","pt":1646212507533,"mc":[{"id":"1.195453616","rc":[{"atb":[[1.87,0]],"id":39980001}],"con":true,"img":false}]}
{"op":"mcm","clk":"5348017387","pt":1646212507951,"mc":[{"id":"1.195453616","rc":[{"atb":[[1.4,39.63]],"id":28755739}],"con":true,"img":false}]}
{"op":"mcm","clk":"5348017483","pt":1646212509556,"mc":[{"id":"1.195453616","rc":[{"atb":[[1.96,7.92],[1.91,0]],"id":39980001}],"con":true,"img":false}]}
{"op":"mcm","clk":"5348017492","pt":1646212509659,"mc":[{"id":"1.195453616","rc":[{"atb":[[1.41,0]],"id":28755739}],"con":true,"img":false}]}
{"op":"mcm","clk":"5348017530","pt":1646212510277,"mc":[{"id":"1.195453616","rc":[{"atb":[[1.95,0]],"id":39980001}],"con":true,"img":false}]}
{"op":"mcm","clk":"5348017609","pt":1646212511683,"mc":[{"id":"1.195453616","rc":[{"atb":[[1.81,0]],"id":37456368}],"con":true,"img":false}]}
{"op":"mcm","clk":"5348017617","pt":1646212511784,"mc":[{"id":"1.195453616","rc":[{"atb":[[1.83,78.77]],"id":37456368}],"con":true,"img":false}]}
{"op":"mcm","clk":"5348017649","pt":1646212512342,"mc":[{"id":"1.195453616","rc":[{"atb":[[1.38,16.85]],"id":28755739},{"atb":[[1.91,10.29]],"id":39980001}],"con":true,"img":false}]}
{"op":"mcm","clk":"5348017700","pt":1646212513675,"mc":[{"id":"1.195453616","rc":[{"atb":[[1.9,0]],"id":39980001},{"atl":[[4.1,0]],"id":39980001}],"con":true,"img":false}]}
{"op":"mcm","clk":"5348017704","pt":1646212513777,"mc":[{"id":"1.195453616","rc":[{"atb":[[1.86,117.39]],"id":39980001},{"atl":[[4.4,35.57]],"id":39980001}],"con":true,"img":false}]}
{"op":"mcm","clk":"5348017758","pt":1646212514659,"mc":[{"id":"1.195453616","rc":[{"atb":[[1.96,0],[1.94,18]],"id":39980001}],"con":true,"img":false}]}
{"op":"mcm","clk":"5348017760","pt":1646212514758,"mc":[{"id":"1.195453616","rc":[{"atb":[[1.92,108.7],[1.94,2.16]],"id":39980001}],"con":true,"img":false}]}
{"op":"mcm","clk":"5348017777","pt":1646212515376,"mc":[{"id":"1.195453616","rc":[{"atl":[[1.88,56.82]],"id":28755739}],"con":true,"img":false}]}
{"op":"mcm","clk":"5348017791","pt":1646212515690,"mc":[{"id":"1.195453616","rc":[{"atl":[[1.91,0],[1.93,0],[1.95,0]],"id":28755739}],"con":true,"img":false}]}
{"op":"mcm","clk":"5348017857","pt":1646212517077,"mc":[{"id":"1.195453616","rc":[{"atb":[[1.91,0]],"id":39980001}],"con":true,"img":false}]}
{"op":"mcm","clk":"5348018147","pt":1646212521965,"mc":[{"id":"1.195453616","rc":[{"atb":[[1.87,40.84]],"id":39980001}],"con":true,"img":false}]}
{"op":"mcm","clk":"5348018171","pt":1646212522473,"mc":[{"id":"1.195453616","rc":[{"atb":[[1.96,7.83]],"id":39980001}],"con":true,"img":false}]}
{"op":"mcm","clk":"5348018241","pt":1646212523658,"mc":[{"id":"1.195453616","rc":[{"atl":[[1.9,0]],"id":28755739}],"con":true,"img":false}]}
{"op":"mcm","clk":"5348018247","pt":1646212523759,"mc":[{"id":"1.195453616","rc":[{"atl":[[2.1,43.59]],"id":28755739}],"con":true,"img":false}]}
{"op":"mcm","clk":"5348018348","pt":1646212525466,"mc":[{"id":"1.195453616","rc":[{"atl":[[1.9,83.33]],"id":28755739}],"con":true,"img":false}]}
{"op":"mcm","clk":"5348018393","pt":1646212526386,"mc":[{"id":"1.195453616","rc":[{"atb":[[1.87,0]],"id":39980001}],"con":true,"img":false}]}
{"op":"mcm","clk":"5348018408","pt":1646212526600,"mc":[{"id":"1.195453616","rc":[{"atb":[[1.92,0],[1.97,7.83]],"id":39980001}],"con":true,"img":false}]}
{"op":"mcm","clk":"5348018525","pt":1646212528765,"mc":[{"id":"1.195453616","rc":[{"atb":[[1.96,0]],"id":39980001}],"con":true,"img":false}]}
{"op":"mcm","clk":"5348018578","pt":1646212529804,"mc":[{"id":"1.195453616","rc":[{"atb":[[1.89,2.16],[1.94,0]],"id":39980001}],"con":true,"img":false}]}
{"op":"mcm","clk":"5348018630","pt":1646212530793,"mc":[{"id":"1.195453616","rc":[{"atb":[[1.87,14.09]],"id":39980001}],"con":true,"img":false}]}
{"op":"mcm","clk":"5348018668","pt":1646212531669,"mc":[{"id":"1.195453616","rc":[{"atb":[[1.89,17.82],[1.97,0]],"id":39980001}],"con":true,"img":false}]}
{"op":"mcm","clk":"5348018787","pt":1646212534404,"mc":[{"id":"1.195453616","rc":[{"atb":[[1.9,8.35]],"id":39980001}],"con":true,"img":false}]}
{"op":"mcm","clk":"5348018835","pt":1646212535389,"mc":[{"id":"1.195453616","rc":[{"atl":[[1.92,135.87]],"id":28755739}],"con":true,"img":false}]}
{"op":"mcm","clk":"5348018929","pt":1646212537292,"mc":[{"id":"1.195453616","rc":[{"spn":1.65,"spf":"NaN","id":28755739},{"spn":2.58,"spf":"NaN","id":37456368},{"atb":[[1.87,0]],"id":39980001},{"spn":2.82,"spf":"NaN","id":39980001}],"con":true,"img":false}]}
{"op":"mcm","clk":"5348019143","pt":1646212541721,"mc":[{"id":"1.195453616","rc":[{"atl":[[11,0]],"id":39784359}],"con":true,"img":false}]}
{"op":"mcm","clk":"5348019146","pt":1646212541777,"mc":[{"id":"1.195453616","rc":[{"atl":[[11.5,11.1]],"id":39784359}],"con":true,"img":false}]}
{"op":"mcm","clk":"5348019201","pt":1646212542913,"mc":[{"id":"1.195453616","rc":[{"atb":[[1.9,17.61]],"id":39980001}],"con":true,"img":false}]}
{"op":"mcm","clk":"5348019226","pt":1646212543322,"mc":[{"id":"1.195453616","rc":[{"atb":[[1.89,2.16],[1.91,17.83]],"id":39980001}],"con":true,"img":false}]}
{"op":"mcm","clk":"5348019233","pt":1646212543485,"mc":[{"id":"1.195453616","rc":[{"atb":[[1.94,2.16]],"id":39980001}],"con":true,"img":false}]}
{"op":"mcm","clk":"5348019236","pt":1646212543585,"mc":[{"id":"1.195453616","rc":[{"atb":[[1.89,0]],"id":39980001}],"con":true,"img":false}]}
{"op":"mcm","clk":"5348019252","pt":1646212544004,"mc":[{"id":"1.195453616","rc":[{"atb":[[1.87,9.18]],"id":39980001}],"con":true,"img":false}]}
{"op":"mcm","clk":"5348019319","pt":1646212545706,"mc":[{"id":"1.195453616","rc":[{"atl":[[2.1,0]],"id":28755739}],"con":true,"img":false}]}
{"op":"mcm","clk":"5348019328","pt":1646212545804,"mc":[{"id":"1.195453616","rc":[{"atl":[[1.89,43.59]],"id":28755739}],"con":true,"img":false}]}
{"op":"mcm","clk":"5348019713","pt":1646212554814,"mc":[{"id":"1.195453616","rc":[{"atb":[[1.91,0],[1.94,19.77]],"id":39980001}],"con":true,"img":false}]}
{"op":"mcm","clk":"5348019915","pt":1646212558522,"mc":[{"id":"1.195453616","rc":[{"atb":[[1.87,0]],"id":39980001}],"con":true,"img":false}]}
{"op":"mcm","clk":"5348020178","pt":1646212563739,"mc":[{"id":"1.195453616","rc":[{"atb":[[1.87,29.66]],"id":39980001}],"con":true,"img":false}]}
{"op":"mcm","clk":"5348020351","pt":1646212567656,"mc":[{"id":"1.195453616","rc":[{"atl":[[4.2,17.87],[3.65,0]],"id":37456368}],"con":true,"img":false}]}
{"op":"mcm","clk":"5348023321","pt":1646212620141,"mc":[{"id":"1.195453616","rc":[{"atl":[[4.8,5.26],[4.6,0]],"id":26503913},{"spn":3.79,"spf":"NaN","id":26503913},{"atl":[[1.92,0],[1.88,0],[1.9,0],[1.86,0],[1.93,21.51]],"id":28755739},{"spn":1.66,"spf":"NaN","id":28755739},{"atb":[[1.82,0],[1.8,124.76],[1.79,25.32]],"id":37456368},{"atb":[[3.4,0],[3.3,52.09]],"id":36036864},{"atb":[[1.78,0],[1.75,159.75],[1.76,0]],"id":39980001},{"spn":2.84,"spf":"NaN","id":39980001}],"con":true,"img":false}]}
{"op":"mcm","clk":"5348023799","pt":1646212627640,"mc":[{"id":"1.195453616","rc":[{"atl":[[1.89,0]],"id":28755739},{"atb":[[1.83,24.94]],"id":37456368}],"con":true,"img":false}]}
{"op":"mcm","clk":"5348023804","pt":1646212627743,"mc":[{"id":"1.195453616","rc":[{"atl":[[2.1,43.59]],"id":28755739},{"atb":[[1.81,53.82]],"id":37456368}],"con":true,"img":false}]}
{"op":"mcm","clk":"5348023809","pt":1646212627845,"mc":[{"id":"1.195453616","rc":[{"atl":[[2.4,71.43],[2.12,0]],"id":28755739}],"con":true,"img":false}]}
{"op":"mcm","clk":"5348023919","pt":1646212629601,"mc":[{"id":"1.195453616","rc":[{"atl":[[2.1,0]],"id":28755739}],"con":true,"img":false}]}
{"op":"mcm","clk":"5348023925","pt":1646212629704,"mc":[{"id":"1.195453616","rc":[{"atl":[[2.22,43.59]],"id":28755739}],"con":true,"img":false}]}
{"op":"mcm","clk":"5348023954","pt":1646212630119,"mc":[{"id":"1.195453616","rc":[{"atl":[[5,12.5]],"id":26503913},{"atl":[[1.95,52.63]],"id":28755739},{"atb":[[1.77,64.94]],"id":37456368},{"atb":[[3.2,22.73]],"id":36036864},{"atb":[[1.73,68.49]],"id":39980001}],"con":true,"img":false}]}
{"op":"mcm","clk":"5348024055","pt":1646212631615,"mc":[{"id":"1.195453616","rc":[{"atb":[[2.88,0]],"id":36036864}],"con":true,"img":false}]}
{"op":"mcm","clk":"5348024060","pt":1646212631714,"mc":[{"id":"1.195453616","rc":[{"atb":[[2.68,33.24]],"id":36036864}],"con":true,"img":false}]}
{"op":"mcm","clk":"5348024445","pt":1646212637760,"mc":[{"id":"1.195453616","rc":[{"atl":[[4.9,0]],"id":26503913}],"con":true,"img":false}]}
{"op":"mcm","clk":"5348024451","pt":1646212637857,"mc":[{"id":"1.195453616","rc":[{"atl":[[5.1,10.89]],"id":26503913}],"con":true,"img":false}]}
{"op":"mcm","clk":"5348024488","pt":1646212638529,"mc":[{"id":"1.195453616","rc":[{"atl":[[2.4,0],[2.2,74.14]],"id":28755739}],"con":true,"img":false}]}
{"op":"mcm","clk":"5348024576","pt":1646212640133,"mc":[{"id":"1.195453616","rc":[{"atl":[[5.2,17.86]],"id":26503913},{"atl":[[1.97,77.32]],"id":28755739},{"atb":[[1.75,233.08]],"id":37456368},{"atb":[[3.1,35.71]],"id":36036864},{"atb":[[1.71,105.63]],"id":39980001}],"con":true,"img":false}]}
{"op":"mcm","clk":"5348024659","pt":1646212641631,"mc":[{"id":"1.195453616","rc":[{"atl":[[11.5,7.14]],"id":39784359}],"con":true,"img":false}]}
{"op":"mcm","clk":"5348024667","pt":1646212641744,"mc":[{"id":"1.195453616","rc":[{"atl":[[11,3.96]],"id":39784359}],"con":true,"img":false}]}
{"op":"mcm","clk":"5348024718","pt":1646212642567,"mc":[{"id":"1.195453616","rc":[{"atb":[[1.78,0],[1.76,0]],"id":37456368},{"atb":[[1.72,0],[1.74,0]],"id":39980001}],"con":true,"img":false}]}
{"op":"mcm","clk":"5348025079","pt":1646212649050,"mc":[{"id":"1.195453616","rc":[{"atl":[[2.2,0],[2.1,90.91]],"id":28755739}],"con":true,"img":false}]}
{"op":"mcm","clk":"5348025145","pt":1646212650134,"mc":[{"id":"1.195453616","rc":[{"atl":[[5.4,28.41]],"id":26503913},{"atl":[[1.99,126.26]],"id":28755739},{"atb":[[1.73,308.22]],"id":37456368},{"atb":[[3,62.5]],"id":36036864},{"atb":[[1.69,181.16]],"id":39980001}],"con":true,"img":false}]}
{"op":"mcm","clk":"5348025313","pt":1646212653281,"mc":[{"id":"1.195453616","rc":[{"atl":[[3.2,9.09],[3.25,0]],"id":37456368}],"con":true,"img":false}]}
{"op":"mcm","clk":"5348025319","pt":1646212653332,"mc":[{"id":"1.195453616","rc":[{"atl":[[3.7,0],[3.65,37.74]],"id":37456368}],"con":true,"img":false}]}
{"op":"mcm","clk":"5348025455","pt":1646212655674,"mc":[{"id":"1.195453616","rc":[{"atl":[[2.22,0]],"id":28755739}],"con":true,"img":false}]}
{"op":"mcm","clk":"5348025462","pt":1646212655776,"mc":[{"id":"1.195453616","rc":[{"atl":[[1.94,43.59]],"id":28755739}],"con":true,"img":false}]}
{"op":"mcm","clk":"5348025479","pt":1646212656085,"mc":[{"id":"1.195453616","rc":[{"atb":[[1.83,0]],"id":37456368}],"con":true,"img":false}]}
{"op":"mcm","clk":"5348025575","pt":1646212657738,"mc":[{"id":"1.195453616","rc":[{"atl":[[7.2,11.9]],"id":36036864},{"atl":[[11,0]],"id":39784359}],"con":true,"img":false}]}
{"op":"mcm","clk":"5348025583","pt":1646212657894,"mc":[{"id":"1.195453616","rc":[{"atl":[[7.6,5.89]],"id":36036864},{"atl":[[11.5,11.1]],"id":39784359}],"con":true,"img":false}]}
{"op":"mcm","clk":"5348025741","pt":1646212660678,"mc":[{"id":"1.195453616","rc":[{"atb":[[1.82,29.97]],"id":37456368}],"con":true,"img":false}]}
{"op":"mcm","clk":"5348025762","pt":1646212661192,"mc":[{"id":"1.195453616","rc":[{"atl":[[1.88,22.73],[1.93,0]],"id":28755739},{"atb":[[1.78,25.64],[1.75,133.08]],"id":39980001}],"con":true,"img":false}]}
{"op":"mcm","clk":"5348025767","pt":1646212661295,"mc":[{"id":"1.195453616","rc":[{"atb":[[1.33,60.61],[1.35,0]],"id":28755739},{"atl":[[1.89,22.47]],"id":28755739},{"atl":[[3.2,0],[3.15,9.3]],"id":37456368},{"atb":[[3.4,8.33],[3.3,43.39]],"id":36036864},{"atl":[[11.5,20.62],[12,0]],"id":39784359}],"con":true,"img":false}]}
{"op":"mcm","clk":"5348025837","pt":1646212662582,"mc":[{"id":"1.195453616","rc":[{"atb":[[1.35,57.14]],"id":28755739},{"atl":[[1.93,21.51]],"id":28755739},{"atb":[[1.75,159.75]],"id":39980001}],"con":true,"img":false}]}
{"op":"mcm","clk":"5348025846","pt":1646212662720,"mc":[{"id":"1.195453616","rc":[{"atb":[[2,20],[1.44,0],[1.89,109],[1.54,0]],"id":26503913},{"atl":[[5.6,21.74],[5.8,0]],"id":26503913},{"atb":[[1.26,384.62],[1.36,0]],"id":28755739},{"atl":[[1.89,0],[1.88,0]],"id":28755739},{"atb":[[1.73,136.99],[1.62,118.77],[1.79,0],[1.77,0],[1.75,133.08],[1.66,30.3]],"id":37456368},{"atb":[[3.6,38.46],[2.6,0],[3.75,7.27],[2.78,0]],"id":39784359},{"atb":[[1.78,0]],"id":39980001},{"atl":[[4.8,0],[4.5,20.74],[4.6,0],[5,0],[6,24],[4.4,29.69]],"id":39980001}],"con":true,"img":false}]}
{"op":"mcm","clk":"5348025850","pt":1646212662792,"mc":[{"id":"1.195453616","rc":[{"atb":[[1.73,0]],"id":37456368}],"con":true,"img":false}]}
{"op":"mcm","clk":"5348025912","pt":1646212663771,"mc":[{"id":"1.195453616","rc":[{"atl":[[3.55,88.24],[3.65,0]],"id":37456368}],"con":true,"img":false}]}
{"op":"mcm","clk":"5348026006","pt":1646212665583,"mc":[{"id":"1.195453616","rc":[{"atl":[[4.8,0],[4.6,5.56]],"id":26503913},{"atl":[[1.89,22.47],[1.93,0]],"id":28755739},{"atb":[[1.72,27.78]],"id":37456368},{"atb":[[1.78,25.64],[1.75,133.08]],"id":39980001}],"con":true,"img":false}]}
{"op":"mcm","clk":"5348026169","pt":1646212669697,"mc":[{"id":"1.195453616","rc":[{"atb":[[1.37,0]],"id":28755739}],"con":true,"img":false}]}
{"op":"mcm","clk":"5348026171","pt":1646212669801,"mc":[{"id":"1.195453616","rc":[{"atb":[[1.36,84.77]],"id":28755739}],"con":true,"img":false}]}
{"op":"mcm","clk":"5348026207","pt":1646212670577,"mc":[{"id":"1.195453616","rc":[{"atb":[[1.4,20.84]],"id":28755739}],"con":true,"img":false}]}
{"op":"mcm","clk":"5348026235","pt":1646212671303,"mc":[{"id":"1.195453616","rc":[{"atb":[[3.3,65.13]],"id":36036864}],"con":true,"img":false}]}
{"op":"mcm","clk":"5348026292","pt":1646212672685,"mc":[{"id":"1.195453616","rc":[{"atb":[[3.65,18.87]],"id":39784359}],"con":true,"img":false}]}
{"op":"mcm","clk":"5348026297","pt":1646212672788,"mc":[{"id":"1.195453616","rc":[{"atb":[[1.38,0]],"id":28755739}],"con":true,"img":false}]}
{"op":"mcm","clk":"5348026474","pt":1646212675594,"mc":[{"id":"1.195453616","rc":[{"atb":[[1.98,51.02]],"id":26503913},{"atl":[[4.8,13.16]],"id":26503913},{"atb":[[1.33,151.52],[1.39,19.27]],"id":28755739},{"atl":[[1.91,54.95]],"id":28755739},{"atb":[[1.7,71.43]],"id":37456368},{"atl":[[3.25,22.22]],"id":37456368},{"atb":[[1.76,65.79]],"id":39980001},{"atl":[[6.4,9.26]],"id":39980001}],"con":true,"img":false}]}
{"op":"mcm","clk":"5348026544","pt":1646212676891,"mc":[{"id":"1.195453616","rc":[{"atb":[[1.48,0]],"id":26503913},{"atl":[[5.4,0]],"id":26503913},{"atl":[[1.99,0]],"id":28755739},{"atl":[[3.55,39.22]],"id":37456368},{"atb":[[3,0]],"id":36036864},{"atb":[[2.66,0]],"id":39784359},{"atb":[[1.73,0],[1.71,0],[1.69,0]],"id":39980001}],"con":true,"img":false}]}
{"op":"mcm","clk":"5348026564","pt":1646212677193,"mc":[{"id":"1.195453616","rc":[{"atb":[[1.37,25.3]],"id":28755739}],"con":true,"img":false}]}
{"op":"mcm","clk":"5348026669","pt":1646212679212,"mc":[{"id":"1.195453616","rc":[{"atb":[[1.82,0]],"id":37456368}],"con":true,"img":false}]}
{"op":"mcm","clk":"5348026782","pt":1646212681328,"mc":[{"id":"1.195453616","rc":[{"spn":3.69,"spf":"NaN","id":26503913},{"spn":2.53,"spf":"NaN","id":37456368},{"atb":[[3.2,34.09]],"id":36036864}],"con":true,"img":false}]}
{"op":"mcm","clk":"5348026795","pt":1646212681540,"mc":[{"id":"1.195453616","rc":[{"atb":[[1.37,0]],"id":28755739}],"con":true,"img":false}]}
{"op":"mcm","clk":"5348026860","pt":1646212682736,"mc":[{"id":"1.195453616","rc":[{"atb":[[3.55,29.41]],"id":39784359}],"con":true,"img":false}]}
{"op":"mcm","clk":"5348026937","pt":1646212684118,"mc":[{"id":"1.195453616","rc":[{"atb":[[2.14,58.49]],"id":26503913},{"atl":[[4.8,5.26],[4.6,0]],"id":26503913},{"atb":[[1.33,60.61],[1.35,0]],"id":28755739},{"atl":[[1.71,3]],"id":28755739},{"atb":[[1.72,0],[1.82,29.97],[1.7,0]],"id":37456368},{"atl":[[2.46,4]],"id":37456368},{"atb":[[2.7,0]],"id":39784359}],"con":true,"img":false}]}
{"op":"mcm","clk":"5348026948","pt":1646212684327,"mc":[{"id":"1.195453616","rc":[{"atb":[[2.16,2]],"id":26503913},{"atl":[[1.63,2],[1.71,0]],"id":28755739},{"atl":[[2.46,0],[2.44,2]],"id":37456368}],"con":true,"img":false}]}
{"op":"mcm","clk":"5348026961","pt":1646212684529,"mc":[{"id":"1.195453616","rc":[{"atb":[[2.18,2]],"id":26503913},{"atb":[[1.35,57.14]],"id":28755739},{"atl":[[1.63,0]],"id":28755739},{"atl":[[2.3,2],[2.44,0]],"id":37456368}],"con":true,"img":false}]}
{"op":"mcm","clk":"5348026977","pt":1646212684736,"mc":[{"id":"1.195453616","rc":[{"atb":[[2.2,4]],"id":26503913},{"atl":[[2.3,0],[2.28,3]],"id":37456368}],"con":true,"img":false}]}
{"op":"mcm","clk":"5348027018","pt":1646212685626,"mc":[{"id":"1.195453616","rc":[{"atb":[[1.64,78.13]],"id":37456368},{"atl":[[3.35,31.91]],"id":37456368},{"atb":[[1.74,101.35]],"id":39980001},{"atl":[[6.8,12.93]],"id":39980001}],"con":true,"img":false}]}
{"op":"mcm","clk":"5348027079","pt":1646212686512,"mc":[{"id":"1.195453616","rc":[{"atb":[[1.37,25.3],[1.35,0]],"id":28755739},{"atl":[[1.63,4]],"id":28755739},{"atl":[[2.26,2]],"id":37456368}],"con":true,"img":false}]}
{"op":"mcm","clk":"5348027095","pt":1646212686718,"mc":[{"id":"1.195453616","rc":[{"atl":[[1.63,0],[1.6,3]],"id":28755739},{"atl":[[2.24,2]],"id":37456368}],"con":true,"img":false}]}
{"op":"mcm","clk":"5348027100","pt":1646212686822,"mc":[{"id":"1.195453616","rc":[{"atl":[[2.26,0],[2.28,0]],"id":37456368}],"con":true,"img":false}]}
{"op":"mcm","clk":"5348027232","pt":1646212688829,"mc":[{"id":"1.195453616","rc":[{"atb":[[1.87,0]],"id":39980001}],"con":true,"img":false}]}
{"op":"mcm","clk":"5348027300","pt":1646212689911,"mc":[{"id":"1.195453616","rc":[{"atb":[[2.16,1.66]],"id":39980001}],"con":true,"img":false}]}
{"op":"mcm","clk":"5348027305","pt":1646212690013,"mc":[{"id":"1.195453616","rc":[{"atb":[[1.94,2.16],[2.1,19.78]],"id":39980001}],"con":true,"img":false}]}
{"op":"mcm","clk":"5348027355","pt":1646212691142,"mc":[{"id":"1.195453616","rc":[{"atb":[[1.82,0]],"id":37456368}],"con":true,"img":false}]}
{"op":"mcm","clk":"5348027364","pt":1646212691297,"mc":[{"id":"1.195453616","rc":[{"atb":[[3.1,59.52]],"id":36036864}],"con":true,"img":false}]}
{"op":"mcm","clk":"5348027371","pt":1646212691504,"mc":[{"id":"1.195453616","rc":[{"atb":[[1.35,57.14]],"id":28755739},{"atl":[[1.59,3],[1.6,0]],"id":28755739},{"atl":[[2.22,4]],"id":37456368}],"con":true,"img":false}]}
{"op":"mcm","clk":"5348027377","pt":1646212691604,"mc":[{"id":"1.195453616","rc":[{"atl":[[2.2,4]],"id":37456368}],"con":true,"img":false}]}
{"op":"mcm","clk":"5348027439","pt":1646212692742,"mc":[{"id":"1.195453616","rc":[{"atb":[[3.45,91.76]],"id":39784359}],"con":true,"img":false}]}
{"op":"mcm","clk":"5348027478","pt":1646212693308,"mc":[{"id":"1.195453616","rc":[{"atb":[[1.91,9.02]],"id":39980001}],"con":true,"img":false}]}
{"op":"mcm","clk":"5348027496","pt":1646212693614,"mc":[{"id":"1.195453616","rc":[{"atb":[[1.36,0]],"id":28755739}],"con":true,"img":false}]}
{"op":"mcm","clk":"5348027501","pt":1646212693719,"mc":[{"id":"1.195453616","rc":[{"atb":[[1.34,84.77]],"id":28755739}],"con":true,"img":false}]}
{"op":"mcm","clk":"5348027511","pt":1646212693928,"mc":[{"id":"1.195453616","rc":[{"atb":[[1.39,0]],"id":28755739}],"con":true,"img":false}]}
{"op":"mcm","clk":"5348027522","pt":1646212694136,"mc":[{"id":"1.195453616","rc":[{"atb":[[1.96,78.12]],"id":26503913},{"atl":[[5.4,28.41]],"id":26503913}],"con":true,"img":false}]}
{"op":"mcm","clk":"5348027581","pt":1646212695316,"mc":[{"id":"1.195453616","rc":[{"atb":[[1.4,0]],"id":28755739}],"con":true,"img":false}]}
{"op":"mcm","clk":"5348027597","pt":1646212695624,"mc":[{"id":"1.195453616","rc":[{"atb":[[1.62,239.74]],"id":37456368},{"atl":[[3.45,51.02]],"id":37456368},{"atb":[[1.72,173.61]],"id":39980001},{"atl":[[7.2,20.16]],"id":39980001}],"con":true,"img":false}]}
{"op":"mcm","clk":"5348027602","pt":1646212695727,"mc":[{"id":"1.195453616","rc":[{"atl":[[11.5,16.66]],"id":39784359}],"con":true,"img":false}]}
{"op":"mcm","clk":"5348027606","pt":1646212695830,"mc":[{"id":"1.195453616","rc":[{"atl":[[11,3.96]],"id":39784359}],"con":true,"img":false}]}
{"op":"mcm","clk":"5348027611","pt":1646212695931,"mc":[{"id":"1.195453616","rc":[{"atb":[[2.16,0]],"id":39980001}],"con":true,"img":false}]}
{"op":"mcm","clk":"5348027617","pt":1646212696034,"mc":[{"id":"1.195453616","rc":[{"atb":[[1.37,0]],"id":28755739},{"atl":[[11,13.96],[11.5,7.14]],"id":39784359},{"atb":[[1.94,41.72]],"id":39980001}],"con":true,"img":false}]}
{"op":"mcm","clk":"5348027626","pt":1646212696137,"mc":[{"id":"1.195453616","rc":[{"atb":[[2.8,4.12]],"id":26503913},{"atb":[[2.22,1.66],[2.1,0]],"id":39980001}],"con":true,"img":false}]}
{"op":"mcm","clk":"5348027655","pt":1646212696754,"mc":[{"id":"1.195453616","rc":[{"atb":[[1.5,0]],"id":26503913},{"atb":[[1.9,9.26]],"id":39980001}],"con":true,"img":false}]}
{"op":"mcm","clk":"5348027658","pt":1646212696810,"mc":[{"id":"1.195453616","rc":[{"atl":[[2.18,2]],"id":37456368},{"atb":[[2.74,0]],"id":39784359}],"con":true,"img":false}]}
{"op":"mcm","clk":"5348027662","pt":1646212696911,"mc":[{"id":"1.195453616","rc":[{"atl":[[1.59,0]],"id":28755739}],"con":true,"img":false}]}
{"op":"mcm","clk":"5348027689","pt":1646212697630,"mc":[{"id":"1.195453616","rc":[{"atl":[[1.94,0]],"id":28755739}],"con":true,"img":false}]}
{"op":"mcm","clk":"5348027694","pt":1646212697737,"mc":[{"id":"1.195453616","rc":[{"atl":[[1.9,43.59]],"id":28755739}],"con":true,"img":false}]}
{"op":"mcm","clk":"5348027821","pt":1646212699850,"mc":[{"id":"1.195453616","rc":[{"atl":[[2.22,0],[2.24,0],[2.18,0],[2.2,0]],"id":37456368},{"trd":[[2.24,4],[2.22,8],[2.18,4],[2.2,8]],"ltp":2.24,"tv":24.0,"id":37456368}],"con":true,"img":false}]}
{"op":"mcm","clk":"5348027830","pt":1646212700050,"mc":[{"id":"1.195453616","rc":[{"atb":[[1.91,13.88]],"id":37456368}],"con":true,"img":false}]}
{"op":"mcm","clk":"5348027874","pt":1646212700687,"mc":[{"id":"1.195453616","rc":[{"atb":[[1.36,41.51]],"id":28755739}],"con":true,"img":false}]}
{"op":"mcm","clk":"5348027882","pt":1646212700822,"mc":[{"id":"1.195453616","rc":[{"atl":[[3.1,2.52]],"id":37456368}],"con":true,"img":false}]}
{"op":"mcm","clk":"5348027918","pt":1646212701557,"mc":[{"id":"1.195453616","rc":[{"atb":[[1.33,212.13]],"id":28755739},{"atl":[[1.93,80.65]],"id":28755739}],"con":true,"img":false}]}
{"op":"mcm","clk":"5348027923","pt":1646212701657,"mc":[{"id":"1.195453616","rc":[{"atb":[[1.33,151.52]],"id":28755739},{"atl":[[7.6,0]],"id":36036864}],"con":true,"img":false}]}
{"op":"mcm","clk":"5348027931","pt":1646212701712,"mc":[{"id":"1.195453616","rc":[{"atl":[[1.97,0]],"id":28755739},{"atl":[[7,14.22]],"id":36036864}],"con":true,"img":false}]}
{"op":"mcm","clk":"5348027940","pt":1646212701815,"mc":[{"id":"1.195453616","rc":[{"atl":[[6.8,11.9]],"id":36036864}],"con":true,"img":false}]}
{"op":"mcm","clk":"5348027947","pt":1646212701931,"mc":[{"id":"1.195453616","rc":[{"atb":[[2.78,4.22]],"id":26503913},{"atl":[[7.2,0]],"id":36036864},{"atb":[[2.22,0]],"id":39980001}],"con":true,"img":false}]}
{"op":"mcm","clk":"5348027956","pt":1646212702022,"mc":[{"id":"1.195453616","rc":[{"atb":[[2.82,1.66]],"id":26503913}],"con":true,"img":false}]}
{"op":"mcm","clk":"5348028000","pt":1646212702740,"mc":[{"id":"1.195453616","rc":[{"atb":[[1.98,7.66]],"id":39980001}],"con":true,"img":false}]}
{"op":"mcm","clk":"5348028050","pt":1646212703722,"mc":[{"id":"1.195453616","rc":[{"atb":[[1.57,0]],"id":37456368}],"con":true,"img":false}]}
{"op":"mcm","clk":"5348028057","pt":1646212703825,"mc":[{"id":"1.195453616","rc":[{"atb":[[1.65,93.48]],"id":37456368}],"con":true,"img":false}]}
{"op":"mcm","clk":"5348028067","pt":1646212704132,"mc":[{"id":"1.195453616","rc":[{"atb":[[1.94,132.98]],"id":26503913}],"con":true,"img":false}]}
{"op":"mcm","clk":"5348028115","pt":1646212705213,"mc":[{"id":"1.195453616","rc":[{"atb":[[1.91,0]],"id":39980001}],"con":true,"img":false}]}
{"op":"mcm","clk":"5348028130","pt":1646212705627,"mc":[{"id":"1.195453616","rc":[{"atb":[[1.6,208.33]],"id":37456368},{"atl":[[3.25,20.69]],"id":37456368}],"con":true,"img":false}]}
{"op":"mcm","clk":"5348028132","pt":1646212705728,"mc":[{"id":"1.195453616","rc":[{"atb":[[1.38,19.78]],"id":28755739}],"con":true,"img":false}]}
{"op":"mcm","clk":"5348028141","pt":1646212706037,"mc":[{"id":"1.195453616","rc":[{"atb":[[1.99,9.26],[1.94,2.16]],"id":39980001}],"con":true,"img":false}]}
{"op":"mcm","clk":"5348028199","pt":1646212707638,"mc":[{"id":"1.195453616","rc":[{"atl":[[3.4,0]],"id":37456368}],"con":true,"img":false}]}
{"op":"mcm","clk":"5348028204","pt":1646212707739,"mc":[{"id":"1.195453616","rc":[{"atl":[[3.2,22.7]],"id":37456368}],"con":true,"img":false}]}
{"op":"mcm","clk":"5348028248","pt":1646212708718,"mc":[{"id":"1.195453616","rc":[{"atb":[[1.98,0]],"id":39980001}],"con":true,"img":false}]}
{"op":"mcm","clk":"5348028286","pt":1646212709645,"mc":[{"id":"1.195453616","rc":[{"atl":[[7,8.33]],"id":36036864}],"con":true,"img":false}]}
{"op":"mcm","clk":"5348028291","pt":1646212709746,"mc":[{"id":"1.195453616","rc":[{"atl":[[7.2,5.89]],"id":36036864}],"con":true,"img":false}]}
{"op":"mcm","clk":"5348028295","pt":1646212709849,"mc":[{"id":"1.195453616","rc":[{"atl":[[6.8,0],[7,23.8]],"id":36036864}],"con":true,"img":false}]}
{"op":"mcm","clk":"5348028307","pt":1646212710058,"mc":[{"id":"1.195453616","rc":[{"atb":[[1.36,0]],"id":28755739},{"atb":[[1.86,20.85]],"id":37456368}],"con":true,"img":false}]}
{"op":"mcm","clk":"5348028372","pt":1646212711140,"mc":[{"id":"1.195453616","rc":[{"atb":[[1.94,20.68]],"id":39980001}],"con":true,"img":false}]}
{"op":"mcm","clk":"5348028379","pt":1646212711243,"mc":[{"id":"1.195453616","rc":[{"atb":[[1.52,0]],"id":26503913},{"atb":[[1.99,0]],"id":39980001}],"con":true,"img":false}]}
{"op":"mcm","clk":"5348028385","pt":1646212711346,"mc":[{"id":"1.195453616","rc":[{"atb":[[1.33,60.6],[1.35,0]],"id":28755739},{"atl":[[1.63,4]],"id":28755739}],"con":true,"img":false}]}
{"op":"mcm","clk":"5348028395","pt":1646212711552,"mc":[{"id":"1.195453616","rc":[{"atl":[[1.59,3],[1.63,0]],"id":28755739}],"con":true,"img":false}]}
{"op":"mcm","clk":"5348028401","pt":1646212711765,"mc":[{"id":"1.195453616","rc":[{"atl":[[1.58,3]],"id":28755739}],"con":true,"img":false}]}
{"op":"mcm","clk":"5348028569","pt":1646212714647,"mc":[{"id":"1.195453616","rc":[{"atb":[[1.38,0]],"id":28755739},{"atl":[[1.57,3]],"id":28755739},{"atb":[[3.4,0],[3.5,8]],"id":36036864},{"atl":[[6.8,3.45],[6.6,0]],"id":36036864},{"atl":[[9.6,0],[9.8,2.27]],"id":39784359},{"atb":[[1.9,17.61]],"id":39980001}],"con":true,"img":false}]}
{"op":"mcm","clk":"5348028584","pt":1646212714957,"mc":[{"id":"1.195453616","rc":[{"atb":[[1.87,31.02]],"id":39980001}],"con":true,"img":false}]}
{"op":"mcm","clk":"5348028609","pt":1646212715470,"mc":[{"id":"1.195453616","rc":[{"atl":[[1.59,0],[1.56,3]],"id":28755739}],"con":true,"img":false}]}
{"op":"mcm","clk":"5348028626","pt":1646212715679,"mc":[{"id":"1.195453616","rc":[{"atl":[[3.35,29.72]],"id":37456368}],"con":true,"img":false}]}
{"op":"mcm","clk":"5348028633","pt":1646212715733,"mc":[{"id":"1.195453616","rc":[{"atl":[[1.58,0],[1.56,0],[1.57,0],[1.66,2]],"id":28755739}],"con":true,"img":false}]}
{"op":"mcm","clk":"5348028642","pt":1646212715833,"mc":[{"id":"1.195453616","rc":[{"atl":[[1.65,3]],"id":28755739}],"con":true,"img":false}]}
{"op":"mcm","clk":"5348028660","pt":1646212716143,"mc":[{"id":"1.195453616","rc":[{"atb":[[2.14,54.49],[2.18,0],[2.2,0],[2.16,0]],"id":26503913}],"con":true,"img":false}]}
{"op":"mcm","clk":"5348028672","pt":1646212716348,"mc":[{"id":"1.195453616","rc":[{"atl":[[1.64,4]],"id":28755739}],"con":true,"img":false}]}
{"op":"mcm","clk":"5348028689","pt":1646212716664,"mc":[{"id":"1.195453616","rc":[{"atl":[[4.8,0],[4.6,5.56]],"id":26503913},{"atb":[[1.35,57.14]],"id":28755739},{"atl":[[1.64,0],[1.89,0],[1.63,2],[1.88,22.73],[1.65,0],[1.66,0]],"id":28755739},{"atl":[[3.1,11.39],[3.15,0]],"id":37456368}],"con":true,"img":false}]}
{"op":"mcm","clk":"5348028697","pt":1646212716765,"mc":[{"id":"1.195453616","rc":[{"atl":[[5.6,0],[6,20]],"id":26503913}],"con":true,"img":false}]}
{"op":"mcm","clk":"5348028704","pt":1646212716867,"mc":[{"id":"1.195453616","rc":[{"atl":[[1.63,0]],"id":28755739}],"con":true,"img":false}]}
{"op":"mcm","clk":"5348028762","pt":1646212718055,"mc":[{"id":"1.195453616","rc":[{"atl":[[11,10]],"id":39784359}],"con":true,"img":false}]}
{"op":"mcm","clk":"5348028766","pt":1646212718157,"mc":[{"id":"1.195453616","rc":[{"atl":[[10.5,9.22]],"id":39784359}],"con":true,"img":false}]}
{"op":"mcm","clk":"5348028788","pt":1646212718571,"mc":[{"id":"1.195453616","rc":[{"atl":[[3.1,8.87]],"id":37456368}],"con":true,"img":false}]}
{"op":"mcm","clk":"5348028811","pt":1646212718981,"mc":[{"id":"1.195453616","rc":[{"atl":[[1000,2.52]],"id":37456368}],"con":true,"img":false}]}
{"op":"mcm","clk":"5348028823","pt":1646212719196,"mc":[{"id":"1.195453616","rc":[{"atl":[[1000,2.1]],"id":37456368}],"con":true,"img":false}]}
{"op":"mcm","clk":"5348028833","pt":1646212719343,"mc":[{"id":"1.195453616","rc":[{"atl":[[1000,0]],"id":37456368}],"con":true,"img":false}]}
{"op":"mcm","clk":"5348028840","pt":1646212719506,"mc":[{"id":"1.195453616","rc":[{"atl":[[3.05,2.1]],"id":37456368}],"con":true,"img":false}]}
{"op":"mcm","clk":"5348028859","pt":1646212719863,"mc":[{"id":"1.195453616","rc":[{"atb":[[1.86,0]],"id":37456368}],"con":true,"img":false}]}
{"op":"mcm","clk":"5348028955","pt":1646212721668,"mc":[{"id":"1.195453616","rc":[{"atl":[[4.8,5.26],[4.6,0]],"id":26503913}],"con":true,"img":false}]}
{"op":"mcm","clk":"5348028985","pt":1646212722083,"mc":[{"id":"1.195453616","rc":[{"atb":[[1.37,22.53]],"id":28755739}],"con":true,"img":false}]}
{"op":"mcm","clk":"5348029080","pt":1646212723738,"mc":[{"id":"1.195453616","rc":[{"atb":[[1.38,19.78]],"id":28755739}],"con":true,"img":false}]}
{"op":"mcm","clk":"5348029097","pt":1646212724359,"mc":[{"id":"1.195453616","rc":[{"atb":[[1.36,41.51]],"id":28755739}],"con":true,"img":false}]}
{"op":"mcm","clk":"5348029116","pt":1646212724666,"mc":[{"id":"1.195453616","rc":[{"atb":[[3.4,20.83]],"id":36036864},{"atl":[[7.2,13.95]],"id":36036864}],"con":true,"img":false}]}
{"op":"mcm","clk":"5348029221","pt":1646212726678,"mc":[{"id":"1.195453616","rc":[{"atb":[[1.33,151.52]],"id":28755739}],"con":true,"img":false}]}
{"op":"mcm","clk":"5348029237","pt":1646212726886,"mc":[{"id":"1.195453616","rc":[{"atb":[[1.33,60.6],[1.35,0],[1.36,0]],"id":28755739},{"atl":[[1.89,22.47],[1.88,0],[1.71,2]],"id":28755739},{"atb":[[3.1,0]],"id":36036864},{"atl":[[7.4,0],[7,15.47],[7.8,0]],"id":36036864}],"con":true,"img":false}]}
{"op":"mcm","clk":"5348029252","pt":1646212727090,"mc":[{"id":"1.195453616","rc":[{"atl":[[1.67,3],[1.71,0]],"id":28755739}],"con":true,"img":false}]}
{"op":"mcm","clk":"5348029297","pt":1646212727862,"mc":[{"id":"1.195453616","rc":[{"atb":[[1.38,0]],"id":28755739}],"con":true,"img":false}]}
{"op":"mcm","clk":"5348029480","pt":1646212731465,"mc":[{"id":"1.195453616","rc":[{"atb":[[1.38,17.29]],"id":28755739}],"con":true,"img":false}]}
{"op":"mcm","clk":"5348029507","pt":1646212731881,"mc":[{"id":"1.195453616","rc":[{"atl":[[7.2,8.06]],"id":36036864}],"con":true,"img":false}]}
{"op":"mcm","clk":"5348029512","pt":1646212731993,"mc":[{"id":"1.195453616","rc":[{"atl":[[1.89,0],[1.88,22.73],[1.66,4]],"id":28755739},{"atl":[[7.2,24.19],[6.8,9.34]],"id":36036864}],"con":true,"img":false}]}
{"op":"mcm","clk":"5348029518","pt":1646212732096,"mc":[{"id":"1.195453616","rc":[{"atl":[[7,0]],"id":36036864}],"con":true,"img":false}]}
{"op":"mcm","clk":"5348029521","pt":1646212732187,"mc":[{"id":"1.195453616","rc":[{"atl":[[1.65,2]],"id":28755739}],"con":true,"img":false}]}
{"op":"mcm","clk":"5348029527","pt":1646212732299,"mc":[{"id":"1.195453616","rc":[{"atb":[[1.65,0]],"id":37456368}],"con":true,"img":false}]}
{"op":"mcm","clk":"5348029531","pt":1646212732392,"mc":[{"id":"1.195453616","rc":[{"atb":[[1.63,93.48]],"id":37456368}],"con":true,"img":false}]}
{"op":"mcm","clk":"5348029570","pt":1646212733171,"mc":[{"id":"1.195453616","rc":[{"atb":[[1.35,57.14]],"id":28755739},{"atl":[[1.67,0],[1.65,0],[1.66,0]],"id":28755739}],"con":true,"img":false}]}
{"op":"mcm","clk":"5348029651","pt":1646212734659,"mc":[{"id":"1.195453616","rc":[{"atb":[[3.3,97.74]],"id":36036864},{"atl":[[7.6,11.36]],"id":36036864}],"con":true,"img":false}]}
{"op":"mcm","clk":"5348029657","pt":1646212734763,"mc":[{"id":"1.195453616","rc":[{"atb":[[3.3,76]],"id":36036864}],"con":true,"img":false}]}
{"op":"mcm","clk":"5348029702","pt":1646212735483,"mc":[{"id":"1.195453616","rc":[{"atb":[[1.86,66.69]],"id":39980001}],"con":true,"img":false}]}
{"op":"mcm","clk":"5348029712","pt":1646212735586,"mc":[{"id":"1.195453616","rc":[{"atb":[[1.88,50.69]],"id":39980001}],"con":true,"img":false}]}
{"op":"mcm","clk":"5348029881","pt":1646212738891,"mc":[{"id":"1.195453616","rc":[{"atb":[[1.9,9.26]],"id":39980001}],"con":true,"img":false}]}
{"op":"mcm","clk":"5348029913","pt":1646212739562,"mc":[{"id":"1.195453616","rc":[{"atl":[[1.89,22.47],[1.88,0],[1.71,3]],"id":28755739},{"atb":[[1.81,0]],"id":37456368}],"con":true,"img":false}]}
{"op":"mcm","clk":"5348029920","pt":1646212739669,"mc":[{"id":"1.195453616","rc":[{"atb":[[1.35,0]],"id":28755739},{"atl":[[1.68,3],[1.71,0]],"id":28755739},{"atb":[[1.66,84.12]],"id":37456368},{"atb":[[1.87,0]],"id":39980001}],"con":true,"img":false}]}
{"op":"mcm","clk":"5348029943","pt":1646212740078,"mc":[{"id":"1.195453616","rc":[{"atl":[[6.8,3.45]],"id":36036864}],"con":true,"img":false}]}
{"op":"mcm","clk":"5348029948","pt":1646212740182,"mc":[{"id":"1.195453616","rc":[{"atl":[[7.2,8.06],[7.6,26.51],[7,5.89]],"id":36036864}],"con":true,"img":false}]}
{"op":"mcm","clk":"5348030035","pt":1646212741790,"mc":[{"id":"1.195453616","rc":[{"spn":3.81,"spf":"NaN","id":26503913},{"atb":[[1.35,57.14]],"id":28755739},{"atl":[[1.68,0]],"id":28755739},{"spn":2.48,"spf":"NaN","id":37456368}],"con":true,"img":false}]}
{"op":"mcm","clk":"5348030137","pt":1646212743627,"mc":[{"id":"1.195453616","rc":[{"atb":[[2.5,0],[2.6,0],[2.7,0]],"id":26503913},{"atl":[[8.6,0],[11.5,0],[6.6,0]],"id":26503913},{"atb":[[1.2,0],[1.25,0],[1.3,0]],"id":28755739},{"atl":[[2.54,0],[2.74,0],[2.94,0]],"id":28755739},{"atb":[[1.8,0],[1.85,0],[1.75,0]],"id":37456368},{"atl":[[4.5,0],[5.5,0],[3.75,0]],"id":37456368},{"atb":[[3.55,0],[3.3,32.61],[3.05,48.78]],"id":36036864},{"atl":[[19.5,0],[9.8,0],[14.5,0]],"id":36036864},{"atb":[[3.45,51.02],[3.95,0],[3.7,0]],"id":39784359},{"atl":[[18.5,0],[13.5,0],[27,0]],"id":39784359},{"atb":[[1.8,0],[1.85,0],[1.75,0]],"id":39980001},{"atl":[[4.5,0],[5.5,0],[3.75,0]],"id":39980001}],"con":true,"img":false}]}
{"op":"mcm","clk":"5348030154","pt":1646212743982,"mc":[{"id":"1.195453616","rc":[{"atl":[[5.1,13.98],[4.4,12.82]],"id":39980001}],"con":true,"img":false}]}
{"op":"mcm","clk":"5348030157","pt":1646212744083,"mc":[{"id":"1.195453616","rc":[{"atb":[[2.72,0]],"id":26503913},{"atb":[[4,0]],"id":39784359},{"atb":[[1.86,0]],"id":39980001}],"con":true,"img":false}]}
{"op":"mcm","clk":"5348030164","pt":1646212744186,"mc":[{"id":"1.195453616","rc":[{"atb":[[2.4,26.91]],"id":26503913},{"atb":[[3.7,20.95]],"id":39784359},{"atb":[[1.79,66.69]],"id":39980001}],"con":true,"img":false}]}
{"op":"mcm","clk":"5348030188","pt":1646212744703,"mc":[{"id":"1.195453616","rc":[{"atb":[[1.38,0]],"id":28755739},{"atb":[[1.86,20.85]],"id":37456368},{"atb":[[3.2,56.82]],"id":36036864},{"atl":[[8,17.86]],"id":36036864}],"con":true,"img":false}]}
{"op":"mcm","clk":"5348030204","pt":1646212745016,"mc":[{"id":"1.195453616","rc":[{"atb":[[2.78,0]],"id":26503913},{"atb":[[1.89,9.36]],"id":37456368},{"atb":[[3.65,3.14]],"id":36036864},{"atb":[[1.92,8.17]],"id":39980001}],"con":true,"img":false}]}
{"op":"mcm","clk":"5348030240","pt":1646212745885,"mc":[{"id":"1.195453616","rc":[{"atb":[[2.76,0]],"id":26503913},{"atb":[[1.89,0]],"id":37456368}],"con":true,"img":false}]}
{"op":"mcm","clk":"5348030277","pt":1646212746610,"mc":[{"id":"1.195453616","rc":[{"atb":[[2.46,2.16]],"id":26503913}],"con":true,"img":false}]}
{"op":"mcm","clk":"5348030346","pt":1646212748102,"mc":[{"id":"1.195453616","rc":[{"atl":[[7,0]],"id":36036864}],"con":true,"img":false}]}
{"op":"mcm","clk":"5348030350","pt":1646212748205,"mc":[{"id":"1.195453616","rc":[{"atl":[[7.4,5.89]],"id":36036864}],"con":true,"img":false}]}
{"op":"mcm","clk":"5348030362","pt":1646212748419,"mc":[{"id":"1.195453616","rc":[{"atb":[[2.5,66.54],[2.6,62.38],[2.7,58.71]],"id":26503913},{"atl":[[8.6,9.55],[11.5,6.91],[6.6,6.47]],"id":26503913},{"atb":[[1.2,499.07],[1.25,399.25],[1.3,332.71]],"id":28755739},{"atl":[[2.54,23.57],[2.74,41.71],[2.94,37.41]],"id":28755739},{"atb":[[1.8,124.76],[1.85,117.42],[1.75,133.08]],"id":37456368},{"atl":[[4.5,20.74],[5.5,16.13],[3.75,13.19]],"id":37456368},{"atb":[[3.55,39.14],[3.3,76],[3.05,97.46]],"id":36036864},{"atl":[[19.5,3.92],[9.8,4.12],[14.5,5.37]],"id":36036864},{"atb":[[3.45,91.76],[3.95,33.83],[3.7,57.92]],"id":39784359},{"atl":[[18.5,4.14],[13.5,2.9],[27,2.79]],"id":39784359},{"atb":[[1.8,124.76],[1.85,117.42],[1.75,133.08]],"id":39980001},{"atl":[[4.5,20.74],[5.5,16.13],[3.75,13.19]],"id":39980001}],"con":true,"img":false}]}
{"op":"mcm","clk":"5348030419","pt":1646212749508,"mc":[{"id":"1.195453616","rc":[{"atb":[[2.8,0]],"id":26503913},{"atb":[[1.38,17.29]],"id":28755739},{"atb":[[1.86,0]],"id":37456368}],"con":true,"img":false}]}
{"op":"mcm","clk":"5348030435","pt":1646212749819,"mc":[{"id":"1.195453616","rc":[{"atl":[[7.2,16.12],[7.6,11.36]],"id":36036864}],"con":true,"img":false}]}
{"op":"mcm","clk":"5348030440","pt":1646212749869,"mc":[{"id":"1.195453616","rc":[{"atb":[[2.82,0]],"id":26503913}],"con":true,"img":false}]}
{"op":"mcm","clk":"5348030449","pt":1646212750076,"mc":[{"id":"1.195453616","rc":[{"atb":[[2.72,1.66]],"id":26503913}],"con":true,"img":false}]}
{"op":"mcm","clk":"5348030488","pt":1646212750910,"mc":[{"id":"1.195453616","rc":[{"atb":[[1.38,37.08]],"id":28755739}],"con":true,"img":false}]}
{"op":"mcm","clk":"5348030528","pt":1646212751776,"mc":[{"id":"1.195453616","rc":[{"atb":[[1.33,151.52]],"id":28755739},{"atl":[[1.95,131.58]],"id":28755739}],"con":true,"img":false}]}
{"op":"mcm","clk":"5348030664","pt":1646212754307,"mc":[{"id":"1.195453616","rc":[{"atb":[[1.81,28.87]],"id":37456368},{"atb":[[1.95,14.48]],"id":39980001}],"con":true,"img":false}]}
{"op":"mcm","clk":"5348030676","pt":1646212754517,"mc":[{"id":"1.195453616","rc":[{"atb":[[1.96,14.48],[1.94,2.16]],"id":39980001}],"con":true,"img":false}]}
{"op":"mcm","clk":"5348030704","pt":1646212755088,"mc":[{"id":"1.195453616","rc":[{"atb":[[1.94,0],[1.99,2.16]],"id":39980001}],"con":true,"img":false}]}
{"op":"mcm","clk":"5348030756","pt":1646212756588,"mc":[{"id":"1.195453616","rc":[{"atl":[[5.6,21.74],[6,0]],"id":26503913},{"atl":[[3.1,0],[3.15,8.66]],"id":37456368}],"con":true,"img":false}]}
{"op":"mcm","clk":"5348030775","pt":1646212756897,"mc":[{"id":"1.195453616","rc":[{"atb":[[2.76,4.27]],"id":26503913},{"atb":[[1.89,8.45]],"id":37456368},{"atb":[[3.65,5.97]],"id":36036864}],"con":true,"img":false}]}
{"op":"mcm","clk":"5348030800","pt":1646212757415,"mc":[{"id":"1.195453616","rc":[{"atb":[[1.9,0]],"id":39980001}],"con":true,"img":false}]}
{"op":"mcm","clk":"5348030854","pt":1646212758397,"mc":[{"id":"1.195453616","rc":[{"atl":[[3.05,0]],"id":37456368},{"atb":[[1.95,0]],"id":39980001}],"con":true,"img":false}]}
{"op":"mcm","clk":"5348030897","pt":1646212759327,"mc":[{"id":"1.195453616","rc":[{"atl":[[1000,2.52]],"id":37456368}],"con":true,"img":false}]}
{"op":"mcm","clk":"5348030903","pt":1646212759532,"mc":[{"id":"1.195453616","rc":[{"atl":[[1000,2.1]],"id":37456368}],"con":true,"img":false}]}
{"op":"mcm","clk":"5348030915","pt":1646212759688,"mc":[{"id":"1.195453616","rc":[{"atl":[[1000,0]],"id":37456368}],"con":true,"img":false}]}
{"op":"mcm","clk":"5348030922","pt":1646212759791,"mc":[{"id":"1.195453616","rc":[{"atl":[[3.1,2.1]],"id":37456368}],"con":true,"img":false}]}
{"op":"mcm","clk":"5348030945","pt":1646212760412,"mc":[{"id":"1.195453616","rc":[{"atb":[[1.81,0]],"id":37456368}],"con":true,"img":false}]}
{"op":"mcm","clk":"5348031017","pt":1646212762008,"mc":[{"id":"1.195453616","rc":[{"atb":[[2.72,0]],"id":26503913}],"con":true,"img":false}]}
{"op":"mcm","clk":"5348031028","pt":1646212762206,"mc":[{"id":"1.195453616","rc":[{"atb":[[2.78,1.66]],"id":26503913}],"con":true,"img":false}]}
{"op":"mcm","clk":"5348031060","pt":1646212762725,"mc":[{"id":"1.195453616","rc":[{"atb":[[1.89,24.96]],"id":39980001}],"con":true,"img":false}]}
{"op":"mcm","clk":"5348031117","pt":1646212763914,"mc":[{"id":"1.195453616","rc":[{"atb":[[1.96,0],[1.99,10.33]],"id":39980001}],"con":true,"img":false}]}
{"op":"mcm","clk":"5348031186","pt":1646212765211,"mc":[{"id":"1.195453616","rc":[{"atb":[[1.86,20.85]],"id":37456368}],"con":true,"img":false}]}
{"op":"mcm","clk":"5348031264","pt":1646212766603,"mc":[{"id":"1.195453616","rc":[{"atl":[[3.45,47.51]],"id":37456368}],"con":true,"img":false}]}
{"op":"mcm","clk":"5348031468","pt":1646212770330,"mc":[{"id":"1.195453616","rc":[{"atb":[[2.76,9]],"id":26503913}],"con":true,"img":false}]}
{"op":"mcm","clk":"5348031477","pt":1646212770537,"mc":[{"id":"1.195453616","rc":[{"atb":[[1.89,17.82]],"id":37456368}],"con":true,"img":false}]}
{"op":"mcm","clk":"5348031504","pt":1646212770942,"mc":[{"id":"1.195453616","rc":[{"atb":[[1.92,17.23]],"id":39980001}],"con":true,"img":false}]}
{"op":"mcm","clk":"5348031535","pt":1646212771520,"mc":[{"id":"1.195453616","rc":[{"atl":[[7.4,0]],"id":36036864}],"con":true,"img":false}]}
{"op":"mcm","clk":"5348031538","pt":1646212771614,"mc":[{"id":"1.195453616","rc":[{"atl":[[7,5.89]],"id":36036864}],"con":true,"img":false}]}
{"op":"mcm","clk":"5348031544","pt":1646212771731,"mc":[{"id":"1.195453616","rc":[{"atl":[[7.6,26.51]],"id":36036864}],"con":true,"img":false}]}
{"op":"mcm","clk":"5348031549","pt":1646212771832,"mc":[{"id":"1.195453616","rc":[{"atl":[[7.2,8.06]],"id":36036864}],"con":true,"img":false}]}
{"op":"mcm","clk":"5348031706","pt":1646212775125,"mc":[{"id":"1.195453616","rc":[{"atb":[[1.66,30.3]],"id":37456368}],"con":true,"img":false}]}
{"op":"mcm","clk":"5348031713","pt":1646212775229,"mc":[{"id":"1.195453616","rc":[{"atb":[[1.81,53.82]],"id":37456368}],"con":true,"img":false}]}
{"op":"mcm","clk":"5348031756","pt":1646212776051,"mc":[{"id":"1.195453616","rc":[{"atb":[[2.4,0]],"id":26503913}],"con":true,"img":false}]}
{"op":"mcm","clk":"5348031764","pt":1646212776148,"mc":[{"id":"1.195453616","rc":[{"atb":[[2.72,26.91]],"id":26503913}],"con":true,"img":false}]}
{"op":"mcm","clk":"5348031864","pt":1646212778010,"mc":[{"id":"1.195453616","rc":[{"atb":[[2.76,4.73]],"id":26503913}],"con":true,"img":false}]}
{"op":"mcm","clk":"5348031973","pt":1646212779517,"mc":[{"id":"1.195453616","rc":[{"atl":[[7,0]],"id":36036864}],"con":true,"img":false}]}
{"op":"mcm","clk":"5348031979","pt":1646212779618,"mc":[{"id":"1.195453616","rc":[{"atl":[[7.4,5.89]],"id":36036864}],"con":true,"img":false}]}
{"op":"mcm","clk":"5348032057","pt":1646212780909,"mc":[{"id":"1.195453616","rc":[{"atl":[[7.2,16.12],[7.6,11.36]],"id":36036864}],"con":true,"img":false}]}
{"op":"mcm","clk":"5348032198","pt":1646212783660,"mc":[{"id":"1.195453616","rc":[{"atb":[[2.78,5.89]],"id":26503913}],"con":true,"img":false}]}
{"op":"mcm","clk":"5348032521","pt":1646212789151,"mc":[{"id":"1.195453616","rc":[{"atb":[[1.79,0]],"id":39980001}],"con":true,"img":false}]}
{"op":"mcm","clk":"5348032525","pt":1646212789249,"mc":[{"id":"1.195453616","rc":[{"atb":[[1.86,66.69]],"id":39980001}],"con":true,"img":false}]}
{"op":"mcm","clk":"5348032541","pt":1646212789567,"mc":[{"id":"1.195453616","rc":[{"atl":[[5.1,0],[4.4,29.69]],"id":39980001}],"con":true,"img":false}]}
{"op":"mcm","clk":"5348032594","pt":1646212790544,"mc":[{"id":"1.195453616","rc":[{"atb":[[3.7,36.96]],"id":39784359}],"con":true,"img":false}]}
{"op":"mcm","clk":"5348032598","pt":1646212790644,"mc":[{"id":"1.195453616","rc":[{"atb":[[4,20.95]],"id":39784359}],"con":true,"img":false}]}
{"op":"mcm","clk":"5348032757","pt":1646212793554,"mc":[{"id":"1.195453616","rc":[{"atb":[[1.63,0]],"id":37456368}],"con":true,"img":false}]}
{"op":"mcm","clk":"5348032766","pt":1646212793660,"mc":[{"id":"1.195453616","rc":[{"atb":[[1.65,93.48]],"id":37456368}],"con":true,"img":false}]}
{"op":"mcm","clk":"5348033264","pt":1646212803042,"mc":[{"id":"1.195453616","rc":[{"spn":3.79,"spf":"NaN","id":26503913},{"spn":2.51,"spf":"NaN","id":37456368},{"atl":[[7.4,0]],"id":36036864},{"spn":2.87,"spf":"NaN","id":39980001}],"con":true,"img":false}]}
{"op":"mcm","clk":"5348033270","pt":1646212803154,"mc":[{"id":"1.195453616","rc":[{"atl":[[7.2,8.06],[7.6,26.51],[7,5.89]],"id":36036864}],"con":true,"img":false}]}
{"op":"mcm","clk":"5348033574","pt":1646212809572,"mc":[{"id":"1.195453616","rc":[{"atb":[[1.34,0]],"id":28755739}],"con":true,"img":false}]}
{"op":"mcm","clk":"5348033582","pt":1646212809678,"mc":[{"id":"1.195453616","rc":[{"atb":[[1.36,84.77]],"id":28755739}],"con":true,"img":false}]}
{"op":"mcm","clk":"5348033615","pt":1646212810604,"mc":[{"id":"1.195453616","rc":[{"atl":[[7,0]],"id":36036864}],"con":true,"img":false}]}
{"op":"mcm","clk":"5348033622","pt":1646212810709,"mc":[{"id":"1.195453616","rc":[{"atl":[[7.4,5.89]],"id":36036864}],"con":true,"img":false}]}
{"op":"mcm","clk":"5348033627","pt":1646212810770,"mc":[{"id":"1.195453616","rc":[{"atb":[[1.38,17.29]],"id":28755739}],"con":true,"img":false}]}
{"op":"mcm","clk":"5348033684","pt":1646212812100,"mc":[{"id":"1.195453616","rc":[{"atl":[[7.2,16.12]],"id":36036864},{"atb":[[4.3,0]],"id":39784359}],"con":true,"img":false}]}
{"op":"mcm","clk":"5348033690","pt":1646212812205,"mc":[{"id":"1.195453616","rc":[{"atl":[[7.6,11.36]],"id":36036864},{"atb":[[4,33.77]],"id":39784359}],"con":true,"img":false}]}
{"op":"mcm","clk":"5348033874","pt":1646212815999,"mc":[{"id":"1.195453616","rc":[{"atb":[[4.4,0]],"id":39784359}],"con":true,"img":false}]}
{"op":"mcm","clk":"5348033882","pt":1646212816203,"mc":[{"id":"1.195453616","rc":[{"atb":[[4.1,1.66]],"id":39784359}],"con":true,"img":false}]}
{"op":"mcm","clk":"5348033937","pt":1646212817088,"mc":[{"id":"1.195453616","rc":[{"atb":[[1.39,19.27]],"id":28755739}],"con":true,"img":false}]}
{"op":"mcm","clk":"5348034206","pt":1646212821526,"mc":[{"id":"1.195453616","rc":[{"atb":[[1.38,0]],"id":28755739}],"con":true,"img":false}]}
{"op":"mcm","clk":"5348034502","pt":1646212825914,"mc":[{"id":"1.195453616","rc":[{"atb":[[1.4,15]],"id":28755739}],"con":true,"img":false}]}
{"op":"mcm","clk":"5348035010","pt":1646212833094,"mc":[{"id":"1.195453616","rc":[{"atb":[[1.37,0]],"id":28755739}],"con":true,"img":false}]}
{"op":"mcm","clk":"5348035076","pt":1646212834130,"mc":[{"id":"1.195453616","rc":[{"atl":[[7.4,0]],"id":36036864}],"con":true,"img":false}]}
{"op":"mcm","clk":"5348035078","pt":1646212834232,"mc":[{"id":"1.195453616","rc":[{"atl":[[7,5.89]],"id":36036864}],"con":true,"img":false}]}
{"op":"mcm","clk":"5348035086","pt":1646212834335,"mc":[{"id":"1.195453616","rc":[{"atl":[[7.2,8.06],[7.6,26.51]],"id":36036864}],"con":true,"img":false}]}
{"op":"mcm","clk":"5348035184","pt":1646212836131,"mc":[{"id":"1.195453616","rc":[{"atb":[[1.4,0]],"id":28755739}],"con":true,"img":false}]}
{"op":"mcm","clk":"5348035429","pt":1646212840615,"mc":[{"id":"1.195453616","rc":[{"atb":[[1.4,15]],"id":28755739}],"con":true,"img":false}]}
{"op":"mcm","clk":"5348035438","pt":1646212840727,"mc":[{"id":"1.195453616","rc":[{"atl":[[1.89,0],[1.88,22.73]],"id":28755739}],"con":true,"img":false}]}
{"op":"mcm","clk":"5348035454","pt":1646212841134,"mc":[{"id":"1.195453616","rc":[{"atl":[[3.1,10.97],[3.15,0]],"id":37456368}],"con":true,"img":false}]}
{"op":"mcm","clk":"5348035496","pt":1646212842019,"mc":[{"id":"1.195453616","rc":[{"atl":[[4.8,0],[4.6,5.56]],"id":26503913},{"atb":[[1.72,27.78]],"id":37456368},{"atl":[[7,0]],"id":36036864}],"con":true,"img":false}]}
{"op":"mcm","clk":"5348035501","pt":1646212842121,"mc":[{"id":"1.195453616","rc":[{"atb":[[1.66,0]],"id":37456368},{"atl":[[7.4,5.89]],"id":36036864}],"con":true,"img":false}]}
{"op":"mcm","clk":"5348035511","pt":1646212842320,"mc":[{"id":"1.195453616","rc":[{"atb":[[1.93,13.74],[1.91,0]],"id":37456368}],"con":true,"img":false}]}
{"op":"mcm","clk":"5348035540","pt":1646212842733,"mc":[{"id":"1.195453616","rc":[{"atl":[[3.1,8.87]],"id":37456368}],"con":true,"img":false}]}
{"op":"mcm","clk":"5348035555","pt":1646212842939,"mc":[{"id":"1.195453616","rc":[{"atl":[[7.2,16.12],[7.6,11.36]],"id":36036864}],"con":true,"img":false}]}
{"op":"mcm","clk":"5348035569","pt":1646212843106,"mc":[{"id":"1.195453616","rc":[{"atb":[[1.96,2.16],[1.92,0]],"id":37456368}],"con":true,"img":false}]}
{"op":"mcm","clk":"5348035631","pt":1646212843830,"mc":[{"id":"1.195453616","rc":[{"atl":[[1000,2.52]],"id":37456368}],"con":true,"img":false}]}
{"op":"mcm","clk":"5348035650","pt":1646212844141,"mc":[{"id":"1.195453616","rc":[{"atl":[[1000,2.1]],"id":37456368}],"con":true,"img":false}]}
{"op":"mcm","clk":"5348035657","pt":1646212844243,"mc":[{"id":"1.195453616","rc":[{"atl":[[1000,0]],"id":37456368}],"con":true,"img":false}]}
{"op":"mcm","clk":"5348035666","pt":1646212844349,"mc":[{"id":"1.195453616","rc":[{"atl":[[3.05,2.1]],"id":37456368}],"con":true,"img":false}]}
{"op":"mcm","clk":"5348035688","pt":1646212844645,"mc":[{"id":"1.195453616","rc":[{"atl":[[1.89,22.47],[1.88,0]],"id":28755739},{"atb":[[1.93,0]],"id":37456368},{"atl":[[3.2,31.17],[3.1,0]],"id":37456368}],"con":true,"img":false}]}
{"op":"mcm","clk":"5348035724","pt":1646212845113,"mc":[{"id":"1.195453616","rc":[{"atl":[[4.8,5.26],[4.6,0]],"id":26503913}],"con":true,"img":false}]}
{"op":"mcm","clk":"5348035731","pt":1646212845217,"mc":[{"id":"1.195453616","rc":[{"atl":[[5.6,0],[5.5,22.22]],"id":26503913},{"atb":[[1.86,0]],"id":37456368}],"con":true,"img":false}]}
{"op":"mcm","clk":"5348035750","pt":1646212845532,"mc":[{"id":"1.195453616","rc":[{"atb":[[1.39,40.65]],"id":28755739}],"con":true,"img":false}]}
{"op":"mcm","clk":"5348035761","pt":1646212845735,"mc":[{"id":"1.195453616","rc":[{"atb":[[1.33,60.6],[1.35,0]],"id":28755739},{"atl":[[1.65,2]],"id":28755739}],"con":true,"img":false}]}
{"op":"mcm","clk":"5348035773","pt":1646212845951,"mc":[{"id":"1.195453616","rc":[{"atl":[[1.62,2],[1.65,0]],"id":28755739}],"con":true,"img":false}]}
{"op":"mcm","clk":"5348035812","pt":1646212846516,"mc":[{"id":"1.195453616","rc":[{"atb":[[1.26,0],[1.38,84.78]],"id":28755739},{"atl":[[1.65,4]],"id":28755739},{"atb":[[1.62,120.97],[1.78,25.64],[1.72,0],[1.77,107.66]],"id":37456368},{"atb":[[3.6,0],[3.8,35.71],[4.4,5.88],[3.75,0]],"id":39784359},{"atl":[[3.95,26.4],[6,0],[3.4,8.33]],"id":39980001}],"con":true,"img":false}]}
{"op":"mcm","clk":"5348035828","pt":1646212846726,"mc":[{"id":"1.195453616","rc":[{"atb":[[1.35,57.14],[1.5,4]],"id":28755739},{"atl":[[1.89,0],[2.04,19.23],[1.62,0],[1.93,0],[1.95,0],[1.91,0],[1.65,0]],"id":28755739},{"atb":[[1.78,0],[1.75,159.75]],"id":37456368}],"con":true,"img":false}]}
{"op":"mcm","clk":"5348035841","pt":1646212846933,"mc":[{"id":"1.195453616","rc":[{"atb":[[1.51,2]],"id":28755739},{"atl":[[2.04,0]],"id":28755739}],"con":true,"img":false}]}
{"op":"mcm","clk":"5348035856","pt":1646212847140,"mc":[{"id":"1.195453616","rc":[{"atb":[[1.52,2]],"id":28755739},{"atl":[[2.04,19.23],[2.12,66.96],[2.16,107.76],[2.08,46.3]],"id":28755739}],"con":true,"img":false}]}
{"op":"mcm","clk":"5348035858","pt":1646212847235,"mc":[{"id":"1.195453616","rc":[{"atb":[[1.4,0]],"id":28755739}],"con":true,"img":false}]}
{"op":"mcm","clk":"5348035884","pt":1646212847561,"mc":[{"id":"1.195453616","rc":[{"atb":[[1.53,4]],"id":28755739},{"atb":[[1.95,13.6]],"id":37456368},{"atb":[[1.86,0]],"id":39980001}],"con":true,"img":false}]}
{"op":"mcm","clk":"5348035891","pt":1646212847606,"mc":[{"id":"1.195453616","rc":[{"atl":[[2.04,0]],"id":28755739},{"atb":[[1.81,66.69]],"id":39980001}],"con":true,"img":false}]}
{"op":"mcm","clk":"5348035966","pt":1646212848940,"mc":[{"id":"1.195453616","rc":[{"atl":[[4.8,0],[4.6,5.56]],"id":26503913},{"atb":[[1.58,4],[1.51,0],[1.53,0],[1.5,0],[1.52,0]],"id":28755739},{"atl":[[2.04,19.23]],"id":28755739}],"con":true,"img":false}]}
{"op":"mcm","clk":"5348036022","pt":1646212849827,"mc":[{"id":"1.195453616","rc":[{"atb":[[1.89,0]],"id":39980001}],"con":true,"img":false}]}
{"op":"mcm","clk":"5348036027","pt":1646212849931,"mc":[{"id":"1.195453616","rc":[{"atb":[[1.82,29.97]],"id":37456368}],"con":true,"img":false}]}
{"op":"mcm","clk":"5348036036","pt":1646212850139,"mc":[{"id":"1.195453616","rc":[{"atb":[[1.39,21.37]],"id":28755739}],"con":true,"img":false}]}
{"op":"mcm","clk":"5348036102","pt":1646212851631,"mc":[{"id":"1.195453616","rc":[{"atl":[[3.05,0]],"id":37456368}],"con":true,"img":false}]}
{"op":"mcm","clk":"5348036124","pt":1646212852041,"mc":[{"id":"1.195453616","rc":[{"atb":[[4.1,0]],"id":39784359}],"con":true,"img":false}]}
{"op":"mcm","clk":"5348036128","pt":1646212852136,"mc":[{"id":"1.195453616","rc":[{"atb":[[1.4,10.39]],"id":28755739},{"atb":[[4.5,1.66]],"id":39784359}],"con":true,"img":false}]}
{"op":"mcm","clk":"5348036162","pt":1646212852756,"mc":[{"id":"1.195453616","rc":[{"atb":[[1.59,4]],"id":28755739},{"atl":[[2.04,0]],"id":28755739},{"atl":[[1000,2.52]],"id":37456368},{"atl":[[10.5,18.44],[11,0]],"id":39784359}],"con":true,"img":false}]}
{"op":"mcm","clk":"5348036173","pt":1646212852917,"mc":[{"id":"1.195453616","rc":[{"atl":[[1000,2.1]],"id":37456368}],"con":true,"img":false}]}
{"op":"mcm","clk":"5348036181","pt":1646212853026,"mc":[{"id":"1.195453616","rc":[{"atl":[[2.04,19.23]],"id":28755739}],"con":true,"img":false}]}
{"op":"mcm","clk":"5348036185","pt":1646212853128,"mc":[{"id":"1.195453616","rc":[{"atb":[[1.6,4]],"id":28755739}],"con":true,"img":false}]}
{"op":"mcm","clk":"5348036191","pt":1646212853234,"mc":[{"id":"1.195453616","rc":[{"atl":[[1000,0]],"id":37456368}],"con":true,"img":false}]}
{"op":"mcm","clk":"5348036198","pt":1646212853336,"mc":[{"id":"1.195453616","rc":[{"atl":[[3.15,2.1]],"id":37456368}],"con":true,"img":false}]}
{"op":"mcm","clk":"5348036239","pt":1646212854158,"mc":[{"id":"1.195453616","rc":[{"atl":[[1.9,0]],"id":28755739}],"con":true,"img":false}]}
{"op":"mcm","clk":"5348036243","pt":1646212854216,"mc":[{"id":"1.195453616","rc":[{"atl":[[2.06,43.59]],"id":28755739}],"con":true,"img":false}]}
{"op":"mcm","clk":"5348036273","pt":1646212854632,"mc":[{"id":"1.195453616","rc":[{"atb":[[1.82,0]],"id":37456368},{"atb":[[1.89,18.6]],"id":39980001}],"con":true,"img":false}]}
{"op":"mcm","clk":"5348036287","pt":1646212855041,"mc":[{"id":"1.195453616","rc":[{"atl":[[3.85,26.4],[3.95,0]],"id":39980001}],"con":true,"img":false}]}
{"op":"mcm","clk":"5348036325","pt":1646212855860,"mc":[{"id":"1.195453616","rc":[{"atb":[[1.41,18.33]],"id":28755739}],"con":true,"img":false}]}
{"op":"mcm","clk":"5348036341","pt":1646212856335,"mc":[{"id":"1.195453616","rc":[{"atb":[[4.5,0]],"id":39784359},{"trd":[[4.5,3.33]],"ltp":4.5,"tv":3.33,"id":39784359}],"con":true,"img":false}]}
{"op":"mcm","clk":"5348036346","pt":1646212856436,"mc":[{"id":"1.195453616","rc":[{"atl":[[3.5,20]],"id":39980001}],"con":true,"img":false}]}
{"op":"mcm","clk":"5348036350","pt":1646212856535,"mc":[{"id":"1.195453616","rc":[{"atb":[[4.2,15.62]],"id":39784359}],"con":true,"img":false}]}
{"op":"mcm","clk":"5348036355","pt":1646212856745,"mc":[{"id":"1.195453616","rc":[{"atb":[[1.73,68.49]],"id":37456368},{"atl":[[3.3,20.24]],"id":37456368}],"con":true,"img":false}]}
{"op":"mcm","clk":"5348036385","pt":1646212857365,"mc":[{"id":"1.195453616","rc":[{"atb":[[1.4,0]],"id":28755739},{"atb":[[1.86,26.8]],"id":37456368}],"con":true,"img":false}]}
{"op":"mcm","clk":"5348036399","pt":1646212857560,"mc":[{"id":"1.195453616","rc":[{"atb":[[1.81,0]],"id":39980001}],"con":true,"img":false}]}
{"op":"mcm","clk":"5348036405","pt":1646212857666,"mc":[{"id":"1.195453616","rc":[{"atb":[[1.77,66.69]],"id":39980001}],"con":true,"img":false}]}
{"op":"mcm","clk":"5348036420","pt":1646212857935,"mc":[{"id":"1.195453616","rc":[{"atb":[[4.5,1.66]],"id":39784359}],"con":true,"img":false}]}
{"op":"mcm","clk":"5348036491","pt":1646212858961,"mc":[{"id":"1.195453616","rc":[{"atl":[[4.8,13.16]],"id":26503913}],"con":true,"img":false}]}
{"op":"mcm","clk":"5348036522","pt":1646212859472,"mc":[{"id":"1.195453616","rc":[{"atb":[[1.89,0]],"id":39980001}],"con":true,"img":false}]}
{"op":"mcm","clk":"5348036601","pt":1646212860951,"mc":[{"id":"1.195453616","rc":[{"atb":[[2.72,54.49],[2.78,19.68]],"id":26503913},{"atl":[[4.6,19.35],[5,40.08],[5.4,0]],"id":26503913},{"atb":[[1.61,2]],"id":28755739},{"atl":[[2.04,17.42],[2.08,81.14]],"id":28755739},{"atb":[[1.64,0],[1.6,0],[1.89,64.95],[1.62,0],[1.96,25.72],[2.1,5],[2.02,10],[1.97,12],[2.18,2.5]],"id":37456368},{"atl":[[3.45,0],[3.35,0],[3.15,25.66],[3.25,47.13]],"id":37456368},{"atb":[[3.55,74.8],[3.65,14.87]],"id":36036864},{"atl":[[7.4,36.37],[6.8,12.35]],"id":36036864},{"atb":[[4,71.02],[3.45,40.74],[3.55,0],[4.4,15.64],[3.65,0]],"id":39784359},{"atl":[[9.6,11.8],[11,5],[11.5,26.75]],"id":39784359},{"atb":[[2,10],[2.08,5],[1.99,33.15],[1.88,96.33],[2.16,2.5]],"id":39980001},{"atl":[[7.2,0],[3.4,31.15],[3.75,58.83]],"id":39980001}],"con":true,"img":false}]}
{"op":"mcm","clk":"5348036622","pt":1646212861158,"mc":[{"id":"1.195453616","rc":[{"atl":[[7.2,8.06],[6.8,28.47]],"id":36036864},{"atb":[[1.99,24.98],[2.06,17.23]],"id":39980001}],"con":true,"img":false}]}
{"op":"mcm","clk":"5348036653","pt":1646212861570,"mc":[{"id":"1.195453616","rc":[{"atl":[[11,20.56]],"id":26503913},{"atb":[[1.26,99.04]],"id":28755739},{"atl":[[2.42,0]],"id":28755739},{"atb":[[1.54,77.51]],"id":37456368},{"atl":[[5.3,35.45]],"id":37456368},{"atl":[[16,13.91],[7.4,30.48]],"id":36036864},{"atb":[[4,50.07]],"id":39784359},{"atl":[[25,10.43]],"id":39784359},{"atb":[[1.88,45.64],[1.75,174.39]],"id":39980001},{"atl":[[5.2,34.17]],"id":39980001}],"con":true,"img":false}]}
{"op":"mcm","clk":"5348036659","pt":1646212861667,"mc":[{"id":"1.195453616","rc":[{"atl":[[7.2,0]],"id":26503913},{"atb":[[1.31,241.94]],"id":28755739},{"atl":[[2.72,46.95]],"id":28755739},{"atb":[[1.65,0]],"id":37456368},{"atl":[[4.2,0]],"id":37456368},{"atl":[[10,0],[7,5.89]],"id":36036864},{"atb":[[3.85,20.95]],"id":39784359},{"atl":[[15.5,0]],"id":39784359},{"atb":[[1.86,50.69],[1.77,0]],"id":39980001},{"atl":[[4.4,12.82]],"id":39980001}],"con":true,"img":false}]}
{"op":"mcm","clk":"5348036671","pt":1646212861871,"mc":[{"id":"1.195453616","rc":[{"atb":[[1.89,56.49]],"id":37456368}],"con":true,"img":false}]}
{"op":"mcm","clk":"5348036686","pt":1646212862034,"mc":[{"id":"1.195453616","rc":[{"atb":[[1.61,4.79]],"id":28755739}],"con":true,"img":false}]}
{"op":"mcm","clk":"5348036697","pt":1646212862139,"mc":[{"id":"1.195453616","rc":[{"atb":[[1.96,23.56],[2.08,2.16]],"id":37456368},{"atb":[[2.12,2.16],[1.99,22.82]],"id":39980001}],"con":true,"img":false}]}
{"op":"mcm","clk":"5348036702","pt":1646212862245,"mc":[{"id":"1.195453616","rc":[{"atl":[[4.5,1.42]],"id":26503913},{"atl":[[2.02,1.27]],"id":28755739},{"atl":[[3.1,1.35]],"id":37456368},{"atl":[[6.6,1.4]],"id":36036864},{"atl":[[9.4,1.4]],"id":39784359},{"atl":[[3.35,1.3]],"id":39980001}],"con":true,"img":false}]}
{"op":"mcm","clk":"5348036744","pt":1646212862968,"mc":[{"id":"1.195453616","rc":[{"atl":[[3.15,23.56]],"id":37456368}],"con":true,"img":false}]}
{"op":"mcm","clk":"5348036752","pt":1646212863070,"mc":[{"id":"1.195453616","rc":[{"spn":3.64,"spf":"NaN","id":26503913},{"atb":[[1.33,151.52]],"id":28755739},{"atl":[[2.04,36.65]],"id":28755739},{"spn":1.81,"spf":"NaN","id":28755739},{"spn":2.64,"spf":"NaN","id":37456368},{"spn":4.42,"spf":1.0,"id":39784359},{"atl":[[4.4,0]],"id":39980001},{"spn":2.75,"spf":"NaN","id":39980001}],"con":true,"img":false}]}
{"op":"mcm","clk":"5348036762","pt":1646212863173,"mc":[{"id":"1.195453616","rc":[{"atl":[[1000,2.52]],"id":37456368},{"atl":[[3.8,12.82]],"id":39980001}],"con":true,"img":false}]}
{"op":"mcm","clk":"5348036769","pt":1646212863270,"mc":[{"id":"1.195453616","rc":[{"atl":[[1000,2.1]],"id":37456368}],"con":true,"img":false}]}
{"op":"mcm","clk":"5348036781","pt":1646212863440,"mc":[{"id":"1.195453616","rc":[{"atl":[[1000,0]],"id":37456368}],"con":true,"img":false}]}
{"op":"mcm","clk":"5348036784","pt":1646212863532,"mc":[{"id":"1.195453616","rc":[{"atl":[[3.05,2.1]],"id":37456368}],"con":true,"img":false}]}
{"op":"mcm","clk":"5348036807","pt":1646212863953,"mc":[{"id":"1.195453616","rc":[{"atb":[[2.2,1.66]],"id":37456368}],"con":true,"img":false}]}
{"op":"mcm","clk":"5348036811","pt":1646212864055,"mc":[{"id":"1.195453616","rc":[{"atl":[[3.1,0]],"id":37456368}],"con":true,"img":false}]}
{"op":"mcm","clk":"5348036815","pt":1646212864151,"mc":[{"id":"1.195453616","rc":[{"atl":[[3.05,3.45]],"id":37456368}],"con":true,"img":false}]}
{"op":"mcm","clk":"5348036845","pt":1646212864569,"mc":[{"id":"1.195453616","rc":[{"atb":[[1.86,0]],"id":37456368}],"con":true,"img":false}]}
{"op":"mcm","clk":"5348036852","pt":1646212864674,"mc":[{"id":"1.195453616","rc":[{"atb":[[2.1,2.75]],"id":39980001}],"con":true,"img":false}]}
{"op":"mcm","clk":"5348036910","pt":1646212865553,"mc":[{"id":"1.195453616","rc":[{"atl":[[5.5,0],[5.2,41.67]],"id":26503913},{"atl":[[2.04,80.25],[2.1,0]],"id":28755739},{"atl":[[3.45,40.82],[3.55,0]],"id":37456368},{"atl":[[10.5,9.22],[9.8,13.63]],"id":39784359},{"atl":[[3.85,0],[3.7,37.04]],"id":39980001}],"con":true,"img":false}]}
{"op":"mcm","clk":"5348036915","pt":1646212865650,"mc":[{"id":"1.195453616","rc":[{"atl":[[2.04,61.02]],"id":28755739}],"con":true,"img":false}]}
{"op":"mcm","clk":"5348036966","pt":1646212866470,"mc":[{"id":"1.195453616","rc":[{"atb":[[4,75.07]],"id":39784359},{"atl":[[3.6,28.85]],"id":39980001}],"con":true,"img":false}]}
{"op":"mcm","clk":"5348036989","pt":1646212866742,"mc":[{"id":"1.195453616","rc":[{"atb":[[1.95,0],[1.71,105.63]],"id":37456368},{"atl":[[3.4,29.1]],"id":37456368}],"con":true,"img":false}]}
{"op":"mcm","clk":"5348037005","pt":1646212867042,"mc":[{"id":"1.195453616","rc":[{"atl":[[2.04,80.25]],"id":28755739},{"atb":[[2.04,6.24]],"id":37456368},{"atl":[[6.8,0]],"id":39980001}],"con":true,"img":false}]}
{"op":"mcm","clk":"5348037053","pt":1646212868124,"mc":[{"id":"1.195453616","rc":[{"atb":[[1.93,8.08]],"id":37456368}],"con":true,"img":false}]}
{"op":"mcm","clk":"5348037071","pt":1646212868545,"mc":[{"id":"1.195453616","rc":[{"atl":[[7,0]],"id":36036864}],"con":true,"img":false}]}
{"op":"mcm","clk":"5348037080","pt":1646212868641,"mc":[{"id":"1.195453616","rc":[{"atl":[[7.2,13.95]],"id":36036864}],"con":true,"img":false}]}
{"op":"mcm","clk":"5348037096","pt":1646212868964,"mc":[{"id":"1.195453616","rc":[{"atl":[[5,46.33]],"id":26503913}],"con":true,"img":false}]}
{"op":"mcm","clk":"5348037137","pt":1646212869578,"mc":[{"id":"1.195453616","rc":[{"atb":[[1.39,0]],"id":28755739}],"con":true,"img":false}]}
{"op":"mcm","clk":"5348037221","pt":1646212870866,"mc":[{"id":"1.195453616","rc":[{"atl":[[3.05,1.35]],"id":37456368}],"con":true,"img":false}]}
{"op":"mcm","clk":"5348037243","pt":1646212871169,"mc":[{"id":"1.195453616","rc":[{"atl":[[1000,2.52]],"id":37456368}],"con":true,"img":false}]}
{"op":"mcm","clk":"5348037251","pt":1646212871375,"mc":[{"id":"1.195453616","rc":[{"atl":[[3.05,0],[1000,2.1]],"id":37456368}],"con":true,"img":false}]}
{"op":"mcm","clk":"5348037259","pt":1646212871481,"mc":[{"id":"1.195453616","rc":[{"atl":[[3.1,1.35]],"id":37456368}],"con":true,"img":false}]}
{"op":"mcm","clk":"5348037267","pt":1646212871588,"mc":[{"id":"1.195453616","rc":[{"atl":[[1000,0]],"id":37456368}],"con":true,"img":false}]}
{"op":"mcm","clk":"5348037275","pt":1646212871684,"mc":[{"id":"1.195453616","rc":[{"atl":[[3,2.1]],"id":37456368}],"con":true,"img":false}]}
{"op":"mcm","clk":"5348037290","pt":1646212871853,"mc":[{"id":"1.195453616","rc":[{"atl":[[3.1,0]],"id":37456368}],"con":true,"img":false}]}
{"op":"mcm","clk":"5348037301","pt":1646212871959,"mc":[{"id":"1.195453616","rc":[{"atl":[[2.04,61.02]],"id":28755739},{"atl":[[3,3.45]],"id":37456368}],"con":true,"img":false}]}
{"op":"mcm","clk":"5348037383","pt":1646212873086,"mc":[{"id":"1.195453616","rc":[{"atl":[[2.04,80.25]],"id":28755739}],"con":true,"img":false}]}
{"op":"mcm","clk":"5348037406","pt":1646212873490,"mc":[{"id":"1.195453616","rc":[{"atb":[[2.04,0]],"id":37456368}],"con":true,"img":false}]}
{"op":"mcm","clk":"5348037557","pt":1646212876492,"mc":[{"id":"1.195453616","rc":[{"atb":[[4,62.25],[3.9,43.1]],"id":39784359}],"con":true,"img":false}]}
{"op":"mcm","clk":"5348037562","pt":1646212876584,"mc":[{"id":"1.195453616","rc":[{"atb":[[4.5,14.49]],"id":39784359},{"atl":[[3.7,83.34]],"id":39980001}],"con":true,"img":false}]}
{"op":"mcm","clk":"5348037569","pt":1646212876751,"mc":[{"id":"1.195453616","rc":[{"atb":[[1.69,181.16]],"id":37456368},{"atl":[[3.5,46.56]],"id":37456368}],"con":true,"img":false}]}
{"op":"mcm","clk":"5348037582","pt":1646212876965,"mc":[{"id":"1.195453616","rc":[{"atb":[[4.5,0]],"id":39784359},{"trd":[[4.5,32.31]],"ltp":4.5,"tv":32.31,"id":39784359}],"con":true,"img":false}]}
{"op":"mcm","clk":"5348037608","pt":1646212877577,"mc":[{"id":"1.195453616","rc":[{"atb":[[3.85,0],[2.98,40.07]],"id":39784359},{"atl":[[10.5,5.25],[9.4,4.88]],"id":39784359},{"atb":[[1.89,31.51],[1.86,0]],"id":39980001}],"con":true,"img":false}]}
{"op":"mcm","clk":"5348037630","pt":1646212878087,"mc":[{"id":"1.195453616","rc":[{"atb":[[3.6,0],[3.7,12.05]],"id":36036864}],"con":true,"img":false}]}
{"op":"mcm","clk":"5348037646","pt":1646212878457,"mc":[{"id":"1.195453616","rc":[{"atb":[[1.89,9.36],[2.22,4.23],[2.04,6.24],[2.08,15.92]],"id":37456368},{"atl":[[3,7.7]],"id":37456368},{"atb":[[3.7,33.67]],"id":36036864},{"atl":[[11.5,7.14],[9.8,37.92]],"id":39784359},{"atl":[[3.8,0],[3.75,13.19]],"id":39980001}],"con":true,"img":false}]}
{"op":"mcm","clk":"5348037651","pt":1646212878548,"mc":[{"id":"1.195453616","rc":[{"atb":[[1.97,0]],"id":37456368},{"atl":[[3.2,44.93],[3.15,0],[3.25,0]],"id":37456368},{"atb":[[3.65,5.97]],"id":36036864},{"atl":[[9.2,9.76]],"id":39784359},{"atb":[[2.1,36.87],[1.88,0],[2.16,6.44]],"id":39980001},{"atl":[[3.6,62.97]],"id":39980001}],"con":true,"img":false}]}
{"op":"mcm","clk":"5348037661","pt":1646212878763,"mc":[{"id":"1.195453616","rc":[{"atl":[[3.2,31.17]],"id":37456368},{"atl":[[9.6,2.49]],"id":39784359},{"atb":[[1.99,0]],"id":39980001}],"con":true,"img":false}]}
{"op":"mcm","clk":"5348037663","pt":1646212878856,"mc":[{"id":"1.195453616","rc":[{"atl":[[1000,2.52]],"id":37456368}],"con":true,"img":false}]}
{"op":"mcm","clk":"5348037669","pt":1646212878961,"mc":[{"id":"1.195453616","rc":[{"atl":[[5.2,53.57]],"id":26503913}],"con":true,"img":false}]}
{"op":"mcm","clk":"5348037678","pt":1646212879074,"mc":[{"id":"1.195453616","rc":[{"atl":[[1000,2.1]],"id":37456368},{"atl":[[9.4,3.47]],"id":39784359}],"con":true,"img":false}]}
{"op":"mcm","clk":"5348037679","pt":1646212879166,"mc":[{"id":"1.195453616","rc":[{"atb":[[2.08,13.76],[2.16,2.16]],"id":37456368},{"atl":[[9,1.4]],"id":39784359}],"con":true,"img":false}]}
{"op":"mcm","clk":"5348037689","pt":1646212879282,"mc":[{"id":"1.195453616","rc":[{"atl":[[1000,0]],"id":37456368}],"con":true,"img":false}]}
{"op":"mcm","clk":"5348037695","pt":1646212879380,"mc":[{"id":"1.195453616","rc":[{"atb":[[2.08,0]],"id":37456368},{"atl":[[2.98,2.1]],"id":37456368}],"con":true,"img":false}]}
{"op":"mcm","clk":"5348037706","pt":1646212879587,"mc":[{"id":"1.195453616","rc":[{"atl":[[5.2,0]],"id":39980001}],"con":true,"img":false}]}
{"op":"mcm","clk":"5348037710","pt":1646212879679,"mc":[{"id":"1.195453616","rc":[{"atl":[[3,6.35]],"id":37456368},{"atl":[[5.9,34.17]],"id":39980001}],"con":true,"img":false}]}
{"op":"mcm","clk":"5348037721","pt":1646212879791,"mc":[{"id":"1.195453616","rc":[{"atl":[[2.98,3.45]],"id":37456368}],"con":true,"img":false}]}
{"op":"mcm","clk":"5348037738","pt":1646212880091,"mc":[{"id":"1.195453616","rc":[{"atl":[[5.1,0]],"id":26503913},{"atl":[[2.06,0]],"id":28755739}],"con":true,"img":false}]}
{"op":"mcm","clk":"5348037745","pt":1646212880253,"mc":[{"id":"1.195453616","rc":[{"atl":[[2.12,174.6]],"id":28755739},{"atb":[[1.93,0]],"id":37456368},{"atb":[[3.65,3.14]],"id":36036864},{"atb":[[1.92,9.06]],"id":39980001}],"con":true,"img":false}]}
{"op":"mcm","clk":"5348037750","pt":1646212880365,"mc":[{"id":"1.195453616","rc":[{"atl":[[2.08,46.3]],"id":28755739}],"con":true,"img":false}]}
{"op":"mcm","clk":"5348037787","pt":1646212881286,"mc":[{"id":"1.195453616","rc":[{"atl":[[2.04,61.02]],"id":28755739},{"atl":[[6.4,0]],"id":39980001}],"con":true,"img":false}]}
{"op":"mcm","clk":"5348037790","pt":1646212881382,"mc":[{"id":"1.195453616","rc":[{"atb":[[2.76,0]],"id":26503913},{"atb":[[3.65,0]],"id":36036864}],"con":true,"img":false}]}
{"op":"mcm","clk":"5348037798","pt":1646212881483,"mc":[{"id":"1.195453616","rc":[{"atb":[[2.6,67.38],[2.68,2.5]],"id":26503913},{"atb":[[3.4,23.33]],"id":36036864}],"con":true,"img":false}]}
{"op":"mcm","clk":"5348037806","pt":1646212881595,"mc":[{"id":"1.195453616","rc":[{"atb":[[2.72,26.91],[2.7,147.69]],"id":26503913},{"atb":[[3.55,39.14],[3.5,76.64]],"id":36036864}],"con":true,"img":false}]}
{"op":"mcm","clk":"5348037811","pt":1646212881699,"mc":[{"id":"1.195453616","rc":[{"atb":[[1.41,38.67]],"id":28755739}],"con":true,"img":false}]}
{"op":"mcm","clk":"5348037831","pt":1646212881999,"mc":[{"id":"1.195453616","rc":[{"atb":[[2.2,0]],"id":37456368}],"con":true,"img":false}]}
{"op":"mcm","clk":"5348037837","pt":1646212882058,"mc":[{"id":"1.195453616","rc":[{"atb":[[2.24,1.66]],"id":37456368}],"con":true,"img":false}]}
{"op":"mcm","clk":"5348037846","pt":1646212882165,"mc":[{"id":"1.195453616","rc":[{"atb":[[2.22,0]],"id":37456368}],"con":true,"img":false}]}
{"op":"mcm","clk":"5348037854","pt":1646212882267,"mc":[{"id":"1.195453616","rc":[{"atb":[[2.26,3.84]],"id":37456368}],"con":true,"img":false}]}
{"op":"mcm","clk":"5348037877","pt":1646212882669,"mc":[{"id":"1.195453616","rc":[{"atb":[[2.72,16.3]],"id":26503913},{"atl":[[3.2,8.47]],"id":37456368},{"atl":[[7.2,8.06]],"id":36036864}],"con":true,"img":false}]}
{"op":"mcm","clk":"5348037895","pt":1646212882885,"mc":[{"id":"1.195453616","rc":[{"atb":[[2.04,0]],"id":37456368}],"con":true,"img":false}]}
{"op":"mcm","clk":"5348037907","pt":1646212883090,"mc":[{"id":"1.195453616","rc":[{"atl":[[2.04,80.25]],"id":28755739}],"con":true,"img":false}]}
{"op":"mcm","clk":"5348037924","pt":1646212883606,"mc":[{"id":"1.195453616","rc":[{"atb":[[2.8,1.5]],"id":26503913},{"atb":[[3.75,1.45]],"id":36036864},{"atb":[[4.5,1.43]],"id":39784359},{"atb":[[2.18,1.36]],"id":39980001}],"con":true,"img":false}]}
{"op":"mcm","clk":"5348038050","pt":1646212885782,"mc":[{"id":"1.195453616","rc":[{"atl":[[2.04,61.02]],"id":28755739}],"con":true,"img":false}]}
{"op":"mcm","clk":"5348038061","pt":1646212885993,"mc":[{"id":"1.195453616","rc":[{"atb":[[2.78,15.45]],"id":26503913},{"atb":[[1.89,17.82]],"id":37456368},{"atb":[[3.8,2.68]],"id":36036864},{"atb":[[2.14,6.59]],"id":39980001}],"con":true,"img":false}]}
{"op":"mcm","clk":"5348038070","pt":1646212886297,"mc":[{"id":"1.195453616","rc":[{"atb":[[3.75,0]],"id":36036864}],"con":true,"img":false}]}
{"op":"mcm","clk":"5348038074","pt":1646212886394,"mc":[{"id":"1.195453616","rc":[{"atb":[[3.8,4.14]],"id":36036864}],"con":true,"img":false}]}
{"op":"mcm","clk":"5348038078","pt":1646212886553,"mc":[{"id":"1.195453616","rc":[{"atl":[[2.04,80.25]],"id":28755739},{"atb":[[2.22,2.02]],"id":37456368}],"con":true,"img":false}]}
{"op":"mcm","clk":"5348038144","pt":1646212887691,"mc":[{"id":"1.195453616","rc":[{"atl":[[2.04,61.02]],"id":28755739}],"con":true,"img":false}]}
{"op":"mcm","clk":"5348038167","pt":1646212888095,"mc":[{"id":"1.195453616","rc":[{"atb":[[2.24,0]],"id":37456368},{"atb":[[3.7,32]],"id":36036864}],"con":true,"img":false}]}
{"op":"mcm","clk":"5348038176","pt":1646212888196,"mc":[{"id":"1.195453616","rc":[{"atb":[[2.12,5.75]],"id":37456368}],"con":true,"img":false}]}
{"op":"mcm","clk":"5348038182","pt":1646212888299,"mc":[{"id":"1.195453616","rc":[{"atb":[[2.26,0],[2.28,1.66]],"id":37456368},{"atb":[[3.85,1.66]],"id":36036864}],"con":true,"img":false}]}
{"op":"mcm","clk":"5348038199","pt":1646212888459,"mc":[{"id":"1.195453616","rc":[{"atb":[[2.3,2.98]],"id":37456368}],"con":true,"img":false}]}
{"op":"mcm","clk":"5348038262","pt":1646212889486,"mc":[{"id":"1.195453616","rc":[{"atb":[[1.89,9.36]],"id":37456368}],"con":true,"img":false}]}
{"op":"mcm","clk":"5348038277","pt":1646212889800,"mc":[{"id":"1.195453616","rc":[{"atb":[[2.12,0],[2.2,2.16]],"id":39980001}],"con":true,"img":false}]}
{"op":"mcm","clk":"5348038328","pt":1646212890895,"mc":[{"id":"1.195453616","rc":[{"atb":[[2.1,34.12]],"id":39980001}],"con":true,"img":false}]}
{"op":"mcm","clk":"5348038370","pt":1646212891568,"mc":[{"id":"1.195453616","rc":[{"atl":[[2.04,80.25]],"id":28755739},{"atl":[[2.52,4]],"id":37456368}],"con":true,"img":false}]}
{"op":"mcm","clk":"5348038411","pt":1646212892286,"mc":[{"id":"1.195453616","rc":[{"atl":[[2.98,1.35]],"id":37456368}],"con":true,"img":false}]}
{"op":"mcm","clk":"5348038460","pt":1646212893211,"mc":[{"id":"1.195453616","rc":[{"atb":[[2.12,0]],"id":37456368}],"con":true,"img":false}]}
{"op":"mcm","clk":"5348038482","pt":1646212893576,"mc":[{"id":"1.195453616","rc":[{"atl":[[9.4,0]],"id":39784359}],"con":true,"img":false}]}
{"op":"mcm","clk":"5348038491","pt":1646212893682,"mc":[{"id":"1.195453616","rc":[{"atl":[[9,4.88]],"id":39784359}],"con":true,"img":false}]}
{"op":"mcm","clk":"5348038503","pt":1646212893892,"mc":[{"id":"1.195453616","rc":[{"atb":[[2.28,0]],"id":37456368}],"con":true,"img":false}]}
{"op":"mcm","clk":"5348038514","pt":1646212894102,"mc":[{"id":"1.195453616","rc":[{"atb":[[2.3,0]],"id":37456368}],"con":true,"img":false}]}
{"op":"mcm","clk":"5348038525","pt":1646212894304,"mc":[{"id":"1.195453616","rc":[{"atb":[[2.24,2.34]],"id":37456368}],"con":true,"img":false}]}
{"op":"mcm","clk":"5348038608","pt":1646212895596,"mc":[{"id":"1.195453616","rc":[{"atl":[[9.6,28.57],[9.8,13.63]],"id":39784359},{"atb":[[2.2,4.64]],"id":39980001}],"con":true,"img":false}]}
{"op":"mcm","clk":"5348038611","pt":1646212895690,"mc":[{"id":"1.195453616","rc":[{"atb":[[3.8,13.29]],"id":36036864}],"con":true,"img":false}]}
{"op":"mcm","clk":"5348038618","pt":1646212895800,"mc":[{"id":"1.195453616","rc":[{"atl":[[3.2,18.22]],"id":37456368},{"atl":[[8.8,10.26]],"id":39784359},{"atb":[[2.14,48.31],[2.1,0],[2.2,11.1]],"id":39980001}],"con":true,"img":false}]}
{"op":"mcm","clk":"5348038622","pt":1646212895898,"mc":[{"id":"1.195453616","rc":[{"atb":[[3.7,10.38]],"id":36036864}],"con":true,"img":false}]}
{"op":"mcm","clk":"5348038625","pt":1646212896002,"mc":[{"id":"1.195453616","rc":[{"atl":[[9.2,0]],"id":39784359},{"atb":[[2.16,2.5]],"id":39980001}],"con":true,"img":false}]}
{"op":"mcm","clk":"5348038632","pt":1646212896110,"mc":[{"id":"1.195453616","rc":[{"atb":[[2.18,0]],"id":39980001}],"con":true,"img":false}]}
{"op":"mcm","clk":"5348038639","pt":1646212896212,"mc":[{"id":"1.195453616","rc":[{"atb":[[2.22,1.36]],"id":39980001}],"con":true,"img":false}]}
{"op":"mcm","clk":"5348038664","pt":1646212896570,"mc":[{"id":"1.195453616","rc":[{"atl":[[9,3.47]],"id":39784359},{"atb":[[1.89,0]],"id":39980001}],"con":true,"img":false}]}
{"op":"mcm","clk":"5348038675","pt":1646212896676,"mc":[{"id":"1.195453616","rc":[{"atl":[[8.6,1.4]],"id":39784359},{"atb":[[1.93,31.51]],"id":39980001}],"con":true,"img":false}]}
{"op":"mcm","clk":"5348038696","pt":1646212896984,"mc":[{"id":"1.195453616","rc":[{"atl":[[2.04,61.02]],"id":28755739},{"atb":[[2.22,0]],"id":37456368},{"atl":[[2.5,4]],"id":37456368}],"con":true,"img":false}]}
{"op":"mcm","clk":"5348038707","pt":1646212897088,"mc":[{"id":"1.195453616","rc":[{"atb":[[2.14,11.28]],"id":37456368}],"con":true,"img":false}]}
{"op":"mcm","clk":"5348038714","pt":1646212897192,"mc":[{"id":"1.195453616","rc":[{"atb":[[2.24,0]],"id":37456368}],"con":true,"img":false}]}
{"op":"mcm","clk":"5348038725","pt":1646212897393,"mc":[{"id":"1.195453616","rc":[{"atb":[[2.2,3.25]],"id":37456368}],"con":true,"img":false}]}
{"op":"mcm","clk":"5348038746","pt":1646212897704,"mc":[{"id":"1.195453616","rc":[{"atb":[[3.8,16.26]],"id":36036864}],"con":true,"img":false}]}
{"op":"mcm","clk":"5348038752","pt":1646212897806,"mc":[{"id":"1.195453616","rc":[{"atb":[[1.92,0]],"id":39980001}],"con":true,"img":false}]}
{"op":"mcm","clk":"5348038775","pt":1646212898271,"mc":[{"id":"1.195453616","rc":[{"atb":[[2.12,3.27]],"id":37456368}],"con":true,"img":false}]}
{"op":"mcm","clk":"5348038781","pt":1646212898373,"mc":[{"id":"1.195453616","rc":[{"atb":[[3.8,13.58]],"id":36036864},{"atb":[[2.14,41.72]],"id":39980001}],"con":true,"img":false}]}
{"op":"mcm","clk":"5348038795","pt":1646212898681,"mc":[{"id":"1.195453616","rc":[{"atb":[[3.55,106.82]],"id":36036864}],"con":true,"img":false}]}
{"op":"mcm","clk":"5348038802","pt":1646212898785,"mc":[{"id":"1.195453616","rc":[{"atb":[[3.5,8]],"id":36036864}],"con":true,"img":false}]}
{"op":"mcm","clk":"5348038840","pt":1646212899509,"mc":[{"id":"1.195453616","rc":[{"atb":[[2.72,0]],"id":26503913}],"con":true,"img":false}]}
{"op":"mcm","clk":"5348038846","pt":1646212899612,"mc":[{"id":"1.195453616","rc":[{"atb":[[2.52,16.3]],"id":26503913}],"con":true,"img":false}]}
{"op":"mcm","clk":"5348038854","pt":1646212899663,"mc":[{"id":"1.195453616","rc":[{"atb":[[2.68,59.12],[2.7,58.71]],"id":26503913}],"con":true,"img":false}]}
{"op":"mcm","clk":"5348038876","pt":1646212900078,"mc":[{"id":"1.195453616","rc":[{"atl":[[2.04,80.25]],"id":28755739},{"atl":[[2.48,2]],"id":37456368}],"con":true,"img":false}]}
{"op":"mcm","clk":"5348038880","pt":1646212900182,"mc":[{"id":"1.195453616","rc":[{"atl":[[3.2,8.47]],"id":37456368}],"con":true,"img":false}]}
{"op":"mcm","clk":"5348038914","pt":1646212901013,"mc":[{"id":"1.195453616","rc":[{"atb":[[2.76,4.27]],"id":26503913},{"atb":[[1.89,17.82]],"id":37456368}],"con":true,"img":false}]}
{"op":"mcm","clk":"5348038978","pt":1646212902408,"mc":[{"id":"1.195453616","rc":[{"atl":[[2.04,61.02]],"id":28755739},{"atl":[[2.46,3]],"id":37456368}],"con":true,"img":false}]}
{"op":"mcm","clk":"5348038986","pt":1646212902614,"mc":[{"id":"1.195453616","rc":[{"atb":[[2.12,0]],"id":37456368}],"con":true,"img":false}]}
{"op":"mcm","clk":"5348039085","pt":1646212904415,"mc":[{"id":"1.195453616","rc":[{"atb":[[3.65,2.83]],"id":36036864},{"atb":[[2.18,6.36]],"id":39980001}],"con":true,"img":false}]}
{"op":"mcm","clk":"5348039211","pt":1646212907193,"mc":[{"id":"1.195453616","rc":[{"atb":[[2.8,13.38]],"id":26503913}],"con":true,"img":false}]}
{"op":"mcm","clk":"5348039217","pt":1646212907295,"mc":[{"id":"1.195453616","rc":[{"atb":[[2.8,33.28]],"id":26503913}],"con":true,"img":false}]}
{"op":"mcm","clk":"5348039225","pt":1646212907503,"mc":[{"id":"1.195453616","rc":[{"atb":[[2.78,1.66]],"id":26503913}],"con":true,"img":false}]}
{"op":"mcm","clk":"5348039253","pt":1646212907918,"mc":[{"id":"1.195453616","rc":[{"atl":[[2.04,80.25]],"id":28755739}],"con":true,"img":false}]}
{"op":"mcm","clk":"5348039256","pt":1646212908015,"mc":[{"id":"1.195453616","rc":[{"atl":[[2.5,0],[2.48,0],[2.52,0],[2.46,0]],"id":37456368},{"trd":[[2.52,8],[2.5,8],[2.46,5.99],[2.48,4]],"ltp":2.52,"tv":25.99,"id":37456368}],"con":true,"img":false}]}
{"op":"mcm","clk":"5348039284","pt":1646212908478,"mc":[{"id":"1.195453616","rc":[{"atb":[[2.2,4.68]],"id":37456368}],"con":true,"img":false}]}
{"op":"mcm","clk":"5348039295","pt":1646212908689,"mc":[{"id":"1.195453616","rc":[{"atb":[[2.82,1.29]],"id":26503913},{"atb":[[2.2,6]],"id":37456368},{"atb":[[3.85,3.04]],"id":36036864},{"atb":[[4.5,2.7]],"id":39784359},{"atb":[[2.22,2.64]],"id":39980001}],"con":true,"img":false}]}
{"op":"mcm","clk":"5348039297","pt":1646212908785,"mc":[{"id":"1.195453616","rc":[{"atb":[[4.2,36.23]],"id":39784359}],"con":true,"img":false}]}
{"op":"mcm","clk":"5348039302","pt":1646212908888,"mc":[{"id":"1.195453616","rc":[{"atb":[[4,27.5],[4.5,13]],"id":39784359}],"con":true,"img":false}]}
{"op":"mcm","clk":"5348039325","pt":1646212909103,"mc":[{"id":"1.195453616","rc":[{"atb":[[4.4,5.88]],"id":39784359}],"con":true,"img":false}]}
{"op":"mcm","clk":"5348039364","pt":1646212909515,"mc":[{"id":"1.195453616","rc":[{"atb":[[3.8,12.12]],"id":36036864}],"con":true,"img":false}]}
{"op":"mcm","clk":"5348039371","pt":1646212909622,"mc":[{"id":"1.195453616","rc":[{"atb":[[3.85,4.5]],"id":36036864}],"con":true,"img":false}]}
{"op":"mcm","clk":"5348039398","pt":1646212910080,"mc":[{"id":"1.195453616","rc":[{"atl":[[3.3,38.66]],"id":37456368}],"con":true,"img":false}]}
{"op":"mcm","clk":"5348039403","pt":1646212910188,"mc":[{"id":"1.195453616","rc":[{"atl":[[3.3,18.42]],"id":37456368}],"con":true,"img":false}]}
{"op":"mcm","clk":"5348039423","pt":1646212910596,"mc":[{"id":"1.195453616","rc":[{"atl":[[9,0]],"id":39784359},{"atb":[[2.18,13.42]],"id":39980001}],"con":true,"img":false}]}
{"op":"mcm","clk":"5348039427","pt":1646212910699,"mc":[{"id":"1.195453616","rc":[{"atl":[[8.6,4.88]],"id":39784359}],"con":true,"img":false}]}
{"op":"mcm","clk":"5348039441","pt":1646212911108,"mc":[{"id":"1.195453616","rc":[{"atb":[[2.76,0]],"id":26503913}],"con":true,"img":false}]}
{"op":"mcm","clk":"5348039458","pt":1646212911500,"mc":[{"id":"1.195453616","rc":[{"atb":[[3.25,23.54]],"id":36036864}],"con":true,"img":false}]}
{"op":"mcm","clk":"5348039461","pt":1646212911595,"mc":[{"id":"1.195453616","rc":[{"atb":[[2.68,0]],"id":36036864}],"con":true,"img":false}]}
{"op":"mcm","clk":"5348039468","pt":1646212911712,"mc":[{"id":"1.195453616","rc":[{"atb":[[2.2,8.62]],"id":39980001}],"con":true,"img":false}]}
{"op":"mcm","clk":"5348039482","pt":1646212912006,"mc":[{"id":"1.195453616","rc":[{"atb":[[2.78,0]],"id":26503913}],"con":true,"img":false}]}
{"op":"mcm","clk":"5348039490","pt":1646212912117,"mc":[{"id":"1.195453616","rc":[{"atb":[[2.82,2.95]],"id":26503913},{"atb":[[2.22,1.66]],"id":37456368}],"con":true,"img":false}]}
{"op":"mcm","clk":"5348039500","pt":1646212912314,"mc":[{"id":"1.195453616","rc":[{"atb":[[2.24,4.25]],"id":37456368}],"con":true,"img":false}]}
{"op":"mcm","clk":"5348039508","pt":1646212912527,"mc":[{"id":"1.195453616","rc":[{"atb":[[2.2,2.75]],"id":37456368},{"atb":[[3.85,18.34]],"id":36036864}],"con":true,"img":false}]}
{"op":"mcm","clk":"5348039515","pt":1646212912622,"mc":[{"id":"1.195453616","rc":[{"atl":[[3.3,41.48]],"id":37456368},{"atl":[[8.4,10.81]],"id":39784359},{"atb":[[2.22,19.19],[2.14,0],[2.18,63.56]],"id":39980001}],"con":true,"img":false}]}
{"op":"mcm","clk":"5348039518","pt":1646212912673,"mc":[{"id":"1.195453616","rc":[{"atb":[[3.8,2.97]],"id":36036864}],"con":true,"img":false}]}
{"op":"mcm","clk":"5348039523","pt":1646212912777,"mc":[{"id":"1.195453616","rc":[{"atl":[[8.8,29.83]],"id":39784359},{"atb":[[2.2,2.16]],"id":39980001}],"con":true,"img":false}]}
{"op":"mcm","clk":"5348039529","pt":1646212912881,"mc":[{"id":"1.195453616","rc":[{"atb":[[2.24,6.41],[2.16,0]],"id":37456368},{"atl":[[9.6,2.5]],"id":39784359},{"atb":[[2.28,2.16],[2.2,0]],"id":39980001}],"con":true,"img":false}]}
{"op":"mcm","clk":"5348039536","pt":1646212912991,"mc":[{"id":"1.195453616","rc":[{"atb":[[2.8,31.77]],"id":26503913},{"atb":[[2.2,1.31]],"id":37456368}],"con":true,"img":false}]}
{"op":"mcm","clk":"5348039540","pt":1646212913092,"mc":[{"id":"1.195453616","rc":[{"atb":[[2.82,4.46]],"id":26503913},{"atb":[[1.01,1.43]],"id":37456368},{"atb":[[2.18,57.2]],"id":39980001}],"con":true,"img":false}]}
{"op":"mcm","clk":"5348039543","pt":1646212913192,"mc":[{"id":"1.195453616","rc":[{"atb":[[2.22,3.66],[2.14,0]],"id":37456368}],"con":true,"img":false}]}
{"op":"mcm","clk":"5348039552","pt":1646212913397,"mc":[{"id":"1.195453616","rc":[{"atl":[[8.6,3.47]],"id":39784359}],"con":true,"img":false}]}
{"op":"mcm","clk":"5348039556","pt":1646212913501,"mc":[{"id":"1.195453616","rc":[{"atb":[[2.2,0]],"id":37456368},{"atl":[[8.2,1.4]],"id":39784359}],"con":true,"img":false}]}
{"op":"mcm","clk":"5348039561","pt":1646212913610,"mc":[{"id":"1.195453616","rc":[{"atb":[[2.24,7.73]],"id":37456368}],"con":true,"img":false}]}
{"op":"mcm","clk":"5348039569","pt":1646212913924,"mc":[{"id":"1.195453616","rc":[{"atb":[[1.01,0]],"id":37456368}],"con":true,"img":false}]}
{"op":"mcm","clk":"5348039574","pt":1646212914015,"mc":[{"id":"1.195453616","rc":[{"atb":[[2.8,19.9]],"id":26503913},{"atb":[[2.26,1.43]],"id":37456368}],"con":true,"img":false}]}
{"op":"mcm","clk":"5348039583","pt":1646212914221,"mc":[{"id":"1.195453616","rc":[{"atb":[[2.28,5.01]],"id":37456368}],"con":true,"img":false}]}
{"op":"mcm","clk":"5348039589","pt":1646212914329,"mc":[{"id":"1.195453616","rc":[{"atb":[[2.24,3.48]],"id":37456368}],"con":true,"img":false}]}
{"op":"mcm","clk":"5348039617","pt":1646212914696,"mc":[{"id":"1.195453616","rc":[{"atb":[[2.26,0]],"id":37456368}],"con":true,"img":false}]}
{"op":"mcm","clk":"5348039626","pt":1646212914800,"mc":[{"id":"1.195453616","rc":[{"atb":[[2.28,6.44]],"id":37456368}],"con":true,"img":false}]}
{"op":"mcm","clk":"5348039631","pt":1646212914901,"mc":[{"id":"1.195453616","rc":[{"atb":[[2.28,1.43]],"id":37456368}],"con":true,"img":false}]}
{"op":"mcm","clk":"5348039644","pt":1646212915311,"mc":[{"id":"1.195453616","rc":[{"atb":[[2.3,3.58],[2.24,2.16]],"id":37456368}],"con":true,"img":false}]}
{"op":"mcm","clk":"5348039649","pt":1646212915409,"mc":[{"id":"1.195453616","rc":[{"atb":[[2.28,2.75]],"id":37456368},{"atb":[[3.7,53.48],[3.55,39.14]],"id":36036864}],"con":true,"img":false}]}
{"op":"mcm","clk":"5348039662","pt":1646212915620,"mc":[{"id":"1.195453616","rc":[{"atb":[[2.28,1.31]],"id":37456368}],"con":true,"img":false}]}
{"op":"mcm","clk":"5348039666","pt":1646212915717,"mc":[{"id":"1.195453616","rc":[{"atb":[[1.01,1.43]],"id":37456368}],"con":true,"img":false}]}
{"op":"mcm","clk":"5348039675","pt":1646212915930,"mc":[{"id":"1.195453616","rc":[{"atb":[[2.28,0]],"id":37456368}],"con":true,"img":false}]}
{"op":"mcm","clk":"5348039681","pt":1646212916031,"mc":[{"id":"1.195453616","rc":[{"atb":[[2.1,6.31]],"id":37456368}],"con":true,"img":false}]}
{"op":"mcm","clk":"5348039685","pt":1646212916135,"mc":[{"id":"1.195453616","rc":[{"atb":[[2.3,0]],"id":37456368}],"con":true,"img":false}]}
{"op":"mcm","clk":"5348039689","pt":1646212916282,"mc":[{"id":"1.195453616","rc":[{"atb":[[2.26,3.08]],"id":37456368}],"con":true,"img":false}]}
{"op":"mcm","clk":"5348039693","pt":1646212916386,"mc":[{"id":"1.195453616","rc":[{"atb":[[2.68,2.5],[2.7,119.73]],"id":26503913},{"atb":[[1.89,9.36]],"id":37456368},{"atb":[[3.65,0]],"id":36036864}],"con":true,"img":false}]}
{"op":"mcm","clk":"5348039700","pt":1646212916494,"mc":[{"id":"1.195453616","rc":[{"atb":[[1.01,0]],"id":37456368}],"con":true,"img":false}]}
{"op":"mcm","clk":"5348039705","pt":1646212916591,"mc":[{"id":"1.195453616","rc":[{"atb":[[2.26,4.51]],"id":37456368}],"con":true,"img":false}]}
{"op":"mcm","clk":"5348039718","pt":1646212916802,"mc":[{"id":"1.195453616","rc":[{"atb":[[2.24,14.95]],"id":39980001}],"con":true,"img":false}]}
{"op":"mcm","clk":"5348039733","pt":1646212917014,"mc":[{"id":"1.195453616","rc":[{"atb":[[2.1,5]],"id":37456368}],"con":true,"img":false}]}
{"op":"mcm","clk":"5348039740","pt":1646212917105,"mc":[{"id":"1.195453616","rc":[{"atb":[[2.04,1.31]],"id":37456368}],"con":true,"img":false}]}
{"op":"mcm","clk":"5348039759","pt":1646212917319,"mc":[{"id":"1.195453616","rc":[{"atb":[[2.04,0]],"id":37456368}],"con":true,"img":false}]}
{"op":"mcm","clk":"5348039767","pt":1646212917423,"mc":[{"id":"1.195453616","rc":[{"atb":[[2.1,6.31]],"id":37456368},{"atb":[[2.22,17.82]],"id":39980001}],"con":true,"img":false}]}
{"op":"mcm","clk":"5348039774","pt":1646212917517,"mc":[{"id":"1.195453616","rc":[{"atb":[[2.26,1.36]],"id":39980001}],"con":true,"img":false}]}
{"op":"mcm","clk":"5348039791","pt":1646212917827,"mc":[{"id":"1.195453616","rc":[{"atb":[[2.22,16.55]],"id":39980001}],"con":true,"img":false}]}
{"op":"mcm","clk":"5348039796","pt":1646212917935,"mc":[{"id":"1.195453616","rc":[{"atl":[[2.04,61.02]],"id":28755739},{"atb":[[2.22,2]],"id":37456368},{"atb":[[2.26,2.64]],"id":39980001}],"con":true,"img":false}]}
{"op":"mcm","clk":"5348039805","pt":1646212918133,"mc":[{"id":"1.195453616","rc":[{"atb":[[2.28,1.66]],"id":37456368}],"con":true,"img":false}]}
{"op":"mcm","clk":"5348039816","pt":1646212918295,"mc":[{"id":"1.195453616","rc":[{"atb":[[2.26,3.08]],"id":37456368}],"con":true,"img":false}]}
{"op":"mcm","clk":"5348039820","pt":1646212918390,"mc":[{"id":"1.195453616","rc":[{"atb":[[1.01,1.43]],"id":37456368}],"con":true,"img":false}]}
{"op":"mcm","clk":"5348039829","pt":1646212918595,"mc":[{"id":"1.195453616","rc":[{"atb":[[2.22,0]],"id":37456368}],"con":true,"img":false}]}
{"op":"mcm","clk":"5348039847","pt":1646212919315,"mc":[{"id":"1.195453616","rc":[{"atb":[[2.28,4.82]],"id":37456368}],"con":true,"img":false}]}
{"op":"mcm","clk":"5348039878","pt":1646212920138,"mc":[{"id":"1.195453616","rc":[{"atl":[[3.4,26.47]],"id":37456368}],"con":true,"img":false}]}
{"op":"mcm","clk":"5348039888","pt":1646212920290,"mc":[{"id":"1.195453616","rc":[{"atl":[[2.04,80.25]],"id":28755739}],"con":true,"img":false}]}
{"op":"mcm","clk":"5348040007","pt":1646212922403,"mc":[{"id":"1.195453616","rc":[{"atb":[[2.24,0]],"id":39980001}],"con":true,"img":false}]}
{"op":"mcm","clk":"5348040028","pt":1646212922813,"mc":[{"id":"1.195453616","rc":[{"atb":[[2.26,1.27]],"id":39980001}],"con":true,"img":false}]}
{"op":"mcm","clk":"5348040033","pt":1646212922916,"mc":[{"id":"1.195453616","rc":[{"atb":[[2.24,1.36]],"id":39980001}],"con":true,"img":false}]}
{"op":"mcm","clk":"5348040080","pt":1646212923742,"mc":[{"id":"1.195453616","rc":[{"spn":3.66,"spf":"NaN","id":26503913},{"spn":2.63,"spf":"NaN","id":37456368},{"spn":3.85,"spf":1.0,"id":36036864},{"spn":4.5,"spf":1.0,"id":39784359},{"atb":[[2.26,0]],"id":39980001},{"spn":2.81,"spf":"NaN","id":39980001}],"con":true,"img":false}]}
{"op":"mcm","clk":"5348040088","pt":1646212923846,"mc":[{"id":"1.195453616","rc":[{"atb":[[2.24,2.64]],"id":39980001}],"con":true,"img":false}]}
{"op":"mcm","clk":"5348040097","pt":1646212923947,"mc":[{"id":"1.195453616","rc":[{"atb":[[2.82,28.84]],"id":26503913}],"con":true,"img":false}]}
{"op":"mcm","clk":"5348040108","pt":1646212924154,"mc":[{"id":"1.195453616","rc":[{"atb":[[2.8,0]],"id":26503913}],"con":true,"img":false}]}
{"op":"mcm","clk":"5348040123","pt":1646212924307,"mc":[{"id":"1.195453616","rc":[{"atb":[[2.68,76.95],[2.7,58.71]],"id":26503913}],"con":true,"img":false}]}
{"op":"mcm","clk":"5348040153","pt":1646212924928,"mc":[{"id":"1.195453616","rc":[{"atb":[[2.28,5.53]],"id":39980001}],"con":true,"img":false}]}
{"op":"mcm","clk":"5348040177","pt":1646212925442,"mc":[{"id":"1.195453616","rc":[{"atb":[[2.24,1.27]],"id":39980001}],"con":true,"img":false}]}
{"op":"mcm","clk":"5348040182","pt":1646212925544,"mc":[{"id":"1.195453616","rc":[{"atb":[[2.28,6.9]],"id":39980001}],"con":true,"img":false}]}
{"op":"mcm","clk":"5348040205","pt":1646212925906,"mc":[{"id":"1.195453616","rc":[{"atb":[[2.24,0]],"id":39980001}],"con":true,"img":false}]}
{"op":"mcm","clk":"5348040211","pt":1646212926009,"mc":[{"id":"1.195453616","rc":[{"atb":[[2.28,8.17]],"id":39980001}],"con":true,"img":false}]}
{"op":"mcm","clk":"5348040249","pt":1646212926730,"mc":[{"id":"1.195453616","rc":[{"atl":[[2.04,61.02]],"id":28755739}],"con":true,"img":false}]}
{"op":"mcm","clk":"5348040292","pt":1646212927653,"mc":[{"id":"1.195453616","rc":[{"atl":[[8.6,0]],"id":39784359}],"con":true,"img":false}]}
{"op":"mcm","clk":"5348040300","pt":1646212927753,"mc":[{"id":"1.195453616","rc":[{"atl":[[8.2,4.88]],"id":39784359}],"con":true,"img":false}]}
{"op":"mcm","clk":"5348040307","pt":1646212927803,"mc":[{"id":"1.195453616","rc":[{"atl":[[2.04,80.25]],"id":28755739}],"con":true,"img":false}]}
{"op":"mcm","clk":"5348040354","pt":1646212928830,"mc":[{"id":"1.195453616","rc":[{"atb":[[2.3,3.96]],"id":37456368}],"con":true,"img":false}]}
{"op":"mcm","clk":"5348040359","pt":1646212928932,"mc":[{"id":"1.195453616","rc":[{"atb":[[2.26,0]],"id":37456368}],"con":true,"img":false}]}
{"op":"mcm","clk":"5348040368","pt":1646212929138,"mc":[{"id":"1.195453616","rc":[{"atl":[[8.2,15.99]],"id":39784359},{"atb":[[2.28,35.58]],"id":39980001}],"con":true,"img":false}]}
{"op":"mcm","clk":"5348040377","pt":1646212929342,"mc":[{"id":"1.195453616","rc":[{"atl":[[8.4,0]],"id":39784359},{"atb":[[2.22,0]],"id":39980001}],"con":true,"img":false}]}
{"op":"mcm","clk":"5348040387","pt":1646212929549,"mc":[{"id":"1.195453616","rc":[{"atl":[[9.6,31.09],[8.8,0]],"id":39784359},{"atb":[[2.18,7.06],[2.16,104.58]],"id":39980001}],"con":true,"img":false}]}
{"op":"mcm","clk":"5348040405","pt":1646212930011,"mc":[{"id":"1.195453616","rc":[{"atb":[[2.28,3.15]],"id":37456368}],"con":true,"img":false}]}
{"op":"mcm","clk":"5348040409","pt":1646212930114,"mc":[{"id":"1.195453616","rc":[{"atl":[[3.5,42.36]],"id":37456368}],"con":true,"img":false}]}
{"op":"mcm","clk":"5348040412","pt":1646212930217,"mc":[{"id":"1.195453616","rc":[{"atb":[[2.32,1.66]],"id":37456368}],"con":true,"img":false}]}
{"op":"mcm","clk":"5348040432","pt":1646212930628,"mc":[{"id":"1.195453616","rc":[{"atb":[[2.34,3.56]],"id":37456368}],"con":true,"img":false}]}
{"op":"mcm","clk":"5348040437","pt":1646212930731,"mc":[{"id":"1.195453616","rc":[{"atb":[[2.3,0]],"id":37456368}],"con":true,"img":false}]}
{"op":"mcm","clk":"5348040453","pt":1646212931041,"mc":[{"id":"1.195453616","rc":[{"atb":[[3.7,43.1]],"id":36036864}],"con":true,"img":false}]}
{"op":"mcm","clk":"5348040457","pt":1646212931143,"mc":[{"id":"1.195453616","rc":[{"atb":[[3.9,10.38]],"id":36036864}],"con":true,"img":false}]}
{"op":"mcm","clk":"5348040462","pt":1646212931253,"mc":[{"id":"1.195453616","rc":[{"atb":[[3.9,24.22]],"id":36036864}],"con":true,"img":false}]}
{"op":"mcm","clk":"5348040469","pt":1646212931350,"mc":[{"id":"1.195453616","rc":[{"atb":[[3.85,4.5]],"id":36036864}],"con":true,"img":false}]}
{"op":"mcm","clk":"5348040472","pt":1646212931451,"mc":[{"id":"1.195453616","rc":[{"atb":[[2.28,0]],"id":37456368}],"con":true,"img":false}]}
{"op":"mcm","clk":"5348040483","pt":1646212931759,"mc":[{"id":"1.195453616","rc":[{"atb":[[3.85,1.66]],"id":36036864}],"con":true,"img":false}]}
{"op":"mcm","clk":"5348040488","pt":1646212931862,"mc":[{"id":"1.195453616","rc":[{"atb":[[3.95,2.83],[3.7,0],[3.8,51.41]],"id":36036864}],"con":true,"img":false}]}
{"op":"mcm","clk":"5348040503","pt":1646212932069,"mc":[{"id":"1.195453616","rc":[{"atl":[[2.04,61.02]],"id":28755739},{"atb":[[2.3,2]],"id":37456368}],"con":true,"img":false}]}
{"op":"mcm","clk":"5348040510","pt":1646212932120,"mc":[{"id":"1.195453616","rc":[{"atb":[[4.5,12.12]],"id":39784359},{"trd":[[4.5,34.08]],"ltp":4.5,"tv":34.08,"id":39784359}],"con":true,"img":false}]}
{"op":"mcm","clk":"5348040542","pt":1646212932642,"mc":[{"id":"1.195453616","rc":[{"atb":[[4.5,11.57]],"id":39784359},{"atl":[[8.2,16.82]],"id":39784359}],"con":true,"img":false}]}
{"op":"mcm","clk":"5348040606","pt":1646212933663,"mc":[{"id":"1.195453616","rc":[{"atl":[[8.2,16.73]],"id":39784359},{"atb":[[2.28,32.21]],"id":39980001}],"con":true,"img":false}]}
{"op":"mcm","clk":"5348040758","pt":1646212935935,"mc":[{"id":"1.195453616","rc":[{"atb":[[2.32,0],[1.89,0]],"id":37456368},{"atb":[[3.85,0],[3.8,48.44]],"id":36036864},{"atb":[[2.18,0]],"id":39980001}],"con":true,"img":false}]}
{"op":"mcm","clk":"5348040765","pt":1646212936152,"mc":[{"id":"1.195453616","rc":[{"atb":[[2.34,0],[2.36,1.66]],"id":37456368},{"atb":[[4,1.66]],"id":36036864}],"con":true,"img":false}]}
{"op":"mcm","clk":"5348040772","pt":1646212936351,"mc":[{"id":"1.195453616","rc":[{"atb":[[2.38,2.08]],"id":37456368}],"con":true,"img":false}]}
{"op":"mcm","clk":"5348040781","pt":1646212936557,"mc":[{"id":"1.195453616","rc":[{"atb":[[2.2,5.33]],"id":37456368},{"atb":[[2.2,29.6]],"id":39980001}],"con":true,"img":false}]}
{"op":"mcm","clk":"5348040814","pt":1646212937129,"mc":[{"id":"1.195453616","rc":[{"atl":[[9.8,42.2]],"id":39784359}],"con":true,"img":false}]}
{"op":"mcm","clk":"5348040819","pt":1646212937231,"mc":[{"id":"1.195453616","rc":[{"atb":[[2.1,5]],"id":37456368},{"atl":[[9.6,2.5]],"id":39784359}],"con":true,"img":false}]}
{"op":"mcm","clk":"5348040826","pt":1646212937325,"mc":[{"id":"1.195453616","rc":[{"atb":[[2.3,0],[2.34,3.75],[2.2,6.64]],"id":37456368}],"con":true,"img":false}]}
{"op":"mcm","clk":"5348040847","pt":1646212937839,"mc":[{"id":"1.195453616","rc":[{"atl":[[2.04,80.25]],"id":28755739}],"con":true,"img":false}]}
{"op":"mcm","clk":"5348040965","pt":1646212940355,"mc":[{"id":"1.195453616","rc":[{"atl":[[2.04,61.02]],"id":28755739}],"con":true,"img":false}]}
{"op":"mcm","clk":"5348041035","pt":1646212941947,"mc":[{"id":"1.195453616","rc":[{"atb":[[2.36,0]],"id":37456368}],"con":true,"img":false}]}
{"op":"mcm","clk":"5348041047","pt":1646212942153,"mc":[{"id":"1.195453616","rc":[{"atb":[[2.4,1.66],[2.38,0]],"id":37456368}],"con":true,"img":false}]}
{"op":"mcm","clk":"5348041060","pt":1646212942358,"mc":[{"id":"1.195453616","rc":[{"atb":[[2.42,2.96]],"id":37456368}],"con":true,"img":false}]}
{"op":"mcm","clk":"5348041072","pt":1646212942564,"mc":[{"id":"1.195453616","rc":[{"atb":[[2.34,0],[2.38,4.41]],"id":37456368}],"con":true,"img":false}]}
{"op":"mcm","clk":"5348041085","pt":1646212942873,"mc":[{"id":"1.195453616","rc":[{"atl":[[2.98,0]],"id":37456368}],"con":true,"img":false}]}
{"op":"mcm","clk":"5348041089","pt":1646212942924,"mc":[{"id":"1.195453616","rc":[{"atl":[[1000,1.35]],"id":37456368}],"con":true,"img":false}]}
{"op":"mcm","clk":"5348041097","pt":1646212943029,"mc":[{"id":"1.195453616","rc":[{"atl":[[3,0]],"id":37456368}],"con":true,"img":false}]}
{"op":"mcm","clk":"5348041102","pt":1646212943159,"mc":[{"id":"1.195453616","rc":[{"atl":[[3.2,14],[3.4,48.3],[2.98,2.52],[3.3,18.42]],"id":37456368}],"con":true,"img":false}]}
{"op":"mcm","clk":"5348041124","pt":1646212943545,"mc":[{"id":"1.195453616","rc":[{"atl":[[2.98,0]],"id":37456368}],"con":true,"img":false}]}
{"op":"mcm","clk":"5348041161","pt":1646212944159,"mc":[{"id":"1.195453616","rc":[{"atl":[[1000,0]],"id":37456368}],"con":true,"img":false}]}
{"op":"mcm","clk":"5348041168","pt":1646212944265,"mc":[{"id":"1.195453616","rc":[{"atl":[[3.15,1.35]],"id":37456368}],"con":true,"img":false}]}
{"op":"mcm","clk":"5348041197","pt":1646212944777,"mc":[{"id":"1.195453616","rc":[{"atl":[[2.04,80.25]],"id":28755739}],"con":true,"img":false}]}
{"op":"mcm","clk":"5348041221","pt":1646212945141,"mc":[{"id":"1.195453616","rc":[{"atb":[[2.2,1.31]],"id":37456368}],"con":true,"img":false}]}
{"op":"mcm","clk":"5348041287","pt":1646212946581,"mc":[{"id":"1.195453616","rc":[{"atb":[[3.9,13.84]],"id":36036864}],"con":true,"img":false}]}
{"op":"mcm","clk":"5348041293","pt":1646212946633,"mc":[{"id":"1.195453616","rc":[{"atb":[[3.95,13.22]],"id":36036864}],"con":true,"img":false}]}
{"op":"mcm","clk":"5348041306","pt":1646212946838,"mc":[{"id":"1.195453616","rc":[{"atl":[[2.04,61.02]],"id":28755739}],"con":true,"img":false}]}
{"op":"mcm","clk":"5348041321","pt":1646212947354,"mc":[{"id":"1.195453616","rc":[{"atb":[[3.95,29.18]],"id":36036864}],"con":true,"img":false}]}
{"op":"mcm","clk":"5348041330","pt":1646212947559,"mc":[{"id":"1.195453616","rc":[{"atb":[[3.9,0]],"id":36036864}],"con":true,"img":false}]}
{"op":"mcm","clk":"5348041336","pt":1646212947662,"mc":[{"id":"1.195453616","rc":[{"atl":[[2.04,80.25]],"id":28755739},{"atb":[[3.8,0],[3.55,120.13]],"id":36036864}],"con":true,"img":false}]}
{"op":"mcm","clk":"5348041352","pt":1646212948071,"mc":[{"id":"1.195453616","rc":[{"atb":[[2.4,0]],"id":37456368}],"con":true,"img":false}]}
{"op":"mcm","clk":"5348041359","pt":1646212948176,"mc":[{"id":"1.195453616","rc":[{"atb":[[2.44,1.66]],"id":37456368}],"con":true,"img":false}]}
{"op":"mcm","clk":"5348041367","pt":1646212948279,"mc":[{"id":"1.195453616","rc":[{"atb":[[2.42,0]],"id":37456368}],"con":true,"img":false}]}
{"op":"mcm","clk":"5348041373","pt":1646212948328,"mc":[{"id":"1.195453616","rc":[{"atb":[[2.46,3.68]],"id":37456368}],"con":true,"img":false}]}
{"op":"mcm","clk":"5348041392","pt":1646212948740,"mc":[{"id":"1.195453616","rc":[{"atl":[[1000,2.52]],"id":37456368}],"con":true,"img":false}]}
{"op":"mcm","clk":"5348041404","pt":1646212948945,"mc":[{"id":"1.195453616","rc":[{"atl":[[1000,2.1]],"id":37456368}],"con":true,"img":false}]}
{"op":"mcm","clk":"5348041417","pt":1646212949151,"mc":[{"id":"1.195453616","rc":[{"atl":[[1000,0]],"id":37456368}],"con":true,"img":false}]}
{"op":"mcm","clk":"5348041423","pt":1646212949253,"mc":[{"id":"1.195453616","rc":[{"atl":[[3.1,2.1]],"id":37456368}],"con":true,"img":false}]}
{"op":"mcm","clk":"5348041437","pt":1646212949561,"mc":[{"id":"1.195453616","rc":[{"atl":[[3.15,0]],"id":37456368}],"con":true,"img":false}]}
{"op":"mcm","clk":"5348041443","pt":1646212949665,"mc":[{"id":"1.195453616","rc":[{"atl":[[3.1,3.45]],"id":37456368}],"con":true,"img":false}]}
{"op":"mcm","clk":"5348041469","pt":1646212949978,"mc":[{"id":"1.195453616","rc":[{"atb":[[2.22,5.33]],"id":37456368}],"con":true,"img":false}]}
{"op":"mcm","clk":"5348041709","pt":1646212953954,"mc":[{"id":"1.195453616","rc":[{"atb":[[2.44,0]],"id":37456368}],"con":true,"img":false}]}
{"op":"mcm","clk":"5348041715","pt":1646212954058,"mc":[{"id":"1.195453616","rc":[{"atb":[[2.38,0],[2.46,0]],"id":37456368}],"con":true,"img":false}]}
{"op":"mcm","clk":"5348041719","pt":1646212954159,"mc":[{"id":"1.195453616","rc":[{"atb":[[2.26,4.39]],"id":37456368}],"con":true,"img":false}]}
{"op":"mcm","clk":"5348041725","pt":1646212954263,"mc":[{"id":"1.195453616","rc":[{"atb":[[2.22,9.72]],"id":37456368}],"con":true,"img":false}]}
{"op":"mcm","clk":"5348041751","pt":1646212954777,"mc":[{"id":"1.195453616","rc":[{"atb":[[2.2,0]],"id":37456368}],"con":true,"img":false}]}
{"op":"mcm","clk":"5348041757","pt":1646212954879,"mc":[{"id":"1.195453616","rc":[{"atb":[[2.26,5.7]],"id":37456368}],"con":true,"img":false}]}
{"op":"mcm","clk":"5348041770","pt":1646212955088,"mc":[{"id":"1.195453616","rc":[{"atb":[[3.5,91.66]],"id":36036864}],"con":true,"img":false}]}
{"op":"mcm","clk":"5348041776","pt":1646212955190,"mc":[{"id":"1.195453616","rc":[{"atb":[[3.55,39.14]],"id":36036864}],"con":true,"img":false}]}
