{"op":"mcm","clk":"5352134793","pt":1646183310069,"mc":[{"id":"1.195503849","marketDefinition":{"bspMarket":false,"turnInPlayEnabled":false,"persistenceEnabled":false,"marketBaseRate":7.0,"eventId":"31272499","eventTypeId":"4339","numberOfWinners":1,"bettingType":"ODDS","marketType":"MATCH_BET","marketTime":"2022-03-02T08:54:00.000Z","suspendTime":"2022-03-02T08:54:00.000Z","bspReconciled":false,"complete":true,"inPlay":false,"crossMatching":true,"runnersVoidable":false,"numberOfActiveRunners":2,"betDelay":0,"status":"OPEN","runners":[{"status":"ACTIVE","sortPriority":1,"id":41207262,"name":"1. Kooky Loopy"},{"status":"ACTIVE","sortPriority":2,"id":43167130,"name":"2. Suited It"}],"regulators":["MR_INT"],"venue":"Rockhampton","countryCode":"AU","discountAllowed":true,"timezone":"Australia/Queensland","openDate":"2022-03-02T08:34:00.000Z","version":4382585404,"name":"Kooky Loopy v Suited It","eventName":"Rockhampton (AUS) 2nd Mar"},"rc":[],"con":true,"img":false}]}
{"op":"mcm","clk":"5352139712","pt":1646183422125,"mc":[{"id":"1.195503849","rc":[{"atb":[[1.45,11.99],[1.85,6.35],[1.65,8.3]],"id":41207262},{"atb":[[1.72,7.49],[1.32,16.87],[1.52,10.38]],"id":43167130}],"con":true,"img":false}]}
{"op":"mcm","clk":"5352146192","pt":1646183572652,"mc":[{"id":"1.195503849","marketDefinition":{"bspMarket":false,"turnInPlayEnabled":false,"persistenceEnabled":false,"marketBaseRate":7.0,"eventId":"31272499","eventTypeId":"4339","numberOfWinners":1,"bettingType":"ODDS","marketType":"MATCH_BET","marketTime":"2022-03-02T08:54:00.000Z","suspendTime":"2022-03-02T08:54:00.000Z","bspReconciled":false,"complete":true,"inPlay":false,"crossMatching":true,"runnersVoidable":false,"numberOfActiveRunners":2,"betDelay":0,"status":"OPEN","runners":[{"status":"ACTIVE","sortPriority":1,"id":41207262,"name":"1. Kooky Loopy"},{"status":"ACTIVE","sortPriority":2,"id":43167130,"name":"2. Suited It"}],"regulators":["MR_INT"],"venue":"Rockhampton","countryCode":"AU","discountAllowed":true,"timezone":"Australia/Queensland","openDate":"2022-03-02T08:28:00.000Z","version":4382597866,"name":"Kooky Loopy v Suited It","eventName":"Rockhampton (AUS) 2nd Mar"},"rc":[],"con":true,"img":false}]}
{"op":"mcm","clk":"5352149154","pt":1646183651828,"mc":[{"id":"1.195503849","marketDefinition":{"bspMarket":false,"turnInPlayEnabled":false,"persistenceEnabled":false,"marketBaseRate":7.0,"eventId":"31272499","eventTypeId":"4339","numberOfWinners":1,"bettingType":"ODDS","marketType":"MATCH_BET","marketTime":"2022-03-02T08:48:00.000Z","suspendTime":"2022-03-02T08:48:00.000Z","bspReconciled":false,"complete":true,"inPlay":false,"crossMatching":true,"runnersVoidable":false,"numberOfActiveRunners":2,"betDelay":0,"status":"OPEN","runners":[{"status":"ACTIVE","sortPriority":1,"id":41207262,"name":"1. Kooky Loopy"},{"status":"ACTIVE","sortPriority":2,"id":43167130,"name":"2. Suited It"}],"regulators":["MR_INT"],"venue":"Rockhampton","countryCode":"AU","discountAllowed":true,"timezone":"Australia/Queensland","openDate":"2022-03-02T08:28:00.000Z","version":4382599166,"name":"Kooky Loopy v Suited It","eventName":"Rockhampton (AUS) 2nd Mar"},"rc":[],"con":true,"img":false}]}
{"op":"mcm","clk":"5352466696","pt":1646191002690,"mc":[{"id":"1.195503849","marketDefinition":{"bspMarket":false,"turnInPlayEnabled":false,"persistenceEnabled":false,"marketBaseRate":7.0,"eventId":"31272499","eventTypeId":"4339","numberOfWinners":1,"bettingType":"ODDS","marketType":"MATCH_BET","marketTime":"2022-03-02T08:48:00.000Z","suspendTime":"2022-03-02T08:48:00.000Z","bspReconciled":false,"complete":true,"inPlay":false,"crossMatching":true,"runnersVoidable":false,"numberOfActiveRunners":2,"betDelay":0,"status":"OPEN","runners":[{"status":"ACTIVE","sortPriority":1,"id":41207262,"name":"1. Kooky Loopy"},{"status":"ACTIVE","sortPriority":2,"id":43167130,"name":"2. Suited It"}],"regulators":["MR_INT"],"venue":"Rockhampton","countryCode":"AU","discountAllowed":true,"timezone":"Australia/Queensland","openDate":"2022-03-02T08:28:00.000Z","version":4382599166,"name":"Kooky Loopy v Suited It","eventName":"Rockhampton (AUS) 2nd Mar"},"rc":[{"atb":[[1.45,12.01],[1.85,6.36],[1.65,8.31]],"id":41207262},{"atb":[[1.72,7.51],[1.32,16.89],[1.52,10.39]],"id":43167130}],"con":true,"img":true}]}
{"op":"mcm","clk":"5352586048","pt":1646194223762,"mc":[{"id":"1.195503849","rc":[{"atb":[[1.45,0],[1.85,0],[1.65,0]],"id":41207262},{"atb":[[1.72,0],[1.32,0],[1.52,0]],"id":43167130}],"con":true,"img":false}]}
{"op":"mcm","clk":"5352586485","pt":1646194236537,"mc":[{"id":"1.195503849","rc":[{"atb":[[1.28,19.31],[1.68,7.95],[1.48,11.26]],"id":41207262},{"atb":[[1.88,6.14],[1.68,7.95],[1.48,11.26]],"id":43167130}],"con":true,"img":false}]}
{"op":"mcm","clk":"5352597949","pt":1646194615822,"mc":[{"id":"1.195503849","rc":[{"atb":[[1.28,0],[1.68,0],[1.48,0]],"id":41207262},{"atb":[[1.88,0],[1.68,0],[1.48,0]],"id":43167130}],"con":true,"img":false}]}
{"op":"mcm","clk":"5352598358","pt":1646194631142,"mc":[{"id":"1.195503849","rc":[{"atb":[[1.28,19.31],[1.68,7.95],[1.48,11.26]],"id":41207262},{"atb":[[1.88,6.14],[1.68,7.95],[1.48,11.26]],"id":43167130}],"con":true,"img":false}]}
{"op":"mcm","clk":"5352601729","pt":1646194734361,"mc":[{"id":"1.195503849","rc":[{"atb":[[1.28,0],[1.68,0],[1.48,0]],"id":41207262},{"atb":[[1.88,0],[1.68,0],[1.48,0]],"id":43167130}],"con":true,"img":false}]}
{"op":"mcm","clk":"5352602385","pt":1646194751668,"mc":[{"id":"1.195503849","rc":[{"atb":[[1.28,19.31],[1.68,7.95],[1.48,11.26]],"id":41207262},{"atb":[[1.88,6.14],[1.68,7.95],[1.48,11.26]],"id":43167130}],"con":true,"img":false}]}
{"op":"mcm","clk":"5352823504","pt":1646201802741,"mc":[{"id":"1.195503849","marketDefinition":{"bspMarket":false,"turnInPlayEnabled":false,"persistenceEnabled":false,"marketBaseRate":7.0,"eventId":"31272499","eventTypeId":"4339","numberOfWinners":1,"bettingType":"ODDS","marketType":"MATCH_BET","marketTime":"2022-03-02T08:48:00.000Z","suspendTime":"2022-03-02T08:48:00.000Z","bspReconciled":false,"complete":true,"inPlay":false,"crossMatching":true,"runnersVoidable":false,"numberOfActiveRunners":2,"betDelay":0,"status":"OPEN","runners":[{"status":"ACTIVE","sortPriority":1,"id":41207262,"name":"1. Kooky Loopy"},{"status":"ACTIVE","sortPriority":2,"id":43167130,"name":"2. Suited It"}],"regulators":["MR_INT"],"venue":"Rockhampton","countryCode":"AU","discountAllowed":true,"timezone":"Australia/Queensland","openDate":"2022-03-02T08:28:00.000Z","version":4382599166,"name":"Kooky Loopy v Suited It","eventName":"Rockhampton (AUS) 2nd Mar"},"rc":[{"atb":[[1.28,19.3],[1.68,7.94],[1.48,11.26]],"id":41207262},{"atb":[[1.88,6.14],[1.68,7.94],[1.48,11.26]],"id":43167130}],"con":true,"img":true}]}
{"op":"mcm","clk":"5353028874","pt":1646207202758,"mc":[{"id":"1.195503849","marketDefinition":{"bspMarket":false,"turnInPlayEnabled":false,"persistenceEnabled":false,"marketBaseRate":7.0,"eventId":"31272499","eventTypeId":"4339","numberOfWinners":1,"bettingType":"ODDS","marketType":"MATCH_BET","marketTime":"2022-03-02T08:48:00.000Z","suspendTime":"2022-03-02T08:48:00.000Z","bspReconciled":false,"complete":true,"inPlay":false,"crossMatching":true,"runnersVoidable":false,"numberOfActiveRunners":2,"betDelay":0,"status":"OPEN","runners":[{"status":"ACTIVE","sortPriority":1,"id":41207262,"name":"1. Kooky Loopy"},{"status":"ACTIVE","sortPriority":2,"id":43167130,"name":"2. Suited It"}],"regulators":["MR_INT"],"venue":"Rockhampton","countryCode":"AU","discountAllowed":true,"timezone":"Australia/Queensland","openDate":"2022-03-02T08:28:00.000Z","version":4382599166,"name":"Kooky Loopy v Suited It","eventName":"Rockhampton (AUS) 2nd Mar"},"rc":[{"atb":[[1.28,19.3],[1.68,7.94],[1.48,11.26]],"id":41207262},{"atb":[[1.88,6.14],[1.68,7.94],[1.48,11.26]],"id":43167130}],"con":true,"img":true}]}
{"op":"mcm","clk":"5353142381","pt":1646209701184,"mc":[{"id":"1.195503849","rc":[{"atb":[[1.28,19.3],[1.68,9.94],[1.48,11.26]],"id":41207262},{"atl":[[2.26,2]],"id":41207262},{"atb":[[1.89,2],[1.88,6.14],[1.68,7.94],[1.48,11.26]],"id":43167130},{"atl":[[2.42,2]],"id":43167130}],"con":true,"img":false}]}
{"op":"mcm","clk":"5353143992","pt":1646209731360,"mc":[{"id":"1.195503849","rc":[{"atl":[[2.4,2],[2.42,0]],"id":43167130}],"con":true,"img":false}]}
{"op":"mcm","clk":"5353147610","pt":1646209801972,"mc":[{"id":"1.195503849","rc":[{"atb":[[1.69,2]],"id":41207262}],"con":true,"img":false}]}
{"op":"mcm","clk":"5353147615","pt":1646209802075,"mc":[{"id":"1.195503849","rc":[{"atb":[[1.68,7.94]],"id":41207262}],"con":true,"img":false}]}
{"op":"mcm","clk":"5353150535","pt":1646209856938,"mc":[{"id":"1.195503849","rc":[{"atb":[[1.69,0]],"id":41207262},{"atl":[[2.26,0]],"id":41207262},{"atb":[[1.89,0]],"id":43167130},{"atl":[[2.4,0]],"id":43167130}],"con":true,"img":false}]}
{"op":"mcm","clk":"5353153943","pt":1646209923143,"mc":[{"id":"1.195503849","rc":[{"atb":[[1.69,2]],"id":41207262},{"atl":[[2.26,2]],"id":41207262},{"atb":[[1.89,2]],"id":43167130},{"atl":[[2.4,2]],"id":43167130}],"con":true,"img":false}]}
{"op":"mcm","clk":"5353154218","pt":1646209928304,"mc":[{"id":"1.195503849","rc":[{"atl":[[2.24,2]],"id":41207262}],"con":true,"img":false}]}
{"op":"mcm","clk":"5353154221","pt":1646209928405,"mc":[{"id":"1.195503849","rc":[{"atl":[[2.26,0]],"id":41207262}],"con":true,"img":false}]}
{"op":"mcm","clk":"5353155816","pt":1646209958955,"mc":[{"id":"1.195503849","rc":[{"atl":[[2.26,2]],"id":41207262},{"atl":[[2.4,0],[2.38,2]],"id":43167130}],"con":true,"img":false}]}
{"op":"mcm","clk":"5353155820","pt":1646209959051,"mc":[{"id":"1.195503849","rc":[{"atl":[[2.24,0]],"id":41207262}],"con":true,"img":false}]}
{"op":"mcm","clk":"5353156090","pt":1646209964047,"mc":[{"id":"1.195503849","rc":[{"atl":[[2.2,2]],"id":41207262}],"con":true,"img":false}]}
{"op":"mcm","clk":"5353156095","pt":1646209964151,"mc":[{"id":"1.195503849","rc":[{"atl":[[2.26,0]],"id":41207262}],"con":true,"img":false}]}
{"op":"mcm","clk":"5353160317","pt":1646210041586,"mc":[{"id":"1.195503849","rc":[{"atb":[[1.28,0],[1.68,0],[1.48,0]],"id":41207262},{"atb":[[1.88,0],[1.68,0],[1.48,0]],"id":43167130}],"con":true,"img":false}]}
{"op":"mcm","clk":"5353160547","pt":1646210045760,"mc":[{"id":"1.195503849","rc":[{"atb":[[1.28,19.3],[1.68,7.94],[1.48,11.26]],"id":41207262},{"atb":[[1.88,6.14],[1.68,7.94],[1.48,11.26]],"id":43167130}],"con":true,"img":false}]}
{"op":"mcm","clk":"5353167620","pt":1646210177979,"mc":[{"id":"1.195503849","rc":[{"atb":[[1.7,2]],"id":41207262}],"con":true,"img":false}]}
{"op":"mcm","clk":"5353167626","pt":1646210178083,"mc":[{"id":"1.195503849","rc":[{"atb":[[1.69,0]],"id":41207262}],"con":true,"img":false}]}
{"op":"mcm","clk":"5353167731","pt":1646210180813,"mc":[{"id":"1.195503849","rc":[{"atl":[[2.36,2],[2.38,0]],"id":43167130}],"con":true,"img":false}]}
{"op":"mcm","clk":"5353167942","pt":1646210184898,"mc":[{"id":"1.195503849","rc":[{"atb":[[1.7,0],[1.69,2]],"id":41207262}],"con":true,"img":false}]}
{"op":"mcm","clk":"5353169499","pt":1646210214118,"mc":[{"id":"1.195503849","rc":[{"atl":[[2.18,2],[2.2,0]],"id":41207262}],"con":true,"img":false}]}
{"op":"mcm","clk":"5353169780","pt":1646210219258,"mc":[{"id":"1.195503849","rc":[{"atl":[[2.2,2]],"id":41207262}],"con":true,"img":false}]}
{"op":"mcm","clk":"5353169784","pt":1646210219361,"mc":[{"id":"1.195503849","rc":[{"atl":[[2.18,0]],"id":41207262}],"con":true,"img":false}]}
{"op":"mcm","clk":"5353172961","pt":1646210279645,"mc":[{"id":"1.195503849","rc":[{"atb":[[1.28,0],[1.68,0],[1.48,0]],"id":41207262},{"atb":[[1.88,0],[1.68,0],[1.48,0]],"id":43167130}],"con":true,"img":false}]}
{"op":"mcm","clk":"5353173221","pt":1646210283727,"mc":[{"id":"1.195503849","rc":[{"atb":[[1.28,19.3],[1.68,7.94],[1.48,11.26]],"id":41207262},{"atb":[[1.88,6.14],[1.68,7.94],[1.48,11.26]],"id":43167130}],"con":true,"img":false}]}
{"op":"mcm","clk":"5353178019","pt":1646210375551,"mc":[{"id":"1.195503849","rc":[{"atb":[[1.68,9.94],[1.69,0]],"id":41207262},{"atl":[[2.36,0],[2.42,2]],"id":43167130}],"con":true,"img":false}]}
{"op":"mcm","clk":"5353179177","pt":1646210399448,"mc":[{"id":"1.195503849","rc":[{"atb":[[1.64,2],[1.68,7.94]],"id":41207262},{"atl":[[2.5,2],[2.42,0]],"id":43167130}],"con":true,"img":false}]}
{"op":"mcm","clk":"5353179467","pt":1646210404676,"mc":[{"id":"1.195503849","rc":[{"atl":[[2.5,0],[2.48,2]],"id":43167130}],"con":true,"img":false}]}
{"op":"mcm","clk":"5353180827","pt":1646210431198,"mc":[{"id":"1.195503849","rc":[{"atb":[[1.64,0],[1.65,2]],"id":41207262}],"con":true,"img":false}]}
{"op":"mcm","clk":"5353181381","pt":1646210441845,"mc":[{"id":"1.195503849","rc":[{"atl":[[2.46,2],[2.48,0]],"id":43167130}],"con":true,"img":false}]}
{"op":"mcm","clk":"5353182465","pt":1646210461576,"mc":[{"id":"1.195503849","rc":[{"atl":[[15.5,1.42]],"id":41207262},{"atl":[[16.5,1.42]],"id":43167130}],"con":true,"img":false}]}
{"op":"mcm","clk":"5353182474","pt":1646210461729,"mc":[{"id":"1.195503849","rc":[{"atl":[[2.46,2],[2.2,0]],"id":41207262}],"con":true,"img":false}]}
{"op":"mcm","clk":"5353182480","pt":1646210461832,"mc":[{"id":"1.195503849","rc":[{"atl":[[2.42,2]],"id":41207262}],"con":true,"img":false}]}
{"op":"mcm","clk":"5353182485","pt":1646210461944,"mc":[{"id":"1.195503849","rc":[{"atl":[[2.4,2],[2.42,0],[2.46,0]],"id":41207262}],"con":true,"img":false}]}
{"op":"mcm","clk":"5353182527","pt":1646210462659,"mc":[{"id":"1.195503849","rc":[{"atl":[[16,1.42]],"id":41207262},{"atl":[[17,1.42]],"id":43167130}],"con":true,"img":false}]}
{"op":"mcm","clk":"5353182551","pt":1646210463019,"mc":[{"id":"1.195503849","rc":[{"atl":[[2.4,0],[2.42,2]],"id":41207262}],"con":true,"img":false}]}
{"op":"mcm","clk":"5353182608","pt":1646210463847,"mc":[{"id":"1.195503849","rc":[{"atl":[[16.5,1.42]],"id":41207262},{"atl":[[17.5,1.42]],"id":43167130}],"con":true,"img":false}]}
{"op":"mcm","clk":"5353182625","pt":1646210464053,"mc":[{"id":"1.195503849","rc":[{"atl":[[2.42,0],[2.38,2]],"id":41207262}],"con":true,"img":false}]}
{"op":"mcm","clk":"5353182663","pt":1646210464826,"mc":[{"id":"1.195503849","rc":[{"atl":[[17,1.42]],"id":41207262},{"atl":[[18,1.42]],"id":43167130}],"con":true,"img":false}]}
{"op":"mcm","clk":"5353182723","pt":1646210465854,"mc":[{"id":"1.195503849","rc":[{"atb":[[1.83,33],[1.84,2],[1.85,2],[1.76,2],[1.82,2],[1.8,2],[1.79,50],[1.74,75],[1.88,21.14],[1.86,22],[1.77,2]],"id":43167130}],"con":true,"img":false}]}
{"op":"mcm","clk":"5353182729","pt":1646210465959,"mc":[{"id":"1.195503849","rc":[{"atb":[[1.86,24]],"id":43167130}],"con":true,"img":false}]}
{"op":"mcm","clk":"5353182735","pt":1646210466061,"mc":[{"id":"1.195503849","rc":[{"atb":[[1.89,0]],"id":43167130}],"con":true,"img":false}]}
{"op":"mcm","clk":"5353182739","pt":1646210466165,"mc":[{"id":"1.195503849","rc":[{"atb":[[1.89,2],[1.86,22]],"id":43167130}],"con":true,"img":false}]}
{"op":"mcm","clk":"5353182748","pt":1646210466268,"mc":[{"id":"1.195503849","rc":[{"atl":[[17.5,1.42]],"id":41207262},{"atl":[[18.5,1.42]],"id":43167130}],"con":true,"img":false}]}
{"op":"mcm","clk":"5353182809","pt":1646210467246,"mc":[{"id":"1.195503849","rc":[{"atl":[[2.8,2],[2.82,2],[2.64,2],[2.58,18],[2.62,27],[2.76,60],[2.74,2],[2.86,90],[2.66,2],[2.68,40],[2.7,2]],"id":43167130}],"con":true,"img":false}]}
{"op":"mcm","clk":"5353182819","pt":1646210467452,"mc":[{"id":"1.195503849","rc":[{"atl":[[1.95,1.42]],"id":41207262},{"atb":[[2.06,1.42]],"id":43167130},{"atl":[[19,1.42]],"id":43167130}],"con":true,"img":false}]}
{"op":"mcm","clk":"5353182825","pt":1646210467556,"mc":[{"id":"1.195503849","rc":[{"atb":[[1.89,0],[2.02,2]],"id":43167130}],"con":true,"img":false}]}
{"op":"mcm","clk":"5353182830","pt":1646210467659,"mc":[{"id":"1.195503849","rc":[{"atl":[[16,0],[16.5,0],[17,0],[17.5,0],[15.5,0]],"id":41207262}],"con":true,"img":false}]}
{"op":"mcm","clk":"5353182922","pt":1646210469149,"mc":[{"id":"1.195503849","rc":[{"atl":[[1.97,2]],"id":41207262}],"con":true,"img":false}]}
{"op":"mcm","clk":"5353182929","pt":1646210469251,"mc":[{"id":"1.195503849","rc":[{"atl":[[2.38,0]],"id":41207262}],"con":true,"img":false}]}
{"op":"mcm","clk":"5353182941","pt":1646210469456,"mc":[{"id":"1.195503849","rc":[{"atl":[[1.95,0]],"id":41207262},{"atl":[[16.5,0],[17,0],[17.5,0],[18,0],[18.5,0],[19,0]],"id":43167130}],"con":true,"img":false}]}
{"op":"mcm","clk":"5353183012","pt":1646210470844,"mc":[{"id":"1.195503849","rc":[{"atb":[[1.74,1.42]],"id":41207262},{"atl":[[1.89,1.42]],"id":41207262},{"atb":[[2.04,1.42]],"id":43167130},{"atl":[[2.34,1.42]],"id":43167130}],"con":true,"img":false}]}
{"op":"mcm","clk":"5353183067","pt":1646210471671,"mc":[{"id":"1.195503849","rc":[{"atb":[[1.74,0]],"id":41207262},{"atl":[[1.89,0]],"id":41207262},{"atl":[[2.34,0]],"id":43167130}],"con":true,"img":false}]}
{"op":"mcm","clk":"5353183104","pt":1646210472547,"mc":[{"id":"1.195503849","rc":[{"atb":[[1.75,1.42]],"id":41207262},{"atl":[[1.91,1.42]],"id":41207262},{"atb":[[2,1.42]],"id":43167130},{"atl":[[2.32,1.42]],"id":43167130}],"con":true,"img":false}]}
{"op":"mcm","clk":"5353183161","pt":1646210473779,"mc":[{"id":"1.195503849","rc":[{"atb":[[1.74,1.42]],"id":41207262},{"atl":[[1.96,1.42]],"id":41207262},{"atb":[[1.99,1.42]],"id":43167130},{"atl":[[2.38,1.42]],"id":43167130}],"con":true,"img":false}]}
{"op":"mcm","clk":"5353183174","pt":1646210473984,"mc":[{"id":"1.195503849","rc":[{"atb":[[1.75,0]],"id":41207262},{"atl":[[1.91,0]],"id":41207262},{"atl":[[2.32,0]],"id":43167130}],"con":true,"img":false}]}
{"op":"mcm","clk":"5353183243","pt":1646210475166,"mc":[{"id":"1.195503849","rc":[{"atb":[[1.73,1.42]],"id":41207262},{"atl":[[1.9,1.42]],"id":41207262},{"atb":[[1.98,1.42]],"id":43167130},{"atl":[[2.4,1.42]],"id":43167130}],"con":true,"img":false}]}
{"op":"mcm","clk":"5353183252","pt":1646210475371,"mc":[{"id":"1.195503849","rc":[{"atb":[[2.06,0]],"id":43167130},{"atl":[[2.38,0]],"id":43167130}],"con":true,"img":false}]}
{"op":"mcm","clk":"5353183291","pt":1646210476145,"mc":[{"id":"1.195503849","rc":[{"atb":[[1.73,2.84]],"id":41207262},{"atl":[[1.92,1.42]],"id":41207262},{"atb":[[1.98,2.84]],"id":43167130},{"atl":[[2.4,2.84]],"id":43167130}],"con":true,"img":false}]}
{"op":"mcm","clk":"5353183330","pt":1646210477068,"mc":[{"id":"1.195503849","rc":[{"atb":[[1.74,0]],"id":41207262},{"atl":[[1.9,0]],"id":41207262},{"atl":[[2.4,1.42]],"id":43167130}],"con":true,"img":false}]}
{"op":"mcm","clk":"5353183363","pt":1646210477687,"mc":[{"id":"1.195503849","rc":[{"atb":[[1.72,1.42]],"id":41207262},{"atl":[[1.98,1.42]],"id":41207262},{"atb":[[2.08,1.42]],"id":43167130},{"atl":[[2.32,1.42]],"id":43167130}],"con":true,"img":false}]}
{"op":"mcm","clk":"5353183407","pt":1646210478359,"mc":[{"id":"1.195503849","rc":[{"atl":[[1.92,0]],"id":41207262}],"con":true,"img":false}]}
{"op":"mcm","clk":"5353183462","pt":1646210479494,"mc":[{"id":"1.195503849","rc":[{"atb":[[1.7,1.42]],"id":41207262},{"atl":[[2.06,1.42]],"id":41207262},{"atb":[[1.97,1.42]],"id":43167130},{"atl":[[2.42,1.42]],"id":43167130}],"con":true,"img":false}]}
{"op":"mcm","clk":"5353183469","pt":1646210479650,"mc":[{"id":"1.195503849","rc":[{"atl":[[2.32,0]],"id":43167130}],"con":true,"img":false}]}
{"op":"mcm","clk":"5353183538","pt":1646210481348,"mc":[{"id":"1.195503849","rc":[{"atb":[[1.73,0]],"id":41207262}],"con":true,"img":false}]}
{"op":"mcm","clk":"5353183585","pt":1646210482476,"mc":[{"id":"1.195503849","rc":[{"atb":[[1.75,1.42]],"id":41207262},{"atl":[[2.08,1.42]],"id":41207262},{"atl":[[2.44,1.42]],"id":43167130}],"con":true,"img":false}]}
{"op":"mcm","clk":"5353183602","pt":1646210482785,"mc":[{"id":"1.195503849","rc":[{"atl":[[2.4,0]],"id":43167130}],"con":true,"img":false}]}
{"op":"mcm","clk":"5353183658","pt":1646210483765,"mc":[{"id":"1.195503849","rc":[{"atb":[[1.74,1.42]],"id":41207262},{"atl":[[2.1,1.42]],"id":41207262},{"atl":[[2.5,1.42]],"id":43167130}],"con":true,"img":false}]}
{"op":"mcm","clk":"5353183674","pt":1646210484074,"mc":[{"id":"1.195503849","rc":[{"atb":[[1.75,0]],"id":41207262},{"atl":[[1.96,0]],"id":41207262},{"atl":[[2.42,0]],"id":43167130}],"con":true,"img":false}]}
{"op":"mcm","clk":"5353183678","pt":1646210484176,"mc":[{"id":"1.195503849","rc":[{"atl":[[1.98,3.42],[1.97,0]],"id":41207262}],"con":true,"img":false}]}
{"op":"mcm","clk":"5353183687","pt":1646210484279,"mc":[{"id":"1.195503849","rc":[{"atl":[[1.98,1.42],[2.04,2]],"id":41207262}],"con":true,"img":false}]}
{"op":"mcm","clk":"5353183692","pt":1646210484382,"mc":[{"id":"1.195503849","rc":[{"atl":[[1.98,3.42]],"id":41207262}],"con":true,"img":false}]}
{"op":"mcm","clk":"5353183697","pt":1646210484485,"mc":[{"id":"1.195503849","rc":[{"atl":[[2.04,0]],"id":41207262}],"con":true,"img":false}]}
{"op":"mcm","clk":"5353183735","pt":1646210485258,"mc":[{"id":"1.195503849","rc":[{"atb":[[1.67,1.42]],"id":41207262},{"atl":[[2.12,1.42]],"id":41207262},{"atl":[[2.52,1.42]],"id":43167130}],"con":true,"img":false}]}
{"op":"mcm","clk":"5353183783","pt":1646210486390,"mc":[{"id":"1.195503849","rc":[{"atb":[[1.96,1.42]],"id":43167130}],"con":true,"img":false}]}
{"op":"mcm","clk":"5353183834","pt":1646210487677,"mc":[{"id":"1.195503849","rc":[{"atb":[[1.95,1.42]],"id":43167130}],"con":true,"img":false}]}
{"op":"mcm","clk":"5353183883","pt":1646210488765,"mc":[{"id":"1.195503849","rc":[{"atb":[[1.95,2.84]],"id":43167130}],"con":true,"img":false}]}
{"op":"mcm","clk":"5353184075","pt":1646210491905,"mc":[{"id":"1.195503849","rc":[{"atl":[[1.96,1.42]],"id":41207262}],"con":true,"img":false}]}
{"op":"mcm","clk":"5353184084","pt":1646210492112,"mc":[{"id":"1.195503849","rc":[{"atl":[[1.98,1.42],[1.97,2]],"id":41207262}],"con":true,"img":false}]}
{"op":"mcm","clk":"5353184249","pt":1646210494486,"mc":[{"id":"1.195503849","rc":[{"atl":[[2.42,1.42]],"id":43167130}],"con":true,"img":false}]}
{"op":"mcm","clk":"5353184343","pt":1646210495877,"mc":[{"id":"1.195503849","rc":[{"atl":[[2.42,0]],"id":43167130}],"con":true,"img":false}]}
{"op":"mcm","clk":"5353184367","pt":1646210496392,"mc":[{"id":"1.195503849","rc":[{"atb":[[1.72,0],[1.74,0],[1.7,0]],"id":41207262},{"trd":[[1.69,1.74],[1.72,2.84],[1.74,2.84],[1.7,2.84]],"ltp":1.69,"tv":10.26,"id":41207262},{"atl":[[2.44,0.21]],"id":43167130},{"trd":[[2.44,1.2]],"ltp":2.44,"tv":1.2,"id":43167130}],"con":true,"img":false}]}
{"op":"mcm","clk":"5353184372","pt":1646210496495,"mc":[{"id":"1.195503849","rc":[{"atl":[[2.44,0]],"id":43167130},{"trd":[[2.44,1.64]],"ltp":2.44,"tv":1.64,"id":43167130}],"con":true,"img":false}]}
{"op":"mcm","clk":"5353184429","pt":1646210497581,"mc":[{"id":"1.195503849","rc":[{"atb":[[1.73,1.42]],"id":41207262},{"atl":[[2.44,1.42]],"id":43167130}],"con":true,"img":false}]}
{"op":"mcm","clk":"5353184522","pt":1646210499588,"mc":[{"id":"1.195503849","rc":[{"atb":[[1.73,0],[1.64,1.42]],"id":41207262}],"con":true,"img":false}]}
{"op":"mcm","clk":"5353184538","pt":1646210499898,"mc":[{"id":"1.195503849","rc":[{"atb":[[1.65,0],[1.66,2]],"id":41207262}],"con":true,"img":false}]}
{"op":"mcm","clk":"5353184561","pt":1646210500313,"mc":[{"id":"1.195503849","rc":[{"atb":[[1.67,3.42]],"id":41207262},{"atl":[[2.42,2]],"id":43167130}],"con":true,"img":false}]}
{"op":"mcm","clk":"5353184566","pt":1646210500417,"mc":[{"id":"1.195503849","rc":[{"atb":[[1.66,0]],"id":41207262},{"atl":[[2.46,0]],"id":43167130}],"con":true,"img":false}]}
{"op":"mcm","clk":"5353184599","pt":1646210500883,"mc":[{"id":"1.195503849","rc":[{"atb":[[1.74,1.42]],"id":41207262},{"atl":[[2.44,3.42],[2.42,0]],"id":43167130}],"con":true,"img":false}]}
{"op":"mcm","clk":"5353184694","pt":1646210502327,"mc":[{"id":"1.195503849","rc":[{"atl":[[2.46,1.42]],"id":43167130}],"con":true,"img":false}]}
{"op":"mcm","clk":"5353184707","pt":1646210502482,"mc":[{"id":"1.195503849","rc":[{"atb":[[1.74,0]],"id":41207262}],"con":true,"img":false}]}
{"op":"mcm","clk":"5353184794","pt":1646210503719,"mc":[{"id":"1.195503849","rc":[{"atb":[[1.75,1.42]],"id":41207262},{"atl":[[2.42,1.42]],"id":43167130}],"con":true,"img":false}]}
{"op":"mcm","clk":"5353184801","pt":1646210503821,"mc":[{"id":"1.195503849","rc":[{"atl":[[2.44,2]],"id":43167130}],"con":true,"img":false}]}
{"op":"mcm","clk":"5353184887","pt":1646210505417,"mc":[{"id":"1.195503849","rc":[{"atb":[[1.75,0]],"id":41207262}],"con":true,"img":false}]}
{"op":"mcm","clk":"5353184938","pt":1646210506091,"mc":[{"id":"1.195503849","rc":[{"atl":[[2.44,0],[2.42,3.42]],"id":43167130}],"con":true,"img":false}]}
{"op":"mcm","clk":"5353184994","pt":1646210506912,"mc":[{"id":"1.195503849","rc":[{"atb":[[1.75,1.42]],"id":41207262}],"con":true,"img":false}]}
{"op":"mcm","clk":"5353185077","pt":1646210508197,"mc":[{"id":"1.195503849","rc":[{"atb":[[1.69,1.42]],"id":41207262},{"atl":[[2.44,1.42]],"id":43167130}],"con":true,"img":false}]}
{"op":"mcm","clk":"5353185093","pt":1646210508406,"mc":[{"id":"1.195503849","rc":[{"atb":[[1.75,0]],"id":41207262}],"con":true,"img":false}]}
{"op":"mcm","clk":"5353185172","pt":1646210509538,"mc":[{"id":"1.195503849","rc":[{"atb":[[1.71,1.42]],"id":41207262},{"atl":[[2.44,2.84]],"id":43167130}],"con":true,"img":false}]}
{"op":"mcm","clk":"5353185203","pt":1646210510001,"mc":[{"id":"1.195503849","rc":[{"atl":[[2.42,2]],"id":43167130}],"con":true,"img":false}]}
{"op":"mcm","clk":"5353185251","pt":1646210510823,"mc":[{"id":"1.195503849","rc":[{"atb":[[1.75,1.42]],"id":41207262}],"con":true,"img":false}]}
{"op":"mcm","clk":"5353185374","pt":1646210513198,"mc":[{"id":"1.195503849","rc":[{"atb":[[1.75,0]],"id":41207262}],"con":true,"img":false}]}
{"op":"mcm","clk":"5353185435","pt":1646210514328,"mc":[{"id":"1.195503849","rc":[{"atb":[[1.76,1.42]],"id":41207262}],"con":true,"img":false}]}
{"op":"mcm","clk":"5353185517","pt":1646210515615,"mc":[{"id":"1.195503849","rc":[{"atb":[[1.76,0]],"id":41207262}],"con":true,"img":false}]}
{"op":"mcm","clk":"5353185551","pt":1646210516131,"mc":[{"id":"1.195503849","rc":[{"atl":[[2.44,4.84],[2.42,0]],"id":43167130}],"con":true,"img":false}]}
{"op":"mcm","clk":"5353185601","pt":1646210517109,"mc":[{"id":"1.195503849","rc":[{"atb":[[1.75,1.42]],"id":41207262},{"atl":[[2.42,1.42]],"id":43167130}],"con":true,"img":false}]}
{"op":"mcm","clk":"5353185665","pt":1646210518037,"mc":[{"id":"1.195503849","rc":[{"atb":[[1.75,0]],"id":41207262},{"atl":[[2.42,0]],"id":43167130}],"con":true,"img":false}]}
{"op":"mcm","clk":"5353185767","pt":1646210519735,"mc":[{"id":"1.195503849","rc":[{"atb":[[1.75,1.42]],"id":41207262},{"atl":[[2.42,1.42]],"id":43167130}],"con":true,"img":false}]}
{"op":"mcm","clk":"5353185837","pt":1646210520814,"mc":[{"id":"1.195503849","rc":[{"atb":[[1.75,0]],"id":41207262},{"atl":[[2.42,0]],"id":43167130}],"con":true,"img":false}]}
{"op":"mcm","clk":"5353185842","pt":1646210520918,"mc":[{"id":"1.195503849","rc":[{"atb":[[1.71,10.4]],"id":41207262},{"atl":[[2.42,9.39]],"id":43167130}],"con":true,"img":false}]}
{"op":"mcm","clk":"5353185859","pt":1646210521226,"mc":[{"id":"1.195503849","rc":[{"atl":[[2.44,2.84],[2.42,11.39]],"id":43167130}],"con":true,"img":false}]}
{"op":"mcm","clk":"5353185911","pt":1646210522003,"mc":[{"id":"1.195503849","rc":[{"atb":[[1.76,1.42]],"id":41207262},{"atl":[[2.32,1.42]],"id":43167130}],"con":true,"img":false}]}
{"op":"mcm","clk":"5353185995","pt":1646210523448,"mc":[{"id":"1.195503849","rc":[{"atb":[[1.73,1.42]],"id":41207262},{"atl":[[2.32,0],[2.38,1.42]],"id":43167130}],"con":true,"img":false}]}
{"op":"mcm","clk":"5353186048","pt":1646210524634,"mc":[{"id":"1.195503849","rc":[{"atl":[[2.4,1.42]],"id":43167130}],"con":true,"img":false}]}
{"op":"mcm","clk":"5353186053","pt":1646210524737,"mc":[{"id":"1.195503849","rc":[{"atb":[[1.76,0]],"id":41207262}],"con":true,"img":false}]}
{"op":"mcm","clk":"5353186125","pt":1646210526023,"mc":[{"id":"1.195503849","rc":[{"atb":[[1.77,1.42]],"id":41207262},{"atl":[[2.38,0]],"id":43167130}],"con":true,"img":false}]}
{"op":"mcm","clk":"5353186206","pt":1646210527512,"mc":[{"id":"1.195503849","rc":[{"atb":[[1.77,0]],"id":41207262}],"con":true,"img":false}]}
{"op":"mcm","clk":"5353186260","pt":1646210528747,"mc":[{"id":"1.195503849","rc":[{"atb":[[1.77,1.42]],"id":41207262},{"atl":[[2.28,1.42]],"id":43167130}],"con":true,"img":false}]}
{"op":"mcm","clk":"5353186332","pt":1646210530139,"mc":[{"id":"1.195503849","rc":[{"atb":[[1.72,1.42]],"id":41207262}],"con":true,"img":false}]}
{"op":"mcm","clk":"5353186383","pt":1646210531218,"mc":[{"id":"1.195503849","rc":[{"atl":[[2.38,1.42]],"id":43167130}],"con":true,"img":false}]}
{"op":"mcm","clk":"5353186422","pt":1646210531772,"mc":[{"id":"1.195503849","rc":[{"atb":[[1.77,10.39]],"id":41207262}],"con":true,"img":false}]}
{"op":"mcm","clk":"5353186432","pt":1646210531839,"mc":[{"id":"1.195503849","rc":[{"atl":[[2.28,10.82]],"id":43167130}],"con":true,"img":false}]}
{"op":"mcm","clk":"5353186558","pt":1646210533746,"mc":[{"id":"1.195503849","rc":[{"atb":[[1.79,1.42]],"id":41207262},{"atl":[[2.26,1.42]],"id":43167130}],"con":true,"img":false}]}
{"op":"mcm","clk":"5353186640","pt":1646210535042,"mc":[{"id":"1.195503849","rc":[{"atb":[[1.8,1.42]],"id":41207262}],"con":true,"img":false}]}
{"op":"mcm","clk":"5353186650","pt":1646210535248,"mc":[{"id":"1.195503849","rc":[{"atl":[[1.96,0]],"id":41207262},{"atl":[[2.26,0]],"id":43167130}],"con":true,"img":false}]}
{"op":"mcm","clk":"5353186660","pt":1646210535455,"mc":[{"id":"1.195503849","rc":[{"atb":[[1.8,10.39]],"id":41207262},{"atl":[[1.98,3.42],[1.97,0]],"id":41207262},{"atl":[[2.26,9.41]],"id":43167130}],"con":true,"img":false}]}
{"op":"mcm","clk":"5353186759","pt":1646210537258,"mc":[{"id":"1.195503849","rc":[{"atb":[[1.77,8.97]],"id":41207262},{"atl":[[2.44,0]],"id":43167130}],"con":true,"img":false}]}
{"op":"mcm","clk":"5353186849","pt":1646210538443,"mc":[{"id":"1.195503849","rc":[{"atl":[[2.24,1.42]],"id":43167130}],"con":true,"img":false}]}
{"op":"mcm","clk":"5353186860","pt":1646210538648,"mc":[{"id":"1.195503849","rc":[{"atl":[[2.46,0]],"id":43167130}],"con":true,"img":false}]}
{"op":"mcm","clk":"5353186872","pt":1646210538854,"mc":[{"id":"1.195503849","rc":[{"atl":[[2.24,10.88]],"id":43167130}],"con":true,"img":false}]}
{"op":"mcm","clk":"5353186920","pt":1646210539626,"mc":[{"id":"1.195503849","rc":[{"atl":[[2.24,12.3]],"id":43167130}],"con":true,"img":false}]}
{"op":"mcm","clk":"5353186953","pt":1646210540246,"mc":[{"id":"1.195503849","rc":[{"atb":[[1.71,8.98]],"id":41207262},{"atl":[[2.28,9.4]],"id":43167130}],"con":true,"img":false}]}
{"op":"mcm","clk":"5353187115","pt":1646210543336,"mc":[{"id":"1.195503849","rc":[{"atl":[[1.98,2],[2.08,0]],"id":41207262},{"atb":[[2.04,0]],"id":43167130}],"con":true,"img":false}]}
{"op":"mcm","clk":"5353187125","pt":1646210543440,"mc":[{"id":"1.195503849","rc":[{"atl":[[1.98,0],[2.06,3.42]],"id":41207262}],"con":true,"img":false}]}
{"op":"mcm","clk":"5353187201","pt":1646210544931,"mc":[{"id":"1.195503849","rc":[{"atb":[[2.08,0]],"id":43167130}],"con":true,"img":false}]}
{"op":"mcm","clk":"5353187209","pt":1646210545032,"mc":[{"id":"1.195503849","rc":[{"atb":[[2,3.42]],"id":43167130}],"con":true,"img":false}]}
{"op":"mcm","clk":"5353187215","pt":1646210545137,"mc":[{"id":"1.195503849","rc":[{"atb":[[2.02,0]],"id":43167130}],"con":true,"img":false}]}
{"op":"mcm","clk":"5353187288","pt":1646210546371,"mc":[{"id":"1.195503849","rc":[{"atb":[[1.83,1.42],[1.72,0]],"id":41207262},{"atb":[[2,2],[1.92,1.42]],"id":43167130},{"atl":[[2.22,1.42]],"id":43167130}],"con":true,"img":false}]}
{"op":"mcm","clk":"5353187334","pt":1646210547245,"mc":[{"id":"1.195503849","rc":[{"atb":[[1.83,10.33]],"id":41207262},{"atl":[[2.22,10.88],[2.42,2]],"id":43167130}],"con":true,"img":false}]}
{"op":"mcm","clk":"5353187352","pt":1646210547658,"mc":[{"id":"1.195503849","rc":[{"atb":[[1.82,1.42]],"id":41207262},{"atb":[[1.91,1.42]],"id":43167130}],"con":true,"img":false}]}
{"op":"mcm","clk":"5353187358","pt":1646210547760,"mc":[{"id":"1.195503849","rc":[{"atb":[[1.73,0]],"id":41207262},{"atl":[[2.22,9.46]],"id":43167130}],"con":true,"img":false}]}
{"op":"mcm","clk":"5353187414","pt":1646210548841,"mc":[{"id":"1.195503849","rc":[{"atb":[[1.85,1.42]],"id":41207262},{"atb":[[1.93,1.42]],"id":43167130},{"atl":[[2.4,0],[2.38,0],[2.18,1.42]],"id":43167130}],"con":true,"img":false}]}
{"op":"mcm","clk":"5353187499","pt":1646210550177,"mc":[{"id":"1.195503849","rc":[{"atb":[[2,0],[1.99,3.42]],"id":43167130}],"con":true,"img":false}]}
{"op":"mcm","clk":"5353187505","pt":1646210550280,"mc":[{"id":"1.195503849","rc":[{"atl":[[2.2,1.42]],"id":43167130}],"con":true,"img":false}]}
{"op":"mcm","clk":"5353187589","pt":1646210551682,"mc":[{"id":"1.195503849","rc":[{"atb":[[1.86,1.42]],"id":41207262},{"atb":[[1.99,2]],"id":43167130},{"atl":[[2.18,0]],"id":43167130}],"con":true,"img":false}]}
{"op":"mcm","clk":"5353187664","pt":1646210553067,"mc":[{"id":"1.195503849","rc":[{"atl":[[2.16,1.42]],"id":43167130}],"con":true,"img":false}]}
{"op":"mcm","clk":"5353187669","pt":1646210553169,"mc":[{"id":"1.195503849","rc":[{"atb":[[1.86,0]],"id":41207262}],"con":true,"img":false}]}
{"op":"mcm","clk":"5353187694","pt":1646210553584,"mc":[{"id":"1.195503849","rc":[{"atb":[[1.85,10.27]],"id":41207262},{"atl":[[2.16,10.92]],"id":43167130}],"con":true,"img":false}]}
{"op":"mcm","clk":"5353187707","pt":1646210553739,"mc":[{"id":"1.195503849","rc":[{"atb":[[1.71,0]],"id":41207262},{"atl":[[2.28,0]],"id":43167130}],"con":true,"img":false}]}
{"op":"mcm","clk":"5353187723","pt":1646210554047,"mc":[{"id":"1.195503849","rc":[{"atb":[[1.87,1.42]],"id":41207262}],"con":true,"img":false}]}
{"op":"mcm","clk":"5353187754","pt":1646210554764,"mc":[{"id":"1.195503849","rc":[{"atb":[[1.82,0],[1.79,0]],"id":41207262},{"atl":[[2.24,9.45]],"id":43167130}],"con":true,"img":false}]}
{"op":"mcm","clk":"5353187782","pt":1646210555378,"mc":[{"id":"1.195503849","rc":[{"atb":[[1.98,4.84],[1.99,0]],"id":43167130}],"con":true,"img":false}]}
{"op":"mcm","clk":"5353187798","pt":1646210555635,"mc":[{"id":"1.195503849","rc":[{"atb":[[1.87,2.84]],"id":41207262},{"atl":[[2.14,1.42]],"id":43167130}],"con":true,"img":false}]}
{"op":"mcm","clk":"5353187850","pt":1646210556767,"mc":[{"id":"1.195503849","rc":[{"atb":[[1.73,2],[1.67,1.42]],"id":41207262},{"atl":[[2.34,2],[2.42,0]],"id":43167130}],"con":true,"img":false}]}
{"op":"mcm","clk":"5353187855","pt":1646210556868,"mc":[{"id":"1.195503849","rc":[{"atb":[[1.88,8.85]],"id":41207262},{"atl":[[2.26,0],[2.14,10.93]],"id":43167130}],"con":true,"img":false}]}
{"op":"mcm","clk":"5353187862","pt":1646210556973,"mc":[{"id":"1.195503849","rc":[{"atb":[[1.77,0]],"id":41207262}],"con":true,"img":false}]}
{"op":"mcm","clk":"5353187883","pt":1646210557387,"mc":[{"id":"1.195503849","rc":[{"atb":[[1.89,1.42]],"id":41207262},{"atl":[[2.14,9.5]],"id":43167130}],"con":true,"img":false}]}
{"op":"mcm","clk":"5353187964","pt":1646210558676,"mc":[{"id":"1.195503849","rc":[{"atb":[[1.89,11.69]],"id":41207262}],"con":true,"img":false}]}
{"op":"mcm","clk":"5353187970","pt":1646210558778,"mc":[{"id":"1.195503849","rc":[{"atb":[[1.8,1.42]],"id":41207262}],"con":true,"img":false}]}
{"op":"mcm","clk":"5353187997","pt":1646210559192,"mc":[{"id":"1.195503849","rc":[{"atb":[[1.83,8.9],[1.85,8.85],[1.8,0]],"id":41207262},{"atl":[[2.2,0]],"id":43167130}],"con":true,"img":false}]}
{"op":"mcm","clk":"5353188034","pt":1646210559862,"mc":[{"id":"1.195503849","rc":[{"atl":[[2.16,1.42]],"id":41207262},{"atl":[[2.12,1.42]],"id":43167130}],"con":true,"img":false}]}
{"op":"mcm","clk":"5353188063","pt":1646210560483,"mc":[{"id":"1.195503849","rc":[{"atb":[[1.87,0],[1.9,8.84]],"id":41207262},{"atl":[[2.12,10.95],[2.24,0],[2.16,9.49]],"id":43167130}],"con":true,"img":false}]}
{"op":"mcm","clk":"5353188072","pt":1646210560685,"mc":[{"id":"1.195503849","rc":[{"atb":[[1.83,0]],"id":41207262}],"con":true,"img":false}]}
{"op":"mcm","clk":"5353188157","pt":1646210561975,"mc":[{"id":"1.195503849","rc":[{"atl":[[2.3,2],[2.34,0]],"id":43167130}],"con":true,"img":false}]}
{"op":"mcm","clk":"5353188448","pt":1646210568154,"mc":[{"id":"1.195503849","rc":[{"atb":[[1.69,0]],"id":41207262}],"con":true,"img":false}]}
{"op":"mcm","clk":"5353188693","pt":1646210572997,"mc":[{"id":"1.195503849","rc":[{"atb":[[1.28,0],[1.68,0],[1.48,0]],"id":41207262},{"atb":[[1.68,0],[1.48,0],[1.88,15]],"id":43167130}],"con":true,"img":false}]}
{"op":"mcm","clk":"5353188740","pt":1646210574084,"mc":[{"id":"1.195503849","rc":[{"atl":[[2.5,0]],"id":43167130}],"con":true,"img":false}]}
{"op":"mcm","clk":"5353189138","pt":1646210582332,"mc":[{"id":"1.195503849","rc":[{"atb":[[1.28,19.3],[1.68,7.94],[1.48,11.26]],"id":41207262},{"atb":[[1.68,7.94],[1.48,11.26],[1.88,21.14]],"id":43167130}],"con":true,"img":false}]}
{"op":"mcm","clk":"5353189615","pt":1646210590606,"mc":[{"id":"1.195503849","rc":[{"atl":[[2.12,10.19]],"id":41207262}],"con":true,"img":false}]}
{"op":"mcm","clk":"5353190155","pt":1646210599611,"mc":[{"id":"1.195503849","rc":[{"atl":[[2.1,10.31]],"id":41207262}],"con":true,"img":false}]}
{"op":"mcm","clk":"5353190245","pt":1646210601408,"mc":[{"id":"1.195503849","rc":[{"atl":[[2.1,1.42]],"id":41207262}],"con":true,"img":false}]}
{"op":"mcm","clk":"5353190254","pt":1646210601620,"mc":[{"id":"1.195503849","rc":[{"atl":[[2.1,10.34]],"id":41207262}],"con":true,"img":false}]}
{"op":"mcm","clk":"5353190261","pt":1646210601829,"mc":[{"id":"1.195503849","rc":[{"atl":[[2.1,1.42]],"id":41207262}],"con":true,"img":false}]}
{"op":"mcm","clk":"5353190556","pt":1646210608028,"mc":[{"id":"1.195503849","rc":[{"atl":[[2.1,10.37]],"id":41207262}],"con":true,"img":false}]}
{"op":"mcm","clk":"5353191301","pt":1646210624462,"mc":[{"id":"1.195503849","rc":[{"atl":[[2.1,1.42]],"id":41207262}],"con":true,"img":false}]}
{"op":"mcm","clk":"5353191335","pt":1646210625280,"mc":[{"id":"1.195503849","rc":[{"atl":[[2.1,10.29]],"id":41207262}],"con":true,"img":false}]}
{"op":"mcm","clk":"5353191388","pt":1646210626770,"mc":[{"id":"1.195503849","rc":[{"atl":[[2.1,1.42]],"id":41207262}],"con":true,"img":false}]}
{"op":"mcm","clk":"5353191643","pt":1646210632492,"mc":[{"id":"1.195503849","rc":[{"atl":[[2.12,1.42]],"id":41207262}],"con":true,"img":false}]}
{"op":"mcm","clk":"5353191684","pt":1646210633583,"mc":[{"id":"1.195503849","rc":[{"atl":[[2.12,10.2]],"id":41207262}],"con":true,"img":false}]}
{"op":"mcm","clk":"5353191691","pt":1646210633685,"mc":[{"id":"1.195503849","rc":[{"atb":[[1.28,0],[1.68,0],[1.48,0]],"id":41207262},{"atb":[[1.68,0],[1.48,0],[1.88,15]],"id":43167130}],"con":true,"img":false}]}
{"op":"mcm","clk":"5353191962","pt":1646210640105,"mc":[{"id":"1.195503849","rc":[{"atl":[[2,24.01]],"id":41207262}],"con":true,"img":false}]}
{"op":"mcm","clk":"5353191970","pt":1646210640268,"mc":[{"id":"1.195503849","rc":[{"atl":[[2,29.12],[2.06,1.42]],"id":41207262},{"trd":[[2,25.16]],"ltp":2.0,"tv":25.16,"id":41207262}],"con":true,"img":false}]}
{"op":"mcm","clk":"5353191973","pt":1646210640371,"mc":[{"id":"1.195503849","rc":[{"atl":[[2,5.56],[2.12,1.42],[2.1,10.21]],"id":41207262},{"trd":[[2,72.28]],"ltp":2.0,"tv":72.28,"id":41207262}],"con":true,"img":false}]}
{"op":"mcm","clk":"5353191980","pt":1646210640578,"mc":[{"id":"1.195503849","rc":[{"atb":[[1.9,12.03]],"id":41207262}],"con":true,"img":false}]}
{"op":"mcm","clk":"5353192166","pt":1646210644108,"mc":[{"id":"1.195503849","rc":[{"atb":[[1.4,13.5],[1.8,6.75],[1.6,9]],"id":41207262},{"atb":[[1.6,9],[1.4,13.5],[1.8,8.75]],"id":43167130}],"con":true,"img":false}]}
{"op":"mcm","clk":"5353192425","pt":1646210650514,"mc":[{"id":"1.195503849","rc":[{"atl":[[2.1,1.42]],"id":41207262}],"con":true,"img":false}]}
{"op":"mcm","clk":"5353192695","pt":1646210655698,"mc":[{"id":"1.195503849","rc":[{"atl":[[2.1,10.1]],"id":41207262}],"con":true,"img":false}]}
{"op":"mcm","clk":"5353192991","pt":1646210661009,"mc":[{"id":"1.195503849","rc":[{"atl":[[2.1,1.42]],"id":41207262}],"con":true,"img":false}]}
{"op":"mcm","clk":"5353193091","pt":1646210662918,"mc":[{"id":"1.195503849","rc":[{"atl":[[2.06,0],[2.12,0],[2.16,0]],"id":41207262}],"con":true,"img":false}]}
{"op":"mcm","clk":"5353193229","pt":1646210665647,"mc":[{"id":"1.195503849","rc":[{"atb":[[1.95,0],[1.97,0]],"id":43167130}],"con":true,"img":false}]}
{"op":"mcm","clk":"5353193348","pt":1646210668428,"mc":[{"id":"1.195503849","rc":[{"atl":[[2.1,0]],"id":41207262},{"atb":[[1.96,0]],"id":43167130}],"con":true,"img":false}]}
{"op":"mcm","clk":"5353193401","pt":1646210669312,"mc":[{"id":"1.195503849","rc":[{"atb":[[1.91,11.12]],"id":43167130}],"con":true,"img":false}]}
{"op":"mcm","clk":"5353193596","pt":1646210672822,"mc":[{"id":"1.195503849","rc":[{"atb":[[1.89,1.42]],"id":43167130}],"con":true,"img":false}]}
{"op":"mcm","clk":"5353193722","pt":1646210675545,"mc":[{"id":"1.195503849","rc":[{"atl":[[2,0],[2.04,23.4]],"id":41207262},{"atb":[[1.98,2.84],[1.97,12.35]],"id":43167130}],"con":true,"img":false}]}
{"op":"mcm","clk":"5353193847","pt":1646210678533,"mc":[{"id":"1.195503849","rc":[{"atb":[[1.93,0]],"id":43167130}],"con":true,"img":false}]}
{"op":"mcm","clk":"5353193959","pt":1646210680649,"mc":[{"id":"1.195503849","rc":[{"atb":[[1.96,19.01],[1.97,0]],"id":43167130}],"con":true,"img":false}]}
{"op":"mcm","clk":"5353193970","pt":1646210680857,"mc":[{"id":"1.195503849","rc":[{"atl":[[2.02,1.42]],"id":41207262}],"con":true,"img":false}]}
{"op":"mcm","clk":"5353194072","pt":1646210682466,"mc":[{"id":"1.195503849","rc":[{"atl":[[2.02,2.84]],"id":41207262}],"con":true,"img":false}]}
{"op":"mcm","clk":"5353194120","pt":1646210683348,"mc":[{"id":"1.195503849","rc":[{"atb":[[1.92,11]],"id":43167130}],"con":true,"img":false}]}
{"op":"mcm","clk":"5353194227","pt":1646210684961,"mc":[{"id":"1.195503849","rc":[{"atb":[[1.99,1.42]],"id":43167130}],"con":true,"img":false}]}
{"op":"mcm","clk":"5353194279","pt":1646210685840,"mc":[{"id":"1.195503849","rc":[{"atb":[[1.96,0],[1.97,19.01]],"id":43167130}],"con":true,"img":false}]}
{"op":"mcm","clk":"5353194335","pt":1646210687382,"mc":[{"id":"1.195503849","rc":[{"atb":[[1.99,0]],"id":43167130}],"con":true,"img":false}]}
{"op":"mcm","clk":"5353194420","pt":1646210689238,"mc":[{"id":"1.195503849","rc":[{"atb":[[1.99,1.42]],"id":43167130}],"con":true,"img":false}]}
{"op":"mcm","clk":"5353194429","pt":1646210689340,"mc":[{"id":"1.195503849","rc":[{"atb":[[1.98,21.85],[1.97,0]],"id":43167130}],"con":true,"img":false}]}
{"op":"mcm","clk":"5353194505","pt":1646210691247,"mc":[{"id":"1.195503849","rc":[{"atb":[[1.97,1.42]],"id":43167130}],"con":true,"img":false}]}
{"op":"mcm","clk":"5353194512","pt":1646210691351,"mc":[{"id":"1.195503849","rc":[{"atb":[[1.99,0]],"id":43167130}],"con":true,"img":false}]}
{"op":"mcm","clk":"5353194554","pt":1646210692590,"mc":[{"id":"1.195503849","rc":[{"atb":[[1.98,2.84],[1.97,20.43]],"id":43167130}],"con":true,"img":false}]}
{"op":"mcm","clk":"5353194584","pt":1646210693367,"mc":[{"id":"1.195503849","rc":[{"atb":[[1.4,0],[1.8,0],[1.6,0]],"id":41207262},{"atb":[[1.6,0],[1.4,0],[1.8,2]],"id":43167130}],"con":true,"img":false}]}
{"op":"mcm","clk":"5353194596","pt":1646210693682,"mc":[{"id":"1.195503849","rc":[{"atb":[[1.99,1.42]],"id":43167130}],"con":true,"img":false}]}
{"op":"mcm","clk":"5353194716","pt":1646210696166,"mc":[{"id":"1.195503849","rc":[{"atb":[[1.93,1.42],[1.99,0]],"id":43167130}],"con":true,"img":false}]}
{"op":"mcm","clk":"5353194761","pt":1646210697047,"mc":[{"id":"1.195503849","rc":[{"atl":[[2,12]],"id":41207262}],"con":true,"img":false}]}
{"op":"mcm","clk":"5353194766","pt":1646210697149,"mc":[{"id":"1.195503849","rc":[{"atb":[[1.93,10.91]],"id":43167130}],"con":true,"img":false}]}
{"op":"mcm","clk":"5353194779","pt":1646210697460,"mc":[{"id":"1.195503849","rc":[{"atb":[[1.93,12.34]],"id":43167130}],"con":true,"img":false}]}
{"op":"mcm","clk":"5353194820","pt":1646210698495,"mc":[{"id":"1.195503849","rc":[{"atb":[[1.94,9.48]],"id":43167130}],"con":true,"img":false}]}
{"op":"mcm","clk":"5353194905","pt":1646210700096,"mc":[{"id":"1.195503849","rc":[{"atb":[[1.99,1.42]],"id":43167130}],"con":true,"img":false}]}
{"op":"mcm","clk":"5353194915","pt":1646210700253,"mc":[{"id":"1.195503849","rc":[{"atb":[[1.94,0]],"id":43167130}],"con":true,"img":false}]}
{"op":"mcm","clk":"5353195040","pt":1646210702395,"mc":[{"id":"1.195503849","rc":[{"atb":[[1.99,2.84]],"id":43167130}],"con":true,"img":false}]}
{"op":"mcm","clk":"5353195113","pt":1646210703792,"mc":[{"id":"1.195503849","rc":[{"atb":[[1.95,12.35],[1.97,1.42]],"id":43167130}],"con":true,"img":false}]}
{"op":"mcm","clk":"5353195189","pt":1646210705190,"mc":[{"id":"1.195503849","rc":[{"atb":[[1.45,12],[1.85,15.21],[1.65,8.31]],"id":41207262},{"atb":[[1.51,10.59],[1.71,7.6],[1.31,17.43]],"id":43167130}],"con":true,"img":false}]}
{"op":"mcm","clk":"5353195192","pt":1646210705295,"mc":[{"id":"1.195503849","rc":[{"atb":[[1.93,2.84]],"id":43167130}],"con":true,"img":false}]}
{"op":"mcm","clk":"5353195237","pt":1646210706181,"mc":[{"id":"1.195503849","rc":[{"atb":[[1.92,1.42]],"id":43167130}],"con":true,"img":false}]}
{"op":"mcm","clk":"5353195369","pt":1646210708914,"mc":[{"id":"1.195503849","rc":[{"atl":[[2.06,23.4],[2.04,0]],"id":41207262}],"con":true,"img":false}]}
{"op":"mcm","clk":"5353195385","pt":1646210709275,"mc":[{"id":"1.195503849","rc":[{"atb":[[1.93,0],[1.92,0]],"id":43167130}],"con":true,"img":false}]}
{"op":"mcm","clk":"5353195450","pt":1646210710512,"mc":[{"id":"1.195503849","rc":[{"atb":[[1.94,12.35],[1.95,0],[1.88,0]],"id":43167130}],"con":true,"img":false}]}
{"op":"mcm","clk":"5353195490","pt":1646210711186,"mc":[{"id":"1.195503849","rc":[{"atb":[[1.96,1.42]],"id":43167130}],"con":true,"img":false}]}
{"op":"mcm","clk":"5353195516","pt":1646210711701,"mc":[{"id":"1.195503849","rc":[{"atb":[[1.91,1.42]],"id":43167130}],"con":true,"img":false}]}
{"op":"mcm","clk":"5353195608","pt":1646210713401,"mc":[{"id":"1.195503849","rc":[{"atb":[[1.95,1.42]],"id":43167130}],"con":true,"img":false}]}
{"op":"mcm","clk":"5353195626","pt":1646210713812,"mc":[{"id":"1.195503849","rc":[{"atb":[[1.89,0],[1.91,0]],"id":43167130}],"con":true,"img":false}]}
{"op":"mcm","clk":"5353195885","pt":1646210719493,"mc":[{"id":"1.195503849","rc":[{"atb":[[1.9,19.55]],"id":41207262},{"atl":[[2.12,18.16]],"id":43167130}],"con":true,"img":false}]}
{"op":"mcm","clk":"5353195993","pt":1646210722232,"mc":[{"id":"1.195503849","rc":[{"atb":[[1.89,8.84]],"id":41207262}],"con":true,"img":false}]}
{"op":"mcm","clk":"5353196301","pt":1646210729100,"mc":[{"id":"1.195503849","rc":[{"atb":[[1.94,0],[1.95,13.77]],"id":43167130}],"con":true,"img":false}]}
{"op":"mcm","clk":"5353196383","pt":1646210731031,"mc":[{"id":"1.195503849","rc":[{"atb":[[1.9,52.03]],"id":41207262},{"atb":[[1.96,31.87]],"id":43167130}],"con":true,"img":false}]}
{"op":"mcm","clk":"5353196547","pt":1646210734529,"mc":[{"id":"1.195503849","rc":[{"atl":[[2.06,0],[2.08,17.7]],"id":41207262},{"atb":[[1.95,1.42],[1.92,12.35],[1.86,0]],"id":43167130},{"atl":[[2.3,0],[2.26,12.35]],"id":43167130}],"con":true,"img":false}]}
{"op":"mcm","clk":"5353196561","pt":1646210734940,"mc":[{"id":"1.195503849","rc":[{"atb":[[1.96,1.42],[1.93,31.42]],"id":43167130}],"con":true,"img":false}]}
{"op":"mcm","clk":"5353196566","pt":1646210735044,"mc":[{"id":"1.195503849","rc":[{"atl":[[2.04,17.7],[2.08,0]],"id":41207262},{"atb":[[1.95,13.77],[1.92,0]],"id":43167130}],"con":true,"img":false}]}
{"op":"mcm","clk":"5353196606","pt":1646210735819,"mc":[{"id":"1.195503849","rc":[{"atb":[[1.83,1.42]],"id":41207262},{"atb":[[1.95,12.35]],"id":43167130},{"atl":[[2.2,1.42]],"id":43167130}],"con":true,"img":false}]}
{"op":"mcm","clk":"5353196713","pt":1646210738442,"mc":[{"id":"1.195503849","rc":[{"atb":[[1.84,1.42]],"id":41207262},{"atl":[[2.24,1.42]],"id":43167130}],"con":true,"img":false}]}
{"op":"mcm","clk":"5353196870","pt":1646210742353,"mc":[{"id":"1.195503849","rc":[{"atb":[[1.9,44.51]],"id":41207262},{"atl":[[2,22.54]],"id":41207262},{"atb":[[1.99,8.54]],"id":43167130},{"atl":[[2.12,10.95]],"id":43167130}],"con":true,"img":false}]}
{"op":"mcm","clk":"5353196895","pt":1646210742919,"mc":[{"id":"1.195503849","rc":[{"atb":[[2,29.23]],"id":43167130}],"con":true,"img":false}]}
{"op":"mcm","clk":"5353196903","pt":1646210743123,"mc":[{"id":"1.195503849","rc":[{"atb":[[1.99,2.84]],"id":43167130}],"con":true,"img":false}]}
{"op":"mcm","clk":"5353196915","pt":1646210743431,"mc":[{"id":"1.195503849","rc":[{"atb":[[2,10.5]],"id":43167130}],"con":true,"img":false}]}
{"op":"mcm","clk":"5353196922","pt":1646210743738,"mc":[{"id":"1.195503849","rc":[{"atb":[[2,0]],"id":43167130}],"con":true,"img":false}]}
{"op":"mcm","clk":"5353196925","pt":1646210743841,"mc":[{"id":"1.195503849","rc":[{"atl":[[2,12]],"id":41207262},{"atl":[[2.24,0],[2.2,0]],"id":43167130}],"con":true,"img":false}]}
{"op":"mcm","clk":"5353196926","pt":1646210743943,"mc":[{"id":"1.195503849","rc":[{"atb":[[1.99,32.37]],"id":43167130}],"con":true,"img":false}]}
{"op":"mcm","clk":"5353196939","pt":1646210744253,"mc":[{"id":"1.195503849","rc":[{"atb":[[1.96,20.43],[1.95,0]],"id":43167130}],"con":true,"img":false}]}
{"op":"mcm","clk":"5353196954","pt":1646210744561,"mc":[{"id":"1.195503849","rc":[{"atb":[[1.99,2.84]],"id":43167130}],"con":true,"img":false}]}
{"op":"mcm","clk":"5353196973","pt":1646210744920,"mc":[{"id":"1.195503849","rc":[{"atb":[[1.97,31.55]],"id":43167130}],"con":true,"img":false}]}
{"op":"mcm","clk":"5353197126","pt":1646210748426,"mc":[{"id":"1.195503849","rc":[{"atl":[[2.16,1.42]],"id":41207262}],"con":true,"img":false}]}
{"op":"mcm","clk":"5353197148","pt":1646210748837,"mc":[{"id":"1.195503849","rc":[{"atl":[[2.16,10.13]],"id":41207262}],"con":true,"img":false}]}
{"op":"mcm","clk":"5353197185","pt":1646210749558,"mc":[{"id":"1.195503849","rc":[{"atb":[[1.9,56.45]],"id":41207262},{"atl":[[2.12,22.12]],"id":43167130}],"con":true,"img":false}]}
{"op":"mcm","clk":"5353197336","pt":1646210752235,"mc":[{"id":"1.195503849","rc":[{"atl":[[2.24,1.42]],"id":43167130}],"con":true,"img":false}]}
{"op":"mcm","clk":"5353197338","pt":1646210752339,"mc":[{"id":"1.195503849","rc":[{"atb":[[1.64,0],[1.83,0],[1.84,0],[1.67,0]],"id":41207262}],"con":true,"img":false}]}
{"op":"mcm","clk":"5353197394","pt":1646210753656,"mc":[{"id":"1.195503849","rc":[{"atb":[[1.45,0],[1.85,8.85],[1.65,0]],"id":41207262},{"atb":[[1.51,0],[1.71,0],[1.31,0]],"id":43167130}],"con":true,"img":false}]}
{"op":"mcm","clk":"5353197421","pt":1646210754333,"mc":[{"id":"1.195503849","rc":[{"atl":[[2.2,1.42]],"id":43167130}],"con":true,"img":false}]}
{"op":"mcm","clk":"5353197429","pt":1646210754537,"mc":[{"id":"1.195503849","rc":[{"atb":[[1.96,1.42],[1.95,19.01]],"id":43167130}],"con":true,"img":false}]}
{"op":"mcm","clk":"5353197477","pt":1646210755566,"mc":[{"id":"1.195503849","rc":[{"atl":[[2.2,2.84]],"id":43167130}],"con":true,"img":false}]}
{"op":"mcm","clk":"5353197721","pt":1646210760166,"mc":[{"id":"1.195503849","rc":[{"atl":[[2.04,0]],"id":41207262}],"con":true,"img":false}]}
{"op":"mcm","clk":"5353197742","pt":1646210760483,"mc":[{"id":"1.195503849","rc":[{"atb":[[1.96,31.87],[1.97,1.42]],"id":43167130}],"con":true,"img":false}]}
{"op":"mcm","clk":"5353197930","pt":1646210763176,"mc":[{"id":"1.195503849","rc":[{"atb":[[1.83,0],[1.84,0],[1.85,0],[1.95,0],[1.82,0],[1.8,0],[1.86,2]],"id":43167130}],"con":true,"img":false}]}
{"op":"mcm","clk":"5353197951","pt":1646210763486,"mc":[{"id":"1.195503849","rc":[{"atb":[[1.96,1.42],[1.93,0],[1.87,33.6]],"id":43167130}],"con":true,"img":false}]}
{"op":"mcm","clk":"5353197983","pt":1646210763954,"mc":[{"id":"1.195503849","rc":[{"atb":[[1.9,23.97]],"id":41207262}],"con":true,"img":false}]}
{"op":"mcm","clk":"5353198013","pt":1646210764469,"mc":[{"id":"1.195503849","rc":[{"atb":[[1.85,43.24]],"id":41207262}],"con":true,"img":false}]}
{"op":"mcm","clk":"5353198037","pt":1646210765138,"mc":[{"id":"1.195503849","rc":[{"atb":[[1.88,19.33]],"id":43167130}],"con":true,"img":false}]}
{"op":"mcm","clk":"5353198048","pt":1646210765446,"mc":[{"id":"1.195503849","rc":[{"atb":[[1.89,32.84]],"id":43167130}],"con":true,"img":false}]}
{"op":"mcm","clk":"5353198059","pt":1646210765754,"mc":[{"id":"1.195503849","rc":[{"atl":[[2.02,0]],"id":41207262},{"atb":[[1.99,0],[1.98,0],[1.97,0],[1.96,0]],"id":43167130}],"con":true,"img":false}]}
{"op":"mcm","clk":"5353198064","pt":1646210765958,"mc":[{"id":"1.195503849","rc":[{"atb":[[1.89,0]],"id":43167130}],"con":true,"img":false}]}
{"op":"mcm","clk":"5353198090","pt":1646210766676,"mc":[{"id":"1.195503849","rc":[{"atb":[[1.9,12.03]],"id":41207262},{"atl":[[2.12,10.95]],"id":43167130}],"con":true,"img":false}]}
{"op":"mcm","clk":"5353198105","pt":1646210767142,"mc":[{"id":"1.195503849","rc":[{"atb":[[1.9,24.3]],"id":41207262},{"atl":[[2.12,22.42]],"id":43167130}],"con":true,"img":false}]}
{"op":"mcm","clk":"5353198113","pt":1646210767400,"mc":[{"id":"1.195503849","rc":[{"atb":[[1.83,6.51],[1.63,8.57],[1.43,12.56]],"id":41207262},{"atb":[[1.56,9.65],[1.36,15.01],[1.76,9.11]],"id":43167130}],"con":true,"img":false}]}
{"op":"mcm","clk":"5353198149","pt":1646210768275,"mc":[{"id":"1.195503849","rc":[{"atb":[[1.86,0],[1.87,75.36]],"id":43167130}],"con":true,"img":false}]}
{"op":"mcm","clk":"5353198159","pt":1646210768481,"mc":[{"id":"1.195503849","rc":[{"atb":[[1.88,9.66]],"id":43167130}],"con":true,"img":false}]}
{"op":"mcm","clk":"5353198329","pt":1646210771463,"mc":[{"id":"1.195503849","rc":[{"atl":[[2,5.93]],"id":41207262},{"trd":[[2,84.42]],"ltp":2.0,"tv":84.42,"id":41207262}],"con":true,"img":false}]}
{"op":"mcm","clk":"5353198332","pt":1646210771567,"mc":[{"id":"1.195503849","rc":[{"atl":[[2,0],[2.16,30.39]],"id":41207262},{"trd":[[2,96.3]],"ltp":2.0,"tv":96.3,"id":41207262},{"atb":[[1.79,0]],"id":43167130}],"con":true,"img":false}]}
{"op":"mcm","clk":"5353198340","pt":1646210771672,"mc":[{"id":"1.195503849","rc":[{"atb":[[1.9,1.42]],"id":43167130}],"con":true,"img":false}]}
{"op":"mcm","clk":"5353198346","pt":1646210771776,"mc":[{"id":"1.195503849","rc":[{"atl":[[2.14,8.62]],"id":41207262},{"atb":[[1.9,11.21]],"id":43167130}],"con":true,"img":false}]}
{"op":"mcm","clk":"5353198354","pt":1646210771982,"mc":[{"id":"1.195503849","rc":[{"atb":[[1.9,56.78]],"id":41207262}],"con":true,"img":false}]}
{"op":"mcm","clk":"5353198414","pt":1646210773377,"mc":[{"id":"1.195503849","rc":[{"atb":[[1.85,2],[1.87,33.6]],"id":43167130}],"con":true,"img":false}]}
{"op":"mcm","clk":"5353198443","pt":1646210773997,"mc":[{"id":"1.195503849","rc":[{"atl":[[2.1,1.42]],"id":41207262},{"atb":[[1.94,1.42]],"id":43167130},{"atl":[[2.06,1.42]],"id":43167130}],"con":true,"img":false}]}
{"op":"mcm","clk":"5353198569","pt":1646210775806,"mc":[{"id":"1.195503849","rc":[{"atb":[[1.89,1.42],[1.94,0]],"id":43167130},{"atl":[[2.08,1.42],[2.06,0]],"id":43167130}],"con":true,"img":false}]}
{"op":"mcm","clk":"5353198585","pt":1646210776093,"mc":[{"id":"1.195503849","rc":[{"atl":[[2.12,10.95]],"id":43167130}],"con":true,"img":false}]}
{"op":"mcm","clk":"5353198592","pt":1646210776173,"mc":[{"id":"1.195503849","rc":[{"atl":[[2.08,12.89]],"id":43167130}],"con":true,"img":false}]}
{"op":"mcm","clk":"5353198613","pt":1646210776481,"mc":[{"id":"1.195503849","rc":[{"atl":[[2.08,4.26]],"id":43167130}],"con":true,"img":false}]}
{"op":"mcm","clk":"5353198623","pt":1646210776685,"mc":[{"id":"1.195503849","rc":[{"atl":[[2.08,1.42]],"id":43167130}],"con":true,"img":false}]}
{"op":"mcm","clk":"5353198691","pt":1646210777988,"mc":[{"id":"1.195503849","rc":[{"atl":[[2.08,4.26]],"id":43167130}],"con":true,"img":false}]}
{"op":"mcm","clk":"5353198699","pt":1646210778198,"mc":[{"id":"1.195503849","rc":[{"atl":[[2.28,1.42]],"id":41207262},{"atb":[[1.93,1.42]],"id":43167130},{"atl":[[2.06,1.42]],"id":43167130}],"con":true,"img":false}]}
{"op":"mcm","clk":"5353198705","pt":1646210778407,"mc":[{"id":"1.195503849","rc":[{"atl":[[2,19.1]],"id":43167130}],"con":true,"img":false}]}
{"op":"mcm","clk":"5353198708","pt":1646210778511,"mc":[{"id":"1.195503849","rc":[{"atl":[[2.08,1.42]],"id":43167130}],"con":true,"img":false}]}
{"op":"mcm","clk":"5353198714","pt":1646210778615,"mc":[{"id":"1.195503849","rc":[{"atl":[[2.06,4.26]],"id":43167130}],"con":true,"img":false}]}
{"op":"mcm","clk":"5353198797","pt":1646210780285,"mc":[{"id":"1.195503849","rc":[{"atl":[[2.1,1.42]],"id":43167130}],"con":true,"img":false}]}
{"op":"mcm","clk":"5353198819","pt":1646210780803,"mc":[{"id":"1.195503849","rc":[{"atb":[[1.93,0]],"id":43167130}],"con":true,"img":false}]}
{"op":"mcm","clk":"5353198890","pt":1646210782298,"mc":[{"id":"1.195503849","rc":[{"atb":[[1.9,44.51]],"id":41207262},{"atl":[[2.06,1.42]],"id":43167130}],"con":true,"img":false}]}
{"op":"mcm","clk":"5353198913","pt":1646210782817,"mc":[{"id":"1.195503849","rc":[{"atb":[[1.9,53.75]],"id":41207262}],"con":true,"img":false}]}
{"op":"mcm","clk":"5353198949","pt":1646210783383,"mc":[{"id":"1.195503849","rc":[{"atl":[[2.1,10.11]],"id":41207262}],"con":true,"img":false}]}
{"op":"mcm","clk":"5353198965","pt":1646210783694,"mc":[{"id":"1.195503849","rc":[{"atb":[[1.9,44.51]],"id":41207262},{"atl":[[2.1,17.32]],"id":41207262},{"atb":[[1.9,19.84]],"id":43167130}],"con":true,"img":false}]}
{"op":"mcm","clk":"5353198972","pt":1646210783796,"mc":[{"id":"1.195503849","rc":[{"atb":[[1.91,9.67]],"id":43167130}],"con":true,"img":false}]}
{"op":"mcm","clk":"5353198984","pt":1646210784003,"mc":[{"id":"1.195503849","rc":[{"atb":[[1.9,11.21],[1.86,33.99],[1.87,0]],"id":43167130}],"con":true,"img":false}]}
{"op":"mcm","clk":"5353198989","pt":1646210784105,"mc":[{"id":"1.195503849","rc":[{"atb":[[1.91,18.3]],"id":43167130}],"con":true,"img":false}]}
{"op":"mcm","clk":"5353199020","pt":1646210784619,"mc":[{"id":"1.195503849","rc":[{"atb":[[1.92,9.63]],"id":43167130}],"con":true,"img":false}]}
{"op":"mcm","clk":"5353199038","pt":1646210784878,"mc":[{"id":"1.195503849","rc":[{"atl":[[2.16,28.96]],"id":41207262},{"atb":[[1.91,9.67]],"id":43167130}],"con":true,"img":false}]}
{"op":"mcm","clk":"5353199042","pt":1646210784980,"mc":[{"id":"1.195503849","rc":[{"atl":[[2.18,2],[2.16,8.7]],"id":41207262},{"atb":[[1.87,33.6],[1.92,18.26]],"id":43167130}],"con":true,"img":false}]}
{"op":"mcm","clk":"5353199048","pt":1646210785085,"mc":[{"id":"1.195503849","rc":[{"atb":[[1.9,51.73]],"id":41207262},{"atl":[[2.1,10.11]],"id":41207262}],"con":true,"img":false}]}
{"op":"mcm","clk":"5353199054","pt":1646210785188,"mc":[{"id":"1.195503849","rc":[{"atl":[[2.08,8.77]],"id":41207262}],"con":true,"img":false}]}
{"op":"mcm","clk":"5353199058","pt":1646210785291,"mc":[{"id":"1.195503849","rc":[{"atb":[[1.93,9.57],[1.92,9.63]],"id":43167130}],"con":true,"img":false}]}
{"op":"mcm","clk":"5353199064","pt":1646210785394,"mc":[{"id":"1.195503849","rc":[{"atb":[[1.88,0]],"id":43167130}],"con":true,"img":false}]}
{"op":"mcm","clk":"5353199123","pt":1646210786581,"mc":[{"id":"1.195503849","rc":[{"atb":[[1.9,44.51]],"id":41207262},{"atl":[[2.08,20.65]],"id":41207262},{"atb":[[1.93,22.08]],"id":43167130}],"con":true,"img":false}]}
{"op":"mcm","clk":"5353199131","pt":1646210786684,"mc":[{"id":"1.195503849","rc":[{"atb":[[1.94,9.5]],"id":43167130}],"con":true,"img":false}]}
{"op":"mcm","clk":"5353199135","pt":1646210786786,"mc":[{"id":"1.195503849","rc":[{"atl":[[2.06,8.87]],"id":41207262},{"atb":[[1.9,1.42]],"id":43167130}],"con":true,"img":false}]}
{"op":"mcm","clk":"5353199143","pt":1646210786991,"mc":[{"id":"1.195503849","rc":[{"atb":[[1.89,34.27],[1.93,9.57]],"id":43167130}],"con":true,"img":false}]}
{"op":"mcm","clk":"5353199149","pt":1646210787093,"mc":[{"id":"1.195503849","rc":[{"atl":[[2.26,1.42],[2.08,8.77]],"id":41207262},{"atb":[[1.94,22.01],[1.88,1.42]],"id":43167130}],"con":true,"img":false}]}
{"op":"mcm","clk":"5353199154","pt":1646210787196,"mc":[{"id":"1.195503849","rc":[{"atl":[[2.06,20.75]],"id":41207262}],"con":true,"img":false}]}
{"op":"mcm","clk":"5353199157","pt":1646210787299,"mc":[{"id":"1.195503849","rc":[{"atb":[[1.95,9.44]],"id":43167130}],"con":true,"img":false}]}
{"op":"mcm","clk":"5353199162","pt":1646210787403,"mc":[{"id":"1.195503849","rc":[{"atb":[[1.91,0]],"id":43167130}],"con":true,"img":false}]}
{"op":"mcm","clk":"5353199170","pt":1646210787507,"mc":[{"id":"1.195503849","rc":[{"atb":[[1.86,0]],"id":43167130}],"con":true,"img":false}]}
{"op":"mcm","clk":"5353199175","pt":1646210787608,"mc":[{"id":"1.195503849","rc":[{"atb":[[1.94,9.5]],"id":43167130}],"con":true,"img":false}]}
{"op":"mcm","clk":"5353199178","pt":1646210787712,"mc":[{"id":"1.195503849","rc":[{"atb":[[1.95,21.95]],"id":43167130}],"con":true,"img":false}]}
{"op":"mcm","clk":"5353199187","pt":1646210788021,"mc":[{"id":"1.195503849","rc":[{"atl":[[2.06,8.87]],"id":41207262},{"atb":[[1.95,9.44],[1.9,33.9]],"id":43167130}],"con":true,"img":false}]}
{"op":"mcm","clk":"5353199249","pt":1646210789412,"mc":[{"id":"1.195503849","rc":[{"atb":[[1.9,52.6]],"id":41207262},{"atl":[[2.2,1.42]],"id":41207262},{"atb":[[1.91,1.42]],"id":43167130}],"con":true,"img":false}]}
{"op":"mcm","clk":"5353199315","pt":1646210790493,"mc":[{"id":"1.195503849","rc":[{"atb":[[1.9,44.51]],"id":41207262}],"con":true,"img":false}]}
{"op":"mcm","clk":"5353199342","pt":1646210791112,"mc":[{"id":"1.195503849","rc":[{"atl":[[2.06,14.69]],"id":41207262}],"con":true,"img":false}]}
{"op":"mcm","clk":"5353199354","pt":1646210791525,"mc":[{"id":"1.195503849","rc":[{"atl":[[2.22,1.42]],"id":41207262}],"con":true,"img":false}]}
{"op":"mcm","clk":"5353199377","pt":1646210792198,"mc":[{"id":"1.195503849","rc":[{"atb":[[1.9,58.7]],"id":41207262},{"atl":[[2.06,8.87]],"id":41207262},{"atl":[[2,25.98]],"id":43167130}],"con":true,"img":false}]}
{"op":"mcm","clk":"5353199450","pt":1646210793693,"mc":[{"id":"1.195503849","rc":[{"atl":[[2,19.1]],"id":43167130}],"con":true,"img":false}]}
{"op":"mcm","clk":"5353199456","pt":1646210793796,"mc":[{"id":"1.195503849","rc":[{"atl":[[2.24,1.42]],"id":41207262}],"con":true,"img":false}]}
{"op":"mcm","clk":"5353199483","pt":1646210794415,"mc":[{"id":"1.195503849","rc":[{"atl":[[2.18,0],[2.16,10.7]],"id":41207262}],"con":true,"img":false}]}
{"op":"mcm","clk":"5353199516","pt":1646210795137,"mc":[{"id":"1.195503849","rc":[{"atl":[[2,25.53]],"id":43167130}],"con":true,"img":false}]}
{"op":"mcm","clk":"5353199521","pt":1646210795239,"mc":[{"id":"1.195503849","rc":[{"atl":[[2.24,2.84]],"id":41207262}],"con":true,"img":false}]}
{"op":"mcm","clk":"5353199575","pt":1646210796526,"mc":[{"id":"1.195503849","rc":[{"atb":[[1.9,44.51]],"id":41207262},{"atl":[[2.06,17.82]],"id":41207262},{"atb":[[1.95,18.44]],"id":43167130},{"atl":[[2,19.1]],"id":43167130}],"con":true,"img":false}]}
{"op":"mcm","clk":"5353199631","pt":1646210798022,"mc":[{"id":"1.195503849","rc":[{"atl":[[2.04,9.17]],"id":41207262},{"atb":[[1.96,9.17]],"id":43167130}],"con":true,"img":false}]}
{"op":"mcm","clk":"5353199636","pt":1646210798226,"mc":[{"id":"1.195503849","rc":[{"atl":[[2.14,0]],"id":41207262},{"trd":[[2,115.4]],"ltp":2.0,"tv":115.4,"id":41207262},{"atl":[[2,0.02]],"id":43167130},{"trd":[[2,19.08]],"ltp":2.0,"tv":19.08,"id":43167130}],"con":true,"img":false}]}
{"op":"mcm","clk":"5353199641","pt":1646210798332,"mc":[{"id":"1.195503849","rc":[{"atl":[[2.06,8.87]],"id":41207262},{"atb":[[1.95,9.44]],"id":43167130}],"con":true,"img":false}]}
{"op":"mcm","clk":"5353199645","pt":1646210798435,"mc":[{"id":"1.195503849","rc":[{"atl":[[2.04,18.12]],"id":41207262},{"atb":[[1.96,18.17]],"id":43167130}],"con":true,"img":false}]}
{"op":"mcm","clk":"5353199649","pt":1646210798537,"mc":[{"id":"1.195503849","rc":[{"atb":[[1.87,0]],"id":43167130}],"con":true,"img":false}]}
{"op":"mcm","clk":"5353199660","pt":1646210798796,"mc":[{"id":"1.195503849","rc":[{"atl":[[2.02,9.18]],"id":41207262}],"con":true,"img":false}]}
{"op":"mcm","clk":"5353199665","pt":1646210798899,"mc":[{"id":"1.195503849","rc":[{"atl":[[2.1,1.42]],"id":41207262},{"atb":[[1.92,0],[1.97,9.16]],"id":43167130}],"con":true,"img":false}]}
{"op":"mcm","clk":"5353199669","pt":1646210799003,"mc":[{"id":"1.195503849","rc":[{"atl":[[2.04,9.17]],"id":41207262}],"con":true,"img":false}]}
{"op":"mcm","clk":"5353199672","pt":1646210799105,"mc":[{"id":"1.195503849","rc":[{"atl":[[2.02,18.13]],"id":41207262},{"atb":[[1.96,9.17]],"id":43167130},{"atl":[[2.06,0]],"id":43167130}],"con":true,"img":false}]}
{"op":"mcm","clk":"5353199677","pt":1646210799209,"mc":[{"id":"1.195503849","rc":[{"atb":[[1.97,18.16]],"id":43167130}],"con":true,"img":false}]}
{"op":"mcm","clk":"5353199686","pt":1646210799416,"mc":[{"id":"1.195503849","rc":[{"atl":[[2.02,9.18]],"id":41207262}],"con":true,"img":false}]}
{"op":"mcm","clk":"5353199692","pt":1646210799519,"mc":[{"id":"1.195503849","rc":[{"atb":[[1.98,29.82],[1.97,9.16]],"id":43167130}],"con":true,"img":false}]}
{"op":"mcm","clk":"5353199701","pt":1646210799725,"mc":[{"id":"1.195503849","rc":[{"atb":[[1.99,9.08]],"id":43167130}],"con":true,"img":false}]}
{"op":"mcm","clk":"5353199708","pt":1646210799828,"mc":[{"id":"1.195503849","rc":[{"atb":[[1.93,0]],"id":43167130},{"atl":[[2,0]],"id":43167130},{"trd":[[2,19.12]],"ltp":2.0,"tv":19.12,"id":43167130}],"con":true,"img":false}]}
{"op":"mcm","clk":"5353199721","pt":1646210800034,"mc":[{"id":"1.195503849","rc":[{"atb":[[1.98,0]],"id":43167130}],"con":true,"img":false}]}
{"op":"mcm","clk":"5353199756","pt":1646210800503,"mc":[{"id":"1.195503849","rc":[{"atb":[[1.97,39.29]],"id":43167130}],"con":true,"img":false}]}
{"op":"mcm","clk":"5353199807","pt":1646210801428,"mc":[{"id":"1.195503849","rc":[{"atl":[[2.08,0],[2.28,1.42]],"id":43167130}],"con":true,"img":false}]}
{"op":"mcm","clk":"5353199882","pt":1646210803403,"mc":[{"id":"1.195503849","rc":[{"atl":[[2.1,0]],"id":43167130}],"con":true,"img":false}]}
{"op":"mcm","clk":"5353199886","pt":1646210803505,"mc":[{"id":"1.195503849","rc":[{"atl":[[2.26,0],[2.24,3.42]],"id":43167130}],"con":true,"img":false}]}
{"op":"mcm","clk":"5353199896","pt":1646210803711,"mc":[{"id":"1.195503849","rc":[{"atb":[[1.9,55.97]],"id":41207262},{"atl":[[2.12,21.69]],"id":43167130}],"con":true,"img":false}]}
{"op":"mcm","clk":"5353199961","pt":1646210805155,"mc":[{"id":"1.195503849","rc":[{"atb":[[1.9,44.51]],"id":41207262},{"atl":[[2.12,10.95]],"id":43167130}],"con":true,"img":false}]}
{"op":"mcm","clk":"5353199979","pt":1646210805427,"mc":[{"id":"1.195503849","rc":[{"atl":[[2,1.42]],"id":41207262},{"atb":[[2,1.42]],"id":43167130},{"atl":[[2.1,1.42]],"id":43167130}],"con":true,"img":false}]}
{"op":"mcm","clk":"5353200047","pt":1646210806418,"mc":[{"id":"1.195503849","rc":[{"atl":[[2,2.84]],"id":41207262},{"atb":[[2,2.84]],"id":43167130},{"atl":[[2.1,2.84]],"id":43167130}],"con":true,"img":false}]}
{"op":"mcm","clk":"5353200071","pt":1646210806825,"mc":[{"id":"1.195503849","rc":[{"atl":[[1.99,9.34]],"id":41207262},{"atb":[[2.02,9]],"id":43167130}],"con":true,"img":false}]}
{"op":"mcm","clk":"5353200075","pt":1646210806928,"mc":[{"id":"1.195503849","rc":[{"atl":[[2.08,0]],"id":41207262},{"atb":[[1.94,0]],"id":43167130}],"con":true,"img":false}]}
{"op":"mcm","clk":"5353200100","pt":1646210807442,"mc":[{"id":"1.195503849","rc":[{"atb":[[1.89,1.42]],"id":43167130},{"atl":[[2.1,1.42]],"id":43167130}],"con":true,"img":false}]}
{"op":"mcm","clk":"5353200123","pt":1646210807910,"mc":[{"id":"1.195503849","rc":[{"atb":[[1.9,52.12]],"id":41207262},{"atb":[[2,32.08]],"id":43167130},{"atl":[[2.1,4.26]],"id":43167130}],"con":true,"img":false}]}
{"op":"mcm","clk":"5353200158","pt":1646210808523,"mc":[{"id":"1.195503849","rc":[{"atb":[[1.9,19.64]],"id":41207262}],"con":true,"img":false}]}
{"op":"mcm","clk":"5353200165","pt":1646210808729,"mc":[{"id":"1.195503849","rc":[{"atl":[[2.08,1.42]],"id":41207262},{"atb":[[1.93,1.42]],"id":43167130},{"atl":[[2.26,1.42]],"id":43167130}],"con":true,"img":false}]}
{"op":"mcm","clk":"5353200172","pt":1646210808937,"mc":[{"id":"1.195503849","rc":[{"atb":[[1.89,41.69]],"id":41207262},{"atl":[[2.12,1.42],[2.14,0]],"id":43167130}],"con":true,"img":false}]}
{"op":"mcm","clk":"5353200176","pt":1646210809041,"mc":[{"id":"1.195503849","rc":[{"atb":[[1.89,32.84],[1.88,0],[1.9,10.8]],"id":41207262},{"atl":[[2.1,2.84]],"id":43167130}],"con":true,"img":false}]}
{"op":"mcm","clk":"5353200190","pt":1646210809351,"mc":[{"id":"1.195503849","rc":[{"atl":[[2.1,0]],"id":43167130}],"con":true,"img":false}]}
{"op":"mcm","clk":"5353200193","pt":1646210809454,"mc":[{"id":"1.195503849","rc":[{"atb":[[1.9,3.19]],"id":41207262}],"con":true,"img":false}]}
{"op":"mcm","clk":"5353200198","pt":1646210809557,"mc":[{"id":"1.195503849","rc":[{"atb":[[1.89,0]],"id":41207262}],"con":true,"img":false}]}
{"op":"mcm","clk":"5353200203","pt":1646210809617,"mc":[{"id":"1.195503849","rc":[{"atl":[[2.12,4.26]],"id":43167130}],"con":true,"img":false}]}
{"op":"mcm","clk":"5353200209","pt":1646210809818,"mc":[{"id":"1.195503849","rc":[{"atl":[[2.16,0]],"id":43167130}],"con":true,"img":false}]}
{"op":"mcm","clk":"5353200213","pt":1646210809918,"mc":[{"id":"1.195503849","rc":[{"atb":[[1.85,8.85]],"id":41207262}],"con":true,"img":false}]}
{"op":"mcm","clk":"5353200216","pt":1646210810021,"mc":[{"id":"1.195503849","rc":[{"atb":[[1.82,35.64]],"id":41207262}],"con":true,"img":false}]}
{"op":"mcm","clk":"5353200223","pt":1646210810227,"mc":[{"id":"1.195503849","rc":[{"atb":[[1.9,0]],"id":41207262},{"atl":[[1.99,6.29]],"id":41207262},{"trd":[[1.99,6.1]],"ltp":1.99,"tv":6.1,"id":41207262}],"con":true,"img":false}]}
{"op":"mcm","clk":"5353200227","pt":1646210810335,"mc":[{"id":"1.195503849","rc":[{"atb":[[1.73,0],[1.77,2]],"id":41207262}],"con":true,"img":false}]}
{"op":"mcm","clk":"5353200232","pt":1646210810433,"mc":[{"id":"1.195503849","rc":[{"atb":[[1.85,18.72]],"id":41207262}],"con":true,"img":false}]}
{"op":"mcm","clk":"5353200254","pt":1646210810846,"mc":[{"id":"1.195503849","rc":[{"atl":[[2.12,1.42]],"id":43167130}],"con":true,"img":false}]}
{"op":"mcm","clk":"5353200267","pt":1646210811053,"mc":[{"id":"1.195503849","rc":[{"atl":[[2.26,0],[2.24,2],[2.28,0],[2.2,0]],"id":43167130}],"con":true,"img":false}]}
{"op":"mcm","clk":"5353200323","pt":1646210812039,"mc":[{"id":"1.195503849","rc":[{"atb":[[1.85,9.87]],"id":41207262}],"con":true,"img":false}]}
{"op":"mcm","clk":"5353200330","pt":1646210812245,"mc":[{"id":"1.195503849","rc":[{"atl":[[2.12,4.26]],"id":43167130}],"con":true,"img":false}]}
{"op":"mcm","clk":"5353200334","pt":1646210812348,"mc":[{"id":"1.195503849","rc":[{"atb":[[1.85,0]],"id":41207262}],"con":true,"img":false}]}
{"op":"mcm","clk":"5353200338","pt":1646210812452,"mc":[{"id":"1.195503849","rc":[{"atb":[[1.81,36.08]],"id":41207262}],"con":true,"img":false}]}
{"op":"mcm","clk":"5353200343","pt":1646210812554,"mc":[{"id":"1.195503849","rc":[{"atb":[[1.82,0],[1.85,14.5]],"id":41207262}],"con":true,"img":false}]}
{"op":"mcm","clk":"5353200361","pt":1646210812868,"mc":[{"id":"1.195503849","rc":[{"atb":[[1.85,0]],"id":41207262}],"con":true,"img":false}]}
{"op":"mcm","clk":"5353200365","pt":1646210812926,"mc":[{"id":"1.195503849","rc":[{"atb":[[1.83,0],[1.63,0],[1.43,0]],"id":41207262},{"atb":[[1.76,2],[1.56,0],[1.36,0]],"id":43167130}],"con":true,"img":false}]}
{"op":"mcm","clk":"5353200377","pt":1646210813233,"mc":[{"id":"1.195503849","rc":[{"atb":[[1.81,54.2]],"id":41207262}],"con":true,"img":false}]}
{"op":"mcm","clk":"5353200391","pt":1646210813646,"mc":[{"id":"1.195503849","rc":[{"atl":[[1.98,1.42]],"id":41207262},{"atl":[[2.52,0]],"id":43167130}],"con":true,"img":false}]}
{"op":"mcm","clk":"5353200399","pt":1646210813851,"mc":[{"id":"1.195503849","rc":[{"atl":[[1.98,11.38]],"id":41207262}],"con":true,"img":false}]}
{"op":"mcm","clk":"5353200546","pt":1646210817251,"mc":[{"id":"1.195503849","rc":[{"atl":[[2.22,0]],"id":43167130}],"con":true,"img":false}]}
{"op":"mcm","clk":"5353200552","pt":1646210817458,"mc":[{"id":"1.195503849","rc":[{"atb":[[1.81,18.12]],"id":41207262},{"atb":[[2,2.84]],"id":43167130}],"con":true,"img":false}]}
{"op":"mcm","clk":"5353200569","pt":1646210817769,"mc":[{"id":"1.195503849","rc":[{"atb":[[1.81,0]],"id":41207262}],"con":true,"img":false}]}
{"op":"mcm","clk":"5353200575","pt":1646210817872,"mc":[{"id":"1.195503849","rc":[{"atb":[[1.77,20.12]],"id":41207262}],"con":true,"img":false}]}
{"op":"mcm","clk":"5353200591","pt":1646210818129,"mc":[{"id":"1.195503849","rc":[{"atb":[[1.77,2]],"id":41207262}],"con":true,"img":false}]}
{"op":"mcm","clk":"5353200610","pt":1646210818437,"mc":[{"id":"1.195503849","rc":[{"atb":[[1.77,6]],"id":41207262}],"con":true,"img":false}]}
{"op":"mcm","clk":"5353200616","pt":1646210818541,"mc":[{"id":"1.195503849","rc":[{"atb":[[1.77,16.19]],"id":41207262}],"con":true,"img":false}]}
{"op":"mcm","clk":"5353200638","pt":1646210818954,"mc":[{"id":"1.195503849","rc":[{"atb":[[1.64,45.67]],"id":41207262}],"con":true,"img":false}]}
{"op":"mcm","clk":"5353200668","pt":1646210819738,"mc":[{"id":"1.195503849","rc":[{"atb":[[1.78,10.18]],"id":41207262}],"con":true,"img":false}]}
{"op":"mcm","clk":"5353200681","pt":1646210819942,"mc":[{"id":"1.195503849","rc":[{"atb":[[1.64,0]],"id":41207262}],"con":true,"img":false}]}
{"op":"mcm","clk":"5353200683","pt":1646210820047,"mc":[{"id":"1.195503849","rc":[{"atb":[[1.77,12.19]],"id":41207262}],"con":true,"img":false}]}
{"op":"mcm","clk":"5353200695","pt":1646210820359,"mc":[{"id":"1.195503849","rc":[{"atb":[[1.78,30.56]],"id":41207262}],"con":true,"img":false}]}
{"op":"mcm","clk":"5353200721","pt":1646210820877,"mc":[{"id":"1.195503849","rc":[{"atb":[[1.78,10.18]],"id":41207262},{"atl":[[2.12,1.42]],"id":43167130}],"con":true,"img":false}]}
{"op":"mcm","clk":"5353200727","pt":1646210820980,"mc":[{"id":"1.195503849","rc":[{"atb":[[1.79,36.99]],"id":41207262}],"con":true,"img":false}]}
{"op":"mcm","clk":"5353200750","pt":1646210821447,"mc":[{"id":"1.195503849","rc":[{"atb":[[1.79,33.2]],"id":41207262},{"atl":[[2.12,4.26]],"id":43167130}],"con":true,"img":false}]}
{"op":"mcm","clk":"5353200763","pt":1646210821757,"mc":[{"id":"1.195503849","rc":[{"atb":[[1.79,0]],"id":41207262}],"con":true,"img":false}]}
{"op":"mcm","clk":"5353200767","pt":1646210821860,"mc":[{"id":"1.195503849","rc":[{"atl":[[2.56,1.42]],"id":43167130}],"con":true,"img":false}]}
{"op":"mcm","clk":"5353200777","pt":1646210822067,"mc":[{"id":"1.195503849","rc":[{"atb":[[1.78,30.56]],"id":41207262}],"con":true,"img":false}]}
{"op":"mcm","clk":"5353200831","pt":1646210823201,"mc":[{"id":"1.195503849","rc":[{"atb":[[1.67,8.06],[1.87,6.21],[1.47,11.49]],"id":41207262},{"atb":[[1.28,19.3],[1.68,7.94],[1.48,11.26]],"id":43167130}],"con":true,"img":false}]}
{"op":"mcm","clk":"5353200845","pt":1646210823355,"mc":[{"id":"1.195503849","rc":[{"atb":[[1.79,10.04]],"id":41207262}],"con":true,"img":false}]}
{"op":"mcm","clk":"5353200870","pt":1646210823869,"mc":[{"id":"1.195503849","rc":[{"atl":[[1.89,0.13]],"id":41207262},{"trd":[[1.89,4.78]],"ltp":1.89,"tv":4.78,"id":41207262},{"atl":[[2.12,0]],"id":43167130},{"trd":[[2.12,4.26]],"ltp":2.12,"tv":4.26,"id":43167130}],"con":true,"img":false}]}
{"op":"mcm","clk":"5353200874","pt":1646210823972,"mc":[{"id":"1.195503849","rc":[{"atb":[[1.79,47.04]],"id":41207262},{"atl":[[1.89,10.13]],"id":41207262},{"atl":[[2.24,0],[2.38,2]],"id":43167130}],"con":true,"img":false}]}
{"op":"mcm","clk":"5353200884","pt":1646210824177,"mc":[{"id":"1.195503849","rc":[{"atl":[[1.89,6.77],[2.06,0]],"id":41207262},{"trd":[[1.89,8.14]],"ltp":1.89,"tv":8.14,"id":41207262},{"trd":[[2.12,7.26]],"ltp":2.12,"tv":7.26,"id":43167130}],"con":true,"img":false}]}
{"op":"mcm","clk":"5353200887","pt":1646210824279,"mc":[{"id":"1.195503849","rc":[{"atb":[[1.8,10.03]],"id":41207262},{"atl":[[2.38,10.43]],"id":43167130}],"con":true,"img":false}]}
{"op":"mcm","clk":"5353200924","pt":1646210825048,"mc":[{"id":"1.195503849","rc":[{"atl":[[2.38,29.74]],"id":43167130}],"con":true,"img":false}]}
{"op":"mcm","clk":"5353200994","pt":1646210826652,"mc":[{"id":"1.195503849","rc":[{"atl":[[2.36,8.43]],"id":43167130}],"con":true,"img":false}]}
{"op":"mcm","clk":"5353201006","pt":1646210826961,"mc":[{"id":"1.195503849","rc":[{"atl":[[2.38,10.43]],"id":43167130}],"con":true,"img":false}]}
{"op":"mcm","clk":"5353201011","pt":1646210827064,"mc":[{"id":"1.195503849","rc":[{"atl":[[2.36,27.74]],"id":43167130}],"con":true,"img":false}]}
{"op":"mcm","clk":"5353201052","pt":1646210827943,"mc":[{"id":"1.195503849","rc":[{"atl":[[2.34,8.44]],"id":43167130}],"con":true,"img":false}]}
{"op":"mcm","clk":"5353201066","pt":1646210828250,"mc":[{"id":"1.195503849","rc":[{"atl":[[2.36,8.43]],"id":43167130}],"con":true,"img":false}]}
{"op":"mcm","clk":"5353201072","pt":1646210828352,"mc":[{"id":"1.195503849","rc":[{"atl":[[2.34,27.75]],"id":43167130}],"con":true,"img":false}]}
{"op":"mcm","clk":"5353201076","pt":1646210828455,"mc":[{"id":"1.195503849","rc":[{"atb":[[1.78,10.18]],"id":41207262}],"con":true,"img":false}]}
{"op":"mcm","clk":"5353201081","pt":1646210828557,"mc":[{"id":"1.195503849","rc":[{"atb":[[1.87,26.59]],"id":41207262}],"con":true,"img":false}]}
{"op":"mcm","clk":"5353201085","pt":1646210828659,"mc":[{"id":"1.195503849","rc":[{"atl":[[2.32,8.44]],"id":43167130}],"con":true,"img":false}]}
{"op":"mcm","clk":"5353201089","pt":1646210828763,"mc":[{"id":"1.195503849","rc":[{"atl":[[1.89,0]],"id":41207262},{"trd":[[1.89,14.91]],"ltp":1.89,"tv":14.91,"id":41207262},{"trd":[[2.12,13.3]],"ltp":2.12,"tv":13.3,"id":43167130}],"con":true,"img":false}]}
{"op":"mcm","clk":"5353201094","pt":1646210828870,"mc":[{"id":"1.195503849","rc":[{"atl":[[2.34,8.44]],"id":43167130}],"con":true,"img":false}]}
{"op":"mcm","clk":"5353201096","pt":1646210828968,"mc":[{"id":"1.195503849","rc":[{"atb":[[1.81,36.08]],"id":41207262},{"atb":[[2.02,37.66]],"id":43167130},{"atl":[[2.32,27.75]],"id":43167130}],"con":true,"img":false}]}
{"op":"mcm","clk":"5353201100","pt":1646210829073,"mc":[{"id":"1.195503849","rc":[{"atl":[[2.3,2],[2.38,8.43]],"id":43167130}],"con":true,"img":false}]}
{"op":"mcm","clk":"5353201104","pt":1646210829175,"mc":[{"id":"1.195503849","rc":[{"atb":[[1.82,9.96],[1.77,2]],"id":41207262}],"con":true,"img":false}]}
{"op":"mcm","clk":"5353201111","pt":1646210829380,"mc":[{"id":"1.195503849","rc":[{"atl":[[2.3,10.47],[2.32,8.44]],"id":43167130}],"con":true,"img":false}]}
{"op":"mcm","clk":"5353201116","pt":1646210829484,"mc":[{"id":"1.195503849","rc":[{"atl":[[2.3,29.78]],"id":43167130}],"con":true,"img":false}]}
{"op":"mcm","clk":"5353201123","pt":1646210829587,"mc":[{"id":"1.195503849","rc":[{"atl":[[2.12,2],[2.16,8.7]],"id":41207262},{"atl":[[2.38,0]],"id":43167130}],"con":true,"img":false}]}
{"op":"mcm","clk":"5353201158","pt":1646210830153,"mc":[{"id":"1.195503849","rc":[{"atb":[[2.04,17]],"id":43167130},{"atl":[[2.36,0],[2.28,8.47]],"id":43167130}],"con":true,"img":false}]}
{"op":"mcm","clk":"5353201163","pt":1646210830256,"mc":[{"id":"1.195503849","rc":[{"atb":[[1.95,0]],"id":43167130}],"con":true,"img":false}]}
{"op":"mcm","clk":"5353201173","pt":1646210830460,"mc":[{"id":"1.195503849","rc":[{"atb":[[1.83,35.22]],"id":41207262},{"atl":[[2.3,10.47]],"id":43167130}],"con":true,"img":false}]}
{"op":"mcm","clk":"5353201175","pt":1646210830562,"mc":[{"id":"1.195503849","rc":[{"atl":[[2.28,27.78]],"id":43167130}],"con":true,"img":false}]}
{"op":"mcm","clk":"5353201182","pt":1646210830769,"mc":[{"id":"1.195503849","rc":[{"atb":[[1.84,9.94]],"id":41207262},{"atl":[[2.26,8.48]],"id":43167130}],"con":true,"img":false}]}
{"op":"mcm","clk":"5353201186","pt":1646210830871,"mc":[{"id":"1.195503849","rc":[{"atb":[[1.78,0]],"id":41207262},{"atl":[[2.34,0]],"id":43167130}],"con":true,"img":false}]}
{"op":"mcm","clk":"5353201190","pt":1646210830975,"mc":[{"id":"1.195503849","rc":[{"atb":[[1.79,10.04]],"id":41207262}],"con":true,"img":false}]}
{"op":"mcm","clk":"5353201198","pt":1646210831077,"mc":[{"id":"1.195503849","rc":[{"atl":[[2.28,8.47]],"id":43167130}],"con":true,"img":false}]}
{"op":"mcm","clk":"5353201204","pt":1646210831180,"mc":[{"id":"1.195503849","rc":[{"atl":[[2.26,27.79]],"id":43167130}],"con":true,"img":false}]}
{"op":"mcm","clk":"5353201212","pt":1646210831385,"mc":[{"id":"1.195503849","rc":[{"atl":[[1.96,1.42]],"id":41207262},{"atb":[[1.95,1.42]],"id":43167130}],"con":true,"img":false}]}
{"op":"mcm","clk":"5353201236","pt":1646210831951,"mc":[{"id":"1.195503849","rc":[{"atb":[[1.85,34.39]],"id":41207262}],"con":true,"img":false}]}
{"op":"mcm","clk":"5353201260","pt":1646210832569,"mc":[{"id":"1.195503849","rc":[{"atl":[[2.32,0],[2.24,8.49]],"id":43167130}],"con":true,"img":false}]}
{"op":"mcm","clk":"5353201270","pt":1646210832775,"mc":[{"id":"1.195503849","rc":[{"atl":[[1.96,11.31]],"id":41207262},{"atb":[[1.94,1.42]],"id":43167130},{"atl":[[2.26,8.48],[2.34,1.42]],"id":43167130}],"con":true,"img":false}]}
{"op":"mcm","clk":"5353201274","pt":1646210832877,"mc":[{"id":"1.195503849","rc":[{"atl":[[2.24,27.8]],"id":43167130}],"con":true,"img":false}]}
{"op":"mcm","clk":"5353201298","pt":1646210833288,"mc":[{"id":"1.195503849","rc":[{"atl":[[2.3,2],[2.22,8.53]],"id":43167130}],"con":true,"img":false}]}
{"op":"mcm","clk":"5353201317","pt":1646210833650,"mc":[{"id":"1.195503849","rc":[{"atl":[[2.24,8.49]],"id":43167130}],"con":true,"img":false}]}
{"op":"mcm","clk":"5353201320","pt":1646210833752,"mc":[{"id":"1.195503849","rc":[{"atl":[[2.22,27.84]],"id":43167130}],"con":true,"img":false}]}
{"op":"mcm","clk":"5353201332","pt":1646210834161,"mc":[{"id":"1.195503849","rc":[{"atl":[[2.3,0],[2.24,10.49]],"id":43167130}],"con":true,"img":false}]}
{"op":"mcm","clk":"5353201353","pt":1646210834574,"mc":[{"id":"1.195503849","rc":[{"atl":[[2.14,1.42]],"id":43167130}],"con":true,"img":false}]}
{"op":"mcm","clk":"5353201365","pt":1646210834985,"mc":[{"id":"1.195503849","rc":[{"atl":[[2.28,0],[2.2,8.5]],"id":43167130}],"con":true,"img":false}]}
{"op":"mcm","clk":"5353201425","pt":1646210836174,"mc":[{"id":"1.195503849","rc":[{"atb":[[1.86,9.79]],"id":41207262}],"con":true,"img":false}]}
{"op":"mcm","clk":"5353201438","pt":1646210836380,"mc":[{"id":"1.195503849","rc":[{"atb":[[1.79,0]],"id":41207262}],"con":true,"img":false}]}
{"op":"mcm","clk":"5353201441","pt":1646210836482,"mc":[{"id":"1.195503849","rc":[{"atb":[[1.81,0]],"id":41207262}],"con":true,"img":false}]}
{"op":"mcm","clk":"5353201552","pt":1646210838690,"mc":[{"id":"1.195503849","rc":[{"atl":[[2.26,10.48],[2.24,8.49]],"id":43167130}],"con":true,"img":false}]}
{"op":"mcm","clk":"5353201563","pt":1646210838897,"mc":[{"id":"1.195503849","rc":[{"atl":[[2.28,1.42]],"id":43167130}],"con":true,"img":false}]}
{"op":"mcm","clk":"5353201648","pt":1646210840594,"mc":[{"id":"1.195503849","rc":[{"atl":[[2.32,1.42],[2.22,8.53]],"id":43167130}],"con":true,"img":false}]}
{"op":"mcm","clk":"5353201652","pt":1646210840697,"mc":[{"id":"1.195503849","rc":[{"atl":[[2.14,20.73]],"id":43167130}],"con":true,"img":false}]}
{"op":"mcm","clk":"5353201667","pt":1646210840955,"mc":[{"id":"1.195503849","rc":[{"atb":[[1.87,60.19]],"id":41207262},{"atl":[[2.14,4.26]],"id":43167130}],"con":true,"img":false}]}
{"op":"mcm","clk":"5353201866","pt":1646210844870,"mc":[{"id":"1.195503849","rc":[{"atb":[[1.86,0]],"id":41207262}],"con":true,"img":false}]}
{"op":"mcm","clk":"5353201897","pt":1646210845490,"mc":[{"id":"1.195503849","rc":[{"atb":[[1.87,26.59]],"id":41207262}],"con":true,"img":false}]}
{"op":"mcm","clk":"5353201936","pt":1646210846212,"mc":[{"id":"1.195503849","rc":[{"atb":[[1.84,0]],"id":41207262}],"con":true,"img":false}]}
{"op":"mcm","clk":"5353201954","pt":1646210846471,"mc":[{"id":"1.195503849","rc":[{"atb":[[1.85,0]],"id":41207262}],"con":true,"img":false}]}
{"op":"mcm","clk":"5353202044","pt":1646210848384,"mc":[{"id":"1.195503849","rc":[{"atl":[[2.32,0],[2.34,0],[2.28,0]],"id":43167130}],"con":true,"img":false}]}
{"op":"mcm","clk":"5353202059","pt":1646210848693,"mc":[{"id":"1.195503849","rc":[{"atb":[[1.84,9.99]],"id":41207262}],"con":true,"img":false}]}
{"op":"mcm","clk":"5353202065","pt":1646210848797,"mc":[{"id":"1.195503849","rc":[{"atb":[[1.84,0]],"id":41207262}],"con":true,"img":false}]}
{"op":"mcm","clk":"5353202139","pt":1646210850392,"mc":[{"id":"1.195503849","rc":[{"atl":[[2.2,0]],"id":43167130}],"con":true,"img":false}]}
{"op":"mcm","clk":"5353202142","pt":1646210850496,"mc":[{"id":"1.195503849","rc":[{"atb":[[1.85,0],[1.9,35.9]],"id":43167130}],"con":true,"img":false}]}
{"op":"mcm","clk":"5353202188","pt":1646210851477,"mc":[{"id":"1.195503849","rc":[{"atl":[[2,0],[1.98,0],[1.96,0],[1.99,0]],"id":41207262},{"trd":[[2,118.24],[1.99,12.39],[1.98,11.38],[1.96,11.31]],"ltp":2.0,"tv":153.32,"id":41207262},{"atb":[[2,0],[2.04,0],[2.02,0]],"id":43167130},{"atl":[[2,10.69]],"id":43167130},{"trd":[[2,33.93],[2.02,86.47],[2.04,44.89]],"ltp":2.0,"tv":165.29,"id":43167130}],"con":true,"img":false}]}
{"op":"mcm","clk":"5353202193","pt":1646210851581,"mc":[{"id":"1.195503849","rc":[{"atb":[[1.88,9.66]],"id":41207262},{"atl":[[2.12,0],[2.1,3.42]],"id":41207262},{"atl":[[2,0],[2.14,12.96]],"id":43167130},{"trd":[[2,55.31]],"ltp":2.0,"tv":55.31,"id":43167130}],"con":true,"img":false}]}
{"op":"mcm","clk":"5353202202","pt":1646210851789,"mc":[{"id":"1.195503849","rc":[{"atb":[[1.87,6.21]],"id":41207262}],"con":true,"img":false}]}
{"op":"mcm","clk":"5353202207","pt":1646210851890,"mc":[{"id":"1.195503849","rc":[{"atb":[[1.88,30.04]],"id":41207262}],"con":true,"img":false}]}
{"op":"mcm","clk":"5353202222","pt":1646210852199,"mc":[{"id":"1.195503849","rc":[{"atb":[[1.88,9.66]],"id":41207262},{"atl":[[2.02,15.72]],"id":41207262},{"atb":[[1.99,15.11]],"id":43167130},{"atl":[[2.14,10.12]],"id":43167130}],"con":true,"img":false}]}
{"op":"mcm","clk":"5353202239","pt":1646210852510,"mc":[{"id":"1.195503849","rc":[{"atb":[[1.9,3.42]],"id":43167130}],"con":true,"img":false}]}
{"op":"mcm","clk":"5353202248","pt":1646210852716,"mc":[{"id":"1.195503849","rc":[{"atl":[[2.1,2],[2.08,0]],"id":41207262},{"atb":[[1.94,0],[1.95,0],[1.93,0],[1.91,0],[1.04,1.45]],"id":43167130},{"atl":[[2.14,8.7]],"id":43167130}],"con":true,"img":false}]}
{"op":"mcm","clk":"5353202258","pt":1646210852923,"mc":[{"id":"1.195503849","rc":[{"atb":[[1.04,0.16]],"id":43167130}],"con":true,"img":false}]}
{"op":"mcm","clk":"5353202264","pt":1646210853026,"mc":[{"id":"1.195503849","rc":[{"atb":[[1.99,44.64]],"id":43167130}],"con":true,"img":false}]}
{"op":"mcm","clk":"5353202268","pt":1646210853078,"mc":[{"id":"1.195503849","rc":[{"atb":[[1.04,0]],"id":43167130}],"con":true,"img":false}]}
{"op":"mcm","clk":"5353202271","pt":1646210853184,"mc":[{"id":"1.195503849","rc":[{"atl":[[2.14,8.53]],"id":43167130},{"trd":[[2.14,0.32]],"ltp":2.14,"tv":0.32,"id":43167130}],"con":true,"img":false}]}
{"op":"mcm","clk":"5353202317","pt":1646210854214,"mc":[{"id":"1.195503849","rc":[{"atb":[[1.88,0]],"id":41207262},{"atl":[[2.14,0]],"id":43167130}],"con":true,"img":false}]}
{"op":"mcm","clk":"5353202332","pt":1646210854522,"mc":[{"id":"1.195503849","rc":[{"atb":[[1.83,0],[1.81,36.08]],"id":41207262},{"atl":[[2.22,14.69]],"id":43167130}],"con":true,"img":false}]}
{"op":"mcm","clk":"5353202357","pt":1646210854986,"mc":[{"id":"1.195503849","rc":[{"atl":[[2.02,9.18]],"id":41207262},{"atb":[[1.99,38.61]],"id":43167130}],"con":true,"img":false}]}
{"op":"mcm","clk":"5353202374","pt":1646210855500,"mc":[{"id":"1.195503849","rc":[{"atb":[[1.99,9.08]],"id":43167130}],"con":true,"img":false}]}
{"op":"mcm","clk":"5353202386","pt":1646210855807,"mc":[{"id":"1.195503849","rc":[{"atb":[[1.87,15.96]],"id":41207262},{"atl":[[2.2,8.62]],"id":43167130}],"con":true,"img":false}]}
{"op":"mcm","clk":"5353202397","pt":1646210856116,"mc":[{"id":"1.195503849","rc":[{"atl":[[2.22,8.53]],"id":43167130}],"con":true,"img":false}]}
{"op":"mcm","clk":"5353202417","pt":1646210856526,"mc":[{"id":"1.195503849","rc":[{"atb":[[1.83,35.22]],"id":41207262},{"atl":[[2.2,16.33]],"id":43167130}],"con":true,"img":false}]}
{"op":"mcm","clk":"5353202426","pt":1646210856731,"mc":[{"id":"1.195503849","rc":[{"atb":[[1.88,1.42]],"id":41207262},{"atl":[[2,1.42],[2.12,2],[2.1,0]],"id":41207262},{"atb":[[2,1.42]],"id":43167130}],"con":true,"img":false}]}
{"op":"mcm","clk":"5353202450","pt":1646210857224,"mc":[{"id":"1.195503849","rc":[{"atl":[[2.24,0],[2.22,0],[2.2,0]],"id":41207262},{"atb":[[1.89,0],[1.88,0],[1.9,2]],"id":43167130}],"con":true,"img":false}]}
{"op":"mcm","clk":"5353202467","pt":1646210857531,"mc":[{"id":"1.195503849","rc":[{"atb":[[1.87,6.21]],"id":41207262}],"con":true,"img":false}]}
{"op":"mcm","clk":"5353202490","pt":1646210857995,"mc":[{"id":"1.195503849","rc":[{"atb":[[1.84,9.83],[1.88,11.26]],"id":41207262},{"atl":[[2.18,17.16]],"id":43167130}],"con":true,"img":false}]}
{"op":"mcm","clk":"5353202498","pt":1646210858098,"mc":[{"id":"1.195503849","rc":[{"atl":[[2.26,2]],"id":43167130}],"con":true,"img":false}]}
{"op":"mcm","clk":"5353202506","pt":1646210858301,"mc":[{"id":"1.195503849","rc":[{"atl":[[2.2,8.62]],"id":43167130}],"con":true,"img":false}]}
{"op":"mcm","clk":"5353202514","pt":1646210858404,"mc":[{"id":"1.195503849","rc":[{"atl":[[2.18,24.87]],"id":43167130}],"con":true,"img":false}]}
{"op":"mcm","clk":"5353202545","pt":1646210859021,"mc":[{"id":"1.195503849","rc":[{"atb":[[1.85,34.39]],"id":41207262}],"con":true,"img":false}]}
{"op":"mcm","clk":"5353202590","pt":1646210859794,"mc":[{"id":"1.195503849","rc":[{"atl":[[2.24,0],[2.16,8.59]],"id":43167130}],"con":true,"img":false}]}
{"op":"mcm","clk":"5353202655","pt":1646210860932,"mc":[{"id":"1.195503849","rc":[{"atl":[[2.18,17.16]],"id":43167130}],"con":true,"img":false}]}
{"op":"mcm","clk":"5353202660","pt":1646210861036,"mc":[{"id":"1.195503849","rc":[{"atl":[[2.16,16.3]],"id":43167130}],"con":true,"img":false}]}
{"op":"mcm","clk":"5353202671","pt":1646210861242,"mc":[{"id":"1.195503849","rc":[{"atl":[[2.16,7.71]],"id":43167130}],"con":true,"img":false}]}
{"op":"mcm","clk":"5353202686","pt":1646210861500,"mc":[{"id":"1.195503849","rc":[{"atl":[[2.16,0]],"id":43167130}],"con":true,"img":false}]}
{"op":"mcm","clk":"5353202690","pt":1646210861605,"mc":[{"id":"1.195503849","rc":[{"atl":[[2.18,24.87]],"id":43167130}],"con":true,"img":false}]}
{"op":"mcm","clk":"5353202698","pt":1646210861809,"mc":[{"id":"1.195503849","rc":[{"atl":[[2.12,0],[2.1,2]],"id":41207262}],"con":true,"img":false}]}
{"op":"mcm","clk":"5353202721","pt":1646210862328,"mc":[{"id":"1.195503849","rc":[{"atl":[[2.16,8.58]],"id":43167130}],"con":true,"img":false}]}
{"op":"mcm","clk":"5353202726","pt":1646210862430,"mc":[{"id":"1.195503849","rc":[{"atb":[[1.88,17.87]],"id":41207262}],"con":true,"img":false}]}
{"op":"mcm","clk":"5353202736","pt":1646210862533,"mc":[{"id":"1.195503849","rc":[{"atb":[[1.89,9.8]],"id":41207262},{"atl":[[2.18,17.16]],"id":43167130}],"con":true,"img":false}]}
{"op":"mcm","clk":"5353202739","pt":1646210862635,"mc":[{"id":"1.195503849","rc":[{"atl":[[2.16,16.29]],"id":43167130}],"con":true,"img":false}]}
{"op":"mcm","clk":"5353202783","pt":1646210863408,"mc":[{"id":"1.195503849","rc":[{"atl":[[2.14,8.61]],"id":43167130}],"con":true,"img":false}]}
{"op":"mcm","clk":"5353202803","pt":1646210863716,"mc":[{"id":"1.195503849","rc":[{"atl":[[2.16,8.58]],"id":43167130}],"con":true,"img":false}]}
{"op":"mcm","clk":"5353202811","pt":1646210863819,"mc":[{"id":"1.195503849","rc":[{"atb":[[1.88,11.26]],"id":41207262},{"atl":[[2.14,16.32]],"id":43167130}],"con":true,"img":false}]}
{"op":"mcm","clk":"5353202822","pt":1646210864024,"mc":[{"id":"1.195503849","rc":[{"atb":[[1.88,44.47]],"id":41207262},{"atl":[[2.12,8.59]],"id":43167130}],"con":true,"img":false}]}
{"op":"mcm","clk":"5353202829","pt":1646210864129,"mc":[{"id":"1.195503849","rc":[{"atb":[[1.89,16.65]],"id":41207262}],"con":true,"img":false}]}
{"op":"mcm","clk":"5353202835","pt":1646210864233,"mc":[{"id":"1.195503849","rc":[{"atb":[[1.9,1.42]],"id":41207262},{"atl":[[2.12,10.01],[2.14,8.61]],"id":43167130}],"con":true,"img":false}]}
{"op":"mcm","clk":"5353202842","pt":1646210864336,"mc":[{"id":"1.195503849","rc":[{"atb":[[1.9,11.18]],"id":41207262},{"atl":[[2.12,17.72]],"id":43167130}],"con":true,"img":false}]}
{"op":"mcm","clk":"5353202856","pt":1646210864491,"mc":[{"id":"1.195503849","rc":[{"atb":[[1.81,0]],"id":41207262}],"con":true,"img":false}]}
{"op":"mcm","clk":"5353202864","pt":1646210864595,"mc":[{"id":"1.195503849","rc":[{"atl":[[2.1,8.68]],"id":43167130}],"con":true,"img":false}]}
{"op":"mcm","clk":"5353202890","pt":1646210865008,"mc":[{"id":"1.195503849","rc":[{"atb":[[1.9,43.66]],"id":41207262}],"con":true,"img":false}]}
{"op":"mcm","clk":"5353202898","pt":1646210865212,"mc":[{"id":"1.195503849","rc":[{"atb":[[1.89,9.8]],"id":41207262},{"atl":[[2.12,10.01]],"id":43167130}],"con":true,"img":false}]}
{"op":"mcm","clk":"5353202906","pt":1646210865420,"mc":[{"id":"1.195503849","rc":[{"atl":[[2.1,16.39]],"id":43167130}],"con":true,"img":false}]}
{"op":"mcm","clk":"5353202909","pt":1646210865523,"mc":[{"id":"1.195503849","rc":[{"atl":[[2.08,8.79]],"id":43167130}],"con":true,"img":false}]}
{"op":"mcm","clk":"5353202914","pt":1646210865626,"mc":[{"id":"1.195503849","rc":[{"atb":[[1.91,9.61]],"id":41207262},{"atl":[[2.08,0],[2.18,8.58]],"id":43167130}],"con":true,"img":false}]}
{"op":"mcm","clk":"5353202920","pt":1646210865732,"mc":[{"id":"1.195503849","rc":[{"atb":[[1.91,0]],"id":41207262},{"atl":[[2.1,7.71]],"id":43167130}],"con":true,"img":false}]}
{"op":"mcm","clk":"5353202926","pt":1646210865938,"mc":[{"id":"1.195503849","rc":[{"atl":[[2.24,1.42]],"id":43167130}],"con":true,"img":false}]}
{"op":"mcm","clk":"5353202929","pt":1646210866041,"mc":[{"id":"1.195503849","rc":[{"atb":[[1.9,50.82]],"id":41207262},{"atl":[[2.1,0]],"id":43167130}],"con":true,"img":false}]}
{"op":"mcm","clk":"5353202936","pt":1646210866199,"mc":[{"id":"1.195503849","rc":[{"atb":[[1.91,9.69]],"id":41207262}],"con":true,"img":false}]}
{"op":"mcm","clk":"5353202941","pt":1646210866302,"mc":[{"id":"1.195503849","rc":[{"atl":[[2.12,16.89]],"id":43167130}],"con":true,"img":false}]}
{"op":"mcm","clk":"5353202945","pt":1646210866404,"mc":[{"id":"1.195503849","rc":[{"atb":[[1.9,43.66]],"id":41207262}],"con":true,"img":false}]}
{"op":"mcm","clk":"5353202948","pt":1646210866509,"mc":[{"id":"1.195503849","rc":[{"atb":[[1.91,16.85]],"id":41207262}],"con":true,"img":false}]}
{"op":"mcm","clk":"5353202954","pt":1646210866618,"mc":[{"id":"1.195503849","rc":[{"atl":[[2.1,8.73]],"id":43167130}],"con":true,"img":false}]}
{"op":"mcm","clk":"5353202959","pt":1646210866713,"mc":[{"id":"1.195503849","rc":[{"atb":[[1.92,9.63]],"id":41207262}],"con":true,"img":false}]}
{"op":"mcm","clk":"5353202964","pt":1646210866817,"mc":[{"id":"1.195503849","rc":[{"atb":[[1.88,34.64]],"id":41207262}],"con":true,"img":false}]}
{"op":"mcm","clk":"5353202969","pt":1646210866920,"mc":[{"id":"1.195503849","rc":[{"atl":[[2.12,10.01]],"id":43167130}],"con":true,"img":false}]}
{"op":"mcm","clk":"5353202975","pt":1646210867023,"mc":[{"id":"1.195503849","rc":[{"atb":[[1.91,9.69]],"id":41207262},{"atl":[[2.1,15.61]],"id":43167130}],"con":true,"img":false}]}
{"op":"mcm","clk":"5353202978","pt":1646210867127,"mc":[{"id":"1.195503849","rc":[{"atb":[[1.92,16.79]],"id":41207262}],"con":true,"img":false}]}
{"op":"mcm","clk":"5353202980","pt":1646210867230,"mc":[{"id":"1.195503849","rc":[{"atl":[[2.08,8.77]],"id":43167130}],"con":true,"img":false}]}
{"op":"mcm","clk":"5353202982","pt":1646210867332,"mc":[{"id":"1.195503849","rc":[{"atb":[[1.92,7.16]],"id":41207262},{"atl":[[2.08,0]],"id":43167130}],"con":true,"img":false}]}
{"op":"mcm","clk":"5353202996","pt":1646210867641,"mc":[{"id":"1.195503849","rc":[{"atb":[[1.92,0]],"id":41207262}],"con":true,"img":false}]}
{"op":"mcm","clk":"5353203010","pt":1646210867804,"mc":[{"id":"1.195503849","rc":[{"atb":[[1.92,16.16]],"id":41207262}],"con":true,"img":false}]}
{"op":"mcm","clk":"5353203018","pt":1646210867901,"mc":[{"id":"1.195503849","rc":[{"atl":[[2.08,8.77]],"id":43167130}],"con":true,"img":false}]}
{"op":"mcm","clk":"5353203031","pt":1646210868115,"mc":[{"id":"1.195503849","rc":[{"atb":[[1.93,9.56]],"id":41207262}],"con":true,"img":false}]}
{"op":"mcm","clk":"5353203035","pt":1646210868210,"mc":[{"id":"1.195503849","rc":[{"atb":[[1.89,0]],"id":41207262}],"con":true,"img":false}]}
{"op":"mcm","clk":"5353203038","pt":1646210868320,"mc":[{"id":"1.195503849","rc":[{"atl":[[2.1,8.73]],"id":43167130}],"con":true,"img":false}]}
{"op":"mcm","clk":"5353203049","pt":1646210868520,"mc":[{"id":"1.195503849","rc":[{"atb":[[1.83,0],[1.92,9.63]],"id":41207262}],"con":true,"img":false}]}
{"op":"mcm","clk":"5353203054","pt":1646210868624,"mc":[{"id":"1.195503849","rc":[{"atl":[[2.08,16.06]],"id":43167130}],"con":true,"img":false}]}
{"op":"mcm","clk":"5353203067","pt":1646210868831,"mc":[{"id":"1.195503849","rc":[{"atb":[[1.93,17.13]],"id":41207262}],"con":true,"img":false}]}
{"op":"mcm","clk":"5353203072","pt":1646210868934,"mc":[{"id":"1.195503849","rc":[{"atb":[[1.94,9.48]],"id":41207262},{"atl":[[2.06,8.87]],"id":43167130}],"con":true,"img":false}]}
{"op":"mcm","clk":"5353203075","pt":1646210869037,"mc":[{"id":"1.195503849","rc":[{"atb":[[1.92,41.4]],"id":41207262}],"con":true,"img":false}]}
{"op":"mcm","clk":"5353203078","pt":1646210869140,"mc":[{"id":"1.195503849","rc":[{"atb":[[1.9,33.9]],"id":41207262},{"atl":[[2.14,0],[2.06,0]],"id":43167130}],"con":true,"img":false}]}
{"op":"mcm","clk":"5353203083","pt":1646210869243,"mc":[{"id":"1.195503849","rc":[{"atb":[[1.93,9.56]],"id":41207262},{"atl":[[2.08,8.77]],"id":43167130}],"con":true,"img":false}]}
{"op":"mcm","clk":"5353203089","pt":1646210869346,"mc":[{"id":"1.195503849","rc":[{"atb":[[1.94,17.05]],"id":41207262},{"atl":[[2.06,16.22]],"id":43167130}],"con":true,"img":false}]}
{"op":"mcm","clk":"5353203099","pt":1646210869503,"mc":[{"id":"1.195503849","rc":[{"atb":[[1.85,0],[1.95,9.38]],"id":41207262},{"atb":[[1.97,9.16]],"id":43167130}],"con":true,"img":false}]}
{"op":"mcm","clk":"5353203104","pt":1646210869607,"mc":[{"id":"1.195503849","rc":[{"atb":[[1.94,9.48],[1.91,0]],"id":41207262},{"atl":[[2.06,8.93]],"id":43167130}],"con":true,"img":false}]}
{"op":"mcm","clk":"5353203109","pt":1646210869717,"mc":[{"id":"1.195503849","rc":[{"atl":[[1000,1.69]],"id":43167130}],"con":true,"img":false}]}
{"op":"mcm","clk":"5353203112","pt":1646210869813,"mc":[{"id":"1.195503849","rc":[{"atl":[[1000,1.87]],"id":41207262}],"con":true,"img":false}]}
{"op":"mcm","clk":"5353203118","pt":1646210869914,"mc":[{"id":"1.195503849","rc":[{"atl":[[1000,0.02]],"id":43167130}],"con":true,"img":false}]}
{"op":"mcm","clk":"5353203122","pt":1646210870021,"mc":[{"id":"1.195503849","rc":[{"atb":[[1.93,40.99]],"id":41207262},{"atl":[[1000,0.2]],"id":41207262},{"atb":[[1.97,39.29]],"id":43167130}],"con":true,"img":false}]}
{"op":"mcm","clk":"5353203127","pt":1646210870120,"mc":[{"id":"1.195503849","rc":[{"atl":[[1000,0]],"id":43167130}],"con":true,"img":false}]}
{"op":"mcm","clk":"5353203131","pt":1646210870224,"mc":[{"id":"1.195503849","rc":[{"atl":[[1000,0]],"id":41207262},{"atl":[[2.1,8.75]],"id":43167130}],"con":true,"img":false}]}
{"op":"mcm","clk":"5353203136","pt":1646210870327,"mc":[{"id":"1.195503849","rc":[{"atl":[[2,1.63]],"id":41207262}],"con":true,"img":false}]}
{"op":"mcm","clk":"5353203175","pt":1646210871319,"mc":[{"id":"1.195503849","rc":[{"atb":[[1.95,0]],"id":41207262},{"atl":[[2.06,0]],"id":43167130}],"con":true,"img":false}]}
{"op":"mcm","clk":"5353203179","pt":1646210871415,"mc":[{"id":"1.195503849","rc":[{"atb":[[1.94,0]],"id":41207262}],"con":true,"img":false}]}
{"op":"mcm","clk":"5353203183","pt":1646210871518,"mc":[{"id":"1.195503849","rc":[{"atb":[[1.93,9.56]],"id":41207262}],"con":true,"img":false}]}
{"op":"mcm","clk":"5353203188","pt":1646210871724,"mc":[{"id":"1.195503849","rc":[{"atb":[[1.92,31.77],[1.93,0]],"id":41207262},{"atl":[[2.08,0]],"id":43167130}],"con":true,"img":false}]}
{"op":"mcm","clk":"5353203196","pt":1646210871929,"mc":[{"id":"1.195503849","rc":[{"atb":[[1.91,9.7]],"id":41207262},{"atl":[[2.1,15.1]],"id":43167130}],"con":true,"img":false}]}
{"op":"mcm","clk":"5353203200","pt":1646210872056,"mc":[{"id":"1.195503849","rc":[{"atb":[[1.92,0],[1.88,1.42],[1.9,1.42]],"id":41207262}],"con":true,"img":false}]}
{"op":"mcm","clk":"5353203212","pt":1646210872314,"mc":[{"id":"1.195503849","rc":[{"atb":[[1.91,16.62]],"id":41207262}],"con":true,"img":false}]}
{"op":"mcm","clk":"5353203220","pt":1646210872520,"mc":[{"id":"1.195503849","rc":[{"atb":[[1.92,9.64],[1.91,48.74]],"id":41207262}],"con":true,"img":false}]}
{"op":"mcm","clk":"5353203226","pt":1646210872622,"mc":[{"id":"1.195503849","rc":[{"atl":[[2.08,8.77]],"id":43167130}],"con":true,"img":false}]}
{"op":"mcm","clk":"5353203234","pt":1646210872828,"mc":[{"id":"1.195503849","rc":[{"atb":[[1.91,41.82]],"id":41207262}],"con":true,"img":false}]}
{"op":"mcm","clk":"5353203240","pt":1646210872930,"mc":[{"id":"1.195503849","rc":[{"atl":[[2.1,8.75]],"id":43167130}],"con":true,"img":false}]}
{"op":"mcm","clk":"5353203247","pt":1646210873138,"mc":[{"id":"1.195503849","rc":[{"atb":[[1.92,20.58]],"id":41207262}],"con":true,"img":false}]}
{"op":"mcm","clk":"5353203253","pt":1646210873243,"mc":[{"id":"1.195503849","rc":[{"atl":[[2.08,18.48]],"id":43167130}],"con":true,"img":false}]}
{"op":"mcm","clk":"5353203256","pt":1646210873347,"mc":[{"id":"1.195503849","rc":[{"atb":[[1.93,9.56]],"id":41207262}],"con":true,"img":false}]}
{"op":"mcm","clk":"5353203267","pt":1646210873556,"mc":[{"id":"1.195503849","rc":[{"atb":[[1.92,52.35]],"id":41207262}],"con":true,"img":false}]}
{"op":"mcm","clk":"5353203270","pt":1646210873610,"mc":[{"id":"1.195503849","rc":[{"atb":[[1.92,41.41]],"id":41207262}],"con":true,"img":false}]}
{"op":"mcm","clk":"5353203275","pt":1646210873712,"mc":[{"id":"1.195503849","rc":[{"atb":[[1.93,20.5]],"id":41207262}],"con":true,"img":false}]}
{"op":"mcm","clk":"5353203279","pt":1646210873818,"mc":[{"id":"1.195503849","rc":[{"atb":[[1.94,9.5]],"id":41207262},{"atl":[[2.06,8.88]],"id":43167130}],"con":true,"img":false}]}
{"op":"mcm","clk":"5353203282","pt":1646210873920,"mc":[{"id":"1.195503849","rc":[{"atb":[[1.87,0],[1.67,0],[1.47,0]],"id":41207262},{"atb":[[1.28,0],[1.68,0],[1.48,0]],"id":43167130}],"con":true,"img":false}]}
{"op":"mcm","clk":"5353203284","pt":1646210874026,"mc":[{"id":"1.195503849","rc":[{"atb":[[1.93,9.56]],"id":41207262},{"atl":[[2.08,8.77]],"id":43167130}],"con":true,"img":false}]}
{"op":"mcm","clk":"5353203288","pt":1646210874130,"mc":[{"id":"1.195503849","rc":[{"atb":[[1.94,20.44]],"id":41207262},{"atl":[[2.06,18.59]],"id":43167130}],"con":true,"img":false}]}
{"op":"mcm","clk":"5353203292","pt":1646210874231,"mc":[{"id":"1.195503849","rc":[{"atb":[[1.95,9.4]],"id":41207262}],"con":true,"img":false}]}
{"op":"mcm","clk":"5353203297","pt":1646210874333,"mc":[{"id":"1.195503849","rc":[{"atb":[[1.91,32.12]],"id":41207262},{"atl":[[2.04,8.99]],"id":43167130}],"con":true,"img":false}]}
{"op":"mcm","clk":"5353203301","pt":1646210874438,"mc":[{"id":"1.195503849","rc":[{"atl":[[2.12,1.42]],"id":43167130}],"con":true,"img":false}]}
{"op":"mcm","clk":"5353203305","pt":1646210874541,"mc":[{"id":"1.195503849","rc":[{"atb":[[1.94,9.5],[1.93,40.99]],"id":41207262},{"atb":[[1.97,9.16],[1.96,39.62]],"id":43167130}],"con":true,"img":false}]}
{"op":"mcm","clk":"5353203307","pt":1646210874643,"mc":[{"id":"1.195503849","rc":[{"atb":[[1.95,20.34]],"id":41207262}],"con":true,"img":false}]}
{"op":"mcm","clk":"5353203311","pt":1646210874745,"mc":[{"id":"1.195503849","rc":[{"atb":[[1.96,9.34]],"id":41207262},{"atl":[[2,0]],"id":41207262},{"trd":[[2,119.87]],"ltp":2.0,"tv":119.87,"id":41207262},{"atb":[[2,0]],"id":43167130},{"trd":[[2,59.79]],"ltp":2.0,"tv":59.79,"id":43167130}],"con":true,"img":false}]}
{"op":"mcm","clk":"5353203320","pt":1646210874952,"mc":[{"id":"1.195503849","rc":[{"atb":[[1.85,1.42],[1.92,31.77]],"id":41207262}],"con":true,"img":false}]}
{"op":"mcm","clk":"5353203323","pt":1646210875055,"mc":[{"id":"1.195503849","rc":[{"atb":[[1.96,9.17]],"id":43167130}],"con":true,"img":false}]}
{"op":"mcm","clk":"5353203333","pt":1646210875367,"mc":[{"id":"1.195503849","rc":[{"atb":[[1.95,9.4]],"id":41207262},{"atl":[[2.06,8.88]],"id":43167130}],"con":true,"img":false}]}
{"op":"mcm","clk":"5353203338","pt":1646210875421,"mc":[{"id":"1.195503849","rc":[{"atb":[[1.96,20.28]],"id":41207262},{"atl":[[2.04,18.7]],"id":43167130}],"con":true,"img":false}]}
{"op":"mcm","clk":"5353203344","pt":1646210875523,"mc":[{"id":"1.195503849","rc":[{"atb":[[1.94,40.59],[1.97,9.28]],"id":41207262},{"atb":[[1.96,39.62]],"id":43167130}],"con":true,"img":false}]}
{"op":"mcm","clk":"5353203350","pt":1646210875627,"mc":[{"id":"1.195503849","rc":[{"atb":[[1.93,31.42]],"id":41207262},{"atl":[[2.1,0.02],[2.02,9.11]],"id":43167130}],"con":true,"img":false}]}
{"op":"mcm","clk":"5353203360","pt":1646210875832,"mc":[{"id":"1.195503849","rc":[{"atb":[[1.96,9.34]],"id":41207262},{"atl":[[2.1,0],[2.08,2]],"id":41207262}],"con":true,"img":false}]}
{"op":"mcm","clk":"5353203363","pt":1646210875935,"mc":[{"id":"1.195503849","rc":[{"atb":[[1.97,20.22]],"id":41207262},{"atl":[[2.04,8.99]],"id":43167130}],"con":true,"img":false}]}
{"op":"mcm","clk":"5353203368","pt":1646210876037,"mc":[{"id":"1.195503849","rc":[{"atb":[[1.91,0]],"id":41207262},{"atb":[[1.96,9.17]],"id":43167130},{"atl":[[2.02,18.82]],"id":43167130}],"con":true,"img":false}]}
{"op":"mcm","clk":"5353203371","pt":1646210876141,"mc":[{"id":"1.195503849","rc":[{"atb":[[1.98,9.22],[1.94,31.09]],"id":41207262},{"atb":[[1.96,0]],"id":43167130}],"con":true,"img":false}]}
{"op":"mcm","clk":"5353203374","pt":1646210876244,"mc":[{"id":"1.195503849","rc":[{"atb":[[1.99,0]],"id":43167130}],"con":true,"img":false}]}
{"op":"mcm","clk":"5353203376","pt":1646210876347,"mc":[{"id":"1.195503849","rc":[{"atl":[[2,0]],"id":41207262},{"trd":[[2,119.88]],"ltp":2.0,"tv":119.88,"id":41207262},{"atb":[[1.91,2]],"id":43167130},{"trd":[[2,59.8]],"ltp":2.0,"tv":59.8,"id":43167130}],"con":true,"img":false}]}
{"op":"mcm","clk":"5353203381","pt":1646210876450,"mc":[{"id":"1.195503849","rc":[{"atb":[[1.97,9.28]],"id":41207262},{"atb":[[1.9,0]],"id":43167130}],"con":true,"img":false}]}
{"op":"mcm","clk":"5353203387","pt":1646210876553,"mc":[{"id":"1.195503849","rc":[{"atb":[[1.98,20.16],[1.94,0]],"id":41207262},{"atb":[[1.92,31.77]],"id":43167130}],"con":true,"img":false}]}
{"op":"mcm","clk":"5353203395","pt":1646210876759,"mc":[{"id":"1.195503849","rc":[{"atb":[[1.87,1.42],[1.99,9.18]],"id":41207262},{"atl":[[2.02,9.11]],"id":43167130}],"con":true,"img":false}]}
{"op":"mcm","clk":"5353203398","pt":1646210876864,"mc":[{"id":"1.195503849","rc":[{"atb":[[1.98,9.22]],"id":41207262}],"con":true,"img":false}]}
{"op":"mcm","clk":"5353203405","pt":1646210876916,"mc":[{"id":"1.195503849","rc":[{"atb":[[1.95,0]],"id":41207262}],"con":true,"img":false}]}
{"op":"mcm","clk":"5353203410","pt":1646210877027,"mc":[{"id":"1.195503849","rc":[{"atl":[[2.02,0]],"id":41207262},{"atb":[[1.92,0]],"id":43167130}],"con":true,"img":false}]}
{"op":"mcm","clk":"5353203432","pt":1646210877432,"mc":[{"id":"1.195503849","rc":[{"atb":[[1.97,0]],"id":41207262},{"atl":[[2.04,0],[2.02,0]],"id":43167130}],"con":true,"img":false}]}
{"op":"mcm","clk":"5353203439","pt":1646210877537,"mc":[{"id":"1.195503849","rc":[{"atb":[[1.98,0],[1.96,0],[1.94,31.09],[1.99,0]],"id":41207262},{"atl":[[2.28,0],[2.26,0]],"id":41207262},{"atb":[[1.87,33.6]],"id":43167130}],"con":true,"img":false}]}
{"op":"mcm","clk":"5353203449","pt":1646210877742,"mc":[{"id":"1.195503849","rc":[{"atl":[[2.06,16.58]],"id":43167130}],"con":true,"img":false}]}
{"op":"mcm","clk":"5353203457","pt":1646210877950,"mc":[{"id":"1.195503849","rc":[{"atb":[[1.94,39.49]],"id":41207262}],"con":true,"img":false}]}
{"op":"mcm","clk":"5353203461","pt":1646210878052,"mc":[{"id":"1.195503849","rc":[{"atb":[[1.92,0],[1.9,10.71],[1.94,8.4],[1.93,0],[1.95,9.29]],"id":41207262},{"atl":[[2.04,9.07]],"id":43167130}],"con":true,"img":false}]}
{"op":"mcm","clk":"5353203468","pt":1646210878258,"mc":[{"id":"1.195503849","rc":[{"atl":[[2.1,2],[2.08,0]],"id":41207262},{"trd":[[1.96,12.48]],"ltp":1.96,"tv":12.48,"id":41207262},{"atl":[[2.04,7.94]],"id":43167130},{"trd":[[2.04,46.01]],"ltp":2.04,"tv":46.01,"id":43167130}],"con":true,"img":false}]}
{"op":"mcm","clk":"5353203475","pt":1646210878361,"mc":[{"id":"1.195503849","rc":[{"atb":[[1.94,0]],"id":41207262},{"atl":[[2.06,8.88]],"id":43167130}],"con":true,"img":false}]}
{"op":"mcm","clk":"5353203484","pt":1646210878464,"mc":[{"id":"1.195503849","rc":[{"atl":[[2.04,15.64]],"id":43167130}],"con":true,"img":false}]}
{"op":"mcm","clk":"5353203491","pt":1646210878568,"mc":[{"id":"1.195503849","rc":[{"atb":[[1.93,31.42]],"id":41207262}],"con":true,"img":false}]}
{"op":"mcm","clk":"5353203498","pt":1646210878672,"mc":[{"id":"1.195503849","rc":[{"atb":[[1.64,8.81],[1.95,17.75]],"id":41207262},{"atb":[[1.9,6.26]],"id":43167130},{"atl":[[2.02,9.11]],"id":43167130}],"con":true,"img":false}]}
{"op":"mcm","clk":"5353203505","pt":1646210878826,"mc":[{"id":"1.195503849","rc":[{"atb":[[1.96,9.22]],"id":41207262}],"con":true,"img":false}]}
{"op":"mcm","clk":"5353203512","pt":1646210879032,"mc":[{"id":"1.195503849","rc":[{"atb":[[1.97,0]],"id":43167130},{"atl":[[2.04,7.94]],"id":43167130}],"con":true,"img":false}]}
{"op":"mcm","clk":"5353203516","pt":1646210879137,"mc":[{"id":"1.195503849","rc":[{"atb":[[1.95,9.29]],"id":41207262},{"atb":[[1.89,2],[1.91,0]],"id":43167130},{"atl":[[2.02,16.81]],"id":43167130}],"con":true,"img":false}]}
{"op":"mcm","clk":"5353203519","pt":1646210879239,"mc":[{"id":"1.195503849","rc":[{"atb":[[1.96,17.68]],"id":41207262}],"con":true,"img":false}]}
{"op":"mcm","clk":"5353203534","pt":1646210879550,"mc":[{"id":"1.195503849","rc":[{"atb":[[1.77,39.96],[1.87,0]],"id":43167130}],"con":true,"img":false}]}
{"op":"mcm","clk":"5353203545","pt":1646210879758,"mc":[{"id":"1.195503849","rc":[{"atl":[[2.02,9.11]],"id":43167130}],"con":true,"img":false}]}
{"op":"mcm","clk":"5353203556","pt":1646210879965,"mc":[{"id":"1.195503849","rc":[{"atb":[[1.91,1.42]],"id":41207262},{"atl":[[90,0.81]],"id":41207262},{"atl":[[2.1,1.44]],"id":43167130}],"con":true,"img":false}]}
{"op":"mcm","clk":"5353203593","pt":1646210880651,"mc":[{"id":"1.195503849","rc":[{"atb":[[1.97,9.02]],"id":41207262}],"con":true,"img":false}]}
{"op":"mcm","clk":"5353203601","pt":1646210880782,"mc":[{"id":"1.195503849","rc":[{"atb":[[1.8,0]],"id":41207262}],"con":true,"img":false}]}
{"op":"mcm","clk":"5353203620","pt":1646210881168,"mc":[{"id":"1.195503849","rc":[{"atb":[[1.96,9.22]],"id":41207262},{"atl":[[2.02,15.59]],"id":43167130}],"con":true,"img":false}]}
{"op":"mcm","clk":"5353203623","pt":1646210881271,"mc":[{"id":"1.195503849","rc":[{"atb":[[1.97,17.48]],"id":41207262}],"con":true,"img":false}]}
{"op":"mcm","clk":"5353203652","pt":1646210881742,"mc":[{"id":"1.195503849","rc":[{"atb":[[1.98,9.01],[1.82,0]],"id":41207262},{"atl":[[2,9.34]],"id":43167130}],"con":true,"img":false}]}
{"op":"mcm","clk":"5353203659","pt":1646210881845,"mc":[{"id":"1.195503849","rc":[{"atl":[[2.08,0]],"id":43167130}],"con":true,"img":false}]}
{"op":"mcm","clk":"5353203668","pt":1646210882051,"mc":[{"id":"1.195503849","rc":[{"atb":[[1.95,40.05],[1.97,9.02]],"id":41207262},{"atl":[[2.04,0]],"id":41207262}],"con":true,"img":false}]}
{"op":"mcm","clk":"5353203674","pt":1646210882154,"mc":[{"id":"1.195503849","rc":[{"atb":[[1.98,17.47]],"id":41207262}],"con":true,"img":false}]}
{"op":"mcm","clk":"5353203688","pt":1646210882463,"mc":[{"id":"1.195503849","rc":[{"atb":[[1.99,8.99]],"id":41207262}],"con":true,"img":false}]}
{"op":"mcm","clk":"5353203697","pt":1646210882566,"mc":[{"id":"1.195503849","rc":[{"atb":[[1.77,2]],"id":43167130}],"con":true,"img":false}]}
{"op":"mcm","clk":"5353203706","pt":1646210882772,"mc":[{"id":"1.195503849","rc":[{"atb":[[1.98,9.01]],"id":41207262}],"con":true,"img":false}]}
{"op":"mcm","clk":"5353203719","pt":1646210883031,"mc":[{"id":"1.195503849","rc":[{"atb":[[1.75,38.97]],"id":43167130}],"con":true,"img":false}]}
{"op":"mcm","clk":"5353203736","pt":1646210883444,"mc":[{"id":"1.195503849","rc":[{"atl":[[2.1,0],[2.14,2]],"id":41207262}],"con":true,"img":false}]}
{"op":"mcm","clk":"5353203743","pt":1646210883652,"mc":[{"id":"1.195503849","rc":[{"atl":[[2.02,9.11]],"id":43167130}],"con":true,"img":false}]}
{"op":"mcm","clk":"5353203752","pt":1646210883704,"mc":[{"id":"1.195503849","rc":[{"atb":[[1.85,0],[1.87,0],[1.88,0],[1.91,0],[1.9,9.29]],"id":41207262},{"atl":[[90,0]],"id":41207262},{"atl":[[2.12,0],[2.1,0.02],[2.24,0],[2.56,0]],"id":43167130}],"con":true,"img":false}]}
{"op":"mcm","clk":"5353203784","pt":1646210884537,"mc":[{"id":"1.195503849","rc":[{"atl":[[2.16,0]],"id":41207262}],"con":true,"img":false}]}
{"op":"mcm","clk":"5353203851","pt":1646210885935,"mc":[{"id":"1.195503849","rc":[{"atb":[[1.89,0],[1.88,2]],"id":43167130}],"con":true,"img":false}]}
{"op":"mcm","clk":"5353203876","pt":1646210886707,"mc":[{"id":"1.195503849","rc":[{"atb":[[1.64,0]],"id":41207262},{"atb":[[1.9,0]],"id":43167130}],"con":true,"img":false}]}
{"op":"mcm","clk":"5353203880","pt":1646210886811,"mc":[{"id":"1.195503849","rc":[{"atb":[[1.99,17.24],[1.67,8.81]],"id":41207262},{"atb":[[1.86,6.26]],"id":43167130},{"atl":[[2,16.92]],"id":43167130}],"con":true,"img":false}]}
{"op":"mcm","clk":"5353203900","pt":1646210887325,"mc":[{"id":"1.195503849","rc":[{"atb":[[1.83,6.51],[1.43,12.56],[1.63,8.57]],"id":41207262},{"atb":[[1.56,9.65],[1.36,15.01],[1.76,9.11]],"id":43167130}],"con":true,"img":false}]}
{"op":"mcm","clk":"5353203918","pt":1646210887741,"mc":[{"id":"1.195503849","rc":[{"atl":[[1.99,9.76]],"id":43167130}],"con":true,"img":false}]}
{"op":"mcm","clk":"5353203923","pt":1646210887845,"mc":[{"id":"1.195503849","rc":[{"atb":[[2,17.24]],"id":41207262},{"atl":[[1.99,19.53]],"id":43167130}],"con":true,"img":false}]}
{"op":"mcm","clk":"5353203929","pt":1646210887948,"mc":[{"id":"1.195503849","rc":[{"atb":[[1.84,0]],"id":41207262},{"atl":[[2.22,0],[2.06,0]],"id":43167130}],"con":true,"img":false}]}
{"op":"mcm","clk":"5353203935","pt":1646210888004,"mc":[{"id":"1.195503849","rc":[{"atl":[[2,9.34]],"id":43167130}],"con":true,"img":false}]}
{"op":"mcm","clk":"5353203943","pt":1646210888157,"mc":[{"id":"1.195503849","rc":[{"atl":[[1.99,27.11]],"id":43167130}],"con":true,"img":false}]}
{"op":"mcm","clk":"5353203948","pt":1646210888209,"mc":[{"id":"1.195503849","rc":[{"atb":[[1.99,8.99]],"id":41207262}],"con":true,"img":false}]}
{"op":"mcm","clk":"5353203957","pt":1646210888316,"mc":[{"id":"1.195503849","rc":[{"atb":[[2,25.49]],"id":41207262},{"atl":[[2.14,6]],"id":41207262},{"atb":[[1.88,6]],"id":43167130}],"con":true,"img":false}]}
{"op":"mcm","clk":"5353203963","pt":1646210888420,"mc":[{"id":"1.195503849","rc":[{"atb":[[2,17.24]],"id":41207262},{"atl":[[2.14,2]],"id":41207262},{"atb":[[1.88,2]],"id":43167130},{"atl":[[1.99,19.53]],"id":43167130}],"con":true,"img":false}]}
{"op":"mcm","clk":"5353203987","pt":1646210888940,"mc":[{"id":"1.195503849","rc":[{"atb":[[2,0]],"id":41207262},{"trd":[[2,167.64]],"ltp":2.0,"tv":167.64,"id":41207262},{"atl":[[1.99,6.2]],"id":43167130},{"trd":[[1.99,13.32]],"ltp":1.99,"tv":13.32,"id":43167130}],"con":true,"img":false}]}
{"op":"mcm","clk":"5353204019","pt":1646210889510,"mc":[{"id":"1.195503849","rc":[{"atb":[[1.99,38.51]],"id":41207262}],"con":true,"img":false}]}
{"op":"mcm","clk":"5353204030","pt":1646210889821,"mc":[{"id":"1.195503849","rc":[{"atb":[[2,8.84]],"id":41207262}],"con":true,"img":false}]}
{"op":"mcm","clk":"5353204038","pt":1646210890030,"mc":[{"id":"1.195503849","rc":[{"atb":[[1.99,8.99]],"id":41207262}],"con":true,"img":false}]}
{"op":"mcm","clk":"5353204073","pt":1646210890802,"mc":[{"id":"1.195503849","rc":[{"atb":[[1.03,3.1]],"id":43167130}],"con":true,"img":false}]}
{"op":"mcm","clk":"5353204080","pt":1646210891007,"mc":[{"id":"1.195503849","rc":[{"atb":[[1.03,0.37]],"id":43167130}],"con":true,"img":false}]}
{"op":"mcm","clk":"5353204087","pt":1646210891111,"mc":[{"id":"1.195503849","rc":[{"atb":[[1.88,0],[1.87,2]],"id":43167130}],"con":true,"img":false}]}
{"op":"mcm","clk":"5353204089","pt":1646210891214,"mc":[{"id":"1.195503849","rc":[{"atb":[[1.03,0]],"id":43167130}],"con":true,"img":false}]}
{"op":"mcm","clk":"5353204093","pt":1646210891318,"mc":[{"id":"1.195503849","rc":[{"atl":[[1.99,5.82]],"id":43167130},{"trd":[[1.99,14.08]],"ltp":1.99,"tv":14.08,"id":43167130}],"con":true,"img":false}]}
{"op":"mcm","clk":"5353204100","pt":1646210891523,"mc":[{"id":"1.195503849","rc":[{"atl":[[1.98,4.47]],"id":43167130}],"con":true,"img":false}]}
{"op":"mcm","clk":"5353204112","pt":1646210891936,"mc":[{"id":"1.195503849","rc":[{"atl":[[1.97,9.71]],"id":43167130}],"con":true,"img":false}]}
{"op":"mcm","clk":"5353204125","pt":1646210892245,"mc":[{"id":"1.195503849","rc":[{"trd":[[2.02,10.91]],"ltp":2.02,"tv":10.91,"id":41207262},{"atl":[[1.98,3],[1.97,0]],"id":43167130},{"trd":[[1.98,1.46],[1.97,9.71]],"ltp":1.98,"tv":11.17,"id":43167130}],"con":true,"img":false}]}
{"op":"mcm","clk":"5353204131","pt":1646210892348,"mc":[{"id":"1.195503849","rc":[{"atb":[[1.87,11.74]],"id":43167130}],"con":true,"img":false}]}
{"op":"mcm","clk":"5353204134","pt":1646210892407,"mc":[{"id":"1.195503849","rc":[{"atl":[[2.14,10.67]],"id":41207262}],"con":true,"img":false}]}
{"op":"mcm","clk":"5353204136","pt":1646210892556,"mc":[{"id":"1.195503849","rc":[{"atb":[[1.97,39.15]],"id":41207262},{"atl":[[2.04,0],[1.97,19.34]],"id":43167130}],"con":true,"img":false}]}
{"op":"mcm","clk":"5353204144","pt":1646210892814,"mc":[{"id":"1.195503849","rc":[{"atb":[[1.67,0]],"id":41207262},{"atb":[[1.86,0]],"id":43167130}],"con":true,"img":false}]}
{"op":"mcm","clk":"5353204150","pt":1646210892917,"mc":[{"id":"1.195503849","rc":[{"atb":[[1.71,8.81]],"id":41207262},{"atb":[[1.82,6.26]],"id":43167130}],"con":true,"img":false}]}
{"op":"mcm","clk":"5353204177","pt":1646210893537,"mc":[{"id":"1.195503849","rc":[{"atb":[[2.02,28.65]],"id":41207262},{"atb":[[1.77,39.96]],"id":43167130}],"con":true,"img":false}]}
{"op":"mcm","clk":"5353204191","pt":1646210893948,"mc":[{"id":"1.195503849","rc":[{"atb":[[2.04,17.08],[1.9,0],[1.04,2.87]],"id":41207262},{"atl":[[2.14,2]],"id":41207262},{"atb":[[1.87,2]],"id":43167130}],"con":true,"img":false}]}
{"op":"mcm","clk":"5353204192","pt":1646210894051,"mc":[{"id":"1.195503849","rc":[{"atb":[[1.87,11.74]],"id":43167130}],"con":true,"img":false}]}
{"op":"mcm","clk":"5353204195","pt":1646210894156,"mc":[{"id":"1.195503849","rc":[{"atb":[[1.04,0.14]],"id":41207262},{"atl":[[2.14,10.29]],"id":41207262},{"atb":[[1.87,21.78]],"id":43167130}],"con":true,"img":false}]}
{"op":"mcm","clk":"5353204205","pt":1646210894312,"mc":[{"id":"1.195503849","rc":[{"atb":[[1.04,0]],"id":41207262}],"con":true,"img":false}]}
{"op":"mcm","clk":"5353204210","pt":1646210894415,"mc":[{"id":"1.195503849","rc":[{"atb":[[2.04,8.54]],"id":41207262},{"atl":[[2.14,18.82]],"id":41207262},{"trd":[[2.14,0.28]],"ltp":2.14,"tv":0.28,"id":41207262}],"con":true,"img":false}]}
{"op":"mcm","clk":"5353204217","pt":1646210894518,"mc":[{"id":"1.195503849","rc":[{"atl":[[2.14,5.86]],"id":41207262},{"atb":[[1.75,0]],"id":43167130}],"con":true,"img":false}]}
{"op":"mcm","clk":"5353204238","pt":1646210895036,"mc":[{"id":"1.195503849","rc":[{"atl":[[2.14,14.53]],"id":41207262}],"con":true,"img":false}]}
{"op":"mcm","clk":"5353204244","pt":1646210895139,"mc":[{"id":"1.195503849","rc":[{"atb":[[1.88,9.6]],"id":43167130},{"atl":[[1.97,9.67]],"id":43167130}],"con":true,"img":false}]}
{"op":"mcm","clk":"5353204254","pt":1646210895344,"mc":[{"id":"1.195503849","rc":[{"atl":[[2.12,8.78]],"id":41207262}],"con":true,"img":false}]}
{"op":"mcm","clk":"5353204261","pt":1646210895449,"mc":[{"id":"1.195503849","rc":[{"atb":[[1.87,11.74]],"id":43167130}],"con":true,"img":false}]}
{"op":"mcm","clk":"5353204264","pt":1646210895554,"mc":[{"id":"1.195503849","rc":[{"atb":[[2,38.07],[2.02,0]],"id":41207262},{"atb":[[1.88,52.85]],"id":43167130}],"con":true,"img":false}]}
{"op":"mcm","clk":"5353204289","pt":1646210896018,"mc":[{"id":"1.195503849","rc":[{"atb":[[1.89,9.59]],"id":43167130}],"con":true,"img":false}]}
{"op":"mcm","clk":"5353204300","pt":1646210896328,"mc":[{"id":"1.195503849","rc":[{"atb":[[1.9,2],[1.87,9.74]],"id":43167130}],"con":true,"img":false}]}
{"op":"mcm","clk":"5353204317","pt":1646210896637,"mc":[{"id":"1.195503849","rc":[{"atb":[[1.71,0]],"id":41207262}],"con":true,"img":false}]}
{"op":"mcm","clk":"5353204322","pt":1646210896740,"mc":[{"id":"1.195503849","rc":[{"atb":[[1.69,8.81]],"id":41207262}],"con":true,"img":false}]}
{"op":"mcm","clk":"5353204353","pt":1646210897511,"mc":[{"id":"1.195503849","rc":[{"atl":[[2.12,0]],"id":41207262},{"atb":[[1.89,0]],"id":43167130}],"con":true,"img":false}]}
{"op":"mcm","clk":"5353204357","pt":1646210897614,"mc":[{"id":"1.195503849","rc":[{"atb":[[1.89,2],[1.9,0]],"id":43167130}],"con":true,"img":false}]}
{"op":"mcm","clk":"5353204369","pt":1646210897820,"mc":[{"id":"1.195503849","rc":[{"atl":[[2.14,10.53]],"id":41207262}],"con":true,"img":false}]}
{"op":"mcm","clk":"5353204399","pt":1646210898442,"mc":[{"id":"1.195503849","rc":[{"atl":[[2.14,18.89]],"id":41207262},{"atb":[[1.88,42.81]],"id":43167130}],"con":true,"img":false}]}
{"op":"mcm","clk":"5353204404","pt":1646210898545,"mc":[{"id":"1.195503849","rc":[{"atb":[[1.89,12.04]],"id":43167130}],"con":true,"img":false}]}
{"op":"mcm","clk":"5353204418","pt":1646210898857,"mc":[{"id":"1.195503849","rc":[{"atb":[[1.89,15.62]],"id":43167130}],"con":true,"img":false}]}
{"op":"mcm","clk":"5353204433","pt":1646210899215,"mc":[{"id":"1.195503849","rc":[{"atl":[[2.12,8.77]],"id":41207262}],"con":true,"img":false}]}
{"op":"mcm","clk":"5353204442","pt":1646210899421,"mc":[{"id":"1.195503849","rc":[{"atl":[[2.14,10.53]],"id":41207262}],"con":true,"img":false}]}
{"op":"mcm","clk":"5353204445","pt":1646210899524,"mc":[{"id":"1.195503849","rc":[{"atl":[[2.12,8.36]],"id":41207262}],"con":true,"img":false}]}
{"op":"mcm","clk":"5353204448","pt":1646210899627,"mc":[{"id":"1.195503849","rc":[{"atb":[[1.89,6]],"id":43167130}],"con":true,"img":false}]}
{"op":"mcm","clk":"5353204463","pt":1646210899942,"mc":[{"id":"1.195503849","rc":[{"atl":[[2.12,0]],"id":41207262},{"atb":[[1.89,15.62]],"id":43167130}],"con":true,"img":false}]}
{"op":"mcm","clk":"5353204466","pt":1646210900042,"mc":[{"id":"1.195503849","rc":[{"atl":[[2.12,8.83],[2.14,18.89]],"id":41207262}],"con":true,"img":false}]}
{"op":"mcm","clk":"5353204481","pt":1646210900351,"mc":[{"id":"1.195503849","rc":[{"atl":[[2.14,10.53]],"id":41207262},{"atb":[[1.9,9.55]],"id":43167130}],"con":true,"img":false}]}
{"op":"mcm","clk":"5353204484","pt":1646210900453,"mc":[{"id":"1.195503849","rc":[{"atl":[[2.12,17.19]],"id":41207262}],"con":true,"img":false}]}
{"op":"mcm","clk":"5353204489","pt":1646210900556,"mc":[{"id":"1.195503849","rc":[{"atb":[[1.77,2]],"id":43167130}],"con":true,"img":false}]}
{"op":"mcm","clk":"5353204497","pt":1646210900710,"mc":[{"id":"1.195503849","rc":[{"atb":[[1.89,11.62]],"id":43167130}],"con":true,"img":false}]}
{"op":"mcm","clk":"5353204513","pt":1646210901019,"mc":[{"id":"1.195503849","rc":[{"atb":[[1.89,44.47],[1.9,15.89]],"id":43167130}],"con":true,"img":false}]}
{"op":"mcm","clk":"5353204520","pt":1646210901225,"mc":[{"id":"1.195503849","rc":[{"atl":[[2.12,8.36]],"id":41207262},{"atb":[[1.89,34.84],[1.9,6.34]],"id":43167130}],"con":true,"img":false}]}
{"op":"mcm","clk":"5353204535","pt":1646210901534,"mc":[{"id":"1.195503849","rc":[{"atl":[[2.12,0]],"id":41207262},{"atb":[[1.89,2],[1.9,0]],"id":43167130}],"con":true,"img":false}]}
{"op":"mcm","clk":"5353204548","pt":1646210901842,"mc":[{"id":"1.195503849","rc":[{"atl":[[2.14,21.48]],"id":41207262},{"atb":[[1.89,6]],"id":43167130}],"con":true,"img":false}]}
{"op":"mcm","clk":"5353204564","pt":1646210902255,"mc":[{"id":"1.195503849","rc":[{"atl":[[2.12,8.78]],"id":41207262}],"con":true,"img":false}]}
{"op":"mcm","clk":"5353204568","pt":1646210902358,"mc":[{"id":"1.195503849","rc":[{"atb":[[1.89,15.6]],"id":43167130}],"con":true,"img":false}]}
{"op":"mcm","clk":"5353204581","pt":1646210902669,"mc":[{"id":"1.195503849","rc":[{"atl":[[2.14,10.53]],"id":41207262}],"con":true,"img":false}]}
{"op":"mcm","clk":"5353204585","pt":1646210902720,"mc":[{"id":"1.195503849","rc":[{"atl":[[2.12,19.73]],"id":41207262}],"con":true,"img":false}]}
{"op":"mcm","clk":"5353204596","pt":1646210903029,"mc":[{"id":"1.195503849","rc":[{"atb":[[1.89,48.45]],"id":43167130}],"con":true,"img":false}]}
{"op":"mcm","clk":"5353204614","pt":1646210903541,"mc":[{"id":"1.195503849","rc":[{"atb":[[1.9,9.56]],"id":43167130}],"con":true,"img":false}]}
{"op":"mcm","clk":"5353204619","pt":1646210903645,"mc":[{"id":"1.195503849","rc":[{"atb":[[1.89,46.45],[1.91,2]],"id":43167130}],"con":true,"img":false}]}
{"op":"mcm","clk":"5353204622","pt":1646210903747,"mc":[{"id":"1.195503849","rc":[{"atb":[[2.04,0]],"id":41207262},{"atl":[[2.02,6.37]],"id":41207262},{"trd":[[2.02,23.29],[2.04,17.08]],"ltp":2.02,"tv":40.37,"id":41207262},{"atb":[[1.89,42.45],[1.9,0]],"id":43167130},{"atl":[[1.98,0],[1.97,0]],"id":43167130},{"trd":[[1.98,4.47],[1.97,19.38]],"ltp":1.98,"tv":23.84,"id":43167130}],"con":true,"img":false}]}
{"op":"mcm","clk":"5353204626","pt":1646210903850,"mc":[{"id":"1.195503849","rc":[{"atl":[[2.02,0],[2.1,8.83]],"id":41207262},{"trd":[[2.02,36.03]],"ltp":2.02,"tv":36.03,"id":41207262},{"atb":[[1.91,9.55],[1.9,2]],"id":43167130}],"con":true,"img":false}]}
{"op":"mcm","clk":"5353204629","pt":1646210903953,"mc":[{"id":"1.195503849","rc":[{"atb":[[1.94,10.31],[1.95,10.26]],"id":43167130}],"con":true,"img":false}]}
{"op":"mcm","clk":"5353204633","pt":1646210904056,"mc":[{"id":"1.195503849","rc":[{"atl":[[2.06,2],[2.14,8.67]],"id":41207262},{"atb":[[1.94,19.76],[1.92,2],[1.9,0]],"id":43167130}],"con":true,"img":false}]}
{"op":"mcm","clk":"5353204637","pt":1646210904159,"mc":[{"id":"1.195503849","rc":[{"atl":[[2.06,10.92],[2.08,2]],"id":41207262}],"con":true,"img":false}]}
{"op":"mcm","clk":"5353204641","pt":1646210904262,"mc":[{"id":"1.195503849","rc":[{"atl":[[2.06,8.92]],"id":41207262},{"atb":[[1.95,30.72],[1.92,0]],"id":43167130}],"con":true,"img":false}]}
{"op":"mcm","clk":"5353204650","pt":1646210904467,"mc":[{"id":"1.195503849","rc":[{"atb":[[2,29.23]],"id":41207262}],"con":true,"img":false}]}
{"op":"mcm","clk":"5353204655","pt":1646210904569,"mc":[{"id":"1.195503849","rc":[{"atb":[[2,0]],"id":41207262},{"atb":[[1.88,9.6]],"id":43167130}],"con":true,"img":false}]}
{"op":"mcm","clk":"5353204671","pt":1646210904934,"mc":[{"id":"1.195503849","rc":[{"atb":[[1.96,9.38]],"id":43167130}],"con":true,"img":false}]}
{"op":"mcm","clk":"5353204678","pt":1646210905037,"mc":[{"id":"1.195503849","rc":[{"atb":[[1.93,31.42]],"id":43167130}],"con":true,"img":false}]}
{"op":"mcm","clk":"5353204692","pt":1646210905346,"mc":[{"id":"1.195503849","rc":[{"atb":[[1.95,21.7]],"id":43167130}],"con":true,"img":false}]}
{"op":"mcm","clk":"5353204698","pt":1646210905449,"mc":[{"id":"1.195503849","rc":[{"atb":[[1.96,18.4]],"id":43167130}],"con":true,"img":false}]}
{"op":"mcm","clk":"5353204706","pt":1646210905552,"mc":[{"id":"1.195503849","rc":[{"atb":[[1.97,9.02]],"id":41207262}],"con":true,"img":false}]}
{"op":"mcm","clk":"5353204711","pt":1646210905655,"mc":[{"id":"1.195503849","rc":[{"atb":[[1.96,9.02]],"id":43167130}],"con":true,"img":false}]}
{"op":"mcm","clk":"5353204717","pt":1646210905762,"mc":[{"id":"1.195503849","rc":[{"atb":[[1.98,0]],"id":41207262}],"con":true,"img":false}]}
{"op":"mcm","clk":"5353204722","pt":1646210905864,"mc":[{"id":"1.195503849","rc":[{"atb":[[1.77,0]],"id":41207262},{"atb":[[1.96,11.02],[1.95,19.7]],"id":43167130}],"con":true,"img":false}]}
{"op":"mcm","clk":"5353204726","pt":1646210905966,"mc":[{"id":"1.195503849","rc":[{"atb":[[1.73,2]],"id":41207262},{"atb":[[1.96,2]],"id":43167130}],"con":true,"img":false}]}
{"op":"mcm","clk":"5353204730","pt":1646210906068,"mc":[{"id":"1.195503849","rc":[{"atb":[[1.96,39.67]],"id":41207262},{"atb":[[1.96,11.38],[1.95,28.72]],"id":43167130},{"atl":[[2.26,0]],"id":43167130}],"con":true,"img":false}]}
{"op":"mcm","clk":"5353204734","pt":1646210906173,"mc":[{"id":"1.195503849","rc":[{"atl":[[2.32,2]],"id":43167130}],"con":true,"img":false}]}
{"op":"mcm","clk":"5353204748","pt":1646210906431,"mc":[{"id":"1.195503849","rc":[{"atb":[[1.95,19.7]],"id":43167130}],"con":true,"img":false}]}
{"op":"mcm","clk":"5353204755","pt":1646210906535,"mc":[{"id":"1.195503849","rc":[{"atb":[[1.96,20.4]],"id":43167130}],"con":true,"img":false}]}
{"op":"mcm","clk":"5353204764","pt":1646210906744,"mc":[{"id":"1.195503849","rc":[{"atb":[[1.95,9.44]],"id":43167130}],"con":true,"img":false}]}
{"op":"mcm","clk":"5353204776","pt":1646210906953,"mc":[{"id":"1.195503849","rc":[{"atl":[[2.12,8.78]],"id":41207262},{"atb":[[1.96,11.38]],"id":43167130}],"con":true,"img":false}]}
{"op":"mcm","clk":"5353204782","pt":1646210907057,"mc":[{"id":"1.195503849","rc":[{"atb":[[1.97,39.15]],"id":41207262}],"con":true,"img":false}]}
{"op":"mcm","clk":"5353204805","pt":1646210907575,"mc":[{"id":"1.195503849","rc":[{"atl":[[2.06,19.35]],"id":41207262},{"atb":[[1.96,21.22]],"id":43167130}],"con":true,"img":false}]}
{"op":"mcm","clk":"5353204819","pt":1646210907834,"mc":[{"id":"1.195503849","rc":[{"atl":[[2.04,8.99]],"id":41207262}],"con":true,"img":false}]}
{"op":"mcm","clk":"5353204830","pt":1646210908042,"mc":[{"id":"1.195503849","rc":[{"atb":[[1.97,9.02]],"id":41207262},{"atl":[[2.06,8.92]],"id":41207262},{"atb":[[1.96,11.38]],"id":43167130}],"con":true,"img":false}]}
{"op":"mcm","clk":"5353204836","pt":1646210908145,"mc":[{"id":"1.195503849","rc":[{"trd":[[2,169.38]],"ltp":2.0,"tv":169.38,"id":41207262},{"atl":[[1.99,4.07]],"id":43167130},{"trd":[[1.99,15.82]],"ltp":1.99,"tv":15.82,"id":43167130}],"con":true,"img":false}]}
{"op":"mcm","clk":"5353204886","pt":1646210909280,"mc":[{"id":"1.195503849","rc":[{"atl":[[2.02,2],[2.08,0]],"id":41207262}],"con":true,"img":false}]}
{"op":"mcm","clk":"5353204895","pt":1646210909436,"mc":[{"id":"1.195503849","rc":[{"atl":[[1.99,0]],"id":43167130},{"trd":[[1.99,23.98]],"ltp":1.99,"tv":23.98,"id":43167130}],"con":true,"img":false}]}
{"op":"mcm","clk":"5353204921","pt":1646210910054,"mc":[{"id":"1.195503849","rc":[{"atb":[[1.89,9.6]],"id":43167130}],"con":true,"img":false}]}
{"op":"mcm","clk":"5353204929","pt":1646210910156,"mc":[{"id":"1.195503849","rc":[{"atl":[[2.02,6]],"id":41207262},{"atb":[[1.96,22.28]],"id":43167130}],"con":true,"img":false}]}
{"op":"mcm","clk":"5353204935","pt":1646210910261,"mc":[{"id":"1.195503849","rc":[{"atb":[[1.97,9.29]],"id":43167130}],"con":true,"img":false}]}
{"op":"mcm","clk":"5353204945","pt":1646210910469,"mc":[{"id":"1.195503849","rc":[{"atb":[[1.97,0]],"id":41207262},{"atb":[[1.91,0]],"id":43167130}],"con":true,"img":false}]}
{"op":"mcm","clk":"5353204950","pt":1646210910569,"mc":[{"id":"1.195503849","rc":[{"atb":[[1.96,9.22]],"id":41207262},{"atb":[[1.94,50.86]],"id":43167130}],"con":true,"img":false}]}
{"op":"mcm","clk":"5353204954","pt":1646210910676,"mc":[{"id":"1.195503849","rc":[{"atb":[[1.96,11.38]],"id":43167130}],"con":true,"img":false}]}
{"op":"mcm","clk":"5353204962","pt":1646210910778,"mc":[{"id":"1.195503849","rc":[{"atb":[[1.97,20.19]],"id":43167130}],"con":true,"img":false}]}
{"op":"mcm","clk":"5353204970","pt":1646210910984,"mc":[{"id":"1.195503849","rc":[{"atb":[[1.98,2],[1.96,9.38]],"id":43167130}],"con":true,"img":false}]}
{"op":"mcm","clk":"5353204974","pt":1646210911035,"mc":[{"id":"1.195503849","rc":[{"atb":[[1.95,9.29]],"id":41207262},{"atb":[[1.94,19.76]],"id":43167130}],"con":true,"img":false}]}
{"op":"mcm","clk":"5353204979","pt":1646210911139,"mc":[{"id":"1.195503849","rc":[{"atl":[[2.02,15.09]],"id":41207262},{"atb":[[1.98,11.26]],"id":43167130}],"con":true,"img":false}]}
{"op":"mcm","clk":"5353204981","pt":1646210911242,"mc":[{"id":"1.195503849","rc":[{"atb":[[1.94,10.31]],"id":43167130},{"atl":[[2,0]],"id":43167130}],"con":true,"img":false}]}
{"op":"mcm","clk":"5353204986","pt":1646210911344,"mc":[{"id":"1.195503849","rc":[{"atb":[[1.97,9.29]],"id":43167130}],"con":true,"img":false}]}
{"op":"mcm","clk":"5353204989","pt":1646210911447,"mc":[{"id":"1.195503849","rc":[{"atb":[[1.98,22.16]],"id":43167130}],"con":true,"img":false}]}
{"op":"mcm","clk":"5353204992","pt":1646210911550,"mc":[{"id":"1.195503849","rc":[{"atb":[[1.94,31.09]],"id":41207262},{"atb":[[1.96,39.83]],"id":43167130}],"con":true,"img":false}]}
{"op":"mcm","clk":"5353205014","pt":1646210912069,"mc":[{"id":"1.195503849","rc":[{"atb":[[1.94,0]],"id":41207262}],"con":true,"img":false}]}
{"op":"mcm","clk":"5353205020","pt":1646210912173,"mc":[{"id":"1.195503849","rc":[{"atb":[[1.95,0],[1.99,9.18]],"id":43167130}],"con":true,"img":false}]}
{"op":"mcm","clk":"5353205028","pt":1646210912274,"mc":[{"id":"1.195503849","rc":[{"atb":[[1.99,0]],"id":41207262}],"con":true,"img":false}]}
{"op":"mcm","clk":"5353205034","pt":1646210912378,"mc":[{"id":"1.195503849","rc":[{"atb":[[1.98,20.16],[1.99,11.18]],"id":43167130}],"con":true,"img":false}]}
{"op":"mcm","clk":"5353205047","pt":1646210912584,"mc":[{"id":"1.195503849","rc":[{"atb":[[1.93,0],[1.87,33.6]],"id":41207262},{"atb":[[1.98,9.26],[1.96,9.38],[1.94,41.4]],"id":43167130}],"con":true,"img":false}]}
{"op":"mcm","clk":"5353205052","pt":1646210912687,"mc":[{"id":"1.195503849","rc":[{"atb":[[1.99,22.08]],"id":43167130}],"con":true,"img":false}]}
{"op":"mcm","clk":"5353205060","pt":1646210912841,"mc":[{"id":"1.195503849","rc":[{"atb":[[1.69,0]],"id":41207262},{"atb":[[1.82,0]],"id":43167130}],"con":true,"img":false}]}
{"op":"mcm","clk":"5353205114","pt":1646210914078,"mc":[{"id":"1.195503849","rc":[{"atb":[[1.94,10.31],[1.95,19.55]],"id":41207262}],"con":true,"img":false}]}
{"op":"mcm","clk":"5353205134","pt":1646210914545,"mc":[{"id":"1.195503849","rc":[{"atb":[[1.93,31.42]],"id":41207262},{"atb":[[1.93,0]],"id":43167130}],"con":true,"img":false}]}
{"op":"mcm","clk":"5353205153","pt":1646210915066,"mc":[{"id":"1.195503849","rc":[{"atb":[[1.99,12.9]],"id":43167130}],"con":true,"img":false}]}
{"op":"mcm","clk":"5353205160","pt":1646210915271,"mc":[{"id":"1.195503849","rc":[{"atb":[[1.99,6]],"id":43167130}],"con":true,"img":false}]}
{"op":"mcm","clk":"5353205171","pt":1646210915578,"mc":[{"id":"1.195503849","rc":[{"atb":[[1.96,39.83]],"id":43167130}],"con":true,"img":false}]}
{"op":"mcm","clk":"5353205234","pt":1646210916967,"mc":[{"id":"1.195503849","rc":[{"atb":[[1.99,15.2]],"id":43167130}],"con":true,"img":false}]}
{"op":"mcm","clk":"5353205250","pt":1646210917386,"mc":[{"id":"1.195503849","marketDefinition":{"bspMarket":false,"turnInPlayEnabled":false,"persistenceEnabled":false,"marketBaseRate":7.0,"eventId":"31272499","eventTypeId":"4339","numberOfWinners":1,"bettingType":"ODDS","marketType":"MATCH_BET","marketTime":"2022-03-02T08:48:00.000Z","suspendTime":"2022-03-02T08:48:00.000Z","bspReconciled":false,"complete":true,"inPlay":false,"crossMatching":true,"runnersVoidable":false,"numberOfActiveRunners":2,"betDelay":0,"status":"SUSPENDED","runners":[{"status":"ACTIVE","sortPriority":1,"id":41207262,"name":"1. Kooky Loopy"},{"status":"ACTIVE","sortPriority":2,"id":43167130,"name":"2. Suited It"}],"regulators":["MR_INT"],"venue":"Rockhampton","countryCode":"AU","discountAllowed":true,"timezone":"Australia/Queensland","openDate":"2022-03-02T08:28:00.000Z","version":4382852223,"name":"Kooky Loopy v Suited It","eventName":"Rockhampton (AUS) 2nd Mar"},"rc":[],"con":true,"img":false}]}
{"op":"mcm","clk":"5353205250","pt":1646210917386,"mc":[{"id":"1.195503849","rc":[{"atb":[[1.73,0],[1.83,0],[1.63,0],[1.43,0],[1.96,0],[1.94,0],[1.95,0],[1.93,0],[1.87,0]],"id":41207262},{"atl":[[2.02,0],[2.06,0],[2.04,0],[2.12,0],[2.1,0],[2.14,0]],"id":41207262},{"atb":[[1.98,0],[1.89,0],[1.96,0],[1.94,0],[1.87,0],[1.76,0],[1.56,0],[1.36,0],[1.99,0],[1.97,0],[1.74,0],[1.88,0],[1.77,0]],"id":43167130},{"atl":[[2.8,0],[2.82,0],[2.32,0],[2.64,0],[2.58,0],[2.62,0],[2.1,0],[2.76,0],[2.02,0],[2.74,0],[2.86,0],[2.18,0],[2.66,0],[2.2,0],[2.16,0],[2.68,0],[2.7,0]],"id":43167130}],"con":true,"img":false}]}
{"op":"mcm","clk":"5353215177","pt":1646211185988,"mc":[{"id":"1.195503849","rc":[{"trd":[[2,0],[1.72,0],[1.99,0],[2.02,0],[1.89,0],[1.98,0],[1.74,0],[2.04,0],[1.7,0],[1.96,0],[2.14,0],[1.69,0]],"ltp":2.0,"tv":0.0,"id":41207262},{"trd":[[2,0],[1.99,0],[2.02,0],[1.98,0],[1.97,0],[2.04,0],[2.12,0],[2.44,0],[2.14,0]],"ltp":2.0,"tv":0.0,"id":43167130}],"con":true,"img":false}]}
{"op":"mcm","clk":"5353215229","pt":1646211187097,"mc":[{"id":"1.195503849","marketDefinition":{"bspMarket":false,"turnInPlayEnabled":false,"persistenceEnabled":false,"marketBaseRate":7.0,"eventId":"31272499","eventTypeId":"4339","numberOfWinners":1,"bettingType":"ODDS","marketType":"MATCH_BET","marketTime":"2022-03-02T08:48:00.000Z","suspendTime":"2022-03-02T08:48:00.000Z","bspReconciled":false,"complete":true,"inPlay":false,"crossMatching":false,"runnersVoidable":false,"numberOfActiveRunners":0,"betDelay":0,"status":"CLOSED","settledTime":"2022-03-02T08:53:04.000Z","runners":[{"status":"WINNER","sortPriority":1,"id":41207262,"name":"1. Kooky Loopy"},{"status":"LOSER","sortPriority":2,"id":43167130,"name":"2. Suited It"}],"regulators":["MR_INT"],"venue":"Rockhampton","countryCode":"AU","discountAllowed":true,"timezone":"Australia/Queensland","openDate":"2022-03-02T08:28:00.000Z","version":4382853110,"name":"Kooky Loopy v Suited It","eventName":"Rockhampton (AUS) 2nd Mar"},"rc":[],"con":true,"img":false}]}
