{"op":"mcm","clk":"5345985300","pt":1646174444262,"mc":[{"id":"1.195453621","marketDefinition":{"bspMarket":true,"turnInPlayEnabled":false,"persistenceEnabled":false,"marketBaseRate":7.0,"eventId":"31272494","eventTypeId":"4339","numberOfWinners":1,"bettingType":"ODDS","marketType":"WIN","marketTime":"2022-03-02T10:27:00.000Z","suspendTime":"2022-03-02T10:27:00.000Z","bspReconciled":false,"complete":true,"inPlay":false,"crossMatching":false,"runnersVoidable":false,"numberOfActiveRunners":7,"betDelay":0,"status":"OPEN","runners":[{"status":"ACTIVE","sortPriority":1,"id":40250501,"name":"1. Dwarshuis"},{"status":"ACTIVE","sortPriority":2,"id":6780934,"name":"2. Peacock"},{"status":"ACTIVE","sortPriority":3,"id":40846831,"name":"3. Rapid Voyage"},{"status":"ACTIVE","sortPriority":4,"id":23806261,"name":"4. Impending"},{"status":"ACTIVE","sortPriority":5,"id":40199925,"name":"6. Parzival"},{"status":"ACTIVE","sortPriority":6,"id":41308374,"name":"7. Gotham Baroness"},{"status":"ACTIVE","sortPriority":7,"id":36463352,"name":"8. Massimo"}],"regulators":["MR_INT"],"venue":"Traralgon","countryCode":"AU","discountAllowed":true,"timezone":"Australia/Sydney","openDate":"2022-03-02T08:31:00.000Z","version":4382425379,"name":"R7 500m Gr5","eventName":"Traralgon (AUS) 2nd Mar"},"rc":[],"con":true,"img":false}]}
{"op":"mcm","clk":"5346059516","pt":1646175786519,"mc":[{"id":"1.195453621","rc":[{"atb":[[7.2,26.34],[9.2,9.95],[10.5,4.29],[8.2,11.33],[15.5,2.81]],"id":23806261},{"atl":[[130,1.02],[280,0.71],[180,0.74],[230,0.87]],"id":23806261},{"spn":72.75,"spf":"NaN","id":23806261},{"atb":[[6.8,14.07],[9.8,4.63],[7.8,6],[5.9,16.66],[5.4,37.11]],"id":40250501},{"atl":[[70,1.92],[140,1.43],[95,1.41],[190,1.05]],"id":40250501},{"spn":39.9,"spf":"NaN","id":40250501},{"atb":[[2,81.65],[2.3,31.4],[1.9,181.45],[1.95,85.94],[2.1,37.11]],"id":36463352},{"atl":[[5.6,28.92],[7.2,32.18],[6.2,25.58],[8.2,27.71]],"id":36463352},{"spn":3.95,"spf":"NaN","id":36463352},{"atb":[[2,40.82],[1.8,102.06],[1.85,96.06],[1.9,45.36],[1.75,217.74]],"id":41308374},{"atl":[[5.6,28.92],[7.2,32.18],[5.1,32.44],[6.2,38.37]],"id":41308374},{"spn":3.55,"spf":"NaN","id":41308374},{"atb":[[7.2,26.34],[9.2,9.95],[10.5,4.29],[8.2,11.33],[15.5,2.81]],"id":40199925},{"atl":[[130,1.02],[280,0.71],[180,0.74],[230,0.87]],"id":40199925},{"spn":72.75,"spf":"NaN","id":40199925},{"atb":[[4,54.43],[4.5,23.33],[5,20.41],[5.5,9.07],[7,6.8]],"id":40846831},{"atl":[[70,2.89],[38,3.59],[48,4.24],[29,4.75]],"id":40846831},{"spn":18.0,"spf":"NaN","id":40846831},{"atb":[[4,54.43],[4.5,23.33],[5,20.41],[5.5,9.07],[7,6.8]],"id":6780934},{"atl":[[70,2.89],[38,3.59],[48,4.24],[29,4.75]],"id":6780934},{"spn":18.0,"spf":"NaN","id":6780934}],"con":true,"img":false}]}
{"op":"mcm","clk":"5346061998","pt":1646175839944,"mc":[{"id":"1.195453621","rc":[{"atb":[[7.2,0],[9.2,0],[10.5,0],[8.2,0],[15.5,0]],"id":23806261},{"atl":[[130,0],[280,0],[180,0],[230,0]],"id":23806261},{"atb":[[6.8,0],[9.8,0],[7.8,0],[5.9,0],[5.4,0]],"id":40250501},{"atl":[[70,0],[140,0],[95,0],[190,0]],"id":40250501},{"atb":[[2,0],[2.3,0],[1.9,0],[1.95,0],[2.1,0]],"id":36463352},{"atl":[[5.6,0],[7.2,0],[6.2,0],[8.2,0]],"id":36463352},{"atb":[[2,0],[1.8,0],[1.85,0],[1.9,0],[1.75,0]],"id":41308374},{"atl":[[5.6,0],[7.2,0],[5.1,0],[6.2,0]],"id":41308374},{"atb":[[7.2,0],[9.2,0],[10.5,0],[8.2,0],[15.5,0]],"id":40199925},{"atl":[[130,0],[280,0],[180,0],[230,0]],"id":40199925},{"atb":[[4,0],[4.5,0],[5,0],[5.5,0],[7,0]],"id":40846831},{"atl":[[70,0],[38,0],[48,0],[29,0]],"id":40846831},{"atb":[[4,0],[4.5,0],[5,0],[5.5,0],[7,0]],"id":6780934},{"atl":[[70,0],[38,0],[48,0],[29,0]],"id":6780934}],"con":true,"img":false}]}
{"op":"mcm","clk":"5346062134","pt":1646175843189,"mc":[{"id":"1.195453621","rc":[{"atb":[[7.2,26.34],[9.2,9.95],[10.5,4.29],[8.2,11.33],[15.5,2.81]],"id":23806261},{"atl":[[130,1.02],[280,0.71],[180,0.74],[230,0.87]],"id":23806261},{"atb":[[6.8,14.07],[9.8,4.63],[7.8,6],[5.9,16.66],[5.4,37.11]],"id":40250501},{"atl":[[70,1.92],[140,1.43],[95,1.41],[190,1.05]],"id":40250501},{"atb":[[2,81.65],[2.3,31.4],[1.9,181.45],[1.95,85.94],[2.1,37.11]],"id":36463352},{"atl":[[5.6,28.92],[7.2,32.18],[6.2,25.58],[8.2,27.71]],"id":36463352},{"atb":[[2,40.82],[1.8,102.06],[1.85,96.06],[1.9,45.36],[1.75,217.74]],"id":41308374},{"atl":[[5.6,28.92],[7.2,32.18],[5.1,32.44],[6.2,38.37]],"id":41308374},{"atb":[[7.2,26.34],[9.2,9.95],[10.5,4.29],[8.2,11.33],[15.5,2.81]],"id":40199925},{"atl":[[130,1.02],[280,0.71],[180,0.74],[230,0.87]],"id":40199925},{"atb":[[4,54.43],[4.5,23.33],[5,20.41],[5.5,9.07],[7,6.8]],"id":40846831},{"atl":[[70,2.89],[38,3.59],[48,4.24],[29,4.75]],"id":40846831},{"atb":[[4,54.43],[4.5,23.33],[5,20.41],[5.5,9.07],[7,6.8]],"id":6780934},{"atl":[[70,2.89],[38,3.59],[48,4.24],[29,4.75]],"id":6780934}],"con":true,"img":false}]}
{"op":"mcm","clk":"5346105179","pt":1646176602705,"mc":[{"id":"1.195453621","marketDefinition":{"bspMarket":true,"turnInPlayEnabled":false,"persistenceEnabled":false,"marketBaseRate":7.0,"eventId":"31272494","eventTypeId":"4339","numberOfWinners":1,"bettingType":"ODDS","marketType":"WIN","marketTime":"2022-03-02T10:27:00.000Z","suspendTime":"2022-03-02T10:27:00.000Z","bspReconciled":false,"complete":true,"inPlay":false,"crossMatching":false,"runnersVoidable":false,"numberOfActiveRunners":7,"betDelay":0,"status":"OPEN","runners":[{"status":"ACTIVE","sortPriority":1,"id":40250501,"name":"1. Dwarshuis"},{"status":"ACTIVE","sortPriority":2,"id":6780934,"name":"2. Peacock"},{"status":"ACTIVE","sortPriority":3,"id":40846831,"name":"3. Rapid Voyage"},{"status":"ACTIVE","sortPriority":4,"id":23806261,"name":"4. Impending"},{"status":"ACTIVE","sortPriority":5,"id":40199925,"name":"6. Parzival"},{"status":"ACTIVE","sortPriority":6,"id":41308374,"name":"7. Gotham Baroness"},{"status":"ACTIVE","sortPriority":7,"id":36463352,"name":"8. Massimo"}],"regulators":["MR_INT"],"venue":"Traralgon","countryCode":"AU","discountAllowed":true,"timezone":"Australia/Sydney","openDate":"2022-03-02T08:31:00.000Z","version":4382425379,"name":"R7 500m Gr5","eventName":"Traralgon (AUS) 2nd Mar"},"rc":[{"atb":[[7.2,26.34],[9.2,9.95],[10.5,4.29],[8.2,11.33],[15.5,2.81]],"id":23806261},{"atl":[[130,1.02],[280,0.71],[180,0.74],[230,0.87]],"id":23806261},{"spn":72.75,"spf":"NaN","id":23806261},{"atb":[[6.8,14.07],[9.8,4.63],[7.8,6],[5.9,16.66],[5.4,37.11]],"id":40250501},{"atl":[[70,1.92],[140,1.43],[95,1.41],[190,1.05]],"id":40250501},{"spn":39.9,"spf":"NaN","id":40250501},{"atb":[[2,81.65],[2.3,31.4],[1.9,181.45],[1.95,85.94],[2.1,37.11]],"id":36463352},{"atl":[[5.6,28.92],[7.2,32.18],[6.2,25.58],[8.2,27.71]],"id":36463352},{"spn":3.95,"spf":"NaN","id":36463352},{"atb":[[2,40.82],[1.8,102.06],[1.85,96.06],[1.9,45.36],[1.75,217.74]],"id":41308374},{"atl":[[5.6,28.92],[7.2,32.18],[5.1,32.44],[6.2,38.37]],"id":41308374},{"spn":3.55,"spf":"NaN","id":41308374},{"atb":[[7.2,26.34],[9.2,9.95],[10.5,4.29],[8.2,11.33],[15.5,2.81]],"id":40199925},{"atl":[[130,1.02],[280,0.71],[180,0.74],[230,0.87]],"id":40199925},{"spn":72.75,"spf":"NaN","id":40199925},{"atb":[[4,54.43],[4.5,23.33],[5,20.41],[5.5,9.07],[7,6.8]],"id":40846831},{"atl":[[70,2.89],[38,3.59],[48,4.24],[29,4.75]],"id":40846831},{"spn":18.0,"spf":"NaN","id":40846831},{"atb":[[4,54.43],[4.5,23.33],[5,20.41],[5.5,9.07],[7,6.8]],"id":6780934},{"atl":[[70,2.89],[38,3.59],[48,4.24],[29,4.75]],"id":6780934},{"spn":18.0,"spf":"NaN","id":6780934}],"con":true,"img":true}]}
{"op":"mcm","clk":"5346278561","pt":1646180037231,"mc":[{"id":"1.195453621","rc":[{"atb":[[7.2,26.34],[9.2,9.95],[10.5,4.29],[8.2,11.34],[15.5,2.81]],"id":23806261},{"atl":[[130,1.02]],"id":23806261},{"atb":[[6.8,14.07],[9.8,4.63],[7.8,6],[5.9,16.66],[5.4,37.11]],"id":40250501},{"atl":[[70,1.92],[140,1.43],[95,1.41],[190,1.05]],"id":40250501},{"atb":[[2,81.66],[2.3,31.4],[1.9,181.47],[1.95,85.95],[2.1,37.11]],"id":36463352},{"spl":[[1.01,2.72]],"id":36463352},{"atl":[[5.6,28.92],[7.2,32.19],[6.2,25.58],[8.2,27.72]],"id":36463352},{"spn":2.3,"spf":1.0,"id":36463352},{"atb":[[2,40.83],[1.8,102.07],[1.85,96.07],[1.9,45.36],[1.75,217.77]],"id":41308374},{"atl":[[5.6,28.92],[7.2,32.19],[5.1,32.45],[6.2,38.38]],"id":41308374},{"atb":[[7.2,26.34],[9.2,9.95],[10.5,4.29],[8.2,11.34],[15.5,2.81]],"id":40199925},{"atl":[[130,1.02]],"id":40199925},{"atb":[[4,54.44],[4.5,23.33],[5,20.41],[5.5,9.07],[7,6.8]],"id":40846831},{"atl":[[70,2.89],[38,3.59],[48,4.24],[29,4.75]],"id":40846831},{"atb":[[4,54.44],[4.5,23.33],[5,20.41],[5.5,9.07],[7,6.8]],"id":6780934},{"atl":[[70,2.89],[38,3.59],[48,4.24],[29,4.75]],"id":6780934}],"con":true,"img":false}]}
{"op":"mcm","clk":"5346767991","pt":1646187402735,"mc":[{"id":"1.195453621","marketDefinition":{"bspMarket":true,"turnInPlayEnabled":false,"persistenceEnabled":false,"marketBaseRate":7.0,"eventId":"31272494","eventTypeId":"4339","numberOfWinners":1,"bettingType":"ODDS","marketType":"WIN","marketTime":"2022-03-02T10:27:00.000Z","suspendTime":"2022-03-02T10:27:00.000Z","bspReconciled":false,"complete":true,"inPlay":false,"crossMatching":false,"runnersVoidable":false,"numberOfActiveRunners":7,"betDelay":0,"status":"OPEN","runners":[{"status":"ACTIVE","sortPriority":1,"id":40250501,"name":"1. Dwarshuis"},{"status":"ACTIVE","sortPriority":2,"id":6780934,"name":"2. Peacock"},{"status":"ACTIVE","sortPriority":3,"id":40846831,"name":"3. Rapid Voyage"},{"status":"ACTIVE","sortPriority":4,"id":23806261,"name":"4. Impending"},{"status":"ACTIVE","sortPriority":5,"id":40199925,"name":"6. Parzival"},{"status":"ACTIVE","sortPriority":6,"id":41308374,"name":"7. Gotham Baroness"},{"status":"ACTIVE","sortPriority":7,"id":36463352,"name":"8. Massimo"}],"regulators":["MR_INT"],"venue":"Traralgon","countryCode":"AU","discountAllowed":true,"timezone":"Australia/Sydney","openDate":"2022-03-02T08:31:00.000Z","version":4382425379,"name":"R7 500m Gr5","eventName":"Traralgon (AUS) 2nd Mar"},"rc":[{"atb":[[7.2,26.38],[9.2,9.97],[10.5,4.3],[8.2,11.35],[15.5,2.81]],"id":23806261},{"atl":[[130,1.03],[280,0.71],[180,0.74],[230,0.87]],"id":23806261},{"spn":72.75,"spf":"NaN","id":23806261},{"atb":[[6.8,14.1],[9.8,4.64],[7.8,6.01],[5.9,16.69],[5.4,37.17]],"id":40250501},{"atl":[[70,1.93],[140,1.43],[95,1.41],[190,1.05]],"id":40250501},{"spn":39.9,"spf":"NaN","id":40250501},{"atb":[[2,81.79],[2.3,31.45],[1.9,181.76],[1.95,86.09],[2.1,37.17]],"id":36463352},{"spl":[[1.01,2.72]],"id":36463352},{"atl":[[5.6,28.97],[7.2,32.24],[6.2,25.62],[8.2,27.76]],"id":36463352},{"spn":2.3,"spf":1.0,"id":36463352},{"atb":[[2,40.89],[1.8,102.24],[1.85,96.22],[1.9,45.43],[1.75,218.11]],"id":41308374},{"atl":[[5.6,28.97],[7.2,32.24],[5.1,32.5],[6.2,38.44]],"id":41308374},{"spn":3.55,"spf":"NaN","id":41308374},{"atb":[[7.2,26.38],[9.2,9.97],[10.5,4.3],[8.2,11.35],[15.5,2.81]],"id":40199925},{"atl":[[130,1.03],[280,0.71],[180,0.74],[230,0.87]],"id":40199925},{"spn":72.75,"spf":"NaN","id":40199925},{"atb":[[4,54.52],[4.5,23.37],[5,20.44],[5.5,9.08],[7,6.81]],"id":40846831},{"atl":[[70,2.89],[38,3.6],[48,4.25],[29,4.76]],"id":40846831},{"spn":18.0,"spf":"NaN","id":40846831},{"atb":[[4,54.52],[4.5,23.37],[5,20.44],[5.5,9.08],[7,6.81]],"id":6780934},{"atl":[[70,2.89],[38,3.6],[48,4.25],[29,4.76]],"id":6780934},{"spn":18.0,"spf":"NaN","id":6780934}],"con":true,"img":true}]}
{"op":"mcm","clk":"5347092542","pt":1646192802714,"mc":[{"id":"1.195453621","marketDefinition":{"bspMarket":true,"turnInPlayEnabled":false,"persistenceEnabled":false,"marketBaseRate":7.0,"eventId":"31272494","eventTypeId":"4339","numberOfWinners":1,"bettingType":"ODDS","marketType":"WIN","marketTime":"2022-03-02T10:27:00.000Z","suspendTime":"2022-03-02T10:27:00.000Z","bspReconciled":false,"complete":true,"inPlay":false,"crossMatching":false,"runnersVoidable":false,"numberOfActiveRunners":7,"betDelay":0,"status":"OPEN","runners":[{"status":"ACTIVE","sortPriority":1,"id":40250501,"name":"1. Dwarshuis"},{"status":"ACTIVE","sortPriority":2,"id":6780934,"name":"2. Peacock"},{"status":"ACTIVE","sortPriority":3,"id":40846831,"name":"3. Rapid Voyage"},{"status":"ACTIVE","sortPriority":4,"id":23806261,"name":"4. Impending"},{"status":"ACTIVE","sortPriority":5,"id":40199925,"name":"6. Parzival"},{"status":"ACTIVE","sortPriority":6,"id":41308374,"name":"7. Gotham Baroness"},{"status":"ACTIVE","sortPriority":7,"id":36463352,"name":"8. Massimo"}],"regulators":["MR_INT"],"venue":"Traralgon","countryCode":"AU","discountAllowed":true,"timezone":"Australia/Sydney","openDate":"2022-03-02T08:31:00.000Z","version":4382425379,"name":"R7 500m Gr5","eventName":"Traralgon (AUS) 2nd Mar"},"rc":[{"atb":[[7.2,26.43],[9.2,9.99],[10.5,4.3],[8.2,11.37],[15.5,2.82]],"id":23806261},{"atl":[[130,1.03],[280,0.71],[180,0.74],[230,0.87]],"id":23806261},{"spn":72.75,"spf":"NaN","id":23806261},{"atb":[[6.8,14.12],[9.8,4.65],[7.8,6.02],[5.9,16.71],[5.4,37.24]],"id":40250501},{"atl":[[70,1.93],[140,1.44],[95,1.42],[190,1.05]],"id":40250501},{"spn":39.9,"spf":"NaN","id":40250501},{"atb":[[2,81.93],[2.3,31.51],[1.9,182.06],[1.95,86.24],[2.1,37.24]],"id":36463352},{"spl":[[1.01,2.73]],"id":36463352},{"atl":[[5.6,29.02],[7.2,32.29],[6.2,25.67],[8.2,27.81]],"id":36463352},{"spn":2.3,"spf":1.0,"id":36463352},{"atb":[[2,40.96],[1.8,102.41],[1.85,96.38],[1.9,45.51],[1.75,218.48]],"id":41308374},{"atl":[[5.6,29.02],[7.2,32.29],[5.1,32.55],[6.2,38.5]],"id":41308374},{"spn":3.55,"spf":"NaN","id":41308374},{"atb":[[7.2,26.43],[9.2,9.99],[10.5,4.3],[8.2,11.37],[15.5,2.82]],"id":40199925},{"atl":[[130,1.03],[280,0.71],[180,0.74],[230,0.87]],"id":40199925},{"spn":72.75,"spf":"NaN","id":40199925},{"atb":[[4,54.62],[4.5,23.41],[5,20.48],[5.5,9.1],[7,6.82]],"id":40846831},{"atl":[[70,2.9],[38,3.61],[48,4.26],[29,4.76]],"id":40846831},{"spn":18.0,"spf":"NaN","id":40846831},{"atb":[[4,54.62],[4.5,23.41],[5,20.48],[5.5,9.1],[7,6.82]],"id":6780934},{"atl":[[70,2.9],[38,3.61],[48,4.26],[29,4.76]],"id":6780934},{"spn":18.0,"spf":"NaN","id":6780934}],"con":true,"img":true}]}
{"op":"mcm","clk":"5347341023","pt":1646197424945,"mc":[{"id":"1.195453621","rc":[{"atb":[[7.2,26.42],[9.2,9.98],[10.5,4.3],[8.2,11.37],[15.5,2.82]],"id":23806261},{"atl":[[130,1.03],[280,0.71],[180,0.74],[230,0.87]],"id":23806261},{"atb":[[6.8,14.11],[9.8,4.65],[7.8,6.02],[5.9,16.71],[5.4,37.22]],"id":40250501},{"atl":[[70,1.93],[140,1.44],[95,1.41],[190,1.05]],"id":40250501},{"atb":[[2,81.9],[2.3,31.49],[1.9,181.99],[1.95,86.2],[2.1,37.22]],"id":36463352},{"spl":[[1.01,2.73]],"id":36463352},{"atl":[[5.6,29],[7.2,32.28],[6.2,25.66],[8.2,27.8]],"id":36463352},{"atb":[[2,40.95],[1.8,102.37],[1.85,96.35],[1.9,45.49],[1.75,218.4]],"id":41308374},{"atl":[[5.6,29],[7.2,32.28],[3.45,8.19],[5.1,32.54],[6.2,38.49]],"id":41308374},{"spn":2.72,"spf":"NaN","id":41308374},{"atb":[[7.2,26.42],[9.2,9.98],[10.5,4.3],[8.2,11.37],[15.5,2.82]],"id":40199925},{"atl":[[130,1.03],[280,0.71],[180,0.74],[230,0.87]],"id":40199925},{"atb":[[4,54.6],[4.5,23.4],[5,20.47],[5.5,9.1],[7,6.82]],"id":40846831},{"atl":[[70,2.89],[38,3.6],[48,4.25],[29,4.76]],"id":40846831},{"atb":[[4,54.6],[4.5,23.4],[5,20.47],[5.5,9.1],[7,6.82]],"id":6780934},{"atl":[[70,2.89],[38,3.6],[48,4.25],[29,4.76]],"id":6780934}],"con":true,"img":false}]}
{"op":"mcm","clk":"5347442048","pt":1646199442701,"mc":[{"id":"1.195453621","rc":[{"atl":[[2.7,6.2]],"id":41308374},{"spn":2.35,"spf":"NaN","id":41308374}],"con":true,"img":false}]}
{"op":"mcm","clk":"5347442821","pt":1646199453683,"mc":[{"id":"1.195453621","rc":[{"atl":[[4,4.92]],"id":36463352}],"con":true,"img":false}]}
{"op":"mcm","clk":"5347467017","pt":1646200028623,"mc":[{"id":"1.195453621","rc":[{"atl":[[65,0.49]],"id":40250501},{"spn":37.4,"spf":"NaN","id":40250501}],"con":true,"img":false}]}
{"op":"mcm","clk":"5347467023","pt":1646200028724,"mc":[{"id":"1.195453621","rc":[{"atl":[[120,0.49]],"id":23806261}],"con":true,"img":false}]}
{"op":"mcm","clk":"5347468052","pt":1646200051960,"mc":[{"id":"1.195453621","marketDefinition":{"bspMarket":true,"turnInPlayEnabled":false,"persistenceEnabled":false,"marketBaseRate":7.0,"eventId":"31272494","eventTypeId":"4339","numberOfWinners":1,"bettingType":"ODDS","marketType":"WIN","marketTime":"2022-03-02T10:27:00.000Z","suspendTime":"2022-03-02T10:27:00.000Z","bspReconciled":false,"complete":true,"inPlay":false,"crossMatching":true,"runnersVoidable":false,"numberOfActiveRunners":7,"betDelay":0,"status":"OPEN","runners":[{"status":"ACTIVE","sortPriority":1,"id":40250501,"name":"1. Dwarshuis"},{"status":"ACTIVE","sortPriority":2,"id":6780934,"name":"2. Peacock"},{"status":"ACTIVE","sortPriority":3,"id":40846831,"name":"3. Rapid Voyage"},{"status":"ACTIVE","sortPriority":4,"id":23806261,"name":"4. Impending"},{"status":"ACTIVE","sortPriority":5,"id":40199925,"name":"6. Parzival"},{"status":"ACTIVE","sortPriority":6,"id":41308374,"name":"7. Gotham Baroness"},{"status":"ACTIVE","sortPriority":7,"id":36463352,"name":"8. Massimo"}],"regulators":["MR_INT"],"venue":"Traralgon","countryCode":"AU","discountAllowed":true,"timezone":"Australia/Sydney","openDate":"2022-03-02T08:31:00.000Z","version":4382425379,"name":"R7 500m Gr5","eventName":"Traralgon (AUS) 2nd Mar"},"rc":[],"con":true,"img":false}]}
{"op":"mcm","clk":"5347624544","pt":1646203602735,"mc":[{"id":"1.195453621","marketDefinition":{"bspMarket":true,"turnInPlayEnabled":false,"persistenceEnabled":false,"marketBaseRate":7.0,"eventId":"31272494","eventTypeId":"4339","numberOfWinners":1,"bettingType":"ODDS","marketType":"WIN","marketTime":"2022-03-02T10:27:00.000Z","suspendTime":"2022-03-02T10:27:00.000Z","bspReconciled":false,"complete":true,"inPlay":false,"crossMatching":true,"runnersVoidable":false,"numberOfActiveRunners":7,"betDelay":0,"status":"OPEN","runners":[{"status":"ACTIVE","sortPriority":1,"id":40250501,"name":"1. Dwarshuis"},{"status":"ACTIVE","sortPriority":2,"id":6780934,"name":"2. Peacock"},{"status":"ACTIVE","sortPriority":3,"id":40846831,"name":"3. Rapid Voyage"},{"status":"ACTIVE","sortPriority":4,"id":23806261,"name":"4. Impending"},{"status":"ACTIVE","sortPriority":5,"id":40199925,"name":"6. Parzival"},{"status":"ACTIVE","sortPriority":6,"id":41308374,"name":"7. Gotham Baroness"},{"status":"ACTIVE","sortPriority":7,"id":36463352,"name":"8. Massimo"}],"regulators":["MR_INT"],"venue":"Traralgon","countryCode":"AU","discountAllowed":true,"timezone":"Australia/Sydney","openDate":"2022-03-02T08:31:00.000Z","version":4382425379,"name":"R7 500m Gr5","eventName":"Traralgon (AUS) 2nd Mar"},"rc":[{"atb":[[7.2,26.42],[9.2,9.98],[10.5,4.3],[8.2,11.37],[15.5,2.82]],"id":23806261},{"atl":[[130,1.03],[280,0.71],[180,0.74],[230,0.87],[120,0.49]],"id":23806261},{"spn":67.75,"spf":"NaN","id":23806261},{"atb":[[6.8,14.11],[9.8,4.65],[7.8,6.02],[5.9,16.71],[5.4,37.22]],"id":40250501},{"atl":[[65,0.49],[70,1.93],[140,1.44],[95,1.41],[190,1.05]],"id":40250501},{"spn":37.4,"spf":"NaN","id":40250501},{"atb":[[2,81.9],[2.3,31.49],[1.9,181.99],[1.95,86.2],[2.1,37.22]],"id":36463352},{"spl":[[1.01,2.73]],"id":36463352},{"atl":[[4,4.92],[5.6,29],[7.2,32.28],[6.2,25.66],[8.2,27.8]],"id":36463352},{"spn":2.3,"spf":1.0,"id":36463352},{"atb":[[2,40.95],[1.8,102.37],[1.85,96.35],[1.9,45.49],[1.75,218.4]],"id":41308374},{"atl":[[5.6,29],[3.45,8.19],[7.2,32.28],[5.1,32.54],[6.2,38.49],[2.7,6.2]],"id":41308374},{"spn":2.35,"spf":"NaN","id":41308374},{"atb":[[7.2,26.42],[9.2,9.98],[10.5,4.3],[8.2,11.37],[15.5,2.82]],"id":40199925},{"atl":[[130,1.03],[280,0.71],[180,0.74],[230,0.87]],"id":40199925},{"spn":72.75,"spf":"NaN","id":40199925},{"atb":[[4,54.6],[4.5,23.4],[5,20.47],[5.5,9.1],[7,6.82]],"id":40846831},{"atl":[[70,2.89],[38,3.6],[48,4.25],[29,4.76]],"id":40846831},{"spn":18.0,"spf":"NaN","id":40846831},{"atb":[[4,54.6],[4.5,23.4],[5,20.47],[5.5,9.1],[7,6.82]],"id":6780934},{"atl":[[70,2.89],[38,3.6],[48,4.25],[29,4.76]],"id":6780934},{"spn":18.0,"spf":"NaN","id":6780934}],"con":true,"img":true}]}
{"op":"mcm","clk":"5347799871","pt":1646208060369,"mc":[{"id":"1.195453621","rc":[{"atb":[[7.2,26.41],[9.2,9.98],[10.5,4.3],[8.2,11.37],[15.5,2.82]],"id":23806261},{"atl":[[130,1.03],[280,0.71],[180,0.74],[230,0.87]],"id":23806261},{"spn":67.75,"spf":"NaN","id":23806261},{"atb":[[6.8,14.11],[9.8,4.65],[7.8,6.02],[5.9,16.7],[5.4,37.21]],"id":40250501},{"atl":[[70,1.93],[140,1.44],[95,1.41],[190,1.05]],"id":40250501},{"atb":[[2,81.87],[2.3,31.49],[1.9,181.94],[1.95,86.18],[2.1,37.21]],"id":36463352},{"spl":[[1.01,2.72]],"id":36463352},{"atl":[[4,4.93],[5.6,29],[7.2,32.27],[6.2,25.65],[8.2,27.79]],"id":36463352},{"atb":[[2,40.93],[1.8,102.34],[1.85,96.32],[1.9,45.48],[1.75,218.34]],"id":41308374},{"atl":[[5.6,29],[3.45,8.18],[7.2,32.27],[5.1,32.53],[6.2,38.48],[2.7,6.21]],"id":41308374},{"atb":[[7.2,26.41],[9.2,9.98],[10.5,4.3],[8.2,11.37],[15.5,2.82]],"id":40199925},{"atl":[[130,1.03],[280,0.71],[180,0.74],[230,0.87]],"id":40199925},{"atb":[[4,54.58],[4.5,23.39],[5,20.46],[5.5,9.09],[7,6.82]],"id":40846831},{"atl":[[70,2.89],[38,3.6],[48,4.25],[29,4.76]],"id":40846831},{"atb":[[4,54.58],[4.5,23.39],[5.1,2.46],[5,20.46],[5.5,9.09],[7,6.82]],"id":6780934},{"atl":[[70,2.89],[38,3.6],[48,4.25],[29,4.76]],"id":6780934}],"con":true,"img":false}]}
{"op":"mcm","clk":"5347799875","pt":1646208060470,"mc":[{"id":"1.195453621","rc":[{"atb":[[2.04,9.72]],"id":36463352}],"con":true,"img":false}]}
{"op":"mcm","clk":"5347799891","pt":1646208060780,"mc":[{"id":"1.195453621","rc":[{"atb":[[5.1,2.46]],"id":40846831}],"con":true,"img":false}]}
{"op":"mcm","clk":"5347799895","pt":1646208060882,"mc":[{"id":"1.195453621","rc":[{"atb":[[2.04,9.72]],"id":41308374}],"con":true,"img":false}]}
{"op":"mcm","clk":"5347801071","pt":1646208092093,"mc":[{"id":"1.195453621","rc":[{"atb":[[2.34,5.61]],"id":36463352},{"atb":[[2.04,16.96]],"id":41308374},{"atb":[[1.01,2.25]],"id":40846831},{"atb":[[1.01,2.25]],"id":6780934}],"con":true,"img":false}]}
{"op":"mcm","clk":"5347801076","pt":1646208092294,"mc":[{"id":"1.195453621","rc":[{"atb":[[1.01,1.83]],"id":6780934}],"con":true,"img":false}]}
{"op":"mcm","clk":"5347801081","pt":1646208092397,"mc":[{"id":"1.195453621","rc":[{"atb":[[1.01,1.83]],"id":40846831}],"con":true,"img":false}]}
{"op":"mcm","clk":"5347801085","pt":1646208092500,"mc":[{"id":"1.195453621","rc":[{"atb":[[1.01,0]],"id":6780934}],"con":true,"img":false}]}
{"op":"mcm","clk":"5347801089","pt":1646208092601,"mc":[{"id":"1.195453621","rc":[{"atb":[[5.1,4.3]],"id":6780934}],"con":true,"img":false}]}
{"op":"mcm","clk":"5347801097","pt":1646208092806,"mc":[{"id":"1.195453621","rc":[{"atb":[[1.01,0]],"id":40846831}],"con":true,"img":false}]}
{"op":"mcm","clk":"5347801101","pt":1646208092909,"mc":[{"id":"1.195453621","rc":[{"atb":[[5.1,4.3]],"id":40846831}],"con":true,"img":false}]}
{"op":"mcm","clk":"5347849095","pt":1646209002736,"mc":[{"id":"1.195453621","marketDefinition":{"bspMarket":true,"turnInPlayEnabled":false,"persistenceEnabled":false,"marketBaseRate":7.0,"eventId":"31272494","eventTypeId":"4339","numberOfWinners":1,"bettingType":"ODDS","marketType":"WIN","marketTime":"2022-03-02T10:27:00.000Z","suspendTime":"2022-03-02T10:27:00.000Z","bspReconciled":false,"complete":true,"inPlay":false,"crossMatching":true,"runnersVoidable":false,"numberOfActiveRunners":7,"betDelay":0,"status":"OPEN","runners":[{"status":"ACTIVE","sortPriority":1,"id":40250501,"name":"1. Dwarshuis"},{"status":"ACTIVE","sortPriority":2,"id":6780934,"name":"2. Peacock"},{"status":"ACTIVE","sortPriority":3,"id":40846831,"name":"3. Rapid Voyage"},{"status":"ACTIVE","sortPriority":4,"id":23806261,"name":"4. Impending"},{"status":"ACTIVE","sortPriority":5,"id":40199925,"name":"6. Parzival"},{"status":"ACTIVE","sortPriority":6,"id":41308374,"name":"7. Gotham Baroness"},{"status":"ACTIVE","sortPriority":7,"id":36463352,"name":"8. Massimo"}],"regulators":["MR_INT"],"venue":"Traralgon","countryCode":"AU","discountAllowed":true,"timezone":"Australia/Sydney","openDate":"2022-03-02T08:31:00.000Z","version":4382425379,"name":"R7 500m Gr5","eventName":"Traralgon (AUS) 2nd Mar"},"rc":[{"atb":[[7.2,26.41],[9.2,9.98],[10.5,4.3],[8.2,11.37],[15.5,2.82]],"id":23806261},{"atl":[[130,1.03],[280,0.71],[180,0.74],[230,0.87],[120,0.49]],"id":23806261},{"spn":67.75,"spf":"NaN","id":23806261},{"atb":[[6.8,14.11],[9.8,4.65],[7.8,6.02],[5.9,16.7],[5.4,37.21]],"id":40250501},{"atl":[[65,0.49],[70,1.93],[140,1.44],[95,1.41],[190,1.05]],"id":40250501},{"spn":37.4,"spf":"NaN","id":40250501},{"atb":[[2,81.87],[2.3,31.49],[2.04,9.72],[1.9,181.94],[1.95,86.18],[2.1,37.21],[2.34,5.61]],"id":36463352},{"spl":[[1.01,2.72]],"id":36463352},{"atl":[[4,4.93],[5.6,29],[7.2,32.27],[6.2,25.65],[8.2,27.79]],"id":36463352},{"spn":2.34,"spf":1.0,"id":36463352},{"atb":[[2,40.93],[1.8,102.34],[2.04,16.96],[1.85,96.32],[1.9,45.48],[1.75,218.34]],"id":41308374},{"atl":[[5.6,29],[3.45,8.18],[7.2,32.27],[5.1,32.53],[6.2,38.48],[2.7,6.21]],"id":41308374},{"spn":2.37,"spf":"NaN","id":41308374},{"atb":[[7.2,26.41],[9.2,9.98],[10.5,4.3],[8.2,11.37],[15.5,2.82]],"id":40199925},{"atl":[[130,1.03],[280,0.71],[180,0.74],[230,0.87]],"id":40199925},{"spn":72.75,"spf":"NaN","id":40199925},{"atb":[[4,54.58],[5.1,4.3],[4.5,23.39],[5,20.46],[5.5,9.09],[7,6.82]],"id":40846831},{"atl":[[70,2.89],[38,3.6],[48,4.25],[29,4.76]],"id":40846831},{"spn":18.0,"spf":"NaN","id":40846831},{"atb":[[4,54.58],[5.1,4.3],[4.5,23.39],[5,20.46],[5.5,9.09],[7,6.82]],"id":6780934},{"atl":[[70,2.89],[38,3.6],[48,4.25],[29,4.76]],"id":6780934},{"spn":18.0,"spf":"NaN","id":6780934}],"con":true,"img":true}]}
{"op":"mcm","clk":"5347883089","pt":1646209620134,"mc":[{"id":"1.195453621","rc":[{"atb":[[18.5,0.58]],"id":23806261},{"spn":69.25,"spf":"NaN","id":23806261},{"atb":[[11.5,0.96]],"id":40250501},{"spn":38.25,"spf":"NaN","id":40250501},{"atb":[[2.26,2]],"id":36463352},{"spn":2.34,"spf":1.0,"id":36463352},{"atb":[[2.02,2]],"id":41308374},{"spn":2.37,"spf":"NaN","id":41308374},{"atb":[[19.5,0.55]],"id":40199925},{"spn":74.75,"spf":"NaN","id":40199925},{"atb":[[8.2,1.4]],"id":40846831},{"spn":18.6,"spf":"NaN","id":40846831},{"atb":[[7.6,1.53]],"id":6780934},{"spn":18.3,"spf":"NaN","id":6780934}],"con":true,"img":false}]}
{"op":"mcm","clk":"5347905574","pt":1646210116508,"mc":[{"id":"1.195453621","rc":[{"atb":[[2.02,0]],"id":41308374}],"con":true,"img":false}]}
{"op":"mcm","clk":"5347905579","pt":1646210116612,"mc":[{"id":"1.195453621","rc":[{"atb":[[1.99,2]],"id":41308374}],"con":true,"img":false}]}
{"op":"mcm","clk":"5347909174","pt":1646210202107,"mc":[{"id":"1.195453621","rc":[{"atb":[[5.6,8.55]],"id":6780934}],"con":true,"img":false}]}
{"op":"mcm","clk":"5347909187","pt":1646210202314,"mc":[{"id":"1.195453621","rc":[{"atb":[[5.6,8.55]],"id":40846831}],"con":true,"img":false}]}
{"op":"mcm","clk":"5347923244","pt":1646210560434,"mc":[{"id":"1.195453621","rc":[{"atb":[[5.6,0]],"id":6780934}],"con":true,"img":false}]}
{"op":"mcm","clk":"5347923257","pt":1646210560632,"mc":[{"id":"1.195453621","rc":[{"atb":[[5.2,9.41]],"id":6780934}],"con":true,"img":false}]}
{"op":"mcm","clk":"5347923266","pt":1646210560846,"mc":[{"id":"1.195453621","rc":[{"atb":[[5.6,0]],"id":40846831}],"con":true,"img":false}]}
{"op":"mcm","clk":"5347923272","pt":1646210561045,"mc":[{"id":"1.195453621","rc":[{"atb":[[5.2,9.41]],"id":40846831}],"con":true,"img":false}]}
{"op":"mcm","clk":"5347925833","pt":1646210621626,"mc":[{"id":"1.195453621","rc":[{"atb":[[5.2,0]],"id":6780934}],"con":true,"img":false}]}
{"op":"mcm","clk":"5347925842","pt":1646210621779,"mc":[{"id":"1.195453621","rc":[{"atb":[[5.7,8.4]],"id":6780934}],"con":true,"img":false}]}
{"op":"mcm","clk":"5347925854","pt":1646210621985,"mc":[{"id":"1.195453621","rc":[{"atb":[[5.2,0]],"id":40846831}],"con":true,"img":false}]}
{"op":"mcm","clk":"5347925862","pt":1646210622191,"mc":[{"id":"1.195453621","rc":[{"atb":[[5.7,8.4]],"id":40846831}],"con":true,"img":false}]}
{"op":"mcm","clk":"5347928581","pt":1646210682780,"mc":[{"id":"1.195453621","rc":[{"atb":[[5.7,0]],"id":6780934}],"con":true,"img":false}]}
{"op":"mcm","clk":"5347928589","pt":1646210682988,"mc":[{"id":"1.195453621","rc":[{"atb":[[5.6,8.55]],"id":6780934}],"con":true,"img":false}]}
{"op":"mcm","clk":"5347928599","pt":1646210683199,"mc":[{"id":"1.195453621","rc":[{"atb":[[5.7,0]],"id":40846831}],"con":true,"img":false}]}
{"op":"mcm","clk":"5347928608","pt":1646210683400,"mc":[{"id":"1.195453621","rc":[{"atb":[[5.6,8.55]],"id":40846831}],"con":true,"img":false}]}
{"op":"mcm","clk":"5347931226","pt":1646210743690,"mc":[{"id":"1.195453621","rc":[{"atb":[[5.6,0]],"id":6780934}],"con":true,"img":false}]}
{"op":"mcm","clk":"5347931233","pt":1646210743895,"mc":[{"id":"1.195453621","rc":[{"atb":[[5.8,8.24]],"id":6780934}],"con":true,"img":false}]}
{"op":"mcm","clk":"5347931243","pt":1646210744100,"mc":[{"id":"1.195453621","rc":[{"atb":[[5.6,0]],"id":40846831}],"con":true,"img":false}]}
{"op":"mcm","clk":"5347931253","pt":1646210744307,"mc":[{"id":"1.195453621","rc":[{"atb":[[5.8,8.24]],"id":40846831}],"con":true,"img":false}]}
{"op":"mcm","clk":"5347936775","pt":1646210865266,"mc":[{"id":"1.195453621","rc":[{"atb":[[5.8,0]],"id":6780934}],"con":true,"img":false}]}
{"op":"mcm","clk":"5347936784","pt":1646210865476,"mc":[{"id":"1.195453621","rc":[{"atb":[[5.2,9.41]],"id":6780934}],"con":true,"img":false}]}
{"op":"mcm","clk":"5347936801","pt":1646210865787,"mc":[{"id":"1.195453621","rc":[{"atb":[[5.8,0]],"id":40846831}],"con":true,"img":false}]}
{"op":"mcm","clk":"5347936810","pt":1646210865988,"mc":[{"id":"1.195453621","rc":[{"atb":[[5.2,9.41]],"id":40846831}],"con":true,"img":false}]}
{"op":"mcm","clk":"5347939942","pt":1646210926364,"mc":[{"id":"1.195453621","rc":[{"atb":[[5.2,0]],"id":6780934}],"con":true,"img":false}]}
{"op":"mcm","clk":"5347939950","pt":1646210926570,"mc":[{"id":"1.195453621","rc":[{"atb":[[5.9,8.08]],"id":6780934}],"con":true,"img":false}]}
{"op":"mcm","clk":"5347939959","pt":1646210926774,"mc":[{"id":"1.195453621","rc":[{"atb":[[5.2,0]],"id":40846831}],"con":true,"img":false}]}
{"op":"mcm","clk":"5347939970","pt":1646210926981,"mc":[{"id":"1.195453621","rc":[{"atb":[[5.9,8.08]],"id":40846831}],"con":true,"img":false}]}
{"op":"mcm","clk":"5347946255","pt":1646211048716,"mc":[{"id":"1.195453621","rc":[{"atb":[[5.9,0]],"id":6780934}],"con":true,"img":false}]}
{"op":"mcm","clk":"5347946270","pt":1646211048874,"mc":[{"id":"1.195453621","rc":[{"atb":[[5.6,8.55]],"id":6780934}],"con":true,"img":false}]}
{"op":"mcm","clk":"5347946285","pt":1646211049086,"mc":[{"id":"1.195453621","rc":[{"atb":[[5.9,0]],"id":40846831}],"con":true,"img":false}]}
{"op":"mcm","clk":"5347946299","pt":1646211049337,"mc":[{"id":"1.195453621","rc":[{"atb":[[5.6,8.55]],"id":40846831}],"con":true,"img":false}]}
{"op":"mcm","clk":"5347949605","pt":1646211110495,"mc":[{"id":"1.195453621","rc":[{"atb":[[5.6,0]],"id":6780934}],"con":true,"img":false}]}
{"op":"mcm","clk":"5347949620","pt":1646211110762,"mc":[{"id":"1.195453621","rc":[{"atb":[[5.2,9.41]],"id":6780934}],"con":true,"img":false}]}
{"op":"mcm","clk":"5347949630","pt":1646211110961,"mc":[{"id":"1.195453621","rc":[{"atb":[[5.6,0]],"id":40846831}],"con":true,"img":false}]}
{"op":"mcm","clk":"5347949640","pt":1646211111170,"mc":[{"id":"1.195453621","rc":[{"atb":[[5.2,9.41]],"id":40846831}],"con":true,"img":false}]}
{"op":"mcm","clk":"5347952498","pt":1646211171394,"mc":[{"id":"1.195453621","rc":[{"atb":[[5.2,0]],"id":6780934}],"con":true,"img":false}]}
{"op":"mcm","clk":"5347952509","pt":1646211171595,"mc":[{"id":"1.195453621","rc":[{"atb":[[5.7,8.4]],"id":6780934}],"con":true,"img":false}]}
{"op":"mcm","clk":"5347952520","pt":1646211171758,"mc":[{"id":"1.195453621","rc":[{"atb":[[5.2,0]],"id":40846831}],"con":true,"img":false}]}
{"op":"mcm","clk":"5347952531","pt":1646211171963,"mc":[{"id":"1.195453621","rc":[{"atb":[[5.7,8.4]],"id":40846831}],"con":true,"img":false}]}
{"op":"mcm","clk":"5347955331","pt":1646211232473,"mc":[{"id":"1.195453621","rc":[{"atb":[[5.7,0]],"id":6780934}],"con":true,"img":false}]}
{"op":"mcm","clk":"5347955340","pt":1646211232680,"mc":[{"id":"1.195453621","rc":[{"atb":[[5.2,9.41]],"id":6780934}],"con":true,"img":false}]}
{"op":"mcm","clk":"5347955349","pt":1646211232884,"mc":[{"id":"1.195453621","rc":[{"atb":[[5.7,0]],"id":40846831}],"con":true,"img":false}]}
{"op":"mcm","clk":"5347955356","pt":1646211233048,"mc":[{"id":"1.195453621","rc":[{"atb":[[5.2,9.41]],"id":40846831}],"con":true,"img":false}]}
{"op":"mcm","clk":"5347958515","pt":1646211293118,"mc":[{"id":"1.195453621","rc":[{"atb":[[5.2,0]],"id":6780934}],"con":true,"img":false}]}
{"op":"mcm","clk":"5347958522","pt":1646211293323,"mc":[{"id":"1.195453621","rc":[{"atb":[[5.6,8.55]],"id":6780934}],"con":true,"img":false}]}
{"op":"mcm","clk":"5347958531","pt":1646211293528,"mc":[{"id":"1.195453621","rc":[{"atb":[[5.2,0]],"id":40846831}],"con":true,"img":false}]}
{"op":"mcm","clk":"5347958541","pt":1646211293734,"mc":[{"id":"1.195453621","rc":[{"atb":[[5.6,8.55]],"id":40846831}],"con":true,"img":false}]}
{"op":"mcm","clk":"5347964441","pt":1646211420788,"mc":[{"id":"1.195453621","rc":[{"atb":[[8.2,21.37]],"id":23806261},{"atb":[[5.4,53.57]],"id":40250501},{"atb":[[4,78.58]],"id":40846831},{"atb":[[4,78.58]],"id":6780934}],"con":true,"img":false}]}
{"op":"mcm","clk":"5347964448","pt":1646211420893,"mc":[{"id":"1.195453621","rc":[{"atb":[[1.47,153.19]],"id":41308374},{"atb":[[8.2,21.37]],"id":40199925}],"con":true,"img":false}]}
{"op":"mcm","clk":"5347964453","pt":1646211420995,"mc":[{"id":"1.195453621","rc":[{"atb":[[3.6,31.54]],"id":40250501},{"atb":[[1.61,118.03]],"id":36463352},{"atb":[[2.8,45.56]],"id":6780934}],"con":true,"img":false}]}
{"op":"mcm","clk":"5347964460","pt":1646211421098,"mc":[{"id":"1.195453621","rc":[{"atb":[[5.3,19.07]],"id":23806261},{"atb":[[2.8,45.56]],"id":40846831}],"con":true,"img":false}]}
{"op":"mcm","clk":"5347964473","pt":1646211421301,"mc":[{"id":"1.195453621","rc":[{"atb":[[1.36,227.78]],"id":36463352},{"atb":[[1.28,292.86]],"id":41308374},{"atb":[[5.3,19.07]],"id":40199925}],"con":true,"img":false}]}
{"op":"mcm","clk":"5347964477","pt":1646211421403,"mc":[{"id":"1.195453621","rc":[{"atb":[[2.62,46.3],[4.2,26.56]],"id":23806261},{"atb":[[2.62,46.3]],"id":40250501},{"atl":[[17,8.5],[8.6,14.2],[6.8,8.2]],"id":36463352},{"atl":[[17,8.5],[34,13.5],[5,8.2],[6,14.2]],"id":41308374},{"atb":[[2.62,46.3],[4.2,26.56]],"id":40199925},{"atb":[[2.62,46.3]],"id":40846831},{"atl":[[70,11.09],[95,14.2]],"id":40846831},{"atb":[[2.62,46.3]],"id":6780934},{"atl":[[70,11.09],[95,14.2]],"id":6780934}],"con":true,"img":false}]}
{"op":"mcm","clk":"5347964482","pt":1646211421505,"mc":[{"id":"1.195453621","rc":[{"atl":[[34,13.5]],"id":36463352}],"con":true,"img":false}]}
{"op":"mcm","clk":"5347967059","pt":1646211477089,"mc":[{"id":"1.195453621","rc":[{"atb":[[5.6,0]],"id":6780934}],"con":true,"img":false}]}
{"op":"mcm","clk":"5347967069","pt":1646211477398,"mc":[{"id":"1.195453621","rc":[{"atb":[[5.2,9.41]],"id":6780934}],"con":true,"img":false}]}
{"op":"mcm","clk":"5347967080","pt":1646211477609,"mc":[{"id":"1.195453621","rc":[{"atb":[[5.6,0]],"id":40846831}],"con":true,"img":false}]}
{"op":"mcm","clk":"5347967087","pt":1646211477769,"mc":[{"id":"1.195453621","rc":[{"atb":[[5.2,9.41]],"id":40846831}],"con":true,"img":false}]}
{"op":"mcm","clk":"5347967545","pt":1646211488277,"mc":[{"id":"1.195453621","rc":[{"atb":[[17.5,3.54],[15,8.4]],"id":23806261},{"atl":[[80,2.72],[60,2.72]],"id":23806261},{"spn":39.25,"spf":"NaN","id":23806261},{"atb":[[10,13.06],[12,5.32]],"id":40250501},{"atl":[[36,2.72],[46,2.72]],"id":40250501},{"spn":24.0,"spf":"NaN","id":40250501},{"atb":[[2.02,112.91],[2.14,52.27]],"id":36463352},{"atl":[[4.8,25.59],[3.8,20.9]],"id":36463352},{"atb":[[2.02,55.9],[1.91,139.19]],"id":41308374},{"atl":[[3.35,24.91],[4.2,39.84]],"id":41308374},{"atb":[[18.5,3.34],[15.5,11.55]],"id":40199925},{"atl":[[70,2.72],[85,2.72]],"id":40199925},{"spn":44.75,"spf":"NaN","id":40199925},{"atb":[[7.6,8.87],[6.6,19.78]],"id":40846831},{"atl":[[19,3.25],[26,4.1]],"id":40846831},{"spn":13.6,"spf":"NaN","id":40846831},{"atb":[[7.2,18.53],[7.8,8.6]],"id":6780934},{"atl":[[20,3.07],[26,4.25]],"id":6780934},{"spn":13.9,"spf":"NaN","id":6780934}],"con":true,"img":false}]}
{"op":"mcm","clk":"5347967891","pt":1646211496805,"mc":[{"id":"1.195453621","rc":[{"atb":[[2.04,9.72]],"id":41308374},{"atb":[[5.1,2.46]],"id":40846831},{"atb":[[5.1,2.46]],"id":6780934}],"con":true,"img":false}]}
{"op":"mcm","clk":"5347968194","pt":1646211505736,"mc":[{"id":"1.195453621","rc":[{"atb":[[2.06,7.09]],"id":41308374},{"atb":[[1.01,2.25]],"id":40846831}],"con":true,"img":false}]}
{"op":"mcm","clk":"5347968203","pt":1646211505939,"mc":[{"id":"1.195453621","rc":[{"atb":[[1.01,1.29]],"id":40846831}],"con":true,"img":false}]}
{"op":"mcm","clk":"5347968216","pt":1646211506103,"mc":[{"id":"1.195453621","rc":[{"atb":[[1.01,0]],"id":40846831}],"con":true,"img":false}]}
{"op":"mcm","clk":"5347968220","pt":1646211506204,"mc":[{"id":"1.195453621","rc":[{"atb":[[6.8,1.29]],"id":40846831}],"con":true,"img":false}]}
{"op":"mcm","clk":"5347968378","pt":1646211510042,"mc":[{"id":"1.195453621","rc":[{"atb":[[2.04,0]],"id":36463352},{"atb":[[2.04,0]],"id":41308374},{"atb":[[5.1,0]],"id":40846831},{"atb":[[5.1,0]],"id":6780934}],"con":true,"img":false}]}
{"op":"mcm","clk":"5347968841","pt":1646211522348,"mc":[{"id":"1.195453621","rc":[{"atb":[[2.06,16.62]],"id":41308374},{"atb":[[6.8,3.03]],"id":40846831}],"con":true,"img":false}]}
{"op":"mcm","clk":"5347968859","pt":1646211522753,"mc":[{"id":"1.195453621","rc":[{"atb":[[2.18,8.56]],"id":36463352}],"con":true,"img":false}]}
{"op":"mcm","clk":"5347969445","pt":1646211537781,"mc":[{"id":"1.195453621","rc":[{"atb":[[5.2,0]],"id":6780934}],"con":true,"img":false}]}
{"op":"mcm","clk":"5347969451","pt":1646211537985,"mc":[{"id":"1.195453621","rc":[{"atb":[[5.7,8.4]],"id":6780934}],"con":true,"img":false}]}
{"op":"mcm","clk":"5347969461","pt":1646211538300,"mc":[{"id":"1.195453621","rc":[{"atb":[[5.2,0]],"id":40846831}],"con":true,"img":false}]}
{"op":"mcm","clk":"5347969467","pt":1646211538504,"mc":[{"id":"1.195453621","rc":[{"atb":[[5.7,8.4]],"id":40846831}],"con":true,"img":false}]}
{"op":"mcm","clk":"5347970833","pt":1646211571631,"mc":[{"id":"1.195453621","rc":[{"atb":[[15,0]],"id":23806261},{"spn":2.38,"spf":"NaN","id":41308374},{"atb":[[15.5,2.82]],"id":40199925},{"atb":[[6.6,0]],"id":40846831}],"con":true,"img":false}]}
{"op":"mcm","clk":"5347970838","pt":1646211571734,"mc":[{"id":"1.195453621","rc":[{"atb":[[16,8.4]],"id":23806261},{"atb":[[16,8.73]],"id":40199925},{"atb":[[7.2,19.78]],"id":40846831}],"con":true,"img":false}]}
{"op":"mcm","clk":"5347970844","pt":1646211571838,"mc":[{"id":"1.195453621","rc":[{"atl":[[3.45,0]],"id":41308374}],"con":true,"img":false}]}
{"op":"mcm","clk":"5347971275","pt":1646211580839,"mc":[{"id":"1.195453621","rc":[{"atb":[[6.8,1.73]],"id":40846831}],"con":true,"img":false}]}
{"op":"mcm","clk":"5347971840","pt":1646211593796,"mc":[{"id":"1.195453621","rc":[{"atb":[[6.8,0]],"id":40846831}],"con":true,"img":false}]}
{"op":"mcm","clk":"5347972047","pt":1646211598979,"mc":[{"id":"1.195453621","rc":[{"atb":[[5.7,0]],"id":6780934}],"con":true,"img":false}]}
{"op":"mcm","clk":"5347972056","pt":1646211599188,"mc":[{"id":"1.195453621","rc":[{"atb":[[5.7,0]],"id":40846831}],"con":true,"img":false}]}
{"op":"mcm","clk":"5347982841","pt":1646211815293,"mc":[{"id":"1.195453621","rc":[{"atb":[[16,8.38],[17.5,3.54],[7.2,26.37],[9.2,9.96],[10.5,4.29],[8.2,21.35],[15.5,2.81]],"id":23806261},{"atl":[[130,1.03],[280,0.71],[80,2.72],[180,0.74],[230,0.87],[60,2.72]],"id":23806261},{"atb":[[3.6,0],[10,13.04],[12,5.31],[6.8,14.09],[9.8,4.64],[7.8,6.01],[5.9,16.68],[5.4,53.51]],"id":40250501},{"atl":[[70,1.92],[140,1.43],[36,2.72],[46,2.72],[95,1.41],[190,1.05]],"id":40250501},{"atb":[[2,81.74],[2.02,112.73],[2.3,31.44],[1.9,181.66],[2.18,8.54],[1.95,86.04],[2.14,52.18],[2.1,37.15],[2.34,5.6]],"id":36463352},{"spl":[[1.01,2.72]],"id":36463352},{"atl":[[4,4.93],[4.8,25.55],[5.6,28.95],[7.2,32.22],[6.2,25.61],[8.2,27.75],[3.8,20.87]],"id":36463352},{"atb":[[2,40.87],[1.8,102.18],[2.02,55.81],[2.06,16.6],[1.85,96.17],[1.91,138.97],[1.9,45.41],[1.75,217.99]],"id":41308374},{"atl":[[5.6,28.95],[7.2,32.22],[5.1,32.48],[6.2,38.42],[3.35,24.87],[4.2,39.78],[2.7,6.2]],"id":41308374},{"atb":[[16,8.71],[7.2,26.37],[18.5,3.34],[9.2,9.96],[10.5,4.29],[8.2,21.35],[15.5,2.81]],"id":40199925},{"atl":[[130,1.03],[70,2.72],[280,0.71],[85,2.72],[180,0.74],[230,0.87]],"id":40199925},{"atb":[[4,78.49],[7.2,19.75],[4.5,23.35],[5,20.43],[5.5,9.08],[7.6,8.85],[7,6.81]],"id":40846831},{"atl":[[70,11.09],[19,3.24],[38,3.6],[48,4.25],[26,4.09],[29,4.75]],"id":40846831},{"atb":[[4,78.49],[7.2,18.5],[4.5,23.35],[5,20.43],[5.5,9.08],[7.8,8.59],[7,6.81]],"id":6780934},{"atl":[[70,11.09],[38,3.6],[20,3.07],[48,4.25],[26,4.25],[29,4.75]],"id":6780934}],"con":true,"img":false}]}
{"op":"mcm","clk":"5347982846","pt":1646211815396,"mc":[{"id":"1.195453621","rc":[{"atb":[[5.3,0]],"id":40199925}],"con":true,"img":false}]}
{"op":"mcm","clk":"5347998024","pt":1646212121525,"mc":[{"id":"1.195453621","rc":[{"atb":[[4.2,26.56]],"id":40250501}],"con":true,"img":false}]}
{"op":"mcm","clk":"5348012599","pt":1646212415425,"mc":[{"id":"1.195453621","rc":[{"atl":[[240,14.2]],"id":23806261},{"atl":[[130,8.2],[150,14.2]],"id":40250501}],"con":true,"img":false}]}
{"op":"mcm","clk":"5348057133","pt":1646213232205,"mc":[{"id":"1.195453621","rc":[{"atl":[[2.7,0]],"id":41308374},{"trd":[[2.7,12.41]],"ltp":2.7,"tv":12.41,"id":41308374},{"spn":2.7,"spf":"NaN","id":41308374},{"atl":[[20,0]],"id":6780934},{"trd":[[20,6.14]],"ltp":20.0,"tv":6.14,"id":6780934},{"spn":16.9,"spf":"NaN","id":6780934}],"con":true,"img":false}]}
{"op":"mcm","clk":"5348057204","pt":1646213233703,"mc":[{"id":"1.195453621","rc":[{"atb":[[2.22,2]],"id":36463352}],"con":true,"img":false}]}
{"op":"mcm","clk":"5348057207","pt":1646213233806,"mc":[{"id":"1.195453621","rc":[{"atb":[[2.26,0]],"id":36463352},{"atb":[[19.5,0]],"id":40199925}],"con":true,"img":false}]}
{"op":"mcm","clk":"5348057218","pt":1646213233911,"mc":[{"id":"1.195453621","rc":[{"atb":[[18.5,0]],"id":23806261},{"atb":[[11.5,0]],"id":40250501},{"atb":[[1.99,0]],"id":41308374},{"atl":[[3.45,8.17]],"id":41308374},{"atb":[[8.2,0]],"id":40846831},{"atb":[[7.4,1.57],[7.6,0]],"id":6780934}],"con":true,"img":false}]}
{"op":"mcm","clk":"5348057221","pt":1646213234011,"mc":[{"id":"1.195453621","rc":[{"atb":[[19.5,0.55]],"id":40199925}],"con":true,"img":false}]}
{"op":"mcm","clk":"5348057227","pt":1646213234115,"mc":[{"id":"1.195453621","rc":[{"atb":[[18.5,0.58]],"id":23806261},{"atb":[[11.5,0.96]],"id":40250501},{"atb":[[8.2,1.4]],"id":40846831}],"con":true,"img":false}]}
{"op":"mcm","clk":"5348057342","pt":1646213236037,"mc":[{"id":"1.195453621","rc":[{"atb":[[7.6,15.15]],"id":23806261},{"atl":[[230,2.87]],"id":23806261},{"atb":[[4.1,32.26]],"id":40250501},{"atl":[[380,2]],"id":40250501},{"atb":[[1.53,188.68]],"id":36463352},{"atl":[[5.2,23.81]],"id":36463352},{"atb":[[1.44,227.27]],"id":41308374},{"atl":[[5.7,21.28]],"id":41308374},{"atb":[[7.4,15.62]],"id":40199925},{"atl":[[210,2]],"id":40199925},{"atb":[[4,111.82]],"id":40846831},{"atl":[[46,2.22]],"id":40846831},{"atb":[[7.2,28.66]],"id":6780934},{"atl":[[190,2]],"id":6780934}],"con":true,"img":false}]}
{"op":"mcm","clk":"5348057796","pt":1646213245259,"mc":[{"id":"1.195453621","rc":[{"atb":[[12.5,10.21],[16,0]],"id":23806261},{"atb":[[7.8,4.19]],"id":6780934},{"atl":[[24,0.16]],"id":6780934}],"con":true,"img":false}]}
{"op":"mcm","clk":"5348057801","pt":1646213245354,"mc":[{"id":"1.195453621","rc":[{"atb":[[17.5,0]],"id":23806261},{"atb":[[12,0]],"id":40250501},{"atb":[[16,0],[18.5,0]],"id":40199925},{"atl":[[26,0]],"id":6780934}],"con":true,"img":false}]}
{"op":"mcm","clk":"5348057808","pt":1646213245458,"mc":[{"id":"1.195453621","rc":[{"atb":[[15,3.54]],"id":23806261},{"atb":[[11,5.31]],"id":40250501},{"atb":[[13,8.71],[15.5,6.15]],"id":40199925},{"atl":[[28,4.25]],"id":6780934}],"con":true,"img":false}]}
{"op":"mcm","clk":"5348058123","pt":1646213251960,"mc":[{"id":"1.195453621","rc":[{"atl":[[24,0]],"id":6780934},{"trd":[[24,0.32]],"ltp":24.0,"tv":0.32,"id":6780934}],"con":true,"img":false}]}
{"op":"mcm","clk":"5348058992","pt":1646213269774,"mc":[{"id":"1.195453621","rc":[{"atl":[[28,0]],"id":6780934},{"trd":[[28,8.5]],"ltp":28.0,"tv":8.5,"id":6780934}],"con":true,"img":false}]}
{"op":"mcm","clk":"5348059030","pt":1646213270550,"mc":[{"id":"1.195453621","rc":[{"atl":[[60,0]],"id":23806261},{"atl":[[36,0]],"id":40250501},{"atl":[[3.35,0]],"id":41308374},{"atl":[[70,0]],"id":40199925},{"atl":[[19,0]],"id":40846831}],"con":true,"img":false}]}
{"op":"mcm","clk":"5348059035","pt":1646213270684,"mc":[{"id":"1.195453621","rc":[{"atl":[[55,2.72]],"id":23806261},{"atl":[[30,2.72]],"id":40250501},{"atl":[[3.25,24.87]],"id":41308374},{"atl":[[60,2.72]],"id":40199925},{"atl":[[17.5,3.24]],"id":40846831}],"con":true,"img":false}]}
{"op":"mcm","clk":"5348059508","pt":1646213280576,"mc":[{"id":"1.195453621","rc":[{"atl":[[3.8,0]],"id":36463352}],"con":true,"img":false}]}
{"op":"mcm","clk":"5348059512","pt":1646213280679,"mc":[{"id":"1.195453621","rc":[{"atl":[[3.7,20.87]],"id":36463352}],"con":true,"img":false}]}
{"op":"mcm","clk":"5348059949","pt":1646213289195,"mc":[{"id":"1.195453621","rc":[{"atl":[[29,1.47]],"id":6780934},{"trd":[[29,6.56]],"ltp":29.0,"tv":6.56,"id":6780934}],"con":true,"img":false}]}
{"op":"mcm","clk":"5348060823","pt":1646213306904,"mc":[{"id":"1.195453621","rc":[{"spn":36.75,"spf":"NaN","id":23806261},{"spn":20.75,"spf":"NaN","id":40250501},{"spn":2.65,"spf":"NaN","id":41308374},{"spn":39.75,"spf":"NaN","id":40199925},{"spn":12.85,"spf":"NaN","id":40846831},{"atl":[[36,3.27]],"id":6780934},{"spn":18.4,"spf":"NaN","id":6780934}],"con":true,"img":false}]}
{"op":"mcm","clk":"5348060831","pt":1646213307114,"mc":[{"id":"1.195453621","rc":[{"atl":[[3.25,0]],"id":41308374}],"con":true,"img":false}]}
{"op":"mcm","clk":"5348060836","pt":1646213307214,"mc":[{"id":"1.195453621","rc":[{"atl":[[3.2,24.87]],"id":41308374}],"con":true,"img":false}]}
{"op":"mcm","clk":"5348060962","pt":1646213309432,"mc":[{"id":"1.195453621","rc":[{"atb":[[2.34,0]],"id":36463352},{"trd":[[2.34,11.21]],"ltp":2.34,"tv":11.21,"id":36463352}],"con":true,"img":false}]}
{"op":"mcm","clk":"5348061095","pt":1646213312235,"mc":[{"id":"1.195453621","rc":[{"atl":[[2.68,4.89]],"id":36463352}],"con":true,"img":false}]}
{"op":"mcm","clk":"5348061905","pt":1646213327377,"mc":[{"id":"1.195453621","rc":[{"atb":[[7.2,18.5],[7.4,9.95]],"id":6780934}],"con":true,"img":false}]}
{"op":"mcm","clk":"5348062266","pt":1646213333975,"mc":[{"id":"1.195453621","rc":[{"atb":[[2.3,19.68]],"id":36463352},{"trd":[[2.3,23.51]],"ltp":2.3,"tv":23.51,"id":36463352}],"con":true,"img":false}]}
{"op":"mcm","clk":"5348062444","pt":1646213336776,"mc":[{"id":"1.195453621","rc":[{"atl":[[60,0]],"id":40199925}],"con":true,"img":false}]}
{"op":"mcm","clk":"5348062449","pt":1646213336883,"mc":[{"id":"1.195453621","rc":[{"atl":[[55,2.72]],"id":40199925}],"con":true,"img":false}]}
{"op":"mcm","clk":"5348063412","pt":1646213354385,"mc":[{"id":"1.195453621","rc":[{"atb":[[7.4,1.57],[6.8,17.24]],"id":6780934}],"con":true,"img":false}]}
{"op":"mcm","clk":"5348067058","pt":1646213417758,"mc":[{"id":"1.195453621","rc":[{"atb":[[2.32,1.23]],"id":36463352},{"spn":2.3,"spf":1.0,"id":36463352},{"atb":[[2.08,1.28]],"id":41308374},{"spn":2.64,"spf":"NaN","id":41308374},{"spn":37.25,"spf":"NaN","id":40199925}],"con":true,"img":false}]}
{"op":"mcm","clk":"5348067500","pt":1646213425906,"mc":[{"id":"1.195453621","rc":[{"atb":[[1.02,2.25]],"id":40846831},{"atb":[[1.02,2.25]],"id":6780934}],"con":true,"img":false}]}
{"op":"mcm","clk":"5348067507","pt":1646213426066,"mc":[{"id":"1.195453621","rc":[{"atb":[[1.02,0.45]],"id":40846831},{"atb":[[1.02,0.46]],"id":6780934}],"con":true,"img":false}]}
{"op":"mcm","clk":"5348067510","pt":1646213426167,"mc":[{"id":"1.195453621","rc":[{"atb":[[1.02,0]],"id":40846831}],"con":true,"img":false}]}
{"op":"mcm","clk":"5348067512","pt":1646213426270,"mc":[{"id":"1.195453621","rc":[{"atb":[[8.4,0.45]],"id":40846831}],"con":true,"img":false}]}
{"op":"mcm","clk":"5348067518","pt":1646213426374,"mc":[{"id":"1.195453621","rc":[{"atb":[[1.02,0]],"id":6780934}],"con":true,"img":false}]}
{"op":"mcm","clk":"5348067524","pt":1646213426478,"mc":[{"id":"1.195453621","rc":[{"atl":[[2.68,0]],"id":36463352},{"atb":[[8,0.46]],"id":6780934}],"con":true,"img":false}]}
{"op":"mcm","clk":"5348067528","pt":1646213426581,"mc":[{"id":"1.195453621","rc":[{"atl":[[3.85,3.4]],"id":36463352}],"con":true,"img":false}]}
{"op":"mcm","clk":"5348067557","pt":1646213427304,"mc":[{"id":"1.195453621","rc":[{"atb":[[7.8,5.41]],"id":6780934}],"con":true,"img":false}]}
{"op":"mcm","clk":"5348067579","pt":1646213427980,"mc":[{"id":"1.195453621","rc":[{"atl":[[3.65,2.73]],"id":36463352},{"atl":[[3.15,2.51]],"id":41308374}],"con":true,"img":false}]}
{"op":"mcm","clk":"5348067661","pt":1646213429389,"mc":[{"id":"1.195453621","rc":[{"atl":[[3.85,0]],"id":36463352}],"con":true,"img":false}]}
{"op":"mcm","clk":"5348067670","pt":1646213429595,"mc":[{"id":"1.195453621","rc":[{"atl":[[3.6,3.63]],"id":36463352}],"con":true,"img":false}]}
{"op":"mcm","clk":"5348067702","pt":1646213430377,"mc":[{"id":"1.195453621","rc":[{"atl":[[3.65,0]],"id":36463352}],"con":true,"img":false}]}
{"op":"mcm","clk":"5348067707","pt":1646213430490,"mc":[{"id":"1.195453621","rc":[{"atl":[[3.55,2.73]],"id":36463352}],"con":true,"img":false}]}
{"op":"mcm","clk":"5348067802","pt":1646213432510,"mc":[{"id":"1.195453621","rc":[{"atl":[[3.6,0]],"id":36463352}],"con":true,"img":false}]}
{"op":"mcm","clk":"5348067815","pt":1646213432709,"mc":[{"id":"1.195453621","rc":[{"atl":[[3.5,3.74]],"id":36463352}],"con":true,"img":false}]}
{"op":"mcm","clk":"5348067825","pt":1646213432813,"mc":[{"id":"1.195453621","rc":[{"atl":[[3.55,0]],"id":36463352}],"con":true,"img":false}]}
{"op":"mcm","clk":"5348067828","pt":1646213432915,"mc":[{"id":"1.195453621","rc":[{"atl":[[3.65,2.73]],"id":36463352}],"con":true,"img":false}]}
{"op":"mcm","clk":"5348069100","pt":1646213455939,"mc":[{"id":"1.195453621","rc":[{"atb":[[1.04,2.25]],"id":23806261},{"atb":[[1.02,2.25]],"id":40250501},{"atb":[[1.04,2.25]],"id":40199925}],"con":true,"img":false}]}
{"op":"mcm","clk":"5348069111","pt":1646213456149,"mc":[{"id":"1.195453621","rc":[{"atb":[[1.04,0.19]],"id":23806261},{"atb":[[1.02,0.31]],"id":40250501},{"atb":[[1.04,0.18]],"id":40199925}],"con":true,"img":false}]}
{"op":"mcm","clk":"5348069116","pt":1646213456252,"mc":[{"id":"1.195453621","rc":[{"atb":[[1.04,0]],"id":40199925}],"con":true,"img":false}]}
{"op":"mcm","clk":"5348069124","pt":1646213456355,"mc":[{"id":"1.195453621","rc":[{"atb":[[20,0.18]],"id":40199925}],"con":true,"img":false}]}
{"op":"mcm","clk":"5348069130","pt":1646213456458,"mc":[{"id":"1.195453621","rc":[{"atb":[[1.04,0]],"id":23806261}],"con":true,"img":false}]}
{"op":"mcm","clk":"5348069135","pt":1646213456563,"mc":[{"id":"1.195453621","rc":[{"atb":[[19,0.19]],"id":23806261}],"con":true,"img":false}]}
{"op":"mcm","clk":"5348069139","pt":1646213456623,"mc":[{"id":"1.195453621","rc":[{"atb":[[1.02,0]],"id":40250501}],"con":true,"img":false}]}
{"op":"mcm","clk":"5348069142","pt":1646213456722,"mc":[{"id":"1.195453621","rc":[{"atb":[[12,0.31]],"id":40250501}],"con":true,"img":false}]}
{"op":"mcm","clk":"5348073971","pt":1646213546661,"mc":[{"id":"1.195453621","rc":[{"spn":37.0,"spf":"NaN","id":23806261},{"spn":21.0,"spf":"NaN","id":40250501},{"atl":[[3.5,0]],"id":36463352},{"spn":2.61,"spf":"NaN","id":41308374},{"spn":37.5,"spf":"NaN","id":40199925},{"spn":12.95,"spf":"NaN","id":40846831},{"spn":18.5,"spf":"NaN","id":6780934}],"con":true,"img":false}]}
{"op":"mcm","clk":"5348073980","pt":1646213546867,"mc":[{"id":"1.195453621","rc":[{"atl":[[3.6,3.63]],"id":36463352},{"atl":[[3.45,0]],"id":41308374}],"con":true,"img":false}]}
{"op":"mcm","clk":"5348073996","pt":1646213547179,"mc":[{"id":"1.195453621","rc":[{"atl":[[3.65,0]],"id":36463352}],"con":true,"img":false}]}
{"op":"mcm","clk":"5348074002","pt":1646213547282,"mc":[{"id":"1.195453621","rc":[{"atl":[[3.55,2.73]],"id":36463352}],"con":true,"img":false}]}
{"op":"mcm","clk":"5348074109","pt":1646213549657,"mc":[{"id":"1.195453621","rc":[{"atl":[[3.6,0]],"id":36463352}],"con":true,"img":false}]}
{"op":"mcm","clk":"5348074115","pt":1646213549759,"mc":[{"id":"1.195453621","rc":[{"atl":[[3.5,3.74]],"id":36463352}],"con":true,"img":false}]}
{"op":"mcm","clk":"5348074136","pt":1646213550174,"mc":[{"id":"1.195453621","rc":[{"atl":[[3.55,0]],"id":36463352}],"con":true,"img":false}]}
{"op":"mcm","clk":"5348074143","pt":1646213550279,"mc":[{"id":"1.195453621","rc":[{"atl":[[1000,2.73]],"id":36463352}],"con":true,"img":false}]}
{"op":"mcm","clk":"5348081629","pt":1646213663985,"mc":[{"id":"1.195453621","rc":[{"atl":[[3.5,0]],"id":36463352}],"con":true,"img":false}]}
{"op":"mcm","clk":"5348081653","pt":1646213664393,"mc":[{"id":"1.195453621","rc":[{"atl":[[1000,0],[3.65,3.59]],"id":36463352}],"con":true,"img":false}]}
{"op":"mcm","clk":"5348081660","pt":1646213664504,"mc":[{"id":"1.195453621","rc":[{"atl":[[3.65,6.32]],"id":36463352}],"con":true,"img":false}]}
{"op":"mcm","clk":"5348081808","pt":1646213666980,"mc":[{"id":"1.195453621","rc":[{"atl":[[3.65,2.73]],"id":36463352}],"con":true,"img":false}]}
{"op":"mcm","clk":"5348081820","pt":1646213667188,"mc":[{"id":"1.195453621","rc":[{"atl":[[3.6,3.64]],"id":36463352}],"con":true,"img":false}]}
{"op":"mcm","clk":"5348081833","pt":1646213667396,"mc":[{"id":"1.195453621","rc":[{"atl":[[3.65,0]],"id":36463352}],"con":true,"img":false}]}
{"op":"mcm","clk":"5348081838","pt":1646213667494,"mc":[{"id":"1.195453621","rc":[{"atl":[[3.55,2.73]],"id":36463352}],"con":true,"img":false}]}
{"op":"mcm","clk":"5348082025","pt":1646213670031,"mc":[{"id":"1.195453621","rc":[{"atl":[[3.6,0]],"id":36463352}],"con":true,"img":false}]}
{"op":"mcm","clk":"5348082040","pt":1646213670196,"mc":[{"id":"1.195453621","rc":[{"atl":[[3.5,3.75]],"id":36463352}],"con":true,"img":false}]}
{"op":"mcm","clk":"5348082055","pt":1646213670397,"mc":[{"id":"1.195453621","rc":[{"atl":[[3.55,0]],"id":36463352}],"con":true,"img":false}]}
{"op":"mcm","clk":"5348082062","pt":1646213670504,"mc":[{"id":"1.195453621","rc":[{"atl":[[1000,2.73]],"id":36463352}],"con":true,"img":false}]}
{"op":"mcm","clk":"5348088757","pt":1646213784208,"mc":[{"id":"1.195453621","rc":[{"atl":[[3.5,0]],"id":36463352}],"con":true,"img":false}]}
{"op":"mcm","clk":"5348088773","pt":1646213784363,"mc":[{"id":"1.195453621","rc":[{"atl":[[3.65,3.59]],"id":36463352}],"con":true,"img":false}]}
{"op":"mcm","clk":"5348088808","pt":1646213784780,"mc":[{"id":"1.195453621","rc":[{"atl":[[1000,0]],"id":36463352}],"con":true,"img":false}]}
{"op":"mcm","clk":"5348088818","pt":1646213784932,"mc":[{"id":"1.195453621","rc":[{"atl":[[3.6,2.73]],"id":36463352}],"con":true,"img":false}]}
{"op":"mcm","clk":"5348088971","pt":1646213787201,"mc":[{"id":"1.195453621","rc":[{"atl":[[3.65,0]],"id":36463352}],"con":true,"img":false}]}
{"op":"mcm","clk":"5348088976","pt":1646213787302,"mc":[{"id":"1.195453621","rc":[{"atl":[[3.55,3.69]],"id":36463352}],"con":true,"img":false}]}
{"op":"mcm","clk":"5348089000","pt":1646213787713,"mc":[{"id":"1.195453621","rc":[{"atl":[[3.6,0]],"id":36463352}],"con":true,"img":false}]}
{"op":"mcm","clk":"5348089007","pt":1646213787769,"mc":[{"id":"1.195453621","rc":[{"atl":[[3.5,2.73]],"id":36463352}],"con":true,"img":false}]}
{"op":"mcm","clk":"5348089154","pt":1646213790290,"mc":[{"id":"1.195453621","rc":[{"atl":[[3.55,0]],"id":36463352}],"con":true,"img":false}]}
{"op":"mcm","clk":"5348089159","pt":1646213790391,"mc":[{"id":"1.195453621","rc":[{"atl":[[3.45,3.79]],"id":36463352}],"con":true,"img":false}]}
{"op":"mcm","clk":"5348089180","pt":1646213790805,"mc":[{"id":"1.195453621","rc":[{"atl":[[3.5,0]],"id":36463352}],"con":true,"img":false}]}
{"op":"mcm","clk":"5348089188","pt":1646213790910,"mc":[{"id":"1.195453621","rc":[{"atl":[[1000,2.73]],"id":36463352}],"con":true,"img":false}]}
{"op":"mcm","clk":"5348089668","pt":1646213798796,"mc":[{"id":"1.195453621","rc":[{"atb":[[1.99,2]],"id":41308374},{"atb":[[7.4,0]],"id":6780934}],"con":true,"img":false}]}
{"op":"mcm","clk":"5348089676","pt":1646213798897,"mc":[{"id":"1.195453621","rc":[{"atb":[[1.02,2.25]],"id":6780934}],"con":true,"img":false}]}
{"op":"mcm","clk":"5348089679","pt":1646213799004,"mc":[{"id":"1.195453621","rc":[{"atb":[[8,0],[1.02,0.46],[7.6,1.53]],"id":6780934}],"con":true,"img":false}]}
{"op":"mcm","clk":"5348089690","pt":1646213799208,"mc":[{"id":"1.195453621","rc":[{"atb":[[1.02,0],[7.8,4.19]],"id":6780934}],"con":true,"img":false}]}
{"op":"mcm","clk":"5348089694","pt":1646213799312,"mc":[{"id":"1.195453621","rc":[{"atb":[[7.4,0.46],[1.02,1.22]],"id":6780934}],"con":true,"img":false}]}
{"op":"mcm","clk":"5348089720","pt":1646213799727,"mc":[{"id":"1.195453621","rc":[{"atb":[[6.8,0],[6.6,17.86]],"id":6780934}],"con":true,"img":false}]}
{"op":"mcm","clk":"5348089950","pt":1646213803999,"mc":[{"id":"1.195453621","rc":[{"atb":[[1.99,0]],"id":41308374}],"con":true,"img":false}]}
{"op":"mcm","clk":"5348094027","pt":1646213876649,"mc":[{"id":"1.195453621","rc":[{"atb":[[7.4,0],[1.02,3.48]],"id":6780934},{"spn":18.4,"spf":"NaN","id":6780934}],"con":true,"img":false}]}
{"op":"mcm","clk":"5348094037","pt":1646213876856,"mc":[{"id":"1.195453621","rc":[{"atb":[[1.02,1.69]],"id":6780934}],"con":true,"img":false}]}
{"op":"mcm","clk":"5348094063","pt":1646213877228,"mc":[{"id":"1.195453621","rc":[{"atb":[[1.02,1.22]],"id":6780934}],"con":true,"img":false}]}
{"op":"mcm","clk":"5348094068","pt":1646213877323,"mc":[{"id":"1.195453621","rc":[{"atb":[[8,0.46]],"id":6780934}],"con":true,"img":false}]}
{"op":"mcm","clk":"5348094097","pt":1646213877944,"mc":[{"id":"1.195453621","rc":[{"atb":[[1.02,0]],"id":6780934}],"con":true,"img":false}]}
{"op":"mcm","clk":"5348094105","pt":1646213878048,"mc":[{"id":"1.195453621","rc":[{"atb":[[7.8,5.41]],"id":6780934}],"con":true,"img":false}]}
{"op":"mcm","clk":"5348095598","pt":1646213904367,"mc":[{"id":"1.195453621","rc":[{"atl":[[3.45,0]],"id":36463352}],"con":true,"img":false}]}
{"op":"mcm","clk":"5348095604","pt":1646213904470,"mc":[{"id":"1.195453621","rc":[{"atl":[[3.65,3.58]],"id":36463352}],"con":true,"img":false}]}
{"op":"mcm","clk":"5348095627","pt":1646213904783,"mc":[{"id":"1.195453621","rc":[{"atl":[[1000,0]],"id":36463352}],"con":true,"img":false}]}
{"op":"mcm","clk":"5348095633","pt":1646213904888,"mc":[{"id":"1.195453621","rc":[{"atl":[[3.6,2.73]],"id":36463352}],"con":true,"img":false}]}
{"op":"mcm","clk":"5348095781","pt":1646213907267,"mc":[{"id":"1.195453621","rc":[{"atb":[[7.8,1.22]],"id":6780934}],"con":true,"img":false}]}
{"op":"mcm","clk":"5348095787","pt":1646213907371,"mc":[{"id":"1.195453621","rc":[{"atl":[[3.65,0]],"id":36463352},{"atb":[[8.2,4.19]],"id":6780934}],"con":true,"img":false}]}
{"op":"mcm","clk":"5348095790","pt":1646213907471,"mc":[{"id":"1.195453621","rc":[{"atl":[[3.55,3.68]],"id":36463352}],"con":true,"img":false}]}
{"op":"mcm","clk":"5348095817","pt":1646213907884,"mc":[{"id":"1.195453621","rc":[{"atl":[[3.6,0]],"id":36463352}],"con":true,"img":false}]}
{"op":"mcm","clk":"5348095821","pt":1646213907987,"mc":[{"id":"1.195453621","rc":[{"atl":[[3.5,2.73]],"id":36463352}],"con":true,"img":false}]}
{"op":"mcm","clk":"5348095967","pt":1646213910369,"mc":[{"id":"1.195453621","rc":[{"atl":[[3.55,0]],"id":36463352}],"con":true,"img":false}]}
{"op":"mcm","clk":"5348095974","pt":1646213910475,"mc":[{"id":"1.195453621","rc":[{"atl":[[3.45,3.78]],"id":36463352}],"con":true,"img":false}]}
{"op":"mcm","clk":"5348096004","pt":1646213910990,"mc":[{"id":"1.195453621","rc":[{"atl":[[3.5,0]],"id":36463352}],"con":true,"img":false}]}
{"op":"mcm","clk":"5348096012","pt":1646213911095,"mc":[{"id":"1.195453621","rc":[{"atl":[[1000,2.73]],"id":36463352}],"con":true,"img":false}]}
{"op":"mcm","clk":"5348097903","pt":1646213942241,"mc":[{"id":"1.195453621","rc":[{"atb":[[1.04,1.66]],"id":36463352},{"atb":[[1.04,1.66]],"id":41308374},{"spn":18.6,"spf":"NaN","id":6780934}],"con":true,"img":false}]}
{"op":"mcm","clk":"5348097920","pt":1646213942552,"mc":[{"id":"1.195453621","rc":[{"atb":[[1.04,1.65]],"id":36463352},{"atb":[[1.04,1.65]],"id":41308374}],"con":true,"img":false}]}
{"op":"mcm","clk":"5348097932","pt":1646213942655,"mc":[{"id":"1.195453621","rc":[{"atb":[[1.04,0]],"id":36463352},{"atb":[[1.04,0]],"id":41308374}],"con":true,"img":false}]}
{"op":"mcm","clk":"5348097941","pt":1646213942757,"mc":[{"id":"1.195453621","rc":[{"atb":[[2.36,1.65]],"id":36463352},{"atb":[[2.12,1.65]],"id":41308374}],"con":true,"img":false}]}
{"op":"mcm","clk":"5348098634","pt":1646213955256,"mc":[{"id":"1.195453621","rc":[{"atb":[[1.85,20.42],[7.6,0]],"id":23806261},{"atl":[[310,2],[380,0]],"id":40250501},{"atl":[[5.2,0],[4.7,25.55]],"id":36463352},{"atb":[[1.99,19.94],[7.4,0]],"id":40199925},{"atb":[[7.2,34.63],[6.6,0]],"id":6780934}],"con":true,"img":false}]}
{"op":"mcm","clk":"5348098647","pt":1646213955462,"mc":[{"id":"1.195453621","rc":[{"atb":[[8.2,35.24],[1.85,0]],"id":23806261},{"atb":[[8,14.29],[1.99,0]],"id":40199925}],"con":true,"img":false}]}
{"op":"mcm","clk":"5348101026","pt":1646213996762,"mc":[{"id":"1.195453621","rc":[{"atb":[[8,0],[1.02,2.25]],"id":6780934}],"con":true,"img":false}]}
{"op":"mcm","clk":"5348101034","pt":1646213996964,"mc":[{"id":"1.195453621","rc":[{"atb":[[1.02,0.45]],"id":6780934}],"con":true,"img":false}]}
{"op":"mcm","clk":"5348101043","pt":1646213997121,"mc":[{"id":"1.195453621","rc":[{"atb":[[1.02,0]],"id":6780934}],"con":true,"img":false}]}
{"op":"mcm","clk":"5348101050","pt":1646213997226,"mc":[{"id":"1.195453621","rc":[{"atb":[[8.4,0.45]],"id":6780934}],"con":true,"img":false}]}
{"op":"mcm","clk":"5348101065","pt":1646213997542,"mc":[{"id":"1.195453621","rc":[{"atl":[[3.6,4.18]],"id":36463352},{"atl":[[3.15,7.29]],"id":41308374}],"con":true,"img":false}]}
{"op":"mcm","clk":"5348101093","pt":1646213998059,"mc":[{"id":"1.195453621","rc":[{"atb":[[7.8,0]],"id":6780934}],"con":true,"img":false}]}
{"op":"mcm","clk":"5348101101","pt":1646213998157,"mc":[{"id":"1.195453621","rc":[{"atl":[[1000,0]],"id":36463352},{"atb":[[8.2,5.41]],"id":6780934}],"con":true,"img":false}]}
{"op":"mcm","clk":"5348101107","pt":1646213998264,"mc":[{"id":"1.195453621","rc":[{"atl":[[3.4,2.73]],"id":36463352}],"con":true,"img":false}]}
{"op":"mcm","clk":"5348101270","pt":1646214000556,"mc":[{"id":"1.195453621","rc":[{"atl":[[3.45,0]],"id":36463352}],"con":true,"img":false}]}
{"op":"mcm","clk":"5348101275","pt":1646214000654,"mc":[{"id":"1.195453621","rc":[{"atl":[[3.35,3.9]],"id":36463352}],"con":true,"img":false}]}
{"op":"mcm","clk":"5348101338","pt":1646214001592,"mc":[{"id":"1.195453621","rc":[{"atl":[[4.1,4.06]],"id":41308374}],"con":true,"img":false}]}
{"op":"mcm","clk":"5348101347","pt":1646214001655,"mc":[{"id":"1.195453621","rc":[{"atl":[[4.6,3.62]],"id":36463352}],"con":true,"img":false}]}
{"op":"mcm","clk":"5348101471","pt":1646214003676,"mc":[{"id":"1.195453621","rc":[{"atl":[[3.4,0]],"id":36463352},{"spn":2.34,"spf":1.0,"id":36463352},{"spn":2.63,"spf":"NaN","id":41308374},{"spn":18.7,"spf":"NaN","id":6780934}],"con":true,"img":false}]}
{"op":"mcm","clk":"5348101475","pt":1646214003773,"mc":[{"id":"1.195453621","rc":[{"atl":[[1000,2.73]],"id":36463352}],"con":true,"img":false}]}
{"op":"mcm","clk":"5348102042","pt":1646214011977,"mc":[{"id":"1.195453621","rc":[{"atl":[[4.8,0]],"id":36463352}],"con":true,"img":false}]}
{"op":"mcm","clk":"5348103005","pt":1646214028121,"mc":[{"id":"1.195453621","rc":[{"atb":[[8.6,3.8],[8.2,1.22]],"id":6780934}],"con":true,"img":false}]}
{"op":"mcm","clk":"5348103062","pt":1646214029094,"mc":[{"id":"1.195453621","rc":[{"atb":[[16,1.65]],"id":23806261},{"atb":[[11.5,2.59]],"id":40250501},{"atb":[[2.32,2.82]],"id":36463352},{"atb":[[2.08,2.87]],"id":41308374},{"atb":[[16,1.61]],"id":40199925},{"atb":[[7.8,1.61]],"id":40846831}],"con":true,"img":false}]}
{"op":"mcm","clk":"5348103074","pt":1646214029298,"mc":[{"id":"1.195453621","rc":[{"atb":[[8.4,0],[1.02,2.25]],"id":40846831}],"con":true,"img":false}]}
{"op":"mcm","clk":"5348103091","pt":1646214029511,"mc":[{"id":"1.195453621","rc":[{"atb":[[1.02,0.45]],"id":40846831}],"con":true,"img":false}]}
{"op":"mcm","clk":"5348103099","pt":1646214029712,"mc":[{"id":"1.195453621","rc":[{"atb":[[1.02,0]],"id":40846831}],"con":true,"img":false}]}
{"op":"mcm","clk":"5348103107","pt":1646214029816,"mc":[{"id":"1.195453621","rc":[{"atb":[[8,0.45]],"id":40846831}],"con":true,"img":false}]}
{"op":"mcm","clk":"5348103705","pt":1646214040824,"mc":[{"id":"1.195453621","rc":[{"atl":[[3.95,38.98]],"id":36463352}],"con":true,"img":false}]}
{"op":"mcm","clk":"5348106831","pt":1646214090691,"mc":[{"id":"1.195453621","rc":[{"atl":[[3,4.93]],"id":41308374},{"spn":2.56,"spf":"NaN","id":41308374},{"spn":12.85,"spf":"NaN","id":40846831},{"spn":18.8,"spf":"NaN","id":6780934}],"con":true,"img":false}]}
{"op":"mcm","clk":"5348106847","pt":1646214091006,"mc":[{"id":"1.195453621","rc":[{"atl":[[3.15,4.77]],"id":41308374}],"con":true,"img":false}]}
{"op":"mcm","clk":"5348106852","pt":1646214091112,"mc":[{"id":"1.195453621","rc":[{"atl":[[2.98,2.51]],"id":41308374}],"con":true,"img":false}]}
{"op":"mcm","clk":"5348107808","pt":1646214108670,"mc":[{"id":"1.195453621","rc":[{"atb":[[2.4,4.93]],"id":41308374}],"con":true,"img":false}]}
{"op":"mcm","clk":"5348107825","pt":1646214108931,"mc":[{"id":"1.195453621","rc":[{"atb":[[2.08,1.59]],"id":41308374}],"con":true,"img":false}]}
{"op":"mcm","clk":"5348107829","pt":1646214109034,"mc":[{"id":"1.195453621","rc":[{"atb":[[2.4,6.21]],"id":41308374}],"con":true,"img":false}]}
{"op":"mcm","clk":"5348107847","pt":1646214109442,"mc":[{"id":"1.195453621","rc":[{"atl":[[2.98,0]],"id":41308374}],"con":true,"img":false}]}
{"op":"mcm","clk":"5348107853","pt":1646214109545,"mc":[{"id":"1.195453621","rc":[{"atl":[[1000,2.51]],"id":41308374}],"con":true,"img":false}]}
{"op":"mcm","clk":"5348108083","pt":1646214114772,"mc":[{"id":"1.195453621","rc":[{"atl":[[3.15,0]],"id":41308374}],"con":true,"img":false}]}
{"op":"mcm","clk":"5348108180","pt":1646214116945,"mc":[{"id":"1.195453621","rc":[{"atb":[[8,0],[1.02,2.25]],"id":40846831},{"atb":[[8.4,0],[1.02,2.25]],"id":6780934}],"con":true,"img":false}]}
{"op":"mcm","clk":"5348108182","pt":1646214117047,"mc":[{"id":"1.195453621","rc":[{"atb":[[1.02,0.45]],"id":40846831},{"atb":[[1.02,0.42]],"id":6780934}],"con":true,"img":false}]}
{"op":"mcm","clk":"5348108186","pt":1646214117151,"mc":[{"id":"1.195453621","rc":[{"atb":[[1.02,0]],"id":40846831}],"con":true,"img":false}]}
{"op":"mcm","clk":"5348108191","pt":1646214117259,"mc":[{"id":"1.195453621","rc":[{"atb":[[8.4,0.45]],"id":40846831}],"con":true,"img":false}]}
{"op":"mcm","clk":"5348108201","pt":1646214117464,"mc":[{"id":"1.195453621","rc":[{"atb":[[1.02,0]],"id":6780934}],"con":true,"img":false}]}
{"op":"mcm","clk":"5348108210","pt":1646214117570,"mc":[{"id":"1.195453621","rc":[{"atb":[[8.8,0.42]],"id":6780934}],"con":true,"img":false}]}
{"op":"mcm","clk":"5348108222","pt":1646214117877,"mc":[{"id":"1.195453621","rc":[{"atl":[[3.6,0],[3.35,0]],"id":36463352}],"con":true,"img":false}]}
{"op":"mcm","clk":"5348108229","pt":1646214117932,"mc":[{"id":"1.195453621","rc":[{"atl":[[3.65,3.57]],"id":36463352}],"con":true,"img":false}]}
{"op":"mcm","clk":"5348108258","pt":1646214118547,"mc":[{"id":"1.195453621","rc":[{"atl":[[1000,0]],"id":36463352}],"con":true,"img":false}]}
{"op":"mcm","clk":"5348108262","pt":1646214118652,"mc":[{"id":"1.195453621","rc":[{"atl":[[3.6,2.73]],"id":36463352}],"con":true,"img":false}]}
{"op":"mcm","clk":"5348108373","pt":1646214120774,"mc":[{"id":"1.195453621","rc":[{"atl":[[3.6,6.91],[3.65,0]],"id":36463352}],"con":true,"img":false}]}
{"op":"mcm","clk":"5348108379","pt":1646214120982,"mc":[{"id":"1.195453621","rc":[{"atl":[[3.55,3.67]],"id":36463352}],"con":true,"img":false}]}
{"op":"mcm","clk":"5348108414","pt":1646214121554,"mc":[{"id":"1.195453621","rc":[{"atl":[[3.6,4.18]],"id":36463352}],"con":true,"img":false}]}
{"op":"mcm","clk":"5348108425","pt":1646214121660,"mc":[{"id":"1.195453621","rc":[{"atl":[[3.5,2.73]],"id":36463352}],"con":true,"img":false}]}
{"op":"mcm","clk":"5348108549","pt":1646214123785,"mc":[{"id":"1.195453621","rc":[{"atl":[[3.55,0]],"id":36463352}],"con":true,"img":false}]}
{"op":"mcm","clk":"5348108555","pt":1646214123839,"mc":[{"id":"1.195453621","rc":[{"atl":[[3.45,3.78]],"id":36463352}],"con":true,"img":false}]}
{"op":"mcm","clk":"5348108570","pt":1646214124151,"mc":[{"id":"1.195453621","rc":[{"atl":[[3.5,0]],"id":36463352}],"con":true,"img":false}]}
{"op":"mcm","clk":"5348108576","pt":1646214124255,"mc":[{"id":"1.195453621","rc":[{"atl":[[3.4,2.73]],"id":36463352}],"con":true,"img":false}]}
{"op":"mcm","clk":"5348108750","pt":1646214126984,"mc":[{"id":"1.195453621","rc":[{"atl":[[3.45,0]],"id":36463352}],"con":true,"img":false}]}
{"op":"mcm","clk":"5348108760","pt":1646214127091,"mc":[{"id":"1.195453621","rc":[{"atl":[[3.35,3.89]],"id":36463352}],"con":true,"img":false}]}
{"op":"mcm","clk":"5348108801","pt":1646214127768,"mc":[{"id":"1.195453621","rc":[{"atl":[[3.4,0]],"id":36463352}],"con":true,"img":false}]}
{"op":"mcm","clk":"5348108810","pt":1646214127867,"mc":[{"id":"1.195453621","rc":[{"atl":[[1000,2.73]],"id":36463352}],"con":true,"img":false}]}
{"op":"mcm","clk":"5348108843","pt":1646214128383,"mc":[{"id":"1.195453621","rc":[{"atl":[[4.1,0]],"id":41308374}],"con":true,"img":false}]}
{"op":"mcm","clk":"5348109634","pt":1646214140971,"mc":[{"id":"1.195453621","rc":[{"atl":[[4.6,0]],"id":36463352}],"con":true,"img":false}]}
{"op":"mcm","clk":"5348109904","pt":1646214146399,"mc":[{"id":"1.195453621","rc":[{"atb":[[8.6,0]],"id":6780934}],"con":true,"img":false}]}
{"op":"mcm","clk":"5348109911","pt":1646214146502,"mc":[{"id":"1.195453621","rc":[{"atb":[[9,3.8]],"id":6780934}],"con":true,"img":false}]}
{"op":"mcm","clk":"5348111888","pt":1646214182266,"mc":[{"id":"1.195453621","rc":[{"spn":2.7,"spf":"NaN","id":41308374},{"atl":[[230,15.07]],"id":40199925},{"spn":12.95,"spf":"NaN","id":40846831},{"spn":19.0,"spf":"NaN","id":6780934}],"con":true,"img":false}]}
{"op":"mcm","clk":"5348113439","pt":1646214207116,"mc":[{"id":"1.195453621","rc":[{"atb":[[1.02,2.25],[8.8,0]],"id":6780934}],"con":true,"img":false}]}
{"op":"mcm","clk":"5348113454","pt":1646214207323,"mc":[{"id":"1.195453621","rc":[{"atb":[[1.02,0.4]],"id":6780934}],"con":true,"img":false}]}
{"op":"mcm","clk":"5348113462","pt":1646214207427,"mc":[{"id":"1.195453621","rc":[{"atb":[[1.02,0]],"id":6780934}],"con":true,"img":false}]}
{"op":"mcm","clk":"5348113470","pt":1646214207527,"mc":[{"id":"1.195453621","rc":[{"atb":[[9.2,0.4]],"id":6780934}],"con":true,"img":false}]}
{"op":"mcm","clk":"5348113733","pt":1646214211328,"mc":[{"id":"1.195453621","rc":[{"spl":[[1.01,29.97]],"id":23806261},{"spl":[[1.01,29.97]],"id":40250501},{"spl":[[1.01,32.69]],"id":36463352},{"spl":[[1.01,29.97]],"id":41308374},{"spl":[[1.01,29.97]],"id":40199925},{"spl":[[1.01,29.97]],"id":40846831},{"spl":[[1.01,29.97]],"id":6780934}],"con":true,"img":false}]}
{"op":"mcm","clk":"5348113762","pt":1646214211724,"mc":[{"id":"1.195453621","rc":[{"atb":[[2.8,0]],"id":6780934}],"con":true,"img":false}]}
{"op":"mcm","clk":"5348113867","pt":1646214213316,"mc":[{"id":"1.195453621","rc":[{"atb":[[8.2,21.35],[7,16.67]],"id":23806261}],"con":true,"img":false}]}
{"op":"mcm","clk":"5348115194","pt":1646214235080,"mc":[{"id":"1.195453621","rc":[{"atb":[[9,0],[9.4,3.47]],"id":6780934}],"con":true,"img":false}]}
{"op":"mcm","clk":"5348115402","pt":1646214238082,"mc":[{"id":"1.195453621","rc":[{"atl":[[3.6,0]],"id":36463352}],"con":true,"img":false}]}
{"op":"mcm","clk":"5348115443","pt":1646214238702,"mc":[{"id":"1.195453621","rc":[{"atl":[[4.5,31.94],[3.95,0]],"id":36463352}],"con":true,"img":false}]}
{"op":"mcm","clk":"5348115577","pt":1646214241078,"mc":[{"id":"1.195453621","rc":[{"atl":[[3.35,0]],"id":36463352}],"con":true,"img":false}]}
{"op":"mcm","clk":"5348115586","pt":1646214241293,"mc":[{"id":"1.195453621","rc":[{"atl":[[3.65,3.57]],"id":36463352}],"con":true,"img":false}]}
{"op":"mcm","clk":"5348115617","pt":1646214241810,"mc":[{"id":"1.195453621","rc":[{"atl":[[1000,0]],"id":36463352}],"con":true,"img":false}]}
{"op":"mcm","clk":"5348115624","pt":1646214241905,"mc":[{"id":"1.195453621","rc":[{"atl":[[3.6,2.73]],"id":36463352}],"con":true,"img":false}]}
{"op":"mcm","clk":"5348115635","pt":1646214242060,"mc":[{"id":"1.195453621","rc":[{"atl":[[4.4,3.79]],"id":36463352}],"con":true,"img":false}]}
{"op":"mcm","clk":"5348115767","pt":1646214244085,"mc":[{"id":"1.195453621","rc":[{"spn":12.4,"spf":1.0,"id":23806261},{"spn":9.99,"spf":1.0,"id":40250501},{"atl":[[3.6,6.91],[3.65,0]],"id":36463352},{"spn":2.27,"spf":1.0,"id":36463352},{"spn":2.12,"spf":1.0,"id":41308374},{"spn":12.4,"spf":1.0,"id":40199925},{"spn":7.41,"spf":1.0,"id":40846831},{"spn":7.54,"spf":1.0,"id":6780934}],"con":true,"img":false}]}
{"op":"mcm","clk":"5348115775","pt":1646214244191,"mc":[{"id":"1.195453621","rc":[{"atl":[[3.55,3.66]],"id":36463352}],"con":true,"img":false}]}
{"op":"mcm","clk":"5348115824","pt":1646214244808,"mc":[{"id":"1.195453621","rc":[{"atl":[[3.6,4.18]],"id":36463352}],"con":true,"img":false}]}
{"op":"mcm","clk":"5348115834","pt":1646214244913,"mc":[{"id":"1.195453621","rc":[{"atl":[[3.5,2.73]],"id":36463352}],"con":true,"img":false}]}
{"op":"mcm","clk":"5348115974","pt":1646214247076,"mc":[{"id":"1.195453621","rc":[{"atl":[[3.55,0]],"id":36463352}],"con":true,"img":false}]}
{"op":"mcm","clk":"5348115978","pt":1646214247182,"mc":[{"id":"1.195453621","rc":[{"atl":[[3.45,3.77]],"id":36463352}],"con":true,"img":false}]}
{"op":"mcm","clk":"5348116010","pt":1646214247905,"mc":[{"id":"1.195453621","rc":[{"atl":[[3.5,0]],"id":36463352}],"con":true,"img":false}]}
{"op":"mcm","clk":"5348116017","pt":1646214248007,"mc":[{"id":"1.195453621","rc":[{"atl":[[3.4,2.73]],"id":36463352}],"con":true,"img":false}]}
{"op":"mcm","clk":"5348116144","pt":1646214250079,"mc":[{"id":"1.195453621","rc":[{"atl":[[3.45,0]],"id":36463352}],"con":true,"img":false}]}
{"op":"mcm","clk":"5348116150","pt":1646214250291,"mc":[{"id":"1.195453621","rc":[{"atl":[[3.35,3.88]],"id":36463352}],"con":true,"img":false}]}
{"op":"mcm","clk":"5348116192","pt":1646214251020,"mc":[{"id":"1.195453621","rc":[{"atl":[[3.4,0]],"id":36463352}],"con":true,"img":false}]}
{"op":"mcm","clk":"5348116199","pt":1646214251122,"mc":[{"id":"1.195453621","rc":[{"atl":[[1000,2.73]],"id":36463352}],"con":true,"img":false}]}
{"op":"mcm","clk":"5348116449","pt":1646214255416,"mc":[{"id":"1.195453621","rc":[{"atb":[[3.7,37.04]],"id":40846831}],"con":true,"img":false}]}
{"op":"mcm","clk":"5348116452","pt":1646214255509,"mc":[{"id":"1.195453621","rc":[{"atb":[[4,78.49]],"id":40846831}],"con":true,"img":false}]}
{"op":"mcm","clk":"5348118244","pt":1646214282266,"mc":[{"id":"1.195453621","rc":[{"atb":[[4,111.82],[3.7,0]],"id":40846831}],"con":true,"img":false}]}
{"op":"mcm","clk":"5348119209","pt":1646214297209,"mc":[{"id":"1.195453621","rc":[{"atb":[[9.2,0],[1.02,2.25]],"id":6780934}],"con":true,"img":false}]}
{"op":"mcm","clk":"5348119221","pt":1646214297418,"mc":[{"id":"1.195453621","rc":[{"atb":[[1.02,0.39]],"id":6780934}],"con":true,"img":false}]}
{"op":"mcm","clk":"5348119231","pt":1646214297594,"mc":[{"id":"1.195453621","rc":[{"atb":[[1.02,0]],"id":6780934}],"con":true,"img":false}]}
{"op":"mcm","clk":"5348119238","pt":1646214297682,"mc":[{"id":"1.195453621","rc":[{"atb":[[9.6,0.39]],"id":6780934}],"con":true,"img":false}]}
{"op":"mcm","clk":"5348119519","pt":1646214302118,"mc":[{"id":"1.195453621","rc":[{"atl":[[4.5,0],[3.95,38.98]],"id":36463352}],"con":true,"img":false}]}
{"op":"mcm","clk":"5348121336","pt":1646214326443,"mc":[{"id":"1.195453621","rc":[{"atb":[[9.4,0]],"id":6780934},{"spn":7.29,"spf":1.0,"id":6780934}],"con":true,"img":false}]}
{"op":"mcm","clk":"5348121343","pt":1646214326541,"mc":[{"id":"1.195453621","rc":[{"atb":[[9.8,3.47]],"id":6780934}],"con":true,"img":false}]}
{"op":"mcm","clk":"5348121358","pt":1646214326748,"mc":[{"id":"1.195453621","rc":[{"atb":[[8.2,0]],"id":6780934}],"con":true,"img":false}]}
{"op":"mcm","clk":"5348121364","pt":1646214326853,"mc":[{"id":"1.195453621","rc":[{"atb":[[7.4,1.22]],"id":6780934}],"con":true,"img":false}]}
{"op":"mcm","clk":"5348123703","pt":1646214361273,"mc":[{"id":"1.195453621","rc":[{"atl":[[3.6,0]],"id":36463352}],"con":true,"img":false}]}
{"op":"mcm","clk":"5348123839","pt":1646214363141,"mc":[{"id":"1.195453621","rc":[{"atl":[[4.4,0]],"id":36463352}],"con":true,"img":false}]}
{"op":"mcm","clk":"5348123921","pt":1646214364326,"mc":[{"id":"1.195453621","rc":[{"atl":[[3.35,0]],"id":36463352}],"con":true,"img":false}]}
{"op":"mcm","clk":"5348123930","pt":1646214364482,"mc":[{"id":"1.195453621","rc":[{"atl":[[3.65,3.57]],"id":36463352}],"con":true,"img":false}]}
{"op":"mcm","clk":"5348123965","pt":1646214365102,"mc":[{"id":"1.195453621","rc":[{"atl":[[1000,0]],"id":36463352}],"con":true,"img":false}]}
{"op":"mcm","clk":"5348123975","pt":1646214365217,"mc":[{"id":"1.195453621","rc":[{"atl":[[3.6,2.73]],"id":36463352}],"con":true,"img":false}]}
{"op":"mcm","clk":"5348124125","pt":1646214367332,"mc":[{"id":"1.195453621","rc":[{"atl":[[3.6,6.91],[3.65,0]],"id":36463352}],"con":true,"img":false}]}
{"op":"mcm","clk":"5348124130","pt":1646214367428,"mc":[{"id":"1.195453621","rc":[{"atl":[[3.55,3.66]],"id":36463352}],"con":true,"img":false}]}
{"op":"mcm","clk":"5348124183","pt":1646214368107,"mc":[{"id":"1.195453621","rc":[{"atl":[[3.6,4.18]],"id":36463352}],"con":true,"img":false}]}
{"op":"mcm","clk":"5348124189","pt":1646214368207,"mc":[{"id":"1.195453621","rc":[{"atl":[[3.5,2.73]],"id":36463352}],"con":true,"img":false}]}
{"op":"mcm","clk":"5348124338","pt":1646214370329,"mc":[{"id":"1.195453621","rc":[{"atl":[[3.55,0]],"id":36463352}],"con":true,"img":false}]}
{"op":"mcm","clk":"5348124343","pt":1646214370429,"mc":[{"id":"1.195453621","rc":[{"atl":[[3.45,3.77]],"id":36463352}],"con":true,"img":false}]}
{"op":"mcm","clk":"5348124364","pt":1646214370739,"mc":[{"id":"1.195453621","rc":[{"atl":[[3.5,0]],"id":36463352}],"con":true,"img":false}]}
{"op":"mcm","clk":"5348124368","pt":1646214370839,"mc":[{"id":"1.195453621","rc":[{"atl":[[3.55,2.73]],"id":36463352}],"con":true,"img":false}]}
{"op":"mcm","clk":"5348124383","pt":1646214371104,"mc":[{"id":"1.195453621","rc":[{"atl":[[3.55,0]],"id":36463352}],"con":true,"img":false}]}
{"op":"mcm","clk":"5348124388","pt":1646214371212,"mc":[{"id":"1.195453621","rc":[{"atl":[[3.4,2.73]],"id":36463352}],"con":true,"img":false}]}
{"op":"mcm","clk":"5348124539","pt":1646214373339,"mc":[{"id":"1.195453621","rc":[{"atl":[[3.45,0]],"id":36463352}],"con":true,"img":false}]}
{"op":"mcm","clk":"5348124547","pt":1646214373442,"mc":[{"id":"1.195453621","rc":[{"atl":[[3.35,3.88]],"id":36463352}],"con":true,"img":false}]}
{"op":"mcm","clk":"5348124565","pt":1646214373704,"mc":[{"id":"1.195453621","rc":[{"atl":[[3.4,0]],"id":36463352}],"con":true,"img":false}]}
{"op":"mcm","clk":"5348124577","pt":1646214373857,"mc":[{"id":"1.195453621","rc":[{"atl":[[3.55,2.73]],"id":36463352}],"con":true,"img":false}]}
{"op":"mcm","clk":"5348125512","pt":1646214387363,"mc":[{"id":"1.195453621","rc":[{"atb":[[9.6,0],[1.02,2.25]],"id":6780934},{"spn":7.53,"spf":1.0,"id":6780934}],"con":true,"img":false}]}
{"op":"mcm","clk":"5348125519","pt":1646214387461,"mc":[{"id":"1.195453621","rc":[{"atb":[[1.02,0.37]],"id":6780934}],"con":true,"img":false}]}
{"op":"mcm","clk":"5348125525","pt":1646214387567,"mc":[{"id":"1.195453621","rc":[{"atb":[[1.02,0]],"id":6780934}],"con":true,"img":false}]}
{"op":"mcm","clk":"5348125531","pt":1646214387667,"mc":[{"id":"1.195453621","rc":[{"atb":[[10,0.37]],"id":6780934}],"con":true,"img":false}]}
{"op":"mcm","clk":"5348136324","pt":1646214420130,"mc":[{"id":"1.195453621","rc":[{"atb":[[9.8,0]],"id":6780934}],"con":true,"img":false}]}
{"op":"mcm","clk":"5348136332","pt":1646214420224,"mc":[{"id":"1.195453621","rc":[{"atb":[[10,3.85]],"id":6780934}],"con":true,"img":false}]}
{"op":"mcm","clk":"5348136976","pt":1646214429866,"mc":[{"id":"1.195453621","rc":[{"atb":[[1.28,0]],"id":41308374}],"con":true,"img":false}]}
{"op":"mcm","clk":"5348137058","pt":1646214430841,"mc":[{"id":"1.195453621","rc":[{"atb":[[18.5,0]],"id":23806261},{"atb":[[11.5,1.63]],"id":40250501},{"atb":[[8.2,0]],"id":40846831},{"atb":[[7.6,0]],"id":6780934}],"con":true,"img":false}]}
{"op":"mcm","clk":"5348137067","pt":1646214430960,"mc":[{"id":"1.195453621","rc":[{"atb":[[8.6,1.33]],"id":40846831},{"atb":[[8,1.44]],"id":6780934}],"con":true,"img":false}]}
{"op":"mcm","clk":"5348137074","pt":1646214431064,"mc":[{"id":"1.195453621","rc":[{"atb":[[19.5,0.55]],"id":23806261},{"atb":[[12.5,0.88]],"id":40250501}],"con":true,"img":false}]}
{"op":"mcm","clk":"5348137602","pt":1646214438858,"mc":[{"id":"1.195453621","rc":[{"atb":[[7.8,4.19]],"id":6780934}],"con":true,"img":false}]}
{"op":"mcm","clk":"5348137612","pt":1646214438964,"mc":[{"id":"1.195453621","rc":[{"atb":[[10,0.37]],"id":6780934}],"con":true,"img":false}]}
{"op":"mcm","clk":"5348138185","pt":1646214447463,"mc":[{"id":"1.195453621","rc":[{"spn":12.41,"spf":1.0,"id":23806261},{"spn":10.01,"spf":1.0,"id":40250501},{"spn":7.43,"spf":1.0,"id":40846831},{"atb":[[10,0],[1.02,2.25]],"id":6780934},{"spn":7.33,"spf":1.0,"id":6780934}],"con":true,"img":false}]}
{"op":"mcm","clk":"5348138196","pt":1646214447671,"mc":[{"id":"1.195453621","rc":[{"atb":[[1.02,0.37]],"id":6780934}],"con":true,"img":false}]}
{"op":"mcm","clk":"5348138223","pt":1646214448084,"mc":[{"id":"1.195453621","rc":[{"atb":[[1.02,0]],"id":6780934}],"con":true,"img":false}]}
{"op":"mcm","clk":"5348138231","pt":1646214448191,"mc":[{"id":"1.195453621","rc":[{"atb":[[8.2,0.37]],"id":6780934}],"con":true,"img":false}]}
{"op":"mcm","clk":"5348139489","pt":1646214465842,"mc":[{"id":"1.195453621","rc":[{"atb":[[7.8,0]],"id":6780934}],"con":true,"img":false}]}
{"op":"mcm","clk":"5348139495","pt":1646214465947,"mc":[{"id":"1.195453621","rc":[{"atb":[[8.2,4.56]],"id":6780934}],"con":true,"img":false}]}
{"op":"mcm","clk":"5348140909","pt":1646214485695,"mc":[{"id":"1.195453621","rc":[{"atl":[[3.6,0]],"id":36463352}],"con":true,"img":false}]}
{"op":"mcm","clk":"5348140930","pt":1646214485954,"mc":[{"id":"1.195453621","rc":[{"atl":[[3.55,0]],"id":36463352}],"con":true,"img":false}]}
{"op":"mcm","clk":"5348140939","pt":1646214486060,"mc":[{"id":"1.195453621","rc":[{"atl":[[1000,2.73]],"id":36463352}],"con":true,"img":false}]}
{"op":"mcm","clk":"5348141053","pt":1646214487564,"mc":[{"id":"1.195453621","rc":[{"atl":[[3.35,0]],"id":36463352}],"con":true,"img":false}]}
{"op":"mcm","clk":"5348141062","pt":1646214487665,"mc":[{"id":"1.195453621","rc":[{"atl":[[3.65,3.57]],"id":36463352}],"con":true,"img":false}]}
{"op":"mcm","clk":"5348141078","pt":1646214487925,"mc":[{"id":"1.195453621","rc":[{"atl":[[1000,0]],"id":36463352}],"con":true,"img":false}]}
{"op":"mcm","clk":"5348141086","pt":1646214487977,"mc":[{"id":"1.195453621","rc":[{"atl":[[3.6,2.73]],"id":36463352}],"con":true,"img":false}]}
{"op":"mcm","clk":"5348141269","pt":1646214490656,"mc":[{"id":"1.195453621","rc":[{"atl":[[3.6,6.91],[3.65,0]],"id":36463352}],"con":true,"img":false}]}
{"op":"mcm","clk":"5348141280","pt":1646214490815,"mc":[{"id":"1.195453621","rc":[{"atl":[[3.55,3.66]],"id":36463352}],"con":true,"img":false}]}
{"op":"mcm","clk":"5348141289","pt":1646214490969,"mc":[{"id":"1.195453621","rc":[{"atl":[[3.6,4.18]],"id":36463352}],"con":true,"img":false}]}
{"op":"mcm","clk":"5348141295","pt":1646214491080,"mc":[{"id":"1.195453621","rc":[{"atl":[[3.5,2.73]],"id":36463352}],"con":true,"img":false}]}
{"op":"mcm","clk":"5348141492","pt":1646214493702,"mc":[{"id":"1.195453621","rc":[{"atl":[[3.55,0]],"id":36463352}],"con":true,"img":false}]}
{"op":"mcm","clk":"5348141511","pt":1646214493810,"mc":[{"id":"1.195453621","rc":[{"atl":[[3.45,3.77]],"id":36463352}],"con":true,"img":false}]}
{"op":"mcm","clk":"5348141603","pt":1646214494181,"mc":[{"id":"1.195453621","rc":[{"atl":[[3.5,0]],"id":36463352}],"con":true,"img":false}]}
{"op":"mcm","clk":"5348141617","pt":1646214494287,"mc":[{"id":"1.195453621","rc":[{"atl":[[3.4,2.73]],"id":36463352}],"con":true,"img":false}]}
{"op":"mcm","clk":"5348141778","pt":1646214496244,"mc":[{"id":"1.195453621","rc":[{"atl":[[3.85,4.32]],"id":36463352}],"con":true,"img":false}]}
{"op":"mcm","clk":"5348141812","pt":1646214496655,"mc":[{"id":"1.195453621","rc":[{"atl":[[3.45,0]],"id":36463352}],"con":true,"img":false}]}
{"op":"mcm","clk":"5348141827","pt":1646214496862,"mc":[{"id":"1.195453621","rc":[{"atl":[[3.35,3.88]],"id":36463352}],"con":true,"img":false}]}
{"op":"mcm","clk":"5348141861","pt":1646214497378,"mc":[{"id":"1.195453621","rc":[{"atl":[[3.4,0]],"id":36463352}],"con":true,"img":false}]}
{"op":"mcm","clk":"5348141870","pt":1646214497481,"mc":[{"id":"1.195453621","rc":[{"atl":[[1000,2.73]],"id":36463352}],"con":true,"img":false}]}
{"op":"mcm","clk":"5348145873","pt":1646214551473,"mc":[{"id":"1.195453621","rc":[{"atl":[[3.95,0]],"id":36463352},{"spn":7.39,"spf":1.0,"id":6780934}],"con":true,"img":false}]}
{"op":"mcm","clk":"5348145882","pt":1646214551582,"mc":[{"id":"1.195453621","rc":[{"atl":[[3.8,38.98]],"id":36463352}],"con":true,"img":false}]}
{"op":"mcm","clk":"5348146686","pt":1646214562377,"mc":[{"id":"1.195453621","rc":[{"atb":[[7.2,18.5],[7,15.89]],"id":6780934}],"con":true,"img":false}]}
{"op":"mcm","clk":"5348148374","pt":1646214586102,"mc":[{"id":"1.195453621","rc":[{"atb":[[7.2,34.39],[7,6.81]],"id":6780934}],"con":true,"img":false}]}
{"op":"mcm","clk":"5348149906","pt":1646214607859,"mc":[{"id":"1.195453621","rc":[{"atl":[[3.6,0]],"id":36463352}],"con":true,"img":false}]}
{"op":"mcm","clk":"5348149964","pt":1646214608639,"mc":[{"id":"1.195453621","rc":[{"atl":[[3.8,0]],"id":36463352}],"con":true,"img":false}]}
{"op":"mcm","clk":"5348149972","pt":1646214608742,"mc":[{"id":"1.195453621","rc":[{"atl":[[3.95,38.98]],"id":36463352}],"con":true,"img":false}]}
{"op":"mcm","clk":"5348150142","pt":1646214610874,"mc":[{"id":"1.195453621","rc":[{"atl":[[3.35,0]],"id":36463352}],"con":true,"img":false}]}
{"op":"mcm","clk":"5348150158","pt":1646214611076,"mc":[{"id":"1.195453621","rc":[{"atl":[[3.65,3.57]],"id":36463352}],"con":true,"img":false}]}
{"op":"mcm","clk":"5348150165","pt":1646214611129,"mc":[{"id":"1.195453621","rc":[{"atl":[[1000,0]],"id":36463352}],"con":true,"img":false}]}
{"op":"mcm","clk":"5348150170","pt":1646214611234,"mc":[{"id":"1.195453621","rc":[{"atl":[[3.65,6.3]],"id":36463352}],"con":true,"img":false}]}
{"op":"mcm","clk":"5348150365","pt":1646214613844,"mc":[{"id":"1.195453621","rc":[{"atl":[[3.6,4.18],[3.65,2.73]],"id":36463352}],"con":true,"img":false}]}
{"op":"mcm","clk":"5348150376","pt":1646214614049,"mc":[{"id":"1.195453621","rc":[{"atl":[[3.6,7.8]],"id":36463352}],"con":true,"img":false}]}
{"op":"mcm","clk":"5348150409","pt":1646214614568,"mc":[{"id":"1.195453621","rc":[{"atl":[[3.65,0]],"id":36463352}],"con":true,"img":false}]}
{"op":"mcm","clk":"5348150417","pt":1646214614670,"mc":[{"id":"1.195453621","rc":[{"atl":[[3.55,2.73]],"id":36463352}],"con":true,"img":false}]}
{"op":"mcm","clk":"5348150563","pt":1646214616846,"mc":[{"id":"1.195453621","rc":[{"atl":[[3.6,4.18]],"id":36463352}],"con":true,"img":false}]}
{"op":"mcm","clk":"5348150582","pt":1646214617058,"mc":[{"id":"1.195453621","rc":[{"atl":[[3.5,3.72]],"id":36463352}],"con":true,"img":false}]}
{"op":"mcm","clk":"5348150627","pt":1646214617776,"mc":[{"id":"1.195453621","rc":[{"atl":[[3.55,0]],"id":36463352}],"con":true,"img":false}]}
{"op":"mcm","clk":"5348150634","pt":1646214617878,"mc":[{"id":"1.195453621","rc":[{"atl":[[3.45,2.73]],"id":36463352}],"con":true,"img":false}]}
{"op":"mcm","clk":"5348150761","pt":1646214619907,"mc":[{"id":"1.195453621","rc":[{"atl":[[3.5,0]],"id":36463352}],"con":true,"img":false}]}
{"op":"mcm","clk":"5348150776","pt":1646214620062,"mc":[{"id":"1.195453621","rc":[{"atl":[[3.4,3.84]],"id":36463352}],"con":true,"img":false}]}
{"op":"mcm","clk":"5348150786","pt":1646214620272,"mc":[{"id":"1.195453621","rc":[{"atl":[[3.45,0]],"id":36463352}],"con":true,"img":false}]}
{"op":"mcm","clk":"5348150792","pt":1646214620369,"mc":[{"id":"1.195453621","rc":[{"atl":[[1000,2.73]],"id":36463352}],"con":true,"img":false}]}
{"op":"mcm","clk":"5348150940","pt":1646214622651,"mc":[{"id":"1.195453621","rc":[{"atl":[[3.85,0]],"id":36463352}],"con":true,"img":false}]}
{"op":"mcm","clk":"5348152057","pt":1646214637388,"mc":[{"id":"1.195453621","rc":[{"atl":[[3.85,4.32]],"id":36463352}],"con":true,"img":false}]}
{"op":"mcm","clk":"5348152383","pt":1646214641941,"mc":[{"id":"1.195453621","rc":[{"atl":[[310,0]],"id":40250501},{"atb":[[8,0],[11,9.97]],"id":40199925},{"atl":[[140,2],[210,0]],"id":40199925}],"con":true,"img":false}]}
{"op":"mcm","clk":"5348152389","pt":1646214642046,"mc":[{"id":"1.195453621","rc":[{"atb":[[11.5,9.52],[7,0]],"id":23806261},{"atl":[[150,2],[230,0.87]],"id":23806261},{"atl":[[120,2]],"id":40250501},{"atl":[[3.8,8.36],[4.7,0]],"id":36463352},{"atb":[[1.44,0],[1.33,111.64]],"id":41308374},{"atb":[[2.34,28.84],[4,78.49]],"id":40846831},{"atb":[[7.2,18.5],[5.8,20.44]],"id":6780934},{"atl":[[190,0],[100,2]],"id":6780934}],"con":true,"img":false}]}
{"op":"mcm","clk":"5348152395","pt":1646214642102,"mc":[{"id":"1.195453621","rc":[{"atl":[[140,0],[100,2]],"id":40199925}],"con":true,"img":false}]}
{"op":"mcm","clk":"5348152403","pt":1646214642206,"mc":[{"id":"1.195453621","rc":[{"atl":[[150,0],[110,2]],"id":23806261},{"atb":[[1.33,0],[1.5,190.23]],"id":41308374},{"atb":[[2.34,0],[3.7,37.04]],"id":40846831},{"atb":[[5.8,0],[8.4,2]],"id":6780934},{"atl":[[75,2],[100,0]],"id":6780934}],"con":true,"img":false}]}
{"op":"mcm","clk":"5348153420","pt":1646214657716,"mc":[{"id":"1.195453621","rc":[{"atb":[[1.03,2.25]],"id":40250501}],"con":true,"img":false}]}
{"op":"mcm","clk":"5348153424","pt":1646214657820,"mc":[{"id":"1.195453621","rc":[{"atb":[[19,0],[1.04,2.25]],"id":23806261},{"atb":[[12,0]],"id":40250501}],"con":true,"img":false}]}
{"op":"mcm","clk":"5348153429","pt":1646214657940,"mc":[{"id":"1.195453621","rc":[{"atb":[[1.04,0.18]],"id":23806261},{"atb":[[1.03,0.28]],"id":40250501}],"con":true,"img":false}]}
{"op":"mcm","clk":"5348153460","pt":1646214658647,"mc":[{"id":"1.195453621","rc":[{"atb":[[1.03,0]],"id":40250501}],"con":true,"img":false}]}
{"op":"mcm","clk":"5348153467","pt":1646214658751,"mc":[{"id":"1.195453621","rc":[{"atb":[[13,0.28]],"id":40250501}],"con":true,"img":false}]}
{"op":"mcm","clk":"5348153480","pt":1646214658908,"mc":[{"id":"1.195453621","rc":[{"atb":[[1.04,0]],"id":23806261}],"con":true,"img":false}]}
{"op":"mcm","clk":"5348153486","pt":1646214659009,"mc":[{"id":"1.195453621","rc":[{"atb":[[20,0.18]],"id":23806261}],"con":true,"img":false}]}
{"op":"mcm","clk":"5348154093","pt":1646214668139,"mc":[{"id":"1.195453621","rc":[{"atb":[[8.6,3.8],[8.2,0.37]],"id":6780934}],"con":true,"img":false}]}
{"op":"mcm","clk":"5348154109","pt":1646214668347,"mc":[{"id":"1.195453621","rc":[{"atl":[[95,2],[110,0]],"id":23806261},{"atl":[[3.8,0]],"id":36463352},{"atl":[[46,0]],"id":40846831},{"atb":[[8,5.44],[8.4,0]],"id":6780934}],"con":true,"img":false}]}
{"op":"mcm","clk":"5348154113","pt":1646214668474,"mc":[{"id":"1.195453621","rc":[{"atl":[[3.7,29.23]],"id":36463352},{"atl":[[36,2.86]],"id":40846831}],"con":true,"img":false}]}
{"op":"mcm","clk":"5348154467","pt":1646214673076,"mc":[{"id":"1.195453621","rc":[{"atl":[[3.7,8.36]],"id":36463352}],"con":true,"img":false}]}
{"op":"mcm","clk":"5348154476","pt":1646214673177,"mc":[{"id":"1.195453621","rc":[{"atl":[[3.55,20.87]],"id":36463352}],"con":true,"img":false}]}
{"op":"mcm","clk":"5348155090","pt":1646214682559,"mc":[{"id":"1.195453621","rc":[{"spn":13.02,"spf":1.0,"id":23806261},{"spn":10.02,"spf":1.0,"id":40250501},{"spn":12.94,"spf":1.0,"id":40199925},{"atb":[[8.6,0]],"id":6780934},{"spn":7.33,"spf":1.0,"id":6780934}],"con":true,"img":false}]}
{"op":"mcm","clk":"5348155099","pt":1646214682662,"mc":[{"id":"1.195453621","rc":[{"atb":[[8.4,3.8]],"id":6780934}],"con":true,"img":false}]}
{"op":"mcm","clk":"5348155109","pt":1646214682767,"mc":[{"id":"1.195453621","rc":[{"atb":[[8,1.44],[7.6,6.81]],"id":6780934}],"con":true,"img":false}]}
{"op":"mcm","clk":"5348155120","pt":1646214682867,"mc":[{"id":"1.195453621","rc":[{"atb":[[8,6.88]],"id":6780934}],"con":true,"img":false}]}
{"op":"mcm","clk":"5348155123","pt":1646214682965,"mc":[{"id":"1.195453621","rc":[{"atb":[[7.6,0]],"id":6780934}],"con":true,"img":false}]}
{"op":"mcm","clk":"5348155482","pt":1646214688682,"mc":[{"id":"1.195453621","rc":[{"atl":[[1000,0]],"id":36463352}],"con":true,"img":false}]}
{"op":"mcm","clk":"5348155489","pt":1646214688784,"mc":[{"id":"1.195453621","rc":[{"atl":[[3.35,2.73]],"id":36463352}],"con":true,"img":false}]}
{"op":"mcm","clk":"5348155662","pt":1646214691571,"mc":[{"id":"1.195453621","rc":[{"atl":[[3.95,0]],"id":36463352}],"con":true,"img":false}]}
{"op":"mcm","clk":"5348155667","pt":1646214691668,"mc":[{"id":"1.195453621","rc":[{"atl":[[3.65,38.98]],"id":36463352}],"con":true,"img":false}]}
{"op":"mcm","clk":"5348155688","pt":1646214691982,"mc":[{"id":"1.195453621","rc":[{"atl":[[3.4,0]],"id":36463352}],"con":true,"img":false}]}
{"op":"mcm","clk":"5348155707","pt":1646214692189,"mc":[{"id":"1.195453621","rc":[{"atl":[[3.3,3.95]],"id":36463352}],"con":true,"img":false}]}
{"op":"mcm","clk":"5348155741","pt":1646214692663,"mc":[{"id":"1.195453621","rc":[{"atl":[[3.35,0]],"id":36463352}],"con":true,"img":false}]}
{"op":"mcm","clk":"5348155748","pt":1646214692757,"mc":[{"id":"1.195453621","rc":[{"atl":[[1000,2.73]],"id":36463352}],"con":true,"img":false}]}
{"op":"mcm","clk":"5348156109","pt":1646214698473,"mc":[{"id":"1.195453621","rc":[{"atb":[[8.4,0]],"id":6780934}],"con":true,"img":false}]}
{"op":"mcm","clk":"5348156115","pt":1646214698580,"mc":[{"id":"1.195453621","rc":[{"atb":[[8,1.44],[8.2,4.17],[7.6,7.26]],"id":6780934}],"con":true,"img":false}]}
{"op":"mcm","clk":"5348157483","pt":1646214720927,"mc":[{"id":"1.195453621","rc":[{"atb":[[8,9.8],[7.6,0]],"id":6780934}],"con":true,"img":false}]}
{"op":"mcm","clk":"5348157655","pt":1646214723352,"mc":[{"id":"1.195453621","rc":[{"atb":[[8.4,0],[1.02,2.25]],"id":40846831}],"con":true,"img":false}]}
{"op":"mcm","clk":"5348157671","pt":1646214723532,"mc":[{"id":"1.195453621","rc":[{"atb":[[1.02,0.42]],"id":40846831}],"con":true,"img":false}]}
{"op":"mcm","clk":"5348157684","pt":1646214723711,"mc":[{"id":"1.195453621","rc":[{"atb":[[1.02,0]],"id":40846831}],"con":true,"img":false}]}
{"op":"mcm","clk":"5348157692","pt":1646214723815,"mc":[{"id":"1.195453621","rc":[{"atb":[[8.8,0.42]],"id":40846831}],"con":true,"img":false}]}
{"op":"mcm","clk":"5348158186","pt":1646214731068,"mc":[{"id":"1.195453621","rc":[{"atl":[[3.6,0]],"id":36463352}],"con":true,"img":false}]}
{"op":"mcm","clk":"5348159799","pt":1646214754983,"mc":[{"id":"1.195453621","rc":[{"atl":[[3.85,0]],"id":36463352},{"spn":7.43,"spf":1.0,"id":40846831},{"spn":7.6,"spf":1.0,"id":6780934}],"con":true,"img":false}]}
{"op":"mcm","clk":"5348159928","pt":1646214756802,"mc":[{"id":"1.195453621","rc":[{"atl":[[3.65,0]],"id":36463352}],"con":true,"img":false}]}
{"op":"mcm","clk":"5348159934","pt":1646214756892,"mc":[{"id":"1.195453621","rc":[{"atl":[[3.95,38.98]],"id":36463352}],"con":true,"img":false}]}
{"op":"mcm","clk":"5348161969","pt":1646214788429,"mc":[{"id":"1.195453621","rc":[{"atl":[[4,34.16],[3.7,0]],"id":36463352},{"atb":[[1.44,111.64],[1.5,0]],"id":41308374},{"atb":[[3.05,45.93],[3.7,0]],"id":40846831},{"atb":[[8,1.44],[7,20.79]],"id":6780934}],"con":true,"img":false}]}
{"op":"mcm","clk":"5348163231","pt":1646214806373,"mc":[{"id":"1.195453621","rc":[{"atl":[[3.3,0]],"id":36463352}],"con":true,"img":false}]}
{"op":"mcm","clk":"5348163240","pt":1646214806576,"mc":[{"id":"1.195453621","rc":[{"atl":[[3.5,3.72]],"id":36463352}],"con":true,"img":false}]}
{"op":"mcm","clk":"5348163267","pt":1646214806996,"mc":[{"id":"1.195453621","rc":[{"atl":[[1000,0]],"id":36463352}],"con":true,"img":false}]}
{"op":"mcm","clk":"5348163274","pt":1646214807043,"mc":[{"id":"1.195453621","rc":[{"atl":[[3.45,2.73]],"id":36463352}],"con":true,"img":false}]}
{"op":"mcm","clk":"5348163387","pt":1646214808794,"mc":[{"id":"1.195453621","rc":[{"atl":[[3.85,4.32]],"id":36463352}],"con":true,"img":false}]}
{"op":"mcm","clk":"5348163420","pt":1646214809256,"mc":[{"id":"1.195453621","rc":[{"atl":[[3.85,8.22],[3.5,0]],"id":36463352}],"con":true,"img":false}]}
{"op":"mcm","clk":"5348163428","pt":1646214809357,"mc":[{"id":"1.195453621","rc":[{"atl":[[3.4,3.84]],"id":36463352}],"con":true,"img":false}]}
{"op":"mcm","clk":"5348163487","pt":1646214810081,"mc":[{"id":"1.195453621","rc":[{"atl":[[3.45,0]],"id":36463352}],"con":true,"img":false}]}
{"op":"mcm","clk":"5348163491","pt":1646214810181,"mc":[{"id":"1.195453621","rc":[{"atl":[[3.35,2.73]],"id":36463352}],"con":true,"img":false}]}
{"op":"mcm","clk":"5348163643","pt":1646214812293,"mc":[{"id":"1.195453621","rc":[{"atl":[[3.4,0]],"id":36463352}],"con":true,"img":false}]}
{"op":"mcm","clk":"5348163647","pt":1646214812396,"mc":[{"id":"1.195453621","rc":[{"atl":[[3.3,3.95]],"id":36463352}],"con":true,"img":false}]}
{"op":"mcm","clk":"5348163660","pt":1646214812552,"mc":[{"id":"1.195453621","rc":[{"atl":[[3.35,0]],"id":36463352}],"con":true,"img":false}]}
{"op":"mcm","clk":"5348163667","pt":1646214812655,"mc":[{"id":"1.195453621","rc":[{"atl":[[3.5,2.73]],"id":36463352}],"con":true,"img":false}]}
{"op":"mcm","clk":"5348167205","pt":1646214864174,"mc":[{"id":"1.195453621","rc":[{"atl":[[3.95,0]],"id":36463352},{"spn":7.35,"spf":1.0,"id":6780934}],"con":true,"img":false}]}
{"op":"mcm","clk":"5348167214","pt":1646214864274,"mc":[{"id":"1.195453621","rc":[{"atl":[[3.8,38.98]],"id":36463352}],"con":true,"img":false}]}
{"op":"mcm","clk":"5348170469","pt":1646214913008,"mc":[{"id":"1.195453621","rc":[{"atl":[[2.94,7.08]],"id":41308374}],"con":true,"img":false}]}
{"op":"mcm","clk":"5348170651","pt":1646214916002,"mc":[{"id":"1.195453621","rc":[{"atl":[[2.94,2.64]],"id":41308374},{"trd":[[2.94,8.87]],"ltp":2.94,"tv":8.87,"id":41308374}],"con":true,"img":false}]}
{"op":"mcm","clk":"5348171117","pt":1646214923228,"mc":[{"id":"1.195453621","rc":[{"atb":[[3.3,43.48],[3.05,0]],"id":40846831},{"atb":[[7.4,16.84],[7,6.81]],"id":6780934}],"con":true,"img":false}]}
{"op":"mcm","clk":"5348171245","pt":1646214925548,"mc":[{"id":"1.195453621","rc":[{"atl":[[3.85,3.9]],"id":36463352},{"spn":7.49,"spf":1.0,"id":6780934}],"con":true,"img":false}]}
{"op":"mcm","clk":"5348171302","pt":1646214926472,"mc":[{"id":"1.195453621","rc":[{"atl":[[3.85,0],[3.3,0]],"id":36463352}],"con":true,"img":false}]}
{"op":"mcm","clk":"5348171315","pt":1646214926626,"mc":[{"id":"1.195453621","rc":[{"atl":[[3.45,3.78]],"id":36463352}],"con":true,"img":false}]}
{"op":"mcm","clk":"5348171358","pt":1646214927452,"mc":[{"id":"1.195453621","rc":[{"atl":[[3.8,0]],"id":36463352}],"con":true,"img":false}]}
{"op":"mcm","clk":"5348171367","pt":1646214927555,"mc":[{"id":"1.195453621","rc":[{"atl":[[3.95,38.98]],"id":36463352}],"con":true,"img":false}]}
{"op":"mcm","clk":"5348171416","pt":1646214928435,"mc":[{"id":"1.195453621","rc":[{"atb":[[1.07,1.66]],"id":23806261},{"atb":[[1.06,1.66]],"id":40250501},{"atb":[[1.01,1.66]],"id":36463352},{"atb":[[1.01,1.66]],"id":41308374},{"atb":[[1.07,1.66]],"id":40199925},{"atb":[[1.04,1.66]],"id":40846831},{"atb":[[1.04,1.66]],"id":6780934}],"con":true,"img":false}]}
{"op":"mcm","clk":"5348171429","pt":1646214928641,"mc":[{"id":"1.195453621","rc":[{"atb":[[1.07,0.1]],"id":23806261},{"atb":[[1.06,0.12]],"id":40250501},{"atb":[[1.01,0.7]],"id":36463352},{"atb":[[1.01,0.68]],"id":41308374},{"atb":[[1.07,0.1]],"id":40199925},{"atb":[[1.04,0.18]],"id":40846831},{"atb":[[1.04,0.19]],"id":6780934}],"con":true,"img":false}]}
{"op":"mcm","clk":"5348171440","pt":1646214928847,"mc":[{"id":"1.195453621","rc":[{"atb":[[1.07,0]],"id":23806261},{"atb":[[1.06,0]],"id":40250501},{"atb":[[1.01,0]],"id":36463352},{"atb":[[1.01,0]],"id":41308374},{"atb":[[1.07,0]],"id":40199925},{"atb":[[1.04,0]],"id":40846831},{"atb":[[1.04,0]],"id":6780934}],"con":true,"img":false}]}
{"op":"mcm","clk":"5348171445","pt":1646214928950,"mc":[{"id":"1.195453621","rc":[{"atb":[[16.5,0.1]],"id":23806261},{"atb":[[13,0.41]],"id":40250501},{"atb":[[2.38,0.7]],"id":36463352},{"atb":[[2.42,0.68]],"id":41308374},{"atb":[[16.5,0.1]],"id":40199925},{"atb":[[8.8,0.61]],"id":40846831},{"atb":[[8.4,0.19]],"id":6780934}],"con":true,"img":false}]}
{"op":"mcm","clk":"5348171461","pt":1646214929258,"mc":[{"id":"1.195453621","rc":[{"atb":[[2.32,1.59]],"id":36463352}],"con":true,"img":false}]}
{"op":"mcm","clk":"5348171471","pt":1646214929363,"mc":[{"id":"1.195453621","rc":[{"atb":[[2.36,2.89]],"id":36463352}],"con":true,"img":false}]}
{"op":"mcm","clk":"5348171588","pt":1646214931370,"mc":[{"id":"1.195453621","rc":[{"atl":[[3.5,0]],"id":36463352}],"con":true,"img":false}]}
{"op":"mcm","clk":"5348171595","pt":1646214931425,"mc":[{"id":"1.195453621","rc":[{"atl":[[3.4,2.73]],"id":36463352}],"con":true,"img":false}]}
{"op":"mcm","clk":"5348171665","pt":1646214932465,"mc":[{"id":"1.195453621","rc":[{"atl":[[3.45,0]],"id":36463352}],"con":true,"img":false}]}
{"op":"mcm","clk":"5348171675","pt":1646214932567,"mc":[{"id":"1.195453621","rc":[{"atl":[[3.35,3.89]],"id":36463352}],"con":true,"img":false}]}
{"op":"mcm","clk":"5348171689","pt":1646214932774,"mc":[{"id":"1.195453621","rc":[{"atl":[[3.4,0]],"id":36463352}],"con":true,"img":false}]}
{"op":"mcm","clk":"5348171698","pt":1646214932825,"mc":[{"id":"1.195453621","rc":[{"atl":[[3.5,2.73]],"id":36463352}],"con":true,"img":false}]}
{"op":"mcm","clk":"5348173853","pt":1646214965692,"mc":[{"id":"1.195453621","rc":[{"atb":[[8.2,0.37]],"id":6780934}],"con":true,"img":false}]}
{"op":"mcm","clk":"5348173859","pt":1646214965796,"mc":[{"id":"1.195453621","rc":[{"atb":[[8.4,3.99]],"id":6780934}],"con":true,"img":false}]}
{"op":"mcm","clk":"5348173868","pt":1646214966004,"mc":[{"id":"1.195453621","rc":[{"atb":[[2.22,0]],"id":36463352},{"atl":[[4,4.93],[3.7,34.16]],"id":36463352},{"atb":[[1.44,0],[1.5,132.42]],"id":41308374},{"atb":[[3.55,39.22],[3.3,0]],"id":40846831},{"atb":[[8,15.73],[7.4,1.22]],"id":6780934}],"con":true,"img":false}]}
{"op":"mcm","clk":"5348176022","pt":1646215000681,"mc":[{"id":"1.195453621","rc":[{"spn":13.04,"spf":1.0,"id":23806261},{"spn":10.04,"spf":1.0,"id":40250501},{"spn":2.27,"spf":1.0,"id":36463352},{"spn":2.13,"spf":1.0,"id":41308374},{"spn":12.96,"spf":1.0,"id":40199925},{"atb":[[3.55,0],[3.9,34.48]],"id":40846831},{"spn":7.44,"spf":1.0,"id":40846831},{"spn":7.8,"spf":1.0,"id":6780934}],"con":true,"img":false}]}
{"op":"mcm","clk":"5348176244","pt":1646215003775,"mc":[{"id":"1.195453621","rc":[{"atl":[[3.55,0]],"id":36463352}],"con":true,"img":false}]}
{"op":"mcm","clk":"5348176250","pt":1646215003880,"mc":[{"id":"1.195453621","rc":[{"atl":[[3.45,20.87]],"id":36463352}],"con":true,"img":false}]}
{"op":"mcm","clk":"5348176287","pt":1646215004505,"mc":[{"id":"1.195453621","rc":[{"atl":[[3.5,0]],"id":36463352}],"con":true,"img":false}]}
{"op":"mcm","clk":"5348176298","pt":1646215004550,"mc":[{"id":"1.195453621","rc":[{"atl":[[3.3,2.73]],"id":36463352}],"con":true,"img":false}]}
{"op":"mcm","clk":"5348176528","pt":1646215007651,"mc":[{"id":"1.195453621","rc":[{"atl":[[3.35,0]],"id":36463352}],"con":true,"img":false}]}
{"op":"mcm","clk":"5348176541","pt":1646215007857,"mc":[{"id":"1.195453621","rc":[{"atl":[[3.25,4.01]],"id":36463352}],"con":true,"img":false}]}
{"op":"mcm","clk":"5348176554","pt":1646215008063,"mc":[{"id":"1.195453621","rc":[{"atl":[[3.3,0]],"id":36463352}],"con":true,"img":false}]}
{"op":"mcm","clk":"5348176560","pt":1646215008170,"mc":[{"id":"1.195453621","rc":[{"atl":[[1000,2.73]],"id":36463352}],"con":true,"img":false}]}
{"op":"mcm","clk":"5348176687","pt":1646215009200,"mc":[{"id":"1.195453621","rc":[{"atb":[[8,1.44],[8.6,4]],"id":6780934}],"con":true,"img":false}]}
{"op":"mcm","clk":"5348177463","pt":1646215021013,"mc":[{"id":"1.195453621","rc":[{"atl":[[3.2,5.44]],"id":36463352}],"con":true,"img":false}]}
{"op":"mcm","clk":"5348177486","pt":1646215021328,"mc":[{"id":"1.195453621","rc":[{"atb":[[11,12.5],[12,6.82],[13,4.17],[14,1.54]],"id":23806261},{"atl":[[260,1],[200,1],[220,1],[240,15.2]],"id":23806261},{"atb":[[4.3,6.06],[3.85,43.86],[3.95,25.42],[4.1,48.39]],"id":40250501},{"atl":[[34,1.52],[38,2.03],[42,3.05],[30,3.72]],"id":40250501},{"atb":[[1.59,127.12],[1.63,31.75],[1.57,219.3],[1.61,200]],"id":36463352},{"atl":[[3.35,21.28],[3.25,12.9],[3.55,49.02],[3.45,51.48]],"id":36463352},{"atb":[[1.96,20.83],[1.94,53.19],[1.92,81.52],[1.9,184.3]],"id":41308374},{"atl":[[5.9,10.2],[6.2,52.84],[5.7,25.54],[6.6,22.32]],"id":41308374},{"atb":[[11,22.47],[12,6.82],[13,12.88],[14,1.54]],"id":40199925},{"atl":[[260,1],[200,1],[220,1],[240,1]],"id":40199925},{"atb":[[6.4,13.89],[6.8,8.62],[7.2,22.98],[6,25]],"id":40846831},{"atl":[[150,1],[170,1],[190,1],[210,1]],"id":40846831},{"atb":[[6.4,13.89],[6.8,8.62],[7.2,21.73],[6,25]],"id":6780934},{"atl":[[32,2.42],[36,6.84],[27,1],[29,3.26]],"id":6780934}],"con":true,"img":false}]}
{"op":"mcm","clk":"5348177511","pt":1646215021590,"mc":[{"id":"1.195453621","rc":[{"atl":[[28,2.65]],"id":6780934}],"con":true,"img":false}]}
{"op":"mcm","clk":"5348177529","pt":1646215021795,"mc":[{"id":"1.195453621","rc":[{"atl":[[3.95,0]],"id":36463352}],"con":true,"img":false}]}
{"op":"mcm","clk":"5348177540","pt":1646215021900,"mc":[{"id":"1.195453621","rc":[{"atl":[[3.5,38.98]],"id":36463352}],"con":true,"img":false}]}
{"op":"mcm","clk":"5348177550","pt":1646215022003,"mc":[{"id":"1.195453621","rc":[{"atb":[[7.8,2.79]],"id":40846831}],"con":true,"img":false}]}
{"op":"mcm","clk":"5348177566","pt":1646215022207,"mc":[{"id":"1.195453621","rc":[{"atb":[[1.02,2.25],[8.8,0.18]],"id":40846831}],"con":true,"img":false}]}
{"op":"mcm","clk":"5348177582","pt":1646215022416,"mc":[{"id":"1.195453621","rc":[{"atb":[[1.02,0.42]],"id":40846831}],"con":true,"img":false}]}
{"op":"mcm","clk":"5348177601","pt":1646215022624,"mc":[{"id":"1.195453621","rc":[{"atb":[[1.02,0]],"id":40846831}],"con":true,"img":false}]}
{"op":"mcm","clk":"5348177609","pt":1646215022728,"mc":[{"id":"1.195453621","rc":[{"atb":[[8,0.42]],"id":40846831}],"con":true,"img":false}]}
{"op":"mcm","clk":"5348177700","pt":1646215023712,"mc":[{"id":"1.195453621","rc":[{"atl":[[3.25,8.89]],"id":36463352}],"con":true,"img":false}]}
{"op":"mcm","clk":"5348177708","pt":1646215023815,"mc":[{"id":"1.195453621","rc":[{"atl":[[3.15,4.14]],"id":36463352},{"atl":[[3.2,0]],"id":41308374}],"con":true,"img":false}]}
{"op":"mcm","clk":"5348177713","pt":1646215023916,"mc":[{"id":"1.195453621","rc":[{"atl":[[3.3,24.87]],"id":41308374}],"con":true,"img":false}]}
{"op":"mcm","clk":"5348177721","pt":1646215024022,"mc":[{"id":"1.195453621","rc":[{"atl":[[3.15,10.68]],"id":36463352}],"con":true,"img":false}]}
{"op":"mcm","clk":"5348177774","pt":1646215024696,"mc":[{"id":"1.195453621","rc":[{"atb":[[17,2.08]],"id":23806261},{"atb":[[13,2.49]],"id":40250501},{"atb":[[2.32,0],[2.38,3.2]],"id":36463352},{"atb":[[17,2.08]],"id":40199925},{"atb":[[8.8,2.5]],"id":6780934}],"con":true,"img":false}]}
{"op":"mcm","clk":"5348177782","pt":1646215024797,"mc":[{"id":"1.195453621","rc":[{"atb":[[1.01,1.59]],"id":36463352}],"con":true,"img":false}]}
{"op":"mcm","clk":"5348177834","pt":1646215025621,"mc":[{"id":"1.195453621","rc":[{"atb":[[4.3,0],[3.85,0],[3.5,40],[3.95,0],[4.1,0],[3.65,7.55]],"id":40250501},{"atl":[[3.15,6.53]],"id":36463352},{"atl":[[6.4,3.7],[5.9,0],[5.7,21.28]],"id":41308374},{"atl":[[150,0],[28,1]],"id":40846831}],"con":true,"img":false}]}
{"op":"mcm","clk":"5348177846","pt":1646215025829,"mc":[{"id":"1.195453621","rc":[{"atl":[[3.1,4.21]],"id":36463352}],"con":true,"img":false}]}
{"op":"mcm","clk":"5348177861","pt":1646215026085,"mc":[{"id":"1.195453621","rc":[{"atl":[[6.2,38.42]],"id":41308374}],"con":true,"img":false}]}
{"op":"mcm","clk":"5348177886","pt":1646215026497,"mc":[{"id":"1.195453621","rc":[{"atl":[[28,0]],"id":6780934}],"con":true,"img":false}]}
{"op":"mcm","clk":"5348177891","pt":1646215026598,"mc":[{"id":"1.195453621","rc":[{"atl":[[1000,2.65]],"id":6780934}],"con":true,"img":false}]}
{"op":"mcm","clk":"5348178221","pt":1646215031811,"mc":[{"id":"1.195453621","rc":[{"atb":[[8.4,0.19]],"id":6780934}],"con":true,"img":false}]}
{"op":"mcm","clk":"5348178228","pt":1646215031914,"mc":[{"id":"1.195453621","rc":[{"atb":[[9,3.8]],"id":6780934}],"con":true,"img":false}]}
{"op":"mcm","clk":"5348178238","pt":1646215032121,"mc":[{"id":"1.195453621","rc":[{"atb":[[8.6,0],[8.8,10.1]],"id":6780934}],"con":true,"img":false}]}
{"op":"mcm","clk":"5348178282","pt":1646215032739,"mc":[{"id":"1.195453621","rc":[{"atb":[[8.8,7.6]],"id":6780934}],"con":true,"img":false}]}
{"op":"mcm","clk":"5348178317","pt":1646215033207,"mc":[{"id":"1.195453621","rc":[{"atl":[[3.2,0]],"id":36463352}],"con":true,"img":false}]}
{"op":"mcm","clk":"5348178432","pt":1646215034920,"mc":[{"id":"1.195453621","rc":[{"atb":[[9.2,2.5]],"id":6780934}],"con":true,"img":false}]}
{"op":"mcm","clk":"5348178469","pt":1646215035338,"mc":[{"id":"1.195453621","rc":[{"atl":[[3.05,5.44]],"id":36463352}],"con":true,"img":false}]}
{"op":"mcm","clk":"5348178487","pt":1646215035647,"mc":[{"id":"1.195453621","rc":[{"atb":[[3.55,19.61]],"id":40250501},{"atl":[[6.8,8.62]],"id":41308374},{"atl":[[30,1.72]],"id":40846831}],"con":true,"img":false}]}
{"op":"mcm","clk":"5348178538","pt":1646215036522,"mc":[{"id":"1.195453621","rc":[{"atl":[[3.15,0]],"id":36463352}],"con":true,"img":false}]}
{"op":"mcm","clk":"5348178572","pt":1646215037247,"mc":[{"id":"1.195453621","rc":[{"atl":[[3,6.53]],"id":36463352}],"con":true,"img":false}]}
{"op":"mcm","clk":"5348178590","pt":1646215037511,"mc":[{"id":"1.195453621","rc":[{"atl":[[170,0],[190,0],[210,0]],"id":40846831}],"con":true,"img":false}]}
{"op":"mcm","clk":"5348178601","pt":1646215037715,"mc":[{"id":"1.195453621","rc":[{"atl":[[3.1,0]],"id":36463352}],"con":true,"img":false}]}
{"op":"mcm","clk":"5348178609","pt":1646215037921,"mc":[{"id":"1.195453621","rc":[{"atb":[[2.38,0.7]],"id":36463352},{"atl":[[2.98,4.38]],"id":36463352}],"con":true,"img":false}]}
{"op":"mcm","clk":"5348178829","pt":1646215041860,"mc":[{"id":"1.195453621","rc":[{"atl":[[3.45,30.61]],"id":36463352}],"con":true,"img":false}]}
{"op":"mcm","clk":"5348178838","pt":1646215041965,"mc":[{"id":"1.195453621","rc":[{"atl":[[3.3,20.87]],"id":36463352}],"con":true,"img":false}]}
{"op":"mcm","clk":"5348179061","pt":1646215045626,"mc":[{"id":"1.195453621","rc":[{"atb":[[3.45,30.61]],"id":40250501},{"atl":[[7.2,44.32]],"id":41308374},{"atl":[[34,2.27]],"id":40846831}],"con":true,"img":false}]}
{"op":"mcm","clk":"5348179162","pt":1646215047227,"mc":[{"id":"1.195453621","rc":[{"atl":[[27,0.77]],"id":6780934},{"trd":[[27,0.45]],"ltp":27.0,"tv":0.45,"id":6780934}],"con":true,"img":false}]}
{"op":"mcm","clk":"5348179170","pt":1646215047334,"mc":[{"id":"1.195453621","rc":[{"atl":[[32,0],[36,3.27],[27,0],[29,1.47],[30,1]],"id":6780934}],"con":true,"img":false}]}
{"op":"mcm","clk":"5348179186","pt":1646215047537,"mc":[{"id":"1.195453621","rc":[{"atl":[[3.05,0]],"id":36463352}],"con":true,"img":false}]}
{"op":"mcm","clk":"5348179201","pt":1646215047746,"mc":[{"id":"1.195453621","rc":[{"atl":[[2.96,5.44]],"id":36463352}],"con":true,"img":false}]}
{"op":"mcm","clk":"5348179321","pt":1646215049655,"mc":[{"id":"1.195453621","rc":[{"atl":[[3,0],[2.98,0]],"id":36463352}],"con":true,"img":false}]}
{"op":"mcm","clk":"5348179331","pt":1646215049758,"mc":[{"id":"1.195453621","rc":[{"atl":[[2.94,4.44]],"id":36463352}],"con":true,"img":false}]}
{"op":"mcm","clk":"5348179377","pt":1646215050337,"mc":[{"id":"1.195453621","rc":[{"atl":[[2.92,6.53]],"id":36463352}],"con":true,"img":false}]}
{"op":"mcm","clk":"5348179543","pt":1646215052762,"mc":[{"id":"1.195453621","rc":[{"atl":[[2.94,0]],"id":36463352}],"con":true,"img":false}]}
{"op":"mcm","clk":"5348179555","pt":1646215052965,"mc":[{"id":"1.195453621","rc":[{"atl":[[2.9,4.5]],"id":36463352}],"con":true,"img":false}]}
{"op":"mcm","clk":"5348179731","pt":1646215055659,"mc":[{"id":"1.195453621","rc":[{"atb":[[3.35,53.19]],"id":40250501},{"atl":[[7.6,18.94]],"id":41308374},{"atl":[[38,6.98]],"id":40846831}],"con":true,"img":false}]}
{"op":"mcm","clk":"5348179739","pt":1646215055762,"mc":[{"id":"1.195453621","rc":[{"atb":[[9,0],[9.4,3.47]],"id":6780934}],"con":true,"img":false}]}
{"op":"mcm","clk":"5348179787","pt":1646215056534,"mc":[{"id":"1.195453621","rc":[{"atb":[[9.2,0]],"id":6780934}],"con":true,"img":false}]}
{"op":"mcm","clk":"5348179824","pt":1646215057367,"mc":[{"id":"1.195453621","rc":[{"atl":[[34,1.49]],"id":6780934}],"con":true,"img":false}]}
{"op":"mcm","clk":"5348179923","pt":1646215059309,"mc":[{"id":"1.195453621","rc":[{"atb":[[9.6,2.5]],"id":6780934}],"con":true,"img":false}]}
{"op":"mcm","clk":"5348179937","pt":1646215059535,"mc":[{"id":"1.195453621","rc":[{"atb":[[9,5.98],[8.8,0]],"id":6780934}],"con":true,"img":false}]}
{"op":"mcm","clk":"5348179946","pt":1646215059689,"mc":[{"id":"1.195453621","rc":[{"atl":[[6.6,0]],"id":41308374}],"con":true,"img":false}]}
{"op":"mcm","clk":"5348179965","pt":1646215060053,"mc":[{"id":"1.195453621","rc":[{"atl":[[2.96,0]],"id":36463352}],"con":true,"img":false}]}
{"op":"mcm","clk":"5348179992","pt":1646215060472,"mc":[{"id":"1.195453621","rc":[{"atl":[[2.88,5.44]],"id":36463352}],"con":true,"img":false}]}
{"op":"mcm","clk":"5348180073","pt":1646215061762,"mc":[{"id":"1.195453621","rc":[{"spn":13.86,"spf":1.0,"id":23806261},{"spn":10.4,"spf":1.0,"id":40250501},{"atl":[[3.5,0],[2.9,0],[3.4,47.91]],"id":36463352},{"spn":2.27,"spf":1.0,"id":36463352},{"spn":14.01,"spf":1.0,"id":40199925},{"spn":7.45,"spf":1.0,"id":40846831},{"spn":8.08,"spf":1.0,"id":6780934}],"con":true,"img":false}]}
{"op":"mcm","clk":"5348180079","pt":1646215061867,"mc":[{"id":"1.195453621","rc":[{"atl":[[32,3.78],[46,0]],"id":40250501},{"atl":[[2.86,4.56]],"id":36463352}],"con":true,"img":false}]}
{"op":"mcm","clk":"5348180143","pt":1646215062742,"mc":[{"id":"1.195453621","rc":[{"atl":[[2.92,0]],"id":36463352}],"con":true,"img":false}]}
{"op":"mcm","clk":"5348180177","pt":1646215063564,"mc":[{"id":"1.195453621","rc":[{"atl":[[2.84,6.53]],"id":36463352}],"con":true,"img":false}]}
{"op":"mcm","clk":"5348180191","pt":1646215063768,"mc":[{"id":"1.195453621","rc":[{"atb":[[12.5,0]],"id":23806261}],"con":true,"img":false}]}
{"op":"mcm","clk":"5348180194","pt":1646215063873,"mc":[{"id":"1.195453621","rc":[{"atb":[[13.5,10.21]],"id":23806261}],"con":true,"img":false}]}
{"op":"mcm","clk":"5348180296","pt":1646215065875,"mc":[{"id":"1.195453621","rc":[{"atl":[[2.86,0]],"id":36463352}],"con":true,"img":false}]}
{"op":"mcm","clk":"5348180323","pt":1646215066388,"mc":[{"id":"1.195453621","rc":[{"atl":[[2.82,4.63]],"id":36463352}],"con":true,"img":false}]}
{"op":"mcm","clk":"5348180376","pt":1646215067373,"mc":[{"id":"1.195453621","rc":[{"atl":[[38,5.59]],"id":6780934}],"con":true,"img":false}]}
{"op":"mcm","clk":"5348180649","pt":1646215072684,"mc":[{"id":"1.195453621","rc":[{"atl":[[2.88,0]],"id":36463352}],"con":true,"img":false}]}
{"op":"mcm","clk":"5348180703","pt":1646215073868,"mc":[{"id":"1.195453621","rc":[{"atb":[[9.4,0]],"id":6780934}],"con":true,"img":false}]}
{"op":"mcm","clk":"5348180708","pt":1646215073980,"mc":[{"id":"1.195453621","rc":[{"atb":[[9.8,3.47]],"id":6780934}],"con":true,"img":false}]}
{"op":"mcm","clk":"5348180749","pt":1646215074998,"mc":[{"id":"1.195453621","rc":[{"atl":[[2.8,5.44]],"id":36463352}],"con":true,"img":false}]}
{"op":"mcm","clk":"5348180755","pt":1646215075101,"mc":[{"id":"1.195453621","rc":[{"atb":[[9.6,0]],"id":6780934}],"con":true,"img":false}]}
{"op":"mcm","clk":"5348180801","pt":1646215075988,"mc":[{"id":"1.195453621","rc":[{"atl":[[2.84,0]],"id":36463352}],"con":true,"img":false}]}
{"op":"mcm","clk":"5348180852","pt":1646215076804,"mc":[{"id":"1.195453621","rc":[{"atl":[[2.82,0],[2.78,6.53]],"id":36463352}],"con":true,"img":false}]}
{"op":"mcm","clk":"5348180858","pt":1646215076908,"mc":[{"id":"1.195453621","rc":[{"atl":[[2.78,11.23]],"id":36463352}],"con":true,"img":false}]}
{"op":"mcm","clk":"5348180888","pt":1646215077371,"mc":[{"id":"1.195453621","rc":[{"atl":[[42,3]],"id":6780934}],"con":true,"img":false}]}
{"op":"mcm","clk":"5348180923","pt":1646215078097,"mc":[{"id":"1.195453621","rc":[{"atl":[[1000,0]],"id":6780934}],"con":true,"img":false}]}
{"op":"mcm","clk":"5348180925","pt":1646215078199,"mc":[{"id":"1.195453621","rc":[{"atl":[[34,4.14]],"id":6780934}],"con":true,"img":false}]}
{"op":"mcm","clk":"5348181004","pt":1646215079896,"mc":[{"id":"1.195453621","rc":[{"atl":[[2.78,6.53]],"id":36463352}],"con":true,"img":false}]}
{"op":"mcm","clk":"5348181009","pt":1646215080100,"mc":[{"id":"1.195453621","rc":[{"atl":[[2.76,4.73]],"id":36463352}],"con":true,"img":false}]}
{"op":"mcm","clk":"5348181370","pt":1646215085834,"mc":[{"id":"1.195453621","rc":[{"atb":[[9.8,0]],"id":6780934}],"con":true,"img":false}]}
{"op":"mcm","clk":"5348181373","pt":1646215085897,"mc":[{"id":"1.195453621","rc":[{"atb":[[9.2,3.47]],"id":6780934}],"con":true,"img":false}]}
{"op":"mcm","clk":"5348181377","pt":1646215086027,"mc":[{"id":"1.195453621","rc":[{"atb":[[9,0],[8.2,6.54]],"id":6780934}],"con":true,"img":false}]}
{"op":"mcm","clk":"5348181384","pt":1646215086196,"mc":[{"id":"1.195453621","rc":[{"atb":[[8.2,0.37],[8.8,9.46]],"id":6780934}],"con":true,"img":false}]}
{"op":"mcm","clk":"5348181419","pt":1646215086813,"mc":[{"id":"1.195453621","rc":[{"atb":[[9.4,2.5]],"id":6780934}],"con":true,"img":false}]}
{"op":"mcm","clk":"5348181445","pt":1646215087225,"mc":[{"id":"1.195453621","rc":[{"atl":[[2.8,0]],"id":36463352}],"con":true,"img":false}]}
{"op":"mcm","clk":"5348181566","pt":1646215089292,"mc":[{"id":"1.195453621","rc":[{"atl":[[2.78,0]],"id":36463352}],"con":true,"img":false}]}
{"op":"mcm","clk":"5348182049","pt":1646215097809,"mc":[{"id":"1.195453621","rc":[{"atl":[[36,0]],"id":6780934}],"con":true,"img":false}]}
{"op":"mcm","clk":"5348182056","pt":1646215097908,"mc":[{"id":"1.195453621","rc":[{"atl":[[32,3.27]],"id":6780934}],"con":true,"img":false}]}
{"op":"mcm","clk":"5348182652","pt":1646215107760,"mc":[{"id":"1.195453621","rc":[{"atb":[[9.2,0]],"id":6780934}],"con":true,"img":false}]}
{"op":"mcm","clk":"5348182659","pt":1646215107821,"mc":[{"id":"1.195453621","rc":[{"atb":[[9.6,3.47]],"id":6780934}],"con":true,"img":false}]}
{"op":"mcm","clk":"5348182672","pt":1646215108022,"mc":[{"id":"1.195453621","rc":[{"atb":[[9,5.98],[8.8,0]],"id":6780934}],"con":true,"img":false}]}
{"op":"mcm","clk":"5348182705","pt":1646215108542,"mc":[{"id":"1.195453621","rc":[{"atb":[[9.4,0]],"id":6780934}],"con":true,"img":false}]}
{"op":"mcm","clk":"5348182852","pt":1646215110752,"mc":[{"id":"1.195453621","rc":[{"atb":[[9.8,2.5]],"id":6780934}],"con":true,"img":false}]}
{"op":"mcm","clk":"5348183759","pt":1646215125752,"mc":[{"id":"1.195453621","rc":[{"spn":14.2,"spf":1.0,"id":23806261},{"atb":[[9.6,0]],"id":6780934},{"spn":7.84,"spf":1.0,"id":6780934}],"con":true,"img":false}]}
{"op":"mcm","clk":"5348183766","pt":1646215125856,"mc":[{"id":"1.195453621","rc":[{"atb":[[10,3.47]],"id":6780934}],"con":true,"img":false}]}
{"op":"mcm","clk":"5348183780","pt":1646215126063,"mc":[{"id":"1.195453621","rc":[{"atl":[[32,4.27],[30,0]],"id":6780934}],"con":true,"img":false}]}
{"op":"mcm","clk":"5348183889","pt":1646215127985,"mc":[{"id":"1.195453621","rc":[{"atb":[[9.8,0]],"id":6780934}],"con":true,"img":false}]}
{"op":"mcm","clk":"5348184471","pt":1646215136096,"mc":[{"id":"1.195453621","rc":[{"atl":[[36,1.41]],"id":6780934}],"con":true,"img":false}]}
{"op":"mcm","clk":"5348184681","pt":1646215139766,"mc":[{"id":"1.195453621","rc":[{"atb":[[10,0]],"id":6780934}],"con":true,"img":false}]}
{"op":"mcm","clk":"5348184685","pt":1646215139866,"mc":[{"id":"1.195453621","rc":[{"atb":[[9.2,3.47],[8.2,6.54]],"id":6780934}],"con":true,"img":false}]}
{"op":"mcm","clk":"5348184699","pt":1646215140076,"mc":[{"id":"1.195453621","rc":[{"atb":[[9,0]],"id":6780934}],"con":true,"img":false}]}
{"op":"mcm","clk":"5348184704","pt":1646215140178,"mc":[{"id":"1.195453621","rc":[{"atb":[[9,6.96]],"id":6780934}],"con":true,"img":false}]}
{"op":"mcm","clk":"5348184712","pt":1646215140277,"mc":[{"id":"1.195453621","rc":[{"atb":[[8.2,0.37]],"id":6780934}],"con":true,"img":false}]}
{"op":"mcm","clk":"5348184842","pt":1646215142002,"mc":[{"id":"1.195453621","rc":[{"atb":[[9.4,2.5]],"id":6780934}],"con":true,"img":false}]}
{"op":"mcm","clk":"5348184867","pt":1646215142270,"mc":[{"id":"1.195453621","rc":[{"atl":[[32,3.27],[36,0],[30,1]],"id":6780934}],"con":true,"img":false}]}
{"op":"mcm","clk":"5348185038","pt":1646215145312,"mc":[{"id":"1.195453621","rc":[{"atb":[[9,0],[8.8,6.96]],"id":6780934}],"con":true,"img":false}]}
{"op":"mcm","clk":"5348185471","pt":1646215152307,"mc":[{"id":"1.195453621","rc":[{"atl":[[27,1],[30,0]],"id":6780934}],"con":true,"img":false}]}
{"op":"mcm","clk":"5348186156","pt":1646215162328,"mc":[{"id":"1.195453621","rc":[{"atl":[[29,3.23]],"id":6780934}],"con":true,"img":false}]}
{"op":"mcm","clk":"5348186285","pt":1646215163826,"mc":[{"id":"1.195453621","rc":[{"atb":[[9.2,0]],"id":6780934}],"con":true,"img":false}]}
{"op":"mcm","clk":"5348186294","pt":1646215163930,"mc":[{"id":"1.195453621","rc":[{"atb":[[9.6,3.47]],"id":6780934}],"con":true,"img":false}]}
{"op":"mcm","clk":"5348186436","pt":1646215165640,"mc":[{"id":"1.195453621","rc":[{"atb":[[9.4,0]],"id":6780934}],"con":true,"img":false}]}
{"op":"mcm","clk":"5348186934","pt":1646215172327,"mc":[{"id":"1.195453621","rc":[{"atl":[[32,5.65],[34,2.65],[38,3.6],[42,0]],"id":6780934}],"con":true,"img":false}]}
{"op":"mcm","clk":"5348187156","pt":1646215175763,"mc":[{"id":"1.195453621","rc":[{"atb":[[9.6,0]],"id":6780934}],"con":true,"img":false}]}
{"op":"mcm","clk":"5348187162","pt":1646215175821,"mc":[{"id":"1.195453621","rc":[{"atb":[[9,3.47]],"id":6780934}],"con":true,"img":false}]}
{"op":"mcm","clk":"5348187167","pt":1646215175927,"mc":[{"id":"1.195453621","rc":[{"atb":[[8.2,7.52],[8.8,0]],"id":6780934}],"con":true,"img":false}]}
{"op":"mcm","clk":"5348187536","pt":1646215182352,"mc":[{"id":"1.195453621","rc":[{"atl":[[36,3.51]],"id":6780934}],"con":true,"img":false}]}
{"op":"mcm","clk":"5348187553","pt":1646215182556,"mc":[{"id":"1.195453621","rc":[{"atl":[[34,0]],"id":6780934}],"con":true,"img":false}]}
{"op":"mcm","clk":"5348187561","pt":1646215182665,"mc":[{"id":"1.195453621","rc":[{"atl":[[28,2.65]],"id":6780934}],"con":true,"img":false}]}
{"op":"mcm","clk":"5348187872","pt":1646215187737,"mc":[{"id":"1.195453621","rc":[{"atb":[[9,0]],"id":6780934},{"spn":7.5,"spf":1.0,"id":6780934}],"con":true,"img":false}]}
{"op":"mcm","clk":"5348187879","pt":1646215187846,"mc":[{"id":"1.195453621","rc":[{"atb":[[8,9.16],[8.2,0.37],[8.4,3.66]],"id":6780934}],"con":true,"img":false}]}
{"op":"mcm","clk":"5348187891","pt":1646215188052,"mc":[{"id":"1.195453621","rc":[{"atl":[[26,1],[27,0]],"id":6780934}],"con":true,"img":false}]}
{"op":"mcm","clk":"5348187909","pt":1646215188462,"mc":[{"id":"1.195453621","rc":[{"atb":[[7.4,0]],"id":6780934}],"con":true,"img":false}]}
{"op":"mcm","clk":"5348187920","pt":1646215188575,"mc":[{"id":"1.195453621","rc":[{"atb":[[8.4,4.89]],"id":6780934}],"con":true,"img":false}]}
{"op":"mcm","clk":"5348187964","pt":1646215189244,"mc":[{"id":"1.195453621","rc":[{"atb":[[8.6,2.5]],"id":6780934}],"con":true,"img":false}]}
{"op":"mcm","clk":"5348187978","pt":1646215189653,"mc":[{"id":"1.195453621","rc":[{"atb":[[8.4,3.66]],"id":6780934}],"con":true,"img":false}]}
{"op":"mcm","clk":"5348187981","pt":1646215189757,"mc":[{"id":"1.195453621","rc":[{"atb":[[8.6,3.72]],"id":6780934}],"con":true,"img":false}]}
{"op":"mcm","clk":"5348188201","pt":1646215193599,"mc":[{"id":"1.195453621","rc":[{"atb":[[8,1.44],[8.6,7.39]],"id":6780934}],"con":true,"img":false}]}
{"op":"mcm","clk":"5348188217","pt":1646215193801,"mc":[{"id":"1.195453621","rc":[{"atb":[[8.6,6.17]],"id":6780934}],"con":true,"img":false}]}
{"op":"mcm","clk":"5348188224","pt":1646215193857,"mc":[{"id":"1.195453621","rc":[{"atb":[[1.02,1.22]],"id":6780934}],"con":true,"img":false}]}
{"op":"mcm","clk":"5348188858","pt":1646215201564,"mc":[{"id":"1.195453621","rc":[{"atl":[[26,0.89]],"id":6780934},{"trd":[[26,0.22]],"ltp":26.0,"tv":0.22,"id":6780934}],"con":true,"img":false}]}
{"op":"mcm","clk":"5348188891","pt":1646215201783,"mc":[{"id":"1.195453621","rc":[{"atl":[[32,3.27],[36,0],[26,0],[29,1.47]],"id":6780934}],"con":true,"img":false}]}
{"op":"mcm","clk":"5348188919","pt":1646215202111,"mc":[{"id":"1.195453621","rc":[{"atl":[[28,0]],"id":6780934}],"con":true,"img":false}]}
{"op":"mcm","clk":"5348188932","pt":1646215202185,"mc":[{"id":"1.195453621","rc":[{"atb":[[8.8,1.55]],"id":6780934}],"con":true,"img":false}]}
{"op":"mcm","clk":"5348188949","pt":1646215202303,"mc":[{"id":"1.195453621","rc":[{"atl":[[1000,2.65]],"id":6780934}],"con":true,"img":false}]}
{"op":"mcm","clk":"5348189033","pt":1646215203008,"mc":[{"id":"1.195453621","rc":[{"atl":[[2.76,0]],"id":36463352}],"con":true,"img":false}]}
{"op":"mcm","clk":"5348189063","pt":1646215203161,"mc":[{"id":"1.195453621","rc":[{"atl":[[3.2,4.08]],"id":36463352}],"con":true,"img":false}]}
{"op":"mcm","clk":"5348189115","pt":1646215203684,"mc":[{"id":"1.195453621","rc":[{"atl":[[3.15,6.53]],"id":36463352}],"con":true,"img":false}]}
{"op":"mcm","clk":"5348189124","pt":1646215203771,"mc":[{"id":"1.195453621","rc":[{"atb":[[2.38,3.2]],"id":36463352},{"atb":[[8.6,3.67]],"id":6780934},{"atl":[[32,0]],"id":6780934}],"con":true,"img":false}]}
{"op":"mcm","clk":"5348189131","pt":1646215203875,"mc":[{"id":"1.195453621","rc":[{"atl":[[36,3.27]],"id":6780934}],"con":true,"img":false}]}
{"op":"mcm","clk":"5348189288","pt":1646215205605,"mc":[{"id":"1.195453621","rc":[{"atl":[[3.1,5.44]],"id":36463352}],"con":true,"img":false}]}
{"op":"mcm","clk":"5348189324","pt":1646215205967,"mc":[{"id":"1.195453621","rc":[{"atl":[[3.2,0]],"id":36463352}],"con":true,"img":false}]}
{"op":"mcm","clk":"5348189341","pt":1646215206213,"mc":[{"id":"1.195453621","rc":[{"atl":[[3.05,4.28]],"id":36463352}],"con":true,"img":false}]}
{"op":"mcm","clk":"5348189375","pt":1646215206500,"mc":[{"id":"1.195453621","rc":[{"atb":[[9,2.5]],"id":6780934}],"con":true,"img":false}]}
{"op":"mcm","clk":"5348189444","pt":1646215207296,"mc":[{"id":"1.195453621","rc":[{"atb":[[8.8,0]],"id":6780934}],"con":true,"img":false}]}
{"op":"mcm","clk":"5348189454","pt":1646215207405,"mc":[{"id":"1.195453621","rc":[{"atb":[[9,4.05]],"id":6780934}],"con":true,"img":false}]}
{"op":"mcm","clk":"5348189482","pt":1646215207669,"mc":[{"id":"1.195453621","rc":[{"atl":[[32,1.57],[36,5.36],[40,3.13],[29,2.47]],"id":6780934}],"con":true,"img":false}]}
{"op":"mcm","clk":"5348189721","pt":1646215210987,"mc":[{"id":"1.195453621","rc":[{"atb":[[8.6,0],[8.8,8.12]],"id":6780934}],"con":true,"img":false}]}
{"op":"mcm","clk":"5348189791","pt":1646215211782,"mc":[{"id":"1.195453621","rc":[{"atb":[[8.4,0.19]],"id":6780934}],"con":true,"img":false}]}
{"op":"mcm","clk":"5348189798","pt":1646215211885,"mc":[{"id":"1.195453621","rc":[{"atb":[[9.2,3.47]],"id":6780934}],"con":true,"img":false}]}
{"op":"mcm","clk":"5348189835","pt":1646215212500,"mc":[{"id":"1.195453621","rc":[{"atb":[[9,2.5]],"id":6780934}],"con":true,"img":false}]}
{"op":"mcm","clk":"5348189843","pt":1646215212603,"mc":[{"id":"1.195453621","rc":[{"atb":[[9.4,1.55]],"id":6780934}],"con":true,"img":false}]}
{"op":"mcm","clk":"5348189850","pt":1646215212706,"mc":[{"id":"1.195453621","rc":[{"atl":[[29,1.47],[30,1]],"id":6780934}],"con":true,"img":false}]}
{"op":"mcm","clk":"5348189883","pt":1646215213184,"mc":[{"id":"1.195453621","rc":[{"atb":[[9,0]],"id":6780934}],"con":true,"img":false}]}
{"op":"mcm","clk":"5348190094","pt":1646215215683,"mc":[{"id":"1.195453621","rc":[{"atb":[[9.6,2.5]],"id":6780934}],"con":true,"img":false}]}
{"op":"mcm","clk":"5348190131","pt":1646215216099,"mc":[{"id":"1.195453621","rc":[{"atb":[[9.4,0]],"id":6780934}],"con":true,"img":false}]}
{"op":"mcm","clk":"5348190143","pt":1646215216202,"mc":[{"id":"1.195453621","rc":[{"atl":[[3.15,0]],"id":36463352},{"atb":[[9.6,4.05]],"id":6780934}],"con":true,"img":false}]}
{"op":"mcm","clk":"5348190235","pt":1646215216989,"mc":[{"id":"1.195453621","rc":[{"atl":[[3,6.53]],"id":36463352}],"con":true,"img":false}]}
{"op":"mcm","clk":"5348190306","pt":1646215217817,"mc":[{"id":"1.195453621","rc":[{"atl":[[3.1,0]],"id":36463352}],"con":true,"img":false}]}
{"op":"mcm","clk":"5348190332","pt":1646215218139,"mc":[{"id":"1.195453621","rc":[{"atl":[[3.05,0]],"id":36463352}],"con":true,"img":false}]}
{"op":"mcm","clk":"5348190354","pt":1646215218287,"mc":[{"id":"1.195453621","rc":[{"atl":[[2.98,4.38]],"id":36463352}],"con":true,"img":false}]}
{"op":"mcm","clk":"5348190363","pt":1646215218439,"mc":[{"id":"1.195453621","rc":[{"atb":[[2.38,0.7]],"id":36463352}],"con":true,"img":false}]}
{"op":"mcm","clk":"5348190408","pt":1646215219070,"mc":[{"id":"1.195453621","rc":[{"atl":[[1000,0]],"id":6780934}],"con":true,"img":false}]}
{"op":"mcm","clk":"5348190423","pt":1646215219250,"mc":[{"id":"1.195453621","rc":[{"atl":[[34,2.65]],"id":6780934}],"con":true,"img":false}]}
{"op":"mcm","clk":"5348190494","pt":1646215220303,"mc":[{"id":"1.195453621","rc":[{"atl":[[2.96,5.44]],"id":36463352}],"con":true,"img":false}]}
{"op":"mcm","clk":"5348190554","pt":1646215221096,"mc":[{"id":"1.195453621","rc":[{"atl":[[2.98,0]],"id":36463352}],"con":true,"img":false}]}
{"op":"mcm","clk":"5348190561","pt":1646215221199,"mc":[{"id":"1.195453621","rc":[{"atl":[[2.94,4.44]],"id":36463352}],"con":true,"img":false}]}
{"op":"mcm","clk":"5348190684","pt":1646215222704,"mc":[{"id":"1.195453621","rc":[{"atl":[[34,4.13]],"id":6780934}],"con":true,"img":false}]}
{"op":"mcm","clk":"5348191243","pt":1646215229539,"mc":[{"id":"1.195453621","rc":[{"atl":[[3,0]],"id":36463352}],"con":true,"img":false}]}
{"op":"mcm","clk":"5348191303","pt":1646215230321,"mc":[{"id":"1.195453621","rc":[{"atl":[[2.92,6.53]],"id":36463352}],"con":true,"img":false}]}
{"op":"mcm","clk":"5348191323","pt":1646215230646,"mc":[{"id":"1.195453621","rc":[{"atl":[[32,0],[36,3.27],[40,0]],"id":6780934}],"con":true,"img":false}]}
{"op":"mcm","clk":"5348191362","pt":1646215231148,"mc":[{"id":"1.195453621","rc":[{"atl":[[34,1.48]],"id":6780934}],"con":true,"img":false}]}
{"op":"mcm","clk":"5348191370","pt":1646215231255,"mc":[{"id":"1.195453621","rc":[{"atl":[[1000,2.65]],"id":6780934}],"con":true,"img":false}]}
{"op":"mcm","clk":"5348191493","pt":1646215232558,"mc":[{"id":"1.195453621","rc":[{"atl":[[2.96,0]],"id":36463352}],"con":true,"img":false}]}
{"op":"mcm","clk":"5348191511","pt":1646215232720,"mc":[{"id":"1.195453621","rc":[{"atl":[[38,5.58]],"id":6780934}],"con":true,"img":false}]}
{"op":"mcm","clk":"5348191530","pt":1646215233116,"mc":[{"id":"1.195453621","rc":[{"atl":[[2.94,0]],"id":36463352}],"con":true,"img":false}]}
{"op":"mcm","clk":"5348191538","pt":1646215233220,"mc":[{"id":"1.195453621","rc":[{"atl":[[2.9,4.5]],"id":36463352}],"con":true,"img":false}]}
{"op":"mcm","clk":"5348191579","pt":1646215233734,"mc":[{"id":"1.195453621","rc":[{"atb":[[9.2,0]],"id":6780934}],"con":true,"img":false}]}
{"op":"mcm","clk":"5348191590","pt":1646215233840,"mc":[{"id":"1.195453621","rc":[{"atb":[[9.8,3.47]],"id":6780934}],"con":true,"img":false}]}
{"op":"mcm","clk":"5348191620","pt":1646215234417,"mc":[{"id":"1.195453621","rc":[{"atb":[[9.6,1.55]],"id":6780934}],"con":true,"img":false}]}
{"op":"mcm","clk":"5348191626","pt":1646215234521,"mc":[{"id":"1.195453621","rc":[{"atl":[[2.88,5.44]],"id":36463352}],"con":true,"img":false}]}
{"op":"mcm","clk":"5348191678","pt":1646215235241,"mc":[{"id":"1.195453621","rc":[{"atb":[[9.6,0]],"id":6780934}],"con":true,"img":false}]}
{"op":"mcm","clk":"5348191695","pt":1646215235344,"mc":[{"id":"1.195453621","rc":[{"atb":[[1.01,1.55]],"id":6780934}],"con":true,"img":false}]}
{"op":"mcm","clk":"5348191778","pt":1646215236024,"mc":[{"id":"1.195453621","rc":[{"atl":[[2.9,0]],"id":36463352}],"con":true,"img":false}]}
{"op":"mcm","clk":"5348191792","pt":1646215236231,"mc":[{"id":"1.195453621","rc":[{"atl":[[2.86,4.56]],"id":36463352}],"con":true,"img":false}]}
{"op":"mcm","clk":"5348192348","pt":1646215242780,"mc":[{"id":"1.195453621","rc":[{"atl":[[2.92,0]],"id":36463352},{"atl":[[42,2.98]],"id":6780934}],"con":true,"img":false}]}
{"op":"mcm","clk":"5348192412","pt":1646215243560,"mc":[{"id":"1.195453621","rc":[{"atl":[[2.84,6.53]],"id":36463352}],"con":true,"img":false}]}
{"op":"mcm","clk":"5348192463","pt":1646215244283,"mc":[{"id":"1.195453621","rc":[{"atb":[[9.8,0]],"id":6780934}],"con":true,"img":false}]}
{"op":"mcm","clk":"5348192470","pt":1646215244392,"mc":[{"id":"1.195453621","rc":[{"atb":[[9,3.47]],"id":6780934}],"con":true,"img":false}]}
{"op":"mcm","clk":"5348192479","pt":1646215244453,"mc":[{"id":"1.195453621","rc":[{"atb":[[8.2,8.68],[8.8,0]],"id":6780934}],"con":true,"img":false}]}
{"op":"mcm","clk":"5348192543","pt":1646215245169,"mc":[{"id":"1.195453621","rc":[{"atl":[[2.86,0]],"id":36463352}],"con":true,"img":false}]}
{"op":"mcm","clk":"5348192551","pt":1646215245274,"mc":[{"id":"1.195453621","rc":[{"atl":[[2.82,4.63]],"id":36463352}],"con":true,"img":false}]}
{"op":"mcm","clk":"5348192675","pt":1646215246776,"mc":[{"id":"1.195453621","rc":[{"atl":[[2.88,0]],"id":36463352}],"con":true,"img":false}]}
{"op":"mcm","clk":"5348192854","pt":1646215249471,"mc":[{"id":"1.195453621","rc":[{"atl":[[2.8,5.44]],"id":36463352},{"spn":7.74,"spf":1.0,"id":6780934}],"con":true,"img":false}]}
{"op":"mcm","clk":"5348192966","pt":1646215251180,"mc":[{"id":"1.195453621","rc":[{"atl":[[2.82,0]],"id":36463352}],"con":true,"img":false}]}
{"op":"mcm","clk":"5348192977","pt":1646215251390,"mc":[{"id":"1.195453621","rc":[{"atl":[[2.78,4.69]],"id":36463352}],"con":true,"img":false}]}
{"op":"mcm","clk":"5348193304","pt":1646215255863,"mc":[{"id":"1.195453621","rc":[{"atb":[[9,0]],"id":6780934}],"con":true,"img":false}]}
{"op":"mcm","clk":"5348193310","pt":1646215255969,"mc":[{"id":"1.195453621","rc":[{"atb":[[8.4,3.66]],"id":6780934}],"con":true,"img":false}]}
{"op":"mcm","clk":"5348193318","pt":1646215256071,"mc":[{"id":"1.195453621","rc":[{"atl":[[2.84,0]],"id":36463352},{"atb":[[8,10.32],[8.2,0.37]],"id":6780934}],"con":true,"img":false}]}
{"op":"mcm","clk":"5348193328","pt":1646215256276,"mc":[{"id":"1.195453621","rc":[{"atl":[[29,2.47],[30,0]],"id":6780934}],"con":true,"img":false}]}
{"op":"mcm","clk":"5348193335","pt":1646215256382,"mc":[{"id":"1.195453621","rc":[{"atb":[[1.02,0]],"id":6780934}],"con":true,"img":false}]}
{"op":"mcm","clk":"5348193339","pt":1646215256481,"mc":[{"id":"1.195453621","rc":[{"atb":[[8.4,4.89]],"id":6780934}],"con":true,"img":false}]}
{"op":"mcm","clk":"5348193366","pt":1646215256748,"mc":[{"id":"1.195453621","rc":[{"atl":[[2.76,6.53]],"id":36463352}],"con":true,"img":false}]}
{"op":"mcm","clk":"5348193384","pt":1646215257052,"mc":[{"id":"1.195453621","rc":[{"atl":[[2.78,0]],"id":36463352},{"atb":[[8.6,2.5]],"id":6780934}],"con":true,"img":false}]}
{"op":"mcm","clk":"5348193392","pt":1646215257165,"mc":[{"id":"1.195453621","rc":[{"atl":[[2.74,4.76]],"id":36463352}],"con":true,"img":false}]}
{"op":"mcm","clk":"5348193415","pt":1646215257362,"mc":[{"id":"1.195453621","rc":[{"atb":[[8.4,3.66]],"id":6780934}],"con":true,"img":false}]}
{"op":"mcm","clk":"5348193419","pt":1646215257466,"mc":[{"id":"1.195453621","rc":[{"atb":[[8.6,3.72]],"id":6780934}],"con":true,"img":false}]}
{"op":"mcm","clk":"5348193556","pt":1646215259790,"mc":[{"id":"1.195453621","rc":[{"atl":[[36,0]],"id":6780934}],"con":true,"img":false}]}
{"op":"mcm","clk":"5348193560","pt":1646215259888,"mc":[{"id":"1.195453621","rc":[{"atl":[[32,3.27]],"id":6780934}],"con":true,"img":false}]}
{"op":"mcm","clk":"5348193676","pt":1646215261353,"mc":[{"id":"1.195453621","rc":[{"atb":[[8.6,7.39]],"id":6780934}],"con":true,"img":false}]}
{"op":"mcm","clk":"5348193683","pt":1646215261458,"mc":[{"id":"1.195453621","rc":[{"atb":[[8,1.43]],"id":6780934}],"con":true,"img":false}]}
{"op":"mcm","clk":"5348193699","pt":1646215261676,"mc":[{"id":"1.195453621","rc":[{"atl":[[2.8,0]],"id":36463352}],"con":true,"img":false}]}
{"op":"mcm","clk":"5348193722","pt":1646215262080,"mc":[{"id":"1.195453621","rc":[{"atb":[[8.6,6.17]],"id":6780934}],"con":true,"img":false}]}
{"op":"mcm","clk":"5348193730","pt":1646215262185,"mc":[{"id":"1.195453621","rc":[{"atb":[[1.02,1.22]],"id":6780934}],"con":true,"img":false}]}
{"op":"mcm","clk":"5348194303","pt":1646215269681,"mc":[{"id":"1.195453621","rc":[{"atl":[[2.76,0]],"id":36463352}],"con":true,"img":false}]}
{"op":"mcm","clk":"5348194904","pt":1646215277777,"mc":[{"id":"1.195453621","rc":[{"atb":[[8.4,0.19]],"id":6780934}],"con":true,"img":false}]}
{"op":"mcm","clk":"5348194911","pt":1646215277880,"mc":[{"id":"1.195453621","rc":[{"atb":[[8.8,3.47]],"id":6780934}],"con":true,"img":false}]}
{"op":"mcm","clk":"5348194951","pt":1646215278710,"mc":[{"id":"1.195453621","rc":[{"atb":[[8.6,3.67]],"id":6780934}],"con":true,"img":false}]}
{"op":"mcm","clk":"5348195066","pt":1646215280419,"mc":[{"id":"1.195453621","rc":[{"atb":[[9,2.5]],"id":6780934}],"con":true,"img":false}]}
{"op":"mcm","clk":"5348196435","pt":1646215301803,"mc":[{"id":"1.195453621","rc":[{"atb":[[8.8,0]],"id":6780934}],"con":true,"img":false}]}
{"op":"mcm","clk":"5348196439","pt":1646215301904,"mc":[{"id":"1.195453621","rc":[{"atb":[[9.2,3.47]],"id":6780934}],"con":true,"img":false}]}
{"op":"mcm","clk":"5348196451","pt":1646215302113,"mc":[{"id":"1.195453621","rc":[{"atb":[[8.6,0],[8.8,5.98]],"id":6780934},{"atl":[[27,1],[29,1.47]],"id":6780934}],"con":true,"img":false}]}
{"op":"mcm","clk":"5348196566","pt":1646215303713,"mc":[{"id":"1.195453621","rc":[{"atb":[[9,0]],"id":6780934}],"con":true,"img":false}]}
{"op":"mcm","clk":"5348196736","pt":1646215306243,"mc":[{"id":"1.195453621","rc":[{"atb":[[9.4,2.5]],"id":6780934}],"con":true,"img":false}]}
{"op":"mcm","clk":"5348197165","pt":1646215312142,"mc":[{"id":"1.195453621","rc":[{"atl":[[29,3.21]],"id":6780934},{"spn":7.99,"spf":1.0,"id":6780934}],"con":true,"img":false}]}
{"op":"mcm","clk":"5348197196","pt":1646215312457,"mc":[{"id":"1.195453621","rc":[{"atl":[[34,0],[38,3.6],[42,0]],"id":6780934}],"con":true,"img":false}]}
{"op":"mcm","clk":"5348197292","pt":1646215313842,"mc":[{"id":"1.195453621","rc":[{"atl":[[32,0]],"id":6780934}],"con":true,"img":false}]}
{"op":"mcm","clk":"5348197299","pt":1646215313945,"mc":[{"id":"1.195453621","rc":[{"atl":[[36,3.27]],"id":6780934}],"con":true,"img":false}]}
{"op":"mcm","clk":"5348197829","pt":1646215321867,"mc":[{"id":"1.195453621","rc":[{"atb":[[9.2,0]],"id":6780934}],"con":true,"img":false}]}
{"op":"mcm","clk":"5348197835","pt":1646215321972,"mc":[{"id":"1.195453621","rc":[{"atb":[[9.6,3.47]],"id":6780934}],"con":true,"img":false}]}
{"op":"mcm","clk":"5348197853","pt":1646215322123,"mc":[{"id":"1.195453621","rc":[{"atl":[[32,2.36]],"id":6780934}],"con":true,"img":false}]}
{"op":"mcm","clk":"5348197978","pt":1646215323838,"mc":[{"id":"1.195453621","rc":[{"atb":[[9.4,0]],"id":6780934}],"con":true,"img":false}]}
{"op":"mcm","clk":"5348198572","pt":1646215332166,"mc":[{"id":"1.195453621","rc":[{"atl":[[36,6.76]],"id":6780934}],"con":true,"img":false}]}
{"op":"mcm","clk":"5348198813","pt":1646215335867,"mc":[{"id":"1.195453621","rc":[{"atb":[[9.6,0]],"id":6780934}],"con":true,"img":false}]}
{"op":"mcm","clk":"5348198821","pt":1646215335971,"mc":[{"id":"1.195453621","rc":[{"atb":[[9,3.47]],"id":6780934}],"con":true,"img":false}]}
{"op":"mcm","clk":"5348198828","pt":1646215336077,"mc":[{"id":"1.195453621","rc":[{"atb":[[8.2,6.54],[8.8,0]],"id":6780934}],"con":true,"img":false}]}
{"op":"mcm","clk":"5348198836","pt":1646215336177,"mc":[{"id":"1.195453621","rc":[{"atb":[[8.8,6.96]],"id":6780934}],"con":true,"img":false}]}
{"op":"mcm","clk":"5348198839","pt":1646215336278,"mc":[{"id":"1.195453621","rc":[{"atb":[[8.2,0.37]],"id":6780934}],"con":true,"img":false}]}
{"op":"mcm","clk":"5348198950","pt":1646215337686,"mc":[{"id":"1.195453621","rc":[{"atb":[[9.2,2.5]],"id":6780934}],"con":true,"img":false}]}
{"op":"mcm","clk":"5348199001","pt":1646215338362,"mc":[{"id":"1.195453621","rc":[{"atl":[[26,1]],"id":6780934}],"con":true,"img":false}]}
{"op":"mcm","clk":"5348199011","pt":1646215338469,"mc":[{"id":"1.195453621","rc":[{"atl":[[27,0]],"id":6780934}],"con":true,"img":false}]}
{"op":"mcm","clk":"5348200529","pt":1646215359926,"mc":[{"id":"1.195453621","rc":[{"atb":[[9,0]],"id":6780934}],"con":true,"img":false}]}
{"op":"mcm","clk":"5348200540","pt":1646215359981,"mc":[{"id":"1.195453621","rc":[{"atb":[[9.4,3.47]],"id":6780934}],"con":true,"img":false}]}
{"op":"mcm","clk":"5348200553","pt":1646215360186,"mc":[{"id":"1.195453621","rc":[{"atl":[[27,1]],"id":6780934}],"con":true,"img":false}]}
{"op":"mcm","clk":"5348200561","pt":1646215360288,"mc":[{"id":"1.195453621","rc":[{"atl":[[26,0]],"id":6780934}],"con":true,"img":false}]}
{"op":"mcm","clk":"5348200670","pt":1646215362301,"mc":[{"id":"1.195453621","rc":[{"atb":[[9.2,0]],"id":6780934}],"con":true,"img":false}]}
{"op":"mcm","clk":"5348200807","pt":1646215364886,"mc":[{"id":"1.195453621","rc":[{"atb":[[9.6,2.5]],"id":6780934}],"con":true,"img":false}]}
{"op":"mcm","clk":"5348201741","pt":1646215379832,"mc":[{"id":"1.195453621","rc":[{"atb":[[9.4,0]],"id":6780934},{"spn":7.83,"spf":1.0,"id":6780934}],"con":true,"img":false}]}
{"op":"mcm","clk":"5348201748","pt":1646215379938,"mc":[{"id":"1.195453621","rc":[{"atb":[[9.8,3.47]],"id":6780934}],"con":true,"img":false}]}
{"op":"mcm","clk":"5348201808","pt":1646215380710,"mc":[{"id":"1.195453621","rc":[{"atb":[[9.6,0]],"id":6780934}],"con":true,"img":false}]}
{"op":"mcm","clk":"5348202006","pt":1646215383414,"mc":[{"id":"1.195453621","rc":[{"atl":[[2.74,0]],"id":36463352}],"con":true,"img":false}]}
{"op":"mcm","clk":"5348202021","pt":1646215383618,"mc":[{"id":"1.195453621","rc":[{"atl":[[3.2,4.08]],"id":36463352}],"con":true,"img":false}]}
{"op":"mcm","clk":"5348202048","pt":1646215383929,"mc":[{"id":"1.195453621","rc":[{"atl":[[3.25,12.25]],"id":36463352}],"con":true,"img":false}]}
{"op":"mcm","clk":"5348202053","pt":1646215384032,"mc":[{"id":"1.195453621","rc":[{"atl":[[3.2,10.62]],"id":36463352}],"con":true,"img":false}]}
{"op":"mcm","clk":"5348202143","pt":1646215385333,"mc":[{"id":"1.195453621","rc":[{"atb":[[2.38,3.2]],"id":36463352}],"con":true,"img":false}]}
{"op":"mcm","clk":"5348202209","pt":1646215386320,"mc":[{"id":"1.195453621","rc":[{"atl":[[3.2,6.53]],"id":36463352}],"con":true,"img":false}]}
{"op":"mcm","clk":"5348202223","pt":1646215386523,"mc":[{"id":"1.195453621","rc":[{"atl":[[3.15,4.15]],"id":36463352}],"con":true,"img":false}]}
{"op":"mcm","clk":"5348202243","pt":1646215386937,"mc":[{"id":"1.195453621","rc":[{"atl":[[3.1,5.44]],"id":36463352}],"con":true,"img":false}]}
{"op":"mcm","clk":"5348202316","pt":1646215387785,"mc":[{"id":"1.195453621","rc":[{"atl":[[3.25,8.89]],"id":36463352}],"con":true,"img":false}]}
{"op":"mcm","clk":"5348202486","pt":1646215389429,"mc":[{"id":"1.195453621","rc":[{"atl":[[3.15,0]],"id":36463352}],"con":true,"img":false}]}
{"op":"mcm","clk":"5348202500","pt":1646215389640,"mc":[{"id":"1.195453621","rc":[{"atl":[[3.05,4.28]],"id":36463352}],"con":true,"img":false}]}
{"op":"mcm","clk":"5348202516","pt":1646215389751,"mc":[{"id":"1.195453621","rc":[{"atb":[[9.8,0]],"id":6780934}],"con":true,"img":false}]}
{"op":"mcm","clk":"5348202525","pt":1646215389841,"mc":[{"id":"1.195453621","rc":[{"atb":[[9,3.47]],"id":6780934}],"con":true,"img":false}]}
{"op":"mcm","clk":"5348202532","pt":1646215389957,"mc":[{"id":"1.195453621","rc":[{"atb":[[8.2,7.52],[8.8,0]],"id":6780934}],"con":true,"img":false}]}
{"op":"mcm","clk":"5348202540","pt":1646215390051,"mc":[{"id":"1.195453621","rc":[{"atb":[[8.2,0.37],[8.8,6.96]],"id":6780934}],"con":true,"img":false}]}
{"op":"mcm","clk":"5348202591","pt":1646215390624,"mc":[{"id":"1.195453621","rc":[{"atb":[[9.2,2.5]],"id":6780934}],"con":true,"img":false}]}
{"op":"mcm","clk":"5348202679","pt":1646215390833,"mc":[{"id":"1.195453621","rc":[{"atb":[[8.6,6.96],[8.8,0]],"id":6780934},{"atl":[[26,1]],"id":6780934}],"con":true,"img":false}]}
{"op":"mcm","clk":"5348202686","pt":1646215390941,"mc":[{"id":"1.195453621","rc":[{"atl":[[27,0]],"id":6780934}],"con":true,"img":false}]}
{"op":"mcm","clk":"5348203135","pt":1646215396565,"mc":[{"id":"1.195453621","rc":[{"atl":[[3.2,0]],"id":36463352}],"con":true,"img":false}]}
{"op":"mcm","clk":"5348203180","pt":1646215397251,"mc":[{"id":"1.195453621","rc":[{"atl":[[3,6.53]],"id":36463352}],"con":true,"img":false}]}
{"op":"mcm","clk":"5348203267","pt":1646215398443,"mc":[{"id":"1.195453621","rc":[{"atl":[[3.05,0]],"id":36463352}],"con":true,"img":false}]}
{"op":"mcm","clk":"5348203287","pt":1646215398652,"mc":[{"id":"1.195453621","rc":[{"atl":[[2.98,4.38]],"id":36463352}],"con":true,"img":false}]}
{"op":"mcm","clk":"5348203296","pt":1646215398762,"mc":[{"id":"1.195453621","rc":[{"atb":[[2.38,0.7]],"id":36463352}],"con":true,"img":false}]}
{"op":"mcm","clk":"5348203330","pt":1646215399272,"mc":[{"id":"1.195453621","rc":[{"atl":[[3.1,0]],"id":36463352}],"con":true,"img":false}]}
{"op":"mcm","clk":"5348203547","pt":1646215402086,"mc":[{"id":"1.195453621","rc":[{"atl":[[2.96,5.44]],"id":36463352}],"con":true,"img":false}]}
{"op":"mcm","clk":"5348203718","pt":1646215404383,"mc":[{"id":"1.195453621","rc":[{"atl":[[2.98,0]],"id":36463352}],"con":true,"img":false}]}
{"op":"mcm","clk":"5348203725","pt":1646215404435,"mc":[{"id":"1.195453621","rc":[{"atl":[[2.94,4.44]],"id":36463352}],"con":true,"img":false}]}
{"op":"mcm","clk":"5348204104","pt":1646215409770,"mc":[{"id":"1.195453621","rc":[{"atl":[[3,0]],"id":36463352}],"con":true,"img":false}]}
{"op":"mcm","clk":"5348204158","pt":1646215410549,"mc":[{"id":"1.195453621","rc":[{"atl":[[2.92,6.53]],"id":36463352}],"con":true,"img":false}]}
{"op":"mcm","clk":"5348204267","pt":1646215411868,"mc":[{"id":"1.195453621","rc":[{"atb":[[9,0]],"id":6780934}],"con":true,"img":false}]}
{"op":"mcm","clk":"5348204278","pt":1646215411966,"mc":[{"id":"1.195453621","rc":[{"atb":[[9.4,3.47]],"id":6780934}],"con":true,"img":false}]}
{"op":"mcm","clk":"5348204405","pt":1646215412956,"mc":[{"id":"1.195453621","rc":[{"atb":[[9.2,0]],"id":6780934}],"con":true,"img":false}]}
{"op":"mcm","clk":"5348204434","pt":1646215413373,"mc":[{"id":"1.195453621","rc":[{"atl":[[2.94,0]],"id":36463352}],"con":true,"img":false}]}
{"op":"mcm","clk":"5348204448","pt":1646215413585,"mc":[{"id":"1.195453621","rc":[{"atl":[[2.9,4.5]],"id":36463352}],"con":true,"img":false}]}
{"op":"mcm","clk":"5348204545","pt":1646215414362,"mc":[{"id":"1.195453621","rc":[{"atl":[[2.96,0]],"id":36463352}],"con":true,"img":false}]}
{"op":"mcm","clk":"5348204754","pt":1646215417258,"mc":[{"id":"1.195453621","rc":[{"atl":[[2.88,5.44]],"id":36463352}],"con":true,"img":false}]}
{"op":"mcm","clk":"5348204770","pt":1646215417462,"mc":[{"id":"1.195453621","rc":[{"atb":[[8.6,0],[8.8,6.96]],"id":6780934}],"con":true,"img":false}]}
{"op":"mcm","clk":"5348204842","pt":1646215418361,"mc":[{"id":"1.195453621","rc":[{"atb":[[9.6,2.5]],"id":6780934}],"con":true,"img":false}]}
{"op":"mcm","clk":"5348204907","pt":1646215419391,"mc":[{"id":"1.195453621","rc":[{"atl":[[2.9,0]],"id":36463352}],"con":true,"img":false}]}
{"op":"mcm","clk":"5348204917","pt":1646215419498,"mc":[{"id":"1.195453621","rc":[{"atl":[[2.86,4.56]],"id":36463352}],"con":true,"img":false}]}
{"op":"mcm","clk":"5348205192","pt":1646215423078,"mc":[{"id":"1.195453621","rc":[{"atl":[[2.92,0]],"id":36463352}],"con":true,"img":false}]}
{"op":"mcm","clk":"5348205263","pt":1646215423874,"mc":[{"id":"1.195453621","rc":[{"atl":[[2.84,6.53]],"id":36463352}],"con":true,"img":false}]}
{"op":"mcm","clk":"5348205278","pt":1646215424070,"mc":[{"id":"1.195453621","rc":[{"atl":[[27,1]],"id":6780934}],"con":true,"img":false}]}
{"op":"mcm","clk":"5348205285","pt":1646215424177,"mc":[{"id":"1.195453621","rc":[{"atl":[[26,0]],"id":6780934}],"con":true,"img":false}]}
{"op":"mcm","clk":"5348205376","pt":1646215425380,"mc":[{"id":"1.195453621","rc":[{"atl":[[2.86,0]],"id":36463352}],"con":true,"img":false}]}
{"op":"mcm","clk":"5348205393","pt":1646215425589,"mc":[{"id":"1.195453621","rc":[{"atl":[[2.82,4.63]],"id":36463352}],"con":true,"img":false}]}
{"op":"mcm","clk":"5348205686","pt":1646215429570,"mc":[{"id":"1.195453621","rc":[{"atl":[[2.88,0]],"id":36463352}],"con":true,"img":false}]}
{"op":"mcm","clk":"5348205833","pt":1646215431616,"mc":[{"id":"1.195453621","rc":[{"atl":[[2.8,5.44]],"id":36463352}],"con":true,"img":false}]}
{"op":"mcm","clk":"5348205857","pt":1646215431879,"mc":[{"id":"1.195453621","rc":[{"atb":[[9.4,0]],"id":6780934}],"con":true,"img":false}]}
{"op":"mcm","clk":"5348205864","pt":1646215431982,"mc":[{"id":"1.195453621","rc":[{"atb":[[9.8,3.47]],"id":6780934}],"con":true,"img":false}]}
{"op":"mcm","clk":"5348205923","pt":1646215432708,"mc":[{"id":"1.195453621","rc":[{"atb":[[9.6,0]],"id":6780934}],"con":true,"img":false}]}
{"op":"mcm","clk":"5348206058","pt":1646215434383,"mc":[{"id":"1.195453621","rc":[{"atl":[[2.82,0]],"id":36463352}],"con":true,"img":false}]}
{"op":"mcm","clk":"5348206078","pt":1646215434589,"mc":[{"id":"1.195453621","rc":[{"atl":[[2.78,4.69]],"id":36463352}],"con":true,"img":false}]}
{"op":"mcm","clk":"5348206221","pt":1646215436418,"mc":[{"id":"1.195453621","rc":[{"atl":[[2.84,0]],"id":36463352}],"con":true,"img":false}]}
{"op":"mcm","clk":"5348206294","pt":1646215437212,"mc":[{"id":"1.195453621","rc":[{"atl":[[2.76,6.53]],"id":36463352}],"con":true,"img":false}]}
{"op":"mcm","clk":"5348206578","pt":1646215440392,"mc":[{"id":"1.195453621","rc":[{"atl":[[2.78,0]],"id":36463352},{"spn":7.93,"spf":1.0,"id":6780934}],"con":true,"img":false}]}
{"op":"mcm","clk":"5348206591","pt":1646215440605,"mc":[{"id":"1.195453621","rc":[{"atl":[[2.74,4.76]],"id":36463352}],"con":true,"img":false}]}
{"op":"mcm","clk":"5348206699","pt":1646215441803,"mc":[{"id":"1.195453621","rc":[{"atb":[[9.8,0]],"id":6780934}],"con":true,"img":false}]}
{"op":"mcm","clk":"5348206706","pt":1646215441909,"mc":[{"id":"1.195453621","rc":[{"atb":[[9,3.47]],"id":6780934}],"con":true,"img":false}]}
{"op":"mcm","clk":"5348206712","pt":1646215442014,"mc":[{"id":"1.195453621","rc":[{"atb":[[8.2,7.52],[8.8,0]],"id":6780934}],"con":true,"img":false}]}
{"op":"mcm","clk":"5348206725","pt":1646215442223,"mc":[{"id":"1.195453621","rc":[{"atb":[[8.2,0.37],[8.8,6.96]],"id":6780934}],"con":true,"img":false}]}
{"op":"mcm","clk":"5348206747","pt":1646215442533,"mc":[{"id":"1.195453621","rc":[{"atl":[[26,1],[27,0]],"id":6780934}],"con":true,"img":false}]}
{"op":"mcm","clk":"5348206795","pt":1646215443109,"mc":[{"id":"1.195453621","rc":[{"atb":[[9.2,2.5]],"id":6780934}],"con":true,"img":false}]}
{"op":"mcm","clk":"5348206850","pt":1646215443734,"mc":[{"id":"1.195453621","rc":[{"atl":[[2.8,0]],"id":36463352}],"con":true,"img":false}]}
{"op":"mcm","clk":"5348207160","pt":1646215447425,"mc":[{"id":"1.195453621","rc":[{"atb":[[8.6,6.96],[8.8,0]],"id":6780934}],"con":true,"img":false}]}
{"op":"mcm","clk":"5348207337","pt":1646215449613,"mc":[{"id":"1.195453621","rc":[{"atl":[[2.76,0]],"id":36463352}],"con":true,"img":false}]}
{"op":"mcm","clk":"5348208426","pt":1646215462354,"mc":[{"id":"1.195453621","rc":[{"atb":[[8.6,0],[8.8,5.98]],"id":6780934}],"con":true,"img":false}]}
{"op":"mcm","clk":"5348208555","pt":1646215463823,"mc":[{"id":"1.195453621","rc":[{"atb":[[9,0]],"id":6780934}],"con":true,"img":false}]}
{"op":"mcm","clk":"5348208563","pt":1646215463937,"mc":[{"id":"1.195453621","rc":[{"atb":[[9.4,3.47]],"id":6780934}],"con":true,"img":false}]}
{"op":"mcm","clk":"5348208645","pt":1646215464907,"mc":[{"id":"1.195453621","rc":[{"atb":[[9.2,0]],"id":6780934}],"con":true,"img":false}]}
{"op":"mcm","clk":"5348208732","pt":1646215466054,"mc":[{"id":"1.195453621","rc":[{"atb":[[9.6,2.5]],"id":6780934}],"con":true,"img":false}]}
{"op":"mcm","clk":"5348210069","pt":1646215481855,"mc":[{"id":"1.195453621","rc":[{"atb":[[9.4,0]],"id":6780934}],"con":true,"img":false}]}
{"op":"mcm","clk":"5348210077","pt":1646215481960,"mc":[{"id":"1.195453621","rc":[{"atb":[[9.8,3.47]],"id":6780934}],"con":true,"img":false}]}
{"op":"mcm","clk":"5348210096","pt":1646215482225,"mc":[{"id":"1.195453621","rc":[{"atl":[[26,0],[27,1]],"id":6780934}],"con":true,"img":false}]}
{"op":"mcm","clk":"5348210171","pt":1646215483266,"mc":[{"id":"1.195453621","rc":[{"atb":[[9.6,0]],"id":6780934}],"con":true,"img":false}]}
{"op":"mcm","clk":"5348211024","pt":1646215493767,"mc":[{"id":"1.195453621","rc":[{"atb":[[9.8,0]],"id":6780934}],"con":true,"img":false}]}
{"op":"mcm","clk":"5348211034","pt":1646215493871,"mc":[{"id":"1.195453621","rc":[{"atb":[[9,3.47]],"id":6780934}],"con":true,"img":false}]}
{"op":"mcm","clk":"5348211042","pt":1646215493972,"mc":[{"id":"1.195453621","rc":[{"atb":[[8.2,6.54],[8.8,0]],"id":6780934}],"con":true,"img":false}]}
{"op":"mcm","clk":"5348211050","pt":1646215494077,"mc":[{"id":"1.195453621","rc":[{"atl":[[27,0]],"id":6780934}],"con":true,"img":false}]}
{"op":"mcm","clk":"5348211053","pt":1646215494179,"mc":[{"id":"1.195453621","rc":[{"atb":[[8.2,0.37],[8.8,6.96]],"id":6780934},{"atl":[[26,1]],"id":6780934}],"con":true,"img":false}]}
{"op":"mcm","clk":"5348211168","pt":1646215495584,"mc":[{"id":"1.195453621","rc":[{"atb":[[9.2,2.5]],"id":6780934}],"con":true,"img":false}]}
{"op":"mcm","clk":"5348211190","pt":1646215495851,"mc":[{"id":"1.195453621","rc":[{"atb":[[1.01,0]],"id":6780934}],"con":true,"img":false}]}
{"op":"mcm","clk":"5348211194","pt":1646215495955,"mc":[{"id":"1.195453621","rc":[{"atb":[[9.2,4.05]],"id":6780934}],"con":true,"img":false}]}
{"op":"mcm","clk":"5348212786","pt":1646215515786,"mc":[{"id":"1.195453621","rc":[{"atb":[[9,0]],"id":6780934},{"spn":7.9,"spf":1.0,"id":6780934}],"con":true,"img":false}]}
{"op":"mcm","clk":"5348212795","pt":1646215515895,"mc":[{"id":"1.195453621","rc":[{"atb":[[9.4,3.47]],"id":6780934}],"con":true,"img":false}]}
{"op":"mcm","clk":"5348212813","pt":1646215516104,"mc":[{"id":"1.195453621","rc":[{"atl":[[26,0],[27,1]],"id":6780934}],"con":true,"img":false}]}
{"op":"mcm","clk":"5348212960","pt":1646215517894,"mc":[{"id":"1.195453621","rc":[{"atb":[[9.2,1.55]],"id":6780934}],"con":true,"img":false}]}
{"op":"mcm","clk":"5348213051","pt":1646215519186,"mc":[{"id":"1.195453621","rc":[{"atb":[[9.6,2.5]],"id":6780934}],"con":true,"img":false}]}
{"op":"mcm","clk":"5348214692","pt":1646215539816,"mc":[{"id":"1.195453621","rc":[{"atb":[[9.4,0]],"id":6780934}],"con":true,"img":false}]}
{"op":"mcm","clk":"5348214703","pt":1646215539923,"mc":[{"id":"1.195453621","rc":[{"atb":[[9.8,3.47]],"id":6780934}],"con":true,"img":false}]}
{"op":"mcm","clk":"5348214753","pt":1646215540548,"mc":[{"id":"1.195453621","rc":[{"atb":[[9.2,0]],"id":6780934}],"con":true,"img":false}]}
{"op":"mcm","clk":"5348214761","pt":1646215540652,"mc":[{"id":"1.195453621","rc":[{"atb":[[10,1.55]],"id":6780934}],"con":true,"img":false}]}
{"op":"mcm","clk":"5348214851","pt":1646215541855,"mc":[{"id":"1.195453621","rc":[{"atb":[[9.6,0]],"id":6780934}],"con":true,"img":false}]}
{"op":"mcm","clk":"5348214920","pt":1646215542646,"mc":[{"id":"1.195453621","rc":[{"atb":[[10,0]],"id":6780934}],"con":true,"img":false}]}
{"op":"mcm","clk":"5348214929","pt":1646215542748,"mc":[{"id":"1.195453621","rc":[{"atb":[[1.01,1.55],[10.5,2.08]],"id":6780934}],"con":true,"img":false}]}
{"op":"mcm","clk":"5348216896","pt":1646215563657,"mc":[{"id":"1.195453621","rc":[{"atl":[[2.74,0]],"id":36463352}],"con":true,"img":false}]}
{"op":"mcm","clk":"5348216907","pt":1646215563762,"mc":[{"id":"1.195453621","rc":[{"atl":[[3.2,4.08]],"id":36463352},{"atb":[[9.8,0]],"id":6780934}],"con":true,"img":false}]}
{"op":"mcm","clk":"5348216923","pt":1646215563970,"mc":[{"id":"1.195453621","rc":[{"atb":[[9,4.16],[8.8,0]],"id":6780934}],"con":true,"img":false}]}
{"op":"mcm","clk":"5348216933","pt":1646215564076,"mc":[{"id":"1.195453621","rc":[{"atb":[[1.01,0]],"id":6780934}],"con":true,"img":false}]}
{"op":"mcm","clk":"5348216943","pt":1646215564140,"mc":[{"id":"1.195453621","rc":[{"atb":[[9,5.71]],"id":6780934}],"con":true,"img":false}]}
{"op":"mcm","clk":"5348216967","pt":1646215564350,"mc":[{"id":"1.195453621","rc":[{"atl":[[3.15,6.53]],"id":36463352}],"con":true,"img":false}]}
{"op":"mcm","clk":"5348217036","pt":1646215564968,"mc":[{"id":"1.195453621","rc":[{"atb":[[2.38,3.2]],"id":36463352},{"atb":[[9,4.16]],"id":6780934}],"con":true,"img":false}]}
{"op":"mcm","clk":"5348217043","pt":1646215565070,"mc":[{"id":"1.195453621","rc":[{"atb":[[1.01,1.55]],"id":6780934}],"con":true,"img":false}]}
{"op":"mcm","clk":"5348217202","pt":1646215566651,"mc":[{"id":"1.195453621","rc":[{"atl":[[3.2,0]],"id":36463352}],"con":true,"img":false}]}
{"op":"mcm","clk":"5348217220","pt":1646215566856,"mc":[{"id":"1.195453621","rc":[{"atl":[[3.1,4.21]],"id":36463352}],"con":true,"img":false}]}
{"op":"mcm","clk":"5348217275","pt":1646215567544,"mc":[{"id":"1.195453621","rc":[{"atl":[[3.05,5.44]],"id":36463352}],"con":true,"img":false}]}
{"op":"mcm","clk":"5348217465","pt":1646215569750,"mc":[{"id":"1.195453621","rc":[{"atl":[[3.1,0]],"id":36463352}],"con":true,"img":false}]}
{"op":"mcm","clk":"5348217479","pt":1646215569952,"mc":[{"id":"1.195453621","rc":[{"atl":[[3,4.36]],"id":36463352}],"con":true,"img":false}]}
{"op":"mcm","clk":"5348217559","pt":1646215570983,"mc":[{"id":"1.195453621","rc":[{"atb":[[2.38,0.7]],"id":36463352}],"con":true,"img":false}]}
{"op":"mcm","clk":"5348218131","pt":1646215576860,"mc":[{"id":"1.195453621","rc":[{"atl":[[3.15,0]],"id":36463352},{"spn":7.73,"spf":1.0,"id":6780934}],"con":true,"img":false}]}
{"op":"mcm","clk":"5348218207","pt":1646215577652,"mc":[{"id":"1.195453621","rc":[{"atl":[[2.98,6.53]],"id":36463352}],"con":true,"img":false}]}
{"op":"mcm","clk":"5348218290","pt":1646215578791,"mc":[{"id":"1.195453621","rc":[{"atl":[[3,0]],"id":36463352}],"con":true,"img":false}]}
{"op":"mcm","clk":"5348218308","pt":1646215578959,"mc":[{"id":"1.195453621","rc":[{"atl":[[2.96,4.42]],"id":36463352}],"con":true,"img":false}]}
{"op":"mcm","clk":"5348218380","pt":1646215579784,"mc":[{"id":"1.195453621","rc":[{"atl":[[3.05,0]],"id":36463352},{"atb":[[11,2.97]],"id":6780934}],"con":true,"img":false}]}
{"op":"mcm","clk":"5348218508","pt":1646215581264,"mc":[{"id":"1.195453621","rc":[{"atb":[[10.5,0]],"id":6780934}],"con":true,"img":false}]}
{"op":"mcm","clk":"5348218640","pt":1646215582667,"mc":[{"id":"1.195453621","rc":[{"atl":[[2.94,5.44]],"id":36463352}],"con":true,"img":false}]}
{"op":"mcm","clk":"5348218664","pt":1646215582872,"mc":[{"id":"1.195453621","rc":[{"atl":[[28,1]],"id":6780934}],"con":true,"img":false}]}
{"op":"mcm","clk":"5348218672","pt":1646215582973,"mc":[{"id":"1.195453621","rc":[{"atl":[[27,0]],"id":6780934}],"con":true,"img":false}]}
{"op":"mcm","clk":"5348218812","pt":1646215584684,"mc":[{"id":"1.195453621","rc":[{"atl":[[2.96,0]],"id":36463352}],"con":true,"img":false}]}
{"op":"mcm","clk":"5348218832","pt":1646215584895,"mc":[{"id":"1.195453621","rc":[{"atl":[[2.92,4.48]],"id":36463352}],"con":true,"img":false}]}
{"op":"mcm","clk":"5348218908","pt":1646215585784,"mc":[{"id":"1.195453621","rc":[{"atl":[[3.3,0]],"id":36463352}],"con":true,"img":false}]}
{"op":"mcm","clk":"5348218919","pt":1646215585886,"mc":[{"id":"1.195453621","rc":[{"atl":[[3.2,20.87]],"id":36463352}],"con":true,"img":false}]}
{"op":"mcm","clk":"5348219312","pt":1646215590086,"mc":[{"id":"1.195453621","rc":[{"atl":[[2.98,0]],"id":36463352}],"con":true,"img":false}]}
{"op":"mcm","clk":"5348219399","pt":1646215590874,"mc":[{"id":"1.195453621","rc":[{"atl":[[2.9,6.53]],"id":36463352}],"con":true,"img":false}]}
{"op":"mcm","clk":"5348219479","pt":1646215591768,"mc":[{"id":"1.195453621","rc":[{"atb":[[11,0]],"id":6780934}],"con":true,"img":false}]}
{"op":"mcm","clk":"5348219486","pt":1646215591870,"mc":[{"id":"1.195453621","rc":[{"atb":[[9.2,2.97]],"id":6780934}],"con":true,"img":false}]}
{"op":"mcm","clk":"5348219499","pt":1646215591969,"mc":[{"id":"1.195453621","rc":[{"atb":[[9,0],[8.2,4.72]],"id":6780934}],"con":true,"img":false}]}
{"op":"mcm","clk":"5348219509","pt":1646215592073,"mc":[{"id":"1.195453621","rc":[{"atb":[[9,5.94]],"id":6780934}],"con":true,"img":false}]}
{"op":"mcm","clk":"5348219517","pt":1646215592184,"mc":[{"id":"1.195453621","rc":[{"atb":[[8.2,0.37]],"id":6780934}],"con":true,"img":false}]}
{"op":"mcm","clk":"5348219590","pt":1646215592968,"mc":[{"id":"1.195453621","rc":[{"atl":[[30,1.68]],"id":6780934}],"con":true,"img":false}]}
{"op":"mcm","clk":"5348219655","pt":1646215593696,"mc":[{"id":"1.195453621","rc":[{"atb":[[9.4,2.5]],"id":6780934}],"con":true,"img":false}]}
{"op":"mcm","clk":"5348219663","pt":1646215593801,"mc":[{"id":"1.195453621","rc":[{"atl":[[2.92,0],[3.2,0]],"id":36463352}],"con":true,"img":false}]}
{"op":"mcm","clk":"5348219671","pt":1646215593896,"mc":[{"id":"1.195453621","rc":[{"atl":[[3.3,20.87]],"id":36463352}],"con":true,"img":false}]}
{"op":"mcm","clk":"5348219682","pt":1646215594000,"mc":[{"id":"1.195453621","rc":[{"atl":[[2.88,4.54]],"id":36463352}],"con":true,"img":false}]}
{"op":"mcm","clk":"5348219757","pt":1646215594896,"mc":[{"id":"1.195453621","rc":[{"atl":[[2.94,0]],"id":36463352}],"con":true,"img":false}]}
{"op":"mcm","clk":"5348220046","pt":1646215598195,"mc":[{"id":"1.195453621","rc":[{"atl":[[2.86,5.44]],"id":36463352}],"con":true,"img":false}]}
{"op":"mcm","clk":"5348220069","pt":1646215598502,"mc":[{"id":"1.195453621","rc":[{"atb":[[9,0],[8.8,5.94]],"id":6780934},{"atl":[[27,1],[28,0],[30,0]],"id":6780934}],"con":true,"img":false}]}
{"op":"mcm","clk":"5348220193","pt":1646215599709,"mc":[{"id":"1.195453621","rc":[{"atl":[[2.88,0]],"id":36463352}],"con":true,"img":false}]}
{"op":"mcm","clk":"5348220211","pt":1646215599915,"mc":[{"id":"1.195453621","rc":[{"atl":[[2.84,4.6]],"id":36463352}],"con":true,"img":false}]}
{"op":"mcm","clk":"5348220482","pt":1646215603203,"mc":[{"id":"1.195453621","rc":[{"atb":[[8,2.86],[11,0],[8.2,35.24],[11.5,0],[12,0],[13,0],[14,0]],"id":23806261},{"atb":[[3.85,19.61],[3.5,0],[4,6.67],[3.65,0]],"id":40250501},{"atb":[[1.53,0],[1.71,127.12],[1.63,0],[1.81,24.69]],"id":36463352},{"atl":[[6.4,0],[6.2,42.27]],"id":41308374},{"atb":[[5,43.79],[3.9,0]],"id":40846831},{"atl":[[22,1],[28,0]],"id":40846831}],"con":true,"img":false}]}
{"op":"mcm","clk":"5348220491","pt":1646215603305,"mc":[{"id":"1.195453621","rc":[{"atl":[[2.9,0]],"id":36463352}],"con":true,"img":false}]}
{"op":"mcm","clk":"5348220542","pt":1646215603986,"mc":[{"id":"1.195453621","rc":[{"atl":[[2.82,6.53]],"id":36463352}],"con":true,"img":false}]}
{"op":"mcm","clk":"5348220574","pt":1646215604503,"mc":[{"id":"1.195453621","rc":[{"atb":[[1.55,142.8]],"id":41308374}],"con":true,"img":false}]}
{"op":"mcm","clk":"5348220584","pt":1646215604607,"mc":[{"id":"1.195453621","rc":[{"atb":[[1.5,0]],"id":41308374}],"con":true,"img":false}]}
{"op":"mcm","clk":"5348220646","pt":1646215605291,"mc":[{"id":"1.195453621","rc":[{"atl":[[85,2],[95,0]],"id":23806261}],"con":true,"img":false}]}
{"op":"mcm","clk":"5348220680","pt":1646215605703,"mc":[{"id":"1.195453621","rc":[{"atl":[[2.84,0]],"id":36463352}],"con":true,"img":false}]}
{"op":"mcm","clk":"5348220698","pt":1646215605908,"mc":[{"id":"1.195453621","rc":[{"atl":[[2.8,4.67]],"id":36463352}],"con":true,"img":false}]}
{"op":"mcm","clk":"5348221089","pt":1646215610393,"mc":[{"id":"1.195453621","rc":[{"atl":[[2.86,0]],"id":36463352}],"con":true,"img":false}]}
{"op":"mcm","clk":"5348221334","pt":1646215613134,"mc":[{"id":"1.195453621","rc":[{"atl":[[2.78,5.44]],"id":36463352}],"con":true,"img":false}]}
{"op":"mcm","clk":"5348221339","pt":1646215613238,"mc":[{"id":"1.195453621","rc":[{"atb":[[7.6,7.58]],"id":23806261},{"atb":[[3.9,17.24]],"id":40250501},{"atb":[[1.79,63.29]],"id":36463352},{"atl":[[24,2.17]],"id":40846831}],"con":true,"img":false}]}
{"op":"mcm","clk":"5348221360","pt":1646215613398,"mc":[{"id":"1.195453621","rc":[{"atb":[[3.35,0],[3.55,0],[3.45,0]],"id":40250501},{"atb":[[1.57,0]],"id":36463352},{"atl":[[38,3.6]],"id":40846831}],"con":true,"img":false}]}
{"op":"mcm","clk":"5348221468","pt":1646215614814,"mc":[{"id":"1.195453621","rc":[{"atl":[[2.8,0]],"id":36463352}],"con":true,"img":false}]}
{"op":"mcm","clk":"5348221488","pt":1646215615019,"mc":[{"id":"1.195453621","rc":[{"atl":[[2.76,4.74]],"id":36463352}],"con":true,"img":false}]}
{"op":"mcm","clk":"5348221554","pt":1646215615810,"mc":[{"id":"1.195453621","rc":[{"atb":[[9.2,0]],"id":6780934}],"con":true,"img":false}]}
{"op":"mcm","clk":"5348221560","pt":1646215615909,"mc":[{"id":"1.195453621","rc":[{"atb":[[9.6,2.97]],"id":6780934}],"con":true,"img":false}]}
{"op":"mcm","clk":"5348221609","pt":1646215616530,"mc":[{"id":"1.195453621","rc":[{"atl":[[2.82,0]],"id":36463352}],"con":true,"img":false}]}
{"op":"mcm","clk":"5348221656","pt":1646215617219,"mc":[{"id":"1.195453621","rc":[{"atb":[[9.4,0]],"id":6780934}],"con":true,"img":false}]}
{"op":"mcm","clk":"5348222147","pt":1646215623220,"mc":[{"id":"1.195453621","rc":[{"atb":[[7.2,38.47],[17.5,2]],"id":23806261},{"atl":[[55,4.72]],"id":23806261},{"atb":[[3.8,26.79],[13,4.49]],"id":40250501},{"atb":[[1.77,97.4]],"id":36463352},{"atb":[[8.6,3.33]],"id":40846831},{"atl":[[26,7.09]],"id":40846831}],"con":true,"img":false}]}
{"op":"mcm","clk":"5348222165","pt":1646215623424,"mc":[{"id":"1.195453621","rc":[{"atb":[[1.59,0]],"id":36463352},{"atb":[[17.5,2]],"id":40199925},{"atl":[[55,4.72]],"id":40199925},{"atl":[[34,0]],"id":40846831},{"atb":[[9.6,4.97]],"id":6780934}],"con":true,"img":false}]}
{"op":"mcm","clk":"5348222178","pt":1646215623629,"mc":[{"id":"1.195453621","rc":[{"atb":[[8.4,9.1],[8.8,0]],"id":6780934}],"con":true,"img":false}]}
{"op":"mcm","clk":"5348222328","pt":1646215625304,"mc":[{"id":"1.195453621","rc":[{"atl":[[2.78,0]],"id":36463352}],"con":true,"img":false}]}
{"op":"mcm","clk":"5348222335","pt":1646215625406,"mc":[{"id":"1.195453621","rc":[{"atb":[[17,0]],"id":23806261},{"atb":[[17,0]],"id":40199925}],"con":true,"img":false}]}
{"op":"mcm","clk":"5348222367","pt":1646215625836,"mc":[{"id":"1.195453621","rc":[{"atb":[[9.6,2]],"id":6780934}],"con":true,"img":false}]}
{"op":"mcm","clk":"5348222502","pt":1646215627721,"mc":[{"id":"1.195453621","rc":[{"atb":[[18,2.08]],"id":23806261},{"atb":[[18,2.08]],"id":40199925}],"con":true,"img":false}]}
{"op":"mcm","clk":"5348222553","pt":1646215628435,"mc":[{"id":"1.195453621","rc":[{"atb":[[17.5,0],[18.5,2]],"id":23806261}],"con":true,"img":false}]}
{"op":"mcm","clk":"5348222572","pt":1646215628646,"mc":[{"id":"1.195453621","rc":[{"atb":[[18.5,0]],"id":23806261},{"atb":[[17.5,0],[18.5,2]],"id":40199925},{"atb":[[9.6,0],[8.6,2]],"id":6780934}],"con":true,"img":false}]}
{"op":"mcm","clk":"5348222579","pt":1646215628705,"mc":[{"id":"1.195453621","rc":[{"atb":[[18.5,2]],"id":23806261},{"atb":[[8.6,0]],"id":6780934}],"con":true,"img":false}]}
{"op":"mcm","clk":"5348222588","pt":1646215628809,"mc":[{"id":"1.195453621","rc":[{"atb":[[8.2,11.47],[8.4,0.19]],"id":6780934}],"con":true,"img":false}]}
{"op":"mcm","clk":"5348222595","pt":1646215628911,"mc":[{"id":"1.195453621","rc":[{"atb":[[8.2,0.37],[8.6,2]],"id":6780934}],"con":true,"img":false}]}
{"op":"mcm","clk":"5348222601","pt":1646215629017,"mc":[{"id":"1.195453621","rc":[{"atb":[[8,13.11]],"id":6780934}],"con":true,"img":false}]}
{"op":"mcm","clk":"5348222611","pt":1646215629126,"mc":[{"id":"1.195453621","rc":[{"atb":[[18,0]],"id":23806261}],"con":true,"img":false}]}
{"op":"mcm","clk":"5348222700","pt":1646215630112,"mc":[{"id":"1.195453621","rc":[{"atb":[[1.02,0]],"id":6780934}],"con":true,"img":false}]}
{"op":"mcm","clk":"5348222707","pt":1646215630219,"mc":[{"id":"1.195453621","rc":[{"atb":[[8.2,1.6]],"id":6780934}],"con":true,"img":false}]}
{"op":"mcm","clk":"5348222715","pt":1646215630319,"mc":[{"id":"1.195453621","rc":[{"atb":[[18,0]],"id":40199925},{"atb":[[8.8,2.5]],"id":6780934}],"con":true,"img":false}]}
{"op":"mcm","clk":"5348222936","pt":1646215633237,"mc":[{"id":"1.195453621","rc":[{"atb":[[6.8,21.55]],"id":23806261},{"atb":[[3.7,46.3]],"id":40250501},{"atb":[[1.75,166.67]],"id":36463352},{"atl":[[28,4.63]],"id":40846831}],"con":true,"img":false}]}
{"op":"mcm","clk":"5348222987","pt":1646215633811,"mc":[{"id":"1.195453621","rc":[{"atb":[[17,2],[18.5,0]],"id":40199925}],"con":true,"img":false}]}
{"op":"mcm","clk":"5348222994","pt":1646215633918,"mc":[{"id":"1.195453621","rc":[{"atb":[[17,2],[18.5,0]],"id":23806261}],"con":true,"img":false}]}
{"op":"mcm","clk":"5348223004","pt":1646215634025,"mc":[{"id":"1.195453621","rc":[{"atb":[[1.61,118.03]],"id":36463352},{"atl":[[30,0]],"id":40846831},{"atl":[[26,1],[27,0]],"id":6780934}],"con":true,"img":false}]}
{"op":"mcm","clk":"5348223134","pt":1646215635640,"mc":[{"id":"1.195453621","rc":[{"atb":[[17.5,2.08]],"id":23806261},{"atb":[[17.5,2.08]],"id":40199925}],"con":true,"img":false}]}
{"op":"mcm","clk":"5348223401","pt":1646215638964,"mc":[{"id":"1.195453621","rc":[{"spn":13.88,"spf":1.0,"id":23806261},{"spn":10.75,"spf":1.0,"id":40250501},{"atb":[[18,2]],"id":40199925},{"spn":14.78,"spf":1.0,"id":40199925},{"spn":7.55,"spf":1.0,"id":40846831},{"spn":7.83,"spf":1.0,"id":6780934}],"con":true,"img":false}]}
{"op":"mcm","clk":"5348223409","pt":1646215639032,"mc":[{"id":"1.195453621","rc":[{"atb":[[17,0]],"id":23806261},{"atb":[[17,0]],"id":40199925}],"con":true,"img":false}]}
{"op":"mcm","clk":"5348223415","pt":1646215639136,"mc":[{"id":"1.195453621","rc":[{"atb":[[18,2]],"id":23806261}],"con":true,"img":false}]}
{"op":"mcm","clk":"5348223560","pt":1646215640743,"mc":[{"id":"1.195453621","rc":[{"atb":[[17.5,0]],"id":23806261},{"atb":[[17.5,0]],"id":40199925}],"con":true,"img":false}]}
{"op":"mcm","clk":"5348223574","pt":1646215640952,"mc":[{"id":"1.195453621","rc":[{"atb":[[17,2],[18,0]],"id":23806261},{"atb":[[17,2],[18,0]],"id":40199925}],"con":true,"img":false}]}
{"op":"mcm","clk":"5348223647","pt":1646215641839,"mc":[{"id":"1.195453621","rc":[{"atb":[[9,3.63]],"id":6780934}],"con":true,"img":false}]}
{"op":"mcm","clk":"5348223662","pt":1646215642044,"mc":[{"id":"1.195453621","rc":[{"atb":[[17.5,2.08]],"id":23806261},{"atb":[[17.5,2.08]],"id":40199925},{"atb":[[9.2,2],[8.6,6.14]],"id":6780934}],"con":true,"img":false}]}
{"op":"mcm","clk":"5348223670","pt":1646215642147,"mc":[{"id":"1.195453621","rc":[{"atb":[[8,1.44]],"id":6780934}],"con":true,"img":false}]}
{"op":"mcm","clk":"5348223780","pt":1646215643456,"mc":[{"id":"1.195453621","rc":[{"atb":[[8.8,0]],"id":6780934}],"con":true,"img":false}]}
{"op":"mcm","clk":"5348223874","pt":1646215644760,"mc":[{"id":"1.195453621","rc":[{"atb":[[9.4,2.5]],"id":6780934}],"con":true,"img":false}]}
{"op":"mcm","clk":"5348223892","pt":1646215644967,"mc":[{"id":"1.195453621","rc":[{"atl":[[26,0],[27,1]],"id":6780934}],"con":true,"img":false}]}
{"op":"mcm","clk":"5348223991","pt":1646215646076,"mc":[{"id":"1.195453621","rc":[{"atb":[[17,0]],"id":40199925}],"con":true,"img":false}]}
{"op":"mcm","clk":"5348224000","pt":1646215646130,"mc":[{"id":"1.195453621","rc":[{"atb":[[17,0],[18,2]],"id":23806261},{"atb":[[18,2]],"id":40199925}],"con":true,"img":false}]}
{"op":"mcm","clk":"5348224096","pt":1646215647333,"mc":[{"id":"1.195453621","rc":[{"atb":[[17.5,0]],"id":23806261},{"atb":[[17.5,0]],"id":40199925}],"con":true,"img":false}]}
{"op":"mcm","clk":"5348224102","pt":1646215647436,"mc":[{"id":"1.195453621","rc":[{"atb":[[17,2],[18,0]],"id":23806261},{"atb":[[17,2],[18,0]],"id":40199925}],"con":true,"img":false}]}
{"op":"mcm","clk":"5348224123","pt":1646215647756,"mc":[{"id":"1.195453621","rc":[{"atb":[[20,0],[1.04,2.25]],"id":23806261}],"con":true,"img":false}]}
{"op":"mcm","clk":"5348224141","pt":1646215647959,"mc":[{"id":"1.195453621","rc":[{"atb":[[1.04,0.18]],"id":23806261},{"atl":[[55,2]],"id":23806261}],"con":true,"img":false}]}
{"op":"mcm","clk":"5348224148","pt":1646215648062,"mc":[{"id":"1.195453621","rc":[{"atl":[[50,2.72]],"id":23806261}],"con":true,"img":false}]}
{"op":"mcm","clk":"5348224157","pt":1646215648174,"mc":[{"id":"1.195453621","rc":[{"atb":[[1.04,0]],"id":23806261},{"atl":[[55,0],[80,4.72]],"id":23806261}],"con":true,"img":false}]}
{"op":"mcm","clk":"5348224165","pt":1646215648269,"mc":[{"id":"1.195453621","rc":[{"atb":[[16.5,0.28]],"id":23806261}],"con":true,"img":false}]}
{"op":"mcm","clk":"5348224172","pt":1646215648375,"mc":[{"id":"1.195453621","rc":[{"atl":[[80,2.72]],"id":23806261}],"con":true,"img":false}]}
{"op":"mcm","clk":"5348224182","pt":1646215648440,"mc":[{"id":"1.195453621","rc":[{"atl":[[50,4.72]],"id":23806261}],"con":true,"img":false}]}
{"op":"mcm","clk":"5348224199","pt":1646215648647,"mc":[{"id":"1.195453621","rc":[{"atb":[[17.5,2.08]],"id":23806261},{"atb":[[17.5,2.08]],"id":40199925}],"con":true,"img":false}]}
{"op":"mcm","clk":"5348224474","pt":1646215651747,"mc":[{"id":"1.195453621","rc":[{"atb":[[11,0]],"id":40250501}],"con":true,"img":false}]}
{"op":"mcm","clk":"5348224480","pt":1646215651852,"mc":[{"id":"1.195453621","rc":[{"atb":[[11.5,6.94]],"id":40250501}],"con":true,"img":false}]}
{"op":"mcm","clk":"5348224539","pt":1646215652572,"mc":[{"id":"1.195453621","rc":[{"atb":[[18,2]],"id":40199925}],"con":true,"img":false}]}
{"op":"mcm","clk":"5348224547","pt":1646215652640,"mc":[{"id":"1.195453621","rc":[{"atb":[[17,0]],"id":40199925}],"con":true,"img":false}]}
{"op":"mcm","clk":"5348224555","pt":1646215652748,"mc":[{"id":"1.195453621","rc":[{"atb":[[18,0]],"id":40199925}],"con":true,"img":false}]}
{"op":"mcm","clk":"5348224566","pt":1646215652853,"mc":[{"id":"1.195453621","rc":[{"atb":[[18,2]],"id":40199925}],"con":true,"img":false}]}
{"op":"mcm","clk":"5348224630","pt":1646215653737,"mc":[{"id":"1.195453621","rc":[{"atb":[[17.5,0]],"id":40199925},{"atl":[[26,3]],"id":40846831}],"con":true,"img":false}]}
{"op":"mcm","clk":"5348224750","pt":1646215654944,"mc":[{"id":"1.195453621","rc":[{"atb":[[8.8,5]],"id":6780934}],"con":true,"img":false}]}
{"op":"mcm","clk":"5348224757","pt":1646215655085,"mc":[{"id":"1.195453621","rc":[{"atb":[[8.6,0]],"id":6780934}],"con":true,"img":false}]}
{"op":"mcm","clk":"5348225043","pt":1646215658051,"mc":[{"id":"1.195453621","rc":[{"atb":[[17,2],[18,0]],"id":40199925}],"con":true,"img":false}]}
{"op":"mcm","clk":"5348225117","pt":1646215659148,"mc":[{"id":"1.195453621","rc":[{"atb":[[17.5,2.08]],"id":40199925}],"con":true,"img":false}]}
{"op":"mcm","clk":"5348225492","pt":1646215663282,"mc":[{"id":"1.195453621","rc":[{"atb":[[17,0],[18,2]],"id":40199925}],"con":true,"img":false}]}
{"op":"mcm","clk":"5348225531","pt":1646215663769,"mc":[{"id":"1.195453621","rc":[{"atb":[[9,0],[9.6,3.4]],"id":6780934}],"con":true,"img":false}]}
{"op":"mcm","clk":"5348225549","pt":1646215663967,"mc":[{"id":"1.195453621","rc":[{"atb":[[9.2,0],[9.8,2]],"id":6780934}],"con":true,"img":false}]}
{"op":"mcm","clk":"5348225606","pt":1646215664549,"mc":[{"id":"1.195453621","rc":[{"atb":[[17.5,0]],"id":40199925},{"atb":[[9.4,0]],"id":6780934}],"con":true,"img":false}]}
{"op":"mcm","clk":"5348225700","pt":1646215665484,"mc":[{"id":"1.195453621","rc":[{"atb":[[10,2.5]],"id":6780934}],"con":true,"img":false}]}
{"op":"mcm","clk":"5348225974","pt":1646215668465,"mc":[{"id":"1.195453621","rc":[{"atb":[[17,2],[18,0]],"id":40199925}],"con":true,"img":false}]}
{"op":"mcm","clk":"5348225992","pt":1646215668667,"mc":[{"id":"1.195453621","rc":[{"atb":[[9,5]],"id":6780934}],"con":true,"img":false}]}
{"op":"mcm","clk":"5348226001","pt":1646215668775,"mc":[{"id":"1.195453621","rc":[{"atb":[[8.8,0]],"id":6780934}],"con":true,"img":false}]}
{"op":"mcm","clk":"5348226096","pt":1646215669669,"mc":[{"id":"1.195453621","rc":[{"atb":[[17.5,2.08]],"id":40199925}],"con":true,"img":false}]}
{"op":"mcm","clk":"5348226275","pt":1646215671790,"mc":[{"id":"1.195453621","rc":[{"atl":[[50,2]],"id":23806261},{"atl":[[23,5.03]],"id":40846831}],"con":true,"img":false}]}
{"op":"mcm","clk":"5348226284","pt":1646215671854,"mc":[{"id":"1.195453621","rc":[{"atl":[[48,2.72]],"id":23806261}],"con":true,"img":false}]}
{"op":"mcm","clk":"5348226290","pt":1646215671962,"mc":[{"id":"1.195453621","rc":[{"atl":[[50,0],[80,4.72]],"id":23806261}],"con":true,"img":false}]}
{"op":"mcm","clk":"5348226433","pt":1646215673679,"mc":[{"id":"1.195453621","rc":[{"atb":[[17,0],[18,2]],"id":40199925}],"con":true,"img":false}]}
{"op":"mcm","clk":"5348226446","pt":1646215673888,"mc":[{"id":"1.195453621","rc":[{"atl":[[48,0]],"id":23806261},{"atb":[[18,0]],"id":40199925}],"con":true,"img":false}]}
{"op":"mcm","clk":"5348226455","pt":1646215673996,"mc":[{"id":"1.195453621","rc":[{"atl":[[55,2.72]],"id":23806261}],"con":true,"img":false}]}
{"op":"mcm","clk":"5348226465","pt":1646215674090,"mc":[{"id":"1.195453621","rc":[{"atb":[[18,2]],"id":40199925}],"con":true,"img":false}]}
{"op":"mcm","clk":"5348226607","pt":1646215675900,"mc":[{"id":"1.195453621","rc":[{"atb":[[17.5,0]],"id":40199925}],"con":true,"img":false}]}
{"op":"mcm","clk":"5348226716","pt":1646215677169,"mc":[{"id":"1.195453621","rc":[{"atl":[[80,2.72],[55,4.72]],"id":23806261}],"con":true,"img":false}]}
{"op":"mcm","clk":"5348226730","pt":1646215677275,"mc":[{"id":"1.195453621","rc":[{"atl":[[55,2.72]],"id":23806261}],"con":true,"img":false}]}
{"op":"mcm","clk":"5348226740","pt":1646215677379,"mc":[{"id":"1.195453621","rc":[{"atl":[[55,4.72]],"id":23806261}],"con":true,"img":false}]}
{"op":"mcm","clk":"5348226914","pt":1646215679167,"mc":[{"id":"1.195453621","rc":[{"atb":[[17,2],[18,0]],"id":40199925}],"con":true,"img":false}]}
{"op":"mcm","clk":"5348226992","pt":1646215680001,"mc":[{"id":"1.195453621","rc":[{"atb":[[17.5,2.08]],"id":40199925}],"con":true,"img":false}]}
{"op":"mcm","clk":"5348227396","pt":1646215684308,"mc":[{"id":"1.195453621","rc":[{"atb":[[17,0],[18,2]],"id":40199925}],"con":true,"img":false}]}
{"op":"mcm","clk":"5348227503","pt":1646215685416,"mc":[{"id":"1.195453621","rc":[{"atb":[[17.5,0]],"id":40199925}],"con":true,"img":false}]}
{"op":"mcm","clk":"5348227528","pt":1646215685588,"mc":[{"id":"1.195453621","rc":[{"atb":[[17,2],[18,0]],"id":40199925}],"con":true,"img":false}]}
{"op":"mcm","clk":"5348227546","pt":1646215685798,"mc":[{"id":"1.195453621","rc":[{"atb":[[10.5,3.11],[9.6,0]],"id":6780934}],"con":true,"img":false}]}
{"op":"mcm","clk":"5348227564","pt":1646215686005,"mc":[{"id":"1.195453621","rc":[{"atb":[[11,2],[9.8,0]],"id":6780934}],"con":true,"img":false}]}
{"op":"mcm","clk":"5348227583","pt":1646215686210,"mc":[{"id":"1.195453621","rc":[{"atb":[[17.5,2.08]],"id":40199925}],"con":true,"img":false}]}
{"op":"mcm","clk":"5348227742","pt":1646215687898,"mc":[{"id":"1.195453621","rc":[{"atb":[[10,0]],"id":6780934}],"con":true,"img":false}]}
{"op":"mcm","clk":"5348227840","pt":1646215689096,"mc":[{"id":"1.195453621","rc":[{"atb":[[11.5,2.08]],"id":6780934}],"con":true,"img":false}]}
{"op":"mcm","clk":"5348227985","pt":1646215690716,"mc":[{"id":"1.195453621","rc":[{"atb":[[18,2]],"id":40199925}],"con":true,"img":false}]}
{"op":"mcm","clk":"5348227992","pt":1646215690813,"mc":[{"id":"1.195453621","rc":[{"atb":[[17,0]],"id":40199925}],"con":true,"img":false}]}
{"op":"mcm","clk":"5348228000","pt":1646215690918,"mc":[{"id":"1.195453621","rc":[{"atb":[[18,0]],"id":40199925}],"con":true,"img":false}]}
{"op":"mcm","clk":"5348228009","pt":1646215691023,"mc":[{"id":"1.195453621","rc":[{"atb":[[18,2]],"id":40199925},{"atl":[[27,0],[28,1]],"id":6780934}],"con":true,"img":false}]}
{"op":"mcm","clk":"5348228196","pt":1646215693113,"mc":[{"id":"1.195453621","rc":[{"atb":[[17.5,0]],"id":40199925}],"con":true,"img":false}]}
{"op":"mcm","clk":"5348228480","pt":1646215696200,"mc":[{"id":"1.195453621","rc":[{"atb":[[17,2],[18,0]],"id":40199925}],"con":true,"img":false}]}
{"op":"mcm","clk":"5348228690","pt":1646215698302,"mc":[{"id":"1.195453621","rc":[{"atb":[[17.5,2.08]],"id":40199925}],"con":true,"img":false}]}
{"op":"mcm","clk":"5348228716","pt":1646215698513,"mc":[{"id":"1.195453621","rc":[{"atb":[[17,0],[18,2]],"id":40199925}],"con":true,"img":false}]}
{"op":"mcm","clk":"5348228816","pt":1646215699817,"mc":[{"id":"1.195453621","rc":[{"atl":[[55,2]],"id":23806261},{"spn":13.86,"spf":1.0,"id":23806261},{"spn":10.84,"spf":1.0,"id":40250501},{"spn":14.45,"spf":1.0,"id":40199925},{"spn":8.49,"spf":1.0,"id":6780934}],"con":true,"img":false}]}
{"op":"mcm","clk":"5348228823","pt":1646215699919,"mc":[{"id":"1.195453621","rc":[{"atl":[[50,2.72]],"id":23806261}],"con":true,"img":false}]}
{"op":"mcm","clk":"5348228831","pt":1646215700026,"mc":[{"id":"1.195453621","rc":[{"atl":[[55,0],[80,4.72]],"id":23806261}],"con":true,"img":false}]}
{"op":"mcm","clk":"5348228837","pt":1646215700131,"mc":[{"id":"1.195453621","rc":[{"atl":[[80,2.72],[50,4.72]],"id":23806261}],"con":true,"img":false}]}
{"op":"mcm","clk":"5348228903","pt":1646215700822,"mc":[{"id":"1.195453621","rc":[{"atb":[[17.5,0]],"id":40199925}],"con":true,"img":false}]}
{"op":"mcm","clk":"5348228918","pt":1646215701034,"mc":[{"id":"1.195453621","rc":[{"atl":[[30,1.68]],"id":6780934}],"con":true,"img":false}]}
{"op":"mcm","clk":"5348229141","pt":1646215703724,"mc":[{"id":"1.195453621","rc":[{"atb":[[17,2],[18,0]],"id":40199925}],"con":true,"img":false}]}
{"op":"mcm","clk":"5348229166","pt":1646215703993,"mc":[{"id":"1.195453621","rc":[{"atl":[[32,0],[36,3.27],[29,1.47]],"id":6780934}],"con":true,"img":false}]}
{"op":"mcm","clk":"5348229330","pt":1646215706136,"mc":[{"id":"1.195453621","rc":[{"atb":[[17.5,2.08]],"id":40199925}],"con":true,"img":false}]}
{"op":"mcm","clk":"5348229346","pt":1646215706335,"mc":[{"id":"1.195453621","rc":[{"atb":[[17,0],[18,2]],"id":40199925}],"con":true,"img":false}]}
{"op":"mcm","clk":"5348229552","pt":1646215708593,"mc":[{"id":"1.195453621","rc":[{"atb":[[17.5,0]],"id":40199925}],"con":true,"img":false}]}
{"op":"mcm","clk":"5348229564","pt":1646215708805,"mc":[{"id":"1.195453621","rc":[{"atb":[[20,0],[1.04,2.25]],"id":40199925}],"con":true,"img":false}]}
{"op":"mcm","clk":"5348229583","pt":1646215709014,"mc":[{"id":"1.195453621","rc":[{"atb":[[1.04,0.18]],"id":40199925}],"con":true,"img":false}]}
{"op":"mcm","clk":"5348229602","pt":1646215709220,"mc":[{"id":"1.195453621","rc":[{"atb":[[1.04,0]],"id":40199925}],"con":true,"img":false}]}
{"op":"mcm","clk":"5348229609","pt":1646215709321,"mc":[{"id":"1.195453621","rc":[{"atb":[[16.5,0.28]],"id":40199925}],"con":true,"img":false}]}
{"op":"mcm","clk":"5348229773","pt":1646215711012,"mc":[{"id":"1.195453621","rc":[{"atl":[[34,2.22]],"id":6780934}],"con":true,"img":false}]}
{"op":"mcm","clk":"5348229823","pt":1646215711530,"mc":[{"id":"1.195453621","rc":[{"atb":[[17,2],[18,0]],"id":40199925}],"con":true,"img":false}]}
{"op":"mcm","clk":"5348229856","pt":1646215711840,"mc":[{"id":"1.195453621","rc":[{"atb":[[10.5,0],[12,2.72]],"id":6780934}],"con":true,"img":false}]}
{"op":"mcm","clk":"5348229875","pt":1646215712006,"mc":[{"id":"1.195453621","rc":[{"atb":[[11,0],[12,4.72]],"id":6780934}],"con":true,"img":false}]}
{"op":"mcm","clk":"5348230058","pt":1646215714002,"mc":[{"id":"1.195453621","rc":[{"atb":[[17.5,2.08]],"id":40199925}],"con":true,"img":false}]}
{"op":"mcm","clk":"5348230068","pt":1646215714106,"mc":[{"id":"1.195453621","rc":[{"atb":[[11.5,0]],"id":6780934}],"con":true,"img":false}]}
{"op":"mcm","clk":"5348230076","pt":1646215714210,"mc":[{"id":"1.195453621","rc":[{"atl":[[28,0],[29,2.47]],"id":6780934}],"con":true,"img":false}]}
{"op":"mcm","clk":"5348230633","pt":1646215720325,"mc":[{"id":"1.195453621","rc":[{"atb":[[9,0],[9.4,9.44]],"id":6780934}],"con":true,"img":false}]}
{"op":"mcm","clk":"5348230970","pt":1646215723823,"mc":[{"id":"1.195453621","rc":[{"atl":[[50,2]],"id":23806261}],"con":true,"img":false}]}
{"op":"mcm","clk":"5348230980","pt":1646215723924,"mc":[{"id":"1.195453621","rc":[{"atl":[[48,2.72]],"id":23806261}],"con":true,"img":false}]}
{"op":"mcm","clk":"5348230988","pt":1646215724031,"mc":[{"id":"1.195453621","rc":[{"atl":[[50,0],[80,4.72]],"id":23806261}],"con":true,"img":false}]}
{"op":"mcm","clk":"5348231005","pt":1646215724245,"mc":[{"id":"1.195453621","rc":[{"atl":[[32,1.57]],"id":6780934}],"con":true,"img":false}]}
{"op":"mcm","clk":"5348231142","pt":1646215725861,"mc":[{"id":"1.195453621","rc":[{"atl":[[48,0]],"id":23806261}],"con":true,"img":false}]}
{"op":"mcm","clk":"5348231158","pt":1646215725968,"mc":[{"id":"1.195453621","rc":[{"atl":[[55,2.72]],"id":23806261}],"con":true,"img":false}]}
{"op":"mcm","clk":"5348231459","pt":1646215729154,"mc":[{"id":"1.195453621","rc":[{"atl":[[80,2.72],[55,4.72]],"id":23806261}],"con":true,"img":false}]}
{"op":"mcm","clk":"5348231465","pt":1646215729256,"mc":[{"id":"1.195453621","rc":[{"atl":[[55,2.72]],"id":23806261}],"con":true,"img":false}]}
{"op":"mcm","clk":"5348231469","pt":1646215729361,"mc":[{"id":"1.195453621","rc":[{"atl":[[55,4.72]],"id":23806261}],"con":true,"img":false}]}
{"op":"mcm","clk":"5348231865","pt":1646215733842,"mc":[{"id":"1.195453621","rc":[{"atb":[[12,2]],"id":6780934}],"con":true,"img":false}]}
{"op":"mcm","clk":"5348231871","pt":1646215733944,"mc":[{"id":"1.195453621","rc":[{"atb":[[12.5,2.72]],"id":6780934}],"con":true,"img":false}]}
{"op":"mcm","clk":"5348231878","pt":1646215734046,"mc":[{"id":"1.195453621","rc":[{"atb":[[12,0],[9.6,2]],"id":6780934}],"con":true,"img":false}]}
{"op":"mcm","clk":"5348231895","pt":1646215734261,"mc":[{"id":"1.195453621","rc":[{"atl":[[36,5.36]],"id":6780934}],"con":true,"img":false}]}
{"op":"mcm","clk":"5348232103","pt":1646215736660,"mc":[{"id":"1.195453621","rc":[{"atb":[[16.5,0.1],[1.04,2.25]],"id":23806261}],"con":true,"img":false}]}
{"op":"mcm","clk":"5348232121","pt":1646215736823,"mc":[{"id":"1.195453621","rc":[{"atb":[[1.04,0.18]],"id":23806261}],"con":true,"img":false}]}
{"op":"mcm","clk":"5348232173","pt":1646215737450,"mc":[{"id":"1.195453621","rc":[{"atb":[[1.04,0]],"id":23806261}],"con":true,"img":false}]}
{"op":"mcm","clk":"5348232185","pt":1646215737555,"mc":[{"id":"1.195453621","rc":[{"atb":[[20,0.18]],"id":23806261}],"con":true,"img":false}]}
{"op":"mcm","clk":"5348232202","pt":1646215737761,"mc":[{"id":"1.195453621","rc":[{"atb":[[17,0],[18,2]],"id":23806261}],"con":true,"img":false}]}
{"op":"mcm","clk":"5348232218","pt":1646215737924,"mc":[{"id":"1.195453621","rc":[{"atl":[[2.76,0]],"id":36463352}],"con":true,"img":false}]}
{"op":"mcm","clk":"5348232239","pt":1646215738139,"mc":[{"id":"1.195453621","rc":[{"atl":[[3.2,4.09]],"id":36463352}],"con":true,"img":false}]}
{"op":"mcm","clk":"5348232302","pt":1646215738652,"mc":[{"id":"1.195453621","rc":[{"atl":[[3.15,6.53]],"id":36463352}],"con":true,"img":false}]}
{"op":"mcm","clk":"5348232348","pt":1646215739124,"mc":[{"id":"1.195453621","rc":[{"atb":[[12.5,4.72],[9.6,0]],"id":6780934}],"con":true,"img":false}]}
{"op":"mcm","clk":"5348232376","pt":1646215739435,"mc":[{"id":"1.195453621","rc":[{"atb":[[5,20.43],[5.5,31.3]],"id":40846831},{"atl":[[34,0],[30,0]],"id":6780934}],"con":true,"img":false}]}
{"op":"mcm","clk":"5348232429","pt":1646215739960,"mc":[{"id":"1.195453621","rc":[{"atb":[[17.5,0]],"id":23806261},{"atb":[[2.38,3.2]],"id":36463352},{"atl":[[3.1,5.44]],"id":36463352}],"con":true,"img":false}]}
{"op":"mcm","clk":"5348232513","pt":1646215740960,"mc":[{"id":"1.195453621","rc":[{"atl":[[3.2,0]],"id":36463352}],"con":true,"img":false}]}
{"op":"mcm","clk":"5348232527","pt":1646215741116,"mc":[{"id":"1.195453621","rc":[{"atl":[[3.05,4.29]],"id":36463352}],"con":true,"img":false}]}
{"op":"mcm","clk":"5348232701","pt":1646215742850,"mc":[{"id":"1.195453621","rc":[{"atb":[[17,2],[18,0]],"id":23806261}],"con":true,"img":false}]}
{"op":"mcm","clk":"5348232826","pt":1646215744250,"mc":[{"id":"1.195453621","rc":[{"atl":[[40,3.13]],"id":6780934}],"con":true,"img":false}]}
{"op":"mcm","clk":"5348232913","pt":1646215745244,"mc":[{"id":"1.195453621","rc":[{"atb":[[17.5,2.08]],"id":23806261}],"con":true,"img":false}]}
{"op":"mcm","clk":"5348232956","pt":1646215745769,"mc":[{"id":"1.195453621","rc":[{"atb":[[12.5,2]],"id":6780934}],"con":true,"img":false}]}
{"op":"mcm","clk":"5348232967","pt":1646215745874,"mc":[{"id":"1.195453621","rc":[{"atb":[[9.8,3.33]],"id":6780934}],"con":true,"img":false}]}
{"op":"mcm","clk":"5348232973","pt":1646215745929,"mc":[{"id":"1.195453621","rc":[{"atb":[[12.5,0],[9.6,2]],"id":6780934}],"con":true,"img":false}]}
{"op":"mcm","clk":"5348233124","pt":1646215747757,"mc":[{"id":"1.195453621","rc":[{"atb":[[10,2.5]],"id":6780934}],"con":true,"img":false}]}
{"op":"mcm","clk":"5348233153","pt":1646215748068,"mc":[{"id":"1.195453621","rc":[{"atb":[[17,0],[18,2]],"id":23806261}],"con":true,"img":false}]}
{"op":"mcm","clk":"5348233343","pt":1646215750372,"mc":[{"id":"1.195453621","rc":[{"atb":[[17.5,0]],"id":23806261}],"con":true,"img":false}]}
{"op":"mcm","clk":"5348233361","pt":1646215750529,"mc":[{"id":"1.195453621","rc":[{"atb":[[17,2],[18,0]],"id":23806261}],"con":true,"img":false}]}
{"op":"mcm","clk":"5348233377","pt":1646215750737,"mc":[{"id":"1.195453621","rc":[{"atb":[[9,5.84],[9.4,0]],"id":6780934},{"atl":[[28,1],[29,1.47]],"id":6780934}],"con":true,"img":false}]}
{"op":"mcm","clk":"5348233398","pt":1646215750943,"mc":[{"id":"1.195453621","rc":[{"atl":[[1000,0]],"id":6780934}],"con":true,"img":false}]}
{"op":"mcm","clk":"5348233408","pt":1646215751049,"mc":[{"id":"1.195453621","rc":[{"atb":[[10,4.5]],"id":6780934},{"atl":[[34,2.65]],"id":6780934}],"con":true,"img":false}]}
{"op":"mcm","clk":"5348233416","pt":1646215751156,"mc":[{"id":"1.195453621","rc":[{"atl":[[3.15,0]],"id":36463352},{"atb":[[9.6,0]],"id":6780934}],"con":true,"img":false}]}
{"op":"mcm","clk":"5348233425","pt":1646215751257,"mc":[{"id":"1.195453621","rc":[{"atb":[[10,2.5]],"id":6780934}],"con":true,"img":false}]}
{"op":"mcm","clk":"5348233434","pt":1646215751364,"mc":[{"id":"1.195453621","rc":[{"atb":[[10,4.5]],"id":6780934}],"con":true,"img":false}]}
{"op":"mcm","clk":"5348233474","pt":1646215751837,"mc":[{"id":"1.195453621","rc":[{"atl":[[55,2]],"id":23806261}],"con":true,"img":false}]}
{"op":"mcm","clk":"5348233486","pt":1646215751937,"mc":[{"id":"1.195453621","rc":[{"atl":[[50,2.72],[80,4.72]],"id":23806261},{"atl":[[3,6.53]],"id":36463352}],"con":true,"img":false}]}
{"op":"mcm","clk":"5348233496","pt":1646215752041,"mc":[{"id":"1.195453621","rc":[{"atl":[[55,0]],"id":23806261}],"con":true,"img":false}]}
{"op":"mcm","clk":"5348233519","pt":1646215752250,"mc":[{"id":"1.195453621","rc":[{"atl":[[3.1,0]],"id":36463352}],"con":true,"img":false}]}
{"op":"mcm","clk":"5348233570","pt":1646215752880,"mc":[{"id":"1.195453621","rc":[{"atb":[[17.5,2.08]],"id":23806261}],"con":true,"img":false}]}
{"op":"mcm","clk":"5348233581","pt":1646215752987,"mc":[{"id":"1.195453621","rc":[{"atb":[[2.38,0.7]],"id":36463352},{"atl":[[3.05,0]],"id":36463352}],"con":true,"img":false}]}
{"op":"mcm","clk":"5348233592","pt":1646215753043,"mc":[{"id":"1.195453621","rc":[{"atl":[[2.98,4.39]],"id":36463352}],"con":true,"img":false}]}
{"op":"mcm","clk":"5348233783","pt":1646215754938,"mc":[{"id":"1.195453621","rc":[{"atl":[[2.96,5.44]],"id":36463352}],"con":true,"img":false}]}
{"op":"mcm","clk":"5348233846","pt":1646215755665,"mc":[{"id":"1.195453621","rc":[{"atb":[[17,0],[18,2]],"id":23806261}],"con":true,"img":false}]}
{"op":"mcm","clk":"5348233858","pt":1646215755873,"mc":[{"id":"1.195453621","rc":[{"atl":[[27,1],[28,0]],"id":6780934}],"con":true,"img":false}]}
{"op":"mcm","clk":"5348233879","pt":1646215756135,"mc":[{"id":"1.195453621","rc":[{"atl":[[2.98,0]],"id":36463352}],"con":true,"img":false}]}
{"op":"mcm","clk":"5348233885","pt":1646215756242,"mc":[{"id":"1.195453621","rc":[{"atl":[[2.94,4.45]],"id":36463352}],"con":true,"img":false}]}
{"op":"mcm","clk":"5348233927","pt":1646215756762,"mc":[{"id":"1.195453621","rc":[{"atb":[[17.5,0]],"id":23806261}],"con":true,"img":false}]}
{"op":"mcm","clk":"5348233949","pt":1646215756978,"mc":[{"id":"1.195453621","rc":[{"atb":[[17,2],[18,0]],"id":23806261}],"con":true,"img":false}]}
{"op":"mcm","clk":"5348233964","pt":1646215757139,"mc":[{"id":"1.195453621","rc":[{"atl":[[80,2.72],[50,4.72]],"id":23806261}],"con":true,"img":false}]}
{"op":"mcm","clk":"5348233975","pt":1646215757292,"mc":[{"id":"1.195453621","rc":[{"atl":[[80,4.72],[50,2.72]],"id":23806261}],"con":true,"img":false}]}
{"op":"mcm","clk":"5348233984","pt":1646215757347,"mc":[{"id":"1.195453621","rc":[{"atl":[[80,2.72],[50,4.72]],"id":23806261}],"con":true,"img":false}]}
{"op":"mcm","clk":"5348234185","pt":1646215759384,"mc":[{"id":"1.195453621","rc":[{"atb":[[17.5,2.08]],"id":23806261}],"con":true,"img":false}]}
{"op":"mcm","clk":"5348234442","pt":1646215762165,"mc":[{"id":"1.195453621","rc":[{"atb":[[17,0],[18,2]],"id":23806261},{"spn":13.94,"spf":1.0,"id":23806261},{"spn":14.36,"spf":1.0,"id":40199925},{"spn":8.35,"spf":1.0,"id":6780934}],"con":true,"img":false}]}
{"op":"mcm","clk":"5348234562","pt":1646215763476,"mc":[{"id":"1.195453621","rc":[{"atb":[[17.5,0]],"id":23806261}],"con":true,"img":false}]}
{"op":"mcm","clk":"5348234581","pt":1646215763684,"mc":[{"id":"1.195453621","rc":[{"atb":[[17,2],[18,0]],"id":23806261}],"con":true,"img":false}]}
{"op":"mcm","clk":"5348234643","pt":1646215764374,"mc":[{"id":"1.195453621","rc":[{"atl":[[3,0]],"id":36463352}],"con":true,"img":false}]}
{"op":"mcm","clk":"5348234712","pt":1646215765163,"mc":[{"id":"1.195453621","rc":[{"atl":[[2.92,6.53]],"id":36463352}],"con":true,"img":false}]}
{"op":"mcm","clk":"5348234773","pt":1646215765898,"mc":[{"id":"1.195453621","rc":[{"atl":[[29,3.21]],"id":6780934}],"con":true,"img":false}]}
{"op":"mcm","clk":"5348234785","pt":1646215765954,"mc":[{"id":"1.195453621","rc":[{"atb":[[17.5,2.08]],"id":23806261}],"con":true,"img":false}]}
{"op":"mcm","clk":"5348234806","pt":1646215766164,"mc":[{"id":"1.195453621","rc":[{"atb":[[17,0],[18,2]],"id":23806261}],"con":true,"img":false}]}
{"op":"mcm","clk":"5348234886","pt":1646215767168,"mc":[{"id":"1.195453621","rc":[{"atl":[[2.96,0]],"id":36463352}],"con":true,"img":false}]}
{"op":"mcm","clk":"5348234980","pt":1646215768260,"mc":[{"id":"1.195453621","rc":[{"atl":[[2.94,0]],"id":36463352}],"con":true,"img":false}]}
{"op":"mcm","clk":"5348235000","pt":1646215768466,"mc":[{"id":"1.195453621","rc":[{"atl":[[2.9,4.51]],"id":36463352}],"con":true,"img":false}]}
{"op":"mcm","clk":"5348235011","pt":1646215768572,"mc":[{"id":"1.195453621","rc":[{"atb":[[17.5,0]],"id":23806261}],"con":true,"img":false}]}
{"op":"mcm","clk":"5348235022","pt":1646215768675,"mc":[{"id":"1.195453621","rc":[{"atl":[[40,0]],"id":6780934}],"con":true,"img":false}]}
{"op":"mcm","clk":"5348235033","pt":1646215768781,"mc":[{"id":"1.195453621","rc":[{"atb":[[20,0],[1.04,2.25]],"id":23806261}],"con":true,"img":false}]}
{"op":"mcm","clk":"5348235052","pt":1646215768941,"mc":[{"id":"1.195453621","rc":[{"atb":[[1.04,0.18]],"id":23806261}],"con":true,"img":false}]}
{"op":"mcm","clk":"5348235062","pt":1646215769096,"mc":[{"id":"1.195453621","rc":[{"atb":[[1.04,0]],"id":23806261}],"con":true,"img":false}]}
{"op":"mcm","clk":"5348235073","pt":1646215769149,"mc":[{"id":"1.195453621","rc":[{"atb":[[16.5,0.28]],"id":23806261}],"con":true,"img":false}]}
{"op":"mcm","clk":"5348235129","pt":1646215769772,"mc":[{"id":"1.195453621","rc":[{"atb":[[10.5,3.11],[9.8,0]],"id":6780934}],"con":true,"img":false}]}
{"op":"mcm","clk":"5348235145","pt":1646215769980,"mc":[{"id":"1.195453621","rc":[{"atb":[[10,2.5],[11,2]],"id":6780934}],"con":true,"img":false}]}
{"op":"mcm","clk":"5348235157","pt":1646215770086,"mc":[{"id":"1.195453621","rc":[{"atl":[[2.88,5.44]],"id":36463352}],"con":true,"img":false}]}
{"op":"mcm","clk":"5348235266","pt":1646215771080,"mc":[{"id":"1.195453621","rc":[{"atl":[[2.9,0]],"id":36463352}],"con":true,"img":false}]}
{"op":"mcm","clk":"5348235286","pt":1646215771289,"mc":[{"id":"1.195453621","rc":[{"atb":[[17,2]],"id":23806261},{"atl":[[2.86,4.57]],"id":36463352},{"atb":[[10,0]],"id":6780934}],"con":true,"img":false}]}
{"op":"mcm","clk":"5348235293","pt":1646215771392,"mc":[{"id":"1.195453621","rc":[{"atb":[[18,0]],"id":23806261}],"con":true,"img":false}]}
{"op":"mcm","clk":"5348235355","pt":1646215772078,"mc":[{"id":"1.195453621","rc":[{"atb":[[17.5,2.08]],"id":23806261}],"con":true,"img":false}]}
{"op":"mcm","clk":"5348235604","pt":1646215774639,"mc":[{"id":"1.195453621","rc":[{"atb":[[11.5,2.08]],"id":6780934}],"con":true,"img":false}]}
{"op":"mcm","clk":"5348235624","pt":1646215774847,"mc":[{"id":"1.195453621","rc":[{"atl":[[27,0],[28,1]],"id":6780934}],"con":true,"img":false}]}
{"op":"mcm","clk":"5348235868","pt":1646215777670,"mc":[{"id":"1.195453621","rc":[{"atl":[[2.92,0]],"id":36463352}],"con":true,"img":false}]}
{"op":"mcm","clk":"5348235941","pt":1646215778452,"mc":[{"id":"1.195453621","rc":[{"atl":[[2.84,6.53]],"id":36463352}],"con":true,"img":false}]}
{"op":"mcm","clk":"5348236076","pt":1646215780082,"mc":[{"id":"1.195453621","rc":[{"atl":[[2.86,0]],"id":36463352}],"con":true,"img":false}]}
{"op":"mcm","clk":"5348236095","pt":1646215780289,"mc":[{"id":"1.195453621","rc":[{"atl":[[2.82,4.63]],"id":36463352}],"con":true,"img":false}]}
{"op":"mcm","clk":"5348236288","pt":1646215782362,"mc":[{"id":"1.195453621","rc":[{"atl":[[2.88,0]],"id":36463352}],"con":true,"img":false}]}
{"op":"mcm","clk":"5348236539","pt":1646215784887,"mc":[{"id":"1.195453621","rc":[{"atl":[[2.8,5.44]],"id":36463352},{"atl":[[30,1.68]],"id":6780934}],"con":true,"img":false}]}
{"op":"mcm","clk":"5348236660","pt":1646215786192,"mc":[{"id":"1.195453621","rc":[{"atl":[[2.82,0]],"id":36463352}],"con":true,"img":false}]}
{"op":"mcm","clk":"5348236667","pt":1646215786297,"mc":[{"id":"1.195453621","rc":[{"atl":[[2.78,4.7]],"id":36463352}],"con":true,"img":false}]}
{"op":"mcm","clk":"5348236695","pt":1646215786567,"mc":[{"id":"1.195453621","rc":[{"atb":[[9,0],[9.4,4.16]],"id":6780934},{"atl":[[28,0],[30,0]],"id":6780934}],"con":true,"img":false}]}
{"op":"mcm","clk":"5348237110","pt":1646215790993,"mc":[{"id":"1.195453621","rc":[{"atl":[[2.84,0]],"id":36463352}],"con":true,"img":false}]}
{"op":"mcm","clk":"5348237187","pt":1646215791673,"mc":[{"id":"1.195453621","rc":[{"atl":[[2.76,6.53]],"id":36463352}],"con":true,"img":false}]}
{"op":"mcm","clk":"5348237198","pt":1646215791783,"mc":[{"id":"1.195453621","rc":[{"atl":[[36,2.09]],"id":6780934}],"con":true,"img":false}]}
{"op":"mcm","clk":"5348237208","pt":1646215791883,"mc":[{"id":"1.195453621","rc":[{"atl":[[32,4.84]],"id":6780934}],"con":true,"img":false}]}
{"op":"mcm","clk":"5348237223","pt":1646215792090,"mc":[{"id":"1.195453621","rc":[{"atl":[[2.78,0]],"id":36463352}],"con":true,"img":false}]}
{"op":"mcm","clk":"5348237235","pt":1646215792195,"mc":[{"id":"1.195453621","rc":[{"atl":[[2.74,4.77]],"id":36463352}],"con":true,"img":false}]}
{"op":"mcm","clk":"5348237511","pt":1646215794894,"mc":[{"id":"1.195453621","rc":[{"atl":[[40,3.13]],"id":6780934}],"con":true,"img":false}]}
{"op":"mcm","clk":"5348237605","pt":1646215795788,"mc":[{"id":"1.195453621","rc":[{"atb":[[10.5,0],[12,2.72]],"id":6780934}],"con":true,"img":false}]}
{"op":"mcm","clk":"5348237625","pt":1646215795993,"mc":[{"id":"1.195453621","rc":[{"atb":[[11,0],[12,4.72]],"id":6780934}],"con":true,"img":false}]}
{"op":"mcm","clk":"5348237647","pt":1646215796204,"mc":[{"id":"1.195453621","rc":[{"atb":[[11.5,4.08],[12,2.72]],"id":6780934}],"con":true,"img":false}]}
{"op":"mcm","clk":"5348237712","pt":1646215796793,"mc":[{"id":"1.195453621","rc":[{"atb":[[16.5,0.1],[1.04,2.25]],"id":40199925}],"con":true,"img":false}]}
{"op":"mcm","clk":"5348237721","pt":1646215796897,"mc":[{"id":"1.195453621","rc":[{"atb":[[1.04,0.18]],"id":40199925}],"con":true,"img":false}]}
{"op":"mcm","clk":"5348237744","pt":1646215797104,"mc":[{"id":"1.195453621","rc":[{"atl":[[2.8,0]],"id":36463352}],"con":true,"img":false}]}
