{"op":"mcm","clk":"5345985306","pt":1646174444265,"mc":[{"id":"1.195453627","marketDefinition":{"bspMarket":true,"turnInPlayEnabled":false,"persistenceEnabled":false,"marketBaseRate":7.0,"eventId":"31272494","eventTypeId":"4339","numberOfWinners":1,"bettingType":"ODDS","marketType":"WIN","marketTime":"2022-03-02T11:32:00.000Z","suspendTime":"2022-03-02T11:32:00.000Z","bspReconciled":false,"complete":true,"inPlay":false,"crossMatching":false,"runnersVoidable":false,"numberOfActiveRunners":6,"betDelay":0,"status":"OPEN","runners":[{"status":"ACTIVE","sortPriority":1,"id":39734233,"name":"1. Bernadette"},{"status":"ACTIVE","sortPriority":2,"id":38761677,"name":"2. General Payton"},{"status":"ACTIVE","sortPriority":3,"id":40324291,"name":"4. Reiko Langer"},{"status":"ACTIVE","sortPriority":4,"id":41818958,"name":"6. Armatree Arrow"},{"status":"ACTIVE","sortPriority":5,"id":38214982,"name":"7. Two Phones"},{"status":"ACTIVE","sortPriority":6,"id":27868829,"name":"8. My Gem"}],"regulators":["MR_INT"],"venue":"Traralgon","countryCode":"AU","discountAllowed":true,"timezone":"Australia/Sydney","openDate":"2022-03-02T08:31:00.000Z","version":4382425377,"name":"R10 395m Gr5","eventName":"Traralgon (AUS) 2nd Mar"},"rc":[],"con":true,"img":false}]}
{"op":"mcm","clk":"5346059623","pt":1646175788371,"mc":[{"id":"1.195453627","rc":[{"atb":[[2.74,46.92],[3.35,17.37],[2.64,99.58],[2.84,44.37],[2.94,21.04]],"id":39734233},{"atl":[[12,18.14],[9.8,15.11],[8.8,17.05],[14.5,14.78]],"id":39734233},{"spn":6.07,"spf":"NaN","id":39734233},{"atb":[[3.45,16.66],[3.2,37.11],[2.88,86.86],[3.95,13.83],[2.98,41.24]],"id":41818958},{"atl":[[16,8.86],[18.5,11.4],[22,9.5],[13.5,10.64]],"id":41818958},{"spn":8.72,"spf":"NaN","id":41818958},{"atb":[[4,13.6],[5,10.2],[3.25,72.58],[3.5,32.66],[3.75,29.69]],"id":38214982},{"atl":[[17,8.31],[19.5,7.19],[24,8.67],[29,7.12]],"id":38214982},{"spn":11.0,"spf":"NaN","id":38214982},{"atb":[[4.8,21.48],[4.3,49.48],[5.8,8.5],[5.3,18.98],[7.6,6.18]],"id":27868829},{"atl":[[65,3.11],[36,3.79],[90,2.24],[46,2.95]],"id":27868829},{"spn":21.8,"spf":"NaN","id":27868829},{"atb":[[1.8,204.13],[1.85,96.06],[1.9,90.72],[1.95,42.97],[2.1,37.11]],"id":38761677},{"atl":[[5.8,27.71],[5.3,30.94],[7.6,30.23],[6.6,35.63]],"id":38761677},{"spn":3.7,"spf":"NaN","id":38761677},{"atb":[[4,13.6],[5,10.2],[3.25,72.58],[3.5,32.66],[3.75,29.69]],"id":40324291},{"atl":[[17,8.31],[19.5,7.19],[24,8.67],[29,7.12]],"id":40324291},{"spn":11.0,"spf":"NaN","id":40324291}],"con":true,"img":false}]}
{"op":"mcm","clk":"5346061998","pt":1646175839944,"mc":[{"id":"1.195453627","rc":[{"atb":[[2.74,0],[3.35,0],[2.64,0],[2.84,0],[2.94,0]],"id":39734233},{"atl":[[12,0],[9.8,0],[8.8,0],[14.5,0]],"id":39734233},{"atb":[[3.45,0],[3.2,0],[2.88,0],[3.95,0],[2.98,0]],"id":41818958},{"atl":[[16,0],[18.5,0],[22,0],[13.5,0]],"id":41818958},{"atb":[[4,0],[5,0],[3.25,0],[3.5,0],[3.75,0]],"id":38214982},{"atl":[[17,0],[19.5,0],[24,0],[29,0]],"id":38214982},{"atb":[[4.8,0],[4.3,0],[5.8,0],[5.3,0],[7.6,0]],"id":27868829},{"atl":[[65,0],[36,0],[90,0],[46,0]],"id":27868829},{"atb":[[1.8,0],[1.85,0],[1.9,0],[1.95,0],[2.1,0]],"id":38761677},{"atl":[[5.8,0],[5.3,0],[7.6,0],[6.6,0]],"id":38761677},{"atb":[[4,0],[5,0],[3.25,0],[3.5,0],[3.75,0]],"id":40324291},{"atl":[[17,0],[19.5,0],[24,0],[29,0]],"id":40324291}],"con":true,"img":false}]}
{"op":"mcm","clk":"5346062228","pt":1646175844782,"mc":[{"id":"1.195453627","rc":[{"atb":[[2.74,46.92],[3.35,17.37],[2.64,99.58],[2.84,44.37],[2.94,21.04]],"id":39734233},{"atl":[[12,18.14],[9.8,15.11],[8.8,17.05],[14.5,14.78]],"id":39734233},{"atb":[[3.45,16.66],[3.2,37.11],[2.88,86.86],[3.95,13.83],[2.98,41.24]],"id":41818958},{"atl":[[16,8.86],[18.5,11.4],[22,9.5],[13.5,10.64]],"id":41818958},{"atb":[[4,13.6],[5,10.2],[3.25,72.58],[3.5,32.66],[3.75,29.69]],"id":38214982},{"atl":[[17,8.31],[19.5,7.19],[24,8.67],[29,7.12]],"id":38214982},{"atb":[[4.8,21.48],[4.3,49.48],[5.8,8.5],[5.3,18.98],[7.6,6.18]],"id":27868829},{"atl":[[65,3.11],[36,3.79],[90,2.24],[46,2.95]],"id":27868829},{"atb":[[1.8,204.13],[1.85,96.06],[1.9,90.72],[1.95,42.97],[2.1,37.11]],"id":38761677},{"atl":[[5.8,27.71],[5.3,30.94],[7.6,30.23],[6.6,35.63]],"id":38761677},{"atb":[[4,13.6],[5,10.2],[3.25,72.58],[3.5,32.66],[3.75,29.69]],"id":40324291},{"atl":[[17,8.31],[19.5,7.19],[24,8.67],[29,7.12]],"id":40324291}],"con":true,"img":false}]}
{"op":"mcm","clk":"5346105171","pt":1646176602702,"mc":[{"id":"1.195453627","marketDefinition":{"bspMarket":true,"turnInPlayEnabled":false,"persistenceEnabled":false,"marketBaseRate":7.0,"eventId":"31272494","eventTypeId":"4339","numberOfWinners":1,"bettingType":"ODDS","marketType":"WIN","marketTime":"2022-03-02T11:32:00.000Z","suspendTime":"2022-03-02T11:32:00.000Z","bspReconciled":false,"complete":true,"inPlay":false,"crossMatching":false,"runnersVoidable":false,"numberOfActiveRunners":6,"betDelay":0,"status":"OPEN","runners":[{"status":"ACTIVE","sortPriority":1,"id":39734233,"name":"1. Bernadette"},{"status":"ACTIVE","sortPriority":2,"id":38761677,"name":"2. General Payton"},{"status":"ACTIVE","sortPriority":3,"id":40324291,"name":"4. Reiko Langer"},{"status":"ACTIVE","sortPriority":4,"id":41818958,"name":"6. Armatree Arrow"},{"status":"ACTIVE","sortPriority":5,"id":38214982,"name":"7. Two Phones"},{"status":"ACTIVE","sortPriority":6,"id":27868829,"name":"8. My Gem"}],"regulators":["MR_INT"],"venue":"Traralgon","countryCode":"AU","discountAllowed":true,"timezone":"Australia/Sydney","openDate":"2022-03-02T08:31:00.000Z","version":4382425377,"name":"R10 395m Gr5","eventName":"Traralgon (AUS) 2nd Mar"},"rc":[{"atb":[[2.74,46.92],[3.35,17.37],[2.64,99.58],[2.84,44.37],[2.94,21.04]],"id":39734233},{"atl":[[12,18.14],[9.8,15.11],[8.8,17.05],[14.5,14.78]],"id":39734233},{"spn":6.07,"spf":"NaN","id":39734233},{"atb":[[3.45,16.66],[3.2,37.11],[2.88,86.86],[3.95,13.83],[2.98,41.24]],"id":41818958},{"atl":[[16,8.86],[18.5,11.4],[22,9.5],[13.5,10.64]],"id":41818958},{"spn":8.72,"spf":"NaN","id":41818958},{"atb":[[4,13.6],[5,10.2],[3.25,72.58],[3.5,32.66],[3.75,29.69]],"id":38214982},{"atl":[[17,8.31],[19.5,7.19],[24,8.67],[29,7.12]],"id":38214982},{"spn":11.0,"spf":"NaN","id":38214982},{"atb":[[4.8,21.48],[4.3,49.48],[5.8,8.5],[5.3,18.98],[7.6,6.18]],"id":27868829},{"atl":[[65,3.11],[36,3.79],[90,2.24],[46,2.95]],"id":27868829},{"spn":21.8,"spf":"NaN","id":27868829},{"atb":[[1.8,204.13],[1.85,96.06],[1.9,90.72],[1.95,42.97],[2.1,37.11]],"id":38761677},{"atl":[[5.8,27.71],[5.3,30.94],[7.6,30.23],[6.6,35.63]],"id":38761677},{"spn":3.7,"spf":"NaN","id":38761677},{"atb":[[4,13.6],[5,10.2],[3.25,72.58],[3.5,32.66],[3.75,29.69]],"id":40324291},{"atl":[[17,8.31],[19.5,7.19],[24,8.67],[29,7.12]],"id":40324291},{"spn":11.0,"spf":"NaN","id":40324291}],"con":true,"img":true}]}
{"op":"mcm","clk":"5346133635","pt":1646177096789,"mc":[{"id":"1.195453627","rc":[{"atb":[[5,0]],"id":38214982},{"atl":[[5,29.8]],"id":38214982},{"trd":[[5,20.4]],"ltp":5.0,"tv":20.4,"id":38214982},{"spn":4.5,"spf":"NaN","id":38214982}],"con":true,"img":false}]}
{"op":"mcm","clk":"5346133813","pt":1646177100502,"mc":[{"id":"1.195453627","rc":[{"atl":[[5,0.56]],"id":38214982},{"trd":[[5,78.9]],"ltp":5.0,"tv":78.9,"id":38214982}],"con":true,"img":false}]}
{"op":"mcm","clk":"5346136707","pt":1646177154868,"mc":[{"id":"1.195453627","rc":[{"atb":[[4,0],[3.25,0],[3.5,0],[3.75,0]],"id":38214982},{"atl":[[17,0],[19.5,0],[24,0],[29,0]],"id":38214982}],"con":true,"img":false}]}
{"op":"mcm","clk":"5346137122","pt":1646177162517,"mc":[{"id":"1.195453627","rc":[{"atb":[[4.5,10.5],[3,73.48],[3.25,32.66],[3.5,29.39],[3.75,13.36]],"id":38214982},{"atl":[[16,9.41],[18.5,8.06],[22,10.08],[27,8.14]],"id":38214982},{"spn":4.75,"spf":"NaN","id":38214982}],"con":true,"img":false}]}
{"op":"mcm","clk":"5346138676","pt":1646177190113,"mc":[{"id":"1.195453627","rc":[{"atl":[[6.6,8.64]],"id":38214982}],"con":true,"img":false}]}
{"op":"mcm","clk":"5346142600","pt":1646177268650,"mc":[{"id":"1.195453627","rc":[{"atl":[[6.6,0]],"id":38214982}],"con":true,"img":false}]}
{"op":"mcm","clk":"5346142607","pt":1646177268751,"mc":[{"id":"1.195453627","rc":[{"atl":[[6.4,8.64]],"id":38214982}],"con":true,"img":false}]}
{"op":"mcm","clk":"5346145077","pt":1646177325631,"mc":[{"id":"1.195453627","rc":[{"atl":[[6.4,0]],"id":38214982}],"con":true,"img":false}]}
{"op":"mcm","clk":"5346145079","pt":1646177325733,"mc":[{"id":"1.195453627","rc":[{"atl":[[6,8.64]],"id":38214982}],"con":true,"img":false}]}
{"op":"mcm","clk":"5346153938","pt":1646177510540,"mc":[{"id":"1.195453627","rc":[{"spl":[[1.01,100]],"id":38214982},{"spn":3.48,"spf":1.0,"id":38214982}],"con":true,"img":false}]}
{"op":"mcm","clk":"5346155598","pt":1646177545481,"mc":[{"id":"1.195453627","rc":[{"atb":[[3.4,1.6]],"id":39734233},{"atb":[[4,1.51]],"id":41818958},{"atb":[[4.6,1.47]],"id":38214982},{"atb":[[2.12,1.6]],"id":38761677},{"atb":[[5.1,1.56]],"id":40324291}],"con":true,"img":false}]}
{"op":"mcm","clk":"5346155639","pt":1646177546152,"mc":[{"id":"1.195453627","rc":[{"atl":[[8.6,1.32]],"id":39734233},{"atl":[[13,1.31]],"id":41818958},{"atl":[[34,1.34]],"id":27868829},{"atl":[[5.2,1.23]],"id":38761677},{"atl":[[16.5,1.32]],"id":40324291}],"con":true,"img":false}]}
{"op":"mcm","clk":"5346157196","pt":1646177578311,"mc":[{"id":"1.195453627","marketDefinition":{"bspMarket":true,"turnInPlayEnabled":false,"persistenceEnabled":false,"marketBaseRate":7.0,"eventId":"31272494","eventTypeId":"4339","numberOfWinners":1,"bettingType":"ODDS","marketType":"WIN","marketTime":"2022-03-02T11:32:00.000Z","suspendTime":"2022-03-02T11:32:00.000Z","bspReconciled":false,"complete":true,"inPlay":false,"crossMatching":true,"runnersVoidable":false,"numberOfActiveRunners":6,"betDelay":0,"status":"OPEN","runners":[{"status":"ACTIVE","sortPriority":1,"id":39734233,"name":"1. Bernadette"},{"status":"ACTIVE","sortPriority":2,"id":38761677,"name":"2. General Payton"},{"status":"ACTIVE","sortPriority":3,"id":40324291,"name":"4. Reiko Langer"},{"status":"ACTIVE","sortPriority":4,"id":41818958,"name":"6. Armatree Arrow"},{"status":"ACTIVE","sortPriority":5,"id":38214982,"name":"7. Two Phones"},{"status":"ACTIVE","sortPriority":6,"id":27868829,"name":"8. My Gem"}],"regulators":["MR_INT"],"venue":"Traralgon","countryCode":"AU","discountAllowed":true,"timezone":"Australia/Sydney","openDate":"2022-03-02T08:31:00.000Z","version":4382425377,"name":"R10 395m Gr5","eventName":"Traralgon (AUS) 2nd Mar"},"rc":[],"con":true,"img":false}]}
{"op":"mcm","clk":"5346188634","pt":1646178210287,"mc":[{"id":"1.195453627","rc":[{"spn":6.0,"spf":"NaN","id":39734233},{"spn":8.5,"spf":"NaN","id":41818958},{"atl":[[6.4,20]],"id":38214982},{"spn":3.51,"spf":1.0,"id":38214982},{"spn":20.8,"spf":"NaN","id":27868829},{"spn":3.66,"spf":"NaN","id":38761677},{"spn":10.8,"spf":"NaN","id":40324291}],"con":true,"img":false}]}
{"op":"mcm","clk":"5346188646","pt":1646178210593,"mc":[{"id":"1.195453627","rc":[{"atl":[[5.9,1.27]],"id":38214982}],"con":true,"img":false}]}
{"op":"mcm","clk":"5346220918","pt":1646178842511,"mc":[{"id":"1.195453627","rc":[{"spl":[[1.01,150]],"id":38214982},{"spn":3.34,"spf":1.0,"id":38214982}],"con":true,"img":false}]}
{"op":"mcm","clk":"5346238839","pt":1646179192807,"mc":[{"id":"1.195453627","rc":[{"atl":[[6,0]],"id":38214982}],"con":true,"img":false}]}
{"op":"mcm","clk":"5346238846","pt":1646179192914,"mc":[{"id":"1.195453627","rc":[{"atl":[[5.8,8.64]],"id":38214982}],"con":true,"img":false}]}
{"op":"mcm","clk":"5346238863","pt":1646179193328,"mc":[{"id":"1.195453627","rc":[{"atl":[[5.9,0]],"id":38214982}],"con":true,"img":false}]}
{"op":"mcm","clk":"5346238871","pt":1646179193429,"mc":[{"id":"1.195453627","rc":[{"atl":[[5.7,1.27]],"id":38214982}],"con":true,"img":false}]}
{"op":"mcm","clk":"5346238881","pt":1646179193690,"mc":[{"id":"1.195453627","rc":[{"atb":[[4.6,0]],"id":38214982}],"con":true,"img":false}]}
{"op":"mcm","clk":"5346238886","pt":1646179193793,"mc":[{"id":"1.195453627","rc":[{"atb":[[1.01,1.47]],"id":38214982}],"con":true,"img":false}]}
{"op":"mcm","clk":"5346238913","pt":1646179194510,"mc":[{"id":"1.195453627","rc":[{"atl":[[5,0],[5.8,1.88],[5.7,0]],"id":38214982},{"trd":[[5.8,13.52],[5,80.02],[5.7,2.55]],"ltp":5.8,"tv":96.08,"id":38214982}],"con":true,"img":false}]}
{"op":"mcm","clk":"5346238931","pt":1646179194921,"mc":[{"id":"1.195453627","rc":[{"atb":[[1.01,0]],"id":38214982}],"con":true,"img":false}]}
{"op":"mcm","clk":"5346238935","pt":1646179195024,"mc":[{"id":"1.195453627","rc":[{"atb":[[4.5,12.14],[4.6,1.47]],"id":38214982}],"con":true,"img":false}]}
{"op":"mcm","clk":"5346239792","pt":1646179211626,"mc":[{"id":"1.195453627","rc":[{"atb":[[2.74,46.93],[3.35,17.37],[3.4,1.6],[2.64,99.59],[2.84,44.38],[2.94,21.04]],"id":39734233},{"atl":[[8.6,1.32],[12,18.14],[9.8,15.11],[8.8,17.05],[14.5,14.78]],"id":39734233},{"atb":[[4,1.51],[3.45,16.66],[3.2,37.11],[2.88,86.87],[3.95,13.83],[2.98,41.24]],"id":41818958},{"atl":[[16,8.86],[18.5,11.4],[22,9.5],[13,1.31],[13.5,10.64]],"id":41818958},{"atb":[[4.5,12.14],[4.6,1.47],[3,73.49],[3.25,32.66],[3.5,29.39],[3.75,13.36]],"id":38214982},{"atl":[[16,9.41],[18.5,8.06],[5.8,0],[22,10.08],[27,8.15]],"id":38214982},{"trd":[[5.8,13.52],[5,80.03],[5.7,2.55]],"ltp":5.8,"tv":96.1,"id":38214982},{"atb":[[4.8,21.48],[4.3,49.49],[5.8,8.5],[5.3,18.98],[7.6,6.18]],"id":27868829},{"atl":[[65,3.11],[34,1.34],[36,3.8],[90,2.24],[46,2.95]],"id":27868829},{"atb":[[1.8,204.15],[1.85,96.07],[2.12,1.6],[1.9,90.73],[1.95,42.98],[2.1,37.11]],"id":38761677},{"atl":[[5.8,27.72],[5.3,30.94],[7.6,30.24],[5.2,1.23],[6.6,35.63]],"id":38761677},{"atb":[[4,13.61],[5.1,1.56],[5,10.2],[3.25,72.58],[3.5,32.66],[3.75,29.69]],"id":40324291},{"atl":[[16.5,1.32],[17,8.31],[19.5,7.19],[24,8.67],[29,7.12]],"id":40324291}],"con":true,"img":false}]}
{"op":"mcm","clk":"5346239794","pt":1646179211727,"mc":[{"id":"1.195453627","rc":[{"atl":[[5.7,1.88]],"id":38214982}],"con":true,"img":false}]}
{"op":"mcm","clk":"5346239814","pt":1646179212444,"mc":[{"id":"1.195453627","rc":[{"atb":[[4.6,0]],"id":38214982}],"con":true,"img":false}]}
{"op":"mcm","clk":"5346239820","pt":1646179212546,"mc":[{"id":"1.195453627","rc":[{"atb":[[1.01,1.47]],"id":38214982}],"con":true,"img":false}]}
{"op":"mcm","clk":"5346316482","pt":1646180692729,"mc":[{"id":"1.195453627","rc":[{"atb":[[4.5,1.64],[3,0],[3.25,0],[3.5,0],[3.75,0]],"id":38214982},{"atl":[[16,0],[18.5,0],[22,0],[27,0]],"id":38214982},{"spn":1.03,"spf":1.0,"id":38214982},{"atb":[[4.8,0],[4.3,0],[5.8,0],[5.3,0],[7.6,0]],"id":27868829},{"atl":[[65,0],[36,0],[90,0],[46,0]],"id":27868829},{"spn":1.0,"spf":"NaN","id":27868829},{"atb":[[4,0],[5,0],[3.25,0],[3.5,0],[3.75,0]],"id":40324291},{"atl":[[17,0],[19.5,0],[24,0],[29,0]],"id":40324291}],"con":true,"img":false}]}
{"op":"mcm","clk":"5346316513","pt":1646180693243,"mc":[{"id":"1.195453627","rc":[{"atb":[[4.5,0]],"id":38214982},{"atb":[[1.02,1.55]],"id":27868829},{"atl":[[34,0]],"id":27868829},{"atb":[[5.1,0]],"id":40324291},{"atl":[[16.5,0]],"id":40324291}],"con":true,"img":false}]}
{"op":"mcm","clk":"5346316522","pt":1646180693346,"mc":[{"id":"1.195453627","rc":[{"atb":[[1.02,1.64]],"id":38214982},{"atl":[[990,1.34]],"id":27868829},{"atb":[[1.02,1.56]],"id":40324291},{"atl":[[990,1.32]],"id":40324291}],"con":true,"img":false}]}
{"op":"mcm","clk":"5346317059","pt":1646180703371,"mc":[{"id":"1.195453627","rc":[{"atb":[[4.5,10.5],[3,73.49],[3.25,32.66],[3.5,29.39],[3.75,13.36]],"id":38214982},{"atl":[[16,9.41],[18.5,8.06],[22,10.08],[27,8.15]],"id":38214982},{"atb":[[4.8,22.02],[4.3,50.72],[5.8,8.72],[5.3,19.46],[7.6,6.34]],"id":27868829},{"atl":[[65,3.07],[36,3.74],[90,2.21],[46,2.91]],"id":27868829},{"atb":[[4,13.95],[5,10.46],[3.25,74.4],[3.5,33.48],[3.75,30.43]],"id":40324291},{"atl":[[17,8.18],[19.5,7.08],[24,8.54],[29,7.01]],"id":40324291}],"con":true,"img":false}]}
{"op":"mcm","clk":"5346317116","pt":1646180704140,"mc":[{"id":"1.195453627","rc":[{"atb":[[1.02,0]],"id":38214982},{"atl":[[990,0]],"id":27868829},{"atl":[[990,0]],"id":40324291}],"con":true,"img":false}]}
{"op":"mcm","clk":"5346317126","pt":1646180704245,"mc":[{"id":"1.195453627","rc":[{"atb":[[4.6,1.64]],"id":38214982},{"atl":[[34,1.34]],"id":27868829},{"atl":[[16.5,1.32]],"id":40324291}],"con":true,"img":false}]}
{"op":"mcm","clk":"5346317997","pt":1646180720383,"mc":[{"id":"1.195453627","rc":[{"atb":[[1.02,0]],"id":40324291}],"con":true,"img":false}]}
{"op":"mcm","clk":"5346318006","pt":1646180720484,"mc":[{"id":"1.195453627","rc":[{"atb":[[5.1,1.56]],"id":40324291}],"con":true,"img":false}]}
{"op":"mcm","clk":"5346401629","pt":1646182002789,"mc":[{"id":"1.195453627","marketDefinition":{"bspMarket":true,"turnInPlayEnabled":false,"persistenceEnabled":false,"marketBaseRate":7.0,"eventId":"31272494","eventTypeId":"4339","numberOfWinners":1,"bettingType":"ODDS","marketType":"WIN","marketTime":"2022-03-02T11:32:00.000Z","suspendTime":"2022-03-02T11:32:00.000Z","bspReconciled":false,"complete":true,"inPlay":false,"crossMatching":true,"runnersVoidable":false,"numberOfActiveRunners":6,"betDelay":0,"status":"OPEN","runners":[{"status":"ACTIVE","sortPriority":1,"id":39734233,"name":"1. Bernadette"},{"status":"ACTIVE","sortPriority":2,"id":38761677,"name":"2. General Payton"},{"status":"ACTIVE","sortPriority":3,"id":40324291,"name":"4. Reiko Langer"},{"status":"ACTIVE","sortPriority":4,"id":41818958,"name":"6. Armatree Arrow"},{"status":"ACTIVE","sortPriority":5,"id":38214982,"name":"7. Two Phones"},{"status":"ACTIVE","sortPriority":6,"id":27868829,"name":"8. My Gem"}],"regulators":["MR_INT"],"venue":"Traralgon","countryCode":"AU","discountAllowed":true,"timezone":"Australia/Sydney","openDate":"2022-03-02T08:31:00.000Z","version":4382425377,"name":"R10 395m Gr5","eventName":"Traralgon (AUS) 2nd Mar"},"rc":[{"atb":[[2.74,46.93],[3.35,17.37],[3.4,1.6],[2.64,99.59],[2.84,44.38],[2.94,21.04]],"id":39734233},{"atl":[[8.6,1.32],[12,18.14],[9.8,15.11],[8.8,17.05],[14.5,14.78]],"id":39734233},{"spn":6.0,"spf":"NaN","id":39734233},{"atb":[[4,1.51],[3.45,16.66],[3.2,37.11],[2.88,86.87],[3.95,13.83],[2.98,41.24]],"id":41818958},{"atl":[[16,8.86],[18.5,11.4],[22,9.5],[13,1.31],[13.5,10.64]],"id":41818958},{"spn":8.5,"spf":"NaN","id":41818958},{"atb":[[4.5,10.5],[1.01,1.47],[4.6,1.64],[3,73.49],[3.25,32.66],[3.5,29.39],[3.75,13.36]],"id":38214982},{"spl":[[1.01,150]],"id":38214982},{"atl":[[16,9.41],[18.5,8.06],[6.4,20],[22,10.08],[5.7,1.88],[27,8.15]],"id":38214982},{"trd":[[5.8,13.52],[5,80.03],[5.7,2.55]],"ltp":5.8,"tv":96.1,"id":38214982},{"spn":3.34,"spf":1.0,"id":38214982},{"atb":[[4.8,22.02],[4.3,50.72],[5.8,8.72],[5.3,19.46],[1.02,1.55],[7.6,6.34]],"id":27868829},{"atl":[[65,3.07],[34,1.34],[36,3.74],[90,2.21],[46,2.91]],"id":27868829},{"spn":20.8,"spf":"NaN","id":27868829},{"atb":[[1.8,204.15],[1.85,96.07],[2.12,1.6],[1.9,90.73],[1.95,42.98],[2.1,37.11]],"id":38761677},{"atl":[[5.8,27.72],[5.3,30.94],[7.6,30.24],[5.2,1.23],[6.6,35.63]],"id":38761677},{"spn":3.66,"spf":"NaN","id":38761677},{"atb":[[4,13.95],[5.1,1.56],[5,10.46],[3.25,74.4],[3.5,33.48],[3.75,30.43]],"id":40324291},{"atl":[[16.5,1.32],[17,8.18],[19.5,7.08],[24,8.54],[29,7.01]],"id":40324291},{"spn":10.8,"spf":"NaN","id":40324291}],"con":true,"img":true}]}
{"op":"mcm","clk":"5346441263","pt":1646182545026,"mc":[{"id":"1.195453627","rc":[{"atl":[[6.4,42]],"id":38214982},{"spn":3.34,"spf":1.0,"id":38214982},{"spn":20.8,"spf":"NaN","id":27868829}],"con":true,"img":false}]}
{"op":"mcm","clk":"5346591720","pt":1646184894416,"mc":[{"id":"1.195453627","rc":[{"atb":[[2.74,47],[3.35,17.4],[3.4,1.6],[2.64,99.74],[2.84,44.45],[2.94,21.08]],"id":39734233},{"atl":[[8.6,1.32],[12,18.17],[9.8,15.14],[8.8,17.08],[14.5,14.8]],"id":39734233},{"atb":[[4,1.51],[3.45,16.69],[3.2,37.17],[2.88,87.01],[3.95,13.86],[2.98,41.31]],"id":41818958},{"atl":[[16,8.88],[18.5,11.42],[22,9.52],[13,1.31],[13.5,10.66]],"id":41818958},{"atb":[[4.5,0],[1.01,1.47],[4.6,1.64],[3,0],[3.25,0],[3.5,0],[3.75,0]],"id":38214982},{"atl":[[16,0],[18.5,0],[22,0],[27,0]],"id":38214982},{"trd":[[5.8,13.53],[5,80.09],[5.7,2.55]],"ltp":5.8,"tv":96.17,"id":38214982},{"spn":1.03,"spf":1.0,"id":38214982},{"atb":[[4.8,22.06],[4.3,50.8],[5.8,8.73],[5.3,19.49],[1.02,1.55],[7.6,6.35]],"id":27868829},{"atl":[[65,3.07],[34,1.34],[36,3.75],[90,2.21],[46,2.91]],"id":27868829},{"atb":[[1.8,204.48],[1.85,96.22],[2.12,1.6],[1.9,90.88],[1.95,43.05],[2.1,37.17]],"id":38761677},{"atl":[[5.8,27.76],[5.3,30.99],[7.6,30.29],[5.2,1.23],[6.6,35.69]],"id":38761677},{"atb":[[4,0],[5.1,1.57],[5,0],[3.25,0],[3.5,0],[3.75,0]],"id":40324291},{"atl":[[16.5,1.32],[17,0],[19.5,0],[24,0],[29,0]],"id":40324291}],"con":true,"img":false}]}
{"op":"mcm","clk":"5346591760","pt":1646184895142,"mc":[{"id":"1.195453627","rc":[{"atb":[[4.6,0]],"id":38214982},{"atb":[[5.1,0]],"id":40324291},{"atl":[[16.5,0]],"id":40324291}],"con":true,"img":false}]}
{"op":"mcm","clk":"5346591764","pt":1646184895245,"mc":[{"id":"1.195453627","rc":[{"atb":[[1.02,1.64]],"id":38214982},{"atb":[[1.02,1.57]],"id":40324291},{"atl":[[990,1.32]],"id":40324291}],"con":true,"img":false}]}
{"op":"mcm","clk":"5346593216","pt":1646184920641,"mc":[{"id":"1.195453627","rc":[{"atb":[[4.5,10.51],[3,73.61],[3.25,32.71],[3.5,29.44],[3.75,13.38]],"id":38214982},{"atl":[[16,9.42],[18.5,8.08],[22,10.1],[27,8.16]],"id":38214982},{"atb":[[4,13.97],[5,10.48],[3.25,74.52],[3.5,33.53],[3.75,30.48]],"id":40324291},{"atl":[[17,8.2],[19.5,7.09],[24,8.55],[29,7.02]],"id":40324291}],"con":true,"img":false}]}
{"op":"mcm","clk":"5346593274","pt":1646184921476,"mc":[{"id":"1.195453627","rc":[{"atb":[[1.02,0]],"id":38214982},{"atl":[[990,0]],"id":40324291}],"con":true,"img":false}]}
{"op":"mcm","clk":"5346593285","pt":1646184921528,"mc":[{"id":"1.195453627","rc":[{"atb":[[4.6,1.64]],"id":38214982},{"atl":[[16.5,1.32]],"id":40324291}],"con":true,"img":false}]}
{"op":"mcm","clk":"5346700612","pt":1646186578133,"mc":[{"id":"1.195453627","rc":[{"spn":3.34,"spf":1.0,"id":38214982},{"atb":[[1.02,0]],"id":40324291},{"spn":10.75,"spf":"NaN","id":40324291}],"con":true,"img":false}]}
{"op":"mcm","clk":"5346700623","pt":1646186578184,"mc":[{"id":"1.195453627","rc":[{"atb":[[5.1,1.57]],"id":40324291}],"con":true,"img":false}]}
{"op":"mcm","clk":"5346767983","pt":1646187402734,"mc":[{"id":"1.195453627","marketDefinition":{"bspMarket":true,"turnInPlayEnabled":false,"persistenceEnabled":false,"marketBaseRate":7.0,"eventId":"31272494","eventTypeId":"4339","numberOfWinners":1,"bettingType":"ODDS","marketType":"WIN","marketTime":"2022-03-02T11:32:00.000Z","suspendTime":"2022-03-02T11:32:00.000Z","bspReconciled":false,"complete":true,"inPlay":false,"crossMatching":true,"runnersVoidable":false,"numberOfActiveRunners":6,"betDelay":0,"status":"OPEN","runners":[{"status":"ACTIVE","sortPriority":1,"id":39734233,"name":"1. Bernadette"},{"status":"ACTIVE","sortPriority":2,"id":38761677,"name":"2. General Payton"},{"status":"ACTIVE","sortPriority":3,"id":40324291,"name":"4. Reiko Langer"},{"status":"ACTIVE","sortPriority":4,"id":41818958,"name":"6. Armatree Arrow"},{"status":"ACTIVE","sortPriority":5,"id":38214982,"name":"7. Two Phones"},{"status":"ACTIVE","sortPriority":6,"id":27868829,"name":"8. My Gem"}],"regulators":["MR_INT"],"venue":"Traralgon","countryCode":"AU","discountAllowed":true,"timezone":"Australia/Sydney","openDate":"2022-03-02T08:31:00.000Z","version":4382425377,"name":"R10 395m Gr5","eventName":"Traralgon (AUS) 2nd Mar"},"rc":[{"atb":[[2.74,47],[3.35,17.4],[3.4,1.6],[2.64,99.74],[2.84,44.45],[2.94,21.08]],"id":39734233},{"atl":[[8.6,1.32],[12,18.17],[9.8,15.14],[8.8,17.08],[14.5,14.8]],"id":39734233},{"spn":6.0,"spf":"NaN","id":39734233},{"atb":[[4,1.51],[3.45,16.69],[3.2,37.17],[2.88,87.01],[3.95,13.86],[2.98,41.31]],"id":41818958},{"atl":[[16,8.88],[18.5,11.42],[22,9.52],[13,1.31],[13.5,10.66]],"id":41818958},{"spn":8.5,"spf":"NaN","id":41818958},{"atb":[[4.5,10.51],[1.01,1.47],[4.6,1.64],[3,73.61],[3.25,32.71],[3.5,29.44],[3.75,13.38]],"id":38214982},{"spl":[[1.01,150]],"id":38214982},{"atl":[[16,9.42],[18.5,8.08],[6.4,42],[22,10.1],[5.7,1.88],[27,8.16]],"id":38214982},{"trd":[[5.8,13.53],[5,80.09],[5.7,2.55]],"ltp":5.8,"tv":96.17,"id":38214982},{"spn":3.34,"spf":1.0,"id":38214982},{"atb":[[4.8,22.06],[4.3,50.8],[5.8,8.73],[5.3,19.49],[1.02,1.55],[7.6,6.35]],"id":27868829},{"atl":[[65,3.07],[34,1.34],[36,3.75],[90,2.21],[46,2.91]],"id":27868829},{"spn":20.8,"spf":"NaN","id":27868829},{"atb":[[1.8,204.48],[1.85,96.22],[2.12,1.6],[1.9,90.88],[1.95,43.05],[2.1,37.17]],"id":38761677},{"atl":[[5.8,27.76],[5.3,30.99],[7.6,30.29],[5.2,1.23],[6.6,35.69]],"id":38761677},{"spn":3.66,"spf":"NaN","id":38761677},{"atb":[[4,13.97],[5.1,1.57],[5,10.48],[3.25,74.52],[3.5,33.53],[3.75,30.48]],"id":40324291},{"atl":[[16.5,1.32],[17,8.2],[19.5,7.09],[24,8.55],[29,7.02]],"id":40324291},{"spn":10.8,"spf":"NaN","id":40324291}],"con":true,"img":true}]}
{"op":"mcm","clk":"5347092534","pt":1646192802713,"mc":[{"id":"1.195453627","marketDefinition":{"bspMarket":true,"turnInPlayEnabled":false,"persistenceEnabled":false,"marketBaseRate":7.0,"eventId":"31272494","eventTypeId":"4339","numberOfWinners":1,"bettingType":"ODDS","marketType":"WIN","marketTime":"2022-03-02T11:32:00.000Z","suspendTime":"2022-03-02T11:32:00.000Z","bspReconciled":false,"complete":true,"inPlay":false,"crossMatching":true,"runnersVoidable":false,"numberOfActiveRunners":6,"betDelay":0,"status":"OPEN","runners":[{"status":"ACTIVE","sortPriority":1,"id":39734233,"name":"1. Bernadette"},{"status":"ACTIVE","sortPriority":2,"id":38761677,"name":"2. General Payton"},{"status":"ACTIVE","sortPriority":3,"id":40324291,"name":"4. Reiko Langer"},{"status":"ACTIVE","sortPriority":4,"id":41818958,"name":"6. Armatree Arrow"},{"status":"ACTIVE","sortPriority":5,"id":38214982,"name":"7. Two Phones"},{"status":"ACTIVE","sortPriority":6,"id":27868829,"name":"8. My Gem"}],"regulators":["MR_INT"],"venue":"Traralgon","countryCode":"AU","discountAllowed":true,"timezone":"Australia/Sydney","openDate":"2022-03-02T08:31:00.000Z","version":4382425377,"name":"R10 395m Gr5","eventName":"Traralgon (AUS) 2nd Mar"},"rc":[{"atb":[[2.74,47.08],[3.35,17.42],[3.4,1.6],[2.64,99.91],[2.84,44.52],[2.94,21.11]],"id":39734233},{"atl":[[8.6,1.32],[12,18.2],[9.8,15.16],[8.8,17.11],[14.5,14.83]],"id":39734233},{"spn":6.0,"spf":"NaN","id":39734233},{"atb":[[4,1.51],[3.45,16.71],[3.2,37.24],[2.88,87.15],[3.95,13.88],[2.98,41.38]],"id":41818958},{"atl":[[16,8.89],[18.5,11.44],[22,9.53],[13,1.31],[13.5,10.67]],"id":41818958},{"spn":8.5,"spf":"NaN","id":41818958},{"atb":[[4.5,10.53],[1.01,1.47],[4.6,1.64],[3,73.73],[3.25,32.77],[3.5,29.49],[3.75,13.4]],"id":38214982},{"spl":[[1.01,150]],"id":38214982},{"atl":[[16,9.44],[18.5,8.09],[6.4,42],[22,10.12],[5.7,1.88],[27,8.17]],"id":38214982},{"trd":[[5.8,13.54],[5,80.16],[5.7,2.56]],"ltp":5.8,"tv":96.25,"id":38214982},{"spn":3.34,"spf":1.0,"id":38214982},{"atb":[[4.8,22.09],[4.3,50.89],[5.8,8.75],[5.3,19.53],[1.02,1.55],[7.6,6.36]],"id":27868829},{"atl":[[65,3.08],[34,1.34],[36,3.75],[90,2.21],[46,2.92]],"id":27868829},{"spn":20.8,"spf":"NaN","id":27868829},{"atb":[[1.8,204.82],[1.85,96.38],[2.12,1.6],[1.9,91.03],[1.95,43.12],[2.1,37.24]],"id":38761677},{"atl":[[5.8,27.81],[5.3,31.04],[7.6,30.34],[5.2,1.23],[6.6,35.75]],"id":38761677},{"spn":3.66,"spf":"NaN","id":38761677},{"atb":[[4,13.99],[5.1,1.56],[5,10.49],[3.25,74.65],[3.5,33.59],[3.75,30.53]],"id":40324291},{"atl":[[16.5,1.32],[17,8.21],[19.5,7.1],[24,8.57],[29,7.04]],"id":40324291},{"spn":10.8,"spf":"NaN","id":40324291}],"con":true,"img":true}]}
{"op":"mcm","clk":"5347352149","pt":1646197690010,"mc":[{"id":"1.195453627","rc":[{"atb":[[2.74,47.07],[3.35,17.42],[3.4,1.6],[2.64,99.87],[2.84,44.5],[2.94,21.1]],"id":39734233},{"atl":[[8.6,1.32],[12,18.19],[9.8,15.16],[8.8,17.1],[14.5,14.82]],"id":39734233},{"atb":[[4,1.51],[3.45,16.71],[3.2,37.22],[2.88,87.12],[3.95,13.87],[2.98,41.36]],"id":41818958},{"atl":[[16,8.89],[18.5,11.43],[22,9.53],[13,1.31],[13.5,10.67]],"id":41818958},{"atb":[[4.5,10.53],[1.01,1.47],[4.6,1.64],[3,73.71],[3.25,32.76],[3.5,29.48],[3.75,13.4]],"id":38214982},{"atl":[[16,9.44],[18.5,8.09],[22,10.11],[27,8.17]],"id":38214982},{"trd":[[5.8,13.54],[5,80.14],[5.7,2.56]],"ltp":5.8,"tv":96.24,"id":38214982},{"spn":3.34,"spf":1.0,"id":38214982},{"atb":[[4.8,22.09],[4.3,50.87],[5.8,8.74],[5.3,19.52],[1.02,1.55],[7.6,6.36]],"id":27868829},{"atl":[[65,3.07],[34,1.34],[36,3.75],[90,2.21],[46,2.92]],"id":27868829},{"atb":[[1.8,204.75],[1.85,96.35],[2.12,1.6],[1.9,91],[1.95,43.1],[2.1,37.22]],"id":38761677},{"atl":[[5.8,27.8],[5.3,31.03],[3.7,8.19],[7.6,30.33],[5.2,1.23],[6.6,35.74]],"id":38761677},{"spn":2.91,"spf":"NaN","id":38761677},{"atb":[[4,13.99],[5.1,1.57],[5,10.49],[3.25,74.62],[3.5,33.57],[3.75,30.52]],"id":40324291},{"atl":[[16.5,1.32],[17,8.21],[19.5,7.1],[24,8.56],[29,7.03]],"id":40324291},{"spn":10.8,"spf":"NaN","id":40324291}],"con":true,"img":false}]}
{"op":"mcm","clk":"5347428394","pt":1646199190110,"mc":[{"id":"1.195453627","rc":[{"atl":[[3.7,0]],"id":38761677},{"spn":3.66,"spf":"NaN","id":38761677}],"con":true,"img":false}]}
{"op":"mcm","clk":"5347428399","pt":1646199190211,"mc":[{"id":"1.195453627","rc":[{"atl":[[3.85,8.19]],"id":38761677}],"con":true,"img":false}]}
{"op":"mcm","clk":"5347478595","pt":1646200292748,"mc":[{"id":"1.195453627","rc":[{"atl":[[2.8,4.92]],"id":38761677},{"spn":2.46,"spf":"NaN","id":38761677}],"con":true,"img":false}]}
{"op":"mcm","clk":"5347739579","pt":1646206797548,"mc":[{"id":"1.195453627","rc":[{"atb":[[2.74,47.05],[3.35,17.41],[3.4,1.6],[2.64,99.85],[2.84,44.49],[2.94,21.1]],"id":39734233},{"atl":[[8.6,1.32],[12,18.19],[9.8,15.15],[8.8,17.1],[14.5,14.82]],"id":39734233},{"atb":[[4,1.51],[3.45,16.7],[3.2,37.21],[2.88,87.1],[3.95,13.87],[2.98,41.35]],"id":41818958},{"atl":[[16,8.89],[18.5,11.43],[22,9.53],[13,1.31],[13.5,10.67]],"id":41818958},{"atb":[[4.5,10.52],[1.01,1.47],[4.6,1.64],[3,73.68],[3.25,32.75],[3.5,29.47],[3.75,13.4]],"id":38214982},{"atl":[[16,9.43],[18.5,8.08],[6.4,62],[22,10.11],[27,8.17]],"id":38214982},{"trd":[[5.8,13.53],[5,80.13],[5.7,2.56]],"ltp":5.8,"tv":96.22,"id":38214982},{"atb":[[4.8,22.08],[4.3,50.86],[5.8,8.74],[5.3,19.51],[1.02,1.55],[7.6,6.35]],"id":27868829},{"atl":[[65,3.07],[34,1.34],[36,3.75],[90,2.21],[46,2.92]],"id":27868829},{"atb":[[1.8,204.69],[1.85,96.32],[2.12,1.6],[1.9,90.97],[1.95,43.09],[2.1,37.21]],"id":38761677},{"atl":[[2.8,4.93],[3.85,8.18],[5.8,27.79],[5.3,31.02],[7.6,30.32],[5.2,1.23],[6.6,35.73]],"id":38761677},{"atb":[[4,13.99],[5.1,1.57],[5,10.49],[3.25,74.6],[3.5,33.56],[3.75,30.51]],"id":40324291},{"atl":[[16.5,1.32],[17,8.2],[19.5,7.1],[24,8.56],[29,7.03]],"id":40324291}],"con":true,"img":false}]}
{"op":"mcm","clk":"5347856304","pt":1646209091314,"mc":[{"id":"1.195453627","rc":[{"atl":[[3.85,0]],"id":38761677}],"con":true,"img":false}]}
{"op":"mcm","clk":"5347856311","pt":1646209091416,"mc":[{"id":"1.195453627","rc":[{"atl":[[3.9,8.18]],"id":38761677}],"con":true,"img":false}]}
{"op":"mcm","clk":"5347991482","pt":1646211993207,"mc":[{"id":"1.195453627","rc":[{"atb":[[2.88,4],[2.74,46.98],[3.35,17.39],[3.4,1.6],[2.64,99.69],[2.84,44.42],[2.94,21.06]],"id":39734233},{"atl":[[8.6,1.32],[12,18.16],[9.8,15.13],[8.8,17.07],[14.5,14.8]],"id":39734233},{"atb":[[4,1.5],[3.45,16.68],[3.2,37.15],[2.88,86.96],[3.95,13.85],[2.98,41.28],[3.25,3.33]],"id":41818958},{"atl":[[16,8.87],[18.5,11.41],[22,9.51],[13,1.31],[13.5,10.65]],"id":41818958},{"atb":[[4.5,10.51],[1.01,1.47],[4.6,1.64],[3,73.57],[3.25,32.69],[3.55,2.94],[3.5,29.42],[3.75,13.37]],"id":38214982},{"atl":[[16,9.42],[18.5,8.07],[22,10.09],[27,8.15]],"id":38214982},{"trd":[[5.8,13.52],[5,80.07],[5.7,2.55]],"ltp":5.8,"tv":96.13,"id":38214982},{"spn":3.35,"spf":1.0,"id":38214982},{"atb":[[4.8,22.05],[4.3,50.78],[1.01,2.25],[5.8,8.73],[5.3,19.48],[1.02,1.55],[7.6,6.34]],"id":27868829},{"atl":[[65,3.07],[34,1.34],[36,3.74],[90,2.21],[46,2.91]],"id":27868829},{"atb":[[1.8,204.37],[1.85,96.17],[2.12,1.6],[1.9,90.83],[1.95,43.02],[2.1,37.15],[2.14,6.59]],"id":38761677},{"atl":[[2.8,4.93],[5.8,27.75],[5.3,30.97],[7.6,30.27],[5.2,1.23],[3.9,8.17],[6.6,35.67]],"id":38761677},{"spn":2.47,"spf":"NaN","id":38761677},{"atb":[[4,13.96],[5.1,1.56],[5,10.47],[3.8,2.68],[3.25,74.48],[3.5,33.51],[3.75,30.47]],"id":40324291},{"atl":[[16.5,1.32],[17,8.19],[19.5,7.09],[24,8.55],[29,7.02]],"id":40324291}],"con":true,"img":false}]}
{"op":"mcm","clk":"5347991487","pt":1646211993411,"mc":[{"id":"1.195453627","rc":[{"atb":[[1.01,1.7]],"id":27868829}],"con":true,"img":false}]}
{"op":"mcm","clk":"5347991493","pt":1646211993518,"mc":[{"id":"1.195453627","rc":[{"atb":[[2.12,0]],"id":38761677}],"con":true,"img":false}]}
{"op":"mcm","clk":"5347991496","pt":1646211993574,"mc":[{"id":"1.195453627","rc":[{"atb":[[2.16,1.6]],"id":38761677}],"con":true,"img":false}]}
{"op":"mcm","clk":"5347991499","pt":1646211993677,"mc":[{"id":"1.195453627","rc":[{"atb":[[1.01,0]],"id":27868829}],"con":true,"img":false}]}
{"op":"mcm","clk":"5347991502","pt":1646211993780,"mc":[{"id":"1.195453627","rc":[{"atb":[[5.4,1.7]],"id":27868829}],"con":true,"img":false}]}
{"op":"mcm","clk":"5347992520","pt":1646212016055,"mc":[{"id":"1.195453627","rc":[{"atb":[[3.25,7.81]],"id":41818958}],"con":true,"img":false}]}
{"op":"mcm","clk":"5347992531","pt":1646212016362,"mc":[{"id":"1.195453627","rc":[{"atb":[[1.98,10.28]],"id":38761677}],"con":true,"img":false}]}
{"op":"mcm","clk":"5347992537","pt":1646212016466,"mc":[{"id":"1.195453627","rc":[{"atb":[[2.88,9.36]],"id":39734233}],"con":true,"img":false}]}
{"op":"mcm","clk":"5347992548","pt":1646212016626,"mc":[{"id":"1.195453627","rc":[{"atb":[[3.8,6.28]],"id":40324291}],"con":true,"img":false}]}
{"op":"mcm","clk":"5347992553","pt":1646212016738,"mc":[{"id":"1.195453627","rc":[{"atb":[[3.55,6.89]],"id":38214982}],"con":true,"img":false}]}
{"op":"mcm","clk":"5347992575","pt":1646212017033,"mc":[{"id":"1.195453627","rc":[{"atb":[[5.4,3.99]],"id":27868829}],"con":true,"img":false}]}
{"op":"mcm","clk":"5348049360","pt":1646213092325,"mc":[{"id":"1.195453627","rc":[{"atb":[[2.74,0],[3.35,0],[2.64,0],[2.84,0],[2.94,0]],"id":39734233},{"atl":[[12,0],[9.8,0],[8.8,0],[14.5,0]],"id":39734233},{"atb":[[4.5,0],[3,0],[3.25,0],[3.5,0],[3.75,0]],"id":38214982},{"atl":[[16,0],[18.5,0],[22,0],[27,0]],"id":38214982},{"spn":1.15,"spf":1.0,"id":38214982},{"atb":[[1.8,0],[1.85,0],[1.9,0],[1.95,0],[2.1,0]],"id":38761677},{"atl":[[5.8,0],[5.3,0],[7.6,0],[6.6,0]],"id":38761677},{"spn":2.48,"spf":"NaN","id":38761677},{"atb":[[4,0],[5,0],[3.25,0],[3.5,0],[3.75,0]],"id":40324291},{"atl":[[17,0],[19.5,0],[24,0],[29,0]],"id":40324291}],"con":true,"img":false}]}
{"op":"mcm","clk":"5348049372","pt":1646213092676,"mc":[{"id":"1.195453627","rc":[{"atl":[[8.6,0]],"id":39734233},{"atb":[[4.6,0]],"id":38214982},{"atl":[[16.5,0]],"id":40324291}],"con":true,"img":false}]}
{"op":"mcm","clk":"5348049375","pt":1646213092729,"mc":[{"id":"1.195453627","rc":[{"atl":[[990,1.32]],"id":39734233},{"atb":[[1.02,1.64]],"id":38214982},{"atl":[[990,1.32]],"id":40324291}],"con":true,"img":false}]}
{"op":"mcm","clk":"5348049407","pt":1646213093152,"mc":[{"id":"1.195453627","rc":[{"atb":[[3.4,0]],"id":39734233},{"atb":[[5.1,0]],"id":40324291}],"con":true,"img":false}]}
{"op":"mcm","clk":"5348049412","pt":1646213093254,"mc":[{"id":"1.195453627","rc":[{"atb":[[1.01,1.6]],"id":39734233},{"atb":[[1.01,1.56]],"id":40324291}],"con":true,"img":false}]}
{"op":"mcm","clk":"5348049771","pt":1646213099629,"mc":[{"id":"1.195453627","rc":[{"atb":[[2.88,5.36]],"id":39734233},{"atb":[[3.55,3.95]],"id":38214982},{"atb":[[2.14,0]],"id":38761677},{"atb":[[3.8,3.6]],"id":40324291}],"con":true,"img":false}]}
{"op":"mcm","clk":"5348049796","pt":1646213100249,"mc":[{"id":"1.195453627","rc":[{"atb":[[2.16,0]],"id":38761677}],"con":true,"img":false}]}
{"op":"mcm","clk":"5348049802","pt":1646213100350,"mc":[{"id":"1.195453627","rc":[{"atb":[[1.01,1.6]],"id":38761677}],"con":true,"img":false}]}
{"op":"mcm","clk":"5348049914","pt":1646213102040,"mc":[{"id":"1.195453627","rc":[{"atb":[[2.74,48.15],[3.35,17.82],[2.64,102.18],[2.84,45.53],[2.94,21.59]],"id":39734233},{"atl":[[12,17.88],[9.8,14.9],[8.8,16.81],[14.5,14.57]],"id":39734233},{"atb":[[4.5,10.51],[3,73.57],[3.25,32.69],[3.5,29.42],[3.75,13.37]],"id":38214982},{"atl":[[16,9.42],[18.5,8.07],[22,10.09],[27,8.15]],"id":38214982},{"atb":[[1.83,201.9],[1.98,53.03],[1.88,95.22],[1.93,90.09],[2.16,36.11]],"id":38761677},{"atl":[[6.8,33.92],[7.8,28.92],[5.9,26.76],[5.4,29.8]],"id":38761677},{"atb":[[4,13.96],[5,10.47],[3.25,74.48],[3.5,33.51],[3.75,30.47]],"id":40324291},{"atl":[[17,8.19],[19.5,7.09],[24,8.55],[29,7.02]],"id":40324291}],"con":true,"img":false}]}
{"op":"mcm","clk":"5348049927","pt":1646213102252,"mc":[{"id":"1.195453627","rc":[{"atl":[[990,0]],"id":39734233},{"atb":[[1.02,0]],"id":38214982},{"atl":[[990,0]],"id":40324291}],"con":true,"img":false}]}
{"op":"mcm","clk":"5348049934","pt":1646213102352,"mc":[{"id":"1.195453627","rc":[{"atl":[[8.6,1.32]],"id":39734233},{"atb":[[4.6,1.64]],"id":38214982},{"atl":[[16.5,1.32]],"id":40324291}],"con":true,"img":false}]}
{"op":"mcm","clk":"5348050909","pt":1646213120501,"mc":[{"id":"1.195453627","rc":[{"atb":[[2.88,9.36]],"id":39734233},{"atb":[[2.2,6.26]],"id":38761677},{"atb":[[3.8,6.28]],"id":40324291}],"con":true,"img":false}]}
{"op":"mcm","clk":"5348050913","pt":1646213120557,"mc":[{"id":"1.195453627","rc":[{"atb":[[3.55,6.89]],"id":38214982}],"con":true,"img":false}]}
{"op":"mcm","clk":"5348051263","pt":1646213125775,"mc":[{"id":"1.195453627","rc":[{"atb":[[1.98,42.74]],"id":38761677}],"con":true,"img":false}]}
{"op":"mcm","clk":"5348051936","pt":1646213137420,"mc":[{"id":"1.195453627","rc":[{"atb":[[2,10.08]],"id":38761677}],"con":true,"img":false}]}
{"op":"mcm","clk":"5348072474","pt":1646213520151,"mc":[{"id":"1.195453627","rc":[{"atb":[[4.1,2]],"id":39734233},{"spn":6.35,"spf":"NaN","id":39734233},{"atb":[[4.7,2]],"id":41818958},{"spn":8.85,"spf":"NaN","id":41818958},{"spn":3.36,"spf":1.0,"id":38214982},{"atb":[[13.5,0.81]],"id":27868829},{"spn":23.75,"spf":"NaN","id":27868829},{"atb":[[2.26,2]],"id":38761677},{"spn":2.53,"spf":"NaN","id":38761677},{"atb":[[5.1,2]],"id":40324291}],"con":true,"img":false}]}
{"op":"mcm","clk":"5348089679","pt":1646213799004,"mc":[{"id":"1.195453627","rc":[{"atb":[[5.6,2]],"id":38214982},{"spn":3.4,"spf":1.0,"id":38214982}],"con":true,"img":false}]}
{"op":"mcm","clk":"5348089847","pt":1646213801790,"mc":[{"id":"1.195453627","rc":[{"atb":[[3.4,15.93]],"id":39734233}],"con":true,"img":false}]}
{"op":"mcm","clk":"5348089857","pt":1646213801996,"mc":[{"id":"1.195453627","rc":[{"atb":[[4,14.5]],"id":41818958}],"con":true,"img":false}]}
{"op":"mcm","clk":"5348089865","pt":1646213802199,"mc":[{"id":"1.195453627","rc":[{"atb":[[5.9,8.04]],"id":27868829}],"con":true,"img":false}]}
{"op":"mcm","clk":"5348093307","pt":1646213862902,"mc":[{"id":"1.195453627","rc":[{"atb":[[5.9,0]],"id":27868829}],"con":true,"img":false}]}
{"op":"mcm","clk":"5348093317","pt":1646213863109,"mc":[{"id":"1.195453627","rc":[{"atb":[[5.5,8.74]],"id":27868829}],"con":true,"img":false}]}
{"op":"mcm","clk":"5348097879","pt":1646213941932,"mc":[{"id":"1.195453627","rc":[{"atb":[[5.5,0]],"id":27868829}],"con":true,"img":false}]}
{"op":"mcm","clk":"5348097893","pt":1646213942138,"mc":[{"id":"1.195453627","rc":[{"atb":[[6,7.81]],"id":27868829}],"con":true,"img":false}]}
{"op":"mcm","clk":"5348101471","pt":1646214003676,"mc":[{"id":"1.195453627","rc":[{"atb":[[6,0]],"id":27868829}],"con":true,"img":false}]}
{"op":"mcm","clk":"5348101483","pt":1646214003883,"mc":[{"id":"1.195453627","rc":[{"atb":[[5.9,8.04]],"id":27868829}],"con":true,"img":false}]}
{"op":"mcm","clk":"5348106413","pt":1646214083004,"mc":[{"id":"1.195453627","rc":[{"atb":[[5.9,0]],"id":27868829}],"con":true,"img":false}]}
{"op":"mcm","clk":"5348106425","pt":1646214083220,"mc":[{"id":"1.195453627","rc":[{"atb":[[6.2,7.58]],"id":27868829}],"con":true,"img":false}]}
{"op":"mcm","clk":"5348106482","pt":1646214084202,"mc":[{"id":"1.195453627","rc":[{"atb":[[1.02,0]],"id":27868829},{"atb":[[1.01,0]],"id":40324291}],"con":true,"img":false}]}
{"op":"mcm","clk":"5348106489","pt":1646214084308,"mc":[{"id":"1.195453627","rc":[{"atb":[[7.8,1.55]],"id":27868829},{"atb":[[5.1,3.56]],"id":40324291}],"con":true,"img":false}]}
{"op":"mcm","clk":"5348112280","pt":1646214188482,"mc":[{"id":"1.195453627","rc":[{"atb":[[6.2,0]],"id":27868829}],"con":true,"img":false}]}
{"op":"mcm","clk":"5348112291","pt":1646214188689,"mc":[{"id":"1.195453627","rc":[{"atb":[[5.5,8.74]],"id":27868829}],"con":true,"img":false}]}
{"op":"mcm","clk":"5348112319","pt":1646214189205,"mc":[{"id":"1.195453627","rc":[{"atb":[[7.8,0]],"id":27868829}],"con":true,"img":false}]}
{"op":"mcm","clk":"5348112323","pt":1646214189255,"mc":[{"id":"1.195453627","rc":[{"atb":[[1.01,1.55]],"id":27868829}],"con":true,"img":false}]}
{"op":"mcm","clk":"5348115864","pt":1646214245272,"mc":[{"id":"1.195453627","rc":[{"atb":[[4.7,0]],"id":41818958}],"con":true,"img":false}]}
{"op":"mcm","clk":"5348115869","pt":1646214245376,"mc":[{"id":"1.195453627","rc":[{"atb":[[4.8,2]],"id":41818958}],"con":true,"img":false}]}
{"op":"mcm","clk":"5348119797","pt":1646214305901,"mc":[{"id":"1.195453627","rc":[{"spn":8.9,"spf":"NaN","id":41818958},{"atb":[[5.5,0]],"id":27868829}],"con":true,"img":false}]}
{"op":"mcm","clk":"5348119809","pt":1646214306106,"mc":[{"id":"1.195453627","rc":[{"atb":[[5.9,8.04]],"id":27868829}],"con":true,"img":false}]}
{"op":"mcm","clk":"5348139366","pt":1646214464129,"mc":[{"id":"1.195453627","rc":[{"atb":[[5.9,0]],"id":27868829}],"con":true,"img":false}]}
{"op":"mcm","clk":"5348139385","pt":1646214464346,"mc":[{"id":"1.195453627","rc":[{"atb":[[5.5,8.74]],"id":27868829}],"con":true,"img":false}]}
{"op":"mcm","clk":"5348146671","pt":1646214562168,"mc":[{"id":"1.195453627","rc":[{"atb":[[5.5,0]],"id":27868829}],"con":true,"img":false}]}
{"op":"mcm","clk":"5348146696","pt":1646214562481,"mc":[{"id":"1.195453627","rc":[{"atb":[[5.9,8.04]],"id":27868829}],"con":true,"img":false}]}
{"op":"mcm","clk":"5348151001","pt":1646214623684,"mc":[{"id":"1.195453627","rc":[{"atb":[[5.9,0]],"id":27868829}],"con":true,"img":false}]}
{"op":"mcm","clk":"5348151015","pt":1646214623893,"mc":[{"id":"1.195453627","rc":[{"atb":[[5.5,8.74]],"id":27868829}],"con":true,"img":false}]}
{"op":"mcm","clk":"5348155452","pt":1646214688272,"mc":[{"id":"1.195453627","rc":[{"atb":[[5.5,0]],"id":27868829}],"con":true,"img":false}]}
{"op":"mcm","clk":"5348155465","pt":1646214688475,"mc":[{"id":"1.195453627","rc":[{"atb":[[5.9,8.04]],"id":27868829}],"con":true,"img":false}]}
{"op":"mcm","clk":"5348159590","pt":1646214751370,"mc":[{"id":"1.195453627","rc":[{"atb":[[5.9,0]],"id":27868829}],"con":true,"img":false}]}
{"op":"mcm","clk":"5348159603","pt":1646214751578,"mc":[{"id":"1.195453627","rc":[{"atb":[[5.5,8.74]],"id":27868829}],"con":true,"img":false}]}
{"op":"mcm","clk":"5348164018","pt":1646214818173,"mc":[{"id":"1.195453627","rc":[{"atb":[[5.5,0]],"id":27868829}],"con":true,"img":false}]}
{"op":"mcm","clk":"5348164034","pt":1646214818380,"mc":[{"id":"1.195453627","rc":[{"atb":[[5.9,8.04]],"id":27868829}],"con":true,"img":false}]}
{"op":"mcm","clk":"5348168204","pt":1646214878979,"mc":[{"id":"1.195453627","rc":[{"atb":[[5.9,0]],"id":27868829}],"con":true,"img":false}]}
{"op":"mcm","clk":"5348168217","pt":1646214879185,"mc":[{"id":"1.195453627","rc":[{"atb":[[5.5,8.74]],"id":27868829}],"con":true,"img":false}]}
{"op":"mcm","clk":"5348173057","pt":1646214952098,"mc":[{"id":"1.195453627","rc":[{"atb":[[5.5,0]],"id":27868829}],"con":true,"img":false}]}
{"op":"mcm","clk":"5348173068","pt":1646214952308,"mc":[{"id":"1.195453627","rc":[{"atb":[[6,7.81]],"id":27868829}],"con":true,"img":false}]}
{"op":"mcm","clk":"5348178938","pt":1646215043671,"mc":[{"id":"1.195453627","rc":[{"atb":[[6,0]],"id":27868829}],"con":true,"img":false}]}
{"op":"mcm","clk":"5348178947","pt":1646215043822,"mc":[{"id":"1.195453627","rc":[{"atb":[[5.5,8.74]],"id":27868829}],"con":true,"img":false}]}
{"op":"mcm","clk":"5348182456","pt":1646215104513,"mc":[{"id":"1.195453627","rc":[{"atb":[[5.5,0]],"id":27868829}],"con":true,"img":false}]}
{"op":"mcm","clk":"5348182473","pt":1646215104718,"mc":[{"id":"1.195453627","rc":[{"atb":[[5.9,8.04]],"id":27868829}],"con":true,"img":false}]}
{"op":"mcm","clk":"5348182500","pt":1646215105130,"mc":[{"id":"1.195453627","rc":[{"atb":[[1.01,0]],"id":27868829}],"con":true,"img":false}]}
{"op":"mcm","clk":"5348182507","pt":1646215105231,"mc":[{"id":"1.195453627","rc":[{"atb":[[7.8,1.55]],"id":27868829}],"con":true,"img":false}]}
{"op":"mcm","clk":"5348189526","pt":1646215208391,"mc":[{"id":"1.195453627","rc":[{"atb":[[5.9,0]],"id":27868829}],"con":true,"img":false}]}
{"op":"mcm","clk":"5348189537","pt":1646215208592,"mc":[{"id":"1.195453627","rc":[{"atb":[[5.5,8.74]],"id":27868829}],"con":true,"img":false}]}
{"op":"mcm","clk":"5348189563","pt":1646215208904,"mc":[{"id":"1.195453627","rc":[{"atb":[[7.8,0]],"id":27868829}],"con":true,"img":false}]}
{"op":"mcm","clk":"5348189571","pt":1646215208962,"mc":[{"id":"1.195453627","rc":[{"atb":[[1.01,1.55]],"id":27868829}],"con":true,"img":false}]}
{"op":"mcm","clk":"5348194323","pt":1646215269995,"mc":[{"id":"1.195453627","rc":[{"atb":[[5.5,0]],"id":27868829}],"con":true,"img":false}]}
{"op":"mcm","clk":"5348194336","pt":1646215270201,"mc":[{"id":"1.195453627","rc":[{"atb":[[5.9,8.04]],"id":27868829}],"con":true,"img":false}]}
{"op":"mcm","clk":"5348198093","pt":1646215325748,"mc":[{"id":"1.195453627","rc":[{"atb":[[3.05,35.12]],"id":40324291}],"con":true,"img":false}]}
{"op":"mcm","clk":"5348198102","pt":1646215325852,"mc":[{"id":"1.195453627","rc":[{"atl":[[16,8.2]],"id":39734233},{"atb":[[4.3,72.6],[2.96,41.84]],"id":27868829},{"atl":[[5.2,9.43]],"id":38761677},{"atb":[[2.22,67.21]],"id":40324291},{"atl":[[40,8.2]],"id":40324291}],"con":true,"img":false}]}
{"op":"mcm","clk":"5348198111","pt":1646215325958,"mc":[{"id":"1.195453627","rc":[{"atl":[[21,14.2]],"id":39734233},{"atl":[[34,14.2],[25,8.2]],"id":41818958},{"atb":[[2.62,46.3]],"id":38214982},{"atl":[[12,8.2],[14.5,14.2]],"id":38214982},{"atb":[[2.62,46.3]],"id":27868829},{"atl":[[130,8.2],[150,14.2]],"id":27868829},{"atl":[[17,8.5],[6.2,14.2]],"id":38761677},{"atl":[[55,14.2]],"id":40324291}],"con":true,"img":false}]}
{"op":"mcm","clk":"5348198117","pt":1646215326060,"mc":[{"id":"1.195453627","rc":[{"atl":[[34,13.5]],"id":39734233},{"atl":[[17,8.5],[34,13.5]],"id":38214982},{"atl":[[34,13.5]],"id":38761677}],"con":true,"img":false}]}
{"op":"mcm","clk":"5348203242","pt":1646215398132,"mc":[{"id":"1.195453627","rc":[{"atb":[[5.9,0]],"id":27868829}],"con":true,"img":false}]}
{"op":"mcm","clk":"5348203260","pt":1646215398338,"mc":[{"id":"1.195453627","rc":[{"atb":[[5.5,8.74]],"id":27868829}],"con":true,"img":false}]}
{"op":"mcm","clk":"5348208613","pt":1646215464542,"mc":[{"id":"1.195453627","rc":[{"atb":[[5.5,0]],"id":27868829}],"con":true,"img":false}]}
{"op":"mcm","clk":"5348208632","pt":1646215464751,"mc":[{"id":"1.195453627","rc":[{"atb":[[6,7.81]],"id":27868829}],"con":true,"img":false}]}
{"op":"mcm","clk":"5348213911","pt":1646215530109,"mc":[{"id":"1.195453627","rc":[{"atb":[[6,0]],"id":27868829}],"con":true,"img":false}]}
{"op":"mcm","clk":"5348213925","pt":1646215530315,"mc":[{"id":"1.195453627","rc":[{"atb":[[5.9,8.04]],"id":27868829}],"con":true,"img":false}]}
{"op":"mcm","clk":"5348213961","pt":1646215530833,"mc":[{"id":"1.195453627","rc":[{"atb":[[1.01,0]],"id":27868829}],"con":true,"img":false}]}
{"op":"mcm","clk":"5348213970","pt":1646215530896,"mc":[{"id":"1.195453627","rc":[{"atb":[[7.8,1.55]],"id":27868829}],"con":true,"img":false}]}
{"op":"mcm","clk":"5348219905","pt":1646215596473,"mc":[{"id":"1.195453627","rc":[{"atb":[[5.9,0]],"id":27868829}],"con":true,"img":false}]}
{"op":"mcm","clk":"5348219923","pt":1646215596676,"mc":[{"id":"1.195453627","rc":[{"atb":[[5.5,8.74]],"id":27868829}],"con":true,"img":false}]}
{"op":"mcm","clk":"5348219957","pt":1646215597094,"mc":[{"id":"1.195453627","rc":[{"atb":[[7.8,0]],"id":27868829}],"con":true,"img":false}]}
{"op":"mcm","clk":"5348219963","pt":1646215597205,"mc":[{"id":"1.195453627","rc":[{"atb":[[1.01,1.55]],"id":27868829}],"con":true,"img":false}]}
{"op":"mcm","clk":"5348224045","pt":1646215646753,"mc":[{"id":"1.195453627","rc":[{"atl":[[5.7,0]],"id":38214982}],"con":true,"img":false}]}
{"op":"mcm","clk":"5348224051","pt":1646215646855,"mc":[{"id":"1.195453627","rc":[{"atb":[[5.6,0.12]],"id":38214982},{"trd":[[5.6,3.76]],"ltp":5.6,"tv":3.76,"id":38214982}],"con":true,"img":false}]}
{"op":"mcm","clk":"5348225026","pt":1646215657779,"mc":[{"id":"1.195453627","rc":[{"spn":3.36,"spf":1.0,"id":38214982},{"atb":[[5.5,0]],"id":27868829}],"con":true,"img":false}]}
{"op":"mcm","clk":"5348225035","pt":1646215657942,"mc":[{"id":"1.195453627","rc":[{"atb":[[5.9,8.04]],"id":27868829}],"con":true,"img":false}]}
{"op":"mcm","clk":"5348231272","pt":1646215727227,"mc":[{"id":"1.195453627","rc":[{"atb":[[5.9,0]],"id":27868829}],"con":true,"img":false}]}
{"op":"mcm","clk":"5348231295","pt":1646215727424,"mc":[{"id":"1.195453627","rc":[{"atb":[[5.5,8.74]],"id":27868829}],"con":true,"img":false}]}
{"op":"mcm","clk":"5348237066","pt":1646215790576,"mc":[{"id":"1.195453627","rc":[{"atb":[[5.5,0]],"id":27868829}],"con":true,"img":false}]}
{"op":"mcm","clk":"5348237085","pt":1646215790786,"mc":[{"id":"1.195453627","rc":[{"atb":[[5.9,8.04]],"id":27868829}],"con":true,"img":false}]}
{"op":"mcm","clk":"5348237134","pt":1646215791200,"mc":[{"id":"1.195453627","rc":[{"atb":[[1.01,0]],"id":38214982},{"atb":[[1.01,0]],"id":27868829}],"con":true,"img":false}]}
{"op":"mcm","clk":"5348237145","pt":1646215791264,"mc":[{"id":"1.195453627","rc":[{"atb":[[4.6,3.11]],"id":38214982},{"atb":[[7.8,1.55]],"id":27868829}],"con":true,"img":false}]}
{"op":"mcm","clk":"5348243370","pt":1646215857558,"mc":[{"id":"1.195453627","rc":[{"spn":3.38,"spf":1.0,"id":38214982},{"atb":[[5.9,0]],"id":27868829}],"con":true,"img":false}]}
{"op":"mcm","clk":"5348243393","pt":1646215857770,"mc":[{"id":"1.195453627","rc":[{"atb":[[5.5,8.74]],"id":27868829}],"con":true,"img":false}]}
{"op":"mcm","clk":"5348243454","pt":1646215858450,"mc":[{"id":"1.195453627","rc":[{"atb":[[7.8,0]],"id":27868829}],"con":true,"img":false}]}
{"op":"mcm","clk":"5348243459","pt":1646215858555,"mc":[{"id":"1.195453627","rc":[{"atb":[[1.01,1.55]],"id":27868829}],"con":true,"img":false}]}
{"op":"mcm","clk":"5348249239","pt":1646215919510,"mc":[{"id":"1.195453627","rc":[{"atb":[[5.5,0]],"id":27868829}],"con":true,"img":false}]}
{"op":"mcm","clk":"5348249257","pt":1646215919718,"mc":[{"id":"1.195453627","rc":[{"atb":[[6,7.81]],"id":27868829}],"con":true,"img":false}]}
{"op":"mcm","clk":"5348249344","pt":1646215920811,"mc":[{"id":"1.195453627","rc":[{"atb":[[1.01,0]],"id":27868829}],"con":true,"img":false}]}
{"op":"mcm","clk":"5348249355","pt":1646215920918,"mc":[{"id":"1.195453627","rc":[{"atb":[[7.8,1.55]],"id":27868829}],"con":true,"img":false}]}
{"op":"mcm","clk":"5348252488","pt":1646215954950,"mc":[{"id":"1.195453627","rc":[{"atb":[[2.8,40]],"id":38214982}],"con":true,"img":false}]}
{"op":"mcm","clk":"5348252497","pt":1646215955085,"mc":[{"id":"1.195453627","rc":[{"atb":[[2.08,75.93]],"id":38214982}],"con":true,"img":false}]}
{"op":"mcm","clk":"5348256096","pt":1646215989277,"mc":[{"id":"1.195453627","rc":[{"atb":[[6,0]],"id":27868829}],"con":true,"img":false}]}
{"op":"mcm","clk":"5348256117","pt":1646215989484,"mc":[{"id":"1.195453627","rc":[{"atb":[[5.9,8.04]],"id":27868829}],"con":true,"img":false}]}
{"op":"mcm","clk":"5348262766","pt":1646216053964,"mc":[{"id":"1.195453627","rc":[{"atb":[[5.9,0]],"id":27868829}],"con":true,"img":false}]}
{"op":"mcm","clk":"5348262787","pt":1646216054173,"mc":[{"id":"1.195453627","rc":[{"atb":[[5.5,8.74]],"id":27868829}],"con":true,"img":false}]}
{"op":"mcm","clk":"5348262849","pt":1646216054692,"mc":[{"id":"1.195453627","rc":[{"atb":[[7.8,0]],"id":27868829}],"con":true,"img":false}]}
{"op":"mcm","clk":"5348262860","pt":1646216054791,"mc":[{"id":"1.195453627","rc":[{"atb":[[1.01,1.55]],"id":27868829}],"con":true,"img":false}]}
{"op":"mcm","clk":"5348278005","pt":1646216125324,"mc":[{"id":"1.195453627","rc":[{"atb":[[5.5,0]],"id":27868829}],"con":true,"img":false}]}
{"op":"mcm","clk":"5348278063","pt":1646216125498,"mc":[{"id":"1.195453627","rc":[{"atb":[[6,7.81]],"id":27868829}],"con":true,"img":false}]}
{"op":"mcm","clk":"5348278301","pt":1646216126480,"mc":[{"id":"1.195453627","rc":[{"atb":[[1.01,0]],"id":27868829}],"con":true,"img":false}]}
{"op":"mcm","clk":"5348278331","pt":1646216126592,"mc":[{"id":"1.195453627","rc":[{"atb":[[7.8,1.55]],"id":27868829}],"con":true,"img":false}]}
{"op":"mcm","clk":"5348296287","pt":1646216251625,"mc":[{"id":"1.195453627","rc":[{"atb":[[6,0]],"id":27868829}],"con":true,"img":false}]}
{"op":"mcm","clk":"5348296317","pt":1646216251835,"mc":[{"id":"1.195453627","rc":[{"atb":[[5.5,8.74]],"id":27868829}],"con":true,"img":false}]}
{"op":"mcm","clk":"5348296425","pt":1646216252730,"mc":[{"id":"1.195453627","rc":[{"atb":[[7.8,0]],"id":27868829}],"con":true,"img":false}]}
{"op":"mcm","clk":"5348296440","pt":1646216252836,"mc":[{"id":"1.195453627","rc":[{"atb":[[1.01,1.55]],"id":27868829}],"con":true,"img":false}]}
{"op":"mcm","clk":"5348304433","pt":1646216315462,"mc":[{"id":"1.195453627","rc":[{"atb":[[5.5,0]],"id":27868829}],"con":true,"img":false}]}
{"op":"mcm","clk":"5348304454","pt":1646216315661,"mc":[{"id":"1.195453627","rc":[{"atb":[[6.2,7.58]],"id":27868829}],"con":true,"img":false}]}
{"op":"mcm","clk":"5348312574","pt":1646216391046,"mc":[{"id":"1.195453627","rc":[{"atb":[[6.2,0]],"id":27868829}],"con":true,"img":false}]}
{"op":"mcm","clk":"5348312596","pt":1646216391262,"mc":[{"id":"1.195453627","rc":[{"atb":[[5.9,8.04]],"id":27868829}],"con":true,"img":false}]}
{"op":"mcm","clk":"5348318914","pt":1646216452439,"mc":[{"id":"1.195453627","rc":[{"atb":[[5.9,0]],"id":27868829}],"con":true,"img":false}]}
{"op":"mcm","clk":"5348318928","pt":1646216452642,"mc":[{"id":"1.195453627","rc":[{"atb":[[5.5,8.74]],"id":27868829}],"con":true,"img":false}]}
{"op":"mcm","clk":"5348326355","pt":1646216522136,"mc":[{"id":"1.195453627","rc":[{"atb":[[5.5,0]],"id":27868829}],"con":true,"img":false}]}
{"op":"mcm","clk":"5348326383","pt":1646216522298,"mc":[{"id":"1.195453627","rc":[{"atb":[[6,7.81]],"id":27868829}],"con":true,"img":false}]}
{"op":"mcm","clk":"5348334673","pt":1646216585079,"mc":[{"id":"1.195453627","rc":[{"atb":[[6,0]],"id":27868829}],"con":true,"img":false}]}
{"op":"mcm","clk":"5348334699","pt":1646216585279,"mc":[{"id":"1.195453627","rc":[{"atb":[[5.9,8.04]],"id":27868829}],"con":true,"img":false}]}
{"op":"mcm","clk":"5348341597","pt":1646216657218,"mc":[{"id":"1.195453627","rc":[{"atb":[[5.9,0]],"id":27868829}],"con":true,"img":false}]}
{"op":"mcm","clk":"5348341620","pt":1646216657380,"mc":[{"id":"1.195453627","rc":[{"atb":[[6.2,7.58]],"id":27868829}],"con":true,"img":false}]}
{"op":"mcm","clk":"5348342101","pt":1646216662689,"mc":[{"id":"1.195453627","rc":[{"atb":[[3.45,45.93],[3.9,20.15]],"id":39734233},{"atl":[[8,8.34],[8.6,16.13]],"id":39734233},{"atb":[[4.6,16.23],[4.1,37.53]],"id":41818958},{"atl":[[9.8,6.64],[13,11.01]],"id":41818958},{"atb":[[4.6,36.65],[5,14.61]],"id":38214982},{"atl":[[11,5.84],[14,9.28]],"id":38214982},{"atb":[[10,12.89],[12.5,5.08]],"id":27868829},{"atl":[[34,4.06],[44,2.72]],"id":27868829},{"atb":[[1.99,114.78],[2.18,49.53]],"id":38761677},{"atl":[[3.7,21.64],[4.9,26.42]],"id":38761677},{"atb":[[5.1,46.4]],"id":40324291},{"atl":[[11.5,5.56],[15.5,7.55]],"id":40324291}],"con":true,"img":false}]}
{"op":"mcm","clk":"5348342116","pt":1646216662902,"mc":[{"id":"1.195453627","rc":[{"atl":[[34,1.34]],"id":27868829}],"con":true,"img":false}]}
{"op":"mcm","clk":"5348342122","pt":1646216663007,"mc":[{"id":"1.195453627","rc":[{"atl":[[38,2.72]],"id":27868829}],"con":true,"img":false}]}
{"op":"mcm","clk":"5348342133","pt":1646216663114,"mc":[{"id":"1.195453627","rc":[{"atb":[[2.9,37.89],[2.12,73.21]],"id":41818958}],"con":true,"img":false}]}
{"op":"mcm","clk":"5348342169","pt":1646216663532,"mc":[{"id":"1.195453627","rc":[{"atl":[[8.6,14.8]],"id":39734233}],"con":true,"img":false}]}
{"op":"mcm","clk":"5348342181","pt":1646216663587,"mc":[{"id":"1.195453627","rc":[{"atl":[[7.8,1.32]],"id":39734233}],"con":true,"img":false}]}
{"op":"mcm","clk":"5348342782","pt":1646216669825,"mc":[{"id":"1.195453627","rc":[{"atb":[[2.88,5.36]],"id":39734233},{"atb":[[3.25,4.47]],"id":41818958},{"atb":[[3.55,3.95]],"id":38214982},{"atb":[[5.4,2.29]],"id":27868829},{"atb":[[2.2,0]],"id":38761677},{"atb":[[3.8,3.6]],"id":40324291}],"con":true,"img":false}]}
{"op":"mcm","clk":"5348343997","pt":1646216681750,"mc":[{"id":"1.195453627","rc":[{"atb":[[3.95,2.54]],"id":39734233}],"con":true,"img":false}]}
{"op":"mcm","clk":"5348344011","pt":1646216681856,"mc":[{"id":"1.195453627","rc":[{"atb":[[1.01,2.25]],"id":41818958},{"atb":[[2.22,6.16]],"id":38761677},{"atb":[[1.01,2.25]],"id":40324291}],"con":true,"img":false}]}
{"op":"mcm","clk":"5348344032","pt":1646216682020,"mc":[{"id":"1.195453627","rc":[{"atb":[[1.01,2.03]],"id":41818958},{"atb":[[1.01,1.78]],"id":40324291}],"con":true,"img":false}]}
{"op":"mcm","clk":"5348344044","pt":1646216682132,"mc":[{"id":"1.195453627","rc":[{"atb":[[1.01,0]],"id":40324291}],"con":true,"img":false}]}
{"op":"mcm","clk":"5348344053","pt":1646216682237,"mc":[{"id":"1.195453627","rc":[{"atb":[[5.2,1.78]],"id":40324291}],"con":true,"img":false}]}
{"op":"mcm","clk":"5348344070","pt":1646216682448,"mc":[{"id":"1.195453627","rc":[{"atb":[[1.01,0]],"id":41818958}],"con":true,"img":false}]}
{"op":"mcm","clk":"5348344081","pt":1646216682551,"mc":[{"id":"1.195453627","rc":[{"atb":[[4.7,2.03]],"id":41818958}],"con":true,"img":false}]}
{"op":"mcm","clk":"5348344607","pt":1646216687358,"mc":[{"id":"1.195453627","rc":[{"atb":[[2.54,46.75],[1.92,89.13]],"id":39734233},{"atb":[[1.57,126.32]],"id":38761677}],"con":true,"img":false}]}
{"op":"mcm","clk":"5348344613","pt":1646216687461,"mc":[{"id":"1.195453627","rc":[{"atb":[[1.34,241.18]],"id":38761677}],"con":true,"img":false}]}
{"op":"mcm","clk":"5348344685","pt":1646216688141,"mc":[{"id":"1.195453627","rc":[{"atb":[[2.88,0]],"id":39734233},{"atb":[[3.25,0]],"id":41818958},{"atb":[[3.55,0]],"id":38214982},{"atb":[[5.4,0]],"id":27868829},{"atb":[[2,0]],"id":38761677},{"atb":[[3.8,0]],"id":40324291}],"con":true,"img":false}]}
{"op":"mcm","clk":"5348344785","pt":1646216689033,"mc":[{"id":"1.195453627","rc":[{"atl":[[8,0]],"id":39734233}],"con":true,"img":false}]}
{"op":"mcm","clk":"5348344797","pt":1646216689136,"mc":[{"id":"1.195453627","rc":[{"atl":[[8.4,8.34]],"id":39734233}],"con":true,"img":false}]}
{"op":"mcm","clk":"5348344820","pt":1646216689356,"mc":[{"id":"1.195453627","rc":[{"atl":[[7.8,0]],"id":39734233}],"con":true,"img":false}]}
{"op":"mcm","clk":"5348344834","pt":1646216689455,"mc":[{"id":"1.195453627","rc":[{"atl":[[8.2,1.32]],"id":39734233}],"con":true,"img":false}]}
{"op":"mcm","clk":"5348345824","pt":1646216700775,"mc":[{"id":"1.195453627","rc":[{"atl":[[38,0]],"id":27868829}],"con":true,"img":false}]}
{"op":"mcm","clk":"5348345835","pt":1646216700882,"mc":[{"id":"1.195453627","rc":[{"atl":[[34,4.06]],"id":27868829}],"con":true,"img":false}]}
{"op":"mcm","clk":"5348346221","pt":1646216704857,"mc":[{"id":"1.195453627","rc":[{"atb":[[2.22,13]],"id":38761677}],"con":true,"img":false}]}
{"op":"mcm","clk":"5348346233","pt":1646216704961,"mc":[{"id":"1.195453627","rc":[{"atb":[[4.2,2.6]],"id":41818958}],"con":true,"img":false}]}
{"op":"mcm","clk":"5348346252","pt":1646216705174,"mc":[{"id":"1.195453627","rc":[{"atb":[[3.5,3.33]],"id":39734233},{"atb":[[5.2,3.77]],"id":40324291}],"con":true,"img":false}]}
{"op":"mcm","clk":"5348347439","pt":1646216718593,"mc":[{"id":"1.195453627","rc":[{"atb":[[3.9,0]],"id":39734233},{"spn":6.15,"spf":"NaN","id":39734233},{"spn":7.3,"spf":"NaN","id":41818958},{"spn":3.91,"spf":1.0,"id":38214982},{"atl":[[3.7,0]],"id":38761677},{"spn":8.35,"spf":"NaN","id":40324291}],"con":true,"img":false}]}
{"op":"mcm","clk":"5348347450","pt":1646216718687,"mc":[{"id":"1.195453627","rc":[{"atb":[[4,20.15]],"id":39734233},{"atl":[[3.6,21.64]],"id":38761677}],"con":true,"img":false}]}
{"op":"mcm","clk":"5348347481","pt":1646216719000,"mc":[{"id":"1.195453627","rc":[{"atb":[[3.4,0]],"id":39734233}],"con":true,"img":false}]}
{"op":"mcm","clk":"5348347498","pt":1646216719208,"mc":[{"id":"1.195453627","rc":[{"atb":[[3.95,15.77]],"id":39734233}],"con":true,"img":false}]}
{"op":"mcm","clk":"5348347518","pt":1646216719366,"mc":[{"id":"1.195453627","rc":[{"atb":[[4,1.5]],"id":41818958}],"con":true,"img":false}]}
{"op":"mcm","clk":"5348347532","pt":1646216719573,"mc":[{"id":"1.195453627","rc":[{"atb":[[4.7,12.62]],"id":41818958}],"con":true,"img":false}]}
{"op":"mcm","clk":"5348347556","pt":1646216719782,"mc":[{"id":"1.195453627","rc":[{"atb":[[6.2,0]],"id":27868829}],"con":true,"img":false}]}
{"op":"mcm","clk":"5348348135","pt":1646216726920,"mc":[{"id":"1.195453627","rc":[{"atb":[[3.95,13.22]],"id":39734233}],"con":true,"img":false}]}
{"op":"mcm","clk":"5348348429","pt":1646216730207,"mc":[{"id":"1.195453627","rc":[{"atl":[[11.5,11.49],[14,0]],"id":38214982}],"con":true,"img":false}]}
{"op":"mcm","clk":"5348348894","pt":1646216735488,"mc":[{"id":"1.195453627","rc":[{"atb":[[3.5,0]],"id":39734233}],"con":true,"img":false}]}
{"op":"mcm","clk":"5348348929","pt":1646216735900,"mc":[{"id":"1.195453627","rc":[{"atb":[[4.1,4.42]],"id":39734233}],"con":true,"img":false}]}
{"op":"mcm","clk":"5348350030","pt":1646216747545,"mc":[{"id":"1.195453627","rc":[{"atb":[[4.1,7.12]],"id":39734233}],"con":true,"img":false}]}
{"op":"mcm","clk":"5348350103","pt":1646216748537,"mc":[{"id":"1.195453627","rc":[{"atb":[[2.26,0]],"id":38761677}],"con":true,"img":false}]}
{"op":"mcm","clk":"5348350122","pt":1646216748743,"mc":[{"id":"1.195453627","rc":[{"atb":[[2.22,15]],"id":38761677}],"con":true,"img":false}]}
{"op":"mcm","clk":"5348350487","pt":1646216752975,"mc":[{"id":"1.195453627","rc":[{"atl":[[5.2,8.2]],"id":38761677}],"con":true,"img":false}]}
{"op":"mcm","clk":"5348350498","pt":1646216753058,"mc":[{"id":"1.195453627","rc":[{"atl":[[2.78,1.23]],"id":38761677}],"con":true,"img":false}]}
{"op":"mcm","clk":"5348351101","pt":1646216759581,"mc":[{"id":"1.195453627","rc":[{"atb":[[4.6,0]],"id":41818958}],"con":true,"img":false}]}
{"op":"mcm","clk":"5348351108","pt":1646216759636,"mc":[{"id":"1.195453627","rc":[{"atb":[[4.8,18.23]],"id":41818958}],"con":true,"img":false}]}
{"op":"mcm","clk":"5348351733","pt":1646216765983,"mc":[{"id":"1.195453627","rc":[{"atb":[[4.7,10.59]],"id":41818958}],"con":true,"img":false}]}
{"op":"mcm","clk":"5348352835","pt":1646216777687,"mc":[{"id":"1.195453627","rc":[{"atb":[[4.2,0]],"id":41818958}],"con":true,"img":false}]}
{"op":"mcm","clk":"5348353194","pt":1646216780990,"mc":[{"id":"1.195453627","rc":[{"atb":[[1.01,2.25]],"id":41818958},{"spn":2.5,"spf":"NaN","id":38761677}],"con":true,"img":false}]}
{"op":"mcm","clk":"5348353213","pt":1646216781196,"mc":[{"id":"1.195453627","rc":[{"atb":[[1.01,1.92]],"id":41818958},{"atl":[[3.9,0]],"id":38761677}],"con":true,"img":false}]}
{"op":"mcm","clk":"5348353228","pt":1646216781402,"mc":[{"id":"1.195453627","rc":[{"atb":[[1.01,0]],"id":41818958}],"con":true,"img":false}]}
{"op":"mcm","clk":"5348353237","pt":1646216781455,"mc":[{"id":"1.195453627","rc":[{"atb":[[4.9,1.92]],"id":41818958}],"con":true,"img":false}]}
{"op":"mcm","clk":"5348353626","pt":1646216785600,"mc":[{"id":"1.195453627","rc":[{"atb":[[4,57.66],[3.45,0]],"id":39734233}],"con":true,"img":false}]}
{"op":"mcm","clk":"5348353709","pt":1646216786591,"mc":[{"id":"1.195453627","rc":[{"atb":[[4.9,4.05]],"id":41818958}],"con":true,"img":false}]}
{"op":"mcm","clk":"5348354156","pt":1646216791824,"mc":[{"id":"1.195453627","rc":[{"atb":[[3.95,0]],"id":39734233}],"con":true,"img":false}]}
{"op":"mcm","clk":"5348354179","pt":1646216791989,"mc":[{"id":"1.195453627","rc":[{"atb":[[3.45,14.38]],"id":39734233}],"con":true,"img":false}]}
{"op":"mcm","clk":"5348354195","pt":1646216792197,"mc":[{"id":"1.195453627","rc":[{"atb":[[4.7,0]],"id":41818958}],"con":true,"img":false}]}
{"op":"mcm","clk":"5348354212","pt":1646216792408,"mc":[{"id":"1.195453627","rc":[{"atb":[[4.1,50.14]],"id":41818958}],"con":true,"img":false}]}
{"op":"mcm","clk":"5348354375","pt":1646216794615,"mc":[{"id":"1.195453627","rc":[{"atb":[[3.5,45.01]],"id":39734233}],"con":true,"img":false}]}
{"op":"mcm","clk":"5348354384","pt":1646216794722,"mc":[{"id":"1.195453627","rc":[{"atb":[[4,20.15]],"id":39734233},{"atb":[[4.8,2]],"id":41818958}],"con":true,"img":false}]}
{"op":"mcm","clk":"5348354393","pt":1646216794779,"mc":[{"id":"1.195453627","rc":[{"atb":[[4.6,16.23]],"id":41818958}],"con":true,"img":false}]}
{"op":"mcm","clk":"5348355095","pt":1646216802014,"mc":[{"id":"1.195453627","rc":[{"atb":[[4.9,2.13]],"id":41818958}],"con":true,"img":false}]}
{"op":"mcm","clk":"5348355930","pt":1646216810635,"mc":[{"id":"1.195453627","rc":[{"atb":[[4.9,0]],"id":41818958}],"con":true,"img":false}]}
{"op":"mcm","clk":"5348355976","pt":1646216811005,"mc":[{"id":"1.195453627","rc":[{"atb":[[1.01,2.25]],"id":41818958}],"con":true,"img":false}]}
{"op":"mcm","clk":"5348355985","pt":1646216811105,"mc":[{"id":"1.195453627","rc":[{"atb":[[1.01,2.03]],"id":41818958}],"con":true,"img":false}]}
{"op":"mcm","clk":"5348356030","pt":1646216811633,"mc":[{"id":"1.195453627","rc":[{"atb":[[1.01,0]],"id":41818958}],"con":true,"img":false}]}
{"op":"mcm","clk":"5348356043","pt":1646216811741,"mc":[{"id":"1.195453627","rc":[{"atb":[[4.7,2.03]],"id":41818958}],"con":true,"img":false}]}
{"op":"mcm","clk":"5348357497","pt":1646216825746,"mc":[{"id":"1.195453627","rc":[{"atb":[[4.2,2.6]],"id":41818958}],"con":true,"img":false}]}
{"op":"mcm","clk":"5348360335","pt":1646216855602,"mc":[{"id":"1.195453627","rc":[{"atb":[[3.45,0]],"id":39734233}],"con":true,"img":false}]}
{"op":"mcm","clk":"5348360358","pt":1646216855770,"mc":[{"id":"1.195453627","rc":[{"atb":[[4.1,19.73]],"id":39734233}],"con":true,"img":false}]}
{"op":"mcm","clk":"5348360375","pt":1646216855980,"mc":[{"id":"1.195453627","rc":[{"atb":[[4.1,37.53]],"id":41818958}],"con":true,"img":false}]}
{"op":"mcm","clk":"5348364009","pt":1646216897549,"mc":[{"id":"1.195453627","rc":[{"atb":[[4,0]],"id":39734233}],"con":true,"img":false}]}
{"op":"mcm","clk":"5348364018","pt":1646216897652,"mc":[{"id":"1.195453627","rc":[{"atb":[[4.2,20.15]],"id":39734233}],"con":true,"img":false}]}
{"op":"mcm","clk":"5348364878","pt":1646216907267,"mc":[{"id":"1.195453627","rc":[{"atb":[[4.1,17.3]],"id":39734233}],"con":true,"img":false}]}
{"op":"mcm","clk":"5348365670","pt":1646216916231,"mc":[{"id":"1.195453627","rc":[{"atb":[[4.3,2.27]],"id":39734233},{"spn":6.25,"spf":"NaN","id":39734233}],"con":true,"img":false}]}
{"op":"mcm","clk":"5348365954","pt":1646216919054,"mc":[{"id":"1.195453627","rc":[{"atb":[[4.1,14.6]],"id":39734233}],"con":true,"img":false}]}
{"op":"mcm","clk":"5348366410","pt":1646216923968,"mc":[{"id":"1.195453627","rc":[{"atb":[[4.1,2]],"id":39734233}],"con":true,"img":false}]}
{"op":"mcm","clk":"5348366425","pt":1646216924192,"mc":[{"id":"1.195453627","rc":[{"atb":[[4.3,14.11]],"id":39734233}],"con":true,"img":false}]}
{"op":"mcm","clk":"5348367373","pt":1646216934270,"mc":[{"id":"1.195453627","rc":[{"atb":[[4.3,16.63]],"id":39734233}],"con":true,"img":false}]}
{"op":"mcm","clk":"5348369514","pt":1646216958798,"mc":[{"id":"1.195453627","rc":[{"atb":[[4.2,0]],"id":39734233}],"con":true,"img":false}]}
{"op":"mcm","clk":"5348369526","pt":1646216958904,"mc":[{"id":"1.195453627","rc":[{"atb":[[4.4,20.15]],"id":39734233}],"con":true,"img":false}]}
{"op":"mcm","clk":"5348369953","pt":1646216964220,"mc":[{"id":"1.195453627","rc":[{"atb":[[2.96,0]],"id":27868829}],"con":true,"img":false}]}
{"op":"mcm","clk":"5348370225","pt":1646216967404,"mc":[{"id":"1.195453627","rc":[{"atb":[[4.3,14.36]],"id":39734233}],"con":true,"img":false}]}
{"op":"mcm","clk":"5348371067","pt":1646216976338,"mc":[{"id":"1.195453627","rc":[{"atb":[[1.01,3.85]],"id":39734233},{"spn":6.3,"spf":"NaN","id":39734233}],"con":true,"img":false}]}
{"op":"mcm","clk":"5348371083","pt":1646216976545,"mc":[{"id":"1.195453627","rc":[{"atb":[[1.01,3.75]],"id":39734233}],"con":true,"img":false}]}
{"op":"mcm","clk":"5348371097","pt":1646216976752,"mc":[{"id":"1.195453627","rc":[{"atb":[[1.01,1.6]],"id":39734233}],"con":true,"img":false}]}
{"op":"mcm","clk":"5348371105","pt":1646216976854,"mc":[{"id":"1.195453627","rc":[{"atb":[[4.5,2.15]],"id":39734233}],"con":true,"img":false}]}
{"op":"mcm","clk":"5348371380","pt":1646216979642,"mc":[{"id":"1.195453627","rc":[{"atb":[[4.3,11.83]],"id":39734233}],"con":true,"img":false}]}
{"op":"mcm","clk":"5348372738","pt":1646216995291,"mc":[{"id":"1.195453627","rc":[{"atb":[[4.5,4.53]],"id":39734233}],"con":true,"img":false}]}
{"op":"mcm","clk":"5348375213","pt":1646217022599,"mc":[{"id":"1.195453627","rc":[{"atb":[[4.5,0]],"id":39734233},{"trd":[[4.5,9.06]],"ltp":4.5,"tv":9.06,"id":39734233}],"con":true,"img":false}]}
{"op":"mcm","clk":"5348375394","pt":1646217024486,"mc":[{"id":"1.195453627","rc":[{"atl":[[1000,2.25]],"id":39734233}],"con":true,"img":false}]}
{"op":"mcm","clk":"5348375424","pt":1646217024694,"mc":[{"id":"1.195453627","rc":[{"atl":[[1000,1.78]],"id":39734233}],"con":true,"img":false}]}
{"op":"mcm","clk":"5348375435","pt":1646217024808,"mc":[{"id":"1.195453627","rc":[{"atl":[[1000,0]],"id":39734233}],"con":true,"img":false}]}
{"op":"mcm","clk":"5348375445","pt":1646217024898,"mc":[{"id":"1.195453627","rc":[{"atl":[[5.4,1.78]],"id":39734233}],"con":true,"img":false}]}
{"op":"mcm","clk":"5348376016","pt":1646217031000,"mc":[{"id":"1.195453627","rc":[{"atb":[[4.4,10.14]],"id":39734233},{"trd":[[4.4,20.02]],"ltp":4.4,"tv":20.02,"id":39734233}],"con":true,"img":false}]}
{"op":"mcm","clk":"5348376100","pt":1646217031900,"mc":[{"id":"1.195453627","rc":[{"atb":[[4.5,1.3]],"id":39734233},{"atb":[[4.7,3.42]],"id":41818958},{"atb":[[5.2,5.05]],"id":40324291}],"con":true,"img":false}]}
{"op":"mcm","clk":"5348376215","pt":1646217033099,"mc":[{"id":"1.195453627","rc":[{"atl":[[9.8,0]],"id":41818958},{"atl":[[14,9.28]],"id":38214982},{"atl":[[3.6,0]],"id":38761677},{"atl":[[11.5,0],[15.5,0]],"id":40324291}],"con":true,"img":false}]}
{"op":"mcm","clk":"5348376226","pt":1646217033200,"mc":[{"id":"1.195453627","rc":[{"atl":[[11.5,6.64]],"id":41818958},{"atl":[[3.85,8.17],[4.1,21.64]],"id":38761677},{"atl":[[16.5,8.88],[13,5.56]],"id":40324291}],"con":true,"img":false}]}
{"op":"mcm","clk":"5348376235","pt":1646217033302,"mc":[{"id":"1.195453627","rc":[{"atl":[[11.5,0],[14,0]],"id":38214982}],"con":true,"img":false}]}
{"op":"mcm","clk":"5348376242","pt":1646217033406,"mc":[{"id":"1.195453627","rc":[{"atl":[[2.78,0]],"id":38761677}],"con":true,"img":false}]}
{"op":"mcm","clk":"5348376252","pt":1646217033512,"mc":[{"id":"1.195453627","rc":[{"atl":[[1000,1.23]],"id":38761677}],"con":true,"img":false}]}
{"op":"mcm","clk":"5348376299","pt":1646217033992,"mc":[{"id":"1.195453627","rc":[{"atl":[[13,9.69]],"id":41818958},{"atl":[[16.5,7.55]],"id":40324291}],"con":true,"img":false}]}
{"op":"mcm","clk":"5348376309","pt":1646217034105,"mc":[{"id":"1.195453627","rc":[{"atl":[[11,1.31]],"id":41818958},{"atl":[[12.5,1.32]],"id":40324291}],"con":true,"img":false}]}
{"op":"mcm","clk":"5348376767","pt":1646217039129,"mc":[{"id":"1.195453627","rc":[{"atl":[[5.4,3.77]],"id":39734233},{"spn":4.95,"spf":"NaN","id":39734233},{"spn":7.9,"spf":"NaN","id":41818958},{"spn":2.51,"spf":"NaN","id":38761677},{"spn":8.85,"spf":"NaN","id":40324291}],"con":true,"img":false}]}
{"op":"mcm","clk":"5348376798","pt":1646217039547,"mc":[{"id":"1.195453627","rc":[{"atb":[[4.5,0]],"id":39734233}],"con":true,"img":false}]}
{"op":"mcm","clk":"5348376810","pt":1646217039635,"mc":[{"id":"1.195453627","rc":[{"atb":[[1.02,1.3]],"id":39734233}],"con":true,"img":false}]}
{"op":"mcm","clk":"5348376891","pt":1646217040440,"mc":[{"id":"1.195453627","rc":[{"atb":[[4.4,0]],"id":39734233},{"atl":[[11,0]],"id":38214982},{"atl":[[34,1.34]],"id":27868829}],"con":true,"img":false}]}
{"op":"mcm","clk":"5348376899","pt":1646217040542,"mc":[{"id":"1.195453627","rc":[{"atb":[[3.85,10.14]],"id":39734233},{"atl":[[11.5,5.84]],"id":38214982},{"atl":[[44,5.44]],"id":27868829}],"con":true,"img":false}]}
{"op":"mcm","clk":"5348377721","pt":1646217049143,"mc":[{"id":"1.195453627","rc":[{"atb":[[4.3,0]],"id":39734233}],"con":true,"img":false}]}
{"op":"mcm","clk":"5348377793","pt":1646217049823,"mc":[{"id":"1.195453627","rc":[{"atb":[[1.02,0]],"id":39734233}],"con":true,"img":false}]}
{"op":"mcm","clk":"5348377798","pt":1646217049928,"mc":[{"id":"1.195453627","rc":[{"atb":[[3.9,1.3]],"id":39734233}],"con":true,"img":false}]}
{"op":"mcm","clk":"5348378025","pt":1646217052539,"mc":[{"id":"1.195453627","rc":[{"atb":[[3.85,20.87]],"id":39734233}],"con":true,"img":false}]}
{"op":"mcm","clk":"5348379292","pt":1646217065442,"mc":[{"id":"1.195453627","rc":[{"atl":[[5.7,5.73],[8.4,0]],"id":39734233},{"atl":[[14,9.28]],"id":38214982}],"con":true,"img":false}]}
{"op":"mcm","clk":"5348379350","pt":1646217066239,"mc":[{"id":"1.195453627","rc":[{"atl":[[8.2,0]],"id":39734233}],"con":true,"img":false}]}
{"op":"mcm","clk":"5348379358","pt":1646217066338,"mc":[{"id":"1.195453627","rc":[{"atl":[[5.3,1.32]],"id":39734233}],"con":true,"img":false}]}
{"op":"mcm","clk":"5348379642","pt":1646217069248,"mc":[{"id":"1.195453627","rc":[{"atl":[[5.4,1.78]],"id":39734233}],"con":true,"img":false}]}
{"op":"mcm","clk":"5348379672","pt":1646217069455,"mc":[{"id":"1.195453627","rc":[{"atl":[[5.1,2.1]],"id":39734233}],"con":true,"img":false}]}
{"op":"mcm","clk":"5348379699","pt":1646217069658,"mc":[{"id":"1.195453627","rc":[{"atl":[[5.3,0]],"id":39734233}],"con":true,"img":false}]}
{"op":"mcm","clk":"5348379711","pt":1646217069763,"mc":[{"id":"1.195453627","rc":[{"atl":[[1000,1.32]],"id":39734233}],"con":true,"img":false}]}
{"op":"mcm","clk":"5348385854","pt":1646217138969,"mc":[{"id":"1.195453627","rc":[{"atb":[[3,45.54]],"id":39734233},{"atl":[[11.5,9.52]],"id":39734233},{"spn":4.6,"spf":"NaN","id":39734233},{"atb":[[3,41.29]],"id":41818958},{"atl":[[25,12.37]],"id":41818958},{"atb":[[1.26,65.4]],"id":38214982},{"atl":[[24,4.35]],"id":38214982},{"atb":[[4.8,48.37]],"id":27868829},{"atl":[[110,2]],"id":27868829},{"atb":[[1.88,208.86]],"id":38761677},{"atl":[[12,9.09]],"id":38761677},{"atb":[[3.45,40.82]],"id":40324291},{"atl":[[32,3.23]],"id":40324291}],"con":true,"img":false}]}
{"op":"mcm","clk":"5348388420","pt":1646217168975,"mc":[{"id":"1.195453627","rc":[{"atb":[[3.85,0],[3.5,0],[3.65,22.05]],"id":39734233},{"atl":[[4.9,0]],"id":38761677}],"con":true,"img":false}]}
{"op":"mcm","clk":"5348388430","pt":1646217169083,"mc":[{"id":"1.195453627","rc":[{"atb":[[3.4,45.01]],"id":39734233},{"atl":[[5.3,26.42]],"id":38761677}],"con":true,"img":false}]}
{"op":"mcm","clk":"5348388503","pt":1646217169964,"mc":[{"id":"1.195453627","rc":[{"atb":[[3.9,0]],"id":39734233}],"con":true,"img":false}]}
{"op":"mcm","clk":"5348388512","pt":1646217170067,"mc":[{"id":"1.195453627","rc":[{"atb":[[3.7,1.3]],"id":39734233}],"con":true,"img":false}]}
{"op":"mcm","clk":"5348389735","pt":1646217183604,"mc":[{"id":"1.195453627","rc":[{"atb":[[2.22,13]],"id":38761677}],"con":true,"img":false}]}
{"op":"mcm","clk":"5348389745","pt":1646217183705,"mc":[{"id":"1.195453627","rc":[{"atb":[[2.26,2]],"id":38761677}],"con":true,"img":false}]}
{"op":"mcm","clk":"5348391724","pt":1646217205720,"mc":[{"id":"1.195453627","rc":[{"atl":[[5.1,0]],"id":39734233},{"spn":4.75,"spf":"NaN","id":39734233},{"spn":2.53,"spf":"NaN","id":38761677}],"con":true,"img":false}]}
{"op":"mcm","clk":"5348391754","pt":1646217206033,"mc":[{"id":"1.195453627","rc":[{"atl":[[5.4,3.77]],"id":39734233}],"con":true,"img":false}]}
{"op":"mcm","clk":"5348391799","pt":1646217206711,"mc":[{"id":"1.195453627","rc":[{"atl":[[1000,0]],"id":39734233}],"con":true,"img":false}]}
{"op":"mcm","clk":"5348391806","pt":1646217206813,"mc":[{"id":"1.195453627","rc":[{"atl":[[5.3,1.32]],"id":39734233}],"con":true,"img":false}]}
{"op":"mcm","clk":"5348392610","pt":1646217216747,"mc":[{"id":"1.195453627","rc":[{"atl":[[5.4,1.98]],"id":39734233}],"con":true,"img":false}]}
{"op":"mcm","clk":"5348392630","pt":1646217216959,"mc":[{"id":"1.195453627","rc":[{"atl":[[1000,2.25]],"id":39734233}],"con":true,"img":false}]}
{"op":"mcm","clk":"5348392652","pt":1646217217120,"mc":[{"id":"1.195453627","rc":[{"atl":[[1000,2.09]],"id":39734233}],"con":true,"img":false}]}
{"op":"mcm","clk":"5348392669","pt":1646217217331,"mc":[{"id":"1.195453627","rc":[{"atl":[[1000,0]],"id":39734233}],"con":true,"img":false}]}
{"op":"mcm","clk":"5348392678","pt":1646217217439,"mc":[{"id":"1.195453627","rc":[{"atl":[[5.3,0],[4.6,2.09]],"id":39734233}],"con":true,"img":false}]}
{"op":"mcm","clk":"5348392687","pt":1646217217539,"mc":[{"id":"1.195453627","rc":[{"atl":[[1000,1.32]],"id":39734233}],"con":true,"img":false}]}
{"op":"mcm","clk":"5348393051","pt":1646217221356,"mc":[{"id":"1.195453627","rc":[{"atl":[[5.4,0]],"id":39734233}],"con":true,"img":false}]}
{"op":"mcm","clk":"5348393093","pt":1646217221828,"mc":[{"id":"1.195453627","rc":[{"atl":[[4.6,4.42]],"id":39734233}],"con":true,"img":false}]}
{"op":"mcm","clk":"5348393206","pt":1646217223128,"mc":[{"id":"1.195453627","rc":[{"atb":[[3.7,0]],"id":39734233}],"con":true,"img":false}]}
{"op":"mcm","clk":"5348393215","pt":1646217223233,"mc":[{"id":"1.195453627","rc":[{"atb":[[1.02,1.3]],"id":39734233}],"con":true,"img":false}]}
{"op":"mcm","clk":"5348394931","pt":1646217241652,"mc":[{"id":"1.195453627","rc":[{"atl":[[11,0]],"id":41818958},{"atl":[[34,0]],"id":27868829},{"atl":[[12.5,0]],"id":40324291}],"con":true,"img":false}]}
{"op":"mcm","clk":"5348394942","pt":1646217241758,"mc":[{"id":"1.195453627","rc":[{"atl":[[1000,1.31]],"id":41818958},{"atl":[[1000,1.34]],"id":27868829},{"atl":[[1000,1.32]],"id":40324291}],"con":true,"img":false}]}
{"op":"mcm","clk":"5348395069","pt":1646217243084,"mc":[{"id":"1.195453627","rc":[{"atl":[[7.2,4.53],[5.7,0]],"id":39734233}],"con":true,"img":false}]}
{"op":"mcm","clk":"5348397238","pt":1646217267278,"mc":[{"id":"1.195453627","rc":[{"spn":4.35,"spf":"NaN","id":39734233},{"spn":8.15,"spf":"NaN","id":41818958},{"atb":[[4.2,26.56]],"id":27868829},{"spn":24.75,"spf":"NaN","id":27868829},{"spn":9.1,"spf":"NaN","id":40324291}],"con":true,"img":false}]}
{"op":"mcm","clk":"5348397246","pt":1646217267387,"mc":[{"id":"1.195453627","rc":[{"atl":[[34,27.7]],"id":41818958}],"con":true,"img":false}]}
{"op":"mcm","clk":"5348397661","pt":1646217272205,"mc":[{"id":"1.195453627","rc":[{"atl":[[7.2,0]],"id":39734233}],"con":true,"img":false}]}
{"op":"mcm","clk":"5348397671","pt":1646217272305,"mc":[{"id":"1.195453627","rc":[{"atl":[[7,4.53]],"id":39734233}],"con":true,"img":false}]}
{"op":"mcm","clk":"5348402160","pt":1646217319203,"mc":[{"id":"1.195453627","rc":[{"atb":[[3.4,0]],"id":39734233},{"atl":[[4.1,0]],"id":38761677}],"con":true,"img":false}]}
{"op":"mcm","clk":"5348402168","pt":1646217319260,"mc":[{"id":"1.195453627","rc":[{"atb":[[3.05,45.01]],"id":39734233},{"atl":[[4.3,21.64]],"id":38761677}],"con":true,"img":false}]}
{"op":"mcm","clk":"5348403140","pt":1646217329186,"mc":[{"id":"1.195453627","rc":[{"atb":[[3.65,0]],"id":39734233},{"atl":[[11.5,0]],"id":38214982}],"con":true,"img":false}]}
{"op":"mcm","clk":"5348403149","pt":1646217329303,"mc":[{"id":"1.195453627","rc":[{"atb":[[3.4,22.05]],"id":39734233},{"atl":[[13,5.84]],"id":38214982}],"con":true,"img":false}]}
{"op":"mcm","clk":"5348404744","pt":1646217346505,"mc":[{"id":"1.195453627","rc":[{"atb":[[5,0]],"id":38214982}],"con":true,"img":false}]}
{"op":"mcm","clk":"5348404758","pt":1646217346607,"mc":[{"id":"1.195453627","rc":[{"atb":[[5.1,14.61]],"id":38214982}],"con":true,"img":false}]}
{"op":"mcm","clk":"5348407610","pt":1646217376946,"mc":[{"id":"1.195453627","rc":[{"atb":[[1.99,0]],"id":38761677}],"con":true,"img":false}]}
{"op":"mcm","clk":"5348407619","pt":1646217377048,"mc":[{"id":"1.195453627","rc":[{"atb":[[2.18,164.31]],"id":38761677}],"con":true,"img":false}]}
{"op":"mcm","clk":"5348410092","pt":1646217405366,"mc":[{"id":"1.195453627","rc":[{"atb":[[3.45,15.93]],"id":39734233},{"spn":3.92,"spf":1.0,"id":38214982}],"con":true,"img":false}]}
{"op":"mcm","clk":"5348411070","pt":1646217416394,"mc":[{"id":"1.195453627","rc":[{"atb":[[1.01,2.25]],"id":41818958},{"atb":[[1.03,2.25]],"id":27868829},{"atb":[[1.03,2.25]],"id":40324291}],"con":true,"img":false}]}
{"op":"mcm","clk":"5348411080","pt":1646217416502,"mc":[{"id":"1.195453627","rc":[{"atb":[[1.01,0.6]],"id":41818958},{"atb":[[1.03,0.27]],"id":27868829},{"atb":[[1.03,0.57]],"id":40324291}],"con":true,"img":false}]}
{"op":"mcm","clk":"5348411097","pt":1646217416710,"mc":[{"id":"1.195453627","rc":[{"atb":[[1.03,0]],"id":40324291}],"con":true,"img":false}]}
{"op":"mcm","clk":"5348411105","pt":1646217416817,"mc":[{"id":"1.195453627","rc":[{"atb":[[6.6,0.57]],"id":40324291}],"con":true,"img":false}]}
{"op":"mcm","clk":"5348411113","pt":1646217416878,"mc":[{"id":"1.195453627","rc":[{"atb":[[1.01,0]],"id":41818958}],"con":true,"img":false}]}
{"op":"mcm","clk":"5348411124","pt":1646217416982,"mc":[{"id":"1.195453627","rc":[{"atb":[[6.2,0.6]],"id":41818958}],"con":true,"img":false}]}
{"op":"mcm","clk":"5348411139","pt":1646217417192,"mc":[{"id":"1.195453627","rc":[{"atb":[[1.03,0]],"id":27868829}],"con":true,"img":false}]}
{"op":"mcm","clk":"5348411149","pt":1646217417302,"mc":[{"id":"1.195453627","rc":[{"atb":[[14,0.27]],"id":27868829}],"con":true,"img":false}]}
{"op":"mcm","clk":"5348411860","pt":1646217424415,"mc":[{"id":"1.195453627","rc":[{"atb":[[3.05,0]],"id":39734233}],"con":true,"img":false}]}
{"op":"mcm","clk":"5348411869","pt":1646217424548,"mc":[{"id":"1.195453627","rc":[{"atb":[[3.4,67.07]],"id":39734233}],"con":true,"img":false}]}
{"op":"mcm","clk":"5348412938","pt":1646217435832,"mc":[{"id":"1.195453627","rc":[{"atb":[[3.4,45.01]],"id":39734233}],"con":true,"img":false}]}
{"op":"mcm","clk":"5348412948","pt":1646217435938,"mc":[{"id":"1.195453627","rc":[{"atb":[[3.5,22.05]],"id":39734233}],"con":true,"img":false}]}
{"op":"mcm","clk":"5348412965","pt":1646217436149,"mc":[{"id":"1.195453627","rc":[{"atb":[[2.5,66.67],[3,0],[4.1,0]],"id":39734233},{"atl":[[8.6,27.96],[11.5,0]],"id":39734233},{"atb":[[3,0],[1.36,33.36]],"id":41818958},{"atb":[[5.6,0]],"id":38214982},{"atl":[[24,0],[14,16.97]],"id":38214982},{"atl":[[48,2.13],[110,0]],"id":27868829},{"atb":[[1.44,180.2],[1.88,95.22]],"id":38761677},{"atb":[[3.45,0],[1.49,67.04]],"id":40324291}],"con":true,"img":false}]}
{"op":"mcm","clk":"5348415667","pt":1646217465684,"mc":[{"id":"1.195453627","rc":[{"atb":[[3.45,0]],"id":39734233},{"spn":4.05,"spf":"NaN","id":39734233},{"spn":8.85,"spf":"NaN","id":41818958},{"spn":3.92,"spf":1.0,"id":38214982},{"spn":25.0,"spf":"NaN","id":27868829},{"spn":9.8,"spf":"NaN","id":40324291}],"con":true,"img":false}]}
{"op":"mcm","clk":"5348415691","pt":1646217465889,"mc":[{"id":"1.195453627","rc":[{"atb":[[3.7,14.46]],"id":39734233}],"con":true,"img":false}]}
{"op":"mcm","clk":"5348415900","pt":1646217467996,"mc":[{"id":"1.195453627","rc":[{"atl":[[7,0]],"id":39734233},{"atl":[[44,2.72]],"id":27868829}],"con":true,"img":false}]}
{"op":"mcm","clk":"5348415910","pt":1646217468099,"mc":[{"id":"1.195453627","rc":[{"atl":[[6.8,4.53]],"id":39734233},{"atl":[[42,2.72]],"id":27868829}],"con":true,"img":false}]}
{"op":"mcm","clk":"5348416112","pt":1646217470204,"mc":[{"id":"1.195453627","rc":[{"atb":[[2.8,48.16],[2.5,0]],"id":39734233},{"atl":[[48,0]],"id":27868829},{"atb":[[1.44,0],[1.68,147.06]],"id":38761677},{"atb":[[2.38,67.12],[1.49,0]],"id":40324291}],"con":true,"img":false}]}
{"op":"mcm","clk":"5348416121","pt":1646217470263,"mc":[{"id":"1.195453627","rc":[{"atl":[[42,5.16]],"id":27868829}],"con":true,"img":false}]}
{"op":"mcm","clk":"5348416546","pt":1646217474815,"mc":[{"id":"1.195453627","rc":[{"atl":[[6.8,0]],"id":39734233}],"con":true,"img":false}]}
{"op":"mcm","clk":"5348416558","pt":1646217474870,"mc":[{"id":"1.195453627","rc":[{"atl":[[7,4.53]],"id":39734233}],"con":true,"img":false}]}
{"op":"mcm","clk":"5348419007","pt":1646217500330,"mc":[{"id":"1.195453627","rc":[{"atb":[[3.5,0]],"id":39734233}],"con":true,"img":false}]}
{"op":"mcm","clk":"5348419020","pt":1646217500435,"mc":[{"id":"1.195453627","rc":[{"atb":[[3.75,22.05]],"id":39734233}],"con":true,"img":false}]}
{"op":"mcm","clk":"5348419620","pt":1646217506214,"mc":[{"id":"1.195453627","rc":[{"atl":[[7,0]],"id":39734233},{"atl":[[42,2.44]],"id":27868829}],"con":true,"img":false}]}
{"op":"mcm","clk":"5348419629","pt":1646217506313,"mc":[{"id":"1.195453627","rc":[{"atl":[[6.8,4.53]],"id":39734233},{"atl":[[40,2.72]],"id":27868829}],"con":true,"img":false}]}
{"op":"mcm","clk":"5348422804","pt":1646217540780,"mc":[{"id":"1.195453627","rc":[{"atl":[[5.6,5.83],[6.8,0]],"id":39734233},{"spn":4.17,"spf":"NaN","id":39734233}],"con":true,"img":false}]}
{"op":"mcm","clk":"5348424121","pt":1646217556094,"mc":[{"id":"1.195453627","rc":[{"atb":[[2.8,0],[2.64,163.16]],"id":39734233},{"atb":[[1.36,0]],"id":41818958},{"atl":[[42,0],[46,5.13]],"id":27868829},{"atb":[[1.68,0],[1.55,181.82]],"id":38761677},{"atb":[[1.89,67.04],[2.38,0]],"id":40324291}],"con":true,"img":false}]}
{"op":"mcm","clk":"5348424642","pt":1646217562733,"mc":[{"id":"1.195453627","rc":[{"atl":[[40,0]],"id":27868829}],"con":true,"img":false}]}
{"op":"mcm","clk":"5348424655","pt":1646217562829,"mc":[{"id":"1.195453627","rc":[{"atl":[[44,5.44]],"id":27868829}],"con":true,"img":false}]}
{"op":"mcm","clk":"5348425054","pt":1646217567741,"mc":[{"id":"1.195453627","rc":[{"atl":[[5.6,0],[7,4.67]],"id":39734233}],"con":true,"img":false}]}
{"op":"mcm","clk":"5348427250","pt":1646217592849,"mc":[{"id":"1.195453627","rc":[{"atl":[[7,0]],"id":39734233},{"atl":[[44,2.72]],"id":27868829}],"con":true,"img":false}]}
{"op":"mcm","clk":"5348427260","pt":1646217592958,"mc":[{"id":"1.195453627","rc":[{"atl":[[6.8,4.67]],"id":39734233},{"atl":[[42,2.72]],"id":27868829}],"con":true,"img":false}]}
{"op":"mcm","clk":"5348427363","pt":1646217594123,"mc":[{"id":"1.195453627","rc":[{"atb":[[3.7,0]],"id":39734233}],"con":true,"img":false}]}
{"op":"mcm","clk":"5348427378","pt":1646217594327,"mc":[{"id":"1.195453627","rc":[{"atb":[[3.8,13.92]],"id":39734233}],"con":true,"img":false}]}
{"op":"mcm","clk":"5348427471","pt":1646217595638,"mc":[{"id":"1.195453627","rc":[{"atl":[[4.6,2.32]],"id":39734233}],"con":true,"img":false}]}
{"op":"mcm","clk":"5348427481","pt":1646217595740,"mc":[{"id":"1.195453627","rc":[{"atl":[[1000,3.58]],"id":39734233}],"con":true,"img":false}]}
{"op":"mcm","clk":"5348427505","pt":1646217595949,"mc":[{"id":"1.195453627","rc":[{"atl":[[1000,2.88]],"id":39734233}],"con":true,"img":false}]}
{"op":"mcm","clk":"5348427525","pt":1646217596156,"mc":[{"id":"1.195453627","rc":[{"atl":[[1000,1.32]],"id":39734233}],"con":true,"img":false}]}
{"op":"mcm","clk":"5348427532","pt":1646217596262,"mc":[{"id":"1.195453627","rc":[{"atb":[[1.02,0]],"id":39734233},{"atl":[[6.2,1.55]],"id":39734233}],"con":true,"img":false}]}
{"op":"mcm","clk":"5348427541","pt":1646217596374,"mc":[{"id":"1.195453627","rc":[{"atb":[[3.85,1.3]],"id":39734233}],"con":true,"img":false}]}
{"op":"mcm","clk":"5348427650","pt":1646217597628,"mc":[{"id":"1.195453627","rc":[{"atl":[[6.8,0]],"id":39734233}],"con":true,"img":false}]}
{"op":"mcm","clk":"5348427660","pt":1646217597728,"mc":[{"id":"1.195453627","rc":[{"atl":[[7,4.67]],"id":39734233}],"con":true,"img":false}]}
{"op":"mcm","clk":"5348427735","pt":1646217598668,"mc":[{"id":"1.195453627","rc":[{"atl":[[6.2,0]],"id":39734233}],"con":true,"img":false}]}
{"op":"mcm","clk":"5348427771","pt":1646217599038,"mc":[{"id":"1.195453627","rc":[{"atl":[[1000,3.58]],"id":39734233}],"con":true,"img":false}]}
{"op":"mcm","clk":"5348427799","pt":1646217599353,"mc":[{"id":"1.195453627","rc":[{"atl":[[1000,3.42]],"id":39734233}],"con":true,"img":false}]}
{"op":"mcm","clk":"5348427818","pt":1646217599562,"mc":[{"id":"1.195453627","rc":[{"atl":[[1000,1.32]],"id":39734233}],"con":true,"img":false}]}
{"op":"mcm","clk":"5348427827","pt":1646217599669,"mc":[{"id":"1.195453627","rc":[{"atl":[[4.6,4.42]],"id":39734233}],"con":true,"img":false}]}
{"op":"mcm","clk":"5348427904","pt":1646217600562,"mc":[{"id":"1.195453627","rc":[{"atb":[[3.85,0]],"id":39734233}],"con":true,"img":false}]}
{"op":"mcm","clk":"5348427913","pt":1646217600667,"mc":[{"id":"1.195453627","rc":[{"atb":[[1.02,1.3]],"id":39734233}],"con":true,"img":false}]}
{"op":"mcm","clk":"5348427993","pt":1646217601658,"mc":[{"id":"1.195453627","rc":[{"atl":[[4.6,2.32]],"id":39734233},{"spn":4.2,"spf":"NaN","id":39734233}],"con":true,"img":false}]}
{"op":"mcm","clk":"5348428007","pt":1646217601867,"mc":[{"id":"1.195453627","rc":[{"atl":[[1000,3.58]],"id":39734233}],"con":true,"img":false}]}
{"op":"mcm","clk":"5348428037","pt":1646217602132,"mc":[{"id":"1.195453627","rc":[{"atb":[[1.02,0]],"id":39734233},{"atl":[[1000,2.83]],"id":39734233}],"con":true,"img":false}]}
{"op":"mcm","clk":"5348428047","pt":1646217602267,"mc":[{"id":"1.195453627","rc":[{"atb":[[3.85,1.3]],"id":39734233}],"con":true,"img":false}]}
{"op":"mcm","clk":"5348428059","pt":1646217602342,"mc":[{"id":"1.195453627","rc":[{"atl":[[1000,1.32]],"id":39734233}],"con":true,"img":false}]}
{"op":"mcm","clk":"5348428066","pt":1646217602443,"mc":[{"id":"1.195453627","rc":[{"atl":[[6.4,1.51]],"id":39734233}],"con":true,"img":false}]}
{"op":"mcm","clk":"5348428186","pt":1646217603966,"mc":[{"id":"1.195453627","rc":[{"atl":[[4.6,0]],"id":39734233}],"con":true,"img":false}]}
{"op":"mcm","clk":"5348428210","pt":1646217604282,"mc":[{"id":"1.195453627","rc":[{"atl":[[6.4,3.18]],"id":39734233}],"con":true,"img":false}]}
{"op":"mcm","clk":"5348428519","pt":1646217607452,"mc":[{"id":"1.195453627","rc":[{"atl":[[1000,0]],"id":41818958},{"atl":[[1000,0]],"id":27868829},{"atl":[[1000,0]],"id":40324291}],"con":true,"img":false}]}
{"op":"mcm","clk":"5348428532","pt":1646217607549,"mc":[{"id":"1.195453627","rc":[{"atl":[[11,1.31]],"id":41818958},{"atl":[[34,1.34]],"id":27868829},{"atl":[[12.5,1.32]],"id":40324291}],"con":true,"img":false}]}
{"op":"mcm","clk":"5348428921","pt":1646217611552,"mc":[{"id":"1.195453627","rc":[{"atb":[[3.75,0]],"id":39734233}],"con":true,"img":false}]}
{"op":"mcm","clk":"5348428931","pt":1646217611655,"mc":[{"id":"1.195453627","rc":[{"atb":[[3.5,22.05]],"id":39734233}],"con":true,"img":false}]}
{"op":"mcm","clk":"5348429407","pt":1646217616888,"mc":[{"id":"1.195453627","rc":[{"atl":[[6.4,1.51]],"id":39734233}],"con":true,"img":false}]}
{"op":"mcm","clk":"5348429464","pt":1646217617475,"mc":[{"id":"1.195453627","rc":[{"atl":[[6.2,1.72],[1000,0]],"id":39734233}],"con":true,"img":false}]}
{"op":"mcm","clk":"5348429472","pt":1646217617573,"mc":[{"id":"1.195453627","rc":[{"atl":[[6.8,1.32]],"id":39734233}],"con":true,"img":false}]}
{"op":"mcm","clk":"5348430330","pt":1646217626700,"mc":[{"id":"1.195453627","rc":[{"atb":[[1.03,2.25]],"id":40324291}],"con":true,"img":false}]}
{"op":"mcm","clk":"5348430340","pt":1646217626803,"mc":[{"id":"1.195453627","rc":[{"atb":[[6.6,0]],"id":40324291}],"con":true,"img":false}]}
{"op":"mcm","clk":"5348430349","pt":1646217626911,"mc":[{"id":"1.195453627","rc":[{"atb":[[1.03,0.57]],"id":40324291}],"con":true,"img":false}]}
{"op":"mcm","clk":"5348430360","pt":1646217627016,"mc":[{"id":"1.195453627","rc":[{"atb":[[1.01,2.25],[6.2,0]],"id":41818958}],"con":true,"img":false}]}
{"op":"mcm","clk":"5348430372","pt":1646217627076,"mc":[{"id":"1.195453627","rc":[{"atb":[[1.03,0]],"id":40324291}],"con":true,"img":false}]}
{"op":"mcm","clk":"5348430384","pt":1646217627177,"mc":[{"id":"1.195453627","rc":[{"atb":[[5.3,0.57]],"id":40324291}],"con":true,"img":false}]}
{"op":"mcm","clk":"5348430402","pt":1646217627390,"mc":[{"id":"1.195453627","rc":[{"atb":[[1.01,0.6]],"id":41818958}],"con":true,"img":false}]}
{"op":"mcm","clk":"5348430437","pt":1646217627699,"mc":[{"id":"1.195453627","rc":[{"atb":[[1.01,0]],"id":41818958}],"con":true,"img":false}]}
{"op":"mcm","clk":"5348430447","pt":1646217627804,"mc":[{"id":"1.195453627","rc":[{"atb":[[4.9,0.6]],"id":41818958}],"con":true,"img":false}]}
{"op":"mcm","clk":"5348431280","pt":1646217636519,"mc":[{"id":"1.195453627","rc":[{"atl":[[7,0]],"id":39734233}],"con":true,"img":false}]}
{"op":"mcm","clk":"5348431288","pt":1646217636624,"mc":[{"id":"1.195453627","rc":[{"atl":[[6,4.67]],"id":39734233}],"con":true,"img":false}]}
{"op":"mcm","clk":"5348431308","pt":1646217636831,"mc":[{"id":"1.195453627","rc":[{"atl":[[6.8,0]],"id":39734233}],"con":true,"img":false}]}
{"op":"mcm","clk":"5348431316","pt":1646217636938,"mc":[{"id":"1.195453627","rc":[{"atl":[[8.4,1.32]],"id":39734233}],"con":true,"img":false}]}
{"op":"mcm","clk":"5348431395","pt":1646217637725,"mc":[{"id":"1.195453627","rc":[{"atl":[[6.4,0]],"id":39734233}],"con":true,"img":false}]}
{"op":"mcm","clk":"5348431414","pt":1646217637933,"mc":[{"id":"1.195453627","rc":[{"atl":[[1000,2.25]],"id":39734233}],"con":true,"img":false}]}
{"op":"mcm","clk":"5348431433","pt":1646217638141,"mc":[{"id":"1.195453627","rc":[{"atl":[[1000,1.63]],"id":39734233}],"con":true,"img":false}]}
{"op":"mcm","clk":"5348431454","pt":1646217638296,"mc":[{"id":"1.195453627","rc":[{"atl":[[1000,0]],"id":39734233}],"con":true,"img":false}]}
{"op":"mcm","clk":"5348431469","pt":1646217638400,"mc":[{"id":"1.195453627","rc":[{"atl":[[5.9,1.63]],"id":39734233}],"con":true,"img":false}]}
{"op":"mcm","clk":"5348431946","pt":1646217643121,"mc":[{"id":"1.195453627","rc":[{"atl":[[46,2.91],[55,2]],"id":27868829}],"con":true,"img":false}]}
{"op":"mcm","clk":"5348432301","pt":1646217646720,"mc":[{"id":"1.195453627","rc":[{"atl":[[6.2,0]],"id":39734233}],"con":true,"img":false}]}
{"op":"mcm","clk":"5348432326","pt":1646217647036,"mc":[{"id":"1.195453627","rc":[{"atl":[[4.6,2.32]],"id":39734233}],"con":true,"img":false}]}
{"op":"mcm","clk":"5348432549","pt":1646217649452,"mc":[{"id":"1.195453627","rc":[{"atl":[[6,0]],"id":39734233}],"con":true,"img":false}]}
{"op":"mcm","clk":"5348432558","pt":1646217649558,"mc":[{"id":"1.195453627","rc":[{"atl":[[7,4.67]],"id":39734233}],"con":true,"img":false}]}
{"op":"mcm","clk":"5348432586","pt":1646217649819,"mc":[{"id":"1.195453627","rc":[{"atl":[[5.9,0]],"id":39734233}],"con":true,"img":false}]}
{"op":"mcm","clk":"5348432607","pt":1646217650031,"mc":[{"id":"1.195453627","rc":[{"atl":[[1000,2.25]],"id":39734233}],"con":true,"img":false}]}
{"op":"mcm","clk":"5348432629","pt":1646217650240,"mc":[{"id":"1.195453627","rc":[{"atl":[[1000,2.1]],"id":39734233}],"con":true,"img":false}]}
{"op":"mcm","clk":"5348432641","pt":1646217650345,"mc":[{"id":"1.195453627","rc":[{"atl":[[1000,0]],"id":39734233}],"con":true,"img":false}]}
{"op":"mcm","clk":"5348432650","pt":1646217650452,"mc":[{"id":"1.195453627","rc":[{"atl":[[4.6,4.43]],"id":39734233}],"con":true,"img":false}]}
{"op":"mcm","clk":"5348432781","pt":1646217652126,"mc":[{"id":"1.195453627","rc":[{"atb":[[3.85,0]],"id":39734233}],"con":true,"img":false}]}
{"op":"mcm","clk":"5348432789","pt":1646217652225,"mc":[{"id":"1.195453627","rc":[{"atb":[[1.02,1.3]],"id":39734233}],"con":true,"img":false}]}
{"op":"mcm","clk":"5348433865","pt":1646217664070,"mc":[{"id":"1.195453627","rc":[{"spn":7.95,"spf":"NaN","id":41818958},{"spn":24.0,"spf":"NaN","id":27868829},{"atb":[[2.18,49.53]],"id":38761677},{"spn":8.9,"spf":"NaN","id":40324291}],"con":true,"img":false}]}
{"op":"mcm","clk":"5348433877","pt":1646217664174,"mc":[{"id":"1.195453627","rc":[{"atb":[[1.99,114.78]],"id":38761677}],"con":true,"img":false}]}
{"op":"mcm","clk":"5348433919","pt":1646217664543,"mc":[{"id":"1.195453627","rc":[{"atl":[[11,0]],"id":41818958},{"atl":[[34,0]],"id":27868829},{"atl":[[12.5,0]],"id":40324291}],"con":true,"img":false}]}
{"op":"mcm","clk":"5348433929","pt":1646217664648,"mc":[{"id":"1.195453627","rc":[{"atl":[[1000,1.31]],"id":41818958},{"atl":[[1000,1.34]],"id":27868829},{"atl":[[1000,1.32]],"id":40324291}],"con":true,"img":false}]}
{"op":"mcm","clk":"5348434503","pt":1646217669650,"mc":[{"id":"1.195453627","rc":[{"atl":[[17,8.5]],"id":39734233}],"con":true,"img":false}]}
{"op":"mcm","clk":"5348436427","pt":1646217688572,"mc":[{"id":"1.195453627","rc":[{"atl":[[5.6,5.83],[7,0]],"id":39734233}],"con":true,"img":false}]}
{"op":"mcm","clk":"5348436449","pt":1646217688778,"mc":[{"id":"1.195453627","rc":[{"atl":[[4.3,0]],"id":38761677}],"con":true,"img":false}]}
{"op":"mcm","clk":"5348436463","pt":1646217688875,"mc":[{"id":"1.195453627","rc":[{"atl":[[4.2,21.64]],"id":38761677}],"con":true,"img":false}]}
{"op":"mcm","clk":"5348437145","pt":1646217696110,"mc":[{"id":"1.195453627","rc":[{"atb":[[3.5,0]],"id":39734233},{"atl":[[13,0]],"id":38214982}],"con":true,"img":false}]}
{"op":"mcm","clk":"5348437155","pt":1646217696211,"mc":[{"id":"1.195453627","rc":[{"atb":[[3.85,22.05]],"id":39734233},{"atl":[[11.5,5.84]],"id":38214982}],"con":true,"img":false}]}
{"op":"mcm","clk":"5348437291","pt":1646217697789,"mc":[{"id":"1.195453627","rc":[{"atl":[[4.6,2.32]],"id":39734233}],"con":true,"img":false}]}
{"op":"mcm","clk":"5348437303","pt":1646217697889,"mc":[{"id":"1.195453627","rc":[{"atl":[[1000,2.25]],"id":39734233}],"con":true,"img":false}]}
{"op":"mcm","clk":"5348437328","pt":1646217698099,"mc":[{"id":"1.195453627","rc":[{"atl":[[1000,1.82]],"id":39734233}],"con":true,"img":false}]}
{"op":"mcm","clk":"5348437359","pt":1646217698416,"mc":[{"id":"1.195453627","rc":[{"atl":[[1000,0]],"id":39734233}],"con":true,"img":false}]}
{"op":"mcm","clk":"5348437366","pt":1646217698520,"mc":[{"id":"1.195453627","rc":[{"atl":[[5.3,1.82]],"id":39734233}],"con":true,"img":false}]}
{"op":"mcm","clk":"5348437393","pt":1646217698836,"mc":[{"id":"1.195453627","rc":[{"atb":[[1.02,0]],"id":39734233}],"con":true,"img":false}]}
{"op":"mcm","clk":"5348437401","pt":1646217698891,"mc":[{"id":"1.195453627","rc":[{"atb":[[3.9,1.3]],"id":39734233}],"con":true,"img":false}]}
{"op":"mcm","clk":"5348437917","pt":1646217704109,"mc":[{"id":"1.195453627","rc":[{"atl":[[4.6,0]],"id":39734233}],"con":true,"img":false}]}
{"op":"mcm","clk":"5348437943","pt":1646217704422,"mc":[{"id":"1.195453627","rc":[{"atl":[[5.3,3.84]],"id":39734233}],"con":true,"img":false}]}
{"op":"mcm","clk":"5348437950","pt":1646217704528,"mc":[{"id":"1.195453627","rc":[{"atl":[[1000,0]],"id":41818958},{"atl":[[1000,0]],"id":27868829},{"atl":[[1000,0]],"id":40324291}],"con":true,"img":false}]}
{"op":"mcm","clk":"5348437960","pt":1646217704637,"mc":[{"id":"1.195453627","rc":[{"atl":[[11,1.31]],"id":41818958},{"atl":[[34,1.34]],"id":27868829},{"atl":[[12.5,1.32]],"id":40324291}],"con":true,"img":false}]}
{"op":"mcm","clk":"5348438023","pt":1646217705217,"mc":[{"id":"1.195453627","rc":[{"atl":[[8.4,0]],"id":39734233}],"con":true,"img":false}]}
{"op":"mcm","clk":"5348438035","pt":1646217705326,"mc":[{"id":"1.195453627","rc":[{"atl":[[5.2,1.32]],"id":39734233}],"con":true,"img":false}]}
{"op":"mcm","clk":"5348438179","pt":1646217706701,"mc":[{"id":"1.195453627","rc":[{"atb":[[3.9,0]],"id":39734233}],"con":true,"img":false}]}
{"op":"mcm","clk":"5348438188","pt":1646217706803,"mc":[{"id":"1.195453627","rc":[{"atb":[[1.02,1.3]],"id":39734233}],"con":true,"img":false}]}
{"op":"mcm","clk":"5348438924","pt":1646217714743,"mc":[{"id":"1.195453627","rc":[{"atb":[[3.8,0]],"id":39734233}],"con":true,"img":false}]}
{"op":"mcm","clk":"5348438944","pt":1646217714955,"mc":[{"id":"1.195453627","rc":[{"atb":[[3.9,13.45]],"id":39734233}],"con":true,"img":false}]}
{"op":"mcm","clk":"5348439315","pt":1646217718831,"mc":[{"id":"1.195453627","rc":[{"atl":[[5.3,1.82]],"id":39734233}],"con":true,"img":false}]}
{"op":"mcm","clk":"5348439337","pt":1646217719147,"mc":[{"id":"1.195453627","rc":[{"atl":[[5,2.14]],"id":39734233}],"con":true,"img":false}]}
{"op":"mcm","clk":"5348439356","pt":1646217719358,"mc":[{"id":"1.195453627","rc":[{"atb":[[1.02,0]],"id":39734233}],"con":true,"img":false}]}
{"op":"mcm","clk":"5348439368","pt":1646217719465,"mc":[{"id":"1.195453627","rc":[{"atb":[[3.95,1.3]],"id":39734233}],"con":true,"img":false}]}
{"op":"mcm","clk":"5348440083","pt":1646217726646,"mc":[{"id":"1.195453627","rc":[{"atl":[[5.2,0]],"id":39734233},{"spn":4.47,"spf":"NaN","id":39734233}],"con":true,"img":false}]}
{"op":"mcm","clk":"5348440090","pt":1646217726757,"mc":[{"id":"1.195453627","rc":[{"atl":[[1000,1.32]],"id":39734233}],"con":true,"img":false}]}
{"op":"mcm","clk":"5348441479","pt":1646217738993,"mc":[{"id":"1.195453627","rc":[{"atb":[[3.85,0],[3.4,0]],"id":39734233}],"con":true,"img":false}]}
{"op":"mcm","clk":"5348441493","pt":1646217739106,"mc":[{"id":"1.195453627","rc":[{"atb":[[3.4,22.05],[2.96,45.01]],"id":39734233}],"con":true,"img":false}]}
{"op":"mcm","clk":"5348441531","pt":1646217739374,"mc":[{"id":"1.195453627","rc":[{"atb":[[3.95,0]],"id":39734233}],"con":true,"img":false}]}
{"op":"mcm","clk":"5348441545","pt":1646217739479,"mc":[{"id":"1.195453627","rc":[{"atb":[[1.02,1.3]],"id":39734233}],"con":true,"img":false}]}
{"op":"mcm","clk":"5348441652","pt":1646217740587,"mc":[{"id":"1.195453627","rc":[{"atb":[[1.02,0]],"id":39734233}],"con":true,"img":false}]}
{"op":"mcm","clk":"5348441660","pt":1646217740691,"mc":[{"id":"1.195453627","rc":[{"atb":[[3.95,1.3]],"id":39734233}],"con":true,"img":false}]}
{"op":"mcm","clk":"5348442066","pt":1646217744502,"mc":[{"id":"1.195453627","rc":[{"atl":[[11.5,0]],"id":38214982}],"con":true,"img":false}]}
{"op":"mcm","clk":"5348442074","pt":1646217744603,"mc":[{"id":"1.195453627","rc":[{"atl":[[13,5.84]],"id":38214982}],"con":true,"img":false}]}
{"op":"mcm","clk":"5348445250","pt":1646217776413,"mc":[{"id":"1.195453627","rc":[{"atb":[[3.9,0]],"id":39734233}],"con":true,"img":false}]}
{"op":"mcm","clk":"5348445263","pt":1646217776615,"mc":[{"id":"1.195453627","rc":[{"atb":[[3.85,12.22]],"id":39734233}],"con":true,"img":false}]}
{"op":"mcm","clk":"5348445324","pt":1646217777347,"mc":[{"id":"1.195453627","rc":[{"atb":[[3.95,0]],"id":39734233}],"con":true,"img":false}]}
{"op":"mcm","clk":"5348445332","pt":1646217777454,"mc":[{"id":"1.195453627","rc":[{"atb":[[3.9,1.3]],"id":39734233}],"con":true,"img":false}]}
{"op":"mcm","clk":"5348445622","pt":1646217780539,"mc":[{"id":"1.195453627","rc":[{"atl":[[5,0]],"id":39734233}],"con":true,"img":false}]}
{"op":"mcm","clk":"5348445656","pt":1646217780854,"mc":[{"id":"1.195453627","rc":[{"atl":[[4.6,2.32]],"id":39734233}],"con":true,"img":false}]}
{"op":"mcm","clk":"5348446106","pt":1646217784952,"mc":[{"id":"1.195453627","rc":[{"atl":[[5.3,0]],"id":39734233}],"con":true,"img":false}]}
{"op":"mcm","clk":"5348446121","pt":1646217785058,"mc":[{"id":"1.195453627","rc":[{"atl":[[1000,3.58]],"id":39734233}],"con":true,"img":false}]}
{"op":"mcm","clk":"5348446155","pt":1646217785329,"mc":[{"id":"1.195453627","rc":[{"atl":[[1000,3.43]],"id":39734233}],"con":true,"img":false}]}
{"op":"mcm","clk":"5348446180","pt":1646217785531,"mc":[{"id":"1.195453627","rc":[{"atl":[[1000,1.32]],"id":39734233}],"con":true,"img":false}]}
{"op":"mcm","clk":"5348446191","pt":1646217785633,"mc":[{"id":"1.195453627","rc":[{"atl":[[4.6,4.43]],"id":39734233}],"con":true,"img":false}]}
{"op":"mcm","clk":"5348446254","pt":1646217786360,"mc":[{"id":"1.195453627","rc":[{"atb":[[3.9,0]],"id":39734233}],"con":true,"img":false}]}
{"op":"mcm","clk":"5348446264","pt":1646217786421,"mc":[{"id":"1.195453627","rc":[{"atb":[[1.02,1.3]],"id":39734233}],"con":true,"img":false}]}
{"op":"mcm","clk":"5348449102","pt":1646217813202,"mc":[{"id":"1.195453627","rc":[{"atb":[[3.4,0]],"id":39734233},{"spn":4.22,"spf":"NaN","id":39734233},{"atl":[[13,0]],"id":38214982}],"con":true,"img":false}]}
{"op":"mcm","clk":"5348449114","pt":1646217813307,"mc":[{"id":"1.195453627","rc":[{"atb":[[3.9,22.05]],"id":39734233},{"atl":[[11.5,5.84]],"id":38214982}],"con":true,"img":false}]}
{"op":"mcm","clk":"5348449192","pt":1646217814091,"mc":[{"id":"1.195453627","rc":[{"atl":[[11,0]],"id":41818958},{"atl":[[34,0]],"id":27868829},{"atl":[[12.5,0]],"id":40324291}],"con":true,"img":false}]}
{"op":"mcm","clk":"5348449201","pt":1646217814204,"mc":[{"id":"1.195453627","rc":[{"atl":[[1000,1.31]],"id":41818958},{"atl":[[1000,1.34]],"id":27868829},{"atl":[[1000,1.32]],"id":40324291}],"con":true,"img":false}]}
{"op":"mcm","clk":"5348449286","pt":1646217814977,"mc":[{"id":"1.195453627","rc":[{"atl":[[4.6,2.32]],"id":39734233}],"con":true,"img":false}]}
{"op":"mcm","clk":"5348449298","pt":1646217815080,"mc":[{"id":"1.195453627","rc":[{"atl":[[1000,3.58]],"id":39734233}],"con":true,"img":false}]}
{"op":"mcm","clk":"5348449310","pt":1646217815185,"mc":[{"id":"1.195453627","rc":[{"atl":[[1000,3.15]],"id":39734233}],"con":true,"img":false}]}
{"op":"mcm","clk":"5348449322","pt":1646217815288,"mc":[{"id":"1.195453627","rc":[{"atl":[[1000,1.32]],"id":39734233}],"con":true,"img":false}]}
{"op":"mcm","clk":"5348449330","pt":1646217815391,"mc":[{"id":"1.195453627","rc":[{"atl":[[5.3,1.82]],"id":39734233}],"con":true,"img":false}]}
{"op":"mcm","clk":"5348449347","pt":1646217815599,"mc":[{"id":"1.195453627","rc":[{"atb":[[1.02,0]],"id":39734233}],"con":true,"img":false}]}
{"op":"mcm","clk":"5348449353","pt":1646217815705,"mc":[{"id":"1.195453627","rc":[{"atb":[[3.95,1.3]],"id":39734233}],"con":true,"img":false}]}
{"op":"mcm","clk":"5348449536","pt":1646217817484,"mc":[{"id":"1.195453627","rc":[{"atb":[[2.82,48.16],[2.64,102.18]],"id":39734233},{"atb":[[1.41,32.92]],"id":41818958},{"atl":[[48,2.13],[55,0]],"id":27868829},{"atb":[[1.55,0],[1.67,149.25]],"id":38761677},{"atb":[[1.89,0],[2.34,67.12]],"id":40324291}],"con":true,"img":false}]}
{"op":"mcm","clk":"5348450006","pt":1646217821616,"mc":[{"id":"1.195453627","rc":[{"atl":[[4.6,0]],"id":39734233}],"con":true,"img":false}]}
{"op":"mcm","clk":"5348450061","pt":1646217822090,"mc":[{"id":"1.195453627","rc":[{"atl":[[5.3,3.84]],"id":39734233}],"con":true,"img":false}]}
{"op":"mcm","clk":"5348450076","pt":1646217822293,"mc":[{"id":"1.195453627","rc":[{"atl":[[1000,0]],"id":41818958},{"atl":[[1000,0]],"id":27868829},{"atl":[[1000,0]],"id":40324291}],"con":true,"img":false}]}
{"op":"mcm","clk":"5348450089","pt":1646217822397,"mc":[{"id":"1.195453627","rc":[{"atb":[[3.95,0]],"id":39734233},{"atl":[[11,1.31]],"id":41818958},{"atl":[[34,1.34]],"id":27868829},{"atl":[[12.5,1.32]],"id":40324291}],"con":true,"img":false}]}
{"op":"mcm","clk":"5348450095","pt":1646217822503,"mc":[{"id":"1.195453627","rc":[{"atb":[[1.02,1.3]],"id":39734233}],"con":true,"img":false}]}
{"op":"mcm","clk":"5348450157","pt":1646217823133,"mc":[{"id":"1.195453627","rc":[{"atl":[[1000,0]],"id":39734233}],"con":true,"img":false}]}
{"op":"mcm","clk":"5348450172","pt":1646217823184,"mc":[{"id":"1.195453627","rc":[{"atl":[[5.2,1.32]],"id":39734233}],"con":true,"img":false}]}
{"op":"mcm","clk":"5348451771","pt":1646217837425,"mc":[{"id":"1.195453627","rc":[{"atb":[[3.85,0]],"id":39734233}],"con":true,"img":false}]}
{"op":"mcm","clk":"5348451847","pt":1646217838132,"mc":[{"id":"1.195453627","rc":[{"atb":[[3.9,0]],"id":39734233}],"con":true,"img":false}]}
{"op":"mcm","clk":"5348451859","pt":1646217838241,"mc":[{"id":"1.195453627","rc":[{"atb":[[3.65,22.05]],"id":39734233}],"con":true,"img":false}]}
{"op":"mcm","clk":"5348451960","pt":1646217839028,"mc":[{"id":"1.195453627","rc":[{"atb":[[1.02,0]],"id":39734233}],"con":true,"img":false}]}
{"op":"mcm","clk":"5348451972","pt":1646217839141,"mc":[{"id":"1.195453627","rc":[{"atb":[[3.7,1.3]],"id":39734233}],"con":true,"img":false}]}
{"op":"mcm","clk":"5348452085","pt":1646217840125,"mc":[{"id":"1.195453627","rc":[{"atl":[[5.3,1.82]],"id":39734233}],"con":true,"img":false}]}
{"op":"mcm","clk":"5348452120","pt":1646217840443,"mc":[{"id":"1.195453627","rc":[{"atl":[[5,2.14]],"id":39734233}],"con":true,"img":false}]}
{"op":"mcm","clk":"5348452152","pt":1646217840755,"mc":[{"id":"1.195453627","rc":[{"atl":[[5.2,0]],"id":39734233}],"con":true,"img":false}]}
{"op":"mcm","clk":"5348452165","pt":1646217840858,"mc":[{"id":"1.195453627","rc":[{"atl":[[1000,1.32]],"id":39734233}],"con":true,"img":false}]}
{"op":"mcm","clk":"5348452370","pt":1646217842851,"mc":[{"id":"1.195453627","rc":[{"atb":[[2.96,0]],"id":39734233}],"con":true,"img":false}]}
{"op":"mcm","clk":"5348452380","pt":1646217842965,"mc":[{"id":"1.195453627","rc":[{"atb":[[3.4,45.01]],"id":39734233}],"con":true,"img":false}]}
{"op":"mcm","clk":"5348452509","pt":1646217844226,"mc":[{"id":"1.195453627","rc":[{"atb":[[3.4,0]],"id":39734233}],"con":true,"img":false}]}
{"op":"mcm","clk":"5348452523","pt":1646217844332,"mc":[{"id":"1.195453627","rc":[{"atb":[[2.98,45.01]],"id":39734233}],"con":true,"img":false}]}
{"op":"mcm","clk":"5348452532","pt":1646217844436,"mc":[{"id":"1.195453627","rc":[{"atb":[[1.04,1.66]],"id":39734233},{"atb":[[1.04,1.66]],"id":38761677}],"con":true,"img":false}]}
{"op":"mcm","clk":"5348452555","pt":1646217844646,"mc":[{"id":"1.195453627","rc":[{"atb":[[1.04,1.65]],"id":39734233},{"atb":[[1.04,1.65]],"id":38761677}],"con":true,"img":false}]}
{"op":"mcm","clk":"5348452573","pt":1646217844858,"mc":[{"id":"1.195453627","rc":[{"atb":[[1.04,0]],"id":39734233},{"atb":[[1.04,0]],"id":38761677}],"con":true,"img":false}]}
{"op":"mcm","clk":"5348452586","pt":1646217844963,"mc":[{"id":"1.195453627","rc":[{"atb":[[3.8,1.65]],"id":39734233},{"atb":[[2.28,1.65]],"id":38761677}],"con":true,"img":false}]}
{"op":"mcm","clk":"5348453671","pt":1646217854880,"mc":[{"id":"1.195453627","rc":[{"atb":[[1.5,32.92]],"id":41818958},{"atb":[[2.46,67.16],[2.34,0]],"id":40324291}],"con":true,"img":false}]}
{"op":"mcm","clk":"5348453682","pt":1646217854989,"mc":[{"id":"1.195453627","rc":[{"atb":[[1.41,0]],"id":41818958}],"con":true,"img":false}]}
{"op":"mcm","clk":"5348453823","pt":1646217856232,"mc":[{"id":"1.195453627","rc":[{"atb":[[3.65,0]],"id":39734233},{"atl":[[11.5,0]],"id":38214982}],"con":true,"img":false}]}
{"op":"mcm","clk":"5348453835","pt":1646217856335,"mc":[{"id":"1.195453627","rc":[{"atb":[[3.4,22.05]],"id":39734233},{"atl":[[13,5.84]],"id":38214982}],"con":true,"img":false}]}
{"op":"mcm","clk":"5348453927","pt":1646217857285,"mc":[{"id":"1.195453627","rc":[{"atb":[[3.7,0]],"id":39734233}],"con":true,"img":false}]}
{"op":"mcm","clk":"5348453936","pt":1646217857390,"mc":[{"id":"1.195453627","rc":[{"atb":[[3.45,1.3]],"id":39734233}],"con":true,"img":false}]}
{"op":"mcm","clk":"5348455554","pt":1646217872179,"mc":[{"id":"1.195453627","rc":[{"atl":[[5,0]],"id":39734233}],"con":true,"img":false}]}
{"op":"mcm","clk":"5348455584","pt":1646217872490,"mc":[{"id":"1.195453627","rc":[{"atl":[[4.6,2.32]],"id":39734233}],"con":true,"img":false}]}
{"op":"mcm","clk":"5348455622","pt":1646217872809,"mc":[{"id":"1.195453627","rc":[{"atl":[[11,0]],"id":41818958},{"atl":[[34,0]],"id":27868829},{"atl":[[12.5,0]],"id":40324291}],"con":true,"img":false}]}
{"op":"mcm","clk":"5348455634","pt":1646217872916,"mc":[{"id":"1.195453627","rc":[{"atl":[[1000,1.31]],"id":41818958},{"atl":[[1000,1.34]],"id":27868829},{"atl":[[1000,1.32]],"id":40324291}],"con":true,"img":false}]}
{"op":"mcm","clk":"5348456942","pt":1646217884224,"mc":[{"id":"1.195453627","rc":[{"atl":[[5.3,0]],"id":39734233},{"spn":4.2,"spf":"NaN","id":39734233},{"spn":8.2,"spf":"NaN","id":41818958},{"spn":25.0,"spf":"NaN","id":27868829},{"spn":2.54,"spf":"NaN","id":38761677},{"spn":9.15,"spf":"NaN","id":40324291}],"con":true,"img":false}]}
{"op":"mcm","clk":"5348456961","pt":1646217884381,"mc":[{"id":"1.195453627","rc":[{"atl":[[1000,3.58]],"id":39734233}],"con":true,"img":false}]}
{"op":"mcm","clk":"5348456985","pt":1646217884593,"mc":[{"id":"1.195453627","rc":[{"atl":[[1000,3.43]],"id":39734233}],"con":true,"img":false}]}
{"op":"mcm","clk":"5348457009","pt":1646217884805,"mc":[{"id":"1.195453627","rc":[{"atl":[[1000,1.32]],"id":39734233}],"con":true,"img":false}]}
{"op":"mcm","clk":"5348457018","pt":1646217884906,"mc":[{"id":"1.195453627","rc":[{"atl":[[4.6,4.43]],"id":39734233}],"con":true,"img":false}]}
{"op":"mcm","clk":"5348457063","pt":1646217885277,"mc":[{"id":"1.195453627","rc":[{"atb":[[3.45,0]],"id":39734233}],"con":true,"img":false}]}
{"op":"mcm","clk":"5348457077","pt":1646217885378,"mc":[{"id":"1.195453627","rc":[{"atb":[[1.02,1.3]],"id":39734233}],"con":true,"img":false}]}
{"op":"mcm","clk":"5348458791","pt":1646217900613,"mc":[{"id":"1.195453627","rc":[{"atb":[[1.99,0]],"id":38761677}],"con":true,"img":false}]}
{"op":"mcm","clk":"5348458807","pt":1646217900720,"mc":[{"id":"1.195453627","rc":[{"atb":[[2.18,164.31]],"id":38761677}],"con":true,"img":false}]}
{"op":"mcm","clk":"5348459110","pt":1646217903112,"mc":[{"id":"1.195453627","rc":[{"atb":[[1.41,33.36],[1.5,0]],"id":41818958},{"atb":[[2.46,0],[2.34,67.21]],"id":40324291}],"con":true,"img":false}]}
{"op":"mcm","clk":"5348460681","pt":1646217915953,"mc":[{"id":"1.195453627","rc":[{"atb":[[3.45,15.93]],"id":39734233}],"con":true,"img":false}]}
{"op":"mcm","clk":"5348461086","pt":1646217919282,"mc":[{"id":"1.195453627","rc":[{"atb":[[2.18,49.53]],"id":38761677}],"con":true,"img":false}]}
{"op":"mcm","clk":"5348461105","pt":1646217919344,"mc":[{"id":"1.195453627","rc":[{"atb":[[1.99,114.78]],"id":38761677}],"con":true,"img":false}]}
{"op":"mcm","clk":"5348464266","pt":1646217945202,"mc":[{"id":"1.195453627","rc":[{"atb":[[2.98,0],[3.4,0]],"id":39734233},{"atl":[[13,0]],"id":38214982}],"con":true,"img":false}]}
{"op":"mcm","clk":"5348464279","pt":1646217945314,"mc":[{"id":"1.195453627","rc":[{"atb":[[3.5,45.01],[3.65,22.05]],"id":39734233},{"atl":[[11.5,5.84]],"id":38214982}],"con":true,"img":false}]}
{"op":"mcm","clk":"5348465743","pt":1646217957530,"mc":[{"id":"1.195453627","rc":[{"atb":[[1.01,2.25],[4.9,0]],"id":41818958},{"atb":[[1.03,2.25],[5.3,0]],"id":40324291}],"con":true,"img":false}]}
{"op":"mcm","clk":"5348465772","pt":1646217957735,"mc":[{"id":"1.195453627","rc":[{"atb":[[1.01,0.6]],"id":41818958},{"atb":[[1.03,0.57]],"id":40324291}],"con":true,"img":false}]}
{"op":"mcm","clk":"5348465855","pt":1646217958316,"mc":[{"id":"1.195453627","rc":[{"atb":[[1.01,0]],"id":41818958}],"con":true,"img":false}]}
{"op":"mcm","clk":"5348465868","pt":1646217958419,"mc":[{"id":"1.195453627","rc":[{"atb":[[6.2,0.6]],"id":41818958}],"con":true,"img":false}]}
{"op":"mcm","clk":"5348465882","pt":1646217958523,"mc":[{"id":"1.195453627","rc":[{"atb":[[1.03,0]],"id":40324291}],"con":true,"img":false}]}
{"op":"mcm","clk":"5348465895","pt":1646217958622,"mc":[{"id":"1.195453627","rc":[{"atb":[[6.6,0.57]],"id":40324291}],"con":true,"img":false}]}
{"op":"mcm","clk":"5348466432","pt":1646217963142,"mc":[{"id":"1.195453627","rc":[{"atl":[[42,5.16],[48,0]],"id":27868829}],"con":true,"img":false}]}
{"op":"mcm","clk":"5348467258","pt":1646217969547,"mc":[{"id":"1.195453627","rc":[{"atl":[[5.6,0],[7.2,4.53]],"id":39734233}],"con":true,"img":false}]}
{"op":"mcm","clk":"5348468490","pt":1646217979047,"mc":[{"id":"1.195453627","rc":[{"atb":[[3.5,0]],"id":39734233}],"con":true,"img":false}]}
{"op":"mcm","clk":"5348468501","pt":1646217979147,"mc":[{"id":"1.195453627","rc":[{"atb":[[2.96,45.01]],"id":39734233}],"con":true,"img":false}]}
{"op":"mcm","clk":"5348468842","pt":1646217982251,"mc":[{"id":"1.195453627","rc":[{"atb":[[3.45,0]],"id":39734233}],"con":true,"img":false}]}
{"op":"mcm","clk":"5348469343","pt":1646217987081,"mc":[{"id":"1.195453627","rc":[{"atb":[[3.65,0]],"id":39734233},{"atl":[[11.5,0]],"id":38214982}],"con":true,"img":false}]}
{"op":"mcm","clk":"5348469352","pt":1646217987184,"mc":[{"id":"1.195453627","rc":[{"atb":[[3.4,22.05]],"id":39734233},{"atl":[[13,5.84]],"id":38214982}],"con":true,"img":false}]}
{"op":"mcm","clk":"5348471547","pt":1646218005505,"mc":[{"id":"1.195453627","rc":[{"atl":[[7.2,0]],"id":39734233},{"spn":8.85,"spf":"NaN","id":41818958},{"spn":9.8,"spf":"NaN","id":40324291}],"con":true,"img":false}]}
{"op":"mcm","clk":"5348471556","pt":1646218005612,"mc":[{"id":"1.195453627","rc":[{"atl":[[7,4.53]],"id":39734233}],"con":true,"img":false}]}
{"op":"mcm","clk":"5348473371","pt":1646218020535,"mc":[{"id":"1.195453627","rc":[{"atb":[[1.02,2.97]],"id":39734233},{"atb":[[1.03,1.66]],"id":41818958},{"atb":[[1.03,1.66]],"id":38214982},{"atb":[[1.06,1.66]],"id":27868829},{"atb":[[1.01,3.26]],"id":38761677},{"atb":[[1.03,1.66]],"id":40324291}],"con":true,"img":false}]}
{"op":"mcm","clk":"5348473395","pt":1646218020704,"mc":[{"id":"1.195453627","rc":[{"atb":[[1.02,1.73]],"id":39734233},{"atb":[[1.03,0.33]],"id":41818958},{"atb":[[1.03,0.31]],"id":38214982},{"atb":[[1.06,0.11]],"id":27868829},{"atb":[[1.01,2.31]],"id":38761677},{"atb":[[1.03,0.3]],"id":40324291}],"con":true,"img":false}]}
{"op":"mcm","clk":"5348473431","pt":1646218021019,"mc":[{"id":"1.195453627","rc":[{"atb":[[1.02,1.3]],"id":39734233},{"atb":[[1.03,0]],"id":41818958},{"atb":[[1.03,0]],"id":38214982},{"atb":[[1.06,0]],"id":27868829},{"atb":[[1.01,1.6]],"id":38761677},{"atb":[[1.03,0]],"id":40324291}],"con":true,"img":false}]}
{"op":"mcm","clk":"5348473455","pt":1646218021235,"mc":[{"id":"1.195453627","rc":[{"atb":[[3.85,0.42]],"id":39734233},{"atb":[[4.9,0.33]],"id":41818958},{"atb":[[5.2,0.31]],"id":38214982},{"atb":[[14,0.38]],"id":27868829},{"atb":[[2.3,0.71]],"id":38761677},{"atb":[[5.3,0.3]],"id":40324291}],"con":true,"img":false}]}
{"op":"mcm","clk":"5348473677","pt":1646218023156,"mc":[{"id":"1.195453627","rc":[{"atb":[[2.82,0],[2.66,60.24]],"id":39734233},{"atb":[[1.41,0]],"id":41818958},{"atl":[[42,2.72],[46,5.13]],"id":27868829},{"atb":[[1.67,0],[1.54,121.39]],"id":38761677},{"atb":[[1.85,63.99],[2.34,0]],"id":40324291}],"con":true,"img":false}]}
{"op":"mcm","clk":"5348474489","pt":1646218029632,"mc":[{"id":"1.195453627","rc":[{"atb":[[1.99,0]],"id":38761677}],"con":true,"img":false}]}
{"op":"mcm","clk":"5348474501","pt":1646218029736,"mc":[{"id":"1.195453627","rc":[{"atb":[[2.18,164.31]],"id":38761677}],"con":true,"img":false}]}
{"op":"mcm","clk":"5348475395","pt":1646218036644,"mc":[{"id":"1.195453627","rc":[{"atl":[[5.6,5.83],[7,0]],"id":39734233}],"con":true,"img":false}]}
{"op":"mcm","clk":"5348480224","pt":1646218075079,"mc":[{"id":"1.195453627","rc":[{"atb":[[2.96,0]],"id":39734233},{"spn":4.22,"spf":"NaN","id":39734233},{"spn":3.92,"spf":1.0,"id":38214982},{"spn":2.55,"spf":"NaN","id":38761677}],"con":true,"img":false}]}
{"op":"mcm","clk":"5348480239","pt":1646218075181,"mc":[{"id":"1.195453627","rc":[{"atb":[[3.4,67.07]],"id":39734233}],"con":true,"img":false}]}
{"op":"mcm","clk":"5348483694","pt":1646218103216,"mc":[{"id":"1.195453627","rc":[{"atl":[[6.4,42]],"id":38214982}],"con":true,"img":false}]}
{"op":"mcm","clk":"5348483710","pt":1646218103326,"mc":[{"id":"1.195453627","rc":[{"atl":[[6.2,20]],"id":38214982}],"con":true,"img":false}]}
{"op":"mcm","clk":"5348495121","pt":1646218197386,"mc":[{"id":"1.195453627","rc":[{"atb":[[2.88,48.16],[2.66,0]],"id":39734233},{"atb":[[1.32,32.48]],"id":41818958},{"atl":[[38,2.7],[46,2.91]],"id":27868829},{"atb":[[1.64,126.32],[1.54,0]],"id":38761677},{"atb":[[1.85,0],[2.84,54.35]],"id":40324291}],"con":true,"img":false}]}
{"op":"mcm","clk":"5348496474","pt":1646218208375,"mc":[{"id":"1.195453627","rc":[{"atb":[[1.44,65.4],[1.26,0]],"id":38214982},{"atb":[[4.8,22.05],[3.2,23.92]],"id":27868829},{"atl":[[32,0],[23,4.55]],"id":40324291}],"con":true,"img":false}]}
{"op":"mcm","clk":"5348500245","pt":1646218233425,"mc":[{"id":"1.195453627","rc":[{"atl":[[3.85,0]],"id":38761677}],"con":true,"img":false}]}
{"op":"mcm","clk":"5348500260","pt":1646218233533,"mc":[{"id":"1.195453627","rc":[{"atl":[[3.9,8.17]],"id":38761677}],"con":true,"img":false}]}
{"op":"mcm","clk":"5348511708","pt":1646218328077,"mc":[{"id":"1.195453627","rc":[{"atb":[[2.72,58.14],[2.88,0]],"id":39734233},{"atb":[[1.32,0]],"id":41818958},{"atl":[[38,0],[40,2.56]],"id":27868829},{"atb":[[1.64,0],[1.5,132.85]],"id":38761677},{"atb":[[2.84,0],[2.38,67.21]],"id":40324291}],"con":true,"img":false}]}
{"op":"mcm","clk":"5348522338","pt":1646218431036,"mc":[{"id":"1.195453627","rc":[{"atl":[[12,19.07]],"id":40324291},{"spn":9.3,"spf":"NaN","id":40324291}],"con":true,"img":false}]}
{"op":"mcm","clk":"5348522955","pt":1646218437504,"mc":[{"id":"1.195453627","rc":[{"atl":[[5.6,0],[7.2,4.53]],"id":39734233}],"con":true,"img":false}]}
{"op":"mcm","clk":"5348525587","pt":1646218464077,"mc":[{"id":"1.195453627","rc":[{"atl":[[7.2,0]],"id":39734233}],"con":true,"img":false}]}
{"op":"mcm","clk":"5348525600","pt":1646218464182,"mc":[{"id":"1.195453627","rc":[{"atl":[[7,4.53]],"id":39734233}],"con":true,"img":false}]}
{"op":"mcm","clk":"5348527019","pt":1646218478382,"mc":[{"id":"1.195453627","rc":[{"atb":[[2.72,0]],"id":39734233},{"atl":[[38,2.7],[40,0]],"id":27868829},{"atb":[[1.64,132.85]],"id":38761677},{"atb":[[2.84,54.35]],"id":40324291}],"con":true,"img":false}]}
{"op":"mcm","clk":"5348527024","pt":1646218478488,"mc":[{"id":"1.195453627","rc":[{"atb":[[2.88,48.16]],"id":39734233},{"atb":[[1.33,32.48]],"id":41818958},{"atb":[[1.5,0]],"id":38761677},{"atb":[[2.38,0]],"id":40324291}],"con":true,"img":false}]}
{"op":"mcm","clk":"5348529154","pt":1646218494548,"mc":[{"id":"1.195453627","rc":[{"atl":[[7,0]],"id":39734233}],"con":true,"img":false}]}
{"op":"mcm","clk":"5348529160","pt":1646218494606,"mc":[{"id":"1.195453627","rc":[{"atl":[[6.8,4.53]],"id":39734233}],"con":true,"img":false}]}
{"op":"mcm","clk":"5348529401","pt":1646218497621,"mc":[{"id":"1.195453627","rc":[{"atl":[[6.8,0]],"id":39734233}],"con":true,"img":false}]}
{"op":"mcm","clk":"5348529407","pt":1646218497722,"mc":[{"id":"1.195453627","rc":[{"atl":[[7.2,4.53]],"id":39734233}],"con":true,"img":false}]}
{"op":"mcm","clk":"5348532387","pt":1646218526058,"mc":[{"id":"1.195453627","rc":[{"atl":[[7.2,0]],"id":39734233}],"con":true,"img":false}]}
{"op":"mcm","clk":"5348532401","pt":1646218526174,"mc":[{"id":"1.195453627","rc":[{"atl":[[7,4.53]],"id":39734233}],"con":true,"img":false}]}
{"op":"mcm","clk":"5348535586","pt":1646218555998,"mc":[{"id":"1.195453627","rc":[{"atl":[[7,0]],"id":39734233}],"con":true,"img":false}]}
{"op":"mcm","clk":"5348535597","pt":1646218556099,"mc":[{"id":"1.195453627","rc":[{"atl":[[6.8,4.53]],"id":39734233}],"con":true,"img":false}]}
{"op":"mcm","clk":"5348536205","pt":1646218561730,"mc":[{"id":"1.195453627","rc":[{"atl":[[6.8,0]],"id":39734233}],"con":true,"img":false}]}
{"op":"mcm","clk":"5348536213","pt":1646218561831,"mc":[{"id":"1.195453627","rc":[{"atl":[[7.2,4.53]],"id":39734233}],"con":true,"img":false}]}
{"op":"mcm","clk":"5348538717","pt":1646218590048,"mc":[{"id":"1.195453627","rc":[{"atl":[[7.2,0]],"id":39734233}],"con":true,"img":false}]}
{"op":"mcm","clk":"5348538725","pt":1646218590149,"mc":[{"id":"1.195453627","rc":[{"atl":[[7,4.53]],"id":39734233}],"con":true,"img":false}]}
{"op":"mcm","clk":"5348539444","pt":1646218598475,"mc":[{"id":"1.195453627","rc":[{"atb":[[2.72,58.14],[2.88,0]],"id":39734233},{"atb":[[1.33,0]],"id":41818958},{"atl":[[38,0],[40,2.56]],"id":27868829},{"atb":[[1.64,0],[1.5,132.85]],"id":38761677},{"atb":[[2.84,0],[2.38,67.21]],"id":40324291}],"con":true,"img":false}]}
{"op":"mcm","clk":"5348541453","pt":1646218621225,"mc":[{"id":"1.195453627","rc":[{"atl":[[7,0]],"id":39734233}],"con":true,"img":false}]}
{"op":"mcm","clk":"5348541466","pt":1646218621324,"mc":[{"id":"1.195453627","rc":[{"atl":[[6.8,4.53]],"id":39734233}],"con":true,"img":false}]}
{"op":"mcm","clk":"5348541910","pt":1646218625623,"mc":[{"id":"1.195453627","rc":[{"atl":[[6.8,0]],"id":39734233}],"con":true,"img":false}]}
{"op":"mcm","clk":"5348541924","pt":1646218625740,"mc":[{"id":"1.195453627","rc":[{"atl":[[7.2,4.53]],"id":39734233}],"con":true,"img":false}]}
{"op":"mcm","clk":"5348544311","pt":1646218652765,"mc":[{"id":"1.195453627","rc":[{"atl":[[7.2,0]],"id":39734233}],"con":true,"img":false}]}
{"op":"mcm","clk":"5348544322","pt":1646218652898,"mc":[{"id":"1.195453627","rc":[{"atl":[[7,4.53]],"id":39734233}],"con":true,"img":false}]}
{"op":"mcm","clk":"5348547149","pt":1646218688267,"mc":[{"id":"1.195453627","rc":[{"atl":[[7,0]],"id":39734233}],"con":true,"img":false}]}
{"op":"mcm","clk":"5348547158","pt":1646218688372,"mc":[{"id":"1.195453627","rc":[{"atl":[[6.8,4.53]],"id":39734233}],"con":true,"img":false}]}
{"op":"mcm","clk":"5348547429","pt":1646218691384,"mc":[{"id":"1.195453627","rc":[{"atl":[[6.8,0]],"id":39734233}],"con":true,"img":false}]}
{"op":"mcm","clk":"5348547443","pt":1646218691484,"mc":[{"id":"1.195453627","rc":[{"atl":[[7.2,4.53]],"id":39734233}],"con":true,"img":false}]}
{"op":"mcm","clk":"5348548904","pt":1646218708800,"mc":[{"id":"1.195453627","rc":[{"atb":[[1.03,2.25],[6.2,0]],"id":41818958}],"con":true,"img":false}]}
{"op":"mcm","clk":"5348548915","pt":1646218708999,"mc":[{"id":"1.195453627","rc":[{"atb":[[1.03,0.57]],"id":41818958}],"con":true,"img":false}]}
{"op":"mcm","clk":"5348548972","pt":1646218709601,"mc":[{"id":"1.195453627","rc":[{"atb":[[1.03,0]],"id":41818958}],"con":true,"img":false}]}
{"op":"mcm","clk":"5348548981","pt":1646218709710,"mc":[{"id":"1.195453627","rc":[{"atb":[[6.6,0.57]],"id":41818958}],"con":true,"img":false}]}
{"op":"mcm","clk":"5348551043","pt":1646218733545,"mc":[{"id":"1.195453627","rc":[{"atl":[[7.2,0]],"id":39734233}],"con":true,"img":false}]}
{"op":"mcm","clk":"5348551053","pt":1646218733647,"mc":[{"id":"1.195453627","rc":[{"atl":[[7,4.53]],"id":39734233}],"con":true,"img":false}]}
{"op":"mcm","clk":"5348553516","pt":1646218763781,"mc":[{"id":"1.195453627","rc":[{"atl":[[7,0]],"id":39734233},{"spn":9.05,"spf":"NaN","id":41818958}],"con":true,"img":false}]}
{"op":"mcm","clk":"5348553525","pt":1646218763882,"mc":[{"id":"1.195453627","rc":[{"atl":[[6.8,4.53]],"id":39734233}],"con":true,"img":false}]}
{"op":"mcm","clk":"5348553922","pt":1646218769102,"mc":[{"id":"1.195453627","rc":[{"atl":[[6.8,0]],"id":39734233}],"con":true,"img":false}]}
{"op":"mcm","clk":"5348553930","pt":1646218769209,"mc":[{"id":"1.195453627","rc":[{"atl":[[7.2,4.53]],"id":39734233}],"con":true,"img":false}]}
{"op":"mcm","clk":"5348556446","pt":1646218800564,"mc":[{"id":"1.195453627","rc":[{"atl":[[7.2,0]],"id":39734233}],"con":true,"img":false}]}
{"op":"mcm","clk":"5348556458","pt":1646218800621,"mc":[{"id":"1.195453627","rc":[{"atl":[[7,4.53]],"id":39734233}],"con":true,"img":false}]}
{"op":"mcm","clk":"5348556566","pt":1646218801548,"mc":[{"id":"1.195453627","rc":[{"atb":[[4,0]],"id":41818958},{"atb":[[5.1,44.83]],"id":40324291}],"con":true,"img":false}]}
{"op":"mcm","clk":"5348556576","pt":1646218801650,"mc":[{"id":"1.195453627","rc":[{"atb":[[4.8,3.5]],"id":41818958},{"atb":[[5.3,1.87]],"id":40324291}],"con":true,"img":false}]}
{"op":"mcm","clk":"5348558027","pt":1646218816941,"mc":[{"id":"1.195453627","rc":[{"atb":[[3.85,0.42],[1.01,1.59],[3.35,17.82],[3.8,1.65],[2.64,102.19],[2.84,45.54],[2.94,21.59],[3.45,15.89],[2.74,48.15],[1.02,1.3],[3.4,67.07]],"id":39734233},{"atl":[[8.6,27.96],[4.6,4.42],[12,17.88],[9.8,14.9],[8.8,16.81],[7,4.54],[14.5,14.57],[1000,1.32]],"id":39734233},{"trd":[[4.4,20.02],[4.5,9.05]],"ltp":4.4,"tv":29.07,"id":39734233},{"atb":[[4.8,3.5],[4.9,0.33],[2.98,41.29],[3.45,16.68],[3.2,37.15],[2.88,86.96],[4.6,16.23],[3.95,13.85],[4.1,37.53],[6.6,0.57],[4.2,2.59],[4.7,3.41]],"id":41818958},{"atl":[[16,8.87],[18.5,11.41],[22,9.51],[11.5,6.64],[13,9.69],[13.5,10.65],[1000,1.31]],"id":41818958},{"atb":[[5.1,14.61],[4.5,10.51],[4.6,36.65],[3,73.57],[5.2,0.31],[3.25,32.7],[3.5,29.43],[3.75,13.38]],"id":38214982},{"atl":[[16,9.42],[18.5,8.07],[22,10.09],[13,5.84],[27,8.15],[14,16.97]],"id":38214982},{"trd":[[5.6,3.76],[5,80.07],[5.8,13.52],[5.7,2.55]],"ltp":5.6,"tv":99.89,"id":38214982},{"atb":[[4.8,22.05],[4.3,72.6],[1.01,1.54],[10,12.9],[5.8,8.73],[5.3,19.48],[12.5,5.08],[14,0.38],[7.6,6.34]],"id":27868829},{"atl":[[65,3.07],[36,3.74],[42,2.72],[44,2.72],[90,2.21],[46,2.91],[1000,1.34]],"id":27868829},{"atb":[[1.83,201.91],[1.01,1.59],[2.3,0.71],[1.98,42.75],[2.22,12.98],[1.93,90.1],[1.88,95.22],[2.28,1.65],[2.18,164.32],[2.16,36.11]],"id":38761677},{"atl":[[2.8,4.92],[5.3,26.42],[6.8,33.92],[7.8,28.92],[5.9,26.76],[5.4,29.8],[1000,1.23],[3.9,8.17],[4.2,21.64]],"id":38761677},{"atb":[[4,13.96],[5.1,44.83],[5,10.47],[5.3,1.87],[5.2,5.05],[3.25,74.48],[6.6,0.57],[3.5,33.51],[3.75,30.47]],"id":40324291},{"atl":[[16.5,7.55],[17,8.19],[19.5,7.09],[12,19.07],[24,8.55],[13,5.56],[29,7.02],[1000,1.32]],"id":40324291}],"con":true,"img":false}]}
{"op":"mcm","clk":"5348559133","pt":1646218828887,"mc":[{"id":"1.195453627","rc":[{"atb":[[6.2,116.25]],"id":38214982},{"atl":[[6.2,0]],"id":38214982},{"trd":[[6.2,40]],"ltp":6.2,"tv":40.0,"id":38214982},{"spn":5.88,"spf":1.0,"id":38214982}],"con":true,"img":false}]}
{"op":"mcm","clk":"5348559151","pt":1646218829094,"mc":[{"id":"1.195453627","rc":[{"atb":[[2.72,0],[2.86,48.16]],"id":39734233},{"atb":[[1.26,32.92]],"id":41818958},{"atb":[[1.64,132.85]],"id":38761677},{"atb":[[3,50]],"id":40324291}],"con":true,"img":false}]}
{"op":"mcm","clk":"5348559160","pt":1646218829150,"mc":[{"id":"1.195453627","rc":[{"atl":[[38,2.7],[40,0]],"id":27868829},{"atb":[[1.5,0]],"id":38761677},{"atb":[[2.38,0]],"id":40324291}],"con":true,"img":false}]}
{"op":"mcm","clk":"5348559274","pt":1646218830562,"mc":[{"id":"1.195453627","rc":[{"atl":[[7,0]],"id":39734233}],"con":true,"img":false}]}
{"op":"mcm","clk":"5348559283","pt":1646218830673,"mc":[{"id":"1.195453627","rc":[{"atl":[[6.8,4.54]],"id":39734233}],"con":true,"img":false}]}
{"op":"mcm","clk":"5348559399","pt":1646218831967,"mc":[{"id":"1.195453627","rc":[{"atb":[[5.2,0.27]],"id":38214982}],"con":true,"img":false}]}
{"op":"mcm","clk":"5348559429","pt":1646218832384,"mc":[{"id":"1.195453627","rc":[{"atb":[[3.85,0]],"id":39734233},{"atb":[[5.2,0]],"id":38214982}],"con":true,"img":false}]}
{"op":"mcm","clk":"5348559436","pt":1646218832487,"mc":[{"id":"1.195453627","rc":[{"atb":[[3.85,0.42]],"id":39734233},{"atb":[[6.2,116.52]],"id":38214982}],"con":true,"img":false}]}
{"op":"mcm","clk":"5348559486","pt":1646218833064,"mc":[{"id":"1.195453627","rc":[{"atb":[[5.1,16.25],[4.2,37.79]],"id":40324291}],"con":true,"img":false}]}
{"op":"mcm","clk":"5348560676","pt":1646218847095,"mc":[{"id":"1.195453627","rc":[{"atb":[[3.4,45.01]],"id":39734233}],"con":true,"img":false}]}
{"op":"mcm","clk":"5348560686","pt":1646218847199,"mc":[{"id":"1.195453627","rc":[{"atb":[[3.5,22.05]],"id":39734233}],"con":true,"img":false}]}
{"op":"mcm","clk":"5348560856","pt":1646218849181,"mc":[{"id":"1.195453627","rc":[{"atl":[[36,6.47]],"id":27868829}],"con":true,"img":false}]}
{"op":"mcm","clk":"5348560866","pt":1646218849279,"mc":[{"id":"1.195453627","rc":[{"atl":[[38,0]],"id":27868829}],"con":true,"img":false}]}
{"op":"mcm","clk":"5348560875","pt":1646218849415,"mc":[{"id":"1.195453627","rc":[{"atb":[[1.02,4.77]],"id":39734233},{"atb":[[1.02,3.92]],"id":38761677}],"con":true,"img":false}]}
{"op":"mcm","clk":"5348560884","pt":1646218849471,"mc":[{"id":"1.195453627","rc":[{"atb":[[1.02,3.29]],"id":41818958},{"atb":[[1.02,3.23]],"id":40324291}],"con":true,"img":false}]}
{"op":"mcm","clk":"5348560919","pt":1646218849881,"mc":[{"id":"1.195453627","rc":[{"atb":[[1.02,2.05]],"id":39734233},{"atb":[[1.02,1.19]],"id":38761677}],"con":true,"img":false}]}
{"op":"mcm","clk":"5348560924","pt":1646218849984,"mc":[{"id":"1.195453627","rc":[{"atb":[[1.02,0.56]],"id":41818958},{"atb":[[1.02,0.5]],"id":40324291}],"con":true,"img":false}]}
{"op":"mcm","clk":"5348560943","pt":1646218850296,"mc":[{"id":"1.195453627","rc":[{"atb":[[1.03,3.13]],"id":38214982}],"con":true,"img":false}]}
{"op":"mcm","clk":"5348560946","pt":1646218850398,"mc":[{"id":"1.195453627","rc":[{"atb":[[1.02,1.3]],"id":39734233},{"atb":[[1.02,0]],"id":38761677}],"con":true,"img":false}]}
{"op":"mcm","clk":"5348560958","pt":1646218850509,"mc":[{"id":"1.195453627","rc":[{"atb":[[3.85,1.17]],"id":39734233},{"atb":[[1.02,0]],"id":41818958},{"atb":[[2.4,1.19]],"id":38761677},{"atb":[[1.02,0]],"id":40324291}],"con":true,"img":false}]}
{"op":"mcm","clk":"5348560963","pt":1646218850608,"mc":[{"id":"1.195453627","rc":[{"atb":[[5.1,0.56]],"id":41818958},{"atb":[[5.7,0.5]],"id":40324291}],"con":true,"img":false}]}
{"op":"mcm","clk":"5348560973","pt":1646218850712,"mc":[{"id":"1.195453627","rc":[{"atb":[[1.03,0.41]],"id":38214982}],"con":true,"img":false}]}
{"op":"mcm","clk":"5348560979","pt":1646218850814,"mc":[{"id":"1.195453627","rc":[{"atb":[[1.03,2.25],[6.6,0]],"id":40324291}],"con":true,"img":false}]}
{"op":"mcm","clk":"5348560986","pt":1646218850875,"mc":[{"id":"1.195453627","rc":[{"atb":[[1.03,0.57]],"id":40324291}],"con":true,"img":false}]}
{"op":"mcm","clk":"5348561001","pt":1646218851078,"mc":[{"id":"1.195453627","rc":[{"atb":[[1.03,0]],"id":38214982},{"atb":[[1.03,0]],"id":40324291}],"con":true,"img":false}]}
{"op":"mcm","clk":"5348561011","pt":1646218851181,"mc":[{"id":"1.195453627","rc":[{"atl":[[6.4,41.59]],"id":38214982},{"trd":[[6.4,0.82]],"ltp":6.4,"tv":0.82,"id":38214982},{"atb":[[5.4,0.57]],"id":40324291}],"con":true,"img":false}]}
{"op":"mcm","clk":"5348561020","pt":1646218851286,"mc":[{"id":"1.195453627","rc":[{"atb":[[1.02,2.97]],"id":27868829}],"con":true,"img":false}]}
{"op":"mcm","clk":"5348561050","pt":1646218851699,"mc":[{"id":"1.195453627","rc":[{"atb":[[1.02,0.25]],"id":27868829}],"con":true,"img":false}]}
{"op":"mcm","clk":"5348561075","pt":1646218852118,"mc":[{"id":"1.195453627","rc":[{"atb":[[1.02,0]],"id":27868829}],"con":true,"img":false}]}
{"op":"mcm","clk":"5348561086","pt":1646218852219,"mc":[{"id":"1.195453627","rc":[{"atb":[[11.5,0.25]],"id":27868829}],"con":true,"img":false}]}
{"op":"mcm","clk":"5348561266","pt":1646218854042,"mc":[{"id":"1.195453627","rc":[{"atb":[[2.28,0],[1.04,1.66]],"id":38761677}],"con":true,"img":false}]}
{"op":"mcm","clk":"5348561288","pt":1646218854188,"mc":[{"id":"1.195453627","rc":[{"atb":[[1.04,1.65]],"id":38761677}],"con":true,"img":false}]}
{"op":"mcm","clk":"5348561308","pt":1646218854397,"mc":[{"id":"1.195453627","rc":[{"atb":[[1.04,0]],"id":38761677}],"con":true,"img":false}]}
{"op":"mcm","clk":"5348561322","pt":1646218854509,"mc":[{"id":"1.195453627","rc":[{"atb":[[2.36,1.65]],"id":38761677}],"con":true,"img":false}]}
{"op":"mcm","clk":"5348561631","pt":1646218858609,"mc":[{"id":"1.195453627","rc":[{"atb":[[5.1,0]],"id":38214982}],"con":true,"img":false}]}
{"op":"mcm","clk":"5348561638","pt":1646218858711,"mc":[{"id":"1.195453627","rc":[{"atb":[[5.2,14.61]],"id":38214982}],"con":true,"img":false}]}
{"op":"mcm","clk":"5348561652","pt":1646218858921,"mc":[{"id":"1.195453627","rc":[{"atb":[[3.25,118.92]],"id":40324291}],"con":true,"img":false}]}
{"op":"mcm","clk":"5348561665","pt":1646218859026,"mc":[{"id":"1.195453627","rc":[{"atb":[[1.03,2.25],[6.6,0]],"id":41818958},{"atb":[[3,0]],"id":40324291}],"con":true,"img":false}]}
{"op":"mcm","clk":"5348561676","pt":1646218859189,"mc":[{"id":"1.195453627","rc":[{"atb":[[1.03,0.57]],"id":41818958}],"con":true,"img":false}]}
{"op":"mcm","clk":"5348561718","pt":1646218859811,"mc":[{"id":"1.195453627","rc":[{"atb":[[1.03,0]],"id":41818958}],"con":true,"img":false}]}
{"op":"mcm","clk":"5348561725","pt":1646218859915,"mc":[{"id":"1.195453627","rc":[{"atb":[[6.4,0.57]],"id":41818958}],"con":true,"img":false}]}
{"op":"mcm","clk":"5348564770","pt":1646218892668,"mc":[{"id":"1.195453627","rc":[{"atb":[[4.2,163.5]],"id":39734233},{"spn":4.4,"spf":"NaN","id":39734233},{"spn":8.95,"spf":"NaN","id":41818958},{"spn":5.9,"spf":1.0,"id":38214982},{"spn":2.6,"spf":"NaN","id":38761677},{"spn":8.85,"spf":"NaN","id":40324291}],"con":true,"img":false}]}
{"op":"mcm","clk":"5348564786","pt":1646218892903,"mc":[{"id":"1.195453627","rc":[{"atb":[[1.34,32.92]],"id":41818958}],"con":true,"img":false}]}
{"op":"mcm","clk":"5348564790","pt":1646218892929,"mc":[{"id":"1.195453627","rc":[{"atb":[[1.26,0]],"id":41818958}],"con":true,"img":false}]}
{"op":"mcm","clk":"5348564887","pt":1646218894074,"mc":[{"id":"1.195453627","rc":[{"atl":[[4.6,2.32]],"id":39734233}],"con":true,"img":false}]}
{"op":"mcm","clk":"5348564924","pt":1646218894441,"mc":[{"id":"1.195453627","rc":[{"atl":[[1000,3.57]],"id":39734233}],"con":true,"img":false}]}
{"op":"mcm","clk":"5348564948","pt":1646218894652,"mc":[{"id":"1.195453627","rc":[{"atl":[[1000,2.88]],"id":39734233}],"con":true,"img":false}]}
{"op":"mcm","clk":"5348564959","pt":1646218894752,"mc":[{"id":"1.195453627","rc":[{"atl":[[6.8,0]],"id":39734233}],"con":true,"img":false}]}
{"op":"mcm","clk":"5348564973","pt":1646218894859,"mc":[{"id":"1.195453627","rc":[{"atl":[[7.2,4.54],[1000,1.32]],"id":39734233}],"con":true,"img":false}]}
{"op":"mcm","clk":"5348564983","pt":1646218894963,"mc":[{"id":"1.195453627","rc":[{"atl":[[6.2,1.56]],"id":39734233}],"con":true,"img":false}]}
{"op":"mcm","clk":"5348565084","pt":1646218895855,"mc":[{"id":"1.195453627","rc":[{"atb":[[1.02,0]],"id":39734233}],"con":true,"img":false}]}
{"op":"mcm","clk":"5348565096","pt":1646218895949,"mc":[{"id":"1.195453627","rc":[{"atb":[[4.3,1.3]],"id":39734233}],"con":true,"img":false}]}
{"op":"mcm","clk":"5348565161","pt":1646218896935,"mc":[{"id":"1.195453627","rc":[{"atl":[[6.2,0]],"id":39734233}],"con":true,"img":false}]}
{"op":"mcm","clk":"5348565171","pt":1646218897035,"mc":[{"id":"1.195453627","rc":[{"atl":[[1000,3.57]],"id":39734233}],"con":true,"img":false}]}
{"op":"mcm","clk":"5348565195","pt":1646218897451,"mc":[{"id":"1.195453627","rc":[{"atl":[[1000,3.42]],"id":39734233}],"con":true,"img":false}]}
{"op":"mcm","clk":"5348565205","pt":1646218897653,"mc":[{"id":"1.195453627","rc":[{"atl":[[1000,1.32]],"id":39734233}],"con":true,"img":false}]}
{"op":"mcm","clk":"5348565211","pt":1646218897763,"mc":[{"id":"1.195453627","rc":[{"atl":[[4.6,4.42]],"id":39734233}],"con":true,"img":false}]}
{"op":"mcm","clk":"5348565297","pt":1646218898795,"mc":[{"id":"1.195453627","rc":[{"atb":[[4.3,0]],"id":39734233}],"con":true,"img":false}]}
{"op":"mcm","clk":"5348565305","pt":1646218898848,"mc":[{"id":"1.195453627","rc":[{"atb":[[1.02,1.3]],"id":39734233}],"con":true,"img":false}]}
{"op":"mcm","clk":"5348565363","pt":1646218899242,"mc":[{"id":"1.195453627","rc":[{"atb":[[3.45,0]],"id":39734233}],"con":true,"img":false}]}
{"op":"mcm","clk":"5348565387","pt":1646218899465,"mc":[{"id":"1.195453627","rc":[{"atb":[[3.55,15.27]],"id":39734233},{"atl":[[36,3.74],[38,2.7]],"id":27868829},{"atb":[[3.6,35.12],[3.25,74.48]],"id":40324291}],"con":true,"img":false}]}
{"op":"mcm","clk":"5348565415","pt":1646218899674,"mc":[{"id":"1.195453627","rc":[{"atb":[[3.4,0]],"id":39734233}],"con":true,"img":false}]}
{"op":"mcm","clk":"5348565430","pt":1646218899781,"mc":[{"id":"1.195453627","rc":[{"atb":[[2.96,45.01]],"id":39734233}],"con":true,"img":false}]}
{"op":"mcm","clk":"5348565456","pt":1646218899953,"mc":[{"id":"1.195453627","rc":[{"atl":[[4.6,2.32]],"id":39734233}],"con":true,"img":false}]}
{"op":"mcm","clk":"5348565471","pt":1646218900111,"mc":[{"id":"1.195453627","rc":[{"atl":[[1000,3.57]],"id":39734233}],"con":true,"img":false}]}
{"op":"mcm","clk":"5348565499","pt":1646218900270,"mc":[{"id":"1.195453627","rc":[{"atl":[[1000,2.78]],"id":39734233}],"con":true,"img":false}]}
{"op":"mcm","clk":"5348565542","pt":1646218900694,"mc":[{"id":"1.195453627","rc":[{"atb":[[1.02,0]],"id":39734233}],"con":true,"img":false}]}
{"op":"mcm","clk":"5348565556","pt":1646218900759,"mc":[{"id":"1.195453627","rc":[{"atb":[[4.3,1.3]],"id":39734233},{"atl":[[1000,1.32]],"id":39734233}],"con":true,"img":false}]}
{"op":"mcm","clk":"5348565569","pt":1646218900884,"mc":[{"id":"1.195453627","rc":[{"atl":[[6.6,1.46]],"id":39734233}],"con":true,"img":false}]}
{"op":"mcm","clk":"5348565673","pt":1646218901586,"mc":[{"id":"1.195453627","rc":[{"atl":[[4.6,0]],"id":39734233}],"con":true,"img":false}]}
{"op":"mcm","clk":"5348565747","pt":1646218902183,"mc":[{"id":"1.195453627","rc":[{"atl":[[1000,2.99]],"id":39734233}],"con":true,"img":false}]}
{"op":"mcm","clk":"5348565792","pt":1646218902461,"mc":[{"id":"1.195453627","rc":[{"atl":[[1000,2.65]],"id":39734233}],"con":true,"img":false}]}
{"op":"mcm","clk":"5348565826","pt":1646218902684,"mc":[{"id":"1.195453627","rc":[{"atl":[[1000,1.33]],"id":39734233},{"atl":[[1000,0]],"id":41818958},{"atl":[[1000,0]],"id":27868829},{"atl":[[1000,0]],"id":40324291}],"con":true,"img":false}]}
{"op":"mcm","clk":"5348565848","pt":1646218902787,"mc":[{"id":"1.195453627","rc":[{"atl":[[1000,0],[7,1.32]],"id":39734233},{"atl":[[11,1.31]],"id":41818958},{"atl":[[34,1.34]],"id":27868829},{"atl":[[11.5,1.32]],"id":40324291}],"con":true,"img":false}]}
{"op":"mcm","clk":"5348565866","pt":1646218902896,"mc":[{"id":"1.195453627","rc":[{"atl":[[8,1.33]],"id":39734233}],"con":true,"img":false}]}
{"op":"mcm","clk":"5348566252","pt":1646218905484,"mc":[{"id":"1.195453627","rc":[{"atl":[[8.2,13.89],[8.6,14.8]],"id":39734233},{"atl":[[19.5,5.41]],"id":41818958},{"atb":[[1.44,0],[1.53,73.3]],"id":38214982},{"atl":[[18.5,5.71],[23,0]],"id":40324291}],"con":true,"img":false}]}
{"op":"mcm","clk":"5348566261","pt":1646218905575,"mc":[{"id":"1.195453627","rc":[{"atl":[[25,8.2]],"id":41818958}],"con":true,"img":false}]}
{"op":"mcm","clk":"5348566382","pt":1646218906501,"mc":[{"id":"1.195453627","rc":[{"atb":[[2.98,45.02],[2.86,0]],"id":39734233}],"con":true,"img":false}]}
{"op":"mcm","clk":"5348567156","pt":1646218912254,"mc":[{"id":"1.195453627","rc":[{"atb":[[1.73,32.92]],"id":41818958}],"con":true,"img":false}]}
{"op":"mcm","clk":"5348567175","pt":1646218912360,"mc":[{"id":"1.195453627","rc":[{"atb":[[1.34,0]],"id":41818958}],"con":true,"img":false}]}
{"op":"mcm","clk":"5348567757","pt":1646218916592,"mc":[{"id":"1.195453627","rc":[{"atl":[[8,0]],"id":39734233}],"con":true,"img":false}]}
{"op":"mcm","clk":"5348567819","pt":1646218917121,"mc":[{"id":"1.195453627","rc":[{"atl":[[6.4,1.66]],"id":39734233}],"con":true,"img":false}]}
{"op":"mcm","clk":"5348568117","pt":1646218919216,"mc":[{"id":"1.195453627","rc":[{"atb":[[1.03,2.25]],"id":41818958}],"con":true,"img":false}]}
{"op":"mcm","clk":"5348568129","pt":1646218919276,"mc":[{"id":"1.195453627","rc":[{"atb":[[6.4,0]],"id":41818958}],"con":true,"img":false}]}
{"op":"mcm","clk":"5348568158","pt":1646218919385,"mc":[{"id":"1.195453627","rc":[{"atb":[[1.03,0.57]],"id":41818958}],"con":true,"img":false}]}
{"op":"mcm","clk":"5348568185","pt":1646218919591,"mc":[{"id":"1.195453627","rc":[{"atb":[[1.03,0]],"id":41818958}],"con":true,"img":false}]}
{"op":"mcm","clk":"5348568205","pt":1646218919705,"mc":[{"id":"1.195453627","rc":[{"atb":[[5.2,0.57]],"id":41818958}],"con":true,"img":false}]}
{"op":"mcm","clk":"5348568318","pt":1646218920503,"mc":[{"id":"1.195453627","rc":[{"atb":[[3.5,0]],"id":39734233}],"con":true,"img":false}]}
{"op":"mcm","clk":"5348568351","pt":1646218920710,"mc":[{"id":"1.195453627","rc":[{"atb":[[3.6,22.05]],"id":39734233}],"con":true,"img":false}]}
{"op":"mcm","clk":"5348568928","pt":1646218924893,"mc":[{"id":"1.195453627","rc":[{"atl":[[7.2,0]],"id":39734233}],"con":true,"img":false}]}
{"op":"mcm","clk":"5348568949","pt":1646218925001,"mc":[{"id":"1.195453627","rc":[{"atl":[[6.2,4.54]],"id":39734233}],"con":true,"img":false}]}
{"op":"mcm","clk":"5348568976","pt":1646218925217,"mc":[{"id":"1.195453627","rc":[{"atb":[[3.35,71.01],[3.55,34.88],[3.45,30.61],[3.65,7.55]],"id":39734233},{"atl":[[9,9.38],[8.2,16.67],[9.4,14.88],[8.6,21.38]],"id":39734233},{"atb":[[1.73,0],[1.99,32.92]],"id":41818958}],"con":true,"img":false}]}
{"op":"mcm","clk":"5348568991","pt":1646218925316,"mc":[{"id":"1.195453627","rc":[{"atb":[[4.3,15.15],[4.5,5.71],[3.95,56.22],[4.1,61.72]],"id":41818958},{"atl":[[19.5,6.49],[21,2.5],[23,3.41],[25,13.41]],"id":41818958},{"atb":[[1.59,123.65],[1.63,30.88],[1.57,213.31],[1.61,79.73]],"id":38214982},{"atl":[[10,2.22],[11,5],[12,15.02],[13,16.26]],"id":38214982},{"atb":[[3.35,31.91],[3.55,7.84],[3.25,55.56],[3.45,20.41]],"id":27868829},{"atl":[[34,2.86],[38,4.73],[42,5.77],[30,1]],"id":27868829},{"atb":[[2.22,53.96],[2.26,17.87],[2.14,109.65],[2.18,227.88]],"id":38761677},{"atl":[[14.5,1.48],[15.5,3.45],[16.5,4.84],[17.5,7.58]],"id":38761677},{"atb":[[4.3,37.88],[4.9,5.13],[4.5,21.43],[4.7,13.51]],"id":40324291},{"atl":[[16.5,8.84],[17.5,3.03],[18.5,10],[19.5,13.85]],"id":40324291}],"con":true,"img":false}]}
{"op":"mcm","clk":"5348569013","pt":1646218925516,"mc":[{"id":"1.195453627","rc":[{"atl":[[7,0]],"id":39734233}],"con":true,"img":false}]}
{"op":"mcm","clk":"5348569028","pt":1646218925580,"mc":[{"id":"1.195453627","rc":[{"atl":[[1000,1.32]],"id":39734233}],"con":true,"img":false}]}
{"op":"mcm","clk":"5348569059","pt":1646218925813,"mc":[{"id":"1.195453627","rc":[{"atb":[[4.4,2.49]],"id":39734233},{"atb":[[5.2,3.06]],"id":41818958},{"atb":[[14,2.46]],"id":27868829},{"atb":[[5.5,2.49]],"id":40324291}],"con":true,"img":false}]}
{"op":"mcm","clk":"5348569191","pt":1646218927090,"mc":[{"id":"1.195453627","rc":[{"atl":[[6.6,0]],"id":39734233}],"con":true,"img":false}]}
{"op":"mcm","clk":"5348569214","pt":1646218927302,"mc":[{"id":"1.195453627","rc":[{"atl":[[1000,3.57]],"id":39734233}],"con":true,"img":false}]}
{"op":"mcm","clk":"5348569228","pt":1646218927409,"mc":[{"id":"1.195453627","rc":[{"atl":[[6.2,0]],"id":39734233}],"con":true,"img":false}]}
{"op":"mcm","clk":"5348569243","pt":1646218927508,"mc":[{"id":"1.195453627","rc":[{"atl":[[1000,2.93],[7.2,4.54]],"id":39734233}],"con":true,"img":false}]}
{"op":"mcm","clk":"5348569270","pt":1646218927817,"mc":[{"id":"1.195453627","rc":[{"atl":[[1000,1.32]],"id":39734233}],"con":true,"img":false}]}
{"op":"mcm","clk":"5348569286","pt":1646218927921,"mc":[{"id":"1.195453627","rc":[{"atl":[[1000,0],[6,1.6]],"id":39734233}],"con":true,"img":false}]}
{"op":"mcm","clk":"5348569298","pt":1646218928028,"mc":[{"id":"1.195453627","rc":[{"atl":[[7,1.32]],"id":39734233}],"con":true,"img":false}]}
{"op":"mcm","clk":"5348569647","pt":1646218931218,"mc":[{"id":"1.195453627","rc":[{"atl":[[6.4,0]],"id":39734233}],"con":true,"img":false}]}
{"op":"mcm","clk":"5348569680","pt":1646218931528,"mc":[{"id":"1.195453627","rc":[{"atl":[[5.9,1.8]],"id":39734233}],"con":true,"img":false}]}
{"op":"mcm","clk":"5348569816","pt":1646218932724,"mc":[{"id":"1.195453627","rc":[{"atb":[[4.4,0]],"id":39734233}],"con":true,"img":false}]}
{"op":"mcm","clk":"5348569860","pt":1646218933096,"mc":[{"id":"1.195453627","rc":[{"atb":[[2.22,47.8]],"id":38761677}],"con":true,"img":false}]}
{"op":"mcm","clk":"5348570008","pt":1646218934502,"mc":[{"id":"1.195453627","rc":[{"spl":[[1.01,5.45]],"id":40324291}],"con":true,"img":false}]}
{"op":"mcm","clk":"5348570075","pt":1646218935184,"mc":[{"id":"1.195453627","rc":[{"atb":[[6.2,136.25]],"id":41818958}],"con":true,"img":false}]}
{"op":"mcm","clk":"5348570133","pt":1646218935808,"mc":[{"id":"1.195453627","rc":[{"atb":[[3,32.81],[2.96,0]],"id":39734233},{"atl":[[8.6,6.58]],"id":39734233},{"atb":[[4.1,43.42]],"id":41818958},{"atl":[[11.5,0],[12.5,3.79]],"id":41818958},{"atb":[[4,26.55],[4.6,3.11]],"id":38214982},{"atl":[[14,7.69],[15.5,11.43]],"id":38214982},{"atl":[[44,0],[60,3.8]],"id":27868829},{"atb":[[2.18,113.09],[2.16,65.05]],"id":38761677},{"atl":[[4.5,12.45],[4.2,0]],"id":38761677}],"con":true,"img":false}]}
{"op":"mcm","clk":"5348570144","pt":1646218935908,"mc":[{"id":"1.195453627","rc":[{"atl":[[8.8,31.62]],"id":39734233}],"con":true,"img":false}]}
{"op":"mcm","clk":"5348570165","pt":1646218936118,"mc":[{"id":"1.195453627","rc":[{"atb":[[4.7,2.02]],"id":41818958}],"con":true,"img":false}]}
{"op":"mcm","clk":"5348570174","pt":1646218936219,"mc":[{"id":"1.195453627","rc":[{"atb":[[6.4,1.39]],"id":41818958}],"con":true,"img":false}]}
{"op":"mcm","clk":"5348570248","pt":1646218937046,"mc":[{"id":"1.195453627","rc":[{"atb":[[5.2,0.57]],"id":41818958}],"con":true,"img":false}]}
{"op":"mcm","clk":"5348570276","pt":1646218937318,"mc":[{"id":"1.195453627","rc":[{"atb":[[1.71,32.92],[1.99,0]],"id":41818958}],"con":true,"img":false}]}
{"op":"mcm","clk":"5348570358","pt":1646218938117,"mc":[{"id":"1.195453627","rc":[{"atl":[[11,0]],"id":41818958}],"con":true,"img":false}]}
{"op":"mcm","clk":"5348570371","pt":1646218938217,"mc":[{"id":"1.195453627","rc":[{"atl":[[12,1.31]],"id":41818958}],"con":true,"img":false}]}
{"op":"mcm","clk":"5348570548","pt":1646218940037,"mc":[{"id":"1.195453627","rc":[{"atb":[[6.6,2.49]],"id":41818958}],"con":true,"img":false}]}
{"op":"mcm","clk":"5348570624","pt":1646218940815,"mc":[{"id":"1.195453627","rc":[{"atb":[[3.6,0],[3.5,13.63]],"id":39734233},{"atl":[[13,14.05]],"id":38214982},{"atl":[[42,3.05],[44,1.01]],"id":27868829},{"atl":[[13,0],[14,3.35]],"id":40324291}],"con":true,"img":false}]}
{"op":"mcm","clk":"5348570668","pt":1646218941338,"mc":[{"id":"1.195453627","rc":[{"atb":[[3.8,8.79],[3.65,0]],"id":39734233},{"atl":[[10,0],[9.8,2.27]],"id":38214982},{"atl":[[29,1],[30,0]],"id":27868829}],"con":true,"img":false}]}
{"op":"mcm","clk":"5348570722","pt":1646218941802,"mc":[{"id":"1.195453627","rc":[{"atb":[[5.2,0]],"id":38214982}],"con":true,"img":false}]}
{"op":"mcm","clk":"5348570734","pt":1646218941907,"mc":[{"id":"1.195453627","rc":[{"atb":[[5.1,14.61]],"id":38214982}],"con":true,"img":false}]}
{"op":"mcm","clk":"5348570741","pt":1646218942012,"mc":[{"id":"1.195453627","rc":[{"atb":[[4.7,0]],"id":41818958}],"con":true,"img":false}]}
{"op":"mcm","clk":"5348570816","pt":1646218942842,"mc":[{"id":"1.195453627","rc":[{"atb":[[2.26,53.03]],"id":38761677}],"con":true,"img":false}]}
{"op":"mcm","clk":"5348570823","pt":1646218942944,"mc":[{"id":"1.195453627","rc":[{"atb":[[2.18,63.56]],"id":38761677}],"con":true,"img":false}]}
{"op":"mcm","clk":"5348570851","pt":1646218943110,"mc":[{"id":"1.195453627","rc":[{"atb":[[1.71,0],[1.57,32.92]],"id":41818958}],"con":true,"img":false}]}
{"op":"mcm","clk":"5348571241","pt":1646218946811,"mc":[{"id":"1.195453627","rc":[{"atl":[[5.9,7.35],[7.2,0]],"id":39734233}],"con":true,"img":false}]}
{"op":"mcm","clk":"5348571355","pt":1646218948008,"mc":[{"id":"1.195453627","rc":[{"atl":[[6,0]],"id":39734233}],"con":true,"img":false}]}
{"op":"mcm","clk":"5348571368","pt":1646218948218,"mc":[{"id":"1.195453627","rc":[{"atl":[[1000,2.25]],"id":39734233}],"con":true,"img":false}]}
{"op":"mcm","clk":"5348571380","pt":1646218948320,"mc":[{"id":"1.195453627","rc":[{"atl":[[13,13.7]],"id":41818958},{"atl":[[16.5,14.08]],"id":40324291}],"con":true,"img":false}]}
{"op":"mcm","clk":"5348571388","pt":1646218948427,"mc":[{"id":"1.195453627","rc":[{"atl":[[1000,1.65]],"id":39734233}],"con":true,"img":false}]}
{"op":"mcm","clk":"5348571413","pt":1646218948734,"mc":[{"id":"1.195453627","rc":[{"atl":[[1000,0]],"id":39734233}],"con":true,"img":false}]}
{"op":"mcm","clk":"5348571425","pt":1646218948833,"mc":[{"id":"1.195453627","rc":[{"atl":[[5.8,1.65]],"id":39734233}],"con":true,"img":false}]}
{"op":"mcm","clk":"5348571507","pt":1646218949719,"mc":[{"id":"1.195453627","rc":[{"atl":[[5.9,5.54]],"id":39734233},{"atb":[[4.2,0]],"id":41818958},{"atb":[[2.22,40.98]],"id":38761677}],"con":true,"img":false}]}
{"op":"mcm","clk":"5348571533","pt":1646218950023,"mc":[{"id":"1.195453627","rc":[{"atl":[[5.8,3.49],[7,0]],"id":39734233}],"con":true,"img":false}]}
{"op":"mcm","clk":"5348571540","pt":1646218950134,"mc":[{"id":"1.195453627","rc":[{"atl":[[1000,1.32]],"id":39734233}],"con":true,"img":false}]}
{"op":"mcm","clk":"5348571592","pt":1646218950700,"mc":[{"id":"1.195453627","rc":[{"atl":[[1000,0]],"id":39734233}],"con":true,"img":false}]}
{"op":"mcm","clk":"5348571605","pt":1646218950856,"mc":[{"id":"1.195453627","rc":[{"atl":[[5.7,1.32]],"id":39734233},{"atb":[[5.4,10.47],[5.1,2]],"id":40324291}],"con":true,"img":false}]}
{"op":"mcm","clk":"5348571639","pt":1646218951115,"mc":[{"id":"1.195453627","rc":[{"atb":[[4.3,0]],"id":39734233}],"con":true,"img":false}]}
{"op":"mcm","clk":"5348571648","pt":1646218951217,"mc":[{"id":"1.195453627","rc":[{"atb":[[1.02,1.3]],"id":39734233}],"con":true,"img":false}]}
{"op":"mcm","clk":"5348571662","pt":1646218951323,"mc":[{"id":"1.195453627","rc":[{"atb":[[3.7,18.52]],"id":39734233},{"atb":[[12.5,0],[13.5,4.29]],"id":27868829}],"con":true,"img":false}]}
{"op":"mcm","clk":"5348571727","pt":1646218952043,"mc":[{"id":"1.195453627","rc":[{"atb":[[5.2,3.76]],"id":40324291}],"con":true,"img":false}]}
{"op":"mcm","clk":"5348571737","pt":1646218952098,"mc":[{"id":"1.195453627","rc":[{"atb":[[5.5,3.78]],"id":40324291}],"con":true,"img":false}]}
{"op":"mcm","clk":"5348572285","pt":1646218957802,"mc":[{"id":"1.195453627","rc":[{"spn":4.95,"spf":"NaN","id":39734233},{"atb":[[4.9,11.51],[4.6,0]],"id":41818958},{"spn":9.3,"spf":"NaN","id":41818958},{"spn":5.86,"spf":1.0,"id":38214982},{"spn":21.5,"spf":"NaN","id":27868829},{"spn":5.49,"spf":1.0,"id":40324291}],"con":true,"img":false}]}
{"op":"mcm","clk":"5348572298","pt":1646218958011,"mc":[{"id":"1.195453627","rc":[{"atb":[[3.35,17.82],[3.55,15.27],[3.45,0]],"id":39734233}],"con":true,"img":false}]}
{"op":"mcm","clk":"5348572317","pt":1646218958321,"mc":[{"id":"1.195453627","rc":[{"atb":[[4.8,13.9],[4.2,0]],"id":40324291}],"con":true,"img":false}]}
{"op":"mcm","clk":"5348572426","pt":1646218959831,"mc":[{"id":"1.195453627","rc":[{"atl":[[5.9,0]],"id":39734233}],"con":true,"img":false}]}
{"op":"mcm","clk":"5348572431","pt":1646218959933,"mc":[{"id":"1.195453627","rc":[{"atl":[[5.7,6.86]],"id":39734233}],"con":true,"img":false}]}
{"op":"mcm","clk":"5348572441","pt":1646218960040,"mc":[{"id":"1.195453627","rc":[{"atb":[[5.2,1.98]],"id":40324291}],"con":true,"img":false}]}
{"op":"mcm","clk":"5348572575","pt":1646218961363,"mc":[{"id":"1.195453627","rc":[{"atb":[[3.6,28.85]],"id":39734233}],"con":true,"img":false}]}
{"op":"mcm","clk":"5348572753","pt":1646218963022,"mc":[{"id":"1.195453627","rc":[{"atl":[[5.8,1.84]],"id":39734233}],"con":true,"img":false}]}
{"op":"mcm","clk":"5348572773","pt":1646218963229,"mc":[{"id":"1.195453627","rc":[{"atl":[[1000,2.25]],"id":39734233}],"con":true,"img":false}]}
{"op":"mcm","clk":"5348572784","pt":1646218963342,"mc":[{"id":"1.195453627","rc":[{"atl":[[1000,1.71],[5.7,5.54]],"id":39734233}],"con":true,"img":false}]}
{"op":"mcm","clk":"5348572789","pt":1646218963444,"mc":[{"id":"1.195453627","rc":[{"atl":[[1000,3.04]],"id":39734233}],"con":true,"img":false}]}
{"op":"mcm","clk":"5348572835","pt":1646218963870,"mc":[{"id":"1.195453627","rc":[{"atb":[[3.5,0]],"id":39734233},{"atl":[[1000,1.32]],"id":39734233}],"con":true,"img":false}]}
{"op":"mcm","clk":"5348572844","pt":1646218963922,"mc":[{"id":"1.195453627","rc":[{"atb":[[3.4,13.63]],"id":39734233},{"atl":[[5.6,1.71]],"id":39734233}],"con":true,"img":false}]}
{"op":"mcm","clk":"5348572976","pt":1646218965350,"mc":[{"id":"1.195453627","rc":[{"atl":[[8.8,16.81]],"id":39734233}],"con":true,"img":false}]}
{"op":"mcm","clk":"5348572983","pt":1646218965441,"mc":[{"id":"1.195453627","rc":[{"atl":[[8.6,21.38]],"id":39734233}],"con":true,"img":false}]}
{"op":"mcm","clk":"5348573370","pt":1646218969268,"mc":[{"id":"1.195453627","rc":[{"atl":[[8.6,6.58]],"id":39734233},{"atb":[[1.94,51.11],[2.16,36.11]],"id":38761677},{"atb":[[4.8,0]],"id":40324291}],"con":true,"img":false}]}
{"op":"mcm","clk":"5348573376","pt":1646218969363,"mc":[{"id":"1.195453627","rc":[{"atl":[[8.8,31.62]],"id":39734233},{"atb":[[4.6,13.9]],"id":40324291}],"con":true,"img":false}]}
{"op":"mcm","clk":"5348573563","pt":1646218971358,"mc":[{"id":"1.195453627","rc":[{"atb":[[3.5,50]],"id":39734233}],"con":true,"img":false}]}
{"op":"mcm","clk":"5348574631","pt":1646218981781,"mc":[{"id":"1.195453627","rc":[{"atl":[[5.3,36.17]],"id":38761677}],"con":true,"img":false}]}
{"op":"mcm","clk":"5348574849","pt":1646218983773,"mc":[{"id":"1.195453627","rc":[{"atl":[[14,0]],"id":40324291}],"con":true,"img":false}]}
{"op":"mcm","clk":"5348574861","pt":1646218983877,"mc":[{"id":"1.195453627","rc":[{"atl":[[13.5,3.35]],"id":40324291}],"con":true,"img":false}]}
{"op":"mcm","clk":"5348574881","pt":1646218984086,"mc":[{"id":"1.195453627","rc":[{"atl":[[11.5,0]],"id":40324291}],"con":true,"img":false}]}
{"op":"mcm","clk":"5348574891","pt":1646218984190,"mc":[{"id":"1.195453627","rc":[{"atl":[[1000,1.32]],"id":40324291}],"con":true,"img":false}]}
{"op":"mcm","clk":"5348574965","pt":1646218984868,"mc":[{"id":"1.195453627","rc":[{"atb":[[3.4,0]],"id":39734233}],"con":true,"img":false}]}
{"op":"mcm","clk":"5348574982","pt":1646218984973,"mc":[{"id":"1.195453627","rc":[{"atb":[[3.65,13.63]],"id":39734233}],"con":true,"img":false}]}
{"op":"mcm","clk":"5348574989","pt":1646218985077,"mc":[{"id":"1.195453627","rc":[{"atl":[[1000,0]],"id":40324291}],"con":true,"img":false}]}
{"op":"mcm","clk":"5348575003","pt":1646218985183,"mc":[{"id":"1.195453627","rc":[{"atl":[[11.5,1.32]],"id":40324291}],"con":true,"img":false}]}
{"op":"mcm","clk":"5348577503","pt":1646219009491,"mc":[{"id":"1.195453627","rc":[{"atb":[[1.03,2.25],[5.2,0]],"id":41818958}],"con":true,"img":false}]}
{"op":"mcm","clk":"5348577514","pt":1646219009595,"mc":[{"id":"1.195453627","rc":[{"atb":[[1.03,0.55]],"id":41818958}],"con":true,"img":false}]}
{"op":"mcm","clk":"5348577562","pt":1646219010010,"mc":[{"id":"1.195453627","rc":[{"atb":[[1.03,0]],"id":41818958}],"con":true,"img":false}]}
{"op":"mcm","clk":"5348577574","pt":1646219010124,"mc":[{"id":"1.195453627","rc":[{"atb":[[6.8,0.55]],"id":41818958}],"con":true,"img":false}]}
{"op":"mcm","clk":"5348577831","pt":1646219012622,"mc":[{"id":"1.195453627","rc":[{"atb":[[3.55,0]],"id":39734233}],"con":true,"img":false}]}
{"op":"mcm","clk":"5348577848","pt":1646219012778,"mc":[{"id":"1.195453627","rc":[{"atb":[[4.3,11.8]],"id":39734233}],"con":true,"img":false}]}
{"op":"mcm","clk":"5348582476","pt":1646219058151,"mc":[{"id":"1.195453627","rc":[{"atl":[[5.8,0]],"id":39734233},{"spn":9.4,"spf":"NaN","id":41818958}],"con":true,"img":false}]}
{"op":"mcm","clk":"5348582518","pt":1646219058568,"mc":[{"id":"1.195453627","rc":[{"atl":[[5.5,1.94]],"id":39734233}],"con":true,"img":false}]}
{"op":"mcm","clk":"5348583965","pt":1646219073377,"mc":[{"id":"1.195453627","rc":[{"atl":[[5.7,0]],"id":39734233}],"con":true,"img":false}]}
{"op":"mcm","clk":"5348583978","pt":1646219073481,"mc":[{"id":"1.195453627","rc":[{"atl":[[5.5,7.48]],"id":39734233}],"con":true,"img":false}]}
{"op":"mcm","clk":"5348584067","pt":1646219074266,"mc":[{"id":"1.195453627","rc":[{"atl":[[5.6,0]],"id":39734233}],"con":true,"img":false}]}
{"op":"mcm","clk":"5348584075","pt":1646219074369,"mc":[{"id":"1.195453627","rc":[{"atl":[[1000,3.57]],"id":39734233}],"con":true,"img":false}]}
{"op":"mcm","clk":"5348584117","pt":1646219074740,"mc":[{"id":"1.195453627","rc":[{"atl":[[1000,3.1]],"id":39734233}],"con":true,"img":false}]}
{"op":"mcm","clk":"5348584138","pt":1646219075047,"mc":[{"id":"1.195453627","rc":[{"atl":[[1000,1.32]],"id":39734233}],"con":true,"img":false}]}
{"op":"mcm","clk":"5348584146","pt":1646219075147,"mc":[{"id":"1.195453627","rc":[{"atl":[[5.4,1.77]],"id":39734233}],"con":true,"img":false}]}
{"op":"mcm","clk":"5348584935","pt":1646219078947,"mc":[{"id":"1.195453627","rc":[{"atb":[[4.3,0]],"id":39734233}],"con":true,"img":false}]}
{"op":"mcm","clk":"5348586047","pt":1646219087660,"mc":[{"id":"1.195453627","rc":[{"atl":[[5.5,5.54]],"id":39734233}],"con":true,"img":false}]}
{"op":"mcm","clk":"5348586068","pt":1646219087872,"mc":[{"id":"1.195453627","rc":[{"atb":[[1.51,49.6],[1.57,0]],"id":41818958},{"atb":[[5.2,0]],"id":40324291}],"con":true,"img":false}]}
{"op":"mcm","clk":"5348586074","pt":1646219087968,"mc":[{"id":"1.195453627","rc":[{"atl":[[5.3,2.01]],"id":39734233}],"con":true,"img":false}]}
{"op":"mcm","clk":"5348586114","pt":1646219088486,"mc":[{"id":"1.195453627","rc":[{"spl":[[1.01,4]],"id":41818958},{"spl":[[1.01,154]],"id":38214982},{"spl":[[1.01,4]],"id":27868829},{"spl":[[1.01,9.45]],"id":40324291}],"con":true,"img":false}]}
{"op":"mcm","clk":"5348586196","pt":1646219089267,"mc":[{"id":"1.195453627","rc":[{"atl":[[5.4,0]],"id":39734233}],"con":true,"img":false}]}
{"op":"mcm","clk":"5348586214","pt":1646219089469,"mc":[{"id":"1.195453627","rc":[{"atl":[[1000,3.57]],"id":39734233}],"con":true,"img":false}]}
{"op":"mcm","clk":"5348586255","pt":1646219089984,"mc":[{"id":"1.195453627","rc":[{"atl":[[1000,3.17]],"id":39734233}],"con":true,"img":false}]}
{"op":"mcm","clk":"5348586269","pt":1646219090194,"mc":[{"id":"1.195453627","rc":[{"atl":[[1000,1.32]],"id":39734233}],"con":true,"img":false}]}
{"op":"mcm","clk":"5348586275","pt":1646219090298,"mc":[{"id":"1.195453627","rc":[{"atl":[[5.2,1.84]],"id":39734233}],"con":true,"img":false}]}
{"op":"mcm","clk":"5348586407","pt":1646219091593,"mc":[{"id":"1.195453627","rc":[{"atb":[[5.5,1.28]],"id":40324291}],"con":true,"img":false}]}
{"op":"mcm","clk":"5348586672","pt":1646219094290,"mc":[{"id":"1.195453627","rc":[{"atb":[[5.7,3]],"id":40324291}],"con":true,"img":false}]}
{"op":"mcm","clk":"5348587564","pt":1646219102878,"mc":[{"id":"1.195453627","rc":[{"atl":[[5.3,0]],"id":39734233}],"con":true,"img":false}]}
{"op":"mcm","clk":"5348587598","pt":1646219103191,"mc":[{"id":"1.195453627","rc":[{"atl":[[5.2,3.9]],"id":39734233}],"con":true,"img":false}]}
{"op":"mcm","clk":"5348591919","pt":1646219134837,"mc":[{"id":"1.195453627","rc":[{"spn":4.7,"spf":"NaN","id":39734233},{"spn":6.58,"spf":1.0,"id":41818958},{"atb":[[2.08,0]],"id":38214982},{"spn":5.81,"spf":1.0,"id":38214982},{"spn":13.8,"spf":1.0,"id":27868829},{"spn":5.5,"spf":1.0,"id":40324291}],"con":true,"img":false}]}
{"op":"mcm","clk":"5348593659","pt":1646219148178,"mc":[{"id":"1.195453627","rc":[{"atb":[[15.5,54.5]],"id":27868829}],"con":true,"img":false}]}
{"op":"mcm","clk":"5348593883","pt":1646219149878,"mc":[{"id":"1.195453627","rc":[{"atb":[[14,0.38]],"id":27868829}],"con":true,"img":false}]}
{"op":"mcm","clk":"5348594300","pt":1646219152675,"mc":[{"id":"1.195453627","rc":[{"atb":[[16,1.32]],"id":27868829}],"con":true,"img":false}]}
{"op":"mcm","clk":"5348594415","pt":1646219153470,"mc":[{"id":"1.195453627","rc":[{"atb":[[16.5,2.08]],"id":27868829}],"con":true,"img":false}]}
{"op":"mcm","clk":"5348594437","pt":1646219153674,"mc":[{"id":"1.195453627","rc":[{"atl":[[36,6.6],[38,2.03]],"id":27868829},{"atl":[[17,14.44],[18.5,4.29]],"id":40324291}],"con":true,"img":false}]}
{"op":"mcm","clk":"5348595159","pt":1646219159682,"mc":[{"id":"1.195453627","rc":[{"atb":[[1.01,2.25],[5.4,9.9]],"id":40324291}],"con":true,"img":false}]}
{"op":"mcm","clk":"5348595178","pt":1646219159893,"mc":[{"id":"1.195453627","rc":[{"atb":[[1.01,0.64]],"id":40324291}],"con":true,"img":false}]}
{"op":"mcm","clk":"5348595210","pt":1646219160202,"mc":[{"id":"1.195453627","rc":[{"atb":[[1.01,0]],"id":40324291}],"con":true,"img":false}]}
{"op":"mcm","clk":"5348595224","pt":1646219160308,"mc":[{"id":"1.195453627","rc":[{"atb":[[5.8,0.64]],"id":40324291}],"con":true,"img":false}]}
{"op":"mcm","clk":"5348596181","pt":1646219168683,"mc":[{"id":"1.195453627","rc":[{"atb":[[1.34,0]],"id":38761677}],"con":true,"img":false}]}
{"op":"mcm","clk":"5348596822","pt":1646219173913,"mc":[{"id":"1.195453627","rc":[{"atb":[[13.5,0.81]],"id":27868829}],"con":true,"img":false}]}
{"op":"mcm","clk":"5348596836","pt":1646219174021,"mc":[{"id":"1.195453627","rc":[{"atb":[[16,4.81]],"id":27868829}],"con":true,"img":false}]}
{"op":"mcm","clk":"5348597335","pt":1646219178294,"mc":[{"id":"1.195453627","rc":[{"atl":[[8.8,16.81]],"id":39734233}],"con":true,"img":false}]}
{"op":"mcm","clk":"5348597346","pt":1646219178401,"mc":[{"id":"1.195453627","rc":[{"atl":[[8.6,21.38]],"id":39734233}],"con":true,"img":false}]}
{"op":"mcm","clk":"5348599254","pt":1646219194916,"mc":[{"id":"1.195453627","rc":[{"spn":16.26,"spf":1.0,"id":27868829},{"atb":[[2.26,51.03]],"id":38761677},{"atb":[[5.1,0]],"id":40324291},{"spn":5.53,"spf":1.0,"id":40324291}],"con":true,"img":false}]}
{"op":"mcm","clk":"5348599263","pt":1646219195011,"mc":[{"id":"1.195453627","rc":[{"atb":[[2.32,2]],"id":38761677}],"con":true,"img":false}]}
{"op":"mcm","clk":"5348599274","pt":1646219195118,"mc":[{"id":"1.195453627","rc":[{"atb":[[5.6,2]],"id":40324291}],"con":true,"img":false}]}
{"op":"mcm","clk":"5348600349","pt":1646219204039,"mc":[{"id":"1.195453627","rc":[{"atb":[[4.3,4.3]],"id":39734233}],"con":true,"img":false}]}
{"op":"mcm","clk":"5348606554","pt":1646219257118,"mc":[{"id":"1.195453627","rc":[{"spn":4.75,"spf":"NaN","id":39734233},{"spl":[[1.01,8]],"id":41818958},{"spn":6.4,"spf":1.0,"id":41818958},{"spl":[[1.01,8]],"id":27868829},{"spn":16.06,"spf":1.0,"id":27868829},{"spl":[[1.01,13.45]],"id":40324291},{"spn":5.52,"spf":1.0,"id":40324291}],"con":true,"img":false}]}
{"op":"mcm","clk":"5348607968","pt":1646219268174,"mc":[{"id":"1.195453627","rc":[{"atb":[[2.12,0]],"id":41818958}],"con":true,"img":false}]}
{"op":"mcm","clk":"5348609480","pt":1646219280372,"mc":[{"id":"1.195453627","rc":[{"spl":[[1.01,12]],"id":41818958},{"spl":[[1.01,12]],"id":27868829},{"spl":[[1.01,17.45]],"id":40324291}],"con":true,"img":false}]}
{"op":"mcm","clk":"5348614977","pt":1646219324344,"mc":[{"id":"1.195453627","rc":[{"atb":[[2.98,0],[2.74,96.31]],"id":39734233},{"atb":[[1.09,33.36],[1.51,0]],"id":41818958},{"spn":6.33,"spf":1.0,"id":41818958},{"atl":[[36,3.74],[38,4.73]],"id":27868829},{"spn":15.87,"spf":1.0,"id":27868829},{"atb":[[1.64,0],[1.5,102.14]],"id":38761677},{"atb":[[3.6,0],[3.3,43.48]],"id":40324291},{"spn":5.49,"spf":1.0,"id":40324291}],"con":true,"img":false}]}
{"op":"mcm","clk":"5348618701","pt":1646219354891,"mc":[{"id":"1.195453627","rc":[{"atb":[[3.3,0]],"id":40324291}],"con":true,"img":false}]}
{"op":"mcm","clk":"5348618713","pt":1646219354991,"mc":[{"id":"1.195453627","rc":[{"atb":[[2.74,48.15],[2.9,52.63]],"id":39734233},{"atb":[[1.09,0],[1.51,33.36]],"id":41818958},{"atl":[[36,6.6],[38,2.03]],"id":27868829},{"atb":[[1.5,0],[1.65,102.14]],"id":38761677},{"atb":[[3.7,37.04]],"id":40324291}],"con":true,"img":false}]}
{"op":"mcm","clk":"5348619302","pt":1646219360195,"mc":[{"id":"1.195453627","rc":[{"atl":[[36,3.74],[40,2.56]],"id":27868829}],"con":true,"img":false}]}
{"op":"mcm","clk":"5348620425","pt":1646219369822,"mc":[{"id":"1.195453627","rc":[{"atb":[[1.51,0]],"id":41818958}],"con":true,"img":false}]}
{"op":"mcm","clk":"5348620440","pt":1646219369928,"mc":[{"id":"1.195453627","rc":[{"atb":[[1.6,33.36]],"id":41818958}],"con":true,"img":false}]}
{"op":"mcm","clk":"5348624351","pt":1646219403092,"mc":[{"id":"1.195453627","rc":[{"atb":[[1.6,0],[1.51,33.36]],"id":41818958},{"atl":[[36,6.6],[40,0]],"id":27868829}],"con":true,"img":false}]}
{"op":"mcm","clk":"5348630762","pt":1646219456825,"mc":[{"id":"1.195453627","rc":[{"atb":[[4.3,50.78]],"id":27868829}],"con":true,"img":false}]}
{"op":"mcm","clk":"5348636452","pt":1646219502735,"mc":[{"id":"1.195453627","rc":[{"atb":[[1.59,33.36],[1.51,0]],"id":41818958}],"con":true,"img":false}]}
{"op":"mcm","clk":"5348637742","pt":1646219512547,"mc":[{"id":"1.195453627","rc":[{"atl":[[8.2,13.89],[7.2,3.23]],"id":39734233},{"atl":[[18.5,12.55],[19.5,5.41]],"id":41818958},{"atb":[[3.55,0],[3.5,31.91],[3.2,0],[3.65,7.55]],"id":27868829},{"atl":[[13.5,1.6]],"id":38761677},{"atl":[[16.5,12.79],[17,15.69]],"id":40324291}],"con":true,"img":false}]}
{"op":"mcm","clk":"5348637750","pt":1646219512651,"mc":[{"id":"1.195453627","rc":[{"atl":[[14.5,0]],"id":38761677}],"con":true,"img":false}]}
{"op":"mcm","clk":"5348639045","pt":1646219522532,"mc":[{"id":"1.195453627","rc":[{"atl":[[7.6,7.58]],"id":39734233},{"atl":[[19.5,8.11]],"id":41818958},{"atb":[[3.55,19.61]],"id":27868829},{"atl":[[34,4.86]],"id":27868829},{"atl":[[14.5,3.7]],"id":38761677},{"atl":[[18,2.94]],"id":40324291}],"con":true,"img":false}]}
{"op":"mcm","clk":"5348640353","pt":1646219532555,"mc":[{"id":"1.195453627","rc":[{"atl":[[8,10.71],[9,0],[9.4,0],[8.6,14.8]],"id":39734233},{"atl":[[21,3.75],[25,8.2]],"id":41818958},{"atb":[[3.25,0],[3.45,30.61]],"id":27868829},{"atl":[[15.5,5.17],[17.5,0]],"id":38761677},{"atl":[[17.5,0],[18.5,0],[19.5,7.09],[19,4.17]],"id":40324291}],"con":true,"img":false}]}
{"op":"mcm","clk":"5348641650","pt":1646219542549,"mc":[{"id":"1.195453627","rc":[{"atl":[[8.4,16.89]],"id":39734233},{"atl":[[23,5.68]],"id":41818958},{"atb":[[3.35,53.19]],"id":27868829},{"atl":[[16.5,8.06]],"id":38761677},{"atl":[[20,6.58]],"id":40324291}],"con":true,"img":false}]}
{"op":"mcm","clk":"5348647221","pt":1646219592826,"mc":[{"id":"1.195453627","rc":[{"atl":[[34,2.86]],"id":27868829}],"con":true,"img":false}]}
{"op":"mcm","clk":"5348647243","pt":1646219593136,"mc":[{"id":"1.195453627","rc":[{"atl":[[34,4.86]],"id":27868829}],"con":true,"img":false}]}
{"op":"mcm","clk":"5348649672","pt":1646219617888,"mc":[{"id":"1.195453627","rc":[{"spl":[[1.01,20.17]],"id":40324291}],"con":true,"img":false}]}
{"op":"mcm","clk":"5348650166","pt":1646219622797,"mc":[{"id":"1.195453627","rc":[{"atb":[[2.9,0],[2.74,96.31]],"id":39734233},{"atb":[[1.59,0],[1.16,33.36]],"id":41818958},{"atl":[[36,3.74],[38,4.73]],"id":27868829},{"atb":[[1.51,102.14],[1.65,0]],"id":38761677},{"atb":[[3.25,118.92],[3.7,0]],"id":40324291}],"con":true,"img":false}]}
{"op":"mcm","clk":"5348650457","pt":1646219625682,"mc":[{"id":"1.195453627","rc":[{"spl":[[1.01,14.72]],"id":41818958}],"con":true,"img":false}]}
{"op":"mcm","clk":"5348650608","pt":1646219627088,"mc":[{"id":"1.195453627","rc":[{"atb":[[1.62,33.36],[1.16,0]],"id":41818958}],"con":true,"img":false}]}
{"op":"mcm","clk":"5348651416","pt":1646219634115,"mc":[{"id":"1.195453627","rc":[{"spl":[[1.01,14.9]],"id":27868829}],"con":true,"img":false}]}
{"op":"mcm","clk":"5348651496","pt":1646219634941,"mc":[{"id":"1.195453627","rc":[{"atb":[[2.92,52.08],[2.74,48.15]],"id":39734233},{"atl":[[36,6.6],[38,2.03]],"id":27868829},{"atb":[[1.64,102.14],[1.51,0]],"id":38761677},{"atb":[[3.25,74.48],[3.7,35.12]],"id":40324291}],"con":true,"img":false}]}
{"op":"mcm","clk":"5348657383","pt":1646219688007,"mc":[{"id":"1.195453627","rc":[{"atb":[[4.2,0]],"id":39734233},{"spn":6.3,"spf":1.0,"id":41818958},{"spn":15.8,"spf":1.0,"id":27868829},{"spn":5.44,"spf":1.0,"id":40324291}],"con":true,"img":false}]}
{"op":"mcm","clk":"5348657723","pt":1646219691208,"mc":[{"id":"1.195453627","rc":[{"atb":[[4.3,0]],"id":39734233}],"con":true,"img":false}]}
{"op":"mcm","clk":"5348657841","pt":1646219692243,"mc":[{"id":"1.195453627","rc":[{"atl":[[1000,0]],"id":39734233}],"con":true,"img":false}]}
{"op":"mcm","clk":"5348657859","pt":1646219692347,"mc":[{"id":"1.195453627","rc":[{"atl":[[5.1,1.32]],"id":39734233}],"con":true,"img":false}]}
{"op":"mcm","clk":"5348658066","pt":1646219694336,"mc":[{"id":"1.195453627","rc":[{"atl":[[36,3.74],[38,4.73]],"id":27868829}],"con":true,"img":false}]}
{"op":"mcm","clk":"5348658077","pt":1646219694440,"mc":[{"id":"1.195453627","rc":[{"atb":[[3.9,2.52]],"id":39734233}],"con":true,"img":false}]}
{"op":"mcm","clk":"5348658302","pt":1646219696744,"mc":[{"id":"1.195453627","rc":[{"atl":[[5.2,1.84]],"id":39734233}],"con":true,"img":false}]}
{"op":"mcm","clk":"5348658336","pt":1646219697007,"mc":[{"id":"1.195453627","rc":[{"atl":[[4.9,2.18]],"id":39734233}],"con":true,"img":false}]}
{"op":"mcm","clk":"5348658386","pt":1646219697424,"mc":[{"id":"1.195453627","rc":[{"atl":[[5.1,0]],"id":39734233}],"con":true,"img":false}]}
{"op":"mcm","clk":"5348658400","pt":1646219697532,"mc":[{"id":"1.195453627","rc":[{"atl":[[1000,1.32]],"id":39734233}],"con":true,"img":false}]}
{"op":"mcm","clk":"5348658415","pt":1646219697641,"mc":[{"id":"1.195453627","rc":[{"atb":[[1.02,0]],"id":39734233}],"con":true,"img":false}]}
{"op":"mcm","clk":"5348658425","pt":1646219697742,"mc":[{"id":"1.195453627","rc":[{"atb":[[3.85,2.47]],"id":39734233}],"con":true,"img":false}]}
{"op":"mcm","clk":"5348658499","pt":1646219698332,"mc":[{"id":"1.195453627","rc":[{"atb":[[5.7,0.5]],"id":40324291}],"con":true,"img":false}]}
{"op":"mcm","clk":"5348659565","pt":1646219707940,"mc":[{"id":"1.195453627","rc":[{"atl":[[12,0]],"id":41818958},{"atl":[[34,3.52]],"id":27868829},{"atl":[[11.5,0]],"id":40324291}],"con":true,"img":false}]}
{"op":"mcm","clk":"5348659576","pt":1646219708040,"mc":[{"id":"1.195453627","rc":[{"atl":[[1000,1.31]],"id":41818958},{"atl":[[1000,1.34]],"id":27868829},{"atl":[[1000,1.32]],"id":40324291}],"con":true,"img":false}]}
{"op":"mcm","clk":"5348659597","pt":1646219708153,"mc":[{"id":"1.195453627","rc":[{"atb":[[1.62,0],[1.54,33.36]],"id":41818958}],"con":true,"img":false}]}
{"op":"mcm","clk":"5348661886","pt":1646219726813,"mc":[{"id":"1.195453627","rc":[{"atl":[[5.5,0]],"id":39734233}],"con":true,"img":false}]}
{"op":"mcm","clk":"5348661898","pt":1646219726913,"mc":[{"id":"1.195453627","rc":[{"atl":[[5.4,5.54]],"id":39734233}],"con":true,"img":false}]}
{"op":"mcm","clk":"5348662224","pt":1646219729494,"mc":[{"id":"1.195453627","rc":[{"atl":[[5.2,0]],"id":39734233}],"con":true,"img":false}]}
{"op":"mcm","clk":"5348662249","pt":1646219729691,"mc":[{"id":"1.195453627","rc":[{"atl":[[1000,3.57]],"id":39734233}],"con":true,"img":false}]}
{"op":"mcm","clk":"5348662262","pt":1646219729795,"mc":[{"id":"1.195453627","rc":[{"atl":[[1000,3.2]],"id":39734233}],"con":true,"img":false}]}
{"op":"mcm","clk":"5348662284","pt":1646219730001,"mc":[{"id":"1.195453627","rc":[{"atl":[[1000,1.32]],"id":39734233}],"con":true,"img":false}]}
{"op":"mcm","clk":"5348662297","pt":1646219730106,"mc":[{"id":"1.195453627","rc":[{"atl":[[4.9,0],[5.1,1.88]],"id":39734233}],"con":true,"img":false}]}
{"op":"mcm","clk":"5348662333","pt":1646219730381,"mc":[{"id":"1.195453627","rc":[{"atl":[[4.6,2.32]],"id":39734233}],"con":true,"img":false}]}
{"op":"mcm","clk":"5348662927","pt":1646219735600,"mc":[{"id":"1.195453627","rc":[{"atl":[[5.1,0]],"id":39734233}],"con":true,"img":false}]}
{"op":"mcm","clk":"5348662937","pt":1646219735705,"mc":[{"id":"1.195453627","rc":[{"atl":[[1000,3.57]],"id":39734233}],"con":true,"img":false}]}
{"op":"mcm","clk":"5348662953","pt":1646219735810,"mc":[{"id":"1.195453627","rc":[{"atl":[[1000,3.41]],"id":39734233}],"con":true,"img":false}]}
{"op":"mcm","clk":"5348662975","pt":1646219736018,"mc":[{"id":"1.195453627","rc":[{"atl":[[1000,1.32]],"id":39734233}],"con":true,"img":false}]}
{"op":"mcm","clk":"5348662991","pt":1646219736080,"mc":[{"id":"1.195453627","rc":[{"atl":[[4.6,4.41]],"id":39734233}],"con":true,"img":false}]}
{"op":"mcm","clk":"5348663054","pt":1646219736595,"mc":[{"id":"1.195453627","rc":[{"atb":[[3.85,1.17]],"id":39734233}],"con":true,"img":false}]}
{"op":"mcm","clk":"5348663065","pt":1646219736697,"mc":[{"id":"1.195453627","rc":[{"atb":[[1.02,1.3]],"id":39734233}],"con":true,"img":false}]}
{"op":"mcm","clk":"5348663094","pt":1646219736906,"mc":[{"id":"1.195453627","rc":[{"atl":[[5.4,0],[7,4.67]],"id":39734233}],"con":true,"img":false}]}
{"op":"mcm","clk":"5348664719","pt":1646219750311,"mc":[{"id":"1.195453627","rc":[{"atl":[[7,0]],"id":39734233},{"spn":4.25,"spf":"NaN","id":39734233},{"spn":5.35,"spf":1.0,"id":40324291}],"con":true,"img":false}]}
{"op":"mcm","clk":"5348664732","pt":1646219750414,"mc":[{"id":"1.195453627","rc":[{"atl":[[6.8,4.67]],"id":39734233}],"con":true,"img":false}]}
{"op":"mcm","clk":"5348665022","pt":1646219752926,"mc":[{"id":"1.195453627","rc":[{"atb":[[2.28,20.4]],"id":38761677}],"con":true,"img":false}]}
{"op":"mcm","clk":"5348665805","pt":1646219760124,"mc":[{"id":"1.195453627","rc":[{"atl":[[7.8,2.94],[7.2,0],[7.6,0]],"id":39734233},{"atb":[[4.3,6.06],[4.5,0]],"id":41818958},{"atl":[[10.5,2.11],[9.8,0]],"id":38214982},{"atb":[[4.9,0],[4.7,5.41]],"id":40324291}],"con":true,"img":false}]}
{"op":"mcm","clk":"5348666283","pt":1646219764853,"mc":[{"id":"1.195453627","rc":[{"atl":[[6.8,0]],"id":39734233}],"con":true,"img":false}]}
{"op":"mcm","clk":"5348666294","pt":1646219764954,"mc":[{"id":"1.195453627","rc":[{"atl":[[6.6,4.67]],"id":39734233}],"con":true,"img":false}]}
{"op":"mcm","clk":"5348666499","pt":1646219766946,"mc":[{"id":"1.195453627","rc":[{"atl":[[6.4,26.57]],"id":38214982},{"trd":[[6.4,30.85]],"ltp":6.4,"tv":30.85,"id":38214982}],"con":true,"img":false}]}
{"op":"mcm","clk":"5348666673","pt":1646219768337,"mc":[{"id":"1.195453627","rc":[{"atb":[[4.9,11.42]],"id":41818958},{"atb":[[14,0.37]],"id":27868829}],"con":true,"img":false}]}
{"op":"mcm","clk":"5348666698","pt":1646219768634,"mc":[{"id":"1.195453627","rc":[{"atb":[[3.85,0.74]],"id":39734233},{"atb":[[4.9,11.17]],"id":41818958},{"atb":[[14,0.27]],"id":27868829},{"atb":[[2.3,0]],"id":38761677},{"atb":[[5.3,1.56]],"id":40324291}],"con":true,"img":false}]}
{"op":"mcm","clk":"5348666714","pt":1646219768744,"mc":[{"id":"1.195453627","rc":[{"atb":[[3.95,0.42]],"id":39734233},{"atb":[[6.8,0.8]],"id":41818958},{"atb":[[17,0.09]],"id":27868829},{"atb":[[2.42,0.71]],"id":38761677},{"atb":[[5.8,0.95]],"id":40324291}],"con":true,"img":false}]}
{"op":"mcm","clk":"5348666783","pt":1646219769362,"mc":[{"id":"1.195453627","rc":[{"atb":[[3.65,0]],"id":39734233}],"con":true,"img":false}]}
{"op":"mcm","clk":"5348666794","pt":1646219769472,"mc":[{"id":"1.195453627","rc":[{"atb":[[3.55,13.63]],"id":39734233}],"con":true,"img":false}]}
{"op":"mcm","clk":"5348666870","pt":1646219770152,"mc":[{"id":"1.195453627","rc":[{"atl":[[7.8,0]],"id":39734233},{"atb":[[4.1,35.36]],"id":41818958},{"atl":[[11.5,4.76]],"id":38214982},{"atb":[[4.5,14.29]],"id":40324291}],"con":true,"img":false}]}
{"op":"mcm","clk":"5348666943","pt":1646219770889,"mc":[{"id":"1.195453627","rc":[{"atb":[[2.28,0]],"id":38761677}],"con":true,"img":false}]}
{"op":"mcm","clk":"5348667167","pt":1646219772782,"mc":[{"id":"1.195453627","rc":[{"atb":[[3.9,0]],"id":39734233}],"con":true,"img":false}]}
{"op":"mcm","clk":"5348667282","pt":1646219773669,"mc":[{"id":"1.195453627","rc":[{"atb":[[2.28,7.14]],"id":38761677}],"con":true,"img":false}]}
{"op":"mcm","clk":"5348667308","pt":1646219773884,"mc":[{"id":"1.195453627","rc":[{"atl":[[7.8,2.94]],"id":39734233}],"con":true,"img":false}]}
{"op":"mcm","clk":"5348667321","pt":1646219773957,"mc":[{"id":"1.195453627","rc":[{"atl":[[11,0],[12,8.2],[13,3.63]],"id":38214982}],"con":true,"img":false}]}
{"op":"mcm","clk":"5348667958","pt":1646219779346,"mc":[{"id":"1.195453627","rc":[{"atl":[[13,0]],"id":38214982}],"con":true,"img":false}]}
{"op":"mcm","clk":"5348667967","pt":1646219779449,"mc":[{"id":"1.195453627","rc":[{"atl":[[13.5,3.63]],"id":38214982}],"con":true,"img":false}]}
{"op":"mcm","clk":"5348668047","pt":1646219780186,"mc":[{"id":"1.195453627","rc":[{"atb":[[3.95,39.27]],"id":41818958},{"atl":[[12.5,6.52]],"id":38214982},{"atb":[[4.3,22.73]],"id":40324291}],"con":true,"img":false}]}
{"op":"mcm","clk":"5348668062","pt":1646219780246,"mc":[{"id":"1.195453627","rc":[{"atb":[[6.2,124.03]],"id":38214982}],"con":true,"img":false}]}
{"op":"mcm","clk":"5348668357","pt":1646219782906,"mc":[{"id":"1.195453627","rc":[{"atb":[[6.2,116.52]],"id":38214982}],"con":true,"img":false}]}
{"op":"mcm","clk":"5348668371","pt":1646219783018,"mc":[{"id":"1.195453627","rc":[{"atl":[[6.4,19.06]],"id":38214982},{"trd":[[6.4,45.87]],"ltp":6.4,"tv":45.87,"id":38214982}],"con":true,"img":false}]}
{"op":"mcm","clk":"5348668480","pt":1646219783982,"mc":[{"id":"1.195453627","rc":[{"atl":[[7.8,0]],"id":39734233}],"con":true,"img":false}]}
{"op":"mcm","clk":"5348668506","pt":1646219784297,"mc":[{"id":"1.195453627","rc":[{"atl":[[5.3,6.16],[6.6,0]],"id":39734233},{"atb":[[2.26,15.87]],"id":38761677}],"con":true,"img":false}]}
{"op":"mcm","clk":"5348668517","pt":1646219784351,"mc":[{"id":"1.195453627","rc":[{"atb":[[2.28,42.31]],"id":38761677}],"con":true,"img":false}]}
{"op":"mcm","clk":"5348668631","pt":1646219785451,"mc":[{"id":"1.195453627","rc":[{"atb":[[3.95,0]],"id":39734233}],"con":true,"img":false}]}
{"op":"mcm","clk":"5348668642","pt":1646219785553,"mc":[{"id":"1.195453627","rc":[{"atb":[[3.9,0.42]],"id":39734233}],"con":true,"img":false}]}
{"op":"mcm","clk":"5348668668","pt":1646219785761,"mc":[{"id":"1.195453627","rc":[{"atl":[[7.8,2.94]],"id":39734233}],"con":true,"img":false}]}
{"op":"mcm","clk":"5348668947","pt":1646219788271,"mc":[{"id":"1.195453627","rc":[{"atb":[[5.1,0]],"id":38214982}],"con":true,"img":false}]}
{"op":"mcm","clk":"5348668959","pt":1646219788366,"mc":[{"id":"1.195453627","rc":[{"atb":[[5,14.61]],"id":38214982}],"con":true,"img":false}]}
{"op":"mcm","clk":"5348668981","pt":1646219788576,"mc":[{"id":"1.195453627","rc":[{"atb":[[5.3,7.5]],"id":38214982}],"con":true,"img":false}]}
{"op":"mcm","clk":"5348669153","pt":1646219790197,"mc":[{"id":"1.195453627","rc":[{"atb":[[3.85,43.86]],"id":41818958},{"atl":[[13.5,13.63]],"id":38214982},{"atb":[[4.1,40.32]],"id":40324291}],"con":true,"img":false}]}
{"op":"mcm","clk":"5348669167","pt":1646219790303,"mc":[{"id":"1.195453627","rc":[{"atb":[[4.7,25.51]],"id":38214982}],"con":true,"img":false}]}
{"op":"mcm","clk":"5348669565","pt":1646219793093,"mc":[{"id":"1.195453627","rc":[{"atb":[[4.7,0]],"id":38214982}],"con":true,"img":false}]}
{"op":"mcm","clk":"5348670085","pt":1646219795818,"mc":[{"id":"1.195453627","rc":[{"atl":[[7.8,0]],"id":39734233}],"con":true,"img":false}]}
{"op":"mcm","clk":"5348670171","pt":1646219796296,"mc":[{"id":"1.195453627","rc":[{"atb":[[2.16,64.74]],"id":38761677}],"con":true,"img":false}]}
{"op":"mcm","clk":"5348670185","pt":1646219796405,"mc":[{"id":"1.195453627","rc":[{"atb":[[1.94,0]],"id":38761677}],"con":true,"img":false}]}
{"op":"mcm","clk":"5348670462","pt":1646219798120,"mc":[{"id":"1.195453627","rc":[{"atl":[[7.8,2.94]],"id":39734233}],"con":true,"img":false}]}
{"op":"mcm","clk":"5348670771","pt":1646219800392,"mc":[{"id":"1.195453627","rc":[{"atb":[[3.8,1.65],[3.75,7.27]],"id":39734233},{"atl":[[7.8,0]],"id":39734233},{"atb":[[4.1,70.79],[3.7,0]],"id":40324291}],"con":true,"img":false}]}
{"op":"mcm","clk":"5348680310","pt":1646219806612,"mc":[{"id":"1.195453627","rc":[{"atl":[[6.6,3.57]],"id":39734233},{"atb":[[4.3,0],[4.5,5.71]],"id":41818958},{"atl":[[18.5,11.41],[20,1.05]],"id":41818958},{"atl":[[10.5,0],[9.8,2.27]],"id":38214982},{"atb":[[4.8,48.37],[3.5,0],[5,5],[3.65,0]],"id":27868829},{"atl":[[13.5,0],[14,1.54]],"id":38761677},{"atb":[[4.9,5.13],[4.7,0]],"id":40324291},{"atl":[[13,1.67],[15,7.14],[17,8.19]],"id":40324291}],"con":true,"img":false}]}
{"op":"mcm","clk":"5348680423","pt":1646219807522,"mc":[{"id":"1.195453627","rc":[{"atb":[[4.3,6.06]],"id":41818958},{"atl":[[10.5,2.11],[9.8,0]],"id":38214982},{"atb":[[4.9,0],[4.7,5.41]],"id":40324291}],"con":true,"img":false}]}
{"op":"mcm","clk":"5348680447","pt":1646219807628,"mc":[{"id":"1.195453627","rc":[{"atb":[[4.5,0]],"id":41818958},{"atl":[[19.5,5.41]],"id":41818958}],"con":true,"img":false}]}
{"op":"mcm","clk":"5348680997","pt":1646219810861,"mc":[{"id":"1.195453627","rc":[{"spn":6.31,"spf":1.0,"id":41818958},{"spn":5.86,"spf":1.0,"id":38214982},{"spn":15.81,"spf":1.0,"id":27868829},{"spn":2.61,"spf":"NaN","id":38761677},{"atb":[[4.6,28.19],[4.1,40.32]],"id":40324291},{"spn":5.36,"spf":1.0,"id":40324291}],"con":true,"img":false}]}
{"op":"mcm","clk":"5348681802","pt":1646219816670,"mc":[{"id":"1.195453627","rc":[{"atb":[[3.65,18.87]],"id":39734233},{"atl":[[7,8.33]],"id":39734233},{"atb":[[4.8,61.53]],"id":27868829},{"atl":[[15,3.57]],"id":38761677}],"con":true,"img":false}]}
{"op":"mcm","clk":"5348681907","pt":1646219817556,"mc":[{"id":"1.195453627","rc":[{"atl":[[22,11.89]],"id":41818958},{"atl":[[14,3.85]],"id":40324291}],"con":true,"img":false}]}
{"op":"mcm","clk":"5348683065","pt":1646219826643,"mc":[{"id":"1.195453627","rc":[{"atb":[[3.6,0],[3.55,43.04],[3.5,0],[3.7,0]],"id":39734233},{"atl":[[7.4,11.72]],"id":39734233},{"atb":[[3.35,0],[3.55,0],[3.45,0],[4.6,20.83]],"id":27868829},{"atl":[[14.5,0],[15.5,0],[16.5,0],[16,5]],"id":38761677}],"con":true,"img":false}]}
{"op":"mcm","clk":"5348683089","pt":1646219826850,"mc":[{"id":"1.195453627","rc":[{"atb":[[4,2]],"id":39734233}],"con":true,"img":false}]}
{"op":"mcm","clk":"5348683173","pt":1646219827532,"mc":[{"id":"1.195453627","rc":[{"atl":[[24,3.26]],"id":41818958},{"atl":[[15,12.5],[20,0]],"id":40324291}],"con":true,"img":false}]}
{"op":"mcm","clk":"5348683198","pt":1646219827745,"mc":[{"id":"1.195453627","rc":[{"atl":[[20,4.05]],"id":41818958},{"atl":[[13,4.67]],"id":40324291}],"con":true,"img":false}]}
{"op":"mcm","clk":"5348684258","pt":1646219836661,"mc":[{"id":"1.195453627","rc":[{"atb":[[3.45,51.02]],"id":39734233},{"atl":[[8,0],[7.8,18.38],[8.4,0]],"id":39734233},{"atb":[[4.4,36.76]],"id":27868829},{"atl":[[17,16.31]],"id":38761677}],"con":true,"img":false}]}
{"op":"mcm","clk":"5348684289","pt":1646219836866,"mc":[{"id":"1.195453627","rc":[{"atb":[[4.1,3]],"id":39734233},{"atl":[[19.5,8.41],[21,0],[23,0]],"id":41818958},{"atb":[[1.75,4]],"id":38214982},{"atl":[[12.5,4],[19,0]],"id":40324291}],"con":true,"img":false}]}
{"op":"mcm","clk":"5348684374","pt":1646219837594,"mc":[{"id":"1.195453627","rc":[{"atl":[[26,5]],"id":41818958},{"atl":[[16,8.33]],"id":40324291}],"con":true,"img":false}]}
{"op":"mcm","clk":"5348684633","pt":1646219839381,"mc":[{"id":"1.195453627","rc":[{"atl":[[8.2,0],[7.2,13.89]],"id":39734233},{"atl":[[38,2.03],[40,2.56]],"id":27868829},{"atl":[[14,11.54],[15,5.36]],"id":40324291}],"con":true,"img":false}]}
{"op":"mcm","clk":"5348684752","pt":1646219840267,"mc":[{"id":"1.195453627","rc":[{"atl":[[5.3,0]],"id":39734233}],"con":true,"img":false}]}
{"op":"mcm","clk":"5348684765","pt":1646219840373,"mc":[{"id":"1.195453627","rc":[{"atl":[[5.2,6.16]],"id":39734233}],"con":true,"img":false}]}
{"op":"mcm","clk":"5348685491","pt":1646219846783,"mc":[{"id":"1.195453627","rc":[{"atb":[[4.2,4]],"id":39734233}],"con":true,"img":false}]}
{"op":"mcm","clk":"5348685507","pt":1646219846888,"mc":[{"id":"1.195453627","rc":[{"atl":[[19,4]],"id":41818958},{"atb":[[1.76,4]],"id":38214982},{"atl":[[12,21.07]],"id":40324291}],"con":true,"img":false}]}
{"op":"mcm","clk":"5348685522","pt":1646219846988,"mc":[{"id":"1.195453627","rc":[{"atb":[[4.3,2],[3.8,8.79],[3.75,0],[3.05,32.82],[2.92,0]],"id":39734233},{"atl":[[18,0]],"id":40324291}],"con":true,"img":false}]}
{"op":"mcm","clk":"5348685691","pt":1646219848208,"mc":[{"id":"1.195453627","rc":[{"atb":[[1.03,2.25]],"id":40324291}],"con":true,"img":false}]}
{"op":"mcm","clk":"5348685703","pt":1646219848305,"mc":[{"id":"1.195453627","rc":[{"atb":[[5.8,0.3]],"id":40324291}],"con":true,"img":false}]}
{"op":"mcm","clk":"5348685720","pt":1646219848413,"mc":[{"id":"1.195453627","rc":[{"atb":[[1.03,0.57]],"id":40324291}],"con":true,"img":false}]}
{"op":"mcm","clk":"5348685748","pt":1646219848618,"mc":[{"id":"1.195453627","rc":[{"atb":[[1.03,0]],"id":40324291}],"con":true,"img":false}]}
{"op":"mcm","clk":"5348685762","pt":1646219848676,"mc":[{"id":"1.195453627","rc":[{"atb":[[6.6,0.57]],"id":40324291}],"con":true,"img":false}]}
{"op":"mcm","clk":"5348685923","pt":1646219849987,"mc":[{"id":"1.195453627","rc":[{"atl":[[4.6,2.32]],"id":39734233}],"con":true,"img":false}]}
{"op":"mcm","clk":"5348685949","pt":1646219850201,"mc":[{"id":"1.195453627","rc":[{"atl":[[1000,3.57]],"id":39734233}],"con":true,"img":false}]}
{"op":"mcm","clk":"5348685974","pt":1646219850408,"mc":[{"id":"1.195453627","rc":[{"atl":[[1000,3.28]],"id":39734233}],"con":true,"img":false}]}
{"op":"mcm","clk":"5348685991","pt":1646219850513,"mc":[{"id":"1.195453627","rc":[{"atl":[[1000,1.32]],"id":39734233}],"con":true,"img":false}]}
{"op":"mcm","clk":"5348686001","pt":1646219850613,"mc":[{"id":"1.195453627","rc":[{"atl":[[4.9,1.95]],"id":39734233}],"con":true,"img":false}]}
{"op":"mcm","clk":"5348686239","pt":1646219852398,"mc":[{"id":"1.195453627","rc":[{"atl":[[13.5,0]],"id":40324291}],"con":true,"img":false}]}
{"op":"mcm","clk":"5348686254","pt":1646219852502,"mc":[{"id":"1.195453627","rc":[{"atl":[[12.5,7.35]],"id":40324291}],"con":true,"img":false}]}
{"op":"mcm","clk":"5348686291","pt":1646219852810,"mc":[{"id":"1.195453627","rc":[{"atl":[[18.5,13.41]],"id":41818958},{"atb":[[1.77,3]],"id":38214982},{"atl":[[11.5,2],[14,3.85],[14.5,7.41]],"id":40324291}],"con":true,"img":false}]}
{"op":"mcm","clk":"5348686469","pt":1646219854429,"mc":[{"id":"1.195453627","rc":[{"atb":[[1.01,3.59]],"id":39734233}],"con":true,"img":false}]}
{"op":"mcm","clk":"5348686491","pt":1646219854635,"mc":[{"id":"1.195453627","rc":[{"atb":[[1.01,5.58]],"id":39734233}],"con":true,"img":false}]}
{"op":"mcm","clk":"5348686520","pt":1646219854794,"mc":[{"id":"1.195453627","rc":[{"atb":[[1.01,3.59]],"id":39734233}],"con":true,"img":false}]}
{"op":"mcm","clk":"5348686536","pt":1646219854902,"mc":[{"id":"1.195453627","rc":[{"atb":[[1.02,3.29]],"id":39734233},{"atb":[[2.28,35.16]],"id":38761677}],"con":true,"img":false}]}
{"op":"mcm","clk":"5348686594","pt":1646219855421,"mc":[{"id":"1.195453627","rc":[{"atb":[[1.01,3.59]],"id":38761677}],"con":true,"img":false}]}
{"op":"mcm","clk":"5348686613","pt":1646219855629,"mc":[{"id":"1.195453627","rc":[{"atb":[[1.01,5.58]],"id":38761677}],"con":true,"img":false}]}
{"op":"mcm","clk":"5348686641","pt":1646219855893,"mc":[{"id":"1.195453627","rc":[{"atb":[[1.01,3.59]],"id":38761677}],"con":true,"img":false}]}
{"op":"mcm","clk":"5348686651","pt":1646219855997,"mc":[{"id":"1.195453627","rc":[{"atb":[[2.38,1.99]],"id":38761677}],"con":true,"img":false}]}
{"op":"mcm","clk":"5348686766","pt":1646219857095,"mc":[{"id":"1.195453627","rc":[{"atb":[[1.01,2]],"id":40324291}],"con":true,"img":false}]}
{"op":"mcm","clk":"5348686784","pt":1646219857300,"mc":[{"id":"1.195453627","rc":[{"atb":[[1.01,3.99]],"id":40324291}],"con":true,"img":false}]}
{"op":"mcm","clk":"5348686812","pt":1646219857512,"mc":[{"id":"1.195453627","rc":[{"atb":[[1.01,2]],"id":40324291}],"con":true,"img":false}]}
{"op":"mcm","clk":"5348686821","pt":1646219857610,"mc":[{"id":"1.195453627","rc":[{"atb":[[1.02,1.99]],"id":40324291}],"con":true,"img":false}]}
{"op":"mcm","clk":"5348686844","pt":1646219857816,"mc":[{"id":"1.195453627","rc":[{"atb":[[1.78,4]],"id":38214982}],"con":true,"img":false}]}
{"op":"mcm","clk":"5348686874","pt":1646219858131,"mc":[{"id":"1.195453627","rc":[{"atb":[[2.3,7.8]],"id":38761677}],"con":true,"img":false}]}
{"op":"mcm","clk":"5348686906","pt":1646219858396,"mc":[{"id":"1.195453627","rc":[{"atb":[[1.01,2]],"id":41818958}],"con":true,"img":false}]}
{"op":"mcm","clk":"5348686919","pt":1646219858503,"mc":[{"id":"1.195453627","rc":[{"atb":[[1.01,3.99]],"id":41818958}],"con":true,"img":false}]}
{"op":"mcm","clk":"5348686941","pt":1646219858708,"mc":[{"id":"1.195453627","rc":[{"atb":[[1.01,2]],"id":41818958}],"con":true,"img":false}]}
{"op":"mcm","clk":"5348686959","pt":1646219858818,"mc":[{"id":"1.195453627","rc":[{"atb":[[1.02,1.99]],"id":41818958}],"con":true,"img":false}]}
{"op":"mcm","clk":"5348687077","pt":1646219859713,"mc":[{"id":"1.195453627","rc":[{"atb":[[1.01,2]],"id":38214982}],"con":true,"img":false}]}
{"op":"mcm","clk":"5348687105","pt":1646219859924,"mc":[{"id":"1.195453627","rc":[{"atb":[[1.01,3.99]],"id":38214982}],"con":true,"img":false}]}
{"op":"mcm","clk":"5348687134","pt":1646219860141,"mc":[{"id":"1.195453627","rc":[{"atb":[[1.01,2]],"id":38214982}],"con":true,"img":false}]}
{"op":"mcm","clk":"5348687152","pt":1646219860232,"mc":[{"id":"1.195453627","rc":[{"atb":[[1.02,1.99]],"id":38214982}],"con":true,"img":false}]}
{"op":"mcm","clk":"5348688015","pt":1646219867320,"mc":[{"id":"1.195453627","rc":[{"atl":[[15.5,12.07],[16.5,0]],"id":40324291}],"con":true,"img":false}]}
{"op":"mcm","clk":"5348689298","pt":1646219877328,"mc":[{"id":"1.195453627","rc":[{"atb":[[3,0]],"id":39734233},{"spn":4.45,"spf":"NaN","id":39734233},{"spn":5.38,"spf":1.0,"id":40324291}],"con":true,"img":false}]}
{"op":"mcm","clk":"5348689312","pt":1646219877431,"mc":[{"id":"1.195453627","rc":[{"atb":[[3.1,32.81]],"id":39734233}],"con":true,"img":false}]}
{"op":"mcm","clk":"5348689576","pt":1646219879585,"mc":[{"id":"1.195453627","rc":[{"atb":[[3.35,0],[2.64,0],[2.84,0],[2.94,0],[2.74,0]],"id":39734233},{"atl":[[12,0],[14.5,0],[9.8,0],[8.8,0]],"id":39734233},{"atb":[[2.98,0],[3.45,0],[3.2,0],[2.88,0],[3.95,25.42]],"id":41818958},{"atl":[[13.5,0],[16,0],[18.5,2],[22,2.38]],"id":41818958},{"atb":[[3,0],[3.25,0],[3.5,0],[3.75,0],[4.5,0]],"id":38214982},{"atl":[[16,0],[18.5,0],[22,0],[27,0]],"id":38214982},{"atb":[[4.8,39.48],[4.3,0],[5.8,0],[5.3,0],[7.6,0]],"id":27868829},{"atl":[[36,0],[46,0],[65,0],[90,0]],"id":27868829},{"atb":[[1.83,0],[1.98,0],[1.93,0],[1.88,0],[2.16,28.62]],"id":38761677},{"atl":[[6.8,0],[7.8,0],[5.9,0],[5.4,0]],"id":38761677},{"atb":[[3.25,0],[3.5,0],[3.75,0],[4,0],[5,0]],"id":40324291},{"atl":[[17,0],[19.5,0],[24,0],[29,0]],"id":40324291}],"con":true,"img":false}]}
{"op":"mcm","clk":"5348689592","pt":1646219879748,"mc":[{"id":"1.195453627","rc":[{"atb":[[2.98,2]],"id":38214982}],"con":true,"img":false}]}
{"op":"mcm","clk":"5348689605","pt":1646219879848,"mc":[{"id":"1.195453627","rc":[{"atl":[[8.6,0]],"id":39734233},{"atl":[[13,0],[16,16.49]],"id":41818958},{"atl":[[15.5,0]],"id":38214982},{"atl":[[60,0]],"id":27868829}],"con":true,"img":false}]}
{"op":"mcm","clk":"5348689620","pt":1646219879970,"mc":[{"id":"1.195453627","rc":[{"atl":[[9.6,14.8]],"id":39734233},{"atl":[[16.5,11.43]],"id":38214982},{"atl":[[75,3.8]],"id":27868829}],"con":true,"img":false}]}
{"op":"mcm","clk":"5348689847","pt":1646219881576,"mc":[{"id":"1.195453627","rc":[{"atb":[[1.02,6.28]],"id":39734233},{"atb":[[1.03,2.88]],"id":41818958},{"atb":[[1.02,3.16]],"id":38761677},{"atb":[[1.02,4.93]],"id":40324291}],"con":true,"img":false}]}
{"op":"mcm","clk":"5348689899","pt":1646219881951,"mc":[{"id":"1.195453627","rc":[{"atb":[[1.02,3.56]],"id":39734233},{"atb":[[1.03,0.16]],"id":41818958},{"atb":[[1.02,0.44]],"id":38761677},{"atb":[[1.02,2.2]],"id":40324291}],"con":true,"img":false}]}
{"op":"mcm","clk":"5348689976","pt":1646219882469,"mc":[{"id":"1.195453627","rc":[{"atb":[[1.02,3.29]],"id":39734233},{"atb":[[1.03,0]],"id":41818958},{"atb":[[1.02,0]],"id":38761677},{"atb":[[1.02,1.99]],"id":40324291}],"con":true,"img":false}]}
{"op":"mcm","clk":"5348689989","pt":1646219882571,"mc":[{"id":"1.195453627","rc":[{"atb":[[4,2.26]],"id":39734233},{"atb":[[6.6,2.66]],"id":41818958},{"atb":[[2.42,1.15]],"id":38761677},{"atb":[[4.9,0.21]],"id":40324291}],"con":true,"img":false}]}
{"op":"mcm","clk":"5348690086","pt":1646219883276,"mc":[{"id":"1.195453627","rc":[{"atb":[[3.35,17.82],[2.64,102.19],[2.84,45.54],[2.94,21.59],[2.74,48.15]],"id":39734233},{"atl":[[12,17.88],[14.5,14.57],[9.8,14.9],[8.8,16.81]],"id":39734233},{"atb":[[2.98,42.32],[3.45,17.1],[3.2,38.09],[2.88,89.14],[3.95,39.62]],"id":41818958},{"atl":[[13.5,10.49],[16,25.23],[18.5,13.24],[22,11.74]],"id":41818958},{"atb":[[3,73.57],[3.25,32.7],[3.5,29.43],[3.75,13.38],[4.5,10.51]],"id":38214982},{"atl":[[16,9.42],[18.5,8.07],[22,10.09],[27,8.15]],"id":38214982},{"atb":[[4.8,61.53],[4.3,50.78],[5.8,8.73],[5.3,19.48],[7.6,6.34]],"id":27868829},{"atl":[[36,3.74],[46,2.91],[65,3.07],[90,2.21]],"id":27868829},{"atb":[[1.83,201.91],[1.98,42.75],[1.93,90.1],[1.88,95.22],[2.16,64.74]],"id":38761677},{"atl":[[6.8,33.92],[7.8,28.92],[5.9,26.76],[5.4,29.8]],"id":38761677},{"atb":[[3.25,74.48],[3.5,33.51],[3.75,30.47],[4,13.96],[5,10.47]],"id":40324291},{"atl":[[17,8.19],[19.5,7.09],[24,8.55],[29,7.02]],"id":40324291}],"con":true,"img":false}]}
{"op":"mcm","clk":"5348690248","pt":1646219884472,"mc":[{"id":"1.195453627","rc":[{"atb":[[2.38,0]],"id":38761677}],"con":true,"img":false}]}
{"op":"mcm","clk":"5348690261","pt":1646219884575,"mc":[{"id":"1.195453627","rc":[{"atb":[[2.42,3.14]],"id":38761677}],"con":true,"img":false}]}
{"op":"mcm","clk":"5348690566","pt":1646219886673,"mc":[{"id":"1.195453627","rc":[{"atb":[[2.3,0]],"id":38761677}],"con":true,"img":false}]}
{"op":"mcm","clk":"5348691001","pt":1646219889756,"mc":[{"id":"1.195453627","rc":[{"atb":[[2.3,7.86]],"id":38761677}],"con":true,"img":false}]}
{"op":"mcm","clk":"5348693979","pt":1646219913328,"mc":[{"id":"1.195453627","rc":[{"atl":[[16.5,0]],"id":38214982}],"con":true,"img":false}]}
{"op":"mcm","clk":"5348693993","pt":1646219913432,"mc":[{"id":"1.195453627","rc":[{"atl":[[15.5,11.43]],"id":38214982}],"con":true,"img":false}]}
{"op":"mcm","clk":"5348694124","pt":1646219914359,"mc":[{"id":"1.195453627","rc":[{"atl":[[9.6,0]],"id":39734233},{"atl":[[75,0]],"id":27868829}],"con":true,"img":false}]}
{"op":"mcm","clk":"5348694129","pt":1646219914429,"mc":[{"id":"1.195453627","rc":[{"atl":[[8.6,14.8]],"id":39734233},{"atl":[[60,3.8]],"id":27868829}],"con":true,"img":false}]}
{"op":"mcm","clk":"5348694247","pt":1646219915323,"mc":[{"id":"1.195453627","rc":[{"atl":[[16,8.74]],"id":41818958}],"con":true,"img":false}]}
{"op":"mcm","clk":"5348694265","pt":1646219915427,"mc":[{"id":"1.195453627","rc":[{"atl":[[13,16.49]],"id":41818958}],"con":true,"img":false}]}
{"op":"mcm","clk":"5348694756","pt":1646219919438,"mc":[{"id":"1.195453627","rc":[{"atb":[[1.02,3.65]],"id":41818958},{"atb":[[1.02,1.66]],"id":27868829},{"atb":[[1.02,3.65]],"id":40324291}],"con":true,"img":false}]}
{"op":"mcm","clk":"5348694787","pt":1646219919605,"mc":[{"id":"1.195453627","rc":[{"atb":[[1.02,3.18]],"id":41818958},{"atb":[[1.02,0.47]],"id":27868829},{"atb":[[1.02,3.21]],"id":40324291}],"con":true,"img":false}]}
{"op":"mcm","clk":"5348694827","pt":1646219920023,"mc":[{"id":"1.195453627","rc":[{"atb":[[1.02,1.99]],"id":40324291}],"con":true,"img":false}]}
{"op":"mcm","clk":"5348694835","pt":1646219920133,"mc":[{"id":"1.195453627","rc":[{"atb":[[6.8,1.22]],"id":40324291}],"con":true,"img":false}]}
{"op":"mcm","clk":"5348694846","pt":1646219920234,"mc":[{"id":"1.195453627","rc":[{"atb":[[1.02,0]],"id":27868829}],"con":true,"img":false}]}
{"op":"mcm","clk":"5348694862","pt":1646219920346,"mc":[{"id":"1.195453627","rc":[{"atb":[[17.5,0.47]],"id":27868829}],"con":true,"img":false}]}
{"op":"mcm","clk":"5348694887","pt":1646219920548,"mc":[{"id":"1.195453627","rc":[{"atb":[[1.02,1.99]],"id":41818958}],"con":true,"img":false}]}
{"op":"mcm","clk":"5348694903","pt":1646219920646,"mc":[{"id":"1.195453627","rc":[{"atb":[[7,1.19]],"id":41818958}],"con":true,"img":false}]}
{"op":"mcm","clk":"5348694934","pt":1646219920854,"mc":[{"id":"1.195453627","rc":[{"atb":[[1.02,3.65],[7,0]],"id":41818958},{"atb":[[6.8,0],[1.02,3.65]],"id":40324291}],"con":true,"img":false}]}
{"op":"mcm","clk":"5348694957","pt":1646219921025,"mc":[{"id":"1.195453627","rc":[{"atb":[[1.02,3.18]],"id":41818958},{"atb":[[1.02,3.21]],"id":40324291}],"con":true,"img":false}]}
{"op":"mcm","clk":"5348694985","pt":1646219921228,"mc":[{"id":"1.195453627","rc":[{"atb":[[1.02,1.99]],"id":40324291}],"con":true,"img":false}]}
{"op":"mcm","clk":"5348694994","pt":1646219921340,"mc":[{"id":"1.195453627","rc":[{"atb":[[5.8,1.53]],"id":40324291}],"con":true,"img":false}]}
{"op":"mcm","clk":"5348695015","pt":1646219921451,"mc":[{"id":"1.195453627","rc":[{"atb":[[1.02,1.99]],"id":41818958},{"atb":[[7,2.49]],"id":40324291}],"con":true,"img":false}]}
{"op":"mcm","clk":"5348695027","pt":1646219921536,"mc":[{"id":"1.195453627","rc":[{"atb":[[6.8,1.99],[6.6,0.16]],"id":41818958}],"con":true,"img":false}]}
{"op":"mcm","clk":"5348695356","pt":1646219923964,"mc":[{"id":"1.195453627","rc":[{"atb":[[7,2.49]],"id":41818958}],"con":true,"img":false}]}
{"op":"mcm","clk":"5348695416","pt":1646219924427,"mc":[{"id":"1.195453627","rc":[{"atb":[[6.8,0.8],[1.02,3.65]],"id":41818958}],"con":true,"img":false}]}
{"op":"mcm","clk":"5348695607","pt":1646219925747,"mc":[{"id":"1.195453627","rc":[{"atb":[[1.02,3.14]],"id":41818958}],"con":true,"img":false}]}
{"op":"mcm","clk":"5348695650","pt":1646219925967,"mc":[{"id":"1.195453627","rc":[{"atb":[[1.02,1.99]],"id":41818958}],"con":true,"img":false}]}
{"op":"mcm","clk":"5348695661","pt":1646219926049,"mc":[{"id":"1.195453627","rc":[{"atb":[[7.2,1.15]],"id":41818958}],"con":true,"img":false}]}
{"op":"mcm","clk":"5348695779","pt":1646219926851,"mc":[{"id":"1.195453627","rc":[{"atb":[[7,0]],"id":41818958}],"con":true,"img":false}]}
{"op":"mcm","clk":"5348696126","pt":1646219929464,"mc":[{"id":"1.195453627","rc":[{"atb":[[7.4,2.49]],"id":41818958}],"con":true,"img":false}]}
{"op":"mcm","clk":"5348696248","pt":1646219930446,"mc":[{"id":"1.195453627","rc":[{"atb":[[2.42,1.15]],"id":38761677}],"con":true,"img":false}]}
{"op":"mcm","clk":"5348696263","pt":1646219930558,"mc":[{"id":"1.195453627","rc":[{"atb":[[1.02,1.99]],"id":38761677}],"con":true,"img":false}]}
{"op":"mcm","clk":"5348696325","pt":1646219931028,"mc":[{"id":"1.195453627","rc":[{"atb":[[2.3,0]],"id":38761677}],"con":true,"img":false}]}
