{"op":"mcm","clk":"5305619419","pt":1646080581421,"mc":[{"id":"1.195395425","marketDefinition":{"bspMarket":true,"turnInPlayEnabled":false,"persistenceEnabled":false,"marketBaseRate":7.0,"eventId":"31270458","eventTypeId":"4339","numberOfWinners":1,"bettingType":"ODDS","marketType":"WIN","marketTime":"2022-03-01T02:54:00.000Z","suspendTime":"2022-03-01T02:54:00.000Z","bspReconciled":false,"complete":true,"inPlay":false,"crossMatching":false,"runnersVoidable":false,"numberOfActiveRunners":7,"betDelay":0,"status":"OPEN","runners":[{"status":"ACTIVE","sortPriority":1,"id":43154454,"name":"1. Buckle Up Iveta"},{"status":"ACTIVE","sortPriority":2,"id":38859241,"name":"2. Theo Dragonet"},{"status":"ACTIVE","sortPriority":3,"id":39318320,"name":"3. Engage The Rage"},{"status":"ACTIVE","sortPriority":4,"id":42189480,"name":"4. Toxic Turtle"},{"status":"ACTIVE","sortPriority":5,"id":36104892,"name":"5. Bridwood Ali"},{"status":"ACTIVE","sortPriority":6,"id":38256919,"name":"6. Warramunga"},{"status":"ACTIVE","sortPriority":7,"id":43154455,"name":"8. Strait Sambuca"}],"regulators":["MR_INT"],"venue":"Devonport","countryCode":"AU","discountAllowed":true,"timezone":"Australia/Sydney","openDate":"2022-03-01T02:00:00.000Z","version":4380714790,"name":"R4 452m Gr5","eventName":"Devonport (AUS) 1st Mar"},"rc":[],"con":true,"img":false}]}
{"op":"mcm","clk":"5305743109","pt":1646082027013,"mc":[{"id":"1.195395425","rc":[{"atb":[[4,33.83],[3.5,40.59],[3.75,36.9],[4.7,27.43]],"id":36104892},{"atl":[[16,8.81],[18.5,7.55],[22,9.44],[27,7.62]],"id":36104892},{"spn":10.35,"spf":"NaN","id":36104892},{"atb":[[12,9.22],[9.8,11.53],[8.8,13.01],[15.5,6.99]],"id":38859241},{"atl":[[270,0.73],[170,0.77],[220,0.9],[120,1.1]],"id":38859241},{"spn":67.75,"spf":"NaN","id":38859241},{"atb":[[1.72,140.96],[1.6,169.15],[1.55,184.53],[1.65,156.14]],"id":43154454},{"atl":[[3.45,53.95],[3.2,60.08],[3.95,67.21],[3.7,73.43]],"id":43154454},{"spn":2.46,"spf":"NaN","id":43154454},{"atb":[[11,10.14],[14.5,7.51],[8.4,13.71],[9.4,12.08]],"id":43154455},{"atl":[[260,0.76],[160,0.83],[210,0.94],[110,1.21]],"id":43154455},{"spn":62.25,"spf":"NaN","id":43154455},{"atb":[[19,5.64],[10.5,10.68],[13,8.46],[15.5,6.99]],"id":39318320},{"atl":[[150,0.88],[300,0.66],[200,0.66],[250,0.79]],"id":39318320},{"spn":84.5,"spf":"NaN","id":39318320},{"atb":[[36,2.9],[18,5.97],[21,5.07],[26,4.05]],"id":38256919},{"atl":[[300,0.44],[350,0.37],[400,0.49],[450,0.44]],"id":38256919},{"spn":168.0,"spf":"NaN","id":38256919},{"atb":[[2.4,72.49],[2.74,58.33],[2.5,67.66],[2.6,63.43]],"id":42189480},{"atl":[[9.6,23.05],[8.6,26.09],[7.6,20.02],[6.6,23.6]],"id":42189480},{"spn":4.67,"spf":"NaN","id":42189480}],"con":true,"img":false}]}
{"op":"mcm","clk":"5305747392","pt":1646082083712,"mc":[{"id":"1.195395425","rc":[{"atb":[[4,0],[3.5,0],[3.75,0],[4.7,0]],"id":36104892},{"atl":[[16,0],[18.5,0],[22,0],[27,0]],"id":36104892},{"atb":[[12,0],[9.8,0],[8.8,0],[15.5,0]],"id":38859241},{"atl":[[270,0],[170,0],[220,0],[120,0]],"id":38859241},{"atb":[[1.72,0],[1.6,0],[1.55,0],[1.65,0]],"id":43154454},{"atl":[[3.45,0],[3.2,0],[3.95,0],[3.7,0]],"id":43154454},{"atb":[[11,0],[14.5,0],[8.4,0],[9.4,0]],"id":43154455},{"atl":[[260,0],[160,0],[210,0],[110,0]],"id":43154455},{"atb":[[19,0],[10.5,0],[13,0],[15.5,0]],"id":39318320},{"atl":[[150,0],[300,0],[200,0],[250,0]],"id":39318320},{"atb":[[36,0],[18,0],[21,0],[26,0]],"id":38256919},{"atl":[[300,0],[350,0],[400,0],[450,0]],"id":38256919},{"atb":[[2.4,0],[2.74,0],[2.5,0],[2.6,0]],"id":42189480},{"atl":[[9.6,0],[8.6,0],[7.6,0],[6.6,0]],"id":42189480}],"con":true,"img":false}]}
{"op":"mcm","clk":"5305747684","pt":1646082087094,"mc":[{"id":"1.195395425","rc":[{"atb":[[4,33.83],[3.5,40.59],[3.75,36.9],[4.7,27.43]],"id":36104892},{"atl":[[16,8.81],[18.5,7.55],[22,9.44],[27,7.62]],"id":36104892},{"atb":[[12,9.22],[9.8,11.53],[8.8,13.01],[15.5,6.99]],"id":38859241},{"atl":[[270,0.73],[170,0.77],[220,0.9],[120,1.1]],"id":38859241},{"atb":[[1.72,140.96],[1.6,169.15],[1.55,184.53],[1.65,156.14]],"id":43154454},{"atl":[[3.45,53.95],[3.2,60.08],[3.95,67.21],[3.7,73.43]],"id":43154454},{"atb":[[11,10.14],[14.5,7.51],[8.4,13.71],[9.4,12.08]],"id":43154455},{"atl":[[260,0.76],[160,0.83],[210,0.94],[110,1.21]],"id":43154455},{"atb":[[19,5.64],[10.5,10.68],[13,8.46],[15.5,6.99]],"id":39318320},{"atl":[[150,0.88],[300,0.66],[200,0.66],[250,0.79]],"id":39318320},{"atb":[[36,2.9],[18,5.97],[21,5.07],[26,4.05]],"id":38256919},{"atl":[[300,0.44],[350,0.37],[400,0.49],[450,0.44]],"id":38256919},{"atb":[[2.4,72.49],[2.74,58.33],[2.5,67.66],[2.6,63.43]],"id":42189480},{"atl":[[9.6,23.05],[8.6,26.09],[7.6,20.02],[6.6,23.6]],"id":42189480}],"con":true,"img":false}]}
{"op":"mcm","clk":"5305990537","pt":1646086602700,"mc":[{"id":"1.195395425","marketDefinition":{"bspMarket":true,"turnInPlayEnabled":false,"persistenceEnabled":false,"marketBaseRate":7.0,"eventId":"31270458","eventTypeId":"4339","numberOfWinners":1,"bettingType":"ODDS","marketType":"WIN","marketTime":"2022-03-01T02:54:00.000Z","suspendTime":"2022-03-01T02:54:00.000Z","bspReconciled":false,"complete":true,"inPlay":false,"crossMatching":false,"runnersVoidable":false,"numberOfActiveRunners":7,"betDelay":0,"status":"OPEN","runners":[{"status":"ACTIVE","sortPriority":1,"id":43154454,"name":"1. Buckle Up Iveta"},{"status":"ACTIVE","sortPriority":2,"id":38859241,"name":"2. Theo Dragonet"},{"status":"ACTIVE","sortPriority":3,"id":39318320,"name":"3. Engage The Rage"},{"status":"ACTIVE","sortPriority":4,"id":42189480,"name":"4. Toxic Turtle"},{"status":"ACTIVE","sortPriority":5,"id":36104892,"name":"5. Bridwood Ali"},{"status":"ACTIVE","sortPriority":6,"id":38256919,"name":"6. Warramunga"},{"status":"ACTIVE","sortPriority":7,"id":43154455,"name":"8. Strait Sambuca"}],"regulators":["MR_INT"],"venue":"Devonport","countryCode":"AU","discountAllowed":true,"timezone":"Australia/Sydney","openDate":"2022-03-01T02:00:00.000Z","version":4380714790,"name":"R4 452m Gr5","eventName":"Devonport (AUS) 1st Mar"},"rc":[{"atb":[[4,33.82],[3.5,40.59],[3.75,36.89],[4.7,27.42]],"id":36104892},{"atl":[[16,8.81],[18.5,7.54],[22,9.43],[27,7.62]],"id":36104892},{"spn":10.35,"spf":"NaN","id":36104892},{"atb":[[12,9.22],[9.8,11.53],[8.8,13.01],[15.5,6.99]],"id":38859241},{"atl":[[270,0.73],[170,0.77],[220,0.9],[120,1.1]],"id":38859241},{"spn":67.75,"spf":"NaN","id":38859241},{"atb":[[1.72,140.94],[1.6,169.12],[1.55,184.5],[1.65,156.11]],"id":43154454},{"atl":[[3.45,53.94],[3.2,60.07],[3.95,67.2],[3.7,73.42]],"id":43154454},{"spn":2.46,"spf":"NaN","id":43154454},{"atb":[[11,10.14],[14.5,7.51],[8.4,13.71],[9.4,12.07]],"id":43154455},{"atl":[[260,0.76],[160,0.83],[210,0.94],[110,1.21]],"id":43154455},{"spn":62.25,"spf":"NaN","id":43154455},{"atb":[[19,5.63],[10.5,10.68],[13,8.45],[15.5,6.99]],"id":39318320},{"atl":[[150,0.88],[300,0.66],[200,0.66],[250,0.79]],"id":39318320},{"spn":84.5,"spf":"NaN","id":39318320},{"atb":[[36,2.9],[18,5.96],[21,5.07],[26,4.05]],"id":38256919},{"atl":[[300,0.44],[350,0.37],[400,0.49],[450,0.44]],"id":38256919},{"spn":168.0,"spf":"NaN","id":38256919},{"atb":[[2.4,72.48],[2.74,58.32],[2.5,67.65],[2.6,63.42]],"id":42189480},{"atl":[[9.6,23.05],[8.6,26.08],[7.6,20.02],[6.6,23.6]],"id":42189480},{"spn":4.67,"spf":"NaN","id":42189480}],"con":true,"img":true}]}
{"op":"mcm","clk":"5306079975","pt":1646088802450,"mc":[{"id":"1.195395425","rc":[{"atb":[[4,0],[3.5,0],[3.75,0],[4.7,0]],"id":36104892},{"atl":[[16,0],[18.5,0],[22,0],[27,0]],"id":36104892},{"spn":"NaN","spf":"NaN","id":36104892},{"atb":[[12,0],[9.8,0],[8.8,0],[15.5,0]],"id":38859241},{"atl":[[270,0],[170,0],[220,0],[120,0]],"id":38859241},{"spn":"NaN","spf":"NaN","id":38859241},{"atb":[[1.72,140.94],[1.6,169.12],[1.55,184.5],[1.65,156.11]],"id":43154454},{"atl":[[3.45,53.94],[3.2,60.07],[3.95,67.2],[3.7,73.42]],"id":43154454},{"atb":[[11,0],[14.5,0],[8.4,0],[9.4,0]],"id":43154455},{"atl":[[260,0],[160,0],[210,0],[110,0]],"id":43154455},{"spn":"NaN","spf":"NaN","id":43154455},{"atb":[[19,0],[10.5,0],[13,0],[15.5,0]],"id":39318320},{"atl":[[150,0],[300,0],[200,0],[250,0]],"id":39318320},{"spn":"NaN","spf":"NaN","id":39318320},{"atb":[[36,2.9],[18,5.96],[21,5.07],[26,4.05]],"id":38256919},{"atb":[[2.4,0],[2.74,0],[2.5,0],[2.6,0]],"id":42189480},{"atl":[[9.6,0],[8.6,0],[7.6,0],[6.6,0]],"id":42189480},{"spn":"NaN","spf":"NaN","id":42189480}],"con":true,"img":false}]}
{"op":"mcm","clk":"5306080184","pt":1646088808513,"mc":[{"id":"1.195395425","rc":[{"atb":[[4.5,28.99],[3.4,42.28],[3.9,34.99],[3.65,38.29]],"id":36104892},{"atl":[[18,7.77],[21,9.9],[26,7.92],[15.5,9.11]],"id":36104892},{"atb":[[9.6,11.79],[17.5,6.14],[11.5,9.66],[14,7.8]],"id":38859241},{"atl":[[140,0.95],[290,0.68],[190,0.69],[240,0.82]],"id":38859241},{"atb":[[12,9.22],[9.8,11.53],[8.8,13.01],[15.5,6.99]],"id":43154455},{"atl":[[270,0.73],[170,0.77],[220,0.9],[120,1.1]],"id":43154455},{"atb":[[16.5,6.54],[20,5.34],[11.5,9.66],[14,7.8]],"id":39318320},{"atl":[[260,0.76],[310,0.64],[160,0.83],[210,0.63]],"id":39318320},{"atb":[[2.4,72.48],[2.74,58.32],[2.5,67.65],[2.6,63.42]],"id":42189480},{"atl":[[9.6,23.05],[8.6,26.08],[7.6,20.02],[6.6,23.6]],"id":42189480}],"con":true,"img":false}]}
{"op":"mcm","clk":"5306083562","pt":1646088893632,"mc":[{"id":"1.195395425","rc":[{"spn":10.0,"spf":"NaN","id":36104892},{"atb":[[9.6,0],[17.5,0],[11.5,0],[14,0]],"id":38859241},{"atl":[[140,0],[290,0],[190,0],[240,0]],"id":38859241},{"atb":[[12,0],[9.8,0],[8.8,0],[15.5,0]],"id":43154455},{"atl":[[270,0],[170,0],[220,0],[120,0]],"id":43154455},{"spn":90.0,"spf":"NaN","id":39318320},{"atb":[[36,0],[18,0],[21,0],[26,0]],"id":38256919},{"atl":[[300,0],[350,0],[400,0],[450,0]],"id":38256919},{"spn":"NaN","spf":"NaN","id":38256919},{"spn":4.67,"spf":"NaN","id":42189480}],"con":true,"img":false}]}
{"op":"mcm","clk":"5306083952","pt":1646088902638,"mc":[{"id":"1.195395425","rc":[{"atb":[[4.8,26.7],[5.8,21.13],[5.3,23.59],[7,16.91]],"id":38859241},{"atl":[[38,5.35],[24,5.74],[48,4.21],[29,4.71]],"id":38859241},{"atb":[[12,9.22],[9.8,11.53],[8.8,13.01],[15.5,6.99]],"id":43154455},{"atl":[[270,0.73],[170,0.77],[220,0.9],[120,1.1]],"id":43154455},{"atb":[[36,2.9],[18,5.96],[21,5.07],[26,4.05]],"id":38256919},{"atl":[[300,0.44],[350,0.37],[400,0.49],[450,0.44]],"id":38256919}],"con":true,"img":false}]}
{"op":"mcm","clk":"5306108652","pt":1646089575616,"mc":[{"id":"1.195395425","rc":[{"spl":[[100,2]],"id":36104892},{"spn":10.0,"spf":1.0,"id":36104892},{"spl":[[100,2]],"id":38859241},{"spn":15.5,"spf":1.0,"id":38859241},{"spl":[[100,2]],"id":43154454},{"spn":2.46,"spf":1.0,"id":43154454},{"spl":[[100,2]],"id":43154455},{"spn":57.75,"spf":1.0,"id":43154455},{"spl":[[100,2]],"id":39318320},{"spn":60.0,"spf":1.0,"id":39318320},{"spl":[[100,2]],"id":38256919},{"spn":68.0,"spf":1.0,"id":38256919},{"spl":[[100,2]],"id":42189480},{"spn":4.67,"spf":1.0,"id":42189480}],"con":true,"img":false}]}
{"op":"mcm","clk":"5306161822","pt":1646091262073,"mc":[{"id":"1.195395425","rc":[{"atb":[[4.5,0],[3.4,0],[3.9,0],[3.65,0]],"id":36104892},{"atl":[[18,0],[21,0],[26,0],[15.5,0]],"id":36104892},{"spn":1.0,"spf":1.0,"id":36104892},{"atb":[[4.8,0],[5.8,0],[5.3,0],[7,0]],"id":38859241},{"atl":[[38,0],[24,0],[48,0],[29,0]],"id":38859241},{"spn":1.0,"spf":1.0,"id":38859241},{"atb":[[1.72,0],[1.6,0],[1.55,0],[1.65,0]],"id":43154454},{"atl":[[3.45,0],[3.2,0],[3.95,0],[3.7,0]],"id":43154454},{"spn":1.0,"spf":1.0,"id":43154454},{"atb":[[12,0],[9.8,0],[8.8,0],[15.5,0]],"id":43154455},{"atl":[[270,0],[170,0],[220,0],[120,0]],"id":43154455},{"spn":1.0,"spf":1.0,"id":43154455},{"atb":[[36,0],[18,0],[21,0],[26,0]],"id":38256919},{"atl":[[300,0],[350,0],[400,0],[450,0]],"id":38256919},{"spn":1.0,"spf":1.0,"id":38256919},{"atb":[[2.4,0],[2.74,0],[2.5,0],[2.6,0]],"id":42189480},{"atl":[[9.6,0],[8.6,0],[7.6,0],[6.6,0]],"id":42189480},{"spn":1.0,"spf":1.0,"id":42189480}],"con":true,"img":false}]}
{"op":"mcm","clk":"5306162001","pt":1646091266482,"mc":[{"id":"1.195395425","rc":[{"atb":[[4,33.82],[3.5,40.59],[3.75,36.89],[4.7,27.42]],"id":36104892},{"atl":[[16,8.81],[18.5,7.54],[22,9.43],[27,7.62]],"id":36104892},{"atb":[[8,14.49],[6,20.29],[7,16.91],[9.4,12.07]],"id":38859241},{"atl":[[75,1.78],[150,1.33],[50,2.69],[100,2]],"id":38859241},{"atb":[[1.6,169.12],[1.7,144.96],[1.77,131.79],[1.65,156.11]],"id":43154454},{"atl":[[4,66.08],[4.5,56.64],[3.5,52.86],[3.75,48.05]],"id":43154454},{"atb":[[16.5,6.54],[9.2,12.37],[10.5,10.68],[13,8.45]],"id":43154455},{"atl":[[130,1.02],[280,0.7],[180,0.73],[230,0.86]],"id":43154455},{"atb":[[32,3.27],[21,5.07],[46,2.25],[26,4.05]],"id":38256919},{"atl":[[350,0.37],[400,0.33],[450,0.44],[500,0.39]],"id":38256919},{"atb":[[2.5,67.65],[2.6,63.42],[2.84,55.14],[2.7,59.69]],"id":42189480},{"atl":[[7.2,21.31],[9.2,24.17],[10.5,20.86],[8.2,18.35]],"id":42189480}],"con":true,"img":false}]}
{"op":"mcm","clk":"5306165600","pt":1646091353676,"mc":[{"id":"1.195395425","rc":[{"spn":10.35,"spf":1.0,"id":36104892},{"spn":29.7,"spf":1.0,"id":38859241},{"atb":[[1.6,0],[1.7,0],[1.77,0],[1.65,0]],"id":43154454},{"atl":[[4,0],[4.5,0],[3.5,0],[3.75,0]],"id":43154454},{"spn":58.25,"spf":1.0,"id":43154455},{"atb":[[32,0],[21,0],[46,0],[26,0]],"id":38256919},{"atl":[[350,0],[400,0],[450,0],[500,0]],"id":38256919},{"spn":5.02,"spf":1.0,"id":42189480}],"con":true,"img":false}]}
{"op":"mcm","clk":"5306165874","pt":1646091361214,"mc":[{"id":"1.195395425","rc":[{"atb":[[1.6,169.12],[1.7,144.96],[1.77,131.79],[1.65,156.11]],"id":43154454},{"atl":[[4,66.08],[4.5,56.64],[3.5,52.86],[3.75,48.05]],"id":43154454},{"atb":[[32,3.27],[21,5.07],[46,2.25],[26,4.05]],"id":38256919},{"atl":[[350,0.37],[400,0.33],[450,0.44],[500,0.39]],"id":38256919}],"con":true,"img":false}]}
{"op":"mcm","clk":"5306196793","pt":1646092002686,"mc":[{"id":"1.195395425","marketDefinition":{"bspMarket":true,"turnInPlayEnabled":false,"persistenceEnabled":false,"marketBaseRate":7.0,"eventId":"31270458","eventTypeId":"4339","numberOfWinners":1,"bettingType":"ODDS","marketType":"WIN","marketTime":"2022-03-01T02:54:00.000Z","suspendTime":"2022-03-01T02:54:00.000Z","bspReconciled":false,"complete":true,"inPlay":false,"crossMatching":false,"runnersVoidable":false,"numberOfActiveRunners":7,"betDelay":0,"status":"OPEN","runners":[{"status":"ACTIVE","sortPriority":1,"id":43154454,"name":"1. Buckle Up Iveta"},{"status":"ACTIVE","sortPriority":2,"id":38859241,"name":"2. Theo Dragonet"},{"status":"ACTIVE","sortPriority":3,"id":39318320,"name":"3. Engage The Rage"},{"status":"ACTIVE","sortPriority":4,"id":42189480,"name":"4. Toxic Turtle"},{"status":"ACTIVE","sortPriority":5,"id":36104892,"name":"5. Bridwood Ali"},{"status":"ACTIVE","sortPriority":6,"id":38256919,"name":"6. Warramunga"},{"status":"ACTIVE","sortPriority":7,"id":43154455,"name":"8. Strait Sambuca"}],"regulators":["MR_INT"],"venue":"Devonport","countryCode":"AU","discountAllowed":true,"timezone":"Australia/Sydney","openDate":"2022-03-01T02:00:00.000Z","version":4380714790,"name":"R4 452m Gr5","eventName":"Devonport (AUS) 1st Mar"},"rc":[{"atb":[[4,33.82],[3.5,40.59],[3.75,36.89],[4.7,27.42]],"id":36104892},{"spl":[[100,2]],"id":36104892},{"atl":[[16,8.81],[18.5,7.54],[22,9.43],[27,7.62]],"id":36104892},{"spn":10.35,"spf":1.0,"id":36104892},{"atb":[[8,14.49],[6,20.29],[7,16.91],[9.4,12.07]],"id":38859241},{"spl":[[100,2]],"id":38859241},{"atl":[[75,1.78],[150,1.33],[50,2.69],[100,2]],"id":38859241},{"spn":29.7,"spf":1.0,"id":38859241},{"atb":[[1.6,169.12],[1.7,144.96],[1.77,131.79],[1.65,156.11]],"id":43154454},{"spl":[[100,2]],"id":43154454},{"atl":[[4,66.08],[4.5,56.64],[3.5,52.86],[3.75,48.05]],"id":43154454},{"spn":2.63,"spf":1.0,"id":43154454},{"atb":[[16.5,6.54],[9.2,12.37],[10.5,10.68],[13,8.45]],"id":43154455},{"spl":[[100,2]],"id":43154455},{"atl":[[130,1.02],[280,0.7],[180,0.73],[230,0.86]],"id":43154455},{"spn":58.25,"spf":1.0,"id":43154455},{"atb":[[16.5,6.54],[20,5.34],[11.5,9.66],[14,7.8]],"id":39318320},{"spl":[[100,2]],"id":39318320},{"atl":[[260,0.76],[310,0.64],[160,0.83],[210,0.63]],"id":39318320},{"spn":60.0,"spf":1.0,"id":39318320},{"atb":[[32,3.27],[21,5.07],[46,2.25],[26,4.05]],"id":38256919},{"spl":[[100,2]],"id":38256919},{"atl":[[350,0.37],[400,0.33],[450,0.44],[500,0.39]],"id":38256919},{"spn":73.0,"spf":1.0,"id":38256919},{"atb":[[2.5,67.65],[2.6,63.42],[2.84,55.14],[2.7,59.69]],"id":42189480},{"spl":[[100,2]],"id":42189480},{"atl":[[7.2,21.31],[9.2,24.17],[10.5,20.86],[8.2,18.35]],"id":42189480},{"spn":5.02,"spf":1.0,"id":42189480}],"con":true,"img":true}]}
{"op":"mcm","clk":"5306280775","pt":1646094293767,"mc":[{"id":"1.195395425","rc":[{"atb":[[4,0],[3.5,0],[3.75,0],[4.7,0]],"id":36104892},{"atl":[[16,0],[18.5,0],[22,0],[27,0]],"id":36104892},{"spn":1.0,"spf":1.0,"id":36104892},{"atb":[[8,0],[6,0],[7,0],[9.4,0]],"id":38859241},{"atl":[[75,0],[150,0],[50,0],[100,0]],"id":38859241},{"spn":1.0,"spf":1.0,"id":38859241},{"atb":[[1.6,169.01],[1.7,144.87],[1.77,131.7],[1.65,156.01]],"id":43154454},{"atl":[[4,66.03],[4.5,56.6],[3.5,52.83],[3.75,48.02]],"id":43154454},{"spn":2.63,"spf":1.0,"id":43154454},{"atb":[[16.5,6.54],[9.2,12.36],[10.5,10.67],[13,8.45]],"id":43154455},{"atl":[[130,1.02],[280,0.7],[180,0.73],[230,0.86]],"id":43154455},{"atb":[[16.5,0],[20,0],[11.5,0],[14,0]],"id":39318320},{"atl":[[260,0],[310,0],[160,0],[210,0]],"id":39318320},{"spn":1.0,"spf":1.0,"id":39318320},{"atb":[[32,0],[21,0],[46,0],[26,0]],"id":38256919},{"atl":[[350,0],[400,0],[450,0],[500,0]],"id":38256919},{"atb":[[2.5,0],[2.6,0],[2.84,0],[2.7,0]],"id":42189480},{"atl":[[7.2,0],[9.2,0],[10.5,0],[8.2,0]],"id":42189480},{"spn":1.0,"spf":1.0,"id":42189480}],"con":true,"img":false}]}
{"op":"mcm","clk":"5306280958","pt":1646094301361,"mc":[{"id":"1.195395425","rc":[{"atb":[[4.5,28.97],[3.4,42.25],[3.9,34.97],[3.65,38.26]],"id":36104892},{"atl":[[18,7.76],[21,9.9],[26,7.92],[15.5,9.1]],"id":36104892},{"atb":[[8,14.48],[6,20.28],[7,16.9],[9.4,12.07]],"id":38859241},{"atl":[[75,1.78],[150,1.33],[50,2.69],[100,2]],"id":38859241},{"atb":[[18,5.96],[23,4.6],[13,8.45],[15.5,6.99]],"id":39318320},{"atl":[[300,0.66],[350,0.56],[200,0.66],[250,0.53]],"id":39318320},{"atb":[[32,3.27],[21,5.07],[46,2.25],[26,4.05]],"id":38256919},{"atl":[[350,0.37],[400,0.32],[450,0.44],[500,0.39]],"id":38256919},{"atb":[[2.5,67.6],[2.6,63.38],[2.84,55.11],[2.7,59.65]],"id":42189480},{"atl":[[7.2,21.3],[9.2,24.16],[10.5,20.85],[8.2,18.34]],"id":42189480}],"con":true,"img":false}]}
{"op":"mcm","clk":"5306283664","pt":1646094387020,"mc":[{"id":"1.195395425","rc":[{"spn":10.0,"spf":1.0,"id":36104892},{"spn":29.7,"spf":1.0,"id":38859241},{"atb":[[1.8,11.48]],"id":43154454},{"spn":2.65,"spf":1.0,"id":43154454},{"spn":61.5,"spf":1.0,"id":39318320},{"spn":73.0,"spf":1.0,"id":38256919},{"spn":5.02,"spf":1.0,"id":42189480}],"con":true,"img":false}]}
{"op":"mcm","clk":"5306283666","pt":1646094387121,"mc":[{"id":"1.195395425","rc":[{"atb":[[2.88,4.88]],"id":42189480}],"con":true,"img":false}]}
{"op":"mcm","clk":"5306283672","pt":1646094387225,"mc":[{"id":"1.195395425","rc":[{"atb":[[4.6,2.55]],"id":36104892}],"con":true,"img":false}]}
{"op":"mcm","clk":"5306288560","pt":1646094531903,"mc":[{"id":"1.195395425","rc":[{"atb":[[4.6,5.05]],"id":36104892},{"spn":10.05,"spf":1.0,"id":36104892},{"atb":[[1.8,22.75]],"id":43154454},{"atb":[[2.88,9.68]],"id":42189480},{"spn":5.04,"spf":1.0,"id":42189480}],"con":true,"img":false}]}
{"op":"mcm","clk":"5306345787","pt":1646096040171,"mc":[{"id":"1.195395425","rc":[{"atb":[[4.5,30.97]],"id":36104892},{"atb":[[9,1.26]],"id":38859241},{"atb":[[1.76,2]],"id":43154454},{"atb":[[15.5,0.7]],"id":43154455},{"atb":[[22,0.49]],"id":39318320},{"atb":[[38,0.28]],"id":38256919},{"atb":[[2.76,2]],"id":42189480}],"con":true,"img":false}]}
{"op":"mcm","clk":"5306346925","pt":1646096067061,"mc":[{"id":"1.195395425","marketDefinition":{"bspMarket":true,"turnInPlayEnabled":false,"persistenceEnabled":false,"marketBaseRate":7.0,"eventId":"31270458","eventTypeId":"4339","numberOfWinners":1,"bettingType":"ODDS","marketType":"WIN","marketTime":"2022-03-01T02:54:00.000Z","suspendTime":"2022-03-01T02:54:00.000Z","bspReconciled":false,"complete":true,"inPlay":false,"crossMatching":true,"runnersVoidable":false,"numberOfActiveRunners":7,"betDelay":0,"status":"OPEN","runners":[{"status":"ACTIVE","sortPriority":1,"id":43154454,"name":"1. Buckle Up Iveta"},{"status":"ACTIVE","sortPriority":2,"id":38859241,"name":"2. Theo Dragonet"},{"status":"ACTIVE","sortPriority":3,"id":39318320,"name":"3. Engage The Rage"},{"status":"ACTIVE","sortPriority":4,"id":42189480,"name":"4. Toxic Turtle"},{"status":"ACTIVE","sortPriority":5,"id":36104892,"name":"5. Bridwood Ali"},{"status":"ACTIVE","sortPriority":6,"id":38256919,"name":"6. Warramunga"},{"status":"ACTIVE","sortPriority":7,"id":43154455,"name":"8. Strait Sambuca"}],"regulators":["MR_INT"],"venue":"Devonport","countryCode":"AU","discountAllowed":true,"timezone":"Australia/Sydney","openDate":"2022-03-01T02:00:00.000Z","version":4380714790,"name":"R4 452m Gr5","eventName":"Devonport (AUS) 1st Mar"},"rc":[],"con":true,"img":false}]}
{"op":"mcm","clk":"5306387013","pt":1646097078654,"mc":[{"id":"1.195395425","rc":[{"atb":[[1.8,22.03]],"id":43154454},{"trd":[[1.8,1.43]],"ltp":1.8,"tv":1.43,"id":43154454}],"con":true,"img":false}]}
{"op":"mcm","clk":"5306387020","pt":1646097078858,"mc":[{"id":"1.195395425","rc":[{"atb":[[1.76,0]],"id":43154454}],"con":true,"img":false}]}
{"op":"mcm","clk":"5306423960","pt":1646097840543,"mc":[{"id":"1.195395425","rc":[{"atb":[[5.2,17.14]],"id":38859241},{"atb":[[1.36,200]],"id":43154454}],"con":true,"img":false}]}
{"op":"mcm","clk":"5306423964","pt":1646097840644,"mc":[{"id":"1.195395425","rc":[{"atb":[[2.8,40]],"id":36104892},{"atl":[[36,8.2]],"id":36104892},{"atb":[[2.62,46.3]],"id":38859241},{"atl":[[17,8.5],[5.8,8.2]],"id":43154454},{"atb":[[8.6,9.47],[2.62,46.3],[4.2,26.56]],"id":43154455},{"atb":[[12,6.55],[2.62,46.3],[4.2,26.56]],"id":39318320},{"atb":[[2.62,46.3],[4.2,26.56]],"id":38256919},{"atb":[[1.86,83.72]],"id":42189480},{"atl":[[13,8.2]],"id":42189480}],"con":true,"img":false}]}
{"op":"mcm","clk":"5306423966","pt":1646097840746,"mc":[{"id":"1.195395425","rc":[{"atl":[[34,13.5]],"id":43154454},{"atl":[[34,13.5]],"id":42189480}],"con":true,"img":false}]}
{"op":"mcm","clk":"5306424958","pt":1646097865169,"mc":[{"id":"1.195395425","rc":[{"atb":[[2.76,0]],"id":42189480}],"con":true,"img":false}]}
{"op":"mcm","clk":"5306424964","pt":1646097865270,"mc":[{"id":"1.195395425","rc":[{"atb":[[2.82,2]],"id":42189480}],"con":true,"img":false}]}
{"op":"mcm","clk":"5306430285","pt":1646097987358,"mc":[{"id":"1.195395425","rc":[{"atb":[[4.6,21.17],[3.95,43.26]],"id":36104892},{"atl":[[9.6,6.74],[13,10.81]],"id":36104892},{"spn":7.1,"spf":1.0,"id":36104892},{"atb":[[7.2,20.01],[8.2,8.05]],"id":38859241},{"atl":[[21,2.89],[30,4.32]],"id":38859241},{"spn":15.2,"spf":1.0,"id":38859241},{"atb":[[1.78,62.86],[1.66,189.3]],"id":43154454},{"atl":[[3.45,50.84],[2.94,29.89]],"id":43154454},{"spn":2.37,"spf":1.0,"id":43154454},{"atb":[[13.5,9.75],[14,4.46]],"id":43154455},{"atl":[[44,2.7],[60,2.7]],"id":43154455},{"spn":30.25,"spf":1.0,"id":43154455},{"atb":[[23,9.53],[25,2.7]],"id":39318320},{"atl":[[140,0.41],[200,3.36]],"id":39318320},{"spn":62.5,"spf":1.0,"id":39318320},{"atb":[[34,2.7],[23,6.49]],"id":38256919},{"atl":[[260,2.7],[190,0.3]],"id":38256919},{"atb":[[2.86,31.18],[2.62,67.94]],"id":42189480},{"atl":[[5.1,14.14],[7,18.34]],"id":42189480},{"spn":3.99,"spf":1.0,"id":42189480}],"con":true,"img":false}]}
{"op":"mcm","clk":"5306430295","pt":1646097987560,"mc":[{"id":"1.195395425","rc":[{"atb":[[20,6.19]],"id":39318320}],"con":true,"img":false}]}
{"op":"mcm","clk":"5306430301","pt":1646097987664,"mc":[{"id":"1.195395425","rc":[{"atb":[[23,4.6]],"id":39318320}],"con":true,"img":false}]}
{"op":"mcm","clk":"5306430528","pt":1646097993659,"mc":[{"id":"1.195395425","rc":[{"atb":[[4.6,18.66]],"id":36104892},{"atb":[[1.8,10.76]],"id":43154454},{"atb":[[2.88,4.88]],"id":42189480}],"con":true,"img":false}]}
{"op":"mcm","clk":"5306430917","pt":1646098002750,"mc":[{"id":"1.195395425","rc":[{"atb":[[4.7,2.43]],"id":36104892},{"atb":[[1.81,11.13]],"id":43154454},{"atb":[[2.9,4.73]],"id":42189480}],"con":true,"img":false}]}
{"op":"mcm","clk":"5306431183","pt":1646098008699,"mc":[{"id":"1.195395425","rc":[{"atb":[[1.8,0]],"id":43154454},{"atb":[[2.88,0]],"id":42189480}],"con":true,"img":false}]}
{"op":"mcm","clk":"5306431455","pt":1646098015019,"mc":[{"id":"1.195395425","rc":[{"atl":[[1000,1.67]],"id":43154454}],"con":true,"img":false}]}
{"op":"mcm","clk":"5306431463","pt":1646098015122,"mc":[{"id":"1.195395425","rc":[{"atb":[[2.9,9.57]],"id":42189480}],"con":true,"img":false}]}
{"op":"mcm","clk":"5306431476","pt":1646098015380,"mc":[{"id":"1.195395425","rc":[{"atl":[[1000,0.64]],"id":43154454}],"con":true,"img":false}]}
{"op":"mcm","clk":"5306431487","pt":1646098015584,"mc":[{"id":"1.195395425","rc":[{"atb":[[1.81,22.47]],"id":43154454}],"con":true,"img":false}]}
{"op":"mcm","clk":"5306431505","pt":1646098015895,"mc":[{"id":"1.195395425","rc":[{"atl":[[1000,0]],"id":43154454}],"con":true,"img":false}]}
{"op":"mcm","clk":"5306431511","pt":1646098015994,"mc":[{"id":"1.195395425","rc":[{"atl":[[2,0.64]],"id":43154454}],"con":true,"img":false}]}
{"op":"mcm","clk":"5306433216","pt":1646098052259,"mc":[{"id":"1.195395425","rc":[{"spn":7.15,"spf":1.0,"id":36104892},{"spn":1.9,"spf":1.0,"id":43154454},{"atb":[[20,0],[24,4.71]],"id":39318320},{"spn":4.0,"spf":1.0,"id":42189480}],"con":true,"img":false}]}
{"op":"mcm","clk":"5306433236","pt":1646098052567,"mc":[{"id":"1.195395425","rc":[{"atl":[[200,0.66]],"id":39318320}],"con":true,"img":false}]}
{"op":"mcm","clk":"5306433245","pt":1646098052672,"mc":[{"id":"1.195395425","rc":[{"atl":[[190,2.7]],"id":39318320}],"con":true,"img":false}]}
{"op":"mcm","clk":"5306434920","pt":1646098084231,"mc":[{"id":"1.195395425","rc":[{"atb":[[27,4.86]],"id":38256919}],"con":true,"img":false}]}
{"op":"mcm","clk":"5306434932","pt":1646098084388,"mc":[{"id":"1.195395425","rc":[{"atb":[[23,0]],"id":38256919}],"con":true,"img":false}]}
{"op":"mcm","clk":"5306437243","pt":1646098138001,"mc":[{"id":"1.195395425","rc":[{"atl":[[2,0]],"id":43154454},{"spn":2.37,"spf":1.0,"id":43154454}],"con":true,"img":false}]}
{"op":"mcm","clk":"5306437252","pt":1646098138205,"mc":[{"id":"1.195395425","rc":[{"atl":[[1000,1.67]],"id":43154454}],"con":true,"img":false}]}
{"op":"mcm","clk":"5306437270","pt":1646098138516,"mc":[{"id":"1.195395425","rc":[{"atl":[[1000,0.39]],"id":43154454}],"con":true,"img":false}]}
{"op":"mcm","clk":"5306437285","pt":1646098138878,"mc":[{"id":"1.195395425","rc":[{"atl":[[1000,0]],"id":43154454}],"con":true,"img":false}]}
{"op":"mcm","clk":"5306437289","pt":1646098138981,"mc":[{"id":"1.195395425","rc":[{"atl":[[3.3,0.39]],"id":43154454}],"con":true,"img":false}]}
{"op":"mcm","clk":"5306437492","pt":1646098144011,"mc":[{"id":"1.195395425","rc":[{"atl":[[3.3,0]],"id":43154454}],"con":true,"img":false}]}
{"op":"mcm","clk":"5306437505","pt":1646098144217,"mc":[{"id":"1.195395425","rc":[{"atl":[[1000,1.67]],"id":43154454}],"con":true,"img":false}]}
{"op":"mcm","clk":"5306437528","pt":1646098144786,"mc":[{"id":"1.195395425","rc":[{"atl":[[1000,0.44]],"id":43154454}],"con":true,"img":false}]}
{"op":"mcm","clk":"5306437546","pt":1646098145093,"mc":[{"id":"1.195395425","rc":[{"atl":[[1000,0]],"id":43154454}],"con":true,"img":false}]}
{"op":"mcm","clk":"5306437551","pt":1646098145196,"mc":[{"id":"1.195395425","rc":[{"atl":[[2.92,0.44]],"id":43154454}],"con":true,"img":false}]}
{"op":"mcm","clk":"5306451118","pt":1646098483722,"mc":[{"id":"1.195395425","rc":[{"spn":2.36,"spf":1.0,"id":43154454},{"atb":[[11,12.19]],"id":43154455}],"con":true,"img":false}]}
{"op":"mcm","clk":"5306451123","pt":1646098483819,"mc":[{"id":"1.195395425","rc":[{"atb":[[13.5,0],[14,0]],"id":43154455}],"con":true,"img":false}]}
{"op":"mcm","clk":"5306451130","pt":1646098483924,"mc":[{"id":"1.195395425","rc":[{"atb":[[13.5,4.46]],"id":43154455}],"con":true,"img":false}]}
{"op":"mcm","clk":"5306455953","pt":1646098622728,"mc":[{"id":"1.195395425","rc":[{"atl":[[34,13.5]],"id":36104892},{"atl":[[17,8.5]],"id":42189480}],"con":true,"img":false}]}
{"op":"mcm","clk":"5306467381","pt":1646098914356,"mc":[{"id":"1.195395425","rc":[{"atl":[[50,10.89]],"id":38859241}],"con":true,"img":false}]}
{"op":"mcm","clk":"5306473555","pt":1646099068057,"mc":[{"id":"1.195395425","rc":[{"atb":[[38,0]],"id":38256919}],"con":true,"img":false}]}
{"op":"mcm","clk":"5306473561","pt":1646099068157,"mc":[{"id":"1.195395425","rc":[{"atb":[[40,0.27]],"id":38256919}],"con":true,"img":false}]}
{"op":"mcm","clk":"5306486320","pt":1646099355614,"mc":[{"id":"1.195395425","rc":[{"atb":[[9,0]],"id":38859241}],"con":true,"img":false}]}
{"op":"mcm","clk":"5306486328","pt":1646099355716,"mc":[{"id":"1.195395425","rc":[{"atb":[[8.6,1.33]],"id":38859241}],"con":true,"img":false}]}
{"op":"mcm","clk":"5306499537","pt":1646099641752,"mc":[{"id":"1.195395425","rc":[{"atb":[[1.53,73.24]],"id":36104892},{"atl":[[23,4.55]],"id":36104892},{"atb":[[4.2,31.25]],"id":38859241},{"atl":[[60,2]],"id":38859241},{"atb":[[7,16.67]],"id":43154455},{"atb":[[10.5,10.53]],"id":39318320},{"atb":[[19,5.56]],"id":38256919},{"atb":[[1.4,119.3]],"id":42189480},{"atl":[[11.5,9.52]],"id":42189480}],"con":true,"img":false}]}
{"op":"mcm","clk":"5306499542","pt":1646099641853,"mc":[{"id":"1.195395425","rc":[{"atl":[[6,20]],"id":43154454}],"con":true,"img":false}]}
{"op":"mcm","clk":"5306502043","pt":1646099697049,"mc":[{"id":"1.195395425","rc":[{"atb":[[1.62,73.24],[1.53,0]],"id":36104892}],"con":true,"img":false}]}
{"op":"mcm","clk":"5306506962","pt":1646099812559,"mc":[{"id":"1.195395425","rc":[{"atb":[[1.02,2.23]],"id":38859241},{"atb":[[1.03,2.23]],"id":43154455}],"con":true,"img":false}]}
{"op":"mcm","clk":"5306506967","pt":1646099812662,"mc":[{"id":"1.195395425","rc":[{"atb":[[1.01,2.23]],"id":36104892}],"con":true,"img":false}]}
{"op":"mcm","clk":"5306506972","pt":1646099812765,"mc":[{"id":"1.195395425","rc":[{"atb":[[1.02,0.38]],"id":38859241}],"con":true,"img":false}]}
{"op":"mcm","clk":"5306506976","pt":1646099812867,"mc":[{"id":"1.195395425","rc":[{"atb":[[1.03,0.21]],"id":43154455}],"con":true,"img":false}]}
{"op":"mcm","clk":"5306506981","pt":1646099812969,"mc":[{"id":"1.195395425","rc":[{"atb":[[1.02,0]],"id":38859241}],"con":true,"img":false}]}
{"op":"mcm","clk":"5306506990","pt":1646099813072,"mc":[{"id":"1.195395425","rc":[{"atb":[[9.6,0.38]],"id":38859241}],"con":true,"img":false}]}
{"op":"mcm","clk":"5306506997","pt":1646099813174,"mc":[{"id":"1.195395425","rc":[{"atb":[[1.01,0.77]],"id":36104892},{"atb":[[1.03,0]],"id":43154455}],"con":true,"img":false}]}
{"op":"mcm","clk":"5306507004","pt":1646099813277,"mc":[{"id":"1.195395425","rc":[{"atb":[[17,0.21]],"id":43154455}],"con":true,"img":false}]}
{"op":"mcm","clk":"5306507008","pt":1646099813379,"mc":[{"id":"1.195395425","rc":[{"atb":[[1.01,0]],"id":36104892}],"con":true,"img":false}]}
{"op":"mcm","clk":"5306507015","pt":1646099813432,"mc":[{"id":"1.195395425","rc":[{"atb":[[4.8,0.77]],"id":36104892}],"con":true,"img":false}]}
{"op":"mcm","clk":"5306512615","pt":1646099938430,"mc":[{"id":"1.195395425","rc":[{"atl":[[16.5,6.45],[23,0]],"id":36104892},{"spn":7.2,"spf":1.0,"id":36104892},{"atb":[[4.2,0],[4.7,27.03]],"id":38859241},{"spn":15.3,"spf":1.0,"id":38859241},{"atb":[[1.79,126.58]],"id":43154454},{"atl":[[3.7,37.04],[6,0]],"id":43154454},{"atl":[[120,2]],"id":43154455},{"spn":30.5,"spf":1.0,"id":43154455},{"atb":[[10.5,0],[6.6,17.86]],"id":39318320},{"atl":[[190,4.7]],"id":39318320},{"atb":[[19,0],[8.2,13.89]],"id":38256919},{"atl":[[260,4.7]],"id":38256919},{"atb":[[1.4,0],[2.1,90.91]],"id":42189480},{"atl":[[5.8,20.83],[11.5,0]],"id":42189480}],"con":true,"img":false}]}
{"op":"mcm","clk":"5306512618","pt":1646099938482,"mc":[{"id":"1.195395425","rc":[{"atb":[[5.2,40.95],[4.7,0]],"id":38859241},{"atl":[[200,2.66]],"id":39318320},{"atb":[[9.2,12.2],[8.2,0]],"id":38256919},{"atl":[[260,2.7],[350,2.37]],"id":38256919},{"atl":[[5.8,0],[5.7,21.28]],"id":42189480}],"con":true,"img":false}]}
{"op":"mcm","clk":"5306512626","pt":1646099938583,"mc":[{"id":"1.195395425","rc":[{"atl":[[190,2.7]],"id":39318320}],"con":true,"img":false}]}
{"op":"mcm","clk":"5306512812","pt":1646099943201,"mc":[{"id":"1.195395425","rc":[{"atb":[[2.2,83.33],[2.1,0]],"id":42189480}],"con":true,"img":false}]}
{"op":"mcm","clk":"5306513021","pt":1646099947620,"mc":[{"id":"1.195395425","rc":[{"atb":[[1.81,11.34]],"id":43154454}],"con":true,"img":false}]}
{"op":"mcm","clk":"5306513397","pt":1646099956602,"mc":[{"id":"1.195395425","rc":[{"atb":[[1.82,10.99]],"id":43154454}],"con":true,"img":false}]}
{"op":"mcm","clk":"5306513719","pt":1646099964854,"mc":[{"id":"1.195395425","rc":[{"atb":[[1.81,0]],"id":43154454}],"con":true,"img":false}]}
{"op":"mcm","clk":"5306514058","pt":1646099972548,"mc":[{"id":"1.195395425","rc":[{"atb":[[1.82,23.32]],"id":43154454}],"con":true,"img":false}]}
{"op":"mcm","clk":"5306514999","pt":1646099991558,"mc":[{"id":"1.195395425","rc":[{"atb":[[1.78,0]],"id":43154454},{"atl":[[5.6,23.92],[7,0]],"id":42189480}],"con":true,"img":false}]}
{"op":"mcm","clk":"5306515002","pt":1646099991659,"mc":[{"id":"1.195395425","rc":[{"atb":[[1.8,62.86]],"id":43154454}],"con":true,"img":false}]}
{"op":"mcm","clk":"5306515186","pt":1646099995363,"mc":[{"id":"1.195395425","rc":[{"atl":[[16.5,0],[14,7.69]],"id":36104892},{"atb":[[4.1,32.26],[5.2,17.14]],"id":38859241},{"atl":[[44,2.33],[60,0]],"id":38859241},{"atb":[[1.79,0],[1.75,133.33]],"id":43154454},{"atb":[[5,25],[7,0]],"id":43154455},{"atb":[[4,33.33],[6.6,0]],"id":39318320},{"atb":[[9.2,0],[7.6,15.15]],"id":38256919},{"atb":[[2.2,0],[2.48,67.57]],"id":42189480},{"atl":[[6,20],[5.7,0]],"id":42189480}],"con":true,"img":false}]}
{"op":"mcm","clk":"5306515202","pt":1646099995568,"mc":[{"id":"1.195395425","rc":[{"atl":[[260,4.7],[350,0.37]],"id":38256919}],"con":true,"img":false}]}
{"op":"mcm","clk":"5306515204","pt":1646099995669,"mc":[{"id":"1.195395425","rc":[{"atl":[[260,2.7],[350,2.37]],"id":38256919}],"con":true,"img":false}]}
{"op":"mcm","clk":"5306515210","pt":1646099995773,"mc":[{"id":"1.195395425","rc":[{"atl":[[260,4.7],[350,0.37]],"id":38256919}],"con":true,"img":false}]}
{"op":"mcm","clk":"5306515356","pt":1646099998752,"mc":[{"id":"1.195395425","rc":[{"atb":[[1.82,12.33]],"id":43154454},{"spn":2.37,"spf":1.0,"id":43154454}],"con":true,"img":false}]}
{"op":"mcm","clk":"5306515468","pt":1646100000607,"mc":[{"id":"1.195395425","rc":[{"atb":[[2.36,73.53],[2.48,0]],"id":42189480}],"con":true,"img":false}]}
{"op":"mcm","clk":"5306515882","pt":1646100007883,"mc":[{"id":"1.195395425","rc":[{"atb":[[4.8,0.77],[4.5,30.98],[4.6,18.67],[3.95,43.28],[3.4,42.27],[3.9,34.98],[3.65,38.28],[4.7,2.43]],"id":36104892},{"atl":[[9.6,6.74],[18,7.77],[21,9.9],[13,10.82],[26,7.92],[15.5,9.11]],"id":36104892},{"atb":[[9.6,0.38],[8,14.49],[7.2,20.02],[8.2,8.06],[6,20.29],[7,16.9],[9.4,12.07]],"id":38859241},{"atl":[[75,1.78],[150,1.33],[21,2.9],[50,10.89],[100,2],[30,4.32]],"id":38859241},{"atb":[[1.82,12.32],[1.8,62.89],[1.83,10.86],[1.6,169.09],[1.7,144.93],[1.77,131.76],[1.66,189.38],[1.65,156.08]],"id":43154454},{"atl":[[4,66.06],[2.92,0.44],[3.45,50.86],[4.5,56.63],[3.5,52.85],[2.94,29.91],[3.75,48.04]],"id":43154454},{"trd":[[1.8,1.43]],"ltp":1.8,"tv":1.43,"id":43154454},{"atb":[[16.5,6.54],[9.2,12.37],[10.5,10.68],[11,12.2],[13,8.45],[13.5,4.46]],"id":43154455},{"atl":[[130,1.02],[280,0.7],[44,2.7],[180,0.73],[230,0.86],[60,2.7]],"id":43154455},{"atb":[[18,5.96],[23,4.61],[24,4.71],[25,2.7],[13,8.45],[15.5,6.99]],"id":39318320},{"atl":[[140,0.41],[300,0.66],[350,0.56],[190,2.7],[200,2.66],[250,0.53]],"id":39318320},{"atb":[[32,3.27],[34,2.7],[21,5.07],[46,2.25],[26,4.05],[27,4.86]],"id":38256919},{"atl":[[260,4.7],[350,0.37],[190,0.3],[400,0.33],[450,0.44],[500,0.39]],"id":38256919},{"atb":[[2.9,9.57],[2.86,31.19],[2.5,67.63],[2.6,63.41],[2.84,55.13],[2.62,67.97],[2.7,59.67]],"id":42189480},{"atl":[[5.6,23.93],[7.2,21.31],[5.1,14.15],[9.2,24.17],[10.5,20.86],[8.2,18.35]],"id":42189480}],"con":true,"img":false}]}
{"op":"mcm","clk":"5306515912","pt":1646100008498,"mc":[{"id":"1.195395425","rc":[{"atb":[[1.82,0]],"id":43154454}],"con":true,"img":false}]}
{"op":"mcm","clk":"5306516251","pt":1646100014490,"mc":[{"id":"1.195395425","rc":[{"atb":[[1.83,23.04]],"id":43154454}],"con":true,"img":false}]}
{"op":"mcm","clk":"5306516363","pt":1646100016607,"mc":[{"id":"1.195395425","rc":[{"atb":[[1.8,0]],"id":43154454},{"atl":[[5.6,0]],"id":42189480}],"con":true,"img":false}]}
{"op":"mcm","clk":"5306516368","pt":1646100016707,"mc":[{"id":"1.195395425","rc":[{"atb":[[1.78,62.89]],"id":43154454},{"atl":[[5.9,23.93]],"id":42189480}],"con":true,"img":false}]}
{"op":"mcm","clk":"5306516726","pt":1646100022819,"mc":[{"id":"1.195395425","rc":[{"atb":[[1.83,12.17]],"id":43154454}],"con":true,"img":false}]}
{"op":"mcm","clk":"5306517022","pt":1646100029032,"mc":[{"id":"1.195395425","rc":[{"atb":[[4.6,27.78],[4.1,0]],"id":38859241},{"atb":[[5.8,20.83],[5,0]],"id":43154455},{"atb":[[4,0],[5.6,21.74]],"id":39318320}],"con":true,"img":false}]}
{"op":"mcm","clk":"5306517293","pt":1646100033918,"mc":[{"id":"1.195395425","rc":[{"atb":[[1.83,0]],"id":43154454}],"con":true,"img":false}]}
{"op":"mcm","clk":"5306517443","pt":1646100036690,"mc":[{"id":"1.195395425","rc":[{"atb":[[1.79,126.58],[1.75,0]],"id":43154454},{"atb":[[2.36,0],[2.46,68.49]],"id":42189480}],"con":true,"img":false}]}
{"op":"mcm","clk":"5306518224","pt":1646100052913,"mc":[{"id":"1.195395425","rc":[{"atb":[[1.82,11]],"id":43154454}],"con":true,"img":false}]}
{"op":"mcm","clk":"5306518263","pt":1646100053740,"mc":[{"id":"1.195395425","rc":[{"atb":[[1.82,23.32]],"id":43154454}],"con":true,"img":false}]}
{"op":"mcm","clk":"5306519626","pt":1646100081770,"mc":[{"id":"1.195395425","rc":[{"atb":[[1.78,0]],"id":43154454}],"con":true,"img":false}]}
{"op":"mcm","clk":"5306519630","pt":1646100081867,"mc":[{"id":"1.195395425","rc":[{"atb":[[1.8,62.89]],"id":43154454}],"con":true,"img":false}]}
{"op":"mcm","clk":"5306519951","pt":1646100089088,"mc":[{"id":"1.195395425","rc":[{"atb":[[1.82,12.32]],"id":43154454}],"con":true,"img":false}]}
{"op":"mcm","clk":"5306520264","pt":1646100095791,"mc":[{"id":"1.195395425","rc":[{"atb":[[1.82,0]],"id":43154454}],"con":true,"img":false}]}
{"op":"mcm","clk":"5306520499","pt":1646100100862,"mc":[{"id":"1.195395425","rc":[{"atb":[[1.83,10.86]],"id":43154454}],"con":true,"img":false}]}
{"op":"mcm","clk":"5306520531","pt":1646100101581,"mc":[{"id":"1.195395425","rc":[{"atb":[[1.83,23.04]],"id":43154454}],"con":true,"img":false}]}
{"op":"mcm","clk":"5306522927","pt":1646100156722,"mc":[{"id":"1.195395425","rc":[{"atb":[[1.79,0],[1.75,133.33]],"id":43154454},{"spn":2.37,"spf":1.0,"id":43154454}],"con":true,"img":false}]}
{"op":"mcm","clk":"5306523159","pt":1646100162151,"mc":[{"id":"1.195395425","rc":[{"atb":[[1.8,0]],"id":43154454}],"con":true,"img":false}]}
{"op":"mcm","clk":"5306523164","pt":1646100162252,"mc":[{"id":"1.195395425","rc":[{"atb":[[1.78,62.89]],"id":43154454}],"con":true,"img":false}]}
{"op":"mcm","clk":"5306523539","pt":1646100170143,"mc":[{"id":"1.195395425","rc":[{"atb":[[1.83,12.17]],"id":43154454}],"con":true,"img":false}]}
{"op":"mcm","clk":"5306523972","pt":1646100179053,"mc":[{"id":"1.195395425","rc":[{"atb":[[1.81,11.13]],"id":43154454}],"con":true,"img":false}]}
{"op":"mcm","clk":"5306524022","pt":1646100179876,"mc":[{"id":"1.195395425","rc":[{"atb":[[1.83,0]],"id":43154454}],"con":true,"img":false}]}
{"op":"mcm","clk":"5306524387","pt":1646100185857,"mc":[{"id":"1.195395425","rc":[{"atb":[[1.81,23.6]],"id":43154454}],"con":true,"img":false}]}
{"op":"mcm","clk":"5306542914","pt":1646100550891,"mc":[{"id":"1.195395425","rc":[{"atl":[[12,9.09],[14,0]],"id":36104892},{"atb":[[1.79,126.58],[1.75,0]],"id":43154454},{"atl":[[3.7,0],[6,20]],"id":43154454},{"spn":2.36,"spf":1.0,"id":43154454},{"atb":[[4.8,26.32],[5.8,0]],"id":43154455},{"atl":[[120,0]],"id":43154455},{"atb":[[5.6,0],[10.5,10.53]],"id":39318320},{"atl":[[200,0.66]],"id":39318320},{"atb":[[19,5.56],[7.6,0]],"id":38256919},{"atl":[[260,2.7]],"id":38256919},{"atb":[[2.46,0],[2.26,79.37]],"id":42189480},{"atl":[[11.5,9.52],[6,0]],"id":42189480}],"con":true,"img":false}]}
{"op":"mcm","clk":"5306542919","pt":1646100550988,"mc":[{"id":"1.195395425","rc":[{"atl":[[23,4.55],[12,0]],"id":36104892},{"atb":[[4.8,0],[7,16.67]],"id":43154455},{"atb":[[1.4,123.09],[2.26,0]],"id":42189480}],"con":true,"img":false}]}
{"op":"mcm","clk":"5306542922","pt":1646100551090,"mc":[{"id":"1.195395425","rc":[{"atb":[[1.79,0]],"id":43154454}],"con":true,"img":false}]}
{"op":"mcm","clk":"5306543764","pt":1646100567310,"mc":[{"id":"1.195395425","rc":[{"atl":[[7,18.35],[5.9,0]],"id":42189480}],"con":true,"img":false}]}
{"op":"mcm","clk":"5306550516","pt":1646100715808,"mc":[{"id":"1.195395425","rc":[{"atl":[[23,0],[14,7.69]],"id":36104892},{"atb":[[4.6,0],[3.1,46.3]],"id":38859241},{"atb":[[1.79,126.58]],"id":43154454},{"atl":[[6,0],[3.55,39.22]],"id":43154454},{"atl":[[110,2]],"id":43154455},{"atb":[[10.5,0],[6,20]],"id":39318320},{"atl":[[200,2.66]],"id":39318320},{"atb":[[19,0],[8.4,13.51]],"id":38256919},{"atl":[[350,2.37]],"id":38256919},{"atb":[[1.4,0],[2.14,87.72]],"id":42189480},{"atl":[[6.4,18.52],[11.5,0]],"id":42189480}],"con":true,"img":false}]}
{"op":"mcm","clk":"5306550846","pt":1646100723108,"mc":[{"id":"1.195395425","rc":[{"atb":[[1.81,12.47]],"id":43154454}],"con":true,"img":false}]}
{"op":"mcm","clk":"5306551075","pt":1646100727889,"mc":[{"id":"1.195395425","rc":[{"atb":[[1.62,0],[1.71,73.24]],"id":36104892},{"atb":[[1.79,0],[1.75,133.33]],"id":43154454}],"con":true,"img":false}]}
{"op":"mcm","clk":"5306551732","pt":1646100741712,"mc":[{"id":"1.195395425","rc":[{"atl":[[32,3.23],[44,0]],"id":38859241},{"atb":[[5.3,23.26],[7,0]],"id":43154455},{"atb":[[3.7,37.04],[6,0]],"id":39318320},{"atb":[[8.4,0],[5.4,22.73]],"id":38256919}],"con":true,"img":false}]}
{"op":"mcm","clk":"5306551736","pt":1646100741816,"mc":[{"id":"1.195395425","rc":[{"atb":[[5.3,0],[6.2,19.23]],"id":43154455}],"con":true,"img":false}]}
{"op":"mcm","clk":"5306551753","pt":1646100742227,"mc":[{"id":"1.195395425","rc":[{"atb":[[3.1,0],[4.1,32.26]],"id":38859241},{"atb":[[3.7,0],[6.6,17.86]],"id":39318320},{"atb":[[10,11.11],[5.4,0]],"id":38256919},{"atl":[[260,4.7],[350,0.37]],"id":38256919},{"atb":[[2.5,134.3],[2.14,0]],"id":42189480}],"con":true,"img":false}]}
{"op":"mcm","clk":"5306551848","pt":1646100744131,"mc":[{"id":"1.195395425","rc":[{"atb":[[1.81,23.6]],"id":43154454}],"con":true,"img":false}]}
{"op":"mcm","clk":"5306552283","pt":1646100753251,"mc":[{"id":"1.195395425","rc":[{"atb":[[1.64,33.82],[4.1,0]],"id":38859241}],"con":true,"img":false}]}
{"op":"mcm","clk":"5306552843","pt":1646100766754,"mc":[{"id":"1.195395425","rc":[{"atl":[[7,0]],"id":42189480}],"con":true,"img":false}]}
{"op":"mcm","clk":"5306552847","pt":1646100766858,"mc":[{"id":"1.195395425","rc":[{"atl":[[6.2,18.35]],"id":42189480}],"con":true,"img":false}]}
{"op":"mcm","clk":"5306552902","pt":1646100768344,"mc":[{"id":"1.195395425","rc":[{"atb":[[1.64,0],[5,25]],"id":38859241}],"con":true,"img":false}]}
{"op":"mcm","clk":"5306557986","pt":1646100873186,"mc":[{"id":"1.195395425","rc":[{"atb":[[1.7,287.79]],"id":43154454},{"atl":[[3.85,35.09]],"id":43154454},{"atb":[[5.5,22.22]],"id":43154455},{"atb":[[6.6,0]],"id":39318320},{"atb":[[10,0]],"id":38256919},{"atb":[[2.36,73.53],[2.5,67.63]],"id":42189480}],"con":true,"img":false}]}
{"op":"mcm","clk":"5306557991","pt":1646100873289,"mc":[{"id":"1.195395425","rc":[{"atl":[[32,0],[48,2.13]],"id":38859241},{"atb":[[1.75,0]],"id":43154454},{"atl":[[3.55,0]],"id":43154454},{"atb":[[6.2,0]],"id":43154455},{"atb":[[5.5,22.22]],"id":39318320},{"atb":[[8.4,13.51]],"id":38256919}],"con":true,"img":false}]}
{"op":"mcm","clk":"5306566413","pt":1646101052919,"mc":[{"id":"1.195395425","rc":[{"atb":[[1.7,144.93],[1.75,133.33]],"id":43154454},{"atb":[[5.5,0],[6,20]],"id":43154455},{"atb":[[5.5,0],[6,20]],"id":39318320},{"atb":[[8.4,0],[9.4,11.9]],"id":38256919},{"atb":[[2.36,0],[2.46,68.49]],"id":42189480}],"con":true,"img":false}]}
{"op":"mcm","clk":"5306572548","pt":1646101189421,"mc":[{"id":"1.195395425","marketDefinition":{"bspMarket":true,"turnInPlayEnabled":false,"persistenceEnabled":false,"marketBaseRate":7.0,"eventId":"31270458","eventTypeId":"4339","numberOfWinners":1,"bettingType":"ODDS","marketType":"WIN","marketTime":"2022-03-01T03:14:00.000Z","suspendTime":"2022-03-01T03:14:00.000Z","bspReconciled":false,"complete":true,"inPlay":false,"crossMatching":true,"runnersVoidable":false,"numberOfActiveRunners":7,"betDelay":0,"status":"OPEN","runners":[{"status":"ACTIVE","sortPriority":1,"id":43154454,"name":"1. Buckle Up Iveta"},{"status":"ACTIVE","sortPriority":2,"id":38859241,"name":"2. Theo Dragonet"},{"status":"ACTIVE","sortPriority":3,"id":39318320,"name":"3. Engage The Rage"},{"status":"ACTIVE","sortPriority":4,"id":42189480,"name":"4. Toxic Turtle"},{"status":"ACTIVE","sortPriority":5,"id":36104892,"name":"5. Bridwood Ali"},{"status":"ACTIVE","sortPriority":6,"id":38256919,"name":"6. Warramunga"},{"status":"ACTIVE","sortPriority":7,"id":43154455,"name":"8. Strait Sambuca"}],"regulators":["MR_INT"],"venue":"Devonport","countryCode":"AU","discountAllowed":true,"timezone":"Australia/Sydney","openDate":"2022-03-01T02:00:00.000Z","version":4381058497,"name":"R4 452m Gr5","eventName":"Devonport (AUS) 1st Mar"},"rc":[],"con":true,"img":false}]}
{"op":"mcm","clk":"5306583841","pt":1646101441597,"mc":[{"id":"1.195395425","rc":[{"atb":[[22,0]],"id":39318320}],"con":true,"img":false}]}
{"op":"mcm","clk":"5306583845","pt":1646101441697,"mc":[{"id":"1.195395425","rc":[{"atb":[[24,5.15]],"id":39318320}],"con":true,"img":false}]}
{"op":"mcm","clk":"5306583932","pt":1646101443197,"mc":[{"id":"1.195395425","rc":[{"atb":[[5,0],[2.1,33.82]],"id":38859241},{"atl":[[48,0],[30,7.77]],"id":38859241},{"atb":[[7.2,16.13],[6,0]],"id":39318320}],"con":true,"img":false}]}
{"op":"mcm","clk":"5306583938","pt":1646101443299,"mc":[{"id":"1.195395425","rc":[{"atb":[[4.6,27.78],[2.1,0]],"id":38859241}],"con":true,"img":false}]}
{"op":"mcm","clk":"5306586086","pt":1646101490280,"mc":[{"id":"1.195395425","rc":[{"atb":[[1.81,20.72]],"id":43154454},{"trd":[[1.81,5.77]],"ltp":1.81,"tv":5.77,"id":43154454}],"con":true,"img":false}]}
{"op":"mcm","clk":"5306589267","pt":1646101563136,"mc":[{"id":"1.195395425","rc":[{"atb":[[1.75,0]],"id":43154454}],"con":true,"img":false}]}
{"op":"mcm","clk":"5306589274","pt":1646101563238,"mc":[{"id":"1.195395425","rc":[{"atb":[[1.71,140.85]],"id":43154454}],"con":true,"img":false}]}
{"op":"mcm","clk":"5306604381","pt":1646101914122,"mc":[{"id":"1.195395425","rc":[{"atb":[[1.75,133.33],[1.71,0]],"id":43154454}],"con":true,"img":false}]}
{"op":"mcm","clk":"5306605698","pt":1646101940845,"mc":[{"id":"1.195395425","rc":[{"atb":[[1.8,73.24],[1.71,0]],"id":36104892}],"con":true,"img":false}]}
{"op":"mcm","clk":"5306606296","pt":1646101955277,"mc":[{"id":"1.195395425","rc":[{"atb":[[1.75,0],[1.76,131.58]],"id":43154454},{"atb":[[7.2,0],[5.2,23.81]],"id":39318320}],"con":true,"img":false}]}
{"op":"mcm","clk":"5306606302","pt":1646101955380,"mc":[{"id":"1.195395425","rc":[{"atb":[[1.79,126.58],[1.76,0]],"id":43154454},{"atb":[[7.4,15.62],[5.2,0]],"id":39318320}],"con":true,"img":false}]}
{"op":"mcm","clk":"5306606390","pt":1646101956966,"mc":[{"id":"1.195395425","rc":[{"atb":[[1.81,11.13]],"id":43154454}],"con":true,"img":false}]}
{"op":"mcm","clk":"5306606744","pt":1646101962880,"mc":[{"id":"1.195395425","rc":[{"atl":[[2.02,2.58]],"id":43154454}],"con":true,"img":false}]}
{"op":"mcm","clk":"5306606811","pt":1646101964003,"mc":[{"id":"1.195395425","rc":[{"atb":[[4.8,3.27]],"id":36104892},{"atb":[[26,1.66]],"id":39318320}],"con":true,"img":false}]}
{"op":"mcm","clk":"5306606834","pt":1646101964564,"mc":[{"id":"1.195395425","rc":[{"atb":[[1.81,0]],"id":43154454}],"con":true,"img":false}]}
{"op":"mcm","clk":"5306607725","pt":1646101983317,"mc":[{"id":"1.195395425","rc":[{"atb":[[1.79,0],[1.78,191.1]],"id":43154454},{"spn":1.9,"spf":1.0,"id":43154454},{"atb":[[7.4,0],[5.7,21.28]],"id":39318320},{"spn":63.0,"spf":1.0,"id":39318320}],"con":true,"img":false}]}
{"op":"mcm","clk":"5306609030","pt":1646102009036,"mc":[{"id":"1.195395425","rc":[{"atb":[[8.6,13.16],[5.7,0]],"id":39318320}],"con":true,"img":false}]}
{"op":"mcm","clk":"5306610440","pt":1646102040295,"mc":[{"id":"1.195395425","rc":[{"atl":[[190,0]],"id":38256919}],"con":true,"img":false}]}
{"op":"mcm","clk":"5306610448","pt":1646102040397,"mc":[{"id":"1.195395425","rc":[{"atl":[[210,0.3]],"id":38256919}],"con":true,"img":false}]}
{"op":"mcm","clk":"5306612006","pt":1646102068926,"mc":[{"id":"1.195395425","rc":[{"atl":[[2.94,0]],"id":43154454}],"con":true,"img":false}]}
{"op":"mcm","clk":"5306612013","pt":1646102069028,"mc":[{"id":"1.195395425","rc":[{"atl":[[2.88,29.91]],"id":43154454}],"con":true,"img":false}]}
{"op":"mcm","clk":"5306612286","pt":1646102074514,"mc":[{"id":"1.195395425","rc":[{"atl":[[2.92,0]],"id":43154454}],"con":true,"img":false}]}
{"op":"mcm","clk":"5306612296","pt":1646102074822,"mc":[{"id":"1.195395425","rc":[{"atl":[[1000,1.66]],"id":43154454}],"con":true,"img":false}]}
{"op":"mcm","clk":"5306612307","pt":1646102075047,"mc":[{"id":"1.195395425","rc":[{"atl":[[1000,0.45]],"id":43154454}],"con":true,"img":false}]}
{"op":"mcm","clk":"5306612337","pt":1646102075640,"mc":[{"id":"1.195395425","rc":[{"atl":[[1000,0]],"id":43154454}],"con":true,"img":false}]}
{"op":"mcm","clk":"5306612344","pt":1646102075694,"mc":[{"id":"1.195395425","rc":[{"atl":[[2.86,0.45]],"id":43154454}],"con":true,"img":false}]}
{"op":"mcm","clk":"5306612736","pt":1646102083332,"mc":[{"id":"1.195395425","rc":[{"atl":[[2.02,0],[2.86,0]],"id":43154454}],"con":true,"img":false}]}
{"op":"mcm","clk":"5306612759","pt":1646102083638,"mc":[{"id":"1.195395425","rc":[{"atl":[[1000,1.66]],"id":43154454}],"con":true,"img":false}]}
{"op":"mcm","clk":"5306612764","pt":1646102083739,"mc":[{"id":"1.195395425","rc":[{"atl":[[1000,3.33]],"id":43154454}],"con":true,"img":false}]}
{"op":"mcm","clk":"5306612774","pt":1646102083947,"mc":[{"id":"1.195395425","rc":[{"atl":[[1000,2.31]],"id":43154454}],"con":true,"img":false}]}
{"op":"mcm","clk":"5306612783","pt":1646102084102,"mc":[{"id":"1.195395425","rc":[{"atl":[[1000,2.22]],"id":43154454}],"con":true,"img":false}]}
{"op":"mcm","clk":"5306612795","pt":1646102084309,"mc":[{"id":"1.195395425","rc":[{"atl":[[1000,1.58]],"id":43154454}],"con":true,"img":false}]}
{"op":"mcm","clk":"5306612799","pt":1646102084407,"mc":[{"id":"1.195395425","rc":[{"atl":[[2,0.64]],"id":43154454}],"con":true,"img":false}]}
{"op":"mcm","clk":"5306612814","pt":1646102084715,"mc":[{"id":"1.195395425","rc":[{"atl":[[1000,0]],"id":43154454}],"con":true,"img":false}]}
{"op":"mcm","clk":"5306612818","pt":1646102084819,"mc":[{"id":"1.195395425","rc":[{"atl":[[3.3,1.58]],"id":43154454}],"con":true,"img":false}]}
{"op":"mcm","clk":"5306613063","pt":1646102089334,"mc":[{"id":"1.195395425","rc":[{"atl":[[3.3,0]],"id":43154454}],"con":true,"img":false}]}
{"op":"mcm","clk":"5306613069","pt":1646102089539,"mc":[{"id":"1.195395425","rc":[{"atl":[[2.86,1.82]],"id":43154454}],"con":true,"img":false}]}
{"op":"mcm","clk":"5306613559","pt":1646102099719,"mc":[{"id":"1.195395425","rc":[{"atb":[[1.81,11.13]],"id":43154454}],"con":true,"img":false}]}
{"op":"mcm","clk":"5306613734","pt":1646102103374,"mc":[{"id":"1.195395425","rc":[{"atb":[[1.73,136.99],[1.78,62.89]],"id":43154454},{"atb":[[2.46,0],[2.34,74.63]],"id":42189480}],"con":true,"img":false}]}
{"op":"mcm","clk":"5306614299","pt":1646102115489,"mc":[{"id":"1.195395425","rc":[{"atb":[[1.8,0]],"id":36104892},{"atl":[[14,0]],"id":36104892},{"atb":[[4.6,0]],"id":38859241},{"atl":[[30,4.32]],"id":38859241},{"atb":[[1.73,0]],"id":43154454},{"atl":[[3.85,0]],"id":43154454},{"atb":[[6,0]],"id":43154455},{"atl":[[110,0]],"id":43154455},{"atb":[[8.6,0]],"id":39318320},{"atl":[[200,0.66]],"id":39318320},{"atb":[[9.4,0]],"id":38256919},{"atl":[[260,2.7]],"id":38256919},{"atb":[[2.34,0]],"id":42189480},{"atl":[[6.4,0]],"id":42189480}],"con":true,"img":false}]}
{"op":"mcm","clk":"5306614475","pt":1646102119380,"mc":[{"id":"1.195395425","rc":[{"atl":[[6.2,0]],"id":42189480}],"con":true,"img":false}]}
{"op":"mcm","clk":"5306614480","pt":1646102119481,"mc":[{"id":"1.195395425","rc":[{"atl":[[7,18.35]],"id":42189480}],"con":true,"img":false}]}
{"op":"mcm","clk":"5306615888","pt":1646102145822,"mc":[{"id":"1.195395425","rc":[{"atl":[[2.88,0]],"id":43154454},{"spn":1.9,"spf":1.0,"id":43154454}],"con":true,"img":false}]}
{"op":"mcm","clk":"5306615891","pt":1646102145925,"mc":[{"id":"1.195395425","rc":[{"atl":[[2.98,29.91]],"id":43154454}],"con":true,"img":false}]}
{"op":"mcm","clk":"5306617119","pt":1646102169160,"mc":[{"id":"1.195395425","rc":[{"atl":[[210,0]],"id":38256919}],"con":true,"img":false}]}
{"op":"mcm","clk":"5306617125","pt":1646102169211,"mc":[{"id":"1.195395425","rc":[{"atl":[[200,0.3]],"id":38256919}],"con":true,"img":false}]}
{"op":"mcm","clk":"5306617288","pt":1646102172166,"mc":[{"id":"1.195395425","marketDefinition":{"bspMarket":true,"turnInPlayEnabled":false,"persistenceEnabled":false,"marketBaseRate":7.0,"eventId":"31270458","eventTypeId":"4339","numberOfWinners":1,"bettingType":"ODDS","marketType":"WIN","marketTime":"2022-03-01T03:29:00.000Z","suspendTime":"2022-03-01T03:29:00.000Z","bspReconciled":false,"complete":true,"inPlay":false,"crossMatching":true,"runnersVoidable":false,"numberOfActiveRunners":7,"betDelay":0,"status":"OPEN","runners":[{"status":"ACTIVE","sortPriority":1,"id":43154454,"name":"1. Buckle Up Iveta"},{"status":"ACTIVE","sortPriority":2,"id":38859241,"name":"2. Theo Dragonet"},{"status":"ACTIVE","sortPriority":3,"id":39318320,"name":"3. Engage The Rage"},{"status":"ACTIVE","sortPriority":4,"id":42189480,"name":"4. Toxic Turtle"},{"status":"ACTIVE","sortPriority":5,"id":36104892,"name":"5. Bridwood Ali"},{"status":"ACTIVE","sortPriority":6,"id":38256919,"name":"6. Warramunga"},{"status":"ACTIVE","sortPriority":7,"id":43154455,"name":"8. Strait Sambuca"}],"regulators":["MR_INT"],"venue":"Devonport","countryCode":"AU","discountAllowed":true,"timezone":"Australia/Sydney","openDate":"2022-03-01T02:00:00.000Z","version":4381069226,"name":"R4 452m Gr5","eventName":"Devonport (AUS) 1st Mar"},"rc":[],"con":true,"img":false}]}
{"op":"mcm","clk":"5306623274","pt":1646102285061,"mc":[{"id":"1.195395425","rc":[{"atb":[[4.9,2.29]],"id":36104892},{"spn":7.25,"spf":1.0,"id":36104892},{"atb":[[1.82,7.79]],"id":43154454},{"spn":1.91,"spf":1.0,"id":43154454},{"atb":[[2.92,6.98]],"id":42189480},{"spn":4.01,"spf":1.0,"id":42189480}],"con":true,"img":false}]}
{"op":"mcm","clk":"5306623337","pt":1646102286295,"mc":[{"id":"1.195395425","rc":[{"atb":[[4.8,0.77],[4.9,4.75]],"id":36104892},{"atb":[[8.4,12.52]],"id":38859241},{"atb":[[14,7.13]],"id":43154455},{"atb":[[2.92,14.46]],"id":42189480}],"con":true,"img":false}]}
{"op":"mcm","clk":"5306623348","pt":1646102286495,"mc":[{"id":"1.195395425","rc":[{"atb":[[1.03,2.23],[17,0]],"id":43154455}],"con":true,"img":false}]}
{"op":"mcm","clk":"5306623359","pt":1646102286699,"mc":[{"id":"1.195395425","rc":[{"atb":[[1.03,0.21]],"id":43154455}],"con":true,"img":false}]}
{"op":"mcm","clk":"5306623368","pt":1646102286906,"mc":[{"id":"1.195395425","rc":[{"atb":[[1.03,0]],"id":43154455}],"con":true,"img":false}]}
{"op":"mcm","clk":"5306623372","pt":1646102287008,"mc":[{"id":"1.195395425","rc":[{"atb":[[14.5,0.21]],"id":43154455}],"con":true,"img":false}]}
{"op":"mcm","clk":"5306623746","pt":1646102293718,"mc":[{"id":"1.195395425","rc":[{"atl":[[2,0]],"id":43154454}],"con":true,"img":false}]}
{"op":"mcm","clk":"5306623759","pt":1646102293874,"mc":[{"id":"1.195395425","rc":[{"atl":[[1000,1.66]],"id":43154454}],"con":true,"img":false}]}
{"op":"mcm","clk":"5306623772","pt":1646102294179,"mc":[{"id":"1.195395425","rc":[{"atl":[[1000,0.39]],"id":43154454}],"con":true,"img":false}]}
{"op":"mcm","clk":"5306623797","pt":1646102294592,"mc":[{"id":"1.195395425","rc":[{"atl":[[1000,0]],"id":43154454}],"con":true,"img":false}]}
{"op":"mcm","clk":"5306623803","pt":1646102294694,"mc":[{"id":"1.195395425","rc":[{"atl":[[3.3,0.39]],"id":43154454}],"con":true,"img":false}]}
{"op":"mcm","clk":"5306623978","pt":1646102297605,"mc":[{"id":"1.195395425","rc":[{"atb":[[1.82,0]],"id":43154454}],"con":true,"img":false}]}
{"op":"mcm","clk":"5306624110","pt":1646102299499,"mc":[{"id":"1.195395425","rc":[{"atl":[[3.3,0]],"id":43154454}],"con":true,"img":false}]}
{"op":"mcm","clk":"5306624126","pt":1646102299703,"mc":[{"id":"1.195395425","rc":[{"atl":[[1000,1.66]],"id":43154454}],"con":true,"img":false}]}
{"op":"mcm","clk":"5306624145","pt":1646102300013,"mc":[{"id":"1.195395425","rc":[{"atl":[[1000,0.43]],"id":43154454}],"con":true,"img":false}]}
{"op":"mcm","clk":"5306624162","pt":1646102300321,"mc":[{"id":"1.195395425","rc":[{"atl":[[1000,0]],"id":43154454}],"con":true,"img":false}]}
{"op":"mcm","clk":"5306624168","pt":1646102300421,"mc":[{"id":"1.195395425","rc":[{"atl":[[2.96,0.43]],"id":43154454}],"con":true,"img":false}]}
{"op":"mcm","clk":"5306624330","pt":1646102303080,"mc":[{"id":"1.195395425","rc":[{"atb":[[1.82,7.79]],"id":43154454}],"con":true,"img":false}]}
{"op":"mcm","clk":"5306624916","pt":1646102313514,"mc":[{"id":"1.195395425","rc":[{"atb":[[8.2,0]],"id":38859241},{"atb":[[13.5,0]],"id":43154455}],"con":true,"img":false}]}
{"op":"mcm","clk":"5306624919","pt":1646102313615,"mc":[{"id":"1.195395425","rc":[{"atb":[[8.6,9.39]],"id":38859241},{"atb":[[14.5,4.68]],"id":43154455}],"con":true,"img":false}]}
{"op":"mcm","clk":"5306624932","pt":1646102313821,"mc":[{"id":"1.195395425","rc":[{"atb":[[9.6,0],[1.02,2.23]],"id":38859241}],"con":true,"img":false}]}
{"op":"mcm","clk":"5306624940","pt":1646102314025,"mc":[{"id":"1.195395425","rc":[{"atb":[[1.02,0.38]],"id":38859241}],"con":true,"img":false}]}
{"op":"mcm","clk":"5306624953","pt":1646102314229,"mc":[{"id":"1.195395425","rc":[{"atb":[[1.02,0]],"id":38859241}],"con":true,"img":false}]}
{"op":"mcm","clk":"5306624957","pt":1646102314331,"mc":[{"id":"1.195395425","rc":[{"atb":[[8.8,0.38]],"id":38859241}],"con":true,"img":false}]}
{"op":"mcm","clk":"5306625054","pt":1646102315916,"mc":[{"id":"1.195395425","rc":[{"atb":[[8.4,0]],"id":38859241},{"atb":[[14,0]],"id":43154455}],"con":true,"img":false}]}
{"op":"mcm","clk":"5306625260","pt":1646102319910,"mc":[{"id":"1.195395425","rc":[{"atb":[[8.8,12.27]],"id":38859241},{"atb":[[15,6.61]],"id":43154455}],"con":true,"img":false}]}
{"op":"mcm","clk":"5306625738","pt":1646102329024,"mc":[{"id":"1.195395425","rc":[{"atb":[[8.6,1.33]],"id":38859241},{"atb":[[14.5,0.21]],"id":43154455}],"con":true,"img":false}]}
{"op":"mcm","clk":"5306625742","pt":1646102329125,"mc":[{"id":"1.195395425","rc":[{"atb":[[8.2,8.06]],"id":38859241},{"atb":[[13.5,4.46]],"id":43154455}],"con":true,"img":false}]}
{"op":"mcm","clk":"5306625847","pt":1646102331121,"mc":[{"id":"1.195395425","rc":[{"atb":[[8.8,0.38]],"id":38859241},{"atb":[[15,0]],"id":43154455}],"con":true,"img":false}]}
{"op":"mcm","clk":"5306626049","pt":1646102335162,"mc":[{"id":"1.195395425","rc":[{"atb":[[8.4,12.52]],"id":38859241},{"atb":[[14,7.13]],"id":43154455}],"con":true,"img":false}]}
{"op":"mcm","clk":"5306627321","pt":1646102360101,"mc":[{"id":"1.195395425","rc":[{"atb":[[8.2,0]],"id":38859241},{"spn":15.2,"spf":1.0,"id":38859241},{"spn":2.34,"spf":1.0,"id":43154454},{"atb":[[13.5,0]],"id":43154455},{"spn":30.25,"spf":1.0,"id":43154455}],"con":true,"img":false}]}
{"op":"mcm","clk":"5306627326","pt":1646102360203,"mc":[{"id":"1.195395425","rc":[{"atb":[[8.6,9.39]],"id":38859241},{"atb":[[14.5,4.68]],"id":43154455}],"con":true,"img":false}]}
{"op":"mcm","clk":"5306627521","pt":1646102363887,"mc":[{"id":"1.195395425","rc":[{"atb":[[8.4,0]],"id":38859241},{"atb":[[14,0]],"id":43154455}],"con":true,"img":false}]}
{"op":"mcm","clk":"5306627723","pt":1646102367980,"mc":[{"id":"1.195395425","rc":[{"atb":[[8.8,12.27]],"id":38859241},{"atb":[[15,6.61]],"id":43154455}],"con":true,"img":false}]}
{"op":"mcm","clk":"5306628089","pt":1646102375485,"mc":[{"id":"1.195395425","rc":[{"atb":[[8.6,1.33]],"id":38859241},{"atb":[[14.5,0.21]],"id":43154455}],"con":true,"img":false}]}
{"op":"mcm","clk":"5306628092","pt":1646102375585,"mc":[{"id":"1.195395425","rc":[{"atb":[[8.2,8.06]],"id":38859241},{"atb":[[13.5,4.46]],"id":43154455}],"con":true,"img":false}]}
{"op":"mcm","clk":"5306628180","pt":1646102377730,"mc":[{"id":"1.195395425","rc":[{"atb":[[8.8,0.38]],"id":38859241},{"atb":[[15,0]],"id":43154455}],"con":true,"img":false}]}
{"op":"mcm","clk":"5306628349","pt":1646102381828,"mc":[{"id":"1.195395425","rc":[{"atb":[[8.4,12.52]],"id":38859241},{"atb":[[14,7.13]],"id":43154455}],"con":true,"img":false}]}
{"op":"mcm","clk":"5306628750","pt":1646102390748,"mc":[{"id":"1.195395425","rc":[{"atb":[[1.02,2.23],[8.8,0]],"id":38859241}],"con":true,"img":false}]}
{"op":"mcm","clk":"5306628756","pt":1646102390852,"mc":[{"id":"1.195395425","rc":[{"atb":[[1.03,2.23],[14.5,0]],"id":43154455}],"con":true,"img":false}]}
{"op":"mcm","clk":"5306628763","pt":1646102391056,"mc":[{"id":"1.195395425","rc":[{"atb":[[1.02,0.38]],"id":38859241},{"atb":[[1.03,0.21]],"id":43154455}],"con":true,"img":false}]}
{"op":"mcm","clk":"5306628773","pt":1646102391213,"mc":[{"id":"1.195395425","rc":[{"atb":[[1.03,0]],"id":43154455}],"con":true,"img":false}]}
{"op":"mcm","clk":"5306628777","pt":1646102391313,"mc":[{"id":"1.195395425","rc":[{"atb":[[17,0.21]],"id":43154455}],"con":true,"img":false}]}
{"op":"mcm","clk":"5306628786","pt":1646102391519,"mc":[{"id":"1.195395425","rc":[{"atb":[[1.02,0]],"id":38859241}],"con":true,"img":false}]}
{"op":"mcm","clk":"5306628789","pt":1646102391622,"mc":[{"id":"1.195395425","rc":[{"atb":[[9.6,0.38]],"id":38859241}],"con":true,"img":false}]}
{"op":"mcm","clk":"5306628841","pt":1646102392649,"mc":[{"id":"1.195395425","rc":[{"atl":[[6.8,2.97]],"id":42189480}],"con":true,"img":false}]}
{"op":"mcm","clk":"5306628849","pt":1646102392854,"mc":[{"id":"1.195395425","rc":[{"atl":[[2.92,6.92]],"id":43154454}],"con":true,"img":false}]}
{"op":"mcm","clk":"5306628929","pt":1646102394242,"mc":[{"id":"1.195395425","rc":[{"atl":[[2.92,13.1]],"id":43154454},{"atl":[[6.8,5.62]],"id":42189480}],"con":true,"img":false}]}
{"op":"mcm","clk":"5306629067","pt":1646102397163,"mc":[{"id":"1.195395425","rc":[{"atb":[[1.82,0]],"id":43154454}],"con":true,"img":false}]}
{"op":"mcm","clk":"5306629148","pt":1646102398750,"mc":[{"id":"1.195395425","rc":[{"atl":[[2.96,0]],"id":43154454}],"con":true,"img":false}]}
{"op":"mcm","clk":"5306629159","pt":1646102398954,"mc":[{"id":"1.195395425","rc":[{"atl":[[1000,1.66]],"id":43154454}],"con":true,"img":false}]}
{"op":"mcm","clk":"5306629169","pt":1646102399260,"mc":[{"id":"1.195395425","rc":[{"atl":[[1000,0.44]],"id":43154454}],"con":true,"img":false}]}
{"op":"mcm","clk":"5306629202","pt":1646102399824,"mc":[{"id":"1.195395425","rc":[{"atl":[[1000,0]],"id":43154454}],"con":true,"img":false}]}
{"op":"mcm","clk":"5306629209","pt":1646102399927,"mc":[{"id":"1.195395425","rc":[{"atl":[[2.9,0.44]],"id":43154454}],"con":true,"img":false}]}
{"op":"mcm","clk":"5306629244","pt":1646102400543,"mc":[{"id":"1.195395425","rc":[{"atb":[[1.82,7.79]],"id":43154454}],"con":true,"img":false}]}
{"op":"mcm","clk":"5306629454","pt":1646102404740,"mc":[{"id":"1.195395425","rc":[{"atl":[[2.86,0]],"id":43154454}],"con":true,"img":false}]}
{"op":"mcm","clk":"5306629462","pt":1646102404944,"mc":[{"id":"1.195395425","rc":[{"atl":[[2.9,1.8]],"id":43154454}],"con":true,"img":false}]}
{"op":"mcm","clk":"5306629472","pt":1646102405147,"mc":[{"id":"1.195395425","rc":[{"atl":[[1000,1.66]],"id":43154454}],"con":true,"img":false}]}
{"op":"mcm","clk":"5306629484","pt":1646102405454,"mc":[{"id":"1.195395425","rc":[{"atl":[[1000,0.45]],"id":43154454}],"con":true,"img":false}]}
{"op":"mcm","clk":"5306629496","pt":1646102405761,"mc":[{"id":"1.195395425","rc":[{"atl":[[1000,0]],"id":43154454}],"con":true,"img":false}]}
{"op":"mcm","clk":"5306629501","pt":1646102405862,"mc":[{"id":"1.195395425","rc":[{"atl":[[2.84,0.45]],"id":43154454}],"con":true,"img":false}]}
{"op":"mcm","clk":"5306629506","pt":1646102405965,"mc":[{"id":"1.195395425","rc":[{"atb":[[8.2,0]],"id":38859241},{"atb":[[13.5,0]],"id":43154455}],"con":true,"img":false}]}
{"op":"mcm","clk":"5306629510","pt":1646102406066,"mc":[{"id":"1.195395425","rc":[{"atb":[[8.6,9.39]],"id":38859241},{"atb":[[14.5,4.46]],"id":43154455}],"con":true,"img":false}]}
{"op":"mcm","clk":"5306629623","pt":1646102408673,"mc":[{"id":"1.195395425","rc":[{"atb":[[1.82,0]],"id":43154454}],"con":true,"img":false}]}
{"op":"mcm","clk":"5306629629","pt":1646102408877,"mc":[{"id":"1.195395425","rc":[{"atb":[[8.4,0]],"id":38859241},{"atb":[[14,0]],"id":43154455}],"con":true,"img":false}]}
{"op":"mcm","clk":"5306629681","pt":1646102410054,"mc":[{"id":"1.195395425","rc":[{"atb":[[1.03,2.89]],"id":36104892},{"atb":[[1.05,2.8]],"id":38859241},{"atb":[[1.02,3.19]],"id":43154454},{"atb":[[1.02,3]],"id":42189480}],"con":true,"img":false}]}
{"op":"mcm","clk":"5306629703","pt":1646102410565,"mc":[{"id":"1.195395425","rc":[{"atb":[[1.03,0.18]],"id":36104892},{"atb":[[1.05,0.1]],"id":38859241},{"atb":[[1.02,0.49]],"id":43154454},{"atb":[[1.02,0.29]],"id":42189480}],"con":true,"img":false}]}
{"op":"mcm","clk":"5306629726","pt":1646102411077,"mc":[{"id":"1.195395425","rc":[{"atb":[[1.05,0]],"id":38859241},{"atb":[[1.02,0]],"id":43154454},{"atb":[[1.02,0]],"id":42189480}],"con":true,"img":false}]}
{"op":"mcm","clk":"5306629730","pt":1646102411179,"mc":[{"id":"1.195395425","rc":[{"atb":[[1.03,0]],"id":36104892},{"atb":[[10.5,0.1]],"id":38859241},{"atb":[[2.16,0.49]],"id":43154454},{"atb":[[3.55,0.29]],"id":42189480}],"con":true,"img":false}]}
{"op":"mcm","clk":"5306629737","pt":1646102411280,"mc":[{"id":"1.195395425","rc":[{"atb":[[5.6,0.18]],"id":36104892}],"con":true,"img":false}]}
{"op":"mcm","clk":"5306629826","pt":1646102413078,"mc":[{"id":"1.195395425","rc":[{"atb":[[8.8,11.88]],"id":38859241},{"atb":[[15,6.61]],"id":43154455}],"con":true,"img":false}]}
{"op":"mcm","clk":"5306629856","pt":1646102413896,"mc":[{"id":"1.195395425","rc":[{"atb":[[1.82,7.79]],"id":43154454}],"con":true,"img":false}]}
{"op":"mcm","clk":"5306630193","pt":1646102420865,"mc":[{"id":"1.195395425","rc":[{"spn":7.6,"spf":1.0,"id":36104892},{"atb":[[8.6,1.33]],"id":38859241},{"spn":15.75,"spf":1.0,"id":38859241},{"spn":2.5,"spf":1.0,"id":43154454},{"atb":[[14.5,0]],"id":43154455},{"spn":30.5,"spf":1.0,"id":43154455},{"spn":4.32,"spf":1.0,"id":42189480}],"con":true,"img":false}]}
{"op":"mcm","clk":"5306630198","pt":1646102420969,"mc":[{"id":"1.195395425","rc":[{"atb":[[8.2,8.06]],"id":38859241},{"atb":[[13.5,4.46]],"id":43154455}],"con":true,"img":false}]}
{"op":"mcm","clk":"5306630399","pt":1646102424671,"mc":[{"id":"1.195395425","rc":[{"atb":[[8.8,0]],"id":38859241},{"atb":[[15,0]],"id":43154455}],"con":true,"img":false}]}
{"op":"mcm","clk":"5306630403","pt":1646102424771,"mc":[{"id":"1.195395425","rc":[{"atb":[[1.03,2.23]],"id":43154455}],"con":true,"img":false}]}
{"op":"mcm","clk":"5306630408","pt":1646102424873,"mc":[{"id":"1.195395425","rc":[{"atb":[[17,0]],"id":43154455}],"con":true,"img":false}]}
{"op":"mcm","clk":"5306630413","pt":1646102424974,"mc":[{"id":"1.195395425","rc":[{"atb":[[1.03,0.21]],"id":43154455}],"con":true,"img":false}]}
{"op":"mcm","clk":"5306630422","pt":1646102425177,"mc":[{"id":"1.195395425","rc":[{"atb":[[1.03,0]],"id":43154455}],"con":true,"img":false}]}
{"op":"mcm","clk":"5306630427","pt":1646102425280,"mc":[{"id":"1.195395425","rc":[{"atb":[[14,0.21]],"id":43154455}],"con":true,"img":false}]}
{"op":"mcm","clk":"5306630612","pt":1646102428666,"mc":[{"id":"1.195395425","rc":[{"atb":[[8.4,12.52]],"id":38859241},{"atb":[[14,7.34]],"id":43154455}],"con":true,"img":false}]}
{"op":"mcm","clk":"5306631035","pt":1646102435993,"mc":[{"id":"1.195395425","rc":[{"atl":[[2.98,0]],"id":43154454}],"con":true,"img":false}]}
{"op":"mcm","clk":"5306631039","pt":1646102436096,"mc":[{"id":"1.195395425","rc":[{"atl":[[2.9,31.71]],"id":43154454}],"con":true,"img":false}]}
{"op":"mcm","clk":"5306631102","pt":1646102437179,"mc":[{"id":"1.195395425","rc":[{"atl":[[2.88,4.22]],"id":43154454}],"con":true,"img":false}]}
{"op":"mcm","clk":"5306631268","pt":1646102440196,"mc":[{"id":"1.195395425","rc":[{"atb":[[1.82,0]],"id":43154454}],"con":true,"img":false}]}
{"op":"mcm","clk":"5306631300","pt":1646102440911,"mc":[{"id":"1.195395425","rc":[{"atl":[[2.9,29.91]],"id":43154454}],"con":true,"img":false}]}
{"op":"mcm","clk":"5306631311","pt":1646102441114,"mc":[{"id":"1.195395425","rc":[{"atl":[[2.86,1.82]],"id":43154454}],"con":true,"img":false}]}
{"op":"mcm","clk":"5306631518","pt":1646102445011,"mc":[{"id":"1.195395425","rc":[{"atl":[[2.88,0]],"id":43154454}],"con":true,"img":false}]}
{"op":"mcm","clk":"5306631539","pt":1646102445522,"mc":[{"id":"1.195395425","rc":[{"atb":[[1.82,8.13]],"id":43154454}],"con":true,"img":false}]}
{"op":"mcm","clk":"5306631864","pt":1646102451213,"mc":[{"id":"1.195395425","rc":[{"atb":[[8.2,0]],"id":38859241},{"atb":[[13.5,0]],"id":43154455},{"atl":[[7,0]],"id":42189480}],"con":true,"img":false}]}
{"op":"mcm","clk":"5306631870","pt":1646102451314,"mc":[{"id":"1.195395425","rc":[{"atb":[[8.6,9.39]],"id":38859241},{"atb":[[14.5,4.46]],"id":43154455},{"atl":[[6.6,18.35]],"id":42189480}],"con":true,"img":false}]}
{"op":"mcm","clk":"5306631963","pt":1646102453413,"mc":[{"id":"1.195395425","rc":[{"atb":[[8.4,0]],"id":38859241},{"atb":[[14,0.21]],"id":43154455}],"con":true,"img":false}]}
{"op":"mcm","clk":"5306632160","pt":1646102457409,"mc":[{"id":"1.195395425","rc":[{"atb":[[8.8,11.88]],"id":38859241},{"atb":[[15,6.61]],"id":43154455}],"con":true,"img":false}]}
{"op":"mcm","clk":"5306632524","pt":1646102465636,"mc":[{"id":"1.195395425","rc":[{"atb":[[8.6,1.33]],"id":38859241},{"atb":[[14.5,0]],"id":43154455}],"con":true,"img":false}]}
{"op":"mcm","clk":"5306632527","pt":1646102465738,"mc":[{"id":"1.195395425","rc":[{"atb":[[8.2,8.06]],"id":38859241},{"atb":[[13.5,4.46]],"id":43154455}],"con":true,"img":false}]}
{"op":"mcm","clk":"5306632655","pt":1646102468960,"mc":[{"id":"1.195395425","rc":[{"atb":[[8.8,0]],"id":38859241},{"atb":[[15,0]],"id":43154455}],"con":true,"img":false}]}
{"op":"mcm","clk":"5306632836","pt":1646102472948,"mc":[{"id":"1.195395425","rc":[{"atb":[[8.4,12.52]],"id":38859241},{"atb":[[14,7.34]],"id":43154455}],"con":true,"img":false}]}
{"op":"mcm","clk":"5306633900","pt":1646102496073,"mc":[{"id":"1.195395425","rc":[{"atb":[[8.2,0]],"id":38859241},{"atb":[[13.5,0]],"id":43154455},{"spn":30.25,"spf":1.0,"id":43154455}],"con":true,"img":false}]}
{"op":"mcm","clk":"5306633907","pt":1646102496174,"mc":[{"id":"1.195395425","rc":[{"atb":[[8.6,9.39]],"id":38859241},{"atb":[[14.5,4.46]],"id":43154455}],"con":true,"img":false}]}
{"op":"mcm","clk":"5306634041","pt":1646102499758,"mc":[{"id":"1.195395425","rc":[{"atb":[[8.4,0]],"id":38859241},{"atb":[[14,0.21]],"id":43154455}],"con":true,"img":false}]}
{"op":"mcm","clk":"5306634215","pt":1646102503905,"mc":[{"id":"1.195395425","rc":[{"atb":[[8.8,11.88]],"id":38859241},{"atb":[[15,6.61]],"id":43154455}],"con":true,"img":false}]}
{"op":"mcm","clk":"5306634545","pt":1646102511584,"mc":[{"id":"1.195395425","rc":[{"atl":[[2.92,6.92]],"id":43154454}],"con":true,"img":false}]}
{"op":"mcm","clk":"5306634551","pt":1646102511789,"mc":[{"id":"1.195395425","rc":[{"atb":[[8.6,1.33]],"id":38859241},{"atl":[[2.9,0]],"id":43154454},{"atb":[[14.5,0]],"id":43154455}],"con":true,"img":false}]}
{"op":"mcm","clk":"5306634556","pt":1646102511890,"mc":[{"id":"1.195395425","rc":[{"atb":[[8.2,8.06]],"id":38859241},{"atl":[[2.98,29.91]],"id":43154454},{"atb":[[13.5,4.46]],"id":43154455}],"con":true,"img":false}]}
{"op":"mcm","clk":"5306634594","pt":1646102512914,"mc":[{"id":"1.195395425","rc":[{"atl":[[2.92,0]],"id":43154454}],"con":true,"img":false}]}
{"op":"mcm","clk":"5306634668","pt":1646102514601,"mc":[{"id":"1.195395425","rc":[{"atl":[[6.8,2.97]],"id":42189480}],"con":true,"img":false}]}
{"op":"mcm","clk":"5306634677","pt":1646102514806,"mc":[{"id":"1.195395425","rc":[{"atb":[[1.82,0]],"id":43154454}],"con":true,"img":false}]}
{"op":"mcm","clk":"5306634708","pt":1646102515477,"mc":[{"id":"1.195395425","rc":[{"atb":[[8.8,0]],"id":38859241},{"atb":[[15,0]],"id":43154455}],"con":true,"img":false}]}
{"op":"mcm","clk":"5306634846","pt":1646102519223,"mc":[{"id":"1.195395425","rc":[{"atl":[[6.8,0]],"id":42189480}],"con":true,"img":false}]}
{"op":"mcm","clk":"5306634865","pt":1646102519589,"mc":[{"id":"1.195395425","rc":[{"atb":[[8.4,12.52]],"id":38859241},{"atb":[[14,7.34]],"id":43154455}],"con":true,"img":false}]}
{"op":"mcm","clk":"5306634868","pt":1646102519686,"mc":[{"id":"1.195395425","rc":[{"atb":[[1.82,8.13]],"id":43154454}],"con":true,"img":false}]}
{"op":"mcm","clk":"5306635071","pt":1646102524908,"mc":[{"id":"1.195395425","rc":[{"atl":[[2.84,0]],"id":43154454}],"con":true,"img":false}]}
{"op":"mcm","clk":"5306635076","pt":1646102525010,"mc":[{"id":"1.195395425","rc":[{"atb":[[1.8,61.98]],"id":36104892},{"atl":[[12.5,8.7]],"id":36104892},{"atb":[[4.6,27.78]],"id":38859241},{"atl":[[27,3.85]],"id":38859241},{"atb":[[1.75,133.33]],"id":43154454},{"atl":[[4,99.39]],"id":43154454},{"atb":[[6.2,19.23]],"id":43154455},{"atl":[[95,2]],"id":43154455},{"atb":[[8,14.29]],"id":39318320},{"atl":[[200,2.66]],"id":39318320},{"atb":[[9.8,11.36]],"id":38256919},{"atl":[[260,4.7]],"id":38256919},{"atb":[[2.4,71.43]],"id":42189480},{"atl":[[6.6,36.21]],"id":42189480}],"con":true,"img":false}]}
{"op":"mcm","clk":"5306635080","pt":1646102525112,"mc":[{"id":"1.195395425","rc":[{"atl":[[1000,1.66]],"id":43154454},{"atl":[[260,2.7],[350,2.37]],"id":38256919}],"con":true,"img":false}]}
{"op":"mcm","clk":"5306635084","pt":1646102525216,"mc":[{"id":"1.195395425","rc":[{"atl":[[260,4.7]],"id":38256919}],"con":true,"img":false}]}
{"op":"mcm","clk":"5306635090","pt":1646102525317,"mc":[{"id":"1.195395425","rc":[{"atl":[[350,0.37]],"id":38256919}],"con":true,"img":false}]}
{"op":"mcm","clk":"5306635096","pt":1646102525421,"mc":[{"id":"1.195395425","rc":[{"atl":[[1000,0.43]],"id":43154454}],"con":true,"img":false}]}
{"op":"mcm","clk":"5306635110","pt":1646102525730,"mc":[{"id":"1.195395425","rc":[{"atl":[[1000,0]],"id":43154454}],"con":true,"img":false}]}
{"op":"mcm","clk":"5306635116","pt":1646102525833,"mc":[{"id":"1.195395425","rc":[{"atl":[[2.96,0.43]],"id":43154454}],"con":true,"img":false}]}
{"op":"mcm","clk":"5306635273","pt":1646102529721,"mc":[{"id":"1.195395425","rc":[{"atb":[[1.82,0]],"id":43154454}],"con":true,"img":false}]}
{"op":"mcm","clk":"5306635507","pt":1646102535047,"mc":[{"id":"1.195395425","rc":[{"atb":[[1.82,8.13]],"id":43154454}],"con":true,"img":false}]}
{"op":"mcm","clk":"5306635736","pt":1646102541038,"mc":[{"id":"1.195395425","rc":[{"atb":[[1.03,2.23]],"id":43154455}],"con":true,"img":false}]}
{"op":"mcm","clk":"5306635740","pt":1646102541141,"mc":[{"id":"1.195395425","rc":[{"atb":[[1.03,0.21],[14,7.13]],"id":43154455}],"con":true,"img":false}]}
{"op":"mcm","clk":"5306635745","pt":1646102541344,"mc":[{"id":"1.195395425","rc":[{"atb":[[1.03,0]],"id":43154455}],"con":true,"img":false}]}
{"op":"mcm","clk":"5306635749","pt":1646102541447,"mc":[{"id":"1.195395425","rc":[{"atb":[[17,0.21]],"id":43154455}],"con":true,"img":false}]}
{"op":"mcm","clk":"5306636006","pt":1646102547511,"mc":[{"id":"1.195395425","rc":[{"atb":[[8.2,0]],"id":38859241},{"atb":[[13.5,0]],"id":43154455}],"con":true,"img":false}]}
{"op":"mcm","clk":"5306636011","pt":1646102547613,"mc":[{"id":"1.195395425","rc":[{"atb":[[8.6,9.39]],"id":38859241},{"atb":[[14.5,4.46]],"id":43154455}],"con":true,"img":false}]}
{"op":"mcm","clk":"5306636205","pt":1646102550959,"mc":[{"id":"1.195395425","rc":[{"atb":[[8.4,0]],"id":38859241},{"atb":[[14,0]],"id":43154455}],"con":true,"img":false}]}
{"op":"mcm","clk":"5306636397","pt":1646102555059,"mc":[{"id":"1.195395425","rc":[{"atb":[[8.8,11.88]],"id":38859241},{"atb":[[15,6.61]],"id":43154455}],"con":true,"img":false}]}
{"op":"mcm","clk":"5306636680","pt":1646102561461,"mc":[{"id":"1.195395425","rc":[{"atl":[[2.86,0]],"id":43154454},{"spn":2.56,"spf":1.0,"id":43154454},{"spn":30.5,"spf":1.0,"id":43154455}],"con":true,"img":false}]}
{"op":"mcm","clk":"5306636689","pt":1646102561664,"mc":[{"id":"1.195395425","rc":[{"atl":[[2.96,1.77]],"id":43154454}],"con":true,"img":false}]}
{"op":"mcm","clk":"5306636699","pt":1646102561869,"mc":[{"id":"1.195395425","rc":[{"atl":[[1000,1.66]],"id":43154454}],"con":true,"img":false}]}
{"op":"mcm","clk":"5306636715","pt":1646102562176,"mc":[{"id":"1.195395425","rc":[{"atl":[[1000,0.45]],"id":43154454}],"con":true,"img":false}]}
{"op":"mcm","clk":"5306636733","pt":1646102562435,"mc":[{"id":"1.195395425","rc":[{"atl":[[1000,0]],"id":43154454}],"con":true,"img":false}]}
{"op":"mcm","clk":"5306636740","pt":1646102562538,"mc":[{"id":"1.195395425","rc":[{"atl":[[2.84,0.45]],"id":43154454}],"con":true,"img":false}]}
{"op":"mcm","clk":"5306636887","pt":1646102565871,"mc":[{"id":"1.195395425","rc":[{"atb":[[1.82,0]],"id":43154454}],"con":true,"img":false}]}
{"op":"mcm","clk":"5306636892","pt":1646102565972,"mc":[{"id":"1.195395425","rc":[{"atl":[[13,0]],"id":36104892},{"atb":[[8.6,1.33]],"id":38859241},{"atb":[[14.5,0]],"id":43154455}],"con":true,"img":false}]}
{"op":"mcm","clk":"5306636896","pt":1646102566074,"mc":[{"id":"1.195395425","rc":[{"atl":[[12,10.82]],"id":36104892},{"atb":[[8.2,8.06]],"id":38859241},{"atb":[[13.5,4.46]],"id":43154455}],"con":true,"img":false}]}
{"op":"mcm","clk":"5306637009","pt":1646102568583,"mc":[{"id":"1.195395425","rc":[{"atb":[[8.8,0]],"id":38859241},{"atb":[[15,0]],"id":43154455}],"con":true,"img":false}]}
{"op":"mcm","clk":"5306637140","pt":1646102571051,"mc":[{"id":"1.195395425","rc":[{"atb":[[1.82,8.13]],"id":43154454}],"con":true,"img":false}]}
{"op":"mcm","clk":"5306637204","pt":1646102572578,"mc":[{"id":"1.195395425","rc":[{"atb":[[8.4,12.52]],"id":38859241},{"atb":[[14,7.13]],"id":43154455}],"con":true,"img":false}]}
{"op":"mcm","clk":"5306637215","pt":1646102572783,"mc":[{"id":"1.195395425","rc":[{"atb":[[1.03,2.23],[17,0]],"id":43154455}],"con":true,"img":false}]}
{"op":"mcm","clk":"5306637222","pt":1646102572986,"mc":[{"id":"1.195395425","rc":[{"atb":[[1.03,0.21]],"id":43154455}],"con":true,"img":false}]}
{"op":"mcm","clk":"5306637228","pt":1646102573144,"mc":[{"id":"1.195395425","rc":[{"atb":[[1.03,0]],"id":43154455}],"con":true,"img":false}]}
{"op":"mcm","clk":"5306637233","pt":1646102573248,"mc":[{"id":"1.195395425","rc":[{"atb":[[14.5,0.21]],"id":43154455}],"con":true,"img":false}]}
{"op":"mcm","clk":"5306637749","pt":1646102584276,"mc":[{"id":"1.195395425","rc":[{"atl":[[30,0]],"id":38859241}],"con":true,"img":false}]}
{"op":"mcm","clk":"5306637754","pt":1646102584379,"mc":[{"id":"1.195395425","rc":[{"atl":[[26,4.32]],"id":38859241}],"con":true,"img":false}]}
{"op":"mcm","clk":"5306638567","pt":1646102602316,"mc":[{"id":"1.195395425","rc":[{"atb":[[8.2,0]],"id":38859241},{"atb":[[13.5,0]],"id":43154455}],"con":true,"img":false}]}
{"op":"mcm","clk":"5306638573","pt":1646102602419,"mc":[{"id":"1.195395425","rc":[{"atb":[[8.6,9.39]],"id":38859241},{"atb":[[14.5,4.68]],"id":43154455}],"con":true,"img":false}]}
{"op":"mcm","clk":"5306638698","pt":1646102605493,"mc":[{"id":"1.195395425","rc":[{"atb":[[8.4,0]],"id":38859241},{"atb":[[14,0]],"id":43154455}],"con":true,"img":false}]}
{"op":"mcm","clk":"5306638853","pt":1646102609482,"mc":[{"id":"1.195395425","rc":[{"atb":[[8.8,11.88]],"id":38859241},{"atb":[[15,6.61]],"id":43154455}],"con":true,"img":false}]}
{"op":"mcm","clk":"5306639326","pt":1646102620537,"mc":[{"id":"1.195395425","rc":[{"atb":[[8.6,1.33]],"id":38859241},{"atb":[[14.5,0.21]],"id":43154455}],"con":true,"img":false}]}
{"op":"mcm","clk":"5306639330","pt":1646102620639,"mc":[{"id":"1.195395425","rc":[{"atb":[[8.2,8.06]],"id":38859241},{"atb":[[13.5,4.46]],"id":43154455}],"con":true,"img":false}]}
{"op":"mcm","clk":"5306639451","pt":1646102622844,"mc":[{"id":"1.195395425","rc":[{"atb":[[8.8,0]],"id":38859241},{"spn":2.5,"spf":1.0,"id":43154454},{"atb":[[15,0]],"id":43154455},{"spn":30.25,"spf":1.0,"id":43154455}],"con":true,"img":false}]}
{"op":"mcm","clk":"5306639653","pt":1646102626946,"mc":[{"id":"1.195395425","rc":[{"atb":[[8.4,12.52]],"id":38859241},{"atb":[[14,7.13]],"id":43154455}],"con":true,"img":false}]}
{"op":"mcm","clk":"5306640098","pt":1646102633576,"mc":[{"id":"1.195395425","rc":[{"atb":[[4.5,2],[3.4,0],[3.9,0],[3.65,0]],"id":36104892},{"atl":[[18,0],[21,0],[26,0],[15.5,0]],"id":36104892},{"atb":[[8,0],[9.4,0],[6,0],[7,0]],"id":38859241},{"atl":[[75,0],[150,0],[50,8.2],[100,0]],"id":38859241},{"atb":[[1.6,0],[1.7,0],[1.77,0],[1.65,0]],"id":43154454},{"atl":[[4,33.33],[4.5,0],[3.5,0],[3.75,0]],"id":43154454},{"atb":[[9.2,0],[10.5,0],[13,0],[16.5,0]],"id":43154455},{"atl":[[130,0],[280,0],[180,0],[230,0]],"id":43154455},{"atb":[[18,0],[23,0],[13,0],[15.5,0]],"id":39318320},{"atl":[[300,0],[350,0],[200,2],[250,0]],"id":39318320},{"atb":[[32,0],[21,0],[46,0],[26,0]],"id":38256919},{"atl":[[350,0],[400,0],[450,0],[500,0]],"id":38256919},{"atb":[[2.5,0],[2.6,0],[2.84,0],[2.7,0]],"id":42189480},{"atl":[[7.2,0],[9.2,0],[10.5,0],[8.2,0]],"id":42189480}],"con":true,"img":false}]}
{"op":"mcm","clk":"5306640205","pt":1646102635883,"mc":[{"id":"1.195395425","rc":[{"atb":[[4.5,30.98],[3.4,42.27],[3.9,34.98],[3.65,38.28]],"id":36104892},{"atl":[[18,7.77],[21,9.9],[26,7.92],[15.5,9.11]],"id":36104892},{"atb":[[8,14.49],[9.4,12.07],[6,20.29],[7,16.9]],"id":38859241},{"atl":[[75,1.78],[150,1.33],[50,10.89],[100,2]],"id":38859241},{"atb":[[1.6,169.09],[1.7,144.93],[1.77,131.76],[1.65,156.08]],"id":43154454},{"atl":[[4,99.39],[4.5,56.63],[3.5,52.85],[3.75,48.04]],"id":43154454},{"atb":[[9.2,12.37],[10.5,10.68],[13,8.45],[16.5,6.54]],"id":43154455},{"atl":[[130,1.02],[280,0.7],[180,0.73],[230,0.86]],"id":43154455},{"atb":[[18,5.96],[23,4.61],[13,8.45],[15.5,6.99]],"id":39318320},{"atl":[[300,0.66],[350,0.56],[200,2.66],[250,0.53]],"id":39318320},{"atb":[[32,3.27],[21,5.07],[46,2.25],[26,4.05]],"id":38256919},{"atl":[[350,0.37],[400,0.33],[450,0.44],[500,0.39]],"id":38256919},{"atb":[[2.5,67.63],[2.6,63.41],[2.84,55.13],[2.7,59.67]],"id":42189480},{"atl":[[7.2,21.31],[9.2,24.17],[10.5,20.86],[8.2,18.35]],"id":42189480}],"con":true,"img":false}]}
{"op":"mcm","clk":"5306640236","pt":1646102636546,"mc":[{"id":"1.195395425","rc":[{"atb":[[14,0]],"id":43154455}],"con":true,"img":false}]}
{"op":"mcm","clk":"5306640449","pt":1646102640544,"mc":[{"id":"1.195395425","rc":[{"atb":[[14,7.13]],"id":43154455}],"con":true,"img":false}]}
{"op":"mcm","clk":"5306641245","pt":1646102656076,"mc":[{"id":"1.195395425","rc":[{"atb":[[8.2,0]],"id":38859241}],"con":true,"img":false}]}
{"op":"mcm","clk":"5306641250","pt":1646102656180,"mc":[{"id":"1.195395425","rc":[{"atb":[[8.6,9.39]],"id":38859241}],"con":true,"img":false}]}
{"op":"mcm","clk":"5306641426","pt":1646102659406,"mc":[{"id":"1.195395425","rc":[{"atb":[[8.4,0]],"id":38859241}],"con":true,"img":false}]}
{"op":"mcm","clk":"5306641611","pt":1646102663300,"mc":[{"id":"1.195395425","rc":[{"atb":[[8.8,11.88]],"id":38859241}],"con":true,"img":false}]}
{"op":"mcm","clk":"5306642092","pt":1646102673397,"mc":[{"id":"1.195395425","rc":[{"atb":[[8.6,1.33]],"id":38859241},{"atb":[[13.5,0]],"id":43154455}],"con":true,"img":false}]}
{"op":"mcm","clk":"5306642096","pt":1646102673500,"mc":[{"id":"1.195395425","rc":[{"atb":[[8.2,8.06]],"id":38859241},{"atb":[[14.5,4.68]],"id":43154455}],"con":true,"img":false}]}
{"op":"mcm","clk":"5306642209","pt":1646102676569,"mc":[{"id":"1.195395425","rc":[{"atb":[[8.8,0]],"id":38859241},{"atb":[[14,0]],"id":43154455}],"con":true,"img":false}]}
{"op":"mcm","clk":"5306642367","pt":1646102680607,"mc":[{"id":"1.195395425","rc":[{"atb":[[8.4,12.52]],"id":38859241},{"atb":[[15,6.61]],"id":43154455}],"con":true,"img":false}]}
{"op":"mcm","clk":"5306642413","pt":1646102682087,"mc":[{"id":"1.195395425","rc":[{"atl":[[2.84,0]],"id":43154454}],"con":true,"img":false}]}
{"op":"mcm","clk":"5306642418","pt":1646102682291,"mc":[{"id":"1.195395425","rc":[{"atl":[[1000,1.66]],"id":43154454}],"con":true,"img":false}]}
{"op":"mcm","clk":"5306642426","pt":1646102682596,"mc":[{"id":"1.195395425","rc":[{"atl":[[1000,0.43]],"id":43154454}],"con":true,"img":false}]}
{"op":"mcm","clk":"5306642433","pt":1646102682803,"mc":[{"id":"1.195395425","rc":[{"atl":[[1000,0]],"id":43154454}],"con":true,"img":false}]}
{"op":"mcm","clk":"5306642437","pt":1646102682905,"mc":[{"id":"1.195395425","rc":[{"atl":[[2.96,2.2]],"id":43154454},{"spn":2.56,"spf":1.0,"id":43154454}],"con":true,"img":false}]}
{"op":"mcm","clk":"5306642670","pt":1646102690931,"mc":[{"id":"1.195395425","rc":[{"atb":[[14.5,0.21]],"id":43154455}],"con":true,"img":false}]}
{"op":"mcm","clk":"5306642677","pt":1646102691022,"mc":[{"id":"1.195395425","rc":[{"atb":[[13.5,4.46]],"id":43154455}],"con":true,"img":false}]}
{"op":"mcm","clk":"5306642818","pt":1646102694246,"mc":[{"id":"1.195395425","rc":[{"atb":[[15,0]],"id":43154455}],"con":true,"img":false}]}
{"op":"mcm","clk":"5306642947","pt":1646102698033,"mc":[{"id":"1.195395425","rc":[{"atb":[[14,7.13]],"id":43154455}],"con":true,"img":false}]}
{"op":"mcm","clk":"5306643318","pt":1646102707137,"mc":[{"id":"1.195395425","rc":[{"atl":[[9.6,22.47]],"id":36104892},{"atb":[[9.4,18.26]],"id":38859241},{"atl":[[21,9.66]],"id":38859241},{"atb":[[1.78,84.53]],"id":43154454},{"atl":[[2.98,42.7]],"id":43154454},{"atl":[[44,6.48]],"id":43154455},{"atb":[[26,7.08]],"id":39318320},{"atl":[[140,1.39]],"id":39318320},{"atl":[[200,1.12]],"id":38256919},{"atb":[[2.92,36.11]],"id":42189480},{"atl":[[5.1,20.22]],"id":42189480}],"con":true,"img":false}]}
{"op":"mcm","clk":"5306643322","pt":1646102707248,"mc":[{"id":"1.195395425","rc":[{"atl":[[140,3.39]],"id":39318320},{"atl":[[260,2.7],[200,3.12]],"id":38256919}],"con":true,"img":false}]}
{"op":"mcm","clk":"5306643325","pt":1646102707341,"mc":[{"id":"1.195395425","rc":[{"atl":[[200,0.66]],"id":39318320}],"con":true,"img":false}]}
{"op":"mcm","clk":"5306643374","pt":1646102708364,"mc":[{"id":"1.195395425","rc":[{"atb":[[8.2,0]],"id":38859241}],"con":true,"img":false}]}
{"op":"mcm","clk":"5306643377","pt":1646102708476,"mc":[{"id":"1.195395425","rc":[{"atb":[[8.6,9.39]],"id":38859241}],"con":true,"img":false}]}
{"op":"mcm","clk":"5306643508","pt":1646102711335,"mc":[{"id":"1.195395425","rc":[{"atb":[[8.4,0]],"id":38859241}],"con":true,"img":false}]}
{"op":"mcm","clk":"5306643539","pt":1646102712155,"mc":[{"id":"1.195395425","rc":[{"atl":[[2.98,46.9]],"id":43154454}],"con":true,"img":false}]}
{"op":"mcm","clk":"5306643640","pt":1646102715358,"mc":[{"id":"1.195395425","rc":[{"atb":[[8.8,11.88]],"id":38859241}],"con":true,"img":false}]}
{"op":"mcm","clk":"5306643658","pt":1646102715971,"mc":[{"id":"1.195395425","rc":[{"atb":[[2.9,4.83]],"id":42189480}],"con":true,"img":false}]}
{"op":"mcm","clk":"5306643847","pt":1646102721232,"mc":[{"id":"1.195395425","rc":[{"atb":[[1.03,2.23],[14.5,0]],"id":43154455}],"con":true,"img":false}]}
{"op":"mcm","clk":"5306643854","pt":1646102721436,"mc":[{"id":"1.195395425","rc":[{"atb":[[1.03,0.21]],"id":43154455}],"con":true,"img":false}]}
{"op":"mcm","clk":"5306643858","pt":1646102721539,"mc":[{"id":"1.195395425","rc":[{"atl":[[2.92,1.44]],"id":43154454}],"con":true,"img":false}]}
{"op":"mcm","clk":"5306643860","pt":1646102721639,"mc":[{"id":"1.195395425","rc":[{"atb":[[1.03,0]],"id":43154455}],"con":true,"img":false}]}
{"op":"mcm","clk":"5306643863","pt":1646102721741,"mc":[{"id":"1.195395425","rc":[{"atb":[[17,0.21]],"id":43154455}],"con":true,"img":false}]}
{"op":"mcm","clk":"5306643878","pt":1646102722050,"mc":[{"id":"1.195395425","rc":[{"atl":[[2.94,8.1]],"id":43154454}],"con":true,"img":false}]}
{"op":"mcm","clk":"5306643937","pt":1646102723683,"mc":[{"id":"1.195395425","rc":[{"atl":[[2.96,0.43]],"id":43154454}],"con":true,"img":false}]}
{"op":"mcm","clk":"5306643945","pt":1646102723837,"mc":[{"id":"1.195395425","rc":[{"atl":[[2.96,0]],"id":43154454}],"con":true,"img":false}]}
{"op":"mcm","clk":"5306643949","pt":1646102723940,"mc":[{"id":"1.195395425","rc":[{"atb":[[2.9,0]],"id":42189480}],"con":true,"img":false}]}
{"op":"mcm","clk":"5306643955","pt":1646102724143,"mc":[{"id":"1.195395425","rc":[{"atb":[[1.82,0]],"id":43154454},{"atl":[[1000,1.66],[2.9,1.8]],"id":43154454}],"con":true,"img":false}]}
{"op":"mcm","clk":"5306643960","pt":1646102724448,"mc":[{"id":"1.195395425","rc":[{"atl":[[1000,0.44]],"id":43154454}],"con":true,"img":false}]}
{"op":"mcm","clk":"5306643963","pt":1646102724550,"mc":[{"id":"1.195395425","rc":[{"atl":[[2.94,0]],"id":43154454}],"con":true,"img":false}]}
{"op":"mcm","clk":"5306643970","pt":1646102724755,"mc":[{"id":"1.195395425","rc":[{"atl":[[1000,0]],"id":43154454}],"con":true,"img":false}]}
{"op":"mcm","clk":"5306643972","pt":1646102724858,"mc":[{"id":"1.195395425","rc":[{"atl":[[2.9,2.24]],"id":43154454}],"con":true,"img":false}]}
{"op":"mcm","clk":"5306644029","pt":1646102726137,"mc":[{"id":"1.195395425","rc":[{"atb":[[8.6,1.33]],"id":38859241},{"atb":[[13.5,0]],"id":43154455}],"con":true,"img":false}]}
{"op":"mcm","clk":"5306644032","pt":1646102726240,"mc":[{"id":"1.195395425","rc":[{"atb":[[8.2,8.06]],"id":38859241},{"atb":[[14.5,4.46]],"id":43154455}],"con":true,"img":false}]}
{"op":"mcm","clk":"5306644049","pt":1646102726854,"mc":[{"id":"1.195395425","rc":[{"atb":[[2.92,29.12]],"id":42189480}],"con":true,"img":false}]}
{"op":"mcm","clk":"5306644053","pt":1646102726956,"mc":[{"id":"1.195395425","rc":[{"atb":[[2.92,21.64]],"id":42189480}],"con":true,"img":false}]}
{"op":"mcm","clk":"5306644130","pt":1646102728849,"mc":[{"id":"1.195395425","rc":[{"atb":[[8.8,0]],"id":38859241},{"atb":[[14,0]],"id":43154455}],"con":true,"img":false}]}
{"op":"mcm","clk":"5306644161","pt":1646102729668,"mc":[{"id":"1.195395425","rc":[{"atl":[[19.5,0.28]],"id":38859241},{"atb":[[1.82,8.13]],"id":43154454}],"con":true,"img":false}]}
{"op":"mcm","clk":"5306644202","pt":1646102730843,"mc":[{"id":"1.195395425","rc":[{"atb":[[2.94,16.45]],"id":42189480}],"con":true,"img":false}]}
{"op":"mcm","clk":"5306644237","pt":1646102732375,"mc":[{"id":"1.195395425","rc":[{"atb":[[2.88,12.03]],"id":42189480}],"con":true,"img":false}]}
{"op":"mcm","clk":"5306644276","pt":1646102733293,"mc":[{"id":"1.195395425","rc":[{"atb":[[8.4,12.52]],"id":38859241},{"atb":[[15,6.61]],"id":43154455}],"con":true,"img":false}]}
{"op":"mcm","clk":"5306644307","pt":1646102733751,"mc":[{"id":"1.195395425","rc":[{"atl":[[110,0.28]],"id":39318320},{"atb":[[2.92,0]],"id":42189480}],"con":true,"img":false}]}
{"op":"mcm","clk":"5306644312","pt":1646102733853,"mc":[{"id":"1.195395425","rc":[{"atb":[[2.94,38.1]],"id":42189480}],"con":true,"img":false}]}
{"op":"mcm","clk":"5306644406","pt":1646102736560,"mc":[{"id":"1.195395425","rc":[{"atl":[[140,2.41]],"id":39318320}],"con":true,"img":false}]}
{"op":"mcm","clk":"5306644408","pt":1646102736662,"mc":[{"id":"1.195395425","rc":[{"atl":[[140,0.41],[180,2],[110,1.52]],"id":39318320}],"con":true,"img":false}]}
{"op":"mcm","clk":"5306644430","pt":1646102737278,"mc":[{"id":"1.195395425","rc":[{"atb":[[2.94,21.64]],"id":42189480}],"con":true,"img":false}]}
{"op":"mcm","clk":"5306644469","pt":1646102738199,"mc":[{"id":"1.195395425","rc":[{"atl":[[4.5,0.28]],"id":42189480}],"con":true,"img":false}]}
{"op":"mcm","clk":"5306644555","pt":1646102741065,"mc":[{"id":"1.195395425","rc":[{"atb":[[2.96,16.45]],"id":42189480}],"con":true,"img":false}]}
{"op":"mcm","clk":"5306644593","pt":1646102742290,"mc":[{"id":"1.195395425","rc":[{"atl":[[9.2,0.28]],"id":36104892}],"con":true,"img":false}]}
{"op":"mcm","clk":"5306644602","pt":1646102742494,"mc":[{"id":"1.195395425","rc":[{"atl":[[180,0],[110,3.52]],"id":39318320}],"con":true,"img":false}]}
{"op":"mcm","clk":"5306644604","pt":1646102742597,"mc":[{"id":"1.195395425","rc":[{"atl":[[180,2]],"id":39318320}],"con":true,"img":false}]}
{"op":"mcm","clk":"5306644606","pt":1646102742700,"mc":[{"id":"1.195395425","rc":[{"atl":[[12.5,0],[9.8,11.36]],"id":36104892},{"atb":[[2.84,46.3],[4.6,0]],"id":38859241},{"atl":[[36,2.86],[27,0]],"id":38859241},{"atb":[[1.75,0],[1.65,309.93]],"id":43154454},{"atb":[[4,33.33],[6.2,0]],"id":43154455},{"atl":[[80,2],[95,0]],"id":43154455},{"atb":[[8,0],[3.8,35.71]],"id":39318320},{"atl":[[110,1.52]],"id":39318320},{"atb":[[9.8,0]],"id":38256919},{"atl":[[280,2],[200,1.12]],"id":38256919},{"atb":[[1.94,86.34],[2.4,0]],"id":42189480},{"atl":[[8.2,32.24],[6.6,18.35]],"id":42189480}],"con":true,"img":false}]}
{"op":"mcm","clk":"5306644612","pt":1646102742904,"mc":[{"id":"1.195395425","rc":[{"atb":[[14.5,0]],"id":43154455},{"atb":[[25,0]],"id":39318320}],"con":true,"img":false}]}
{"op":"mcm","clk":"5306644616","pt":1646102743008,"mc":[{"id":"1.195395425","rc":[{"spn":7.4,"spf":1.0,"id":36104892},{"spn":15.0,"spf":1.0,"id":38859241},{"spn":2.53,"spf":1.0,"id":43154454},{"atb":[[13.5,4.46]],"id":43154455},{"spn":30.5,"spf":1.0,"id":43154455},{"atb":[[27,2.7]],"id":39318320},{"atl":[[180,0],[110,3.52]],"id":39318320},{"spn":63.5,"spf":1.0,"id":39318320},{"spn":4.02,"spf":1.0,"id":42189480}],"con":true,"img":false}]}
{"op":"mcm","clk":"5306644640","pt":1646102743569,"mc":[{"id":"1.195395425","rc":[{"atb":[[26,5.41]],"id":39318320}],"con":true,"img":false}]}
{"op":"mcm","clk":"5306644654","pt":1646102743979,"mc":[{"id":"1.195395425","rc":[{"atb":[[26,0]],"id":39318320},{"atb":[[2.94,0]],"id":42189480}],"con":true,"img":false}]}
{"op":"mcm","clk":"5306644658","pt":1646102744080,"mc":[{"id":"1.195395425","rc":[{"atb":[[27,7.91]],"id":39318320},{"atb":[[2.96,38.1]],"id":42189480}],"con":true,"img":false}]}
{"op":"mcm","clk":"5306644663","pt":1646102744287,"mc":[{"id":"1.195395425","rc":[{"atb":[[2.88,0]],"id":42189480}],"con":true,"img":false}]}
{"op":"mcm","clk":"5306644696","pt":1646102745104,"mc":[{"id":"1.195395425","rc":[{"atb":[[15,0]],"id":43154455}],"con":true,"img":false}]}
{"op":"mcm","clk":"5306644751","pt":1646102746891,"mc":[{"id":"1.195395425","rc":[{"atb":[[2.96,21.64]],"id":42189480}],"con":true,"img":false}]}
{"op":"mcm","clk":"5306644808","pt":1646102748885,"mc":[{"id":"1.195395425","rc":[{"atb":[[14,7.13]],"id":43154455}],"con":true,"img":false}]}
{"op":"mcm","clk":"5306644829","pt":1646102749502,"mc":[{"id":"1.195395425","rc":[{"atb":[[2.88,12.03]],"id":42189480}],"con":true,"img":false}]}
{"op":"mcm","clk":"5306644863","pt":1646102751028,"mc":[{"id":"1.195395425","rc":[{"atb":[[2.88,55.92]],"id":42189480}],"con":true,"img":false}]}
{"op":"mcm","clk":"5306644907","pt":1646102752308,"mc":[{"id":"1.195395425","rc":[{"atl":[[2.98,42.7]],"id":43154454}],"con":true,"img":false}]}
{"op":"mcm","clk":"5306644910","pt":1646102752410,"mc":[{"id":"1.195395425","rc":[{"atb":[[5,3]],"id":36104892},{"atl":[[9.4,3.2]],"id":36104892},{"atb":[[9.6,3.68]],"id":38859241},{"atl":[[20,2.5]],"id":38859241},{"atl":[[2.9,5.2]],"id":43154454},{"atb":[[2.98,3]],"id":42189480},{"atl":[[5,3.68]],"id":42189480}],"con":true,"img":false}]}
{"op":"mcm","clk":"5306644972","pt":1646102753595,"mc":[{"id":"1.195395425","rc":[{"atl":[[2.9,3.4]],"id":43154454}],"con":true,"img":false}]}
{"op":"mcm","clk":"5306644974","pt":1646102753698,"mc":[{"id":"1.195395425","rc":[{"atl":[[9.6,6.74]],"id":36104892},{"atb":[[9.4,12.07]],"id":38859241},{"atl":[[21,2.9]],"id":38859241}],"con":true,"img":false}]}
{"op":"mcm","clk":"5306644982","pt":1646102753800,"mc":[{"id":"1.195395425","rc":[{"atl":[[2.88,1.82],[2.9,2.96]],"id":43154454},{"atb":[[3.8,0],[3.5,40]],"id":39318320}],"con":true,"img":false}]}
{"op":"mcm","clk":"5306644984","pt":1646102753911,"mc":[{"id":"1.195395425","rc":[{"atl":[[9.4,19.3]],"id":36104892},{"atb":[[9.6,9.23]],"id":38859241},{"atl":[[20,9.62]],"id":38859241}],"con":true,"img":false}]}
{"op":"mcm","clk":"5306644988","pt":1646102754003,"mc":[{"id":"1.195395425","rc":[{"atl":[[1000,1.66]],"id":43154454}],"con":true,"img":false}]}
{"op":"mcm","clk":"5306645000","pt":1646102754310,"mc":[{"id":"1.195395425","rc":[{"atl":[[1000,0.44]],"id":43154454}],"con":true,"img":false}]}
{"op":"mcm","clk":"5306645013","pt":1646102754618,"mc":[{"id":"1.195395425","rc":[{"atl":[[1000,0]],"id":43154454}],"con":true,"img":false}]}
{"op":"mcm","clk":"5306645017","pt":1646102754718,"mc":[{"id":"1.195395425","rc":[{"atl":[[2.88,2.26]],"id":43154454}],"con":true,"img":false}]}
{"op":"mcm","clk":"5306645032","pt":1646102754927,"mc":[{"id":"1.195395425","rc":[{"atb":[[4.9,2.29]],"id":36104892},{"atb":[[8.4,0]],"id":38859241},{"atl":[[2.86,8.34]],"id":43154454},{"atb":[[2.88,12.03]],"id":42189480}],"con":true,"img":false}]}
{"op":"mcm","clk":"5306645083","pt":1646102756412,"mc":[{"id":"1.195395425","rc":[{"atb":[[4.6,22.98]],"id":36104892}],"con":true,"img":false}]}
{"op":"mcm","clk":"5306645129","pt":1646102757696,"mc":[{"id":"1.195395425","rc":[{"atb":[[4.9,0]],"id":36104892},{"atb":[[1.82,0]],"id":43154454},{"atb":[[2.88,0]],"id":42189480}],"con":true,"img":false}]}
{"op":"mcm","clk":"5306645165","pt":1646102758823,"mc":[{"id":"1.195395425","rc":[{"atb":[[2.9,6.58]],"id":42189480}],"con":true,"img":false}]}
{"op":"mcm","clk":"5306645197","pt":1646102759742,"mc":[{"id":"1.195395425","rc":[{"atl":[[2.88,0.44]],"id":43154454}],"con":true,"img":false}]}
{"op":"mcm","clk":"5306645199","pt":1646102759841,"mc":[{"id":"1.195395425","rc":[{"atl":[[2.88,0]],"id":43154454}],"con":true,"img":false}]}
{"op":"mcm","clk":"5306645201","pt":1646102759945,"mc":[{"id":"1.195395425","rc":[{"atl":[[2.84,1.84]],"id":43154454}],"con":true,"img":false}]}
{"op":"mcm","clk":"5306645205","pt":1646102760099,"mc":[{"id":"1.195395425","rc":[{"atl":[[1000,1.66]],"id":43154454}],"con":true,"img":false}]}
{"op":"mcm","clk":"5306645215","pt":1646102760306,"mc":[{"id":"1.195395425","rc":[{"atl":[[1000,0.45]],"id":43154454}],"con":true,"img":false}]}
{"op":"mcm","clk":"5306645223","pt":1646102760613,"mc":[{"id":"1.195395425","rc":[{"atl":[[1000,0]],"id":43154454}],"con":true,"img":false}]}
{"op":"mcm","clk":"5306645228","pt":1646102760717,"mc":[{"id":"1.195395425","rc":[{"atl":[[2.84,2.29]],"id":43154454}],"con":true,"img":false}]}
{"op":"mcm","clk":"5306645252","pt":1646102761226,"mc":[{"id":"1.195395425","rc":[{"atl":[[2.86,0]],"id":43154454}],"con":true,"img":false}]}
{"op":"mcm","clk":"5306645261","pt":1646102761433,"mc":[{"id":"1.195395425","rc":[{"atl":[[2.82,8.45]],"id":43154454}],"con":true,"img":false}]}
{"op":"mcm","clk":"5306645364","pt":1646102764138,"mc":[{"id":"1.195395425","rc":[{"atb":[[1.2,2.23]],"id":43154455}],"con":true,"img":false}]}
{"op":"mcm","clk":"5306645376","pt":1646102764447,"mc":[{"id":"1.195395425","rc":[{"atb":[[1.2,1.67]],"id":43154455}],"con":true,"img":false}]}
{"op":"mcm","clk":"5306645386","pt":1646102764704,"mc":[{"id":"1.195395425","rc":[{"atb":[[1.2,0]],"id":43154455}],"con":true,"img":false}]}
{"op":"mcm","clk":"5306645389","pt":1646102764807,"mc":[{"id":"1.195395425","rc":[{"atb":[[14.5,1.67]],"id":43154455}],"con":true,"img":false}]}
{"op":"mcm","clk":"5306645396","pt":1646102765012,"mc":[{"id":"1.195395425","rc":[{"atb":[[1.82,8.13]],"id":43154454},{"atb":[[3,2.3]],"id":42189480}],"con":true,"img":false}]}
{"op":"mcm","clk":"5306645417","pt":1646102765727,"mc":[{"id":"1.195395425","rc":[{"atb":[[5.2,0],[2.62,0]],"id":38859241},{"atl":[[50,2.69]],"id":38859241},{"atb":[[1.36,0]],"id":43154454},{"atl":[[34,0],[5.8,0],[17,0]],"id":43154454},{"atb":[[12,0],[2.62,0],[4.2,0]],"id":39318320},{"atb":[[1.86,0]],"id":42189480},{"atl":[[17,0],[34,0],[13,0]],"id":42189480}],"con":true,"img":false}]}
{"op":"mcm","clk":"5306645422","pt":1646102765829,"mc":[{"id":"1.195395425","rc":[{"atb":[[2.8,0]],"id":36104892},{"atl":[[34,0],[36,0]],"id":36104892},{"atl":[[2.84,0.45]],"id":43154454},{"atb":[[2.62,0],[8.6,0],[4.2,0]],"id":43154455},{"atb":[[2.62,0],[4.2,0]],"id":38256919}],"con":true,"img":false}]}
{"op":"mcm","clk":"5306645428","pt":1646102766035,"mc":[{"id":"1.195395425","rc":[{"atl":[[2.84,0]],"id":43154454}],"con":true,"img":false}]}
{"op":"mcm","clk":"5306645436","pt":1646102766238,"mc":[{"id":"1.195395425","rc":[{"atl":[[2.82,0],[2.8,1.87],[1000,1.66]],"id":43154454}],"con":true,"img":false}]}
{"op":"mcm","clk":"5306645450","pt":1646102766544,"mc":[{"id":"1.195395425","rc":[{"atl":[[1000,0.45]],"id":43154454}],"con":true,"img":false}]}
{"op":"mcm","clk":"5306645467","pt":1646102766851,"mc":[{"id":"1.195395425","rc":[{"atb":[[5.1,2.5]],"id":36104892},{"atb":[[9.8,2.5]],"id":38859241},{"atb":[[1.83,2.5]],"id":43154454},{"atl":[[1000,0]],"id":43154454},{"atb":[[3.05,2.5]],"id":42189480}],"con":true,"img":false}]}
{"op":"mcm","clk":"5306645472","pt":1646102766952,"mc":[{"id":"1.195395425","rc":[{"atl":[[2.8,2.32]],"id":43154454}],"con":true,"img":false}]}
{"op":"mcm","clk":"5306645531","pt":1646102768743,"mc":[{"id":"1.195395425","rc":[{"atb":[[9.6,3.68]],"id":38859241}],"con":true,"img":false}]}
{"op":"mcm","clk":"5306645536","pt":1646102768844,"mc":[{"id":"1.195395425","rc":[{"atb":[[9.8,7.43]],"id":38859241}],"con":true,"img":false}]}
{"op":"mcm","clk":"5306645551","pt":1646102769252,"mc":[{"id":"1.195395425","rc":[{"atb":[[2.9,0]],"id":42189480}],"con":true,"img":false}]}
{"op":"mcm","clk":"5306645638","pt":1646102771918,"mc":[{"id":"1.195395425","rc":[{"atb":[[1.82,0]],"id":43154454},{"atb":[[3,0]],"id":42189480}],"con":true,"img":false}]}
{"op":"mcm","clk":"5306645647","pt":1646102772122,"mc":[{"id":"1.195395425","rc":[{"atb":[[4.6,20.43]],"id":36104892}],"con":true,"img":false}]}
{"op":"mcm","clk":"5306645681","pt":1646102772840,"mc":[{"id":"1.195395425","rc":[{"atl":[[2.92,0]],"id":43154454}],"con":true,"img":false}]}
{"op":"mcm","clk":"5306645743","pt":1646102774427,"mc":[{"id":"1.195395425","rc":[{"atb":[[2.88,13.06]],"id":42189480}],"con":true,"img":false}]}
{"op":"mcm","clk":"5306645785","pt":1646102775449,"mc":[{"id":"1.195395425","rc":[{"atl":[[2.76,1.44]],"id":43154454}],"con":true,"img":false}]}
{"op":"mcm","clk":"5306645862","pt":1646102777438,"mc":[{"id":"1.195395425","rc":[{"atb":[[1.2,2.23]],"id":42189480}],"con":true,"img":false}]}
{"op":"mcm","clk":"5306645867","pt":1646102777540,"mc":[{"id":"1.195395425","rc":[{"atb":[[13.5,0]],"id":43154455},{"atl":[[44,3.77]],"id":43154455}],"con":true,"img":false}]}
{"op":"mcm","clk":"5306645871","pt":1646102777644,"mc":[{"id":"1.195395425","rc":[{"atl":[[9.2,7.03],[9.8,0]],"id":36104892},{"atb":[[4,33.33],[2.84,0]],"id":38859241},{"atl":[[36,0],[27,3.85]],"id":38859241},{"atb":[[1.65,156.08],[1.76,131.58]],"id":43154454},{"atb":[[4,0],[5.8,20.83],[14.5,6.14]],"id":43154455},{"atl":[[42,2.7]],"id":43154455},{"atl":[[280,0],[210,2]],"id":38256919},{"atb":[[1.94,0],[2.34,52.84]],"id":42189480},{"atl":[[8.2,18.35],[7,16.67]],"id":42189480}],"con":true,"img":false}]}
{"op":"mcm","clk":"5306645873","pt":1646102777742,"mc":[{"id":"1.195395425","rc":[{"atb":[[1.2,1.96]],"id":42189480}],"con":true,"img":false}]}
{"op":"mcm","clk":"5306645886","pt":1646102778053,"mc":[{"id":"1.195395425","rc":[{"atb":[[1.2,0]],"id":42189480}],"con":true,"img":false}]}
{"op":"mcm","clk":"5306645890","pt":1646102778153,"mc":[{"id":"1.195395425","rc":[{"atb":[[3.1,1.96]],"id":42189480}],"con":true,"img":false}]}
{"op":"mcm","clk":"5306645894","pt":1646102778256,"mc":[{"id":"1.195395425","rc":[{"atl":[[2.8,0]],"id":43154454}],"con":true,"img":false}]}
{"op":"mcm","clk":"5306645900","pt":1646102778358,"mc":[{"id":"1.195395425","rc":[{"atb":[[1.79,3.59]],"id":43154454}],"con":true,"img":false}]}
{"op":"mcm","clk":"5306645904","pt":1646102778460,"mc":[{"id":"1.195395425","rc":[{"atl":[[2.74,1.91]],"id":43154454}],"con":true,"img":false}]}
{"op":"mcm","clk":"5306645908","pt":1646102778562,"mc":[{"id":"1.195395425","rc":[{"atl":[[1000,1.66]],"id":43154454}],"con":true,"img":false}]}
{"op":"mcm","clk":"5306645919","pt":1646102778818,"mc":[{"id":"1.195395425","rc":[{"atl":[[1000,0.46]],"id":43154454}],"con":true,"img":false}]}
{"op":"mcm","clk":"5306645929","pt":1646102779024,"mc":[{"id":"1.195395425","rc":[{"atb":[[3.05,0]],"id":42189480}],"con":true,"img":false}]}
{"op":"mcm","clk":"5306645935","pt":1646102779130,"mc":[{"id":"1.195395425","rc":[{"atl":[[1000,0]],"id":43154454}],"con":true,"img":false}]}
{"op":"mcm","clk":"5306645940","pt":1646102779229,"mc":[{"id":"1.195395425","rc":[{"atl":[[2.74,2.37]],"id":43154454}],"con":true,"img":false}]}
{"op":"mcm","clk":"5306645960","pt":1646102779636,"mc":[{"id":"1.195395425","rc":[{"atb":[[14,0]],"id":43154455}],"con":true,"img":false}]}
{"op":"mcm","clk":"5306645975","pt":1646102780046,"mc":[{"id":"1.195395425","rc":[{"atb":[[3.15,2.5]],"id":42189480}],"con":true,"img":false}]}
{"op":"mcm","clk":"5306646070","pt":1646102782358,"mc":[{"id":"1.195395425","rc":[{"atb":[[14.5,4.46]],"id":43154455}],"con":true,"img":false}]}
{"op":"mcm","clk":"5306646078","pt":1646102782563,"mc":[{"id":"1.195395425","rc":[{"atb":[[17,0],[1.03,2.23]],"id":43154455}],"con":true,"img":false}]}
{"op":"mcm","clk":"5306646084","pt":1646102782764,"mc":[{"id":"1.195395425","rc":[{"atb":[[1.03,0.21]],"id":43154455}],"con":true,"img":false}]}
{"op":"mcm","clk":"5306646095","pt":1646102782968,"mc":[{"id":"1.195395425","rc":[{"atb":[[1.03,0]],"id":43154455}],"con":true,"img":false}]}
{"op":"mcm","clk":"5306646099","pt":1646102783021,"mc":[{"id":"1.195395425","rc":[{"atb":[[15,0.21]],"id":43154455}],"con":true,"img":false}]}
{"op":"mcm","clk":"5306646113","pt":1646102783327,"mc":[{"id":"1.195395425","rc":[{"atb":[[15,6.83]],"id":43154455},{"atb":[[2.88,0]],"id":42189480}],"con":true,"img":false}]}
{"op":"mcm","clk":"5306646132","pt":1646102783735,"mc":[{"id":"1.195395425","rc":[{"atb":[[17,2.08]],"id":43154455}],"con":true,"img":false}]}
{"op":"mcm","clk":"5306646161","pt":1646102784959,"mc":[{"id":"1.195395425","rc":[{"atb":[[3.1,0]],"id":42189480}],"con":true,"img":false}]}
{"op":"mcm","clk":"5306646181","pt":1646102785469,"mc":[{"id":"1.195395425","rc":[{"atl":[[9.4,3.2]],"id":36104892},{"atl":[[44,0]],"id":43154455}],"con":true,"img":false}]}
{"op":"mcm","clk":"5306646188","pt":1646102785724,"mc":[{"id":"1.195395425","rc":[{"atl":[[9.2,23.53]],"id":36104892},{"atl":[[42,6.66]],"id":43154455}],"con":true,"img":false}]}
{"op":"mcm","clk":"5306646284","pt":1646102788638,"mc":[{"id":"1.195395425","rc":[{"atb":[[2.88,13.06]],"id":42189480}],"con":true,"img":false}]}
{"op":"mcm","clk":"5306646326","pt":1646102789970,"mc":[{"id":"1.195395425","rc":[{"atl":[[2.76,0]],"id":43154454}],"con":true,"img":false}]}
{"op":"mcm","clk":"5306646332","pt":1646102790172,"mc":[{"id":"1.195395425","rc":[{"atb":[[1.2,2.23]],"id":43154455}],"con":true,"img":false}]}
{"op":"mcm","clk":"5306646342","pt":1646102790479,"mc":[{"id":"1.195395425","rc":[{"atb":[[1.2,1.55]],"id":43154455}],"con":true,"img":false}]}
{"op":"mcm","clk":"5306646356","pt":1646102790738,"mc":[{"id":"1.195395425","rc":[{"atb":[[1.2,0]],"id":43154455}],"con":true,"img":false}]}
{"op":"mcm","clk":"5306646360","pt":1646102790843,"mc":[{"id":"1.195395425","rc":[{"atl":[[9.6,0]],"id":36104892},{"atl":[[21,0]],"id":38859241},{"atb":[[15.5,2.25]],"id":43154455},{"atb":[[27,5.2]],"id":39318320}],"con":true,"img":false}]}
{"op":"mcm","clk":"5306646365","pt":1646102790945,"mc":[{"id":"1.195395425","rc":[{"atl":[[9.2,30.28]],"id":36104892},{"atl":[[19.5,3.18]],"id":38859241},{"atb":[[28,2.7]],"id":39318320}],"con":true,"img":false}]}
{"op":"mcm","clk":"5306646369","pt":1646102791047,"mc":[{"id":"1.195395425","rc":[{"atb":[[3,3.08]],"id":42189480}],"con":true,"img":false}]}
{"op":"mcm","clk":"5306646428","pt":1646102792480,"mc":[{"id":"1.195395425","rc":[{"atb":[[5,0]],"id":36104892},{"atb":[[9.6,0.38]],"id":38859241},{"atl":[[20,7.12]],"id":38859241},{"atb":[[2.98,0]],"id":42189480}],"con":true,"img":false}]}
{"op":"mcm","clk":"5306646430","pt":1646102792530,"mc":[{"id":"1.195395425","rc":[{"atb":[[10,3.4]],"id":38859241}],"con":true,"img":false}]}
{"op":"mcm","clk":"5306646470","pt":1646102793557,"mc":[{"id":"1.195395425","rc":[{"atb":[[9.8,4.92]],"id":38859241}],"con":true,"img":false}]}
{"op":"mcm","clk":"5306646487","pt":1646102794068,"mc":[{"id":"1.195395425","rc":[{"atb":[[2.88,0]],"id":42189480}],"con":true,"img":false}]}
{"op":"mcm","clk":"5306646501","pt":1646102794581,"mc":[{"id":"1.195395425","rc":[{"atl":[[19.5,0.28]],"id":38859241}],"con":true,"img":false}]}
{"op":"mcm","clk":"5306646506","pt":1646102794680,"mc":[{"id":"1.195395425","rc":[{"atb":[[10.5,2.19]],"id":38859241},{"atl":[[21,2.9]],"id":38859241}],"con":true,"img":false}]}
{"op":"mcm","clk":"5306646548","pt":1646102796484,"mc":[{"id":"1.195395425","rc":[{"atl":[[2.72,1.44]],"id":43154454}],"con":true,"img":false}]}
{"op":"mcm","clk":"5306646554","pt":1646102796681,"mc":[{"id":"1.195395425","rc":[{"atb":[[3.1,11.18],[3.5,0]],"id":39318320}],"con":true,"img":false}]}
{"op":"mcm","clk":"5306646583","pt":1646102797549,"mc":[{"id":"1.195395425","rc":[{"atb":[[2.88,14.72]],"id":42189480}],"con":true,"img":false}]}
{"op":"mcm","clk":"5306646594","pt":1646102797856,"mc":[{"id":"1.195395425","rc":[{"atb":[[3,0]],"id":42189480}],"con":true,"img":false}]}
{"op":"mcm","clk":"5306646725","pt":1646102801872,"mc":[{"id":"1.195395425","rc":[{"atb":[[9.8,0]],"id":38859241},{"atl":[[2.74,0]],"id":43154454},{"atb":[[27,0]],"id":39318320}],"con":true,"img":false}]}
{"op":"mcm","clk":"5306646735","pt":1646102802074,"mc":[{"id":"1.195395425","rc":[{"atl":[[2.7,1.93]],"id":43154454}],"con":true,"img":false}]}
{"op":"mcm","clk":"5306646738","pt":1646102802177,"mc":[{"id":"1.195395425","rc":[{"atb":[[10.5,5.64]],"id":38859241},{"atb":[[28,7.71]],"id":39318320}],"con":true,"img":false}]}
{"op":"mcm","clk":"5306646743","pt":1646102802282,"mc":[{"id":"1.195395425","rc":[{"atl":[[1000,1.66]],"id":43154454}],"con":true,"img":false}]}
{"op":"mcm","clk":"5306654501","pt":1646102802765,"mc":[{"id":"1.195395425","rc":[{"atl":[[1000,0.47]],"id":43154454}],"con":true,"img":false}]}
{"op":"mcm","clk":"5306654510","pt":1646102802890,"mc":[{"id":"1.195395425","rc":[{"atl":[[1000,0]],"id":43154454}],"con":true,"img":false}]}
{"op":"mcm","clk":"5306654517","pt":1646102803005,"mc":[{"id":"1.195395425","rc":[{"atl":[[2.7,2.41]],"id":43154454},{"atb":[[2.98,3.36]],"id":42189480}],"con":true,"img":false}]}
{"op":"mcm","clk":"5306654571","pt":1646102804174,"mc":[{"id":"1.195395425","rc":[{"atl":[[2.62,1.44]],"id":43154454},{"spn":2.39,"spf":1.0,"id":43154454},{"spn":29.5,"spf":1.0,"id":43154455},{"spn":64.0,"spf":1.0,"id":39318320}],"con":true,"img":false}]}
{"op":"mcm","clk":"5306654623","pt":1646102805403,"mc":[{"id":"1.195395425","rc":[{"atb":[[1.79,0]],"id":43154454}],"con":true,"img":false}]}
{"op":"mcm","clk":"5306654774","pt":1646102808073,"mc":[{"id":"1.195395425","rc":[{"atl":[[2.7,0]],"id":43154454},{"atb":[[2.88,0]],"id":42189480}],"con":true,"img":false}]}
{"op":"mcm","clk":"5306654781","pt":1646102808278,"mc":[{"id":"1.195395425","rc":[{"atl":[[2.6,2.01]],"id":43154454}],"con":true,"img":false}]}
{"op":"mcm","clk":"5306654790","pt":1646102808482,"mc":[{"id":"1.195395425","rc":[{"atl":[[1000,1.66]],"id":43154454}],"con":true,"img":false}]}
{"op":"mcm","clk":"5306654793","pt":1646102808588,"mc":[{"id":"1.195395425","rc":[{"atb":[[4,0],[4.5,28.57]],"id":38859241},{"atb":[[5.8,0],[6.6,17.86]],"id":43154455},{"atb":[[4.3,12.97],[3.1,0]],"id":39318320},{"atb":[[2.34,0],[2.46,62.4]],"id":42189480}],"con":true,"img":false}]}
{"op":"mcm","clk":"5306654799","pt":1646102808788,"mc":[{"id":"1.195395425","rc":[{"atl":[[1000,0.49]],"id":43154454}],"con":true,"img":false}]}
{"op":"mcm","clk":"5306654808","pt":1646102809096,"mc":[{"id":"1.195395425","rc":[{"atl":[[1000,0]],"id":43154454}],"con":true,"img":false}]}
{"op":"mcm","clk":"5306654812","pt":1646102809197,"mc":[{"id":"1.195395425","rc":[{"atl":[[2.6,2.5]],"id":43154454}],"con":true,"img":false}]}
{"op":"mcm","clk":"5306654871","pt":1646102810681,"mc":[{"id":"1.195395425","rc":[{"atb":[[1.79,3.59]],"id":43154454}],"con":true,"img":false}]}
{"op":"mcm","clk":"5306654888","pt":1646102811190,"mc":[{"id":"1.195395425","rc":[{"atb":[[14.5,0]],"id":43154455},{"atl":[[200,0.81]],"id":38256919}],"con":true,"img":false}]}
{"op":"mcm","clk":"5306654895","pt":1646102811295,"mc":[{"id":"1.195395425","rc":[{"atb":[[13.5,4.46]],"id":43154455},{"atl":[[190,0.3],[250,2]],"id":38256919}],"con":true,"img":false}]}
{"op":"mcm","clk":"5306654902","pt":1646102811397,"mc":[{"id":"1.195395425","rc":[{"atl":[[1000,2.23]],"id":39318320},{"atl":[[210,0]],"id":38256919}],"con":true,"img":false}]}
{"op":"mcm","clk":"5306654908","pt":1646102811498,"mc":[{"id":"1.195395425","rc":[{"atl":[[1000,0.03]],"id":39318320},{"atl":[[210,2],[250,0]],"id":38256919}],"con":true,"img":false}]}
{"op":"mcm","clk":"5306654914","pt":1646102811599,"mc":[{"id":"1.195395425","rc":[{"atl":[[210,0],[250,2]],"id":38256919}],"con":true,"img":false}]}
{"op":"mcm","clk":"5306654918","pt":1646102811700,"mc":[{"id":"1.195395425","rc":[{"atl":[[1000,0]],"id":39318320},{"atl":[[210,2]],"id":38256919},{"atb":[[2.88,13.87]],"id":42189480}],"con":true,"img":false}]}
{"op":"mcm","clk":"5306654926","pt":1646102811804,"mc":[{"id":"1.195395425","rc":[{"atl":[[100,0.03]],"id":39318320},{"atl":[[250,0]],"id":38256919}],"con":true,"img":false}]}
{"op":"mcm","clk":"5306654946","pt":1646102812212,"mc":[{"id":"1.195395425","rc":[{"atl":[[2.62,0]],"id":43154454}],"con":true,"img":false}]}
{"op":"mcm","clk":"5306654992","pt":1646102813399,"mc":[{"id":"1.195395425","rc":[{"atb":[[15,0.21]],"id":43154455}],"con":true,"img":false}]}
{"op":"mcm","clk":"5306655075","pt":1646102816102,"mc":[{"id":"1.195395425","rc":[{"atl":[[2.72,0]],"id":43154454}],"con":true,"img":false}]}
{"op":"mcm","clk":"5306655116","pt":1646102817078,"mc":[{"id":"1.195395425","rc":[{"atb":[[14,7.13]],"id":43154455}],"con":true,"img":false}]}
{"op":"mcm","clk":"5306655153","pt":1646102818103,"mc":[{"id":"1.195395425","rc":[{"atl":[[200,0]],"id":38256919}],"con":true,"img":false}]}
{"op":"mcm","clk":"5306655158","pt":1646102818205,"mc":[{"id":"1.195395425","rc":[{"atb":[[15.5,0.7]],"id":43154455},{"atl":[[210,0],[250,2]],"id":38256919}],"con":true,"img":false}]}
{"op":"mcm","clk":"5306655167","pt":1646102818409,"mc":[{"id":"1.195395425","rc":[{"atl":[[190,1.16]],"id":38256919}],"con":true,"img":false}]}
{"op":"mcm","clk":"5306655373","pt":1646102823534,"mc":[{"id":"1.195395425","rc":[{"atb":[[1.2,2.23]],"id":43154455}],"con":true,"img":false}]}
{"op":"mcm","clk":"5306655385","pt":1646102823842,"mc":[{"id":"1.195395425","rc":[{"atb":[[1.2,1.67]],"id":43154455}],"con":true,"img":false}]}
{"op":"mcm","clk":"5306655396","pt":1646102824052,"mc":[{"id":"1.195395425","rc":[{"atl":[[2.54,1.44]],"id":43154454}],"con":true,"img":false}]}
{"op":"mcm","clk":"5306655400","pt":1646102824250,"mc":[{"id":"1.195395425","rc":[{"atb":[[1.2,0]],"id":43154455}],"con":true,"img":false}]}
{"op":"mcm","clk":"5306655404","pt":1646102824353,"mc":[{"id":"1.195395425","rc":[{"atb":[[14.5,1.67]],"id":43154455}],"con":true,"img":false}]}
{"op":"mcm","clk":"5306655459","pt":1646102825957,"mc":[{"id":"1.195395425","rc":[{"atl":[[2.6,0.49]],"id":43154454}],"con":true,"img":false}]}
{"op":"mcm","clk":"5306655461","pt":1646102826042,"mc":[{"id":"1.195395425","rc":[{"atl":[[2.6,0]],"id":43154454}],"con":true,"img":false}]}
{"op":"mcm","clk":"5306655465","pt":1646102826143,"mc":[{"id":"1.195395425","rc":[{"atl":[[2.52,2.07]],"id":43154454}],"con":true,"img":false}]}
{"op":"mcm","clk":"5306655471","pt":1646102826346,"mc":[{"id":"1.195395425","rc":[{"atl":[[1000,1.66]],"id":43154454}],"con":true,"img":false}]}
{"op":"mcm","clk":"5306655481","pt":1646102826552,"mc":[{"id":"1.195395425","rc":[{"atl":[[1000,0.5]],"id":43154454}],"con":true,"img":false}]}
{"op":"mcm","clk":"5306655492","pt":1646102826860,"mc":[{"id":"1.195395425","rc":[{"atl":[[1000,0]],"id":43154454}],"con":true,"img":false}]}
{"op":"mcm","clk":"5306655495","pt":1646102826960,"mc":[{"id":"1.195395425","rc":[{"atl":[[2.52,2.58]],"id":43154454}],"con":true,"img":false}]}
{"op":"mcm","clk":"5306655511","pt":1646102827370,"mc":[{"id":"1.195395425","rc":[{"atl":[[9.2,23.53]],"id":36104892}],"con":true,"img":false}]}
{"op":"mcm","clk":"5306655516","pt":1646102827473,"mc":[{"id":"1.195395425","rc":[{"atl":[[9,6.74]],"id":36104892}],"con":true,"img":false}]}
{"op":"mcm","clk":"5306655527","pt":1646102827679,"mc":[{"id":"1.195395425","rc":[{"atl":[[9.2,16.78],[8.8,6.75]],"id":36104892}],"con":true,"img":false}]}
{"op":"mcm","clk":"5306655648","pt":1646102830643,"mc":[{"id":"1.195395425","rc":[{"atb":[[1.79,0]],"id":43154454}],"con":true,"img":false}]}
{"op":"mcm","clk":"5306655727","pt":1646102832583,"mc":[{"id":"1.195395425","rc":[{"atl":[[9.4,0]],"id":36104892},{"atl":[[2.9,0]],"id":43154454}],"con":true,"img":false}]}
{"op":"mcm","clk":"5306655731","pt":1646102832635,"mc":[{"id":"1.195395425","rc":[{"atl":[[8.6,2.98]],"id":36104892},{"atb":[[3.15,5.5]],"id":42189480}],"con":true,"img":false}]}
{"op":"mcm","clk":"5306655779","pt":1646102833967,"mc":[{"id":"1.195395425","rc":[{"atl":[[2.54,0]],"id":43154454}],"con":true,"img":false}]}
{"op":"mcm","clk":"5306655838","pt":1646102835453,"mc":[{"id":"1.195395425","rc":[{"atl":[[2.44,1.44]],"id":43154454}],"con":true,"img":false}]}
{"op":"mcm","clk":"5306655850","pt":1646102835654,"mc":[{"id":"1.195395425","rc":[{"atb":[[1.79,3.59]],"id":43154454}],"con":true,"img":false}]}
{"op":"mcm","clk":"5306655876","pt":1646102836271,"mc":[{"id":"1.195395425","rc":[{"atb":[[2.88,0]],"id":42189480}],"con":true,"img":false}]}
{"op":"mcm","clk":"5306655950","pt":1646102838061,"mc":[{"id":"1.195395425","rc":[{"atl":[[2.52,0.5]],"id":43154454}],"con":true,"img":false}]}
{"op":"mcm","clk":"5306655960","pt":1646102838368,"mc":[{"id":"1.195395425","rc":[{"atl":[[2.42,2.16],[2.52,0]],"id":43154454}],"con":true,"img":false}]}
{"op":"mcm","clk":"5306655971","pt":1646102838574,"mc":[{"id":"1.195395425","rc":[{"atl":[[1000,1.66]],"id":43154454}],"con":true,"img":false}]}
{"op":"mcm","clk":"5306655982","pt":1646102838880,"mc":[{"id":"1.195395425","rc":[{"atl":[[1000,0.53]],"id":43154454}],"con":true,"img":false}]}
{"op":"mcm","clk":"5306655998","pt":1646102839185,"mc":[{"id":"1.195395425","rc":[{"atl":[[1000,0]],"id":43154454}],"con":true,"img":false}]}
{"op":"mcm","clk":"5306656003","pt":1646102839287,"mc":[{"id":"1.195395425","rc":[{"atl":[[2.42,2.69]],"id":43154454}],"con":true,"img":false}]}
{"op":"mcm","clk":"5306656033","pt":1646102839852,"mc":[{"id":"1.195395425","rc":[{"atl":[[9.2,0.28]],"id":36104892}],"con":true,"img":false}]}
{"op":"mcm","clk":"5306656045","pt":1646102840159,"mc":[{"id":"1.195395425","rc":[{"atl":[[8.8,24.09]],"id":36104892}],"con":true,"img":false}]}
{"op":"mcm","clk":"5306656174","pt":1646102843180,"mc":[{"id":"1.195395425","rc":[{"atb":[[1.79,0]],"id":43154454}],"con":true,"img":false}]}
{"op":"mcm","clk":"5306656224","pt":1646102844563,"mc":[{"id":"1.195395425","rc":[{"atb":[[13.5,0]],"id":43154455},{"atl":[[42,3.96]],"id":43154455},{"atl":[[260,0]],"id":38256919}],"con":true,"img":false}]}
{"op":"mcm","clk":"5306656229","pt":1646102844665,"mc":[{"id":"1.195395425","rc":[{"atb":[[14.5,6.14]],"id":43154455},{"atl":[[40,2.7]],"id":43154455},{"atl":[[240,2.7]],"id":38256919}],"con":true,"img":false}]}
{"op":"mcm","clk":"5306656343","pt":1646102847893,"mc":[{"id":"1.195395425","rc":[{"atb":[[14,0]],"id":43154455}],"con":true,"img":false}]}
{"op":"mcm","clk":"5306656401","pt":1646102849478,"mc":[{"id":"1.195395425","rc":[{"atb":[[1.79,3.59]],"id":43154454},{"atb":[[14.5,4.46]],"id":43154455}],"con":true,"img":false}]}
{"op":"mcm","clk":"5306656463","pt":1646102850961,"mc":[{"id":"1.195395425","rc":[{"atl":[[8.8,6.75]],"id":36104892}],"con":true,"img":false}]}
{"op":"mcm","clk":"5306656481","pt":1646102851371,"mc":[{"id":"1.195395425","rc":[{"atl":[[8.6,20.77]],"id":36104892}],"con":true,"img":false}]}
{"op":"mcm","clk":"5306656486","pt":1646102851472,"mc":[{"id":"1.195395425","rc":[{"atb":[[15,6.83]],"id":43154455}],"con":true,"img":false}]}
{"op":"mcm","clk":"5306656522","pt":1646102852392,"mc":[{"id":"1.195395425","rc":[{"atl":[[210,2],[250,0]],"id":38256919}],"con":true,"img":false}]}
{"op":"mcm","clk":"5306656770","pt":1646102859078,"mc":[{"id":"1.195395425","rc":[{"atl":[[42,0]],"id":43154455}],"con":true,"img":false}]}
{"op":"mcm","clk":"5306656787","pt":1646102859487,"mc":[{"id":"1.195395425","rc":[{"atl":[[40,6.86]],"id":43154455}],"con":true,"img":false}]}
{"op":"mcm","clk":"5306656801","pt":1646102860000,"mc":[{"id":"1.195395425","rc":[{"atl":[[2.44,0]],"id":43154454}],"con":true,"img":false}]}
{"op":"mcm","clk":"5306656842","pt":1646102860873,"mc":[{"id":"1.195395425","rc":[{"atl":[[9,0]],"id":36104892},{"atl":[[2.4,4.22]],"id":43154454},{"atl":[[190,0.86]],"id":38256919}],"con":true,"img":false}]}
{"op":"mcm","clk":"5306656846","pt":1646102860975,"mc":[{"id":"1.195395425","rc":[{"atl":[[9.6,6.74]],"id":36104892},{"atl":[[180,0.3],[210,0],[230,2]],"id":38256919}],"con":true,"img":false}]}
{"op":"mcm","clk":"5306656856","pt":1646102861182,"mc":[{"id":"1.195395425","rc":[{"atl":[[2.38,10.02]],"id":43154454}],"con":true,"img":false}]}
{"op":"mcm","clk":"5306656886","pt":1646102862205,"mc":[{"id":"1.195395425","rc":[{"atl":[[2.42,2.16]],"id":43154454}],"con":true,"img":false}]}
{"op":"mcm","clk":"5306656888","pt":1646102862307,"mc":[{"id":"1.195395425","rc":[{"atl":[[2.42,0]],"id":43154454}],"con":true,"img":false}]}
{"op":"mcm","clk":"5306656894","pt":1646102862511,"mc":[{"id":"1.195395425","rc":[{"atl":[[1000,1.66]],"id":43154454}],"con":true,"img":false}]}
{"op":"mcm","clk":"5306656899","pt":1646102862716,"mc":[{"id":"1.195395425","rc":[{"atl":[[2.36,2.22]],"id":43154454}],"con":true,"img":false}]}
{"op":"mcm","clk":"5306656904","pt":1646102862818,"mc":[{"id":"1.195395425","rc":[{"atl":[[1000,0.55]],"id":43154454}],"con":true,"img":false}]}
{"op":"mcm","clk":"5306656909","pt":1646102863023,"mc":[{"id":"1.195395425","rc":[{"atl":[[1000,0]],"id":43154454}],"con":true,"img":false}]}
{"op":"mcm","clk":"5306656911","pt":1646102863073,"mc":[{"id":"1.195395425","rc":[{"atl":[[2.36,2.77]],"id":43154454}],"con":true,"img":false}]}
{"op":"mcm","clk":"5306656914","pt":1646102863176,"mc":[{"id":"1.195395425","rc":[{"atl":[[2.36,4.21]],"id":43154454},{"atb":[[1.2,2.23]],"id":43154455}],"con":true,"img":false}]}
{"op":"mcm","clk":"5306656924","pt":1646102863483,"mc":[{"id":"1.195395425","rc":[{"atb":[[1.2,1.55]],"id":43154455}],"con":true,"img":false}]}
{"op":"mcm","clk":"5306656930","pt":1646102863687,"mc":[{"id":"1.195395425","rc":[{"atl":[[2.38,0]],"id":43154454},{"atb":[[1.2,0]],"id":43154455}],"con":true,"img":false}]}
{"op":"mcm","clk":"5306656933","pt":1646102863789,"mc":[{"id":"1.195395425","rc":[{"atb":[[15.5,2.25]],"id":43154455}],"con":true,"img":false}]}
{"op":"mcm","clk":"5306657007","pt":1646102865782,"mc":[{"id":"1.195395425","rc":[{"spn":7.1,"spf":1.0,"id":36104892},{"atb":[[1.79,0]],"id":43154454},{"spn":2.26,"spf":1.0,"id":43154454},{"spn":28.5,"spf":1.0,"id":43154455}],"con":true,"img":false}]}
{"op":"mcm","clk":"5306657095","pt":1646102867981,"mc":[{"id":"1.195395425","rc":[{"atl":[[2.36,2.77]],"id":43154454}],"con":true,"img":false}]}
{"op":"mcm","clk":"5306657103","pt":1646102868084,"mc":[{"id":"1.195395425","rc":[{"atl":[[2.36,2.22]],"id":43154454},{"atl":[[190,0]],"id":38256919}],"con":true,"img":false}]}
{"op":"mcm","clk":"5306657110","pt":1646102868187,"mc":[{"id":"1.195395425","rc":[{"atl":[[2.36,0]],"id":43154454}],"con":true,"img":false}]}
{"op":"mcm","clk":"5306657117","pt":1646102868289,"mc":[{"id":"1.195395425","rc":[{"atl":[[1000,1.66]],"id":43154454}],"con":true,"img":false}]}
{"op":"mcm","clk":"5306657121","pt":1646102868390,"mc":[{"id":"1.195395425","rc":[{"atl":[[180,1.21]],"id":38256919}],"con":true,"img":false}]}
{"op":"mcm","clk":"5306657126","pt":1646102868493,"mc":[{"id":"1.195395425","rc":[{"atl":[[2.34,2.23],[1000,0.55]],"id":43154454}],"con":true,"img":false}]}
{"op":"mcm","clk":"5306657133","pt":1646102868698,"mc":[{"id":"1.195395425","rc":[{"atl":[[2.4,0],[1000,0]],"id":43154454}],"con":true,"img":false}]}
{"op":"mcm","clk":"5306657139","pt":1646102868800,"mc":[{"id":"1.195395425","rc":[{"atl":[[2.34,2.79]],"id":43154454}],"con":true,"img":false}]}
{"op":"mcm","clk":"5306657178","pt":1646102869925,"mc":[{"id":"1.195395425","rc":[{"atl":[[2.3,1.44]],"id":43154454}],"con":true,"img":false}]}
{"op":"mcm","clk":"5306657219","pt":1646102871305,"mc":[{"id":"1.195395425","rc":[{"atb":[[1.79,3.59]],"id":43154454}],"con":true,"img":false}]}
{"op":"mcm","clk":"5306657225","pt":1646102871511,"mc":[{"id":"1.195395425","rc":[{"atb":[[1.03,2.23],[15,6.61]],"id":43154455}],"con":true,"img":false}]}
{"op":"mcm","clk":"5306657231","pt":1646102871714,"mc":[{"id":"1.195395425","rc":[{"atb":[[1.03,0.21]],"id":43154455}],"con":true,"img":false}]}
{"op":"mcm","clk":"5306657242","pt":1646102871922,"mc":[{"id":"1.195395425","rc":[{"atb":[[1.03,0]],"id":43154455}],"con":true,"img":false}]}
{"op":"mcm","clk":"5306657248","pt":1646102872023,"mc":[{"id":"1.195395425","rc":[{"atb":[[17.5,0.21]],"id":43154455}],"con":true,"img":false}]}
{"op":"mcm","clk":"5306657268","pt":1646102872489,"mc":[{"id":"1.195395425","rc":[{"atb":[[5.1,6.5]],"id":36104892}],"con":true,"img":false}]}
{"op":"mcm","clk":"5306657328","pt":1646102874224,"mc":[{"id":"1.195395425","rc":[{"atl":[[2.34,2.23]],"id":43154454}],"con":true,"img":false}]}
{"op":"mcm","clk":"5306657334","pt":1646102874427,"mc":[{"id":"1.195395425","rc":[{"atl":[[2.34,0],[1000,1.66]],"id":43154454}],"con":true,"img":false}]}
{"op":"mcm","clk":"5306657339","pt":1646102874582,"mc":[{"id":"1.195395425","rc":[{"atl":[[2.28,2.29]],"id":43154454}],"con":true,"img":false}]}
{"op":"mcm","clk":"5306657347","pt":1646102874786,"mc":[{"id":"1.195395425","rc":[{"atl":[[2.28,6.52],[1000,0.57]],"id":43154454}],"con":true,"img":false}]}
{"op":"mcm","clk":"5306657354","pt":1646102875096,"mc":[{"id":"1.195395425","rc":[{"atl":[[1000,0]],"id":43154454}],"con":true,"img":false}]}
{"op":"mcm","clk":"5306657358","pt":1646102875198,"mc":[{"id":"1.195395425","rc":[{"atl":[[2.28,7.1]],"id":43154454}],"con":true,"img":false}]}
{"op":"mcm","clk":"5306657405","pt":1646102876685,"mc":[{"id":"1.195395425","rc":[{"atb":[[15.5,0.7]],"id":43154455}],"con":true,"img":false}]}
{"op":"mcm","clk":"5306657451","pt":1646102878015,"mc":[{"id":"1.195395425","rc":[{"atb":[[14.5,0]],"id":43154455},{"atl":[[40,4.16]],"id":43154455}],"con":true,"img":false}]}
{"op":"mcm","clk":"5306657454","pt":1646102878116,"mc":[{"id":"1.195395425","rc":[{"atb":[[13.5,4.46]],"id":43154455},{"atl":[[42,2.7]],"id":43154455}],"con":true,"img":false}]}
{"op":"mcm","clk":"5306657492","pt":1646102879091,"mc":[{"id":"1.195395425","rc":[{"atb":[[1.79,0]],"id":43154454}],"con":true,"img":false}]}
{"op":"mcm","clk":"5306657518","pt":1646102880013,"mc":[{"id":"1.195395425","rc":[{"atb":[[15,0]],"id":43154455}],"con":true,"img":false}]}
{"op":"mcm","clk":"5306657526","pt":1646102880217,"mc":[{"id":"1.195395425","rc":[{"atl":[[2.28,6.52]],"id":43154454}],"con":true,"img":false}]}
{"op":"mcm","clk":"5306657532","pt":1646102880321,"mc":[{"id":"1.195395425","rc":[{"atl":[[2.28,4.22]],"id":43154454}],"con":true,"img":false}]}
{"op":"mcm","clk":"5306657536","pt":1646102880424,"mc":[{"id":"1.195395425","rc":[{"atl":[[1000,1.66]],"id":43154454}],"con":true,"img":false}]}
{"op":"mcm","clk":"5306657546","pt":1646102880733,"mc":[{"id":"1.195395425","rc":[{"atl":[[2.26,2.31],[1000,0.58]],"id":43154454}],"con":true,"img":false}]}
{"op":"mcm","clk":"5306657559","pt":1646102881042,"mc":[{"id":"1.195395425","rc":[{"atl":[[1000,0]],"id":43154454}],"con":true,"img":false}]}
{"op":"mcm","clk":"5306657566","pt":1646102881094,"mc":[{"id":"1.195395425","rc":[{"atl":[[2.26,2.89]],"id":43154454}],"con":true,"img":false}]}
{"op":"mcm","clk":"5306657571","pt":1646102881198,"mc":[{"id":"1.195395425","rc":[{"atl":[[2.24,10.65]],"id":43154454}],"con":true,"img":false}]}
{"op":"mcm","clk":"5306657617","pt":1646102882122,"mc":[{"id":"1.195395425","rc":[{"atl":[[2.28,0]],"id":43154454}],"con":true,"img":false}]}
{"op":"mcm","clk":"5306657648","pt":1646102882945,"mc":[{"id":"1.195395425","rc":[{"atl":[[2.3,0]],"id":43154454}],"con":true,"img":false}]}
{"op":"mcm","clk":"5306657678","pt":1646102883514,"mc":[{"id":"1.195395425","rc":[{"atb":[[14,7.13]],"id":43154455}],"con":true,"img":false}]}
{"op":"mcm","clk":"5306657719","pt":1646102884641,"mc":[{"id":"1.195395425","rc":[{"atb":[[1.79,3.59]],"id":43154454}],"con":true,"img":false}]}
{"op":"mcm","clk":"5306657736","pt":1646102885000,"mc":[{"id":"1.195395425","rc":[{"atl":[[2.22,4.22]],"id":43154454}],"con":true,"img":false}]}
{"op":"mcm","clk":"5306657763","pt":1646102885617,"mc":[{"id":"1.195395425","rc":[{"atl":[[2.24,0]],"id":43154454}],"con":true,"img":false}]}
{"op":"mcm","clk":"5306657776","pt":1646102885924,"mc":[{"id":"1.195395425","rc":[{"atb":[[1.83,0]],"id":43154454}],"con":true,"img":false}]}
{"op":"mcm","clk":"5306657789","pt":1646102886231,"mc":[{"id":"1.195395425","rc":[{"atl":[[2.26,2.31]],"id":43154454},{"atl":[[210,2],[230,0]],"id":38256919}],"con":true,"img":false}]}
{"op":"mcm","clk":"5306657793","pt":1646102886338,"mc":[{"id":"1.195395425","rc":[{"atl":[[2.26,0]],"id":43154454}],"con":true,"img":false}]}
{"op":"mcm","clk":"5306657798","pt":1646102886440,"mc":[{"id":"1.195395425","rc":[{"atl":[[1000,1.66]],"id":43154454}],"con":true,"img":false}]}
{"op":"mcm","clk":"5306657803","pt":1646102886644,"mc":[{"id":"1.195395425","rc":[{"atl":[[1000,0.6]],"id":43154454}],"con":true,"img":false}]}
{"op":"mcm","clk":"5306657806","pt":1646102886747,"mc":[{"id":"1.195395425","rc":[{"atl":[[2.2,2.37]],"id":43154454}],"con":true,"img":false}]}
{"op":"mcm","clk":"5306657813","pt":1646102886902,"mc":[{"id":"1.195395425","rc":[{"atl":[[1000,0]],"id":43154454}],"con":true,"img":false}]}
{"op":"mcm","clk":"5306657818","pt":1646102887004,"mc":[{"id":"1.195395425","rc":[{"atl":[[2.2,2.98]],"id":43154454}],"con":true,"img":false}]}
{"op":"mcm","clk":"5306657829","pt":1646102887208,"mc":[{"id":"1.195395425","rc":[{"atb":[[1.82,2.5]],"id":43154454},{"atl":[[2.18,10.94]],"id":43154454}],"con":true,"img":false}]}
{"op":"mcm","clk":"5306657873","pt":1646102888436,"mc":[{"id":"1.195395425","rc":[{"atb":[[1.82,0]],"id":43154454}],"con":true,"img":false}]}
{"op":"mcm","clk":"5306657939","pt":1646102890327,"mc":[{"id":"1.195395425","rc":[{"atb":[[4.6,16.11]],"id":36104892}],"con":true,"img":false}]}
{"op":"mcm","clk":"5306658034","pt":1646102892324,"mc":[{"id":"1.195395425","rc":[{"atl":[[2.2,0.6]],"id":43154454}],"con":true,"img":false}]}
{"op":"mcm","clk":"5306658039","pt":1646102892428,"mc":[{"id":"1.195395425","rc":[{"atl":[[2.2,0]],"id":43154454}],"con":true,"img":false}]}
{"op":"mcm","clk":"5306658047","pt":1646102892531,"mc":[{"id":"1.195395425","rc":[{"atl":[[2.22,0]],"id":43154454}],"con":true,"img":false}]}
{"op":"mcm","clk":"5306658050","pt":1646102892632,"mc":[{"id":"1.195395425","rc":[{"atl":[[1000,1.66]],"id":43154454}],"con":true,"img":false}]}
{"op":"mcm","clk":"5306658057","pt":1646102892737,"mc":[{"id":"1.195395425","rc":[{"atb":[[2.16,0]],"id":43154454},{"atl":[[2.16,1.92]],"id":43154454},{"trd":[[2.16,0.98]],"ltp":2.16,"tv":0.98,"id":43154454}],"con":true,"img":false}]}
{"op":"mcm","clk":"5306658063","pt":1646102892838,"mc":[{"id":"1.195395425","rc":[{"atb":[[1.02,2.23]],"id":38859241},{"atb":[[1.75,133.33],[1.76,0]],"id":43154454}],"con":true,"img":false}]}
{"op":"mcm","clk":"5306658069","pt":1646102892941,"mc":[{"id":"1.195395425","rc":[{"atb":[[9.6,0]],"id":38859241}],"con":true,"img":false}]}
{"op":"mcm","clk":"5306658077","pt":1646102893043,"mc":[{"id":"1.195395425","rc":[{"atb":[[1.02,0.33]],"id":38859241},{"atl":[[1000,0.6]],"id":43154454}],"con":true,"img":false}]}
{"op":"mcm","clk":"5306658088","pt":1646102893249,"mc":[{"id":"1.195395425","rc":[{"atb":[[1.02,0]],"id":38859241}],"con":true,"img":false}]}
{"op":"mcm","clk":"5306658093","pt":1646102893352,"mc":[{"id":"1.195395425","rc":[{"atb":[[11,0.33]],"id":38859241},{"atl":[[1000,0]],"id":43154454}],"con":true,"img":false}]}
{"op":"mcm","clk":"5306658097","pt":1646102893454,"mc":[{"id":"1.195395425","rc":[{"atl":[[2.16,2.53]],"id":43154454}],"con":true,"img":false}]}
{"op":"mcm","clk":"5306658120","pt":1646102893918,"mc":[{"id":"1.195395425","rc":[{"atl":[[2.18,0]],"id":43154454}],"con":true,"img":false}]}
{"op":"mcm","clk":"5306658131","pt":1646102894122,"mc":[{"id":"1.195395425","rc":[{"atb":[[1.82,4.22]],"id":43154454}],"con":true,"img":false}]}
{"op":"mcm","clk":"5306658147","pt":1646102894531,"mc":[{"id":"1.195395425","rc":[{"atb":[[1.82,12.57]],"id":43154454}],"con":true,"img":false}]}
{"op":"mcm","clk":"5306658236","pt":1646102896526,"mc":[{"id":"1.195395425","rc":[{"atb":[[1.79,0]],"id":43154454}],"con":true,"img":false}]}
{"op":"mcm","clk":"5306658348","pt":1646102899341,"mc":[{"id":"1.195395425","rc":[{"atb":[[1.82,4.22]],"id":43154454}],"con":true,"img":false}]}
{"op":"mcm","clk":"5306658503","pt":1646102902726,"mc":[{"id":"1.195395425","rc":[{"atb":[[1.79,7.39]],"id":43154454}],"con":true,"img":false}]}
{"op":"mcm","clk":"5306658511","pt":1646102902931,"mc":[{"id":"1.195395425","rc":[{"atl":[[9,12.5]],"id":36104892},{"atb":[[1.78,212.74]],"id":43154454},{"atl":[[230,2]],"id":38256919}],"con":true,"img":false}]}
{"op":"mcm","clk":"5306658515","pt":1646102903033,"mc":[{"id":"1.195395425","rc":[{"atl":[[8.8,0]],"id":36104892},{"atb":[[1.75,0]],"id":43154454},{"atl":[[210,0]],"id":38256919}],"con":true,"img":false}]}
{"op":"mcm","clk":"5306658846","pt":1646102910378,"mc":[{"id":"1.195395425","rc":[{"atl":[[21,0]],"id":38859241},{"atb":[[13.5,0]],"id":43154455},{"atl":[[180,0.9],[240,0]],"id":38256919}],"con":true,"img":false}]}
{"op":"mcm","clk":"5306658848","pt":1646102910481,"mc":[{"id":"1.195395425","rc":[{"atl":[[19.5,3.18]],"id":38859241},{"atb":[[14.5,4.46]],"id":43154455},{"atl":[[350,2.37],[170,0.3],[220,2.7],[230,0]],"id":38256919}],"con":true,"img":false}]}
{"op":"mcm","clk":"5306658921","pt":1646102912070,"mc":[{"id":"1.195395425","rc":[{"atb":[[2.96,0]],"id":42189480}],"con":true,"img":false}]}
{"op":"mcm","clk":"5306658930","pt":1646102912276,"mc":[{"id":"1.195395425","rc":[{"atb":[[14,0]],"id":43154455}],"con":true,"img":false}]}
{"op":"mcm","clk":"5306658957","pt":1646102913041,"mc":[{"id":"1.195395425","rc":[{"atb":[[2.98,25]],"id":42189480}],"con":true,"img":false}]}
{"op":"mcm","clk":"5306659076","pt":1646102915654,"mc":[{"id":"1.195395425","rc":[{"atb":[[15,6.61]],"id":43154455}],"con":true,"img":false}]}
{"op":"mcm","clk":"5306659120","pt":1646102916679,"mc":[{"id":"1.195395425","rc":[{"atb":[[2.98,21.64]],"id":42189480}],"con":true,"img":false}]}
{"op":"mcm","clk":"5306659349","pt":1646102922264,"mc":[{"id":"1.195395425","rc":[{"atb":[[3,6.38]],"id":42189480}],"con":true,"img":false}]}
{"op":"mcm","clk":"5306659438","pt":1646102924267,"mc":[{"id":"1.195395425","rc":[{"atl":[[20,0]],"id":38859241},{"atl":[[180,0]],"id":38256919}],"con":true,"img":false}]}
{"op":"mcm","clk":"5306659458","pt":1646102924881,"mc":[{"id":"1.195395425","rc":[{"atl":[[19.5,10.49]],"id":38859241},{"atl":[[170,1.27]],"id":38256919}],"con":true,"img":false}]}
{"op":"mcm","clk":"5306659536","pt":1646102926671,"mc":[{"id":"1.195395425","rc":[{"atl":[[9.6,0]],"id":36104892},{"spn":15.25,"spf":1.0,"id":38859241},{"spn":1.99,"spf":1.0,"id":43154454},{"atb":[[14.5,0]],"id":43154455},{"spn":28.75,"spf":1.0,"id":43154455},{"atl":[[220,0]],"id":38256919}],"con":true,"img":false}]}
{"op":"mcm","clk":"5306659543","pt":1646102926773,"mc":[{"id":"1.195395425","rc":[{"atl":[[8.8,6.74]],"id":36104892},{"atb":[[13.5,4.46]],"id":43154455},{"atl":[[260,2.7]],"id":38256919}],"con":true,"img":false}]}
{"op":"mcm","clk":"5306659660","pt":1646102929999,"mc":[{"id":"1.195395425","rc":[{"atb":[[15,0]],"id":43154455}],"con":true,"img":false}]}
{"op":"mcm","clk":"5306659787","pt":1646102933304,"mc":[{"id":"1.195395425","rc":[{"atb":[[14,7.13]],"id":43154455}],"con":true,"img":false}]}
{"op":"mcm","clk":"5306659879","pt":1646102935813,"mc":[{"id":"1.195395425","rc":[{"atb":[[2.98,0]],"id":42189480}],"con":true,"img":false}]}
{"op":"mcm","clk":"5306659902","pt":1646102936274,"mc":[{"id":"1.195395425","rc":[{"atb":[[3,27.73]],"id":42189480}],"con":true,"img":false}]}
{"op":"mcm","clk":"5306660035","pt":1646102939910,"mc":[{"id":"1.195395425","rc":[{"atb":[[3,21.34]],"id":42189480}],"con":true,"img":false}]}
{"op":"mcm","clk":"5306660139","pt":1646102942376,"mc":[{"id":"1.195395425","rc":[{"atb":[[1.66,0]],"id":43154454},{"atl":[[2.98,12.79]],"id":43154454}],"con":true,"img":false}]}
{"op":"mcm","clk":"5306660146","pt":1646102942480,"mc":[{"id":"1.195395425","rc":[{"atb":[[1.71,189.38]],"id":43154454},{"atl":[[2.92,29.91]],"id":43154454}],"con":true,"img":false}]}
{"op":"mcm","clk":"5306660198","pt":1646102943709,"mc":[{"id":"1.195395425","rc":[{"atl":[[230,2]],"id":38256919}],"con":true,"img":false}]}
{"op":"mcm","clk":"5306660204","pt":1646102943814,"mc":[{"id":"1.195395425","rc":[{"atl":[[350,0.37]],"id":38256919}],"con":true,"img":false}]}
{"op":"mcm","clk":"5306660221","pt":1646102944326,"mc":[{"id":"1.195395425","rc":[{"atb":[[1.79,0]],"id":43154454}],"con":true,"img":false}]}
{"op":"mcm","clk":"5306660247","pt":1646102945406,"mc":[{"id":"1.195395425","rc":[{"atb":[[15,0.28]],"id":38859241}],"con":true,"img":false}]}
{"op":"mcm","clk":"5306660330","pt":1646102947605,"mc":[{"id":"1.195395425","rc":[{"atb":[[1.79,7.39]],"id":43154454}],"con":true,"img":false}]}
{"op":"mcm","clk":"5306660336","pt":1646102947810,"mc":[{"id":"1.195395425","rc":[{"atl":[[8.6,33.27],[9,0]],"id":36104892},{"atb":[[3.6,20.14],[4.5,0]],"id":38859241},{"atb":[[1.78,84.53],[1.77,261.63]],"id":43154454},{"atl":[[210,2]],"id":38256919}],"con":true,"img":false}]}
{"op":"mcm","clk":"5306660338","pt":1646102947912,"mc":[{"id":"1.195395425","rc":[{"atl":[[230,0]],"id":38256919}],"con":true,"img":false}]}
{"op":"mcm","clk":"5306660350","pt":1646102948323,"mc":[{"id":"1.195395425","rc":[{"atb":[[1.79,12.04]],"id":43154454}],"con":true,"img":false}]}
{"op":"mcm","clk":"5306660524","pt":1646102952725,"mc":[{"id":"1.195395425","rc":[{"atb":[[10,0]],"id":38859241}],"con":true,"img":false}]}
{"op":"mcm","clk":"5306660548","pt":1646102953341,"mc":[{"id":"1.195395425","rc":[{"atb":[[1.43,500]],"id":36104892},{"atb":[[1.43,500]],"id":38859241},{"atb":[[1.43,500]],"id":43154455},{"atb":[[1.43,500]],"id":39318320},{"atb":[[1.43,500]],"id":38256919},{"atb":[[1.43,500]],"id":42189480}],"con":true,"img":false}]}
{"op":"mcm","clk":"5306660630","pt":1646102955338,"mc":[{"id":"1.195395425","rc":[{"atb":[[15,0]],"id":38859241}],"con":true,"img":false}]}
{"op":"mcm","clk":"5306660777","pt":1646102958314,"mc":[{"id":"1.195395425","rc":[{"atl":[[8.8,0]],"id":36104892},{"atl":[[19.5,7.59]],"id":38859241},{"atb":[[13.5,0]],"id":43154455},{"atl":[[170,0.96]],"id":38256919}],"con":true,"img":false}]}
{"op":"mcm","clk":"5306660783","pt":1646102958419,"mc":[{"id":"1.195395425","rc":[{"atl":[[9.6,6.74]],"id":36104892},{"atl":[[21,2.9]],"id":38859241},{"atb":[[14.5,4.46]],"id":43154455},{"atl":[[190,0.3],[210,0],[250,2]],"id":38256919}],"con":true,"img":false}]}
{"op":"mcm","clk":"5306660786","pt":1646102958521,"mc":[{"id":"1.195395425","rc":[{"atl":[[8.6,20.77],[9,12.5]],"id":36104892}],"con":true,"img":false}]}
{"op":"mcm","clk":"5306660857","pt":1646102960235,"mc":[{"id":"1.195395425","rc":[{"atb":[[14,0]],"id":43154455}],"con":true,"img":false}]}
{"op":"mcm","clk":"5306660862","pt":1646102960339,"mc":[{"id":"1.195395425","rc":[{"atl":[[19.5,7.31]],"id":38859241}],"con":true,"img":false}]}
{"op":"mcm","clk":"5306660900","pt":1646102961263,"mc":[{"id":"1.195395425","rc":[{"atb":[[1.82,15.05]],"id":43154454}],"con":true,"img":false}]}
{"op":"mcm","clk":"5306660928","pt":1646102961828,"mc":[{"id":"1.195395425","rc":[{"atl":[[19.5,18.13]],"id":38859241}],"con":true,"img":false}]}
{"op":"mcm","clk":"5306660972","pt":1646102962862,"mc":[{"id":"1.195395425","rc":[{"atb":[[11,11.15]],"id":38859241}],"con":true,"img":false}]}
{"op":"mcm","clk":"5306660993","pt":1646102963533,"mc":[{"id":"1.195395425","rc":[{"atb":[[15,6.61]],"id":43154455}],"con":true,"img":false}]}
{"op":"mcm","clk":"5306660996","pt":1646102963634,"mc":[{"id":"1.195395425","rc":[{"atb":[[10.5,3.55]],"id":38859241}],"con":true,"img":false}]}
{"op":"mcm","clk":"5306660999","pt":1646102963736,"mc":[{"id":"1.195395425","rc":[{"atb":[[28,18.53]],"id":39318320}],"con":true,"img":false}]}
{"op":"mcm","clk":"5306661016","pt":1646102964249,"mc":[{"id":"1.195395425","rc":[{"atl":[[4.5,11.11]],"id":42189480}],"con":true,"img":false}]}
{"op":"mcm","clk":"5306661044","pt":1646102965068,"mc":[{"id":"1.195395425","rc":[{"atl":[[2.98,0]],"id":43154454}],"con":true,"img":false}]}
{"op":"mcm","clk":"5306661047","pt":1646102965169,"mc":[{"id":"1.195395425","rc":[{"atb":[[5.6,11.01]],"id":36104892}],"con":true,"img":false}]}
{"op":"mcm","clk":"5306661060","pt":1646102965426,"mc":[{"id":"1.195395425","rc":[{"atl":[[2.92,40.73]],"id":43154454}],"con":true,"img":false}]}
{"op":"mcm","clk":"5306661072","pt":1646102965736,"mc":[{"id":"1.195395425","rc":[{"atb":[[11.5,2.08]],"id":38859241}],"con":true,"img":false}]}
{"op":"mcm","clk":"5306661077","pt":1646102965841,"mc":[{"id":"1.195395425","rc":[{"atb":[[5.1,4]],"id":36104892}],"con":true,"img":false}]}
{"op":"mcm","clk":"5306661099","pt":1646102966454,"mc":[{"id":"1.195395425","rc":[{"atb":[[17.5,11.03]],"id":43154455}],"con":true,"img":false}]}
{"op":"mcm","clk":"5306661117","pt":1646102967067,"mc":[{"id":"1.195395425","rc":[{"atb":[[17,0]],"id":43154455}],"con":true,"img":false}]}
{"op":"mcm","clk":"5306661173","pt":1646102968348,"mc":[{"id":"1.195395425","rc":[{"atb":[[1.79,4.65]],"id":43154454},{"atb":[[15,0]],"id":43154455}],"con":true,"img":false}]}
{"op":"mcm","clk":"5306661205","pt":1646102969268,"mc":[{"id":"1.195395425","rc":[{"atb":[[18,2.08]],"id":43154455}],"con":true,"img":false}]}
{"op":"mcm","clk":"5306661301","pt":1646102971731,"mc":[{"id":"1.195395425","rc":[{"atb":[[1.83,11.28]],"id":43154454}],"con":true,"img":false}]}
{"op":"mcm","clk":"5306661323","pt":1646102972350,"mc":[{"id":"1.195395425","rc":[{"atb":[[1.82,10.82]],"id":43154454}],"con":true,"img":false}]}
{"op":"mcm","clk":"5306661428","pt":1646102974761,"mc":[{"id":"1.195395425","rc":[{"atb":[[1.79,0]],"id":43154454}],"con":true,"img":false}]}
{"op":"mcm","clk":"5306661445","pt":1646102975169,"mc":[{"id":"1.195395425","rc":[{"atb":[[10.5,0.1]],"id":38859241},{"atl":[[5.1,14.15]],"id":42189480}],"con":true,"img":false}]}
{"op":"mcm","clk":"5306661519","pt":1646102977167,"mc":[{"id":"1.195395425","rc":[{"atb":[[1.43,0]],"id":36104892},{"atb":[[1.43,0]],"id":38859241},{"atb":[[1.43,0]],"id":43154455},{"atb":[[1.43,0]],"id":39318320},{"atb":[[1.43,0]],"id":38256919},{"atb":[[1.43,0]],"id":42189480}],"con":true,"img":false}]}
{"op":"mcm","clk":"5306661548","pt":1646102977884,"mc":[{"id":"1.195395425","rc":[{"atb":[[1.43,500]],"id":36104892},{"atb":[[1.43,500]],"id":38859241},{"atb":[[1.43,500]],"id":43154455},{"atb":[[1.43,500]],"id":39318320},{"atb":[[1.43,500]],"id":38256919},{"atb":[[1.43,500]],"id":42189480}],"con":true,"img":false}]}
{"op":"mcm","clk":"5306661630","pt":1646102979679,"mc":[{"id":"1.195395425","rc":[{"atb":[[1.84,7.9]],"id":43154454}],"con":true,"img":false}]}
{"op":"mcm","clk":"5306661683","pt":1646102980656,"mc":[{"id":"1.195395425","rc":[{"atb":[[3.6,0],[4.1,32.26]],"id":38859241},{"atb":[[1.78,212.74],[1.77,131.76]],"id":43154454}],"con":true,"img":false}]}
{"op":"mcm","clk":"5306661785","pt":1646102982460,"mc":[{"id":"1.195395425","rc":[{"atb":[[1.83,0]],"id":43154454}],"con":true,"img":false}]}
{"op":"mcm","clk":"5306661923","pt":1646102985747,"mc":[{"id":"1.195395425","rc":[{"atb":[[1.85,5.92]],"id":43154454}],"con":true,"img":false}]}
{"op":"mcm","clk":"5306662062","pt":1646102988891,"mc":[{"id":"1.195395425","rc":[{"spn":15.5,"spf":1.0,"id":38859241},{"atb":[[1.84,0]],"id":43154454},{"spn":2.0,"spf":1.0,"id":43154454},{"spn":29.0,"spf":1.0,"id":43154455}],"con":true,"img":false}]}
{"op":"mcm","clk":"5306662134","pt":1646102990382,"mc":[{"id":"1.195395425","rc":[{"atb":[[14.5,0]],"id":43154455}],"con":true,"img":false}]}
{"op":"mcm","clk":"5306662138","pt":1646102990483,"mc":[{"id":"1.195395425","rc":[{"atb":[[13.5,4.46]],"id":43154455}],"con":true,"img":false}]}
{"op":"mcm","clk":"5306662179","pt":1646102991462,"mc":[{"id":"1.195395425","rc":[{"atl":[[9.2,0]],"id":36104892},{"atl":[[110,3.23]],"id":39318320},{"atl":[[4.5,10.82]],"id":42189480}],"con":true,"img":false}]}
{"op":"mcm","clk":"5306662223","pt":1646102991975,"mc":[{"id":"1.195395425","rc":[{"atb":[[1.85,0]],"id":43154454}],"con":true,"img":false}]}
{"op":"mcm","clk":"5306662259","pt":1646102992696,"mc":[{"id":"1.195395425","rc":[{"atb":[[1.83,4.22]],"id":43154454}],"con":true,"img":false}]}
{"op":"mcm","clk":"5306662278","pt":1646102992800,"mc":[{"id":"1.195395425","rc":[{"atb":[[5.1,0]],"id":36104892},{"atl":[[5,0]],"id":42189480}],"con":true,"img":false}]}
{"op":"mcm","clk":"5306662316","pt":1646102993576,"mc":[{"id":"1.195395425","rc":[{"atb":[[1.86,4.15]],"id":43154454}],"con":true,"img":false}]}
{"op":"mcm","clk":"5306662408","pt":1646102995169,"mc":[{"id":"1.195395425","rc":[{"atb":[[1.84,3.16]],"id":43154454}],"con":true,"img":false}]}
{"op":"mcm","clk":"5306662545","pt":1646102998508,"mc":[{"id":"1.195395425","rc":[{"atb":[[1.84,0]],"id":43154454}],"con":true,"img":false}]}
{"op":"mcm","clk":"5306662635","pt":1646103000715,"mc":[{"id":"1.195395425","rc":[{"atb":[[1.83,0]],"id":43154454}],"con":true,"img":false}]}
{"op":"mcm","clk":"5306662669","pt":1646103001690,"mc":[{"id":"1.195395425","rc":[{"atb":[[1.87,3.11]],"id":43154454}],"con":true,"img":false}]}
{"op":"mcm","clk":"5306662674","pt":1646103001897,"mc":[{"id":"1.195395425","rc":[{"atl":[[8.6,33.27],[9,0]],"id":36104892}],"con":true,"img":false}]}
{"op":"mcm","clk":"5306662693","pt":1646103002512,"mc":[{"id":"1.195395425","rc":[{"atb":[[1.86,0]],"id":43154454}],"con":true,"img":false}]}
{"op":"mcm","clk":"5306662860","pt":1646103005799,"mc":[{"id":"1.195395425","rc":[{"atl":[[2.14,0.28]],"id":43154454}],"con":true,"img":false}]}
{"op":"mcm","clk":"5306662882","pt":1646103006311,"mc":[{"id":"1.195395425","rc":[{"atl":[[21,0]],"id":38859241},{"atl":[[260,0],[190,0]],"id":38256919}],"con":true,"img":false}]}
{"op":"mcm","clk":"5306662887","pt":1646103006413,"mc":[{"id":"1.195395425","rc":[{"atl":[[19,2.9]],"id":38859241},{"atl":[[160,0.3],[350,2.37],[240,2.7],[250,0]],"id":38256919}],"con":true,"img":false}]}
{"op":"mcm","clk":"5306662938","pt":1646103007489,"mc":[{"id":"1.195395425","rc":[{"atb":[[1.83,3.74]],"id":43154454}],"con":true,"img":false}]}
{"op":"mcm","clk":"5306663014","pt":1646103009282,"mc":[{"id":"1.195395425","rc":[{"atb":[[1.87,0]],"id":43154454}],"con":true,"img":false}]}
{"op":"mcm","clk":"5306663026","pt":1646103009486,"mc":[{"id":"1.195395425","rc":[{"atl":[[2.16,0.6]],"id":43154454}],"con":true,"img":false}]}
{"op":"mcm","clk":"5306663036","pt":1646103009693,"mc":[{"id":"1.195395425","rc":[{"atl":[[2.16,0],[1000,1.66]],"id":43154454}],"con":true,"img":false}]}
{"op":"mcm","clk":"5306663054","pt":1646103010001,"mc":[{"id":"1.195395425","rc":[{"atl":[[1000,1.43]],"id":43154454}],"con":true,"img":false}]}
{"op":"mcm","clk":"5306663066","pt":1646103010205,"mc":[{"id":"1.195395425","rc":[{"atl":[[1000,3.1]],"id":43154454}],"con":true,"img":false}]}
{"op":"mcm","clk":"5306663076","pt":1646103010410,"mc":[{"id":"1.195395425","rc":[{"atl":[[1000,1.66]],"id":43154454}],"con":true,"img":false}]}
{"op":"mcm","clk":"5306663081","pt":1646103010511,"mc":[{"id":"1.195395425","rc":[{"atl":[[2.9,1.43]],"id":43154454}],"con":true,"img":false}]}
{"op":"mcm","clk":"5306663090","pt":1646103010717,"mc":[{"id":"1.195395425","rc":[{"atb":[[1.84,2.5]],"id":43154454}],"con":true,"img":false}]}
{"op":"mcm","clk":"5306663092","pt":1646103010820,"mc":[{"id":"1.195395425","rc":[{"atl":[[1000,0.61]],"id":43154454}],"con":true,"img":false}]}
{"op":"mcm","clk":"5306663110","pt":1646103011127,"mc":[{"id":"1.195395425","rc":[{"atl":[[1000,0]],"id":43154454}],"con":true,"img":false}]}
{"op":"mcm","clk":"5306663114","pt":1646103011230,"mc":[{"id":"1.195395425","rc":[{"atl":[[2.14,0.9]],"id":43154454}],"con":true,"img":false}]}
{"op":"mcm","clk":"5306663135","pt":1646103011795,"mc":[{"id":"1.195395425","rc":[{"atl":[[19.5,10.82]],"id":38859241},{"atl":[[170,0]],"id":38256919}],"con":true,"img":false}]}
{"op":"mcm","clk":"5306663138","pt":1646103011897,"mc":[{"id":"1.195395425","rc":[{"atl":[[19,10.41]],"id":38859241},{"atb":[[1.84,0]],"id":43154454},{"atl":[[160,1.33]],"id":38256919}],"con":true,"img":false}]}
{"op":"mcm","clk":"5306663140","pt":1646103011999,"mc":[{"id":"1.195395425","rc":[{"atl":[[9,12.5]],"id":36104892}],"con":true,"img":false}]}
{"op":"mcm","clk":"5306663145","pt":1646103012102,"mc":[{"id":"1.195395425","rc":[{"atl":[[8.6,20.77]],"id":36104892}],"con":true,"img":false}]}
{"op":"mcm","clk":"5306663155","pt":1646103012411,"mc":[{"id":"1.195395425","rc":[{"atl":[[18,0.28]],"id":38859241}],"con":true,"img":false}]}
{"op":"mcm","clk":"5306663164","pt":1646103012615,"mc":[{"id":"1.195395425","rc":[{"atb":[[1.84,2.8]],"id":43154454}],"con":true,"img":false}]}
{"op":"mcm","clk":"5306663214","pt":1646103013999,"mc":[{"id":"1.195395425","rc":[{"atl":[[2.88,4.22]],"id":43154454}],"con":true,"img":false}]}
{"op":"mcm","clk":"5306663278","pt":1646103015537,"mc":[{"id":"1.195395425","rc":[{"atb":[[1.81,14.02]],"id":43154454}],"con":true,"img":false}]}
{"op":"mcm","clk":"5306663282","pt":1646103015586,"mc":[{"id":"1.195395425","rc":[{"atl":[[85,0.28]],"id":39318320}],"con":true,"img":false}]}
{"op":"mcm","clk":"5306663284","pt":1646103015689,"mc":[{"id":"1.195395425","rc":[{"atl":[[2.9,0]],"id":43154454}],"con":true,"img":false}]}
{"op":"mcm","clk":"5306663291","pt":1646103015895,"mc":[{"id":"1.195395425","rc":[{"atl":[[1000,1.66]],"id":43154454}],"con":true,"img":false}]}
{"op":"mcm","clk":"5306663297","pt":1646103016202,"mc":[{"id":"1.195395425","rc":[{"atl":[[1000,1.45]],"id":43154454}],"con":true,"img":false}]}
{"op":"mcm","clk":"5306663303","pt":1646103016408,"mc":[{"id":"1.195395425","rc":[{"atl":[[1000,0]],"id":43154454}],"con":true,"img":false}]}
{"op":"mcm","clk":"5306663306","pt":1646103016510,"mc":[{"id":"1.195395425","rc":[{"atl":[[2.86,1.45]],"id":43154454}],"con":true,"img":false}]}
{"op":"mcm","clk":"5306663322","pt":1646103016920,"mc":[{"id":"1.195395425","rc":[{"atl":[[110,2]],"id":39318320}],"con":true,"img":false}]}
{"op":"mcm","clk":"5306663335","pt":1646103017125,"mc":[{"id":"1.195395425","rc":[{"atl":[[85,1.25]],"id":39318320}],"con":true,"img":false}]}
{"op":"mcm","clk":"5306663488","pt":1646103021229,"mc":[{"id":"1.195395425","rc":[{"atb":[[1.84,13.63]],"id":43154454},{"atl":[[2.88,0]],"id":43154454}],"con":true,"img":false}]}
{"op":"mcm","clk":"5306663500","pt":1646103021537,"mc":[{"id":"1.195395425","rc":[{"atl":[[2.84,4.22]],"id":43154454}],"con":true,"img":false}]}
{"op":"mcm","clk":"5306663508","pt":1646103021741,"mc":[{"id":"1.195395425","rc":[{"atl":[[18,11.11]],"id":38859241}],"con":true,"img":false}]}
{"op":"mcm","clk":"5306663545","pt":1646103022614,"mc":[{"id":"1.195395425","rc":[{"atb":[[11.5,12.9]],"id":38859241}],"con":true,"img":false}]}
{"op":"mcm","clk":"5306663553","pt":1646103022817,"mc":[{"id":"1.195395425","rc":[{"atb":[[4.3,0],[5.1,24.39]],"id":39318320}],"con":true,"img":false}]}
{"op":"mcm","clk":"5306663585","pt":1646103023541,"mc":[{"id":"1.195395425","rc":[{"atb":[[28,29.35]],"id":39318320}],"con":true,"img":false}]}
{"op":"mcm","clk":"5306663607","pt":1646103024001,"mc":[{"id":"1.195395425","rc":[{"atl":[[4.5,21.64]],"id":42189480}],"con":true,"img":false}]}
{"op":"mcm","clk":"5306663629","pt":1646103024516,"mc":[{"id":"1.195395425","rc":[{"atl":[[19,2.9]],"id":38859241}],"con":true,"img":false}]}
{"op":"mcm","clk":"5306663634","pt":1646103024617,"mc":[{"id":"1.195395425","rc":[{"atl":[[18,19.07]],"id":38859241}],"con":true,"img":false}]}
{"op":"mcm","clk":"5306663656","pt":1646103024924,"mc":[{"id":"1.195395425","rc":[{"atb":[[5.6,21.83]],"id":36104892}],"con":true,"img":false}]}
{"op":"mcm","clk":"5306663664","pt":1646103025133,"mc":[{"id":"1.195395425","rc":[{"atl":[[7.8,0.28]],"id":36104892}],"con":true,"img":false}]}
{"op":"mcm","clk":"5306663681","pt":1646103025646,"mc":[{"id":"1.195395425","rc":[{"atb":[[4.7,0]],"id":36104892}],"con":true,"img":false}]}
{"op":"mcm","clk":"5306663689","pt":1646103025803,"mc":[{"id":"1.195395425","rc":[{"atb":[[18,12.9]],"id":43154455}],"con":true,"img":false}]}
{"op":"mcm","clk":"5306663701","pt":1646103026110,"mc":[{"id":"1.195395425","rc":[{"atb":[[3.15,3]],"id":42189480}],"con":true,"img":false}]}
{"op":"mcm","clk":"5306663761","pt":1646103027546,"mc":[{"id":"1.195395425","rc":[{"atb":[[3.3,2.5]],"id":42189480}],"con":true,"img":false}]}
{"op":"mcm","clk":"5306663778","pt":1646103027955,"mc":[{"id":"1.195395425","rc":[{"atl":[[2.86,0]],"id":43154454}],"con":true,"img":false}]}
{"op":"mcm","clk":"5306663786","pt":1646103028109,"mc":[{"id":"1.195395425","rc":[{"atl":[[1000,1.66]],"id":43154454}],"con":true,"img":false}]}
{"op":"mcm","clk":"5306663797","pt":1646103028417,"mc":[{"id":"1.195395425","rc":[{"atl":[[1000,1.46]],"id":43154454}],"con":true,"img":false}]}
{"op":"mcm","clk":"5306663806","pt":1646103028623,"mc":[{"id":"1.195395425","rc":[{"atl":[[1000,0]],"id":43154454}],"con":true,"img":false}]}
{"op":"mcm","clk":"5306663811","pt":1646103028724,"mc":[{"id":"1.195395425","rc":[{"atl":[[2.82,1.46]],"id":43154454}],"con":true,"img":false}]}
{"op":"mcm","clk":"5306663859","pt":1646103029852,"mc":[{"id":"1.195395425","rc":[{"atl":[[2.84,0]],"id":43154454}],"con":true,"img":false}]}
{"op":"mcm","clk":"5306663975","pt":1646103032820,"mc":[{"id":"1.195395425","rc":[{"atl":[[2.82,4.46]],"id":43154454}],"con":true,"img":false}]}
{"op":"mcm","clk":"5306664013","pt":1646103033944,"mc":[{"id":"1.195395425","rc":[{"atl":[[2.82,3]],"id":43154454}],"con":true,"img":false}]}
{"op":"mcm","clk":"5306664021","pt":1646103034148,"mc":[{"id":"1.195395425","rc":[{"atl":[[1000,1.66]],"id":43154454}],"con":true,"img":false}]}
{"op":"mcm","clk":"5306664024","pt":1646103034251,"mc":[{"id":"1.195395425","rc":[{"atl":[[9,0],[8.8,12.82]],"id":36104892}],"con":true,"img":false}]}
{"op":"mcm","clk":"5306664029","pt":1646103034355,"mc":[{"id":"1.195395425","rc":[{"atl":[[1000,1.47]],"id":43154454}],"con":true,"img":false}]}
{"op":"mcm","clk":"5306664055","pt":1646103034866,"mc":[{"id":"1.195395425","rc":[{"atl":[[1000,0]],"id":43154454}],"con":true,"img":false}]}
{"op":"mcm","clk":"5306664061","pt":1646103034967,"mc":[{"id":"1.195395425","rc":[{"atl":[[2.8,1.47]],"id":43154454}],"con":true,"img":false}]}
{"op":"mcm","clk":"5306664185","pt":1646103037748,"mc":[{"id":"1.195395425","rc":[{"atb":[[3.95,21.21]],"id":36104892},{"atl":[[9.6,0],[10.5,4.55]],"id":36104892},{"atb":[[7.2,10.88]],"id":38859241},{"atl":[[19,0],[38,5.27],[26,0]],"id":38859241},{"atb":[[1.71,47.76]],"id":43154454},{"atl":[[2.92,10.82],[3.2,19.67]],"id":43154454},{"atb":[[11,8.45]],"id":43154455},{"atl":[[42,0],[60,0]],"id":43154455},{"atb":[[18.5,6.75],[24,0.44]],"id":39318320},{"atl":[[140,0],[180,0.24],[190,0]],"id":39318320},{"atl":[[260,0.16],[160,1.02],[240,0]],"id":38256919},{"atl":[[5.1,0],[6.2,8.32],[6.8,23.88],[6.6,0]],"id":42189480}],"con":true,"img":false}]}
{"op":"mcm","clk":"5306664191","pt":1646103037847,"mc":[{"id":"1.195395425","rc":[{"atl":[[23,2.9]],"id":38859241},{"atl":[[75,2.7],[48,2.7]],"id":43154455},{"atl":[[240,2.7]],"id":39318320},{"atl":[[440,2.7]],"id":38256919}],"con":true,"img":false}]}
{"op":"mcm","clk":"5306664222","pt":1646103038467,"mc":[{"id":"1.195395425","rc":[{"atb":[[1.85,4.22]],"id":43154454}],"con":true,"img":false}]}
{"op":"mcm","clk":"5306664239","pt":1646103038698,"mc":[{"id":"1.195395425","rc":[{"atl":[[350,0.37],[220,2]],"id":38256919}],"con":true,"img":false}]}
{"op":"mcm","clk":"5306664325","pt":1646103039970,"mc":[{"id":"1.195395425","rc":[{"atb":[[3.3,5.05]],"id":42189480}],"con":true,"img":false}]}
{"op":"mcm","clk":"5306664367","pt":1646103041047,"mc":[{"id":"1.195395425","rc":[{"atb":[[3.2,2.8]],"id":42189480}],"con":true,"img":false}]}
{"op":"mcm","clk":"5306664380","pt":1646103041458,"mc":[{"id":"1.195395425","rc":[{"atb":[[1.84,10.82]],"id":43154454}],"con":true,"img":false}]}
{"op":"mcm","clk":"5306664444","pt":1646103043458,"mc":[{"id":"1.195395425","rc":[{"atb":[[1.83,0]],"id":43154454}],"con":true,"img":false}]}
{"op":"mcm","clk":"5306664496","pt":1646103044842,"mc":[{"id":"1.195395425","rc":[{"atl":[[10.5,0],[12,0],[14,14.82]],"id":36104892},{"atb":[[8.6,7.02],[8.2,0]],"id":38859241},{"atl":[[23,0]],"id":38859241},{"atb":[[13.5,0]],"id":43154455},{"atl":[[48,0],[55,0.8]],"id":43154455}],"con":true,"img":false}]}
{"op":"mcm","clk":"5306664501","pt":1646103044945,"mc":[{"id":"1.195395425","rc":[{"atl":[[11,4.55]],"id":36104892},{"atl":[[25,2.9]],"id":38859241},{"atb":[[1.86,3.16]],"id":43154454},{"atb":[[14,4.46]],"id":43154455}],"con":true,"img":false}]}
{"op":"mcm","clk":"5306664504","pt":1646103045046,"mc":[{"id":"1.195395425","rc":[{"atb":[[1.79,126.58],[1.78,84.53]],"id":43154454}],"con":true,"img":false}]}
{"op":"mcm","clk":"5306664552","pt":1646103046179,"mc":[{"id":"1.195395425","rc":[{"atb":[[1.78,62.89]],"id":43154454}],"con":true,"img":false}]}
{"op":"mcm","clk":"5306664560","pt":1646103046332,"mc":[{"id":"1.195395425","rc":[{"atb":[[1.79,148.22]],"id":43154454}],"con":true,"img":false}]}
{"op":"mcm","clk":"5306664585","pt":1646103046947,"mc":[{"id":"1.195395425","rc":[{"atb":[[1.85,0]],"id":43154454}],"con":true,"img":false}]}
{"op":"mcm","clk":"5306664656","pt":1646103048685,"mc":[{"id":"1.195395425","rc":[{"atb":[[1.2,2.23]],"id":43154454}],"con":true,"img":false}]}
{"op":"mcm","clk":"5306664664","pt":1646103048891,"mc":[{"id":"1.195395425","rc":[{"spn":6.7,"spf":1.0,"id":36104892},{"spn":14.75,"spf":1.0,"id":38859241},{"atb":[[1.2,2.21]],"id":43154454},{"spn":2.0,"spf":1.0,"id":43154454},{"spn":56.5,"spf":1.0,"id":39318320}],"con":true,"img":false}]}
{"op":"mcm","clk":"5306664679","pt":1646103049146,"mc":[{"id":"1.195395425","rc":[{"atb":[[1.2,0]],"id":43154454}],"con":true,"img":false}]}
{"op":"mcm","clk":"5306664685","pt":1646103049248,"mc":[{"id":"1.195395425","rc":[{"atb":[[1.87,2.21]],"id":43154454}],"con":true,"img":false}]}
{"op":"mcm","clk":"5306664703","pt":1646103049657,"mc":[{"id":"1.195395425","rc":[{"atb":[[1.86,0]],"id":43154454}],"con":true,"img":false}]}
{"op":"mcm","clk":"5306664708","pt":1646103049761,"mc":[{"id":"1.195395425","rc":[{"atl":[[7.8,0]],"id":36104892},{"atl":[[18,18.78]],"id":38859241},{"atl":[[2.14,0.61]],"id":43154454},{"atl":[[85,0.96]],"id":39318320}],"con":true,"img":false}]}
{"op":"mcm","clk":"5306664774","pt":1646103051250,"mc":[{"id":"1.195395425","rc":[{"atb":[[1.88,2.5]],"id":43154454}],"con":true,"img":false}]}
{"op":"mcm","clk":"5306664795","pt":1646103051762,"mc":[{"id":"1.195395425","rc":[{"atb":[[17.5,10.82],[1.03,2.23]],"id":43154455}],"con":true,"img":false}]}
{"op":"mcm","clk":"5306664799","pt":1646103051863,"mc":[{"id":"1.195395425","rc":[{"atb":[[1.03,0.2]],"id":43154455}],"con":true,"img":false}]}
{"op":"mcm","clk":"5306664805","pt":1646103051966,"mc":[{"id":"1.195395425","rc":[{"atb":[[1.03,0]],"id":43154455}],"con":true,"img":false}]}
{"op":"mcm","clk":"5306664807","pt":1646103052067,"mc":[{"id":"1.195395425","rc":[{"atb":[[18.5,0.2]],"id":43154455}],"con":true,"img":false}]}
{"op":"mcm","clk":"5306664839","pt":1646103052681,"mc":[{"id":"1.195395425","rc":[{"atb":[[1.81,2.88]],"id":43154454}],"con":true,"img":false}]}
{"op":"mcm","clk":"5306664844","pt":1646103052785,"mc":[{"id":"1.195395425","rc":[{"atl":[[240,0]],"id":39318320}],"con":true,"img":false}]}
{"op":"mcm","clk":"5306664850","pt":1646103052887,"mc":[{"id":"1.195395425","rc":[{"atl":[[290,2.7]],"id":39318320}],"con":true,"img":false}]}
{"op":"mcm","clk":"5306664858","pt":1646103052990,"mc":[{"id":"1.195395425","rc":[{"atb":[[1.85,9.77]],"id":43154454},{"atb":[[3.3,2.5]],"id":42189480}],"con":true,"img":false}]}
{"op":"mcm","clk":"5306664874","pt":1646103053348,"mc":[{"id":"1.195395425","rc":[{"atb":[[1.87,0]],"id":43154454}],"con":true,"img":false}]}
{"op":"mcm","clk":"5306664988","pt":1646103056260,"mc":[{"id":"1.195395425","rc":[{"atb":[[3.25,4.2]],"id":42189480}],"con":true,"img":false}]}
{"op":"mcm","clk":"5306664994","pt":1646103056463,"mc":[{"id":"1.195395425","rc":[{"atl":[[8.6,33.59]],"id":36104892},{"atl":[[210,2]],"id":38256919}],"con":true,"img":false}]}
{"op":"mcm","clk":"5306664997","pt":1646103056566,"mc":[{"id":"1.195395425","rc":[{"atl":[[8.8,0]],"id":36104892},{"atl":[[200,2],[210,0],[220,0]],"id":38256919}],"con":true,"img":false}]}
{"op":"mcm","clk":"5306665036","pt":1646103057587,"mc":[{"id":"1.195395425","rc":[{"atl":[[17.5,0.28]],"id":38859241}],"con":true,"img":false}]}
{"op":"mcm","clk":"5306665065","pt":1646103058558,"mc":[{"id":"1.195395425","rc":[{"atb":[[1.2,2.23]],"id":43154454}],"con":true,"img":false}]}
{"op":"mcm","clk":"5306665077","pt":1646103058866,"mc":[{"id":"1.195395425","rc":[{"atb":[[1.2,1.75]],"id":43154454}],"con":true,"img":false}]}
{"op":"mcm","clk":"5306665089","pt":1646103059173,"mc":[{"id":"1.195395425","rc":[{"atb":[[1.2,0]],"id":43154454}],"con":true,"img":false}]}
{"op":"mcm","clk":"5306665093","pt":1646103059275,"mc":[{"id":"1.195395425","rc":[{"atb":[[1.89,1.75]],"id":43154454}],"con":true,"img":false}]}
{"op":"mcm","clk":"5306665108","pt":1646103059581,"mc":[{"id":"1.195395425","rc":[{"atb":[[4.7,25.05]],"id":36104892}],"con":true,"img":false}]}
{"op":"mcm","clk":"5306665155","pt":1646103060759,"mc":[{"id":"1.195395425","rc":[{"atb":[[1.88,0]],"id":43154454}],"con":true,"img":false}]}
{"op":"mcm","clk":"5306665173","pt":1646103061270,"mc":[{"id":"1.195395425","rc":[{"atb":[[1.85,0]],"id":43154454}],"con":true,"img":false}]}
{"op":"mcm","clk":"5306665186","pt":1646103061575,"mc":[{"id":"1.195395425","rc":[{"atb":[[4.7,31.17]],"id":36104892},{"atb":[[3.2,0]],"id":42189480}],"con":true,"img":false}]}
{"op":"mcm","clk":"5306665292","pt":1646103064186,"mc":[{"id":"1.195395425","rc":[{"atb":[[1.89,0]],"id":43154454}],"con":true,"img":false}]}
{"op":"mcm","clk":"5306665295","pt":1646103064290,"mc":[{"id":"1.195395425","rc":[{"atb":[[1.78,125.78]],"id":43154454}],"con":true,"img":false}]}
{"op":"mcm","clk":"5306665298","pt":1646103064391,"mc":[{"id":"1.195395425","rc":[{"atb":[[1.79,21.64]],"id":43154454}],"con":true,"img":false}]}
{"op":"mcm","clk":"5306665315","pt":1646103064801,"mc":[{"id":"1.195395425","rc":[{"atb":[[1.8,25.14]],"id":43154454}],"con":true,"img":false}]}
{"op":"mcm","clk":"5306665349","pt":1646103065571,"mc":[{"id":"1.195395425","rc":[{"atb":[[1.85,2.5]],"id":43154454}],"con":true,"img":false}]}
{"op":"mcm","clk":"5306665358","pt":1646103065777,"mc":[{"id":"1.195395425","rc":[{"atl":[[90,0.28]],"id":39318320}],"con":true,"img":false}]}
{"op":"mcm","clk":"5306665401","pt":1646103066698,"mc":[{"id":"1.195395425","rc":[{"atb":[[1.79,0]],"id":43154454}],"con":true,"img":false}]}
{"op":"mcm","clk":"5306665404","pt":1646103066801,"mc":[{"id":"1.195395425","rc":[{"atb":[[1.8,46.79]],"id":43154454}],"con":true,"img":false}]}
{"op":"mcm","clk":"5306665423","pt":1646103067107,"mc":[{"id":"1.195395425","rc":[{"atl":[[200,0],[210,2]],"id":38256919}],"con":true,"img":false}]}
{"op":"mcm","clk":"5306665456","pt":1646103067775,"mc":[{"id":"1.195395425","rc":[{"atb":[[1.2,2.23]],"id":42189480}],"con":true,"img":false}]}
{"op":"mcm","clk":"5306665464","pt":1646103068081,"mc":[{"id":"1.195395425","rc":[{"atb":[[1.2,1.96]],"id":42189480}],"con":true,"img":false}]}
{"op":"mcm","clk":"5306665471","pt":1646103068286,"mc":[{"id":"1.195395425","rc":[{"atb":[[4.8,12.16],[4.6,0]],"id":36104892},{"atl":[[11,0]],"id":36104892},{"atl":[[25,0]],"id":38859241},{"atl":[[260,0]],"id":38256919},{"atb":[[2.72,21.47],[2.62,0]],"id":42189480},{"atl":[[6.2,0]],"id":42189480}],"con":true,"img":false}]}
{"op":"mcm","clk":"5306665478","pt":1646103068388,"mc":[{"id":"1.195395425","rc":[{"atl":[[10.5,4.55]],"id":36104892},{"atl":[[23,2.9]],"id":38859241},{"atl":[[210,2.16]],"id":38256919},{"atb":[[1.2,0]],"id":42189480},{"atl":[[5.6,8.32]],"id":42189480}],"con":true,"img":false}]}
{"op":"mcm","clk":"5306665482","pt":1646103068491,"mc":[{"id":"1.195395425","rc":[{"atb":[[3.35,1.96]],"id":42189480}],"con":true,"img":false}]}
{"op":"mcm","clk":"5306665522","pt":1646103069311,"mc":[{"id":"1.195395425","rc":[{"atb":[[3.3,0]],"id":42189480}],"con":true,"img":false}]}
{"op":"mcm","clk":"5306665569","pt":1646103070381,"mc":[{"id":"1.195395425","rc":[{"atb":[[1.2,2.23]],"id":43154454}],"con":true,"img":false}]}
{"op":"mcm","clk":"5306665577","pt":1646103070688,"mc":[{"id":"1.195395425","rc":[{"atb":[[1.2,1.75]],"id":43154454}],"con":true,"img":false}]}
{"op":"mcm","clk":"5306665589","pt":1646103070996,"mc":[{"id":"1.195395425","rc":[{"atb":[[1.2,0]],"id":43154454}],"con":true,"img":false}]}
{"op":"mcm","clk":"5306665595","pt":1646103071098,"mc":[{"id":"1.195395425","rc":[{"atb":[[1.86,1.75]],"id":43154454}],"con":true,"img":false}]}
{"op":"mcm","clk":"5306665620","pt":1646103071711,"mc":[{"id":"1.195395425","rc":[{"atb":[[4.7,6.11]],"id":36104892},{"atb":[[3.25,0]],"id":42189480}],"con":true,"img":false}]}
{"op":"mcm","clk":"5306665652","pt":1646103072682,"mc":[{"id":"1.195395425","rc":[{"atl":[[90,0]],"id":39318320}],"con":true,"img":false}]}
{"op":"mcm","clk":"5306665661","pt":1646103072989,"mc":[{"id":"1.195395425","rc":[{"atl":[[2.82,0]],"id":43154454},{"atb":[[3.15,0]],"id":42189480}],"con":true,"img":false}]}
{"op":"mcm","clk":"5306665665","pt":1646103073090,"mc":[{"id":"1.195395425","rc":[{"atb":[[1.85,0]],"id":43154454}],"con":true,"img":false}]}
{"op":"mcm","clk":"5306665667","pt":1646103073193,"mc":[{"id":"1.195395425","rc":[{"atb":[[4.7,0]],"id":36104892},{"atb":[[1.8,21.64]],"id":43154454}],"con":true,"img":false}]}
{"op":"mcm","clk":"5306665684","pt":1646103073809,"mc":[{"id":"1.195395425","rc":[{"atb":[[1.87,2.5]],"id":43154454}],"con":true,"img":false}]}
{"op":"mcm","clk":"5306665737","pt":1646103075188,"mc":[{"id":"1.195395425","rc":[{"atb":[[4.9,23.76]],"id":36104892},{"atb":[[2.88,49.31]],"id":42189480}],"con":true,"img":false}]}
{"op":"mcm","clk":"5306665769","pt":1646103076108,"mc":[{"id":"1.195395425","rc":[{"atb":[[3.35,0]],"id":42189480}],"con":true,"img":false}]}
{"op":"mcm","clk":"5306665805","pt":1646103076878,"mc":[{"id":"1.195395425","rc":[{"atb":[[1.87,5.69]],"id":43154454}],"con":true,"img":false}]}
{"op":"mcm","clk":"5306665813","pt":1646103077082,"mc":[{"id":"1.195395425","rc":[{"atl":[[2.74,0.28]],"id":43154454}],"con":true,"img":false}]}
{"op":"mcm","clk":"5306665853","pt":1646103077903,"mc":[{"id":"1.195395425","rc":[{"atl":[[2.74,0.57]],"id":43154454}],"con":true,"img":false}]}
{"op":"mcm","clk":"5306665893","pt":1646103078722,"mc":[{"id":"1.195395425","rc":[{"atb":[[1.88,4.22]],"id":43154454}],"con":true,"img":false}]}
{"op":"mcm","clk":"5306665905","pt":1646103079030,"mc":[{"id":"1.195395425","rc":[{"atb":[[5,5.65]],"id":36104892},{"atb":[[1.86,0]],"id":43154454}],"con":true,"img":false}]}
{"op":"mcm","clk":"5306665922","pt":1646103079389,"mc":[{"id":"1.195395425","rc":[{"atl":[[2.74,0.86]],"id":43154454}],"con":true,"img":false}]}
{"op":"mcm","clk":"5306665942","pt":1646103079902,"mc":[{"id":"1.195395425","rc":[{"atb":[[1.87,3.18]],"id":43154454}],"con":true,"img":false}]}
{"op":"mcm","clk":"5306665972","pt":1646103080721,"mc":[{"id":"1.195395425","rc":[{"atl":[[2.74,1.15]],"id":43154454}],"con":true,"img":false}]}
{"op":"mcm","clk":"5306666004","pt":1646103081590,"mc":[{"id":"1.195395425","rc":[{"atl":[[2.8,0]],"id":43154454}],"con":true,"img":false}]}
{"op":"mcm","clk":"5306666007","pt":1646103081692,"mc":[{"id":"1.195395425","rc":[{"atb":[[2.9,11.91]],"id":42189480}],"con":true,"img":false}]}
{"op":"mcm","clk":"5306666010","pt":1646103081795,"mc":[{"id":"1.195395425","rc":[{"atl":[[1000,1.66]],"id":43154454}],"con":true,"img":false}]}
{"op":"mcm","clk":"5306666024","pt":1646103082101,"mc":[{"id":"1.195395425","rc":[{"atb":[[4.9,0]],"id":36104892},{"atb":[[1.87,0]],"id":43154454},{"atl":[[1000,1.51]],"id":43154454}],"con":true,"img":false}]}
{"op":"mcm","clk":"5306666029","pt":1646103082205,"mc":[{"id":"1.195395425","rc":[{"atb":[[1.89,2.5]],"id":43154454}],"con":true,"img":false}]}
{"op":"mcm","clk":"5306666033","pt":1646103082409,"mc":[{"id":"1.195395425","rc":[{"atl":[[1000,0]],"id":43154454}],"con":true,"img":false}]}
{"op":"mcm","clk":"5306666038","pt":1646103082511,"mc":[{"id":"1.195395425","rc":[{"atl":[[2.72,1.51]],"id":43154454}],"con":true,"img":false}]}
{"op":"mcm","clk":"5306666095","pt":1646103083686,"mc":[{"id":"1.195395425","rc":[{"atb":[[2.88,0]],"id":42189480}],"con":true,"img":false}]}
{"op":"mcm","clk":"5306666106","pt":1646103083995,"mc":[{"id":"1.195395425","rc":[{"atb":[[1.78,62.89]],"id":43154454}],"con":true,"img":false}]}
{"op":"mcm","clk":"5306666110","pt":1646103084096,"mc":[{"id":"1.195395425","rc":[{"atb":[[1.81,65.78]],"id":43154454}],"con":true,"img":false}]}
{"op":"mcm","clk":"5306666132","pt":1646103084608,"mc":[{"id":"1.195395425","rc":[{"atb":[[1.85,4.65]],"id":43154454}],"con":true,"img":false}]}
{"op":"mcm","clk":"5306666161","pt":1646103085529,"mc":[{"id":"1.195395425","rc":[{"atb":[[1.85,16.42]],"id":43154454}],"con":true,"img":false}]}
{"op":"mcm","clk":"5306666192","pt":1646103086196,"mc":[{"id":"1.195395425","rc":[{"atb":[[1.88,0]],"id":43154454}],"con":true,"img":false}]}
{"op":"mcm","clk":"5306666243","pt":1646103087319,"mc":[{"id":"1.195395425","rc":[{"atb":[[2.92,44.12]],"id":42189480}],"con":true,"img":false}]}
{"op":"mcm","clk":"5306666247","pt":1646103087420,"mc":[{"id":"1.195395425","rc":[{"atb":[[5,0]],"id":36104892}],"con":true,"img":false}]}
{"op":"mcm","clk":"5306666252","pt":1646103087624,"mc":[{"id":"1.195395425","rc":[{"atb":[[1.9,4.22]],"id":43154454}],"con":true,"img":false}]}
{"op":"mcm","clk":"5306666284","pt":1646103088339,"mc":[{"id":"1.195395425","rc":[{"atb":[[1.89,0]],"id":43154454}],"con":true,"img":false}]}
{"op":"mcm","clk":"5306666354","pt":1646103089922,"mc":[{"id":"1.195395425","rc":[{"atb":[[2.9,0]],"id":42189480}],"con":true,"img":false}]}
{"op":"mcm","clk":"5306666383","pt":1646103090638,"mc":[{"id":"1.195395425","rc":[{"atl":[[90,0.28]],"id":39318320}],"con":true,"img":false}]}
{"op":"mcm","clk":"5306666388","pt":1646103090740,"mc":[{"id":"1.195395425","rc":[{"atb":[[4.9,23.76]],"id":36104892}],"con":true,"img":false}]}
{"op":"mcm","clk":"5306666462","pt":1646103092224,"mc":[{"id":"1.195395425","rc":[{"atb":[[1.8,0]],"id":43154454}],"con":true,"img":false}]}
{"op":"mcm","clk":"5306666470","pt":1646103092429,"mc":[{"id":"1.195395425","rc":[{"atb":[[2.92,0]],"id":42189480}],"con":true,"img":false}]}
{"op":"mcm","clk":"5306666475","pt":1646103092531,"mc":[{"id":"1.195395425","rc":[{"atb":[[1.81,87.42]],"id":43154454}],"con":true,"img":false}]}
{"op":"mcm","clk":"5306666486","pt":1646103092939,"mc":[{"id":"1.195395425","rc":[{"atb":[[4.9,29.56]],"id":36104892}],"con":true,"img":false}]}
{"op":"mcm","clk":"5306666578","pt":1646103095143,"mc":[{"id":"1.195395425","rc":[{"atb":[[1.9,0]],"id":43154454}],"con":true,"img":false}]}
{"op":"mcm","clk":"5306666588","pt":1646103095348,"mc":[{"id":"1.195395425","rc":[{"atb":[[1.79,62.89],[1.78,0]],"id":43154454}],"con":true,"img":false}]}
{"op":"mcm","clk":"5306666591","pt":1646103095448,"mc":[{"id":"1.195395425","rc":[{"atb":[[1.91,4.22]],"id":43154454}],"con":true,"img":false}]}
{"op":"mcm","clk":"5306666599","pt":1646103095602,"mc":[{"id":"1.195395425","rc":[{"atb":[[2.88,12.03]],"id":42189480}],"con":true,"img":false}]}
{"op":"mcm","clk":"5306666608","pt":1646103095913,"mc":[{"id":"1.195395425","rc":[{"atb":[[2.88,61.34]],"id":42189480}],"con":true,"img":false}]}
{"op":"mcm","clk":"5306666729","pt":1646103098743,"mc":[{"id":"1.195395425","rc":[{"atl":[[200,2],[210,0.16]],"id":38256919}],"con":true,"img":false}]}
{"op":"mcm","clk":"5306666760","pt":1646103099356,"mc":[{"id":"1.195395425","rc":[{"atl":[[210,0]],"id":38256919},{"atl":[[5.6,0]],"id":42189480}],"con":true,"img":false}]}
{"op":"mcm","clk":"5306666763","pt":1646103099458,"mc":[{"id":"1.195395425","rc":[{"atl":[[200,2.16]],"id":38256919},{"atl":[[5.5,8.32]],"id":42189480}],"con":true,"img":false}]}
{"op":"mcm","clk":"5306666907","pt":1646103102637,"mc":[{"id":"1.195395425","rc":[{"atb":[[1.91,0]],"id":43154454}],"con":true,"img":false}]}
{"op":"mcm","clk":"5306666918","pt":1646103102946,"mc":[{"id":"1.195395425","rc":[{"atb":[[1.92,4.22]],"id":43154454}],"con":true,"img":false}]}
{"op":"mcm","clk":"5306667012","pt":1646103105351,"mc":[{"id":"1.195395425","rc":[{"atb":[[1.85,11.77]],"id":43154454}],"con":true,"img":false}]}
{"op":"mcm","clk":"5306667036","pt":1646103105762,"mc":[{"id":"1.195395425","rc":[{"atb":[[4.8,0.77]],"id":36104892},{"atb":[[34,0],[27,0]],"id":38256919}],"con":true,"img":false}]}
{"op":"mcm","clk":"5306667044","pt":1646103105863,"mc":[{"id":"1.195395425","rc":[{"atb":[[5,11.39]],"id":36104892},{"atb":[[22,4.86],[28,2.7]],"id":38256919}],"con":true,"img":false}]}
{"op":"mcm","clk":"5306667123","pt":1646103107656,"mc":[{"id":"1.195395425","rc":[{"atb":[[4.9,5.79]],"id":36104892}],"con":true,"img":false}]}
{"op":"mcm","clk":"5306667266","pt":1646103110943,"mc":[{"id":"1.195395425","rc":[{"atb":[[4.9,0]],"id":36104892},{"spn":7.1,"spf":1.0,"id":36104892},{"spn":14.5,"spf":1.0,"id":38859241},{"atb":[[1.86,5.91]],"id":43154454},{"spn":2.03,"spf":1.0,"id":43154454},{"spn":29.25,"spf":1.0,"id":43154455}],"con":true,"img":false}]}
{"op":"mcm","clk":"5306667288","pt":1646103111453,"mc":[{"id":"1.195395425","rc":[{"atb":[[1.92,0]],"id":43154454}],"con":true,"img":false}]}
{"op":"mcm","clk":"5306667353","pt":1646103113044,"mc":[{"id":"1.195395425","rc":[{"atl":[[17.5,3.26]],"id":38859241},{"atb":[[1.87,4.22]],"id":43154454},{"atl":[[2.72,5.21]],"id":43154454},{"atl":[[4.4,3.1]],"id":42189480}],"con":true,"img":false}]}
{"op":"mcm","clk":"5306667358","pt":1646103113147,"mc":[{"id":"1.195395425","rc":[{"atb":[[1.87,6.73]],"id":43154454}],"con":true,"img":false}]}
{"op":"mcm","clk":"5306667389","pt":1646103114473,"mc":[{"id":"1.195395425","rc":[{"atb":[[5,0]],"id":36104892},{"atb":[[8.6,1.33]],"id":38859241},{"atl":[[3.45,35.47]],"id":43154454}],"con":true,"img":false}]}
{"op":"mcm","clk":"5306667395","pt":1646103114575,"mc":[{"id":"1.195395425","rc":[{"atb":[[4.7,11.39]],"id":36104892},{"atb":[[8.2,5.69]],"id":38859241}],"con":true,"img":false}]}
{"op":"mcm","clk":"5306667444","pt":1646103115756,"mc":[{"id":"1.195395425","rc":[{"atb":[[1.85,0]],"id":43154454}],"con":true,"img":false}]}
{"op":"mcm","clk":"5306667525","pt":1646103117450,"mc":[{"id":"1.195395425","rc":[{"atb":[[4.8,25.16]],"id":36104892}],"con":true,"img":false}]}
{"op":"mcm","clk":"5306667547","pt":1646103117964,"mc":[{"id":"1.195395425","rc":[{"atl":[[2.72,3.7]],"id":43154454}],"con":true,"img":false}]}
{"op":"mcm","clk":"5306667554","pt":1646103118170,"mc":[{"id":"1.195395425","rc":[{"atl":[[1000,1.66]],"id":43154454}],"con":true,"img":false}]}
{"op":"mcm","clk":"5306667570","pt":1646103118477,"mc":[{"id":"1.195395425","rc":[{"atl":[[1000,1.52]],"id":43154454}],"con":true,"img":false}]}
{"op":"mcm","clk":"5306667578","pt":1646103118683,"mc":[{"id":"1.195395425","rc":[{"atl":[[1000,0]],"id":43154454}],"con":true,"img":false}]}
{"op":"mcm","clk":"5306667585","pt":1646103118735,"mc":[{"id":"1.195395425","rc":[{"atl":[[2.7,1.52]],"id":43154454}],"con":true,"img":false}]}
{"op":"mcm","clk":"5306667605","pt":1646103119144,"mc":[{"id":"1.195395425","rc":[{"atb":[[4.8,31.12]],"id":36104892},{"atb":[[1.86,0]],"id":43154454}],"con":true,"img":false}]}
{"op":"mcm","clk":"5306667610","pt":1646103119246,"mc":[{"id":"1.195395425","rc":[{"atb":[[1.88,5.04]],"id":43154454}],"con":true,"img":false}]}
{"op":"mcm","clk":"5306667646","pt":1646103120275,"mc":[{"id":"1.195395425","rc":[{"atb":[[1.87,2.5]],"id":43154454}],"con":true,"img":false}]}
{"op":"mcm","clk":"5306667656","pt":1646103120478,"mc":[{"id":"1.195395425","rc":[{"atb":[[1.89,4.22]],"id":43154454}],"con":true,"img":false}]}
{"op":"mcm","clk":"5306667678","pt":1646103120838,"mc":[{"id":"1.195395425","rc":[{"atb":[[1.79,88.21]],"id":43154454}],"con":true,"img":false}]}
{"op":"mcm","clk":"5306667687","pt":1646103121044,"mc":[{"id":"1.195395425","rc":[{"atb":[[1.87,0]],"id":43154454}],"con":true,"img":false}]}
{"op":"mcm","clk":"5306667755","pt":1646103122583,"mc":[{"id":"1.195395425","rc":[{"atb":[[1.88,0]],"id":43154454}],"con":true,"img":false}]}
{"op":"mcm","clk":"5306667819","pt":1646103123965,"mc":[{"id":"1.195395425","rc":[{"atl":[[18,10.82]],"id":38859241}],"con":true,"img":false}]}
{"op":"mcm","clk":"5306667853","pt":1646103124937,"mc":[{"id":"1.195395425","rc":[{"atl":[[17.5,11.46]],"id":38859241}],"con":true,"img":false}]}
{"op":"mcm","clk":"5306667902","pt":1646103126166,"mc":[{"id":"1.195395425","rc":[{"atb":[[1.85,8.45]],"id":43154454}],"con":true,"img":false}]}
{"op":"mcm","clk":"5306667958","pt":1646103127443,"mc":[{"id":"1.195395425","rc":[{"atb":[[1.66,30.45]],"id":43154454}],"con":true,"img":false}]}
{"op":"mcm","clk":"5306667962","pt":1646103127545,"mc":[{"id":"1.195395425","rc":[{"atb":[[1.89,0]],"id":43154454}],"con":true,"img":false}]}
{"op":"mcm","clk":"5306667970","pt":1646103127751,"mc":[{"id":"1.195395425","rc":[{"atb":[[1.9,4.22]],"id":43154454}],"con":true,"img":false}]}
{"op":"mcm","clk":"5306668028","pt":1646103129387,"mc":[{"id":"1.195395425","rc":[{"atb":[[1.81,24.53]],"id":43154454},{"atl":[[50,2.7],[55,0]],"id":43154455},{"atl":[[290,0],[180,0]],"id":39318320},{"atl":[[200,2]],"id":38256919},{"atb":[[2.86,0]],"id":42189480}],"con":true,"img":false}]}
{"op":"mcm","clk":"5306668033","pt":1646103129489,"mc":[{"id":"1.195395425","rc":[{"atb":[[1.82,73.71]],"id":43154454},{"atl":[[170,0.24],[240,2.7]],"id":39318320},{"atl":[[190,0.16]],"id":38256919},{"atb":[[2.9,31.19]],"id":42189480}],"con":true,"img":false}]}
{"op":"mcm","clk":"5306668049","pt":1646103129747,"mc":[{"id":"1.195395425","rc":[{"atl":[[2.14,0]],"id":43154454}],"con":true,"img":false}]}
{"op":"mcm","clk":"5306668057","pt":1646103129952,"mc":[{"id":"1.195395425","rc":[{"atl":[[1000,1.66]],"id":43154454}],"con":true,"img":false}]}
{"op":"mcm","clk":"5306668067","pt":1646103130256,"mc":[{"id":"1.195395425","rc":[{"atl":[[1000,0.49]],"id":43154454}],"con":true,"img":false}]}
{"op":"mcm","clk":"5306668080","pt":1646103130566,"mc":[{"id":"1.195395425","rc":[{"atl":[[1000,0]],"id":43154454}],"con":true,"img":false}]}
{"op":"mcm","clk":"5306668085","pt":1646103130670,"mc":[{"id":"1.195395425","rc":[{"atl":[[2.7,2.02]],"id":43154454}],"con":true,"img":false}]}
{"op":"mcm","clk":"5306668111","pt":1646103131184,"mc":[{"id":"1.195395425","rc":[{"atb":[[2.88,12.03]],"id":42189480}],"con":true,"img":false}]}
{"op":"mcm","clk":"5306668205","pt":1646103133691,"mc":[{"id":"1.195395425","rc":[{"atb":[[2.88,0]],"id":42189480}],"con":true,"img":false}]}
{"op":"mcm","clk":"5306668242","pt":1646103134560,"mc":[{"id":"1.195395425","rc":[{"atb":[[2.46,76.3],[2.7,71.55]],"id":42189480}],"con":true,"img":false}]}
{"op":"mcm","clk":"5306668266","pt":1646103135173,"mc":[{"id":"1.195395425","rc":[{"atb":[[1.9,0]],"id":43154454}],"con":true,"img":false}]}
{"op":"mcm","clk":"5306668280","pt":1646103135582,"mc":[{"id":"1.195395425","rc":[{"atb":[[1.91,4.22]],"id":43154454}],"con":true,"img":false}]}
{"op":"mcm","clk":"5306668592","pt":1646103142701,"mc":[{"id":"1.195395425","rc":[{"atb":[[1.8,0]],"id":36104892},{"atl":[[8.6,20.77]],"id":36104892},{"atb":[[4.1,0]],"id":38859241},{"atl":[[27,0]],"id":38859241},{"atb":[[1.79,25.32]],"id":43154454},{"atl":[[4,66.06]],"id":43154454},{"atb":[[6.6,0]],"id":43154455},{"atl":[[80,0]],"id":43154455},{"atb":[[5.1,0]],"id":39318320},{"atl":[[110,0]],"id":39318320},{"atl":[[200,0]],"id":38256919},{"atb":[[2.46,13.9]],"id":42189480},{"atl":[[7,0]],"id":42189480}],"con":true,"img":false}]}
{"op":"mcm","clk":"5306668632","pt":1646103143622,"mc":[{"id":"1.195395425","rc":[{"atb":[[1.91,0]],"id":43154454}],"con":true,"img":false}]}
{"op":"mcm","clk":"5306668655","pt":1646103144030,"mc":[{"id":"1.195395425","rc":[{"atb":[[1.92,4.22]],"id":43154454}],"con":true,"img":false}]}
{"op":"mcm","clk":"5306668667","pt":1646103144289,"mc":[{"id":"1.195395425","rc":[{"atb":[[1.86,2.5]],"id":43154454}],"con":true,"img":false}]}
{"op":"mcm","clk":"5306668676","pt":1646103144493,"mc":[{"id":"1.195395425","rc":[{"atb":[[4.8,25.16]],"id":36104892}],"con":true,"img":false}]}
{"op":"mcm","clk":"5306668684","pt":1646103144697,"mc":[{"id":"1.195395425","rc":[{"atb":[[4.7,0]],"id":36104892},{"atl":[[75,0]],"id":43154455},{"atl":[[440,0]],"id":38256919},{"atb":[[2.9,0]],"id":42189480}],"con":true,"img":false}]}
{"op":"mcm","clk":"5306668688","pt":1646103144800,"mc":[{"id":"1.195395425","rc":[{"atb":[[4.9,11.39]],"id":36104892},{"atl":[[90,2.7]],"id":43154455},{"atl":[[390,2.7]],"id":38256919},{"atb":[[2.86,31.19]],"id":42189480}],"con":true,"img":false}]}
{"op":"mcm","clk":"5306668757","pt":1646103146796,"mc":[{"id":"1.195395425","rc":[{"atb":[[1.86,0]],"id":43154454}],"con":true,"img":false}]}
{"op":"mcm","clk":"5306668781","pt":1646103147307,"mc":[{"id":"1.195395425","rc":[{"atb":[[4.8,0.77]],"id":36104892},{"atb":[[18.5,5.5]],"id":43154455}],"con":true,"img":false}]}
{"op":"mcm","clk":"5306668853","pt":1646103148891,"mc":[{"id":"1.195395425","rc":[{"atb":[[18,10.82]],"id":43154455}],"con":true,"img":false}]}
{"op":"mcm","clk":"5306668866","pt":1646103149197,"mc":[{"id":"1.195395425","rc":[{"atb":[[28,0]],"id":38256919},{"atb":[[2.72,0]],"id":42189480}],"con":true,"img":false}]}
{"op":"mcm","clk":"5306668869","pt":1646103149301,"mc":[{"id":"1.195395425","rc":[{"atb":[[30,2.7]],"id":38256919},{"atb":[[2.62,21.47]],"id":42189480}],"con":true,"img":false}]}
{"op":"mcm","clk":"5306668901","pt":1646103149815,"mc":[{"id":"1.195395425","rc":[{"atb":[[19,2.08]],"id":43154455}],"con":true,"img":false}]}
{"op":"mcm","clk":"5306669016","pt":1646103152218,"mc":[{"id":"1.195395425","rc":[{"atb":[[1.92,0]],"id":43154454}],"con":true,"img":false}]}
{"op":"mcm","clk":"5306669031","pt":1646103152525,"mc":[{"id":"1.195395425","rc":[{"atb":[[1.93,4.22]],"id":43154454}],"con":true,"img":false}]}
{"op":"mcm","clk":"5306669054","pt":1646103153240,"mc":[{"id":"1.195395425","rc":[{"atl":[[2.72,0]],"id":43154454}],"con":true,"img":false}]}
{"op":"mcm","clk":"5306669122","pt":1646103154625,"mc":[{"id":"1.195395425","rc":[{"atl":[[2.74,0.86]],"id":43154454}],"con":true,"img":false}]}
{"op":"mcm","clk":"5306669161","pt":1646103155599,"mc":[{"id":"1.195395425","rc":[{"atl":[[2.74,0.57]],"id":43154454}],"con":true,"img":false}]}
{"op":"mcm","clk":"5306669199","pt":1646103156521,"mc":[{"id":"1.195395425","rc":[{"atl":[[2.74,0.28]],"id":43154454}],"con":true,"img":false}]}
{"op":"mcm","clk":"5306669242","pt":1646103157492,"mc":[{"id":"1.195395425","rc":[{"atl":[[2.74,0]],"id":43154454}],"con":true,"img":false}]}
{"op":"mcm","clk":"5306669345","pt":1646103159798,"mc":[{"id":"1.195395425","rc":[{"atb":[[4.9,0]],"id":36104892},{"atl":[[190,0]],"id":38256919}],"con":true,"img":false}]}
{"op":"mcm","clk":"5306669350","pt":1646103159901,"mc":[{"id":"1.195395425","rc":[{"atb":[[4.7,11.39]],"id":36104892},{"atl":[[240,0.16]],"id":38256919}],"con":true,"img":false}]}
{"op":"mcm","clk":"5306669369","pt":1646103160309,"mc":[{"id":"1.195395425","rc":[{"atb":[[1.81,2.88]],"id":43154454}],"con":true,"img":false}]}
{"op":"mcm","clk":"5306669377","pt":1646103160515,"mc":[{"id":"1.195395425","rc":[{"atb":[[1.93,0]],"id":43154454},{"atl":[[2.66,0.28]],"id":43154454}],"con":true,"img":false}]}
{"op":"mcm","clk":"5306669382","pt":1646103160617,"mc":[{"id":"1.195395425","rc":[{"atb":[[1.82,95.35]],"id":43154454}],"con":true,"img":false}]}
{"op":"mcm","clk":"5306669417","pt":1646103161642,"mc":[{"id":"1.195395425","rc":[{"atb":[[1.86,2.5]],"id":43154454}],"con":true,"img":false}]}
{"op":"mcm","clk":"5306669430","pt":1646103161797,"mc":[{"id":"1.195395425","rc":[{"atb":[[4.8,25.19]],"id":36104892},{"atb":[[1.86,6.73]],"id":43154454}],"con":true,"img":false}]}
{"op":"mcm","clk":"5306669435","pt":1646103161901,"mc":[{"id":"1.195395425","rc":[{"atl":[[2.66,0.57]],"id":43154454}],"con":true,"img":false}]}
{"op":"mcm","clk":"5306669474","pt":1646103162824,"mc":[{"id":"1.195395425","rc":[{"atl":[[2.66,0.86]],"id":43154454}],"con":true,"img":false}]}
{"op":"mcm","clk":"5306669543","pt":1646103164413,"mc":[{"id":"1.195395425","rc":[{"atl":[[2.64,0.28]],"id":43154454}],"con":true,"img":false}]}
{"op":"mcm","clk":"5306669615","pt":1646103166304,"mc":[{"id":"1.195395425","rc":[{"atl":[[2.7,1.52]],"id":43154454}],"con":true,"img":false}]}
{"op":"mcm","clk":"5306669624","pt":1646103166510,"mc":[{"id":"1.195395425","rc":[{"atl":[[2.7,0]],"id":43154454}],"con":true,"img":false}]}
{"op":"mcm","clk":"5306669632","pt":1646103166713,"mc":[{"id":"1.195395425","rc":[{"atl":[[1000,1.66]],"id":43154454}],"con":true,"img":false}]}
{"op":"mcm","clk":"5306669639","pt":1646103166919,"mc":[{"id":"1.195395425","rc":[{"atl":[[1000,3.33]],"id":43154454}],"con":true,"img":false}]}
{"op":"mcm","clk":"5306669648","pt":1646103167122,"mc":[{"id":"1.195395425","rc":[{"atl":[[1000,2.17]],"id":43154454}],"con":true,"img":false}]}
{"op":"mcm","clk":"5306669650","pt":1646103167225,"mc":[{"id":"1.195395425","rc":[{"atl":[[1000,2.06]],"id":43154454}],"con":true,"img":false}]}
{"op":"mcm","clk":"5306669661","pt":1646103167532,"mc":[{"id":"1.195395425","rc":[{"atl":[[1000,1.56]],"id":43154454}],"con":true,"img":false}]}
{"op":"mcm","clk":"5306669665","pt":1646103167634,"mc":[{"id":"1.195395425","rc":[{"atl":[[2.64,0.78]],"id":43154454}],"con":true,"img":false}]}
{"op":"mcm","clk":"5306669682","pt":1646103167940,"mc":[{"id":"1.195395425","rc":[{"atl":[[1000,0]],"id":43154454}],"con":true,"img":false}]}
{"op":"mcm","clk":"5306669690","pt":1646103168042,"mc":[{"id":"1.195395425","rc":[{"atl":[[2.64,2.35]],"id":43154454}],"con":true,"img":false}]}
{"op":"mcm","clk":"5306669908","pt":1646103173316,"mc":[{"id":"1.195395425","rc":[{"atl":[[8.2,0.28]],"id":36104892},{"spn":6.9,"spf":1.0,"id":36104892},{"spn":2.25,"spf":1.0,"id":43154454},{"spn":29.5,"spf":1.0,"id":43154455},{"spn":3.97,"spf":1.0,"id":42189480}],"con":true,"img":false}]}
{"op":"mcm","clk":"5306669958","pt":1646103174748,"mc":[{"id":"1.195395425","rc":[{"atb":[[8.2,0]],"id":38859241},{"atl":[[50,0]],"id":43154455},{"atb":[[30,0]],"id":38256919}],"con":true,"img":false}]}
{"op":"mcm","clk":"5306669964","pt":1646103174853,"mc":[{"id":"1.195395425","rc":[{"atb":[[8.4,5.69]],"id":38859241},{"atl":[[48,2.7]],"id":43154455},{"atb":[[34,2.7]],"id":38256919}],"con":true,"img":false}]}
{"op":"mcm","clk":"5306670068","pt":1646103177569,"mc":[{"id":"1.195395425","rc":[{"atb":[[4.5,2],[3.4,0],[3.9,0],[3.65,0]],"id":36104892},{"atl":[[18,0],[21,0],[26,0],[15.5,0]],"id":36104892},{"atb":[[8,0],[6,0],[7,0],[9.4,0]],"id":38859241},{"atl":[[75,0],[150,0],[50,0],[100,0]],"id":38859241},{"atb":[[1.6,0],[1.7,0],[1.77,0],[1.65,0]],"id":43154454},{"atl":[[4,0],[4.5,0],[3.5,0],[3.75,0]],"id":43154454},{"atb":[[16.5,0],[9.2,0],[10.5,0],[13,0]],"id":43154455},{"atl":[[130,0],[280,0],[180,0],[230,0]],"id":43154455},{"atb":[[18,0],[23,0],[13,0],[15.5,0]],"id":39318320},{"atl":[[300,0],[350,0],[200,0],[250,0]],"id":39318320},{"atb":[[32,0],[21,0],[46,0],[26,0]],"id":38256919},{"atl":[[350,0],[400,0],[450,0],[500,0]],"id":38256919},{"atb":[[2.5,0],[2.6,0],[2.84,0],[2.7,11.88]],"id":42189480},{"atl":[[7.2,0],[9.2,0],[10.5,0],[8.2,0]],"id":42189480}],"con":true,"img":false}]}
{"op":"mcm","clk":"5306670152","pt":1646103179667,"mc":[{"id":"1.195395425","rc":[{"atb":[[4.8,53.65],[4.3,65.52],[3.9,74.55]],"id":36104892},{"atl":[[18,12.72],[21,10.81],[15.5,7.45]],"id":36104892},{"atb":[[8,30.89],[9,27.02],[10,12.01]],"id":38859241},{"atl":[[75,2.92],[50,2.2],[100,2.18]],"id":38859241},{"atb":[[1.8,135.13],[1.7,308.89],[1.75,288.29]],"id":43154454},{"atl":[[4,72.07],[3.5,43.24],[3.75,78.62]],"id":43154454},{"atb":[[18,17.17],[13,18.01],[15.5,15.61]],"id":43154455},{"atl":[[130,0.83],[180,1.2],[230,0.94]],"id":43154455},{"atb":[[18,12.72],[21,10.81],[26,4.32]],"id":39318320},{"atl":[[300,0.72],[200,0.54],[250,0.86]],"id":39318320},{"atb":[[32,6.97],[42,5.27],[55,2]],"id":38256919},{"atl":[[350,0.3],[400,0.54],[450,0.48]],"id":38256919},{"atb":[[2.8,120.12],[2.9,56.9],[2.7,139.07]],"id":42189480},{"atl":[[7.2,17.43],[9.2,26.36],[8.2,30.03]],"id":42189480}],"con":true,"img":false}]}
{"op":"mcm","clk":"5306670531","pt":1646103189746,"mc":[{"id":"1.195395425","rc":[{"atb":[[4.7,0]],"id":36104892},{"atb":[[2.38,39.04]],"id":42189480}],"con":true,"img":false}]}
{"op":"mcm","clk":"5306670535","pt":1646103189850,"mc":[{"id":"1.195395425","rc":[{"atb":[[4.9,11.39]],"id":36104892},{"atb":[[2.62,0]],"id":42189480}],"con":true,"img":false}]}
{"op":"mcm","clk":"5306670638","pt":1646103192356,"mc":[{"id":"1.195395425","rc":[{"atb":[[4.8,29.22]],"id":36104892}],"con":true,"img":false}]}
{"op":"mcm","clk":"5306670670","pt":1646103193174,"mc":[{"id":"1.195395425","rc":[{"atb":[[5.7,4]],"id":36104892},{"atl":[[2.88,2.52]],"id":43154454}],"con":true,"img":false}]}
{"op":"mcm","clk":"5306670827","pt":1646103197679,"mc":[{"id":"1.195395425","rc":[{"atl":[[2.66,0.57]],"id":43154454}],"con":true,"img":false}]}
{"op":"mcm","clk":"5306670931","pt":1646103199681,"mc":[{"id":"1.195395425","rc":[{"atl":[[2.66,0.28]],"id":43154454}],"con":true,"img":false}]}
{"op":"mcm","clk":"5306670964","pt":1646103200349,"mc":[{"id":"1.195395425","rc":[{"atl":[[2.66,0]],"id":43154454}],"con":true,"img":false}]}
{"op":"mcm","clk":"5306671018","pt":1646103201576,"mc":[{"id":"1.195395425","rc":[{"atb":[[1.85,0]],"id":43154454},{"atb":[[18.5,0.2]],"id":43154455}],"con":true,"img":false}]}
{"op":"mcm","clk":"5306671038","pt":1646103202088,"mc":[{"id":"1.195395425","rc":[{"atl":[[1000,2.23]],"id":39318320}],"con":true,"img":false}]}
{"op":"mcm","clk":"5306671045","pt":1646103202291,"mc":[{"id":"1.195395425","rc":[{"atl":[[100,0]],"id":39318320}],"con":true,"img":false}]}
{"op":"mcm","clk":"5306671053","pt":1646103202496,"mc":[{"id":"1.195395425","rc":[{"atl":[[1000,0.04]],"id":39318320}],"con":true,"img":false}]}
{"op":"mcm","clk":"5306671061","pt":1646103202650,"mc":[{"id":"1.195395425","rc":[{"atl":[[1000,0]],"id":39318320}],"con":true,"img":false}]}
{"op":"mcm","clk":"5306671064","pt":1646103202751,"mc":[{"id":"1.195395425","rc":[{"atl":[[80,0.04]],"id":39318320}],"con":true,"img":false}]}
{"op":"mcm","clk":"5306671122","pt":1646103204387,"mc":[{"id":"1.195395425","rc":[{"atb":[[1.82,32.46],[1.86,2.5]],"id":43154454}],"con":true,"img":false}]}
{"op":"mcm","clk":"5306671126","pt":1646103204488,"mc":[{"id":"1.195395425","rc":[{"atb":[[1.81,65.78]],"id":43154454}],"con":true,"img":false}]}
{"op":"mcm","clk":"5306671137","pt":1646103204693,"mc":[{"id":"1.195395425","rc":[{"atb":[[1.87,4.22]],"id":43154454}],"con":true,"img":false}]}
{"op":"mcm","clk":"5306671158","pt":1646103205155,"mc":[{"id":"1.195395425","rc":[{"atb":[[1.86,0]],"id":43154454}],"con":true,"img":false}]}
{"op":"mcm","clk":"5306671454","pt":1646103212578,"mc":[{"id":"1.195395425","rc":[{"atb":[[1.87,0]],"id":43154454}],"con":true,"img":false}]}
{"op":"mcm","clk":"5306671473","pt":1646103212987,"mc":[{"id":"1.195395425","rc":[{"atb":[[1.88,4.22]],"id":43154454}],"con":true,"img":false}]}
{"op":"mcm","clk":"5306671519","pt":1646103214215,"mc":[{"id":"1.195395425","rc":[{"atl":[[2.64,2.06]],"id":43154454}],"con":true,"img":false}]}
{"op":"mcm","clk":"5306671696","pt":1646103218828,"mc":[{"id":"1.195395425","rc":[{"atb":[[3.95,0],[4.4,14.3]],"id":36104892},{"atb":[[1.71,0]],"id":43154454},{"atb":[[18.5,0],[22,4.85]],"id":39318320},{"atb":[[2.86,0]],"id":42189480}],"con":true,"img":false}]}
{"op":"mcm","clk":"5306671700","pt":1646103218881,"mc":[{"id":"1.195395425","rc":[{"atb":[[1.76,47.76]],"id":43154454},{"atb":[[2.92,31.19]],"id":42189480}],"con":true,"img":false}]}
{"op":"mcm","clk":"5306671762","pt":1646103220727,"mc":[{"id":"1.195395425","rc":[{"atb":[[1.88,0]],"id":43154454}],"con":true,"img":false}]}
{"op":"mcm","clk":"5306671771","pt":1646103220883,"mc":[{"id":"1.195395425","rc":[{"atb":[[1.89,4.22]],"id":43154454}],"con":true,"img":false}]}
{"op":"mcm","clk":"5306672034","pt":1646103227228,"mc":[{"id":"1.195395425","rc":[{"spl":[[1.01,0.05]],"id":43154454},{"atl":[[2.64,2.01]],"id":43154454},{"trd":[[2.64,0.1]],"ltp":2.64,"tv":0.1,"id":43154454}],"con":true,"img":false}]}
{"op":"mcm","clk":"5306672057","pt":1646103227944,"mc":[{"id":"1.195395425","rc":[{"atl":[[17.5,11.41]],"id":38859241},{"trd":[[17.5,0.1]],"ltp":17.5,"tv":0.1,"id":38859241}],"con":true,"img":false}]}
{"op":"mcm","clk":"5306672065","pt":1646103228048,"mc":[{"id":"1.195395425","rc":[{"spl":[[1.01,0.05]],"id":38859241}],"con":true,"img":false}]}
{"op":"mcm","clk":"5306672072","pt":1646103228150,"mc":[{"id":"1.195395425","rc":[{"atb":[[5.1,6.07]],"id":36104892},{"atl":[[10.5,8.26]],"id":36104892},{"atb":[[1.01,3.36],[11,10.82],[1.02,2.23]],"id":38859241},{"atl":[[23,6.6]],"id":38859241},{"atb":[[1.29,85.93]],"id":43154454},{"atb":[[1.01,3.36]],"id":43154455},{"atl":[[65,3.7]],"id":43154455},{"atb":[[1.01,3.36]],"id":39318320},{"atl":[[320,3.7]],"id":39318320},{"atb":[[1.01,3.36]],"id":38256919},{"atl":[[470,3.7]],"id":38256919},{"atb":[[2.44,17.3]],"id":42189480},{"atl":[[5.3,3.7]],"id":42189480}],"con":true,"img":false}]}
{"op":"mcm","clk":"5306672083","pt":1646103228303,"mc":[{"id":"1.195395425","rc":[{"atb":[[1.02,0.31]],"id":38859241}],"con":true,"img":false}]}
{"op":"mcm","clk":"5306672088","pt":1646103228408,"mc":[{"id":"1.195395425","rc":[{"atb":[[1.01,2.96]],"id":38859241},{"atb":[[1.01,1.78]],"id":43154455},{"atb":[[1.01,1.18]],"id":39318320},{"atb":[[1.01,0.85]],"id":38256919}],"con":true,"img":false}]}
{"op":"mcm","clk":"5306672091","pt":1646103228510,"mc":[{"id":"1.195395425","rc":[{"atb":[[1.02,0]],"id":38859241}],"con":true,"img":false}]}
{"op":"mcm","clk":"5306672098","pt":1646103228613,"mc":[{"id":"1.195395425","rc":[{"atb":[[1.01,0],[12,0.31]],"id":38859241},{"atb":[[1.01,0]],"id":43154455},{"atb":[[1.01,0]],"id":39318320},{"atb":[[1.01,0]],"id":38256919}],"con":true,"img":false}]}
{"op":"mcm","clk":"5306672103","pt":1646103228714,"mc":[{"id":"1.195395425","rc":[{"atb":[[9.4,2.96]],"id":38859241},{"atb":[[1.89,0]],"id":43154454},{"atb":[[15,1.78]],"id":43154455},{"atb":[[22,6.04]],"id":39318320},{"atl":[[80,0],[85,0.95]],"id":39318320},{"trd":[[85,0.02],[80,0.08]],"ltp":85.0,"tv":0.1,"id":39318320},{"atb":[[30,0.85]],"id":38256919}],"con":true,"img":false}]}
{"op":"mcm","clk":"5306672108","pt":1646103228815,"mc":[{"id":"1.195395425","rc":[{"atb":[[1.05,2.23]],"id":39318320},{"spl":[[1.01,0.05]],"id":39318320}],"con":true,"img":false}]}
{"op":"mcm","clk":"5306672113","pt":1646103228917,"mc":[{"id":"1.195395425","rc":[{"atb":[[1.05,0.12]],"id":39318320}],"con":true,"img":false}]}
{"op":"mcm","clk":"5306672119","pt":1646103229019,"mc":[{"id":"1.195395425","rc":[{"atb":[[1.9,4.22]],"id":43154454}],"con":true,"img":false}]}
{"op":"mcm","clk":"5306672124","pt":1646103229123,"mc":[{"id":"1.195395425","rc":[{"atb":[[1.05,0]],"id":39318320}],"con":true,"img":false}]}
{"op":"mcm","clk":"5306672127","pt":1646103229221,"mc":[{"id":"1.195395425","rc":[{"atb":[[29,0.12]],"id":39318320}],"con":true,"img":false}]}
{"op":"mcm","clk":"5306672132","pt":1646103229327,"mc":[{"id":"1.195395425","rc":[{"atb":[[18.5,0],[1.04,2.23]],"id":43154455}],"con":true,"img":false}]}
{"op":"mcm","clk":"5306672143","pt":1646103229529,"mc":[{"id":"1.195395425","rc":[{"atb":[[1.04,0.19]],"id":43154455}],"con":true,"img":false}]}
{"op":"mcm","clk":"5306672149","pt":1646103229632,"mc":[{"id":"1.195395425","rc":[{"spl":[[1.01,0.05]],"id":42189480},{"atl":[[4.4,3.05]],"id":42189480},{"trd":[[4.4,0.1]],"ltp":4.4,"tv":0.1,"id":42189480}],"con":true,"img":false}]}
{"op":"mcm","clk":"5306672153","pt":1646103229733,"mc":[{"id":"1.195395425","rc":[{"atb":[[1.04,0]],"id":43154455}],"con":true,"img":false}]}
{"op":"mcm","clk":"5306672155","pt":1646103229834,"mc":[{"id":"1.195395425","rc":[{"atb":[[19.5,0.19]],"id":43154455},{"atb":[[3.05,2.53]],"id":42189480}],"con":true,"img":false}]}
{"op":"mcm","clk":"5306672183","pt":1646103230449,"mc":[{"id":"1.195395425","rc":[{"spl":[[1.01,0.05]],"id":36104892},{"atl":[[8.2,0.23]],"id":36104892},{"trd":[[8.2,0.1]],"ltp":8.2,"tv":0.1,"id":36104892}],"con":true,"img":false}]}
{"op":"mcm","clk":"5306672188","pt":1646103230654,"mc":[{"id":"1.195395425","rc":[{"atb":[[4.5,0]],"id":36104892}],"con":true,"img":false}]}
{"op":"mcm","clk":"5306672222","pt":1646103231322,"mc":[{"id":"1.195395425","rc":[{"atl":[[160,0.96]],"id":38256919},{"trd":[[160,0.1]],"ltp":160.0,"tv":0.1,"id":38256919}],"con":true,"img":false}]}
{"op":"mcm","clk":"5306672228","pt":1646103231425,"mc":[{"id":"1.195395425","rc":[{"atb":[[40,0]],"id":38256919},{"spl":[[1.01,0.05]],"id":38256919}],"con":true,"img":false}]}
{"op":"mcm","clk":"5306672234","pt":1646103231525,"mc":[{"id":"1.195395425","rc":[{"atb":[[24,0.44]],"id":38256919}],"con":true,"img":false}]}
{"op":"mcm","clk":"5306672283","pt":1646103233222,"mc":[{"id":"1.195395425","rc":[{"atb":[[12,3.31]],"id":38859241},{"atl":[[1000,2.23]],"id":43154454},{"atb":[[3.05,6.53]],"id":42189480}],"con":true,"img":false}]}
{"op":"mcm","clk":"5306672297","pt":1646103233730,"mc":[{"id":"1.195395425","rc":[{"spn":5.7,"spf":1.0,"id":36104892},{"spn":12.0,"spf":1.0,"id":38859241},{"atl":[[1000,1.11]],"id":43154454},{"spn":1.9,"spf":1.0,"id":43154454},{"spn":29.75,"spf":1.0,"id":43154455},{"spn":29.0,"spf":1.0,"id":39318320},{"spn":55.0,"spf":1.0,"id":38256919},{"spn":3.55,"spf":1.0,"id":42189480}],"con":true,"img":false}]}
{"op":"mcm","clk":"5306672307","pt":1646103234037,"mc":[{"id":"1.195395425","rc":[{"atl":[[1000,0]],"id":43154454}],"con":true,"img":false}]}
{"op":"mcm","clk":"5306672310","pt":1646103234139,"mc":[{"id":"1.195395425","rc":[{"atb":[[11.5,10.82]],"id":38859241},{"atb":[[1.9,3.11]],"id":43154454},{"trd":[[1.9,2.23]],"ltp":1.9,"tv":2.23,"id":43154454}],"con":true,"img":false}]}
{"op":"mcm","clk":"5306672387","pt":1646103236039,"mc":[{"id":"1.195395425","rc":[{"atl":[[2.64,12.83]],"id":43154454}],"con":true,"img":false}]}
{"op":"mcm","clk":"5306672428","pt":1646103237063,"mc":[{"id":"1.195395425","rc":[{"atb":[[1.9,10.82]],"id":43154454}],"con":true,"img":false}]}
{"op":"mcm","clk":"5306672443","pt":1646103237323,"mc":[{"id":"1.195395425","rc":[{"atl":[[1000,2.53]],"id":43154454}],"con":true,"img":false}]}
{"op":"mcm","clk":"5306672456","pt":1646103237532,"mc":[{"id":"1.195395425","rc":[{"atl":[[17.5,22.23]],"id":38859241},{"atl":[[1000,0.81]],"id":43154454}],"con":true,"img":false}]}
{"op":"mcm","clk":"5306672461","pt":1646103237635,"mc":[{"id":"1.195395425","rc":[{"atl":[[1000,0]],"id":43154454}],"con":true,"img":false}]}
{"op":"mcm","clk":"5306672465","pt":1646103237731,"mc":[{"id":"1.195395425","rc":[{"atl":[[2.62,0.81]],"id":43154454}],"con":true,"img":false}]}
{"op":"mcm","clk":"5306672474","pt":1646103238041,"mc":[{"id":"1.195395425","rc":[{"atl":[[2.64,12.38]],"id":43154454}],"con":true,"img":false}]}
{"op":"mcm","clk":"5306672487","pt":1646103238350,"mc":[{"id":"1.195395425","rc":[{"atb":[[12,14.13]],"id":38859241},{"atl":[[2.64,10.82]],"id":43154454}],"con":true,"img":false}]}
{"op":"mcm","clk":"5306672497","pt":1646103238554,"mc":[{"id":"1.195395425","rc":[{"atl":[[1000,1.66]],"id":43154454}],"con":true,"img":false}]}
{"op":"mcm","clk":"5306672506","pt":1646103238759,"mc":[{"id":"1.195395425","rc":[{"atl":[[1000,3.33]],"id":43154454}],"con":true,"img":false}]}
{"op":"mcm","clk":"5306672517","pt":1646103239018,"mc":[{"id":"1.195395425","rc":[{"atl":[[1000,2.12]],"id":43154454}],"con":true,"img":false}]}
