{"op":"mcm","clk":"5345904398","pt":1646079078742,"mc":[{"id":"1.195395455","marketDefinition":{"bspMarket":true,"turnInPlayEnabled":false,"persistenceEnabled":false,"marketBaseRate":5.0,"eventId":"31270459","eventTypeId":"4339","numberOfWinners":1,"bettingType":"ODDS","marketType":"WIN","marketTime":"2022-03-01T02:04:00.000Z","suspendTime":"2022-03-01T02:04:00.000Z","bspReconciled":false,"complete":true,"inPlay":false,"crossMatching":false,"runnersVoidable":false,"numberOfActiveRunners":8,"betDelay":0,"status":"OPEN","runners":[{"status":"ACTIVE","sortPriority":1,"id":37672294,"name":"1. Wizard Willie"},{"status":"ACTIVE","sortPriority":2,"id":28002629,"name":"2. St Andrews"},{"status":"ACTIVE","sortPriority":3,"id":43154433,"name":"3. Sapporo Bale"},{"status":"ACTIVE","sortPriority":4,"id":42393370,"name":"5. Goldstar Tookie"},{"status":"ACTIVE","sortPriority":5,"id":22150928,"name":"6. Smash Grenade"},{"status":"ACTIVE","sortPriority":6,"id":36993903,"name":"7. Baldrick"},{"status":"ACTIVE","sortPriority":7,"id":37267533,"name":"8. Diamond Empress"},{"status":"ACTIVE","sortPriority":8,"id":37455733,"name":"9. Just Stagger"}],"regulators":["MR_INT"],"venue":"Addington","countryCode":"NZ","discountAllowed":false,"timezone":"NZ","openDate":"2022-02-28T23:02:00.000Z","version":4380660692,"name":"R11 295m C2","eventName":"Addington (NZL) 1st Mar"},"rc":[],"con":true,"img":false}]}
{"op":"mcm","clk":"5345904623","pt":1646079080740,"mc":[{"id":"1.195395455","marketDefinition":{"bspMarket":true,"turnInPlayEnabled":false,"persistenceEnabled":false,"marketBaseRate":5.0,"eventId":"31270459","eventTypeId":"4339","numberOfWinners":1,"bettingType":"ODDS","marketType":"WIN","marketTime":"2022-03-01T02:04:00.000Z","suspendTime":"2022-03-01T02:04:00.000Z","bspReconciled":false,"complete":true,"inPlay":false,"crossMatching":false,"runnersVoidable":false,"numberOfActiveRunners":8,"betDelay":0,"status":"OPEN","runners":[{"status":"ACTIVE","sortPriority":1,"id":37672294,"name":"1. Wizard Willie"},{"status":"ACTIVE","sortPriority":2,"id":28002629,"name":"2. St Andrews"},{"status":"ACTIVE","sortPriority":3,"id":43154433,"name":"3. Sapporo Bale"},{"status":"ACTIVE","sortPriority":4,"id":42393370,"name":"5. Goldstar Tookie"},{"status":"ACTIVE","sortPriority":5,"id":22150928,"name":"6. Smash Grenade"},{"status":"ACTIVE","sortPriority":6,"id":36993903,"name":"7. Baldrick"},{"status":"ACTIVE","sortPriority":7,"id":37267533,"name":"8. Diamond Empress"},{"status":"ACTIVE","sortPriority":8,"id":37455733,"name":"9. Just Stagger"}],"regulators":["MR_INT"],"venue":"Addington","countryCode":"NZ","discountAllowed":true,"timezone":"NZ","openDate":"2022-02-28T23:02:00.000Z","version":4380660692,"name":"R11 295m C2","eventName":"Addington (NZL) 1st Mar"},"rc":[],"con":true,"img":false}]}
{"op":"mcm","clk":"5346133847","pt":1646081622893,"mc":[{"id":"1.195395455","rc":[{"atb":[[8,17.39],[9,10.14],[10,4.5],[6,32.47]],"id":37672294},{"atl":[[75,1.78],[150,1.33],[50,2.7],[100,2]],"id":37672294},{"spn":30.0,"spf":"NaN","id":37672294},{"atb":[[8,11.6],[9,5.07],[5.5,36.08],[7,20.29]],"id":28002629},{"atl":[[75,2.67],[40,3.39],[50,2.7],[100,2]],"id":28002629},{"spn":24.5,"spf":"NaN","id":28002629},{"atb":[[2.92,63.43],[2.72,94.41],[3.3,17.65],[3.05,39.6]],"id":42393370},{"atl":[[9.2,16.13],[10.5,20.88],[8.2,18.37],[13,16.53]],"id":42393370},{"spn":5.75,"spf":"NaN","id":42393370},{"atb":[[18,4.77],[21,2.02],[10.5,17.09],[15.5,8.4]],"id":36993903},{"atl":[[150,0.88],[300,0.66],[200,0.66],[250,0.79]],"id":36993903},{"spn":85.5,"spf":"NaN","id":36993903},{"atb":[[16,2.7],[11,12.17],[13.5,6.49],[8.4,21.94]],"id":37267533},{"atl":[[260,0.76],[160,0.83],[210,0.94],[110,1.21]],"id":37267533},{"spn":63.0,"spf":"NaN","id":37267533},{"atb":[[18,2.38],[9.2,19.8],[13,10.14],[15.5,5.59]],"id":37455733},{"atl":[[130,1.02],[280,0.7],[180,0.74],[230,0.86]],"id":37455733},{"spn":74.0,"spf":"NaN","id":37455733},{"atb":[[12,3.69],[6.8,27.99],[9.8,9.22],[8.8,15.61]],"id":22150928},{"atl":[[70,1.91],[140,1.42],[95,1.4],[190,1.05]],"id":22150928},{"spn":41.0,"spf":"NaN","id":22150928},{"atb":[[1.6,202.98],[1.7,57.99],[1.5,324.78],[1.65,124.91]],"id":43154433},{"atl":[[3.45,80.99],[3.2,60.13],[3.7,73.49],[2.98,66.81]],"id":43154433},{"spn":2.34,"spf":"NaN","id":43154433}],"con":true,"img":false}]}
{"op":"mcm","clk":"5346134842","pt":1646081638282,"mc":[{"id":"1.195395455","rc":[{"atb":[[8,0],[9,0],[10,0],[6,0]],"id":37672294},{"atl":[[75,0],[150,0],[50,0],[100,0]],"id":37672294},{"atb":[[8,0],[9,0],[5.5,0],[7,0]],"id":28002629},{"atl":[[75,0],[40,0],[50,0],[100,0]],"id":28002629},{"atb":[[2.92,0],[2.72,0],[3.3,0],[3.05,0]],"id":42393370},{"atl":[[9.2,0],[10.5,0],[8.2,0],[13,0]],"id":42393370},{"atb":[[18,0],[21,0],[10.5,0],[15.5,0]],"id":36993903},{"atl":[[150,0],[300,0],[200,0],[250,0]],"id":36993903},{"atb":[[16,0],[11,0],[13.5,0],[8.4,0]],"id":37267533},{"atl":[[260,0],[160,0],[210,0],[110,0]],"id":37267533},{"atb":[[18,0],[9.2,0],[13,0],[15.5,0]],"id":37455733},{"atl":[[130,0],[280,0],[180,0],[230,0]],"id":37455733},{"atb":[[12,0],[6.8,0],[9.8,0],[8.8,0]],"id":22150928},{"atl":[[70,0],[140,0],[95,0],[190,0]],"id":22150928},{"atb":[[1.6,0],[1.7,0],[1.5,0],[1.65,0]],"id":43154433},{"atl":[[3.45,0],[3.2,0],[3.7,0],[2.98,0]],"id":43154433}],"con":true,"img":false}]}
{"op":"mcm","clk":"5346136090","pt":1646081658332,"mc":[{"id":"1.195395455","rc":[{"atb":[[8,17.39],[9,10.14],[10,4.5],[6,32.47]],"id":37672294},{"atl":[[75,1.78],[150,1.33],[50,2.7],[100,2]],"id":37672294},{"atb":[[8,11.6],[9,5.07],[5.5,36.08],[7,20.29]],"id":28002629},{"atl":[[75,2.67],[40,3.39],[50,2.7],[100,2]],"id":28002629},{"atb":[[2.92,63.43],[2.72,94.41],[3.3,17.65],[3.05,39.6]],"id":42393370},{"atl":[[9.2,16.13],[10.5,20.88],[8.2,18.37],[13,16.53]],"id":42393370},{"atb":[[18,4.77],[21,2.02],[10.5,17.09],[15.5,8.4]],"id":36993903},{"atl":[[150,0.88],[300,0.66],[200,0.66],[250,0.79]],"id":36993903},{"atb":[[16,2.7],[11,12.17],[13.5,6.49],[8.4,21.94]],"id":37267533},{"atl":[[260,0.76],[160,0.83],[210,0.94],[110,1.21]],"id":37267533},{"atb":[[18,2.38],[9.2,19.8],[13,10.14],[15.5,5.59]],"id":37455733},{"atl":[[130,1.02],[280,0.7],[180,0.74],[230,0.86]],"id":37455733},{"atb":[[12,3.69],[6.8,27.99],[9.8,9.22],[8.8,15.61]],"id":22150928},{"atl":[[70,1.91],[140,1.42],[95,1.4],[190,1.05]],"id":22150928},{"atb":[[1.6,202.98],[1.7,57.99],[1.5,324.78],[1.65,124.91]],"id":43154433},{"atl":[[3.45,80.99],[3.2,60.13],[3.7,73.49],[2.98,66.81]],"id":43154433}],"con":true,"img":false}]}
{"op":"mcm","clk":"5346138739","pt":1646081696168,"mc":[{"id":"1.195395455","rc":[{"atb":[[8,0],[9,0],[10,0],[6,0]],"id":37672294},{"atl":[[75,0],[150,0],[50,0],[100,0]],"id":37672294},{"spn":"NaN","spf":"NaN","id":37672294},{"atb":[[8,0],[9,0],[5.5,0],[7,0]],"id":28002629},{"atl":[[75,0],[40,0],[50,0],[100,0]],"id":28002629},{"spn":"NaN","spf":"NaN","id":28002629},{"atb":[[2.92,0],[2.72,0],[3.3,0],[3.05,0]],"id":42393370},{"atl":[[9.2,0],[10.5,0],[8.2,0],[13,0]],"id":42393370},{"spn":"NaN","spf":"NaN","id":42393370},{"atb":[[18,0],[21,0],[10.5,0],[15.5,0]],"id":36993903},{"atl":[[150,0],[300,0],[200,0],[250,0]],"id":36993903},{"spn":"NaN","spf":"NaN","id":36993903},{"atb":[[16,0],[11,0],[13.5,0],[8.4,0]],"id":37267533},{"atl":[[260,0],[160,0],[210,0],[110,0]],"id":37267533},{"spn":"NaN","spf":"NaN","id":37267533},{"atb":[[18,0],[9.2,0],[13,0],[15.5,0]],"id":37455733},{"atl":[[130,0],[280,0],[180,0],[230,0]],"id":37455733},{"spn":"NaN","spf":"NaN","id":37455733},{"atb":[[12,0],[6.8,0],[9.8,0],[8.8,0]],"id":22150928},{"atl":[[70,0],[140,0],[95,0],[190,0]],"id":22150928},{"spn":"NaN","spf":"NaN","id":22150928},{"atb":[[1.6,0],[1.7,0],[1.5,0],[1.65,0]],"id":43154433},{"atl":[[3.45,0],[3.2,0],[3.7,0],[2.98,0]],"id":43154433},{"spn":"NaN","spf":"NaN","id":43154433}],"con":true,"img":false}]}
{"op":"mcm","clk":"5346140410","pt":1646081720446,"mc":[{"id":"1.195395455","rc":[{"atb":[[6.4,30.07],[11,4.05],[8.4,16.46],[9.4,9.66]],"id":37672294},{"atl":[[80,1.67],[160,1.25],[55,2.45],[110,1.81]],"id":37672294},{"atb":[[4.8,10.68],[4.3,24.6],[3.4,67.66],[3.9,41.99]],"id":28002629},{"atl":[[18,7.78],[21,9.92],[26,7.93],[15.5,9.12]],"id":28002629},{"atb":[[3.4,16.91],[3.15,37.76],[2.96,62.14],[2.76,92.26]],"id":42393370},{"atl":[[11,19.84],[13.5,15.87],[8.4,17.87],[9.4,15.75]],"id":42393370},{"atb":[[18,7.16],[21,4.05],[26,1.62],[13,13.53]],"id":36993903},{"atl":[[300,0.66],[350,0.56],[200,0.66],[250,0.53]],"id":36993903},{"atb":[[17,2.53],[12,11.06],[8.8,20.81],[14.5,6.01]],"id":37267533},{"atl":[[270,0.73],[170,0.78],[220,0.9],[120,1.1]],"id":37267533},{"atb":[[16.5,5.23],[9.6,18.88],[19,2.25],[14,9.36]],"id":37455733},{"atl":[[140,0.95],[290,0.68],[190,0.69],[240,0.82]],"id":37455733},{"atb":[[7.2,26.19],[9.2,14.85],[10.5,8.54],[13,3.38]],"id":22150928},{"atl":[[80,1.67],[160,1.25],[210,0.94],[110,1.21]],"id":22150928},{"atb":[[1.8,50.74],[1.6,270.65],[1.7,173.99],[1.75,108.26]],"id":43154433},{"atl":[[4,66.14],[4.5,56.69],[3.5,52.91],[3.75,48.1]],"id":43154433}],"con":true,"img":false}]}
{"op":"mcm","clk":"5346195992","pt":1646082440880,"mc":[{"id":"1.195395455","rc":[{"atb":[[6.4,0],[11,0],[8.4,0],[9.4,0]],"id":37672294},{"atl":[[80,0],[160,0],[55,0],[110,0]],"id":37672294},{"atb":[[4.8,0],[4.3,0],[3.4,0],[3.9,0]],"id":28002629},{"atl":[[18,0],[21,0],[26,0],[15.5,0]],"id":28002629},{"atb":[[3.4,0],[3.15,0],[2.96,0],[2.76,0]],"id":42393370},{"atl":[[11,0],[13.5,0],[8.4,0],[9.4,0]],"id":42393370},{"atb":[[18,0],[21,0],[26,0],[13,0]],"id":36993903},{"atl":[[300,0],[350,0],[200,0],[250,0]],"id":36993903},{"atb":[[17,0],[12,0],[8.8,0],[14.5,0]],"id":37267533},{"atl":[[270,0],[170,0],[220,0],[120,0]],"id":37267533},{"atb":[[16.5,0],[9.6,0],[19,0],[14,0]],"id":37455733},{"atl":[[140,0],[290,0],[190,0],[240,0]],"id":37455733},{"atb":[[7.2,0],[9.2,0],[10.5,0],[13,0]],"id":22150928},{"atl":[[80,0],[160,0],[210,0],[110,0]],"id":22150928},{"spn":2.65,"spf":"NaN","id":43154433}],"con":true,"img":false}]}
{"op":"mcm","clk":"5346196483","pt":1646082446521,"mc":[{"id":"1.195395455","rc":[{"atb":[[6.4,30.07],[11,4.05],[8.4,16.46],[9.4,9.66]],"id":37672294},{"atl":[[80,1.67],[160,1.25],[55,2.45],[110,1.81]],"id":37672294},{"atb":[[4.8,10.68],[4.3,24.6],[3.4,67.66],[3.9,41.99]],"id":28002629},{"atl":[[18,7.78],[21,9.92],[26,7.93],[15.5,9.12]],"id":28002629},{"atb":[[3.6,15.61],[3.1,57.99],[3.35,34.55],[2.84,88.25]],"id":42393370},{"atl":[[12,18.04],[9.8,15.03],[8.8,16.95],[14.5,14.7]],"id":42393370},{"atb":[[18,7.16],[21,4.05],[26,1.62],[13,13.53]],"id":36993903},{"atl":[[300,0.66],[350,0.56],[200,0.66],[250,0.53]],"id":36993903},{"atb":[[17,2.53],[12,11.06],[8.8,20.81],[14.5,6.01]],"id":37267533},{"atl":[[270,0.73],[170,0.78],[220,0.9],[120,1.1]],"id":37267533},{"atb":[[18,4.77],[21,2.02],[10.5,17.09],[15.5,8.4]],"id":37455733},{"atl":[[150,0.88],[300,0.66],[200,0.66],[250,0.79]],"id":37455733},{"atb":[[7.2,26.19],[9.2,14.85],[10.5,8.54],[13,3.38]],"id":22150928},{"atl":[[80,1.67],[160,1.25],[210,0.94],[110,1.21]],"id":22150928}],"con":true,"img":false}]}
{"op":"mcm","clk":"5346204628","pt":1646082532158,"mc":[{"id":"1.195395455","rc":[{"spn":33.0,"spf":"NaN","id":37672294},{"spn":10.15,"spf":"NaN","id":28002629},{"spn":6.2,"spf":"NaN","id":42393370},{"spn":113.0,"spf":"NaN","id":36993903},{"spn":68.5,"spf":"NaN","id":37267533},{"spn":85.5,"spf":"NaN","id":37455733},{"atb":[[7.2,0],[9.2,0],[10.5,0],[13,0]],"id":22150928},{"atl":[[80,0],[160,0],[210,0],[110,0]],"id":22150928},{"atb":[[1.8,0],[1.6,0],[1.7,0],[1.75,0]],"id":43154433},{"atl":[[4,0],[4.5,0],[3.5,0],[3.75,0]],"id":43154433},{"spn":"NaN","spf":"NaN","id":43154433}],"con":true,"img":false}]}
{"op":"mcm","clk":"5346204839","pt":1646082534504,"mc":[{"id":"1.195395455","rc":[{"atb":[[7.2,26.19],[9.2,14.85],[10.5,8.54],[13,3.38]],"id":22150928},{"atl":[[80,1.67],[160,1.25],[210,0.94],[110,1.21]],"id":22150928},{"atb":[[1.8,50.74],[1.6,270.65],[1.7,173.99],[1.75,108.26]],"id":43154433},{"atl":[[4,66.14],[4.5,56.69],[3.5,52.91],[3.75,48.1]],"id":43154433}],"con":true,"img":false}]}
{"op":"mcm","clk":"5346223648","pt":1646082746444,"mc":[{"id":"1.195395455","rc":[{"atb":[[15.5,0]],"id":37455733},{"atl":[[150,0],[200,0],[250,0]],"id":37455733},{"spn":160.5,"spf":"NaN","id":37455733},{"spn":46.5,"spf":"NaN","id":22150928},{"spn":2.65,"spf":"NaN","id":43154433}],"con":true,"img":false}]}
{"op":"mcm","clk":"5346223656","pt":1646082746591,"mc":[{"id":"1.195395455","rc":[{"atb":[[6.4,0],[11,0],[8.4,0],[9.4,0]],"id":37672294},{"atl":[[80,0],[160,0],[55,0],[110,0]],"id":37672294},{"atb":[[4.8,0],[4.3,0],[3.4,0],[3.9,0]],"id":28002629},{"atl":[[18,0],[21,0],[26,0],[15.5,0]],"id":28002629},{"atb":[[3.6,0],[3.1,0],[3.35,0],[2.84,0]],"id":42393370},{"atl":[[12,0],[9.8,0],[8.8,0],[14.5,0]],"id":42393370},{"atb":[[18,0],[21,0],[26,0],[13,0]],"id":36993903},{"atl":[[300,0],[350,0],[200,0],[250,0]],"id":36993903},{"atb":[[17,0],[12,0],[8.8,0],[14.5,0]],"id":37267533},{"atl":[[270,0],[170,0],[220,0],[120,0]],"id":37267533},{"atb":[[18,0],[21,0],[10.5,0]],"id":37455733},{"atl":[[300,0]],"id":37455733},{"atb":[[7.2,0],[9.2,0],[10.5,0],[13,0]],"id":22150928},{"atl":[[80,0],[160,0],[210,0],[110,0]],"id":22150928},{"atb":[[1.8,0],[1.6,0],[1.7,0],[1.75,0]],"id":43154433},{"atl":[[4,0],[4.5,0],[3.5,0],[3.75,0]],"id":43154433}],"con":true,"img":false}]}
{"op":"mcm","clk":"5346226100","pt":1646082775428,"mc":[{"id":"1.195395455","rc":[{"atb":[[6.4,30.07],[11,4.05],[8.4,16.46],[9.4,9.66]],"id":37672294},{"atl":[[80,1.67],[160,1.25],[55,2.45],[110,1.81]],"id":37672294},{"atb":[[4.8,10.68],[4.3,24.6],[3.4,67.66],[3.9,41.99]],"id":28002629},{"atl":[[18,7.78],[21,9.92],[26,7.93],[15.5,9.12]],"id":28002629},{"atb":[[3.6,15.61],[3.1,57.99],[3.35,34.55],[2.84,88.25]],"id":42393370},{"atl":[[12,18.04],[9.8,15.03],[8.8,16.95],[14.5,14.7]],"id":42393370},{"atb":[[18,7.16],[21,4.05],[26,1.62],[13,13.53]],"id":36993903},{"atl":[[300,0.66],[350,0.56],[200,0.66],[250,0.53]],"id":36993903},{"atb":[[17.5,4.92],[20,2.13],[10,18.04],[15,8.69]],"id":37267533},{"atl":[[150,0.88],[300,0.66],[200,0.66],[250,0.79]],"id":37267533},{"atb":[[18,4.77],[21,2.02],[10.5,17.09],[15.5,8.4]],"id":37455733},{"atl":[[150,0.88],[300,0.66],[200,0.66],[250,0.79]],"id":37455733},{"atb":[[6.4,30.07],[11,4.05],[8.4,16.46],[9.4,9.66]],"id":22150928},{"atl":[[80,1.67],[160,1.25],[55,2.45],[110,1.81]],"id":22150928},{"atb":[[1.8,50.74],[1.6,270.65],[1.7,173.99],[1.75,108.26]],"id":43154433},{"atl":[[4,66.14],[4.5,56.69],[3.5,52.91],[3.75,48.1]],"id":43154433}],"con":true,"img":false}]}
{"op":"mcm","clk":"5346252991","pt":1646083002680,"mc":[{"id":"1.195395455","marketDefinition":{"bspMarket":true,"turnInPlayEnabled":false,"persistenceEnabled":false,"marketBaseRate":5.0,"eventId":"31270459","eventTypeId":"4339","numberOfWinners":1,"bettingType":"ODDS","marketType":"WIN","marketTime":"2022-03-01T02:04:00.000Z","suspendTime":"2022-03-01T02:04:00.000Z","bspReconciled":false,"complete":true,"inPlay":false,"crossMatching":false,"runnersVoidable":false,"numberOfActiveRunners":8,"betDelay":0,"status":"OPEN","runners":[{"status":"ACTIVE","sortPriority":1,"id":37672294,"name":"1. Wizard Willie"},{"status":"ACTIVE","sortPriority":2,"id":28002629,"name":"2. St Andrews"},{"status":"ACTIVE","sortPriority":3,"id":43154433,"name":"3. Sapporo Bale"},{"status":"ACTIVE","sortPriority":4,"id":42393370,"name":"5. Goldstar Tookie"},{"status":"ACTIVE","sortPriority":5,"id":22150928,"name":"6. Smash Grenade"},{"status":"ACTIVE","sortPriority":6,"id":36993903,"name":"7. Baldrick"},{"status":"ACTIVE","sortPriority":7,"id":37267533,"name":"8. Diamond Empress"},{"status":"ACTIVE","sortPriority":8,"id":37455733,"name":"9. Just Stagger"}],"regulators":["MR_INT"],"venue":"Addington","countryCode":"NZ","discountAllowed":true,"timezone":"NZ","openDate":"2022-02-28T23:02:00.000Z","version":4380660692,"name":"R11 295m C2","eventName":"Addington (NZL) 1st Mar"},"rc":[{"atb":[[6.4,30.07],[11,4.05],[8.4,16.46],[9.4,9.66]],"id":37672294},{"atl":[[80,1.67],[160,1.25],[55,2.45],[110,1.81]],"id":37672294},{"spn":33.0,"spf":"NaN","id":37672294},{"atb":[[4.8,10.68],[4.3,24.6],[3.4,67.66],[3.9,41.99]],"id":28002629},{"atl":[[18,7.78],[21,9.92],[26,7.93],[15.5,9.12]],"id":28002629},{"spn":10.15,"spf":"NaN","id":28002629},{"atb":[[3.6,15.61],[3.1,57.99],[3.35,34.55],[2.84,88.25]],"id":42393370},{"atl":[[12,18.04],[9.8,15.03],[8.8,16.95],[14.5,14.7]],"id":42393370},{"spn":6.2,"spf":"NaN","id":42393370},{"atb":[[18,7.16],[21,4.05],[26,1.62],[13,13.53]],"id":36993903},{"atl":[[300,0.66],[350,0.56],[200,0.66],[250,0.53]],"id":36993903},{"spn":113.0,"spf":"NaN","id":36993903},{"atb":[[17.5,4.92],[20,2.13],[10,18.04],[15,8.69]],"id":37267533},{"atl":[[150,0.88],[300,0.66],[200,0.66],[250,0.79]],"id":37267533},{"spn":85.0,"spf":"NaN","id":37267533},{"atb":[[18,4.77],[21,2.02],[10.5,17.09],[15.5,8.4]],"id":37455733},{"atl":[[150,0.88],[300,0.66],[200,0.66],[250,0.79]],"id":37455733},{"spn":85.5,"spf":"NaN","id":37455733},{"atb":[[6.4,30.07],[11,4.05],[8.4,16.46],[9.4,9.66]],"id":22150928},{"atl":[[80,1.67],[160,1.25],[55,2.45],[110,1.81]],"id":22150928},{"spn":33.0,"spf":"NaN","id":22150928},{"atb":[[1.8,50.74],[1.6,270.65],[1.7,173.99],[1.75,108.26]],"id":43154433},{"atl":[[4,66.14],[4.5,56.69],[3.5,52.91],[3.75,48.1]],"id":43154433},{"spn":2.65,"spf":"NaN","id":43154433}],"con":true,"img":true}]}
{"op":"mcm","clk":"5346262710","pt":1646083101481,"mc":[{"id":"1.195395455","rc":[{"atb":[[6.4,0],[11,0],[8.4,0],[9.4,0]],"id":37672294},{"atl":[[80,0],[160,0],[55,0],[110,0]],"id":37672294},{"spn":"NaN","spf":"NaN","id":37672294},{"spn":85.0,"spf":"NaN","id":37267533},{"spn":85.5,"spf":"NaN","id":37455733},{"spn":33.0,"spf":"NaN","id":22150928}],"con":true,"img":false}]}
{"op":"mcm","clk":"5346262947","pt":1646083104399,"mc":[{"id":"1.195395455","rc":[{"atb":[[6.4,30.07],[11,4.05],[8.4,16.46],[9.4,9.66]],"id":37672294},{"atl":[[80,1.67],[160,1.25],[55,2.45],[110,1.81]],"id":37672294}],"con":true,"img":false}]}
{"op":"mcm","clk":"5346267327","pt":1646083161480,"mc":[{"id":"1.195395455","rc":[{"atb":[[6.4,0],[11,0],[8.4,0],[9.4,0]],"id":37672294},{"atl":[[80,0],[160,0],[55,0],[110,0]],"id":37672294},{"atb":[[4.8,0],[4.3,0],[3.4,0],[3.9,0]],"id":28002629},{"atl":[[18,0],[21,0],[26,0],[15.5,0]],"id":28002629},{"atb":[[3.6,0],[3.1,0],[3.35,0],[2.84,0]],"id":42393370},{"atl":[[12,0],[9.8,0],[8.8,0],[14.5,0]],"id":42393370},{"atb":[[6.4,0],[11,0],[8.4,0],[9.4,0]],"id":22150928},{"atl":[[80,0],[160,0],[55,0],[110,0]],"id":22150928},{"atb":[[1.8,0],[1.6,0],[1.7,0],[1.75,0]],"id":43154433},{"atl":[[4,0],[4.5,0],[3.5,0],[3.75,0]],"id":43154433}],"con":true,"img":false}]}
{"op":"mcm","clk":"5346267674","pt":1646083166473,"mc":[{"id":"1.195395455","rc":[{"atb":[[6.4,30.07],[11,4.05],[8.4,16.46],[9.4,9.66]],"id":37672294},{"atl":[[80,1.67],[160,1.25],[55,2.45],[110,1.81]],"id":37672294},{"spn":33.0,"spf":"NaN","id":37672294},{"atb":[[4.8,10.68],[4.3,24.6],[3.4,67.66],[3.9,41.99]],"id":28002629},{"atl":[[18,7.78],[21,9.92],[26,7.93],[15.5,9.12]],"id":28002629},{"atb":[[2.8,90.21],[3,60.89],[3.25,36.08],[3.5,16.23]],"id":42393370},{"atl":[[11,19.84],[13.5,15.87],[8.4,17.87],[9.4,15.75]],"id":42393370},{"spn":5.95,"spf":"NaN","id":42393370},{"atb":[[6.4,30.07],[11,4.05],[8.4,16.46],[9.4,9.66]],"id":22150928},{"atl":[[80,1.67],[160,1.25],[55,2.45],[110,1.81]],"id":22150928},{"atb":[[1.8,50.74],[1.6,270.65],[1.7,173.99],[1.75,108.26]],"id":43154433},{"atl":[[4,66.14],[4.5,56.69],[3.5,52.91],[3.75,48.1]],"id":43154433}],"con":true,"img":false}]}
{"op":"mcm","clk":"5346272705","pt":1646083234955,"mc":[{"id":"1.195395455","marketDefinition":{"bspMarket":true,"turnInPlayEnabled":false,"persistenceEnabled":false,"marketBaseRate":5.0,"eventId":"31270459","eventTypeId":"4339","numberOfWinners":1,"bettingType":"ODDS","marketType":"WIN","marketTime":"2022-03-01T02:04:00.000Z","suspendTime":"2022-03-01T02:04:00.000Z","bspReconciled":false,"complete":true,"inPlay":false,"crossMatching":false,"runnersVoidable":false,"numberOfActiveRunners":8,"betDelay":0,"status":"SUSPENDED","runners":[{"status":"ACTIVE","sortPriority":1,"id":37672294,"name":"1. Wizard Willie"},{"status":"ACTIVE","sortPriority":2,"id":28002629,"name":"2. St Andrews"},{"status":"ACTIVE","sortPriority":3,"id":43154433,"name":"3. Sapporo Bale"},{"status":"ACTIVE","sortPriority":4,"id":42393370,"name":"5. Goldstar Tookie"},{"status":"ACTIVE","sortPriority":5,"id":22150928,"name":"6. Smash Grenade"},{"status":"ACTIVE","sortPriority":6,"id":36993903,"name":"7. Baldrick"},{"status":"ACTIVE","sortPriority":7,"id":37267533,"name":"8. Diamond Empress"},{"status":"ACTIVE","sortPriority":8,"id":37455733,"name":"9. Just Stagger"}],"regulators":["MR_INT"],"venue":"Addington","countryCode":"NZ","discountAllowed":true,"timezone":"NZ","openDate":"2022-02-28T23:02:00.000Z","version":4380772702,"name":"R11 295m C2","eventName":"Addington (NZL) 1st Mar"},"rc":[],"con":true,"img":false}]}
{"op":"mcm","clk":"5346274031","pt":1646083252299,"mc":[{"id":"1.195395455","rc":[{"atb":[[18,0],[21,0],[10.5,0],[15.5,0]],"id":37455733},{"atl":[[150,0],[300,0],[200,0],[250,0]],"id":37455733}],"con":true,"img":false}]}
{"op":"mcm","clk":"5346274088","pt":1646083252990,"mc":[{"id":"1.195395455","marketDefinition":{"bspMarket":true,"turnInPlayEnabled":false,"persistenceEnabled":false,"marketBaseRate":5.0,"eventId":"31270459","eventTypeId":"4339","numberOfWinners":1,"bettingType":"ODDS","marketType":"WIN","marketTime":"2022-03-01T02:04:00.000Z","suspendTime":"2022-03-01T02:04:00.000Z","bspReconciled":false,"complete":true,"inPlay":false,"crossMatching":false,"runnersVoidable":false,"numberOfActiveRunners":7,"betDelay":0,"status":"SUSPENDED","runners":[{"status":"ACTIVE","sortPriority":1,"id":37672294,"name":"1. Wizard Willie"},{"status":"ACTIVE","sortPriority":2,"id":28002629,"name":"2. St Andrews"},{"status":"ACTIVE","sortPriority":3,"id":43154433,"name":"3. Sapporo Bale"},{"status":"ACTIVE","sortPriority":4,"id":42393370,"name":"5. Goldstar Tookie"},{"status":"ACTIVE","sortPriority":5,"id":22150928,"name":"6. Smash Grenade"},{"status":"ACTIVE","sortPriority":6,"id":37267533,"name":"8. Diamond Empress"},{"status":"ACTIVE","sortPriority":7,"id":37455733,"name":"9. Just Stagger"},{"status":"REMOVED","sortPriority":8,"removalDate":"2022-02-28T21:20:52.000Z","id":36993903,"name":"7. Baldrick"}],"regulators":["MR_INT"],"venue":"Addington","countryCode":"NZ","discountAllowed":true,"timezone":"NZ","openDate":"2022-02-28T23:02:00.000Z","version":4380773812,"name":"R11 295m C2","eventName":"Addington (NZL) 1st Mar"},"rc":[],"con":true,"img":false}]}
{"op":"mcm","clk":"5346274088","pt":1646083252990,"mc":[{"id":"1.195395455","rc":[{"atb":[[6.4,0],[11,0],[8.4,0],[9.4,0]],"id":37672294},{"atl":[[80,0],[160,0],[55,0],[110,0]],"id":37672294},{"atb":[[4.8,0],[4.3,0],[3.4,0],[3.9,0]],"id":28002629},{"atl":[[18,0],[21,0],[26,0],[15.5,0]],"id":28002629},{"atb":[[2.8,0],[3,0],[3.25,0],[3.5,0]],"id":42393370},{"atl":[[11,0],[13.5,0],[8.4,0],[9.4,0]],"id":42393370},{"atb":[[18,0],[21,0],[26,0],[13,0]],"id":36993903},{"atl":[[300,0],[350,0],[200,0],[250,0]],"id":36993903},{"atb":[[17.5,0],[20,0],[10,0],[15,0]],"id":37267533},{"atl":[[150,0],[300,0],[200,0],[250,0]],"id":37267533},{"atb":[[6.4,0],[11,0],[8.4,0],[9.4,0]],"id":22150928},{"atl":[[80,0],[160,0],[55,0],[110,0]],"id":22150928},{"atb":[[1.8,0],[1.6,0],[1.7,0],[1.75,0]],"id":43154433},{"atl":[[4,0],[4.5,0],[3.5,0],[3.75,0]],"id":43154433}],"con":true,"img":false}]}
{"op":"mcm","clk":"5346274405","pt":1646083256995,"mc":[{"id":"1.195395455","marketDefinition":{"bspMarket":true,"turnInPlayEnabled":false,"persistenceEnabled":false,"marketBaseRate":5.0,"eventId":"31270459","eventTypeId":"4339","numberOfWinners":1,"bettingType":"ODDS","marketType":"WIN","marketTime":"2022-03-01T02:04:00.000Z","suspendTime":"2022-03-01T02:04:00.000Z","bspReconciled":false,"complete":true,"inPlay":false,"crossMatching":false,"runnersVoidable":false,"numberOfActiveRunners":7,"betDelay":0,"status":"OPEN","runners":[{"status":"ACTIVE","sortPriority":1,"id":37672294,"name":"1. Wizard Willie"},{"status":"ACTIVE","sortPriority":2,"id":28002629,"name":"2. St Andrews"},{"status":"ACTIVE","sortPriority":3,"id":43154433,"name":"3. Sapporo Bale"},{"status":"ACTIVE","sortPriority":4,"id":42393370,"name":"5. Goldstar Tookie"},{"status":"ACTIVE","sortPriority":5,"id":22150928,"name":"6. Smash Grenade"},{"status":"ACTIVE","sortPriority":6,"id":37267533,"name":"8. Diamond Empress"},{"status":"ACTIVE","sortPriority":7,"id":37455733,"name":"9. Just Stagger"},{"status":"REMOVED","sortPriority":8,"removalDate":"2022-02-28T21:20:52.000Z","id":36993903,"name":"7. Baldrick"}],"regulators":["MR_INT"],"venue":"Addington","countryCode":"NZ","discountAllowed":true,"timezone":"NZ","openDate":"2022-02-28T23:02:00.000Z","version":4380773820,"name":"R11 295m C2","eventName":"Addington (NZL) 1st Mar"},"rc":[],"con":true,"img":false}]}
{"op":"mcm","clk":"5346533081","pt":1646089410920,"mc":[{"id":"1.195395455","rc":[{"spl":[[100,2]],"id":37672294},{"spn":1.0,"spf":1.0,"id":37672294},{"spl":[[100,2]],"id":28002629},{"spn":1.0,"spf":1.0,"id":28002629},{"spl":[[100,2]],"id":42393370},{"spn":1.0,"spf":1.0,"id":42393370},{"spl":[[100,2]],"id":37267533},{"spn":1.0,"spf":1.0,"id":37267533},{"spl":[[100,2]],"id":37455733},{"spn":1.0,"spf":1.0,"id":37455733},{"spl":[[100,2]],"id":22150928},{"spn":1.0,"spf":1.0,"id":22150928},{"spl":[[100,2]],"id":43154433},{"spn":1.0,"spf":1.0,"id":43154433}],"con":true,"img":false}]}
{"op":"mcm","clk":"5346638792","pt":1646093040125,"mc":[{"id":"1.195395455","rc":[{"atb":[[10.5,1.06]],"id":37672294},{"spn":55.25,"spf":1.0,"id":37672294},{"atb":[[4.3,2]],"id":28002629},{"spn":52.15,"spf":1.0,"id":28002629},{"atb":[[3.65,2]],"id":42393370},{"spn":51.82,"spf":1.0,"id":42393370},{"atb":[[22,0.49]],"id":37267533},{"spn":61.0,"spf":1.0,"id":37267533},{"atb":[[22,0.49]],"id":37455733},{"spn":61.0,"spf":1.0,"id":37455733},{"atb":[[11.5,0.96]],"id":22150928},{"spn":55.75,"spf":1.0,"id":22150928},{"atb":[[1.67,2]],"id":43154433},{"spn":50.83,"spf":1.0,"id":43154433}],"con":true,"img":false}]}
{"op":"mcm","clk":"5346719522","pt":1646095082824,"mc":[{"id":"1.195395455","rc":[{"atb":[[9.6,5.03],[6,25.96]],"id":37672294},{"atl":[[60,0.73],[120,2.7]],"id":37672294},{"spn":35.25,"spf":1.0,"id":37672294},{"atb":[[2.74,72.47],[3.9,14.92]],"id":28002629},{"atl":[[17,2.7],[34,3.78]],"id":28002629},{"spn":10.65,"spf":1.0,"id":28002629},{"atb":[[2.98,21.85],[2.2,106]],"id":42393370},{"atl":[[12,3.93],[24,5.4]],"id":42393370},{"spn":7.82,"spf":1.0,"id":42393370},{"atb":[[18,2.7],[11,12.43]],"id":37267533},{"atl":[[170,0.25],[340,2.7]],"id":37267533},{"atb":[[22,3.19],[13.5,9.6]],"id":37455733},{"atl":[[210,0.2],[430,2.7]],"id":37455733},{"atb":[[9.6,5.03],[6,25.96]],"id":22150928},{"atl":[[65,0.67],[130,2.7]],"id":22150928},{"spn":38.25,"spf":1.0,"id":22150928},{"atb":[[1.4,43.26],[1.25,466.22]],"id":43154433},{"atl":[[3.2,19.66],[5.7,24.79]],"id":43154433},{"spn":2.43,"spf":1.0,"id":43154433}],"con":true,"img":false}]}
{"op":"mcm","clk":"5346720204","pt":1646095099644,"mc":[{"id":"1.195395455","rc":[{"atb":[[1.01,2.23]],"id":37672294},{"atb":[[2.78,5.06]],"id":28002629},{"atb":[[1.01,2.23]],"id":22150928}],"con":true,"img":false}]}
{"op":"mcm","clk":"5346720210","pt":1646095099851,"mc":[{"id":"1.195395455","rc":[{"atb":[[1.01,1.72]],"id":37672294},{"atb":[[1.01,1.72]],"id":22150928}],"con":true,"img":false}]}
{"op":"mcm","clk":"5346720222","pt":1646095100057,"mc":[{"id":"1.195395455","rc":[{"atb":[[1.01,0]],"id":37672294}],"con":true,"img":false}]}
{"op":"mcm","clk":"5346720228","pt":1646095100159,"mc":[{"id":"1.195395455","rc":[{"atb":[[6.2,1.72]],"id":37672294}],"con":true,"img":false}]}
{"op":"mcm","clk":"5346720233","pt":1646095100262,"mc":[{"id":"1.195395455","rc":[{"atb":[[1.01,0]],"id":22150928}],"con":true,"img":false}]}
{"op":"mcm","clk":"5346720238","pt":1646095100364,"mc":[{"id":"1.195395455","rc":[{"atb":[[6.2,1.72]],"id":22150928}],"con":true,"img":false}]}
{"op":"mcm","clk":"5346722159","pt":1646095149254,"mc":[{"id":"1.195395455","rc":[{"atb":[[2.74,0]],"id":28002629}],"con":true,"img":false}]}
{"op":"mcm","clk":"5346722199","pt":1646095149354,"mc":[{"id":"1.195395455","rc":[{"atb":[[2.8,72.47]],"id":28002629}],"con":true,"img":false}]}
{"op":"mcm","clk":"5346722548","pt":1646095156730,"mc":[{"id":"1.195395455","rc":[{"atb":[[2.78,0]],"id":28002629}],"con":true,"img":false}]}
{"op":"mcm","clk":"5346722910","pt":1646095165779,"mc":[{"id":"1.195395455","rc":[{"atb":[[2.84,4.89]],"id":28002629}],"con":true,"img":false}]}
{"op":"mcm","clk":"5346725065","pt":1646095213721,"mc":[{"id":"1.195395455","rc":[{"atb":[[2.8,0]],"id":28002629}],"con":true,"img":false}]}
{"op":"mcm","clk":"5346725068","pt":1646095213825,"mc":[{"id":"1.195395455","rc":[{"atb":[[2.86,72.47]],"id":28002629}],"con":true,"img":false}]}
{"op":"mcm","clk":"5346725444","pt":1646095222963,"mc":[{"id":"1.195395455","rc":[{"atb":[[2.84,0]],"id":28002629}],"con":true,"img":false}]}
{"op":"mcm","clk":"5346725808","pt":1646095231853,"mc":[{"id":"1.195395455","rc":[{"atb":[[2.9,4.73]],"id":28002629}],"con":true,"img":false}]}
{"op":"mcm","clk":"5346727619","pt":1646095285684,"mc":[{"id":"1.195395455","rc":[{"atb":[[2.9,9.57]],"id":28002629}],"con":true,"img":false}]}
{"op":"mcm","clk":"5346727624","pt":1646095285885,"mc":[{"id":"1.195395455","rc":[{"atb":[[6.2,3.49]],"id":37672294}],"con":true,"img":false}]}
{"op":"mcm","clk":"5346727644","pt":1646095286655,"mc":[{"id":"1.195395455","rc":[{"atb":[[6.2,3.49]],"id":22150928}],"con":true,"img":false}]}
{"op":"mcm","clk":"5346728613","pt":1646095319630,"mc":[{"id":"1.195395455","marketDefinition":{"bspMarket":true,"turnInPlayEnabled":false,"persistenceEnabled":false,"marketBaseRate":5.0,"eventId":"31270459","eventTypeId":"4339","numberOfWinners":1,"bettingType":"ODDS","marketType":"WIN","marketTime":"2022-03-01T02:04:00.000Z","suspendTime":"2022-03-01T02:04:00.000Z","bspReconciled":false,"complete":true,"inPlay":false,"crossMatching":true,"runnersVoidable":false,"numberOfActiveRunners":7,"betDelay":0,"status":"OPEN","runners":[{"status":"ACTIVE","sortPriority":1,"id":37672294,"name":"1. Wizard Willie"},{"status":"ACTIVE","sortPriority":2,"id":28002629,"name":"2. St Andrews"},{"status":"ACTIVE","sortPriority":3,"id":43154433,"name":"3. Sapporo Bale"},{"status":"ACTIVE","sortPriority":4,"id":42393370,"name":"5. Goldstar Tookie"},{"status":"ACTIVE","sortPriority":5,"id":22150928,"name":"6. Smash Grenade"},{"status":"ACTIVE","sortPriority":6,"id":37267533,"name":"8. Diamond Empress"},{"status":"ACTIVE","sortPriority":7,"id":37455733,"name":"9. Just Stagger"},{"status":"REMOVED","sortPriority":8,"removalDate":"2022-02-28T21:20:52.000Z","id":36993903,"name":"7. Baldrick"}],"regulators":["MR_INT"],"venue":"Addington","countryCode":"NZ","discountAllowed":true,"timezone":"NZ","openDate":"2022-02-28T23:02:00.000Z","version":4380773820,"name":"R11 295m C2","eventName":"Addington (NZL) 1st Mar"},"rc":[],"con":true,"img":false}]}
{"op":"mcm","clk":"5346729166","pt":1646095334380,"mc":[{"id":"1.195395455","rc":[{"atb":[[6,0]],"id":37672294},{"atb":[[6,0]],"id":22150928}],"con":true,"img":false}]}
{"op":"mcm","clk":"5346729171","pt":1646095334486,"mc":[{"id":"1.195395455","rc":[{"atb":[[6.4,25.96]],"id":37672294},{"atb":[[6.4,25.96]],"id":22150928}],"con":true,"img":false}]}
{"op":"mcm","clk":"5346729478","pt":1646095343078,"mc":[{"id":"1.195395455","rc":[{"atb":[[6.2,1.76]],"id":37672294},{"atb":[[6.2,1.76]],"id":22150928}],"con":true,"img":false}]}
{"op":"mcm","clk":"5346729699","pt":1646095348619,"mc":[{"id":"1.195395455","rc":[{"atb":[[6.2,0]],"id":37672294},{"atb":[[6.2,0]],"id":22150928}],"con":true,"img":false}]}
{"op":"mcm","clk":"5346729816","pt":1646095352020,"mc":[{"id":"1.195395455","rc":[{"atb":[[1.01,2.23]],"id":37672294},{"atb":[[1.01,2.23]],"id":22150928}],"con":true,"img":false}]}
{"op":"mcm","clk":"5346729818","pt":1646095352117,"mc":[{"id":"1.195395455","rc":[{"atb":[[1.01,1.61]],"id":37672294},{"atb":[[1.01,1.61]],"id":22150928}],"con":true,"img":false}]}
{"op":"mcm","clk":"5346729824","pt":1646095352323,"mc":[{"id":"1.195395455","rc":[{"atb":[[1.01,0]],"id":37672294}],"con":true,"img":false}]}
{"op":"mcm","clk":"5346729826","pt":1646095352425,"mc":[{"id":"1.195395455","rc":[{"atb":[[6.6,1.61]],"id":37672294}],"con":true,"img":false}]}
{"op":"mcm","clk":"5346729828","pt":1646095352528,"mc":[{"id":"1.195395455","rc":[{"atb":[[1.01,0]],"id":22150928}],"con":true,"img":false}]}
{"op":"mcm","clk":"5346729831","pt":1646095352630,"mc":[{"id":"1.195395455","rc":[{"atb":[[6.6,1.61]],"id":22150928}],"con":true,"img":false}]}
{"op":"mcm","clk":"5346729891","pt":1646095354480,"mc":[{"id":"1.195395455","rc":[{"atb":[[1.01,1.67]],"id":37672294}],"con":true,"img":false}]}
{"op":"mcm","clk":"5346729897","pt":1646095354687,"mc":[{"id":"1.195395455","rc":[{"atb":[[1.01,1.67]],"id":22150928}],"con":true,"img":false}]}
{"op":"mcm","clk":"5346729899","pt":1646095354792,"mc":[{"id":"1.195395455","rc":[{"atb":[[1.01,1.64]],"id":37672294}],"con":true,"img":false}]}
{"op":"mcm","clk":"5346729909","pt":1646095355097,"mc":[{"id":"1.195395455","rc":[{"atb":[[1.01,0]],"id":37672294},{"atb":[[1.01,1.64]],"id":22150928}],"con":true,"img":false}]}
{"op":"mcm","clk":"5346729911","pt":1646095355202,"mc":[{"id":"1.195395455","rc":[{"atb":[[6.6,3.26]],"id":37672294}],"con":true,"img":false}]}
{"op":"mcm","clk":"5346729919","pt":1646095355507,"mc":[{"id":"1.195395455","rc":[{"atb":[[1.01,0]],"id":22150928}],"con":true,"img":false}]}
{"op":"mcm","clk":"5346729922","pt":1646095355612,"mc":[{"id":"1.195395455","rc":[{"atb":[[6.6,3.26]],"id":22150928}],"con":true,"img":false}]}
{"op":"mcm","clk":"5346730574","pt":1646095374378,"mc":[{"id":"1.195395455","rc":[{"atb":[[2.86,0]],"id":28002629}],"con":true,"img":false}]}
{"op":"mcm","clk":"5346730578","pt":1646095374431,"mc":[{"id":"1.195395455","rc":[{"atb":[[2.92,72.47]],"id":28002629}],"con":true,"img":false}]}
{"op":"mcm","clk":"5346730858","pt":1646095382048,"mc":[{"id":"1.195395455","rc":[{"atb":[[2.9,4.83]],"id":28002629}],"con":true,"img":false}]}
{"op":"mcm","clk":"5346731104","pt":1646095390691,"mc":[{"id":"1.195395455","rc":[{"atb":[[2.9,0]],"id":28002629}],"con":true,"img":false}]}
{"op":"mcm","clk":"5346731201","pt":1646095394082,"mc":[{"id":"1.195395455","rc":[{"atb":[[2.96,4.59]],"id":28002629}],"con":true,"img":false}]}
{"op":"mcm","clk":"5346731284","pt":1646095396808,"mc":[{"id":"1.195395455","rc":[{"atb":[[2.96,9.28]],"id":28002629}],"con":true,"img":false}]}
{"op":"mcm","clk":"5346731461","pt":1646095402013,"mc":[{"id":"1.195395455","rc":[{"atb":[[5.3,16.74]],"id":37672294},{"atb":[[9.4,8.57]],"id":37267533},{"atb":[[11.5,6.86]],"id":37455733},{"atb":[[5.3,16.74]],"id":22150928}],"con":true,"img":false}]}
{"op":"mcm","clk":"5346731836","pt":1646095414145,"mc":[{"id":"1.195395455","rc":[{"atb":[[6.4,0]],"id":37672294},{"atb":[[6.4,0]],"id":22150928}],"con":true,"img":false}]}
{"op":"mcm","clk":"5346731840","pt":1646095414196,"mc":[{"id":"1.195395455","rc":[{"atb":[[6.8,25.96]],"id":37672294},{"atb":[[6.8,25.96]],"id":22150928}],"con":true,"img":false}]}
{"op":"mcm","clk":"5346732046","pt":1646095421134,"mc":[{"id":"1.195395455","rc":[{"atb":[[6.6,1.64]],"id":37672294},{"atb":[[6.6,1.64]],"id":22150928}],"con":true,"img":false}]}
{"op":"mcm","clk":"5346732389","pt":1646095432853,"mc":[{"id":"1.195395455","rc":[{"atb":[[6.6,0]],"id":37672294},{"atb":[[6.6,0]],"id":22150928}],"con":true,"img":false}]}
{"op":"mcm","clk":"5346733081","pt":1646095453771,"mc":[{"id":"1.195395455","rc":[{"atb":[[2.92,0]],"id":28002629}],"con":true,"img":false}]}
{"op":"mcm","clk":"5346733085","pt":1646095453875,"mc":[{"id":"1.195395455","rc":[{"atb":[[2.98,72.47]],"id":28002629}],"con":true,"img":false}]}
{"op":"mcm","clk":"5346733319","pt":1646095460200,"mc":[{"id":"1.195395455","rc":[{"atb":[[2.96,4.68]],"id":28002629}],"con":true,"img":false}]}
{"op":"mcm","clk":"5346733580","pt":1646095468845,"mc":[{"id":"1.195395455","rc":[{"atb":[[2.96,0]],"id":28002629}],"con":true,"img":false}]}
{"op":"mcm","clk":"5346733590","pt":1646095469204,"mc":[{"id":"1.195395455","rc":[{"atb":[[3,4.5]],"id":28002629}],"con":true,"img":false}]}
{"op":"mcm","clk":"5346733765","pt":1646095474709,"mc":[{"id":"1.195395455","rc":[{"atb":[[3,9.1]],"id":28002629}],"con":true,"img":false}]}
{"op":"mcm","clk":"5346736057","pt":1646095530352,"mc":[{"id":"1.195395455","rc":[{"atb":[[2.98,0]],"id":28002629}],"con":true,"img":false}]}
{"op":"mcm","clk":"5346736065","pt":1646095530454,"mc":[{"id":"1.195395455","rc":[{"atb":[[3.05,72.47]],"id":28002629}],"con":true,"img":false}]}
{"op":"mcm","clk":"5346736396","pt":1646095538230,"mc":[{"id":"1.195395455","rc":[{"atb":[[3,4.59]],"id":28002629}],"con":true,"img":false}]}
{"op":"mcm","clk":"5346736733","pt":1646095546950,"mc":[{"id":"1.195395455","rc":[{"atb":[[3,0]],"id":28002629}],"con":true,"img":false}]}
{"op":"mcm","clk":"5346736743","pt":1646095547261,"mc":[{"id":"1.195395455","rc":[{"atb":[[3.1,4.29]],"id":28002629}],"con":true,"img":false}]}
{"op":"mcm","clk":"5346736964","pt":1646095553070,"mc":[{"id":"1.195395455","rc":[{"atb":[[3.1,8.66]],"id":28002629}],"con":true,"img":false}]}
{"op":"mcm","clk":"5346739199","pt":1646095605160,"mc":[{"id":"1.195395455","rc":[{"atb":[[3.15,58.95],[3.9,0],[3.05,0]],"id":28002629}],"con":true,"img":false}]}
{"op":"mcm","clk":"5346739202","pt":1646095605261,"mc":[{"id":"1.195395455","rc":[{"atb":[[3.95,14.92]],"id":28002629}],"con":true,"img":false}]}
{"op":"mcm","clk":"5346739557","pt":1646095613417,"mc":[{"id":"1.195395455","rc":[{"atb":[[3.1,4.37]],"id":28002629}],"con":true,"img":false}]}
{"op":"mcm","clk":"5346739791","pt":1646095619122,"mc":[{"id":"1.195395455","rc":[{"atb":[[3.1,0]],"id":28002629}],"con":true,"img":false}]}
{"op":"mcm","clk":"5346739919","pt":1646095622411,"mc":[{"id":"1.195395455","rc":[{"atb":[[3.2,4.1]],"id":28002629}],"con":true,"img":false}]}
{"op":"mcm","clk":"5346740036","pt":1646095625137,"mc":[{"id":"1.195395455","rc":[{"atb":[[3.2,8.28]],"id":28002629}],"con":true,"img":false}]}
{"op":"mcm","clk":"5346741724","pt":1646095678015,"mc":[{"id":"1.195395455","rc":[{"atb":[[3.95,0],[3.15,0]],"id":28002629}],"con":true,"img":false}]}
{"op":"mcm","clk":"5346741727","pt":1646095678116,"mc":[{"id":"1.195395455","rc":[{"atb":[[4,14.92],[3.25,58.95]],"id":28002629}],"con":true,"img":false}]}
{"op":"mcm","clk":"5346741948","pt":1646095685552,"mc":[{"id":"1.195395455","rc":[{"atb":[[3.2,4.17]],"id":28002629}],"con":true,"img":false}]}
{"op":"mcm","clk":"5346742124","pt":1646095691361,"mc":[{"id":"1.195395455","rc":[{"atb":[[3.2,0]],"id":28002629}],"con":true,"img":false}]}
{"op":"mcm","clk":"5346742202","pt":1646095694341,"mc":[{"id":"1.195395455","rc":[{"atb":[[2.62,46.3]],"id":37672294},{"atl":[[34,13.5]],"id":42393370},{"atb":[[2.62,46.3],[4.2,26.56]],"id":37267533},{"atb":[[2.62,46.3],[4.2,26.56]],"id":37455733},{"atb":[[2.62,46.3]],"id":22150928},{"atl":[[17,8.5],[34,13.5]],"id":43154433}],"con":true,"img":false}]}
{"op":"mcm","clk":"5346742211","pt":1646095694547,"mc":[{"id":"1.195395455","rc":[{"atb":[[3.3,3.91]],"id":28002629}],"con":true,"img":false}]}
{"op":"mcm","clk":"5346742285","pt":1646095697164,"mc":[{"id":"1.195395455","rc":[{"atb":[[3.3,7.91]],"id":28002629}],"con":true,"img":false}]}
{"op":"mcm","clk":"5346743750","pt":1646095749148,"mc":[{"id":"1.195395455","rc":[{"atb":[[4,0],[3.25,0]],"id":28002629}],"con":true,"img":false}]}
{"op":"mcm","clk":"5346743754","pt":1646095749250,"mc":[{"id":"1.195395455","rc":[{"atb":[[4.1,14.92],[3.35,58.95]],"id":28002629}],"con":true,"img":false}]}
{"op":"mcm","clk":"5346744006","pt":1646095757888,"mc":[{"id":"1.195395455","rc":[{"atb":[[3.3,3.99]],"id":28002629}],"con":true,"img":false}]}
{"op":"mcm","clk":"5346744048","pt":1646095759074,"mc":[{"id":"1.195395455","rc":[{"atb":[[2.64,43.9]],"id":28002629}],"con":true,"img":false}]}
{"op":"mcm","clk":"5346744174","pt":1646095763492,"mc":[{"id":"1.195395455","rc":[{"atb":[[3.3,0]],"id":28002629}],"con":true,"img":false}]}
{"op":"mcm","clk":"5346744272","pt":1646095766780,"mc":[{"id":"1.195395455","rc":[{"atb":[[3.4,3.76]],"id":28002629}],"con":true,"img":false}]}
{"op":"mcm","clk":"5346744335","pt":1646095769481,"mc":[{"id":"1.195395455","rc":[{"atb":[[3.4,7.59]],"id":28002629}],"con":true,"img":false}]}
{"op":"mcm","clk":"5346745813","pt":1646095818249,"mc":[{"id":"1.195395455","rc":[{"atb":[[4.1,0],[3.35,0]],"id":28002629}],"con":true,"img":false}]}
{"op":"mcm","clk":"5346745816","pt":1646095818351,"mc":[{"id":"1.195395455","rc":[{"atb":[[3.45,58.95],[4.4,14.92]],"id":28002629}],"con":true,"img":false}]}
{"op":"mcm","clk":"5346746066","pt":1646095826914,"mc":[{"id":"1.195395455","rc":[{"atb":[[3.4,3.83]],"id":28002629}],"con":true,"img":false}]}
{"op":"mcm","clk":"5346746329","pt":1646095835524,"mc":[{"id":"1.195395455","rc":[{"atb":[[3.4,0]],"id":28002629}],"con":true,"img":false}]}
{"op":"mcm","clk":"5346746345","pt":1646095835933,"mc":[{"id":"1.195395455","rc":[{"atb":[[3.5,3.6]],"id":28002629}],"con":true,"img":false}]}
{"op":"mcm","clk":"5346746479","pt":1646095841530,"mc":[{"id":"1.195395455","rc":[{"atb":[[3.5,7.28]],"id":28002629}],"con":true,"img":false}]}
{"op":"mcm","clk":"5346747910","pt":1646095886020,"mc":[{"id":"1.195395455","rc":[{"atb":[[3.45,0]],"id":28002629},{"spn":10.7,"spf":1.0,"id":28002629}],"con":true,"img":false}]}
{"op":"mcm","clk":"5346747914","pt":1646095886126,"mc":[{"id":"1.195395455","rc":[{"atb":[[3.55,58.95]],"id":28002629}],"con":true,"img":false}]}
{"op":"mcm","clk":"5346748171","pt":1646095893002,"mc":[{"id":"1.195395455","rc":[{"atb":[[3.5,3.67]],"id":28002629}],"con":true,"img":false}]}
{"op":"mcm","clk":"5346748476","pt":1646095902014,"mc":[{"id":"1.195395455","rc":[{"atb":[[3.6,3.47],[3.5,0]],"id":28002629}],"con":true,"img":false}]}
{"op":"mcm","clk":"5346748660","pt":1646095907953,"mc":[{"id":"1.195395455","rc":[{"atb":[[3.6,7.01]],"id":28002629}],"con":true,"img":false}]}
{"op":"mcm","clk":"5346749947","pt":1646095951957,"mc":[{"id":"1.195395455","rc":[{"atb":[[3.55,0],[3.65,47.59]],"id":28002629}],"con":true,"img":false}]}
{"op":"mcm","clk":"5346750161","pt":1646095959247,"mc":[{"id":"1.195395455","rc":[{"atb":[[3.6,3.54]],"id":28002629}],"con":true,"img":false}]}
{"op":"mcm","clk":"5346750401","pt":1646095968158,"mc":[{"id":"1.195395455","rc":[{"atb":[[3.6,0],[3.7,3.33]],"id":28002629}],"con":true,"img":false}]}
{"op":"mcm","clk":"5346750560","pt":1646095974156,"mc":[{"id":"1.195395455","rc":[{"atb":[[3.7,6.73]],"id":28002629}],"con":true,"img":false}]}
{"op":"mcm","clk":"5346751361","pt":1646096000998,"mc":[{"id":"1.195395455","rc":[{"atl":[[40,8.2]],"id":28002629},{"atl":[[22,8.2]],"id":42393370},{"atl":[[5.2,8.2]],"id":43154433}],"con":true,"img":false}]}
{"op":"mcm","clk":"5346751844","pt":1646096016268,"mc":[{"id":"1.195395455","rc":[{"atb":[[3.65,0]],"id":28002629}],"con":true,"img":false}]}
{"op":"mcm","clk":"5346751849","pt":1646096016370,"mc":[{"id":"1.195395455","rc":[{"atb":[[3.75,47.59]],"id":28002629}],"con":true,"img":false}]}
{"op":"mcm","clk":"5346752109","pt":1646096025388,"mc":[{"id":"1.195395455","rc":[{"atb":[[3.7,3.4]],"id":28002629}],"con":true,"img":false}]}
{"op":"mcm","clk":"5346752340","pt":1646096034311,"mc":[{"id":"1.195395455","rc":[{"atb":[[3.7,0]],"id":28002629}],"con":true,"img":false}]}
{"op":"mcm","clk":"5346752344","pt":1646096034377,"mc":[{"id":"1.195395455","rc":[{"atb":[[3.8,3.21]],"id":28002629}],"con":true,"img":false}]}
{"op":"mcm","clk":"5346752533","pt":1646096040221,"mc":[{"id":"1.195395455","rc":[{"atb":[[3.8,6.5]],"id":28002629}],"con":true,"img":false}]}
{"op":"mcm","clk":"5346752805","pt":1646096048288,"mc":[{"id":"1.195395455","rc":[{"atl":[[24,0]],"id":42393370},{"atl":[[5.7,0]],"id":43154433}],"con":true,"img":false}]}
{"op":"mcm","clk":"5346752808","pt":1646096048391,"mc":[{"id":"1.195395455","rc":[{"atl":[[21,5.4]],"id":42393370},{"atl":[[5.1,24.79]],"id":43154433}],"con":true,"img":false}]}
{"op":"mcm","clk":"5346753904","pt":1646096079852,"mc":[{"id":"1.195395455","rc":[{"atb":[[3.75,0]],"id":28002629}],"con":true,"img":false}]}
{"op":"mcm","clk":"5346753907","pt":1646096079958,"mc":[{"id":"1.195395455","rc":[{"atb":[[3.85,47.59]],"id":28002629}],"con":true,"img":false}]}
{"op":"mcm","clk":"5346754256","pt":1646096088484,"mc":[{"id":"1.195395455","rc":[{"atb":[[3.8,3.28]],"id":28002629}],"con":true,"img":false}]}
{"op":"mcm","clk":"5346754467","pt":1646096094494,"mc":[{"id":"1.195395455","rc":[{"atb":[[3.8,0]],"id":28002629}],"con":true,"img":false}]}
{"op":"mcm","clk":"5346754571","pt":1646096097522,"mc":[{"id":"1.195395455","rc":[{"atb":[[3.9,3.1]],"id":28002629}],"con":true,"img":false}]}
{"op":"mcm","clk":"5346754703","pt":1646096100712,"mc":[{"id":"1.195395455","rc":[{"atb":[[3.9,6.28]],"id":28002629}],"con":true,"img":false}]}
{"op":"mcm","clk":"5346755132","pt":1646096110827,"mc":[{"id":"1.195395455","rc":[{"atb":[[2.72,76.26]],"id":28002629}],"con":true,"img":false}]}
{"op":"mcm","clk":"5346755137","pt":1646096110930,"mc":[{"id":"1.195395455","rc":[{"atb":[[3.85,0]],"id":28002629}],"con":true,"img":false}]}
{"op":"mcm","clk":"5346755411","pt":1646096118635,"mc":[{"id":"1.195395455","rc":[{"atb":[[3.9,3.17]],"id":28002629}],"con":true,"img":false}]}
{"op":"mcm","clk":"5346755616","pt":1646096124550,"mc":[{"id":"1.195395455","rc":[{"atb":[[3.9,0]],"id":28002629}],"con":true,"img":false}]}
{"op":"mcm","clk":"5346755730","pt":1646096127531,"mc":[{"id":"1.195395455","rc":[{"atb":[[2.76,5.11]],"id":28002629}],"con":true,"img":false}]}
{"op":"mcm","clk":"5346755841","pt":1646096130560,"mc":[{"id":"1.195395455","rc":[{"atb":[[2.76,10.33]],"id":28002629}],"con":true,"img":false}]}
{"op":"mcm","clk":"5346756232","pt":1646096141357,"mc":[{"id":"1.195395455","rc":[{"atb":[[4.4,0]],"id":28002629},{"spn":10.65,"spf":1.0,"id":28002629}],"con":true,"img":false}]}
{"op":"mcm","clk":"5346756239","pt":1646096141460,"mc":[{"id":"1.195395455","rc":[{"atb":[[3.9,14.92]],"id":28002629}],"con":true,"img":false}]}
{"op":"mcm","clk":"5346758270","pt":1646096201891,"mc":[{"id":"1.195395455","rc":[{"atb":[[2.72,0]],"id":28002629}],"con":true,"img":false}]}
{"op":"mcm","clk":"5346758275","pt":1646096201995,"mc":[{"id":"1.195395455","rc":[{"atb":[[2.78,76.26]],"id":28002629}],"con":true,"img":false}]}
{"op":"mcm","clk":"5346758549","pt":1646096208691,"mc":[{"id":"1.195395455","rc":[{"atb":[[2.76,5.22]],"id":28002629}],"con":true,"img":false}]}
{"op":"mcm","clk":"5346758816","pt":1646096214811,"mc":[{"id":"1.195395455","rc":[{"atb":[[2.76,0]],"id":28002629}],"con":true,"img":false}]}
{"op":"mcm","clk":"5346758948","pt":1646096217589,"mc":[{"id":"1.195395455","rc":[{"atb":[[2.82,4.94]],"id":28002629}],"con":true,"img":false}]}
{"op":"mcm","clk":"5346759096","pt":1646096220821,"mc":[{"id":"1.195395455","rc":[{"atb":[[2.82,9.99]],"id":28002629}],"con":true,"img":false}]}
{"op":"mcm","clk":"5346760363","pt":1646096247444,"mc":[{"id":"1.195395455","rc":[{"atl":[[60,0]],"id":37672294}],"con":true,"img":false}]}
{"op":"mcm","clk":"5346760369","pt":1646096247544,"mc":[{"id":"1.195395455","rc":[{"atl":[[70,0.73]],"id":37672294}],"con":true,"img":false}]}
{"op":"mcm","clk":"5346761109","pt":1646096265367,"mc":[{"id":"1.195395455","rc":[{"spn":40.25,"spf":1.0,"id":37672294},{"atb":[[2.78,0]],"id":28002629}],"con":true,"img":false}]}
{"op":"mcm","clk":"5346761113","pt":1646096265470,"mc":[{"id":"1.195395455","rc":[{"atb":[[2.84,76.26]],"id":28002629}],"con":true,"img":false}]}
{"op":"mcm","clk":"5346761369","pt":1646096271792,"mc":[{"id":"1.195395455","rc":[{"atb":[[2.82,5.04]],"id":28002629}],"con":true,"img":false}]}
{"op":"mcm","clk":"5346761712","pt":1646096280899,"mc":[{"id":"1.195395455","rc":[{"atb":[[2.82,0]],"id":28002629}],"con":true,"img":false}]}
{"op":"mcm","clk":"5346761822","pt":1646096283830,"mc":[{"id":"1.195395455","rc":[{"atb":[[2.88,4.79]],"id":28002629}],"con":true,"img":false}]}
{"op":"mcm","clk":"5346761945","pt":1646096286923,"mc":[{"id":"1.195395455","rc":[{"atb":[[2.88,9.68]],"id":28002629}],"con":true,"img":false}]}
{"op":"mcm","clk":"5346763756","pt":1646096346850,"mc":[{"id":"1.195395455","rc":[{"atb":[[2.84,0]],"id":28002629}],"con":true,"img":false}]}
{"op":"mcm","clk":"5346763760","pt":1646096346899,"mc":[{"id":"1.195395455","rc":[{"atb":[[2.9,76.26]],"id":28002629}],"con":true,"img":false}]}
{"op":"mcm","clk":"5346764000","pt":1646096356017,"mc":[{"id":"1.195395455","rc":[{"atb":[[2.88,4.88]],"id":28002629}],"con":true,"img":false}]}
{"op":"mcm","clk":"5346764318","pt":1646096364958,"mc":[{"id":"1.195395455","rc":[{"atb":[[2.94,4.64]],"id":28002629}],"con":true,"img":false}]}
{"op":"mcm","clk":"5346764320","pt":1646096365064,"mc":[{"id":"1.195395455","rc":[{"atb":[[2.88,0]],"id":28002629}],"con":true,"img":false}]}
{"op":"mcm","clk":"5346764495","pt":1646096370966,"mc":[{"id":"1.195395455","rc":[{"atb":[[2.94,9.37]],"id":28002629}],"con":true,"img":false}]}
{"op":"mcm","clk":"5346766454","pt":1646096431066,"mc":[{"id":"1.195395455","rc":[{"atb":[[2.9,0]],"id":28002629}],"con":true,"img":false}]}
{"op":"mcm","clk":"5346766458","pt":1646096431169,"mc":[{"id":"1.195395455","rc":[{"atb":[[2.96,76.26]],"id":28002629}],"con":true,"img":false}]}
{"op":"mcm","clk":"5346766827","pt":1646096439973,"mc":[{"id":"1.195395455","rc":[{"atb":[[2.94,4.72]],"id":28002629}],"con":true,"img":false}]}
{"op":"mcm","clk":"5346767039","pt":1646096446188,"mc":[{"id":"1.195395455","rc":[{"atb":[[2.94,0]],"id":28002629}],"con":true,"img":false}]}
{"op":"mcm","clk":"5346767145","pt":1646096449110,"mc":[{"id":"1.195395455","rc":[{"atb":[[3,4.5]],"id":28002629}],"con":true,"img":false}]}
{"op":"mcm","clk":"5346767240","pt":1646096452292,"mc":[{"id":"1.195395455","rc":[{"atb":[[3,9.1]],"id":28002629}],"con":true,"img":false}]}
{"op":"mcm","clk":"5346769571","pt":1646096512097,"mc":[{"id":"1.195395455","rc":[{"atb":[[2.96,0],[3.05,61.65]],"id":28002629}],"con":true,"img":false}]}
{"op":"mcm","clk":"5346769829","pt":1646096521219,"mc":[{"id":"1.195395455","rc":[{"atb":[[3,4.59]],"id":28002629}],"con":true,"img":false}]}
{"op":"mcm","clk":"5346770117","pt":1646096530199,"mc":[{"id":"1.195395455","rc":[{"atb":[[3.1,4.29]],"id":28002629}],"con":true,"img":false}]}
{"op":"mcm","clk":"5346770128","pt":1646096530609,"mc":[{"id":"1.195395455","rc":[{"atb":[[3,0]],"id":28002629}],"con":true,"img":false}]}
{"op":"mcm","clk":"5346770313","pt":1646096536413,"mc":[{"id":"1.195395455","rc":[{"atb":[[3.1,8.66]],"id":28002629}],"con":true,"img":false}]}
{"op":"mcm","clk":"5346770351","pt":1646096537340,"mc":[{"id":"1.195395455","rc":[{"atb":[[1.67,0]],"id":43154433}],"con":true,"img":false}]}
{"op":"mcm","clk":"5346770357","pt":1646096537446,"mc":[{"id":"1.195395455","rc":[{"atb":[[1.71,2]],"id":43154433}],"con":true,"img":false}]}
{"op":"mcm","clk":"5346772370","pt":1646096590932,"mc":[{"id":"1.195395455","rc":[{"atb":[[3.9,0],[3.05,0]],"id":28002629},{"spn":2.45,"spf":1.0,"id":43154433}],"con":true,"img":false}]}
{"op":"mcm","clk":"5346772377","pt":1646096591034,"mc":[{"id":"1.195395455","rc":[{"atb":[[3.95,14.92],[3.15,61.65]],"id":28002629}],"con":true,"img":false}]}
{"op":"mcm","clk":"5346772752","pt":1646096599353,"mc":[{"id":"1.195395455","rc":[{"atb":[[3.1,4.37]],"id":28002629}],"con":true,"img":false}]}
{"op":"mcm","clk":"5346773156","pt":1646096608350,"mc":[{"id":"1.195395455","rc":[{"atb":[[3.2,4.1]],"id":28002629}],"con":true,"img":false}]}
{"op":"mcm","clk":"5346773165","pt":1646096608555,"mc":[{"id":"1.195395455","rc":[{"atb":[[3.1,0]],"id":28002629}],"con":true,"img":false}]}
{"op":"mcm","clk":"5346773420","pt":1646096614523,"mc":[{"id":"1.195395455","rc":[{"atb":[[3.2,8.28]],"id":28002629}],"con":true,"img":false}]}
{"op":"mcm","clk":"5346774459","pt":1646096642918,"mc":[{"id":"1.195395455","rc":[{"atb":[[5.8,20.83]],"id":37672294},{"atl":[[120,4.7]],"id":37672294},{"atb":[[1.41,243.9],[1.71,0]],"id":43154433},{"atl":[[4.1,32.26]],"id":43154433}],"con":true,"img":false}]}
{"op":"mcm","clk":"5346774462","pt":1646096643024,"mc":[{"id":"1.195395455","rc":[{"atb":[[2.82,43.9],[4.3,0]],"id":28002629},{"atl":[[17,6.49]],"id":28002629},{"atb":[[3,50]],"id":42393370},{"atl":[[13,8.2]],"id":42393370},{"atb":[[6.8,17.24]],"id":37267533},{"atl":[[340,4.7]],"id":37267533},{"atb":[[6.4,18.52]],"id":37455733},{"atl":[[660,2]],"id":37455733},{"atb":[[4.3,30.3]],"id":22150928},{"atl":[[130,4.7]],"id":22150928},{"atb":[[1.67,2]],"id":43154433}],"con":true,"img":false}]}
{"op":"mcm","clk":"5346774471","pt":1646096643233,"mc":[{"id":"1.195395455","rc":[{"atb":[[4.4,2]],"id":28002629},{"atb":[[1.41,0],[1.46,217.39]],"id":43154433}],"con":true,"img":false}]}
{"op":"mcm","clk":"5346774934","pt":1646096656614,"mc":[{"id":"1.195395455","rc":[{"spn":10.7,"spf":1.0,"id":28002629},{"atb":[[1.48,19.14]],"id":43154433},{"spn":2.43,"spf":1.0,"id":43154433}],"con":true,"img":false}]}
{"op":"mcm","clk":"5346774936","pt":1646096656716,"mc":[{"id":"1.195395455","rc":[{"atb":[[3.05,4.48]],"id":42393370}],"con":true,"img":false}]}
{"op":"mcm","clk":"5346775019","pt":1646096659442,"mc":[{"id":"1.195395455","rc":[{"atb":[[3.05,8.88]],"id":42393370},{"atb":[[1.48,37.91]],"id":43154433}],"con":true,"img":false}]}
{"op":"mcm","clk":"5346775338","pt":1646096667429,"mc":[{"id":"1.195395455","rc":[{"atb":[[3.95,0],[3.15,0]],"id":28002629}],"con":true,"img":false}]}
{"op":"mcm","clk":"5346775344","pt":1646096667530,"mc":[{"id":"1.195395455","rc":[{"atb":[[4,14.92],[3.25,61.65]],"id":28002629}],"con":true,"img":false}]}
{"op":"mcm","clk":"5346775633","pt":1646096674572,"mc":[{"id":"1.195395455","rc":[{"atb":[[3.2,4.17]],"id":28002629}],"con":true,"img":false}]}
{"op":"mcm","clk":"5346775848","pt":1646096680641,"mc":[{"id":"1.195395455","rc":[{"atb":[[3.2,0]],"id":28002629}],"con":true,"img":false}]}
{"op":"mcm","clk":"5346775947","pt":1646096683464,"mc":[{"id":"1.195395455","rc":[{"atb":[[3.3,3.91]],"id":28002629}],"con":true,"img":false}]}
{"op":"mcm","clk":"5346776077","pt":1646096687071,"mc":[{"id":"1.195395455","rc":[{"atb":[[3.3,7.91]],"id":28002629}],"con":true,"img":false}]}
{"op":"mcm","clk":"5346777262","pt":1646096717617,"mc":[{"id":"1.195395455","rc":[{"atl":[[21,0],[12.5,10.81]],"id":42393370},{"atl":[[4,38.85],[5.1,0]],"id":43154433}],"con":true,"img":false}]}
{"op":"mcm","clk":"5346777266","pt":1646096717720,"mc":[{"id":"1.195395455","rc":[{"atb":[[2.98,0]],"id":42393370},{"atb":[[1.4,0]],"id":43154433}],"con":true,"img":false}]}
{"op":"mcm","clk":"5346777271","pt":1646096717820,"mc":[{"id":"1.195395455","rc":[{"atb":[[3.1,21.85]],"id":42393370},{"atb":[[1.49,43.26]],"id":43154433}],"con":true,"img":false}]}
{"op":"mcm","clk":"5346777273","pt":1646096717928,"mc":[{"id":"1.195395455","rc":[{"atb":[[3,0],[3.15,21.85]],"id":42393370}],"con":true,"img":false}]}
{"op":"mcm","clk":"5346777546","pt":1646096725540,"mc":[{"id":"1.195395455","rc":[{"atb":[[3.05,4.48]],"id":42393370}],"con":true,"img":false}]}
{"op":"mcm","clk":"5346777922","pt":1646096734844,"mc":[{"id":"1.195395455","rc":[{"atb":[[3.05,0]],"id":42393370}],"con":true,"img":false}]}
{"op":"mcm","clk":"5346778158","pt":1646096742252,"mc":[{"id":"1.195395455","rc":[{"atb":[[3.25,0]],"id":28002629}],"con":true,"img":false}]}
{"op":"mcm","clk":"5346778162","pt":1646096742353,"mc":[{"id":"1.195395455","rc":[{"atb":[[3.35,61.65]],"id":28002629}],"con":true,"img":false}]}
{"op":"mcm","clk":"5346778388","pt":1646096749654,"mc":[{"id":"1.195395455","rc":[{"atb":[[3.3,3.99]],"id":28002629}],"con":true,"img":false}]}
{"op":"mcm","clk":"5346778647","pt":1646096758576,"mc":[{"id":"1.195395455","rc":[{"atb":[[3.4,3.76]],"id":28002629}],"con":true,"img":false}]}
{"op":"mcm","clk":"5346778656","pt":1646096758886,"mc":[{"id":"1.195395455","rc":[{"atb":[[3.3,0]],"id":28002629}],"con":true,"img":false}]}
{"op":"mcm","clk":"5346778854","pt":1646096764789,"mc":[{"id":"1.195395455","rc":[{"atb":[[3.4,7.59]],"id":28002629}],"con":true,"img":false}]}
{"op":"mcm","clk":"5346778897","pt":1646096766891,"mc":[{"id":"1.195395455","rc":[{"atb":[[3.1,0]],"id":42393370}],"con":true,"img":false}]}
{"op":"mcm","clk":"5346778899","pt":1646096766994,"mc":[{"id":"1.195395455","rc":[{"atb":[[3.2,21.85],[2.32,75.76]],"id":42393370}],"con":true,"img":false}]}
{"op":"mcm","clk":"5346778901","pt":1646096767096,"mc":[{"id":"1.195395455","rc":[{"atb":[[3.15,0]],"id":42393370}],"con":true,"img":false}]}
{"op":"mcm","clk":"5346779576","pt":1646096791422,"mc":[{"id":"1.195395455","rc":[{"atb":[[3.2,0]],"id":42393370}],"con":true,"img":false}]}
{"op":"mcm","clk":"5346779580","pt":1646096791525,"mc":[{"id":"1.195395455","rc":[{"atb":[[2.9,21.85]],"id":42393370}],"con":true,"img":false}]}
{"op":"mcm","clk":"5346779839","pt":1646096802871,"mc":[{"id":"1.195395455","rc":[{"atb":[[2.92,52.08]],"id":42393370}],"con":true,"img":false}]}
{"op":"mcm","clk":"5346779843","pt":1646096802973,"mc":[{"id":"1.195395455","rc":[{"atb":[[2.32,0]],"id":42393370}],"con":true,"img":false}]}
{"op":"mcm","clk":"5346780094","pt":1646096814762,"mc":[{"id":"1.195395455","rc":[{"atl":[[12.5,19.01],[13,0]],"id":42393370},{"atl":[[660,0],[980,2]],"id":37455733}],"con":true,"img":false}]}
{"op":"mcm","clk":"5346780112","pt":1646096815478,"mc":[{"id":"1.195395455","rc":[{"atb":[[4,0],[3.35,0]],"id":28002629}],"con":true,"img":false}]}
{"op":"mcm","clk":"5346780115","pt":1646096815581,"mc":[{"id":"1.195395455","rc":[{"atb":[[3.45,61.65],[4.5,14.92]],"id":28002629}],"con":true,"img":false}]}
{"op":"mcm","clk":"5346780205","pt":1646096818974,"mc":[{"id":"1.195395455","rc":[{"atb":[[2.96,4.68]],"id":42393370}],"con":true,"img":false}]}
{"op":"mcm","clk":"5346780282","pt":1646096821694,"mc":[{"id":"1.195395455","rc":[{"atb":[[2.96,9.28]],"id":42393370}],"con":true,"img":false}]}
{"op":"mcm","clk":"5346780286","pt":1646096821796,"mc":[{"id":"1.195395455","rc":[{"atb":[[3.4,3.83]],"id":28002629}],"con":true,"img":false}]}
{"op":"mcm","clk":"5346780601","pt":1646096830987,"mc":[{"id":"1.195395455","rc":[{"atb":[[3.4,0]],"id":28002629}],"con":true,"img":false}]}
{"op":"mcm","clk":"5346780688","pt":1646096833703,"mc":[{"id":"1.195395455","rc":[{"atb":[[3.5,3.6]],"id":28002629}],"con":true,"img":false}]}
{"op":"mcm","clk":"5346780811","pt":1646096836941,"mc":[{"id":"1.195395455","rc":[{"atb":[[3.5,7.28]],"id":28002629}],"con":true,"img":false}]}
{"op":"mcm","clk":"5346781630","pt":1646096863147,"mc":[{"id":"1.195395455","rc":[{"spn":10.75,"spf":1.0,"id":28002629},{"atb":[[2.9,0]],"id":42393370}],"con":true,"img":false}]}
{"op":"mcm","clk":"5346781634","pt":1646096863250,"mc":[{"id":"1.195395455","rc":[{"atb":[[3,21.85]],"id":42393370}],"con":true,"img":false}]}
{"op":"mcm","clk":"5346781638","pt":1646096863349,"mc":[{"id":"1.195395455","rc":[{"atb":[[2.92,0],[3.05,21.85]],"id":42393370}],"con":true,"img":false}]}
{"op":"mcm","clk":"5346781859","pt":1646096869977,"mc":[{"id":"1.195395455","rc":[{"atb":[[2.96,4.68]],"id":42393370}],"con":true,"img":false}]}
{"op":"mcm","clk":"5346782203","pt":1646096879085,"mc":[{"id":"1.195395455","rc":[{"atb":[[2.96,0]],"id":42393370}],"con":true,"img":false}]}
{"op":"mcm","clk":"5346782469","pt":1646096886081,"mc":[{"id":"1.195395455","rc":[{"atb":[[3.55,49.75]],"id":28002629}],"con":true,"img":false}]}
{"op":"mcm","clk":"5346782473","pt":1646096886181,"mc":[{"id":"1.195395455","rc":[{"atb":[[3.45,0]],"id":28002629}],"con":true,"img":false}]}
{"op":"mcm","clk":"5346782772","pt":1646096893901,"mc":[{"id":"1.195395455","rc":[{"atb":[[3.5,3.67]],"id":28002629}],"con":true,"img":false}]}
{"op":"mcm","clk":"5346783071","pt":1646096902815,"mc":[{"id":"1.195395455","rc":[{"atb":[[3.6,3.47]],"id":28002629}],"con":true,"img":false}]}
{"op":"mcm","clk":"5346783094","pt":1646096903427,"mc":[{"id":"1.195395455","rc":[{"atb":[[3.5,0]],"id":28002629}],"con":true,"img":false}]}
{"op":"mcm","clk":"5346783269","pt":1646096909045,"mc":[{"id":"1.195395455","rc":[{"atb":[[3.6,7.01]],"id":28002629}],"con":true,"img":false}]}
{"op":"mcm","clk":"5346783293","pt":1646096909759,"mc":[{"id":"1.195395455","rc":[{"atb":[[3,0]],"id":42393370}],"con":true,"img":false}]}
{"op":"mcm","clk":"5346783297","pt":1646096909862,"mc":[{"id":"1.195395455","rc":[{"atb":[[3.1,21.85]],"id":42393370}],"con":true,"img":false}]}
{"op":"mcm","clk":"5346783300","pt":1646096909964,"mc":[{"id":"1.195395455","rc":[{"atb":[[2.3,76.92],[3.05,0]],"id":42393370}],"con":true,"img":false}]}
{"op":"mcm","clk":"5346783302","pt":1646096910068,"mc":[{"id":"1.195395455","rc":[{"atb":[[3.15,21.85]],"id":42393370}],"con":true,"img":false}]}
{"op":"mcm","clk":"5346783306","pt":1646096910121,"mc":[{"id":"1.195395455","rc":[{"atb":[[2.3,0]],"id":42393370}],"con":true,"img":false}]}
{"op":"mcm","clk":"5346784105","pt":1646096932902,"mc":[{"id":"1.195395455","rc":[{"atb":[[4.5,0]],"id":28002629},{"spn":10.7,"spf":1.0,"id":28002629}],"con":true,"img":false}]}
{"op":"mcm","clk":"5346784109","pt":1646096933005,"mc":[{"id":"1.195395455","rc":[{"atb":[[3.8,14.92]],"id":28002629}],"con":true,"img":false}]}
{"op":"mcm","clk":"5346785031","pt":1646096955541,"mc":[{"id":"1.195395455","rc":[{"atb":[[3.55,0]],"id":28002629},{"atb":[[3.1,0]],"id":42393370}],"con":true,"img":false}]}
{"op":"mcm","clk":"5346785034","pt":1646096955642,"mc":[{"id":"1.195395455","rc":[{"atb":[[3.65,49.75]],"id":28002629},{"atb":[[3.2,21.85],[2.3,76.92]],"id":42393370}],"con":true,"img":false}]}
{"op":"mcm","clk":"5346785037","pt":1646096955748,"mc":[{"id":"1.195395455","rc":[{"atb":[[3.15,0]],"id":42393370}],"con":true,"img":false}]}
{"op":"mcm","clk":"5346785040","pt":1646096955851,"mc":[{"id":"1.195395455","rc":[{"atb":[[2.3,0],[3.25,21.85]],"id":42393370}],"con":true,"img":false}]}
{"op":"mcm","clk":"5346785368","pt":1646096963032,"mc":[{"id":"1.195395455","rc":[{"atb":[[3.6,3.54]],"id":28002629}],"con":true,"img":false}]}
{"op":"mcm","clk":"5346785667","pt":1646096969322,"mc":[{"id":"1.195395455","rc":[{"atb":[[3.6,0]],"id":28002629}],"con":true,"img":false}]}
{"op":"mcm","clk":"5346785771","pt":1646096971941,"mc":[{"id":"1.195395455","rc":[{"atb":[[3.7,3.33]],"id":28002629},{"atb":[[3.3,3.91]],"id":42393370}],"con":true,"img":false}]}
{"op":"mcm","clk":"5346785901","pt":1646096975230,"mc":[{"id":"1.195395455","rc":[{"atb":[[3.7,6.73]],"id":28002629}],"con":true,"img":false}]}
{"op":"mcm","clk":"5346787569","pt":1646097023040,"mc":[{"id":"1.195395455","rc":[{"atb":[[3.65,0]],"id":28002629},{"atb":[[3.2,0]],"id":42393370}],"con":true,"img":false}]}
{"op":"mcm","clk":"5346787574","pt":1646097023141,"mc":[{"id":"1.195395455","rc":[{"atb":[[3.75,49.75]],"id":28002629},{"atb":[[3.35,21.85]],"id":42393370}],"con":true,"img":false}]}
{"op":"mcm","clk":"5346787921","pt":1646097032160,"mc":[{"id":"1.195395455","rc":[{"atb":[[3.7,3.4]],"id":28002629},{"atb":[[3.3,0]],"id":42393370}],"con":true,"img":false}]}
{"op":"mcm","clk":"5346787932","pt":1646097032466,"mc":[{"id":"1.195395455","rc":[{"atb":[[2.82,0],[2.62,58.82]],"id":28002629},{"atl":[[12.5,10.81],[13,8.33]],"id":42393370},{"atl":[[980,0]],"id":37455733}],"con":true,"img":false}]}
{"op":"mcm","clk":"5346788265","pt":1646097041057,"mc":[{"id":"1.195395455","rc":[{"atb":[[3.8,18.14]],"id":28002629},{"atb":[[3.4,3.76]],"id":42393370}],"con":true,"img":false}]}
{"op":"mcm","clk":"5346788292","pt":1646097041774,"mc":[{"id":"1.195395455","rc":[{"atb":[[3.7,0]],"id":28002629}],"con":true,"img":false}]}
{"op":"mcm","clk":"5346788363","pt":1646097043468,"mc":[{"id":"1.195395455","rc":[{"atl":[[880,2]],"id":37455733}],"con":true,"img":false}]}
{"op":"mcm","clk":"5346788417","pt":1646097044759,"mc":[{"id":"1.195395455","rc":[{"atb":[[2.7,76.26]],"id":28002629}],"con":true,"img":false}]}
{"op":"mcm","clk":"5346788423","pt":1646097044859,"mc":[{"id":"1.195395455","rc":[{"atb":[[3.75,0]],"id":28002629}],"con":true,"img":false}]}
{"op":"mcm","clk":"5346788683","pt":1646097053173,"mc":[{"id":"1.195395455","rc":[{"atb":[[3.8,14.92]],"id":28002629}],"con":true,"img":false}]}
{"op":"mcm","clk":"5346788898","pt":1646097059587,"mc":[{"id":"1.195395455","rc":[{"atb":[[2.74,5.28]],"id":28002629}],"con":true,"img":false}]}
{"op":"mcm","clk":"5346789091","pt":1646097065198,"mc":[{"id":"1.195395455","rc":[{"atb":[[2.74,10.46]],"id":28002629}],"con":true,"img":false}]}
{"op":"mcm","clk":"5346789108","pt":1646097065708,"mc":[{"id":"1.195395455","rc":[{"atb":[[2.74,54.36],[2.62,0]],"id":28002629},{"atl":[[12,12.26],[13,0]],"id":42393370}],"con":true,"img":false}]}
{"op":"mcm","clk":"5346789152","pt":1646097066689,"mc":[{"id":"1.195395455","rc":[{"atl":[[21,6.49],[12.5,0]],"id":42393370}],"con":true,"img":false}]}
{"op":"mcm","clk":"5346789157","pt":1646097066791,"mc":[{"id":"1.195395455","rc":[{"atb":[[3.35,0]],"id":42393370}],"con":true,"img":false}]}
{"op":"mcm","clk":"5346789161","pt":1646097066892,"mc":[{"id":"1.195395455","rc":[{"atl":[[17,3.79]],"id":28002629},{"atb":[[3.3,21.85]],"id":42393370}],"con":true,"img":false}]}
{"op":"mcm","clk":"5346789166","pt":1646097067000,"mc":[{"id":"1.195395455","rc":[{"atl":[[32,3.23],[17,0],[19,2.7]],"id":28002629}],"con":true,"img":false}]}
{"op":"mcm","clk":"5346789444","pt":1646097074190,"mc":[{"id":"1.195395455","rc":[{"atb":[[2.74,49.18]],"id":28002629},{"atb":[[3.4,0]],"id":42393370}],"con":true,"img":false}]}
{"op":"mcm","clk":"5346789731","pt":1646097083237,"mc":[{"id":"1.195395455","rc":[{"atb":[[2.78,5.06]],"id":28002629},{"spn":11.7,"spf":1.0,"id":28002629},{"atb":[[3.35,3.83]],"id":42393370}],"con":true,"img":false}]}
{"op":"mcm","clk":"5346789843","pt":1646097086638,"mc":[{"id":"1.195395455","rc":[{"atb":[[2.74,43.9]],"id":28002629}],"con":true,"img":false}]}
{"op":"mcm","clk":"5346790076","pt":1646097092544,"mc":[{"id":"1.195395455","rc":[{"atb":[[2.78,10.22]],"id":28002629}],"con":true,"img":false}]}
{"op":"mcm","clk":"5346790370","pt":1646097099844,"mc":[{"id":"1.195395455","rc":[{"atl":[[19,5.93]],"id":28002629}],"con":true,"img":false}]}
{"op":"mcm","clk":"5346790374","pt":1646097099944,"mc":[{"id":"1.195395455","rc":[{"atl":[[32,0]],"id":28002629}],"con":true,"img":false}]}
{"op":"mcm","clk":"5346790794","pt":1646097110478,"mc":[{"id":"1.195395455","rc":[{"atb":[[2.7,0]],"id":28002629},{"atb":[[3.3,0]],"id":42393370}],"con":true,"img":false}]}
{"op":"mcm","clk":"5346790799","pt":1646097110584,"mc":[{"id":"1.195395455","rc":[{"atb":[[2.8,76.26]],"id":28002629},{"atb":[[3.4,21.85]],"id":42393370}],"con":true,"img":false}]}
{"op":"mcm","clk":"5346791123","pt":1646097119382,"mc":[{"id":"1.195395455","rc":[{"atb":[[2.78,5.16]],"id":28002629},{"atb":[[3.35,0]],"id":42393370}],"con":true,"img":false}]}
{"op":"mcm","clk":"5346791498","pt":1646097128287,"mc":[{"id":"1.195395455","rc":[{"atb":[[2.84,4.89]],"id":28002629},{"atb":[[3.45,3.68]],"id":42393370}],"con":true,"img":false}]}
{"op":"mcm","clk":"5346791511","pt":1646097128597,"mc":[{"id":"1.195395455","rc":[{"atb":[[2.78,0]],"id":28002629}],"con":true,"img":false}]}
{"op":"mcm","clk":"5346791638","pt":1646097131425,"mc":[{"id":"1.195395455","rc":[{"atl":[[34,0],[18.5,7.03]],"id":28002629}],"con":true,"img":false}]}
{"op":"mcm","clk":"5346791680","pt":1646097132402,"mc":[{"id":"1.195395455","rc":[{"atl":[[18,5.88]],"id":28002629}],"con":true,"img":false}]}
{"op":"mcm","clk":"5346791683","pt":1646097132506,"mc":[{"id":"1.195395455","rc":[{"atl":[[19,2.7]],"id":28002629}],"con":true,"img":false}]}
{"op":"mcm","clk":"5346791768","pt":1646097134709,"mc":[{"id":"1.195395455","rc":[{"atb":[[2.84,9.88]],"id":28002629}],"con":true,"img":false}]}
{"op":"mcm","clk":"5346792450","pt":1646097152850,"mc":[{"id":"1.195395455","rc":[{"atl":[[18.5,0],[38,3.24]],"id":28002629},{"spn":11.2,"spf":1.0,"id":28002629}],"con":true,"img":false}]}
{"op":"mcm","clk":"5346792452","pt":1646097152953,"mc":[{"id":"1.195395455","rc":[{"atl":[[18,0],[19,8.26]],"id":28002629}],"con":true,"img":false}]}
{"op":"mcm","clk":"5346792457","pt":1646097153056,"mc":[{"id":"1.195395455","rc":[{"atl":[[32,3.23]],"id":28002629}],"con":true,"img":false}]}
{"op":"mcm","clk":"5346792461","pt":1646097153157,"mc":[{"id":"1.195395455","rc":[{"atl":[[19,2.7]],"id":28002629}],"con":true,"img":false}]}
{"op":"mcm","clk":"5346792465","pt":1646097153261,"mc":[{"id":"1.195395455","rc":[{"atl":[[32,0],[19,5.95]],"id":28002629}],"con":true,"img":false}]}
{"op":"mcm","clk":"5346793290","pt":1646097174073,"mc":[{"id":"1.195395455","rc":[{"atb":[[2.8,0]],"id":28002629},{"atb":[[3.4,0]],"id":42393370}],"con":true,"img":false}]}
{"op":"mcm","clk":"5346793293","pt":1646097174171,"mc":[{"id":"1.195395455","rc":[{"atb":[[2.86,76.26]],"id":28002629},{"atb":[[3.5,21.85]],"id":42393370}],"con":true,"img":false}]}
{"op":"mcm","clk":"5346793701","pt":1646097182364,"mc":[{"id":"1.195395455","rc":[{"atb":[[2.84,4.98]],"id":28002629},{"atb":[[3.45,0]],"id":42393370}],"con":true,"img":false}]}
{"op":"mcm","clk":"5346793970","pt":1646097188686,"mc":[{"id":"1.195395455","rc":[{"atb":[[2.84,0]],"id":28002629}],"con":true,"img":false}]}
{"op":"mcm","clk":"5346794080","pt":1646097191406,"mc":[{"id":"1.195395455","rc":[{"atb":[[2.9,4.73]],"id":28002629},{"atb":[[3.55,3.53]],"id":42393370}],"con":true,"img":false}]}
{"op":"mcm","clk":"5346794148","pt":1646097193103,"mc":[{"id":"1.195395455","rc":[{"atb":[[2.32,54.55]],"id":42393370}],"con":true,"img":false}]}
{"op":"mcm","clk":"5346794218","pt":1646097194690,"mc":[{"id":"1.195395455","rc":[{"atb":[[2.9,9.57]],"id":28002629}],"con":true,"img":false}]}
{"op":"mcm","clk":"5346795073","pt":1646097215726,"mc":[{"id":"1.195395455","rc":[{"atl":[[18.5,7.03],[38,0]],"id":28002629},{"spn":11.45,"spf":1.0,"id":28002629},{"atb":[[3.5,0]],"id":42393370}],"con":true,"img":false}]}
{"op":"mcm","clk":"5346795078","pt":1646097215826,"mc":[{"id":"1.195395455","rc":[{"atl":[[18,5.88]],"id":28002629},{"atb":[[3.3,21.85]],"id":42393370}],"con":true,"img":false}]}
{"op":"mcm","clk":"5346795081","pt":1646097215928,"mc":[{"id":"1.195395455","rc":[{"atl":[[19,2.7]],"id":28002629}],"con":true,"img":false}]}
{"op":"mcm","clk":"5346795302","pt":1646097221545,"mc":[{"id":"1.195395455","rc":[{"atb":[[6.4,0],[5.4,22.73]],"id":37455733},{"atb":[[4.3,0],[4.9,25.64]],"id":22150928},{"atl":[[4.1,0],[3.65,37.74]],"id":43154433}],"con":true,"img":false}]}
{"op":"mcm","clk":"5346795431","pt":1646097224474,"mc":[{"id":"1.195395455","rc":[{"atb":[[3.55,0]],"id":42393370}],"con":true,"img":false}]}
{"op":"mcm","clk":"5346795772","pt":1646097233479,"mc":[{"id":"1.195395455","rc":[{"atb":[[3.35,3.83]],"id":42393370}],"con":true,"img":false}]}
{"op":"mcm","clk":"5346795887","pt":1646097236163,"mc":[{"id":"1.195395455","rc":[{"atb":[[2.86,0]],"id":28002629},{"atl":[[38,3.24]],"id":28002629},{"atb":[[2.2,0]],"id":42393370}],"con":true,"img":false}]}
{"op":"mcm","clk":"5346795895","pt":1646097236266,"mc":[{"id":"1.195395455","rc":[{"atb":[[2.92,76.26]],"id":28002629},{"atl":[[18.5,0]],"id":28002629},{"atb":[[2.34,106]],"id":42393370}],"con":true,"img":false}]}
{"op":"mcm","clk":"5346795900","pt":1646097236368,"mc":[{"id":"1.195395455","rc":[{"atl":[[19,8.26]],"id":28002629}],"con":true,"img":false}]}
{"op":"mcm","clk":"5346795903","pt":1646097236471,"mc":[{"id":"1.195395455","rc":[{"atl":[[18,0]],"id":28002629}],"con":true,"img":false}]}
{"op":"mcm","clk":"5346796131","pt":1646097242384,"mc":[{"id":"1.195395455","rc":[{"atb":[[2.9,4.83]],"id":28002629}],"con":true,"img":false}]}
{"op":"mcm","clk":"5346796374","pt":1646097248909,"mc":[{"id":"1.195395455","rc":[{"atb":[[2.9,0]],"id":28002629}],"con":true,"img":false}]}
{"op":"mcm","clk":"5346796605","pt":1646097254514,"mc":[{"id":"1.195395455","rc":[{"atb":[[2.96,4.59]],"id":28002629}],"con":true,"img":false}]}
{"op":"mcm","clk":"5346796615","pt":1646097254819,"mc":[{"id":"1.195395455","rc":[{"atb":[[2.96,9.28]],"id":28002629}],"con":true,"img":false}]}
{"op":"mcm","clk":"5346796713","pt":1646097256889,"mc":[{"id":"1.195395455","rc":[{"atl":[[5.1,28.42]],"id":43154433}],"con":true,"img":false}]}
{"op":"mcm","clk":"5346796718","pt":1646097256992,"mc":[{"id":"1.195395455","rc":[{"atb":[[9.6,0]],"id":37672294},{"atb":[[3.3,0]],"id":42393370},{"atl":[[4,0],[3.2,0]],"id":43154433}],"con":true,"img":false}]}
{"op":"mcm","clk":"5346796724","pt":1646097257097,"mc":[{"id":"1.195395455","rc":[{"atb":[[9,5.03]],"id":37672294},{"atb":[[3.4,21.85]],"id":42393370},{"atl":[[3.6,19.66],[5,25],[3.65,0]],"id":43154433}],"con":true,"img":false}]}
{"op":"mcm","clk":"5346797035","pt":1646097263524,"mc":[{"id":"1.195395455","rc":[{"atb":[[3.35,0]],"id":42393370}],"con":true,"img":false}]}
{"op":"mcm","clk":"5346797412","pt":1646097272530,"mc":[{"id":"1.195395455","rc":[{"atb":[[3.45,3.68]],"id":42393370}],"con":true,"img":false}]}
{"op":"mcm","clk":"5346797584","pt":1646097277473,"mc":[{"id":"1.195395455","rc":[{"atb":[[2.74,0],[2.6,58.82]],"id":28002629},{"spn":11.7,"spf":1.0,"id":28002629},{"atl":[[12,3.93],[12.5,8.7]],"id":42393370},{"atl":[[880,0],[960,2]],"id":37455733},{"spn":2.63,"spf":1.0,"id":43154433}],"con":true,"img":false}]}
{"op":"mcm","clk":"5346797984","pt":1646097288045,"mc":[{"id":"1.195395455","rc":[{"atl":[[3.8,35.71]],"id":43154433}],"con":true,"img":false}]}
{"op":"mcm","clk":"5346797989","pt":1646097288148,"mc":[{"id":"1.195395455","rc":[{"atl":[[5,0]],"id":43154433}],"con":true,"img":false}]}
{"op":"mcm","clk":"5346798253","pt":1646097297258,"mc":[{"id":"1.195395455","rc":[{"atb":[[9,0]],"id":37672294},{"atb":[[2.92,0]],"id":28002629},{"atl":[[18.5,7.03],[38,0]],"id":28002629},{"atl":[[3.6,0]],"id":43154433}],"con":true,"img":false}]}
{"op":"mcm","clk":"5346798257","pt":1646097297362,"mc":[{"id":"1.195395455","rc":[{"atb":[[9.6,5.03]],"id":37672294},{"atb":[[2.98,76.26]],"id":28002629},{"atl":[[18,5.88],[19,2.7]],"id":28002629},{"atl":[[5,25],[3.35,19.66],[3.8,0]],"id":43154433}],"con":true,"img":false}]}
{"op":"mcm","clk":"5346798607","pt":1646097305671,"mc":[{"id":"1.195395455","rc":[{"atb":[[2.96,4.68]],"id":28002629}],"con":true,"img":false}]}
{"op":"mcm","clk":"5346798956","pt":1646097314492,"mc":[{"id":"1.195395455","rc":[{"atb":[[3,4.5]],"id":28002629}],"con":true,"img":false}]}
{"op":"mcm","clk":"5346798969","pt":1646097314903,"mc":[{"id":"1.195395455","rc":[{"atb":[[2.96,0]],"id":28002629}],"con":true,"img":false}]}
{"op":"mcm","clk":"5346799059","pt":1646097317316,"mc":[{"id":"1.195395455","rc":[{"atl":[[18.5,0],[38,3.24]],"id":28002629},{"atb":[[3.4,0]],"id":42393370},{"atl":[[5.1,0]],"id":43154433}],"con":true,"img":false}]}
{"op":"mcm","clk":"5346799065","pt":1646097317433,"mc":[{"id":"1.195395455","rc":[{"atb":[[3.5,21.85]],"id":42393370},{"atl":[[4.9,28.42]],"id":43154433}],"con":true,"img":false}]}
{"op":"mcm","clk":"5346799068","pt":1646097317529,"mc":[{"id":"1.195395455","rc":[{"atl":[[19,8.26]],"id":28002629}],"con":true,"img":false}]}
{"op":"mcm","clk":"5346799070","pt":1646097317619,"mc":[{"id":"1.195395455","rc":[{"atl":[[18,0]],"id":28002629}],"con":true,"img":false}]}
{"op":"mcm","clk":"5346799191","pt":1646097320905,"mc":[{"id":"1.195395455","rc":[{"atb":[[3,9.1]],"id":28002629}],"con":true,"img":false}]}
{"op":"mcm","clk":"5346799427","pt":1646097326600,"mc":[{"id":"1.195395455","rc":[{"atb":[[3.45,0]],"id":42393370}],"con":true,"img":false}]}
{"op":"mcm","clk":"5346799489","pt":1646097327938,"mc":[{"id":"1.195395455","rc":[{"atl":[[5,0],[3.8,35.71]],"id":43154433}],"con":true,"img":false}]}
{"op":"mcm","clk":"5346799803","pt":1646097335630,"mc":[{"id":"1.195395455","rc":[{"atb":[[3.55,3.53]],"id":42393370}],"con":true,"img":false}]}
{"op":"mcm","clk":"5346800623","pt":1646097357353,"mc":[{"id":"1.195395455","rc":[{"atb":[[3.5,0]],"id":42393370},{"spn":2.51,"spf":1.0,"id":43154433}],"con":true,"img":false}]}
{"op":"mcm","clk":"5346800630","pt":1646097357457,"mc":[{"id":"1.195395455","rc":[{"atb":[[3.3,21.85]],"id":42393370}],"con":true,"img":false}]}
{"op":"mcm","clk":"5346800918","pt":1646097365771,"mc":[{"id":"1.195395455","rc":[{"atb":[[3.55,0]],"id":42393370}],"con":true,"img":false}]}
{"op":"mcm","clk":"5346801252","pt":1646097374714,"mc":[{"id":"1.195395455","rc":[{"atb":[[3.35,3.83]],"id":42393370}],"con":true,"img":false}]}
{"op":"mcm","clk":"5346802050","pt":1646097396644,"mc":[{"id":"1.195395455","rc":[{"atb":[[2.98,0],[3.05,61.65]],"id":28002629},{"atl":[[18.5,7.03],[38,0]],"id":28002629},{"atb":[[3.3,0]],"id":42393370},{"atl":[[4.9,0],[3.75,42.38]],"id":43154433}],"con":true,"img":false}]}
{"op":"mcm","clk":"5346802053","pt":1646097396746,"mc":[{"id":"1.195395455","rc":[{"atl":[[18,5.88],[19,2.7]],"id":28002629},{"atb":[[3.4,21.85]],"id":42393370}],"con":true,"img":false}]}
{"op":"mcm","clk":"5346802376","pt":1646097404751,"mc":[{"id":"1.195395455","rc":[{"atb":[[3,4.59]],"id":28002629},{"atb":[[3.35,0]],"id":42393370}],"con":true,"img":false}]}
{"op":"mcm","clk":"5346802702","pt":1646097413771,"mc":[{"id":"1.195395455","rc":[{"atb":[[3.1,4.29]],"id":28002629},{"atb":[[3.45,3.68]],"id":42393370}],"con":true,"img":false}]}
{"op":"mcm","clk":"5346802800","pt":1646097416141,"mc":[{"id":"1.195395455","rc":[{"atl":[[18.5,0],[38,3.24]],"id":28002629}],"con":true,"img":false}]}
{"op":"mcm","clk":"5346802803","pt":1646097416244,"mc":[{"id":"1.195395455","rc":[{"atl":[[19,8.26]],"id":28002629}],"con":true,"img":false}]}
{"op":"mcm","clk":"5346802807","pt":1646097416348,"mc":[{"id":"1.195395455","rc":[{"atl":[[18,0]],"id":28002629}],"con":true,"img":false}]}
{"op":"mcm","clk":"5346804187","pt":1646097454222,"mc":[{"id":"1.195395455","rc":[{"atb":[[3.05,0]],"id":28002629},{"atb":[[3.4,0]],"id":42393370}],"con":true,"img":false}]}
{"op":"mcm","clk":"5346804191","pt":1646097454326,"mc":[{"id":"1.195395455","rc":[{"atb":[[3.15,61.65]],"id":28002629},{"atb":[[3.5,21.85]],"id":42393370}],"con":true,"img":false}]}
{"op":"mcm","clk":"5346804473","pt":1646097461925,"mc":[{"id":"1.195395455","rc":[{"atb":[[3.1,0]],"id":28002629},{"atb":[[3.45,0]],"id":42393370}],"con":true,"img":false}]}
{"op":"mcm","clk":"5346804535","pt":1646097463825,"mc":[{"id":"1.195395455","rc":[{"atb":[[2.74,51.36],[2.6,0]],"id":28002629},{"atl":[[12,10.42],[12.5,0]],"id":42393370},{"atl":[[890,2],[960,0]],"id":37455733},{"atl":[[3.8,0],[3.65,37.74]],"id":43154433}],"con":true,"img":false}]}
{"op":"mcm","clk":"5346804783","pt":1646097470949,"mc":[{"id":"1.195395455","rc":[{"atb":[[3.2,4.1]],"id":28002629},{"atb":[[3.55,3.53]],"id":42393370}],"con":true,"img":false}]}
{"op":"mcm","clk":"5346804850","pt":1646097472856,"mc":[{"id":"1.195395455","rc":[{"atl":[[18.5,7.03],[38,0]],"id":28002629}],"con":true,"img":false}]}
{"op":"mcm","clk":"5346804856","pt":1646097472957,"mc":[{"id":"1.195395455","rc":[{"atl":[[18,5.88],[19,2.7]],"id":28002629}],"con":true,"img":false}]}
{"op":"mcm","clk":"5346805539","pt":1646097491645,"mc":[{"id":"1.195395455","rc":[{"atb":[[9.6,0]],"id":37672294},{"atb":[[3.5,0]],"id":42393370},{"atl":[[3.35,0],[3.75,0]],"id":43154433}],"con":true,"img":false}]}
{"op":"mcm","clk":"5346805545","pt":1646097491746,"mc":[{"id":"1.195395455","rc":[{"atb":[[9,5.03]],"id":37672294},{"atb":[[3.3,21.85]],"id":42393370},{"atl":[[3.6,19.66],[5.1,52.81]],"id":43154433}],"con":true,"img":false}]}
{"op":"mcm","clk":"5346805550","pt":1646097491851,"mc":[{"id":"1.195395455","rc":[{"atb":[[3.15,0]],"id":28002629},{"atl":[[34,3.24],[18.5,0]],"id":28002629},{"atl":[[7.2,18.8],[5.1,24.39],[3.65,0]],"id":43154433}],"con":true,"img":false}]}
{"op":"mcm","clk":"5346805552","pt":1646097491954,"mc":[{"id":"1.195395455","rc":[{"atb":[[3.05,61.65]],"id":28002629},{"atl":[[18,0],[19,8.26]],"id":28002629}],"con":true,"img":false}]}
{"op":"mcm","clk":"5346805702","pt":1646097495560,"mc":[{"id":"1.195395455","rc":[{"atb":[[3,0]],"id":28002629}],"con":true,"img":false}]}
{"op":"mcm","clk":"5346805813","pt":1646097498086,"mc":[{"id":"1.195395455","rc":[{"atb":[[3.55,0]],"id":42393370}],"con":true,"img":false}]}
{"op":"mcm","clk":"5346805938","pt":1646097500966,"mc":[{"id":"1.195395455","rc":[{"atb":[[3.2,0]],"id":28002629}],"con":true,"img":false}]}
{"op":"mcm","clk":"5346806191","pt":1646097507389,"mc":[{"id":"1.195395455","rc":[{"atb":[[3.1,4.37]],"id":28002629}],"con":true,"img":false}]}
{"op":"mcm","clk":"5346806278","pt":1646097510008,"mc":[{"id":"1.195395455","rc":[{"atb":[[3.1,8.66]],"id":28002629},{"atb":[[3.35,3.83]],"id":42393370}],"con":true,"img":false}]}
{"op":"mcm","clk":"5346806673","pt":1646097520433,"mc":[{"id":"1.195395455","rc":[{"atl":[[5.1,0],[3.65,37.74]],"id":43154433},{"spn":2.63,"spf":1.0,"id":43154433}],"con":true,"img":false}]}
{"op":"mcm","clk":"5346806990","pt":1646097529108,"mc":[{"id":"1.195395455","rc":[{"atb":[[9,0]],"id":37672294},{"atb":[[3.3,0]],"id":42393370},{"atl":[[3.6,0]],"id":43154433}],"con":true,"img":false}]}
{"op":"mcm","clk":"5346806993","pt":1646097529211,"mc":[{"id":"1.195395455","rc":[{"atb":[[9.6,5.03]],"id":37672294},{"atb":[[3.4,21.85]],"id":42393370},{"atl":[[5.1,24.39],[3.35,19.66],[3.65,0]],"id":43154433}],"con":true,"img":false}]}
{"op":"mcm","clk":"5346807161","pt":1646097534742,"mc":[{"id":"1.195395455","rc":[{"atb":[[2.74,0],[2.6,58.82]],"id":28002629},{"atb":[[3.4,43.7],[3.25,0]],"id":42393370},{"atl":[[12,3.93],[13.5,8]],"id":42393370}],"con":true,"img":false}]}
{"op":"mcm","clk":"5346807203","pt":1646097537148,"mc":[{"id":"1.195395455","rc":[{"atb":[[3.35,0]],"id":42393370}],"con":true,"img":false}]}
{"op":"mcm","clk":"5346807532","pt":1646097547562,"mc":[{"id":"1.195395455","rc":[{"atb":[[3.05,0]],"id":28002629}],"con":true,"img":false}]}
{"op":"mcm","clk":"5346807533","pt":1646097547669,"mc":[{"id":"1.195395455","rc":[{"atb":[[3.15,61.65]],"id":28002629}],"con":true,"img":false}]}
{"op":"mcm","clk":"5346807562","pt":1646097549258,"mc":[{"id":"1.195395455","rc":[{"atb":[[3.45,3.68]],"id":42393370}],"con":true,"img":false}]}
{"op":"mcm","clk":"5346807567","pt":1646097549361,"mc":[{"id":"1.195395455","rc":[{"atb":[[3.45,7.43]],"id":42393370}],"con":true,"img":false}]}
{"op":"mcm","clk":"5346807730","pt":1646097555164,"mc":[{"id":"1.195395455","rc":[{"atb":[[3.1,4.37]],"id":28002629}],"con":true,"img":false}]}
{"op":"mcm","clk":"5346807807","pt":1646097557475,"mc":[{"id":"1.195395455","rc":[{"atl":[[5.1,0],[3.65,37.74]],"id":43154433}],"con":true,"img":false}]}
{"op":"mcm","clk":"5346808060","pt":1646097565380,"mc":[{"id":"1.195395455","rc":[{"atl":[[34,0],[18.5,7.03]],"id":28002629},{"atl":[[7.2,0],[3.6,44.82]],"id":43154433}],"con":true,"img":false}]}
{"op":"mcm","clk":"5346808065","pt":1646097565484,"mc":[{"id":"1.195395455","rc":[{"atl":[[18,5.88],[19,2.7]],"id":28002629}],"con":true,"img":false}]}
{"op":"mcm","clk":"5346808117","pt":1646097567173,"mc":[{"id":"1.195395455","rc":[{"atb":[[3.2,4.1]],"id":28002629}],"con":true,"img":false}]}
{"op":"mcm","clk":"5346808633","pt":1646097584023,"mc":[{"id":"1.195395455","rc":[{"atb":[[9.6,0]],"id":37672294},{"spn":11.2,"spf":1.0,"id":28002629},{"atb":[[3.4,21.85]],"id":42393370},{"atl":[[3.6,0],[5.1,28.42],[3.35,0]],"id":43154433},{"spn":2.66,"spf":1.0,"id":43154433}],"con":true,"img":false}]}
{"op":"mcm","clk":"5346808639","pt":1646097584125,"mc":[{"id":"1.195395455","rc":[{"atb":[[9,5.03]],"id":37672294},{"atb":[[3.5,21.85]],"id":42393370},{"atl":[[3.6,19.66],[5,25],[3.65,0]],"id":43154433}],"con":true,"img":false}]}
{"op":"mcm","clk":"5346808899","pt":1646097591308,"mc":[{"id":"1.195395455","rc":[{"atb":[[3.45,3.75]],"id":42393370}],"con":true,"img":false}]}
{"op":"mcm","clk":"5346809437","pt":1646097600309,"mc":[{"id":"1.195395455","rc":[{"atb":[[3.55,3.53]],"id":42393370}],"con":true,"img":false}]}
{"op":"mcm","clk":"5346809501","pt":1646097602057,"mc":[{"id":"1.195395455","rc":[{"atl":[[18.5,0],[38,3.24]],"id":28002629},{"atl":[[21,0],[13,10.81]],"id":42393370}],"con":true,"img":false}]}
{"op":"mcm","clk":"5346809509","pt":1646097602211,"mc":[{"id":"1.195395455","rc":[{"atl":[[18,0],[19,8.26]],"id":28002629}],"con":true,"img":false}]}
{"op":"mcm","clk":"5346809831","pt":1646097611860,"mc":[{"id":"1.195395455","rc":[{"atl":[[5,0],[3.65,37.74]],"id":43154433}],"con":true,"img":false}]}
{"op":"mcm","clk":"5346810143","pt":1646097619973,"mc":[{"id":"1.195395455","rc":[{"atb":[[9,0]],"id":37672294},{"atb":[[3.15,0]],"id":28002629},{"atl":[[3.6,0]],"id":43154433}],"con":true,"img":false}]}
{"op":"mcm","clk":"5346810147","pt":1646097620076,"mc":[{"id":"1.195395455","rc":[{"atb":[[9.6,5.03]],"id":37672294},{"atb":[[3.25,61.65]],"id":28002629},{"atl":[[3.35,19.66]],"id":43154433}],"con":true,"img":false}]}
{"op":"mcm","clk":"5346810150","pt":1646097620181,"mc":[{"id":"1.195395455","rc":[{"atl":[[5,25],[3.65,0]],"id":43154433}],"con":true,"img":false}]}
{"op":"mcm","clk":"5346810355","pt":1646097627258,"mc":[{"id":"1.195395455","rc":[{"atb":[[3.2,0]],"id":28002629}],"con":true,"img":false}]}
{"op":"mcm","clk":"5346810608","pt":1646097636282,"mc":[{"id":"1.195395455","rc":[{"atb":[[3.3,3.91]],"id":28002629}],"con":true,"img":false}]}
{"op":"mcm","clk":"5346810650","pt":1646097637671,"mc":[{"id":"1.195395455","rc":[{"atl":[[5.1,0]],"id":43154433}],"con":true,"img":false}]}
{"op":"mcm","clk":"5346810653","pt":1646097637773,"mc":[{"id":"1.195395455","rc":[{"atl":[[4.9,28.42]],"id":43154433}],"con":true,"img":false}]}
{"op":"mcm","clk":"5346810695","pt":1646097639266,"mc":[{"id":"1.195395455","rc":[{"atl":[[5,0],[3.65,37.74]],"id":43154433}],"con":true,"img":false}]}
{"op":"mcm","clk":"5346811068","pt":1646097654801,"mc":[{"id":"1.195395455","rc":[{"atb":[[2.6,0],[2.48,29.84]],"id":28002629},{"spn":11.7,"spf":1.0,"id":28002629},{"atb":[[3.4,0],[3.15,46.51]],"id":42393370},{"atl":[[13.5,0],[14.5,7.41]],"id":42393370},{"atl":[[3.8,35.71],[3.65,0]],"id":43154433},{"spn":2.51,"spf":1.0,"id":43154433}],"con":true,"img":false}]}
{"op":"mcm","clk":"5346811088","pt":1646097655416,"mc":[{"id":"1.195395455","rc":[{"atl":[[13,0]],"id":42393370}],"con":true,"img":false}]}
{"op":"mcm","clk":"5346811091","pt":1646097655519,"mc":[{"id":"1.195395455","rc":[{"atl":[[14,10.81]],"id":42393370}],"con":true,"img":false}]}
{"op":"mcm","clk":"5346811696","pt":1646097673434,"mc":[{"id":"1.195395455","rc":[{"atl":[[18.5,7.03],[38,0]],"id":28002629}],"con":true,"img":false}]}
{"op":"mcm","clk":"5346811702","pt":1646097673539,"mc":[{"id":"1.195395455","rc":[{"atl":[[18,5.88],[19,2.7]],"id":28002629}],"con":true,"img":false}]}
{"op":"mcm","clk":"5346812363","pt":1646097690588,"mc":[{"id":"1.195395455","rc":[{"atl":[[38,3.24]],"id":28002629}],"con":true,"img":false}]}
{"op":"mcm","clk":"5346812369","pt":1646097690690,"mc":[{"id":"1.195395455","rc":[{"atl":[[18.5,0]],"id":28002629}],"con":true,"img":false}]}
{"op":"mcm","clk":"5346812373","pt":1646097690796,"mc":[{"id":"1.195395455","rc":[{"atl":[[18,0],[19,8.26]],"id":28002629}],"con":true,"img":false}]}
{"op":"mcm","clk":"5346812829","pt":1646097702666,"mc":[{"id":"1.195395455","rc":[{"atl":[[19,5.56]],"id":28002629},{"atl":[[4.9,0],[3.75,42.38]],"id":43154433}],"con":true,"img":false}]}
{"op":"mcm","clk":"5346812835","pt":1646097702770,"mc":[{"id":"1.195395455","rc":[{"atl":[[32,3.23],[17.5,2.7],[19,0]],"id":28002629}],"con":true,"img":false}]}
{"op":"mcm","clk":"5346812867","pt":1646097703901,"mc":[{"id":"1.195395455","rc":[{"atb":[[2.62,29.84],[2.48,0]],"id":28002629},{"atb":[[3.4,41.67],[3.15,0]],"id":42393370},{"atl":[[14,18.5],[14.5,0]],"id":42393370},{"atl":[[3.8,0],[3.65,37.74]],"id":43154433}],"con":true,"img":false}]}
{"op":"mcm","clk":"5346813230","pt":1646097713915,"mc":[{"id":"1.195395455","rc":[{"atl":[[14,10.81],[14.5,7.41]],"id":42393370}],"con":true,"img":false}]}
{"op":"mcm","clk":"5346813791","pt":1646097729358,"mc":[{"id":"1.195395455","rc":[{"atl":[[32,0],[17.5,5.93]],"id":28002629},{"spn":10.95,"spf":1.0,"id":28002629}],"con":true,"img":false}]}
{"op":"mcm","clk":"5346813827","pt":1646097730436,"mc":[{"id":"1.195395455","rc":[{"atb":[[3.45,44.57],[3.4,0]],"id":42393370}],"con":true,"img":false}]}
{"op":"mcm","clk":"5346814808","pt":1646097759411,"mc":[{"id":"1.195395455","rc":[{"atl":[[3.75,0]],"id":43154433}],"con":true,"img":false}]}
{"op":"mcm","clk":"5346814810","pt":1646097759514,"mc":[{"id":"1.195395455","rc":[{"atl":[[3.6,42.38]],"id":43154433}],"con":true,"img":false}]}
{"op":"mcm","clk":"5346814882","pt":1646097761685,"mc":[{"id":"1.195395455","rc":[{"atl":[[14,18.5],[14.5,0]],"id":42393370}],"con":true,"img":false}]}
{"op":"mcm","clk":"5346815011","pt":1646097765989,"mc":[{"id":"1.195395455","rc":[{"atb":[[3.1,0]],"id":28002629}],"con":true,"img":false}]}
{"op":"mcm","clk":"5346815309","pt":1646097774231,"mc":[{"id":"1.195395455","rc":[{"atb":[[3.45,3.75],[3.4,41.67]],"id":42393370}],"con":true,"img":false}]}
{"op":"mcm","clk":"5346815429","pt":1646097778030,"mc":[{"id":"1.195395455","rc":[{"atb":[[3.3,7.91]],"id":28002629}],"con":true,"img":false}]}
{"op":"mcm","clk":"5346817499","pt":1646097834178,"mc":[{"id":"1.195395455","rc":[{"atb":[[3.45,44.57],[3.4,0]],"id":42393370},{"atl":[[890,0],[980,2]],"id":37455733}],"con":true,"img":false}]}
{"op":"mcm","clk":"5346817599","pt":1646097836743,"mc":[{"id":"1.195395455","rc":[{"atb":[[3.95,33.9],[5.4,0]],"id":37455733},{"atb":[[5.6,21.74],[4.9,0]],"id":22150928},{"atl":[[4.2,31.25],[3.65,0]],"id":43154433}],"con":true,"img":false}]}
{"op":"mcm","clk":"5346817650","pt":1646097838133,"mc":[{"id":"1.195395455","rc":[{"atb":[[3.45,40.82]],"id":42393370}],"con":true,"img":false}]}
{"op":"mcm","clk":"5346817871","pt":1646097843729,"mc":[{"id":"1.195395455","rc":[{"atb":[[3.25,0]],"id":28002629},{"atl":[[3.6,0]],"id":43154433}],"con":true,"img":false}]}
{"op":"mcm","clk":"5346817874","pt":1646097843833,"mc":[{"id":"1.195395455","rc":[{"atb":[[3.35,61.65]],"id":28002629},{"atl":[[4.1,42.38]],"id":43154433}],"con":true,"img":false}]}
{"op":"mcm","clk":"5346818132","pt":1646097850152,"mc":[{"id":"1.195395455","rc":[{"atb":[[3.5,25.52]],"id":42393370}],"con":true,"img":false}]}
{"op":"mcm","clk":"5346818231","pt":1646097852616,"mc":[{"id":"1.195395455","rc":[{"atb":[[3.3,3.99]],"id":28002629}],"con":true,"img":false}]}
{"op":"mcm","clk":"5346818525","pt":1646097860224,"mc":[{"id":"1.195395455","rc":[{"atb":[[2.7,76.26]],"id":28002629}],"con":true,"img":false}]}
{"op":"mcm","clk":"5346818529","pt":1646097860327,"mc":[{"id":"1.195395455","rc":[{"atb":[[3.35,0]],"id":28002629}],"con":true,"img":false}]}
{"op":"mcm","clk":"5346818623","pt":1646097862137,"mc":[{"id":"1.195395455","rc":[{"atb":[[3.3,0]],"id":28002629}],"con":true,"img":false}]}
{"op":"mcm","clk":"5346819114","pt":1646097874153,"mc":[{"id":"1.195395455","rc":[{"atb":[[2.74,5.28]],"id":28002629}],"con":true,"img":false}]}
{"op":"mcm","clk":"5346819214","pt":1646097876677,"mc":[{"id":"1.195395455","rc":[{"atb":[[2.74,10.46]],"id":28002629}],"con":true,"img":false}]}
{"op":"mcm","clk":"5346819960","pt":1646097894615,"mc":[{"id":"1.195395455","rc":[{"atb":[[3.45,0],[3.4,41.67]],"id":42393370},{"atl":[[900,2],[980,0]],"id":37455733}],"con":true,"img":false}]}
{"op":"mcm","clk":"5346820630","pt":1646097910215,"mc":[{"id":"1.195395455","rc":[{"atb":[[3.5,21.85]],"id":42393370}],"con":true,"img":false}]}
{"op":"mcm","clk":"5346820879","pt":1646097916224,"mc":[{"id":"1.195395455","rc":[{"atb":[[3.45,3.75]],"id":42393370}],"con":true,"img":false}]}
{"op":"mcm","clk":"5346821788","pt":1646097941072,"mc":[{"id":"1.195395455","rc":[{"atb":[[2.7,0]],"id":28002629}],"con":true,"img":false}]}
{"op":"mcm","clk":"5346821793","pt":1646097941173,"mc":[{"id":"1.195395455","rc":[{"atb":[[2.76,76.26]],"id":28002629}],"con":true,"img":false}]}
{"op":"mcm","clk":"5346821882","pt":1646097943653,"mc":[{"id":"1.195395455","rc":[{"atb":[[3.4,0],[3.5,43.7]],"id":42393370},{"atl":[[14,10.81],[14.5,7.41]],"id":42393370},{"atl":[[900,0]],"id":37455733}],"con":true,"img":false}]}
{"op":"mcm","clk":"5346822097","pt":1646097948891,"mc":[{"id":"1.195395455","rc":[{"atb":[[2.74,5.28]],"id":28002629}],"con":true,"img":false}]}
{"op":"mcm","clk":"5346822443","pt":1646097957778,"mc":[{"id":"1.195395455","rc":[{"atb":[[2.8,5.01]],"id":28002629}],"con":true,"img":false}]}
{"op":"mcm","clk":"5346822477","pt":1646097958393,"mc":[{"id":"1.195395455","rc":[{"atb":[[2.74,0]],"id":28002629},{"atb":[[3.45,0]],"id":42393370}],"con":true,"img":false}]}
{"op":"mcm","clk":"5346822696","pt":1646097964398,"mc":[{"id":"1.195395455","rc":[{"atb":[[2.8,10.12]],"id":28002629}],"con":true,"img":false}]}
{"op":"mcm","clk":"5346822700","pt":1646097964501,"mc":[{"id":"1.195395455","rc":[{"atb":[[3.55,7.13]],"id":42393370}],"con":true,"img":false}]}
{"op":"mcm","clk":"5346824611","pt":1646098020152,"mc":[{"id":"1.195395455","rc":[{"atb":[[2.76,0]],"id":28002629}],"con":true,"img":false}]}
{"op":"mcm","clk":"5346824613","pt":1646098020256,"mc":[{"id":"1.195395455","rc":[{"atb":[[2.82,76.26]],"id":28002629}],"con":true,"img":false}]}
{"op":"mcm","clk":"5346824830","pt":1646098027082,"mc":[{"id":"1.195395455","rc":[{"atb":[[2.8,5.11]],"id":28002629}],"con":true,"img":false}]}
{"op":"mcm","clk":"5346825094","pt":1646098036001,"mc":[{"id":"1.195395455","rc":[{"atb":[[2.86,4.84]],"id":28002629}],"con":true,"img":false}]}
{"op":"mcm","clk":"5346825208","pt":1646098039703,"mc":[{"id":"1.195395455","rc":[{"atb":[[2.8,0]],"id":28002629}],"con":true,"img":false}]}
{"op":"mcm","clk":"5346825431","pt":1646098045485,"mc":[{"id":"1.195395455","rc":[{"atb":[[2.86,9.79]],"id":28002629}],"con":true,"img":false}]}
{"op":"mcm","clk":"5346826171","pt":1646098063671,"mc":[{"id":"1.195395455","rc":[{"atb":[[2.46,44.76],[2.62,0]],"id":28002629},{"atb":[[3.25,44.44],[3.5,21.85]],"id":42393370},{"atl":[[16,6.67],[14.5,0]],"id":42393370}],"con":true,"img":false}]}
{"op":"mcm","clk":"5346826247","pt":1646098065726,"mc":[{"id":"1.195395455","rc":[{"atb":[[3.5,0]],"id":42393370},{"atl":[[14,0],[15.5,8.65]],"id":42393370}],"con":true,"img":false}]}
{"op":"mcm","clk":"5346826253","pt":1646098065829,"mc":[{"id":"1.195395455","rc":[{"atb":[[3.3,21.85]],"id":42393370}],"con":true,"img":false}]}
{"op":"mcm","clk":"5346826507","pt":1646098072154,"mc":[{"id":"1.195395455","rc":[{"atb":[[3.55,3.6]],"id":42393370}],"con":true,"img":false}]}
{"op":"mcm","clk":"5346826961","pt":1646098081968,"mc":[{"id":"1.195395455","rc":[{"atb":[[3.55,0]],"id":42393370}],"con":true,"img":false}]}
{"op":"mcm","clk":"5346827041","pt":1646098084074,"mc":[{"id":"1.195395455","rc":[{"atb":[[3.35,3.83]],"id":42393370}],"con":true,"img":false}]}
{"op":"mcm","clk":"5346827201","pt":1646098087977,"mc":[{"id":"1.195395455","rc":[{"atb":[[3.3,25.84]],"id":42393370}],"con":true,"img":false}]}
{"op":"mcm","clk":"5346827565","pt":1646098095962,"mc":[{"id":"1.195395455","rc":[{"atb":[[2.82,0]],"id":28002629}],"con":true,"img":false}]}
{"op":"mcm","clk":"5346827570","pt":1646098096063,"mc":[{"id":"1.195395455","rc":[{"atb":[[2.88,76.26]],"id":28002629}],"con":true,"img":false}]}
{"op":"mcm","clk":"5346827971","pt":1646098105201,"mc":[{"id":"1.195395455","rc":[{"atb":[[2.86,4.94]],"id":28002629}],"con":true,"img":false}]}
{"op":"mcm","clk":"5346828151","pt":1646098108795,"mc":[{"id":"1.195395455","rc":[{"atb":[[2.86,0]],"id":28002629}],"con":true,"img":false}]}
{"op":"mcm","clk":"5346828247","pt":1646098111210,"mc":[{"id":"1.195395455","rc":[{"atb":[[3.3,3.99]],"id":42393370}],"con":true,"img":false}]}
{"op":"mcm","clk":"5346828253","pt":1646098111313,"mc":[{"id":"1.195395455","rc":[{"atb":[[3.4,21.85]],"id":42393370}],"con":true,"img":false}]}
{"op":"mcm","clk":"5346828350","pt":1646098114085,"mc":[{"id":"1.195395455","rc":[{"atb":[[2.92,4.69]],"id":28002629}],"con":true,"img":false}]}
{"op":"mcm","clk":"5346828378","pt":1646098114701,"mc":[{"id":"1.195395455","rc":[{"atb":[[2.92,9.48]],"id":28002629}],"con":true,"img":false}]}
{"op":"mcm","clk":"5346828546","pt":1646098120196,"mc":[{"id":"1.195395455","rc":[{"atb":[[3.35,0]],"id":42393370}],"con":true,"img":false}]}
{"op":"mcm","clk":"5346828711","pt":1646098126099,"mc":[{"id":"1.195395455","rc":[{"atb":[[3.4,0]],"id":42393370}],"con":true,"img":false}]}
{"op":"mcm","clk":"5346828715","pt":1646098126202,"mc":[{"id":"1.195395455","rc":[{"atb":[[3.35,21.85]],"id":42393370}],"con":true,"img":false}]}
{"op":"mcm","clk":"5346829267","pt":1646098144166,"mc":[{"id":"1.195395455","rc":[{"atb":[[3.4,3.76]],"id":42393370}],"con":true,"img":false}]}
{"op":"mcm","clk":"5346830083","pt":1646098170395,"mc":[{"id":"1.195395455","rc":[{"atb":[[2.88,0]],"id":28002629}],"con":true,"img":false}]}
{"op":"mcm","clk":"5346830088","pt":1646098170498,"mc":[{"id":"1.195395455","rc":[{"atb":[[2.94,76.26]],"id":28002629}],"con":true,"img":false}]}
{"op":"mcm","clk":"5346830271","pt":1646098177287,"mc":[{"id":"1.195395455","rc":[{"atb":[[2.92,4.78]],"id":28002629}],"con":true,"img":false}]}
{"op":"mcm","clk":"5346830489","pt":1646098185310,"mc":[{"id":"1.195395455","rc":[{"atb":[[3.35,0]],"id":42393370}],"con":true,"img":false}]}
{"op":"mcm","clk":"5346830492","pt":1646098185412,"mc":[{"id":"1.195395455","rc":[{"atb":[[3.45,21.85]],"id":42393370}],"con":true,"img":false}]}
{"op":"mcm","clk":"5346830526","pt":1646098186440,"mc":[{"id":"1.195395455","rc":[{"atb":[[2.98,4.55]],"id":28002629}],"con":true,"img":false}]}
{"op":"mcm","clk":"5346830541","pt":1646098186799,"mc":[{"id":"1.195395455","rc":[{"atb":[[2.92,0]],"id":28002629}],"con":true,"img":false}]}
{"op":"mcm","clk":"5346830717","pt":1646098192510,"mc":[{"id":"1.195395455","rc":[{"atb":[[3.4,0]],"id":42393370}],"con":true,"img":false}]}
{"op":"mcm","clk":"5346830728","pt":1646098192818,"mc":[{"id":"1.195395455","rc":[{"atb":[[2.98,9.19]],"id":28002629}],"con":true,"img":false}]}
{"op":"mcm","clk":"5346830895","pt":1646098199967,"mc":[{"id":"1.195395455","rc":[{"atb":[[3.45,0]],"id":42393370}],"con":true,"img":false}]}
{"op":"mcm","clk":"5346830900","pt":1646098200019,"mc":[{"id":"1.195395455","rc":[{"atb":[[3.35,21.85]],"id":42393370}],"con":true,"img":false}]}
{"op":"mcm","clk":"5346831520","pt":1646098219357,"mc":[{"id":"1.195395455","rc":[{"atb":[[3.4,3.76]],"id":42393370}],"con":true,"img":false}]}
{"op":"mcm","clk":"5346832215","pt":1646098242815,"mc":[{"id":"1.195395455","rc":[{"atb":[[3,63.28],[2.94,0]],"id":28002629}],"con":true,"img":false}]}
{"op":"mcm","clk":"5346832430","pt":1646098249539,"mc":[{"id":"1.195395455","rc":[{"atb":[[2.98,4.64]],"id":28002629}],"con":true,"img":false}]}
{"op":"mcm","clk":"5346832631","pt":1646098257338,"mc":[{"id":"1.195395455","rc":[{"atb":[[3.35,0]],"id":42393370}],"con":true,"img":false}]}
{"op":"mcm","clk":"5346832634","pt":1646098257442,"mc":[{"id":"1.195395455","rc":[{"atb":[[3.45,21.85]],"id":42393370}],"con":true,"img":false}]}
{"op":"mcm","clk":"5346832663","pt":1646098258413,"mc":[{"id":"1.195395455","rc":[{"atb":[[3.05,4.39]],"id":28002629}],"con":true,"img":false}]}
{"op":"mcm","clk":"5346832688","pt":1646098259029,"mc":[{"id":"1.195395455","rc":[{"atb":[[2.98,0]],"id":28002629}],"con":true,"img":false}]}
{"op":"mcm","clk":"5346832862","pt":1646098264561,"mc":[{"id":"1.195395455","rc":[{"atb":[[3.4,0]],"id":42393370}],"con":true,"img":false}]}
{"op":"mcm","clk":"5346832880","pt":1646098264922,"mc":[{"id":"1.195395455","rc":[{"atb":[[3.05,8.88]],"id":28002629}],"con":true,"img":false}]}
{"op":"mcm","clk":"5346833107","pt":1646098271565,"mc":[{"id":"1.195395455","rc":[{"atb":[[3.45,0]],"id":42393370}],"con":true,"img":false}]}
{"op":"mcm","clk":"5346833113","pt":1646098271668,"mc":[{"id":"1.195395455","rc":[{"atb":[[3.35,21.85]],"id":42393370}],"con":true,"img":false}]}
{"op":"mcm","clk":"5346833612","pt":1646098288496,"mc":[{"id":"1.195395455","rc":[{"atb":[[3.4,3.76]],"id":42393370}],"con":true,"img":false}]}
{"op":"mcm","clk":"5346834105","pt":1646098303007,"mc":[{"id":"1.195395455","rc":[{"atb":[[5.8,0],[6.6,17.86]],"id":37672294},{"atb":[[2.46,0],[2.58,44.76]],"id":28002629},{"atb":[[3.45,4],[3.25,0]],"id":42393370},{"atl":[[16,0],[15,7.14]],"id":42393370}],"con":true,"img":false}]}
{"op":"mcm","clk":"5346834511","pt":1646098314028,"mc":[{"id":"1.195395455","rc":[{"atb":[[3,0]],"id":28002629}],"con":true,"img":false}]}
{"op":"mcm","clk":"5346834515","pt":1646098314127,"mc":[{"id":"1.195395455","rc":[{"atb":[[3.1,63.28]],"id":28002629}],"con":true,"img":false}]}
{"op":"mcm","clk":"5346834788","pt":1646098321631,"mc":[{"id":"1.195395455","rc":[{"atb":[[3.05,4.48]],"id":28002629}],"con":true,"img":false}]}
{"op":"mcm","clk":"5346834814","pt":1646098322450,"mc":[{"id":"1.195395455","rc":[{"atb":[[3.3,0]],"id":42393370}],"con":true,"img":false}]}
{"op":"mcm","clk":"5346835007","pt":1646098328042,"mc":[{"id":"1.195395455","rc":[{"atb":[[3.35,0]],"id":42393370}],"con":true,"img":false}]}
{"op":"mcm","clk":"5346835011","pt":1646098328143,"mc":[{"id":"1.195395455","rc":[{"atb":[[3.5,21.85]],"id":42393370}],"con":true,"img":false}]}
{"op":"mcm","clk":"5346835016","pt":1646098328247,"mc":[{"id":"1.195395455","rc":[{"atb":[[3.5,25.85]],"id":42393370}],"con":true,"img":false}]}
{"op":"mcm","clk":"5346835022","pt":1646098328349,"mc":[{"id":"1.195395455","rc":[{"atb":[[3.45,0]],"id":42393370}],"con":true,"img":false}]}
{"op":"mcm","clk":"5346835112","pt":1646098330554,"mc":[{"id":"1.195395455","rc":[{"atb":[[3.15,4.19]],"id":28002629}],"con":true,"img":false}]}
{"op":"mcm","clk":"5346835259","pt":1646098334457,"mc":[{"id":"1.195395455","rc":[{"atb":[[3.05,0]],"id":28002629}],"con":true,"img":false}]}
{"op":"mcm","clk":"5346835352","pt":1646098336664,"mc":[{"id":"1.195395455","rc":[{"atb":[[3.4,0]],"id":42393370}],"con":true,"img":false}]}
{"op":"mcm","clk":"5346835479","pt":1646098340160,"mc":[{"id":"1.195395455","rc":[{"atb":[[3.15,8.47]],"id":28002629}],"con":true,"img":false}]}
{"op":"mcm","clk":"5346835551","pt":1646098341873,"mc":[{"id":"1.195395455","rc":[{"atb":[[3.8,0]],"id":28002629}],"con":true,"img":false}]}
{"op":"mcm","clk":"5346835553","pt":1646098341975,"mc":[{"id":"1.195395455","rc":[{"atb":[[3.85,14.92]],"id":28002629}],"con":true,"img":false}]}
{"op":"mcm","clk":"5346835688","pt":1646098345567,"mc":[{"id":"1.195395455","rc":[{"atb":[[3.55,3.53]],"id":42393370}],"con":true,"img":false}]}
{"op":"mcm","clk":"5346835722","pt":1646098346235,"mc":[{"id":"1.195395455","rc":[{"atb":[[3.55,7.13]],"id":42393370}],"con":true,"img":false}]}
{"op":"mcm","clk":"5346836067","pt":1646098355263,"mc":[{"id":"1.195395455","rc":[{"atb":[[3.5,4]],"id":42393370},{"atl":[[15.5,0]],"id":42393370}],"con":true,"img":false}]}
{"op":"mcm","clk":"5346836071","pt":1646098355367,"mc":[{"id":"1.195395455","rc":[{"atb":[[3.55,28.98]],"id":42393370},{"atl":[[14.5,8.65]],"id":42393370}],"con":true,"img":false}]}
{"op":"mcm","clk":"5346836246","pt":1646098359576,"mc":[{"id":"1.195395455","rc":[{"atb":[[2.32,58.82],[2.58,0]],"id":28002629},{"atb":[[3.1,47.62]],"id":42393370},{"atl":[[11.5,7.14]],"id":42393370},{"atl":[[430,4.7]],"id":37455733},{"atb":[[4.6,27.78]],"id":22150928},{"atl":[[4.8,26.32],[4.2,0]],"id":43154433}],"con":true,"img":false}]}
{"op":"mcm","clk":"5346836251","pt":1646098359679,"mc":[{"id":"1.195395455","rc":[{"atb":[[3.5,0]],"id":42393370},{"atl":[[15,0]],"id":42393370},{"atb":[[5.6,0]],"id":22150928}],"con":true,"img":false}]}
{"op":"mcm","clk":"5346836399","pt":1646098363675,"mc":[{"id":"1.195395455","rc":[{"atb":[[3.55,25.45]],"id":42393370}],"con":true,"img":false}]}
{"op":"mcm","clk":"5346836608","pt":1646098368609,"mc":[{"id":"1.195395455","rc":[{"atb":[[3.55,3.6]],"id":42393370},{"atl":[[21,6.49],[14.5,0]],"id":42393370},{"atl":[[4.1,0],[4.7,31.49]],"id":43154433}],"con":true,"img":false}]}
{"op":"mcm","clk":"5346836613","pt":1646098368710,"mc":[{"id":"1.195395455","rc":[{"atb":[[3.15,21.85]],"id":42393370}],"con":true,"img":false}]}
{"op":"mcm","clk":"5346836661","pt":1646098370304,"mc":[{"id":"1.195395455","rc":[{"atb":[[3.55,0]],"id":42393370}],"con":true,"img":false}]}
{"op":"mcm","clk":"5346836746","pt":1646098372516,"mc":[{"id":"1.195395455","rc":[{"atb":[[5.7,21.28],[6.6,0]],"id":37672294},{"atb":[[2.32,0],[2.48,58.82]],"id":28002629},{"atb":[[3.2,45.45],[3.1,0]],"id":42393370},{"atl":[[11.5,0],[12,13.02]],"id":42393370},{"atl":[[4.8,0],[4.2,31.25]],"id":43154433}],"con":true,"img":false}]}
{"op":"mcm","clk":"5346837154","pt":1646098382912,"mc":[{"id":"1.195395455","rc":[{"atb":[[3.1,0]],"id":28002629}],"con":true,"img":false}]}
{"op":"mcm","clk":"5346837159","pt":1646098383013,"mc":[{"id":"1.195395455","rc":[{"atb":[[3.2,63.28]],"id":28002629}],"con":true,"img":false}]}
{"op":"mcm","clk":"5346837330","pt":1646098387425,"mc":[{"id":"1.195395455","rc":[{"atb":[[2.36,58.82],[2.48,0]],"id":28002629},{"atb":[[3.95,0],[5.2,23.81]],"id":37455733}],"con":true,"img":false}]}
{"op":"mcm","clk":"5346837411","pt":1646098389115,"mc":[{"id":"1.195395455","rc":[{"atb":[[3.25,4.07]],"id":42393370}],"con":true,"img":false}]}
{"op":"mcm","clk":"5346837476","pt":1646098390806,"mc":[{"id":"1.195395455","rc":[{"atb":[[3.15,4.27]],"id":28002629}],"con":true,"img":false}]}
{"op":"mcm","clk":"5346837541","pt":1646098392300,"mc":[{"id":"1.195395455","rc":[{"atl":[[3.8,35.71],[4.2,0]],"id":43154433}],"con":true,"img":false}]}
{"op":"mcm","clk":"5346837590","pt":1646098393731,"mc":[{"id":"1.195395455","rc":[{"atb":[[3.25,8.07]],"id":42393370}],"con":true,"img":false}]}
{"op":"mcm","clk":"5346837665","pt":1646098395991,"mc":[{"id":"1.195395455","rc":[{"atb":[[3.15,0]],"id":42393370}],"con":true,"img":false}]}
{"op":"mcm","clk":"5346837668","pt":1646098396092,"mc":[{"id":"1.195395455","rc":[{"atb":[[3.25,29.92]],"id":42393370}],"con":true,"img":false}]}
{"op":"mcm","clk":"5346837816","pt":1646098400316,"mc":[{"id":"1.195395455","rc":[{"atb":[[3.15,0]],"id":28002629}],"con":true,"img":false}]}
{"op":"mcm","clk":"5346837885","pt":1646098402729,"mc":[{"id":"1.195395455","rc":[{"atb":[[3.25,4]],"id":28002629},{"atb":[[3.25,25.92]],"id":42393370}],"con":true,"img":false}]}
{"op":"mcm","clk":"5346837995","pt":1646098406322,"mc":[{"id":"1.195395455","rc":[{"atb":[[3.25,8.07]],"id":28002629}],"con":true,"img":false}]}
{"op":"mcm","clk":"5346838187","pt":1646098411738,"mc":[{"id":"1.195395455","rc":[{"atb":[[3.3,3.91]],"id":42393370}],"con":true,"img":false}]}
{"op":"mcm","clk":"5346838612","pt":1646098422768,"mc":[{"id":"1.195395455","rc":[{"atb":[[3.25,4.07]],"id":42393370}],"con":true,"img":false}]}
{"op":"mcm","clk":"5346838616","pt":1646098422871,"mc":[{"id":"1.195395455","rc":[{"atb":[[3.3,25.76]],"id":42393370}],"con":true,"img":false}]}
{"op":"mcm","clk":"5346838696","pt":1646098424465,"mc":[{"id":"1.195395455","rc":[{"atb":[[3.25,0]],"id":42393370}],"con":true,"img":false}]}
{"op":"mcm","clk":"5346838747","pt":1646098425540,"mc":[{"id":"1.195395455","rc":[{"atl":[[3.75,42.38],[4.7,0]],"id":43154433}],"con":true,"img":false}]}
{"op":"mcm","clk":"5346838920","pt":1646098429855,"mc":[{"id":"1.195395455","rc":[{"atb":[[3.3,21.85]],"id":42393370}],"con":true,"img":false}]}
{"op":"mcm","clk":"5346839200","pt":1646098436775,"mc":[{"id":"1.195395455","rc":[{"atb":[[3.3,0]],"id":42393370}],"con":true,"img":false}]}
{"op":"mcm","clk":"5346839203","pt":1646098436882,"mc":[{"id":"1.195395455","rc":[{"atb":[[2.36,73.53],[3.2,0],[3.25,21.85]],"id":42393370}],"con":true,"img":false}]}
{"op":"mcm","clk":"5346839399","pt":1646098441501,"mc":[{"id":"1.195395455","rc":[{"atb":[[9,2.5],[8.6,6.58],[8.2,10.42],[7.8,18.38]],"id":37672294},{"atl":[[32,2.42],[36,3.57],[27,1],[29,1.79]],"id":37672294},{"atb":[[3.45,8.16],[3.35,21.28],[3.25,41.4],[3.15,58.14]],"id":28002629},{"atl":[[8.6,2.63],[9,6.25],[9.8,14.2],[9.4,8.93]],"id":28002629},{"atb":[[3.2,22.73],[3.1,35.71],[3,62.5],[3.3,8.7]],"id":42393370},{"atl":[[8,7.14],[7.6,3.03],[8.8,16.03],[8.4,10.14]],"id":42393370},{"atb":[[8,7.14],[7.2,20.16],[7.6,11.36],[8.4,2.7]],"id":37267533},{"atl":[[270,1],[290,1],[310,1],[250,1]],"id":37267533},{"atb":[[5.1,12.2],[5.3,4.65],[4.9,19.23],[4.7,33.78]],"id":37455733},{"atl":[[340,1],[360,1],[380,1],[400,1]],"id":37455733},{"atb":[[6.2,14.42],[7,3.33],[6.6,8.93],[5.9,25.51]],"id":22150928},{"atl":[[32,2.42],[36,3.57],[27,1],[29,1.79]],"id":22150928},{"atb":[[1.56,133.93],[1.6,33.33],[1.58,86.21],[1.54,231.48]],"id":43154433},{"atl":[[2.92,10.42],[3.1,59.52],[3,37.5],[2.96,25.51]],"id":43154433}],"con":true,"img":false}]}
{"op":"mcm","clk":"5346839402","pt":1646098441603,"mc":[{"id":"1.195395455","rc":[{"atl":[[2.98,25.25],[2.94,10.31],[3.05,36.59],[3.15,58.14]],"id":43154433}],"con":true,"img":false}]}
{"op":"mcm","clk":"5346839407","pt":1646098441707,"mc":[{"id":"1.195395455","rc":[{"atl":[[75,2],[120,2.7]],"id":37672294},{"atl":[[17.5,2.7],[9.4,14.86]],"id":28002629},{"atl":[[270,3],[340,2.7]],"id":37267533},{"atl":[[360,3],[430,2.7]],"id":37455733},{"atl":[[65,2.67],[130,2.7]],"id":22150928},{"atb":[[1.46,0],[1.58,129.48]],"id":43154433}],"con":true,"img":false}]}
{"op":"mcm","clk":"5346839412","pt":1646098441764,"mc":[{"id":"1.195395455","rc":[{"atb":[[5.1,24.39]],"id":22150928}],"con":true,"img":false}]}
{"op":"mcm","clk":"5346839418","pt":1646098441864,"mc":[{"id":"1.195395455","rc":[{"atb":[[4.6,0]],"id":22150928},{"atl":[[3.1,0],[3,0],[2.92,0],[2.96,0]],"id":43154433}],"con":true,"img":false}]}
{"op":"mcm","clk":"5346839679","pt":1646098447405,"mc":[{"id":"1.195395455","rc":[{"atb":[[3.2,0]],"id":28002629}],"con":true,"img":false}]}
{"op":"mcm","clk":"5346839681","pt":1646098447504,"mc":[{"id":"1.195395455","rc":[{"atb":[[3.4,63.28]],"id":28002629}],"con":true,"img":false}]}
{"op":"mcm","clk":"5346839706","pt":1646098447975,"mc":[{"id":"1.195395455","rc":[{"atb":[[3.25,37.4]],"id":28002629},{"atb":[[1.48,19.14]],"id":43154433}],"con":true,"img":false}]}
{"op":"mcm","clk":"5346839976","pt":1646098453821,"mc":[{"id":"1.195395455","rc":[{"atb":[[3.3,12.61]],"id":42393370}],"con":true,"img":false}]}
{"op":"mcm","clk":"5346839996","pt":1646098454286,"mc":[{"id":"1.195395455","rc":[{"atl":[[2.92,10.42],[2.94,0]],"id":43154433}],"con":true,"img":false}]}
{"op":"mcm","clk":"5346840013","pt":1646098454694,"mc":[{"id":"1.195395455","rc":[{"atb":[[3.25,33.33]],"id":28002629},{"atb":[[1.48,0]],"id":43154433}],"con":true,"img":false}]}
{"op":"mcm","clk":"5346840017","pt":1646098454796,"mc":[{"id":"1.195395455","rc":[{"atb":[[3.15,4.27]],"id":42393370}],"con":true,"img":false}]}
{"op":"mcm","clk":"5346840072","pt":1646098456085,"mc":[{"id":"1.195395455","rc":[{"atb":[[2.36,0],[3.3,34.46]],"id":42393370}],"con":true,"img":false}]}
{"op":"mcm","clk":"5346840115","pt":1646098456905,"mc":[{"id":"1.195395455","rc":[{"atb":[[1.6,48.35]],"id":43154433}],"con":true,"img":false}]}
{"op":"mcm","clk":"5346840135","pt":1646098457316,"mc":[{"id":"1.195395455","rc":[{"atb":[[9.6,0]],"id":37672294},{"atb":[[3.85,0]],"id":28002629},{"atb":[[9.6,0]],"id":22150928}],"con":true,"img":false}]}
{"op":"mcm","clk":"5346840143","pt":1646098457439,"mc":[{"id":"1.195395455","rc":[{"atb":[[8.4,5.03]],"id":37672294},{"atb":[[3.45,23.08]],"id":28002629},{"atb":[[8.4,5.03]],"id":22150928}],"con":true,"img":false}]}
{"op":"mcm","clk":"5346840285","pt":1646098460286,"mc":[{"id":"1.195395455","rc":[{"atb":[[1.6,63.67]],"id":43154433}],"con":true,"img":false}]}
{"op":"mcm","clk":"5346840302","pt":1646098460798,"mc":[{"id":"1.195395455","rc":[{"atb":[[1.61,129.48]],"id":43154433}],"con":true,"img":false}]}
{"op":"mcm","clk":"5346840306","pt":1646098460901,"mc":[{"id":"1.195395455","rc":[{"atb":[[1.58,86.21]],"id":43154433}],"con":true,"img":false}]}
{"op":"mcm","clk":"5346840398","pt":1646098462906,"mc":[{"id":"1.195395455","rc":[{"atb":[[3.3,30.55]],"id":42393370}],"con":true,"img":false}]}
{"op":"mcm","clk":"5346840461","pt":1646098464300,"mc":[{"id":"1.195395455","rc":[{"atl":[[2.94,10.31]],"id":43154433}],"con":true,"img":false}]}
{"op":"mcm","clk":"5346840465","pt":1646098464402,"mc":[{"id":"1.195395455","rc":[{"atl":[[2.92,0]],"id":43154433}],"con":true,"img":false}]}
{"op":"mcm","clk":"5346840528","pt":1646098465898,"mc":[{"id":"1.195395455","rc":[{"atl":[[2.92,10.42]],"id":43154433}],"con":true,"img":false}]}
{"op":"mcm","clk":"5346840534","pt":1646098466001,"mc":[{"id":"1.195395455","rc":[{"atl":[[2.94,0]],"id":43154433}],"con":true,"img":false}]}
{"op":"mcm","clk":"5346840612","pt":1646098467439,"mc":[{"id":"1.195395455","rc":[{"atl":[[12,9.09]],"id":42393370},{"atl":[[170,0]],"id":37267533},{"atl":[[210,0]],"id":37455733}],"con":true,"img":false}]}
{"op":"mcm","clk":"5346840618","pt":1646098467541,"mc":[{"id":"1.195395455","rc":[{"atl":[[11,3.93]],"id":42393370},{"atl":[[160,0.25]],"id":37267533},{"atl":[[380,3],[200,0.2]],"id":37455733}],"con":true,"img":false}]}
{"op":"mcm","clk":"5346840625","pt":1646098467643,"mc":[{"id":"1.195395455","rc":[{"atl":[[270,1],[290,3]],"id":37267533},{"atl":[[360,1]],"id":37455733}],"con":true,"img":false}]}
{"op":"mcm","clk":"5346840688","pt":1646098468927,"mc":[{"id":"1.195395455","rc":[{"atb":[[1.6,48.65]],"id":43154433}],"con":true,"img":false}]}
{"op":"mcm","clk":"5346840778","pt":1646098471808,"mc":[{"id":"1.195395455","rc":[{"atb":[[3.35,3.83]],"id":42393370}],"con":true,"img":false}]}
{"op":"mcm","clk":"5346840803","pt":1646098472421,"mc":[{"id":"1.195395455","rc":[{"atb":[[3.15,0]],"id":42393370}],"con":true,"img":false}]}
{"op":"mcm","clk":"5346840807","pt":1646098472524,"mc":[{"id":"1.195395455","rc":[{"atb":[[3.5,3.67]],"id":28002629}],"con":true,"img":false}]}
{"op":"mcm","clk":"5346840909","pt":1646098474840,"mc":[{"id":"1.195395455","rc":[{"atb":[[3.5,7.28]],"id":28002629}],"con":true,"img":false}]}
{"op":"mcm","clk":"5346840956","pt":1646098475919,"mc":[{"id":"1.195395455","rc":[{"atl":[[2.94,10.31]],"id":43154433}],"con":true,"img":false}]}
{"op":"mcm","clk":"5346840962","pt":1646098476023,"mc":[{"id":"1.195395455","rc":[{"atl":[[2.92,0]],"id":43154433}],"con":true,"img":false}]}
{"op":"mcm","clk":"5346841020","pt":1646098477353,"mc":[{"id":"1.195395455","rc":[{"atl":[[70,0],[46,2.7]],"id":37672294},{"atl":[[65,2],[46,2.7]],"id":22150928}],"con":true,"img":false}]}
{"op":"mcm","clk":"5346841025","pt":1646098477455,"mc":[{"id":"1.195395455","rc":[{"atl":[[17.5,0]],"id":28002629},{"atb":[[3.25,0]],"id":42393370},{"atl":[[340,0]],"id":37267533},{"atl":[[430,0]],"id":37455733},{"atb":[[1.49,0]],"id":43154433},{"atl":[[3.35,0]],"id":43154433}],"con":true,"img":false}]}
{"op":"mcm","clk":"5346841031","pt":1646098477559,"mc":[{"id":"1.195395455","rc":[{"atl":[[14.5,2.7]],"id":28002629},{"atb":[[3.35,25.68]],"id":42393370},{"atl":[[240,2.7]],"id":37267533},{"atl":[[330,2.7]],"id":37455733},{"atb":[[1.62,43.26]],"id":43154433},{"atl":[[2.96,19.66]],"id":43154433}],"con":true,"img":false}]}
{"op":"mcm","clk":"5346841037","pt":1646098477616,"mc":[{"id":"1.195395455","rc":[{"atl":[[330,4.7],[380,1]],"id":37455733},{"atb":[[1.63,48.65]],"id":43154433}],"con":true,"img":false}]}
{"op":"mcm","clk":"5346841042","pt":1646098477819,"mc":[{"id":"1.195395455","rc":[{"atb":[[1.61,0]],"id":43154433}],"con":true,"img":false}]}
{"op":"mcm","clk":"5346841092","pt":1646098478944,"mc":[{"id":"1.195395455","rc":[{"atl":[[2.92,10.42],[2.94,0]],"id":43154433}],"con":true,"img":false}]}
{"op":"mcm","clk":"5346841283","pt":1646098484026,"mc":[{"id":"1.195395455","rc":[{"spn":18.75,"spf":1.0,"id":37672294},{"spn":6.5,"spf":1.0,"id":28002629},{"atb":[[3.35,21.85]],"id":42393370},{"spn":5.62,"spf":1.0,"id":42393370},{"spn":19.25,"spf":1.0,"id":22150928},{"spn":2.29,"spf":1.0,"id":43154433}],"con":true,"img":false}]}
{"op":"mcm","clk":"5346841370","pt":1646098486435,"mc":[{"id":"1.195395455","rc":[{"atl":[[290,1],[240,4.7]],"id":37267533}],"con":true,"img":false}]}
{"op":"mcm","clk":"5346841409","pt":1646098487359,"mc":[{"id":"1.195395455","rc":[{"atb":[[8,18.38]],"id":37672294}],"con":true,"img":false}]}
{"op":"mcm","clk":"5346841412","pt":1646098487461,"mc":[{"id":"1.195395455","rc":[{"atb":[[6.8,0]],"id":37672294}],"con":true,"img":false}]}
{"op":"mcm","clk":"5346841476","pt":1646098488953,"mc":[{"id":"1.195395455","rc":[{"atl":[[2.92,0],[2.94,10.31]],"id":43154433}],"con":true,"img":false}]}
{"op":"mcm","clk":"5346841545","pt":1646098490546,"mc":[{"id":"1.195395455","rc":[{"atl":[[2.92,10.42],[2.94,0]],"id":43154433}],"con":true,"img":false}]}
{"op":"mcm","clk":"5346841736","pt":1646098495849,"mc":[{"id":"1.195395455","rc":[{"atb":[[3.4,3.76]],"id":42393370},{"atb":[[1.65,13.86]],"id":43154433}],"con":true,"img":false}]}
{"op":"mcm","clk":"5346841756","pt":1646098496362,"mc":[{"id":"1.195395455","rc":[{"atb":[[1.63,0],[1.65,57.13]],"id":43154433}],"con":true,"img":false}]}
{"op":"mcm","clk":"5346841792","pt":1646098497342,"mc":[{"id":"1.195395455","rc":[{"atl":[[21,0],[11.5,11.89]],"id":42393370}],"con":true,"img":false}]}
{"op":"mcm","clk":"5346841919","pt":1646098500582,"mc":[{"id":"1.195395455","rc":[{"atl":[[2.92,0],[2.94,10.31]],"id":43154433}],"con":true,"img":false}]}
{"op":"mcm","clk":"5346841924","pt":1646098500682,"mc":[{"id":"1.195395455","rc":[{"atb":[[1.3,240]],"id":43154433}],"con":true,"img":false}]}
{"op":"mcm","clk":"5346841951","pt":1646098501456,"mc":[{"id":"1.195395455","rc":[{"atl":[[260,1],[250,0]],"id":37267533},{"atl":[[340,0],[350,1]],"id":37455733},{"atb":[[1.6,15.32],[1.58,34.48],[1.62,102.39],[1.65,13.86]],"id":43154433}],"con":true,"img":false}]}
{"op":"mcm","clk":"5346841995","pt":1646098502686,"mc":[{"id":"1.195395455","rc":[{"atb":[[1.6,0]],"id":43154433}],"con":true,"img":false}]}
{"op":"mcm","clk":"5346841998","pt":1646098502742,"mc":[{"id":"1.195395455","rc":[{"atb":[[3.35,25.76]],"id":42393370}],"con":true,"img":false}]}
{"op":"mcm","clk":"5346842059","pt":1646098504955,"mc":[{"id":"1.195395455","rc":[{"atb":[[1.65,0]],"id":43154433}],"con":true,"img":false}]}
{"op":"mcm","clk":"5346842286","pt":1646098511472,"mc":[{"id":"1.195395455","rc":[{"atl":[[280,1]],"id":37267533},{"atl":[[370,1]],"id":37455733},{"atb":[[1.56,89.29]],"id":43154433}],"con":true,"img":false}]}
{"op":"mcm","clk":"5346842400","pt":1646098514602,"mc":[{"id":"1.195395455","rc":[{"atb":[[1.64,14.35]],"id":43154433}],"con":true,"img":false}]}
{"op":"mcm","clk":"5346842488","pt":1646098516967,"mc":[{"id":"1.195395455","rc":[{"atb":[[1.64,28.43]],"id":43154433}],"con":true,"img":false}]}
{"op":"mcm","clk":"5346842507","pt":1646098517376,"mc":[{"id":"1.195395455","rc":[{"atl":[[240,2]],"id":37267533},{"atl":[[330,2]],"id":37455733}],"con":true,"img":false}]}
{"op":"mcm","clk":"5346842509","pt":1646098517479,"mc":[{"id":"1.195395455","rc":[{"atl":[[230,2.7]],"id":37267533},{"atl":[[320,2.7]],"id":37455733}],"con":true,"img":false}]}
{"op":"mcm","clk":"5346842522","pt":1646098517891,"mc":[{"id":"1.195395455","rc":[{"atl":[[270,0],[290,0],[310,0]],"id":37267533},{"atl":[[360,0],[380,0],[400,0]],"id":37455733},{"atl":[[2.92,10.42],[2.94,0]],"id":43154433}],"con":true,"img":false}]}
{"op":"mcm","clk":"5346842645","pt":1646098521485,"mc":[{"id":"1.195395455","rc":[{"atl":[[300,1]],"id":37267533},{"atl":[[390,1]],"id":37455733}],"con":true,"img":false}]}
{"op":"mcm","clk":"5346842791","pt":1646098525902,"mc":[{"id":"1.195395455","rc":[{"atl":[[2.94,10.31]],"id":43154433}],"con":true,"img":false}]}
{"op":"mcm","clk":"5346842795","pt":1646098526005,"mc":[{"id":"1.195395455","rc":[{"atl":[[2.92,0]],"id":43154433}],"con":true,"img":false}]}
{"op":"mcm","clk":"5346843025","pt":1646098531515,"mc":[{"id":"1.195395455","rc":[{"atl":[[320,1]],"id":37267533},{"atl":[[410,1]],"id":37455733}],"con":true,"img":false}]}
{"op":"mcm","clk":"5346843194","pt":1646098535928,"mc":[{"id":"1.195395455","rc":[{"atb":[[1.54,138.89]],"id":43154433}],"con":true,"img":false}]}
{"op":"mcm","clk":"5346843258","pt":1646098537420,"mc":[{"id":"1.195395455","rc":[{"atb":[[1.62,59.13]],"id":43154433},{"atl":[[2.92,10.42],[2.94,0]],"id":43154433}],"con":true,"img":false}]}
{"op":"mcm","clk":"5346843264","pt":1646098537522,"mc":[{"id":"1.195395455","rc":[{"atb":[[1.65,43.26]],"id":43154433}],"con":true,"img":false}]}
{"op":"mcm","clk":"5346843375","pt":1646098540706,"mc":[{"id":"1.195395455","rc":[{"atl":[[2.94,10.31]],"id":43154433}],"con":true,"img":false}]}
{"op":"mcm","clk":"5346843379","pt":1646098540810,"mc":[{"id":"1.195395455","rc":[{"atl":[[2.92,0]],"id":43154433}],"con":true,"img":false}]}
{"op":"mcm","clk":"5346843514","pt":1646098544035,"mc":[{"id":"1.195395455","rc":[{"atb":[[1.64,14.35]],"id":43154433},{"spn":2.3,"spf":1.0,"id":43154433}],"con":true,"img":false}]}
{"op":"mcm","clk":"5346843644","pt":1646098547317,"mc":[{"id":"1.195395455","rc":[{"atb":[[1.31,375.98]],"id":43154433}],"con":true,"img":false}]}
{"op":"mcm","clk":"5346843651","pt":1646098547419,"mc":[{"id":"1.195395455","rc":[{"atb":[[1.25,0],[1.65,0]],"id":43154433}],"con":true,"img":false}]}
{"op":"mcm","clk":"5346843656","pt":1646098547523,"mc":[{"id":"1.195395455","rc":[{"atb":[[1.63,43.26]],"id":43154433}],"con":true,"img":false}]}
{"op":"mcm","clk":"5346843755","pt":1646098550340,"mc":[{"id":"1.195395455","rc":[{"atl":[[2.92,10.42]],"id":43154433}],"con":true,"img":false}]}
{"op":"mcm","clk":"5346843759","pt":1646098550444,"mc":[{"id":"1.195395455","rc":[{"atl":[[2.94,0]],"id":43154433}],"con":true,"img":false}]}
{"op":"mcm","clk":"5346843817","pt":1646098552031,"mc":[{"id":"1.195395455","rc":[{"atl":[[2.92,0],[2.94,10.31]],"id":43154433}],"con":true,"img":false}]}
{"op":"mcm","clk":"5346844111","pt":1646098562045,"mc":[{"id":"1.195395455","rc":[{"atb":[[1.52,240.38]],"id":43154433}],"con":true,"img":false}]}
{"op":"mcm","clk":"5346844141","pt":1646098563021,"mc":[{"id":"1.195395455","rc":[{"atl":[[2.92,10.42]],"id":43154433}],"con":true,"img":false}]}
{"op":"mcm","clk":"5346844142","pt":1646098563122,"mc":[{"id":"1.195395455","rc":[{"atl":[[2.94,0]],"id":43154433}],"con":true,"img":false}]}
{"op":"mcm","clk":"5346844166","pt":1646098563743,"mc":[{"id":"1.195395455","rc":[{"atl":[[2.92,0],[2.94,10.31]],"id":43154433}],"con":true,"img":false}]}
{"op":"mcm","clk":"5346844211","pt":1646098565023,"mc":[{"id":"1.195395455","rc":[{"atb":[[1.64,28.43]],"id":43154433}],"con":true,"img":false}]}
{"op":"mcm","clk":"5346844593","pt":1646098574662,"mc":[{"id":"1.195395455","rc":[{"atl":[[2.92,10.42],[2.94,0]],"id":43154433}],"con":true,"img":false}]}
{"op":"mcm","clk":"5346844617","pt":1646098575379,"mc":[{"id":"1.195395455","rc":[{"atl":[[2.92,0],[2.94,10.31]],"id":43154433}],"con":true,"img":false}]}
{"op":"mcm","clk":"5346844948","pt":1646098586091,"mc":[{"id":"1.195395455","rc":[{"atl":[[2.92,10.42],[2.94,0]],"id":43154433}],"con":true,"img":false}]}
{"op":"mcm","clk":"5346844997","pt":1646098587269,"mc":[{"id":"1.195395455","rc":[{"atl":[[2.94,10.31]],"id":43154433}],"con":true,"img":false}]}
{"op":"mcm","clk":"5346845002","pt":1646098587370,"mc":[{"id":"1.195395455","rc":[{"atb":[[1.63,0]],"id":43154433},{"atl":[[2.92,0]],"id":43154433}],"con":true,"img":false}]}
{"op":"mcm","clk":"5346845005","pt":1646098587476,"mc":[{"id":"1.195395455","rc":[{"atb":[[1.65,43.26]],"id":43154433}],"con":true,"img":false}]}
{"op":"mcm","clk":"5346845307","pt":1646098595204,"mc":[{"id":"1.195395455","rc":[{"atb":[[1.64,14.35]],"id":43154433}],"con":true,"img":false}]}
{"op":"mcm","clk":"5346845384","pt":1646098597408,"mc":[{"id":"1.195395455","rc":[{"atb":[[1.65,0]],"id":43154433},{"atl":[[2.92,10.42]],"id":43154433}],"con":true,"img":false}]}
{"op":"mcm","clk":"5346845390","pt":1646098597512,"mc":[{"id":"1.195395455","rc":[{"atb":[[1.63,43.26]],"id":43154433},{"atl":[[2.94,0]],"id":43154433}],"con":true,"img":false}]}
{"op":"mcm","clk":"5346845487","pt":1646098600298,"mc":[{"id":"1.195395455","rc":[{"atl":[[2.92,0],[2.94,10.31]],"id":43154433}],"con":true,"img":false}]}
{"op":"mcm","clk":"5346845829","pt":1646098610428,"mc":[{"id":"1.195395455","rc":[{"atl":[[2.92,10.42]],"id":43154433},{"spn":2.29,"spf":1.0,"id":43154433}],"con":true,"img":false}]}
{"op":"mcm","clk":"5346845834","pt":1646098610482,"mc":[{"id":"1.195395455","rc":[{"atl":[[2.94,0]],"id":43154433}],"con":true,"img":false}]}
{"op":"mcm","clk":"5346845890","pt":1646098612321,"mc":[{"id":"1.195395455","rc":[{"atl":[[2.92,0],[2.94,10.31]],"id":43154433}],"con":true,"img":false}]}
{"op":"mcm","clk":"5346845920","pt":1646098613092,"mc":[{"id":"1.195395455","rc":[{"atb":[[1.64,28.43]],"id":43154433}],"con":true,"img":false}]}
{"op":"mcm","clk":"5346846277","pt":1646098622733,"mc":[{"id":"1.195395455","rc":[{"atl":[[2.92,10.42],[2.94,0]],"id":43154433}],"con":true,"img":false}]}
{"op":"mcm","clk":"5346846341","pt":1646098624937,"mc":[{"id":"1.195395455","rc":[{"atl":[[2.92,0],[2.94,10.31]],"id":43154433}],"con":true,"img":false}]}
{"op":"mcm","clk":"5346846700","pt":1646098635033,"mc":[{"id":"1.195395455","rc":[{"atl":[[2.92,10.42],[2.94,0]],"id":43154433}],"con":true,"img":false}]}
{"op":"mcm","clk":"5346846748","pt":1646098636731,"mc":[{"id":"1.195395455","rc":[{"atl":[[2.94,10.31]],"id":43154433}],"con":true,"img":false}]}
{"op":"mcm","clk":"5346846751","pt":1646098636832,"mc":[{"id":"1.195395455","rc":[{"atl":[[2.92,0]],"id":43154433}],"con":true,"img":false}]}
{"op":"mcm","clk":"5346846766","pt":1646098637447,"mc":[{"id":"1.195395455","rc":[{"atb":[[1.63,0]],"id":43154433}],"con":true,"img":false}]}
{"op":"mcm","clk":"5346846770","pt":1646098637548,"mc":[{"id":"1.195395455","rc":[{"atb":[[1.65,43.26]],"id":43154433}],"con":true,"img":false}]}
{"op":"mcm","clk":"5346847081","pt":1646098646125,"mc":[{"id":"1.195395455","rc":[{"atb":[[1.64,14.35]],"id":43154433}],"con":true,"img":false}]}
{"op":"mcm","clk":"5346847127","pt":1646098647350,"mc":[{"id":"1.195395455","rc":[{"atb":[[1.65,0]],"id":43154433}],"con":true,"img":false}]}
{"op":"mcm","clk":"5346847130","pt":1646098647451,"mc":[{"id":"1.195395455","rc":[{"atb":[[1.63,43.26]],"id":43154433}],"con":true,"img":false}]}
{"op":"mcm","clk":"5346847592","pt":1646098659346,"mc":[{"id":"1.195395455","rc":[{"atl":[[2.92,10.42],[2.94,0]],"id":43154433}],"con":true,"img":false}]}
{"op":"mcm","clk":"5346847695","pt":1646098661856,"mc":[{"id":"1.195395455","rc":[{"atl":[[2.92,0],[2.94,10.31]],"id":43154433}],"con":true,"img":false}]}
{"op":"mcm","clk":"5346847951","pt":1646098667191,"mc":[{"id":"1.195395455","rc":[{"atb":[[1.64,28.43]],"id":43154433}],"con":true,"img":false}]}
{"op":"mcm","clk":"5346848138","pt":1646098671396,"mc":[{"id":"1.195395455","rc":[{"atl":[[2.92,10.42]],"id":43154433}],"con":true,"img":false}]}
{"op":"mcm","clk":"5346848142","pt":1646098671499,"mc":[{"id":"1.195395455","rc":[{"atl":[[2.94,0]],"id":43154433}],"con":true,"img":false}]}
{"op":"mcm","clk":"5346848213","pt":1646098673297,"mc":[{"id":"1.195395455","rc":[{"atl":[[2.94,10.31]],"id":43154433}],"con":true,"img":false}]}
{"op":"mcm","clk":"5346848216","pt":1646098673400,"mc":[{"id":"1.195395455","rc":[{"atl":[[2.92,0]],"id":43154433}],"con":true,"img":false}]}
{"op":"mcm","clk":"5346848697","pt":1646098683471,"mc":[{"id":"1.195395455","rc":[{"atl":[[2.92,10.42],[2.94,0]],"id":43154433}],"con":true,"img":false}]}
{"op":"mcm","clk":"5346848853","pt":1646098687008,"mc":[{"id":"1.195395455","rc":[{"atl":[[2.92,0],[2.94,10.31]],"id":43154433}],"con":true,"img":false}]}
{"op":"mcm","clk":"5346848863","pt":1646098687316,"mc":[{"id":"1.195395455","rc":[{"atb":[[1.63,0]],"id":43154433}],"con":true,"img":false}]}
{"op":"mcm","clk":"5346848869","pt":1646098687419,"mc":[{"id":"1.195395455","rc":[{"atb":[[1.65,43.26]],"id":43154433}],"con":true,"img":false}]}
{"op":"mcm","clk":"5346849166","pt":1646098694296,"mc":[{"id":"1.195395455","rc":[{"atb":[[1.64,14.35]],"id":43154433}],"con":true,"img":false}]}
{"op":"mcm","clk":"5346849225","pt":1646098695729,"mc":[{"id":"1.195395455","rc":[{"atl":[[2.92,10.42]],"id":43154433}],"con":true,"img":false}]}
{"op":"mcm","clk":"5346849230","pt":1646098695832,"mc":[{"id":"1.195395455","rc":[{"atl":[[2.94,0]],"id":43154433}],"con":true,"img":false}]}
{"op":"mcm","clk":"5346849297","pt":1646098697425,"mc":[{"id":"1.195395455","rc":[{"atb":[[1.65,0]],"id":43154433}],"con":true,"img":false}]}
{"op":"mcm","clk":"5346849302","pt":1646098697526,"mc":[{"id":"1.195395455","rc":[{"atb":[[1.63,43.26]],"id":43154433}],"con":true,"img":false}]}
{"op":"mcm","clk":"5346849341","pt":1646098698295,"mc":[{"id":"1.195395455","rc":[{"atl":[[2.92,0],[2.94,10.31]],"id":43154433}],"con":true,"img":false}]}
{"op":"mcm","clk":"5346850136","pt":1646098718363,"mc":[{"id":"1.195395455","rc":[{"atb":[[1.64,28.43]],"id":43154433}],"con":true,"img":false}]}
{"op":"mcm","clk":"5346851223","pt":1646098747283,"mc":[{"id":"1.195395455","rc":[{"atb":[[1.63,0]],"id":43154433},{"spn":2.3,"spf":1.0,"id":43154433}],"con":true,"img":false}]}
{"op":"mcm","clk":"5346851227","pt":1646098747385,"mc":[{"id":"1.195395455","rc":[{"atb":[[1.65,43.26]],"id":43154433}],"con":true,"img":false}]}
{"op":"mcm","clk":"5346851562","pt":1646098754382,"mc":[{"id":"1.195395455","rc":[{"atb":[[1.64,14.35]],"id":43154433}],"con":true,"img":false}]}
{"op":"mcm","clk":"5346851695","pt":1646098757405,"mc":[{"id":"1.195395455","rc":[{"atb":[[1.65,0]],"id":43154433}],"con":true,"img":false}]}
{"op":"mcm","clk":"5346851700","pt":1646098757508,"mc":[{"id":"1.195395455","rc":[{"atb":[[1.63,43.26]],"id":43154433}],"con":true,"img":false}]}
{"op":"mcm","clk":"5346852427","pt":1646098775434,"mc":[{"id":"1.195395455","rc":[{"atb":[[1.64,28.43]],"id":43154433}],"con":true,"img":false}]}
{"op":"mcm","clk":"5346853244","pt":1646098797334,"mc":[{"id":"1.195395455","rc":[{"atb":[[1.63,0]],"id":43154433}],"con":true,"img":false}]}
{"op":"mcm","clk":"5346853249","pt":1646098797435,"mc":[{"id":"1.195395455","rc":[{"atb":[[1.65,43.26]],"id":43154433}],"con":true,"img":false}]}
{"op":"mcm","clk":"5346853591","pt":1646098805540,"mc":[{"id":"1.195395455","rc":[{"atb":[[1.64,14.35]],"id":43154433}],"con":true,"img":false}]}
{"op":"mcm","clk":"5346853661","pt":1646098807463,"mc":[{"id":"1.195395455","rc":[{"atb":[[1.65,0]],"id":43154433}],"con":true,"img":false}]}
{"op":"mcm","clk":"5346853668","pt":1646098807563,"mc":[{"id":"1.195395455","rc":[{"atb":[[1.63,43.26]],"id":43154433}],"con":true,"img":false}]}
{"op":"mcm","clk":"5346853759","pt":1646098809566,"mc":[{"id":"1.195395455","rc":[{"atl":[[27,0],[28,1]],"id":37672294},{"atl":[[8.6,0],[8.4,2.7]],"id":28002629},{"atl":[[260,0],[270,1]],"id":37267533},{"atl":[[350,0],[360,1]],"id":37455733},{"atl":[[27,0],[28,1]],"id":22150928}],"con":true,"img":false}]}
{"op":"mcm","clk":"5346853763","pt":1646098809670,"mc":[{"id":"1.195395455","rc":[{"atl":[[9,18.75],[9.4,8.93]],"id":28002629}],"con":true,"img":false}]}
{"op":"mcm","clk":"5346853768","pt":1646098809770,"mc":[{"id":"1.195395455","rc":[{"atl":[[9,6.25],[9.4,20.83]],"id":28002629}],"con":true,"img":false}]}
{"op":"mcm","clk":"5346854004","pt":1646098815780,"mc":[{"id":"1.195395455","rc":[{"atb":[[3.1,83.33],[3.3,8.7]],"id":42393370}],"con":true,"img":false}]}
{"op":"mcm","clk":"5346854159","pt":1646098819573,"mc":[{"id":"1.195395455","rc":[{"atl":[[30,1.72]],"id":37672294},{"atl":[[290,1]],"id":37267533},{"atl":[[380,1]],"id":37455733},{"atl":[[30,1.72]],"id":22150928}],"con":true,"img":false}]}
{"op":"mcm","clk":"5346854319","pt":1646098823569,"mc":[{"id":"1.195395455","rc":[{"atb":[[1.64,28.43]],"id":43154433}],"con":true,"img":false}]}
{"op":"mcm","clk":"5346854446","pt":1646098826081,"mc":[{"id":"1.195395455","rc":[{"atl":[[27,1],[28,0],[30,0]],"id":37672294},{"atl":[[8.6,2.63],[8.4,0]],"id":28002629},{"atl":[[270,0],[260,1],[290,0]],"id":37267533},{"atl":[[350,1],[360,0],[380,0]],"id":37455733},{"atl":[[27,1],[28,0],[30,0]],"id":22150928}],"con":true,"img":false}]}
{"op":"mcm","clk":"5346854450","pt":1646098826186,"mc":[{"id":"1.195395455","rc":[{"atl":[[9,18.75],[9.4,8.93]],"id":28002629},{"atb":[[3.4,12.09],[3.3,0]],"id":42393370},{"atl":[[340,1],[370,0],[390,0],[410,0]],"id":37455733},{"atb":[[1.62,0],[1.61,89.29]],"id":43154433}],"con":true,"img":false}]}
{"op":"mcm","clk":"5346854525","pt":1646098827778,"mc":[{"id":"1.195395455","rc":[{"atb":[[3.45,14.92],[3.35,8.51]],"id":28002629}],"con":true,"img":false}]}
{"op":"mcm","clk":"5346854668","pt":1646098830703,"mc":[{"id":"1.195395455","rc":[{"atb":[[3.35,21.85]],"id":42393370}],"con":true,"img":false}]}
{"op":"mcm","clk":"5346854692","pt":1646098831165,"mc":[{"id":"1.195395455","rc":[{"atb":[[3.1,35.71],[3.35,44.58]],"id":42393370}],"con":true,"img":false}]}
{"op":"mcm","clk":"5346854694","pt":1646098831267,"mc":[{"id":"1.195395455","rc":[{"atl":[[9,6.25],[9.4,20.83]],"id":28002629}],"con":true,"img":false}]}
{"op":"mcm","clk":"5346854749","pt":1646098832702,"mc":[{"id":"1.195395455","rc":[{"atb":[[1.64,14.35]],"id":43154433}],"con":true,"img":false}]}
{"op":"mcm","clk":"5346854880","pt":1646098835581,"mc":[{"id":"1.195395455","rc":[{"atb":[[3.5,3.67]],"id":28002629}],"con":true,"img":false}]}
{"op":"mcm","clk":"5346854907","pt":1646098836094,"mc":[{"id":"1.195395455","rc":[{"atl":[[26,1],[27,0]],"id":37672294},{"atb":[[4.4,0]],"id":28002629},{"atl":[[8.6,0],[8.4,2.7]],"id":28002629},{"atb":[[3.35,53.09],[3.4,3.76]],"id":42393370},{"atl":[[260,0],[250,1]],"id":37267533},{"atb":[[22,2.7]],"id":37455733},{"atl":[[330,3]],"id":37455733},{"atl":[[26,1],[27,0]],"id":22150928},{"atb":[[1.6,33.33],[1.58,0]],"id":43154433}],"con":true,"img":false}]}
{"op":"mcm","clk":"5346854911","pt":1646098836196,"mc":[{"id":"1.195395455","rc":[{"atb":[[4.2,2]],"id":28002629}],"con":true,"img":false}]}
{"op":"mcm","clk":"5346854917","pt":1646098836308,"mc":[{"id":"1.195395455","rc":[{"atb":[[27,0.39]],"id":37455733}],"con":true,"img":false}]}
{"op":"mcm","clk":"5346854962","pt":1646098837376,"mc":[{"id":"1.195395455","rc":[{"atb":[[3.4,0]],"id":28002629},{"atb":[[1.63,0]],"id":43154433}],"con":true,"img":false}]}
{"op":"mcm","clk":"5346854968","pt":1646098837477,"mc":[{"id":"1.195395455","rc":[{"atb":[[3.3,63.28]],"id":28002629},{"atb":[[1.62,43.26]],"id":43154433}],"con":true,"img":false}]}
{"op":"mcm","clk":"5346855128","pt":1646098841489,"mc":[{"id":"1.195395455","rc":[{"atb":[[1.65,43.27],[1.61,0]],"id":43154433}],"con":true,"img":false}]}
{"op":"mcm","clk":"5346855132","pt":1646098841590,"mc":[{"id":"1.195395455","rc":[{"atb":[[1.63,14.3]],"id":43154433}],"con":true,"img":false}]}
{"op":"mcm","clk":"5346855169","pt":1646098842411,"mc":[{"id":"1.195395455","rc":[{"atb":[[3.5,0]],"id":28002629},{"atb":[[1.64,0]],"id":43154433}],"con":true,"img":false}]}
{"op":"mcm","clk":"5346855308","pt":1646098846105,"mc":[{"id":"1.195395455","rc":[{"atb":[[3.25,22.22]],"id":28002629},{"atl":[[370,1]],"id":37455733},{"atb":[[1.58,86.21]],"id":43154433}],"con":true,"img":false}]}
{"op":"mcm","clk":"5346855324","pt":1646098846615,"mc":[{"id":"1.195395455","rc":[{"atb":[[1.64,45.27],[1.65,0]],"id":43154433}],"con":true,"img":false}]}
{"op":"mcm","clk":"5346855378","pt":1646098848411,"mc":[{"id":"1.195395455","rc":[{"atb":[[3.4,7.59]],"id":42393370}],"con":true,"img":false}]}
{"op":"mcm","clk":"5346855435","pt":1646098850715,"mc":[{"id":"1.195395455","rc":[{"atb":[[1.63,0]],"id":43154433}],"con":true,"img":false}]}
{"op":"mcm","clk":"5346855438","pt":1646098850817,"mc":[{"id":"1.195395455","rc":[{"atb":[[1.64,0],[1.63,47.27]],"id":43154433}],"con":true,"img":false}]}
{"op":"mcm","clk":"5346855551","pt":1646098853492,"mc":[{"id":"1.195395455","rc":[{"atl":[[2.96,0]],"id":43154433}],"con":true,"img":false}]}
{"op":"mcm","clk":"5346855555","pt":1646098853596,"mc":[{"id":"1.195395455","rc":[{"atb":[[3.35,12.34]],"id":28002629},{"atl":[[3,19.66]],"id":43154433}],"con":true,"img":false}]}
{"op":"mcm","clk":"5346855598","pt":1646098854620,"mc":[{"id":"1.195395455","rc":[{"atb":[[3.35,16.26]],"id":28002629}],"con":true,"img":false}]}
{"op":"mcm","clk":"5346855627","pt":1646098855235,"mc":[{"id":"1.195395455","rc":[{"atb":[[3.35,44.58],[3.4,15.92]],"id":42393370},{"atb":[[1.52,0]],"id":43154433}],"con":true,"img":false}]}
{"op":"mcm","clk":"5346855665","pt":1646098856114,"mc":[{"id":"1.195395455","rc":[{"atb":[[3.15,34.88]],"id":28002629},{"atl":[[390,1]],"id":37455733},{"atb":[[1.56,133.93]],"id":43154433}],"con":true,"img":false}]}
{"op":"mcm","clk":"5346855677","pt":1646098856520,"mc":[{"id":"1.195395455","rc":[{"atb":[[1.7,115.9],[1.55,295.01],[1.75,54.08],[1.65,187.21]],"id":43154433},{"atl":[[3.45,53.95],[3.2,60.08],[3.95,67.21],[3.7,73.43]],"id":43154433}],"con":true,"img":false}]}
{"op":"mcm","clk":"5346855709","pt":1646098857342,"mc":[{"id":"1.195395455","rc":[{"atl":[[21,6.49],[11.5,0]],"id":42393370}],"con":true,"img":false}]}
{"op":"mcm","clk":"5346855750","pt":1646098858321,"mc":[{"id":"1.195395455","rc":[{"atl":[[340,0]],"id":37455733},{"atl":[[3.8,0],[3.5,40]],"id":43154433}],"con":true,"img":false}]}
{"op":"mcm","clk":"5346855879","pt":1646098861511,"mc":[{"id":"1.195395455","rc":[{"atb":[[1.67,0]],"id":43154433}],"con":true,"img":false}]}
{"op":"mcm","clk":"5346855881","pt":1646098861618,"mc":[{"id":"1.195395455","rc":[{"atb":[[1.71,2]],"id":43154433}],"con":true,"img":false}]}
{"op":"mcm","clk":"5346855928","pt":1646098863106,"mc":[{"id":"1.195395455","rc":[{"atl":[[8.6,2.63]],"id":28002629}],"con":true,"img":false}]}
{"op":"mcm","clk":"5346855930","pt":1646098863206,"mc":[{"id":"1.195395455","rc":[{"atl":[[25,1],[26,0]],"id":37672294},{"atl":[[8.6,8.88],[8.4,0],[9.4,8.93]],"id":28002629},{"atl":[[240,3],[250,0]],"id":37267533},{"atl":[[320,3.7],[330,2]],"id":37455733},{"atl":[[25,1],[26,0]],"id":22150928},{"atb":[[1.6,0],[1.63,31.75],[1.67,108.18]],"id":43154433}],"con":true,"img":false}]}
{"op":"mcm","clk":"5346855991","pt":1646098865209,"mc":[{"id":"1.195395455","rc":[{"atb":[[3.3,21.74]],"id":42393370}],"con":true,"img":false}]}
{"op":"mcm","clk":"5346856004","pt":1646098865618,"mc":[{"id":"1.195395455","rc":[{"atb":[[1.62,0]],"id":43154433},{"atl":[[3,0]],"id":43154433}],"con":true,"img":false}]}
{"op":"mcm","clk":"5346856010","pt":1646098865727,"mc":[{"id":"1.195395455","rc":[{"atb":[[1.66,43.26]],"id":43154433},{"atl":[[3.1,19.66]],"id":43154433}],"con":true,"img":false}]}
{"op":"mcm","clk":"5346856076","pt":1646098867318,"mc":[{"id":"1.195395455","rc":[{"atl":[[3.75,0]],"id":43154433}],"con":true,"img":false}]}
{"op":"mcm","clk":"5346856080","pt":1646098867419,"mc":[{"id":"1.195395455","rc":[{"atl":[[3.9,42.38]],"id":43154433}],"con":true,"img":false}]}
{"op":"mcm","clk":"5346856104","pt":1646098867935,"mc":[{"id":"1.195395455","rc":[{"spn":17.75,"spf":1.0,"id":37672294},{"atl":[[8.6,6.25],[8.4,2.7]],"id":28002629},{"spn":6.3,"spf":1.0,"id":28002629},{"atb":[[3,0]],"id":42393370},{"spn":63.5,"spf":1.0,"id":37455733},{"spn":18.25,"spf":1.0,"id":22150928},{"spn":2.34,"spf":1.0,"id":43154433}],"con":true,"img":false}]}
{"op":"mcm","clk":"5346856119","pt":1646098868442,"mc":[{"id":"1.195395455","rc":[{"atl":[[8.6,0],[9,15.2]],"id":28002629}],"con":true,"img":false}]}
{"op":"mcm","clk":"5346856262","pt":1646098872550,"mc":[{"id":"1.195395455","rc":[{"atb":[[1.78,11.78]],"id":43154433}],"con":true,"img":false}]}
{"op":"mcm","clk":"5346856286","pt":1646098873218,"mc":[{"id":"1.195395455","rc":[{"atl":[[27,1.92]],"id":37672294},{"atl":[[260,1]],"id":37267533},{"atl":[[27,1.92]],"id":22150928},{"atb":[[1.61,81.97]],"id":43154433}],"con":true,"img":false}]}
{"op":"mcm","clk":"5346856300","pt":1646098873628,"mc":[{"id":"1.195395455","rc":[{"atl":[[9,6.25],[9.4,20.83]],"id":28002629}],"con":true,"img":false}]}
{"op":"mcm","clk":"5346856328","pt":1646098874653,"mc":[{"id":"1.195395455","rc":[{"atb":[[1.78,23.33]],"id":43154433}],"con":true,"img":false}]}
{"op":"mcm","clk":"5346856355","pt":1646098875221,"mc":[{"id":"1.195395455","rc":[{"atb":[[3.2,34.09]],"id":42393370}],"con":true,"img":false}]}
{"op":"mcm","clk":"5346856358","pt":1646098875428,"mc":[{"id":"1.195395455","rc":[{"atb":[[18,0]],"id":37267533}],"con":true,"img":false}]}
{"op":"mcm","clk":"5346856362","pt":1646098875534,"mc":[{"id":"1.195395455","rc":[{"atb":[[20,2.7]],"id":37267533}],"con":true,"img":false}]}
{"op":"mcm","clk":"5346856406","pt":1646098876819,"mc":[{"id":"1.195395455","rc":[{"atl":[[36,0]],"id":37672294},{"atl":[[320,0]],"id":37267533},{"atl":[[310,1],[320,2.7]],"id":37455733},{"atl":[[36,0]],"id":22150928},{"atb":[[1.64,31.25]],"id":43154433}],"con":true,"img":false}]}
{"op":"mcm","clk":"5346856411","pt":1646098876919,"mc":[{"id":"1.195395455","rc":[{"atb":[[1.63,0]],"id":43154433}],"con":true,"img":false}]}
{"op":"mcm","clk":"5346856426","pt":1646098877329,"mc":[{"id":"1.195395455","rc":[{"atl":[[14.5,0]],"id":28002629}],"con":true,"img":false}]}
{"op":"mcm","clk":"5346856428","pt":1646098877433,"mc":[{"id":"1.195395455","rc":[{"atl":[[13.5,2.7]],"id":28002629}],"con":true,"img":false}]}
{"op":"mcm","clk":"5346856449","pt":1646098877945,"mc":[{"id":"1.195395455","rc":[{"atb":[[3.05,60.98]],"id":28002629}],"con":true,"img":false}]}
{"op":"mcm","clk":"5346856542","pt":1646098880257,"mc":[{"id":"1.195395455","rc":[{"atb":[[1.61,0]],"id":43154433}],"con":true,"img":false}]}
{"op":"mcm","clk":"5346856654","pt":1646098883231,"mc":[{"id":"1.195395455","rc":[{"atl":[[32,4.03]],"id":37672294},{"atl":[[32,6.45]],"id":22150928}],"con":true,"img":false}]}
{"op":"mcm","clk":"5346856657","pt":1646098883334,"mc":[{"id":"1.195395455","rc":[{"atl":[[32,4.03]],"id":22150928}],"con":true,"img":false}]}
{"op":"mcm","clk":"5346856715","pt":1646098885237,"mc":[{"id":"1.195395455","rc":[{"atb":[[3.1,59.52]],"id":42393370}],"con":true,"img":false}]}
{"op":"mcm","clk":"5346856783","pt":1646098886833,"mc":[{"id":"1.195395455","rc":[{"atl":[[330,3]],"id":37455733},{"atb":[[1.62,80.65]],"id":43154433}],"con":true,"img":false}]}
{"op":"mcm","clk":"5346856805","pt":1646098887346,"mc":[{"id":"1.195395455","rc":[{"atb":[[3.35,22.73]],"id":42393370},{"atl":[[8.6,5.69],[11,0]],"id":42393370},{"atl":[[200,0]],"id":37455733},{"atb":[[1.66,0]],"id":43154433},{"atl":[[3.1,0]],"id":43154433}],"con":true,"img":false}]}
{"op":"mcm","clk":"5346856811","pt":1646098887448,"mc":[{"id":"1.195395455","rc":[{"atb":[[3.45,21.85]],"id":42393370},{"atl":[[190,0.2]],"id":37455733},{"atb":[[1.68,43.26]],"id":43154433},{"atl":[[3.15,77.8]],"id":43154433}],"con":true,"img":false}]}
{"op":"mcm","clk":"5346857001","pt":1646098892475,"mc":[{"id":"1.195395455","rc":[{"atl":[[390,0]],"id":37455733},{"atb":[[1.54,0]],"id":43154433}],"con":true,"img":false}]}
{"op":"mcm","clk":"5346857139","pt":1646098895758,"mc":[{"id":"1.195395455","rc":[{"atb":[[3.4,12.16]],"id":42393370}],"con":true,"img":false}]}
{"op":"mcm","clk":"5346857176","pt":1646098896837,"mc":[{"id":"1.195395455","rc":[{"atb":[[1.6,125]],"id":43154433}],"con":true,"img":false}]}
{"op":"mcm","clk":"5346857193","pt":1646098897346,"mc":[{"id":"1.195395455","rc":[{"atl":[[46,0]],"id":37672294},{"atl":[[46,0]],"id":22150928}],"con":true,"img":false}]}
{"op":"mcm","clk":"5346857196","pt":1646098897448,"mc":[{"id":"1.195395455","rc":[{"atl":[[42,2.7]],"id":37672294},{"atl":[[44,2.7]],"id":22150928}],"con":true,"img":false}]}
{"op":"mcm","clk":"5346857406","pt":1646098902586,"mc":[{"id":"1.195395455","rc":[{"atb":[[3.4,8.33]],"id":42393370}],"con":true,"img":false}]}
{"op":"mcm","clk":"5346857431","pt":1646098903259,"mc":[{"id":"1.195395455","rc":[{"atl":[[8.2,2.78],[8.4,0]],"id":28002629},{"atl":[[240,2]],"id":37267533},{"atb":[[1.56,0]],"id":43154433}],"con":true,"img":false}]}
{"op":"mcm","clk":"5346857435","pt":1646098903363,"mc":[{"id":"1.195395455","rc":[{"atl":[[9,18.75]],"id":28002629}],"con":true,"img":false}]}
{"op":"mcm","clk":"5346857438","pt":1646098903459,"mc":[{"id":"1.195395455","rc":[{"atl":[[9.4,8.93]],"id":28002629}],"con":true,"img":false}]}
{"op":"mcm","clk":"5346857441","pt":1646098903563,"mc":[{"id":"1.195395455","rc":[{"atl":[[9,6.25],[9.4,20.83]],"id":28002629}],"con":true,"img":false}]}
{"op":"mcm","clk":"5346857446","pt":1646098903774,"mc":[{"id":"1.195395455","rc":[{"atb":[[3.35,7.75],[3.3,71.98]],"id":28002629},{"atl":[[3,10],[2.94,0]],"id":43154433}],"con":true,"img":false}]}
{"op":"mcm","clk":"5346857487","pt":1646098904796,"mc":[{"id":"1.195395455","rc":[{"atb":[[3.5,3.6]],"id":42393370}],"con":true,"img":false}]}
{"op":"mcm","clk":"5346857489","pt":1646098904897,"mc":[{"id":"1.195395455","rc":[{"atl":[[2.98,0]],"id":43154433}],"con":true,"img":false}]}
{"op":"mcm","clk":"5346857614","pt":1646098908486,"mc":[{"id":"1.195395455","rc":[{"atb":[[3.25,4.07]],"id":42393370}],"con":true,"img":false}]}
{"op":"mcm","clk":"5346857775","pt":1646098913277,"mc":[{"id":"1.195395455","rc":[{"atl":[[320,1]],"id":37267533}],"con":true,"img":false}]}
{"op":"mcm","clk":"5346857787","pt":1646098913791,"mc":[{"id":"1.195395455","rc":[{"atb":[[3.2,22.73]],"id":28002629},{"atl":[[8.6,6.58]],"id":28002629},{"atb":[[1.58,215.52]],"id":43154433},{"atl":[[3.1,23.81]],"id":43154433}],"con":true,"img":false}]}
{"op":"mcm","clk":"5346857788","pt":1646098913893,"mc":[{"id":"1.195395455","rc":[{"atl":[[9,18.75],[9.4,8.93]],"id":28002629}],"con":true,"img":false}]}
{"op":"mcm","clk":"5346857858","pt":1646098916098,"mc":[{"id":"1.195395455","rc":[{"atl":[[3,0],[3.05,9.76]],"id":43154433}],"con":true,"img":false}]}
{"op":"mcm","clk":"5346857864","pt":1646098916202,"mc":[{"id":"1.195395455","rc":[{"atb":[[3.25,0],[3.15,0],[3.05,0]],"id":28002629},{"atl":[[9.8,0]],"id":28002629}],"con":true,"img":false}]}
{"op":"mcm","clk":"5346857903","pt":1646098917282,"mc":[{"id":"1.195395455","rc":[{"atb":[[3.45,0]],"id":42393370},{"atl":[[320,0]],"id":37455733},{"atb":[[1.68,0]],"id":43154433}],"con":true,"img":false}]}
{"op":"mcm","clk":"5346857906","pt":1646098917385,"mc":[{"id":"1.195395455","rc":[{"atb":[[3.4,30.18]],"id":42393370},{"atl":[[300,2.7]],"id":37455733},{"atb":[[1.71,45.26]],"id":43154433}],"con":true,"img":false}]}
{"op":"mcm","clk":"5346857912","pt":1646098917486,"mc":[{"id":"1.195395455","rc":[{"atl":[[300,4.7]],"id":37455733}],"con":true,"img":false}]}
{"op":"mcm","clk":"5346857916","pt":1646098917588,"mc":[{"id":"1.195395455","rc":[{"atl":[[330,1]],"id":37455733}],"con":true,"img":false}]}
{"op":"mcm","clk":"5346858136","pt":1646098923804,"mc":[{"id":"1.195395455","rc":[{"atb":[[3.1,35.71]],"id":28002629},{"atl":[[9,21.88]],"id":28002629}],"con":true,"img":false}]}
{"op":"mcm","clk":"5346858158","pt":1646098924314,"mc":[{"id":"1.195395455","rc":[{"atl":[[300,5.7]],"id":37455733}],"con":true,"img":false}]}
{"op":"mcm","clk":"5346858162","pt":1646098924417,"mc":[{"id":"1.195395455","rc":[{"atl":[[260,0]],"id":37267533},{"atl":[[310,0]],"id":37455733}],"con":true,"img":false}]}
{"op":"mcm","clk":"5346858211","pt":1646098925803,"mc":[{"id":"1.195395455","rc":[{"atb":[[3.5,0]],"id":42393370}],"con":true,"img":false}]}
{"op":"mcm","clk":"5346858229","pt":1646098926112,"mc":[{"id":"1.195395455","rc":[{"atl":[[3.15,42.92]],"id":43154433}],"con":true,"img":false}]}
{"op":"mcm","clk":"5346858275","pt":1646098927292,"mc":[{"id":"1.195395455","rc":[{"atb":[[3.3,8.7]],"id":28002629},{"atl":[[130,0]],"id":22150928}],"con":true,"img":false}]}
{"op":"mcm","clk":"5346858279","pt":1646098927394,"mc":[{"id":"1.195395455","rc":[{"atb":[[3.25,63.28]],"id":28002629},{"atl":[[90,2.7]],"id":22150928}],"con":true,"img":false}]}
{"op":"mcm","clk":"5346858317","pt":1646098928415,"mc":[{"id":"1.195395455","rc":[{"spn":6.2,"spf":1.0,"id":28002629},{"atl":[[280,0]],"id":37267533},{"spn":2.41,"spf":1.0,"id":43154433}],"con":true,"img":false}]}
{"op":"mcm","clk":"5346858467","pt":1646098932616,"mc":[{"id":"1.195395455","rc":[{"atb":[[3.25,0]],"id":42393370}],"con":true,"img":false}]}
{"op":"mcm","clk":"5346858499","pt":1646098933797,"mc":[{"id":"1.195395455","rc":[{"atb":[[3,62.5]],"id":28002629},{"atl":[[9.4,14.88]],"id":28002629}],"con":true,"img":false}]}
{"op":"mcm","clk":"5346858515","pt":1646098934310,"mc":[{"id":"1.195395455","rc":[{"atl":[[340,1]],"id":37267533}],"con":true,"img":false}]}
{"op":"mcm","clk":"5346858531","pt":1646098934819,"mc":[{"id":"1.195395455","rc":[{"atb":[[3.35,3.91]],"id":28002629},{"atb":[[3.45,3.68]],"id":42393370}],"con":true,"img":false}]}
{"op":"mcm","clk":"5346858584","pt":1646098936108,"mc":[{"id":"1.195395455","rc":[{"atl":[[3.25,33.33]],"id":43154433}],"con":true,"img":false}]}
{"op":"mcm","clk":"5346858690","pt":1646098938622,"mc":[{"id":"1.195395455","rc":[{"atb":[[3.45,7.43]],"id":42393370}],"con":true,"img":false}]}
{"op":"mcm","clk":"5346858890","pt":1646098943812,"mc":[{"id":"1.195395455","rc":[{"atb":[[3.3,12.61]],"id":28002629}],"con":true,"img":false}]}
{"op":"mcm","clk":"5346858908","pt":1646098944326,"mc":[{"id":"1.195395455","rc":[{"atl":[[360,1]],"id":37267533}],"con":true,"img":false}]}
{"op":"mcm","clk":"5346858925","pt":1646098944735,"mc":[{"id":"1.195395455","rc":[{"atb":[[3.35,0]],"id":28002629}],"con":true,"img":false}]}
{"op":"mcm","clk":"5346858984","pt":1646098946121,"mc":[{"id":"1.195395455","rc":[{"atl":[[3.35,53.19]],"id":43154433}],"con":true,"img":false}]}
{"op":"mcm","clk":"5346859177","pt":1646098950942,"mc":[{"id":"1.195395455","rc":[{"atb":[[3.3,16.61]],"id":28002629}],"con":true,"img":false}]}
{"op":"mcm","clk":"5346859324","pt":1646098954230,"mc":[{"id":"1.195395455","rc":[{"atl":[[3.1,0]],"id":43154433}],"con":true,"img":false}]}
{"op":"mcm","clk":"5346859446","pt":1646098957410,"mc":[{"id":"1.195395455","rc":[{"atl":[[300,3]],"id":37455733}],"con":true,"img":false}]}
{"op":"mcm","clk":"5346859450","pt":1646098957515,"mc":[{"id":"1.195395455","rc":[{"atl":[[290,2.7]],"id":37455733}],"con":true,"img":false}]}
{"op":"mcm","clk":"5346860106","pt":1646098972459,"mc":[{"id":"1.195395455","rc":[{"atb":[[3.15,9.3],[3.3,7.91]],"id":28002629},{"atb":[[6.8,0],[7.8,14.71]],"id":37267533},{"atl":[[3.1,9.52],[3.05,0]],"id":43154433}],"con":true,"img":false}]}
{"op":"mcm","clk":"5346860364","pt":1646098978771,"mc":[{"id":"1.195395455","rc":[{"atb":[[3.2,0]],"id":28002629}],"con":true,"img":false}]}
{"op":"mcm","clk":"5346860442","pt":1646098980468,"mc":[{"id":"1.195395455","rc":[{"atb":[[13,13.52],[18,7.16],[21,4.05],[26,1.62]],"id":37267533},{"atl":[[300,1.66],[350,0.56],[200,0.66],[250,0.53]],"id":37267533},{"atb":[[6.4,30.05],[11,4.05],[8.4,21.47],[9.4,9.65]],"id":22150928},{"atl":[[80,1.67],[160,1.24],[55,2.45],[110,1.81]],"id":22150928}],"con":true,"img":false}]}
{"op":"mcm","clk":"5346860451","pt":1646098980672,"mc":[{"id":"1.195395455","rc":[{"atl":[[220,2],[240,0]],"id":37267533}],"con":true,"img":false}]}
{"op":"mcm","clk":"5346860493","pt":1646098981753,"mc":[{"id":"1.195395455","rc":[{"atb":[[4.2,0]],"id":28002629}],"con":true,"img":false}]}
{"op":"mcm","clk":"5346860498","pt":1646098981857,"mc":[{"id":"1.195395455","rc":[{"atb":[[4.3,2]],"id":28002629}],"con":true,"img":false}]}
{"op":"mcm","clk":"5346860520","pt":1646098982471,"mc":[{"id":"1.195395455","rc":[{"atb":[[3.05,24.39]],"id":28002629},{"atl":[[3.2,82.81]],"id":43154433}],"con":true,"img":false}]}
{"op":"mcm","clk":"5346860667","pt":1646098985766,"mc":[{"id":"1.195395455","rc":[{"atl":[[24,1],[25,0]],"id":37672294},{"atb":[[11.5,0]],"id":22150928},{"atl":[[25,0]],"id":22150928},{"atl":[[3.35,0],[3.25,0],[3.15,19.66]],"id":43154433}],"con":true,"img":false}]}
{"op":"mcm","clk":"5346860671","pt":1646098985871,"mc":[{"id":"1.195395455","rc":[{"atb":[[12,0.92]],"id":22150928}],"con":true,"img":false}]}
{"op":"mcm","clk":"5346860749","pt":1646098987353,"mc":[{"id":"1.195395455","rc":[{"atb":[[3.25,0]],"id":28002629}],"con":true,"img":false}]}
{"op":"mcm","clk":"5346860755","pt":1646098987455,"mc":[{"id":"1.195395455","rc":[{"atb":[[3.2,63.28]],"id":28002629}],"con":true,"img":false}]}
{"op":"mcm","clk":"5346860817","pt":1646098988687,"mc":[{"id":"1.195395455","rc":[{"spn":17.25,"spf":1.0,"id":37672294},{"spn":6.25,"spf":1.0,"id":28002629},{"spn":63.0,"spf":1.0,"id":37267533},{"atl":[[32,2.42]],"id":22150928},{"spn":19.5,"spf":1.0,"id":22150928},{"spn":2.44,"spf":1.0,"id":43154433}],"con":true,"img":false}]}
{"op":"mcm","clk":"5346860899","pt":1646098990687,"mc":[{"id":"1.195395455","rc":[{"atb":[[8.4,0],[9.4,10.95]],"id":37267533},{"atb":[[5.1,0],[5.3,0]],"id":37455733}],"con":true,"img":false}]}
{"op":"mcm","clk":"5346860905","pt":1646098990740,"mc":[{"id":"1.195395455","rc":[{"atl":[[7.2,3.23],[7.6,0]],"id":42393370},{"atb":[[5.1,4.88]],"id":37455733},{"atb":[[8,2.86],[7,0]],"id":22150928}],"con":true,"img":false}]}
{"op":"mcm","clk":"5346860987","pt":1646098992485,"mc":[{"id":"1.195395455","rc":[{"atb":[[2.98,37.88]],"id":28002629},{"atl":[[3.3,32.61]],"id":43154433}],"con":true,"img":false}]}
{"op":"mcm","clk":"5346861089","pt":1646098994855,"mc":[{"id":"1.195395455","rc":[{"atb":[[3.3,3.99]],"id":28002629}],"con":true,"img":false}]}
{"op":"mcm","clk":"5346861181","pt":1646098997367,"mc":[{"id":"1.195395455","rc":[{"atb":[[3.2,0]],"id":28002629}],"con":true,"img":false}]}
{"op":"mcm","clk":"5346861185","pt":1646098997471,"mc":[{"id":"1.195395455","rc":[{"atb":[[3.15,72.58]],"id":28002629}],"con":true,"img":false}]}
{"op":"mcm","clk":"5346861334","pt":1646099000661,"mc":[{"id":"1.195395455","rc":[{"atl":[[7.6,7.58]],"id":42393370},{"atb":[[9,6.25]],"id":37267533},{"atb":[[4.9,12.82]],"id":37455733},{"atb":[[7.6,7.58]],"id":22150928},{"atl":[[36,3.57]],"id":22150928}],"con":true,"img":false}]}
{"op":"mcm","clk":"5346861378","pt":1646099001759,"mc":[{"id":"1.195395455","rc":[{"atb":[[3.3,0]],"id":28002629}],"con":true,"img":false}]}
{"op":"mcm","clk":"5346861405","pt":1646099002374,"mc":[{"id":"1.195395455","rc":[{"atb":[[3.1,0],[3,0]],"id":28002629},{"atl":[[8.8,0]],"id":42393370},{"atb":[[8,0],[7.2,0],[7.6,0]],"id":37267533},{"atb":[[5.9,0],[6.2,0],[6.6,0]],"id":22150928}],"con":true,"img":false}]}
{"op":"mcm","clk":"5346861408","pt":1646099002481,"mc":[{"id":"1.195395455","rc":[{"atb":[[2.94,64.43]],"id":28002629},{"atl":[[3.4,52.08]],"id":43154433}],"con":true,"img":false}]}
{"op":"mcm","clk":"5346861604","pt":1646099007363,"mc":[{"id":"1.195395455","rc":[{"atb":[[3.15,9.3]],"id":28002629},{"atl":[[8.6,0]],"id":42393370},{"atl":[[160,0]],"id":37267533}],"con":true,"img":false}]}
{"op":"mcm","clk":"5346861606","pt":1646099007466,"mc":[{"id":"1.195395455","rc":[{"atb":[[3.1,63.28]],"id":28002629},{"atl":[[11.5,5.69]],"id":42393370},{"atl":[[150,0.25]],"id":37267533}],"con":true,"img":false}]}
{"op":"mcm","clk":"5346861717","pt":1646099010699,"mc":[{"id":"1.195395455","rc":[{"atl":[[8,10.71]],"id":42393370},{"atb":[[8.6,9.87]],"id":37267533},{"atb":[[4.7,20.27]],"id":37455733},{"atb":[[7.2,12.1]],"id":22150928}],"con":true,"img":false}]}
{"op":"mcm","clk":"5346862001","pt":1646099017373,"mc":[{"id":"1.195395455","rc":[{"atl":[[230,0]],"id":37267533}],"con":true,"img":false}]}
{"op":"mcm","clk":"5346862004","pt":1646099017477,"mc":[{"id":"1.195395455","rc":[{"atl":[[210,2.7]],"id":37267533}],"con":true,"img":false}]}
{"op":"mcm","clk":"5346862009","pt":1646099017581,"mc":[{"id":"1.195395455","rc":[{"atl":[[200,2.66]],"id":37267533}],"con":true,"img":false}]}
{"op":"mcm","clk":"5346862012","pt":1646099017682,"mc":[{"id":"1.195395455","rc":[{"atl":[[220,0]],"id":37267533}],"con":true,"img":false}]}
{"op":"mcm","clk":"5346862016","pt":1646099017886,"mc":[{"id":"1.195395455","rc":[{"atb":[[12,0]],"id":22150928}],"con":true,"img":false}]}
{"op":"mcm","clk":"5346862018","pt":1646099017989,"mc":[{"id":"1.195395455","rc":[{"atb":[[12.5,0.88]],"id":22150928}],"con":true,"img":false}]}
{"op":"mcm","clk":"5346862038","pt":1646099018912,"mc":[{"id":"1.195395455","rc":[{"atl":[[7.8,2.3]],"id":42393370},{"atl":[[3.15,25.38]],"id":43154433}],"con":true,"img":false}]}
{"op":"mcm","clk":"5346862069","pt":1646099019785,"mc":[{"id":"1.195395455","rc":[{"atl":[[3.15,31.21]],"id":43154433}],"con":true,"img":false}]}
{"op":"mcm","clk":"5346862077","pt":1646099020092,"mc":[{"id":"1.195395455","rc":[{"atl":[[7.8,4.66]],"id":42393370}],"con":true,"img":false}]}
{"op":"mcm","clk":"5346862106","pt":1646099020712,"mc":[{"id":"1.195395455","rc":[{"atl":[[8.4,16.89]],"id":42393370},{"atb":[[8.2,17.36]],"id":37267533},{"atb":[[6.8,47.51]],"id":22150928}],"con":true,"img":false}]}
{"op":"mcm","clk":"5346862110","pt":1646099020815,"mc":[{"id":"1.195395455","rc":[{"atb":[[4.5,35.71]],"id":37455733}],"con":true,"img":false}]}
{"op":"mcm","clk":"5346862152","pt":1646099021487,"mc":[{"id":"1.195395455","rc":[{"atb":[[2.36,0],[2.18,75.76],[3.15,0],[2.94,10.31]],"id":28002629},{"atb":[[3.35,0],[3.4,52.91]],"id":42393370},{"atl":[[3.1,0],[3.25,8.89],[3.5,0],[3.95,101.11]],"id":43154433}],"con":true,"img":false}]}
{"op":"mcm","clk":"5346862171","pt":1646099021795,"mc":[{"id":"1.195395455","rc":[{"atb":[[2.96,10.2],[3.05,0]],"id":28002629},{"atl":[[3.2,60.08]],"id":43154433}],"con":true,"img":false}]}
{"op":"mcm","clk":"5346862241","pt":1646099023593,"mc":[{"id":"1.195395455","rc":[{"atb":[[2.98,0]],"id":28002629},{"atl":[[90,0]],"id":22150928}],"con":true,"img":false}]}
{"op":"mcm","clk":"5346862245","pt":1646099023696,"mc":[{"id":"1.195395455","rc":[{"atl":[[60,2.7]],"id":22150928}],"con":true,"img":false}]}
{"op":"mcm","clk":"5346862305","pt":1646099024978,"mc":[{"id":"1.195395455","rc":[{"atb":[[3.15,4.19]],"id":28002629}],"con":true,"img":false}]}
{"op":"mcm","clk":"5346862337","pt":1646099025698,"mc":[{"id":"1.195395455","rc":[{"atb":[[3.15,8.47]],"id":28002629}],"con":true,"img":false}]}
{"op":"mcm","clk":"5346862406","pt":1646099027292,"mc":[{"id":"1.195395455","rc":[{"atb":[[3.1,0]],"id":28002629},{"atb":[[18.5,7.03]],"id":37267533}],"con":true,"img":false}]}
{"op":"mcm","clk":"5346862410","pt":1646099027392,"mc":[{"id":"1.195395455","rc":[{"atb":[[2.98,63.28]],"id":28002629},{"atb":[[11,0]],"id":37267533}],"con":true,"img":false}]}
{"op":"mcm","clk":"5346862573","pt":1646099031496,"mc":[{"id":"1.195395455","rc":[{"atl":[[3.35,21.28]],"id":43154433}],"con":true,"img":false}]}
{"op":"mcm","clk":"5346862586","pt":1646099031806,"mc":[{"id":"1.195395455","rc":[{"atb":[[2.92,26.04]],"id":28002629}],"con":true,"img":false}]}
{"op":"mcm","clk":"5346862683","pt":1646099034013,"mc":[{"id":"1.195395455","rc":[{"atb":[[3.15,4.27]],"id":28002629}],"con":true,"img":false}]}
{"op":"mcm","clk":"5346862792","pt":1646099036687,"mc":[{"id":"1.195395455","rc":[{"atb":[[20,0]],"id":37267533}],"con":true,"img":false}]}
{"op":"mcm","clk":"5346862799","pt":1646099036841,"mc":[{"id":"1.195395455","rc":[{"atb":[[22,3.19]],"id":37267533}],"con":true,"img":false}]}
{"op":"mcm","clk":"5346862823","pt":1646099037304,"mc":[{"id":"1.195395455","rc":[{"atb":[[2.98,0]],"id":28002629}],"con":true,"img":false}]}
{"op":"mcm","clk":"5346862826","pt":1646099037408,"mc":[{"id":"1.195395455","rc":[{"atb":[[2.96,73.48]],"id":28002629}],"con":true,"img":false}]}
{"op":"mcm","clk":"5346862836","pt":1646099037720,"mc":[{"id":"1.195395455","rc":[{"atb":[[2.28,75.76],[2.18,0]],"id":28002629},{"atl":[[7.2,0],[7.8,7.6]],"id":42393370},{"atb":[[10,2.22],[9.4,8.57]],"id":37267533},{"atb":[[5.1,0],[5.5,4.44]],"id":37455733},{"atb":[[8,0],[8.6,2.63]],"id":22150928},{"atl":[[3.25,0],[3.3,8.7]],"id":43154433}],"con":true,"img":false}]}
{"op":"mcm","clk":"5346862857","pt":1646099038338,"mc":[{"id":"1.195395455","rc":[{"atl":[[7.6,0]],"id":42393370}],"con":true,"img":false}]}
{"op":"mcm","clk":"5346862970","pt":1646099041825,"mc":[{"id":"1.195395455","rc":[{"atb":[[2.88,39.89]],"id":28002629}],"con":true,"img":false}]}
{"op":"mcm","clk":"5346863045","pt":1646099043831,"mc":[{"id":"1.195395455","rc":[{"atb":[[3.15,0]],"id":28002629}],"con":true,"img":false}]}
{"op":"mcm","clk":"5346863198","pt":1646099047742,"mc":[{"id":"1.195395455","rc":[{"atl":[[8.2,6.94]],"id":42393370},{"atb":[[9.6,5.81]],"id":37267533},{"atb":[[5.3,11.63]],"id":37455733},{"atb":[[8.2,6.94]],"id":22150928},{"atl":[[3.4,20.83]],"id":43154433}],"con":true,"img":false}]}
{"op":"mcm","clk":"5346863307","pt":1646099050254,"mc":[{"id":"1.195395455","rc":[{"spn":5.72,"spf":1.0,"id":42393370},{"atb":[[9,0],[8.2,0],[8.6,0]],"id":37267533},{"atb":[[4.5,0]],"id":37455733},{"atb":[[6.8,25.96],[7.2,0],[7.6,0]],"id":22150928},{"spn":19.75,"spf":1.0,"id":22150928},{"spn":2.46,"spf":1.0,"id":43154433}],"con":true,"img":false}]}
{"op":"mcm","clk":"5346863377","pt":1646099051844,"mc":[{"id":"1.195395455","rc":[{"atb":[[2.84,67.93]],"id":28002629}],"con":true,"img":false}]}
{"op":"mcm","clk":"5346863550","pt":1646099055737,"mc":[{"id":"1.195395455","rc":[{"atb":[[3,4.59]],"id":28002629}],"con":true,"img":false}]}
{"op":"mcm","clk":"5346863627","pt":1646099057324,"mc":[{"id":"1.195395455","rc":[{"atl":[[11.5,0]],"id":42393370}],"con":true,"img":false}]}
{"op":"mcm","clk":"5346863631","pt":1646099057426,"mc":[{"id":"1.195395455","rc":[{"atl":[[10.5,5.69]],"id":42393370}],"con":true,"img":false}]}
{"op":"mcm","clk":"5346863646","pt":1646099057731,"mc":[{"id":"1.195395455","rc":[{"atl":[[8.6,9.87]],"id":42393370},{"atb":[[9.2,9.15]],"id":37267533},{"atb":[[5.1,18.29]],"id":37455733},{"atb":[[7.8,11.03]],"id":22150928},{"atl":[[3.5,30]],"id":43154433}],"con":true,"img":false}]}
{"op":"mcm","clk":"5346863657","pt":1646099058041,"mc":[{"id":"1.195395455","rc":[{"atb":[[3,9.1]],"id":28002629}],"con":true,"img":false}]}
{"op":"mcm","clk":"5346863814","pt":1646099061844,"mc":[{"id":"1.195395455","rc":[{"atb":[[2.94,0]],"id":28002629}],"con":true,"img":false}]}
{"op":"mcm","clk":"5346863849","pt":1646099062792,"mc":[{"id":"1.195395455","rc":[{"atl":[[8,0],[8.4,0]],"id":42393370},{"atb":[[4.7,0]],"id":37455733}],"con":true,"img":false}]}
{"op":"mcm","clk":"5346864061","pt":1646099067337,"mc":[{"id":"1.195395455","rc":[{"atl":[[210,0]],"id":37267533}],"con":true,"img":false}]}
{"op":"mcm","clk":"5346864065","pt":1646099067437,"mc":[{"id":"1.195395455","rc":[{"atl":[[190,2.7],[200,0.66],[250,2.53]],"id":37267533}],"con":true,"img":false}]}
{"op":"mcm","clk":"5346864082","pt":1646099067747,"mc":[{"id":"1.195395455","rc":[{"atl":[[9,15.62]],"id":42393370},{"atb":[[8.8,16.03]],"id":37267533},{"atb":[[4.9,32.05]],"id":37455733},{"atb":[[7.4,19.53]],"id":22150928},{"atl":[[3.6,48.08]],"id":43154433}],"con":true,"img":false}]}
{"op":"mcm","clk":"5346864376","pt":1646099074066,"mc":[{"id":"1.195395455","rc":[{"atl":[[3.35,0]],"id":43154433}],"con":true,"img":false}]}
{"op":"mcm","clk":"5346864511","pt":1646099077455,"mc":[{"id":"1.195395455","rc":[{"atl":[[190,0]],"id":37267533}],"con":true,"img":false}]}
{"op":"mcm","clk":"5346864515","pt":1646099077557,"mc":[{"id":"1.195395455","rc":[{"atl":[[240,2.7]],"id":37267533}],"con":true,"img":false}]}
{"op":"mcm","clk":"5346864631","pt":1646099080280,"mc":[{"id":"1.195395455","rc":[{"atl":[[230,2],[250,0.53]],"id":37267533}],"con":true,"img":false}]}
{"op":"mcm","clk":"5346865375","pt":1646099097375,"mc":[{"id":"1.195395455","rc":[{"atb":[[2.96,10.2]],"id":28002629}],"con":true,"img":false}]}
{"op":"mcm","clk":"5346865380","pt":1646099097478,"mc":[{"id":"1.195395455","rc":[{"atb":[[2.98,63.28]],"id":28002629}],"con":true,"img":false}]}
{"op":"mcm","clk":"5346865813","pt":1646099107292,"mc":[{"id":"1.195395455","rc":[{"atl":[[10.5,0]],"id":42393370},{"atb":[[8,18.38]],"id":22150928}],"con":true,"img":false}]}
{"op":"mcm","clk":"5346865818","pt":1646099107393,"mc":[{"id":"1.195395455","rc":[{"atl":[[8.8,5.69]],"id":42393370},{"atb":[[6.8,0]],"id":22150928}],"con":true,"img":false}]}
{"op":"mcm","clk":"5346866279","pt":1646099117306,"mc":[{"id":"1.195395455","rc":[{"atl":[[240,0]],"id":37267533},{"atl":[[3.15,11.55]],"id":43154433}],"con":true,"img":false}]}
{"op":"mcm","clk":"5346866284","pt":1646099117409,"mc":[{"id":"1.195395455","rc":[{"atl":[[220,2.7]],"id":37267533},{"atl":[[3.35,19.66]],"id":43154433}],"con":true,"img":false}]}
{"op":"mcm","clk":"5346866288","pt":1646099117511,"mc":[{"id":"1.195395455","rc":[{"atl":[[210,2],[230,0]],"id":37267533}],"con":true,"img":false}]}
{"op":"mcm","clk":"5346867000","pt":1646099136245,"mc":[{"id":"1.195395455","rc":[{"atl":[[3.15,5.83]],"id":43154433}],"con":true,"img":false}]}
{"op":"mcm","clk":"5346867111","pt":1646099139215,"mc":[{"id":"1.195395455","rc":[{"atl":[[7.8,5.29]],"id":42393370}],"con":true,"img":false}]}
{"op":"mcm","clk":"5346867131","pt":1646099140030,"mc":[{"id":"1.195395455","rc":[{"atl":[[3.15,0]],"id":43154433}],"con":true,"img":false}]}
{"op":"mcm","clk":"5346867199","pt":1646099142137,"mc":[{"id":"1.195395455","rc":[{"atl":[[3.15,5.72]],"id":43154433}],"con":true,"img":false}]}
{"op":"mcm","clk":"5346867310","pt":1646099146026,"mc":[{"id":"1.195395455","rc":[{"atl":[[7.8,2.94]],"id":42393370}],"con":true,"img":false}]}
{"op":"mcm","clk":"5346867588","pt":1646099152629,"mc":[{"id":"1.195395455","rc":[{"atl":[[3.15,11.55]],"id":43154433}],"con":true,"img":false}]}
{"op":"mcm","clk":"5346867784","pt":1646099157442,"mc":[{"id":"1.195395455","rc":[{"atl":[[220,0]],"id":37267533},{"atl":[[190,0]],"id":37455733}],"con":true,"img":false}]}
{"op":"mcm","clk":"5346867789","pt":1646099157545,"mc":[{"id":"1.195395455","rc":[{"atl":[[200,3.36]],"id":37267533},{"atl":[[180,0.2]],"id":37455733}],"con":true,"img":false}]}
{"op":"mcm","clk":"5346867793","pt":1646099157648,"mc":[{"id":"1.195395455","rc":[{"atl":[[190,2],[210,0]],"id":37267533}],"con":true,"img":false}]}
{"op":"mcm","clk":"5346867814","pt":1646099158262,"mc":[{"id":"1.195395455","rc":[{"atb":[[3.15,46.51]],"id":42393370}],"con":true,"img":false}]}
{"op":"mcm","clk":"5346867822","pt":1646099158366,"mc":[{"id":"1.195395455","rc":[{"atb":[[3.4,30.18]],"id":42393370}],"con":true,"img":false}]}
{"op":"mcm","clk":"5346868203","pt":1646099167436,"mc":[{"id":"1.195395455","rc":[{"atb":[[3.4,8.33]],"id":42393370}],"con":true,"img":false}]}
{"op":"mcm","clk":"5346868209","pt":1646099167545,"mc":[{"id":"1.195395455","rc":[{"atb":[[3.35,21.85]],"id":42393370}],"con":true,"img":false}]}
{"op":"mcm","clk":"5346868541","pt":1646099175380,"mc":[{"id":"1.195395455","rc":[{"atb":[[3.45,3.75]],"id":42393370}],"con":true,"img":false}]}
{"op":"mcm","clk":"5346868775","pt":1646099182087,"mc":[{"id":"1.195395455","rc":[{"atb":[[3.45,0]],"id":42393370}],"con":true,"img":false}]}
{"op":"mcm","clk":"5346868823","pt":1646099183266,"mc":[{"id":"1.195395455","rc":[{"atb":[[3.4,30.07],[3.15,0]],"id":42393370}],"con":true,"img":false}]}
{"op":"mcm","clk":"5346869369","pt":1646099197476,"mc":[{"id":"1.195395455","rc":[{"atl":[[200,0.66]],"id":37267533}],"con":true,"img":false}]}
{"op":"mcm","clk":"5346869373","pt":1646099197580,"mc":[{"id":"1.195395455","rc":[{"atl":[[180,2.7],[190,0],[200,2.66]],"id":37267533}],"con":true,"img":false}]}
{"op":"mcm","clk":"5346869414","pt":1646099199271,"mc":[{"id":"1.195395455","rc":[{"atb":[[3.45,3.68]],"id":42393370}],"con":true,"img":false}]}
{"op":"mcm","clk":"5346869424","pt":1646099199578,"mc":[{"id":"1.195395455","rc":[{"atb":[[26,0.17]],"id":37267533},{"trd":[[26,2.88]],"ltp":26.0,"tv":2.88,"id":37267533}],"con":true,"img":false}]}
{"op":"mcm","clk":"5346869443","pt":1646099200041,"mc":[{"id":"1.195395455","rc":[{"atb":[[3.45,7.43]],"id":42393370}],"con":true,"img":false}]}
{"op":"mcm","clk":"5346877148","pt":1646099207484,"mc":[{"id":"1.195395455","rc":[{"atb":[[3.35,0]],"id":42393370},{"atl":[[180,0]],"id":37267533}],"con":true,"img":false}]}
{"op":"mcm","clk":"5346877152","pt":1646099207580,"mc":[{"id":"1.195395455","rc":[{"atb":[[3.45,29.28]],"id":42393370},{"atl":[[190,2.7]],"id":37267533}],"con":true,"img":false}]}
{"op":"mcm","clk":"5346877156","pt":1646099207682,"mc":[{"id":"1.195395455","rc":[{"atl":[[250,2.53]],"id":37267533}],"con":true,"img":false}]}
{"op":"mcm","clk":"5346877159","pt":1646099207787,"mc":[{"id":"1.195395455","rc":[{"atl":[[200,0.66]],"id":37267533}],"con":true,"img":false}]}
{"op":"mcm","clk":"5346877360","pt":1646099214595,"mc":[{"id":"1.195395455","rc":[{"atb":[[3.45,25.6]],"id":42393370}],"con":true,"img":false}]}
{"op":"mcm","clk":"5346877447","pt":1646099217465,"mc":[{"id":"1.195395455","rc":[{"atl":[[190,0]],"id":37267533}],"con":true,"img":false}]}
{"op":"mcm","clk":"5346877451","pt":1646099217567,"mc":[{"id":"1.195395455","rc":[{"atl":[[240,2.7]],"id":37267533}],"con":true,"img":false}]}
{"op":"mcm","clk":"5346877501","pt":1646099219207,"mc":[{"id":"1.195395455","rc":[{"atl":[[230,2],[250,0.53]],"id":37267533}],"con":true,"img":false}]}
{"op":"mcm","clk":"5346877622","pt":1646099223414,"mc":[{"id":"1.195395455","rc":[{"atb":[[3.5,3.6]],"id":42393370}],"con":true,"img":false}]}
{"op":"mcm","clk":"5346877755","pt":1646099227672,"mc":[{"id":"1.195395455","rc":[{"atb":[[3.45,33.76],[3.4,21.74]],"id":42393370},{"atl":[[290,1]],"id":37267533},{"atl":[[290,3.7]],"id":37455733}],"con":true,"img":false}]}
{"op":"mcm","clk":"5346877762","pt":1646099227774,"mc":[{"id":"1.195395455","rc":[{"atl":[[300,0.66]],"id":37267533},{"atl":[[280,2],[300,0]],"id":37455733}],"con":true,"img":false}]}
{"op":"mcm","clk":"5346877857","pt":1646099230595,"mc":[{"id":"1.195395455","rc":[{"atb":[[3.45,30.01]],"id":42393370}],"con":true,"img":false}]}
{"op":"mcm","clk":"5346878109","pt":1646099237730,"mc":[{"id":"1.195395455","rc":[{"atl":[[310,1]],"id":37455733}],"con":true,"img":false}]}
{"op":"mcm","clk":"5346878240","pt":1646099242102,"mc":[{"id":"1.195395455","rc":[{"atb":[[3.5,7.28]],"id":42393370}],"con":true,"img":false}]}
{"op":"mcm","clk":"5346878282","pt":1646099243332,"mc":[{"id":"1.195395455","rc":[{"atl":[[370,0]],"id":37455733}],"con":true,"img":false}]}
{"op":"mcm","clk":"5346878735","pt":1646099257427,"mc":[{"id":"1.195395455","rc":[{"atl":[[240,0]],"id":37267533},{"atb":[[8.4,16.44]],"id":22150928}],"con":true,"img":false}]}
{"op":"mcm","clk":"5346878740","pt":1646099257529,"mc":[{"id":"1.195395455","rc":[{"atl":[[220,2.7]],"id":37267533},{"atb":[[9.6,5.03]],"id":22150928}],"con":true,"img":false}]}
{"op":"mcm","clk":"5346878746","pt":1646099257632,"mc":[{"id":"1.195395455","rc":[{"atl":[[210,2],[230,0]],"id":37267533}],"con":true,"img":false}]}
{"op":"mcm","clk":"5346878810","pt":1646099259529,"mc":[{"id":"1.195395455","rc":[{"atl":[[3.15,5.83]],"id":43154433}],"con":true,"img":false}]}
{"op":"mcm","clk":"5346878926","pt":1646099262466,"mc":[{"id":"1.195395455","rc":[{"atl":[[3.15,11.55]],"id":43154433}],"con":true,"img":false}]}
{"op":"mcm","clk":"5346879103","pt":1646099267471,"mc":[{"id":"1.195395455","rc":[{"atl":[[290,1]],"id":37455733}],"con":true,"img":false}]}
{"op":"mcm","clk":"5346879106","pt":1646099267524,"mc":[{"id":"1.195395455","rc":[{"atl":[[270,2.7]],"id":37455733}],"con":true,"img":false}]}
{"op":"mcm","clk":"5346879274","pt":1646099272350,"mc":[{"id":"1.195395455","rc":[{"atl":[[3.15,5.72]],"id":43154433}],"con":true,"img":false}]}
{"op":"mcm","clk":"5346879486","pt":1646099278242,"mc":[{"id":"1.195395455","rc":[{"atl":[[3.15,11.55]],"id":43154433}],"con":true,"img":false}]}
{"op":"mcm","clk":"5346879492","pt":1646099278344,"mc":[{"id":"1.195395455","rc":[{"atl":[[3.15,14.95]],"id":43154433}],"con":true,"img":false}]}
{"op":"mcm","clk":"5346879567","pt":1646099280142,"mc":[{"id":"1.195395455","rc":[{"atl":[[8.2,0],[8.4,2.7]],"id":28002629}],"con":true,"img":false}]}
{"op":"mcm","clk":"5346879572","pt":1646099280244,"mc":[{"id":"1.195395455","rc":[{"atl":[[8.6,19.74],[9,9.38]],"id":28002629}],"con":true,"img":false}]}
{"op":"mcm","clk":"5346879576","pt":1646099280345,"mc":[{"id":"1.195395455","rc":[{"atl":[[9,21.88]],"id":28002629}],"con":true,"img":false}]}
{"op":"mcm","clk":"5346879581","pt":1646099280448,"mc":[{"id":"1.195395455","rc":[{"atl":[[8.6,6.58]],"id":28002629}],"con":true,"img":false}]}
{"op":"mcm","clk":"5346880006","pt":1646099290169,"mc":[{"id":"1.195395455","rc":[{"atl":[[8.8,6.41]],"id":28002629}],"con":true,"img":false}]}
{"op":"mcm","clk":"5346880011","pt":1646099290271,"mc":[{"id":"1.195395455","rc":[{"atl":[[8.6,13.16]],"id":28002629}],"con":true,"img":false}]}
{"op":"mcm","clk":"5346880017","pt":1646099290375,"mc":[{"id":"1.195395455","rc":[{"atl":[[9,9.38]],"id":28002629}],"con":true,"img":false}]}
{"op":"mcm","clk":"5346880084","pt":1646099291887,"mc":[{"id":"1.195395455","rc":[{"atl":[[8.6,6.58],[9,0],[9.4,0]],"id":28002629}],"con":true,"img":false}]}
{"op":"mcm","clk":"5346880236","pt":1646099295374,"mc":[{"id":"1.195395455","rc":[{"atl":[[8.6,0],[8.8,15.69]],"id":28002629}],"con":true,"img":false}]}
{"op":"mcm","clk":"5346880340","pt":1646099297481,"mc":[{"id":"1.195395455","rc":[{"atl":[[220,0]],"id":37267533}],"con":true,"img":false}]}
{"op":"mcm","clk":"5346880345","pt":1646099297583,"mc":[{"id":"1.195395455","rc":[{"atl":[[200,3.36]],"id":37267533}],"con":true,"img":false}]}
{"op":"mcm","clk":"5346880350","pt":1646099297685,"mc":[{"id":"1.195395455","rc":[{"atl":[[190,2],[210,0]],"id":37267533}],"con":true,"img":false}]}
{"op":"mcm","clk":"5346880434","pt":1646099300205,"mc":[{"id":"1.195395455","rc":[{"atl":[[9.2,9.15]],"id":28002629}],"con":true,"img":false}]}
{"op":"mcm","clk":"5346880445","pt":1646099300359,"mc":[{"id":"1.195395455","rc":[{"atl":[[9.2,21.35],[8.8,6.41]],"id":28002629}],"con":true,"img":false}]}
{"op":"mcm","clk":"5346880592","pt":1646099303807,"mc":[{"id":"1.195395455","rc":[{"spn":6.35,"spf":1.0,"id":28002629},{"atb":[[3.4,0],[3.15,46.51]],"id":42393370}],"con":true,"img":false}]}
{"op":"mcm","clk":"5346880751","pt":1646099307514,"mc":[{"id":"1.195395455","rc":[{"atb":[[3.45,8.16]],"id":42393370},{"atb":[[9.6,0]],"id":22150928}],"con":true,"img":false}]}
{"op":"mcm","clk":"5346880758","pt":1646099307615,"mc":[{"id":"1.195395455","rc":[{"atb":[[3.35,21.85]],"id":42393370},{"atb":[[8.6,7.66]],"id":22150928}],"con":true,"img":false}]}
{"op":"mcm","clk":"5346880862","pt":1646099310183,"mc":[{"id":"1.195395455","rc":[{"atl":[[9.6,14.53]],"id":28002629}],"con":true,"img":false}]}
{"op":"mcm","clk":"5346881146","pt":1646099316605,"mc":[{"id":"1.195395455","rc":[{"atb":[[3.5,3.67]],"id":42393370}],"con":true,"img":false}]}
{"op":"mcm","clk":"5346881219","pt":1646099318506,"mc":[{"id":"1.195395455","rc":[{"atb":[[3,19.1],[2.96,0]],"id":28002629},{"atb":[[3.35,43.7],[3.15,0]],"id":42393370}],"con":true,"img":false}]}
{"op":"mcm","clk":"5346881285","pt":1646099320404,"mc":[{"id":"1.195395455","rc":[{"atb":[[3.5,0]],"id":42393370}],"con":true,"img":false}]}
{"op":"mcm","clk":"5346881478","pt":1646099325501,"mc":[{"id":"1.195395455","rc":[{"atb":[[3.4,3.76]],"id":42393370}],"con":true,"img":false}]}
{"op":"mcm","clk":"5346881597","pt":1646099328630,"mc":[{"id":"1.195395455","rc":[{"atb":[[2.96,25.51]],"id":28002629}],"con":true,"img":false}]}
{"op":"mcm","clk":"5346881655","pt":1646099329712,"mc":[{"id":"1.195395455","rc":[{"atb":[[2.84,0]],"id":28002629}],"con":true,"img":false}]}
{"op":"mcm","clk":"5346881753","pt":1646099332331,"mc":[{"id":"1.195395455","rc":[{"atb":[[3.4,7.59]],"id":42393370}],"con":true,"img":false}]}
{"op":"mcm","clk":"5346881969","pt":1646099337425,"mc":[{"id":"1.195395455","rc":[{"atl":[[200,0.66]],"id":37267533}],"con":true,"img":false}]}
{"op":"mcm","clk":"5346881974","pt":1646099337525,"mc":[{"id":"1.195395455","rc":[{"atl":[[180,2.7]],"id":37267533}],"con":true,"img":false}]}
{"op":"mcm","clk":"5346881978","pt":1646099337628,"mc":[{"id":"1.195395455","rc":[{"atl":[[190,0],[200,2.66]],"id":37267533}],"con":true,"img":false}]}
{"op":"mcm","clk":"5346881985","pt":1646099337730,"mc":[{"id":"1.195395455","rc":[{"atl":[[180,4.7]],"id":37267533}],"con":true,"img":false}]}
{"op":"mcm","clk":"5346881990","pt":1646099337834,"mc":[{"id":"1.195395455","rc":[{"atl":[[200,0.66]],"id":37267533}],"con":true,"img":false}]}
{"op":"mcm","clk":"5346882028","pt":1646099338606,"mc":[{"id":"1.195395455","rc":[{"atb":[[2.92,65.1]],"id":28002629}],"con":true,"img":false}]}
{"op":"mcm","clk":"5346882034","pt":1646099338709,"mc":[{"id":"1.195395455","rc":[{"atb":[[2.92,39.06]],"id":28002629}],"con":true,"img":false}]}
{"op":"mcm","clk":"5346882162","pt":1646099341944,"mc":[{"id":"1.195395455","rc":[{"atl":[[7.2,3.23],[7.8,0]],"id":42393370},{"atb":[[5.6,4.35],[5.5,0]],"id":37455733},{"atb":[[8.4,19.14],[8.6,5.03]],"id":22150928}],"con":true,"img":false}]}
{"op":"mcm","clk":"5346882166","pt":1646099342047,"mc":[{"id":"1.195395455","rc":[{"atl":[[10.5,10.53]],"id":42393370}],"con":true,"img":false}]}
{"op":"mcm","clk":"5346882170","pt":1646099342150,"mc":[{"id":"1.195395455","rc":[{"atl":[[12,0]],"id":42393370}],"con":true,"img":false}]}
{"op":"mcm","clk":"5346882431","pt":1646099348630,"mc":[{"id":"1.195395455","rc":[{"atb":[[2.88,66.49]],"id":28002629}],"con":true,"img":false}]}
{"op":"mcm","clk":"5346882562","pt":1646099351918,"mc":[{"id":"1.195395455","rc":[{"atl":[[7.6,7.58]],"id":42393370},{"atb":[[8,25.52]],"id":22150928}],"con":true,"img":false}]}
{"op":"mcm","clk":"5346882752","pt":1646099357152,"mc":[{"id":"1.195395455","rc":[{"atl":[[8.6,0],[9,0],[8.2,0]],"id":42393370},{"atb":[[8.2,0],[7.4,0],[7.8,0]],"id":22150928}],"con":true,"img":false}]}
{"op":"mcm","clk":"5346882758","pt":1646099357358,"mc":[{"id":"1.195395455","rc":[{"atl":[[8.8,0]],"id":42393370},{"atb":[[8,7.14],[8.6,0],[6.6,23.25]],"id":22150928}],"con":true,"img":false}]}
{"op":"mcm","clk":"5346882762","pt":1646099357460,"mc":[{"id":"1.195395455","rc":[{"atl":[[11.5,5.69]],"id":42393370},{"atb":[[9.6,5.03]],"id":22150928}],"con":true,"img":false}]}
{"op":"mcm","clk":"5346882910","pt":1646099361936,"mc":[{"id":"1.195395455","rc":[{"atl":[[8,10.71]],"id":42393370},{"atb":[[7.6,11.36]],"id":22150928}],"con":true,"img":false}]}
{"op":"mcm","clk":"5346883008","pt":1646099364667,"mc":[{"id":"1.195395455","rc":[{"atl":[[7.8,2.3]],"id":42393370},{"spn":5.42,"spf":1.0,"id":42393370}],"con":true,"img":false}]}
{"op":"mcm","clk":"5346883015","pt":1646099364871,"mc":[{"id":"1.195395455","rc":[{"atl":[[70,8.2]],"id":37672294}],"con":true,"img":false}]}
{"op":"mcm","clk":"5346883020","pt":1646099364972,"mc":[{"id":"1.195395455","rc":[{"atl":[[70,8.2]],"id":22150928}],"con":true,"img":false}]}
{"op":"mcm","clk":"5346883043","pt":1646099365644,"mc":[{"id":"1.195395455","rc":[{"atl":[[7.8,4.66]],"id":42393370}],"con":true,"img":false}]}
{"op":"mcm","clk":"5346883096","pt":1646099367444,"mc":[{"id":"1.195395455","rc":[{"atb":[[2.98,0]],"id":28002629}],"con":true,"img":false}]}
{"op":"mcm","clk":"5346883100","pt":1646099367547,"mc":[{"id":"1.195395455","rc":[{"atb":[[3.05,63.28]],"id":28002629}],"con":true,"img":false}]}
{"op":"mcm","clk":"5346883249","pt":1646099371964,"mc":[{"id":"1.195395455","rc":[{"atl":[[8.4,16.89]],"id":42393370},{"atb":[[7.2,20.16]],"id":22150928}],"con":true,"img":false}]}
{"op":"mcm","clk":"5346883400","pt":1646099376794,"mc":[{"id":"1.195395455","rc":[{"atb":[[3,14.59]],"id":28002629}],"con":true,"img":false}]}
{"op":"mcm","clk":"5346883419","pt":1646099377361,"mc":[{"id":"1.195395455","rc":[{"atb":[[3.05,0]],"id":28002629},{"atl":[[180,2]],"id":37267533}],"con":true,"img":false}]}
{"op":"mcm","clk":"5346883423","pt":1646099377462,"mc":[{"id":"1.195395455","rc":[{"atb":[[2.98,63.28]],"id":28002629},{"atl":[[170,2.7],[180,0],[200,2.66]],"id":37267533}],"con":true,"img":false}]}
{"op":"mcm","clk":"5346883483","pt":1646099379771,"mc":[{"id":"1.195395455","rc":[{"atl":[[3.15,9.23]],"id":43154433}],"con":true,"img":false}]}
{"op":"mcm","clk":"5346883575","pt":1646099382650,"mc":[{"id":"1.195395455","rc":[{"atl":[[3.15,14.95]],"id":43154433}],"con":true,"img":false}]}
{"op":"mcm","clk":"5346883696","pt":1646099387277,"mc":[{"id":"1.195395455","rc":[{"atl":[[170,4.7]],"id":37267533}],"con":true,"img":false}]}
{"op":"mcm","clk":"5346883699","pt":1646099387378,"mc":[{"id":"1.195395455","rc":[{"atl":[[170,2],[180,2],[200,0.66]],"id":37267533}],"con":true,"img":false}]}
{"op":"mcm","clk":"5346883702","pt":1646099387481,"mc":[{"id":"1.195395455","rc":[{"atl":[[170,0],[190,2.7]],"id":37267533}],"con":true,"img":false}]}
{"op":"mcm","clk":"5346883956","pt":1646099394686,"mc":[{"id":"1.195395455","rc":[{"atb":[[3,19.1]],"id":28002629}],"con":true,"img":false}]}
{"op":"mcm","clk":"5346883999","pt":1646099396076,"mc":[{"id":"1.195395455","rc":[{"atl":[[3.15,9.12]],"id":43154433}],"con":true,"img":false}]}
{"op":"mcm","clk":"5346884049","pt":1646099397414,"mc":[{"id":"1.195395455","rc":[{"atl":[[11.5,0]],"id":42393370}],"con":true,"img":false}]}
{"op":"mcm","clk":"5346884052","pt":1646099397520,"mc":[{"id":"1.195395455","rc":[{"atl":[[10.5,16.22]],"id":42393370}],"con":true,"img":false}]}
{"op":"mcm","clk":"5346884184","pt":1646099401805,"mc":[{"id":"1.195395455","rc":[{"atl":[[3.15,14.95]],"id":43154433}],"con":true,"img":false}]}
{"op":"mcm","clk":"5346884361","pt":1646099407315,"mc":[{"id":"1.195395455","rc":[{"atl":[[120,0]],"id":37672294},{"atb":[[7.8,18.93],[6.6,0]],"id":22150928}],"con":true,"img":false}]}
{"op":"mcm","clk":"5346884365","pt":1646099407417,"mc":[{"id":"1.195395455","rc":[{"atl":[[65,2.7]],"id":37672294}],"con":true,"img":false}]}
{"op":"mcm","clk":"5346884487","pt":1646099411128,"mc":[{"id":"1.195395455","rc":[{"atb":[[1.05,2.8]],"id":37672294},{"atb":[[1.02,2.98]],"id":28002629},{"atb":[[1.02,3.16]],"id":43154433}],"con":true,"img":false}]}
{"op":"mcm","clk":"5346884503","pt":1646099411593,"mc":[{"id":"1.195395455","rc":[{"atb":[[1.05,0.1]],"id":37672294},{"atb":[[1.02,0.27]],"id":28002629},{"atb":[[1.02,0.45]],"id":43154433}],"con":true,"img":false}]}
{"op":"mcm","clk":"5346884514","pt":1646099411901,"mc":[{"id":"1.195395455","rc":[{"atb":[[1.02,2.94]],"id":42393370}],"con":true,"img":false}]}
{"op":"mcm","clk":"5346884524","pt":1646099412107,"mc":[{"id":"1.195395455","rc":[{"atb":[[1.05,0]],"id":37672294},{"atb":[[1.02,0]],"id":28002629},{"atb":[[1.02,0]],"id":43154433}],"con":true,"img":false}]}
{"op":"mcm","clk":"5346884528","pt":1646099412207,"mc":[{"id":"1.195395455","rc":[{"atb":[[10.5,1.16]],"id":37672294},{"atb":[[3.85,0.27]],"id":28002629},{"atb":[[2.3,0.45]],"id":43154433}],"con":true,"img":false}]}
{"op":"mcm","clk":"5346884532","pt":1646099412315,"mc":[{"id":"1.195395455","rc":[{"atb":[[1.02,0.24]],"id":42393370}],"con":true,"img":false}]}
{"op":"mcm","clk":"5346884543","pt":1646099412513,"mc":[{"id":"1.195395455","rc":[{"atl":[[10.5,5.69],[9.4,11.9]],"id":42393370}],"con":true,"img":false}]}
{"op":"mcm","clk":"5346884554","pt":1646099412821,"mc":[{"id":"1.195395455","rc":[{"atb":[[1.02,0]],"id":42393370}],"con":true,"img":false}]}
{"op":"mcm","clk":"5346884560","pt":1646099412925,"mc":[{"id":"1.195395455","rc":[{"atb":[[4.3,0.24]],"id":42393370}],"con":true,"img":false}]}
{"op":"mcm","clk":"5346884771","pt":1646099418788,"mc":[{"id":"1.195395455","rc":[{"atb":[[1.78,11.78]],"id":43154433}],"con":true,"img":false}]}
{"op":"mcm","clk":"5346884980","pt":1646099425822,"mc":[{"id":"1.195395455","rc":[{"spn":5.75,"spf":1.0,"id":42393370},{"atb":[[1.78,0]],"id":43154433},{"spn":2.72,"spf":1.0,"id":43154433}],"con":true,"img":false}]}
{"op":"mcm","clk":"5346885026","pt":1646099427419,"mc":[{"id":"1.195395455","rc":[{"atb":[[2.98,0]],"id":28002629},{"atl":[[190,0]],"id":37267533}],"con":true,"img":false}]}
{"op":"mcm","clk":"5346885030","pt":1646099427522,"mc":[{"id":"1.195395455","rc":[{"atb":[[3.05,63.28]],"id":28002629},{"atl":[[170,2.7],[180,0],[200,2.66]],"id":37267533}],"con":true,"img":false}]}
{"op":"mcm","clk":"5346885178","pt":1646099431828,"mc":[{"id":"1.195395455","rc":[{"atb":[[3,14.5]],"id":28002629}],"con":true,"img":false}]}
{"op":"mcm","clk":"5346885274","pt":1646099434444,"mc":[{"id":"1.195395455","rc":[{"atb":[[1.01,1.67]],"id":37672294},{"atl":[[1000,1.67]],"id":37672294},{"atl":[[1000,1.67]],"id":28002629},{"atl":[[1000,1.67]],"id":42393370},{"atb":[[1.03,1.67]],"id":22150928},{"atl":[[1000,1.67]],"id":22150928}],"con":true,"img":false}]}
{"op":"mcm","clk":"5346885277","pt":1646099434648,"mc":[{"id":"1.195395455","rc":[{"atl":[[1000,0.31]],"id":22150928}],"con":true,"img":false}]}
{"op":"mcm","clk":"5346885280","pt":1646099434751,"mc":[{"id":"1.195395455","rc":[{"atb":[[1.01,0.76]],"id":37672294},{"atl":[[1000,0.35]],"id":37672294},{"atl":[[1000,1.01]],"id":28002629},{"atl":[[1000,1.19]],"id":42393370},{"atb":[[1.03,0.64]],"id":22150928}],"con":true,"img":false}]}
{"op":"mcm","clk":"5346885296","pt":1646099435318,"mc":[{"id":"1.195395455","rc":[{"atl":[[1000,0]],"id":22150928}],"con":true,"img":false}]}
{"op":"mcm","clk":"5346885299","pt":1646099435418,"mc":[{"id":"1.195395455","rc":[{"atl":[[26,0.31]],"id":22150928}],"con":true,"img":false}]}
{"op":"mcm","clk":"5346885314","pt":1646099435931,"mc":[{"id":"1.195395455","rc":[{"atl":[[1000,0]],"id":28002629}],"con":true,"img":false}]}
{"op":"mcm","clk":"5346885317","pt":1646099436032,"mc":[{"id":"1.195395455","rc":[{"atl":[[8.2,1.01]],"id":28002629}],"con":true,"img":false}]}
{"op":"mcm","clk":"5346885322","pt":1646099436132,"mc":[{"id":"1.195395455","rc":[{"atl":[[8.2,3.71]],"id":28002629},{"atl":[[1000,0]],"id":42393370}],"con":true,"img":false}]}
{"op":"mcm","clk":"5346885325","pt":1646099436239,"mc":[{"id":"1.195395455","rc":[{"atb":[[9.2,5.49]],"id":37672294},{"atb":[[3.5,7.95]],"id":28002629},{"atl":[[9.2,9.15],[8.8,19.23]],"id":28002629},{"atb":[[3.5,5.6]],"id":42393370},{"atl":[[7,1.19]],"id":42393370},{"atb":[[9.8,10.54]],"id":22150928},{"atb":[[1.72,128.89]],"id":43154433}],"con":true,"img":false}]}
{"op":"mcm","clk":"5346885329","pt":1646099436339,"mc":[{"id":"1.195395455","rc":[{"atl":[[8.2,1.01]],"id":28002629},{"atb":[[1.03,0]],"id":22150928}],"con":true,"img":false}]}
{"op":"mcm","clk":"5346885334","pt":1646099436441,"mc":[{"id":"1.195395455","rc":[{"atl":[[8.2,4.73],[8.8,6.41]],"id":28002629},{"atb":[[13,0.64]],"id":22150928}],"con":true,"img":false}]}
{"op":"mcm","clk":"5346885342","pt":1646099436646,"mc":[{"id":"1.195395455","rc":[{"atl":[[1000,0]],"id":37672294}],"con":true,"img":false}]}
{"op":"mcm","clk":"5346885348","pt":1646099436750,"mc":[{"id":"1.195395455","rc":[{"atl":[[23,0.35]],"id":37672294}],"con":true,"img":false}]}
{"op":"mcm","clk":"5346885352","pt":1646099436850,"mc":[{"id":"1.195395455","rc":[{"atb":[[3,10]],"id":28002629},{"atl":[[170,4.7]],"id":37267533}],"con":true,"img":false}]}
{"op":"mcm","clk":"5346885356","pt":1646099436953,"mc":[{"id":"1.195395455","rc":[{"atb":[[1.01,0]],"id":37672294},{"atl":[[200,0.66]],"id":37267533}],"con":true,"img":false}]}
{"op":"mcm","clk":"5346885359","pt":1646099437056,"mc":[{"id":"1.195395455","rc":[{"atb":[[11,0.76]],"id":37672294}],"con":true,"img":false}]}
{"op":"mcm","clk":"5346885372","pt":1646099437416,"mc":[{"id":"1.195395455","rc":[{"atl":[[10.5,0]],"id":42393370}],"con":true,"img":false}]}
{"op":"mcm","clk":"5346885375","pt":1646099437519,"mc":[{"id":"1.195395455","rc":[{"atl":[[9.2,5.69]],"id":42393370}],"con":true,"img":false}]}
{"op":"mcm","clk":"5346885408","pt":1646099438443,"mc":[{"id":"1.195395455","rc":[{"atb":[[3,0],[2.84,10.87]],"id":28002629},{"atl":[[3.35,28.17],[3.3,0]],"id":43154433}],"con":true,"img":false}]}
{"op":"mcm","clk":"5346885451","pt":1646099439725,"mc":[{"id":"1.195395455","rc":[{"atb":[[2.9,10.53],[2.96,0]],"id":28002629},{"atl":[[3.35,19.66],[3.3,8.7]],"id":43154433}],"con":true,"img":false}]}
{"op":"mcm","clk":"5346885615","pt":1646099444753,"mc":[{"id":"1.195395455","rc":[{"atb":[[2.92,0]],"id":28002629}],"con":true,"img":false}]}
{"op":"mcm","clk":"5346885711","pt":1646099447422,"mc":[{"id":"1.195395455","rc":[{"atb":[[8.4,0]],"id":37672294},{"atb":[[3.45,0],[3.05,0]],"id":28002629},{"atb":[[3.35,21.85]],"id":42393370},{"atb":[[22,0.49]],"id":37267533},{"atb":[[1.71,2]],"id":43154433}],"con":true,"img":false}]}
{"op":"mcm","clk":"5346885714","pt":1646099447526,"mc":[{"id":"1.195395455","rc":[{"atb":[[9.4,5.03]],"id":37672294},{"atb":[[2.92,63.28],[4.4,14.92]],"id":28002629},{"atb":[[3.55,21.85]],"id":42393370},{"atb":[[23,2.7]],"id":37267533},{"atb":[[1.73,43.26]],"id":43154433}],"con":true,"img":false}]}
{"op":"mcm","clk":"5346885789","pt":1646099449728,"mc":[{"id":"1.195395455","rc":[{"atb":[[2.86,26.88]],"id":28002629}],"con":true,"img":false}]}
{"op":"mcm","clk":"5346885807","pt":1646099450241,"mc":[{"id":"1.195395455","rc":[{"atb":[[9.2,0]],"id":37672294},{"atb":[[3.5,0]],"id":28002629},{"atb":[[3.5,0]],"id":42393370},{"atb":[[14,7.13]],"id":37455733},{"atb":[[1.72,0]],"id":43154433}],"con":true,"img":false}]}
{"op":"mcm","clk":"5346885955","pt":1646099454354,"mc":[{"id":"1.195395455","rc":[{"atb":[[9.6,10.42]],"id":37672294},{"atb":[[3.9,32]],"id":28002629},{"atb":[[3.7,3.35]],"id":42393370},{"atb":[[1.71,132.7]],"id":43154433}],"con":true,"img":false}]}
{"op":"mcm","clk":"5346885979","pt":1646099454925,"mc":[{"id":"1.195395455","rc":[{"atb":[[3.4,3.83]],"id":42393370}],"con":true,"img":false}]}
{"op":"mcm","clk":"5346886059","pt":1646099457357,"mc":[{"id":"1.195395455","rc":[{"atb":[[4.4,0]],"id":28002629},{"atb":[[3.55,0]],"id":42393370},{"atb":[[18.5,0]],"id":37267533},{"atb":[[7.8,0],[9.6,0]],"id":22150928},{"atb":[[1.73,0]],"id":43154433}],"con":true,"img":false}]}
{"op":"mcm","clk":"5346886065","pt":1646099457459,"mc":[{"id":"1.195395455","rc":[{"atb":[[3.95,14.92]],"id":28002629},{"atb":[[3.5,21.85]],"id":42393370},{"atb":[[22,7.52]],"id":37267533},{"atb":[[10,5.03],[8.6,18.93]],"id":22150928},{"atb":[[1.72,43.26]],"id":43154433}],"con":true,"img":false}]}
{"op":"mcm","clk":"5346886152","pt":1646099459768,"mc":[{"id":"1.195395455","rc":[{"atb":[[2.82,41.21]],"id":28002629}],"con":true,"img":false}]}
{"op":"mcm","clk":"5346886155","pt":1646099459871,"mc":[{"id":"1.195395455","rc":[{"atb":[[3.9,0]],"id":28002629},{"atb":[[3.7,0]],"id":42393370},{"atb":[[9.8,0]],"id":22150928},{"atb":[[1.71,2]],"id":43154433}],"con":true,"img":false}]}
{"op":"mcm","clk":"5346886222","pt":1646099461874,"mc":[{"id":"1.195395455","rc":[{"atb":[[2.88,0],[2.84,0]],"id":28002629}],"con":true,"img":false}]}
{"op":"mcm","clk":"5346886233","pt":1646099462082,"mc":[{"id":"1.195395455","rc":[{"atb":[[3.4,0]],"id":42393370}],"con":true,"img":false}]}
{"op":"mcm","clk":"5346886275","pt":1646099463161,"mc":[{"id":"1.195395455","rc":[{"atb":[[2.88,10.64],[2.9,0]],"id":28002629},{"atl":[[3.35,28.17],[3.3,0]],"id":43154433}],"con":true,"img":false}]}
{"op":"mcm","clk":"5346886293","pt":1646099463672,"mc":[{"id":"1.195395455","rc":[{"atb":[[2.94,47.83]],"id":28002629},{"atb":[[3.55,5.04]],"id":42393370},{"atb":[[1.73,122.72]],"id":43154433}],"con":true,"img":false}]}
{"op":"mcm","clk":"5346886437","pt":1646099467481,"mc":[{"id":"1.195395455","rc":[{"atb":[[3.95,0]],"id":28002629},{"atl":[[170,2]],"id":37267533},{"atb":[[10,0]],"id":22150928},{"atb":[[1.72,0]],"id":43154433}],"con":true,"img":false}]}
{"op":"mcm","clk":"5346886445","pt":1646099467584,"mc":[{"id":"1.195395455","rc":[{"atb":[[3.4,14.92]],"id":28002629},{"atl":[[160,2.7]],"id":37267533},{"atb":[[9.6,5.03]],"id":22150928},{"atb":[[1.71,45.26]],"id":43154433}],"con":true,"img":false}]}
{"op":"mcm","clk":"5346886448","pt":1646099467687,"mc":[{"id":"1.195395455","rc":[{"atl":[[170,0],[200,2.66]],"id":37267533}],"con":true,"img":false}]}
{"op":"mcm","clk":"5346886559","pt":1646099469997,"mc":[{"id":"1.195395455","rc":[{"atl":[[7.2,0],[7.4,3.12]],"id":42393370},{"atb":[[10,0],[10.5,2.11]],"id":37267533},{"atb":[[5.6,0],[5.7,4.26]],"id":37455733},{"atb":[[8.4,16.44],[8.8,2.56]],"id":22150928},{"atl":[[3.35,19.66],[3.55,7.84]],"id":43154433}],"con":true,"img":false}]}
{"op":"mcm","clk":"5346886568","pt":1646099470150,"mc":[{"id":"1.195395455","rc":[{"atl":[[7,0],[1000,1.67]],"id":42393370}],"con":true,"img":false}]}
{"op":"mcm","clk":"5346886571","pt":1646099470255,"mc":[{"id":"1.195395455","rc":[{"atl":[[1000,1.19]],"id":42393370}],"con":true,"img":false}]}
{"op":"mcm","clk":"5346886580","pt":1646099470458,"mc":[{"id":"1.195395455","rc":[{"atl":[[1000,0]],"id":42393370}],"con":true,"img":false}]}
{"op":"mcm","clk":"5346886586","pt":1646099470560,"mc":[{"id":"1.195395455","rc":[{"atl":[[7.2,1.19]],"id":42393370}],"con":true,"img":false}]}
{"op":"mcm","clk":"5346886604","pt":1646099470875,"mc":[{"id":"1.195395455","rc":[{"atb":[[2.94,0]],"id":28002629},{"atb":[[9.8,10.54]],"id":22150928},{"atb":[[1.73,0]],"id":43154433}],"con":true,"img":false}]}
{"op":"mcm","clk":"5346886685","pt":1646099473174,"mc":[{"id":"1.195395455","rc":[{"atb":[[2.84,27.17]],"id":28002629}],"con":true,"img":false}]}
{"op":"mcm","clk":"5346886739","pt":1646099474759,"mc":[{"id":"1.195395455","rc":[{"atb":[[3.45,8.52]],"id":28002629},{"atb":[[1.72,128.89]],"id":43154433}],"con":true,"img":false}]}
{"op":"mcm","clk":"5346886793","pt":1646099476550,"mc":[{"id":"1.195395455","rc":[{"atl":[[160,4.7],[200,0.66]],"id":37267533}],"con":true,"img":false}]}
{"op":"mcm","clk":"5346886822","pt":1646099477470,"mc":[{"id":"1.195395455","rc":[{"atb":[[3.5,0]],"id":42393370}],"con":true,"img":false}]}
{"op":"mcm","clk":"5346886826","pt":1646099477574,"mc":[{"id":"1.195395455","rc":[{"atb":[[3.6,21.85]],"id":42393370}],"con":true,"img":false}]}
{"op":"mcm","clk":"5346886829","pt":1646099477676,"mc":[{"id":"1.195395455","rc":[{"atl":[[3.4,0]],"id":43154433}],"con":true,"img":false}]}
{"op":"mcm","clk":"5346886906","pt":1646099479986,"mc":[{"id":"1.195395455","rc":[{"atl":[[7.8,12.01]],"id":42393370},{"atb":[[5.5,11.11]],"id":37455733},{"atb":[[8.4,23.2]],"id":22150928},{"atl":[[3.5,0],[3.65,18.87]],"id":43154433}],"con":true,"img":false}]}
{"op":"mcm","clk":"5346886919","pt":1646099480293,"mc":[{"id":"1.195395455","rc":[{"atb":[[3.55,0]],"id":42393370}],"con":true,"img":false}]}
{"op":"mcm","clk":"5346886987","pt":1646099482084,"mc":[{"id":"1.195395455","rc":[{"atl":[[7.8,9.7]],"id":42393370}],"con":true,"img":false}]}
{"op":"mcm","clk":"5346887028","pt":1646099483163,"mc":[{"id":"1.195395455","rc":[{"atb":[[2.8,41.67]],"id":28002629}],"con":true,"img":false}]}
{"op":"mcm","clk":"5346887059","pt":1646099483981,"mc":[{"id":"1.195395455","rc":[{"atb":[[3.7,3.35]],"id":42393370}],"con":true,"img":false}]}
{"op":"mcm","clk":"5346887143","pt":1646099486085,"mc":[{"id":"1.195395455","rc":[{"spn":17.0,"spf":1.0,"id":37672294},{"atb":[[2.82,0],[2.86,0]],"id":28002629},{"spn":6.25,"spf":1.0,"id":28002629},{"atl":[[8,0],[7.6,0],[8.4,0]],"id":42393370},{"atb":[[4.9,0]],"id":37455733},{"atb":[[7.2,0]],"id":22150928},{"spn":19.5,"spf":1.0,"id":22150928}],"con":true,"img":false}]}
{"op":"mcm","clk":"5346887155","pt":1646099486288,"mc":[{"id":"1.195395455","rc":[{"atl":[[7.8,7.35]],"id":42393370}],"con":true,"img":false}]}
{"op":"mcm","clk":"5346887208","pt":1646099487368,"mc":[{"id":"1.195395455","rc":[{"atb":[[9.4,0]],"id":37672294},{"atb":[[3.6,0]],"id":42393370},{"atb":[[1.71,2]],"id":43154433},{"atl":[[3.35,0]],"id":43154433}],"con":true,"img":false}]}
{"op":"mcm","clk":"5346887211","pt":1646099487470,"mc":[{"id":"1.195395455","rc":[{"atb":[[9.8,5.03]],"id":37672294},{"atb":[[3.5,21.85]],"id":42393370},{"atb":[[1.73,43.26]],"id":43154433},{"atl":[[3.4,19.66]],"id":43154433}],"con":true,"img":false}]}
{"op":"mcm","clk":"5346887215","pt":1646099487572,"mc":[{"id":"1.195395455","rc":[{"atb":[[1.01,1.67],[11,0]],"id":37672294}],"con":true,"img":false}]}
{"op":"mcm","clk":"5346887218","pt":1646099487675,"mc":[{"id":"1.195395455","rc":[{"atb":[[1.01,0.76]],"id":37672294}],"con":true,"img":false}]}
{"op":"mcm","clk":"5346887229","pt":1646099487880,"mc":[{"id":"1.195395455","rc":[{"atb":[[1.01,0]],"id":37672294}],"con":true,"img":false}]}
{"op":"mcm","clk":"5346887234","pt":1646099487983,"mc":[{"id":"1.195395455","rc":[{"atb":[[10,0.76]],"id":37672294}],"con":true,"img":false}]}
{"op":"mcm","clk":"5346887299","pt":1646099489473,"mc":[{"id":"1.195395455","rc":[{"atb":[[9.6,0]],"id":37672294},{"atb":[[3.7,0]],"id":42393370},{"atb":[[1.72,0]],"id":43154433}],"con":true,"img":false}]}
{"op":"mcm","clk":"5346887322","pt":1646099489984,"mc":[{"id":"1.195395455","rc":[{"atl":[[8.2,10.42]],"id":42393370},{"atb":[[5.3,17.44]],"id":37455733},{"atb":[[8,10.71]],"id":22150928},{"atl":[[3.75,27.27]],"id":43154433}],"con":true,"img":false}]}
{"op":"mcm","clk":"5346887457","pt":1646099493167,"mc":[{"id":"1.195395455","rc":[{"atb":[[2.76,71.02]],"id":28002629}],"con":true,"img":false}]}
{"op":"mcm","clk":"5346887471","pt":1646099493474,"mc":[{"id":"1.195395455","rc":[{"atb":[[9.2,11.27]],"id":37672294},{"atb":[[3.55,5.04]],"id":42393370},{"atb":[[1.71,132.25]],"id":43154433}],"con":true,"img":false}]}
{"op":"mcm","clk":"5346887518","pt":1646099494504,"mc":[{"id":"1.195395455","rc":[{"atb":[[1.01,1.67]],"id":37672294}],"con":true,"img":false}]}
{"op":"mcm","clk":"5346887524","pt":1646099494607,"mc":[{"id":"1.195395455","rc":[{"atb":[[1.01,0.76],[10,0]],"id":37672294}],"con":true,"img":false}]}
{"op":"mcm","clk":"5346887533","pt":1646099494763,"mc":[{"id":"1.195395455","rc":[{"atb":[[1.01,0]],"id":37672294}],"con":true,"img":false}]}
{"op":"mcm","clk":"5346887537","pt":1646099494915,"mc":[{"id":"1.195395455","rc":[{"atb":[[11,0.76]],"id":37672294}],"con":true,"img":false}]}
{"op":"mcm","clk":"5346887634","pt":1646099497377,"mc":[{"id":"1.195395455","rc":[{"atb":[[9.8,0]],"id":37672294},{"atl":[[150,0]],"id":37267533},{"atb":[[13.5,0]],"id":37455733},{"atb":[[9.6,0]],"id":22150928},{"atb":[[1.73,0]],"id":43154433}],"con":true,"img":false}]}
{"op":"mcm","clk":"5346887640","pt":1646099497482,"mc":[{"id":"1.195395455","rc":[{"atb":[[9.4,5.03]],"id":37672294},{"atl":[[140,0.25]],"id":37267533},{"atb":[[14.5,9.6]],"id":37455733},{"atb":[[10,5.03]],"id":22150928},{"atb":[[1.72,43.26]],"id":43154433}],"con":true,"img":false}]}
{"op":"mcm","clk":"5346887729","pt":1646099499997,"mc":[{"id":"1.195395455","rc":[{"atl":[[8.6,16.45]],"id":42393370},{"atb":[[5.1,30.49]],"id":37455733},{"atb":[[7.6,18.94]],"id":22150928},{"atl":[[3.85,43.86]],"id":43154433}],"con":true,"img":false}]}
{"op":"mcm","clk":"5346887735","pt":1646099500098,"mc":[{"id":"1.195395455","rc":[{"atl":[[3.15,9.23]],"id":43154433}],"con":true,"img":false}]}
{"op":"mcm","clk":"5346887755","pt":1646099500614,"mc":[{"id":"1.195395455","rc":[{"atb":[[2.92,73.7],[2.88,0]],"id":28002629}],"con":true,"img":false}]}
{"op":"mcm","clk":"5346887757","pt":1646099500714,"mc":[{"id":"1.195395455","rc":[{"atb":[[14,0]],"id":37455733},{"atb":[[9.8,0]],"id":22150928},{"atb":[[1.71,2]],"id":43154433},{"atl":[[3.6,0]],"id":43154433}],"con":true,"img":false}]}
{"op":"mcm","clk":"5346887835","pt":1646099502515,"mc":[{"id":"1.195395455","rc":[{"atl":[[46,2.22]],"id":37672294}],"con":true,"img":false}]}
{"op":"mcm","clk":"5346887841","pt":1646099502617,"mc":[{"id":"1.195395455","rc":[{"atl":[[75,0]],"id":37672294}],"con":true,"img":false}]}
{"op":"mcm","clk":"5346887933","pt":1646099504517,"mc":[{"id":"1.195395455","rc":[{"atb":[[15,6.6]],"id":37455733},{"atb":[[1.73,122.72]],"id":43154433}],"con":true,"img":false}]}
{"op":"mcm","clk":"5346888040","pt":1646099507390,"mc":[{"id":"1.195395455","rc":[{"atb":[[3.4,0]],"id":28002629},{"atb":[[3.5,0]],"id":42393370},{"atl":[[160,2]],"id":37267533},{"atb":[[10,0]],"id":22150928},{"atb":[[1.72,0]],"id":43154433}],"con":true,"img":false}]}
{"op":"mcm","clk":"5346888045","pt":1646099507514,"mc":[{"id":"1.195395455","rc":[{"atb":[[4.4,14.92]],"id":28002629},{"atb":[[3.6,21.85]],"id":42393370},{"atl":[[150,2.7],[160,0],[200,2.66]],"id":37267533},{"atb":[[9.6,5.03]],"id":22150928},{"atb":[[1.71,45.26]],"id":43154433}],"con":true,"img":false}]}
{"op":"mcm","clk":"5346888164","pt":1646099510106,"mc":[{"id":"1.195395455","rc":[{"atb":[[3.45,0]],"id":28002629},{"atb":[[3.55,0]],"id":42393370},{"atb":[[9.8,10.51]],"id":22150928},{"atb":[[1.73,0]],"id":43154433}],"con":true,"img":false}]}
{"op":"mcm","clk":"5346888186","pt":1646099510616,"mc":[{"id":"1.195395455","rc":[{"atb":[[2.88,26.6]],"id":28002629}],"con":true,"img":false}]}
{"op":"mcm","clk":"5346888334","pt":1646099514205,"mc":[{"id":"1.195395455","rc":[{"atb":[[3.9,31.89]],"id":28002629},{"atb":[[3.7,3.35]],"id":42393370},{"atb":[[1.72,128.44]],"id":43154433}],"con":true,"img":false}]}
{"op":"mcm","clk":"5346888412","pt":1646099515997,"mc":[{"id":"1.195395455","rc":[{"atl":[[150,4.7],[200,0.66]],"id":37267533}],"con":true,"img":false}]}
{"op":"mcm","clk":"5346888470","pt":1646099517432,"mc":[{"id":"1.195395455","rc":[{"atb":[[4.4,0]],"id":28002629}],"con":true,"img":false}]}
{"op":"mcm","clk":"5346888474","pt":1646099517535,"mc":[{"id":"1.195395455","rc":[{"atb":[[3.95,14.92]],"id":28002629}],"con":true,"img":false}]}
{"op":"mcm","clk":"5346888494","pt":1646099518001,"mc":[{"id":"1.195395455","rc":[{"atb":[[2.76,0]],"id":28002629}],"con":true,"img":false}]}
{"op":"mcm","clk":"5346888557","pt":1646099519744,"mc":[{"id":"1.195395455","rc":[{"atb":[[3.9,0]],"id":28002629}],"con":true,"img":false}]}
{"op":"mcm","clk":"5346888597","pt":1646099520617,"mc":[{"id":"1.195395455","rc":[{"atb":[[2.84,40.76]],"id":28002629}],"con":true,"img":false}]}
{"op":"mcm","clk":"5346888673","pt":1646099522212,"mc":[{"id":"1.195395455","rc":[{"atl":[[3.15,3.4]],"id":43154433}],"con":true,"img":false}]}
{"op":"mcm","clk":"5346888742","pt":1646099523552,"mc":[{"id":"1.195395455","rc":[{"atb":[[2.94,47.67]],"id":28002629}],"con":true,"img":false}]}
