{"op":"mcm","clk":"5351767851","pt":1646175389015,"mc":[{"id":"1.195453781","marketDefinition":{"bspMarket":true,"turnInPlayEnabled":false,"persistenceEnabled":false,"marketBaseRate":7.0,"eventId":"31272499","eventTypeId":"4339","numberOfWinners":3,"bettingType":"ODDS","marketType":"PLACE","marketTime":"2022-03-02T11:39:00.000Z","suspendTime":"2022-03-02T11:39:00.000Z","bspReconciled":false,"complete":true,"inPlay":false,"crossMatching":false,"runnersVoidable":false,"numberOfActiveRunners":8,"betDelay":0,"status":"OPEN","runners":[{"status":"ACTIVE","sortPriority":1,"id":40917608,"name":"1. Blazing Norman"},{"status":"ACTIVE","sortPriority":2,"id":38904370,"name":"2. Blazing Brothers"},{"status":"ACTIVE","sortPriority":3,"id":38247349,"name":"3. Hearts Thunder"},{"status":"ACTIVE","sortPriority":4,"id":42472248,"name":"4. Paddy Hayze"},{"status":"ACTIVE","sortPriority":5,"id":28671742,"name":"5. Hooper"},{"status":"ACTIVE","sortPriority":6,"id":41653210,"name":"6. Go Again Bear"},{"status":"ACTIVE","sortPriority":7,"id":41120152,"name":"8. Rosas Memory"},{"status":"ACTIVE","sortPriority":8,"id":28866557,"name":"9. Black Magic Ryno"}],"regulators":["MR_INT"],"venue":"Rockhampton","countryCode":"AU","discountAllowed":true,"timezone":"Australia/Queensland","openDate":"2022-03-02T08:34:00.000Z","version":4382437847,"name":"To Be Placed","eventName":"Rockhampton (AUS) 2nd Mar"},"rc":[],"con":true,"img":false}]}
{"op":"mcm","clk":"5351835883","pt":1646176787551,"mc":[{"id":"1.195453781","rc":[{"atb":[[2.4,86.32],[2.5,80.56],[2.6,37.76]],"id":41653210},{"atl":[[6.2,2.32],[10.5,2.54],[21,2.41],[8.2,1.67],[15.5,1.66]],"id":41653210},{"spn":4.4,"spf":"NaN","id":41653210},{"atb":[[3.45,24.66],[3.2,54.93],[2.98,61.03]],"id":28866557},{"atl":[[18.5,1.38],[44,1.12],[13.5,0.96],[27,0.93],[9.4,1.43]],"id":28866557},{"spn":6.42,"spf":"NaN","id":28866557},{"atb":[[1.01,12084.92],[1.02,6042.46],[1.07,863.2]],"id":40917608},{"atl":[[2.88,25.71],[2.28,9.43],[2.68,14.38],[2.08,11.19],[2.48,16.33]],"id":40917608},{"spn":1.57,"spf":"NaN","id":40917608},{"atb":[[1.4,302.12],[1.45,134.27],[1.35,345.28]],"id":41120152},{"atl":[[4.5,13.81],[2.9,6.35],[3.25,10.74],[3.75,8.79],[2.7,7.1]],"id":41120152},{"spn":2.07,"spf":"NaN","id":41120152},{"atb":[[1.4,302.12],[1.45,268.55],[1.5,120.84]],"id":42472248},{"atl":[[3.45,9.86],[3.95,8.19],[4.9,12.39],[2.98,6.1],[2.78,6.78]],"id":42472248},{"spn":2.14,"spf":"NaN","id":42472248},{"atb":[[1.6,201.41],[1.55,219.72],[1.65,92.96]],"id":38247349},{"atl":[[3.45,4.93],[3.95,8.19],[4.9,6.19],[2.98,6.1],[5.9,9.86]],"id":38247349},{"spn":2.31,"spf":"NaN","id":38247349},{"atb":[[2.74,69.45],[2.84,65.67],[2.94,31.14]],"id":28671742},{"atl":[[8,1.72],[10,1.34],[20,1.27],[15,1.72],[30,1.66]],"id":28671742},{"spn":5.47,"spf":"NaN","id":28671742},{"atb":[[2.82,66.4],[2.92,62.94],[3.05,29.47]],"id":38904370},{"atl":[[32,1.55],[10.5,1.27],[21,1.2],[8.2,1.67],[15.5,1.66]],"id":38904370},{"spn":5.62,"spf":"NaN","id":38904370}],"con":true,"img":false}]}
{"op":"mcm","clk":"5351837310","pt":1646176822852,"mc":[{"id":"1.195453781","rc":[{"atb":[[3.2,0]],"id":28866557},{"atl":[[18.5,0],[44,0],[9.4,0]],"id":28866557}],"con":true,"img":false}]}
{"op":"mcm","clk":"5351837314","pt":1646176822954,"mc":[{"id":"1.195453781","rc":[{"atb":[[2.4,0],[2.5,0],[2.6,0]],"id":41653210},{"atl":[[6.2,0],[10.5,0],[21,0],[8.2,0],[15.5,0]],"id":41653210},{"atb":[[3.45,0],[2.98,0]],"id":28866557},{"atl":[[13.5,0],[27,0]],"id":28866557},{"atb":[[1.01,0],[1.02,0],[1.07,0]],"id":40917608},{"atl":[[2.88,0],[2.28,0],[2.68,0],[2.08,0],[2.48,0]],"id":40917608},{"atb":[[1.4,0],[1.45,0],[1.35,0]],"id":41120152},{"atl":[[4.5,0],[2.9,0],[3.25,0],[3.75,0],[2.7,0]],"id":41120152},{"atb":[[1.4,0],[1.45,0],[1.5,0]],"id":42472248},{"atl":[[3.45,0],[3.95,0],[4.9,0],[2.98,0],[2.78,0]],"id":42472248},{"atb":[[1.6,0],[1.55,0],[1.65,0]],"id":38247349},{"atl":[[3.45,0],[3.95,0],[4.9,0],[2.98,0],[5.9,0]],"id":38247349},{"atb":[[2.74,0],[2.84,0],[2.94,0]],"id":28671742},{"atl":[[8,0],[10,0],[20,0],[15,0],[30,0]],"id":28671742},{"atb":[[2.82,0],[2.92,0],[3.05,0]],"id":38904370},{"atl":[[32,0],[10.5,0],[21,0],[8.2,0],[15.5,0]],"id":38904370}],"con":true,"img":false}]}
{"op":"mcm","clk":"5351837809","pt":1646176834572,"mc":[{"id":"1.195453781","rc":[{"atb":[[2.5,80.56],[2.6,75.53],[2.7,35.54]],"id":41653210},{"atl":[[16.5,1.55],[8.6,1.58],[11.5,2.3],[23,2.19],[6.6,2.15]],"id":41653210},{"atb":[[4.5,34.52],[5,30.21],[5.5,13.42]],"id":28866557},{"atl":[[18.5,0.69],[85,0.28],[170,0.28],[44,0.56],[27,0.46]],"id":28866557},{"atb":[[1.01,12084.92],[1.09,671.38],[1.04,3021.23]],"id":40917608},{"atl":[[2.72,14.05],[2.92,25.17],[2.32,9.15],[2.52,15.9],[2.12,10.78]],"id":40917608},{"atb":[[1.4,151.06],[1.3,402.83],[1.35,345.28]],"id":41120152},{"atl":[[4.3,14.64],[2.86,6.49],[2.66,7.27],[3.15,11.24],[3.65,9.11]],"id":41120152},{"atb":[[1.4,302.12],[1.45,134.27],[1.35,345.28]],"id":42472248},{"atl":[[4.5,13.81],[2.9,6.35],[3.25,10.74],[3.75,8.79],[2.7,7.1]],"id":42472248},{"atb":[[1.45,268.55],[1.55,109.86],[1.5,241.69]],"id":38247349},{"atl":[[2.82,6.64],[5.1,11.79],[4.1,7.79],[3.55,9.47],[3.05,5.89]],"id":38247349},{"atb":[[2.5,80.56],[2.6,75.53],[2.7,35.54]],"id":28671742},{"atl":[[16.5,1.55],[8.6,1.58],[11.5,2.3],[23,2.19],[6.6,2.15]],"id":28671742},{"atb":[[2.86,64.97],[3.15,28.1],[2.96,61.66]],"id":38904370},{"atl":[[16,1.61],[34,1.46],[11,1.2],[22,1.14],[8.4,1.63]],"id":38904370}],"con":true,"img":false}]}
{"op":"mcm","clk":"5351846227","pt":1646177033161,"mc":[{"id":"1.195453781","rc":[{"spn":4.65,"spf":"NaN","id":41653210},{"atb":[[4.5,0],[5,0],[5.5,0]],"id":28866557},{"atl":[[18.5,0],[85,0],[170,0],[44,0],[27,0]],"id":28866557},{"spn":"NaN","spf":"NaN","id":28866557},{"spn":2.03,"spf":"NaN","id":41120152},{"spn":1.6,"spf":"NaN","id":40917608},{"spn":2.07,"spf":"NaN","id":42472248},{"atb":[[1.45,0],[1.55,0],[1.5,0]],"id":38247349},{"atl":[[2.82,0],[5.1,0],[4.1,0],[3.55,0],[3.05,0]],"id":38247349},{"spn":"NaN","spf":"NaN","id":38247349},{"atb":[[2.5,0],[2.6,0],[2.7,0]],"id":28671742},{"atl":[[16.5,0],[8.6,0],[11.5,0],[23,0],[6.6,0]],"id":28671742},{"spn":"NaN","spf":"NaN","id":28671742},{"atb":[[2.86,0],[3.15,0],[2.96,0]],"id":38904370},{"atl":[[16,0],[34,0],[11,0],[22,0],[8.4,0]],"id":38904370},{"spn":"NaN","spf":"NaN","id":38904370}],"con":true,"img":false}]}
{"op":"mcm","clk":"5351846461","pt":1646177038468,"mc":[{"id":"1.195453781","rc":[{"atb":[[3.6,46.47],[3.85,21.2],[3.35,51.42]],"id":28866557},{"atl":[[17.5,0.73],[75,0.65],[40,0.62],[12.5,1.05],[25,1]],"id":28866557},{"atb":[[1.6,201.41],[1.55,219.72],[1.65,92.96]],"id":38247349},{"atl":[[3.45,4.93],[3.95,8.19],[4.9,6.19],[2.98,6.1],[5.9,9.86]],"id":38247349},{"atb":[[2.88,64.28],[2.98,30.51],[2.78,67.89]],"id":28671742},{"atl":[[32,1.55],[10.5,1.27],[21,1.2],[8.2,1.67],[15.5,1.66]],"id":28671742},{"atb":[[2.82,66.4],[2.92,62.94],[3.05,29.47]],"id":38904370},{"atl":[[32,1.55],[10.5,1.27],[21,1.2],[8.2,1.67],[15.5,1.66]],"id":38904370}],"con":true,"img":false}]}
{"op":"mcm","clk":"5351867350","pt":1646177513989,"mc":[{"id":"1.195453781","rc":[{"atb":[[2.5,0],[2.6,0],[2.7,0]],"id":41653210},{"atl":[[16.5,0],[8.6,0],[11.5,0],[23,0],[6.6,0]],"id":41653210},{"spn":"NaN","spf":"NaN","id":41653210},{"atb":[[3.6,0],[3.85,0],[3.35,0]],"id":28866557},{"atl":[[17.5,0],[75,0],[40,0],[12.5,0],[25,0]],"id":28866557},{"atb":[[1.4,0],[1.3,0],[1.35,0]],"id":41120152},{"atl":[[4.3,0],[2.86,0],[2.66,0],[3.15,0],[3.65,0]],"id":41120152},{"spn":"NaN","spf":"NaN","id":41120152},{"spn":2.31,"spf":"NaN","id":38247349},{"atb":[[2.88,0],[2.98,0],[2.78,0]],"id":28671742},{"atl":[[32,0],[10.5,0],[21,0],[8.2,0],[15.5,0]],"id":28671742},{"atb":[[2.82,0],[2.92,0],[3.05,0]],"id":38904370},{"atl":[[32,0],[10.5,0],[21,0],[8.2,0],[15.5,0]],"id":38904370}],"con":true,"img":false}]}
{"op":"mcm","clk":"5351867764","pt":1646177524687,"mc":[{"id":"1.195453781","rc":[{"atb":[[2.74,69.45],[2.84,65.67],[2.94,31.14]],"id":41653210},{"atl":[[8,1.72],[10,1.34],[20,1.27],[15,1.72],[30,1.66]],"id":41653210},{"atb":[[4.3,18.31],[3.9,41.67],[3.65,45.6]],"id":28866557},{"atl":[[32,0.77],[21,0.6],[55,0.44],[110,0.44],[15.5,0.83]],"id":28866557},{"atb":[[1.4,302.12],[1.45,134.27],[1.35,345.28]],"id":41120152},{"atl":[[4.5,13.81],[2.9,6.35],[3.25,10.74],[3.75,8.79],[2.7,7.1]],"id":41120152},{"atb":[[2.88,64.28],[2.98,30.51],[2.78,67.89]],"id":28671742},{"atl":[[32,1.55],[10.5,1.27],[21,1.2],[8.2,1.67],[15.5,1.66]],"id":28671742},{"atb":[[2.9,63.6],[3,60.42],[3.25,26.85]],"id":38904370},{"atl":[[16,1.61],[34,1.46],[11,1.2],[22,1.14],[8.4,1.63]],"id":38904370}],"con":true,"img":false}]}
{"op":"mcm","clk":"5351869739","pt":1646177573457,"mc":[{"id":"1.195453781","rc":[{"atb":[[2.74,0],[2.84,0],[2.94,0]],"id":41653210},{"atl":[[8,0],[10,0],[20,0],[15,0],[30,0]],"id":41653210},{"atb":[[4.3,0],[3.9,0],[3.65,0]],"id":28866557},{"atl":[[32,0],[21,0],[55,0],[110,0],[15.5,0]],"id":28866557},{"atb":[[2.88,0],[2.98,0],[2.78,0]],"id":28671742},{"atl":[[32,0],[10.5,0],[21,0],[8.2,0],[15.5,0]],"id":28671742}],"con":true,"img":false}]}
{"op":"mcm","clk":"5351870292","pt":1646177583506,"mc":[{"id":"1.195453781","rc":[{"atb":[[2,120.84],[2.2,50.35],[2.1,109.86]],"id":41653210},{"atl":[[17.5,2.92],[9,3.02],[5.5,2.68],[12.5,2.1],[7,2.01]],"id":41653210},{"spn":3.85,"spf":"NaN","id":41653210},{"atb":[[4,40.28],[4.5,17.26],[3.75,43.94]],"id":28866557},{"atl":[[16,0.8],[34,0.73],[22,0.57],[60,0.4],[120,0.4]],"id":28866557},{"spn":10.25,"spf":"NaN","id":28866557},{"spn":2.07,"spf":"NaN","id":41120152},{"atb":[[2.88,64.28],[2.98,30.51],[2.78,67.89]],"id":28671742},{"atl":[[32,1.55],[10.5,1.27],[21,1.2],[8.2,1.67],[15.5,1.66]],"id":28671742},{"spn":5.59,"spf":"NaN","id":28671742},{"spn":5.82,"spf":"NaN","id":38904370}],"con":true,"img":false}]}
{"op":"mcm","clk":"5351872453","pt":1646177632348,"mc":[{"id":"1.195453781","rc":[{"atb":[[2,0],[2.2,0],[2.1,0]],"id":41653210},{"atl":[[17.5,0],[9,0],[5.5,0],[12.5,0],[7,0]],"id":41653210},{"atb":[[1.4,0],[1.45,0],[1.35,0]],"id":41120152},{"atl":[[4.5,0],[2.9,0],[3.25,0],[3.75,0],[2.7,0]],"id":41120152}],"con":true,"img":false}]}
{"op":"mcm","clk":"5351872618","pt":1646177636453,"mc":[{"id":"1.195453781","rc":[{"atb":[[2.3,46.47],[2.2,100.7],[2.1,109.86]],"id":41653210},{"atl":[[5.6,2.62],[7.2,1.94],[18,2.84],[9.2,2.94],[13,2.01]],"id":41653210},{"atb":[[1.45,268.55],[1.55,109.86],[1.5,241.69]],"id":41120152},{"atl":[[2.82,6.64],[5.1,11.79],[4.1,7.79],[3.55,9.47],[3.05,5.89]],"id":41120152}],"con":true,"img":false}]}
{"op":"mcm","clk":"5352003900","pt":1646180202630,"mc":[{"id":"1.195453781","marketDefinition":{"bspMarket":true,"turnInPlayEnabled":false,"persistenceEnabled":false,"marketBaseRate":7.0,"eventId":"31272499","eventTypeId":"4339","numberOfWinners":3,"bettingType":"ODDS","marketType":"PLACE","marketTime":"2022-03-02T11:39:00.000Z","suspendTime":"2022-03-02T11:39:00.000Z","bspReconciled":false,"complete":true,"inPlay":false,"crossMatching":false,"runnersVoidable":false,"numberOfActiveRunners":8,"betDelay":0,"status":"OPEN","runners":[{"status":"ACTIVE","sortPriority":1,"id":40917608,"name":"1. Blazing Norman"},{"status":"ACTIVE","sortPriority":2,"id":38904370,"name":"2. Blazing Brothers"},{"status":"ACTIVE","sortPriority":3,"id":38247349,"name":"3. Hearts Thunder"},{"status":"ACTIVE","sortPriority":4,"id":42472248,"name":"4. Paddy Hayze"},{"status":"ACTIVE","sortPriority":5,"id":28671742,"name":"5. Hooper"},{"status":"ACTIVE","sortPriority":6,"id":41653210,"name":"6. Go Again Bear"},{"status":"ACTIVE","sortPriority":7,"id":41120152,"name":"8. Rosas Memory"},{"status":"ACTIVE","sortPriority":8,"id":28866557,"name":"9. Black Magic Ryno"}],"regulators":["MR_INT"],"venue":"Rockhampton","countryCode":"AU","discountAllowed":true,"timezone":"Australia/Queensland","openDate":"2022-03-02T08:34:00.000Z","version":4382437847,"name":"To Be Placed","eventName":"Rockhampton (AUS) 2nd Mar"},"rc":[{"atb":[[2.3,46.48],[2.2,100.71],[2.1,109.87]],"id":41653210},{"atl":[[5.6,2.62],[7.2,1.94],[18,2.84],[9.2,2.94],[13,2.01]],"id":41653210},{"spn":3.95,"spf":"NaN","id":41653210},{"atb":[[4,40.28],[4.5,17.26],[3.75,43.95]],"id":28866557},{"atl":[[16,0.8],[34,0.73],[22,0.57],[60,0.4],[120,0.4]],"id":28866557},{"spn":10.25,"spf":"NaN","id":28866557},{"atb":[[1.45,268.58],[1.55,109.87],[1.5,241.72]],"id":41120152},{"atl":[[2.82,6.64],[5.1,11.79],[4.1,7.79],[3.55,9.47],[3.05,5.89]],"id":41120152},{"spn":2.18,"spf":"NaN","id":41120152},{"atb":[[1.01,12086.23],[1.09,671.45],[1.04,3021.55]],"id":40917608},{"atl":[[2.72,14.05],[2.92,25.17],[2.32,9.15],[2.52,15.9],[2.12,10.79]],"id":40917608},{"spn":1.6,"spf":"NaN","id":40917608},{"atb":[[1.4,302.15],[1.45,134.29],[1.35,345.32]],"id":42472248},{"atl":[[4.5,13.81],[2.9,6.35],[3.25,10.74],[3.75,8.79],[2.7,7.11]],"id":42472248},{"spn":2.07,"spf":"NaN","id":42472248},{"atb":[[1.6,201.43],[1.55,219.75],[1.65,92.97]],"id":38247349},{"atl":[[3.45,4.93],[3.95,8.19],[4.9,6.19],[2.98,6.1],[5.9,9.86]],"id":38247349},{"spn":2.31,"spf":"NaN","id":38247349},{"atb":[[2.88,64.29],[2.98,30.52],[2.78,67.9]],"id":28671742},{"atl":[[32,1.55],[10.5,1.27],[21,1.2],[8.2,1.67],[15.5,1.66]],"id":28671742},{"spn":5.59,"spf":"NaN","id":28671742},{"atb":[[2.9,63.61],[3,60.43],[3.25,26.85]],"id":38904370},{"atl":[[16,1.61],[34,1.46],[11,1.2],[22,1.14],[8.4,1.63]],"id":38904370},{"spn":5.82,"spf":"NaN","id":38904370}],"con":true,"img":true}]}
{"op":"mcm","clk":"5352146212","pt":1646183572669,"mc":[{"id":"1.195453781","marketDefinition":{"bspMarket":true,"turnInPlayEnabled":false,"persistenceEnabled":false,"marketBaseRate":7.0,"eventId":"31272499","eventTypeId":"4339","numberOfWinners":3,"bettingType":"ODDS","marketType":"PLACE","marketTime":"2022-03-02T11:39:00.000Z","suspendTime":"2022-03-02T11:39:00.000Z","bspReconciled":false,"complete":true,"inPlay":false,"crossMatching":false,"runnersVoidable":false,"numberOfActiveRunners":8,"betDelay":0,"status":"OPEN","runners":[{"status":"ACTIVE","sortPriority":1,"id":40917608,"name":"1. Blazing Norman"},{"status":"ACTIVE","sortPriority":2,"id":38904370,"name":"2. Blazing Brothers"},{"status":"ACTIVE","sortPriority":3,"id":38247349,"name":"3. Hearts Thunder"},{"status":"ACTIVE","sortPriority":4,"id":42472248,"name":"4. Paddy Hayze"},{"status":"ACTIVE","sortPriority":5,"id":28671742,"name":"5. Hooper"},{"status":"ACTIVE","sortPriority":6,"id":41653210,"name":"6. Go Again Bear"},{"status":"ACTIVE","sortPriority":7,"id":41120152,"name":"8. Rosas Memory"},{"status":"ACTIVE","sortPriority":8,"id":28866557,"name":"9. Black Magic Ryno"}],"regulators":["MR_INT"],"venue":"Rockhampton","countryCode":"AU","discountAllowed":true,"timezone":"Australia/Queensland","openDate":"2022-03-02T08:28:00.000Z","version":4382597854,"name":"To Be Placed","eventName":"Rockhampton (AUS) 2nd Mar"},"rc":[],"con":true,"img":false}]}
{"op":"mcm","clk":"5352165500","pt":1646184089748,"mc":[{"id":"1.195453781","marketDefinition":{"bspMarket":true,"turnInPlayEnabled":false,"persistenceEnabled":false,"marketBaseRate":7.0,"eventId":"31272499","eventTypeId":"4339","numberOfWinners":3,"bettingType":"ODDS","marketType":"PLACE","marketTime":"2022-03-02T11:29:00.000Z","suspendTime":"2022-03-02T11:29:00.000Z","bspReconciled":false,"complete":true,"inPlay":false,"crossMatching":false,"runnersVoidable":false,"numberOfActiveRunners":8,"betDelay":0,"status":"OPEN","runners":[{"status":"ACTIVE","sortPriority":1,"id":40917608,"name":"1. Blazing Norman"},{"status":"ACTIVE","sortPriority":2,"id":38904370,"name":"2. Blazing Brothers"},{"status":"ACTIVE","sortPriority":3,"id":38247349,"name":"3. Hearts Thunder"},{"status":"ACTIVE","sortPriority":4,"id":42472248,"name":"4. Paddy Hayze"},{"status":"ACTIVE","sortPriority":5,"id":28671742,"name":"5. Hooper"},{"status":"ACTIVE","sortPriority":6,"id":41653210,"name":"6. Go Again Bear"},{"status":"ACTIVE","sortPriority":7,"id":41120152,"name":"8. Rosas Memory"},{"status":"ACTIVE","sortPriority":8,"id":28866557,"name":"9. Black Magic Ryno"}],"regulators":["MR_INT"],"venue":"Rockhampton","countryCode":"AU","discountAllowed":true,"timezone":"Australia/Queensland","openDate":"2022-03-02T08:28:00.000Z","version":4382606664,"name":"To Be Placed","eventName":"Rockhampton (AUS) 2nd Mar"},"rc":[],"con":true,"img":false}]}
{"op":"mcm","clk":"5352238020","pt":1646185602659,"mc":[{"id":"1.195453781","marketDefinition":{"bspMarket":true,"turnInPlayEnabled":false,"persistenceEnabled":false,"marketBaseRate":7.0,"eventId":"31272499","eventTypeId":"4339","numberOfWinners":3,"bettingType":"ODDS","marketType":"PLACE","marketTime":"2022-03-02T11:29:00.000Z","suspendTime":"2022-03-02T11:29:00.000Z","bspReconciled":false,"complete":true,"inPlay":false,"crossMatching":false,"runnersVoidable":false,"numberOfActiveRunners":8,"betDelay":0,"status":"OPEN","runners":[{"status":"ACTIVE","sortPriority":1,"id":40917608,"name":"1. Blazing Norman"},{"status":"ACTIVE","sortPriority":2,"id":38904370,"name":"2. Blazing Brothers"},{"status":"ACTIVE","sortPriority":3,"id":38247349,"name":"3. Hearts Thunder"},{"status":"ACTIVE","sortPriority":4,"id":42472248,"name":"4. Paddy Hayze"},{"status":"ACTIVE","sortPriority":5,"id":28671742,"name":"5. Hooper"},{"status":"ACTIVE","sortPriority":6,"id":41653210,"name":"6. Go Again Bear"},{"status":"ACTIVE","sortPriority":7,"id":41120152,"name":"8. Rosas Memory"},{"status":"ACTIVE","sortPriority":8,"id":28866557,"name":"9. Black Magic Ryno"}],"regulators":["MR_INT"],"venue":"Rockhampton","countryCode":"AU","discountAllowed":true,"timezone":"Australia/Queensland","openDate":"2022-03-02T08:28:00.000Z","version":4382606664,"name":"To Be Placed","eventName":"Rockhampton (AUS) 2nd Mar"},"rc":[{"atb":[[2.3,46.55],[2.2,100.87],[2.1,110.04]],"id":41653210},{"atl":[[5.6,2.63],[7.2,1.95],[18,2.84],[9.2,2.94],[13,2.01]],"id":41653210},{"spn":3.95,"spf":"NaN","id":41653210},{"atb":[[4,40.35],[4.5,17.29],[3.75,44.02]],"id":28866557},{"atl":[[16,0.8],[34,0.73],[22,0.57],[60,0.4],[120,0.4]],"id":28866557},{"spn":10.25,"spf":"NaN","id":28866557},{"atb":[[1.45,269],[1.55,110.04],[1.5,242.1]],"id":41120152},{"atl":[[2.82,6.65],[5.1,11.81],[4.1,7.8],[3.55,9.49],[3.05,5.9]],"id":41120152},{"spn":2.18,"spf":"NaN","id":41120152},{"atb":[[1.01,12105.34],[1.09,672.51],[1.04,3026.33]],"id":40917608},{"atl":[[2.72,14.07],[2.92,25.21],[2.32,9.17],[2.52,15.92],[2.12,10.8]],"id":40917608},{"spn":1.6,"spf":"NaN","id":40917608},{"atb":[[1.4,302.63],[1.45,134.5],[1.35,345.86]],"id":42472248},{"atl":[[4.5,13.83],[2.9,6.36],[3.25,10.75],[3.75,8.8],[2.7,7.12]],"id":42472248},{"spn":2.07,"spf":"NaN","id":42472248},{"atb":[[1.6,201.75],[1.55,220.09],[1.65,93.11]],"id":38247349},{"atl":[[3.45,4.94],[3.95,8.2],[4.9,6.2],[2.98,6.11],[5.9,9.88]],"id":38247349},{"spn":2.31,"spf":"NaN","id":38247349},{"atb":[[2.88,64.39],[2.98,30.56],[2.78,68]],"id":28671742},{"atl":[[32,1.55],[10.5,1.27],[21,1.21],[8.2,1.67],[15.5,1.66]],"id":28671742},{"spn":5.59,"spf":"NaN","id":28671742},{"atb":[[2.9,63.71],[3,60.52],[3.25,26.89]],"id":38904370},{"atl":[[16,1.61],[34,1.46],[11,1.21],[22,1.15],[8.4,1.63]],"id":38904370},{"spn":5.82,"spf":"NaN","id":38904370}],"con":true,"img":true}]}
{"op":"mcm","clk":"5352465317","pt":1646191002609,"mc":[{"id":"1.195453781","marketDefinition":{"bspMarket":true,"turnInPlayEnabled":false,"persistenceEnabled":false,"marketBaseRate":7.0,"eventId":"31272499","eventTypeId":"4339","numberOfWinners":3,"bettingType":"ODDS","marketType":"PLACE","marketTime":"2022-03-02T11:29:00.000Z","suspendTime":"2022-03-02T11:29:00.000Z","bspReconciled":false,"complete":true,"inPlay":false,"crossMatching":false,"runnersVoidable":false,"numberOfActiveRunners":8,"betDelay":0,"status":"OPEN","runners":[{"status":"ACTIVE","sortPriority":1,"id":40917608,"name":"1. Blazing Norman"},{"status":"ACTIVE","sortPriority":2,"id":38904370,"name":"2. Blazing Brothers"},{"status":"ACTIVE","sortPriority":3,"id":38247349,"name":"3. Hearts Thunder"},{"status":"ACTIVE","sortPriority":4,"id":42472248,"name":"4. Paddy Hayze"},{"status":"ACTIVE","sortPriority":5,"id":28671742,"name":"5. Hooper"},{"status":"ACTIVE","sortPriority":6,"id":41653210,"name":"6. Go Again Bear"},{"status":"ACTIVE","sortPriority":7,"id":41120152,"name":"8. Rosas Memory"},{"status":"ACTIVE","sortPriority":8,"id":28866557,"name":"9. Black Magic Ryno"}],"regulators":["MR_INT"],"venue":"Rockhampton","countryCode":"AU","discountAllowed":true,"timezone":"Australia/Queensland","openDate":"2022-03-02T08:28:00.000Z","version":4382606664,"name":"To Be Placed","eventName":"Rockhampton (AUS) 2nd Mar"},"rc":[{"atb":[[2.3,46.63],[2.2,101.04],[2.1,110.23]],"id":41653210},{"atl":[[5.6,2.63],[7.2,1.95],[18,2.85],[9.2,2.95],[13,2.02]],"id":41653210},{"spn":3.95,"spf":"NaN","id":41653210},{"atb":[[4,40.41],[4.5,17.32],[3.75,44.09]],"id":28866557},{"atl":[[16,0.8],[34,0.73],[22,0.57],[60,0.4],[120,0.4]],"id":28866557},{"spn":10.25,"spf":"NaN","id":28866557},{"atb":[[1.45,269.46],[1.55,110.23],[1.5,242.51]],"id":41120152},{"atl":[[2.82,6.66],[5.1,11.83],[4.1,7.82],[3.55,9.5],[3.05,5.91]],"id":41120152},{"spn":2.18,"spf":"NaN","id":41120152},{"atb":[[1.01,12125.84],[1.09,673.65],[1.04,3031.46]],"id":40917608},{"atl":[[2.72,14.09],[2.92,25.26],[2.32,9.18],[2.52,15.95],[2.12,10.82]],"id":40917608},{"spn":1.6,"spf":"NaN","id":40917608},{"atb":[[1.4,303.14],[1.45,134.73],[1.35,346.45]],"id":42472248},{"atl":[[4.5,13.85],[2.9,6.37],[3.25,10.77],[3.75,8.82],[2.7,7.13]],"id":42472248},{"spn":2.07,"spf":"NaN","id":42472248},{"atb":[[1.6,202.09],[1.55,220.47],[1.65,93.27]],"id":38247349},{"atl":[[3.45,4.94],[3.95,8.22],[4.9,6.21],[2.98,6.12],[5.9,9.89]],"id":38247349},{"spn":2.31,"spf":"NaN","id":38247349},{"atb":[[2.88,64.5],[2.98,30.62],[2.78,68.12]],"id":28671742},{"atl":[[32,1.56],[10.5,1.27],[21,1.21],[8.2,1.68],[15.5,1.67]],"id":28671742},{"spn":5.59,"spf":"NaN","id":28671742},{"atb":[[2.9,63.81],[3,60.62],[3.25,26.94]],"id":38904370},{"atl":[[16,1.61],[34,1.46],[11,1.21],[22,1.15],[8.4,1.63]],"id":38904370},{"spn":5.82,"spf":"NaN","id":38904370}],"con":true,"img":true}]}
{"op":"mcm","clk":"5352732298","pt":1646198603668,"mc":[{"id":"1.195453781","rc":[{"atb":[[2.3,46.61],[2.2,101.01],[2.1,110.19]],"id":41653210},{"atl":[[5.6,2.63],[7.2,1.95],[18,2.85],[9.2,2.95],[13,2.02]],"id":41653210},{"spn":3.95,"spf":"NaN","id":41653210},{"atb":[[4,0],[4.5,0],[3.75,0]],"id":28866557},{"atl":[[16,0],[34,0],[22,0],[60,0],[120,0]],"id":28866557},{"spn":"NaN","spf":"NaN","id":28866557},{"atb":[[1.45,0],[1.55,0],[1.5,0]],"id":41120152},{"atl":[[2.82,0],[5.1,0],[4.1,0],[3.55,0],[3.05,0]],"id":41120152},{"spn":"NaN","spf":"NaN","id":41120152},{"atb":[[1.01,0],[1.09,0],[1.04,0]],"id":40917608},{"atl":[[2.72,0],[2.92,0],[2.32,0],[2.52,0],[2.12,0]],"id":40917608},{"spn":"NaN","spf":"NaN","id":40917608},{"atb":[[1.4,0],[1.45,0],[1.35,0]],"id":42472248},{"atl":[[4.5,0],[2.9,0],[3.25,0],[3.75,0],[2.7,0]],"id":42472248},{"spn":"NaN","spf":"NaN","id":42472248},{"atb":[[1.6,0],[1.55,0],[1.65,0]],"id":38247349},{"atl":[[3.45,0],[3.95,0],[4.9,0],[2.98,0],[5.9,0]],"id":38247349},{"spn":"NaN","spf":"NaN","id":38247349},{"atb":[[2.88,64.47],[2.98,30.6],[2.78,68.09]],"id":28671742},{"atl":[[32,1.56],[10.5,1.27],[21,1.21],[8.2,1.68],[15.5,1.67]],"id":28671742},{"atb":[[2.9,0],[3,0],[3.25,0]],"id":38904370},{"atl":[[16,0],[34,0],[11,0],[22,0],[8.4,0]],"id":38904370},{"spn":"NaN","spf":"NaN","id":38904370}],"con":true,"img":false}]}
{"op":"mcm","clk":"5352732765","pt":1646198617584,"mc":[{"id":"1.195453781","rc":[{"atb":[[4,40.4],[4.5,17.31],[3.75,44.07]],"id":28866557},{"atl":[[16,0.8],[34,0.73],[22,0.57],[60,0.4],[120,0.4]],"id":28866557},{"atb":[[1.01,12121.21],[1.02,6060.6],[1.07,865.79]],"id":40917608},{"atl":[[2.88,25.78],[2.28,9.46],[2.68,14.43],[2.08,11.22],[2.48,16.38]],"id":40917608},{"atb":[[1.45,269.35],[1.55,110.19],[1.5,242.42]],"id":41120152},{"atl":[[2.82,6.66],[5.1,11.82],[4.1,7.81],[3.55,9.5],[3.05,5.91]],"id":41120152},{"atb":[[1.6,101.01],[1.55,220.38],[1.5,242.42]],"id":42472248},{"atl":[[2.88,6.44],[3.2,5.5],[3.7,8.97],[4.4,7.13],[5.4,11.01]],"id":42472248},{"atb":[[1.6,202.02],[1.55,220.38],[1.65,93.24]],"id":38247349},{"atl":[[3.45,4.94],[3.95,8.21],[4.9,6.21],[2.98,6.12],[5.9,9.89]],"id":38247349},{"atb":[[2.8,67.33],[2.9,31.89],[2.7,71.3]],"id":38904370},{"atl":[[19.5,1.31],[9.8,1.37],[7.8,1.77],[14.5,1.79],[29,1.73]],"id":38904370}],"con":true,"img":false}]}
{"op":"mcm","clk":"5352822113","pt":1646201802647,"mc":[{"id":"1.195453781","marketDefinition":{"bspMarket":true,"turnInPlayEnabled":false,"persistenceEnabled":false,"marketBaseRate":7.0,"eventId":"31272499","eventTypeId":"4339","numberOfWinners":3,"bettingType":"ODDS","marketType":"PLACE","marketTime":"2022-03-02T11:29:00.000Z","suspendTime":"2022-03-02T11:29:00.000Z","bspReconciled":false,"complete":true,"inPlay":false,"crossMatching":false,"runnersVoidable":false,"numberOfActiveRunners":8,"betDelay":0,"status":"OPEN","runners":[{"status":"ACTIVE","sortPriority":1,"id":40917608,"name":"1. Blazing Norman"},{"status":"ACTIVE","sortPriority":2,"id":38904370,"name":"2. Blazing Brothers"},{"status":"ACTIVE","sortPriority":3,"id":38247349,"name":"3. Hearts Thunder"},{"status":"ACTIVE","sortPriority":4,"id":42472248,"name":"4. Paddy Hayze"},{"status":"ACTIVE","sortPriority":5,"id":28671742,"name":"5. Hooper"},{"status":"ACTIVE","sortPriority":6,"id":41653210,"name":"6. Go Again Bear"},{"status":"ACTIVE","sortPriority":7,"id":41120152,"name":"8. Rosas Memory"},{"status":"ACTIVE","sortPriority":8,"id":28866557,"name":"9. Black Magic Ryno"}],"regulators":["MR_INT"],"venue":"Rockhampton","countryCode":"AU","discountAllowed":true,"timezone":"Australia/Queensland","openDate":"2022-03-02T08:28:00.000Z","version":4382606664,"name":"To Be Placed","eventName":"Rockhampton (AUS) 2nd Mar"},"rc":[{"atb":[[2.3,46.61],[2.2,101.01],[2.1,110.19]],"id":41653210},{"atl":[[5.6,2.63],[7.2,1.95],[18,2.85],[9.2,2.95],[13,2.02]],"id":41653210},{"spn":3.95,"spf":"NaN","id":41653210},{"atb":[[4,40.4],[4.5,17.31],[3.75,44.07]],"id":28866557},{"atl":[[16,0.8],[34,0.73],[22,0.57],[60,0.4],[120,0.4]],"id":28866557},{"spn":10.25,"spf":"NaN","id":28866557},{"atb":[[1.45,269.35],[1.55,110.19],[1.5,242.42]],"id":41120152},{"atl":[[2.82,6.66],[5.1,11.82],[4.1,7.81],[3.55,9.5],[3.05,5.91]],"id":41120152},{"spn":2.18,"spf":"NaN","id":41120152},{"atb":[[1.01,12121.21],[1.02,6060.6],[1.07,865.79]],"id":40917608},{"atl":[[2.88,25.78],[2.28,9.46],[2.68,14.43],[2.08,11.22],[2.48,16.38]],"id":40917608},{"spn":1.57,"spf":"NaN","id":40917608},{"atb":[[1.6,101.01],[1.55,220.38],[1.5,242.42]],"id":42472248},{"atl":[[2.88,6.44],[3.2,5.5],[3.7,8.97],[4.4,7.13],[5.4,11.01]],"id":42472248},{"spn":2.24,"spf":"NaN","id":42472248},{"atb":[[1.6,202.02],[1.55,220.38],[1.65,93.24]],"id":38247349},{"atl":[[3.45,4.94],[3.95,8.21],[4.9,6.21],[2.98,6.12],[5.9,9.89]],"id":38247349},{"spn":2.31,"spf":"NaN","id":38247349},{"atb":[[2.88,64.47],[2.98,30.6],[2.78,68.09]],"id":28671742},{"atl":[[32,1.56],[10.5,1.27],[21,1.21],[8.2,1.68],[15.5,1.67]],"id":28671742},{"spn":5.59,"spf":"NaN","id":28671742},{"atb":[[2.8,67.33],[2.9,31.89],[2.7,71.3]],"id":38904370},{"atl":[[19.5,1.31],[9.8,1.37],[7.8,1.77],[14.5,1.79],[29,1.73]],"id":38904370},{"spn":5.35,"spf":"NaN","id":38904370}],"con":true,"img":true}]}
{"op":"mcm","clk":"5353027488","pt":1646207202684,"mc":[{"id":"1.195453781","marketDefinition":{"bspMarket":true,"turnInPlayEnabled":false,"persistenceEnabled":false,"marketBaseRate":7.0,"eventId":"31272499","eventTypeId":"4339","numberOfWinners":3,"bettingType":"ODDS","marketType":"PLACE","marketTime":"2022-03-02T11:29:00.000Z","suspendTime":"2022-03-02T11:29:00.000Z","bspReconciled":false,"complete":true,"inPlay":false,"crossMatching":false,"runnersVoidable":false,"numberOfActiveRunners":8,"betDelay":0,"status":"OPEN","runners":[{"status":"ACTIVE","sortPriority":1,"id":40917608,"name":"1. Blazing Norman"},{"status":"ACTIVE","sortPriority":2,"id":38904370,"name":"2. Blazing Brothers"},{"status":"ACTIVE","sortPriority":3,"id":38247349,"name":"3. Hearts Thunder"},{"status":"ACTIVE","sortPriority":4,"id":42472248,"name":"4. Paddy Hayze"},{"status":"ACTIVE","sortPriority":5,"id":28671742,"name":"5. Hooper"},{"status":"ACTIVE","sortPriority":6,"id":41653210,"name":"6. Go Again Bear"},{"status":"ACTIVE","sortPriority":7,"id":41120152,"name":"8. Rosas Memory"},{"status":"ACTIVE","sortPriority":8,"id":28866557,"name":"9. Black Magic Ryno"}],"regulators":["MR_INT"],"venue":"Rockhampton","countryCode":"AU","discountAllowed":true,"timezone":"Australia/Queensland","openDate":"2022-03-02T08:28:00.000Z","version":4382606664,"name":"To Be Placed","eventName":"Rockhampton (AUS) 2nd Mar"},"rc":[{"atb":[[2.3,46.6],[2.2,100.98],[2.1,110.16]],"id":41653210},{"atl":[[5.6,2.63],[7.2,1.95],[18,2.84],[9.2,2.95],[13,2.01]],"id":41653210},{"spn":3.95,"spf":"NaN","id":41653210},{"atb":[[4,40.39],[4.5,17.3],[3.75,44.06]],"id":28866557},{"atl":[[16,0.8],[34,0.73],[22,0.57],[60,0.4],[120,0.4]],"id":28866557},{"spn":10.25,"spf":"NaN","id":28866557},{"atb":[[1.45,269.28],[1.55,110.16],[1.5,242.35]],"id":41120152},{"atl":[[2.82,6.65],[5.1,11.82],[4.1,7.81],[3.55,9.5],[3.05,5.91]],"id":41120152},{"spn":2.18,"spf":"NaN","id":41120152},{"atb":[[1.01,12117.9],[1.02,6058.95],[1.07,865.56]],"id":40917608},{"atl":[[2.88,25.78],[2.28,9.46],[2.68,14.42],[2.08,11.22],[2.48,16.37]],"id":40917608},{"spn":1.57,"spf":"NaN","id":40917608},{"atb":[[1.6,100.98],[1.55,220.32],[1.5,242.35]],"id":42472248},{"atl":[[2.88,6.44],[3.2,5.5],[3.7,8.97],[4.4,7.12],[5.4,11.01]],"id":42472248},{"spn":2.24,"spf":"NaN","id":42472248},{"atb":[[1.6,201.96],[1.55,220.32],[1.65,93.21]],"id":38247349},{"atl":[[3.45,4.94],[3.95,8.21],[4.9,6.21],[2.98,6.11],[5.9,9.89]],"id":38247349},{"spn":2.31,"spf":"NaN","id":38247349},{"atb":[[2.88,64.45],[2.98,30.6],[2.78,68.07]],"id":28671742},{"atl":[[32,1.56],[10.5,1.27],[21,1.21],[8.2,1.68],[15.5,1.67]],"id":28671742},{"spn":5.59,"spf":"NaN","id":28671742},{"atb":[[2.8,67.31],[2.9,31.88],[2.7,71.28]],"id":38904370},{"atl":[[19.5,1.31],[9.8,1.37],[7.8,1.77],[14.5,1.79],[29,1.73]],"id":38904370},{"spn":5.35,"spf":"NaN","id":38904370}],"con":true,"img":true}]}
{"op":"mcm","clk":"5353298841","pt":1646212602694,"mc":[{"id":"1.195453781","marketDefinition":{"bspMarket":true,"turnInPlayEnabled":false,"persistenceEnabled":false,"marketBaseRate":7.0,"eventId":"31272499","eventTypeId":"4339","numberOfWinners":3,"bettingType":"ODDS","marketType":"PLACE","marketTime":"2022-03-02T11:29:00.000Z","suspendTime":"2022-03-02T11:29:00.000Z","bspReconciled":false,"complete":true,"inPlay":false,"crossMatching":false,"runnersVoidable":false,"numberOfActiveRunners":8,"betDelay":0,"status":"OPEN","runners":[{"status":"ACTIVE","sortPriority":1,"id":40917608,"name":"1. Blazing Norman"},{"status":"ACTIVE","sortPriority":2,"id":38904370,"name":"2. Blazing Brothers"},{"status":"ACTIVE","sortPriority":3,"id":38247349,"name":"3. Hearts Thunder"},{"status":"ACTIVE","sortPriority":4,"id":42472248,"name":"4. Paddy Hayze"},{"status":"ACTIVE","sortPriority":5,"id":28671742,"name":"5. Hooper"},{"status":"ACTIVE","sortPriority":6,"id":41653210,"name":"6. Go Again Bear"},{"status":"ACTIVE","sortPriority":7,"id":41120152,"name":"8. Rosas Memory"},{"status":"ACTIVE","sortPriority":8,"id":28866557,"name":"9. Black Magic Ryno"}],"regulators":["MR_INT"],"venue":"Rockhampton","countryCode":"AU","discountAllowed":true,"timezone":"Australia/Queensland","openDate":"2022-03-02T08:28:00.000Z","version":4382606664,"name":"To Be Placed","eventName":"Rockhampton (AUS) 2nd Mar"},"rc":[{"atb":[[2.3,46.53],[2.2,100.82],[2.1,109.98]],"id":41653210},{"atl":[[5.6,2.63],[7.2,1.95],[18,2.84],[9.2,2.94],[13,2.01]],"id":41653210},{"spn":3.95,"spf":"NaN","id":41653210},{"atb":[[4,40.32],[4.5,17.28],[3.75,43.99]],"id":28866557},{"atl":[[16,0.8],[34,0.73],[22,0.57],[60,0.4],[120,0.4]],"id":28866557},{"spn":10.25,"spf":"NaN","id":28866557},{"atb":[[1.45,268.85],[1.55,109.98],[1.5,241.97]],"id":41120152},{"atl":[[2.82,6.64],[5.1,11.8],[4.1,7.8],[3.55,9.48],[3.05,5.9]],"id":41120152},{"spn":2.18,"spf":"NaN","id":41120152},{"atb":[[1.01,12098.75],[1.02,6049.37],[1.07,864.19]],"id":40917608},{"atl":[[2.88,25.73],[2.28,9.45],[2.68,14.4],[2.08,11.2],[2.48,16.34]],"id":40917608},{"spn":1.57,"spf":"NaN","id":40917608},{"atb":[[1.6,100.82],[1.55,219.97],[1.5,241.97]],"id":42472248},{"atl":[[2.88,6.43],[3.2,5.49],[3.7,8.95],[4.4,7.11],[5.4,10.99]],"id":42472248},{"spn":2.24,"spf":"NaN","id":42472248},{"atb":[[1.6,201.64],[1.55,219.97],[1.65,93.06]],"id":38247349},{"atl":[[3.45,4.93],[3.95,8.2],[4.9,6.2],[2.98,6.1],[5.9,9.87]],"id":38247349},{"spn":2.31,"spf":"NaN","id":38247349},{"atb":[[2.88,64.35],[2.98,30.55],[2.78,67.97]],"id":28671742},{"atl":[[32,1.55],[10.5,1.27],[21,1.2],[8.2,1.67],[15.5,1.66]],"id":28671742},{"spn":5.59,"spf":"NaN","id":28671742},{"atb":[[2.8,67.21],[2.9,31.83],[2.7,71.17]],"id":38904370},{"atl":[[19.5,1.3],[9.8,1.37],[7.8,1.77],[14.5,1.79],[29,1.72]],"id":38904370},{"spn":5.35,"spf":"NaN","id":38904370}],"con":true,"img":true}]}
{"op":"mcm","clk":"5353347386","pt":1646213424664,"mc":[{"id":"1.195453781","rc":[{"atb":[[2.3,46.53],[2.2,100.82],[2.1,109.98]],"id":41653210},{"atl":[[5.6,2.63],[7.2,1.95],[18,2.84],[9.2,2.94],[13,2.01]],"id":41653210},{"atb":[[4,40.32],[4.5,17.28],[3.75,43.99]],"id":28866557},{"atl":[[16,0.8],[34,0.73],[22,0.57],[60,0.4],[120,0.4]],"id":28866557},{"spn":10.25,"spf":"NaN","id":28866557},{"atb":[[1.45,268.85],[1.55,109.98],[1.5,241.97]],"id":41120152},{"atl":[[2.82,6.64],[5.1,11.8],[4.1,7.8],[3.55,9.48],[3.05,5.9]],"id":41120152},{"spn":2.18,"spf":"NaN","id":41120152},{"atb":[[1.01,12098.75],[1.02,6049.37],[1.07,864.19]],"id":40917608},{"atl":[[2.88,25.73],[2.28,9.45],[2.68,14.4],[2.08,11.2],[2.48,16.34]],"id":40917608},{"spn":1.57,"spf":"NaN","id":40917608},{"atb":[[1.6,100.82],[1.55,219.97],[1.5,241.97]],"id":42472248},{"atl":[[2.88,6.43],[3.2,5.49],[3.7,8.95],[4.4,7.11],[5.4,10.99]],"id":42472248},{"spn":2.24,"spf":"NaN","id":42472248},{"atb":[[1.6,201.64],[1.55,219.97],[1.65,93.06]],"id":38247349},{"atl":[[3.45,4.93],[3.95,8.2],[4.9,6.2],[2.98,6.1],[5.9,9.87]],"id":38247349},{"spn":2.31,"spf":"NaN","id":38247349},{"atb":[[2.88,64.35],[2.98,30.55],[2.78,67.97]],"id":28671742},{"atl":[[32,1.55],[10.5,1.27],[21,1.2],[8.2,1.67],[15.5,1.66]],"id":28671742},{"atb":[[2.8,0],[2.9,0],[2.7,0]],"id":38904370},{"atl":[[19.5,0],[9.8,0],[7.8,0],[14.5,0],[29,0]],"id":38904370}],"con":true,"img":false}]}
{"op":"mcm","clk":"5353348298","pt":1646213442874,"mc":[{"id":"1.195453781","rc":[{"atb":[[2.74,69.53],[2.84,65.75],[2.94,31.18]],"id":38904370},{"atl":[[8,1.72],[10,1.34],[20,1.27],[15,1.72],[30,1.66]],"id":38904370}],"con":true,"img":false}]}
{"op":"mcm","clk":"5353454065","pt":1646215224731,"mc":[{"id":"1.195453781","rc":[{"atb":[[2.22,35.73],[2.12,38.69]],"id":41653210},{"atl":[[9,5.44],[8.4,5.89]],"id":41653210},{"atb":[[6,8.71],[5.4,9.43]],"id":28866557},{"atl":[[34,3.46],[36,2.72]],"id":28866557},{"spn":11.0,"spf":"NaN","id":28866557},{"atb":[[1.56,77.85],[1.46,93.19]],"id":41120152},{"atl":[[4.5,11.98],[4.2,13.62]],"id":41120152},{"spn":2.19,"spf":"NaN","id":41120152},{"atb":[[1.11,101.58],[1.1,393.3]],"id":40917608},{"atl":[[1.83,47.38],[1.71,43.59]],"id":40917608},{"spn":1.41,"spf":"NaN","id":40917608},{"atb":[[1.56,72.28],[1.51,75.51]],"id":42472248},{"atl":[[4.5,12.45],[4.9,8.95]],"id":42472248},{"atb":[[1.56,71.04],[1.61,71.47]],"id":38247349},{"atl":[[5.3,9.25],[4.9,17.37]],"id":38247349},{"atb":[[2.8,20.94],[2.94,22.94]],"id":28671742},{"atl":[[13.5,3.48],[14.5,2.79]],"id":28671742},{"atb":[[2.92,23.43],[2.76,23.32]],"id":38904370},{"atl":[[13.5,3.48],[14,3.15]],"id":38904370},{"spn":5.47,"spf":"NaN","id":38904370}],"con":true,"img":false}]}
{"op":"mcm","clk":"5353458641","pt":1646215287331,"mc":[{"id":"1.195453781","rc":[{"atb":[[2.22,0]],"id":41653210},{"atb":[[1.56,0]],"id":42472248},{"atb":[[1.61,0]],"id":38247349},{"atb":[[2.8,0],[2.94,0]],"id":28671742},{"atb":[[2.92,0],[2.76,0]],"id":38904370}],"con":true,"img":false}]}
{"op":"mcm","clk":"5353458650","pt":1646215287433,"mc":[{"id":"1.195453781","rc":[{"atb":[[2.32,35.73]],"id":41653210},{"atb":[[1.61,72.28]],"id":42472248},{"atb":[[1.66,71.47]],"id":38247349},{"atb":[[2.9,20.94],[3,22.94]],"id":28671742},{"atb":[[2.86,23.32],[2.96,23.43]],"id":38904370}],"con":true,"img":false}]}
{"op":"mcm","clk":"5353631775","pt":1646216975402,"mc":[{"id":"1.195453781","rc":[{"atb":[[2.24,80.65]],"id":41653210},{"atl":[[7,5.45]],"id":41653210},{"spn":3.96,"spf":"NaN","id":41653210},{"atb":[[2.88,34.56]],"id":28866557},{"atl":[[70,2]],"id":28866557},{"atb":[[1.4,219.98]],"id":41120152},{"atl":[[4,13.3]],"id":41120152},{"atb":[[1.04,2500]],"id":40917608},{"atl":[[2.2,83.33]],"id":40917608},{"atb":[[1.52,192.31]],"id":42472248},{"atl":[[3.45,11.94]],"id":42472248},{"spn":2.24,"spf":"NaN","id":42472248},{"atl":[[4.4,12.22]],"id":38247349},{"spn":2.32,"spf":"NaN","id":38247349},{"atb":[[2.84,54.35]],"id":28671742},{"atl":[[10.5,4.63]],"id":28671742},{"spn":5.6,"spf":"NaN","id":28671742},{"atb":[[1.35,62.36]],"id":38904370},{"atl":[[8,3.72]],"id":38904370},{"spn":5.48,"spf":"NaN","id":38904370}],"con":true,"img":false}]}
{"op":"mcm","clk":"5353631790","pt":1646216975609,"mc":[{"id":"1.195453781","rc":[{"atb":[[2.88,117.54],[2.84,0]],"id":28671742}],"con":true,"img":false}]}
{"op":"mcm","clk":"5353634287","pt":1646217003060,"mc":[{"id":"1.195453781","rc":[{"atl":[[9.6,3.49],[10.5,1.27]],"id":28671742}],"con":true,"img":false}]}
{"op":"mcm","clk":"5353635232","pt":1646217012268,"mc":[{"id":"1.195453781","rc":[{"atb":[[2.24,0],[2.34,46.53]],"id":41653210},{"atl":[[7,0],[6.6,5.45]],"id":41653210},{"atb":[[1.05,2000],[1.04,0]],"id":40917608},{"atb":[[1.56,178.57],[1.52,0]],"id":42472248}],"con":true,"img":false}]}
{"op":"mcm","clk":"5353635703","pt":1646217016744,"mc":[{"id":"1.195453781","rc":[{"atl":[[4.5,0],[3.4,18.16]],"id":42472248}],"con":true,"img":false}]}
{"op":"mcm","clk":"5353635715","pt":1646217016851,"mc":[{"id":"1.195453781","rc":[{"atl":[[4.2,0]],"id":41120152},{"atb":[[1.51,0]],"id":42472248},{"atl":[[4.9,6.2]],"id":38247349}],"con":true,"img":false}]}
{"op":"mcm","clk":"5353635725","pt":1646217016951,"mc":[{"id":"1.195453781","rc":[{"atl":[[3.9,13.62]],"id":41120152},{"atb":[[1.56,254.08]],"id":42472248},{"atl":[[4.3,11.17]],"id":38247349}],"con":true,"img":false}]}
{"op":"mcm","clk":"5353638530","pt":1646217045588,"mc":[{"id":"1.195453781","rc":[{"spn":3.97,"spf":"NaN","id":41653210},{"atb":[[1.46,0]],"id":41120152},{"atl":[[4.5,0],[3.95,14.71]],"id":41120152},{"atl":[[1.71,0]],"id":40917608},{"spn":1.47,"spf":"NaN","id":40917608},{"atb":[[1.56,0]],"id":38247349},{"atl":[[13.5,0]],"id":28671742},{"atl":[[13.5,0]],"id":38904370}],"con":true,"img":false}]}
{"op":"mcm","clk":"5353638543","pt":1646217045692,"mc":[{"id":"1.195453781","rc":[{"atl":[[1.64,43.59]],"id":40917608},{"atb":[[1.51,93.19]],"id":41120152},{"atb":[[1.61,71.04]],"id":38247349},{"atl":[[12,3.48]],"id":28671742},{"atl":[[12,3.48]],"id":38904370}],"con":true,"img":false}]}
{"op":"mcm","clk":"5353640255","pt":1646217065283,"mc":[{"id":"1.195453781","rc":[{"atb":[[2.32,0]],"id":41653210}],"con":true,"img":false}]}
{"op":"mcm","clk":"5353640267","pt":1646217065386,"mc":[{"id":"1.195453781","rc":[{"atb":[[2.36,35.73],[2.32,75.76]],"id":41653210}],"con":true,"img":false}]}
{"op":"mcm","clk":"5353640277","pt":1646217065493,"mc":[{"id":"1.195453781","rc":[{"atb":[[2.34,0]],"id":41653210}],"con":true,"img":false}]}
{"op":"mcm","clk":"5353640291","pt":1646217065594,"mc":[{"id":"1.195453781","rc":[{"atb":[[2.32,0],[2.34,71.46]],"id":41653210}],"con":true,"img":false}]}
{"op":"mcm","clk":"5353642431","pt":1646217087429,"mc":[{"id":"1.195453781","rc":[{"atl":[[1.83,0]],"id":40917608},{"atl":[[4.3,23.23],[5.3,0]],"id":38247349}],"con":true,"img":false}]}
{"op":"mcm","clk":"5353642440","pt":1646217087533,"mc":[{"id":"1.195453781","rc":[{"atl":[[1.75,47.38]],"id":40917608}],"con":true,"img":false}]}
{"op":"mcm","clk":"5353645616","pt":1646217123054,"mc":[{"id":"1.195453781","rc":[{"atb":[[2.24,80.65],[2.34,0]],"id":41653210},{"spn":3.98,"spf":"NaN","id":41653210},{"spn":1.37,"spf":"NaN","id":40917608},{"atb":[[1.56,75.51],[1.52,192.31]],"id":42472248},{"atl":[[9.6,0],[10.5,6.44]],"id":28671742}],"con":true,"img":false}]}
{"op":"mcm","clk":"5353646088","pt":1646217128893,"mc":[{"id":"1.195453781","rc":[{"atb":[[2.36,0]],"id":41653210}],"con":true,"img":false}]}
{"op":"mcm","clk":"5353646096","pt":1646217128959,"mc":[{"id":"1.195453781","rc":[{"atb":[[2.32,35.73]],"id":41653210}],"con":true,"img":false}]}
{"op":"mcm","clk":"5353650099","pt":1646217174141,"mc":[{"id":"1.195453781","rc":[{"atl":[[12,0]],"id":28671742}],"con":true,"img":false}]}
{"op":"mcm","clk":"5353650110","pt":1646217174247,"mc":[{"id":"1.195453781","rc":[{"atl":[[10,3.48]],"id":28671742}],"con":true,"img":false}]}
{"op":"mcm","clk":"5353651812","pt":1646217193153,"mc":[{"id":"1.195453781","rc":[{"spn":3.96,"spf":"NaN","id":41653210},{"atl":[[4.3,11.17]],"id":38247349}],"con":true,"img":false}]}
{"op":"mcm","clk":"5353651825","pt":1646217193257,"mc":[{"id":"1.195453781","rc":[{"atl":[[4.9,18.25]],"id":38247349}],"con":true,"img":false}]}
{"op":"mcm","clk":"5353659423","pt":1646217273764,"mc":[{"id":"1.195453781","rc":[{"atl":[[4.9,6.2]],"id":38247349}],"con":true,"img":false}]}
{"op":"mcm","clk":"5353659431","pt":1646217273865,"mc":[{"id":"1.195453781","rc":[{"atl":[[4.3,23.23]],"id":38247349}],"con":true,"img":false}]}
{"op":"mcm","clk":"5353670582","pt":1646217388201,"mc":[{"id":"1.195453781","rc":[{"atl":[[4.3,11.17]],"id":38247349}],"con":true,"img":false}]}
{"op":"mcm","clk":"5353670592","pt":1646217388303,"mc":[{"id":"1.195453781","rc":[{"atl":[[4.9,18.25]],"id":38247349}],"con":true,"img":false}]}
{"op":"mcm","clk":"5353718896","pt":1646217819737,"mc":[{"id":"1.195453781","rc":[{"atb":[[2.32,0],[2.12,0]],"id":41653210},{"atl":[[9,0],[8.4,0]],"id":41653210},{"spn":3.95,"spf":"NaN","id":41653210},{"atb":[[6,0],[5.4,0]],"id":28866557},{"atl":[[34,0.73],[36,0]],"id":28866557},{"spn":10.25,"spf":"NaN","id":28866557},{"atb":[[1.11,0],[1.1,0]],"id":40917608},{"atl":[[1.64,0],[1.75,0]],"id":40917608},{"spn":1.57,"spf":"NaN","id":40917608},{"atb":[[1.56,0],[1.51,0]],"id":41120152},{"atl":[[3.95,0],[3.9,0]],"id":41120152},{"spn":2.18,"spf":"NaN","id":41120152},{"atb":[[1.56,0],[1.61,0]],"id":42472248},{"atl":[[3.4,0],[4.9,0]],"id":42472248},{"spn":2.24,"spf":"NaN","id":42472248},{"atb":[[1.66,0],[1.61,0]],"id":38247349},{"atl":[[4.3,0],[4.9,6.2]],"id":38247349},{"spn":2.31,"spf":"NaN","id":38247349},{"atb":[[2.9,0],[3,0]],"id":28671742},{"atl":[[10,0],[14.5,0]],"id":28671742},{"spn":5.59,"spf":"NaN","id":28671742},{"atb":[[2.86,0],[2.96,0]],"id":38904370},{"atl":[[12,0],[14,0]],"id":38904370},{"spn":5.47,"spf":"NaN","id":38904370}],"con":true,"img":false}]}
{"op":"mcm","clk":"5353718919","pt":1646217819945,"mc":[{"id":"1.195453781","rc":[{"atb":[[1.05,0],[1.04,2500]],"id":40917608}],"con":true,"img":false}]}
{"op":"mcm","clk":"5353719475","pt":1646217825016,"mc":[{"id":"1.195453781","rc":[{"atl":[[3.45,0],[3.8,15.4]],"id":42472248}],"con":true,"img":false}]}
{"op":"mcm","clk":"5353722724","pt":1646217854775,"mc":[{"id":"1.195453781","rc":[{"atb":[[2.12,38.69],[2.26,34.6]],"id":41653210},{"atl":[[7.8,6.4],[8.4,5.99]],"id":41653210},{"atb":[[6,8.71],[5.4,9.43]],"id":28866557},{"atl":[[32,5.44]],"id":28866557},{"atb":[[1.11,101.58],[1.1,393.3]],"id":40917608},{"atl":[[1.65,43.59],[1.76,51.75]],"id":40917608},{"atb":[[1.51,169.41]],"id":41120152},{"atl":[[3.95,14.71],[3.9,14.78]],"id":41120152},{"atb":[[1.56,141.05]],"id":42472248},{"atl":[[4.6,10.69],[3.75,15.85]],"id":42472248},{"atb":[[1.61,136.69]],"id":38247349},{"atl":[[4.3,13.21],[5,9.94]],"id":38247349},{"atb":[[2.9,19.83],[2.96,22.94]],"id":28671742},{"atl":[[12.5,3.79],[13.5,3.01]],"id":28671742},{"atb":[[2.96,23.43],[2.76,23.32]],"id":38904370},{"atl":[[12.5,3.79],[13,3.42]],"id":38904370}],"con":true,"img":false}]}
{"op":"mcm","clk":"5353723597","pt":1646217863259,"mc":[{"id":"1.195453781","rc":[{"atb":[[2.32,1.66]],"id":41653210},{"atb":[[3,1.66]],"id":28671742},{"atb":[[2.98,1.66]],"id":38904370}],"con":true,"img":false}]}
{"op":"mcm","clk":"5353724306","pt":1646217870194,"mc":[{"id":"1.195453781","marketDefinition":{"bspMarket":true,"turnInPlayEnabled":false,"persistenceEnabled":false,"marketBaseRate":7.0,"eventId":"31272499","eventTypeId":"4339","numberOfWinners":3,"bettingType":"ODDS","marketType":"PLACE","marketTime":"2022-03-02T11:29:00.000Z","suspendTime":"2022-03-02T11:29:00.000Z","bspReconciled":false,"complete":true,"inPlay":false,"crossMatching":true,"runnersVoidable":false,"numberOfActiveRunners":8,"betDelay":0,"status":"OPEN","runners":[{"status":"ACTIVE","sortPriority":1,"id":40917608,"name":"1. Blazing Norman"},{"status":"ACTIVE","sortPriority":2,"id":38904370,"name":"2. Blazing Brothers"},{"status":"ACTIVE","sortPriority":3,"id":38247349,"name":"3. Hearts Thunder"},{"status":"ACTIVE","sortPriority":4,"id":42472248,"name":"4. Paddy Hayze"},{"status":"ACTIVE","sortPriority":5,"id":28671742,"name":"5. Hooper"},{"status":"ACTIVE","sortPriority":6,"id":41653210,"name":"6. Go Again Bear"},{"status":"ACTIVE","sortPriority":7,"id":41120152,"name":"8. Rosas Memory"},{"status":"ACTIVE","sortPriority":8,"id":28866557,"name":"9. Black Magic Ryno"}],"regulators":["MR_INT"],"venue":"Rockhampton","countryCode":"AU","discountAllowed":true,"timezone":"Australia/Queensland","openDate":"2022-03-02T08:28:00.000Z","version":4382606664,"name":"To Be Placed","eventName":"Rockhampton (AUS) 2nd Mar"},"rc":[],"con":true,"img":false}]}
{"op":"mcm","clk":"5353725794","pt":1646217885430,"mc":[{"id":"1.195453781","rc":[{"spn":3.96,"spf":"NaN","id":41653210},{"spn":11.0,"spf":"NaN","id":28866557},{"spn":1.38,"spf":"NaN","id":40917608},{"atl":[[3.45,15.4],[3.8,0]],"id":42472248},{"spn":5.6,"spf":"NaN","id":28671742},{"spn":5.49,"spf":"NaN","id":38904370}],"con":true,"img":false}]}
{"op":"mcm","clk":"5353729543","pt":1646217918592,"mc":[{"id":"1.195453781","rc":[{"atb":[[2.26,0]],"id":41653210},{"atb":[[1.51,83.92]],"id":41120152},{"atb":[[1.56,68.77]],"id":42472248},{"atb":[[1.61,65.21]],"id":38247349},{"atl":[[4.3,25.26],[5,0]],"id":38247349},{"atl":[[12.5,0]],"id":28671742},{"atb":[[2.76,0]],"id":38904370}],"con":true,"img":false}]}
{"op":"mcm","clk":"5353729557","pt":1646217918661,"mc":[{"id":"1.195453781","rc":[{"atb":[[2.32,36.26]],"id":41653210},{"atb":[[1.56,85.48]],"id":41120152},{"atb":[[1.61,72.28]],"id":42472248},{"atb":[[1.66,71.47]],"id":38247349},{"atl":[[10,3.79]],"id":28671742},{"atb":[[2.86,23.32]],"id":38904370}],"con":true,"img":false}]}
{"op":"mcm","clk":"5353732020","pt":1646217941230,"mc":[{"id":"1.195453781","rc":[{"atl":[[3.75,0]],"id":42472248}],"con":true,"img":false}]}
{"op":"mcm","clk":"5353732028","pt":1646217941337,"mc":[{"id":"1.195453781","rc":[{"atl":[[3.4,15.85]],"id":42472248}],"con":true,"img":false}]}
{"op":"mcm","clk":"5353735203","pt":1646217973672,"mc":[{"id":"1.195453781","rc":[{"spn":2.19,"spf":"NaN","id":41120152},{"spn":2.24,"spf":"NaN","id":42472248},{"atb":[[1.7,11.91]],"id":38247349},{"spn":2.34,"spf":"NaN","id":38247349}],"con":true,"img":false}]}
{"op":"mcm","clk":"5353735213","pt":1646217973737,"mc":[{"id":"1.195453781","rc":[{"atb":[[3,4.16]],"id":38904370}],"con":true,"img":false}]}
{"op":"mcm","clk":"5353735233","pt":1646217973945,"mc":[{"id":"1.195453781","rc":[{"atb":[[2.38,6.04]],"id":41653210}],"con":true,"img":false}]}
{"op":"mcm","clk":"5353735265","pt":1646217974257,"mc":[{"id":"1.195453781","rc":[{"atb":[[3.05,4.06]],"id":28671742}],"con":true,"img":false}]}
{"op":"mcm","clk":"5353735281","pt":1646217974490,"mc":[{"id":"1.195453781","rc":[{"atb":[[1.6,13.89]],"id":41120152}],"con":true,"img":false}]}
{"op":"mcm","clk":"5353735327","pt":1646217974980,"mc":[{"id":"1.195453781","rc":[{"atb":[[1.65,12.82]],"id":42472248}],"con":true,"img":false}]}
{"op":"mcm","clk":"5353735650","pt":1646217978268,"mc":[{"id":"1.195453781","rc":[{"atb":[[2.32,34.6]],"id":41653210},{"atb":[[3,0]],"id":28671742},{"atb":[[2.98,0]],"id":38904370}],"con":true,"img":false}]}
{"op":"mcm","clk":"5353735666","pt":1646217978480,"mc":[{"id":"1.195453781","rc":[{"atb":[[2.4,1.66]],"id":41653210},{"atb":[[3.1,1.66]],"id":28671742},{"atb":[[3.05,1.66]],"id":38904370}],"con":true,"img":false}]}
{"op":"mcm","clk":"5353746763","pt":1646218009909,"mc":[{"id":"1.195453781","rc":[{"atb":[[2.96,0]],"id":28671742}],"con":true,"img":false}]}
{"op":"mcm","clk":"5353746773","pt":1646218010014,"mc":[{"id":"1.195453781","rc":[{"atb":[[3,22.94]],"id":28671742}],"con":true,"img":false}]}
{"op":"mcm","clk":"5353748337","pt":1646218026550,"mc":[{"id":"1.195453781","rc":[{"atb":[[2.24,0],[1.71,85.22]],"id":41653210},{"atb":[[2.88,0],[3.15,34.56]],"id":28866557},{"atl":[[2.54,59.95],[2.2,0]],"id":40917608},{"atb":[[1.53,62.36],[1.35,0]],"id":38904370}],"con":true,"img":false}]}
{"op":"mcm","clk":"5353748347","pt":1646218026620,"mc":[{"id":"1.195453781","rc":[{"atb":[[1.08,164.55]],"id":38247349}],"con":true,"img":false}]}
{"op":"mcm","clk":"5353750806","pt":1646218053162,"mc":[{"id":"1.195453781","rc":[{"atb":[[2.38,11.49]],"id":41653210},{"spn":4.0,"spf":"NaN","id":41653210},{"atb":[[1.6,26.43]],"id":41120152},{"spn":2.21,"spf":"NaN","id":41120152},{"atb":[[1.65,24.38]],"id":42472248},{"spn":2.26,"spf":"NaN","id":42472248},{"atb":[[1.7,22.65]],"id":38247349},{"atb":[[3.05,7.73]],"id":28671742},{"spn":5.65,"spf":"NaN","id":28671742},{"atb":[[3,7.92]],"id":38904370},{"spn":5.52,"spf":"NaN","id":38904370}],"con":true,"img":false}]}
{"op":"mcm","clk":"5353773068","pt":1646218310022,"mc":[{"id":"1.195453781","rc":[{"atb":[[1.05,2000]],"id":40917608},{"atb":[[1.56,247.34],[1.52,0]],"id":42472248},{"atb":[[2.88,64.35],[2.68,45.9]],"id":28671742}],"con":true,"img":false}]}
{"op":"mcm","clk":"5353773079","pt":1646218310122,"mc":[{"id":"1.195453781","rc":[{"atb":[[1.04,0]],"id":40917608}],"con":true,"img":false}]}
{"op":"mcm","clk":"5353774073","pt":1646218322949,"mc":[{"id":"1.195453781","rc":[{"atl":[[9.6,3.79],[10.5,1.27]],"id":28671742}],"con":true,"img":false}]}
{"op":"mcm","clk":"5353774500","pt":1646218328648,"mc":[{"id":"1.195453781","rc":[{"atl":[[10,0]],"id":28671742}],"con":true,"img":false}]}
{"op":"mcm","clk":"5353774507","pt":1646218328754,"mc":[{"id":"1.195453781","rc":[{"atl":[[12,3.79]],"id":28671742}],"con":true,"img":false}]}
{"op":"mcm","clk":"5353774900","pt":1646218333555,"mc":[{"id":"1.195453781","rc":[{"atb":[[3,45.89],[2.68,0]],"id":28671742}],"con":true,"img":false}]}
{"op":"mcm","clk":"5353784011","pt":1646218443057,"mc":[{"id":"1.195453781","rc":[{"atb":[[3,22.94],[2.84,54.35]],"id":28671742},{"atl":[[9.6,0],[10.5,6.74]],"id":28671742}],"con":true,"img":false}]}
{"op":"mcm","clk":"5353788722","pt":1646218489801,"mc":[{"id":"1.195453781","rc":[{"atl":[[12,0]],"id":28671742}],"con":true,"img":false}]}
{"op":"mcm","clk":"5353788734","pt":1646218489903,"mc":[{"id":"1.195453781","rc":[{"atl":[[10,3.79]],"id":28671742}],"con":true,"img":false}]}
{"op":"mcm","clk":"5353812702","pt":1646218723663,"mc":[{"id":"1.195453781","rc":[{"atb":[[1.8,85.22],[1.71,0]],"id":41653210},{"atb":[[3.15,0],[3.5,34.56]],"id":28866557},{"atl":[[2.54,0],[2.76,32.7]],"id":40917608},{"atl":[[4,0],[3.3,14.71]],"id":41120152},{"atb":[[1.08,0],[1.17,164.55]],"id":38247349},{"atb":[[1.62,62.36],[1.53,0]],"id":38904370}],"con":true,"img":false}]}
{"op":"mcm","clk":"5353814610","pt":1646218743011,"mc":[{"id":"1.195453781","rc":[{"atb":[[1.84,148.81],[1.88,56.82],[1.9,22.22],[1.86,87.21]],"id":41653210},{"atl":[[4.8,19.74],[4.6,13.89],[5,31.25],[4.4,5.88]],"id":41653210},{"atb":[[3.45,30.61],[3.35,53.19],[3.55,19.61],[3.65,7.55]],"id":28866557},{"atl":[[21,1],[23,2.27],[25,3.12],[27,4.81]],"id":28866557},{"atb":[[1.4,0],[1.46,250],[1.5,341.97],[1.48,364.58],[1.52,38.46]],"id":41120152},{"atl":[[2.36,14.71],[2.4,35.71],[2.44,52.08],[2.48,84.46]],"id":41120152},{"atb":[[1.02,6299.37],[1.06,250],[1.08,250],[1.04,250]],"id":40917608},{"atl":[[2.8,27.78],[2.88,92.22],[2.84,40.76],[2.76,44.06]],"id":40917608},{"atb":[[1.56,283.05],[1.54,92.59],[1.5,491.97],[1.52,144.23]],"id":42472248},{"atl":[[3.2,14.58],[3.4,47.1],[3.3,21.74],[3.5,50]],"id":42472248},{"atb":[[1.27,74.07],[1.25,200],[1.21,250],[1.23,250]],"id":38247349},{"atl":[[3.6,48.08],[3.4,20.83],[3.3,8.7],[3.5,30]],"id":38247349},{"atb":[[3,45.89],[2.98,68.43],[2.84,0],[3.15,9.3],[2.94,64.43],[3.05,32.12]],"id":28671742},{"atl":[[9.6,3.79],[10.5,1.27],[6.2,3.85],[7.4,19.53],[6.6,8.93],[7,12.5]],"id":28671742},{"atb":[[1.72,27.78],[1.7,71.43],[1.68,110.29],[1.66,189.39]],"id":38904370},{"atl":[[6.2,24.04],[5.5,4.44],[5.7,10.64],[5.9,15.31]],"id":38904370}],"con":true,"img":false}]}
{"op":"mcm","clk":"5353814626","pt":1646218743211,"mc":[{"id":"1.195453781","rc":[{"atl":[[8,1.72],[5.9,19.04]],"id":38904370}],"con":true,"img":false}]}
{"op":"mcm","clk":"5353814770","pt":1646218744680,"mc":[{"id":"1.195453781","rc":[{"atb":[[3.05,28.45]],"id":28671742}],"con":true,"img":false}]}
{"op":"mcm","clk":"5353815140","pt":1646218748322,"mc":[{"id":"1.195453781","rc":[{"atl":[[4.3,13.21]],"id":38247349}],"con":true,"img":false}]}
{"op":"mcm","clk":"5353815148","pt":1646218748380,"mc":[{"id":"1.195453781","rc":[{"atl":[[4.8,12.05]],"id":38247349}],"con":true,"img":false}]}
{"op":"mcm","clk":"5353815403","pt":1646218750683,"mc":[{"id":"1.195453781","rc":[{"atb":[[3.1,5.24]],"id":28671742}],"con":true,"img":false}]}
{"op":"mcm","clk":"5353815598","pt":1646218752719,"mc":[{"id":"1.195453781","rc":[{"atb":[[3.1,3.57]],"id":28671742}],"con":true,"img":false}]}
{"op":"mcm","clk":"5353815620","pt":1646218752875,"mc":[{"id":"1.195453781","rc":[{"atb":[[3.2,1.66]],"id":28671742}],"con":true,"img":false}]}
{"op":"mcm","clk":"5353816141","pt":1646218758306,"mc":[{"id":"1.195453781","rc":[{"atb":[[2.12,0],[1.92,48.5]],"id":41653210},{"atb":[[6,0],[5.4,0]],"id":28866557},{"atb":[[1.51,0]],"id":41120152},{"atl":[[2.38,31.59],[3.9,0]],"id":41120152},{"atl":[[2.32,29.79],[1.65,0],[1.76,0]],"id":40917608},{"atb":[[2.4,26.92],[2.9,0]],"id":28671742},{"atb":[[2.26,32.58],[2.86,0]],"id":38904370}],"con":true,"img":false}]}
{"op":"mcm","clk":"5353816150","pt":1646218758410,"mc":[{"id":"1.195453781","rc":[{"atb":[[5.5,8.71],[4.9,9.43]],"id":28866557},{"atb":[[1.47,83.92]],"id":41120152},{"atl":[[2.12,43.59]],"id":40917608}],"con":true,"img":false}]}
{"op":"mcm","clk":"5353817191","pt":1646218768318,"mc":[{"id":"1.195453781","rc":[{"atb":[[3,22.95]],"id":28671742}],"con":true,"img":false}]}
{"op":"mcm","clk":"5353817203","pt":1646218768420,"mc":[{"id":"1.195453781","rc":[{"atb":[[3.1,26.52]],"id":28671742}],"con":true,"img":false}]}
{"op":"mcm","clk":"5353817542","pt":1646218771717,"mc":[{"id":"1.195453781","rc":[{"atb":[[1.09,222.22],[1.08,0]],"id":40917608}],"con":true,"img":false}]}
{"op":"mcm","clk":"5353818135","pt":1646218778240,"mc":[{"id":"1.195453781","rc":[{"atl":[[7.8,0]],"id":41653210},{"atl":[[4.3,0]],"id":38247349},{"atl":[[10,0]],"id":28671742},{"atl":[[12.5,0]],"id":38904370}],"con":true,"img":false}]}
{"op":"mcm","clk":"5353818144","pt":1646218778343,"mc":[{"id":"1.195453781","rc":[{"atl":[[4.7,11.78]],"id":41653210},{"atl":[[32,2.72]],"id":28866557},{"atb":[[1.11,0]],"id":40917608},{"atl":[[3.35,18.55]],"id":38247349},{"atl":[[6.8,7.51]],"id":28671742},{"atl":[[5.8,9.08]],"id":38904370}],"con":true,"img":false}]}
{"op":"mcm","clk":"5353818152","pt":1646218778443,"mc":[{"id":"1.195453781","rc":[{"atl":[[23,4.99]],"id":28866557},{"atb":[[1.24,101.58]],"id":40917608}],"con":true,"img":false}]}
{"op":"mcm","clk":"5353818161","pt":1646218778549,"mc":[{"id":"1.195453781","rc":[{"atl":[[5.7,21.28],[5.9,15.31]],"id":38904370}],"con":true,"img":false}]}
{"op":"mcm","clk":"5353819156","pt":1646218788339,"mc":[{"id":"1.195453781","rc":[{"spn":3.4,"spf":"NaN","id":41653210},{"spn":10.75,"spf":"NaN","id":28866557},{"spn":1.66,"spf":"NaN","id":40917608},{"spn":1.98,"spf":"NaN","id":41120152},{"atl":[[4.6,0],[3.4,31.25]],"id":42472248},{"spn":4.7,"spf":"NaN","id":28671742},{"spn":4.27,"spf":"NaN","id":38904370}],"con":true,"img":false}]}
{"op":"mcm","clk":"5353819168","pt":1646218788444,"mc":[{"id":"1.195453781","rc":[{"atl":[[4.1,10.69],[3.25,15.85]],"id":42472248}],"con":true,"img":false}]}
{"op":"mcm","clk":"5353819492","pt":1646218791824,"mc":[{"id":"1.195453781","rc":[{"atb":[[3.05,24.39]],"id":28671742}],"con":true,"img":false}]}
{"op":"mcm","clk":"5353820093","pt":1646218798263,"mc":[{"id":"1.195453781","rc":[{"atl":[[8.4,0]],"id":41653210},{"atl":[[32,0]],"id":28866557},{"atb":[[1.1,0]],"id":40917608},{"atl":[[3.95,0]],"id":41120152},{"atl":[[4.8,0]],"id":38247349},{"atb":[[3.1,3.57]],"id":28671742},{"atl":[[13.5,0]],"id":28671742},{"atl":[[13,0]],"id":38904370}],"con":true,"img":false}]}
{"op":"mcm","clk":"5353820102","pt":1646218798370,"mc":[{"id":"1.195453781","rc":[{"atl":[[6.6,13.07]],"id":41653210},{"atl":[[22,3.3]],"id":28866557},{"atl":[[3.5,14.71]],"id":41120152},{"atb":[[1.21,187.28]],"id":40917608},{"atl":[[4.3,12.05]],"id":38247349},{"atb":[[3,45.89]],"id":28671742},{"atl":[[9.8,4.28]],"id":28671742},{"atl":[[8.6,5.4]],"id":38904370}],"con":true,"img":false}]}
{"op":"mcm","clk":"5353821238","pt":1646218808248,"mc":[{"id":"1.195453781","rc":[{"atb":[[2.4,1.66],[1.92,48.5],[2.32,34.6],[2.3,46.53],[2.38,11.48],[2.2,100.82],[2.1,109.99]],"id":41653210},{"atl":[[5.6,2.63],[7.2,1.95],[18,2.84],[9.2,2.94],[13,2.01],[6.6,13.08],[4.7,0]],"id":41653210},{"atb":[[4,40.33],[4.5,17.28],[5.5,8.72],[4.9,9.43],[3.75,43.99]],"id":28866557},{"atl":[[22,3.3],[23,4.99]],"id":28866557},{"atb":[[1.56,85.49],[1.6,26.39],[1.45,268.87],[1.55,109.99],[1.5,341.98],[1.47,83.93]],"id":41120152},{"atl":[[2.82,6.64],[5.1,11.8],[4.1,7.8],[2.38,31.59],[3.55,9.48],[3.5,14.71],[3.05,5.9]],"id":41120152},{"atb":[[1.01,12099.41],[1.21,187.29],[1.02,6299.7],[1.07,864.24],[1.24,101.58]],"id":40917608},{"atl":[[2.88,92.23],[2.32,29.79],[2.12,43.6],[2.28,9.45],[2.68,14.4],[2.08,11.2],[2.48,16.35]],"id":40917608},{"atb":[[1.56,283.05],[1.6,100.82],[1.55,219.99],[1.5,491.98],[1.65,24.35],[1.61,72.28]],"id":42472248},{"atl":[[2.88,6.43],[3.2,14.58],[4.1,10.69],[3.7,8.96],[3.25,15.85],[4.4,7.11],[5.4,10.99]],"id":42472248},{"atb":[[1.6,201.65],[1.55,219.99],[1.7,22.63],[1.66,71.47],[1.65,93.07],[1.61,65.22]],"id":38247349},{"atl":[[3.45,4.93],[4.3,12.05],[3.95,8.2],[3.35,18.55],[4.9,6.2],[2.98,6.1],[5.9,9.87]],"id":38247349},{"atb":[[2.4,26.92],[3.2,1.66],[2.88,64.36],[3.1,3.57],[3,45.9],[2.98,68.43],[2.78,67.97]],"id":28671742},{"atl":[[6.8,7.51],[9.8,4.28]],"id":28671742},{"atb":[[2.74,69.53],[3,7.91],[2.84,65.75],[2.26,32.58],[2.96,23.44],[2.94,31.18],[3.05,1.66]],"id":38904370},{"atl":[[8.6,5.4],[5.8,0]],"id":38904370}],"con":true,"img":false}]}
{"op":"mcm","clk":"5353821247","pt":1646218808349,"mc":[{"id":"1.195453781","rc":[{"atl":[[4.5,11.78]],"id":41653210},{"atl":[[5.6,9.08]],"id":38904370}],"con":true,"img":false}]}
{"op":"mcm","clk":"5353821254","pt":1646218808451,"mc":[{"id":"1.195453781","rc":[{"atl":[[5.7,10.64],[5.9,35.72]],"id":38904370}],"con":true,"img":false}]}
{"op":"mcm","clk":"5353822195","pt":1646218817564,"mc":[{"id":"1.195453781","rc":[{"atb":[[3.05,28.45]],"id":28671742}],"con":true,"img":false}]}
{"op":"mcm","clk":"5353822260","pt":1646218818244,"mc":[{"id":"1.195453781","rc":[{"atl":[[22,0.57]],"id":28866557},{"atl":[[5.6,0]],"id":38904370}],"con":true,"img":false}]}
{"op":"mcm","clk":"5353822270","pt":1646218818346,"mc":[{"id":"1.195453781","rc":[{"atl":[[24,2.72]],"id":28866557},{"atl":[[5.8,9.08]],"id":38904370}],"con":true,"img":false}]}
{"op":"mcm","clk":"5353823114","pt":1646218826901,"mc":[{"id":"1.195453781","rc":[{"atl":[[5.7,21.28],[5.9,15.31]],"id":38904370}],"con":true,"img":false}]}
{"op":"mcm","clk":"5353824366","pt":1646218838291,"mc":[{"id":"1.195453781","rc":[{"atb":[[3,22.95]],"id":28671742}],"con":true,"img":false}]}
{"op":"mcm","clk":"5353824372","pt":1646218838396,"mc":[{"id":"1.195453781","rc":[{"atb":[[3.1,26.52]],"id":28671742}],"con":true,"img":false}]}
{"op":"mcm","clk":"5353825329","pt":1646218848291,"mc":[{"id":"1.195453781","rc":[{"atl":[[5.8,0]],"id":38904370}],"con":true,"img":false}]}
{"op":"mcm","clk":"5353825336","pt":1646218848394,"mc":[{"id":"1.195453781","rc":[{"atl":[[5.6,9.08]],"id":38904370}],"con":true,"img":false}]}
{"op":"mcm","clk":"5353825344","pt":1646218848500,"mc":[{"id":"1.195453781","rc":[{"atl":[[5.7,10.64],[5.9,35.72]],"id":38904370}],"con":true,"img":false}]}
{"op":"mcm","clk":"5353826219","pt":1646218858299,"mc":[{"id":"1.195453781","rc":[{"atl":[[5.6,0]],"id":38904370}],"con":true,"img":false}]}
{"op":"mcm","clk":"5353826227","pt":1646218858405,"mc":[{"id":"1.195453781","rc":[{"atl":[[5.8,9.08]],"id":38904370}],"con":true,"img":false}]}
{"op":"mcm","clk":"5353826669","pt":1646218863039,"mc":[{"id":"1.195453781","rc":[{"atb":[[3,0],[2.84,54.35]],"id":28671742}],"con":true,"img":false}]}
{"op":"mcm","clk":"5353827157","pt":1646218868146,"mc":[{"id":"1.195453781","rc":[{"atb":[[3.05,24.39]],"id":28671742}],"con":true,"img":false}]}
{"op":"mcm","clk":"5353828231","pt":1646218878246,"mc":[{"id":"1.195453781","rc":[{"atb":[[3.1,3.57],[3.15,13.17]],"id":28671742}],"con":true,"img":false}]}
{"op":"mcm","clk":"5353828240","pt":1646218878352,"mc":[{"id":"1.195453781","rc":[{"atb":[[3,22.95]],"id":28671742}],"con":true,"img":false}]}
{"op":"mcm","clk":"5353832400","pt":1646218911631,"mc":[{"id":"1.195453781","rc":[{"atb":[[3.15,9.3]],"id":28671742}],"con":true,"img":false}]}
{"op":"mcm","clk":"5353834718","pt":1646218923994,"mc":[{"id":"1.195453781","rc":[{"atb":[[3.05,28.45]],"id":28671742}],"con":true,"img":false}]}
{"op":"mcm","clk":"5353837098","pt":1646218948318,"mc":[{"id":"1.195453781","rc":[{"atb":[[3,0]],"id":28671742}],"con":true,"img":false}]}
{"op":"mcm","clk":"5353837104","pt":1646218948423,"mc":[{"id":"1.195453781","rc":[{"atb":[[3.1,26.52]],"id":28671742}],"con":true,"img":false}]}
{"op":"mcm","clk":"5353848608","pt":1646219082332,"mc":[{"id":"1.195453781","rc":[{"atb":[[3.05,24.39]],"id":28671742}],"con":true,"img":false}]}
{"op":"mcm","clk":"5353849110","pt":1646219088328,"mc":[{"id":"1.195453781","rc":[{"atb":[[3.1,3.57]],"id":28671742}],"con":true,"img":false}]}
{"op":"mcm","clk":"5353849116","pt":1646219088434,"mc":[{"id":"1.195453781","rc":[{"atb":[[3,22.95]],"id":28671742}],"con":true,"img":false}]}
{"op":"mcm","clk":"5353869017","pt":1646219297904,"mc":[{"id":"1.195453781","rc":[{"atb":[[3.05,28.45]],"id":28671742}],"con":true,"img":false}]}
{"op":"mcm","clk":"5353870802","pt":1646219318258,"mc":[{"id":"1.195453781","rc":[{"atb":[[3,0]],"id":28671742}],"con":true,"img":false}]}
{"op":"mcm","clk":"5353870811","pt":1646219318366,"mc":[{"id":"1.195453781","rc":[{"atb":[[3.1,26.52]],"id":28671742}],"con":true,"img":false}]}
{"op":"mcm","clk":"5353872035","pt":1646219330800,"mc":[{"id":"1.195453781","rc":[{"atb":[[2,20],[1.89,87.21],[1.8,0],[1.9,0]],"id":41653210},{"atb":[[3.75,51.26],[3.65,0]],"id":28866557},{"atl":[[3.2,5.49],[3.3,8.7]],"id":42472248},{"atb":[[3.15,0],[3.05,13.82]],"id":28671742}],"con":true,"img":false}]}
{"op":"mcm","clk":"5353872251","pt":1646219332975,"mc":[{"id":"1.195453781","rc":[{"atb":[[3.1,22.95]],"id":28671742}],"con":true,"img":false}]}
{"op":"mcm","clk":"5353872717","pt":1646219337688,"mc":[{"id":"1.195453781","rc":[{"atb":[[3.2,0]],"id":28671742}],"con":true,"img":false}]}
{"op":"mcm","clk":"5353872725","pt":1646219337793,"mc":[{"id":"1.195453781","rc":[{"atb":[[3.15,1.66]],"id":28671742}],"con":true,"img":false}]}
{"op":"mcm","clk":"5353872762","pt":1646219338321,"mc":[{"id":"1.195453781","rc":[{"atl":[[3.25,0]],"id":42472248},{"atb":[[3.1,0]],"id":28671742}],"con":true,"img":false}]}
{"op":"mcm","clk":"5353872769","pt":1646219338384,"mc":[{"id":"1.195453781","rc":[{"atl":[[3.35,15.85]],"id":42472248},{"atb":[[3,22.95]],"id":28671742}],"con":true,"img":false}]}
{"op":"mcm","clk":"5353872819","pt":1646219339007,"mc":[{"id":"1.195453781","rc":[{"atb":[[3.05,17.48]],"id":28671742}],"con":true,"img":false}]}
{"op":"mcm","clk":"5353873003","pt":1646219340816,"mc":[{"id":"1.195453781","rc":[{"atb":[[1.98,51.02]],"id":41653210},{"atb":[[3.65,18.87]],"id":28866557},{"atl":[[3.4,20.83]],"id":42472248},{"atb":[[2.98,55.8]],"id":28671742}],"con":true,"img":false}]}
{"op":"mcm","clk":"5353873332","pt":1646219344231,"mc":[{"id":"1.195453781","rc":[{"atb":[[1.84,0]],"id":41653210},{"atb":[[3.35,0]],"id":28866557}],"con":true,"img":false}]}
{"op":"mcm","clk":"5353873931","pt":1646219350819,"mc":[{"id":"1.195453781","rc":[{"atb":[[1.96,78.12]],"id":41653210},{"atb":[[3.55,29.41]],"id":28866557},{"atl":[[3.5,30]],"id":42472248},{"atb":[[2.94,38.66]],"id":28671742}],"con":true,"img":false}]}
{"op":"mcm","clk":"5353874522","pt":1646219356825,"mc":[{"id":"1.195453781","rc":[{"atb":[[3.15,0]],"id":28671742}],"con":true,"img":false}]}
{"op":"mcm","clk":"5353874533","pt":1646219356933,"mc":[{"id":"1.195453781","rc":[{"atb":[[3.1,1.66]],"id":28671742}],"con":true,"img":false}]}
{"op":"mcm","clk":"5353874900","pt":1646219360831,"mc":[{"id":"1.195453781","rc":[{"atb":[[1.94,132.98],[1.86,0]],"id":41653210},{"atb":[[3.45,51.02]],"id":28866557},{"atl":[[3.6,48.08]],"id":42472248},{"atb":[[2.9,65.79]],"id":28671742},{"spn":4.65,"spf":"NaN","id":28671742}],"con":true,"img":false}]}
{"op":"mcm","clk":"5353875851","pt":1646219370765,"mc":[{"id":"1.195453781","rc":[{"atb":[[1.88,0]],"id":41653210}],"con":true,"img":false}]}
{"op":"mcm","clk":"5353877309","pt":1646219388274,"mc":[{"id":"1.195453781","rc":[{"atb":[[1.92,0]],"id":41653210}],"con":true,"img":false}]}
{"op":"mcm","clk":"5353877320","pt":1646219388377,"mc":[{"id":"1.195453781","rc":[{"atb":[[1.99,48.5]],"id":41653210}],"con":true,"img":false}]}
{"op":"mcm","clk":"5353896634","pt":1646219580177,"mc":[{"id":"1.195453781","rc":[{"atb":[[1.54,129.63]],"id":42472248}],"con":true,"img":false}]}
{"op":"mcm","clk":"5353896647","pt":1646219580277,"mc":[{"id":"1.195453781","rc":[{"atb":[[1.56,247.34],[1.54,37.04]],"id":42472248}],"con":true,"img":false}]}
{"op":"mcm","clk":"5353897651","pt":1646219590181,"mc":[{"id":"1.195453781","rc":[{"atb":[[1.52,96.15]],"id":42472248}],"con":true,"img":false}]}
{"op":"mcm","clk":"5353898503","pt":1646219600216,"mc":[{"id":"1.195453781","rc":[{"atb":[[1.5,391.98]],"id":42472248}],"con":true,"img":false}]}
{"op":"mcm","clk":"5353899517","pt":1646219610165,"mc":[{"id":"1.195453781","rc":[{"atb":[[1.48,250]],"id":42472248}],"con":true,"img":false}]}
{"op":"mcm","clk":"5353900920","pt":1646219624842,"mc":[{"id":"1.195453781","rc":[{"atb":[[3.45,0],[3.1,9.52],[3.55,0],[3.5,0],[2.96,51.02],[3.75,43.99],[3.65,0]],"id":28866557},{"atl":[[2.64,44.9],[2.76,0]],"id":40917608},{"atb":[[1.56,68.77]],"id":42472248},{"atl":[[3.45,23.56],[3.3,0]],"id":42472248},{"atb":[[1.26,250],[1.36,55.56],[1.27,0],[1.17,0]],"id":38247349},{"atb":[[3.1,11.18],[3.05,7.72]],"id":28671742}],"con":true,"img":false}]}
{"op":"mcm","clk":"5353900932","pt":1646219624899,"mc":[{"id":"1.195453781","rc":[{"atb":[[1.49,204.08]],"id":42472248}],"con":true,"img":false}]}
{"op":"mcm","clk":"5353900964","pt":1646219625212,"mc":[{"id":"1.195453781","rc":[{"atl":[[2.34,14.93],[2.36,0]],"id":41120152},{"atl":[[3.4,0]],"id":42472248},{"atb":[[2.84,0],[2.96,51.02]],"id":28671742},{"atl":[[12,8.56],[9.6,0],[6.2,0],[6.6,3.57]],"id":28671742},{"atl":[[5.7,21.28],[5.9,15.31]],"id":38904370}],"con":true,"img":false}]}
{"op":"mcm","clk":"5353901014","pt":1646219625732,"mc":[{"id":"1.195453781","rc":[{"atb":[[1.5,281.98],[1.52,0]],"id":41120152}],"con":true,"img":false}]}
{"op":"mcm","clk":"5353901258","pt":1646219628236,"mc":[{"id":"1.195453781","rc":[{"atl":[[3.35,0]],"id":42472248}],"con":true,"img":false}]}
{"op":"mcm","clk":"5353901264","pt":1646219628341,"mc":[{"id":"1.195453781","rc":[{"atl":[[3.4,15.85]],"id":42472248}],"con":true,"img":false}]}
{"op":"mcm","clk":"5353901354","pt":1646219629339,"mc":[{"id":"1.195453781","rc":[{"atb":[[1.52,38.46]],"id":41120152}],"con":true,"img":false}]}
{"op":"mcm","clk":"5353901967","pt":1646219634837,"mc":[{"id":"1.195453781","rc":[{"atb":[[3,25]],"id":28866557},{"atl":[[2.68,44.16]],"id":40917608},{"atl":[[3.55,19.61]],"id":42472248},{"atb":[[1.34,147.06]],"id":38247349}],"con":true,"img":false}]}
{"op":"mcm","clk":"5353902002","pt":1646219635253,"mc":[{"id":"1.195453781","rc":[{"atl":[[7,8.33]],"id":28671742}],"con":true,"img":false}]}
{"op":"mcm","clk":"5353902320","pt":1646219638246,"mc":[{"id":"1.195453781","rc":[{"atl":[[6.8,0]],"id":28671742}],"con":true,"img":false}]}
{"op":"mcm","clk":"5353902331","pt":1646219638339,"mc":[{"id":"1.195453781","rc":[{"atl":[[7.2,7.51]],"id":28671742}],"con":true,"img":false}]}
{"op":"mcm","clk":"5353902425","pt":1646219639330,"mc":[{"id":"1.195453781","rc":[{"atb":[[1.5,341.98]],"id":41120152}],"con":true,"img":false}]}
{"op":"mcm","clk":"5353902734","pt":1646219642256,"mc":[{"id":"1.195453781","rc":[{"spn":1.97,"spf":"NaN","id":41120152},{"atl":[[2.88,25.74]],"id":40917608},{"atb":[[1.25,0],[1.21,0],[1.23,0]],"id":38247349},{"spn":4.85,"spf":"NaN","id":28671742}],"con":true,"img":false}]}
{"op":"mcm","clk":"5353902998","pt":1646219644860,"mc":[{"id":"1.195453781","rc":[{"atb":[[2.96,89.29]],"id":28866557},{"atl":[[2.72,43.6]],"id":40917608},{"atl":[[3.65,28.3]],"id":42472248},{"atb":[[1.32,234.37]],"id":38247349}],"con":true,"img":false}]}
{"op":"mcm","clk":"5353903044","pt":1646219645281,"mc":[{"id":"1.195453781","rc":[{"atl":[[7.4,11.72]],"id":28671742}],"con":true,"img":false}]}
{"op":"mcm","clk":"5353903352","pt":1646219648260,"mc":[{"id":"1.195453781","rc":[{"atl":[[5.8,0]],"id":38904370}],"con":true,"img":false}]}
{"op":"mcm","clk":"5353903365","pt":1646219648362,"mc":[{"id":"1.195453781","rc":[{"atl":[[5.6,9.08]],"id":38904370}],"con":true,"img":false}]}
{"op":"mcm","clk":"5353903371","pt":1646219648463,"mc":[{"id":"1.195453781","rc":[{"atl":[[5.7,10.64],[5.9,35.72]],"id":38904370}],"con":true,"img":false}]}
{"op":"mcm","clk":"5353903384","pt":1646219648568,"mc":[{"id":"1.195453781","rc":[{"atl":[[5.5,13.53],[5.9,15.31]],"id":38904370}],"con":true,"img":false}]}
{"op":"mcm","clk":"5353903993","pt":1646219654898,"mc":[{"id":"1.195453781","rc":[{"atb":[[2.92,65.1]],"id":28866557},{"atl":[[2.84,0],[2.76,71.02]],"id":40917608},{"atl":[[3.6,0],[3.5,0],[3.75,45.45]],"id":42472248},{"atb":[[1.3,250]],"id":38247349}],"con":true,"img":false}]}
{"op":"mcm","clk":"5353904036","pt":1646219655272,"mc":[{"id":"1.195453781","rc":[{"atl":[[7.8,18.38]],"id":28671742}],"con":true,"img":false}]}
{"op":"mcm","clk":"5353904324","pt":1646219658274,"mc":[{"id":"1.195453781","rc":[{"atl":[[24,0]],"id":28866557}],"con":true,"img":false}]}
{"op":"mcm","clk":"5353904332","pt":1646219658386,"mc":[{"id":"1.195453781","rc":[{"atl":[[22,3.3]],"id":28866557}],"con":true,"img":false}]}
{"op":"mcm","clk":"5353904400","pt":1646219659177,"mc":[{"id":"1.195453781","rc":[{"atl":[[22,0.57]],"id":28866557}],"con":true,"img":false}]}
{"op":"mcm","clk":"5353904410","pt":1646219659267,"mc":[{"id":"1.195453781","rc":[{"atl":[[23,7.72]],"id":28866557}],"con":true,"img":false}]}
{"op":"mcm","clk":"5353904979","pt":1646219664877,"mc":[{"id":"1.195453781","rc":[{"atl":[[2.8,0]],"id":40917608}],"con":true,"img":false}]}
{"op":"mcm","clk":"5353907417","pt":1646219688324,"mc":[{"id":"1.195453781","rc":[{"atl":[[5.6,0]],"id":38904370}],"con":true,"img":false}]}
{"op":"mcm","clk":"5353907428","pt":1646219688427,"mc":[{"id":"1.195453781","rc":[{"atl":[[5.9,35.72],[5.4,9.08]],"id":38904370}],"con":true,"img":false}]}
{"op":"mcm","clk":"5353907440","pt":1646219688530,"mc":[{"id":"1.195453781","rc":[{"atl":[[5.5,4.44]],"id":38904370}],"con":true,"img":false}]}
{"op":"mcm","clk":"5353907725","pt":1646219691312,"mc":[{"id":"1.195453781","rc":[{"atb":[[2,0],[2.3,61.91],[1.89,0],[2.16,69.2]],"id":41653210},{"atb":[[3.1,0],[3.4,34.56],[3.55,7.84],[2.96,38.27]],"id":28866557},{"atl":[[2.72,0],[3.1,57.14],[2.64,0],[2.68,14.4],[2.76,0]],"id":40917608},{"atl":[[3.45,0],[3.85,42.11],[3.55,0]],"id":42472248},{"atb":[[1.36,0],[1.26,0],[1.32,0],[1.3,0],[1.09,222.22],[1.34,0]],"id":38247349},{"atb":[[3.1,12.85],[3.15,9.3],[2.96,0]],"id":28671742},{"atb":[[2,20],[1.89,71.43],[1.62,0],[1.72,0]],"id":38904370}],"con":true,"img":false}]}
{"op":"mcm","clk":"5353907775","pt":1646219691832,"mc":[{"id":"1.195453781","rc":[{"atb":[[1.5,281.98],[1.52,0]],"id":41120152},{"atb":[[1.56,104.48],[1.54,0]],"id":42472248},{"atl":[[3.65,0]],"id":42472248}],"con":true,"img":false}]}
{"op":"mcm","clk":"5353907794","pt":1646219692039,"mc":[{"id":"1.195453781","rc":[{"atl":[[3.75,0]],"id":42472248}],"con":true,"img":false}]}
{"op":"mcm","clk":"5353907816","pt":1646219692246,"mc":[{"id":"1.195453781","rc":[{"atb":[[1.56,68.77],[1.54,37.04]],"id":42472248}],"con":true,"img":false}]}
{"op":"mcm","clk":"5353908079","pt":1646219694930,"mc":[{"id":"1.195453781","rc":[{"atb":[[3.1,11.19]],"id":28671742}],"con":true,"img":false}]}
{"op":"mcm","clk":"5353908099","pt":1646219695124,"mc":[{"id":"1.195453781","rc":[{"atb":[[3.2,1.66]],"id":28671742}],"con":true,"img":false}]}
{"op":"mcm","clk":"5353908416","pt":1646219698165,"mc":[{"id":"1.195453781","rc":[{"atl":[[5.3,9.09],[5.9,15.31]],"id":38904370}],"con":true,"img":false}]}
{"op":"mcm","clk":"5353908433","pt":1646219698324,"mc":[{"id":"1.195453781","rc":[{"atl":[[23,4.99]],"id":28866557},{"atl":[[4.1,0],[3.4,0],[3.8,13.75]],"id":42472248},{"atl":[[5.4,0]],"id":38904370}],"con":true,"img":false}]}
{"op":"mcm","clk":"5353908443","pt":1646219698426,"mc":[{"id":"1.195453781","rc":[{"atl":[[24,2.72]],"id":28866557},{"atl":[[3.8,29.61]],"id":42472248},{"atl":[[5.8,9.08]],"id":38904370}],"con":true,"img":false}]}
{"op":"mcm","clk":"5353908452","pt":1646219698529,"mc":[{"id":"1.195453781","rc":[{"atl":[[5.3,0],[5.7,25.95]],"id":38904370}],"con":true,"img":false}]}
{"op":"mcm","clk":"5353908706","pt":1646219701052,"mc":[{"id":"1.195453781","rc":[{"atb":[[3.1,0],[3.15,18.6]],"id":28671742}],"con":true,"img":false}]}
{"op":"mcm","clk":"5353908741","pt":1646219701368,"mc":[{"id":"1.195453781","rc":[{"atb":[[2.26,39.68]],"id":41653210},{"atb":[[3.45,20.41]],"id":28866557},{"atl":[[3.2,22.73]],"id":40917608},{"atb":[[1.07,250]],"id":38247349},{"atb":[[3.05,32.11]],"id":28671742},{"atb":[[1.98,51.02]],"id":38904370}],"con":true,"img":false}]}
{"op":"mcm","clk":"5353908799","pt":1646219701841,"mc":[{"id":"1.195453781","rc":[{"atb":[[1.48,312.5]],"id":41120152}],"con":true,"img":false}]}
{"op":"mcm","clk":"5353908852","pt":1646219702265,"mc":[{"id":"1.195453781","rc":[{"atl":[[3.95,16.95]],"id":42472248},{"spn":4.9,"spf":"NaN","id":28671742}],"con":true,"img":false}]}
{"op":"mcm","clk":"5353909244","pt":1646219705942,"mc":[{"id":"1.195453781","rc":[{"atb":[[3.05,28.45]],"id":28671742}],"con":true,"img":false}]}
{"op":"mcm","clk":"5353909594","pt":1646219709561,"mc":[{"id":"1.195453781","rc":[{"atb":[[1.98,0],[1.96,0],[1.94,0]],"id":41653210},{"atb":[[2.92,0],[3,0],[2.96,0]],"id":28866557},{"atb":[[2.9,0]],"id":28671742},{"atb":[[1.66,0]],"id":38904370}],"con":true,"img":false}]}
{"op":"mcm","clk":"5353909783","pt":1646219711358,"mc":[{"id":"1.195453781","rc":[{"atb":[[2.22,61.48]],"id":41653210},{"atb":[[3.35,31.91]],"id":28866557},{"atl":[[3.3,32.61]],"id":40917608},{"atb":[[1.05,250]],"id":38247349},{"atb":[[2.98,68.43]],"id":28671742},{"atb":[[1.96,78.12]],"id":38904370}],"con":true,"img":false}]}
{"op":"mcm","clk":"5353909832","pt":1646219711869,"mc":[{"id":"1.195453781","rc":[{"atb":[[1.46,163.04]],"id":41120152}],"con":true,"img":false}]}
{"op":"mcm","clk":"5353909842","pt":1646219711972,"mc":[{"id":"1.195453781","rc":[{"atb":[[3.1,3.57]],"id":28671742}],"con":true,"img":false}]}
{"op":"mcm","clk":"5353909872","pt":1646219712283,"mc":[{"id":"1.195453781","rc":[{"atl":[[4.1,24.19]],"id":42472248}],"con":true,"img":false}]}
{"op":"mcm","clk":"5353910506","pt":1646219718272,"mc":[{"id":"1.195453781","rc":[{"atb":[[1.99,0]],"id":41653210}],"con":true,"img":false}]}
{"op":"mcm","clk":"5353910516","pt":1646219718373,"mc":[{"id":"1.195453781","rc":[{"atb":[[1.91,48.5]],"id":41653210}],"con":true,"img":false}]}
{"op":"mcm","clk":"5353910651","pt":1646219719676,"mc":[{"id":"1.195453781","rc":[{"atb":[[3.4,8.33],[3.15,9.3]],"id":28671742},{"atl":[[6.8,3.45],[6.6,0]],"id":28671742},{"atb":[[1.68,0]],"id":38904370}],"con":true,"img":false}]}
{"op":"mcm","clk":"5353910747","pt":1646219720675,"mc":[{"id":"1.195453781","rc":[{"atb":[[1.54,181.62]],"id":42472248}],"con":true,"img":false}]}
{"op":"mcm","clk":"5353910756","pt":1646219720783,"mc":[{"id":"1.195453781","rc":[{"atb":[[2.3,46.53],[2.22,16.39],[2.26,0]],"id":41653210},{"atl":[[5.6,24.37],[3.6,4],[6.6,7.63]],"id":41653210},{"atl":[[44,2.33],[70,0],[18.5,1.14],[21,0]],"id":28866557},{"atb":[[1.57,3],[1.52,38.46]],"id":41120152},{"atl":[[3.3,0],[2.34,0],[2.4,0],[2.86,53.76],[2.42,14.08]],"id":41120152},{"atb":[[1.05,0]],"id":40917608},{"atb":[[1.49,0]],"id":42472248},{"atl":[[3.5,3]],"id":42472248},{"atb":[[1.09,0],[1.08,250]],"id":38247349},{"atl":[[3.35,27.06],[3.3,0],[2.48,2]],"id":38247349},{"atb":[[3.15,0],[2.98,118.94]],"id":28671742},{"atl":[[12,0],[8.6,13.16]],"id":28671742},{"atb":[[2.14,2]],"id":38904370},{"atl":[[5.5,0],[5.7,19.57]],"id":38904370}],"con":true,"img":false}]}
{"op":"mcm","clk":"5353910780","pt":1646219720989,"mc":[{"id":"1.195453781","rc":[{"atl":[[3.55,2]],"id":41653210},{"atb":[[1.58,4]],"id":41120152},{"atb":[[1.02,11299.7]],"id":40917608},{"atl":[[3.45,3]],"id":42472248},{"atl":[[2.48,0],[2.42,4]],"id":38247349},{"atb":[[2.16,4]],"id":38904370}],"con":true,"img":false}]}
{"op":"mcm","clk":"5353910807","pt":1646219721198,"mc":[{"id":"1.195453781","rc":[{"atl":[[3.6,0],[3.55,0],[3.25,4]],"id":41653210},{"atb":[[1.59,2]],"id":41120152},{"atl":[[3.4,2]],"id":42472248},{"atl":[[2.22,3],[2.42,0]],"id":38247349},{"atb":[[2.18,3]],"id":38904370}],"con":true,"img":false}]}
{"op":"mcm","clk":"5353910833","pt":1646219721412,"mc":[{"id":"1.195453781","rc":[{"atl":[[3.4,52.08]],"id":40917608}],"con":true,"img":false}]}
{"op":"mcm","clk":"5353910925","pt":1646219722304,"mc":[{"id":"1.195453781","rc":[{"atl":[[4.3,37.88]],"id":42472248}],"con":true,"img":false}]}
{"op":"mcm","clk":"5353911155","pt":1646219724402,"mc":[{"id":"1.195453781","rc":[{"atl":[[3.2,2]],"id":41653210},{"atb":[[1.6,28.39]],"id":41120152},{"atl":[[3.35,4]],"id":42472248},{"atl":[[2.22,0]],"id":38247349},{"atb":[[2.2,3]],"id":38904370}],"con":true,"img":false}]}
{"op":"mcm","clk":"5353911342","pt":1646219726082,"mc":[{"id":"1.195453781","rc":[{"atb":[[2.3,61.91]],"id":41653210},{"atl":[[3.25,0],[3.2,0],[3.15,3]],"id":41653210},{"atl":[[2.4,14.29]],"id":41120152}],"con":true,"img":false}]}
{"op":"mcm","clk":"5353911361","pt":1646219726288,"mc":[{"id":"1.195453781","rc":[{"atl":[[3.15,0]],"id":41653210}],"con":true,"img":false}]}
{"op":"mcm","clk":"5353911570","pt":1646219728287,"mc":[{"id":"1.195453781","rc":[{"atl":[[2.38,0]],"id":41120152},{"atl":[[5.8,0]],"id":38904370}],"con":true,"img":false}]}
{"op":"mcm","clk":"5353911582","pt":1646219728389,"mc":[{"id":"1.195453781","rc":[{"atl":[[2.42,45.67]],"id":41120152},{"atl":[[5.6,9.08]],"id":38904370}],"con":true,"img":false}]}
{"op":"mcm","clk":"5353911596","pt":1646219728492,"mc":[{"id":"1.195453781","rc":[{"atl":[[6.2,43.27],[5.7,4.26]],"id":38904370}],"con":true,"img":false}]}
{"op":"mcm","clk":"5353911698","pt":1646219729534,"mc":[{"id":"1.195453781","rc":[{"atb":[[2.3,15.38],[2.2,0],[2.1,0]],"id":41653210},{"atl":[[5.6,21.74],[7.2,0],[18,0],[9.2,0],[13,0]],"id":41653210},{"atb":[[4,0],[4.5,0],[3.75,0]],"id":28866557},{"atl":[[16,0],[34,0],[22,0],[60,0],[120,0]],"id":28866557},{"atb":[[1.45,0],[1.55,0],[1.5,40]],"id":41120152},{"atl":[[2.82,0],[5.1,0],[4.1,0],[3.55,0],[3.05,0]],"id":41120152},{"atb":[[1.01,0],[1.02,5250],[1.07,0]],"id":40917608},{"atl":[[2.88,0],[2.28,0],[2.68,0],[2.08,0],[2.48,0]],"id":40917608},{"atb":[[1.6,0],[1.55,0],[1.5,150]],"id":42472248},{"atl":[[4.4,0],[5.4,0],[2.88,0],[3.2,0],[3.7,0]],"id":42472248},{"atb":[[1.6,0],[1.55,0],[1.65,0]],"id":38247349},{"atl":[[3.45,0],[3.95,0],[4.9,0],[2.98,0],[5.9,0]],"id":38247349},{"atb":[[2.88,0],[2.98,88.39],[2.78,0]],"id":28671742},{"atl":[[32,0],[10.5,0],[21,0],[8.2,0],[15.5,0]],"id":28671742},{"atb":[[2.84,0],[2.94,0],[2.74,0]],"id":38904370},{"atl":[[8,0],[10,0],[20,0],[15,0],[30,0]],"id":38904370}],"con":true,"img":false}]}
{"op":"mcm","clk":"5353911720","pt":1646219729696,"mc":[{"id":"1.195453781","rc":[{"atb":[[3.3,21.74]],"id":28671742},{"atl":[[7.2,15.57]],"id":28671742}],"con":true,"img":false}]}
{"op":"mcm","clk":"5353911769","pt":1646219730112,"mc":[{"id":"1.195453781","rc":[{"atb":[[1.54,37.03],[1.66,68.78]],"id":42472248}],"con":true,"img":false}]}
{"op":"mcm","clk":"5353911783","pt":1646219730218,"mc":[{"id":"1.195453781","rc":[{"atl":[[5.6,0],[5,56.25]],"id":41653210},{"atb":[[2.98,37.88],[3.25,30.07]],"id":28671742}],"con":true,"img":false}]}
{"op":"mcm","clk":"5353911795","pt":1646219730321,"mc":[{"id":"1.195453781","rc":[{"atb":[[3,4.16]],"id":38904370}],"con":true,"img":false}]}
{"op":"mcm","clk":"5353911842","pt":1646219730692,"mc":[{"id":"1.195453781","rc":[{"atb":[[3.25,55.56]],"id":28866557},{"atl":[[19.5,2.7]],"id":28866557},{"atb":[[1.06,250]],"id":38247349},{"atl":[[3.45,20.41]],"id":38247349},{"atb":[[1.94,132.98]],"id":38904370},{"atl":[[5.9,10.2]],"id":38904370}],"con":true,"img":false}]}
{"op":"mcm","clk":"5353911891","pt":1646219731211,"mc":[{"id":"1.195453781","rc":[{"atl":[[27,0]],"id":28866557},{"atl":[[2.4,0]],"id":41120152},{"atl":[[3.6,0],[3.4,0],[3.5,0]],"id":38247349},{"atb":[[2.98,0],[2.94,0],[3.05,4.06]],"id":28671742},{"atl":[[7.4,0],[7,0],[7.8,0]],"id":28671742},{"atb":[[1.7,0]],"id":38904370}],"con":true,"img":false}]}
{"op":"mcm","clk":"5353912085","pt":1646219733099,"mc":[{"id":"1.195453781","rc":[{"atb":[[1.65,12.81]],"id":42472248},{"atb":[[3.1,0]],"id":28671742}],"con":true,"img":false}]}
{"op":"mcm","clk":"5353912106","pt":1646219733303,"mc":[{"id":"1.195453781","rc":[{"atb":[[3.2,0]],"id":28671742}],"con":true,"img":false}]}
{"op":"mcm","clk":"5353912125","pt":1646219733567,"mc":[{"id":"1.195453781","rc":[{"atb":[[3.45,1.66]],"id":28671742}],"con":true,"img":false}]}
{"op":"mcm","clk":"5353912257","pt":1646219734924,"mc":[{"id":"1.195453781","rc":[{"atb":[[2.3,61.91],[2.2,100.82],[2.1,109.99]],"id":41653210},{"atl":[[5.6,2.63],[7.2,1.95],[18,2.84],[9.2,2.94],[13,2.01]],"id":41653210},{"atb":[[4,40.33],[4.5,17.28],[3.75,43.99]],"id":28866557},{"atl":[[16,0.8],[34,0.73],[22,0.57],[60,0.4],[120,0.4]],"id":28866557},{"atb":[[1.45,268.87],[1.55,109.99],[1.5,281.98]],"id":41120152},{"atl":[[2.82,6.64],[5.1,11.8],[4.1,7.8],[3.55,9.48],[3.05,5.9]],"id":41120152},{"atb":[[1.01,12099.41],[1.02,11299.7],[1.07,864.24]],"id":40917608},{"atl":[[2.88,25.74],[2.28,9.45],[2.68,14.4],[2.08,11.2],[2.48,16.35]],"id":40917608},{"atb":[[1.6,100.82],[1.55,219.99],[1.5,391.98]],"id":42472248},{"atl":[[4.4,7.11],[5.4,10.99],[2.88,6.43],[3.2,5.49],[3.7,8.96]],"id":42472248},{"atb":[[1.6,201.65],[1.55,219.99],[1.65,93.07]],"id":38247349},{"atl":[[3.45,25.34],[3.95,8.2],[4.9,6.2],[2.98,6.1],[5.9,9.87]],"id":38247349},{"atb":[[2.88,64.36],[2.98,30.55],[2.78,67.97]],"id":28671742},{"atl":[[32,1.55],[10.5,1.27],[21,1.2],[8.2,1.67],[15.5,1.66]],"id":28671742},{"atb":[[2.84,65.75],[2.94,31.18],[2.74,69.53]],"id":38904370},{"atl":[[8,1.72],[10,1.34],[20,1.27],[15,1.72],[30,1.66]],"id":38904370}],"con":true,"img":false}]}
{"op":"mcm","clk":"5353912393","pt":1646219736124,"mc":[{"id":"1.195453781","rc":[{"atb":[[2.26,39.68]],"id":41653210},{"atb":[[1.5,381.98]],"id":41120152},{"atl":[[2.46,34.25]],"id":41120152}],"con":true,"img":false}]}
{"op":"mcm","clk":"5353912402","pt":1646219736229,"mc":[{"id":"1.195453781","rc":[{"atb":[[1.5,341.98]],"id":41120152}],"con":true,"img":false}]}
{"op":"mcm","clk":"5353912417","pt":1646219736395,"mc":[{"id":"1.195453781","rc":[{"atb":[[2.3,46.53],[2.26,0]],"id":41653210},{"atl":[[3.65,4]],"id":41653210},{"atl":[[2.4,14.29],[2.42,31.59]],"id":41120152},{"atb":[[1.66,0],[1.61,153.87]],"id":42472248}],"con":true,"img":false}]}
{"op":"mcm","clk":"5353912439","pt":1646219736600,"mc":[{"id":"1.195453781","rc":[{"atl":[[2.46,0]],"id":41120152}],"con":true,"img":false}]}
{"op":"mcm","clk":"5353912553","pt":1646219737827,"mc":[{"id":"1.195453781","rc":[{"atl":[[6.2,24.04],[5.5,9.09]],"id":38904370}],"con":true,"img":false}]}
{"op":"mcm","clk":"5353912605","pt":1646219738306,"mc":[{"id":"1.195453781","rc":[{"atb":[[1.47,0]],"id":41120152},{"atb":[[1.21,0],[1.08,491.65],[1.24,0]],"id":40917608},{"atl":[[3.35,8.51]],"id":38247349},{"atl":[[5.6,0]],"id":38904370}],"con":true,"img":false}]}
{"op":"mcm","clk":"5353912615","pt":1646219738404,"mc":[{"id":"1.195453781","rc":[{"atb":[[1.1,101.58]],"id":40917608},{"atb":[[1.46,246.97]],"id":41120152},{"atl":[[3.4,18.55]],"id":38247349},{"atl":[[5.8,9.08]],"id":38904370}],"con":true,"img":false}]}
{"op":"mcm","clk":"5353912683","pt":1646219739114,"mc":[{"id":"1.195453781","rc":[{"atb":[[3.4,11.46]],"id":28671742}],"con":true,"img":false}]}
{"op":"mcm","clk":"5353912728","pt":1646219739514,"mc":[{"id":"1.195453781","rc":[{"atb":[[3.4,33.2],[3.25,0]],"id":28671742}],"con":true,"img":false}]}
{"op":"mcm","clk":"5353912751","pt":1646219739724,"mc":[{"id":"1.195453781","rc":[{"atb":[[3.2,34.09]],"id":28671742},{"atl":[[7.6,11.36]],"id":28671742}],"con":true,"img":false}]}
{"op":"mcm","clk":"5353912824","pt":1646219740312,"mc":[{"id":"1.195453781","rc":[{"atl":[[3.25,2],[3.65,0]],"id":41653210}],"con":true,"img":false}]}
{"op":"mcm","clk":"5353912872","pt":1646219740730,"mc":[{"id":"1.195453781","rc":[{"atl":[[21,3.75]],"id":28866557},{"atb":[[1.04,250]],"id":38247349},{"atl":[[3.55,29.41]],"id":38247349},{"atl":[[6.2,14.42]],"id":38904370}],"con":true,"img":false}]}
{"op":"mcm","clk":"5353912898","pt":1646219740940,"mc":[{"id":"1.195453781","rc":[{"atl":[[25,0]],"id":28866557},{"atb":[[1.07,0],[1.05,0]],"id":38247349}],"con":true,"img":false}]}
{"op":"mcm","clk":"5353912923","pt":1646219741105,"mc":[{"id":"1.195453781","rc":[{"atl":[[3.2,2]],"id":41653210}],"con":true,"img":false}]}
{"op":"mcm","clk":"5353912970","pt":1646219741520,"mc":[{"id":"1.195453781","rc":[{"atb":[[1.61,0]],"id":38247349}],"con":true,"img":false}]}
{"op":"mcm","clk":"5353912983","pt":1646219741623,"mc":[{"id":"1.195453781","rc":[{"atb":[[2.3,61.91]],"id":41653210},{"atl":[[3.25,0],[3.2,0],[3.15,2]],"id":41653210},{"atl":[[2.32,0],[2.12,0],[2.52,28.68],[2.66,23.69]],"id":40917608},{"atl":[[2.4,0],[2.42,45.67]],"id":41120152},{"atb":[[1.66,100.83],[1.61,72.28]],"id":42472248},{"atb":[[1.56,65.22]],"id":38247349}],"con":true,"img":false}]}
{"op":"mcm","clk":"5353913011","pt":1646219741833,"mc":[{"id":"1.195453781","rc":[{"atl":[[3.15,0]],"id":41653210}],"con":true,"img":false}]}
{"op":"mcm","clk":"5353913043","pt":1646219741994,"mc":[{"id":"1.195453781","rc":[{"atb":[[3.4,30.07]],"id":28671742},{"atb":[[3,7.91]],"id":38904370}],"con":true,"img":false}]}
{"op":"mcm","clk":"5353913153","pt":1646219742925,"mc":[{"id":"1.195453781","rc":[{"atl":[[5.5,0],[5.7,22.44]],"id":38904370}],"con":true,"img":false}]}
{"op":"mcm","clk":"5353913438","pt":1646219745542,"mc":[{"id":"1.195453781","rc":[{"atb":[[3.4,21.74],[3.15,9.3],[3.3,0]],"id":28671742},{"atl":[[6.2,3.85]],"id":28671742}],"con":true,"img":false}]}
{"op":"mcm","clk":"5353913469","pt":1646219745808,"mc":[{"id":"1.195453781","rc":[{"atb":[[3.05,0]],"id":28671742}],"con":true,"img":false}]}
{"op":"mcm","clk":"5353913483","pt":1646219745935,"mc":[{"id":"1.195453781","rc":[{"atb":[[3.2,0]],"id":28671742}],"con":true,"img":false}]}
{"op":"mcm","clk":"5353913821","pt":1646219749110,"mc":[{"id":"1.195453781","rc":[{"atb":[[1.7,10.72]],"id":42472248},{"atb":[[3.5,3]],"id":28671742}],"con":true,"img":false}]}
{"op":"mcm","clk":"5353913980","pt":1646219750733,"mc":[{"id":"1.195453781","rc":[{"atl":[[23,8.4]],"id":28866557},{"atb":[[1.02,250]],"id":38247349},{"atl":[[3.65,47.17]],"id":38247349},{"atl":[[6.6,22.32]],"id":38904370}],"con":true,"img":false}]}
{"op":"mcm","clk":"5353913991","pt":1646219750837,"mc":[{"id":"1.195453781","rc":[{"atb":[[1.68,72.29],[1.66,0]],"id":42472248}],"con":true,"img":false}]}
{"op":"mcm","clk":"5353914070","pt":1646219751519,"mc":[{"id":"1.195453781","rc":[{"atb":[[1.48,468.75]],"id":41120152},{"atl":[[2.46,34.25]],"id":41120152}],"con":true,"img":false}]}
{"op":"mcm","clk":"5353914079","pt":1646219751627,"mc":[{"id":"1.195453781","rc":[{"atb":[[2.3,46.53],[2.26,39.68]],"id":41653210},{"atl":[[3.6,3]],"id":41653210},{"atb":[[1.48,364.58]],"id":41120152}],"con":true,"img":false}]}
{"op":"mcm","clk":"5353914104","pt":1646219751828,"mc":[{"id":"1.195453781","rc":[{"atb":[[2.26,0]],"id":41653210},{"atl":[[3.6,0],[3.25,3]],"id":41653210}],"con":true,"img":false}]}
{"op":"mcm","clk":"5353914151","pt":1646219752246,"mc":[{"id":"1.195453781","rc":[{"atb":[[3.45,0]],"id":28671742}],"con":true,"img":false}]}
{"op":"mcm","clk":"5353914171","pt":1646219752415,"mc":[{"id":"1.195453781","rc":[{"atb":[[3.55,1.66]],"id":28671742}],"con":true,"img":false}]}
{"op":"mcm","clk":"5353914346","pt":1646219754134,"mc":[{"id":"1.195453781","rc":[{"atb":[[1.7,0]],"id":42472248}],"con":true,"img":false}]}
{"op":"mcm","clk":"5353914409","pt":1646219754720,"mc":[{"id":"1.195453781","rc":[{"atl":[[3.2,4]],"id":41653210}],"con":true,"img":false}]}
{"op":"mcm","clk":"5353914429","pt":1646219754926,"mc":[{"id":"1.195453781","rc":[{"atl":[[3.15,2]],"id":41653210}],"con":true,"img":false}]}
{"op":"mcm","clk":"5353914448","pt":1646219755136,"mc":[{"id":"1.195453781","rc":[{"atl":[[3.1,2]],"id":41653210}],"con":true,"img":false}]}
{"op":"mcm","clk":"5353914488","pt":1646219755548,"mc":[{"id":"1.195453781","rc":[{"atb":[[3.05,24.39]],"id":28671742}],"con":true,"img":false}]}
{"op":"mcm","clk":"5353914539","pt":1646219756030,"mc":[{"id":"1.195453781","rc":[{"atb":[[1.68,0],[1.66,144.58]],"id":42472248}],"con":true,"img":false}]}
{"op":"mcm","clk":"5353914806","pt":1646219758345,"mc":[{"id":"1.195453781","rc":[{"atl":[[4.5,0]],"id":41653210},{"atb":[[4.5,29.14],[4.9,0]],"id":28866557},{"atl":[[3.8,15.85]],"id":42472248}],"con":true,"img":false}]}
{"op":"mcm","clk":"5353914820","pt":1646219758442,"mc":[{"id":"1.195453781","rc":[{"atl":[[4.7,11.78]],"id":41653210},{"atl":[[3.9,13.75]],"id":42472248}],"con":true,"img":false}]}
{"op":"mcm","clk":"5353914831","pt":1646219758551,"mc":[{"id":"1.195453781","rc":[{"atb":[[2.3,61.91]],"id":41653210},{"atl":[[3.1,0],[3.25,0],[3.2,0],[3.15,0]],"id":41653210}],"con":true,"img":false}]}
{"op":"mcm","clk":"5353914964","pt":1646219759863,"mc":[{"id":"1.195453781","rc":[{"atb":[[1.65,0]],"id":42472248}],"con":true,"img":false}]}
{"op":"mcm","clk":"5353915135","pt":1646219761143,"mc":[{"id":"1.195453781","rc":[{"atb":[[1.66,0]],"id":42472248}],"con":true,"img":false}]}
{"op":"mcm","clk":"5353915145","pt":1646219761236,"mc":[{"id":"1.195453781","rc":[{"atb":[[1.62,161.29]],"id":42472248}],"con":true,"img":false}]}
{"op":"mcm","clk":"5353915196","pt":1646219761658,"mc":[{"id":"1.195453781","rc":[{"atb":[[1.46,333.93]],"id":41120152},{"atl":[[2.5,50]],"id":41120152}],"con":true,"img":false}]}
{"op":"mcm","clk":"5353915622","pt":1646219765441,"mc":[{"id":"1.195453781","rc":[{"spn":2.01,"spf":"NaN","id":41120152},{"spn":1.59,"spf":"NaN","id":40917608},{"spn":2.25,"spf":"NaN","id":42472248},{"atb":[[2.98,68.43]],"id":28671742},{"spn":4.87,"spf":"NaN","id":28671742},{"spn":4.37,"spf":"NaN","id":38904370}],"con":true,"img":false}]}
{"op":"mcm","clk":"5353915770","pt":1646219766740,"mc":[{"id":"1.195453781","rc":[{"atb":[[1.1,0]],"id":40917608},{"atl":[[2.52,0]],"id":40917608},{"atb":[[3,0]],"id":28671742},{"atl":[[7.2,8.06]],"id":28671742},{"atl":[[5.8,0]],"id":38904370}],"con":true,"img":false}]}
{"op":"mcm","clk":"5353915783","pt":1646219766847,"mc":[{"id":"1.195453781","rc":[{"atb":[[1.25,101.58]],"id":40917608},{"atl":[[2.2,28.68]],"id":40917608},{"atb":[[2.9,22.95]],"id":28671742},{"atl":[[9,7.51]],"id":28671742},{"atl":[[5.6,9.08]],"id":38904370}],"con":true,"img":false}]}
{"op":"mcm","clk":"5353915794","pt":1646219766951,"mc":[{"id":"1.195453781","rc":[{"atl":[[6.2,33.65],[5.7,4.26]],"id":38904370}],"con":true,"img":false}]}
{"op":"mcm","clk":"5353915815","pt":1646219767164,"mc":[{"id":"1.195453781","rc":[{"atl":[[2.44,0],[2.48,0]],"id":41120152}],"con":true,"img":false}]}
{"op":"mcm","clk":"5353915959","pt":1646219768272,"mc":[{"id":"1.195453781","rc":[{"atb":[[1.61,0]],"id":42472248}],"con":true,"img":false}]}
{"op":"mcm","clk":"5353915972","pt":1646219768377,"mc":[{"id":"1.195453781","rc":[{"atb":[[1.63,72.28]],"id":42472248}],"con":true,"img":false}]}
{"op":"mcm","clk":"5353915987","pt":1646219768482,"mc":[{"id":"1.195453781","rc":[{"atb":[[1.62,0],[1.61,163.93]],"id":42472248}],"con":true,"img":false}]}
{"op":"mcm","clk":"5353916004","pt":1646219768545,"mc":[{"id":"1.195453781","rc":[{"atb":[[2.26,39.68]],"id":41653210}],"con":true,"img":false}]}
{"op":"mcm","clk":"5353916353","pt":1646219771673,"mc":[{"id":"1.195453781","rc":[{"atl":[[2.54,81.17]],"id":41120152}],"con":true,"img":false}]}
{"op":"mcm","clk":"5353916471","pt":1646219772777,"mc":[{"id":"1.195453781","rc":[{"atb":[[3.05,28.45]],"id":28671742}],"con":true,"img":false}]}
{"op":"mcm","clk":"5353916774","pt":1646219775564,"mc":[{"id":"1.195453781","rc":[{"atb":[[2.94,64.43]],"id":28671742}],"con":true,"img":false}]}
{"op":"mcm","clk":"5353916787","pt":1646219775667,"mc":[{"id":"1.195453781","rc":[{"atb":[[1.67,11.2]],"id":42472248}],"con":true,"img":false}]}
{"op":"mcm","clk":"5353916802","pt":1646219775803,"mc":[{"id":"1.195453781","rc":[{"atb":[[2.3,46.53],[2.26,0]],"id":41653210},{"atl":[[3.65,3]],"id":41653210}],"con":true,"img":false}]}
{"op":"mcm","clk":"5353916815","pt":1646219775877,"mc":[{"id":"1.195453781","rc":[{"atl":[[6.2,14.42],[5.5,9.09]],"id":38904370}],"con":true,"img":false}]}
{"op":"mcm","clk":"5353916829","pt":1646219775985,"mc":[{"id":"1.195453781","rc":[{"atl":[[3.3,2],[3.65,0]],"id":41653210}],"con":true,"img":false}]}
{"op":"mcm","clk":"5353916955","pt":1646219777083,"mc":[{"id":"1.195453781","rc":[{"atl":[[3.25,3]],"id":41653210}],"con":true,"img":false}]}
{"op":"mcm","clk":"5353916993","pt":1646219777401,"mc":[{"id":"1.195453781","rc":[{"atb":[[1.68,72.29],[1.61,0]],"id":42472248}],"con":true,"img":false}]}
{"op":"mcm","clk":"5353917106","pt":1646219778350,"mc":[{"id":"1.195453781","rc":[{"atl":[[23,5.68]],"id":28866557},{"atb":[[1.46,250]],"id":41120152},{"atl":[[2.42,14.08]],"id":41120152},{"atb":[[1.67,0]],"id":42472248},{"atl":[[5.6,0]],"id":38904370}],"con":true,"img":false}]}
{"op":"mcm","clk":"5353917117","pt":1646219778451,"mc":[{"id":"1.195453781","rc":[{"atl":[[20,2.72]],"id":28866557},{"atb":[[1.47,83.93]],"id":41120152},{"atl":[[2.44,31.59]],"id":41120152},{"atl":[[6,9.08]],"id":38904370}],"con":true,"img":false}]}
{"op":"mcm","clk":"5353917131","pt":1646219778556,"mc":[{"id":"1.195453781","rc":[{"atb":[[2.18,42.37]],"id":41653210},{"atb":[[1.64,144.58],[1.68,0]],"id":42472248}],"con":true,"img":false}]}
{"op":"mcm","clk":"5353917228","pt":1646219779446,"mc":[{"id":"1.195453781","rc":[{"atl":[[3.2,3]],"id":41653210}],"con":true,"img":false}]}
{"op":"mcm","clk":"5353917405","pt":1646219780981,"mc":[{"id":"1.195453781","rc":[{"atb":[[2.3,61.91]],"id":41653210},{"atl":[[3.25,0],[3.3,0],[3.2,0],[3.15,2]],"id":41653210},{"atl":[[5.5,0],[5.9,23.55]],"id":38904370}],"con":true,"img":false}]}
{"op":"mcm","clk":"5353917423","pt":1646219781197,"mc":[{"id":"1.195453781","rc":[{"atl":[[3.15,0]],"id":41653210}],"con":true,"img":false}]}
{"op":"mcm","clk":"5353917593","pt":1646219782785,"mc":[{"id":"1.195453781","rc":[{"atb":[[1.22,178.78]],"id":40917608},{"atl":[[2.66,0]],"id":40917608},{"atb":[[1.56,0]],"id":38247349}],"con":true,"img":false}]}
{"op":"mcm","clk":"5353917608","pt":1646219782888,"mc":[{"id":"1.195453781","rc":[{"atb":[[1.08,0]],"id":40917608},{"atl":[[2.4,23.69]],"id":40917608},{"atb":[[1.61,65.22]],"id":38247349}],"con":true,"img":false}]}
{"op":"mcm","clk":"5353918091","pt":1646219787489,"mc":[{"id":"1.195453781","rc":[{"atb":[[1.68,11.04]],"id":42472248}],"con":true,"img":false}]}
{"op":"mcm","clk":"5353918114","pt":1646219787691,"mc":[{"id":"1.195453781","rc":[{"atb":[[1.64,0],[1.68,83.33]],"id":42472248}],"con":true,"img":false}]}
{"op":"mcm","clk":"5353918408","pt":1646219790567,"mc":[{"id":"1.195453781","rc":[{"atb":[[1.68,72.29]],"id":42472248}],"con":true,"img":false}]}
{"op":"mcm","clk":"5353918449","pt":1646219790981,"mc":[{"id":"1.195453781","rc":[{"atb":[[2.26,39.68]],"id":41653210}],"con":true,"img":false}]}
{"op":"mcm","clk":"5353918730","pt":1646219792808,"mc":[{"id":"1.195453781","rc":[{"atb":[[1.64,144.58],[1.68,0]],"id":42472248}],"con":true,"img":false}]}
{"op":"mcm","clk":"5353919460","pt":1646219796302,"mc":[{"id":"1.195453781","rc":[{"atb":[[2.3,46.53],[2.26,0]],"id":41653210},{"atl":[[3.65,3]],"id":41653210}],"con":true,"img":false}]}
{"op":"mcm","clk":"5353919530","pt":1646219796624,"mc":[{"id":"1.195453781","rc":[{"atl":[[3.3,2],[3.65,0]],"id":41653210}],"con":true,"img":false}]}
{"op":"mcm","clk":"5353919829","pt":1646219798326,"mc":[{"id":"1.195453781","rc":[{"atl":[[24,0]],"id":28866557},{"atb":[[1.63,0]],"id":42472248},{"atb":[[2.9,0]],"id":28671742},{"atl":[[6,0]],"id":38904370}],"con":true,"img":false}]}
{"op":"mcm","clk":"5353919848","pt":1646219798384,"mc":[{"id":"1.195453781","rc":[{"atl":[[20,5.45]],"id":28866557},{"atb":[[1.65,72.28]],"id":42472248},{"atb":[[3,22.95]],"id":28671742},{"atl":[[5.8,9.08]],"id":38904370}],"con":true,"img":false}]}
{"op":"mcm","clk":"5353919865","pt":1646219798489,"mc":[{"id":"1.195453781","rc":[{"atb":[[1.64,0],[1.61,163.93]],"id":42472248},{"atl":[[6.2,33.65],[5.9,10.2]],"id":38904370}],"con":true,"img":false}]}
{"op":"mcm","clk":"5353919913","pt":1646219798800,"mc":[{"id":"1.195453781","rc":[{"atl":[[6.2,14.42],[5.7,13.35]],"id":38904370}],"con":true,"img":false}]}
{"op":"mcm","clk":"5353920224","pt":1646219801020,"mc":[{"id":"1.195453781","rc":[{"atb":[[2.14,65.79]],"id":41653210},{"atl":[[3.25,3]],"id":41653210}],"con":true,"img":false}]}
{"op":"mcm","clk":"5353920283","pt":1646219801397,"mc":[{"id":"1.195453781","rc":[{"atb":[[2.3,61.91]],"id":41653210},{"atl":[[3.25,0],[3.3,0],[3.2,3]],"id":41653210},{"atb":[[1.66,100.83],[1.61,0]],"id":42472248}],"con":true,"img":false}]}
{"op":"mcm","clk":"5353920299","pt":1646219801502,"mc":[{"id":"1.195453781","rc":[{"atb":[[2.3,46.53],[2.34,5]],"id":41653210},{"atb":[[1.1,314.6]],"id":40917608},{"atb":[[1.59,0],[1.6,26.39],[1.58,0],[1.57,0],[1.61,51.57]],"id":41120152},{"atl":[[2.42,0],[2.44,45.48]],"id":41120152},{"atb":[[1.62,50.74]],"id":42472248},{"atl":[[3.35,0],[3.45,0],[3.4,0],[3.65,2]],"id":42472248},{"atb":[[1.67,46.95]],"id":38247349},{"atb":[[3.35,22.95],[3.4,0]],"id":28671742},{"atb":[[3.1,3.33],[2.14,0],[2.18,0],[2.2,0],[2.16,0]],"id":38904370},{"atl":[[5.5,4.44],[5.7,9.09]],"id":38904370}],"con":true,"img":false}]}
{"op":"mcm","clk":"5353920314","pt":1646219801615,"mc":[{"id":"1.195453781","rc":[{"atl":[[3.3,4]],"id":41653210}],"con":true,"img":false}]}
{"op":"mcm","clk":"5353920323","pt":1646219801708,"mc":[{"id":"1.195453781","rc":[{"atl":[[3.6,2]],"id":42472248}],"con":true,"img":false}]}
{"op":"mcm","clk":"5353920337","pt":1646219801826,"mc":[{"id":"1.195453781","rc":[{"atl":[[3.25,4],[3.3,0]],"id":41653210}],"con":true,"img":false}]}
{"op":"mcm","clk":"5353920349","pt":1646219801921,"mc":[{"id":"1.195453781","rc":[{"atl":[[3.6,0],[3.45,3],[3.65,0]],"id":42472248},{"atb":[[2.14,4]],"id":38904370},{"atl":[[5.5,0],[5.7,13.35]],"id":38904370}],"con":true,"img":false}]}
{"op":"mcm","clk":"5353920378","pt":1646219802085,"mc":[{"id":"1.195453781","rc":[{"atl":[[3.15,2]],"id":41653210},{"atl":[[3.4,2]],"id":42472248},{"atb":[[2.16,4]],"id":38904370}],"con":true,"img":false}]}
{"op":"mcm","clk":"5353920427","pt":1646219802794,"mc":[{"id":"1.195453781","rc":[{"atb":[[1.6,13.88]],"id":41120152},{"atb":[[1.7,11.9]],"id":38247349},{"atb":[[3.5,0]],"id":28671742}],"con":true,"img":false}]}
{"op":"mcm","clk":"5353920568","pt":1646219803612,"mc":[{"id":"1.195453781","rc":[{"atb":[[2.3,61.91]],"id":41653210},{"atl":[[3.25,0],[3.2,0],[3.15,0]],"id":41653210},{"atl":[[18.5,0],[19,1.11]],"id":28866557},{"atb":[[1.57,3]],"id":41120152},{"atl":[[2.46,13.7],[2.44,31.59]],"id":41120152},{"atb":[[1.02,6299.7]],"id":40917608},{"atl":[[3.45,0],[3.4,0],[3.65,2]],"id":42472248},{"atl":[[3.95,42.1],[3.35,0],[3.25,8.89],[4.4,0]],"id":38247349},{"atb":[[2.18,3]],"id":38904370}],"con":true,"img":false}]}
{"op":"mcm","clk":"5353920590","pt":1646219803860,"mc":[{"id":"1.195453781","rc":[{"atb":[[1.58,2]],"id":41120152},{"atl":[[3.6,4]],"id":42472248},{"atb":[[2.2,2]],"id":38904370}],"con":true,"img":false}]}
{"op":"mcm","clk":"5353920668","pt":1646219804533,"mc":[{"id":"1.195453781","rc":[{"atb":[[1.59,2]],"id":41120152},{"atl":[[3.55,2]],"id":42472248}],"con":true,"img":false}]}
{"op":"mcm","clk":"5353920717","pt":1646219804893,"mc":[{"id":"1.195453781","rc":[{"atb":[[1.6,15.88]],"id":41120152}],"con":true,"img":false}]}
{"op":"mcm","clk":"5353920731","pt":1646219805009,"mc":[{"id":"1.195453781","rc":[{"atb":[[1.62,0]],"id":42472248}],"con":true,"img":false}]}
{"op":"mcm","clk":"5353920916","pt":1646219806630,"mc":[{"id":"1.195453781","rc":[{"atb":[[1.6,267.49],[1.66,0]],"id":42472248}],"con":true,"img":false}]}
{"op":"mcm","clk":"5353920949","pt":1646219806931,"mc":[{"id":"1.195453781","rc":[{"atb":[[2.34,0]],"id":41653210}],"con":true,"img":false}]}
{"op":"mcm","clk":"5353921165","pt":1646219808346,"mc":[{"id":"1.195453781","rc":[{"atb":[[1.65,11.54]],"id":41120152},{"atl":[[2.44,0]],"id":41120152},{"atb":[[1.71,10.57]],"id":38247349},{"atb":[[3.45,3.06]],"id":28671742}],"con":true,"img":false}]}
{"op":"mcm","clk":"5353921182","pt":1646219808448,"mc":[{"id":"1.195453781","rc":[{"atl":[[2.48,31.59]],"id":41120152}],"con":true,"img":false}]}
{"op":"mcm","clk":"5353921287","pt":1646219809058,"mc":[{"id":"1.195453781","rc":[{"atb":[[1.57,55.19]],"id":42472248}],"con":true,"img":false}]}
{"op":"mcm","clk":"5353921637","pt":1646219810960,"mc":[{"id":"1.195453781","rc":[{"atb":[[1.61,0]],"id":41120152},{"atb":[[1.67,0]],"id":38247349}],"con":true,"img":false}]}
{"op":"mcm","clk":"5353921653","pt":1646219811020,"mc":[{"id":"1.195453781","rc":[{"atb":[[2.34,5]],"id":41653210}],"con":true,"img":false}]}
{"op":"mcm","clk":"5353921703","pt":1646219811336,"mc":[{"id":"1.195453781","rc":[{"atb":[[3.55,0]],"id":28671742},{"atb":[[3.05,0]],"id":38904370}],"con":true,"img":false}]}
{"op":"mcm","clk":"5353921722","pt":1646219811446,"mc":[{"id":"1.195453781","rc":[{"atb":[[1.65,0]],"id":41120152},{"atb":[[1.71,0]],"id":38247349}],"con":true,"img":false}]}
{"op":"mcm","clk":"5353921737","pt":1646219811542,"mc":[{"id":"1.195453781","rc":[{"atb":[[3.5,1.66]],"id":28671742},{"atb":[[3.15,1.66]],"id":38904370}],"con":true,"img":false}]}
{"op":"mcm","clk":"5353922021","pt":1646219813657,"mc":[{"id":"1.195453781","rc":[{"atb":[[2.26,39.68]],"id":41653210},{"atl":[[20,8.08]],"id":28866557},{"atl":[[2.5,33.33]],"id":41120152},{"atl":[[3.35,21.28]],"id":38247349}],"con":true,"img":false}]}
{"op":"mcm","clk":"5353922076","pt":1646219814023,"mc":[{"id":"1.195453781","rc":[{"atb":[[2.14,0]],"id":41653210},{"atl":[[19.5,0],[21,0],[23,0]],"id":28866557},{"atl":[[3.65,0]],"id":38247349}],"con":true,"img":false}]}
{"op":"mcm","clk":"5353922148","pt":1646219814551,"mc":[{"id":"1.195453781","rc":[{"atb":[[1.69,10.87]],"id":42472248}],"con":true,"img":false}]}
{"op":"mcm","clk":"5353922271","pt":1646219815458,"mc":[{"id":"1.195453781","rc":[{"atb":[[1.61,31.77]],"id":41120152},{"atb":[[1.67,35.69]],"id":38247349},{"atb":[[3.1,0]],"id":38904370}],"con":true,"img":false}]}
{"op":"mcm","clk":"5353922486","pt":1646219817144,"mc":[{"id":"1.195453781","rc":[{"atb":[[1.57,0]],"id":42472248}],"con":true,"img":false}]}
{"op":"mcm","clk":"5353922526","pt":1646219817484,"mc":[{"id":"1.195453781","rc":[{"atb":[[1.6,28.39]],"id":41120152},{"atb":[[1.7,22.63]],"id":38247349}],"con":true,"img":false}]}
{"op":"mcm","clk":"5353922611","pt":1646219818239,"mc":[{"id":"1.195453781","rc":[{"atl":[[20,5.35]],"id":28866557},{"atb":[[1.56,0]],"id":42472248}],"con":true,"img":false}]}
{"op":"mcm","clk":"5353922623","pt":1646219818347,"mc":[{"id":"1.195453781","rc":[{"atl":[[24,2.72]],"id":28866557},{"atb":[[1.61,68.77]],"id":42472248}],"con":true,"img":false}]}
{"op":"mcm","clk":"5353922709","pt":1646219819125,"mc":[{"id":"1.195453781","rc":[{"atb":[[3.05,4.58]],"id":38904370}],"con":true,"img":false}]}
{"op":"mcm","clk":"5353922959","pt":1646219821652,"mc":[{"id":"1.195453781","rc":[{"atb":[[1.62,43.51]],"id":42472248}],"con":true,"img":false}]}
{"op":"mcm","clk":"5353922966","pt":1646219821757,"mc":[{"id":"1.195453781","rc":[{"atb":[[1.62,69.49]],"id":42472248},{"atl":[[3.5,28.98]],"id":42472248}],"con":true,"img":false}]}
{"op":"mcm","clk":"5353922976","pt":1646219821859,"mc":[{"id":"1.195453781","rc":[{"atb":[[1.69,23.86]],"id":42472248},{"atl":[[3.35,2.5],[3.55,7],[2.88,19.42]],"id":42472248}],"con":true,"img":false}]}
{"op":"mcm","clk":"5353923176","pt":1646219823645,"mc":[{"id":"1.195453781","rc":[{"atb":[[2.32,71.99],[2.22,61.48],[2.38,24.5]],"id":41653210},{"atl":[[4.4,18.9],[4.7,49.17]],"id":41653210},{"atb":[[4,61.45],[5.6,10.56]],"id":28866557},{"atl":[[16,1.48],[22,4.14]],"id":28866557},{"atb":[[1.59,91.98],[1.61,76.76]],"id":41120152},{"atl":[[2.54,48.7],[2.5,123.31],[2.46,58.69]],"id":41120152},{"atb":[[1.7,55.56],[1.66,137.33]],"id":38247349},{"atl":[[3.45,35.54],[3.35,87.14],[2.98,23.93]],"id":38247349}],"con":true,"img":false}]}
{"op":"mcm","clk":"5353923206","pt":1646219823954,"mc":[{"id":"1.195453781","rc":[{"atb":[[2.62,10],[2.78,2.5],[2.7,5]],"id":41653210},{"atb":[[4.5,39.14],[5.3,2.5],[4.9,5]],"id":28866557},{"atb":[[1.71,5],[1.67,10],[1.75,2.5]],"id":41120152},{"atb":[[1.15,2.5],[1.11,5]],"id":40917608},{"atl":[[1.94,10],[2.06,75.47],[2.28,109.31],[1.9,5],[1.86,2.5]],"id":40917608},{"atb":[[1.94,2.5],[1.9,5],[1.86,10]],"id":38247349},{"atb":[[3.6,5],[3.8,2.5],[3.45,8.54],[3.4,10],[3.15,28.49]],"id":28671742},{"atl":[[7.2,27.25],[6.2,9.33]],"id":28671742},{"atl":[[5.6,12.76],[5.9,39.14]],"id":38904370}],"con":true,"img":false}]}
{"op":"mcm","clk":"5353923234","pt":1646219824163,"mc":[{"id":"1.195453781","rc":[{"atl":[[5.5,12.76],[5.7,4.26]],"id":38904370}],"con":true,"img":false}]}
{"op":"mcm","clk":"5353923281","pt":1646219824581,"mc":[{"id":"1.195453781","rc":[{"atl":[[4.8,46.06],[5,31.25]],"id":41653210},{"atl":[[2.72,58.14],[2.86,0]],"id":41120152},{"atl":[[8,14.29],[8.6,0]],"id":28671742}],"con":true,"img":false}]}
{"op":"mcm","clk":"5353923483","pt":1646219826588,"mc":[{"id":"1.195453781","rc":[{"spn":3.59,"spf":"NaN","id":41653210},{"spn":10.8,"spf":"NaN","id":28866557},{"atb":[[1.6,15.88]],"id":41120152},{"spn":2.1,"spf":"NaN","id":41120152},{"spn":1.55,"spf":"NaN","id":40917608},{"spn":2.28,"spf":"NaN","id":42472248},{"atb":[[1.7,44.83]],"id":38247349},{"spn":2.46,"spf":"NaN","id":38247349},{"spn":5.0,"spf":"NaN","id":28671742},{"spn":4.32,"spf":"NaN","id":38904370}],"con":true,"img":false}]}
{"op":"mcm","clk":"5353923572","pt":1646219827274,"mc":[{"id":"1.195453781","rc":[{"atb":[[2.34,0]],"id":41653210},{"atb":[[1.61,44.99]],"id":41120152},{"atb":[[1.1,0]],"id":40917608},{"atb":[[1.67,0]],"id":38247349}],"con":true,"img":false}]}
{"op":"mcm","clk":"5353923680","pt":1646219828272,"mc":[{"id":"1.195453781","rc":[{"atb":[[1.66,65.86]],"id":38247349},{"atb":[[3,0]],"id":28671742},{"atl":[[9,0]],"id":28671742}],"con":true,"img":false}]}
{"op":"mcm","clk":"5353923693","pt":1646219828376,"mc":[{"id":"1.195453781","rc":[{"atb":[[1.68,71.47]],"id":38247349},{"atb":[[3.4,32.95]],"id":28671742},{"atl":[[7.4,7.51]],"id":28671742}],"con":true,"img":false}]}
{"op":"mcm","clk":"5353923799","pt":1646219829274,"mc":[{"id":"1.195453781","rc":[{"atl":[[5.5,0],[5.7,25.54]],"id":38904370}],"con":true,"img":false}]}
{"op":"mcm","clk":"5353923819","pt":1646219829485,"mc":[{"id":"1.195453781","rc":[{"atb":[[3.45,5.48]],"id":28671742}],"con":true,"img":false}]}
{"op":"mcm","clk":"5353924008","pt":1646219831161,"mc":[{"id":"1.195453781","rc":[{"atb":[[2.64,10]],"id":41653210},{"atb":[[1.16,196.62]],"id":40917608},{"atb":[[1.68,10]],"id":41120152},{"atb":[[1.87,10]],"id":38247349}],"con":true,"img":false}]}
{"op":"mcm","clk":"5353924032","pt":1646219831372,"mc":[{"id":"1.195453781","rc":[{"atb":[[2.4,0]],"id":41653210},{"atb":[[3.5,0]],"id":28671742},{"atb":[[3.15,0]],"id":38904370}],"con":true,"img":false}]}
{"op":"mcm","clk":"5353924057","pt":1646219831580,"mc":[{"id":"1.195453781","rc":[{"atb":[[2.8,1.66]],"id":41653210},{"atb":[[3.85,1.66]],"id":28671742},{"atb":[[3.1,1.66]],"id":38904370}],"con":true,"img":false}]}
{"op":"mcm","clk":"5353924166","pt":1646219832473,"mc":[{"id":"1.195453781","rc":[{"atb":[[1.74,10.14]],"id":38247349}],"con":true,"img":false}]}
{"op":"mcm","clk":"5353924175","pt":1646219832579,"mc":[{"id":"1.195453781","rc":[{"atb":[[1.65,11.54]],"id":41120152}],"con":true,"img":false}]}
{"op":"mcm","clk":"5353924295","pt":1646219833675,"mc":[{"id":"1.195453781","rc":[{"atb":[[2.18,105.93]],"id":41653210},{"atl":[[24,8.15]],"id":28866557},{"atl":[[2.58,79.11]],"id":41120152},{"atl":[[3.55,49.02]],"id":38247349}],"con":true,"img":false}]}
{"op":"mcm","clk":"5353924413","pt":1646219834773,"mc":[{"id":"1.195453781","rc":[{"atb":[[2.64,0]],"id":41653210}],"con":true,"img":false}]}
{"op":"mcm","clk":"5353924425","pt":1646219834881,"mc":[{"id":"1.195453781","rc":[{"atb":[[1.6,2]],"id":41120152},{"atb":[[1.25,0],[1.22,0]],"id":40917608}],"con":true,"img":false}]}
{"op":"mcm","clk":"5353924438","pt":1646219834983,"mc":[{"id":"1.195453781","rc":[{"atb":[[1.21,101.58],[1.19,178.78]],"id":40917608},{"atb":[[1.69,35.93]],"id":42472248}],"con":true,"img":false}]}
{"op":"mcm","clk":"5353924455","pt":1646219835087,"mc":[{"id":"1.195453781","rc":[{"atl":[[4.8,19.74],[5,56.25]],"id":41653210}],"con":true,"img":false}]}
{"op":"mcm","clk":"5353924551","pt":1646219835771,"mc":[{"id":"1.195453781","rc":[{"atb":[[3.5,3]],"id":28671742}],"con":true,"img":false}]}
{"op":"mcm","clk":"5353924738","pt":1646219837591,"mc":[{"id":"1.195453781","rc":[{"atl":[[3.6,0],[3.55,5],[3.5,25.98],[3.65,0]],"id":42472248}],"con":true,"img":false}]}
{"op":"mcm","clk":"5353924748","pt":1646219837695,"mc":[{"id":"1.195453781","rc":[{"atb":[[1.62,71.99]],"id":42472248}],"con":true,"img":false}]}
{"op":"mcm","clk":"5353924815","pt":1646219838272,"mc":[{"id":"1.195453781","rc":[{"atl":[[3.9,0]],"id":42472248},{"atl":[[3.4,0]],"id":38247349}],"con":true,"img":false}]}
{"op":"mcm","clk":"5353924824","pt":1646219838392,"mc":[{"id":"1.195453781","rc":[{"atl":[[3.8,29.61]],"id":42472248},{"atl":[[3.3,18.55]],"id":38247349}],"con":true,"img":false}]}
{"op":"mcm","clk":"5353924848","pt":1646219838586,"mc":[{"id":"1.195453781","rc":[{"atb":[[1.16,0]],"id":40917608}],"con":true,"img":false}]}
{"op":"mcm","clk":"5353924914","pt":1646219839272,"mc":[{"id":"1.195453781","rc":[{"atl":[[3.35,73.74],[3.5,0]],"id":42472248}],"con":true,"img":false}]}
{"op":"mcm","clk":"5353925065","pt":1646219840684,"mc":[{"id":"1.195453781","rc":[{"atb":[[2.72,5.42]],"id":41653210}],"con":true,"img":false}]}
{"op":"mcm","clk":"5353925103","pt":1646219840997,"mc":[{"id":"1.195453781","rc":[{"atl":[[18.5,1.14],[19,0]],"id":28866557},{"atl":[[3.2,9.09],[3.25,0]],"id":38247349}],"con":true,"img":false}]}
{"op":"mcm","clk":"5353925125","pt":1646219841205,"mc":[{"id":"1.195453781","rc":[{"atb":[[2.32,34.6],[2.78,16.98],[2.7,33.97]],"id":41653210},{"atb":[[4,40.33],[5.3,14.29]],"id":28866557},{"atb":[[1.59,2],[1.68,72.39],[1.75,33.69]],"id":41120152},{"atb":[[1.94,16.67],[1.87,38.34],[1.66,0]],"id":38247349},{"atl":[[3.35,21.28],[3.3,46.89]],"id":38247349}],"con":true,"img":false}]}
{"op":"mcm","clk":"5353925133","pt":1646219841266,"mc":[{"id":"1.195453781","rc":[{"atb":[[2.38,11.48]],"id":41653210},{"atb":[[1.61,0]],"id":41120152},{"atb":[[1.7,11.9]],"id":38247349}],"con":true,"img":false}]}
{"op":"mcm","clk":"5353925154","pt":1646219841523,"mc":[{"id":"1.195453781","rc":[{"atl":[[1.85,11.25],[1.94,32.5],[2.28,9.45]],"id":40917608},{"atb":[[3.8,8.84],[3.5,16.76],[3.15,9.3]],"id":28671742},{"atl":[[5.8,41.86],[5.9,10.2]],"id":38904370}],"con":true,"img":false}]}
{"op":"mcm","clk":"5353925181","pt":1646219841689,"mc":[{"id":"1.195453781","rc":[{"atl":[[2.06,0]],"id":40917608},{"atb":[[3.45,0]],"id":28671742},{"atl":[[5.8,62.69],[5.7,4.26]],"id":38904370}],"con":true,"img":false}]}
{"op":"mcm","clk":"5353925279","pt":1646219842787,"mc":[{"id":"1.195453781","rc":[{"atb":[[1.16,196.62]],"id":40917608}],"con":true,"img":false}]}
{"op":"mcm","clk":"5353925420","pt":1646219844573,"mc":[{"id":"1.195453781","rc":[{"atb":[[2.38,6.03]],"id":41653210},{"atb":[[1.65,0]],"id":41120152},{"atb":[[1.74,0]],"id":38247349}],"con":true,"img":false}]}
{"op":"mcm","clk":"5353925446","pt":1646219844885,"mc":[{"id":"1.195453781","rc":[{"atb":[[1.87,28.34]],"id":38247349}],"con":true,"img":false}]}
{"op":"mcm","clk":"5353925814","pt":1646219848309,"mc":[{"id":"1.195453781","rc":[{"atb":[[2.32,0]],"id":41653210},{"atl":[[9.2,27.51],[6.6,0]],"id":41653210},{"atl":[[40,7.22],[24,5.43]],"id":28866557},{"atb":[[1.56,0],[1.36,106.57],[1.47,0]],"id":41120152},{"atl":[[3.5,0],[2.48,0],[4.2,38.22]],"id":41120152},{"atb":[[1.21,0],[1.19,0],[1.05,339.43]],"id":40917608},{"atl":[[2.4,89.72],[2.2,0]],"id":40917608},{"atb":[[1.65,0],[1.39,103.62],[1.61,0]],"id":42472248},{"atl":[[3.8,15.85],[4,32.69]],"id":42472248},{"atb":[[1.45,92.05],[1.68,0],[1.61,0]],"id":38247349},{"atl":[[4.3,0],[3.3,28.34],[5.4,36.68]],"id":38247349},{"atb":[[2.4,46.72]],"id":28671742},{"atl":[[7.4,0],[15,16.1],[9.8,0]],"id":28671742},{"atb":[[2.26,0],[2.1,72.44]],"id":38904370},{"atl":[[8.6,0],[15,17.89]],"id":38904370}],"con":true,"img":false}]}
{"op":"mcm","clk":"5353925827","pt":1646219848409,"mc":[{"id":"1.195453781","rc":[{"atb":[[2.4,34.6]],"id":41653210},{"atb":[[1.62,85.49]],"id":41120152},{"atl":[[2.44,31.59]],"id":41120152},{"atb":[[1.17,101.58]],"id":40917608},{"atl":[[2.04,28.68]],"id":40917608},{"atb":[[1.7,72.28]],"id":42472248},{"atb":[[1.71,71.47]],"id":38247349},{"atl":[[3.4,18.55]],"id":38247349},{"atl":[[7,7.51]],"id":28671742}],"con":true,"img":false}]}
{"op":"mcm","clk":"5353925837","pt":1646219848519,"mc":[{"id":"1.195453781","rc":[{"atb":[[4.5,27.28],[4.6,20.43]],"id":28866557},{"atl":[[2.54,145.24],[2.5,33.33]],"id":41120152},{"atb":[[1.6,420.76],[1.62,46.01]],"id":42472248}],"con":true,"img":false}]}
{"op":"mcm","clk":"5353925846","pt":1646219848621,"mc":[{"id":"1.195453781","rc":[{"atl":[[2.44,80.39]],"id":41120152},{"atb":[[1.7,153.23]],"id":42472248},{"atl":[[7.2,8.05],[7,32.79]],"id":28671742}],"con":true,"img":false}]}
{"op":"mcm","clk":"5353925854","pt":1646219848726,"mc":[{"id":"1.195453781","rc":[{"atl":[[2.54,48.7]],"id":41120152},{"atb":[[1.88,35.75]],"id":38247349}],"con":true,"img":false}]}
{"op":"mcm","clk":"5353925864","pt":1646219848831,"mc":[{"id":"1.195453781","rc":[{"atl":[[2.46,13.7]],"id":41120152},{"atb":[[1.69,22.94]],"id":42472248}],"con":true,"img":false}]}
{"op":"mcm","clk":"5353926050","pt":1646219850775,"mc":[{"id":"1.195453781","rc":[{"atb":[[1.72,10.42]],"id":41120152},{"atb":[[1.69,12.06]],"id":42472248}],"con":true,"img":false}]}
{"op":"mcm","clk":"5353926060","pt":1646219850931,"mc":[{"id":"1.195453781","rc":[{"atb":[[2.76,4.26]],"id":41653210},{"atb":[[1.68,62.39]],"id":41120152},{"atb":[[1.62,2.5]],"id":42472248}],"con":true,"img":false}]}
{"op":"mcm","clk":"5353926101","pt":1646219851302,"mc":[{"id":"1.195453781","rc":[{"atb":[[5.7,1.66]],"id":28866557}],"con":true,"img":false}]}
{"op":"mcm","clk":"5353926123","pt":1646219851505,"mc":[{"id":"1.195453781","rc":[{"atb":[[5.7,6.93]],"id":28866557}],"con":true,"img":false}]}
{"op":"mcm","clk":"5353926146","pt":1646219851715,"mc":[{"id":"1.195453781","rc":[{"atb":[[5.6,0]],"id":28866557}],"con":true,"img":false}]}
{"op":"mcm","clk":"5353926222","pt":1646219852394,"mc":[{"id":"1.195453781","rc":[{"atb":[[1.7,0]],"id":38247349},{"atb":[[3.05,24.39]],"id":28671742}],"con":true,"img":false}]}
{"op":"mcm","clk":"5353926468","pt":1646219855316,"mc":[{"id":"1.195453781","rc":[{"atb":[[2.72,0]],"id":41653210},{"atb":[[1.76,41.39]],"id":41120152},{"atb":[[1.63,49.93]],"id":42472248}],"con":true,"img":false}]}
{"op":"mcm","clk":"5353926566","pt":1646219856519,"mc":[{"id":"1.195453781","rc":[{"atb":[[1.72,0]],"id":41120152},{"atb":[[1.74,10.14]],"id":42472248},{"atb":[[1.75,10]],"id":38247349}],"con":true,"img":false}]}
{"op":"mcm","clk":"5353926733","pt":1646219858297,"mc":[{"id":"1.195453781","rc":[{"atb":[[1.68,0],[1.71,105.53],[1.76,91.65]],"id":41120152},{"atb":[[1.7,80.95]],"id":42472248},{"atb":[[1.87,0],[1.88,96.67]],"id":38247349}],"con":true,"img":false}]}
{"op":"mcm","clk":"5353926745","pt":1646219858400,"mc":[{"id":"1.195453781","rc":[{"atb":[[1.75,2.5]],"id":41120152},{"atb":[[1.66,72.28]],"id":42472248}],"con":true,"img":false}]}
{"op":"mcm","clk":"5353926759","pt":1646219858608,"mc":[{"id":"1.195453781","rc":[{"atl":[[1.94,10],[1.9,29.38]],"id":40917608}],"con":true,"img":false}]}
{"op":"mcm","clk":"5353926805","pt":1646219859136,"mc":[{"id":"1.195453781","rc":[{"atb":[[2.82,3.33]],"id":41653210},{"atb":[[1.63,0]],"id":42472248}],"con":true,"img":false}]}
{"op":"mcm","clk":"5353926823","pt":1646219859340,"mc":[{"id":"1.195453781","rc":[{"atb":[[2.82,26.48],[2.76,53.07],[2.7,5]],"id":41653210}],"con":true,"img":false}]}
{"op":"mcm","clk":"5353926842","pt":1646219859501,"mc":[{"id":"1.195453781","rc":[{"atb":[[2.78,2.5]],"id":41653210},{"atb":[[1.75,0]],"id":38247349}],"con":true,"img":false}]}
{"op":"mcm","clk":"5353927124","pt":1646219862614,"mc":[{"id":"1.195453781","rc":[{"atb":[[2.76,48.81]],"id":41653210},{"atb":[[1.8,9.38]],"id":41120152}],"con":true,"img":false}]}
{"op":"mcm","clk":"5353927193","pt":1646219863293,"mc":[{"id":"1.195453781","rc":[{"atb":[[1.71,30.42]],"id":42472248}],"con":true,"img":false}]}
{"op":"mcm","clk":"5353927325","pt":1646219864812,"mc":[{"id":"1.195453781","rc":[{"atb":[[1.62,0]],"id":41120152},{"atl":[[2.04,0]],"id":40917608},{"atb":[[3.4,10]],"id":28671742}],"con":true,"img":false}]}
{"op":"mcm","clk":"5353927333","pt":1646219864919,"mc":[{"id":"1.195453781","rc":[{"atl":[[18.5,0],[19,1.11]],"id":28866557},{"atl":[[1.89,40.87]],"id":40917608},{"atb":[[1.77,53.08]],"id":41120152},{"atl":[[3.8,0]],"id":42472248},{"atl":[[3.4,0]],"id":38247349},{"atb":[[3.55,16.02]],"id":28671742}],"con":true,"img":false}]}
{"op":"mcm","clk":"5353927345","pt":1646219865018,"mc":[{"id":"1.195453781","rc":[{"atl":[[3.3,15.85]],"id":42472248},{"atl":[[3.25,18.55]],"id":38247349},{"atb":[[3.55,45.78]],"id":28671742}],"con":true,"img":false}]}
{"op":"mcm","clk":"5353927357","pt":1646219865125,"mc":[{"id":"1.195453781","rc":[{"atb":[[2.72,23.76],[2.4,0]],"id":41653210},{"atb":[[1.76,50.26]],"id":41120152},{"atb":[[3.5,3]],"id":28671742}],"con":true,"img":false}]}
{"op":"mcm","clk":"5353927370","pt":1646219865230,"mc":[{"id":"1.195453781","rc":[{"atl":[[3.35,2.5],[3.3,68.77]],"id":42472248},{"atl":[[3.25,71.38],[3.3,0]],"id":38247349}],"con":true,"img":false}]}
{"op":"mcm","clk":"5353927399","pt":1646219865542,"mc":[{"id":"1.195453781","rc":[{"atb":[[1.8,0]],"id":41120152},{"atl":[[2.5,136.28]],"id":41120152},{"atb":[[1.6,267.49],[1.7,155.74]],"id":42472248},{"atb":[[1.92,8.16]],"id":38247349},{"atb":[[3.5,0]],"id":28671742}],"con":true,"img":false}]}
{"op":"mcm","clk":"5353927406","pt":1646219865646,"mc":[{"id":"1.195453781","rc":[{"atb":[[1.74,47.53]],"id":42472248}],"con":true,"img":false}]}
{"op":"mcm","clk":"5353927424","pt":1646219865804,"mc":[{"id":"1.195453781","rc":[{"atb":[[1.7,74.79]],"id":42472248}],"con":true,"img":false}]}
{"op":"mcm","clk":"5353927481","pt":1646219866636,"mc":[{"id":"1.195453781","rc":[{"atb":[[2.38,0]],"id":41653210},{"atb":[[1.69,0]],"id":42472248}],"con":true,"img":false}]}
{"op":"mcm","clk":"5353927673","pt":1646219868610,"mc":[{"id":"1.195453781","rc":[{"atb":[[2.88,3.99]],"id":41653210}],"con":true,"img":false}]}
{"op":"mcm","clk":"5353927781","pt":1646219869615,"mc":[{"id":"1.195453781","rc":[{"atb":[[1.88,60.92]],"id":38247349}],"con":true,"img":false}]}
{"op":"mcm","clk":"5353927793","pt":1646219869721,"mc":[{"id":"1.195453781","rc":[{"atb":[[1.78,40.33]],"id":41120152}],"con":true,"img":false}]}
{"op":"mcm","clk":"5353927963","pt":1646219871360,"mc":[{"id":"1.195453781","rc":[{"atb":[[2.8,0]],"id":41653210}],"con":true,"img":false}]}
{"op":"mcm","clk":"5353927985","pt":1646219871521,"mc":[{"id":"1.195453781","rc":[{"atb":[[2.9,1.66]],"id":41653210}],"con":true,"img":false}]}
{"op":"mcm","clk":"5353927993","pt":1646219871627,"mc":[{"id":"1.195453781","rc":[{"atb":[[3.65,2.83]],"id":28671742}],"con":true,"img":false}]}
{"op":"mcm","clk":"5353928009","pt":1646219871737,"mc":[{"id":"1.195453781","rc":[{"atb":[[2.82,23.15]],"id":41653210}],"con":true,"img":false}]}
{"op":"mcm","clk":"5353928046","pt":1646219872150,"mc":[{"id":"1.195453781","rc":[{"atl":[[4.3,6.06],[4.1,6.45],[4.4,13.02]],"id":41653210}],"con":true,"img":false}]}
{"op":"mcm","clk":"5353928066","pt":1646219872364,"mc":[{"id":"1.195453781","rc":[{"atl":[[4.8,0],[4.6,0],[5,25],[4.1,15.83],[4.4,31.78],[4.7,11.78]],"id":41653210}],"con":true,"img":false}]}
{"op":"mcm","clk":"5353928083","pt":1646219872517,"mc":[{"id":"1.195453781","rc":[{"atl":[[4.4,18.76]],"id":41653210}],"con":true,"img":false}]}
{"op":"mcm","clk":"5353928180","pt":1646219873719,"mc":[{"id":"1.195453781","rc":[{"atb":[[1.95,33.11]],"id":38247349}],"con":true,"img":false}]}
{"op":"mcm","clk":"5353928191","pt":1646219873823,"mc":[{"id":"1.195453781","rc":[{"atl":[[2.44,48.8]],"id":41120152},{"atb":[[1.66,0]],"id":42472248},{"atb":[[1.95,63.57]],"id":38247349},{"atl":[[7,25.28]],"id":28671742}],"con":true,"img":false}]}
{"op":"mcm","clk":"5353928200","pt":1646219873925,"mc":[{"id":"1.195453781","rc":[{"atl":[[2.42,31.59]],"id":41120152},{"atb":[[1.75,72.28]],"id":42472248},{"atb":[[1.94,2.5]],"id":38247349},{"atl":[[6.8,10.96]],"id":28671742}],"con":true,"img":false}]}
{"op":"mcm","clk":"5353928208","pt":1646219874031,"mc":[{"id":"1.195453781","rc":[{"atl":[[2.42,79.05]],"id":41120152}],"con":true,"img":false}]}
{"op":"mcm","clk":"5353928225","pt":1646219874244,"mc":[{"id":"1.195453781","rc":[{"atl":[[2.44,0]],"id":41120152}],"con":true,"img":false}]}
{"op":"mcm","clk":"5353928254","pt":1646219874659,"mc":[{"id":"1.195453781","rc":[{"atb":[[2.88,0]],"id":41653210},{"atb":[[1.74,37.39]],"id":42472248},{"atb":[[1.89,45.92],[1.71,0],[1.92,0]],"id":38247349}],"con":true,"img":false}]}
{"op":"mcm","clk":"5353928285","pt":1646219875022,"mc":[{"id":"1.195453781","rc":[{"atb":[[1.78,117.83],[1.76,200.39]],"id":41120152},{"atb":[[1.88,0],[1.9,54.54]],"id":38247349}],"con":true,"img":false}]}
{"op":"mcm","clk":"5353928298","pt":1646219875127,"mc":[{"id":"1.195453781","rc":[{"atb":[[1.71,5],[1.76,150.13]],"id":41120152}],"con":true,"img":false}]}
{"op":"mcm","clk":"5353928315","pt":1646219875336,"mc":[{"id":"1.195453781","rc":[{"atl":[[1.89,119.07],[1.9,5]],"id":40917608}],"con":true,"img":false}]}
{"op":"mcm","clk":"5353928381","pt":1646219875919,"mc":[{"id":"1.195453781","rc":[{"atb":[[5.8,6.55]],"id":28866557}],"con":true,"img":false}]}
{"op":"mcm","clk":"5353928396","pt":1646219876034,"mc":[{"id":"1.195453781","rc":[{"atb":[[5.9,8.93],[5.5,26.59]],"id":28866557}],"con":true,"img":false}]}
{"op":"mcm","clk":"5353928406","pt":1646219876127,"mc":[{"id":"1.195453781","rc":[{"atb":[[5.3,2.5]],"id":28866557}],"con":true,"img":false}]}
{"op":"mcm","clk":"5353928416","pt":1646219876235,"mc":[{"id":"1.195453781","rc":[{"atb":[[5.7,1.66]],"id":28866557}],"con":true,"img":false}]}
{"op":"mcm","clk":"5353928548","pt":1646219877531,"mc":[{"id":"1.195453781","rc":[{"atb":[[1.82,9.15]],"id":41120152}],"con":true,"img":false}]}
{"op":"mcm","clk":"5353928568","pt":1646219877746,"mc":[{"id":"1.195453781","rc":[{"atl":[[4.8,26.32],[5,0]],"id":41653210}],"con":true,"img":false}]}
{"op":"mcm","clk":"5353928589","pt":1646219877949,"mc":[{"id":"1.195453781","rc":[{"atb":[[1.71,0]],"id":42472248}],"con":true,"img":false}]}
{"op":"mcm","clk":"5353928656","pt":1646219878529,"mc":[{"id":"1.195453781","rc":[{"atb":[[3.65,5.97]],"id":28671742}],"con":true,"img":false}]}
{"op":"mcm","clk":"5353928678","pt":1646219878842,"mc":[{"id":"1.195453781","rc":[{"atb":[[2.82,27.72]],"id":41653210}],"con":true,"img":false}]}
{"op":"mcm","clk":"5353928696","pt":1646219878955,"mc":[{"id":"1.195453781","rc":[{"atl":[[4,0]],"id":42472248}],"con":true,"img":false}]}
{"op":"mcm","clk":"5353928702","pt":1646219879052,"mc":[{"id":"1.195453781","rc":[{"atl":[[3.8,32.69]],"id":42472248}],"con":true,"img":false}]}
{"op":"mcm","clk":"5353928790","pt":1646219879732,"mc":[{"id":"1.195453781","rc":[{"atb":[[5.8,0]],"id":28866557},{"atb":[[1.78,77.5]],"id":41120152}],"con":true,"img":false}]}
{"op":"mcm","clk":"5353928813","pt":1646219879943,"mc":[{"id":"1.195453781","rc":[{"atb":[[5.9,0]],"id":28866557}],"con":true,"img":false}]}
{"op":"mcm","clk":"5353928825","pt":1646219880047,"mc":[{"id":"1.195453781","rc":[{"atb":[[5.6,5.27]],"id":28866557}],"con":true,"img":false}]}
{"op":"mcm","clk":"5353928884","pt":1646219880583,"mc":[{"id":"1.195453781","rc":[{"atb":[[1.79,9.5]],"id":42472248},{"atb":[[1.99,7.58]],"id":38247349}],"con":true,"img":false}]}
{"op":"mcm","clk":"5353928993","pt":1646219881630,"mc":[{"id":"1.195453781","rc":[{"atb":[[3.6,34.76]],"id":28671742}],"con":true,"img":false}]}
{"op":"mcm","clk":"5353929002","pt":1646219881734,"mc":[{"id":"1.195453781","rc":[{"atb":[[3.55,16.02]],"id":28671742}],"con":true,"img":false}]}
{"op":"mcm","clk":"5353929041","pt":1646219882154,"mc":[{"id":"1.195453781","rc":[{"atl":[[4.3,21.21]],"id":41653210},{"atb":[[1.7,0],[1.71,44.3],[1.74,122.62]],"id":42472248}],"con":true,"img":false}]}
{"op":"mcm","clk":"5353929050","pt":1646219882256,"mc":[{"id":"1.195453781","rc":[{"atl":[[4.3,15.15]],"id":41653210},{"atb":[[1.79,52.12]],"id":42472248}],"con":true,"img":false}]}
{"op":"mcm","clk":"5353929069","pt":1646219882465,"mc":[{"id":"1.195453781","rc":[{"atb":[[1.74,85.23]],"id":42472248}],"con":true,"img":false}]}
{"op":"mcm","clk":"5353929195","pt":1646219883628,"mc":[{"id":"1.195453781","rc":[{"atb":[[1.79,42.62]],"id":42472248},{"atb":[[3.65,3.14]],"id":28671742}],"con":true,"img":false}]}
{"op":"mcm","clk":"5353929205","pt":1646219883739,"mc":[{"id":"1.195453781","rc":[{"atb":[[1.79,0]],"id":42472248}],"con":true,"img":false}]}
{"op":"mcm","clk":"5353929216","pt":1646219883838,"mc":[{"id":"1.195453781","rc":[{"atb":[[5.3,14.29],[5.5,8.72]],"id":28866557},{"atb":[[1.75,155.82]],"id":42472248}],"con":true,"img":false}]}
{"op":"mcm","clk":"5353929292","pt":1646219884671,"mc":[{"id":"1.195453781","rc":[{"atb":[[5.8,3.33]],"id":28866557},{"atb":[[1.79,27.47]],"id":41120152},{"atb":[[1.95,30.46]],"id":38247349}],"con":true,"img":false}]}
{"op":"mcm","clk":"5353929357","pt":1646219885257,"mc":[{"id":"1.195453781","rc":[{"atl":[[4.1,9.38],[4.2,6.25]],"id":41653210},{"atb":[[3.05,9.76],[3.15,0]],"id":28671742},{"atl":[[5.9,4.08],[6.2,5.48]],"id":28671742}],"con":true,"img":false}]}
{"op":"mcm","clk":"5353929382","pt":1646219885459,"mc":[{"id":"1.195453781","rc":[{"atl":[[6.8,34.94],[5.9,11.25],[7,0]],"id":28671742}],"con":true,"img":false}]}
{"op":"mcm","clk":"5353929400","pt":1646219885667,"mc":[{"id":"1.195453781","rc":[{"atl":[[6.2,0]],"id":28671742}],"con":true,"img":false}]}
{"op":"mcm","clk":"5353929484","pt":1646219886571,"mc":[{"id":"1.195453781","rc":[{"atb":[[2.88,3.99]],"id":41653210},{"atb":[[1.99,0]],"id":38247349}],"con":true,"img":false}]}
{"op":"mcm","clk":"5353929499","pt":1646219886773,"mc":[{"id":"1.195453781","rc":[{"atb":[[2.76,0],[2.88,15.71],[2.78,25.94]],"id":41653210},{"spn":3.5,"spf":"NaN","id":41653210},{"spn":10.9,"spf":"NaN","id":28866557},{"spn":2.12,"spf":"NaN","id":41120152},{"spn":1.51,"spf":"NaN","id":40917608},{"spn":2.31,"spf":"NaN","id":42472248},{"spn":2.46,"spf":"NaN","id":38247349},{"spn":4.87,"spf":"NaN","id":28671742},{"spn":4.35,"spf":"NaN","id":38904370}],"con":true,"img":false}]}
{"op":"mcm","clk":"5353929512","pt":1646219886877,"mc":[{"id":"1.195453781","rc":[{"atb":[[2.82,4.57]],"id":41653210}],"con":true,"img":false}]}
{"op":"mcm","clk":"5353929637","pt":1646219888253,"mc":[{"id":"1.195453781","rc":[{"atb":[[2.72,0]],"id":41653210},{"atl":[[2.42,47.46]],"id":41120152},{"atl":[[3.3,52.92]],"id":42472248},{"atl":[[3.25,52.83]],"id":38247349},{"atb":[[3.55,0]],"id":28671742}],"con":true,"img":false}]}
{"op":"mcm","clk":"5353929642","pt":1646219888345,"mc":[{"id":"1.195453781","rc":[{"atb":[[2.84,23.76]],"id":41653210},{"atb":[[1.51,55.41],[1.36,0]],"id":41120152},{"atl":[[2.48,31.59]],"id":41120152},{"atl":[[3.25,15.85]],"id":42472248},{"atl":[[3.2,27.64]],"id":38247349},{"atb":[[3.6,50.78]],"id":28671742}],"con":true,"img":false}]}
{"op":"mcm","clk":"5353929652","pt":1646219888449,"mc":[{"id":"1.195453781","rc":[{"atl":[[2.5,33.33],[2.48,120.19],[2.42,0]],"id":41120152},{"atl":[[3.25,100.1],[3.3,0]],"id":42472248},{"atb":[[1.96,22.74]],"id":38247349}],"con":true,"img":false}]}
{"op":"mcm","clk":"5353929668","pt":1646219888658,"mc":[{"id":"1.195453781","rc":[{"atl":[[2.48,151.07]],"id":41120152}],"con":true,"img":false}]}
{"op":"mcm","clk":"5353929683","pt":1646219888862,"mc":[{"id":"1.195453781","rc":[{"atl":[[4.3,51.95],[4.4,0]],"id":41653210}],"con":true,"img":false}]}
{"op":"mcm","clk":"5353929783","pt":1646219889866,"mc":[{"id":"1.195453781","rc":[{"atb":[[1.74,0],[1.71,205]],"id":42472248}],"con":true,"img":false}]}
{"op":"mcm","clk":"5353929828","pt":1646219890278,"mc":[{"id":"1.195453781","rc":[{"atb":[[5.7,0]],"id":28866557},{"atb":[[1.96,61.42]],"id":38247349}],"con":true,"img":false}]}
{"op":"mcm","clk":"5353929846","pt":1646219890484,"mc":[{"id":"1.195453781","rc":[{"atb":[[1.95,0]],"id":38247349}],"con":true,"img":false}]}
{"op":"mcm","clk":"5353929854","pt":1646219890587,"mc":[{"id":"1.195453781","rc":[{"atl":[[2.46,59.31]],"id":41120152}],"con":true,"img":false}]}
{"op":"mcm","clk":"5353929860","pt":1646219890645,"mc":[{"id":"1.195453781","rc":[{"atl":[[2.26,3]],"id":38247349}],"con":true,"img":false}]}
{"op":"mcm","clk":"5353929873","pt":1646219890749,"mc":[{"id":"1.195453781","rc":[{"atl":[[2.48,120.19]],"id":41120152},{"atl":[[3.2,105.01]],"id":38247349}],"con":true,"img":false}]}
{"op":"mcm","clk":"5353929882","pt":1646219890853,"mc":[{"id":"1.195453781","rc":[{"atl":[[3.25,0]],"id":38247349}],"con":true,"img":false}]}
{"op":"mcm","clk":"5353929891","pt":1646219890964,"mc":[{"id":"1.195453781","rc":[{"atl":[[2.38,2],[2.26,0]],"id":38247349}],"con":true,"img":false}]}
{"op":"mcm","clk":"5353929908","pt":1646219891170,"mc":[{"id":"1.195453781","rc":[{"atl":[[2.38,0],[2.16,4]],"id":38247349}],"con":true,"img":false}]}
{"op":"mcm","clk":"5353929941","pt":1646219891482,"mc":[{"id":"1.195453781","rc":[{"atb":[[1.78,216.46],[1.76,0],[1.82,78.63]],"id":41120152}],"con":true,"img":false}]}
{"op":"mcm","clk":"5353929964","pt":1646219891697,"mc":[{"id":"1.195453781","rc":[{"atb":[[1.78,138.96]],"id":41120152}],"con":true,"img":false}]}
{"op":"mcm","clk":"5353929980","pt":1646219891758,"mc":[{"id":"1.195453781","rc":[{"atl":[[4.1,15.83]],"id":41653210},{"atb":[[1.01,22099.41]],"id":40917608},{"atb":[[1.64,156.25],[1.6,100.82]],"id":42472248},{"atl":[[2.14,4]],"id":38247349},{"atl":[[6,4],[5.9,7.17]],"id":28671742}],"con":true,"img":false}]}
{"op":"mcm","clk":"5353929997","pt":1646219891965,"mc":[{"id":"1.195453781","rc":[{"atl":[[3.2,27.64]],"id":38247349}],"con":true,"img":false}]}
{"op":"mcm","clk":"5353930053","pt":1646219892386,"mc":[{"id":"1.195453781","rc":[{"atb":[[1.71,160.7]],"id":42472248}],"con":true,"img":false}]}
{"op":"mcm","clk":"5353930062","pt":1646219892487,"mc":[{"id":"1.195453781","rc":[{"atb":[[5.3,2.5],[5.9,6.45],[5.5,21.62]],"id":28866557}],"con":true,"img":false}]}
{"op":"mcm","clk":"5353930087","pt":1646219892706,"mc":[{"id":"1.195453781","rc":[{"atb":[[5.6,0]],"id":28866557}],"con":true,"img":false}]}
{"op":"mcm","clk":"5353930103","pt":1646219892861,"mc":[{"id":"1.195453781","rc":[{"atb":[[2.88,11.72]],"id":41653210},{"atb":[[1.82,69.48]],"id":41120152},{"atb":[[1.79,9.5]],"id":42472248}],"con":true,"img":false}]}
{"op":"mcm","clk":"5353930120","pt":1646219893067,"mc":[{"id":"1.195453781","rc":[{"atb":[[1.82,0]],"id":41120152}],"con":true,"img":false}]}
{"op":"mcm","clk":"5353930129","pt":1646219893174,"mc":[{"id":"1.195453781","rc":[{"atb":[[1.79,124.06]],"id":41120152}],"con":true,"img":false}]}
{"op":"mcm","clk":"5353930202","pt":1646219893907,"mc":[{"id":"1.195453781","rc":[{"atb":[[1.79,20.04]],"id":42472248}],"con":true,"img":false}]}
{"op":"mcm","clk":"5353930235","pt":1646219894275,"mc":[{"id":"1.195453781","rc":[{"atb":[[1.96,38.68]],"id":38247349}],"con":true,"img":false}]}
{"op":"mcm","clk":"5353930251","pt":1646219894488,"mc":[{"id":"1.195453781","rc":[{"atb":[[1.96,0]],"id":38247349}],"con":true,"img":false}]}
{"op":"mcm","clk":"5353930266","pt":1646219894693,"mc":[{"id":"1.195453781","rc":[{"atb":[[1.89,87.83],[1.9,5],[1.94,23.46]],"id":38247349}],"con":true,"img":false}]}
{"op":"mcm","clk":"5353930408","pt":1646219896152,"mc":[{"id":"1.195453781","rc":[{"atl":[[2.5,145.04],[2.48,31.59]],"id":41120152}],"con":true,"img":false}]}
{"op":"mcm","clk":"5353930420","pt":1646219896260,"mc":[{"id":"1.195453781","rc":[{"atb":[[5.8,0]],"id":28866557}],"con":true,"img":false}]}
{"op":"mcm","clk":"5353930432","pt":1646219896365,"mc":[{"id":"1.195453781","rc":[{"atb":[[1.72,43.69]],"id":42472248}],"con":true,"img":false}]}
{"op":"mcm","clk":"5353930446","pt":1646219896465,"mc":[{"id":"1.195453781","rc":[{"atb":[[5.9,0]],"id":28866557}],"con":true,"img":false}]}
{"op":"mcm","clk":"5353930463","pt":1646219896671,"mc":[{"id":"1.195453781","rc":[{"atb":[[5.6,2.99]],"id":28866557}],"con":true,"img":false}]}
{"op":"mcm","clk":"5353930632","pt":1646219898296,"mc":[{"id":"1.195453781","rc":[{"atb":[[2.84,0]],"id":41653210},{"atl":[[20,2.63]],"id":28866557},{"atb":[[1.77,0]],"id":41120152},{"atb":[[1.45,0],[1.61,50.98]],"id":38247349},{"atl":[[3.2,9.09]],"id":38247349}],"con":true,"img":false}]}
{"op":"mcm","clk":"5353930643","pt":1646219898397,"mc":[{"id":"1.195453781","rc":[{"atb":[[2.8,23.76]],"id":41653210},{"atl":[[18,2.72]],"id":28866557},{"atb":[[1.8,53.08]],"id":41120152},{"atl":[[3.4,18.55]],"id":38247349}],"con":true,"img":false}]}
{"op":"mcm","clk":"5353930654","pt":1646219898501,"mc":[{"id":"1.195453781","rc":[{"atb":[[1.71,0],[1.72,139.3]],"id":42472248}],"con":true,"img":false}]}
{"op":"mcm","clk":"5353930660","pt":1646219898556,"mc":[{"id":"1.195453781","rc":[{"atb":[[1.79,67.84]],"id":42472248}],"con":true,"img":false}]}
{"op":"mcm","clk":"5353930679","pt":1646219898764,"mc":[{"id":"1.195453781","rc":[{"atb":[[1.75,72.28]],"id":42472248}],"con":true,"img":false}]}
{"op":"mcm","clk":"5353930799","pt":1646219900078,"mc":[{"id":"1.195453781","rc":[{"atb":[[5.5,8.72]],"id":28866557}],"con":true,"img":false}]}
{"op":"mcm","clk":"5353930809","pt":1646219900192,"mc":[{"id":"1.195453781","rc":[{"atb":[[5.3,10.35]],"id":28866557}],"con":true,"img":false}]}
{"op":"mcm","clk":"5353930864","pt":1646219900767,"mc":[{"id":"1.195453781","rc":[{"atb":[[5.7,5.97]],"id":28866557}],"con":true,"img":false}]}
{"op":"mcm","clk":"5353930891","pt":1646219900978,"mc":[{"id":"1.195453781","rc":[{"atl":[[2.12,4],[3.95,8.2],[3.7,37.04]],"id":38247349}],"con":true,"img":false}]}
{"op":"mcm","clk":"5353930902","pt":1646219901180,"mc":[{"id":"1.195453781","rc":[{"atl":[[2.1,2]],"id":38247349}],"con":true,"img":false}]}
{"op":"mcm","clk":"5353930956","pt":1646219901813,"mc":[{"id":"1.195453781","rc":[{"atl":[[4.5,21.43]],"id":41653210},{"atb":[[2.98,55.8]],"id":28671742},{"atl":[[6.4,9.26]],"id":28671742}],"con":true,"img":false}]}
{"op":"mcm","clk":"5353930978","pt":1646219901971,"mc":[{"id":"1.195453781","rc":[{"atl":[[6.4,33.9],[6.8,10.96]],"id":28671742}],"con":true,"img":false}]}
{"op":"mcm","clk":"5353931046","pt":1646219902704,"mc":[{"id":"1.195453781","rc":[{"atb":[[1.79,58.34]],"id":42472248}],"con":true,"img":false}]}
{"op":"mcm","clk":"5353931059","pt":1646219902806,"mc":[{"id":"1.195453781","rc":[{"atb":[[2.84,4.07]],"id":41653210},{"atb":[[1.73,10],[1.62,0],[1.81,2.5],[1.77,5]],"id":42472248}],"con":true,"img":false}]}
{"op":"mcm","clk":"5353931081","pt":1646219902967,"mc":[{"id":"1.195453781","rc":[{"atb":[[2.8,67.59],[2.78,2.5]],"id":41653210},{"atb":[[1.81,21.2]],"id":42472248}],"con":true,"img":false}]}
{"op":"mcm","clk":"5353931102","pt":1646219903177,"mc":[{"id":"1.195453781","rc":[{"atb":[[1.79,10.54]],"id":42472248}],"con":true,"img":false}]}
{"op":"mcm","clk":"5353931145","pt":1646219903699,"mc":[{"id":"1.195453781","rc":[{"atl":[[2.48,0]],"id":41120152},{"atb":[[3.6,34.76]],"id":28671742}],"con":true,"img":false}]}
{"op":"mcm","clk":"5353931152","pt":1646219903801,"mc":[{"id":"1.195453781","rc":[{"atl":[[2.44,31.59]],"id":41120152},{"atb":[[3.65,19.16]],"id":28671742}],"con":true,"img":false}]}
{"op":"mcm","clk":"5353931164","pt":1646219903913,"mc":[{"id":"1.195453781","rc":[{"atl":[[2.54,160.83],[2.5,33.33]],"id":41120152},{"atl":[[2.08,4],[2.16,0]],"id":38247349},{"atl":[[7.6,0]],"id":28671742}],"con":true,"img":false}]}
{"op":"mcm","clk":"5353931181","pt":1646219904115,"mc":[{"id":"1.195453781","rc":[{"atl":[[2.54,48.7]],"id":41120152}],"con":true,"img":false}]}
{"op":"mcm","clk":"5353931241","pt":1646219904697,"mc":[{"id":"1.195453781","rc":[{"atl":[[2.5,147.47]],"id":41120152}],"con":true,"img":false}]}
{"op":"mcm","clk":"5353931261","pt":1646219904902,"mc":[{"id":"1.195453781","rc":[{"atl":[[2.44,83.13]],"id":41120152},{"atb":[[1.72,95.61]],"id":42472248}],"con":true,"img":false}]}
{"op":"mcm","clk":"5353931272","pt":1646219905007,"mc":[{"id":"1.195453781","rc":[{"atb":[[2.84,0]],"id":41653210},{"atl":[[2.46,13.7]],"id":41120152}],"con":true,"img":false}]}
{"op":"mcm","clk":"5353931363","pt":1646219906001,"mc":[{"id":"1.195453781","rc":[{"atb":[[1.72,0],[1.77,49.96]],"id":42472248}],"con":true,"img":false}]}
{"op":"mcm","clk":"5353931520","pt":1646219907511,"mc":[{"id":"1.195453781","rc":[{"atl":[[2.14,0],[2.06,3]],"id":38247349}],"con":true,"img":false}]}
{"op":"mcm","clk":"5353931530","pt":1646219907617,"mc":[{"id":"1.195453781","rc":[{"atb":[[1.84,8.93],[1.8,153.08]],"id":41120152}],"con":true,"img":false}]}
{"op":"mcm","clk":"5353931552","pt":1646219907776,"mc":[{"id":"1.195453781","rc":[{"atb":[[1.78,0],[1.79,188.13]],"id":41120152}],"con":true,"img":false}]}
{"op":"mcm","clk":"5353931607","pt":1646219908308,"mc":[{"id":"1.195453781","rc":[{"atb":[[1.51,56.89],[1.39,0]],"id":42472248},{"atb":[[2.8,28.04],[2.4,0]],"id":28671742},{"atb":[[2.26,53.1],[2.1,0]],"id":38904370}],"con":true,"img":false}]}
{"op":"mcm","clk":"5353931639","pt":1646219908614,"mc":[{"id":"1.195453781","rc":[{"atb":[[5.8,4.29],[5.3,2.5],[5.5,17.3]],"id":28866557}],"con":true,"img":false}]}
{"op":"mcm","clk":"5353931652","pt":1646219908723,"mc":[{"id":"1.195453781","rc":[{"atb":[[5.6,0]],"id":28866557}],"con":true,"img":false}]}
{"op":"mcm","clk":"5353931684","pt":1646219908987,"mc":[{"id":"1.195453781","rc":[{"atb":[[1.82,38.37]],"id":42472248}],"con":true,"img":false}]}
{"op":"mcm","clk":"5353931710","pt":1646219909206,"mc":[{"id":"1.195453781","rc":[{"atb":[[1.84,93.39]],"id":41120152}],"con":true,"img":false}]}
{"op":"mcm","clk":"5353931725","pt":1646219909405,"mc":[{"id":"1.195453781","rc":[{"atb":[[1.8,53.08]],"id":41120152}],"con":true,"img":false}]}
{"op":"mcm","clk":"5353931744","pt":1646219909614,"mc":[{"id":"1.195453781","rc":[{"atb":[[2.82,0]],"id":41653210},{"atb":[[3.65,16.02]],"id":28671742}],"con":true,"img":false}]}
{"op":"mcm","clk":"5353931841","pt":1646219910508,"mc":[{"id":"1.195453781","rc":[{"atb":[[2.8,23.76],[2.78,46.33]],"id":41653210}],"con":true,"img":false}]}
{"op":"mcm","clk":"5353931874","pt":1646219910818,"mc":[{"id":"1.195453781","rc":[{"atb":[[2.86,4.03]],"id":41653210},{"atb":[[1.84,84.46]],"id":41120152}],"con":true,"img":false}]}
{"op":"mcm","clk":"5353931895","pt":1646219910976,"mc":[{"id":"1.195453781","rc":[{"atb":[[1.84,0]],"id":41120152}],"con":true,"img":false}]}
{"op":"mcm","clk":"5353931907","pt":1646219911080,"mc":[{"id":"1.195453781","rc":[{"atb":[[5.7,0]],"id":28866557},{"atb":[[1.79,160.66]],"id":41120152}],"con":true,"img":false}]}
{"op":"mcm","clk":"5353931922","pt":1646219911185,"mc":[{"id":"1.195453781","rc":[{"atb":[[1.79,261.93]],"id":41120152}],"con":true,"img":false}]}
{"op":"mcm","clk":"5353931929","pt":1646219911289,"mc":[{"id":"1.195453781","rc":[{"atb":[[5.8,0]],"id":28866557}],"con":true,"img":false}]}
{"op":"mcm","clk":"5353931952","pt":1646219911493,"mc":[{"id":"1.195453781","rc":[{"atb":[[5.6,2.99]],"id":28866557}],"con":true,"img":false}]}
{"op":"mcm","clk":"5353931977","pt":1646219911808,"mc":[{"id":"1.195453781","rc":[{"atl":[[4.7,45.56]],"id":41653210},{"atb":[[2.94,38.66]],"id":28671742},{"atl":[[6.8,20.44]],"id":28671742}],"con":true,"img":false}]}
{"op":"mcm","clk":"5353932049","pt":1646219912491,"mc":[{"id":"1.195453781","rc":[{"atl":[[4.2,0]],"id":41653210},{"atl":[[6,0],[5.9,11.25]],"id":28671742},{"atl":[[5.8,66.86],[5.7,0]],"id":38904370}],"con":true,"img":false}]}
{"op":"mcm","clk":"5353932068","pt":1646219912698,"mc":[{"id":"1.195453781","rc":[{"atl":[[4.3,15.15],[4.5,77.32]],"id":41653210},{"atl":[[6.4,9.26],[6.8,63.24]],"id":28671742},{"atl":[[5.6,0],[5.8,34.08],[5.9,44.64]],"id":38904370}],"con":true,"img":false}]}
{"op":"mcm","clk":"5353932075","pt":1646219912801,"mc":[{"id":"1.195453781","rc":[{"atl":[[5.7,13.59]],"id":38904370}],"con":true,"img":false}]}
{"op":"mcm","clk":"5353932155","pt":1646219913692,"mc":[{"id":"1.195453781","rc":[{"atb":[[2.86,0]],"id":41653210},{"atb":[[1.81,30.47]],"id":42472248}],"con":true,"img":false}]}
{"op":"mcm","clk":"5353932229","pt":1646219914471,"mc":[{"id":"1.195453781","rc":[{"atb":[[1.79,85.39],[1.77,5]],"id":42472248}],"con":true,"img":false}]}
{"op":"mcm","clk":"5353932239","pt":1646219914686,"mc":[{"id":"1.195453781","rc":[{"atb":[[1.82,75.79]],"id":42472248}],"con":true,"img":false}]}
{"op":"mcm","clk":"5353932254","pt":1646219914788,"mc":[{"id":"1.195453781","rc":[{"atb":[[1.81,11.77]],"id":42472248}],"con":true,"img":false}]}
{"op":"mcm","clk":"5353932297","pt":1646219915317,"mc":[{"id":"1.195453781","rc":[{"atb":[[5.7,5.97]],"id":28866557},{"atb":[[1.76,41.39],[1.79,101.27],[1.75,169.9]],"id":41120152}],"con":true,"img":false}]}
{"op":"mcm","clk":"5353932314","pt":1646219915520,"mc":[{"id":"1.195453781","rc":[{"atb":[[5.8,4.29]],"id":28866557}],"con":true,"img":false}]}
{"op":"mcm","clk":"5353932324","pt":1646219915573,"mc":[{"id":"1.195453781","rc":[{"atb":[[5.6,0]],"id":28866557}],"con":true,"img":false}]}
{"op":"mcm","clk":"5353932426","pt":1646219916729,"mc":[{"id":"1.195453781","rc":[{"atb":[[2.8,0]],"id":41653210},{"atl":[[4.7,33.78]],"id":41653210},{"atl":[[2.44,51.54]],"id":41120152},{"atl":[[3.25,84.25]],"id":42472248}],"con":true,"img":false}]}
{"op":"mcm","clk":"5353932438","pt":1646219916786,"mc":[{"id":"1.195453781","rc":[{"atb":[[2.82,23.76]],"id":41653210},{"atl":[[4.2,11.78]],"id":41653210},{"atl":[[2.48,31.59]],"id":41120152},{"atb":[[1.81,2.5]],"id":42472248},{"atl":[[3.2,21.35]],"id":42472248}],"con":true,"img":false}]}
{"op":"mcm","clk":"5353932453","pt":1646219916894,"mc":[{"id":"1.195453781","rc":[{"atl":[[2.5,33.33],[2.48,150.19]],"id":41120152}],"con":true,"img":false}]}
{"op":"mcm","clk":"5353932682","pt":1646219919284,"mc":[{"id":"1.195453781","rc":[{"atb":[[5.7,0]],"id":28866557}],"con":true,"img":false}]}
{"op":"mcm","clk":"5353932691","pt":1646219919391,"mc":[{"id":"1.195453781","rc":[{"atb":[[5.3,10.35],[5.5,8.72]],"id":28866557}],"con":true,"img":false}]}
{"op":"mcm","clk":"5353932703","pt":1646219919492,"mc":[{"id":"1.195453781","rc":[{"atb":[[5.8,0]],"id":28866557}],"con":true,"img":false}]}
{"op":"mcm","clk":"5353932709","pt":1646219919598,"mc":[{"id":"1.195453781","rc":[{"atb":[[5.6,3.16]],"id":28866557}],"con":true,"img":false}]}
{"op":"mcm","clk":"5353932772","pt":1646219920225,"mc":[{"id":"1.195453781","rc":[{"atb":[[2.84,4.07]],"id":41653210}],"con":true,"img":false}]}
{"op":"mcm","clk":"5353932789","pt":1646219920433,"mc":[{"id":"1.195453781","rc":[{"atb":[[2.82,66.57],[2.78,2.5]],"id":41653210},{"atb":[[1.84,8.93]],"id":41120152}],"con":true,"img":false}]}
{"op":"mcm","clk":"5353932993","pt":1646219922485,"mc":[{"id":"1.195453781","rc":[{"atb":[[2.9,65.79]],"id":28671742},{"atl":[[6,10]],"id":38904370}],"con":true,"img":false}]}
{"op":"mcm","clk":"5353933043","pt":1646219923009,"mc":[{"id":"1.195453781","rc":[{"atb":[[2.84,0]],"id":41653210}],"con":true,"img":false}]}
{"op":"mcm","clk":"5353933053","pt":1646219923113,"mc":[{"id":"1.195453781","rc":[{"atb":[[1.86,8.73]],"id":42472248}],"con":true,"img":false}]}
{"op":"mcm","clk":"5353933063","pt":1646219923216,"mc":[{"id":"1.195453781","rc":[{"atb":[[5.7,6.32]],"id":28866557},{"atb":[[1.76,0]],"id":41120152},{"atb":[[1.81,63.67]],"id":42472248}],"con":true,"img":false}]}
{"op":"mcm","clk":"5353933074","pt":1646219923319,"mc":[{"id":"1.195453781","rc":[{"atb":[[1.79,10.54],[1.86,39.31]],"id":42472248}],"con":true,"img":false}]}
{"op":"mcm","clk":"5353933083","pt":1646219923424,"mc":[{"id":"1.195453781","rc":[{"atb":[[1.84,87.39]],"id":41120152}],"con":true,"img":false}]}
{"op":"mcm","clk":"5353933101","pt":1646219923540,"mc":[{"id":"1.195453781","rc":[{"atb":[[1.84,97.3],[1.79,0]],"id":41120152},{"atb":[[1.82,38.37],[1.79,0]],"id":42472248}],"con":true,"img":false}]}
{"op":"mcm","clk":"5353933108","pt":1646219923631,"mc":[{"id":"1.195453781","rc":[{"atb":[[1.79,156.93],[1.75,2.5]],"id":41120152}],"con":true,"img":false}]}
{"op":"mcm","clk":"5353933117","pt":1646219923740,"mc":[{"id":"1.195453781","rc":[{"atb":[[1.79,0]],"id":41120152}],"con":true,"img":false}]}
{"op":"mcm","clk":"5353933171","pt":1646219924248,"mc":[{"id":"1.195453781","rc":[{"atb":[[2.82,42.81]],"id":41653210},{"atl":[[4.2,0]],"id":41653210},{"atl":[[1.89,78.2]],"id":40917608},{"atb":[[1.83,49.24]],"id":42472248},{"atb":[[1.89,41.91]],"id":38247349}],"con":true,"img":false}]}
{"op":"mcm","clk":"5353933190","pt":1646219924317,"mc":[{"id":"1.195453781","rc":[{"atb":[[2.8,23.76]],"id":41653210},{"atl":[[4.4,11.78]],"id":41653210},{"atb":[[5.8,4.42],[5.3,2.5],[5.5,17.56]],"id":28866557},{"atl":[[1.82,40.87]],"id":40917608},{"atb":[[1.75,0]],"id":42472248},{"atb":[[1.95,45.92]],"id":38247349}],"con":true,"img":false}]}
{"op":"mcm","clk":"5353933218","pt":1646219924525,"mc":[{"id":"1.195453781","rc":[{"atb":[[5.6,0]],"id":28866557},{"atl":[[1.89,0],[1.82,79.97],[1.86,80.7]],"id":40917608},{"atb":[[1.89,0],[1.95,52.67],[1.9,18.5]],"id":38247349}],"con":true,"img":false}]}
{"op":"mcm","clk":"5353933226","pt":1646219924625,"mc":[{"id":"1.195453781","rc":[{"atl":[[1.85,0]],"id":40917608},{"atb":[[1.94,2.5]],"id":38247349}],"con":true,"img":false}]}
{"op":"mcm","clk":"5353933245","pt":1646219924733,"mc":[{"id":"1.195453781","rc":[{"atl":[[6.2,0],[6.6,0],[5.9,34.44]],"id":38904370}],"con":true,"img":false}]}
{"op":"mcm","clk":"5353933274","pt":1646219925043,"mc":[{"id":"1.195453781","rc":[{"atb":[[1.82,0]],"id":42472248}],"con":true,"img":false}]}
{"op":"mcm","clk":"5353933342","pt":1646219925731,"mc":[{"id":"1.195453781","rc":[{"atb":[[1.84,88.37]],"id":41120152},{"atb":[[1.86,30.58]],"id":42472248}],"con":true,"img":false}]}
{"op":"mcm","clk":"5353933363","pt":1646219925942,"mc":[{"id":"1.195453781","rc":[{"atb":[[1.86,0]],"id":42472248}],"con":true,"img":false}]}
{"op":"mcm","clk":"5353933376","pt":1646219925998,"mc":[{"id":"1.195453781","rc":[{"atb":[[1.83,109.11]],"id":42472248}],"con":true,"img":false}]}
{"op":"mcm","clk":"5353933505","pt":1646219927102,"mc":[{"id":"1.195453781","rc":[{"atb":[[5.7,0]],"id":28866557},{"atb":[[1.76,41.39]],"id":41120152}],"con":true,"img":false}]}
{"op":"mcm","clk":"5353933514","pt":1646219927205,"mc":[{"id":"1.195453781","rc":[{"atb":[[5.8,0],[5.3,10.35],[5.5,8.72]],"id":28866557}],"con":true,"img":false}]}
{"op":"mcm","clk":"5353933526","pt":1646219927322,"mc":[{"id":"1.195453781","rc":[{"atb":[[5.6,3.92]],"id":28866557}],"con":true,"img":false}]}
{"op":"mcm","clk":"5353933569","pt":1646219927831,"mc":[{"id":"1.195453781","rc":[{"atb":[[2.82,0],[2.8,70.23]],"id":41653210}],"con":true,"img":false}]}
{"op":"mcm","clk":"5353933604","pt":1646219928351,"mc":[{"id":"1.195453781","rc":[{"atb":[[1.95,6.75]],"id":38247349}],"con":true,"img":false}]}
{"op":"mcm","clk":"5353933612","pt":1646219928404,"mc":[{"id":"1.195453781","rc":[{"atl":[[4.5,21.43],[4.4,54.59]],"id":41653210},{"atb":[[5.7,1.66]],"id":28866557},{"atb":[[1.74,45.92]],"id":38247349}],"con":true,"img":false}]}
{"op":"mcm","clk":"5353933671","pt":1646219928925,"mc":[{"id":"1.195453781","rc":[{"atb":[[1.78,40.33]],"id":42472248}],"con":true,"img":false}]}
{"op":"mcm","clk":"5353933829","pt":1646219930548,"mc":[{"id":"1.195453781","rc":[{"atb":[[1.78,196.35],[1.81,2.5]],"id":42472248}],"con":true,"img":false}]}
{"op":"mcm","clk":"5353933876","pt":1646219930917,"mc":[{"id":"1.195453781","rc":[{"atb":[[1.76,198.32]],"id":41120152}],"con":true,"img":false}]}
{"op":"mcm","clk":"5353933895","pt":1646219931131,"mc":[{"id":"1.195453781","rc":[{"atb":[[5.8,3.33],[5.7,4.96]],"id":28866557}],"con":true,"img":false}]}
{"op":"mcm","clk":"5353933915","pt":1646219931335,"mc":[{"id":"1.195453781","rc":[{"atb":[[5.6,0]],"id":28866557}],"con":true,"img":false}]}
{"op":"mcm","clk":"5353933966","pt":1646219931814,"mc":[{"id":"1.195453781","rc":[{"atb":[[1.88,8.52]],"id":41120152},{"atl":[[1.9,165.4],[1.86,2.5]],"id":40917608},{"atb":[[1.87,8.62]],"id":42472248}],"con":true,"img":false}]}
{"op":"mcm","clk":"5353933982","pt":1646219931922,"mc":[{"id":"1.195453781","rc":[{"atb":[[1.88,80.27]],"id":41120152},{"atb":[[1.87,39.2]],"id":42472248}],"con":true,"img":false}]}
{"op":"mcm","clk":"5353933990","pt":1646219932026,"mc":[{"id":"1.195453781","rc":[{"atb":[[1.84,9.91]],"id":41120152},{"atb":[[1.83,49.24]],"id":42472248}],"con":true,"img":false}]}
{"op":"mcm","clk":"5353934044","pt":1646219932549,"mc":[{"id":"1.195453781","rc":[{"atl":[[6.4,13.89]],"id":38904370}],"con":true,"img":false}]}
{"op":"mcm","clk":"5353934251","pt":1646219934751,"mc":[{"id":"1.195453781","rc":[{"atb":[[2.86,4.03]],"id":41653210},{"atb":[[1.88,71.75]],"id":41120152}],"con":true,"img":false}]}
{"op":"mcm","clk":"5353934271","pt":1646219934958,"mc":[{"id":"1.195453781","rc":[{"atb":[[1.88,0]],"id":41120152}],"con":true,"img":false}]}
{"op":"mcm","clk":"5353934281","pt":1646219935064,"mc":[{"id":"1.195453781","rc":[{"atb":[[5.3,2.5],[5.5,17.81]],"id":28866557}],"con":true,"img":false}]}
{"op":"mcm","clk":"5353934291","pt":1646219935120,"mc":[{"id":"1.195453781","rc":[{"atb":[[5.9,4.54]],"id":28866557},{"atb":[[1.84,88.37]],"id":41120152}],"con":true,"img":false}]}
{"op":"mcm","clk":"5353934308","pt":1646219935328,"mc":[{"id":"1.195453781","rc":[{"atb":[[5.7,1.66]],"id":28866557}],"con":true,"img":false}]}
{"op":"mcm","clk":"5353934317","pt":1646219935429,"mc":[{"id":"1.195453781","rc":[{"atb":[[1.76,156.93]],"id":41120152},{"atb":[[1.78,156.02]],"id":42472248}],"con":true,"img":false}]}
{"op":"mcm","clk":"5353934488","pt":1646219937418,"mc":[{"id":"1.195453781","rc":[{"atb":[[5.8,0]],"id":28866557}],"con":true,"img":false}]}
{"op":"mcm","clk":"5353934500","pt":1646219937523,"mc":[{"id":"1.195453781","rc":[{"atb":[[5.9,0]],"id":28866557}],"con":true,"img":false}]}
{"op":"mcm","clk":"5353934511","pt":1646219937627,"mc":[{"id":"1.195453781","rc":[{"atb":[[1.78,9.62]],"id":38247349}],"con":true,"img":false}]}
{"op":"mcm","clk":"5353934521","pt":1646219937730,"mc":[{"id":"1.195453781","rc":[{"atb":[[5.6,2.37]],"id":28866557}],"con":true,"img":false}]}
{"op":"mcm","clk":"5353934571","pt":1646219938255,"mc":[{"id":"1.195453781","rc":[{"atl":[[2.48,118.6]],"id":41120152},{"atl":[[3.4,0]],"id":38247349}],"con":true,"img":false}]}
{"op":"mcm","clk":"5353934579","pt":1646219938359,"mc":[{"id":"1.195453781","rc":[{"atl":[[2.52,31.59]],"id":41120152},{"atl":[[3.5,18.55]],"id":38247349}],"con":true,"img":false}]}
{"op":"mcm","clk":"5353934622","pt":1646219938782,"mc":[{"id":"1.195453781","rc":[{"atb":[[1.78,0],[1.81,93.34]],"id":42472248}],"con":true,"img":false}]}
{"op":"mcm","clk":"5353934703","pt":1646219939466,"mc":[{"id":"1.195453781","rc":[{"atl":[[2.12,0],[2.1,0],[2.08,0],[2.06,0]],"id":38247349}],"con":true,"img":false}]}
{"op":"mcm","clk":"5353934721","pt":1646219939628,"mc":[{"id":"1.195453781","rc":[{"atl":[[3.35,62.66]],"id":38247349}],"con":true,"img":false}]}
{"op":"mcm","clk":"5353934728","pt":1646219939733,"mc":[{"id":"1.195453781","rc":[{"atb":[[1.77,40.85]],"id":41120152},{"atb":[[1.84,37.45]],"id":42472248}],"con":true,"img":false}]}
{"op":"mcm","clk":"5353934742","pt":1646219939845,"mc":[{"id":"1.195453781","rc":[{"atb":[[5.7,4.69]],"id":28866557}],"con":true,"img":false}]}
{"op":"mcm","clk":"5353934749","pt":1646219939948,"mc":[{"id":"1.195453781","rc":[{"atb":[[1.76,0],[1.77,197.78]],"id":41120152}],"con":true,"img":false}]}
{"op":"mcm","clk":"5353934764","pt":1646219940056,"mc":[{"id":"1.195453781","rc":[{"atb":[[5.6,0]],"id":28866557}],"con":true,"img":false}]}
{"op":"mcm","clk":"5353934932","pt":1646219941700,"mc":[{"id":"1.195453781","rc":[{"atb":[[2.3,15.38],[2.1,0],[2.2,0]],"id":41653210},{"atl":[[5.6,0],[7.2,0],[18,0],[9.2,24.56],[13,0]],"id":41653210},{"atb":[[3.75,0],[4,0],[4.5,10]],"id":28866557},{"atl":[[16,0.68],[34,0],[22,3.57],[60,0],[120,0]],"id":28866557},{"atb":[[1.45,0],[1.55,0],[1.5,100]],"id":41120152},{"atl":[[2.82,0],[3.55,0],[3.05,0],[5.1,0],[4.1,0]],"id":41120152},{"atb":[[1.01,10000],[1.02,250],[1.07,0]],"id":40917608},{"atl":[[2.08,0],[2.48,0],[2.88,0],[2.28,0],[2.68,0]],"id":40917608},{"atb":[[1.6,0],[1.55,0],[1.5,150]],"id":42472248},{"atl":[[4.4,0],[5.4,0],[2.88,12.99],[3.2,15.85],[3.7,0]],"id":42472248},{"atb":[[1.6,0],[1.55,0],[1.65,0]],"id":38247349},{"atl":[[3.45,30.61],[3.95,0],[4.9,0],[2.98,17.83],[5.9,0]],"id":38247349},{"atb":[[2.98,25.25],[2.88,0],[2.78,0]],"id":28671742},{"atl":[[32,0],[10.5,0],[21,0],[8.2,0],[15.5,0]],"id":28671742},{"atb":[[2.84,0],[2.94,0],[2.74,0]],"id":38904370},{"atl":[[8,0],[10,0],[20,0],[15,16.16],[30,0]],"id":38904370}],"con":true,"img":false}]}
{"op":"mcm","clk":"5353934952","pt":1646219941879,"mc":[{"id":"1.195453781","rc":[{"atl":[[2.88,0]],"id":42472248},{"atl":[[2.98,0]],"id":38247349}],"con":true,"img":false}]}
{"op":"mcm","clk":"5353934973","pt":1646219942084,"mc":[{"id":"1.195453781","rc":[{"atb":[[5.8,3.33]],"id":28866557},{"atl":[[16,0]],"id":28866557},{"atl":[[3.2,52.21],[3.35,95.65],[3.25,0]],"id":42472248},{"atb":[[1.91,21.93]],"id":38247349},{"atl":[[3.2,29.28]],"id":38247349}],"con":true,"img":false}]}
{"op":"mcm","clk":"5353934992","pt":1646219942280,"mc":[{"id":"1.195453781","rc":[{"atb":[[5.5,8.72],[5.3,10.35]],"id":28866557},{"atl":[[18,6.64]],"id":28866557},{"atb":[[1.91,98.76],[1.9,5]],"id":38247349}],"con":true,"img":false}]}
{"op":"mcm","clk":"5353935019","pt":1646219942440,"mc":[{"id":"1.195453781","rc":[{"atl":[[6.8,21.55]],"id":38904370}],"con":true,"img":false}]}
{"op":"mcm","clk":"5353935036","pt":1646219942653,"mc":[{"id":"1.195453781","rc":[{"atb":[[2.8,46.47]],"id":41653210},{"atb":[[5.5,20.77],[5.3,2.5]],"id":28866557}],"con":true,"img":false}]}
{"op":"mcm","clk":"5353935045","pt":1646219942755,"mc":[{"id":"1.195453781","rc":[{"atb":[[2.82,23.76]],"id":41653210},{"atb":[[5.9,6.02]],"id":28866557}],"con":true,"img":false}]}
{"op":"mcm","clk":"5353935057","pt":1646219942963,"mc":[{"id":"1.195453781","rc":[{"atb":[[2.82,70.23],[2.8,0]],"id":41653210},{"atb":[[5.7,1.66]],"id":28866557}],"con":true,"img":false}]}
{"op":"mcm","clk":"5353935102","pt":1646219943383,"mc":[{"id":"1.195453781","rc":[{"atl":[[1.89,5],[1.85,2.5],[1.9,160.4],[1.86,0],[1.94,0],[1.93,10]],"id":40917608}],"con":true,"img":false}]}
{"op":"mcm","clk":"5353935124","pt":1646219943545,"mc":[{"id":"1.195453781","rc":[{"atl":[[1.89,132.47],[1.9,0]],"id":40917608}],"con":true,"img":false}]}
{"op":"mcm","clk":"5353935169","pt":1646219944067,"mc":[{"id":"1.195453781","rc":[{"atb":[[1.88,8.52]],"id":41120152}],"con":true,"img":false}]}
{"op":"mcm","clk":"5353935178","pt":1646219944171,"mc":[{"id":"1.195453781","rc":[{"atb":[[2.86,0]],"id":41653210},{"atb":[[1.01,0]],"id":40917608},{"atb":[[1.78,0]],"id":38247349},{"atb":[[3,4.16]],"id":38904370}],"con":true,"img":false}]}
{"op":"mcm","clk":"5353935189","pt":1646219944276,"mc":[{"id":"1.195453781","rc":[{"atb":[[1.8,0],[1.88,80.9]],"id":41120152},{"atb":[[1.83,0]],"id":42472248},{"atb":[[1.61,0],[1.52,66.94]],"id":38247349},{"atb":[[2.8,0],[2.5,40.72]],"id":28671742},{"atb":[[2.96,0]],"id":38904370}],"con":true,"img":false}]}
{"op":"mcm","clk":"5353935197","pt":1646219944380,"mc":[{"id":"1.195453781","rc":[{"atb":[[1.85,53.08]],"id":41120152},{"atb":[[1.88,49.24]],"id":42472248},{"atb":[[2.72,23.44]],"id":38904370}],"con":true,"img":false}]}
{"op":"mcm","clk":"5353935210","pt":1646219944437,"mc":[{"id":"1.195453781","rc":[{"atb":[[1.84,9.91]],"id":41120152},{"atb":[[2.26,124.62]],"id":38904370}],"con":true,"img":false}]}
{"op":"mcm","clk":"5353935225","pt":1646219944544,"mc":[{"id":"1.195453781","rc":[{"atb":[[1.88,115.58]],"id":42472248},{"atb":[[2.26,53.1]],"id":38904370}],"con":true,"img":false}]}
{"op":"mcm","clk":"5353935247","pt":1646219944749,"mc":[{"id":"1.195453781","rc":[{"atb":[[1.87,8.62]],"id":42472248}],"con":true,"img":false}]}
{"op":"mcm","clk":"5353935333","pt":1646219945853,"mc":[{"id":"1.195453781","rc":[{"atb":[[1.81,2.5],[1.84,171.94]],"id":42472248}],"con":true,"img":false}]}
{"op":"mcm","clk":"5353935351","pt":1646219946059,"mc":[{"id":"1.195453781","rc":[{"atb":[[5.8,0]],"id":28866557}],"con":true,"img":false}]}
{"op":"mcm","clk":"5353935370","pt":1646219946274,"mc":[{"id":"1.195453781","rc":[{"atb":[[5.9,0]],"id":28866557},{"atb":[[1.84,166.84],[1.77,40.85]],"id":41120152}],"con":true,"img":false}]}
{"op":"mcm","clk":"5353935385","pt":1646219946481,"mc":[{"id":"1.195453781","rc":[{"atb":[[2.3,61.91],[2.1,109.99],[2.2,100.82]],"id":41653210},{"atl":[[5.6,0.11],[7.2,0.08],[9.2,25.09]],"id":41653210},{"atb":[[3.75,43.99],[5.6,6.49],[4,40.33],[4.5,27.28]],"id":28866557},{"atl":[[16,0.03],[34,0.13],[22,3.59]],"id":28866557},{"atb":[[1.45,268.87],[1.55,109.99],[1.5,341.98]],"id":41120152},{"atl":[[2.82,0.29],[3.55,1.71],[3.05,0.26]],"id":41120152},{"atb":[[1.01,12099.41],[1.02,6299.7],[1.07,864.24]],"id":40917608},{"atl":[[2.28,0.42],[2.08,0.5],[2.48,2.94]],"id":40917608},{"atb":[[1.6,100.82],[1.55,219.99],[1.5,391.98]],"id":42472248},{"atl":[[3.2,52.45],[2.88,0.28],[3.7,1.61]],"id":42472248},{"atb":[[1.6,201.65],[1.55,219.99],[1.65,93.07]],"id":38247349},{"atl":[[3.45,30.83],[3.95,1.47],[2.98,0.27]],"id":38247349},{"atb":[[2.98,55.8],[2.88,64.36],[2.78,67.97]],"id":28671742},{"atl":[[10.5,0.05],[8.2,0.07],[15.5,0.29]],"id":28671742},{"atb":[[2.84,65.75],[2.94,31.18],[2.74,69.53]],"id":38904370},{"atl":[[8,0.07],[10,0.05],[15,16.47]],"id":38904370}],"con":true,"img":false}]}
{"op":"mcm","clk":"5353935425","pt":1646219946862,"mc":[{"id":"1.195453781","rc":[{"spn":10.85,"spf":"NaN","id":28866557},{"spn":1.49,"spf":"NaN","id":40917608},{"spn":2.16,"spf":"NaN","id":41120152},{"spn":2.38,"spf":"NaN","id":42472248},{"atl":[[3.45,121.41],[3.35,21.28]],"id":38247349},{"spn":4.4,"spf":"NaN","id":38904370}],"con":true,"img":false}]}
{"op":"mcm","clk":"5353935438","pt":1646219946963,"mc":[{"id":"1.195453781","rc":[{"atb":[[1.88,72.38]],"id":41120152},{"atb":[[1.87,0]],"id":42472248}],"con":true,"img":false}]}
{"op":"mcm","clk":"5353935464","pt":1646219947183,"mc":[{"id":"1.195453781","rc":[{"atb":[[1.88,0]],"id":41120152}],"con":true,"img":false}]}
{"op":"mcm","clk":"5353935476","pt":1646219947229,"mc":[{"id":"1.195453781","rc":[{"atb":[[1.85,136.5]],"id":41120152}],"con":true,"img":false}]}
{"op":"mcm","clk":"5353935489","pt":1646219947340,"mc":[{"id":"1.195453781","rc":[{"atb":[[1.84,9.91],[1.77,197.78]],"id":41120152}],"con":true,"img":false}]}
{"op":"mcm","clk":"5353935548","pt":1646219948074,"mc":[{"id":"1.195453781","rc":[{"atb":[[1.77,156.93]],"id":41120152},{"atb":[[1.84,134.49]],"id":42472248}],"con":true,"img":false}]}
{"op":"mcm","clk":"5353935667","pt":1646219949277,"mc":[{"id":"1.195453781","rc":[{"atl":[[3.2,36.6],[3.35,2.5],[3.55,94.35]],"id":42472248},{"atb":[[1.39,111.5],[1.52,0]],"id":38247349}],"con":true,"img":false}]}
{"op":"mcm","clk":"5353935677","pt":1646219949378,"mc":[{"id":"1.195453781","rc":[{"atb":[[5.3,16.48],[5.5,8.72]],"id":28866557},{"atl":[[3.3,15.85]],"id":42472248}],"con":true,"img":false}]}
{"op":"mcm","clk":"5353935716","pt":1646219949743,"mc":[{"id":"1.195453781","rc":[{"atb":[[2.88,15.71]],"id":41653210},{"atb":[[1.95,14.65]],"id":38247349}],"con":true,"img":false}]}
{"op":"mcm","clk":"5353935740","pt":1646219950054,"mc":[{"id":"1.195453781","rc":[{"atb":[[2.82,23.76],[2.78,52.32]],"id":41653210}],"con":true,"img":false}]}
{"op":"mcm","clk":"5353935767","pt":1646219950367,"mc":[{"id":"1.195453781","rc":[{"atb":[[5.7,7.78]],"id":28866557}],"con":true,"img":false}]}
{"op":"mcm","clk":"5353935775","pt":1646219950476,"mc":[{"id":"1.195453781","rc":[{"atb":[[1.91,76.83]],"id":38247349}],"con":true,"img":false}]}
{"op":"mcm","clk":"5353935783","pt":1646219950576,"mc":[{"id":"1.195453781","rc":[{"atb":[[5.8,3.33],[5.3,2.5],[5.6,0],[5.5,28.49]],"id":28866557}],"con":true,"img":false}]}
{"op":"mcm","clk":"5353935959","pt":1646219952681,"mc":[{"id":"1.195453781","rc":[{"atb":[[2.88,11.72]],"id":41653210},{"atb":[[1.92,8.16]],"id":42472248},{"atb":[[3,7.91]],"id":38904370}],"con":true,"img":false}]}
{"op":"mcm","clk":"5353935977","pt":1646219952889,"mc":[{"id":"1.195453781","rc":[{"atb":[[1.92,47.5]],"id":42472248}],"con":true,"img":false}]}
{"op":"mcm","clk":"5353935987","pt":1646219952992,"mc":[{"id":"1.195453781","rc":[{"atb":[[5.9,7.48]],"id":28866557},{"atb":[[1.78,40.33]],"id":41120152},{"atb":[[1.82,38.37]],"id":42472248}],"con":true,"img":false}]}
{"op":"mcm","clk":"5353935996","pt":1646219953049,"mc":[{"id":"1.195453781","rc":[{"atb":[[5.7,1.66]],"id":28866557},{"atb":[[1.88,49.24]],"id":42472248}],"con":true,"img":false}]}
{"op":"mcm","clk":"5353936090","pt":1646219954246,"mc":[{"id":"1.195453781","rc":[{"atb":[[2.82,0]],"id":41653210}],"con":true,"img":false}]}
{"op":"mcm","clk":"5353936098","pt":1646219954349,"mc":[{"id":"1.195453781","rc":[{"atb":[[2.8,23.76]],"id":41653210}],"con":true,"img":false}]}
{"op":"mcm","clk":"5353936156","pt":1646219955078,"mc":[{"id":"1.195453781","rc":[{"atb":[[1.78,178.15],[1.77,0]],"id":41120152}],"con":true,"img":false}]}
{"op":"mcm","clk":"5353936167","pt":1646219955180,"mc":[{"id":"1.195453781","rc":[{"atb":[[1.92,34.19]],"id":38247349}],"con":true,"img":false}]}
{"op":"mcm","clk":"5353936225","pt":1646219955866,"mc":[{"id":"1.195453781","rc":[{"atb":[[1.89,8.43]],"id":41120152},{"atb":[[1.92,39.34]],"id":42472248}],"con":true,"img":false}]}
{"op":"mcm","clk":"5353936238","pt":1646219956072,"mc":[{"id":"1.195453781","rc":[{"atb":[[1.89,57.36]],"id":41120152},{"atb":[[1.92,0]],"id":42472248}],"con":true,"img":false}]}
{"op":"mcm","clk":"5353936243","pt":1646219956175,"mc":[{"id":"1.195453781","rc":[{"atb":[[1.85,53.08]],"id":41120152},{"atb":[[1.84,0],[1.82,151.27],[1.88,88.58]],"id":42472248}],"con":true,"img":false}]}
{"op":"mcm","clk":"5353936304","pt":1646219956956,"mc":[{"id":"1.195453781","rc":[{"atb":[[1.84,0]],"id":41120152}],"con":true,"img":false}]}
{"op":"mcm","clk":"5353936321","pt":1646219957167,"mc":[{"id":"1.195453781","rc":[{"atl":[[3.35,81.62],[3.55,5]],"id":42472248}],"con":true,"img":false}]}
{"op":"mcm","clk":"5353936328","pt":1646219957275,"mc":[{"id":"1.195453781","rc":[{"atb":[[5.8,0]],"id":28866557},{"atb":[[1.82,112.9]],"id":42472248}],"con":true,"img":false}]}
{"op":"mcm","clk":"5353936338","pt":1646219957378,"mc":[{"id":"1.195453781","rc":[{"atb":[[1.92,110.45],[1.91,0]],"id":38247349}],"con":true,"img":false}]}
{"op":"mcm","clk":"5353936348","pt":1646219957482,"mc":[{"id":"1.195453781","rc":[{"atb":[[5.3,16.48],[5.9,0],[5.5,8.72]],"id":28866557}],"con":true,"img":false}]}
{"op":"mcm","clk":"5353936355","pt":1646219957584,"mc":[{"id":"1.195453781","rc":[{"atb":[[5.6,6.24]],"id":28866557}],"con":true,"img":false}]}
{"op":"mcm","clk":"5353936385","pt":1646219957846,"mc":[{"id":"1.195453781","rc":[{"atb":[[5.7,7.59]],"id":28866557}],"con":true,"img":false}]}
{"op":"mcm","clk":"5353936396","pt":1646219957953,"mc":[{"id":"1.195453781","rc":[{"atb":[[5.3,2.5],[5.5,28.12]],"id":28866557}],"con":true,"img":false}]}
{"op":"mcm","clk":"5353936402","pt":1646219958109,"mc":[{"id":"1.195453781","rc":[{"atb":[[5.6,0]],"id":28866557}],"con":true,"img":false}]}
{"op":"mcm","clk":"5353936475","pt":1646219958794,"mc":[{"id":"1.195453781","rc":[{"atb":[[2.84,4.07]],"id":41653210},{"atb":[[1.89,48.93]],"id":41120152},{"atb":[[1.95,6.75]],"id":38247349}],"con":true,"img":false}]}
{"op":"mcm","clk":"5353936493","pt":1646219958949,"mc":[{"id":"1.195453781","rc":[{"atb":[[2.8,70.23],[2.78,2.5]],"id":41653210},{"atb":[[1.89,0]],"id":41120152}],"con":true,"img":false}]}
{"op":"mcm","clk":"5353936501","pt":1646219959054,"mc":[{"id":"1.195453781","rc":[{"atb":[[1.85,131.54]],"id":41120152}],"con":true,"img":false}]}
{"op":"mcm","clk":"5353936508","pt":1646219959160,"mc":[{"id":"1.195453781","rc":[{"atb":[[1.85,78.46]],"id":41120152},{"atl":[[3.5,0]],"id":38247349}],"con":true,"img":false}]}
{"op":"mcm","clk":"5353936520","pt":1646219959264,"mc":[{"id":"1.195453781","rc":[{"atb":[[1.85,0],[1.79,53.08]],"id":41120152},{"atl":[[3.4,18.55]],"id":38247349}],"con":true,"img":false}]}
{"op":"mcm","clk":"5353936527","pt":1646219959374,"mc":[{"id":"1.195453781","rc":[{"atb":[[1.78,275.65]],"id":41120152},{"atl":[[3.45,30.83],[3.4,78.29]],"id":38247349}],"con":true,"img":false}]}
{"op":"mcm","clk":"5353936540","pt":1646219959579,"mc":[{"id":"1.195453781","rc":[{"atb":[[1.78,235.32]],"id":41120152}],"con":true,"img":false}]}
{"op":"mcm","clk":"5353936738","pt":1646219961781,"mc":[{"id":"1.195453781","rc":[{"atb":[[2.84,0]],"id":41653210}],"con":true,"img":false}]}
{"op":"mcm","clk":"5353936761","pt":1646219962092,"mc":[{"id":"1.195453781","rc":[{"atb":[[1.78,97.5],[1.75,159.43]],"id":41120152}],"con":true,"img":false}]}
{"op":"mcm","clk":"5353936768","pt":1646219962198,"mc":[{"id":"1.195453781","rc":[{"atb":[[5.8,6.55]],"id":28866557},{"atb":[[1.83,37.9]],"id":42472248}],"con":true,"img":false}]}
{"op":"mcm","clk":"5353936778","pt":1646219962299,"mc":[{"id":"1.195453781","rc":[{"atb":[[1.79,154.35]],"id":41120152}],"con":true,"img":false}]}
{"op":"mcm","clk":"5353936790","pt":1646219962407,"mc":[{"id":"1.195453781","rc":[{"atb":[[5.9,9.9]],"id":28866557}],"con":true,"img":false}]}
{"op":"mcm","clk":"5353936799","pt":1646219962456,"mc":[{"id":"1.195453781","rc":[{"atb":[[1.78,0]],"id":41120152}],"con":true,"img":false}]}
{"op":"mcm","clk":"5353936808","pt":1646219962614,"mc":[{"id":"1.195453781","rc":[{"atb":[[5.7,1.66]],"id":28866557}],"con":true,"img":false}]}
{"op":"mcm","clk":"5353936964","pt":1646219964301,"mc":[{"id":"1.195453781","rc":[{"atl":[[18,3.92]],"id":28866557},{"atb":[[1.76,41.39]],"id":41120152},{"atl":[[3.3,0]],"id":42472248},{"atb":[[1.74,0]],"id":38247349}],"con":true,"img":false}]}
{"op":"mcm","clk":"5353936976","pt":1646219964404,"mc":[{"id":"1.195453781","rc":[{"atl":[[16.5,2.72]],"id":28866557},{"atl":[[3.15,15.85]],"id":42472248},{"atb":[[1.93,45.92]],"id":38247349}],"con":true,"img":false}]}
{"op":"mcm","clk":"5353936988","pt":1646219964507,"mc":[{"id":"1.195453781","rc":[{"atl":[[3.35,2.5],[3.55,97.42]],"id":42472248}],"con":true,"img":false}]}
{"op":"mcm","clk":"5353936998","pt":1646219964610,"mc":[{"id":"1.195453781","rc":[{"atl":[[16.5,5.24]],"id":28866557},{"atl":[[3.15,53.06],[3.55,5]],"id":42472248}],"con":true,"img":false}]}
{"op":"mcm","clk":"5353937010","pt":1646219964664,"mc":[{"id":"1.195453781","rc":[{"atl":[[18,0]],"id":28866557}],"con":true,"img":false}]}
{"op":"mcm","clk":"5353937018","pt":1646219964769,"mc":[{"id":"1.195453781","rc":[{"atl":[[3.2,0.24]],"id":42472248}],"con":true,"img":false}]}
{"op":"mcm","clk":"5353937030","pt":1646219964873,"mc":[{"id":"1.195453781","rc":[{"atb":[[1.92,8.16]],"id":42472248}],"con":true,"img":false}]}
{"op":"mcm","clk":"5353937039","pt":1646219964978,"mc":[{"id":"1.195453781","rc":[{"atb":[[1.83,107],[1.82,0],[1.92,42.71]],"id":42472248}],"con":true,"img":false}]}
{"op":"mcm","clk":"5353937050","pt":1646219965082,"mc":[{"id":"1.195453781","rc":[{"atb":[[1.88,49.24]],"id":42472248}],"con":true,"img":false}]}
{"op":"mcm","clk":"5353937127","pt":1646219965866,"mc":[{"id":"1.195453781","rc":[{"atb":[[2.8,23.76],[2.78,48.97]],"id":41653210}],"con":true,"img":false}]}
{"op":"mcm","clk":"5353937174","pt":1646219966493,"mc":[{"id":"1.195453781","rc":[{"atb":[[5.8,0]],"id":28866557}],"con":true,"img":false}]}
{"op":"mcm","clk":"5353937189","pt":1646219966697,"mc":[{"id":"1.195453781","rc":[{"atb":[[5.3,14.38],[5.9,0],[5.5,8.72]],"id":28866557}],"con":true,"img":false}]}
{"op":"mcm","clk":"5353937194","pt":1646219966805,"mc":[{"id":"1.195453781","rc":[{"atb":[[5.6,5.19]],"id":28866557}],"con":true,"img":false}]}
{"op":"mcm","clk":"5353937270","pt":1646219967597,"mc":[{"id":"1.195453781","rc":[{"atb":[[1.83,9.04]],"id":41120152}],"con":true,"img":false}]}
{"op":"mcm","clk":"5353937287","pt":1646219967805,"mc":[{"id":"1.195453781","rc":[{"atb":[[1.76,180.8],[1.75,2.5]],"id":41120152}],"con":true,"img":false}]}
{"op":"mcm","clk":"5353937298","pt":1646219967916,"mc":[{"id":"1.195453781","rc":[{"atb":[[5.7,6.8]],"id":28866557}],"con":true,"img":false}]}
{"op":"mcm","clk":"5353937310","pt":1646219968120,"mc":[{"id":"1.195453781","rc":[{"atb":[[5.6,0]],"id":28866557}],"con":true,"img":false}]}
{"op":"mcm","clk":"5353937361","pt":1646219968595,"mc":[{"id":"1.195453781","rc":[{"atb":[[1.83,69.1]],"id":42472248},{"atb":[[1.92,76.26]],"id":38247349}],"con":true,"img":false}]}
{"op":"mcm","clk":"5353937416","pt":1646219969221,"mc":[{"id":"1.195453781","rc":[{"atl":[[2.52,0]],"id":41120152}],"con":true,"img":false}]}
{"op":"mcm","clk":"5353937427","pt":1646219969329,"mc":[{"id":"1.195453781","rc":[{"atl":[[2.46,45.29]],"id":41120152}],"con":true,"img":false}]}
{"op":"mcm","clk":"5353937571","pt":1646219970901,"mc":[{"id":"1.195453781","rc":[{"atb":[[1.83,100.43]],"id":41120152},{"atb":[[1.97,7.74]],"id":38247349}],"con":true,"img":false}]}
{"op":"mcm","clk":"5353937581","pt":1646219971007,"mc":[{"id":"1.195453781","rc":[{"atb":[[5.8,6.55]],"id":28866557},{"atb":[[1.76,139.41],[1.79,53.08]],"id":41120152}],"con":true,"img":false}]}
{"op":"mcm","clk":"5353937591","pt":1646219971115,"mc":[{"id":"1.195453781","rc":[{"atb":[[1.97,18.61]],"id":38247349}],"con":true,"img":false}]}
{"op":"mcm","clk":"5353937600","pt":1646219971222,"mc":[{"id":"1.195453781","rc":[{"atb":[[1.95,0]],"id":38247349}],"con":true,"img":false}]}
{"op":"mcm","clk":"5353937662","pt":1646219972004,"mc":[{"id":"1.195453781","rc":[{"atl":[[3.55,98.93]],"id":42472248}],"con":true,"img":false}]}
{"op":"mcm","clk":"5353937682","pt":1646219972207,"mc":[{"id":"1.195453781","rc":[{"atb":[[1.93,122.18],[1.92,0]],"id":38247349}],"con":true,"img":false}]}
{"op":"mcm","clk":"5353937692","pt":1646219972318,"mc":[{"id":"1.195453781","rc":[{"atb":[[5.3,2.5],[5.9,8.85],[5.5,26.48]],"id":28866557}],"con":true,"img":false}]}
{"op":"mcm","clk":"5353937715","pt":1646219972526,"mc":[{"id":"1.195453781","rc":[{"atb":[[5.7,1.66]],"id":28866557}],"con":true,"img":false}]}
{"op":"mcm","clk":"5353937774","pt":1646219973208,"mc":[{"id":"1.195453781","rc":[{"atb":[[1.84,37.45]],"id":42472248},{"atb":[[1.98,15.48]],"id":38247349}],"con":true,"img":false}]}
{"op":"mcm","clk":"5353937790","pt":1646219973417,"mc":[{"id":"1.195453781","rc":[{"atb":[[1.83,0],[1.84,175.39]],"id":42472248}],"con":true,"img":false}]}
{"op":"mcm","clk":"5353937818","pt":1646219973732,"mc":[{"id":"1.195453781","rc":[{"atb":[[2.84,4.07]],"id":41653210},{"atb":[[1.83,91.39]],"id":41120152}],"con":true,"img":false}]}
{"op":"mcm","clk":"5353937836","pt":1646219973890,"mc":[{"id":"1.195453781","rc":[{"atb":[[2.8,70.23],[2.78,2.5]],"id":41653210},{"atb":[[1.83,0]],"id":41120152}],"con":true,"img":false}]}
{"op":"mcm","clk":"5353937846","pt":1646219973993,"mc":[{"id":"1.195453781","rc":[{"atb":[[2.84,8.59]],"id":41653210}],"con":true,"img":false}]}
{"op":"mcm","clk":"5353937858","pt":1646219974104,"mc":[{"id":"1.195453781","rc":[{"atb":[[1.76,78.46],[1.75,159.43]],"id":41120152}],"con":true,"img":false}]}
{"op":"mcm","clk":"5353937871","pt":1646219974207,"mc":[{"id":"1.195453781","rc":[{"atb":[[1.79,0]],"id":41120152},{"atb":[[1.96,8.67]],"id":42472248},{"atb":[[2.72,0]],"id":38904370}],"con":true,"img":false}]}
{"op":"mcm","clk":"5353937881","pt":1646219974314,"mc":[{"id":"1.195453781","rc":[{"atb":[[1.77,53.08]],"id":41120152},{"atb":[[2.96,23.44]],"id":38904370}],"con":true,"img":false}]}
{"op":"mcm","clk":"5353937893","pt":1646219974415,"mc":[{"id":"1.195453781","rc":[{"atb":[[1.96,47.21]],"id":42472248}],"con":true,"img":false}]}
{"op":"mcm","clk":"5353937917","pt":1646219974622,"mc":[{"id":"1.195453781","rc":[{"atb":[[1.92,8.16]],"id":42472248}],"con":true,"img":false}]}
{"op":"mcm","clk":"5353937953","pt":1646219975088,"mc":[{"id":"1.195453781","rc":[{"atb":[[5.8,0]],"id":28866557},{"atb":[[1.77,93.94]],"id":41120152}],"con":true,"img":false}]}
{"op":"mcm","clk":"5353937963","pt":1646219975194,"mc":[{"id":"1.195453781","rc":[{"atb":[[5.3,14.38]],"id":28866557}],"con":true,"img":false}]}
{"op":"mcm","clk":"5353937972","pt":1646219975301,"mc":[{"id":"1.195453781","rc":[{"atb":[[5.9,0],[5.5,8.72]],"id":28866557}],"con":true,"img":false}]}
{"op":"mcm","clk":"5353937980","pt":1646219975403,"mc":[{"id":"1.195453781","rc":[{"atb":[[5.6,5.19]],"id":28866557}],"con":true,"img":false}]}
{"op":"mcm","clk":"5353938111","pt":1646219976919,"mc":[{"id":"1.195453781","rc":[{"atb":[[2.84,4.52]],"id":41653210},{"atb":[[1.92,0]],"id":42472248}],"con":true,"img":false}]}
{"op":"mcm","clk":"5353938118","pt":1646219977023,"mc":[{"id":"1.195453781","rc":[{"atb":[[1.77,197.84]],"id":41120152},{"atb":[[1.84,137.94]],"id":42472248}],"con":true,"img":false}]}
{"op":"mcm","clk":"5353938132","pt":1646219977130,"mc":[{"id":"1.195453781","rc":[{"atb":[[5.7,6.8]],"id":28866557}],"con":true,"img":false}]}
{"op":"mcm","clk":"5353938141","pt":1646219977229,"mc":[{"id":"1.195453781","rc":[{"atb":[[1.76,0]],"id":41120152}],"con":true,"img":false}]}
{"op":"mcm","clk":"5353938153","pt":1646219977335,"mc":[{"id":"1.195453781","rc":[{"atb":[[5.6,0]],"id":28866557}],"con":true,"img":false}]}
{"op":"mcm","clk":"5353938161","pt":1646219977439,"mc":[{"id":"1.195453781","rc":[{"atb":[[1.71,202.25],[1.75,2.5]],"id":41120152}],"con":true,"img":false}]}
{"op":"mcm","clk":"5353938181","pt":1646219977600,"mc":[{"id":"1.195453781","rc":[{"atb":[[2.8,72.73]],"id":41653210},{"atl":[[2.44,65.43]],"id":41120152},{"atl":[[3.2,20.19]],"id":38247349}],"con":true,"img":false}]}
{"op":"mcm","clk":"5353938188","pt":1646219977704,"mc":[{"id":"1.195453781","rc":[{"atb":[[2.62,0],[2.78,0],[2.7,0]],"id":41653210},{"atl":[[2.46,31.59]],"id":41120152},{"atl":[[3.25,8.89]],"id":38247349}],"con":true,"img":false}]}
{"op":"mcm","clk":"5353938211","pt":1646219977914,"mc":[{"id":"1.195453781","rc":[{"atl":[[3.35,72.42],[3.4,18.55]],"id":38247349}],"con":true,"img":false}]}
{"op":"mcm","clk":"5353938321","pt":1646219979218,"mc":[{"id":"1.195453781","rc":[{"atl":[[3.4,0]],"id":38247349},{"atb":[[2.8,28.92]],"id":28671742}],"con":true,"img":false}]}
{"op":"mcm","clk":"5353938330","pt":1646219979322,"mc":[{"id":"1.195453781","rc":[{"atl":[[3.35,90.97]],"id":38247349},{"atb":[[2.5,0]],"id":28671742}],"con":true,"img":false}]}
{"op":"mcm","clk":"5353938341","pt":1646219979424,"mc":[{"id":"1.195453781","rc":[{"atb":[[5.8,3.33]],"id":28866557},{"atb":[[1.77,156.98]],"id":41120152}],"con":true,"img":false}]}
{"op":"mcm","clk":"5353938429","pt":1646219980213,"mc":[{"id":"1.195453781","rc":[{"atb":[[1.54,0]],"id":42472248},{"atl":[[3.85,35.09],[3.95,0],[4.1,0]],"id":42472248},{"atb":[[2.14,0],[2.18,0],[2.2,0],[2.16,0]],"id":38904370}],"con":true,"img":false}]}
{"op":"mcm","clk":"5353938438","pt":1646219980317,"mc":[{"id":"1.195453781","rc":[{"atb":[[1.59,0],[1.6,0],[1.58,0],[1.57,0]],"id":41120152},{"atb":[[1.56,35.71]],"id":42472248},{"atl":[[4.2,6.25]],"id":42472248},{"atl":[[5.6,4.35],[5.8,29.91]],"id":38904370}],"con":true,"img":false}]}
{"op":"mcm","clk":"5353938449","pt":1646219980422,"mc":[{"id":"1.195453781","rc":[{"atb":[[1.54,37.04]],"id":42472248},{"atl":[[3.85,42.11]],"id":42472248},{"atb":[[1.09,222.22],[1.08,0]],"id":38247349},{"atb":[[2.14,2]],"id":38904370},{"atl":[[5.6,13.73]],"id":38904370}],"con":true,"img":false}]}
{"op":"mcm","clk":"5353938461","pt":1646219980525,"mc":[{"id":"1.195453781","rc":[{"atb":[[1.56,0]],"id":42472248},{"atl":[[5.6,9.38],[5.8,66.34],[5.9,0]],"id":38904370}],"con":true,"img":false}]}
{"op":"mcm","clk":"5353938469","pt":1646219980628,"mc":[{"id":"1.195453781","rc":[{"atb":[[2.16,4]],"id":38904370},{"atl":[[5.7,0]],"id":38904370}],"con":true,"img":false}]}
{"op":"mcm","clk":"5353938487","pt":1646219980836,"mc":[{"id":"1.195453781","rc":[{"atb":[[2.18,3]],"id":38904370},{"atl":[[5.6,0]],"id":38904370}],"con":true,"img":false}]}
{"op":"mcm","clk":"5353938506","pt":1646219981050,"mc":[{"id":"1.195453781","rc":[{"atl":[[4.1,9.38],[4.2,6.25]],"id":41653210},{"atl":[[19,0],[21,1]],"id":28866557},{"atb":[[1.5,281.98],[1.52,0]],"id":41120152},{"atl":[[2.72,0],[2.44,51.54],[2.6,62.5],[2.14,2],[2.34,14.93]],"id":41120152},{"atb":[[1.15,0],[1.11,0],[1.13,5],[1.17,104.08]],"id":40917608},{"atl":[[2.72,2]],"id":40917608},{"atl":[[3.35,0],[3.55,93.93],[3.3,2.5]],"id":42472248},{"atb":[[1.09,0],[1.08,250]],"id":38247349},{"atl":[[6.2,3.85],[5.9,7.17]],"id":28671742},{"atb":[[2.14,0],[2.18,0],[2.16,0]],"id":38904370},{"atl":[[5.6,4.35],[5.8,62.17],[6.8,24.05],[5.7,12.98]],"id":38904370}],"con":true,"img":false}]}
{"op":"mcm","clk":"5353938522","pt":1646219981203,"mc":[{"id":"1.195453781","rc":[{"atl":[[4.3,49.31],[4.4,11.78]],"id":41653210},{"atb":[[5.3,11.88],[4.9,0],[5.4,2.5],[4.5,17.28]],"id":28866557},{"atl":[[20,0]],"id":28866557},{"atl":[[2.44,151.24],[1.94,3],[2.14,29.06],[2.48,0]],"id":41120152},{"atl":[[3.65,3]],"id":42472248},{"atl":[[6.4,38.92],[6.8,20.44],[5.9,0]],"id":28671742},{"atl":[[5.6,17.33],[5.8,41.34]],"id":38904370}],"con":true,"img":false}]}
{"op":"mcm","clk":"5353938531","pt":1646219981318,"mc":[{"id":"1.195453781","rc":[{"atb":[[5.3,0],[5.5,21.65]],"id":28866557}],"con":true,"img":false}]}
{"op":"mcm","clk":"5353938539","pt":1646219981420,"mc":[{"id":"1.195453781","rc":[{"atb":[[5.9,6.44]],"id":28866557},{"atl":[[2.44,99.7],[1.95,3]],"id":41120152},{"atl":[[3.6,4]],"id":42472248},{"atb":[[1.94,0],[1.93,127.18],[1.97,21.11],[1.9,0],[1.86,0]],"id":38247349},{"atl":[[6.4,18.78]],"id":28671742}],"con":true,"img":false}]}
{"op":"mcm","clk":"5353938543","pt":1646219981518,"mc":[{"id":"1.195453781","rc":[{"atb":[[5.7,1.66]],"id":28866557}],"con":true,"img":false}]}
{"op":"mcm","clk":"5353938552","pt":1646219981628,"mc":[{"id":"1.195453781","rc":[{"atl":[[2.44,0]],"id":41120152}],"con":true,"img":false}]}
{"op":"mcm","clk":"5353938559","pt":1646219981738,"mc":[{"id":"1.195453781","rc":[{"atl":[[1.94,0],[1.95,0],[1.93,2]],"id":41120152},{"atb":[[1.85,37.01]],"id":42472248},{"atl":[[3.55,96.93]],"id":42472248},{"atb":[[3.6,29.76],[3.85,4.16],[3.8,6.34],[3.4,0],[3.65,21.02]],"id":28671742}],"con":true,"img":false}]}
{"op":"mcm","clk":"5353938575","pt":1646219981942,"mc":[{"id":"1.195453781","rc":[{"atb":[[1.84,0],[1.85,181.71]],"id":42472248},{"atb":[[3.6,0],[3.85,23],[3.65,58.7]],"id":28671742}],"con":true,"img":false}]}
{"op":"mcm","clk":"5353938591","pt":1646219982099,"mc":[{"id":"1.195453781","rc":[{"atb":[[3.8,0]],"id":28671742}],"con":true,"img":false}]}
{"op":"mcm","clk":"5353938602","pt":1646219982208,"mc":[{"id":"1.195453781","rc":[{"atl":[[1.92,2]],"id":41120152},{"atl":[[2.72,0]],"id":40917608}],"con":true,"img":false}]}
{"op":"mcm","clk":"5353938614","pt":1646219982315,"mc":[{"id":"1.195453781","rc":[{"atl":[[3.5,4]],"id":42472248}],"con":true,"img":false}]}
{"op":"mcm","clk":"5353938631","pt":1646219982519,"mc":[{"id":"1.195453781","rc":[{"atl":[[3.55,3],[3.5,101.41]],"id":42472248}],"con":true,"img":false}]}
{"op":"mcm","clk":"5353938657","pt":1646219982833,"mc":[{"id":"1.195453781","rc":[{"atb":[[2.86,4.03]],"id":41653210},{"atb":[[2,7.5]],"id":42472248}],"con":true,"img":false}]}
{"op":"mcm","clk":"5353938675","pt":1646219983051,"mc":[{"id":"1.195453781","rc":[{"atb":[[2.8,26.26],[2.84,27.96]],"id":41653210}],"con":true,"img":false}]}
{"op":"mcm","clk":"5353938731","pt":1646219983617,"mc":[{"id":"1.195453781","rc":[{"atb":[[5.8,0]],"id":28866557},{"atb":[[1.16,0]],"id":40917608},{"atb":[[1.98,0]],"id":38247349}],"con":true,"img":false}]}
{"op":"mcm","clk":"5353938746","pt":1646219983718,"mc":[{"id":"1.195453781","rc":[{"atb":[[5.9,0],[5.4,15.84]],"id":28866557}],"con":true,"img":false}]}
{"op":"mcm","clk":"5353938755","pt":1646219983835,"mc":[{"id":"1.195453781","rc":[{"atb":[[5.5,8.72]],"id":28866557},{"atb":[[1.93,50.92],[1.65,261.19]],"id":38247349}],"con":true,"img":false}]}
{"op":"mcm","clk":"5353938764","pt":1646219984004,"mc":[{"id":"1.195453781","rc":[{"atb":[[5.6,2]],"id":28866557}],"con":true,"img":false}]}
{"op":"mcm","clk":"5353938778","pt":1646219984262,"mc":[{"id":"1.195453781","rc":[{"atb":[[1.61,47.22]],"id":38247349}],"con":true,"img":false}]}
{"op":"mcm","clk":"5353938783","pt":1646219984346,"mc":[{"id":"1.195453781","rc":[{"atl":[[3.15,37.21]],"id":42472248},{"atb":[[1.93,5],[1.39,0]],"id":38247349}],"con":true,"img":false}]}
{"op":"mcm","clk":"5353938791","pt":1646219984517,"mc":[{"id":"1.195453781","rc":[{"atl":[[3.1,15.85]],"id":42472248},{"atb":[[1.75,45.92]],"id":38247349}],"con":true,"img":false}]}
{"op":"mcm","clk":"5353938802","pt":1646219984614,"mc":[{"id":"1.195453781","rc":[{"atl":[[3.1,53.95]],"id":42472248}],"con":true,"img":false}]}
{"op":"mcm","clk":"5353938811","pt":1646219984819,"mc":[{"id":"1.195453781","rc":[{"atl":[[3.15,0]],"id":42472248}],"con":true,"img":false}]}
{"op":"mcm","clk":"5353938880","pt":1646219985603,"mc":[{"id":"1.195453781","rc":[{"atb":[[1.85,144.7]],"id":42472248}],"con":true,"img":false}]}
{"op":"mcm","clk":"5353938890","pt":1646219985706,"mc":[{"id":"1.195453781","rc":[{"atb":[[2.86,0]],"id":41653210},{"atb":[[1.97,13.37]],"id":38247349}],"con":true,"img":false}]}
{"op":"mcm","clk":"5353938914","pt":1646219986027,"mc":[{"id":"1.195453781","rc":[{"atl":[[2.32,15.15],[1.93,0],[2.34,0],[1.92,0],[1.91,4]],"id":41120152}],"con":true,"img":false}]}
{"op":"mcm","clk":"5353938939","pt":1646219986437,"mc":[{"id":"1.195453781","rc":[{"atl":[[5.6,4.35],[5.8,62.17]],"id":38904370}],"con":true,"img":false}]}
{"op":"mcm","clk":"5353938956","pt":1646219986699,"mc":[{"id":"1.195453781","rc":[{"atb":[[1.75,96.68],[1.65,93.07]],"id":38247349}],"con":true,"img":false}]}
{"op":"mcm","clk":"5353938963","pt":1646219986802,"mc":[{"id":"1.195453781","rc":[{"atb":[[5.7,4.41]],"id":28866557}],"con":true,"img":false}]}
{"op":"mcm","clk":"5353938969","pt":1646219986908,"mc":[{"id":"1.195453781","rc":[{"atb":[[5.4,2.5],[5.6,0],[5.5,20.75]],"id":28866557}],"con":true,"img":false}]}
{"op":"mcm","clk":"5353938982","pt":1646219987117,"mc":[{"id":"1.195453781","rc":[{"atb":[[5.5,8.72]],"id":28866557}],"con":true,"img":false}]}
{"op":"mcm","clk":"5353939049","pt":1646219987852,"mc":[{"id":"1.195453781","rc":[{"atb":[[1.85,0],[1.88,193.94]],"id":42472248}],"con":true,"img":false}]}
{"op":"mcm","clk":"5353939057","pt":1646219987948,"mc":[{"id":"1.195453781","rc":[{"atb":[[5.8,3.33]],"id":28866557},{"atb":[[1.1,314.6]],"id":40917608},{"atb":[[1.76,41.39]],"id":38247349}],"con":true,"img":false}]}
{"op":"mcm","clk":"5353939125","pt":1646219988728,"mc":[{"id":"1.195453781","rc":[{"atb":[[3.35,88.05],[3.65,21.02]],"id":28671742}],"con":true,"img":false}]}
{"op":"mcm","clk":"5353939169","pt":1646219989249,"mc":[{"id":"1.195453781","rc":[{"atb":[[1.17,2.5]],"id":40917608},{"atl":[[2.46,0]],"id":41120152},{"atb":[[1.88,144.7]],"id":42472248}],"con":true,"img":false}]}
{"op":"mcm","clk":"5353939175","pt":1646219989349,"mc":[{"id":"1.195453781","rc":[{"atl":[[2.48,31.59]],"id":41120152},{"atb":[[1.1,416.19]],"id":40917608},{"atb":[[1.97,49.24]],"id":42472248}],"con":true,"img":false}]}
{"op":"mcm","clk":"5353939200","pt":1646219989668,"mc":[{"id":"1.195453781","rc":[{"atb":[[5.5,20.75]],"id":28866557}],"con":true,"img":false}]}
{"op":"mcm","clk":"5353939209","pt":1646219989719,"mc":[{"id":"1.195453781","rc":[{"atb":[[2.8,85.74],[2.84,4.52]],"id":41653210},{"atb":[[1.89,35.35]],"id":42472248}],"con":true,"img":false}]}
{"op":"mcm","clk":"5353939216","pt":1646219989821,"mc":[{"id":"1.195453781","rc":[{"atb":[[5.9,5.81]],"id":28866557}],"con":true,"img":false}]}
{"op":"mcm","clk":"5353939230","pt":1646219990032,"mc":[{"id":"1.195453781","rc":[{"atb":[[5.7,1.66]],"id":28866557}],"con":true,"img":false}]}
{"op":"mcm","clk":"5353939282","pt":1646219990713,"mc":[{"id":"1.195453781","rc":[{"atl":[[3.95,16.95]],"id":42472248}],"con":true,"img":false}]}
{"op":"mcm","clk":"5353939306","pt":1646219991127,"mc":[{"id":"1.195453781","rc":[{"atb":[[3.65,5]],"id":28671742}],"con":true,"img":false}]}
{"op":"mcm","clk":"5353939314","pt":1646219991231,"mc":[{"id":"1.195453781","rc":[{"atb":[[3.4,16.02]],"id":28671742}],"con":true,"img":false}]}
{"op":"mcm","clk":"5353939326","pt":1646219991338,"mc":[{"id":"1.195453781","rc":[{"atl":[[4.4,26.49]],"id":41653210},{"atl":[[23,2.27]],"id":28866557},{"atl":[[6.6,8.93]],"id":28671742},{"atl":[[5.8,72.59]],"id":38904370}],"con":true,"img":false}]}
{"op":"mcm","clk":"5353939380","pt":1646219992011,"mc":[{"id":"1.195453781","rc":[{"atb":[[2,0]],"id":42472248}],"con":true,"img":false}]}
{"op":"mcm","clk":"5353939392","pt":1646219992117,"mc":[{"id":"1.195453781","rc":[{"atb":[[1.97,111.17]],"id":42472248}],"con":true,"img":false}]}
{"op":"mcm","clk":"5353939404","pt":1646219992325,"mc":[{"id":"1.195453781","rc":[{"atb":[[1.96,8.67]],"id":42472248}],"con":true,"img":false}]}
{"op":"mcm","clk":"5353939513","pt":1646219993728,"mc":[{"id":"1.195453781","rc":[{"atb":[[5.8,0]],"id":28866557},{"atb":[[1.89,0]],"id":42472248}],"con":true,"img":false}]}
{"op":"mcm","clk":"5353939520","pt":1646219993833,"mc":[{"id":"1.195453781","rc":[{"atb":[[5.9,0],[5.4,15.84],[5.5,8.72]],"id":28866557}],"con":true,"img":false}]}
{"op":"mcm","clk":"5353939528","pt":1646219993937,"mc":[{"id":"1.195453781","rc":[{"atb":[[5.5,10.72]],"id":28866557}],"con":true,"img":false}]}
{"op":"mcm","clk":"5353939550","pt":1646219994256,"mc":[{"id":"1.195453781","rc":[{"atb":[[1.77,103.9]],"id":41120152},{"atl":[[3.35,72.42]],"id":38247349}],"con":true,"img":false}]}
{"op":"mcm","clk":"5353939559","pt":1646219994357,"mc":[{"id":"1.195453781","rc":[{"atb":[[1.78,53.08]],"id":41120152},{"atl":[[3.3,18.55]],"id":38247349}],"con":true,"img":false}]}
{"op":"mcm","clk":"5353939567","pt":1646219994462,"mc":[{"id":"1.195453781","rc":[{"atb":[[1.77,0]],"id":41120152}],"con":true,"img":false}]}
{"op":"mcm","clk":"5353939579","pt":1646219994567,"mc":[{"id":"1.195453781","rc":[{"atb":[[1.78,86.24],[1.75,68.82],[1.71,5]],"id":41120152},{"atl":[[3.35,21.28],[3.3,66.43]],"id":38247349}],"con":true,"img":false}]}
{"op":"mcm","clk":"5353939597","pt":1646219994725,"mc":[{"id":"1.195453781","rc":[{"atl":[[4.3,34.16],[4.5,0],[4.7,0]],"id":41653210},{"atb":[[1.8,9.38]],"id":38247349},{"atl":[[7.2,0],[6.4,9.52],[6.8,7.51]],"id":28671742},{"atl":[[5.5,9.38],[6.8,2.5]],"id":38904370}],"con":true,"img":false}]}
{"op":"mcm","clk":"5353939603","pt":1646219994831,"mc":[{"id":"1.195453781","rc":[{"atl":[[5.8,40.33],[5.7,25.95]],"id":38904370}],"con":true,"img":false}]}
{"op":"mcm","clk":"5353939615","pt":1646219994936,"mc":[{"id":"1.195453781","rc":[{"atl":[[5.6,26.09],[5.8,19.5]],"id":38904370}],"con":true,"img":false}]}
{"op":"mcm","clk":"5353939663","pt":1646219995563,"mc":[{"id":"1.195453781","rc":[{"atl":[[2.32,81.46]],"id":41120152},{"atl":[[6.6,36.6]],"id":28671742}],"con":true,"img":false}]}
{"op":"mcm","clk":"5353939680","pt":1646219995722,"mc":[{"id":"1.195453781","rc":[{"atb":[[5.6,5.19]],"id":28866557},{"atl":[[6.2,19.23]],"id":28671742}],"con":true,"img":false}]}
{"op":"mcm","clk":"5353939691","pt":1646219995933,"mc":[{"id":"1.195453781","rc":[{"atb":[[5.5,8.72]],"id":28866557},{"atl":[[6.4,0]],"id":28671742}],"con":true,"img":false}]}
{"op":"mcm","clk":"5353939713","pt":1646219996248,"mc":[{"id":"1.195453781","rc":[{"atb":[[1.48,468.75]],"id":41120152},{"atl":[[2.36,36.76],[2.06,2],[1.91,0]],"id":41120152},{"atb":[[3.35,22.95],[3.4,68.91]],"id":28671742}],"con":true,"img":false}]}
{"op":"mcm","clk":"5353939726","pt":1646219996349,"mc":[{"id":"1.195453781","rc":[{"atb":[[1.48,312.5]],"id":41120152},{"atl":[[2.06,15.33]],"id":41120152}],"con":true,"img":false}]}
{"op":"mcm","clk":"5353939733","pt":1646219996454,"mc":[{"id":"1.195453781","rc":[{"atl":[[2.54,0],[2.5,0],[2.58,0],[2.14,0],[2.02,2],[2.06,13.33]],"id":41120152}],"con":true,"img":false}]}
{"op":"mcm","clk":"5353939743","pt":1646219996661,"mc":[{"id":"1.195453781","rc":[{"atl":[[2.02,0],[1.98,4]],"id":41120152},{"atb":[[1.97,49.24]],"id":42472248}],"con":true,"img":false}]}
{"op":"mcm","clk":"5353939843","pt":1646219997749,"mc":[{"id":"1.195453781","rc":[{"atb":[[2.86,4.03]],"id":41653210},{"atb":[[2.02,7.35]],"id":42472248}],"con":true,"img":false}]}
{"op":"mcm","clk":"5353939854","pt":1646219997962,"mc":[{"id":"1.195453781","rc":[{"atb":[[2.8,26.26],[2.84,27.96]],"id":41653210},{"atb":[[1.88,0]],"id":42472248}],"con":true,"img":false}]}
{"op":"mcm","clk":"5353939867","pt":1646219998166,"mc":[{"id":"1.195453781","rc":[{"atb":[[5.8,3.33]],"id":28866557},{"atb":[[1.89,35.35]],"id":42472248},{"atb":[[1.76,0],[1.8,43.5],[1.75,45.92]],"id":38247349}],"con":true,"img":false}]}
{"op":"mcm","clk":"5353939874","pt":1646219998270,"mc":[{"id":"1.195453781","rc":[{"atb":[[5.7,6.8]],"id":28866557}],"con":true,"img":false}]}
{"op":"mcm","clk":"5353939884","pt":1646219998375,"mc":[{"id":"1.195453781","rc":[{"atb":[[5.4,2.5],[5.6,0],[5.5,22.06]],"id":28866557}],"con":true,"img":false}]}
{"op":"mcm","clk":"5353939943","pt":1646219999260,"mc":[{"id":"1.195453781","rc":[{"atl":[[2.48,0]],"id":41120152}],"con":true,"img":false}]}
{"op":"mcm","clk":"5353939950","pt":1646219999364,"mc":[{"id":"1.195453781","rc":[{"atl":[[2.52,31.59]],"id":41120152}],"con":true,"img":false}]}
{"op":"mcm","clk":"5353940011","pt":1646220000039,"mc":[{"id":"1.195453781","rc":[{"atl":[[5.6,4.35],[5.7,47.23]],"id":38904370}],"con":true,"img":false}]}
{"op":"mcm","clk":"5353940075","pt":1646220000873,"mc":[{"id":"1.195453781","rc":[{"atl":[[4.1,24.19]],"id":42472248}],"con":true,"img":false}]}
{"op":"mcm","clk":"5353940088","pt":1646220001032,"mc":[{"id":"1.195453781","rc":[{"atb":[[2.86,0]],"id":41653210},{"atb":[[5.9,6.44]],"id":28866557},{"atb":[[1.8,34.12]],"id":38247349}],"con":true,"img":false}]}
{"op":"mcm","clk":"5353940094","pt":1646220001134,"mc":[{"id":"1.195453781","rc":[{"atb":[[5.5,8.72],[5.7,20.14]],"id":28866557},{"atb":[[1.75,2.5],[1.71,128.22]],"id":41120152}],"con":true,"img":false}]}
{"op":"mcm","clk":"5353940099","pt":1646220001237,"mc":[{"id":"1.195453781","rc":[{"atb":[[5.7,15]],"id":28866557}],"con":true,"img":false}]}
{"op":"mcm","clk":"5353940124","pt":1646220001507,"mc":[{"id":"1.195453781","rc":[{"atl":[[6,15]],"id":38904370}],"con":true,"img":false}]}
{"op":"mcm","clk":"5353940128","pt":1646220001556,"mc":[{"id":"1.195453781","rc":[{"atl":[[4.6,20.83]],"id":41653210},{"atl":[[25,3.12]],"id":28866557},{"atl":[[7,12.5]],"id":28671742}],"con":true,"img":false}]}
{"op":"mcm","clk":"5353940145","pt":1646220001765,"mc":[{"id":"1.195453781","rc":[{"atl":[[22,0.02],[24,0]],"id":28866557},{"atl":[[1.97,3]],"id":41120152},{"atl":[[4.2,0]],"id":42472248}],"con":true,"img":false}]}
{"op":"mcm","clk":"5353940168","pt":1646220001982,"mc":[{"id":"1.195453781","rc":[{"atl":[[23,15.2]],"id":28866557},{"atl":[[2.32,15.15]],"id":41120152}],"con":true,"img":false}]}
{"op":"mcm","clk":"5353940176","pt":1646220002081,"mc":[{"id":"1.195453781","rc":[{"atb":[[1.89,0]],"id":42472248},{"atb":[[1.81,38.84]],"id":38247349}],"con":true,"img":false}]}
{"op":"mcm","clk":"5353940186","pt":1646220002185,"mc":[{"id":"1.195453781","rc":[{"atl":[[6.8,59.71],[6.6,8.93]],"id":28671742}],"con":true,"img":false}]}
{"op":"mcm","clk":"5353940192","pt":1646220002236,"mc":[{"id":"1.195453781","rc":[{"atb":[[1.8,0],[1.81,89.6]],"id":38247349}],"con":true,"img":false}]}
{"op":"mcm","clk":"5353940341","pt":1646220003963,"mc":[{"id":"1.195453781","rc":[{"atb":[[5.8,0]],"id":28866557}],"con":true,"img":false}]}
{"op":"mcm","clk":"5353940359","pt":1646220004171,"mc":[{"id":"1.195453781","rc":[{"atb":[[5.9,0]],"id":28866557}],"con":true,"img":false}]}
{"op":"mcm","clk":"5353940367","pt":1646220004272,"mc":[{"id":"1.195453781","rc":[{"atl":[[4.4,14.71]],"id":41653210},{"atb":[[5.8,8.77]],"id":28866557},{"atb":[[1.97,0]],"id":42472248},{"atl":[[3.1,38.1]],"id":42472248},{"atl":[[6.8,52.2]],"id":28671742}],"con":true,"img":false}]}
{"op":"mcm","clk":"5353940378","pt":1646220004377,"mc":[{"id":"1.195453781","rc":[{"atl":[[4.2,18.03]],"id":41653210},{"atb":[[1.65,49.24]],"id":42472248},{"atl":[[3.05,15.85]],"id":42472248},{"atl":[[6,7.51]],"id":28671742}],"con":true,"img":false}]}
{"op":"mcm","clk":"5353940385","pt":1646220004481,"mc":[{"id":"1.195453781","rc":[{"atb":[[1.81,26.56]],"id":42472248}],"con":true,"img":false}]}
{"op":"mcm","clk":"5353940394","pt":1646220004590,"mc":[{"id":"1.195453781","rc":[{"atb":[[2.8,92.7],[2.84,4.52]],"id":41653210},{"atl":[[3.3,26.56],[3.5,4],[3.05,27.88]],"id":42472248}],"con":true,"img":false}]}
{"op":"mcm","clk":"5353940405","pt":1646220004742,"mc":[{"id":"1.195453781","rc":[{"atl":[[3.1,0]],"id":42472248}],"con":true,"img":false}]}
{"op":"mcm","clk":"5353940417","pt":1646220004848,"mc":[{"id":"1.195453781","rc":[{"atb":[[5.5,34.96]],"id":28866557}],"con":true,"img":false}]}
{"op":"mcm","clk":"5353940428","pt":1646220004950,"mc":[{"id":"1.195453781","rc":[{"atb":[[5.7,1.66]],"id":28866557}],"con":true,"img":false}]}
{"op":"mcm","clk":"5353940500","pt":1646220005942,"mc":[{"id":"1.195453781","rc":[{"atb":[[1.98,22.07]],"id":42472248}],"con":true,"img":false}]}
{"op":"mcm","clk":"5353940522","pt":1646220006257,"mc":[{"id":"1.195453781","rc":[{"atb":[[1.81,2.5]],"id":42472248}],"con":true,"img":false}]}
{"op":"mcm","clk":"5353940532","pt":1646220006359,"mc":[{"id":"1.195453781","rc":[{"atb":[[1.46,163.04]],"id":41120152},{"atl":[[2.4,53.57]],"id":41120152}],"con":true,"img":false}]}
{"op":"mcm","clk":"5353940606","pt":1646220007040,"mc":[{"id":"1.195453781","rc":[{"spn":10.9,"spf":"NaN","id":28866557},{"spn":1.87,"spf":"NaN","id":41120152},{"atb":[[2.02,0]],"id":42472248},{"spn":2.43,"spf":"NaN","id":42472248},{"spn":2.47,"spf":"NaN","id":38247349},{"spn":4.92,"spf":"NaN","id":28671742},{"spn":4.3,"spf":"NaN","id":38904370}],"con":true,"img":false}]}
{"op":"mcm","clk":"5353940632","pt":1646220007355,"mc":[{"id":"1.195453781","rc":[{"atb":[[2.84,0]],"id":41653210},{"atb":[[1.96,0]],"id":42472248}],"con":true,"img":false}]}
{"op":"mcm","clk":"5353940645","pt":1646220007565,"mc":[{"id":"1.195453781","rc":[{"atb":[[5.7,0]],"id":28866557}],"con":true,"img":false}]}
{"op":"mcm","clk":"5353940654","pt":1646220007673,"mc":[{"id":"1.195453781","rc":[{"atb":[[5.5,8.72],[5.4,23.59]],"id":28866557}],"con":true,"img":false}]}
{"op":"mcm","clk":"5353940667","pt":1646220007773,"mc":[{"id":"1.195453781","rc":[{"atb":[[5.8,0],[5.9,1.66]],"id":28866557}],"con":true,"img":false}]}
{"op":"mcm","clk":"5353940687","pt":1646220007987,"mc":[{"id":"1.195453781","rc":[{"atb":[[5.5,19.2]],"id":28866557}],"con":true,"img":false}]}
{"op":"mcm","clk":"5353940789","pt":1646220009285,"mc":[{"id":"1.195453781","rc":[{"atl":[[2.52,0]],"id":41120152},{"atb":[[1.1,314.6]],"id":40917608},{"atb":[[1.75,0]],"id":38247349}],"con":true,"img":false}]}
{"op":"mcm","clk":"5353940801","pt":1646220009389,"mc":[{"id":"1.195453781","rc":[{"atb":[[1.11,101.58]],"id":40917608},{"atl":[[2.58,31.59]],"id":41120152},{"atb":[[1.82,45.92]],"id":38247349}],"con":true,"img":false}]}
{"op":"mcm","clk":"5353940815","pt":1646220009545,"mc":[{"id":"1.195453781","rc":[{"atl":[[6.6,51.17]],"id":28671742}],"con":true,"img":false}]}
{"op":"mcm","clk":"5353940818","pt":1646220009649,"mc":[{"id":"1.195453781","rc":[{"atl":[[6.8,0]],"id":28671742}],"con":true,"img":false}]}
{"op":"mcm","clk":"5353940824","pt":1646220009754,"mc":[{"id":"1.195453781","rc":[{"atb":[[5.6,5.19]],"id":28866557},{"atl":[[6,21.49]],"id":28671742}],"con":true,"img":false}]}
{"op":"mcm","clk":"5353940838","pt":1646220009860,"mc":[{"id":"1.195453781","rc":[{"atl":[[1.96,3]],"id":41120152}],"con":true,"img":false}]}
{"op":"mcm","clk":"5353940848","pt":1646220009966,"mc":[{"id":"1.195453781","rc":[{"atb":[[5.5,8.72]],"id":28866557},{"atl":[[6.2,3.85]],"id":28671742}],"con":true,"img":false}]}
{"op":"mcm","clk":"5353940866","pt":1646220010172,"mc":[{"id":"1.195453781","rc":[{"atb":[[5.6,10.19]],"id":28866557},{"atb":[[1.98,0]],"id":42472248}],"con":true,"img":false}]}
{"op":"mcm","clk":"5353940874","pt":1646220010276,"mc":[{"id":"1.195453781","rc":[{"atb":[[1.81,8.12]],"id":42472248}],"con":true,"img":false}]}
{"op":"mcm","clk":"5353940880","pt":1646220010381,"mc":[{"id":"1.195453781","rc":[{"atl":[[1.96,5]],"id":41120152}],"con":true,"img":false}]}
{"op":"mcm","clk":"5353940900","pt":1646220010588,"mc":[{"id":"1.195453781","rc":[{"atl":[[2.06,0]],"id":41120152}],"con":true,"img":false}]}
{"op":"mcm","clk":"5353940914","pt":1646220010747,"mc":[{"id":"1.195453781","rc":[{"atl":[[1.95,2]],"id":41120152}],"con":true,"img":false}]}
{"op":"mcm","clk":"5353940948","pt":1646220011061,"mc":[{"id":"1.195453781","rc":[{"atb":[[2.8,26.26],[2.3,140.19]],"id":41653210},{"atl":[[3.3,2.5],[3.5,31.18]],"id":42472248}],"con":true,"img":false}]}
{"op":"mcm","clk":"5353940993","pt":1646220011482,"mc":[{"id":"1.195453781","rc":[{"atl":[[4.8,59.21]],"id":41653210},{"atl":[[6.4,23.15]],"id":38904370}],"con":true,"img":false}]}
{"op":"mcm","clk":"5353941003","pt":1646220011583,"mc":[{"id":"1.195453781","rc":[{"atl":[[27,4.81]],"id":28866557},{"atl":[[7.4,19.53]],"id":28671742}],"con":true,"img":false}]}
{"op":"mcm","clk":"5353941046","pt":1646220011948,"mc":[{"id":"1.195453781","rc":[{"atb":[[1.1,0]],"id":40917608},{"atb":[[1.81,50.76]],"id":38247349}],"con":true,"img":false}]}
{"op":"mcm","clk":"5353941064","pt":1646220012157,"mc":[{"id":"1.195453781","rc":[{"atb":[[1.82,96.68],[1.81,0]],"id":38247349}],"con":true,"img":false}]}
{"op":"mcm","clk":"5353941079","pt":1646220012264,"mc":[{"id":"1.195453781","rc":[{"atb":[[5.7,5.19]],"id":28866557}],"con":true,"img":false}]}
{"op":"mcm","clk":"5353941090","pt":1646220012368,"mc":[{"id":"1.195453781","rc":[{"atb":[[5.4,2.5],[5.5,32.09]],"id":28866557}],"con":true,"img":false}]}
{"op":"mcm","clk":"5353941102","pt":1646220012472,"mc":[{"id":"1.195453781","rc":[{"atb":[[5.6,5]],"id":28866557}],"con":true,"img":false}]}
{"op":"mcm","clk":"5353941222","pt":1646220013980,"mc":[{"id":"1.195453781","rc":[{"atb":[[1.74,32.49]],"id":42472248}],"con":true,"img":false}]}
{"op":"mcm","clk":"5353941249","pt":1646220014293,"mc":[{"id":"1.195453781","rc":[{"atl":[[3.05,12.03]],"id":42472248}],"con":true,"img":false}]}
{"op":"mcm","clk":"5353941256","pt":1646220014348,"mc":[{"id":"1.195453781","rc":[{"atl":[[3.45,15.85]],"id":42472248}],"con":true,"img":false}]}
{"op":"mcm","clk":"5353941266","pt":1646220014451,"mc":[{"id":"1.195453781","rc":[{"atb":[[1.14,2.74]],"id":40917608},{"atb":[[1.74,36.23]],"id":42472248},{"atb":[[1.83,28.54]],"id":38247349}],"con":true,"img":false}]}
{"op":"mcm","clk":"5353941313","pt":1646220014971,"mc":[{"id":"1.195453781","rc":[{"atb":[[5.8,5]],"id":28866557}],"con":true,"img":false}]}
