{"op":"mcm","clk":"5351767843","pt":1646175389002,"mc":[{"id":"1.195453769","marketDefinition":{"bspMarket":true,"turnInPlayEnabled":false,"persistenceEnabled":false,"marketBaseRate":7.0,"eventId":"31272499","eventTypeId":"4339","numberOfWinners":2,"bettingType":"ODDS","marketType":"PLACE","marketTime":"2022-03-02T09:37:00.000Z","suspendTime":"2022-03-02T09:37:00.000Z","bspReconciled":false,"complete":true,"inPlay":false,"crossMatching":false,"runnersVoidable":false,"numberOfActiveRunners":5,"betDelay":0,"status":"OPEN","runners":[{"status":"ACTIVE","sortPriority":1,"id":38678129,"name":"2. Blue Jeans Talk"},{"status":"ACTIVE","sortPriority":2,"id":39791031,"name":"4. On The Buses"},{"status":"ACTIVE","sortPriority":3,"id":38240390,"name":"5. Wink At Me"},{"status":"ACTIVE","sortPriority":4,"id":36749619,"name":"7. Love You Peaches"},{"status":"ACTIVE","sortPriority":5,"id":39734310,"name":"8. Canary Wharf"}],"regulators":["MR_INT"],"venue":"Rockhampton","countryCode":"AU","discountAllowed":true,"timezone":"Australia/Queensland","openDate":"2022-03-02T08:34:00.000Z","version":4382437835,"name":"To Be Placed","eventName":"Rockhampton (AUS) 2nd Mar"},"rc":[],"con":true,"img":false}]}
{"op":"mcm","clk":"5351835810","pt":1646176785738,"mc":[{"id":"1.195453769","rc":[{"atb":[[1.4,302.12],[1.45,268.55],[1.5,120.84]],"id":39734310},{"atl":[[3.45,9.86],[3.95,8.19],[4.9,12.39],[2.98,6.1],[2.78,6.78]],"id":39734310},{"spn":2.14,"spf":"NaN","id":39734310},{"atb":[[1.98,61.66],[1.88,137.32],[1.93,129.94]],"id":38240390},{"atl":[[4.9,3.09],[9.8,2.74],[7.8,3.55],[5.9,2.46],[14.5,3.58]],"id":38240390},{"spn":3.44,"spf":"NaN","id":38240390},{"atb":[[1.8,151.06],[1.85,142.17],[1.9,67.13]],"id":38678129},{"atl":[[4,4.02],[8,3.45],[5,3.02],[10,5.37],[6,4.83]],"id":38678129},{"spn":2.95,"spf":"NaN","id":38678129},{"atb":[[1.01,12084.92],[1.11,549.31],[1.06,2014.15]],"id":36749619},{"atl":[[2.36,8.88],[2.56,15.49],[2.96,24.66],[2.16,10.41],[2.76,13.73]],"id":36749619},{"spn":1.63,"spf":"NaN","id":36749619},{"atb":[[5.8,25.17],[7.6,9.15],[6.6,21.57]],"id":39791031},{"atl":[[65,0.19],[130,0.18],[36,0.34],[330,0.14],[230,0.1]],"id":39791031},{"spn":21.8,"spf":"NaN","id":39791031}],"con":true,"img":false}]}
{"op":"mcm","clk":"5352004154","pt":1646180202639,"mc":[{"id":"1.195453769","marketDefinition":{"bspMarket":true,"turnInPlayEnabled":false,"persistenceEnabled":false,"marketBaseRate":7.0,"eventId":"31272499","eventTypeId":"4339","numberOfWinners":2,"bettingType":"ODDS","marketType":"PLACE","marketTime":"2022-03-02T09:37:00.000Z","suspendTime":"2022-03-02T09:37:00.000Z","bspReconciled":false,"complete":true,"inPlay":false,"crossMatching":false,"runnersVoidable":false,"numberOfActiveRunners":5,"betDelay":0,"status":"OPEN","runners":[{"status":"ACTIVE","sortPriority":1,"id":38678129,"name":"2. Blue Jeans Talk"},{"status":"ACTIVE","sortPriority":2,"id":39791031,"name":"4. On The Buses"},{"status":"ACTIVE","sortPriority":3,"id":38240390,"name":"5. Wink At Me"},{"status":"ACTIVE","sortPriority":4,"id":36749619,"name":"7. Love You Peaches"},{"status":"ACTIVE","sortPriority":5,"id":39734310,"name":"8. Canary Wharf"}],"regulators":["MR_INT"],"venue":"Rockhampton","countryCode":"AU","discountAllowed":true,"timezone":"Australia/Queensland","openDate":"2022-03-02T08:34:00.000Z","version":4382437835,"name":"To Be Placed","eventName":"Rockhampton (AUS) 2nd Mar"},"rc":[{"atb":[[1.4,302.15],[1.45,268.58],[1.5,120.86]],"id":39734310},{"atl":[[3.45,9.86],[3.95,8.19],[4.9,12.39],[2.98,6.1],[2.78,6.78]],"id":39734310},{"spn":2.14,"spf":"NaN","id":39734310},{"atb":[[1.98,61.66],[1.88,137.34],[1.93,129.95]],"id":38240390},{"atl":[[4.9,3.09],[9.8,2.74],[7.8,3.55],[5.9,2.46],[14.5,3.58]],"id":38240390},{"spn":3.44,"spf":"NaN","id":38240390},{"atb":[[1.8,151.07],[1.85,142.19],[1.9,67.14]],"id":38678129},{"atl":[[4,4.02],[8,3.45],[5,3.02],[10,5.37],[6,4.83]],"id":38678129},{"spn":2.95,"spf":"NaN","id":38678129},{"atb":[[1.01,12086.23],[1.11,549.37],[1.06,2014.37]],"id":36749619},{"atl":[[2.36,8.88],[2.56,15.49],[2.96,24.66],[2.16,10.42],[2.76,13.73]],"id":36749619},{"spn":1.63,"spf":"NaN","id":36749619},{"atb":[[5.8,25.17],[7.6,9.15],[6.6,21.58]],"id":39791031},{"atl":[[65,0.19],[130,0.18],[36,0.34],[330,0.14],[230,0.1]],"id":39791031},{"spn":21.8,"spf":"NaN","id":39791031}],"con":true,"img":true}]}
{"op":"mcm","clk":"5352146209","pt":1646183572662,"mc":[{"id":"1.195453769","marketDefinition":{"bspMarket":true,"turnInPlayEnabled":false,"persistenceEnabled":false,"marketBaseRate":7.0,"eventId":"31272499","eventTypeId":"4339","numberOfWinners":2,"bettingType":"ODDS","marketType":"PLACE","marketTime":"2022-03-02T09:37:00.000Z","suspendTime":"2022-03-02T09:37:00.000Z","bspReconciled":false,"complete":true,"inPlay":false,"crossMatching":false,"runnersVoidable":false,"numberOfActiveRunners":5,"betDelay":0,"status":"OPEN","runners":[{"status":"ACTIVE","sortPriority":1,"id":38678129,"name":"2. Blue Jeans Talk"},{"status":"ACTIVE","sortPriority":2,"id":39791031,"name":"4. On The Buses"},{"status":"ACTIVE","sortPriority":3,"id":38240390,"name":"5. Wink At Me"},{"status":"ACTIVE","sortPriority":4,"id":36749619,"name":"7. Love You Peaches"},{"status":"ACTIVE","sortPriority":5,"id":39734310,"name":"8. Canary Wharf"}],"regulators":["MR_INT"],"venue":"Rockhampton","countryCode":"AU","discountAllowed":true,"timezone":"Australia/Queensland","openDate":"2022-03-02T08:28:00.000Z","version":4382597830,"name":"To Be Placed","eventName":"Rockhampton (AUS) 2nd Mar"},"rc":[],"con":true,"img":false}]}
{"op":"mcm","clk":"5352155585","pt":1646183832198,"mc":[{"id":"1.195453769","marketDefinition":{"bspMarket":true,"turnInPlayEnabled":false,"persistenceEnabled":false,"marketBaseRate":7.0,"eventId":"31272499","eventTypeId":"4339","numberOfWinners":2,"bettingType":"ODDS","marketType":"PLACE","marketTime":"2022-03-02T09:27:00.000Z","suspendTime":"2022-03-02T09:27:00.000Z","bspReconciled":false,"complete":true,"inPlay":false,"crossMatching":false,"runnersVoidable":false,"numberOfActiveRunners":5,"betDelay":0,"status":"OPEN","runners":[{"status":"ACTIVE","sortPriority":1,"id":38678129,"name":"2. Blue Jeans Talk"},{"status":"ACTIVE","sortPriority":2,"id":39791031,"name":"4. On The Buses"},{"status":"ACTIVE","sortPriority":3,"id":38240390,"name":"5. Wink At Me"},{"status":"ACTIVE","sortPriority":4,"id":36749619,"name":"7. Love You Peaches"},{"status":"ACTIVE","sortPriority":5,"id":39734310,"name":"8. Canary Wharf"}],"regulators":["MR_INT"],"venue":"Rockhampton","countryCode":"AU","discountAllowed":true,"timezone":"Australia/Queensland","openDate":"2022-03-02T08:28:00.000Z","version":4382601896,"name":"To Be Placed","eventName":"Rockhampton (AUS) 2nd Mar"},"rc":[],"con":true,"img":false}]}
{"op":"mcm","clk":"5352238279","pt":1646185602674,"mc":[{"id":"1.195453769","marketDefinition":{"bspMarket":true,"turnInPlayEnabled":false,"persistenceEnabled":false,"marketBaseRate":7.0,"eventId":"31272499","eventTypeId":"4339","numberOfWinners":2,"bettingType":"ODDS","marketType":"PLACE","marketTime":"2022-03-02T09:27:00.000Z","suspendTime":"2022-03-02T09:27:00.000Z","bspReconciled":false,"complete":true,"inPlay":false,"crossMatching":false,"runnersVoidable":false,"numberOfActiveRunners":5,"betDelay":0,"status":"OPEN","runners":[{"status":"ACTIVE","sortPriority":1,"id":38678129,"name":"2. Blue Jeans Talk"},{"status":"ACTIVE","sortPriority":2,"id":39791031,"name":"4. On The Buses"},{"status":"ACTIVE","sortPriority":3,"id":38240390,"name":"5. Wink At Me"},{"status":"ACTIVE","sortPriority":4,"id":36749619,"name":"7. Love You Peaches"},{"status":"ACTIVE","sortPriority":5,"id":39734310,"name":"8. Canary Wharf"}],"regulators":["MR_INT"],"venue":"Rockhampton","countryCode":"AU","discountAllowed":true,"timezone":"Australia/Queensland","openDate":"2022-03-02T08:28:00.000Z","version":4382601896,"name":"To Be Placed","eventName":"Rockhampton (AUS) 2nd Mar"},"rc":[{"atb":[[1.4,302.63],[1.45,269],[1.5,121.05]],"id":39734310},{"atl":[[3.45,9.88],[3.95,8.2],[4.9,12.41],[2.98,6.11],[2.78,6.79]],"id":39734310},{"spn":2.14,"spf":"NaN","id":39734310},{"atb":[[1.98,61.76],[1.88,137.55],[1.93,130.16]],"id":38240390},{"atl":[[4.9,3.1],[9.8,2.75],[7.8,3.56],[5.9,2.47],[14.5,3.58]],"id":38240390},{"spn":3.44,"spf":"NaN","id":38240390},{"atb":[[1.8,151.31],[1.85,142.41],[1.9,67.25]],"id":38678129},{"atl":[[4,4.03],[8,3.45],[5,3.02],[10,5.38],[6,4.84]],"id":38678129},{"spn":2.95,"spf":"NaN","id":38678129},{"atb":[[1.01,12105.34],[1.11,550.24],[1.06,2017.55]],"id":36749619},{"atl":[[2.36,8.89],[2.56,15.51],[2.96,24.7],[2.16,10.43],[2.76,13.75]],"id":36749619},{"spn":1.63,"spf":"NaN","id":36749619},{"atb":[[5.8,25.21],[7.6,9.17],[6.6,21.61]],"id":39791031},{"atl":[[65,0.19],[130,0.18],[36,0.34],[330,0.14],[230,0.1]],"id":39791031},{"spn":21.8,"spf":"NaN","id":39791031}],"con":true,"img":true}]}
{"op":"mcm","clk":"5352465576","pt":1646191002622,"mc":[{"id":"1.195453769","marketDefinition":{"bspMarket":true,"turnInPlayEnabled":false,"persistenceEnabled":false,"marketBaseRate":7.0,"eventId":"31272499","eventTypeId":"4339","numberOfWinners":2,"bettingType":"ODDS","marketType":"PLACE","marketTime":"2022-03-02T09:27:00.000Z","suspendTime":"2022-03-02T09:27:00.000Z","bspReconciled":false,"complete":true,"inPlay":false,"crossMatching":false,"runnersVoidable":false,"numberOfActiveRunners":5,"betDelay":0,"status":"OPEN","runners":[{"status":"ACTIVE","sortPriority":1,"id":38678129,"name":"2. Blue Jeans Talk"},{"status":"ACTIVE","sortPriority":2,"id":39791031,"name":"4. On The Buses"},{"status":"ACTIVE","sortPriority":3,"id":38240390,"name":"5. Wink At Me"},{"status":"ACTIVE","sortPriority":4,"id":36749619,"name":"7. Love You Peaches"},{"status":"ACTIVE","sortPriority":5,"id":39734310,"name":"8. Canary Wharf"}],"regulators":["MR_INT"],"venue":"Rockhampton","countryCode":"AU","discountAllowed":true,"timezone":"Australia/Queensland","openDate":"2022-03-02T08:28:00.000Z","version":4382601896,"name":"To Be Placed","eventName":"Rockhampton (AUS) 2nd Mar"},"rc":[{"atb":[[1.4,303.14],[1.45,269.46],[1.5,121.25]],"id":39734310},{"atl":[[3.45,9.89],[3.95,8.22],[4.9,12.43],[2.98,6.12],[2.78,6.81]],"id":39734310},{"spn":2.14,"spf":"NaN","id":39734310},{"atb":[[1.98,61.86],[1.88,137.79],[1.93,130.38]],"id":38240390},{"atl":[[4.9,3.1],[9.8,2.75],[7.8,3.56],[5.9,2.47],[14.5,3.59]],"id":38240390},{"spn":3.44,"spf":"NaN","id":38240390},{"atb":[[1.8,151.57],[1.85,142.65],[1.9,67.36]],"id":38678129},{"atl":[[4,4.04],[8,3.46],[5,3.03],[10,5.39],[6,4.85]],"id":38678129},{"spn":2.95,"spf":"NaN","id":38678129},{"atb":[[1.01,12125.84],[1.11,551.17],[1.06,2020.97]],"id":36749619},{"atl":[[2.36,8.91],[2.56,15.54],[2.96,24.74],[2.16,10.45],[2.76,13.78]],"id":36749619},{"spn":1.63,"spf":"NaN","id":36749619},{"atb":[[5.8,25.26],[7.6,9.18],[6.6,21.65]],"id":39791031},{"atl":[[65,0.19],[130,0.18],[36,0.34],[330,0.14],[230,0.1]],"id":39791031},{"spn":21.8,"spf":"NaN","id":39791031}],"con":true,"img":true}]}
{"op":"mcm","clk":"5352822385","pt":1646201802666,"mc":[{"id":"1.195453769","marketDefinition":{"bspMarket":true,"turnInPlayEnabled":false,"persistenceEnabled":false,"marketBaseRate":7.0,"eventId":"31272499","eventTypeId":"4339","numberOfWinners":2,"bettingType":"ODDS","marketType":"PLACE","marketTime":"2022-03-02T09:27:00.000Z","suspendTime":"2022-03-02T09:27:00.000Z","bspReconciled":false,"complete":true,"inPlay":false,"crossMatching":false,"runnersVoidable":false,"numberOfActiveRunners":5,"betDelay":0,"status":"OPEN","runners":[{"status":"ACTIVE","sortPriority":1,"id":38678129,"name":"2. Blue Jeans Talk"},{"status":"ACTIVE","sortPriority":2,"id":39791031,"name":"4. On The Buses"},{"status":"ACTIVE","sortPriority":3,"id":38240390,"name":"5. Wink At Me"},{"status":"ACTIVE","sortPriority":4,"id":36749619,"name":"7. Love You Peaches"},{"status":"ACTIVE","sortPriority":5,"id":39734310,"name":"8. Canary Wharf"}],"regulators":["MR_INT"],"venue":"Rockhampton","countryCode":"AU","discountAllowed":true,"timezone":"Australia/Queensland","openDate":"2022-03-02T08:28:00.000Z","version":4382601896,"name":"To Be Placed","eventName":"Rockhampton (AUS) 2nd Mar"},"rc":[{"atb":[[1.4,303.03],[1.45,269.35],[1.5,121.21]],"id":39734310},{"atl":[[3.45,9.89],[3.95,8.21],[4.9,12.43],[2.98,6.12],[2.78,6.8]],"id":39734310},{"spn":2.14,"spf":"NaN","id":39734310},{"atb":[[1.98,61.84],[1.88,137.73],[1.93,130.33]],"id":38240390},{"atl":[[4.9,3.1],[9.8,2.75],[7.8,3.56],[5.9,2.47],[14.5,3.59]],"id":38240390},{"spn":3.44,"spf":"NaN","id":38240390},{"atb":[[1.8,151.51],[1.85,142.6],[1.9,67.33]],"id":38678129},{"atl":[[4,4.04],[8,3.46],[5,3.03],[10,5.38],[6,4.84]],"id":38678129},{"spn":2.95,"spf":"NaN","id":38678129},{"atb":[[1.01,12121.21],[1.11,550.96],[1.06,2020.2]],"id":36749619},{"atl":[[2.36,8.91],[2.56,15.53],[2.96,24.73],[2.16,10.45],[2.76,13.77]],"id":36749619},{"spn":1.63,"spf":"NaN","id":36749619},{"atb":[[5.8,25.25],[7.6,9.18],[6.6,21.64]],"id":39791031},{"atl":[[65,0.19],[130,0.18],[36,0.34],[330,0.14],[230,0.1]],"id":39791031},{"spn":21.8,"spf":"NaN","id":39791031}],"con":true,"img":true}]}
{"op":"mcm","clk":"5353027760","pt":1646207202701,"mc":[{"id":"1.195453769","marketDefinition":{"bspMarket":true,"turnInPlayEnabled":false,"persistenceEnabled":false,"marketBaseRate":7.0,"eventId":"31272499","eventTypeId":"4339","numberOfWinners":2,"bettingType":"ODDS","marketType":"PLACE","marketTime":"2022-03-02T09:27:00.000Z","suspendTime":"2022-03-02T09:27:00.000Z","bspReconciled":false,"complete":true,"inPlay":false,"crossMatching":false,"runnersVoidable":false,"numberOfActiveRunners":5,"betDelay":0,"status":"OPEN","runners":[{"status":"ACTIVE","sortPriority":1,"id":38678129,"name":"2. Blue Jeans Talk"},{"status":"ACTIVE","sortPriority":2,"id":39791031,"name":"4. On The Buses"},{"status":"ACTIVE","sortPriority":3,"id":38240390,"name":"5. Wink At Me"},{"status":"ACTIVE","sortPriority":4,"id":36749619,"name":"7. Love You Peaches"},{"status":"ACTIVE","sortPriority":5,"id":39734310,"name":"8. Canary Wharf"}],"regulators":["MR_INT"],"venue":"Rockhampton","countryCode":"AU","discountAllowed":true,"timezone":"Australia/Queensland","openDate":"2022-03-02T08:28:00.000Z","version":4382601896,"name":"To Be Placed","eventName":"Rockhampton (AUS) 2nd Mar"},"rc":[{"atb":[[1.4,302.94],[1.45,269.28],[1.5,121.17]],"id":39734310},{"atl":[[3.45,9.89],[3.95,8.21],[4.9,12.42],[2.98,6.11],[2.78,6.8]],"id":39734310},{"spn":2.14,"spf":"NaN","id":39734310},{"atb":[[1.98,61.82],[1.88,137.7],[1.93,130.3]],"id":38240390},{"atl":[[4.9,3.1],[9.8,2.75],[7.8,3.56],[5.9,2.47],[14.5,3.59]],"id":38240390},{"spn":3.44,"spf":"NaN","id":38240390},{"atb":[[1.8,151.47],[1.85,142.56],[1.9,67.31]],"id":38678129},{"atl":[[4,4.03],[8,3.46],[5,3.02],[10,5.38],[6,4.84]],"id":38678129},{"spn":2.95,"spf":"NaN","id":38678129},{"atb":[[1.01,12117.9],[1.11,550.81],[1.06,2019.65]],"id":36749619},{"atl":[[2.36,8.9],[2.56,15.53],[2.96,24.73],[2.16,10.44],[2.76,13.77]],"id":36749619},{"spn":1.63,"spf":"NaN","id":36749619},{"atb":[[5.8,25.24],[7.6,9.18],[6.6,21.63]],"id":39791031},{"atl":[[65,0.19],[130,0.18],[36,0.34],[330,0.14],[230,0.1]],"id":39791031},{"spn":21.8,"spf":"NaN","id":39791031}],"con":true,"img":true}]}
{"op":"mcm","clk":"5353055756","pt":1646207852572,"mc":[{"id":"1.195453769","rc":[{"atb":[[1.4,302.94],[1.63,69.31],[1.45,269.28],[1.5,121.17],[1.52,125]],"id":39734310},{"atl":[[4.8,16.92],[3.45,9.89],[3.95,8.21],[4.9,12.42],[2.98,6.11],[2.78,6.8],[4.7,11.8]],"id":39734310},{"spn":2.2,"spf":"NaN","id":39734310},{"atb":[[1.98,61.82],[1.88,137.7],[1.94,46.45],[1.93,130.3],[1.69,97.16]],"id":38240390},{"atl":[[6.4,12.55],[5.8,9.09],[4.9,3.1],[9.8,2.75],[7.8,3.56],[5.9,2.47],[14.5,3.59]],"id":38240390},{"atb":[[1.8,151.47],[1.85,142.56],[1.9,67.31],[1.86,122.33]],"id":38678129},{"atl":[[4,4.03],[8,3.46],[5,3.02],[10,5.38],[6,13.58],[6.6,10.98]],"id":38678129},{"atb":[[1.12,552.4],[1.01,12117.9],[1.11,550.81],[1.06,2019.65],[1.13,99.93]],"id":36749619},{"atl":[[2.36,8.9],[2.56,15.53],[2.06,62.77],[1.9,43.66],[2.96,24.73],[2.16,10.44],[2.76,13.77]],"id":36749619},{"spn":1.51,"spf":"NaN","id":36749619},{"atb":[[5.8,25.24],[9.2,6.88],[11,4.36],[7.6,9.18],[6.6,21.63]],"id":39791031},{"atl":[[65,2.92],[130,0.18],[70,2.72],[36,0.34],[330,0.14],[230,0.1]],"id":39791031},{"spn":23.5,"spf":"NaN","id":39791031}],"con":true,"img":false}]}
{"op":"mcm","clk":"5353058116","pt":1646207909754,"mc":[{"id":"1.195453769","rc":[{"atb":[[1.94,0]],"id":38240390},{"atb":[[1.86,71.56]],"id":38678129}],"con":true,"img":false}]}
{"op":"mcm","clk":"5353058123","pt":1646207909860,"mc":[{"id":"1.195453769","rc":[{"atb":[[1.99,46.45]],"id":38240390},{"atb":[[1.91,50.77]],"id":38678129}],"con":true,"img":false}]}
{"op":"mcm","clk":"5353137773","pt":1646209622637,"mc":[{"id":"1.195453769","rc":[{"atb":[[1.08,250]],"id":39734310},{"atl":[[2.76,6.81]],"id":39734310},{"spn":2.19,"spf":"NaN","id":39734310},{"atb":[[2,61.83]],"id":38240390},{"atl":[[7,12.21]],"id":38240390},{"spn":3.45,"spf":"NaN","id":38240390},{"atb":[[1.62,143.12]],"id":38678129},{"atl":[[7.2,15.03]],"id":38678129},{"spn":2.95,"spf":"NaN","id":38678129},{"atb":[[1.1,1000]],"id":36749619},{"atl":[[1.89,43.67]],"id":36749619},{"spn":1.51,"spf":"NaN","id":36749619},{"atb":[[3.75,18.36]],"id":39791031},{"atl":[[240,2]],"id":39791031}],"con":true,"img":false}]}
{"op":"mcm","clk":"5353139418","pt":1646209651059,"mc":[{"id":"1.195453769","rc":[{"atb":[[2,0],[1.97,103.09]],"id":38240390},{"atb":[[1.09,1111.11],[1.1,0]],"id":36749619}],"con":true,"img":false}]}
{"op":"mcm","clk":"5353140562","pt":1646209671260,"mc":[{"id":"1.195453769","rc":[{"atl":[[1.9,0]],"id":36749619},{"atl":[[65,0.19]],"id":39791031}],"con":true,"img":false}]}
{"op":"mcm","clk":"5353140570","pt":1646209671360,"mc":[{"id":"1.195453769","rc":[{"atl":[[1.82,43.66],[1.89,0]],"id":36749619},{"atl":[[60,2.72]],"id":39791031}],"con":true,"img":false}]}
{"op":"mcm","clk":"5353140576","pt":1646209671464,"mc":[{"id":"1.195453769","rc":[{"atl":[[2.04,87.34]],"id":36749619}],"con":true,"img":false}]}
{"op":"mcm","clk":"5353141234","pt":1646209683358,"mc":[{"id":"1.195453769","rc":[{"spn":3.44,"spf":"NaN","id":38240390},{"atl":[[2.06,0]],"id":36749619},{"spn":1.47,"spf":"NaN","id":36749619}],"con":true,"img":false}]}
{"op":"mcm","clk":"5353141246","pt":1646209683461,"mc":[{"id":"1.195453769","rc":[{"atl":[[1.98,62.77]],"id":36749619}],"con":true,"img":false}]}
{"op":"mcm","clk":"5353142390","pt":1646209701294,"mc":[{"id":"1.195453769","rc":[{"atb":[[2,61.83],[1.97,0]],"id":38240390},{"atb":[[1.09,0],[1.1,1000]],"id":36749619}],"con":true,"img":false}]}
{"op":"mcm","clk":"5353142757","pt":1646209708126,"mc":[{"id":"1.195453769","rc":[{"atl":[[1.81,62.77],[2.04,0]],"id":36749619}],"con":true,"img":false}]}
{"op":"mcm","clk":"5353143355","pt":1646209718500,"mc":[{"id":"1.195453769","rc":[{"atl":[[1.98,0],[2.44,43.12]],"id":36749619},{"atb":[[3.45,23.05],[4.3,13.23],[9.2,0],[11,0]],"id":39791031}],"con":true,"img":false}]}
{"op":"mcm","clk":"5353143363","pt":1646209718602,"mc":[{"id":"1.195453769","rc":[{"atb":[[1.86,0]],"id":38678129}],"con":true,"img":false}]}
{"op":"mcm","clk":"5353143371","pt":1646209718708,"mc":[{"id":"1.195453769","rc":[{"atb":[[1.81,71.56]],"id":38678129}],"con":true,"img":false}]}
{"op":"mcm","clk":"5353143999","pt":1646209731459,"mc":[{"id":"1.195453769","rc":[{"atl":[[2.98,19.73],[2.76,0]],"id":39734310},{"atl":[[7.2,0],[5.2,13.58]],"id":38678129},{"atb":[[1.1,0],[1.05,2000]],"id":36749619}],"con":true,"img":false}]}
{"op":"mcm","clk":"5353144404","pt":1646209739347,"mc":[{"id":"1.195453769","rc":[{"atb":[[1.63,0]],"id":39734310},{"atb":[[1.99,0]],"id":38240390},{"atl":[[6,4.84]],"id":38678129},{"atl":[[1.82,0]],"id":36749619},{"atl":[[60,0]],"id":39791031}],"con":true,"img":false}]}
{"op":"mcm","clk":"5353144410","pt":1646209739450,"mc":[{"id":"1.195453769","rc":[{"atb":[[1.66,69.31]],"id":39734310},{"atb":[[2,0],[1.99,101.01],[2.02,46.45]],"id":38240390},{"atl":[[5.4,8.73]],"id":38678129},{"atl":[[1.8,43.66],[1.81,0],[2.14,87.72]],"id":36749619},{"atl":[[24,2.72]],"id":39791031}],"con":true,"img":false}]}
{"op":"mcm","clk":"5353144688","pt":1646209744373,"mc":[{"id":"1.195453769","rc":[{"spn":2.22,"spf":"NaN","id":39734310},{"spn":3.46,"spf":"NaN","id":38240390},{"atl":[[1.79,43.67],[2.14,0]],"id":36749619},{"spn":1.46,"spf":"NaN","id":36749619},{"spn":15.8,"spf":"NaN","id":39791031}],"con":true,"img":false}]}
{"op":"mcm","clk":"5353144947","pt":1646209749485,"mc":[{"id":"1.195453769","rc":[{"atl":[[24,0]],"id":39791031}],"con":true,"img":false}]}
{"op":"mcm","clk":"5353144954","pt":1646209749540,"mc":[{"id":"1.195453769","rc":[{"atl":[[60,2.72]],"id":39791031}],"con":true,"img":false}]}
{"op":"mcm","clk":"5353145526","pt":1646209761678,"mc":[{"id":"1.195453769","rc":[{"atb":[[2.02,0]],"id":38240390}],"con":true,"img":false}]}
{"op":"mcm","clk":"5353145531","pt":1646209761791,"mc":[{"id":"1.195453769","rc":[{"atb":[[2,46.45]],"id":38240390}],"con":true,"img":false}]}
{"op":"mcm","clk":"5353145802","pt":1646209767416,"mc":[{"id":"1.195453769","rc":[{"atl":[[2.98,6.11],[2.84,13.62]],"id":39734310}],"con":true,"img":false}]}
{"op":"mcm","clk":"5353145807","pt":1646209767518,"mc":[{"id":"1.195453769","rc":[{"atl":[[5,11.75],[5.2,0]],"id":38678129},{"atb":[[1.05,0],[1.07,1428.57]],"id":36749619}],"con":true,"img":false}]}
{"op":"mcm","clk":"5353145983","pt":1646209770819,"mc":[{"id":"1.195453769","rc":[{"atl":[[5.4,0]],"id":38678129},{"atb":[[4.3,0],[11,4.36]],"id":39791031}],"con":true,"img":false}]}
{"op":"mcm","clk":"5353145986","pt":1646209770923,"mc":[{"id":"1.195453769","rc":[{"atl":[[5.1,8.73]],"id":38678129}],"con":true,"img":false}]}
{"op":"mcm","clk":"5353146235","pt":1646209775412,"mc":[{"id":"1.195453769","rc":[{"atb":[[2.02,61.83]],"id":38240390}],"con":true,"img":false}]}
{"op":"mcm","clk":"5353146242","pt":1646209775514,"mc":[{"id":"1.195453769","rc":[{"atb":[[1.99,0]],"id":38240390}],"con":true,"img":false}]}
{"op":"mcm","clk":"5353146431","pt":1646209779837,"mc":[{"id":"1.195453769","rc":[{"atl":[[1.8,0]],"id":36749619}],"con":true,"img":false}]}
{"op":"mcm","clk":"5353146436","pt":1646209779940,"mc":[{"id":"1.195453769","rc":[{"atl":[[1.79,0],[1.78,43.66],[2.14,87.34]],"id":36749619}],"con":true,"img":false}]}
{"op":"mcm","clk":"5353147082","pt":1646209792252,"mc":[{"id":"1.195453769","rc":[{"atb":[[2,0]],"id":38240390}],"con":true,"img":false}]}
{"op":"mcm","clk":"5353147086","pt":1646209792354,"mc":[{"id":"1.195453769","rc":[{"atb":[[1.99,147.46]],"id":38240390}],"con":true,"img":false}]}
{"op":"mcm","clk":"5353147094","pt":1646209792457,"mc":[{"id":"1.195453769","rc":[{"atb":[[2.02,0]],"id":38240390}],"con":true,"img":false}]}
{"op":"mcm","clk":"5353147567","pt":1646209801246,"mc":[{"id":"1.195453769","rc":[{"atb":[[1.81,0]],"id":38678129},{"atl":[[5.1,0]],"id":38678129},{"atl":[[1.97,68.23],[2.44,0]],"id":36749619}],"con":true,"img":false}]}
{"op":"mcm","clk":"5353147570","pt":1646209801348,"mc":[{"id":"1.195453769","rc":[{"atb":[[1.86,71.56]],"id":38678129},{"atl":[[4.9,8.73]],"id":38678129}],"con":true,"img":false}]}
{"op":"mcm","clk":"5353148292","pt":1646209814155,"mc":[{"id":"1.195453769","rc":[{"spn":3.44,"spf":"NaN","id":38240390},{"spn":1.45,"spf":"NaN","id":36749619},{"atb":[[3.45,0],[9.2,6.88]],"id":39791031},{"spn":23.5,"spf":"NaN","id":39791031}],"con":true,"img":false}]}
{"op":"mcm","clk":"5353148360","pt":1646209815452,"mc":[{"id":"1.195453769","rc":[{"atl":[[1.77,68.23],[2.14,0]],"id":36749619}],"con":true,"img":false}]}
{"op":"mcm","clk":"5353148745","pt":1646209823279,"mc":[{"id":"1.195453769","rc":[{"atb":[[1.99,101.01]],"id":38240390}],"con":true,"img":false}]}
{"op":"mcm","clk":"5353148749","pt":1646209823382,"mc":[{"id":"1.195453769","rc":[{"atb":[[2,46.45]],"id":38240390}],"con":true,"img":false}]}
{"op":"mcm","clk":"5353148754","pt":1646209823486,"mc":[{"id":"1.195453769","rc":[{"atb":[[2.02,61.83]],"id":38240390}],"con":true,"img":false}]}
{"op":"mcm","clk":"5353148761","pt":1646209823589,"mc":[{"id":"1.195453769","rc":[{"atb":[[1.99,0]],"id":38240390}],"con":true,"img":false}]}
{"op":"mcm","clk":"5353150031","pt":1646209846908,"mc":[{"id":"1.195453769","rc":[{"atb":[[2,0]],"id":38240390}],"con":true,"img":false}]}
{"op":"mcm","clk":"5353150037","pt":1646209847011,"mc":[{"id":"1.195453769","rc":[{"atb":[[1.99,46.45]],"id":38240390}],"con":true,"img":false}]}
{"op":"mcm","clk":"5353150046","pt":1646209847115,"mc":[{"id":"1.195453769","rc":[{"atb":[[1.99,147.46],[2.02,0]],"id":38240390}],"con":true,"img":false}]}
{"op":"mcm","clk":"5353150296","pt":1646209851409,"mc":[{"id":"1.195453769","rc":[{"atl":[[2.84,0],[2.98,26.54]],"id":39734310}],"con":true,"img":false}]}
{"op":"mcm","clk":"5353150712","pt":1646209860140,"mc":[{"id":"1.195453769","rc":[{"atl":[[1.78,0]],"id":36749619}],"con":true,"img":false}]}
{"op":"mcm","clk":"5353150716","pt":1646209860242,"mc":[{"id":"1.195453769","rc":[{"atl":[[1.76,43.66]],"id":36749619}],"con":true,"img":false}]}
{"op":"mcm","clk":"5353150727","pt":1646209860346,"mc":[{"id":"1.195453769","rc":[{"atl":[[1.96,104.17],[1.77,0]],"id":36749619}],"con":true,"img":false}]}
{"op":"mcm","clk":"5353151221","pt":1646209869636,"mc":[{"id":"1.195453769","rc":[{"atb":[[1.66,0]],"id":39734310},{"atl":[[4.9,0]],"id":38678129},{"atl":[[2.44,43.12]],"id":36749619},{"atb":[[4.1,14.08],[3.35,24.03]],"id":39791031}],"con":true,"img":false}]}
{"op":"mcm","clk":"5353151228","pt":1646209869739,"mc":[{"id":"1.195453769","rc":[{"atb":[[1.61,69.31]],"id":39734310},{"atl":[[5.6,8.73]],"id":38678129},{"atl":[[1.97,0]],"id":36749619},{"atb":[[9.2,0],[11,0]],"id":39791031}],"con":true,"img":false}]}
{"op":"mcm","clk":"5353151409","pt":1646209872639,"mc":[{"id":"1.195453769","rc":[{"atb":[[1.52,0]],"id":39734310},{"atl":[[5.6,0],[6.6,0]],"id":38678129}],"con":true,"img":false}]}
{"op":"mcm","clk":"5353151414","pt":1646209872741,"mc":[{"id":"1.195453769","rc":[{"atb":[[1.46,125]],"id":39734310},{"atl":[[7.2,10.98],[6.4,8.73]],"id":38678129}],"con":true,"img":false}]}
{"op":"mcm","clk":"5353151605","pt":1646209875734,"mc":[{"id":"1.195453769","rc":[{"spn":2.19,"spf":"NaN","id":39734310},{"atb":[[1.99,101.01]],"id":38240390},{"atb":[[1.86,0]],"id":38678129},{"spn":1.44,"spf":"NaN","id":36749619},{"spn":21.8,"spf":"NaN","id":39791031}],"con":true,"img":false}]}
{"op":"mcm","clk":"5353151611","pt":1646209875839,"mc":[{"id":"1.195453769","rc":[{"atb":[[2,46.45]],"id":38240390},{"atb":[[1.81,71.56]],"id":38678129}],"con":true,"img":false}]}
{"op":"mcm","clk":"5353151620","pt":1646209875942,"mc":[{"id":"1.195453769","rc":[{"atb":[[1.99,0],[2.02,61.83]],"id":38240390}],"con":true,"img":false}]}
{"op":"mcm","clk":"5353152028","pt":1646209883072,"mc":[{"id":"1.195453769","rc":[{"atb":[[1.61,0]],"id":39734310}],"con":true,"img":false}]}
{"op":"mcm","clk":"5353152033","pt":1646209883174,"mc":[{"id":"1.195453769","rc":[{"atb":[[1.51,69.31]],"id":39734310}],"con":true,"img":false}]}
{"op":"mcm","clk":"5353152516","pt":1646209892462,"mc":[{"id":"1.195453769","rc":[{"atl":[[2.96,22.28],[4.7,0]],"id":39734310}],"con":true,"img":false}]}
{"op":"mcm","clk":"5353152648","pt":1646209895080,"mc":[{"id":"1.195453769","rc":[{"atl":[[1.96,0],[1.75,43.67]],"id":36749619}],"con":true,"img":false}]}
{"op":"mcm","clk":"5353153002","pt":1646209902481,"mc":[{"id":"1.195453769","rc":[{"atb":[[2,0]],"id":38240390},{"atl":[[6.4,0]],"id":38678129},{"atb":[[10,4.85]],"id":39791031}],"con":true,"img":false}]}
{"op":"mcm","clk":"5353153012","pt":1646209902583,"mc":[{"id":"1.195453769","rc":[{"atb":[[1.99,147.46]],"id":38240390},{"atl":[[4.9,8.73]],"id":38678129},{"atb":[[4.1,0]],"id":39791031}],"con":true,"img":false}]}
{"op":"mcm","clk":"5353153016","pt":1646209902685,"mc":[{"id":"1.195453769","rc":[{"atb":[[2.02,0]],"id":38240390}],"con":true,"img":false}]}
{"op":"mcm","clk":"5353153481","pt":1646209912317,"mc":[{"id":"1.195453769","rc":[{"atl":[[60,0]],"id":39791031}],"con":true,"img":false}]}
{"op":"mcm","clk":"5353153487","pt":1646209912372,"mc":[{"id":"1.195453769","rc":[{"atl":[[50,2.72]],"id":39791031}],"con":true,"img":false}]}
{"op":"mcm","clk":"5353153916","pt":1646209922729,"mc":[{"id":"1.195453769","rc":[{"atl":[[1.76,0]],"id":36749619}],"con":true,"img":false}]}
{"op":"mcm","clk":"5353153921","pt":1646209922785,"mc":[{"id":"1.195453769","rc":[{"atl":[[1.74,43.66]],"id":36749619}],"con":true,"img":false}]}
{"op":"mcm","clk":"5353153928","pt":1646209922891,"mc":[{"id":"1.195453769","rc":[{"atl":[[1.75,0],[2.14,87.34]],"id":36749619}],"con":true,"img":false}]}
{"op":"mcm","clk":"5353153943","pt":1646209923143,"mc":[{"id":"1.195453769","rc":[{"atl":[[1.75,87.34],[2.14,0]],"id":36749619}],"con":true,"img":false}]}
{"op":"mcm","clk":"5353154196","pt":1646209927833,"mc":[{"id":"1.195453769","rc":[{"atb":[[10,0],[4.1,14.08]],"id":39791031}],"con":true,"img":false}]}
{"op":"mcm","clk":"5353154437","pt":1646209932329,"mc":[{"id":"1.195453769","rc":[{"atb":[[1.99,101.01]],"id":38240390},{"atb":[[1.81,0]],"id":38678129},{"atl":[[70,0]],"id":39791031}],"con":true,"img":false}]}
{"op":"mcm","clk":"5353154443","pt":1646209932425,"mc":[{"id":"1.195453769","rc":[{"atb":[[2,46.45]],"id":38240390},{"atb":[[1.86,71.56]],"id":38678129},{"atl":[[29,2.72]],"id":39791031}],"con":true,"img":false}]}
{"op":"mcm","clk":"5353154669","pt":1646209936945,"mc":[{"id":"1.195453769","rc":[{"spn":2.14,"spf":"NaN","id":39734310},{"atb":[[1.99,0],[2.02,61.83]],"id":38240390},{"spn":3.46,"spf":"NaN","id":38240390},{"spn":1.43,"spf":"NaN","id":36749619},{"spn":18.3,"spf":"NaN","id":39791031}],"con":true,"img":false}]}
{"op":"mcm","clk":"5353155895","pt":1646209960386,"mc":[{"id":"1.195453769","rc":[{"atb":[[1.51,0]],"id":39734310},{"atb":[[2,0]],"id":38240390},{"atl":[[50,0]],"id":39791031}],"con":true,"img":false}]}
{"op":"mcm","clk":"5353155902","pt":1646209960490,"mc":[{"id":"1.195453769","rc":[{"atb":[[1.61,69.31]],"id":39734310},{"atb":[[1.99,147.46],[2.02,0]],"id":38240390},{"atl":[[24,2.72]],"id":39791031}],"con":true,"img":false}]}
{"op":"mcm","clk":"5353157123","pt":1646209983082,"mc":[{"id":"1.195453769","rc":[{"atb":[[1.89,75.32],[1.69,0]],"id":38240390}],"con":true,"img":false}]}
{"op":"mcm","clk":"5353157131","pt":1646209983188,"mc":[{"id":"1.195453769","rc":[{"atb":[[1.46,0]],"id":39734310},{"atl":[[7.2,0]],"id":38678129}],"con":true,"img":false}]}
{"op":"mcm","clk":"5353157137","pt":1646209983289,"mc":[{"id":"1.195453769","rc":[{"atb":[[1.51,125]],"id":39734310},{"atl":[[6.4,10.98]],"id":38678129}],"con":true,"img":false}]}
{"op":"mcm","clk":"5353157646","pt":1646209992684,"mc":[{"id":"1.195453769","rc":[{"atb":[[1.99,101.01]],"id":38240390}],"con":true,"img":false}]}
{"op":"mcm","clk":"5353157654","pt":1646209992786,"mc":[{"id":"1.195453769","rc":[{"atb":[[2,46.45]],"id":38240390}],"con":true,"img":false}]}
{"op":"mcm","clk":"5353157754","pt":1646209994226,"mc":[{"id":"1.195453769","rc":[{"atb":[[2.02,61.83]],"id":38240390}],"con":true,"img":false}]}
{"op":"mcm","clk":"5353157759","pt":1646209994328,"mc":[{"id":"1.195453769","rc":[{"atb":[[1.99,0]],"id":38240390}],"con":true,"img":false}]}
{"op":"mcm","clk":"5353158877","pt":1646210014630,"mc":[{"id":"1.195453769","rc":[{"spn":2.19,"spf":"NaN","id":39734310},{"atb":[[2,0]],"id":38240390},{"spn":15.8,"spf":"NaN","id":39791031}],"con":true,"img":false}]}
{"op":"mcm","clk":"5353158880","pt":1646210014732,"mc":[{"id":"1.195453769","rc":[{"atb":[[1.99,46.45]],"id":38240390}],"con":true,"img":false}]}
{"op":"mcm","clk":"5353158886","pt":1646210014937,"mc":[{"id":"1.195453769","rc":[{"atb":[[2,100],[2.02,0]],"id":38240390}],"con":true,"img":false}]}
{"op":"mcm","clk":"5353160863","pt":1646210052040,"mc":[{"id":"1.195453769","rc":[{"atb":[[1.99,0]],"id":38240390},{"atb":[[1.86,0]],"id":38678129}],"con":true,"img":false}]}
{"op":"mcm","clk":"5353160868","pt":1646210052143,"mc":[{"id":"1.195453769","rc":[{"atb":[[2,0],[1.99,101.01],[2.02,46.45]],"id":38240390},{"atb":[[1.91,122.33]],"id":38678129}],"con":true,"img":false}]}
{"op":"mcm","clk":"5353161647","pt":1646210066493,"mc":[{"id":"1.195453769","rc":[{"atb":[[2.02,0]],"id":38240390},{"atb":[[1.91,50.77]],"id":38678129}],"con":true,"img":false}]}
{"op":"mcm","clk":"5353161652","pt":1646210066595,"mc":[{"id":"1.195453769","rc":[{"atb":[[2,46.45]],"id":38240390},{"atb":[[1.86,71.56]],"id":38678129}],"con":true,"img":false}]}
{"op":"mcm","clk":"5353162614","pt":1646210085022,"mc":[{"id":"1.195453769","rc":[{"atb":[[1.99,0],[2.02,61.83]],"id":38240390}],"con":true,"img":false}]}
{"op":"mcm","clk":"5353163471","pt":1646210101698,"mc":[{"id":"1.195453769","rc":[{"atb":[[2,0]],"id":38240390}],"con":true,"img":false}]}
{"op":"mcm","clk":"5353163477","pt":1646210101801,"mc":[{"id":"1.195453769","rc":[{"atb":[[1.99,147.46],[2.02,0]],"id":38240390}],"con":true,"img":false}]}
{"op":"mcm","clk":"5353165150","pt":1646210133573,"mc":[{"id":"1.195453769","rc":[{"atb":[[1.99,101.01]],"id":38240390}],"con":true,"img":false}]}
{"op":"mcm","clk":"5353165154","pt":1646210133671,"mc":[{"id":"1.195453769","rc":[{"atb":[[2,46.45]],"id":38240390}],"con":true,"img":false}]}
{"op":"mcm","clk":"5353165193","pt":1646210134141,"mc":[{"id":"1.195453769","rc":[{"atb":[[2.02,61.83]],"id":38240390}],"con":true,"img":false}]}
{"op":"mcm","clk":"5353165199","pt":1646210134243,"mc":[{"id":"1.195453769","rc":[{"atb":[[1.99,0]],"id":38240390}],"con":true,"img":false}]}
{"op":"mcm","clk":"5353166354","pt":1646210155080,"mc":[{"id":"1.195453769","rc":[{"atb":[[2,0]],"id":38240390}],"con":true,"img":false}]}
{"op":"mcm","clk":"5353166359","pt":1646210155185,"mc":[{"id":"1.195453769","rc":[{"atb":[[1.99,46.45]],"id":38240390}],"con":true,"img":false}]}
{"op":"mcm","clk":"5353166368","pt":1646210155289,"mc":[{"id":"1.195453769","rc":[{"atb":[[1.99,147.46]],"id":38240390}],"con":true,"img":false}]}
{"op":"mcm","clk":"5353166375","pt":1646210155386,"mc":[{"id":"1.195453769","rc":[{"atb":[[2.02,0]],"id":38240390}],"con":true,"img":false}]}
{"op":"mcm","clk":"5353168099","pt":1646210187998,"mc":[{"id":"1.195453769","rc":[{"atb":[[1.99,101.01]],"id":38240390}],"con":true,"img":false}]}
{"op":"mcm","clk":"5353168101","pt":1646210188100,"mc":[{"id":"1.195453769","rc":[{"atb":[[2,46.45]],"id":38240390}],"con":true,"img":false}]}
{"op":"mcm","clk":"5353168111","pt":1646210188203,"mc":[{"id":"1.195453769","rc":[{"atb":[[1.99,0],[2.02,61.83]],"id":38240390}],"con":true,"img":false}]}
{"op":"mcm","clk":"5353169926","pt":1646210222458,"mc":[{"id":"1.195453769","rc":[{"atb":[[2,0]],"id":38240390}],"con":true,"img":false}]}
{"op":"mcm","clk":"5353169934","pt":1646210222560,"mc":[{"id":"1.195453769","rc":[{"atb":[[1.99,46.45]],"id":38240390}],"con":true,"img":false}]}
{"op":"mcm","clk":"5353169941","pt":1646210222663,"mc":[{"id":"1.195453769","rc":[{"atb":[[1.99,147.46],[2.02,0]],"id":38240390}],"con":true,"img":false}]}
{"op":"mcm","clk":"5353170604","pt":1646210235482,"mc":[{"id":"1.195453769","rc":[{"atb":[[1.73,91.7],[1.89,0]],"id":38240390}],"con":true,"img":false}]}
{"op":"mcm","clk":"5353171746","pt":1646210257404,"mc":[{"id":"1.195453769","rc":[{"atb":[[1.99,101.01]],"id":38240390}],"con":true,"img":false}]}
{"op":"mcm","clk":"5353171752","pt":1646210257506,"mc":[{"id":"1.195453769","rc":[{"atb":[[2,46.45]],"id":38240390}],"con":true,"img":false}]}
{"op":"mcm","clk":"5353171765","pt":1646210257710,"mc":[{"id":"1.195453769","rc":[{"atb":[[1.99,0],[2.02,61.83]],"id":38240390}],"con":true,"img":false}]}
{"op":"mcm","clk":"5353173343","pt":1646210285848,"mc":[{"id":"1.195453769","rc":[{"atb":[[2,0]],"id":38240390}],"con":true,"img":false}]}
{"op":"mcm","clk":"5353173351","pt":1646210285955,"mc":[{"id":"1.195453769","rc":[{"atb":[[1.99,46.45]],"id":38240390}],"con":true,"img":false}]}
{"op":"mcm","clk":"5353173357","pt":1646210286050,"mc":[{"id":"1.195453769","rc":[{"atb":[[1.99,147.46],[2.02,0]],"id":38240390}],"con":true,"img":false}]}
{"op":"mcm","clk":"5353174965","pt":1646210314965,"mc":[{"id":"1.195453769","rc":[{"atb":[[1.99,101.01]],"id":38240390}],"con":true,"img":false}]}
{"op":"mcm","clk":"5353174971","pt":1646210315068,"mc":[{"id":"1.195453769","rc":[{"atb":[[2,46.45]],"id":38240390}],"con":true,"img":false}]}
{"op":"mcm","clk":"5353174977","pt":1646210315172,"mc":[{"id":"1.195453769","rc":[{"atb":[[1.99,0],[2.02,61.83]],"id":38240390}],"con":true,"img":false}]}
{"op":"mcm","clk":"5353176347","pt":1646210343289,"mc":[{"id":"1.195453769","rc":[{"atb":[[2,0]],"id":38240390}],"con":true,"img":false}]}
{"op":"mcm","clk":"5353176352","pt":1646210343388,"mc":[{"id":"1.195453769","rc":[{"atb":[[1.99,46.45]],"id":38240390}],"con":true,"img":false}]}
{"op":"mcm","clk":"5353176359","pt":1646210343493,"mc":[{"id":"1.195453769","rc":[{"atb":[[1.99,147.46],[2.02,0]],"id":38240390}],"con":true,"img":false}]}
{"op":"mcm","clk":"5353178035","pt":1646210375913,"mc":[{"id":"1.195453769","rc":[{"atb":[[1.99,101.01]],"id":38240390},{"spn":3.44,"spf":"NaN","id":38240390}],"con":true,"img":false}]}
{"op":"mcm","clk":"5353178039","pt":1646210376016,"mc":[{"id":"1.195453769","rc":[{"atb":[[2,46.45]],"id":38240390}],"con":true,"img":false}]}
{"op":"mcm","clk":"5353178049","pt":1646210376220,"mc":[{"id":"1.195453769","rc":[{"atb":[[1.99,0],[2.02,61.83]],"id":38240390}],"con":true,"img":false}]}
{"op":"mcm","clk":"5353179045","pt":1646210396763,"mc":[{"id":"1.195453769","rc":[{"atb":[[2,0]],"id":38240390}],"con":true,"img":false}]}
{"op":"mcm","clk":"5353179048","pt":1646210396859,"mc":[{"id":"1.195453769","rc":[{"atb":[[1.99,147.46],[2.02,0]],"id":38240390}],"con":true,"img":false}]}
{"op":"mcm","clk":"5353180614","pt":1646210427276,"mc":[{"id":"1.195453769","rc":[{"atb":[[1.99,101.01]],"id":38240390}],"con":true,"img":false}]}
{"op":"mcm","clk":"5353180619","pt":1646210427380,"mc":[{"id":"1.195453769","rc":[{"atb":[[2,46.45]],"id":38240390}],"con":true,"img":false}]}
{"op":"mcm","clk":"5353180624","pt":1646210427485,"mc":[{"id":"1.195453769","rc":[{"atb":[[2.02,61.83]],"id":38240390}],"con":true,"img":false}]}
{"op":"mcm","clk":"5353180629","pt":1646210427586,"mc":[{"id":"1.195453769","rc":[{"atb":[[1.99,0]],"id":38240390}],"con":true,"img":false}]}
{"op":"mcm","clk":"5353181681","pt":1646210447007,"mc":[{"id":"1.195453769","rc":[{"atb":[[2,0]],"id":38240390},{"spn":3.46,"spf":"NaN","id":38240390}],"con":true,"img":false}]}
{"op":"mcm","clk":"5353181686","pt":1646210447109,"mc":[{"id":"1.195453769","rc":[{"atb":[[1.99,147.46],[2.02,0]],"id":38240390}],"con":true,"img":false}]}
{"op":"mcm","clk":"5353183198","pt":1646210474347,"mc":[{"id":"1.195453769","rc":[{"atb":[[1.99,101.01]],"id":38240390}],"con":true,"img":false}]}
{"op":"mcm","clk":"5353183202","pt":1646210474449,"mc":[{"id":"1.195453769","rc":[{"atb":[[2,46.45]],"id":38240390}],"con":true,"img":false}]}
{"op":"mcm","clk":"5353183278","pt":1646210475990,"mc":[{"id":"1.195453769","rc":[{"atb":[[1.99,0],[2.02,61.83]],"id":38240390}],"con":true,"img":false}]}
{"op":"mcm","clk":"5353184216","pt":1646210494076,"mc":[{"id":"1.195453769","rc":[{"atb":[[2,0]],"id":38240390}],"con":true,"img":false}]}
{"op":"mcm","clk":"5353184226","pt":1646210494179,"mc":[{"id":"1.195453769","rc":[{"atb":[[1.99,147.46]],"id":38240390}],"con":true,"img":false}]}
{"op":"mcm","clk":"5353184235","pt":1646210494280,"mc":[{"id":"1.195453769","rc":[{"atb":[[2.02,0]],"id":38240390}],"con":true,"img":false}]}
{"op":"mcm","clk":"5353186510","pt":1646210532924,"mc":[{"id":"1.195453769","rc":[{"atb":[[1.99,101.01]],"id":38240390},{"spn":3.44,"spf":"NaN","id":38240390}],"con":true,"img":false}]}
{"op":"mcm","clk":"5353186517","pt":1646210533027,"mc":[{"id":"1.195453769","rc":[{"atb":[[2,46.45]],"id":38240390}],"con":true,"img":false}]}
{"op":"mcm","clk":"5353186531","pt":1646210533232,"mc":[{"id":"1.195453769","rc":[{"atb":[[1.99,0],[2.02,61.83]],"id":38240390}],"con":true,"img":false}]}
{"op":"mcm","clk":"5353186555","pt":1646210533643,"mc":[{"id":"1.195453769","rc":[{"atb":[[2.04,1.67]],"id":38240390}],"con":true,"img":false}]}
{"op":"mcm","clk":"5353187480","pt":1646210549929,"mc":[{"id":"1.195453769","marketDefinition":{"bspMarket":true,"turnInPlayEnabled":false,"persistenceEnabled":false,"marketBaseRate":7.0,"eventId":"31272499","eventTypeId":"4339","numberOfWinners":2,"bettingType":"ODDS","marketType":"PLACE","marketTime":"2022-03-02T09:27:00.000Z","suspendTime":"2022-03-02T09:27:00.000Z","bspReconciled":false,"complete":true,"inPlay":false,"crossMatching":true,"runnersVoidable":false,"numberOfActiveRunners":5,"betDelay":0,"status":"OPEN","runners":[{"status":"ACTIVE","sortPriority":1,"id":38678129,"name":"2. Blue Jeans Talk"},{"status":"ACTIVE","sortPriority":2,"id":39791031,"name":"4. On The Buses"},{"status":"ACTIVE","sortPriority":3,"id":38240390,"name":"5. Wink At Me"},{"status":"ACTIVE","sortPriority":4,"id":36749619,"name":"7. Love You Peaches"},{"status":"ACTIVE","sortPriority":5,"id":39734310,"name":"8. Canary Wharf"}],"regulators":["MR_INT"],"venue":"Rockhampton","countryCode":"AU","discountAllowed":true,"timezone":"Australia/Queensland","openDate":"2022-03-02T08:28:00.000Z","version":4382601896,"name":"To Be Placed","eventName":"Rockhampton (AUS) 2nd Mar"},"rc":[],"con":true,"img":false}]}
{"op":"mcm","clk":"5353188180","pt":1646210562488,"mc":[{"id":"1.195453769","rc":[{"atb":[[1.65,11.57]],"id":39734310},{"atb":[[2.06,7.09]],"id":38240390},{"atb":[[1.95,7.92]],"id":38678129}],"con":true,"img":false}]}
{"op":"mcm","clk":"5353188333","pt":1646210565685,"mc":[{"id":"1.195453769","rc":[{"atb":[[2,0]],"id":38240390}],"con":true,"img":false}]}
{"op":"mcm","clk":"5353188335","pt":1646210565792,"mc":[{"id":"1.195453769","rc":[{"atb":[[1.99,46.45]],"id":38240390}],"con":true,"img":false}]}
{"op":"mcm","clk":"5353188470","pt":1646210568669,"mc":[{"id":"1.195453769","rc":[{"atb":[[2.04,0]],"id":38240390}],"con":true,"img":false}]}
{"op":"mcm","clk":"5353188474","pt":1646210568773,"mc":[{"id":"1.195453769","rc":[{"atb":[[2.08,1.67]],"id":38240390}],"con":true,"img":false}]}
{"op":"mcm","clk":"5353189413","pt":1646210587620,"mc":[{"id":"1.195453769","rc":[{"atb":[[1.86,0]],"id":38678129}],"con":true,"img":false}]}
{"op":"mcm","clk":"5353189417","pt":1646210587715,"mc":[{"id":"1.195453769","rc":[{"atb":[[1.91,122.33]],"id":38678129}],"con":true,"img":false}]}
{"op":"mcm","clk":"5353190372","pt":1646210603739,"mc":[{"id":"1.195453769","rc":[{"spn":2.21,"spf":"NaN","id":39734310},{"atb":[[1.73,0]],"id":38240390},{"spn":3.49,"spf":"NaN","id":38240390},{"spn":2.97,"spf":"NaN","id":38678129}],"con":true,"img":false}]}
{"op":"mcm","clk":"5353191684","pt":1646210633583,"mc":[{"id":"1.195453769","rc":[{"atb":[[1.89,75.32]],"id":38240390}],"con":true,"img":false}]}
{"op":"mcm","clk":"5353192642","pt":1646210654706,"mc":[{"id":"1.195453769","rc":[{"atl":[[1.73,43.67],[1.75,0]],"id":36749619},{"atl":[[190,2]],"id":39791031}],"con":true,"img":false}]}
{"op":"mcm","clk":"5353192649","pt":1646210654811,"mc":[{"id":"1.195453769","rc":[{"atl":[[2.86,22.28],[2.98,6.11]],"id":39734310},{"atb":[[2.02,0],[2.04,61.83]],"id":38240390},{"atl":[[240,0]],"id":39791031}],"con":true,"img":false}]}
{"op":"mcm","clk":"5353192709","pt":1646210655905,"mc":[{"id":"1.195453769","rc":[{"atb":[[2.06,0]],"id":38240390}],"con":true,"img":false}]}
{"op":"mcm","clk":"5353192933","pt":1646210659925,"mc":[{"id":"1.195453769","rc":[{"atb":[[2.08,0]],"id":38240390}],"con":true,"img":false}]}
{"op":"mcm","clk":"5353192940","pt":1646210660027,"mc":[{"id":"1.195453769","rc":[{"atb":[[2,100],[2.06,1.67]],"id":38240390}],"con":true,"img":false}]}
{"op":"mcm","clk":"5353192946","pt":1646210660131,"mc":[{"id":"1.195453769","rc":[{"atb":[[2.04,0]],"id":38240390}],"con":true,"img":false}]}
{"op":"mcm","clk":"5353193285","pt":1646210667039,"mc":[{"id":"1.195453769","rc":[{"atb":[[2.06,0]],"id":38240390},{"spn":3.45,"spf":"NaN","id":38240390},{"spn":1.43,"spf":"NaN","id":36749619}],"con":true,"img":false}]}
{"op":"mcm","clk":"5353193289","pt":1646210667141,"mc":[{"id":"1.195453769","rc":[{"atb":[[2.02,1.67]],"id":38240390}],"con":true,"img":false}]}
{"op":"mcm","clk":"5353193339","pt":1646210668222,"mc":[{"id":"1.195453769","rc":[{"atb":[[2.04,7.23]],"id":38240390}],"con":true,"img":false}]}
{"op":"mcm","clk":"5353193654","pt":1646210674030,"mc":[{"id":"1.195453769","rc":[{"atb":[[2.02,0]],"id":38240390}],"con":true,"img":false}]}
{"op":"mcm","clk":"5353193660","pt":1646210674239,"mc":[{"id":"1.195453769","rc":[{"atb":[[2.06,1.67]],"id":38240390}],"con":true,"img":false}]}
{"op":"mcm","clk":"5353193708","pt":1646210675233,"mc":[{"id":"1.195453769","rc":[{"atb":[[1.73,91.7],[1.89,0]],"id":38240390}],"con":true,"img":false}]}
{"op":"mcm","clk":"5353194014","pt":1646210681535,"mc":[{"id":"1.195453769","rc":[{"atl":[[2.86,0]],"id":39734310},{"atb":[[2,0],[2.06,8.91]],"id":38240390}],"con":true,"img":false}]}
{"op":"mcm","clk":"5353194021","pt":1646210681639,"mc":[{"id":"1.195453769","rc":[{"atl":[[2.84,22.28]],"id":39734310}],"con":true,"img":false}]}
{"op":"mcm","clk":"5353194512","pt":1646210691351,"mc":[{"id":"1.195453769","rc":[{"atl":[[2.96,0]],"id":39734310},{"atl":[[1.74,0]],"id":36749619}],"con":true,"img":false}]}
{"op":"mcm","clk":"5353194516","pt":1646210691454,"mc":[{"id":"1.195453769","rc":[{"atl":[[2.82,22.28]],"id":39734310},{"atl":[[1.73,0],[1.72,43.66],[2.14,87.34]],"id":36749619}],"con":true,"img":false}]}
{"op":"mcm","clk":"5353195415","pt":1646210709790,"mc":[{"id":"1.195453769","rc":[{"atl":[[1.72,0]],"id":36749619}],"con":true,"img":false}]}
{"op":"mcm","clk":"5353195422","pt":1646210709892,"mc":[{"id":"1.195453769","rc":[{"atl":[[2.12,43.66]],"id":36749619}],"con":true,"img":false}]}
{"op":"mcm","clk":"5353195819","pt":1646210717893,"mc":[{"id":"1.195453769","rc":[{"atl":[[2.14,0],[2.1,43.67]],"id":36749619}],"con":true,"img":false}]}
{"op":"mcm","clk":"5353197227","pt":1646210750232,"mc":[{"id":"1.195453769","rc":[{"spn":3.48,"spf":"NaN","id":38240390},{"atl":[[2.12,0]],"id":36749619},{"spn":1.61,"spf":"NaN","id":36749619}],"con":true,"img":false}]}
{"op":"mcm","clk":"5353197233","pt":1646210750335,"mc":[{"id":"1.195453769","rc":[{"atl":[[2.1,0],[2.14,87.34],[2.08,43.66]],"id":36749619}],"con":true,"img":false}]}
{"op":"mcm","clk":"5353197960","pt":1646210763589,"mc":[{"id":"1.195453769","rc":[{"atb":[[2.04,15.27]],"id":38240390}],"con":true,"img":false}]}
{"op":"mcm","clk":"5353197967","pt":1646210763645,"mc":[{"id":"1.195453769","rc":[{"atb":[[1.95,16.71]],"id":38678129}],"con":true,"img":false}]}
{"op":"mcm","clk":"5353197983","pt":1646210763954,"mc":[{"id":"1.195453769","rc":[{"atb":[[1.65,24.41]],"id":39734310}],"con":true,"img":false}]}
{"op":"mcm","clk":"5353198323","pt":1646210771360,"mc":[{"id":"1.195453769","rc":[{"atl":[[2.08,0]],"id":36749619}],"con":true,"img":false}]}
{"op":"mcm","clk":"5353198329","pt":1646210771463,"mc":[{"id":"1.195453769","rc":[{"atl":[[2.12,43.66]],"id":36749619}],"con":true,"img":false}]}
{"op":"mcm","clk":"5353198592","pt":1646210776173,"mc":[{"id":"1.195453769","rc":[{"atl":[[2.14,0],[2.1,43.67]],"id":36749619}],"con":true,"img":false}]}
{"op":"mcm","clk":"5353199427","pt":1646210793230,"mc":[{"id":"1.195453769","rc":[{"atl":[[2.84,0],[2.98,50.67]],"id":39734310},{"atb":[[2.02,61.83],[2.06,1.67]],"id":38240390}],"con":true,"img":false}]}
{"op":"mcm","clk":"5353199480","pt":1646210794313,"mc":[{"id":"1.195453769","rc":[{"atl":[[2.82,0]],"id":39734310}],"con":true,"img":false}]}
{"op":"mcm","clk":"5353199483","pt":1646210794415,"mc":[{"id":"1.195453769","rc":[{"atl":[[2.96,22.28]],"id":39734310}],"con":true,"img":false}]}
{"op":"mcm","clk":"5353199488","pt":1646210794621,"mc":[{"id":"1.195453769","rc":[{"atb":[[2.04,8.03]],"id":38240390}],"con":true,"img":false}]}
{"op":"mcm","clk":"5353199749","pt":1646210800448,"mc":[{"id":"1.195453769","rc":[{"atb":[[2.06,8.76]],"id":38240390}],"con":true,"img":false}]}
{"op":"mcm","clk":"5353200219","pt":1646210810128,"mc":[{"id":"1.195453769","rc":[{"atb":[[2.04,0]],"id":38240390}],"con":true,"img":false}]}
{"op":"mcm","clk":"5353200698","pt":1646210820463,"mc":[{"id":"1.195453769","rc":[{"atl":[[2.12,0]],"id":36749619}],"con":true,"img":false}]}
{"op":"mcm","clk":"5353200705","pt":1646210820566,"mc":[{"id":"1.195453769","rc":[{"atl":[[2.14,87.34],[2.08,43.66]],"id":36749619}],"con":true,"img":false}]}
{"op":"mcm","clk":"5353200711","pt":1646210820669,"mc":[{"id":"1.195453769","rc":[{"atl":[[2.1,0]],"id":36749619}],"con":true,"img":false}]}
{"op":"mcm","clk":"5353200717","pt":1646210820773,"mc":[{"id":"1.195453769","rc":[{"atl":[[2.06,43.67],[2.14,0]],"id":36749619}],"con":true,"img":false}]}
{"op":"mcm","clk":"5353200780","pt":1646210822170,"mc":[{"id":"1.195453769","rc":[{"atb":[[2.06,16.64]],"id":38240390}],"con":true,"img":false}]}
{"op":"mcm","clk":"5353202779","pt":1646210863307,"mc":[{"id":"1.195453769","rc":[{"atl":[[2.08,0]],"id":36749619}],"con":true,"img":false}]}
{"op":"mcm","clk":"5353202783","pt":1646210863408,"mc":[{"id":"1.195453769","rc":[{"atl":[[2.06,0],[2.04,43.66],[2.14,87.34]],"id":36749619}],"con":true,"img":false}]}
{"op":"mcm","clk":"5353203468","pt":1646210878258,"mc":[{"id":"1.195453769","rc":[{"atl":[[2.04,0]],"id":36749619}],"con":true,"img":false}]}
{"op":"mcm","clk":"5353203475","pt":1646210878361,"mc":[{"id":"1.195453769","rc":[{"atl":[[2.12,43.66]],"id":36749619}],"con":true,"img":false}]}
{"op":"mcm","clk":"5353203943","pt":1646210888157,"mc":[{"id":"1.195453769","rc":[{"atl":[[2.14,0],[2.1,43.67]],"id":36749619}],"con":true,"img":false}]}
{"op":"mcm","clk":"5353205123","pt":1646210914341,"mc":[{"id":"1.195453769","rc":[{"atb":[[1.41,158.29],[1.51,0],[1.61,0]],"id":39734310},{"atl":[[6.4,0],[4.9,0],[9.8,6.99]],"id":38678129},{"atl":[[24,0],[29,0]],"id":39791031}],"con":true,"img":false}]}
{"op":"mcm","clk":"5353205130","pt":1646210914442,"mc":[{"id":"1.195453769","rc":[{"atb":[[1.51,69.31]],"id":39734310},{"atl":[[7.8,8.73]],"id":38678129},{"atl":[[42,2.72],[48,2.72]],"id":39791031}],"con":true,"img":false}]}
{"op":"mcm","clk":"5353205258","pt":1646210917553,"mc":[{"id":"1.195453769","rc":[{"atb":[[1.65,12.84]],"id":39734310}],"con":true,"img":false}]}
{"op":"mcm","clk":"5353205474","pt":1646210923390,"mc":[{"id":"1.195453769","rc":[{"atb":[[1.54,13.93]],"id":39734310}],"con":true,"img":false}]}
{"op":"mcm","clk":"5353205752","pt":1646210930572,"mc":[{"id":"1.195453769","rc":[{"atb":[[1.65,0]],"id":39734310}],"con":true,"img":false}]}
{"op":"mcm","clk":"5353205993","pt":1646210937208,"mc":[{"id":"1.195453769","rc":[{"atl":[[5.8,0]],"id":38240390},{"atb":[[1.91,50.77]],"id":38678129},{"atl":[[2.12,0]],"id":36749619},{"atb":[[8.4,5.9]],"id":39791031}],"con":true,"img":false}]}
{"op":"mcm","clk":"5353205997","pt":1646210937312,"mc":[{"id":"1.195453769","rc":[{"atl":[[5.2,9.09]],"id":38240390},{"atb":[[1.86,71.56]],"id":38678129},{"atl":[[1.78,43.66]],"id":36749619},{"atb":[[4.1,0]],"id":39791031}],"con":true,"img":false}]}
{"op":"mcm","clk":"5353206000","pt":1646210937414,"mc":[{"id":"1.195453769","rc":[{"atl":[[2.14,87.34]],"id":36749619}],"con":true,"img":false}]}
{"op":"mcm","clk":"5353206004","pt":1646210937518,"mc":[{"id":"1.195453769","rc":[{"atl":[[2.1,0]],"id":36749619}],"con":true,"img":false}]}
{"op":"mcm","clk":"5353206208","pt":1646210943931,"mc":[{"id":"1.195453769","rc":[{"atb":[[1.54,29.4]],"id":39734310}],"con":true,"img":false}]}
{"op":"mcm","clk":"5353206765","pt":1646210961343,"mc":[{"id":"1.195453769","rc":[{"spn":2.16,"spf":"NaN","id":39734310},{"atl":[[1.77,43.67],[2.14,0]],"id":36749619},{"spn":1.45,"spf":"NaN","id":36749619},{"spn":22.2,"spf":"NaN","id":39791031}],"con":true,"img":false}]}
{"op":"mcm","clk":"5353207065","pt":1646210970335,"mc":[{"id":"1.195453769","rc":[{"atl":[[3.85,22.37]],"id":39734310},{"atl":[[2,66.59]],"id":36749619},{"atb":[[7,9.73]],"id":39791031}],"con":true,"img":false}]}
{"op":"mcm","clk":"5353207070","pt":1646210970438,"mc":[{"id":"1.195453769","rc":[{"atl":[[4.8,0]],"id":39734310},{"atl":[[2.44,0]],"id":36749619},{"atb":[[3.35,0]],"id":39791031}],"con":true,"img":false}]}
{"op":"mcm","clk":"5353209965","pt":1646211050264,"mc":[{"id":"1.195453769","rc":[{"atb":[[1.41,0]],"id":39734310},{"atb":[[1.86,0]],"id":38678129},{"atl":[[9.8,0],[7.8,0]],"id":38678129},{"atl":[[1.78,0]],"id":36749619}],"con":true,"img":false}]}
{"op":"mcm","clk":"5353209970","pt":1646211050367,"mc":[{"id":"1.195453769","rc":[{"atb":[[1.46,158.29]],"id":39734310},{"atb":[[1.91,122.33]],"id":38678129},{"atl":[[4.9,8.73],[8.4,6.99]],"id":38678129},{"atl":[[1.99,87.34],[1.77,0],[1.76,43.66]],"id":36749619}],"con":true,"img":false}]}
{"op":"mcm","clk":"5353210219","pt":1646211057282,"mc":[{"id":"1.195453769","rc":[{"atl":[[3.85,0],[4.6,16.92]],"id":39734310},{"atl":[[2,0],[2.5,43.12]],"id":36749619},{"atb":[[4.1,14.08],[3.35,24.03],[7,0],[8.4,0]],"id":39791031}],"con":true,"img":false}]}
{"op":"mcm","clk":"5353210707","pt":1646211069087,"mc":[{"id":"1.195453769","rc":[{"atb":[[1.91,50.77]],"id":38678129},{"atl":[[1.76,0]],"id":36749619}],"con":true,"img":false}]}
{"op":"mcm","clk":"5353210711","pt":1646211069191,"mc":[{"id":"1.195453769","rc":[{"atb":[[1.86,71.56]],"id":38678129},{"atl":[[1.99,0],[1.98,43.66],[2.14,87.72]],"id":36749619}],"con":true,"img":false}]}
{"op":"mcm","clk":"5353211722","pt":1646211091839,"mc":[{"id":"1.195453769","rc":[{"atl":[[1.97,43.67],[2.14,0]],"id":36749619}],"con":true,"img":false}]}
{"op":"mcm","clk":"5353212079","pt":1646211101152,"mc":[{"id":"1.195453769","rc":[{"atl":[[1.98,0]],"id":36749619},{"atb":[[8.6,5.74]],"id":39791031}],"con":true,"img":false}]}
{"op":"mcm","clk":"5353212083","pt":1646211101253,"mc":[{"id":"1.195453769","rc":[{"atl":[[1.85,43.66],[2.14,87.34]],"id":36749619},{"atb":[[4.1,0]],"id":39791031}],"con":true,"img":false}]}
{"op":"mcm","clk":"5353212086","pt":1646211101358,"mc":[{"id":"1.195453769","rc":[{"atl":[[1.97,0],[1.84,43.67]],"id":36749619}],"con":true,"img":false}]}
{"op":"mcm","clk":"5353212089","pt":1646211101461,"mc":[{"id":"1.195453769","rc":[{"atl":[[2.14,0]],"id":36749619}],"con":true,"img":false}]}
{"op":"mcm","clk":"5353213696","pt":1646211149006,"mc":[{"id":"1.195453769","rc":[{"atl":[[3.85,22.37],[4.6,0]],"id":39734310},{"atb":[[1.86,0]],"id":38678129},{"atl":[[1.83,79.69],[2.5,0],[1.85,0]],"id":36749619},{"spn":1.48,"spf":"NaN","id":36749619},{"atb":[[3.35,0],[7,9.73]],"id":39791031},{"spn":22.3,"spf":"NaN","id":39791031}],"con":true,"img":false}]}
{"op":"mcm","clk":"5353213701","pt":1646211149108,"mc":[{"id":"1.195453769","rc":[{"atb":[[1.91,122.33]],"id":38678129},{"atl":[[1.83,123.36],[1.82,43.67],[1.84,0]],"id":36749619}],"con":true,"img":false}]}
{"op":"mcm","clk":"5353213972","pt":1646211156719,"mc":[{"id":"1.195453769","rc":[{"atl":[[1.83,43.66]],"id":36749619}],"con":true,"img":false}]}
{"op":"mcm","clk":"5353213976","pt":1646211156821,"mc":[{"id":"1.195453769","rc":[{"atl":[[2,79.69]],"id":36749619}],"con":true,"img":false}]}
{"op":"mcm","clk":"5353215345","pt":1646211189909,"mc":[{"id":"1.195453769","rc":[{"atl":[[1.83,0]],"id":36749619}],"con":true,"img":false}]}
{"op":"mcm","clk":"5353215351","pt":1646211190010,"mc":[{"id":"1.195453769","rc":[{"atl":[[1.82,0],[1.99,87.34],[1.81,43.66]],"id":36749619}],"con":true,"img":false}]}
{"op":"mcm","clk":"5353215601","pt":1646211196735,"mc":[{"id":"1.195453769","rc":[{"atl":[[4.6,16.92]],"id":39734310},{"atl":[[2.5,43.12]],"id":36749619},{"atb":[[4.1,14.08],[3.35,24.03]],"id":39791031}],"con":true,"img":false}]}
{"op":"mcm","clk":"5353215606","pt":1646211196796,"mc":[{"id":"1.195453769","rc":[{"atl":[[3.85,0]],"id":39734310},{"atl":[[2,0]],"id":36749619},{"atb":[[8.6,0],[7,0]],"id":39791031}],"con":true,"img":false}]}
{"op":"mcm","clk":"5353215617","pt":1646211197001,"mc":[{"id":"1.195453769","rc":[{"atl":[[4.9,0]],"id":38678129}],"con":true,"img":false}]}
{"op":"mcm","clk":"5353215620","pt":1646211197101,"mc":[{"id":"1.195453769","rc":[{"atl":[[5.8,8.73]],"id":38678129}],"con":true,"img":false}]}
{"op":"mcm","clk":"5353216217","pt":1646211211440,"mc":[{"id":"1.195453769","rc":[{"atl":[[1.8,43.67]],"id":36749619},{"spn":1.46,"spf":"NaN","id":36749619},{"spn":21.8,"spf":"NaN","id":39791031}],"con":true,"img":false}]}
{"op":"mcm","clk":"5353216226","pt":1646211211545,"mc":[{"id":"1.195453769","rc":[{"atl":[[1.99,0]],"id":36749619}],"con":true,"img":false}]}
{"op":"mcm","clk":"5353216527","pt":1646211217729,"mc":[{"id":"1.195453769","rc":[{"atb":[[1.91,50.77]],"id":38678129},{"atl":[[5.8,0]],"id":38678129}],"con":true,"img":false}]}
{"op":"mcm","clk":"5353216534","pt":1646211217830,"mc":[{"id":"1.195453769","rc":[{"atb":[[1.86,71.56]],"id":38678129},{"atl":[[8,12.19]],"id":38678129}],"con":true,"img":false}]}
{"op":"mcm","clk":"5353217299","pt":1646211237261,"mc":[{"id":"1.195453769","rc":[{"atb":[[4.1,0],[8.8,5.6]],"id":39791031}],"con":true,"img":false}]}
{"op":"mcm","clk":"5353217699","pt":1646211246783,"mc":[{"id":"1.195453769","rc":[{"atl":[[1.81,0]],"id":36749619}],"con":true,"img":false}]}
{"op":"mcm","clk":"5353217703","pt":1646211246889,"mc":[{"id":"1.195453769","rc":[{"atl":[[1.79,43.66],[2.14,87.34]],"id":36749619}],"con":true,"img":false}]}
{"op":"mcm","clk":"5353217710","pt":1646211246993,"mc":[{"id":"1.195453769","rc":[{"atl":[[1.8,0]],"id":36749619}],"con":true,"img":false}]}
{"op":"mcm","clk":"5353217712","pt":1646211247091,"mc":[{"id":"1.195453769","rc":[{"atl":[[1.78,43.67],[2.14,0]],"id":36749619}],"con":true,"img":false}]}
{"op":"mcm","clk":"5353218161","pt":1646211259545,"mc":[{"id":"1.195453769","rc":[{"atl":[[3.9,22.37]],"id":39734310},{"atl":[[8,3.46]],"id":38678129},{"atl":[[2.02,64.95]],"id":36749619}],"con":true,"img":false}]}
{"op":"mcm","clk":"5353218165","pt":1646211259647,"mc":[{"id":"1.195453769","rc":[{"atl":[[4.6,0]],"id":39734310},{"atl":[[4.9,8.73]],"id":38678129},{"atl":[[2.5,0]],"id":36749619}],"con":true,"img":false}]}
{"op":"mcm","clk":"5353218904","pt":1646211275965,"mc":[{"id":"1.195453769","rc":[{"spn":1.45,"spf":"NaN","id":36749619},{"atb":[[7.2,9.73]],"id":39791031},{"spn":22.4,"spf":"NaN","id":39791031}],"con":true,"img":false}]}
{"op":"mcm","clk":"5353218907","pt":1646211276068,"mc":[{"id":"1.195453769","rc":[{"atb":[[1.86,0]],"id":38678129},{"atb":[[3.35,0]],"id":39791031}],"con":true,"img":false}]}
{"op":"mcm","clk":"5353218912","pt":1646211276130,"mc":[{"id":"1.195453769","rc":[{"atb":[[1.91,122.33]],"id":38678129}],"con":true,"img":false}]}
{"op":"mcm","clk":"5353219726","pt":1646211295186,"mc":[{"id":"1.195453769","rc":[{"atl":[[1.79,0]],"id":36749619}],"con":true,"img":false}]}
{"op":"mcm","clk":"5353219729","pt":1646211295286,"mc":[{"id":"1.195453769","rc":[{"atl":[[1.77,43.66]],"id":36749619}],"con":true,"img":false}]}
{"op":"mcm","clk":"5353219731","pt":1646211295383,"mc":[{"id":"1.195453769","rc":[{"atl":[[2,87.34]],"id":36749619}],"con":true,"img":false}]}
{"op":"mcm","clk":"5353219734","pt":1646211295485,"mc":[{"id":"1.195453769","rc":[{"atl":[[1.78,0]],"id":36749619}],"con":true,"img":false}]}
{"op":"mcm","clk":"5353220626","pt":1646211315733,"mc":[{"id":"1.195453769","rc":[{"atl":[[2,0],[1.76,64.96]],"id":36749619}],"con":true,"img":false}]}
{"op":"mcm","clk":"5353221344","pt":1646211333127,"mc":[{"id":"1.195453769","rc":[{"atl":[[4.5,16.92]],"id":39734310},{"atl":[[2.44,43.12]],"id":36749619},{"atb":[[4.1,14.08],[3.3,24.56]],"id":39791031}],"con":true,"img":false}]}
{"op":"mcm","clk":"5353221348","pt":1646211333225,"mc":[{"id":"1.195453769","rc":[{"atl":[[3.9,0]],"id":39734310},{"atl":[[2.02,0]],"id":36749619},{"atb":[[7.2,0],[8.8,0]],"id":39791031}],"con":true,"img":false}]}
{"op":"mcm","clk":"5353221676","pt":1646211340547,"mc":[{"id":"1.195453769","rc":[{"atb":[[1.91,50.77]],"id":38678129},{"spn":1.44,"spf":"NaN","id":36749619},{"spn":21.8,"spf":"NaN","id":39791031}],"con":true,"img":false}]}
{"op":"mcm","clk":"5353221680","pt":1646211340650,"mc":[{"id":"1.195453769","rc":[{"atb":[[1.86,71.56]],"id":38678129}],"con":true,"img":false}]}
{"op":"mcm","clk":"5353222454","pt":1646211358167,"mc":[{"id":"1.195453769","rc":[{"atb":[[1.51,0]],"id":39734310},{"atl":[[1.77,0]],"id":36749619},{"atl":[[42,0]],"id":39791031}],"con":true,"img":false}]}
{"op":"mcm","clk":"5353222458","pt":1646211358269,"mc":[{"id":"1.195453769","rc":[{"atb":[[1.61,69.31]],"id":39734310},{"atl":[[1.75,43.66],[2.14,87.72],[1.76,0]],"id":36749619},{"atl":[[24,2.72]],"id":39791031}],"con":true,"img":false}]}
{"op":"mcm","clk":"5353222468","pt":1646211358375,"mc":[{"id":"1.195453769","rc":[{"atl":[[1.75,87.33]],"id":36749619}],"con":true,"img":false}]}
{"op":"mcm","clk":"5353222474","pt":1646211358477,"mc":[{"id":"1.195453769","rc":[{"atl":[[2.14,0]],"id":36749619}],"con":true,"img":false}]}
{"op":"mcm","clk":"5353222496","pt":1646211358988,"mc":[{"id":"1.195453769","rc":[{"atb":[[1.54,15.46]],"id":39734310}],"con":true,"img":false}]}
{"op":"mcm","clk":"5353222794","pt":1646211364819,"mc":[{"id":"1.195453769","rc":[{"atb":[[1.65,11.57]],"id":39734310}],"con":true,"img":false}]}
{"op":"mcm","clk":"5353223018","pt":1646211369923,"mc":[{"id":"1.195453769","rc":[{"atb":[[1.61,0]],"id":39734310},{"atl":[[24,0]],"id":39791031}],"con":true,"img":false}]}
{"op":"mcm","clk":"5353223022","pt":1646211370022,"mc":[{"id":"1.195453769","rc":[{"atb":[[1.51,69.31]],"id":39734310},{"atl":[[46,2.72]],"id":39791031}],"con":true,"img":false}]}
{"op":"mcm","clk":"5353223066","pt":1646211370905,"mc":[{"id":"1.195453769","rc":[{"atb":[[1.65,0]],"id":39734310}],"con":true,"img":false}]}
{"op":"mcm","clk":"5353223346","pt":1646211376929,"mc":[{"id":"1.195453769","rc":[{"atb":[[1.54,29.4]],"id":39734310}],"con":true,"img":false}]}
{"op":"mcm","clk":"5353224047","pt":1646211392549,"mc":[{"id":"1.195453769","rc":[{"atb":[[8.6,5.74],[4.1,0]],"id":39791031}],"con":true,"img":false}]}
{"op":"mcm","clk":"5353224418","pt":1646211400549,"mc":[{"id":"1.195453769","rc":[{"atb":[[1.86,0]],"id":38678129},{"spn":1.44,"spf":"NaN","id":36749619},{"spn":22.3,"spf":"NaN","id":39791031}],"con":true,"img":false}]}
{"op":"mcm","clk":"5353224426","pt":1646211400653,"mc":[{"id":"1.195453769","rc":[{"atb":[[1.91,122.33]],"id":38678129}],"con":true,"img":false}]}
{"op":"mcm","clk":"5353225386","pt":1646211422183,"mc":[{"id":"1.195453769","rc":[{"atb":[[1.18,111.11],[1.12,250],[1.16,250],[1.14,250]],"id":39734310},{"atl":[[2.56,32.05],[2.52,13.16],[2.6,46.88],[2.64,76.22]],"id":39734310},{"atb":[[1.82,91.46],[1.8,156.25],[1.84,59.52],[1.86,23.26]],"id":38240390},{"atl":[[8.2,17.36],[7.4,7.81],[7,15.54],[7.8,14.59]],"id":38240390},{"atb":[[1.72,27.78],[1.7,71.43],[1.68,110.29],[1.66,189.39]],"id":38678129},{"atl":[[3.2,22.73],[3.1,9.52],[3.4,52.08],[3.3,32.61]],"id":38678129},{"atb":[[1.12,719.07],[1.06,2269.65],[1.1,250],[1.08,250]],"id":36749619},{"atl":[[1.67,74.63],[1.65,30.77],[1.71,176.06],[1.69,108.7]],"id":36749619},{"atb":[[3.85,17.54],[3.95,6.78],[3.75,45.63],[3.65,47.17]],"id":39791031},{"atl":[[70,1],[80,1],[90,1.4],[60,1]],"id":39791031}],"con":true,"img":false}]}
{"op":"mcm","clk":"5353225402","pt":1646211422502,"mc":[{"id":"1.195453769","rc":[{"atl":[[3.85,22.92]],"id":39734310},{"atb":[[1.91,50.77]],"id":38678129},{"atl":[[2,66.59]],"id":36749619},{"atb":[[6.8,9.73]],"id":39791031}],"con":true,"img":false}]}
{"op":"mcm","clk":"5353225407","pt":1646211422594,"mc":[{"id":"1.195453769","rc":[{"atl":[[4.5,0]],"id":39734310},{"atb":[[1.86,71.56]],"id":38678129},{"atl":[[2.44,0]],"id":36749619},{"atb":[[3.3,0]],"id":39791031}],"con":true,"img":false}]}
{"op":"mcm","clk":"5353225661","pt":1646211427511,"mc":[{"id":"1.195453769","rc":[{"atb":[[1.86,0],[1.71,86.68]],"id":38678129}],"con":true,"img":false}]}
{"op":"mcm","clk":"5353225669","pt":1646211427613,"mc":[{"id":"1.195453769","rc":[{"atl":[[5.2,0]],"id":38240390},{"atl":[[48,0]],"id":39791031}],"con":true,"img":false}]}
{"op":"mcm","clk":"5353225676","pt":1646211427713,"mc":[{"id":"1.195453769","rc":[{"atl":[[5.6,9.09]],"id":38240390},{"atl":[[50,2.72]],"id":39791031}],"con":true,"img":false}]}
{"op":"mcm","clk":"5353226372","pt":1646211442627,"mc":[{"id":"1.195453769","rc":[{"atb":[[1.13,0]],"id":36749619}],"con":true,"img":false}]}
{"op":"mcm","clk":"5353226375","pt":1646211442728,"mc":[{"id":"1.195453769","rc":[{"atb":[[1.14,99.93]],"id":36749619}],"con":true,"img":false}]}
{"op":"mcm","clk":"5353226585","pt":1646211447521,"mc":[{"id":"1.195453769","rc":[{"atl":[[2.96,0]],"id":39734310},{"atl":[[3.25,19.41]],"id":38678129},{"atl":[[1.75,43.67]],"id":36749619},{"atb":[[8.6,0]],"id":39791031}],"con":true,"img":false}]}
{"op":"mcm","clk":"5353226588","pt":1646211447624,"mc":[{"id":"1.195453769","rc":[{"atl":[[2.58,22.28]],"id":39734310},{"atl":[[4.9,0]],"id":38678129},{"atl":[[1.66,43.66]],"id":36749619},{"atb":[[11,5.74]],"id":39791031}],"con":true,"img":false}]}
{"op":"mcm","clk":"5353227035","pt":1646211457529,"mc":[{"id":"1.195453769","rc":[{"atb":[[1.73,0],[1.89,75.32]],"id":38240390}],"con":true,"img":false}]}
{"op":"mcm","clk":"5353227503","pt":1646211467548,"mc":[{"id":"1.195453769","rc":[{"atb":[[1.46,0],[1.51,196.49]],"id":39734310},{"atl":[[3.85,0]],"id":39734310},{"spn":2.03,"spf":"NaN","id":39734310},{"atl":[[4.5,17.58],[8.4,0]],"id":38678129},{"spn":2.52,"spf":"NaN","id":38678129},{"atl":[[2,0],[1.7,94.97]],"id":36749619},{"spn":1.39,"spf":"NaN","id":36749619},{"spn":23.5,"spf":"NaN","id":39791031}],"con":true,"img":false}]}
{"op":"mcm","clk":"5353227510","pt":1646211467651,"mc":[{"id":"1.195453769","rc":[{"atl":[[3.5,22.92]],"id":39734310}],"con":true,"img":false}]}
{"op":"mcm","clk":"5353227738","pt":1646211472473,"mc":[{"id":"1.195453769","rc":[{"atb":[[9.2,6.88]],"id":39791031}],"con":true,"img":false}]}
{"op":"mcm","clk":"5353227744","pt":1646211472580,"mc":[{"id":"1.195453769","rc":[{"atb":[[6.8,0]],"id":39791031}],"con":true,"img":false}]}
{"op":"mcm","clk":"5353228725","pt":1646211492593,"mc":[{"id":"1.195453769","rc":[{"atl":[[2.58,0]],"id":39734310}],"con":true,"img":false}]}
{"op":"mcm","clk":"5353228730","pt":1646211492696,"mc":[{"id":"1.195453769","rc":[{"atl":[[2.54,22.28]],"id":39734310}],"con":true,"img":false}]}
{"op":"mcm","clk":"5353246919","pt":1646211807443,"mc":[{"id":"1.195453769","rc":[{"atb":[[1.4,302.46],[1.45,268.85],[1.54,29.36],[1.5,120.98],[1.51,196.18]],"id":39734310},{"atl":[[3.45,9.87],[2.54,22.24],[3.95,8.2],[4.9,12.4],[2.98,6.1],[2.78,6.79],[3.5,22.88]],"id":39734310},{"atb":[[1.99,46.38],[2.02,0],[2.06,16.61],[1.98,61.73],[1.89,75.2],[1.88,137.48],[1.93,130.09],[2.08,46.46]],"id":38240390},{"atl":[[5.6,9.08],[6.4,12.53],[4.9,3.1],[9.8,2.75],[7.8,14.58],[5.9,2.46],[14.5,3.58]],"id":38240390},{"spn":3.49,"spf":"NaN","id":38240390},{"atb":[[1.8,151.23],[1.85,142.34],[1.91,50.69],[1.9,67.21],[1.95,16.69],[1.71,86.54]],"id":38678129},{"atl":[[4,4.03],[8,3.45],[4.5,17.55],[5,11.75],[10,5.37],[6,4.83],[3.25,19.37]],"id":38678129},{"atb":[[1.12,718.19],[1.01,12098.75],[1.11,549.94],[1.14,99.78],[1.06,2266.45]],"id":36749619},{"atl":[[1.7,94.82],[2.76,13.75],[2.36,8.89],[2.56,15.51],[1.88,113.64],[1.66,43.59],[1.75,0],[2.96,24.69],[2.16,10.43]],"id":36749619},{"atb":[[9.2,6.87],[5.8,25.2],[11,5.73],[7.6,9.16],[6.6,21.6]],"id":39791031},{"atl":[[130,2.18],[34,1],[36,0.34],[46,2.72],[190,0],[50,2.72],[230,0.1],[60,0],[65,0.19],[330,0.14]],"id":39791031},{"spn":22.5,"spf":"NaN","id":39791031}],"con":true,"img":false}]}
{"op":"mcm","clk":"5353246925","pt":1646211807549,"mc":[{"id":"1.195453769","rc":[{"atl":[[3.4,41.67]],"id":39734310}],"con":true,"img":false}]}
{"op":"mcm","clk":"5353246931","pt":1646211807649,"mc":[{"id":"1.195453769","rc":[{"atl":[[3.05,44.5],[3.4,0]],"id":39734310}],"con":true,"img":false}]}
{"op":"mcm","clk":"5353247057","pt":1646211810040,"mc":[{"id":"1.195453769","rc":[{"atb":[[2.06,9.52]],"id":38240390}],"con":true,"img":false}]}
{"op":"mcm","clk":"5353247174","pt":1646211812457,"mc":[{"id":"1.195453769","rc":[{"atl":[[50,0]],"id":39791031}],"con":true,"img":false}]}
{"op":"mcm","clk":"5353247178","pt":1646211812557,"mc":[{"id":"1.195453769","rc":[{"atl":[[55,2.72]],"id":39791031}],"con":true,"img":false}]}
{"op":"mcm","clk":"5353247304","pt":1646211814572,"mc":[{"id":"1.195453769","rc":[{"atb":[[2.06,7.86]],"id":38240390}],"con":true,"img":false}]}
{"op":"mcm","clk":"5353247316","pt":1646211814735,"mc":[{"id":"1.195453769","rc":[{"atb":[[2.1,1.66]],"id":38240390}],"con":true,"img":false}]}
{"op":"mcm","clk":"5353247389","pt":1646211815965,"mc":[{"id":"1.195453769","rc":[{"atb":[[2.12,6.71]],"id":38240390}],"con":true,"img":false}]}
{"op":"mcm","clk":"5353247483","pt":1646211817465,"mc":[{"id":"1.195453769","rc":[{"atl":[[38,1.35]],"id":39791031}],"con":true,"img":false}]}
{"op":"mcm","clk":"5353247704","pt":1646211821588,"mc":[{"id":"1.195453769","rc":[{"atb":[[2.1,0]],"id":38240390}],"con":true,"img":false}]}
{"op":"mcm","clk":"5353247713","pt":1646211821748,"mc":[{"id":"1.195453769","rc":[{"atb":[[2.14,1.66]],"id":38240390}],"con":true,"img":false}]}
{"op":"mcm","clk":"5353247772","pt":1646211822685,"mc":[{"id":"1.195453769","rc":[{"atb":[[2.08,0]],"id":38240390}],"con":true,"img":false}]}
{"op":"mcm","clk":"5353247778","pt":1646211822787,"mc":[{"id":"1.195453769","rc":[{"atb":[[2.14,8.37]],"id":38240390},{"atl":[[1.74,135.14],[1.88,0]],"id":36749619}],"con":true,"img":false}]}
{"op":"mcm","clk":"5353247912","pt":1646211824857,"mc":[{"id":"1.195453769","rc":[{"atb":[[2.12,0]],"id":38240390}],"con":true,"img":false}]}
{"op":"mcm","clk":"5353247977","pt":1646211826089,"mc":[{"id":"1.195453769","rc":[{"atb":[[2.06,0]],"id":38240390}],"con":true,"img":false}]}
{"op":"mcm","clk":"5353248057","pt":1646211827477,"mc":[{"id":"1.195453769","rc":[{"atl":[[42,1.83],[90,0]],"id":39791031}],"con":true,"img":false}]}
{"op":"mcm","clk":"5353248273","pt":1646211830992,"mc":[{"id":"1.195453769","rc":[{"atb":[[2.04,7.23]],"id":38240390}],"con":true,"img":false}]}
{"op":"mcm","clk":"5353248375","pt":1646211832599,"mc":[{"id":"1.195453769","rc":[{"atl":[[2.54,0]],"id":39734310}],"con":true,"img":false}]}
{"op":"mcm","clk":"5353248383","pt":1646211832700,"mc":[{"id":"1.195453769","rc":[{"atl":[[2.58,22.24]],"id":39734310}],"con":true,"img":false}]}
{"op":"mcm","clk":"5353248651","pt":1646211837489,"mc":[{"id":"1.195453769","rc":[{"atb":[[9.2,0],[11,0]],"id":39791031},{"atl":[[80,0],[46,5.5]],"id":39791031}],"con":true,"img":false}]}
{"op":"mcm","clk":"5353248656","pt":1646211837594,"mc":[{"id":"1.195453769","rc":[{"atb":[[9.6,5.73],[8,6.87]],"id":39791031}],"con":true,"img":false}]}
{"op":"mcm","clk":"5353248662","pt":1646211837696,"mc":[{"id":"1.195453769","rc":[{"atb":[[2.04,15.25]],"id":38240390}],"con":true,"img":false}]}
{"op":"mcm","clk":"5353249161","pt":1646211847533,"mc":[{"id":"1.195453769","rc":[{"atl":[[70,0]],"id":39791031}],"con":true,"img":false}]}
{"op":"mcm","clk":"5353249571","pt":1646211854721,"mc":[{"id":"1.195453769","rc":[{"atl":[[4.5,46.12],[5,3.02]],"id":38678129},{"atl":[[1.65,0],[1.66,73.89]],"id":36749619},{"atl":[[34,0],[30,1]],"id":39791031}],"con":true,"img":false}]}
{"op":"mcm","clk":"5353249718","pt":1646211857545,"mc":[{"id":"1.195453769","rc":[{"atl":[[46,2.78]],"id":39791031}],"con":true,"img":false}]}
{"op":"mcm","clk":"5353249723","pt":1646211857648,"mc":[{"id":"1.195453769","rc":[{"atl":[[38,4.07]],"id":39791031}],"con":true,"img":false}]}
{"op":"mcm","clk":"5353250073","pt":1646211864749,"mc":[{"id":"1.195453769","rc":[{"atl":[[1.68,73.53]],"id":36749619},{"atl":[[34,1.52]],"id":39791031}],"con":true,"img":false}]}
{"op":"mcm","clk":"5353250539","pt":1646211872940,"mc":[{"id":"1.195453769","rc":[{"spn":3.52,"spf":"NaN","id":38240390},{"atl":[[1.68,0],[1.66,43.59],[1.65,30.77]],"id":36749619},{"spn":19.8,"spf":"NaN","id":39791031}],"con":true,"img":false}]}
{"op":"mcm","clk":"5353250544","pt":1646211873044,"mc":[{"id":"1.195453769","rc":[{"atl":[[46,0],[30,0]],"id":39791031}],"con":true,"img":false}]}
{"op":"mcm","clk":"5353250626","pt":1646211874739,"mc":[{"id":"1.195453769","rc":[{"atl":[[46,2.78]],"id":39791031}],"con":true,"img":false}]}
{"op":"mcm","clk":"5353250771","pt":1646211877471,"mc":[{"id":"1.195453769","rc":[{"atl":[[55,0]],"id":39791031}],"con":true,"img":false}]}
{"op":"mcm","clk":"5353250776","pt":1646211877572,"mc":[{"id":"1.195453769","rc":[{"atl":[[40,2.72]],"id":39791031}],"con":true,"img":false}]}
{"op":"mcm","clk":"5353252148","pt":1646211902508,"mc":[{"id":"1.195453769","rc":[{"atl":[[2.58,0]],"id":39734310}],"con":true,"img":false}]}
{"op":"mcm","clk":"5353252155","pt":1646211902607,"mc":[{"id":"1.195453769","rc":[{"atl":[[2.54,22.24]],"id":39734310}],"con":true,"img":false}]}
{"op":"mcm","clk":"5353257765","pt":1646211993001,"mc":[{"id":"1.195453769","rc":[{"atb":[[2.14,1.66],[2.1,46.38]],"id":38240390},{"atb":[[1.07,0],[1.04,2500]],"id":36749619},{"atl":[[1.81,123.46],[1.74,0]],"id":36749619},{"spn":21.8,"spf":"NaN","id":39791031}],"con":true,"img":false}]}
{"op":"mcm","clk":"5353257793","pt":1646211993464,"mc":[{"id":"1.195453769","rc":[{"atb":[[2.04,8.01]],"id":38240390}],"con":true,"img":false}]}
{"op":"mcm","clk":"5353257808","pt":1646211993669,"mc":[{"id":"1.195453769","rc":[{"atb":[[2.14,0]],"id":38240390}],"con":true,"img":false}]}
{"op":"mcm","clk":"5353257821","pt":1646211993875,"mc":[{"id":"1.195453769","rc":[{"atb":[[2.12,1.66]],"id":38240390}],"con":true,"img":false}]}
{"op":"mcm","clk":"5353258174","pt":1646211999381,"mc":[{"id":"1.195453769","rc":[{"atb":[[2.14,6.59]],"id":38240390}],"con":true,"img":false}]}
{"op":"mcm","clk":"5353258314","pt":1646212001594,"mc":[{"id":"1.195453769","rc":[{"atb":[[2.12,0]],"id":38240390}],"con":true,"img":false}]}
{"op":"mcm","clk":"5353258323","pt":1646212001698,"mc":[{"id":"1.195453769","rc":[{"atb":[[2.16,1.66]],"id":38240390}],"con":true,"img":false}]}
{"op":"mcm","clk":"5353258704","pt":1646212007623,"mc":[{"id":"1.195453769","rc":[{"atb":[[2.1,0],[2.16,8.25]],"id":38240390},{"atb":[[1.06,3933.12],[1.04,0]],"id":36749619},{"atl":[[1.81,0],[1.74,135.14]],"id":36749619}],"con":true,"img":false}]}
{"op":"mcm","clk":"5353258743","pt":1646212008186,"mc":[{"id":"1.195453769","rc":[{"atl":[[8.2,0],[7.4,0],[7,12.21],[7.8,3.55],[9.4,14.28]],"id":38240390},{"atb":[[1.7,0],[1.68,0],[1.72,0],[1.27,74.07],[1.66,0],[1.17,173.08]],"id":38678129},{"atl":[[2.32,15.15],[1.74,0]],"id":36749619},{"atb":[[5.1,4.88],[5,18.34],[3.95,0],[3.75,27.27]],"id":39791031}],"con":true,"img":false}]}
{"op":"mcm","clk":"5353258750","pt":1646212008289,"mc":[{"id":"1.195453769","rc":[{"atl":[[7,0]],"id":38240390},{"atb":[[1.62,0]],"id":38678129},{"atl":[[2.32,90.91],[1.67,0],[1.65,0],[1.71,0],[1.69,0]],"id":36749619}],"con":true,"img":false}]}
{"op":"mcm","clk":"5353258757","pt":1646212008394,"mc":[{"id":"1.195453769","rc":[{"atb":[[2.14,0]],"id":38240390}],"con":true,"img":false}]}
{"op":"mcm","clk":"5353258982","pt":1646212012512,"mc":[{"id":"1.195453769","rc":[{"atl":[[1.7,0]],"id":36749619}],"con":true,"img":false}]}
{"op":"mcm","clk":"5353258989","pt":1646212012618,"mc":[{"id":"1.195453769","rc":[{"atb":[[1.71,0]],"id":38678129}],"con":true,"img":false}]}
{"op":"mcm","clk":"5353258995","pt":1646212012720,"mc":[{"id":"1.195453769","rc":[{"atb":[[1.62,86.54]],"id":38678129}],"con":true,"img":false}]}
{"op":"mcm","clk":"5353259104","pt":1646212014550,"mc":[{"id":"1.195453769","rc":[{"atb":[[2.04,15.25]],"id":38240390}],"con":true,"img":false}]}
{"op":"mcm","clk":"5353259354","pt":1646212018224,"mc":[{"id":"1.195453769","rc":[{"atl":[[9.8,8.43]],"id":38240390},{"atb":[[1.25,200]],"id":38678129},{"atl":[[2.36,45.65]],"id":36749619},{"atb":[[4.9,12.82]],"id":39791031}],"con":true,"img":false}]}
{"op":"mcm","clk":"5353259767","pt":1646212024851,"mc":[{"id":"1.195453769","rc":[{"atb":[[3.65,0]],"id":39791031}],"con":true,"img":false}]}
{"op":"mcm","clk":"5353259964","pt":1646212028257,"mc":[{"id":"1.195453769","rc":[{"atl":[[10.5,7.89]],"id":38240390},{"atb":[[1.23,250]],"id":38678129},{"atl":[[2.4,53.57]],"id":36749619},{"atb":[[4.7,20.27]],"id":39791031}],"con":true,"img":false}]}
{"op":"mcm","clk":"5353260198","pt":1646212032440,"mc":[{"id":"1.195453769","rc":[{"atl":[[3.25,0]],"id":38678129}],"con":true,"img":false}]}
{"op":"mcm","clk":"5353260204","pt":1646212032543,"mc":[{"id":"1.195453769","rc":[{"atl":[[3.15,19.37]],"id":38678129},{"atl":[[1.86,76.84]],"id":36749619}],"con":true,"img":false}]}
{"op":"mcm","clk":"5353260502","pt":1646212037442,"mc":[{"id":"1.195453769","rc":[{"atl":[[1.66,0]],"id":36749619}],"con":true,"img":false}]}
{"op":"mcm","clk":"5353260512","pt":1646212037546,"mc":[{"id":"1.195453769","rc":[{"atl":[[1.72,43.59]],"id":36749619}],"con":true,"img":false}]}
{"op":"mcm","clk":"5353260548","pt":1646212038267,"mc":[{"id":"1.195453769","rc":[{"atl":[[11.5,11.9]],"id":38240390},{"atb":[[1.21,250]],"id":38678129},{"atl":[[2.44,86.81]],"id":36749619},{"atb":[[4.5,35.71],[3.75,0]],"id":39791031}],"con":true,"img":false}]}
{"op":"mcm","clk":"5353261114","pt":1646212048254,"mc":[{"id":"1.195453769","rc":[{"atb":[[3.85,0]],"id":39791031}],"con":true,"img":false}]}
{"op":"mcm","clk":"5353262344","pt":1646212067500,"mc":[{"id":"1.195453769","rc":[{"spn":3.53,"spf":"NaN","id":38240390},{"atl":[[1.86,0]],"id":36749619},{"spn":1.43,"spf":"NaN","id":36749619}],"con":true,"img":false}]}
{"op":"mcm","clk":"5353262349","pt":1646212067601,"mc":[{"id":"1.195453769","rc":[{"atl":[[1.94,76.84]],"id":36749619}],"con":true,"img":false}]}
{"op":"mcm","clk":"5353262641","pt":1646212072531,"mc":[{"id":"1.195453769","rc":[{"atl":[[1.72,0]],"id":36749619}],"con":true,"img":false}]}
{"op":"mcm","clk":"5353262648","pt":1646212072634,"mc":[{"id":"1.195453769","rc":[{"atl":[[1.79,43.59]],"id":36749619}],"con":true,"img":false}]}
{"op":"mcm","clk":"5353263237","pt":1646212082456,"mc":[{"id":"1.195453769","rc":[{"atb":[[8,9.72]],"id":39791031}],"con":true,"img":false}]}
{"op":"mcm","clk":"5353263540","pt":1646212087468,"mc":[{"id":"1.195453769","rc":[{"atb":[[8,0]],"id":39791031}],"con":true,"img":false}]}
{"op":"mcm","clk":"5353263545","pt":1646212087571,"mc":[{"id":"1.195453769","rc":[{"atb":[[7.2,9.72]],"id":39791031}],"con":true,"img":false}]}
{"op":"mcm","clk":"5353263883","pt":1646212093578,"mc":[{"id":"1.195453769","rc":[{"atb":[[1.55,20.54]],"id":39734310},{"atb":[[1.92,18.36]],"id":38678129},{"atb":[[1.15,69.84]],"id":36749619}],"con":true,"img":false}]}
{"op":"mcm","clk":"5353265329","pt":1646212116905,"mc":[{"id":"1.195453769","rc":[{"atb":[[2.06,46.38],[2.16,1.66]],"id":38240390},{"atl":[[34,0],[30,1]],"id":39791031}],"con":true,"img":false}]}
{"op":"mcm","clk":"5353265359","pt":1646212117329,"mc":[{"id":"1.195453769","rc":[{"atb":[[2.04,8.01]],"id":38240390}],"con":true,"img":false}]}
{"op":"mcm","clk":"5353265423","pt":1646212117998,"mc":[{"id":"1.195453769","rc":[{"atb":[[2.06,0],[2.16,9.68]],"id":38240390},{"atl":[[32,1],[30,0]],"id":39791031}],"con":true,"img":false}]}
{"op":"mcm","clk":"5353265753","pt":1646212122502,"mc":[{"id":"1.195453769","rc":[{"atl":[[1.94,0]],"id":36749619}],"con":true,"img":false}]}
{"op":"mcm","clk":"5353265758","pt":1646212122606,"mc":[{"id":"1.195453769","rc":[{"atl":[[2.02,76.84]],"id":36749619}],"con":true,"img":false}]}
{"op":"mcm","clk":"5353265976","pt":1646212126342,"mc":[{"id":"1.195453769","rc":[{"atb":[[2.04,15.25]],"id":38240390}],"con":true,"img":false}]}
{"op":"mcm","clk":"5353266633","pt":1646212137572,"mc":[{"id":"1.195453769","rc":[{"spn":2.03,"spf":"NaN","id":39734310},{"atl":[[1.79,0]],"id":36749619},{"spn":1.58,"spf":"NaN","id":36749619},{"spn":20.8,"spf":"NaN","id":39791031}],"con":true,"img":false}]}
{"op":"mcm","clk":"5353266637","pt":1646212137615,"mc":[{"id":"1.195453769","rc":[{"atl":[[1.88,43.59]],"id":36749619}],"con":true,"img":false}]}
{"op":"mcm","clk":"5353268807","pt":1646212177632,"mc":[{"id":"1.195453769","rc":[{"atb":[[9.6,0]],"id":39791031}],"con":true,"img":false}]}
{"op":"mcm","clk":"5353268820","pt":1646212177732,"mc":[{"id":"1.195453769","rc":[{"atb":[[8.6,5.73]],"id":39791031}],"con":true,"img":false}]}
{"op":"mcm","clk":"5353270269","pt":1646212202550,"mc":[{"id":"1.195453769","rc":[{"atl":[[2.02,0],[2.12,58.85]],"id":36749619},{"spn":1.51,"spf":"NaN","id":36749619},{"spn":20.3,"spf":"NaN","id":39791031}],"con":true,"img":false}]}
{"op":"mcm","clk":"5353270776","pt":1646212212574,"mc":[{"id":"1.195453769","rc":[{"atl":[[6.4,0]],"id":38240390}],"con":true,"img":false}]}
{"op":"mcm","clk":"5353270783","pt":1646212212665,"mc":[{"id":"1.195453769","rc":[{"atl":[[6.8,12.53]],"id":38240390}],"con":true,"img":false}]}
{"op":"mcm","clk":"5353273385","pt":1646212260135,"mc":[{"id":"1.195453769","rc":[{"atb":[[1.83,24.1]],"id":38240390},{"atl":[[3.2,0],[3.1,0],[3.25,8.89]],"id":38678129}],"con":true,"img":false}]}
{"op":"mcm","clk":"5353273390","pt":1646212260234,"mc":[{"id":"1.195453769","rc":[{"atb":[[1.84,0],[1.86,0]],"id":38240390}],"con":true,"img":false}]}
{"op":"mcm","clk":"5353273793","pt":1646212267592,"mc":[{"id":"1.195453769","rc":[{"atl":[[3.15,0]],"id":38678129},{"spn":2.6,"spf":"NaN","id":38678129}],"con":true,"img":false}]}
{"op":"mcm","clk":"5353273801","pt":1646212267694,"mc":[{"id":"1.195453769","rc":[{"atl":[[3.25,28.26]],"id":38678129}],"con":true,"img":false}]}
{"op":"mcm","clk":"5353273955","pt":1646212270181,"mc":[{"id":"1.195453769","rc":[{"atb":[[1.81,61.73]],"id":38240390},{"atl":[[3.35,21.28]],"id":38678129}],"con":true,"img":false}]}
{"op":"mcm","clk":"5353274501","pt":1646212280206,"mc":[{"id":"1.195453769","rc":[{"atb":[[1.79,94.94]],"id":38240390},{"atl":[[3.45,30.61]],"id":38678129}],"con":true,"img":false}]}
{"op":"mcm","clk":"5353275061","pt":1646212290177,"mc":[{"id":"1.195453769","rc":[{"atb":[[1.82,0],[1.8,0],[1.77,162.34]],"id":38240390},{"atl":[[3.4,0],[3.55,49.02],[3.3,0]],"id":38678129}],"con":true,"img":false}]}
{"op":"mcm","clk":"5353275545","pt":1646212297536,"mc":[{"id":"1.195453769","rc":[{"atl":[[3.25,8.89]],"id":38678129},{"atl":[[1.88,0]],"id":36749619}],"con":true,"img":false}]}
{"op":"mcm","clk":"5353275553","pt":1646212297588,"mc":[{"id":"1.195453769","rc":[{"atl":[[3.3,19.37]],"id":38678129},{"atl":[[1.98,43.59]],"id":36749619}],"con":true,"img":false}]}
{"op":"mcm","clk":"5353275649","pt":1646212299233,"mc":[{"id":"1.195453769","rc":[{"atb":[[2.16,1.66],[2.14,46.38]],"id":38240390},{"atl":[[32,0],[34,1]],"id":39791031}],"con":true,"img":false}]}
{"op":"mcm","clk":"5353275681","pt":1646212299797,"mc":[{"id":"1.195453769","rc":[{"atb":[[2.04,8.01]],"id":38240390}],"con":true,"img":false}]}
{"op":"mcm","clk":"5353275717","pt":1646212300414,"mc":[{"id":"1.195453769","rc":[{"atb":[[1.18,0],[1.16,125]],"id":39734310},{"atb":[[1.83,0],[1.86,23.26]],"id":38240390}],"con":true,"img":false}]}
{"op":"mcm","clk":"5353275748","pt":1646212300930,"mc":[{"id":"1.195453769","rc":[{"atb":[[2.04,0]],"id":38240390}],"con":true,"img":false}]}
{"op":"mcm","clk":"5353275826","pt":1646212302015,"mc":[{"id":"1.195453769","rc":[{"atb":[[1.18,111.11]],"id":39734310},{"atb":[[1.83,24.1],[1.86,0]],"id":38240390},{"atl":[[3.1,9.52],[3.25,0]],"id":38678129}],"con":true,"img":false}]}
{"op":"mcm","clk":"5353275872","pt":1646212302734,"mc":[{"id":"1.195453769","rc":[{"atl":[[4.9,11.33],[9.4,0]],"id":38240390},{"atl":[[2.32,75.76],[2.42,14.08]],"id":36749619},{"atb":[[5.1,0],[5.4,4.55]],"id":39791031}],"con":true,"img":false}]}
{"op":"mcm","clk":"5353275880","pt":1646212302837,"mc":[{"id":"1.195453769","rc":[{"atl":[[5.5,9.08],[4.9,8.23]],"id":38240390}],"con":true,"img":false}]}
{"op":"mcm","clk":"5353275889","pt":1646212302940,"mc":[{"id":"1.195453769","rc":[{"atl":[[4.9,17.31]],"id":38240390},{"atl":[[2.36,8.89]],"id":36749619}],"con":true,"img":false}]}
{"op":"mcm","clk":"5353275896","pt":1646212303042,"mc":[{"id":"1.195453769","rc":[{"atl":[[5.5,0]],"id":38240390}],"con":true,"img":false}]}
{"op":"mcm","clk":"5353276075","pt":1646212305730,"mc":[{"id":"1.195453769","rc":[{"atb":[[2.18,6.36]],"id":38240390}],"con":true,"img":false}]}
{"op":"mcm","clk":"5353276155","pt":1646212307026,"mc":[{"id":"1.195453769","rc":[{"atl":[[2.4,0]],"id":36749619}],"con":true,"img":false}]}
{"op":"mcm","clk":"5353276198","pt":1646212307543,"mc":[{"id":"1.195453769","rc":[{"atl":[[5.6,0]],"id":38240390}],"con":true,"img":false}]}
{"op":"mcm","clk":"5353276205","pt":1646212307646,"mc":[{"id":"1.195453769","rc":[{"atl":[[6.6,9.08]],"id":38240390}],"con":true,"img":false}]}
{"op":"mcm","clk":"5353276223","pt":1646212307955,"mc":[{"id":"1.195453769","rc":[{"atb":[[2.16,0]],"id":38240390}],"con":true,"img":false}]}
{"op":"mcm","clk":"5353276228","pt":1646212308005,"mc":[{"id":"1.195453769","rc":[{"atb":[[2.2,1.66]],"id":38240390}],"con":true,"img":false}]}
{"op":"mcm","clk":"5353276454","pt":1646212312016,"mc":[{"id":"1.195453769","rc":[{"atb":[[1.16,250]],"id":39734310},{"atl":[[3.2,22.73]],"id":38678129}],"con":true,"img":false}]}
{"op":"mcm","clk":"5353276491","pt":1646212312737,"mc":[{"id":"1.195453769","rc":[{"atl":[[5.1,12.2]],"id":38240390},{"atl":[[2.46,34.25]],"id":36749619},{"atb":[[5.2,11.9]],"id":39791031}],"con":true,"img":false}]}
{"op":"mcm","clk":"5353276584","pt":1646212314450,"mc":[{"id":"1.195453769","rc":[{"atb":[[2.18,13.42]],"id":38240390}],"con":true,"img":false}]}
{"op":"mcm","clk":"5353276988","pt":1646212322052,"mc":[{"id":"1.195453769","rc":[{"atl":[[3.45,0],[3.35,0],[3.55,0],[3.3,51.98]],"id":38678129}],"con":true,"img":false}]}
{"op":"mcm","clk":"5353277030","pt":1646212322776,"mc":[{"id":"1.195453769","rc":[{"atl":[[5.3,17.44],[11.5,0]],"id":38240390},{"atl":[[2.5,50]],"id":36749619},{"atb":[[4.5,0],[5,37.09],[4.9,0],[4.7,0]],"id":39791031}],"con":true,"img":false}]}
{"op":"mcm","clk":"5353277046","pt":1646212322982,"mc":[{"id":"1.195453769","rc":[{"atl":[[4.5,4]],"id":38240390},{"atl":[[2.26,2]],"id":36749619}],"con":true,"img":false}]}
{"op":"mcm","clk":"5353277068","pt":1646212323448,"mc":[{"id":"1.195453769","rc":[{"atb":[[1.18,0],[1.16,125]],"id":39734310},{"atl":[[2.36,3]],"id":39734310},{"atb":[[1.83,0],[1.86,23.26]],"id":38240390},{"atl":[[4.5,0],[10.5,0]],"id":38240390},{"atb":[[1.33,3]],"id":38678129},{"atl":[[3.2,0],[3.1,0],[3.25,8.89]],"id":38678129},{"atl":[[2.24,3]],"id":36749619}],"con":true,"img":false}]}
{"op":"mcm","clk":"5353277075","pt":1646212323548,"mc":[{"id":"1.195453769","rc":[{"atl":[[2.34,3]],"id":39734310}],"con":true,"img":false}]}
{"op":"mcm","clk":"5353277081","pt":1646212323650,"mc":[{"id":"1.195453769","rc":[{"atb":[[1.34,2]],"id":38678129}],"con":true,"img":false}]}
{"op":"mcm","clk":"5353277236","pt":1646212326185,"mc":[{"id":"1.195453769","rc":[{"atb":[[1.55,0]],"id":39734310}],"con":true,"img":false}]}
{"op":"mcm","clk":"5353277295","pt":1646212327267,"mc":[{"id":"1.195453769","rc":[{"atl":[[2.32,3]],"id":39734310},{"atb":[[1.35,4]],"id":38678129},{"atl":[[2.22,3]],"id":36749619}],"con":true,"img":false}]}
{"op":"mcm","clk":"5353277307","pt":1646212327473,"mc":[{"id":"1.195453769","rc":[{"atl":[[2.36,0]],"id":39734310}],"con":true,"img":false}]}
{"op":"mcm","clk":"5353277375","pt":1646212328659,"mc":[{"id":"1.195453769","rc":[{"atb":[[1.55,20.54]],"id":39734310},{"spn":1.93,"spf":"NaN","id":39734310},{"spn":3.55,"spf":"NaN","id":38240390},{"spn":1.56,"spf":"NaN","id":36749619},{"spn":21.3,"spf":"NaN","id":39791031}],"con":true,"img":false}]}
{"op":"mcm","clk":"5353277599","pt":1646212332778,"mc":[{"id":"1.195453769","rc":[{"atl":[[2.54,81.17]],"id":36749619},{"atb":[[4.8,32.89]],"id":39791031}],"con":true,"img":false}]}
{"op":"mcm","clk":"5353277642","pt":1646212333504,"mc":[{"id":"1.195453769","rc":[{"atb":[[1.1,250]],"id":39734310},{"atb":[[1.84,59.52]],"id":38240390},{"atl":[[5.5,27.78]],"id":38240390},{"atl":[[3.35,21.28]],"id":38678129}],"con":true,"img":false}]}
{"op":"mcm","clk":"5353277652","pt":1646212333658,"mc":[{"id":"1.195453769","rc":[{"atl":[[2.3,4]],"id":39734310}],"con":true,"img":false}]}
{"op":"mcm","clk":"5353277658","pt":1646212333762,"mc":[{"id":"1.195453769","rc":[{"atb":[[1.79,0],[1.81,0],[1.77,0]],"id":38240390},{"atl":[[9.8,2.75]],"id":38240390},{"atb":[[1.36,2]],"id":38678129},{"atl":[[2.44,0],[2.2,3]],"id":36749619}],"con":true,"img":false}]}
{"op":"mcm","clk":"5353277664","pt":1646212333862,"mc":[{"id":"1.195453769","rc":[{"atl":[[2.34,0]],"id":39734310}],"con":true,"img":false}]}
{"op":"mcm","clk":"5353277710","pt":1646212334792,"mc":[{"id":"1.195453769","rc":[{"atl":[[2.32,0],[2.28,2]],"id":39734310}],"con":true,"img":false}]}
{"op":"mcm","clk":"5353277798","pt":1646212336486,"mc":[{"id":"1.195453769","rc":[{"atb":[[1.55,0]],"id":39734310}],"con":true,"img":false}]}
{"op":"mcm","clk":"5353277861","pt":1646212337565,"mc":[{"id":"1.195453769","rc":[{"atl":[[6.6,0]],"id":38240390}],"con":true,"img":false}]}
{"op":"mcm","clk":"5353277869","pt":1646212337670,"mc":[{"id":"1.195453769","rc":[{"atl":[[4.8,9.08]],"id":38240390}],"con":true,"img":false}]}
{"op":"mcm","clk":"5353278028","pt":1646212340809,"mc":[{"id":"1.195453769","rc":[{"atb":[[1.55,20.54]],"id":39734310}],"con":true,"img":false}]}
{"op":"mcm","clk":"5353278149","pt":1646212342611,"mc":[{"id":"1.195453769","rc":[{"atl":[[2.26,3]],"id":39734310}],"con":true,"img":false}]}
{"op":"mcm","clk":"5353278163","pt":1646212342817,"mc":[{"id":"1.195453769","rc":[{"atl":[[2.3,0],[2.24,4]],"id":39734310}],"con":true,"img":false}]}
{"op":"mcm","clk":"5353278204","pt":1646212343485,"mc":[{"id":"1.195453769","rc":[{"atb":[[1.82,91.46]],"id":38240390},{"atl":[[3.45,30.61]],"id":38678129}],"con":true,"img":false}]}
{"op":"mcm","clk":"5353278367","pt":1646212346789,"mc":[{"id":"1.195453769","rc":[{"atb":[[1.55,0]],"id":39734310}],"con":true,"img":false}]}
{"op":"mcm","clk":"5353278419","pt":1646212347618,"mc":[{"id":"1.195453769","rc":[{"atl":[[2.22,2]],"id":39734310},{"atl":[[32,1],[34,0]],"id":39791031}],"con":true,"img":false}]}
{"op":"mcm","clk":"5353278577","pt":1646212350817,"mc":[{"id":"1.195453769","rc":[{"atb":[[1.55,20.54]],"id":39734310}],"con":true,"img":false}]}
{"op":"mcm","clk":"5353278582","pt":1646212350917,"mc":[{"id":"1.195453769","rc":[{"atl":[[2.3,2]],"id":39734310}],"con":true,"img":false}]}
{"op":"mcm","clk":"5353278586","pt":1646212351019,"mc":[{"id":"1.195453769","rc":[{"atl":[[2.22,0]],"id":39734310}],"con":true,"img":false}]}
{"op":"mcm","clk":"5353278735","pt":1646212353508,"mc":[{"id":"1.195453769","rc":[{"atb":[[1.8,156.25]],"id":38240390},{"atl":[[3.55,49.02]],"id":38678129}],"con":true,"img":false}]}
{"op":"mcm","clk":"5353278742","pt":1646212353618,"mc":[{"id":"1.195453769","rc":[{"atl":[[2.32,4],[2.24,0]],"id":39734310},{"atl":[[3.3,19.37]],"id":38678129}],"con":true,"img":false}]}
{"op":"mcm","clk":"5353278994","pt":1646212355591,"mc":[{"id":"1.195453769","rc":[{"atl":[[2.34,4]],"id":39734310}],"con":true,"img":false}]}
{"op":"mcm","clk":"5353279001","pt":1646212355697,"mc":[{"id":"1.195453769","rc":[{"atl":[[2.26,0]],"id":39734310}],"con":true,"img":false}]}
{"op":"mcm","clk":"5353279050","pt":1646212356521,"mc":[{"id":"1.195453769","rc":[{"atl":[[2.26,2],[2.34,0]],"id":39734310}],"con":true,"img":false}]}
{"op":"mcm","clk":"5353279060","pt":1646212356623,"mc":[{"id":"1.195453769","rc":[{"atb":[[1.55,0]],"id":39734310}],"con":true,"img":false}]}
{"op":"mcm","clk":"5353279112","pt":1646212357400,"mc":[{"id":"1.195453769","rc":[{"atl":[[2.32,0],[2.24,4]],"id":39734310}],"con":true,"img":false}]}
{"op":"mcm","clk":"5353279125","pt":1646212357605,"mc":[{"id":"1.195453769","rc":[{"atl":[[2.32,2]],"id":39734310}],"con":true,"img":false}]}
{"op":"mcm","clk":"5353279128","pt":1646212357709,"mc":[{"id":"1.195453769","rc":[{"atl":[[2.24,0]],"id":39734310}],"con":true,"img":false}]}
{"op":"mcm","clk":"5353279224","pt":1646212359306,"mc":[{"id":"1.195453769","rc":[{"atb":[[1.18,111.11],[1.16,0]],"id":39734310},{"atl":[[2.3,0],[2.32,0],[2.26,0],[2.28,0]],"id":39734310},{"atb":[[1.83,24.1],[1.84,0],[1.86,0]],"id":38240390},{"atl":[[4.5,2]],"id":38240390},{"atb":[[1.33,0],[1.34,0],[1.35,0],[1.36,0]],"id":38678129},{"atl":[[3.1,9.52],[3.25,0]],"id":38678129}],"con":true,"img":false}]}
{"op":"mcm","clk":"5353279228","pt":1646212359411,"mc":[{"id":"1.195453769","rc":[{"atl":[[2.22,0],[2.26,0],[2.24,0],[2.2,0],[2.16,13.43]],"id":36749619}],"con":true,"img":false}]}
{"op":"mcm","clk":"5353279243","pt":1646212359718,"mc":[{"id":"1.195453769","rc":[{"atl":[[4.5,0],[4.3,2]],"id":38240390},{"atl":[[2.14,4]],"id":36749619}],"con":true,"img":false}]}
{"op":"mcm","clk":"5353279253","pt":1646212359922,"mc":[{"id":"1.195453769","rc":[{"atl":[[4.2,3]],"id":38240390}],"con":true,"img":false}]}
{"op":"mcm","clk":"5353279257","pt":1646212360028,"mc":[{"id":"1.195453769","rc":[{"atl":[[2.12,60.85]],"id":36749619}],"con":true,"img":false}]}
{"op":"mcm","clk":"5353279260","pt":1646212360130,"mc":[{"id":"1.195453769","rc":[{"atl":[[4.1,3]],"id":38240390},{"atl":[[2.1,3]],"id":36749619}],"con":true,"img":false}]}
{"op":"mcm","clk":"5353279292","pt":1646212360644,"mc":[{"id":"1.195453769","rc":[{"atl":[[4,2]],"id":38240390}],"con":true,"img":false}]}
{"op":"mcm","clk":"5353279306","pt":1646212360801,"mc":[{"id":"1.195453769","rc":[{"atb":[[1.55,20.54]],"id":39734310}],"con":true,"img":false}]}
{"op":"mcm","clk":"5353279322","pt":1646212361115,"mc":[{"id":"1.195453769","rc":[{"atl":[[6.8,0],[5.2,15.8]],"id":38240390}],"con":true,"img":false}]}
{"op":"mcm","clk":"5353279453","pt":1646212363125,"mc":[{"id":"1.195453769","rc":[{"atl":[[40,0]],"id":39791031}],"con":true,"img":false}]}
{"op":"mcm","clk":"5353279461","pt":1646212363227,"mc":[{"id":"1.195453769","rc":[{"atl":[[36,3.06]],"id":39791031}],"con":true,"img":false}]}
{"op":"mcm","clk":"5353279540","pt":1646212364256,"mc":[{"id":"1.195453769","rc":[{"atb":[[2.12,61.73]],"id":38240390},{"atl":[[4,0],[4.5,3],[4.1,0]],"id":38240390},{"atl":[[2.26,4]],"id":36749619}],"con":true,"img":false}]}
{"op":"mcm","clk":"5353279548","pt":1646212364362,"mc":[{"id":"1.195453769","rc":[{"atb":[[2.14,0]],"id":38240390},{"atl":[[2.12,58.85],[2.1,0],[2.14,0],[2.16,10.43]],"id":36749619}],"con":true,"img":false}]}
{"op":"mcm","clk":"5353279577","pt":1646212364728,"mc":[{"id":"1.195453769","rc":[{"atl":[[4.4,2]],"id":38240390},{"atl":[[2.26,0],[2.24,4]],"id":36749619}],"con":true,"img":false}]}
{"op":"mcm","clk":"5353279601","pt":1646212365037,"mc":[{"id":"1.195453769","rc":[{"atl":[[2.24,0]],"id":36749619}],"con":true,"img":false}]}
{"op":"mcm","clk":"5353279667","pt":1646212365915,"mc":[{"id":"1.195453769","rc":[{"atb":[[2.18,7.06]],"id":38240390}],"con":true,"img":false}]}
{"op":"mcm","clk":"5353279844","pt":1646212369358,"mc":[{"id":"1.195453769","rc":[{"atb":[[1.16,250]],"id":39734310},{"atb":[[1.81,61.73]],"id":38240390},{"atl":[[3.2,22.73]],"id":38678129}],"con":true,"img":false}]}
{"op":"mcm","clk":"5353279855","pt":1646212369518,"mc":[{"id":"1.195453769","rc":[{"atb":[[1.1,0]],"id":39734310}],"con":true,"img":false}]}
{"op":"mcm","clk":"5353279869","pt":1646212369728,"mc":[{"id":"1.195453769","rc":[{"atl":[[3.45,0],[3.35,0],[3.55,0]],"id":38678129}],"con":true,"img":false}]}
{"op":"mcm","clk":"5353279991","pt":1646212371848,"mc":[{"id":"1.195453769","rc":[{"atb":[[2.16,6.48]],"id":38240390}],"con":true,"img":false}]}
{"op":"mcm","clk":"5353280417","pt":1646212379330,"mc":[{"id":"1.195453769","rc":[{"atb":[[1.79,94.94]],"id":38240390},{"atl":[[3.3,51.98]],"id":38678129}],"con":true,"img":false}]}
{"op":"mcm","clk":"5353280510","pt":1646212380836,"mc":[{"id":"1.195453769","rc":[{"atb":[[2.1,61.73],[1.82,0],[1.8,0]],"id":38240390}],"con":true,"img":false}]}
{"op":"mcm","clk":"5353280516","pt":1646212380940,"mc":[{"id":"1.195453769","rc":[{"atb":[[2.12,0]],"id":38240390}],"con":true,"img":false}]}
{"op":"mcm","clk":"5353280687","pt":1646212383676,"mc":[{"id":"1.195453769","rc":[{"atb":[[1.4,0],[1.45,0],[1.5,0]],"id":39734310},{"atl":[[3.45,0],[3.95,0],[4.9,0],[2.98,0],[2.78,0]],"id":39734310},{"atb":[[1.98,0],[1.88,0],[1.93,0]],"id":38240390},{"atl":[[4.9,14.21],[7.8,0],[5.9,0],[14.5,0],[9.8,0]],"id":38240390},{"atb":[[1.8,0],[1.85,0],[1.9,0]],"id":38678129},{"atl":[[4,0],[8,0],[5,0],[10,0],[6,0]],"id":38678129},{"atb":[[1.01,0],[1.11,0],[1.06,1916.67]],"id":36749619},{"atl":[[2.36,0],[2.56,0],[2.96,0],[2.16,0],[2.76,0]],"id":36749619},{"atb":[[5.8,0],[7.6,0],[6.6,0]],"id":39791031},{"atl":[[65,0],[130,2],[36,2.72],[330,0],[230,0]],"id":39791031}],"con":true,"img":false}]}
{"op":"mcm","clk":"5353280703","pt":1646212383932,"mc":[{"id":"1.195453769","rc":[{"atb":[[2.16,0]],"id":38240390}],"con":true,"img":false}]}
{"op":"mcm","clk":"5353280772","pt":1646212385171,"mc":[{"id":"1.195453769","rc":[{"atb":[[1.51,69.2]],"id":39734310},{"atb":[[1.89,0]],"id":38240390},{"atl":[[36,0]],"id":39791031}],"con":true,"img":false}]}
{"op":"mcm","clk":"5353280778","pt":1646212385276,"mc":[{"id":"1.195453769","rc":[{"atb":[[1.44,126.98]],"id":39734310},{"atb":[[1.84,75.2]],"id":38240390},{"atl":[[40,2.72]],"id":39791031}],"con":true,"img":false}]}
{"op":"mcm","clk":"5353280916","pt":1646212387563,"mc":[{"id":"1.195453769","rc":[{"atb":[[1.4,302.46],[1.45,268.85],[1.5,120.98]],"id":39734310},{"atl":[[3.45,9.87],[3.95,8.2],[4.9,12.4],[2.98,6.1],[2.78,6.79]],"id":39734310},{"atb":[[1.98,61.73],[1.88,137.48],[1.93,130.09]],"id":38240390},{"atl":[[4.9,17.31],[7.8,3.55],[5.9,2.46],[14.5,3.58],[9.8,2.75]],"id":38240390},{"atb":[[1.8,151.23],[1.85,142.34],[1.9,67.21]],"id":38678129},{"atl":[[4,4.03],[8,3.45],[5,3.02],[10,5.37],[6,4.83]],"id":38678129},{"atb":[[1.01,12098.75],[1.11,549.94],[1.06,3933.12]],"id":36749619},{"atl":[[2.36,8.89],[2.56,15.51],[2.96,24.69],[2.16,10.43],[2.76,13.75]],"id":36749619},{"atb":[[5.8,25.2],[7.6,9.16],[6.6,21.6]],"id":39791031},{"atl":[[130,2.18],[65,0.19],[36,0.34],[330,0.14],[230,0.1]],"id":39791031}],"con":true,"img":false}]}
{"op":"mcm","clk":"5353281013","pt":1646212389262,"mc":[{"id":"1.195453769","rc":[{"spn":2.03,"spf":"NaN","id":39734310},{"atl":[[4.3,0],[4.4,0],[4.5,0],[4.2,0]],"id":38240390},{"spn":3.5,"spf":"NaN","id":38240390},{"spn":2.52,"spf":"NaN","id":38678129},{"spn":20.3,"spf":"NaN","id":39791031}],"con":true,"img":false}]}
{"op":"mcm","clk":"5353281023","pt":1646212389364,"mc":[{"id":"1.195453769","rc":[{"atb":[[1.77,162.34]],"id":38240390},{"atl":[[3.4,52.08]],"id":38678129}],"con":true,"img":false}]}
{"op":"mcm","clk":"5353281057","pt":1646212389877,"mc":[{"id":"1.195453769","rc":[{"atb":[[2.14,6.59]],"id":38240390}],"con":true,"img":false}]}
{"op":"mcm","clk":"5353281130","pt":1646212391074,"mc":[{"id":"1.195453769","rc":[{"atb":[[2.12,61.73],[2.1,0]],"id":38240390}],"con":true,"img":false}]}
{"op":"mcm","clk":"5353281137","pt":1646212391171,"mc":[{"id":"1.195453769","rc":[{"atl":[[3.3,32.61]],"id":38678129}],"con":true,"img":false}]}
{"op":"mcm","clk":"5353281146","pt":1646212391274,"mc":[{"id":"1.195453769","rc":[{"atl":[[3.15,19.37]],"id":38678129}],"con":true,"img":false}]}
{"op":"mcm","clk":"5353281200","pt":1646212392100,"mc":[{"id":"1.195453769","rc":[{"atb":[[2.18,0]],"id":38240390}],"con":true,"img":false}]}
{"op":"mcm","clk":"5353281277","pt":1646212392986,"mc":[{"id":"1.195453769","rc":[{"atb":[[2.14,0]],"id":38240390}],"con":true,"img":false}]}
{"op":"mcm","clk":"5353281461","pt":1646212395976,"mc":[{"id":"1.195453769","rc":[{"atb":[[2.2,0]],"id":38240390}],"con":true,"img":false}]}
{"op":"mcm","clk":"5353281467","pt":1646212396075,"mc":[{"id":"1.195453769","rc":[{"atb":[[2,100]],"id":38240390}],"con":true,"img":false}]}
{"op":"mcm","clk":"5353281473","pt":1646212396185,"mc":[{"id":"1.195453769","rc":[{"atb":[[2.12,0],[2.14,1.66]],"id":38240390}],"con":true,"img":false}]}
{"op":"mcm","clk":"5353281479","pt":1646212396287,"mc":[{"id":"1.195453769","rc":[{"atb":[[2.12,61.73]],"id":38240390}],"con":true,"img":false}]}
{"op":"mcm","clk":"5353281484","pt":1646212396390,"mc":[{"id":"1.195453769","rc":[{"atb":[[2,0]],"id":38240390}],"con":true,"img":false}]}
{"op":"mcm","clk":"5353281556","pt":1646212397677,"mc":[{"id":"1.195453769","rc":[{"atl":[[2.58,12.66],[2.52,0]],"id":39734310}],"con":true,"img":false}]}
{"op":"mcm","clk":"5353281580","pt":1646212398089,"mc":[{"id":"1.195453769","rc":[{"atl":[[2.56,0]],"id":39734310}],"con":true,"img":false}]}
{"op":"mcm","clk":"5353281626","pt":1646212398910,"mc":[{"id":"1.195453769","rc":[{"atb":[[2.16,6.48]],"id":38240390}],"con":true,"img":false}]}
{"op":"mcm","clk":"5353281756","pt":1646212401184,"mc":[{"id":"1.195453769","rc":[{"atb":[[1.55,0]],"id":39734310}],"con":true,"img":false}]}
{"op":"mcm","clk":"5353281889","pt":1646212402900,"mc":[{"id":"1.195453769","rc":[{"atb":[[2.14,0]],"id":38240390}],"con":true,"img":false}]}
{"op":"mcm","clk":"5353281896","pt":1646212403005,"mc":[{"id":"1.195453769","rc":[{"atb":[[2.18,1.66]],"id":38240390}],"con":true,"img":false}]}
{"op":"mcm","clk":"5353282010","pt":1646212405374,"mc":[{"id":"1.195453769","rc":[{"atb":[[1.55,20.54]],"id":39734310}],"con":true,"img":false}]}
{"op":"mcm","clk":"5353282100","pt":1646212407078,"mc":[{"id":"1.195453769","rc":[{"atl":[[2.54,0]],"id":39734310}],"con":true,"img":false}]}
{"op":"mcm","clk":"5353282106","pt":1646212407182,"mc":[{"id":"1.195453769","rc":[{"atl":[[2.58,34.9]],"id":39734310}],"con":true,"img":false}]}
{"op":"mcm","clk":"5353282138","pt":1646212407730,"mc":[{"id":"1.195453769","rc":[{"atl":[[2.62,30.86]],"id":39734310}],"con":true,"img":false}]}
{"op":"mcm","clk":"5353282317","pt":1646212410721,"mc":[{"id":"1.195453769","rc":[{"atl":[[2.52,13.16]],"id":39734310}],"con":true,"img":false}]}
{"op":"mcm","clk":"5353282325","pt":1646212410829,"mc":[{"id":"1.195453769","rc":[{"atl":[[2.58,22.24]],"id":39734310}],"con":true,"img":false}]}
{"op":"mcm","clk":"5353282476","pt":1646212413203,"mc":[{"id":"1.195453769","rc":[{"atb":[[1.55,0]],"id":39734310}],"con":true,"img":false}]}
{"op":"mcm","clk":"5353282633","pt":1646212416192,"mc":[{"id":"1.195453769","rc":[{"atb":[[2.16,13.66]],"id":38240390}],"con":true,"img":false}]}
{"op":"mcm","clk":"5353282682","pt":1646212417117,"mc":[{"id":"1.195453769","rc":[{"atb":[[1.55,20.54]],"id":39734310},{"atb":[[1.14,0]],"id":36749619}],"con":true,"img":false}]}
{"op":"mcm","clk":"5353282687","pt":1646212417220,"mc":[{"id":"1.195453769","rc":[{"atb":[[1.16,99.78]],"id":36749619}],"con":true,"img":false}]}
{"op":"mcm","clk":"5353282896","pt":1646212420744,"mc":[{"id":"1.195453769","rc":[{"atl":[[2.56,32.05]],"id":39734310}],"con":true,"img":false}]}
{"op":"mcm","clk":"5353282902","pt":1646212420846,"mc":[{"id":"1.195453769","rc":[{"atb":[[1.84,0],[1.62,107.9]],"id":38240390},{"atb":[[1.15,0]],"id":36749619}],"con":true,"img":false}]}
{"op":"mcm","clk":"5353282927","pt":1646212421202,"mc":[{"id":"1.195453769","rc":[{"atb":[[1.16,0]],"id":36749619}],"con":true,"img":false}]}
{"op":"mcm","clk":"5353282938","pt":1646212421310,"mc":[{"id":"1.195453769","rc":[{"atb":[[1.15,99.78]],"id":36749619}],"con":true,"img":false}]}
{"op":"mcm","clk":"5353283042","pt":1646212422803,"mc":[{"id":"1.195453769","rc":[{"atb":[[1.55,0]],"id":39734310}],"con":true,"img":false}]}
{"op":"mcm","clk":"5353283151","pt":1646212425116,"mc":[{"id":"1.195453769","rc":[{"atb":[[1.16,69.84]],"id":36749619}],"con":true,"img":false}]}
{"op":"mcm","clk":"5353283193","pt":1646212426044,"mc":[{"id":"1.195453769","rc":[{"atl":[[2.62,0]],"id":39734310}],"con":true,"img":false}]}
{"op":"mcm","clk":"5353283249","pt":1646212427129,"mc":[{"id":"1.195453769","rc":[{"atb":[[1.55,20.54]],"id":39734310},{"atb":[[1.99,0]],"id":38240390},{"atl":[[4.8,0]],"id":38240390}],"con":true,"img":false}]}
{"op":"mcm","clk":"5353283256","pt":1646212427227,"mc":[{"id":"1.195453769","rc":[{"atb":[[1.82,46.38]],"id":38240390},{"atl":[[5.3,26.52]],"id":38240390}],"con":true,"img":false}]}
{"op":"mcm","clk":"5353283365","pt":1646212429137,"mc":[{"id":"1.195453769","rc":[{"atb":[[1.44,0]],"id":39734310}],"con":true,"img":false}]}
{"op":"mcm","clk":"5353283369","pt":1646212429241,"mc":[{"id":"1.195453769","rc":[{"atb":[[1.51,196.18]],"id":39734310}],"con":true,"img":false}]}
{"op":"mcm","clk":"5353284085","pt":1646212441141,"mc":[{"id":"1.195453769","rc":[{"atl":[[2.58,0]],"id":39734310}],"con":true,"img":false}]}
{"op":"mcm","clk":"5353284095","pt":1646212441246,"mc":[{"id":"1.195453769","rc":[{"atl":[[2.54,22.24]],"id":39734310}],"con":true,"img":false}]}
{"op":"mcm","clk":"5353284292","pt":1646212444483,"mc":[{"id":"1.195453769","rc":[{"atb":[[1.55,0]],"id":39734310}],"con":true,"img":false}]}
{"op":"mcm","clk":"5353284536","pt":1646212448351,"mc":[{"id":"1.195453769","rc":[{"atb":[[1.55,20.54]],"id":39734310}],"con":true,"img":false}]}
{"op":"mcm","clk":"5353284583","pt":1646212449180,"mc":[{"id":"1.195453769","rc":[{"atb":[[1.15,0]],"id":36749619}],"con":true,"img":false}]}
{"op":"mcm","clk":"5353284589","pt":1646212449276,"mc":[{"id":"1.195453769","rc":[{"spn":3.54,"spf":"NaN","id":38240390},{"atb":[[1.17,99.78]],"id":36749619},{"spn":1.57,"spf":"NaN","id":36749619}],"con":true,"img":false}]}
{"op":"mcm","clk":"5353284820","pt":1646212452464,"mc":[{"id":"1.195453769","rc":[{"atb":[[1.16,0]],"id":36749619}],"con":true,"img":false}]}
{"op":"mcm","clk":"5353284866","pt":1646212453179,"mc":[{"id":"1.195453769","rc":[{"atb":[[1.17,0]],"id":36749619}],"con":true,"img":false}]}
{"op":"mcm","clk":"5353284871","pt":1646212453285,"mc":[{"id":"1.195453769","rc":[{"atb":[[1.15,99.78]],"id":36749619}],"con":true,"img":false}]}
{"op":"mcm","clk":"5353285087","pt":1646212456575,"mc":[{"id":"1.195453769","rc":[{"atb":[[1.16,69.84]],"id":36749619}],"con":true,"img":false}]}
{"op":"mcm","clk":"5353285128","pt":1646212457188,"mc":[{"id":"1.195453769","rc":[{"atb":[[1.82,0]],"id":38240390}],"con":true,"img":false}]}
{"op":"mcm","clk":"5353285134","pt":1646212457291,"mc":[{"id":"1.195453769","rc":[{"atb":[[1.99,46.38]],"id":38240390}],"con":true,"img":false}]}
{"op":"mcm","clk":"5353285830","pt":1646212469172,"mc":[{"id":"1.195453769","rc":[{"atl":[[5.3,17.44]],"id":38240390}],"con":true,"img":false}]}
{"op":"mcm","clk":"5353285836","pt":1646212469276,"mc":[{"id":"1.195453769","rc":[{"atl":[[4.8,9.08]],"id":38240390}],"con":true,"img":false}]}
{"op":"mcm","clk":"5353286354","pt":1646212479120,"mc":[{"id":"1.195453769","rc":[{"atb":[[1.89,75.2],[1.62,0]],"id":38240390}],"con":true,"img":false}]}
{"op":"mcm","clk":"5353286364","pt":1646212479227,"mc":[{"id":"1.195453769","rc":[{"atb":[[1.15,0]],"id":36749619}],"con":true,"img":false}]}
{"op":"mcm","clk":"5353286372","pt":1646212479326,"mc":[{"id":"1.195453769","rc":[{"atb":[[1.17,99.78]],"id":36749619}],"con":true,"img":false}]}
{"op":"mcm","clk":"5353286498","pt":1646212481744,"mc":[{"id":"1.195453769","rc":[{"atb":[[1.16,0]],"id":36749619}],"con":true,"img":false}]}
{"op":"mcm","clk":"5353286577","pt":1646212483240,"mc":[{"id":"1.195453769","rc":[{"atb":[[1.17,0]],"id":36749619}],"con":true,"img":false}]}
{"op":"mcm","clk":"5353286582","pt":1646212483341,"mc":[{"id":"1.195453769","rc":[{"atb":[[1.14,99.78]],"id":36749619}],"con":true,"img":false}]}
{"op":"mcm","clk":"5353286599","pt":1646212483547,"mc":[{"id":"1.195453769","rc":[{"atl":[[2.26,4]],"id":36749619}],"con":true,"img":false}]}
{"op":"mcm","clk":"5353286645","pt":1646212484219,"mc":[{"id":"1.195453769","rc":[{"atb":[[1.18,0],[1.16,125]],"id":39734310},{"atl":[[2.46,4]],"id":39734310},{"atb":[[1.83,0],[1.86,23.26]],"id":38240390},{"atb":[[1.33,3]],"id":38678129},{"atl":[[3.2,0],[3.1,0],[3.25,8.89]],"id":38678129},{"atl":[[2.26,0],[2.24,4]],"id":36749619}],"con":true,"img":false}]}
{"op":"mcm","clk":"5353286652","pt":1646212484423,"mc":[{"id":"1.195453769","rc":[{"atl":[[2.44,4],[2.46,0]],"id":39734310},{"atb":[[1.34,3]],"id":38678129}],"con":true,"img":false}]}
{"op":"mcm","clk":"5353286691","pt":1646212485243,"mc":[{"id":"1.195453769","rc":[{"atl":[[2.42,3]],"id":39734310},{"atb":[[1.35,3]],"id":38678129}],"con":true,"img":false}]}
{"op":"mcm","clk":"5353286711","pt":1646212485553,"mc":[{"id":"1.195453769","rc":[{"atl":[[2.54,35.23],[2.4,2],[2.52,0]],"id":39734310},{"atb":[[2.12,0],[2.16,60.04]],"id":38240390},{"atb":[[1.36,2]],"id":38678129},{"atl":[[2.24,0]],"id":36749619},{"atl":[[32,0],[34,1]],"id":39791031}],"con":true,"img":false}]}
{"op":"mcm","clk":"5353286719","pt":1646212485713,"mc":[{"id":"1.195453769","rc":[{"atb":[[1.18,111.11]],"id":39734310},{"atl":[[2.44,0],[2.4,0],[2.42,0],[2.38,4]],"id":39734310},{"atb":[[1.83,24.1],[1.86,0]],"id":38240390},{"atb":[[1.33,0],[1.34,0],[1.35,0],[1.36,0]],"id":38678129},{"atl":[[3.1,9.52]],"id":38678129},{"atb":[[1.15,69.84]],"id":36749619},{"atl":[[2.26,2]],"id":36749619}],"con":true,"img":false}]}
{"op":"mcm","clk":"5353286729","pt":1646212485917,"mc":[{"id":"1.195453769","rc":[{"atl":[[2.38,0]],"id":39734310}],"con":true,"img":false}]}
{"op":"mcm","clk":"5353286741","pt":1646212486222,"mc":[{"id":"1.195453769","rc":[{"atb":[[2.16,53.56]],"id":38240390},{"atl":[[2.26,0]],"id":36749619}],"con":true,"img":false}]}
{"op":"mcm","clk":"5353286761","pt":1646212486530,"mc":[{"id":"1.195453769","rc":[{"atb":[[1.18,0],[1.21,317.18],[1.54,66.4],[1.08,0]],"id":39734310},{"atb":[[1.41,48.78],[1.83,0],[1.79,0],[1.81,0],[1.77,0],[2.16,7.18]],"id":38240390},{"atl":[[4.9,3.1],[3.3,8.7],[4.7,12.2]],"id":38240390},{"atb":[[1.53,188.68],[1.27,0],[1.63,31.75],[1.17,0]],"id":38678129},{"atl":[[2.54,0],[2.32,0],[2.5,0],[3.1,57.14],[2.42,0],[2.46,0]],"id":36749619},{"atb":[[5,18.75],[6.6,43.03],[5.4,0]],"id":39791031}],"con":true,"img":false}]}
{"op":"mcm","clk":"5353286765","pt":1646212486632,"mc":[{"id":"1.195453769","rc":[{"atb":[[1.35,123.46]],"id":38240390}],"con":true,"img":false}]}
{"op":"mcm","clk":"5353286822","pt":1646212487506,"mc":[{"id":"1.195453769","rc":[{"atb":[[1.55,0]],"id":39734310}],"con":true,"img":false}]}
{"op":"mcm","clk":"5353286929","pt":1646212489307,"mc":[{"id":"1.195453769","rc":[{"atb":[[1.54,52.47]],"id":39734310}],"con":true,"img":false}]}
{"op":"mcm","clk":"5353287025","pt":1646212491239,"mc":[{"id":"1.195453769","rc":[{"atl":[[3.15,0]],"id":38678129}],"con":true,"img":false}]}
{"op":"mcm","clk":"5353287028","pt":1646212491338,"mc":[{"id":"1.195453769","rc":[{"atl":[[3.25,28.26]],"id":38678129}],"con":true,"img":false}]}
{"op":"mcm","clk":"5353287048","pt":1646212491757,"mc":[{"id":"1.195453769","rc":[{"atb":[[1.55,36.73]],"id":39734310}],"con":true,"img":false}]}
{"op":"mcm","clk":"5353287126","pt":1646212493151,"mc":[{"id":"1.195453769","rc":[{"atl":[[4.8,0]],"id":38240390},{"atl":[[2.12,0]],"id":36749619}],"con":true,"img":false}]}
{"op":"mcm","clk":"5353287135","pt":1646212493254,"mc":[{"id":"1.195453769","rc":[{"atl":[[5.2,24.88]],"id":38240390},{"atl":[[2.22,58.85]],"id":36749619}],"con":true,"img":false}]}
{"op":"mcm","clk":"5353287244","pt":1646212495207,"mc":[{"id":"1.195453769","rc":[{"atb":[[1.58,12.96]],"id":39734310},{"atb":[[2.04,7.23]],"id":38240390}],"con":true,"img":false}]}
{"op":"mcm","clk":"5353287307","pt":1646212496550,"mc":[{"id":"1.195453769","rc":[{"atb":[[1.52,96.15]],"id":39734310},{"atl":[[2.58,31.65]],"id":39734310},{"atb":[[1.39,128.21]],"id":38240390},{"atl":[[3.4,20.83]],"id":38240390},{"atb":[[1.61,81.97]],"id":38678129},{"atl":[[3.2,22.73]],"id":36749619},{"atb":[[6.2,9.62]],"id":39791031}],"con":true,"img":false}]}
{"op":"mcm","clk":"5353287342","pt":1646212497061,"mc":[{"id":"1.195453769","rc":[{"atl":[[5.1,0],[5.3,0],[5.5,0]],"id":38240390},{"atb":[[1.21,0]],"id":38678129},{"atb":[[4.8,0],[5,0],[5.2,0]],"id":39791031}],"con":true,"img":false}]}
{"op":"mcm","clk":"5353287382","pt":1646212497735,"mc":[{"id":"1.195453769","rc":[{"atb":[[1.12,0]],"id":39734310},{"atl":[[2.56,0],[2.6,0],[2.64,0]],"id":39734310}],"con":true,"img":false}]}
{"op":"mcm","clk":"5353287387","pt":1646212497839,"mc":[{"id":"1.195453769","rc":[{"atb":[[1.55,0]],"id":39734310}],"con":true,"img":false}]}
{"op":"mcm","clk":"5353287466","pt":1646212499136,"mc":[{"id":"1.195453769","rc":[{"atb":[[1.89,0],[1.68,98.09]],"id":38240390}],"con":true,"img":false}]}
{"op":"mcm","clk":"5353287553","pt":1646212500735,"mc":[{"id":"1.195453769","rc":[{"atb":[[1.84,2.5],[1.76,10],[1.8,5],[1.52,196.49]],"id":39734310},{"atl":[[2.54,83.37],[2.78,87.87]],"id":39734310},{"atb":[[2.12,10],[1.99,77.97],[2.28,2.5],[2.2,5],[2.16,19.13]],"id":38240390},{"atl":[[4.8,5],[4.4,2.5],[3.3,20.65],[4.7,43.79]],"id":38240390},{"atb":[[1.91,120.63],[1.95,51.66]],"id":38678129},{"atl":[[3.1,44.49]],"id":38678129},{"atb":[[1.12,916.25],[1.15,166.37],[1.16,2.5]],"id":36749619},{"atl":[[2.24,10],[1.98,125.22],[2.22,160.39],[2.16,15.43],[2.08,2.5]],"id":36749619},{"atb":[[7.2,24.44],[7.4,2.5],[8.8,7.36],[6.6,48.03]],"id":39791031},{"atl":[[34,3.42]],"id":39791031}],"con":true,"img":false}]}
{"op":"mcm","clk":"5353287568","pt":1646212500927,"mc":[{"id":"1.195453769","rc":[{"atb":[[1.52,96.15]],"id":39734310}],"con":true,"img":false}]}
{"op":"mcm","clk":"5353287584","pt":1646212501238,"mc":[{"id":"1.195453769","rc":[{"atb":[[1.58,0]],"id":39734310},{"atb":[[1.95,43.74]],"id":38678129}],"con":true,"img":false}]}
{"op":"mcm","clk":"5353287627","pt":1646212501963,"mc":[{"id":"1.195453769","rc":[{"atb":[[1.55,14.25]],"id":39734310}],"con":true,"img":false}]}
{"op":"mcm","clk":"5353287757","pt":1646212504026,"mc":[{"id":"1.195453769","rc":[{"atb":[[1.15,96.53]],"id":36749619}],"con":true,"img":false}]}
{"op":"mcm","clk":"5353287853","pt":1646212505957,"mc":[{"id":"1.195453769","rc":[{"atb":[[1.55,0]],"id":39734310},{"atl":[[2.88,53.19],[3.05,0]],"id":39734310}],"con":true,"img":false}]}
{"op":"mcm","clk":"5353287878","pt":1646212506550,"mc":[{"id":"1.195453769","rc":[{"atb":[[1.5,270.98]],"id":39734310},{"atl":[[2.62,46.3]],"id":39734310},{"atb":[[1.37,202.7]],"id":38240390},{"atl":[[3.5,30]],"id":38240390},{"atb":[[1.59,127.12]],"id":38678129},{"atl":[[3.3,32.61]],"id":36749619},{"atb":[[5.9,15.31]],"id":39791031}],"con":true,"img":false}]}
{"op":"mcm","clk":"5353287885","pt":1646212506659,"mc":[{"id":"1.195453769","rc":[{"atl":[[4.2,31.25]],"id":38240390}],"con":true,"img":false}]}
{"op":"mcm","clk":"5353287894","pt":1646212506760,"mc":[{"id":"1.195453769","rc":[{"atl":[[4.7,31.59]],"id":38240390}],"con":true,"img":false}]}
{"op":"mcm","clk":"5353287925","pt":1646212507277,"mc":[{"id":"1.195453769","rc":[{"atb":[[1.99,7.59]],"id":38678129}],"con":true,"img":false}]}
{"op":"mcm","clk":"5353287961","pt":1646212507846,"mc":[{"id":"1.195453769","rc":[{"atb":[[2.18,0]],"id":38240390}],"con":true,"img":false}]}
{"op":"mcm","clk":"5353287970","pt":1646212508056,"mc":[{"id":"1.195453769","rc":[{"atb":[[2.3,1.66]],"id":38240390}],"con":true,"img":false}]}
{"op":"mcm","clk":"5353287981","pt":1646212508260,"mc":[{"id":"1.195453769","rc":[{"atb":[[1.17,2.25]],"id":36749619}],"con":true,"img":false}]}
{"op":"mcm","clk":"5353287988","pt":1646212508464,"mc":[{"id":"1.195453769","rc":[{"atb":[[1.54,37.04]],"id":39734310},{"atb":[[2.16,11.95]],"id":38240390}],"con":true,"img":false}]}
{"op":"mcm","clk":"5353287999","pt":1646212508572,"mc":[{"id":"1.195453769","rc":[{"atb":[[1.17,1.75]],"id":36749619}],"con":true,"img":false}]}
{"op":"mcm","clk":"5353288023","pt":1646212508983,"mc":[{"id":"1.195453769","rc":[{"atb":[[1.17,0]],"id":36749619}],"con":true,"img":false}]}
{"op":"mcm","clk":"5353288028","pt":1646212509035,"mc":[{"id":"1.195453769","rc":[{"atb":[[1.17,1.75]],"id":36749619}],"con":true,"img":false}]}
{"op":"mcm","clk":"5353288034","pt":1646212509142,"mc":[{"id":"1.195453769","rc":[{"atb":[[1.51,126.98]],"id":39734310}],"con":true,"img":false}]}
{"op":"mcm","clk":"5353288036","pt":1646212509237,"mc":[{"id":"1.195453769","rc":[{"atb":[[1.58,69.2]],"id":39734310}],"con":true,"img":false}]}
{"op":"mcm","clk":"5353288126","pt":1646212510746,"mc":[{"id":"1.195453769","rc":[{"atb":[[1.77,3.75]],"id":39734310},{"spn":2.19,"spf":"NaN","id":39734310},{"spn":2.8,"spf":"NaN","id":38240390},{"atb":[[1.92,0]],"id":38678129},{"spn":2.54,"spf":"NaN","id":38678129},{"spn":21.4,"spf":"NaN","id":39791031}],"con":true,"img":false}]}
{"op":"mcm","clk":"5353288275","pt":1646212513886,"mc":[{"id":"1.195453769","rc":[{"atb":[[1.14,0]],"id":39734310},{"atb":[[1.23,0]],"id":38678129}],"con":true,"img":false}]}
{"op":"mcm","clk":"5353288342","pt":1646212514868,"mc":[{"id":"1.195453769","rc":[{"atb":[[1.92,11.39]],"id":38678129}],"con":true,"img":false}]}
{"op":"mcm","clk":"5353288467","pt":1646212516568,"mc":[{"id":"1.195453769","rc":[{"atb":[[1.62,12.12],[1.48,250]],"id":39734310},{"atl":[[2.66,75.3]],"id":39734310},{"atb":[[1.35,373.46]],"id":38240390},{"atl":[[3.6,48.08]],"id":38240390},{"atb":[[1.57,219.3]],"id":38678129},{"atl":[[3.4,52.08]],"id":36749619},{"atb":[[5.7,26.6]],"id":39791031}],"con":true,"img":false}]}
{"op":"mcm","clk":"5353288571","pt":1646212518276,"mc":[{"id":"1.195453769","rc":[{"atl":[[2.62,101.27],[2.78,6.79]],"id":39734310},{"atb":[[1.99,46.38],[2.28,21.74],[2.16,60.85]],"id":38240390},{"atl":[[3.5,78.9],[4.7,0]],"id":38240390},{"atb":[[1.99,53.25],[1.92,102.71],[1.91,50.69]],"id":38678129},{"atb":[[1.12,723.19],[1.16,15.95],[1.14,267.72]],"id":36749619},{"atl":[[2.22,58.85],[2.16,125.59]],"id":36749619},{"atb":[[7.2,9.72],[7.6,23.88]],"id":39791031}],"con":true,"img":false}]}
{"op":"mcm","clk":"5353288583","pt":1646212518483,"mc":[{"id":"1.195453769","rc":[{"atb":[[1.16,0]],"id":39734310},{"atb":[[2.16,48.9]],"id":38240390},{"atb":[[1.95,8.77],[1.25,0]],"id":38678129},{"atb":[[1.15,0]],"id":36749619}],"con":true,"img":false}]}
{"op":"mcm","clk":"5353288600","pt":1646212518787,"mc":[{"id":"1.195453769","rc":[{"atl":[[2.86,2]],"id":36749619}],"con":true,"img":false}]}
{"op":"mcm","clk":"5353288619","pt":1646212519091,"mc":[{"id":"1.195453769","rc":[{"atl":[[3.55,17.09]],"id":38240390},{"atb":[[8.6,0]],"id":39791031}],"con":true,"img":false}]}
{"op":"mcm","clk":"5353288625","pt":1646212519193,"mc":[{"id":"1.195453769","rc":[{"atl":[[5.2,15.8]],"id":38240390},{"atb":[[9.8,5.73]],"id":39791031}],"con":true,"img":false}]}
{"op":"mcm","clk":"5353288635","pt":1646212519368,"mc":[{"id":"1.195453769","rc":[{"atb":[[10,7.36],[8.8,0]],"id":39791031}],"con":true,"img":false}]}
{"op":"mcm","clk":"5353288655","pt":1646212519674,"mc":[{"id":"1.195453769","rc":[{"atb":[[2.04,0]],"id":38240390},{"atb":[[1.99,45.66]],"id":38678129}],"con":true,"img":false}]}
{"op":"mcm","clk":"5353288666","pt":1646212519874,"mc":[{"id":"1.195453769","rc":[{"atb":[[1.99,0]],"id":38678129}],"con":true,"img":false}]}
{"op":"mcm","clk":"5353288673","pt":1646212519980,"mc":[{"id":"1.195453769","rc":[{"atb":[[1.95,66.59]],"id":38678129}],"con":true,"img":false}]}
{"op":"mcm","clk":"5353288736","pt":1646212521159,"mc":[{"id":"1.195453769","rc":[{"atb":[[1.91,0]],"id":38678129}],"con":true,"img":false}]}
{"op":"mcm","clk":"5353288740","pt":1646212521264,"mc":[{"id":"1.195453769","rc":[{"atb":[[1.89,2.5],[1.85,147.34],[1.96,50.69]],"id":38678129}],"con":true,"img":false}]}
{"op":"mcm","clk":"5353288849","pt":1646212523101,"mc":[{"id":"1.195453769","rc":[{"atl":[[1.98,81.63]],"id":36749619},{"atl":[[38,1.35]],"id":39791031}],"con":true,"img":false}]}
{"op":"mcm","clk":"5353288856","pt":1646212523194,"mc":[{"id":"1.195453769","rc":[{"atl":[[1.82,43.59]],"id":36749619},{"atl":[[34,6.14]],"id":39791031}],"con":true,"img":false}]}
{"op":"mcm","clk":"5353288867","pt":1646212523296,"mc":[{"id":"1.195453769","rc":[{"atl":[[1.98,0]],"id":36749619}],"con":true,"img":false}]}
{"op":"mcm","clk":"5353288881","pt":1646212523399,"mc":[{"id":"1.195453769","rc":[{"atl":[[1.82,88.25]],"id":36749619}],"con":true,"img":false}]}
{"op":"mcm","clk":"5353288946","pt":1646212524488,"mc":[{"id":"1.195453769","rc":[{"atb":[[1.92,91.32]],"id":38678129}],"con":true,"img":false}]}
{"op":"mcm","clk":"5353288986","pt":1646212525097,"mc":[{"id":"1.195453769","rc":[{"atl":[[1.82,44.66]],"id":36749619}],"con":true,"img":false}]}
{"op":"mcm","clk":"5353288990","pt":1646212525201,"mc":[{"id":"1.195453769","rc":[{"atl":[[1.92,43.59]],"id":36749619}],"con":true,"img":false}]}
{"op":"mcm","clk":"5353289001","pt":1646212525369,"mc":[{"id":"1.195453769","rc":[{"atl":[[1.82,0]],"id":36749619}],"con":true,"img":false}]}
{"op":"mcm","clk":"5353289013","pt":1646212525572,"mc":[{"id":"1.195453769","rc":[{"atl":[[2.06,13.84]],"id":36749619}],"con":true,"img":false}]}
{"op":"mcm","clk":"5353289021","pt":1646212525678,"mc":[{"id":"1.195453769","rc":[{"atb":[[2.2,11.26]],"id":38240390}],"con":true,"img":false}]}
{"op":"mcm","clk":"5353289069","pt":1646212526499,"mc":[{"id":"1.195453769","rc":[{"atb":[[1.12,815.14]],"id":36749619}],"con":true,"img":false}]}
{"op":"mcm","clk":"5353289073","pt":1646212526608,"mc":[{"id":"1.195453769","rc":[{"atb":[[1.14,99.78]],"id":36749619}],"con":true,"img":false}]}
{"op":"mcm","clk":"5353289180","pt":1646212528676,"mc":[{"id":"1.195453769","rc":[{"atb":[[2,7.51]],"id":38678129}],"con":true,"img":false}]}
{"op":"mcm","clk":"5353289186","pt":1646212528800,"mc":[{"id":"1.195453769","rc":[{"atb":[[1.93,38.2]],"id":38678129},{"atl":[[2.84,2]],"id":36749619}],"con":true,"img":false}]}
{"op":"mcm","clk":"5353289282","pt":1646212530585,"mc":[{"id":"1.195453769","rc":[{"atl":[[2.82,3]],"id":36749619}],"con":true,"img":false}]}
{"op":"mcm","clk":"5353289302","pt":1646212531103,"mc":[{"id":"1.195453769","rc":[{"atb":[[2.2,18.2]],"id":38240390}],"con":true,"img":false}]}
{"op":"mcm","clk":"5353289320","pt":1646212531304,"mc":[{"id":"1.195453769","rc":[{"atb":[[1.95,57.82]],"id":38678129}],"con":true,"img":false}]}
{"op":"mcm","clk":"5353289342","pt":1646212531572,"mc":[{"id":"1.195453769","rc":[{"atb":[[1.62,25.57]],"id":39734310}],"con":true,"img":false}]}
{"op":"mcm","clk":"5353289392","pt":1646212532504,"mc":[{"id":"1.195453769","rc":[{"atb":[[1.93,0]],"id":38678129}],"con":true,"img":false}]}
{"op":"mcm","clk":"5353289538","pt":1646212535183,"mc":[{"id":"1.195453769","rc":[{"atb":[[1.51,0]],"id":39734310}],"con":true,"img":false}]}
{"op":"mcm","clk":"5353289545","pt":1646212535283,"mc":[{"id":"1.195453769","rc":[{"atb":[[1.53,126.98]],"id":39734310}],"con":true,"img":false}]}
{"op":"mcm","clk":"5353289559","pt":1646212535486,"mc":[{"id":"1.195453769","rc":[{"atb":[[2,65.33],[1.95,173.47],[1.92,0]],"id":38678129},{"atl":[[2.08,94.45],[2.16,15.43]],"id":36749619}],"con":true,"img":false}]}
{"op":"mcm","clk":"5353289566","pt":1646212535593,"mc":[{"id":"1.195453769","rc":[{"atb":[[1.95,115.65]],"id":38678129}],"con":true,"img":false}]}
{"op":"mcm","clk":"5353289586","pt":1646212535902,"mc":[{"id":"1.195453769","rc":[{"atb":[[2.02,1.66]],"id":38678129}],"con":true,"img":false}]}
{"op":"mcm","clk":"5353289629","pt":1646212536783,"mc":[{"id":"1.195453769","rc":[{"atb":[[1.97,8.27]],"id":38678129}],"con":true,"img":false}]}
{"op":"mcm","clk":"5353289638","pt":1646212536884,"mc":[{"id":"1.195453769","rc":[{"atl":[[2.8,4]],"id":36749619}],"con":true,"img":false}]}
{"op":"mcm","clk":"5353289645","pt":1646212536986,"mc":[{"id":"1.195453769","rc":[{"atl":[[2.54,35.23]],"id":39734310}],"con":true,"img":false}]}
{"op":"mcm","clk":"5353289690","pt":1646212537814,"mc":[{"id":"1.195453769","rc":[{"atb":[[2,57.82]],"id":38678129}],"con":true,"img":false}]}
{"op":"mcm","clk":"5353289708","pt":1646212538121,"mc":[{"id":"1.195453769","rc":[{"atl":[[2.54,62.72]],"id":39734310}],"con":true,"img":false}]}
{"op":"mcm","clk":"5353289770","pt":1646212539202,"mc":[{"id":"1.195453769","rc":[{"atl":[[3.55,0]],"id":38240390}],"con":true,"img":false}]}
{"op":"mcm","clk":"5353289775","pt":1646212539310,"mc":[{"id":"1.195453769","rc":[{"atl":[[3.45,17.09]],"id":38240390}],"con":true,"img":false}]}
{"op":"mcm","clk":"5353289786","pt":1646212539511,"mc":[{"id":"1.195453769","rc":[{"atl":[[3.5,30],[3.45,79.31]],"id":38240390}],"con":true,"img":false}]}
{"op":"mcm","clk":"5353289838","pt":1646212540385,"mc":[{"id":"1.195453769","rc":[{"atl":[[1.92,88.25]],"id":36749619}],"con":true,"img":false}]}
{"op":"mcm","clk":"5353289854","pt":1646212540592,"mc":[{"id":"1.195453769","rc":[{"atl":[[2.06,0]],"id":36749619}],"con":true,"img":false}]}
{"op":"mcm","clk":"5353289885","pt":1646212541212,"mc":[{"id":"1.195453769","rc":[{"atb":[[7.2,0]],"id":39791031}],"con":true,"img":false}]}
{"op":"mcm","clk":"5353289894","pt":1646212541322,"mc":[{"id":"1.195453769","rc":[{"atb":[[8,9.72]],"id":39791031}],"con":true,"img":false}]}
{"op":"mcm","clk":"5353289905","pt":1646212541524,"mc":[{"id":"1.195453769","rc":[{"atb":[[8,27.54],[7.6,9.16]],"id":39791031}],"con":true,"img":false}]}
{"op":"mcm","clk":"5353290003","pt":1646212543119,"mc":[{"id":"1.195453769","rc":[{"atl":[[2.22,0]],"id":36749619}],"con":true,"img":false}]}
{"op":"mcm","clk":"5353290010","pt":1646212543219,"mc":[{"id":"1.195453769","rc":[{"atl":[[2.02,58.85]],"id":36749619}],"con":true,"img":false}]}
{"op":"mcm","clk":"5353290037","pt":1646212543588,"mc":[{"id":"1.195453769","rc":[{"atb":[[2.04,7.23]],"id":38678129}],"con":true,"img":false}]}
{"op":"mcm","clk":"5353290041","pt":1646212543716,"mc":[{"id":"1.195453769","rc":[{"atb":[[2.04,52.89]],"id":38678129}],"con":true,"img":false}]}
{"op":"mcm","clk":"5353290048","pt":1646212543795,"mc":[{"id":"1.195453769","rc":[{"atb":[[2,0]],"id":38678129}],"con":true,"img":false}]}
{"op":"mcm","clk":"5353290199","pt":1646212546418,"mc":[{"id":"1.195453769","rc":[{"atb":[[2.04,45.66]],"id":38678129}],"con":true,"img":false}]}
{"op":"mcm","clk":"5353290234","pt":1646212547188,"mc":[{"id":"1.195453769","rc":[{"atl":[[2.54,40.48]],"id":39734310},{"atb":[[9.8,0]],"id":39791031}],"con":true,"img":false}]}
{"op":"mcm","clk":"5353290237","pt":1646212547289,"mc":[{"id":"1.195453769","rc":[{"atl":[[2.6,22.24]],"id":39734310},{"atb":[[10.5,5.73]],"id":39791031}],"con":true,"img":false}]}
{"op":"mcm","clk":"5353290242","pt":1646212547397,"mc":[{"id":"1.195453769","rc":[{"atl":[[2.62,46.3]],"id":39734310},{"atb":[[10,0],[11,8]],"id":39791031}],"con":true,"img":false}]}
{"op":"mcm","clk":"5353290247","pt":1646212547497,"mc":[{"id":"1.195453769","rc":[{"atl":[[2.6,63.12]],"id":39734310}],"con":true,"img":false}]}
{"op":"mcm","clk":"5353290362","pt":1646212549714,"mc":[{"id":"1.195453769","rc":[{"atb":[[1.17,0]],"id":36749619},{"atl":[[1.17,5.51]],"id":36749619},{"trd":[[1.17,3.5]],"ltp":1.17,"tv":3.5,"id":36749619}],"con":true,"img":false}]}
{"op":"mcm","clk":"5353290367","pt":1646212549818,"mc":[{"id":"1.195453769","rc":[{"atl":[[1.17,0]],"id":36749619},{"trd":[[1.17,14.52]],"ltp":1.17,"tv":14.52,"id":36749619}],"con":true,"img":false}]}
{"op":"mcm","clk":"5353290408","pt":1646212549917,"mc":[{"id":"1.195453769","rc":[{"atb":[[2.02,0]],"id":38678129}],"con":true,"img":false}]}
{"op":"mcm","clk":"5353290413","pt":1646212550024,"mc":[{"id":"1.195453769","rc":[{"atl":[[1.91,5.51]],"id":36749619}],"con":true,"img":false}]}
{"op":"mcm","clk":"5353290418","pt":1646212550128,"mc":[{"id":"1.195453769","rc":[{"atb":[[2.04,0],[2.06,1.66]],"id":38678129}],"con":true,"img":false}]}
{"op":"mcm","clk":"5353290423","pt":1646212550226,"mc":[{"id":"1.195453769","rc":[{"atb":[[1.97,66.09]],"id":38678129},{"atl":[[1.91,93.42]],"id":36749619}],"con":true,"img":false}]}
{"op":"mcm","clk":"5353290433","pt":1646212550428,"mc":[{"id":"1.195453769","rc":[{"atl":[[1.92,43.59]],"id":36749619}],"con":true,"img":false}]}
{"op":"mcm","clk":"5353290473","pt":1646212551104,"mc":[{"id":"1.195453769","rc":[{"atb":[[1.12,263.62],[1.09,735.73]],"id":36749619}],"con":true,"img":false}]}
{"op":"mcm","clk":"5353290529","pt":1646212552233,"mc":[{"id":"1.195453769","rc":[{"atb":[[1.12,260.83]],"id":36749619}],"con":true,"img":false}]}
{"op":"mcm","clk":"5353290533","pt":1646212552333,"mc":[{"id":"1.195453769","rc":[{"atb":[[1.17,11.16]],"id":36749619},{"atl":[[2.08,2.5],[2.02,189.01]],"id":36749619}],"con":true,"img":false}]}
{"op":"mcm","clk":"5353290539","pt":1646212552434,"mc":[{"id":"1.195453769","rc":[{"atb":[[1.17,113.93]],"id":36749619}],"con":true,"img":false}]}
{"op":"mcm","clk":"5353290544","pt":1646212552538,"mc":[{"id":"1.195453769","rc":[{"atb":[[1.12,168.88],[1.14,305.31]],"id":36749619}],"con":true,"img":false}]}
{"op":"mcm","clk":"5353290549","pt":1646212552600,"mc":[{"id":"1.195453769","rc":[{"atb":[[1.16,2.5]],"id":36749619}],"con":true,"img":false}]}
{"op":"mcm","clk":"5353290568","pt":1646212553117,"mc":[{"id":"1.195453769","rc":[{"atl":[[3.5,0],[5.2,38.12]],"id":39734310},{"atb":[[1.68,70.48]],"id":38240390},{"atl":[[6.2,30.98],[5.2,0]],"id":38240390},{"atl":[[4.5,28.57],[6.4,30.35]],"id":38678129},{"atl":[[2.48,78.15],[2.02,130.16]],"id":36749619},{"atl":[[40,0],[85,4.48]],"id":39791031}],"con":true,"img":false}]}
{"op":"mcm","clk":"5353290572","pt":1646212553213,"mc":[{"id":"1.195453769","rc":[{"atb":[[1.96,0]],"id":38678129},{"atl":[[1.92,0]],"id":36749619},{"atb":[[10.5,0]],"id":39791031}],"con":true,"img":false}]}
{"op":"mcm","clk":"5353290576","pt":1646212553318,"mc":[{"id":"1.195453769","rc":[{"atb":[[1.98,50.69],[1.95,0],[1.9,205.64]],"id":38678129},{"atl":[[1.84,43.59]],"id":36749619},{"atb":[[8,9.72],[9.6,5.73],[11,0]],"id":39791031}],"con":true,"img":false}]}
{"op":"mcm","clk":"5353290584","pt":1646212553420,"mc":[{"id":"1.195453769","rc":[{"atb":[[7.6,30.37],[7.8,5.32]],"id":39791031}],"con":true,"img":false}]}
{"op":"mcm","clk":"5353290590","pt":1646212553528,"mc":[{"id":"1.195453769","rc":[{"atb":[[1.98,108.51]],"id":38678129}],"con":true,"img":false}]}
{"op":"mcm","clk":"5353290597","pt":1646212553734,"mc":[{"id":"1.195453769","rc":[{"atb":[[1.97,8.27]],"id":38678129}],"con":true,"img":false}]}
{"op":"mcm","clk":"5353290665","pt":1646212555225,"mc":[{"id":"1.195453769","rc":[{"atb":[[8,0]],"id":39791031}],"con":true,"img":false}]}
{"op":"mcm","clk":"5353290670","pt":1646212555334,"mc":[{"id":"1.195453769","rc":[{"atb":[[7.8,15.04]],"id":39791031}],"con":true,"img":false}]}
{"op":"mcm","clk":"5353290702","pt":1646212555939,"mc":[{"id":"1.195453769","rc":[{"atl":[[1000,2.25]],"id":36749619}],"con":true,"img":false}]}
{"op":"mcm","clk":"5353290718","pt":1646212556207,"mc":[{"id":"1.195453769","rc":[{"atl":[[1000,1.07]],"id":36749619}],"con":true,"img":false}]}
{"op":"mcm","clk":"5353290734","pt":1646212556413,"mc":[{"id":"1.195453769","rc":[{"atl":[[1000,0]],"id":36749619}],"con":true,"img":false}]}
{"op":"mcm","clk":"5353290739","pt":1646212556513,"mc":[{"id":"1.195453769","rc":[{"atl":[[1.9,1.07]],"id":36749619}],"con":true,"img":false}]}
{"op":"mcm","clk":"5353290765","pt":1646212556940,"mc":[{"id":"1.195453769","rc":[{"atb":[[2.06,0]],"id":38678129}],"con":true,"img":false}]}
{"op":"mcm","clk":"5353290772","pt":1646212557135,"mc":[{"id":"1.195453769","rc":[{"atb":[[1.53,71.75]],"id":39734310},{"atl":[[3.45,62.22]],"id":38240390},{"atb":[[1.09,225.05]],"id":36749619},{"atl":[[1.84,138.83]],"id":36749619},{"atl":[[34,4.65]],"id":39791031}],"con":true,"img":false}]}
{"op":"mcm","clk":"5353290776","pt":1646212557235,"mc":[{"id":"1.195453769","rc":[{"atl":[[3.55,17.09]],"id":38240390}],"con":true,"img":false}]}
{"op":"mcm","clk":"5353290788","pt":1646212557437,"mc":[{"id":"1.195453769","rc":[{"atl":[[1.91,5.51]],"id":36749619}],"con":true,"img":false}]}
{"op":"mcm","clk":"5353290815","pt":1646212557903,"mc":[{"id":"1.195453769","rc":[{"atl":[[2.54,12.99]],"id":39734310}],"con":true,"img":false}]}
{"op":"mcm","clk":"5353290825","pt":1646212558109,"mc":[{"id":"1.195453769","rc":[{"atl":[[2.58,45.14]],"id":39734310}],"con":true,"img":false}]}
{"op":"mcm","clk":"5353290864","pt":1646212559041,"mc":[{"id":"1.195453769","rc":[{"atl":[[2.66,3]],"id":38240390}],"con":true,"img":false}]}
{"op":"mcm","clk":"5353290875","pt":1646212559245,"mc":[{"id":"1.195453769","rc":[{"atl":[[3.45,0],[3.4,83.05]],"id":38240390}],"con":true,"img":false}]}
{"op":"mcm","clk":"5353290889","pt":1646212559499,"mc":[{"id":"1.195453769","rc":[{"atb":[[1.97,0]],"id":38678129}],"con":true,"img":false}]}
{"op":"mcm","clk":"5353290893","pt":1646212559598,"mc":[{"id":"1.195453769","rc":[{"atl":[[2.64,2]],"id":38240390}],"con":true,"img":false}]}
{"op":"mcm","clk":"5353290978","pt":1646212561147,"mc":[{"id":"1.195453769","rc":[{"atb":[[1.89,118.15],[1.9,67.21]],"id":38678129}],"con":true,"img":false}]}
{"op":"mcm","clk":"5353291078","pt":1646212562953,"mc":[{"id":"1.195453769","rc":[{"atb":[[2.3,0]],"id":38240390}],"con":true,"img":false}]}
{"op":"mcm","clk":"5353291104","pt":1646212563222,"mc":[{"id":"1.195453769","rc":[{"atl":[[2.62,4],[2.66,0]],"id":38240390}],"con":true,"img":false}]}
{"op":"mcm","clk":"5353291110","pt":1646212563321,"mc":[{"id":"1.195453769","rc":[{"atl":[[2.6,2]],"id":38240390},{"atl":[[2.8,0],[2.82,0],[2.72,3],[2.84,0],[2.86,0]],"id":36749619}],"con":true,"img":false}]}
{"op":"mcm","clk":"5353291118","pt":1646212563427,"mc":[{"id":"1.195453769","rc":[{"atl":[[2.6,22.24],[2.58,31.65]],"id":39734310},{"atl":[[2.64,0],[2.62,2]],"id":38240390}],"con":true,"img":false}]}
{"op":"mcm","clk":"5353291127","pt":1646212563633,"mc":[{"id":"1.195453769","rc":[{"atl":[[2.6,0],[3.3,8.7],[3.4,20.83],[2.46,4]],"id":38240390}],"con":true,"img":false}]}
{"op":"mcm","clk":"5353291133","pt":1646212563737,"mc":[{"id":"1.195453769","rc":[{"atl":[[1.9,0]],"id":36749619}],"con":true,"img":false}]}
{"op":"mcm","clk":"5353291151","pt":1646212564044,"mc":[{"id":"1.195453769","rc":[{"atb":[[9.8,7.8]],"id":39791031}],"con":true,"img":false}]}
{"op":"mcm","clk":"5353291162","pt":1646212564246,"mc":[{"id":"1.195453769","rc":[{"atb":[[7.6,9.16],[7.8,25.32]],"id":39791031}],"con":true,"img":false}]}
{"op":"mcm","clk":"5353291172","pt":1646212564450,"mc":[{"id":"1.195453769","rc":[{"atl":[[2.44,4]],"id":38240390}],"con":true,"img":false}]}
{"op":"mcm","clk":"5353291232","pt":1646212565745,"mc":[{"id":"1.195453769","rc":[{"atb":[[2.02,7.36]],"id":38678129}],"con":true,"img":false}]}
{"op":"mcm","clk":"5353291243","pt":1646212565948,"mc":[{"id":"1.195453769","rc":[{"atb":[[2.02,65.18]],"id":38678129}],"con":true,"img":false}]}
{"op":"mcm","clk":"5353291248","pt":1646212566049,"mc":[{"id":"1.195453769","rc":[{"atb":[[1.98,50.69]],"id":38678129}],"con":true,"img":false}]}
{"op":"mcm","clk":"5353291272","pt":1646212566525,"mc":[{"id":"1.195453769","rc":[{"atl":[[1.83,5.51]],"id":36749619}],"con":true,"img":false}]}
{"op":"mcm","clk":"5353291279","pt":1646212566628,"mc":[{"id":"1.195453769","rc":[{"atl":[[1.91,0]],"id":36749619}],"con":true,"img":false}]}
{"op":"mcm","clk":"5353291285","pt":1646212566734,"mc":[{"id":"1.195453769","rc":[{"atb":[[1.84,0],[1.85,2.5],[1.76,0],[1.8,0],[1.81,5],[1.77,13.75]],"id":39734310},{"atb":[[1.12,163.88],[1.16,0],[1.13,5],[1.17,116.43]],"id":36749619},{"atl":[[1.83,95.1]],"id":36749619},{"atb":[[8,2.5],[7.4,0],[6.6,43.03]],"id":39791031}],"con":true,"img":false}]}
{"op":"mcm","clk":"5353291298","pt":1646212566937,"mc":[{"id":"1.195453769","rc":[{"atb":[[1.14,99.78],[1.13,245.73]],"id":36749619},{"atl":[[1.84,43.59]],"id":36749619}],"con":true,"img":false}]}
{"op":"mcm","clk":"5353291313","pt":1646212567145,"mc":[{"id":"1.195453769","rc":[{"atl":[[2.42,2]],"id":38240390}],"con":true,"img":false}]}
{"op":"mcm","clk":"5353291320","pt":1646212567246,"mc":[{"id":"1.195453769","rc":[{"atb":[[1.91,39.04]],"id":38678129},{"atl":[[2.7,3]],"id":36749619}],"con":true,"img":false}]}
{"op":"mcm","clk":"5353291326","pt":1646212567349,"mc":[{"id":"1.195453769","rc":[{"atl":[[2.42,0]],"id":38240390}],"con":true,"img":false}]}
{"op":"mcm","clk":"5353291336","pt":1646212567556,"mc":[{"id":"1.195453769","rc":[{"atl":[[2.44,0],[2.46,0]],"id":38240390}],"con":true,"img":false}]}
{"op":"mcm","clk":"5353291346","pt":1646212567653,"mc":[{"id":"1.195453769","rc":[{"atb":[[2.02,57.82]],"id":38678129}],"con":true,"img":false}]}
{"op":"mcm","clk":"5353291358","pt":1646212567816,"mc":[{"id":"1.195453769","rc":[{"atl":[[2.62,0]],"id":38240390}],"con":true,"img":false}]}
{"op":"mcm","clk":"5353291367","pt":1646212567917,"mc":[{"id":"1.195453769","rc":[{"atb":[[2.02,0]],"id":38678129}],"con":true,"img":false}]}
{"op":"mcm","clk":"5353291373","pt":1646212568019,"mc":[{"id":"1.195453769","rc":[{"atl":[[3.3,37.98]],"id":38240390},{"atl":[[2.68,4]],"id":36749619}],"con":true,"img":false}]}
{"op":"mcm","clk":"5353291380","pt":1646212568121,"mc":[{"id":"1.195453769","rc":[{"atb":[[1.91,92.78]],"id":38678129}],"con":true,"img":false}]}
{"op":"mcm","clk":"5353291427","pt":1646212568950,"mc":[{"id":"1.195453769","rc":[{"atb":[[2.3,1.66]],"id":38240390},{"atl":[[2.72,0],[2.66,2],[2.68,0],[2.7,0]],"id":36749619}],"con":true,"img":false}]}
{"op":"mcm","clk":"5353291485","pt":1646212569826,"mc":[{"id":"1.195453769","rc":[{"atb":[[1.9,209.98]],"id":38678129}],"con":true,"img":false}]}
{"op":"mcm","clk":"5353291490","pt":1646212569928,"mc":[{"id":"1.195453769","rc":[{"atb":[[1.98,121.64],[1.89,2.5]],"id":38678129},{"atb":[[8,13.24],[7.8,9.72]],"id":39791031}],"con":true,"img":false}]}
{"op":"mcm","clk":"5353291504","pt":1646212570133,"mc":[{"id":"1.195453769","rc":[{"atb":[[1.91,39.04]],"id":38678129}],"con":true,"img":false}]}
{"op":"mcm","clk":"5353291548","pt":1646212570857,"mc":[{"id":"1.195453769","rc":[{"atb":[[1.77,10]],"id":39734310},{"spn":2.19,"spf":"NaN","id":39734310},{"spn":2.54,"spf":"NaN","id":38678129},{"atb":[[1.17,105.27]],"id":36749619},{"atl":[[1000,2.25]],"id":36749619},{"spn":1.5,"spf":"NaN","id":36749619},{"spn":21.9,"spf":"NaN","id":39791031}],"con":true,"img":false}]}
{"op":"mcm","clk":"5353291566","pt":1646212571159,"mc":[{"id":"1.195453769","rc":[{"atb":[[1.98,70.95]],"id":38678129},{"atl":[[1000,1.15]],"id":36749619}],"con":true,"img":false}]}
{"op":"mcm","clk":"5353291573","pt":1646212571260,"mc":[{"id":"1.195453769","rc":[{"atb":[[1.92,50.69]],"id":38678129}],"con":true,"img":false}]}
{"op":"mcm","clk":"5353291580","pt":1646212571319,"mc":[{"id":"1.195453769","rc":[{"atb":[[1.98,0]],"id":38678129}],"con":true,"img":false}]}
{"op":"mcm","clk":"5353291587","pt":1646212571421,"mc":[{"id":"1.195453769","rc":[{"atb":[[1.92,104.43]],"id":38678129},{"atl":[[1000,0]],"id":36749619}],"con":true,"img":false}]}
{"op":"mcm","clk":"5353291599","pt":1646212571572,"mc":[{"id":"1.195453769","rc":[{"atl":[[1.77,1.15]],"id":36749619}],"con":true,"img":false}]}
{"op":"mcm","clk":"5353291652","pt":1646212572147,"mc":[{"id":"1.195453769","rc":[{"atl":[[2.86,4],[2.66,0]],"id":36749619}],"con":true,"img":false}]}
{"op":"mcm","clk":"5353291868","pt":1646212575555,"mc":[{"id":"1.195453769","rc":[{"atl":[[3.5,109.68]],"id":38240390}],"con":true,"img":false}]}
{"op":"mcm","clk":"5353291884","pt":1646212575860,"mc":[{"id":"1.195453769","rc":[{"atl":[[2.84,2]],"id":36749619}],"con":true,"img":false}]}
{"op":"mcm","clk":"5353291898","pt":1646212576070,"mc":[{"id":"1.195453769","rc":[{"atl":[[2.82,4]],"id":36749619}],"con":true,"img":false}]}
{"op":"mcm","clk":"5353291909","pt":1646212576226,"mc":[{"id":"1.195453769","rc":[{"atl":[[2.8,3]],"id":36749619}],"con":true,"img":false}]}
{"op":"mcm","clk":"5353292016","pt":1646212578034,"mc":[{"id":"1.195453769","rc":[{"atb":[[1.78,3.75]],"id":39734310},{"atb":[[1.18,73.69]],"id":36749619},{"atl":[[1.77,0]],"id":36749619}],"con":true,"img":false}]}
{"op":"mcm","clk":"5353292029","pt":1646212578243,"mc":[{"id":"1.195453769","rc":[{"atb":[[1.18,219.85],[1.14,345.49],[1.13,5]],"id":36749619}],"con":true,"img":false}]}
{"op":"mcm","clk":"5353292045","pt":1646212578451,"mc":[{"id":"1.195453769","rc":[{"atb":[[1.17,2.5]],"id":36749619}],"con":true,"img":false}]}
{"op":"mcm","clk":"5353292088","pt":1646212579268,"mc":[{"id":"1.195453769","rc":[{"atl":[[3.55,0]],"id":38240390}],"con":true,"img":false}]}
{"op":"mcm","clk":"5353292093","pt":1646212579322,"mc":[{"id":"1.195453769","rc":[{"atl":[[3.45,17.09]],"id":38240390}],"con":true,"img":false}]}
{"op":"mcm","clk":"5353292161","pt":1646212580568,"mc":[{"id":"1.195453769","rc":[{"atb":[[1.96,7.83]],"id":38678129}],"con":true,"img":false}]}
{"op":"mcm","clk":"5353292172","pt":1646212580769,"mc":[{"id":"1.195453769","rc":[{"atb":[[1.91,146.53]],"id":38678129}],"con":true,"img":false}]}
{"op":"mcm","clk":"5353292179","pt":1646212580871,"mc":[{"id":"1.195453769","rc":[{"atb":[[1.9,67.21]],"id":38678129}],"con":true,"img":false}]}
{"op":"mcm","clk":"5353292245","pt":1646212582154,"mc":[{"id":"1.195453769","rc":[{"atb":[[1.96,65.65]],"id":38678129}],"con":true,"img":false}]}
{"op":"mcm","clk":"5353292255","pt":1646212582360,"mc":[{"id":"1.195453769","rc":[{"atb":[[1.92,50.69]],"id":38678129}],"con":true,"img":false}]}
{"op":"mcm","clk":"5353292271","pt":1646212582670,"mc":[{"id":"1.195453769","rc":[{"atb":[[1.96,57.82]],"id":38678129}],"con":true,"img":false}]}
{"op":"mcm","clk":"5353292281","pt":1646212582876,"mc":[{"id":"1.195453769","rc":[{"atb":[[1.96,0]],"id":38678129}],"con":true,"img":false}]}
{"op":"mcm","clk":"5353292285","pt":1646212582927,"mc":[{"id":"1.195453769","rc":[{"atb":[[1.92,122.08]],"id":38678129}],"con":true,"img":false}]}
{"op":"mcm","clk":"5353292294","pt":1646212583134,"mc":[{"id":"1.195453769","rc":[{"atl":[[1.84,0]],"id":36749619}],"con":true,"img":false}]}
{"op":"mcm","clk":"5353292300","pt":1646212583236,"mc":[{"id":"1.195453769","rc":[{"atl":[[2.08,139.53],[1.82,43.59],[2.02,0]],"id":36749619}],"con":true,"img":false}]}
{"op":"mcm","clk":"5353292303","pt":1646212583339,"mc":[{"id":"1.195453769","rc":[{"atl":[[1.82,141.15],[1.81,5.51]],"id":36749619}],"con":true,"img":false}]}
{"op":"mcm","clk":"5353292312","pt":1646212583545,"mc":[{"id":"1.195453769","rc":[{"atl":[[1.83,0]],"id":36749619}],"con":true,"img":false}]}
{"op":"mcm","clk":"5353292350","pt":1646212584470,"mc":[{"id":"1.195453769","rc":[{"atb":[[1.91,107.49]],"id":38678129},{"atl":[[1000,2.25]],"id":36749619}],"con":true,"img":false}]}
{"op":"mcm","clk":"5353292371","pt":1646212584829,"mc":[{"id":"1.195453769","rc":[{"atl":[[1000,1.15]],"id":36749619}],"con":true,"img":false}]}
{"op":"mcm","clk":"5353292380","pt":1646212585241,"mc":[{"id":"1.195453769","rc":[{"atl":[[1000,0]],"id":36749619}],"con":true,"img":false}]}
{"op":"mcm","clk":"5353292385","pt":1646212585344,"mc":[{"id":"1.195453769","rc":[{"atl":[[1.77,1.15]],"id":36749619}],"con":true,"img":false}]}
{"op":"mcm","clk":"5353292424","pt":1646212586275,"mc":[{"id":"1.195453769","rc":[{"atb":[[1.89,0],[1.85,142.34],[1.9,69.71]],"id":38678129}],"con":true,"img":false}]}
{"op":"mcm","clk":"5353292476","pt":1646212587155,"mc":[{"id":"1.195453769","rc":[{"atb":[[1.58,0]],"id":39734310},{"atb":[[1.92,71.39]],"id":38678129},{"atb":[[9.6,0]],"id":39791031}],"con":true,"img":false}]}
{"op":"mcm","clk":"5353292481","pt":1646212587258,"mc":[{"id":"1.195453769","rc":[{"atb":[[1.61,69.2]],"id":39734310},{"atb":[[1.93,50.69]],"id":38678129},{"atb":[[10,5.73],[7.8,28.41]],"id":39791031}],"con":true,"img":false}]}
{"op":"mcm","clk":"5353292489","pt":1646212587361,"mc":[{"id":"1.195453769","rc":[{"atl":[[2.54,0],[2.6,34.74]],"id":39734310},{"atb":[[1.93,122.08]],"id":38678129},{"atb":[[8,2.5],[10.5,7.8],[9.8,0]],"id":39791031}],"con":true,"img":false}]}
{"op":"mcm","clk":"5353292493","pt":1646212587463,"mc":[{"id":"1.195453769","rc":[{"atb":[[1.92,0]],"id":38678129},{"atb":[[7.8,9.72]],"id":39791031}],"con":true,"img":false}]}
{"op":"mcm","clk":"5353292518","pt":1646212587976,"mc":[{"id":"1.195453769","rc":[{"atb":[[1.18,146.16]],"id":36749619}],"con":true,"img":false}]}
{"op":"mcm","clk":"5353292536","pt":1646212588231,"mc":[{"id":"1.195453769","rc":[{"atb":[[1.9,221.26]],"id":38678129}],"con":true,"img":false}]}
{"op":"mcm","clk":"5353292544","pt":1646212588333,"mc":[{"id":"1.195453769","rc":[{"atb":[[1.91,0]],"id":38678129}],"con":true,"img":false}]}
{"op":"mcm","clk":"5353292552","pt":1646212588436,"mc":[{"id":"1.195453769","rc":[{"atl":[[2.58,0]],"id":39734310}],"con":true,"img":false}]}
{"op":"mcm","clk":"5353292562","pt":1646212588542,"mc":[{"id":"1.195453769","rc":[{"atl":[[2.66,134.92]],"id":39734310}],"con":true,"img":false}]}
{"op":"mcm","clk":"5353292566","pt":1646212588643,"mc":[{"id":"1.195453769","rc":[{"atb":[[1.62,13.44]],"id":39734310}],"con":true,"img":false}]}
{"op":"mcm","clk":"5353292590","pt":1646212589052,"mc":[{"id":"1.195453769","rc":[{"atb":[[7.8,14.81]],"id":39791031}],"con":true,"img":false}]}
{"op":"mcm","clk":"5353292714","pt":1646212591585,"mc":[{"id":"1.195453769","rc":[{"atb":[[1.78,0]],"id":39734310},{"atl":[[3.45,83.45]],"id":38240390}],"con":true,"img":false}]}
{"op":"mcm","clk":"5353292719","pt":1646212591686,"mc":[{"id":"1.195453769","rc":[{"atl":[[3.5,29.99]],"id":38240390}],"con":true,"img":false}]}
{"op":"mcm","clk":"5353292726","pt":1646212591789,"mc":[{"id":"1.195453769","rc":[{"atb":[[1.94,37.79]],"id":38678129},{"atl":[[1.77,0]],"id":36749619}],"con":true,"img":false}]}
{"op":"mcm","clk":"5353292737","pt":1646212591946,"mc":[{"id":"1.195453769","rc":[{"atb":[[1.94,99.51]],"id":38678129}],"con":true,"img":false}]}
{"op":"mcm","clk":"5353292756","pt":1646212592260,"mc":[{"id":"1.195453769","rc":[{"atb":[[1.93,50.69]],"id":38678129}],"con":true,"img":false}]}
{"op":"mcm","clk":"5353292895","pt":1646212594753,"mc":[{"id":"1.195453769","rc":[{"atb":[[1.65,11.56]],"id":39734310}],"con":true,"img":false}]}
{"op":"mcm","clk":"5353292929","pt":1646212595474,"mc":[{"id":"1.195453769","rc":[{"atb":[[1.78,3.75]],"id":39734310},{"atb":[[1.15,160.77]],"id":36749619}],"con":true,"img":false}]}
{"op":"mcm","clk":"5353292939","pt":1646212595680,"mc":[{"id":"1.195453769","rc":[{"atb":[[1.15,415.15],[1.14,99.78]],"id":36749619}],"con":true,"img":false}]}
{"op":"mcm","clk":"5353293040","pt":1646212596972,"mc":[{"id":"1.195453769","rc":[{"atl":[[2.6,64.55]],"id":39734310}],"con":true,"img":false}]}
{"op":"mcm","clk":"5353293063","pt":1646212597384,"mc":[{"id":"1.195453769","rc":[{"atl":[[2.64,30.49]],"id":39734310}],"con":true,"img":false}]}
{"op":"mcm","clk":"5353293135","pt":1646212598773,"mc":[{"id":"1.195453769","rc":[{"atl":[[1000,2.25]],"id":36749619}],"con":true,"img":false}]}
{"op":"mcm","clk":"5353293149","pt":1646212599082,"mc":[{"id":"1.195453769","rc":[{"atl":[[1000,1.17]],"id":36749619}],"con":true,"img":false}]}
{"op":"mcm","clk":"5353293153","pt":1646212599184,"mc":[{"id":"1.195453769","rc":[{"atl":[[1.81,104.28]],"id":36749619}],"con":true,"img":false}]}
{"op":"mcm","clk":"5353293164","pt":1646212599390,"mc":[{"id":"1.195453769","rc":[{"atl":[[1000,0],[1.82,43.59]],"id":36749619}],"con":true,"img":false}]}
{"op":"mcm","clk":"5353293167","pt":1646212599492,"mc":[{"id":"1.195453769","rc":[{"atl":[[1.75,1.17]],"id":36749619}],"con":true,"img":false}]}
{"op":"mcm","clk":"5353293178","pt":1646212599698,"mc":[{"id":"1.195453769","rc":[{"atl":[[1.74,5.51]],"id":36749619}],"con":true,"img":false}]}
{"op":"mcm","clk":"5353293185","pt":1646212599853,"mc":[{"id":"1.195453769","rc":[{"atl":[[2.08,2.5],[1.82,206.7],[1.81,98.77]],"id":36749619}],"con":true,"img":false}]}
{"op":"mcm","clk":"5353293221","pt":1646212600577,"mc":[{"id":"1.195453769","rc":[{"atb":[[1.98,7.66]],"id":38678129}],"con":true,"img":false}]}
{"op":"mcm","clk":"5353293230","pt":1646212600678,"mc":[{"id":"1.195453769","rc":[{"atb":[[1.98,65.48],[1.9,69.71],[1.93,166.34]],"id":38678129}],"con":true,"img":false}]}
{"op":"mcm","clk":"5353293243","pt":1646212600883,"mc":[{"id":"1.195453769","rc":[{"atb":[[1.94,37.79]],"id":38678129}],"con":true,"img":false}]}
{"op":"mcm","clk":"5353293259","pt":1646212601191,"mc":[{"id":"1.195453769","rc":[{"atb":[[1.14,0]],"id":36749619},{"atl":[[1.82,163.11]],"id":36749619}],"con":true,"img":false}]}
{"op":"mcm","clk":"5353293269","pt":1646212601295,"mc":[{"id":"1.195453769","rc":[{"atb":[[1.13,104.78]],"id":36749619},{"atl":[[1.81,142.36]],"id":36749619}],"con":true,"img":false}]}
{"op":"mcm","clk":"5353293279","pt":1646212601504,"mc":[{"id":"1.195453769","rc":[{"atl":[[2.82,54.95],[2.88,0]],"id":39734310},{"atl":[[3.25,8.89],[3.3,29.28]],"id":38240390},{"atb":[[1.59,0],[1.58,34.48],[1.63,0],[1.61,0]],"id":38678129},{"atl":[[2.74,3]],"id":38678129},{"atl":[[2.8,0],[2.82,0],[2.84,0],[2.08,0],[2.24,0],[2.86,0],[2.16,10.43]],"id":36749619},{"atl":[[34,3.65],[36,1.34]],"id":39791031}],"con":true,"img":false}]}
{"op":"mcm","clk":"5353293294","pt":1646212601709,"mc":[{"id":"1.195453769","rc":[{"atl":[[2.6,34.74],[2.66,75.3]],"id":39734310},{"atb":[[2.12,0],[2.26,5],[2.34,2.5],[2.28,19.24],[2.18,10],[2.2,13.2]],"id":38240390},{"atl":[[3.25,38.17]],"id":38240390},{"atl":[[2.36,2],[2.74,43.52]],"id":38678129}],"con":true,"img":false}]}
{"op":"mcm","clk":"5353293305","pt":1646212601865,"mc":[{"id":"1.195453769","rc":[{"atb":[[2.26,67.61],[2.34,32.55],[2.16,0]],"id":38240390},{"atl":[[3.3,0]],"id":38240390},{"atl":[[3.1,9.52]],"id":38678129}],"con":true,"img":false}]}
{"op":"mcm","clk":"5353293312","pt":1646212602072,"mc":[{"id":"1.195453769","rc":[{"atb":[[2.28,0]],"id":38240390}],"con":true,"img":false}]}
{"op":"mcm","clk":"5353301462","pt":1646212603107,"mc":[{"id":"1.195453769","rc":[{"atb":[[8,11.74]],"id":39791031}],"con":true,"img":false}]}
{"op":"mcm","clk":"5353301486","pt":1646212603574,"mc":[{"id":"1.195453769","rc":[{"atb":[[2.2,6.94]],"id":38240390},{"atb":[[1.98,57.82]],"id":38678129}],"con":true,"img":false}]}
{"op":"mcm","clk":"5353301519","pt":1646212604504,"mc":[{"id":"1.195453769","rc":[{"atb":[[1.62,0]],"id":39734310}],"con":true,"img":false}]}
{"op":"mcm","clk":"5353301544","pt":1646212604864,"mc":[{"id":"1.195453769","rc":[{"atb":[[2.3,0]],"id":38240390}],"con":true,"img":false}]}
{"op":"mcm","clk":"5353301554","pt":1646212605070,"mc":[{"id":"1.195453769","rc":[{"atb":[[2.36,1.66]],"id":38240390},{"atb":[[1.93,115.65]],"id":38678129}],"con":true,"img":false}]}
{"op":"mcm","clk":"5353301562","pt":1646212605172,"mc":[{"id":"1.195453769","rc":[{"atb":[[1.99,50.69]],"id":38678129}],"con":true,"img":false}]}
{"op":"mcm","clk":"5353301602","pt":1646212605894,"mc":[{"id":"1.195453769","rc":[{"atb":[[1.94,0]],"id":38678129},{"atb":[[1.15,254.38]],"id":36749619}],"con":true,"img":false}]}
{"op":"mcm","clk":"5353301605","pt":1646212605997,"mc":[{"id":"1.195453769","rc":[{"atl":[[1.75,0]],"id":36749619}],"con":true,"img":false}]}
{"op":"mcm","clk":"5353301639","pt":1646212606568,"mc":[{"id":"1.195453769","rc":[{"atb":[[1.99,121.35]],"id":38678129},{"atl":[[2.34,2]],"id":38678129},{"atl":[[2.14,5],[2.06,2.5],[1.74,0]],"id":36749619}],"con":true,"img":false}]}
{"op":"mcm","clk":"5353301650","pt":1646212606671,"mc":[{"id":"1.195453769","rc":[{"atb":[[1.98,0]],"id":38678129},{"atl":[[1.8,5.51]],"id":36749619}],"con":true,"img":false}]}
{"op":"mcm","clk":"5353301710","pt":1646212607394,"mc":[{"id":"1.195453769","rc":[{"atl":[[2.68,44.64]],"id":39734310}],"con":true,"img":false}]}
{"op":"mcm","clk":"5353301750","pt":1646212608018,"mc":[{"id":"1.195453769","rc":[{"atb":[[1.9,228.69],[1.93,0]],"id":38678129}],"con":true,"img":false}]}
{"op":"mcm","clk":"5353301777","pt":1646212608585,"mc":[{"id":"1.195453769","rc":[{"atb":[[1.68,0]],"id":38240390},{"atl":[[3.45,66.36]],"id":38240390}],"con":true,"img":false}]}
{"op":"mcm","clk":"5353301785","pt":1646212608693,"mc":[{"id":"1.195453769","rc":[{"atb":[[1.58,70.48]],"id":38240390},{"atl":[[3.55,17.09]],"id":38240390}],"con":true,"img":false}]}
{"op":"mcm","clk":"5353301814","pt":1646212609210,"mc":[{"id":"1.195453769","rc":[{"atb":[[2.26,5],[2.2,115.52]],"id":38240390}],"con":true,"img":false}]}
{"op":"mcm","clk":"5353301839","pt":1646212609681,"mc":[{"id":"1.195453769","rc":[{"atb":[[2.4,5.36]],"id":38240390}],"con":true,"img":false}]}
{"op":"mcm","clk":"5353301862","pt":1646212609993,"mc":[{"id":"1.195453769","rc":[{"atl":[[2.38,3]],"id":38678129}],"con":true,"img":false}]}
{"op":"mcm","clk":"5353301868","pt":1646212610096,"mc":[{"id":"1.195453769","rc":[{"atl":[[2.66,0],[2.62,0]],"id":39734310}],"con":true,"img":false}]}
{"op":"mcm","clk":"5353301883","pt":1646212610508,"mc":[{"id":"1.195453769","rc":[{"atl":[[2.32,2],[2.38,0]],"id":38678129}],"con":true,"img":false}]}
{"op":"mcm","clk":"5353301910","pt":1646212610971,"mc":[{"id":"1.195453769","rc":[{"atb":[[2.36,0]],"id":38240390}],"con":true,"img":false}]}
{"op":"mcm","clk":"5353301920","pt":1646212611178,"mc":[{"id":"1.195453769","rc":[{"atb":[[2.42,1.66]],"id":38240390}],"con":true,"img":false}]}
{"op":"mcm","clk":"5353301936","pt":1646212611489,"mc":[{"id":"1.195453769","rc":[{"atb":[[1.56,89.29]],"id":38678129},{"atl":[[40,1.28]],"id":39791031}],"con":true,"img":false}]}
{"op":"mcm","clk":"5353301949","pt":1646212611697,"mc":[{"id":"1.195453769","rc":[{"atl":[[2.82,0],[2.74,57.47]],"id":39734310},{"atl":[[2.3,2]],"id":38678129},{"atl":[[38,0],[42,0],[46,0]],"id":39791031}],"con":true,"img":false}]}
{"op":"mcm","clk":"5353301955","pt":1646212611801,"mc":[{"id":"1.195453769","rc":[{"atl":[[48,2.5]],"id":39791031}],"con":true,"img":false}]}
{"op":"mcm","clk":"5353302026","pt":1646212613198,"mc":[{"id":"1.195453769","rc":[{"atb":[[1.99,0]],"id":38240390}],"con":true,"img":false}]}
{"op":"mcm","clk":"5353302032","pt":1646212613301,"mc":[{"id":"1.195453769","rc":[{"atb":[[1.8,46.38]],"id":38240390},{"atb":[[1.86,41.31]],"id":38678129},{"atb":[[1.19,102.3]],"id":36749619}],"con":true,"img":false}]}
{"op":"mcm","clk":"5353302037","pt":1646212613405,"mc":[{"id":"1.195453769","rc":[{"atb":[[1.15,0],[1.19,285.81],[1.17,263.42]],"id":36749619},{"atl":[[1000,2.25]],"id":36749619}],"con":true,"img":false}]}
{"op":"mcm","clk":"5353302043","pt":1646212613509,"mc":[{"id":"1.195453769","rc":[{"atb":[[1.18,0]],"id":36749619}],"con":true,"img":false}]}
{"op":"mcm","clk":"5353302054","pt":1646212613716,"mc":[{"id":"1.195453769","rc":[{"atl":[[1000,1.14]],"id":36749619}],"con":true,"img":false}]}
{"op":"mcm","clk":"5353302073","pt":1646212614080,"mc":[{"id":"1.195453769","rc":[{"atl":[[1000,0]],"id":36749619}],"con":true,"img":false}]}
{"op":"mcm","clk":"5353302079","pt":1646212614183,"mc":[{"id":"1.195453769","rc":[{"atl":[[1.79,1.14]],"id":36749619}],"con":true,"img":false}]}
{"op":"mcm","clk":"5353302104","pt":1646212614702,"mc":[{"id":"1.195453769","rc":[{"atl":[[1.8,105.51]],"id":36749619}],"con":true,"img":false}]}
{"op":"mcm","clk":"5353302118","pt":1646212614909,"mc":[{"id":"1.195453769","rc":[{"atl":[[1.81,43.59]],"id":36749619}],"con":true,"img":false}]}
{"op":"mcm","clk":"5353302131","pt":1646212615115,"mc":[{"id":"1.195453769","rc":[{"atl":[[2.6,12.5]],"id":39734310}],"con":true,"img":false}]}
{"op":"mcm","clk":"5353302135","pt":1646212615219,"mc":[{"id":"1.195453769","rc":[{"atl":[[2.66,22.24]],"id":39734310},{"atl":[[1.78,5.51]],"id":36749619}],"con":true,"img":false}]}
{"op":"mcm","clk":"5353302147","pt":1646212615373,"mc":[{"id":"1.195453769","rc":[{"atb":[[1.9,69.71],[1.86,106.29]],"id":38678129},{"atl":[[1.8,100],[1.82,0],[1.81,213.75]],"id":36749619}],"con":true,"img":false}]}
{"op":"mcm","clk":"5353302218","pt":1646212617028,"mc":[{"id":"1.195453769","rc":[{"atb":[[1.78,0]],"id":39734310},{"atb":[[1.86,64.98]],"id":38678129},{"atl":[[2.36,0],[2.28,2]],"id":38678129}],"con":true,"img":false}]}
{"op":"mcm","clk":"5353302226","pt":1646212617079,"mc":[{"id":"1.195453769","rc":[{"atl":[[1.81,170.16]],"id":36749619}],"con":true,"img":false}]}
{"op":"mcm","clk":"5353302231","pt":1646212617183,"mc":[{"id":"1.195453769","rc":[{"atl":[[2.28,4]],"id":38678129},{"atl":[[1.79,44.74]],"id":36749619}],"con":true,"img":false}]}
{"op":"mcm","clk":"5353302240","pt":1646212617287,"mc":[{"id":"1.195453769","rc":[{"atl":[[2.74,0]],"id":38678129}],"con":true,"img":false}]}
{"op":"mcm","clk":"5353302244","pt":1646212617388,"mc":[{"id":"1.195453769","rc":[{"atl":[[2.72,72.67]],"id":39734310},{"atb":[[2.26,85.07],[2.4,45.39]],"id":38240390}],"con":true,"img":false}]}
{"op":"mcm","clk":"5353302246","pt":1646212617492,"mc":[{"id":"1.195453769","rc":[{"atb":[[2.2,6.94]],"id":38240390}],"con":true,"img":false}]}
{"op":"mcm","clk":"5353302251","pt":1646212617595,"mc":[{"id":"1.195453769","rc":[{"atb":[[1.65,24.38]],"id":39734310},{"atb":[[2.34,2.5],[2.2,0]],"id":38240390}],"con":true,"img":false}]}
{"op":"mcm","clk":"5353302311","pt":1646212618781,"mc":[{"id":"1.195453769","rc":[{"atb":[[2.4,40.03]],"id":38240390}],"con":true,"img":false}]}
{"op":"mcm","clk":"5353302398","pt":1646212620495,"mc":[{"id":"1.195453769","rc":[{"atl":[[1.79,43.59]],"id":36749619}],"con":true,"img":false}]}
{"op":"mcm","clk":"5353302407","pt":1646212620600,"mc":[{"id":"1.195453769","rc":[{"atb":[[1.13,379.47]],"id":36749619}],"con":true,"img":false}]}
{"op":"mcm","clk":"5353302412","pt":1646212620704,"mc":[{"id":"1.195453769","rc":[{"atb":[[1.17,2.5]],"id":36749619}],"con":true,"img":false}]}
{"op":"mcm","clk":"5353302448","pt":1646212621541,"mc":[{"id":"1.195453769","rc":[{"atb":[[1.45,0],[1.4,0],[1.5,150]],"id":39734310},{"atl":[[3.45,0],[3.95,0],[4.9,0],[2.98,0],[2.78,0]],"id":39734310},{"atb":[[1.98,0],[1.93,0],[1.88,0]],"id":38240390},{"atl":[[4.9,0],[7.8,0],[5.9,0],[14.5,0],[9.8,0]],"id":38240390},{"atb":[[1.8,0],[1.54,138.89],[1.85,0],[1.9,2.5]],"id":38678129},{"atl":[[8,0],[10,0],[4,0],[5,0],[6,0]],"id":38678129},{"atb":[[1.01,0],[1.11,0],[1.06,1916.67]],"id":36749619},{"atl":[[2.76,0],[2.36,0],[2.56,0],[2.96,0],[2.16,0]],"id":36749619},{"atb":[[5.8,0],[7.6,0],[6.6,21.43]],"id":39791031},{"atl":[[65,0],[130,2],[36,1],[330,0],[44,1.74],[230,0]],"id":39791031}],"con":true,"img":false}]}
{"op":"mcm","clk":"5353302538","pt":1646212623147,"mc":[{"id":"1.195453769","rc":[{"atb":[[1.99,70.66]],"id":38678129}],"con":true,"img":false}]}
{"op":"mcm","clk":"5353302542","pt":1646212623197,"mc":[{"id":"1.195453769","rc":[{"atb":[[2,50.69]],"id":38678129}],"con":true,"img":false}]}
{"op":"mcm","clk":"5353302548","pt":1646212623301,"mc":[{"id":"1.195453769","rc":[{"atb":[[2,55.57],[1.99,0],[1.9,12.25],[1.86,0]],"id":38678129}],"con":true,"img":false}]}
{"op":"mcm","clk":"5353302593","pt":1646212624534,"mc":[{"id":"1.195453769","rc":[{"atb":[[2.46,5.15]],"id":38240390}],"con":true,"img":false}]}
{"op":"mcm","clk":"5353302605","pt":1646212624687,"mc":[{"id":"1.195453769","rc":[{"atb":[[2.26,5],[2.34,91]],"id":38240390}],"con":true,"img":false}]}
{"op":"mcm","clk":"5353302609","pt":1646212624790,"mc":[{"id":"1.195453769","rc":[{"atb":[[1.78,3.75]],"id":39734310},{"atb":[[2.28,27.75]],"id":38240390}],"con":true,"img":false}]}
{"op":"mcm","clk":"5353302626","pt":1646212625154,"mc":[{"id":"1.195453769","rc":[{"atb":[[1.45,268.85],[1.4,302.46],[1.5,270.98],[1.61,0]],"id":39734310},{"atl":[[3.45,1.78],[2.98,0.27],[2.78,0.3]],"id":39734310},{"atb":[[1.98,61.73],[1.93,130.09],[1.88,137.48]],"id":38240390},{"atl":[[4.9,0.14],[7.8,0.64],[5.9,0.1]],"id":38240390},{"atb":[[2,4.88],[1.8,151.23],[1.85,142.34],[1.9,79.46]],"id":38678129},{"atl":[[4,0.17],[5,0.13],[6,0.87]],"id":38678129},{"atb":[[1.01,12098.75],[1.11,549.94],[1.06,3933.12]],"id":36749619},{"atl":[[2.36,0.4],[2.56,2.79],[2.16,0.46]],"id":36749619},{"atb":[[5.8,25.2],[7.6,9.16],[6.6,43.03]],"id":39791031},{"atl":[[130,2.03],[65,0.01],[36,1.01]],"id":39791031}],"con":true,"img":false}]}
{"op":"mcm","clk":"5353302631","pt":1646212625206,"mc":[{"id":"1.195453769","rc":[{"atb":[[1.65,93.58]],"id":39734310},{"atb":[[1.86,50.69]],"id":38678129}],"con":true,"img":false}]}
{"op":"mcm","clk":"5353302633","pt":1646212625310,"mc":[{"id":"1.195453769","rc":[{"atb":[[2,0]],"id":38678129}],"con":true,"img":false}]}
{"op":"mcm","clk":"5353302639","pt":1646212625414,"mc":[{"id":"1.195453769","rc":[{"atb":[[1.9,83.96]],"id":38678129}],"con":true,"img":false}]}
{"op":"mcm","clk":"5353302795","pt":1646212627895,"mc":[{"id":"1.195453769","rc":[{"atb":[[1.65,82.02]],"id":39734310}],"con":true,"img":false}]}
{"op":"mcm","clk":"5353302809","pt":1646212628207,"mc":[{"id":"1.195453769","rc":[{"atl":[[1000,2.25]],"id":36749619}],"con":true,"img":false}]}
{"op":"mcm","clk":"5353302828","pt":1646212628516,"mc":[{"id":"1.195453769","rc":[{"atl":[[1000,1.15]],"id":36749619}],"con":true,"img":false}]}
{"op":"mcm","clk":"5353302845","pt":1646212628825,"mc":[{"id":"1.195453769","rc":[{"atl":[[1000,0]],"id":36749619}],"con":true,"img":false}]}
{"op":"mcm","clk":"5353302850","pt":1646212628928,"mc":[{"id":"1.195453769","rc":[{"atb":[[2.42,0]],"id":38240390},{"atl":[[1.77,1.15]],"id":36749619}],"con":true,"img":false}]}
{"op":"mcm","clk":"5353302854","pt":1646212629031,"mc":[{"id":"1.195453769","rc":[{"atb":[[2.48,1.66]],"id":38240390},{"atl":[[1.76,5.51]],"id":36749619}],"con":true,"img":false}]}
{"op":"mcm","clk":"5353302866","pt":1646212629238,"mc":[{"id":"1.195453769","rc":[{"atl":[[1.78,0]],"id":36749619}],"con":true,"img":false}]}
{"op":"mcm","clk":"5353302895","pt":1646212629806,"mc":[{"id":"1.195453769","rc":[{"atl":[[2.26,4]],"id":38678129},{"atb":[[8,9.24],[10,8.23],[9.2,5],[8.4,10]],"id":39791031}],"con":true,"img":false}]}
{"op":"mcm","clk":"5353302900","pt":1646212629912,"mc":[{"id":"1.195453769","rc":[{"atl":[[2.3,0],[2.32,0],[2.34,0],[2.28,2]],"id":38678129},{"atl":[[1.76,42.34]],"id":36749619},{"atb":[[9.2,17.99]],"id":39791031}],"con":true,"img":false}]}
{"op":"mcm","clk":"5353302905","pt":1646212630013,"mc":[{"id":"1.195453769","rc":[{"atl":[[2.26,0]],"id":38678129},{"atb":[[8,0]],"id":39791031}],"con":true,"img":false}]}
{"op":"mcm","clk":"5353302910","pt":1646212630116,"mc":[{"id":"1.195453769","rc":[{"atl":[[1.8,0]],"id":36749619}],"con":true,"img":false}]}
{"op":"mcm","clk":"5353302926","pt":1646212630425,"mc":[{"id":"1.195453769","rc":[{"atb":[[1.85,260.78],[1.9,74.21]],"id":38678129}],"con":true,"img":false}]}
{"op":"mcm","clk":"5353302934","pt":1646212630632,"mc":[{"id":"1.195453769","rc":[{"atl":[[2.28,0]],"id":38678129}],"con":true,"img":false}]}
{"op":"mcm","clk":"5353302942","pt":1646212630736,"mc":[{"id":"1.195453769","rc":[{"atl":[[3.1,47.62]],"id":38678129}],"con":true,"img":false}]}
{"op":"mcm","clk":"5353302947","pt":1646212630838,"mc":[{"id":"1.195453769","rc":[{"atl":[[2.6,25.62],[2.66,48.49]],"id":39734310}],"con":true,"img":false}]}
{"op":"mcm","clk":"5353302953","pt":1646212630941,"mc":[{"id":"1.195453769","rc":[{"atl":[[2.66,22.24]],"id":39734310},{"spn":2.22,"spf":"NaN","id":39734310},{"spn":2.86,"spf":"NaN","id":38240390},{"spn":2.5,"spf":"NaN","id":38678129},{"spn":1.47,"spf":"NaN","id":36749619},{"spn":22.25,"spf":"NaN","id":39791031}],"con":true,"img":false}]}
{"op":"mcm","clk":"5353302959","pt":1646212631043,"mc":[{"id":"1.195453769","rc":[{"atl":[[2.6,12.5]],"id":39734310}],"con":true,"img":false}]}
{"op":"mcm","clk":"5353302963","pt":1646212631146,"mc":[{"id":"1.195453769","rc":[{"atb":[[1.8,0]],"id":38240390}],"con":true,"img":false}]}
{"op":"mcm","clk":"5353302966","pt":1646212631249,"mc":[{"id":"1.195453769","rc":[{"atb":[[1.74,46.38]],"id":38240390}],"con":true,"img":false}]}
{"op":"mcm","clk":"5353303008","pt":1646212631919,"mc":[{"id":"1.195453769","rc":[{"atb":[[2.28,0]],"id":38240390}],"con":true,"img":false}]}
{"op":"mcm","clk":"5353303047","pt":1646212632547,"mc":[{"id":"1.195453769","rc":[{"atb":[[1.52,240.38]],"id":38678129},{"atl":[[48,5.16]],"id":39791031}],"con":true,"img":false}]}
{"op":"mcm","clk":"5353303052","pt":1646212632640,"mc":[{"id":"1.195453769","rc":[{"atb":[[2.46,49.4]],"id":38240390}],"con":true,"img":false}]}
{"op":"mcm","clk":"5353303060","pt":1646212632746,"mc":[{"id":"1.195453769","rc":[{"atb":[[2.4,0]],"id":38240390}],"con":true,"img":false}]}
{"op":"mcm","clk":"5353303067","pt":1646212632848,"mc":[{"id":"1.195453769","rc":[{"atl":[[2.82,54.95],[2.74,0]],"id":39734310},{"atl":[[3.35,8.51],[3.25,29.28]],"id":38240390},{"atb":[[1.63,31.75],[1.58,0],[1.57,0]],"id":38678129}],"con":true,"img":false}]}
{"op":"mcm","clk":"5353303074","pt":1646212632950,"mc":[{"id":"1.195453769","rc":[{"atb":[[2.26,138.86],[2.34,2.5]],"id":38240390}],"con":true,"img":false}]}
{"op":"mcm","clk":"5353303083","pt":1646212633054,"mc":[{"id":"1.195453769","rc":[{"atl":[[3.25,0],[3.45,0],[3.4,95.99]],"id":38240390}],"con":true,"img":false}]}
{"op":"mcm","clk":"5353303089","pt":1646212633106,"mc":[{"id":"1.195453769","rc":[{"atl":[[3.35,30.51]],"id":38240390}],"con":true,"img":false}]}
{"op":"mcm","clk":"5353303150","pt":1646212634037,"mc":[{"id":"1.195453769","rc":[{"atb":[[1.69,10.89]],"id":39734310},{"atl":[[2.6,25.62]],"id":39734310},{"atb":[[2.46,44.25]],"id":38240390}],"con":true,"img":false}]}
{"op":"mcm","clk":"5353303229","pt":1646212635117,"mc":[{"id":"1.195453769","rc":[{"atb":[[1.19,183.51]],"id":36749619},{"atl":[[1.77,0]],"id":36749619}],"con":true,"img":false}]}
{"op":"mcm","clk":"5353303238","pt":1646212635221,"mc":[{"id":"1.195453769","rc":[{"atb":[[1.19,0]],"id":36749619}],"con":true,"img":false}]}
{"op":"mcm","clk":"5353303245","pt":1646212635323,"mc":[{"id":"1.195453769","rc":[{"atb":[[1.12,450.43],[1.17,162.82]],"id":36749619}],"con":true,"img":false}]}
{"op":"mcm","clk":"5353303249","pt":1646212635426,"mc":[{"id":"1.195453769","rc":[{"atb":[[1.13,104.78]],"id":36749619}],"con":true,"img":false}]}
{"op":"mcm","clk":"5353303274","pt":1646212635943,"mc":[{"id":"1.195453769","rc":[{"atl":[[2.6,12.5]],"id":39734310}],"con":true,"img":false}]}
{"op":"mcm","clk":"5353303312","pt":1646212636717,"mc":[{"id":"1.195453769","rc":[{"atb":[[1.62,0]],"id":38678129},{"atl":[[3.25,8.89]],"id":38678129}],"con":true,"img":false}]}
{"op":"mcm","clk":"5353303323","pt":1646212636821,"mc":[{"id":"1.195453769","rc":[{"atb":[[1.57,86.54]],"id":38678129},{"atl":[[3.5,19.37]],"id":38678129}],"con":true,"img":false}]}
{"op":"mcm","clk":"5353303346","pt":1646212637235,"mc":[{"id":"1.195453769","rc":[{"atl":[[2.64,43.61]],"id":39734310}],"con":true,"img":false}]}
{"op":"mcm","clk":"5353303356","pt":1646212637441,"mc":[{"id":"1.195453769","rc":[{"atl":[[2.64,30.49]],"id":39734310}],"con":true,"img":false}]}
{"op":"mcm","clk":"5353303381","pt":1646212637958,"mc":[{"id":"1.195453769","rc":[{"atb":[[1.21,0],[1.26,317.18]],"id":39734310}],"con":true,"img":false}]}
{"op":"mcm","clk":"5353303408","pt":1646212638527,"mc":[{"id":"1.195453769","rc":[{"atb":[[1.87,40.84]],"id":38678129}],"con":true,"img":false}]}
{"op":"mcm","clk":"5353303413","pt":1646212638629,"mc":[{"id":"1.195453769","rc":[{"atb":[[1.86,183.38]],"id":38678129}],"con":true,"img":false}]}
{"op":"mcm","clk":"5353303417","pt":1646212638732,"mc":[{"id":"1.195453769","rc":[{"atb":[[1.85,142.34]],"id":38678129}],"con":true,"img":false}]}
{"op":"mcm","clk":"5353303445","pt":1646212639146,"mc":[{"id":"1.195453769","rc":[{"atl":[[3.55,0]],"id":38240390},{"atb":[[1.86,132.69]],"id":38678129}],"con":true,"img":false}]}
{"op":"mcm","clk":"5353303454","pt":1646212639259,"mc":[{"id":"1.195453769","rc":[{"atl":[[4.1,17.09]],"id":38240390},{"atb":[[1.71,50.69]],"id":38678129}],"con":true,"img":false}]}
{"op":"mcm","clk":"5353303483","pt":1646212639821,"mc":[{"id":"1.195453769","rc":[{"atb":[[2.52,4.94]],"id":38240390},{"atb":[[1.94,8]],"id":38678129}],"con":true,"img":false}]}
{"op":"mcm","clk":"5353303489","pt":1646212639923,"mc":[{"id":"1.195453769","rc":[{"atb":[[2.26,5],[2.34,93.27]],"id":38240390},{"atb":[[1.94,63.09]],"id":38678129}],"con":true,"img":false}]}
{"op":"mcm","clk":"5353303497","pt":1646212640026,"mc":[{"id":"1.195453769","rc":[{"atl":[[3.4,20.83],[3.5,120.77]],"id":38240390}],"con":true,"img":false}]}
{"op":"mcm","clk":"5353303501","pt":1646212640131,"mc":[{"id":"1.195453769","rc":[{"atb":[[1.9,69.71]],"id":38678129}],"con":true,"img":false}]}
{"op":"mcm","clk":"5353303508","pt":1646212640337,"mc":[{"id":"1.195453769","rc":[{"atl":[[2.6,25.62]],"id":39734310}],"con":true,"img":false}]}
{"op":"mcm","clk":"5353303516","pt":1646212640441,"mc":[{"id":"1.195453769","rc":[{"atl":[[2.6,12.5]],"id":39734310}],"con":true,"img":false}]}
{"op":"mcm","clk":"5353303522","pt":1646212640545,"mc":[{"id":"1.195453769","rc":[{"atl":[[2.6,25.62]],"id":39734310}],"con":true,"img":false}]}
{"op":"mcm","clk":"5353303542","pt":1646212640959,"mc":[{"id":"1.195453769","rc":[{"atb":[[2.48,0]],"id":38240390}],"con":true,"img":false}]}
{"op":"mcm","clk":"5353303551","pt":1646212641164,"mc":[{"id":"1.195453769","rc":[{"atb":[[2.54,1.66]],"id":38240390},{"atb":[[11,1.66]],"id":39791031}],"con":true,"img":false}]}
{"op":"mcm","clk":"5353303560","pt":1646212641319,"mc":[{"id":"1.195453769","rc":[{"atb":[[11.5,4]],"id":39791031}],"con":true,"img":false}]}
{"op":"mcm","clk":"5353303568","pt":1646212641525,"mc":[{"id":"1.195453769","rc":[{"atb":[[10.5,0]],"id":39791031}],"con":true,"img":false}]}
{"op":"mcm","clk":"5353303603","pt":1646212642454,"mc":[{"id":"1.195453769","rc":[{"atb":[[1.65,69.2]],"id":39734310}],"con":true,"img":false}]}
{"op":"mcm","clk":"5353303622","pt":1646212642866,"mc":[{"id":"1.195453769","rc":[{"atb":[[1.94,55.09]],"id":38678129}],"con":true,"img":false}]}
{"op":"mcm","clk":"5353303626","pt":1646212642971,"mc":[{"id":"1.195453769","rc":[{"atb":[[1.65,71.2]],"id":39734310},{"atl":[[2.82,0],[2.72,84.3]],"id":39734310},{"atb":[[1.14,179.1]],"id":36749619}],"con":true,"img":false}]}
{"op":"mcm","clk":"5353303630","pt":1646212643027,"mc":[{"id":"1.195453769","rc":[{"atl":[[2.72,67.74],[2.6,13.12],[2.64,0],[2.68,0]],"id":39734310},{"atb":[[1.94,0]],"id":38678129},{"atl":[[1000,2.25]],"id":36749619}],"con":true,"img":false}]}
{"op":"mcm","clk":"5353303635","pt":1646212643134,"mc":[{"id":"1.195453769","rc":[{"atb":[[1.66,3]],"id":39734310},{"atb":[[1.12,163.88],[1.13,393.69]],"id":36749619}],"con":true,"img":false}]}
{"op":"mcm","clk":"5353303639","pt":1646212643237,"mc":[{"id":"1.195453769","rc":[{"atb":[[1.67,2]],"id":39734310},{"atl":[[2.6,0]],"id":39734310},{"atb":[[1.9,124.8]],"id":38678129}],"con":true,"img":false}]}
{"op":"mcm","clk":"5353303646","pt":1646212643341,"mc":[{"id":"1.195453769","rc":[{"atl":[[2.66,35.83]],"id":39734310},{"atl":[[1000,1.17]],"id":36749619}],"con":true,"img":false}]}
{"op":"mcm","clk":"5353303655","pt":1646212643548,"mc":[{"id":"1.195453769","rc":[{"atl":[[3.45,20.41]],"id":38240390},{"atl":[[1000,0]],"id":36749619}],"con":true,"img":false}]}
{"op":"mcm","clk":"5353303661","pt":1646212643651,"mc":[{"id":"1.195453769","rc":[{"atb":[[1.61,81.97]],"id":38678129},{"atl":[[1.75,1.17]],"id":36749619}],"con":true,"img":false}]}
{"op":"mcm","clk":"5353303668","pt":1646212643755,"mc":[{"id":"1.195453769","rc":[{"atl":[[1.74,5.51]],"id":36749619}],"con":true,"img":false}]}
{"op":"mcm","clk":"5353303673","pt":1646212643859,"mc":[{"id":"1.195453769","rc":[{"atl":[[1.76,36.83],[1.79,227.02]],"id":36749619}],"con":true,"img":false}]}
{"op":"mcm","clk":"5353303677","pt":1646212643961,"mc":[{"id":"1.195453769","rc":[{"atl":[[1.81,0]],"id":36749619}],"con":true,"img":false}]}
{"op":"mcm","clk":"5353303724","pt":1646212644838,"mc":[{"id":"1.195453769","rc":[{"atl":[[1.74,113.62]],"id":36749619},{"atb":[[10,16.23],[9.2,5]],"id":39791031}],"con":true,"img":false}]}
{"op":"mcm","clk":"5353303737","pt":1646212645044,"mc":[{"id":"1.195453769","rc":[{"atl":[[1.76,0]],"id":36749619}],"con":true,"img":false}]}
{"op":"mcm","clk":"5353303743","pt":1646212645149,"mc":[{"id":"1.195453769","rc":[{"atb":[[1.68,2]],"id":39734310},{"atl":[[3.6,0],[3.5,90.77],[3.4,0]],"id":38240390},{"atb":[[1.56,0],[1.54,0],[1.52,0]],"id":38678129}],"con":true,"img":false}]}
{"op":"mcm","clk":"5353303767","pt":1646212645795,"mc":[{"id":"1.195453769","rc":[{"atl":[[3.45,14.9]],"id":39734310}],"con":true,"img":false}]}
{"op":"mcm","clk":"5353303795","pt":1646212646361,"mc":[{"id":"1.195453769","rc":[{"atl":[[34,5.14]],"id":39791031}],"con":true,"img":false}]}
{"op":"mcm","clk":"5353303809","pt":1646212646568,"mc":[{"id":"1.195453769","rc":[{"atb":[[1.78,0]],"id":39734310}],"con":true,"img":false}]}
{"op":"mcm","clk":"5353303833","pt":1646212646980,"mc":[{"id":"1.195453769","rc":[{"atb":[[11,0]],"id":39791031}],"con":true,"img":false}]}
{"op":"mcm","clk":"5353303842","pt":1646212647136,"mc":[{"id":"1.195453769","rc":[{"atb":[[11.5,0],[12,1.66]],"id":39791031}],"con":true,"img":false}]}
{"op":"mcm","clk":"5353303846","pt":1646212647242,"mc":[{"id":"1.195453769","rc":[{"atb":[[12.5,2.21]],"id":39791031}],"con":true,"img":false}]}
{"op":"mcm","clk":"5353303859","pt":1646212647555,"mc":[{"id":"1.195453769","rc":[{"atb":[[2.52,23.96]],"id":38240390}],"con":true,"img":false}]}
{"op":"mcm","clk":"5353303866","pt":1646212647658,"mc":[{"id":"1.195453769","rc":[{"atb":[[2.46,0]],"id":38240390}],"con":true,"img":false}]}
{"op":"mcm","clk":"5353303871","pt":1646212647758,"mc":[{"id":"1.195453769","rc":[{"atb":[[2.26,89.22],[2.34,2.5]],"id":38240390}],"con":true,"img":false}]}
{"op":"mcm","clk":"5353303887","pt":1646212648071,"mc":[{"id":"1.195453769","rc":[{"atb":[[1.9,122.3],[1.91,5],[1.87,50.84],[1.95,2.5]],"id":38678129}],"con":true,"img":false}]}
{"op":"mcm","clk":"5353303893","pt":1646212648174,"mc":[{"id":"1.195453769","rc":[{"atb":[[1.9,184.55],[1.86,0]],"id":38678129}],"con":true,"img":false}]}
{"op":"mcm","clk":"5353303909","pt":1646212648584,"mc":[{"id":"1.195453769","rc":[{"atl":[[2.66,13.59]],"id":39734310}],"con":true,"img":false}]}
{"op":"mcm","clk":"5353303913","pt":1646212648638,"mc":[{"id":"1.195453769","rc":[{"atl":[[2.7,22.24]],"id":39734310}],"con":true,"img":false}]}
{"op":"mcm","clk":"5353303927","pt":1646212648947,"mc":[{"id":"1.195453769","rc":[{"atl":[[2.66,0]],"id":39734310},{"atb":[[2.52,19.02]],"id":38240390}],"con":true,"img":false}]}
{"op":"mcm","clk":"5353303934","pt":1646212649051,"mc":[{"id":"1.195453769","rc":[{"atl":[[2.7,39.93]],"id":39734310}],"con":true,"img":false}]}
{"op":"mcm","clk":"5353303956","pt":1646212649465,"mc":[{"id":"1.195453769","rc":[{"atb":[[1.09,0],[1.07,316.75]],"id":36749619},{"atb":[[6.8,14.75],[7.8,0]],"id":39791031}],"con":true,"img":false}]}
{"op":"mcm","clk":"5353303972","pt":1646212649774,"mc":[{"id":"1.195453769","rc":[{"atl":[[1.75,0]],"id":36749619}],"con":true,"img":false}]}
{"op":"mcm","clk":"5353304026","pt":1646212650757,"mc":[{"id":"1.195453769","rc":[{"atl":[[1.79,43.59],[2.06,164.26]],"id":36749619}],"con":true,"img":false}]}
{"op":"mcm","clk":"5353304090","pt":1646212651888,"mc":[{"id":"1.195453769","rc":[{"atb":[[1.94,8]],"id":38678129}],"con":true,"img":false}]}
{"op":"mcm","clk":"5353304141","pt":1646212652869,"mc":[{"id":"1.195453769","rc":[{"atb":[[1.74,0]],"id":38240390},{"atb":[[12,0]],"id":39791031}],"con":true,"img":false}]}
{"op":"mcm","clk":"5353304145","pt":1646212652971,"mc":[{"id":"1.195453769","rc":[{"atb":[[2.28,46.38]],"id":38240390},{"atb":[[10,8.23],[9.2,15.82],[12.5,0]],"id":39791031}],"con":true,"img":false}]}
{"op":"mcm","clk":"5353304149","pt":1646212653073,"mc":[{"id":"1.195453769","rc":[{"atb":[[1.68,0],[1.67,0],[1.66,0],[1.65,69.2]],"id":39734310},{"atl":[[2.6,12.5]],"id":39734310}],"con":true,"img":false}]}
{"op":"mcm","clk":"5353304156","pt":1646212653177,"mc":[{"id":"1.195453769","rc":[{"atb":[[9.4,4.81]],"id":39791031}],"con":true,"img":false}]}
{"op":"mcm","clk":"5353304170","pt":1646212653488,"mc":[{"id":"1.195453769","rc":[{"atb":[[1.91,30.34],[1.9,122.3]],"id":38678129}],"con":true,"img":false}]}
{"op":"mcm","clk":"5353304174","pt":1646212653590,"mc":[{"id":"1.195453769","rc":[{"atb":[[1.78,3.75]],"id":39734310},{"atb":[[1.87,10]],"id":38678129}],"con":true,"img":false}]}
{"op":"mcm","clk":"5353304200","pt":1646212654184,"mc":[{"id":"1.195453769","rc":[{"atl":[[3.55,29.41]],"id":38240390},{"atb":[[1.59,127.12]],"id":38678129}],"con":true,"img":false}]}
{"op":"mcm","clk":"5353304227","pt":1646212654648,"mc":[{"id":"1.195453769","rc":[{"atb":[[2.28,123.18]],"id":38240390},{"atb":[[1.95,31.92]],"id":38678129}],"con":true,"img":false}]}
{"op":"mcm","clk":"5353304232","pt":1646212654751,"mc":[{"id":"1.195453769","rc":[{"atb":[[2.26,5]],"id":38240390},{"atb":[[1.9,67.21]],"id":38678129}],"con":true,"img":false}]}
{"op":"mcm","clk":"5353304237","pt":1646212654852,"mc":[{"id":"1.195453769","rc":[{"atl":[[2.82,52.44],[2.72,11.63]],"id":39734310}],"con":true,"img":false}]}
{"op":"mcm","clk":"5353304241","pt":1646212654957,"mc":[{"id":"1.195453769","rc":[{"atl":[[3.45,1.78],[2.7,22.24]],"id":39734310}],"con":true,"img":false}]}
{"op":"mcm","clk":"5353304306","pt":1646212656088,"mc":[{"id":"1.195453769","rc":[{"atb":[[10.5,7.46]],"id":39791031}],"con":true,"img":false}]}
{"op":"mcm","clk":"5353304312","pt":1646212656189,"mc":[{"id":"1.195453769","rc":[{"atb":[[9.4,0]],"id":39791031}],"con":true,"img":false}]}
{"op":"mcm","clk":"5353304336","pt":1646212656655,"mc":[{"id":"1.195453769","rc":[{"atl":[[1000,2.25]],"id":36749619}],"con":true,"img":false}]}
{"op":"mcm","clk":"5353304351","pt":1646212656963,"mc":[{"id":"1.195453769","rc":[{"atl":[[3.3,8.7]],"id":38240390},{"atl":[[1000,1.18]],"id":36749619}],"con":true,"img":false}]}
{"op":"mcm","clk":"5353304354","pt":1646212657064,"mc":[{"id":"1.195453769","rc":[{"atl":[[3.3,29.49],[3.5,0],[3.45,82.06]],"id":38240390}],"con":true,"img":false}]}
{"op":"mcm","clk":"5353304356","pt":1646212657173,"mc":[{"id":"1.195453769","rc":[{"atl":[[3.35,8.51]],"id":38240390}],"con":true,"img":false}]}
{"op":"mcm","clk":"5353304365","pt":1646212657372,"mc":[{"id":"1.195453769","rc":[{"atl":[[1000,0]],"id":36749619}],"con":true,"img":false}]}
{"op":"mcm","clk":"5353304368","pt":1646212657475,"mc":[{"id":"1.195453769","rc":[{"atl":[[1.73,1.18]],"id":36749619}],"con":true,"img":false}]}
{"op":"mcm","clk":"5353304379","pt":1646212657635,"mc":[{"id":"1.195453769","rc":[{"atl":[[1.72,5.51]],"id":36749619}],"con":true,"img":false}]}
{"op":"mcm","clk":"5353304398","pt":1646212657901,"mc":[{"id":"1.195453769","rc":[{"atb":[[1.13,293.91]],"id":36749619},{"atl":[[1.74,108.11]],"id":36749619}],"con":true,"img":false}]}
{"op":"mcm","clk":"5353304403","pt":1646212657999,"mc":[{"id":"1.195453769","rc":[{"atb":[[1.15,99.78]],"id":36749619}],"con":true,"img":false}]}
{"op":"mcm","clk":"5353304416","pt":1646212658155,"mc":[{"id":"1.195453769","rc":[{"atb":[[1.14,474.9],[1.13,5]],"id":36749619}],"con":true,"img":false}]}
{"op":"mcm","clk":"5353304443","pt":1646212658568,"mc":[{"id":"1.195453769","rc":[{"atl":[[1.79,232.86],[2.06,2.5]],"id":36749619}],"con":true,"img":false}]}
{"op":"mcm","clk":"5353304456","pt":1646212658770,"mc":[{"id":"1.195453769","rc":[{"atb":[[1.69,22.97]],"id":39734310}],"con":true,"img":false}]}
{"op":"mcm","clk":"5353304460","pt":1646212658873,"mc":[{"id":"1.195453769","rc":[{"atb":[[11,1.66]],"id":39791031}],"con":true,"img":false}]}
{"op":"mcm","clk":"5353304474","pt":1646212659080,"mc":[{"id":"1.195453769","rc":[{"atl":[[3.3,20.79]],"id":38240390},{"atb":[[1.06,2266.45],[1.08,577.76]],"id":36749619},{"atl":[[2.72,3]],"id":36749619}],"con":true,"img":false}]}
{"op":"mcm","clk":"5353304478","pt":1646212659184,"mc":[{"id":"1.195453769","rc":[{"atl":[[2.6,24.97]],"id":39734310}],"con":true,"img":false}]}
{"op":"mcm","clk":"5353304485","pt":1646212659286,"mc":[{"id":"1.195453769","rc":[{"atl":[[2.72,0],[1.84,4]],"id":36749619}],"con":true,"img":false}]}
{"op":"mcm","clk":"5353304493","pt":1646212659389,"mc":[{"id":"1.195453769","rc":[{"atl":[[2.6,12.5]],"id":39734310}],"con":true,"img":false}]}
{"op":"mcm","clk":"5353304498","pt":1646212659492,"mc":[{"id":"1.195453769","rc":[{"atl":[[1.72,116.62]],"id":36749619},{"atb":[[10,18.45],[9.2,5]],"id":39791031}],"con":true,"img":false}]}
{"op":"mcm","clk":"5353304503","pt":1646212659595,"mc":[{"id":"1.195453769","rc":[{"atl":[[1.74,0]],"id":36749619}],"con":true,"img":false}]}
{"op":"mcm","clk":"5353304509","pt":1646212659698,"mc":[{"id":"1.195453769","rc":[{"atb":[[1.45,44.44],[1.41,0]],"id":38240390},{"atl":[[3.1,38.1]],"id":38678129},{"atl":[[1.83,2]],"id":36749619}],"con":true,"img":false}]}
{"op":"mcm","clk":"5353304521","pt":1646212659855,"mc":[{"id":"1.195453769","rc":[{"atl":[[3.1,0]],"id":38678129}],"con":true,"img":false}]}
{"op":"mcm","clk":"5353304525","pt":1646212659956,"mc":[{"id":"1.195453769","rc":[{"atl":[[3.3,62.03]],"id":38678129},{"atl":[[1.82,2]],"id":36749619}],"con":true,"img":false}]}
{"op":"mcm","clk":"5353304552","pt":1646212660373,"mc":[{"id":"1.195453769","rc":[{"atl":[[2.72,36.58],[2.7,0]],"id":39734310},{"atb":[[1.92,35.1]],"id":38678129}],"con":true,"img":false}]}
{"op":"mcm","clk":"5353304559","pt":1646212660472,"mc":[{"id":"1.195453769","rc":[{"atl":[[2.8,22.24]],"id":39734310}],"con":true,"img":false}]}
{"op":"mcm","clk":"5353304565","pt":1646212660575,"mc":[{"id":"1.195453769","rc":[{"atb":[[2.34,8.1]],"id":38240390}],"con":true,"img":false}]}
{"op":"mcm","clk":"5353304567","pt":1646212660679,"mc":[{"id":"1.195453769","rc":[{"atb":[[1.41,48.78]],"id":38240390},{"atl":[[3.1,9.52]],"id":38678129},{"atl":[[1.83,0],[1.84,0],[1.82,0]],"id":36749619}],"con":true,"img":false}]}
{"op":"mcm","clk":"5353304574","pt":1646212660781,"mc":[{"id":"1.195453769","rc":[{"atb":[[1.45,0]],"id":38240390}],"con":true,"img":false}]}
{"op":"mcm","clk":"5353304610","pt":1646212661345,"mc":[{"id":"1.195453769","rc":[{"atl":[[2.6,19.06]],"id":39734310}],"con":true,"img":false}]}
{"op":"mcm","clk":"5353304626","pt":1646212661655,"mc":[{"id":"1.195453769","rc":[{"atl":[[2.82,0],[2.78,55.94]],"id":39734310},{"atb":[[1.18,2.03]],"id":36749619}],"con":true,"img":false}]}
{"op":"mcm","clk":"5353304635","pt":1646212661759,"mc":[{"id":"1.195453769","rc":[{"atl":[[2.6,12.5]],"id":39734310},{"atb":[[1.18,164.33]],"id":36749619}],"con":true,"img":false}]}
{"op":"mcm","clk":"5353304640","pt":1646212661860,"mc":[{"id":"1.195453769","rc":[{"atb":[[1.17,2.5]],"id":36749619},{"atl":[[1.79,189.27]],"id":36749619},{"atb":[[11.5,5.11]],"id":39791031}],"con":true,"img":false}]}
{"op":"mcm","clk":"5353304644","pt":1646212661963,"mc":[{"id":"1.195453769","rc":[{"atl":[[1.71,43.59]],"id":36749619},{"atb":[[10.5,0]],"id":39791031}],"con":true,"img":false}]}
{"op":"mcm","clk":"5353304652","pt":1646212662066,"mc":[{"id":"1.195453769","rc":[{"atl":[[2.6,25.62]],"id":39734310},{"atl":[[1.7,5.51]],"id":36749619}],"con":true,"img":false}]}
{"op":"mcm","clk":"5353304661","pt":1646212662272,"mc":[{"id":"1.195453769","rc":[{"atl":[[1.72,111.11]],"id":36749619}],"con":true,"img":false}]}
{"op":"mcm","clk":"5353304681","pt":1646212662789,"mc":[{"id":"1.195453769","rc":[{"atb":[[1.92,97.26],[1.91,5]],"id":38678129}],"con":true,"img":false}]}
{"op":"mcm","clk":"5353304689","pt":1646212662994,"mc":[{"id":"1.195453769","rc":[{"atl":[[4.1,0]],"id":38240390}],"con":true,"img":false}]}
{"op":"mcm","clk":"5353304692","pt":1646212663046,"mc":[{"id":"1.195453769","rc":[{"atl":[[4,17.09]],"id":38240390}],"con":true,"img":false}]}
{"op":"mcm","clk":"5353304710","pt":1646212663254,"mc":[{"id":"1.195453769","rc":[{"atb":[[1.65,72.2]],"id":39734310},{"atl":[[2.6,13.12]],"id":39734310}],"con":true,"img":false}]}
{"op":"mcm","clk":"5353304722","pt":1646212663460,"mc":[{"id":"1.195453769","rc":[{"atl":[[2.6,0]],"id":39734310}],"con":true,"img":false}]}
{"op":"mcm","clk":"5353304729","pt":1646212663563,"mc":[{"id":"1.195453769","rc":[{"atl":[[2.72,43.14],[2.76,28.41]],"id":39734310}],"con":true,"img":false}]}
{"op":"mcm","clk":"5353304736","pt":1646212663668,"mc":[{"id":"1.195453769","rc":[{"atb":[[1.94,0]],"id":38678129}],"con":true,"img":false}]}
{"op":"mcm","clk":"5353304762","pt":1646212664078,"mc":[{"id":"1.195453769","rc":[{"atb":[[1.78,0]],"id":39734310},{"atb":[[1.14,295.8]],"id":36749619}],"con":true,"img":false}]}
{"op":"mcm","clk":"5353304768","pt":1646212664180,"mc":[{"id":"1.195453769","rc":[{"atl":[[1.73,0]],"id":36749619}],"con":true,"img":false}]}
{"op":"mcm","clk":"5353304773","pt":1646212664284,"mc":[{"id":"1.195453769","rc":[{"atb":[[1.66,4]],"id":39734310}],"con":true,"img":false}]}
{"op":"mcm","clk":"5353304801","pt":1646212664854,"mc":[{"id":"1.195453769","rc":[{"atb":[[1.67,2]],"id":39734310},{"atb":[[11,0]],"id":39791031}],"con":true,"img":false}]}
{"op":"mcm","clk":"5353304804","pt":1646212664958,"mc":[{"id":"1.195453769","rc":[{"atb":[[9.2,20.16]],"id":39791031}],"con":true,"img":false}]}
{"op":"mcm","clk":"5353304809","pt":1646212665062,"mc":[{"id":"1.195453769","rc":[{"atb":[[10,8.23],[11.5,0]],"id":39791031}],"con":true,"img":false}]}
{"op":"mcm","clk":"5353304815","pt":1646212665165,"mc":[{"id":"1.195453769","rc":[{"atb":[[9.4,4.81]],"id":39791031}],"con":true,"img":false}]}
{"op":"mcm","clk":"5353304818","pt":1646212665269,"mc":[{"id":"1.195453769","rc":[{"atl":[[1.72,310.9]],"id":36749619}],"con":true,"img":false}]}
{"op":"mcm","clk":"5353304822","pt":1646212665372,"mc":[{"id":"1.195453769","rc":[{"atl":[[1.79,0]],"id":36749619}],"con":true,"img":false}]}
{"op":"mcm","clk":"5353304861","pt":1646212666199,"mc":[{"id":"1.195453769","rc":[{"atb":[[1.68,4]],"id":39734310}],"con":true,"img":false}]}
{"op":"mcm","clk":"5353304908","pt":1646212667082,"mc":[{"id":"1.195453769","rc":[{"atl":[[2.72,18.19],[2.78,113.55]],"id":39734310}],"con":true,"img":false}]}
{"op":"mcm","clk":"5353304919","pt":1646212667287,"mc":[{"id":"1.195453769","rc":[{"atl":[[2.04,2.5],[2.14,0],[2.06,0]],"id":36749619}],"con":true,"img":false}]}
{"op":"mcm","clk":"5353304927","pt":1646212667493,"mc":[{"id":"1.195453769","rc":[{"atb":[[1.58,0]],"id":38240390}],"con":true,"img":false}]}
{"op":"mcm","clk":"5353304933","pt":1646212667596,"mc":[{"id":"1.195453769","rc":[{"atb":[[1.71,70.48]],"id":38240390},{"atb":[[10.5,7.46]],"id":39791031}],"con":true,"img":false}]}
{"op":"mcm","clk":"5353304938","pt":1646212667698,"mc":[{"id":"1.195453769","rc":[{"atb":[[9.4,0]],"id":39791031}],"con":true,"img":false}]}
{"op":"mcm","clk":"5353304942","pt":1646212667801,"mc":[{"id":"1.195453769","rc":[{"atb":[[9.2,5],[9.4,14.92]],"id":39791031}],"con":true,"img":false}]}
{"op":"mcm","clk":"5353305030","pt":1646212668777,"mc":[{"id":"1.195453769","rc":[{"spl":[[1.01,2.72]],"id":36749619}],"con":true,"img":false}]}
{"op":"mcm","clk":"5353305056","pt":1646212669492,"mc":[{"id":"1.195453769","rc":[{"atb":[[1.92,35.1],[1.91,67.16]],"id":38678129}],"con":true,"img":false}]}
{"op":"mcm","clk":"5353305112","pt":1646212670471,"mc":[{"id":"1.195453769","rc":[{"atb":[[2.34,14.32]],"id":38240390}],"con":true,"img":false}]}
{"op":"mcm","clk":"5353305132","pt":1646212670882,"mc":[{"id":"1.195453769","rc":[{"atb":[[11,1.66]],"id":39791031}],"con":true,"img":false}]}
{"op":"mcm","clk":"5353305137","pt":1646212670986,"mc":[{"id":"1.195453769","rc":[{"atl":[[3.65,47.17]],"id":38240390},{"atb":[[1.57,305.84]],"id":38678129},{"atb":[[11.5,5.11]],"id":39791031}],"con":true,"img":false}]}
{"op":"mcm","clk":"5353305141","pt":1646212671090,"mc":[{"id":"1.195453769","rc":[{"atb":[[10.5,0]],"id":39791031}],"con":true,"img":false}]}
{"op":"mcm","clk":"5353305146","pt":1646212671190,"mc":[{"id":"1.195453769","rc":[{"atb":[[1.78,3.75]],"id":39734310},{"atb":[[1.19,115.03]],"id":36749619}],"con":true,"img":false}]}
{"op":"mcm","clk":"5353305151","pt":1646212671294,"mc":[{"id":"1.195453769","rc":[{"atl":[[1000,2.25]],"id":36749619}],"con":true,"img":false}]}
{"op":"mcm","clk":"5353305156","pt":1646212671396,"mc":[{"id":"1.195453769","rc":[{"atb":[[1.18,162.3]],"id":36749619}],"con":true,"img":false}]}
{"op":"mcm","clk":"5353305162","pt":1646212671603,"mc":[{"id":"1.195453769","rc":[{"atb":[[1.2,2.21]],"id":36749619},{"atl":[[1000,1.21]],"id":36749619}],"con":true,"img":false}]}
{"op":"mcm","clk":"5353305172","pt":1646212671807,"mc":[{"id":"1.195453769","rc":[{"atl":[[1000,0]],"id":36749619}],"con":true,"img":false}]}
{"op":"mcm","clk":"5353305175","pt":1646212671909,"mc":[{"id":"1.195453769","rc":[{"atl":[[1.69,1.21]],"id":36749619}],"con":true,"img":false}]}
{"op":"mcm","clk":"5353305181","pt":1646212672012,"mc":[{"id":"1.195453769","rc":[{"atb":[[2.28,76.8]],"id":38240390}],"con":true,"img":false}]}
{"op":"mcm","clk":"5353305186","pt":1646212672114,"mc":[{"id":"1.195453769","rc":[{"atb":[[2.06,46.38]],"id":38240390},{"atl":[[1.68,5.51]],"id":36749619}],"con":true,"img":false}]}
{"op":"mcm","clk":"5353305192","pt":1646212672217,"mc":[{"id":"1.195453769","rc":[{"atl":[[1.7,0]],"id":36749619}],"con":true,"img":false}]}
{"op":"mcm","clk":"5353305210","pt":1646212672580,"mc":[{"id":"1.195453769","rc":[{"atb":[[1.18,402.06],[1.14,0]],"id":36749619}],"con":true,"img":false}]}
{"op":"mcm","clk":"5353305281","pt":1646212673780,"mc":[{"id":"1.195453769","rc":[{"atl":[[2.8,63.91]],"id":39734310},{"atb":[[1.62,72.11],[1.57,219.3]],"id":38678129},{"atl":[[1.68,42.34]],"id":36749619},{"atb":[[10,18.4],[9.4,0]],"id":39791031}],"con":true,"img":false}]}
{"op":"mcm","clk":"5353305291","pt":1646212673989,"mc":[{"id":"1.195453769","rc":[{"atl":[[1.72,199.79]],"id":36749619}],"con":true,"img":false}]}
{"op":"mcm","clk":"5353305317","pt":1646212674299,"mc":[{"id":"1.195453769","rc":[{"atl":[[3.1,47.62]],"id":38678129}],"con":true,"img":false}]}
{"op":"mcm","clk":"5353305333","pt":1646212674506,"mc":[{"id":"1.195453769","rc":[{"atl":[[3.3,32.61]],"id":38678129}],"con":true,"img":false}]}
{"op":"mcm","clk":"5353305388","pt":1646212675592,"mc":[{"id":"1.195453769","rc":[{"atb":[[1.95,39.83]],"id":38678129}],"con":true,"img":false}]}
{"op":"mcm","clk":"5353305415","pt":1646212676110,"mc":[{"id":"1.195453769","rc":[{"atb":[[1.2,66.66]],"id":36749619}],"con":true,"img":false}]}
{"op":"mcm","clk":"5353305427","pt":1646212676312,"mc":[{"id":"1.195453769","rc":[{"atb":[[1.18,239.76]],"id":36749619}],"con":true,"img":false}]}
{"op":"mcm","clk":"5353305429","pt":1646212676416,"mc":[{"id":"1.195453769","rc":[{"atb":[[1.68,0],[1.67,0],[1.66,0],[1.65,69.2]],"id":39734310},{"atl":[[2.8,41.67]],"id":39734310}],"con":true,"img":false}]}
{"op":"mcm","clk":"5353305433","pt":1646212676517,"mc":[{"id":"1.195453769","rc":[{"atl":[[2.76,50.65]],"id":39734310}],"con":true,"img":false}]}
{"op":"mcm","clk":"5353305441","pt":1646212676671,"mc":[{"id":"1.195453769","rc":[{"atl":[[2.74,50.66]],"id":39734310}],"con":true,"img":false}]}
{"op":"mcm","clk":"5353305447","pt":1646212676775,"mc":[{"id":"1.195453769","rc":[{"atl":[[2.78,0.3],[2.76,85.44]],"id":39734310}],"con":true,"img":false}]}
{"op":"mcm","clk":"5353305451","pt":1646212676881,"mc":[{"id":"1.195453769","rc":[{"atb":[[11,0]],"id":39791031}],"con":true,"img":false}]}
{"op":"mcm","clk":"5353305455","pt":1646212676983,"mc":[{"id":"1.195453769","rc":[{"atb":[[12,1.66]],"id":39791031}],"con":true,"img":false}]}
{"op":"mcm","clk":"5353305457","pt":1646212677087,"mc":[{"id":"1.195453769","rc":[{"atb":[[10,8.23],[9.2,20.16],[11.5,0],[12.5,5.08]],"id":39791031}],"con":true,"img":false}]}
{"op":"mcm","clk":"5353305484","pt":1646212677916,"mc":[{"id":"1.195453769","rc":[{"atb":[[1.15,0]],"id":36749619}],"con":true,"img":false}]}
{"op":"mcm","clk":"5353305490","pt":1646212678018,"mc":[{"id":"1.195453769","rc":[{"atb":[[1.13,104.78]],"id":36749619}],"con":true,"img":false}]}
{"op":"mcm","clk":"5353305493","pt":1646212678123,"mc":[{"id":"1.195453769","rc":[{"atl":[[1.69,0]],"id":36749619}],"con":true,"img":false}]}
{"op":"mcm","clk":"5353305518","pt":1646212678588,"mc":[{"id":"1.195453769","rc":[{"atb":[[1.71,0]],"id":38240390}],"con":true,"img":false}]}
{"op":"mcm","clk":"5353305524","pt":1646212678690,"mc":[{"id":"1.195453769","rc":[{"atb":[[1.63,70.48]],"id":38240390}],"con":true,"img":false}]}
{"op":"mcm","clk":"5353305533","pt":1646212678900,"mc":[{"id":"1.195453769","rc":[{"atb":[[1.85,0],[1.81,0]],"id":39734310}],"con":true,"img":false}]}
{"op":"mcm","clk":"5353305552","pt":1646212679207,"mc":[{"id":"1.195453769","rc":[{"atb":[[10,18.35],[9.2,5]],"id":39791031}],"con":true,"img":false}]}
{"op":"mcm","clk":"5353305693","pt":1646212681796,"mc":[{"id":"1.195453769","rc":[{"atb":[[1.78,0]],"id":39734310},{"atb":[[1.19,0]],"id":36749619}],"con":true,"img":false}]}
{"op":"mcm","clk":"5353305696","pt":1646212681897,"mc":[{"id":"1.195453769","rc":[{"atl":[[3.5,0]],"id":38678129},{"atb":[[1.17,167.91]],"id":36749619}],"con":true,"img":false}]}
{"op":"mcm","clk":"5353305703","pt":1646212682002,"mc":[{"id":"1.195453769","rc":[{"atl":[[3.25,28.26]],"id":38678129},{"atb":[[1.18,0]],"id":36749619}],"con":true,"img":false}]}
{"op":"mcm","clk":"5353305760","pt":1646212682930,"mc":[{"id":"1.195453769","rc":[{"spl":[[1.01,5.44]],"id":36749619},{"atb":[[12,0]],"id":39791031}],"con":true,"img":false}]}
{"op":"mcm","clk":"5353305766","pt":1646212683033,"mc":[{"id":"1.195453769","rc":[{"atb":[[2.26,0],[2.34,11.82],[2.36,2.5],[2.28,81.8],[2.18,0]],"id":38240390}],"con":true,"img":false}]}
{"op":"mcm","clk":"5353305775","pt":1646212683084,"mc":[{"id":"1.195453769","rc":[{"atb":[[10,8.23],[9.2,20.12],[12.5,0],[13,1.66]],"id":39791031}],"con":true,"img":false}]}
{"op":"mcm","clk":"5353305780","pt":1646212683188,"mc":[{"id":"1.195453769","rc":[{"atb":[[2.34,60.6],[2.28,5]],"id":38240390},{"atb":[[13.5,2.21]],"id":39791031}],"con":true,"img":false}]}
{"op":"mcm","clk":"5353305827","pt":1646212683914,"mc":[{"id":"1.195453769","rc":[{"atl":[[2.84,67.93]],"id":39734310},{"atb":[[2.06,0]],"id":38240390}],"con":true,"img":false}]}
{"op":"mcm","clk":"5353305832","pt":1646212684012,"mc":[{"id":"1.195453769","rc":[{"atb":[[1.94,46.38]],"id":38240390}],"con":true,"img":false}]}
{"op":"mcm","clk":"5353305888","pt":1646212684888,"mc":[{"id":"1.195453769","rc":[{"atb":[[2.34,54.99]],"id":38240390}],"con":true,"img":false}]}
{"op":"mcm","clk":"5353305926","pt":1646212685718,"mc":[{"id":"1.195453769","rc":[{"atl":[[1000,2.25]],"id":36749619}],"con":true,"img":false}]}
{"op":"mcm","clk":"5353305944","pt":1646212686027,"mc":[{"id":"1.195453769","rc":[{"atl":[[1000,1.22]],"id":36749619}],"con":true,"img":false}]}
{"op":"mcm","clk":"5353305961","pt":1646212686302,"mc":[{"id":"1.195453769","rc":[{"atl":[[1000,0]],"id":36749619}],"con":true,"img":false}]}
{"op":"mcm","clk":"5353305965","pt":1646212686404,"mc":[{"id":"1.195453769","rc":[{"atl":[[1.67,1.22]],"id":36749619}],"con":true,"img":false}]}
{"op":"mcm","clk":"5353305970","pt":1646212686508,"mc":[{"id":"1.195453769","rc":[{"atl":[[1.66,5.51]],"id":36749619}],"con":true,"img":false}]}
{"op":"mcm","clk":"5353305975","pt":1646212686611,"mc":[{"id":"1.195453769","rc":[{"atl":[[1.68,36.83],[1.71,209],[1.72,0]],"id":36749619}],"con":true,"img":false}]}
{"op":"mcm","clk":"5353305995","pt":1646212687023,"mc":[{"id":"1.195453769","rc":[{"atl":[[4,0]],"id":38240390}],"con":true,"img":false}]}
{"op":"mcm","clk":"5353306000","pt":1646212687125,"mc":[{"id":"1.195453769","rc":[{"atl":[[3.6,17.09]],"id":38240390}],"con":true,"img":false}]}
{"op":"mcm","clk":"5353306034","pt":1646212687794,"mc":[{"id":"1.195453769","rc":[{"atl":[[1.66,83.13]],"id":36749619},{"atb":[[10,14.05]],"id":39791031}],"con":true,"img":false}]}
{"op":"mcm","clk":"5353306037","pt":1646212687896,"mc":[{"id":"1.195453769","rc":[{"atb":[[9.2,5]],"id":39791031}],"con":true,"img":false}]}
{"op":"mcm","clk":"5353306046","pt":1646212688000,"mc":[{"id":"1.195453769","rc":[{"atl":[[1.68,0]],"id":36749619}],"con":true,"img":false}]}
{"op":"mcm","clk":"5353306072","pt":1646212688413,"mc":[{"id":"1.195453769","rc":[{"atl":[[2.72,6.56],[2.6,12.5]],"id":39734310},{"atb":[[1.13,386.64]],"id":36749619}],"con":true,"img":false}]}
{"op":"mcm","clk":"5353306080","pt":1646212688519,"mc":[{"id":"1.195453769","rc":[{"atl":[[2.74,103.86],[2.6,39.1]],"id":39734310},{"atb":[[1.17,2.5]],"id":36749619}],"con":true,"img":false}]}
{"op":"mcm","clk":"5353306086","pt":1646212688621,"mc":[{"id":"1.195453769","rc":[{"atl":[[2.72,0],[2.76,50.65]],"id":39734310}],"con":true,"img":false}]}
{"op":"mcm","clk":"5353306094","pt":1646212688929,"mc":[{"id":"1.195453769","rc":[{"atb":[[13,0]],"id":39791031}],"con":true,"img":false}]}
{"op":"mcm","clk":"5353306104","pt":1646212689137,"mc":[{"id":"1.195453769","rc":[{"atl":[[2.72,11.63],[2.6,26.6]],"id":39734310},{"atl":[[3.35,0],[3.4,8.33]],"id":38240390},{"atb":[[13.5,0]],"id":39791031}],"con":true,"img":false}]}
{"op":"mcm","clk":"5353306108","pt":1646212689238,"mc":[{"id":"1.195453769","rc":[{"atb":[[10.5,5.41]],"id":39791031}],"con":true,"img":false}]}
{"op":"mcm","clk":"5353306116","pt":1646212689290,"mc":[{"id":"1.195453769","rc":[{"atl":[[2.6,0]],"id":39734310},{"atl":[[3.3,0]],"id":38240390}],"con":true,"img":false}]}
{"op":"mcm","clk":"5353306122","pt":1646212689436,"mc":[{"id":"1.195453769","rc":[{"atl":[[2.74,129.81]],"id":39734310},{"atl":[[3.45,28.53],[3.55,104.56]],"id":38240390}],"con":true,"img":false}]}
{"op":"mcm","clk":"5353306130","pt":1646212689503,"mc":[{"id":"1.195453769","rc":[{"atb":[[1.66,19]],"id":39734310},{"atb":[[1.14,93.33]],"id":36749619}],"con":true,"img":false}]}
{"op":"mcm","clk":"5353306137","pt":1646212689603,"mc":[{"id":"1.195453769","rc":[{"atb":[[10,8.23],[9.2,20.21]],"id":39791031}],"con":true,"img":false}]}
{"op":"mcm","clk":"5353306184","pt":1646212690630,"mc":[{"id":"1.195453769","rc":[{"atb":[[2.4,5.36]],"id":38240390}],"con":true,"img":false}]}
{"op":"mcm","clk":"5353306199","pt":1646212690835,"mc":[{"id":"1.195453769","rc":[{"atl":[[2.74,79.15],[2.76,107.47]],"id":39734310}],"con":true,"img":false}]}
{"op":"mcm","clk":"5353306300","pt":1646212692431,"mc":[{"id":"1.195453769","rc":[{"atl":[[2.76,85.23]],"id":39734310},{"spn":2.24,"spf":"NaN","id":39734310},{"spn":2.97,"spf":"NaN","id":38240390},{"spn":2.52,"spf":"NaN","id":38678129},{"spn":1.2,"spf":1.0,"id":36749619}],"con":true,"img":false}]}
{"op":"mcm","clk":"5353306306","pt":1646212692534,"mc":[{"id":"1.195453769","rc":[{"atl":[[2.72,33.87]],"id":39734310}],"con":true,"img":false}]}
{"op":"mcm","clk":"5353306311","pt":1646212692637,"mc":[{"id":"1.195453769","rc":[{"atl":[[1.67,0]],"id":36749619}],"con":true,"img":false}]}
{"op":"mcm","clk":"5353306339","pt":1646212693102,"mc":[{"id":"1.195453769","rc":[{"atl":[[2.04,180.67],[1.71,43.59]],"id":36749619}],"con":true,"img":false}]}
{"op":"mcm","clk":"5353306358","pt":1646212693515,"mc":[{"id":"1.195453769","rc":[{"atl":[[2.72,22.24],[2.64,12.2]],"id":39734310}],"con":true,"img":false}]}
{"op":"mcm","clk":"5353306427","pt":1646212694905,"mc":[{"id":"1.195453769","rc":[{"atb":[[1.71,0]],"id":38678129},{"atb":[[11,1.66]],"id":39791031}],"con":true,"img":false}]}
{"op":"mcm","clk":"5353306430","pt":1646212695005,"mc":[{"id":"1.195453769","rc":[{"atb":[[1.96,50.69]],"id":38678129},{"atb":[[10,18.45],[9.2,5],[11.5,5.11]],"id":39791031}],"con":true,"img":false}]}
{"op":"mcm","clk":"5353306437","pt":1646212695109,"mc":[{"id":"1.195453769","rc":[{"atb":[[1.96,106.9],[1.92,147.53]],"id":38678129}],"con":true,"img":false}]}
{"op":"mcm","clk":"5353306443","pt":1646212695213,"mc":[{"id":"1.195453769","rc":[{"atl":[[2.76,28.41],[2.7,58.82]],"id":39734310},{"atb":[[1.91,5]],"id":38678129},{"atb":[[10.5,0]],"id":39791031}],"con":true,"img":false}]}
{"op":"mcm","clk":"5353306447","pt":1646212695315,"mc":[{"id":"1.195453769","rc":[{"atl":[[2.72,84.12]],"id":39734310},{"atb":[[1.95,10.41]],"id":38678129}],"con":true,"img":false}]}
{"op":"mcm","clk":"5353306453","pt":1646212695418,"mc":[{"id":"1.195453769","rc":[{"atl":[[2.74,25.95]],"id":39734310}],"con":true,"img":false}]}
{"op":"mcm","clk":"5353306457","pt":1646212695519,"mc":[{"id":"1.195453769","rc":[{"atb":[[1.95,19.19]],"id":38678129}],"con":true,"img":false}]}
{"op":"mcm","clk":"5353306476","pt":1646212695829,"mc":[{"id":"1.195453769","rc":[{"atb":[[1.14,318.03],[1.13,104.78]],"id":36749619}],"con":true,"img":false}]}
{"op":"mcm","clk":"5353306508","pt":1646212696445,"mc":[{"id":"1.195453769","rc":[{"atb":[[1.09,224.13],[1.07,0]],"id":36749619}],"con":true,"img":false}]}
{"op":"mcm","clk":"5353306528","pt":1646212696702,"mc":[{"id":"1.195453769","rc":[{"atb":[[1.95,11.27]],"id":38678129}],"con":true,"img":false}]}
{"op":"mcm","clk":"5353306554","pt":1646212697116,"mc":[{"id":"1.195453769","rc":[{"atb":[[2.36,46.03]],"id":38240390}],"con":true,"img":false}]}
{"op":"mcm","clk":"5353306561","pt":1646212697219,"mc":[{"id":"1.195453769","rc":[{"atb":[[2.34,6.21]],"id":38240390}],"con":true,"img":false}]}
{"op":"mcm","clk":"5353306646","pt":1646212699018,"mc":[{"id":"1.195453769","rc":[{"atl":[[3.5,20]],"id":38240390}],"con":true,"img":false}]}
{"op":"mcm","clk":"5353306690","pt":1646212699532,"mc":[{"id":"1.195453769","rc":[{"atl":[[3.55,75.15],[3.45,8.12],[3.65,0]],"id":38240390}],"con":true,"img":false}]}
{"op":"mcm","clk":"5353306698","pt":1646212699637,"mc":[{"id":"1.195453769","rc":[{"atb":[[1.66,0]],"id":39734310},{"atb":[[1.92,112.43]],"id":38678129}],"con":true,"img":false}]}
{"op":"mcm","clk":"5353306704","pt":1646212699739,"mc":[{"id":"1.195453769","rc":[{"atl":[[1000,2.25]],"id":36749619}],"con":true,"img":false}]}
{"op":"mcm","clk":"5353306719","pt":1646212700050,"mc":[{"id":"1.195453769","rc":[{"atb":[[2.4,0]],"id":38240390},{"atl":[[1000,1.24]],"id":36749619}],"con":true,"img":false}]}
{"op":"mcm","clk":"5353306738","pt":1646212700359,"mc":[{"id":"1.195453769","rc":[{"atl":[[1000,0]],"id":36749619}],"con":true,"img":false}]}
{"op":"mcm","clk":"5353306744","pt":1646212700410,"mc":[{"id":"1.195453769","rc":[{"atl":[[1.65,1.24]],"id":36749619}],"con":true,"img":false}]}
{"op":"mcm","clk":"5353306749","pt":1646212700513,"mc":[{"id":"1.195453769","rc":[{"atl":[[1.64,5.51]],"id":36749619}],"con":true,"img":false}]}
{"op":"mcm","clk":"5353306757","pt":1646212700618,"mc":[{"id":"1.195453769","rc":[{"atl":[[1.71,209]],"id":36749619}],"con":true,"img":false}]}
