{"op":"mcm","clk":"5345985297","pt":1646174444260,"mc":[{"id":"1.195453611","marketDefinition":{"bspMarket":true,"turnInPlayEnabled":false,"persistenceEnabled":false,"marketBaseRate":7.0,"eventId":"31272494","eventTypeId":"4339","numberOfWinners":1,"bettingType":"ODDS","marketType":"WIN","marketTime":"2022-03-02T08:51:00.000Z","suspendTime":"2022-03-02T08:51:00.000Z","bspReconciled":false,"complete":true,"inPlay":false,"crossMatching":false,"runnersVoidable":false,"numberOfActiveRunners":6,"betDelay":0,"status":"OPEN","runners":[{"status":"ACTIVE","sortPriority":1,"id":43066529,"name":"1. Piopio"},{"status":"ACTIVE","sortPriority":2,"id":41676292,"name":"2. Jasper Bale"},{"status":"ACTIVE","sortPriority":3,"id":41762566,"name":"3. Afro Boy"},{"status":"ACTIVE","sortPriority":4,"id":42651625,"name":"4. Average Axel"},{"status":"ACTIVE","sortPriority":5,"id":43167172,"name":"6. Fancy Like"},{"status":"ACTIVE","sortPriority":6,"id":43167173,"name":"8. Simon Rose"}],"regulators":["MR_INT"],"venue":"Traralgon","countryCode":"AU","discountAllowed":true,"timezone":"Australia/Sydney","openDate":"2022-03-02T08:31:00.000Z","version":4382425361,"name":"R2 395m Gr6/7","eventName":"Traralgon (AUS) 2nd Mar"},"rc":[],"con":true,"img":false}]}
{"op":"mcm","clk":"5346059516","pt":1646175786519,"mc":[{"id":"1.195453611","rc":[{"atb":[[6.8,28.15],[9.8,4.63],[8.8,10.46],[7.8,12],[14.5,3.02]],"id":41762566},{"atl":[[270,0.74],[170,0.78],[220,0.9],[120,1.11]],"id":41762566},{"spn":67.25,"spf":"NaN","id":41762566},{"atb":[[2.82,22.43],[2.72,47.47],[2.52,107.44],[2.62,50.4],[3.05,19.91]],"id":43066529},{"atl":[[9.2,16.22],[10.5,21],[8.2,18.47],[13,16.63]],"id":43066529},{"spn":5.62,"spf":"NaN","id":43066529},{"atb":[[6.8,28.15],[9.8,4.63],[8.8,10.46],[7.8,12],[14.5,3.02]],"id":42651625},{"atl":[[270,0.74],[170,0.78],[220,0.9],[120,1.11]],"id":42651625},{"spn":67.25,"spf":"NaN","id":42651625},{"atb":[[4.8,42.97],[8.6,5.37],[5.8,17.01],[5.3,18.98],[6.6,7.28]],"id":41676292},{"atl":[[65,2.07],[130,1.54],[90,2.24],[46,2.95]],"id":41676292},{"spn":27.3,"spf":"NaN","id":41676292},{"atb":[[1.8,204.13],[1.85,96.06],[1.9,90.72],[1.95,42.97],[2.1,37.11]],"id":43167172},{"atl":[[5.8,27.71],[5.3,30.94],[7.6,30.23],[6.6,35.63]],"id":43167172},{"spn":3.7,"spf":"NaN","id":43167172},{"atb":[[2,163.3],[2.5,27.21],[2.3,31.4],[2.2,68.04],[2.1,74.22]],"id":43167173},{"atl":[[8,28.5],[9,24.94],[6,26.6],[7,22.17]],"id":43167173},{"spn":4.25,"spf":"NaN","id":43167173}],"con":true,"img":false}]}
{"op":"mcm","clk":"5346061998","pt":1646175839944,"mc":[{"id":"1.195453611","rc":[{"atb":[[6.8,0],[9.8,0],[8.8,0],[7.8,0],[14.5,0]],"id":41762566},{"atl":[[270,0],[170,0],[220,0],[120,0]],"id":41762566},{"atb":[[2.82,0],[2.72,0],[2.52,0],[2.62,0],[3.05,0]],"id":43066529},{"atl":[[9.2,0],[10.5,0],[8.2,0],[13,0]],"id":43066529},{"atb":[[6.8,0],[9.8,0],[8.8,0],[7.8,0],[14.5,0]],"id":42651625},{"atl":[[270,0],[170,0],[220,0],[120,0]],"id":42651625},{"atb":[[4.8,0],[8.6,0],[5.8,0],[5.3,0],[6.6,0]],"id":41676292},{"atl":[[65,0],[130,0],[90,0],[46,0]],"id":41676292},{"atb":[[1.8,0],[1.85,0],[1.9,0],[1.95,0],[2.1,0]],"id":43167172},{"atl":[[5.8,0],[5.3,0],[7.6,0],[6.6,0]],"id":43167172},{"atb":[[2,0],[2.5,0],[2.3,0],[2.2,0],[2.1,0]],"id":43167173},{"atl":[[8,0],[9,0],[6,0],[7,0]],"id":43167173}],"con":true,"img":false}]}
{"op":"mcm","clk":"5346062134","pt":1646175843189,"mc":[{"id":"1.195453611","rc":[{"atb":[[6.8,28.15],[9.8,4.63],[8.8,10.46],[7.8,12],[14.5,3.02]],"id":41762566},{"atl":[[270,0.74],[170,0.78],[220,0.9],[120,1.11]],"id":41762566},{"atb":[[2.82,22.43],[2.72,47.47],[2.52,107.44],[2.62,50.4],[3.05,19.91]],"id":43066529},{"atl":[[9.2,16.22],[10.5,21],[8.2,18.47],[13,16.63]],"id":43066529},{"atb":[[6.8,28.15],[9.8,4.63],[8.8,10.46],[7.8,12],[14.5,3.02]],"id":42651625},{"atl":[[270,0.74],[170,0.78],[220,0.9],[120,1.11]],"id":42651625},{"atb":[[4.8,42.97],[8.6,5.37],[5.8,17.01],[5.3,18.98],[6.6,7.28]],"id":41676292},{"atl":[[65,2.07],[130,1.54],[90,2.24],[46,2.95]],"id":41676292},{"atb":[[1.8,204.13],[1.85,96.06],[1.9,90.72],[1.95,42.97],[2.1,37.11]],"id":43167172},{"atl":[[5.8,27.71],[5.3,30.94],[7.6,30.23],[6.6,35.63]],"id":43167172},{"atb":[[2,163.3],[2.5,27.21],[2.3,31.4],[2.2,68.04],[2.1,74.22]],"id":43167173},{"atl":[[8,28.5],[9,24.94],[6,26.6],[7,22.17]],"id":43167173}],"con":true,"img":false}]}
{"op":"mcm","clk":"5346105158","pt":1646176602701,"mc":[{"id":"1.195453611","marketDefinition":{"bspMarket":true,"turnInPlayEnabled":false,"persistenceEnabled":false,"marketBaseRate":7.0,"eventId":"31272494","eventTypeId":"4339","numberOfWinners":1,"bettingType":"ODDS","marketType":"WIN","marketTime":"2022-03-02T08:51:00.000Z","suspendTime":"2022-03-02T08:51:00.000Z","bspReconciled":false,"complete":true,"inPlay":false,"crossMatching":false,"runnersVoidable":false,"numberOfActiveRunners":6,"betDelay":0,"status":"OPEN","runners":[{"status":"ACTIVE","sortPriority":1,"id":43066529,"name":"1. Piopio"},{"status":"ACTIVE","sortPriority":2,"id":41676292,"name":"2. Jasper Bale"},{"status":"ACTIVE","sortPriority":3,"id":41762566,"name":"3. Afro Boy"},{"status":"ACTIVE","sortPriority":4,"id":42651625,"name":"4. Average Axel"},{"status":"ACTIVE","sortPriority":5,"id":43167172,"name":"6. Fancy Like"},{"status":"ACTIVE","sortPriority":6,"id":43167173,"name":"8. Simon Rose"}],"regulators":["MR_INT"],"venue":"Traralgon","countryCode":"AU","discountAllowed":true,"timezone":"Australia/Sydney","openDate":"2022-03-02T08:31:00.000Z","version":4382425361,"name":"R2 395m Gr6/7","eventName":"Traralgon (AUS) 2nd Mar"},"rc":[{"atb":[[6.8,28.15],[9.8,4.63],[8.8,10.46],[7.8,12],[14.5,3.02]],"id":41762566},{"atl":[[270,0.74],[170,0.78],[220,0.9],[120,1.11]],"id":41762566},{"spn":67.25,"spf":"NaN","id":41762566},{"atb":[[2.82,22.43],[2.72,47.47],[2.52,107.44],[2.62,50.4],[3.05,19.91]],"id":43066529},{"atl":[[9.2,16.22],[10.5,21],[8.2,18.47],[13,16.63]],"id":43066529},{"spn":5.62,"spf":"NaN","id":43066529},{"atb":[[6.8,28.15],[9.8,4.63],[8.8,10.46],[7.8,12],[14.5,3.02]],"id":42651625},{"atl":[[270,0.74],[170,0.78],[220,0.9],[120,1.11]],"id":42651625},{"spn":67.25,"spf":"NaN","id":42651625},{"atb":[[4.8,42.97],[8.6,5.37],[5.8,17.01],[5.3,18.98],[6.6,7.28]],"id":41676292},{"atl":[[65,2.07],[130,1.54],[90,2.24],[46,2.95]],"id":41676292},{"spn":27.3,"spf":"NaN","id":41676292},{"atb":[[1.8,204.13],[1.85,96.06],[1.9,90.72],[1.95,42.97],[2.1,37.11]],"id":43167172},{"atl":[[5.8,27.71],[5.3,30.94],[7.6,30.23],[6.6,35.63]],"id":43167172},{"spn":3.7,"spf":"NaN","id":43167172},{"atb":[[2,163.3],[2.5,27.21],[2.3,31.4],[2.2,68.04],[2.1,74.22]],"id":43167173},{"atl":[[8,28.5],[9,24.94],[6,26.6],[7,22.17]],"id":43167173},{"spn":4.25,"spf":"NaN","id":43167173}],"con":true,"img":true}]}
{"op":"mcm","clk":"5346244432","pt":1646179315905,"mc":[{"id":"1.195453611","rc":[{"atb":[[20,0.28],[6.8,28.15],[9.8,4.63],[8.8,10.46],[7.8,12.01],[14.5,3.02]],"id":41762566},{"atl":[[120,1.11]],"id":41762566},{"spb":[[20,5.44]],"id":41762566},{"spn":70.0,"spf":"Infinity","id":41762566},{"atb":[[2.82,22.43],[2.72,47.47],[2.52,107.45],[2.62,50.4],[3.05,19.92]],"id":43066529},{"atl":[[9.2,16.22],[10.5,21],[8.2,18.47],[13,16.63]],"id":43066529},{"atb":[[6.8,28.15],[9.8,4.63],[8.8,10.46],[7.8,12.01],[14.5,3.02]],"id":42651625},{"atl":[[120,1.11]],"id":42651625},{"atb":[[4.8,42.98],[8.6,5.37],[5.8,17.01],[5.3,18.98],[6.6,7.28]],"id":41676292},{"atl":[[65,2.07],[130,1.54],[90,2.24],[46,2.95]],"id":41676292},{"atb":[[1.8,204.15],[1.85,96.07],[1.9,90.73],[1.95,42.98],[2.1,37.11]],"id":43167172},{"atl":[[5.8,27.72],[5.3,30.94],[7.6,30.24],[6.6,35.63]],"id":43167172},{"atb":[[2,163.32],[2.5,27.22],[2.3,31.4],[2.2,68.05],[2.1,74.23]],"id":43167173},{"atl":[[8,28.51],[9,24.94],[6,26.61],[7,22.17]],"id":43167173}],"con":true,"img":false}]}
{"op":"mcm","clk":"5346348655","pt":1646181275049,"mc":[{"id":"1.195453611","rc":[{"atl":[[4.8,8.16]],"id":43167172},{"spn":3.45,"spf":"NaN","id":43167172}],"con":true,"img":false}]}
{"op":"mcm","clk":"5346767970","pt":1646187402733,"mc":[{"id":"1.195453611","marketDefinition":{"bspMarket":true,"turnInPlayEnabled":false,"persistenceEnabled":false,"marketBaseRate":7.0,"eventId":"31272494","eventTypeId":"4339","numberOfWinners":1,"bettingType":"ODDS","marketType":"WIN","marketTime":"2022-03-02T08:51:00.000Z","suspendTime":"2022-03-02T08:51:00.000Z","bspReconciled":false,"complete":true,"inPlay":false,"crossMatching":false,"runnersVoidable":false,"numberOfActiveRunners":6,"betDelay":0,"status":"OPEN","runners":[{"status":"ACTIVE","sortPriority":1,"id":43066529,"name":"1. Piopio"},{"status":"ACTIVE","sortPriority":2,"id":41676292,"name":"2. Jasper Bale"},{"status":"ACTIVE","sortPriority":3,"id":41762566,"name":"3. Afro Boy"},{"status":"ACTIVE","sortPriority":4,"id":42651625,"name":"4. Average Axel"},{"status":"ACTIVE","sortPriority":5,"id":43167172,"name":"6. Fancy Like"},{"status":"ACTIVE","sortPriority":6,"id":43167173,"name":"8. Simon Rose"}],"regulators":["MR_INT"],"venue":"Traralgon","countryCode":"AU","discountAllowed":true,"timezone":"Australia/Sydney","openDate":"2022-03-02T08:31:00.000Z","version":4382425361,"name":"R2 395m Gr6/7","eventName":"Traralgon (AUS) 2nd Mar"},"rc":[{"atb":[[20,0.28],[6.8,28.2],[9.8,4.64],[8.8,10.48],[7.8,12.02],[14.5,3.03]],"id":41762566},{"atl":[[270,0.74],[170,0.79],[220,0.91],[120,1.11]],"id":41762566},{"spb":[[20,5.45]],"id":41762566},{"spn":70.0,"spf":"Infinity","id":41762566},{"atb":[[2.82,22.47],[2.72,47.55],[2.52,107.62],[2.62,50.48],[3.05,19.95]],"id":43066529},{"atl":[[9.2,16.24],[10.5,21.04],[8.2,18.5],[13,16.65]],"id":43066529},{"spn":5.62,"spf":"NaN","id":43066529},{"atb":[[6.8,28.2],[9.8,4.64],[8.8,10.48],[7.8,12.02],[14.5,3.03]],"id":42651625},{"atl":[[270,0.74],[170,0.79],[220,0.91],[120,1.11]],"id":42651625},{"spn":67.25,"spf":"NaN","id":42651625},{"atb":[[4.8,43.05],[8.6,5.38],[5.8,17.04],[5.3,19.01],[6.6,7.3]],"id":41676292},{"atl":[[65,2.08],[130,1.54],[90,2.24],[46,2.96]],"id":41676292},{"spn":27.3,"spf":"NaN","id":41676292},{"atb":[[1.8,204.48],[1.85,96.22],[1.9,90.88],[1.95,43.05],[2.1,37.17]],"id":43167172},{"atl":[[4.8,8.17],[5.8,27.76],[5.3,30.99],[7.6,30.29],[6.6,35.69]],"id":43167172},{"spn":3.45,"spf":"NaN","id":43167172},{"atb":[[2,163.58],[2.5,27.26],[2.3,31.45],[2.2,68.16],[2.1,74.35]],"id":43167173},{"atl":[[8,28.55],[9,24.98],[6,26.65],[7,22.2]],"id":43167173},{"spn":4.25,"spf":"NaN","id":43167173}],"con":true,"img":true}]}
{"op":"mcm","clk":"5347092521","pt":1646192802713,"mc":[{"id":"1.195453611","marketDefinition":{"bspMarket":true,"turnInPlayEnabled":false,"persistenceEnabled":false,"marketBaseRate":7.0,"eventId":"31272494","eventTypeId":"4339","numberOfWinners":1,"bettingType":"ODDS","marketType":"WIN","marketTime":"2022-03-02T08:51:00.000Z","suspendTime":"2022-03-02T08:51:00.000Z","bspReconciled":false,"complete":true,"inPlay":false,"crossMatching":false,"runnersVoidable":false,"numberOfActiveRunners":6,"betDelay":0,"status":"OPEN","runners":[{"status":"ACTIVE","sortPriority":1,"id":43066529,"name":"1. Piopio"},{"status":"ACTIVE","sortPriority":2,"id":41676292,"name":"2. Jasper Bale"},{"status":"ACTIVE","sortPriority":3,"id":41762566,"name":"3. Afro Boy"},{"status":"ACTIVE","sortPriority":4,"id":42651625,"name":"4. Average Axel"},{"status":"ACTIVE","sortPriority":5,"id":43167172,"name":"6. Fancy Like"},{"status":"ACTIVE","sortPriority":6,"id":43167173,"name":"8. Simon Rose"}],"regulators":["MR_INT"],"venue":"Traralgon","countryCode":"AU","discountAllowed":true,"timezone":"Australia/Sydney","openDate":"2022-03-02T08:31:00.000Z","version":4382425361,"name":"R2 395m Gr6/7","eventName":"Traralgon (AUS) 2nd Mar"},"rc":[{"atb":[[20,0.28],[6.8,28.24],[9.8,4.65],[8.8,10.5],[7.8,12.04],[14.5,3.03]],"id":41762566},{"atl":[[270,0.74],[170,0.79],[220,0.91],[120,1.11]],"id":41762566},{"spb":[[20,5.46]],"id":41762566},{"spn":70.0,"spf":"Infinity","id":41762566},{"atb":[[2.82,22.5],[2.72,47.63],[2.52,107.8],[2.62,50.57],[3.05,19.98]],"id":43066529},{"atl":[[9.2,16.27],[10.5,21.07],[8.2,18.53],[13,16.68]],"id":43066529},{"spn":5.62,"spf":"NaN","id":43066529},{"atb":[[6.8,28.24],[9.8,4.65],[8.8,10.5],[7.8,12.04],[14.5,3.03]],"id":42651625},{"atl":[[270,0.74],[170,0.79],[220,0.91],[120,1.11]],"id":42651625},{"spn":67.25,"spf":"NaN","id":42651625},{"atb":[[4.8,43.12],[8.6,5.39],[5.8,17.06],[5.3,19.05],[6.6,7.31]],"id":41676292},{"atl":[[65,2.08],[130,1.55],[90,2.25],[46,2.96]],"id":41676292},{"spn":27.3,"spf":"NaN","id":41676292},{"atb":[[1.8,204.82],[1.85,96.38],[1.9,91.03],[1.95,43.12],[2.1,37.24]],"id":43167172},{"atl":[[4.8,8.19],[5.8,27.81],[5.3,31.04],[7.6,30.34],[6.6,35.75]],"id":43167172},{"spn":3.45,"spf":"NaN","id":43167172},{"atb":[[2,163.86],[2.5,27.31],[2.3,31.51],[2.2,68.27],[2.1,74.48]],"id":43167173},{"atl":[[8,28.6],[9,25.02],[6,26.69],[7,22.24]],"id":43167173},{"spn":4.25,"spf":"NaN","id":43167173}],"con":true,"img":true}]}
{"op":"mcm","clk":"5347282875","pt":1646196275549,"mc":[{"id":"1.195453611","rc":[{"atb":[[20,0.28],[6.8,28.24],[9.8,4.65],[8.8,10.5],[7.8,12.04],[14.5,3.03]],"id":41762566},{"atl":[[270,0.74],[170,0.79],[220,0.91],[120,1.11]],"id":41762566},{"spb":[[20,5.46]],"id":41762566},{"atb":[[2.82,22.5],[2.72,47.63],[2.52,107.8],[2.62,50.57],[3.05,19.98]],"id":43066529},{"atl":[[9.2,16.27],[10.5,21.07],[8.2,18.53],[13,16.68]],"id":43066529},{"atb":[[6.8,28.24],[9.8,4.65],[8.8,10.5],[7.8,12.04],[14.5,3.03]],"id":42651625},{"atl":[[270,0.74],[170,0.79],[220,0.91],[120,1.11]],"id":42651625},{"atb":[[4.8,43.12],[8.6,5.39],[5.8,17.06],[5.3,19.05],[6.6,7.31]],"id":41676292},{"atl":[[65,2.08],[130,1.55],[90,2.25],[46,2.96]],"id":41676292},{"atb":[[1.8,204.82],[1.85,96.38],[1.9,91.03],[1.95,43.12],[2.1,37.24]],"id":43167172},{"atl":[[4.8,0],[5.8,27.81],[5.3,31.04],[7.6,30.34],[6.6,35.75]],"id":43167172},{"spn":3.7,"spf":"NaN","id":43167172},{"atb":[[2,163.86],[2.5,27.31],[2.3,31.51],[2.2,68.27],[2.1,74.48]],"id":43167173},{"atl":[[8,28.6],[9,25.02],[6,26.69],[7,22.24]],"id":43167173}],"con":true,"img":false}]}
{"op":"mcm","clk":"5347282881","pt":1646196275652,"mc":[{"id":"1.195453611","rc":[{"atl":[[4.9,8.19]],"id":43167172}],"con":true,"img":false}]}
{"op":"mcm","clk":"5347327702","pt":1646197134697,"mc":[{"id":"1.195453611","rc":[{"atl":[[3,4.92]],"id":43167172},{"spn":2.55,"spf":"NaN","id":43167172}],"con":true,"img":false}]}
{"op":"mcm","clk":"5347327966","pt":1646197141866,"mc":[{"id":"1.195453611","marketDefinition":{"bspMarket":true,"turnInPlayEnabled":false,"persistenceEnabled":false,"marketBaseRate":7.0,"eventId":"31272494","eventTypeId":"4339","numberOfWinners":1,"bettingType":"ODDS","marketType":"WIN","marketTime":"2022-03-02T08:51:00.000Z","suspendTime":"2022-03-02T08:51:00.000Z","bspReconciled":false,"complete":true,"inPlay":false,"crossMatching":true,"runnersVoidable":false,"numberOfActiveRunners":6,"betDelay":0,"status":"OPEN","runners":[{"status":"ACTIVE","sortPriority":1,"id":43066529,"name":"1. Piopio"},{"status":"ACTIVE","sortPriority":2,"id":41676292,"name":"2. Jasper Bale"},{"status":"ACTIVE","sortPriority":3,"id":41762566,"name":"3. Afro Boy"},{"status":"ACTIVE","sortPriority":4,"id":42651625,"name":"4. Average Axel"},{"status":"ACTIVE","sortPriority":5,"id":43167172,"name":"6. Fancy Like"},{"status":"ACTIVE","sortPriority":6,"id":43167173,"name":"8. Simon Rose"}],"regulators":["MR_INT"],"venue":"Traralgon","countryCode":"AU","discountAllowed":true,"timezone":"Australia/Sydney","openDate":"2022-03-02T08:31:00.000Z","version":4382425361,"name":"R2 395m Gr6/7","eventName":"Traralgon (AUS) 2nd Mar"},"rc":[],"con":true,"img":false}]}
{"op":"mcm","clk":"5347340056","pt":1646197402658,"mc":[{"id":"1.195453611","rc":[{"atb":[[20,0.28],[6.8,0],[9.8,0],[8.8,0],[7.8,0],[14.5,0]],"id":41762566},{"atl":[[270,0],[170,0],[220,0],[120,0]],"id":41762566},{"spb":[[20,5.46]],"id":41762566},{"spn":"Infinity","spf":"Infinity","id":41762566},{"atb":[[2.82,0],[2.72,0],[2.52,0],[2.62,0],[3.05,0]],"id":43066529},{"atl":[[9.2,0],[10.5,0],[8.2,0],[13,0]],"id":43066529},{"spn":"NaN","spf":"NaN","id":43066529},{"atb":[[6.8,28.23],[9.8,4.65],[8.8,10.49],[7.8,12.04],[14.5,3.03]],"id":42651625},{"atl":[[270,0.74],[170,0.79],[220,0.91],[120,1.11]],"id":42651625},{"atb":[[4.8,0],[8.6,0],[5.8,0],[5.3,0],[6.6,0]],"id":41676292},{"atl":[[65,0],[130,0],[90,0],[46,0]],"id":41676292},{"spn":"NaN","spf":"NaN","id":41676292},{"atb":[[1.8,0],[1.85,0],[1.9,0],[1.95,0],[2.1,0]],"id":43167172},{"atl":[[5.8,0],[5.3,0],[3,4.92],[7.6,0],[4.9,8.19],[6.6,0]],"id":43167172},{"spn":1.0,"spf":"NaN","id":43167172},{"atb":[[2,0],[2.5,0],[2.3,0],[2.2,0],[2.1,0]],"id":43167173},{"atl":[[8,0],[9,0],[6,0],[7,0]],"id":43167173},{"spn":"NaN","spf":"NaN","id":43167173}],"con":true,"img":false}]}
{"op":"mcm","clk":"5347340415","pt":1646197411162,"mc":[{"id":"1.195453611","rc":[{"atb":[[18,2.4],[9.2,9.98],[10.5,8.62],[8.2,22.75],[13,3.41]],"id":41762566},{"atl":[[150,0.89],[300,0.67],[200,0.67],[250,0.8]],"id":41762566},{"atb":[[2.56,105],[2.86,22.01],[2.66,49.33],[3.15,19.04],[2.76,46.53]],"id":43066529},{"atl":[[11,20.01],[13.5,16.01],[8.4,18.03],[9.4,15.88]],"id":43066529},{"atb":[[5.6,35.61],[7.2,13.2],[10.5,4.3],[6.2,15.75],[8.2,5.68]],"id":41676292},{"atl":[[80,1.68],[160,1.26],[210,0.95],[110,1.22]],"id":41676292},{"atb":[[2,40.95],[1.85,192.7],[1.9,91],[2.2,34.12],[1.95,86.2]],"id":43167172},{"atl":[[8,28.59],[5.5,29.65],[6,26.68],[7,33.36]],"id":43167172},{"atb":[[2.36,30.11],[2.06,77.26],[1.98,83.57],[1.93,176.12],[2.16,35.3]],"id":43167173},{"atl":[[6.4,24.71],[7.4,31.27],[5.7,28.39],[8.4,27.04]],"id":43167173}],"con":true,"img":false}]}
{"op":"mcm","clk":"5347343251","pt":1646197475536,"mc":[{"id":"1.195453611","rc":[{"spn":85.0,"spf":"Infinity","id":41762566},{"spn":5.77,"spf":"NaN","id":43066529},{"spn":45.25,"spf":"NaN","id":41676292},{"atl":[[4.9,0]],"id":43167172},{"spn":2.6,"spf":"NaN","id":43167172},{"spn":4.03,"spf":"NaN","id":43167173}],"con":true,"img":false}]}
{"op":"mcm","clk":"5347343257","pt":1646197475640,"mc":[{"id":"1.195453611","rc":[{"atl":[[3.85,8.19]],"id":43167172}],"con":true,"img":false}]}
{"op":"mcm","clk":"5347423645","pt":1646199096916,"mc":[{"id":"1.195453611","rc":[{"atl":[[22,25]],"id":41762566},{"spn":21.0,"spf":"Infinity","id":41762566}],"con":true,"img":false}]}
{"op":"mcm","clk":"5347423727","pt":1646199098196,"mc":[{"id":"1.195453611","rc":[{"atl":[[22,14.46]],"id":41762566},{"trd":[[22,21.08]],"ltp":22.0,"tv":21.08,"id":41762566}],"con":true,"img":false}]}
{"op":"mcm","clk":"5347423809","pt":1646199099786,"mc":[{"id":"1.195453611","rc":[{"atl":[[22,3.47]],"id":41762566},{"trd":[[22,43.06]],"ltp":22.0,"tv":43.06,"id":41762566}],"con":true,"img":false}]}
{"op":"mcm","clk":"5347502426","pt":1646200806794,"mc":[{"id":"1.195453611","rc":[{"atl":[[8.2,1.32]],"id":43066529},{"spn":5.67,"spf":"NaN","id":43066529},{"atl":[[2.98,1.36]],"id":43167172},{"spn":2.59,"spf":"NaN","id":43167172},{"atl":[[5.6,1.25]],"id":43167173},{"spn":3.98,"spf":"NaN","id":43167173}],"con":true,"img":false}]}
{"op":"mcm","clk":"5347502484","pt":1646200807712,"mc":[{"id":"1.195453611","rc":[{"atb":[[3.2,1.42]],"id":43066529},{"atb":[[2.22,1.49]],"id":43167172},{"atb":[[2.38,1.6]],"id":43167173}],"con":true,"img":false}]}
{"op":"mcm","clk":"5347558402","pt":1646202086259,"mc":[{"id":"1.195453611","rc":[{"atb":[[2.8,4.59]],"id":43066529},{"spn":5.7,"spf":"NaN","id":43066529},{"atb":[[2.24,6.66]],"id":43167172},{"spn":2.61,"spf":"NaN","id":43167172},{"atb":[[2.2,6.88]],"id":43167173},{"spn":3.99,"spf":"NaN","id":43167173}],"con":true,"img":false}]}
{"op":"mcm","clk":"5347561643","pt":1646202169018,"mc":[{"id":"1.195453611","rc":[{"atb":[[2.04,9.72]],"id":43167172},{"atb":[[2.1,9.18]],"id":43167173}],"con":true,"img":false}]}
{"op":"mcm","clk":"5347561677","pt":1646202169890,"mc":[{"id":"1.195453611","rc":[{"atb":[[2.8,10.21]],"id":43066529}],"con":true,"img":false}]}
{"op":"mcm","clk":"5347632955","pt":1646203860096,"mc":[{"id":"1.195453611","rc":[{"atb":[[13.5,0.81]],"id":41762566},{"atb":[[3.25,2]],"id":43066529},{"spn":5.72,"spf":"NaN","id":43066529},{"atb":[[22,0.49]],"id":42651625},{"spn":71.0,"spf":"NaN","id":42651625},{"atb":[[11.5,0.96]],"id":41676292},{"spn":45.75,"spf":"NaN","id":41676292},{"atb":[[2.22,3.49]],"id":43167172},{"atb":[[2.32,2]],"id":43167173}],"con":true,"img":false}]}
{"op":"mcm","clk":"5347662751","pt":1646204641006,"mc":[{"id":"1.195453611","rc":[{"atb":[[18,2.4],[9.2,9.98],[10.5,8.61],[8.2,22.74],[13,3.41]],"id":41762566},{"atl":[[150,0.89],[300,0.67],[200,0.67],[250,0.8]],"id":41762566},{"spb":[[20,5.45]],"id":41762566},{"trd":[[22,43.05]],"ltp":22.0,"tv":43.05,"id":41762566},{"atb":[[2.8,10.22],[2.56,104.97],[3.2,1.41],[2.86,22],[2.66,49.32],[3.15,19.03],[2.76,46.52]],"id":43066529},{"atl":[[8.2,1.32],[11,20.01],[13.5,16],[8.4,18.02],[9.4,15.88]],"id":43066529},{"atb":[[6.8,28.23],[9.8,4.65],[8.8,10.49],[7.8,12.04],[14.5,3.03]],"id":42651625},{"atl":[[270,0.74],[170,0.79],[220,0.91],[120,1.11]],"id":42651625},{"atb":[[5.6,35.6],[7.2,13.2],[10.5,4.3],[6.2,15.74],[8.2,5.68]],"id":41676292},{"atl":[[80,1.68],[160,1.26],[210,0.95],[110,1.22]],"id":41676292},{"atb":[[2.24,6.67],[2,40.93],[2.22,2],[2.04,9.72],[1.85,192.65],[1.9,90.97],[2.2,34.11],[1.95,86.18]],"id":43167172},{"atl":[[8,28.58],[3.85,8.18],[5.5,29.64],[3,4.93],[6,26.68],[2.98,1.36],[7,33.35]],"id":43167172},{"atb":[[2.36,30.1],[2.06,77.24],[1.98,83.54],[2.38,1.6],[2.2,6.89],[1.93,176.08],[2.16,35.29],[2.1,9.18]],"id":43167173},{"atl":[[5.6,1.25],[6.4,24.7],[7.4,31.26],[5.7,28.38],[8.4,27.04]],"id":43167173}],"con":true,"img":false}]}
{"op":"mcm","clk":"5347662754","pt":1646204641078,"mc":[{"id":"1.195453611","rc":[{"atb":[[2.26,1.49]],"id":43167172}],"con":true,"img":false}]}
{"op":"mcm","clk":"5347676341","pt":1646205100387,"mc":[{"id":"1.195453611","rc":[{"atb":[[11.5,0]],"id":41676292},{"spn":45.25,"spf":"NaN","id":41676292},{"spn":2.62,"spf":"NaN","id":43167172}],"con":true,"img":false}]}
{"op":"mcm","clk":"5347676346","pt":1646205100489,"mc":[{"id":"1.195453611","rc":[{"atb":[[12,0.92]],"id":41676292}],"con":true,"img":false}]}
{"op":"mcm","clk":"5347694406","pt":1646205605746,"mc":[{"id":"1.195453611","rc":[{"atb":[[19,0.57],[13.5,0]],"id":41762566},{"spn":46.0,"spf":"NaN","id":41676292}],"con":true,"img":false}]}
{"op":"mcm","clk":"5347694409","pt":1646205605856,"mc":[{"id":"1.195453611","rc":[{"atb":[[3.25,0]],"id":43066529}],"con":true,"img":false}]}
{"op":"mcm","clk":"5347694412","pt":1646205605952,"mc":[{"id":"1.195453611","rc":[{"atb":[[3.25,2]],"id":43066529}],"con":true,"img":false}]}
{"op":"mcm","clk":"5347696951","pt":1646205665047,"mc":[{"id":"1.195453611","rc":[{"atb":[[9.4,8.57]],"id":41762566},{"atb":[[2.12,64.29]],"id":43066529},{"atb":[[7.6,10.91]],"id":42651625},{"atb":[[5.7,15.32]],"id":41676292},{"atb":[[1.57,126.32]],"id":43167172},{"atb":[[1.61,118.03]],"id":43167173}],"con":true,"img":false}]}
{"op":"mcm","clk":"5347696955","pt":1646205665149,"mc":[{"id":"1.195453611","rc":[{"atb":[[6,16.4],[4.2,26.56]],"id":41762566},{"atl":[[70,14.2],[55,8.2]],"id":41762566},{"atb":[[1.67,122.39]],"id":43066529},{"atl":[[34,13.5],[19.5,14.2],[15.5,8.2]],"id":43066529},{"atb":[[5,20.5],[4.2,26.56]],"id":42651625},{"atb":[[3.8,29.29]],"id":41676292},{"atb":[[1.34,241.18]],"id":43167172},{"atl":[[5.6,8.2],[17,8.5],[34,13.5],[6.8,14.2]],"id":43167172},{"atb":[[1.36,227.78]],"id":43167173},{"atl":[[17,8.5],[10,8.2],[13,14.2]],"id":43167173}],"con":true,"img":false}]}
{"op":"mcm","clk":"5347696960","pt":1646205665251,"mc":[{"id":"1.195453611","rc":[{"atb":[[2.62,46.3]],"id":41762566},{"atb":[[2.62,46.3]],"id":42651625},{"atl":[[34,13.5]],"id":43167173}],"con":true,"img":false}]}
{"op":"mcm","clk":"5347697003","pt":1646205666275,"mc":[{"id":"1.195453611","rc":[{"atb":[[2.62,46.3]],"id":41676292}],"con":true,"img":false}]}
{"op":"mcm","clk":"5347698101","pt":1646205692985,"mc":[{"id":"1.195453611","rc":[{"atb":[[14,8.93],[18.5,3.34]],"id":41762566},{"atl":[[65,5.45]],"id":41762566},{"atb":[[3.2,77.15]],"id":43066529},{"atl":[[6.4,10.84],[8.2,16.33]],"id":43066529},{"atb":[[19.5,6.53],[25,2.72]],"id":42651625},{"atl":[[140,0.42],[160,2.72]],"id":42651625},{"atb":[[8.6,14.71],[11,5.85]],"id":41676292},{"atl":[[42,2.72],[30,2.72]],"id":41676292},{"atb":[[2.02,124.45],[2.22,49.98]],"id":43167172},{"atl":[[4.9,28.93],[3.75,21.28]],"id":43167172},{"atb":[[2.22,47.98],[2.18,104.08]],"id":43167173},{"atl":[[3.95,19.84],[5.3,26.69]],"id":43167173}],"con":true,"img":false}]}
{"op":"mcm","clk":"5347698122","pt":1646205693395,"mc":[{"id":"1.195453611","rc":[{"atl":[[8.2,15.01]],"id":43066529}],"con":true,"img":false}]}
{"op":"mcm","clk":"5347698125","pt":1646205693497,"mc":[{"id":"1.195453611","rc":[{"atl":[[6.2,1.32]],"id":43066529}],"con":true,"img":false}]}
{"op":"mcm","clk":"5347698474","pt":1646205701716,"mc":[{"id":"1.195453611","rc":[{"atb":[[2.8,5.62]],"id":43066529},{"atb":[[2.24,0]],"id":43167172},{"atb":[[2.2,0]],"id":43167173}],"con":true,"img":false}]}
{"op":"mcm","clk":"5347698522","pt":1646205702487,"mc":[{"id":"1.195453611","rc":[{"atb":[[2.26,0]],"id":43167172}],"con":true,"img":false}]}
{"op":"mcm","clk":"5347698529","pt":1646205702589,"mc":[{"id":"1.195453611","rc":[{"atb":[[2.24,1.49]],"id":43167172}],"con":true,"img":false}]}
{"op":"mcm","clk":"5347698837","pt":1646205710714,"mc":[{"id":"1.195453611","rc":[{"atb":[[3.25,5.34]],"id":43066529},{"atb":[[2.26,5.97]],"id":43167172},{"atb":[[2.4,5.37]],"id":43167173}],"con":true,"img":false}]}
{"op":"mcm","clk":"5347700219","pt":1646205748283,"mc":[{"id":"1.195453611","rc":[{"spn":4.72,"spf":"NaN","id":43066529},{"atl":[[130,2.72]],"id":42651625},{"spn":72.5,"spf":"NaN","id":42651625},{"spn":21.0,"spf":"NaN","id":41676292},{"spn":3.17,"spf":"NaN","id":43167173}],"con":true,"img":false}]}
{"op":"mcm","clk":"5347700223","pt":1646205748386,"mc":[{"id":"1.195453611","rc":[{"atl":[[140,0]],"id":42651625}],"con":true,"img":false}]}
{"op":"mcm","clk":"5347700238","pt":1646205748644,"mc":[{"id":"1.195453611","rc":[{"atl":[[120,2.33]],"id":42651625}],"con":true,"img":false}]}
{"op":"mcm","clk":"5347701811","pt":1646205786125,"mc":[{"id":"1.195453611","rc":[{"atb":[[2.8,0]],"id":43066529},{"atb":[[2.04,0]],"id":43167172},{"atb":[[2.1,0]],"id":43167173}],"con":true,"img":false}]}
{"op":"mcm","clk":"5347701816","pt":1646205786227,"mc":[{"id":"1.195453611","rc":[{"atl":[[3.85,0]],"id":43167172}],"con":true,"img":false}]}
{"op":"mcm","clk":"5347702238","pt":1646205796238,"mc":[{"id":"1.195453611","rc":[{"atb":[[3.25,9.82]],"id":43066529}],"con":true,"img":false}]}
{"op":"mcm","clk":"5347702248","pt":1646205796444,"mc":[{"id":"1.195453611","rc":[{"atb":[[2.4,12.58]],"id":43167173}],"con":true,"img":false}]}
{"op":"mcm","clk":"5347702260","pt":1646205796752,"mc":[{"id":"1.195453611","rc":[{"atb":[[2.26,14]],"id":43167172}],"con":true,"img":false}]}
{"op":"mcm","clk":"5347710501","pt":1646206017641,"mc":[{"id":"1.195453611","rc":[{"atb":[[5,0]],"id":42651625}],"con":true,"img":false}]}
{"op":"mcm","clk":"5347714056","pt":1646206135725,"mc":[{"id":"1.195453611","rc":[{"atb":[[9.2,0],[10.5,0],[8.2,0],[13,0],[18,0]],"id":41762566},{"atl":[[150,0],[300,0],[200,0],[250,0]],"id":41762566},{"atb":[[6.8,0],[9.8,0],[8.8,0],[7.8,0],[14.5,0]],"id":42651625},{"atl":[[270,0],[170,0],[220,0],[120,1.21]],"id":42651625},{"atb":[[5.6,0],[7.2,0],[10.5,0],[6.2,0],[8.2,0]],"id":41676292},{"atl":[[80,0],[160,0],[210,0],[110,0]],"id":41676292}],"con":true,"img":false}]}
{"op":"mcm","clk":"5347714153","pt":1646206137784,"mc":[{"id":"1.195453611","rc":[{"atb":[[22,0]],"id":42651625}],"con":true,"img":false}]}
{"op":"mcm","clk":"5347714158","pt":1646206137886,"mc":[{"id":"1.195453611","rc":[{"atb":[[27,0.39]],"id":42651625}],"con":true,"img":false}]}
{"op":"mcm","clk":"5347714538","pt":1646206147408,"mc":[{"id":"1.195453611","rc":[{"atl":[[150,0.39]],"id":42651625}],"con":true,"img":false}]}
{"op":"mcm","clk":"5347714542","pt":1646206147509,"mc":[{"id":"1.195453611","rc":[{"atl":[[130,0]],"id":42651625}],"con":true,"img":false}]}
{"op":"mcm","clk":"5347714575","pt":1646206148328,"mc":[{"id":"1.195453611","rc":[{"atb":[[18.5,0]],"id":41762566},{"atl":[[160,0],[120,0]],"id":42651625}],"con":true,"img":false}]}
{"op":"mcm","clk":"5347714580","pt":1646206148430,"mc":[{"id":"1.195453611","rc":[{"atb":[[17,3.34]],"id":41762566},{"atl":[[210,2.72],[1000,1.21]],"id":42651625}],"con":true,"img":false}]}
{"op":"mcm","clk":"5347714768","pt":1646206153365,"mc":[{"id":"1.195453611","rc":[{"atb":[[11.5,3.89],[16.5,2.64],[9.6,9.51],[8.6,10.77],[7.6,24.8]],"id":41762566},{"atl":[[140,0.96],[290,0.69],[190,0.7],[240,0.83]],"id":41762566},{"atb":[[18,2.4],[10.5,17.23],[26,1.63],[13,6.82],[15.5,5.64]],"id":42651625},{"atl":[[290,0.46],[340,0.58],[390,0.51],[240,0.55]],"id":42651625},{"atb":[[8.6,20.1],[5.8,34.11],[11.5,3.89],[7.6,12.4],[6.6,14.62]],"id":41676292},{"atl":[[130,1.03],[90,1.5],[180,1.11],[230,0.87]],"id":41676292}],"con":true,"img":false}]}
{"op":"mcm","clk":"5347714861","pt":1646206155629,"mc":[{"id":"1.195453611","rc":[{"atb":[[2.4,7.21]],"id":43167173}],"con":true,"img":false}]}
{"op":"mcm","clk":"5347715460","pt":1646206171048,"mc":[{"id":"1.195453611","rc":[{"atb":[[2.4,0]],"id":43167173}],"con":true,"img":false}]}
{"op":"mcm","clk":"5347715625","pt":1646206174659,"mc":[{"id":"1.195453611","rc":[{"atl":[[42,0],[30,0]],"id":41676292},{"atl":[[3.75,0]],"id":43167172}],"con":true,"img":false}]}
{"op":"mcm","clk":"5347715630","pt":1646206174760,"mc":[{"id":"1.195453611","rc":[{"atl":[[36,2.72],[50,2.72]],"id":41676292},{"atl":[[3.7,21.28]],"id":43167172}],"con":true,"img":false}]}
{"op":"mcm","clk":"5347715635","pt":1646206174864,"mc":[{"id":"1.195453611","rc":[{"atl":[[990,1.31]],"id":41676292},{"atl":[[3.85,8.18]],"id":43167172}],"con":true,"img":false}]}
{"op":"mcm","clk":"5347715640","pt":1646206174967,"mc":[{"id":"1.195453611","rc":[{"atl":[[2.98,0]],"id":43167172}],"con":true,"img":false}]}
{"op":"mcm","clk":"5347715648","pt":1646206175070,"mc":[{"id":"1.195453611","rc":[{"atl":[[1000,1.36]],"id":43167172}],"con":true,"img":false}]}
{"op":"mcm","clk":"5347715668","pt":1646206175532,"mc":[{"id":"1.195453611","rc":[{"atl":[[1000,0]],"id":43167172}],"con":true,"img":false}]}
{"op":"mcm","clk":"5347715673","pt":1646206175635,"mc":[{"id":"1.195453611","rc":[{"atl":[[2.98,1.36]],"id":43167172}],"con":true,"img":false}]}
{"op":"mcm","clk":"5347715872","pt":1646206180081,"mc":[{"id":"1.195453611","rc":[{"atb":[[2.26,8.02]],"id":43167173}],"con":true,"img":false}]}
{"op":"mcm","clk":"5347716855","pt":1646206203695,"mc":[{"id":"1.195453611","rc":[{"spn":88.5,"spf":"NaN","id":42651625},{"spn":24.0,"spf":"NaN","id":41676292},{"atb":[[2.4,5.37]],"id":43167173}],"con":true,"img":false}]}
{"op":"mcm","clk":"5347717299","pt":1646206213777,"mc":[{"id":"1.195453611","rc":[{"atb":[[17,10.32]],"id":41762566}],"con":true,"img":false}]}
{"op":"mcm","clk":"5347717308","pt":1646206213882,"mc":[{"id":"1.195453611","rc":[{"atb":[[14,0]],"id":41762566}],"con":true,"img":false}]}
{"op":"mcm","clk":"5347718294","pt":1646206237998,"mc":[{"id":"1.195453611","rc":[{"atb":[[12,10.82]],"id":41676292}],"con":true,"img":false}]}
{"op":"mcm","clk":"5347718300","pt":1646206238255,"mc":[{"id":"1.195453611","rc":[{"atb":[[8.6,5.38],[11,0]],"id":41676292},{"atl":[[3.85,0]],"id":43167172}],"con":true,"img":false}]}
{"op":"mcm","clk":"5347718305","pt":1646206238308,"mc":[{"id":"1.195453611","rc":[{"atb":[[12,16.67]],"id":41676292}],"con":true,"img":false}]}
{"op":"mcm","clk":"5347721893","pt":1646206314288,"mc":[{"id":"1.195453611","rc":[{"atl":[[17,8.5]],"id":43066529}],"con":true,"img":false}]}
{"op":"mcm","clk":"5347722604","pt":1646206335334,"mc":[{"id":"1.195453611","rc":[{"atb":[[12,15.75]],"id":41676292}],"con":true,"img":false}]}
{"op":"mcm","clk":"5347722610","pt":1646206335437,"mc":[{"id":"1.195453611","rc":[{"atb":[[13.5,0.81]],"id":41676292}],"con":true,"img":false}]}
{"op":"mcm","clk":"5347732461","pt":1646206615429,"mc":[{"id":"1.195453611","rc":[{"atl":[[130,9.23],[150,14.2]],"id":41676292},{"spn":24.75,"spf":"NaN","id":41676292}],"con":true,"img":false}]}
{"op":"mcm","clk":"5347738060","pt":1646206755001,"mc":[{"id":"1.195453611","rc":[{"atb":[[4.2,26.56]],"id":41676292}],"con":true,"img":false}]}
{"op":"mcm","clk":"5347768779","pt":1646207418409,"mc":[{"id":"1.195453611","rc":[{"atb":[[3.25,0]],"id":43066529},{"trd":[[3.25,19.65]],"ltp":3.25,"tv":19.65,"id":43066529},{"spn":4.7,"spf":"NaN","id":43066529},{"atl":[[3,0],[2.98,0]],"id":43167172},{"trd":[[3,9.87],[2.98,2.72]],"ltp":3.0,"tv":12.59,"id":43167172},{"spn":2.98,"spf":"NaN","id":43167172}],"con":true,"img":false}]}
{"op":"mcm","clk":"5347768786","pt":1646207418510,"mc":[{"id":"1.195453611","rc":[{"atb":[[2.22,47.98]],"id":43167172}],"con":true,"img":false}]}
{"op":"mcm","clk":"5347768791","pt":1646207418612,"mc":[{"id":"1.195453611","rc":[{"atl":[[3.85,8.18]],"id":43167172}],"con":true,"img":false}]}
{"op":"mcm","clk":"5347768801","pt":1646207418818,"mc":[{"id":"1.195453611","rc":[{"atb":[[3.25,1.34]],"id":43066529},{"atb":[[2.28,1.36]],"id":43167172},{"atb":[[2.4,6.68]],"id":43167173}],"con":true,"img":false}]}
{"op":"mcm","clk":"5347768912","pt":1646207420924,"mc":[{"id":"1.195453611","rc":[{"atl":[[3.8,2.85]],"id":43066529}],"con":true,"img":false}]}
{"op":"mcm","clk":"5347768954","pt":1646207421502,"mc":[{"id":"1.195453611","rc":[{"atb":[[3.2,75.73]],"id":43066529}],"con":true,"img":false}]}
{"op":"mcm","clk":"5347768959","pt":1646207421606,"mc":[{"id":"1.195453611","rc":[{"atb":[[1.01,1.41]],"id":43066529}],"con":true,"img":false}]}
{"op":"mcm","clk":"5347768971","pt":1646207421804,"mc":[{"id":"1.195453611","rc":[{"atb":[[2.26,15.84]],"id":43167172}],"con":true,"img":false}]}
{"op":"mcm","clk":"5347768981","pt":1646207422010,"mc":[{"id":"1.195453611","rc":[{"atb":[[3.25,0]],"id":43066529}],"con":true,"img":false}]}
{"op":"mcm","clk":"5347768989","pt":1646207422114,"mc":[{"id":"1.195453611","rc":[{"atb":[[3.2,26.61],[1.01,2.76]],"id":43066529}],"con":true,"img":false}]}
{"op":"mcm","clk":"5347768996","pt":1646207422216,"mc":[{"id":"1.195453611","rc":[{"atb":[[2.88,49.12]],"id":43066529}],"con":true,"img":false}]}
{"op":"mcm","clk":"5347769149","pt":1646207425313,"mc":[{"id":"1.195453611","rc":[{"atl":[[3.8,6.69]],"id":43066529}],"con":true,"img":false}]}
{"op":"mcm","clk":"5347769188","pt":1646207425931,"mc":[{"id":"1.195453611","rc":[{"atb":[[3.2,0]],"id":43066529},{"trd":[[3.2,53.22]],"ltp":3.2,"tv":53.22,"id":43066529},{"atl":[[3.7,0]],"id":43167172},{"trd":[[3.7,42.57]],"ltp":3.7,"tv":42.57,"id":43167172}],"con":true,"img":false}]}
{"op":"mcm","clk":"5347769237","pt":1646207426913,"mc":[{"id":"1.195453611","rc":[{"atb":[[2.4,1.31]],"id":43167173}],"con":true,"img":false}]}
{"op":"mcm","clk":"5347769273","pt":1646207427694,"mc":[{"id":"1.195453611","rc":[{"atb":[[2.4,0]],"id":43167173}],"con":true,"img":false}]}
{"op":"mcm","clk":"5347769277","pt":1646207427794,"mc":[{"id":"1.195453611","rc":[{"atb":[[2.38,2.91]],"id":43167173}],"con":true,"img":false}]}
{"op":"mcm","clk":"5347769522","pt":1646207433244,"mc":[{"id":"1.195453611","rc":[{"atl":[[65,2.72]],"id":41762566},{"atb":[[2.88,0]],"id":43066529},{"atl":[[150,0],[210,0]],"id":42651625},{"atl":[[36,0],[50,0]],"id":41676292},{"atl":[[4.9,0]],"id":43167172},{"atl":[[3.95,0]],"id":43167173}],"con":true,"img":false}]}
{"op":"mcm","clk":"5347769527","pt":1646207433303,"mc":[{"id":"1.195453611","rc":[{"atl":[[100,2.72]],"id":41762566},{"atb":[[2.68,49.12]],"id":43066529},{"atl":[[190,0.39],[230,2.72]],"id":42651625},{"atl":[[42,2.72],[60,2.72]],"id":41676292},{"atl":[[5.4,28.93]],"id":43167172},{"atl":[[4.4,19.84]],"id":43167173}],"con":true,"img":false}]}
{"op":"mcm","clk":"5347769533","pt":1646207433408,"mc":[{"id":"1.195453611","rc":[{"atb":[[3.15,0],[2.26,2]],"id":43066529},{"trd":[[3.15,38.07]],"ltp":3.15,"tv":38.07,"id":43066529},{"atl":[[3.85,0]],"id":43167172},{"trd":[[3.85,16.37]],"ltp":3.85,"tv":16.37,"id":43167172}],"con":true,"img":false}]}
{"op":"mcm","clk":"5347769544","pt":1646207433615,"mc":[{"id":"1.195453611","rc":[{"atb":[[2.64,11.94]],"id":43167172}],"con":true,"img":false}]}
{"op":"mcm","clk":"5347769547","pt":1646207433716,"mc":[{"id":"1.195453611","rc":[{"atl":[[4.2,8.18]],"id":43167172}],"con":true,"img":false}]}
{"op":"mcm","clk":"5347769553","pt":1646207433811,"mc":[{"id":"1.195453611","rc":[{"atl":[[5.6,0]],"id":43167173}],"con":true,"img":false}]}
{"op":"mcm","clk":"5347769557","pt":1646207433914,"mc":[{"id":"1.195453611","rc":[{"atl":[[4.3,1.25]],"id":43167173}],"con":true,"img":false}]}
{"op":"mcm","clk":"5347769578","pt":1646207434326,"mc":[{"id":"1.195453611","rc":[{"atb":[[2.28,0]],"id":43167172}],"con":true,"img":false}]}
{"op":"mcm","clk":"5347769586","pt":1646207434428,"mc":[{"id":"1.195453611","rc":[{"atb":[[2.66,1.36]],"id":43167172}],"con":true,"img":false}]}
{"op":"mcm","clk":"5347769596","pt":1646207434634,"mc":[{"id":"1.195453611","rc":[{"atb":[[14,8.58],[17,3.34]],"id":41762566},{"atb":[[2.22,69.12],[2.68,0]],"id":43066529},{"atb":[[12,5.85],[9.8,12.37]],"id":41676292}],"con":true,"img":false}]}
{"op":"mcm","clk":"5347769666","pt":1646207435924,"mc":[{"id":"1.195453611","rc":[{"atb":[[2.26,14]],"id":43167173}],"con":true,"img":false}]}
{"op":"mcm","clk":"5347770016","pt":1646207443327,"mc":[{"id":"1.195453611","rc":[{"atb":[[3.2,26.61]],"id":43066529},{"atl":[[4.2,26.48]],"id":43167172}],"con":true,"img":false}]}
{"op":"mcm","clk":"5347770122","pt":1646207445433,"mc":[{"id":"1.195453611","rc":[{"atb":[[3.2,19.24]],"id":43066529},{"trd":[[3.2,67.94]],"ltp":3.2,"tv":67.94,"id":43066529}],"con":true,"img":false}]}
{"op":"mcm","clk":"5347770135","pt":1646207445739,"mc":[{"id":"1.195453611","rc":[{"atb":[[3.2,0]],"id":43066529}],"con":true,"img":false}]}
{"op":"mcm","clk":"5347770139","pt":1646207445844,"mc":[{"id":"1.195453611","rc":[{"atb":[[2.96,19.24]],"id":43066529}],"con":true,"img":false}]}
{"op":"mcm","clk":"5347770307","pt":1646207449024,"mc":[{"id":"1.195453611","rc":[{"atl":[[5.6,0]],"id":43167172}],"con":true,"img":false}]}
{"op":"mcm","clk":"5347770381","pt":1646207450416,"mc":[{"id":"1.195453611","rc":[{"atl":[[4.5,7.27]],"id":43066529},{"atb":[[2.66,13.68]],"id":43167172}],"con":true,"img":false}]}
{"op":"mcm","clk":"5347770386","pt":1646207450521,"mc":[{"id":"1.195453611","rc":[{"atl":[[6.4,0]],"id":43066529},{"atb":[[2.22,0]],"id":43167172}],"con":true,"img":false}]}
{"op":"mcm","clk":"5347770393","pt":1646207450627,"mc":[{"id":"1.195453611","rc":[{"atl":[[6.2,0]],"id":43066529}],"con":true,"img":false}]}
{"op":"mcm","clk":"5347770400","pt":1646207450727,"mc":[{"id":"1.195453611","rc":[{"atl":[[3.75,1.32]],"id":43066529}],"con":true,"img":false}]}
{"op":"mcm","clk":"5347770423","pt":1646207451026,"mc":[{"id":"1.195453611","rc":[{"atl":[[3.8,3.83]],"id":43066529}],"con":true,"img":false}]}
{"op":"mcm","clk":"5347770430","pt":1646207451128,"mc":[{"id":"1.195453611","rc":[{"atl":[[3.65,2.98]],"id":43066529}],"con":true,"img":false}]}
{"op":"mcm","clk":"5347770477","pt":1646207451852,"mc":[{"id":"1.195453611","rc":[{"atl":[[3.75,0]],"id":43066529}],"con":true,"img":false}]}
{"op":"mcm","clk":"5347770484","pt":1646207451954,"mc":[{"id":"1.195453611","rc":[{"atl":[[1000,1.32]],"id":43066529}],"con":true,"img":false}]}
{"op":"mcm","clk":"5347770538","pt":1646207452829,"mc":[{"id":"1.195453611","rc":[{"atb":[[17,0]],"id":41762566}],"con":true,"img":false}]}
{"op":"mcm","clk":"5347770546","pt":1646207452934,"mc":[{"id":"1.195453611","rc":[{"atb":[[17.5,3.34]],"id":41762566}],"con":true,"img":false}]}
{"op":"mcm","clk":"5347770659","pt":1646207455247,"mc":[{"id":"1.195453611","rc":[{"atb":[[25,0]],"id":42651625}],"con":true,"img":false}]}
{"op":"mcm","clk":"5347770667","pt":1646207455342,"mc":[{"id":"1.195453611","rc":[{"atb":[[32,2.72]],"id":42651625}],"con":true,"img":false}]}
{"op":"mcm","clk":"5347770710","pt":1646207456367,"mc":[{"id":"1.195453611","rc":[{"atb":[[2.96,27.2]],"id":43066529}],"con":true,"img":false}]}
{"op":"mcm","clk":"5347770742","pt":1646207457138,"mc":[{"id":"1.195453611","rc":[{"atb":[[2.26,9.87]],"id":43167172}],"con":true,"img":false}]}
{"op":"mcm","clk":"5347771001","pt":1646207461978,"mc":[{"id":"1.195453611","rc":[{"atb":[[9,12.5]],"id":41762566},{"atl":[[390,2]],"id":41762566},{"atb":[[2.94,51.55]],"id":43066529},{"atl":[[24,4.35]],"id":43066529},{"atb":[[10.5,27.76]],"id":42651625},{"atl":[[440,2]],"id":42651625},{"atb":[[4.1,32.26]],"id":41676292},{"atl":[[60,4.72]],"id":41676292},{"atb":[[1.69,144.93]],"id":43167172},{"atl":[[7,50.02]],"id":43167172},{"atb":[[1.26,125.23]],"id":43167173},{"atl":[[5.2,23.81]],"id":43167173}],"con":true,"img":false}]}
{"op":"mcm","clk":"5347771081","pt":1646207463471,"mc":[{"id":"1.195453611","rc":[{"atb":[[2.24,0]],"id":43167172}],"con":true,"img":false}]}
{"op":"mcm","clk":"5347771088","pt":1646207463573,"mc":[{"id":"1.195453611","rc":[{"atb":[[2.68,1.49]],"id":43167172}],"con":true,"img":false}]}
{"op":"mcm","clk":"5347771212","pt":1646207466041,"mc":[{"id":"1.195453611","rc":[{"atb":[[2.24,6.06]],"id":43167172}],"con":true,"img":false}]}
{"op":"mcm","clk":"5347771270","pt":1646207467069,"mc":[{"id":"1.195453611","rc":[{"atb":[[2.6,62.5],[2.94,0]],"id":43066529}],"con":true,"img":false}]}
{"op":"mcm","clk":"5347771636","pt":1646207473950,"mc":[{"id":"1.195453611","rc":[{"atb":[[2.36,29.24],[4.1,0]],"id":41676292}],"con":true,"img":false}]}
{"op":"mcm","clk":"5347771644","pt":1646207474055,"mc":[{"id":"1.195453611","rc":[{"atb":[[10.5,17.23]],"id":42651625}],"con":true,"img":false}]}
{"op":"mcm","clk":"5347771653","pt":1646207474158,"mc":[{"id":"1.195453611","rc":[{"atb":[[11.5,9.52]],"id":42651625}],"con":true,"img":false}]}
{"op":"mcm","clk":"5347771774","pt":1646207476361,"mc":[{"id":"1.195453611","rc":[{"atb":[[2.26,1.84]],"id":43167172}],"con":true,"img":false}]}
{"op":"mcm","clk":"5347772131","pt":1646207483261,"mc":[{"id":"1.195453611","rc":[{"spn":3.3,"spf":"NaN","id":43066529},{"atb":[[19.5,0],[27,5.04]],"id":42651625},{"spn":111.0,"spf":"NaN","id":42651625},{"spn":27.75,"spf":"NaN","id":41676292},{"spn":3.44,"spf":"NaN","id":43167172},{"spn":3.34,"spf":"NaN","id":43167173}],"con":true,"img":false}]}
{"op":"mcm","clk":"5347772374","pt":1646207488295,"mc":[{"id":"1.195453611","rc":[{"atb":[[2.06,9.52]],"id":43167172}],"con":true,"img":false}]}
{"op":"mcm","clk":"5347772385","pt":1646207488499,"mc":[{"id":"1.195453611","rc":[{"atb":[[2.66,1.36]],"id":43167172}],"con":true,"img":false}]}
{"op":"mcm","clk":"5347772393","pt":1646207488604,"mc":[{"id":"1.195453611","rc":[{"atb":[[2.68,13.8]],"id":43167172}],"con":true,"img":false}]}
{"op":"mcm","clk":"5347772430","pt":1646207489170,"mc":[{"id":"1.195453611","rc":[{"atb":[[2.66,0]],"id":43167172}],"con":true,"img":false}]}
{"op":"mcm","clk":"5347772437","pt":1646207489273,"mc":[{"id":"1.195453611","rc":[{"atb":[[2.7,1.36]],"id":43167172}],"con":true,"img":false}]}
{"op":"mcm","clk":"5347773014","pt":1646207499094,"mc":[{"id":"1.195453611","rc":[{"atb":[[9,0],[10,9.52]],"id":41762566},{"atl":[[13.5,24],[24,0]],"id":43066529},{"atb":[[1.69,0],[1.77,129.87]],"id":43167172},{"atb":[[1.98,185.58],[1.26,0]],"id":43167173},{"atl":[[4.6,26.7],[5.2,0]],"id":43167173}],"con":true,"img":false}]}
{"op":"mcm","clk":"5347773634","pt":1646207509690,"mc":[{"id":"1.195453611","rc":[{"atl":[[3.8,0]],"id":43066529}],"con":true,"img":false}]}
{"op":"mcm","clk":"5347773649","pt":1646207509996,"mc":[{"id":"1.195453611","rc":[{"atl":[[3.3,4.41]],"id":43066529}],"con":true,"img":false}]}
{"op":"mcm","clk":"5347773699","pt":1646207511024,"mc":[{"id":"1.195453611","rc":[{"atb":[[2.36,0],[4.6,27.78]],"id":41676292}],"con":true,"img":false}]}
{"op":"mcm","clk":"5347773818","pt":1646207512979,"mc":[{"id":"1.195453611","rc":[{"atb":[[2.68,1.49]],"id":43167172}],"con":true,"img":false}]}
{"op":"mcm","clk":"5347773824","pt":1646207513087,"mc":[{"id":"1.195453611","rc":[{"atb":[[2.7,13.68]],"id":43167172}],"con":true,"img":false}]}
{"op":"mcm","clk":"5347773902","pt":1646207514415,"mc":[{"id":"1.195453611","rc":[{"atl":[[3.65,0]],"id":43066529}],"con":true,"img":false}]}
{"op":"mcm","clk":"5347773913","pt":1646207514620,"mc":[{"id":"1.195453611","rc":[{"atl":[[3.3,7.71]],"id":43066529}],"con":true,"img":false}]}
{"op":"mcm","clk":"5347774091","pt":1646207518005,"mc":[{"id":"1.195453611","rc":[{"atl":[[4.5,35.09]],"id":43167173}],"con":true,"img":false}]}
{"op":"mcm","clk":"5347774098","pt":1646207518109,"mc":[{"id":"1.195453611","rc":[{"atl":[[5.3,0]],"id":43167173}],"con":true,"img":false}]}
{"op":"mcm","clk":"5347775369","pt":1646207539713,"mc":[{"id":"1.195453611","rc":[{"atl":[[4,4.93]],"id":43167172}],"con":true,"img":false}]}
{"op":"mcm","clk":"5347775398","pt":1646207540226,"mc":[{"id":"1.195453611","rc":[{"atb":[[2.68,0]],"id":43167172}],"con":true,"img":false}]}
{"op":"mcm","clk":"5347775404","pt":1646207540329,"mc":[{"id":"1.195453611","rc":[{"atb":[[2.72,1.49]],"id":43167172}],"con":true,"img":false}]}
{"op":"mcm","clk":"5347776138","pt":1646207553385,"mc":[{"id":"1.195453611","rc":[{"spn":3.13,"spf":"NaN","id":43066529},{"atb":[[11.5,0]],"id":42651625},{"atb":[[2.36,29.24],[4.6,0]],"id":41676292},{"atl":[[55,2],[60,2.72]],"id":41676292},{"spn":3.36,"spf":"NaN","id":43167172},{"atl":[[4.6,0],[4.7,27.03]],"id":43167173}],"con":true,"img":false}]}
{"op":"mcm","clk":"5347776146","pt":1646207553440,"mc":[{"id":"1.195453611","rc":[{"atb":[[11.5,9.52]],"id":42651625}],"con":true,"img":false}]}
{"op":"mcm","clk":"5347776230","pt":1646207554466,"mc":[{"id":"1.195453611","rc":[{"atl":[[4.5,0]],"id":43167173}],"con":true,"img":false}]}
{"op":"mcm","clk":"5347776237","pt":1646207554569,"mc":[{"id":"1.195453611","rc":[{"atl":[[4.6,35.09]],"id":43167173}],"con":true,"img":false}]}
{"op":"mcm","clk":"5347776738","pt":1646207563562,"mc":[{"id":"1.195453611","rc":[{"atb":[[2.7,1.36]],"id":43167172}],"con":true,"img":false}]}
{"op":"mcm","clk":"5347776745","pt":1646207563662,"mc":[{"id":"1.195453611","rc":[{"atb":[[2.72,13.8]],"id":43167172}],"con":true,"img":false}]}
{"op":"mcm","clk":"5347776752","pt":1646207563761,"mc":[{"id":"1.195453611","rc":[{"atl":[[4,4.33]],"id":43167172},{"trd":[[4,1.21]],"ltp":4.0,"tv":1.21,"id":43167172}],"con":true,"img":false}]}
{"op":"mcm","clk":"5347776780","pt":1646207564378,"mc":[{"id":"1.195453611","rc":[{"atb":[[2.7,0]],"id":43167172}],"con":true,"img":false}]}
{"op":"mcm","clk":"5347776785","pt":1646207564482,"mc":[{"id":"1.195453611","rc":[{"atb":[[2.74,1.36]],"id":43167172}],"con":true,"img":false}]}
{"op":"mcm","clk":"5347776793","pt":1646207564689,"mc":[{"id":"1.195453611","rc":[{"atl":[[4.2,8.18]],"id":43167172}],"con":true,"img":false}]}
{"op":"mcm","clk":"5347776798","pt":1646207564792,"mc":[{"id":"1.195453611","rc":[{"atl":[[4.4,18.29]],"id":43167172}],"con":true,"img":false}]}
{"op":"mcm","clk":"5347777899","pt":1646207584712,"mc":[{"id":"1.195453611","rc":[{"atb":[[2.18,0]],"id":43167173}],"con":true,"img":false}]}
{"op":"mcm","clk":"5347777903","pt":1646207584771,"mc":[{"id":"1.195453611","rc":[{"atb":[[2.08,104.08]],"id":43167173}],"con":true,"img":false}]}
{"op":"mcm","clk":"5347778140","pt":1646207589577,"mc":[{"id":"1.195453611","rc":[{"atb":[[4.4,29.29],[2.36,0]],"id":41676292}],"con":true,"img":false}]}
{"op":"mcm","clk":"5347778171","pt":1646207590196,"mc":[{"id":"1.195453611","rc":[{"atb":[[2.72,1.49]],"id":43167172}],"con":true,"img":false}]}
{"op":"mcm","clk":"5347778176","pt":1646207590299,"mc":[{"id":"1.195453611","rc":[{"atb":[[2.74,13.68]],"id":43167172}],"con":true,"img":false}]}
{"op":"mcm","clk":"5347778196","pt":1646207590819,"mc":[{"id":"1.195453611","rc":[{"atb":[[2.72,0]],"id":43167172}],"con":true,"img":false}]}
{"op":"mcm","clk":"5347778203","pt":1646207590881,"mc":[{"id":"1.195453611","rc":[{"atb":[[2.66,1.49]],"id":43167172}],"con":true,"img":false}]}
{"op":"mcm","clk":"5347778900","pt":1646207604519,"mc":[{"id":"1.195453611","rc":[{"atb":[[2.74,1.36]],"id":43167172}],"con":true,"img":false}]}
{"op":"mcm","clk":"5347778905","pt":1646207604622,"mc":[{"id":"1.195453611","rc":[{"atb":[[2.68,12.31]],"id":43167172}],"con":true,"img":false}]}
{"op":"mcm","clk":"5347778950","pt":1646207605499,"mc":[{"id":"1.195453611","rc":[{"atb":[[2.74,0]],"id":43167172}],"con":true,"img":false}]}
{"op":"mcm","clk":"5347778958","pt":1646207605604,"mc":[{"id":"1.195453611","rc":[{"atb":[[2.7,1.36]],"id":43167172}],"con":true,"img":false}]}
{"op":"mcm","clk":"5347779108","pt":1646207608427,"mc":[{"id":"1.195453611","rc":[{"atl":[[60,0]],"id":41676292}],"con":true,"img":false}]}
{"op":"mcm","clk":"5347779116","pt":1646207608530,"mc":[{"id":"1.195453611","rc":[{"atl":[[50,2.72]],"id":41676292}],"con":true,"img":false}]}
{"op":"mcm","clk":"5347779130","pt":1646207608736,"mc":[{"id":"1.195453611","rc":[{"atl":[[990,0]],"id":41676292}],"con":true,"img":false}]}
{"op":"mcm","clk":"5347779134","pt":1646207608791,"mc":[{"id":"1.195453611","rc":[{"atl":[[40,1.31]],"id":41676292}],"con":true,"img":false}]}
{"op":"mcm","clk":"5347779311","pt":1646207611241,"mc":[{"id":"1.195453611","rc":[{"atl":[[4.4,0]],"id":43167172},{"atl":[[4.4,0]],"id":43167173}],"con":true,"img":false}]}
{"op":"mcm","clk":"5347779320","pt":1646207611300,"mc":[{"id":"1.195453611","rc":[{"atl":[[4.3,18.29]],"id":43167172},{"atl":[[4.3,21.09]],"id":43167173}],"con":true,"img":false}]}
{"op":"mcm","clk":"5347781924","pt":1646207659669,"mc":[{"id":"1.195453611","rc":[{"atb":[[2.22,0]],"id":43066529},{"spn":26.75,"spf":"NaN","id":41676292},{"atl":[[4.3,0]],"id":43167172},{"spn":3.35,"spf":"NaN","id":43167172}],"con":true,"img":false}]}
{"op":"mcm","clk":"5347781930","pt":1646207659771,"mc":[{"id":"1.195453611","rc":[{"atb":[[2.14,69.12]],"id":43066529},{"atl":[[4.5,18.29]],"id":43167172}],"con":true,"img":false}]}
{"op":"mcm","clk":"5347781949","pt":1646207660078,"mc":[{"id":"1.195453611","rc":[{"atb":[[2.66,0]],"id":43167172}],"con":true,"img":false}]}
{"op":"mcm","clk":"5347781957","pt":1646207660180,"mc":[{"id":"1.195453611","rc":[{"atb":[[2.7,2.86]],"id":43167172}],"con":true,"img":false}]}
{"op":"mcm","clk":"5347782444","pt":1646207670084,"mc":[{"id":"1.195453611","rc":[{"atl":[[65,0]],"id":41762566},{"atb":[[2.88,31.14],[2.96,0]],"id":43066529}],"con":true,"img":false}]}
{"op":"mcm","clk":"5347782450","pt":1646207670188,"mc":[{"id":"1.195453611","rc":[{"atl":[[75,2.72]],"id":41762566}],"con":true,"img":false}]}
{"op":"mcm","clk":"5347782612","pt":1646207673377,"mc":[{"id":"1.195453611","rc":[{"atb":[[1.69,144.93],[1.77,0]],"id":43167172},{"atl":[[4.9,25.64],[4.7,0]],"id":43167173}],"con":true,"img":false}]}
{"op":"mcm","clk":"5347782651","pt":1646207674154,"mc":[{"id":"1.195453611","rc":[{"atl":[[4.6,0]],"id":43167173}],"con":true,"img":false}]}
{"op":"mcm","clk":"5347782656","pt":1646207674257,"mc":[{"id":"1.195453611","rc":[{"atl":[[4.8,35.09]],"id":43167173}],"con":true,"img":false}]}
{"op":"mcm","clk":"5347783121","pt":1646207684585,"mc":[{"id":"1.195453611","rc":[{"atb":[[2.68,0]],"id":43167172}],"con":true,"img":false}]}
{"op":"mcm","clk":"5347783127","pt":1646207684688,"mc":[{"id":"1.195453611","rc":[{"atb":[[2.72,12.31]],"id":43167172}],"con":true,"img":false}]}
{"op":"mcm","clk":"5347783140","pt":1646207685008,"mc":[{"id":"1.195453611","rc":[{"atb":[[2.7,1.36]],"id":43167172}],"con":true,"img":false}]}
{"op":"mcm","clk":"5347783146","pt":1646207685106,"mc":[{"id":"1.195453611","rc":[{"atb":[[2.74,1.49]],"id":43167172}],"con":true,"img":false}]}
{"op":"mcm","clk":"5347783155","pt":1646207685204,"mc":[{"id":"1.195453611","rc":[{"atb":[[2.7,0]],"id":43167172}],"con":true,"img":false}]}
{"op":"mcm","clk":"5347783162","pt":1646207685305,"mc":[{"id":"1.195453611","rc":[{"atb":[[2.74,2.86]],"id":43167172}],"con":true,"img":false}]}
{"op":"mcm","clk":"5347783220","pt":1646207686486,"mc":[{"id":"1.195453611","rc":[{"atb":[[17.5,0]],"id":41762566},{"atl":[[42,0]],"id":41676292}],"con":true,"img":false}]}
{"op":"mcm","clk":"5347783223","pt":1646207686589,"mc":[{"id":"1.195453611","rc":[{"atb":[[18,3.34]],"id":41762566},{"atl":[[40,4.04]],"id":41676292}],"con":true,"img":false}]}
{"op":"mcm","clk":"5347783394","pt":1646207690505,"mc":[{"id":"1.195453611","rc":[{"atl":[[4.5,0]],"id":43167172}],"con":true,"img":false}]}
{"op":"mcm","clk":"5347783400","pt":1646207690611,"mc":[{"id":"1.195453611","rc":[{"atl":[[4.4,18.29]],"id":43167172}],"con":true,"img":false}]}
{"op":"mcm","clk":"5347783899","pt":1646207700990,"mc":[{"id":"1.195453611","rc":[{"atb":[[13.5,0]],"id":41676292}],"con":true,"img":false}]}
{"op":"mcm","clk":"5347783904","pt":1646207701093,"mc":[{"id":"1.195453611","rc":[{"atb":[[13,0.84]],"id":41676292}],"con":true,"img":false}]}
{"op":"mcm","clk":"5347784351","pt":1646207710612,"mc":[{"id":"1.195453611","rc":[{"atb":[[2.72,0]],"id":43167172}],"con":true,"img":false}]}
{"op":"mcm","clk":"5347784357","pt":1646207710714,"mc":[{"id":"1.195453611","rc":[{"atb":[[2.76,12.31]],"id":43167172}],"con":true,"img":false}]}
{"op":"mcm","clk":"5347784367","pt":1646207711021,"mc":[{"id":"1.195453611","rc":[{"atb":[[2.74,1.49]],"id":43167172}],"con":true,"img":false}]}
{"op":"mcm","clk":"5347784373","pt":1646207711126,"mc":[{"id":"1.195453611","rc":[{"atb":[[2.78,1.36]],"id":43167172}],"con":true,"img":false}]}
{"op":"mcm","clk":"5347784578","pt":1646207715341,"mc":[{"id":"1.195453611","rc":[{"atb":[[2.02,0]],"id":43167172}],"con":true,"img":false}]}
{"op":"mcm","clk":"5347784585","pt":1646207715444,"mc":[{"id":"1.195453611","rc":[{"atb":[[2.22,124.45]],"id":43167172}],"con":true,"img":false}]}
{"op":"mcm","clk":"5347784603","pt":1646207715750,"mc":[{"id":"1.195453611","rc":[{"atb":[[2.74,0]],"id":43167172}],"con":true,"img":false}]}
{"op":"mcm","clk":"5347784609","pt":1646207715809,"mc":[{"id":"1.195453611","rc":[{"atb":[[2.78,2.86]],"id":43167172}],"con":true,"img":false}]}
{"op":"mcm","clk":"5347785090","pt":1646207724754,"mc":[{"id":"1.195453611","rc":[{"spn":3.09,"spf":"NaN","id":43066529},{"spn":26.5,"spf":"NaN","id":41676292},{"atb":[[2.24,0]],"id":43167172},{"spn":3.39,"spf":"NaN","id":43167172}],"con":true,"img":false}]}
{"op":"mcm","clk":"5347785162","pt":1646207725935,"mc":[{"id":"1.195453611","rc":[{"atl":[[1000,2.25]],"id":41676292}],"con":true,"img":false}]}
{"op":"mcm","clk":"5347785169","pt":1646207726038,"mc":[{"id":"1.195453611","rc":[{"atl":[[1000,0.09]],"id":41676292}],"con":true,"img":false}]}
{"op":"mcm","clk":"5347785178","pt":1646207726242,"mc":[{"id":"1.195453611","rc":[{"atl":[[1000,0]],"id":41676292}],"con":true,"img":false}]}
{"op":"mcm","clk":"5347785183","pt":1646207726347,"mc":[{"id":"1.195453611","rc":[{"atl":[[38,0.09]],"id":41676292}],"con":true,"img":false}]}
{"op":"mcm","clk":"5347785560","pt":1646207733742,"mc":[{"id":"1.195453611","rc":[{"atb":[[2.26,7.82]],"id":43167172}],"con":true,"img":false}]}
{"op":"mcm","clk":"5347785568","pt":1646207733843,"mc":[{"id":"1.195453611","rc":[{"atl":[[4.2,0]],"id":43167172}],"con":true,"img":false}]}
{"op":"mcm","clk":"5347785584","pt":1646207734150,"mc":[{"id":"1.195453611","rc":[{"atb":[[12,0]],"id":41676292}],"con":true,"img":false}]}
{"op":"mcm","clk":"5347785589","pt":1646207734252,"mc":[{"id":"1.195453611","rc":[{"atb":[[11.5,9.74]],"id":41676292}],"con":true,"img":false}]}
{"op":"mcm","clk":"5347785628","pt":1646207734969,"mc":[{"id":"1.195453611","rc":[{"atb":[[2.06,0]],"id":43167172}],"con":true,"img":false}]}
{"op":"mcm","clk":"5347785912","pt":1646207740558,"mc":[{"id":"1.195453611","rc":[{"atb":[[2.76,0]],"id":43167172}],"con":true,"img":false}]}
{"op":"mcm","clk":"5347785920","pt":1646207740660,"mc":[{"id":"1.195453611","rc":[{"atb":[[2.8,12.31]],"id":43167172}],"con":true,"img":false}]}
{"op":"mcm","clk":"5347785936","pt":1646207741072,"mc":[{"id":"1.195453611","rc":[{"atb":[[2.78,1.49]],"id":43167172}],"con":true,"img":false}]}
{"op":"mcm","clk":"5347785939","pt":1646207741174,"mc":[{"id":"1.195453611","rc":[{"atb":[[2.82,1.36]],"id":43167172}],"con":true,"img":false}]}
{"op":"mcm","clk":"5347786186","pt":1646207746769,"mc":[{"id":"1.195453611","rc":[{"atb":[[2.26,15.84]],"id":43167172}],"con":true,"img":false}]}
{"op":"mcm","clk":"5347786624","pt":1646207755171,"mc":[{"id":"1.195453611","rc":[{"atb":[[1.34,0]],"id":43167172}],"con":true,"img":false}]}
{"op":"mcm","clk":"5347786902","pt":1646207760866,"mc":[{"id":"1.195453611","rc":[{"atl":[[190,0]],"id":42651625}],"con":true,"img":false}]}
{"op":"mcm","clk":"5347786908","pt":1646207760970,"mc":[{"id":"1.195453611","rc":[{"atl":[[180,0.39]],"id":42651625}],"con":true,"img":false}]}
{"op":"mcm","clk":"5347786925","pt":1646207761276,"mc":[{"id":"1.195453611","rc":[{"atb":[[2.78,0]],"id":43167172}],"con":true,"img":false}]}
{"op":"mcm","clk":"5347786931","pt":1646207761379,"mc":[{"id":"1.195453611","rc":[{"atb":[[2.82,2.86]],"id":43167172}],"con":true,"img":false}]}
{"op":"mcm","clk":"5347788146","pt":1646207785921,"mc":[{"id":"1.195453611","rc":[{"spn":106.0,"spf":"NaN","id":42651625},{"spn":25.5,"spf":"NaN","id":41676292},{"atb":[[2.8,0],[2.84,11.53]],"id":43167172},{"spn":3.42,"spf":"NaN","id":43167172}],"con":true,"img":false}]}
{"op":"mcm","clk":"5347788157","pt":1646207786126,"mc":[{"id":"1.195453611","rc":[{"atb":[[2.82,1.49]],"id":43167172}],"con":true,"img":false}]}
{"op":"mcm","clk":"5347788162","pt":1646207786230,"mc":[{"id":"1.195453611","rc":[{"atb":[[2.82,0],[2.86,1.36]],"id":43167172}],"con":true,"img":false}]}
{"op":"mcm","clk":"5347788166","pt":1646207786331,"mc":[{"id":"1.195453611","rc":[{"atb":[[2.86,2.86]],"id":43167172}],"con":true,"img":false}]}
{"op":"mcm","clk":"5347788285","pt":1646207788595,"mc":[{"id":"1.195453611","rc":[{"atb":[[2.08,0]],"id":43167173}],"con":true,"img":false}]}
{"op":"mcm","clk":"5347788293","pt":1646207788698,"mc":[{"id":"1.195453611","rc":[{"atb":[[2.18,104.08]],"id":43167173}],"con":true,"img":false}]}
{"op":"mcm","clk":"5347789341","pt":1646207812129,"mc":[{"id":"1.195453611","rc":[{"atb":[[2.84,0]],"id":43167172}],"con":true,"img":false}]}
{"op":"mcm","clk":"5347789345","pt":1646207812238,"mc":[{"id":"1.195453611","rc":[{"atb":[[2.88,11.53]],"id":43167172}],"con":true,"img":false}]}
{"op":"mcm","clk":"5347789374","pt":1646207812745,"mc":[{"id":"1.195453611","rc":[{"atb":[[2.86,1.49]],"id":43167172}],"con":true,"img":false}]}
{"op":"mcm","clk":"5347789377","pt":1646207812852,"mc":[{"id":"1.195453611","rc":[{"atb":[[2.9,1.36]],"id":43167172}],"con":true,"img":false}]}
{"op":"mcm","clk":"5347793540","pt":1646207906271,"mc":[{"id":"1.195453611","rc":[{"atb":[[1.03,2.25]],"id":41676292},{"spn":3.45,"spf":"NaN","id":43167172}],"con":true,"img":false}]}
{"op":"mcm","clk":"5347793549","pt":1646207906471,"mc":[{"id":"1.195453611","rc":[{"atb":[[1.03,0.27]],"id":41676292}],"con":true,"img":false}]}
{"op":"mcm","clk":"5347793556","pt":1646207906630,"mc":[{"id":"1.195453611","rc":[{"atb":[[1.03,0]],"id":41676292}],"con":true,"img":false}]}
{"op":"mcm","clk":"5347793561","pt":1646207906733,"mc":[{"id":"1.195453611","rc":[{"atb":[[13.5,0.27]],"id":41676292}],"con":true,"img":false}]}
{"op":"mcm","clk":"5347795924","pt":1646207967134,"mc":[{"id":"1.195453611","rc":[{"spl":[[1.01,10.91]],"id":43066529},{"spn":2.88,"spf":1.0,"id":43066529},{"spn":25.75,"spf":"NaN","id":41676292}],"con":true,"img":false}]}
{"op":"mcm","clk":"5347796964","pt":1646207991375,"mc":[{"id":"1.195453611","rc":[{"atb":[[13,0]],"id":41676292}],"con":true,"img":false}]}
{"op":"mcm","clk":"5347796967","pt":1646207991471,"mc":[{"id":"1.195453611","rc":[{"atb":[[13.5,1.08]],"id":41676292}],"con":true,"img":false}]}
{"op":"mcm","clk":"5347797575","pt":1646208004708,"mc":[{"id":"1.195453611","rc":[{"atb":[[2.18,0]],"id":43167173}],"con":true,"img":false}]}
{"op":"mcm","clk":"5347797583","pt":1646208004766,"mc":[{"id":"1.195453611","rc":[{"atb":[[2.08,104.08]],"id":43167173}],"con":true,"img":false}]}
{"op":"mcm","clk":"5347804397","pt":1646208177338,"mc":[{"id":"1.195453611","rc":[{"spl":[[1.01,30.02]],"id":41762566},{"spn":13.1,"spf":1.18,"id":41762566},{"spl":[[1.01,40.93]],"id":43066529},{"spn":2.87,"spf":1.0,"id":43066529},{"spl":[[1.01,30.02]],"id":42651625},{"spn":18.37,"spf":1.0,"id":42651625},{"spl":[[1.01,30.02]],"id":41676292},{"spn":10.16,"spf":1.0,"id":41676292},{"spl":[[1.01,30.02]],"id":43167172},{"spn":2.7,"spf":1.0,"id":43167172},{"spl":[[1.01,30.02]],"id":43167173},{"spn":2.36,"spf":1.0,"id":43167173}],"con":true,"img":false}]}
{"op":"mcm","clk":"5347804629","pt":1646208182231,"mc":[{"id":"1.195453611","rc":[{"atb":[[1.04,1.67]],"id":43066529},{"atb":[[1.04,1.67]],"id":43167172},{"atb":[[1.04,1.67]],"id":43167173}],"con":true,"img":false}]}
{"op":"mcm","clk":"5347804642","pt":1646208182440,"mc":[{"id":"1.195453611","rc":[{"atb":[[1.04,1.66]],"id":43066529},{"atb":[[1.04,1.66]],"id":43167172},{"atb":[[1.04,1.66]],"id":43167173}],"con":true,"img":false}]}
{"op":"mcm","clk":"5347804650","pt":1646208182541,"mc":[{"id":"1.195453611","rc":[{"atb":[[1.04,0]],"id":43066529},{"atb":[[1.04,0]],"id":43167172},{"atb":[[1.04,0]],"id":43167173}],"con":true,"img":false}]}
{"op":"mcm","clk":"5347804656","pt":1646208182645,"mc":[{"id":"1.195453611","rc":[{"atb":[[2.94,1.66]],"id":43066529},{"atb":[[2.94,1.66]],"id":43167172},{"atb":[[2.44,1.66]],"id":43167173}],"con":true,"img":false}]}
{"op":"mcm","clk":"5347804840","pt":1646208186115,"mc":[{"id":"1.195453611","rc":[{"atb":[[12,1.57]],"id":41676292},{"atb":[[2.86,0]],"id":43167172}],"con":true,"img":false}]}
{"op":"mcm","clk":"5347804846","pt":1646208186217,"mc":[{"id":"1.195453611","rc":[{"atb":[[2.9,2.86]],"id":43167172}],"con":true,"img":false}]}
{"op":"mcm","clk":"5347805713","pt":1646208207188,"mc":[{"id":"1.195453611","rc":[{"atb":[[2.88,0]],"id":43167172}],"con":true,"img":false}]}
{"op":"mcm","clk":"5347805718","pt":1646208207242,"mc":[{"id":"1.195453611","rc":[{"atb":[[2.92,11.53]],"id":43167172}],"con":true,"img":false}]}
{"op":"mcm","clk":"5347805727","pt":1646208207448,"mc":[{"id":"1.195453611","rc":[{"atb":[[2.9,1.36]],"id":43167172},{"atl":[[4.8,61.41],[4.9,0]],"id":43167173}],"con":true,"img":false}]}
{"op":"mcm","clk":"5347805733","pt":1646208207552,"mc":[{"id":"1.195453611","rc":[{"atb":[[2.66,1.49]],"id":43167172}],"con":true,"img":false}]}
{"op":"mcm","clk":"5347805775","pt":1646208208376,"mc":[{"id":"1.195453611","rc":[{"atb":[[2.66,0]],"id":43167172}],"con":true,"img":false}]}
{"op":"mcm","clk":"5347805783","pt":1646208208483,"mc":[{"id":"1.195453611","rc":[{"atb":[[2.94,3.15]],"id":43167172}],"con":true,"img":false}]}
{"op":"mcm","clk":"5347806691","pt":1646208233281,"mc":[{"id":"1.195453611","rc":[{"atb":[[2.92,0]],"id":43167172}],"con":true,"img":false}]}
{"op":"mcm","clk":"5347806698","pt":1646208233383,"mc":[{"id":"1.195453611","rc":[{"atb":[[2.96,11.53]],"id":43167172}],"con":true,"img":false}]}
{"op":"mcm","clk":"5347806711","pt":1646208233698,"mc":[{"id":"1.195453611","rc":[{"atb":[[2.94,1.66]],"id":43167172}],"con":true,"img":false}]}
{"op":"mcm","clk":"5347806717","pt":1646208233793,"mc":[{"id":"1.195453611","rc":[{"atb":[[2.98,1.49]],"id":43167172}],"con":true,"img":false}]}
{"op":"mcm","clk":"5347806723","pt":1646208234102,"mc":[{"id":"1.195453611","rc":[{"atb":[[2.9,0]],"id":43167172}],"con":true,"img":false}]}
{"op":"mcm","clk":"5347806724","pt":1646208234204,"mc":[{"id":"1.195453611","rc":[{"atb":[[2.66,1.36]],"id":43167172}],"con":true,"img":false}]}
{"op":"mcm","clk":"5347806766","pt":1646208235191,"mc":[{"id":"1.195453611","rc":[{"atb":[[2.94,0],[1.04,1.67]],"id":43167172}],"con":true,"img":false}]}
{"op":"mcm","clk":"5347806775","pt":1646208235284,"mc":[{"id":"1.195453611","rc":[{"atb":[[1.04,1.66]],"id":43167172}],"con":true,"img":false}]}
{"op":"mcm","clk":"5347806781","pt":1646208235387,"mc":[{"id":"1.195453611","rc":[{"atb":[[1.04,0]],"id":43167172}],"con":true,"img":false}]}
{"op":"mcm","clk":"5347806789","pt":1646208235492,"mc":[{"id":"1.195453611","rc":[{"atb":[[3.05,1.66]],"id":43167172}],"con":true,"img":false}]}
{"op":"mcm","clk":"5347807137","pt":1646208244800,"mc":[{"id":"1.195453611","rc":[{"spn":2.87,"spf":1.0,"id":43066529},{"spn":10.39,"spf":1.0,"id":41676292},{"atb":[[2.26,9.87]],"id":43167172},{"spn":2.77,"spf":1.0,"id":43167172},{"spn":2.36,"spf":1.0,"id":43167173}],"con":true,"img":false}]}
{"op":"mcm","clk":"5347807867","pt":1646208260641,"mc":[{"id":"1.195453611","rc":[{"atb":[[2.96,0]],"id":43167172}],"con":true,"img":false}]}
{"op":"mcm","clk":"5347807873","pt":1646208260745,"mc":[{"id":"1.195453611","rc":[{"atb":[[3,11.53]],"id":43167172}],"con":true,"img":false}]}
{"op":"mcm","clk":"5347807913","pt":1646208261725,"mc":[{"id":"1.195453611","rc":[{"atb":[[2.98,0]],"id":43167172}],"con":true,"img":false}]}
{"op":"mcm","clk":"5347807918","pt":1646208261826,"mc":[{"id":"1.195453611","rc":[{"atb":[[3.05,3.15]],"id":43167172}],"con":true,"img":false}]}
{"op":"mcm","clk":"5347808580","pt":1646208279066,"mc":[{"id":"1.195453611","rc":[{"atb":[[2.26,1.84]],"id":43167172}],"con":true,"img":false}]}
{"op":"mcm","clk":"5347810876","pt":1646208335043,"mc":[{"id":"1.195453611","rc":[{"atb":[[10,0],[7.4,15.62]],"id":41762566},{"spn":12.97,"spf":1.18,"id":41762566},{"atb":[[9,12.5],[11.5,0]],"id":42651625},{"atl":[[390,2.51],[440,0]],"id":42651625},{"spn":18.17,"spf":1.0,"id":42651625},{"atb":[[3.85,35.09],[4.4,0]],"id":41676292},{"spn":2.79,"spf":1.0,"id":43167172},{"atl":[[4.8,35.09],[4.6,27.78]],"id":43167173}],"con":true,"img":false}]}
{"op":"mcm","clk":"5347810879","pt":1646208335143,"mc":[{"id":"1.195453611","rc":[{"atb":[[10.5,9.52],[7.4,0]],"id":41762566},{"atb":[[11.5,9.52]],"id":42651625},{"atb":[[3.85,0],[4.5,28.57]],"id":41676292},{"atl":[[4.5,28.57]],"id":43167173}],"con":true,"img":false}]}
{"op":"mcm","clk":"5347810887","pt":1646208335251,"mc":[{"id":"1.195453611","rc":[{"atb":[[9,0]],"id":42651625},{"atl":[[4.6,0]],"id":43167173}],"con":true,"img":false}]}
{"op":"mcm","clk":"5347812084","pt":1646208360286,"mc":[{"id":"1.195453611","rc":[{"atb":[[1.09,1.67]],"id":41762566},{"atb":[[1.03,1.67]],"id":43066529},{"atb":[[1.17,1.67]],"id":42651625},{"atb":[[1.06,1.67]],"id":41676292},{"atb":[[1.03,1.67]],"id":43167172},{"atb":[[1.01,1.67]],"id":43167173}],"con":true,"img":false}]}
{"op":"mcm","clk":"5347812103","pt":1646208360550,"mc":[{"id":"1.195453611","rc":[{"atb":[[1.09,0.08]],"id":41762566},{"atb":[[1.03,0.55]],"id":43066529},{"atb":[[1.17,0.04]],"id":42651625},{"atb":[[1.06,0.11]],"id":41676292},{"atb":[[1.03,0.53]],"id":43167172},{"atb":[[1.01,0.67]],"id":43167173}],"con":true,"img":false}]}
{"op":"mcm","clk":"5347812118","pt":1646208360759,"mc":[{"id":"1.195453611","rc":[{"atb":[[1.09,0]],"id":41762566},{"atb":[[1.03,0]],"id":43066529},{"atb":[[1.17,0]],"id":42651625},{"atb":[[1.06,0]],"id":41676292},{"atb":[[1.03,0]],"id":43167172},{"atb":[[1.01,0]],"id":43167173}],"con":true,"img":false}]}
{"op":"mcm","clk":"5347812124","pt":1646208360856,"mc":[{"id":"1.195453611","rc":[{"atb":[[19,0.65]],"id":41762566},{"atb":[[2.96,0.55]],"id":43066529},{"atb":[[34,0.04]],"id":42651625},{"atb":[[14,0.11]],"id":41676292},{"atb":[[3.1,0.53]],"id":43167172},{"atb":[[2.46,0.67]],"id":43167173}],"con":true,"img":false}]}
{"op":"mcm","clk":"5347812285","pt":1646208364772,"mc":[{"id":"1.195453611","rc":[{"atb":[[1.04,1.67]],"id":43167173}],"con":true,"img":false}]}
{"op":"mcm","clk":"5347812290","pt":1646208364872,"mc":[{"id":"1.195453611","rc":[{"atb":[[2.44,0]],"id":43167173}],"con":true,"img":false}]}
{"op":"mcm","clk":"5347812292","pt":1646208364974,"mc":[{"id":"1.195453611","rc":[{"atb":[[1.04,1.66]],"id":43167173}],"con":true,"img":false}]}
{"op":"mcm","clk":"5347812301","pt":1646208365181,"mc":[{"id":"1.195453611","rc":[{"atb":[[1.04,0]],"id":43167173}],"con":true,"img":false}]}
{"op":"mcm","clk":"5347812306","pt":1646208365283,"mc":[{"id":"1.195453611","rc":[{"atb":[[2.52,1.66]],"id":43167173}],"con":true,"img":false}]}
{"op":"mcm","clk":"5347813367","pt":1646208390099,"mc":[{"id":"1.195453611","rc":[{"atl":[[4.8,0]],"id":43167173}],"con":true,"img":false}]}
{"op":"mcm","clk":"5347813371","pt":1646208390199,"mc":[{"id":"1.195453611","rc":[{"atl":[[4.4,35.09]],"id":43167173}],"con":true,"img":false}]}
{"op":"mcm","clk":"5347814511","pt":1646208417944,"mc":[{"id":"1.195453611","rc":[{"atb":[[17,6.97]],"id":41762566},{"spn":14.83,"spf":1.18,"id":41762566},{"spn":2.87,"spf":1.0,"id":43066529},{"spn":18.4,"spf":1.0,"id":42651625},{"spn":10.41,"spf":1.0,"id":41676292},{"spn":2.81,"spf":1.0,"id":43167172},{"spn":2.37,"spf":1.0,"id":43167173}],"con":true,"img":false}]}
{"op":"mcm","clk":"5347814515","pt":1646208418049,"mc":[{"id":"1.195453611","rc":[{"atb":[[14,0]],"id":41762566}],"con":true,"img":false}]}
{"op":"mcm","clk":"5347816081","pt":1646208455098,"mc":[{"id":"1.195453611","rc":[{"atl":[[4.8,26.32],[4.5,0]],"id":43167173}],"con":true,"img":false}]}
{"op":"mcm","clk":"5347816103","pt":1646208455716,"mc":[{"id":"1.195453611","rc":[{"atl":[[4.4,0]],"id":43167173}],"con":true,"img":false}]}
{"op":"mcm","clk":"5347816109","pt":1646208455819,"mc":[{"id":"1.195453611","rc":[{"atl":[[4.7,35.09]],"id":43167173}],"con":true,"img":false}]}
{"op":"mcm","clk":"5347820412","pt":1646208556497,"mc":[{"id":"1.195453611","rc":[{"spn":13.75,"spf":1.18,"id":41762566},{"atb":[[2.6,0],[1.53,95.84]],"id":43066529},{"atl":[[9.8,11.36],[7,33.35]],"id":43167172}],"con":true,"img":false}]}
{"op":"mcm","clk":"5347821619","pt":1646208586330,"mc":[{"id":"1.195453611","rc":[{"atl":[[75,0]],"id":41762566}],"con":true,"img":false}]}
{"op":"mcm","clk":"5347821623","pt":1646208586431,"mc":[{"id":"1.195453611","rc":[{"atl":[[65,2.72]],"id":41762566}],"con":true,"img":false}]}
{"op":"mcm","clk":"5347822926","pt":1646208613959,"mc":[{"id":"1.195453611","rc":[{"atb":[[2.08,0]],"id":43167173}],"con":true,"img":false}]}
{"op":"mcm","clk":"5347822934","pt":1646208614059,"mc":[{"id":"1.195453611","rc":[{"atb":[[2.18,104.08]],"id":43167173}],"con":true,"img":false}]}
{"op":"mcm","clk":"5347824912","pt":1646208657427,"mc":[{"id":"1.195453611","rc":[{"atb":[[1.03,2.25]],"id":41676292}],"con":true,"img":false}]}
{"op":"mcm","clk":"5347824917","pt":1646208657528,"mc":[{"id":"1.195453611","rc":[{"atb":[[13.5,0.81]],"id":41676292}],"con":true,"img":false}]}
{"op":"mcm","clk":"5347824924","pt":1646208657634,"mc":[{"id":"1.195453611","rc":[{"atb":[[1.03,0.25]],"id":41676292}],"con":true,"img":false}]}
{"op":"mcm","clk":"5347824949","pt":1646208658139,"mc":[{"id":"1.195453611","rc":[{"atb":[[1.03,0]],"id":41676292}],"con":true,"img":false}]}
{"op":"mcm","clk":"5347824952","pt":1646208658242,"mc":[{"id":"1.195453611","rc":[{"atb":[[14.5,0.25]],"id":41676292}],"con":true,"img":false}]}
{"op":"mcm","clk":"5347826147","pt":1646208686647,"mc":[{"id":"1.195453611","rc":[{"atb":[[1.36,0]],"id":43167173}],"con":true,"img":false}]}
{"op":"mcm","clk":"5347826160","pt":1646208686856,"mc":[{"id":"1.195453611","rc":[{"atl":[[320,2],[390,0]],"id":41762566},{"atb":[[11.5,0],[17,6.25]],"id":42651625},{"atl":[[390,0.51],[470,2]],"id":42651625},{"atb":[[2.76,46.3],[4.5,0]],"id":41676292},{"atb":[[1.69,0],[1.74,135.14]],"id":43167172},{"atb":[[1.98,83.54],[2.06,171.58]],"id":43167173},{"atl":[[4.8,0],[4.5,28.57]],"id":43167173}],"con":true,"img":false}]}
{"op":"mcm","clk":"5347827111","pt":1646208709196,"mc":[{"id":"1.195453611","rc":[{"spl":[[1.01,37.02]],"id":41762566},{"spl":[[1.01,37.02]],"id":42651625},{"spl":[[1.01,37.02]],"id":41676292}],"con":true,"img":false}]}
{"op":"mcm","clk":"5347827229","pt":1646208711677,"mc":[{"id":"1.195453611","rc":[{"atb":[[2.76,0],[5.2,23.81]],"id":41676292}],"con":true,"img":false}]}
{"op":"mcm","clk":"5347827586","pt":1646208719569,"mc":[{"id":"1.195453611","rc":[{"spn":12.96,"spf":1.14,"id":41762566},{"spl":[[1.01,40.02]],"id":42651625},{"spn":17.3,"spf":1.0,"id":42651625},{"spl":[[1.01,40.02]],"id":41676292},{"spn":9.72,"spf":1.0,"id":41676292}],"con":true,"img":false}]}
{"op":"mcm","clk":"5347827776","pt":1646208723386,"mc":[{"id":"1.195453611","rc":[{"atb":[[12.5,8.7],[17,0]],"id":42651625},{"atl":[[420,2],[470,0]],"id":42651625},{"atl":[[50,4.76],[55,0]],"id":41676292}],"con":true,"img":false}]}
{"op":"mcm","clk":"5347827790","pt":1646208723594,"mc":[{"id":"1.195453611","rc":[{"atl":[[38,0],[1000,2.25]],"id":41676292}],"con":true,"img":false}]}
{"op":"mcm","clk":"5347827801","pt":1646208723806,"mc":[{"id":"1.195453611","rc":[{"atl":[[1000,0.09]],"id":41676292}],"con":true,"img":false}]}
{"op":"mcm","clk":"5347827818","pt":1646208724010,"mc":[{"id":"1.195453611","rc":[{"atl":[[1000,0]],"id":41676292}],"con":true,"img":false}]}
{"op":"mcm","clk":"5347827825","pt":1646208724106,"mc":[{"id":"1.195453611","rc":[{"atl":[[48,0.09]],"id":41676292}],"con":true,"img":false}]}
{"op":"mcm","clk":"5347828655","pt":1646208741507,"mc":[{"id":"1.195453611","rc":[{"atl":[[4.7,0]],"id":43167173}],"con":true,"img":false}]}
{"op":"mcm","clk":"5347828661","pt":1646208741606,"mc":[{"id":"1.195453611","rc":[{"atl":[[4.4,35.09]],"id":43167173}],"con":true,"img":false}]}
{"op":"mcm","clk":"5347828945","pt":1646208747900,"mc":[{"id":"1.195453611","rc":[{"atl":[[48,2.22],[50,2.72]],"id":41676292}],"con":true,"img":false}]}
{"op":"mcm","clk":"5347830387","pt":1646208777872,"mc":[{"id":"1.195453611","rc":[{"atl":[[50,0]],"id":41676292}],"con":true,"img":false}]}
{"op":"mcm","clk":"5347830393","pt":1646208777977,"mc":[{"id":"1.195453611","rc":[{"atl":[[46,2.72]],"id":41676292}],"con":true,"img":false}]}
{"op":"mcm","clk":"5347833657","pt":1646208843332,"mc":[{"id":"1.195453611","rc":[{"spn":16.72,"spf":1.0,"id":42651625},{"atb":[[1.67,126.32]],"id":43167172}],"con":true,"img":false}]}
{"op":"mcm","clk":"5347833662","pt":1646208843500,"mc":[{"id":"1.195453611","rc":[{"atb":[[4.5,28.57],[5.2,0]],"id":41676292},{"atl":[[48,0.09],[55,2]],"id":41676292},{"atb":[[1.74,0]],"id":43167172},{"atl":[[4.8,26.32],[4.5,0]],"id":43167173}],"con":true,"img":false}]}
{"op":"mcm","clk":"5347833711","pt":1646208844459,"mc":[{"id":"1.195453611","rc":[{"atl":[[46,0]],"id":41676292},{"atl":[[4.4,0]],"id":43167173}],"con":true,"img":false}]}
{"op":"mcm","clk":"5347833716","pt":1646208844562,"mc":[{"id":"1.195453611","rc":[{"atl":[[50,2.72]],"id":41676292},{"atl":[[4.7,35.09]],"id":43167173}],"con":true,"img":false}]}
{"op":"mcm","clk":"5347836521","pt":1646208898221,"mc":[{"id":"1.195453611","rc":[{"atl":[[50,0]],"id":41676292}],"con":true,"img":false}]}
{"op":"mcm","clk":"5347836526","pt":1646208898321,"mc":[{"id":"1.195453611","rc":[{"atl":[[46,2.72]],"id":41676292}],"con":true,"img":false}]}
{"op":"mcm","clk":"5347836561","pt":1646208898994,"mc":[{"id":"1.195453611","rc":[{"atl":[[46,0]],"id":41676292}],"con":true,"img":false}]}
{"op":"mcm","clk":"5347836568","pt":1646208899097,"mc":[{"id":"1.195453611","rc":[{"atl":[[50,2.72]],"id":41676292}],"con":true,"img":false}]}
{"op":"mcm","clk":"5347839781","pt":1646208953118,"mc":[{"id":"1.195453611","rc":[{"atl":[[50,0]],"id":41676292}],"con":true,"img":false}]}
{"op":"mcm","clk":"5347839789","pt":1646208953170,"mc":[{"id":"1.195453611","rc":[{"atl":[[46,2.72]],"id":41676292}],"con":true,"img":false}]}
{"op":"mcm","clk":"5347839834","pt":1646208953891,"mc":[{"id":"1.195453611","rc":[{"atl":[[46,0]],"id":41676292}],"con":true,"img":false}]}
{"op":"mcm","clk":"5347839843","pt":1646208953994,"mc":[{"id":"1.195453611","rc":[{"atl":[[50,2.72]],"id":41676292}],"con":true,"img":false}]}
{"op":"mcm","clk":"5347839854","pt":1646208954200,"mc":[{"id":"1.195453611","rc":[{"atl":[[40,2.72]],"id":41676292}],"con":true,"img":false}]}
{"op":"mcm","clk":"5347839860","pt":1646208954302,"mc":[{"id":"1.195453611","rc":[{"atl":[[1000,1.31]],"id":41676292}],"con":true,"img":false}]}
{"op":"mcm","clk":"5347839884","pt":1646208954816,"mc":[{"id":"1.195453611","rc":[{"atl":[[1000,0]],"id":41676292}],"con":true,"img":false}]}
{"op":"mcm","clk":"5347839888","pt":1646208954868,"mc":[{"id":"1.195453611","rc":[{"atl":[[38,1.31]],"id":41676292}],"con":true,"img":false}]}
{"op":"mcm","clk":"5347851145","pt":1646209007372,"mc":[{"id":"1.195453611","rc":[{"atb":[[13.5,0]],"id":41676292}],"con":true,"img":false}]}
{"op":"mcm","clk":"5347851151","pt":1646209007479,"mc":[{"id":"1.195453611","rc":[{"atb":[[13,0.84]],"id":41676292}],"con":true,"img":false}]}
{"op":"mcm","clk":"5347865433","pt":1646209261689,"mc":[{"id":"1.195453611","rc":[{"atb":[[27,4.65]],"id":42651625},{"spn":16.55,"spf":1.0,"id":42651625},{"spn":9.71,"spf":1.0,"id":41676292}],"con":true,"img":false}]}
{"op":"mcm","clk":"5347865447","pt":1646209261893,"mc":[{"id":"1.195453611","rc":[{"atb":[[30,0.35]],"id":42651625}],"con":true,"img":false}]}
{"op":"mcm","clk":"5347865507","pt":1646209262979,"mc":[{"id":"1.195453611","rc":[{"atb":[[11,12.5],[12,6.82],[13,4.17],[14,1.54]],"id":41762566},{"atl":[[330,1],[350,1],[370,1],[390,1]],"id":41762566},{"atb":[[1.59,124.98],[1.63,31.21],[1.57,215.6],[1.61,80.59]],"id":43066529},{"atl":[[8,7.14],[8.4,28.16],[7.6,3.03],[8.8,16.03]],"id":43066529},{"atb":[[12,11.36],[13,13.07],[14,3.85],[15,1.43]],"id":42651625},{"atl":[[380,1],[400,1],[420,3],[440,1]],"id":42651625},{"atb":[[9,9.38],[9.4,5.95],[8.6,21.83],[9.8,14.64]],"id":41676292},{"atl":[[32,1],[36,1.43],[40,4.64],[44,2.91]],"id":41676292},{"atb":[[2.22,140.84],[2.14,65.79],[2.1,113.64],[2.18,42.37]],"id":43167172},{"atl":[[10.5,5.26],[11.5,7.14],[12.5,10.87],[9.8,13.63]],"id":43167172},{"atb":[[2.22,88.96],[2.26,29.87],[2.14,109.65],[2.18,167.64]],"id":43167173},{"atl":[[3.85,43.86],[3.55,7.84],[3.75,27.27],[3.65,18.87]],"id":43167173}],"con":true,"img":false}]}
{"op":"mcm","clk":"5347865523","pt":1646209263288,"mc":[{"id":"1.195453611","rc":[{"atl":[[290,1.69],[330,0]],"id":41762566},{"atl":[[7.2,3.23],[7.6,0]],"id":43066529},{"atb":[[12.5,0],[3.75,36.36]],"id":42651625},{"atl":[[380,0],[430,1]],"id":42651625},{"atb":[[5,25]],"id":41676292},{"atb":[[1.72,126.32],[1.67,0]],"id":43167172},{"atl":[[4.3,19.84]],"id":43167173}],"con":true,"img":false}]}
{"op":"mcm","clk":"5347865529","pt":1646209263391,"mc":[{"id":"1.195453611","rc":[{"atb":[[4.5,0]],"id":41676292},{"atl":[[3.5,1.25]],"id":43167173}],"con":true,"img":false}]}
{"op":"mcm","clk":"5347865571","pt":1646209264069,"mc":[{"id":"1.195453611","rc":[{"atl":[[4.5,0]],"id":43066529},{"atb":[[13.5,2.08]],"id":41676292}],"con":true,"img":false}]}
{"op":"mcm","clk":"5347865575","pt":1646209264174,"mc":[{"id":"1.195453611","rc":[{"atl":[[4.6,7.27]],"id":43066529}],"con":true,"img":false}]}
{"op":"mcm","clk":"5347865638","pt":1646209265258,"mc":[{"id":"1.195453611","rc":[{"atb":[[1.03,2.92]],"id":41762566},{"atb":[[1.02,3.6]],"id":43066529},{"atb":[[1.02,2.98]],"id":41676292}],"con":true,"img":false}]}
{"op":"mcm","clk":"5347865643","pt":1646209265361,"mc":[{"id":"1.195453611","rc":[{"atb":[[1.02,3.56]],"id":43167172},{"atb":[[1.02,3.81]],"id":43167173}],"con":true,"img":false}]}
{"op":"mcm","clk":"5347865664","pt":1646209265695,"mc":[{"id":"1.195453611","rc":[{"atb":[[1.03,0.19]],"id":41762566},{"atb":[[1.02,0.87]],"id":43066529},{"atb":[[1.02,0.25]],"id":41676292}],"con":true,"img":false}]}
{"op":"mcm","clk":"5347865675","pt":1646209265892,"mc":[{"id":"1.195453611","rc":[{"atb":[[1.02,0.83]],"id":43167172},{"atb":[[1.02,1.08]],"id":43167173}],"con":true,"img":false}]}
{"op":"mcm","clk":"5347865688","pt":1646209266055,"mc":[{"id":"1.195453611","rc":[{"atb":[[1.03,2.9]],"id":42651625}],"con":true,"img":false}]}
{"op":"mcm","clk":"5347865694","pt":1646209266157,"mc":[{"id":"1.195453611","rc":[{"atb":[[1.03,0]],"id":41762566},{"atb":[[1.02,0]],"id":43066529},{"atb":[[1.02,0]],"id":41676292}],"con":true,"img":false}]}
{"op":"mcm","clk":"5347865701","pt":1646209266262,"mc":[{"id":"1.195453611","rc":[{"atb":[[14.5,0.19]],"id":41762566},{"atb":[[3.15,0.87]],"id":43066529},{"atl":[[400,0]],"id":42651625},{"atb":[[11,0.25]],"id":41676292}],"con":true,"img":false}]}
{"op":"mcm","clk":"5347865705","pt":1646209266364,"mc":[{"id":"1.195453611","rc":[{"atb":[[1.02,0]],"id":43167172},{"atb":[[1.02,0]],"id":43167173}],"con":true,"img":false}]}
{"op":"mcm","clk":"5347865715","pt":1646209266468,"mc":[{"id":"1.195453611","rc":[{"atb":[[1.03,0.17]],"id":42651625},{"atb":[[3.3,0.83]],"id":43167172},{"atb":[[2.56,1.08]],"id":43167173}],"con":true,"img":false}]}
{"op":"mcm","clk":"5347865733","pt":1646209266880,"mc":[{"id":"1.195453611","rc":[{"atb":[[1.03,0]],"id":42651625}],"con":true,"img":false}]}
{"op":"mcm","clk":"5347865741","pt":1646209266982,"mc":[{"id":"1.195453611","rc":[{"atb":[[16,0.17]],"id":42651625}],"con":true,"img":false}]}
{"op":"mcm","clk":"5347865753","pt":1646209267182,"mc":[{"id":"1.195453611","rc":[{"atl":[[260,2],[320,0]],"id":41762566},{"atb":[[2.52,0],[1.04,1.67]],"id":43167173}],"con":true,"img":false}]}
{"op":"mcm","clk":"5347865768","pt":1646209267390,"mc":[{"id":"1.195453611","rc":[{"atb":[[1.04,1.66]],"id":43167173}],"con":true,"img":false}]}
{"op":"mcm","clk":"5347865771","pt":1646209267492,"mc":[{"id":"1.195453611","rc":[{"atb":[[1.04,0]],"id":43167173}],"con":true,"img":false}]}
{"op":"mcm","clk":"5347865774","pt":1646209267595,"mc":[{"id":"1.195453611","rc":[{"atb":[[2.62,1.66]],"id":43167173}],"con":true,"img":false}]}
{"op":"mcm","clk":"5347866110","pt":1646209273268,"mc":[{"id":"1.195453611","rc":[{"atl":[[310,1]],"id":41762566},{"atl":[[7.6,7.58]],"id":43066529},{"atl":[[420,2],[450,1]],"id":42651625}],"con":true,"img":false}]}
{"op":"mcm","clk":"5347866403","pt":1646209277588,"mc":[{"id":"1.195453611","rc":[{"atl":[[38,0]],"id":41676292},{"atl":[[3.5,0]],"id":43167173}],"con":true,"img":false}]}
{"op":"mcm","clk":"5347866408","pt":1646209277683,"mc":[{"id":"1.195453611","rc":[{"atl":[[1000,1.31]],"id":41676292},{"atl":[[1000,1.25]],"id":43167173}],"con":true,"img":false}]}
{"op":"mcm","clk":"5347866578","pt":1646209280569,"mc":[{"id":"1.195453611","rc":[{"atb":[[3,0],[3.05,13.89]],"id":43167172}],"con":true,"img":false}]}
{"op":"mcm","clk":"5347866680","pt":1646209282413,"mc":[{"id":"1.195453611","rc":[{"atb":[[15,5.48],[3.75,0]],"id":42651625}],"con":true,"img":false}]}
{"op":"mcm","clk":"5347866726","pt":1646209283085,"mc":[{"id":"1.195453611","rc":[{"atb":[[2.22,40.98]],"id":43167173}],"con":true,"img":false}]}
{"op":"mcm","clk":"5347866733","pt":1646209283190,"mc":[{"id":"1.195453611","rc":[{"atb":[[2.28,47.98]],"id":43167173}],"con":true,"img":false}]}
{"op":"mcm","clk":"5347866739","pt":1646209283293,"mc":[{"id":"1.195453611","rc":[{"atl":[[330,1],[390,0]],"id":41762566},{"atl":[[8,10.71],[8.8,0]],"id":43066529},{"atl":[[470,1]],"id":42651625}],"con":true,"img":false}]}
{"op":"mcm","clk":"5347866817","pt":1646209284787,"mc":[{"id":"1.195453611","rc":[{"atb":[[2.26,23.89]],"id":43167173}],"con":true,"img":false}]}
{"op":"mcm","clk":"5347866908","pt":1646209286599,"mc":[{"id":"1.195453611","rc":[{"atl":[[40,1.92]],"id":41676292}],"con":true,"img":false}]}
{"op":"mcm","clk":"5347866913","pt":1646209286701,"mc":[{"id":"1.195453611","rc":[{"atl":[[38,2.72]],"id":41676292}],"con":true,"img":false}]}
{"op":"mcm","clk":"5347867115","pt":1646209290604,"mc":[{"id":"1.195453611","rc":[{"atl":[[4.6,0]],"id":43066529}],"con":true,"img":false}]}
{"op":"mcm","clk":"5347867122","pt":1646209290709,"mc":[{"id":"1.195453611","rc":[{"atl":[[4.5,7.27]],"id":43066529}],"con":true,"img":false}]}
{"op":"mcm","clk":"5347867266","pt":1646209293320,"mc":[{"id":"1.195453611","rc":[{"atl":[[370,0]],"id":41762566},{"atl":[[8.4,34.91]],"id":43066529},{"atl":[[490,1]],"id":42651625}],"con":true,"img":false}]}
{"op":"mcm","clk":"5347867639","pt":1646209301336,"mc":[{"id":"1.195453611","rc":[{"atb":[[2.26,15.87]],"id":43167173}],"con":true,"img":false}]}
{"op":"mcm","clk":"5347867735","pt":1646209303340,"mc":[{"id":"1.195453611","rc":[{"atl":[[440,0]],"id":42651625}],"con":true,"img":false}]}
{"op":"mcm","clk":"5347867749","pt":1646209303608,"mc":[{"id":"1.195453611","rc":[{"atl":[[8.2,0]],"id":43066529}],"con":true,"img":false}]}
{"op":"mcm","clk":"5347867754","pt":1646209303706,"mc":[{"id":"1.195453611","rc":[{"atl":[[7.4,15.01]],"id":43066529}],"con":true,"img":false}]}
{"op":"mcm","clk":"5347867767","pt":1646209304117,"mc":[{"id":"1.195453611","rc":[{"atl":[[50,0]],"id":41676292}],"con":true,"img":false}]}
{"op":"mcm","clk":"5347867771","pt":1646209304225,"mc":[{"id":"1.195453611","rc":[{"atl":[[42,2.72]],"id":41676292}],"con":true,"img":false}]}
{"op":"mcm","clk":"5347867774","pt":1646209304325,"mc":[{"id":"1.195453611","rc":[{"atl":[[3.55,11.26]],"id":43167173}],"con":true,"img":false}]}
{"op":"mcm","clk":"5347867983","pt":1646209308633,"mc":[{"id":"1.195453611","rc":[{"atb":[[2.28,0]],"id":43167173}],"con":true,"img":false}]}
{"op":"mcm","clk":"5347867986","pt":1646209308734,"mc":[{"id":"1.195453611","rc":[{"atb":[[2.24,47.98]],"id":43167173}],"con":true,"img":false}]}
{"op":"mcm","clk":"5347869334","pt":1646209335687,"mc":[{"id":"1.195453611","rc":[{"atl":[[290,0.69],[300,1]],"id":41762566},{"spn":14.0,"spf":1.14,"id":41762566},{"spn":2.88,"spf":1.0,"id":43066529},{"atl":[[430,0],[440,1]],"id":42651625},{"spn":17.66,"spf":1.0,"id":42651625},{"spn":10.46,"spf":1.0,"id":41676292},{"spn":2.83,"spf":1.0,"id":43167172},{"spn":2.38,"spf":1.0,"id":43167173}],"con":true,"img":false}]}
{"op":"mcm","clk":"5347869904","pt":1646209345710,"mc":[{"id":"1.195453611","rc":[{"atl":[[320,1]],"id":41762566},{"atl":[[460,1]],"id":42651625}],"con":true,"img":false}]}
{"op":"mcm","clk":"5347870371","pt":1646209355675,"mc":[{"id":"1.195453611","rc":[{"atl":[[310,0],[330,0],[350,0],[340,1]],"id":41762566},{"atl":[[450,0],[470,0],[490,0],[480,1]],"id":42651625}],"con":true,"img":false}]}
{"op":"mcm","clk":"5347870853","pt":1646209365706,"mc":[{"id":"1.195453611","rc":[{"atl":[[360,1]],"id":41762566},{"atl":[[500,1]],"id":42651625}],"con":true,"img":false}]}
{"op":"mcm","clk":"5347880828","pt":1646209574743,"mc":[{"id":"1.195453611","rc":[{"atb":[[3.8,0]],"id":41676292}],"con":true,"img":false}]}
{"op":"mcm","clk":"5347886854","pt":1646209695138,"mc":[{"id":"1.195453611","rc":[{"atl":[[7.2,0],[7,3.33]],"id":43066529}],"con":true,"img":false}]}
{"op":"mcm","clk":"5347890882","pt":1646209775675,"mc":[{"id":"1.195453611","rc":[{"atl":[[300,0],[310,1]],"id":41762566},{"atl":[[7.2,3.23],[7,0]],"id":43066529},{"atl":[[440,0],[450,1]],"id":42651625}],"con":true,"img":false}]}
{"op":"mcm","clk":"5347891378","pt":1646209785723,"mc":[{"id":"1.195453611","rc":[{"atl":[[330,1]],"id":41762566},{"atl":[[470,1]],"id":42651625}],"con":true,"img":false}]}
{"op":"mcm","clk":"5347891559","pt":1646209789782,"mc":[{"id":"1.195453611","rc":[{"atl":[[300,1],[310,0],[330,0]],"id":41762566},{"atl":[[7.2,0],[7,3.33]],"id":43066529},{"atl":[[440,1],[450,0],[470,0]],"id":42651625}],"con":true,"img":false}]}
{"op":"mcm","clk":"5347893122","pt":1646209820036,"mc":[{"id":"1.195453611","rc":[{"atl":[[300,0],[310,1]],"id":41762566},{"atl":[[440,0],[450,1]],"id":42651625}],"con":true,"img":false}]}
{"op":"mcm","clk":"5347893630","pt":1646209830051,"mc":[{"id":"1.195453611","rc":[{"atl":[[330,1]],"id":41762566},{"atl":[[470,1]],"id":42651625}],"con":true,"img":false}]}
{"op":"mcm","clk":"5347893880","pt":1646209835067,"mc":[{"id":"1.195453611","rc":[{"atl":[[320,0],[340,0],[360,0]],"id":41762566},{"atl":[[460,0],[480,0],[500,0]],"id":42651625}],"con":true,"img":false}]}
{"op":"mcm","clk":"5347894116","pt":1646209840086,"mc":[{"id":"1.195453611","rc":[{"atl":[[350,1]],"id":41762566},{"atl":[[490,1]],"id":42651625}],"con":true,"img":false}]}
{"op":"mcm","clk":"5347894636","pt":1646209850063,"mc":[{"id":"1.195453611","rc":[{"atl":[[370,1]],"id":41762566},{"atl":[[510,1]],"id":42651625}],"con":true,"img":false}]}
{"op":"mcm","clk":"5347895742","pt":1646209873315,"mc":[{"id":"1.195453611","rc":[{"atb":[[18.5,2]],"id":41762566},{"atb":[[32,4.72]],"id":42651625},{"atl":[[230,4.72]],"id":42651625},{"atb":[[14,2.11]],"id":41676292},{"atl":[[36,3.43]],"id":41676292}],"con":true,"img":false}]}
{"op":"mcm","clk":"5347895797","pt":1646209874708,"mc":[{"id":"1.195453611","rc":[{"atb":[[13.5,0]],"id":41676292}],"con":true,"img":false}]}
{"op":"mcm","clk":"5347895966","pt":1646209877915,"mc":[{"id":"1.195453611","rc":[{"atb":[[14.5,2.34]],"id":41676292}],"con":true,"img":false}]}
{"op":"mcm","clk":"5347896872","pt":1646209897605,"mc":[{"id":"1.195453611","rc":[{"atb":[[18,0]],"id":41762566}],"con":true,"img":false}]}
{"op":"mcm","clk":"5347896878","pt":1646209897709,"mc":[{"id":"1.195453611","rc":[{"atb":[[17.5,2],[18.5,0],[19,3.99]],"id":41762566}],"con":true,"img":false}]}
{"op":"mcm","clk":"5347896882","pt":1646209897811,"mc":[{"id":"1.195453611","rc":[{"atb":[[17.5,0],[19.5,2]],"id":41762566}],"con":true,"img":false}]}
{"op":"mcm","clk":"5347896891","pt":1646209898018,"mc":[{"id":"1.195453611","rc":[{"atb":[[10.5,0],[3.5,40]],"id":41762566},{"atl":[[260,0],[310,0],[320,2]],"id":41762566},{"atl":[[6.8,3.45],[7,0]],"id":43066529},{"atb":[[15,1.43],[7.2,16.13]],"id":42651625},{"atl":[[450,0],[500,1]],"id":42651625},{"atb":[[3.1,46.3],[5,0]],"id":41676292}],"con":true,"img":false}]}
{"op":"mcm","clk":"5347896895","pt":1646209898120,"mc":[{"id":"1.195453611","rc":[{"atb":[[13,8.34],[3.5,0]],"id":41762566},{"atb":[[7.2,0],[17,4.05]],"id":42651625},{"atb":[[4.8,26.32],[3.1,0]],"id":41676292}],"con":true,"img":false}]}
{"op":"mcm","clk":"5347897266","pt":1646209907427,"mc":[{"id":"1.195453611","rc":[{"spn":14.78,"spf":1.14,"id":41762566},{"atb":[[9.2,12.2]],"id":42651625},{"atl":[[320,2],[470,0]],"id":42651625},{"spn":18.81,"spf":1.0,"id":42651625},{"spn":10.76,"spf":1.0,"id":41676292},{"atl":[[3.55,3.42],[3.65,7.55]],"id":43167173}],"con":true,"img":false}]}
{"op":"mcm","clk":"5347897272","pt":1646209907589,"mc":[{"id":"1.195453611","rc":[{"atb":[[8.2,13.89],[13,4.17]],"id":41762566},{"atl":[[170,2],[220,1],[320,0]],"id":41762566},{"atl":[[6.8,0],[13.5,16],[5.1,4.88],[8.8,12.82]],"id":43066529},{"atb":[[17,0]],"id":42651625},{"atl":[[380,1],[420,0]],"id":42651625},{"atl":[[40,4.48],[55,0]],"id":41676292},{"atb":[[1.43,84.74],[1.72,0]],"id":43167172},{"atb":[[2.06,77.24],[1.9,111.11]],"id":43167173},{"atl":[[4.8,0],[4.1,32.26]],"id":43167173}],"con":true,"img":false}]}
{"op":"mcm","clk":"5347897291","pt":1646209908047,"mc":[{"id":"1.195453611","rc":[{"atl":[[5.6,26.69],[4.7,0]],"id":43167173}],"con":true,"img":false}]}
{"op":"mcm","clk":"5347897345","pt":1646209909125,"mc":[{"id":"1.195453611","rc":[{"atl":[[3.55,0]],"id":43167173}],"con":true,"img":false}]}
{"op":"mcm","clk":"5347897354","pt":1646209909434,"mc":[{"id":"1.195453611","rc":[{"atl":[[1000,0]],"id":41676292},{"atl":[[1000,0]],"id":43167173}],"con":true,"img":false}]}
{"op":"mcm","clk":"5347897357","pt":1646209909536,"mc":[{"id":"1.195453611","rc":[{"atl":[[34,1.31]],"id":41676292},{"atl":[[3.6,1.25]],"id":43167173}],"con":true,"img":false}]}
{"op":"mcm","clk":"5347897416","pt":1646209910873,"mc":[{"id":"1.195453611","rc":[{"atb":[[4.8,0],[7.4,15.32]],"id":41676292}],"con":true,"img":false}]}
{"op":"mcm","clk":"5347897647","pt":1646209917445,"mc":[{"id":"1.195453611","rc":[{"atl":[[240,1.83]],"id":41762566},{"atl":[[5.3,11.63]],"id":43066529},{"atl":[[400,1]],"id":42651625},{"atl":[[3.75,18.18]],"id":43167173}],"con":true,"img":false}]}
{"op":"mcm","clk":"5347897657","pt":1646209917648,"mc":[{"id":"1.195453611","rc":[{"atl":[[330,0],[350,0],[370,0]],"id":41762566},{"atl":[[8,0],[8.4,18.02],[7.6,0]],"id":43066529},{"atl":[[490,0],[510,0]],"id":42651625},{"atl":[[3.7,7.41],[3.65,0]],"id":43167173}],"con":true,"img":false}]}
{"op":"mcm","clk":"5347897662","pt":1646209917854,"mc":[{"id":"1.195453611","rc":[{"atl":[[3.6,0]],"id":43167173}],"con":true,"img":false}]}
{"op":"mcm","clk":"5347897669","pt":1646209917956,"mc":[{"id":"1.195453611","rc":[{"atl":[[3.65,1.25]],"id":43167173}],"con":true,"img":false}]}
{"op":"mcm","clk":"5347897748","pt":1646209920056,"mc":[{"id":"1.195453611","rc":[{"atb":[[19,0.65]],"id":41762566}],"con":true,"img":false}]}
{"op":"mcm","clk":"5347897756","pt":1646209920159,"mc":[{"id":"1.195453611","rc":[{"atb":[[17.5,2],[19.5,3.34]],"id":41762566},{"atb":[[9.2,0],[13.5,8]],"id":42651625},{"atl":[[320,0],[230,6.72]],"id":42651625}],"con":true,"img":false}]}
{"op":"mcm","clk":"5347897763","pt":1646209920267,"mc":[{"id":"1.195453611","rc":[{"atb":[[8.2,0],[12.5,6.82],[17.5,0]],"id":41762566},{"atl":[[7.6,15.15],[8.8,0]],"id":43066529},{"atb":[[1.43,0],[1.7,105.53]],"id":43167172},{"atb":[[2.22,81.96],[1.9,0]],"id":43167173}],"con":true,"img":false}]}
{"op":"mcm","clk":"5347897770","pt":1646209920467,"mc":[{"id":"1.195453611","rc":[{"atb":[[19.5,5.34]],"id":41762566}],"con":true,"img":false}]}
{"op":"mcm","clk":"5347897775","pt":1646209920569,"mc":[{"id":"1.195453611","rc":[{"atb":[[19.5,2]],"id":41762566}],"con":true,"img":false}]}
{"op":"mcm","clk":"5347897783","pt":1646209920673,"mc":[{"id":"1.195453611","rc":[{"atb":[[17.5,3.34]],"id":41762566}],"con":true,"img":false}]}
{"op":"mcm","clk":"5347897959","pt":1646209925257,"mc":[{"id":"1.195453611","rc":[{"atb":[[18,2],[19.5,0]],"id":41762566}],"con":true,"img":false}]}
{"op":"mcm","clk":"5347897966","pt":1646209925461,"mc":[{"id":"1.195453611","rc":[{"atl":[[38,5.42],[40,1.92]],"id":41676292}],"con":true,"img":false}]}
{"op":"mcm","clk":"5347898057","pt":1646209927471,"mc":[{"id":"1.195453611","rc":[{"atl":[[260,1]],"id":41762566},{"atl":[[5.5,16.67]],"id":43066529},{"atl":[[420,1]],"id":42651625}],"con":true,"img":false}]}
{"op":"mcm","clk":"5347898067","pt":1646209927678,"mc":[{"id":"1.195453611","rc":[{"atl":[[3.8,17.86]],"id":43167173}],"con":true,"img":false}]}
{"op":"mcm","clk":"5347898455","pt":1646209937462,"mc":[{"id":"1.195453611","rc":[{"atl":[[280,1]],"id":41762566},{"atl":[[5.7,26.6]],"id":43066529},{"atl":[[440,1]],"id":42651625}],"con":true,"img":false}]}
{"op":"mcm","clk":"5347898462","pt":1646209937666,"mc":[{"id":"1.195453611","rc":[{"atl":[[3.9,25.86]],"id":43167173}],"con":true,"img":false}]}
{"op":"mcm","clk":"5347898780","pt":1646209945108,"mc":[{"id":"1.195453611","rc":[{"atb":[[3.05,3.15]],"id":43167172}],"con":true,"img":false}]}
{"op":"mcm","clk":"5347898784","pt":1646209945208,"mc":[{"id":"1.195453611","rc":[{"atb":[[3.1,11.27]],"id":43167172}],"con":true,"img":false}]}
{"op":"mcm","clk":"5347898796","pt":1646209945518,"mc":[{"id":"1.195453611","rc":[{"atb":[[17.5,0]],"id":41762566},{"atl":[[4.5,0]],"id":43066529}],"con":true,"img":false}]}
{"op":"mcm","clk":"5347898802","pt":1646209945570,"mc":[{"id":"1.195453611","rc":[{"atb":[[18.5,3.34]],"id":41762566},{"atl":[[4.2,7.27]],"id":43066529}],"con":true,"img":false}]}
{"op":"mcm","clk":"5347898806","pt":1646209945672,"mc":[{"id":"1.195453611","rc":[{"atb":[[17.5,2],[18,0]],"id":41762566}],"con":true,"img":false}]}
{"op":"mcm","clk":"5347898810","pt":1646209945774,"mc":[{"id":"1.195453611","rc":[{"atb":[[17.5,0],[19,2.65]],"id":41762566}],"con":true,"img":false}]}
{"op":"mcm","clk":"5347898879","pt":1646209947523,"mc":[{"id":"1.195453611","rc":[{"atl":[[500,0]],"id":42651625}],"con":true,"img":false}]}
{"op":"mcm","clk":"5347898892","pt":1646209947680,"mc":[{"id":"1.195453611","rc":[{"atl":[[3.85,0],[3.75,0],[4,41.67]],"id":43167173}],"con":true,"img":false}]}
{"op":"mcm","clk":"5347899798","pt":1646209969545,"mc":[{"id":"1.195453611","rc":[{"atb":[[18.5,0]],"id":41762566},{"spn":14.08,"spf":1.14,"id":41762566},{"spn":18.5,"spf":1.0,"id":42651625},{"spn":2.85,"spf":1.0,"id":43167172}],"con":true,"img":false}]}
{"op":"mcm","clk":"5347899804","pt":1646209969598,"mc":[{"id":"1.195453611","rc":[{"atb":[[19.5,3.34]],"id":41762566}],"con":true,"img":false}]}
{"op":"mcm","clk":"5347899811","pt":1646209969751,"mc":[{"id":"1.195453611","rc":[{"atb":[[17.5,2],[19,0.65]],"id":41762566}],"con":true,"img":false}]}
{"op":"mcm","clk":"5347899858","pt":1646209971052,"mc":[{"id":"1.195453611","rc":[{"atl":[[7.4,0],[5.4,24.56]],"id":43066529}],"con":true,"img":false}]}
{"op":"mcm","clk":"5347899995","pt":1646209974817,"mc":[{"id":"1.195453611","rc":[{"atb":[[17.5,0],[20,2.28]],"id":41762566}],"con":true,"img":false}]}
{"op":"mcm","clk":"5347900072","pt":1646209976931,"mc":[{"id":"1.195453611","rc":[{"atl":[[230,4.72],[240,2.55]],"id":42651625},{"atl":[[38,2.72],[40,4.48]],"id":41676292},{"atl":[[3.75,7.27],[3.7,0]],"id":43167173}],"con":true,"img":false}]}
{"op":"mcm","clk":"5347900077","pt":1646209977034,"mc":[{"id":"1.195453611","rc":[{"atb":[[19.5,0]],"id":41762566}],"con":true,"img":false}]}
{"op":"mcm","clk":"5347900081","pt":1646209977137,"mc":[{"id":"1.195453611","rc":[{"atb":[[17.5,2],[18,3.34],[20,0.28]],"id":41762566}],"con":true,"img":false}]}
{"op":"mcm","clk":"5347900175","pt":1646209979256,"mc":[{"id":"1.195453611","rc":[{"atl":[[1000,0]],"id":42651625},{"atl":[[3.65,0]],"id":43167173}],"con":true,"img":false}]}
{"op":"mcm","clk":"5347900179","pt":1646209979313,"mc":[{"id":"1.195453611","rc":[{"atl":[[220,1.21]],"id":42651625},{"atl":[[3.7,1.25]],"id":43167173}],"con":true,"img":false}]}
{"op":"mcm","clk":"5347900318","pt":1646209982353,"mc":[{"id":"1.195453611","rc":[{"atb":[[17.5,0],[18.5,2]],"id":41762566}],"con":true,"img":false}]}
{"op":"mcm","clk":"5347900365","pt":1646209983132,"mc":[{"id":"1.195453611","rc":[{"atl":[[170,0],[120,2]],"id":41762566}],"con":true,"img":false}]}
{"op":"mcm","clk":"5347900553","pt":1646209986948,"mc":[{"id":"1.195453611","rc":[{"atl":[[3.85,17.54]],"id":43167173}],"con":true,"img":false}]}
{"op":"mcm","clk":"5347900677","pt":1646209988962,"mc":[{"id":"1.195453611","rc":[{"atl":[[220,3.21],[240,0.55]],"id":42651625},{"atl":[[38,5.42],[40,1.92]],"id":41676292}],"con":true,"img":false}]}
{"op":"mcm","clk":"5347900687","pt":1646209989168,"mc":[{"id":"1.195453611","rc":[{"atl":[[210,2],[230,2.72]],"id":42651625}],"con":true,"img":false}]}
{"op":"mcm","clk":"5347900705","pt":1646209989442,"mc":[{"id":"1.195453611","rc":[{"atl":[[220,2]],"id":42651625}],"con":true,"img":false}]}
{"op":"mcm","clk":"5347900709","pt":1646209989539,"mc":[{"id":"1.195453611","rc":[{"atl":[[210,3.21]],"id":42651625}],"con":true,"img":false}]}
{"op":"mcm","clk":"5347901023","pt":1646209996962,"mc":[{"id":"1.195453611","rc":[{"atl":[[3.8,0],[4,0],[3.95,25.42],[3.9,0]],"id":43167173}],"con":true,"img":false}]}
{"op":"mcm","clk":"5347901395","pt":1646210006092,"mc":[{"id":"1.195453611","rc":[{"atb":[[18,0]],"id":41762566}],"con":true,"img":false}]}
{"op":"mcm","clk":"5347901400","pt":1646210006195,"mc":[{"id":"1.195453611","rc":[{"atb":[[19,3.99]],"id":41762566}],"con":true,"img":false}]}
{"op":"mcm","clk":"5347901404","pt":1646210006250,"mc":[{"id":"1.195453611","rc":[{"atb":[[17.5,2],[18.5,0]],"id":41762566}],"con":true,"img":false}]}
{"op":"mcm","clk":"5347901409","pt":1646210006401,"mc":[{"id":"1.195453611","rc":[{"atb":[[17.5,0]],"id":41762566}],"con":true,"img":false}]}
{"op":"mcm","clk":"5347901415","pt":1646210006458,"mc":[{"id":"1.195453611","rc":[{"atb":[[19.5,2]],"id":41762566}],"con":true,"img":false}]}
{"op":"mcm","clk":"5347901422","pt":1646210006561,"mc":[{"id":"1.195453611","rc":[{"atb":[[19,0.65]],"id":41762566}],"con":true,"img":false}]}
{"op":"mcm","clk":"5347901428","pt":1646210006660,"mc":[{"id":"1.195453611","rc":[{"atb":[[17.5,3.34]],"id":41762566}],"con":true,"img":false}]}
{"op":"mcm","clk":"5347901440","pt":1646210006969,"mc":[{"id":"1.195453611","rc":[{"atl":[[4.1,72.58]],"id":43167173}],"con":true,"img":false}]}
{"op":"mcm","clk":"5347901634","pt":1646210011587,"mc":[{"id":"1.195453611","rc":[{"atb":[[18,2]],"id":41762566}],"con":true,"img":false}]}
{"op":"mcm","clk":"5347901637","pt":1646210011690,"mc":[{"id":"1.195453611","rc":[{"atb":[[19.5,0]],"id":41762566}],"con":true,"img":false}]}
{"op":"mcm","clk":"5347901844","pt":1646210017093,"mc":[{"id":"1.195453611","rc":[{"atl":[[4.2,0]],"id":43066529}],"con":true,"img":false}]}
{"op":"mcm","clk":"5347901847","pt":1646210017196,"mc":[{"id":"1.195453611","rc":[{"atl":[[5,7.27]],"id":43066529}],"con":true,"img":false}]}
{"op":"mcm","clk":"5347901877","pt":1646210017970,"mc":[{"id":"1.195453611","rc":[{"atb":[[2.6,9.48]],"id":43167173}],"con":true,"img":false}]}
{"op":"mcm","clk":"5347901897","pt":1646210018587,"mc":[{"id":"1.195453611","rc":[{"atb":[[2.38,1.6]],"id":43167173}],"con":true,"img":false}]}
{"op":"mcm","clk":"5347901904","pt":1646210018691,"mc":[{"id":"1.195453611","rc":[{"atb":[[2.62,2.97]],"id":43167173}],"con":true,"img":false}]}
{"op":"mcm","clk":"5347901929","pt":1646210019102,"mc":[{"id":"1.195453611","rc":[{"atl":[[230,0]],"id":42651625}],"con":true,"img":false}]}
{"op":"mcm","clk":"5347901934","pt":1646210019204,"mc":[{"id":"1.195453611","rc":[{"atl":[[200,2.72]],"id":42651625}],"con":true,"img":false}]}
{"op":"mcm","clk":"5347901951","pt":1646210019643,"mc":[{"id":"1.195453611","rc":[{"atl":[[210,2]],"id":42651625}],"con":true,"img":false}]}
{"op":"mcm","clk":"5347901956","pt":1646210019717,"mc":[{"id":"1.195453611","rc":[{"atl":[[190,1.21]],"id":42651625}],"con":true,"img":false}]}
{"op":"mcm","clk":"5347901965","pt":1646210019873,"mc":[{"id":"1.195453611","rc":[{"atl":[[190,3.21],[210,0]],"id":42651625}],"con":true,"img":false}]}
{"op":"mcm","clk":"5347901971","pt":1646210020079,"mc":[{"id":"1.195453611","rc":[{"atl":[[190,1.21]],"id":42651625}],"con":true,"img":false}]}
{"op":"mcm","clk":"5347901980","pt":1646210020285,"mc":[{"id":"1.195453611","rc":[{"atl":[[200,4.72]],"id":42651625}],"con":true,"img":false}]}
{"op":"mcm","clk":"5347902051","pt":1646210022088,"mc":[{"id":"1.195453611","rc":[{"atb":[[2.6,0]],"id":43167173}],"con":true,"img":false}]}
{"op":"mcm","clk":"5347902081","pt":1646210022911,"mc":[{"id":"1.195453611","rc":[{"atb":[[2.62,1.66]],"id":43167173}],"con":true,"img":false}]}
{"op":"mcm","clk":"5347902087","pt":1646210023013,"mc":[{"id":"1.195453611","rc":[{"atb":[[2.38,2.91]],"id":43167173}],"con":true,"img":false}]}
{"op":"mcm","clk":"5347902203","pt":1646210026108,"mc":[{"id":"1.195453611","rc":[{"atb":[[2.6,9.48]],"id":43167173}],"con":true,"img":false}]}
{"op":"mcm","clk":"5347902213","pt":1646210026408,"mc":[{"id":"1.195453611","rc":[{"atb":[[2.38,1.6]],"id":43167173}],"con":true,"img":false}]}
{"op":"mcm","clk":"5347902217","pt":1646210026509,"mc":[{"id":"1.195453611","rc":[{"atb":[[2.62,2.97]],"id":43167173}],"con":true,"img":false}]}
{"op":"mcm","clk":"5347902338","pt":1646210030131,"mc":[{"id":"1.195453611","rc":[{"spn":14.58,"spf":1.14,"id":41762566},{"atb":[[2.6,0]],"id":43167173},{"spn":2.39,"spf":1.0,"id":43167173}],"con":true,"img":false}]}
{"op":"mcm","clk":"5347902354","pt":1646210030693,"mc":[{"id":"1.195453611","rc":[{"atb":[[2.62,1.66]],"id":43167173}],"con":true,"img":false}]}
{"op":"mcm","clk":"5347902358","pt":1646210030795,"mc":[{"id":"1.195453611","rc":[{"atb":[[2.38,2.91]],"id":43167173}],"con":true,"img":false}]}
{"op":"mcm","clk":"5347902407","pt":1646210032035,"mc":[{"id":"1.195453611","rc":[{"atb":[[17.5,0]],"id":41762566}],"con":true,"img":false}]}
{"op":"mcm","clk":"5347902410","pt":1646210032139,"mc":[{"id":"1.195453611","rc":[{"atb":[[18.5,3.34]],"id":41762566}],"con":true,"img":false}]}
{"op":"mcm","clk":"5347902415","pt":1646210032243,"mc":[{"id":"1.195453611","rc":[{"atb":[[17.5,2],[18,0]],"id":41762566}],"con":true,"img":false}]}
{"op":"mcm","clk":"5347902420","pt":1646210032300,"mc":[{"id":"1.195453611","rc":[{"atb":[[17.5,0],[19,2.65]],"id":41762566},{"atb":[[2.64,8.22]],"id":43167173}],"con":true,"img":false}]}
{"op":"mcm","clk":"5347902448","pt":1646210033014,"mc":[{"id":"1.195453611","rc":[{"atb":[[2.38,1.6]],"id":43167173}],"con":true,"img":false}]}
{"op":"mcm","clk":"5347902452","pt":1646210033117,"mc":[{"id":"1.195453611","rc":[{"atb":[[2.66,1.31]],"id":43167173}],"con":true,"img":false}]}
{"op":"mcm","clk":"5347902571","pt":1646210037034,"mc":[{"id":"1.195453611","rc":[{"atl":[[5,0]],"id":43066529}],"con":true,"img":false}]}
{"op":"mcm","clk":"5347902576","pt":1646210037136,"mc":[{"id":"1.195453611","rc":[{"atl":[[4.2,7.27]],"id":43066529}],"con":true,"img":false}]}
{"op":"mcm","clk":"5347902583","pt":1646210037343,"mc":[{"id":"1.195453611","rc":[{"atl":[[3.8,7.14],[3.75,0]],"id":43167173}],"con":true,"img":false}]}
{"op":"mcm","clk":"5347902596","pt":1646210037652,"mc":[{"id":"1.195453611","rc":[{"atl":[[3.7,0]],"id":43167173}],"con":true,"img":false}]}
{"op":"mcm","clk":"5347902603","pt":1646210037755,"mc":[{"id":"1.195453611","rc":[{"atl":[[3.75,1.25]],"id":43167173}],"con":true,"img":false}]}
{"op":"mcm","clk":"5347902607","pt":1646210037807,"mc":[{"id":"1.195453611","rc":[{"atl":[[4.1,40.32],[4.2,31.25]],"id":43167173}],"con":true,"img":false}]}
{"op":"mcm","clk":"5347902733","pt":1646210040712,"mc":[{"id":"1.195453611","rc":[{"atb":[[2.64,0]],"id":43167173}],"con":true,"img":false}]}
{"op":"mcm","clk":"5347902773","pt":1646210041430,"mc":[{"id":"1.195453611","rc":[{"atb":[[2.66,0]],"id":43167173}],"con":true,"img":false}]}
{"op":"mcm","clk":"5347902780","pt":1646210041534,"mc":[{"id":"1.195453611","rc":[{"atb":[[2.38,2.91]],"id":43167173}],"con":true,"img":false}]}
{"op":"mcm","clk":"5347902899","pt":1646210044527,"mc":[{"id":"1.195453611","rc":[{"atb":[[2.6,9.48]],"id":43167173}],"con":true,"img":false}]}
{"op":"mcm","clk":"5347902920","pt":1646210045038,"mc":[{"id":"1.195453611","rc":[{"atb":[[2.38,1.6]],"id":43167173}],"con":true,"img":false}]}
{"op":"mcm","clk":"5347902923","pt":1646210045142,"mc":[{"id":"1.195453611","rc":[{"atb":[[2.62,2.97]],"id":43167173}],"con":true,"img":false}]}
{"op":"mcm","clk":"5347903029","pt":1646210047356,"mc":[{"id":"1.195453611","rc":[{"atl":[[3.9,17.24]],"id":43167173}],"con":true,"img":false}]}
{"op":"mcm","clk":"5347903057","pt":1646210048024,"mc":[{"id":"1.195453611","rc":[{"atb":[[2.6,0]],"id":43167173}],"con":true,"img":false}]}
{"op":"mcm","clk":"5347903086","pt":1646210048743,"mc":[{"id":"1.195453611","rc":[{"atb":[[2.62,1.66]],"id":43167173}],"con":true,"img":false}]}
{"op":"mcm","clk":"5347903092","pt":1646210048845,"mc":[{"id":"1.195453611","rc":[{"atb":[[2.38,2.91]],"id":43167173}],"con":true,"img":false}]}
{"op":"mcm","clk":"5347903262","pt":1646210052348,"mc":[{"id":"1.195453611","rc":[{"atb":[[2.6,9.48]],"id":43167173}],"con":true,"img":false}]}
{"op":"mcm","clk":"5347903328","pt":1646210053838,"mc":[{"id":"1.195453611","rc":[{"atb":[[2.38,1.6]],"id":43167173}],"con":true,"img":false}]}
{"op":"mcm","clk":"5347903332","pt":1646210053940,"mc":[{"id":"1.195453611","rc":[{"atb":[[2.62,2.97]],"id":43167173}],"con":true,"img":false}]}
{"op":"mcm","clk":"5347903397","pt":1646210055533,"mc":[{"id":"1.195453611","rc":[{"atb":[[18.5,0]],"id":41762566}],"con":true,"img":false}]}
{"op":"mcm","clk":"5347903403","pt":1646210055642,"mc":[{"id":"1.195453611","rc":[{"atb":[[17.5,2],[19,0.65],[19.5,3.34]],"id":41762566}],"con":true,"img":false}]}
{"op":"mcm","clk":"5347903408","pt":1646210055738,"mc":[{"id":"1.195453611","rc":[{"atb":[[20,2.28]],"id":41762566}],"con":true,"img":false}]}
{"op":"mcm","clk":"5347903413","pt":1646210055849,"mc":[{"id":"1.195453611","rc":[{"atb":[[17.5,0]],"id":41762566}],"con":true,"img":false}]}
{"op":"mcm","clk":"5347903433","pt":1646210056356,"mc":[{"id":"1.195453611","rc":[{"atb":[[2.6,0]],"id":43167173}],"con":true,"img":false}]}
{"op":"mcm","clk":"5347903473","pt":1646210057387,"mc":[{"id":"1.195453611","rc":[{"atl":[[3.85,0],[4,25],[3.95,0],[4.1,0]],"id":43167173}],"con":true,"img":false}]}
{"op":"mcm","clk":"5347903480","pt":1646210057449,"mc":[{"id":"1.195453611","rc":[{"atb":[[2.62,1.66]],"id":43167173}],"con":true,"img":false}]}
{"op":"mcm","clk":"5347903488","pt":1646210057543,"mc":[{"id":"1.195453611","rc":[{"atb":[[2.38,2.91]],"id":43167173},{"atl":[[4.3,0]],"id":43167173}],"con":true,"img":false}]}
{"op":"mcm","clk":"5347903494","pt":1646210057647,"mc":[{"id":"1.195453611","rc":[{"atl":[[4.1,19.84]],"id":43167173}],"con":true,"img":false}]}
{"op":"mcm","clk":"5347903579","pt":1646210059550,"mc":[{"id":"1.195453611","rc":[{"atl":[[200,2]],"id":42651625}],"con":true,"img":false}]}
{"op":"mcm","clk":"5347903583","pt":1646210059653,"mc":[{"id":"1.195453611","rc":[{"atl":[[180,3.12]],"id":42651625}],"con":true,"img":false}]}
{"op":"mcm","clk":"5347903587","pt":1646210059756,"mc":[{"id":"1.195453611","rc":[{"atl":[[170,2]],"id":42651625}],"con":true,"img":false}]}
{"op":"mcm","clk":"5347903591","pt":1646210059859,"mc":[{"id":"1.195453611","rc":[{"atl":[[200,0]],"id":42651625},{"atb":[[2.6,9.48]],"id":43167173}],"con":true,"img":false}]}
{"op":"mcm","clk":"5347903602","pt":1646210060167,"mc":[{"id":"1.195453611","rc":[{"atb":[[2.38,1.6]],"id":43167173}],"con":true,"img":false}]}
{"op":"mcm","clk":"5347903608","pt":1646210060270,"mc":[{"id":"1.195453611","rc":[{"atb":[[2.62,2.97]],"id":43167173}],"con":true,"img":false}]}
{"op":"mcm","clk":"5347903685","pt":1646210062276,"mc":[{"id":"1.195453611","rc":[{"atl":[[190,0]],"id":42651625}],"con":true,"img":false}]}
{"op":"mcm","clk":"5347903689","pt":1646210062378,"mc":[{"id":"1.195453611","rc":[{"atl":[[170,3.21]],"id":42651625}],"con":true,"img":false}]}
{"op":"mcm","clk":"5347903695","pt":1646210062584,"mc":[{"id":"1.195453611","rc":[{"atl":[[180,0.39]],"id":42651625}],"con":true,"img":false}]}
{"op":"mcm","clk":"5347903701","pt":1646210062640,"mc":[{"id":"1.195453611","rc":[{"atl":[[210,2.72]],"id":42651625}],"con":true,"img":false}]}
{"op":"mcm","clk":"5347903708","pt":1646210062790,"mc":[{"id":"1.195453611","rc":[{"atl":[[170,2]],"id":42651625}],"con":true,"img":false}]}
{"op":"mcm","clk":"5347903714","pt":1646210062843,"mc":[{"id":"1.195453611","rc":[{"atl":[[1000,1.21]],"id":42651625}],"con":true,"img":false}]}
{"op":"mcm","clk":"5347903719","pt":1646210062943,"mc":[{"id":"1.195453611","rc":[{"atl":[[170,0],[210,4.72]],"id":42651625}],"con":true,"img":false}]}
{"op":"mcm","clk":"5347903741","pt":1646210063357,"mc":[{"id":"1.195453611","rc":[{"atl":[[1000,0]],"id":42651625}],"con":true,"img":false}]}
{"op":"mcm","clk":"5347903744","pt":1646210063460,"mc":[{"id":"1.195453611","rc":[{"atl":[[200,1.21]],"id":42651625}],"con":true,"img":false}]}
{"op":"mcm","clk":"5347903762","pt":1646210063971,"mc":[{"id":"1.195453611","rc":[{"atb":[[2.6,0]],"id":43167173}],"con":true,"img":false}]}
{"op":"mcm","clk":"5347903775","pt":1646210064382,"mc":[{"id":"1.195453611","rc":[{"atb":[[2.62,1.66]],"id":43167173}],"con":true,"img":false}]}
{"op":"mcm","clk":"5347903780","pt":1646210064486,"mc":[{"id":"1.195453611","rc":[{"atb":[[2.38,2.91]],"id":43167173}],"con":true,"img":false}]}
{"op":"mcm","clk":"5347903884","pt":1646210067366,"mc":[{"id":"1.195453611","rc":[{"atl":[[4.2,70.31]],"id":43167173}],"con":true,"img":false}]}
{"op":"mcm","clk":"5347903902","pt":1646210067776,"mc":[{"id":"1.195453611","rc":[{"atb":[[2.6,9.48]],"id":43167173}],"con":true,"img":false}]}
{"op":"mcm","clk":"5347903940","pt":1646210068869,"mc":[{"id":"1.195453611","rc":[{"atb":[[2.38,1.6]],"id":43167173}],"con":true,"img":false}]}
{"op":"mcm","clk":"5347903942","pt":1646210068974,"mc":[{"id":"1.195453611","rc":[{"atb":[[2.62,2.97]],"id":43167173}],"con":true,"img":false}]}
{"op":"mcm","clk":"5347904035","pt":1646210071498,"mc":[{"id":"1.195453611","rc":[{"atb":[[2.6,0]],"id":43167173}],"con":true,"img":false}]}
{"op":"mcm","clk":"5347904061","pt":1646210072266,"mc":[{"id":"1.195453611","rc":[{"atb":[[2.62,1.66]],"id":43167173}],"con":true,"img":false}]}
{"op":"mcm","clk":"5347904068","pt":1646210072371,"mc":[{"id":"1.195453611","rc":[{"atb":[[2.38,2.91]],"id":43167173}],"con":true,"img":false}]}
{"op":"mcm","clk":"5347904174","pt":1646210075192,"mc":[{"id":"1.195453611","rc":[{"atb":[[2.6,9.48]],"id":43167173}],"con":true,"img":false}]}
{"op":"mcm","clk":"5347904198","pt":1646210075872,"mc":[{"id":"1.195453611","rc":[{"atb":[[2.38,1.6]],"id":43167173}],"con":true,"img":false}]}
{"op":"mcm","clk":"5347904202","pt":1646210075965,"mc":[{"id":"1.195453611","rc":[{"atb":[[2.62,2.97]],"id":43167173}],"con":true,"img":false}]}
{"op":"mcm","clk":"5347904260","pt":1646210077608,"mc":[{"id":"1.195453611","rc":[{"atl":[[5,6.76],[4.2,0]],"id":43066529}],"con":true,"img":false}]}
{"op":"mcm","clk":"5347904304","pt":1646210078892,"mc":[{"id":"1.195453611","rc":[{"atb":[[2.6,0]],"id":43167173}],"con":true,"img":false}]}
{"op":"mcm","clk":"5347904326","pt":1646210079505,"mc":[{"id":"1.195453611","rc":[{"atb":[[2.62,1.66]],"id":43167173}],"con":true,"img":false}]}
{"op":"mcm","clk":"5347904334","pt":1646210079607,"mc":[{"id":"1.195453611","rc":[{"atb":[[2.38,2.91]],"id":43167173}],"con":true,"img":false}]}
{"op":"mcm","clk":"5347904446","pt":1646210083172,"mc":[{"id":"1.195453611","rc":[{"atb":[[2.6,9.48]],"id":43167173}],"con":true,"img":false}]}
{"op":"mcm","clk":"5347904462","pt":1646210083688,"mc":[{"id":"1.195453611","rc":[{"atb":[[2.38,1.6]],"id":43167173}],"con":true,"img":false}]}
{"op":"mcm","clk":"5347904467","pt":1646210083792,"mc":[{"id":"1.195453611","rc":[{"atb":[[2.62,2.97]],"id":43167173}],"con":true,"img":false}]}
{"op":"mcm","clk":"5347904598","pt":1646210087389,"mc":[{"id":"1.195453611","rc":[{"atb":[[2.6,0]],"id":43167173}],"con":true,"img":false}]}
{"op":"mcm","clk":"5347904617","pt":1646210087902,"mc":[{"id":"1.195453611","rc":[{"atb":[[2.62,1.66]],"id":43167173}],"con":true,"img":false}]}
{"op":"mcm","clk":"5347904620","pt":1646210088003,"mc":[{"id":"1.195453611","rc":[{"atb":[[2.38,2.91]],"id":43167173}],"con":true,"img":false}]}
{"op":"mcm","clk":"5347904759","pt":1646210092112,"mc":[{"id":"1.195453611","rc":[{"spn":14.87,"spf":1.14,"id":41762566},{"atb":[[2.6,9.48]],"id":43167173},{"spn":2.46,"spf":1.0,"id":43167173}],"con":true,"img":false}]}
{"op":"mcm","clk":"5347904775","pt":1646210092722,"mc":[{"id":"1.195453611","rc":[{"atb":[[2.38,1.6]],"id":43167173}],"con":true,"img":false}]}
{"op":"mcm","clk":"5347904779","pt":1646210092823,"mc":[{"id":"1.195453611","rc":[{"atb":[[2.62,2.97]],"id":43167173}],"con":true,"img":false}]}
{"op":"mcm","clk":"5347904856","pt":1646210095500,"mc":[{"id":"1.195453611","rc":[{"atl":[[5,0]],"id":43066529}],"con":true,"img":false}]}
{"op":"mcm","clk":"5347904860","pt":1646210095601,"mc":[{"id":"1.195453611","rc":[{"atl":[[4.9,6.76]],"id":43066529}],"con":true,"img":false}]}
{"op":"mcm","clk":"5347904877","pt":1646210096118,"mc":[{"id":"1.195453611","rc":[{"atb":[[2.6,0]],"id":43167173}],"con":true,"img":false}]}
{"op":"mcm","clk":"5347904894","pt":1646210096931,"mc":[{"id":"1.195453611","rc":[{"atb":[[2.62,1.66]],"id":43167173}],"con":true,"img":false}]}
{"op":"mcm","clk":"5347904902","pt":1646210097033,"mc":[{"id":"1.195453611","rc":[{"atb":[[2.38,2.91]],"id":43167173}],"con":true,"img":false}]}
{"op":"mcm","clk":"5347905019","pt":1646210100319,"mc":[{"id":"1.195453611","rc":[{"atb":[[2.6,9.48]],"id":43167173}],"con":true,"img":false}]}
{"op":"mcm","clk":"5347905068","pt":1646210101508,"mc":[{"id":"1.195453611","rc":[{"atb":[[2.38,1.6]],"id":43167173}],"con":true,"img":false}]}
{"op":"mcm","clk":"5347905072","pt":1646210101600,"mc":[{"id":"1.195453611","rc":[{"atb":[[2.62,2.97]],"id":43167173}],"con":true,"img":false}]}
{"op":"mcm","clk":"5347905142","pt":1646210103502,"mc":[{"id":"1.195453611","rc":[{"atl":[[210,2]],"id":42651625}],"con":true,"img":false}]}
{"op":"mcm","clk":"5347905149","pt":1646210103607,"mc":[{"id":"1.195453611","rc":[{"atl":[[190,2.72]],"id":42651625}],"con":true,"img":false}]}
{"op":"mcm","clk":"5347905153","pt":1646210103714,"mc":[{"id":"1.195453611","rc":[{"atl":[[190,4.72],[200,0]],"id":42651625}],"con":true,"img":false}]}
{"op":"mcm","clk":"5347905160","pt":1646210103810,"mc":[{"id":"1.195453611","rc":[{"atl":[[210,0],[1000,1.21]],"id":42651625}],"con":true,"img":false}]}
{"op":"mcm","clk":"5347905183","pt":1646210104427,"mc":[{"id":"1.195453611","rc":[{"atl":[[1000,0]],"id":42651625}],"con":true,"img":false}]}
{"op":"mcm","clk":"5347905186","pt":1646210104529,"mc":[{"id":"1.195453611","rc":[{"atl":[[180,1.6]],"id":42651625},{"atb":[[2.6,0]],"id":43167173}],"con":true,"img":false}]}
{"op":"mcm","clk":"5347905202","pt":1646210105038,"mc":[{"id":"1.195453611","rc":[{"atb":[[2.62,1.66]],"id":43167173}],"con":true,"img":false}]}
{"op":"mcm","clk":"5347905204","pt":1646210105093,"mc":[{"id":"1.195453611","rc":[{"atb":[[2.38,2.91]],"id":43167173}],"con":true,"img":false}]}
{"op":"mcm","clk":"5347905315","pt":1646210108842,"mc":[{"id":"1.195453611","rc":[{"atb":[[2.6,9.48]],"id":43167173}],"con":true,"img":false}]}
{"op":"mcm","clk":"5347905341","pt":1646210109517,"mc":[{"id":"1.195453611","rc":[{"atb":[[2.38,1.6]],"id":43167173}],"con":true,"img":false}]}
{"op":"mcm","clk":"5347905343","pt":1646210109620,"mc":[{"id":"1.195453611","rc":[{"atb":[[2.62,2.97]],"id":43167173}],"con":true,"img":false}]}
{"op":"mcm","clk":"5347905456","pt":1646210112708,"mc":[{"id":"1.195453611","rc":[{"atb":[[2.6,0]],"id":43167173}],"con":true,"img":false}]}
{"op":"mcm","clk":"5347905471","pt":1646210113226,"mc":[{"id":"1.195453611","rc":[{"atb":[[2.62,1.66]],"id":43167173}],"con":true,"img":false}]}
{"op":"mcm","clk":"5347905475","pt":1646210113326,"mc":[{"id":"1.195453611","rc":[{"atb":[[2.38,2.91]],"id":43167173}],"con":true,"img":false}]}
{"op":"mcm","clk":"5347905490","pt":1646210114041,"mc":[{"id":"1.195453611","rc":[{"atl":[[4.9,0]],"id":43066529}],"con":true,"img":false}]}
{"op":"mcm","clk":"5347905496","pt":1646210114146,"mc":[{"id":"1.195453611","rc":[{"atl":[[4.8,6.76]],"id":43066529}],"con":true,"img":false}]}
{"op":"mcm","clk":"5347905603","pt":1646210117232,"mc":[{"id":"1.195453611","rc":[{"atb":[[2.6,9.48]],"id":43167173}],"con":true,"img":false}]}
{"op":"mcm","clk":"5347905632","pt":1646210118006,"mc":[{"id":"1.195453611","rc":[{"atb":[[2.38,1.6]],"id":43167173}],"con":true,"img":false}]}
{"op":"mcm","clk":"5347905636","pt":1646210118108,"mc":[{"id":"1.195453611","rc":[{"atb":[[2.62,2.97]],"id":43167173}],"con":true,"img":false}]}
{"op":"mcm","clk":"5347905733","pt":1646210121239,"mc":[{"id":"1.195453611","rc":[{"atb":[[2.6,0]],"id":43167173}],"con":true,"img":false}]}
{"op":"mcm","clk":"5347905767","pt":1646210122527,"mc":[{"id":"1.195453611","rc":[{"atb":[[2.62,1.66]],"id":43167173}],"con":true,"img":false}]}
{"op":"mcm","clk":"5347905771","pt":1646210122624,"mc":[{"id":"1.195453611","rc":[{"atb":[[2.38,2.91]],"id":43167173}],"con":true,"img":false}]}
{"op":"mcm","clk":"5347905863","pt":1646210125560,"mc":[{"id":"1.195453611","rc":[{"atb":[[2.6,9.48]],"id":43167173}],"con":true,"img":false}]}
{"op":"mcm","clk":"5347905877","pt":1646210125868,"mc":[{"id":"1.195453611","rc":[{"atb":[[2.38,1.6]],"id":43167173}],"con":true,"img":false}]}
{"op":"mcm","clk":"5347905882","pt":1646210125967,"mc":[{"id":"1.195453611","rc":[{"atb":[[2.62,2.97]],"id":43167173}],"con":true,"img":false}]}
{"op":"mcm","clk":"5347906009","pt":1646210129969,"mc":[{"id":"1.195453611","rc":[{"atb":[[2.6,0]],"id":43167173}],"con":true,"img":false}]}
{"op":"mcm","clk":"5347906043","pt":1646210130641,"mc":[{"id":"1.195453611","rc":[{"atb":[[2.62,1.66]],"id":43167173}],"con":true,"img":false}]}
{"op":"mcm","clk":"5347906048","pt":1646210130746,"mc":[{"id":"1.195453611","rc":[{"atb":[[2.38,2.91]],"id":43167173}],"con":true,"img":false}]}
{"op":"mcm","clk":"5347906113","pt":1646210132543,"mc":[{"id":"1.195453611","rc":[{"atl":[[4.8,0]],"id":43066529}],"con":true,"img":false}]}
{"op":"mcm","clk":"5347906118","pt":1646210132645,"mc":[{"id":"1.195453611","rc":[{"atl":[[4.7,6.76]],"id":43066529}],"con":true,"img":false}]}
{"op":"mcm","clk":"5347906178","pt":1646210133930,"mc":[{"id":"1.195453611","rc":[{"atb":[[2.6,9.48]],"id":43167173}],"con":true,"img":false}]}
{"op":"mcm","clk":"5347906201","pt":1646210134548,"mc":[{"id":"1.195453611","rc":[{"atb":[[2.38,1.6]],"id":43167173}],"con":true,"img":false}]}
{"op":"mcm","clk":"5347906205","pt":1646210134650,"mc":[{"id":"1.195453611","rc":[{"atb":[[2.62,2.97]],"id":43167173}],"con":true,"img":false}]}
{"op":"mcm","clk":"5347906333","pt":1646210138252,"mc":[{"id":"1.195453611","rc":[{"atb":[[2.6,0]],"id":43167173}],"con":true,"img":false}]}
{"op":"mcm","clk":"5347906362","pt":1646210139279,"mc":[{"id":"1.195453611","rc":[{"atb":[[2.62,1.66]],"id":43167173}],"con":true,"img":false}]}
{"op":"mcm","clk":"5347906364","pt":1646210139377,"mc":[{"id":"1.195453611","rc":[{"atb":[[2.38,2.91]],"id":43167173}],"con":true,"img":false}]}
{"op":"mcm","clk":"5347906383","pt":1646210139750,"mc":[{"id":"1.195453611","rc":[{"atb":[[12.5,0]],"id":41762566},{"atb":[[10.5,27.76],[13.5,0]],"id":42651625},{"atl":[[180,3.6],[220,0]],"id":42651625},{"atl":[[36,6.29],[38,2.72]],"id":41676292},{"atl":[[3.8,0],[3.9,6.9]],"id":43167173}],"con":true,"img":false}]}
{"op":"mcm","clk":"5347906387","pt":1646210139842,"mc":[{"id":"1.195453611","rc":[{"atb":[[10.5,9.52]],"id":41762566},{"atl":[[170,2]],"id":42651625}],"con":true,"img":false}]}
{"op":"mcm","clk":"5347906392","pt":1646210139946,"mc":[{"id":"1.195453611","rc":[{"atl":[[190,2.72]],"id":42651625}],"con":true,"img":false}]}
{"op":"mcm","clk":"5347906397","pt":1646210140048,"mc":[{"id":"1.195453611","rc":[{"atl":[[180,2.39]],"id":42651625},{"atl":[[3.75,0]],"id":43167173}],"con":true,"img":false}]}
{"op":"mcm","clk":"5347906403","pt":1646210140156,"mc":[{"id":"1.195453611","rc":[{"atl":[[170,3.21]],"id":42651625},{"atl":[[3.85,1.25],[4.4,29.41],[4.2,39.06]],"id":43167173}],"con":true,"img":false}]}
{"op":"mcm","clk":"5347906421","pt":1646210140567,"mc":[{"id":"1.195453611","rc":[{"atl":[[190,0]],"id":42651625}],"con":true,"img":false}]}
{"op":"mcm","clk":"5347906425","pt":1646210140671,"mc":[{"id":"1.195453611","rc":[{"atl":[[230,2.72]],"id":42651625}],"con":true,"img":false}]}
{"op":"mcm","clk":"5347906459","pt":1646210141347,"mc":[{"id":"1.195453611","rc":[{"atl":[[170,2]],"id":42651625}],"con":true,"img":false}]}
{"op":"mcm","clk":"5347906469","pt":1646210141444,"mc":[{"id":"1.195453611","rc":[{"atl":[[1000,1.21]],"id":42651625}],"con":true,"img":false}]}
{"op":"mcm","clk":"5347906501","pt":1646210142579,"mc":[{"id":"1.195453611","rc":[{"atb":[[2.6,9.48]],"id":43167173}],"con":true,"img":false}]}
{"op":"mcm","clk":"5347906554","pt":1646210143864,"mc":[{"id":"1.195453611","rc":[{"atb":[[2.38,1.6]],"id":43167173}],"con":true,"img":false}]}
{"op":"mcm","clk":"5347906556","pt":1646210143967,"mc":[{"id":"1.195453611","rc":[{"atb":[[2.62,2.97]],"id":43167173}],"con":true,"img":false}]}
{"op":"mcm","clk":"5347906566","pt":1646210144384,"mc":[{"id":"1.195453611","rc":[{"atl":[[220,0],[230,1]],"id":41762566},{"atb":[[1.62,124.98],[1.53,0],[1.72,27.31],[1.63,0],[1.66,29.79]],"id":43066529},{"atb":[[10.5,17.23],[12,0],[13,6.82],[14,0],[15,0],[7.2,3.23]],"id":42651625},{"atb":[[9.4,2.38],[9.8,12.37]],"id":41676292},{"atl":[[10.5,2.11],[9.8,11.36]],"id":43167172}],"con":true,"img":false}]}
{"op":"mcm","clk":"5347906570","pt":1646210144436,"mc":[{"id":"1.195453611","rc":[{"atb":[[7.2,19.36]],"id":42651625}],"con":true,"img":false}]}
{"op":"mcm","clk":"5347906571","pt":1646210144539,"mc":[{"id":"1.195453611","rc":[{"atb":[[1.72,0]],"id":43066529}],"con":true,"img":false}]}
{"op":"mcm","clk":"5347906578","pt":1646210144850,"mc":[{"id":"1.195453611","rc":[{"atl":[[220,2]],"id":42651625}],"con":true,"img":false}]}
{"op":"mcm","clk":"5347906583","pt":1646210144952,"mc":[{"id":"1.195453611","rc":[{"atl":[[170,0]],"id":42651625}],"con":true,"img":false}]}
{"op":"mcm","clk":"5347906585","pt":1646210145055,"mc":[{"id":"1.195453611","rc":[{"atl":[[180,0.39],[220,4]],"id":42651625}],"con":true,"img":false}]}
{"op":"mcm","clk":"5347906588","pt":1646210145158,"mc":[{"id":"1.195453611","rc":[{"atl":[[220,2],[230,4.72]],"id":42651625}],"con":true,"img":false}]}
{"op":"mcm","clk":"5347906593","pt":1646210145261,"mc":[{"id":"1.195453611","rc":[{"atl":[[220,0],[230,6.72]],"id":42651625}],"con":true,"img":false}]}
{"op":"mcm","clk":"5347906665","pt":1646210146860,"mc":[{"id":"1.195453611","rc":[{"atb":[[1.72,27.31],[1.66,0]],"id":43066529}],"con":true,"img":false}]}
{"op":"mcm","clk":"5347906668","pt":1646210146973,"mc":[{"id":"1.195453611","rc":[{"atb":[[2.6,0]],"id":43167173}],"con":true,"img":false}]}
{"op":"mcm","clk":"5347906696","pt":1646210147740,"mc":[{"id":"1.195453611","rc":[{"atb":[[2.62,1.66]],"id":43167173}],"con":true,"img":false}]}
{"op":"mcm","clk":"5347906704","pt":1646210147845,"mc":[{"id":"1.195453611","rc":[{"atb":[[2.38,2.91]],"id":43167173}],"con":true,"img":false}]}
{"op":"mcm","clk":"5347906775","pt":1646210149764,"mc":[{"id":"1.195453611","rc":[{"atl":[[4,16.67]],"id":43167173}],"con":true,"img":false}]}
{"op":"mcm","clk":"5347906831","pt":1646210151449,"mc":[{"id":"1.195453611","rc":[{"atb":[[2.6,9.48]],"id":43167173}],"con":true,"img":false}]}
{"op":"mcm","clk":"5347906841","pt":1646210151670,"mc":[{"id":"1.195453611","rc":[{"atb":[[2.38,1.6]],"id":43167173}],"con":true,"img":false}]}
{"op":"mcm","clk":"5347906844","pt":1646210151762,"mc":[{"id":"1.195453611","rc":[{"atb":[[2.62,2.97]],"id":43167173}],"con":true,"img":false}]}
{"op":"mcm","clk":"5347906858","pt":1646210152095,"mc":[{"id":"1.195453611","rc":[{"atl":[[4.7,0]],"id":43066529}],"con":true,"img":false}]}
{"op":"mcm","clk":"5347906865","pt":1646210152172,"mc":[{"id":"1.195453611","rc":[{"spn":14.63,"spf":1.14,"id":41762566},{"atl":[[4.2,6.76]],"id":43066529},{"spn":17.39,"spf":1.0,"id":42651625},{"spn":10.68,"spf":1.0,"id":41676292},{"spn":2.47,"spf":1.0,"id":43167173}],"con":true,"img":false}]}
{"op":"mcm","clk":"5347906939","pt":1646210154355,"mc":[{"id":"1.195453611","rc":[{"atl":[[250,1]],"id":41762566},{"atb":[[6.8,8.62]],"id":42651625},{"atb":[[9,6.25]],"id":41676292},{"atl":[[11.5,4.76]],"id":43167172}],"con":true,"img":false}]}
{"op":"mcm","clk":"5347906974","pt":1646210155489,"mc":[{"id":"1.195453611","rc":[{"atb":[[2.6,0]],"id":43167173}],"con":true,"img":false}]}
{"op":"mcm","clk":"5347907004","pt":1646210156265,"mc":[{"id":"1.195453611","rc":[{"atb":[[2.62,1.66]],"id":43167173}],"con":true,"img":false}]}
{"op":"mcm","clk":"5347907009","pt":1646210156368,"mc":[{"id":"1.195453611","rc":[{"atb":[[2.38,2.91]],"id":43167173}],"con":true,"img":false}]}
{"op":"mcm","clk":"5347907023","pt":1646210156883,"mc":[{"id":"1.195453611","rc":[{"atb":[[1.7,70.22]],"id":43066529}],"con":true,"img":false}]}
{"op":"mcm","clk":"5347907097","pt":1646210159454,"mc":[{"id":"1.195453611","rc":[{"atb":[[2.6,9.48]],"id":43167173}],"con":true,"img":false}]}
{"op":"mcm","clk":"5347907108","pt":1646210159761,"mc":[{"id":"1.195453611","rc":[{"atl":[[4.2,23.44]],"id":43167173}],"con":true,"img":false}]}
{"op":"mcm","clk":"5347907174","pt":1646210161206,"mc":[{"id":"1.195453611","rc":[{"atb":[[2.38,1.6]],"id":43167173}],"con":true,"img":false}]}
{"op":"mcm","clk":"5347907176","pt":1646210161263,"mc":[{"id":"1.195453611","rc":[{"atb":[[2.62,2.97]],"id":43167173}],"con":true,"img":false}]}
{"op":"mcm","clk":"5347907316","pt":1646210164405,"mc":[{"id":"1.195453611","rc":[{"atl":[[240,0.83],[260,0],[270,1],[280,0]],"id":41762566},{"atb":[[6.4,13.89]],"id":42651625},{"atb":[[8.6,15.25]],"id":41676292},{"atl":[[12.5,6.52]],"id":43167172}],"con":true,"img":false}]}
{"op":"mcm","clk":"5347907361","pt":1646210165384,"mc":[{"id":"1.195453611","rc":[{"atb":[[2.6,0]],"id":43167173}],"con":true,"img":false}]}
{"op":"mcm","clk":"5347907400","pt":1646210166104,"mc":[{"id":"1.195453611","rc":[{"atb":[[2.62,1.66]],"id":43167173}],"con":true,"img":false}]}
{"op":"mcm","clk":"5347907407","pt":1646210166206,"mc":[{"id":"1.195453611","rc":[{"atb":[[2.38,2.91]],"id":43167173}],"con":true,"img":false}]}
{"op":"mcm","clk":"5347907451","pt":1646210166880,"mc":[{"id":"1.195453611","rc":[{"atb":[[1.59,0],[1.68,108.44],[1.57,0],[1.61,0]],"id":43066529}],"con":true,"img":false}]}
{"op":"mcm","clk":"5347907522","pt":1646210168710,"mc":[{"id":"1.195453611","rc":[{"atb":[[2.6,9.48]],"id":43167173}],"con":true,"img":false}]}
{"op":"mcm","clk":"5347907575","pt":1646210169793,"mc":[{"id":"1.195453611","rc":[{"atl":[[4.4,66.17]],"id":43167173}],"con":true,"img":false}]}
{"op":"mcm","clk":"5347907582","pt":1646210169898,"mc":[{"id":"1.195453611","rc":[{"atb":[[2.38,1.6]],"id":43167173}],"con":true,"img":false}]}
{"op":"mcm","clk":"5347907587","pt":1646210170000,"mc":[{"id":"1.195453611","rc":[{"atb":[[2.62,2.97]],"id":43167173}],"con":true,"img":false}]}
{"op":"mcm","clk":"5347907693","pt":1646210172266,"mc":[{"id":"1.195453611","rc":[{"atb":[[2.6,0]],"id":43167173}],"con":true,"img":false}]}
{"op":"mcm","clk":"5347907736","pt":1646210173297,"mc":[{"id":"1.195453611","rc":[{"atb":[[2.62,1.66]],"id":43167173}],"con":true,"img":false}]}
{"op":"mcm","clk":"5347907739","pt":1646210173400,"mc":[{"id":"1.195453611","rc":[{"atb":[[2.38,2.91]],"id":43167173}],"con":true,"img":false}]}
{"op":"mcm","clk":"5347907777","pt":1646210174385,"mc":[{"id":"1.195453611","rc":[{"atl":[[290,1.69]],"id":41762566},{"atb":[[6,25]],"id":42651625},{"atb":[[8.2,17.36]],"id":41676292},{"atl":[[13.5,10]],"id":43167172}],"con":true,"img":false}]}
{"op":"mcm","clk":"5347907867","pt":1646210176636,"mc":[{"id":"1.195453611","rc":[{"atb":[[2.6,9.48]],"id":43167173}],"con":true,"img":false}]}
{"op":"mcm","clk":"5347907884","pt":1646210176893,"mc":[{"id":"1.195453611","rc":[{"atb":[[1.66,186.2]],"id":43066529}],"con":true,"img":false}]}
{"op":"mcm","clk":"5347907905","pt":1646210177203,"mc":[{"id":"1.195453611","rc":[{"atb":[[2.38,1.6]],"id":43167173}],"con":true,"img":false}]}
{"op":"mcm","clk":"5347907911","pt":1646210177308,"mc":[{"id":"1.195453611","rc":[{"atb":[[2.62,2.97]],"id":43167173}],"con":true,"img":false}]}
{"op":"mcm","clk":"5347908042","pt":1646210180193,"mc":[{"id":"1.195453611","rc":[{"atb":[[2.6,0]],"id":43167173}],"con":true,"img":false}]}
{"op":"mcm","clk":"5347908117","pt":1646210181489,"mc":[{"id":"1.195453611","rc":[{"atb":[[2.62,1.66]],"id":43167173}],"con":true,"img":false}]}
{"op":"mcm","clk":"5347908125","pt":1646210181592,"mc":[{"id":"1.195453611","rc":[{"atb":[[2.38,2.91]],"id":43167173}],"con":true,"img":false}]}
{"op":"mcm","clk":"5347908240","pt":1646210184017,"mc":[{"id":"1.195453611","rc":[{"atb":[[2.6,9.48]],"id":43167173}],"con":true,"img":false}]}
{"op":"mcm","clk":"5347908288","pt":1646210184793,"mc":[{"id":"1.195453611","rc":[{"atb":[[2.38,1.6]],"id":43167173}],"con":true,"img":false}]}
{"op":"mcm","clk":"5347908295","pt":1646210184898,"mc":[{"id":"1.195453611","rc":[{"atb":[[2.62,2.97]],"id":43167173}],"con":true,"img":false}]}
{"op":"mcm","clk":"5347908450","pt":1646210188099,"mc":[{"id":"1.195453611","rc":[{"atb":[[2.6,0]],"id":43167173}],"con":true,"img":false}]}
{"op":"mcm","clk":"5347908458","pt":1646210188407,"mc":[{"id":"1.195453611","rc":[{"atb":[[2.62,1.66]],"id":43167173}],"con":true,"img":false}]}
{"op":"mcm","clk":"5347908461","pt":1646210188509,"mc":[{"id":"1.195453611","rc":[{"atb":[[2.38,2.91]],"id":43167173}],"con":true,"img":false}]}
{"op":"mcm","clk":"5347908604","pt":1646210192212,"mc":[{"id":"1.195453611","rc":[{"atb":[[2.6,9.48]],"id":43167173}],"con":true,"img":false}]}
{"op":"mcm","clk":"5347908637","pt":1646210192931,"mc":[{"id":"1.195453611","rc":[{"atb":[[2.38,1.6]],"id":43167173}],"con":true,"img":false}]}
{"op":"mcm","clk":"5347908643","pt":1646210192982,"mc":[{"id":"1.195453611","rc":[{"atb":[[2.62,2.97]],"id":43167173}],"con":true,"img":false}]}
{"op":"mcm","clk":"5347908788","pt":1646210196014,"mc":[{"id":"1.195453611","rc":[{"atb":[[2.6,0]],"id":43167173}],"con":true,"img":false}]}
{"op":"mcm","clk":"5347908826","pt":1646210196786,"mc":[{"id":"1.195453611","rc":[{"atb":[[2.62,1.66]],"id":43167173}],"con":true,"img":false}]}
{"op":"mcm","clk":"5347908831","pt":1646210196888,"mc":[{"id":"1.195453611","rc":[{"atb":[[2.38,2.91]],"id":43167173}],"con":true,"img":false}]}
{"op":"mcm","clk":"5347909071","pt":1646210199831,"mc":[{"id":"1.195453611","rc":[{"atb":[[2.6,9.48]],"id":43167173}],"con":true,"img":false}]}
{"op":"mcm","clk":"5347909118","pt":1646210200808,"mc":[{"id":"1.195453611","rc":[{"atb":[[2.38,1.6]],"id":43167173}],"con":true,"img":false}]}
{"op":"mcm","clk":"5347909121","pt":1646210200910,"mc":[{"id":"1.195453611","rc":[{"atb":[[2.62,2.97]],"id":43167173}],"con":true,"img":false}]}
{"op":"mcm","clk":"5347909237","pt":1646210203390,"mc":[{"id":"1.195453611","rc":[{"atb":[[2.6,0]],"id":43167173}],"con":true,"img":false}]}
{"op":"mcm","clk":"5347909256","pt":1646210204007,"mc":[{"id":"1.195453611","rc":[{"atb":[[2.62,1.66]],"id":43167173}],"con":true,"img":false}]}
{"op":"mcm","clk":"5347909259","pt":1646210204116,"mc":[{"id":"1.195453611","rc":[{"atb":[[2.38,2.91]],"id":43167173}],"con":true,"img":false}]}
{"op":"mcm","clk":"5347909419","pt":1646210207919,"mc":[{"id":"1.195453611","rc":[{"atb":[[2.6,9.48]],"id":43167173}],"con":true,"img":false}]}
{"op":"mcm","clk":"5347909443","pt":1646210208433,"mc":[{"id":"1.195453611","rc":[{"atb":[[2.38,1.6]],"id":43167173}],"con":true,"img":false}]}
{"op":"mcm","clk":"5347909447","pt":1646210208539,"mc":[{"id":"1.195453611","rc":[{"atb":[[2.62,2.97]],"id":43167173}],"con":true,"img":false}]}
{"op":"mcm","clk":"5347909564","pt":1646210211633,"mc":[{"id":"1.195453611","rc":[{"atb":[[2.6,0]],"id":43167173}],"con":true,"img":false}]}
{"op":"mcm","clk":"5347909618","pt":1646210212619,"mc":[{"id":"1.195453611","rc":[{"spn":10.66,"spf":1.0,"id":41676292},{"atb":[[2.62,1.66]],"id":43167173},{"spn":2.38,"spf":1.0,"id":43167173}],"con":true,"img":false}]}
{"op":"mcm","clk":"5347909625","pt":1646210212720,"mc":[{"id":"1.195453611","rc":[{"atb":[[2.38,2.91]],"id":43167173}],"con":true,"img":false}]}
{"op":"mcm","clk":"5347909752","pt":1646210215557,"mc":[{"id":"1.195453611","rc":[{"atb":[[2.6,9.48]],"id":43167173}],"con":true,"img":false}]}
{"op":"mcm","clk":"5347909784","pt":1646210216228,"mc":[{"id":"1.195453611","rc":[{"atb":[[2.38,1.6]],"id":43167173}],"con":true,"img":false}]}
{"op":"mcm","clk":"5347909788","pt":1646210216330,"mc":[{"id":"1.195453611","rc":[{"atb":[[2.62,2.97]],"id":43167173}],"con":true,"img":false}]}
{"op":"mcm","clk":"5347909913","pt":1646210219312,"mc":[{"id":"1.195453611","rc":[{"atb":[[2.6,0]],"id":43167173}],"con":true,"img":false}]}
{"op":"mcm","clk":"5347909924","pt":1646210219516,"mc":[{"id":"1.195453611","rc":[{"atb":[[2.62,1.66]],"id":43167173}],"con":true,"img":false}]}
{"op":"mcm","clk":"5347909929","pt":1646210219619,"mc":[{"id":"1.195453611","rc":[{"atb":[[2.38,2.91]],"id":43167173}],"con":true,"img":false}]}
{"op":"mcm","clk":"5347909963","pt":1646210220341,"mc":[{"id":"1.195453611","rc":[{"atb":[[1.02,3.03]],"id":43066529},{"atb":[[1.05,2.81]],"id":41676292},{"atb":[[1.02,3.05]],"id":43167172},{"atb":[[1.03,3.1]],"id":43167173}],"con":true,"img":false}]}
{"op":"mcm","clk":"5347909987","pt":1646210220753,"mc":[{"id":"1.195453611","rc":[{"atb":[[1.02,0.3]],"id":43066529},{"atb":[[1.05,0.08]],"id":41676292},{"atb":[[1.02,0.32]],"id":43167172},{"atb":[[1.03,0.37]],"id":43167173}],"con":true,"img":false}]}
{"op":"mcm","clk":"5347910010","pt":1646210221114,"mc":[{"id":"1.195453611","rc":[{"atb":[[1.02,0]],"id":43167172},{"atb":[[1.03,0]],"id":43167173}],"con":true,"img":false}]}
{"op":"mcm","clk":"5347910018","pt":1646210221216,"mc":[{"id":"1.195453611","rc":[{"atb":[[1.02,0]],"id":43066529},{"atb":[[1.05,0]],"id":41676292},{"atb":[[3.35,0.32]],"id":43167172},{"atb":[[2.86,0.37]],"id":43167173}],"con":true,"img":false}]}
{"op":"mcm","clk":"5347910022","pt":1646210221318,"mc":[{"id":"1.195453611","rc":[{"atl":[[3.3,7.4]],"id":43066529},{"trd":[[3.3,0.61]],"ltp":3.3,"tv":0.61,"id":43066529},{"atb":[[12,1.66]],"id":41676292},{"atb":[[2.64,8.22]],"id":43167173}],"con":true,"img":false}]}
{"op":"mcm","clk":"5347910028","pt":1646210221476,"mc":[{"id":"1.195453611","rc":[{"atb":[[11.5,0],[16.5,0],[9.6,0],[8.6,0],[7.6,0]],"id":41762566},{"atl":[[140,0],[190,0],[240,0],[290,1]],"id":41762566},{"atb":[[2.76,0],[2.56,0],[2.86,0],[2.66,0]],"id":43066529},{"atl":[[11,0],[13.5,0],[8.4,0],[9.4,0]],"id":43066529},{"atb":[[10.5,0],[13,0],[15.5,0],[18,0],[26,0]],"id":42651625},{"atl":[[290,0],[340,0],[390,0],[240,0]],"id":42651625},{"atb":[[5.8,0],[11.5,5.85],[8.6,9.87],[7.6,0],[6.6,0]],"id":41676292},{"atl":[[130,8.2],[180,0],[230,0],[90,0]],"id":41676292},{"atb":[[2,0],[1.85,0],[1.95,0],[1.9,0],[2.2,0]],"id":43167172},{"atl":[[8,0],[5.5,0],[6,0],[7,0]],"id":43167172},{"atb":[[1.98,0],[1.93,0],[2.36,0],[2.06,0],[2.16,0]],"id":43167173},{"atl":[[6.4,0],[7.4,0],[8.4,0],[5.7,0]],"id":43167173}],"con":true,"img":false}]}
{"op":"mcm","clk":"5347910054","pt":1646210222042,"mc":[{"id":"1.195453611","rc":[{"atb":[[14,10.47],[17,0]],"id":41762566},{"atl":[[6.4,22.92],[5.4,0]],"id":43167172}],"con":true,"img":false}]}
{"op":"mcm","clk":"5347910074","pt":1646210222451,"mc":[{"id":"1.195453611","rc":[{"atb":[[2.38,1.6]],"id":43167173}],"con":true,"img":false}]}
{"op":"mcm","clk":"5347910083","pt":1646210222555,"mc":[{"id":"1.195453611","rc":[{"atb":[[2.66,1.31]],"id":43167173}],"con":true,"img":false}]}
{"op":"mcm","clk":"5347910110","pt":1646210223017,"mc":[{"id":"1.195453611","rc":[{"atb":[[3.05,1.49],[1.04,1.67]],"id":43167172},{"atb":[[2.62,0],[1.04,1.67]],"id":43167173}],"con":true,"img":false}]}
{"op":"mcm","clk":"5347910116","pt":1646210223121,"mc":[{"id":"1.195453611","rc":[{"atb":[[1.04,1.66]],"id":43167172},{"atb":[[1.04,1.66]],"id":43167173}],"con":true,"img":false}]}
{"op":"mcm","clk":"5347910125","pt":1646210223326,"mc":[{"id":"1.195453611","rc":[{"atb":[[1.04,0]],"id":43167172},{"atb":[[1.04,0]],"id":43167173}],"con":true,"img":false}]}
{"op":"mcm","clk":"5347910129","pt":1646210223428,"mc":[{"id":"1.195453611","rc":[{"atb":[[3.25,1.66]],"id":43167172},{"atb":[[2.7,1.66]],"id":43167173}],"con":true,"img":false}]}
{"op":"mcm","clk":"5347910167","pt":1646210224356,"mc":[{"id":"1.195453611","rc":[{"atb":[[2.76,2.5]],"id":43167173}],"con":true,"img":false}]}
{"op":"mcm","clk":"5347910179","pt":1646210224669,"mc":[{"id":"1.195453611","rc":[{"atb":[[11.5,4.08],[16.5,2.76],[9.6,9.96],[8.6,11.27],[7.6,25.96]],"id":41762566},{"atl":[[140,0.93],[190,0.68],[240,0.81],[290,1.67]],"id":41762566},{"atb":[[2.76,41.87],[2.56,94.47],[2.86,19.8],[2.66,44.39],[3.15,18.01]],"id":43066529},{"atl":[[11,21.23],[13.5,16.99],[8.4,19.13],[9.4,16.85]],"id":43066529},{"atb":[[10.5,18.04],[13,7.13],[15.5,5.91],[18,2.52],[26,1.71]],"id":42651625},{"atl":[[290,0.44],[340,0.57],[390,0.5],[240,0.54]],"id":42651625},{"atb":[[5.8,35.7],[11.5,9.93],[8.6,15.5],[7.6,12.98],[6.6,15.3]],"id":41676292},{"atl":[[130,9.2],[180,1.08],[230,0.85],[90,1.45]],"id":41676292},{"atb":[[2,42.84],[1.85,201.61],[1.95,90.19],[1.9,95.2],[2.2,35.7]],"id":43167172},{"atl":[[8,27.77],[5.5,28.79],[6,25.91],[7,32.4]],"id":43167172},{"atb":[[1.98,87.43],[1.93,184.26],[2.36,31.5],[2.06,80.83],[2.16,36.93]],"id":43167173},{"atl":[[6.4,24],[7.4,30.37],[8.4,26.27],[5.7,27.57]],"id":43167173}],"con":true,"img":false}]}
{"op":"mcm","clk":"5347910211","pt":1646210225543,"mc":[{"id":"1.195453611","rc":[{"atb":[[2.82,13.02]],"id":43167172}],"con":true,"img":false}]}
{"op":"mcm","clk":"5347910258","pt":1646210226829,"mc":[{"id":"1.195453611","rc":[{"atl":[[1000,1.67]],"id":41676292}],"con":true,"img":false}]}
{"op":"mcm","clk":"5347910264","pt":1646210226932,"mc":[{"id":"1.195453611","rc":[{"atl":[[1000,0.27]],"id":41676292}],"con":true,"img":false}]}
{"op":"mcm","clk":"5347910267","pt":1646210227035,"mc":[{"id":"1.195453611","rc":[{"atl":[[1000,0]],"id":41676292}],"con":true,"img":false}]}
{"op":"mcm","clk":"5347910272","pt":1646210227138,"mc":[{"id":"1.195453611","rc":[{"atl":[[30,0.27]],"id":41676292}],"con":true,"img":false}]}
{"op":"mcm","clk":"5347910277","pt":1646210227242,"mc":[{"id":"1.195453611","rc":[{"atl":[[32,3],[36,4.29]],"id":41676292}],"con":true,"img":false}]}
{"op":"mcm","clk":"5347910282","pt":1646210227448,"mc":[{"id":"1.195453611","rc":[{"atl":[[32,1]],"id":41676292}],"con":true,"img":false}]}
{"op":"mcm","clk":"5347910287","pt":1646210227551,"mc":[{"id":"1.195453611","rc":[{"atl":[[32,3]],"id":41676292}],"con":true,"img":false}]}
{"op":"mcm","clk":"5347910292","pt":1646210227653,"mc":[{"id":"1.195453611","rc":[{"atb":[[2.64,0]],"id":43167173}],"con":true,"img":false}]}
{"op":"mcm","clk":"5347910301","pt":1646210227859,"mc":[{"id":"1.195453611","rc":[{"atl":[[34,0]],"id":41676292}],"con":true,"img":false}]}
{"op":"mcm","clk":"5347910307","pt":1646210227962,"mc":[{"id":"1.195453611","rc":[{"atl":[[30,1.58]],"id":41676292}],"con":true,"img":false}]}
{"op":"mcm","clk":"5347910336","pt":1646210228533,"mc":[{"id":"1.195453611","rc":[{"atb":[[2.66,0]],"id":43167173}],"con":true,"img":false}]}
{"op":"mcm","clk":"5347910340","pt":1646210228633,"mc":[{"id":"1.195453611","rc":[{"atb":[[2.38,2.91]],"id":43167173}],"con":true,"img":false}]}
{"op":"mcm","clk":"5347910389","pt":1646210229870,"mc":[{"id":"1.195453611","rc":[{"atb":[[2.82,0]],"id":43167172},{"atb":[[1.2,2.25]],"id":43167173}],"con":true,"img":false}]}
{"op":"mcm","clk":"5347910398","pt":1646210230127,"mc":[{"id":"1.195453611","rc":[{"atb":[[1.2,2.01]],"id":43167173}],"con":true,"img":false}]}
{"op":"mcm","clk":"5347910411","pt":1646210230433,"mc":[{"id":"1.195453611","rc":[{"atb":[[1.2,0]],"id":43167173}],"con":true,"img":false}]}
{"op":"mcm","clk":"5347910419","pt":1646210230540,"mc":[{"id":"1.195453611","rc":[{"atb":[[2.78,2.01]],"id":43167173}],"con":true,"img":false}]}
{"op":"mcm","clk":"5347910458","pt":1646210231366,"mc":[{"id":"1.195453611","rc":[{"atb":[[2.76,0]],"id":43167173}],"con":true,"img":false}]}
{"op":"mcm","clk":"5347910488","pt":1646210232034,"mc":[{"id":"1.195453611","rc":[{"atb":[[2.8,2.5]],"id":43167173}],"con":true,"img":false}]}
{"op":"mcm","clk":"5347910658","pt":1646210235738,"mc":[{"id":"1.195453611","rc":[{"atb":[[1.01,4.76]],"id":43066529}],"con":true,"img":false}]}
{"op":"mcm","clk":"5347910662","pt":1646210235840,"mc":[{"id":"1.195453611","rc":[{"atb":[[2.78,0]],"id":43167173}],"con":true,"img":false}]}
{"op":"mcm","clk":"5347910668","pt":1646210235942,"mc":[{"id":"1.195453611","rc":[{"atb":[[1.01,6.75]],"id":43066529}],"con":true,"img":false}]}
{"op":"mcm","clk":"5347910675","pt":1646210236046,"mc":[{"id":"1.195453611","rc":[{"atb":[[1.01,4.76]],"id":43066529}],"con":true,"img":false}]}
{"op":"mcm","clk":"5347910681","pt":1646210236148,"mc":[{"id":"1.195453611","rc":[{"atb":[[1.02,1.99]],"id":43066529}],"con":true,"img":false}]}
{"op":"mcm","clk":"5347910817","pt":1646210239541,"mc":[{"id":"1.195453611","rc":[{"atb":[[1.01,2]],"id":43167172}],"con":true,"img":false}]}
{"op":"mcm","clk":"5347910829","pt":1646210239849,"mc":[{"id":"1.195453611","rc":[{"atb":[[1.01,3.99]],"id":43167172},{"atb":[[2.76,2.88]],"id":43167173}],"con":true,"img":false}]}
{"op":"mcm","clk":"5347910839","pt":1646210240158,"mc":[{"id":"1.195453611","rc":[{"atb":[[1.01,2]],"id":43167172}],"con":true,"img":false}]}
{"op":"mcm","clk":"5347910844","pt":1646210240261,"mc":[{"id":"1.195453611","rc":[{"atb":[[1.02,1.99]],"id":43167172}],"con":true,"img":false}]}
{"op":"mcm","clk":"5347910892","pt":1646210241338,"mc":[{"id":"1.195453611","rc":[{"atb":[[1.01,2]],"id":43167173}],"con":true,"img":false}]}
{"op":"mcm","clk":"5347910904","pt":1646210241543,"mc":[{"id":"1.195453611","rc":[{"atb":[[1.01,3.99]],"id":43167173}],"con":true,"img":false}]}
{"op":"mcm","clk":"5347910912","pt":1646210241749,"mc":[{"id":"1.195453611","rc":[{"atb":[[1.01,2]],"id":43167173}],"con":true,"img":false}]}
{"op":"mcm","clk":"5347910916","pt":1646210241851,"mc":[{"id":"1.195453611","rc":[{"atb":[[1.02,1.99]],"id":43167173}],"con":true,"img":false}]}
{"op":"mcm","clk":"5347911312","pt":1646210250553,"mc":[{"id":"1.195453611","rc":[{"atb":[[2.88,0]],"id":43066529}],"con":true,"img":false}]}
{"op":"mcm","clk":"5347911315","pt":1646210250656,"mc":[{"id":"1.195453611","rc":[{"atb":[[2.94,32.8]],"id":43066529}],"con":true,"img":false}]}
{"op":"mcm","clk":"5347911402","pt":1646210252867,"mc":[{"id":"1.195453611","rc":[{"atl":[[3.3,4.1]],"id":43066529}],"con":true,"img":false}]}
{"op":"mcm","clk":"5347911406","pt":1646210252969,"mc":[{"id":"1.195453611","rc":[{"atl":[[3.95,2.75]],"id":43066529}],"con":true,"img":false}]}
{"op":"mcm","clk":"5347911545","pt":1646210255851,"mc":[{"id":"1.195453611","rc":[{"atl":[[3.95,0]],"id":43066529}],"con":true,"img":false}]}
{"op":"mcm","clk":"5347911555","pt":1646210256058,"mc":[{"id":"1.195453611","rc":[{"atl":[[3.3,7.4]],"id":43066529}],"con":true,"img":false}]}
{"op":"mcm","clk":"5347911600","pt":1646210256987,"mc":[{"id":"1.195453611","rc":[{"atb":[[1.03,1.67]],"id":41676292}],"con":true,"img":false}]}
{"op":"mcm","clk":"5347911614","pt":1646210257195,"mc":[{"id":"1.195453611","rc":[{"atb":[[1.03,0.55]],"id":41676292}],"con":true,"img":false}]}
{"op":"mcm","clk":"5347911627","pt":1646210257356,"mc":[{"id":"1.195453611","rc":[{"atb":[[1.03,0]],"id":41676292}],"con":true,"img":false}]}
{"op":"mcm","clk":"5347911639","pt":1646210257453,"mc":[{"id":"1.195453611","rc":[{"atl":[[3.3,3.29]],"id":43066529},{"atb":[[15,0.55]],"id":41676292}],"con":true,"img":false}]}
{"op":"mcm","clk":"5347911651","pt":1646210257761,"mc":[{"id":"1.195453611","rc":[{"atl":[[3.95,3.43]],"id":43066529}],"con":true,"img":false}]}
{"op":"mcm","clk":"5347911699","pt":1646210258789,"mc":[{"id":"1.195453611","rc":[{"atl":[[3.3,0]],"id":43066529}],"con":true,"img":false}]}
{"op":"mcm","clk":"5347911707","pt":1646210258891,"mc":[{"id":"1.195453611","rc":[{"atl":[[3.95,6.18]],"id":43066529}],"con":true,"img":false}]}
{"op":"mcm","clk":"5347911710","pt":1646210258994,"mc":[{"id":"1.195453611","rc":[{"atb":[[1.86,4]],"id":43066529},{"atl":[[5.3,4.65],[5.1,0]],"id":43066529}],"con":true,"img":false}]}
{"op":"mcm","clk":"5347911724","pt":1646210259360,"mc":[{"id":"1.195453611","rc":[{"atl":[[3.8,2.5]],"id":43167173}],"con":true,"img":false}]}
{"op":"mcm","clk":"5347911768","pt":1646210260381,"mc":[{"id":"1.195453611","rc":[{"atl":[[3.85,0]],"id":43167173}],"con":true,"img":false}]}
{"op":"mcm","clk":"5347911774","pt":1646210260485,"mc":[{"id":"1.195453611","rc":[{"atl":[[3.75,1.25]],"id":43167173}],"con":true,"img":false}]}
{"op":"mcm","clk":"5347911782","pt":1646210260690,"mc":[{"id":"1.195453611","rc":[{"atb":[[2.76,0]],"id":43167173}],"con":true,"img":false}]}
{"op":"mcm","clk":"5347911799","pt":1646210261110,"mc":[{"id":"1.195453611","rc":[{"atb":[[3.2,2.86]],"id":43066529}],"con":true,"img":false}]}
{"op":"mcm","clk":"5347911812","pt":1646210261361,"mc":[{"id":"1.195453611","rc":[{"atb":[[1.87,4],[1.86,0]],"id":43066529},{"atl":[[5.1,4.88]],"id":43066529},{"atl":[[3.85,7.02],[3.9,0]],"id":43167173}],"con":true,"img":false}]}
{"op":"mcm","clk":"5347911844","pt":1646210262183,"mc":[{"id":"1.195453611","rc":[{"atl":[[3.8,0]],"id":43167173}],"con":true,"img":false}]}
{"op":"mcm","clk":"5347911867","pt":1646210262695,"mc":[{"id":"1.195453611","rc":[{"atl":[[3.75,0]],"id":43167173}],"con":true,"img":false}]}
{"op":"mcm","clk":"5347911872","pt":1646210262798,"mc":[{"id":"1.195453611","rc":[{"atl":[[3.95,3.43]],"id":43066529},{"atl":[[3.8,1.25]],"id":43167173}],"con":true,"img":false}]}
{"op":"mcm","clk":"5347911876","pt":1646210262901,"mc":[{"id":"1.195453611","rc":[{"atl":[[3.9,2.79]],"id":43066529}],"con":true,"img":false}]}
{"op":"mcm","clk":"5347911971","pt":1646210264603,"mc":[{"id":"1.195453611","rc":[{"atb":[[2.58,5.47]],"id":43167173}],"con":true,"img":false}]}
{"op":"mcm","clk":"5347911976","pt":1646210264705,"mc":[{"id":"1.195453611","rc":[{"atl":[[3.75,2.5]],"id":43167173}],"con":true,"img":false}]}
{"op":"mcm","clk":"5347911994","pt":1646210265072,"mc":[{"id":"1.195453611","rc":[{"atl":[[3.8,0]],"id":43167173}],"con":true,"img":false}]}
{"op":"mcm","clk":"5347912000","pt":1646210265167,"mc":[{"id":"1.195453611","rc":[{"atl":[[3.7,1.25]],"id":43167173}],"con":true,"img":false}]}
{"op":"mcm","clk":"5347912023","pt":1646210265578,"mc":[{"id":"1.195453611","rc":[{"atb":[[2.38,1.6]],"id":43167173}],"con":true,"img":false}]}
{"op":"mcm","clk":"5347912030","pt":1646210265681,"mc":[{"id":"1.195453611","rc":[{"atb":[[2.58,6.78]],"id":43167173}],"con":true,"img":false}]}
{"op":"mcm","clk":"5347912049","pt":1646210266093,"mc":[{"id":"1.195453611","rc":[{"atl":[[6.4,0],[5.4,28.93]],"id":43167172}],"con":true,"img":false}]}
{"op":"mcm","clk":"5347912055","pt":1646210266299,"mc":[{"id":"1.195453611","rc":[{"atb":[[1.87,0]],"id":43066529}],"con":true,"img":false}]}
{"op":"mcm","clk":"5347912094","pt":1646210267274,"mc":[{"id":"1.195453611","rc":[{"atl":[[3.75,0]],"id":43167173}],"con":true,"img":false}]}
{"op":"mcm","clk":"5347912102","pt":1646210267480,"mc":[{"id":"1.195453611","rc":[{"atl":[[3.7,0]],"id":43167173}],"con":true,"img":false}]}
{"op":"mcm","clk":"5347912107","pt":1646210267584,"mc":[{"id":"1.195453611","rc":[{"atl":[[3.8,1.25]],"id":43167173}],"con":true,"img":false}]}
{"op":"mcm","clk":"5347912150","pt":1646210268511,"mc":[{"id":"1.195453611","rc":[{"atb":[[17,6.97]],"id":41762566}],"con":true,"img":false}]}
{"op":"mcm","clk":"5347912155","pt":1646210268614,"mc":[{"id":"1.195453611","rc":[{"atb":[[14,1.54]],"id":41762566}],"con":true,"img":false}]}
{"op":"mcm","clk":"5347912163","pt":1646210268720,"mc":[{"id":"1.195453611","rc":[{"atl":[[3.75,2.5]],"id":43167173}],"con":true,"img":false}]}
{"op":"mcm","clk":"5347912211","pt":1646210269604,"mc":[{"id":"1.195453611","rc":[{"atb":[[3.25,4.48]],"id":43066529}],"con":true,"img":false}]}
{"op":"mcm","clk":"5347912215","pt":1646210269706,"mc":[{"id":"1.195453611","rc":[{"atl":[[3.95,0]],"id":43066529}],"con":true,"img":false}]}
{"op":"mcm","clk":"5347912236","pt":1646210270174,"mc":[{"id":"1.195453611","rc":[{"atl":[[3.85,3.52]],"id":43066529}],"con":true,"img":false}]}
{"op":"mcm","clk":"5347912251","pt":1646210270485,"mc":[{"id":"1.195453611","rc":[{"atb":[[2.58,1.31]],"id":43167173}],"con":true,"img":false}]}
{"op":"mcm","clk":"5347912266","pt":1646210270794,"mc":[{"id":"1.195453611","rc":[{"atl":[[3.9,0]],"id":43066529}],"con":true,"img":false}]}
{"op":"mcm","clk":"5347912273","pt":1646210271002,"mc":[{"id":"1.195453611","rc":[{"atl":[[3.8,2.86]],"id":43066529}],"con":true,"img":false}]}
{"op":"mcm","clk":"5347912286","pt":1646210271311,"mc":[{"id":"1.195453611","rc":[{"atb":[[2.58,0]],"id":43167173}],"con":true,"img":false}]}
{"op":"mcm","clk":"5347912294","pt":1646210271416,"mc":[{"id":"1.195453611","rc":[{"atl":[[5.3,11.63]],"id":43066529},{"atb":[[2.38,2.91]],"id":43167173}],"con":true,"img":false}]}
{"op":"mcm","clk":"5347912302","pt":1646210271569,"mc":[{"id":"1.195453611","rc":[{"atl":[[3.85,0],[3.9,6.9]],"id":43167173}],"con":true,"img":false}]}
{"op":"mcm","clk":"5347912386","pt":1646210273126,"mc":[{"id":"1.195453611","rc":[{"spn":14.65,"spf":1.14,"id":41762566},{"atb":[[3.2,0]],"id":43066529},{"spn":3.06,"spf":1.0,"id":43066529},{"spn":17.49,"spf":1.0,"id":42651625},{"spn":10.77,"spf":1.0,"id":41676292},{"spn":2.87,"spf":1.0,"id":43167172},{"spn":2.43,"spf":1.0,"id":43167173}],"con":true,"img":false}]}
{"op":"mcm","clk":"5347912434","pt":1646210274413,"mc":[{"id":"1.195453611","rc":[{"atb":[[2.58,5.47]],"id":43167173}],"con":true,"img":false}]}
{"op":"mcm","clk":"5347912460","pt":1646210275189,"mc":[{"id":"1.195453611","rc":[{"atb":[[2.38,1.6]],"id":43167173}],"con":true,"img":false}]}
{"op":"mcm","clk":"5347912466","pt":1646210275292,"mc":[{"id":"1.195453611","rc":[{"atb":[[2.58,6.78]],"id":43167173}],"con":true,"img":false}]}
{"op":"mcm","clk":"5347912812","pt":1646210282898,"mc":[{"id":"1.195453611","rc":[{"atl":[[3.85,0]],"id":43066529}],"con":true,"img":false}]}
{"op":"mcm","clk":"5347912820","pt":1646210283207,"mc":[{"id":"1.195453611","rc":[{"atb":[[3.25,0]],"id":43066529},{"atl":[[3.75,3.61]],"id":43066529}],"con":true,"img":false}]}
{"op":"mcm","clk":"5347912895","pt":1646210285224,"mc":[{"id":"1.195453611","rc":[{"atb":[[3.2,2.86]],"id":43066529}],"con":true,"img":false}]}
{"op":"mcm","clk":"5347912925","pt":1646210285896,"mc":[{"id":"1.195453611","rc":[{"atb":[[2.58,1.31]],"id":43167173}],"con":true,"img":false}]}
{"op":"mcm","clk":"5347912947","pt":1646210286411,"mc":[{"id":"1.195453611","rc":[{"atb":[[2.58,0]],"id":43167173}],"con":true,"img":false}]}
{"op":"mcm","clk":"5347912950","pt":1646210286514,"mc":[{"id":"1.195453611","rc":[{"atb":[[2.38,2.91]],"id":43167173}],"con":true,"img":false}]}
{"op":"mcm","clk":"5347913020","pt":1646210288318,"mc":[{"id":"1.195453611","rc":[{"atb":[[2.6,5.18]],"id":43167173}],"con":true,"img":false}]}
{"op":"mcm","clk":"5347913043","pt":1646210288838,"mc":[{"id":"1.195453611","rc":[{"atb":[[2.38,1.6]],"id":43167173}],"con":true,"img":false}]}
{"op":"mcm","clk":"5347913051","pt":1646210288935,"mc":[{"id":"1.195453611","rc":[{"atb":[[2.6,6.49]],"id":43167173}],"con":true,"img":false}]}
{"op":"mcm","clk":"5347914332","pt":1646210320052,"mc":[{"id":"1.195453611","rc":[{"atl":[[3.85,7.02],[3.9,0]],"id":43167173}],"con":true,"img":false}]}
{"op":"mcm","clk":"5347914356","pt":1646210320670,"mc":[{"id":"1.195453611","rc":[{"atl":[[200,1],[230,0]],"id":41762566},{"atb":[[1.83,23.69],[1.62,0],[1.72,0],[1.8,70.22],[1.9,21.85]],"id":43066529},{"atl":[[3.55,2]],"id":43066529},{"atb":[[8.2,13.69],[7.2,0]],"id":42651625},{"atb":[[9,0],[8.2,0],[7.4,3.12],[9.4,0],[8.6,5.63],[6.2,19.23]],"id":41676292},{"atl":[[36,1.43],[42,5.16]],"id":41676292},{"atl":[[10.5,0],[7.6,18.18],[9.8,0]],"id":43167172}],"con":true,"img":false}]}
{"op":"mcm","clk":"5347914388","pt":1646210321953,"mc":[{"id":"1.195453611","rc":[{"atb":[[1.9,0]],"id":43066529},{"atl":[[3.8,0],[3.5,2]],"id":43066529},{"atl":[[3.9,6.9]],"id":43167173}],"con":true,"img":false}]}
{"op":"mcm","clk":"5347914391","pt":1646210322055,"mc":[{"id":"1.195453611","rc":[{"atb":[[14,0.11]],"id":41676292},{"atl":[[3.85,0]],"id":43167173}],"con":true,"img":false}]}
{"op":"mcm","clk":"5347914394","pt":1646210322262,"mc":[{"id":"1.195453611","rc":[{"atb":[[1.03,1.67],[15,0]],"id":41676292}],"con":true,"img":false}]}
{"op":"mcm","clk":"5347914400","pt":1646210322366,"mc":[{"id":"1.195453611","rc":[{"atl":[[3.45,4]],"id":43066529}],"con":true,"img":false}]}
{"op":"mcm","clk":"5347914404","pt":1646210322468,"mc":[{"id":"1.195453611","rc":[{"atl":[[3.6,3.02]],"id":43066529},{"atb":[[1.03,0.55]],"id":41676292},{"atb":[[2.6,1.31]],"id":43167173}],"con":true,"img":false}]}
{"op":"mcm","clk":"5347914418","pt":1646210322679,"mc":[{"id":"1.195453611","rc":[{"atl":[[5.4,0]],"id":43066529},{"atb":[[1.03,0],[9.8,0]],"id":41676292}],"con":true,"img":false}]}
{"op":"mcm","clk":"5347914421","pt":1646210322777,"mc":[{"id":"1.195453611","rc":[{"atl":[[5.2,24.56]],"id":43066529},{"atb":[[12.5,0.55],[8.8,12.37]],"id":41676292}],"con":true,"img":false}]}
{"op":"mcm","clk":"5347914429","pt":1646210322932,"mc":[{"id":"1.195453611","rc":[{"atb":[[1.03,1.67],[12.5,0]],"id":41676292}],"con":true,"img":false}]}
{"op":"mcm","clk":"5347914436","pt":1646210323036,"mc":[{"id":"1.195453611","rc":[{"atl":[[5.2,0]],"id":43066529}],"con":true,"img":false}]}
{"op":"mcm","clk":"5347914440","pt":1646210323139,"mc":[{"id":"1.195453611","rc":[{"atl":[[5.4,24.56]],"id":43066529},{"atb":[[1.03,0.54]],"id":41676292},{"atb":[[2.6,0]],"id":43167173}],"con":true,"img":false}]}
{"op":"mcm","clk":"5347914444","pt":1646210323241,"mc":[{"id":"1.195453611","rc":[{"atb":[[2.38,2.91]],"id":43167173}],"con":true,"img":false}]}
{"op":"mcm","clk":"5347914448","pt":1646210323344,"mc":[{"id":"1.195453611","rc":[{"atb":[[1.03,0]],"id":41676292}],"con":true,"img":false}]}
{"op":"mcm","clk":"5347914450","pt":1646210323447,"mc":[{"id":"1.195453611","rc":[{"atb":[[15.5,0.54]],"id":41676292}],"con":true,"img":false}]}
{"op":"mcm","clk":"5347914470","pt":1646210324270,"mc":[{"id":"1.195453611","rc":[{"atb":[[1.83,0],[1.9,21.85]],"id":43066529},{"atl":[[3.55,0],[3.5,0],[3.45,0]],"id":43066529}],"con":true,"img":false}]}
{"op":"mcm","clk":"5347914508","pt":1646210326330,"mc":[{"id":"1.195453611","rc":[{"atb":[[2.58,5.47]],"id":43167173}],"con":true,"img":false}]}
{"op":"mcm","clk":"5347914541","pt":1646210327053,"mc":[{"id":"1.195453611","rc":[{"atb":[[2.38,1.6]],"id":43167173}],"con":true,"img":false}]}
{"op":"mcm","clk":"5347914544","pt":1646210327156,"mc":[{"id":"1.195453611","rc":[{"atb":[[2.58,6.78]],"id":43167173}],"con":true,"img":false}]}
{"op":"mcm","clk":"5347914555","pt":1646210327774,"mc":[{"id":"1.195453611","rc":[{"atb":[[2.58,5.47]],"id":43167173}],"con":true,"img":false}]}
{"op":"mcm","clk":"5347914559","pt":1646210327878,"mc":[{"id":"1.195453611","rc":[{"atb":[[1.02,3.3]],"id":43167173}],"con":true,"img":false}]}
{"op":"mcm","clk":"5347914588","pt":1646210328654,"mc":[{"id":"1.195453611","rc":[{"atb":[[1.02,1.99]],"id":43167173}],"con":true,"img":false}]}
{"op":"mcm","clk":"5347914591","pt":1646210328756,"mc":[{"id":"1.195453611","rc":[{"atb":[[2.6,1.31]],"id":43167173}],"con":true,"img":false}]}
{"op":"mcm","clk":"5347914601","pt":1646210329272,"mc":[{"id":"1.195453611","rc":[{"atl":[[38,5.42],[42,2.72]],"id":41676292}],"con":true,"img":false}]}
{"op":"mcm","clk":"5347914609","pt":1646210329733,"mc":[{"id":"1.195453611","rc":[{"atb":[[3.45,3.01]],"id":43167172}],"con":true,"img":false}]}
{"op":"mcm","clk":"5347914635","pt":1646210330660,"mc":[{"id":"1.195453611","rc":[{"atl":[[220,1]],"id":41762566},{"atb":[[7.8,7.35]],"id":42651625},{"atb":[[7,8.33]],"id":41676292},{"atl":[[8,34.91]],"id":43167172}],"con":true,"img":false}]}
{"op":"mcm","clk":"5347914679","pt":1646210331738,"mc":[{"id":"1.195453611","rc":[{"atb":[[2.58,0]],"id":43167173}],"con":true,"img":false}]}
{"op":"mcm","clk":"5347914735","pt":1646210333282,"mc":[{"id":"1.195453611","rc":[{"spn":3.05,"spf":1.0,"id":43066529},{"spn":9.92,"spf":1.0,"id":41676292},{"spn":2.97,"spf":1.0,"id":43167172},{"atb":[[2.6,0]],"id":43167173},{"spn":2.43,"spf":1.0,"id":43167173}],"con":true,"img":false}]}
{"op":"mcm","clk":"5347914738","pt":1646210333384,"mc":[{"id":"1.195453611","rc":[{"atb":[[2.38,2.91]],"id":43167173}],"con":true,"img":false}]}
{"op":"mcm","clk":"5347914747","pt":1646210333647,"mc":[{"id":"1.195453611","rc":[{"atl":[[250,0],[270,0],[290,0.67]],"id":41762566},{"atb":[[6.4,0],[6.8,0],[6,0]],"id":42651625},{"atl":[[11.5,0],[12.5,0],[13.5,0]],"id":43167172}],"con":true,"img":false}]}
{"op":"mcm","clk":"5347914768","pt":1646210334268,"mc":[{"id":"1.195453611","rc":[{"atb":[[1.88,55.86]],"id":43066529}],"con":true,"img":false}]}
{"op":"mcm","clk":"5347914815","pt":1646210335562,"mc":[{"id":"1.195453611","rc":[{"atb":[[2.58,5.47]],"id":43167173}],"con":true,"img":false}]}
{"op":"mcm","clk":"5347914841","pt":1646210336076,"mc":[{"id":"1.195453611","rc":[{"atl":[[3.75,0]],"id":43066529}],"con":true,"img":false}]}
{"op":"mcm","clk":"5347914883","pt":1646210337466,"mc":[{"id":"1.195453611","rc":[{"atb":[[2.38,1.6]],"id":43167173}],"con":true,"img":false}]}
{"op":"mcm","clk":"5347914889","pt":1646210337569,"mc":[{"id":"1.195453611","rc":[{"atb":[[2.58,6.78]],"id":43167173}],"con":true,"img":false}]}
{"op":"mcm","clk":"5347914914","pt":1646210338554,"mc":[{"id":"1.195453611","rc":[{"atb":[[2.58,5.47]],"id":43167173}],"con":true,"img":false}]}
{"op":"mcm","clk":"5347914919","pt":1646210338658,"mc":[{"id":"1.195453611","rc":[{"atb":[[1.02,3.3]],"id":43167173}],"con":true,"img":false}]}
{"op":"mcm","clk":"5347914980","pt":1646210340658,"mc":[{"id":"1.195453611","rc":[{"atl":[[240,1.81]],"id":41762566},{"atb":[[7.4,11.72]],"id":42651625},{"atb":[[6.6,28.69]],"id":41676292},{"atl":[[8.4,10.14]],"id":43167172}],"con":true,"img":false}]}
{"op":"mcm","clk":"5347914986","pt":1646210340864,"mc":[{"id":"1.195453611","rc":[{"atb":[[1.02,1.99]],"id":43167173}],"con":true,"img":false}]}
{"op":"mcm","clk":"5347914988","pt":1646210340967,"mc":[{"id":"1.195453611","rc":[{"atb":[[2.6,1.31]],"id":43167173}],"con":true,"img":false}]}
{"op":"mcm","clk":"5347915066","pt":1646210343079,"mc":[{"id":"1.195453611","rc":[{"atl":[[38,2.7]],"id":41676292}],"con":true,"img":false}]}
{"op":"mcm","clk":"5347915070","pt":1646210343182,"mc":[{"id":"1.195453611","rc":[{"atl":[[34,2.72]],"id":41676292}],"con":true,"img":false}]}
{"op":"mcm","clk":"5347915075","pt":1646210343287,"mc":[{"id":"1.195453611","rc":[{"atb":[[3.45,0]],"id":43167172}],"con":true,"img":false}]}
{"op":"mcm","clk":"5347915079","pt":1646210343388,"mc":[{"id":"1.195453611","rc":[{"atb":[[3.5,3.01]],"id":43167172}],"con":true,"img":false}]}
{"op":"mcm","clk":"5347915092","pt":1646210343695,"mc":[{"id":"1.195453611","rc":[{"atb":[[2.94,1.66]],"id":43066529}],"con":true,"img":false}]}
{"op":"mcm","clk":"5347915099","pt":1646210343799,"mc":[{"id":"1.195453611","rc":[{"atb":[[3.2,34]],"id":43066529}],"con":true,"img":false}]}
{"op":"mcm","clk":"5347915106","pt":1646210343953,"mc":[{"id":"1.195453611","rc":[{"atb":[[1.66,0]],"id":43066529}],"con":true,"img":false}]}
{"op":"mcm","clk":"5347915115","pt":1646210344264,"mc":[{"id":"1.195453611","rc":[{"atb":[[1.86,85.74]],"id":43066529}],"con":true,"img":false}]}
{"op":"mcm","clk":"5347915120","pt":1646210344470,"mc":[{"id":"1.195453611","rc":[{"atl":[[3.55,3.01]],"id":43167172}],"con":true,"img":false}]}
{"op":"mcm","clk":"5347915130","pt":1646210344779,"mc":[{"id":"1.195453611","rc":[{"atb":[[2.58,0]],"id":43167173}],"con":true,"img":false}]}
{"op":"mcm","clk":"5347915158","pt":1646210345295,"mc":[{"id":"1.195453611","rc":[{"atb":[[3.05,0]],"id":43167172}],"con":true,"img":false}]}
{"op":"mcm","clk":"5347915162","pt":1646210345398,"mc":[{"id":"1.195453611","rc":[{"atb":[[1.01,3.49]],"id":43167172}],"con":true,"img":false}]}
{"op":"mcm","clk":"5347915185","pt":1646210345761,"mc":[{"id":"1.195453611","rc":[{"atb":[[3.5,0]],"id":43167172}],"con":true,"img":false}]}
{"op":"mcm","clk":"5347915202","pt":1646210346072,"mc":[{"id":"1.195453611","rc":[{"atl":[[3.55,0]],"id":43167172}],"con":true,"img":false}]}
{"op":"mcm","clk":"5347915244","pt":1646210347101,"mc":[{"id":"1.195453611","rc":[{"atb":[[1.03,1.67],[15.5,0]],"id":41676292},{"atb":[[3.45,3.01]],"id":43167172}],"con":true,"img":false}]}
{"op":"mcm","clk":"5347915253","pt":1646210347259,"mc":[{"id":"1.195453611","rc":[{"atb":[[1.03,0.54]],"id":41676292}],"con":true,"img":false}]}
{"op":"mcm","clk":"5347915257","pt":1646210347358,"mc":[{"id":"1.195453611","rc":[{"atb":[[2.6,0]],"id":43167173}],"con":true,"img":false}]}
{"op":"mcm","clk":"5347915261","pt":1646210347468,"mc":[{"id":"1.195453611","rc":[{"atb":[[1.03,0]],"id":41676292},{"atb":[[2.38,2.91]],"id":43167173}],"con":true,"img":false}]}
{"op":"mcm","clk":"5347915265","pt":1646210347567,"mc":[{"id":"1.195453611","rc":[{"atb":[[15,0.54]],"id":41676292}],"con":true,"img":false}]}
{"op":"mcm","clk":"5347915272","pt":1646210347670,"mc":[{"id":"1.195453611","rc":[{"atb":[[1.02,1.67]],"id":41676292}],"con":true,"img":false}]}
{"op":"mcm","clk":"5347915276","pt":1646210347773,"mc":[{"id":"1.195453611","rc":[{"atb":[[15,0]],"id":41676292}],"con":true,"img":false}]}
{"op":"mcm","clk":"5347915285","pt":1646210347979,"mc":[{"id":"1.195453611","rc":[{"atb":[[1.02,0.51]],"id":41676292}],"con":true,"img":false}]}
{"op":"mcm","clk":"5347915292","pt":1646210348184,"mc":[{"id":"1.195453611","rc":[{"atb":[[1.02,0]],"id":41676292}],"con":true,"img":false}]}
{"op":"mcm","clk":"5347915296","pt":1646210348288,"mc":[{"id":"1.195453611","rc":[{"atb":[[16,0.51]],"id":41676292}],"con":true,"img":false}]}
{"op":"mcm","clk":"5347915304","pt":1646210348493,"mc":[{"id":"1.195453611","rc":[{"atb":[[2.62,4.89]],"id":43167173}],"con":true,"img":false}]}
{"op":"mcm","clk":"5347915383","pt":1646210350503,"mc":[{"id":"1.195453611","rc":[{"atb":[[2.38,1.6]],"id":43167173}],"con":true,"img":false}]}
{"op":"mcm","clk":"5347915387","pt":1646210350559,"mc":[{"id":"1.195453611","rc":[{"atb":[[2.62,6.21]],"id":43167173}],"con":true,"img":false}]}
{"op":"mcm","clk":"5347915390","pt":1646210350660,"mc":[{"id":"1.195453611","rc":[{"atl":[[260,1]],"id":41762566},{"atb":[[7,20.83]],"id":42651625},{"atb":[[6.2,43.27]],"id":41676292},{"atl":[[8.8,16.03]],"id":43167172}],"con":true,"img":false}]}
{"op":"mcm","clk":"5347915395","pt":1646210350760,"mc":[{"id":"1.195453611","rc":[{"atb":[[1.68,0]],"id":43066529}],"con":true,"img":false}]}
{"op":"mcm","clk":"5347915508","pt":1646210354105,"mc":[{"id":"1.195453611","rc":[{"atl":[[3.55,3.81]],"id":43066529}],"con":true,"img":false}]}
{"op":"mcm","clk":"5347915516","pt":1646210354264,"mc":[{"id":"1.195453611","rc":[{"atb":[[1.84,146.3]],"id":43066529}],"con":true,"img":false}]}
{"op":"mcm","clk":"5347915615","pt":1646210357871,"mc":[{"id":"1.195453611","rc":[{"atb":[[3.05,3.01]],"id":43167173}],"con":true,"img":false}]}
{"op":"mcm","clk":"5347915626","pt":1646210358078,"mc":[{"id":"1.195453611","rc":[{"atb":[[1.7,0]],"id":43066529}],"con":true,"img":false}]}
{"op":"mcm","clk":"5347915646","pt":1646210358498,"mc":[{"id":"1.195453611","rc":[{"atb":[[2.8,0]],"id":43167173},{"atl":[[3.75,0]],"id":43167173}],"con":true,"img":false}]}
{"op":"mcm","clk":"5347915682","pt":1646210359213,"mc":[{"id":"1.195453611","rc":[{"atl":[[3.8,0]],"id":43167173}],"con":true,"img":false}]}
{"op":"mcm","clk":"5347915684","pt":1646210359275,"mc":[{"id":"1.195453611","rc":[{"atl":[[1000,1.25]],"id":43167173}],"con":true,"img":false}]}
{"op":"mcm","clk":"5347915716","pt":1646210360194,"mc":[{"id":"1.195453611","rc":[{"atb":[[3.05,0]],"id":43167173}],"con":true,"img":false}]}
{"op":"mcm","clk":"5347915723","pt":1646210360297,"mc":[{"id":"1.195453611","rc":[{"atb":[[3.15,3.01]],"id":43167173}],"con":true,"img":false}]}
{"op":"mcm","clk":"5347915779","pt":1646210361492,"mc":[{"id":"1.195453611","rc":[{"atl":[[3.2,3.01]],"id":43167173}],"con":true,"img":false}]}
{"op":"mcm","clk":"5347915816","pt":1646210362410,"mc":[{"id":"1.195453611","rc":[{"atb":[[2.62,4.89]],"id":43167173}],"con":true,"img":false}]}
{"op":"mcm","clk":"5347915818","pt":1646210362513,"mc":[{"id":"1.195453611","rc":[{"atb":[[1.02,3.3]],"id":43167173}],"con":true,"img":false}]}
{"op":"mcm","clk":"5347915823","pt":1646210362616,"mc":[{"id":"1.195453611","rc":[{"atb":[[3.15,0]],"id":43167173}],"con":true,"img":false}]}
{"op":"mcm","clk":"5347915836","pt":1646210363079,"mc":[{"id":"1.195453611","rc":[{"atl":[[3.2,0]],"id":43167173}],"con":true,"img":false}]}
{"op":"mcm","clk":"5347915845","pt":1646210363387,"mc":[{"id":"1.195453611","rc":[{"atl":[[1000,0]],"id":43167173}],"con":true,"img":false}]}
{"op":"mcm","clk":"5347915849","pt":1646210363490,"mc":[{"id":"1.195453611","rc":[{"atl":[[3.85,1.25]],"id":43167173}],"con":true,"img":false}]}
{"op":"mcm","clk":"5347915852","pt":1646210363593,"mc":[{"id":"1.195453611","rc":[{"atl":[[42,0]],"id":41676292}],"con":true,"img":false}]}
{"op":"mcm","clk":"5347915854","pt":1646210363697,"mc":[{"id":"1.195453611","rc":[{"atl":[[36,4.15]],"id":41676292},{"atb":[[1.02,1.99]],"id":43167173}],"con":true,"img":false}]}
{"op":"mcm","clk":"5347915857","pt":1646210363800,"mc":[{"id":"1.195453611","rc":[{"atb":[[2.62,6.21]],"id":43167173}],"con":true,"img":false}]}
{"op":"mcm","clk":"5347916257","pt":1646210375294,"mc":[{"id":"1.195453611","rc":[{"atb":[[1.05,2.81]],"id":41762566}],"con":true,"img":false}]}
{"op":"mcm","clk":"5347916269","pt":1646210375808,"mc":[{"id":"1.195453611","rc":[{"atb":[[1.05,0.08]],"id":41762566}],"con":true,"img":false}]}
{"op":"mcm","clk":"5347916276","pt":1646210376219,"mc":[{"id":"1.195453611","rc":[{"atb":[[1.05,0]],"id":41762566}],"con":true,"img":false}]}
{"op":"mcm","clk":"5347916280","pt":1646210376322,"mc":[{"id":"1.195453611","rc":[{"atl":[[22,3.38]],"id":41762566},{"trd":[[22,43.23]],"ltp":22.0,"tv":43.23,"id":41762566}],"con":true,"img":false}]}
{"op":"mcm","clk":"5347916294","pt":1646210377096,"mc":[{"id":"1.195453611","rc":[{"atl":[[220,1.24]],"id":42651625},{"atb":[[16,0],[1.02,1.67]],"id":41676292},{"atl":[[30,2.83]],"id":41676292}],"con":true,"img":false}]}
{"op":"mcm","clk":"5347916297","pt":1646210377199,"mc":[{"id":"1.195453611","rc":[{"atl":[[1000,1.24]],"id":43167173}],"con":true,"img":false}]}
{"op":"mcm","clk":"5347916309","pt":1646210377511,"mc":[{"id":"1.195453611","rc":[{"atl":[[1000,0]],"id":43167173}],"con":true,"img":false}]}
{"op":"mcm","clk":"5347916314","pt":1646210377615,"mc":[{"id":"1.195453611","rc":[{"atb":[[1.02,0.51]],"id":41676292},{"atl":[[3.85,2.49]],"id":43167173}],"con":true,"img":false}]}
{"op":"mcm","clk":"5347916319","pt":1646210377822,"mc":[{"id":"1.195453611","rc":[{"atb":[[1.02,0]],"id":41676292}],"con":true,"img":false}]}
{"op":"mcm","clk":"5347916321","pt":1646210377925,"mc":[{"id":"1.195453611","rc":[{"atb":[[15,0.51]],"id":41676292}],"con":true,"img":false}]}
{"op":"mcm","clk":"5347916328","pt":1646210378131,"mc":[{"id":"1.195453611","rc":[{"atb":[[15,0],[1.02,1.67]],"id":41676292}],"con":true,"img":false}]}
{"op":"mcm","clk":"5347916331","pt":1646210378336,"mc":[{"id":"1.195453611","rc":[{"atb":[[1.02,0.5]],"id":41676292}],"con":true,"img":false}]}
{"op":"mcm","clk":"5347916339","pt":1646210378494,"mc":[{"id":"1.195453611","rc":[{"atb":[[1.02,0]],"id":41676292}],"con":true,"img":false}]}
{"op":"mcm","clk":"5347916340","pt":1646210378593,"mc":[{"id":"1.195453611","rc":[{"atb":[[16.5,0.5]],"id":41676292}],"con":true,"img":false}]}
{"op":"mcm","clk":"5347916453","pt":1646210381432,"mc":[{"id":"1.195453611","rc":[{"atb":[[13,0]],"id":41676292}],"con":true,"img":false}]}
{"op":"mcm","clk":"5347916461","pt":1646210381535,"mc":[{"id":"1.195453611","rc":[{"atb":[[12,2.58]],"id":41676292}],"con":true,"img":false}]}
{"op":"mcm","clk":"5347916574","pt":1646210384834,"mc":[{"id":"1.195453611","rc":[{"atl":[[1000,0]],"id":42651625}],"con":true,"img":false}]}
{"op":"mcm","clk":"5347916577","pt":1646210384937,"mc":[{"id":"1.195453611","rc":[{"atl":[[220,2.45]],"id":42651625}],"con":true,"img":false}]}
{"op":"mcm","clk":"5347916854","pt":1646210393921,"mc":[{"id":"1.195453611","rc":[{"atb":[[20,0]],"id":41762566},{"atl":[[20,3.17]],"id":41762566},{"trd":[[20,4.57]],"ltp":20.0,"tv":4.57,"id":41762566},{"spn":14.09,"spf":1.14,"id":41762566},{"spn":3.19,"spf":1.0,"id":43066529},{"spn":9.92,"spf":1.0,"id":41676292},{"spn":2.95,"spf":1.0,"id":43167172},{"spn":2.44,"spf":1.0,"id":43167173}],"con":true,"img":false}]}
{"op":"mcm","clk":"5347916857","pt":1646210394023,"mc":[{"id":"1.195453611","rc":[{"atl":[[20,0]],"id":41762566},{"trd":[[20,10.92]],"ltp":20.0,"tv":10.92,"id":41762566}],"con":true,"img":false}]}
{"op":"mcm","clk":"5347916865","pt":1646210394230,"mc":[{"id":"1.195453611","rc":[{"atb":[[20,2]],"id":41762566}],"con":true,"img":false}]}
{"op":"mcm","clk":"5347916868","pt":1646210394331,"mc":[{"id":"1.195453611","rc":[{"atl":[[3.55,3.71]],"id":43066529},{"trd":[[3.55,0.19]],"ltp":3.55,"tv":0.19,"id":43066529}],"con":true,"img":false}]}
{"op":"mcm","clk":"5347916879","pt":1646210394846,"mc":[{"id":"1.195453611","rc":[{"atb":[[19,0.57]],"id":41762566},{"atb":[[2.96,0]],"id":43066529},{"atb":[[14,0]],"id":41676292},{"atb":[[3.1,10.73]],"id":43167172},{"atb":[[2.46,0]],"id":43167173}],"con":true,"img":false}]}
{"op":"mcm","clk":"5347916881","pt":1646210394949,"mc":[{"id":"1.195453611","rc":[{"atb":[[20,2.08]],"id":41762566},{"atb":[[3.2,34.56]],"id":43066529},{"atb":[[15,0.11]],"id":41676292},{"atb":[[3.5,0.53]],"id":43167172},{"atb":[[2.72,0.67]],"id":43167173}],"con":true,"img":false}]}
{"op":"mcm","clk":"5347916902","pt":1646210395619,"mc":[{"id":"1.195453611","rc":[{"atb":[[3.25,3.38]],"id":43066529}],"con":true,"img":false}]}
{"op":"mcm","clk":"5347916931","pt":1646210396546,"mc":[{"id":"1.195453611","rc":[{"atb":[[3.2,31.7]],"id":43066529}],"con":true,"img":false}]}
{"op":"mcm","clk":"5347917222","pt":1646210404159,"mc":[{"id":"1.195453611","rc":[{"atb":[[11,11.2]],"id":41762566}],"con":true,"img":false}]}
{"op":"mcm","clk":"5347917356","pt":1646210407161,"mc":[{"id":"1.195453611","rc":[{"atb":[[16.5,0],[1.02,1.67]],"id":41676292}],"con":true,"img":false}]}
{"op":"mcm","clk":"5347917367","pt":1646210407319,"mc":[{"id":"1.195453611","rc":[{"atb":[[1.02,0.5]],"id":41676292}],"con":true,"img":false}]}
{"op":"mcm","clk":"5347917375","pt":1646210407630,"mc":[{"id":"1.195453611","rc":[{"atb":[[1.02,0]],"id":41676292}],"con":true,"img":false}]}
{"op":"mcm","clk":"5347917379","pt":1646210407734,"mc":[{"id":"1.195453611","rc":[{"atb":[[15.5,0.5]],"id":41676292}],"con":true,"img":false}]}
{"op":"mcm","clk":"5347917419","pt":1646210408964,"mc":[{"id":"1.195453611","rc":[{"atb":[[3.25,1.02]],"id":43066529},{"trd":[[3.25,24.37]],"ltp":3.25,"tv":24.37,"id":43066529}],"con":true,"img":false}]}
{"op":"mcm","clk":"5347917649","pt":1646210416594,"mc":[{"id":"1.195453611","rc":[{"atl":[[230,4]],"id":42651625}],"con":true,"img":false}]}
{"op":"mcm","clk":"5347917659","pt":1646210416749,"mc":[{"id":"1.195453611","rc":[{"atl":[[210,2.72]],"id":42651625}],"con":true,"img":false}]}
{"op":"mcm","clk":"5347917663","pt":1646210416852,"mc":[{"id":"1.195453611","rc":[{"atl":[[210,6.72],[230,0]],"id":42651625}],"con":true,"img":false}]}
{"op":"mcm","clk":"5347917673","pt":1646210417063,"mc":[{"id":"1.195453611","rc":[{"atl":[[5.4,0]],"id":43066529}],"con":true,"img":false}]}
{"op":"mcm","clk":"5347917676","pt":1646210417166,"mc":[{"id":"1.195453611","rc":[{"atl":[[5.6,24.56]],"id":43066529}],"con":true,"img":false}]}
{"op":"mcm","clk":"5347917846","pt":1646210424139,"mc":[{"id":"1.195453611","rc":[{"atl":[[4.1,0]],"id":43167173}],"con":true,"img":false}]}
{"op":"mcm","clk":"5347917854","pt":1646210424243,"mc":[{"id":"1.195453611","rc":[{"atl":[[4.3,19.84]],"id":43167173}],"con":true,"img":false}]}
{"op":"mcm","clk":"5347917919","pt":1646210426554,"mc":[{"id":"1.195453611","rc":[{"atl":[[4.2,0]],"id":43066529}],"con":true,"img":false}]}
{"op":"mcm","clk":"5347917924","pt":1646210426656,"mc":[{"id":"1.195453611","rc":[{"atl":[[5,6.76]],"id":43066529}],"con":true,"img":false}]}
{"op":"mcm","clk":"5347918304","pt":1646210436050,"mc":[{"id":"1.195453611","rc":[{"atl":[[3.6,0]],"id":43066529}],"con":true,"img":false}]}
{"op":"mcm","clk":"5347918310","pt":1646210436156,"mc":[{"id":"1.195453611","rc":[{"atl":[[4.7,2.31]],"id":43066529}],"con":true,"img":false}]}
{"op":"mcm","clk":"5347918377","pt":1646210438167,"mc":[{"id":"1.195453611","rc":[{"atl":[[3.55,0]],"id":43066529}],"con":true,"img":false}]}
{"op":"mcm","clk":"5347918380","pt":1646210438269,"mc":[{"id":"1.195453611","rc":[{"atb":[[2.04,2]],"id":43066529},{"atl":[[5.3,4.65],[5.1,0]],"id":43066529}],"con":true,"img":false}]}
{"op":"mcm","clk":"5347918386","pt":1646210438374,"mc":[{"id":"1.195453611","rc":[{"atl":[[4.6,2.86]],"id":43066529}],"con":true,"img":false}]}
{"op":"mcm","clk":"5347918389","pt":1646210438475,"mc":[{"id":"1.195453611","rc":[{"atb":[[3.25,3.97]],"id":43066529}],"con":true,"img":false}]}
{"op":"mcm","clk":"5347918402","pt":1646210438683,"mc":[{"id":"1.195453611","rc":[{"atl":[[4.6,9.41]],"id":43066529}],"con":true,"img":false}]}
{"op":"mcm","clk":"5347918414","pt":1646210438892,"mc":[{"id":"1.195453611","rc":[{"atl":[[1000,0]],"id":43066529}],"con":true,"img":false}]}
{"op":"mcm","clk":"5347918420","pt":1646210438950,"mc":[{"id":"1.195453611","rc":[{"atl":[[4.5,1.32]],"id":43066529}],"con":true,"img":false}]}
{"op":"mcm","clk":"5347918425","pt":1646210439155,"mc":[{"id":"1.195453611","rc":[{"atl":[[4.7,0]],"id":43066529}],"con":true,"img":false}]}
{"op":"mcm","clk":"5347918431","pt":1646210439262,"mc":[{"id":"1.195453611","rc":[{"atl":[[4.5,3.75]],"id":43066529}],"con":true,"img":false}]}
{"op":"mcm","clk":"5347918444","pt":1646210439565,"mc":[{"id":"1.195453611","rc":[{"atb":[[1.01,3.41]],"id":43066529}],"con":true,"img":false}]}
{"op":"mcm","clk":"5347918448","pt":1646210439669,"mc":[{"id":"1.195453611","rc":[{"atb":[[3.25,5.31]],"id":43066529}],"con":true,"img":false}]}
{"op":"mcm","clk":"5347918493","pt":1646210440859,"mc":[{"id":"1.195453611","rc":[{"atl":[[1000,1.24]],"id":43066529}],"con":true,"img":false}]}
{"op":"mcm","clk":"5347918501","pt":1646210441067,"mc":[{"id":"1.195453611","rc":[{"atl":[[1000,0]],"id":43066529}],"con":true,"img":false}]}
{"op":"mcm","clk":"5347918504","pt":1646210441169,"mc":[{"id":"1.195453611","rc":[{"atl":[[4.4,1.24]],"id":43066529},{"atb":[[2.62,1.31]],"id":43167173}],"con":true,"img":false}]}
{"op":"mcm","clk":"5347918531","pt":1646210441792,"mc":[{"id":"1.195453611","rc":[{"atb":[[2.62,0]],"id":43167173}],"con":true,"img":false}]}
{"op":"mcm","clk":"5347918536","pt":1646210441897,"mc":[{"id":"1.195453611","rc":[{"atb":[[2.38,2.91]],"id":43167173}],"con":true,"img":false}]}
{"op":"mcm","clk":"5347918546","pt":1646210442077,"mc":[{"id":"1.195453611","rc":[{"atb":[[2.06,3]],"id":43066529},{"atl":[[3.85,9.51],[3.9,0]],"id":43167173}],"con":true,"img":false}]}
{"op":"mcm","clk":"5347918655","pt":1646210444491,"mc":[{"id":"1.195453611","rc":[{"atl":[[3.85,12.81]],"id":43167173}],"con":true,"img":false}]}
{"op":"mcm","clk":"5347918666","pt":1646210444998,"mc":[{"id":"1.195453611","rc":[{"atb":[[2.4,6.24]],"id":43167173}],"con":true,"img":false}]}
{"op":"mcm","clk":"5347918680","pt":1646210445469,"mc":[{"id":"1.195453611","rc":[{"atb":[[2.38,1.6]],"id":43167173}],"con":true,"img":false}]}
{"op":"mcm","clk":"5347918685","pt":1646210445565,"mc":[{"id":"1.195453611","rc":[{"atb":[[2.4,7.55]],"id":43167173}],"con":true,"img":false}]}
{"op":"mcm","clk":"5347918762","pt":1646210448291,"mc":[{"id":"1.195453611","rc":[{"atl":[[5.5,27.78]],"id":43066529}],"con":true,"img":false}]}
{"op":"mcm","clk":"5347918764","pt":1646210448393,"mc":[{"id":"1.195453611","rc":[{"atl":[[5.5,11.1]],"id":43066529}],"con":true,"img":false}]}
{"op":"mcm","clk":"5347918852","pt":1646210451169,"mc":[{"id":"1.195453611","rc":[{"atl":[[4.6,2.86]],"id":43066529}],"con":true,"img":false}]}
{"op":"mcm","clk":"5347918896","pt":1646210452095,"mc":[{"id":"1.195453611","rc":[{"atb":[[2.08,3]],"id":43066529}],"con":true,"img":false}]}
{"op":"mcm","clk":"5347919006","pt":1646210455707,"mc":[{"id":"1.195453611","rc":[{"spn":14.58,"spf":1.14,"id":41762566},{"spn":3.2,"spf":1.0,"id":43066529},{"atl":[[210,4]],"id":42651625},{"spn":9.91,"spf":1.0,"id":41676292},{"spn":2.96,"spf":1.0,"id":43167172},{"spn":2.41,"spf":1.0,"id":43167173}],"con":true,"img":false}]}
{"op":"mcm","clk":"5347919009","pt":1646210455809,"mc":[{"id":"1.195453611","rc":[{"atl":[[200,2.72]],"id":42651625}],"con":true,"img":false}]}
{"op":"mcm","clk":"5347919025","pt":1646210456173,"mc":[{"id":"1.195453611","rc":[{"atl":[[4.6,0]],"id":43066529}],"con":true,"img":false}]}
{"op":"mcm","clk":"5347919031","pt":1646210456277,"mc":[{"id":"1.195453611","rc":[{"atl":[[4.3,3.06]],"id":43066529},{"atl":[[220,1.24]],"id":42651625}],"con":true,"img":false}]}
{"op":"mcm","clk":"5347919035","pt":1646210456377,"mc":[{"id":"1.195453611","rc":[{"atl":[[190,1.21]],"id":42651625}],"con":true,"img":false}]}
{"op":"mcm","clk":"5347919041","pt":1646210456480,"mc":[{"id":"1.195453611","rc":[{"atl":[[190,5.21],[210,0]],"id":42651625}],"con":true,"img":false}]}
{"op":"mcm","clk":"5347919047","pt":1646210456584,"mc":[{"id":"1.195453611","rc":[{"atb":[[3.25,3.97]],"id":43066529}],"con":true,"img":false}]}
{"op":"mcm","clk":"5347919051","pt":1646210456692,"mc":[{"id":"1.195453611","rc":[{"atb":[[1.01,4.76]],"id":43066529}],"con":true,"img":false}]}
{"op":"mcm","clk":"5347919059","pt":1646210456887,"mc":[{"id":"1.195453611","rc":[{"atl":[[4.5,2.42]],"id":43066529}],"con":true,"img":false}]}
{"op":"mcm","clk":"5347919065","pt":1646210456991,"mc":[{"id":"1.195453611","rc":[{"atl":[[4.2,1.32]],"id":43066529},{"atl":[[220,0]],"id":42651625}],"con":true,"img":false}]}
{"op":"mcm","clk":"5347919073","pt":1646210457093,"mc":[{"id":"1.195453611","rc":[{"atl":[[4.5,0]],"id":43066529}],"con":true,"img":false}]}
{"op":"mcm","clk":"5347919080","pt":1646210457196,"mc":[{"id":"1.195453611","rc":[{"atl":[[4.2,3.92]],"id":43066529}],"con":true,"img":false}]}
{"op":"mcm","clk":"5347919129","pt":1646210458309,"mc":[{"id":"1.195453611","rc":[{"atl":[[5.7,15.96]],"id":43066529}],"con":true,"img":false}]}
{"op":"mcm","clk":"5347919193","pt":1646210460294,"mc":[{"id":"1.195453611","rc":[{"atb":[[20,2.3]],"id":41762566}],"con":true,"img":false}]}
{"op":"mcm","clk":"5347919200","pt":1646210460503,"mc":[{"id":"1.195453611","rc":[{"atl":[[1000,2]],"id":43066529},{"atl":[[1000,2]],"id":42651625},{"atl":[[1000,2]],"id":41676292},{"atl":[[1000,2]],"id":43167172},{"atl":[[1000,2]],"id":43167173}],"con":true,"img":false}]}
{"op":"mcm","clk":"5347919213","pt":1646210460696,"mc":[{"id":"1.195453611","rc":[{"atl":[[1000,1]],"id":43066529},{"atl":[[1000,1]],"id":42651625},{"atl":[[1000,1]],"id":41676292},{"atl":[[1000,1]],"id":43167172},{"atl":[[1000,1]],"id":43167173}],"con":true,"img":false}]}
{"op":"mcm","clk":"5347919228","pt":1646210460903,"mc":[{"id":"1.195453611","rc":[{"atl":[[1000,0]],"id":43066529},{"atl":[[1000,0]],"id":42651625},{"atl":[[1000,0]],"id":41676292},{"atl":[[1000,0]],"id":43167172},{"atl":[[1000,0]],"id":43167173}],"con":true,"img":false}]}
{"op":"mcm","clk":"5347919232","pt":1646210461012,"mc":[{"id":"1.195453611","rc":[{"atl":[[4.1,1]],"id":43066529},{"atl":[[180,1.39]],"id":42651625},{"atl":[[29,1]],"id":41676292},{"atl":[[3.95,1]],"id":43167172},{"atl":[[3.8,1]],"id":43167173}],"con":true,"img":false}]}
{"op":"mcm","clk":"5347919245","pt":1646210461211,"mc":[{"id":"1.195453611","rc":[{"atb":[[2.04,0],[2.08,0],[2.06,0]],"id":43066529},{"atl":[[5.1,4.88]],"id":43066529}],"con":true,"img":false}]}
{"op":"mcm","clk":"5347919254","pt":1646210461522,"mc":[{"id":"1.195453611","rc":[{"atb":[[1.01,1]],"id":41762566}],"con":true,"img":false}]}
{"op":"mcm","clk":"5347919276","pt":1646210462097,"mc":[{"id":"1.195453611","rc":[{"atb":[[3.3,1]],"id":43066529},{"atb":[[3.5,1.53]],"id":43167172},{"atb":[[2.72,1.67]],"id":43167173}],"con":true,"img":false}]}
{"op":"mcm","clk":"5347919295","pt":1646210462605,"mc":[{"id":"1.195453611","rc":[{"atl":[[3.85,9.51]],"id":43167173}],"con":true,"img":false}]}
{"op":"mcm","clk":"5347919300","pt":1646210462811,"mc":[{"id":"1.195453611","rc":[{"atb":[[3.25,0]],"id":43066529}],"con":true,"img":false}]}
{"op":"mcm","clk":"5347919314","pt":1646210463233,"mc":[{"id":"1.195453611","rc":[{"atb":[[3.3,0]],"id":43066529}],"con":true,"img":false}]}
{"op":"mcm","clk":"5347919322","pt":1646210463285,"mc":[{"id":"1.195453611","rc":[{"atb":[[3.25,1]],"id":43066529}],"con":true,"img":false}]}
{"op":"mcm","clk":"5347919364","pt":1646210464105,"mc":[{"id":"1.195453611","rc":[{"atl":[[5.4,6.06],[5,0]],"id":43066529}],"con":true,"img":false}]}
{"op":"mcm","clk":"5347919393","pt":1646210465194,"mc":[{"id":"1.195453611","rc":[{"atb":[[1.05,2.81]],"id":41762566}],"con":true,"img":false}]}
{"op":"mcm","clk":"5347919409","pt":1646210465699,"mc":[{"id":"1.195453611","rc":[{"atb":[[1.05,0.08]],"id":41762566}],"con":true,"img":false}]}
{"op":"mcm","clk":"5347919422","pt":1646210466113,"mc":[{"id":"1.195453611","rc":[{"atb":[[1.05,0]],"id":41762566},{"atb":[[3.55,3.01]],"id":43167172}],"con":true,"img":false}]}
{"op":"mcm","clk":"5347919428","pt":1646210466216,"mc":[{"id":"1.195453611","rc":[{"atl":[[22,3.29]],"id":41762566},{"trd":[[22,43.41]],"ltp":22.0,"tv":43.41,"id":41762566}],"con":true,"img":false}]}
{"op":"mcm","clk":"5347919431","pt":1646210466321,"mc":[{"id":"1.195453611","rc":[{"atl":[[22,0]],"id":41762566},{"trd":[[22,49.99]],"ltp":22.0,"tv":49.99,"id":41762566},{"atb":[[3.45,3.97]],"id":43167172}],"con":true,"img":false}]}
{"op":"mcm","clk":"5347919434","pt":1646210466526,"mc":[{"id":"1.195453611","rc":[{"atl":[[1000,2]],"id":41762566}],"con":true,"img":false}]}
{"op":"mcm","clk":"5347919439","pt":1646210466731,"mc":[{"id":"1.195453611","rc":[{"atl":[[55,8.29],[1000,1]],"id":41762566}],"con":true,"img":false}]}
{"op":"mcm","clk":"5347919446","pt":1646210466836,"mc":[{"id":"1.195453611","rc":[{"atl":[[1000,0]],"id":41762566}],"con":true,"img":false}]}
{"op":"mcm","clk":"5347919448","pt":1646210466896,"mc":[{"id":"1.195453611","rc":[{"atl":[[50,1]],"id":41762566}],"con":true,"img":false}]}
{"op":"mcm","clk":"5347919452","pt":1646210466995,"mc":[{"id":"1.195453611","rc":[{"atl":[[50,2.46]],"id":41762566}],"con":true,"img":false}]}
{"op":"mcm","clk":"5347919455","pt":1646210467100,"mc":[{"id":"1.195453611","rc":[{"atb":[[3.5,0.53]],"id":43167172}],"con":true,"img":false}]}
{"op":"mcm","clk":"5347919459","pt":1646210467201,"mc":[{"id":"1.195453611","rc":[{"atl":[[3.6,2]],"id":43167172},{"trd":[[3.6,2]],"ltp":3.6,"tv":2.0,"id":43167172}],"con":true,"img":false}]}
{"op":"mcm","clk":"5347919464","pt":1646210467299,"mc":[{"id":"1.195453611","rc":[{"atl":[[3.6,0]],"id":43167172},{"trd":[[3.6,6.02]],"ltp":3.6,"tv":6.02,"id":43167172}],"con":true,"img":false}]}
{"op":"mcm","clk":"5347919472","pt":1646210467504,"mc":[{"id":"1.195453611","rc":[{"atl":[[3.95,0]],"id":43167172}],"con":true,"img":false}]}
{"op":"mcm","clk":"5347919485","pt":1646210468018,"mc":[{"id":"1.195453611","rc":[{"atl":[[4.3,0]],"id":43066529}],"con":true,"img":false}]}
{"op":"mcm","clk":"5347919488","pt":1646210468121,"mc":[{"id":"1.195453611","rc":[{"atl":[[3.95,1]],"id":43167172}],"con":true,"img":false}]}
{"op":"mcm","clk":"5347919491","pt":1646210468224,"mc":[{"id":"1.195453611","rc":[{"atl":[[4.1,4.21]],"id":43066529},{"atl":[[1000,2],[3.95,4.38]],"id":43167172}],"con":true,"img":false}]}
{"op":"mcm","clk":"5347919503","pt":1646210468487,"mc":[{"id":"1.195453611","rc":[{"atb":[[3.5,0.46]],"id":43167172},{"atl":[[1000,1]],"id":43167172}],"con":true,"img":false}]}
{"op":"mcm","clk":"5347919507","pt":1646210468589,"mc":[{"id":"1.195453611","rc":[{"atb":[[3.25,3.89]],"id":43066529}],"con":true,"img":false}]}
{"op":"mcm","clk":"5347919514","pt":1646210468692,"mc":[{"id":"1.195453611","rc":[{"atb":[[3.2,31.14]],"id":43066529},{"atb":[[3.5,0]],"id":43167172},{"atl":[[1000,0]],"id":43167172}],"con":true,"img":false}]}
{"op":"mcm","clk":"5347919517","pt":1646210468797,"mc":[{"id":"1.195453611","rc":[{"atb":[[3.3,0.55]],"id":43066529},{"atb":[[3.6,0.46]],"id":43167172},{"atl":[[3.95,5.38]],"id":43167172}],"con":true,"img":false}]}
{"op":"mcm","clk":"5347919525","pt":1646210468998,"mc":[{"id":"1.195453611","rc":[{"atb":[[3.55,0]],"id":43167172}],"con":true,"img":false}]}
{"op":"mcm","clk":"5347919526","pt":1646210469103,"mc":[{"id":"1.195453611","rc":[{"atb":[[3.6,3.47]],"id":43167172}],"con":true,"img":false}]}
{"op":"mcm","clk":"5347919563","pt":1646210470132,"mc":[{"id":"1.195453611","rc":[{"atl":[[4.2,1.32]],"id":43066529}],"con":true,"img":false}]}
{"op":"mcm","clk":"5347919568","pt":1646210470227,"mc":[{"id":"1.195453611","rc":[{"atl":[[3.65,3.01]],"id":43167172}],"con":true,"img":false}]}
{"op":"mcm","clk":"5347919573","pt":1646210470330,"mc":[{"id":"1.195453611","rc":[{"atl":[[4,2.72]],"id":43066529},{"atb":[[3.6,0]],"id":43167172},{"trd":[[3.6,12.97]],"ltp":3.6,"tv":12.97,"id":43167172}],"con":true,"img":false}]}
{"op":"mcm","clk":"5347919577","pt":1646210470386,"mc":[{"id":"1.195453611","rc":[{"atl":[[3.6,2]],"id":43167172}],"con":true,"img":false}]}
{"op":"mcm","clk":"5347919581","pt":1646210470491,"mc":[{"id":"1.195453611","rc":[{"atl":[[3.95,4.38]],"id":43167172}],"con":true,"img":false}]}
{"op":"mcm","clk":"5347919587","pt":1646210470594,"mc":[{"id":"1.195453611","rc":[{"atb":[[3.45,3.01]],"id":43167172}],"con":true,"img":false}]}
{"op":"mcm","clk":"5347919599","pt":1646210470898,"mc":[{"id":"1.195453611","rc":[{"atl":[[4.1,3.21]],"id":43066529},{"atb":[[2.4,1.31]],"id":43167173}],"con":true,"img":false}]}
{"op":"mcm","clk":"5347919602","pt":1646210471002,"mc":[{"id":"1.195453611","rc":[{"atl":[[3.95,1]],"id":43066529}],"con":true,"img":false}]}
{"op":"mcm","clk":"5347919604","pt":1646210471105,"mc":[{"id":"1.195453611","rc":[{"atb":[[3.3,1.32]],"id":43066529},{"atl":[[3.95,1.66]],"id":43066529},{"atl":[[3.95,3.38]],"id":43167172}],"con":true,"img":false}]}
{"op":"mcm","clk":"5347919606","pt":1646210471209,"mc":[{"id":"1.195453611","rc":[{"atl":[[3.55,1]],"id":43167172}],"con":true,"img":false}]}
{"op":"mcm","clk":"5347919611","pt":1646210471306,"mc":[{"id":"1.195453611","rc":[{"atb":[[10.5,0],[13,8.77]],"id":41762566},{"atb":[[1.7,0],[1.77,105.53]],"id":43167172},{"atl":[[3.65,3.94]],"id":43167172},{"atl":[[3.85,2.49],[3.9,6.9]],"id":43167173}],"con":true,"img":false}]}
{"op":"mcm","clk":"5347919627","pt":1646210471723,"mc":[{"id":"1.195453611","rc":[{"atb":[[2.4,0]],"id":43167173}],"con":true,"img":false}]}
{"op":"mcm","clk":"5347919630","pt":1646210471826,"mc":[{"id":"1.195453611","rc":[{"atb":[[2.38,2.91]],"id":43167173}],"con":true,"img":false}]}
{"op":"mcm","clk":"5347919631","pt":1646210471989,"mc":[{"id":"1.195453611","rc":[{"atl":[[3.65,0.93]],"id":43167172}],"con":true,"img":false}]}
{"op":"mcm","clk":"5347919635","pt":1646210472091,"mc":[{"id":"1.195453611","rc":[{"atl":[[5.3,11.63]],"id":43066529}],"con":true,"img":false}]}
{"op":"mcm","clk":"5347919657","pt":1646210472808,"mc":[{"id":"1.195453611","rc":[{"atl":[[48,1.24]],"id":41762566},{"atl":[[4.4,0]],"id":43066529}],"con":true,"img":false}]}
{"op":"mcm","clk":"5347919660","pt":1646210472911,"mc":[{"id":"1.195453611","rc":[{"atl":[[48,1.35]],"id":41762566},{"atl":[[180,2.63]],"id":42651625}],"con":true,"img":false}]}
{"op":"mcm","clk":"5347919695","pt":1646210473727,"mc":[{"id":"1.195453611","rc":[{"atl":[[190,4]],"id":42651625}],"con":true,"img":false}]}
{"op":"mcm","clk":"5347919700","pt":1646210473830,"mc":[{"id":"1.195453611","rc":[{"atl":[[170,1.21]],"id":42651625}],"con":true,"img":false}]}
{"op":"mcm","clk":"5347919704","pt":1646210473934,"mc":[{"id":"1.195453611","rc":[{"atl":[[170,5.21],[190,0]],"id":42651625}],"con":true,"img":false}]}
{"op":"mcm","clk":"5347919710","pt":1646210474036,"mc":[{"id":"1.195453611","rc":[{"atl":[[170,3.21]],"id":42651625}],"con":true,"img":false}]}
{"op":"mcm","clk":"5347919718","pt":1646210474197,"mc":[{"id":"1.195453611","rc":[{"atl":[[170,5.21],[180,1.63]],"id":42651625}],"con":true,"img":false}]}
{"op":"mcm","clk":"5347919720","pt":1646210474298,"mc":[{"id":"1.195453611","rc":[{"atl":[[160,1]],"id":42651625}],"con":true,"img":false}]}
{"op":"mcm","clk":"5347919728","pt":1646210474604,"mc":[{"id":"1.195453611","rc":[{"atl":[[200,0]],"id":42651625}],"con":true,"img":false}]}
{"op":"mcm","clk":"5347919733","pt":1646210474709,"mc":[{"id":"1.195453611","rc":[{"atl":[[230,2.72]],"id":42651625},{"atb":[[2.48,7.06]],"id":43167173}],"con":true,"img":false}]}
{"op":"mcm","clk":"5347919757","pt":1646210475426,"mc":[{"id":"1.195453611","rc":[{"atb":[[2.98,16.37]],"id":43066529},{"atb":[[2.2,16.37]],"id":43167173}],"con":true,"img":false}]}
{"op":"mcm","clk":"5347919761","pt":1646210475527,"mc":[{"id":"1.195453611","rc":[{"atb":[[16,16.37]],"id":41762566},{"atb":[[26,18.08]],"id":42651625},{"atb":[[11.5,26.31]],"id":41676292},{"atb":[[2.14,82.16]],"id":43167172}],"con":true,"img":false}]}
{"op":"mcm","clk":"5347919771","pt":1646210475732,"mc":[{"id":"1.195453611","rc":[{"atl":[[3.95,0]],"id":43167172}],"con":true,"img":false}]}
{"op":"mcm","clk":"5347919788","pt":1646210476301,"mc":[{"id":"1.195453611","rc":[{"atb":[[2.38,1.6]],"id":43167173}],"con":true,"img":false}]}
{"op":"mcm","clk":"5347919791","pt":1646210476405,"mc":[{"id":"1.195453611","rc":[{"atb":[[2.5,1.31]],"id":43167173}],"con":true,"img":false}]}
{"op":"mcm","clk":"5347919797","pt":1646210476506,"mc":[{"id":"1.195453611","rc":[{"atl":[[3.95,6.78],[3.9,0]],"id":43167173}],"con":true,"img":false}]}
{"op":"mcm","clk":"5347919821","pt":1646210477224,"mc":[{"id":"1.195453611","rc":[{"atl":[[3.85,1.24]],"id":43167173}],"con":true,"img":false}]}
{"op":"mcm","clk":"5347919825","pt":1646210477328,"mc":[{"id":"1.195453611","rc":[{"atl":[[3.9,1.25]],"id":43167173}],"con":true,"img":false}]}
{"op":"mcm","clk":"5347919831","pt":1646210477534,"mc":[{"id":"1.195453611","rc":[{"atl":[[3.8,0]],"id":43167173}],"con":true,"img":false}]}
{"op":"mcm","clk":"5347919834","pt":1646210477636,"mc":[{"id":"1.195453611","rc":[{"atl":[[3.9,2.25]],"id":43167173}],"con":true,"img":false}]}
{"op":"mcm","clk":"5347919922","pt":1646210480115,"mc":[{"id":"1.195453611","rc":[{"atl":[[3.9,3.38]],"id":43066529},{"atb":[[2.48,0]],"id":43167173}],"con":true,"img":false}]}
{"op":"mcm","clk":"5347919924","pt":1646210480221,"mc":[{"id":"1.195453611","rc":[{"atl":[[3.9,4.01]],"id":43066529}],"con":true,"img":false}]}
{"op":"mcm","clk":"5347919929","pt":1646210480420,"mc":[{"id":"1.195453611","rc":[{"atb":[[2.98,32.75]],"id":43066529},{"atl":[[3.95,0.66]],"id":43066529}],"con":true,"img":false}]}
{"op":"mcm","clk":"5347919934","pt":1646210480524,"mc":[{"id":"1.195453611","rc":[{"atl":[[3.85,1]],"id":43066529},{"atb":[[11.5,39.95]],"id":41676292},{"atb":[[2.14,98.54]],"id":43167172},{"atb":[[2.2,32.75]],"id":43167173}],"con":true,"img":false}]}
{"op":"mcm","clk":"5347919938","pt":1646210480628,"mc":[{"id":"1.195453611","rc":[{"atl":[[3.85,1.64]],"id":43066529}],"con":true,"img":false}]}
{"op":"mcm","clk":"5347919949","pt":1646210480936,"mc":[{"id":"1.195453611","rc":[{"atb":[[2.5,0]],"id":43167173}],"con":true,"img":false}]}
{"op":"mcm","clk":"5347919952","pt":1646210481040,"mc":[{"id":"1.195453611","rc":[{"atb":[[2.38,2.91]],"id":43167173}],"con":true,"img":false}]}
{"op":"mcm","clk":"5347919956","pt":1646210481142,"mc":[{"id":"1.195453611","rc":[{"atl":[[4,0],[4.1,0]],"id":43066529}],"con":true,"img":false}]}
{"op":"mcm","clk":"5347919958","pt":1646210481197,"mc":[{"id":"1.195453611","rc":[{"atl":[[3.85,4.46]],"id":43066529}],"con":true,"img":false}]}
{"op":"mcm","clk":"5347919962","pt":1646210481302,"mc":[{"id":"1.195453611","rc":[{"atb":[[1.01,5.75]],"id":43167172}],"con":true,"img":false}]}
{"op":"mcm","clk":"5347919966","pt":1646210481403,"mc":[{"id":"1.195453611","rc":[{"atb":[[3.25,1]],"id":43066529},{"atb":[[12,3.9]],"id":41676292}],"con":true,"img":false}]}
{"op":"mcm","clk":"5347919972","pt":1646210481510,"mc":[{"id":"1.195453611","rc":[{"atb":[[1.02,1.67]],"id":41676292}],"con":true,"img":false}]}
{"op":"mcm","clk":"5347919978","pt":1646210481609,"mc":[{"id":"1.195453611","rc":[{"atb":[[15.5,0]],"id":41676292}],"con":true,"img":false}]}
{"op":"mcm","clk":"5347919982","pt":1646210481713,"mc":[{"id":"1.195453611","rc":[{"atb":[[1.02,0.5]],"id":41676292}],"con":true,"img":false}]}
{"op":"mcm","clk":"5347919985","pt":1646210481813,"mc":[{"id":"1.195453611","rc":[{"atb":[[1.01,5]],"id":43167172}],"con":true,"img":false}]}
{"op":"mcm","clk":"5347919988","pt":1646210481915,"mc":[{"id":"1.195453611","rc":[{"atb":[[1.02,0]],"id":41676292}],"con":true,"img":false}]}
{"op":"mcm","clk":"5347919990","pt":1646210482020,"mc":[{"id":"1.195453611","rc":[{"atb":[[12.5,0.5]],"id":41676292}],"con":true,"img":false}]}
{"op":"mcm","clk":"5347920008","pt":1646210482425,"mc":[{"id":"1.195453611","rc":[{"atb":[[1.01,3.49]],"id":43167172}],"con":true,"img":false}]}
{"op":"mcm","clk":"5347920013","pt":1646210482527,"mc":[{"id":"1.195453611","rc":[{"atl":[[3.6,1.5],[3.55,0]],"id":43167172},{"trd":[[3.6,13.98],[3.55,2]],"ltp":3.6,"tv":15.98,"id":43167172}],"con":true,"img":false}]}
{"op":"mcm","clk":"5347920019","pt":1646210482732,"mc":[{"id":"1.195453611","rc":[{"atl":[[1000,2]],"id":43167172}],"con":true,"img":false}]}
{"op":"mcm","clk":"5347920024","pt":1646210482939,"mc":[{"id":"1.195453611","rc":[{"atl":[[5.5,16.67]],"id":43066529},{"atl":[[1000,1],[3.65,0]],"id":43167172}],"con":true,"img":false}]}
{"op":"mcm","clk":"5347920030","pt":1646210483147,"mc":[{"id":"1.195453611","rc":[{"atl":[[1000,0]],"id":43167172}],"con":true,"img":false}]}
{"op":"mcm","clk":"5347920037","pt":1646210483210,"mc":[{"id":"1.195453611","rc":[{"atl":[[3.95,1]],"id":43167172}],"con":true,"img":false}]}
{"op":"mcm","clk":"5347920063","pt":1646210483920,"mc":[{"id":"1.195453611","rc":[{"atb":[[2.52,6.32]],"id":43167173}],"con":true,"img":false}]}
{"op":"mcm","clk":"5347920081","pt":1646210484536,"mc":[{"id":"1.195453611","rc":[{"atb":[[1.01,5.75]],"id":43167172},{"atb":[[2.38,1.6]],"id":43167173}],"con":true,"img":false}]}
{"op":"mcm","clk":"5347920085","pt":1646210484638,"mc":[{"id":"1.195453611","rc":[{"atb":[[2.52,7.63]],"id":43167173}],"con":true,"img":false}]}
{"op":"mcm","clk":"5347920097","pt":1646210485106,"mc":[{"id":"1.195453611","rc":[{"atb":[[1.01,5]],"id":43167172}],"con":true,"img":false}]}
{"op":"mcm","clk":"5347920124","pt":1646210485724,"mc":[{"id":"1.195453611","rc":[{"atb":[[1.01,3.49]],"id":43167172}],"con":true,"img":false}]}
{"op":"mcm","clk":"5347920127","pt":1646210485823,"mc":[{"id":"1.195453611","rc":[{"atb":[[3.6,0]],"id":43167172},{"atl":[[3.6,0]],"id":43167172},{"trd":[[3.6,16.97]],"ltp":3.6,"tv":16.97,"id":43167172}],"con":true,"img":false}]}
{"op":"mcm","clk":"5347920133","pt":1646210485925,"mc":[{"id":"1.195453611","rc":[{"atb":[[3.6,0]],"id":43167172},{"trd":[[3.6,16.99]],"ltp":3.6,"tv":16.99,"id":43167172}],"con":true,"img":false}]}
{"op":"mcm","clk":"5347920150","pt":1646210486235,"mc":[{"id":"1.195453611","rc":[{"atb":[[3.5,1]],"id":43167172}],"con":true,"img":false}]}
{"op":"mcm","clk":"5347920195","pt":1646210487117,"mc":[{"id":"1.195453611","rc":[{"atl":[[3.9,3.38]],"id":43167172}],"con":true,"img":false}]}
{"op":"mcm","clk":"5347920198","pt":1646210487218,"mc":[{"id":"1.195453611","rc":[{"atl":[[3.9,4.02]],"id":43167172},{"atl":[[4.1,16.13]],"id":43167173}],"con":true,"img":false}]}
{"op":"mcm","clk":"5347920205","pt":1646210487322,"mc":[{"id":"1.195453611","rc":[{"atl":[[3.95,0]],"id":43167172},{"atl":[[3.95,0],[3.9,9.15]],"id":43167173}],"con":true,"img":false}]}
{"op":"mcm","clk":"5347920207","pt":1646210487425,"mc":[{"id":"1.195453611","rc":[{"atl":[[3.85,1],[4,4.97]],"id":43167172}],"con":true,"img":false}]}
{"op":"mcm","clk":"5347920218","pt":1646210487626,"mc":[{"id":"1.195453611","rc":[{"atb":[[12,2.98]],"id":41676292},{"atl":[[3.9,3.38]],"id":43167172}],"con":true,"img":false}]}
{"op":"mcm","clk":"5347920221","pt":1646210487728,"mc":[{"id":"1.195453611","rc":[{"atb":[[1.03,2.25],[13.5,0.81],[14.5,2.08]],"id":41676292}],"con":true,"img":false}]}
{"op":"mcm","clk":"5347920231","pt":1646210487936,"mc":[{"id":"1.195453611","rc":[{"atb":[[1.03,0.25]],"id":41676292}],"con":true,"img":false}]}
{"op":"mcm","clk":"5347920242","pt":1646210488142,"mc":[{"id":"1.195453611","rc":[{"atb":[[1.03,0]],"id":41676292}],"con":true,"img":false}]}
{"op":"mcm","clk":"5347920245","pt":1646210488247,"mc":[{"id":"1.195453611","rc":[{"atb":[[12.5,0.76]],"id":41676292}],"con":true,"img":false}]}
{"op":"mcm","clk":"5347920257","pt":1646210488558,"mc":[{"id":"1.195453611","rc":[{"atl":[[55,0.09]],"id":41762566},{"atb":[[3.5,4.01]],"id":43167172}],"con":true,"img":false}]}
{"op":"mcm","clk":"5347920265","pt":1646210488820,"mc":[{"id":"1.195453611","rc":[{"atl":[[50,1.46]],"id":41762566}],"con":true,"img":false}]}
{"op":"mcm","clk":"5347920269","pt":1646210488926,"mc":[{"id":"1.195453611","rc":[{"atl":[[60,1]],"id":41762566}],"con":true,"img":false}]}
{"op":"mcm","clk":"5347920282","pt":1646210489229,"mc":[{"id":"1.195453611","rc":[{"atl":[[50,0.1]],"id":41762566}],"con":true,"img":false}]}
{"op":"mcm","clk":"5347920287","pt":1646210489332,"mc":[{"id":"1.195453611","rc":[{"atl":[[60,2.36]],"id":41762566},{"atb":[[2.52,1.31]],"id":43167173}],"con":true,"img":false}]}
{"op":"mcm","clk":"5347920293","pt":1646210489436,"mc":[{"id":"1.195453611","rc":[{"atl":[[3.55,3.01]],"id":43167172}],"con":true,"img":false}]}
{"op":"mcm","clk":"5347920304","pt":1646210489640,"mc":[{"id":"1.195453611","rc":[{"atb":[[3.5,2]],"id":43167172},{"atl":[[3.85,0],[3.55,0]],"id":43167172},{"trd":[[3.55,8.01],[3.5,4]],"ltp":3.55,"tv":12.01,"id":43167172}],"con":true,"img":false}]}
{"op":"mcm","clk":"5347920308","pt":1646210489742,"mc":[{"id":"1.195453611","rc":[{"atl":[[3.55,0]],"id":43167172},{"trd":[[3.55,8.02]],"ltp":3.55,"tv":8.02,"id":43167172}],"con":true,"img":false}]}
{"op":"mcm","clk":"5347920314","pt":1646210489844,"mc":[{"id":"1.195453611","rc":[{"atl":[[1000,2]],"id":43167172}],"con":true,"img":false}]}
{"op":"mcm","clk":"5347920320","pt":1646210489946,"mc":[{"id":"1.195453611","rc":[{"atb":[[2.52,0]],"id":43167173}],"con":true,"img":false}]}
{"op":"mcm","clk":"5347920323","pt":1646210490049,"mc":[{"id":"1.195453611","rc":[{"atl":[[1000,1]],"id":43167172},{"atb":[[2.38,2.91]],"id":43167173}],"con":true,"img":false}]}
{"op":"mcm","clk":"5347920326","pt":1646210490152,"mc":[{"id":"1.195453611","rc":[{"atl":[[3.85,1]],"id":43167172}],"con":true,"img":false}]}
{"op":"mcm","clk":"5347920330","pt":1646210490255,"mc":[{"id":"1.195453611","rc":[{"atl":[[1000,0]],"id":43167172}],"con":true,"img":false}]}
{"op":"mcm","clk":"5347920336","pt":1646210490315,"mc":[{"id":"1.195453611","rc":[{"atl":[[3.85,2]],"id":43167172}],"con":true,"img":false}]}
{"op":"mcm","clk":"5347920373","pt":1646210491034,"mc":[{"id":"1.195453611","rc":[{"atl":[[5.4,0]],"id":43066529}],"con":true,"img":false}]}
{"op":"mcm","clk":"5347920377","pt":1646210491131,"mc":[{"id":"1.195453611","rc":[{"atl":[[5.2,6.06]],"id":43066529}],"con":true,"img":false}]}
{"op":"mcm","clk":"5347920434","pt":1646210492120,"mc":[{"id":"1.195453611","rc":[{"atl":[[3.55,3.01]],"id":43167172}],"con":true,"img":false}]}
