{"op":"mcm","clk":"5305619428","pt":1646080581432,"mc":[{"id":"1.195395433","marketDefinition":{"bspMarket":true,"turnInPlayEnabled":false,"persistenceEnabled":false,"marketBaseRate":7.0,"eventId":"31270458","eventTypeId":"4339","numberOfWinners":1,"bettingType":"ODDS","marketType":"WIN","marketTime":"2022-03-01T04:22:00.000Z","suspendTime":"2022-03-01T04:22:00.000Z","bspReconciled":false,"complete":true,"inPlay":false,"crossMatching":false,"runnersVoidable":false,"numberOfActiveRunners":7,"betDelay":0,"status":"OPEN","runners":[{"status":"ACTIVE","sortPriority":1,"id":28774786,"name":"1. Winklee Casey"},{"status":"ACTIVE","sortPriority":2,"id":32825135,"name":"2. Highland Fame"},{"status":"ACTIVE","sortPriority":3,"id":40835929,"name":"4. Self Control"},{"status":"ACTIVE","sortPriority":4,"id":34135026,"name":"5. Quick Joey Small"},{"status":"ACTIVE","sortPriority":5,"id":36474395,"name":"6. Buckle Up Miri"},{"status":"ACTIVE","sortPriority":6,"id":41286501,"name":"7. Wynburn Stroller"},{"status":"ACTIVE","sortPriority":7,"id":38375776,"name":"8. Blazer"}],"regulators":["MR_INT"],"venue":"Devonport","countryCode":"AU","discountAllowed":true,"timezone":"Australia/Sydney","openDate":"2022-03-01T02:00:00.000Z","version":4380714806,"name":"R8 452m Heat","eventName":"Devonport (AUS) 1st Mar"},"rc":[],"con":true,"img":false}]}
{"op":"mcm","clk":"5305743101","pt":1646082026907,"mc":[{"id":"1.195395433","rc":[{"atb":[[32,3.27],[42,2.47],[90,1.14],[55,1.87]],"id":36474395},{"atl":[[530,0.24],[580,0.22],[630,0.31],[680,0.29]],"id":36474395},{"spn":310.0,"spf":"NaN","id":36474395},{"atb":[[2.8,56.38],[2.6,63.43],[2.94,52.31],[2.7,59.7]],"id":28774786},{"atl":[[12,18.02],[9.8,22.53],[8.8,16.94],[7.8,19.43]],"id":28774786},{"spn":5.37,"spf":"NaN","id":28774786},{"atb":[[4.3,30.75],[3.8,36.24],[3.55,39.8],[3.3,44.12]],"id":32825135},{"atl":[[17,8.26],[19.5,10.71],[24,8.62],[14.5,9.79]],"id":32825135},{"spn":9.4,"spf":"NaN","id":32825135},{"atb":[[9,12.68],[5.8,21.14],[7.6,15.37],[6.6,18.12]],"id":41286501},{"atl":[[65,2.06],[130,1.53],[90,2.23],[46,2.93]],"id":41286501},{"spn":27.5,"spf":"NaN","id":41286501},{"atb":[[16.5,6.54],[9.2,12.37],[10.5,10.68],[13,8.46]],"id":38375776},{"atl":[[130,1.02],[280,0.7],[180,0.73],[230,0.86]],"id":38375776},{"spn":73.25,"spf":"NaN","id":38375776},{"atb":[[3.45,41.42],[3.1,48.33],[2.84,55.15],[2.94,52.31]],"id":40835929},{"atl":[[12,18.02],[9.8,15.02],[8.8,16.94],[14.5,14.68]],"id":40835929},{"spn":6.12,"spf":"NaN","id":40835929},{"atb":[[2.3,78.07],[2.44,70.48],[2.2,84.57],[2.1,92.26]],"id":34135026},{"atl":[[8.6,26.09],[5.8,27.54],[7.6,30.04],[6.6,23.6]],"id":34135026},{"spn":4.12,"spf":"NaN","id":34135026}],"con":true,"img":false}]}
{"op":"mcm","clk":"5305747397","pt":1646082083779,"mc":[{"id":"1.195395433","rc":[{"atb":[[32,0],[42,0],[90,0],[55,0]],"id":36474395},{"atl":[[530,0],[580,0],[630,0],[680,0]],"id":36474395},{"atb":[[2.8,0],[2.6,0],[2.94,0],[2.7,0]],"id":28774786},{"atl":[[12,0],[9.8,0],[8.8,0],[7.8,0]],"id":28774786},{"atb":[[4.3,0],[3.8,0],[3.55,0],[3.3,0]],"id":32825135},{"atl":[[17,0],[19.5,0],[24,0],[14.5,0]],"id":32825135},{"atb":[[9,0],[5.8,0],[7.6,0],[6.6,0]],"id":41286501},{"atl":[[65,0],[130,0],[90,0],[46,0]],"id":41286501},{"atb":[[16.5,0],[9.2,0],[10.5,0],[13,0]],"id":38375776},{"atl":[[130,0],[280,0],[180,0],[230,0]],"id":38375776},{"atb":[[3.45,0],[3.1,0],[2.84,0],[2.94,0]],"id":40835929},{"atl":[[12,0],[9.8,0],[8.8,0],[14.5,0]],"id":40835929},{"atb":[[2.3,0],[2.44,0],[2.2,0],[2.1,0]],"id":34135026},{"atl":[[8.6,0],[5.8,0],[7.6,0],[6.6,0]],"id":34135026}],"con":true,"img":false}]}
{"op":"mcm","clk":"5305747678","pt":1646082086939,"mc":[{"id":"1.195395433","rc":[{"atb":[[32,3.27],[42,2.47],[90,1.14],[55,1.87]],"id":36474395},{"atl":[[530,0.24],[580,0.22],[630,0.31],[680,0.29]],"id":36474395},{"atb":[[2.8,56.38],[2.6,63.43],[2.94,52.31],[2.7,59.7]],"id":28774786},{"atl":[[12,18.02],[9.8,22.53],[8.8,16.94],[7.8,19.43]],"id":28774786},{"atb":[[4.3,30.75],[3.8,36.24],[3.55,39.8],[3.3,44.12]],"id":32825135},{"atl":[[17,8.26],[19.5,10.71],[24,8.62],[14.5,9.79]],"id":32825135},{"atb":[[9,12.68],[5.8,21.14],[7.6,15.37],[6.6,18.12]],"id":41286501},{"atl":[[65,2.06],[130,1.53],[90,2.23],[46,2.93]],"id":41286501},{"atb":[[16.5,6.54],[9.2,12.37],[10.5,10.68],[13,8.46]],"id":38375776},{"atl":[[130,1.02],[280,0.7],[180,0.73],[230,0.86]],"id":38375776},{"atb":[[3.45,41.42],[3.1,48.33],[2.84,55.15],[2.94,52.31]],"id":40835929},{"atl":[[12,18.02],[9.8,15.02],[8.8,16.94],[14.5,14.68]],"id":40835929},{"atb":[[2.3,78.07],[2.44,70.48],[2.2,84.57],[2.1,92.26]],"id":34135026},{"atl":[[8.6,26.09],[5.8,27.54],[7.6,30.04],[6.6,23.6]],"id":34135026}],"con":true,"img":false}]}
{"op":"mcm","clk":"5305892559","pt":1646084097566,"mc":[{"id":"1.195395433","rc":[{"atb":[[3.45,1.43]],"id":40835929},{"trd":[[3.45,79.99]],"ltp":3.45,"tv":79.99,"id":40835929}],"con":true,"img":false}]}
{"op":"mcm","clk":"5305893460","pt":1646084112787,"mc":[{"id":"1.195395433","rc":[{"atl":[[4,40]],"id":40835929}],"con":true,"img":false}]}
{"op":"mcm","clk":"5305897459","pt":1646084190566,"mc":[{"id":"1.195395433","rc":[{"atb":[[1.02,1.32]],"id":36474395},{"atb":[[2.96,1.34]],"id":28774786},{"spn":5.38,"spf":"NaN","id":28774786},{"atb":[[4.4,1.32]],"id":32825135},{"spn":9.45,"spf":"NaN","id":32825135},{"spn":3.72,"spf":"NaN","id":40835929},{"atb":[[2.46,1.31]],"id":34135026},{"spn":4.13,"spf":"NaN","id":34135026}],"con":true,"img":false}]}
{"op":"mcm","clk":"5305912243","pt":1646084482090,"mc":[{"id":"1.195395433","rc":[{"atb":[[2.8,0],[2.6,0],[2.94,0],[2.7,0]],"id":28774786},{"atl":[[12,0],[9.8,0],[8.8,0],[7.8,0]],"id":28774786},{"spn":"Infinity","spf":"NaN","id":28774786},{"atb":[[4.3,0],[3.8,0],[3.55,0],[3.3,0]],"id":32825135},{"atl":[[17,0],[19.5,0],[24,0],[14.5,0]],"id":32825135},{"spn":"Infinity","spf":"NaN","id":32825135},{"atb":[[9,0],[5.8,0],[7.6,0],[6.6,0]],"id":41286501},{"atl":[[65,0],[130,0],[90,0],[46,0]],"id":41286501},{"spn":"NaN","spf":"NaN","id":41286501},{"atb":[[16.5,0],[9.2,0],[10.5,0],[13,0]],"id":38375776},{"atl":[[130,0],[280,0],[180,0],[230,0]],"id":38375776},{"spn":"NaN","spf":"NaN","id":38375776},{"atb":[[3.45,0],[3.1,0],[2.84,0],[2.94,0]],"id":40835929},{"atl":[[12,0],[9.8,0],[8.8,0],[14.5,0]],"id":40835929},{"spn":1.0,"spf":"NaN","id":40835929},{"atb":[[2.3,0],[2.44,0],[2.2,0],[2.1,0]],"id":34135026},{"atl":[[8.6,0],[5.8,0],[7.6,0],[6.6,0]],"id":34135026},{"spn":"Infinity","spf":"NaN","id":34135026}],"con":true,"img":false}]}
{"op":"mcm","clk":"5305912265","pt":1646084482557,"mc":[{"id":"1.195395433","rc":[{"atb":[[2.96,0]],"id":28774786},{"atb":[[4.4,0]],"id":32825135},{"atb":[[1.02,1.29]],"id":41286501},{"atb":[[1.02,1.32]],"id":38375776},{"atb":[[1.02,1.27]],"id":40835929},{"atb":[[2.46,0]],"id":34135026}],"con":true,"img":false}]}
{"op":"mcm","clk":"5305912272","pt":1646084482660,"mc":[{"id":"1.195395433","rc":[{"atb":[[1.02,1.34]],"id":28774786},{"atb":[[1.02,1.32]],"id":32825135},{"atb":[[1.02,1.31]],"id":34135026}],"con":true,"img":false}]}
{"op":"mcm","clk":"5305912505","pt":1646084488469,"mc":[{"id":"1.195395433","rc":[{"atb":[[2.86,59.94],[3.25,49.55],[2.96,56.88],[2.76,63.34]],"id":28774786},{"atl":[[11,18.62],[13.5,14.9],[8.4,16.78],[9.4,14.78]],"id":28774786},{"atb":[[4,37.16],[3.5,44.59],[3.75,40.54],[4.7,30.13]],"id":32825135},{"atl":[[16,8.27],[18.5,7.09],[22,8.87],[27,7.16]],"id":32825135},{"atb":[[10.5,11.73],[6.8,19.22],[8.8,14.29],[7.8,16.39]],"id":41286501},{"atl":[[70,1.79],[140,1.34],[95,1.32],[190,0.98]],"id":41286501},{"atb":[[16.5,7.19],[20,5.86],[11.5,10.62],[14,8.57]],"id":38375776},{"atl":[[260,0.71],[310,0.6],[160,0.77],[210,0.59]],"id":38375776},{"atb":[[3.4,32.08],[3.15,35.81],[2.96,39.28],[3.75,28]],"id":40835929},{"atl":[[18,13.39],[10.5,15.97],[13,12.65],[15.5,15.7]],"id":40835929},{"atb":[[2.24,89.91],[2,111.49],[1.95,117.35],[2.1,101.35]],"id":34135026},{"atl":[[8,26.61],[5.5,27.59],[6,24.83],[7,31.04]],"id":34135026}],"con":true,"img":false}]}
{"op":"mcm","clk":"5305912538","pt":1646084489247,"mc":[{"id":"1.195395433","rc":[{"atb":[[1.02,0]],"id":28774786},{"atb":[[1.02,0]],"id":32825135},{"atb":[[1.02,0]],"id":34135026}],"con":true,"img":false}]}
{"op":"mcm","clk":"5305912543","pt":1646084489350,"mc":[{"id":"1.195395433","rc":[{"atb":[[3.3,1.34]],"id":28774786},{"atb":[[4.8,1.32]],"id":32825135},{"atb":[[2.26,1.31]],"id":34135026}],"con":true,"img":false}]}
{"op":"mcm","clk":"5305912566","pt":1646084489972,"mc":[{"id":"1.195395433","rc":[{"atl":[[990,1.27]],"id":36474395},{"atl":[[8.2,1.33]],"id":28774786},{"atl":[[15.5,1.39]],"id":32825135},{"atl":[[990,1.32]],"id":41286501},{"atl":[[990,1.32]],"id":38375776},{"atl":[[5.4,1.3]],"id":34135026}],"con":true,"img":false}]}
{"op":"mcm","clk":"5305912587","pt":1646084490545,"mc":[{"id":"1.195395433","rc":[{"atb":[[3.3,3.01]],"id":28774786},{"atb":[[4.8,2.96]],"id":32825135},{"atb":[[11,1.5]],"id":41286501},{"atb":[[21,1.58]],"id":38375776},{"atb":[[2.26,2.91]],"id":34135026}],"con":true,"img":false}]}
{"op":"mcm","clk":"5305913859","pt":1646084518627,"mc":[{"id":"1.195395433","marketDefinition":{"bspMarket":true,"turnInPlayEnabled":false,"persistenceEnabled":false,"marketBaseRate":7.0,"eventId":"31270458","eventTypeId":"4339","numberOfWinners":1,"bettingType":"ODDS","marketType":"WIN","marketTime":"2022-03-01T04:22:00.000Z","suspendTime":"2022-03-01T04:22:00.000Z","bspReconciled":false,"complete":true,"inPlay":false,"crossMatching":true,"runnersVoidable":false,"numberOfActiveRunners":7,"betDelay":0,"status":"OPEN","runners":[{"status":"ACTIVE","sortPriority":1,"id":28774786,"name":"1. Winklee Casey"},{"status":"ACTIVE","sortPriority":2,"id":32825135,"name":"2. Highland Fame"},{"status":"ACTIVE","sortPriority":3,"id":40835929,"name":"4. Self Control"},{"status":"ACTIVE","sortPriority":4,"id":34135026,"name":"5. Quick Joey Small"},{"status":"ACTIVE","sortPriority":5,"id":36474395,"name":"6. Buckle Up Miri"},{"status":"ACTIVE","sortPriority":6,"id":41286501,"name":"7. Wynburn Stroller"},{"status":"ACTIVE","sortPriority":7,"id":38375776,"name":"8. Blazer"}],"regulators":["MR_INT"],"venue":"Devonport","countryCode":"AU","discountAllowed":true,"timezone":"Australia/Sydney","openDate":"2022-03-01T02:00:00.000Z","version":4380714806,"name":"R8 452m Heat","eventName":"Devonport (AUS) 1st Mar"},"rc":[],"con":true,"img":false}]}
{"op":"mcm","clk":"5305916703","pt":1646084576898,"mc":[{"id":"1.195395433","rc":[{"spn":5.75,"spf":"NaN","id":28774786},{"spn":10.15,"spf":"NaN","id":32825135},{"spn":40.5,"spf":"NaN","id":41286501},{"spn":90.5,"spf":"NaN","id":38375776},{"spn":3.87,"spf":"NaN","id":40835929},{"atl":[[2.5,5.95]],"id":34135026},{"spn":2.38,"spf":"NaN","id":34135026}],"con":true,"img":false}]}
{"op":"mcm","clk":"5305916722","pt":1646084577310,"mc":[{"id":"1.195395433","rc":[{"atb":[[2.26,1.59]],"id":34135026}],"con":true,"img":false}]}
{"op":"mcm","clk":"5305916729","pt":1646084577413,"mc":[{"id":"1.195395433","rc":[{"atb":[[1.02,1.31]],"id":34135026}],"con":true,"img":false}]}
{"op":"mcm","clk":"5305916739","pt":1646084577621,"mc":[{"id":"1.195395433","rc":[{"atb":[[2.26,0]],"id":34135026}],"con":true,"img":false}]}
{"op":"mcm","clk":"5305916746","pt":1646084577672,"mc":[{"id":"1.195395433","rc":[{"atb":[[1.01,1.59]],"id":34135026}],"con":true,"img":false}]}
{"op":"mcm","clk":"5305962428","pt":1646085907588,"mc":[{"id":"1.195395433","rc":[{"atb":[[32,3.27],[42,2.47],[90,1.14],[1.02,1.32],[55,1.87]],"id":36474395},{"atl":[[990,1.27]],"id":36474395},{"atb":[[2.86,59.93],[3.25,49.54],[3.3,3],[2.96,56.87],[2.76,63.33]],"id":28774786},{"atl":[[8.2,1.33],[11,18.62],[13.5,14.89],[8.4,16.77],[9.4,14.78]],"id":28774786},{"atb":[[4.8,2.95],[4,37.15],[3.5,44.59],[3.75,40.53],[4.7,30.12]],"id":32825135},{"atl":[[16,8.27],[18.5,7.09],[22,8.87],[27,7.16],[15.5,1.39]],"id":32825135},{"atb":[[10.5,11.73],[11,1.5],[1.02,1.29],[6.8,19.21],[8.8,14.29],[7.8,16.39]],"id":41286501},{"atl":[[70,1.79],[140,1.34],[95,1.32],[190,0.98],[990,1.32]],"id":41286501},{"atb":[[16.5,7.19],[20,5.86],[21,1.58],[11.5,10.61],[1.02,1.32],[14,8.57]],"id":38375776},{"atl":[[260,0.71],[160,0.77],[990,1.32]],"id":38375776},{"atb":[[1.02,1.27],[3.4,32.07],[3.15,35.8],[2.96,39.28],[3.75,27.99]],"id":40835929},{"atl":[[4,60],[18,13.38],[10.5,15.97],[13,12.64],[15.5,15.7]],"id":40835929},{"trd":[[3.45,79.98]],"ltp":3.45,"tv":79.98,"id":40835929},{"atb":[[2.24,89.89],[2,111.47],[1.01,1.59],[1.02,1.31],[1.95,117.34],[2.1,101.34]],"id":34135026},{"atl":[[8,26.6],[2.5,5.95],[5.5,27.59],[6,24.83],[7,31.04],[5.4,1.3]],"id":34135026},{"spn":2.37,"spf":"NaN","id":34135026}],"con":true,"img":false}]}
{"op":"mcm","clk":"5305990516","pt":1646086602699,"mc":[{"id":"1.195395433","marketDefinition":{"bspMarket":true,"turnInPlayEnabled":false,"persistenceEnabled":false,"marketBaseRate":7.0,"eventId":"31270458","eventTypeId":"4339","numberOfWinners":1,"bettingType":"ODDS","marketType":"WIN","marketTime":"2022-03-01T04:22:00.000Z","suspendTime":"2022-03-01T04:22:00.000Z","bspReconciled":false,"complete":true,"inPlay":false,"crossMatching":true,"runnersVoidable":false,"numberOfActiveRunners":7,"betDelay":0,"status":"OPEN","runners":[{"status":"ACTIVE","sortPriority":1,"id":28774786,"name":"1. Winklee Casey"},{"status":"ACTIVE","sortPriority":2,"id":32825135,"name":"2. Highland Fame"},{"status":"ACTIVE","sortPriority":3,"id":40835929,"name":"4. Self Control"},{"status":"ACTIVE","sortPriority":4,"id":34135026,"name":"5. Quick Joey Small"},{"status":"ACTIVE","sortPriority":5,"id":36474395,"name":"6. Buckle Up Miri"},{"status":"ACTIVE","sortPriority":6,"id":41286501,"name":"7. Wynburn Stroller"},{"status":"ACTIVE","sortPriority":7,"id":38375776,"name":"8. Blazer"}],"regulators":["MR_INT"],"venue":"Devonport","countryCode":"AU","discountAllowed":true,"timezone":"Australia/Sydney","openDate":"2022-03-01T02:00:00.000Z","version":4380714806,"name":"R8 452m Heat","eventName":"Devonport (AUS) 1st Mar"},"rc":[{"atb":[[32,3.27],[42,2.47],[90,1.14],[1.02,1.32],[55,1.87]],"id":36474395},{"atl":[[530,0.24],[580,0.22],[630,0.31],[680,0.29],[990,1.27]],"id":36474395},{"spn":310.0,"spf":"NaN","id":36474395},{"atb":[[2.86,59.93],[3.25,49.54],[3.3,3],[2.96,56.87],[2.76,63.33]],"id":28774786},{"atl":[[8.2,1.33],[11,18.62],[13.5,14.89],[8.4,16.77],[9.4,14.78]],"id":28774786},{"spn":5.75,"spf":"NaN","id":28774786},{"atb":[[4.8,2.95],[4,37.15],[3.5,44.59],[3.75,40.53],[4.7,30.12]],"id":32825135},{"atl":[[16,8.27],[18.5,7.09],[22,8.87],[27,7.16],[15.5,1.39]],"id":32825135},{"spn":10.15,"spf":"NaN","id":32825135},{"atb":[[10.5,11.73],[11,1.5],[1.02,1.29],[6.8,19.21],[8.8,14.29],[7.8,16.39]],"id":41286501},{"atl":[[70,1.79],[140,1.34],[95,1.32],[190,0.98],[990,1.32]],"id":41286501},{"spn":40.5,"spf":"NaN","id":41286501},{"atb":[[16.5,7.19],[20,5.86],[21,1.58],[11.5,10.61],[1.02,1.32],[14,8.57]],"id":38375776},{"atl":[[260,0.71],[310,0.6],[160,0.77],[210,0.59],[990,1.32]],"id":38375776},{"spn":90.5,"spf":"NaN","id":38375776},{"atb":[[1.02,1.27],[3.4,32.07],[3.15,35.8],[2.96,39.28],[3.75,27.99]],"id":40835929},{"atl":[[4,60],[18,13.38],[10.5,15.97],[13,12.64],[15.5,15.7]],"id":40835929},{"trd":[[3.45,79.98]],"ltp":3.45,"tv":79.98,"id":40835929},{"spn":3.87,"spf":"NaN","id":40835929},{"atb":[[2.24,89.89],[2,111.47],[1.01,1.59],[1.02,1.31],[1.95,117.34],[2.1,101.34]],"id":34135026},{"atl":[[8,26.6],[2.5,5.95],[5.5,27.59],[6,24.83],[7,31.04],[5.4,1.3]],"id":34135026},{"spn":2.37,"spf":"NaN","id":34135026}],"con":true,"img":true}]}
{"op":"mcm","clk":"5306015821","pt":1646087172471,"mc":[{"id":"1.195395433","rc":[{"spl":[[1.01,50]],"id":40835929},{"spn":3.59,"spf":1.0,"id":40835929}],"con":true,"img":false}]}
{"op":"mcm","clk":"5306066888","pt":1646088476495,"mc":[{"id":"1.195395433","rc":[{"atl":[[2.5,0]],"id":34135026},{"spn":3.82,"spf":"NaN","id":34135026}],"con":true,"img":false}]}
{"op":"mcm","clk":"5306066921","pt":1646088477167,"mc":[{"id":"1.195395433","rc":[{"atb":[[1.01,0],[1.02,0]],"id":34135026}],"con":true,"img":false}]}
{"op":"mcm","clk":"5306066927","pt":1646088477265,"mc":[{"id":"1.195395433","rc":[{"atb":[[2.26,2.9]],"id":34135026}],"con":true,"img":false}]}
{"op":"mcm","clk":"5306115935","pt":1646089826533,"mc":[{"id":"1.195395433","rc":[{"spl":[[100,2]],"id":36474395},{"spn":95.0,"spf":1.0,"id":36474395},{"spl":[[100,2]],"id":28774786},{"spn":5.75,"spf":1.0,"id":28774786},{"spl":[[100,2]],"id":32825135},{"spn":10.15,"spf":1.0,"id":32825135},{"spl":[[100,2]],"id":41286501},{"spn":40.5,"spf":1.0,"id":41286501},{"spl":[[100,2]],"id":38375776},{"spn":60.5,"spf":1.0,"id":38375776},{"spl":[[100,2]],"id":40835929},{"spl":[[100,2]],"id":34135026},{"spn":3.83,"spf":1.0,"id":34135026}],"con":true,"img":false}]}
{"op":"mcm","clk":"5306117573","pt":1646089885145,"mc":[{"id":"1.195395433","rc":[{"spl":[[1.01,200]],"id":40835929}],"con":true,"img":false}]}
{"op":"mcm","clk":"5306196772","pt":1646092002677,"mc":[{"id":"1.195395433","marketDefinition":{"bspMarket":true,"turnInPlayEnabled":false,"persistenceEnabled":false,"marketBaseRate":7.0,"eventId":"31270458","eventTypeId":"4339","numberOfWinners":1,"bettingType":"ODDS","marketType":"WIN","marketTime":"2022-03-01T04:22:00.000Z","suspendTime":"2022-03-01T04:22:00.000Z","bspReconciled":false,"complete":true,"inPlay":false,"crossMatching":true,"runnersVoidable":false,"numberOfActiveRunners":7,"betDelay":0,"status":"OPEN","runners":[{"status":"ACTIVE","sortPriority":1,"id":28774786,"name":"1. Winklee Casey"},{"status":"ACTIVE","sortPriority":2,"id":32825135,"name":"2. Highland Fame"},{"status":"ACTIVE","sortPriority":3,"id":40835929,"name":"4. Self Control"},{"status":"ACTIVE","sortPriority":4,"id":34135026,"name":"5. Quick Joey Small"},{"status":"ACTIVE","sortPriority":5,"id":36474395,"name":"6. Buckle Up Miri"},{"status":"ACTIVE","sortPriority":6,"id":41286501,"name":"7. Wynburn Stroller"},{"status":"ACTIVE","sortPriority":7,"id":38375776,"name":"8. Blazer"}],"regulators":["MR_INT"],"venue":"Devonport","countryCode":"AU","discountAllowed":true,"timezone":"Australia/Sydney","openDate":"2022-03-01T02:00:00.000Z","version":4380714806,"name":"R8 452m Heat","eventName":"Devonport (AUS) 1st Mar"},"rc":[{"atb":[[32,3.27],[42,2.47],[90,1.14],[1.02,1.32],[55,1.87]],"id":36474395},{"spl":[[100,2]],"id":36474395},{"atl":[[530,0.24],[580,0.22],[630,0.31],[680,0.29],[990,1.27]],"id":36474395},{"spn":95.0,"spf":1.0,"id":36474395},{"atb":[[2.86,59.93],[3.25,49.54],[3.3,3],[2.96,56.87],[2.76,63.33]],"id":28774786},{"spl":[[100,2]],"id":28774786},{"atl":[[8.2,1.33],[11,18.62],[13.5,14.89],[8.4,16.77],[9.4,14.78]],"id":28774786},{"spn":5.75,"spf":1.0,"id":28774786},{"atb":[[4.8,2.95],[4,37.15],[3.5,44.59],[3.75,40.53],[4.7,30.12]],"id":32825135},{"spl":[[100,2]],"id":32825135},{"atl":[[16,8.27],[18.5,7.09],[22,8.87],[27,7.16],[15.5,1.39]],"id":32825135},{"spn":10.15,"spf":1.0,"id":32825135},{"atb":[[10.5,11.73],[11,1.5],[1.02,1.29],[6.8,19.21],[8.8,14.29],[7.8,16.39]],"id":41286501},{"spl":[[100,2]],"id":41286501},{"atl":[[70,1.79],[140,1.34],[95,1.32],[190,0.98],[990,1.32]],"id":41286501},{"spn":40.5,"spf":1.0,"id":41286501},{"atb":[[16.5,7.19],[20,5.86],[21,1.58],[11.5,10.61],[1.02,1.32],[14,8.57]],"id":38375776},{"spl":[[100,2]],"id":38375776},{"atl":[[260,0.71],[310,0.6],[160,0.77],[210,0.59],[990,1.32]],"id":38375776},{"spn":60.5,"spf":1.0,"id":38375776},{"atb":[[1.02,1.27],[3.4,32.07],[3.15,35.8],[2.96,39.28],[3.75,27.99]],"id":40835929},{"spl":[[1.01,200],[100,2]],"id":40835929},{"atl":[[4,60],[18,13.38],[10.5,15.97],[13,12.64],[15.5,15.7]],"id":40835929},{"trd":[[3.45,79.98]],"ltp":3.45,"tv":79.98,"id":40835929},{"spn":2.53,"spf":1.0,"id":40835929},{"atb":[[2.24,89.89],[2,111.47],[2.26,2.9],[1.95,117.34],[2.1,101.34]],"id":34135026},{"spl":[[100,2]],"id":34135026},{"atl":[[8,26.6],[5.5,27.59],[6,24.83],[7,31.04],[5.4,1.3]],"id":34135026},{"spn":3.83,"spf":1.0,"id":34135026}],"con":true,"img":true}]}
{"op":"mcm","clk":"5306212885","pt":1646092434187,"mc":[{"id":"1.195395433","rc":[{"atb":[[2.86,0],[3.25,0],[2.96,0],[2.76,0]],"id":28774786},{"atl":[[11,0],[13.5,0],[8.4,0],[9.4,0]],"id":28774786},{"atb":[[4,0],[3.5,0],[3.75,0],[4.7,0]],"id":32825135},{"atl":[[16,0],[18.5,0],[22,0],[27,0]],"id":32825135},{"atb":[[10.5,0],[6.8,0],[8.8,0],[7.8,0]],"id":41286501},{"atl":[[70,0],[140,0],[95,0],[190,0]],"id":41286501},{"spn":55.5,"spf":1.0,"id":41286501},{"atb":[[3.4,0],[3.15,0],[2.96,0],[3.75,0]],"id":40835929},{"atl":[[18,0],[10.5,0],[13,0],[15.5,0]],"id":40835929},{"spn":1.01,"spf":1.0,"id":40835929}],"con":true,"img":false}]}
{"op":"mcm","clk":"5306212902","pt":1646092434549,"mc":[{"id":"1.195395433","rc":[{"atb":[[3.3,0]],"id":28774786},{"atl":[[8.2,0]],"id":28774786},{"atb":[[4.8,0]],"id":32825135},{"atl":[[15.5,0]],"id":32825135},{"atb":[[11,0]],"id":41286501},{"atb":[[1.02,2.95]],"id":40835929},{"atl":[[3.95,1.39]],"id":40835929}],"con":true,"img":false}]}
{"op":"mcm","clk":"5306212906","pt":1646092434652,"mc":[{"id":"1.195395433","rc":[{"atb":[[1.02,3]],"id":28774786},{"atl":[[990,1.33]],"id":28774786},{"atb":[[1.02,2.95]],"id":32825135},{"atl":[[990,1.39]],"id":32825135},{"atb":[[1.02,2.8]],"id":41286501}],"con":true,"img":false}]}
{"op":"mcm","clk":"5306213321","pt":1646092445081,"mc":[{"id":"1.195395433","rc":[{"atb":[[2.86,59.93],[3.25,49.54],[2.96,56.87],[2.76,63.33]],"id":28774786},{"atl":[[11,18.62],[13.5,14.89],[8.4,16.77],[9.4,14.78]],"id":28774786},{"atb":[[4,37.15],[3.5,44.59],[3.75,40.53],[4.7,30.12]],"id":32825135},{"atl":[[16,8.27],[18.5,7.09],[22,8.87],[27,7.16]],"id":32825135},{"atb":[[10.5,11.73],[6.8,19.21],[8.8,14.29],[7.8,16.39]],"id":41286501},{"atl":[[70,1.79],[140,1.34],[95,1.32],[190,0.98]],"id":41286501},{"atb":[[3.4,32.07],[3.15,35.8],[2.96,39.28],[3.75,27.99]],"id":40835929},{"atl":[[18,13.38],[10.5,15.97],[13,12.64],[15.5,15.7]],"id":40835929}],"con":true,"img":false}]}
{"op":"mcm","clk":"5306213335","pt":1646092445492,"mc":[{"id":"1.195395433","rc":[{"atb":[[1.02,0]],"id":28774786},{"atb":[[1.02,0]],"id":32825135},{"atb":[[1.02,1.29]],"id":41286501}],"con":true,"img":false}]}
{"op":"mcm","clk":"5306213340","pt":1646092445594,"mc":[{"id":"1.195395433","rc":[{"atb":[[3.3,3]],"id":28774786},{"atb":[[4.8,2.95]],"id":32825135},{"atb":[[11,1.5]],"id":41286501}],"con":true,"img":false}]}
{"op":"mcm","clk":"5306227847","pt":1646092818653,"mc":[{"id":"1.195395433","rc":[{"atb":[[32,3.27],[42,2.47],[90,1.14],[1.02,1.32],[55,1.87]],"id":36474395},{"atl":[[530,0.24],[580,0.22],[630,0.31],[680,0.29],[990,1.27]],"id":36474395},{"atb":[[2.86,59.89],[3.25,49.51],[3.3,3],[2.96,56.83],[2.76,63.29]],"id":28774786},{"atl":[[11,18.61],[13.5,14.88],[8.4,16.76],[990,0],[9.4,14.77]],"id":28774786},{"spn":5.85,"spf":1.0,"id":28774786},{"atb":[[4.8,2.95],[4,37.13],[3.5,44.56],[3.75,40.51],[4.7,30.1]],"id":32825135},{"atl":[[16,8.26],[18.5,7.09],[22,8.86],[27,7.16],[990,0]],"id":32825135},{"spn":10.4,"spf":1.0,"id":32825135},{"atb":[[10.5,11.72],[11,1.5],[1.02,1.29],[6.8,19.2],[8.8,14.28],[7.8,16.38]],"id":41286501},{"atl":[[70,1.79],[140,1.34],[95,1.31],[190,0.98],[990,1.32]],"id":41286501},{"spn":40.5,"spf":1.0,"id":41286501},{"atb":[[16.5,7.18],[20,5.86],[21,1.57],[11.5,10.61],[1.02,1.32],[14,8.56]],"id":38375776},{"atl":[[260,0.71],[310,0.6],[160,0.77],[210,0.59],[990,1.32]],"id":38375776},{"atb":[[1.02,2.94],[3.4,32.05],[3.15,35.78],[2.96,39.25],[3.75,27.97]],"id":40835929},{"atl":[[18,13.38],[3.95,0],[10.5,15.96],[13,12.63],[15.5,15.69]],"id":40835929},{"trd":[[3.45,79.95]],"ltp":3.45,"tv":79.95,"id":40835929},{"spn":2.53,"spf":1.0,"id":40835929},{"atb":[[2.24,89.83],[2,111.4],[2.26,2.9],[1.95,117.26],[2.1,101.27]],"id":34135026},{"atl":[[8,26.58],[5.5,27.57],[6,24.81],[7,31.02],[5.4,1.3]],"id":34135026}],"con":true,"img":false}]}
{"op":"mcm","clk":"5306227851","pt":1646092818755,"mc":[{"id":"1.195395433","rc":[{"atl":[[8.2,1.33]],"id":28774786},{"atl":[[15.5,1.39]],"id":32825135},{"atl":[[1000,1.39]],"id":40835929}],"con":true,"img":false}]}
{"op":"mcm","clk":"5306257975","pt":1646093633807,"mc":[{"id":"1.195395433","rc":[{"atb":[[2.86,0],[3.25,0],[2.96,0],[2.76,0]],"id":28774786},{"atl":[[11,0],[13.5,0],[8.4,0],[9.4,0]],"id":28774786},{"spn":5.75,"spf":1.0,"id":28774786},{"atb":[[4,0],[3.5,0],[3.75,0],[4.7,0]],"id":32825135},{"atl":[[16,0],[18.5,0],[22,0],[27,0]],"id":32825135},{"spn":10.15,"spf":1.0,"id":32825135},{"atb":[[10.5,0],[6.8,0],[8.8,0],[7.8,0]],"id":41286501},{"atl":[[70,0],[140,0],[95,0],[190,0]],"id":41286501},{"spn":55.5,"spf":1.0,"id":41286501},{"atb":[[3.4,0],[3.15,0],[2.96,0],[3.75,0]],"id":40835929},{"atl":[[18,0],[10.5,0],[13,0],[15.5,0]],"id":40835929},{"spn":1.01,"spf":1.0,"id":40835929},{"atb":[[2.24,0],[2,0],[1.95,0],[2.1,0]],"id":34135026},{"atl":[[8,0],[5.5,0],[6,0],[7,0]],"id":34135026}],"con":true,"img":false}]}
{"op":"mcm","clk":"5306258003","pt":1646093634324,"mc":[{"id":"1.195395433","rc":[{"atb":[[3.3,1.66]],"id":28774786},{"atb":[[4.8,1.63]],"id":32825135},{"atb":[[2.26,1.59]],"id":34135026}],"con":true,"img":false}]}
{"op":"mcm","clk":"5306258008","pt":1646093634429,"mc":[{"id":"1.195395433","rc":[{"atb":[[1.02,1.34]],"id":28774786},{"atb":[[1.02,1.32]],"id":32825135},{"atb":[[1.02,1.31]],"id":34135026}],"con":true,"img":false}]}
{"op":"mcm","clk":"5306258030","pt":1646093634690,"mc":[{"id":"1.195395433","rc":[{"atb":[[3.3,0]],"id":28774786},{"atb":[[4.8,0]],"id":32825135},{"atb":[[11,0]],"id":41286501},{"atb":[[2.26,0]],"id":34135026}],"con":true,"img":false}]}
{"op":"mcm","clk":"5306258037","pt":1646093634793,"mc":[{"id":"1.195395433","rc":[{"atb":[[1.02,3]],"id":28774786},{"atb":[[1.02,2.95]],"id":32825135},{"atb":[[1.02,2.79]],"id":41286501},{"atb":[[1.02,2.9]],"id":34135026}],"con":true,"img":false}]}
{"op":"mcm","clk":"5306258123","pt":1646093637107,"mc":[{"id":"1.195395433","rc":[{"atl":[[8.2,0]],"id":28774786},{"atl":[[15.5,0]],"id":32825135},{"atl":[[1000,0]],"id":40835929},{"atl":[[5.4,0]],"id":34135026}],"con":true,"img":false}]}
{"op":"mcm","clk":"5306258128","pt":1646093637209,"mc":[{"id":"1.195395433","rc":[{"atl":[[990,1.33]],"id":28774786},{"atl":[[990,1.39]],"id":32825135},{"atl":[[3.95,1.39]],"id":40835929},{"atl":[[990,1.3]],"id":34135026}],"con":true,"img":false}]}
{"op":"mcm","clk":"5306258591","pt":1646093651678,"mc":[{"id":"1.195395433","rc":[{"atb":[[3.85,39.08],[3,55.69],[3.25,49.51],[3.5,44.56]],"id":28774786},{"atl":[[16.5,12],[19,10.34],[11.5,11.81],[14,9.54]],"id":28774786},{"atb":[[4,37.13],[3.5,44.56],[3.75,40.51],[4.7,30.1]],"id":32825135},{"atl":[[16,8.26],[18.5,7.09],[22,8.86],[27,7.16]],"id":32825135},{"atb":[[10.5,11.72],[6.8,19.2],[8.8,14.28],[7.8,16.38]],"id":41286501},{"atl":[[70,1.79],[140,1.34],[95,1.31],[190,0.98]],"id":41286501},{"atb":[[2.4,54.95],[2.5,51.28],[2.3,59.18],[2.64,46.91]],"id":40835929},{"atl":[[7.2,24.46],[9.2,27.74],[6.2,29.16],[8.2,31.59]],"id":40835929},{"atb":[[2.06,105.09],[1.98,113.67],[2.2,92.83],[1.93,119.78]],"id":34135026},{"atl":[[6.8,32.08],[7.8,27.37],[5.9,25.32],[5.4,28.2]],"id":34135026}],"con":true,"img":false}]}
{"op":"mcm","clk":"5306258603","pt":1646093652246,"mc":[{"id":"1.195395433","rc":[{"atb":[[1.02,1.34]],"id":28774786},{"atl":[[990,0]],"id":28774786},{"atb":[[1.02,1.32]],"id":32825135},{"atl":[[990,0]],"id":32825135},{"atb":[[1.02,1.29]],"id":41286501},{"atb":[[1.02,1.27]],"id":40835929},{"atb":[[1.02,1.31]],"id":34135026},{"atl":[[990,0]],"id":34135026}],"con":true,"img":false}]}
{"op":"mcm","clk":"5306258605","pt":1646093652349,"mc":[{"id":"1.195395433","rc":[{"atb":[[1.02,0],[3.9,1.66]],"id":28774786},{"atl":[[11,1.33]],"id":28774786},{"atb":[[4.8,1.63],[1.02,0]],"id":32825135},{"atl":[[15.5,1.39]],"id":32825135},{"atb":[[11,1.5]],"id":41286501},{"atb":[[1.02,0],[2.66,1.67]],"id":40835929},{"atb":[[2.22,1.59],[1.02,0]],"id":34135026},{"atl":[[5.3,1.3]],"id":34135026}],"con":true,"img":false}]}
{"op":"mcm","clk":"5306258607","pt":1646093652401,"mc":[{"id":"1.195395433","rc":[{"atb":[[3.9,3]],"id":28774786},{"atb":[[4.8,2.95]],"id":32825135},{"atb":[[2.66,2.94]],"id":40835929},{"atb":[[2.22,2.9]],"id":34135026}],"con":true,"img":false}]}
{"op":"mcm","clk":"5306259908","pt":1646093694217,"mc":[{"id":"1.195395433","rc":[{"atb":[[3.85,0],[3,0],[3.25,0],[3.5,0]],"id":28774786},{"atl":[[16.5,0],[19,0],[11.5,0],[14,0]],"id":28774786},{"spn":7.45,"spf":1.0,"id":28774786},{"spn":40.5,"spf":1.0,"id":41286501},{"atb":[[2.4,0],[2.5,0],[2.3,0],[2.64,0]],"id":40835929},{"atl":[[7.2,0],[9.2,0],[6.2,0],[8.2,0]],"id":40835929},{"spn":1.02,"spf":1.0,"id":40835929},{"spn":3.76,"spf":1.0,"id":34135026}],"con":true,"img":false}]}
{"op":"mcm","clk":"5306259942","pt":1646093694891,"mc":[{"id":"1.195395433","rc":[{"atb":[[3.9,0]],"id":28774786},{"atl":[[11,0]],"id":28774786},{"atb":[[2.66,0]],"id":40835929}],"con":true,"img":false}]}
{"op":"mcm","clk":"5306259947","pt":1646093694992,"mc":[{"id":"1.195395433","rc":[{"atb":[[1.02,3]],"id":28774786},{"atl":[[990,1.33]],"id":28774786},{"atb":[[1.02,2.94]],"id":40835929}],"con":true,"img":false}]}
{"op":"mcm","clk":"5306260620","pt":1646093715874,"mc":[{"id":"1.195395433","rc":[{"atb":[[3.45,45.47],[3.2,50.63],[4.1,35.93],[3.7,41.26]],"id":28774786},{"atl":[[16,8.26],[18.5,10.63],[22,8.86],[13.5,9.92]],"id":28774786},{"atb":[[2.88,40.92],[2.78,43.22],[2.68,45.79],[3.05,37.53]],"id":40835929},{"atl":[[9.2,18.49],[10.5,23.94],[8.2,21.06],[13,18.95]],"id":40835929}],"con":true,"img":false}]}
{"op":"mcm","clk":"5306260675","pt":1646093716544,"mc":[{"id":"1.195395433","rc":[{"atb":[[1.02,0]],"id":28774786},{"atb":[[1.02,1.27]],"id":40835929}],"con":true,"img":false}]}
{"op":"mcm","clk":"5306260678","pt":1646093716645,"mc":[{"id":"1.195395433","rc":[{"atb":[[4.2,3]],"id":28774786},{"atb":[[3.1,1.67]],"id":40835929}],"con":true,"img":false}]}
{"op":"mcm","clk":"5306260831","pt":1646093719418,"mc":[{"id":"1.195395433","rc":[{"atl":[[990,0]],"id":28774786}],"con":true,"img":false}]}
{"op":"mcm","clk":"5306260834","pt":1646093719521,"mc":[{"id":"1.195395433","rc":[{"atl":[[13,1.33]],"id":28774786}],"con":true,"img":false}]}
{"op":"mcm","clk":"5306262186","pt":1646093753180,"mc":[{"id":"1.195395433","rc":[{"atb":[[3.45,0],[3.2,0],[4.1,0],[3.7,0]],"id":28774786},{"atl":[[16,0],[18.5,0],[22,0],[13.5,0]],"id":28774786},{"atb":[[4,0],[3.5,0],[3.75,0],[4.7,0]],"id":32825135},{"atl":[[16,0],[18.5,0],[22,0],[27,0]],"id":32825135},{"atb":[[10.5,0],[6.8,0],[8.8,0],[7.8,0]],"id":41286501},{"atl":[[70,0],[140,0],[95,0],[190,0]],"id":41286501},{"atb":[[16.5,0],[20,0],[11.5,0],[14,0]],"id":38375776},{"atl":[[260,0],[310,0],[160,0],[210,0]],"id":38375776},{"atb":[[2.88,0],[2.78,0],[2.68,0],[3.05,0]],"id":40835929},{"atl":[[9.2,0],[10.5,0],[8.2,0],[13,0]],"id":40835929}],"con":true,"img":false}]}
{"op":"mcm","clk":"5306262214","pt":1646093753697,"mc":[{"id":"1.195395433","rc":[{"atl":[[13,0]],"id":28774786},{"atl":[[15.5,0]],"id":32825135}],"con":true,"img":false}]}
{"op":"mcm","clk":"5306262220","pt":1646093753805,"mc":[{"id":"1.195395433","rc":[{"atb":[[4.2,1.34]],"id":28774786},{"atl":[[990,1.33]],"id":28774786},{"atb":[[4.8,1.32]],"id":32825135},{"atl":[[990,1.39]],"id":32825135},{"atb":[[11,0]],"id":41286501},{"atb":[[21,0]],"id":38375776},{"atb":[[3.1,0]],"id":40835929}],"con":true,"img":false}]}
{"op":"mcm","clk":"5306262224","pt":1646093753908,"mc":[{"id":"1.195395433","rc":[{"atb":[[1.02,1.66],[4.2,0]],"id":28774786},{"atb":[[4.8,0],[1.02,1.63]],"id":32825135},{"atb":[[1.02,2.79]],"id":41286501},{"atb":[[1.02,2.9]],"id":38375776},{"atb":[[1.02,2.94]],"id":40835929}],"con":true,"img":false}]}
{"op":"mcm","clk":"5306262228","pt":1646093754006,"mc":[{"id":"1.195395433","rc":[{"atb":[[1.02,3]],"id":28774786},{"atb":[[1.02,2.95]],"id":32825135}],"con":true,"img":false}]}
{"op":"mcm","clk":"5306262718","pt":1646093767420,"mc":[{"id":"1.195395433","rc":[{"atb":[[3.45,45.47],[3.2,50.63],[4.1,35.93],[3.7,41.26]],"id":28774786},{"atl":[[16,8.26],[18.5,10.63],[22,8.86],[13.5,9.92]],"id":28774786},{"spn":8.8,"spf":1.0,"id":28774786},{"atb":[[4,37.13],[4.5,31.82],[5.2,26.52],[3.75,40.51]],"id":32825135},{"atl":[[17,7.75],[19.5,6.7],[24,8.09],[29,6.64]],"id":32825135},{"spn":11.1,"spf":1.0,"id":32825135},{"atb":[[10.5,11.72],[6.8,19.2],[8.8,14.28],[7.8,16.38]],"id":41286501},{"atl":[[70,1.79],[140,1.34],[95,1.31],[190,0.98]],"id":41286501},{"spn":40.25,"spf":1.0,"id":41286501},{"atb":[[16.5,7.18],[20,5.86],[11.5,10.61],[14,8.56]],"id":38375776},{"atl":[[260,0.71],[310,0.6],[160,0.77],[210,0.59]],"id":38375776},{"spn":60.0,"spf":1.0,"id":38375776},{"atb":[[2.88,40.92],[2.78,43.22],[2.68,45.79],[3.05,37.53]],"id":40835929},{"atl":[[9.2,18.49],[10.5,23.94],[8.2,21.06],[13,18.95]],"id":40835929},{"spn":2.53,"spf":1.0,"id":40835929}],"con":true,"img":false}]}
{"op":"mcm","clk":"5306262732","pt":1646093767727,"mc":[{"id":"1.195395433","rc":[{"atb":[[1.02,1.66]],"id":28774786},{"atb":[[1.02,1.63]],"id":32825135}],"con":true,"img":false}]}
{"op":"mcm","clk":"5306262735","pt":1646093767829,"mc":[{"id":"1.195395433","rc":[{"atb":[[4.2,1.34]],"id":28774786},{"atb":[[5.3,1.32]],"id":32825135}],"con":true,"img":false}]}
{"op":"mcm","clk":"5306262749","pt":1646093768196,"mc":[{"id":"1.195395433","rc":[{"atl":[[990,0]],"id":32825135}],"con":true,"img":false}]}
{"op":"mcm","clk":"5306262755","pt":1646093768294,"mc":[{"id":"1.195395433","rc":[{"atl":[[16.5,1.39]],"id":32825135}],"con":true,"img":false}]}
{"op":"mcm","clk":"5306262799","pt":1646093769425,"mc":[{"id":"1.195395433","rc":[{"atb":[[1.02,0]],"id":32825135},{"atb":[[1.02,1.29]],"id":41286501},{"atb":[[1.02,1.32]],"id":38375776}],"con":true,"img":false}]}
{"op":"mcm","clk":"5306262803","pt":1646093769528,"mc":[{"id":"1.195395433","rc":[{"atb":[[5.3,2.95]],"id":32825135},{"atb":[[11,1.5]],"id":41286501},{"atb":[[21,1.57]],"id":38375776}],"con":true,"img":false}]}
{"op":"mcm","clk":"5306272704","pt":1646094053144,"mc":[{"id":"1.195395433","rc":[{"spn":8.85,"spf":1.0,"id":28774786},{"spn":10.9,"spf":1.0,"id":32825135},{"atb":[[10.5,0],[6.8,0],[8.8,0],[7.8,0]],"id":41286501},{"atl":[[70,0],[140,0],[95,0],[190,0]],"id":41286501},{"spn":55.5,"spf":1.0,"id":41286501},{"spn":60.5,"spf":1.0,"id":38375776},{"atb":[[2.88,0],[2.78,0],[2.68,0],[3.05,0]],"id":40835929},{"atl":[[9.2,0],[10.5,0],[8.2,0],[13,0]],"id":40835929},{"spn":1.01,"spf":1.0,"id":40835929}],"con":true,"img":false}]}
{"op":"mcm","clk":"5306272720","pt":1646094053555,"mc":[{"id":"1.195395433","rc":[{"atl":[[990,0]],"id":28774786}],"con":true,"img":false}]}
{"op":"mcm","clk":"5306272728","pt":1646094053660,"mc":[{"id":"1.195395433","rc":[{"atl":[[13,1.33]],"id":28774786}],"con":true,"img":false}]}
{"op":"mcm","clk":"5306272742","pt":1646094053862,"mc":[{"id":"1.195395433","rc":[{"atb":[[1.02,0]],"id":28774786},{"atb":[[11,0]],"id":41286501}],"con":true,"img":false}]}
{"op":"mcm","clk":"5306272745","pt":1646094053964,"mc":[{"id":"1.195395433","rc":[{"atb":[[4.2,3]],"id":28774786},{"atb":[[1.02,2.79]],"id":41286501}],"con":true,"img":false}]}
{"op":"mcm","clk":"5306273006","pt":1646094058590,"mc":[{"id":"1.195395433","rc":[{"atb":[[10.5,11.72],[6.8,19.2],[8.8,14.28],[7.8,16.38]],"id":41286501},{"atl":[[70,1.79],[140,1.34],[95,1.31],[190,0.98]],"id":41286501},{"atb":[[2.88,40.92],[2.78,43.22],[2.68,45.79],[3.05,37.53]],"id":40835929},{"atl":[[9.2,18.49],[10.5,23.94],[8.2,21.06],[13,18.95]],"id":40835929}],"con":true,"img":false}]}
{"op":"mcm","clk":"5306273059","pt":1646094059879,"mc":[{"id":"1.195395433","rc":[{"atb":[[1.02,1.29]],"id":41286501},{"atb":[[1.02,1.27]],"id":40835929}],"con":true,"img":false}]}
{"op":"mcm","clk":"5306273063","pt":1646094059983,"mc":[{"id":"1.195395433","rc":[{"atb":[[11,1.5]],"id":41286501},{"atb":[[3.1,1.67]],"id":40835929}],"con":true,"img":false}]}
{"op":"mcm","clk":"5306275782","pt":1646094141388,"mc":[{"id":"1.195395433","rc":[{"spn":8.6,"spf":1.0,"id":28774786},{"spn":40.5,"spf":1.0,"id":41286501},{"atb":[[2.88,0],[2.78,0],[2.68,0],[3.05,0]],"id":40835929},{"atl":[[9.2,0],[10.5,0],[8.2,0],[13,0]],"id":40835929},{"spn":1.01,"spf":1.0,"id":40835929}],"con":true,"img":false}]}
{"op":"mcm","clk":"5306275810","pt":1646094142204,"mc":[{"id":"1.195395433","rc":[{"atb":[[3.1,0]],"id":40835929}],"con":true,"img":false}]}
{"op":"mcm","clk":"5306275814","pt":1646094142312,"mc":[{"id":"1.195395433","rc":[{"atb":[[1.02,2.94]],"id":40835929}],"con":true,"img":false}]}
{"op":"mcm","clk":"5306275963","pt":1646094146415,"mc":[{"id":"1.195395433","rc":[{"atb":[[2.88,40.92],[2.78,43.22],[2.68,45.79],[3.05,37.53]],"id":40835929},{"atl":[[9.2,18.49],[10.5,23.94],[8.2,21.06],[13,18.95]],"id":40835929}],"con":true,"img":false}]}
{"op":"mcm","clk":"5306275978","pt":1646094146988,"mc":[{"id":"1.195395433","rc":[{"atb":[[1.02,1.27]],"id":40835929}],"con":true,"img":false}]}
{"op":"mcm","clk":"5306275983","pt":1646094147090,"mc":[{"id":"1.195395433","rc":[{"atb":[[3.1,1.67]],"id":40835929}],"con":true,"img":false}]}
{"op":"mcm","clk":"5306278970","pt":1646094232769,"mc":[{"id":"1.195395433","rc":[{"atb":[[3.45,0],[3.2,0],[4.1,0],[3.7,0]],"id":28774786},{"atl":[[16,0],[18.5,0],[22,0],[13.5,0]],"id":28774786},{"atb":[[10.5,0],[6.8,0],[8.8,0],[7.8,0]],"id":41286501},{"atl":[[70,0],[140,0],[95,0],[190,0]],"id":41286501},{"spn":55.5,"spf":1.0,"id":41286501},{"atb":[[2.88,0],[2.78,0],[2.68,0],[3.05,0]],"id":40835929},{"atl":[[9.2,0],[10.5,0],[8.2,0],[13,0]],"id":40835929},{"atb":[[2.06,0],[1.98,0],[2.2,0],[1.93,0]],"id":34135026},{"atl":[[6.8,0],[7.8,0],[5.9,0],[5.4,0]],"id":34135026}],"con":true,"img":false}]}
{"op":"mcm","clk":"5306278989","pt":1646094233238,"mc":[{"id":"1.195395433","rc":[{"atl":[[13,0]],"id":28774786},{"atl":[[5.3,0]],"id":34135026}],"con":true,"img":false}]}
{"op":"mcm","clk":"5306278992","pt":1646094233342,"mc":[{"id":"1.195395433","rc":[{"atl":[[990,1.33]],"id":28774786},{"atl":[[990,1.3]],"id":34135026}],"con":true,"img":false}]}
{"op":"mcm","clk":"5306278996","pt":1646094233447,"mc":[{"id":"1.195395433","rc":[{"atb":[[4.2,0]],"id":28774786},{"atb":[[11,0]],"id":41286501},{"atb":[[3.1,0]],"id":40835929},{"atb":[[2.22,0]],"id":34135026}],"con":true,"img":false}]}
{"op":"mcm","clk":"5306279003","pt":1646094233547,"mc":[{"id":"1.195395433","rc":[{"atb":[[1.02,3]],"id":28774786},{"atb":[[1.02,2.79]],"id":41286501},{"atb":[[1.02,2.94]],"id":40835929},{"atb":[[1.02,2.9]],"id":34135026}],"con":true,"img":false}]}
{"op":"mcm","clk":"5306279101","pt":1646094236631,"mc":[{"id":"1.195395433","rc":[{"atb":[[3.45,45.47],[3.1,53.04],[2.84,60.54],[2.94,57.42]],"id":28774786},{"atl":[[12,16.92],[9.8,14.1],[8.8,15.9],[14.5,13.78]],"id":28774786},{"atb":[[7.2,17.96],[9.2,13.58],[8.2,15.47],[11.5,10.61]],"id":41286501},{"atl":[[80,1.56],[160,1.16],[210,0.89],[110,1.13]],"id":41286501},{"atb":[[2.74,44.21],[2.64,46.91],[2.98,38.85],[2.84,41.81]],"id":40835929},{"atl":[[8,21.66],[9,18.95],[10,25.27],[12.5,19.77]],"id":40835929},{"atb":[[2.3,85.69],[2.06,105.09],[1.98,113.67],[2.16,96.03]],"id":34135026},{"atl":[[5.6,26.97],[7.2,30.02],[6.2,23.86],[8.2,25.85]],"id":34135026}],"con":true,"img":false}]}
{"op":"mcm","clk":"5306279118","pt":1646094237148,"mc":[{"id":"1.195395433","rc":[{"atb":[[1.02,1.66]],"id":28774786},{"atb":[[1.02,1.67]],"id":40835929},{"atb":[[1.02,1.59]],"id":34135026}],"con":true,"img":false}]}
{"op":"mcm","clk":"5306279122","pt":1646094237249,"mc":[{"id":"1.195395433","rc":[{"atb":[[3.5,1.34]],"id":28774786},{"atb":[[3,1.27]],"id":40835929},{"atb":[[2.32,1.31]],"id":34135026}],"con":true,"img":false}]}
{"op":"mcm","clk":"5306279129","pt":1646094237455,"mc":[{"id":"1.195395433","rc":[{"atl":[[990,0]],"id":28774786},{"atl":[[990,0]],"id":34135026}],"con":true,"img":false}]}
{"op":"mcm","clk":"5306279133","pt":1646094237555,"mc":[{"id":"1.195395433","rc":[{"atl":[[8.6,1.33]],"id":28774786},{"atl":[[5.5,1.3]],"id":34135026}],"con":true,"img":false}]}
{"op":"mcm","clk":"5306279215","pt":1646094240131,"mc":[{"id":"1.195395433","rc":[{"atb":[[1.02,0]],"id":28774786},{"atb":[[1.02,1.29]],"id":41286501},{"atb":[[1.02,0]],"id":40835929},{"atb":[[1.02,0]],"id":34135026}],"con":true,"img":false}]}
{"op":"mcm","clk":"5306279218","pt":1646094240231,"mc":[{"id":"1.195395433","rc":[{"atb":[[3.5,3]],"id":28774786},{"atb":[[12,1.5]],"id":41286501},{"atb":[[3,2.94]],"id":40835929},{"atb":[[2.32,2.9]],"id":34135026}],"con":true,"img":false}]}
{"op":"mcm","clk":"5306333077","pt":1646095729623,"mc":[{"id":"1.195395433","rc":[{"spn":6.05,"spf":1.0,"id":28774786},{"spn":46.0,"spf":1.0,"id":41286501},{"spl":[[8.6,2.7]],"id":40835929},{"spn":2.56,"spf":1.0,"id":40835929},{"spn":3.91,"spf":1.0,"id":34135026}],"con":true,"img":false}]}
{"op":"mcm","clk":"5306333975","pt":1646095750842,"mc":[{"id":"1.195395433","rc":[{"spl":[[8.6,2.7]],"id":36474395}],"con":true,"img":false}]}
{"op":"mcm","clk":"5306404685","pt":1646097402652,"mc":[{"id":"1.195395433","marketDefinition":{"bspMarket":true,"turnInPlayEnabled":false,"persistenceEnabled":false,"marketBaseRate":7.0,"eventId":"31270458","eventTypeId":"4339","numberOfWinners":1,"bettingType":"ODDS","marketType":"WIN","marketTime":"2022-03-01T04:22:00.000Z","suspendTime":"2022-03-01T04:22:00.000Z","bspReconciled":false,"complete":true,"inPlay":false,"crossMatching":true,"runnersVoidable":false,"numberOfActiveRunners":7,"betDelay":0,"status":"OPEN","runners":[{"status":"ACTIVE","sortPriority":1,"id":28774786,"name":"1. Winklee Casey"},{"status":"ACTIVE","sortPriority":2,"id":32825135,"name":"2. Highland Fame"},{"status":"ACTIVE","sortPriority":3,"id":40835929,"name":"4. Self Control"},{"status":"ACTIVE","sortPriority":4,"id":34135026,"name":"5. Quick Joey Small"},{"status":"ACTIVE","sortPriority":5,"id":36474395,"name":"6. Buckle Up Miri"},{"status":"ACTIVE","sortPriority":6,"id":41286501,"name":"7. Wynburn Stroller"},{"status":"ACTIVE","sortPriority":7,"id":38375776,"name":"8. Blazer"}],"regulators":["MR_INT"],"venue":"Devonport","countryCode":"AU","discountAllowed":true,"timezone":"Australia/Sydney","openDate":"2022-03-01T02:00:00.000Z","version":4380714806,"name":"R8 452m Heat","eventName":"Devonport (AUS) 1st Mar"},"rc":[{"atb":[[32,3.27],[42,2.47],[90,1.14],[1.02,1.32],[55,1.87]],"id":36474395},{"spl":[[8.6,2.7],[100,2]],"id":36474395},{"atl":[[530,0.24],[580,0.22],[630,0.31],[680,0.29],[990,1.27]],"id":36474395},{"spn":69.77,"spf":1.0,"id":36474395},{"atb":[[3.45,45.47],[3.1,53.04],[2.84,60.54],[3.5,3],[2.94,57.42]],"id":28774786},{"spl":[[100,2]],"id":28774786},{"atl":[[8.6,1.33],[12,16.92],[9.8,14.1],[8.8,15.9],[14.5,13.78]],"id":28774786},{"spn":6.05,"spf":1.0,"id":28774786},{"atb":[[4,37.13],[4.5,31.82],[5.3,2.95],[5.2,26.52],[3.75,40.51]],"id":32825135},{"spl":[[100,2]],"id":32825135},{"atl":[[16.5,1.39],[17,7.75],[19.5,6.7],[24,8.09],[29,6.64]],"id":32825135},{"spn":10.9,"spf":1.0,"id":32825135},{"atb":[[7.2,17.96],[9.2,13.58],[8.2,15.47],[11.5,10.61],[1.02,1.29],[12,1.5]],"id":41286501},{"spl":[[100,2]],"id":41286501},{"atl":[[80,1.56],[160,1.16],[210,0.89],[110,1.13],[990,1.32]],"id":41286501},{"spn":46.0,"spf":1.0,"id":41286501},{"atb":[[16.5,7.18],[20,5.86],[21,1.57],[11.5,10.61],[1.02,1.32],[14,8.56]],"id":38375776},{"spl":[[100,2]],"id":38375776},{"atl":[[260,0.71],[310,0.6],[160,0.77],[210,0.59],[990,1.32]],"id":38375776},{"spn":60.5,"spf":1.0,"id":38375776},{"atb":[[2.74,44.21],[3,2.94],[2.64,46.91],[2.98,38.85],[2.84,41.81]],"id":40835929},{"spl":[[8.6,2.7],[1.01,200],[100,2]],"id":40835929},{"atl":[[4,60],[8,21.66],[9,18.95],[10,25.27],[3.95,1.39],[12.5,19.77]],"id":40835929},{"trd":[[3.45,79.95]],"ltp":3.45,"tv":79.95,"id":40835929},{"spn":2.56,"spf":1.0,"id":40835929},{"atb":[[2.32,2.9],[2.3,85.69],[2.06,105.09],[1.98,113.67],[2.16,96.03]],"id":34135026},{"spl":[[100,2]],"id":34135026},{"atl":[[5.6,26.97],[7.2,30.02],[6.2,23.86],[5.5,1.3],[8.2,25.85]],"id":34135026},{"spn":3.91,"spf":1.0,"id":34135026}],"con":true,"img":true}]}
{"op":"mcm","clk":"5306496515","pt":1646099574077,"mc":[{"id":"1.195395433","rc":[{"spn":69.77,"spf":1.0,"id":36474395},{"atb":[[3.5,7.05]],"id":28774786}],"con":true,"img":false}]}
{"op":"mcm","clk":"5306496519","pt":1646099574178,"mc":[{"id":"1.195395433","rc":[{"atb":[[5.3,5.31]],"id":32825135}],"con":true,"img":false}]}
{"op":"mcm","clk":"5306496524","pt":1646099574281,"mc":[{"id":"1.195395433","rc":[{"atb":[[2.34,7.54]],"id":34135026}],"con":true,"img":false}]}
{"op":"mcm","clk":"5306496535","pt":1646099574590,"mc":[{"id":"1.195395433","rc":[{"atb":[[2.32,1.31]],"id":34135026}],"con":true,"img":false}]}
{"op":"mcm","clk":"5306496541","pt":1646099574641,"mc":[{"id":"1.195395433","rc":[{"atb":[[2.36,1.59]],"id":34135026}],"con":true,"img":false}]}
{"op":"mcm","clk":"5306496579","pt":1646099575359,"mc":[{"id":"1.195395433","rc":[{"atb":[[2.32,0]],"id":34135026}],"con":true,"img":false}]}
{"op":"mcm","clk":"5306496585","pt":1646099575463,"mc":[{"id":"1.195395433","rc":[{"atb":[[2.36,2.9]],"id":34135026}],"con":true,"img":false}]}
{"op":"mcm","clk":"5306499015","pt":1646099630237,"mc":[{"id":"1.195395433","rc":[{"atb":[[3.5,10.65]],"id":28774786},{"atb":[[1.01,2.23]],"id":32825135},{"atb":[[2.34,14.27]],"id":34135026}],"con":true,"img":false}]}
{"op":"mcm","clk":"5306499035","pt":1646099630546,"mc":[{"id":"1.195395433","rc":[{"atb":[[1.01,2.1]],"id":32825135}],"con":true,"img":false}]}
{"op":"mcm","clk":"5306499046","pt":1646099630751,"mc":[{"id":"1.195395433","rc":[{"atb":[[1.01,0]],"id":32825135}],"con":true,"img":false}]}
{"op":"mcm","clk":"5306499055","pt":1646099630855,"mc":[{"id":"1.195395433","rc":[{"atb":[[5.3,7.41]],"id":32825135}],"con":true,"img":false}]}
{"op":"mcm","clk":"5306566931","pt":1646101065207,"mc":[{"id":"1.195395433","marketDefinition":{"bspMarket":true,"turnInPlayEnabled":false,"persistenceEnabled":false,"marketBaseRate":7.0,"eventId":"31270458","eventTypeId":"4339","numberOfWinners":1,"bettingType":"ODDS","marketType":"WIN","marketTime":"2022-03-01T04:42:00.000Z","suspendTime":"2022-03-01T04:42:00.000Z","bspReconciled":false,"complete":true,"inPlay":false,"crossMatching":true,"runnersVoidable":false,"numberOfActiveRunners":7,"betDelay":0,"status":"OPEN","runners":[{"status":"ACTIVE","sortPriority":1,"id":28774786,"name":"1. Winklee Casey"},{"status":"ACTIVE","sortPriority":2,"id":32825135,"name":"2. Highland Fame"},{"status":"ACTIVE","sortPriority":3,"id":40835929,"name":"4. Self Control"},{"status":"ACTIVE","sortPriority":4,"id":34135026,"name":"5. Quick Joey Small"},{"status":"ACTIVE","sortPriority":5,"id":36474395,"name":"6. Buckle Up Miri"},{"status":"ACTIVE","sortPriority":6,"id":41286501,"name":"7. Wynburn Stroller"},{"status":"ACTIVE","sortPriority":7,"id":38375776,"name":"8. Blazer"}],"regulators":["MR_INT"],"venue":"Devonport","countryCode":"AU","discountAllowed":true,"timezone":"Australia/Sydney","openDate":"2022-03-01T02:00:00.000Z","version":4381057846,"name":"R8 452m Heat","eventName":"Devonport (AUS) 1st Mar"},"rc":[],"con":true,"img":false}]}
{"op":"mcm","clk":"5306639983","pt":1646102631572,"mc":[{"id":"1.195395433","rc":[{"atb":[[32,3.27],[42,2.47],[90,1.14],[1.02,1.32],[55,1.87]],"id":36474395},{"spl":[[8.6,2.7]],"id":36474395},{"atl":[[530,0.24],[630,0.31],[680,0.29],[990,1.27]],"id":36474395},{"atb":[[3.45,45.48],[3.1,53.07],[2.84,60.57],[3.5,10.65],[2.94,57.44]],"id":28774786},{"atl":[[8.6,1.33],[12,16.93],[9.8,14.1],[8.8,15.91],[14.5,13.79]],"id":28774786},{"atb":[[4,0],[4.5,0],[5.3,7.41],[5.2,0],[3.75,0]],"id":32825135},{"atl":[[16.5,1.39],[17,0],[19.5,0],[24,0],[29,0]],"id":32825135},{"atb":[[7.2,0],[9.2,0],[8.2,0],[11.5,0],[1.02,1.29],[12,1.5]],"id":41286501},{"atl":[[80,0],[160,0],[210,0],[110,0],[990,1.32]],"id":41286501},{"spn":56.0,"spf":1.0,"id":41286501},{"atb":[[16.5,7.19],[20,5.86],[21,1.57],[11.5,10.61],[1.02,1.32],[14,8.57]],"id":38375776},{"atl":[[260,0.71],[310,0.6],[160,0.77],[210,0.59],[990,1.31]],"id":38375776},{"atb":[[2.74,44.23],[3,2.94],[2.64,46.93],[2.98,38.87],[2.84,41.83]],"id":40835929},{"spl":[[8.6,2.7]],"id":40835929},{"atl":[[8,21.67],[9,18.96],[10,25.28],[3.95,1.39],[12.5,19.78]],"id":40835929},{"trd":[[3.45,79.97]],"ltp":3.45,"tv":79.97,"id":40835929},{"spn":2.56,"spf":1.0,"id":40835929},{"atb":[[2.36,2.9],[2.3,0],[2.06,0],[1.98,0],[2.16,0],[2.34,14.26]],"id":34135026},{"atl":[[5.6,0],[7.2,0],[6.2,0],[5.5,1.3],[8.2,0]],"id":34135026},{"spn":3.93,"spf":1.0,"id":34135026}],"con":true,"img":false}]}
{"op":"mcm","clk":"5306640029","pt":1646102632238,"mc":[{"id":"1.195395433","rc":[{"atb":[[5.3,5.77]],"id":32825135},{"atb":[[12,0]],"id":41286501},{"atb":[[2.36,1.31]],"id":34135026}],"con":true,"img":false}]}
{"op":"mcm","clk":"5306640034","pt":1646102632341,"mc":[{"id":"1.195395433","rc":[{"atb":[[1.01,1.63]],"id":32825135},{"atl":[[16.5,0]],"id":32825135},{"atb":[[1.02,2.79]],"id":41286501},{"atb":[[1.01,1.59]],"id":34135026},{"atl":[[5.5,0]],"id":34135026}],"con":true,"img":false}]}
{"op":"mcm","clk":"5306640041","pt":1646102632442,"mc":[{"id":"1.195395433","rc":[{"atl":[[990,1.39]],"id":32825135},{"atl":[[990,1.3]],"id":34135026}],"con":true,"img":false}]}
{"op":"mcm","clk":"5306640047","pt":1646102632544,"mc":[{"id":"1.195395433","rc":[{"atb":[[5.3,4.45]],"id":32825135},{"atb":[[2.36,0]],"id":34135026}],"con":true,"img":false}]}
{"op":"mcm","clk":"5306640052","pt":1646102632647,"mc":[{"id":"1.195395433","rc":[{"atb":[[1.02,1.31]],"id":32825135},{"atb":[[1.02,1.31]],"id":34135026}],"con":true,"img":false}]}
{"op":"mcm","clk":"5306640205","pt":1646102635883,"mc":[{"id":"1.195395433","rc":[{"atb":[[4,37.15],[3.5,44.58],[3.75,40.52],[4.7,30.12]],"id":32825135},{"atl":[[16,8.27],[18.5,7.09],[22,8.86],[27,7.16]],"id":32825135},{"atb":[[7.2,17.97],[9.2,13.59],[8.2,15.48],[11.5,10.61]],"id":41286501},{"atl":[[80,1.56],[160,1.16],[210,0.89],[110,1.13]],"id":41286501},{"atb":[[2.3,85.73],[2.06,105.14],[1.98,113.72],[2.16,96.07]],"id":34135026},{"atl":[[5.6,26.98],[7.2,30.03],[6.2,23.87],[8.2,25.86]],"id":34135026}],"con":true,"img":false}]}
{"op":"mcm","clk":"5306640230","pt":1646102636444,"mc":[{"id":"1.195395433","rc":[{"atl":[[990,0]],"id":32825135},{"atb":[[1.02,1.29]],"id":41286501},{"atb":[[1.01,0]],"id":34135026},{"atl":[[990,0]],"id":34135026}],"con":true,"img":false}]}
{"op":"mcm","clk":"5306640236","pt":1646102636546,"mc":[{"id":"1.195395433","rc":[{"atl":[[15.5,1.39]],"id":32825135},{"atb":[[12,1.5]],"id":41286501},{"atb":[[2.36,1.59]],"id":34135026},{"atl":[[5.5,1.3]],"id":34135026}],"con":true,"img":false}]}
{"op":"mcm","clk":"5306640246","pt":1646102636752,"mc":[{"id":"1.195395433","rc":[{"atb":[[1.02,0]],"id":34135026}],"con":true,"img":false}]}
{"op":"mcm","clk":"5306640252","pt":1646102636855,"mc":[{"id":"1.195395433","rc":[{"atb":[[2.36,2.9]],"id":34135026}],"con":true,"img":false}]}
{"op":"mcm","clk":"5306640324","pt":1646102638034,"mc":[{"id":"1.195395433","rc":[{"atb":[[5.3,2.35]],"id":32825135}],"con":true,"img":false}]}
{"op":"mcm","clk":"5306640342","pt":1646102638340,"mc":[{"id":"1.195395433","rc":[{"atb":[[1.02,0]],"id":32825135}],"con":true,"img":false}]}
{"op":"mcm","clk":"5306640348","pt":1646102638442,"mc":[{"id":"1.195395433","rc":[{"atb":[[4.8,1.31]],"id":32825135}],"con":true,"img":false}]}
{"op":"mcm","clk":"5306640894","pt":1646102649369,"mc":[{"id":"1.195395433","rc":[{"atb":[[5.3,0]],"id":32825135}],"con":true,"img":false}]}
{"op":"mcm","clk":"5306640913","pt":1646102649782,"mc":[{"id":"1.195395433","rc":[{"atb":[[1.01,0]],"id":32825135}],"con":true,"img":false}]}
{"op":"mcm","clk":"5306640921","pt":1646102649884,"mc":[{"id":"1.195395433","rc":[{"atb":[[4.8,2.95]],"id":32825135}],"con":true,"img":false}]}
{"op":"mcm","clk":"5306641086","pt":1646102652959,"mc":[{"id":"1.195395433","rc":[{"atb":[[4.8,5.32]],"id":32825135}],"con":true,"img":false}]}
{"op":"mcm","clk":"5306641195","pt":1646102654952,"mc":[{"id":"1.195395433","rc":[{"atb":[[4.8,7.98]],"id":32825135}],"con":true,"img":false}]}
{"op":"mcm","clk":"5306653014","pt":1646102802685,"mc":[{"id":"1.195395433","marketDefinition":{"bspMarket":true,"turnInPlayEnabled":false,"persistenceEnabled":false,"marketBaseRate":7.0,"eventId":"31270458","eventTypeId":"4339","numberOfWinners":1,"bettingType":"ODDS","marketType":"WIN","marketTime":"2022-03-01T04:42:00.000Z","suspendTime":"2022-03-01T04:42:00.000Z","bspReconciled":false,"complete":true,"inPlay":false,"crossMatching":true,"runnersVoidable":false,"numberOfActiveRunners":7,"betDelay":0,"status":"OPEN","runners":[{"status":"ACTIVE","sortPriority":1,"id":28774786,"name":"1. Winklee Casey"},{"status":"ACTIVE","sortPriority":2,"id":32825135,"name":"2. Highland Fame"},{"status":"ACTIVE","sortPriority":3,"id":40835929,"name":"4. Self Control"},{"status":"ACTIVE","sortPriority":4,"id":34135026,"name":"5. Quick Joey Small"},{"status":"ACTIVE","sortPriority":5,"id":36474395,"name":"6. Buckle Up Miri"},{"status":"ACTIVE","sortPriority":6,"id":41286501,"name":"7. Wynburn Stroller"},{"status":"ACTIVE","sortPriority":7,"id":38375776,"name":"8. Blazer"}],"regulators":["MR_INT"],"venue":"Devonport","countryCode":"AU","discountAllowed":true,"timezone":"Australia/Sydney","openDate":"2022-03-01T02:00:00.000Z","version":4381057846,"name":"R8 452m Heat","eventName":"Devonport (AUS) 1st Mar"},"rc":[{"atb":[[32,3.27],[42,2.47],[90,1.14],[1.02,1.32],[55,1.87]],"id":36474395},{"spl":[[8.6,2.7],[100,2]],"id":36474395},{"atl":[[530,0.24],[580,0.22],[630,0.31],[680,0.29],[990,1.27]],"id":36474395},{"spn":69.77,"spf":1.0,"id":36474395},{"atb":[[3.45,45.48],[3.1,53.07],[2.84,60.57],[3.5,10.65],[2.94,57.44]],"id":28774786},{"spl":[[100,2]],"id":28774786},{"atl":[[8.6,1.33],[12,16.93],[9.8,14.1],[8.8,15.91],[14.5,13.79]],"id":28774786},{"spn":6.05,"spf":1.0,"id":28774786},{"atb":[[4.8,7.98],[4,37.15],[3.5,44.58],[3.75,40.52],[4.7,30.12]],"id":32825135},{"spl":[[100,2]],"id":32825135},{"atl":[[16,8.27],[18.5,7.09],[22,8.86],[27,7.16],[15.5,1.39]],"id":32825135},{"spn":10.15,"spf":1.0,"id":32825135},{"atb":[[7.2,17.97],[9.2,13.59],[8.2,15.48],[11.5,10.61],[1.02,1.29],[12,1.5]],"id":41286501},{"spl":[[100,2]],"id":41286501},{"atl":[[80,1.56],[160,1.16],[210,0.89],[110,1.13],[990,1.32]],"id":41286501},{"spn":46.0,"spf":1.0,"id":41286501},{"atb":[[16.5,7.19],[20,5.86],[21,1.57],[11.5,10.61],[1.02,1.32],[14,8.57]],"id":38375776},{"spl":[[100,2]],"id":38375776},{"atl":[[260,0.71],[310,0.6],[160,0.77],[210,0.59],[990,1.31]],"id":38375776},{"spn":60.5,"spf":1.0,"id":38375776},{"atb":[[2.74,44.23],[3,2.94],[2.64,46.93],[2.98,38.87],[2.84,41.83]],"id":40835929},{"spl":[[8.6,2.7],[1.01,200],[100,2]],"id":40835929},{"atl":[[4,60],[8,21.67],[9,18.96],[10,25.28],[3.95,1.39],[12.5,19.78]],"id":40835929},{"trd":[[3.45,79.97]],"ltp":3.45,"tv":79.97,"id":40835929},{"spn":2.56,"spf":1.0,"id":40835929},{"atb":[[2.36,2.9],[2.3,85.73],[2.06,105.14],[1.98,113.72],[2.16,96.07],[2.34,14.26]],"id":34135026},{"spl":[[100,2]],"id":34135026},{"atl":[[5.6,26.98],[7.2,30.03],[6.2,23.87],[5.5,1.3],[8.2,25.86]],"id":34135026},{"spn":3.93,"spf":1.0,"id":34135026}],"con":true,"img":true}]}
{"op":"mcm","clk":"5306667895","pt":1646103125962,"mc":[{"id":"1.195395433","rc":[{"atb":[[2.24,58.06]],"id":28774786},{"atb":[[2.9,37.89]],"id":32825135},{"spn":10.15,"spf":1.0,"id":32825135},{"spn":46.0,"spf":1.0,"id":41286501},{"atb":[[1.92,78.26]],"id":40835929},{"spn":2.68,"spf":1.0,"id":40835929},{"atb":[[1.61,118.03]],"id":34135026}],"con":true,"img":false}]}
{"op":"mcm","clk":"5306667898","pt":1646103126064,"mc":[{"id":"1.195395433","rc":[{"atb":[[16,4.8],[2.62,46.3]],"id":36474395},{"atl":[[16,8.2]],"id":28774786},{"atl":[[38,8.2]],"id":32825135},{"atb":[[6.2,13.85],[2.62,46.3]],"id":41286501},{"atb":[[10.5,7.58]],"id":38375776},{"atl":[[6.8,8.2]],"id":40835929},{"atl":[[9.8,8.2]],"id":34135026}],"con":true,"img":false}]}
{"op":"mcm","clk":"5306667902","pt":1646103126166,"mc":[{"id":"1.195395433","rc":[{"atb":[[4.2,26.56]],"id":36474395},{"atb":[[2.62,46.3],[4.2,26.56]],"id":38375776},{"atl":[[17,8.5]],"id":40835929},{"atl":[[17,8.5]],"id":34135026}],"con":true,"img":false}]}
{"op":"mcm","clk":"5306667906","pt":1646103126267,"mc":[{"id":"1.195395433","rc":[{"atl":[[34,13.5]],"id":28774786},{"atl":[[34,13.5]],"id":40835929}],"con":true,"img":false}]}
{"op":"mcm","clk":"5306667908","pt":1646103126371,"mc":[{"id":"1.195395433","rc":[{"atl":[[34,13.5]],"id":34135026}],"con":true,"img":false}]}
{"op":"mcm","clk":"5306674312","pt":1646103287226,"mc":[{"id":"1.195395433","marketDefinition":{"bspMarket":true,"turnInPlayEnabled":false,"persistenceEnabled":false,"marketBaseRate":7.0,"eventId":"31270458","eventTypeId":"4339","numberOfWinners":1,"bettingType":"ODDS","marketType":"WIN","marketTime":"2022-03-01T05:17:00.000Z","suspendTime":"2022-03-01T05:17:00.000Z","bspReconciled":false,"complete":true,"inPlay":false,"crossMatching":true,"runnersVoidable":false,"numberOfActiveRunners":7,"betDelay":0,"status":"OPEN","runners":[{"status":"ACTIVE","sortPriority":1,"id":28774786,"name":"1. Winklee Casey"},{"status":"ACTIVE","sortPriority":2,"id":32825135,"name":"2. Highland Fame"},{"status":"ACTIVE","sortPriority":3,"id":40835929,"name":"4. Self Control"},{"status":"ACTIVE","sortPriority":4,"id":34135026,"name":"5. Quick Joey Small"},{"status":"ACTIVE","sortPriority":5,"id":36474395,"name":"6. Buckle Up Miri"},{"status":"ACTIVE","sortPriority":6,"id":41286501,"name":"7. Wynburn Stroller"},{"status":"ACTIVE","sortPriority":7,"id":38375776,"name":"8. Blazer"}],"regulators":["MR_INT"],"venue":"Devonport","countryCode":"AU","discountAllowed":true,"timezone":"Australia/Sydney","openDate":"2022-03-01T02:00:00.000Z","version":4381083921,"name":"R8 452m Heat","eventName":"Devonport (AUS) 1st Mar"},"rc":[],"con":true,"img":false}]}
{"op":"mcm","clk":"5306740846","pt":1646104893466,"mc":[{"id":"1.195395433","rc":[{"atl":[[3.9,8.11]],"id":34135026},{"spn":3.13,"spf":1.0,"id":34135026}],"con":true,"img":false}]}
{"op":"mcm","clk":"5306742899","pt":1646104938732,"mc":[{"id":"1.195395433","rc":[{"atl":[[3.3,4.89]],"id":34135026}],"con":true,"img":false}]}
{"op":"mcm","clk":"5306742924","pt":1646104939350,"mc":[{"id":"1.195395433","rc":[{"atl":[[5.5,0]],"id":34135026}],"con":true,"img":false}]}
{"op":"mcm","clk":"5306742931","pt":1646104939453,"mc":[{"id":"1.195395433","rc":[{"atl":[[3.25,1.3]],"id":34135026}],"con":true,"img":false}]}
{"op":"mcm","clk":"5306763985","pt":1646105520112,"mc":[{"id":"1.195395433","rc":[{"atb":[[95,0.12]],"id":36474395},{"spn":71.54,"spf":1.0,"id":36474395},{"atb":[[3.55,2]],"id":28774786},{"spn":6.07,"spf":1.0,"id":28774786},{"atb":[[5.1,2]],"id":32825135},{"spn":10.3,"spf":1.0,"id":32825135},{"atb":[[12.5,0.88]],"id":41286501},{"spn":46.25,"spf":1.0,"id":41286501},{"atb":[[22,0.49]],"id":38375776},{"spn":61.0,"spf":1.0,"id":38375776},{"atb":[[2.16,98.07]],"id":34135026},{"spn":2.8,"spf":1.0,"id":34135026}],"con":true,"img":false}]}
{"op":"mcm","clk":"5306763997","pt":1646105520728,"mc":[{"id":"1.195395433","rc":[{"atb":[[3.5,8.99]],"id":28774786}],"con":true,"img":false}]}
{"op":"mcm","clk":"5306764001","pt":1646105520781,"mc":[{"id":"1.195395433","rc":[{"atb":[[3.55,3.66]],"id":28774786}],"con":true,"img":false}]}
{"op":"mcm","clk":"5306764028","pt":1646105522413,"mc":[{"id":"1.195395433","rc":[{"atb":[[4.2,26.56]],"id":41286501}],"con":true,"img":false}]}
{"op":"mcm","clk":"5306765267","pt":1646105575868,"mc":[{"id":"1.195395433","rc":[{"atb":[[22,0]],"id":38375776}],"con":true,"img":false}]}
{"op":"mcm","clk":"5306765269","pt":1646105575970,"mc":[{"id":"1.195395433","rc":[{"atb":[[21,2.08]],"id":38375776}],"con":true,"img":false}]}
{"op":"mcm","clk":"5306779783","pt":1646106059214,"mc":[{"id":"1.195395433","rc":[{"atb":[[5.1,0]],"id":32825135},{"spn":10.15,"spf":1.0,"id":32825135},{"atb":[[21,1.57]],"id":38375776},{"spn":60.5,"spf":1.0,"id":38375776},{"atb":[[2.16,96.07]],"id":34135026}],"con":true,"img":false}]}
{"op":"mcm","clk":"5306779786","pt":1646106059317,"mc":[{"id":"1.195395433","rc":[{"atb":[[95,0]],"id":36474395},{"atb":[[3.55,1.66]],"id":28774786},{"atb":[[12.5,0]],"id":41286501}],"con":true,"img":false}]}
{"op":"mcm","clk":"5306792741","pt":1646106461199,"mc":[{"id":"1.195395433","rc":[{"atb":[[80,2.7],[60,2.7]],"id":36474395},{"spn":84.22,"spf":1.0,"id":36474395},{"atb":[[3.5,76.57]],"id":28774786},{"atl":[[7.2,9.36],[8.6,15.92]],"id":28774786},{"spn":5.37,"spf":1.0,"id":28774786},{"atb":[[4.8,23.25],[4.1,40.04]],"id":32825135},{"atl":[[10.5,6.1],[14.5,8.65]],"id":32825135},{"spn":7.65,"spf":1.0,"id":32825135},{"atb":[[12,6.77],[9.4,15.15]],"id":41286501},{"atl":[[34,2.7],[46,2.7]],"id":41286501},{"spn":23.0,"spf":1.0,"id":41286501},{"atb":[[17,7.08],[21,4.47]],"id":38375776},{"atl":[[140,2.7],[100,2.7]],"id":38375776},{"atb":[[2.86,59.92],[3,31.96]],"id":40835929},{"atl":[[5.6,12.61],[7.8,16.38]],"id":40835929},{"spn":2.88,"spf":1.0,"id":40835929},{"atb":[[2.18,49.18],[2.08,122.28]],"id":34135026},{"atl":[[3.85,20.36],[5,29.21]],"id":34135026}],"con":true,"img":false}]}
{"op":"mcm","clk":"5306792754","pt":1646106461602,"mc":[{"id":"1.195395433","rc":[{"atb":[[3,30.68]],"id":40835929}],"con":true,"img":false}]}
{"op":"mcm","clk":"5306792760","pt":1646106461704,"mc":[{"id":"1.195395433","rc":[{"atb":[[1.02,1.27]],"id":40835929}],"con":true,"img":false}]}
{"op":"mcm","clk":"5306792768","pt":1646106461910,"mc":[{"id":"1.195395433","rc":[{"atl":[[8.6,14.59]],"id":28774786}],"con":true,"img":false}]}
{"op":"mcm","clk":"5306792772","pt":1646106462012,"mc":[{"id":"1.195395433","rc":[{"atl":[[7,1.33]],"id":28774786}],"con":true,"img":false}]}
{"op":"mcm","clk":"5306793000","pt":1646106469419,"mc":[{"id":"1.195395433","rc":[{"atb":[[3.5,72.96]],"id":28774786},{"atb":[[4.8,20.88]],"id":32825135}],"con":true,"img":false}]}
{"op":"mcm","clk":"5306793249","pt":1646106477336,"mc":[{"id":"1.195395433","rc":[{"atb":[[3.5,68.92]],"id":28774786},{"atb":[[4.8,18.22]],"id":32825135}],"con":true,"img":false}]}
{"op":"mcm","clk":"5306793280","pt":1646106478354,"mc":[{"id":"1.195395433","rc":[{"atb":[[3.55,4.58]],"id":28774786},{"atb":[[1.01,2.23]],"id":32825135}],"con":true,"img":false}]}
{"op":"mcm","clk":"5306793287","pt":1646106478558,"mc":[{"id":"1.195395433","rc":[{"atb":[[1.01,1.9]],"id":32825135}],"con":true,"img":false}]}
{"op":"mcm","clk":"5306793291","pt":1646106478714,"mc":[{"id":"1.195395433","rc":[{"atb":[[1.01,0]],"id":32825135}],"con":true,"img":false}]}
{"op":"mcm","clk":"5306793294","pt":1646106478814,"mc":[{"id":"1.195395433","rc":[{"atb":[[4.9,1.9]],"id":32825135}],"con":true,"img":false}]}
{"op":"mcm","clk":"5306793298","pt":1646106479019,"mc":[{"id":"1.195395433","rc":[{"atb":[[3.5,67.58]],"id":28774786}],"con":true,"img":false}]}
{"op":"mcm","clk":"5306793301","pt":1646106479121,"mc":[{"id":"1.195395433","rc":[{"atb":[[3.55,5.92]],"id":28774786}],"con":true,"img":false}]}
{"op":"mcm","clk":"5306793437","pt":1646106483267,"mc":[{"id":"1.195395433","rc":[{"atb":[[3.55,9.2]],"id":28774786}],"con":true,"img":false}]}
{"op":"mcm","clk":"5306793442","pt":1646106483370,"mc":[{"id":"1.195395433","rc":[{"atb":[[4.9,4.04]],"id":32825135}],"con":true,"img":false}]}
{"op":"mcm","clk":"5306793461","pt":1646106483831,"mc":[{"id":"1.195395433","rc":[{"atb":[[4.8,15.26]],"id":32825135}],"con":true,"img":false}]}
{"op":"mcm","clk":"5306793466","pt":1646106483933,"mc":[{"id":"1.195395433","rc":[{"atb":[[5,1.63],[4.9,5.36]],"id":32825135}],"con":true,"img":false}]}
{"op":"mcm","clk":"5306794207","pt":1646106501380,"mc":[{"id":"1.195395433","rc":[{"atb":[[4.9,3.22]],"id":32825135}],"con":true,"img":false}]}
{"op":"mcm","clk":"5306794458","pt":1646106507468,"mc":[{"id":"1.195395433","rc":[{"atb":[[4.8,17.46]],"id":32825135}],"con":true,"img":false}]}
{"op":"mcm","clk":"5306794587","pt":1646106511197,"mc":[{"id":"1.195395433","rc":[{"atb":[[80,0]],"id":36474395}],"con":true,"img":false}]}
{"op":"mcm","clk":"5306794595","pt":1646106511300,"mc":[{"id":"1.195395433","rc":[{"atb":[[95,2.7]],"id":36474395}],"con":true,"img":false}]}
{"op":"mcm","clk":"5306797141","pt":1646106600114,"mc":[{"id":"1.195395433","rc":[{"atb":[[95,2.82]],"id":36474395},{"spn":95.0,"spf":1.0,"id":36474395},{"atb":[[3.65,2]],"id":28774786},{"spn":5.32,"spf":1.0,"id":28774786},{"atb":[[4.9,5.22]],"id":32825135},{"spn":7.75,"spf":1.0,"id":32825135},{"atb":[[12.5,0.88]],"id":41286501},{"spn":23.25,"spf":1.0,"id":41286501},{"atb":[[21,4.98]],"id":38375776},{"spn":2.88,"spf":1.0,"id":40835929},{"atb":[[2.32,2]],"id":34135026}],"con":true,"img":false}]}
{"op":"mcm","clk":"5306797148","pt":1646106600317,"mc":[{"id":"1.195395433","rc":[{"atl":[[3.9,0]],"id":34135026}],"con":true,"img":false}]}
{"op":"mcm","clk":"5306797152","pt":1646106600419,"mc":[{"id":"1.195395433","rc":[{"atb":[[3.55,7.53]],"id":28774786},{"atl":[[3.85,28.47]],"id":34135026}],"con":true,"img":false}]}
{"op":"mcm","clk":"5306797156","pt":1646106600523,"mc":[{"id":"1.195395433","rc":[{"atb":[[3.65,3.66]],"id":28774786}],"con":true,"img":false}]}
{"op":"mcm","clk":"5306798329","pt":1646106639783,"mc":[{"id":"1.195395433","rc":[{"atb":[[12,1.5]],"id":41286501}],"con":true,"img":false}]}
{"op":"mcm","clk":"5306798333","pt":1646106639885,"mc":[{"id":"1.195395433","rc":[{"atb":[[10.5,5.27]],"id":41286501}],"con":true,"img":false}]}
{"op":"mcm","clk":"5306798348","pt":1646106640450,"mc":[{"id":"1.195395433","rc":[{"atb":[[1.02,0]],"id":41286501}],"con":true,"img":false}]}
{"op":"mcm","clk":"5306798350","pt":1646106640550,"mc":[{"id":"1.195395433","rc":[{"atb":[[12,2.79]],"id":41286501}],"con":true,"img":false}]}
{"op":"mcm","clk":"5306798989","pt":1646106660321,"mc":[{"id":"1.195395433","rc":[{"atl":[[10.5,0]],"id":32825135},{"spn":9.75,"spf":1.0,"id":32825135},{"atl":[[34,0]],"id":41286501},{"spn":29.25,"spf":1.0,"id":41286501},{"atb":[[2.86,0]],"id":40835929},{"spn":2.82,"spf":1.0,"id":40835929}],"con":true,"img":false}]}
{"op":"mcm","clk":"5306798998","pt":1646106660374,"mc":[{"id":"1.195395433","rc":[{"atl":[[11.5,6.1]],"id":32825135},{"atl":[[32,2.7]],"id":41286501},{"atb":[[2.76,59.92]],"id":40835929}],"con":true,"img":false}]}
{"op":"mcm","clk":"5306799009","pt":1646106660735,"mc":[{"id":"1.195395433","rc":[{"atl":[[15.5,0]],"id":32825135}],"con":true,"img":false}]}
{"op":"mcm","clk":"5306799014","pt":1646106660787,"mc":[{"id":"1.195395433","rc":[{"atl":[[11,1.39]],"id":32825135}],"con":true,"img":false}]}
{"op":"mcm","clk":"5306799483","pt":1646106675622,"mc":[{"id":"1.195395433","rc":[{"atl":[[3.85,8.11]],"id":34135026}],"con":true,"img":false}]}
{"op":"mcm","clk":"5306799487","pt":1646106675727,"mc":[{"id":"1.195395433","rc":[{"atl":[[4,20.36]],"id":34135026}],"con":true,"img":false}]}
{"op":"mcm","clk":"5306799960","pt":1646106690513,"mc":[{"id":"1.195395433","rc":[{"atb":[[60,0]],"id":36474395}],"con":true,"img":false}]}
{"op":"mcm","clk":"5306799964","pt":1646106690615,"mc":[{"id":"1.195395433","rc":[{"atb":[[65,2.7]],"id":36474395}],"con":true,"img":false}]}
{"op":"mcm","clk":"5306800582","pt":1646106707465,"mc":[{"id":"1.195395433","rc":[{"atl":[[11.5,0]],"id":32825135}],"con":true,"img":false}]}
{"op":"mcm","clk":"5306800584","pt":1646106707568,"mc":[{"id":"1.195395433","rc":[{"atl":[[10.5,6.1]],"id":32825135}],"con":true,"img":false}]}
{"op":"mcm","clk":"5306800602","pt":1646106708230,"mc":[{"id":"1.195395433","rc":[{"atl":[[11,0]],"id":32825135}],"con":true,"img":false}]}
{"op":"mcm","clk":"5306800605","pt":1646106708333,"mc":[{"id":"1.195395433","rc":[{"atl":[[1000,1.39]],"id":32825135}],"con":true,"img":false}]}
{"op":"mcm","clk":"5306801139","pt":1646106723772,"mc":[{"id":"1.195395433","rc":[{"atb":[[3.7,2.5]],"id":28774786},{"spn":5.35,"spf":1.0,"id":28774786},{"atb":[[5.1,2.5]],"id":32825135},{"spn":7.8,"spf":1.0,"id":32825135},{"atb":[[13,2.08]],"id":41286501},{"spn":22.5,"spf":1.0,"id":41286501},{"atb":[[22,1.66]],"id":38375776},{"spn":61.0,"spf":1.0,"id":38375776},{"spn":2.85,"spf":1.0,"id":40835929},{"atb":[[2.38,2.5]],"id":34135026},{"spn":2.81,"spf":1.0,"id":34135026}],"con":true,"img":false}]}
{"op":"mcm","clk":"5306801164","pt":1646106724593,"mc":[{"id":"1.195395433","rc":[{"atb":[[3.65,2]],"id":28774786},{"atb":[[5,0]],"id":32825135},{"atb":[[12,1.29]],"id":41286501},{"atb":[[2.36,1.31]],"id":34135026}],"con":true,"img":false}]}
{"op":"mcm","clk":"5306801167","pt":1646106724696,"mc":[{"id":"1.195395433","rc":[{"atb":[[3.7,4.16]],"id":28774786},{"atb":[[5.1,4.14]],"id":32825135},{"atb":[[13,3.59]],"id":41286501},{"atb":[[2.38,4.09]],"id":34135026}],"con":true,"img":false}]}
{"op":"mcm","clk":"5306801209","pt":1646106726077,"mc":[{"id":"1.195395433","rc":[{"atb":[[4.9,3.9]],"id":32825135},{"atb":[[2.36,0]],"id":34135026}],"con":true,"img":false}]}
{"op":"mcm","clk":"5306801211","pt":1646106726180,"mc":[{"id":"1.195395433","rc":[{"atb":[[5.1,5.46]],"id":32825135},{"atb":[[2.38,5.41]],"id":34135026}],"con":true,"img":false}]}
{"op":"mcm","clk":"5306801378","pt":1646106729971,"mc":[{"id":"1.195395433","rc":[{"atl":[[4,0]],"id":34135026}],"con":true,"img":false}]}
{"op":"mcm","clk":"5306801382","pt":1646106730073,"mc":[{"id":"1.195395433","rc":[{"atl":[[3.85,28.47]],"id":34135026}],"con":true,"img":false}]}
{"op":"mcm","clk":"5306801680","pt":1646106738309,"mc":[{"id":"1.195395433","rc":[{"atb":[[2.76,0]],"id":40835929}],"con":true,"img":false}]}
{"op":"mcm","clk":"5306801686","pt":1646106738410,"mc":[{"id":"1.195395433","rc":[{"atb":[[2.86,59.92]],"id":40835929}],"con":true,"img":false}]}
{"op":"mcm","clk":"5306817754","pt":1646107178456,"mc":[{"id":"1.195395433","rc":[{"atb":[[95,2.7]],"id":36474395},{"atb":[[3.65,0]],"id":28774786},{"atb":[[4.9,1.9]],"id":32825135},{"atb":[[12.5,0]],"id":41286501},{"atb":[[21,4.47]],"id":38375776},{"spn":2.88,"spf":1.0,"id":40835929},{"atb":[[2.32,0]],"id":34135026}],"con":true,"img":false}]}
{"op":"mcm","clk":"5306817779","pt":1646107179127,"mc":[{"id":"1.195395433","rc":[{"atb":[[3.7,2.5]],"id":28774786},{"atb":[[5.1,3.82]],"id":32825135},{"atb":[[13,2.08]],"id":41286501}],"con":true,"img":false}]}
{"op":"mcm","clk":"5306817784","pt":1646107179230,"mc":[{"id":"1.195395433","rc":[{"atb":[[1.01,1.66]],"id":28774786},{"atb":[[1.01,1.63]],"id":32825135},{"atb":[[1.01,1.5]],"id":41286501}],"con":true,"img":false}]}
{"op":"mcm","clk":"5306817820","pt":1646107179949,"mc":[{"id":"1.195395433","rc":[{"atb":[[5.1,2.5]],"id":32825135}],"con":true,"img":false}]}
{"op":"mcm","clk":"5306817825","pt":1646107180055,"mc":[{"id":"1.195395433","rc":[{"atb":[[1.02,1.31]],"id":32825135}],"con":true,"img":false}]}
{"op":"mcm","clk":"5306817897","pt":1646107181338,"mc":[{"id":"1.195395433","rc":[{"atb":[[1.02,0]],"id":32825135}],"con":true,"img":false}]}
{"op":"mcm","clk":"5306817901","pt":1646107181441,"mc":[{"id":"1.195395433","rc":[{"atb":[[4.9,3.22]],"id":32825135}],"con":true,"img":false}]}
{"op":"mcm","clk":"5306817917","pt":1646107181855,"mc":[{"id":"1.195395433","rc":[{"atb":[[1.01,0]],"id":32825135}],"con":true,"img":false}]}
{"op":"mcm","clk":"5306817926","pt":1646107181965,"mc":[{"id":"1.195395433","rc":[{"atb":[[5.1,4.14]],"id":32825135}],"con":true,"img":false}]}
{"op":"mcm","clk":"5306819641","pt":1646107216898,"mc":[{"id":"1.195395433","marketDefinition":{"bspMarket":true,"turnInPlayEnabled":false,"persistenceEnabled":false,"marketBaseRate":7.0,"eventId":"31270458","eventTypeId":"4339","numberOfWinners":1,"bettingType":"ODDS","marketType":"WIN","marketTime":"2022-03-01T06:10:00.000Z","suspendTime":"2022-03-01T06:10:00.000Z","bspReconciled":false,"complete":true,"inPlay":false,"crossMatching":true,"runnersVoidable":false,"numberOfActiveRunners":7,"betDelay":0,"status":"OPEN","runners":[{"status":"ACTIVE","sortPriority":1,"id":28774786,"name":"1. Winklee Casey"},{"status":"ACTIVE","sortPriority":2,"id":32825135,"name":"2. Highland Fame"},{"status":"ACTIVE","sortPriority":3,"id":40835929,"name":"4. Self Control"},{"status":"ACTIVE","sortPriority":4,"id":34135026,"name":"5. Quick Joey Small"},{"status":"ACTIVE","sortPriority":5,"id":36474395,"name":"6. Buckle Up Miri"},{"status":"ACTIVE","sortPriority":6,"id":41286501,"name":"7. Wynburn Stroller"},{"status":"ACTIVE","sortPriority":7,"id":38375776,"name":"8. Blazer"}],"regulators":["MR_INT"],"venue":"Devonport","countryCode":"AU","discountAllowed":true,"timezone":"Australia/Sydney","openDate":"2022-03-01T02:00:00.000Z","version":4381118361,"name":"R8 452m Heat","eventName":"Devonport (AUS) 1st Mar"},"rc":[],"con":true,"img":false}]}
{"op":"mcm","clk":"5306823208","pt":1646107326071,"mc":[{"id":"1.195395433","rc":[{"atb":[[65,2.7],[32,3.27],[42,2.47],[90,1.14],[95,2.7],[1.02,1.32],[55,1.87]],"id":36474395},{"spl":[[8.6,2.7]],"id":36474395},{"atl":[[530,0.24],[580,0.22],[630,0.31],[680,0.29],[990,1.27]],"id":36474395},{"atb":[[3.45,45.46],[1.01,1.66],[3.1,53.03],[3.7,2.5],[3.55,7.54],[2.84,60.53],[3.5,67.54],[2.94,57.41]],"id":28774786},{"atl":[[7.2,9.35],[8.6,14.58],[12,16.92],[9.8,14.09],[8.8,15.9],[7,1.33],[14.5,13.78]],"id":28774786},{"atb":[[4.8,17.45],[4,37.12],[5.1,4.14],[4.1,40.01],[4.9,3.22],[3.5,44.55],[3.75,40.5],[4.7,30.1]],"id":32825135},{"atl":[[16,8.26],[18.5,7.08],[10.5,6.1],[22,8.86],[27,7.15],[14.5,8.65],[1000,1.39]],"id":32825135},{"atb":[[7.2,17.96],[1.01,1.5],[9.2,13.58],[10.5,5.27],[8.2,15.47],[11.5,10.6],[12,1.29],[13,2.08],[9.4,15.14]],"id":41286501},{"atl":[[32,2.7],[80,1.56],[160,1.16],[46,2.7],[210,0.89],[110,1.13],[990,1.32]],"id":41286501},{"atb":[[16.5,7.18],[17,7.07],[20,5.86],[21,4.47],[22,1.66],[11.5,10.6],[1.02,1.32],[14,8.56]],"id":38375776},{"atl":[[260,0.71],[140,2.7],[310,0.6],[160,0.77],[100,2.7],[210,0.59],[990,1.31]],"id":38375776},{"atb":[[2.86,59.89],[2.74,44.2],[1.02,1.27],[3,30.66],[2.64,46.9],[2.98,38.84],[2.84,41.8],[3.05,3.38]],"id":40835929},{"spl":[[8.6,2.7]],"id":40835929},{"atl":[[5.6,12.61],[8,21.66],[9,18.95],[10,25.27],[3.95,1.39],[12.5,19.77],[7.8,16.38]],"id":40835929},{"trd":[[3.45,79.95]],"ltp":3.45,"tv":79.95,"id":40835929},{"spn":2.88,"spf":1.0,"id":40835929},{"atb":[[2.3,85.68],[2.06,105.07],[1.98,113.65],[2.38,5.4],[2.18,49.15],[2.16,96.01],[2.34,14.27],[2.08,122.21]],"id":34135026},{"atl":[[5.6,26.96],[7.2,30.01],[3.85,28.46],[5,29.2],[6.2,23.85],[8.2,25.84],[3.25,1.3],[3.3,4.89]],"id":34135026}],"con":true,"img":false}]}
{"op":"mcm","clk":"5306823221","pt":1646107326436,"mc":[{"id":"1.195395433","rc":[{"atb":[[3,28.99]],"id":40835929}],"con":true,"img":false}]}
{"op":"mcm","clk":"5306823228","pt":1646107326535,"mc":[{"id":"1.195395433","rc":[{"atb":[[3.1,1.66]],"id":40835929}],"con":true,"img":false}]}
{"op":"mcm","clk":"5306823358","pt":1646107329354,"mc":[{"id":"1.195395433","rc":[{"atb":[[3.05,0]],"id":40835929}],"con":true,"img":false}]}
{"op":"mcm","clk":"5306823367","pt":1646107329655,"mc":[{"id":"1.195395433","rc":[{"atl":[[3.9,3.38]],"id":40835929}],"con":true,"img":false}]}
{"op":"mcm","clk":"5306823371","pt":1646107329758,"mc":[{"id":"1.195395433","rc":[{"atb":[[3.1,0]],"id":40835929}],"con":true,"img":false}]}
{"op":"mcm","clk":"5306823374","pt":1646107329861,"mc":[{"id":"1.195395433","rc":[{"atb":[[3.05,1.66]],"id":40835929}],"con":true,"img":false}]}
{"op":"mcm","clk":"5306823394","pt":1646107330374,"mc":[{"id":"1.195395433","rc":[{"atl":[[3.95,0]],"id":40835929}],"con":true,"img":false}]}
{"op":"mcm","clk":"5306823398","pt":1646107330475,"mc":[{"id":"1.195395433","rc":[{"atl":[[3.85,1.39]],"id":40835929}],"con":true,"img":false}]}
{"op":"mcm","clk":"5306823636","pt":1646107337287,"mc":[{"id":"1.195395433","rc":[{"atl":[[3.9,0]],"id":40835929}],"con":true,"img":false}]}
{"op":"mcm","clk":"5306823649","pt":1646107337547,"mc":[{"id":"1.195395433","rc":[{"atl":[[3.85,0]],"id":40835929}],"con":true,"img":false}]}
{"op":"mcm","clk":"5306823653","pt":1646107337649,"mc":[{"id":"1.195395433","rc":[{"atl":[[3.95,1.39]],"id":40835929}],"con":true,"img":false}]}
{"op":"mcm","clk":"5306825185","pt":1646107382452,"mc":[{"id":"1.195395433","rc":[{"atl":[[110,9.33]],"id":41286501}],"con":true,"img":false}]}
{"op":"mcm","clk":"5306832427","pt":1646107573418,"mc":[{"id":"1.195395433","rc":[{"spn":2.88,"spf":1.0,"id":40835929},{"atl":[[3.85,8.11]],"id":34135026}],"con":true,"img":false}]}
{"op":"mcm","clk":"5306832429","pt":1646107573521,"mc":[{"id":"1.195395433","rc":[{"atl":[[4,20.34]],"id":34135026}],"con":true,"img":false}]}
{"op":"mcm","clk":"5306833422","pt":1646107609517,"mc":[{"id":"1.195395433","rc":[{"atb":[[10.5,0]],"id":41286501},{"atl":[[5.6,0]],"id":40835929},{"atb":[[2.18,0]],"id":34135026}],"con":true,"img":false}]}
{"op":"mcm","clk":"5306833428","pt":1646107609618,"mc":[{"id":"1.195395433","rc":[{"atb":[[12,6.56]],"id":41286501},{"atl":[[5.5,12.61]],"id":40835929},{"atb":[[2.32,49.15]],"id":34135026}],"con":true,"img":false}]}
{"op":"mcm","clk":"5306833439","pt":1646107610081,"mc":[{"id":"1.195395433","rc":[{"atb":[[1.01,0]],"id":41286501}],"con":true,"img":false}]}
{"op":"mcm","clk":"5306833440","pt":1646107610182,"mc":[{"id":"1.195395433","rc":[{"atb":[[13,3.58]],"id":41286501}],"con":true,"img":false}]}
{"op":"mcm","clk":"5306833442","pt":1646107610285,"mc":[{"id":"1.195395433","rc":[{"atb":[[12,5.27]],"id":41286501}],"con":true,"img":false}]}
{"op":"mcm","clk":"5306833444","pt":1646107610388,"mc":[{"id":"1.195395433","rc":[{"atb":[[1.02,1.29]],"id":41286501}],"con":true,"img":false}]}
{"op":"mcm","clk":"5306833462","pt":1646107611303,"mc":[{"id":"1.195395433","rc":[{"atb":[[2.34,7.53]],"id":34135026}],"con":true,"img":false}]}
{"op":"mcm","clk":"5306833502","pt":1646107613396,"mc":[{"id":"1.195395433","rc":[{"atb":[[2.34,0]],"id":34135026}],"con":true,"img":false}]}
{"op":"mcm","clk":"5306833810","pt":1646107625507,"mc":[{"id":"1.195395433","rc":[{"atb":[[2.36,6.13]],"id":34135026}],"con":true,"img":false}]}
{"op":"mcm","clk":"5306833829","pt":1646107626321,"mc":[{"id":"1.195395433","rc":[{"atb":[[2.36,11.61]],"id":34135026}],"con":true,"img":false}]}
{"op":"mcm","clk":"5306833897","pt":1646107629127,"mc":[{"id":"1.195395433","rc":[{"atb":[[12,0]],"id":41286501},{"atb":[[2.32,0]],"id":34135026}],"con":true,"img":false}]}
{"op":"mcm","clk":"5306833899","pt":1646107629229,"mc":[{"id":"1.195395433","rc":[{"atb":[[10.5,5.27]],"id":41286501},{"atb":[[2.18,49.15]],"id":34135026}],"con":true,"img":false}]}
{"op":"mcm","clk":"5306833903","pt":1646107629535,"mc":[{"id":"1.195395433","rc":[{"atb":[[1.02,0]],"id":41286501}],"con":true,"img":false}]}
{"op":"mcm","clk":"5306833906","pt":1646107629638,"mc":[{"id":"1.195395433","rc":[{"atb":[[12,1.29]],"id":41286501}],"con":true,"img":false}]}
{"op":"mcm","clk":"5306833911","pt":1646107629843,"mc":[{"id":"1.195395433","rc":[{"atb":[[13,2.08]],"id":41286501}],"con":true,"img":false}]}
{"op":"mcm","clk":"5306833912","pt":1646107629944,"mc":[{"id":"1.195395433","rc":[{"atb":[[1.01,1.5]],"id":41286501}],"con":true,"img":false}]}
{"op":"mcm","clk":"5306834119","pt":1646107638325,"mc":[{"id":"1.195395433","rc":[{"atb":[[2.36,6.13]],"id":34135026}],"con":true,"img":false}]}
{"op":"mcm","clk":"5306834241","pt":1646107643438,"mc":[{"id":"1.195395433","rc":[{"atb":[[2.36,0]],"id":34135026}],"con":true,"img":false}]}
{"op":"mcm","clk":"5306834251","pt":1646107643638,"mc":[{"id":"1.195395433","rc":[{"atb":[[2.38,3.81]],"id":34135026}],"con":true,"img":false}]}
{"op":"mcm","clk":"5306834254","pt":1646107643743,"mc":[{"id":"1.195395433","rc":[{"atb":[[1.01,1.59]],"id":34135026}],"con":true,"img":false}]}
{"op":"mcm","clk":"5306834257","pt":1646107643846,"mc":[{"id":"1.195395433","rc":[{"atb":[[2.38,2.5]],"id":34135026}],"con":true,"img":false}]}
{"op":"mcm","clk":"5306834260","pt":1646107643948,"mc":[{"id":"1.195395433","rc":[{"atb":[[2.32,1.31]],"id":34135026}],"con":true,"img":false}]}
{"op":"mcm","clk":"5306834376","pt":1646107647334,"mc":[{"id":"1.195395433","rc":[{"atb":[[2.34,5.56]],"id":34135026}],"con":true,"img":false}]}
{"op":"mcm","clk":"5306834388","pt":1646107647844,"mc":[{"id":"1.195395433","rc":[{"atb":[[2.32,0]],"id":34135026}],"con":true,"img":false}]}
{"op":"mcm","clk":"5306834392","pt":1646107647945,"mc":[{"id":"1.195395433","rc":[{"atb":[[2.34,6.87]],"id":34135026}],"con":true,"img":false}]}
{"op":"mcm","clk":"5306834400","pt":1646107648251,"mc":[{"id":"1.195395433","rc":[{"atl":[[4,0]],"id":34135026}],"con":true,"img":false}]}
{"op":"mcm","clk":"5306834404","pt":1646107648353,"mc":[{"id":"1.195395433","rc":[{"atl":[[3.85,28.46]],"id":34135026}],"con":true,"img":false}]}
{"op":"mcm","clk":"5306834440","pt":1646107649477,"mc":[{"id":"1.195395433","rc":[{"atb":[[2.34,13.1]],"id":34135026}],"con":true,"img":false}]}
{"op":"mcm","clk":"5306834472","pt":1646107650650,"mc":[{"id":"1.195395433","rc":[{"atl":[[7.2,0]],"id":28774786},{"atl":[[10.5,0]],"id":32825135},{"atb":[[2.86,0]],"id":40835929}],"con":true,"img":false}]}
{"op":"mcm","clk":"5306834475","pt":1646107650753,"mc":[{"id":"1.195395433","rc":[{"atl":[[7.4,9.35]],"id":28774786},{"atl":[[12,6.1]],"id":32825135},{"atb":[[2.66,59.89]],"id":40835929}],"con":true,"img":false}]}
{"op":"mcm","clk":"5306834478","pt":1646107650854,"mc":[{"id":"1.195395433","rc":[{"atb":[[1.01,0]],"id":34135026}],"con":true,"img":false}]}
{"op":"mcm","clk":"5306834479","pt":1646107650956,"mc":[{"id":"1.195395433","rc":[{"atb":[[2.38,4.09]],"id":34135026}],"con":true,"img":false}]}
{"op":"mcm","clk":"5306834482","pt":1646107651160,"mc":[{"id":"1.195395433","rc":[{"atl":[[7,0]],"id":28774786},{"atl":[[1000,0]],"id":32825135}],"con":true,"img":false}]}
{"op":"mcm","clk":"5306834484","pt":1646107651263,"mc":[{"id":"1.195395433","rc":[{"atl":[[7.2,1.33]],"id":28774786},{"atl":[[11.5,1.39]],"id":32825135}],"con":true,"img":false}]}
{"op":"mcm","clk":"5306834495","pt":1646107651772,"mc":[{"id":"1.195395433","rc":[{"atb":[[2.34,11.79]],"id":34135026}],"con":true,"img":false}]}
{"op":"mcm","clk":"5306834497","pt":1646107651875,"mc":[{"id":"1.195395433","rc":[{"atb":[[2.38,5.4]],"id":34135026}],"con":true,"img":false}]}
{"op":"mcm","clk":"5306834830","pt":1646107662980,"mc":[{"id":"1.195395433","rc":[{"atb":[[3,0]],"id":40835929}],"con":true,"img":false}]}
{"op":"mcm","clk":"5306834833","pt":1646107663081,"mc":[{"id":"1.195395433","rc":[{"atb":[[2.86,28.99]],"id":40835929}],"con":true,"img":false}]}
{"op":"mcm","clk":"5306834844","pt":1646107663491,"mc":[{"id":"1.195395433","rc":[{"atb":[[3.05,0]],"id":40835929}],"con":true,"img":false}]}
{"op":"mcm","clk":"5306834847","pt":1646107663592,"mc":[{"id":"1.195395433","rc":[{"atb":[[3,1.66]],"id":40835929}],"con":true,"img":false}]}
{"op":"mcm","clk":"5306834853","pt":1646107663796,"mc":[{"id":"1.195395433","rc":[{"atb":[[1.02,0]],"id":40835929}],"con":true,"img":false}]}
{"op":"mcm","clk":"5306834854","pt":1646107663899,"mc":[{"id":"1.195395433","rc":[{"atb":[[3,2.94]],"id":40835929}],"con":true,"img":false}]}
{"op":"mcm","clk":"5306834892","pt":1646107665481,"mc":[{"id":"1.195395433","rc":[{"atl":[[3.85,8.11]],"id":34135026}],"con":true,"img":false}]}
{"op":"mcm","clk":"5306834893","pt":1646107665584,"mc":[{"id":"1.195395433","rc":[{"atl":[[4,20.34]],"id":34135026}],"con":true,"img":false}]}
{"op":"mcm","clk":"5306835862","pt":1646107695631,"mc":[{"id":"1.195395433","rc":[{"atb":[[2.86,0]],"id":40835929},{"atb":[[2.08,0]],"id":34135026}],"con":true,"img":false}]}
{"op":"mcm","clk":"5306835865","pt":1646107695733,"mc":[{"id":"1.195395433","rc":[{"atb":[[3,31.94]],"id":40835929},{"atb":[[1.99,122.21]],"id":34135026}],"con":true,"img":false}]}
{"op":"mcm","clk":"5306835877","pt":1646107696244,"mc":[{"id":"1.195395433","rc":[{"atb":[[3,30.66]],"id":40835929}],"con":true,"img":false}]}
{"op":"mcm","clk":"5306835879","pt":1646107696347,"mc":[{"id":"1.195395433","rc":[{"atb":[[1.02,1.27]],"id":40835929}],"con":true,"img":false}]}
{"op":"mcm","clk":"5306835900","pt":1646107697319,"mc":[{"id":"1.195395433","rc":[{"atb":[[3.05,3.38]],"id":40835929}],"con":true,"img":false}]}
{"op":"mcm","clk":"5306835916","pt":1646107697726,"mc":[{"id":"1.195395433","rc":[{"atb":[[3,28.99]],"id":40835929}],"con":true,"img":false}]}
{"op":"mcm","clk":"5306835920","pt":1646107697828,"mc":[{"id":"1.195395433","rc":[{"atb":[[3.1,1.66]],"id":40835929}],"con":true,"img":false}]}
{"op":"mcm","clk":"5306835951","pt":1646107698905,"mc":[{"id":"1.195395433","rc":[{"spn":5.45,"spf":1.0,"id":28774786},{"spn":8.3,"spf":1.0,"id":32825135},{"atb":[[3.05,0]],"id":40835929},{"spn":2.83,"spf":1.0,"id":40835929}],"con":true,"img":false}]}
{"op":"mcm","clk":"5306835963","pt":1646107699213,"mc":[{"id":"1.195395433","rc":[{"atl":[[3.9,3.38]],"id":40835929}],"con":true,"img":false}]}
{"op":"mcm","clk":"5306835973","pt":1646107699518,"mc":[{"id":"1.195395433","rc":[{"atb":[[3.1,0]],"id":40835929}],"con":true,"img":false}]}
{"op":"mcm","clk":"5306835978","pt":1646107699620,"mc":[{"id":"1.195395433","rc":[{"atb":[[3.05,1.66]],"id":40835929}],"con":true,"img":false}]}
{"op":"mcm","clk":"5306835980","pt":1646107699721,"mc":[{"id":"1.195395433","rc":[{"atl":[[3.95,0]],"id":40835929}],"con":true,"img":false}]}
{"op":"mcm","clk":"5306835982","pt":1646107699822,"mc":[{"id":"1.195395433","rc":[{"atl":[[3.85,1.39]],"id":40835929}],"con":true,"img":false}]}
{"op":"mcm","clk":"5306835998","pt":1646107700537,"mc":[{"id":"1.195395433","rc":[{"atl":[[3.9,0]],"id":40835929}],"con":true,"img":false}]}
{"op":"mcm","clk":"5306836006","pt":1646107701047,"mc":[{"id":"1.195395433","rc":[{"atl":[[3.85,0]],"id":40835929}],"con":true,"img":false}]}
{"op":"mcm","clk":"5306836009","pt":1646107701151,"mc":[{"id":"1.195395433","rc":[{"atl":[[3.95,1.39]],"id":40835929}],"con":true,"img":false}]}
{"op":"mcm","clk":"5306836690","pt":1646107722637,"mc":[{"id":"1.195395433","rc":[{"atb":[[3.5,44.34]],"id":28774786},{"atb":[[4.8,2.19]],"id":32825135},{"atl":[[5.5,0]],"id":40835929},{"atl":[[4,0]],"id":34135026}],"con":true,"img":false}]}
{"op":"mcm","clk":"5306836692","pt":1646107722738,"mc":[{"id":"1.195395433","rc":[{"atb":[[3.6,23.19]],"id":28774786},{"atb":[[4.9,18.48]],"id":32825135},{"atl":[[5.4,12.61]],"id":40835929},{"atl":[[3.8,20.34]],"id":34135026}],"con":true,"img":false}]}
{"op":"mcm","clk":"5306836702","pt":1646107723147,"mc":[{"id":"1.195395433","rc":[{"atb":[[3.55,6.19]],"id":28774786},{"atb":[[4.9,17.17]],"id":32825135}],"con":true,"img":false}]}
{"op":"mcm","clk":"5306836705","pt":1646107723249,"mc":[{"id":"1.195395433","rc":[{"atb":[[3.65,1.34]],"id":28774786},{"atb":[[5.1,5.46]],"id":32825135}],"con":true,"img":false}]}
{"op":"mcm","clk":"5306836714","pt":1646107723555,"mc":[{"id":"1.195395433","rc":[{"atb":[[1.01,0]],"id":28774786}],"con":true,"img":false}]}
{"op":"mcm","clk":"5306836719","pt":1646107723658,"mc":[{"id":"1.195395433","rc":[{"atb":[[3.7,4.16]],"id":28774786}],"con":true,"img":false}]}
{"op":"mcm","clk":"5306836737","pt":1646107724432,"mc":[{"id":"1.195395433","rc":[{"atb":[[3.65,0]],"id":28774786}],"con":true,"img":false}]}
{"op":"mcm","clk":"5306836740","pt":1646107724533,"mc":[{"id":"1.195395433","rc":[{"atb":[[3.7,5.51]],"id":28774786}],"con":true,"img":false}]}
{"op":"mcm","clk":"5306836762","pt":1646107725759,"mc":[{"id":"1.195395433","rc":[{"atl":[[32,0]],"id":41286501},{"atb":[[2.66,0]],"id":40835929},{"atl":[[3.8,0]],"id":34135026}],"con":true,"img":false}]}
{"op":"mcm","clk":"5306836767","pt":1646107725860,"mc":[{"id":"1.195395433","rc":[{"atl":[[34,2.7]],"id":41286501},{"atb":[[2.86,59.89]],"id":40835929},{"atl":[[4,20.34]],"id":34135026}],"con":true,"img":false}]}
{"op":"mcm","clk":"5306836880","pt":1646107729953,"mc":[{"id":"1.195395433","rc":[{"atb":[[3.7,3.84]],"id":28774786}],"con":true,"img":false}]}
{"op":"mcm","clk":"5306836884","pt":1646107730056,"mc":[{"id":"1.195395433","rc":[{"atb":[[3.65,1.66]],"id":28774786}],"con":true,"img":false}]}
{"op":"mcm","clk":"5306836895","pt":1646107730462,"mc":[{"id":"1.195395433","rc":[{"atb":[[3.7,2.5]],"id":28774786}],"con":true,"img":false}]}
{"op":"mcm","clk":"5306836899","pt":1646107730565,"mc":[{"id":"1.195395433","rc":[{"atb":[[3.65,3]],"id":28774786}],"con":true,"img":false}]}
{"op":"mcm","clk":"5306836909","pt":1646107730770,"mc":[{"id":"1.195395433","rc":[{"atb":[[3.65,1.34]],"id":28774786}],"con":true,"img":false}]}
{"op":"mcm","clk":"5306836912","pt":1646107730871,"mc":[{"id":"1.195395433","rc":[{"atb":[[3.75,1.66]],"id":28774786}],"con":true,"img":false}]}
{"op":"mcm","clk":"5306836935","pt":1646107731437,"mc":[{"id":"1.195395433","rc":[{"atb":[[3.55,3.27]],"id":28774786},{"atb":[[4.9,15.26]],"id":32825135}],"con":true,"img":false}]}
{"op":"mcm","clk":"5306836990","pt":1646107732971,"mc":[{"id":"1.195395433","rc":[{"atb":[[3.7,0]],"id":28774786}],"con":true,"img":false}]}
{"op":"mcm","clk":"5306837015","pt":1646107733434,"mc":[{"id":"1.195395433","rc":[{"atb":[[3.8,2.5]],"id":28774786}],"con":true,"img":false}]}
{"op":"mcm","clk":"5306837022","pt":1646107733639,"mc":[{"id":"1.195395433","rc":[{"atb":[[3.75,0]],"id":28774786}],"con":true,"img":false}]}
{"op":"mcm","clk":"5306837029","pt":1646107733742,"mc":[{"id":"1.195395433","rc":[{"atb":[[1.01,1.66]],"id":28774786}],"con":true,"img":false}]}
{"op":"mcm","clk":"5306837084","pt":1646107735578,"mc":[{"id":"1.195395433","rc":[{"atb":[[4.9,0]],"id":32825135}],"con":true,"img":false}]}
{"op":"mcm","clk":"5306837088","pt":1646107735681,"mc":[{"id":"1.195395433","rc":[{"atb":[[4.8,17.45]],"id":32825135}],"con":true,"img":false}]}
{"op":"mcm","clk":"5306837097","pt":1646107735838,"mc":[{"id":"1.195395433","rc":[{"atb":[[5.1,4.14]],"id":32825135}],"con":true,"img":false}]}
{"op":"mcm","clk":"5306837099","pt":1646107735940,"mc":[{"id":"1.195395433","rc":[{"atb":[[1.02,1.31]],"id":32825135}],"con":true,"img":false}]}
{"op":"mcm","clk":"5306837108","pt":1646107736146,"mc":[{"id":"1.195395433","rc":[{"atb":[[5.1,2.5]],"id":32825135}],"con":true,"img":false}]}
{"op":"mcm","clk":"5306837111","pt":1646107736248,"mc":[{"id":"1.195395433","rc":[{"atb":[[1.01,1.63]],"id":32825135}],"con":true,"img":false}]}
{"op":"mcm","clk":"5306837121","pt":1646107736453,"mc":[{"id":"1.195395433","rc":[{"atb":[[1.02,0]],"id":32825135}],"con":true,"img":false}]}
{"op":"mcm","clk":"5306837124","pt":1646107736553,"mc":[{"id":"1.195395433","rc":[{"atb":[[4.9,1.31]],"id":32825135}],"con":true,"img":false}]}
{"op":"mcm","clk":"5306837228","pt":1646107739770,"mc":[{"id":"1.195395433","rc":[{"atb":[[3.55,0]],"id":28774786}],"con":true,"img":false}]}
{"op":"mcm","clk":"5306837245","pt":1646107740588,"mc":[{"id":"1.195395433","rc":[{"atb":[[3.65,4.15]],"id":28774786}],"con":true,"img":false}]}
{"op":"mcm","clk":"5306837416","pt":1646107745654,"mc":[{"id":"1.195395433","rc":[{"atb":[[3.65,7.3]],"id":28774786}],"con":true,"img":false}]}
{"op":"mcm","clk":"5306837629","pt":1646107752569,"mc":[{"id":"1.195395433","rc":[{"atb":[[1.01,3.87]],"id":32825135}],"con":true,"img":false}]}
{"op":"mcm","clk":"5306837632","pt":1646107752670,"mc":[{"id":"1.195395433","rc":[{"atb":[[1.01,3.54]],"id":32825135}],"con":true,"img":false}]}
{"op":"mcm","clk":"5306837639","pt":1646107752873,"mc":[{"id":"1.195395433","rc":[{"atb":[[1.01,1.63]],"id":32825135}],"con":true,"img":false}]}
{"op":"mcm","clk":"5306837645","pt":1646107752975,"mc":[{"id":"1.195395433","rc":[{"atb":[[4.9,3.22]],"id":32825135}],"con":true,"img":false}]}
{"op":"mcm","clk":"5306837662","pt":1646107753434,"mc":[{"id":"1.195395433","rc":[{"atb":[[1.01,0]],"id":32825135}],"con":true,"img":false}]}
{"op":"mcm","clk":"5306837667","pt":1646107753537,"mc":[{"id":"1.195395433","rc":[{"atb":[[5.1,4.14]],"id":32825135}],"con":true,"img":false}]}
{"op":"mcm","clk":"5306837773","pt":1646107755838,"mc":[{"id":"1.195395433","rc":[{"atl":[[12,0]],"id":32825135}],"con":true,"img":false}]}
{"op":"mcm","clk":"5306837775","pt":1646107755941,"mc":[{"id":"1.195395433","rc":[{"atl":[[10.5,6.1]],"id":32825135}],"con":true,"img":false}]}
{"op":"mcm","clk":"5306837784","pt":1646107756248,"mc":[{"id":"1.195395433","rc":[{"atl":[[11.5,0]],"id":32825135}],"con":true,"img":false}]}
{"op":"mcm","clk":"5306837790","pt":1646107756351,"mc":[{"id":"1.195395433","rc":[{"atl":[[1000,1.39]],"id":32825135}],"con":true,"img":false}]}
{"op":"mcm","clk":"5306837794","pt":1646107756454,"mc":[{"id":"1.195395433","rc":[{"atl":[[34,0]],"id":41286501}],"con":true,"img":false}]}
{"op":"mcm","clk":"5306837798","pt":1646107756555,"mc":[{"id":"1.195395433","rc":[{"atl":[[32,2.7]],"id":41286501}],"con":true,"img":false}]}
{"op":"mcm","clk":"5306838177","pt":1646107767255,"mc":[{"id":"1.195395433","rc":[{"spn":5.5,"spf":1.0,"id":28774786},{"spn":7.8,"spf":1.0,"id":32825135},{"atl":[[5.4,0]],"id":40835929},{"spn":2.88,"spf":1.0,"id":40835929}],"con":true,"img":false}]}
{"op":"mcm","clk":"5306838180","pt":1646107767357,"mc":[{"id":"1.195395433","rc":[{"atl":[[5.6,12.61]],"id":40835929}],"con":true,"img":false}]}
{"op":"mcm","clk":"5306838799","pt":1646107783482,"mc":[{"id":"1.195395433","rc":[{"atl":[[4,0]],"id":34135026}],"con":true,"img":false}]}
{"op":"mcm","clk":"5306838805","pt":1646107783584,"mc":[{"id":"1.195395433","rc":[{"atl":[[3.85,28.46]],"id":34135026}],"con":true,"img":false}]}
{"op":"mcm","clk":"5306838900","pt":1646107785788,"mc":[{"id":"1.195395433","rc":[{"atl":[[10.5,0]],"id":32825135},{"atb":[[2.86,0]],"id":40835929},{"atb":[[1.99,0]],"id":34135026}],"con":true,"img":false}]}
{"op":"mcm","clk":"5306838903","pt":1646107785890,"mc":[{"id":"1.195395433","rc":[{"atl":[[12,6.1]],"id":32825135},{"atb":[[2.76,59.89]],"id":40835929},{"atb":[[2.08,122.21]],"id":34135026}],"con":true,"img":false}]}
{"op":"mcm","clk":"5306838912","pt":1646107786297,"mc":[{"id":"1.195395433","rc":[{"atl":[[1000,0]],"id":32825135}],"con":true,"img":false}]}
{"op":"mcm","clk":"5306838914","pt":1646107786400,"mc":[{"id":"1.195395433","rc":[{"atl":[[11.5,1.39]],"id":32825135}],"con":true,"img":false}]}
{"op":"mcm","clk":"5306839298","pt":1646107800143,"mc":[{"id":"1.195395433","rc":[{"atb":[[95,2.82]],"id":36474395},{"atb":[[3.65,9.3]],"id":28774786},{"atb":[[4.9,5.22]],"id":32825135},{"atb":[[12.5,0.88]],"id":41286501},{"atb":[[21,4.98]],"id":38375776},{"atb":[[2.32,2]],"id":34135026}],"con":true,"img":false}]}
{"op":"mcm","clk":"5306839314","pt":1646107800710,"mc":[{"id":"1.195395433","rc":[{"atb":[[1.01,0]],"id":41286501}],"con":true,"img":false}]}
{"op":"mcm","clk":"5306839318","pt":1646107800810,"mc":[{"id":"1.195395433","rc":[{"atb":[[13,3.58]],"id":41286501}],"con":true,"img":false}]}
{"op":"mcm","clk":"5306839332","pt":1646107801220,"mc":[{"id":"1.195395433","rc":[{"atb":[[4.9,3.9]],"id":32825135}],"con":true,"img":false}]}
{"op":"mcm","clk":"5306839334","pt":1646107801321,"mc":[{"id":"1.195395433","rc":[{"atb":[[5.1,5.46]],"id":32825135}],"con":true,"img":false}]}
{"op":"mcm","clk":"5306839844","pt":1646107815552,"mc":[{"id":"1.195395433","rc":[{"atb":[[4.8,2.19]],"id":32825135},{"atl":[[5.6,0]],"id":40835929}],"con":true,"img":false}]}
{"op":"mcm","clk":"5306839848","pt":1646107815655,"mc":[{"id":"1.195395433","rc":[{"atb":[[5.1,20.72]],"id":32825135},{"atl":[[5.3,12.61]],"id":40835929}],"con":true,"img":false}]}
{"op":"mcm","clk":"5306839939","pt":1646107818164,"mc":[{"id":"1.195395433","rc":[{"atb":[[4.8,0]],"id":32825135}],"con":true,"img":false}]}
{"op":"mcm","clk":"5306840197","pt":1646107824763,"mc":[{"id":"1.195395433","rc":[{"atb":[[4.9,2]],"id":32825135}],"con":true,"img":false}]}
{"op":"mcm","clk":"5306840378","pt":1646107830096,"mc":[{"id":"1.195395433","rc":[{"atb":[[5.2,1.98]],"id":32825135},{"spn":8.35,"spf":1.0,"id":32825135},{"spn":2.85,"spf":1.0,"id":40835929}],"con":true,"img":false}]}
{"op":"mcm","clk":"5306840399","pt":1646107830864,"mc":[{"id":"1.195395433","rc":[{"atb":[[5.1,19.08]],"id":32825135}],"con":true,"img":false}]}
{"op":"mcm","clk":"5306840402","pt":1646107830966,"mc":[{"id":"1.195395433","rc":[{"atb":[[5.1,16.57],[5.2,3.62]],"id":32825135}],"con":true,"img":false}]}
{"op":"mcm","clk":"5306840450","pt":1646107832498,"mc":[{"id":"1.195395433","rc":[{"atb":[[5.3,2.5]],"id":32825135}],"con":true,"img":false}]}
{"op":"mcm","clk":"5306840462","pt":1646107832820,"mc":[{"id":"1.195395433","rc":[{"atb":[[5.2,1.98]],"id":32825135}],"con":true,"img":false}]}
{"op":"mcm","clk":"5306840465","pt":1646107832857,"mc":[{"id":"1.195395433","rc":[{"atb":[[5.3,4.14]],"id":32825135}],"con":true,"img":false}]}
{"op":"mcm","clk":"5306840477","pt":1646107833368,"mc":[{"id":"1.195395433","rc":[{"atb":[[5.1,15.26]],"id":32825135}],"con":true,"img":false}]}
{"op":"mcm","clk":"5306840480","pt":1646107833470,"mc":[{"id":"1.195395433","rc":[{"atb":[[5.3,5.46]],"id":32825135}],"con":true,"img":false}]}
{"op":"mcm","clk":"5306840488","pt":1646107833680,"mc":[{"id":"1.195395433","rc":[{"atb":[[1.01,2.23]],"id":32825135}],"con":true,"img":false}]}
{"op":"mcm","clk":"5306840494","pt":1646107833886,"mc":[{"id":"1.195395433","rc":[{"atb":[[1.01,1.77]],"id":32825135}],"con":true,"img":false}]}
{"op":"mcm","clk":"5306840501","pt":1646107834091,"mc":[{"id":"1.195395433","rc":[{"atb":[[1.01,0]],"id":32825135}],"con":true,"img":false}]}
{"op":"mcm","clk":"5306840506","pt":1646107834195,"mc":[{"id":"1.195395433","rc":[{"atb":[[5.2,3.76]],"id":32825135}],"con":true,"img":false}]}
{"op":"mcm","clk":"5306840944","pt":1646107848210,"mc":[{"id":"1.195395433","rc":[{"atb":[[5.2,1.77]],"id":32825135}],"con":true,"img":false}]}
{"op":"mcm","clk":"5306840951","pt":1646107848923,"mc":[{"id":"1.195395433","rc":[{"atb":[[4.8,32.44]],"id":32825135}],"con":true,"img":false}]}
{"op":"mcm","clk":"5306840953","pt":1646107849025,"mc":[{"id":"1.195395433","rc":[{"atb":[[4.1,0]],"id":32825135}],"con":true,"img":false}]}
{"op":"mcm","clk":"5306841308","pt":1646107860415,"mc":[{"id":"1.195395433","rc":[{"atb":[[4.1,40.01]],"id":32825135}],"con":true,"img":false}]}
{"op":"mcm","clk":"5306841312","pt":1646107860518,"mc":[{"id":"1.195395433","rc":[{"atb":[[4.8,0]],"id":32825135}],"con":true,"img":false}]}
{"op":"mcm","clk":"5306841666","pt":1646107871928,"mc":[{"id":"1.195395433","rc":[{"atb":[[5.1,0]],"id":32825135},{"atl":[[5.3,0]],"id":40835929}],"con":true,"img":false}]}
{"op":"mcm","clk":"5306841671","pt":1646107872029,"mc":[{"id":"1.195395433","rc":[{"atb":[[4.8,15.26]],"id":32825135},{"atl":[[5.5,12.61]],"id":40835929}],"con":true,"img":false}]}
{"op":"mcm","clk":"5306841682","pt":1646107872438,"mc":[{"id":"1.195395433","rc":[{"atb":[[5.3,2.5]],"id":32825135}],"con":true,"img":false}]}
{"op":"mcm","clk":"5306841686","pt":1646107872540,"mc":[{"id":"1.195395433","rc":[{"atb":[[1.01,1.63],[1.02,1.31]],"id":32825135}],"con":true,"img":false}]}
{"op":"mcm","clk":"5306841698","pt":1646107873050,"mc":[{"id":"1.195395433","rc":[{"atb":[[1.02,0]],"id":32825135}],"con":true,"img":false}]}
{"op":"mcm","clk":"5306841701","pt":1646107873152,"mc":[{"id":"1.195395433","rc":[{"atb":[[4.9,3.31]],"id":32825135}],"con":true,"img":false}]}
{"op":"mcm","clk":"5306841839","pt":1646107878063,"mc":[{"id":"1.195395433","rc":[{"atb":[[4.8,17.45]],"id":32825135}],"con":true,"img":false}]}
{"op":"mcm","clk":"5306841857","pt":1646107878828,"mc":[{"id":"1.195395433","rc":[{"atb":[[5.2,0]],"id":32825135}],"con":true,"img":false}]}
{"op":"mcm","clk":"5306842157","pt":1646107887730,"mc":[{"id":"1.195395433","rc":[{"atb":[[1.01,3.87]],"id":32825135}],"con":true,"img":false}]}
{"op":"mcm","clk":"5306842171","pt":1646107888037,"mc":[{"id":"1.195395433","rc":[{"atb":[[1.01,3.54]],"id":32825135}],"con":true,"img":false}]}
{"op":"mcm","clk":"5306842175","pt":1646107888241,"mc":[{"id":"1.195395433","rc":[{"atb":[[1.01,1.63]],"id":32825135}],"con":true,"img":false}]}
{"op":"mcm","clk":"5306842180","pt":1646107888342,"mc":[{"id":"1.195395433","rc":[{"atb":[[4.9,5.22]],"id":32825135}],"con":true,"img":false}]}
{"op":"mcm","clk":"5306842287","pt":1646107890854,"mc":[{"id":"1.195395433","rc":[{"atl":[[7.4,0]],"id":28774786},{"atl":[[12,0]],"id":32825135},{"spn":8.4,"spf":1.0,"id":32825135}],"con":true,"img":false}]}
{"op":"mcm","clk":"5306842290","pt":1646107890957,"mc":[{"id":"1.195395433","rc":[{"atl":[[7.2,10.69]],"id":28774786},{"atl":[[10.5,6.1]],"id":32825135}],"con":true,"img":false}]}
{"op":"mcm","clk":"5306842305","pt":1646107891466,"mc":[{"id":"1.195395433","rc":[{"atl":[[11.5,0]],"id":32825135}],"con":true,"img":false}]}
{"op":"mcm","clk":"5306842308","pt":1646107891570,"mc":[{"id":"1.195395433","rc":[{"atl":[[1000,1.39]],"id":32825135}],"con":true,"img":false}]}
{"op":"mcm","clk":"5306845686","pt":1646108044777,"mc":[{"id":"1.195395433","rc":[{"atb":[[2.24,0]],"id":28774786},{"atl":[[16,0],[34,0]],"id":28774786},{"atb":[[2.9,0]],"id":32825135},{"atl":[[38,0]],"id":32825135},{"spn":7.9,"spf":1.0,"id":32825135}],"con":true,"img":false}]}
{"op":"mcm","clk":"5306845687","pt":1646108044879,"mc":[{"id":"1.195395433","rc":[{"atb":[[16,0],[2.62,0],[4.2,0]],"id":36474395},{"atb":[[6.2,0],[2.62,0],[4.2,0]],"id":41286501},{"atl":[[110,1.13]],"id":41286501},{"atb":[[10.5,0],[2.62,0],[4.2,0]],"id":38375776},{"atb":[[1.92,0]],"id":40835929},{"atl":[[17,0],[34,0],[6.8,0]],"id":40835929},{"atb":[[1.61,0]],"id":34135026},{"atl":[[17,0],[34,0],[9.8,0]],"id":34135026}],"con":true,"img":false}]}
{"op":"mcm","clk":"5306846837","pt":1646108100161,"mc":[{"id":"1.195395433","rc":[{"atb":[[4.3,46.97],[2.66,45.18]],"id":36474395},{"atl":[[17,11.5]],"id":28774786},{"atl":[[34,15.5]],"id":32825135},{"atb":[[4.3,46.97],[2.66,45.18]],"id":41286501},{"atb":[[4.3,46.97],[2.66,45.18]],"id":38375776},{"atl":[[17,11.5]],"id":40835929}],"con":true,"img":false}]}
{"op":"mcm","clk":"5306846840","pt":1646108100263,"mc":[{"id":"1.195395433","rc":[{"atl":[[34,15.5]],"id":28774786},{"atl":[[34,15.5]],"id":40835929},{"atl":[[17,11.5],[34,15.5]],"id":34135026}],"con":true,"img":false}]}
{"op":"mcm","clk":"5306846854","pt":1646108100779,"mc":[{"id":"1.195395433","rc":[{"atb":[[1.02,0]],"id":36474395}],"con":true,"img":false}]}
{"op":"mcm","clk":"5306846856","pt":1646108100877,"mc":[{"id":"1.195395433","rc":[{"atb":[[4.4,1.32]],"id":36474395}],"con":true,"img":false}]}
{"op":"mcm","clk":"5306858957","pt":1646108241895,"mc":[{"id":"1.195395433","rc":[{"atb":[[3.8,13.32]],"id":28774786}],"con":true,"img":false}]}
{"op":"mcm","clk":"5306858965","pt":1646108242201,"mc":[{"id":"1.195395433","rc":[{"atb":[[3.65,7.95]],"id":28774786}],"con":true,"img":false}]}
{"op":"mcm","clk":"5306858967","pt":1646108242303,"mc":[{"id":"1.195395433","rc":[{"atb":[[3.85,1.34]],"id":28774786}],"con":true,"img":false}]}
{"op":"mcm","clk":"5306858990","pt":1646108242866,"mc":[{"id":"1.195395433","rc":[{"atb":[[1.01,0]],"id":28774786}],"con":true,"img":false}]}
{"op":"mcm","clk":"5306858993","pt":1646108242967,"mc":[{"id":"1.195395433","rc":[{"atb":[[3.85,3]],"id":28774786},{"atb":[[5.3,13.32]],"id":32825135}],"con":true,"img":false}]}
{"op":"mcm","clk":"5306859011","pt":1646108243378,"mc":[{"id":"1.195395433","rc":[{"atb":[[4.9,3.9]],"id":32825135}],"con":true,"img":false}]}
{"op":"mcm","clk":"5306859015","pt":1646108243479,"mc":[{"id":"1.195395433","rc":[{"atb":[[5.4,1.31]],"id":32825135}],"con":true,"img":false}]}
{"op":"mcm","clk":"5306859021","pt":1646108243585,"mc":[{"id":"1.195395433","rc":[{"atb":[[3.8,10.81]],"id":28774786}],"con":true,"img":false}]}
{"op":"mcm","clk":"5306859024","pt":1646108243786,"mc":[{"id":"1.195395433","rc":[{"atb":[[1.01,0]],"id":32825135}],"con":true,"img":false}]}
{"op":"mcm","clk":"5306859028","pt":1646108243888,"mc":[{"id":"1.195395433","rc":[{"atb":[[5.4,2.95]],"id":32825135},{"atb":[[3.05,12.48]],"id":40835929}],"con":true,"img":false}]}
{"op":"mcm","clk":"5306859054","pt":1646108244501,"mc":[{"id":"1.195395433","rc":[{"atl":[[3.25,12.11]],"id":34135026}],"con":true,"img":false}]}
{"op":"mcm","clk":"5306859088","pt":1646108245678,"mc":[{"id":"1.195395433","rc":[{"atb":[[95,13.63]],"id":36474395},{"atb":[[3.9,2.5]],"id":28774786},{"atb":[[5.3,10.81]],"id":32825135}],"con":true,"img":false}]}
{"op":"mcm","clk":"5306859107","pt":1646108246191,"mc":[{"id":"1.195395433","rc":[{"atl":[[32,13.51]],"id":41286501}],"con":true,"img":false}]}
{"op":"mcm","clk":"5306859119","pt":1646108246498,"mc":[{"id":"1.195395433","rc":[{"atb":[[3.85,1.34]],"id":28774786}],"con":true,"img":false}]}
{"op":"mcm","clk":"5306859124","pt":1646108246600,"mc":[{"id":"1.195395433","rc":[{"atb":[[3.9,4.16]],"id":28774786}],"con":true,"img":false}]}
{"op":"mcm","clk":"5306859135","pt":1646108246908,"mc":[{"id":"1.195395433","rc":[{"atb":[[3.85,0]],"id":28774786}],"con":true,"img":false}]}
{"op":"mcm","clk":"5306859139","pt":1646108247011,"mc":[{"id":"1.195395433","rc":[{"atb":[[3.9,5.51]],"id":28774786}],"con":true,"img":false}]}
{"op":"mcm","clk":"5306859146","pt":1646108247319,"mc":[{"id":"1.195395433","rc":[{"atb":[[22,12.48]],"id":38375776}],"con":true,"img":false}]}
{"op":"mcm","clk":"5306859184","pt":1646108248186,"mc":[{"id":"1.195395433","rc":[{"atb":[[21,3.4]],"id":38375776}],"con":true,"img":false}]}
{"op":"mcm","clk":"5306859186","pt":1646108248289,"mc":[{"id":"1.195395433","rc":[{"atb":[[5.5,2.5]],"id":32825135},{"atb":[[23,1.57]],"id":38375776}],"con":true,"img":false}]}
{"op":"mcm","clk":"5306859215","pt":1646108249005,"mc":[{"id":"1.195395433","rc":[{"atb":[[5.4,1.31]],"id":32825135}],"con":true,"img":false}]}
{"op":"mcm","clk":"5306859219","pt":1646108249106,"mc":[{"id":"1.195395433","rc":[{"atb":[[5.5,4.14]],"id":32825135}],"con":true,"img":false}]}
{"op":"mcm","clk":"5306859230","pt":1646108249311,"mc":[{"id":"1.195395433","rc":[{"atb":[[22,10.81]],"id":38375776}],"con":true,"img":false}]}
{"op":"mcm","clk":"5306859233","pt":1646108249413,"mc":[{"id":"1.195395433","rc":[{"atb":[[5.4,0]],"id":32825135}],"con":true,"img":false}]}
{"op":"mcm","clk":"5306859240","pt":1646108249516,"mc":[{"id":"1.195395433","rc":[{"atb":[[5.5,5.46]],"id":32825135}],"con":true,"img":false}]}
{"op":"mcm","clk":"5306859306","pt":1646108251203,"mc":[{"id":"1.195395433","rc":[{"atb":[[24,1.66]],"id":38375776}],"con":true,"img":false}]}
{"op":"mcm","clk":"5306860124","pt":1646108274245,"mc":[{"id":"1.195395433","rc":[{"spn":5.55,"spf":1.0,"id":28774786},{"atb":[[2.66,45.18]],"id":32825135},{"spn":8.0,"spf":1.0,"id":32825135},{"spn":62.0,"spf":1.0,"id":38375776},{"spn":2.87,"spf":1.0,"id":40835929}],"con":true,"img":false}]}
{"op":"mcm","clk":"5306860238","pt":1646108277006,"mc":[{"id":"1.195395433","rc":[{"atb":[[100,2.24]],"id":36474395}],"con":true,"img":false}]}
{"op":"mcm","clk":"5306860250","pt":1646108277313,"mc":[{"id":"1.195395433","rc":[{"atb":[[100,3.74]],"id":36474395}],"con":true,"img":false}]}
{"op":"mcm","clk":"5306860675","pt":1646108290326,"mc":[{"id":"1.195395433","rc":[{"atl":[[32,10.81]],"id":41286501},{"atb":[[21,0.51]],"id":38375776}],"con":true,"img":false}]}
{"op":"mcm","clk":"5306860679","pt":1646108290430,"mc":[{"id":"1.195395433","rc":[{"atl":[[30,2.7]],"id":41286501},{"atb":[[23,4.47]],"id":38375776}],"con":true,"img":false}]}
{"op":"mcm","clk":"5306860708","pt":1646108291143,"mc":[{"id":"1.195395433","rc":[{"atl":[[990,0]],"id":41286501}],"con":true,"img":false}]}
{"op":"mcm","clk":"5306860711","pt":1646108291246,"mc":[{"id":"1.195395433","rc":[{"atl":[[29,1.32]],"id":41286501}],"con":true,"img":false}]}
{"op":"mcm","clk":"5306860990","pt":1646108301236,"mc":[{"id":"1.195395433","rc":[{"atb":[[3.9,16.32]],"id":28774786}],"con":true,"img":false}]}
{"op":"mcm","clk":"5306861028","pt":1646108302767,"mc":[{"id":"1.195395433","rc":[{"atb":[[5.5,16.27]],"id":32825135}],"con":true,"img":false}]}
{"op":"mcm","clk":"5306861066","pt":1646108304047,"mc":[{"id":"1.195395433","rc":[{"atb":[[3.05,23.3]],"id":40835929}],"con":true,"img":false}]}
{"op":"mcm","clk":"5306861089","pt":1646108304658,"mc":[{"id":"1.195395433","rc":[{"atl":[[3.25,22.93]],"id":34135026}],"con":true,"img":false}]}
{"op":"mcm","clk":"5306861136","pt":1646108305941,"mc":[{"id":"1.195395433","rc":[{"atb":[[100,14.56]],"id":36474395}],"con":true,"img":false}]}
{"op":"mcm","clk":"5306861152","pt":1646108306454,"mc":[{"id":"1.195395433","rc":[{"atl":[[29,12.14]],"id":41286501}],"con":true,"img":false}]}
{"op":"mcm","clk":"5306861195","pt":1646108307787,"mc":[{"id":"1.195395433","rc":[{"atb":[[24,12.48]],"id":38375776}],"con":true,"img":false}]}
{"op":"mcm","clk":"5306861208","pt":1646108308253,"mc":[{"id":"1.195395433","rc":[{"atb":[[23,2.89]],"id":38375776}],"con":true,"img":false}]}
{"op":"mcm","clk":"5306861212","pt":1646108308354,"mc":[{"id":"1.195395433","rc":[{"atb":[[25,1.57]],"id":38375776}],"con":true,"img":false}]}
{"op":"mcm","clk":"5306861252","pt":1646108309993,"mc":[{"id":"1.195395433","rc":[{"atb":[[24,10.81]],"id":38375776}],"con":true,"img":false}]}
{"op":"mcm","clk":"5306861291","pt":1646108311374,"mc":[{"id":"1.195395433","rc":[{"atb":[[4.9,2]],"id":32825135}],"con":true,"img":false}]}
{"op":"mcm","clk":"5306861295","pt":1646108311578,"mc":[{"id":"1.195395433","rc":[{"atb":[[26,1.66]],"id":38375776}],"con":true,"img":false}]}
{"op":"mcm","clk":"5306861440","pt":1646108317000,"mc":[{"id":"1.195395433","rc":[{"atb":[[4.8,15.26]],"id":32825135}],"con":true,"img":false}]}
{"op":"mcm","clk":"5306861533","pt":1646108320376,"mc":[{"id":"1.195395433","rc":[{"atb":[[1.01,2.23]],"id":32825135}],"con":true,"img":false}]}
{"op":"mcm","clk":"5306861539","pt":1646108320578,"mc":[{"id":"1.195395433","rc":[{"atb":[[1.01,1.61]],"id":32825135}],"con":true,"img":false}]}
{"op":"mcm","clk":"5306861550","pt":1646108320883,"mc":[{"id":"1.195395433","rc":[{"atb":[[1.01,0]],"id":32825135}],"con":true,"img":false}]}
{"op":"mcm","clk":"5306861556","pt":1646108320985,"mc":[{"id":"1.195395433","rc":[{"atb":[[5.6,1.61]],"id":32825135}],"con":true,"img":false}]}
{"op":"mcm","clk":"5306861604","pt":1646108322884,"mc":[{"id":"1.195395433","rc":[{"atb":[[5.5,13.77]],"id":32825135}],"con":true,"img":false}]}
{"op":"mcm","clk":"5306861612","pt":1646108323085,"mc":[{"id":"1.195395433","rc":[{"atb":[[5.6,3.43]],"id":32825135}],"con":true,"img":false}]}
{"op":"mcm","clk":"5306861633","pt":1646108324209,"mc":[{"id":"1.195395433","rc":[{"atb":[[5.5,12.13]],"id":32825135}],"con":true,"img":false}]}
{"op":"mcm","clk":"5306861638","pt":1646108324262,"mc":[{"id":"1.195395433","rc":[{"atb":[[5.7,1.63]],"id":32825135}],"con":true,"img":false}]}
{"op":"mcm","clk":"5306861663","pt":1646108325182,"mc":[{"id":"1.195395433","rc":[{"atb":[[5.8,2.5]],"id":32825135}],"con":true,"img":false}]}
{"op":"mcm","clk":"5306861681","pt":1646108325998,"mc":[{"id":"1.195395433","rc":[{"atb":[[5.7,0]],"id":32825135}],"con":true,"img":false}]}
{"op":"mcm","clk":"5306861684","pt":1646108326101,"mc":[{"id":"1.195395433","rc":[{"atb":[[5.8,4.14]],"id":32825135}],"con":true,"img":false}]}
{"op":"mcm","clk":"5306861705","pt":1646108326919,"mc":[{"id":"1.195395433","rc":[{"atb":[[12,0]],"id":41286501}],"con":true,"img":false}]}
{"op":"mcm","clk":"5306861710","pt":1646108326974,"mc":[{"id":"1.195395433","rc":[{"atb":[[1.02,1.29]],"id":41286501}],"con":true,"img":false}]}
{"op":"mcm","clk":"5306861722","pt":1646108327382,"mc":[{"id":"1.195395433","rc":[{"atb":[[1.02,0]],"id":41286501}],"con":true,"img":false}]}
{"op":"mcm","clk":"5306861725","pt":1646108327484,"mc":[{"id":"1.195395433","rc":[{"atb":[[12,1.29]],"id":41286501}],"con":true,"img":false}]}
{"op":"mcm","clk":"5306861739","pt":1646108327997,"mc":[{"id":"1.195395433","rc":[{"atb":[[12,0]],"id":41286501}],"con":true,"img":false}]}
{"op":"mcm","clk":"5306861741","pt":1646108328095,"mc":[{"id":"1.195395433","rc":[{"atb":[[1.02,1.29]],"id":41286501}],"con":true,"img":false}]}
{"op":"mcm","clk":"5306861753","pt":1646108328605,"mc":[{"id":"1.195395433","rc":[{"atb":[[1.02,0],[13,2.08]],"id":41286501}],"con":true,"img":false}]}
{"op":"mcm","clk":"5306861758","pt":1646108328707,"mc":[{"id":"1.195395433","rc":[{"atb":[[1.01,1.5],[12,1.29]],"id":41286501}],"con":true,"img":false}]}
{"op":"mcm","clk":"5306861768","pt":1646108329218,"mc":[{"id":"1.195395433","rc":[{"atb":[[12,0]],"id":41286501}],"con":true,"img":false}]}
{"op":"mcm","clk":"5306861771","pt":1646108329271,"mc":[{"id":"1.195395433","rc":[{"atb":[[1.02,1.29]],"id":41286501}],"con":true,"img":false}]}
{"op":"mcm","clk":"5306861788","pt":1646108329783,"mc":[{"id":"1.195395433","rc":[{"atb":[[1.02,0]],"id":41286501}],"con":true,"img":false}]}
{"op":"mcm","clk":"5306861791","pt":1646108329886,"mc":[{"id":"1.195395433","rc":[{"atb":[[12,1.29]],"id":41286501}],"con":true,"img":false}]}
{"op":"mcm","clk":"5306861806","pt":1646108330294,"mc":[{"id":"1.195395433","rc":[{"atb":[[95,10.93]],"id":36474395}],"con":true,"img":false}]}
{"op":"mcm","clk":"5306861808","pt":1646108330396,"mc":[{"id":"1.195395433","rc":[{"atb":[[110,2.7]],"id":36474395},{"atb":[[12,0]],"id":41286501}],"con":true,"img":false}]}
{"op":"mcm","clk":"5306861812","pt":1646108330499,"mc":[{"id":"1.195395433","rc":[{"atb":[[1.02,1.29]],"id":41286501}],"con":true,"img":false}]}
{"op":"mcm","clk":"5306861828","pt":1646108331010,"mc":[{"id":"1.195395433","rc":[{"atb":[[1.02,0]],"id":41286501}],"con":true,"img":false}]}
{"op":"mcm","clk":"5306861830","pt":1646108331112,"mc":[{"id":"1.195395433","rc":[{"atb":[[12,1.29]],"id":41286501}],"con":true,"img":false}]}
{"op":"mcm","clk":"5306861846","pt":1646108331678,"mc":[{"id":"1.195395433","rc":[{"atb":[[12,0]],"id":41286501}],"con":true,"img":false}]}
{"op":"mcm","clk":"5306861850","pt":1646108331779,"mc":[{"id":"1.195395433","rc":[{"atb":[[1.02,1.29]],"id":41286501}],"con":true,"img":false}]}
{"op":"mcm","clk":"5306861864","pt":1646108332288,"mc":[{"id":"1.195395433","rc":[{"atb":[[1.02,0]],"id":41286501}],"con":true,"img":false}]}
{"op":"mcm","clk":"5306861868","pt":1646108332392,"mc":[{"id":"1.195395433","rc":[{"atb":[[5.6,1.81]],"id":32825135},{"atb":[[12,1.29]],"id":41286501}],"con":true,"img":false}]}
{"op":"mcm","clk":"5306861879","pt":1646108332906,"mc":[{"id":"1.195395433","rc":[{"atb":[[12,0]],"id":41286501}],"con":true,"img":false}]}
{"op":"mcm","clk":"5306861886","pt":1646108333009,"mc":[{"id":"1.195395433","rc":[{"atb":[[1.02,1.29]],"id":41286501}],"con":true,"img":false}]}
{"op":"mcm","clk":"5306861898","pt":1646108333418,"mc":[{"id":"1.195395433","rc":[{"atb":[[1.02,0]],"id":41286501}],"con":true,"img":false}]}
{"op":"mcm","clk":"5306861903","pt":1646108333520,"mc":[{"id":"1.195395433","rc":[{"atb":[[12,1.29]],"id":41286501}],"con":true,"img":false}]}
{"op":"mcm","clk":"5306861917","pt":1646108334083,"mc":[{"id":"1.195395433","rc":[{"atb":[[12,0]],"id":41286501}],"con":true,"img":false}]}
{"op":"mcm","clk":"5306861921","pt":1646108334235,"mc":[{"id":"1.195395433","rc":[{"atb":[[100,12.31]],"id":36474395},{"atb":[[1.02,1.29]],"id":41286501}],"con":true,"img":false}]}
{"op":"mcm","clk":"5306861930","pt":1646108334489,"mc":[{"id":"1.195395433","rc":[{"atb":[[120,2.24]],"id":36474395},{"spn":114.77,"spf":1.0,"id":36474395},{"spn":8.15,"spf":1.0,"id":32825135},{"spn":21.0,"spf":1.0,"id":41286501},{"spn":63.0,"spf":1.0,"id":38375776},{"spn":2.88,"spf":1.0,"id":40835929}],"con":true,"img":false}]}
{"op":"mcm","clk":"5306861933","pt":1646108334695,"mc":[{"id":"1.195395433","rc":[{"atb":[[1.02,0]],"id":41286501}],"con":true,"img":false}]}
{"op":"mcm","clk":"5306861937","pt":1646108334798,"mc":[{"id":"1.195395433","rc":[{"atb":[[12,1.29]],"id":41286501}],"con":true,"img":false}]}
{"op":"mcm","clk":"5306861941","pt":1646108335208,"mc":[{"id":"1.195395433","rc":[{"atb":[[12,0]],"id":41286501}],"con":true,"img":false}]}
{"op":"mcm","clk":"5306861945","pt":1646108335310,"mc":[{"id":"1.195395433","rc":[{"atb":[[1.02,1.29]],"id":41286501}],"con":true,"img":false}]}
{"op":"mcm","clk":"5306861958","pt":1646108335825,"mc":[{"id":"1.195395433","rc":[{"atl":[[10.5,0]],"id":32825135}],"con":true,"img":false}]}
{"op":"mcm","clk":"5306861961","pt":1646108335928,"mc":[{"id":"1.195395433","rc":[{"atl":[[11,6.1]],"id":32825135},{"atb":[[1.02,0]],"id":41286501}],"con":true,"img":false}]}
{"op":"mcm","clk":"5306861964","pt":1646108335983,"mc":[{"id":"1.195395433","rc":[{"atb":[[100,10.81]],"id":36474395},{"atb":[[5.8,2.5]],"id":32825135},{"atb":[[1.01,0],[12,1.29]],"id":41286501}],"con":true,"img":false}]}
{"op":"mcm","clk":"5306861967","pt":1646108336087,"mc":[{"id":"1.195395433","rc":[{"atb":[[110,4.2]],"id":36474395},{"atb":[[1.01,1.63]],"id":32825135},{"atb":[[13,3.58]],"id":41286501}],"con":true,"img":false}]}
{"op":"mcm","clk":"5306861977","pt":1646108336492,"mc":[{"id":"1.195395433","rc":[{"atb":[[110,2.7]],"id":36474395}],"con":true,"img":false}]}
{"op":"mcm","clk":"5306861980","pt":1646108336595,"mc":[{"id":"1.195395433","rc":[{"atb":[[120,3.74]],"id":36474395}],"con":true,"img":false}]}
{"op":"mcm","clk":"5306862090","pt":1646108340889,"mc":[{"id":"1.195395433","rc":[{"atb":[[5.6,0]],"id":32825135}],"con":true,"img":false}]}
{"op":"mcm","clk":"5306862105","pt":1646108341402,"mc":[{"id":"1.195395433","rc":[{"atb":[[1.01,3.87]],"id":32825135}],"con":true,"img":false}]}
{"op":"mcm","clk":"5306862107","pt":1646108341506,"mc":[{"id":"1.195395433","rc":[{"atb":[[1.01,3.54]],"id":32825135}],"con":true,"img":false}]}
{"op":"mcm","clk":"5306862110","pt":1646108341607,"mc":[{"id":"1.195395433","rc":[{"atb":[[1.01,1.63]],"id":32825135}],"con":true,"img":false}]}
{"op":"mcm","clk":"5306862113","pt":1646108341709,"mc":[{"id":"1.195395433","rc":[{"atb":[[4.9,3.9]],"id":32825135}],"con":true,"img":false}]}
{"op":"mcm","clk":"5306862243","pt":1646108347021,"mc":[{"id":"1.195395433","rc":[{"atb":[[4.8,17.45]],"id":32825135}],"con":true,"img":false}]}
{"op":"mcm","clk":"5306862475","pt":1646108358119,"mc":[{"id":"1.195395433","rc":[{"atl":[[30,0]],"id":41286501}],"con":true,"img":false}]}
{"op":"mcm","clk":"5306862476","pt":1646108358222,"mc":[{"id":"1.195395433","rc":[{"atl":[[28,2.7]],"id":41286501}],"con":true,"img":false}]}
{"op":"mcm","clk":"5306862482","pt":1646108358528,"mc":[{"id":"1.195395433","rc":[{"atb":[[12,0]],"id":41286501}],"con":true,"img":false}]}
{"op":"mcm","clk":"5306862483","pt":1646108358631,"mc":[{"id":"1.195395433","rc":[{"atb":[[1.02,1.29]],"id":41286501},{"atl":[[29,10.81]],"id":41286501}],"con":true,"img":false}]}
{"op":"mcm","clk":"5306862487","pt":1646108358734,"mc":[{"id":"1.195395433","rc":[{"atl":[[27,1.32]],"id":41286501}],"con":true,"img":false}]}
{"op":"mcm","clk":"5306862492","pt":1646108358836,"mc":[{"id":"1.195395433","rc":[{"atb":[[13,2.08]],"id":41286501}],"con":true,"img":false}]}
{"op":"mcm","clk":"5306862495","pt":1646108358938,"mc":[{"id":"1.195395433","rc":[{"atb":[[1.01,1.5]],"id":41286501}],"con":true,"img":false}]}
{"op":"mcm","clk":"5306862501","pt":1646108359140,"mc":[{"id":"1.195395433","rc":[{"atb":[[1.02,0]],"id":41286501}],"con":true,"img":false}]}
{"op":"mcm","clk":"5306862503","pt":1646108359244,"mc":[{"id":"1.195395433","rc":[{"atb":[[12,1.29]],"id":41286501}],"con":true,"img":false}]}
{"op":"mcm","clk":"5306862519","pt":1646108359756,"mc":[{"id":"1.195395433","rc":[{"atb":[[1.01,0]],"id":41286501}],"con":true,"img":false}]}
{"op":"mcm","clk":"5306862522","pt":1646108359858,"mc":[{"id":"1.195395433","rc":[{"atb":[[13,3.58]],"id":41286501}],"con":true,"img":false}]}
{"op":"mcm","clk":"5306862526","pt":1646108359961,"mc":[{"id":"1.195395433","rc":[{"atb":[[12,0]],"id":41286501}],"con":true,"img":false}]}
{"op":"mcm","clk":"5306862531","pt":1646108360062,"mc":[{"id":"1.195395433","rc":[{"atb":[[1.02,1.29]],"id":41286501}],"con":true,"img":false}]}
{"op":"mcm","clk":"5306862541","pt":1646108360370,"mc":[{"id":"1.195395433","rc":[{"atb":[[1.02,0]],"id":41286501}],"con":true,"img":false}]}
{"op":"mcm","clk":"5306862544","pt":1646108360422,"mc":[{"id":"1.195395433","rc":[{"atb":[[12,1.29]],"id":41286501}],"con":true,"img":false}]}
{"op":"mcm","clk":"5306862548","pt":1646108360626,"mc":[{"id":"1.195395433","rc":[{"atb":[[13,2.08]],"id":41286501}],"con":true,"img":false}]}
{"op":"mcm","clk":"5306862551","pt":1646108360729,"mc":[{"id":"1.195395433","rc":[{"atb":[[1.01,1.5]],"id":41286501}],"con":true,"img":false}]}
{"op":"mcm","clk":"5306862555","pt":1646108360934,"mc":[{"id":"1.195395433","rc":[{"atb":[[12,0]],"id":41286501}],"con":true,"img":false}]}
{"op":"mcm","clk":"5306862559","pt":1646108361036,"mc":[{"id":"1.195395433","rc":[{"atb":[[1.02,1.29]],"id":41286501}],"con":true,"img":false}]}
{"op":"mcm","clk":"5306862569","pt":1646108361546,"mc":[{"id":"1.195395433","rc":[{"atb":[[1.02,0]],"id":41286501}],"con":true,"img":false}]}
{"op":"mcm","clk":"5306862573","pt":1646108361647,"mc":[{"id":"1.195395433","rc":[{"atb":[[12,1.29]],"id":41286501}],"con":true,"img":false}]}
{"op":"mcm","clk":"5306862590","pt":1646108362159,"mc":[{"id":"1.195395433","rc":[{"atb":[[12,0]],"id":41286501},{"atb":[[23,0]],"id":38375776}],"con":true,"img":false}]}
{"op":"mcm","clk":"5306862595","pt":1646108362262,"mc":[{"id":"1.195395433","rc":[{"atb":[[1.02,1.29]],"id":41286501},{"atb":[[25,4.47]],"id":38375776}],"con":true,"img":false}]}
{"op":"mcm","clk":"5306862616","pt":1646108362727,"mc":[{"id":"1.195395433","rc":[{"atb":[[1.02,0]],"id":41286501}],"con":true,"img":false}]}
{"op":"mcm","clk":"5306862621","pt":1646108362831,"mc":[{"id":"1.195395433","rc":[{"atb":[[12,1.29]],"id":41286501}],"con":true,"img":false}]}
{"op":"mcm","clk":"5306862638","pt":1646108363340,"mc":[{"id":"1.195395433","rc":[{"atb":[[12,0]],"id":41286501}],"con":true,"img":false}]}
{"op":"mcm","clk":"5306862641","pt":1646108363442,"mc":[{"id":"1.195395433","rc":[{"atb":[[1.02,1.29]],"id":41286501}],"con":true,"img":false}]}
{"op":"mcm","clk":"5306862663","pt":1646108364157,"mc":[{"id":"1.195395433","rc":[{"atb":[[1.02,0]],"id":41286501}],"con":true,"img":false}]}
{"op":"mcm","clk":"5306862665","pt":1646108364257,"mc":[{"id":"1.195395433","rc":[{"atb":[[12,1.29]],"id":41286501}],"con":true,"img":false}]}
{"op":"mcm","clk":"5306862671","pt":1646108364463,"mc":[{"id":"1.195395433","rc":[{"atb":[[12,0]],"id":41286501}],"con":true,"img":false}]}
{"op":"mcm","clk":"5306862673","pt":1646108364565,"mc":[{"id":"1.195395433","rc":[{"atb":[[1.02,1.29]],"id":41286501}],"con":true,"img":false}]}
{"op":"mcm","clk":"5306862689","pt":1646108365129,"mc":[{"id":"1.195395433","rc":[{"atb":[[1.02,0]],"id":41286501}],"con":true,"img":false}]}
{"op":"mcm","clk":"5306862692","pt":1646108365232,"mc":[{"id":"1.195395433","rc":[{"atb":[[12,1.29]],"id":41286501}],"con":true,"img":false}]}
{"op":"mcm","clk":"5306862695","pt":1646108365334,"mc":[{"id":"1.195395433","rc":[{"atl":[[3.85,20.34]],"id":34135026}],"con":true,"img":false}]}
{"op":"mcm","clk":"5306862709","pt":1646108365741,"mc":[{"id":"1.195395433","rc":[{"atb":[[12,0]],"id":41286501}],"con":true,"img":false}]}
{"op":"mcm","clk":"5306862713","pt":1646108365845,"mc":[{"id":"1.195395433","rc":[{"atb":[[1.02,1.29]],"id":41286501}],"con":true,"img":false}]}
{"op":"mcm","clk":"5306862732","pt":1646108366457,"mc":[{"id":"1.195395433","rc":[{"atb":[[1.02,0]],"id":41286501}],"con":true,"img":false}]}
{"op":"mcm","clk":"5306862734","pt":1646108366559,"mc":[{"id":"1.195395433","rc":[{"atb":[[12,1.29]],"id":41286501}],"con":true,"img":false}]}
{"op":"mcm","clk":"5306862750","pt":1646108366970,"mc":[{"id":"1.195395433","rc":[{"atb":[[12,0]],"id":41286501}],"con":true,"img":false}]}
{"op":"mcm","clk":"5306862753","pt":1646108367073,"mc":[{"id":"1.195395433","rc":[{"atb":[[1.02,1.29]],"id":41286501}],"con":true,"img":false}]}
{"op":"mcm","clk":"5306862764","pt":1646108367540,"mc":[{"id":"1.195395433","rc":[{"atb":[[1.02,0]],"id":41286501}],"con":true,"img":false}]}
{"op":"mcm","clk":"5306862765","pt":1646108367643,"mc":[{"id":"1.195395433","rc":[{"atb":[[12,1.29]],"id":41286501}],"con":true,"img":false}]}
{"op":"mcm","clk":"5306862771","pt":1646108368151,"mc":[{"id":"1.195395433","rc":[{"atb":[[12,0]],"id":41286501}],"con":true,"img":false}]}
{"op":"mcm","clk":"5306862774","pt":1646108368252,"mc":[{"id":"1.195395433","rc":[{"atb":[[1.02,1.29]],"id":41286501}],"con":true,"img":false}]}
{"op":"mcm","clk":"5306862788","pt":1646108368764,"mc":[{"id":"1.195395433","rc":[{"atb":[[1.02,0]],"id":41286501}],"con":true,"img":false}]}
{"op":"mcm","clk":"5306862791","pt":1646108368868,"mc":[{"id":"1.195395433","rc":[{"atb":[[12,1.29]],"id":41286501}],"con":true,"img":false}]}
{"op":"mcm","clk":"5306862798","pt":1646108369377,"mc":[{"id":"1.195395433","rc":[{"atb":[[12,0]],"id":41286501}],"con":true,"img":false}]}
{"op":"mcm","clk":"5306862802","pt":1646108369430,"mc":[{"id":"1.195395433","rc":[{"atb":[[1.02,1.29]],"id":41286501}],"con":true,"img":false}]}
{"op":"mcm","clk":"5306862815","pt":1646108369944,"mc":[{"id":"1.195395433","rc":[{"atb":[[110,0]],"id":36474395},{"atb":[[1.02,0]],"id":41286501}],"con":true,"img":false}]}
{"op":"mcm","clk":"5306862817","pt":1646108370048,"mc":[{"id":"1.195395433","rc":[{"atb":[[130,2.7]],"id":36474395},{"atb":[[12,1.29]],"id":41286501}],"con":true,"img":false}]}
{"op":"mcm","clk":"5306862823","pt":1646108370254,"mc":[{"id":"1.195395433","rc":[{"atb":[[120,2.24]],"id":36474395}],"con":true,"img":false}]}
{"op":"mcm","clk":"5306862824","pt":1646108370356,"mc":[{"id":"1.195395433","rc":[{"atb":[[130,4.2]],"id":36474395}],"con":true,"img":false}]}
{"op":"mcm","clk":"5306862829","pt":1646108370560,"mc":[{"id":"1.195395433","rc":[{"atb":[[12,0]],"id":41286501}],"con":true,"img":false}]}
{"op":"mcm","clk":"5306862833","pt":1646108370662,"mc":[{"id":"1.195395433","rc":[{"atb":[[1.02,1.29]],"id":41286501}],"con":true,"img":false}]}
{"op":"mcm","clk":"5306862855","pt":1646108371637,"mc":[{"id":"1.195395433","rc":[{"atb":[[1.02,0]],"id":41286501}],"con":true,"img":false}]}
{"op":"mcm","clk":"5306862857","pt":1646108371739,"mc":[{"id":"1.195395433","rc":[{"atb":[[12,1.29]],"id":41286501}],"con":true,"img":false}]}
{"op":"mcm","clk":"5306862878","pt":1646108372555,"mc":[{"id":"1.195395433","rc":[{"atb":[[12,0]],"id":41286501}],"con":true,"img":false}]}
{"op":"mcm","clk":"5306862880","pt":1646108372656,"mc":[{"id":"1.195395433","rc":[{"atb":[[1.02,1.29]],"id":41286501}],"con":true,"img":false}]}
{"op":"mcm","clk":"5306862887","pt":1646108372962,"mc":[{"id":"1.195395433","rc":[{"atb":[[1.02,0]],"id":41286501}],"con":true,"img":false}]}
{"op":"mcm","clk":"5306862890","pt":1646108373064,"mc":[{"id":"1.195395433","rc":[{"atb":[[12,1.29]],"id":41286501}],"con":true,"img":false}]}
{"op":"mcm","clk":"5306862904","pt":1646108373474,"mc":[{"id":"1.195395433","rc":[{"atb":[[12,0]],"id":41286501}],"con":true,"img":false}]}
{"op":"mcm","clk":"5306862907","pt":1646108373575,"mc":[{"id":"1.195395433","rc":[{"atb":[[1.02,1.29]],"id":41286501}],"con":true,"img":false}]}
{"op":"mcm","clk":"5306862922","pt":1646108374242,"mc":[{"id":"1.195395433","rc":[{"atb":[[120,0]],"id":36474395}],"con":true,"img":false}]}
{"op":"mcm","clk":"5306862926","pt":1646108374446,"mc":[{"id":"1.195395433","rc":[{"atb":[[1.02,0]],"id":41286501}],"con":true,"img":false}]}
{"op":"mcm","clk":"5306862928","pt":1646108374546,"mc":[{"id":"1.195395433","rc":[{"atb":[[140,2.24]],"id":36474395},{"atb":[[12,1.29]],"id":41286501}],"con":true,"img":false}]}
{"op":"mcm","clk":"5306862931","pt":1646108374752,"mc":[{"id":"1.195395433","rc":[{"atb":[[130,2.7]],"id":36474395},{"atb":[[12,0]],"id":41286501}],"con":true,"img":false}]}
{"op":"mcm","clk":"5306862935","pt":1646108374854,"mc":[{"id":"1.195395433","rc":[{"atb":[[1.01,1.5]],"id":36474395},{"atb":[[1.02,1.29]],"id":41286501}],"con":true,"img":false}]}
{"op":"mcm","clk":"5306862943","pt":1646108375365,"mc":[{"id":"1.195395433","rc":[{"atb":[[1.02,0]],"id":41286501}],"con":true,"img":false}]}
{"op":"mcm","clk":"5306862944","pt":1646108375464,"mc":[{"id":"1.195395433","rc":[{"atb":[[12,1.29]],"id":41286501}],"con":true,"img":false}]}
{"op":"mcm","clk":"5306862951","pt":1646108376077,"mc":[{"id":"1.195395433","rc":[{"atb":[[12,0]],"id":41286501}],"con":true,"img":false}]}
{"op":"mcm","clk":"5306862952","pt":1646108376180,"mc":[{"id":"1.195395433","rc":[{"atb":[[1.02,1.29]],"id":41286501}],"con":true,"img":false}]}
{"op":"mcm","clk":"5306862961","pt":1646108376645,"mc":[{"id":"1.195395433","rc":[{"atb":[[1.02,0]],"id":41286501}],"con":true,"img":false}]}
{"op":"mcm","clk":"5306862962","pt":1646108376748,"mc":[{"id":"1.195395433","rc":[{"atb":[[12,1.29]],"id":41286501}],"con":true,"img":false}]}
{"op":"mcm","clk":"5306862973","pt":1646108377159,"mc":[{"id":"1.195395433","rc":[{"atb":[[12,0]],"id":41286501}],"con":true,"img":false}]}
{"op":"mcm","clk":"5306862977","pt":1646108377260,"mc":[{"id":"1.195395433","rc":[{"atb":[[1.02,1.29]],"id":41286501}],"con":true,"img":false}]}
{"op":"mcm","clk":"5306862983","pt":1646108377769,"mc":[{"id":"1.195395433","rc":[{"atb":[[1.02,0]],"id":41286501}],"con":true,"img":false}]}
{"op":"mcm","clk":"5306862984","pt":1646108377872,"mc":[{"id":"1.195395433","rc":[{"atb":[[12,1.29]],"id":41286501}],"con":true,"img":false}]}
{"op":"mcm","clk":"5306862996","pt":1646108378387,"mc":[{"id":"1.195395433","rc":[{"atb":[[12,0]],"id":41286501}],"con":true,"img":false}]}
{"op":"mcm","clk":"5306862999","pt":1646108378488,"mc":[{"id":"1.195395433","rc":[{"atb":[[1.02,1.29]],"id":41286501}],"con":true,"img":false}]}
{"op":"mcm","clk":"5306863009","pt":1646108378949,"mc":[{"id":"1.195395433","rc":[{"atb":[[1.02,0]],"id":41286501}],"con":true,"img":false}]}
{"op":"mcm","clk":"5306863011","pt":1646108379050,"mc":[{"id":"1.195395433","rc":[{"atb":[[12,1.29]],"id":41286501}],"con":true,"img":false}]}
{"op":"mcm","clk":"5306863023","pt":1646108379560,"mc":[{"id":"1.195395433","rc":[{"atb":[[12,0]],"id":41286501}],"con":true,"img":false}]}
{"op":"mcm","clk":"5306863024","pt":1646108379663,"mc":[{"id":"1.195395433","rc":[{"atb":[[1.02,1.29]],"id":41286501}],"con":true,"img":false}]}
{"op":"mcm","clk":"5306863041","pt":1646108380479,"mc":[{"id":"1.195395433","rc":[{"atb":[[1.02,0]],"id":41286501}],"con":true,"img":false}]}
{"op":"mcm","clk":"5306863044","pt":1646108380581,"mc":[{"id":"1.195395433","rc":[{"atb":[[12,1.29]],"id":41286501}],"con":true,"img":false}]}
{"op":"mcm","clk":"5306863053","pt":1646108380889,"mc":[{"id":"1.195395433","rc":[{"atb":[[12,0]],"id":41286501}],"con":true,"img":false}]}
{"op":"mcm","clk":"5306863056","pt":1646108380991,"mc":[{"id":"1.195395433","rc":[{"atb":[[1.02,1.29]],"id":41286501}],"con":true,"img":false}]}
{"op":"mcm","clk":"5306863061","pt":1646108381351,"mc":[{"id":"1.195395433","rc":[{"atb":[[1.02,0]],"id":41286501}],"con":true,"img":false}]}
{"op":"mcm","clk":"5306863063","pt":1646108381451,"mc":[{"id":"1.195395433","rc":[{"atb":[[12,1.29]],"id":41286501}],"con":true,"img":false}]}
{"op":"mcm","clk":"5306863076","pt":1646108381965,"mc":[{"id":"1.195395433","rc":[{"atb":[[12,0]],"id":41286501}],"con":true,"img":false}]}
{"op":"mcm","clk":"5306863078","pt":1646108382068,"mc":[{"id":"1.195395433","rc":[{"atb":[[1.02,1.29]],"id":41286501}],"con":true,"img":false}]}
{"op":"mcm","clk":"5306863096","pt":1646108382579,"mc":[{"id":"1.195395433","rc":[{"atb":[[1.02,0]],"id":41286501}],"con":true,"img":false}]}
{"op":"mcm","clk":"5306863098","pt":1646108382682,"mc":[{"id":"1.195395433","rc":[{"atb":[[12,1.29]],"id":41286501}],"con":true,"img":false}]}
{"op":"mcm","clk":"5306863113","pt":1646108383193,"mc":[{"id":"1.195395433","rc":[{"atb":[[12,0]],"id":41286501}],"con":true,"img":false}]}
{"op":"mcm","clk":"5306863116","pt":1646108383245,"mc":[{"id":"1.195395433","rc":[{"atb":[[1.02,1.29]],"id":41286501}],"con":true,"img":false}]}
{"op":"mcm","clk":"5306863140","pt":1646108383962,"mc":[{"id":"1.195395433","rc":[{"atb":[[1.02,0]],"id":41286501}],"con":true,"img":false}]}
{"op":"mcm","clk":"5306863142","pt":1646108384063,"mc":[{"id":"1.195395433","rc":[{"atb":[[12,1.29]],"id":41286501}],"con":true,"img":false}]}
{"op":"mcm","clk":"5306863149","pt":1646108384370,"mc":[{"id":"1.195395433","rc":[{"atb":[[12,0]],"id":41286501}],"con":true,"img":false}]}
{"op":"mcm","clk":"5306863151","pt":1646108384472,"mc":[{"id":"1.195395433","rc":[{"atb":[[1.02,1.29]],"id":41286501}],"con":true,"img":false}]}
{"op":"mcm","clk":"5306863164","pt":1646108384981,"mc":[{"id":"1.195395433","rc":[{"atb":[[1.02,0]],"id":41286501}],"con":true,"img":false}]}
{"op":"mcm","clk":"5306863167","pt":1646108385083,"mc":[{"id":"1.195395433","rc":[{"atb":[[12,1.29]],"id":41286501}],"con":true,"img":false}]}
{"op":"mcm","clk":"5306863179","pt":1646108385592,"mc":[{"id":"1.195395433","rc":[{"atb":[[12,0]],"id":41286501}],"con":true,"img":false}]}
{"op":"mcm","clk":"5306863182","pt":1646108385695,"mc":[{"id":"1.195395433","rc":[{"atb":[[1.02,1.29]],"id":41286501}],"con":true,"img":false}]}
{"op":"mcm","clk":"5306863192","pt":1646108386157,"mc":[{"id":"1.195395433","rc":[{"atb":[[1.02,0]],"id":41286501}],"con":true,"img":false}]}
{"op":"mcm","clk":"5306863194","pt":1646108386259,"mc":[{"id":"1.195395433","rc":[{"atb":[[12,1.29]],"id":41286501}],"con":true,"img":false}]}
{"op":"mcm","clk":"5306863206","pt":1646108386773,"mc":[{"id":"1.195395433","rc":[{"atb":[[12,0]],"id":41286501}],"con":true,"img":false}]}
{"op":"mcm","clk":"5306863209","pt":1646108386876,"mc":[{"id":"1.195395433","rc":[{"atb":[[1.02,1.29]],"id":41286501}],"con":true,"img":false}]}
{"op":"mcm","clk":"5306863218","pt":1646108387387,"mc":[{"id":"1.195395433","rc":[{"atb":[[1.02,0]],"id":41286501}],"con":true,"img":false}]}
{"op":"mcm","clk":"5306863221","pt":1646108387489,"mc":[{"id":"1.195395433","rc":[{"atb":[[12,1.29]],"id":41286501}],"con":true,"img":false}]}
{"op":"mcm","clk":"5306863227","pt":1646108388001,"mc":[{"id":"1.195395433","rc":[{"atb":[[12,0]],"id":41286501}],"con":true,"img":false}]}
{"op":"mcm","clk":"5306863233","pt":1646108388104,"mc":[{"id":"1.195395433","rc":[{"atb":[[1.02,1.29]],"id":41286501}],"con":true,"img":false}]}
{"op":"mcm","clk":"5306863244","pt":1646108388668,"mc":[{"id":"1.195395433","rc":[{"atb":[[1.02,0]],"id":41286501}],"con":true,"img":false}]}
{"op":"mcm","clk":"5306863248","pt":1646108388769,"mc":[{"id":"1.195395433","rc":[{"atb":[[12,1.29]],"id":41286501}],"con":true,"img":false}]}
{"op":"mcm","clk":"5306863261","pt":1646108389180,"mc":[{"id":"1.195395433","rc":[{"atb":[[12,0]],"id":41286501}],"con":true,"img":false}]}
{"op":"mcm","clk":"5306863268","pt":1646108389282,"mc":[{"id":"1.195395433","rc":[{"atb":[[1.02,1.29]],"id":41286501}],"con":true,"img":false}]}
{"op":"mcm","clk":"5306863281","pt":1646108389789,"mc":[{"id":"1.195395433","rc":[{"atb":[[1.02,0]],"id":41286501}],"con":true,"img":false}]}
{"op":"mcm","clk":"5306863283","pt":1646108389892,"mc":[{"id":"1.195395433","rc":[{"atb":[[12,1.29]],"id":41286501}],"con":true,"img":false}]}
{"op":"mcm","clk":"5306863292","pt":1646108390301,"mc":[{"id":"1.195395433","rc":[{"atb":[[12,0]],"id":41286501}],"con":true,"img":false}]}
{"op":"mcm","clk":"5306863293","pt":1646108390403,"mc":[{"id":"1.195395433","rc":[{"atb":[[1.02,1.29]],"id":41286501}],"con":true,"img":false}]}
{"op":"mcm","clk":"5306863307","pt":1646108390966,"mc":[{"id":"1.195395433","rc":[{"atb":[[1.02,0]],"id":41286501}],"con":true,"img":false}]}
{"op":"mcm","clk":"5306863310","pt":1646108391067,"mc":[{"id":"1.195395433","rc":[{"atb":[[12,1.29]],"id":41286501}],"con":true,"img":false}]}
{"op":"mcm","clk":"5306863326","pt":1646108391579,"mc":[{"id":"1.195395433","rc":[{"atb":[[12,0]],"id":41286501}],"con":true,"img":false}]}
{"op":"mcm","clk":"5306863329","pt":1646108391681,"mc":[{"id":"1.195395433","rc":[{"atb":[[1.02,1.29]],"id":41286501}],"con":true,"img":false}]}
{"op":"mcm","clk":"5306863341","pt":1646108392191,"mc":[{"id":"1.195395433","rc":[{"atb":[[1.02,0]],"id":41286501}],"con":true,"img":false}]}
{"op":"mcm","clk":"5306863344","pt":1646108392292,"mc":[{"id":"1.195395433","rc":[{"atb":[[12,1.29]],"id":41286501}],"con":true,"img":false}]}
{"op":"mcm","clk":"5306863357","pt":1646108392805,"mc":[{"id":"1.195395433","rc":[{"atb":[[12,0]],"id":41286501}],"con":true,"img":false}]}
{"op":"mcm","clk":"5306863360","pt":1646108392908,"mc":[{"id":"1.195395433","rc":[{"atb":[[1.02,1.29]],"id":41286501}],"con":true,"img":false}]}
{"op":"mcm","clk":"5306863371","pt":1646108393370,"mc":[{"id":"1.195395433","rc":[{"atb":[[1.02,0]],"id":41286501}],"con":true,"img":false}]}
{"op":"mcm","clk":"5306863374","pt":1646108393471,"mc":[{"id":"1.195395433","rc":[{"atb":[[12,1.29]],"id":41286501}],"con":true,"img":false}]}
{"op":"mcm","clk":"5306863390","pt":1646108393983,"mc":[{"id":"1.195395433","rc":[{"atb":[[12,0]],"id":41286501}],"con":true,"img":false}]}
{"op":"mcm","clk":"5306863395","pt":1646108394085,"mc":[{"id":"1.195395433","rc":[{"atb":[[1.02,1.29]],"id":41286501}],"con":true,"img":false}]}
{"op":"mcm","clk":"5306863410","pt":1646108394595,"mc":[{"id":"1.195395433","rc":[{"spn":134.77,"spf":1.0,"id":36474395},{"spn":8.4,"spf":1.0,"id":32825135},{"atb":[[1.02,0]],"id":41286501},{"spn":20.0,"spf":1.0,"id":41286501}],"con":true,"img":false}]}
{"op":"mcm","clk":"5306863413","pt":1646108394696,"mc":[{"id":"1.195395433","rc":[{"atb":[[12,1.29]],"id":41286501}],"con":true,"img":false}]}
{"op":"mcm","clk":"5306863429","pt":1646108395208,"mc":[{"id":"1.195395433","rc":[{"atb":[[12,0]],"id":41286501}],"con":true,"img":false}]}
{"op":"mcm","clk":"5306863433","pt":1646108395310,"mc":[{"id":"1.195395433","rc":[{"atb":[[130,0]],"id":36474395},{"atl":[[11,0]],"id":32825135},{"atb":[[1.02,1.29]],"id":41286501}],"con":true,"img":false}]}
{"op":"mcm","clk":"5306863435","pt":1646108395413,"mc":[{"id":"1.195395433","rc":[{"atb":[[110,2.7]],"id":36474395},{"atl":[[10.5,6.1]],"id":32825135}],"con":true,"img":false}]}
{"op":"mcm","clk":"5306863442","pt":1646108395719,"mc":[{"id":"1.195395433","rc":[{"atb":[[1.02,0]],"id":41286501}],"con":true,"img":false}]}
{"op":"mcm","clk":"5306863447","pt":1646108395771,"mc":[{"id":"1.195395433","rc":[{"atb":[[12,1.29]],"id":41286501}],"con":true,"img":false}]}
{"op":"mcm","clk":"5306863463","pt":1646108396386,"mc":[{"id":"1.195395433","rc":[{"atb":[[12,0]],"id":41286501}],"con":true,"img":false}]}
{"op":"mcm","clk":"5306863467","pt":1646108396487,"mc":[{"id":"1.195395433","rc":[{"atb":[[1.02,1.29]],"id":41286501}],"con":true,"img":false}]}
{"op":"mcm","clk":"5306863482","pt":1646108396996,"mc":[{"id":"1.195395433","rc":[{"atb":[[1.02,0]],"id":41286501}],"con":true,"img":false}]}
{"op":"mcm","clk":"5306863485","pt":1646108397099,"mc":[{"id":"1.195395433","rc":[{"atb":[[12,1.29]],"id":41286501}],"con":true,"img":false}]}
{"op":"mcm","clk":"5306863498","pt":1646108397611,"mc":[{"id":"1.195395433","rc":[{"atb":[[12,0]],"id":41286501}],"con":true,"img":false}]}
{"op":"mcm","clk":"5306863500","pt":1646108397714,"mc":[{"id":"1.195395433","rc":[{"atb":[[1.02,1.29]],"id":41286501}],"con":true,"img":false}]}
{"op":"mcm","clk":"5306863513","pt":1646108398175,"mc":[{"id":"1.195395433","rc":[{"atb":[[1.02,0]],"id":41286501}],"con":true,"img":false}]}
{"op":"mcm","clk":"5306863514","pt":1646108398276,"mc":[{"id":"1.195395433","rc":[{"atb":[[12,1.29]],"id":41286501}],"con":true,"img":false}]}
{"op":"mcm","clk":"5306863526","pt":1646108398789,"mc":[{"id":"1.195395433","rc":[{"atb":[[12,0]],"id":41286501}],"con":true,"img":false}]}
{"op":"mcm","clk":"5306863528","pt":1646108398891,"mc":[{"id":"1.195395433","rc":[{"atb":[[1.02,1.29]],"id":41286501}],"con":true,"img":false}]}
{"op":"mcm","clk":"5306863532","pt":1646108399398,"mc":[{"id":"1.195395433","rc":[{"atb":[[1.02,0]],"id":41286501}],"con":true,"img":false}]}
{"op":"mcm","clk":"5306863534","pt":1646108399502,"mc":[{"id":"1.195395433","rc":[{"atb":[[12,1.29]],"id":41286501}],"con":true,"img":false}]}
{"op":"mcm","clk":"5306863543","pt":1646108400011,"mc":[{"id":"1.195395433","rc":[{"atb":[[12,0]],"id":41286501}],"con":true,"img":false}]}
{"op":"mcm","clk":"5306863545","pt":1646108400114,"mc":[{"id":"1.195395433","rc":[{"atb":[[1.02,1.29]],"id":41286501}],"con":true,"img":false}]}
{"op":"mcm","clk":"5306863555","pt":1646108400576,"mc":[{"id":"1.195395433","rc":[{"atb":[[1.02,0]],"id":41286501}],"con":true,"img":false}]}
{"op":"mcm","clk":"5306863557","pt":1646108400677,"mc":[{"id":"1.195395433","rc":[{"atb":[[12,1.29]],"id":41286501},{"atb":[[2.18,66.1]],"id":34135026}],"con":true,"img":false}]}
{"op":"mcm","clk":"5306863570","pt":1646108401188,"mc":[{"id":"1.195395433","rc":[{"atb":[[12,0]],"id":41286501}],"con":true,"img":false}]}
{"op":"mcm","clk":"5306863574","pt":1646108401292,"mc":[{"id":"1.195395433","rc":[{"atb":[[1.02,1.29]],"id":41286501}],"con":true,"img":false}]}
{"op":"mcm","clk":"5306863588","pt":1646108401803,"mc":[{"id":"1.195395433","rc":[{"atb":[[1.02,0]],"id":41286501}],"con":true,"img":false}]}
{"op":"mcm","clk":"5306863592","pt":1646108401906,"mc":[{"id":"1.195395433","rc":[{"atb":[[12,1.29]],"id":41286501}],"con":true,"img":false}]}
{"op":"mcm","clk":"5306863624","pt":1646108402676,"mc":[{"id":"1.195395433","rc":[{"atb":[[12,0]],"id":41286501}],"con":true,"img":false}]}
{"op":"mcm","clk":"5306863628","pt":1646108402778,"mc":[{"id":"1.195395433","rc":[{"atb":[[1.02,1.29]],"id":41286501}],"con":true,"img":false}]}
{"op":"mcm","clk":"5306863635","pt":1646108402983,"mc":[{"id":"1.195395433","rc":[{"atb":[[1.02,0]],"id":41286501}],"con":true,"img":false}]}
{"op":"mcm","clk":"5306863641","pt":1646108403086,"mc":[{"id":"1.195395433","rc":[{"atb":[[12,1.29]],"id":41286501}],"con":true,"img":false}]}
{"op":"mcm","clk":"5306863646","pt":1646108403291,"mc":[{"id":"1.195395433","rc":[{"atb":[[3.6,0]],"id":28774786}],"con":true,"img":false}]}
{"op":"mcm","clk":"5306863647","pt":1646108403419,"mc":[{"id":"1.195395433","rc":[{"atb":[[3.7,23.19]],"id":28774786}],"con":true,"img":false}]}
{"op":"mcm","clk":"5306863654","pt":1646108403595,"mc":[{"id":"1.195395433","rc":[{"atb":[[12,0]],"id":41286501}],"con":true,"img":false}]}
{"op":"mcm","clk":"5306863657","pt":1646108403698,"mc":[{"id":"1.195395433","rc":[{"atb":[[1.02,1.29]],"id":41286501}],"con":true,"img":false}]}
{"op":"mcm","clk":"5306863669","pt":1646108404208,"mc":[{"id":"1.195395433","rc":[{"atb":[[1.02,0]],"id":41286501}],"con":true,"img":false}]}
{"op":"mcm","clk":"5306863670","pt":1646108404311,"mc":[{"id":"1.195395433","rc":[{"atb":[[12,1.29]],"id":41286501}],"con":true,"img":false}]}
{"op":"mcm","clk":"5306863687","pt":1646108404821,"mc":[{"id":"1.195395433","rc":[{"atb":[[12,0]],"id":41286501}],"con":true,"img":false}]}
{"op":"mcm","clk":"5306863691","pt":1646108404925,"mc":[{"id":"1.195395433","rc":[{"atb":[[1.02,1.29]],"id":41286501}],"con":true,"img":false}]}
{"op":"mcm","clk":"5306863710","pt":1646108405391,"mc":[{"id":"1.195395433","rc":[{"atb":[[1.02,0]],"id":41286501}],"con":true,"img":false}]}
{"op":"mcm","clk":"5306863716","pt":1646108405493,"mc":[{"id":"1.195395433","rc":[{"atb":[[12,1.29]],"id":41286501}],"con":true,"img":false}]}
{"op":"mcm","clk":"5306863735","pt":1646108406009,"mc":[{"id":"1.195395433","rc":[{"atb":[[12,0]],"id":41286501}],"con":true,"img":false}]}
{"op":"mcm","clk":"5306863737","pt":1646108406110,"mc":[{"id":"1.195395433","rc":[{"atb":[[1.02,1.29]],"id":41286501}],"con":true,"img":false}]}
{"op":"mcm","clk":"5306863748","pt":1646108406519,"mc":[{"id":"1.195395433","rc":[{"atb":[[1.02,0]],"id":41286501}],"con":true,"img":false}]}
{"op":"mcm","clk":"5306863751","pt":1646108406621,"mc":[{"id":"1.195395433","rc":[{"atb":[[12,1.29]],"id":41286501}],"con":true,"img":false}]}
{"op":"mcm","clk":"5306863769","pt":1646108407188,"mc":[{"id":"1.195395433","rc":[{"atb":[[12,0]],"id":41286501}],"con":true,"img":false}]}
{"op":"mcm","clk":"5306863773","pt":1646108407290,"mc":[{"id":"1.195395433","rc":[{"atb":[[1.02,1.29]],"id":41286501}],"con":true,"img":false}]}
{"op":"mcm","clk":"5306863780","pt":1646108407701,"mc":[{"id":"1.195395433","rc":[{"atb":[[1.96,20.94]],"id":34135026}],"con":true,"img":false}]}
{"op":"mcm","clk":"5306863781","pt":1646108407803,"mc":[{"id":"1.195395433","rc":[{"atb":[[1.02,0]],"id":41286501}],"con":true,"img":false}]}
{"op":"mcm","clk":"5306863783","pt":1646108407905,"mc":[{"id":"1.195395433","rc":[{"atb":[[12,1.29]],"id":41286501}],"con":true,"img":false}]}
{"op":"mcm","clk":"5306863788","pt":1646108408411,"mc":[{"id":"1.195395433","rc":[{"atb":[[12,0]],"id":41286501}],"con":true,"img":false}]}
{"op":"mcm","clk":"5306863789","pt":1646108408514,"mc":[{"id":"1.195395433","rc":[{"atb":[[1.02,1.29]],"id":41286501}],"con":true,"img":false}]}
{"op":"mcm","clk":"5306863800","pt":1646108408923,"mc":[{"id":"1.195395433","rc":[{"atb":[[1.02,0]],"id":41286501}],"con":true,"img":false}]}
{"op":"mcm","clk":"5306863801","pt":1646108409024,"mc":[{"id":"1.195395433","rc":[{"atb":[[12,1.29]],"id":41286501}],"con":true,"img":false}]}
{"op":"mcm","clk":"5306863813","pt":1646108409690,"mc":[{"id":"1.195395433","rc":[{"atb":[[12,0]],"id":41286501}],"con":true,"img":false}]}
{"op":"mcm","clk":"5306863817","pt":1646108409792,"mc":[{"id":"1.195395433","rc":[{"atb":[[1.02,1.29]],"id":41286501}],"con":true,"img":false}]}
{"op":"mcm","clk":"5306863829","pt":1646108410303,"mc":[{"id":"1.195395433","rc":[{"atb":[[1.02,0]],"id":41286501}],"con":true,"img":false}]}
{"op":"mcm","clk":"5306863831","pt":1646108410406,"mc":[{"id":"1.195395433","rc":[{"atb":[[12,1.29]],"id":41286501}],"con":true,"img":false}]}
{"op":"mcm","clk":"5306863834","pt":1646108410508,"mc":[{"id":"1.195395433","rc":[{"atb":[[3.65,5.14]],"id":28774786}],"con":true,"img":false}]}
{"op":"mcm","clk":"5306863850","pt":1646108411020,"mc":[{"id":"1.195395433","rc":[{"atb":[[12,0]],"id":41286501}],"con":true,"img":false}]}
{"op":"mcm","clk":"5306863854","pt":1646108411123,"mc":[{"id":"1.195395433","rc":[{"atb":[[1.02,1.29]],"id":41286501}],"con":true,"img":false}]}
{"op":"mcm","clk":"5306863867","pt":1646108411484,"mc":[{"id":"1.195395433","rc":[{"atb":[[1.02,0]],"id":41286501}],"con":true,"img":false}]}
{"op":"mcm","clk":"5306863870","pt":1646108411587,"mc":[{"id":"1.195395433","rc":[{"atb":[[12,1.29]],"id":41286501}],"con":true,"img":false}]}
{"op":"mcm","clk":"5306863888","pt":1646108412096,"mc":[{"id":"1.195395433","rc":[{"atb":[[12,0]],"id":41286501}],"con":true,"img":false}]}
{"op":"mcm","clk":"5306863893","pt":1646108412198,"mc":[{"id":"1.195395433","rc":[{"atb":[[1.02,1.29]],"id":41286501}],"con":true,"img":false}]}
{"op":"mcm","clk":"5306863905","pt":1646108412816,"mc":[{"id":"1.195395433","rc":[{"atb":[[1.02,0]],"id":41286501}],"con":true,"img":false}]}
{"op":"mcm","clk":"5306863907","pt":1646108412919,"mc":[{"id":"1.195395433","rc":[{"atb":[[12,1.29]],"id":41286501}],"con":true,"img":false}]}
{"op":"mcm","clk":"5306863920","pt":1646108413431,"mc":[{"id":"1.195395433","rc":[{"atb":[[12,0]],"id":41286501}],"con":true,"img":false}]}
{"op":"mcm","clk":"5306863922","pt":1646108413485,"mc":[{"id":"1.195395433","rc":[{"atb":[[1.02,1.29]],"id":41286501}],"con":true,"img":false}]}
{"op":"mcm","clk":"5306863931","pt":1646108413892,"mc":[{"id":"1.195395433","rc":[{"atb":[[1.02,0]],"id":41286501}],"con":true,"img":false}]}
{"op":"mcm","clk":"5306863934","pt":1646108413997,"mc":[{"id":"1.195395433","rc":[{"atb":[[12,1.29]],"id":41286501}],"con":true,"img":false}]}
{"op":"mcm","clk":"5306863947","pt":1646108414509,"mc":[{"id":"1.195395433","rc":[{"atb":[[12,0]],"id":41286501}],"con":true,"img":false}]}
{"op":"mcm","clk":"5306863949","pt":1646108414609,"mc":[{"id":"1.195395433","rc":[{"atb":[[1.02,1.29]],"id":41286501}],"con":true,"img":false}]}
{"op":"mcm","clk":"5306863955","pt":1646108414710,"mc":[{"id":"1.195395433","rc":[{"atb":[[2.82,11.15],[3.15,9.4]],"id":28774786}],"con":true,"img":false}]}
{"op":"mcm","clk":"5306863959","pt":1646108414916,"mc":[{"id":"1.195395433","rc":[{"atb":[[2.72,11.74],[2.48,13.72]],"id":40835929}],"con":true,"img":false}]}
{"op":"mcm","clk":"5306863969","pt":1646108415120,"mc":[{"id":"1.195395433","rc":[{"atb":[[1.02,0]],"id":41286501}],"con":true,"img":false}]}
{"op":"mcm","clk":"5306863974","pt":1646108415224,"mc":[{"id":"1.195395433","rc":[{"atb":[[12,1.29]],"id":41286501}],"con":true,"img":false}]}
{"op":"mcm","clk":"5306863986","pt":1646108415788,"mc":[{"id":"1.195395433","rc":[{"atb":[[12,0]],"id":41286501}],"con":true,"img":false}]}
{"op":"mcm","clk":"5306863989","pt":1646108415890,"mc":[{"id":"1.195395433","rc":[{"atb":[[1.02,1.29]],"id":41286501}],"con":true,"img":false}]}
{"op":"mcm","clk":"5306864008","pt":1646108416402,"mc":[{"id":"1.195395433","rc":[{"atb":[[1.02,0]],"id":41286501}],"con":true,"img":false}]}
{"op":"mcm","clk":"5306864011","pt":1646108416504,"mc":[{"id":"1.195395433","rc":[{"atb":[[12,1.29]],"id":41286501}],"con":true,"img":false}]}
{"op":"mcm","clk":"5306864016","pt":1646108417013,"mc":[{"id":"1.195395433","rc":[{"atb":[[12,0]],"id":41286501}],"con":true,"img":false}]}
{"op":"mcm","clk":"5306864018","pt":1646108417115,"mc":[{"id":"1.195395433","rc":[{"atb":[[1.02,1.29]],"id":41286501}],"con":true,"img":false}]}
{"op":"mcm","clk":"5306864028","pt":1646108417522,"mc":[{"id":"1.195395433","rc":[{"atb":[[1.02,0]],"id":41286501}],"con":true,"img":false}]}
{"op":"mcm","clk":"5306864030","pt":1646108417624,"mc":[{"id":"1.195395433","rc":[{"atb":[[12,1.29]],"id":41286501}],"con":true,"img":false}]}
{"op":"mcm","clk":"5306864043","pt":1646108418136,"mc":[{"id":"1.195395433","rc":[{"atb":[[12,0]],"id":41286501}],"con":true,"img":false}]}
{"op":"mcm","clk":"5306864047","pt":1646108418190,"mc":[{"id":"1.195395433","rc":[{"atb":[[1.02,1.29]],"id":41286501}],"con":true,"img":false}]}
{"op":"mcm","clk":"5306864065","pt":1646108418805,"mc":[{"id":"1.195395433","rc":[{"atb":[[1.02,0]],"id":41286501}],"con":true,"img":false}]}
{"op":"mcm","clk":"5306864069","pt":1646108418908,"mc":[{"id":"1.195395433","rc":[{"atb":[[12,1.29]],"id":41286501}],"con":true,"img":false}]}
{"op":"mcm","clk":"5306864076","pt":1646108419114,"mc":[{"id":"1.195395433","rc":[{"atb":[[3.65,2]],"id":28774786}],"con":true,"img":false}]}
{"op":"mcm","clk":"5306864079","pt":1646108419319,"mc":[{"id":"1.195395433","rc":[{"atb":[[12,0]],"id":41286501}],"con":true,"img":false}]}
{"op":"mcm","clk":"5306864080","pt":1646108419419,"mc":[{"id":"1.195395433","rc":[{"atb":[[1.02,1.29]],"id":41286501}],"con":true,"img":false}]}
{"op":"mcm","clk":"5306864082","pt":1646108419521,"mc":[{"id":"1.195395433","rc":[{"atb":[[3.75,2.71]],"id":28774786}],"con":true,"img":false}]}
{"op":"mcm","clk":"5306864089","pt":1646108419931,"mc":[{"id":"1.195395433","rc":[{"atb":[[1.02,0]],"id":41286501}],"con":true,"img":false}]}
{"op":"mcm","clk":"5306864092","pt":1646108420031,"mc":[{"id":"1.195395433","rc":[{"atb":[[12,1.29]],"id":41286501}],"con":true,"img":false}]}
{"op":"mcm","clk":"5306864105","pt":1646108420497,"mc":[{"id":"1.195395433","rc":[{"atb":[[12,0]],"id":41286501}],"con":true,"img":false}]}
{"op":"mcm","clk":"5306864110","pt":1646108420598,"mc":[{"id":"1.195395433","rc":[{"atb":[[1.02,1.29]],"id":41286501}],"con":true,"img":false}]}
{"op":"mcm","clk":"5306864126","pt":1646108421111,"mc":[{"id":"1.195395433","rc":[{"atb":[[1.02,0]],"id":41286501}],"con":true,"img":false}]}
{"op":"mcm","clk":"5306864128","pt":1646108421213,"mc":[{"id":"1.195395433","rc":[{"atb":[[12,1.29]],"id":41286501}],"con":true,"img":false}]}
{"op":"mcm","clk":"5306864141","pt":1646108421725,"mc":[{"id":"1.195395433","rc":[{"atb":[[12,0]],"id":41286501}],"con":true,"img":false}]}
{"op":"mcm","clk":"5306864144","pt":1646108421828,"mc":[{"id":"1.195395433","rc":[{"atb":[[1.02,1.29]],"id":41286501}],"con":true,"img":false}]}
{"op":"mcm","clk":"5306864161","pt":1646108422417,"mc":[{"id":"1.195395433","rc":[{"atb":[[1.02,0]],"id":41286501}],"con":true,"img":false}]}
{"op":"mcm","clk":"5306864164","pt":1646108422493,"mc":[{"id":"1.195395433","rc":[{"atb":[[12,1.29]],"id":41286501}],"con":true,"img":false}]}
{"op":"mcm","clk":"5306864178","pt":1646108422906,"mc":[{"id":"1.195395433","rc":[{"atb":[[12,0]],"id":41286501}],"con":true,"img":false}]}
{"op":"mcm","clk":"5306864183","pt":1646108423012,"mc":[{"id":"1.195395433","rc":[{"atb":[[1.02,1.29]],"id":41286501}],"con":true,"img":false}]}
{"op":"mcm","clk":"5306864202","pt":1646108423522,"mc":[{"id":"1.195395433","rc":[{"atb":[[1.02,0]],"id":41286501}],"con":true,"img":false}]}
{"op":"mcm","clk":"5306864205","pt":1646108423623,"mc":[{"id":"1.195395433","rc":[{"atb":[[12,1.29]],"id":41286501}],"con":true,"img":false}]}
{"op":"mcm","clk":"5306864225","pt":1646108424133,"mc":[{"id":"1.195395433","rc":[{"atb":[[12,0]],"id":41286501}],"con":true,"img":false}]}
{"op":"mcm","clk":"5306864228","pt":1646108424236,"mc":[{"id":"1.195395433","rc":[{"atb":[[1.02,1.29]],"id":41286501}],"con":true,"img":false}]}
{"op":"mcm","clk":"5306864245","pt":1646108424701,"mc":[{"id":"1.195395433","rc":[{"atb":[[1.02,0]],"id":41286501}],"con":true,"img":false}]}
{"op":"mcm","clk":"5306864248","pt":1646108424802,"mc":[{"id":"1.195395433","rc":[{"atb":[[12,1.29]],"id":41286501}],"con":true,"img":false}]}
{"op":"mcm","clk":"5306864260","pt":1646108425110,"mc":[{"id":"1.195395433","rc":[{"atb":[[3.75,5.75]],"id":28774786}],"con":true,"img":false}]}
{"op":"mcm","clk":"5306864272","pt":1646108425417,"mc":[{"id":"1.195395433","rc":[{"atb":[[12,0]],"id":41286501}],"con":true,"img":false}]}
{"op":"mcm","clk":"5306864279","pt":1646108425520,"mc":[{"id":"1.195395433","rc":[{"atb":[[1.02,1.29]],"id":41286501}],"con":true,"img":false}]}
{"op":"mcm","clk":"5306864291","pt":1646108425930,"mc":[{"id":"1.195395433","rc":[{"atb":[[1.02,0]],"id":41286501}],"con":true,"img":false}]}
{"op":"mcm","clk":"5306864293","pt":1646108426029,"mc":[{"id":"1.195395433","rc":[{"atb":[[12,1.29]],"id":41286501}],"con":true,"img":false}]}
{"op":"mcm","clk":"5306864305","pt":1646108426541,"mc":[{"id":"1.195395433","rc":[{"atb":[[12,0]],"id":41286501}],"con":true,"img":false}]}
{"op":"mcm","clk":"5306864309","pt":1646108426596,"mc":[{"id":"1.195395433","rc":[{"atb":[[1.02,1.29]],"id":41286501}],"con":true,"img":false}]}
{"op":"mcm","clk":"5306864323","pt":1646108427108,"mc":[{"id":"1.195395433","rc":[{"atb":[[1.02,0]],"id":41286501}],"con":true,"img":false}]}
{"op":"mcm","clk":"5306864324","pt":1646108427211,"mc":[{"id":"1.195395433","rc":[{"atb":[[12,1.29]],"id":41286501}],"con":true,"img":false}]}
{"op":"mcm","clk":"5306864336","pt":1646108427722,"mc":[{"id":"1.195395433","rc":[{"atb":[[12,0]],"id":41286501}],"con":true,"img":false}]}
{"op":"mcm","clk":"5306864341","pt":1646108427824,"mc":[{"id":"1.195395433","rc":[{"atb":[[1.02,1.29]],"id":41286501}],"con":true,"img":false}]}
{"op":"mcm","clk":"5306864359","pt":1646108428334,"mc":[{"id":"1.195395433","rc":[{"atb":[[1.02,0]],"id":41286501}],"con":true,"img":false}]}
{"op":"mcm","clk":"5306864360","pt":1646108428437,"mc":[{"id":"1.195395433","rc":[{"atb":[[12,1.29]],"id":41286501}],"con":true,"img":false}]}
{"op":"mcm","clk":"5306864379","pt":1646108429005,"mc":[{"id":"1.195395433","rc":[{"atb":[[12,0]],"id":41286501}],"con":true,"img":false}]}
{"op":"mcm","clk":"5306864383","pt":1646108429107,"mc":[{"id":"1.195395433","rc":[{"atb":[[1.02,1.29]],"id":41286501}],"con":true,"img":false}]}
{"op":"mcm","clk":"5306864397","pt":1646108429518,"mc":[{"id":"1.195395433","rc":[{"atb":[[1.02,0]],"id":41286501}],"con":true,"img":false}]}
{"op":"mcm","clk":"5306864399","pt":1646108429617,"mc":[{"id":"1.195395433","rc":[{"atb":[[12,1.29]],"id":41286501}],"con":true,"img":false}]}
{"op":"mcm","clk":"5306864411","pt":1646108430231,"mc":[{"id":"1.195395433","rc":[{"atb":[[12,0]],"id":41286501}],"con":true,"img":false}]}
{"op":"mcm","clk":"5306864413","pt":1646108430335,"mc":[{"id":"1.195395433","rc":[{"atb":[[1.02,1.29]],"id":41286501}],"con":true,"img":false}]}
{"op":"mcm","clk":"5306864422","pt":1646108430741,"mc":[{"id":"1.195395433","rc":[{"atb":[[1.02,0]],"id":41286501}],"con":true,"img":false}]}
{"op":"mcm","clk":"5306864423","pt":1646108430844,"mc":[{"id":"1.195395433","rc":[{"atb":[[12,1.29]],"id":41286501}],"con":true,"img":false}]}
{"op":"mcm","clk":"5306864436","pt":1646108431410,"mc":[{"id":"1.195395433","rc":[{"atb":[[12,0]],"id":41286501}],"con":true,"img":false}]}
{"op":"mcm","clk":"5306864439","pt":1646108431512,"mc":[{"id":"1.195395433","rc":[{"atb":[[1.02,1.29]],"id":41286501}],"con":true,"img":false}]}
{"op":"mcm","clk":"5306864451","pt":1646108432020,"mc":[{"id":"1.195395433","rc":[{"atb":[[1.02,0]],"id":41286501}],"con":true,"img":false}]}
{"op":"mcm","clk":"5306864456","pt":1646108432122,"mc":[{"id":"1.195395433","rc":[{"atb":[[12,1.29]],"id":41286501}],"con":true,"img":false}]}
{"op":"mcm","clk":"5306864471","pt":1646108432530,"mc":[{"id":"1.195395433","rc":[{"atb":[[12,0]],"id":41286501}],"con":true,"img":false}]}
{"op":"mcm","clk":"5306864477","pt":1646108432634,"mc":[{"id":"1.195395433","rc":[{"atb":[[1.02,1.29]],"id":41286501}],"con":true,"img":false}]}
{"op":"mcm","clk":"5306864491","pt":1646108433145,"mc":[{"id":"1.195395433","rc":[{"atb":[[1.02,0]],"id":41286501}],"con":true,"img":false}]}
{"op":"mcm","clk":"5306864494","pt":1646108433247,"mc":[{"id":"1.195395433","rc":[{"atb":[[12,1.29]],"id":41286501}],"con":true,"img":false}]}
{"op":"mcm","clk":"5306864506","pt":1646108433813,"mc":[{"id":"1.195395433","rc":[{"atb":[[12,0]],"id":41286501}],"con":true,"img":false}]}
{"op":"mcm","clk":"5306864510","pt":1646108433916,"mc":[{"id":"1.195395433","rc":[{"atb":[[1.02,1.29]],"id":41286501}],"con":true,"img":false}]}
{"op":"mcm","clk":"5306864536","pt":1646108434428,"mc":[{"id":"1.195395433","rc":[{"atb":[[1.02,0]],"id":41286501}],"con":true,"img":false}]}
{"op":"mcm","clk":"5306864540","pt":1646108434526,"mc":[{"id":"1.195395433","rc":[{"atb":[[12,1.29]],"id":41286501}],"con":true,"img":false}]}
{"op":"mcm","clk":"5306864548","pt":1646108434935,"mc":[{"id":"1.195395433","rc":[{"atb":[[12,0]],"id":41286501}],"con":true,"img":false}]}
{"op":"mcm","clk":"5306864550","pt":1646108435037,"mc":[{"id":"1.195395433","rc":[{"atb":[[1.02,1.29]],"id":41286501}],"con":true,"img":false}]}
{"op":"mcm","clk":"5306864563","pt":1646108435549,"mc":[{"id":"1.195395433","rc":[{"atb":[[1.02,0]],"id":41286501}],"con":true,"img":false}]}
{"op":"mcm","clk":"5306864566","pt":1646108435652,"mc":[{"id":"1.195395433","rc":[{"atb":[[12,1.29]],"id":41286501}],"con":true,"img":false}]}
{"op":"mcm","clk":"5306864577","pt":1646108436118,"mc":[{"id":"1.195395433","rc":[{"atb":[[12,0]],"id":41286501}],"con":true,"img":false}]}
{"op":"mcm","clk":"5306864579","pt":1646108436225,"mc":[{"id":"1.195395433","rc":[{"atb":[[1.02,1.29]],"id":41286501}],"con":true,"img":false}]}
{"op":"mcm","clk":"5306864589","pt":1646108436735,"mc":[{"id":"1.195395433","rc":[{"atb":[[1.02,0]],"id":41286501}],"con":true,"img":false}]}
{"op":"mcm","clk":"5306864593","pt":1646108436839,"mc":[{"id":"1.195395433","rc":[{"atb":[[12,1.29]],"id":41286501}],"con":true,"img":false}]}
{"op":"mcm","clk":"5306864609","pt":1646108437349,"mc":[{"id":"1.195395433","rc":[{"atb":[[12,0]],"id":41286501}],"con":true,"img":false}]}
{"op":"mcm","clk":"5306864612","pt":1646108437452,"mc":[{"id":"1.195395433","rc":[{"atb":[[1.02,1.29]],"id":41286501}],"con":true,"img":false}]}
{"op":"mcm","clk":"5306864628","pt":1646108438016,"mc":[{"id":"1.195395433","rc":[{"atb":[[1.02,0]],"id":41286501}],"con":true,"img":false}]}
{"op":"mcm","clk":"5306864631","pt":1646108438167,"mc":[{"id":"1.195395433","rc":[{"atb":[[12,1.29]],"id":41286501}],"con":true,"img":false}]}
{"op":"mcm","clk":"5306864644","pt":1646108438628,"mc":[{"id":"1.195395433","rc":[{"atb":[[12,0]],"id":41286501}],"con":true,"img":false}]}
{"op":"mcm","clk":"5306864645","pt":1646108438728,"mc":[{"id":"1.195395433","rc":[{"atb":[[1.02,1.29]],"id":41286501}],"con":true,"img":false}]}
{"op":"mcm","clk":"5306864657","pt":1646108439139,"mc":[{"id":"1.195395433","rc":[{"atb":[[1.02,0]],"id":41286501}],"con":true,"img":false}]}
{"op":"mcm","clk":"5306864661","pt":1646108439241,"mc":[{"id":"1.195395433","rc":[{"atb":[[12,1.29]],"id":41286501}],"con":true,"img":false}]}
{"op":"mcm","clk":"5306864675","pt":1646108439852,"mc":[{"id":"1.195395433","rc":[{"atb":[[12,0]],"id":41286501}],"con":true,"img":false}]}
{"op":"mcm","clk":"5306864676","pt":1646108439956,"mc":[{"id":"1.195395433","rc":[{"atb":[[1.02,1.29]],"id":41286501}],"con":true,"img":false}]}
{"op":"mcm","clk":"5306864686","pt":1646108440415,"mc":[{"id":"1.195395433","rc":[{"atb":[[1.02,0]],"id":41286501}],"con":true,"img":false}]}
{"op":"mcm","clk":"5306864687","pt":1646108440518,"mc":[{"id":"1.195395433","rc":[{"atb":[[12,1.29]],"id":41286501}],"con":true,"img":false}]}
{"op":"mcm","clk":"5306864697","pt":1646108440928,"mc":[{"id":"1.195395433","rc":[{"atb":[[12,0]],"id":41286501}],"con":true,"img":false}]}
{"op":"mcm","clk":"5306864699","pt":1646108441030,"mc":[{"id":"1.195395433","rc":[{"atb":[[1.02,1.29]],"id":41286501}],"con":true,"img":false}]}
{"op":"mcm","clk":"5306864713","pt":1646108441539,"mc":[{"id":"1.195395433","rc":[{"atb":[[1.02,0]],"id":41286501}],"con":true,"img":false}]}
{"op":"mcm","clk":"5306864715","pt":1646108441641,"mc":[{"id":"1.195395433","rc":[{"atb":[[12,1.29]],"id":41286501}],"con":true,"img":false}]}
{"op":"mcm","clk":"5306864736","pt":1646108442255,"mc":[{"id":"1.195395433","rc":[{"atb":[[12,0]],"id":41286501}],"con":true,"img":false}]}
{"op":"mcm","clk":"5306864739","pt":1646108442359,"mc":[{"id":"1.195395433","rc":[{"atb":[[1.02,1.29]],"id":41286501}],"con":true,"img":false}]}
{"op":"mcm","clk":"5306864755","pt":1646108442723,"mc":[{"id":"1.195395433","rc":[{"atb":[[1.02,0]],"id":41286501}],"con":true,"img":false}]}
{"op":"mcm","clk":"5306864758","pt":1646108442825,"mc":[{"id":"1.195395433","rc":[{"atb":[[12,1.29]],"id":41286501}],"con":true,"img":false}]}
{"op":"mcm","clk":"5306864772","pt":1646108443338,"mc":[{"id":"1.195395433","rc":[{"atb":[[12,0]],"id":41286501}],"con":true,"img":false}]}
{"op":"mcm","clk":"5306864774","pt":1646108443440,"mc":[{"id":"1.195395433","rc":[{"atb":[[1.02,1.29]],"id":41286501}],"con":true,"img":false}]}
{"op":"mcm","clk":"5306864792","pt":1646108443953,"mc":[{"id":"1.195395433","rc":[{"atb":[[1.02,0]],"id":41286501}],"con":true,"img":false}]}
{"op":"mcm","clk":"5306864795","pt":1646108444055,"mc":[{"id":"1.195395433","rc":[{"atb":[[12,1.29]],"id":41286501}],"con":true,"img":false}]}
{"op":"mcm","clk":"5306864816","pt":1646108444667,"mc":[{"id":"1.195395433","rc":[{"atb":[[12,0]],"id":41286501}],"con":true,"img":false}]}
{"op":"mcm","clk":"5306864819","pt":1646108444771,"mc":[{"id":"1.195395433","rc":[{"atb":[[1.02,1.29]],"id":41286501}],"con":true,"img":false}]}
{"op":"mcm","clk":"5306864830","pt":1646108445234,"mc":[{"id":"1.195395433","rc":[{"atb":[[1.02,0]],"id":41286501}],"con":true,"img":false}]}
{"op":"mcm","clk":"5306864832","pt":1646108445336,"mc":[{"id":"1.195395433","rc":[{"atb":[[12,1.29]],"id":41286501}],"con":true,"img":false}]}
{"op":"mcm","clk":"5306864850","pt":1646108445746,"mc":[{"id":"1.195395433","rc":[{"atb":[[12,0]],"id":41286501}],"con":true,"img":false}]}
{"op":"mcm","clk":"5306864857","pt":1646108445850,"mc":[{"id":"1.195395433","rc":[{"atb":[[1.02,1.29]],"id":41286501}],"con":true,"img":false}]}
{"op":"mcm","clk":"5306864871","pt":1646108446357,"mc":[{"id":"1.195395433","rc":[{"atb":[[1.02,0]],"id":41286501}],"con":true,"img":false}]}
{"op":"mcm","clk":"5306864874","pt":1646108446459,"mc":[{"id":"1.195395433","rc":[{"atb":[[12,1.29]],"id":41286501}],"con":true,"img":false}]}
{"op":"mcm","clk":"5306864890","pt":1646108447075,"mc":[{"id":"1.195395433","rc":[{"atb":[[12,0]],"id":41286501}],"con":true,"img":false}]}
{"op":"mcm","clk":"5306864894","pt":1646108447128,"mc":[{"id":"1.195395433","rc":[{"atb":[[1.02,1.29]],"id":41286501}],"con":true,"img":false}]}
{"op":"mcm","clk":"5306864906","pt":1646108447538,"mc":[{"id":"1.195395433","rc":[{"atb":[[1.02,0]],"id":41286501}],"con":true,"img":false}]}
{"op":"mcm","clk":"5306864907","pt":1646108447639,"mc":[{"id":"1.195395433","rc":[{"atb":[[12,1.29]],"id":41286501}],"con":true,"img":false}]}
{"op":"mcm","clk":"5306864925","pt":1646108448149,"mc":[{"id":"1.195395433","rc":[{"atb":[[12,0]],"id":41286501}],"con":true,"img":false}]}
{"op":"mcm","clk":"5306864930","pt":1646108448253,"mc":[{"id":"1.195395433","rc":[{"atb":[[1.02,1.29]],"id":41286501}],"con":true,"img":false}]}
{"op":"mcm","clk":"5306864944","pt":1646108448863,"mc":[{"id":"1.195395433","rc":[{"atb":[[1.02,0]],"id":41286501}],"con":true,"img":false}]}
{"op":"mcm","clk":"5306864945","pt":1646108448967,"mc":[{"id":"1.195395433","rc":[{"atb":[[12,1.29]],"id":41286501}],"con":true,"img":false}]}
{"op":"mcm","clk":"5306864957","pt":1646108449379,"mc":[{"id":"1.195395433","rc":[{"atb":[[12,0]],"id":41286501}],"con":true,"img":false}]}
{"op":"mcm","clk":"5306864959","pt":1646108449432,"mc":[{"id":"1.195395433","rc":[{"atb":[[1.02,1.29]],"id":41286501}],"con":true,"img":false}]}
{"op":"mcm","clk":"5306864975","pt":1646108449947,"mc":[{"id":"1.195395433","rc":[{"atb":[[1.02,0]],"id":41286501}],"con":true,"img":false}]}
{"op":"mcm","clk":"5306864978","pt":1646108450049,"mc":[{"id":"1.195395433","rc":[{"atb":[[12,1.29]],"id":41286501}],"con":true,"img":false}]}
{"op":"mcm","clk":"5306864987","pt":1646108450660,"mc":[{"id":"1.195395433","rc":[{"atb":[[12,0]],"id":41286501}],"con":true,"img":false}]}
{"op":"mcm","clk":"5306864990","pt":1646108450766,"mc":[{"id":"1.195395433","rc":[{"atb":[[1.02,1.29]],"id":41286501}],"con":true,"img":false}]}
{"op":"mcm","clk":"5306865004","pt":1646108451276,"mc":[{"id":"1.195395433","rc":[{"atb":[[1.02,0]],"id":41286501}],"con":true,"img":false}]}
{"op":"mcm","clk":"5306865007","pt":1646108451378,"mc":[{"id":"1.195395433","rc":[{"atb":[[12,1.29]],"id":41286501}],"con":true,"img":false}]}
{"op":"mcm","clk":"5306865023","pt":1646108451744,"mc":[{"id":"1.195395433","rc":[{"atb":[[12,0]],"id":41286501}],"con":true,"img":false}]}
{"op":"mcm","clk":"5306865025","pt":1646108451847,"mc":[{"id":"1.195395433","rc":[{"atb":[[1.02,1.29]],"id":41286501}],"con":true,"img":false}]}
{"op":"mcm","clk":"5306865040","pt":1646108452458,"mc":[{"id":"1.195395433","rc":[{"atb":[[1.02,0]],"id":41286501}],"con":true,"img":false}]}
{"op":"mcm","clk":"5306865042","pt":1646108452561,"mc":[{"id":"1.195395433","rc":[{"atb":[[12,1.29]],"id":41286501}],"con":true,"img":false}]}
{"op":"mcm","clk":"5306865052","pt":1646108452969,"mc":[{"id":"1.195395433","rc":[{"atb":[[12,0]],"id":41286501}],"con":true,"img":false}]}
{"op":"mcm","clk":"5306865056","pt":1646108453072,"mc":[{"id":"1.195395433","rc":[{"atb":[[1.02,1.29]],"id":41286501}],"con":true,"img":false}]}
{"op":"mcm","clk":"5306865076","pt":1646108453684,"mc":[{"id":"1.195395433","rc":[{"atb":[[1.02,0]],"id":41286501}],"con":true,"img":false}]}
{"op":"mcm","clk":"5306865081","pt":1646108453786,"mc":[{"id":"1.195395433","rc":[{"atb":[[12,1.29]],"id":41286501}],"con":true,"img":false}]}
{"op":"mcm","clk":"5306865097","pt":1646108454144,"mc":[{"id":"1.195395433","rc":[{"atb":[[12,0]],"id":41286501}],"con":true,"img":false}]}
{"op":"mcm","clk":"5306865101","pt":1646108454246,"mc":[{"id":"1.195395433","rc":[{"atb":[[1.02,1.29]],"id":41286501}],"con":true,"img":false}]}
{"op":"mcm","clk":"5306865117","pt":1646108454760,"mc":[{"id":"1.195395433","rc":[{"spn":124.31,"spf":1.0,"id":36474395},{"spn":8.15,"spf":1.0,"id":32825135},{"atb":[[1.02,0]],"id":41286501}],"con":true,"img":false}]}
{"op":"mcm","clk":"5306865119","pt":1646108454862,"mc":[{"id":"1.195395433","rc":[{"atb":[[12,1.29]],"id":41286501}],"con":true,"img":false}]}
{"op":"mcm","clk":"5306865136","pt":1646108455372,"mc":[{"id":"1.195395433","rc":[{"atb":[[12,0]],"id":41286501}],"con":true,"img":false}]}
{"op":"mcm","clk":"5306865141","pt":1646108455473,"mc":[{"id":"1.195395433","rc":[{"atb":[[1.02,1.29]],"id":41286501}],"con":true,"img":false}]}
{"op":"mcm","clk":"5306865157","pt":1646108455985,"mc":[{"id":"1.195395433","rc":[{"atb":[[1.02,0]],"id":41286501}],"con":true,"img":false}]}
{"op":"mcm","clk":"5306865159","pt":1646108456085,"mc":[{"id":"1.195395433","rc":[{"atb":[[12,1.29]],"id":41286501}],"con":true,"img":false}]}
{"op":"mcm","clk":"5306865174","pt":1646108456552,"mc":[{"id":"1.195395433","rc":[{"atb":[[12,0]],"id":41286501}],"con":true,"img":false}]}
{"op":"mcm","clk":"5306865175","pt":1646108456651,"mc":[{"id":"1.195395433","rc":[{"atb":[[1.02,1.29]],"id":41286501}],"con":true,"img":false}]}
{"op":"mcm","clk":"5306865192","pt":1646108457266,"mc":[{"id":"1.195395433","rc":[{"atb":[[1.02,0]],"id":41286501}],"con":true,"img":false}]}
{"op":"mcm","clk":"5306865194","pt":1646108457371,"mc":[{"id":"1.195395433","rc":[{"atb":[[12,1.29]],"id":41286501}],"con":true,"img":false}]}
{"op":"mcm","clk":"5306865204","pt":1646108457777,"mc":[{"id":"1.195395433","rc":[{"atb":[[3.7,0]],"id":28774786},{"atb":[[12,0]],"id":41286501}],"con":true,"img":false}]}
{"op":"mcm","clk":"5306865207","pt":1646108457879,"mc":[{"id":"1.195395433","rc":[{"atb":[[3.8,34.01]],"id":28774786},{"atb":[[1.02,1.29]],"id":41286501}],"con":true,"img":false}]}
{"op":"mcm","clk":"5306865219","pt":1646108458392,"mc":[{"id":"1.195395433","rc":[{"atb":[[1.02,0]],"id":41286501}],"con":true,"img":false}]}
{"op":"mcm","clk":"5306865224","pt":1646108458494,"mc":[{"id":"1.195395433","rc":[{"atb":[[12,1.29]],"id":41286501}],"con":true,"img":false}]}
{"op":"mcm","clk":"5306865235","pt":1646108459061,"mc":[{"id":"1.195395433","rc":[{"atb":[[12,0]],"id":41286501}],"con":true,"img":false}]}
{"op":"mcm","clk":"5306865236","pt":1646108459160,"mc":[{"id":"1.195395433","rc":[{"atb":[[1.02,1.29]],"id":41286501}],"con":true,"img":false}]}
{"op":"mcm","clk":"5306865256","pt":1646108459672,"mc":[{"id":"1.195395433","rc":[{"atb":[[1.02,0]],"id":41286501}],"con":true,"img":false}]}
{"op":"mcm","clk":"5306865259","pt":1646108459775,"mc":[{"id":"1.195395433","rc":[{"atb":[[12,1.29]],"id":41286501}],"con":true,"img":false}]}
{"op":"mcm","clk":"5306865273","pt":1646108460288,"mc":[{"id":"1.195395433","rc":[{"atb":[[12,0]],"id":41286501}],"con":true,"img":false}]}
{"op":"mcm","clk":"5306865276","pt":1646108460390,"mc":[{"id":"1.195395433","rc":[{"atb":[[1.02,1.29]],"id":41286501}],"con":true,"img":false}]}
{"op":"mcm","clk":"5306865289","pt":1646108460752,"mc":[{"id":"1.195395433","rc":[{"atb":[[1.02,0]],"id":41286501}],"con":true,"img":false}]}
{"op":"mcm","clk":"5306865292","pt":1646108460855,"mc":[{"id":"1.195395433","rc":[{"atb":[[12,1.29]],"id":41286501}],"con":true,"img":false}]}
{"op":"mcm","clk":"5306865309","pt":1646108461367,"mc":[{"id":"1.195395433","rc":[{"atb":[[12,0]],"id":41286501}],"con":true,"img":false}]}
{"op":"mcm","clk":"5306865311","pt":1646108461471,"mc":[{"id":"1.195395433","rc":[{"atb":[[1.02,1.29]],"id":41286501}],"con":true,"img":false}]}
{"op":"mcm","clk":"5306865329","pt":1646108462082,"mc":[{"id":"1.195395433","rc":[{"atb":[[1.02,0]],"id":41286501}],"con":true,"img":false}]}
{"op":"mcm","clk":"5306865331","pt":1646108462183,"mc":[{"id":"1.195395433","rc":[{"atb":[[12,1.29]],"id":41286501}],"con":true,"img":false}]}
{"op":"mcm","clk":"5306865348","pt":1646108463000,"mc":[{"id":"1.195395433","rc":[{"atb":[[12,0]],"id":41286501}],"con":true,"img":false}]}
{"op":"mcm","clk":"5306865351","pt":1646108463102,"mc":[{"id":"1.195395433","rc":[{"atb":[[1.02,1.29]],"id":41286501}],"con":true,"img":false}]}
{"op":"mcm","clk":"5306865370","pt":1646108463768,"mc":[{"id":"1.195395433","rc":[{"atb":[[1.02,0]],"id":41286501}],"con":true,"img":false}]}
{"op":"mcm","clk":"5306865371","pt":1646108463873,"mc":[{"id":"1.195395433","rc":[{"atb":[[12,1.29]],"id":41286501}],"con":true,"img":false}]}
{"op":"mcm","clk":"5306865391","pt":1646108464389,"mc":[{"id":"1.195395433","rc":[{"atb":[[12,0]],"id":41286501}],"con":true,"img":false}]}
{"op":"mcm","clk":"5306865393","pt":1646108464489,"mc":[{"id":"1.195395433","rc":[{"atb":[[1.02,1.29]],"id":41286501}],"con":true,"img":false}]}
{"op":"mcm","clk":"5306865396","pt":1646108464592,"mc":[{"id":"1.195395433","rc":[{"atb":[[3.75,3.03]],"id":28774786}],"con":true,"img":false}]}
{"op":"mcm","clk":"5306865408","pt":1646108465001,"mc":[{"id":"1.195395433","rc":[{"atb":[[1.02,0]],"id":41286501}],"con":true,"img":false}]}
{"op":"mcm","clk":"5306865410","pt":1646108465104,"mc":[{"id":"1.195395433","rc":[{"atb":[[12,1.29]],"id":41286501}],"con":true,"img":false}]}
{"op":"mcm","clk":"5306865430","pt":1646108465874,"mc":[{"id":"1.195395433","rc":[{"atb":[[12,0]],"id":41286501}],"con":true,"img":false}]}
{"op":"mcm","clk":"5306865432","pt":1646108465978,"mc":[{"id":"1.195395433","rc":[{"atb":[[1.02,1.29]],"id":41286501}],"con":true,"img":false}]}
{"op":"mcm","clk":"5306865462","pt":1646108466897,"mc":[{"id":"1.195395433","rc":[{"atb":[[1.02,0]],"id":41286501}],"con":true,"img":false}]}
{"op":"mcm","clk":"5306865467","pt":1646108466999,"mc":[{"id":"1.195395433","rc":[{"atb":[[12,1.29]],"id":41286501}],"con":true,"img":false}]}
{"op":"mcm","clk":"5306865501","pt":1646108468086,"mc":[{"id":"1.195395433","rc":[{"atb":[[12,0]],"id":41286501}],"con":true,"img":false}]}
{"op":"mcm","clk":"5306865505","pt":1646108468179,"mc":[{"id":"1.195395433","rc":[{"atb":[[1.02,1.29]],"id":41286501}],"con":true,"img":false}]}
{"op":"mcm","clk":"5306865514","pt":1646108468588,"mc":[{"id":"1.195395433","rc":[{"atb":[[1.02,0]],"id":41286501}],"con":true,"img":false}]}
{"op":"mcm","clk":"5306865518","pt":1646108468687,"mc":[{"id":"1.195395433","rc":[{"atb":[[12,1.29]],"id":41286501}],"con":true,"img":false}]}
{"op":"mcm","clk":"5306865531","pt":1646108469200,"mc":[{"id":"1.195395433","rc":[{"atb":[[12,0]],"id":41286501}],"con":true,"img":false}]}
{"op":"mcm","clk":"5306865537","pt":1646108469301,"mc":[{"id":"1.195395433","rc":[{"atb":[[1.02,1.29]],"id":41286501}],"con":true,"img":false}]}
{"op":"mcm","clk":"5306865553","pt":1646108469814,"mc":[{"id":"1.195395433","rc":[{"atb":[[1.02,0]],"id":41286501}],"con":true,"img":false}]}
{"op":"mcm","clk":"5306865556","pt":1646108469869,"mc":[{"id":"1.195395433","rc":[{"atb":[[12,1.29]],"id":41286501}],"con":true,"img":false}]}
{"op":"mcm","clk":"5306865583","pt":1646108470380,"mc":[{"id":"1.195395433","rc":[{"atb":[[12,0]],"id":41286501}],"con":true,"img":false}]}
{"op":"mcm","clk":"5306865588","pt":1646108470483,"mc":[{"id":"1.195395433","rc":[{"atb":[[1.02,1.29]],"id":41286501}],"con":true,"img":false}]}
{"op":"mcm","clk":"5306865602","pt":1646108470993,"mc":[{"id":"1.195395433","rc":[{"atb":[[1.02,0]],"id":41286501}],"con":true,"img":false}]}
{"op":"mcm","clk":"5306865606","pt":1646108471093,"mc":[{"id":"1.195395433","rc":[{"atb":[[12,1.29]],"id":41286501}],"con":true,"img":false}]}
{"op":"mcm","clk":"5306865624","pt":1646108471606,"mc":[{"id":"1.195395433","rc":[{"atb":[[12,0]],"id":41286501}],"con":true,"img":false}]}
{"op":"mcm","clk":"5306865629","pt":1646108471708,"mc":[{"id":"1.195395433","rc":[{"atb":[[1.02,1.29]],"id":41286501}],"con":true,"img":false}]}
{"op":"mcm","clk":"5306865650","pt":1646108472222,"mc":[{"id":"1.195395433","rc":[{"atb":[[1.02,0]],"id":41286501}],"con":true,"img":false}]}
{"op":"mcm","clk":"5306865652","pt":1646108472275,"mc":[{"id":"1.195395433","rc":[{"atb":[[12,1.29]],"id":41286501}],"con":true,"img":false}]}
{"op":"mcm","clk":"5306865665","pt":1646108472785,"mc":[{"id":"1.195395433","rc":[{"atb":[[12,0]],"id":41286501}],"con":true,"img":false}]}
{"op":"mcm","clk":"5306865668","pt":1646108472887,"mc":[{"id":"1.195395433","rc":[{"atb":[[1.02,1.29]],"id":41286501}],"con":true,"img":false}]}
{"op":"mcm","clk":"5306865676","pt":1646108473298,"mc":[{"id":"1.195395433","rc":[{"atb":[[3.75,0]],"id":28774786}],"con":true,"img":false}]}
{"op":"mcm","clk":"5306865677","pt":1646108473398,"mc":[{"id":"1.195395433","rc":[{"atb":[[1.02,0]],"id":41286501}],"con":true,"img":false}]}
{"op":"mcm","clk":"5306865680","pt":1646108473500,"mc":[{"id":"1.195395433","rc":[{"atb":[[12,1.29]],"id":41286501}],"con":true,"img":false}]}
{"op":"mcm","clk":"5306865683","pt":1646108473602,"mc":[{"id":"1.195395433","rc":[{"atb":[[3.85,2.61]],"id":28774786}],"con":true,"img":false}]}
{"op":"mcm","clk":"5306865690","pt":1646108474012,"mc":[{"id":"1.195395433","rc":[{"atb":[[12,0]],"id":41286501}],"con":true,"img":false}]}
{"op":"mcm","clk":"5306865692","pt":1646108474115,"mc":[{"id":"1.195395433","rc":[{"atb":[[1.02,1.29]],"id":41286501}],"con":true,"img":false}]}
{"op":"mcm","clk":"5306865702","pt":1646108474577,"mc":[{"id":"1.195395433","rc":[{"atb":[[1.02,0]],"id":41286501}],"con":true,"img":false}]}
{"op":"mcm","clk":"5306865705","pt":1646108474680,"mc":[{"id":"1.195395433","rc":[{"atb":[[12,1.29]],"id":41286501}],"con":true,"img":false}]}
{"op":"mcm","clk":"5306865729","pt":1646108475316,"mc":[{"id":"1.195395433","rc":[{"atb":[[12,0]],"id":41286501}],"con":true,"img":false}]}
{"op":"mcm","clk":"5306865732","pt":1646108475420,"mc":[{"id":"1.195395433","rc":[{"atb":[[1.02,1.29]],"id":41286501}],"con":true,"img":false}]}
{"op":"mcm","clk":"5306865742","pt":1646108475679,"mc":[{"id":"1.195395433","rc":[{"atb":[[1.05,596.74]],"id":36474395},{"atb":[[1.05,474.04]],"id":28774786},{"atb":[[1.05,515.09]],"id":32825135},{"atb":[[1.05,564.85]],"id":41286501},{"atb":[[1.05,587.78]],"id":38375776},{"atb":[[1.05,398.74]],"id":40835929},{"atb":[[1.05,369.8]],"id":34135026}],"con":true,"img":false}]}
{"op":"mcm","clk":"5306865745","pt":1646108475781,"mc":[{"id":"1.195395433","rc":[{"atb":[[1.02,0]],"id":41286501}],"con":true,"img":false}]}
{"op":"mcm","clk":"5306865746","pt":1646108475884,"mc":[{"id":"1.195395433","rc":[{"atb":[[12,1.29]],"id":41286501}],"con":true,"img":false}]}
{"op":"mcm","clk":"5306865758","pt":1646108476393,"mc":[{"id":"1.195395433","rc":[{"atb":[[12,0]],"id":41286501}],"con":true,"img":false}]}
{"op":"mcm","clk":"5306865760","pt":1646108476499,"mc":[{"id":"1.195395433","rc":[{"atb":[[1.02,1.29]],"id":41286501}],"con":true,"img":false}]}
{"op":"mcm","clk":"5306865782","pt":1646108477416,"mc":[{"id":"1.195395433","rc":[{"atb":[[1.02,0]],"id":41286501}],"con":true,"img":false}]}
{"op":"mcm","clk":"5306865784","pt":1646108477518,"mc":[{"id":"1.195395433","rc":[{"atb":[[12,1.29]],"id":41286501}],"con":true,"img":false}]}
{"op":"mcm","clk":"5306865798","pt":1646108478185,"mc":[{"id":"1.195395433","rc":[{"atb":[[12,0]],"id":41286501}],"con":true,"img":false}]}
{"op":"mcm","clk":"5306865803","pt":1646108478288,"mc":[{"id":"1.195395433","rc":[{"atb":[[1.02,1.29]],"id":41286501}],"con":true,"img":false}]}
{"op":"mcm","clk":"5306865819","pt":1646108478801,"mc":[{"id":"1.195395433","rc":[{"atb":[[1.02,0]],"id":41286501}],"con":true,"img":false}]}
{"op":"mcm","clk":"5306865822","pt":1646108478904,"mc":[{"id":"1.195395433","rc":[{"atb":[[12,1.29]],"id":41286501}],"con":true,"img":false}]}
{"op":"mcm","clk":"5306865830","pt":1646108479214,"mc":[{"id":"1.195395433","rc":[{"atb":[[3.85,5.54]],"id":28774786}],"con":true,"img":false}]}
{"op":"mcm","clk":"5306865836","pt":1646108479420,"mc":[{"id":"1.195395433","rc":[{"atb":[[12,0]],"id":41286501}],"con":true,"img":false}]}
{"op":"mcm","clk":"5306865839","pt":1646108479522,"mc":[{"id":"1.195395433","rc":[{"atb":[[1.02,1.29]],"id":41286501}],"con":true,"img":false}]}
{"op":"mcm","clk":"5306865856","pt":1646108479986,"mc":[{"id":"1.195395433","rc":[{"atb":[[1.02,0]],"id":41286501}],"con":true,"img":false}]}
{"op":"mcm","clk":"5306865860","pt":1646108480089,"mc":[{"id":"1.195395433","rc":[{"atb":[[12,1.29]],"id":41286501}],"con":true,"img":false}]}
{"op":"mcm","clk":"5306865877","pt":1646108480702,"mc":[{"id":"1.195395433","rc":[{"atb":[[12,0]],"id":41286501}],"con":true,"img":false}]}
{"op":"mcm","clk":"5306865880","pt":1646108480805,"mc":[{"id":"1.195395433","rc":[{"atb":[[1.02,1.29]],"id":41286501}],"con":true,"img":false}]}
{"op":"mcm","clk":"5306865888","pt":1646108481212,"mc":[{"id":"1.195395433","rc":[{"atb":[[1.02,0]],"id":41286501}],"con":true,"img":false}]}
{"op":"mcm","clk":"5306865891","pt":1646108481313,"mc":[{"id":"1.195395433","rc":[{"atb":[[12,1.29]],"id":41286501}],"con":true,"img":false}]}
{"op":"mcm","clk":"5306865903","pt":1646108481824,"mc":[{"id":"1.195395433","rc":[{"atb":[[12,0]],"id":41286501}],"con":true,"img":false}]}
{"op":"mcm","clk":"5306865904","pt":1646108481926,"mc":[{"id":"1.195395433","rc":[{"atb":[[1.02,1.29]],"id":41286501}],"con":true,"img":false}]}
{"op":"mcm","clk":"5306865913","pt":1646108482387,"mc":[{"id":"1.195395433","rc":[{"atb":[[1.02,0]],"id":41286501}],"con":true,"img":false}]}
{"op":"mcm","clk":"5306865915","pt":1646108482489,"mc":[{"id":"1.195395433","rc":[{"atb":[[12,1.29]],"id":41286501}],"con":true,"img":false}]}
{"op":"mcm","clk":"5306865924","pt":1646108483000,"mc":[{"id":"1.195395433","rc":[{"atb":[[12,0]],"id":41286501}],"con":true,"img":false}]}
{"op":"mcm","clk":"5306865925","pt":1646108483105,"mc":[{"id":"1.195395433","rc":[{"atb":[[1.02,1.29]],"id":41286501}],"con":true,"img":false}]}
{"op":"mcm","clk":"5306865936","pt":1646108483613,"mc":[{"id":"1.195395433","rc":[{"atb":[[1.02,0]],"id":41286501}],"con":true,"img":false}]}
{"op":"mcm","clk":"5306865939","pt":1646108483715,"mc":[{"id":"1.195395433","rc":[{"atb":[[12,1.29]],"id":41286501}],"con":true,"img":false}]}
{"op":"mcm","clk":"5306865954","pt":1646108484226,"mc":[{"id":"1.195395433","rc":[{"atb":[[12,0]],"id":41286501}],"con":true,"img":false}]}
{"op":"mcm","clk":"5306865958","pt":1646108484326,"mc":[{"id":"1.195395433","rc":[{"atb":[[1.02,1.29]],"id":41286501}],"con":true,"img":false}]}
{"op":"mcm","clk":"5306865975","pt":1646108484792,"mc":[{"id":"1.195395433","rc":[{"atb":[[1.02,0]],"id":41286501}],"con":true,"img":false}]}
{"op":"mcm","clk":"5306865978","pt":1646108484893,"mc":[{"id":"1.195395433","rc":[{"atb":[[12,1.29]],"id":41286501}],"con":true,"img":false}]}
{"op":"mcm","clk":"5306865990","pt":1646108485406,"mc":[{"id":"1.195395433","rc":[{"atb":[[12,0]],"id":41286501}],"con":true,"img":false}]}
{"op":"mcm","clk":"5306865991","pt":1646108485510,"mc":[{"id":"1.195395433","rc":[{"atb":[[1.02,1.29]],"id":41286501}],"con":true,"img":false}]}
{"op":"mcm","clk":"5306866007","pt":1646108486020,"mc":[{"id":"1.195395433","rc":[{"atb":[[1.02,0]],"id":41286501}],"con":true,"img":false}]}
{"op":"mcm","clk":"5306866010","pt":1646108486122,"mc":[{"id":"1.195395433","rc":[{"atb":[[12,1.29]],"id":41286501}],"con":true,"img":false}]}
{"op":"mcm","clk":"5306866023","pt":1646108486634,"mc":[{"id":"1.195395433","rc":[{"atb":[[12,0]],"id":41286501}],"con":true,"img":false}]}
{"op":"mcm","clk":"5306866027","pt":1646108486736,"mc":[{"id":"1.195395433","rc":[{"atb":[[1.02,1.29]],"id":41286501}],"con":true,"img":false}]}
{"op":"mcm","clk":"5306866042","pt":1646108487202,"mc":[{"id":"1.195395433","rc":[{"atb":[[1.02,0]],"id":41286501}],"con":true,"img":false}]}
{"op":"mcm","clk":"5306866046","pt":1646108487313,"mc":[{"id":"1.195395433","rc":[{"atb":[[12,1.29]],"id":41286501}],"con":true,"img":false}]}
{"op":"mcm","clk":"5306866062","pt":1646108487713,"mc":[{"id":"1.195395433","rc":[{"atb":[[12,0]],"id":41286501}],"con":true,"img":false}]}
{"op":"mcm","clk":"5306866066","pt":1646108487816,"mc":[{"id":"1.195395433","rc":[{"atb":[[1.02,1.29]],"id":41286501}],"con":true,"img":false}]}
{"op":"mcm","clk":"5306866086","pt":1646108488531,"mc":[{"id":"1.195395433","rc":[{"atb":[[1.02,0]],"id":41286501}],"con":true,"img":false}]}
{"op":"mcm","clk":"5306866088","pt":1646108488634,"mc":[{"id":"1.195395433","rc":[{"atb":[[12,1.29]],"id":41286501}],"con":true,"img":false}]}
{"op":"mcm","clk":"5306866098","pt":1646108488991,"mc":[{"id":"1.195395433","rc":[{"atb":[[12,0]],"id":41286501}],"con":true,"img":false}]}
{"op":"mcm","clk":"5306866100","pt":1646108489101,"mc":[{"id":"1.195395433","rc":[{"atb":[[1.02,1.29]],"id":41286501}],"con":true,"img":false}]}
{"op":"mcm","clk":"5306866119","pt":1646108489915,"mc":[{"id":"1.195395433","rc":[{"atb":[[1.02,0]],"id":41286501}],"con":true,"img":false}]}
{"op":"mcm","clk":"5306866122","pt":1646108490012,"mc":[{"id":"1.195395433","rc":[{"atb":[[12,1.29]],"id":41286501}],"con":true,"img":false}]}
{"op":"mcm","clk":"5306866130","pt":1646108490218,"mc":[{"id":"1.195395433","rc":[{"atb":[[12,0]],"id":41286501}],"con":true,"img":false}]}
{"op":"mcm","clk":"5306866134","pt":1646108490322,"mc":[{"id":"1.195395433","rc":[{"atb":[[1.02,1.29]],"id":41286501}],"con":true,"img":false}]}
{"op":"mcm","clk":"5306866142","pt":1646108490835,"mc":[{"id":"1.195395433","rc":[{"atb":[[1.02,0]],"id":41286501}],"con":true,"img":false}]}
{"op":"mcm","clk":"5306866144","pt":1646108490959,"mc":[{"id":"1.195395433","rc":[{"atb":[[12,1.29]],"id":41286501}],"con":true,"img":false}]}
{"op":"mcm","clk":"5306866150","pt":1646108491403,"mc":[{"id":"1.195395433","rc":[{"atb":[[12,0]],"id":41286501}],"con":true,"img":false}]}
{"op":"mcm","clk":"5306866152","pt":1646108491505,"mc":[{"id":"1.195395433","rc":[{"atb":[[1.02,1.29]],"id":41286501}],"con":true,"img":false}]}
{"op":"mcm","clk":"5306866160","pt":1646108492017,"mc":[{"id":"1.195395433","rc":[{"atb":[[1.02,0]],"id":41286501}],"con":true,"img":false}]}
{"op":"mcm","clk":"5306866163","pt":1646108492120,"mc":[{"id":"1.195395433","rc":[{"atb":[[12,1.29]],"id":41286501}],"con":true,"img":false}]}
{"op":"mcm","clk":"5306866178","pt":1646108492632,"mc":[{"id":"1.195395433","rc":[{"atb":[[12,0]],"id":41286501}],"con":true,"img":false}]}
{"op":"mcm","clk":"5306866183","pt":1646108492735,"mc":[{"id":"1.195395433","rc":[{"atb":[[1.02,1.29]],"id":41286501}],"con":true,"img":false}]}
{"op":"mcm","clk":"5306866202","pt":1646108493199,"mc":[{"id":"1.195395433","rc":[{"atb":[[1.02,0]],"id":41286501}],"con":true,"img":false}]}
{"op":"mcm","clk":"5306866205","pt":1646108493310,"mc":[{"id":"1.195395433","rc":[{"atb":[[12,1.29]],"id":41286501}],"con":true,"img":false}]}
{"op":"mcm","clk":"5306866220","pt":1646108493813,"mc":[{"id":"1.195395433","rc":[{"atb":[[12,0]],"id":41286501}],"con":true,"img":false}]}
{"op":"mcm","clk":"5306866222","pt":1646108493916,"mc":[{"id":"1.195395433","rc":[{"atb":[[1.02,1.29]],"id":41286501}],"con":true,"img":false}]}
{"op":"mcm","clk":"5306866232","pt":1646108494426,"mc":[{"id":"1.195395433","rc":[{"atb":[[1.02,0]],"id":41286501}],"con":true,"img":false}]}
{"op":"mcm","clk":"5306866234","pt":1646108494529,"mc":[{"id":"1.195395433","rc":[{"atb":[[12,1.29]],"id":41286501}],"con":true,"img":false}]}
{"op":"mcm","clk":"5306866243","pt":1646108494938,"mc":[{"id":"1.195395433","rc":[{"atb":[[12,0]],"id":41286501}],"con":true,"img":false}]}
{"op":"mcm","clk":"5306866246","pt":1646108495040,"mc":[{"id":"1.195395433","rc":[{"atb":[[1.02,1.29]],"id":41286501}],"con":true,"img":false}]}
{"op":"mcm","clk":"5306866259","pt":1646108495606,"mc":[{"id":"1.195395433","rc":[{"atb":[[1.02,0]],"id":41286501}],"con":true,"img":false}]}
{"op":"mcm","clk":"5306866263","pt":1646108495708,"mc":[{"id":"1.195395433","rc":[{"atb":[[12,1.29]],"id":41286501}],"con":true,"img":false}]}
{"op":"mcm","clk":"5306866280","pt":1646108496219,"mc":[{"id":"1.195395433","rc":[{"atb":[[12,0]],"id":41286501}],"con":true,"img":false}]}
{"op":"mcm","clk":"5306866283","pt":1646108496324,"mc":[{"id":"1.195395433","rc":[{"atb":[[1.02,1.29]],"id":41286501}],"con":true,"img":false}]}
{"op":"mcm","clk":"5306866297","pt":1646108496831,"mc":[{"id":"1.195395433","rc":[{"atb":[[1.02,0]],"id":41286501}],"con":true,"img":false}]}
{"op":"mcm","clk":"5306866300","pt":1646108496931,"mc":[{"id":"1.195395433","rc":[{"atb":[[12,1.29]],"id":41286501}],"con":true,"img":false}]}
{"op":"mcm","clk":"5306866320","pt":1646108497701,"mc":[{"id":"1.195395433","rc":[{"atb":[[12,0]],"id":41286501}],"con":true,"img":false}]}
{"op":"mcm","clk":"5306866324","pt":1646108497805,"mc":[{"id":"1.195395433","rc":[{"atb":[[1.02,1.29]],"id":41286501}],"con":true,"img":false}]}
{"op":"mcm","clk":"5306866330","pt":1646108498011,"mc":[{"id":"1.195395433","rc":[{"atb":[[1.02,0]],"id":41286501}],"con":true,"img":false}]}
{"op":"mcm","clk":"5306866336","pt":1646108498110,"mc":[{"id":"1.195395433","rc":[{"atb":[[12,1.29]],"id":41286501}],"con":true,"img":false}]}
{"op":"mcm","clk":"5306866353","pt":1646108498619,"mc":[{"id":"1.195395433","rc":[{"atb":[[12,0]],"id":41286501}],"con":true,"img":false}]}
{"op":"mcm","clk":"5306866355","pt":1646108498722,"mc":[{"id":"1.195395433","rc":[{"atb":[[1.02,1.29]],"id":41286501}],"con":true,"img":false}]}
{"op":"mcm","clk":"5306866366","pt":1646108499231,"mc":[{"id":"1.195395433","rc":[{"atb":[[3.8,10.81]],"id":28774786},{"atb":[[1.02,0]],"id":41286501}],"con":true,"img":false}]}
{"op":"mcm","clk":"5306866369","pt":1646108499332,"mc":[{"id":"1.195395433","rc":[{"atb":[[3.85,28.74]],"id":28774786},{"atb":[[12,1.29]],"id":41286501}],"con":true,"img":false}]}
{"op":"mcm","clk":"5306866380","pt":1646108499742,"mc":[{"id":"1.195395433","rc":[{"atb":[[12,0]],"id":41286501}],"con":true,"img":false}]}
{"op":"mcm","clk":"5306866381","pt":1646108499844,"mc":[{"id":"1.195395433","rc":[{"atb":[[1.02,1.29]],"id":41286501}],"con":true,"img":false}]}
{"op":"mcm","clk":"5306866406","pt":1646108500420,"mc":[{"id":"1.195395433","rc":[{"atb":[[1.02,0]],"id":41286501}],"con":true,"img":false}]}
{"op":"mcm","clk":"5306866409","pt":1646108500518,"mc":[{"id":"1.195395433","rc":[{"atb":[[12,1.29]],"id":41286501}],"con":true,"img":false}]}
{"op":"mcm","clk":"5306866424","pt":1646108500925,"mc":[{"id":"1.195395433","rc":[{"atb":[[3.05,7.95]],"id":40835929},{"trd":[[3.05,30.69]],"ltp":3.05,"tv":30.69,"id":40835929}],"con":true,"img":false}]}
{"op":"mcm","clk":"5306866426","pt":1646108501029,"mc":[{"id":"1.195395433","rc":[{"atb":[[12,0]],"id":41286501}],"con":true,"img":false}]}
{"op":"mcm","clk":"5306866432","pt":1646108501130,"mc":[{"id":"1.195395433","rc":[{"atb":[[1.02,1.29]],"id":41286501}],"con":true,"img":false}]}
{"op":"mcm","clk":"5306866444","pt":1646108501639,"mc":[{"id":"1.195395433","rc":[{"atb":[[1.02,0]],"id":41286501}],"con":true,"img":false}]}
{"op":"mcm","clk":"5306866446","pt":1646108501742,"mc":[{"id":"1.195395433","rc":[{"atb":[[12,1.29]],"id":41286501},{"atl":[[3.95,2.95]],"id":40835929}],"con":true,"img":false}]}
{"op":"mcm","clk":"5306866460","pt":1646108502255,"mc":[{"id":"1.195395433","rc":[{"atb":[[12,0]],"id":41286501}],"con":true,"img":false}]}
{"op":"mcm","clk":"5306866463","pt":1646108502309,"mc":[{"id":"1.195395433","rc":[{"atb":[[1.02,1.29]],"id":41286501}],"con":true,"img":false}]}
{"op":"mcm","clk":"5306866484","pt":1646108502820,"mc":[{"id":"1.195395433","rc":[{"atb":[[1.02,0]],"id":41286501}],"con":true,"img":false}]}
{"op":"mcm","clk":"5306866490","pt":1646108502921,"mc":[{"id":"1.195395433","rc":[{"atb":[[12,1.29]],"id":41286501}],"con":true,"img":false}]}
{"op":"mcm","clk":"5306866498","pt":1646108503228,"mc":[{"id":"1.195395433","rc":[{"atb":[[1.1,314.7]],"id":40835929}],"con":true,"img":false}]}
{"op":"mcm","clk":"5306866501","pt":1646108503432,"mc":[{"id":"1.195395433","rc":[{"atb":[[12,0]],"id":41286501}],"con":true,"img":false}]}
{"op":"mcm","clk":"5306866505","pt":1646108503533,"mc":[{"id":"1.195395433","rc":[{"atb":[[1.02,1.29]],"id":41286501}],"con":true,"img":false}]}
{"op":"mcm","clk":"5306866531","pt":1646108504355,"mc":[{"id":"1.195395433","rc":[{"atb":[[1.02,0]],"id":41286501}],"con":true,"img":false}]}
{"op":"mcm","clk":"5306866535","pt":1646108504411,"mc":[{"id":"1.195395433","rc":[{"atb":[[12,1.29]],"id":41286501}],"con":true,"img":false}]}
{"op":"mcm","clk":"5306866543","pt":1646108504716,"mc":[{"id":"1.195395433","rc":[{"atb":[[12,0]],"id":41286501}],"con":true,"img":false}]}
{"op":"mcm","clk":"5306866547","pt":1646108504821,"mc":[{"id":"1.195395433","rc":[{"atb":[[1.02,1.29]],"id":41286501}],"con":true,"img":false}]}
{"op":"mcm","clk":"5306866557","pt":1646108505229,"mc":[{"id":"1.195395433","rc":[{"atb":[[1.02,0]],"id":41286501}],"con":true,"img":false}]}
{"op":"mcm","clk":"5306866560","pt":1646108505330,"mc":[{"id":"1.195395433","rc":[{"atb":[[12,1.29]],"id":41286501}],"con":true,"img":false}]}
{"op":"mcm","clk":"5306866571","pt":1646108505743,"mc":[{"id":"1.195395433","rc":[{"atb":[[12,0]],"id":41286501}],"con":true,"img":false}]}
{"op":"mcm","clk":"5306866575","pt":1646108505845,"mc":[{"id":"1.195395433","rc":[{"atb":[[1.02,1.29]],"id":41286501}],"con":true,"img":false}]}
{"op":"mcm","clk":"5306866580","pt":1646108506047,"mc":[{"id":"1.195395433","rc":[{"atb":[[2.38,5.08]],"id":34135026},{"trd":[[2.38,0.65]],"ltp":2.38,"tv":0.65,"id":34135026}],"con":true,"img":false}]}
{"op":"mcm","clk":"5306866583","pt":1646108506148,"mc":[{"id":"1.195395433","rc":[{"atb":[[2.32,0]],"id":34135026}],"con":true,"img":false}]}
{"op":"mcm","clk":"5306866587","pt":1646108506455,"mc":[{"id":"1.195395433","rc":[{"atb":[[1.02,0]],"id":41286501}],"con":true,"img":false}]}
{"op":"mcm","clk":"5306866591","pt":1646108506556,"mc":[{"id":"1.195395433","rc":[{"atb":[[12,1.29]],"id":41286501}],"con":true,"img":false}]}
{"op":"mcm","clk":"5306866597","pt":1646108506815,"mc":[{"id":"1.195395433","rc":[{"atb":[[3.85,26.12]],"id":28774786}],"con":true,"img":false}]}
{"op":"mcm","clk":"5306866601","pt":1646108507023,"mc":[{"id":"1.195395433","rc":[{"atb":[[12,0]],"id":41286501}],"con":true,"img":false}]}
{"op":"mcm","clk":"5306866604","pt":1646108507125,"mc":[{"id":"1.195395433","rc":[{"atb":[[1.02,1.29]],"id":41286501}],"con":true,"img":false}]}
{"op":"mcm","clk":"5306866608","pt":1646108507228,"mc":[{"id":"1.195395433","rc":[{"atb":[[2.38,5.03]],"id":34135026},{"trd":[[2.38,0.75]],"ltp":2.38,"tv":0.75,"id":34135026}],"con":true,"img":false}]}
{"op":"mcm","clk":"5306866618","pt":1646108507536,"mc":[{"id":"1.195395433","rc":[{"atb":[[1.02,0]],"id":41286501},{"atb":[[2.38,3.67]],"id":34135026},{"trd":[[2.38,0.85]],"ltp":2.38,"tv":0.85,"id":34135026}],"con":true,"img":false}]}
{"op":"mcm","clk":"5306866621","pt":1646108507637,"mc":[{"id":"1.195395433","rc":[{"atb":[[1.01,4.87]],"id":36474395},{"atb":[[3.3,10.83]],"id":28774786},{"atl":[[8.8,19.6]],"id":28774786},{"atb":[[4.9,10.29]],"id":32825135},{"atl":[[14.5,12.35]],"id":32825135},{"atb":[[1.01,4.87],[12,1.29]],"id":41286501},{"atl":[[42,3.7]],"id":41286501},{"atb":[[1.01,3.36]],"id":38375776},{"atl":[[220,3.7]],"id":38375776},{"atb":[[2.46,17.06]],"id":40835929},{"atb":[[2.36,1.31],[1.59,42.23],[2.38,3.62]],"id":34135026},{"trd":[[2.38,0.96]],"ltp":2.38,"tv":0.96,"id":34135026}],"con":true,"img":false}]}
{"op":"mcm","clk":"5306866623","pt":1646108507841,"mc":[{"id":"1.195395433","rc":[{"atb":[[1.01,1.83]],"id":36474395},{"atb":[[1.01,4.46]],"id":41286501},{"atb":[[1.01,1.34]],"id":38375776}],"con":true,"img":false}]}
{"op":"mcm","clk":"5306866628","pt":1646108508048,"mc":[{"id":"1.195395433","rc":[{"atb":[[1.01,1.5]],"id":36474395},{"atb":[[1.01,1.5]],"id":41286501},{"atb":[[1.01,0]],"id":38375776}],"con":true,"img":false}]}
{"op":"mcm","clk":"5306866633","pt":1646108508148,"mc":[{"id":"1.195395433","rc":[{"atb":[[75,0.33]],"id":36474395},{"atb":[[9.4,18.1]],"id":41286501},{"atb":[[19.5,1.34]],"id":38375776}],"con":true,"img":false}]}
{"op":"mcm","clk":"5306866645","pt":1646108508454,"mc":[{"id":"1.195395433","rc":[{"atb":[[12,0]],"id":41286501}],"con":true,"img":false}]}
{"op":"mcm","clk":"5306866650","pt":1646108508556,"mc":[{"id":"1.195395433","rc":[{"atb":[[1.02,1.29]],"id":41286501}],"con":true,"img":false}]}
{"op":"mcm","clk":"5306866662","pt":1646108508864,"mc":[{"id":"1.195395433","rc":[{"atb":[[1.02,0]],"id":41286501}],"con":true,"img":false}]}
{"op":"mcm","clk":"5306866666","pt":1646108508918,"mc":[{"id":"1.195395433","rc":[{"atb":[[12,1.29]],"id":41286501}],"con":true,"img":false}]}
{"op":"mcm","clk":"5306866669","pt":1646108509022,"mc":[{"id":"1.195395433","rc":[{"atl":[[3.2,3.38]],"id":34135026}],"con":true,"img":false}]}
{"op":"mcm","clk":"5306866680","pt":1646108509330,"mc":[{"id":"1.195395433","rc":[{"atl":[[3.25,21.63],[1000,1.66]],"id":34135026}],"con":true,"img":false}]}
{"op":"mcm","clk":"5306866681","pt":1646108509430,"mc":[{"id":"1.195395433","rc":[{"atl":[[3.15,1.3]],"id":34135026}],"con":true,"img":false}]}
{"op":"mcm","clk":"5306866682","pt":1646108509533,"mc":[{"id":"1.195395433","rc":[{"atb":[[4.3,0],[2.66,0]],"id":36474395},{"atl":[[17,0],[34,0]],"id":28774786},{"atb":[[2.66,0]],"id":32825135},{"atl":[[34,0]],"id":32825135},{"atb":[[4.3,0],[2.66,0]],"id":41286501},{"atb":[[4.3,0],[2.66,0]],"id":38375776},{"atl":[[17,0],[34,0]],"id":40835929},{"atl":[[34,0],[17,0]],"id":34135026}],"con":true,"img":false}]}
{"op":"mcm","clk":"5306866684","pt":1646108509636,"mc":[{"id":"1.195395433","rc":[{"atl":[[1000,0.35]],"id":34135026}],"con":true,"img":false}]}
{"op":"mcm","clk":"5306866690","pt":1646108509840,"mc":[{"id":"1.195395433","rc":[{"atl":[[1000,0]],"id":34135026}],"con":true,"img":false}]}
{"op":"mcm","clk":"5306866694","pt":1646108509943,"mc":[{"id":"1.195395433","rc":[{"atl":[[3.2,3.73]],"id":34135026}],"con":true,"img":false}]}
{"op":"mcm","clk":"5306866703","pt":1646108510249,"mc":[{"id":"1.195395433","rc":[{"atb":[[3.95,78.15]],"id":40835929},{"atl":[[3.95,0]],"id":40835929},{"trd":[[3.95,5.91]],"ltp":3.95,"tv":5.91,"id":40835929}],"con":true,"img":false}]}
{"op":"mcm","clk":"5306866720","pt":1646108510862,"mc":[{"id":"1.195395433","rc":[{"atb":[[3.35,10.6]],"id":40835929}],"con":true,"img":false}]}
{"op":"mcm","clk":"5306866750","pt":1646108511939,"mc":[{"id":"1.195395433","rc":[{"atl":[[3.2,3.38]],"id":34135026}],"con":true,"img":false}]}
{"op":"mcm","clk":"5306866840","pt":1646108514146,"mc":[{"id":"1.195395433","rc":[{"atb":[[110,0.39]],"id":36474395},{"atb":[[3.85,2.93],[3.5,0],[3.15,36.51]],"id":28774786},{"atl":[[7.2,1.33],[8.2,6]],"id":28774786},{"atb":[[4.1,21.32]],"id":32825135},{"atl":[[10.5,0],[12.5,3.76]],"id":32825135},{"atb":[[9.4,11.93]],"id":41286501},{"atl":[[46,0],[28,0],[60,3.98]],"id":41286501},{"atl":[[140,0.31],[100,0]],"id":38375776},{"atb":[[2.76,0],[2.66,30.25]],"id":40835929},{"atl":[[5.5,0]],"id":40835929},{"atl":[[4.5,12.36],[3.85,0],[1000,1.66]],"id":34135026}],"con":true,"img":false}]}
{"op":"mcm","clk":"5306866844","pt":1646108514248,"mc":[{"id":"1.195395433","rc":[{"atb":[[3.5,23.19]],"id":28774786},{"atl":[[30,2.7]],"id":41286501},{"atl":[[150,2.7]],"id":38375776},{"atl":[[5.7,12.61]],"id":40835929}],"con":true,"img":false}]}
{"op":"mcm","clk":"5306866849","pt":1646108514350,"mc":[{"id":"1.195395433","rc":[{"atl":[[1000,0.36]],"id":34135026}],"con":true,"img":false}]}
{"op":"mcm","clk":"5306866858","pt":1646108514654,"mc":[{"id":"1.195395433","rc":[{"atl":[[1000,0]],"id":34135026}],"con":true,"img":false}]}
{"op":"mcm","clk":"5306866860","pt":1646108514757,"mc":[{"id":"1.195395433","rc":[{"atl":[[3.1,0.36]],"id":34135026}],"con":true,"img":false}]}
{"op":"mcm","clk":"5306866864","pt":1646108514858,"mc":[{"id":"1.195395433","rc":[{"spn":119.93,"spf":1.0,"id":36474395},{"atl":[[7.2,0]],"id":28774786},{"spn":6.05,"spf":1.0,"id":28774786},{"atl":[[1000,0]],"id":32825135},{"spn":9.15,"spf":1.0,"id":32825135},{"atb":[[12,0]],"id":41286501},{"atl":[[27,0]],"id":41286501},{"spn":21.0,"spf":1.0,"id":41286501},{"spn":3.35,"spf":1.0,"id":40835929},{"spn":2.74,"spf":1.0,"id":34135026}],"con":true,"img":false}]}
{"op":"mcm","clk":"5306866867","pt":1646108514961,"mc":[{"id":"1.195395433","rc":[{"atl":[[8,1.33]],"id":28774786},{"atl":[[12,1.39]],"id":32825135},{"atb":[[1.02,1.29]],"id":41286501},{"atl":[[28,1.32]],"id":41286501}],"con":true,"img":false}]}
{"op":"mcm","clk":"5306866874","pt":1646108515266,"mc":[{"id":"1.195395433","rc":[{"atb":[[3.85,0]],"id":28774786}],"con":true,"img":false}]}
{"op":"mcm","clk":"5306866880","pt":1646108515469,"mc":[{"id":"1.195395433","rc":[{"atb":[[1.05,436.82]],"id":40835929}],"con":true,"img":false}]}
{"op":"mcm","clk":"5306866920","pt":1646108516444,"mc":[{"id":"1.195395433","rc":[{"atl":[[3.2,0]],"id":34135026}],"con":true,"img":false}]}
{"op":"mcm","clk":"5306866937","pt":1646108517161,"mc":[{"id":"1.195395433","rc":[{"atl":[[3.15,0]],"id":34135026}],"con":true,"img":false}]}
{"op":"mcm","clk":"5306866938","pt":1646108517259,"mc":[{"id":"1.195395433","rc":[{"atl":[[3.2,1.3]],"id":34135026}],"con":true,"img":false}]}
{"op":"mcm","clk":"5306866954","pt":1646108517875,"mc":[{"id":"1.195395433","rc":[{"atl":[[3.1,0]],"id":34135026}],"con":true,"img":false}]}
{"op":"mcm","clk":"5306866991","pt":1646108519360,"mc":[{"id":"1.195395433","rc":[{"atl":[[1000,1.66]],"id":34135026}],"con":true,"img":false}]}
{"op":"mcm","clk":"5306866995","pt":1646108519563,"mc":[{"id":"1.195395433","rc":[{"atl":[[4,35]],"id":40835929},{"trd":[[4,50]],"ltp":4.0,"tv":50.0,"id":40835929},{"atl":[[1000,0.35]],"id":34135026}],"con":true,"img":false}]}
{"op":"mcm","clk":"5306866999","pt":1646108519768,"mc":[{"id":"1.195395433","rc":[{"atl":[[1000,0]],"id":34135026}],"con":true,"img":false}]}
{"op":"mcm","clk":"5306867002","pt":1646108519869,"mc":[{"id":"1.195395433","rc":[{"atl":[[3.15,0.35]],"id":34135026}],"con":true,"img":false}]}
{"op":"mcm","clk":"5306867068","pt":1646108522275,"mc":[{"id":"1.195395433","rc":[{"spl":[[1.01,5.67]],"id":41286501}],"con":true,"img":false}]}
{"op":"mcm","clk":"5306867071","pt":1646108522379,"mc":[{"id":"1.195395433","rc":[{"spl":[[1.01,16.98]],"id":32825135},{"spl":[[1.01,230.33]],"id":40835929},{"atl":[[1000,25.15]],"id":40835929}],"con":true,"img":false}]}
{"op":"mcm","clk":"5306867153","pt":1646108524885,"mc":[{"id":"1.195395433","rc":[{"atb":[[3.9,27.14]],"id":28774786}],"con":true,"img":false}]}
{"op":"mcm","clk":"5306867181","pt":1646108526166,"mc":[{"id":"1.195395433","rc":[{"atb":[[5.8,13.32]],"id":32825135}],"con":true,"img":false}]}
