{"op":"mcm","clk":"5351767846","pt":1646175389004,"mc":[{"id":"1.195453762","marketDefinition":{"bspMarket":true,"turnInPlayEnabled":false,"persistenceEnabled":false,"marketBaseRate":7.0,"eventId":"31272499","eventTypeId":"4339","numberOfWinners":1,"bettingType":"ODDS","marketType":"WIN","marketTime":"2022-03-02T08:34:00.000Z","suspendTime":"2022-03-02T08:34:00.000Z","bspReconciled":false,"complete":true,"inPlay":false,"crossMatching":false,"runnersVoidable":false,"numberOfActiveRunners":8,"betDelay":0,"status":"OPEN","runners":[{"status":"ACTIVE","sortPriority":1,"id":41017865,"name":"1. Supreme Orson"},{"status":"ACTIVE","sortPriority":2,"id":43167124,"name":"2. Goody Goody Yum"},{"status":"ACTIVE","sortPriority":3,"id":43167125,"name":"3. Lovely Result"},{"status":"ACTIVE","sortPriority":4,"id":43167126,"name":"4. Zipping Fern"},{"status":"ACTIVE","sortPriority":5,"id":43167127,"name":"5. Zipping Raven"},{"status":"ACTIVE","sortPriority":6,"id":43167128,"name":"6. Anges Girl"},{"status":"ACTIVE","sortPriority":7,"id":42688789,"name":"7. Pressure"},{"status":"ACTIVE","sortPriority":8,"id":37178159,"name":"8. Haim"}],"regulators":["MR_INT"],"venue":"Rockhampton","countryCode":"AU","discountAllowed":true,"timezone":"Australia/Queensland","openDate":"2022-03-02T08:34:00.000Z","version":4382437829,"name":"R1 407m Mdn","eventName":"Rockhampton (AUS) 2nd Mar"},"rc":[],"con":true,"img":false}]}
{"op":"mcm","clk":"5351829775","pt":1646176640937,"mc":[{"id":"1.195453762","rc":[{"atb":[[32,3.31],[42,2.5],[21,5.13],[26,4.1]],"id":37178159},{"atl":[[300,0.44],[350,0.38],[400,0.5],[450,0.44]],"id":37178159},{"spn":171.0,"spf":"NaN","id":37178159},{"atb":[[16.5,6.63],[19,5.71],[23,4.67],[14,7.9]],"id":41017865},{"atl":[[260,0.77],[310,0.64],[160,0.83],[210,0.63]],"id":41017865},{"spn":91.5,"spf":"NaN","id":41017865},{"atb":[[4,34.25],[4.5,29.35],[5,25.68],[5.5,22.83]],"id":43167126},{"atl":[[17,8.31],[19.5,7.19],[24,8.67],[29,7.12]],"id":43167126},{"spn":11.25,"spf":"NaN","id":43167126},{"atb":[[4,34.25],[4.5,29.35],[5,25.68],[5.5,22.83]],"id":43167127},{"atl":[[17,8.31],[19.5,7.19],[24,8.67],[29,7.12]],"id":43167127},{"spn":11.25,"spf":"NaN","id":43167127},{"atb":[[9.2,12.53],[10.5,10.81],[8.2,14.27],[13,8.56]],"id":43167128},{"atl":[[80,1.68],[160,1.25],[210,0.95],[110,1.21]],"id":43167128},{"spn":46.5,"spf":"NaN","id":43167128},{"atb":[[12,9.34],[9.8,11.67],[8.8,13.17],[7.8,15.11]],"id":42688789},{"atl":[[70,1.92],[140,1.43],[95,1.41],[190,1.05]],"id":42688789},{"spn":41.0,"spf":"NaN","id":42688789},{"atb":[[1.8,128.43],[1.85,120.88],[1.9,114.16],[1.75,137]],"id":43167124},{"atl":[[4,44.34],[4.5,57.01],[5,49.89],[3.75,48.37]],"id":43167124},{"spn":2.82,"spf":"NaN","id":43167124},{"atb":[[2.9,54.07],[3,51.37],[3.25,45.66],[3.5,41.09]],"id":43167125},{"atl":[[11,19.95],[13.5,15.96],[8.4,17.98],[9.4,15.84]],"id":43167125},{"spn":5.95,"spf":"NaN","id":43167125}],"con":true,"img":false}]}
{"op":"mcm","clk":"5351831286","pt":1646176677769,"mc":[{"id":"1.195453762","rc":[{"atb":[[32,0],[42,0],[21,0],[26,0]],"id":37178159},{"atl":[[300,0],[350,0],[400,0],[450,0]],"id":37178159},{"atb":[[16.5,0],[19,0],[23,0],[14,0]],"id":41017865},{"atl":[[260,0],[310,0],[160,0],[210,0]],"id":41017865},{"atb":[[4,0],[4.5,0],[5,0],[5.5,0]],"id":43167126},{"atl":[[17,0],[19.5,0],[24,0],[29,0]],"id":43167126},{"atb":[[4,0],[4.5,0],[5,0],[5.5,0]],"id":43167127},{"atl":[[17,0],[19.5,0],[24,0],[29,0]],"id":43167127},{"atb":[[9.2,0],[10.5,0],[8.2,0],[13,0]],"id":43167128},{"atl":[[80,0],[160,0],[210,0],[110,0]],"id":43167128},{"atb":[[12,0],[9.8,0],[8.8,0],[7.8,0]],"id":42688789},{"atl":[[70,0],[140,0],[95,0],[190,0]],"id":42688789},{"atb":[[1.8,0],[1.85,0],[1.9,0],[1.75,0]],"id":43167124},{"atl":[[4,0],[4.5,0],[5,0],[3.75,0]],"id":43167124},{"atb":[[2.9,0],[3,0],[3.25,0],[3.5,0]],"id":43167125},{"atl":[[11,0],[13.5,0],[8.4,0],[9.4,0]],"id":43167125}],"con":true,"img":false}]}
{"op":"mcm","clk":"5351832829","pt":1646176717820,"mc":[{"id":"1.195453762","rc":[{"atb":[[32,3.31],[42,2.5],[21,5.13],[26,4.1]],"id":37178159},{"atl":[[300,0.44],[350,0.38],[400,0.5],[450,0.44]],"id":37178159},{"atb":[[16.5,6.63],[19,5.71],[23,4.67],[14,7.9]],"id":41017865},{"atl":[[260,0.77],[310,0.64],[160,0.83],[210,0.63]],"id":41017865},{"atb":[[4,34.25],[4.5,29.35],[5,25.68],[5.5,22.83]],"id":43167126},{"atl":[[17,8.31],[19.5,7.19],[24,8.67],[29,7.12]],"id":43167126},{"atb":[[4,34.25],[4.5,29.35],[5,25.68],[5.5,22.83]],"id":43167127},{"atl":[[17,8.31],[19.5,7.19],[24,8.67],[29,7.12]],"id":43167127},{"atb":[[9.2,12.53],[10.5,10.81],[8.2,14.27],[13,8.56]],"id":43167128},{"atl":[[80,1.68],[160,1.25],[210,0.95],[110,1.21]],"id":43167128},{"atb":[[12,9.34],[9.8,11.67],[8.8,13.17],[7.8,15.11]],"id":42688789},{"atl":[[70,1.92],[140,1.43],[95,1.41],[190,1.05]],"id":42688789},{"atb":[[1.8,128.43],[1.85,120.88],[1.9,114.16],[1.75,137]],"id":43167124},{"atl":[[4,44.34],[4.5,57.01],[5,49.89],[3.75,48.37]],"id":43167124},{"atb":[[2.9,54.07],[3,51.37],[3.25,45.66],[3.5,41.09]],"id":43167125},{"atl":[[11,19.95],[13.5,15.96],[8.4,17.98],[9.4,15.84]],"id":43167125}],"con":true,"img":false}]}
{"op":"mcm","clk":"5351834978","pt":1646176767411,"mc":[{"id":"1.195453762","rc":[{"atb":[[32,0],[42,0],[21,0],[26,0]],"id":37178159},{"atl":[[300,0],[350,0],[400,0],[450,0]],"id":37178159},{"atb":[[16.5,0],[19,0],[23,0],[14,0]],"id":41017865},{"atl":[[260,0],[310,0],[160,0],[210,0]],"id":41017865},{"atb":[[4,0],[4.5,0],[5,0],[5.5,0]],"id":43167126},{"atl":[[17,0],[19.5,0],[24,0],[29,0]],"id":43167126},{"atb":[[4,0],[4.5,0],[5,0],[5.5,0]],"id":43167127},{"atl":[[17,0],[19.5,0],[24,0],[29,0]],"id":43167127},{"atb":[[9.2,0],[10.5,0],[8.2,0],[13,0]],"id":43167128},{"atl":[[80,0],[160,0],[210,0],[110,0]],"id":43167128},{"atb":[[12,0],[9.8,0],[8.8,0],[7.8,0]],"id":42688789},{"atl":[[70,0],[140,0],[95,0],[190,0]],"id":42688789},{"atb":[[1.8,0],[1.85,0],[1.9,0],[1.75,0]],"id":43167124},{"atl":[[4,0],[4.5,0],[5,0],[3.75,0]],"id":43167124},{"atb":[[2.9,0],[3,0],[3.25,0],[3.5,0]],"id":43167125},{"atl":[[11,0],[13.5,0],[8.4,0],[9.4,0]],"id":43167125}],"con":true,"img":false}]}
{"op":"mcm","clk":"5351835816","pt":1646176785835,"mc":[{"id":"1.195453762","rc":[{"atb":[[32,3.31],[42,2.5],[26,4.1],[55,1.9]],"id":37178159},{"atl":[[350,0.38],[400,0.33],[450,0.44],[500,0.39]],"id":37178159},{"spn":202.5,"spf":"NaN","id":37178159},{"atb":[[16.5,6.63],[19,5.71],[23,4.67],[14,7.9]],"id":41017865},{"atl":[[260,0.77],[310,0.64],[160,0.83],[210,0.63]],"id":41017865},{"atb":[[4,34.25],[4.5,29.35],[5,25.68],[5.5,22.83]],"id":43167126},{"atl":[[17,8.31],[19.5,7.19],[24,8.67],[29,7.12]],"id":43167126},{"atb":[[4,34.25],[4.5,29.35],[5,25.68],[5.5,22.83]],"id":43167127},{"atl":[[17,8.31],[19.5,7.19],[24,8.67],[29,7.12]],"id":43167127},{"atb":[[9.6,11.94],[8.6,13.52],[11.5,9.78],[14,7.9]],"id":43167128},{"atl":[[130,1.02],[90,1.49],[180,1.11],[230,0.87]],"id":43167128},{"spn":52.0,"spf":"NaN","id":43167128},{"atb":[[9.2,12.53],[10.5,10.81],[8.2,14.27],[13,8.56]],"id":42688789},{"atl":[[80,1.68],[160,1.25],[210,0.95],[110,1.21]],"id":42688789},{"spn":46.5,"spf":"NaN","id":42688789},{"atb":[[2,102.74],[1.85,120.88],[1.9,114.16],[1.95,108.15]],"id":43167124},{"atl":[[5.6,43.38],[5.1,32.44],[4.6,36.95],[6.2,38.37]],"id":43167124},{"spn":3.3,"spf":"NaN","id":43167124},{"atb":[[2.9,54.07],[3,51.37],[3.25,45.66],[3.5,41.09]],"id":43167125},{"atl":[[11,19.95],[13.5,15.96],[8.4,17.98],[9.4,15.84]],"id":43167125}],"con":true,"img":false}]}
{"op":"mcm","clk":"5351867339","pt":1646177513679,"mc":[{"id":"1.195453762","rc":[{"atb":[[9.6,0],[8.6,0],[11.5,0],[14,0]],"id":43167128},{"atl":[[130,0],[90,0],[180,0],[230,0]],"id":43167128},{"spn":"NaN","spf":"NaN","id":43167128},{"atb":[[2.9,0],[3,0],[3.25,0],[3.5,0]],"id":43167125},{"atl":[[11,0],[13.5,0],[8.4,0],[9.4,0]],"id":43167125},{"spn":"NaN","spf":"NaN","id":43167125}],"con":true,"img":false}]}
{"op":"mcm","clk":"5351867764","pt":1646177524687,"mc":[{"id":"1.195453762","rc":[{"atb":[[9.2,12.53],[10.5,10.81],[8.2,14.27],[13,8.56]],"id":43167128},{"atl":[[80,1.68],[160,1.25],[210,0.95],[110,1.21]],"id":43167128},{"atb":[[3.6,39.52],[3.1,48.92],[3.35,43.72],[2.94,52.96]],"id":43167125},{"atl":[[12,18.14],[9.8,15.11],[8.8,17.05],[14.5,14.78]],"id":43167125}],"con":true,"img":false}]}
{"op":"mcm","clk":"5352004162","pt":1646180202639,"mc":[{"id":"1.195453762","marketDefinition":{"bspMarket":true,"turnInPlayEnabled":false,"persistenceEnabled":false,"marketBaseRate":7.0,"eventId":"31272499","eventTypeId":"4339","numberOfWinners":1,"bettingType":"ODDS","marketType":"WIN","marketTime":"2022-03-02T08:34:00.000Z","suspendTime":"2022-03-02T08:34:00.000Z","bspReconciled":false,"complete":true,"inPlay":false,"crossMatching":false,"runnersVoidable":false,"numberOfActiveRunners":8,"betDelay":0,"status":"OPEN","runners":[{"status":"ACTIVE","sortPriority":1,"id":41017865,"name":"1. Supreme Orson"},{"status":"ACTIVE","sortPriority":2,"id":43167124,"name":"2. Goody Goody Yum"},{"status":"ACTIVE","sortPriority":3,"id":43167125,"name":"3. Lovely Result"},{"status":"ACTIVE","sortPriority":4,"id":43167126,"name":"4. Zipping Fern"},{"status":"ACTIVE","sortPriority":5,"id":43167127,"name":"5. Zipping Raven"},{"status":"ACTIVE","sortPriority":6,"id":43167128,"name":"6. Anges Girl"},{"status":"ACTIVE","sortPriority":7,"id":42688789,"name":"7. Pressure"},{"status":"ACTIVE","sortPriority":8,"id":37178159,"name":"8. Haim"}],"regulators":["MR_INT"],"venue":"Rockhampton","countryCode":"AU","discountAllowed":true,"timezone":"Australia/Queensland","openDate":"2022-03-02T08:34:00.000Z","version":4382437829,"name":"R1 407m Mdn","eventName":"Rockhampton (AUS) 2nd Mar"},"rc":[{"atb":[[32,3.31],[42,2.5],[26,4.11],[55,1.9]],"id":37178159},{"atl":[[350,0.38],[400,0.33],[450,0.44],[500,0.39]],"id":37178159},{"spn":202.5,"spf":"NaN","id":37178159},{"atb":[[16.5,6.63],[19,5.71],[23,4.67],[14,7.9]],"id":41017865},{"atl":[[260,0.77],[310,0.64],[160,0.83],[210,0.63]],"id":41017865},{"spn":91.5,"spf":"NaN","id":41017865},{"atb":[[4,34.25],[4.5,29.36],[5,25.69],[5.5,22.83]],"id":43167126},{"atl":[[17,8.31],[19.5,7.19],[24,8.67],[29,7.12]],"id":43167126},{"spn":11.25,"spf":"NaN","id":43167126},{"atb":[[4,34.25],[4.5,29.36],[5,25.69],[5.5,22.83]],"id":43167127},{"atl":[[17,8.31],[19.5,7.19],[24,8.67],[29,7.12]],"id":43167127},{"spn":11.25,"spf":"NaN","id":43167127},{"atb":[[9.2,12.53],[10.5,10.81],[8.2,14.27],[13,8.56]],"id":43167128},{"atl":[[80,1.68],[160,1.25],[210,0.95],[110,1.21]],"id":43167128},{"spn":46.5,"spf":"NaN","id":43167128},{"atb":[[9.2,12.53],[10.5,10.81],[8.2,14.27],[13,8.56]],"id":42688789},{"atl":[[80,1.68],[160,1.25],[210,0.95],[110,1.21]],"id":42688789},{"spn":46.5,"spf":"NaN","id":42688789},{"atb":[[2,102.76],[1.85,120.89],[1.9,114.17],[1.95,108.16]],"id":43167124},{"atl":[[5.6,43.39],[5.1,32.45],[4.6,36.96],[6.2,38.38]],"id":43167124},{"spn":3.3,"spf":"NaN","id":43167124},{"atb":[[3.6,39.52],[3.1,48.93],[3.35,43.72],[2.94,52.96]],"id":43167125},{"atl":[[12,18.14],[9.8,15.11],[8.8,17.05],[14.5,14.78]],"id":43167125},{"spn":6.2,"spf":"NaN","id":43167125}],"con":true,"img":true}]}
{"op":"mcm","clk":"5352146195","pt":1646183572653,"mc":[{"id":"1.195453762","marketDefinition":{"bspMarket":true,"turnInPlayEnabled":false,"persistenceEnabled":false,"marketBaseRate":7.0,"eventId":"31272499","eventTypeId":"4339","numberOfWinners":1,"bettingType":"ODDS","marketType":"WIN","marketTime":"2022-03-02T08:34:00.000Z","suspendTime":"2022-03-02T08:34:00.000Z","bspReconciled":false,"complete":true,"inPlay":false,"crossMatching":false,"runnersVoidable":false,"numberOfActiveRunners":8,"betDelay":0,"status":"OPEN","runners":[{"status":"ACTIVE","sortPriority":1,"id":41017865,"name":"1. Supreme Orson"},{"status":"ACTIVE","sortPriority":2,"id":43167124,"name":"2. Goody Goody Yum"},{"status":"ACTIVE","sortPriority":3,"id":43167125,"name":"3. Lovely Result"},{"status":"ACTIVE","sortPriority":4,"id":43167126,"name":"4. Zipping Fern"},{"status":"ACTIVE","sortPriority":5,"id":43167127,"name":"5. Zipping Raven"},{"status":"ACTIVE","sortPriority":6,"id":43167128,"name":"6. Anges Girl"},{"status":"ACTIVE","sortPriority":7,"id":42688789,"name":"7. Pressure"},{"status":"ACTIVE","sortPriority":8,"id":37178159,"name":"8. Haim"}],"regulators":["MR_INT"],"venue":"Rockhampton","countryCode":"AU","discountAllowed":true,"timezone":"Australia/Queensland","openDate":"2022-03-02T08:28:00.000Z","version":4382597816,"name":"R1 407m Mdn","eventName":"Rockhampton (AUS) 2nd Mar"},"rc":[],"con":true,"img":false}]}
{"op":"mcm","clk":"5352147044","pt":1646183591678,"mc":[{"id":"1.195453762","marketDefinition":{"bspMarket":true,"turnInPlayEnabled":false,"persistenceEnabled":false,"marketBaseRate":7.0,"eventId":"31272499","eventTypeId":"4339","numberOfWinners":1,"bettingType":"ODDS","marketType":"WIN","marketTime":"2022-03-02T08:28:00.000Z","suspendTime":"2022-03-02T08:28:00.000Z","bspReconciled":false,"complete":true,"inPlay":false,"crossMatching":false,"runnersVoidable":false,"numberOfActiveRunners":8,"betDelay":0,"status":"OPEN","runners":[{"status":"ACTIVE","sortPriority":1,"id":41017865,"name":"1. Supreme Orson"},{"status":"ACTIVE","sortPriority":2,"id":43167124,"name":"2. Goody Goody Yum"},{"status":"ACTIVE","sortPriority":3,"id":43167125,"name":"3. Lovely Result"},{"status":"ACTIVE","sortPriority":4,"id":43167126,"name":"4. Zipping Fern"},{"status":"ACTIVE","sortPriority":5,"id":43167127,"name":"5. Zipping Raven"},{"status":"ACTIVE","sortPriority":6,"id":43167128,"name":"6. Anges Girl"},{"status":"ACTIVE","sortPriority":7,"id":42688789,"name":"7. Pressure"},{"status":"ACTIVE","sortPriority":8,"id":37178159,"name":"8. Haim"}],"regulators":["MR_INT"],"venue":"Rockhampton","countryCode":"AU","discountAllowed":true,"timezone":"Australia/Queensland","openDate":"2022-03-02T08:28:00.000Z","version":4382598286,"name":"R1 407m Mdn","eventName":"Rockhampton (AUS) 2nd Mar"},"rc":[],"con":true,"img":false}]}
{"op":"mcm","clk":"5352238287","pt":1646185602675,"mc":[{"id":"1.195453762","marketDefinition":{"bspMarket":true,"turnInPlayEnabled":false,"persistenceEnabled":false,"marketBaseRate":7.0,"eventId":"31272499","eventTypeId":"4339","numberOfWinners":1,"bettingType":"ODDS","marketType":"WIN","marketTime":"2022-03-02T08:28:00.000Z","suspendTime":"2022-03-02T08:28:00.000Z","bspReconciled":false,"complete":true,"inPlay":false,"crossMatching":false,"runnersVoidable":false,"numberOfActiveRunners":8,"betDelay":0,"status":"OPEN","runners":[{"status":"ACTIVE","sortPriority":1,"id":41017865,"name":"1. Supreme Orson"},{"status":"ACTIVE","sortPriority":2,"id":43167124,"name":"2. Goody Goody Yum"},{"status":"ACTIVE","sortPriority":3,"id":43167125,"name":"3. Lovely Result"},{"status":"ACTIVE","sortPriority":4,"id":43167126,"name":"4. Zipping Fern"},{"status":"ACTIVE","sortPriority":5,"id":43167127,"name":"5. Zipping Raven"},{"status":"ACTIVE","sortPriority":6,"id":43167128,"name":"6. Anges Girl"},{"status":"ACTIVE","sortPriority":7,"id":42688789,"name":"7. Pressure"},{"status":"ACTIVE","sortPriority":8,"id":37178159,"name":"8. Haim"}],"regulators":["MR_INT"],"venue":"Rockhampton","countryCode":"AU","discountAllowed":true,"timezone":"Australia/Queensland","openDate":"2022-03-02T08:28:00.000Z","version":4382598286,"name":"R1 407m Mdn","eventName":"Rockhampton (AUS) 2nd Mar"},"rc":[{"atb":[[32,3.32],[42,2.5],[26,4.11],[55,1.9]],"id":37178159},{"atl":[[350,0.38],[400,0.33],[450,0.44],[500,0.39]],"id":37178159},{"spn":202.5,"spf":"NaN","id":37178159},{"atb":[[16.5,6.64],[19,5.72],[23,4.67],[14,7.91]],"id":41017865},{"atl":[[260,0.77],[310,0.64],[160,0.83],[210,0.63]],"id":41017865},{"spn":91.5,"spf":"NaN","id":41017865},{"atb":[[4,34.3],[4.5,29.4],[5,25.73],[5.5,22.86]],"id":43167126},{"atl":[[17,8.33],[19.5,7.2],[24,8.69],[29,7.13]],"id":43167126},{"spn":11.25,"spf":"NaN","id":43167126},{"atb":[[4,34.3],[4.5,29.4],[5,25.73],[5.5,22.86]],"id":43167127},{"atl":[[17,8.33],[19.5,7.2],[24,8.69],[29,7.13]],"id":43167127},{"spn":11.25,"spf":"NaN","id":43167127},{"atb":[[9.2,12.55],[10.5,10.83],[8.2,14.29],[13,8.57]],"id":43167128},{"atl":[[80,1.68],[160,1.25],[210,0.95],[110,1.22]],"id":43167128},{"spn":46.5,"spf":"NaN","id":43167128},{"atb":[[9.2,12.55],[10.5,10.83],[8.2,14.29],[13,8.57]],"id":42688789},{"atl":[[80,1.68],[160,1.25],[210,0.95],[110,1.22]],"id":42688789},{"spn":46.5,"spf":"NaN","id":42688789},{"atb":[[2,102.92],[1.85,121.08],[1.9,114.35],[1.95,108.33]],"id":43167124},{"atl":[[5.6,43.45],[5.1,32.5],[4.6,37.01],[6.2,38.44]],"id":43167124},{"spn":3.3,"spf":"NaN","id":43167124},{"atb":[[3.6,39.58],[3.1,49.01],[3.35,43.79],[2.94,53.05]],"id":43167125},{"atl":[[12,18.17],[9.8,15.14],[8.8,17.08],[14.5,14.8]],"id":43167125},{"spn":6.2,"spf":"NaN","id":43167125}],"con":true,"img":true}]}
{"op":"mcm","clk":"5352465584","pt":1646191002625,"mc":[{"id":"1.195453762","marketDefinition":{"bspMarket":true,"turnInPlayEnabled":false,"persistenceEnabled":false,"marketBaseRate":7.0,"eventId":"31272499","eventTypeId":"4339","numberOfWinners":1,"bettingType":"ODDS","marketType":"WIN","marketTime":"2022-03-02T08:28:00.000Z","suspendTime":"2022-03-02T08:28:00.000Z","bspReconciled":false,"complete":true,"inPlay":false,"crossMatching":false,"runnersVoidable":false,"numberOfActiveRunners":8,"betDelay":0,"status":"OPEN","runners":[{"status":"ACTIVE","sortPriority":1,"id":41017865,"name":"1. Supreme Orson"},{"status":"ACTIVE","sortPriority":2,"id":43167124,"name":"2. Goody Goody Yum"},{"status":"ACTIVE","sortPriority":3,"id":43167125,"name":"3. Lovely Result"},{"status":"ACTIVE","sortPriority":4,"id":43167126,"name":"4. Zipping Fern"},{"status":"ACTIVE","sortPriority":5,"id":43167127,"name":"5. Zipping Raven"},{"status":"ACTIVE","sortPriority":6,"id":43167128,"name":"6. Anges Girl"},{"status":"ACTIVE","sortPriority":7,"id":42688789,"name":"7. Pressure"},{"status":"ACTIVE","sortPriority":8,"id":37178159,"name":"8. Haim"}],"regulators":["MR_INT"],"venue":"Rockhampton","countryCode":"AU","discountAllowed":true,"timezone":"Australia/Queensland","openDate":"2022-03-02T08:28:00.000Z","version":4382598286,"name":"R1 407m Mdn","eventName":"Rockhampton (AUS) 2nd Mar"},"rc":[{"atb":[[32,3.32],[42,2.51],[26,4.12],[55,1.91]],"id":37178159},{"atl":[[350,0.38],[400,0.33],[450,0.44],[500,0.39]],"id":37178159},{"spn":202.5,"spf":"NaN","id":37178159},{"atb":[[16.5,6.65],[19,5.72],[23,4.68],[14,7.93]],"id":41017865},{"atl":[[260,0.77],[310,0.64],[160,0.84],[210,0.63]],"id":41017865},{"spn":91.5,"spf":"NaN","id":41017865},{"atb":[[4,34.36],[4.5,29.45],[5,25.77],[5.5,22.9]],"id":43167126},{"atl":[[17,8.34],[19.5,7.21],[24,8.7],[29,7.14]],"id":43167126},{"spn":11.25,"spf":"NaN","id":43167126},{"atb":[[4,34.36],[4.5,29.45],[5,25.77],[5.5,22.9]],"id":43167127},{"atl":[[17,8.34],[19.5,7.21],[24,8.7],[29,7.14]],"id":43167127},{"spn":11.25,"spf":"NaN","id":43167127},{"atb":[[9.2,12.57],[10.5,10.85],[8.2,14.32],[13,8.59]],"id":43167128},{"atl":[[80,1.68],[160,1.26],[210,0.95],[110,1.22]],"id":43167128},{"spn":46.5,"spf":"NaN","id":43167128},{"atb":[[9.2,12.57],[10.5,10.85],[8.2,14.32],[13,8.59]],"id":42688789},{"atl":[[80,1.68],[160,1.26],[210,0.95],[110,1.22]],"id":42688789},{"spn":46.5,"spf":"NaN","id":42688789},{"atb":[[2,103.09],[1.85,121.29],[1.9,114.55],[1.95,108.52]],"id":43167124},{"atl":[[5.6,43.53],[5.1,32.55],[4.6,37.08],[6.2,38.5]],"id":43167124},{"spn":3.3,"spf":"NaN","id":43167124},{"atb":[[3.6,39.65],[3.1,49.09],[3.35,43.87],[2.94,53.14]],"id":43167125},{"atl":[[12,18.2],[9.8,15.16],[8.8,17.11],[14.5,14.83]],"id":43167125},{"spn":6.2,"spf":"NaN","id":43167125}],"con":true,"img":true}]}
{"op":"mcm","clk":"5352688133","pt":1646197055664,"mc":[{"id":"1.195453762","rc":[{"atb":[[32,3.32],[42,2.51],[26,4.12],[55,1.91]],"id":37178159},{"atl":[[350,0.38],[400,0.33],[450,0.44],[500,0.39]],"id":37178159},{"atb":[[16.5,6.65],[19,5.72],[23,4.68],[14,7.93]],"id":41017865},{"atl":[[260,0.77],[310,0.64],[160,0.84],[210,0.63]],"id":41017865},{"atb":[[4,34.36],[4.5,29.45],[5,25.77],[5.5,22.9]],"id":43167126},{"atl":[[17,8.34],[19.5,7.21],[24,8.7],[29,7.14]],"id":43167126},{"atb":[[4,34.36],[4.5,29.45],[5,25.77],[5.5,22.9]],"id":43167127},{"atl":[[17,8.34],[19.5,7.21],[24,8.7],[29,7.14]],"id":43167127},{"atb":[[9.2,12.57],[10.5,10.85],[8.2,14.32],[13,8.59]],"id":43167128},{"atl":[[80,1.68],[160,1.26],[210,0.95],[110,1.22]],"id":43167128},{"spn":46.5,"spf":"NaN","id":43167128},{"atb":[[9.2,12.57],[10.5,10.85],[8.2,14.32],[13,8.59]],"id":42688789},{"atl":[[80,1.68],[160,1.26],[210,0.95],[110,1.22]],"id":42688789},{"atb":[[2,103.09],[1.85,121.29],[1.9,114.55],[1.95,108.52]],"id":43167124},{"atl":[[5.6,43.53],[5.1,32.55],[4.6,37.08],[6.2,38.5],[2.7,6.19]],"id":43167124},{"spn":2.35,"spf":"NaN","id":43167124},{"atb":[[3.6,39.65],[3.1,49.09],[3.35,43.87],[2.94,53.14]],"id":43167125},{"atl":[[12,18.2],[9.8,15.16],[8.8,17.11],[14.5,14.83]],"id":43167125},{"spn":6.2,"spf":"NaN","id":43167125}],"con":true,"img":false}]}
{"op":"mcm","clk":"5352795307","pt":1646200887024,"mc":[{"id":"1.195453762","rc":[{"atb":[[32,3.32],[42,2.51],[26,4.12],[55,1.91]],"id":37178159},{"atl":[[350,0.38],[400,0.33],[450,0.44],[500,0.39]],"id":37178159},{"atb":[[16.5,6.65],[19,5.72],[23,4.68],[14,7.92]],"id":41017865},{"atl":[[260,0.77],[310,0.64],[160,0.84],[210,0.63]],"id":41017865},{"atb":[[4,34.35],[4.5,29.44],[1.01,2.25],[5,25.76],[5.5,22.89]],"id":43167126},{"atl":[[17,8.34],[19.5,7.21],[24,8.7],[29,7.14]],"id":43167126},{"atb":[[4,34.35],[4.5,29.44],[1.01,2.25],[5,25.76],[5.5,22.89]],"id":43167127},{"atl":[[17,8.34],[19.5,7.21],[24,8.7],[29,7.14]],"id":43167127},{"atb":[[9.2,12.56],[10.5,10.84],[8.2,14.31],[13,8.58]],"id":43167128},{"atl":[[80,1.68],[160,1.26],[210,0.95],[110,1.22]],"id":43167128},{"atb":[[9.2,12.56],[10.5,10.84],[8.2,14.31],[13,8.58]],"id":42688789},{"atl":[[80,1.68],[160,1.26],[210,0.95],[110,1.22]],"id":42688789},{"atb":[[2,103.05],[1.85,121.24],[2.04,7.94],[1.9,114.5],[1.95,108.47]],"id":43167124},{"atl":[[5.6,43.51],[5.1,32.54],[4.6,37.06],[6.2,38.49],[2.7,6.2]],"id":43167124},{"spn":2.37,"spf":"NaN","id":43167124},{"atb":[[3.6,39.63],[3.1,49.07],[3.35,43.85],[2.94,53.12],[3.65,3.11]],"id":43167125},{"atl":[[12,18.19],[9.8,15.16],[8.8,17.1],[14.5,14.82]],"id":43167125},{"spn":6.22,"spf":"NaN","id":43167125}],"con":true,"img":false}]}
{"op":"mcm","clk":"5352795311","pt":1646200887227,"mc":[{"id":"1.195453762","rc":[{"atb":[[1.01,1.79]],"id":43167126},{"atb":[[1.01,1.79]],"id":43167127}],"con":true,"img":false}]}
{"op":"mcm","clk":"5352795345","pt":1646200889024,"mc":[{"id":"1.195453762","rc":[{"atb":[[1.01,0]],"id":43167127}],"con":true,"img":false}]}
{"op":"mcm","clk":"5352795347","pt":1646200889126,"mc":[{"id":"1.195453762","rc":[{"atb":[[5.6,1.79]],"id":43167127}],"con":true,"img":false}]}
{"op":"mcm","clk":"5352795357","pt":1646200889330,"mc":[{"id":"1.195453762","rc":[{"atb":[[1.01,0]],"id":43167126}],"con":true,"img":false}]}
{"op":"mcm","clk":"5352795360","pt":1646200889433,"mc":[{"id":"1.195453762","rc":[{"atb":[[5.6,1.79]],"id":43167126}],"con":true,"img":false}]}
{"op":"mcm","clk":"5352796912","pt":1646200962141,"mc":[{"id":"1.195453762","rc":[{"spn":11.3,"spf":"NaN","id":43167126},{"spn":11.3,"spf":"NaN","id":43167127},{"atb":[[3.65,6.92]],"id":43167125}],"con":true,"img":false}]}
{"op":"mcm","clk":"5352796927","pt":1646200962656,"mc":[{"id":"1.195453762","rc":[{"atb":[[5.6,3.99]],"id":43167127}],"con":true,"img":false}]}
{"op":"mcm","clk":"5352796944","pt":1646200963014,"mc":[{"id":"1.195453762","rc":[{"atb":[[2.04,17.67]],"id":43167124}],"con":true,"img":false}]}
{"op":"mcm","clk":"5352796960","pt":1646200963425,"mc":[{"id":"1.195453762","rc":[{"atb":[[5.6,3.99]],"id":43167126}],"con":true,"img":false}]}
{"op":"mcm","clk":"5352797307","pt":1646200979417,"mc":[{"id":"1.195453762","marketDefinition":{"bspMarket":true,"turnInPlayEnabled":false,"persistenceEnabled":false,"marketBaseRate":7.0,"eventId":"31272499","eventTypeId":"4339","numberOfWinners":1,"bettingType":"ODDS","marketType":"WIN","marketTime":"2022-03-02T08:28:00.000Z","suspendTime":"2022-03-02T08:28:00.000Z","bspReconciled":false,"complete":true,"inPlay":false,"crossMatching":true,"runnersVoidable":false,"numberOfActiveRunners":8,"betDelay":0,"status":"OPEN","runners":[{"status":"ACTIVE","sortPriority":1,"id":41017865,"name":"1. Supreme Orson"},{"status":"ACTIVE","sortPriority":2,"id":43167124,"name":"2. Goody Goody Yum"},{"status":"ACTIVE","sortPriority":3,"id":43167125,"name":"3. Lovely Result"},{"status":"ACTIVE","sortPriority":4,"id":43167126,"name":"4. Zipping Fern"},{"status":"ACTIVE","sortPriority":5,"id":43167127,"name":"5. Zipping Raven"},{"status":"ACTIVE","sortPriority":6,"id":43167128,"name":"6. Anges Girl"},{"status":"ACTIVE","sortPriority":7,"id":42688789,"name":"7. Pressure"},{"status":"ACTIVE","sortPriority":8,"id":37178159,"name":"8. Haim"}],"regulators":["MR_INT"],"venue":"Rockhampton","countryCode":"AU","discountAllowed":true,"timezone":"Australia/Queensland","openDate":"2022-03-02T08:28:00.000Z","version":4382598286,"name":"R1 407m Mdn","eventName":"Rockhampton (AUS) 2nd Mar"},"rc":[],"con":true,"img":false}]}
{"op":"mcm","clk":"5352844651","pt":1646202480168,"mc":[{"id":"1.195453762","rc":[{"atb":[[55,2.11]],"id":37178159},{"atb":[[21,0.51]],"id":41017865},{"atb":[[5.3,2]],"id":43167126},{"atb":[[5.3,2]],"id":43167127},{"atb":[[13.5,0.81]],"id":43167128},{"spn":46.75,"spf":"NaN","id":43167128},{"atb":[[13.5,0.81]],"id":42688789},{"spn":46.75,"spf":"NaN","id":42688789},{"atb":[[1.91,2]],"id":43167124},{"atb":[[3.55,2]],"id":43167125}],"con":true,"img":false}]}
{"op":"mcm","clk":"5352869663","pt":1646203260274,"mc":[{"id":"1.195453762","rc":[{"atb":[[5.6,0.99]],"id":43167126},{"trd":[[5.6,5.99]],"ltp":5.6,"tv":5.99,"id":43167126}],"con":true,"img":false}]}
{"op":"mcm","clk":"5352869698","pt":1646203261353,"mc":[{"id":"1.195453762","rc":[{"atl":[[1000,2.25]],"id":43167126}],"con":true,"img":false}]}
{"op":"mcm","clk":"5352869711","pt":1646203261557,"mc":[{"id":"1.195453762","rc":[{"atl":[[1000,1.47]],"id":43167126}],"con":true,"img":false}]}
{"op":"mcm","clk":"5352869727","pt":1646203262074,"mc":[{"id":"1.195453762","rc":[{"atl":[[1000,0]],"id":43167126}],"con":true,"img":false}]}
{"op":"mcm","clk":"5352869729","pt":1646203262172,"mc":[{"id":"1.195453762","rc":[{"atl":[[6.8,1.47]],"id":43167126}],"con":true,"img":false}]}
{"op":"mcm","clk":"5352869883","pt":1646203266480,"mc":[{"id":"1.195453762","rc":[{"atb":[[5.6,0.99]],"id":43167127},{"trd":[[5.6,5.99]],"ltp":5.6,"tv":5.99,"id":43167127}],"con":true,"img":false}]}
{"op":"mcm","clk":"5352869910","pt":1646203267355,"mc":[{"id":"1.195453762","rc":[{"atl":[[1000,2.25]],"id":43167127}],"con":true,"img":false}]}
{"op":"mcm","clk":"5352869914","pt":1646203267459,"mc":[{"id":"1.195453762","rc":[{"atl":[[1000,1.47]],"id":43167127}],"con":true,"img":false}]}
{"op":"mcm","clk":"5352869923","pt":1646203267665,"mc":[{"id":"1.195453762","rc":[{"atl":[[1000,0]],"id":43167127}],"con":true,"img":false}]}
{"op":"mcm","clk":"5352869932","pt":1646203267767,"mc":[{"id":"1.195453762","rc":[{"atl":[[6.8,1.47]],"id":43167127}],"con":true,"img":false}]}
{"op":"mcm","clk":"5352873713","pt":1646203375742,"mc":[{"id":"1.195453762","rc":[{"atl":[[6.8,0]],"id":43167126},{"spn":6.2,"spf":"NaN","id":43167127}],"con":true,"img":false}]}
{"op":"mcm","clk":"5352873724","pt":1646203376000,"mc":[{"id":"1.195453762","rc":[{"atl":[[1000,2.25]],"id":43167126}],"con":true,"img":false}]}
{"op":"mcm","clk":"5352873734","pt":1646203376205,"mc":[{"id":"1.195453762","rc":[{"atl":[[1000,0.55]],"id":43167126}],"con":true,"img":false}]}
{"op":"mcm","clk":"5352873740","pt":1646203376308,"mc":[{"id":"1.195453762","rc":[{"atl":[[1000,0]],"id":43167126}],"con":true,"img":false}]}
{"op":"mcm","clk":"5352873744","pt":1646203376410,"mc":[{"id":"1.195453762","rc":[{"atl":[[18,0.55]],"id":43167126}],"con":true,"img":false}]}
{"op":"mcm","clk":"5352873818","pt":1646203378714,"mc":[{"id":"1.195453762","rc":[{"atl":[[18,0]],"id":43167126}],"con":true,"img":false}]}
{"op":"mcm","clk":"5352873823","pt":1646203378816,"mc":[{"id":"1.195453762","rc":[{"atl":[[1000,2.25]],"id":43167126}],"con":true,"img":false}]}
{"op":"mcm","clk":"5352873832","pt":1646203379029,"mc":[{"id":"1.195453762","rc":[{"atl":[[1000,0.6]],"id":43167126}],"con":true,"img":false}]}
{"op":"mcm","clk":"5352873841","pt":1646203379234,"mc":[{"id":"1.195453762","rc":[{"atl":[[1000,0]],"id":43167126}],"con":true,"img":false}]}
{"op":"mcm","clk":"5352873845","pt":1646203379329,"mc":[{"id":"1.195453762","rc":[{"atl":[[16.5,0.6]],"id":43167126}],"con":true,"img":false}]}
{"op":"mcm","clk":"5352873924","pt":1646203381742,"mc":[{"id":"1.195453762","rc":[{"atl":[[6.8,0]],"id":43167127}],"con":true,"img":false}]}
{"op":"mcm","clk":"5352873934","pt":1646203382152,"mc":[{"id":"1.195453762","rc":[{"atl":[[1000,2.25]],"id":43167127}],"con":true,"img":false}]}
{"op":"mcm","clk":"5352873944","pt":1646203382407,"mc":[{"id":"1.195453762","rc":[{"atl":[[1000,0.55]],"id":43167127}],"con":true,"img":false}]}
{"op":"mcm","clk":"5352873953","pt":1646203382612,"mc":[{"id":"1.195453762","rc":[{"atl":[[1000,0]],"id":43167127}],"con":true,"img":false}]}
{"op":"mcm","clk":"5352873957","pt":1646203382714,"mc":[{"id":"1.195453762","rc":[{"atl":[[18,0.55]],"id":43167127}],"con":true,"img":false}]}
{"op":"mcm","clk":"5352874031","pt":1646203384611,"mc":[{"id":"1.195453762","rc":[{"atl":[[18,0]],"id":43167127}],"con":true,"img":false}]}
{"op":"mcm","clk":"5352874037","pt":1646203384713,"mc":[{"id":"1.195453762","rc":[{"atl":[[1000,2.25]],"id":43167127}],"con":true,"img":false}]}
{"op":"mcm","clk":"5352874048","pt":1646203384918,"mc":[{"id":"1.195453762","rc":[{"atl":[[1000,0.6]],"id":43167127}],"con":true,"img":false}]}
{"op":"mcm","clk":"5352874053","pt":1646203385124,"mc":[{"id":"1.195453762","rc":[{"atl":[[1000,0]],"id":43167127}],"con":true,"img":false}]}
{"op":"mcm","clk":"5352874057","pt":1646203385227,"mc":[{"id":"1.195453762","rc":[{"atl":[[16.5,0.6]],"id":43167127}],"con":true,"img":false}]}
{"op":"mcm","clk":"5352906297","pt":1646204324406,"mc":[{"id":"1.195453762","rc":[{"atb":[[34,3.37],[60,2.73]],"id":37178159},{"atl":[[340,2.9]],"id":37178159},{"spn":200.0,"spf":"NaN","id":37178159},{"atb":[[17,7.14],[19.5,3.16]],"id":41017865},{"atl":[[70,2.73],[100,2.73]],"id":41017865},{"spn":46.5,"spf":"NaN","id":41017865},{"atb":[[5.1,14.28],[4.6,32.91]],"id":43167126},{"atl":[[11,5.85],[15.5,7.64]],"id":43167126},{"spn":8.3,"spf":"NaN","id":43167126},{"atb":[[5.1,14.28],[4.6,32.23]],"id":43167127},{"atl":[[11.5,5.57],[15.5,7.48]],"id":43167127},{"spn":8.55,"spf":"NaN","id":43167127},{"atb":[[11,10.72],[13.5,5.49]],"id":43167128},{"atl":[[40,2.73],[55,2.73]],"id":43167128},{"spn":26.75,"spf":"NaN","id":43167128},{"atb":[[11,12.55],[13.5,5.49]],"id":42688789},{"atl":[[40,2.73],[55,2.73]],"id":42688789},{"spn":26.75,"spf":"NaN","id":42688789},{"atb":[[1.96,57.63],[1.86,148.51]],"id":43167124},{"atl":[[3.35,24.91],[4.4,36.58]],"id":43167124},{"atb":[[3.4,24.4],[3.15,58.96]],"id":43167125},{"atl":[[8.6,16.92],[6.8,10.09]],"id":43167125},{"spn":5.22,"spf":"NaN","id":43167125}],"con":true,"img":false}]}
{"op":"mcm","clk":"5352906321","pt":1646204325274,"mc":[{"id":"1.195453762","rc":[{"atl":[[16.5,0]],"id":43167126},{"atl":[[16.5,0]],"id":43167127}],"con":true,"img":false}]}
{"op":"mcm","clk":"5352906325","pt":1646204325377,"mc":[{"id":"1.195453762","rc":[{"atl":[[1000,2.25]],"id":43167126},{"atl":[[1000,2.25]],"id":43167127}],"con":true,"img":false}]}
{"op":"mcm","clk":"5352906333","pt":1646204325584,"mc":[{"id":"1.195453762","rc":[{"atl":[[1000,0.95]],"id":43167126},{"atl":[[1000,0.91]],"id":43167127}],"con":true,"img":false}]}
{"op":"mcm","clk":"5352906340","pt":1646204325793,"mc":[{"id":"1.195453762","rc":[{"atl":[[1000,0]],"id":43167127}],"con":true,"img":false}]}
{"op":"mcm","clk":"5352906344","pt":1646204325893,"mc":[{"id":"1.195453762","rc":[{"atl":[[11,0.91]],"id":43167127}],"con":true,"img":false}]}
{"op":"mcm","clk":"5352906353","pt":1646204326099,"mc":[{"id":"1.195453762","rc":[{"atl":[[1000,0]],"id":43167126}],"con":true,"img":false}]}
{"op":"mcm","clk":"5352906358","pt":1646204326200,"mc":[{"id":"1.195453762","rc":[{"atl":[[10.5,0.95]],"id":43167126}],"con":true,"img":false}]}
{"op":"mcm","clk":"5352917487","pt":1646204645026,"mc":[{"id":"1.195453762","rc":[{"atb":[[32,3.32],[16,4.8],[34,3.37],[42,2.51],[26,4.12],[55,2.11],[60,2.72]],"id":37178159},{"atl":[[340,2.9],[350,0.38],[450,0.44],[500,0.39]],"id":37178159},{"atb":[[16.5,6.64],[17,7.14],[19.5,3.16],[19,5.72],[23,4.68],[12,6.55],[7.6,12.42],[14,7.92]],"id":41017865},{"atl":[[260,0.77],[70,2.72],[310,0.64],[160,0.84],[100,2.72],[210,0.63]],"id":41017865},{"atb":[[5.6,0.99],[4,34.34],[5.1,14.27],[4.5,29.43],[5,25.75],[4.6,32.9],[5.5,22.89],[3.25,32],[2.34,61.19]],"id":43167126},{"atl":[[17,8.34],[19.5,7.21],[10.5,0.95],[11,5.85],[24,8.7],[29,7.14],[15.5,7.64]],"id":43167126},{"trd":[[5.6,6]],"ltp":5.6,"tv":6.0,"id":43167126},{"spn":8.05,"spf":"NaN","id":43167126},{"atb":[[5.6,0.99],[4,34.34],[5.1,14.27],[4.5,29.43],[5,25.75],[4.6,32.22],[5.5,22.89],[3.25,32],[2.34,61.19]],"id":43167127},{"atl":[[17,8.34],[19.5,7.21],[11,0.91],[11.5,5.57],[24,8.7],[29,7.14],[15.5,7.48]],"id":43167127},{"trd":[[5.6,6]],"ltp":5.6,"tv":6.0,"id":43167127},{"spn":8.3,"spf":"NaN","id":43167127},{"atb":[[7.2,11.61],[9.2,12.56],[10.5,10.84],[11,10.72],[8.2,14.31],[13,8.58],[13.5,5.49]],"id":43167128},{"atl":[[40,2.72],[80,1.68],[160,1.26],[210,0.95],[55,2.72],[110,1.22]],"id":43167128},{"atb":[[7.2,11.61],[9.2,12.56],[10.5,10.84],[11,12.55],[8.2,14.31],[13,8.58],[13.5,5.49],[4.7,22.16]],"id":42688789},{"atl":[[40,2.72],[80,1.68],[160,1.26],[210,0.95],[55,2.72],[110,1.22]],"id":42688789},{"atb":[[2,103.02],[1.28,292.86],[2.04,17.68],[1.85,121.21],[1.9,114.47],[1.96,57.62],[1.86,148.47],[1.95,108.44],[1.47,153.19]],"id":43167124},{"atl":[[5.6,43.5],[5.1,32.53],[4.6,37.05],[6.2,38.48],[3.35,24.91],[4.4,36.57],[2.7,6.21]],"id":43167124},{"atb":[[3.6,39.62],[1.79,103.8],[2.32,54.55],[3.1,49.06],[3.35,43.84],[3.4,24.39],[3.15,58.95],[2.94,53.1],[3.65,6.93]],"id":43167125},{"atl":[[8.6,16.92],[6.8,10.09],[12,18.19],[9.8,15.15],[8.8,17.1],[14.5,14.82]],"id":43167125}],"con":true,"img":false}]}
{"op":"mcm","clk":"5352917490","pt":1646204645125,"mc":[{"id":"1.195453762","rc":[{"atb":[[2.62,46.3],[4.2,26.56],[15,5.86]],"id":37178159},{"atb":[[2.62,46.3],[4.2,26.56]],"id":41017865},{"atb":[[2.62,46.3]],"id":43167126},{"atl":[[20,8.2],[26,14.2]],"id":43167126},{"atb":[[2.62,46.3]],"id":43167127},{"atl":[[21,8.2]],"id":43167127},{"atb":[[2.62,46.3],[4.7,22.16]],"id":43167128},{"atb":[[2.62,46.3],[4.2,26.56]],"id":42688789},{"atl":[[34,13.5],[5,8.2]],"id":43167124},{"atl":[[12.5,8.2],[15.5,14.2]],"id":43167125}],"con":true,"img":false}]}
{"op":"mcm","clk":"5352917494","pt":1646204645226,"mc":[{"id":"1.195453762","rc":[{"atl":[[28,14.2]],"id":43167127},{"atb":[[4.2,26.56]],"id":43167128}],"con":true,"img":false}]}
{"op":"mcm","clk":"5352917499","pt":1646204645329,"mc":[{"id":"1.195453762","rc":[{"atl":[[17,8.5],[6,14.2]],"id":43167124},{"atl":[[34,13.5]],"id":43167125}],"con":true,"img":false}]}
{"op":"mcm","clk":"5352928938","pt":1646204930948,"mc":[{"id":"1.195453762","rc":[{"atl":[[34,13.5]],"id":43167126},{"atl":[[34,13.5]],"id":43167127}],"con":true,"img":false}]}
{"op":"mcm","clk":"5352934037","pt":1646205054847,"mc":[{"id":"1.195453762","rc":[{"atb":[[4,0],[4.5,0],[5,0],[5.5,0]],"id":43167126},{"atl":[[17,0],[19.5,0],[24,0],[29,0]],"id":43167126},{"atb":[[9.2,0],[10.5,0],[8.2,0],[13,0]],"id":42688789},{"atl":[[80,0],[160,0],[210,0],[110,0]],"id":42688789},{"atb":[[3.6,0],[3.1,0],[3.35,0],[2.94,0]],"id":43167125},{"atl":[[12,0],[9.8,0],[8.8,0],[14.5,0]],"id":43167125}],"con":true,"img":false}]}
{"op":"mcm","clk":"5352934146","pt":1646205057363,"mc":[{"id":"1.195453762","rc":[{"atb":[[5.1,0],[4.6,0]],"id":43167126},{"atb":[[13.5,0.81]],"id":42688789},{"atb":[[3.4,0],[3.15,0]],"id":43167125}],"con":true,"img":false}]}
{"op":"mcm","clk":"5352934148","pt":1646205057466,"mc":[{"id":"1.195453762","rc":[{"atb":[[4.8,14.27],[4,32.9]],"id":43167126},{"atb":[[12.5,4.68]],"id":42688789},{"atb":[[2.82,58.95],[3.25,24.39]],"id":43167125}],"con":true,"img":false}]}
{"op":"mcm","clk":"5352934306","pt":1646205061543,"mc":[{"id":"1.195453762","rc":[{"atb":[[3.65,3.8]],"id":43167125}],"con":true,"img":false}]}
{"op":"mcm","clk":"5352934749","pt":1646205071715,"mc":[{"id":"1.195453762","rc":[{"atb":[[4,67.24],[4.5,29.43],[5,25.75],[5.5,22.89]],"id":43167126},{"atl":[[17,8.34],[19.5,7.21],[24,8.7],[29,7.14]],"id":43167126},{"atb":[[12,9.36],[9.8,11.7],[8.8,13.2],[7.8,15.15]],"id":42688789},{"atl":[[70,1.93],[140,1.44],[95,1.41],[190,1.05]],"id":42688789},{"atb":[[3.4,42.93],[3.15,47.92],[3.9,35.52],[3.65,42.68]],"id":43167125},{"atl":[[18,11.76],[10.5,14.04],[13,11.11],[15.5,27.99]],"id":43167125}],"con":true,"img":false}]}
{"op":"mcm","clk":"5352934844","pt":1646205074565,"mc":[{"id":"1.195453762","rc":[{"atl":[[3.3,4.56]],"id":43167124}],"con":true,"img":false}]}
{"op":"mcm","clk":"5352935068","pt":1646205079797,"mc":[{"id":"1.195453762","rc":[{"atb":[[3.65,38.88]],"id":43167125}],"con":true,"img":false}]}
{"op":"mcm","clk":"5352935074","pt":1646205079900,"mc":[{"id":"1.195453762","rc":[{"atl":[[4.3,4.7]],"id":43167124}],"con":true,"img":false}]}
{"op":"mcm","clk":"5352935564","pt":1646205091611,"mc":[{"id":"1.195453762","rc":[{"atb":[[3.95,2.55]],"id":43167125}],"con":true,"img":false}]}
{"op":"mcm","clk":"5352935569","pt":1646205091714,"mc":[{"id":"1.195453762","rc":[{"atb":[[3.95,5.97]],"id":43167125}],"con":true,"img":false}]}
{"op":"mcm","clk":"5352936174","pt":1646205103927,"mc":[{"id":"1.195453762","rc":[{"atb":[[4.8,0]],"id":43167126},{"atb":[[3.25,0]],"id":43167125}],"con":true,"img":false}]}
{"op":"mcm","clk":"5352936179","pt":1646205104030,"mc":[{"id":"1.195453762","rc":[{"atb":[[5.1,14.27]],"id":43167126},{"atb":[[3.45,24.39]],"id":43167125}],"con":true,"img":false}]}
{"op":"mcm","clk":"5352937143","pt":1646205127372,"mc":[{"id":"1.195453762","rc":[{"atb":[[4,34.34]],"id":43167126},{"atb":[[12.5,0]],"id":42688789},{"atb":[[2.82,0]],"id":43167125},{"spn":5.37,"spf":"NaN","id":43167125}],"con":true,"img":false}]}
{"op":"mcm","clk":"5352937148","pt":1646205127473,"mc":[{"id":"1.195453762","rc":[{"atb":[[4.6,32.9]],"id":43167126},{"atb":[[13,4.68]],"id":42688789},{"atb":[[3.2,58.95]],"id":43167125}],"con":true,"img":false}]}
{"op":"mcm","clk":"5352937752","pt":1646205142891,"mc":[{"id":"1.195453762","rc":[{"atb":[[11,0]],"id":42688789}],"con":true,"img":false}]}
{"op":"mcm","clk":"5352937757","pt":1646205142993,"mc":[{"id":"1.195453762","rc":[{"atb":[[12.5,12.55]],"id":42688789}],"con":true,"img":false}]}
{"op":"mcm","clk":"5352938111","pt":1646205152878,"mc":[{"id":"1.195453762","rc":[{"atl":[[6.8,0]],"id":43167125}],"con":true,"img":false}]}
{"op":"mcm","clk":"5352938116","pt":1646205152979,"mc":[{"id":"1.195453762","rc":[{"atl":[[7,10.09]],"id":43167125}],"con":true,"img":false}]}
{"op":"mcm","clk":"5352938986","pt":1646205167924,"mc":[{"id":"1.195453762","rc":[{"atl":[[8.6,0],[7,0]],"id":43167125}],"con":true,"img":false}]}
{"op":"mcm","clk":"5352938990","pt":1646205168026,"mc":[{"id":"1.195453762","rc":[{"atl":[[7.2,10.09],[10,16.92]],"id":43167125}],"con":true,"img":false}]}
{"op":"mcm","clk":"5352939407","pt":1646205176952,"mc":[{"id":"1.195453762","rc":[{"atl":[[40,0]],"id":42688789},{"atl":[[3.35,0]],"id":43167124},{"atb":[[3.45,0]],"id":43167125}],"con":true,"img":false}]}
{"op":"mcm","clk":"5352939414","pt":1646205177054,"mc":[{"id":"1.195453762","rc":[{"atl":[[38,2.72]],"id":42688789},{"atl":[[3.25,24.91]],"id":43167124},{"atb":[[3.7,24.39]],"id":43167125}],"con":true,"img":false}]}
{"op":"mcm","clk":"5352940022","pt":1646205190876,"mc":[{"id":"1.195453762","rc":[{"spn":25.75,"spf":"NaN","id":42688789},{"atl":[[3.3,0]],"id":43167124},{"spn":5.57,"spf":"NaN","id":43167125}],"con":true,"img":false}]}
{"op":"mcm","clk":"5352940175","pt":1646205193768,"mc":[{"id":"1.195453762","rc":[{"atl":[[3.2,4.7]],"id":43167124}],"con":true,"img":false}]}
{"op":"mcm","clk":"5352940348","pt":1646205197063,"mc":[{"id":"1.195453762","rc":[{"atl":[[4.3,0]],"id":43167124}],"con":true,"img":false}]}
{"op":"mcm","clk":"5352940493","pt":1646205199886,"mc":[{"id":"1.195453762","rc":[{"atb":[[5.1,0]],"id":43167127}],"con":true,"img":false}]}
{"op":"mcm","clk":"5352940498","pt":1646205199990,"mc":[{"id":"1.195453762","rc":[{"atb":[[5.6,15.27]],"id":43167127}],"con":true,"img":false}]}
{"op":"mcm","clk":"5352940827","pt":1646205207276,"mc":[{"id":"1.195453762","rc":[{"atl":[[4.3,4.7]],"id":43167124}],"con":true,"img":false}]}
{"op":"mcm","clk":"5352941333","pt":1646205218141,"mc":[{"id":"1.195453762","rc":[{"atb":[[5.6,14.27]],"id":43167127}],"con":true,"img":false}]}
{"op":"mcm","clk":"5352941728","pt":1646205225823,"mc":[{"id":"1.195453762","rc":[{"atl":[[170,14.2]],"id":43167128},{"atl":[[150,14.2]],"id":42688789}],"con":true,"img":false}]}
{"op":"mcm","clk":"5352941774","pt":1646205226541,"mc":[{"id":"1.195453762","rc":[{"atb":[[4.6,0]],"id":43167127},{"atb":[[3.2,0]],"id":43167125}],"con":true,"img":false}]}
{"op":"mcm","clk":"5352941781","pt":1646205226644,"mc":[{"id":"1.195453762","rc":[{"atb":[[5.1,32.22]],"id":43167127},{"atb":[[3.45,58.95]],"id":43167125}],"con":true,"img":false}]}
{"op":"mcm","clk":"5352941953","pt":1646205230152,"mc":[{"id":"1.195453762","rc":[{"atl":[[1000,1.67]],"id":43167127}],"con":true,"img":false}]}
{"op":"mcm","clk":"5352941956","pt":1646205230254,"mc":[{"id":"1.195453762","rc":[{"atb":[[5.7,2.15]],"id":43167127}],"con":true,"img":false}]}
{"op":"mcm","clk":"5352941970","pt":1646205230564,"mc":[{"id":"1.195453762","rc":[{"atl":[[1000,0.99]],"id":43167127}],"con":true,"img":false}]}
{"op":"mcm","clk":"5352941990","pt":1646205231028,"mc":[{"id":"1.195453762","rc":[{"atl":[[1000,0]],"id":43167127}],"con":true,"img":false}]}
{"op":"mcm","clk":"5352941998","pt":1646205231130,"mc":[{"id":"1.195453762","rc":[{"atl":[[6.8,0.99]],"id":43167127}],"con":true,"img":false}]}
{"op":"mcm","clk":"5352945452","pt":1646205311080,"mc":[{"id":"1.195453762","rc":[{"spn":6.25,"spf":"NaN","id":43167127},{"atl":[[3.2,0]],"id":43167124}],"con":true,"img":false}]}
{"op":"mcm","clk":"5352946189","pt":1646205326609,"mc":[{"id":"1.195453762","rc":[{"atl":[[4.3,0]],"id":43167124}],"con":true,"img":false}]}
{"op":"mcm","clk":"5352947255","pt":1646205353573,"mc":[{"id":"1.195453762","rc":[{"atl":[[6.8,0]],"id":43167127}],"con":true,"img":false}]}
{"op":"mcm","clk":"5352947262","pt":1646205353729,"mc":[{"id":"1.195453762","rc":[{"atl":[[1000,1.67]],"id":43167127}],"con":true,"img":false}]}
{"op":"mcm","clk":"5352947274","pt":1646205354036,"mc":[{"id":"1.195453762","rc":[{"atl":[[1000,0.67]],"id":43167127}],"con":true,"img":false}]}
{"op":"mcm","clk":"5352947294","pt":1646205354448,"mc":[{"id":"1.195453762","rc":[{"atl":[[1000,0]],"id":43167127}],"con":true,"img":false}]}
{"op":"mcm","clk":"5352947300","pt":1646205354550,"mc":[{"id":"1.195453762","rc":[{"atl":[[10,0.67]],"id":43167127}],"con":true,"img":false}]}
{"op":"mcm","clk":"5352947370","pt":1646205356144,"mc":[{"id":"1.195453762","rc":[{"atl":[[3.2,4.7]],"id":43167124}],"con":true,"img":false}]}
{"op":"mcm","clk":"5352947676","pt":1646205363067,"mc":[{"id":"1.195453762","rc":[{"atl":[[4.3,4.7]],"id":43167124}],"con":true,"img":false}]}
{"op":"mcm","clk":"5352951914","pt":1646205473359,"mc":[{"id":"1.195453762","rc":[{"spn":7.85,"spf":"NaN","id":43167127},{"atl":[[3.2,0]],"id":43167124}],"con":true,"img":false}]}
{"op":"mcm","clk":"5352952011","pt":1646205476242,"mc":[{"id":"1.195453762","rc":[{"atl":[[3.2,4.7]],"id":43167124}],"con":true,"img":false}]}
{"op":"mcm","clk":"5352952032","pt":1646205476961,"mc":[{"id":"1.195453762","rc":[{"atl":[[10,0]],"id":43167127}],"con":true,"img":false}]}
{"op":"mcm","clk":"5352952038","pt":1646205477165,"mc":[{"id":"1.195453762","rc":[{"atl":[[1000,1.67]],"id":43167127}],"con":true,"img":false}]}
{"op":"mcm","clk":"5352952048","pt":1646205477472,"mc":[{"id":"1.195453762","rc":[{"atl":[[1000,0.64]],"id":43167127}],"con":true,"img":false}]}
{"op":"mcm","clk":"5352952064","pt":1646205477833,"mc":[{"id":"1.195453762","rc":[{"atl":[[1000,0]],"id":43167127}],"con":true,"img":false}]}
{"op":"mcm","clk":"5352952068","pt":1646205477935,"mc":[{"id":"1.195453762","rc":[{"atl":[[10.5,0.64]],"id":43167127}],"con":true,"img":false}]}
{"op":"mcm","clk":"5352952430","pt":1646205488968,"mc":[{"id":"1.195453762","rc":[{"atl":[[4.3,0]],"id":43167124}],"con":true,"img":false}]}
{"op":"mcm","clk":"5352952864","pt":1646205500778,"mc":[{"id":"1.195453762","rc":[{"atl":[[4.3,4.7]],"id":43167124}],"con":true,"img":false}]}
{"op":"mcm","clk":"5352953447","pt":1646205518203,"mc":[{"id":"1.195453762","rc":[{"atb":[[21,0]],"id":41017865},{"atb":[[3.55,0]],"id":43167125}],"con":true,"img":false}]}
{"op":"mcm","clk":"5352953453","pt":1646205518306,"mc":[{"id":"1.195453762","rc":[{"atb":[[22,0.49]],"id":41017865},{"atb":[[3.85,2]],"id":43167125}],"con":true,"img":false}]}
{"op":"mcm","clk":"5352955876","pt":1646205593486,"mc":[{"id":"1.195453762","rc":[{"spn":8.1,"spf":"NaN","id":43167127},{"atl":[[3.2,0]],"id":43167124}],"con":true,"img":false}]}
{"op":"mcm","clk":"5352955974","pt":1646205596426,"mc":[{"id":"1.195453762","rc":[{"atl":[[3.2,4.7]],"id":43167124}],"con":true,"img":false}]}
{"op":"mcm","clk":"5352956216","pt":1646205603107,"mc":[{"id":"1.195453762","rc":[{"atb":[[5.3,0]],"id":43167127},{"atb":[[1.91,0]],"id":43167124}],"con":true,"img":false}]}
{"op":"mcm","clk":"5352956221","pt":1646205603220,"mc":[{"id":"1.195453762","rc":[{"atb":[[22,0]],"id":41017865},{"atb":[[4.6,34.9],[5.3,0]],"id":43167126},{"atb":[[13.5,4.68]],"id":43167128},{"atb":[[1.91,2]],"id":43167124},{"atb":[[3.85,0]],"id":43167125}],"con":true,"img":false}]}
{"op":"mcm","clk":"5352956227","pt":1646205603420,"mc":[{"id":"1.195453762","rc":[{"atb":[[22,0.49]],"id":41017865},{"atb":[[13.5,5.49]],"id":43167128},{"atb":[[3.85,2]],"id":43167125}],"con":true,"img":false}]}
{"op":"mcm","clk":"5352957006","pt":1646205625253,"mc":[{"id":"1.195453762","rc":[{"atl":[[4.3,0]],"id":43167124}],"con":true,"img":false}]}
{"op":"mcm","clk":"5352957437","pt":1646205639482,"mc":[{"id":"1.195453762","rc":[{"atl":[[4.3,4.7]],"id":43167124}],"con":true,"img":false}]}
{"op":"mcm","clk":"5352958169","pt":1646205663197,"mc":[{"id":"1.195453762","rc":[{"atb":[[42,2.76]],"id":37178159}],"con":true,"img":false}]}
{"op":"mcm","clk":"5352958174","pt":1646205663299,"mc":[{"id":"1.195453762","rc":[{"atb":[[55,1.91]],"id":37178159}],"con":true,"img":false}]}
{"op":"mcm","clk":"5352959761","pt":1646205713962,"mc":[{"id":"1.195453762","rc":[{"atl":[[3.2,0]],"id":43167124}],"con":true,"img":false}]}
{"op":"mcm","clk":"5352959821","pt":1646205716839,"mc":[{"id":"1.195453762","rc":[{"atl":[[3.2,4.7]],"id":43167124}],"con":true,"img":false}]}
{"op":"mcm","clk":"5352961586","pt":1646205774862,"mc":[{"id":"1.195453762","rc":[{"atl":[[4.3,0]],"id":43167124}],"con":true,"img":false}]}
{"op":"mcm","clk":"5352961956","pt":1646205787047,"mc":[{"id":"1.195453762","rc":[{"atl":[[4.3,4.7]],"id":43167124}],"con":true,"img":false}]}
{"op":"mcm","clk":"5352963609","pt":1646205834079,"mc":[{"id":"1.195453762","rc":[{"atl":[[3.2,0]],"id":43167124}],"con":true,"img":false}]}
{"op":"mcm","clk":"5352963707","pt":1646205837012,"mc":[{"id":"1.195453762","rc":[{"atl":[[3.2,4.7]],"id":43167124}],"con":true,"img":false}]}
{"op":"mcm","clk":"5352966323","pt":1646205907192,"mc":[{"id":"1.195453762","rc":[{"atl":[[4.3,0]],"id":43167124}],"con":true,"img":false}]}
{"op":"mcm","clk":"5352966857","pt":1646205919004,"mc":[{"id":"1.195453762","rc":[{"atl":[[4.3,4.7]],"id":43167124}],"con":true,"img":false}]}
{"op":"mcm","clk":"5352968109","pt":1646205954315,"mc":[{"id":"1.195453762","rc":[{"atl":[[3.2,0]],"id":43167124}],"con":true,"img":false}]}
{"op":"mcm","clk":"5352968222","pt":1646205957245,"mc":[{"id":"1.195453762","rc":[{"atl":[[3.2,4.7]],"id":43167124}],"con":true,"img":false}]}
{"op":"mcm","clk":"5352969161","pt":1646205984483,"mc":[{"id":"1.195453762","rc":[{"atl":[[3.1,8.18]],"id":43167124}],"con":true,"img":false}]}
{"op":"mcm","clk":"5352971049","pt":1646206039406,"mc":[{"id":"1.195453762","rc":[{"atl":[[4.3,0]],"id":43167124}],"con":true,"img":false}]}
{"op":"mcm","clk":"5352971510","pt":1646206051230,"mc":[{"id":"1.195453762","rc":[{"atl":[[4.3,4.7]],"id":43167124}],"con":true,"img":false}]}
{"op":"mcm","clk":"5352972488","pt":1646206074456,"mc":[{"id":"1.195453762","rc":[{"atl":[[3.2,0]],"id":43167124}],"con":true,"img":false}]}
{"op":"mcm","clk":"5352973283","pt":1646206095288,"mc":[{"id":"1.195453762","rc":[{"atb":[[13.5,8]],"id":37178159},{"atl":[[470,2]],"id":37178159},{"atb":[[8,14.29]],"id":41017865},{"atl":[[180,2]],"id":41017865},{"atb":[[3.55,39.22]],"id":43167126},{"atl":[[18.5,5.71]],"id":43167126},{"atb":[[3.6,38.46]],"id":43167127},{"atl":[[21,13.2]],"id":43167127},{"atb":[[7.4,15.62]],"id":43167128},{"atl":[[140,2]],"id":43167128},{"atb":[[4.5,28.57]],"id":42688789},{"atl":[[120,2]],"id":42688789},{"atb":[[1.43,232.56]],"id":43167124},{"atl":[[3.3,36.57]],"id":43167124},{"atb":[[3.1,47.62]],"id":43167125},{"atl":[[14,7.69]],"id":43167125}],"con":true,"img":false}]}
{"op":"mcm","clk":"5352973797","pt":1646206108663,"mc":[{"id":"1.195453762","rc":[{"atl":[[140,9.64]],"id":42688789}],"con":true,"img":false}]}
{"op":"mcm","clk":"5352974593","pt":1646206132236,"mc":[{"id":"1.195453762","rc":[{"atl":[[430,2],[470,0]],"id":37178159},{"atb":[[9,12.5]],"id":41017865},{"atb":[[3.6,0]],"id":43167127},{"atb":[[8.4,13.51]],"id":43167128}],"con":true,"img":false}]}
{"op":"mcm","clk":"5352974599","pt":1646206132338,"mc":[{"id":"1.195453762","rc":[{"atb":[[8,0]],"id":41017865},{"atb":[[3.8,35.71],[3.55,0]],"id":43167126},{"atb":[[3.9,34.48]],"id":43167127},{"atb":[[7.4,0]],"id":43167128}],"con":true,"img":false}]}
{"op":"mcm","clk":"5352974786","pt":1646206138405,"mc":[{"id":"1.195453762","rc":[{"atl":[[3.25,81.68]],"id":43167124}],"con":true,"img":false}]}
{"op":"mcm","clk":"5352974791","pt":1646206138504,"mc":[{"id":"1.195453762","rc":[{"atl":[[4.4,0]],"id":43167124}],"con":true,"img":false}]}
{"op":"mcm","clk":"5352975892","pt":1646206171666,"mc":[{"id":"1.195453762","rc":[{"atl":[[4.3,0]],"id":43167124}],"con":true,"img":false}]}
{"op":"mcm","clk":"5352976190","pt":1646206180851,"mc":[{"id":"1.195453762","rc":[{"atl":[[3.2,6.31]],"id":43167124}],"con":true,"img":false}]}
{"op":"mcm","clk":"5352977157","pt":1646206203797,"mc":[{"id":"1.195453762","rc":[{"atl":[[3.2,11.01]],"id":43167124}],"con":true,"img":false}]}
{"op":"mcm","clk":"5352978226","pt":1646206226828,"mc":[{"id":"1.195453762","rc":[{"atl":[[1000,2.25]],"id":41017865},{"atb":[[1.01,2.25]],"id":43167127},{"atb":[[1.03,2.25]],"id":43167128},{"atb":[[1.02,2.25]],"id":43167125}],"con":true,"img":false}]}
{"op":"mcm","clk":"5352978231","pt":1646206227029,"mc":[{"id":"1.195453762","rc":[{"atl":[[1000,0.06]],"id":41017865},{"atb":[[1.01,0.64]],"id":43167127},{"atb":[[1.03,0.27]],"id":43167128},{"atb":[[1.02,0.94]],"id":43167125}],"con":true,"img":false}]}
{"op":"mcm","clk":"5352978247","pt":1646206227544,"mc":[{"id":"1.195453762","rc":[{"atb":[[1.01,0]],"id":43167127}],"con":true,"img":false}]}
{"op":"mcm","clk":"5352978253","pt":1646206227649,"mc":[{"id":"1.195453762","rc":[{"atb":[[5.8,0.64]],"id":43167127}],"con":true,"img":false}]}
{"op":"mcm","clk":"5352978258","pt":1646206227752,"mc":[{"id":"1.195453762","rc":[{"atb":[[1.02,0]],"id":43167125}],"con":true,"img":false}]}
{"op":"mcm","clk":"5352978265","pt":1646206227853,"mc":[{"id":"1.195453762","rc":[{"atb":[[4,0.94]],"id":43167125}],"con":true,"img":false}]}
{"op":"mcm","clk":"5352978272","pt":1646206227957,"mc":[{"id":"1.195453762","rc":[{"atl":[[1000,0]],"id":41017865}],"con":true,"img":false}]}
{"op":"mcm","clk":"5352978278","pt":1646206228060,"mc":[{"id":"1.195453762","rc":[{"atl":[[65,0.06]],"id":41017865}],"con":true,"img":false}]}
{"op":"mcm","clk":"5352978284","pt":1646206228115,"mc":[{"id":"1.195453762","rc":[{"atb":[[1.03,0]],"id":43167128}],"con":true,"img":false}]}
{"op":"mcm","clk":"5352978289","pt":1646206228222,"mc":[{"id":"1.195453762","rc":[{"atb":[[14,0.27]],"id":43167128}],"con":true,"img":false}]}
{"op":"mcm","clk":"5352979809","pt":1646206256859,"mc":[{"id":"1.195453762","rc":[{"atb":[[1.04,2.25]],"id":41017865},{"atb":[[1.03,2.25]],"id":42688789}],"con":true,"img":false}]}
{"op":"mcm","clk":"5352979820","pt":1646206257068,"mc":[{"id":"1.195453762","rc":[{"atb":[[1.04,0.15]],"id":41017865},{"atb":[[1.03,0.27]],"id":42688789}],"con":true,"img":false}]}
{"op":"mcm","clk":"5352979829","pt":1646206257169,"mc":[{"id":"1.195453762","rc":[{"atb":[[1.03,0]],"id":42688789}],"con":true,"img":false}]}
{"op":"mcm","clk":"5352979834","pt":1646206257271,"mc":[{"id":"1.195453762","rc":[{"atb":[[14,0.27]],"id":42688789}],"con":true,"img":false}]}
{"op":"mcm","clk":"5352979845","pt":1646206257481,"mc":[{"id":"1.195453762","rc":[{"atb":[[1.04,0]],"id":41017865}],"con":true,"img":false}]}
{"op":"mcm","clk":"5352979852","pt":1646206257580,"mc":[{"id":"1.195453762","rc":[{"atb":[[24,0.15]],"id":41017865}],"con":true,"img":false}]}
{"op":"mcm","clk":"5352980154","pt":1646206263099,"mc":[{"id":"1.195453762","rc":[{"atb":[[3.6,38.46],[3.9,0]],"id":43167127}],"con":true,"img":false}]}
{"op":"mcm","clk":"5352980719","pt":1646206273193,"mc":[{"id":"1.195453762","rc":[{"spn":44.5,"spf":"NaN","id":41017865},{"spn":8.15,"spf":"NaN","id":43167127},{"spn":27.0,"spf":"NaN","id":43167128},{"spn":26.0,"spf":"NaN","id":42688789},{"atl":[[2.7,6.04]],"id":43167124},{"trd":[[2.7,0.33]],"ltp":2.7,"tv":0.33,"id":43167124},{"spn":5.6,"spf":"NaN","id":43167125}],"con":true,"img":false}]}
{"op":"mcm","clk":"5352980729","pt":1646206273399,"mc":[{"id":"1.195453762","rc":[{"atb":[[1.91,0]],"id":43167124}],"con":true,"img":false}]}
{"op":"mcm","clk":"5352981881","pt":1646206297993,"mc":[{"id":"1.195453762","rc":[{"atl":[[3.2,4.7]],"id":43167124}],"con":true,"img":false}]}
{"op":"mcm","clk":"5352982287","pt":1646206306898,"mc":[{"id":"1.195453762","rc":[{"atl":[[3.2,11.01]],"id":43167124}],"con":true,"img":false}]}
{"op":"mcm","clk":"5352982923","pt":1646206321029,"mc":[{"id":"1.195453762","rc":[{"atl":[[3.2,6.31]],"id":43167124}],"con":true,"img":false}]}
{"op":"mcm","clk":"5352983099","pt":1646206324068,"mc":[{"id":"1.195453762","rc":[{"atl":[[3.2,11.01]],"id":43167124}],"con":true,"img":false}]}
{"op":"mcm","clk":"5352983703","pt":1646206336054,"mc":[{"id":"1.195453762","rc":[{"atl":[[3.25,56.76]],"id":43167124}],"con":true,"img":false}]}
{"op":"mcm","clk":"5352983708","pt":1646206336156,"mc":[{"id":"1.195453762","rc":[{"atl":[[3.15,24.91]],"id":43167124}],"con":true,"img":false}]}
{"op":"mcm","clk":"5352987549","pt":1646206430272,"mc":[{"id":"1.195453762","rc":[{"atl":[[3.2,4.7]],"id":43167124}],"con":true,"img":false}]}
{"op":"mcm","clk":"5352987697","pt":1646206433978,"mc":[{"id":"1.195453762","rc":[{"atl":[[3.15,0]],"id":43167124}],"con":true,"img":false}]}
{"op":"mcm","clk":"5352987701","pt":1646206434080,"mc":[{"id":"1.195453762","rc":[{"atl":[[3.25,81.68]],"id":43167124}],"con":true,"img":false}]}
{"op":"mcm","clk":"5352987935","pt":1646206439197,"mc":[{"id":"1.195453762","rc":[{"atl":[[3.2,11.01]],"id":43167124}],"con":true,"img":false}]}
{"op":"mcm","clk":"5352988040","pt":1646206441270,"mc":[{"id":"1.195453762","rc":[{"atl":[[3.2,6.31]],"id":43167124}],"con":true,"img":false}]}
{"op":"mcm","clk":"5352988178","pt":1646206444170,"mc":[{"id":"1.195453762","rc":[{"atl":[[3.2,11.01]],"id":43167124}],"con":true,"img":false}]}
{"op":"mcm","clk":"5352989999","pt":1646206488649,"mc":[{"id":"1.195453762","rc":[{"atl":[[3.25,56.76]],"id":43167124}],"con":true,"img":false}]}
{"op":"mcm","clk":"5352990003","pt":1646206488751,"mc":[{"id":"1.195453762","rc":[{"atl":[[3.15,24.91]],"id":43167124}],"con":true,"img":false}]}
{"op":"mcm","clk":"5352993263","pt":1646206561595,"mc":[{"id":"1.195453762","rc":[{"atl":[[3.2,6.31]],"id":43167124}],"con":true,"img":false}]}
{"op":"mcm","clk":"5352993310","pt":1646206562880,"mc":[{"id":"1.195453762","rc":[{"atl":[[3.2,0]],"id":43167124}],"con":true,"img":false}]}
{"op":"mcm","clk":"5352993363","pt":1646206564291,"mc":[{"id":"1.195453762","rc":[{"atl":[[3.15,0]],"id":43167124}],"con":true,"img":false}]}
{"op":"mcm","clk":"5352993367","pt":1646206564299,"mc":[{"id":"1.195453762","rc":[{"atl":[[3.25,81.68]],"id":43167124}],"con":true,"img":false}]}
{"op":"mcm","clk":"5352993372","pt":1646206564472,"mc":[{"id":"1.195453762","rc":[{"atl":[[3.1,13.04]],"id":43167124}],"con":true,"img":false}]}
{"op":"mcm","clk":"5352993669","pt":1646206571895,"mc":[{"id":"1.195453762","rc":[{"atl":[[3.2,6.31]],"id":43167124}],"con":true,"img":false}]}
{"op":"mcm","clk":"5352995825","pt":1646206622848,"mc":[{"id":"1.195453762","rc":[{"atl":[[3.25,56.76]],"id":43167124}],"con":true,"img":false}]}
{"op":"mcm","clk":"5352995830","pt":1646206622952,"mc":[{"id":"1.195453762","rc":[{"atl":[[3.15,24.91]],"id":43167124}],"con":true,"img":false}]}
{"op":"mcm","clk":"5352998312","pt":1646206681658,"mc":[{"id":"1.195453762","rc":[{"atl":[[3.1,8.18]],"id":43167124}],"con":true,"img":false}]}
{"op":"mcm","clk":"5352998424","pt":1646206684690,"mc":[{"id":"1.195453762","rc":[{"atl":[[3.1,13.04]],"id":43167124}],"con":true,"img":false}]}
{"op":"mcm","clk":"5352998930","pt":1646206698102,"mc":[{"id":"1.195453762","rc":[{"atl":[[3.2,0]],"id":43167124}],"con":true,"img":false}]}
{"op":"mcm","clk":"5352999172","pt":1646206703914,"mc":[{"id":"1.195453762","rc":[{"atl":[[3.15,0]],"id":43167124}],"con":true,"img":false}]}
{"op":"mcm","clk":"5352999177","pt":1646206704017,"mc":[{"id":"1.195453762","rc":[{"atl":[[3.25,81.68]],"id":43167124}],"con":true,"img":false}]}
{"op":"mcm","clk":"5352999448","pt":1646206709829,"mc":[{"id":"1.195453762","rc":[{"atl":[[3.2,6.31]],"id":43167124}],"con":true,"img":false}]}
{"op":"mcm","clk":"5353001509","pt":1646206757300,"mc":[{"id":"1.195453762","rc":[{"atl":[[3.25,56.76]],"id":43167124}],"con":true,"img":false}]}
{"op":"mcm","clk":"5353001515","pt":1646206757408,"mc":[{"id":"1.195453762","rc":[{"atl":[[3.15,24.91]],"id":43167124}],"con":true,"img":false}]}
{"op":"mcm","clk":"5353002234","pt":1646206775629,"mc":[{"id":"1.195453762","rc":[{"atb":[[2.12,7.09]],"id":43167124}],"con":true,"img":false}]}
{"op":"mcm","clk":"5353003325","pt":1646206801864,"mc":[{"id":"1.195453762","rc":[{"atl":[[3.1,8.18]],"id":43167124}],"con":true,"img":false}]}
{"op":"mcm","clk":"5353003344","pt":1646206802280,"mc":[{"id":"1.195453762","rc":[{"atb":[[1.04,1.67]],"id":43167124}],"con":true,"img":false}]}
{"op":"mcm","clk":"5353003356","pt":1646206802435,"mc":[{"id":"1.195453762","rc":[{"atb":[[1.04,1.66]],"id":43167124}],"con":true,"img":false}]}
{"op":"mcm","clk":"5353003366","pt":1646206802641,"mc":[{"id":"1.195453762","rc":[{"atb":[[1.04,0]],"id":43167124}],"con":true,"img":false}]}
{"op":"mcm","clk":"5353003371","pt":1646206802745,"mc":[{"id":"1.195453762","rc":[{"atb":[[2.1,1.66]],"id":43167124}],"con":true,"img":false}]}
{"op":"mcm","clk":"5353004332","pt":1646206827220,"mc":[{"id":"1.195453762","rc":[{"atl":[[3.2,0]],"id":43167124},{"spn":2.41,"spf":"NaN","id":43167124}],"con":true,"img":false}]}
{"op":"mcm","clk":"5353004989","pt":1646206843442,"mc":[{"id":"1.195453762","rc":[{"atl":[[3.15,0]],"id":43167124}],"con":true,"img":false}]}
{"op":"mcm","clk":"5353004993","pt":1646206843546,"mc":[{"id":"1.195453762","rc":[{"atl":[[3.25,81.68]],"id":43167124}],"con":true,"img":false}]}
{"op":"mcm","clk":"5353016181","pt":1646207109135,"mc":[{"id":"1.195453762","rc":[{"atb":[[1.28,0]],"id":43167124}],"con":true,"img":false}]}
{"op":"mcm","clk":"5353017047","pt":1646207127955,"mc":[{"id":"1.195453762","rc":[{"atb":[[2.7,3.96]],"id":43167124},{"atl":[[2.7,0]],"id":43167124},{"trd":[[2.7,12.42]],"ltp":2.7,"tv":12.42,"id":43167124}],"con":true,"img":false}]}
{"op":"mcm","clk":"5353017161","pt":1646207130586,"mc":[{"id":"1.195453762","rc":[{"atb":[[2.1,0],[1.04,1.67]],"id":43167124}],"con":true,"img":false}]}
{"op":"mcm","clk":"5353017176","pt":1646207130788,"mc":[{"id":"1.195453762","rc":[{"atb":[[1.04,1.66]],"id":43167124}],"con":true,"img":false}]}
{"op":"mcm","clk":"5353017191","pt":1646207131053,"mc":[{"id":"1.195453762","rc":[{"atb":[[1.04,0]],"id":43167124}],"con":true,"img":false}]}
{"op":"mcm","clk":"5353017196","pt":1646207131151,"mc":[{"id":"1.195453762","rc":[{"atb":[[2.18,1.66]],"id":43167124}],"con":true,"img":false}]}
{"op":"mcm","clk":"5353018642","pt":1646207153912,"mc":[{"id":"1.195453762","rc":[{"atl":[[3.15,37.06],[3.3,0]],"id":43167124}],"con":true,"img":false}]}
{"op":"mcm","clk":"5353018746","pt":1646207156316,"mc":[{"id":"1.195453762","rc":[{"atb":[[9,0],[7.2,16.13]],"id":41017865}],"con":true,"img":false}]}
{"op":"mcm","clk":"5353018775","pt":1646207156989,"mc":[{"id":"1.195453762","rc":[{"atl":[[4.2,36.57]],"id":43167124}],"con":true,"img":false}]}
{"op":"mcm","clk":"5353018780","pt":1646207157092,"mc":[{"id":"1.195453762","rc":[{"atl":[[3.25,24.91]],"id":43167124}],"con":true,"img":false}]}
{"op":"mcm","clk":"5353021021","pt":1646207187054,"mc":[{"id":"1.195453762","rc":[{"atl":[[3.25,0]],"id":43167124},{"spn":2.9,"spf":"NaN","id":43167124}],"con":true,"img":false}]}
{"op":"mcm","clk":"5353021028","pt":1646207187155,"mc":[{"id":"1.195453762","rc":[{"atl":[[3.1,33.1]],"id":43167124}],"con":true,"img":false}]}
{"op":"mcm","clk":"5353021438","pt":1646207192982,"mc":[{"id":"1.195453762","rc":[{"atl":[[70,0]],"id":41017865},{"atl":[[11,0]],"id":43167126}],"con":true,"img":false}]}
{"op":"mcm","clk":"5353021444","pt":1646207193085,"mc":[{"id":"1.195453762","rc":[{"atl":[[75,2.72]],"id":41017865},{"atl":[[11.5,5.85]],"id":43167126}],"con":true,"img":false}]}
{"op":"mcm","clk":"5353030874","pt":1646207215222,"mc":[{"id":"1.195453762","rc":[{"atl":[[65,0],[1000,2.25]],"id":41017865}],"con":true,"img":false}]}
{"op":"mcm","clk":"5353030885","pt":1646207215428,"mc":[{"id":"1.195453762","rc":[{"atl":[[1000,0.06]],"id":41017865}],"con":true,"img":false}]}
{"op":"mcm","clk":"5353030900","pt":1646207215692,"mc":[{"id":"1.195453762","rc":[{"atl":[[1000,0]],"id":41017865}],"con":true,"img":false}]}
{"op":"mcm","clk":"5353030907","pt":1646207215795,"mc":[{"id":"1.195453762","rc":[{"atl":[[70,0.06]],"id":41017865}],"con":true,"img":false}]}
{"op":"mcm","clk":"5353031351","pt":1646207223219,"mc":[{"id":"1.195453762","rc":[{"atb":[[5.1,0]],"id":43167126},{"atl":[[7.2,0]],"id":43167125}],"con":true,"img":false}]}
{"op":"mcm","clk":"5353031357","pt":1646207223322,"mc":[{"id":"1.195453762","rc":[{"atb":[[5.6,15.27]],"id":43167126},{"atl":[[13,19.44],[14,0],[7,10.09]],"id":43167125}],"con":true,"img":false}]}
{"op":"mcm","clk":"5353031673","pt":1646207229914,"mc":[{"id":"1.195453762","rc":[{"atb":[[5.6,14.27]],"id":43167126}],"con":true,"img":false}]}
{"op":"mcm","clk":"5353032228","pt":1646207242052,"mc":[{"id":"1.195453762","rc":[{"atl":[[1000,1.67]],"id":43167126}],"con":true,"img":false}]}
{"op":"mcm","clk":"5353032241","pt":1646207242358,"mc":[{"id":"1.195453762","rc":[{"atl":[[1000,0.99]],"id":43167126}],"con":true,"img":false}]}
{"op":"mcm","clk":"5353032263","pt":1646207242770,"mc":[{"id":"1.195453762","rc":[{"atl":[[1000,0]],"id":43167126}],"con":true,"img":false}]}
{"op":"mcm","clk":"5353032267","pt":1646207242872,"mc":[{"id":"1.195453762","rc":[{"atl":[[6.8,0.99]],"id":43167126}],"con":true,"img":false}]}
{"op":"mcm","clk":"5353032872","pt":1646207255978,"mc":[{"id":"1.195453762","rc":[{"spn":47.0,"spf":"NaN","id":41017865},{"spn":6.2,"spf":"NaN","id":43167126},{"atl":[[3.1,29.09]],"id":43167124},{"trd":[[3.1,8]],"ltp":3.1,"tv":8.0,"id":43167124},{"spn":5.5,"spf":"NaN","id":43167125}],"con":true,"img":false}]}
{"op":"mcm","clk":"5353032882","pt":1646207256184,"mc":[{"id":"1.195453762","rc":[{"atl":[[430,0]],"id":37178159},{"atl":[[21,8.2]],"id":43167127},{"atl":[[55,4.72]],"id":42688789},{"atl":[[3.1,24.91]],"id":43167124}],"con":true,"img":false}]}
{"op":"mcm","clk":"5353032886","pt":1646207256286,"mc":[{"id":"1.195453762","rc":[{"atb":[[17,6.08],[13.5,0]],"id":37178159},{"atl":[[340,4.9]],"id":37178159},{"atb":[[8.2,13.89],[7.2,0]],"id":41017865},{"atl":[[180,0],[110,2]],"id":41017865},{"atb":[[4.1,32.26],[3.8,0]],"id":43167126},{"atl":[[14,7.64],[18.5,0]],"id":43167126},{"atb":[[3.6,0],[4.4,29.41]],"id":43167127},{"atl":[[15.5,14.38]],"id":43167127},{"atb":[[10,11.11],[8.4,0]],"id":43167128},{"atl":[[140,0],[75,2]],"id":43167128},{"atl":[[120,0]],"id":42688789},{"atb":[[1.43,0],[1.56,178.57]],"id":43167124},{"atl":[[3.35,42.55],[3.15,0]],"id":43167124},{"atb":[[3.1,0],[3.75,36.36]],"id":43167125},{"atl":[[9.2,12.2],[13,11.11]],"id":43167125}],"con":true,"img":false}]}
{"op":"mcm","clk":"5353032894","pt":1646207256393,"mc":[{"id":"1.195453762","rc":[{"atl":[[44,2.33],[55,2.72]],"id":42688789},{"atb":[[2.14,5.79]],"id":43167124}],"con":true,"img":false}]}
{"op":"mcm","clk":"5353032898","pt":1646207256500,"mc":[{"id":"1.195453762","rc":[{"atl":[[3.3,8.18]],"id":43167124}],"con":true,"img":false}]}
{"op":"mcm","clk":"5353032973","pt":1646207257796,"mc":[{"id":"1.195453762","rc":[{"atb":[[4.6,2]],"id":43167126},{"atl":[[3.1,0]],"id":43167124}],"con":true,"img":false}]}
{"op":"mcm","clk":"5353032979","pt":1646207257899,"mc":[{"id":"1.195453762","rc":[{"atb":[[5.1,32.9]],"id":43167126},{"atl":[[3.3,33.1]],"id":43167124}],"con":true,"img":false}]}
{"op":"mcm","clk":"5353033589","pt":1646207271503,"mc":[{"id":"1.195453762","rc":[{"atb":[[3.7,0]],"id":43167125}],"con":true,"img":false}]}
{"op":"mcm","clk":"5353033593","pt":1646207271603,"mc":[{"id":"1.195453762","rc":[{"atb":[[3.8,24.39]],"id":43167125}],"con":true,"img":false}]}
{"op":"mcm","clk":"5353034008","pt":1646207281601,"mc":[{"id":"1.195453762","rc":[{"atb":[[10.5,10.53],[8.2,0]],"id":41017865},{"atl":[[85,2],[110,0]],"id":41017865},{"atl":[[13,8.33],[15.5,7.48]],"id":43167127},{"atl":[[3.35,0],[3.25,36.57]],"id":43167124}],"con":true,"img":false}]}
{"op":"mcm","clk":"5353034013","pt":1646207281703,"mc":[{"id":"1.195453762","rc":[{"atl":[[1000,2.25]],"id":41017865}],"con":true,"img":false}]}
{"op":"mcm","clk":"5353034016","pt":1646207281808,"mc":[{"id":"1.195453762","rc":[{"atl":[[70,0]],"id":41017865}],"con":true,"img":false}]}
{"op":"mcm","clk":"5353034018","pt":1646207281909,"mc":[{"id":"1.195453762","rc":[{"atl":[[1000,0.06]],"id":41017865}],"con":true,"img":false}]}
{"op":"mcm","clk":"5353034025","pt":1646207282115,"mc":[{"id":"1.195453762","rc":[{"atl":[[1000,0]],"id":41017865}],"con":true,"img":false}]}
{"op":"mcm","clk":"5353034030","pt":1646207282217,"mc":[{"id":"1.195453762","rc":[{"atl":[[80,0.06]],"id":41017865}],"con":true,"img":false}]}
{"op":"mcm","clk":"5353034864","pt":1646207300448,"mc":[{"id":"1.195453762","rc":[{"atl":[[13.5,9.47],[15.5,0]],"id":43167126},{"atl":[[55,0]],"id":42688789},{"atl":[[10,0]],"id":43167125}],"con":true,"img":false}]}
{"op":"mcm","clk":"5353034867","pt":1646207300549,"mc":[{"id":"1.195453762","rc":[{"atl":[[42,2.72]],"id":42688789},{"atl":[[9,16.92]],"id":43167125}],"con":true,"img":false}]}
{"op":"mcm","clk":"5353035089","pt":1646207306842,"mc":[{"id":"1.195453762","rc":[{"atl":[[10.5,0]],"id":43167126},{"atb":[[2.7,0]],"id":43167124}],"con":true,"img":false}]}
{"op":"mcm","clk":"5353035096","pt":1646207306945,"mc":[{"id":"1.195453762","rc":[{"atl":[[1000,2.25]],"id":43167126}],"con":true,"img":false}]}
{"op":"mcm","clk":"5353035110","pt":1646207307255,"mc":[{"id":"1.195453762","rc":[{"atl":[[1000,0.91]],"id":43167126}],"con":true,"img":false}]}
{"op":"mcm","clk":"5353035128","pt":1646207307564,"mc":[{"id":"1.195453762","rc":[{"atl":[[1000,0]],"id":43167126}],"con":true,"img":false}]}
{"op":"mcm","clk":"5353035133","pt":1646207307667,"mc":[{"id":"1.195453762","rc":[{"atl":[[11,0.91]],"id":43167126}],"con":true,"img":false}]}
{"op":"mcm","clk":"5353035159","pt":1646207308283,"mc":[{"id":"1.195453762","rc":[{"atl":[[3.2,6.31]],"id":43167124}],"con":true,"img":false}]}
{"op":"mcm","clk":"5353035167","pt":1646207308490,"mc":[{"id":"1.195453762","rc":[{"atl":[[3.25,0],[3.15,33.1]],"id":43167124}],"con":true,"img":false}]}
{"op":"mcm","clk":"5353035237","pt":1646207309876,"mc":[{"id":"1.195453762","rc":[{"atl":[[3.1,4.85]],"id":43167124}],"con":true,"img":false}]}
{"op":"mcm","clk":"5353035241","pt":1646207309980,"mc":[{"id":"1.195453762","rc":[{"atl":[[3.1,11.16],[3.15,0]],"id":43167124}],"con":true,"img":false}]}
{"op":"mcm","clk":"5353035245","pt":1646207310082,"mc":[{"id":"1.195453762","rc":[{"atl":[[3.1,4.85],[3.15,33.1]],"id":43167124}],"con":true,"img":false}]}
{"op":"mcm","clk":"5353035249","pt":1646207310185,"mc":[{"id":"1.195453762","rc":[{"atl":[[3.1,16.01]],"id":43167124}],"con":true,"img":false}]}
{"op":"mcm","clk":"5353035254","pt":1646207310288,"mc":[{"id":"1.195453762","rc":[{"atl":[[3.15,0]],"id":43167124}],"con":true,"img":false}]}
{"op":"mcm","clk":"5353035971","pt":1646207326612,"mc":[{"id":"1.195453762","rc":[{"atl":[[100,0]],"id":41017865},{"spn":49.5,"spf":"NaN","id":41017865},{"spn":2.64,"spf":"NaN","id":43167124}],"con":true,"img":false}]}
{"op":"mcm","clk":"5353035977","pt":1646207326714,"mc":[{"id":"1.195453762","rc":[{"atl":[[80,2.78]],"id":41017865}],"con":true,"img":false}]}
{"op":"mcm","clk":"5353035988","pt":1646207326972,"mc":[{"id":"1.195453762","rc":[{"atl":[[70,1.25]],"id":41017865},{"atl":[[11,2.18]],"id":43167126},{"atl":[[11,2.25]],"id":43167127},{"atl":[[36,1.33]],"id":42688789},{"atl":[[3.05,1.31]],"id":43167124},{"atl":[[6.8,1.2]],"id":43167125}],"con":true,"img":false}]}
{"op":"mcm","clk":"5353036103","pt":1646207329913,"mc":[{"id":"1.195453762","rc":[{"atb":[[5.7,2.15]],"id":43167126}],"con":true,"img":false}]}
{"op":"mcm","clk":"5353036308","pt":1646207333788,"mc":[{"id":"1.195453762","rc":[{"atl":[[12.5,10.08],[15.5,0]],"id":43167127}],"con":true,"img":false}]}
{"op":"mcm","clk":"5353036375","pt":1646207335017,"mc":[{"id":"1.195453762","rc":[{"atl":[[85,0],[100,2]],"id":41017865},{"atl":[[13,0],[14.5,7.41]],"id":43167127},{"atl":[[44,0],[48,2.13]],"id":42688789},{"atl":[[3.1,4.85],[3.2,39.41]],"id":43167124}],"con":true,"img":false}]}
{"op":"mcm","clk":"5353036684","pt":1646207341093,"mc":[{"id":"1.195453762","rc":[{"atl":[[80,0.06]],"id":41017865},{"atl":[[12.5,0]],"id":43167127},{"atl":[[42,0]],"id":42688789}],"con":true,"img":false}]}
{"op":"mcm","clk":"5353036689","pt":1646207341203,"mc":[{"id":"1.195453762","rc":[{"atl":[[95,2.72]],"id":41017865},{"atl":[[14,10.08]],"id":43167127},{"atl":[[46,2.72]],"id":42688789}],"con":true,"img":false}]}
{"op":"mcm","clk":"5353037594","pt":1646207361240,"mc":[{"id":"1.195453762","rc":[{"atl":[[3.3,8.18]],"id":43167124}],"con":true,"img":false}]}
{"op":"mcm","clk":"5353037599","pt":1646207361342,"mc":[{"id":"1.195453762","rc":[{"atl":[[3.15,24.91]],"id":43167124}],"con":true,"img":false}]}
{"op":"mcm","clk":"5353037978","pt":1646207368761,"mc":[{"id":"1.195453762","rc":[{"atl":[[6.8,0]],"id":43167126}],"con":true,"img":false}]}
{"op":"mcm","clk":"5353037985","pt":1646207368862,"mc":[{"id":"1.195453762","rc":[{"atl":[[13,8.33],[14,0]],"id":43167126}],"con":true,"img":false}]}
{"op":"mcm","clk":"5353037997","pt":1646207369070,"mc":[{"id":"1.195453762","rc":[{"atl":[[1000,1.67]],"id":43167126}],"con":true,"img":false}]}
{"op":"mcm","clk":"5353038013","pt":1646207369379,"mc":[{"id":"1.195453762","rc":[{"atl":[[1000,0.67]],"id":43167126}],"con":true,"img":false}]}
{"op":"mcm","clk":"5353038035","pt":1646207369740,"mc":[{"id":"1.195453762","rc":[{"atl":[[1000,0]],"id":43167126}],"con":true,"img":false}]}
{"op":"mcm","clk":"5353038043","pt":1646207369844,"mc":[{"id":"1.195453762","rc":[{"atl":[[10,0.67]],"id":43167126}],"con":true,"img":false}]}
{"op":"mcm","clk":"5353038905","pt":1646207387866,"mc":[{"id":"1.195453762","rc":[{"spn":47.0,"spf":"NaN","id":41017865},{"atb":[[5.1,0]],"id":43167126},{"spn":7.85,"spf":"NaN","id":43167126},{"spn":25.0,"spf":"NaN","id":42688789},{"spn":2.61,"spf":"NaN","id":43167124},{"atl":[[7,0]],"id":43167125},{"spn":5.4,"spf":"NaN","id":43167125}],"con":true,"img":false}]}
{"op":"mcm","clk":"5353038911","pt":1646207387967,"mc":[{"id":"1.195453762","rc":[{"atb":[[4.6,34.9]],"id":43167126},{"atl":[[7.2,10.09]],"id":43167125}],"con":true,"img":false}]}
{"op":"mcm","clk":"5353038935","pt":1646207388481,"mc":[{"id":"1.195453762","rc":[{"atl":[[6.8,0]],"id":43167125}],"con":true,"img":false}]}
{"op":"mcm","clk":"5353038938","pt":1646207388584,"mc":[{"id":"1.195453762","rc":[{"atl":[[7,1.2]],"id":43167125}],"con":true,"img":false}]}
{"op":"mcm","clk":"5353039611","pt":1646207402497,"mc":[{"id":"1.195453762","rc":[{"atb":[[5.6,0]],"id":43167126}],"con":true,"img":false}]}
{"op":"mcm","clk":"5353039616","pt":1646207402600,"mc":[{"id":"1.195453762","rc":[{"atb":[[5.1,14.27]],"id":43167126}],"con":true,"img":false}]}
{"op":"mcm","clk":"5353039622","pt":1646207402704,"mc":[{"id":"1.195453762","rc":[{"atl":[[3.3,0]],"id":43167124}],"con":true,"img":false}]}
{"op":"mcm","clk":"5353040257","pt":1646207417430,"mc":[{"id":"1.195453762","rc":[{"atl":[[13.5,0]],"id":43167126}],"con":true,"img":false}]}
{"op":"mcm","clk":"5353040262","pt":1646207417541,"mc":[{"id":"1.195453762","rc":[{"atl":[[12.5,9.47]],"id":43167126}],"con":true,"img":false}]}
{"op":"mcm","clk":"5353040631","pt":1646207425879,"mc":[{"id":"1.195453762","rc":[{"atb":[[5.7,0]],"id":43167126}],"con":true,"img":false}]}
{"op":"mcm","clk":"5353040644","pt":1646207426034,"mc":[{"id":"1.195453762","rc":[{"atl":[[3.2,33.1]],"id":43167124}],"con":true,"img":false}]}
{"op":"mcm","clk":"5353040688","pt":1646207427170,"mc":[{"id":"1.195453762","rc":[{"atl":[[3.1,0]],"id":43167124}],"con":true,"img":false}]}
{"op":"mcm","clk":"5353040721","pt":1646207427838,"mc":[{"id":"1.195453762","rc":[{"atl":[[3.05,0]],"id":43167124}],"con":true,"img":false}]}
{"op":"mcm","clk":"5353040726","pt":1646207427941,"mc":[{"id":"1.195453762","rc":[{"atl":[[3.1,1.31]],"id":43167124}],"con":true,"img":false}]}
{"op":"mcm","clk":"5353040785","pt":1646207430053,"mc":[{"id":"1.195453762","rc":[{"atl":[[3.1,6.16]],"id":43167124}],"con":true,"img":false}]}
{"op":"mcm","clk":"5353041109","pt":1646207438792,"mc":[{"id":"1.195453762","rc":[{"atb":[[5.6,2.19]],"id":43167126}],"con":true,"img":false}]}
{"op":"mcm","clk":"5353041112","pt":1646207438895,"mc":[{"id":"1.195453762","rc":[{"atl":[[3.15,31.32]],"id":43167124}],"con":true,"img":false}]}
{"op":"mcm","clk":"5353043044","pt":1646207493038,"mc":[{"id":"1.195453762","rc":[{"spn":7.8,"spf":"NaN","id":43167126},{"atb":[[10,0],[8.8,12.82]],"id":43167128},{"atb":[[1.48,206.06],[1.56,0]],"id":43167124},{"atl":[[3.35,42.55],[3.2,0]],"id":43167124},{"spn":2.64,"spf":"NaN","id":43167124},{"atb":[[3.45,99.77],[3.75,0]],"id":43167125},{"atl":[[9.2,0],[11,10]],"id":43167125},{"spn":5.5,"spf":"NaN","id":43167125}],"con":true,"img":false}]}
{"op":"mcm","clk":"5353043275","pt":1646207500481,"mc":[{"id":"1.195453762","rc":[{"atl":[[10,0]],"id":43167126}],"con":true,"img":false}]}
{"op":"mcm","clk":"5353043283","pt":1646207500642,"mc":[{"id":"1.195453762","rc":[{"atl":[[13,0],[14,7.69],[1000,1.67]],"id":43167126}],"con":true,"img":false}]}
{"op":"mcm","clk":"5353043294","pt":1646207500953,"mc":[{"id":"1.195453762","rc":[{"atl":[[1000,0.64]],"id":43167126}],"con":true,"img":false}]}
{"op":"mcm","clk":"5353043316","pt":1646207501360,"mc":[{"id":"1.195453762","rc":[{"atl":[[1000,0]],"id":43167126}],"con":true,"img":false}]}
{"op":"mcm","clk":"5353043322","pt":1646207501464,"mc":[{"id":"1.195453762","rc":[{"atl":[[10.5,0.64]],"id":43167126}],"con":true,"img":false}]}
{"op":"mcm","clk":"5353043748","pt":1646207518364,"mc":[{"id":"1.195453762","rc":[{"atl":[[12.5,0]],"id":43167126},{"atl":[[3.15,6.41]],"id":43167124},{"atb":[[3.8,0]],"id":43167125}],"con":true,"img":false}]}
{"op":"mcm","clk":"5353043756","pt":1646207518467,"mc":[{"id":"1.195453762","rc":[{"atl":[[13.5,9.47]],"id":43167126},{"atl":[[3.3,24.91]],"id":43167124},{"atb":[[3.7,24.39]],"id":43167125}],"con":true,"img":false}]}
{"op":"mcm","clk":"5353044824","pt":1646207547414,"mc":[{"id":"1.195453762","rc":[{"atl":[[3.1,1.31]],"id":43167124}],"con":true,"img":false}]}
{"op":"mcm","clk":"5353044916","pt":1646207550347,"mc":[{"id":"1.195453762","rc":[{"atl":[[3.25,4.62]],"id":43167124}],"con":true,"img":false}]}
{"op":"mcm","clk":"5353045132","pt":1646207554728,"mc":[{"id":"1.195453762","rc":[{"spn":8.05,"spf":"NaN","id":43167126},{"atl":[[3.15,0]],"id":43167124}],"con":true,"img":false}]}
{"op":"mcm","clk":"5353045156","pt":1646207555292,"mc":[{"id":"1.195453762","rc":[{"atl":[[3.1,0]],"id":43167124}],"con":true,"img":false}]}
{"op":"mcm","clk":"5353045158","pt":1646207555394,"mc":[{"id":"1.195453762","rc":[{"atl":[[3.2,1.31]],"id":43167124}],"con":true,"img":false}]}
{"op":"mcm","clk":"5353045445","pt":1646207563500,"mc":[{"id":"1.195453762","rc":[{"atl":[[3.3,31.03]],"id":43167124}],"con":true,"img":false}]}
{"op":"mcm","clk":"5353046306","pt":1646207589679,"mc":[{"id":"1.195453762","rc":[{"atb":[[1.03,2.87]],"id":37178159},{"atb":[[1.03,2.87]],"id":41017865},{"atb":[[1.02,3.17]],"id":43167126},{"atb":[[1.02,3.17]],"id":43167127},{"atb":[[1.02,2.95]],"id":43167128},{"atb":[[1.03,2.93]],"id":42688789},{"atb":[[1.02,4]],"id":43167124},{"atb":[[1.02,3.37]],"id":43167125}],"con":true,"img":false}]}
{"op":"mcm","clk":"5353046325","pt":1646207590195,"mc":[{"id":"1.195453762","rc":[{"atb":[[1.03,0.14]],"id":37178159},{"atb":[[1.03,0.14]],"id":41017865},{"atb":[[1.02,0.44]],"id":43167126},{"atb":[[1.02,0.44]],"id":43167127},{"atb":[[1.02,0.22]],"id":43167128},{"atb":[[1.03,0.2]],"id":42688789},{"atb":[[1.02,1.27]],"id":43167124},{"atb":[[1.02,0.64]],"id":43167125}],"con":true,"img":false}]}
{"op":"mcm","clk":"5353046345","pt":1646207590671,"mc":[{"id":"1.195453762","rc":[{"atb":[[1.03,0]],"id":37178159},{"atb":[[1.03,0]],"id":41017865},{"atb":[[1.02,0]],"id":43167126},{"atb":[[1.02,0]],"id":43167127},{"atb":[[1.02,0]],"id":43167128},{"atb":[[1.03,0]],"id":42688789},{"atb":[[1.02,0]],"id":43167124},{"atb":[[1.02,0]],"id":43167125}],"con":true,"img":false}]}
{"op":"mcm","clk":"5353046348","pt":1646207590776,"mc":[{"id":"1.195453762","rc":[{"atb":[[19,0.14]],"id":37178159},{"atb":[[19,5.87]],"id":41017865},{"atb":[[6.2,0.44]],"id":43167126},{"atb":[[6.2,0.44]],"id":43167127},{"atb":[[12.5,0.22]],"id":43167128},{"atb":[[13.5,1.01]],"id":42688789},{"atb":[[2.18,2.93]],"id":43167124},{"atb":[[4.3,0.64]],"id":43167125}],"con":true,"img":false}]}
{"op":"mcm","clk":"5353047241","pt":1646207613307,"mc":[{"id":"1.195453762","rc":[{"atl":[[13.5,17.47],[14,0]],"id":43167126},{"atl":[[3.35,0],[3.3,67.6]],"id":43167124}],"con":true,"img":false}]}
{"op":"mcm","clk":"5353048649","pt":1646207658741,"mc":[{"id":"1.195453762","rc":[{"spn":8.35,"spf":"NaN","id":43167126},{"spn":8.35,"spf":"NaN","id":43167127},{"atl":[[3,4.93]],"id":43167124},{"spn":2.59,"spf":"NaN","id":43167124},{"spn":5.65,"spf":"NaN","id":43167125}],"con":true,"img":false}]}
{"op":"mcm","clk":"5353048660","pt":1646207659151,"mc":[{"id":"1.195453762","rc":[{"atl":[[3.2,0]],"id":43167124}],"con":true,"img":false}]}
{"op":"mcm","clk":"5353048667","pt":1646207659254,"mc":[{"id":"1.195453762","rc":[{"atl":[[2.98,1.31]],"id":43167124}],"con":true,"img":false}]}
{"op":"mcm","clk":"5353048939","pt":1646207667729,"mc":[{"id":"1.195453762","rc":[{"atl":[[3.25,0]],"id":43167124}],"con":true,"img":false}]}
{"op":"mcm","clk":"5353049031","pt":1646207670549,"mc":[{"id":"1.195453762","rc":[{"atl":[[3.25,4.62]],"id":43167124}],"con":true,"img":false}]}
{"op":"mcm","clk":"5353049732","pt":1646207690562,"mc":[{"id":"1.195453762","rc":[{"atl":[[3.3,61.48]],"id":43167124}],"con":true,"img":false}]}
{"op":"mcm","clk":"5353050149","pt":1646207701767,"mc":[{"id":"1.195453762","rc":[{"atl":[[3.25,10.84]],"id":43167124}],"con":true,"img":false}]}
{"op":"mcm","clk":"5353053265","pt":1646207788026,"mc":[{"id":"1.195453762","rc":[{"atl":[[3.25,6.21]],"id":43167124},{"spn":2.58,"spf":"NaN","id":43167124}],"con":true,"img":false}]}
{"op":"mcm","clk":"5353053400","pt":1646207791015,"mc":[{"id":"1.195453762","rc":[{"atl":[[3.25,10.84]],"id":43167124}],"con":true,"img":false}]}
{"op":"mcm","clk":"5353054509","pt":1646207819746,"mc":[{"id":"1.195453762","rc":[{"atl":[[3.25,4.62]],"id":43167124}],"con":true,"img":false}]}
{"op":"mcm","clk":"5353054983","pt":1646207831734,"mc":[{"id":"1.195453762","rc":[{"atl":[[3.25,10.84]],"id":43167124}],"con":true,"img":false}]}
{"op":"mcm","clk":"5353056954","pt":1646207882994,"mc":[{"id":"1.195453762","rc":[{"atl":[[13.5,8],[14.5,0]],"id":43167127},{"atb":[[9.2,27.8],[10,5.56],[11,12.72],[9.6,8.72],[8.8,0]],"id":43167128},{"atl":[[150,1],[170,15.2],[190,1],[210,1.95]],"id":43167128},{"atl":[[46,4.94],[48,0]],"id":42688789},{"atb":[[3.35,31.91],[3.55,7.84],[3.25,55.56],[3.45,120.18]],"id":43167125},{"atl":[[8.2,17.36],[7.4,7.81],[7.8,11.03],[7,4.53]],"id":43167125}],"con":true,"img":false}]}
{"op":"mcm","clk":"5353056960","pt":1646207883099,"mc":[{"id":"1.195453762","rc":[{"atb":[[32,4.32],[25,5.21],[27,2.88],[29,1.79]],"id":37178159},{"atl":[[710,1],[730,1],[750,1],[770,1]],"id":37178159},{"atb":[[15.5,8.62],[16.5,11.48],[17.5,3.03],[18.5,1.14]],"id":41017865},{"atl":[[300,1],[320,1],[340,1],[90,2],[360,1],[100,0]],"id":41017865},{"atb":[[4.8,13.16],[4.4,36.76],[5,30.75],[4.6,55.73]],"id":43167126},{"atl":[[11,4.18],[12,4.55],[12.5,8.34],[13,6.25],[13.5,9.47],[14,9.62]],"id":43167126},{"atb":[[5.3,4.65],[4.9,19.23],[5.1,44.42],[4.7,33.78]],"id":43167127},{"atl":[[11,4.25],[12,4.55],[13,6.25],[14,19.7]],"id":43167127},{"atb":[[10,16.67]],"id":43167128},{"atb":[[4.3,22.73],[4.5,42.86],[4.1,40.32],[4.7,27.57]],"id":42688789},{"atl":[[34,1],[38,4.07],[42,1.83],[46,7.72]],"id":42688789},{"atb":[[1.78,25.64],[1.48,0],[1.76,65.79],[1.56,178.57],[1.72,173.61],[1.74,101.35]],"id":43167124},{"atl":[[3.1,9.52],[3.3,57.52],[3.2,22.73],[3.4,52.08],[3.15,36.57]],"id":43167124},{"atb":[[3.8,35.71],[3.45,79.36]],"id":43167125}],"con":true,"img":false}]}
{"op":"mcm","clk":"5353056973","pt":1646207883405,"mc":[{"id":"1.195453762","rc":[{"atl":[[3.55,7.84]],"id":43167124}],"con":true,"img":false}]}
{"op":"mcm","clk":"5353056978","pt":1646207883508,"mc":[{"id":"1.195453762","rc":[{"atb":[[32,3.32],[12.5,8.7],[17,0],[20,1.05],[25,0],[27,0],[29,0]],"id":37178159},{"atb":[[14.5,1.48],[17.5,0],[18.5,0]],"id":41017865},{"atb":[[4.8,5.26],[5,25.75]],"id":43167126},{"atl":[[34,1],[150,0]],"id":43167128},{"atb":[[4.8,5.26],[4.7,22.16]],"id":42688789},{"atl":[[3.1,0],[3.3,24.91],[3.2,0],[3.15,0]],"id":43167124}],"con":true,"img":false}]}
{"op":"mcm","clk":"5353056985","pt":1646207883712,"mc":[{"id":"1.195453762","rc":[{"atl":[[3.55,44.41]],"id":43167124}],"con":true,"img":false}]}
{"op":"mcm","clk":"5353057011","pt":1646207884227,"mc":[{"id":"1.195453762","rc":[{"atl":[[11,3.26]],"id":43167126},{"atl":[[11,3.33]],"id":43167127}],"con":true,"img":false}]}
{"op":"mcm","clk":"5353057014","pt":1646207884329,"mc":[{"id":"1.195453762","rc":[{"atl":[[1000,2.25]],"id":43167126},{"atl":[[1000,2.25]],"id":43167127}],"con":true,"img":false}]}
{"op":"mcm","clk":"5353057024","pt":1646207884535,"mc":[{"id":"1.195453762","rc":[{"atl":[[1000,0.96]],"id":43167127}],"con":true,"img":false}]}
{"op":"mcm","clk":"5353057029","pt":1646207884642,"mc":[{"id":"1.195453762","rc":[{"atl":[[1000,0.95]],"id":43167126}],"con":true,"img":false}]}
{"op":"mcm","clk":"5353057033","pt":1646207884690,"mc":[{"id":"1.195453762","rc":[{"atl":[[1000,0]],"id":43167127}],"con":true,"img":false}]}
{"op":"mcm","clk":"5353057040","pt":1646207884796,"mc":[{"id":"1.195453762","rc":[{"atl":[[10.5,1.6]],"id":43167127}],"con":true,"img":false}]}
{"op":"mcm","clk":"5353057047","pt":1646207885001,"mc":[{"id":"1.195453762","rc":[{"atl":[[1000,0]],"id":43167126}],"con":true,"img":false}]}
{"op":"mcm","clk":"5353057051","pt":1646207885101,"mc":[{"id":"1.195453762","rc":[{"atl":[[10.5,1.59]],"id":43167126}],"con":true,"img":false}]}
{"op":"mcm","clk":"5353057067","pt":1646207885410,"mc":[{"id":"1.195453762","rc":[{"atl":[[11,2]],"id":43167126},{"atl":[[11,2]],"id":43167127}],"con":true,"img":false}]}
{"op":"mcm","clk":"5353057074","pt":1646207885512,"mc":[{"id":"1.195453762","rc":[{"atl":[[10.5,2.86]],"id":43167126},{"atl":[[10.5,2.94]],"id":43167127}],"con":true,"img":false}]}
{"op":"mcm","clk":"5353057092","pt":1646207885923,"mc":[{"id":"1.195453762","rc":[{"atl":[[10.5,2.29]],"id":43167127}],"con":true,"img":false}]}
{"op":"mcm","clk":"5353057102","pt":1646207886128,"mc":[{"id":"1.195453762","rc":[{"atl":[[10.5,2.22]],"id":43167126}],"con":true,"img":false}]}
{"op":"mcm","clk":"5353057104","pt":1646207886231,"mc":[{"id":"1.195453762","rc":[{"atb":[[16.5,6.64]],"id":41017865},{"atl":[[1000,1.67]],"id":43167127},{"atl":[[3.4,0]],"id":43167124}],"con":true,"img":false}]}
{"op":"mcm","clk":"5353057115","pt":1646207886540,"mc":[{"id":"1.195453762","rc":[{"atl":[[1000,0.67]],"id":43167127}],"con":true,"img":false}]}
{"op":"mcm","clk":"5353057121","pt":1646207886590,"mc":[{"id":"1.195453762","rc":[{"atl":[[1000,1.67]],"id":43167126}],"con":true,"img":false}]}
{"op":"mcm","clk":"5353057130","pt":1646207886796,"mc":[{"id":"1.195453762","rc":[{"atl":[[1000,0]],"id":43167127}],"con":true,"img":false}]}
{"op":"mcm","clk":"5353057134","pt":1646207886897,"mc":[{"id":"1.195453762","rc":[{"atl":[[10,0.67]],"id":43167127}],"con":true,"img":false}]}
{"op":"mcm","clk":"5353057145","pt":1646207887204,"mc":[{"id":"1.195453762","rc":[{"atl":[[1000,0.67]],"id":43167126}],"con":true,"img":false}]}
{"op":"mcm","clk":"5353057166","pt":1646207887819,"mc":[{"id":"1.195453762","rc":[{"atl":[[1000,0]],"id":43167126}],"con":true,"img":false}]}
{"op":"mcm","clk":"5353057169","pt":1646207887922,"mc":[{"id":"1.195453762","rc":[{"atl":[[10,0.67]],"id":43167126}],"con":true,"img":false}]}
{"op":"mcm","clk":"5353057411","pt":1646207893437,"mc":[{"id":"1.195453762","rc":[{"atb":[[19,2.92]],"id":37178159}],"con":true,"img":false}]}
{"op":"mcm","clk":"5353057419","pt":1646207893542,"mc":[{"id":"1.195453762","rc":[{"atb":[[13.5,4],[15.5,0]],"id":41017865},{"atb":[[4.6,48.79]],"id":43167126},{"atl":[[38,1.35]],"id":43167128},{"atl":[[3.65,18.87]],"id":43167124}],"con":true,"img":false}]}
{"op":"mcm","clk":"5353057423","pt":1646207893645,"mc":[{"id":"1.195453762","rc":[{"atl":[[13,14.58]],"id":43167126},{"atl":[[7.2,13.32]],"id":43167125}],"con":true,"img":false}]}
{"op":"mcm","clk":"5353057430","pt":1646207893751,"mc":[{"id":"1.195453762","rc":[{"atl":[[12.5,0]],"id":43167126},{"atl":[[7,1.2]],"id":43167125}],"con":true,"img":false}]}
{"op":"mcm","clk":"5353057822","pt":1646207902121,"mc":[{"id":"1.195453762","rc":[{"atl":[[44,2.33],[46,5.5]],"id":42688789}],"con":true,"img":false}]}
{"op":"mcm","clk":"5353057826","pt":1646207902222,"mc":[{"id":"1.195453762","rc":[{"atl":[[85,2],[90,0]],"id":41017865},{"atb":[[3.85,26.39],[3.8,0]],"id":43167125}],"con":true,"img":false}]}
{"op":"mcm","clk":"5353057888","pt":1646207903550,"mc":[{"id":"1.195453762","rc":[{"atb":[[18,4.41]],"id":37178159},{"atb":[[12.5,6.52]],"id":41017865},{"atb":[[4.4,22.06]],"id":43167126},{"atl":[[170,14.2],[42,1.83],[190,0],[210,0.95]],"id":43167128},{"atl":[[3.75,27.27]],"id":43167124}],"con":true,"img":false}]}
{"op":"mcm","clk":"5353057891","pt":1646207903654,"mc":[{"id":"1.195453762","rc":[{"atl":[[7.6,7.58]],"id":43167125}],"con":true,"img":false}]}
{"op":"mcm","clk":"5353057952","pt":1646207905349,"mc":[{"id":"1.195453762","rc":[{"atl":[[75,0]],"id":41017865},{"atl":[[11.5,0]],"id":43167126},{"atb":[[3.7,0]],"id":43167125}],"con":true,"img":false}]}
{"op":"mcm","clk":"5353057955","pt":1646207905448,"mc":[{"id":"1.195453762","rc":[{"atl":[[70,3.98]],"id":41017865},{"atl":[[11,7.85]],"id":43167126},{"atb":[[3.9,59.92]],"id":43167125}],"con":true,"img":false}]}
{"op":"mcm","clk":"5353058067","pt":1646207908271,"mc":[{"id":"1.195453762","rc":[{"atl":[[3.25,6.21]],"id":43167124}],"con":true,"img":false}]}
{"op":"mcm","clk":"5353058077","pt":1646207908426,"mc":[{"id":"1.195453762","rc":[{"atl":[[38,2.57]],"id":43167128}],"con":true,"img":false}]}
{"op":"mcm","clk":"5353058168","pt":1646207911244,"mc":[{"id":"1.195453762","rc":[{"atl":[[3.25,10.84]],"id":43167124}],"con":true,"img":false}]}
{"op":"mcm","clk":"5353058287","pt":1646207913553,"mc":[{"id":"1.195453762","rc":[{"atb":[[17,7.81]],"id":37178159},{"atb":[[11.5,11.9]],"id":41017865},{"atb":[[4.2,39.06]],"id":43167126},{"atl":[[46,2.78]],"id":43167128},{"atl":[[3.85,43.86]],"id":43167124}],"con":true,"img":false}]}
{"op":"mcm","clk":"5353058293","pt":1646207913655,"mc":[{"id":"1.195453762","rc":[{"atl":[[8,10.71],[8.2,0],[7.4,0],[7.8,0]],"id":43167125}],"con":true,"img":false}]}
{"op":"mcm","clk":"5353058443","pt":1646207917453,"mc":[{"id":"1.195453762","rc":[{"atb":[[1.2,2.25]],"id":43167124}],"con":true,"img":false}]}
{"op":"mcm","clk":"5353058459","pt":1646207917867,"mc":[{"id":"1.195453762","rc":[{"atb":[[1.2,2.05]],"id":43167124}],"con":true,"img":false}]}
{"op":"mcm","clk":"5353058472","pt":1646207918178,"mc":[{"id":"1.195453762","rc":[{"atb":[[1.2,0]],"id":43167124}],"con":true,"img":false}]}
{"op":"mcm","clk":"5353058476","pt":1646207918279,"mc":[{"id":"1.195453762","rc":[{"atb":[[2.2,2.05]],"id":43167124}],"con":true,"img":false}]}
{"op":"mcm","clk":"5353058585","pt":1646207920480,"mc":[{"id":"1.195453762","rc":[{"atl":[[13.5,0]],"id":43167126}],"con":true,"img":false}]}
{"op":"mcm","clk":"5353058587","pt":1646207920582,"mc":[{"id":"1.195453762","rc":[{"atl":[[12.5,9.47]],"id":43167126}],"con":true,"img":false}]}
{"op":"mcm","clk":"5353058717","pt":1646207923675,"mc":[{"id":"1.195453762","rc":[{"atl":[[8.4,16.89]],"id":43167125}],"con":true,"img":false}]}
{"op":"mcm","clk":"5353058789","pt":1646207925372,"mc":[{"id":"1.195453762","rc":[{"atl":[[70,1.25],[95,0]],"id":41017865},{"atl":[[14,9.62]],"id":43167127},{"atl":[[46,2.78]],"id":42688789},{"atl":[[3.5,51.31],[4.2,0]],"id":43167124},{"atl":[[9,0]],"id":43167125}],"con":true,"img":false}]}
{"op":"mcm","clk":"5353058791","pt":1646207925475,"mc":[{"id":"1.195453762","rc":[{"atl":[[65,2.72],[80,2.78]],"id":41017865},{"atl":[[12.5,10.08]],"id":43167127},{"atl":[[40,2.72]],"id":42688789},{"atl":[[7.4,16.92]],"id":43167125}],"con":true,"img":false}]}
{"op":"mcm","clk":"5353058794","pt":1646207925577,"mc":[{"id":"1.195453762","rc":[{"atl":[[40,0]],"id":43167128}],"con":true,"img":false}]}
{"op":"mcm","clk":"5353058799","pt":1646207925682,"mc":[{"id":"1.195453762","rc":[{"atl":[[36,2.72]],"id":43167128}],"con":true,"img":false}]}
{"op":"mcm","clk":"5353058808","pt":1646207925889,"mc":[{"id":"1.195453762","rc":[{"atl":[[70,0]],"id":41017865},{"atl":[[38,1.35]],"id":43167128}],"con":true,"img":false}]}
{"op":"mcm","clk":"5353058814","pt":1646207925991,"mc":[{"id":"1.195453762","rc":[{"atl":[[60,1.25]],"id":41017865},{"atl":[[34,2.22]],"id":43167128}],"con":true,"img":false}]}
{"op":"mcm","clk":"5353058994","pt":1646207930385,"mc":[{"id":"1.195453762","rc":[{"atl":[[65,0]],"id":41017865}],"con":true,"img":false}]}
{"op":"mcm","clk":"5353059003","pt":1646207930487,"mc":[{"id":"1.195453762","rc":[{"atl":[[70,2.72]],"id":41017865}],"con":true,"img":false}]}
{"op":"mcm","clk":"5353059012","pt":1646207930690,"mc":[{"id":"1.195453762","rc":[{"atl":[[60,0]],"id":41017865}],"con":true,"img":false}]}
{"op":"mcm","clk":"5353059019","pt":1646207930796,"mc":[{"id":"1.195453762","rc":[{"atl":[[65,1.25]],"id":41017865}],"con":true,"img":false}]}
{"op":"mcm","clk":"5353059374","pt":1646207940399,"mc":[{"id":"1.195453762","rc":[{"atl":[[36,0]],"id":43167128}],"con":true,"img":false}]}
{"op":"mcm","clk":"5353059378","pt":1646207940498,"mc":[{"id":"1.195453762","rc":[{"atl":[[38,4.07]],"id":43167128}],"con":true,"img":false}]}
{"op":"mcm","clk":"5353059398","pt":1646207940913,"mc":[{"id":"1.195453762","rc":[{"atl":[[34,1]],"id":43167128}],"con":true,"img":false}]}
{"op":"mcm","clk":"5353059404","pt":1646207941011,"mc":[{"id":"1.195453762","rc":[{"atl":[[36,1.22]],"id":43167128}],"con":true,"img":false}]}
{"op":"mcm","clk":"5353059563","pt":1646207945016,"mc":[{"id":"1.195453762","rc":[{"spn":44.5,"spf":"NaN","id":41017865},{"spn":8.1,"spf":"NaN","id":43167126},{"spn":8.1,"spf":"NaN","id":43167127},{"atb":[[1.2,2.25]],"id":43167128},{"spn":24.0,"spf":"NaN","id":43167128},{"spn":24.0,"spf":"NaN","id":42688789},{"spn":2.59,"spf":"NaN","id":43167124}],"con":true,"img":false}]}
{"op":"mcm","clk":"5353059578","pt":1646207945321,"mc":[{"id":"1.195453762","rc":[{"atb":[[1.2,1.82]],"id":43167128}],"con":true,"img":false}]}
{"op":"mcm","clk":"5353059584","pt":1646207945378,"mc":[{"id":"1.195453762","rc":[{"atl":[[55,0]],"id":43167128}],"con":true,"img":false}]}
{"op":"mcm","clk":"5353059587","pt":1646207945478,"mc":[{"id":"1.195453762","rc":[{"atl":[[40,2.72]],"id":43167128}],"con":true,"img":false}]}
{"op":"mcm","clk":"5353059591","pt":1646207945579,"mc":[{"id":"1.195453762","rc":[{"atb":[[1.2,0]],"id":43167128}],"con":true,"img":false}]}
{"op":"mcm","clk":"5353059594","pt":1646207945683,"mc":[{"id":"1.195453762","rc":[{"atb":[[14,2.09]],"id":43167128}],"con":true,"img":false}]}
{"op":"mcm","clk":"5353059732","pt":1646207949997,"mc":[{"id":"1.195453762","rc":[{"atb":[[14,0.27]],"id":43167128}],"con":true,"img":false}]}
{"op":"mcm","clk":"5353059968","pt":1646207955427,"mc":[{"id":"1.195453762","rc":[{"atl":[[70,0]],"id":41017865}],"con":true,"img":false}]}
{"op":"mcm","clk":"5353059971","pt":1646207955530,"mc":[{"id":"1.195453762","rc":[{"atl":[[65,3.98]],"id":41017865}],"con":true,"img":false}]}
{"op":"mcm","clk":"5353060113","pt":1646207958122,"mc":[{"id":"1.195453762","rc":[{"atl":[[3.25,4.62]],"id":43167124}],"con":true,"img":false}]}
{"op":"mcm","clk":"5353060199","pt":1646207960330,"mc":[{"id":"1.195453762","rc":[{"atl":[[65,1.25]],"id":41017865}],"con":true,"img":false}]}
{"op":"mcm","clk":"5353060204","pt":1646207960434,"mc":[{"id":"1.195453762","rc":[{"atl":[[70,2.72]],"id":41017865}],"con":true,"img":false}]}
{"op":"mcm","clk":"5353060597","pt":1646207970149,"mc":[{"id":"1.195453762","rc":[{"atl":[[3.45,5.86]],"id":43167124}],"con":true,"img":false}]}
{"op":"mcm","clk":"5353061199","pt":1646207985329,"mc":[{"id":"1.195453762","rc":[{"atl":[[70,0]],"id":41017865}],"con":true,"img":false}]}
{"op":"mcm","clk":"5353061203","pt":1646207985430,"mc":[{"id":"1.195453762","rc":[{"atl":[[65,3.98]],"id":41017865}],"con":true,"img":false}]}
{"op":"mcm","clk":"5353061208","pt":1646207985634,"mc":[{"id":"1.195453762","rc":[{"atl":[[65,2.72]],"id":41017865}],"con":true,"img":false}]}
{"op":"mcm","clk":"5353061213","pt":1646207985741,"mc":[{"id":"1.195453762","rc":[{"atl":[[75,1.25]],"id":41017865}],"con":true,"img":false}]}
{"op":"mcm","clk":"5353061243","pt":1646207986254,"mc":[{"id":"1.195453762","rc":[{"atl":[[75,0]],"id":41017865}],"con":true,"img":false}]}
{"op":"mcm","clk":"5353061248","pt":1646207986354,"mc":[{"id":"1.195453762","rc":[{"atl":[[60,1.25]],"id":41017865}],"con":true,"img":false}]}
{"op":"mcm","clk":"5353061330","pt":1646207988867,"mc":[{"id":"1.195453762","rc":[{"atl":[[60,2.49]],"id":41017865}],"con":true,"img":false}]}
{"op":"mcm","clk":"5353061333","pt":1646207988970,"mc":[{"id":"1.195453762","rc":[{"atl":[[1000,1.24]],"id":43167124}],"con":true,"img":false}]}
{"op":"mcm","clk":"5353061337","pt":1646207989066,"mc":[{"id":"1.195453762","rc":[{"atl":[[1000,1.24]],"id":43167126},{"atl":[[1000,1.24]],"id":43167125}],"con":true,"img":false}]}
{"op":"mcm","clk":"5353061342","pt":1646207989170,"mc":[{"id":"1.195453762","rc":[{"atl":[[1000,1.24]],"id":43167127},{"atl":[[34,2.24]],"id":43167128},{"atl":[[1000,0]],"id":43167124}],"con":true,"img":false}]}
{"op":"mcm","clk":"5353061348","pt":1646207989271,"mc":[{"id":"1.195453762","rc":[{"atl":[[1000,0]],"id":43167126},{"atl":[[34,2.24]],"id":42688789},{"atl":[[2.98,2.55]],"id":43167124},{"atl":[[1000,0]],"id":43167125}],"con":true,"img":false}]}
{"op":"mcm","clk":"5353061354","pt":1646207989372,"mc":[{"id":"1.195453762","rc":[{"atl":[[330,1.24]],"id":37178159},{"atl":[[10,1.92]],"id":43167126},{"atl":[[7,2.44]],"id":43167125}],"con":true,"img":false}]}
{"op":"mcm","clk":"5353061358","pt":1646207989475,"mc":[{"id":"1.195453762","rc":[{"atl":[[1000,0]],"id":43167127},{"atl":[[36,0]],"id":43167128}],"con":true,"img":false}]}
{"op":"mcm","clk":"5353061362","pt":1646207989578,"mc":[{"id":"1.195453762","rc":[{"atl":[[10,1.92]],"id":43167127},{"atl":[[34,3.47]],"id":43167128}],"con":true,"img":false}]}
{"op":"mcm","clk":"5353061383","pt":1646207990041,"mc":[{"id":"1.195453762","rc":[{"atl":[[10.5,0.95]],"id":43167126},{"atl":[[10.5,0.96]],"id":43167127},{"atl":[[36,0]],"id":42688789}],"con":true,"img":false}]}
{"op":"mcm","clk":"5353061387","pt":1646207990147,"mc":[{"id":"1.195453762","rc":[{"atl":[[10,3.19]],"id":43167126},{"atl":[[10,3.25]],"id":43167127},{"atl":[[34,3.58]],"id":42688789}],"con":true,"img":false}]}
{"op":"mcm","clk":"5353061394","pt":1646207990352,"mc":[{"id":"1.195453762","rc":[{"atl":[[40,0]],"id":43167128}],"con":true,"img":false}]}
{"op":"mcm","clk":"5353061397","pt":1646207990451,"mc":[{"id":"1.195453762","rc":[{"atl":[[44,2.72]],"id":43167128}],"con":true,"img":false}]}
{"op":"mcm","clk":"5353061477","pt":1646207992352,"mc":[{"id":"1.195453762","rc":[{"atl":[[10.5,0]],"id":43167126}],"con":true,"img":false}]}
{"op":"mcm","clk":"5353061481","pt":1646207992455,"mc":[{"id":"1.195453762","rc":[{"atl":[[1000,2.25]],"id":43167126},{"atl":[[10.5,0]],"id":43167127}],"con":true,"img":false}]}
{"op":"mcm","clk":"5353061489","pt":1646207992556,"mc":[{"id":"1.195453762","rc":[{"atl":[[1000,1.02]],"id":43167126},{"atl":[[1000,2.25]],"id":43167127}],"con":true,"img":false}]}
{"op":"mcm","clk":"5353061500","pt":1646207992763,"mc":[{"id":"1.195453762","rc":[{"atl":[[1000,0]],"id":43167126},{"atl":[[1000,1.03]],"id":43167127}],"con":true,"img":false}]}
{"op":"mcm","clk":"5353061507","pt":1646207992864,"mc":[{"id":"1.195453762","rc":[{"atl":[[9.8,1.02]],"id":43167126}],"con":true,"img":false}]}
{"op":"mcm","clk":"5353061529","pt":1646207993171,"mc":[{"id":"1.195453762","rc":[{"atl":[[1000,0]],"id":43167127}],"con":true,"img":false}]}
{"op":"mcm","clk":"5353061534","pt":1646207993272,"mc":[{"id":"1.195453762","rc":[{"atl":[[9.8,1.03]],"id":43167127}],"con":true,"img":false}]}
{"op":"mcm","clk":"5353061588","pt":1646207994352,"mc":[{"id":"1.195453762","rc":[{"atl":[[10,2.51]],"id":43167126}],"con":true,"img":false}]}
{"op":"mcm","clk":"5353061596","pt":1646207994554,"mc":[{"id":"1.195453762","rc":[{"atl":[[1000,1.67]],"id":43167126}],"con":true,"img":false}]}
{"op":"mcm","clk":"5353061598","pt":1646207994756,"mc":[{"id":"1.195453762","rc":[{"atl":[[10,1.24]],"id":43167126},{"atl":[[10,2.58]],"id":43167127}],"con":true,"img":false}]}
{"op":"mcm","clk":"5353061605","pt":1646207994858,"mc":[{"id":"1.195453762","rc":[{"atl":[[10.5,1.26],[1000,0.7]],"id":43167126}],"con":true,"img":false}]}
{"op":"mcm","clk":"5353061616","pt":1646207995170,"mc":[{"id":"1.195453762","rc":[{"atl":[[1000,0]],"id":43167126},{"atl":[[1000,1.67]],"id":43167127}],"con":true,"img":false}]}
{"op":"mcm","clk":"5353061618","pt":1646207995270,"mc":[{"id":"1.195453762","rc":[{"atl":[[9.6,0.7]],"id":43167126}],"con":true,"img":false}]}
{"op":"mcm","clk":"5353061622","pt":1646207995373,"mc":[{"id":"1.195453762","rc":[{"atl":[[10,1.24]],"id":43167127}],"con":true,"img":false}]}
{"op":"mcm","clk":"5353061623","pt":1646207995471,"mc":[{"id":"1.195453762","rc":[{"atl":[[11,3.33]],"id":43167127}],"con":true,"img":false}]}
{"op":"mcm","clk":"5353061628","pt":1646207995677,"mc":[{"id":"1.195453762","rc":[{"atl":[[1000,0.69]],"id":43167127}],"con":true,"img":false}]}
{"op":"mcm","clk":"5353061642","pt":1646207995983,"mc":[{"id":"1.195453762","rc":[{"atl":[[1000,0]],"id":43167127}],"con":true,"img":false}]}
{"op":"mcm","clk":"5353061646","pt":1646207996086,"mc":[{"id":"1.195453762","rc":[{"atl":[[9.8,1.72]],"id":43167127}],"con":true,"img":false}]}
{"op":"mcm","clk":"5353061828","pt":1646208000395,"mc":[{"id":"1.195453762","rc":[{"atl":[[65,0]],"id":41017865}],"con":true,"img":false}]}
{"op":"mcm","clk":"5353061833","pt":1646208000499,"mc":[{"id":"1.195453762","rc":[{"atl":[[70,2.72]],"id":41017865}],"con":true,"img":false}]}
{"op":"mcm","clk":"5353061853","pt":1646208000766,"mc":[{"id":"1.195453762","rc":[{"atl":[[60,1.24]],"id":41017865}],"con":true,"img":false}]}
{"op":"mcm","clk":"5353061860","pt":1646208000874,"mc":[{"id":"1.195453762","rc":[{"atl":[[65,1.25]],"id":41017865}],"con":true,"img":false}]}
{"op":"mcm","clk":"5353061915","pt":1646208001659,"mc":[{"id":"1.195453762","rc":[{"atb":[[5.6,3.82]],"id":43167126},{"atb":[[5.7,3.64]],"id":43167127},{"atb":[[14,1.83]],"id":43167128},{"atb":[[13.5,2.6]],"id":42688789},{"atb":[[2.2,3.53]],"id":43167124},{"atb":[[4,2.49]],"id":43167125}],"con":true,"img":false}]}
{"op":"mcm","clk":"5353062218","pt":1646208005792,"mc":[{"id":"1.195453762","rc":[{"spn":195.0,"spf":"NaN","id":37178159},{"spn":42.0,"spf":"NaN","id":41017865},{"spn":7.9,"spf":"NaN","id":43167126},{"atl":[[9.8,1.03]],"id":43167127},{"spn":8.0,"spf":"NaN","id":43167127}],"con":true,"img":false}]}
{"op":"mcm","clk":"5353062229","pt":1646208005894,"mc":[{"id":"1.195453762","rc":[{"atb":[[5.6,1.62]],"id":43167126},{"atb":[[5.7,1.48]],"id":43167127}],"con":true,"img":false}]}
{"op":"mcm","clk":"5353062247","pt":1646208006097,"mc":[{"id":"1.195453762","rc":[{"atl":[[1000,1.67]],"id":43167127}],"con":true,"img":false}]}
{"op":"mcm","clk":"5353062274","pt":1646208006461,"mc":[{"id":"1.195453762","rc":[{"atl":[[1000,0.7]],"id":43167127}],"con":true,"img":false}]}
{"op":"mcm","clk":"5353062298","pt":1646208006982,"mc":[{"id":"1.195453762","rc":[{"atl":[[1000,0]],"id":43167127}],"con":true,"img":false}]}
{"op":"mcm","clk":"5353062304","pt":1646208007083,"mc":[{"id":"1.195453762","rc":[{"atl":[[9.6,0.7]],"id":43167127}],"con":true,"img":false}]}
{"op":"mcm","clk":"5353062464","pt":1646208010371,"mc":[{"id":"1.195453762","rc":[{"atl":[[340,4.72]],"id":37178159}],"con":true,"img":false}]}
{"op":"mcm","clk":"5353062470","pt":1646208010473,"mc":[{"id":"1.195453762","rc":[{"atl":[[320,0.17]],"id":37178159}],"con":true,"img":false}]}
{"op":"mcm","clk":"5353063228","pt":1646208023892,"mc":[{"id":"1.195453762","rc":[{"atl":[[10,0]],"id":43167126},{"atl":[[10,0]],"id":43167127}],"con":true,"img":false}]}
{"op":"mcm","clk":"5353063297","pt":1646208025332,"mc":[{"id":"1.195453762","rc":[{"atl":[[340,2]],"id":37178159}],"con":true,"img":false}]}
{"op":"mcm","clk":"5353063302","pt":1646208025389,"mc":[{"id":"1.195453762","rc":[{"atl":[[320,2.9]],"id":37178159}],"con":true,"img":false}]}
{"op":"mcm","clk":"5353063307","pt":1646208025493,"mc":[{"id":"1.195453762","rc":[{"atl":[[320,4.9]],"id":37178159}],"con":true,"img":false}]}
{"op":"mcm","clk":"5353063314","pt":1646208025598,"mc":[{"id":"1.195453762","rc":[{"atl":[[340,0]],"id":37178159}],"con":true,"img":false}]}
{"op":"mcm","clk":"5353063480","pt":1646208029543,"mc":[{"id":"1.195453762","rc":[{"atl":[[3.25,0]],"id":43167124}],"con":true,"img":false}]}
{"op":"mcm","clk":"5353063560","pt":1646208031541,"mc":[{"id":"1.195453762","rc":[{"atl":[[3.25,4.62]],"id":43167124}],"con":true,"img":false}]}
{"op":"mcm","clk":"5353064000","pt":1646208041644,"mc":[{"id":"1.195453762","rc":[{"atl":[[1000,1.24]],"id":43167126},{"atl":[[1000,1.24]],"id":43167127}],"con":true,"img":false}]}
{"op":"mcm","clk":"5353064010","pt":1646208041948,"mc":[{"id":"1.195453762","rc":[{"atl":[[1000,0]],"id":43167126},{"atl":[[1000,0]],"id":43167127}],"con":true,"img":false}]}
{"op":"mcm","clk":"5353064017","pt":1646208042050,"mc":[{"id":"1.195453762","rc":[{"atl":[[9.6,1.94]],"id":43167126},{"atl":[[9.6,1.95]],"id":43167127}],"con":true,"img":false}]}
{"op":"mcm","clk":"5353064281","pt":1646208048672,"mc":[{"id":"1.195453762","rc":[{"spl":[[1.01,30.02]],"id":37178159},{"spl":[[1.01,30.02]],"id":41017865},{"spl":[[1.01,30.02]],"id":43167126},{"spl":[[1.01,30.02]],"id":43167127},{"spl":[[1.01,30.02]],"id":43167128},{"spl":[[1.01,30.02]],"id":42688789},{"spl":[[1.01,30.02]],"id":43167124},{"spl":[[1.01,30.02]],"id":43167125}],"con":true,"img":false}]}
{"op":"mcm","clk":"5353064504","pt":1646208054363,"mc":[{"id":"1.195453762","rc":[{"atl":[[9.6,1.24]],"id":43167126}],"con":true,"img":false}]}
{"op":"mcm","clk":"5353064523","pt":1646208054669,"mc":[{"id":"1.195453762","rc":[{"atl":[[9.6,1.24]],"id":43167127}],"con":true,"img":false}]}
{"op":"mcm","clk":"5353064539","pt":1646208054979,"mc":[{"id":"1.195453762","rc":[{"atl":[[1000,1.67]],"id":43167126}],"con":true,"img":false}]}
{"op":"mcm","clk":"5353064556","pt":1646208055237,"mc":[{"id":"1.195453762","rc":[{"atl":[[1000,1.67]],"id":43167127}],"con":true,"img":false}]}
{"op":"mcm","clk":"5353064573","pt":1646208055646,"mc":[{"id":"1.195453762","rc":[{"atl":[[1000,0.71]],"id":43167126}],"con":true,"img":false}]}
{"op":"mcm","clk":"5353064594","pt":1646208056058,"mc":[{"id":"1.195453762","rc":[{"atl":[[1000,0.72]],"id":43167127}],"con":true,"img":false}]}
{"op":"mcm","clk":"5353064615","pt":1646208056468,"mc":[{"id":"1.195453762","rc":[{"atl":[[1000,0]],"id":43167126}],"con":true,"img":false}]}
{"op":"mcm","clk":"5353064621","pt":1646208056571,"mc":[{"id":"1.195453762","rc":[{"atl":[[9.4,0.71]],"id":43167126}],"con":true,"img":false}]}
{"op":"mcm","clk":"5353064633","pt":1646208056878,"mc":[{"id":"1.195453762","rc":[{"atl":[[1000,0]],"id":43167127}],"con":true,"img":false}]}
{"op":"mcm","clk":"5353064637","pt":1646208056979,"mc":[{"id":"1.195453762","rc":[{"atl":[[9.4,0.72]],"id":43167127}],"con":true,"img":false}]}
{"op":"mcm","clk":"5353065481","pt":1646208076702,"mc":[{"id":"1.195453762","rc":[{"spn":30.87,"spf":1.0,"id":37178159},{"spn":18.43,"spf":1.0,"id":41017865},{"atl":[[9.6,0]],"id":43167126},{"spn":5.44,"spf":1.0,"id":43167126},{"atl":[[9.6,0]],"id":43167127},{"spn":5.57,"spf":1.0,"id":43167127},{"spn":12.2,"spf":1.0,"id":43167128},{"spn":12.47,"spf":1.0,"id":42688789},{"spn":2.11,"spf":1.0,"id":43167124},{"spn":3.92,"spf":1.0,"id":43167125}],"con":true,"img":false}]}
{"op":"mcm","clk":"5353066247","pt":1646208093727,"mc":[{"id":"1.195453762","rc":[{"atl":[[3.45,0]],"id":43167124}],"con":true,"img":false}]}
{"op":"mcm","clk":"5353066592","pt":1646208102105,"mc":[{"id":"1.195453762","rc":[{"atl":[[3.45,5.86]],"id":43167124}],"con":true,"img":false}]}
{"op":"mcm","clk":"5353066776","pt":1646208106629,"mc":[{"id":"1.195453762","rc":[{"atl":[[9.8,0]],"id":43167126}],"con":true,"img":false}]}
{"op":"mcm","clk":"5353066779","pt":1646208106730,"mc":[{"id":"1.195453762","rc":[{"atl":[[1000,2.25]],"id":43167126}],"con":true,"img":false}]}
{"op":"mcm","clk":"5353066784","pt":1646208106938,"mc":[{"id":"1.195453762","rc":[{"atl":[[1000,0.95]],"id":43167126}],"con":true,"img":false}]}
{"op":"mcm","clk":"5353066791","pt":1646208107141,"mc":[{"id":"1.195453762","rc":[{"atl":[[1000,0]],"id":43167126}],"con":true,"img":false}]}
{"op":"mcm","clk":"5353066793","pt":1646208107244,"mc":[{"id":"1.195453762","rc":[{"atl":[[10.5,2.22]],"id":43167126}],"con":true,"img":false}]}
{"op":"mcm","clk":"5353066852","pt":1646208109245,"mc":[{"id":"1.195453762","rc":[{"atb":[[5.2,5.64]],"id":43167126}],"con":true,"img":false}]}
{"op":"mcm","clk":"5353066864","pt":1646208109653,"mc":[{"id":"1.195453762","rc":[{"atl":[[9.8,0]],"id":43167127}],"con":true,"img":false}]}
{"op":"mcm","clk":"5353066870","pt":1646208109755,"mc":[{"id":"1.195453762","rc":[{"atl":[[1000,2.25]],"id":43167127}],"con":true,"img":false}]}
{"op":"mcm","clk":"5353066879","pt":1646208109913,"mc":[{"id":"1.195453762","rc":[{"atl":[[1000,0.96]],"id":43167127}],"con":true,"img":false}]}
{"op":"mcm","clk":"5353066887","pt":1646208110221,"mc":[{"id":"1.195453762","rc":[{"atl":[[1000,0]],"id":43167127}],"con":true,"img":false}]}
{"op":"mcm","clk":"5353066892","pt":1646208110323,"mc":[{"id":"1.195453762","rc":[{"atl":[[10.5,0.96]],"id":43167127}],"con":true,"img":false}]}
{"op":"mcm","clk":"5353066907","pt":1646208110735,"mc":[{"id":"1.195453762","rc":[{"atl":[[11,2]],"id":43167127}],"con":true,"img":false}]}
{"op":"mcm","clk":"5353066910","pt":1646208110836,"mc":[{"id":"1.195453762","rc":[{"atl":[[10.5,2.29]],"id":43167127}],"con":true,"img":false}]}
{"op":"mcm","clk":"5353066940","pt":1646208111654,"mc":[{"id":"1.195453762","rc":[{"atl":[[1000,1.24]],"id":43167126}],"con":true,"img":false}]}
{"op":"mcm","clk":"5353066945","pt":1646208111757,"mc":[{"id":"1.195453762","rc":[{"atl":[[1000,1.24]],"id":43167127}],"con":true,"img":false}]}
{"op":"mcm","clk":"5353066949","pt":1646208111910,"mc":[{"id":"1.195453762","rc":[{"atl":[[1000,0]],"id":43167126}],"con":true,"img":false}]}
{"op":"mcm","clk":"5353066951","pt":1646208112015,"mc":[{"id":"1.195453762","rc":[{"atl":[[10,1.24]],"id":43167126},{"atl":[[1000,0]],"id":43167127}],"con":true,"img":false}]}
{"op":"mcm","clk":"5353066956","pt":1646208112119,"mc":[{"id":"1.195453762","rc":[{"atl":[[10,1.24]],"id":43167127}],"con":true,"img":false}]}
{"op":"mcm","clk":"5353066974","pt":1646208112528,"mc":[{"id":"1.195453762","rc":[{"atl":[[10.5,0.96]],"id":43167127}],"con":true,"img":false}]}
{"op":"mcm","clk":"5353066979","pt":1646208112635,"mc":[{"id":"1.195453762","rc":[{"atl":[[10,2.58]],"id":43167127}],"con":true,"img":false}]}
{"op":"mcm","clk":"5353067108","pt":1646208115719,"mc":[{"id":"1.195453762","rc":[{"atl":[[10.5,0]],"id":43167127}],"con":true,"img":false}]}
{"op":"mcm","clk":"5353067115","pt":1646208115821,"mc":[{"id":"1.195453762","rc":[{"atl":[[1000,2.25]],"id":43167127}],"con":true,"img":false}]}
{"op":"mcm","clk":"5353067122","pt":1646208116025,"mc":[{"id":"1.195453762","rc":[{"atl":[[1000,1.03]],"id":43167127}],"con":true,"img":false}]}
{"op":"mcm","clk":"5353067134","pt":1646208116231,"mc":[{"id":"1.195453762","rc":[{"atl":[[1000,0]],"id":43167127}],"con":true,"img":false}]}
{"op":"mcm","clk":"5353067137","pt":1646208116335,"mc":[{"id":"1.195453762","rc":[{"atl":[[9.8,1.03]],"id":43167127}],"con":true,"img":false}]}
{"op":"mcm","clk":"5353068484","pt":1646208146766,"mc":[{"id":"1.195453762","rc":[{"spn":5.46,"spf":1.0,"id":43167126},{"atl":[[10,1.33]],"id":43167127}],"con":true,"img":false}]}
{"op":"mcm","clk":"5353068553","pt":1646208148674,"mc":[{"id":"1.195453762","rc":[{"atl":[[3.25,0]],"id":43167124}],"con":true,"img":false}]}
{"op":"mcm","clk":"5353068678","pt":1646208151708,"mc":[{"id":"1.195453762","rc":[{"atl":[[3.25,4.62]],"id":43167124}],"con":true,"img":false}]}
{"op":"mcm","clk":"5353069273","pt":1646208164204,"mc":[{"id":"1.195453762","rc":[{"atl":[[1000,1.24]],"id":43167127}],"con":true,"img":false}]}
{"op":"mcm","clk":"5353069284","pt":1646208164515,"mc":[{"id":"1.195453762","rc":[{"atl":[[1000,0]],"id":43167127}],"con":true,"img":false}]}
{"op":"mcm","clk":"5353069288","pt":1646208164617,"mc":[{"id":"1.195453762","rc":[{"atl":[[9.6,1.24]],"id":43167127}],"con":true,"img":false}]}
{"op":"mcm","clk":"5353070995","pt":1646208200460,"mc":[{"id":"1.195453762","rc":[{"atl":[[44,0]],"id":43167128}],"con":true,"img":false}]}
{"op":"mcm","clk":"5353071006","pt":1646208200563,"mc":[{"id":"1.195453762","rc":[{"atl":[[40,2.72]],"id":43167128}],"con":true,"img":false}]}
{"op":"mcm","clk":"5353071165","pt":1646208204161,"mc":[{"id":"1.195453762","rc":[{"atl":[[10.5,0.95]],"id":43167126}],"con":true,"img":false}]}
{"op":"mcm","clk":"5353071171","pt":1646208204264,"mc":[{"id":"1.195453762","rc":[{"atl":[[10,2.51]],"id":43167126}],"con":true,"img":false}]}
{"op":"mcm","clk":"5353071246","pt":1646208205858,"mc":[{"id":"1.195453762","rc":[{"atl":[[10.5,0]],"id":43167126}],"con":true,"img":false}]}
{"op":"mcm","clk":"5353071257","pt":1646208206060,"mc":[{"id":"1.195453762","rc":[{"atl":[[1000,2.25]],"id":43167126}],"con":true,"img":false}]}
{"op":"mcm","clk":"5353071265","pt":1646208206162,"mc":[{"id":"1.195453762","rc":[{"atl":[[1000,1.02]],"id":43167126}],"con":true,"img":false}]}
{"op":"mcm","clk":"5353071277","pt":1646208206367,"mc":[{"id":"1.195453762","rc":[{"atl":[[1000,0]],"id":43167126}],"con":true,"img":false}]}
{"op":"mcm","clk":"5353071282","pt":1646208206469,"mc":[{"id":"1.195453762","rc":[{"atl":[[9.8,1.02]],"id":43167126}],"con":true,"img":false}]}
{"op":"mcm","clk":"5353071687","pt":1646208216685,"mc":[{"id":"1.195453762","rc":[{"atl":[[10,1.26]],"id":43167126}],"con":true,"img":false}]}
{"op":"mcm","clk":"5353071947","pt":1646208222388,"mc":[{"id":"1.195453762","rc":[{"atb":[[10.5,0],[8.6,13.16]],"id":41017865},{"atb":[[8,14.29],[10,5.56]],"id":43167128},{"atb":[[1.45,202.7],[1.56,0]],"id":43167124},{"atb":[[3.85,2],[3.55,47.06]],"id":43167125}],"con":true,"img":false}]}
{"op":"mcm","clk":"5353072291","pt":1646208230401,"mc":[{"id":"1.195453762","rc":[{"atb":[[3.9,35.52]],"id":43167125}],"con":true,"img":false}]}
{"op":"mcm","clk":"5353072294","pt":1646208230499,"mc":[{"id":"1.195453762","rc":[{"atb":[[3.7,24.39]],"id":43167125}],"con":true,"img":false}]}
{"op":"mcm","clk":"5353072452","pt":1646208234203,"mc":[{"id":"1.195453762","rc":[{"atl":[[1000,1.24]],"id":43167126}],"con":true,"img":false}]}
{"op":"mcm","clk":"5353072467","pt":1646208234511,"mc":[{"id":"1.195453762","rc":[{"atl":[[1000,0]],"id":43167126}],"con":true,"img":false}]}
{"op":"mcm","clk":"5353072473","pt":1646208234613,"mc":[{"id":"1.195453762","rc":[{"atl":[[9.6,1.24]],"id":43167126}],"con":true,"img":false}]}
{"op":"mcm","clk":"5353072954","pt":1646208244077,"mc":[{"id":"1.195453762","rc":[{"atb":[[5.7,2.5]],"id":43167126},{"atb":[[5.9,2.5]],"id":43167127},{"atb":[[14.5,2.08]],"id":43167128},{"atb":[[14,2.35]],"id":42688789},{"atb":[[2.22,2.5]],"id":43167124},{"atb":[[4.1,2.5]],"id":43167125}],"con":true,"img":false}]}
{"op":"mcm","clk":"5353072962","pt":1646208244284,"mc":[{"id":"1.195453762","rc":[{"atb":[[10,11.11],[8.6,0]],"id":41017865},{"atb":[[8,0],[9.4,11.9]],"id":43167128},{"atb":[[1.45,0],[1.53,177.94]],"id":43167124},{"atb":[[3.85,26.39],[3.55,7.84]],"id":43167125}],"con":true,"img":false}]}
{"op":"mcm","clk":"5353072985","pt":1646208244900,"mc":[{"id":"1.195453762","rc":[{"atb":[[5.6,0]],"id":43167126},{"atb":[[14,0.27]],"id":43167128},{"atb":[[13.5,1.01]],"id":42688789},{"atb":[[2.2,2.05]],"id":43167124},{"atb":[[4,0.94]],"id":43167125}],"con":true,"img":false}]}
{"op":"mcm","clk":"5353072989","pt":1646208245002,"mc":[{"id":"1.195453762","rc":[{"atb":[[5.8,1.62]],"id":43167126},{"atb":[[14.5,3.64]],"id":43167128},{"atb":[[14,3.94]],"id":42688789},{"atb":[[2.22,3.98]],"id":43167124},{"atb":[[4.2,1.55]],"id":43167125}],"con":true,"img":false}]}
{"op":"mcm","clk":"5353073075","pt":1646208247108,"mc":[{"id":"1.195453762","rc":[{"atb":[[5.7,0]],"id":43167126},{"atb":[[4.1,0]],"id":43167125}],"con":true,"img":false}]}
{"op":"mcm","clk":"5353073104","pt":1646208247725,"mc":[{"id":"1.195453762","rc":[{"atb":[[5.8,0]],"id":43167126},{"atb":[[4.2,0]],"id":43167125}],"con":true,"img":false}]}
{"op":"mcm","clk":"5353073110","pt":1646208247831,"mc":[{"id":"1.195453762","rc":[{"atb":[[5.6,1.62]],"id":43167126},{"atb":[[4,2.49]],"id":43167125}],"con":true,"img":false}]}
{"op":"mcm","clk":"5353073174","pt":1646208249010,"mc":[{"id":"1.195453762","rc":[{"atb":[[5.2,0]],"id":43167126},{"atb":[[2.2,0]],"id":43167124}],"con":true,"img":false}]}
{"op":"mcm","clk":"5353073195","pt":1646208249423,"mc":[{"id":"1.195453762","rc":[{"atb":[[5.7,2.5]],"id":43167126},{"atb":[[4.1,2.5]],"id":43167125}],"con":true,"img":false}]}
{"op":"mcm","clk":"5353073245","pt":1646208250499,"mc":[{"id":"1.195453762","rc":[{"atb":[[5.6,0]],"id":43167126},{"atb":[[4,0.94]],"id":43167125}],"con":true,"img":false}]}
{"op":"mcm","clk":"5353073249","pt":1646208250602,"mc":[{"id":"1.195453762","rc":[{"atb":[[5.8,1.62]],"id":43167126},{"atb":[[4.2,1.55]],"id":43167125}],"con":true,"img":false}]}
{"op":"mcm","clk":"5353073309","pt":1646208252043,"mc":[{"id":"1.195453762","rc":[{"atb":[[5.7,0]],"id":43167126},{"atb":[[4.1,0]],"id":43167125}],"con":true,"img":false}]}
{"op":"mcm","clk":"5353073331","pt":1646208252405,"mc":[{"id":"1.195453762","rc":[{"atb":[[5.8,0]],"id":43167126},{"atb":[[4.2,0]],"id":43167125}],"con":true,"img":false}]}
{"op":"mcm","clk":"5353073338","pt":1646208252509,"mc":[{"id":"1.195453762","rc":[{"atb":[[5.6,1.62]],"id":43167126},{"atb":[[4,2.49]],"id":43167125}],"con":true,"img":false}]}
{"op":"mcm","clk":"5353073360","pt":1646208253023,"mc":[{"id":"1.195453762","rc":[{"atb":[[5.7,2.5]],"id":43167126},{"atb":[[4.1,2.5]],"id":43167125}],"con":true,"img":false}]}
{"op":"mcm","clk":"5353073386","pt":1646208253742,"mc":[{"id":"1.195453762","rc":[{"atb":[[2.24,2.78]],"id":43167124}],"con":true,"img":false}]}
{"op":"mcm","clk":"5353073407","pt":1646208254205,"mc":[{"id":"1.195453762","rc":[{"atb":[[2.22,2.5]],"id":43167124}],"con":true,"img":false}]}
{"op":"mcm","clk":"5353073415","pt":1646208254309,"mc":[{"id":"1.195453762","rc":[{"atb":[[2.24,4.26]],"id":43167124}],"con":true,"img":false}]}
{"op":"mcm","clk":"5353073440","pt":1646208254723,"mc":[{"id":"1.195453762","rc":[{"atb":[[2.22,0]],"id":43167124}],"con":true,"img":false}]}
{"op":"mcm","clk":"5353073485","pt":1646208255647,"mc":[{"id":"1.195453762","rc":[{"atb":[[2.26,2.5]],"id":43167124}],"con":true,"img":false}]}
{"op":"mcm","clk":"5353073500","pt":1646208255806,"mc":[{"id":"1.195453762","rc":[{"atl":[[80,4.78]],"id":41017865},{"atl":[[42,4.27]],"id":42688789}],"con":true,"img":false}]}
{"op":"mcm","clk":"5353073506","pt":1646208255907,"mc":[{"id":"1.195453762","rc":[{"atl":[[85,0]],"id":41017865},{"atl":[[44,0]],"id":42688789}],"con":true,"img":false}]}
{"op":"mcm","clk":"5353073513","pt":1646208256112,"mc":[{"id":"1.195453762","rc":[{"atb":[[2.24,2.78]],"id":43167124}],"con":true,"img":false}]}
{"op":"mcm","clk":"5353073516","pt":1646208256214,"mc":[{"id":"1.195453762","rc":[{"atb":[[2.26,3.98]],"id":43167124}],"con":true,"img":false}]}
{"op":"mcm","clk":"5353073609","pt":1646208258323,"mc":[{"id":"1.195453762","rc":[{"atb":[[2.24,0]],"id":43167124}],"con":true,"img":false}]}
{"op":"mcm","clk":"5353073641","pt":1646208258941,"mc":[{"id":"1.195453762","rc":[{"atb":[[2.26,2.5]],"id":43167124}],"con":true,"img":false}]}
{"op":"mcm","clk":"5353073645","pt":1646208259044,"mc":[{"id":"1.195453762","rc":[{"atb":[[1.01,1.47]],"id":43167124}],"con":true,"img":false}]}
{"op":"mcm","clk":"5353073694","pt":1646208259925,"mc":[{"id":"1.195453762","rc":[{"atl":[[9.8,0]],"id":43167127}],"con":true,"img":false}]}
{"op":"mcm","clk":"5353073707","pt":1646208260127,"mc":[{"id":"1.195453762","rc":[{"atl":[[1000,2.25]],"id":43167127}],"con":true,"img":false}]}
{"op":"mcm","clk":"5353073716","pt":1646208260230,"mc":[{"id":"1.195453762","rc":[{"atl":[[1000,0.91]],"id":43167127}],"con":true,"img":false}]}
{"op":"mcm","clk":"5353073725","pt":1646208260434,"mc":[{"id":"1.195453762","rc":[{"atl":[[1000,0]],"id":43167127}],"con":true,"img":false}]}
{"op":"mcm","clk":"5353073733","pt":1646208260540,"mc":[{"id":"1.195453762","rc":[{"atl":[[11,2.91]],"id":43167127}],"con":true,"img":false}]}
{"op":"mcm","clk":"5353073824","pt":1646208262139,"mc":[{"id":"1.195453762","rc":[{"atl":[[3.45,0]],"id":43167124}],"con":true,"img":false}]}
{"op":"mcm","clk":"5353073878","pt":1646208263014,"mc":[{"id":"1.195453762","rc":[{"atb":[[2.2,2.75]],"id":43167124}],"con":true,"img":false}]}
{"op":"mcm","clk":"5353073910","pt":1646208263527,"mc":[{"id":"1.195453762","rc":[{"atb":[[1.01,0]],"id":43167124}],"con":true,"img":false}]}
{"op":"mcm","clk":"5353073915","pt":1646208263627,"mc":[{"id":"1.195453762","rc":[{"atb":[[2.26,3.98]],"id":43167124}],"con":true,"img":false}]}
{"op":"mcm","clk":"5353074005","pt":1646208265429,"mc":[{"id":"1.195453762","rc":[{"atl":[[40,0]],"id":43167128},{"atb":[[3.7,0]],"id":43167125}],"con":true,"img":false}]}
{"op":"mcm","clk":"5353074011","pt":1646208265534,"mc":[{"id":"1.195453762","rc":[{"atl":[[44,2.72]],"id":43167128},{"atb":[[3.9,59.92]],"id":43167125}],"con":true,"img":false}]}
{"op":"mcm","clk":"5353074207","pt":1646208268936,"mc":[{"id":"1.195453762","rc":[{"atl":[[3.25,0]],"id":43167124}],"con":true,"img":false}]}
{"op":"mcm","clk":"5353074221","pt":1646208269246,"mc":[{"id":"1.195453762","rc":[{"atl":[[9.6,0]],"id":43167127}],"con":true,"img":false}]}
{"op":"mcm","clk":"5353074253","pt":1646208269961,"mc":[{"id":"1.195453762","rc":[{"atl":[[10,0]],"id":43167127}],"con":true,"img":false}]}
{"op":"mcm","clk":"5353074259","pt":1646208270019,"mc":[{"id":"1.195453762","rc":[{"atl":[[10.5,1.33]],"id":43167127}],"con":true,"img":false}]}
{"op":"mcm","clk":"5353074345","pt":1646208271859,"mc":[{"id":"1.195453762","rc":[{"atl":[[3.25,4.62]],"id":43167124}],"con":true,"img":false}]}
{"op":"mcm","clk":"5353074750","pt":1646208280455,"mc":[{"id":"1.195453762","rc":[{"spn":5.49,"spf":1.0,"id":43167126},{"atl":[[9.4,0]],"id":43167127},{"spn":5.6,"spf":1.0,"id":43167127},{"spn":12.49,"spf":1.0,"id":43167128},{"spn":12.67,"spf":1.0,"id":42688789},{"spn":2.13,"spf":1.0,"id":43167124},{"spn":3.94,"spf":1.0,"id":43167125}],"con":true,"img":false}]}
{"op":"mcm","clk":"5353074754","pt":1646208280557,"mc":[{"id":"1.195453762","rc":[{"atl":[[3.45,5.86]],"id":43167124}],"con":true,"img":false}]}
{"op":"mcm","clk":"5353074779","pt":1646208280963,"mc":[{"id":"1.195453762","rc":[{"atl":[[1000,1.67]],"id":43167127}],"con":true,"img":false}]}
{"op":"mcm","clk":"5353074796","pt":1646208281277,"mc":[{"id":"1.195453762","rc":[{"atl":[[1000,0.68]],"id":43167127}],"con":true,"img":false}]}
{"op":"mcm","clk":"5353074813","pt":1646208281577,"mc":[{"id":"1.195453762","rc":[{"atl":[[1000,0]],"id":43167127}],"con":true,"img":false}]}
{"op":"mcm","clk":"5353074819","pt":1646208281679,"mc":[{"id":"1.195453762","rc":[{"atl":[[10,0.68]],"id":43167127}],"con":true,"img":false}]}
{"op":"mcm","clk":"5353075080","pt":1646208286664,"mc":[{"id":"1.195453762","rc":[{"atl":[[1000,1.24]],"id":43167127}],"con":true,"img":false}]}
{"op":"mcm","clk":"5353075089","pt":1646208286866,"mc":[{"id":"1.195453762","rc":[{"atl":[[1000,0]],"id":43167127}],"con":true,"img":false}]}
{"op":"mcm","clk":"5353075096","pt":1646208286969,"mc":[{"id":"1.195453762","rc":[{"atl":[[10,1.92]],"id":43167127}],"con":true,"img":false}]}
{"op":"mcm","clk":"5353075326","pt":1646208292088,"mc":[{"id":"1.195453762","rc":[{"atl":[[10,1.24]],"id":43167127}],"con":true,"img":false}]}
{"op":"mcm","clk":"5353075333","pt":1646208292250,"mc":[{"id":"1.195453762","rc":[{"atl":[[1000,1.67]],"id":43167127}],"con":true,"img":false}]}
{"op":"mcm","clk":"5353075351","pt":1646208292661,"mc":[{"id":"1.195453762","rc":[{"atl":[[1000,0.7]],"id":43167127}],"con":true,"img":false}]}
{"op":"mcm","clk":"5353075368","pt":1646208292969,"mc":[{"id":"1.195453762","rc":[{"atl":[[1000,0]],"id":43167127}],"con":true,"img":false}]}
{"op":"mcm","clk":"5353075376","pt":1646208293071,"mc":[{"id":"1.195453762","rc":[{"atl":[[9.8,0.7]],"id":43167127}],"con":true,"img":false}]}
{"op":"mcm","clk":"5353075583","pt":1646208297997,"mc":[{"id":"1.195453762","rc":[{"atl":[[10.5,0]],"id":43167127}],"con":true,"img":false}]}
{"op":"mcm","clk":"5353075589","pt":1646208298055,"mc":[{"id":"1.195453762","rc":[{"atl":[[10,2.58]],"id":43167127}],"con":true,"img":false}]}
{"op":"mcm","clk":"5353075628","pt":1646208298982,"mc":[{"id":"1.195453762","rc":[{"atl":[[11,2]],"id":43167127}],"con":true,"img":false}]}
{"op":"mcm","clk":"5353075636","pt":1646208299186,"mc":[{"id":"1.195453762","rc":[{"atl":[[1000,2.25]],"id":43167127}],"con":true,"img":false}]}
{"op":"mcm","clk":"5353075646","pt":1646208299390,"mc":[{"id":"1.195453762","rc":[{"atl":[[1000,1.03]],"id":43167127}],"con":true,"img":false}]}
{"op":"mcm","clk":"5353075653","pt":1646208299594,"mc":[{"id":"1.195453762","rc":[{"atl":[[1000,0]],"id":43167127}],"con":true,"img":false}]}
{"op":"mcm","clk":"5353075657","pt":1646208299697,"mc":[{"id":"1.195453762","rc":[{"atl":[[9.8,1.73]],"id":43167127}],"con":true,"img":false}]}
{"op":"mcm","clk":"5353075880","pt":1646208303996,"mc":[{"id":"1.195453762","rc":[{"atl":[[9.8,1.03]],"id":43167127}],"con":true,"img":false}]}
{"op":"mcm","clk":"5353075895","pt":1646208304256,"mc":[{"id":"1.195453762","rc":[{"atl":[[1000,1.67]],"id":43167127}],"con":true,"img":false}]}
{"op":"mcm","clk":"5353075909","pt":1646208304469,"mc":[{"id":"1.195453762","rc":[{"atl":[[10,1.24]],"id":43167127}],"con":true,"img":false}]}
{"op":"mcm","clk":"5353075915","pt":1646208304574,"mc":[{"id":"1.195453762","rc":[{"atl":[[11,3.33],[1000,0.71]],"id":43167127}],"con":true,"img":false}]}
{"op":"mcm","clk":"5353075929","pt":1646208304885,"mc":[{"id":"1.195453762","rc":[{"atl":[[1000,0]],"id":43167127}],"con":true,"img":false}]}
{"op":"mcm","clk":"5353075933","pt":1646208304988,"mc":[{"id":"1.195453762","rc":[{"atl":[[9.6,0.71]],"id":43167127}],"con":true,"img":false}]}
{"op":"mcm","clk":"5353076408","pt":1646208315496,"mc":[{"id":"1.195453762","rc":[{"atl":[[2.96,2.5]],"id":43167124},{"atl":[[6.8,2.5]],"id":43167125}],"con":true,"img":false}]}
{"op":"mcm","clk":"5353076424","pt":1646208315908,"mc":[{"id":"1.195453762","rc":[{"atl":[[2.98,1.24]],"id":43167124},{"atl":[[7,1.24]],"id":43167125}],"con":true,"img":false}]}
{"op":"mcm","clk":"5353076430","pt":1646208315968,"mc":[{"id":"1.195453762","rc":[{"atl":[[2.94,1.31]],"id":43167124},{"atl":[[6.6,1.2]],"id":43167125}],"con":true,"img":false}]}
{"op":"mcm","clk":"5353076475","pt":1646208316891,"mc":[{"id":"1.195453762","rc":[{"atl":[[2.96,0]],"id":43167124},{"atl":[[6.8,0]],"id":43167125}],"con":true,"img":false}]}
{"op":"mcm","clk":"5353076514","pt":1646208317711,"mc":[{"id":"1.195453762","rc":[{"atl":[[2.94,0]],"id":43167124},{"atl":[[6.6,0]],"id":43167125}],"con":true,"img":false}]}
{"op":"mcm","clk":"5353076518","pt":1646208317815,"mc":[{"id":"1.195453762","rc":[{"atl":[[2.98,2.55]],"id":43167124},{"atl":[[7,2.44]],"id":43167125}],"con":true,"img":false}]}
{"op":"mcm","clk":"5353076712","pt":1646208321712,"mc":[{"id":"1.195453762","rc":[{"atl":[[10,0]],"id":43167127}],"con":true,"img":false}]}
{"op":"mcm","clk":"5353076956","pt":1646208327011,"mc":[{"id":"1.195453762","rc":[{"atb":[[1.03,2.25]],"id":43167128}],"con":true,"img":false}]}
{"op":"mcm","clk":"5353076960","pt":1646208327115,"mc":[{"id":"1.195453762","rc":[{"atb":[[14,0]],"id":43167128}],"con":true,"img":false}]}
{"op":"mcm","clk":"5353076965","pt":1646208327215,"mc":[{"id":"1.195453762","rc":[{"atb":[[1.03,0.24]],"id":43167128}],"con":true,"img":false}]}
{"op":"mcm","clk":"5353076974","pt":1646208327420,"mc":[{"id":"1.195453762","rc":[{"atb":[[1.03,0]],"id":43167128}],"con":true,"img":false}]}
{"op":"mcm","clk":"5353076982","pt":1646208327524,"mc":[{"id":"1.195453762","rc":[{"atb":[[15,0.24]],"id":43167128}],"con":true,"img":false}]}
{"op":"mcm","clk":"5353077038","pt":1646208329010,"mc":[{"id":"1.195453762","rc":[{"atl":[[9.8,0]],"id":43167126}],"con":true,"img":false}]}
{"op":"mcm","clk":"5353077051","pt":1646208329217,"mc":[{"id":"1.195453762","rc":[{"atl":[[1000,2.25]],"id":43167126}],"con":true,"img":false}]}
{"op":"mcm","clk":"5353077064","pt":1646208329420,"mc":[{"id":"1.195453762","rc":[{"atl":[[1000,0.95]],"id":43167126}],"con":true,"img":false}]}
{"op":"mcm","clk":"5353077074","pt":1646208329626,"mc":[{"id":"1.195453762","rc":[{"atl":[[1000,0]],"id":43167126}],"con":true,"img":false}]}
{"op":"mcm","clk":"5353077081","pt":1646208329724,"mc":[{"id":"1.195453762","rc":[{"atl":[[10.5,0.95]],"id":43167126}],"con":true,"img":false}]}
{"op":"mcm","clk":"5353077260","pt":1646208332622,"mc":[{"id":"1.195453762","rc":[{"atl":[[2.96,2.5]],"id":43167124},{"atl":[[6.8,2.5]],"id":43167125}],"con":true,"img":false}]}
{"op":"mcm","clk":"5353077306","pt":1646208333294,"mc":[{"id":"1.195453762","rc":[{"atl":[[2.98,1.24]],"id":43167124},{"atl":[[7,1.24]],"id":43167125}],"con":true,"img":false}]}
{"op":"mcm","clk":"5353077312","pt":1646208333393,"mc":[{"id":"1.195453762","rc":[{"atl":[[2.94,1.31]],"id":43167124},{"atl":[[6.6,1.2]],"id":43167125}],"con":true,"img":false}]}
{"op":"mcm","clk":"5353077340","pt":1646208334011,"mc":[{"id":"1.195453762","rc":[{"atl":[[2.96,0]],"id":43167124},{"atl":[[6.8,0]],"id":43167125}],"con":true,"img":false}]}
{"op":"mcm","clk":"5353077367","pt":1646208334523,"mc":[{"id":"1.195453762","rc":[{"atl":[[2.94,0]],"id":43167124},{"atl":[[6.6,0]],"id":43167125}],"con":true,"img":false}]}
{"op":"mcm","clk":"5353077375","pt":1646208334628,"mc":[{"id":"1.195453762","rc":[{"atl":[[2.98,2.55]],"id":43167124},{"atl":[[7,2.44]],"id":43167125}],"con":true,"img":false}]}
{"op":"mcm","clk":"5353077543","pt":1646208337924,"mc":[{"id":"1.195453762","rc":[{"atl":[[2.96,2.5]],"id":43167124},{"atl":[[6.8,2.5]],"id":43167125}],"con":true,"img":false}]}
{"op":"mcm","clk":"5353077582","pt":1646208338742,"mc":[{"id":"1.195453762","rc":[{"atl":[[2.98,1.24]],"id":43167124},{"atl":[[7,1.24]],"id":43167125}],"con":true,"img":false}]}
{"op":"mcm","clk":"5353077591","pt":1646208338797,"mc":[{"id":"1.195453762","rc":[{"atl":[[2.94,1.31]],"id":43167124},{"atl":[[6.6,1.2]],"id":43167125}],"con":true,"img":false}]}
{"op":"mcm","clk":"5353077608","pt":1646208339104,"mc":[{"id":"1.195453762","rc":[{"atl":[[9.6,0]],"id":43167126},{"atl":[[1000,1.24]],"id":43167127},{"atl":[[2.98,0]],"id":43167124},{"atl":[[7,0]],"id":43167125}],"con":true,"img":false}]}
{"op":"mcm","clk":"5353077615","pt":1646208339309,"mc":[{"id":"1.195453762","rc":[{"atl":[[1000,0]],"id":43167127}],"con":true,"img":false}]}
{"op":"mcm","clk":"5353077623","pt":1646208339414,"mc":[{"id":"1.195453762","rc":[{"atl":[[9.6,1.96]],"id":43167127}],"con":true,"img":false}]}
{"op":"mcm","clk":"5353077649","pt":1646208339934,"mc":[{"id":"1.195453762","rc":[{"atl":[[10,0]],"id":43167126}],"con":true,"img":false}]}
{"op":"mcm","clk":"5353077654","pt":1646208340039,"mc":[{"id":"1.195453762","rc":[{"atl":[[10.5,2.22]],"id":43167126}],"con":true,"img":false}]}
{"op":"mcm","clk":"5353077688","pt":1646208340721,"mc":[{"id":"1.195453762","rc":[{"spn":12.49,"spf":1.0,"id":43167128},{"atl":[[2.96,0]],"id":43167124},{"atl":[[6.8,0]],"id":43167125}],"con":true,"img":false}]}
{"op":"mcm","clk":"5353077708","pt":1646208341130,"mc":[{"id":"1.195453762","rc":[{"atl":[[2.94,0]],"id":43167124},{"atl":[[6.6,0]],"id":43167125}],"con":true,"img":false}]}
{"op":"mcm","clk":"5353077713","pt":1646208341231,"mc":[{"id":"1.195453762","rc":[{"atl":[[2.98,1.31]],"id":43167124},{"atl":[[7,1.2]],"id":43167125}],"con":true,"img":false}]}
{"op":"mcm","clk":"5353077744","pt":1646208341901,"mc":[{"id":"1.195453762","rc":[{"atl":[[2.96,2.5]],"id":43167124},{"atl":[[6.8,2.5]],"id":43167125}],"con":true,"img":false}]}
{"op":"mcm","clk":"5353078466","pt":1646208356625,"mc":[{"id":"1.195453762","rc":[{"atl":[[1000,1.24]],"id":43167124}],"con":true,"img":false}]}
{"op":"mcm","clk":"5353078476","pt":1646208356732,"mc":[{"id":"1.195453762","rc":[{"atl":[[1000,1.24]],"id":43167125}],"con":true,"img":false}]}
{"op":"mcm","clk":"5353078479","pt":1646208356829,"mc":[{"id":"1.195453762","rc":[{"atl":[[1000,1.24]],"id":43167126},{"atl":[[1000,0]],"id":43167124}],"con":true,"img":false}]}
{"op":"mcm","clk":"5353078485","pt":1646208356932,"mc":[{"id":"1.195453762","rc":[{"atl":[[2.94,1.24]],"id":43167124},{"atl":[[1000,0]],"id":43167125}],"con":true,"img":false}]}
{"op":"mcm","clk":"5353078495","pt":1646208357041,"mc":[{"id":"1.195453762","rc":[{"atl":[[1000,0]],"id":43167126},{"atl":[[6.6,1.24]],"id":43167125}],"con":true,"img":false}]}
{"op":"mcm","clk":"5353078501","pt":1646208357143,"mc":[{"id":"1.195453762","rc":[{"atl":[[10,1.24]],"id":43167126}],"con":true,"img":false}]}
{"op":"mcm","clk":"5353078538","pt":1646208357975,"mc":[{"id":"1.195453762","rc":[{"atl":[[10.5,0.95]],"id":43167126},{"atl":[[2.96,0]],"id":43167124},{"atl":[[6.8,0]],"id":43167125}],"con":true,"img":false}]}
{"op":"mcm","clk":"5353078540","pt":1646208358023,"mc":[{"id":"1.195453762","rc":[{"atl":[[10,2.51]],"id":43167126}],"con":true,"img":false}]}
{"op":"mcm","clk":"5353078590","pt":1646208359155,"mc":[{"id":"1.195453762","rc":[{"atl":[[10.5,0]],"id":43167126}],"con":true,"img":false}]}
{"op":"mcm","clk":"5353078599","pt":1646208359260,"mc":[{"id":"1.195453762","rc":[{"atl":[[1000,2.25]],"id":43167126}],"con":true,"img":false}]}
{"op":"mcm","clk":"5353078607","pt":1646208359466,"mc":[{"id":"1.195453762","rc":[{"atl":[[1000,1.02]],"id":43167126}],"con":true,"img":false}]}
{"op":"mcm","clk":"5353078611","pt":1646208359667,"mc":[{"id":"1.195453762","rc":[{"atl":[[1000,0]],"id":43167126}],"con":true,"img":false}]}
{"op":"mcm","clk":"5353078617","pt":1646208359771,"mc":[{"id":"1.195453762","rc":[{"atl":[[9.8,1.02]],"id":43167126}],"con":true,"img":false}]}
{"op":"mcm","clk":"5353079349","pt":1646208374185,"mc":[{"id":"1.195453762","rc":[{"atl":[[9.6,0.71]],"id":43167127}],"con":true,"img":false}]}
{"op":"mcm","clk":"5353080064","pt":1646208389219,"mc":[{"id":"1.195453762","rc":[{"atl":[[3.25,0]],"id":43167124}],"con":true,"img":false}]}
{"op":"mcm","clk":"5353080178","pt":1646208391707,"mc":[{"id":"1.195453762","rc":[{"atl":[[10,1.26]],"id":43167126}],"con":true,"img":false}]}
{"op":"mcm","clk":"5353080199","pt":1646208392121,"mc":[{"id":"1.195453762","rc":[{"atl":[[3.25,4.62]],"id":43167124}],"con":true,"img":false}]}
{"op":"mcm","clk":"5353080344","pt":1646208395422,"mc":[{"id":"1.195453762","rc":[{"atl":[[44,0]],"id":43167128}],"con":true,"img":false}]}
{"op":"mcm","clk":"5353080349","pt":1646208395527,"mc":[{"id":"1.195453762","rc":[{"atl":[[40,2.72]],"id":43167128},{"atb":[[2.12,6.55]],"id":43167124}],"con":true,"img":false}]}
{"op":"mcm","clk":"5353080582","pt":1646208399924,"mc":[{"id":"1.195453762","rc":[{"atb":[[2.12,0]],"id":43167124}],"con":true,"img":false}]}
{"op":"mcm","clk":"5353080588","pt":1646208400030,"mc":[{"id":"1.195453762","rc":[{"atb":[[2.16,6.55]],"id":43167124}],"con":true,"img":false}]}
{"op":"mcm","clk":"5353080990","pt":1646208409141,"mc":[{"id":"1.195453762","rc":[{"atl":[[1000,1.24]],"id":43167126},{"spn":2.14,"spf":1.0,"id":43167124}],"con":true,"img":false}]}
{"op":"mcm","clk":"5353081006","pt":1646208409449,"mc":[{"id":"1.195453762","rc":[{"atl":[[1000,0]],"id":43167126}],"con":true,"img":false}]}
{"op":"mcm","clk":"5353081011","pt":1646208409546,"mc":[{"id":"1.195453762","rc":[{"atl":[[9.6,1.24]],"id":43167126}],"con":true,"img":false}]}
{"op":"mcm","clk":"5353081360","pt":1646208416242,"mc":[{"id":"1.195453762","rc":[{"atl":[[9.8,0]],"id":43167127}],"con":true,"img":false}]}
{"op":"mcm","clk":"5353081368","pt":1646208416450,"mc":[{"id":"1.195453762","rc":[{"atl":[[1000,2.25]],"id":43167127}],"con":true,"img":false}]}
{"op":"mcm","clk":"5353081372","pt":1646208416554,"mc":[{"id":"1.195453762","rc":[{"atl":[[1000,0.96]],"id":43167127}],"con":true,"img":false}]}
{"op":"mcm","clk":"5353081389","pt":1646208416859,"mc":[{"id":"1.195453762","rc":[{"atl":[[1000,0]],"id":43167127}],"con":true,"img":false}]}
{"op":"mcm","clk":"5353081393","pt":1646208416961,"mc":[{"id":"1.195453762","rc":[{"atl":[[10.5,0.96]],"id":43167127}],"con":true,"img":false}]}
{"op":"mcm","clk":"5353081403","pt":1646208417122,"mc":[{"id":"1.195453762","rc":[{"atl":[[2.92,2.5]],"id":43167124},{"atl":[[6.4,2.5]],"id":43167125}],"con":true,"img":false}]}
{"op":"mcm","clk":"5353081900","pt":1646208426666,"mc":[{"id":"1.195453762","rc":[{"atl":[[1000,1.24]],"id":43167127},{"atl":[[2.94,0]],"id":43167124},{"atl":[[6.6,0]],"id":43167125}],"con":true,"img":false}]}
{"op":"mcm","clk":"5353081907","pt":1646208426872,"mc":[{"id":"1.195453762","rc":[{"atl":[[1000,0]],"id":43167127}],"con":true,"img":false}]}
{"op":"mcm","clk":"5353081911","pt":1646208426975,"mc":[{"id":"1.195453762","rc":[{"atl":[[10,1.24]],"id":43167127}],"con":true,"img":false}]}
{"op":"mcm","clk":"5353081923","pt":1646208427138,"mc":[{"id":"1.195453762","rc":[{"atl":[[11,2]],"id":43167127},{"atl":[[2.98,0]],"id":43167124},{"atl":[[7,0]],"id":43167125}],"con":true,"img":false}]}
{"op":"mcm","clk":"5353081928","pt":1646208427242,"mc":[{"id":"1.195453762","rc":[{"atl":[[10.5,2.29]],"id":43167127},{"atl":[[2.9,1.31]],"id":43167124},{"atl":[[6.2,1.2]],"id":43167125}],"con":true,"img":false}]}
{"op":"mcm","clk":"5353081950","pt":1646208427753,"mc":[{"id":"1.195453762","rc":[{"atl":[[10.5,0.96]],"id":43167127}],"con":true,"img":false}]}
{"op":"mcm","clk":"5353081954","pt":1646208427852,"mc":[{"id":"1.195453762","rc":[{"atl":[[10,2.58]],"id":43167127},{"atl":[[2.92,0]],"id":43167124},{"atl":[[6.4,0]],"id":43167125}],"con":true,"img":false}]}
{"op":"mcm","clk":"5353081967","pt":1646208428160,"mc":[{"id":"1.195453762","rc":[{"atl":[[10.5,0]],"id":43167127},{"atb":[[3.95,3.42]],"id":43167125}],"con":true,"img":false}]}
{"op":"mcm","clk":"5353081977","pt":1646208428367,"mc":[{"id":"1.195453762","rc":[{"atl":[[1000,2.25]],"id":43167127},{"atl":[[2.9,0]],"id":43167124},{"atl":[[6.2,0]],"id":43167125}],"con":true,"img":false}]}
{"op":"mcm","clk":"5353081986","pt":1646208428469,"mc":[{"id":"1.195453762","rc":[{"atl":[[2.98,1.31]],"id":43167124},{"atl":[[7,1.2]],"id":43167125}],"con":true,"img":false}]}
{"op":"mcm","clk":"5353081991","pt":1646208428566,"mc":[{"id":"1.195453762","rc":[{"atl":[[1000,1.03]],"id":43167127}],"con":true,"img":false}]}
{"op":"mcm","clk":"5353082004","pt":1646208428772,"mc":[{"id":"1.195453762","rc":[{"atl":[[1000,0]],"id":43167127}],"con":true,"img":false}]}
{"op":"mcm","clk":"5353082012","pt":1646208428874,"mc":[{"id":"1.195453762","rc":[{"atl":[[9.8,1.03]],"id":43167127}],"con":true,"img":false}]}
{"op":"mcm","clk":"5353082673","pt":1646208444200,"mc":[{"id":"1.195453762","rc":[{"atl":[[1000,1.24]],"id":43167124}],"con":true,"img":false}]}
{"op":"mcm","clk":"5353082677","pt":1646208444258,"mc":[{"id":"1.195453762","rc":[{"atl":[[1000,1.24]],"id":43167125}],"con":true,"img":false}]}
{"op":"mcm","clk":"5353082686","pt":1646208444466,"mc":[{"id":"1.195453762","rc":[{"atl":[[1000,0]],"id":43167124},{"atl":[[1000,0]],"id":43167125}],"con":true,"img":false}]}
{"op":"mcm","clk":"5353082689","pt":1646208444566,"mc":[{"id":"1.195453762","rc":[{"atl":[[2.98,2.55]],"id":43167124},{"atl":[[7,2.44]],"id":43167125}],"con":true,"img":false}]}
{"op":"mcm","clk":"5353083334","pt":1646208460498,"mc":[{"id":"1.195453762","rc":[{"atb":[[20,0],[21,1]],"id":37178159},{"atb":[[14.5,0],[15,1.43]],"id":41017865},{"atb":[[5.1,19.15]],"id":43167126},{"atb":[[10,0],[9.2,12.56],[11,10.72],[8.2,28.2],[8.4,2.7],[9.6,0]],"id":43167128},{"atb":[[1.45,167.14],[1.53,0]],"id":43167124},{"atl":[[3.85,42.11],[3.55,0]],"id":43167124}],"con":true,"img":false}]}
{"op":"mcm","clk":"5353083339","pt":1646208460602,"mc":[{"id":"1.195453762","rc":[{"atb":[[4.8,0]],"id":43167126},{"atb":[[9.4,0]],"id":43167128},{"atb":[[3.85,2],[3.95,29.81]],"id":43167125},{"atl":[[7.4,20.04],[7.2,10.09]],"id":43167125}],"con":true,"img":false}]}
{"op":"mcm","clk":"5353083342","pt":1646208460703,"mc":[{"id":"1.195453762","rc":[{"atb":[[8.2,14.31]],"id":43167128}],"con":true,"img":false}]}
{"op":"mcm","clk":"5353083347","pt":1646208460806,"mc":[{"id":"1.195453762","rc":[{"atb":[[6.2,19.23]],"id":43167128}],"con":true,"img":false}]}
{"op":"mcm","clk":"5353083393","pt":1646208461681,"mc":[{"id":"1.195453762","rc":[{"atl":[[10,1.33]],"id":43167127}],"con":true,"img":false}]}
{"op":"mcm","clk":"5353083571","pt":1646208465391,"mc":[{"id":"1.195453762","rc":[{"atl":[[3.5,0]],"id":43167124}],"con":true,"img":false}]}
{"op":"mcm","clk":"5353083578","pt":1646208465495,"mc":[{"id":"1.195453762","rc":[{"atl":[[3.6,51.31]],"id":43167124}],"con":true,"img":false}]}
{"op":"mcm","clk":"5353083614","pt":1646208466527,"mc":[{"id":"1.195453762","rc":[{"atl":[[80,2.78],[85,2]],"id":41017865},{"atl":[[42,1.83],[44,2.33]],"id":42688789},{"atl":[[3.65,0]],"id":43167124},{"atl":[[7.4,16.92],[7.8,2.94]],"id":43167125}],"con":true,"img":false}]}
{"op":"mcm","clk":"5353083797","pt":1646208470386,"mc":[{"id":"1.195453762","rc":[{"spn":30.9,"spf":1.0,"id":37178159},{"spn":18.46,"spf":1.0,"id":41017865},{"spn":12.48,"spf":1.0,"id":43167128},{"atl":[[3.6,0]],"id":43167124},{"atb":[[3.9,35.52]],"id":43167125},{"atl":[[7.4,0]],"id":43167125},{"spn":3.97,"spf":1.0,"id":43167125}],"con":true,"img":false}]}
{"op":"mcm","clk":"5353083802","pt":1646208470489,"mc":[{"id":"1.195453762","rc":[{"atb":[[4.9,12.82]],"id":43167126},{"atb":[[8,7.14]],"id":43167128},{"atl":[[3.75,0],[3.95,16.95],[3.7,51.31]],"id":43167124},{"atb":[[3.7,24.39]],"id":43167125},{"atl":[[7.6,24.5]],"id":43167125}],"con":true,"img":false}]}
{"op":"mcm","clk":"5353084016","pt":1646208475332,"mc":[{"id":"1.195453762","rc":[{"atl":[[3.7,0]],"id":43167124}],"con":true,"img":false}]}
{"op":"mcm","clk":"5353084020","pt":1646208475434,"mc":[{"id":"1.195453762","rc":[{"atl":[[3.8,51.31]],"id":43167124}],"con":true,"img":false}]}
{"op":"mcm","clk":"5353084072","pt":1646208476514,"mc":[{"id":"1.195453762","rc":[{"atl":[[8.2,6.94],[7.6,16.92]],"id":43167125}],"con":true,"img":false}]}
{"op":"mcm","clk":"5353084162","pt":1646208479039,"mc":[{"id":"1.195453762","rc":[{"atl":[[1000,1.24]],"id":43167127}],"con":true,"img":false}]}
{"op":"mcm","clk":"5353084174","pt":1646208479198,"mc":[{"id":"1.195453762","rc":[{"atl":[[1000,0]],"id":43167127}],"con":true,"img":false}]}
{"op":"mcm","clk":"5353084180","pt":1646208479313,"mc":[{"id":"1.195453762","rc":[{"atl":[[9.6,1.96]],"id":43167127}],"con":true,"img":false}]}
{"op":"mcm","clk":"5353084233","pt":1646208480433,"mc":[{"id":"1.195453762","rc":[{"atl":[[7.6,0]],"id":43167125}],"con":true,"img":false}]}
{"op":"mcm","clk":"5353084239","pt":1646208480537,"mc":[{"id":"1.195453762","rc":[{"atb":[[4.4,0],[4.6,34.9],[4.2,0],[4.7,20.27]],"id":43167126},{"atb":[[15,2.24],[7.6,11.36]],"id":43167128},{"atl":[[4.1,24.19]],"id":43167124},{"atl":[[7.8,19.86]],"id":43167125}],"con":true,"img":false}]}
{"op":"mcm","clk":"5353084249","pt":1646208480745,"mc":[{"id":"1.195453762","rc":[{"atl":[[310,2]],"id":37178159},{"atb":[[24,2.15]],"id":41017865},{"atl":[[32,2]],"id":42688789}],"con":true,"img":false}]}
{"op":"mcm","clk":"5353084263","pt":1646208481106,"mc":[{"id":"1.195453762","rc":[{"atb":[[24,3.79]],"id":41017865},{"atb":[[14.5,2.08]],"id":43167128}],"con":true,"img":false}]}
{"op":"mcm","clk":"5353084266","pt":1646208481210,"mc":[{"id":"1.195453762","rc":[{"atb":[[14.5,0],[15,3.81]],"id":43167128}],"con":true,"img":false}]}
{"op":"mcm","clk":"5353084272","pt":1646208481313,"mc":[{"id":"1.195453762","rc":[{"atl":[[310,3.22]],"id":37178159}],"con":true,"img":false}]}
{"op":"mcm","clk":"5353084275","pt":1646208481416,"mc":[{"id":"1.195453762","rc":[{"atl":[[34,2.24]],"id":42688789}],"con":true,"img":false}]}
{"op":"mcm","clk":"5353084284","pt":1646208481519,"mc":[{"id":"1.195453762","rc":[{"atl":[[32,3.33]],"id":42688789}],"con":true,"img":false}]}
{"op":"mcm","clk":"5353084299","pt":1646208482032,"mc":[{"id":"1.195453762","rc":[{"atb":[[15,2.24]],"id":43167128}],"con":true,"img":false}]}
{"op":"mcm","clk":"5353084302","pt":1646208482134,"mc":[{"id":"1.195453762","rc":[{"atb":[[1.01,1.56]],"id":43167128}],"con":true,"img":false}]}
{"op":"mcm","clk":"5353084445","pt":1646208485436,"mc":[{"id":"1.195453762","rc":[{"atl":[[40,0]],"id":43167128}],"con":true,"img":false}]}
{"op":"mcm","clk":"5353084449","pt":1646208485538,"mc":[{"id":"1.195453762","rc":[{"atl":[[44,2.72]],"id":43167128}],"con":true,"img":false}]}
{"op":"mcm","clk":"5353084453","pt":1646208485642,"mc":[{"id":"1.195453762","rc":[{"atb":[[14,2],[15,0.24]],"id":43167128}],"con":true,"img":false}]}
{"op":"mcm","clk":"5353084466","pt":1646208485950,"mc":[{"id":"1.195453762","rc":[{"atb":[[1.01,0]],"id":43167128},{"atl":[[42,4.27],[44,0]],"id":42688789}],"con":true,"img":false}]}
{"op":"mcm","clk":"5353084473","pt":1646208486054,"mc":[{"id":"1.195453762","rc":[{"atb":[[14,3.56]],"id":43167128}],"con":true,"img":false}]}
{"op":"mcm","clk":"5353084489","pt":1646208486521,"mc":[{"id":"1.195453762","rc":[{"atl":[[8.6,9.87]],"id":43167125}],"con":true,"img":false}]}
{"op":"mcm","clk":"5353084666","pt":1646208490539,"mc":[{"id":"1.195453762","rc":[{"atb":[[4.5,65.14]],"id":43167126},{"atb":[[7.2,31.77]],"id":43167128},{"atl":[[4.3,37.88]],"id":43167124}],"con":true,"img":false}]}
{"op":"mcm","clk":"5353084914","pt":1646208496523,"mc":[{"id":"1.195453762","rc":[{"atl":[[9,15.62]],"id":43167125}],"con":true,"img":false}]}
{"op":"mcm","clk":"5353084917","pt":1646208496622,"mc":[{"id":"1.195453762","rc":[{"atl":[[330,0]],"id":37178159},{"atl":[[34,1]],"id":42688789},{"atl":[[8,0],[8.4,0]],"id":43167125}],"con":true,"img":false}]}
{"op":"mcm","clk":"5353084926","pt":1646208496982,"mc":[{"id":"1.195453762","rc":[{"atl":[[32,2]],"id":42688789}],"con":true,"img":false}]}
{"op":"mcm","clk":"5353084930","pt":1646208497033,"mc":[{"id":"1.195453762","rc":[{"atl":[[1000,1.33]],"id":42688789}],"con":true,"img":false}]}
{"op":"mcm","clk":"5353084932","pt":1646208497134,"mc":[{"id":"1.195453762","rc":[{"atl":[[32,0],[36,2]],"id":42688789}],"con":true,"img":false}]}
{"op":"mcm","clk":"5353084953","pt":1646208497647,"mc":[{"id":"1.195453762","rc":[{"atl":[[1000,0]],"id":42688789}],"con":true,"img":false}]}
{"op":"mcm","clk":"5353084959","pt":1646208497750,"mc":[{"id":"1.195453762","rc":[{"atl":[[36,3.33]],"id":42688789}],"con":true,"img":false}]}
{"op":"mcm","clk":"5353085074","pt":1646208500470,"mc":[{"id":"1.195453762","rc":[{"atl":[[320,2.17]],"id":37178159},{"atl":[[7.8,2.94]],"id":43167125}],"con":true,"img":false}]}
{"op":"mcm","clk":"5353085078","pt":1646208500527,"mc":[{"id":"1.195453762","rc":[{"atl":[[340,2.72]],"id":37178159},{"atl":[[8.4,16.92]],"id":43167125}],"con":true,"img":false}]}
{"op":"mcm","clk":"5353085164","pt":1646208503248,"mc":[{"id":"1.195453762","rc":[{"atl":[[9.8,0]],"id":43167126}],"con":true,"img":false}]}
{"op":"mcm","clk":"5353085169","pt":1646208503351,"mc":[{"id":"1.195453762","rc":[{"atl":[[1000,2.25]],"id":43167126}],"con":true,"img":false}]}
{"op":"mcm","clk":"5353085178","pt":1646208503559,"mc":[{"id":"1.195453762","rc":[{"atl":[[42,1.83],[44,2.33]],"id":42688789}],"con":true,"img":false}]}
{"op":"mcm","clk":"5353085190","pt":1646208503867,"mc":[{"id":"1.195453762","rc":[{"atl":[[1000,0.95]],"id":43167126}],"con":true,"img":false}]}
{"op":"mcm","clk":"5353085200","pt":1646208504175,"mc":[{"id":"1.195453762","rc":[{"atl":[[1000,0]],"id":43167126}],"con":true,"img":false}]}
{"op":"mcm","clk":"5353085204","pt":1646208504278,"mc":[{"id":"1.195453762","rc":[{"atl":[[10.5,0.95]],"id":43167126}],"con":true,"img":false}]}
{"op":"mcm","clk":"5353085245","pt":1646208505362,"mc":[{"id":"1.195453762","rc":[{"atl":[[320,2]],"id":37178159}],"con":true,"img":false}]}
{"op":"mcm","clk":"5353085254","pt":1646208505463,"mc":[{"id":"1.195453762","rc":[{"atl":[[300,0.17]],"id":37178159}],"con":true,"img":false}]}
{"op":"mcm","clk":"5353085346","pt":1646208507262,"mc":[{"id":"1.195453762","rc":[{"atb":[[1.03,2.25]],"id":43167128}],"con":true,"img":false}]}
{"op":"mcm","clk":"5353085350","pt":1646208507365,"mc":[{"id":"1.195453762","rc":[{"atb":[[1.03,0.24],[15,0]],"id":43167128}],"con":true,"img":false}]}
{"op":"mcm","clk":"5353085360","pt":1646208507570,"mc":[{"id":"1.195453762","rc":[{"atb":[[1.03,0]],"id":43167128}],"con":true,"img":false}]}
{"op":"mcm","clk":"5353085365","pt":1646208507672,"mc":[{"id":"1.195453762","rc":[{"atb":[[14.5,0.24]],"id":43167128}],"con":true,"img":false}]}
{"op":"mcm","clk":"5353085428","pt":1646208509265,"mc":[{"id":"1.195453762","rc":[{"atl":[[3.25,0]],"id":43167124}],"con":true,"img":false}]}
{"op":"mcm","clk":"5353085568","pt":1646208512248,"mc":[{"id":"1.195453762","rc":[{"atl":[[3.25,4.62]],"id":43167124}],"con":true,"img":false}]}
{"op":"mcm","clk":"5353085577","pt":1646208512453,"mc":[{"id":"1.195453762","rc":[{"atb":[[4.6,2]],"id":43167126},{"atb":[[13.5,0.81]],"id":43167128}],"con":true,"img":false}]}
{"op":"mcm","clk":"5353085582","pt":1646208512557,"mc":[{"id":"1.195453762","rc":[{"atb":[[5,58.66]],"id":43167126},{"atb":[[14.5,4.93]],"id":43167128}],"con":true,"img":false}]}
{"op":"mcm","clk":"5353085586","pt":1646208512661,"mc":[{"id":"1.195453762","rc":[{"atb":[[15,2]],"id":43167128}],"con":true,"img":false}]}
{"op":"mcm","clk":"5353085590","pt":1646208512763,"mc":[{"id":"1.195453762","rc":[{"atb":[[14,1.56]],"id":43167128}],"con":true,"img":false}]}
{"op":"mcm","clk":"5353085605","pt":1646208513278,"mc":[{"id":"1.195453762","rc":[{"atb":[[14,0]],"id":43167128}],"con":true,"img":false}]}
{"op":"mcm","clk":"5353085612","pt":1646208513381,"mc":[{"id":"1.195453762","rc":[{"atb":[[15,3.56]],"id":43167128}],"con":true,"img":false}]}
{"op":"mcm","clk":"5353085641","pt":1646208514151,"mc":[{"id":"1.195453762","rc":[{"atl":[[300,1.41]],"id":37178159},{"atl":[[9.6,0]],"id":43167126}],"con":true,"img":false}]}
{"op":"mcm","clk":"5353085646","pt":1646208514254,"mc":[{"id":"1.195453762","rc":[{"atl":[[300,3.41],[320,0]],"id":37178159}],"con":true,"img":false}]}
{"op":"mcm","clk":"5353085650","pt":1646208514356,"mc":[{"id":"1.195453762","rc":[{"atl":[[300,1.41],[290,2],[310,5.22]],"id":37178159},{"atl":[[10,0]],"id":43167126}],"con":true,"img":false}]}
{"op":"mcm","clk":"5353085654","pt":1646208514459,"mc":[{"id":"1.195453762","rc":[{"atl":[[300,3.41],[310,3.22]],"id":37178159},{"atl":[[10.5,2.22]],"id":43167126}],"con":true,"img":false}]}
{"op":"mcm","clk":"5353085658","pt":1646208514562,"mc":[{"id":"1.195453762","rc":[{"atl":[[290,0]],"id":37178159}],"con":true,"img":false}]}
{"op":"mcm","clk":"5353085672","pt":1646208514973,"mc":[{"id":"1.195453762","rc":[{"atl":[[310,2]],"id":37178159}],"con":true,"img":false}]}
{"op":"mcm","clk":"5353085678","pt":1646208515077,"mc":[{"id":"1.195453762","rc":[{"atl":[[290,1.22]],"id":37178159}],"con":true,"img":false}]}
{"op":"mcm","clk":"5353085684","pt":1646208515181,"mc":[{"id":"1.195453762","rc":[{"atl":[[290,3.22]],"id":37178159}],"con":true,"img":false}]}
{"op":"mcm","clk":"5353085689","pt":1646208515285,"mc":[{"id":"1.195453762","rc":[{"atl":[[310,0]],"id":37178159}],"con":true,"img":false}]}
{"op":"mcm","clk":"5353085693","pt":1646208515339,"mc":[{"id":"1.195453762","rc":[{"atl":[[280,2],[300,1.41]],"id":37178159}],"con":true,"img":false}]}
{"op":"mcm","clk":"5353085702","pt":1646208515548,"mc":[{"id":"1.195453762","rc":[{"atl":[[280,0]],"id":37178159}],"con":true,"img":false}]}
{"op":"mcm","clk":"5353085709","pt":1646208515646,"mc":[{"id":"1.195453762","rc":[{"atl":[[280,2],[290,2]],"id":37178159}],"con":true,"img":false}]}
{"op":"mcm","clk":"5353085715","pt":1646208515748,"mc":[{"id":"1.195453762","rc":[{"atl":[[280,3.22]],"id":37178159}],"con":true,"img":false}]}
{"op":"mcm","clk":"5353085905","pt":1646208520389,"mc":[{"id":"1.195453762","rc":[{"atl":[[38,1.35]],"id":42688789}],"con":true,"img":false}]}
{"op":"mcm","clk":"5353085910","pt":1646208520492,"mc":[{"id":"1.195453762","rc":[{"atl":[[34,3.72]],"id":42688789}],"con":true,"img":false}]}
{"op":"mcm","clk":"5353085915","pt":1646208520595,"mc":[{"id":"1.195453762","rc":[{"atl":[[32,2],[36,1.33]],"id":42688789}],"con":true,"img":false}]}
{"op":"mcm","clk":"5353085937","pt":1646208521060,"mc":[{"id":"1.195453762","rc":[{"atl":[[36,0]],"id":42688789}],"con":true,"img":false}]}
{"op":"mcm","clk":"5353085940","pt":1646208521165,"mc":[{"id":"1.195453762","rc":[{"atl":[[32,3.33]],"id":42688789}],"con":true,"img":false}]}
{"op":"mcm","clk":"5353086108","pt":1646208525389,"mc":[{"id":"1.195453762","rc":[{"atb":[[14.5,0.24]],"id":43167128}],"con":true,"img":false}]}
{"op":"mcm","clk":"5353086112","pt":1646208525491,"mc":[{"id":"1.195453762","rc":[{"atb":[[13.5,5.49]],"id":43167128}],"con":true,"img":false}]}
{"op":"mcm","clk":"5353086118","pt":1646208525595,"mc":[{"id":"1.195453762","rc":[{"atl":[[42,4.27]],"id":42688789}],"con":true,"img":false}]}
{"op":"mcm","clk":"5353086123","pt":1646208525698,"mc":[{"id":"1.195453762","rc":[{"atl":[[44,0]],"id":42688789}],"con":true,"img":false}]}
{"op":"mcm","clk":"5353086157","pt":1646208526373,"mc":[{"id":"1.195453762","rc":[{"atb":[[15,2]],"id":43167128}],"con":true,"img":false}]}
{"op":"mcm","clk":"5353086162","pt":1646208526476,"mc":[{"id":"1.195453762","rc":[{"atb":[[1.01,1.56],[14,2]],"id":43167128}],"con":true,"img":false}]}
{"op":"mcm","clk":"5353086168","pt":1646208526580,"mc":[{"id":"1.195453762","rc":[{"atb":[[15,0]],"id":43167128}],"con":true,"img":false}]}
{"op":"mcm","clk":"5353086361","pt":1646208531583,"mc":[{"id":"1.195453762","rc":[{"spn":19.47,"spf":1.0,"id":41017865},{"atl":[[1000,1.24]],"id":43167126},{"spn":12.22,"spf":1.0,"id":43167128}],"con":true,"img":false}]}
{"op":"mcm","clk":"5353086368","pt":1646208531687,"mc":[{"id":"1.195453762","rc":[{"atl":[[30,1.24]],"id":42688789}],"con":true,"img":false}]}
{"op":"mcm","clk":"5353086378","pt":1646208531890,"mc":[{"id":"1.195453762","rc":[{"atl":[[1000,0]],"id":43167126}],"con":true,"img":false}]}
{"op":"mcm","clk":"5353086382","pt":1646208531993,"mc":[{"id":"1.195453762","rc":[{"atl":[[10,1.24]],"id":43167126}],"con":true,"img":false}]}
{"op":"mcm","clk":"5353086402","pt":1646208532405,"mc":[{"id":"1.195453762","rc":[{"atl":[[10.5,0.95]],"id":43167126}],"con":true,"img":false}]}
{"op":"mcm","clk":"5353086407","pt":1646208532465,"mc":[{"id":"1.195453762","rc":[{"atl":[[10,2.51]],"id":43167126}],"con":true,"img":false}]}
{"op":"mcm","clk":"5353086448","pt":1646208533488,"mc":[{"id":"1.195453762","rc":[{"atl":[[10.5,0]],"id":43167126}],"con":true,"img":false}]}
{"op":"mcm","clk":"5353086452","pt":1646208533589,"mc":[{"id":"1.195453762","rc":[{"atl":[[1000,2.25]],"id":43167126}],"con":true,"img":false}]}
{"op":"mcm","clk":"5353086461","pt":1646208533795,"mc":[{"id":"1.195453762","rc":[{"atl":[[1000,1.02]],"id":43167126}],"con":true,"img":false}]}
{"op":"mcm","clk":"5353086468","pt":1646208534001,"mc":[{"id":"1.195453762","rc":[{"atl":[[1000,0]],"id":43167126}],"con":true,"img":false}]}
{"op":"mcm","clk":"5353086474","pt":1646208534106,"mc":[{"id":"1.195453762","rc":[{"atl":[[9.8,1.02]],"id":43167126}],"con":true,"img":false}]}
{"op":"mcm","clk":"5353086514","pt":1646208535390,"mc":[{"id":"1.195453762","rc":[{"atl":[[300,1.24]],"id":37178159},{"atl":[[34,1]],"id":42688789}],"con":true,"img":false}]}
{"op":"mcm","clk":"5353086520","pt":1646208535492,"mc":[{"id":"1.195453762","rc":[{"atl":[[270,0.17]],"id":37178159},{"atl":[[38,4.07]],"id":42688789}],"con":true,"img":false}]}
{"op":"mcm","clk":"5353086523","pt":1646208535595,"mc":[{"id":"1.195453762","rc":[{"atb":[[25,1.67]],"id":41017865},{"atb":[[14.5,2.33]],"id":43167128}],"con":true,"img":false}]}
{"op":"mcm","clk":"5353086544","pt":1646208536106,"mc":[{"id":"1.195453762","rc":[{"atl":[[32,2]],"id":42688789}],"con":true,"img":false}]}
{"op":"mcm","clk":"5353086550","pt":1646208536209,"mc":[{"id":"1.195453762","rc":[{"atl":[[1000,1.33]],"id":42688789}],"con":true,"img":false}]}
{"op":"mcm","clk":"5353087052","pt":1646208549208,"mc":[{"id":"1.195453762","rc":[{"atl":[[300,0]],"id":37178159}],"con":true,"img":false}]}
{"op":"mcm","clk":"5353087085","pt":1646208549979,"mc":[{"id":"1.195453762","rc":[{"atb":[[5.6,0]],"id":43167126},{"atb":[[1.01,0]],"id":43167128},{"atb":[[4,0.94]],"id":43167125}],"con":true,"img":false}]}
{"op":"mcm","clk":"5353087091","pt":1646208550082,"mc":[{"id":"1.195453762","rc":[{"atb":[[5.8,1.62]],"id":43167126},{"atb":[[14.5,3.89]],"id":43167128},{"atb":[[4.2,1.55]],"id":43167125}],"con":true,"img":false}]}
{"op":"mcm","clk":"5353087095","pt":1646208550183,"mc":[{"id":"1.195453762","rc":[{"atb":[[15,2]],"id":43167128}],"con":true,"img":false}]}
{"op":"mcm","clk":"5353087099","pt":1646208550294,"mc":[{"id":"1.195453762","rc":[{"atb":[[14,0]],"id":43167128}],"con":true,"img":false}]}
{"op":"mcm","clk":"5353087102","pt":1646208550390,"mc":[{"id":"1.195453762","rc":[{"atl":[[9.4,0]],"id":43167126}],"con":true,"img":false}]}
{"op":"mcm","clk":"5353087109","pt":1646208550493,"mc":[{"id":"1.195453762","rc":[{"atl":[[12.5,18.17]],"id":43167126}],"con":true,"img":false}]}
{"op":"mcm","clk":"5353087115","pt":1646208550596,"mc":[{"id":"1.195453762","rc":[{"atl":[[13,6.25]],"id":43167126}],"con":true,"img":false}]}
{"op":"mcm","clk":"5353087123","pt":1646208550803,"mc":[{"id":"1.195453762","rc":[{"atl":[[1000,1.67]],"id":43167126}],"con":true,"img":false}]}
{"op":"mcm","clk":"5353087128","pt":1646208550914,"mc":[{"id":"1.195453762","rc":[{"atl":[[10,1.24]],"id":43167126},{"atl":[[9.6,1.24]],"id":43167127},{"atb":[[14.5,2.33]],"id":43167128}],"con":true,"img":false}]}
{"op":"mcm","clk":"5353087133","pt":1646208551012,"mc":[{"id":"1.195453762","rc":[{"atl":[[10.5,1.26]],"id":43167126},{"atb":[[15,3.56]],"id":43167128}],"con":true,"img":false}]}
{"op":"mcm","clk":"5353087137","pt":1646208551117,"mc":[{"id":"1.195453762","rc":[{"atb":[[14.5,4.33],[15,1.56]],"id":43167128},{"atl":[[3.45,0]],"id":43167124}],"con":true,"img":false}]}
{"op":"mcm","clk":"5353087150","pt":1646208551324,"mc":[{"id":"1.195453762","rc":[{"atl":[[1000,1.67]],"id":43167127}],"con":true,"img":false}]}
{"op":"mcm","clk":"5353087166","pt":1646208551588,"mc":[{"id":"1.195453762","rc":[{"atl":[[1000,0.7]],"id":43167126},{"atl":[[10,0]],"id":43167127}],"con":true,"img":false}]}
{"op":"mcm","clk":"5353087169","pt":1646208551687,"mc":[{"id":"1.195453762","rc":[{"atl":[[11,3.33]],"id":43167127}],"con":true,"img":false}]}
{"op":"mcm","clk":"5353087173","pt":1646208551790,"mc":[{"id":"1.195453762","rc":[{"atb":[[5.7,0]],"id":43167126},{"atb":[[14.5,2.24]],"id":43167128},{"atb":[[4.1,0]],"id":43167125}],"con":true,"img":false}]}
{"op":"mcm","clk":"5353087177","pt":1646208551892,"mc":[{"id":"1.195453762","rc":[{"atl":[[1000,0.73]],"id":43167127}],"con":true,"img":false}]}
{"op":"mcm","clk":"5353087183","pt":1646208551994,"mc":[{"id":"1.195453762","rc":[{"atl":[[1000,0]],"id":43167126}],"con":true,"img":false}]}
{"op":"mcm","clk":"5353087187","pt":1646208552098,"mc":[{"id":"1.195453762","rc":[{"atl":[[9.6,0.7]],"id":43167126}],"con":true,"img":false}]}
{"op":"mcm","clk":"5353087206","pt":1646208552509,"mc":[{"id":"1.195453762","rc":[{"atb":[[5.8,0]],"id":43167126},{"atb":[[4.2,0]],"id":43167125}],"con":true,"img":false}]}
{"op":"mcm","clk":"5353087211","pt":1646208552612,"mc":[{"id":"1.195453762","rc":[{"atb":[[5.6,1.62]],"id":43167126},{"atb":[[4,2.49]],"id":43167125}],"con":true,"img":false}]}
{"op":"mcm","clk":"5353087216","pt":1646208552715,"mc":[{"id":"1.195453762","rc":[{"atl":[[1000,0]],"id":43167127}],"con":true,"img":false}]}
{"op":"mcm","clk":"5353087222","pt":1646208552818,"mc":[{"id":"1.195453762","rc":[{"atl":[[9.4,0.73]],"id":43167127}],"con":true,"img":false}]}
{"op":"mcm","clk":"5353087232","pt":1646208553023,"mc":[{"id":"1.195453762","rc":[{"atb":[[15.5,2.08]],"id":43167128},{"atb":[[4.1,2.5]],"id":43167125}],"con":true,"img":false}]}
{"op":"mcm","clk":"5353087239","pt":1646208553130,"mc":[{"id":"1.195453762","rc":[{"atb":[[4,5.39]],"id":43167125}],"con":true,"img":false}]}
{"op":"mcm","clk":"5353087247","pt":1646208553231,"mc":[{"id":"1.195453762","rc":[{"atb":[[14.5,0.24],[15.5,4.08]],"id":43167128}],"con":true,"img":false}]}
{"op":"mcm","clk":"5353087253","pt":1646208553290,"mc":[{"id":"1.195453762","rc":[{"atb":[[15,0]],"id":43167128},{"atb":[[4,3.84]],"id":43167125}],"con":true,"img":false}]}
{"op":"mcm","clk":"5353087261","pt":1646208553386,"mc":[{"id":"1.195453762","rc":[{"atb":[[15.5,5.64]],"id":43167128},{"atb":[[4.2,1.55]],"id":43167125}],"con":true,"img":false}]}
{"op":"mcm","clk":"5353087290","pt":1646208554111,"mc":[{"id":"1.195453762","rc":[{"atb":[[15.5,4.08]],"id":43167128}],"con":true,"img":false}]}
{"op":"mcm","clk":"5353087296","pt":1646208554209,"mc":[{"id":"1.195453762","rc":[{"atb":[[1.01,1.56]],"id":43167128}],"con":true,"img":false}]}
{"op":"mcm","clk":"5353087322","pt":1646208554722,"mc":[{"id":"1.195453762","rc":[{"atb":[[4.1,0]],"id":43167125}],"con":true,"img":false}]}
{"op":"mcm","clk":"5353087357","pt":1646208555617,"mc":[{"id":"1.195453762","rc":[{"atb":[[4.2,0]],"id":43167125}],"con":true,"img":false}]}
{"op":"mcm","clk":"5353087364","pt":1646208555721,"mc":[{"id":"1.195453762","rc":[{"atb":[[4.1,1.55]],"id":43167125}],"con":true,"img":false}]}
{"op":"mcm","clk":"5353087717","pt":1646208564626,"mc":[{"id":"1.195453762","rc":[{"atb":[[4,0.94]],"id":43167125}],"con":true,"img":false}]}
{"op":"mcm","clk":"5353087736","pt":1646208565141,"mc":[{"id":"1.195453762","rc":[{"atb":[[4.1,0]],"id":43167125}],"con":true,"img":false}]}
{"op":"mcm","clk":"5353087741","pt":1646208565244,"mc":[{"id":"1.195453762","rc":[{"atb":[[4,2.49]],"id":43167125}],"con":true,"img":false}]}
{"op":"mcm","clk":"5353087745","pt":1646208565346,"mc":[{"id":"1.195453762","rc":[{"atl":[[3.7,5.47]],"id":43167124}],"con":true,"img":false}]}
{"op":"mcm","clk":"5353087752","pt":1646208565552,"mc":[{"id":"1.195453762","rc":[{"atb":[[3.95,26.39]],"id":43167125}],"con":true,"img":false}]}
{"op":"mcm","clk":"5353087785","pt":1646208566326,"mc":[{"id":"1.195453762","rc":[{"atb":[[5.7,2.5]],"id":43167126},{"atb":[[4.1,2.5]],"id":43167125}],"con":true,"img":false}]}
{"op":"mcm","clk":"5353087798","pt":1646208566636,"mc":[{"id":"1.195453762","rc":[{"atl":[[270,1.41]],"id":37178159},{"atb":[[5.6,0]],"id":43167126},{"atl":[[10,0]],"id":43167126},{"atl":[[9.6,0]],"id":43167127}],"con":true,"img":false}]}
{"op":"mcm","clk":"5353087806","pt":1646208566738,"mc":[{"id":"1.195453762","rc":[{"atl":[[270,3.41]],"id":37178159},{"atb":[[5.8,1.62]],"id":43167126}],"con":true,"img":false}]}
{"op":"mcm","clk":"5353087811","pt":1646208566842,"mc":[{"id":"1.195453762","rc":[{"atl":[[280,1.22],[290,0]],"id":37178159}],"con":true,"img":false}]}
{"op":"mcm","clk":"5353087818","pt":1646208566946,"mc":[{"id":"1.195453762","rc":[{"atl":[[260,2]],"id":37178159}],"con":true,"img":false}]}
{"op":"mcm","clk":"5353087839","pt":1646208567409,"mc":[{"id":"1.195453762","rc":[{"atl":[[280,0]],"id":37178159}],"con":true,"img":false}]}
{"op":"mcm","clk":"5353087845","pt":1646208567519,"mc":[{"id":"1.195453762","rc":[{"atl":[[260,3.22]],"id":37178159}],"con":true,"img":false}]}
{"op":"mcm","clk":"5353087906","pt":1646208568749,"mc":[{"id":"1.195453762","rc":[{"atb":[[5.7,0]],"id":43167126}],"con":true,"img":false}]}
{"op":"mcm","clk":"5353087928","pt":1646208569058,"mc":[{"id":"1.195453762","rc":[{"atb":[[5.8,0]],"id":43167126}],"con":true,"img":false}]}
{"op":"mcm","clk":"5353087934","pt":1646208569160,"mc":[{"id":"1.195453762","rc":[{"atb":[[5.6,1.62]],"id":43167126}],"con":true,"img":false}]}
{"op":"mcm","clk":"5353088239","pt":1646208575550,"mc":[{"id":"1.195453762","rc":[{"atl":[[9.8,0]],"id":43167127}],"con":true,"img":false}]}
{"op":"mcm","clk":"5353088242","pt":1646208575654,"mc":[{"id":"1.195453762","rc":[{"atl":[[1000,2.25]],"id":43167127}],"con":true,"img":false}]}
{"op":"mcm","clk":"5353088246","pt":1646208575756,"mc":[{"id":"1.195453762","rc":[{"atb":[[60,4.72]],"id":37178159},{"atl":[[85,0],[100,2]],"id":41017865},{"atb":[[4,28.88],[3.95,0]],"id":43167125},{"atl":[[7.8,0],[7.6,3.03]],"id":43167125}],"con":true,"img":false}]}
{"op":"mcm","clk":"5353088254","pt":1646208575860,"mc":[{"id":"1.195453762","rc":[{"atl":[[1000,0.96]],"id":43167127}],"con":true,"img":false}]}
{"op":"mcm","clk":"5353088259","pt":1646208575964,"mc":[{"id":"1.195453762","rc":[{"atl":[[1000,0]],"id":43167127}],"con":true,"img":false}]}
{"op":"mcm","clk":"5353088265","pt":1646208576014,"mc":[{"id":"1.195453762","rc":[{"atl":[[10.5,0.96]],"id":43167127}],"con":true,"img":false}]}
{"op":"mcm","clk":"5353088277","pt":1646208576426,"mc":[{"id":"1.195453762","rc":[{"atl":[[11,2]],"id":43167127}],"con":true,"img":false}]}
{"op":"mcm","clk":"5353088282","pt":1646208576530,"mc":[{"id":"1.195453762","rc":[{"atl":[[10.5,2.29]],"id":43167127},{"atb":[[4.1,5.48]],"id":43167125}],"con":true,"img":false}]}
{"op":"mcm","clk":"5353088482","pt":1646208580448,"mc":[{"id":"1.195453762","rc":[{"atl":[[80,0.06]],"id":41017865}],"con":true,"img":false}]}
{"op":"mcm","clk":"5353088485","pt":1646208580552,"mc":[{"id":"1.195453762","rc":[{"atl":[[95,2.72]],"id":41017865}],"con":true,"img":false}]}
{"op":"mcm","clk":"5353088519","pt":1646208581223,"mc":[{"id":"1.195453762","rc":[{"atl":[[65,0]],"id":41017865}],"con":true,"img":false}]}
{"op":"mcm","clk":"5353088524","pt":1646208581327,"mc":[{"id":"1.195453762","rc":[{"atl":[[1000,1.25]],"id":41017865}],"con":true,"img":false}]}
{"op":"mcm","clk":"5353088642","pt":1646208584065,"mc":[{"id":"1.195453762","rc":[{"atl":[[1000,1.24]],"id":43167126}],"con":true,"img":false}]}
{"op":"mcm","clk":"5353088648","pt":1646208584167,"mc":[{"id":"1.195453762","rc":[{"atl":[[1000,1.24]],"id":43167127}],"con":true,"img":false}]}
{"op":"mcm","clk":"5353088653","pt":1646208584268,"mc":[{"id":"1.195453762","rc":[{"atl":[[1000,0]],"id":43167126}],"con":true,"img":false}]}
{"op":"mcm","clk":"5353088660","pt":1646208584372,"mc":[{"id":"1.195453762","rc":[{"atl":[[9.6,1.94]],"id":43167126},{"atl":[[1000,0]],"id":43167127}],"con":true,"img":false}]}
{"op":"mcm","clk":"5353088664","pt":1646208584474,"mc":[{"id":"1.195453762","rc":[{"atl":[[10,1.24]],"id":43167127}],"con":true,"img":false}]}
{"op":"mcm","clk":"5353088684","pt":1646208584737,"mc":[{"id":"1.195453762","rc":[{"atl":[[10.5,0.96]],"id":43167127}],"con":true,"img":false}]}
{"op":"mcm","clk":"5353088688","pt":1646208584838,"mc":[{"id":"1.195453762","rc":[{"atl":[[10,2.58]],"id":43167127}],"con":true,"img":false}]}
{"op":"mcm","clk":"5353088799","pt":1646208587561,"mc":[{"id":"1.195453762","rc":[{"atl":[[10.5,0]],"id":43167127}],"con":true,"img":false}]}
{"op":"mcm","clk":"5353088801","pt":1646208587663,"mc":[{"id":"1.195453762","rc":[{"atl":[[1000,2.25]],"id":43167127}],"con":true,"img":false}]}
{"op":"mcm","clk":"5353088808","pt":1646208587870,"mc":[{"id":"1.195453762","rc":[{"atl":[[1000,1.03]],"id":43167127}],"con":true,"img":false}]}
{"op":"mcm","clk":"5353088816","pt":1646208588078,"mc":[{"id":"1.195453762","rc":[{"atl":[[1000,0]],"id":43167127}],"con":true,"img":false}]}
{"op":"mcm","clk":"5353088818","pt":1646208588178,"mc":[{"id":"1.195453762","rc":[{"atl":[[9.8,1.03]],"id":43167127}],"con":true,"img":false}]}
{"op":"mcm","clk":"5353088854","pt":1646208588851,"mc":[{"id":"1.195453762","rc":[{"atl":[[9.6,1.24]],"id":43167126}],"con":true,"img":false}]}
{"op":"mcm","clk":"5353088862","pt":1646208589055,"mc":[{"id":"1.195453762","rc":[{"atl":[[1000,1.67]],"id":43167126}],"con":true,"img":false}]}
{"op":"mcm","clk":"5353088881","pt":1646208589467,"mc":[{"id":"1.195453762","rc":[{"atl":[[1000,0.71]],"id":43167126}],"con":true,"img":false}]}
{"op":"mcm","clk":"5353088898","pt":1646208589882,"mc":[{"id":"1.195453762","rc":[{"atl":[[1000,0]],"id":43167126}],"con":true,"img":false}]}
{"op":"mcm","clk":"5353088901","pt":1646208589935,"mc":[{"id":"1.195453762","rc":[{"atl":[[9.4,0.71]],"id":43167126}],"con":true,"img":false}]}
{"op":"mcm","clk":"5353089062","pt":1646208593355,"mc":[{"id":"1.195453762","rc":[{"spn":33.77,"spf":1.0,"id":37178159},{"spn":19.94,"spf":1.0,"id":41017865},{"spn":5.44,"spf":1.0,"id":43167126},{"spn":12.67,"spf":1.0,"id":43167128},{"atb":[[14.5,2]],"id":42688789},{"atl":[[42,1.83],[48,2.13]],"id":42688789},{"spn":12.84,"spf":1.0,"id":42688789},{"atb":[[4,2.49],[3.95,24.39]],"id":43167125},{"atl":[[7.4,3.12],[7.6,0]],"id":43167125},{"spn":3.98,"spf":1.0,"id":43167125}],"con":true,"img":false}]}
{"op":"mcm","clk":"5353089069","pt":1646208593458,"mc":[{"id":"1.195453762","rc":[{"atb":[[3.95,0],[3.9,59.91]],"id":43167125}],"con":true,"img":false}]}
{"op":"mcm","clk":"5353089102","pt":1646208594179,"mc":[{"id":"1.195453762","rc":[{"atb":[[14,2.35]],"id":42688789}],"con":true,"img":false}]}
{"op":"mcm","clk":"5353089107","pt":1646208594281,"mc":[{"id":"1.195453762","rc":[{"atb":[[14.5,3.58]],"id":42688789}],"con":true,"img":false}]}
{"op":"mcm","clk":"5353089111","pt":1646208594384,"mc":[{"id":"1.195453762","rc":[{"atb":[[14,4.35]],"id":42688789}],"con":true,"img":false}]}
{"op":"mcm","clk":"5353089115","pt":1646208594488,"mc":[{"id":"1.195453762","rc":[{"atb":[[14.5,1.58]],"id":42688789}],"con":true,"img":false}]}
{"op":"mcm","clk":"5353089121","pt":1646208594539,"mc":[{"id":"1.195453762","rc":[{"atb":[[14,2.35]],"id":42688789}],"con":true,"img":false}]}
{"op":"mcm","clk":"5353089125","pt":1646208594642,"mc":[{"id":"1.195453762","rc":[{"atb":[[14,4.35]],"id":42688789},{"atb":[[4.1,2.5]],"id":43167125}],"con":true,"img":false}]}
{"op":"mcm","clk":"5353089146","pt":1646208595053,"mc":[{"id":"1.195453762","rc":[{"atb":[[14,2.27]],"id":42688789}],"con":true,"img":false}]}
{"op":"mcm","clk":"5353089250","pt":1646208597385,"mc":[{"id":"1.195453762","rc":[{"atb":[[1.05,2.25]],"id":41017865}],"con":true,"img":false}]}
{"op":"mcm","clk":"5353089258","pt":1646208597592,"mc":[{"id":"1.195453762","rc":[{"atb":[[24,3.63],[1.05,0.14]],"id":41017865}],"con":true,"img":false}]}
{"op":"mcm","clk":"5353089265","pt":1646208597748,"mc":[{"id":"1.195453762","rc":[{"atb":[[1.05,0]],"id":41017865}],"con":true,"img":false}]}
{"op":"mcm","clk":"5353089268","pt":1646208597852,"mc":[{"id":"1.195453762","rc":[{"atb":[[26,0.14]],"id":41017865}],"con":true,"img":false}]}
{"op":"mcm","clk":"5353089446","pt":1646208601689,"mc":[{"id":"1.195453762","rc":[{"atl":[[270,2.17]],"id":37178159}],"con":true,"img":false}]}
{"op":"mcm","clk":"5353089512","pt":1646208603092,"mc":[{"id":"1.195453762","rc":[{"atb":[[3.85,26.39],[3.9,35.52]],"id":43167125},{"atl":[[7.4,0],[7.6,3.03]],"id":43167125}],"con":true,"img":false}]}
{"op":"mcm","clk":"5353089631","pt":1646208605473,"mc":[{"id":"1.195453762","rc":[{"atb":[[3.85,2],[4,28.88]],"id":43167125}],"con":true,"img":false}]}
{"op":"mcm","clk":"5353089694","pt":1646208606563,"mc":[{"id":"1.195453762","rc":[{"atb":[[4.1,5.41]],"id":43167125}],"con":true,"img":false}]}
{"op":"mcm","clk":"5353090035","pt":1646208614778,"mc":[{"id":"1.195453762","rc":[{"atb":[[2.28,5.96]],"id":43167124}],"con":true,"img":false}]}
{"op":"mcm","clk":"5353090062","pt":1646208615396,"mc":[{"id":"1.195453762","rc":[{"atb":[[2.26,2.5]],"id":43167124},{"atb":[[4,27.33]],"id":43167125}],"con":true,"img":false}]}
{"op":"mcm","clk":"5353090070","pt":1646208615499,"mc":[{"id":"1.195453762","rc":[{"atb":[[2.3,1.47]],"id":43167124},{"atb":[[4.2,1.55]],"id":43167125}],"con":true,"img":false}]}
{"op":"mcm","clk":"5353090089","pt":1646208616065,"mc":[{"id":"1.195453762","rc":[{"atb":[[2.26,0]],"id":43167124}],"con":true,"img":false}]}
{"op":"mcm","clk":"5353090142","pt":1646208617100,"mc":[{"id":"1.195453762","rc":[{"atb":[[2.18,1.27],[1.04,1.67]],"id":43167124}],"con":true,"img":false}]}
{"op":"mcm","clk":"5353090151","pt":1646208617264,"mc":[{"id":"1.195453762","rc":[{"atb":[[1.04,1.66]],"id":43167124}],"con":true,"img":false}]}
{"op":"mcm","clk":"5353090166","pt":1646208617476,"mc":[{"id":"1.195453762","rc":[{"atb":[[1.04,0]],"id":43167124}],"con":true,"img":false}]}
{"op":"mcm","clk":"5353090173","pt":1646208617572,"mc":[{"id":"1.195453762","rc":[{"atb":[[2.26,1.66]],"id":43167124}],"con":true,"img":false}]}
{"op":"mcm","clk":"5353090232","pt":1646208618798,"mc":[{"id":"1.195453762","rc":[{"atb":[[4.1,0]],"id":43167125}],"con":true,"img":false}]}
{"op":"mcm","clk":"5353090264","pt":1646208619105,"mc":[{"id":"1.195453762","rc":[{"atl":[[9.6,0]],"id":43167126},{"atl":[[10,1.33]],"id":43167127}],"con":true,"img":false}]}
{"op":"mcm","clk":"5353090270","pt":1646208619166,"mc":[{"id":"1.195453762","rc":[{"atl":[[250,1.24]],"id":37178159}],"con":true,"img":false}]}
{"op":"mcm","clk":"5353090275","pt":1646208619270,"mc":[{"id":"1.195453762","rc":[{"atl":[[250,3.24]],"id":37178159},{"atb":[[4.2,0]],"id":43167125}],"con":true,"img":false}]}
{"op":"mcm","clk":"5353090280","pt":1646208619371,"mc":[{"id":"1.195453762","rc":[{"atl":[[240,2],[260,1.22],[270,0.17]],"id":37178159},{"atb":[[4,0.94],[3.95,27.97],[4.1,1.55]],"id":43167125}],"con":true,"img":false}]}
{"op":"mcm","clk":"5353090293","pt":1646208619578,"mc":[{"id":"1.195453762","rc":[{"atb":[[4,28.91],[3.95,0]],"id":43167125}],"con":true,"img":false}]}
{"op":"mcm","clk":"5353090303","pt":1646208619879,"mc":[{"id":"1.195453762","rc":[{"atl":[[260,0]],"id":37178159}],"con":true,"img":false}]}
{"op":"mcm","clk":"5353090310","pt":1646208619983,"mc":[{"id":"1.195453762","rc":[{"atl":[[240,3.22]],"id":37178159}],"con":true,"img":false}]}
{"op":"mcm","clk":"5353090379","pt":1646208621384,"mc":[{"id":"1.195453762","rc":[{"atb":[[2.28,0]],"id":43167124}],"con":true,"img":false}]}
{"op":"mcm","clk":"5353090394","pt":1646208621811,"mc":[{"id":"1.195453762","rc":[{"atb":[[2.2,0]],"id":43167124}],"con":true,"img":false}]}
{"op":"mcm","clk":"5353090401","pt":1646208621903,"mc":[{"id":"1.195453762","rc":[{"spl":[[1.01,37.02]],"id":37178159},{"spl":[[1.01,37.02]],"id":41017865},{"spl":[[1.01,37.02]],"id":43167128},{"spl":[[1.01,37.02]],"id":42688789}],"con":true,"img":false}]}
{"op":"mcm","clk":"5353090536","pt":1646208624695,"mc":[{"id":"1.195453762","rc":[{"atb":[[4.1,4.41]],"id":43167125}],"con":true,"img":false}]}
{"op":"mcm","clk":"5353090542","pt":1646208624799,"mc":[{"id":"1.195453762","rc":[{"atl":[[700,1],[710,0]],"id":37178159},{"atl":[[300,0],[290,1]],"id":41017865},{"atl":[[10.5,3.37]],"id":43167126},{"atl":[[10.5,2.11],[11,0]],"id":43167127},{"atl":[[32,1],[34,2.47]],"id":43167128},{"atl":[[32,3],[34,0]],"id":42688789},{"atb":[[3.55,0],[3.65,46.43]],"id":43167125}],"con":true,"img":false}]}
{"op":"mcm","clk":"5353090547","pt":1646208624902,"mc":[{"id":"1.195453762","rc":[{"atl":[[11,5.85]],"id":43167126},{"atl":[[30,2.24]],"id":42688789}],"con":true,"img":false}]}
{"op":"mcm","clk":"5353090562","pt":1646208625210,"mc":[{"id":"1.195453762","rc":[{"atl":[[10.5,2.11]],"id":43167126},{"atl":[[10,0]],"id":43167127},{"atl":[[34,1.24]],"id":43167128},{"atl":[[1000,0]],"id":42688789}],"con":true,"img":false}]}
{"op":"mcm","clk":"5353090568","pt":1646208625313,"mc":[{"id":"1.195453762","rc":[{"atl":[[270,0]],"id":37178159},{"atl":[[9.8,2.29]],"id":43167126},{"atl":[[9.8,2.36]],"id":43167127},{"atl":[[36,1.22]],"id":43167128},{"atl":[[30,3.58]],"id":42688789}],"con":true,"img":false}]}
{"op":"mcm","clk":"5353090575","pt":1646208625373,"mc":[{"id":"1.195453762","rc":[{"atl":[[700,0],[710,1],[310,0.17]],"id":37178159},{"atl":[[10.5,0],[11,7.85]],"id":43167126},{"atl":[[10.5,0],[11,2]],"id":43167127},{"atl":[[32,0],[34,2.24]],"id":43167128},{"atl":[[32,2]],"id":42688789}],"con":true,"img":false}]}
{"op":"mcm","clk":"5353090584","pt":1646208625584,"mc":[{"id":"1.195453762","rc":[{"atb":[[2.3,0]],"id":43167124}],"con":true,"img":false}]}
{"op":"mcm","clk":"5353090589","pt":1646208625686,"mc":[{"id":"1.195453762","rc":[{"atb":[[2.18,2.75]],"id":43167124}],"con":true,"img":false}]}
{"op":"mcm","clk":"5353090599","pt":1646208625885,"mc":[{"id":"1.195453762","rc":[{"atl":[[9.8,1.02]],"id":43167126},{"atl":[[9.8,1.03]],"id":43167127},{"atl":[[36,0]],"id":43167128}],"con":true,"img":false}]}
{"op":"mcm","clk":"5353090602","pt":1646208625985,"mc":[{"id":"1.195453762","rc":[{"atl":[[1000,1.26]],"id":43167126},{"atl":[[1000,1.33]],"id":43167127},{"atl":[[34,3.47]],"id":43167128}],"con":true,"img":false}]}
{"op":"mcm","clk":"5353090623","pt":1646208626398,"mc":[{"id":"1.195453762","rc":[{"atb":[[2.18,11.38]],"id":43167124}],"con":true,"img":false}]}
{"op":"mcm","clk":"5353090631","pt":1646208626604,"mc":[{"id":"1.195453762","rc":[{"atb":[[2.18,15.14]],"id":43167124}],"con":true,"img":false}]}
{"op":"mcm","clk":"5353090665","pt":1646208627384,"mc":[{"id":"1.195453762","rc":[{"atb":[[1.03,2.25],[14.5,0]],"id":43167128}],"con":true,"img":false}]}
{"op":"mcm","clk":"5353090676","pt":1646208627584,"mc":[{"id":"1.195453762","rc":[{"atb":[[1.03,0.23]],"id":43167128}],"con":true,"img":false}]}
{"op":"mcm","clk":"5353090734","pt":1646208628818,"mc":[{"id":"1.195453762","rc":[{"atb":[[5.2,5.64]],"id":43167126},{"atb":[[1.03,0]],"id":43167128}],"con":true,"img":false}]}
{"op":"mcm","clk":"5353090742","pt":1646208628921,"mc":[{"id":"1.195453762","rc":[{"atb":[[16,0.23]],"id":43167128}],"con":true,"img":false}]}
{"op":"mcm","clk":"5353090778","pt":1646208629693,"mc":[{"id":"1.195453762","rc":[{"atl":[[3.25,0]],"id":43167124}],"con":true,"img":false}]}
{"op":"mcm","clk":"5353090920","pt":1646208632683,"mc":[{"id":"1.195453762","rc":[{"atl":[[3.25,4.62]],"id":43167124}],"con":true,"img":false}]}
{"op":"mcm","clk":"5353091010","pt":1646208634812,"mc":[{"id":"1.195453762","rc":[{"atb":[[3.55,19.61]],"id":43167125}],"con":true,"img":false}]}
{"op":"mcm","clk":"5353091014","pt":1646208634917,"mc":[{"id":"1.195453762","rc":[{"atl":[[34,1.52]],"id":42688789}],"con":true,"img":false}]}
{"op":"mcm","clk":"5353091088","pt":1646208636617,"mc":[{"id":"1.195453762","rc":[{"atl":[[1000,2.58]],"id":43167127}],"con":true,"img":false}]}
{"op":"mcm","clk":"5353091099","pt":1646208636824,"mc":[{"id":"1.195453762","rc":[{"atl":[[1000,1.33]],"id":43167127}],"con":true,"img":false}]}
{"op":"mcm","clk":"5353091105","pt":1646208636927,"mc":[{"id":"1.195453762","rc":[{"atl":[[9.6,1.24]],"id":43167127}],"con":true,"img":false}]}
{"op":"mcm","clk":"5353091464","pt":1646208644816,"mc":[{"id":"1.195453762","rc":[{"atb":[[3.25,0],[3.45,89.56]],"id":43167125}],"con":true,"img":false}]}
{"op":"mcm","clk":"5353091468","pt":1646208644918,"mc":[{"id":"1.195453762","rc":[{"atl":[[42,3.05],[46,0]],"id":42688789}],"con":true,"img":false}]}
{"op":"mcm","clk":"5353091691","pt":1646208650423,"mc":[{"id":"1.195453762","rc":[{"atl":[[38,1.35]],"id":42688789}],"con":true,"img":false}]}
{"op":"mcm","clk":"5353091696","pt":1646208650526,"mc":[{"id":"1.195453762","rc":[{"atl":[[36,2.72]],"id":42688789}],"con":true,"img":false}]}
{"op":"mcm","clk":"5353091701","pt":1646208650630,"mc":[{"id":"1.195453762","rc":[{"atl":[[30,2.24]],"id":42688789}],"con":true,"img":false}]}
{"op":"mcm","clk":"5353091706","pt":1646208650734,"mc":[{"id":"1.195453762","rc":[{"atl":[[1000,1.33]],"id":42688789}],"con":true,"img":false}]}
{"op":"mcm","clk":"5353091896","pt":1646208654846,"mc":[{"id":"1.195453762","rc":[{"spn":30.58,"spf":1.0,"id":37178159},{"spn":19.09,"spf":1.0,"id":41017865},{"spn":5.46,"spf":1.0,"id":43167126},{"spn":12.26,"spf":1.0,"id":43167128},{"spn":12.23,"spf":1.0,"id":42688789},{"spn":2.16,"spf":1.0,"id":43167124},{"atb":[[3.35,85.1]],"id":43167125},{"spn":4.02,"spf":1.0,"id":43167125}],"con":true,"img":false}]}
{"op":"mcm","clk":"5353091902","pt":1646208654948,"mc":[{"id":"1.195453762","rc":[{"atb":[[3.35,53.19]],"id":43167125}],"con":true,"img":false}]}
{"op":"mcm","clk":"5353091924","pt":1646208655461,"mc":[{"id":"1.195453762","rc":[{"atl":[[36,0]],"id":42688789}],"con":true,"img":false}]}
{"op":"mcm","clk":"5353091929","pt":1646208655563,"mc":[{"id":"1.195453762","rc":[{"atl":[[38,4.07]],"id":42688789}],"con":true,"img":false}]}
{"op":"mcm","clk":"5353092263","pt":1646208662682,"mc":[{"id":"1.195453762","rc":[{"atl":[[9.8,0]],"id":43167126}],"con":true,"img":false}]}
{"op":"mcm","clk":"5353092269","pt":1646208662743,"mc":[{"id":"1.195453762","rc":[{"atl":[[1000,3.52]],"id":43167126}],"con":true,"img":false}]}
{"op":"mcm","clk":"5353092283","pt":1646208662943,"mc":[{"id":"1.195453762","rc":[{"atl":[[1000,2.22]],"id":43167126}],"con":true,"img":false}]}
{"op":"mcm","clk":"5353092298","pt":1646208663151,"mc":[{"id":"1.195453762","rc":[{"atl":[[1000,1.26]],"id":43167126}],"con":true,"img":false}]}
{"op":"mcm","clk":"5353092306","pt":1646208663253,"mc":[{"id":"1.195453762","rc":[{"atl":[[10.5,0.95]],"id":43167126}],"con":true,"img":false}]}
{"op":"mcm","clk":"5353092351","pt":1646208663977,"mc":[{"id":"1.195453762","rc":[{"atl":[[1000,0]],"id":43167126}],"con":true,"img":false}]}
{"op":"mcm","clk":"5353092358","pt":1646208664080,"mc":[{"id":"1.195453762","rc":[{"atl":[[10.5,2.22]],"id":43167126}],"con":true,"img":false}]}
{"op":"mcm","clk":"5353092717","pt":1646208671586,"mc":[{"id":"1.195453762","rc":[{"atl":[[1000,1.24]],"id":43167126},{"atl":[[9.6,0]],"id":43167127}],"con":true,"img":false}]}
{"op":"mcm","clk":"5353092733","pt":1646208671850,"mc":[{"id":"1.195453762","rc":[{"atl":[[1000,0]],"id":43167126}],"con":true,"img":false}]}
{"op":"mcm","clk":"5353092737","pt":1646208671948,"mc":[{"id":"1.195453762","rc":[{"atl":[[10,1.24]],"id":43167126}],"con":true,"img":false}]}
{"op":"mcm","clk":"5353092753","pt":1646208672292,"mc":[{"id":"1.195453762","rc":[{"atl":[[10.5,0.95]],"id":43167126}],"con":true,"img":false}]}
{"op":"mcm","clk":"5353092759","pt":1646208672357,"mc":[{"id":"1.195453762","rc":[{"atl":[[10,2.51]],"id":43167126}],"con":true,"img":false}]}
{"op":"mcm","clk":"5353092878","pt":1646208674773,"mc":[{"id":"1.195453762","rc":[{"atl":[[10.5,0]],"id":43167126}],"con":true,"img":false}]}
{"op":"mcm","clk":"5353092884","pt":1646208674878,"mc":[{"id":"1.195453762","rc":[{"atl":[[1000,2.25]],"id":43167126}],"con":true,"img":false}]}
{"op":"mcm","clk":"5353092894","pt":1646208675083,"mc":[{"id":"1.195453762","rc":[{"atl":[[1000,1.02]],"id":43167126}],"con":true,"img":false}]}
{"op":"mcm","clk":"5353092903","pt":1646208675289,"mc":[{"id":"1.195453762","rc":[{"atl":[[1000,0]],"id":43167126}],"con":true,"img":false}]}
{"op":"mcm","clk":"5353092909","pt":1646208675392,"mc":[{"id":"1.195453762","rc":[{"atl":[[9.8,1.02]],"id":43167126}],"con":true,"img":false}]}
{"op":"mcm","clk":"5353093370","pt":1646208685871,"mc":[{"id":"1.195453762","rc":[{"atl":[[3.7,0]],"id":43167124}],"con":true,"img":false}]}
{"op":"mcm","clk":"5353093936","pt":1646208697507,"mc":[{"id":"1.195453762","rc":[{"atl":[[9.4,0]],"id":43167127},{"atl":[[3.7,5.47]],"id":43167124}],"con":true,"img":false}]}
{"op":"mcm","clk":"5353093953","pt":1646208697816,"mc":[{"id":"1.195453762","rc":[{"atl":[[1000,3]],"id":43167127}],"con":true,"img":false}]}
{"op":"mcm","clk":"5353093972","pt":1646208698076,"mc":[{"id":"1.195453762","rc":[{"atl":[[1000,0.71]],"id":43167127}],"con":true,"img":false}]}
{"op":"mcm","clk":"5353093981","pt":1646208698181,"mc":[{"id":"1.195453762","rc":[{"atl":[[11,3.33]],"id":43167127}],"con":true,"img":false}]}
{"op":"mcm","clk":"5353094017","pt":1646208698799,"mc":[{"id":"1.195453762","rc":[{"atl":[[1000,0]],"id":43167127}],"con":true,"img":false}]}
{"op":"mcm","clk":"5353094024","pt":1646208698900,"mc":[{"id":"1.195453762","rc":[{"atl":[[9.6,0.71]],"id":43167127}],"con":true,"img":false}]}
{"op":"mcm","clk":"5353094417","pt":1646208706620,"mc":[{"id":"1.195453762","rc":[{"atl":[[10,1.26]],"id":43167126}],"con":true,"img":false}]}
{"op":"mcm","clk":"5353094978","pt":1646208720124,"mc":[{"id":"1.195453762","rc":[{"atb":[[4.8,5.26],[4.9,0],[5.1,14.27]],"id":43167126},{"atb":[[5.3,0],[5.1,37.1]],"id":43167127},{"atl":[[32,3],[30,1.24]],"id":42688789},{"atb":[[1.78,0],[1.76,0],[1.75,26.67]],"id":43167124}],"con":true,"img":false}]}
{"op":"mcm","clk":"5353094989","pt":1646208720431,"mc":[{"id":"1.195453762","rc":[{"atb":[[5,25.75]],"id":43167126}],"con":true,"img":false}]}
{"op":"mcm","clk":"5353094992","pt":1646208720534,"mc":[{"id":"1.195453762","rc":[{"atb":[[4.8,38.16]],"id":43167126}],"con":true,"img":false}]}
{"op":"mcm","clk":"5353095151","pt":1646208724047,"mc":[{"id":"1.195453762","rc":[{"atl":[[1000,1.24]],"id":43167126}],"con":true,"img":false}]}
{"op":"mcm","clk":"5353095166","pt":1646208724357,"mc":[{"id":"1.195453762","rc":[{"atl":[[700,1],[710,0]],"id":37178159},{"atl":[[10.5,2.11],[11,5.85],[1000,0]],"id":43167126},{"atl":[[10.5,2.11],[11,1.33]],"id":43167127},{"atl":[[32,1],[34,2.47]],"id":43167128}],"con":true,"img":false}]}
{"op":"mcm","clk":"5353095170","pt":1646208724460,"mc":[{"id":"1.195453762","rc":[{"atl":[[9.6,1.24]],"id":43167126}],"con":true,"img":false}]}
{"op":"mcm","clk":"5353095354","pt":1646208728834,"mc":[{"id":"1.195453762","rc":[{"atb":[[5.2,0]],"id":43167126}],"con":true,"img":false}]}
{"op":"mcm","clk":"5353095405","pt":1646208730167,"mc":[{"id":"1.195453762","rc":[{"atl":[[36,1.43]],"id":42688789},{"atb":[[1.73,68.49]],"id":43167124}],"con":true,"img":false}]}
{"op":"mcm","clk":"5353095419","pt":1646208730425,"mc":[{"id":"1.195453762","rc":[{"atb":[[60,2]],"id":37178159},{"atb":[[13,0]],"id":42688789},{"atl":[[34,0],[38,2.72],[42,0]],"id":42688789}],"con":true,"img":false}]}
{"op":"mcm","clk":"5353095424","pt":1646208730528,"mc":[{"id":"1.195453762","rc":[{"atb":[[44,2.72],[55,3.91],[60,0]],"id":37178159},{"atb":[[12.5,17.23]],"id":42688789}],"con":true,"img":false}]}
{"op":"mcm","clk":"5353095428","pt":1646208730630,"mc":[{"id":"1.195453762","rc":[{"atb":[[42,4.76],[55,1.91]],"id":37178159},{"atl":[[10,0]],"id":43167126},{"atl":[[11,0]],"id":43167127},{"atl":[[34,1.24]],"id":43167128}],"con":true,"img":false}]}
{"op":"mcm","clk":"5353095432","pt":1646208730733,"mc":[{"id":"1.195453762","rc":[{"atl":[[9.8,2.29]],"id":43167126},{"atl":[[9.8,2.36]],"id":43167127},{"atl":[[36,1.22]],"id":43167128}],"con":true,"img":false}]}
{"op":"mcm","clk":"5353095469","pt":1646208731454,"mc":[{"id":"1.195453762","rc":[{"atb":[[14.5,0]],"id":42688789}],"con":true,"img":false}]}
{"op":"mcm","clk":"5353095474","pt":1646208731557,"mc":[{"id":"1.195453762","rc":[{"atb":[[1.01,1.58],[13.5,3.01]],"id":42688789}],"con":true,"img":false}]}
{"op":"mcm","clk":"5353095478","pt":1646208731660,"mc":[{"id":"1.195453762","rc":[{"atb":[[14,0.27]],"id":42688789}],"con":true,"img":false}]}
{"op":"mcm","clk":"5353095488","pt":1646208731867,"mc":[{"id":"1.195453762","rc":[{"atl":[[9.8,1.33]],"id":43167127}],"con":true,"img":false}]}
{"op":"mcm","clk":"5353095495","pt":1646208731919,"mc":[{"id":"1.195453762","rc":[{"atl":[[1000,2.25]],"id":43167127}],"con":true,"img":false}]}
{"op":"mcm","clk":"5353095508","pt":1646208732125,"mc":[{"id":"1.195453762","rc":[{"atl":[[1000,0.91]],"id":43167127}],"con":true,"img":false}]}
{"op":"mcm","clk":"5353095514","pt":1646208732227,"mc":[{"id":"1.195453762","rc":[{"atb":[[5.7,2.5]],"id":43167126},{"atb":[[1.01,0],[14,2.35]],"id":42688789},{"atb":[[4.2,2.5]],"id":43167125}],"con":true,"img":false}]}
{"op":"mcm","clk":"5353095519","pt":1646208732330,"mc":[{"id":"1.195453762","rc":[{"atl":[[1000,0],[9.8,0]],"id":43167127},{"atb":[[14,3.94]],"id":42688789}],"con":true,"img":false}]}
{"op":"mcm","clk":"5353095528","pt":1646208732435,"mc":[{"id":"1.195453762","rc":[{"atl":[[10.5,3.44],[11,0.91]],"id":43167127}],"con":true,"img":false}]}
{"op":"mcm","clk":"5353095558","pt":1646208732948,"mc":[{"id":"1.195453762","rc":[{"atb":[[5.6,0]],"id":43167126},{"atb":[[4.1,2.86]],"id":43167125}],"con":true,"img":false}]}
{"op":"mcm","clk":"5353095562","pt":1646208733051,"mc":[{"id":"1.195453762","rc":[{"atb":[[5.8,1.62]],"id":43167126},{"atb":[[4.3,2.19],[4.1,0]],"id":43167125}],"con":true,"img":false}]}
{"op":"mcm","clk":"5353095590","pt":1646208733773,"mc":[{"id":"1.195453762","rc":[{"atb":[[5.7,0]],"id":43167126},{"atb":[[4.2,0]],"id":43167125}],"con":true,"img":false}]}
{"op":"mcm","clk":"5353095614","pt":1646208734339,"mc":[{"id":"1.195453762","rc":[{"atb":[[4.6,15.89]],"id":43167126},{"atb":[[4.9,32.05]],"id":43167127}],"con":true,"img":false}]}
{"op":"mcm","clk":"5353095618","pt":1646208734443,"mc":[{"id":"1.195453762","rc":[{"atb":[[4.9,12.82]],"id":43167127}],"con":true,"img":false}]}
{"op":"mcm","clk":"5353095625","pt":1646208734648,"mc":[{"id":"1.195453762","rc":[{"atb":[[5.8,0]],"id":43167126},{"atb":[[4.3,0.64]],"id":43167125}],"con":true,"img":false}]}
{"op":"mcm","clk":"5353095627","pt":1646208734751,"mc":[{"id":"1.195453762","rc":[{"atb":[[5.6,1.62]],"id":43167126},{"atl":[[11,0]],"id":43167127},{"atb":[[4,0.94],[3.95,29.55],[4.1,1.55]],"id":43167125}],"con":true,"img":false}]}
{"op":"mcm","clk":"5353095633","pt":1646208734854,"mc":[{"id":"1.195453762","rc":[{"atl":[[1000,2.25]],"id":43167127}],"con":true,"img":false}]}
{"op":"mcm","clk":"5353095648","pt":1646208735060,"mc":[{"id":"1.195453762","rc":[{"atl":[[1000,1]],"id":43167127}],"con":true,"img":false}]}
{"op":"mcm","clk":"5353095667","pt":1646208735368,"mc":[{"id":"1.195453762","rc":[{"atl":[[1000,0]],"id":43167127}],"con":true,"img":false}]}
{"op":"mcm","clk":"5353095672","pt":1646208735471,"mc":[{"id":"1.195453762","rc":[{"atl":[[10,1]],"id":43167127},{"atl":[[40,0]],"id":42688789},{"atb":[[4.1,0]],"id":43167125}],"con":true,"img":false}]}
{"op":"mcm","clk":"5353095677","pt":1646208735525,"mc":[{"id":"1.195453762","rc":[{"atl":[[46,2.72]],"id":42688789},{"atb":[[4,2.49]],"id":43167125}],"con":true,"img":false}]}
{"op":"mcm","clk":"5353095696","pt":1646208735933,"mc":[{"id":"1.195453762","rc":[{"atl":[[10.5,2.11]],"id":43167127},{"atb":[[4,5.4]],"id":43167125}],"con":true,"img":false}]}
{"op":"mcm","clk":"5353095699","pt":1646208736035,"mc":[{"id":"1.195453762","rc":[{"atl":[[10,2.34]],"id":43167127}],"con":true,"img":false}]}
{"op":"mcm","clk":"5353095707","pt":1646208736240,"mc":[{"id":"1.195453762","rc":[{"atb":[[5.7,2.5]],"id":43167126},{"atb":[[4.1,2.5]],"id":43167125}],"con":true,"img":false}]}
{"op":"mcm","clk":"5353095743","pt":1646208736960,"mc":[{"id":"1.195453762","rc":[{"atb":[[4,3.85]],"id":43167125}],"con":true,"img":false}]}
{"op":"mcm","clk":"5353095748","pt":1646208737063,"mc":[{"id":"1.195453762","rc":[{"atb":[[4.2,1.55]],"id":43167125}],"con":true,"img":false}]}
{"op":"mcm","clk":"5353095828","pt":1646208738969,"mc":[{"id":"1.195453762","rc":[{"atb":[[4.1,0]],"id":43167125}],"con":true,"img":false}]}
{"op":"mcm","clk":"5353095844","pt":1646208739334,"mc":[{"id":"1.195453762","rc":[{"atb":[[4.2,0]],"id":43167125}],"con":true,"img":false}]}
{"op":"mcm","clk":"5353095848","pt":1646208739437,"mc":[{"id":"1.195453762","rc":[{"atb":[[4.1,1.55]],"id":43167125}],"con":true,"img":false}]}
{"op":"mcm","clk":"5353095881","pt":1646208740155,"mc":[{"id":"1.195453762","rc":[{"atl":[[40,1.92]],"id":42688789},{"atb":[[1.71,105.63]],"id":43167124}],"con":true,"img":false}]}
{"op":"mcm","clk":"5353095890","pt":1646208740360,"mc":[{"id":"1.195453762","rc":[{"atb":[[1.96,0]],"id":43167124}],"con":true,"img":false}]}
{"op":"mcm","clk":"5353095896","pt":1646208740463,"mc":[{"id":"1.195453762","rc":[{"atb":[[2.02,57.62]],"id":43167124}],"con":true,"img":false}]}
{"op":"mcm","clk":"5353095939","pt":1646208741547,"mc":[{"id":"1.195453762","rc":[{"atl":[[1000,1.24]],"id":43167127}],"con":true,"img":false}]}
{"op":"mcm","clk":"5353095949","pt":1646208741856,"mc":[{"id":"1.195453762","rc":[{"atl":[[1000,0]],"id":43167127}],"con":true,"img":false}]}
{"op":"mcm","clk":"5353095953","pt":1646208741959,"mc":[{"id":"1.195453762","rc":[{"atl":[[9.8,1.24]],"id":43167127}],"con":true,"img":false}]}
{"op":"mcm","clk":"5353095978","pt":1646208742579,"mc":[{"id":"1.195453762","rc":[{"atl":[[10,1]],"id":43167127}],"con":true,"img":false}]}
{"op":"mcm","clk":"5353095985","pt":1646208742632,"mc":[{"id":"1.195453762","rc":[{"atl":[[9.8,2.58]],"id":43167127}],"con":true,"img":false}]}
{"op":"mcm","clk":"5353096039","pt":1646208743868,"mc":[{"id":"1.195453762","rc":[{"atl":[[10,0]],"id":43167127}],"con":true,"img":false}]}
{"op":"mcm","clk":"5353096057","pt":1646208744176,"mc":[{"id":"1.195453762","rc":[{"atl":[[1000,2.25]],"id":43167127}],"con":true,"img":false}]}
{"op":"mcm","clk":"5353096071","pt":1646208744381,"mc":[{"id":"1.195453762","rc":[{"atb":[[4.4,22.06]],"id":43167126},{"atb":[[4.7,20.27]],"id":43167127},{"atl":[[1000,1.05]],"id":43167127}],"con":true,"img":false}]}
{"op":"mcm","clk":"5353096085","pt":1646208744643,"mc":[{"id":"1.195453762","rc":[{"atl":[[1000,0]],"id":43167127}],"con":true,"img":false}]}
{"op":"mcm","clk":"5353096089","pt":1646208744743,"mc":[{"id":"1.195453762","rc":[{"atl":[[9.6,1.77]],"id":43167127}],"con":true,"img":false}]}
{"op":"mcm","clk":"5353096120","pt":1646208745366,"mc":[{"id":"1.195453762","rc":[{"atl":[[38,0]],"id":42688789},{"atb":[[4,33.4]],"id":43167125}],"con":true,"img":false}]}
{"op":"mcm","clk":"5353096127","pt":1646208745546,"mc":[{"id":"1.195453762","rc":[{"atl":[[36,4.15]],"id":42688789},{"atb":[[3.95,0]],"id":43167125}],"con":true,"img":false}]}
{"op":"mcm","clk":"5353096204","pt":1646208746863,"mc":[{"id":"1.195453762","rc":[{"atb":[[2.04,9.72]],"id":43167124}],"con":true,"img":false}]}
{"op":"mcm","clk":"5353096268","pt":1646208748050,"mc":[{"id":"1.195453762","rc":[{"atb":[[4,30.49]],"id":43167125}],"con":true,"img":false}]}
{"op":"mcm","clk":"5353096349","pt":1646208749852,"mc":[{"id":"1.195453762","rc":[{"atl":[[3.25,0]],"id":43167124}],"con":true,"img":false}]}
{"op":"mcm","clk":"5353096363","pt":1646208750161,"mc":[{"id":"1.195453762","rc":[{"atl":[[44,2.91]],"id":42688789},{"atb":[[1.69,181.16],[1.72,0],[1.74,0]],"id":43167124}],"con":true,"img":false}]}
{"op":"mcm","clk":"5353096440","pt":1646208751660,"mc":[{"id":"1.195453762","rc":[{"atb":[[2.4,4.93]],"id":43167124}],"con":true,"img":false}]}
{"op":"mcm","clk":"5353096450","pt":1646208751764,"mc":[{"id":"1.195453762","rc":[{"atb":[[1.79,25.32]],"id":43167124}],"con":true,"img":false}]}
{"op":"mcm","clk":"5353096458","pt":1646208751867,"mc":[{"id":"1.195453762","rc":[{"atb":[[4.5,29.43],[4.7,0]],"id":43167126},{"atb":[[1.75,0]],"id":43167124}],"con":true,"img":false}]}
{"op":"mcm","clk":"5353096482","pt":1646208752280,"mc":[{"id":"1.195453762","rc":[{"atl":[[2.98,1.24]],"id":43167124}],"con":true,"img":false}]}
{"op":"mcm","clk":"5353096489","pt":1646208752382,"mc":[{"id":"1.195453762","rc":[{"atl":[[1000,1.31]],"id":43167124}],"con":true,"img":false}]}
{"op":"mcm","clk":"5353096515","pt":1646208752745,"mc":[{"id":"1.195453762","rc":[{"atb":[[17,0]],"id":41017865}],"con":true,"img":false}]}
{"op":"mcm","clk":"5353096518","pt":1646208752848,"mc":[{"id":"1.195453762","rc":[{"atb":[[14.5,7.14]],"id":41017865}],"con":true,"img":false}]}
{"op":"mcm","clk":"5353096582","pt":1646208754084,"mc":[{"id":"1.195453762","rc":[{"atb":[[4.1,4.41]],"id":43167125}],"con":true,"img":false}]}
{"op":"mcm","clk":"5353096602","pt":1646208754393,"mc":[{"id":"1.195453762","rc":[{"atb":[[4.2,39.06]],"id":43167126},{"atb":[[4.5,65.14]],"id":43167127}],"con":true,"img":false}]}
{"op":"mcm","clk":"5353096642","pt":1646208755371,"mc":[{"id":"1.195453762","rc":[{"atb":[[4.8,5.26]],"id":43167126}],"con":true,"img":false}]}
{"op":"mcm","clk":"5353096645","pt":1646208755474,"mc":[{"id":"1.195453762","rc":[{"atb":[[4.7,32.9]],"id":43167126}],"con":true,"img":false}]}
{"op":"mcm","clk":"5353096713","pt":1646208757275,"mc":[{"id":"1.195453762","rc":[{"atl":[[9.6,1.05]],"id":43167127}],"con":true,"img":false}]}
{"op":"mcm","clk":"5353096731","pt":1646208757586,"mc":[{"id":"1.195453762","rc":[{"atl":[[1000,1.67]],"id":43167127},{"atb":[[2.04,0]],"id":43167124}],"con":true,"img":false}]}
{"op":"mcm","clk":"5353096736","pt":1646208757689,"mc":[{"id":"1.195453762","rc":[{"atl":[[9.8,1.24]],"id":43167127}],"con":true,"img":false}]}
{"op":"mcm","clk":"5353096741","pt":1646208757791,"mc":[{"id":"1.195453762","rc":[{"atl":[[10.5,3.44]],"id":43167127}],"con":true,"img":false}]}
{"op":"mcm","clk":"5353096754","pt":1646208758098,"mc":[{"id":"1.195453762","rc":[{"atl":[[1000,0.73]],"id":43167127}],"con":true,"img":false}]}
{"op":"mcm","clk":"5353096766","pt":1646208758357,"mc":[{"id":"1.195453762","rc":[{"atl":[[1000,0]],"id":43167127}],"con":true,"img":false}]}
{"op":"mcm","clk":"5353096770","pt":1646208758461,"mc":[{"id":"1.195453762","rc":[{"atl":[[9.4,0.73]],"id":43167127}],"con":true,"img":false}]}
{"op":"mcm","clk":"5353096794","pt":1646208758973,"mc":[{"id":"1.195453762","rc":[{"atl":[[2.98,0]],"id":43167124}],"con":true,"img":false}]}
{"op":"mcm","clk":"5353096861","pt":1646208760263,"mc":[{"id":"1.195453762","rc":[{"atl":[[44,0]],"id":43167128}],"con":true,"img":false}]}
{"op":"mcm","clk":"5353096867","pt":1646208760365,"mc":[{"id":"1.195453762","rc":[{"atl":[[40,2.72]],"id":43167128}],"con":true,"img":false}]}
{"op":"mcm","clk":"5353096928","pt":1646208761701,"mc":[{"id":"1.195453762","rc":[{"atl":[[32,2],[29,1]],"id":42688789}],"con":true,"img":false}]}
{"op":"mcm","clk":"5353096936","pt":1646208761805,"mc":[{"id":"1.195453762","rc":[{"atb":[[1.77,64.94]],"id":43167124}],"con":true,"img":false}]}
{"op":"mcm","clk":"5353096962","pt":1646208762476,"mc":[{"id":"1.195453762","rc":[{"atl":[[1000,0]],"id":42688789}],"con":true,"img":false}]}
{"op":"mcm","clk":"5353096967","pt":1646208762577,"mc":[{"id":"1.195453762","rc":[{"atl":[[32,3.33]],"id":42688789}],"con":true,"img":false}]}
{"op":"mcm","clk":"5353096976","pt":1646208762784,"mc":[{"id":"1.195453762","rc":[{"atl":[[44,5.24],[48,0]],"id":42688789}],"con":true,"img":false}]}
{"op":"mcm","clk":"5353096979","pt":1646208762885,"mc":[{"id":"1.195453762","rc":[{"atb":[[1.69,0]],"id":43167124}],"con":true,"img":false}]}
{"op":"mcm","clk":"5353097065","pt":1646208764900,"mc":[{"id":"1.195453762","rc":[{"atb":[[1.79,0],[1.77,0],[1.75,26.67]],"id":43167124}],"con":true,"img":false}]}
{"op":"mcm","clk":"5353097085","pt":1646208765369,"mc":[{"id":"1.195453762","rc":[{"atb":[[1.86,0]],"id":43167124},{"atl":[[8.4,0]],"id":43167125}],"con":true,"img":false}]}
{"op":"mcm","clk":"5353097089","pt":1646208765473,"mc":[{"id":"1.195453762","rc":[{"atb":[[1.96,148.47]],"id":43167124},{"atl":[[8,16.92]],"id":43167125}],"con":true,"img":false}]}
{"op":"mcm","clk":"5353097139","pt":1646208766503,"mc":[{"id":"1.195453762","rc":[{"atb":[[8.6,2.63]],"id":43167128}],"con":true,"img":false}]}
{"op":"mcm","clk":"5353097144","pt":1646208766607,"mc":[{"id":"1.195453762","rc":[{"atb":[[16.5,1.29],[19,0.14],[21,0]],"id":37178159},{"atb":[[13,1.67],[15,0]],"id":41017865},{"atb":[[4.8,0],[4.9,5.13]],"id":43167126},{"atb":[[8,0],[8.4,0],[7.2,11.61],[7.6,0]],"id":43167128},{"atb":[[4.8,0],[4.9,5.13],[4.6,5.56]],"id":42688789},{"atb":[[1.79,25.32]],"id":43167124},{"atb":[[3.55,7.84],[3.65,38.88]],"id":43167125}],"con":true,"img":false}]}
{"op":"mcm","clk":"5353097295","pt":1646208770370,"mc":[{"id":"1.195453762","rc":[{"atl":[[70,0]],"id":41017865}],"con":true,"img":false}]}
{"op":"mcm","clk":"5353097301","pt":1646208770473,"mc":[{"id":"1.195453762","rc":[{"atl":[[65,2.72]],"id":41017865}],"con":true,"img":false}]}
{"op":"mcm","clk":"5353097584","pt":1646208776518,"mc":[{"id":"1.195453762","rc":[{"atl":[[9.8,0]],"id":43167127}],"con":true,"img":false}]}
{"op":"mcm","clk":"5353097589","pt":1646208776622,"mc":[{"id":"1.195453762","rc":[{"atb":[[15.5,3.45],[18,0]],"id":37178159},{"atb":[[12,11.1],[13.5,0]],"id":41017865},{"atb":[[8.2,21.25]],"id":43167128},{"atb":[[4.6,0]],"id":42688789},{"atl":[[32,4.94]],"id":42688789},{"atb":[[1.77,64.94]],"id":43167124},{"atb":[[3.45,79.36]],"id":43167125}],"con":true,"img":false}]}
{"op":"mcm","clk":"5353098019","pt":1646208785408,"mc":[{"id":"1.195453762","rc":[{"spn":27.81,"spf":1.0,"id":37178159},{"spn":18.57,"spf":1.0,"id":41017865},{"spn":5.49,"spf":1.0,"id":43167126},{"spn":12.36,"spf":1.0,"id":42688789},{"spn":2.21,"spf":1.0,"id":43167124},{"atl":[[7.2,0]],"id":43167125}],"con":true,"img":false}]}
{"op":"mcm","clk":"5353098023","pt":1646208785509,"mc":[{"id":"1.195453762","rc":[{"atl":[[5.9,4]],"id":43167125}],"con":true,"img":false}]}
{"op":"mcm","clk":"5353098028","pt":1646208785612,"mc":[{"id":"1.195453762","rc":[{"atb":[[17,0]],"id":37178159},{"atl":[[7.2,4]],"id":43167126},{"atl":[[7.2,2]],"id":43167127},{"atl":[[44,2.33]],"id":42688789},{"atb":[[1.71,0]],"id":43167124},{"atl":[[7,12.53]],"id":43167125}],"con":true,"img":false}]}
{"op":"mcm","clk":"5353098033","pt":1646208785719,"mc":[{"id":"1.195453762","rc":[{"atb":[[7.2,27.74],[6.2,0]],"id":43167128},{"atb":[[4,0.94],[4.1,34.9]],"id":43167125},{"atl":[[7.4,3.12],[5.9,0],[5.6,4],[7.6,0]],"id":43167125}],"con":true,"img":false}]}
{"op":"mcm","clk":"5353098048","pt":1646208786030,"mc":[{"id":"1.195453762","rc":[{"atl":[[7,11.33]],"id":43167125}],"con":true,"img":false}]}
{"op":"mcm","clk":"5353098055","pt":1646208786135,"mc":[{"id":"1.195453762","rc":[{"atl":[[5.5,1.2]],"id":43167125}],"con":true,"img":false}]}
{"op":"mcm","clk":"5353098073","pt":1646208786396,"mc":[{"id":"1.195453762","rc":[{"atb":[[5.7,0]],"id":43167127}],"con":true,"img":false}]}
{"op":"mcm","clk":"5353098078","pt":1646208786507,"mc":[{"id":"1.195453762","rc":[{"atb":[[14.5,5.56]],"id":37178159},{"atb":[[1.01,1.48]],"id":43167127}],"con":true,"img":false}]}
{"op":"mcm","clk":"5353098083","pt":1646208786602,"mc":[{"id":"1.195453762","rc":[{"atb":[[11,7.5]],"id":41017865},{"atb":[[7.8,11.03]],"id":43167128},{"atb":[[4.7,35.67]],"id":42688789},{"atl":[[40,3.21]],"id":42688789},{"atb":[[1.75,100]],"id":43167124}],"con":true,"img":false}]}
{"op":"mcm","clk":"5353098126","pt":1646208787426,"mc":[{"id":"1.195453762","rc":[{"atb":[[5.7,0]],"id":43167126},{"atb":[[5.9,0]],"id":43167127}],"con":true,"img":false}]}
