{"op":"mcm","clk":"5317728466","pt":1646251399803,"mc":[{"id":"1.195532861","marketDefinition":{"bspMarket":true,"turnInPlayEnabled":false,"persistenceEnabled":false,"marketBaseRate":5.0,"eventId":"31275720","eventTypeId":"4339","numberOfWinners":2,"bettingType":"ODDS","marketType":"PLACE","marketTime":"2022-03-03T15:11:00.000Z","suspendTime":"2022-03-03T15:11:00.000Z","bspReconciled":false,"complete":true,"inPlay":false,"crossMatching":false,"runnersVoidable":false,"numberOfActiveRunners":6,"betDelay":0,"status":"OPEN","runners":[{"status":"ACTIVE","sortPriority":1,"id":42252553,"name":"1. Millrose Minnie"},{"status":"ACTIVE","sortPriority":2,"id":28791247,"name":"2. Mustang Murray"},{"status":"ACTIVE","sortPriority":3,"id":37665265,"name":"3. Sims Pride"},{"status":"ACTIVE","sortPriority":4,"id":39947224,"name":"4. Kahuna Donna"},{"status":"ACTIVE","sortPriority":5,"id":23239795,"name":"5. Chuck Jaeger"},{"status":"ACTIVE","sortPriority":6,"id":41529436,"name":"6. So Handsome"}],"regulators":["MR_INT"],"venue":"Romford","countryCode":"GB","discountAllowed":false,"timezone":"Europe/London","openDate":"2022-03-03T13:57:00.000Z","version":4384107295,"name":"To Be Placed","eventName":"Romford 3rd Mar"},"rc":[],"con":true,"img":false}]}
{"op":"mcm","clk":"5317728852","pt":1646251401759,"mc":[{"id":"1.195532861","marketDefinition":{"bspMarket":true,"turnInPlayEnabled":false,"persistenceEnabled":false,"marketBaseRate":5.0,"eventId":"31275720","eventTypeId":"4339","numberOfWinners":2,"bettingType":"ODDS","marketType":"PLACE","marketTime":"2022-03-03T15:11:00.000Z","suspendTime":"2022-03-03T15:11:00.000Z","bspReconciled":false,"complete":true,"inPlay":false,"crossMatching":false,"runnersVoidable":false,"numberOfActiveRunners":6,"betDelay":0,"status":"OPEN","runners":[{"status":"ACTIVE","sortPriority":1,"id":42252553,"name":"1. Millrose Minnie"},{"status":"ACTIVE","sortPriority":2,"id":28791247,"name":"2. Mustang Murray"},{"status":"ACTIVE","sortPriority":3,"id":37665265,"name":"3. Sims Pride"},{"status":"ACTIVE","sortPriority":4,"id":39947224,"name":"4. Kahuna Donna"},{"status":"ACTIVE","sortPriority":5,"id":23239795,"name":"5. Chuck Jaeger"},{"status":"ACTIVE","sortPriority":6,"id":41529436,"name":"6. So Handsome"}],"regulators":["MR_INT"],"venue":"Romford","countryCode":"GB","discountAllowed":true,"timezone":"Europe/London","openDate":"2022-03-03T13:57:00.000Z","version":4384107295,"name":"To Be Placed","eventName":"Romford 3rd Mar"},"rc":[],"con":true,"img":false}]}
{"op":"mcm","clk":"5321081980","pt":1646305950896,"mc":[{"id":"1.195532861","rc":[{"atb":[[1.01,102.04]],"id":28791247},{"spn":"Infinity","spf":"NaN","id":28791247},{"atb":[[1.01,102.04]],"id":39947224},{"spn":"Infinity","spf":"NaN","id":39947224},{"atb":[[1.01,102.04]],"id":37665265},{"spn":"Infinity","spf":"NaN","id":37665265},{"atb":[[1.01,102.04]],"id":41529436},{"spn":"Infinity","spf":"NaN","id":41529436},{"atb":[[1.01,102.04]],"id":42252553},{"spn":"Infinity","spf":"NaN","id":42252553},{"atb":[[1.01,102.04]],"id":23239795},{"spn":"Infinity","spf":"NaN","id":23239795}],"con":true,"img":false}]}
{"op":"mcm","clk":"5321220653","pt":1646307333062,"mc":[{"id":"1.195532861","rc":[{"atl":[[1000,5]],"id":28791247},{"spn":500.5,"spf":"NaN","id":28791247},{"atl":[[1000,5]],"id":39947224},{"spn":500.5,"spf":"NaN","id":39947224},{"atl":[[1000,5]],"id":37665265},{"spn":500.5,"spf":"NaN","id":37665265},{"atl":[[1000,5]],"id":41529436},{"spn":500.5,"spf":"NaN","id":41529436},{"atl":[[1000,5]],"id":42252553},{"spn":500.5,"spf":"NaN","id":42252553},{"atl":[[1000,5]],"id":23239795},{"spn":500.5,"spf":"NaN","id":23239795}],"con":true,"img":false}]}
{"op":"mcm","clk":"5321220690","pt":1646307333475,"mc":[{"id":"1.195532861","rc":[{"atb":[[1.01,4802.04]],"id":28791247},{"atb":[[1.01,4802.04]],"id":39947224},{"atb":[[1.01,4802.04]],"id":37665265},{"atb":[[1.01,4802.04]],"id":41529436},{"atb":[[1.01,4802.04]],"id":42252553},{"atb":[[1.01,4802.04]],"id":23239795}],"con":true,"img":false}]}
{"op":"mcm","clk":"5321902197","pt":1646314354429,"mc":[{"id":"1.195532861","rc":[{"spl":[[1.01,1]],"id":37665265},{"spn":1.01,"spf":1.0,"id":37665265}],"con":true,"img":false}]}
{"op":"mcm","clk":"5322264474","pt":1646318243627,"mc":[{"id":"1.195532861","rc":[{"atl":[[46,2.73]],"id":28791247},{"spn":23.5,"spf":"NaN","id":28791247},{"atl":[[46,2.73]],"id":39947224},{"spn":23.5,"spf":"NaN","id":39947224},{"atl":[[46,2.73]],"id":37665265},{"atl":[[46,2.73]],"id":41529436},{"spn":23.5,"spf":"NaN","id":41529436},{"atl":[[46,2.73]],"id":42252553},{"spn":23.5,"spf":"NaN","id":42252553},{"atl":[[46,2.73]],"id":23239795},{"spn":23.5,"spf":"NaN","id":23239795}],"con":true,"img":false}]}
{"op":"mcm","clk":"5322303152","pt":1646318645478,"mc":[{"id":"1.195532861","rc":[{"atb":[[1.01,5052.04]],"id":28791247},{"atl":[[70,2.17],[80,3.16],[50,1],[60,1.69]],"id":28791247},{"atb":[[1.01,5052.04]],"id":39947224},{"atl":[[70,2.17],[80,3.16],[50,1],[60,1.69]],"id":39947224},{"atb":[[1.01,5052.04]],"id":37665265},{"atl":[[70,2.17],[80,3.16],[50,1],[60,1.69]],"id":37665265},{"atb":[[1.01,5052.04]],"id":41529436},{"atl":[[70,2.17],[80,3.16],[50,1],[60,1.69]],"id":41529436},{"atb":[[1.01,5052.04]],"id":42252553},{"atl":[[70,2.17],[80,3.16],[50,1],[60,1.69]],"id":42252553},{"atb":[[1.01,5052.04]],"id":23239795},{"atl":[[70,2.17],[80,3.16],[50,1],[60,1.69]],"id":23239795}],"con":true,"img":false}]}
{"op":"mcm","clk":"5322305441","pt":1646318670004,"mc":[{"id":"1.195532861","marketDefinition":{"bspMarket":true,"turnInPlayEnabled":false,"persistenceEnabled":false,"marketBaseRate":5.0,"eventId":"31275720","eventTypeId":"4339","numberOfWinners":2,"bettingType":"ODDS","marketType":"PLACE","marketTime":"2022-03-03T15:11:00.000Z","suspendTime":"2022-03-03T15:11:00.000Z","bspReconciled":false,"complete":true,"inPlay":false,"crossMatching":true,"runnersVoidable":false,"numberOfActiveRunners":6,"betDelay":0,"status":"OPEN","runners":[{"status":"ACTIVE","sortPriority":1,"id":42252553,"name":"1. Millrose Minnie"},{"status":"ACTIVE","sortPriority":2,"id":28791247,"name":"2. Mustang Murray"},{"status":"ACTIVE","sortPriority":3,"id":37665265,"name":"3. Sims Pride"},{"status":"ACTIVE","sortPriority":4,"id":39947224,"name":"4. Kahuna Donna"},{"status":"ACTIVE","sortPriority":5,"id":23239795,"name":"5. Chuck Jaeger"},{"status":"ACTIVE","sortPriority":6,"id":41529436,"name":"6. So Handsome"}],"regulators":["MR_INT"],"venue":"Romford","countryCode":"GB","discountAllowed":true,"timezone":"Europe/London","openDate":"2022-03-03T13:57:00.000Z","version":4384107295,"name":"To Be Placed","eventName":"Romford 3rd Mar"},"rc":[],"con":true,"img":false}]}
{"op":"mcm","clk":"5322345352","pt":1646319016718,"mc":[{"id":"1.195532861","rc":[{"spl":[[1.01,1.65]],"id":42252553},{"spn":1.01,"spf":1.0,"id":42252553}],"con":true,"img":false}]}
{"op":"mcm","clk":"5322365026","pt":1646319289747,"mc":[{"id":"1.195532861","rc":[{"spl":[[1.01,11.65]],"id":42252553}],"con":true,"img":false}]}
{"op":"mcm","clk":"5322375394","pt":1646319448715,"mc":[{"id":"1.195532861","rc":[{"atb":[[1.01,5054.04]],"id":42252553}],"con":true,"img":false}]}
{"op":"mcm","clk":"5322375407","pt":1646319448919,"mc":[{"id":"1.195532861","rc":[{"atb":[[1.01,5056.03]],"id":42252553}],"con":true,"img":false}]}
{"op":"mcm","clk":"5322375431","pt":1646319449190,"mc":[{"id":"1.195532861","rc":[{"atb":[[1.01,5054.04]],"id":42252553}],"con":true,"img":false}]}
{"op":"mcm","clk":"5322375436","pt":1646319449293,"mc":[{"id":"1.195532861","rc":[{"atb":[[1.02,1.99]],"id":42252553}],"con":true,"img":false}]}
{"op":"mcm","clk":"5322375453","pt":1646319449497,"mc":[{"id":"1.195532861","rc":[{"atb":[[1.01,5054.04]],"id":28791247}],"con":true,"img":false}]}
{"op":"mcm","clk":"5322375467","pt":1646319449699,"mc":[{"id":"1.195532861","rc":[{"atb":[[1.01,5056.03]],"id":28791247}],"con":true,"img":false}]}
{"op":"mcm","clk":"5322375477","pt":1646319449913,"mc":[{"id":"1.195532861","rc":[{"atb":[[1.01,5054.04]],"id":28791247}],"con":true,"img":false}]}
{"op":"mcm","clk":"5322375480","pt":1646319450013,"mc":[{"id":"1.195532861","rc":[{"atb":[[1.02,1.99]],"id":28791247}],"con":true,"img":false}]}
{"op":"mcm","clk":"5322375491","pt":1646319450213,"mc":[{"id":"1.195532861","rc":[{"atb":[[1.01,5054.04]],"id":37665265}],"con":true,"img":false}]}
{"op":"mcm","clk":"5322375501","pt":1646319450419,"mc":[{"id":"1.195532861","rc":[{"atb":[[1.01,5056.03]],"id":37665265}],"con":true,"img":false}]}
{"op":"mcm","clk":"5322375512","pt":1646319450584,"mc":[{"id":"1.195532861","rc":[{"atb":[[1.01,5054.04]],"id":37665265}],"con":true,"img":false}]}
{"op":"mcm","clk":"5322375521","pt":1646319450691,"mc":[{"id":"1.195532861","rc":[{"atb":[[1.02,1.99]],"id":37665265}],"con":true,"img":false}]}
{"op":"mcm","clk":"5322375541","pt":1646319451005,"mc":[{"id":"1.195532861","rc":[{"atb":[[1.01,5054.04]],"id":39947224}],"con":true,"img":false}]}
{"op":"mcm","clk":"5322375562","pt":1646319451310,"mc":[{"id":"1.195532861","rc":[{"atb":[[1.01,5056.03]],"id":39947224}],"con":true,"img":false}]}
{"op":"mcm","clk":"5322375585","pt":1646319451612,"mc":[{"id":"1.195532861","rc":[{"atb":[[1.01,5054.04]],"id":39947224}],"con":true,"img":false}]}
{"op":"mcm","clk":"5322375594","pt":1646319451715,"mc":[{"id":"1.195532861","rc":[{"atb":[[1.02,1.99]],"id":39947224}],"con":true,"img":false}]}
{"op":"mcm","clk":"5322375613","pt":1646319451924,"mc":[{"id":"1.195532861","rc":[{"atb":[[1.01,5054.04]],"id":23239795}],"con":true,"img":false}]}
{"op":"mcm","clk":"5322375629","pt":1646319452134,"mc":[{"id":"1.195532861","rc":[{"atb":[[1.01,5056.03]],"id":23239795}],"con":true,"img":false}]}
{"op":"mcm","clk":"5322375642","pt":1646319452295,"mc":[{"id":"1.195532861","rc":[{"atb":[[1.01,5054.04]],"id":23239795}],"con":true,"img":false}]}
{"op":"mcm","clk":"5322375650","pt":1646319452403,"mc":[{"id":"1.195532861","rc":[{"atb":[[1.02,1.99]],"id":23239795}],"con":true,"img":false}]}
{"op":"mcm","clk":"5322375674","pt":1646319452710,"mc":[{"id":"1.195532861","rc":[{"atb":[[1.01,5054.04]],"id":41529436}],"con":true,"img":false}]}
{"op":"mcm","clk":"5322375694","pt":1646319452911,"mc":[{"id":"1.195532861","rc":[{"atb":[[1.01,5056.03]],"id":41529436}],"con":true,"img":false}]}
{"op":"mcm","clk":"5322375716","pt":1646319453219,"mc":[{"id":"1.195532861","rc":[{"atb":[[1.01,5054.04]],"id":41529436}],"con":true,"img":false}]}
{"op":"mcm","clk":"5322375721","pt":1646319453324,"mc":[{"id":"1.195532861","rc":[{"atb":[[1.02,1.99]],"id":41529436}],"con":true,"img":false}]}
{"op":"mcm","clk":"5322381862","pt":1646319545322,"mc":[{"id":"1.195532861","rc":[{"atb":[[1.5,200]],"id":28791247},{"atl":[[9.4,2]],"id":28791247},{"spn":5.45,"spf":"NaN","id":28791247},{"atb":[[1.71,140.85]],"id":39947224},{"atl":[[26,2]],"id":39947224},{"spn":13.85,"spf":"NaN","id":39947224},{"atb":[[1.64,156.25]],"id":37665265},{"atl":[[10,2]],"id":37665265},{"spn":1.64,"spf":1.0,"id":37665265},{"atb":[[1.88,113.64]],"id":41529436},{"atl":[[18,2]],"id":41529436},{"spn":9.94,"spf":"NaN","id":41529436},{"atb":[[1.04,2500]],"id":42252553},{"atl":[[4.2,2]],"id":42252553},{"spn":1.04,"spf":1.0,"id":42252553},{"atb":[[1.62,161.29]],"id":23239795},{"atl":[[7.2,2]],"id":23239795},{"spn":4.41,"spf":"NaN","id":23239795}],"con":true,"img":false}]}
{"op":"mcm","clk":"5322381890","pt":1646319545740,"mc":[{"id":"1.195532861","rc":[{"atb":[[1.48,83.33]],"id":28791247},{"atl":[[50,0],[9.8,4.55]],"id":28791247},{"atb":[[1.69,57.97]],"id":39947224},{"atl":[[50,0],[28,1.48]],"id":39947224},{"atb":[[1.62,64.52]],"id":37665265},{"atl":[[11,4],[50,0]],"id":37665265},{"atb":[[1.86,46.51]],"id":41529436},{"atl":[[19,2.22],[50,0]],"id":41529436},{"atb":[[1.02,0]],"id":42252553},{"atb":[[1.6,66.67]],"id":23239795},{"atl":[[7.6,6.06],[50,0]],"id":23239795}],"con":true,"img":false}]}
{"op":"mcm","clk":"5322381897","pt":1646319545831,"mc":[{"id":"1.195532861","rc":[{"atb":[[1.05,1.99]],"id":42252553}],"con":true,"img":false}]}
{"op":"mcm","clk":"5322381909","pt":1646319546044,"mc":[{"id":"1.195532861","rc":[{"atb":[[1.02,0]],"id":28791247}],"con":true,"img":false}]}
{"op":"mcm","clk":"5322381916","pt":1646319546143,"mc":[{"id":"1.195532861","rc":[{"atb":[[1.51,1.99]],"id":28791247}],"con":true,"img":false}]}
{"op":"mcm","clk":"5322381932","pt":1646319546318,"mc":[{"id":"1.195532861","rc":[{"atb":[[1.02,0]],"id":37665265}],"con":true,"img":false}]}
{"op":"mcm","clk":"5322381941","pt":1646319546415,"mc":[{"id":"1.195532861","rc":[{"atb":[[1.65,1.99]],"id":37665265}],"con":true,"img":false}]}
{"op":"mcm","clk":"5322381955","pt":1646319546618,"mc":[{"id":"1.195532861","rc":[{"atb":[[1.02,0]],"id":39947224}],"con":true,"img":false}]}
{"op":"mcm","clk":"5322381965","pt":1646319546723,"mc":[{"id":"1.195532861","rc":[{"atb":[[1.72,1.99]],"id":39947224}],"con":true,"img":false}]}
{"op":"mcm","clk":"5322381990","pt":1646319547038,"mc":[{"id":"1.195532861","rc":[{"atb":[[1.02,0]],"id":23239795}],"con":true,"img":false}]}
{"op":"mcm","clk":"5322381997","pt":1646319547148,"mc":[{"id":"1.195532861","rc":[{"atb":[[1.49,81.63]],"id":28791247},{"atb":[[1.7,57.14]],"id":39947224},{"atb":[[1.63,63.49]],"id":37665265},{"atb":[[1.03,250]],"id":42252553},{"atl":[[50,0],[4.4,11.76]],"id":42252553},{"atb":[[1.63,1.99]],"id":23239795}],"con":true,"img":false}]}
{"op":"mcm","clk":"5322382012","pt":1646319547447,"mc":[{"id":"1.195532861","rc":[{"atb":[[1.02,0]],"id":41529436}],"con":true,"img":false}]}
{"op":"mcm","clk":"5322382020","pt":1646319547550,"mc":[{"id":"1.195532861","rc":[{"atb":[[1.89,1.99]],"id":41529436}],"con":true,"img":false}]}
{"op":"mcm","clk":"5322382033","pt":1646319547710,"mc":[{"id":"1.195532861","rc":[{"atb":[[1.87,45.98]],"id":41529436},{"atb":[[1.61,65.57]],"id":23239795}],"con":true,"img":false}]}
{"op":"mcm","clk":"5322382041","pt":1646319547814,"mc":[{"id":"1.195532861","rc":[{"atb":[[1.53,2.15]],"id":28791247},{"atb":[[1.74,2.15]],"id":39947224},{"atb":[[1.67,2.15]],"id":37665265}],"con":true,"img":false}]}
{"op":"mcm","clk":"5322382102","pt":1646319548756,"mc":[{"id":"1.195532861","rc":[{"atb":[[1.51,0]],"id":28791247}],"con":true,"img":false}]}
{"op":"mcm","clk":"5322382108","pt":1646319548855,"mc":[{"id":"1.195532861","rc":[{"atb":[[1.54,1.99]],"id":28791247}],"con":true,"img":false}]}
{"op":"mcm","clk":"5322382118","pt":1646319549028,"mc":[{"id":"1.195532861","rc":[{"atb":[[1.65,0]],"id":37665265},{"atb":[[1.91,2.15]],"id":41529436},{"atb":[[1.65,2.15]],"id":23239795}],"con":true,"img":false}]}
{"op":"mcm","clk":"5322382126","pt":1646319549134,"mc":[{"id":"1.195532861","rc":[{"atb":[[1.68,1.99]],"id":37665265}],"con":true,"img":false}]}
{"op":"mcm","clk":"5322382146","pt":1646319549451,"mc":[{"id":"1.195532861","rc":[{"atb":[[1.72,0]],"id":39947224}],"con":true,"img":false}]}
{"op":"mcm","clk":"5322382160","pt":1646319549751,"mc":[{"id":"1.195532861","rc":[{"atb":[[1.52,76.92]],"id":28791247},{"atb":[[1.72,55.56],[1.75,1.99]],"id":39947224},{"atb":[[1.66,60.61]],"id":37665265},{"atb":[[1.89,46.93]],"id":41529436},{"atb":[[1.63,65.48]],"id":23239795}],"con":true,"img":false}]}
{"op":"mcm","clk":"5322382183","pt":1646319550109,"mc":[{"id":"1.195532861","rc":[{"atb":[[1.73,54.79],[1.72,0]],"id":39947224}],"con":true,"img":false}]}
{"op":"mcm","clk":"5322382189","pt":1646319550214,"mc":[{"id":"1.195532861","rc":[{"atb":[[1.52,79.82]],"id":28791247},{"atb":[[1.05,731.35]],"id":42252553},{"atb":[[1.63,123.36]],"id":23239795}],"con":true,"img":false}]}
{"op":"mcm","clk":"5322382197","pt":1646319550317,"mc":[{"id":"1.195532861","rc":[{"atb":[[1.06,731.36],[1.04,0]],"id":42252553}],"con":true,"img":false}]}
{"op":"mcm","clk":"5322382210","pt":1646319550527,"mc":[{"id":"1.195532861","rc":[{"atb":[[1.05,729.36]],"id":42252553}],"con":true,"img":false}]}
{"op":"mcm","clk":"5322382219","pt":1646319550631,"mc":[{"id":"1.195532861","rc":[{"atb":[[1.07,1.99]],"id":42252553}],"con":true,"img":false}]}
{"op":"mcm","clk":"5322382226","pt":1646319550741,"mc":[{"id":"1.195532861","rc":[{"atl":[[18,0],[18.5,4]],"id":41529436},{"atb":[[1.04,250]],"id":42252553},{"atl":[[7.2,0],[7.4,4]],"id":23239795}],"con":true,"img":false}]}
{"op":"mcm","clk":"5322382236","pt":1646319550845,"mc":[{"id":"1.195532861","rc":[{"atb":[[1.63,121.37]],"id":23239795}],"con":true,"img":false}]}
{"op":"mcm","clk":"5322382242","pt":1646319550944,"mc":[{"id":"1.195532861","rc":[{"atb":[[1.66,1.99]],"id":23239795}],"con":true,"img":false}]}
{"op":"mcm","clk":"5322382262","pt":1646319551102,"mc":[{"id":"1.195532861","rc":[{"atb":[[1.89,44.94]],"id":41529436}],"con":true,"img":false}]}
{"op":"mcm","clk":"5322382271","pt":1646319551278,"mc":[{"id":"1.195532861","rc":[{"atb":[[1.92,1.99]],"id":41529436}],"con":true,"img":false}]}
{"op":"mcm","clk":"5322382354","pt":1646319552301,"mc":[{"id":"1.195532861","rc":[{"atb":[[1.89,0],[1.9,44.44]],"id":41529436},{"atl":[[19,0],[19.5,2.16]],"id":41529436},{"atb":[[1.05,979.36]],"id":42252553},{"atb":[[1.64,62.5],[1.63,57.88]],"id":23239795},{"atl":[[7.6,0],[7.8,5.88]],"id":23239795}],"con":true,"img":false}]}
{"op":"mcm","clk":"5322382472","pt":1646319553940,"mc":[{"id":"1.195532861","rc":[{"atb":[[1.52,76.92]],"id":28791247},{"atb":[[1.05,250]],"id":42252553},{"atb":[[1.63,0]],"id":23239795}],"con":true,"img":false}]}
{"op":"mcm","clk":"5322382583","pt":1646319555411,"mc":[{"id":"1.195532861","rc":[{"atb":[[1.5,0],[1.66,2.15]],"id":28791247},{"atb":[[1.97,2.15],[1.71,0]],"id":39947224},{"atb":[[1.64,0],[1.77,2.15]],"id":37665265},{"atb":[[2.14,2.15]],"id":41529436},{"atb":[[1.62,0],[1.7,2.15]],"id":23239795}],"con":true,"img":false}]}
{"op":"mcm","clk":"5322382592","pt":1646319555516,"mc":[{"id":"1.195532861","rc":[{"atb":[[1.88,0]],"id":41529436}],"con":true,"img":false}]}
{"op":"mcm","clk":"5322382609","pt":1646319555726,"mc":[{"id":"1.195532861","rc":[{"atb":[[1.64,62.5],[1.52,0]],"id":28791247},{"atb":[[1.73,0],[1.95,42.11]],"id":39947224},{"atb":[[1.66,0],[1.75,53.33]],"id":37665265},{"atb":[[1.9,0],[2.1,36.36]],"id":41529436},{"atb":[[1.64,0],[1.68,58.82]],"id":23239795}],"con":true,"img":false}]}
{"op":"mcm","clk":"5322382673","pt":1646319556462,"mc":[{"id":"1.195532861","rc":[{"atb":[[1.65,0],[1.71,2.15]],"id":23239795}],"con":true,"img":false}]}
{"op":"mcm","clk":"5322382715","pt":1646319556822,"mc":[{"id":"1.195532861","rc":[{"atb":[[1.68,0],[1.69,57.97]],"id":23239795}],"con":true,"img":false}]}
{"op":"mcm","clk":"5322382746","pt":1646319557136,"mc":[{"id":"1.195532861","rc":[{"atb":[[1.54,0]],"id":28791247}],"con":true,"img":false}]}
{"op":"mcm","clk":"5322382756","pt":1646319557241,"mc":[{"id":"1.195532861","rc":[{"atb":[[1.67,1.99]],"id":28791247}],"con":true,"img":false}]}
{"op":"mcm","clk":"5322382776","pt":1646319557448,"mc":[{"id":"1.195532861","rc":[{"atb":[[1.64,0],[1.65,61.54]],"id":28791247}],"con":true,"img":false}]}
{"op":"mcm","clk":"5322382787","pt":1646319557559,"mc":[{"id":"1.195532861","rc":[{"atb":[[1.68,0]],"id":37665265}],"con":true,"img":false}]}
{"op":"mcm","clk":"5322382794","pt":1646319557657,"mc":[{"id":"1.195532861","rc":[{"atb":[[1.78,1.99]],"id":37665265}],"con":true,"img":false}]}
{"op":"mcm","clk":"5322382814","pt":1646319557821,"mc":[{"id":"1.195532861","rc":[{"atb":[[1.75,0]],"id":39947224},{"atb":[[1.75,0],[1.76,52.63]],"id":37665265}],"con":true,"img":false}]}
{"op":"mcm","clk":"5322382824","pt":1646319557917,"mc":[{"id":"1.195532861","rc":[{"atb":[[1.5,4.97]],"id":28791247},{"atb":[[1.98,1.99]],"id":39947224},{"atb":[[1.07,515.33]],"id":42252553},{"atb":[[1.62,4.97]],"id":23239795}],"con":true,"img":false}]}
{"op":"mcm","clk":"5322382841","pt":1646319558130,"mc":[{"id":"1.195532861","rc":[{"atb":[[1.96,41.67],[1.95,0]],"id":39947224},{"atb":[[1.66,0]],"id":23239795}],"con":true,"img":false}]}
{"op":"mcm","clk":"5322382849","pt":1646319558239,"mc":[{"id":"1.195532861","rc":[{"atb":[[1.72,1.99]],"id":23239795}],"con":true,"img":false}]}
{"op":"mcm","clk":"5322382862","pt":1646319558435,"mc":[{"id":"1.195532861","rc":[{"atb":[[1.92,0]],"id":41529436}],"con":true,"img":false}]}
{"op":"mcm","clk":"5322382874","pt":1646319558542,"mc":[{"id":"1.195532861","rc":[{"atb":[[2.16,1.99]],"id":41529436}],"con":true,"img":false}]}
{"op":"mcm","clk":"5322382935","pt":1646319559426,"mc":[{"id":"1.195532861","rc":[{"atb":[[2.12,35.71],[2.1,0]],"id":41529436},{"atb":[[1.7,59.29],[1.69,0]],"id":23239795}],"con":true,"img":false}]}
{"op":"mcm","clk":"5322382994","pt":1646319560358,"mc":[{"id":"1.195532861","rc":[{"atb":[[1.14,515.33]],"id":42252553}],"con":true,"img":false}]}
{"op":"mcm","clk":"5322383004","pt":1646319560414,"mc":[{"id":"1.195532861","rc":[{"atb":[[1.06,0]],"id":42252553}],"con":true,"img":false}]}
{"op":"mcm","clk":"5322383008","pt":1646319560514,"mc":[{"id":"1.195532861","rc":[{"atb":[[1.12,250]],"id":42252553}],"con":true,"img":false}]}
{"op":"mcm","clk":"5322383017","pt":1646319560620,"mc":[{"id":"1.195532861","rc":[{"atb":[[1.05,0]],"id":42252553}],"con":true,"img":false}]}
{"op":"mcm","clk":"5322383040","pt":1646319560932,"mc":[{"id":"1.195532861","rc":[{"atb":[[2.18,1.65]],"id":41529436}],"con":true,"img":false}]}
{"op":"mcm","clk":"5322383056","pt":1646319561140,"mc":[{"id":"1.195532861","rc":[{"atl":[[9.2,2.74],[9.4,0]],"id":28791247},{"atl":[[25,2],[26,0]],"id":39947224},{"atl":[[10,0],[9.8,2.74]],"id":37665265},{"atb":[[2.12,0],[2.14,37.24]],"id":41529436},{"atl":[[18.5,0],[18,2.74]],"id":41529436},{"atl":[[4.3,4],[4.2,0]],"id":42252553}],"con":true,"img":false}]}
{"op":"mcm","clk":"5322383077","pt":1646319561458,"mc":[{"id":"1.195532861","rc":[{"atb":[[1.07,513.34]],"id":42252553}],"con":true,"img":false}]}
{"op":"mcm","clk":"5322383082","pt":1646319561560,"mc":[{"id":"1.195532861","rc":[{"atb":[[1.15,1.99]],"id":42252553}],"con":true,"img":false}]}
{"op":"mcm","clk":"5322383095","pt":1646319561715,"mc":[{"id":"1.195532861","rc":[{"atl":[[9.6,4.65],[9.8,0]],"id":28791247},{"atl":[[27,1.54],[28,0]],"id":39947224},{"atl":[[10.5,4.21],[11,0]],"id":37665265},{"atl":[[19.5,0],[19,2.22]],"id":41529436},{"atb":[[1.12,0],[1.13,250]],"id":42252553},{"atl":[[4.5,11.43],[4.4,0]],"id":42252553}],"con":true,"img":false}]}
{"op":"mcm","clk":"5322383214","pt":1646319563220,"mc":[{"id":"1.195532861","rc":[{"atb":[[1.5,0]],"id":28791247},{"atb":[[1.07,0]],"id":42252553}],"con":true,"img":false}]}
{"op":"mcm","clk":"5322383402","pt":1646319565456,"mc":[{"id":"1.195532861","rc":[{"atb":[[1.97,0],[2.2,2.15]],"id":39947224},{"atb":[[2.18,3.65],[2.14,35.09]],"id":41529436},{"atb":[[1.72,4.14],[1.7,57.14]],"id":23239795}],"con":true,"img":false}]}
{"op":"mcm","clk":"5322383440","pt":1646319565823,"mc":[{"id":"1.195532861","rc":[{"atb":[[1.98,0]],"id":39947224}],"con":true,"img":false}]}
{"op":"mcm","clk":"5322383447","pt":1646319565926,"mc":[{"id":"1.195532861","rc":[{"atb":[[2.22,1.99]],"id":39947224}],"con":true,"img":false}]}
{"op":"mcm","clk":"5322383466","pt":1646319566135,"mc":[{"id":"1.195532861","rc":[{"atb":[[2.16,0]],"id":41529436}],"con":true,"img":false}]}
{"op":"mcm","clk":"5322383472","pt":1646319566238,"mc":[{"id":"1.195532861","rc":[{"atb":[[2.2,1.99]],"id":41529436}],"con":true,"img":false}]}
{"op":"mcm","clk":"5322383494","pt":1646319566552,"mc":[{"id":"1.195532861","rc":[{"atl":[[9.2,0],[9.4,5.48]],"id":28791247},{"atb":[[1.96,0],[2.18,33.9]],"id":39947224},{"atl":[[25,0],[26,4]],"id":39947224},{"atl":[[10,5.48],[9.8,0]],"id":37665265},{"atb":[[2.14,0],[2.16,34.48]],"id":41529436}],"con":true,"img":false}]}
{"op":"mcm","clk":"5322383526","pt":1646319566965,"mc":[{"id":"1.195532861","rc":[{"atl":[[9.6,0],[9.8,4.55]],"id":28791247},{"atl":[[27,0],[28,1.48]],"id":39947224},{"atl":[[10.5,0],[11,4]],"id":37665265}],"con":true,"img":false}]}
{"op":"mcm","clk":"5322383580","pt":1646319567747,"mc":[{"id":"1.195532861","rc":[{"atb":[[1.5,9.94]],"id":28791247},{"atb":[[1.05,729.36]],"id":42252553}],"con":true,"img":false}]}
{"op":"mcm","clk":"5322383659","pt":1646319569053,"mc":[{"id":"1.195532861","rc":[{"atb":[[2.18,2]],"id":41529436}],"con":true,"img":false}]}
{"op":"mcm","clk":"5322383670","pt":1646319569260,"mc":[{"id":"1.195532861","rc":[{"atb":[[2.24,1.65]],"id":39947224},{"atb":[[2.22,1.65]],"id":41529436}],"con":true,"img":false}]}
{"op":"mcm","clk":"5322383684","pt":1646319569418,"mc":[{"id":"1.195532861","rc":[{"atb":[[1.68,147.06]],"id":23239795},{"atl":[[8.2,13.89]],"id":23239795}],"con":true,"img":false}]}
{"op":"mcm","clk":"5322383692","pt":1646319569523,"mc":[{"id":"1.195532861","rc":[{"atb":[[1.62,0]],"id":23239795}],"con":true,"img":false}]}
{"op":"mcm","clk":"5322383785","pt":1646319571037,"mc":[{"id":"1.195532861","rc":[{"atl":[[4.3,0],[4.1,4]],"id":42252553}],"con":true,"img":false}]}
{"op":"mcm","clk":"5322383810","pt":1646319571351,"mc":[{"id":"1.195532861","rc":[{"atb":[[2.18,0],[2.2,35.48]],"id":39947224},{"atb":[[2.18,35.9],[2.16,0]],"id":41529436},{"atl":[[4.5,0],[4.3,12.12]],"id":42252553},{"atb":[[1.01,4804.04],[1.61,0]],"id":23239795},{"atl":[[70,0],[80,0],[60,0]],"id":23239795}],"con":true,"img":false}]}
{"op":"mcm","clk":"5322383864","pt":1646319571928,"mc":[{"id":"1.195532861","rc":[{"atl":[[4,4],[4.1,0]],"id":42252553}],"con":true,"img":false}]}
{"op":"mcm","clk":"5322383973","pt":1646319573442,"mc":[{"id":"1.195532861","rc":[{"atb":[[1.05,0]],"id":42252553},{"atb":[[1.73,2.9]],"id":23239795}],"con":true,"img":false}]}
{"op":"mcm","clk":"5322384016","pt":1646319573963,"mc":[{"id":"1.195532861","rc":[{"atb":[[1.72,2.15]],"id":23239795}],"con":true,"img":false}]}
{"op":"mcm","clk":"5322384024","pt":1646319574066,"mc":[{"id":"1.195532861","rc":[{"atb":[[1.74,1.99]],"id":23239795}],"con":true,"img":false}]}
{"op":"mcm","clk":"5322384037","pt":1646319574223,"mc":[{"id":"1.195532861","rc":[{"atl":[[4.3,0],[4.2,12.5]],"id":42252553},{"atb":[[1.72,57.71]],"id":23239795}],"con":true,"img":false}]}
{"op":"mcm","clk":"5322384118","pt":1646319575345,"mc":[{"id":"1.195532861","rc":[{"atb":[[2.24,3.65],[2.2,33.33]],"id":39947224},{"atb":[[2.22,3.65],[2.18,33.9]],"id":41529436},{"atb":[[1.72,55.56],[1.74,4.89]],"id":23239795}],"con":true,"img":false}]}
{"op":"mcm","clk":"5322384125","pt":1646319575451,"mc":[{"id":"1.195532861","rc":[{"atb":[[1.75,2.15],[1.71,0]],"id":23239795}],"con":true,"img":false}]}
{"op":"mcm","clk":"5322384133","pt":1646319575555,"mc":[{"id":"1.195532861","rc":[{"atb":[[1.05,729.36]],"id":42252553}],"con":true,"img":false}]}
{"op":"mcm","clk":"5322384149","pt":1646319575764,"mc":[{"id":"1.195532861","rc":[{"atb":[[2.22,0]],"id":39947224}],"con":true,"img":false}]}
{"op":"mcm","clk":"5322384155","pt":1646319575867,"mc":[{"id":"1.195532861","rc":[{"atb":[[2.26,1.99]],"id":39947224}],"con":true,"img":false}]}
{"op":"mcm","clk":"5322384170","pt":1646319576075,"mc":[{"id":"1.195532861","rc":[{"atb":[[2.22,32.79],[2.2,0]],"id":39947224},{"atb":[[1.73,57.69],[1.72,0],[1.74,2.9]],"id":23239795}],"con":true,"img":false}]}
{"op":"mcm","clk":"5322384179","pt":1646319576133,"mc":[{"id":"1.195532861","rc":[{"atb":[[1.76,1.99]],"id":23239795}],"con":true,"img":false}]}
{"op":"mcm","clk":"5322384195","pt":1646319576340,"mc":[{"id":"1.195532861","rc":[{"atb":[[2.2,0]],"id":41529436}],"con":true,"img":false}]}
{"op":"mcm","clk":"5322384205","pt":1646319576440,"mc":[{"id":"1.195532861","rc":[{"atb":[[2.24,1.99]],"id":41529436}],"con":true,"img":false}]}
{"op":"mcm","clk":"5322384212","pt":1646319576546,"mc":[{"id":"1.195532861","rc":[{"atb":[[1.73,2.9],[1.74,56.95]],"id":23239795}],"con":true,"img":false}]}
{"op":"mcm","clk":"5322384258","pt":1646319576963,"mc":[{"id":"1.195532861","rc":[{"atb":[[1.63,158.73],[1.67,4.14],[1.66,0]],"id":28791247},{"atl":[[9,4.55],[10.5,10.53],[9.4,0]],"id":28791247},{"atb":[[1.74,135.14]],"id":37665265},{"atl":[[12,9.09]],"id":37665265},{"atb":[[2.18,0],[2.2,33.33]],"id":41529436},{"atb":[[1.16,250],[1.14,0]],"id":42252553}],"con":true,"img":false}]}
{"op":"mcm","clk":"5322384267","pt":1646319577066,"mc":[{"id":"1.195532861","rc":[{"atb":[[2.24,2]],"id":39947224},{"atb":[[2.22,2]],"id":41529436},{"atl":[[4,0],[4.2,20.5]],"id":42252553}],"con":true,"img":false}]}
{"op":"mcm","clk":"5322384288","pt":1646319577273,"mc":[{"id":"1.195532861","rc":[{"atb":[[2.28,1.65]],"id":39947224},{"atb":[[2.26,1.65]],"id":41529436},{"atb":[[1.15,0]],"id":42252553},{"atb":[[1.73,0]],"id":23239795}],"con":true,"img":false}]}
{"op":"mcm","clk":"5322384295","pt":1646319577375,"mc":[{"id":"1.195532861","rc":[{"atb":[[1.17,1.99]],"id":42252553}],"con":true,"img":false}]}
{"op":"mcm","clk":"5322384481","pt":1646319579573,"mc":[{"id":"1.195532861","rc":[{"atb":[[1.5,0],[1.48,0]],"id":28791247},{"atl":[[70,0],[80,0],[9.8,0],[60,0],[9.4,4.76]],"id":28791247},{"atb":[[2.24,34.26],[2.22,0]],"id":39947224},{"atb":[[1.63,0],[1.01,4804.04]],"id":37665265},{"atl":[[80,0]],"id":37665265},{"atb":[[2.22,34.79],[2.2,0]],"id":41529436},{"atb":[[1.15,250],[1.13,0]],"id":42252553},{"atl":[[4.4,11.76],[4.2,8]],"id":42252553},{"atb":[[1.71,4.97]],"id":23239795}],"con":true,"img":false}]}
{"op":"mcm","clk":"5322384641","pt":1646319581975,"mc":[{"id":"1.195532861","rc":[{"atl":[[10,0],[9.8,5.48]],"id":37665265}],"con":true,"img":false}]}
{"op":"mcm","clk":"5322384747","pt":1646319583385,"mc":[{"id":"1.195532861","rc":[{"atl":[[10.5,4.21],[11,0]],"id":37665265},{"atb":[[1.05,0]],"id":42252553}],"con":true,"img":false}]}
{"op":"mcm","clk":"5322384756","pt":1646319583488,"mc":[{"id":"1.195532861","rc":[{"atb":[[1.68,2.9]],"id":28791247}],"con":true,"img":false}]}
{"op":"mcm","clk":"5322384772","pt":1646319583648,"mc":[{"id":"1.195532861","rc":[{"atb":[[1.65,0],[1.66,60.61]],"id":28791247}],"con":true,"img":false}]}
{"op":"mcm","clk":"5322384804","pt":1646319584064,"mc":[{"id":"1.195532861","rc":[{"atb":[[1.67,2.15]],"id":28791247}],"con":true,"img":false}]}
{"op":"mcm","clk":"5322384813","pt":1646319584167,"mc":[{"id":"1.195532861","rc":[{"atb":[[1.69,1.99]],"id":28791247}],"con":true,"img":false}]}
{"op":"mcm","clk":"5322384883","pt":1646319585151,"mc":[{"id":"1.195532861","rc":[{"atb":[[1.67,61.85]],"id":28791247},{"atb":[[2.24,32.26],[2.28,3.65]],"id":39947224},{"atb":[[2.22,32.79],[2.26,3.65]],"id":41529436},{"atb":[[1.74,54.05],[1.76,4.14]],"id":23239795}],"con":true,"img":false}]}
{"op":"mcm","clk":"5322384891","pt":1646319585254,"mc":[{"id":"1.195532861","rc":[{"atb":[[1.66,0]],"id":28791247},{"atb":[[2.28,1.65],[2.26,5.31]],"id":39947224},{"atb":[[2.24,5.31],[2.26,1.65]],"id":41529436},{"atb":[[1.75,7.12]],"id":23239795}],"con":true,"img":false}]}
{"op":"mcm","clk":"5322384901","pt":1646319585358,"mc":[{"id":"1.195532861","rc":[{"atb":[[1.76,1.99]],"id":23239795}],"con":true,"img":false}]}
{"op":"mcm","clk":"5322384959","pt":1646319586452,"mc":[{"id":"1.195532861","rc":[{"atb":[[1.72,138.89]],"id":23239795},{"atl":[[8.6,19.74]],"id":23239795}],"con":true,"img":false}]}
{"op":"mcm","clk":"5322384985","pt":1646319586761,"mc":[{"id":"1.195532861","rc":[{"atb":[[1.67,59.7],[1.69,4.89]],"id":28791247},{"atb":[[1.16,0],[1.17,251.99]],"id":42252553}],"con":true,"img":false}]}
{"op":"mcm","clk":"5322385033","pt":1646319587280,"mc":[{"id":"1.195532861","rc":[{"atb":[[1.05,478.77]],"id":42252553}],"con":true,"img":false}]}
{"op":"mcm","clk":"5322385169","pt":1646319589360,"mc":[{"id":"1.195532861","rc":[{"atb":[[1.68,0]],"id":28791247},{"atb":[[1.71,0]],"id":23239795}],"con":true,"img":false}]}
{"op":"mcm","clk":"5322385173","pt":1646319589463,"mc":[{"id":"1.195532861","rc":[{"atb":[[2.2,83.33]],"id":39947224},{"atl":[[30,3.45]],"id":39947224},{"atb":[[1.13,250]],"id":42252553},{"atl":[[4.6,27.78]],"id":42252553}],"con":true,"img":false}]}
{"op":"mcm","clk":"5322385179","pt":1646319589566,"mc":[{"id":"1.195532861","rc":[{"atb":[[2.18,84.75]],"id":41529436},{"atl":[[20,5.26]],"id":41529436}],"con":true,"img":false}]}
{"op":"mcm","clk":"5322385262","pt":1646319591056,"mc":[{"id":"1.195532861","rc":[{"atl":[[9,0],[8.8,4.76]],"id":28791247},{"atb":[[1.01,4804.04],[1.69,0]],"id":39947224},{"atl":[[80,0]],"id":39947224},{"atb":[[1.86,0]],"id":41529436},{"atl":[[80,0]],"id":41529436},{"atb":[[1.04,0]],"id":42252553},{"atl":[[80,0]],"id":42252553},{"atl":[[7.4,0],[7.6,13.89]],"id":23239795}],"con":true,"img":false}]}
{"op":"mcm","clk":"5322385268","pt":1646319591156,"mc":[{"id":"1.195532861","rc":[{"atl":[[9.2,3.13]],"id":28791247},{"atb":[[1.6,0]],"id":23239795},{"atl":[[7.6,17.79]],"id":23239795}],"con":true,"img":false}]}
{"op":"mcm","clk":"5322385276","pt":1646319591262,"mc":[{"id":"1.195532861","rc":[{"atl":[[9.2,8.01]],"id":28791247},{"atl":[[7.6,13.89],[7.8,0]],"id":23239795}],"con":true,"img":false}]}
{"op":"mcm","clk":"5322385283","pt":1646319591362,"mc":[{"id":"1.195532861","rc":[{"atl":[[8,5.71]],"id":23239795}],"con":true,"img":false}]}
{"op":"mcm","clk":"5322385298","pt":1646319591675,"mc":[{"id":"1.195532861","rc":[{"atb":[[1.64,6.35]],"id":28791247},{"atb":[[1.05,0]],"id":42252553},{"atb":[[1.76,8.36]],"id":23239795}],"con":true,"img":false}]}
{"op":"mcm","clk":"5322385328","pt":1646319592195,"mc":[{"id":"1.195532861","rc":[{"atl":[[9.2,4.88]],"id":28791247}],"con":true,"img":false}]}
{"op":"mcm","clk":"5322385411","pt":1646319593390,"mc":[{"id":"1.195532861","rc":[{"atb":[[1.72,208.33]],"id":37665265}],"con":true,"img":false}]}
{"op":"mcm","clk":"5322385494","pt":1646319594587,"mc":[{"id":"1.195532861","rc":[{"atb":[[1.79,2.15],[1.67,0]],"id":37665265}],"con":true,"img":false}]}
{"op":"mcm","clk":"5322385507","pt":1646319594794,"mc":[{"id":"1.195532861","rc":[{"atb":[[1.79,4.3],[1.77,0]],"id":37665265}],"con":true,"img":false}]}
{"op":"mcm","clk":"5322385512","pt":1646319594900,"mc":[{"id":"1.195532861","rc":[{"atb":[[1.79,2.15],[1.78,6.29]],"id":37665265}],"con":true,"img":false}]}
{"op":"mcm","clk":"5322385526","pt":1646319594959,"mc":[{"id":"1.195532861","rc":[{"atb":[[1.77,8.37],[1.75,2.15]],"id":23239795}],"con":true,"img":false}]}
{"op":"mcm","clk":"5322385563","pt":1646319595376,"mc":[{"id":"1.195532861","rc":[{"atb":[[1.78,4.3]],"id":37665265}],"con":true,"img":false}]}
{"op":"mcm","clk":"5322385571","pt":1646319595481,"mc":[{"id":"1.195532861","rc":[{"atb":[[1.8,1.99]],"id":37665265},{"atb":[[1.18,176.39]],"id":42252553}],"con":true,"img":false}]}
{"op":"mcm","clk":"5322385583","pt":1646319595585,"mc":[{"id":"1.195532861","rc":[{"atb":[[1.8,4.14],[1.78,0]],"id":37665265}],"con":true,"img":false}]}
{"op":"mcm","clk":"5322385595","pt":1646319595794,"mc":[{"id":"1.195532861","rc":[{"atb":[[1.76,6.37]],"id":23239795}],"con":true,"img":false}]}
{"op":"mcm","clk":"5322385602","pt":1646319595896,"mc":[{"id":"1.195532861","rc":[{"atb":[[1.78,1.99]],"id":23239795}],"con":true,"img":false}]}
{"op":"mcm","clk":"5322385645","pt":1646319596472,"mc":[{"id":"1.195532861","rc":[{"atb":[[1.19,250],[1.17,1.99]],"id":42252553}],"con":true,"img":false}]}
{"op":"mcm","clk":"5322385658","pt":1646319596683,"mc":[{"id":"1.195532861","rc":[{"atb":[[1.17,0]],"id":42252553}],"con":true,"img":false}]}
{"op":"mcm","clk":"5322385662","pt":1646319596788,"mc":[{"id":"1.195532861","rc":[{"atb":[[1.19,251.99]],"id":42252553}],"con":true,"img":false}]}
{"op":"mcm","clk":"5322385676","pt":1646319596995,"mc":[{"id":"1.195532861","rc":[{"atb":[[1.78,51.28],[1.76,0]],"id":37665265},{"atb":[[1.15,0],[1.17,235.29]],"id":42252553},{"atb":[[1.73,6.76],[1.74,0],[1.76,59]],"id":23239795}],"con":true,"img":false}]}
{"op":"mcm","clk":"5322385685","pt":1646319597098,"mc":[{"id":"1.195532861","rc":[{"atb":[[1.73,0]],"id":23239795}],"con":true,"img":false}]}
{"op":"mcm","clk":"5322385696","pt":1646319597261,"mc":[{"id":"1.195532861","rc":[{"atb":[[1.76,52.63]],"id":23239795}],"con":true,"img":false}]}
{"op":"mcm","clk":"5322385829","pt":1646319599176,"mc":[{"id":"1.195532861","rc":[{"atb":[[1.18,0]],"id":42252553}],"con":true,"img":false}]}
{"op":"mcm","clk":"5322385869","pt":1646319599592,"mc":[{"id":"1.195532861","rc":[{"atb":[[2.16,129.31]],"id":39947224},{"atl":[[34,4.55]],"id":39947224},{"atb":[[2.14,131.58]],"id":41529436},{"atl":[[22,7.14]],"id":41529436}],"con":true,"img":false}]}
{"op":"mcm","clk":"5322385941","pt":1646319600487,"mc":[{"id":"1.195532861","rc":[{"atl":[[70,0]],"id":39947224},{"atb":[[1.01,4804.04]],"id":41529436},{"atl":[[70,0]],"id":41529436}],"con":true,"img":false}]}
{"op":"mcm","clk":"5322385954","pt":1646319600699,"mc":[{"id":"1.195532861","rc":[{"atb":[[2.48,10]],"id":41529436}],"con":true,"img":false}]}
{"op":"mcm","clk":"5322385987","pt":1646319601075,"mc":[{"id":"1.195532861","rc":[{"atb":[[2.48,0]],"id":41529436}],"con":true,"img":false}]}
{"op":"mcm","clk":"5322386004","pt":1646319601281,"mc":[{"id":"1.195532861","rc":[{"atb":[[1.65,153.85]],"id":28791247},{"atl":[[9.6,11.63]],"id":28791247},{"atb":[[1.73,12.43]],"id":23239795}],"con":true,"img":false}]}
{"op":"mcm","clk":"5322386128","pt":1646319602492,"mc":[{"id":"1.195532861","rc":[{"atb":[[1.01,4804.04],[1.74,10.2]],"id":28791247}],"con":true,"img":false}]}
{"op":"mcm","clk":"5322386144","pt":1646319602705,"mc":[{"id":"1.195532861","rc":[{"atb":[[1.74,0]],"id":28791247}],"con":true,"img":false}]}
{"op":"mcm","clk":"5322386246","pt":1646319603708,"mc":[{"id":"1.195532861","rc":[{"atb":[[1.64,0],[1.53,2.15]],"id":28791247},{"atl":[[46,2.73]],"id":28791247},{"atb":[[1.74,2.15],[2.28,1.65]],"id":39947224},{"atl":[[46,2.73]],"id":39947224},{"atb":[[1.79,2.15]],"id":37665265},{"atl":[[46,2.73]],"id":37665265},{"atb":[[1.91,2.15],[2.26,1.65]],"id":41529436},{"atl":[[46,2.73]],"id":41529436},{"spl":[[1.01,11.65]],"id":42252553},{"atl":[[46,2.73]],"id":42252553},{"atb":[[1.73,12.44],[1.75,2.15]],"id":23239795},{"atl":[[46,2.73]],"id":23239795}],"con":true,"img":false}]}
{"op":"mcm","clk":"5322386257","pt":1646319603812,"mc":[{"id":"1.195532861","rc":[{"atb":[[1.14,260.78]],"id":42252553}],"con":true,"img":false}]}
{"op":"mcm","clk":"5322386364","pt":1646319605092,"mc":[{"id":"1.195532861","rc":[{"atb":[[1.53,0]],"id":28791247},{"atb":[[1.74,0]],"id":39947224},{"atb":[[1.91,0]],"id":41529436},{"atb":[[1.75,0]],"id":23239795}],"con":true,"img":false}]}
{"op":"mcm","clk":"5322386395","pt":1646319605189,"mc":[{"id":"1.195532861","rc":[{"atb":[[1.7,2.15]],"id":28791247},{"atb":[[2.3,2.15]],"id":39947224},{"atb":[[2.28,2.15]],"id":41529436},{"atb":[[1.8,2.15]],"id":23239795}],"con":true,"img":false}]}
{"op":"mcm","clk":"5322386415","pt":1646319605402,"mc":[{"id":"1.195532861","rc":[{"spn":5.25,"spf":"NaN","id":28791247},{"atb":[[2.3,4.31],[2.26,1.99]],"id":39947224},{"spn":14.15,"spf":"NaN","id":39947224},{"spn":1.8,"spf":1.0,"id":37665265},{"atb":[[2.24,1.99],[2.28,4.31]],"id":41529436},{"spn":10.14,"spf":"NaN","id":41529436},{"spn":1.19,"spf":1.0,"id":42252553},{"atb":[[1.8,4.31],[1.77,0]],"id":23239795},{"spn":4.7,"spf":"NaN","id":23239795}],"con":true,"img":false}]}
{"op":"mcm","clk":"5322386468","pt":1646319606027,"mc":[{"id":"1.195532861","rc":[{"atb":[[1.69,2.9]],"id":28791247}],"con":true,"img":false}]}
{"op":"mcm","clk":"5322386479","pt":1646319606086,"mc":[{"id":"1.195532861","rc":[{"atb":[[1.71,1.99]],"id":28791247}],"con":true,"img":false}]}
{"op":"mcm","clk":"5322386494","pt":1646319606186,"mc":[{"id":"1.195532861","rc":[{"atb":[[1.71,4.15],[1.69,0]],"id":28791247}],"con":true,"img":false}]}
{"op":"mcm","clk":"5322386514","pt":1646319606501,"mc":[{"id":"1.195532861","rc":[{"atb":[[2.26,0]],"id":39947224}],"con":true,"img":false}]}
{"op":"mcm","clk":"5322386521","pt":1646319606604,"mc":[{"id":"1.195532861","rc":[{"atb":[[2.32,1.99]],"id":39947224}],"con":true,"img":false}]}
{"op":"mcm","clk":"5322386540","pt":1646319606918,"mc":[{"id":"1.195532861","rc":[{"atb":[[1.78,0]],"id":23239795}],"con":true,"img":false}]}
{"op":"mcm","clk":"5322386549","pt":1646319607021,"mc":[{"id":"1.195532861","rc":[{"atb":[[1.76,131.58]],"id":37665265},{"atb":[[1.15,250]],"id":42252553},{"atl":[[4.8,39.47]],"id":42252553},{"atb":[[1.81,1.99],[1.78,51.28],[1.76,0]],"id":23239795},{"atl":[[8.4,13.51]],"id":23239795}],"con":true,"img":false}]}
{"op":"mcm","clk":"5322386574","pt":1646319607390,"mc":[{"id":"1.195532861","rc":[{"atb":[[2.24,0]],"id":41529436},{"atb":[[1.73,0]],"id":23239795}],"con":true,"img":false}]}
{"op":"mcm","clk":"5322386582","pt":1646319607503,"mc":[{"id":"1.195532861","rc":[{"atb":[[2.3,1.99]],"id":41529436}],"con":true,"img":false}]}
{"op":"mcm","clk":"5322386591","pt":1646319607603,"mc":[{"id":"1.195532861","rc":[{"atb":[[1.67,0],[1.69,57.97]],"id":28791247},{"atb":[[2.24,3.97],[2.28,32.9]],"id":39947224},{"atb":[[1.62,0]],"id":37665265},{"atb":[[2.24,32.26],[2.22,0]],"id":41529436},{"atb":[[1.01,4804.04]],"id":42252553},{"atl":[[70,0]],"id":42252553},{"atb":[[1.79,50.63],[1.78,0]],"id":23239795}],"con":true,"img":false}]}
{"op":"mcm","clk":"5322386600","pt":1646319607708,"mc":[{"id":"1.195532861","rc":[{"atb":[[2.24,0]],"id":39947224}],"con":true,"img":false}]}
{"op":"mcm","clk":"5322386607","pt":1646319607814,"mc":[{"id":"1.195532861","rc":[{"atl":[[9,9.52],[8.8,0]],"id":28791247},{"atb":[[1.92,12.11]],"id":37665265},{"atb":[[2.24,0],[2.26,33.4]],"id":41529436},{"atb":[[1.16,62.5]],"id":42252553}],"con":true,"img":false}]}
{"op":"mcm","clk":"5322386646","pt":1646319608190,"mc":[{"id":"1.195532861","rc":[{"atl":[[9.2,0]],"id":28791247},{"atb":[[1.78,0],[1.9,44.44]],"id":37665265}],"con":true,"img":false}]}
{"op":"mcm","clk":"5322386656","pt":1646319608292,"mc":[{"id":"1.195532861","rc":[{"atb":[[1.92,0]],"id":37665265},{"atb":[[1.16,0]],"id":42252553}],"con":true,"img":false}]}
{"op":"mcm","clk":"5322386674","pt":1646319608497,"mc":[{"id":"1.195532861","rc":[{"atb":[[1.88,45.45],[1.9,0]],"id":37665265}],"con":true,"img":false}]}
{"op":"mcm","clk":"5322386683","pt":1646319608601,"mc":[{"id":"1.195532861","rc":[{"atb":[[1.8,2.15]],"id":37665265}],"con":true,"img":false}]}
{"op":"mcm","clk":"5322386691","pt":1646319608705,"mc":[{"id":"1.195532861","rc":[{"atb":[[1.91,1.99]],"id":37665265}],"con":true,"img":false}]}
{"op":"mcm","clk":"5322386724","pt":1646319609129,"mc":[{"id":"1.195532861","rc":[{"atb":[[1.8,0],[1.91,4.14]],"id":37665265}],"con":true,"img":false}]}
{"op":"mcm","clk":"5322386736","pt":1646319609232,"mc":[{"id":"1.195532861","rc":[{"atb":[[1.89,44.94],[1.88,0]],"id":37665265}],"con":true,"img":false}]}
{"op":"mcm","clk":"5322386747","pt":1646319609290,"mc":[{"id":"1.195532861","rc":[{"atb":[[1.8,47.44],[1.91,1.99]],"id":37665265},{"atb":[[1.58,33.9]],"id":42252553}],"con":true,"img":false}]}
{"op":"mcm","clk":"5322386755","pt":1646319609390,"mc":[{"id":"1.195532861","rc":[{"atb":[[1.56,178.57],[1.14,0]],"id":42252553}],"con":true,"img":false}]}
{"op":"mcm","clk":"5322386763","pt":1646319609498,"mc":[{"id":"1.195532861","rc":[{"atb":[[1.68,4.55]],"id":28791247},{"atb":[[1.19,1.99]],"id":42252553}],"con":true,"img":false}]}
{"op":"mcm","clk":"5322386786","pt":1646319609817,"mc":[{"id":"1.195532861","rc":[{"atb":[[2.28,31.25]],"id":39947224},{"atb":[[2.26,31.75]],"id":41529436}],"con":true,"img":false}]}
{"op":"mcm","clk":"5322386793","pt":1646319609918,"mc":[{"id":"1.195532861","rc":[{"atb":[[2.34,1.65]],"id":39947224},{"atb":[[2.32,1.65]],"id":41529436},{"atb":[[1.56,250],[1.17,0]],"id":42252553}],"con":true,"img":false}]}
{"op":"mcm","clk":"5322386815","pt":1646319610334,"mc":[{"id":"1.195532861","rc":[{"atb":[[1.58,0]],"id":42252553}],"con":true,"img":false}]}
{"op":"mcm","clk":"5322386824","pt":1646319610394,"mc":[{"id":"1.195532861","rc":[{"atb":[[1.19,0]],"id":42252553}],"con":true,"img":false}]}
{"op":"mcm","clk":"5322386831","pt":1646319610502,"mc":[{"id":"1.195532861","rc":[{"atb":[[1.59,1.99]],"id":42252553}],"con":true,"img":false}]}
{"op":"mcm","clk":"5322386841","pt":1646319610605,"mc":[{"id":"1.195532861","rc":[{"atb":[[2.12,17.55]],"id":28791247},{"atb":[[2.3,35.08],[2.28,0]],"id":39947224},{"atb":[[2.28,35.56],[2.26,0],[2.76,6.2]],"id":41529436},{"atb":[[1.56,178.57],[1.54,74.07]],"id":42252553}],"con":true,"img":false}]}
{"op":"mcm","clk":"5322386860","pt":1646319610911,"mc":[{"id":"1.195532861","rc":[{"atb":[[1.91,0]],"id":37665265}],"con":true,"img":false}]}
{"op":"mcm","clk":"5322386867","pt":1646319610927,"mc":[{"id":"1.195532861","rc":[{"atb":[[2.08,37.04],[1.69,0]],"id":28791247},{"atb":[[2.72,23.26],[2.28,4.31]],"id":41529436},{"atb":[[1.57,70.18],[1.54,0]],"id":42252553}],"con":true,"img":false}]}
{"op":"mcm","clk":"5322386875","pt":1646319611019,"mc":[{"id":"1.195532861","rc":[{"atb":[[1.9,1.99]],"id":37665265}],"con":true,"img":false}]}
{"op":"mcm","clk":"5322386890","pt":1646319611239,"mc":[{"id":"1.195532861","rc":[{"atb":[[1.8,0],[1.9,46.93]],"id":37665265}],"con":true,"img":false}]}
{"op":"mcm","clk":"5322386901","pt":1646319611441,"mc":[{"id":"1.195532861","rc":[{"atb":[[2.12,0]],"id":28791247},{"atb":[[1.8,47.44],[1.9,1.99]],"id":37665265},{"atb":[[2.76,0]],"id":41529436}],"con":true,"img":false}]}
{"op":"mcm","clk":"5322386915","pt":1646319611602,"mc":[{"id":"1.195532861","rc":[{"atb":[[1.8,0],[1.9,46.93]],"id":37665265},{"atb":[[1.73,9.46]],"id":23239795}],"con":true,"img":false}]}
{"op":"mcm","clk":"5322386937","pt":1646319611912,"mc":[{"id":"1.195532861","rc":[{"atb":[[1.59,0]],"id":42252553}],"con":true,"img":false}]}
{"op":"mcm","clk":"5322386944","pt":1646319612016,"mc":[{"id":"1.195532861","rc":[{"atb":[[2.04,38.46],[2.08,0]],"id":28791247},{"atb":[[1.89,0],[1.88,45.45]],"id":37665265},{"atb":[[2.72,0],[2.68,23.81]],"id":41529436},{"atb":[[1.58,1.99]],"id":42252553}],"con":true,"img":false}]}
{"op":"mcm","clk":"5322386955","pt":1646319612122,"mc":[{"id":"1.195532861","rc":[{"atb":[[1.57,0],[1.55,72.73]],"id":42252553}],"con":true,"img":false}]}
{"op":"mcm","clk":"5322386972","pt":1646319612329,"mc":[{"id":"1.195532861","rc":[{"atb":[[1.71,2.16]],"id":28791247}],"con":true,"img":false}]}
{"op":"mcm","clk":"5322386979","pt":1646319612435,"mc":[{"id":"1.195532861","rc":[{"atb":[[2.1,1.99]],"id":28791247}],"con":true,"img":false}]}
{"op":"mcm","clk":"5322386988","pt":1646319612537,"mc":[{"id":"1.195532861","rc":[{"atb":[[2,40],[2.04,0]],"id":28791247},{"atb":[[1.56,250],[1.55,0]],"id":42252553}],"con":true,"img":false}]}
{"op":"mcm","clk":"5322387007","pt":1646319612742,"mc":[{"id":"1.195532861","rc":[{"atb":[[2,0],[2.06,37.74]],"id":28791247},{"atl":[[10,10.96],[9.8,0]],"id":37665265},{"atb":[[2.3,0]],"id":41529436},{"atl":[[4.1,11.76],[4.2,0]],"id":42252553}],"con":true,"img":false}]}
{"op":"mcm","clk":"5322387015","pt":1646319612848,"mc":[{"id":"1.195532861","rc":[{"atb":[[2.74,1.99]],"id":41529436},{"atl":[[4.3,7.81]],"id":42252553}],"con":true,"img":false}]}
{"op":"mcm","clk":"5322387026","pt":1646319612904,"mc":[{"id":"1.195532861","rc":[{"atl":[[12.5,4.54]],"id":37665265}],"con":true,"img":false}]}
{"op":"mcm","clk":"5322387040","pt":1646319613113,"mc":[{"id":"1.195532861","rc":[{"atl":[[12.5,0]],"id":37665265}],"con":true,"img":false}]}
{"op":"mcm","clk":"5322387064","pt":1646319613422,"mc":[{"id":"1.195532861","rc":[{"atb":[[1.58,0]],"id":42252553}],"con":true,"img":false}]}
{"op":"mcm","clk":"5322387073","pt":1646319613525,"mc":[{"id":"1.195532861","rc":[{"atb":[[1.57,1.99]],"id":42252553}],"con":true,"img":false}]}
{"op":"mcm","clk":"5322387082","pt":1646319613630,"mc":[{"id":"1.195532861","rc":[{"atl":[[10.5,0],[11,4]],"id":37665265},{"atb":[[2.68,0],[2.7,23.53]],"id":41529436},{"atb":[[1.56,178.57],[1.59,2.15],[1.54,74.07]],"id":42252553},{"atl":[[4.3,12.12],[4.4,0]],"id":42252553}],"con":true,"img":false}]}
{"op":"mcm","clk":"5322387087","pt":1646319613735,"mc":[{"id":"1.195532861","rc":[{"atb":[[1.68,0],[2.1,0]],"id":28791247},{"atb":[[1.55,72.73]],"id":42252553}],"con":true,"img":false}]}
{"op":"mcm","clk":"5322387095","pt":1646319613839,"mc":[{"id":"1.195532861","rc":[{"atb":[[2.08,1.99]],"id":28791247},{"atb":[[1.16,228.18],[1.57,72.17],[1.54,0]],"id":42252553}],"con":true,"img":false}]}
{"op":"mcm","clk":"5322387111","pt":1646319613996,"mc":[{"id":"1.195532861","rc":[{"atb":[[2.06,0],[2.04,38.46]],"id":28791247},{"atb":[[2.74,0]],"id":41529436},{"atb":[[1.03,0]],"id":42252553}],"con":true,"img":false}]}
{"op":"mcm","clk":"5322387117","pt":1646319614112,"mc":[{"id":"1.195532861","rc":[{"atb":[[2.7,25.52]],"id":41529436}],"con":true,"img":false}]}
{"op":"mcm","clk":"5322387156","pt":1646319614624,"mc":[{"id":"1.195532861","rc":[{"atb":[[1.56,0],[1.55,254.55]],"id":42252553}],"con":true,"img":false}]}
{"op":"mcm","clk":"5322387179","pt":1646319614936,"mc":[{"id":"1.195532861","rc":[{"atb":[[2.3,32.92],[2.34,3.65]],"id":39947224},{"atb":[[2.7,29.84]],"id":41529436}],"con":true,"img":false}]}
{"op":"mcm","clk":"5322387187","pt":1646319615038,"mc":[{"id":"1.195532861","rc":[{"atb":[[2.32,37.08],[2.34,1.65]],"id":39947224},{"atb":[[2.32,52.69],[2.28,2.15],[2.7,25.52]],"id":41529436},{"atb":[[1.57,70.18]],"id":42252553}],"con":true,"img":false}]}
{"op":"mcm","clk":"5322387197","pt":1646319615143,"mc":[{"id":"1.195532861","rc":[{"atb":[[2.32,1.65],[2.7,29.84]],"id":41529436},{"atb":[[1.6,1.99]],"id":42252553}],"con":true,"img":false}]}
{"op":"mcm","clk":"5322387207","pt":1646319615209,"mc":[{"id":"1.195532861","rc":[{"atb":[[2.66,24.1],[2.7,1.99]],"id":41529436}],"con":true,"img":false}]}
{"op":"mcm","clk":"5322387212","pt":1646319615300,"mc":[{"id":"1.195532861","rc":[{"atb":[[2.32,54.35]],"id":41529436}],"con":true,"img":false}]}
{"op":"mcm","clk":"5322387220","pt":1646319615406,"mc":[{"id":"1.195532861","rc":[{"atb":[[2.08,0]],"id":28791247},{"atb":[[2.7,26.09]],"id":41529436},{"atb":[[1.57,0],[1.58,68.97]],"id":42252553}],"con":true,"img":false}]}
{"op":"mcm","clk":"5322387232","pt":1646319615514,"mc":[{"id":"1.195532861","rc":[{"atb":[[2.06,1.99]],"id":28791247},{"atb":[[2.32,1.65]],"id":41529436}],"con":true,"img":false}]}
{"op":"mcm","clk":"5322387249","pt":1646319615720,"mc":[{"id":"1.195532861","rc":[{"atb":[[2.02,39.22],[2.06,4.15],[2.04,0],[1.71,0]],"id":28791247}],"con":true,"img":false}]}
{"op":"mcm","clk":"5322387260","pt":1646319615847,"mc":[{"id":"1.195532861","rc":[{"atb":[[2.3,30.77],[2.38,2.15]],"id":39947224}],"con":true,"img":false}]}
{"op":"mcm","clk":"5322387280","pt":1646319616006,"mc":[{"id":"1.195532861","rc":[{"atb":[[2.32,1.99],[2.38,4.31]],"id":39947224}],"con":true,"img":false}]}
{"op":"mcm","clk":"5322387316","pt":1646319616319,"mc":[{"id":"1.195532861","rc":[{"atb":[[2.32,0]],"id":39947224}],"con":true,"img":false}]}
{"op":"mcm","clk":"5322387331","pt":1646319616425,"mc":[{"id":"1.195532861","rc":[{"atb":[[2.4,1.99],[2.3,0],[2.34,31.5]],"id":39947224}],"con":true,"img":false}]}
{"op":"mcm","clk":"5322387397","pt":1646319617207,"mc":[{"id":"1.195532861","rc":[{"atb":[[2.36,29.41],[2.34,1.65]],"id":39947224}],"con":true,"img":false}]}
{"op":"mcm","clk":"5322387430","pt":1646319617621,"mc":[{"id":"1.195532861","rc":[{"atb":[[1.77,129.87]],"id":23239795},{"atl":[[8.8,19.23]],"id":23239795}],"con":true,"img":false}]}
{"op":"mcm","clk":"5322387447","pt":1646319617827,"mc":[{"id":"1.195532861","rc":[{"atb":[[2.34,0]],"id":39947224},{"atb":[[2.32,0]],"id":41529436}],"con":true,"img":false}]}
{"op":"mcm","clk":"5322387458","pt":1646319617930,"mc":[{"id":"1.195532861","rc":[{"atl":[[9,0],[9.4,16.66]],"id":28791247},{"atl":[[10,0],[9.8,9.09]],"id":37665265},{"atb":[[1.72,0],[1.7,0],[1.68,0]],"id":23239795},{"atl":[[8.6,0],[8.2,0]],"id":23239795}],"con":true,"img":false}]}
{"op":"mcm","clk":"5322387465","pt":1646319618034,"mc":[{"id":"1.195532861","rc":[{"atb":[[2.08,1.65]],"id":28791247},{"atb":[[2.42,1.65]],"id":39947224},{"atb":[[2.72,1.65]],"id":41529436},{"atb":[[1.16,0]],"id":42252553}],"con":true,"img":false}]}
{"op":"mcm","clk":"5322387472","pt":1646319618139,"mc":[{"id":"1.195532861","rc":[{"atb":[[1.77,47.41]],"id":37665265}],"con":true,"img":false}]}
{"op":"mcm","clk":"5322387526","pt":1646319618816,"mc":[{"id":"1.195532861","rc":[{"atb":[[2.02,0],[2.04,38.46]],"id":28791247},{"atl":[[9.8,4.55],[9.4,11.9]],"id":28791247},{"atb":[[2.36,0],[2.38,33.3],[2.84,6.8]],"id":39947224},{"atl":[[10.5,4.21],[11,0]],"id":37665265},{"atb":[[2.66,0],[2.68,23.81]],"id":41529436}],"con":true,"img":false}]}
{"op":"mcm","clk":"5322387544","pt":1646319619025,"mc":[{"id":"1.195532861","rc":[{"atb":[[2.84,0]],"id":39947224}],"con":true,"img":false}]}
{"op":"mcm","clk":"5322387596","pt":1646319619712,"mc":[{"id":"1.195532861","rc":[{"atb":[[1.55,72.73],[1.54,185.19]],"id":42252553}],"con":true,"img":false}]}
{"op":"mcm","clk":"5322387611","pt":1646319619914,"mc":[{"id":"1.195532861","rc":[{"atb":[[1.73,0]],"id":23239795}],"con":true,"img":false}]}
{"op":"mcm","clk":"5322387621","pt":1646319620120,"mc":[{"id":"1.195532861","rc":[{"atl":[[9.6,0]],"id":28791247}],"con":true,"img":false}]}
{"op":"mcm","clk":"5322387760","pt":1646319622008,"mc":[{"id":"1.195532861","rc":[{"atb":[[1.56,4.55]],"id":42252553}],"con":true,"img":false}]}
{"op":"mcm","clk":"5322387922","pt":1646319624349,"mc":[{"id":"1.195532861","rc":[{"atl":[[18.5,5.48]],"id":41529436},{"atl":[[4,12.12]],"id":42252553},{"atl":[[7.4,13.51]],"id":23239795}],"con":true,"img":false}]}
{"op":"mcm","clk":"5322387926","pt":1646319624454,"mc":[{"id":"1.195532861","rc":[{"atl":[[18,0]],"id":41529436},{"atl":[[4.1,0]],"id":42252553},{"atl":[[7.6,0]],"id":23239795}],"con":true,"img":false}]}
{"op":"mcm","clk":"5322387939","pt":1646319624618,"mc":[{"id":"1.195532861","rc":[{"atl":[[19,0]],"id":41529436},{"atl":[[4.3,0],[4.2,12.5]],"id":42252553},{"atl":[[7.8,5.88]],"id":23239795}],"con":true,"img":false}]}
{"op":"mcm","clk":"5322387946","pt":1646319624718,"mc":[{"id":"1.195532861","rc":[{"atl":[[19.5,5.77]],"id":41529436}],"con":true,"img":false}]}
{"op":"mcm","clk":"5322387998","pt":1646319625347,"mc":[{"id":"1.195532861","rc":[{"atl":[[19.5,2.16]],"id":41529436}],"con":true,"img":false}]}
{"op":"mcm","clk":"5322388007","pt":1646319625450,"mc":[{"id":"1.195532861","rc":[{"atb":[[2.42,3.65],[2.38,31.14]],"id":39947224}],"con":true,"img":false}]}
{"op":"mcm","clk":"5322388035","pt":1646319625716,"mc":[{"id":"1.195532861","rc":[{"atb":[[1.81,6.4]],"id":23239795}],"con":true,"img":false}]}
{"op":"mcm","clk":"5322388044","pt":1646319625819,"mc":[{"id":"1.195532861","rc":[{"atb":[[1.8,2.15],[1.82,6.41]],"id":23239795}],"con":true,"img":false}]}
{"op":"mcm","clk":"5322388096","pt":1646319626444,"mc":[{"id":"1.195532861","rc":[{"atb":[[1.8,0],[1.84,2.15]],"id":23239795}],"con":true,"img":false}]}
{"op":"mcm","clk":"5322388106","pt":1646319626548,"mc":[{"id":"1.195532861","rc":[{"atb":[[2.4,0]],"id":39947224}],"con":true,"img":false}]}
{"op":"mcm","clk":"5322388111","pt":1646319626651,"mc":[{"id":"1.195532861","rc":[{"atb":[[2.44,1.99]],"id":39947224},{"atb":[[1.82,0],[1.84,8.56]],"id":23239795}],"con":true,"img":false}]}
{"op":"mcm","clk":"5322388131","pt":1646319626862,"mc":[{"id":"1.195532861","rc":[{"atb":[[1.81,4.41]],"id":23239795}],"con":true,"img":false}]}
{"op":"mcm","clk":"5322388142","pt":1646319626924,"mc":[{"id":"1.195532861","rc":[{"atb":[[1.83,1.99]],"id":23239795}],"con":true,"img":false}]}
{"op":"mcm","clk":"5322388209","pt":1646319627760,"mc":[{"id":"1.195532861","rc":[{"atb":[[1.83,0]],"id":23239795}],"con":true,"img":false}]}
{"op":"mcm","clk":"5322388217","pt":1646319627858,"mc":[{"id":"1.195532861","rc":[{"atb":[[1.85,1.99]],"id":23239795}],"con":true,"img":false}]}
{"op":"mcm","clk":"5322388238","pt":1646319628121,"mc":[{"id":"1.195532861","rc":[{"atb":[[2.4,28.57],[2.38,2.15]],"id":39947224},{"atb":[[1.83,48.19]],"id":23239795}],"con":true,"img":false}]}
{"op":"mcm","clk":"5322388277","pt":1646319628774,"mc":[{"id":"1.195532861","rc":[{"atb":[[2,100]],"id":28791247},{"atl":[[11.5,14.29]],"id":28791247},{"atb":[[1.86,116.28]],"id":37665265}],"con":true,"img":false}]}
{"op":"mcm","clk":"5322388345","pt":1646319629656,"mc":[{"id":"1.195532861","rc":[{"atb":[[1.63,0],[1.49,0],[1.65,0]],"id":28791247},{"atl":[[9.2,10.53],[9.4,0]],"id":28791247},{"atb":[[1.72,0]],"id":37665265},{"atl":[[4,0],[4.1,27.78]],"id":42252553}],"con":true,"img":false}]}
{"op":"mcm","clk":"5322388377","pt":1646319630075,"mc":[{"id":"1.195532861","rc":[{"atb":[[1.81,0]],"id":23239795}],"con":true,"img":false}]}
{"op":"mcm","clk":"5322388424","pt":1646319630759,"mc":[{"id":"1.195532861","rc":[{"atl":[[9.6,4.65]],"id":28791247},{"atl":[[4.3,12.12],[4.2,0]],"id":42252553}],"con":true,"img":false}]}
{"op":"mcm","clk":"5322388510","pt":1646319631864,"mc":[{"id":"1.195532861","rc":[{"atb":[[1.77,0]],"id":37665265},{"atb":[[1.56,0]],"id":42252553}],"con":true,"img":false}]}
{"op":"mcm","clk":"5322388657","pt":1646319633857,"mc":[{"id":"1.195532861","rc":[{"atb":[[2.42,2]],"id":39947224},{"atb":[[1.8,12.66]],"id":23239795}],"con":true,"img":false}]}
{"op":"mcm","clk":"5322388671","pt":1646319634111,"mc":[{"id":"1.195532861","rc":[{"atb":[[2.46,1.65]],"id":39947224}],"con":true,"img":false}]}
{"op":"mcm","clk":"5322388714","pt":1646319634639,"mc":[{"id":"1.195532861","rc":[{"atb":[[2.64,60.98]],"id":41529436},{"atl":[[21,5]],"id":41529436}],"con":true,"img":false}]}
{"op":"mcm","clk":"5322388722","pt":1646319634875,"mc":[{"id":"1.195532861","rc":[{"atb":[[2.42,0],[2.46,3.65]],"id":39947224}],"con":true,"img":false}]}
{"op":"mcm","clk":"5322388734","pt":1646319634899,"mc":[{"id":"1.195532861","rc":[{"atl":[[9.2,0],[9.4,11.9]],"id":28791247},{"atb":[[2.4,0],[2.42,28.17]],"id":39947224},{"atb":[[2.18,0],[1.87,0],[2.14,0]],"id":41529436},{"atl":[[20,0],[22,0],[60,0]],"id":41529436}],"con":true,"img":false}]}
{"op":"mcm","clk":"5322388741","pt":1646319634952,"mc":[{"id":"1.195532861","rc":[{"atl":[[9.4,14.95]],"id":28791247}],"con":true,"img":false}]}
{"op":"mcm","clk":"5322388761","pt":1646319635276,"mc":[{"id":"1.195532861","rc":[{"atl":[[9.4,11.9]],"id":28791247}],"con":true,"img":false}]}
{"op":"mcm","clk":"5322388795","pt":1646319635583,"mc":[{"id":"1.195532861","rc":[{"atl":[[9.6,0]],"id":28791247}],"con":true,"img":false}]}
{"op":"mcm","clk":"5322388815","pt":1646319635838,"mc":[{"id":"1.195532861","rc":[{"atb":[[2.44,0]],"id":39947224}],"con":true,"img":false}]}
{"op":"mcm","clk":"5322388822","pt":1646319635940,"mc":[{"id":"1.195532861","rc":[{"atb":[[2.48,1.99]],"id":39947224}],"con":true,"img":false}]}
{"op":"mcm","clk":"5322388831","pt":1646319636045,"mc":[{"id":"1.195532861","rc":[{"atb":[[1.91,32.84]],"id":37665265},{"atb":[[1.56,4.55]],"id":42252553}],"con":true,"img":false}]}
{"op":"mcm","clk":"5322388837","pt":1646319636148,"mc":[{"id":"1.195532861","rc":[{"atb":[[1.92,45.45],[1.9,1.99]],"id":37665265}],"con":true,"img":false}]}
{"op":"mcm","clk":"5322388885","pt":1646319636924,"mc":[{"id":"1.195532861","rc":[{"atb":[[1.79,0],[1.95,2.15]],"id":37665265}],"con":true,"img":false}]}
{"op":"mcm","clk":"5322388894","pt":1646319637028,"mc":[{"id":"1.195532861","rc":[{"atb":[[1.9,0]],"id":37665265}],"con":true,"img":false}]}
{"op":"mcm","clk":"5322388905","pt":1646319637133,"mc":[{"id":"1.195532861","rc":[{"atb":[[1.93,1.99]],"id":37665265}],"con":true,"img":false}]}
{"op":"mcm","clk":"5322388976","pt":1646319638171,"mc":[{"id":"1.195532861","rc":[{"atb":[[1.81,123.46]],"id":23239795},{"atl":[[8.2,13.89]],"id":23239795}],"con":true,"img":false}]}
{"op":"mcm","clk":"5322388992","pt":1646319638430,"mc":[{"id":"1.195532861","rc":[{"atb":[[1.93,0]],"id":37665265}],"con":true,"img":false}]}
{"op":"mcm","clk":"5322388998","pt":1646319638534,"mc":[{"id":"1.195532861","rc":[{"atb":[[1.96,1.99]],"id":37665265}],"con":true,"img":false}]}
{"op":"mcm","clk":"5322389022","pt":1646319638755,"mc":[{"id":"1.195532861","rc":[{"atb":[[1.88,0],[1.94,42.55]],"id":37665265}],"con":true,"img":false}]}
{"op":"mcm","clk":"5322389072","pt":1646319639677,"mc":[{"id":"1.195532861","rc":[{"atb":[[1.91,0]],"id":37665265}],"con":true,"img":false}]}
{"op":"mcm","clk":"5322389080","pt":1646319639781,"mc":[{"id":"1.195532861","rc":[{"atb":[[2.42,0],[2.44,27.78]],"id":39947224},{"atb":[[1.58,0],[1.54,259.26]],"id":42252553},{"atl":[[8,0],[8.8,0],[8.4,0]],"id":23239795}],"con":true,"img":false}]}
{"op":"mcm","clk":"5322389086","pt":1646319639833,"mc":[{"id":"1.195532861","rc":[{"atl":[[3.95,27.78],[4.1,0]],"id":42252553}],"con":true,"img":false}]}
{"op":"mcm","clk":"5322389096","pt":1646319639943,"mc":[{"id":"1.195532861","rc":[{"atl":[[8.2,19.6]],"id":23239795}],"con":true,"img":false}]}
{"op":"mcm","clk":"5322389103","pt":1646319640040,"mc":[{"id":"1.195532861","rc":[{"atb":[[1.55,0]],"id":42252553}],"con":true,"img":false}]}
{"op":"mcm","clk":"5322389117","pt":1646319640246,"mc":[{"id":"1.195532861","rc":[{"atl":[[8.2,13.89]],"id":23239795}],"con":true,"img":false}]}
{"op":"mcm","clk":"5322389153","pt":1646319640767,"mc":[{"id":"1.195532861","rc":[{"atb":[[1.98,153.06]],"id":28791247},{"atl":[[12.5,21.74]],"id":28791247}],"con":true,"img":false}]}
{"op":"mcm","clk":"5322389169","pt":1646319640984,"mc":[{"id":"1.195532861","rc":[{"atl":[[4.3,0],[4.1,12.9]],"id":42252553}],"con":true,"img":false}]}
{"op":"mcm","clk":"5322389220","pt":1646319641654,"mc":[{"id":"1.195532861","rc":[{"atb":[[1.8,0]],"id":23239795}],"con":true,"img":false}]}
{"op":"mcm","clk":"5322389240","pt":1646319641971,"mc":[{"id":"1.195532861","rc":[{"atb":[[2.46,2]],"id":39947224}],"con":true,"img":false}]}
{"op":"mcm","clk":"5322389260","pt":1646319642178,"mc":[{"id":"1.195532861","rc":[{"atb":[[2.5,1.65]],"id":39947224}],"con":true,"img":false}]}
{"op":"mcm","clk":"5322389302","pt":1646319642758,"mc":[{"id":"1.195532861","rc":[{"atb":[[2.44,0]],"id":39947224}],"con":true,"img":false}]}
{"op":"mcm","clk":"5322389313","pt":1646319642853,"mc":[{"id":"1.195532861","rc":[{"atb":[[2.46,29.4]],"id":39947224}],"con":true,"img":false}]}
{"op":"mcm","clk":"5322389353","pt":1646319643586,"mc":[{"id":"1.195532861","rc":[{"atb":[[1.56,0]],"id":42252553}],"con":true,"img":false}]}
{"op":"mcm","clk":"5322389366","pt":1646319643744,"mc":[{"id":"1.195532861","rc":[{"atb":[[1.96,4.89]],"id":37665265}],"con":true,"img":false}]}
{"op":"mcm","clk":"5322389381","pt":1646319643940,"mc":[{"id":"1.195532861","rc":[{"atb":[[2.5,3.65],[2.46,27.4]],"id":39947224}],"con":true,"img":false}]}
{"op":"mcm","clk":"5322389434","pt":1646319644668,"mc":[{"id":"1.195532861","rc":[{"atb":[[2.6,93.75]],"id":41529436},{"atl":[[23,6.82]],"id":41529436}],"con":true,"img":false}]}
{"op":"mcm","clk":"5322389443","pt":1646319644782,"mc":[{"id":"1.195532861","rc":[{"atb":[[2.58,13.1]],"id":41529436}],"con":true,"img":false}]}
{"op":"mcm","clk":"5322389476","pt":1646319645197,"mc":[{"id":"1.195532861","rc":[{"atl":[[9.2,10.53]],"id":28791247},{"atl":[[4,33.33]],"id":42252553}],"con":true,"img":false}]}
{"op":"mcm","clk":"5322389485","pt":1646319645312,"mc":[{"id":"1.195532861","rc":[{"atl":[[9.4,0]],"id":28791247},{"atb":[[2.58,0]],"id":41529436},{"atl":[[3.95,0]],"id":42252553}],"con":true,"img":false}]}
{"op":"mcm","clk":"5322389490","pt":1646319645342,"mc":[{"id":"1.195532861","rc":[{"atl":[[9.6,4.65],[9.8,0]],"id":28791247},{"atb":[[2.48,0]],"id":39947224},{"atb":[[1.92,0],[1.97,4.89]],"id":37665265}],"con":true,"img":false}]}
{"op":"mcm","clk":"5322389498","pt":1646319645456,"mc":[{"id":"1.195532861","rc":[{"atb":[[2.52,1.99]],"id":39947224}],"con":true,"img":false}]}
{"op":"mcm","clk":"5322389532","pt":1646319645879,"mc":[{"id":"1.195532861","rc":[{"atb":[[1.96,2.9]],"id":37665265},{"atb":[[1.16,21.14]],"id":42252553},{"atb":[[1.85,9.37]],"id":23239795}],"con":true,"img":false}]}
{"op":"mcm","clk":"5322389542","pt":1646319645975,"mc":[{"id":"1.195532861","rc":[{"atb":[[1.98,1.99]],"id":37665265}],"con":true,"img":false}]}
{"op":"mcm","clk":"5322389545","pt":1646319646071,"mc":[{"id":"1.195532861","rc":[{"atb":[[1.97,0],[1.96,12.68]],"id":37665265},{"atb":[[1.84,2.15],[1.86,9.38]],"id":23239795}],"con":true,"img":false}]}
{"op":"mcm","clk":"5322389591","pt":1646319646647,"mc":[{"id":"1.195532861","rc":[{"atb":[[1.98,0]],"id":37665265}],"con":true,"img":false}]}
{"op":"mcm","clk":"5322389598","pt":1646319646752,"mc":[{"id":"1.195532861","rc":[{"atb":[[1.97,1.99]],"id":37665265}],"con":true,"img":false}]}
{"op":"mcm","clk":"5322389622","pt":1646319647071,"mc":[{"id":"1.195532861","rc":[{"atb":[[1.85,7.38]],"id":23239795}],"con":true,"img":false}]}
{"op":"mcm","clk":"5322389627","pt":1646319647168,"mc":[{"id":"1.195532861","rc":[{"atb":[[1.87,1.99]],"id":23239795}],"con":true,"img":false}]}
{"op":"mcm","clk":"5322389660","pt":1646319647375,"mc":[{"id":"1.195532861","rc":[{"atb":[[1.7,0],[2.1,2.15]],"id":28791247},{"atb":[[1.84,0],[1.88,2.15]],"id":23239795}],"con":true,"img":false}]}
{"op":"mcm","clk":"5322389676","pt":1646319647587,"mc":[{"id":"1.195532861","rc":[{"atb":[[2.06,1.99],[2.1,4.31]],"id":28791247}],"con":true,"img":false}]}
{"op":"mcm","clk":"5322389685","pt":1646319647640,"mc":[{"id":"1.195532861","rc":[{"atb":[[1.96,9.78]],"id":37665265}],"con":true,"img":false}]}
{"op":"mcm","clk":"5322389694","pt":1646319647744,"mc":[{"id":"1.195532861","rc":[{"atb":[[2.06,0]],"id":28791247}],"con":true,"img":false}]}
{"op":"mcm","clk":"5322389703","pt":1646319647894,"mc":[{"id":"1.195532861","rc":[{"atb":[[2.12,1.99]],"id":28791247}],"con":true,"img":false}]}
{"op":"mcm","clk":"5322389724","pt":1646319648077,"mc":[{"id":"1.195532861","rc":[{"atb":[[1.87,0]],"id":23239795}],"con":true,"img":false}]}
{"op":"mcm","clk":"5322389730","pt":1646319648163,"mc":[{"id":"1.195532861","rc":[{"atb":[[1.83,0],[1.82,6.02],[1.89,1.99],[1.86,55.89]],"id":23239795},{"atl":[[8.6,19.74]],"id":23239795}],"con":true,"img":false}]}
{"op":"mcm","clk":"5322389760","pt":1646319648386,"mc":[{"id":"1.195532861","rc":[{"atb":[[1.82,0]],"id":23239795}],"con":true,"img":false}]}
{"op":"mcm","clk":"5322389790","pt":1646319648685,"mc":[{"id":"1.195532861","rc":[{"atb":[[1.73,11.21],[2.08,38.69]],"id":28791247},{"atb":[[2.46,0],[2.48,27.03]],"id":39947224},{"atb":[[1.94,0],[1.95,44.26]],"id":37665265},{"atl":[[4.1,0],[4.2,12.5]],"id":42252553},{"atb":[[1.86,9.38],[1.87,45.98]],"id":23239795}],"con":true,"img":false}]}
{"op":"mcm","clk":"5322389809","pt":1646319648891,"mc":[{"id":"1.195532861","rc":[{"atb":[[1.73,0]],"id":28791247}],"con":true,"img":false}]}
{"op":"mcm","clk":"5322389859","pt":1646319649584,"mc":[{"id":"1.195532861","rc":[{"atb":[[1.85,0]],"id":23239795}],"con":true,"img":false}]}
{"op":"mcm","clk":"5322389884","pt":1646319649986,"mc":[{"id":"1.195532861","rc":[{"atb":[[2.08,37.04]],"id":28791247},{"atb":[[2.5,2]],"id":39947224}],"con":true,"img":false}]}
{"op":"mcm","clk":"5322389900","pt":1646319650195,"mc":[{"id":"1.195532861","rc":[{"atb":[[2.14,1.65]],"id":28791247},{"atb":[[2.54,1.65]],"id":39947224},{"atl":[[25,3.45],[26,0]],"id":39947224},{"atl":[[7.4,0],[7.6,15.15]],"id":23239795}],"con":true,"img":false}]}
{"op":"mcm","clk":"5322389916","pt":1646319650355,"mc":[{"id":"1.195532861","rc":[{"atb":[[2.1,40.67],[2.08,0]],"id":28791247},{"atb":[[2.54,3.65],[2.5,26.67],[2.48,3.33]],"id":39947224},{"atl":[[27,1.54],[28,0]],"id":39947224},{"atl":[[8,5.71],[7.8,0]],"id":23239795}],"con":true,"img":false}]}
{"op":"mcm","clk":"5322389930","pt":1646319650559,"mc":[{"id":"1.195532861","rc":[{"atl":[[32,4.22]],"id":39947224}],"con":true,"img":false}]}
{"op":"mcm","clk":"5322389936","pt":1646319650664,"mc":[{"id":"1.195532861","rc":[{"atl":[[32,0]],"id":39947224}],"con":true,"img":false}]}
{"op":"mcm","clk":"5322389944","pt":1646319650767,"mc":[{"id":"1.195532861","rc":[{"atb":[[2.52,0],[2.48,0]],"id":39947224}],"con":true,"img":false}]}
{"op":"mcm","clk":"5322389950","pt":1646319650870,"mc":[{"id":"1.195532861","rc":[{"atb":[[2.56,1.99]],"id":39947224}],"con":true,"img":false}]}
{"op":"mcm","clk":"5322390007","pt":1646319651597,"mc":[{"id":"1.195532861","rc":[{"atb":[[1.16,0]],"id":42252553}],"con":true,"img":false}]}
{"op":"mcm","clk":"5322390015","pt":1646319651648,"mc":[{"id":"1.195532861","rc":[{"atb":[[1.87,20.01]],"id":37665265}],"con":true,"img":false}]}
{"op":"mcm","clk":"5322390023","pt":1646319651765,"mc":[{"id":"1.195532861","rc":[{"atb":[[2.5,0],[2.52,26.32]],"id":39947224}],"con":true,"img":false}]}
{"op":"mcm","clk":"5322390181","pt":1646319653807,"mc":[{"id":"1.195532861","rc":[{"atb":[[1.16,21.14]],"id":42252553},{"atb":[[1.89,4.89]],"id":23239795}],"con":true,"img":false}]}
{"op":"mcm","clk":"5322390241","pt":1646319654682,"mc":[{"id":"1.195532861","rc":[{"atb":[[2.56,160.26]],"id":41529436},{"atl":[[25,10.42]],"id":41529436}],"con":true,"img":false}]}
{"op":"mcm","clk":"5322390286","pt":1646319655199,"mc":[{"id":"1.195532861","rc":[{"atb":[[1.9,4.89],[1.86,0]],"id":23239795}],"con":true,"img":false}]}
{"op":"mcm","clk":"5322390317","pt":1646319655566,"mc":[{"id":"1.195532861","rc":[{"atb":[[1.88,47.6],[1.87,0]],"id":23239795}],"con":true,"img":false}]}
{"op":"mcm","clk":"5322390325","pt":1646319655681,"mc":[{"id":"1.195532861","rc":[{"atl":[[9,10.53],[9.2,0]],"id":28791247},{"atl":[[25,0],[26,4]],"id":39947224},{"atb":[[1.93,14.54]],"id":37665265},{"atl":[[10,11.11],[9.8,0]],"id":37665265},{"atl":[[18.5,0],[18,5]],"id":41529436}],"con":true,"img":false}]}
{"op":"mcm","clk":"5322390341","pt":1646319655886,"mc":[{"id":"1.195532861","rc":[{"atb":[[1.93,0]],"id":37665265},{"atl":[[10,18.49]],"id":37665265},{"atb":[[1.89,2.9]],"id":23239795}],"con":true,"img":false}]}
{"op":"mcm","clk":"5322390347","pt":1646319655985,"mc":[{"id":"1.195532861","rc":[{"atb":[[1.91,1.99]],"id":23239795}],"con":true,"img":false}]}
{"op":"mcm","clk":"5322390358","pt":1646319656090,"mc":[{"id":"1.195532861","rc":[{"atb":[[1.89,50.51],[1.9,0]],"id":23239795}],"con":true,"img":false}]}
{"op":"mcm","clk":"5322390365","pt":1646319656195,"mc":[{"id":"1.195532861","rc":[{"atl":[[10,11.11]],"id":37665265},{"atb":[[1.89,2.9],[1.91,4.89]],"id":23239795}],"con":true,"img":false}]}
{"op":"mcm","clk":"5322390374","pt":1646319656298,"mc":[{"id":"1.195532861","rc":[{"atb":[[1.89,53.41]],"id":23239795}],"con":true,"img":false}]}
{"op":"mcm","clk":"5322390381","pt":1646319656401,"mc":[{"id":"1.195532861","rc":[{"atl":[[9.6,0],[9.4,4.76]],"id":28791247},{"atl":[[27,0],[28,1.48]],"id":39947224},{"atl":[[10.5,0],[11,4]],"id":37665265},{"atl":[[19.5,0],[19,2.22]],"id":41529436},{"atb":[[1.89,98.35],[1.88,2.15],[1.91,1.99]],"id":23239795}],"con":true,"img":false}]}
{"op":"mcm","clk":"5322390400","pt":1646319656669,"mc":[{"id":"1.195532861","rc":[{"atb":[[2.14,3.65],[2.1,38.51]],"id":28791247}],"con":true,"img":false}]}
{"op":"mcm","clk":"5322390424","pt":1646319657087,"mc":[{"id":"1.195532861","rc":[{"atb":[[2.12,0]],"id":28791247}],"con":true,"img":false}]}
{"op":"mcm","clk":"5322390430","pt":1646319657183,"mc":[{"id":"1.195532861","rc":[{"atb":[[2.16,1.99]],"id":28791247}],"con":true,"img":false}]}
{"op":"mcm","clk":"5322390452","pt":1646319657402,"mc":[{"id":"1.195532861","rc":[{"atb":[[1.91,0]],"id":23239795}],"con":true,"img":false}]}
{"op":"mcm","clk":"5322390458","pt":1646319657497,"mc":[{"id":"1.195532861","rc":[{"atb":[[1.9,1.99]],"id":23239795}],"con":true,"img":false}]}
{"op":"mcm","clk":"5322390468","pt":1646319657607,"mc":[{"id":"1.195532861","rc":[{"atb":[[1.89,95.45]],"id":23239795}],"con":true,"img":false}]}
{"op":"mcm","clk":"5322390481","pt":1646319657813,"mc":[{"id":"1.195532861","rc":[{"atb":[[2.12,35.71],[2.1,2.15],[2.08,18.18]],"id":28791247},{"atb":[[1.89,50.51],[1.88,47.6]],"id":23239795}],"con":true,"img":false}]}
{"op":"mcm","clk":"5322390491","pt":1646319657861,"mc":[{"id":"1.195532861","rc":[{"atb":[[2.14,2]],"id":28791247},{"atb":[[2.54,2]],"id":39947224}],"con":true,"img":false}]}
{"op":"mcm","clk":"5322390505","pt":1646319658075,"mc":[{"id":"1.195532861","rc":[{"atb":[[2.18,1.65]],"id":28791247},{"atb":[[2.58,1.65]],"id":39947224}],"con":true,"img":false}]}
{"op":"mcm","clk":"5322390512","pt":1646319658175,"mc":[{"id":"1.195532861","rc":[{"atb":[[2.08,0]],"id":28791247}],"con":true,"img":false}]}
{"op":"mcm","clk":"5322390550","pt":1646319658600,"mc":[{"id":"1.195532861","rc":[{"atb":[[2.12,0],[2.14,37.09]],"id":28791247},{"atb":[[2.54,27.97],[2.52,0]],"id":39947224}],"con":true,"img":false}]}
{"op":"mcm","clk":"5322390559","pt":1646319658699,"mc":[{"id":"1.195532861","rc":[{"atb":[[1.52,192.31]],"id":42252553},{"atl":[[4.4,29.41]],"id":42252553}],"con":true,"img":false}]}
{"op":"mcm","clk":"5322390571","pt":1646319658903,"mc":[{"id":"1.195532861","rc":[{"atl":[[4.7,13.89]],"id":42252553}],"con":true,"img":false}]}
{"op":"mcm","clk":"5322390578","pt":1646319659013,"mc":[{"id":"1.195532861","rc":[{"atb":[[2.2,2.15],[2.1,0]],"id":28791247},{"atb":[[1.92,2.15],[1.88,45.45]],"id":23239795}],"con":true,"img":false}]}
{"op":"mcm","clk":"5322390597","pt":1646319659277,"mc":[{"id":"1.195532861","rc":[{"atl":[[4.7,0]],"id":42252553}],"con":true,"img":false}]}
{"op":"mcm","clk":"5322390603","pt":1646319659377,"mc":[{"id":"1.195532861","rc":[{"atb":[[2.54,25.97],[2.58,3.65]],"id":39947224},{"atb":[[1.87,0]],"id":37665265}],"con":true,"img":false}]}
{"op":"mcm","clk":"5322390620","pt":1646319659594,"mc":[{"id":"1.195532861","rc":[{"atb":[[2.16,0]],"id":28791247}],"con":true,"img":false}]}
{"op":"mcm","clk":"5322390628","pt":1646319659697,"mc":[{"id":"1.195532861","rc":[{"atb":[[2.22,1.99]],"id":28791247},{"atb":[[1.14,52.39]],"id":42252553},{"atl":[[60,0]],"id":42252553},{"atb":[[1.88,0],[1.9,46.43]],"id":23239795}],"con":true,"img":false}]}
{"op":"mcm","clk":"5322390646","pt":1646319659904,"mc":[{"id":"1.195532861","rc":[{"atb":[[1.14,0]],"id":42252553}],"con":true,"img":false}]}
{"op":"mcm","clk":"5322390651","pt":1646319660001,"mc":[{"id":"1.195532861","rc":[{"atb":[[1.9,44.44]],"id":23239795}],"con":true,"img":false}]}
{"op":"mcm","clk":"5322390661","pt":1646319660109,"mc":[{"id":"1.195532861","rc":[{"atb":[[1.93,1.99]],"id":23239795}],"con":true,"img":false}]}
{"op":"mcm","clk":"5322390720","pt":1646319660684,"mc":[{"id":"1.195532861","rc":[{"atb":[[1.55,181.82],[1.54,74.07]],"id":42252553},{"atl":[[3,6.94]],"id":42252553},{"atb":[[1.9,0],[1.91,43.96]],"id":23239795}],"con":true,"img":false}]}
{"op":"mcm","clk":"5322390729","pt":1646319660793,"mc":[{"id":"1.195532861","rc":[{"atb":[[2.56,0]],"id":39947224},{"atb":[[1.58,12.5]],"id":42252553}],"con":true,"img":false}]}
{"op":"mcm","clk":"5322390736","pt":1646319660892,"mc":[{"id":"1.195532861","rc":[{"atb":[[2.6,1.99]],"id":39947224},{"atb":[[1.58,0]],"id":42252553},{"atl":[[3,0]],"id":42252553}],"con":true,"img":false}]}
{"op":"mcm","clk":"5322390773","pt":1646319661371,"mc":[{"id":"1.195532861","rc":[{"atb":[[1.16,0]],"id":42252553}],"con":true,"img":false}]}
{"op":"mcm","clk":"5322390780","pt":1646319661523,"mc":[{"id":"1.195532861","rc":[{"atb":[[1.91,46.86]],"id":23239795}],"con":true,"img":false}]}
{"op":"mcm","clk":"5322390809","pt":1646319661786,"mc":[{"id":"1.195532861","rc":[{"atb":[[2.56,25.64],[2.54,0]],"id":39947224}],"con":true,"img":false}]}
{"op":"mcm","clk":"5322390817","pt":1646319661890,"mc":[{"id":"1.195532861","rc":[{"atl":[[18,0]],"id":41529436}],"con":true,"img":false}]}
{"op":"mcm","clk":"5322390825","pt":1646319661992,"mc":[{"id":"1.195532861","rc":[{"atl":[[18.5,5.71]],"id":41529436},{"atl":[[4,0],[3.95,29.41]],"id":42252553}],"con":true,"img":false}]}
{"op":"mcm","clk":"5322390868","pt":1646319662392,"mc":[{"id":"1.195532861","rc":[{"atl":[[19,0],[19.5,2.16]],"id":41529436}],"con":true,"img":false}]}
{"op":"mcm","clk":"5322390970","pt":1646319663602,"mc":[{"id":"1.195532861","rc":[{"atb":[[1.87,20.01]],"id":37665265},{"atb":[[1.56,4.55]],"id":42252553}],"con":true,"img":false}]}
{"op":"mcm","clk":"5322391091","pt":1646319664909,"mc":[{"id":"1.195532861","rc":[{"atb":[[2.18,0]],"id":28791247},{"atb":[[2.58,2]],"id":39947224}],"con":true,"img":false}]}
{"op":"mcm","clk":"5322391106","pt":1646319665116,"mc":[{"id":"1.195532861","rc":[{"atb":[[2.24,1.65]],"id":28791247},{"atb":[[2.62,1.65]],"id":39947224}],"con":true,"img":false}]}
{"op":"mcm","clk":"5322391123","pt":1646319665281,"mc":[{"id":"1.195532861","rc":[{"atb":[[1.89,0],[1.91,43.96],[1.93,4.15]],"id":23239795}],"con":true,"img":false}]}
{"op":"mcm","clk":"5322391153","pt":1646319665596,"mc":[{"id":"1.195532861","rc":[{"spn":5.62,"spf":"NaN","id":28791247},{"atb":[[2.56,0],[2.58,27.32]],"id":39947224},{"spn":14.31,"spf":"NaN","id":39947224},{"spn":1.97,"spf":1.0,"id":37665265},{"atb":[[2.76,11.24]],"id":41529436},{"spn":10.63,"spf":"NaN","id":41529436},{"atl":[[4.1,12.9],[4.2,0]],"id":42252553},{"spn":1.56,"spf":1.0,"id":42252553},{"spn":4.76,"spf":"NaN","id":23239795}],"con":true,"img":false}]}
{"op":"mcm","clk":"5322391160","pt":1646319665692,"mc":[{"id":"1.195532861","rc":[{"atb":[[2.14,35.09],[2.16,38.46]],"id":28791247},{"atl":[[10,0],[9.8,9.09]],"id":37665265},{"atb":[[2.78,11.24]],"id":41529436},{"atl":[[7.4,13.89],[7.6,0]],"id":23239795}],"con":true,"img":false}]}
{"op":"mcm","clk":"5322391166","pt":1646319665797,"mc":[{"id":"1.195532861","rc":[{"atb":[[2.7,1.99]],"id":41529436}],"con":true,"img":false}]}
{"op":"mcm","clk":"5322391176","pt":1646319665901,"mc":[{"id":"1.195532861","rc":[{"atl":[[10.5,4.21],[11,0]],"id":37665265},{"atb":[[2.74,22.99],[2.68,0]],"id":41529436},{"atl":[[7.8,5.88]],"id":23239795}],"con":true,"img":false}]}
{"op":"mcm","clk":"5322391194","pt":1646319666113,"mc":[{"id":"1.195532861","rc":[{"atb":[[2.76,0]],"id":41529436}],"con":true,"img":false}]}
{"op":"mcm","clk":"5322391326","pt":1646319667985,"mc":[{"id":"1.195532861","rc":[{"atb":[[2.7,0]],"id":41529436}],"con":true,"img":false}]}
{"op":"mcm","clk":"5322391332","pt":1646319668092,"mc":[{"id":"1.195532861","rc":[{"atb":[[2.8,1.99]],"id":41529436}],"con":true,"img":false}]}
{"op":"mcm","clk":"5322391344","pt":1646319668300,"mc":[{"id":"1.195532861","rc":[{"atb":[[2.62,3.65]],"id":39947224}],"con":true,"img":false}]}
{"op":"mcm","clk":"5322391349","pt":1646319668405,"mc":[{"id":"1.195532861","rc":[{"atb":[[2.58,25.32]],"id":39947224}],"con":true,"img":false}]}
{"op":"mcm","clk":"5322391361","pt":1646319668616,"mc":[{"id":"1.195532861","rc":[{"atb":[[2.1,90.91]],"id":28791247},{"atl":[[9.8,11.36]],"id":28791247}],"con":true,"img":false}]}
{"op":"mcm","clk":"5322391370","pt":1646319668716,"mc":[{"id":"1.195532861","rc":[{"atb":[[2.6,0]],"id":39947224}],"con":true,"img":false}]}
{"op":"mcm","clk":"5322391375","pt":1646319668822,"mc":[{"id":"1.195532861","rc":[{"atb":[[2.64,1.99]],"id":39947224}],"con":true,"img":false}]}
{"op":"mcm","clk":"5322391401","pt":1646319669189,"mc":[{"id":"1.195532861","rc":[{"atb":[[2,0],[1.98,0],[2.04,0]],"id":28791247},{"atl":[[12.5,0]],"id":28791247},{"atb":[[2.6,25],[2.58,0]],"id":39947224},{"atb":[[2.74,0],[2.76,22.73]],"id":41529436}],"con":true,"img":false}]}
{"op":"mcm","clk":"5322391412","pt":1646319669394,"mc":[{"id":"1.195532861","rc":[{"atb":[[1.08,50]],"id":28791247},{"atb":[[1.08,50]],"id":39947224},{"atb":[[1.08,50]],"id":37665265},{"atb":[[1.08,50]],"id":41529436},{"atb":[[1.08,50]],"id":42252553},{"atb":[[1.08,50]],"id":23239795}],"con":true,"img":false}]}
{"op":"mcm","clk":"5322391417","pt":1646319669500,"mc":[{"id":"1.195532861","rc":[{"atb":[[1.87,0]],"id":37665265},{"atb":[[1.82,7.88]],"id":23239795}],"con":true,"img":false}]}
{"op":"mcm","clk":"5322391506","pt":1646319670807,"mc":[{"id":"1.195532861","rc":[{"atb":[[2.16,0],[2.14,85.09]],"id":28791247},{"atl":[[10.5,14.74],[9.8,0]],"id":37665265}],"con":true,"img":false}]}
{"op":"mcm","clk":"5322391533","pt":1646319671122,"mc":[{"id":"1.195532861","rc":[{"atl":[[10.5,10.53],[11.5,3.81]],"id":37665265}],"con":true,"img":false}]}
{"op":"mcm","clk":"5322391596","pt":1646319671893,"mc":[{"id":"1.195532861","rc":[{"atb":[[2.62,2]],"id":39947224},{"atb":[[2.72,0]],"id":41529436}],"con":true,"img":false}]}
{"op":"mcm","clk":"5322391606","pt":1646319672016,"mc":[{"id":"1.195532861","rc":[{"atb":[[2.66,1.65]],"id":39947224},{"atb":[[2.82,1.65]],"id":41529436}],"con":true,"img":false}]}
{"op":"mcm","clk":"5322391620","pt":1646319672215,"mc":[{"id":"1.195532861","rc":[{"atb":[[2.66,3.65],[2.62,0]],"id":39947224}],"con":true,"img":false}]}
{"op":"mcm","clk":"5322391691","pt":1646319673008,"mc":[{"id":"1.195532861","rc":[{"atb":[[2.64,0]],"id":39947224}],"con":true,"img":false}]}
{"op":"mcm","clk":"5322391698","pt":1646319673100,"mc":[{"id":"1.195532861","rc":[{"atb":[[2.6,0],[2.62,24.69],[2.68,1.99]],"id":39947224},{"atb":[[2.78,33.71],[2.76,0]],"id":41529436}],"con":true,"img":false}]}
{"op":"mcm","clk":"5322391713","pt":1646319673311,"mc":[{"id":"1.195532861","rc":[{"atb":[[2.64,24.39],[2.62,0]],"id":39947224}],"con":true,"img":false}]}
{"op":"mcm","clk":"5322391830","pt":1646319674611,"mc":[{"id":"1.195532861","rc":[{"atb":[[2.82,3.65],[2.78,22.47]],"id":41529436},{"atl":[[7.2,5.88],[7.4,0]],"id":23239795}],"con":true,"img":false}]}
{"op":"mcm","clk":"5322391853","pt":1646319674916,"mc":[{"id":"1.195532861","rc":[{"atb":[[2.8,0]],"id":41529436},{"atl":[[7.6,6.06],[7.8,0]],"id":23239795}],"con":true,"img":false}]}
{"op":"mcm","clk":"5322391864","pt":1646319675023,"mc":[{"id":"1.195532861","rc":[{"atb":[[2.84,1.99]],"id":41529436}],"con":true,"img":false}]}
{"op":"mcm","clk":"5322391885","pt":1646319675330,"mc":[{"id":"1.195532861","rc":[{"atb":[[1.87,20.01]],"id":37665265}],"con":true,"img":false}]}
{"op":"mcm","clk":"5322391903","pt":1646319675540,"mc":[{"id":"1.195532861","rc":[{"atb":[[1.5,250]],"id":42252553}],"con":true,"img":false}]}
{"op":"mcm","clk":"5322392040","pt":1646319677140,"mc":[{"id":"1.195532861","rc":[{"atb":[[1.82,0]],"id":23239795}],"con":true,"img":false}]}
{"op":"mcm","clk":"5322392094","pt":1646319677723,"mc":[{"id":"1.195532861","rc":[{"atl":[[9,0],[9.2,12.2]],"id":28791247},{"atb":[[1.15,0],[1.13,0]],"id":42252553}],"con":true,"img":false}]}
{"op":"mcm","clk":"5322392101","pt":1646319677826,"mc":[{"id":"1.195532861","rc":[{"atl":[[9.2,15.33]],"id":28791247}],"con":true,"img":false}]}
{"op":"mcm","clk":"5322392116","pt":1646319678036,"mc":[{"id":"1.195532861","rc":[{"atl":[[9.2,12.2]],"id":28791247}],"con":true,"img":false}]}
{"op":"mcm","clk":"5322392146","pt":1646319678508,"mc":[{"id":"1.195532861","rc":[{"atb":[[2.06,141.51]],"id":28791247},{"atl":[[9.6,4.65],[9.4,0]],"id":28791247}],"con":true,"img":false}]}
{"op":"mcm","clk":"5322392185","pt":1646319679023,"mc":[{"id":"1.195532861","rc":[{"atb":[[2.66,2]],"id":39947224},{"atb":[[2.82,2]],"id":41529436}],"con":true,"img":false}]}
{"op":"mcm","clk":"5322392203","pt":1646319679236,"mc":[{"id":"1.195532861","rc":[{"atb":[[2.7,1.65]],"id":39947224},{"atb":[[2.86,1.65]],"id":41529436}],"con":true,"img":false}]}
{"op":"mcm","clk":"5322392221","pt":1646319679437,"mc":[{"id":"1.195532861","rc":[{"atb":[[2.82,0],[2.86,3.65]],"id":41529436}],"con":true,"img":false}]}
{"op":"mcm","clk":"5322392234","pt":1646319679600,"mc":[{"id":"1.195532861","rc":[{"atb":[[2.66,26.1],[2.64,0]],"id":39947224},{"atl":[[10,9.09],[10.5,0]],"id":37665265}],"con":true,"img":false}]}
{"op":"mcm","clk":"5322392262","pt":1646319679924,"mc":[{"id":"1.195532861","rc":[{"atl":[[11,4],[11.5,0]],"id":37665265}],"con":true,"img":false}]}
{"op":"mcm","clk":"5322392294","pt":1646319680335,"mc":[{"id":"1.195532861","rc":[{"atb":[[2.84,0]],"id":41529436}],"con":true,"img":false}]}
{"op":"mcm","clk":"5322392307","pt":1646319680436,"mc":[{"id":"1.195532861","rc":[{"atb":[[2.88,1.99]],"id":41529436}],"con":true,"img":false}]}
{"op":"mcm","clk":"5322392359","pt":1646319681011,"mc":[{"id":"1.195532861","rc":[{"atb":[[2.66,24.1],[2.7,3.65]],"id":39947224}],"con":true,"img":false}]}
{"op":"mcm","clk":"5322392377","pt":1646319681323,"mc":[{"id":"1.195532861","rc":[{"atb":[[1.82,7.88]],"id":23239795}],"con":true,"img":false}]}
{"op":"mcm","clk":"5322392394","pt":1646319681529,"mc":[{"id":"1.195532861","rc":[{"atb":[[2.68,0]],"id":39947224}],"con":true,"img":false}]}
{"op":"mcm","clk":"5322392401","pt":1646319681635,"mc":[{"id":"1.195532861","rc":[{"atb":[[2.72,1.99]],"id":39947224}],"con":true,"img":false}]}
{"op":"mcm","clk":"5322392445","pt":1646319682114,"mc":[{"id":"1.195532861","rc":[{"atb":[[2.66,0],[2.68,23.81]],"id":39947224}],"con":true,"img":false}]}
{"op":"mcm","clk":"5322392495","pt":1646319682832,"mc":[{"id":"1.195532861","rc":[{"atb":[[2.12,89.29],[2.14,35.09]],"id":28791247},{"atl":[[9.6,16.28],[9.2,0]],"id":28791247},{"atl":[[18.5,0],[18,5]],"id":41529436}],"con":true,"img":false}]}
{"op":"mcm","clk":"5322392512","pt":1646319683040,"mc":[{"id":"1.195532861","rc":[{"atl":[[19,4.28]],"id":41529436}],"con":true,"img":false}]}
{"op":"mcm","clk":"5322392519","pt":1646319683148,"mc":[{"id":"1.195532861","rc":[{"atl":[[9.6,11.63],[10,4.44]],"id":28791247},{"atl":[[19,6.5],[19.5,0]],"id":41529436}],"con":true,"img":false}]}
{"op":"mcm","clk":"5322392528","pt":1646319683253,"mc":[{"id":"1.195532861","rc":[{"atb":[[1.87,0]],"id":37665265}],"con":true,"img":false}]}
{"op":"mcm","clk":"5322392533","pt":1646319683347,"mc":[{"id":"1.195532861","rc":[{"atl":[[9.8,0]],"id":28791247},{"atl":[[19,2.22]],"id":41529436}],"con":true,"img":false}]}
{"op":"mcm","clk":"5322392654","pt":1646319684927,"mc":[{"id":"1.195532861","rc":[{"atb":[[1.89,112.36]],"id":23239795},{"atl":[[8,14.29]],"id":23239795}],"con":true,"img":false}]}
{"op":"mcm","clk":"5322392699","pt":1646319685547,"mc":[{"id":"1.195532861","rc":[{"atb":[[1.48,250]],"id":42252553}],"con":true,"img":false}]}
{"op":"mcm","clk":"5322392736","pt":1646319685959,"mc":[{"id":"1.195532861","rc":[{"atb":[[2.7,2]],"id":39947224},{"atb":[[2.86,2]],"id":41529436}],"con":true,"img":false}]}
{"op":"mcm","clk":"5322392751","pt":1646319686124,"mc":[{"id":"1.195532861","rc":[{"atb":[[2.74,1.65]],"id":39947224},{"atb":[[2.9,1.65]],"id":41529436},{"atb":[[1.77,0]],"id":23239795}],"con":true,"img":false}]}
{"op":"mcm","clk":"5322392808","pt":1646319686949,"mc":[{"id":"1.195532861","rc":[{"atb":[[2.68,0],[2.7,25.53]],"id":39947224}],"con":true,"img":false}]}
{"op":"mcm","clk":"5322392843","pt":1646319687327,"mc":[{"id":"1.195532861","rc":[{"atb":[[1.87,20.01]],"id":37665265},{"atb":[[1.82,0]],"id":23239795}],"con":true,"img":false}]}
{"op":"mcm","clk":"5322392878","pt":1646319687734,"mc":[{"id":"1.195532861","rc":[{"atb":[[2.12,0],[2.14,122.81]],"id":28791247},{"atl":[[9.6,0],[9,10.53]],"id":28791247},{"atl":[[10,0],[10.5,10.53]],"id":37665265},{"atl":[[7.2,0],[7.4,17.92]],"id":23239795}],"con":true,"img":false}]}
{"op":"mcm","clk":"5322392902","pt":1646319687944,"mc":[{"id":"1.195532861","rc":[{"atl":[[9.4,4.76]],"id":28791247},{"atl":[[11,0],[11.5,3.81]],"id":37665265},{"atl":[[7.6,0],[7.8,5.88]],"id":23239795}],"con":true,"img":false}]}
{"op":"mcm","clk":"5322392920","pt":1646319688145,"mc":[{"id":"1.195532861","rc":[{"atl":[[7.4,13.89]],"id":23239795}],"con":true,"img":false}]}
{"op":"mcm","clk":"5322392927","pt":1646319688248,"mc":[{"id":"1.195532861","rc":[{"atb":[[2.9,3.65],[2.86,0]],"id":41529436}],"con":true,"img":false}]}
{"op":"mcm","clk":"5322392951","pt":1646319688455,"mc":[{"id":"1.195532861","rc":[{"atb":[[1.99,20]],"id":37665265}],"con":true,"img":false}]}
{"op":"mcm","clk":"5322392975","pt":1646319688627,"mc":[{"id":"1.195532861","rc":[{"atb":[[2,9.78],[1.99,0],[1.96,0]],"id":37665265},{"atb":[[2.88,0]],"id":41529436}],"con":true,"img":false}]}
{"op":"mcm","clk":"5322392988","pt":1646319688721,"mc":[{"id":"1.195532861","rc":[{"atb":[[2.92,1.99]],"id":41529436}],"con":true,"img":false}]}
{"op":"mcm","clk":"5322393010","pt":1646319689026,"mc":[{"id":"1.195532861","rc":[{"atb":[[1.98,40.82],[1.95,2.15]],"id":37665265}],"con":true,"img":false}]}
{"op":"mcm","clk":"5322393057","pt":1646319689544,"mc":[{"id":"1.195532861","rc":[{"atb":[[1.97,0]],"id":37665265}],"con":true,"img":false}]}
{"op":"mcm","clk":"5322393065","pt":1646319689648,"mc":[{"id":"1.195532861","rc":[{"atb":[[2.02,1.99]],"id":37665265}],"con":true,"img":false}]}
{"op":"mcm","clk":"5322393076","pt":1646319689751,"mc":[{"id":"1.195532861","rc":[{"atb":[[2.74,3.65],[2.7,23.53]],"id":39947224}],"con":true,"img":false}]}
{"op":"mcm","clk":"5322393115","pt":1646319690173,"mc":[{"id":"1.195532861","rc":[{"atb":[[2.72,0]],"id":39947224}],"con":true,"img":false}]}
{"op":"mcm","clk":"5322393135","pt":1646319690334,"mc":[{"id":"1.195532861","rc":[{"atb":[[2.76,1.99]],"id":39947224}],"con":true,"img":false}]}
{"op":"mcm","clk":"5322393153","pt":1646319690553,"mc":[{"id":"1.195532861","rc":[{"atb":[[2.72,23.26],[2.7,0]],"id":39947224},{"atb":[[1.99,40.4],[1.98,0]],"id":37665265}],"con":true,"img":false}]}
{"op":"mcm","clk":"5322393169","pt":1646319690745,"mc":[{"id":"1.195532861","rc":[{"atb":[[2.6,7.14]],"id":39947224}],"con":true,"img":false}]}
{"op":"mcm","clk":"5322393179","pt":1646319690953,"mc":[{"id":"1.195532861","rc":[{"atb":[[2.6,0]],"id":39947224}],"con":true,"img":false}]}
{"op":"mcm","clk":"5322393200","pt":1646319691259,"mc":[{"id":"1.195532861","rc":[{"atb":[[1.87,0]],"id":37665265},{"atb":[[1.94,2.9]],"id":23239795}],"con":true,"img":false}]}
{"op":"mcm","clk":"5322393321","pt":1646319692949,"mc":[{"id":"1.195532861","rc":[{"atb":[[2.74,2]],"id":39947224},{"atb":[[2.9,2]],"id":41529436}],"con":true,"img":false}]}
{"op":"mcm","clk":"5322393330","pt":1646319693054,"mc":[{"id":"1.195532861","rc":[{"atb":[[2.12,89.29],[2.14,35.09]],"id":28791247},{"atl":[[9.6,11.63],[9,0]],"id":28791247},{"atb":[[2.78,1.65]],"id":39947224},{"atb":[[2.04,1.65]],"id":37665265},{"atb":[[2.94,1.65]],"id":41529436},{"atb":[[1.8,12.54],[1.92,45.63],[1.91,0]],"id":23239795},{"atl":[[7.2,13.89],[7.4,0]],"id":23239795}],"con":true,"img":false}]}
{"op":"mcm","clk":"5322393337","pt":1646319693152,"mc":[{"id":"1.195532861","rc":[{"atb":[[2.74,57.47],[2.66,9.02]],"id":41529436}],"con":true,"img":false}]}
{"op":"mcm","clk":"5322393346","pt":1646319693263,"mc":[{"id":"1.195532861","rc":[{"atb":[[2.08,5.19]],"id":28791247}],"con":true,"img":false}]}
{"op":"mcm","clk":"5322393354","pt":1646319693359,"mc":[{"id":"1.195532861","rc":[{"atb":[[2.66,0]],"id":41529436},{"atb":[[1.8,0]],"id":23239795}],"con":true,"img":false}]}
{"op":"mcm","clk":"5322393368","pt":1646319693463,"mc":[{"id":"1.195532861","rc":[{"atb":[[2.08,0]],"id":28791247}],"con":true,"img":false}]}
{"op":"mcm","clk":"5322393395","pt":1646319693737,"mc":[{"id":"1.195532861","rc":[{"atl":[[9.8,4.55],[9.4,0]],"id":28791247},{"atb":[[2.72,0],[2.74,24.99]],"id":39947224},{"atb":[[2,49.78],[1.99,0]],"id":37665265},{"atb":[[2.56,0],[2.64,0],[2.6,0]],"id":41529436},{"atl":[[7.6,6.06],[7.8,0]],"id":23239795}],"con":true,"img":false}]}
{"op":"mcm","clk":"5322393525","pt":1646319695144,"mc":[{"id":"1.195532861","rc":[{"atb":[[1.87,24.72]],"id":37665265}],"con":true,"img":false}]}
{"op":"mcm","clk":"5322393669","pt":1646319697061,"mc":[{"id":"1.195532861","rc":[{"atb":[[1.93,2.16]],"id":23239795}],"con":true,"img":false}]}
{"op":"mcm","clk":"5322393675","pt":1646319697165,"mc":[{"id":"1.195532861","rc":[{"atb":[[1.95,1.99]],"id":23239795}],"con":true,"img":false}]}
{"op":"mcm","clk":"5322393690","pt":1646319697325,"mc":[{"id":"1.195532861","rc":[{"atb":[[2,40],[2.04,3.65]],"id":37665265},{"atb":[[1.95,4.15],[1.93,0]],"id":23239795}],"con":true,"img":false}]}
{"op":"mcm","clk":"5322393707","pt":1646319697639,"mc":[{"id":"1.195532861","rc":[{"atb":[[2.02,0]],"id":37665265}],"con":true,"img":false}]}
{"op":"mcm","clk":"5322393718","pt":1646319697742,"mc":[{"id":"1.195532861","rc":[{"atb":[[2.06,1.99]],"id":37665265}],"con":true,"img":false}]}
{"op":"mcm","clk":"5322393768","pt":1646319698361,"mc":[{"id":"1.195532861","rc":[{"atb":[[2.74,22.99],[2.78,3.65]],"id":39947224}],"con":true,"img":false}]}
{"op":"mcm","clk":"5322393785","pt":1646319698569,"mc":[{"id":"1.195532861","rc":[{"atb":[[2.78,1.65],[2.76,5.31]],"id":39947224}],"con":true,"img":false}]}
{"op":"mcm","clk":"5322393794","pt":1646319698673,"mc":[{"id":"1.195532861","rc":[{"atl":[[10,9.09],[10.5,0]],"id":37665265},{"atb":[[2.88,22.47],[2.9,0]],"id":41529436},{"atb":[[1.92,2.15],[1.93,43.01]],"id":23239795}],"con":true,"img":false}]}
{"op":"mcm","clk":"5322393803","pt":1646319698735,"mc":[{"id":"1.195532861","rc":[{"atb":[[1.92,16.12]],"id":37665265}],"con":true,"img":false}]}
{"op":"mcm","clk":"5322393814","pt":1646319698839,"mc":[{"id":"1.195532861","rc":[{"atb":[[2.76,3.32]],"id":39947224},{"atb":[[1.92,0]],"id":37665265}],"con":true,"img":false}]}
{"op":"mcm","clk":"5322393821","pt":1646319698941,"mc":[{"id":"1.195532861","rc":[{"atb":[[2.8,1.99]],"id":39947224}],"con":true,"img":false}]}
{"op":"mcm","clk":"5322393831","pt":1646319699044,"mc":[{"id":"1.195532861","rc":[{"atl":[[11,7.39]],"id":37665265},{"atl":[[4.5,13.62]],"id":42252553}],"con":true,"img":false}]}
{"op":"mcm","clk":"5322393842","pt":1646319699147,"mc":[{"id":"1.195532861","rc":[{"atb":[[2.8,3.99],[2.76,0]],"id":39947224}],"con":true,"img":false}]}
{"op":"mcm","clk":"5322393852","pt":1646319699252,"mc":[{"id":"1.195532861","rc":[{"atl":[[4.5,0]],"id":42252553}],"con":true,"img":false}]}
{"op":"mcm","clk":"5322393862","pt":1646319699352,"mc":[{"id":"1.195532861","rc":[{"atl":[[11,0]],"id":37665265}],"con":true,"img":false}]}
{"op":"mcm","clk":"5322393868","pt":1646319699461,"mc":[{"id":"1.195532861","rc":[{"atb":[[2.74,0],[2.76,22.73]],"id":39947224},{"atl":[[11,4],[11.5,0]],"id":37665265}],"con":true,"img":false}]}
{"op":"mcm","clk":"5322393891","pt":1646319699768,"mc":[{"id":"1.195532861","rc":[{"atb":[[2.92,0]],"id":41529436}],"con":true,"img":false}]}
{"op":"mcm","clk":"5322393899","pt":1646319699869,"mc":[{"id":"1.195532861","rc":[{"atb":[[2.9,1.99]],"id":41529436}],"con":true,"img":false}]}
{"op":"mcm","clk":"5322393906","pt":1646319699938,"mc":[{"id":"1.195532861","rc":[{"atb":[[2.78,0]],"id":39947224},{"atb":[[2.04,2]],"id":37665265}],"con":true,"img":false}]}
{"op":"mcm","clk":"5322393920","pt":1646319700149,"mc":[{"id":"1.195532861","rc":[{"atb":[[2.82,1.65]],"id":39947224},{"atb":[[2.08,1.65]],"id":37665265}],"con":true,"img":false}]}
{"op":"mcm","clk":"5322393954","pt":1646319700551,"mc":[{"id":"1.195532861","rc":[{"atb":[[1.87,0]],"id":37665265},{"atb":[[1.94,0]],"id":23239795}],"con":true,"img":false}]}
{"op":"mcm","clk":"5322394027","pt":1646319701652,"mc":[{"id":"1.195532861","rc":[{"atb":[[2.84,9.3],[2.78,22.47],[2.76,0]],"id":39947224}],"con":true,"img":false}]}
{"op":"mcm","clk":"5322394047","pt":1646319701858,"mc":[{"id":"1.195532861","rc":[{"atb":[[2.84,0]],"id":39947224}],"con":true,"img":false}]}
{"op":"mcm","clk":"5322394161","pt":1646319703155,"mc":[{"id":"1.195532861","rc":[{"atb":[[2.7,88.24]],"id":41529436}],"con":true,"img":false}]}
{"op":"mcm","clk":"5322394211","pt":1646319703680,"mc":[{"id":"1.195532861","rc":[{"atl":[[9.6,0],[9.4,4.55]],"id":28791247},{"atl":[[10,0],[10.5,10.53]],"id":37665265},{"atb":[[2.88,0],[2.9,24.46]],"id":41529436}],"con":true,"img":false}]}
{"op":"mcm","clk":"5322394222","pt":1646319703775,"mc":[{"id":"1.195532861","rc":[{"atb":[[2.02,245.1]],"id":28791247},{"atl":[[12.5,21.74]],"id":28791247}],"con":true,"img":false}]}
{"op":"mcm","clk":"5322394287","pt":1646319704573,"mc":[{"id":"1.195532861","rc":[{"atl":[[10,0]],"id":28791247},{"atb":[[1.87,8.74]],"id":37665265},{"atl":[[11,0],[11.5,3.81]],"id":37665265},{"atb":[[1.9,5.38]],"id":23239795}],"con":true,"img":false}]}
{"op":"mcm","clk":"5322394401","pt":1646319705989,"mc":[{"id":"1.195532861","rc":[{"atb":[[2.04,0],[2.08,3.65]],"id":37665265}],"con":true,"img":false}]}
{"op":"mcm","clk":"5322394473","pt":1646319706975,"mc":[{"id":"1.195532861","rc":[{"atb":[[2.06,0]],"id":37665265},{"atb":[[2.94,0]],"id":41529436}],"con":true,"img":false}]}
{"op":"mcm","clk":"5322394485","pt":1646319707081,"mc":[{"id":"1.195532861","rc":[{"atb":[[1.02,1.99]],"id":37665265}],"con":true,"img":false}]}
{"op":"mcm","clk":"5322394498","pt":1646319707186,"mc":[{"id":"1.195532861","rc":[{"atb":[[2.92,1.65]],"id":41529436}],"con":true,"img":false}]}
{"op":"mcm","clk":"5322394612","pt":1646319708688,"mc":[{"id":"1.195532861","rc":[{"atb":[[1.91,109.89]],"id":23239795},{"atl":[[8.4,20.27]],"id":23239795}],"con":true,"img":false}]}
{"op":"mcm","clk":"5322394705","pt":1646319710090,"mc":[{"id":"1.195532861","rc":[{"atb":[[1.92,0],[1.96,2.15]],"id":23239795}],"con":true,"img":false}]}
{"op":"mcm","clk":"5322394725","pt":1646319710259,"mc":[{"id":"1.195532861","rc":[{"atb":[[1.94,42.55],[1.93,0]],"id":23239795},{"atl":[[8.6,0],[8.2,0]],"id":23239795}],"con":true,"img":false}]}
{"op":"mcm","clk":"5322394769","pt":1646319710781,"mc":[{"id":"1.195532861","rc":[{"atb":[[1.95,2.16]],"id":23239795}],"con":true,"img":false}]}
{"op":"mcm","clk":"5322394780","pt":1646319710886,"mc":[{"id":"1.195532861","rc":[{"atb":[[1.97,1.99]],"id":23239795}],"con":true,"img":false}]}
{"op":"mcm","clk":"5322394805","pt":1646319711090,"mc":[{"id":"1.195532861","rc":[{"atb":[[1.97,4.15],[1.95,0]],"id":23239795}],"con":true,"img":false}]}
{"op":"mcm","clk":"5322394858","pt":1646319711664,"mc":[{"id":"1.195532861","rc":[{"atb":[[2.74,57.47]],"id":39947224},{"atl":[[38,6.76]],"id":39947224}],"con":true,"img":false}]}
{"op":"mcm","clk":"5322394866","pt":1646319711771,"mc":[{"id":"1.195532861","rc":[{"atb":[[1.9,0]],"id":23239795}],"con":true,"img":false}]}
{"op":"mcm","clk":"5322394990","pt":1646319713180,"mc":[{"id":"1.195532861","rc":[{"atb":[[2.66,150.6]],"id":41529436}],"con":true,"img":false}]}
{"op":"mcm","clk":"5322395106","pt":1646319714576,"mc":[{"id":"1.195532861","rc":[{"atb":[[1.98,102.04]],"id":37665265},{"atl":[[12.5,8.7]],"id":37665265}],"con":true,"img":false}]}
{"op":"mcm","clk":"5322395215","pt":1646319715769,"mc":[{"id":"1.195532861","rc":[{"atb":[[1.92,5.38]],"id":23239795}],"con":true,"img":false}]}
{"op":"mcm","clk":"5322395327","pt":1646319717679,"mc":[{"id":"1.195532861","rc":[{"atb":[[1.87,0]],"id":37665265}],"con":true,"img":false}]}
{"op":"mcm","clk":"5322395494","pt":1646319720273,"mc":[{"id":"1.195532861","rc":[{"atb":[[1.94,24.94],[2.2,14.96],[1.95,42.11]],"id":23239795},{"atl":[[8,42.42],[6.8,13.79],[8.8,32.05]],"id":23239795}],"con":true,"img":false}]}
{"op":"mcm","clk":"5322395501","pt":1646319720380,"mc":[{"id":"1.195532861","rc":[{"atb":[[2.04,10],[2.12,5],[2.2,17.46]],"id":23239795},{"atl":[[5.6,5],[6,10],[5.2,2.5]],"id":23239795}],"con":true,"img":false}]}
{"op":"mcm","clk":"5322395510","pt":1646319720484,"mc":[{"id":"1.195532861","rc":[{"atb":[[2.24,16.68],[2.4,2.5],[2.32,5],[2.14,46.47]],"id":28791247},{"atl":[[8,5.03],[10.5,28.73],[6.2,2.5],[7,5],[7.8,10]],"id":28791247},{"atb":[[3,5.58],[2.98,5],[2.74,69.53],[2.9,10],[3.15,2.5]],"id":39947224},{"atl":[[16,5.33],[9,2.5],[11.5,10],[9.8,5],[30,10.95]],"id":39947224},{"atb":[[1.98,126.56],[2.3,2.5],[2.22,5],[2.14,24.71]],"id":37665265},{"atl":[[5.6,2.5],[12,27.85],[6,5],[6.8,10],[8.4,10.81]],"id":37665265},{"atb":[[2.9,31.96],[2.74,94.31]],"id":41529436},{"atl":[[8,10],[7.2,5],[6.4,2.5],[21,15.71],[9.8,7.5]],"id":41529436},{"atb":[[1.6,15.09],[1.55,234.71],[1.49,21.83]],"id":42252553},{"atl":[[3.35,2.5],[3,13.1],[3.55,5],[4.4,80.59],[3.75,10]],"id":42252553},{"atb":[[2.04,39.92]],"id":23239795},{"atl":[[6,23.79],[6.8,0],[6.6,1.8]],"id":23239795}],"con":true,"img":false}]}
{"op":"mcm","clk":"5322395519","pt":1646319720587,"mc":[{"id":"1.195532861","rc":[{"atl":[[7.8,14.55],[9.4,0]],"id":28791247},{"atb":[[2.8,1.99],[2.9,13.99]],"id":39947224},{"atl":[[11.5,13.45],[26,0]],"id":39947224},{"atb":[[2.14,64.71],[2.08,1.65]],"id":37665265},{"atl":[[10.5,0],[6.8,19.09]],"id":37665265},{"atl":[[8,15],[18,0]],"id":41529436},{"atb":[[1.49,0]],"id":42252553},{"atl":[[3.95,0],[3.75,39.41]],"id":42252553},{"atb":[[1.97,1.99]],"id":23239795},{"atl":[[7.2,0]],"id":23239795}],"con":true,"img":false}]}
{"op":"mcm","clk":"5322395526","pt":1646319720691,"mc":[{"id":"1.195532861","rc":[{"atl":[[27,3]],"id":39947224}],"con":true,"img":false}]}
{"op":"mcm","clk":"5322395537","pt":1646319720791,"mc":[{"id":"1.195532861","rc":[{"atl":[[9.6,4.56]],"id":28791247},{"atb":[[1.97,0]],"id":23239795}],"con":true,"img":false}]}
{"op":"mcm","clk":"5322395543","pt":1646319720894,"mc":[{"id":"1.195532861","rc":[{"atb":[[2.24,15.03]],"id":28791247},{"atl":[[9.6,0],[5.9,6.03]],"id":28791247},{"atb":[[2.82,0]],"id":39947224},{"atl":[[27,0]],"id":39947224},{"atb":[[2.08,0]],"id":37665265},{"atl":[[6.8,6]],"id":41529436},{"atb":[[2.22,1.99]],"id":23239795}],"con":true,"img":false}]}
{"op":"mcm","clk":"5322395562","pt":1646319721096,"mc":[{"id":"1.195532861","rc":[{"atb":[[2.42,1.65]],"id":28791247},{"atb":[[3.2,1.65]],"id":39947224},{"atb":[[2.32,1.65]],"id":37665265},{"atb":[[2.22,3.64]],"id":23239795}],"con":true,"img":false}]}
{"op":"mcm","clk":"5322395578","pt":1646319721303,"mc":[{"id":"1.195532861","rc":[{"atl":[[6.2,10.19],[9.8,0]],"id":28791247},{"atb":[[2.78,0]],"id":39947224},{"atl":[[34,0],[38,0],[28,0],[30,7.5],[60,0]],"id":39947224},{"atb":[[1.74,0]],"id":37665265},{"atl":[[5.8,8.33],[11.5,0],[12.5,0]],"id":37665265},{"atl":[[19,0],[6.8,12.9]],"id":41529436},{"atb":[[2.1,36.36]],"id":23239795},{"atl":[[5.4,9.09]],"id":23239795}],"con":true,"img":false}]}
{"op":"mcm","clk":"5322395591","pt":1646319721365,"mc":[{"id":"1.195532861","rc":[{"atb":[[2.22,0]],"id":28791247},{"atb":[[2.86,21.51]],"id":39947224},{"atl":[[9.4,4.76]],"id":39947224},{"atb":[[1.55,52.89],[1.54,259.26]],"id":42252553},{"atl":[[3.1,19.05],[4.1,0]],"id":42252553},{"atb":[[1.95,0]],"id":23239795},{"atl":[[7.6,0]],"id":23239795}],"con":true,"img":false}]}
{"op":"mcm","clk":"5322395598","pt":1646319721474,"mc":[{"id":"1.195532861","rc":[{"atb":[[2.42,3.64]],"id":28791247}],"con":true,"img":false}]}
{"op":"mcm","clk":"5322395607","pt":1646319721689,"mc":[{"id":"1.195532861","rc":[{"atb":[[2.3,2.15],[2.14,35.09],[2.2,0]],"id":28791247},{"atb":[[2.8,0]],"id":39947224},{"atb":[[1.95,0],[2.02,4.02],[2.2,2.15]],"id":37665265},{"atb":[[1.59,0],[1.63,2.15]],"id":42252553},{"atb":[[1.96,0],[2.26,2.15]],"id":23239795}],"con":true,"img":false}]}
{"op":"mcm","clk":"5322395617","pt":1646319721787,"mc":[{"id":"1.195532861","rc":[{"atb":[[3.2,3.64]],"id":39947224}],"con":true,"img":false}]}
{"op":"mcm","clk":"5322395631","pt":1646319721989,"mc":[{"id":"1.195532861","rc":[{"atb":[[1.7,0],[2.2,0],[2.16,0]],"id":39947224},{"atb":[[1.79,0]],"id":23239795}],"con":true,"img":false}]}
{"op":"mcm","clk":"5322395655","pt":1646319722294,"mc":[{"id":"1.195532861","rc":[{"atb":[[1.6,13.1]],"id":42252553}],"con":true,"img":false}]}
{"op":"mcm","clk":"5322395662","pt":1646319722409,"mc":[{"id":"1.195532861","rc":[{"atl":[[6.8,6.9]],"id":41529436},{"atb":[[1.58,12.53],[1.02,1.99]],"id":42252553},{"atb":[[2.1,40.36]],"id":23239795}],"con":true,"img":false}]}
{"op":"mcm","clk":"5322395684","pt":1646319722709,"mc":[{"id":"1.195532861","rc":[{"atl":[[5.9,0]],"id":28791247},{"atb":[[1.58,0]],"id":42252553},{"atb":[[2.22,1.65],[2.1,36.36]],"id":23239795}],"con":true,"img":false}]}
{"op":"mcm","clk":"5322395694","pt":1646319722773,"mc":[{"id":"1.195532861","rc":[{"atb":[[2.28,1.99]],"id":23239795}],"con":true,"img":false}]}
{"op":"mcm","clk":"5322395748","pt":1646319723397,"mc":[{"id":"1.195532861","rc":[{"atl":[[6.2,2.5],[6.6,7.14]],"id":28791247}],"con":true,"img":false}]}
{"op":"mcm","clk":"5322395763","pt":1646319723503,"mc":[{"id":"1.195532861","rc":[{"atl":[[6.2,3.42]],"id":41529436}],"con":true,"img":false}]}
{"op":"mcm","clk":"5322395790","pt":1646319723809,"mc":[{"id":"1.195532861","rc":[{"atb":[[2.02,0]],"id":37665265},{"atl":[[6.8,0],[6.6,7.14],[7,3.45]],"id":41529436},{"atb":[[1.92,0]],"id":23239795}],"con":true,"img":false}]}
{"op":"mcm","clk":"5322395808","pt":1646319723985,"mc":[{"id":"1.195532861","rc":[{"atl":[[7,0]],"id":41529436}],"con":true,"img":false}]}
{"op":"mcm","clk":"5322396081","pt":1646319727709,"mc":[{"id":"1.195532861","rc":[{"spn":4.31,"spf":"NaN","id":28791247},{"spn":6.1,"spf":"NaN","id":39947224},{"atb":[[2.16,6.24]],"id":37665265},{"spn":2.32,"spf":1.0,"id":37665265},{"spn":4.56,"spf":"NaN","id":41529436},{"spn":1.6,"spf":1.0,"id":42252553},{"atb":[[2.14,5.8]],"id":23239795},{"spn":3.74,"spf":"NaN","id":23239795}],"con":true,"img":false}]}
{"op":"mcm","clk":"5322396102","pt":1646319727980,"mc":[{"id":"1.195532861","rc":[{"atb":[[2.22,0]],"id":23239795}],"con":true,"img":false}]}
{"op":"mcm","clk":"5322396112","pt":1646319728089,"mc":[{"id":"1.195532861","rc":[{"atb":[[2.3,1.65]],"id":23239795}],"con":true,"img":false}]}
{"op":"mcm","clk":"5322396157","pt":1646319728704,"mc":[{"id":"1.195532861","rc":[{"atb":[[2.96,7.02]],"id":39947224}],"con":true,"img":false}]}
{"op":"mcm","clk":"5322396162","pt":1646319728806,"mc":[{"id":"1.195532861","rc":[{"atb":[[2.22,5.81],[2.04,10]],"id":23239795},{"atl":[[5.6,16.59],[6,10]],"id":23239795}],"con":true,"img":false}]}
{"op":"mcm","clk":"5322396169","pt":1646319728907,"mc":[{"id":"1.195532861","rc":[{"atl":[[7,14.64],[7.8,10]],"id":28791247},{"atb":[[2.9,10],[3.05,6.15]],"id":39947224},{"atl":[[11.5,10],[9.8,12.26]],"id":39947224},{"atb":[[2.3,5.82],[2.14,24.71]],"id":37665265},{"atl":[[6,15.83],[6.8,10]],"id":37665265},{"atl":[[8,10],[6,3.42]],"id":41529436},{"atl":[[3.35,34.65],[3.75,10]],"id":42252553}],"con":true,"img":false}]}
{"op":"mcm","clk":"5322396188","pt":1646319729210,"mc":[{"id":"1.195532861","rc":[{"atb":[[2.96,0]],"id":39947224}],"con":true,"img":false}]}
{"op":"mcm","clk":"5322396199","pt":1646319729313,"mc":[{"id":"1.195532861","rc":[{"atl":[[6.4,9.91],[6.6,0]],"id":41529436}],"con":true,"img":false}]}
{"op":"mcm","clk":"5322396273","pt":1646319730201,"mc":[{"id":"1.195532861","rc":[{"atl":[[6.2,0]],"id":41529436}],"con":true,"img":false}]}
{"op":"mcm","clk":"5322396289","pt":1646319730403,"mc":[{"id":"1.195532861","rc":[{"atl":[[7.2,18.33],[6,0]],"id":41529436}],"con":true,"img":false}]}
{"op":"mcm","clk":"5322396346","pt":1646319731194,"mc":[{"id":"1.195532861","rc":[{"atb":[[2.14,0]],"id":23239795}],"con":true,"img":false}]}
{"op":"mcm","clk":"5322396353","pt":1646319731294,"mc":[{"id":"1.195532861","rc":[{"atb":[[2.82,54.95]],"id":39947224},{"atl":[[9.8,23.62]],"id":39947224},{"atb":[[1.96,156.25]],"id":37665265},{"atl":[[6,35.83]],"id":37665265},{"atl":[[3.2,45.45]],"id":42252553},{"atb":[[2.06,94.34]],"id":23239795},{"atl":[[5.6,38.33]],"id":23239795}],"con":true,"img":false}]}
{"op":"mcm","clk":"5322396365","pt":1646319731414,"mc":[{"id":"1.195532861","rc":[{"atl":[[3.2,77.6]],"id":42252553}],"con":true,"img":false}]}
{"op":"mcm","clk":"5322396373","pt":1646319731506,"mc":[{"id":"1.195532861","rc":[{"atl":[[6,3.54]],"id":41529436},{"atl":[[3.35,2.5]],"id":42252553}],"con":true,"img":false}]}
{"op":"mcm","clk":"5322396394","pt":1646319731712,"mc":[{"id":"1.195532861","rc":[{"atl":[[7.2,5],[5.9,9.91]],"id":41529436}],"con":true,"img":false}]}
{"op":"mcm","clk":"5322396418","pt":1646319732118,"mc":[{"id":"1.195532861","rc":[{"atb":[[2.22,81.97],[2.12,0]],"id":28791247},{"atb":[[1.76,0]],"id":37665265},{"atl":[[70,0]],"id":37665265},{"atl":[[6.4,2.5],[6.2,7.69]],"id":41529436},{"atl":[[4.8,0]],"id":42252553},{"atb":[[1.81,0]],"id":23239795},{"atl":[[8.8,0]],"id":23239795}],"con":true,"img":false}]}
{"op":"mcm","clk":"5322396437","pt":1646319732326,"mc":[{"id":"1.195532861","rc":[{"atb":[[2.3,0],[2.38,2.15]],"id":28791247},{"atb":[[2.28,2.15],[2.2,0]],"id":37665265}],"con":true,"img":false}]}
{"op":"mcm","clk":"5322396509","pt":1646319733417,"mc":[{"id":"1.195532861","rc":[{"atl":[[7,31.31]],"id":28791247}],"con":true,"img":false}]}
{"op":"mcm","clk":"5322396524","pt":1646319733728,"mc":[{"id":"1.195532861","rc":[{"atl":[[12.5,0]],"id":28791247}],"con":true,"img":false}]}
{"op":"mcm","clk":"5322396549","pt":1646319733996,"mc":[{"id":"1.195532861","rc":[{"atb":[[3,12.88]],"id":39947224},{"atb":[[2.22,0],[2.18,36.36]],"id":23239795}],"con":true,"img":false}]}
{"op":"mcm","clk":"5322396557","pt":1646319734098,"mc":[{"id":"1.195532861","rc":[{"atb":[[3.05,0]],"id":39947224}],"con":true,"img":false}]}
{"op":"mcm","clk":"5322396623","pt":1646319735121,"mc":[{"id":"1.195532861","rc":[{"atb":[[2.3,4.21]],"id":23239795}],"con":true,"img":false}]}
{"op":"mcm","clk":"5322396718","pt":1646319736216,"mc":[{"id":"1.195532861","rc":[{"atb":[[2.28,0]],"id":23239795}],"con":true,"img":false}]}
{"op":"mcm","clk":"5322396726","pt":1646319736322,"mc":[{"id":"1.195532861","rc":[{"atb":[[2.32,1.99]],"id":23239795}],"con":true,"img":false}]}
{"op":"mcm","clk":"5322396781","pt":1646319737043,"mc":[{"id":"1.195532861","rc":[{"atb":[[2.22,8.82]],"id":37665265}],"con":true,"img":false}]}
{"op":"mcm","clk":"5322396794","pt":1646319737211,"mc":[{"id":"1.195532861","rc":[{"atb":[[2.22,5]],"id":37665265}],"con":true,"img":false}]}
{"op":"mcm","clk":"5322396836","pt":1646319737826,"mc":[{"id":"1.195532861","rc":[{"atb":[[2.3,9.24],[1.94,0],[2.2,36.57]],"id":23239795},{"atl":[[5.6,68.91],[8,14.29],[5.1,5.03]],"id":23239795}],"con":true,"img":false}]}
{"op":"mcm","clk":"5322396842","pt":1646319737937,"mc":[{"id":"1.195532861","rc":[{"atb":[[2.14,27.91]],"id":37665265},{"atl":[[6,0]],"id":41529436},{"atl":[[5.6,57.32],[6.6,0],[5.4,19.09]],"id":23239795}],"con":true,"img":false}]}
{"op":"mcm","clk":"5322396852","pt":1646319738040,"mc":[{"id":"1.195532861","rc":[{"atl":[[10.5,10.53],[6,4.61],[7,43.61]],"id":28791247},{"atb":[[2.74,57.47],[3,23.39],[3.25,6.31]],"id":39947224},{"atl":[[9.8,40.44],[8.8,6.31],[30,0]],"id":39947224},{"atb":[[2.3,12.06],[1.98,102.04],[2.22,20.6]],"id":37665265},{"atl":[[5.5,6.24],[6,60.79],[12,9.08]],"id":37665265},{"atl":[[5.8,13.2],[6.2,46.03],[21,5]],"id":41529436},{"atb":[[1.56,37.3],[1.55,0]],"id":42252553},{"atl":[[3.2,130],[2.98,19.65],[4.4,29.41],[3.3,11.11]],"id":42252553},{"atb":[[2.2,21.61]],"id":23239795}],"con":true,"img":false}]}
{"op":"mcm","clk":"5322396860","pt":1646319738142,"mc":[{"id":"1.195532861","rc":[{"atl":[[8,0],[6.6,17.14],[7,33.97]],"id":28791247},{"atl":[[16,0],[9.4,14.76]],"id":39947224},{"atl":[[5.8,18.33],[6,49.96],[8.4,0]],"id":37665265},{"atl":[[6.4,20.1],[5.9,0]],"id":41529436},{"atl":[[5.3,9.3],[5.4,10]],"id":23239795}],"con":true,"img":false}]}
{"op":"mcm","clk":"5322396873","pt":1646319738242,"mc":[{"id":"1.195532861","rc":[{"atb":[[3,17.81]],"id":39947224},{"atl":[[9.8,33.18]],"id":39947224},{"atb":[[2.14,13.2]],"id":37665265},{"atl":[[9.8,0]],"id":41529436},{"atl":[[3,0],[3.3,0]],"id":42252553},{"atl":[[5.5,4.04]],"id":23239795}],"con":true,"img":false}]}
{"op":"mcm","clk":"5322396884","pt":1646319738302,"mc":[{"id":"1.195532861","rc":[{"atb":[[3.2,1.65]],"id":39947224},{"atb":[[2.14,10]],"id":37665265},{"atl":[[5.8,0]],"id":41529436}],"con":true,"img":false}]}
{"op":"mcm","clk":"5322396890","pt":1646319738413,"mc":[{"id":"1.195532861","rc":[{"atl":[[6.4,7.41],[6.6,10]],"id":28791247},{"atb":[[3.3,1.99]],"id":39947224},{"atl":[[9.2,4.88]],"id":39947224},{"atl":[[5.8,10],[5.2,2.82],[5.7,8.51]],"id":37665265},{"atl":[[6.2,38.34],[6,8],[5.9,16.33]],"id":41529436}],"con":true,"img":false}]}
{"op":"mcm","clk":"5322396897","pt":1646319738508,"mc":[{"id":"1.195532861","rc":[{"atl":[[5.9,4.17]],"id":37665265}],"con":true,"img":false}]}
{"op":"mcm","clk":"5322396909","pt":1646319738719,"mc":[{"id":"1.195532861","rc":[{"atl":[[5.9,0]],"id":37665265},{"atl":[[5.5,0]],"id":23239795}],"con":true,"img":false}]}
{"op":"mcm","clk":"5322396929","pt":1646319739031,"mc":[{"id":"1.195532861","rc":[{"atl":[[5.7,3]],"id":41529436}],"con":true,"img":false}]}
{"op":"mcm","clk":"5322396944","pt":1646319739241,"mc":[{"id":"1.195532861","rc":[{"atl":[[5.7,0],[5.4,9.09]],"id":37665265},{"atl":[[6,0],[5.9,24.49]],"id":41529436}],"con":true,"img":false}]}
{"op":"mcm","clk":"5322397047","pt":1646319740532,"mc":[{"id":"1.195532861","rc":[{"atl":[[3.1,0],[3.05,19.51]],"id":42252553}],"con":true,"img":false}]}
{"op":"mcm","clk":"5322397057","pt":1646319740641,"mc":[{"id":"1.195532861","rc":[{"atb":[[2.16,0]],"id":37665265},{"atb":[[1.56,32.75]],"id":42252553},{"atl":[[3.2,97.85],[3.1,39.3]],"id":42252553},{"atb":[[2.3,6.68]],"id":23239795}],"con":true,"img":false}]}
{"op":"mcm","clk":"5322397160","pt":1646319741908,"mc":[{"id":"1.195532861","rc":[{"atb":[[3.2,0]],"id":39947224},{"atb":[[2.3,5.03]],"id":23239795}],"con":true,"img":false}]}
{"op":"mcm","clk":"5322397174","pt":1646319742115,"mc":[{"id":"1.195532861","rc":[{"atb":[[2.34,1.65]],"id":23239795}],"con":true,"img":false}]}
{"op":"mcm","clk":"5322397185","pt":1646319742218,"mc":[{"id":"1.195532861","rc":[{"atb":[[2.18,0],[2.2,43.22]],"id":23239795}],"con":true,"img":false}]}
{"op":"mcm","clk":"5322397194","pt":1646319742318,"mc":[{"id":"1.195532861","rc":[{"atb":[[2.3,8.74],[2.28,15.87]],"id":37665265},{"atb":[[2.9,9.49],[2.86,53.76]],"id":41529436},{"atb":[[1.63,31.52]],"id":42252553}],"con":true,"img":false}]}
{"op":"mcm","clk":"5322397206","pt":1646319742426,"mc":[{"id":"1.195532861","rc":[{"atb":[[2.86,65]],"id":41529436},{"atb":[[1.6,0]],"id":42252553}],"con":true,"img":false}]}
{"op":"mcm","clk":"5322397213","pt":1646319742520,"mc":[{"id":"1.195532861","rc":[{"atb":[[2.74,74.17],[2.78,81.17]],"id":41529436}],"con":true,"img":false}]}
{"op":"mcm","clk":"5322397225","pt":1646319742633,"mc":[{"id":"1.195532861","rc":[{"atb":[[2.86,63.46]],"id":41529436}],"con":true,"img":false}]}
{"op":"mcm","clk":"5322397242","pt":1646319742841,"mc":[{"id":"1.195532861","rc":[{"atb":[[2.86,53.76],[2.74,59.97]],"id":41529436},{"atb":[[2.16,5.41]],"id":23239795}],"con":true,"img":false}]}
{"op":"mcm","clk":"5322397264","pt":1646319743153,"mc":[{"id":"1.195532861","rc":[{"atb":[[2.36,2.15],[2.28,13.72]],"id":37665265}],"con":true,"img":false}]}
{"op":"mcm","clk":"5322397283","pt":1646319743311,"mc":[{"id":"1.195532861","rc":[{"atb":[[2.16,0]],"id":23239795}],"con":true,"img":false}]}
{"op":"mcm","clk":"5322397409","pt":1646319744712,"mc":[{"id":"1.195532861","rc":[{"atb":[[2.16,20.58]],"id":37665265},{"atb":[[1.57,16.78]],"id":42252553},{"atb":[[2.22,4.73]],"id":23239795}],"con":true,"img":false}]}
{"op":"mcm","clk":"5322397496","pt":1646319745914,"mc":[{"id":"1.195532861","rc":[{"atl":[[5.7,3.66]],"id":28791247}],"con":true,"img":false}]}
{"op":"mcm","clk":"5322397529","pt":1646319746325,"mc":[{"id":"1.195532861","rc":[{"atl":[[5.6,3.66],[6.6,0]],"id":28791247},{"atl":[[5.8,0],[5.2,9.06]],"id":37665265},{"atl":[[5.6,21.74],[6.4,2.5]],"id":41529436}],"con":true,"img":false}]}
{"op":"mcm","clk":"5322397537","pt":1646319746428,"mc":[{"id":"1.195532861","rc":[{"atl":[[5.5,18.15]],"id":37665265},{"atl":[[5.6,0],[5.7,24.28]],"id":41529436}],"con":true,"img":false}]}
{"op":"mcm","clk":"5322397546","pt":1646319746527,"mc":[{"id":"1.195532861","rc":[{"atl":[[5.2,2.82]],"id":37665265},{"atl":[[5.7,3],[5.9,44.9]],"id":41529436}],"con":true,"img":false}]}
{"op":"mcm","clk":"5322397558","pt":1646319746630,"mc":[{"id":"1.195532861","rc":[{"atl":[[5.9,24.49]],"id":41529436}],"con":true,"img":false}]}
{"op":"mcm","clk":"5322397569","pt":1646319746734,"mc":[{"id":"1.195532861","rc":[{"atl":[[6.2,57.57]],"id":41529436}],"con":true,"img":false}]}
{"op":"mcm","clk":"5322397622","pt":1646319747357,"mc":[{"id":"1.195532861","rc":[{"atl":[[6.4,0],[5.8,8.33]],"id":28791247},{"atb":[[3,10.51],[3.05,10]],"id":39947224},{"atb":[[2.34,8.74],[2.28,0]],"id":37665265},{"atb":[[2.86,0],[2.84,54.35]],"id":41529436}],"con":true,"img":false}]}
{"op":"mcm","clk":"5322397634","pt":1646319747509,"mc":[{"id":"1.195532861","rc":[{"atl":[[5.2,11.91]],"id":37665265}],"con":true,"img":false}]}
{"op":"mcm","clk":"5322397644","pt":1646319747618,"mc":[{"id":"1.195532861","rc":[{"atl":[[5.5,6.24]],"id":37665265}],"con":true,"img":false}]}
{"op":"mcm","clk":"5322397691","pt":1646319748142,"mc":[{"id":"1.195532861","rc":[{"atl":[[5.7,0]],"id":41529436},{"atb":[[2.02,147.06]],"id":23239795}],"con":true,"img":false}]}
{"op":"mcm","clk":"5322397708","pt":1646319748346,"mc":[{"id":"1.195532861","rc":[{"atl":[[6.4,40.79],[6.2,19.22]],"id":41529436}],"con":true,"img":false}]}
{"op":"mcm","clk":"5322397719","pt":1646319748449,"mc":[{"id":"1.195532861","rc":[{"atb":[[2.78,84.27]],"id":39947224},{"atl":[[9.6,11.63]],"id":39947224},{"atb":[[2.16,0]],"id":37665265},{"atl":[[6.2,26.91],[5.9,16.33]],"id":41529436},{"atb":[[1.89,0]],"id":23239795}],"con":true,"img":false}]}
{"op":"mcm","clk":"5322397769","pt":1646319749020,"mc":[{"id":"1.195532861","rc":[{"atb":[[2.32,0]],"id":37665265}],"con":true,"img":false}]}
{"op":"mcm","clk":"5322397786","pt":1646319749220,"mc":[{"id":"1.195532861","rc":[{"atb":[[1.94,250],[2.38,1.65]],"id":37665265},{"atl":[[5.6,24.24]],"id":37665265}],"con":true,"img":false}]}
{"op":"mcm","clk":"5322397809","pt":1646319749532,"mc":[{"id":"1.195532861","rc":[{"atb":[[1.86,0]],"id":37665265},{"atl":[[60,0]],"id":37665265}],"con":true,"img":false}]}
{"op":"mcm","clk":"5322397833","pt":1646319749744,"mc":[{"id":"1.195532861","rc":[{"atl":[[5.7,0]],"id":28791247}],"con":true,"img":false}]}
{"op":"mcm","clk":"5322397848","pt":1646319749947,"mc":[{"id":"1.195532861","rc":[{"atl":[[5.6,0],[6,16.6]],"id":28791247}],"con":true,"img":false}]}
{"op":"mcm","clk":"5322397876","pt":1646319750324,"mc":[{"id":"1.195532861","rc":[{"atl":[[5.8,0],[6,24.6]],"id":28791247}],"con":true,"img":false}]}
{"op":"mcm","clk":"5322397896","pt":1646319750531,"mc":[{"id":"1.195532861","rc":[{"atl":[[5.5,8.47]],"id":28791247}],"con":true,"img":false}]}
{"op":"mcm","clk":"5322397973","pt":1646319751558,"mc":[{"id":"1.195532861","rc":[{"atl":[[6,16.6],[5.7,8.51]],"id":28791247}],"con":true,"img":false}]}
{"op":"mcm","clk":"5322398002","pt":1646319751829,"mc":[{"id":"1.195532861","rc":[{"atl":[[6.4,59.31],[6.2,7.68]],"id":41529436}],"con":true,"img":false}]}
{"op":"mcm","clk":"5322398023","pt":1646319752132,"mc":[{"id":"1.195532861","rc":[{"atb":[[2.38,4.33]],"id":37665265}],"con":true,"img":false}]}
{"op":"mcm","clk":"5322398044","pt":1646319752467,"mc":[{"id":"1.195532861","rc":[{"atb":[[3,20.51],[3.05,0]],"id":39947224},{"atb":[[2.3,18.74],[2.34,0]],"id":37665265},{"atb":[[2.82,54.95],[2.84,0]],"id":41529436}],"con":true,"img":false}]}
{"op":"mcm","clk":"5322398251","pt":1646319754951,"mc":[{"id":"1.195532861","rc":[{"atl":[[5.6,26.74],[5.3,26.66],[5.7,3.84]],"id":23239795}],"con":true,"img":false}]}
{"op":"mcm","clk":"5322398258","pt":1646319755050,"mc":[{"id":"1.195532861","rc":[{"atb":[[3.05,6.04]],"id":39947224},{"atl":[[3.15,8.53]],"id":42252553},{"atb":[[2.32,7.64],[2.26,13],[2.2,24.11]],"id":23239795}],"con":true,"img":false}]}
{"op":"mcm","clk":"5322398275","pt":1646319755269,"mc":[{"id":"1.195532861","rc":[{"atl":[[6,40.84],[7,21.67],[5.4,9.09]],"id":28791247},{"atb":[[3,10],[3.3,7.53],[3.05,19.69]],"id":39947224},{"atl":[[9.2,26.72],[9.8,16.36]],"id":39947224},{"atb":[[2.3,37.9],[2.22,5],[2.38,15.83]],"id":37665265},{"atl":[[5.1,11.5],[5.5,36.9],[6,25]],"id":37665265},{"atl":[[3.2,45.45],[3.1,119.95]],"id":42252553},{"atb":[[2.3,0]],"id":23239795}],"con":true,"img":false}]}
{"op":"mcm","clk":"5322398290","pt":1646319755419,"mc":[{"id":"1.195532861","rc":[{"atl":[[5.6,8.7],[6,36.23],[5.7,0]],"id":28791247},{"atb":[[3.25,0]],"id":39947224},{"atb":[[2.3,31.66]],"id":37665265},{"atl":[[5.5,30.66],[5.3,9.3],[5.4,0]],"id":37665265}],"con":true,"img":false}]}
{"op":"mcm","clk":"5322398298","pt":1646319755529,"mc":[{"id":"1.195532861","rc":[{"atb":[[3.05,13.65]],"id":39947224},{"atl":[[3.15,0]],"id":42252553},{"atl":[[5.7,0]],"id":23239795}],"con":true,"img":false}]}
{"op":"mcm","clk":"5322398409","pt":1646319757055,"mc":[{"id":"1.195532861","rc":[{"atl":[[5.5,0]],"id":28791247}],"con":true,"img":false}]}
{"op":"mcm","clk":"5322398430","pt":1646319757263,"mc":[{"id":"1.195532861","rc":[{"atl":[[5.4,0]],"id":28791247}],"con":true,"img":false}]}
{"op":"mcm","clk":"5322398440","pt":1646319757369,"mc":[{"id":"1.195532861","rc":[{"atl":[[5.5,9.26]],"id":28791247}],"con":true,"img":false}]}
{"op":"mcm","clk":"5322398449","pt":1646319757428,"mc":[{"id":"1.195532861","rc":[{"atl":[[5.6,0],[5.8,8.33],[6.2,21.73],[6,24.24]],"id":28791247}],"con":true,"img":false}]}
{"op":"mcm","clk":"5322398456","pt":1646319757534,"mc":[{"id":"1.195532861","rc":[{"atl":[[5.7,12.86]],"id":28791247},{"atb":[[2.26,31.66]],"id":37665265},{"atb":[[2.32,1.99]],"id":23239795}],"con":true,"img":false}]}
{"op":"mcm","clk":"5322398465","pt":1646319757638,"mc":[{"id":"1.195532861","rc":[{"atb":[[2.3,21.66]],"id":37665265},{"atb":[[2.26,18.65]],"id":23239795}],"con":true,"img":false}]}
{"op":"mcm","clk":"5322398473","pt":1646319757740,"mc":[{"id":"1.195532861","rc":[{"atl":[[5.7,8.51]],"id":28791247}],"con":true,"img":false}]}
{"op":"mcm","clk":"5322398480","pt":1646319757841,"mc":[{"id":"1.195532861","rc":[{"atl":[[5.8,0]],"id":28791247},{"atb":[[2.38,13.15]],"id":37665265},{"atb":[[2.22,0]],"id":23239795}],"con":true,"img":false}]}
{"op":"mcm","clk":"5322398507","pt":1646319758102,"mc":[{"id":"1.195532861","rc":[{"atb":[[2.44,2.15],[2.36,0]],"id":37665265}],"con":true,"img":false}]}
{"op":"mcm","clk":"5322398512","pt":1646319758152,"mc":[{"id":"1.195532861","rc":[{"atb":[[1.99,250]],"id":23239795}],"con":true,"img":false}]}
{"op":"mcm","clk":"5322398548","pt":1646319758467,"mc":[{"id":"1.195532861","rc":[{"atb":[[2.74,143.68]],"id":39947224},{"atl":[[10,16.67]],"id":39947224},{"atl":[[6.6,17.86]],"id":41529436},{"atb":[[1.91,0]],"id":23239795}],"con":true,"img":false}]}
{"op":"mcm","clk":"5322398569","pt":1646319758630,"mc":[{"id":"1.195532861","rc":[{"atb":[[2.32,0]],"id":23239795}],"con":true,"img":false}]}
{"op":"mcm","clk":"5322398579","pt":1646319758733,"mc":[{"id":"1.195532861","rc":[{"atb":[[2.28,1.99]],"id":23239795}],"con":true,"img":false}]}
{"op":"mcm","clk":"5322398587","pt":1646319758837,"mc":[{"id":"1.195532861","rc":[{"atl":[[9.8,5],[9.4,10]],"id":39947224},{"atl":[[25,0]],"id":41529436}],"con":true,"img":false}]}
{"op":"mcm","clk":"5322398614","pt":1646319759145,"mc":[{"id":"1.195532861","rc":[{"atl":[[5.3,3]],"id":28791247}],"con":true,"img":false}]}
{"op":"mcm","clk":"5322398638","pt":1646319759460,"mc":[{"id":"1.195532861","rc":[{"atl":[[5.5,18.15],[5.7,0]],"id":28791247}],"con":true,"img":false}]}
{"op":"mcm","clk":"5322398685","pt":1646319760043,"mc":[{"id":"1.195532861","rc":[{"atl":[[5.6,27.77]],"id":37665265}],"con":true,"img":false}]}
{"op":"mcm","clk":"5322398714","pt":1646319760451,"mc":[{"id":"1.195532861","rc":[{"atb":[[2.82,0],[2.84,54.35]],"id":41529436}],"con":true,"img":false}]}
{"op":"mcm","clk":"5322398729","pt":1646319760659,"mc":[{"id":"1.195532861","rc":[{"atl":[[5.6,24.24]],"id":37665265}],"con":true,"img":false}]}
{"op":"mcm","clk":"5322398809","pt":1646319761858,"mc":[{"id":"1.195532861","rc":[{"atb":[[2.32,16.84]],"id":37665265},{"atb":[[2.22,4.01]],"id":23239795}],"con":true,"img":false}]}
{"op":"mcm","clk":"5322398821","pt":1646319761960,"mc":[{"id":"1.195532861","rc":[{"atl":[[5.3,0]],"id":28791247}],"con":true,"img":false}]}
{"op":"mcm","clk":"5322398876","pt":1646319762639,"mc":[{"id":"1.195532861","rc":[{"atl":[[5.5,9.26],[5.7,8.51]],"id":28791247}],"con":true,"img":false}]}
{"op":"mcm","clk":"5322398896","pt":1646319762844,"mc":[{"id":"1.195532861","rc":[{"atb":[[2.28,7.68]],"id":23239795}],"con":true,"img":false}]}
{"op":"mcm","clk":"5322398909","pt":1646319763050,"mc":[{"id":"1.195532861","rc":[{"atb":[[2.22,21.97],[2.26,7.8],[2.28,1.99]],"id":23239795}],"con":true,"img":false}]}
{"op":"mcm","clk":"5322398939","pt":1646319763564,"mc":[{"id":"1.195532861","rc":[{"atb":[[2.38,11.5]],"id":37665265},{"atb":[[2.34,0]],"id":23239795}],"con":true,"img":false}]}
{"op":"mcm","clk":"5322398953","pt":1646319763770,"mc":[{"id":"1.195532861","rc":[{"atb":[[2.46,1.65]],"id":37665265},{"atb":[[2.3,1.65],[2.2,2.5],[2.16,36.36]],"id":23239795}],"con":true,"img":false}]}
{"op":"mcm","clk":"5322398959","pt":1646319763873,"mc":[{"id":"1.195532861","rc":[{"atl":[[6.8,4.46]],"id":28791247}],"con":true,"img":false}]}
{"op":"mcm","clk":"5322398975","pt":1646319764033,"mc":[{"id":"1.195532861","rc":[{"atl":[[6.8,0]],"id":28791247}],"con":true,"img":false}]}
{"op":"mcm","clk":"5322399042","pt":1646319765084,"mc":[{"id":"1.195532861","rc":[{"atl":[[5.4,3]],"id":28791247}],"con":true,"img":false}]}
{"op":"mcm","clk":"5322399063","pt":1646319765349,"mc":[{"id":"1.195532861","rc":[{"atl":[[5.6,8.7],[5.7,0]],"id":28791247}],"con":true,"img":false}]}
{"op":"mcm","clk":"5322399069","pt":1646319765449,"mc":[{"id":"1.195532861","rc":[{"atl":[[6.2,2.5],[5.3,8.51]],"id":28791247}],"con":true,"img":false}]}
{"op":"mcm","clk":"5322399080","pt":1646319765556,"mc":[{"id":"1.195532861","rc":[{"atb":[[2.32,38.5],[2.26,0]],"id":37665265}],"con":true,"img":false}]}
{"op":"mcm","clk":"5322399092","pt":1646319765662,"mc":[{"id":"1.195532861","rc":[{"atl":[[5.3,0],[5.4,20.02]],"id":28791247}],"con":true,"img":false}]}
{"op":"mcm","clk":"5322399163","pt":1646319766438,"mc":[{"id":"1.195532861","rc":[{"atl":[[5,2.2]],"id":23239795}],"con":true,"img":false}]}
{"op":"mcm","clk":"5322399172","pt":1646319766540,"mc":[{"id":"1.195532861","rc":[{"atl":[[5,4.7],[4.9,3.53]],"id":23239795}],"con":true,"img":false}]}
{"op":"mcm","clk":"5322399181","pt":1646319766644,"mc":[{"id":"1.195532861","rc":[{"atl":[[5.1,0],[5.4,0]],"id":23239795}],"con":true,"img":false}]}
{"op":"mcm","clk":"5322399189","pt":1646319766750,"mc":[{"id":"1.195532861","rc":[{"atl":[[5.4,17.02]],"id":28791247}],"con":true,"img":false}]}
{"op":"mcm","clk":"5322399196","pt":1646319766856,"mc":[{"id":"1.195532861","rc":[{"atl":[[5.1,9.76],[5.3,17.36]],"id":23239795}],"con":true,"img":false}]}
{"op":"mcm","clk":"5322399241","pt":1646319767374,"mc":[{"id":"1.195532861","rc":[{"atb":[[2.32,21.66]],"id":37665265},{"atb":[[2.22,17.96]],"id":23239795}],"con":true,"img":false}]}
{"op":"mcm","clk":"5322399358","pt":1646319768475,"mc":[{"id":"1.195532861","rc":[{"atl":[[11,25]],"id":39947224},{"atl":[[7,25]],"id":41529436}],"con":true,"img":false}]}
{"op":"mcm","clk":"5322399386","pt":1646319768571,"mc":[{"id":"1.195532861","rc":[{"atl":[[5.4,18.95]],"id":28791247}],"con":true,"img":false}]}
{"op":"mcm","clk":"5322399435","pt":1646319768881,"mc":[{"id":"1.195532861","rc":[{"atl":[[23,0]],"id":41529436}],"con":true,"img":false}]}
{"op":"mcm","clk":"5322399580","pt":1646319770449,"mc":[{"id":"1.195532861","rc":[{"atb":[[3.35,1.65]],"id":39947224}],"con":true,"img":false}]}
{"op":"mcm","clk":"5322399629","pt":1646319771096,"mc":[{"id":"1.195532861","rc":[{"atl":[[5,2.49]],"id":23239795}],"con":true,"img":false}]}
{"op":"mcm","clk":"5322399649","pt":1646319771256,"mc":[{"id":"1.195532861","rc":[{"atb":[[2.34,4.37]],"id":28791247},{"atl":[[5.4,17.02]],"id":28791247},{"atb":[[2.3,4.21]],"id":23239795}],"con":true,"img":false}]}
{"op":"mcm","clk":"5322399663","pt":1646319771461,"mc":[{"id":"1.195532861","rc":[{"atl":[[5.6,30.44]],"id":28791247}],"con":true,"img":false}]}
{"op":"mcm","clk":"5322399669","pt":1646319771565,"mc":[{"id":"1.195532861","rc":[{"atl":[[5.4,0]],"id":28791247}],"con":true,"img":false}]}
{"op":"mcm","clk":"5322399676","pt":1646319771669,"mc":[{"id":"1.195532861","rc":[{"atb":[[2.28,0]],"id":23239795},{"atl":[[5.1,19.52]],"id":23239795}],"con":true,"img":false}]}
{"op":"mcm","clk":"5322399685","pt":1646319771773,"mc":[{"id":"1.195532861","rc":[{"atb":[[2.32,1.99]],"id":23239795},{"atl":[[5,0]],"id":23239795}],"con":true,"img":false}]}
{"op":"mcm","clk":"5322399697","pt":1646319771877,"mc":[{"id":"1.195532861","rc":[{"atb":[[2.3,13.23]],"id":23239795},{"atl":[[5.1,47.46],[5.3,0]],"id":23239795}],"con":true,"img":false}]}
{"op":"mcm","clk":"5322399707","pt":1646319771981,"mc":[{"id":"1.195532861","rc":[{"atl":[[4.9,0]],"id":23239795}],"con":true,"img":false}]}
{"op":"mcm","clk":"5322399716","pt":1646319772035,"mc":[{"id":"1.195532861","rc":[{"atb":[[3.35,8.26]],"id":39947224},{"atb":[[2.32,50.41],[2.44,17.75]],"id":37665265},{"atl":[[5.3,55.3],[5.5,0]],"id":37665265},{"atb":[[2.26,2.15]],"id":23239795},{"atl":[[5.1,19.52],[5,10.14]],"id":23239795}],"con":true,"img":false}]}
{"op":"mcm","clk":"5322399723","pt":1646319772143,"mc":[{"id":"1.195532861","rc":[{"atb":[[3.15,19.8]],"id":39947224},{"atb":[[2.3,10.44]],"id":37665265}],"con":true,"img":false}]}
{"op":"mcm","clk":"5322399732","pt":1646319772246,"mc":[{"id":"1.195532861","rc":[{"atb":[[3.3,1.99],[3.05,0]],"id":39947224},{"atb":[[2.38,0]],"id":37665265}],"con":true,"img":false}]}
{"op":"mcm","clk":"5322399741","pt":1646319772348,"mc":[{"id":"1.195532861","rc":[{"atb":[[2.3,2.5]],"id":37665265}],"con":true,"img":false}]}
{"op":"mcm","clk":"5322399751","pt":1646319772455,"mc":[{"id":"1.195532861","rc":[{"atb":[[3.15,2.5]],"id":39947224}],"con":true,"img":false}]}
{"op":"mcm","clk":"5322399771","pt":1646319772656,"mc":[{"id":"1.195532861","rc":[{"atb":[[3.3,0]],"id":39947224}],"con":true,"img":false}]}
{"op":"mcm","clk":"5322399781","pt":1646319772770,"mc":[{"id":"1.195532861","rc":[{"atl":[[5.6,21.74],[5.7,8.51]],"id":28791247},{"atb":[[3,0],[3.05,10],[3.4,1.99]],"id":39947224},{"atb":[[2.84,0],[2.78,137.35]],"id":41529436},{"atb":[[2.3,4.21],[2.36,2.15]],"id":23239795},{"atl":[[5.1,9.76],[5.2,12.02]],"id":23239795}],"con":true,"img":false}]}
{"op":"mcm","clk":"5322399790","pt":1646319772866,"mc":[{"id":"1.195532861","rc":[{"atb":[[2.26,0]],"id":23239795}],"con":true,"img":false}]}
{"op":"mcm","clk":"5322399801","pt":1646319772970,"mc":[{"id":"1.195532861","rc":[{"atl":[[6,0],[5.7,32.83]],"id":28791247},{"atb":[[2.74,154.52],[2.78,78.65]],"id":41529436},{"atb":[[2.22,0],[2.26,19.95]],"id":23239795}],"con":true,"img":false}]}
{"op":"mcm","clk":"5322399818","pt":1646319773179,"mc":[{"id":"1.195532861","rc":[{"atb":[[2.26,0]],"id":23239795}],"con":true,"img":false}]}
{"op":"mcm","clk":"5322399827","pt":1646319773285,"mc":[{"id":"1.195532861","rc":[{"atb":[[2.32,0]],"id":23239795},{"atl":[[5.2,16.27]],"id":23239795}],"con":true,"img":false}]}
{"op":"mcm","clk":"5322399838","pt":1646319773341,"mc":[{"id":"1.195532861","rc":[{"atb":[[2.38,1.99]],"id":23239795}],"con":true,"img":false}]}
{"op":"mcm","clk":"5322399847","pt":1646319773448,"mc":[{"id":"1.195532861","rc":[{"atb":[[1.51,24.04]],"id":42252553},{"atl":[[5.2,12.02]],"id":23239795}],"con":true,"img":false}]}
{"op":"mcm","clk":"5322399862","pt":1646319773550,"mc":[{"id":"1.195532861","rc":[{"atl":[[5.2,17.49]],"id":23239795}],"con":true,"img":false}]}
{"op":"mcm","clk":"5322399872","pt":1646319773658,"mc":[{"id":"1.195532861","rc":[{"atb":[[1.51,0]],"id":42252553}],"con":true,"img":false}]}
{"op":"mcm","clk":"5322399895","pt":1646319773862,"mc":[{"id":"1.195532861","rc":[{"atl":[[5.2,12.02]],"id":23239795}],"con":true,"img":false}]}
{"op":"mcm","clk":"5322399972","pt":1646319774645,"mc":[{"id":"1.195532861","rc":[{"atl":[[5.2,3]],"id":28791247}],"con":true,"img":false}]}
{"op":"mcm","clk":"5322399983","pt":1646319774750,"mc":[{"id":"1.195532861","rc":[{"atl":[[5.1,4.99]],"id":28791247}],"con":true,"img":false}]}
{"op":"mcm","clk":"5322400001","pt":1646319774968,"mc":[{"id":"1.195532861","rc":[{"atl":[[5.5,0]],"id":28791247},{"atb":[[2.3,1.65]],"id":23239795}],"con":true,"img":false}]}
{"op":"mcm","clk":"5322400011","pt":1646319775060,"mc":[{"id":"1.195532861","rc":[{"atl":[[5.3,9.3],[5.7,24.32]],"id":28791247}],"con":true,"img":false}]}
{"op":"mcm","clk":"5322400160","pt":1646319776775,"mc":[{"id":"1.195532861","rc":[{"atb":[[2.34,0]],"id":28791247}],"con":true,"img":false}]}
{"op":"mcm","clk":"5322400225","pt":1646319777560,"mc":[{"id":"1.195532861","rc":[{"atb":[[3.35,6.61]],"id":39947224},{"atb":[[2.3,0]],"id":23239795}],"con":true,"img":false}]}
{"op":"mcm","clk":"5322400233","pt":1646319777662,"mc":[{"id":"1.195532861","rc":[{"atb":[[2.4,1.65]],"id":23239795}],"con":true,"img":false}]}
{"op":"mcm","clk":"5322400281","pt":1646319778489,"mc":[{"id":"1.195532861","rc":[{"atl":[[7.4,39.06]],"id":41529436}],"con":true,"img":false}]}
{"op":"mcm","clk":"5322400296","pt":1646319778693,"mc":[{"id":"1.195532861","rc":[{"atb":[[2.22,6.21]],"id":23239795}],"con":true,"img":false}]}
{"op":"mcm","clk":"5322400311","pt":1646319778850,"mc":[{"id":"1.195532861","rc":[{"atl":[[21,0]],"id":41529436}],"con":true,"img":false}]}
{"op":"mcm","clk":"5322400318","pt":1646319778956,"mc":[{"id":"1.195532861","rc":[{"atl":[[2.98,0]],"id":42252553}],"con":true,"img":false}]}
{"op":"mcm","clk":"5322400324","pt":1646319779058,"mc":[{"id":"1.195532861","rc":[{"atl":[[3.2,174.37],[3.1,0],[3,38.38]],"id":42252553}],"con":true,"img":false}]}
{"op":"mcm","clk":"5322400329","pt":1646319779161,"mc":[{"id":"1.195532861","rc":[{"atl":[[3,48.21]],"id":42252553}],"con":true,"img":false}]}
{"op":"mcm","clk":"5322400335","pt":1646319779263,"mc":[{"id":"1.195532861","rc":[{"atl":[[5.2,12.98]],"id":28791247}],"con":true,"img":false}]}
{"op":"mcm","clk":"5322400342","pt":1646319779368,"mc":[{"id":"1.195532861","rc":[{"atl":[[5.6,0],[5.3,31.04],[5.2,3]],"id":28791247},{"atl":[[3,38.38]],"id":42252553}],"con":true,"img":false}]}
{"op":"mcm","clk":"5322400365","pt":1646319779777,"mc":[{"id":"1.195532861","rc":[{"atb":[[2.22,26.19]],"id":23239795}],"con":true,"img":false}]}
{"op":"mcm","clk":"5322400373","pt":1646319779882,"mc":[{"id":"1.195532861","rc":[{"atl":[[5.2,0]],"id":28791247},{"atb":[[2.32,21.66],[2.3,41.66]],"id":37665265}],"con":true,"img":false}]}
{"op":"mcm","clk":"5322400391","pt":1646319780088,"mc":[{"id":"1.195532861","rc":[{"atl":[[5.1,0],[5.3,9.3],[5.7,45.6]],"id":28791247}],"con":true,"img":false}]}
{"op":"mcm","clk":"5322400411","pt":1646319780255,"mc":[{"id":"1.195532861","rc":[{"atl":[[6.2,21.73],[5.2,6.48],[5.7,24.32]],"id":28791247}],"con":true,"img":false}]}
{"op":"mcm","clk":"5322400429","pt":1646319780462,"mc":[{"id":"1.195532861","rc":[{"atl":[[5.1,9.3],[6.2,2.5]],"id":28791247}],"con":true,"img":false}]}
{"op":"mcm","clk":"5322400446","pt":1646319780673,"mc":[{"id":"1.195532861","rc":[{"atb":[[2.34,4.37]],"id":28791247}],"con":true,"img":false}]}
{"op":"mcm","clk":"5322400616","pt":1646319782565,"mc":[{"id":"1.195532861","rc":[{"atl":[[5,8.5]],"id":23239795}],"con":true,"img":false}]}
{"op":"mcm","clk":"5322400626","pt":1646319782669,"mc":[{"id":"1.195532861","rc":[{"atl":[[5.2,30.28]],"id":23239795}],"con":true,"img":false}]}
{"op":"mcm","clk":"5322400633","pt":1646319782773,"mc":[{"id":"1.195532861","rc":[{"atl":[[3.1,19.05],[3.05,0]],"id":42252553},{"atl":[[5.1,0],[5.4,22.73]],"id":23239795}],"con":true,"img":false}]}
{"op":"mcm","clk":"5322400640","pt":1646319782877,"mc":[{"id":"1.195532861","rc":[{"atl":[[5,0],[5.3,7.97],[5.2,12.01],[5.4,45.46]],"id":23239795}],"con":true,"img":false}]}
{"op":"mcm","clk":"5322400647","pt":1646319782982,"mc":[{"id":"1.195532861","rc":[{"atl":[[5.2,24.04],[5.4,22.73]],"id":23239795}],"con":true,"img":false}]}
{"op":"mcm","clk":"5322400654","pt":1646319783080,"mc":[{"id":"1.195532861","rc":[{"atl":[[5.1,8]],"id":23239795}],"con":true,"img":false}]}
{"op":"mcm","clk":"5322400673","pt":1646319783393,"mc":[{"id":"1.195532861","rc":[{"atb":[[2.36,0],[2.28,2.15]],"id":23239795},{"atl":[[5.3,0]],"id":23239795}],"con":true,"img":false}]}
{"op":"mcm","clk":"5322400693","pt":1646319783661,"mc":[{"id":"1.195532861","rc":[{"atl":[[5.3,2]],"id":23239795}],"con":true,"img":false}]}
{"op":"mcm","clk":"5322400736","pt":1646319784184,"mc":[{"id":"1.195532861","rc":[{"atb":[[2.08,4.54]],"id":23239795},{"atl":[[5.6,5],[8,0],[5.3,11.3],[5.2,14.52],[8.4,0],[5.4,0]],"id":23239795}],"con":true,"img":false}]}
{"op":"mcm","clk":"5322400750","pt":1646319784396,"mc":[{"id":"1.195532861","rc":[{"atb":[[2.08,0]],"id":23239795}],"con":true,"img":false}]}
{"op":"mcm","clk":"5322400764","pt":1646319784560,"mc":[{"id":"1.195532861","rc":[{"atl":[[5,3]],"id":28791247}],"con":true,"img":false}]}
{"op":"mcm","clk":"5322400794","pt":1646319784982,"mc":[{"id":"1.195532861","rc":[{"atl":[[5.3,0],[5.2,16]],"id":28791247}],"con":true,"img":false}]}
{"op":"mcm","clk":"5322400841","pt":1646319785498,"mc":[{"id":"1.195532861","rc":[{"atb":[[2.38,0]],"id":23239795}],"con":true,"img":false}]}
{"op":"mcm","clk":"5322400848","pt":1646319785603,"mc":[{"id":"1.195532861","rc":[{"atb":[[2.3,1.99]],"id":23239795}],"con":true,"img":false}]}
{"op":"mcm","clk":"5322400857","pt":1646319785659,"mc":[{"id":"1.195532861","rc":[{"atb":[[2.2,26.62]],"id":23239795}],"con":true,"img":false}]}
{"op":"mcm","clk":"5322400864","pt":1646319785763,"mc":[{"id":"1.195532861","rc":[{"atb":[[2.22,6.21],[2.2,2.5]],"id":23239795}],"con":true,"img":false}]}
{"op":"mcm","clk":"5322400902","pt":1646319786278,"mc":[{"id":"1.195532861","rc":[{"atl":[[5,0]],"id":28791247},{"atb":[[2.3,11.99],[2.04,0],[2.12,0],[2.38,5],[2.46,2.5],[2.2,0]],"id":23239795}],"con":true,"img":false}]}
{"op":"mcm","clk":"5322400912","pt":1646319786385,"mc":[{"id":"1.195532861","rc":[{"atl":[[5.1,0],[5.7,45.6],[7,16.67],[7.8,0]],"id":28791247},{"atb":[[2.98,0],[3.2,2.5],[2.9,0],[3.15,0]],"id":39947224},{"atb":[[2.14,0]],"id":37665265},{"atl":[[8,0],[7.2,0],[6.4,56.81],[6,2.5]],"id":41529436}],"con":true,"img":false}]}
{"op":"mcm","clk":"5322400920","pt":1646319786488,"mc":[{"id":"1.195532861","rc":[{"atl":[[6.2,14.8],[5.3,2.5],[5.7,50.6]],"id":28791247},{"atl":[[9,0],[11.5,0],[9.8,0],[8.8,8.81]],"id":39947224},{"atb":[[2.38,2.5]],"id":37665265},{"atl":[[6.4,38.29],[6.2,51.62]],"id":41529436}],"con":true,"img":false}]}
{"op":"mcm","clk":"5322400931","pt":1646319786592,"mc":[{"id":"1.195532861","rc":[{"atl":[[5.7,26.28]],"id":28791247},{"atl":[[6.4,0],[6,22.5]],"id":41529436}],"con":true,"img":false}]}
{"op":"mcm","clk":"5322400941","pt":1646319786694,"mc":[{"id":"1.195532861","rc":[{"atl":[[6.2,2.5],[5.2,6.48],[5.4,9.09]],"id":28791247},{"atl":[[9.2,8.63],[8.8,18.81],[9.4,28.98]],"id":39947224},{"atl":[[6.2,70.85]],"id":41529436}],"con":true,"img":false}]}
{"op":"mcm","clk":"5322400952","pt":1646319786801,"mc":[{"id":"1.195532861","rc":[{"atl":[[9.2,20.83],[8.8,8.81]],"id":39947224},{"atl":[[6,2.5],[6.6,22.21]],"id":41529436}],"con":true,"img":false}]}
{"op":"mcm","clk":"5322400964","pt":1646319786903,"mc":[{"id":"1.195532861","rc":[{"atl":[[5.2,21.93]],"id":28791247}],"con":true,"img":false}]}
{"op":"mcm","clk":"5322400972","pt":1646319787006,"mc":[{"id":"1.195532861","rc":[{"atl":[[9.2,8.63],[9.4,40.88]],"id":39947224}],"con":true,"img":false}]}
{"op":"mcm","clk":"5322400981","pt":1646319787064,"mc":[{"id":"1.195532861","rc":[{"atl":[[9.2,4.88]],"id":39947224},{"atl":[[6.6,17.86]],"id":41529436}],"con":true,"img":false}]}
{"op":"mcm","clk":"5322400998","pt":1646319787276,"mc":[{"id":"1.195532861","rc":[{"atl":[[5.2,6.48]],"id":28791247}],"con":true,"img":false}]}
{"op":"mcm","clk":"5322401027","pt":1646319787585,"mc":[{"id":"1.195532861","rc":[{"atl":[[5.1,1.95]],"id":28791247}],"con":true,"img":false}]}
{"op":"mcm","clk":"5322401050","pt":1646319788001,"mc":[{"id":"1.195532861","rc":[{"spn":3.76,"spf":"NaN","id":28791247},{"spn":2.46,"spf":1.0,"id":37665265},{"spn":4.41,"spf":"NaN","id":41529436},{"spn":1.63,"spf":1.0,"id":42252553},{"atb":[[2.3,10]],"id":23239795},{"spn":3.78,"spf":"NaN","id":23239795}],"con":true,"img":false}]}
{"op":"mcm","clk":"5322401061","pt":1646319788103,"mc":[{"id":"1.195532861","rc":[{"atl":[[6.4,7.42]],"id":41529436},{"atb":[[2.48,1.99]],"id":23239795}],"con":true,"img":false}]}
{"op":"mcm","clk":"5322401078","pt":1646319788326,"mc":[{"id":"1.195532861","rc":[{"atl":[[5.3,11.8]],"id":28791247}],"con":true,"img":false}]}
{"op":"mcm","clk":"5322401089","pt":1646319788373,"mc":[{"id":"1.195532861","rc":[{"atb":[[2.34,0]],"id":28791247},{"atl":[[5.4,0]],"id":28791247},{"atl":[[6.4,0]],"id":41529436},{"atb":[[2.22,0]],"id":23239795},{"atl":[[5.3,47.3]],"id":23239795}],"con":true,"img":false}]}
{"op":"mcm","clk":"5322401104","pt":1646319788585,"mc":[{"id":"1.195532861","rc":[{"atb":[[2.32,60.82],[2.3,2.5]],"id":37665265}],"con":true,"img":false}]}
{"op":"mcm","clk":"5322401111","pt":1646319788689,"mc":[{"id":"1.195532861","rc":[{"atb":[[3.05,31.76]],"id":39947224}],"con":true,"img":false}]}
{"op":"mcm","clk":"5322401139","pt":1646319789096,"mc":[{"id":"1.195532861","rc":[{"atb":[[2.38,17.25]],"id":28791247},{"atb":[[3.1,31.76],[3.05,21.76]],"id":39947224},{"atb":[[1.56,211.32],[1.54,74.07]],"id":42252553}],"con":true,"img":false}]}
{"op":"mcm","clk":"5322401148","pt":1646319789200,"mc":[{"id":"1.195532861","rc":[{"atl":[[3,0]],"id":42252553}],"con":true,"img":false}]}
{"op":"mcm","clk":"5322401156","pt":1646319789303,"mc":[{"id":"1.195532861","rc":[{"atl":[[2.9,4.85],[3.05,39.02]],"id":42252553}],"con":true,"img":false}]}
{"op":"mcm","clk":"5322401171","pt":1646319789446,"mc":[{"id":"1.195532861","rc":[{"atl":[[3.2,45.45],[3.35,126.96]],"id":42252553}],"con":true,"img":false}]}
{"op":"mcm","clk":"5322401179","pt":1646319789512,"mc":[{"id":"1.195532861","rc":[{"atl":[[5.7,66.74]],"id":28791247},{"atl":[[2.9,0]],"id":42252553}],"con":true,"img":false}]}
{"op":"mcm","clk":"5322401192","pt":1646319789617,"mc":[{"id":"1.195532861","rc":[{"atl":[[3.1,62.92],[3.35,84.41]],"id":42252553}],"con":true,"img":false}]}
{"op":"mcm","clk":"5322401199","pt":1646319789680,"mc":[{"id":"1.195532861","rc":[{"atl":[[3.1,43.87],[2.94,20.62]],"id":42252553}],"con":true,"img":false}]}
{"op":"mcm","clk":"5322401218","pt":1646319789884,"mc":[{"id":"1.195532861","rc":[{"atl":[[3.05,47.55]],"id":42252553}],"con":true,"img":false}]}
{"op":"mcm","clk":"5322401226","pt":1646319789989,"mc":[{"id":"1.195532861","rc":[{"atl":[[2.98,20.2],[2.94,0]],"id":42252553}],"con":true,"img":false}]}
{"op":"mcm","clk":"5322401259","pt":1646319790402,"mc":[{"id":"1.195532861","rc":[{"atl":[[3.05,39.02]],"id":42252553}],"con":true,"img":false}]}
{"op":"mcm","clk":"5322401307","pt":1646319790879,"mc":[{"id":"1.195532861","rc":[{"atl":[[3.05,58.53]],"id":42252553}],"con":true,"img":false}]}
{"op":"mcm","clk":"5322401320","pt":1646319790983,"mc":[{"id":"1.195532861","rc":[{"atl":[[2.98,0]],"id":42252553}],"con":true,"img":false}]}
{"op":"mcm","clk":"5322401341","pt":1646319791192,"mc":[{"id":"1.195532861","rc":[{"atl":[[5.1,9.55]],"id":28791247}],"con":true,"img":false}]}
{"op":"mcm","clk":"5322401358","pt":1646319791395,"mc":[{"id":"1.195532861","rc":[{"atl":[[5.2,0]],"id":28791247}],"con":true,"img":false}]}
{"op":"mcm","clk":"5322401376","pt":1646319791606,"mc":[{"id":"1.195532861","rc":[{"atl":[[5.4,3.9]],"id":28791247}],"con":true,"img":false}]}
{"op":"mcm","clk":"5322401386","pt":1646319791817,"mc":[{"id":"1.195532861","rc":[{"atl":[[5.4,0]],"id":28791247}],"con":true,"img":false}]}
{"op":"mcm","clk":"5322401447","pt":1646319792503,"mc":[{"id":"1.195532861","rc":[{"atb":[[2.44,2.55]],"id":28791247},{"atb":[[2.34,25.23]],"id":37665265},{"atb":[[2.4,0]],"id":23239795}],"con":true,"img":false}]}
{"op":"mcm","clk":"5322401461","pt":1646319792711,"mc":[{"id":"1.195532861","rc":[{"atb":[[2.38,2.15]],"id":28791247},{"atb":[[2.5,1.65]],"id":23239795}],"con":true,"img":false}]}
{"op":"mcm","clk":"5322401473","pt":1646319792814,"mc":[{"id":"1.195532861","rc":[{"atb":[[2.36,12.7]],"id":28791247}],"con":true,"img":false}]}
{"op":"mcm","clk":"5322401513","pt":1646319793289,"mc":[{"id":"1.195532861","rc":[{"atb":[[2.34,3.18],[2.36,0]],"id":28791247}],"con":true,"img":false}]}
{"op":"mcm","clk":"5322401521","pt":1646319793391,"mc":[{"id":"1.195532861","rc":[{"atb":[[2.42,1.65]],"id":28791247}],"con":true,"img":false}]}
{"op":"mcm","clk":"5322401531","pt":1646319793495,"mc":[{"id":"1.195532861","rc":[{"atb":[[2.34,0],[2.46,4.8]],"id":28791247},{"atb":[[3.45,3.01]],"id":39947224},{"atb":[[2.48,2.75]],"id":37665265},{"atb":[[2.94,1.77]],"id":41529436},{"atb":[[1.64,4.8]],"id":42252553},{"atb":[[2.52,2.64]],"id":23239795}],"con":true,"img":false}]}
{"op":"mcm","clk":"5322401540","pt":1646319793595,"mc":[{"id":"1.195532861","rc":[{"atb":[[3.45,11.63]],"id":39947224},{"atb":[[2.48,20.31]],"id":37665265},{"atb":[[2.92,10.64],[2.78,110.93]],"id":41529436},{"atb":[[1.64,52.44],[1.56,178.57],[1.57,111.03]],"id":42252553}],"con":true,"img":false}]}
{"op":"mcm","clk":"5322401549","pt":1646319793708,"mc":[{"id":"1.195532861","rc":[{"atb":[[2.74,59.97]],"id":41529436}],"con":true,"img":false}]}
{"op":"mcm","clk":"5322401556","pt":1646319793803,"mc":[{"id":"1.195532861","rc":[{"atb":[[3.35,0]],"id":39947224},{"atb":[[2.44,2.15],[2.28,3.93]],"id":37665265},{"atb":[[2.9,1.99]],"id":41529436},{"atb":[[1.63,2.15],[1.62,16.25]],"id":42252553}],"con":true,"img":false}]}
{"op":"mcm","clk":"5322401568","pt":1646319793916,"mc":[{"id":"1.195532861","rc":[{"atb":[[3.35,6.95]],"id":39947224},{"atb":[[2.54,2.15],[2.44,0],[2.28,0]],"id":37665265},{"atb":[[2.86,16.04],[2.76,14.04]],"id":41529436},{"atb":[[1.62,0],[1.63,0],[1.67,2.15]],"id":42252553},{"atb":[[2.44,2.15],[2.28,0]],"id":23239795}],"con":true,"img":false}]}
{"op":"mcm","clk":"5322401583","pt":1646319794119,"mc":[{"id":"1.195532861","rc":[{"atl":[[5.1,21.35],[5.7,45.46]],"id":28791247},{"atl":[[3.15,18.6]],"id":42252553}],"con":true,"img":false}]}
{"op":"mcm","clk":"5322401590","pt":1646319794217,"mc":[{"id":"1.195532861","rc":[{"atb":[[2.56,2.52]],"id":37665265},{"atb":[[1.68,4.41]],"id":42252553},{"atl":[[3.05,39.02]],"id":42252553},{"atl":[[5.5,22.22]],"id":23239795}],"con":true,"img":false}]}
{"op":"mcm","clk":"5322401599","pt":1646319794278,"mc":[{"id":"1.195532861","rc":[{"atb":[[2.46,1.99]],"id":28791247}],"con":true,"img":false}]}
{"op":"mcm","clk":"5322401609","pt":1646319794378,"mc":[{"id":"1.195532861","rc":[{"atb":[[2.48,2.75]],"id":28791247},{"atb":[[3.35,0]],"id":39947224},{"atb":[[2.86,0],[2.76,0]],"id":41529436}],"con":true,"img":false}]}
{"op":"mcm","clk":"5322401628","pt":1646319794688,"mc":[{"id":"1.195532861","rc":[{"atl":[[3.1,0],[3.15,65.11]],"id":42252553}],"con":true,"img":false}]}
{"op":"mcm","clk":"5322401681","pt":1646319795308,"mc":[{"id":"1.195532861","rc":[{"atb":[[2.48,0]],"id":28791247}],"con":true,"img":false}]}
{"op":"mcm","clk":"5322401690","pt":1646319795410,"mc":[{"id":"1.195532861","rc":[{"atb":[[2.46,0]],"id":28791247},{"atl":[[2.92,41.67],[3.2,132.56],[3.35,2.5]],"id":42252553}],"con":true,"img":false}]}
{"op":"mcm","clk":"5322401694","pt":1646319795513,"mc":[{"id":"1.195532861","rc":[{"atb":[[2.5,1.99]],"id":28791247}],"con":true,"img":false}]}
{"op":"mcm","clk":"5322401701","pt":1646319795618,"mc":[{"id":"1.195532861","rc":[{"atb":[[3.4,0]],"id":39947224},{"atl":[[3.05,0]],"id":42252553}],"con":true,"img":false}]}
{"op":"mcm","clk":"5322401708","pt":1646319795676,"mc":[{"id":"1.195532861","rc":[{"atb":[[3.5,1.99]],"id":39947224}],"con":true,"img":false}]}
{"op":"mcm","clk":"5322401728","pt":1646319795884,"mc":[{"id":"1.195532861","rc":[{"atb":[[2.48,0]],"id":23239795}],"con":true,"img":false}]}
{"op":"mcm","clk":"5322401736","pt":1646319795986,"mc":[{"id":"1.195532861","rc":[{"atb":[[2.54,1.99]],"id":23239795}],"con":true,"img":false}]}
{"op":"mcm","clk":"5322401747","pt":1646319796091,"mc":[{"id":"1.195532861","rc":[{"atl":[[5.1,19.4]],"id":28791247}],"con":true,"img":false}]}
{"op":"mcm","clk":"5322401752","pt":1646319796191,"mc":[{"id":"1.195532861","rc":[{"atb":[[2.44,0]],"id":28791247},{"atb":[[2.32,21.66],[2.48,49.57]],"id":37665265},{"atb":[[2.9,0]],"id":41529436}],"con":true,"img":false}]}
{"op":"mcm","clk":"5322401760","pt":1646319796299,"mc":[{"id":"1.195532861","rc":[{"atb":[[2.94,3.76]],"id":41529436}],"con":true,"img":false}]}
{"op":"mcm","clk":"5322401797","pt":1646319796716,"mc":[{"id":"1.195532861","rc":[{"atl":[[2.92,0]],"id":42252553}],"con":true,"img":false}]}
{"op":"mcm","clk":"5322401809","pt":1646319796823,"mc":[{"id":"1.195532861","rc":[{"atl":[[2.94,41.24]],"id":42252553}],"con":true,"img":false}]}
{"op":"mcm","clk":"5322401857","pt":1646319797496,"mc":[{"id":"1.195532861","rc":[{"atb":[[2.5,0]],"id":28791247}],"con":true,"img":false}]}
{"op":"mcm","clk":"5322401864","pt":1646319797601,"mc":[{"id":"1.195532861","rc":[{"atb":[[2.44,1.99]],"id":28791247}],"con":true,"img":false}]}
{"op":"mcm","clk":"5322401910","pt":1646319798117,"mc":[{"id":"1.195532861","rc":[{"atb":[[2.34,0]],"id":37665265},{"atb":[[1.57,94.25]],"id":42252553}],"con":true,"img":false}]}
{"op":"mcm","clk":"5322401930","pt":1646319798278,"mc":[{"id":"1.195532861","rc":[{"atl":[[5.5,22.22]],"id":28791247}],"con":true,"img":false}]}
{"op":"mcm","clk":"5322401946","pt":1646319798487,"mc":[{"id":"1.195532861","rc":[{"atl":[[5.8,8.27]],"id":28791247}],"con":true,"img":false}]}
{"op":"mcm","clk":"5322401959","pt":1646319798590,"mc":[{"id":"1.195532861","rc":[{"atl":[[5.8,0],[11.5,0]],"id":28791247}],"con":true,"img":false}]}
{"op":"mcm","clk":"5322401987","pt":1646319798903,"mc":[{"id":"1.195532861","rc":[{"atl":[[3.15,46.51],[2.98,20.2]],"id":42252553}],"con":true,"img":false}]}
{"op":"mcm","clk":"5322402013","pt":1646319799220,"mc":[{"id":"1.195532861","rc":[{"atb":[[2.32,0],[2.22,0],[2.1,181.82],[2.4,0],[2.24,0]],"id":28791247},{"atl":[[5.5,44.44]],"id":28791247},{"atb":[[3.45,3.01]],"id":39947224},{"atb":[[2.32,0],[2.48,2.75],[2.2,83.33]],"id":37665265},{"atb":[[2.04,96.15],[2.16,0]],"id":23239795}],"con":true,"img":false}]}
{"op":"mcm","clk":"5322402024","pt":1646319799318,"mc":[{"id":"1.195532861","rc":[{"atl":[[5.1,7.6]],"id":28791247}],"con":true,"img":false}]}
{"op":"mcm","clk":"5322402088","pt":1646319800002,"mc":[{"id":"1.195532861","rc":[{"atb":[[2.34,4.37]],"id":28791247}],"con":true,"img":false}]}
{"op":"mcm","clk":"5322402127","pt":1646319800471,"mc":[{"id":"1.195532861","rc":[{"atb":[[2.42,0]],"id":28791247},{"atb":[[2.46,0]],"id":37665265},{"atb":[[2.92,8.99]],"id":41529436},{"atb":[[2.5,0]],"id":23239795}],"con":true,"img":false}]}
{"op":"mcm","clk":"5322402146","pt":1646319800622,"mc":[{"id":"1.195532861","rc":[{"atb":[[2.46,1.65]],"id":28791247},{"atb":[[2.58,1.65]],"id":37665265},{"atb":[[2.56,1.65]],"id":23239795}],"con":true,"img":false}]}
{"op":"mcm","clk":"5322402176","pt":1646319800993,"mc":[{"id":"1.195532861","rc":[{"atb":[[2.48,3.08]],"id":23239795}],"con":true,"img":false}]}
{"op":"mcm","clk":"5322402196","pt":1646319801200,"mc":[{"id":"1.195532861","rc":[{"atb":[[2.48,0]],"id":23239795}],"con":true,"img":false}]}
{"op":"mcm","clk":"5322402277","pt":1646319802231,"mc":[{"id":"1.195532861","rc":[{"atb":[[1.58,7.93]],"id":42252553},{"atb":[[2.4,6.48]],"id":23239795}],"con":true,"img":false}]}
{"op":"mcm","clk":"5322402320","pt":1646319802703,"mc":[{"id":"1.195532861","rc":[{"atl":[[5.5,68.38]],"id":28791247}],"con":true,"img":false}]}
{"op":"mcm","clk":"5322402328","pt":1646319802807,"mc":[{"id":"1.195532861","rc":[{"atl":[[5.7,5]],"id":28791247}],"con":true,"img":false}]}
{"op":"mcm","clk":"5322402410","pt":1646319803989,"mc":[{"id":"1.195532861","rc":[{"atb":[[2.44,0],[2.34,0]],"id":28791247}],"con":true,"img":false}]}
{"op":"mcm","clk":"5322402423","pt":1646319804132,"mc":[{"id":"1.195532861","rc":[{"atb":[[2.4,1.99]],"id":28791247},{"atl":[[5.7,31.91]],"id":23239795}],"con":true,"img":false}]}
{"op":"mcm","clk":"5322402433","pt":1646319804235,"mc":[{"id":"1.195532861","rc":[{"atl":[[5.6,3.48]],"id":28791247},{"atb":[[3.45,8.93]],"id":39947224}],"con":true,"img":false}]}
{"op":"mcm","clk":"5322402447","pt":1646319804442,"mc":[{"id":"1.195532861","rc":[{"atb":[[2.38,0],[2.2,2.15]],"id":28791247}],"con":true,"img":false}]}
{"op":"mcm","clk":"5322402454","pt":1646319804546,"mc":[{"id":"1.195532861","rc":[{"atl":[[5.6,0]],"id":28791247}],"con":true,"img":false}]}
{"op":"mcm","clk":"5322402470","pt":1646319804860,"mc":[{"id":"1.195532861","rc":[{"atb":[[3.1,56.42],[3.05,0]],"id":39947224}],"con":true,"img":false}]}
{"op":"mcm","clk":"5322402489","pt":1646319805220,"mc":[{"id":"1.195532861","rc":[{"atb":[[2.14,59.34]],"id":28791247}],"con":true,"img":false}]}
{"op":"mcm","clk":"5322402499","pt":1646319805429,"mc":[{"id":"1.195532861","rc":[{"atl":[[2.92,41.67]],"id":42252553}],"con":true,"img":false}]}
{"op":"mcm","clk":"5322402508","pt":1646319805532,"mc":[{"id":"1.195532861","rc":[{"atl":[[2.98,70.71],[3.15,0],[2.94,0]],"id":42252553}],"con":true,"img":false}]}
{"op":"mcm","clk":"5322402514","pt":1646319805635,"mc":[{"id":"1.195532861","rc":[{"atl":[[3.2,45.45],[2.98,166.69]],"id":42252553}],"con":true,"img":false}]}
{"op":"mcm","clk":"5322402525","pt":1646319805844,"mc":[{"id":"1.195532861","rc":[{"atb":[[2.4,0]],"id":23239795}],"con":true,"img":false}]}
{"op":"mcm","clk":"5322402553","pt":1646319806159,"mc":[{"id":"1.195532861","rc":[{"atb":[[2.4,0]],"id":28791247}],"con":true,"img":false}]}
{"op":"mcm","clk":"5322402562","pt":1646319806263,"mc":[{"id":"1.195532861","rc":[{"atb":[[2.22,1.99],[2.2,16.7]],"id":28791247}],"con":true,"img":false}]}
{"op":"mcm","clk":"5322402680","pt":1646319807877,"mc":[{"id":"1.195532861","rc":[{"atb":[[2.16,7.28]],"id":28791247},{"atb":[[1.58,0]],"id":42252553}],"con":true,"img":false}]}
{"op":"mcm","clk":"5322402726","pt":1646319808345,"mc":[{"id":"1.195532861","rc":[{"atl":[[5.7,36.91]],"id":28791247}],"con":true,"img":false}]}
{"op":"mcm","clk":"5322402732","pt":1646319808451,"mc":[{"id":"1.195532861","rc":[{"atb":[[2.46,0]],"id":28791247}],"con":true,"img":false}]}
{"op":"mcm","clk":"5322402739","pt":1646319808554,"mc":[{"id":"1.195532861","rc":[{"atb":[[2.24,1.65],[2.12,89.29]],"id":28791247}],"con":true,"img":false}]}
{"op":"mcm","clk":"5322402750","pt":1646319808657,"mc":[{"id":"1.195532861","rc":[{"atb":[[2.1,90.91]],"id":28791247}],"con":true,"img":false}]}
{"op":"mcm","clk":"5322402765","pt":1646319808863,"mc":[{"id":"1.195532861","rc":[{"atl":[[2.96,20.41]],"id":42252553}],"con":true,"img":false}]}
{"op":"mcm","clk":"5322402772","pt":1646319808967,"mc":[{"id":"1.195532861","rc":[{"atl":[[2.98,146.49]],"id":42252553}],"con":true,"img":false}]}
{"op":"mcm","clk":"5322402786","pt":1646319809172,"mc":[{"id":"1.195532861","rc":[{"atl":[[10.5,0]],"id":28791247}],"con":true,"img":false}]}
{"op":"mcm","clk":"5322402815","pt":1646319809639,"mc":[{"id":"1.195532861","rc":[{"atb":[[2.94,22.75]],"id":41529436},{"atb":[[1.57,0]],"id":42252553}],"con":true,"img":false}]}
{"op":"mcm","clk":"5322402825","pt":1646319809741,"mc":[{"id":"1.195532861","rc":[{"atb":[[1.64,130.04]],"id":42252553}],"con":true,"img":false}]}
{"op":"mcm","clk":"5322402831","pt":1646319809846,"mc":[{"id":"1.195532861","rc":[{"atb":[[2.92,0]],"id":41529436}],"con":true,"img":false}]}
{"op":"mcm","clk":"5322402838","pt":1646319809950,"mc":[{"id":"1.195532861","rc":[{"atb":[[2.74,163.37],[2.78,78.65]],"id":41529436}],"con":true,"img":false}]}
{"op":"mcm","clk":"5322402848","pt":1646319810052,"mc":[{"id":"1.195532861","rc":[{"atb":[[2.56,4.21]],"id":23239795}],"con":true,"img":false}]}
{"op":"mcm","clk":"5322402904","pt":1646319810782,"mc":[{"id":"1.195532861","rc":[{"atl":[[5.3,45.3]],"id":23239795}],"con":true,"img":false}]}
{"op":"mcm","clk":"5322402920","pt":1646319810939,"mc":[{"id":"1.195532861","rc":[{"atl":[[5.3,67.82],[5.2,2.5]],"id":23239795}],"con":true,"img":false}]}
{"op":"mcm","clk":"5322402948","pt":1646319811363,"mc":[{"id":"1.195532861","rc":[{"atb":[[2.54,0]],"id":23239795}],"con":true,"img":false}]}
{"op":"mcm","clk":"5322402958","pt":1646319811458,"mc":[{"id":"1.195532861","rc":[{"atb":[[2.58,1.99]],"id":23239795}],"con":true,"img":false}]}
{"op":"mcm","clk":"5322402987","pt":1646319811972,"mc":[{"id":"1.195532861","rc":[{"atb":[[2.16,0]],"id":28791247}],"con":true,"img":false}]}
{"op":"mcm","clk":"5322402994","pt":1646319812084,"mc":[{"id":"1.195532861","rc":[{"atb":[[1.57,8.37]],"id":42252553}],"con":true,"img":false}]}
{"op":"mcm","clk":"5322403058","pt":1646319812966,"mc":[{"id":"1.195532861","rc":[{"atl":[[5.6,10.56]],"id":23239795}],"con":true,"img":false}]}
{"op":"mcm","clk":"5322403068","pt":1646319813172,"mc":[{"id":"1.195532861","rc":[{"atl":[[5.6,5]],"id":23239795}],"con":true,"img":false}]}
{"op":"mcm","clk":"5322403122","pt":1646319814157,"mc":[{"id":"1.195532861","rc":[{"atl":[[5.9,51.02]],"id":23239795}],"con":true,"img":false}]}
{"op":"mcm","clk":"5322403193","pt":1646319815149,"mc":[{"id":"1.195532861","rc":[{"atl":[[5.2,9.09]],"id":37665265}],"con":true,"img":false}]}
{"op":"mcm","clk":"5322403199","pt":1646319815252,"mc":[{"id":"1.195532861","rc":[{"atl":[[5.3,78.56],[5.2,0]],"id":37665265}],"con":true,"img":false}]}
{"op":"mcm","clk":"5322403207","pt":1646319815356,"mc":[{"id":"1.195532861","rc":[{"atl":[[5.6,55.6]],"id":37665265}],"con":true,"img":false}]}
{"op":"mcm","clk":"5322403213","pt":1646319815460,"mc":[{"id":"1.195532861","rc":[{"atl":[[5.3,38.41]],"id":37665265}],"con":true,"img":false}]}
{"op":"mcm","clk":"5322403217","pt":1646319815564,"mc":[{"id":"1.195532861","rc":[{"atl":[[5.1,0]],"id":37665265}],"con":true,"img":false}]}
{"op":"mcm","clk":"5322403224","pt":1646319815671,"mc":[{"id":"1.195532861","rc":[{"atl":[[5.2,10.52]],"id":37665265}],"con":true,"img":false}]}
{"op":"mcm","clk":"5322403237","pt":1646319815772,"mc":[{"id":"1.195532861","rc":[{"atl":[[5.3,32.56],[5.4,5.02]],"id":37665265}],"con":true,"img":false}]}
{"op":"mcm","clk":"5322403250","pt":1646319815980,"mc":[{"id":"1.195532861","rc":[{"atb":[[2.16,4.01]],"id":28791247}],"con":true,"img":false}]}
{"op":"mcm","clk":"5322403271","pt":1646319816135,"mc":[{"id":"1.195532861","rc":[{"atl":[[5.4,0]],"id":37665265}],"con":true,"img":false}]}
{"op":"mcm","clk":"5322403292","pt":1646319816445,"mc":[{"id":"1.195532861","rc":[{"atb":[[2.56,2.55]],"id":23239795}],"con":true,"img":false}]}
{"op":"mcm","clk":"5322403301","pt":1646319816549,"mc":[{"id":"1.195532861","rc":[{"atb":[[2.6,1.65]],"id":23239795}],"con":true,"img":false}]}
{"op":"mcm","clk":"5322403376","pt":1646319817853,"mc":[{"id":"1.195532861","rc":[{"atl":[[5.3,23.26],[5.4,9.09]],"id":37665265}],"con":true,"img":false}]}
{"op":"mcm","clk":"5322403415","pt":1646319818370,"mc":[{"id":"1.195532861","rc":[{"atl":[[5.9,51.02]],"id":28791247}],"con":true,"img":false}]}
{"op":"mcm","clk":"5322403454","pt":1646319818840,"mc":[{"id":"1.195532861","rc":[{"atl":[[3,50]],"id":42252553}],"con":true,"img":false}]}
{"op":"mcm","clk":"5322403528","pt":1646319819670,"mc":[{"id":"1.195532861","rc":[{"atb":[[2.56,0]],"id":23239795}],"con":true,"img":false}]}
{"op":"mcm","clk":"5322403553","pt":1646319819981,"mc":[{"id":"1.195532861","rc":[{"atl":[[4.6,0]],"id":42252553}],"con":true,"img":false}]}
{"op":"mcm","clk":"5322403561","pt":1646319820036,"mc":[{"id":"1.195532861","rc":[{"atl":[[7,0]],"id":28791247}],"con":true,"img":false}]}
{"op":"mcm","clk":"5322403578","pt":1646319820343,"mc":[{"id":"1.195532861","rc":[{"atl":[[5.3,0],[5.4,31.82]],"id":37665265}],"con":true,"img":false}]}
{"op":"mcm","clk":"5322403620","pt":1646319821073,"mc":[{"id":"1.195532861","rc":[{"atb":[[2.16,28.26],[2.14,35.09]],"id":28791247}],"con":true,"img":false}]}
{"op":"mcm","clk":"5322403631","pt":1646319821282,"mc":[{"id":"1.195532861","rc":[{"atl":[[5.3,71.33]],"id":23239795}],"con":true,"img":false}]}
{"op":"mcm","clk":"5322403653","pt":1646319821547,"mc":[{"id":"1.195532861","rc":[{"atl":[[5.3,67.82]],"id":23239795}],"con":true,"img":false}]}
{"op":"mcm","clk":"5322403681","pt":1646319822062,"mc":[{"id":"1.195532861","rc":[{"atb":[[2.24,16.2]],"id":28791247}],"con":true,"img":false}]}
{"op":"mcm","clk":"5322403698","pt":1646319822274,"mc":[{"id":"1.195532861","rc":[{"atb":[[2.2,2.15]],"id":28791247}],"con":true,"img":false}]}
{"op":"mcm","clk":"5322403703","pt":1646319822377,"mc":[{"id":"1.195532861","rc":[{"atb":[[2.3,2.15],[2.2,0]],"id":28791247}],"con":true,"img":false}]}
{"op":"mcm","clk":"5322403741","pt":1646319822851,"mc":[{"id":"1.195532861","rc":[{"atl":[[5,2.56]],"id":28791247},{"atl":[[8.6,1.57]],"id":39947224},{"atl":[[5.1,2.44]],"id":37665265},{"atl":[[5.8,1.83]],"id":41529436},{"atl":[[2.9,1.83]],"id":42252553},{"atl":[[5,2.56]],"id":23239795}],"con":true,"img":false}]}
{"op":"mcm","clk":"5322403751","pt":1646319822953,"mc":[{"id":"1.195532861","rc":[{"atl":[[5,10.16],[5.3,50.6],[5.5,46.16]],"id":28791247},{"atl":[[8.6,6.45],[9.2,32.26],[9.4,0]],"id":39947224},{"atl":[[5.8,21]],"id":41529436},{"atl":[[2.9,40.86],[2.98,95.98]],"id":42252553},{"atl":[[5,5.12],[5.3,9.3],[5.2,12.9],[4.9,3.8]],"id":23239795}],"con":true,"img":false}]}
{"op":"mcm","clk":"5322403760","pt":1646319823058,"mc":[{"id":"1.195532861","rc":[{"atl":[[5.3,41.3],[5.5,22.22],[4.9,7.62],[5.2,9.52]],"id":28791247},{"atl":[[9,5],[9.2,27.38],[8.4,5.54]],"id":39947224},{"atl":[[5.3,9.3],[5.4,22.73]],"id":37665265},{"atl":[[6.4,18.04],[6.2,43.93],[6,60.25],[5.9,0]],"id":41529436},{"atl":[[4.8,2.8],[5.3,0],[5.1,0],[5.2,22.42]],"id":23239795}],"con":true,"img":false}]}
{"op":"mcm","clk":"5322403770","pt":1646319823156,"mc":[{"id":"1.195532861","rc":[{"atl":[[4.8,2.8]],"id":28791247},{"atl":[[8.2,1.74]],"id":39947224},{"atl":[[6.2,0]],"id":41529436},{"atl":[[2.98,0],[2.94,10.42],[2.92,0],[2.96,121.27]],"id":42252553}],"con":true,"img":false}]}
{"op":"mcm","clk":"5322403776","pt":1646319823261,"mc":[{"id":"1.195532861","rc":[{"atl":[[5.1,9.76],[5.2,0]],"id":28791247},{"atl":[[9,0],[8.8,7.63],[9.4,4.38]],"id":39947224},{"atl":[[6.4,0],[6,10.5]],"id":41529436},{"atl":[[5,15.12],[5.2,12.9]],"id":23239795}],"con":true,"img":false}]}
{"op":"mcm","clk":"5322403801","pt":1646319823675,"mc":[{"id":"1.195532861","rc":[{"atl":[[9.4,0]],"id":39947224},{"atb":[[2.4,6.68]],"id":37665265},{"atl":[[2.94,0]],"id":42252553}],"con":true,"img":false}]}
{"op":"mcm","clk":"5322403837","pt":1646319824191,"mc":[{"id":"1.195532861","rc":[{"atl":[[5.1,0],[5,20.16],[5.2,4.38]],"id":28791247},{"atl":[[8.6,11.71],[8.8,2.5]],"id":39947224}],"con":true,"img":false}]}
{"op":"mcm","clk":"5322403865","pt":1646319824455,"mc":[{"id":"1.195532861","rc":[{"atb":[[2.24,14.55]],"id":28791247}],"con":true,"img":false}]}
{"op":"mcm","clk":"5322403888","pt":1646319824665,"mc":[{"id":"1.195532861","rc":[{"atb":[[2.32,1.65],[2.22,0]],"id":28791247},{"atl":[[5.2,0]],"id":28791247}],"con":true,"img":false}]}
{"op":"mcm","clk":"5322403899","pt":1646319824768,"mc":[{"id":"1.195532861","rc":[{"atb":[[2.32,3.64]],"id":28791247}],"con":true,"img":false}]}
{"op":"mcm","clk":"5322403931","pt":1646319825078,"mc":[{"id":"1.195532861","rc":[{"atb":[[2.64,60.98],[2.78,22.47],[2.94,3.76]],"id":41529436},{"atl":[[2.96,100.86],[2.94,20.62]],"id":42252553},{"atb":[[2.58,0]],"id":23239795}],"con":true,"img":false}]}
{"op":"mcm","clk":"5322403940","pt":1646319825182,"mc":[{"id":"1.195532861","rc":[{"atb":[[2.54,1.99]],"id":23239795}],"con":true,"img":false}]}
{"op":"mcm","clk":"5322403946","pt":1646319825288,"mc":[{"id":"1.195532861","rc":[{"atl":[[2.96,119.31]],"id":42252553}],"con":true,"img":false}]}
{"op":"mcm","clk":"5322403975","pt":1646319825555,"mc":[{"id":"1.195532861","rc":[{"atb":[[1.57,0]],"id":42252553}],"con":true,"img":false}]}
{"op":"mcm","clk":"5322403998","pt":1646319825862,"mc":[{"id":"1.195532861","rc":[{"atl":[[2.96,100.86]],"id":42252553}],"con":true,"img":false}]}
{"op":"mcm","clk":"5322404028","pt":1646319826280,"mc":[{"id":"1.195532861","rc":[{"atb":[[2.94,1.77]],"id":41529436}],"con":true,"img":false}]}
{"op":"mcm","clk":"5322404036","pt":1646319826383,"mc":[{"id":"1.195532861","rc":[{"atb":[[2.8,1.99],[2.74,59.97],[2.78,45.03],[2.7,144.79]],"id":41529436}],"con":true,"img":false}]}
{"op":"mcm","clk":"5322404044","pt":1646319826486,"mc":[{"id":"1.195532861","rc":[{"atb":[[2.94,0]],"id":41529436}],"con":true,"img":false}]}
{"op":"mcm","clk":"5322404135","pt":1646319827686,"mc":[{"id":"1.195532861","rc":[{"atl":[[5.1,11.74],[5.4,0]],"id":37665265}],"con":true,"img":false}]}
{"op":"mcm","clk":"5322404145","pt":1646319827791,"mc":[{"id":"1.195532861","rc":[{"atb":[[2.16,24.25]],"id":28791247},{"atb":[[2.78,22.56],[2.76,32.09]],"id":41529436}],"con":true,"img":false}]}
{"op":"mcm","clk":"5322404168","pt":1646319827999,"mc":[{"id":"1.195532861","rc":[{"atb":[[2.76,22.73]],"id":41529436},{"atb":[[1.57,8.37]],"id":42252553}],"con":true,"img":false}]}
{"op":"mcm","clk":"5322404183","pt":1646319828157,"mc":[{"id":"1.195532861","rc":[{"atb":[[3.55,2.81]],"id":39947224},{"atb":[[2.6,2.44]],"id":37665265},{"atb":[[2.82,1.97]],"id":41529436},{"atb":[[2.62,2.38]],"id":23239795}],"con":true,"img":false}]}
{"op":"mcm","clk":"5322404192","pt":1646319828261,"mc":[{"id":"1.195532861","rc":[{"atb":[[3.2,12.94],[3.1,31.76]],"id":39947224}],"con":true,"img":false}]}
{"op":"mcm","clk":"5322404248","pt":1646319828989,"mc":[{"id":"1.195532861","rc":[{"atb":[[3.15,8.02]],"id":39947224}],"con":true,"img":false}]}
{"op":"mcm","clk":"5322404257","pt":1646319829092,"mc":[{"id":"1.195532861","rc":[{"atb":[[2.78,45.03]],"id":41529436}],"con":true,"img":false}]}
{"op":"mcm","clk":"5322404261","pt":1646319829196,"mc":[{"id":"1.195532861","rc":[{"atb":[[3.5,0]],"id":39947224},{"atb":[[2.76,0]],"id":41529436}],"con":true,"img":false}]}
{"op":"mcm","clk":"5322404270","pt":1646319829299,"mc":[{"id":"1.195532861","rc":[{"atb":[[3.6,1.99]],"id":39947224}],"con":true,"img":false}]}
{"op":"mcm","clk":"5322404287","pt":1646319829536,"mc":[{"id":"1.195532861","rc":[{"atb":[[3.15,0]],"id":39947224},{"atb":[[2.54,0]],"id":23239795}],"con":true,"img":false}]}
{"op":"mcm","clk":"5322404298","pt":1646319829669,"mc":[{"id":"1.195532861","rc":[{"atb":[[2.64,1.99]],"id":23239795}],"con":true,"img":false}]}
{"op":"mcm","clk":"5322404342","pt":1646319830293,"mc":[{"id":"1.195532861","rc":[{"atl":[[4.8,10.42],[5,12.56]],"id":28791247},{"atl":[[8.6,6.83],[8.2,7.28]],"id":39947224},{"atl":[[4.8,6.6],[5,12.56]],"id":23239795}],"con":true,"img":false}]}
{"op":"mcm","clk":"5322404348","pt":1646319830401,"mc":[{"id":"1.195532861","rc":[{"atl":[[4.8,2.8],[4.9,27.78]],"id":28791247},{"atl":[[8.2,1.74],[8.4,11.08]],"id":39947224},{"atl":[[4.8,2.8],[4.9,16.7]],"id":23239795}],"con":true,"img":false}]}
{"op":"mcm","clk":"5322404401","pt":1646319830975,"mc":[{"id":"1.195532861","rc":[{"atl":[[5.6,24.24],[5.3,36.26]],"id":37665265}],"con":true,"img":false}]}
{"op":"mcm","clk":"5322404434","pt":1646319831288,"mc":[{"id":"1.195532861","rc":[{"atl":[[5,9.78]],"id":37665265}],"con":true,"img":false}]}
{"op":"mcm","clk":"5322404446","pt":1646319831392,"mc":[{"id":"1.195532861","rc":[{"atb":[[3.45,3.01]],"id":39947224},{"atl":[[4.9,2.68]],"id":37665265},{"atb":[[2.04,0],[1.95,105.26]],"id":23239795}],"con":true,"img":false}]}
{"op":"mcm","clk":"5322404457","pt":1646319831499,"mc":[{"id":"1.195532861","rc":[{"atl":[[5.2,0]],"id":37665265}],"con":true,"img":false}]}
{"op":"mcm","clk":"5322404467","pt":1646319831603,"mc":[{"id":"1.195532861","rc":[{"atb":[[2.14,0],[2.1,36.36]],"id":28791247},{"atl":[[5.1,21.5],[5.3,26.96]],"id":37665265},{"atb":[[2.1,0],[2.2,33.33]],"id":23239795}],"con":true,"img":false}]}
{"op":"mcm","clk":"5322404474","pt":1646319831659,"mc":[{"id":"1.195532861","rc":[{"atb":[[2.14,4.35]],"id":28791247},{"atb":[[3.1,0],[2.92,52.08]],"id":39947224},{"atb":[[1.95,0],[2.06,188.68]],"id":23239795}],"con":true,"img":false}]}
{"op":"mcm","clk":"5322404481","pt":1646319831762,"mc":[{"id":"1.195532861","rc":[{"atb":[[2.18,5.46]],"id":28791247},{"atb":[[2.4,0]],"id":37665265}],"con":true,"img":false}]}
{"op":"mcm","clk":"5322404489","pt":1646319831868,"mc":[{"id":"1.195532861","rc":[{"atb":[[2.14,0]],"id":28791247}],"con":true,"img":false}]}
{"op":"mcm","clk":"5322404508","pt":1646319832177,"mc":[{"id":"1.195532861","rc":[{"atb":[[2.24,0],[2.16,0]],"id":28791247},{"atb":[[3.05,48.78],[2.92,0]],"id":39947224},{"atb":[[2.54,10.72],[2.6,6.34],[2.34,5],[2.2,0]],"id":37665265},{"atb":[[2.06,94.34],[2.16,86.21]],"id":23239795}],"con":true,"img":false}]}
{"op":"mcm","clk":"5322404524","pt":1646319832386,"mc":[{"id":"1.195532861","rc":[{"atb":[[2.26,3.25],[2.34,0],[2.4,5.5]],"id":37665265}],"con":true,"img":false}]}
{"op":"mcm","clk":"5322404531","pt":1646319832488,"mc":[{"id":"1.195532861","rc":[{"atb":[[2.58,0]],"id":37665265},{"atb":[[2.6,0]],"id":23239795}],"con":true,"img":false}]}
{"op":"mcm","clk":"5322404551","pt":1646319832695,"mc":[{"id":"1.195532861","rc":[{"atb":[[2.62,1.65]],"id":37665265},{"atb":[[2.66,1.65]],"id":23239795}],"con":true,"img":false}]}
{"op":"mcm","clk":"5322404570","pt":1646319832902,"mc":[{"id":"1.195532861","rc":[{"atb":[[2.26,0]],"id":37665265}],"con":true,"img":false}]}
{"op":"mcm","clk":"5322404671","pt":1646319834206,"mc":[{"id":"1.195532861","rc":[{"atl":[[9,12.5]],"id":39947224}],"con":true,"img":false}]}
{"op":"mcm","clk":"5322404692","pt":1646319834468,"mc":[{"id":"1.195532861","rc":[{"atl":[[9.6,0],[10,0],[11,0]],"id":39947224}],"con":true,"img":false}]}
{"op":"mcm","clk":"5322404735","pt":1646319834984,"mc":[{"id":"1.195532861","rc":[{"atl":[[5.1,12.2],[4.9,12.46]],"id":37665265}],"con":true,"img":false}]}
{"op":"mcm","clk":"5322404757","pt":1646319835295,"mc":[{"id":"1.195532861","rc":[{"atb":[[3.55,7.17]],"id":39947224}],"con":true,"img":false}]}
{"op":"mcm","clk":"5322404787","pt":1646319835665,"mc":[{"id":"1.195532861","rc":[{"atb":[[2.18,0]],"id":28791247},{"atb":[[2.62,7.25]],"id":37665265}],"con":true,"img":false}]}
{"op":"mcm","clk":"5322404795","pt":1646319835771,"mc":[{"id":"1.195532861","rc":[{"atb":[[3.65,2.63]],"id":39947224},{"atb":[[2.64,2.33]],"id":37665265},{"atb":[[2.68,2.25]],"id":23239795}],"con":true,"img":false}]}
{"op":"mcm","clk":"5322404824","pt":1646319836076,"mc":[{"id":"1.195532861","rc":[{"atb":[[2.3,0],[2.18,2.15]],"id":28791247}],"con":true,"img":false}]}
{"op":"mcm","clk":"5322404839","pt":1646319836285,"mc":[{"id":"1.195532861","rc":[{"atb":[[2.32,6.94]],"id":28791247}],"con":true,"img":false}]}
{"op":"mcm","clk":"5322404844","pt":1646319836389,"mc":[{"id":"1.195532861","rc":[{"atb":[[2.16,3.88]],"id":28791247},{"atb":[[2.6,9.46]],"id":37665265}],"con":true,"img":false}]}
{"op":"mcm","clk":"5322404861","pt":1646319836595,"mc":[{"id":"1.195532861","rc":[{"atb":[[2.16,13.54]],"id":28791247},{"atb":[[2.6,6.34]],"id":37665265}],"con":true,"img":false}]}
{"op":"mcm","clk":"5322404868","pt":1646319836698,"mc":[{"id":"1.195532861","rc":[{"atb":[[3.6,0]],"id":39947224}],"con":true,"img":false}]}
{"op":"mcm","clk":"5322404889","pt":1646319836802,"mc":[{"id":"1.195532861","rc":[{"atb":[[3.7,1.99]],"id":39947224}],"con":true,"img":false}]}
{"op":"mcm","clk":"5322404906","pt":1646319837008,"mc":[{"id":"1.195532861","rc":[{"atb":[[3.75,2.46]],"id":39947224},{"atb":[[2.64,0]],"id":23239795}],"con":true,"img":false}]}
{"op":"mcm","clk":"5322404914","pt":1646319837064,"mc":[{"id":"1.195532861","rc":[{"atb":[[2.7,1.99]],"id":23239795}],"con":true,"img":false}]}
{"op":"mcm","clk":"5322404928","pt":1646319837273,"mc":[{"id":"1.195532861","rc":[{"atb":[[2.32,3.64]],"id":28791247}],"con":true,"img":false}]}
{"op":"mcm","clk":"5322405028","pt":1646319838484,"mc":[{"id":"1.195532861","rc":[{"atl":[[5,44.98],[5.3,2.5]],"id":28791247},{"atl":[[8.6,29.73],[9.2,0]],"id":39947224},{"atl":[[5,29.12],[5.2,2.5],[4.7,3.79]],"id":23239795}],"con":true,"img":false}]}
{"op":"mcm","clk":"5322405036","pt":1646319838590,"mc":[{"id":"1.195532861","rc":[{"atl":[[4.7,12.16]],"id":28791247},{"atl":[[8,3.82]],"id":39947224},{"atl":[[6.6,64.76]],"id":41529436},{"atl":[[4.9,12.9],[4.6,3.09]],"id":23239795}],"con":true,"img":false}]}
{"op":"mcm","clk":"5322405046","pt":1646319838697,"mc":[{"id":"1.195532861","rc":[{"atb":[[2.32,1.65]],"id":28791247},{"atl":[[4.6,3.09]],"id":28791247},{"atl":[[7.8,1.94],[8.4,5.54]],"id":39947224},{"atl":[[4.9,0],[4.5,3.09]],"id":23239795}],"con":true,"img":false}]}
{"op":"mcm","clk":"5322405055","pt":1646319838802,"mc":[{"id":"1.195532861","rc":[{"atb":[[2.18,6.57],[2.2,1.99]],"id":28791247},{"atl":[[4.9,0],[4.5,3.09],[5.2,5.6]],"id":28791247}],"con":true,"img":false}]}
{"op":"mcm","clk":"5322405064","pt":1646319838915,"mc":[{"id":"1.195532861","rc":[{"atl":[[4.4,3.42],[5.6,7.36]],"id":28791247},{"atl":[[7.8,3.94],[8.4,0]],"id":39947224},{"atl":[[4.4,3.42]],"id":23239795}],"con":true,"img":false}]}
{"op":"mcm","clk":"5322405074","pt":1646319839010,"mc":[{"id":"1.195532861","rc":[{"atl":[[5,34.98],[4.7,22.97]],"id":28791247},{"atb":[[3.7,0]],"id":39947224},{"atl":[[8,7.7],[8.2,7.3]],"id":39947224},{"atl":[[5,19.12],[4.7,14.6]],"id":23239795}],"con":true,"img":false}]}
{"op":"mcm","clk":"5322405081","pt":1646319839123,"mc":[{"id":"1.195532861","rc":[{"atl":[[4.3,3.09],[4.5,0],[5.2,0]],"id":28791247},{"atb":[[3.8,1.99]],"id":39947224},{"atl":[[7.8,1.94]],"id":39947224}],"con":true,"img":false}]}
{"op":"mcm","clk":"5322405088","pt":1646319839219,"mc":[{"id":"1.195532861","rc":[{"atl":[[4.6,14.2],[4.7,12.16]],"id":28791247},{"atb":[[3.55,4.36],[3.75,0],[3.45,0],[3.65,0]],"id":39947224},{"atl":[[4.6,14.2],[4.7,3.79]],"id":23239795}],"con":true,"img":false}]}
{"op":"mcm","clk":"5322405095","pt":1646319839276,"mc":[{"id":"1.195532861","rc":[{"atl":[[4.5,11.43],[4.2,3.82]],"id":28791247}],"con":true,"img":false}]}
{"op":"mcm","clk":"5322405105","pt":1646319839382,"mc":[{"id":"1.195532861","rc":[{"atl":[[4.3,0],[5.6,0],[4.1,3.42]],"id":28791247},{"atb":[[3.2,2.5],[3.05,67.53]],"id":39947224}],"con":true,"img":false}]}
{"op":"mcm","clk":"5322405113","pt":1646319839482,"mc":[{"id":"1.195532861","rc":[{"atl":[[4,2.11]],"id":28791247}],"con":true,"img":false}]}
{"op":"mcm","clk":"5322405197","pt":1646319840425,"mc":[{"id":"1.195532861","rc":[{"atb":[[2.32,0],[2.12,0],[2.16,49.9]],"id":28791247},{"atl":[[5.9,0],[4.5,0],[5.5,0],[5.7,5],[4.2,16.32]],"id":28791247},{"atb":[[3.25,21.51],[3.05,18.75]],"id":39947224},{"atb":[[2.62,5.59],[2.48,15.43],[2.4,0]],"id":37665265},{"atb":[[2.78,22.47]],"id":41529436},{"atb":[[1.59,74.07],[1.56,0]],"id":42252553},{"atb":[[2.26,79.37],[2.66,0],[2.16,0]],"id":23239795}],"con":true,"img":false}]}
{"op":"mcm","clk":"5322405218","pt":1646319840590,"mc":[{"id":"1.195532861","rc":[{"atb":[[2.22,1.65],[2.12,89.29],[2.16,13.54]],"id":28791247},{"atb":[[2.66,1.65]],"id":37665265},{"atb":[[2.84,1.65]],"id":41529436},{"atb":[[1.53,7.41]],"id":42252553},{"atb":[[2.72,1.65]],"id":23239795}],"con":true,"img":false}]}
{"op":"mcm","clk":"5322405244","pt":1646319840904,"mc":[{"id":"1.195532861","rc":[{"atb":[[1.53,0]],"id":42252553}],"con":true,"img":false}]}
{"op":"mcm","clk":"5322405273","pt":1646319841219,"mc":[{"id":"1.195532861","rc":[{"atb":[[2.22,4.21]],"id":28791247},{"atb":[[2.62,0]],"id":37665265}],"con":true,"img":false}]}
{"op":"mcm","clk":"5322405290","pt":1646319841382,"mc":[{"id":"1.195532861","rc":[{"atb":[[2.7,5.99]],"id":23239795}],"con":true,"img":false}]}
{"op":"mcm","clk":"5322405302","pt":1646319841487,"mc":[{"id":"1.195532861","rc":[{"atb":[[2.12,0],[2.18,2.15],[2.16,0]],"id":28791247},{"atb":[[2.62,10.52]],"id":23239795}],"con":true,"img":false}]}
{"op":"mcm","clk":"5322405310","pt":1646319841586,"mc":[{"id":"1.195532861","rc":[{"atl":[[5.3,50.22]],"id":37665265}],"con":true,"img":false}]}
{"op":"mcm","clk":"5322405319","pt":1646319841691,"mc":[{"id":"1.195532861","rc":[{"atb":[[1.98,102.04]],"id":28791247}],"con":true,"img":false}]}
{"op":"mcm","clk":"5322405331","pt":1646319841794,"mc":[{"id":"1.195532861","rc":[{"atb":[[2.74,116.79],[2.7,88.24]],"id":41529436}],"con":true,"img":false}]}
{"op":"mcm","clk":"5322405349","pt":1646319842001,"mc":[{"id":"1.195532861","rc":[{"atl":[[5.6,2.5],[6,5],[12,0]],"id":37665265}],"con":true,"img":false}]}
{"op":"mcm","clk":"5322405430","pt":1646319843093,"mc":[{"id":"1.195532861","rc":[{"atb":[[1.57,0]],"id":42252553}],"con":true,"img":false}]}
{"op":"mcm","clk":"5322405483","pt":1646319843715,"mc":[{"id":"1.195532861","rc":[{"atb":[[3.2,19.56]],"id":39947224}],"con":true,"img":false}]}
{"op":"mcm","clk":"5322405493","pt":1646319843819,"mc":[{"id":"1.195532861","rc":[{"atb":[[3.05,0]],"id":39947224}],"con":true,"img":false}]}
{"op":"mcm","clk":"5322405508","pt":1646319843981,"mc":[{"id":"1.195532861","rc":[{"atl":[[2.76,45.45]],"id":42252553}],"con":true,"img":false}]}
{"op":"mcm","clk":"5322405514","pt":1646319844084,"mc":[{"id":"1.195532861","rc":[{"atl":[[2.9,20.45],[2.74,42.98],[2.96,0]],"id":42252553}],"con":true,"img":false}]}
{"op":"mcm","clk":"5322405524","pt":1646319844190,"mc":[{"id":"1.195532861","rc":[{"atl":[[2.94,127.27]],"id":42252553}],"con":true,"img":false}]}
{"op":"mcm","clk":"5322405529","pt":1646319844289,"mc":[{"id":"1.195532861","rc":[{"atl":[[2.9,1.83]],"id":42252553}],"con":true,"img":false}]}
{"op":"mcm","clk":"5322405568","pt":1646319844917,"mc":[{"id":"1.195532861","rc":[{"atb":[[2.86,0],[2.96,20.41]],"id":39947224},{"atb":[[2,0],[2.04,38.46]],"id":37665265},{"atb":[[2.68,23.81]],"id":41529436},{"atl":[[2.94,106.65],[2.78,22.47]],"id":42252553},{"atb":[[2.3,40.77],[2.2,0]],"id":23239795}],"con":true,"img":false}]}
{"op":"mcm","clk":"5322405576","pt":1646319845021,"mc":[{"id":"1.195532861","rc":[{"atb":[[2.2,0]],"id":28791247},{"atb":[[2.72,9.02],[2.78,0]],"id":41529436}],"con":true,"img":false}]}
{"op":"mcm","clk":"5322405588","pt":1646319845077,"mc":[{"id":"1.195532861","rc":[{"atb":[[2.24,1.99]],"id":28791247}],"con":true,"img":false}]}
{"op":"mcm","clk":"5322405597","pt":1646319845180,"mc":[{"id":"1.195532861","rc":[{"atb":[[2.66,4.44]],"id":37665265}],"con":true,"img":false}]}
{"op":"mcm","clk":"5322405604","pt":1646319845285,"mc":[{"id":"1.195532861","rc":[{"atb":[[3.8,0]],"id":39947224}],"con":true,"img":false}]}
{"op":"mcm","clk":"5322405614","pt":1646319845387,"mc":[{"id":"1.195532861","rc":[{"atb":[[3.6,1.99]],"id":39947224}],"con":true,"img":false}]}
{"op":"mcm","clk":"5322405630","pt":1646319845592,"mc":[{"id":"1.195532861","rc":[{"atb":[[2.72,0],[2.74,59.32]],"id":41529436}],"con":true,"img":false}]}
{"op":"mcm","clk":"5322405639","pt":1646319845697,"mc":[{"id":"1.195532861","rc":[{"atb":[[2.8,0]],"id":41529436}],"con":true,"img":false}]}
{"op":"mcm","clk":"5322405647","pt":1646319845800,"mc":[{"id":"1.195532861","rc":[{"atb":[[2.84,3.64]],"id":41529436}],"con":true,"img":false}]}
{"op":"mcm","clk":"5322405690","pt":1646319846320,"mc":[{"id":"1.195532861","rc":[{"atl":[[5.1,44.44],[5.3,23.26]],"id":37665265},{"atb":[[2.7,0]],"id":41529436}],"con":true,"img":false}]}
{"op":"mcm","clk":"5322405724","pt":1646319846586,"mc":[{"id":"1.195532861","rc":[{"atl":[[4.8,12.09]],"id":37665265}],"con":true,"img":false}]}
{"op":"mcm","clk":"5322405736","pt":1646319846684,"mc":[{"id":"1.195532861","rc":[{"atl":[[4.7,2.94]],"id":37665265},{"atb":[[2.84,1.65]],"id":41529436}],"con":true,"img":false}]}
{"op":"mcm","clk":"5322405743","pt":1646319846794,"mc":[{"id":"1.195532861","rc":[{"atl":[[5.1,48.13],[5,0],[4.9,2.68],[4.7,15.03]],"id":37665265},{"atb":[[2.76,1.99]],"id":41529436}],"con":true,"img":false}]}
{"op":"mcm","clk":"5322405754","pt":1646319846894,"mc":[{"id":"1.195532861","rc":[{"atl":[[4.8,24.18],[4.7,2.94]],"id":37665265}],"con":true,"img":false}]}
{"op":"mcm","clk":"5322405764","pt":1646319846995,"mc":[{"id":"1.195532861","rc":[{"atb":[[2.04,38.46],[2.1,0]],"id":28791247},{"atb":[[2.82,0],[2.96,0],[2.78,22.47]],"id":39947224},{"atb":[[2.04,0],[2.1,36.36]],"id":37665265},{"atl":[[5.1,44.44],[4.9,12.94],[5.4,4.2]],"id":37665265},{"atb":[[2.3,10],[2.5,26.67]],"id":23239795}],"con":true,"img":false}]}
{"op":"mcm","clk":"5322405772","pt":1646319847100,"mc":[{"id":"1.195532861","rc":[{"atb":[[2.5,26.67]],"id":41529436}],"con":true,"img":false}]}
{"op":"mcm","clk":"5322405781","pt":1646319847205,"mc":[{"id":"1.195532861","rc":[{"atb":[[2.66,0],[2.68,0]],"id":41529436}],"con":true,"img":false}]}
{"op":"mcm","clk":"5322405789","pt":1646319847310,"mc":[{"id":"1.195532861","rc":[{"atb":[[2.22,1.65]],"id":28791247},{"atb":[[1.6,7.05]],"id":42252553}],"con":true,"img":false}]}
{"op":"mcm","clk":"5322405804","pt":1646319847518,"mc":[{"id":"1.195532861","rc":[{"atb":[[2.06,0]],"id":28791247},{"atb":[[2.54,2.15],[2.6,19.83],[2.66,12.53]],"id":37665265},{"atl":[[5.4,0]],"id":37665265}],"con":true,"img":false}]}
{"op":"mcm","clk":"5322405812","pt":1646319847577,"mc":[{"id":"1.195532861","rc":[{"atb":[[2.54,12.88],[2.48,2.75]],"id":37665265},{"atb":[[2.26,0],[2.68,9.9]],"id":23239795}],"con":true,"img":false}]}
{"op":"mcm","clk":"5322405820","pt":1646319847682,"mc":[{"id":"1.195532861","rc":[{"atb":[[2.6,15.93]],"id":37665265}],"con":true,"img":false}]}
{"op":"mcm","clk":"5322405829","pt":1646319847783,"mc":[{"id":"1.195532861","rc":[{"atb":[[2.76,0]],"id":41529436}],"con":true,"img":false}]}
{"op":"mcm","clk":"5322405837","pt":1646319847889,"mc":[{"id":"1.195532861","rc":[{"atb":[[2.84,3.64]],"id":41529436}],"con":true,"img":false}]}
{"op":"mcm","clk":"5322405854","pt":1646319848196,"mc":[{"id":"1.195532861","rc":[{"spn":3.12,"spf":"NaN","id":28791247},{"spn":5.7,"spf":"NaN","id":39947224},{"spn":2.66,"spf":1.0,"id":37665265},{"atb":[[2.84,1.65]],"id":41529436},{"spn":4.32,"spf":"NaN","id":41529436},{"spn":1.66,"spf":1.0,"id":42252553},{"spn":3.56,"spf":"NaN","id":23239795}],"con":true,"img":false}]}
{"op":"mcm","clk":"5322405864","pt":1646319848299,"mc":[{"id":"1.195532861","rc":[{"atb":[[2.76,1.99]],"id":41529436}],"con":true,"img":false}]}
{"op":"mcm","clk":"5322405881","pt":1646319848511,"mc":[{"id":"1.195532861","rc":[{"atb":[[2.22,0]],"id":28791247}],"con":true,"img":false}]}
{"op":"mcm","clk":"5322405901","pt":1646319848721,"mc":[{"id":"1.195532861","rc":[{"atb":[[2.26,1.65],[2.1,2.15]],"id":28791247}],"con":true,"img":false}]}
{"op":"mcm","clk":"5322405911","pt":1646319848777,"mc":[{"id":"1.195532861","rc":[{"atb":[[2.18,0]],"id":28791247}],"con":true,"img":false}]}
{"op":"mcm","clk":"5322405921","pt":1646319848884,"mc":[{"id":"1.195532861","rc":[{"atb":[[2.74,2.5],[2.64,163.46]],"id":41529436}],"con":true,"img":false}]}
{"op":"mcm","clk":"5322405934","pt":1646319848986,"mc":[{"id":"1.195532861","rc":[{"atb":[[2.72,4.15],[2.3,0],[2.64,5],[2.38,0],[2.46,0]],"id":23239795}],"con":true,"img":false}]}
{"op":"mcm","clk":"5322405945","pt":1646319849090,"mc":[{"id":"1.195532861","rc":[{"atb":[[2.6,18.43]],"id":37665265},{"atl":[[6.2,10],[5.3,2.5],[6,8],[5.7,5]],"id":41529436}],"con":true,"img":false}]}
{"op":"mcm","clk":"5322405956","pt":1646319849195,"mc":[{"id":"1.195532861","rc":[{"atl":[[6.2,0]],"id":28791247},{"atb":[[2.3,0],[2.22,0],[2.38,0]],"id":37665265},{"atl":[[6.2,15.53],[5.3,7.5],[5.2,5.71]],"id":41529436}],"con":true,"img":false}]}
{"op":"mcm","clk":"5322405966","pt":1646319849297,"mc":[{"id":"1.195532861","rc":[{"atl":[[5.8,18.5]],"id":41529436}],"con":true,"img":false}]}
{"op":"mcm","clk":"5322405975","pt":1646319849403,"mc":[{"id":"1.195532861","rc":[{"atl":[[5.1,5.71],[5.8,1.82],[5.3,2.5]],"id":41529436}],"con":true,"img":false}]}
{"op":"mcm","clk":"5322405984","pt":1646319849508,"mc":[{"id":"1.195532861","rc":[{"atl":[[5,2.56],[6.2,10]],"id":41529436}],"con":true,"img":false}]}
{"op":"mcm","clk":"5322406085","pt":1646319850603,"mc":[{"id":"1.195532861","rc":[{"atl":[[6,0],[5.2,15.23]],"id":41529436},{"atl":[[4.4,6.84],[4.5,0]],"id":23239795}],"con":true,"img":false}]}
{"op":"mcm","clk":"5322406111","pt":1646319850809,"mc":[{"id":"1.195532861","rc":[{"atb":[[3.2,17.06],[3.25,24.01]],"id":39947224}],"con":true,"img":false}]}
{"op":"mcm","clk":"5322406123","pt":1646319851017,"mc":[{"id":"1.195532861","rc":[{"atb":[[1.68,0]],"id":42252553}],"con":true,"img":false}]}
{"op":"mcm","clk":"5322406133","pt":1646319851225,"mc":[{"id":"1.195532861","rc":[{"atb":[[2.06,6.19]],"id":28791247},{"atb":[[1.64,52.44],[1.6,88.86]],"id":42252553}],"con":true,"img":false}]}
{"op":"mcm","clk":"5322406167","pt":1646319851704,"mc":[{"id":"1.195532861","rc":[{"atb":[[1.59,92.69]],"id":42252553}],"con":true,"img":false}]}
{"op":"mcm","clk":"5322406179","pt":1646319851803,"mc":[{"id":"1.195532861","rc":[{"atb":[[2.06,15.03]],"id":28791247}],"con":true,"img":false}]}
{"op":"mcm","clk":"5322406191","pt":1646319851906,"mc":[{"id":"1.195532861","rc":[{"atb":[[1.59,74.07]],"id":42252553}],"con":true,"img":false}]}
{"op":"mcm","clk":"5322406197","pt":1646319852009,"mc":[{"id":"1.195532861","rc":[{"atb":[[2.24,0]],"id":28791247}],"con":true,"img":false}]}
{"op":"mcm","clk":"5322406204","pt":1646319852114,"mc":[{"id":"1.195532861","rc":[{"atb":[[2.12,1.99]],"id":28791247}],"con":true,"img":false}]}
{"op":"mcm","clk":"5322406222","pt":1646319852322,"mc":[{"id":"1.195532861","rc":[{"atb":[[2.7,4]],"id":23239795}],"con":true,"img":false}]}
{"op":"mcm","clk":"5322406229","pt":1646319852429,"mc":[{"id":"1.195532861","rc":[{"atb":[[2.74,1.99]],"id":23239795}],"con":true,"img":false}]}
{"op":"mcm","clk":"5322406251","pt":1646319852696,"mc":[{"id":"1.195532861","rc":[{"atb":[[2.76,0]],"id":41529436}],"con":true,"img":false}]}
{"op":"mcm","clk":"5322406259","pt":1646319852799,"mc":[{"id":"1.195532861","rc":[{"atb":[[2.84,3.64]],"id":41529436}],"con":true,"img":false}]}
{"op":"mcm","clk":"5322406265","pt":1646319852905,"mc":[{"id":"1.195532861","rc":[{"atb":[[1.64,47.64]],"id":42252553}],"con":true,"img":false}]}
{"op":"mcm","clk":"5322406331","pt":1646319853581,"mc":[{"id":"1.195532861","rc":[{"atl":[[8.2,37.3]],"id":39947224}],"con":true,"img":false}]}
{"op":"mcm","clk":"5322406338","pt":1646319853688,"mc":[{"id":"1.195532861","rc":[{"atl":[[5,2.56],[4.2,30.46]],"id":28791247},{"atl":[[8.6,6.83]],"id":39947224},{"atl":[[4.8,6.33],[4.3,6.12],[5,2.56],[4.7,29.77]],"id":23239795}],"con":true,"img":false}]}
{"op":"mcm","clk":"5322406348","pt":1646319853791,"mc":[{"id":"1.195532861","rc":[{"atl":[[3.95,3.2]],"id":28791247},{"atl":[[7.6,9.04]],"id":39947224},{"atl":[[5.2,35.59],[6.6,17.86]],"id":41529436},{"atl":[[5.1,4.9],[4.2,3.82]],"id":23239795}],"con":true,"img":false}]}
{"op":"mcm","clk":"5322406355","pt":1646319853897,"mc":[{"id":"1.195532861","rc":[{"atl":[[3.9,2.25]],"id":28791247},{"atl":[[8,3.82],[7.4,9.89]],"id":39947224},{"atl":[[4.7,25.98]],"id":23239795}],"con":true,"img":false}]}
{"op":"mcm","clk":"5322406366","pt":1646319854001,"mc":[{"id":"1.195532861","rc":[{"atl":[[4.1,0],[3.9,5.45],[4.7,0]],"id":28791247},{"atl":[[8,0]],"id":39947224}],"con":true,"img":false}]}
{"op":"mcm","clk":"5322406373","pt":1646319854102,"mc":[{"id":"1.195532861","rc":[{"atl":[[8.2,41.55]],"id":39947224},{"atl":[[5.1,0]],"id":23239795}],"con":true,"img":false}]}
{"op":"mcm","clk":"5322406382","pt":1646319854304,"mc":[{"id":"1.195532861","rc":[{"atl":[[8.2,37.3]],"id":39947224},{"atl":[[4.8,2.8]],"id":23239795}],"con":true,"img":false}]}
{"op":"mcm","clk":"5322406473","pt":1646319855295,"mc":[{"id":"1.195532861","rc":[{"atl":[[4,15.44]],"id":28791247},{"atl":[[7.8,7.82]],"id":39947224}],"con":true,"img":false}]}
{"op":"mcm","clk":"5322406481","pt":1646319855395,"mc":[{"id":"1.195532861","rc":[{"atl":[[4.3,5.25]],"id":28791247}],"con":true,"img":false}]}
{"op":"mcm","clk":"5322406499","pt":1646319855603,"mc":[{"id":"1.195532861","rc":[{"atl":[[4.3,0]],"id":28791247}],"con":true,"img":false}]}
{"op":"mcm","clk":"5322406513","pt":1646319855807,"mc":[{"id":"1.195532861","rc":[{"atl":[[2.82,54.95]],"id":42252553}],"con":true,"img":false}]}
{"op":"mcm","clk":"5322406531","pt":1646319856016,"mc":[{"id":"1.195532861","rc":[{"atb":[[3.2,21.26]],"id":39947224},{"atb":[[1.64,0]],"id":42252553},{"atl":[[3.35,0],[3,0],[3.55,0],[4.4,0],[3.75,0],[2.92,8.1],[3.2,0]],"id":42252553}],"con":true,"img":false}]}
{"op":"mcm","clk":"5322406544","pt":1646319856224,"mc":[{"id":"1.195532861","rc":[{"atb":[[3.2,17.06]],"id":39947224},{"atl":[[2.92,0]],"id":42252553}],"con":true,"img":false}]}
{"op":"mcm","clk":"5322406569","pt":1646319856487,"mc":[{"id":"1.195532861","rc":[{"atb":[[2.26,0]],"id":28791247},{"atb":[[2.72,8.62],[2.66,5.9]],"id":23239795}],"con":true,"img":false}]}
{"op":"mcm","clk":"5322406575","pt":1646319856592,"mc":[{"id":"1.195532861","rc":[{"atb":[[2.04,40.96]],"id":28791247},{"atb":[[2.62,2.38],[2.68,25.24]],"id":23239795}],"con":true,"img":false}]}
{"op":"mcm","clk":"5322406584","pt":1646319856695,"mc":[{"id":"1.195532861","rc":[{"atb":[[2.14,1.65]],"id":28791247},{"atb":[[2.76,1.65],[2.7,0]],"id":23239795}],"con":true,"img":false}]}
{"op":"mcm","clk":"5322406606","pt":1646319857006,"mc":[{"id":"1.195532861","rc":[{"atb":[[2.66,0]],"id":23239795}],"con":true,"img":false}]}
{"op":"mcm","clk":"5322406679","pt":1646319857896,"mc":[{"id":"1.195532861","rc":[{"atb":[[2.06,94.34]],"id":37665265},{"atl":[[5.1,59.07]],"id":37665265},{"atb":[[2.46,68.49]],"id":23239795},{"atl":[[4.8,29.12]],"id":23239795}],"con":true,"img":false}]}
{"op":"mcm","clk":"5322406704","pt":1646319858208,"mc":[{"id":"1.195532861","rc":[{"atb":[[1.59,184.61],[1.6,7.05]],"id":42252553}],"con":true,"img":false}]}
{"op":"mcm","clk":"5322406760","pt":1646319858939,"mc":[{"id":"1.195532861","rc":[{"atb":[[2.84,1.65]],"id":41529436}],"con":true,"img":false}]}
{"op":"mcm","clk":"5322406768","pt":1646319858996,"mc":[{"id":"1.195532861","rc":[{"atb":[[2.76,1.99]],"id":41529436},{"atb":[[1.6,0]],"id":42252553},{"atl":[[2.78,33.83]],"id":42252553}],"con":true,"img":false}]}
{"op":"mcm","clk":"5322406774","pt":1646319859098,"mc":[{"id":"1.195532861","rc":[{"atl":[[2.72,46.51]],"id":42252553}],"con":true,"img":false}]}
{"op":"mcm","clk":"5322406779","pt":1646319859209,"mc":[{"id":"1.195532861","rc":[{"atl":[[2.74,2.12],[2.78,139.14],[2.94,0],[2.7,47.66]],"id":42252553}],"con":true,"img":false}]}
{"op":"mcm","clk":"5322406788","pt":1646319859308,"mc":[{"id":"1.195532861","rc":[{"atl":[[2.76,0]],"id":42252553}],"con":true,"img":false}]}
{"op":"mcm","clk":"5322406807","pt":1646319859616,"mc":[{"id":"1.195532861","rc":[{"atb":[[1.67,0],[1.62,2.15]],"id":42252553}],"con":true,"img":false}]}
{"op":"mcm","clk":"5322406814","pt":1646319859722,"mc":[{"id":"1.195532861","rc":[{"atb":[[1.59,110.54],[1.55,181.82],[1.62,48.23]],"id":42252553}],"con":true,"img":false}]}
{"op":"mcm","clk":"5322406835","pt":1646319859930,"mc":[{"id":"1.195532861","rc":[{"atb":[[1.02,0]],"id":42252553}],"con":true,"img":false}]}
{"op":"mcm","clk":"5322406844","pt":1646319860031,"mc":[{"id":"1.195532861","rc":[{"atb":[[1.63,1.99]],"id":42252553}],"con":true,"img":false}]}
{"op":"mcm","clk":"5322406862","pt":1646319860241,"mc":[{"id":"1.195532861","rc":[{"atb":[[2.76,0]],"id":41529436}],"con":true,"img":false}]}
{"op":"mcm","clk":"5322406873","pt":1646319860296,"mc":[{"id":"1.195532861","rc":[{"atb":[[2.84,3.64]],"id":41529436}],"con":true,"img":false}]}
{"op":"mcm","clk":"5322406881","pt":1646319860401,"mc":[{"id":"1.195532861","rc":[{"atb":[[1.98,0],[1.96,0],[1.94,0]],"id":37665265},{"atb":[[1.99,0]],"id":23239795},{"atl":[[5.9,0],[5.5,0],[5.7,0]],"id":23239795}],"con":true,"img":false}]}
{"op":"mcm","clk":"5322406942","pt":1646319861332,"mc":[{"id":"1.195532861","rc":[{"atl":[[5.1,26.83],[4.9,63.9]],"id":37665265}],"con":true,"img":false}]}
{"op":"mcm","clk":"5322406956","pt":1646319861436,"mc":[{"id":"1.195532861","rc":[{"atb":[[2.46,68.49]],"id":41529436},{"atl":[[5.4,22.73]],"id":41529436}],"con":true,"img":false}]}
{"op":"mcm","clk":"5322406977","pt":1646319861597,"mc":[{"id":"1.195532861","rc":[{"atl":[[4.6,15.47]],"id":37665265}],"con":true,"img":false}]}
{"op":"mcm","clk":"5322406983","pt":1646319861700,"mc":[{"id":"1.195532861","rc":[{"atl":[[4.8,12.09],[4.5,3.25],[4.7,29.97]],"id":37665265}],"con":true,"img":false}]}
{"op":"mcm","clk":"5322406994","pt":1646319861805,"mc":[{"id":"1.195532861","rc":[{"atl":[[4.8,0]],"id":37665265}],"con":true,"img":false}]}
{"op":"mcm","clk":"5322406999","pt":1646319861911,"mc":[{"id":"1.195532861","rc":[{"atl":[[4.7,40.78]],"id":37665265},{"atl":[[7.4,0],[6.6,0],[7,0]],"id":41529436},{"atl":[[2.74,25.11]],"id":42252553}],"con":true,"img":false}]}
{"op":"mcm","clk":"5322407009","pt":1646319862012,"mc":[{"id":"1.195532861","rc":[{"atb":[[2,4.24]],"id":28791247}],"con":true,"img":false}]}
{"op":"mcm","clk":"5322407024","pt":1646319862216,"mc":[{"id":"1.195532861","rc":[{"atb":[[2,0]],"id":28791247}],"con":true,"img":false}]}
{"op":"mcm","clk":"5322407055","pt":1646319862636,"mc":[{"id":"1.195532861","rc":[{"atl":[[2.84,19.32]],"id":42252553}],"con":true,"img":false}]}
{"op":"mcm","clk":"5322407068","pt":1646319862798,"mc":[{"id":"1.195532861","rc":[{"atl":[[2.84,0]],"id":42252553}],"con":true,"img":false}]}
{"op":"mcm","clk":"5322407077","pt":1646319862902,"mc":[{"id":"1.195532861","rc":[{"atb":[[1.56,65.19]],"id":42252553}],"con":true,"img":false}]}
{"op":"mcm","clk":"5322407106","pt":1646319863316,"mc":[{"id":"1.195532861","rc":[{"atb":[[2.84,1.65]],"id":41529436}],"con":true,"img":false}]}
{"op":"mcm","clk":"5322407112","pt":1646319863417,"mc":[{"id":"1.195532861","rc":[{"atb":[[2.76,1.99]],"id":41529436}],"con":true,"img":false}]}
{"op":"mcm","clk":"5322407183","pt":1646319864245,"mc":[{"id":"1.195532861","rc":[{"atl":[[4.9,3.41]],"id":41529436}],"con":true,"img":false}]}
{"op":"mcm","clk":"5322407195","pt":1646319864401,"mc":[{"id":"1.195532861","rc":[{"atl":[[4.8,6.21],[5.1,0],[5.2,32.22]],"id":41529436}],"con":true,"img":false}]}
{"op":"mcm","clk":"5322407202","pt":1646319864509,"mc":[{"id":"1.195532861","rc":[{"atl":[[5.3,8.19]],"id":41529436}],"con":true,"img":false}]}
{"op":"mcm","clk":"5322407207","pt":1646319864610,"mc":[{"id":"1.195532861","rc":[{"atl":[[5,12.56]],"id":41529436}],"con":true,"img":false}]}
{"op":"mcm","clk":"5322407213","pt":1646319864713,"mc":[{"id":"1.195532861","rc":[{"atl":[[4.1,13.37]],"id":28791247}],"con":true,"img":false}]}
{"op":"mcm","clk":"5322407236","pt":1646319864923,"mc":[{"id":"1.195532861","rc":[{"atl":[[5.3,2.5]],"id":41529436}],"con":true,"img":false}]}
{"op":"mcm","clk":"5322407247","pt":1646319865128,"mc":[{"id":"1.195532861","rc":[{"atb":[[1.56,187.55],[1.59,0]],"id":42252553}],"con":true,"img":false}]}
{"op":"mcm","clk":"5322407328","pt":1646319865913,"mc":[{"id":"1.195532861","rc":[{"atl":[[4.1,0]],"id":28791247}],"con":true,"img":false}]}
{"op":"mcm","clk":"5322407341","pt":1646319866126,"mc":[{"id":"1.195532861","rc":[{"atb":[[2,100]],"id":28791247},{"atl":[[4.2,49.21]],"id":28791247},{"atb":[[2.74,57.47]],"id":39947224},{"atl":[[8.2,45.63]],"id":39947224}],"con":true,"img":false}]}
{"op":"mcm","clk":"5322407403","pt":1646319866908,"mc":[{"id":"1.195532861","rc":[{"atb":[[2.66,10.61],[2.68,17.59]],"id":23239795},{"atl":[[4.6,40.18],[4.4,3.42]],"id":23239795}],"con":true,"img":false}]}
{"op":"mcm","clk":"5322407512","pt":1646319868523,"mc":[{"id":"1.195532861","rc":[{"atl":[[7.8,45.68]],"id":39947224}],"con":true,"img":false}]}
{"op":"mcm","clk":"5322407520","pt":1646319868627,"mc":[{"id":"1.195532861","rc":[{"atl":[[4,33.64],[4.2,35.07]],"id":28791247},{"atl":[[8.2,15.63]],"id":39947224},{"atb":[[2.42,105.63]],"id":23239795},{"atl":[[5,40.06],[4.4,23.3],[4.2,9.25],[4.7,0]],"id":23239795}],"con":true,"img":false}]}
{"op":"mcm","clk":"5322407533","pt":1646319868727,"mc":[{"id":"1.195532861","rc":[{"atl":[[3.85,4.02]],"id":28791247},{"atl":[[7.2,12.9]],"id":39947224},{"atl":[[5,33.96],[5.2,11.86]],"id":41529436},{"atl":[[4.3,0]],"id":23239795}],"con":true,"img":false}]}
{"op":"mcm","clk":"5322407541","pt":1646319868831,"mc":[{"id":"1.195532861","rc":[{"atl":[[3.8,6.41],[3.95,0],[3.9,2.25]],"id":28791247},{"atl":[[7.6,0],[7,12.35]],"id":39947224}],"con":true,"img":false}]}
{"op":"mcm","clk":"5322407549","pt":1646319868936,"mc":[{"id":"1.195532861","rc":[{"atl":[[7.4,2.19]],"id":39947224}],"con":true,"img":false}]}
{"op":"mcm","clk":"5322407560","pt":1646319869143,"mc":[{"id":"1.195532861","rc":[{"atl":[[4.1,4.51],[3.9,16.04]],"id":28791247},{"atl":[[7.4,8.44]],"id":39947224},{"atb":[[2.02,0]],"id":23239795}],"con":true,"img":false}]}
{"op":"mcm","clk":"5322407566","pt":1646319869248,"mc":[{"id":"1.195532861","rc":[{"atl":[[4.3,5.51]],"id":28791247},{"atl":[[7.8,39.8]],"id":39947224}],"con":true,"img":false}]}
{"op":"mcm","clk":"5322407572","pt":1646319869305,"mc":[{"id":"1.195532861","rc":[{"atl":[[4.1,0]],"id":28791247}],"con":true,"img":false}]}
{"op":"mcm","clk":"5322407579","pt":1646319869407,"mc":[{"id":"1.195532861","rc":[{"atl":[[4.3,0]],"id":28791247}],"con":true,"img":false}]}
{"op":"mcm","clk":"5322407725","pt":1646319871309,"mc":[{"id":"1.195532861","rc":[{"atb":[[2.74,15.39]],"id":23239795}],"con":true,"img":false}]}
{"op":"mcm","clk":"5322407741","pt":1646319871515,"mc":[{"id":"1.195532861","rc":[{"atb":[[2.72,2.5]],"id":23239795}],"con":true,"img":false}]}
{"op":"mcm","clk":"5322407779","pt":1646319872031,"mc":[{"id":"1.195532861","rc":[{"atb":[[1.56,65.19],[1.55,304.18]],"id":42252553}],"con":true,"img":false}]}
{"op":"mcm","clk":"5322407804","pt":1646319872344,"mc":[{"id":"1.195532861","rc":[{"atb":[[3.2,22.18],[3.55,0],[3.25,2.5],[3.05,22.47]],"id":39947224},{"atl":[[4.6,43.25],[4.7,13.75]],"id":37665265},{"atb":[[1.62,2.15],[1.61,5.71]],"id":42252553}],"con":true,"img":false}]}
{"op":"mcm","clk":"5322407817","pt":1646319872551,"mc":[{"id":"1.195532861","rc":[{"atb":[[3.2,0],[3.3,15.59],[3.05,54.03]],"id":39947224},{"atb":[[2.02,147.06]],"id":37665265},{"atl":[[4.9,79.28]],"id":37665265},{"atl":[[2.78,172.85]],"id":42252553}],"con":true,"img":false}]}
{"op":"mcm","clk":"5322407852","pt":1646319872924,"mc":[{"id":"1.195532861","rc":[{"atb":[[1.56,154.71],[1.55,181.82],[1.61,0]],"id":42252553}],"con":true,"img":false}]}
{"op":"mcm","clk":"5322407913","pt":1646319873801,"mc":[{"id":"1.195532861","rc":[{"atb":[[2.66,0],[2.68,28.2]],"id":23239795},{"atl":[[4.5,28.57],[4.6,14.2]],"id":23239795}],"con":true,"img":false}]}
{"op":"mcm","clk":"5322407921","pt":1646319873904,"mc":[{"id":"1.195532861","rc":[{"atl":[[2.68,47.62]],"id":42252553}],"con":true,"img":false}]}
{"op":"mcm","clk":"5322407933","pt":1646319873959,"mc":[{"id":"1.195532861","rc":[{"atl":[[7.6,15.15],[7,2.46]],"id":39947224},{"atl":[[2.72,0],[2.74,147.33]],"id":42252553}],"con":true,"img":false}]}
{"op":"mcm","clk":"5322407939","pt":1646319874059,"mc":[{"id":"1.195532861","rc":[{"atl":[[2.66,2.29],[2.78,56.18]],"id":42252553}],"con":true,"img":false}]}
{"op":"mcm","clk":"5322407947","pt":1646319874163,"mc":[{"id":"1.195532861","rc":[{"atl":[[2.66,49.91],[2.7,2.21]],"id":42252553}],"con":true,"img":false}]}
{"op":"mcm","clk":"5322408019","pt":1646319875204,"mc":[{"id":"1.195532861","rc":[{"atb":[[2.42,105.63]],"id":41529436},{"atl":[[5.2,26.15]],"id":41529436}],"con":true,"img":false}]}
{"op":"mcm","clk":"5322408031","pt":1646319875364,"mc":[{"id":"1.195532861","rc":[{"atb":[[3.6,0]],"id":39947224}],"con":true,"img":false}]}
{"op":"mcm","clk":"5322408038","pt":1646319875470,"mc":[{"id":"1.195532861","rc":[{"atb":[[3.35,1.99]],"id":39947224},{"atl":[[4.5,103.22],[4.4,3.42]],"id":23239795}],"con":true,"img":false}]}
{"op":"mcm","clk":"5322408050","pt":1646319875677,"mc":[{"id":"1.195532861","rc":[{"atb":[[2.76,0]],"id":41529436}],"con":true,"img":false}]}
{"op":"mcm","clk":"5322408056","pt":1646319875781,"mc":[{"id":"1.195532861","rc":[{"atb":[[2.84,3.64]],"id":41529436}],"con":true,"img":false}]}
{"op":"mcm","clk":"5322408073","pt":1646319875988,"mc":[{"id":"1.195532861","rc":[{"atl":[[4.9,28.32]],"id":37665265}],"con":true,"img":false}]}
{"op":"mcm","clk":"5322408083","pt":1646319876092,"mc":[{"id":"1.195532861","rc":[{"atl":[[4.7,66.33]],"id":37665265}],"con":true,"img":false}]}
{"op":"mcm","clk":"5322408095","pt":1646319876298,"mc":[{"id":"1.195532861","rc":[{"atl":[[2.7,25.74]],"id":42252553}],"con":true,"img":false}]}
{"op":"mcm","clk":"5322408102","pt":1646319876400,"mc":[{"id":"1.195532861","rc":[{"atl":[[4.4,14.71]],"id":37665265}],"con":true,"img":false}]}
{"op":"mcm","clk":"5322408110","pt":1646319876503,"mc":[{"id":"1.195532861","rc":[{"atl":[[4.8,4.04]],"id":37665265}],"con":true,"img":false}]}
{"op":"mcm","clk":"5322408115","pt":1646319876607,"mc":[{"id":"1.195532861","rc":[{"atl":[[4.3,3.61],[4.6,38.89],[4.7,55.52]],"id":37665265}],"con":true,"img":false}]}
{"op":"mcm","clk":"5322408122","pt":1646319876659,"mc":[{"id":"1.195532861","rc":[{"atl":[[4.8,0]],"id":37665265},{"atb":[[2.48,3.34]],"id":41529436}],"con":true,"img":false}]}
{"op":"mcm","clk":"5322408135","pt":1646319876866,"mc":[{"id":"1.195532861","rc":[{"atb":[[2.48,0]],"id":41529436}],"con":true,"img":false}]}
{"op":"mcm","clk":"5322408150","pt":1646319877075,"mc":[{"id":"1.195532861","rc":[{"atb":[[2.86,21.51]],"id":39947224},{"atl":[[4.5,14.68],[4.6,27.78]],"id":37665265},{"atb":[[2.84,1.65]],"id":41529436},{"atb":[[1.54,0],[1.5,80]],"id":42252553},{"atl":[[4.6,3.09],[4.7,10.81]],"id":23239795}],"con":true,"img":false}]}
{"op":"mcm","clk":"5322408160","pt":1646319877177,"mc":[{"id":"1.195532861","rc":[{"atb":[[2.76,1.99]],"id":41529436}],"con":true,"img":false}]}
{"op":"mcm","clk":"5322408175","pt":1646319877385,"mc":[{"id":"1.195532861","rc":[{"atl":[[7.6,0],[7.8,54.51]],"id":39947224},{"atb":[[1.52,0]],"id":42252553},{"atl":[[4.6,14.2]],"id":23239795}],"con":true,"img":false}]}
{"op":"mcm","clk":"5322408290","pt":1646319878891,"mc":[{"id":"1.195532861","rc":[{"atl":[[4.7,4.05]],"id":41529436},{"atb":[[1.56,65.19],[1.55,303.73]],"id":42252553}],"con":true,"img":false}]}
{"op":"mcm","clk":"5322408299","pt":1646319878993,"mc":[{"id":"1.195532861","rc":[{"atl":[[4.8,2.8],[4.9,0],[4.6,3.09],[5.5,5.35]],"id":41529436}],"con":true,"img":false}]}
{"op":"mcm","clk":"5322408308","pt":1646319879099,"mc":[{"id":"1.195532861","rc":[{"atl":[[4.6,7.14]],"id":41529436}],"con":true,"img":false}]}
{"op":"mcm","clk":"5322408319","pt":1646319879201,"mc":[{"id":"1.195532861","rc":[{"atl":[[4.6,3.09],[4.7,10.23]],"id":41529436}],"con":true,"img":false}]}
{"op":"mcm","clk":"5322408327","pt":1646319879304,"mc":[{"id":"1.195532861","rc":[{"atl":[[4.3,13.66]],"id":41529436}],"con":true,"img":false}]}
{"op":"mcm","clk":"5322408335","pt":1646319879407,"mc":[{"id":"1.195532861","rc":[{"atl":[[4.8,13.33],[4.6,7.14],[5.5,0],[4.7,4.05]],"id":41529436}],"con":true,"img":false}]}
