{"op":"mcm","clk":"5351767852","pt":1646175389015,"mc":[{"id":"1.195453767","marketDefinition":{"bspMarket":true,"turnInPlayEnabled":false,"persistenceEnabled":false,"marketBaseRate":7.0,"eventId":"31272499","eventTypeId":"4339","numberOfWinners":2,"bettingType":"ODDS","marketType":"PLACE","marketTime":"2022-03-02T09:14:00.000Z","suspendTime":"2022-03-02T09:14:00.000Z","bspReconciled":false,"complete":true,"inPlay":false,"crossMatching":false,"runnersVoidable":false,"numberOfActiveRunners":7,"betDelay":0,"status":"OPEN","runners":[{"status":"ACTIVE","sortPriority":1,"id":43167133,"name":"1. Sunset Sienna"},{"status":"ACTIVE","sortPriority":2,"id":42154339,"name":"3. Foxy One"},{"status":"ACTIVE","sortPriority":3,"id":42688787,"name":"4. Double Espresso"},{"status":"ACTIVE","sortPriority":4,"id":41818763,"name":"5. Dr Kammi"},{"status":"ACTIVE","sortPriority":5,"id":39637621,"name":"6. Katara Love"},{"status":"ACTIVE","sortPriority":6,"id":42162698,"name":"7. Black Petunia"},{"status":"ACTIVE","sortPriority":7,"id":41910350,"name":"8. Big Time Money"}],"regulators":["MR_INT"],"venue":"Rockhampton","countryCode":"AU","discountAllowed":true,"timezone":"Australia/Queensland","openDate":"2022-03-02T08:34:00.000Z","version":4382437865,"name":"To Be Placed","eventName":"Rockhampton (AUS) 2nd Mar"},"rc":[],"con":true,"img":false}]}
{"op":"mcm","clk":"5351829775","pt":1646176640937,"mc":[{"id":"1.195453767","rc":[{"atb":[[4.5,34.52],[5,30.21],[5.5,13.42]],"id":42162698},{"atl":[[18.5,0.69],[85,0.28],[170,0.28],[44,0.56],[27,0.46]],"id":42162698},{"spn":12.0,"spf":"NaN","id":42162698},{"atb":[[2.06,57],[1.98,123.31],[1.93,129.94]],"id":39637621},{"atl":[[16,3.22],[6.4,2.23],[11,2.41],[5.2,2.87],[8.4,3.26]],"id":39637621},{"spn":3.63,"spf":"NaN","id":39637621},{"atb":[[4,40.28],[4.5,17.26],[3.75,43.94]],"id":41910350},{"atl":[[16,0.8],[34,0.73],[22,0.57],[60,0.4],[120,0.4]],"id":41910350},{"spn":10.25,"spf":"NaN","id":41910350},{"atb":[[2,120.84],[1.95,127.2],[2.1,54.93]],"id":41818763},{"atl":[[16.5,3.11],[8.6,3.17],[5.3,2.8],[11.5,2.3],[6.6,2.15]],"id":41818763},{"spn":3.7,"spf":"NaN","id":41818763},{"atb":[[2.8,67.13],[2.9,31.8],[2.7,71.08]],"id":43167133},{"atl":[[19.5,1.3],[9.8,1.37],[7.8,1.77],[14.5,1.79],[29,1.72]],"id":43167133},{"spn":5.35,"spf":"NaN","id":43167133},{"atb":[[1.2,604.24],[1.25,241.69],[1.15,805.66]],"id":42154339},{"atl":[[3.6,18.59],[3.1,11.5],[2.44,8.39],[2.64,7.37],[2.84,13.13]],"id":42154339},{"spn":1.84,"spf":"NaN","id":42154339},{"atb":[[2.4,43.16],[2.3,92.96],[2.2,100.7]],"id":42688787},{"atl":[[9.6,2.8],[19,2.68],[5.8,2.52],[7.6,1.82],[14,1.86]],"id":42688787},{"spn":4.1,"spf":"NaN","id":42688787}],"con":true,"img":false}]}
{"op":"mcm","clk":"5351831304","pt":1646176678182,"mc":[{"id":"1.195453767","rc":[{"atb":[[4.5,0],[5,0],[5.5,0]],"id":42162698},{"atl":[[18.5,0],[85,0],[170,0],[44,0],[27,0]],"id":42162698},{"atb":[[2.06,0],[1.98,0],[1.93,0]],"id":39637621},{"atl":[[16,0],[6.4,0],[11,0],[5.2,0],[8.4,0]],"id":39637621},{"atb":[[4,0],[4.5,0],[3.75,0]],"id":41910350},{"atl":[[16,0],[34,0],[22,0],[60,0],[120,0]],"id":41910350},{"atb":[[2,0],[1.95,0],[2.1,0]],"id":41818763},{"atl":[[16.5,0],[8.6,0],[5.3,0],[11.5,0],[6.6,0]],"id":41818763},{"atb":[[2.8,0],[2.9,0],[2.7,0]],"id":43167133},{"atl":[[19.5,0],[9.8,0],[7.8,0],[14.5,0],[29,0]],"id":43167133},{"atb":[[1.2,0],[1.25,0],[1.15,0]],"id":42154339},{"atl":[[3.6,0],[3.1,0],[2.44,0],[2.64,0],[2.84,0]],"id":42154339},{"atb":[[2.4,0],[2.3,0],[2.2,0]],"id":42688787},{"atl":[[9.6,0],[19,0],[5.8,0],[7.6,0],[14,0]],"id":42688787}],"con":true,"img":false}]}
{"op":"mcm","clk":"5351832836","pt":1646176717930,"mc":[{"id":"1.195453767","rc":[{"atb":[[4.1,19.49],[3.8,43.16],[3.55,47.39]],"id":42162698},{"atl":[[19.5,0.65],[95,0.51],[48,0.51],[14.5,0.89],[29,0.86]],"id":42162698},{"spn":9.3,"spf":"NaN","id":42162698},{"atb":[[1.8,151.06],[1.85,142.17],[1.9,67.13]],"id":39637621},{"atl":[[4,4.02],[8,3.45],[5,3.02],[10,5.37],[6,4.83]],"id":39637621},{"spn":2.95,"spf":"NaN","id":39637621},{"atb":[[2.06,57],[1.98,123.31],[1.93,129.94]],"id":41818763},{"atl":[[16,3.22],[6.4,2.23],[11,2.41],[5.2,2.87],[8.4,3.26]],"id":41818763},{"spn":3.63,"spf":"NaN","id":41818763},{"atb":[[5,30.21],[5.5,26.85],[6,12.08]],"id":41910350},{"atl":[[19.5,0.65],[95,0.25],[190,0.25],[48,0.51],[29,0.43]],"id":41910350},{"spn":12.75,"spf":"NaN","id":41910350},{"atb":[[2.88,64.28],[2.98,30.51],[2.78,67.89]],"id":43167133},{"atl":[[32,1.55],[10.5,1.27],[21,1.2],[8.2,1.67],[15.5,1.66]],"id":43167133},{"spn":5.59,"spf":"NaN","id":43167133},{"atb":[[1.2,604.24],[1.25,483.39],[1.3,201.41]],"id":42154339},{"atl":[[2.54,7.84],[3.85,16.96],[2.74,6.94],[3.35,10.28],[2.94,12.46]],"id":42154339},{"spn":1.92,"spf":"NaN","id":42154339},{"atb":[[2.4,86.32],[2.5,80.56],[2.6,37.76]],"id":42688787},{"atl":[[6.2,2.32],[10.5,2.54],[21,2.41],[8.2,1.67],[15.5,1.66]],"id":42688787},{"spn":4.4,"spf":"NaN","id":42688787}],"con":true,"img":false}]}
{"op":"mcm","clk":"5351835002","pt":1646176767877,"mc":[{"id":"1.195453767","rc":[{"atb":[[4.1,0],[3.8,0],[3.55,0]],"id":42162698},{"atl":[[19.5,0],[95,0],[48,0],[14.5,0],[29,0]],"id":42162698},{"atb":[[1.8,0],[1.85,0],[1.9,0]],"id":39637621},{"atl":[[4,0],[8,0],[5,0],[10,0],[6,0]],"id":39637621},{"atb":[[5,0],[5.5,0],[6,0]],"id":41910350},{"atl":[[19.5,0],[95,0],[190,0],[48,0],[29,0]],"id":41910350},{"atb":[[2.06,0],[1.98,0],[1.93,0]],"id":41818763},{"atl":[[16,0],[6.4,0],[11,0],[5.2,0],[8.4,0]],"id":41818763},{"atb":[[2.88,0],[2.98,0],[2.78,0]],"id":43167133},{"atl":[[32,0],[10.5,0],[21,0],[8.2,0],[15.5,0]],"id":43167133},{"atb":[[1.2,0],[1.25,0],[1.3,0]],"id":42154339},{"atl":[[2.54,0],[3.85,0],[2.74,0],[3.35,0],[2.94,0]],"id":42154339},{"atb":[[2.4,0],[2.5,0],[2.6,0]],"id":42688787},{"atl":[[6.2,0],[10.5,0],[21,0],[8.2,0],[15.5,0]],"id":42688787}],"con":true,"img":false}]}
{"op":"mcm","clk":"5351835816","pt":1646176785835,"mc":[{"id":"1.195453767","rc":[{"atb":[[4.1,19.49],[3.8,43.16],[3.55,47.39]],"id":42162698},{"atl":[[19.5,0.65],[95,0.51],[48,0.51],[14.5,0.89],[29,0.86]],"id":42162698},{"atb":[[1.8,151.06],[1.85,142.17],[1.9,67.13]],"id":39637621},{"atl":[[4,4.02],[8,3.45],[5,3.02],[10,5.37],[6,4.83]],"id":39637621},{"atb":[[4.1,19.49],[3.8,43.16],[3.55,47.39]],"id":41910350},{"atl":[[19.5,0.65],[95,0.51],[48,0.51],[14.5,0.89],[29,0.86]],"id":41910350},{"spn":9.3,"spf":"NaN","id":41910350},{"atb":[[2.06,114],[1.98,123.31],[2.16,52.09]],"id":41818763},{"atl":[[17,3.02],[6.8,2.08],[12,2.19],[8.8,3.09],[5.4,2.74]],"id":41818763},{"spn":3.78,"spf":"NaN","id":41818763},{"atb":[[2.9,63.6],[3,60.42],[3.25,26.85]],"id":43167133},{"atl":[[16,1.61],[34,1.46],[11,1.2],[22,1.14],[8.4,1.63]],"id":43167133},{"spn":5.82,"spf":"NaN","id":43167133},{"atb":[[1.2,604.24],[1.25,483.39],[1.3,201.41]],"id":42154339},{"atl":[[2.54,7.84],[3.85,16.96],[2.74,6.94],[3.35,10.28],[2.94,12.46]],"id":42154339},{"atb":[[2.4,86.32],[2.5,80.56],[2.6,37.76]],"id":42688787},{"atl":[[6.2,2.32],[10.5,2.54],[21,2.41],[8.2,1.67],[15.5,1.66]],"id":42688787}],"con":true,"img":false}]}
{"op":"mcm","clk":"5352004161","pt":1646180202639,"mc":[{"id":"1.195453767","marketDefinition":{"bspMarket":true,"turnInPlayEnabled":false,"persistenceEnabled":false,"marketBaseRate":7.0,"eventId":"31272499","eventTypeId":"4339","numberOfWinners":2,"bettingType":"ODDS","marketType":"PLACE","marketTime":"2022-03-02T09:14:00.000Z","suspendTime":"2022-03-02T09:14:00.000Z","bspReconciled":false,"complete":true,"inPlay":false,"crossMatching":false,"runnersVoidable":false,"numberOfActiveRunners":7,"betDelay":0,"status":"OPEN","runners":[{"status":"ACTIVE","sortPriority":1,"id":43167133,"name":"1. Sunset Sienna"},{"status":"ACTIVE","sortPriority":2,"id":42154339,"name":"3. Foxy One"},{"status":"ACTIVE","sortPriority":3,"id":42688787,"name":"4. Double Espresso"},{"status":"ACTIVE","sortPriority":4,"id":41818763,"name":"5. Dr Kammi"},{"status":"ACTIVE","sortPriority":5,"id":39637621,"name":"6. Katara Love"},{"status":"ACTIVE","sortPriority":6,"id":42162698,"name":"7. Black Petunia"},{"status":"ACTIVE","sortPriority":7,"id":41910350,"name":"8. Big Time Money"}],"regulators":["MR_INT"],"venue":"Rockhampton","countryCode":"AU","discountAllowed":true,"timezone":"Australia/Queensland","openDate":"2022-03-02T08:34:00.000Z","version":4382437865,"name":"To Be Placed","eventName":"Rockhampton (AUS) 2nd Mar"},"rc":[{"atb":[[4.1,19.49],[3.8,43.16],[3.55,47.39]],"id":42162698},{"atl":[[19.5,0.65],[95,0.51],[48,0.51],[14.5,0.89],[29,0.86]],"id":42162698},{"spn":9.3,"spf":"NaN","id":42162698},{"atb":[[1.8,151.07],[1.85,142.19],[1.9,67.14]],"id":39637621},{"atl":[[4,4.02],[8,3.45],[5,3.02],[10,5.37],[6,4.83]],"id":39637621},{"spn":2.95,"spf":"NaN","id":39637621},{"atb":[[2.06,114.01],[1.98,123.32],[2.16,52.09]],"id":41818763},{"atl":[[17,3.02],[6.8,2.08],[12,2.19],[8.8,3.09],[5.4,2.74]],"id":41818763},{"spn":3.78,"spf":"NaN","id":41818763},{"atb":[[4.1,19.49],[3.8,43.16],[3.55,47.39]],"id":41910350},{"atl":[[19.5,0.65],[95,0.51],[48,0.51],[14.5,0.89],[29,0.86]],"id":41910350},{"spn":9.3,"spf":"NaN","id":41910350},{"atb":[[2.9,63.61],[3,60.43],[3.25,26.85]],"id":43167133},{"atl":[[16,1.61],[34,1.46],[11,1.2],[22,1.14],[8.4,1.63]],"id":43167133},{"spn":5.82,"spf":"NaN","id":43167133},{"atb":[[1.2,604.31],[1.25,483.44],[1.3,201.43]],"id":42154339},{"atl":[[2.54,7.85],[3.85,16.96],[2.74,6.94],[3.35,10.28],[2.94,12.46]],"id":42154339},{"spn":1.92,"spf":"NaN","id":42154339},{"atb":[[2.4,86.32],[2.5,80.57],[2.6,37.77]],"id":42688787},{"atl":[[6.2,2.32],[10.5,2.54],[21,2.41],[8.2,1.67],[15.5,1.66]],"id":42688787},{"spn":4.4,"spf":"NaN","id":42688787}],"con":true,"img":true}]}
{"op":"mcm","clk":"5352086372","pt":1646182161128,"mc":[{"id":"1.195453767","rc":[{"atb":[[4.1,0],[3.8,0],[3.55,0]],"id":42162698},{"atl":[[19.5,0],[95,0],[48,0],[14.5,0],[29,0]],"id":42162698},{"spn":"NaN","spf":"NaN","id":42162698},{"atb":[[1.8,0],[1.85,0],[1.9,0]],"id":39637621},{"atl":[[4,0],[8,0],[5,0],[10,0],[6,0]],"id":39637621},{"spn":"NaN","spf":"NaN","id":39637621},{"atb":[[2.06,0],[1.98,0],[2.16,0]],"id":41818763},{"atl":[[17,0],[6.8,0],[12,0],[8.8,0],[5.4,0]],"id":41818763},{"spn":"NaN","spf":"NaN","id":41818763},{"atb":[[4.1,19.49],[3.8,43.16],[3.55,47.39]],"id":41910350},{"atb":[[2.9,0],[3,0],[3.25,0]],"id":43167133},{"atl":[[16,0],[34,0],[11,0],[22,0],[8.4,0]],"id":43167133},{"spn":"NaN","spf":"NaN","id":43167133},{"atb":[[1.2,0],[1.25,0],[1.3,0]],"id":42154339},{"atl":[[2.54,0],[3.85,0],[2.74,0],[3.35,0],[2.94,0]],"id":42154339},{"spn":"NaN","spf":"NaN","id":42154339},{"atb":[[2.4,0],[2.5,0],[2.6,0]],"id":42688787},{"atl":[[6.2,0],[10.5,0],[21,0],[8.2,0],[15.5,0]],"id":42688787},{"spn":"NaN","spf":"NaN","id":42688787}],"con":true,"img":false}]}
{"op":"mcm","clk":"5352086552","pt":1646182166438,"mc":[{"id":"1.195453767","rc":[{"atb":[[4.3,18.31],[3.9,41.67],[3.65,45.6]],"id":42162698},{"atl":[[32,0.77],[21,0.6],[55,0.44],[110,0.44],[15.5,0.83]],"id":42162698},{"atb":[[1.7,172.65],[1.75,80.57],[1.65,185.94]],"id":39637621},{"atl":[[4,4.02],[8,6.9],[5,6.04],[6,4.83],[3.5,4.83]],"id":39637621},{"atb":[[2.06,114.01],[2.26,47.96],[2.16,104.19]],"id":41818763},{"atl":[[5.6,2.62],[7.2,1.94],[18,2.84],[9.2,2.94],[13,2.01]],"id":41818763},{"atb":[[3.4,50.35],[3.15,56.21],[3.65,22.8]],"id":43167133},{"atl":[[32,0.77],[10.5,1.27],[21,1.2],[55,0.89],[15.5,0.83]],"id":43167133},{"atb":[[1.2,604.31],[1.25,241.72],[1.15,805.74]],"id":42154339},{"atl":[[3.6,18.59],[3.1,11.5],[2.44,8.39],[2.64,7.37],[2.84,13.13]],"id":42154339},{"atb":[[2.8,67.14],[2.9,31.8],[2.7,71.09]],"id":42688787},{"atl":[[19.5,1.3],[9.8,1.37],[7.8,1.77],[14.5,1.79],[29,1.72]],"id":42688787}],"con":true,"img":false}]}
{"op":"mcm","clk":"5352146200","pt":1646183572654,"mc":[{"id":"1.195453767","marketDefinition":{"bspMarket":true,"turnInPlayEnabled":false,"persistenceEnabled":false,"marketBaseRate":7.0,"eventId":"31272499","eventTypeId":"4339","numberOfWinners":2,"bettingType":"ODDS","marketType":"PLACE","marketTime":"2022-03-02T09:14:00.000Z","suspendTime":"2022-03-02T09:14:00.000Z","bspReconciled":false,"complete":true,"inPlay":false,"crossMatching":false,"runnersVoidable":false,"numberOfActiveRunners":7,"betDelay":0,"status":"OPEN","runners":[{"status":"ACTIVE","sortPriority":1,"id":43167133,"name":"1. Sunset Sienna"},{"status":"ACTIVE","sortPriority":2,"id":42154339,"name":"3. Foxy One"},{"status":"ACTIVE","sortPriority":3,"id":42688787,"name":"4. Double Espresso"},{"status":"ACTIVE","sortPriority":4,"id":41818763,"name":"5. Dr Kammi"},{"status":"ACTIVE","sortPriority":5,"id":39637621,"name":"6. Katara Love"},{"status":"ACTIVE","sortPriority":6,"id":42162698,"name":"7. Black Petunia"},{"status":"ACTIVE","sortPriority":7,"id":41910350,"name":"8. Big Time Money"}],"regulators":["MR_INT"],"venue":"Rockhampton","countryCode":"AU","discountAllowed":true,"timezone":"Australia/Queensland","openDate":"2022-03-02T08:28:00.000Z","version":4382597826,"name":"To Be Placed","eventName":"Rockhampton (AUS) 2nd Mar"},"rc":[],"con":true,"img":false}]}
{"op":"mcm","clk":"5352154044","pt":1646183791128,"mc":[{"id":"1.195453767","marketDefinition":{"bspMarket":true,"turnInPlayEnabled":false,"persistenceEnabled":false,"marketBaseRate":7.0,"eventId":"31272499","eventTypeId":"4339","numberOfWinners":2,"bettingType":"ODDS","marketType":"PLACE","marketTime":"2022-03-02T09:08:00.000Z","suspendTime":"2022-03-02T09:08:00.000Z","bspReconciled":false,"complete":true,"inPlay":false,"crossMatching":false,"runnersVoidable":false,"numberOfActiveRunners":7,"betDelay":0,"status":"OPEN","runners":[{"status":"ACTIVE","sortPriority":1,"id":43167133,"name":"1. Sunset Sienna"},{"status":"ACTIVE","sortPriority":2,"id":42154339,"name":"3. Foxy One"},{"status":"ACTIVE","sortPriority":3,"id":42688787,"name":"4. Double Espresso"},{"status":"ACTIVE","sortPriority":4,"id":41818763,"name":"5. Dr Kammi"},{"status":"ACTIVE","sortPriority":5,"id":39637621,"name":"6. Katara Love"},{"status":"ACTIVE","sortPriority":6,"id":42162698,"name":"7. Black Petunia"},{"status":"ACTIVE","sortPriority":7,"id":41910350,"name":"8. Big Time Money"}],"regulators":["MR_INT"],"venue":"Rockhampton","countryCode":"AU","discountAllowed":true,"timezone":"Australia/Queensland","openDate":"2022-03-02T08:28:00.000Z","version":4382601692,"name":"To Be Placed","eventName":"Rockhampton (AUS) 2nd Mar"},"rc":[],"con":true,"img":false}]}
{"op":"mcm","clk":"5352238286","pt":1646185602675,"mc":[{"id":"1.195453767","marketDefinition":{"bspMarket":true,"turnInPlayEnabled":false,"persistenceEnabled":false,"marketBaseRate":7.0,"eventId":"31272499","eventTypeId":"4339","numberOfWinners":2,"bettingType":"ODDS","marketType":"PLACE","marketTime":"2022-03-02T09:08:00.000Z","suspendTime":"2022-03-02T09:08:00.000Z","bspReconciled":false,"complete":true,"inPlay":false,"crossMatching":false,"runnersVoidable":false,"numberOfActiveRunners":7,"betDelay":0,"status":"OPEN","runners":[{"status":"ACTIVE","sortPriority":1,"id":43167133,"name":"1. Sunset Sienna"},{"status":"ACTIVE","sortPriority":2,"id":42154339,"name":"3. Foxy One"},{"status":"ACTIVE","sortPriority":3,"id":42688787,"name":"4. Double Espresso"},{"status":"ACTIVE","sortPriority":4,"id":41818763,"name":"5. Dr Kammi"},{"status":"ACTIVE","sortPriority":5,"id":39637621,"name":"6. Katara Love"},{"status":"ACTIVE","sortPriority":6,"id":42162698,"name":"7. Black Petunia"},{"status":"ACTIVE","sortPriority":7,"id":41910350,"name":"8. Big Time Money"}],"regulators":["MR_INT"],"venue":"Rockhampton","countryCode":"AU","discountAllowed":true,"timezone":"Australia/Queensland","openDate":"2022-03-02T08:28:00.000Z","version":4382601692,"name":"To Be Placed","eventName":"Rockhampton (AUS) 2nd Mar"},"rc":[{"atb":[[4.3,18.34],[3.9,41.74],[3.65,45.67]],"id":42162698},{"atl":[[32,0.77],[21,0.6],[55,0.44],[110,0.44],[15.5,0.83]],"id":42162698},{"spn":9.9,"spf":"NaN","id":42162698},{"atb":[[1.7,172.93],[1.75,80.7],[1.65,186.23]],"id":39637621},{"atl":[[4,4.03],[8,6.91],[5,6.05],[6,4.84],[3.5,4.84]],"id":39637621},{"spn":2.62,"spf":"NaN","id":39637621},{"atb":[[2.06,114.19],[2.26,48.03],[2.16,104.35]],"id":41818763},{"atl":[[5.6,2.63],[7.2,1.95],[18,2.84],[9.2,2.94],[13,2.01]],"id":41818763},{"spn":3.93,"spf":"NaN","id":41818763},{"atb":[[4.1,19.52],[3.8,43.23],[3.55,47.47]],"id":41910350},{"atl":[[19.5,0.65],[95,0.51],[48,0.51],[14.5,0.89],[29,0.86]],"id":41910350},{"spn":9.3,"spf":"NaN","id":41910350},{"atb":[[3.4,50.43],[3.15,56.3],[3.65,22.84]],"id":43167133},{"atl":[[32,0.77],[10.5,1.27],[21,1.21],[55,0.89],[15.5,0.83]],"id":43167133},{"spn":7.07,"spf":"NaN","id":43167133},{"atb":[[1.2,605.26],[1.25,242.1],[1.15,807.02]],"id":42154339},{"atl":[[3.6,18.62],[3.1,11.52],[2.44,8.4],[2.64,7.38],[2.84,13.15]],"id":42154339},{"spn":1.84,"spf":"NaN","id":42154339},{"atb":[[2.8,67.25],[2.9,31.85],[2.7,71.2]],"id":42688787},{"atl":[[19.5,1.3],[9.8,1.37],[7.8,1.77],[14.5,1.79],[29,1.72]],"id":42688787},{"spn":5.35,"spf":"NaN","id":42688787}],"con":true,"img":true}]}
{"op":"mcm","clk":"5352465583","pt":1646191002624,"mc":[{"id":"1.195453767","marketDefinition":{"bspMarket":true,"turnInPlayEnabled":false,"persistenceEnabled":false,"marketBaseRate":7.0,"eventId":"31272499","eventTypeId":"4339","numberOfWinners":2,"bettingType":"ODDS","marketType":"PLACE","marketTime":"2022-03-02T09:08:00.000Z","suspendTime":"2022-03-02T09:08:00.000Z","bspReconciled":false,"complete":true,"inPlay":false,"crossMatching":false,"runnersVoidable":false,"numberOfActiveRunners":7,"betDelay":0,"status":"OPEN","runners":[{"status":"ACTIVE","sortPriority":1,"id":43167133,"name":"1. Sunset Sienna"},{"status":"ACTIVE","sortPriority":2,"id":42154339,"name":"3. Foxy One"},{"status":"ACTIVE","sortPriority":3,"id":42688787,"name":"4. Double Espresso"},{"status":"ACTIVE","sortPriority":4,"id":41818763,"name":"5. Dr Kammi"},{"status":"ACTIVE","sortPriority":5,"id":39637621,"name":"6. Katara Love"},{"status":"ACTIVE","sortPriority":6,"id":42162698,"name":"7. Black Petunia"},{"status":"ACTIVE","sortPriority":7,"id":41910350,"name":"8. Big Time Money"}],"regulators":["MR_INT"],"venue":"Rockhampton","countryCode":"AU","discountAllowed":true,"timezone":"Australia/Queensland","openDate":"2022-03-02T08:28:00.000Z","version":4382601692,"name":"To Be Placed","eventName":"Rockhampton (AUS) 2nd Mar"},"rc":[{"atb":[[4.3,18.37],[3.9,41.81],[3.65,45.75]],"id":42162698},{"atl":[[32,0.78],[21,0.6],[55,0.44],[110,0.44],[15.5,0.83]],"id":42162698},{"spn":9.9,"spf":"NaN","id":42162698},{"atb":[[1.7,173.22],[1.75,80.83],[1.65,186.55]],"id":39637621},{"atl":[[4,4.04],[8,6.93],[5,6.06],[6,4.85],[3.5,4.85]],"id":39637621},{"spn":2.62,"spf":"NaN","id":39637621},{"atb":[[2.06,114.39],[2.26,48.12],[2.16,104.53]],"id":41818763},{"atl":[[5.6,2.63],[7.2,1.95],[18,2.85],[9.2,2.95],[13,2.02]],"id":41818763},{"spn":3.93,"spf":"NaN","id":41818763},{"atb":[[4.1,19.55],[3.8,43.3],[3.55,47.55]],"id":41910350},{"atl":[[19.5,0.65],[95,0.51],[48,0.51],[14.5,0.89],[29,0.86]],"id":41910350},{"spn":9.3,"spf":"NaN","id":41910350},{"atb":[[3.4,50.52],[3.15,56.4],[3.65,22.88]],"id":43167133},{"atl":[[32,0.78],[10.5,1.27],[21,1.21],[55,0.89],[15.5,0.83]],"id":43167133},{"spn":7.07,"spf":"NaN","id":43167133},{"atb":[[1.2,606.29],[1.25,242.51],[1.15,808.38]],"id":42154339},{"atl":[[3.6,18.65],[3.1,11.54],[2.44,8.42],[2.64,7.39],[2.84,13.18]],"id":42154339},{"spn":1.84,"spf":"NaN","id":42154339},{"atb":[[2.8,67.36],[2.9,31.9],[2.7,71.32]],"id":42688787},{"atl":[[19.5,1.31],[9.8,1.37],[7.8,1.78],[14.5,1.79],[29,1.73]],"id":42688787},{"spn":5.35,"spf":"NaN","id":42688787}],"con":true,"img":true}]}
{"op":"mcm","clk":"5352601727","pt":1646194734259,"mc":[{"id":"1.195453767","rc":[{"atb":[[4.3,0],[3.9,0],[3.65,0]],"id":42162698},{"atl":[[32,0],[21,0],[55,0],[110,0],[15.5,0]],"id":42162698},{"atb":[[1.7,0],[1.75,0],[1.65,0]],"id":39637621},{"atl":[[4,0],[8,0],[5,0],[6,0],[3.5,0]],"id":39637621},{"atb":[[2.06,0],[2.26,0],[2.16,0]],"id":41818763},{"atl":[[5.6,0],[7.2,0],[18,0],[9.2,0],[13,0]],"id":41818763},{"atb":[[4.1,19.55],[3.8,43.3],[3.55,47.55]],"id":41910350},{"atl":[[19.5,0.65],[95,0.51],[48,0.51],[14.5,0.89],[29,0.86]],"id":41910350},{"atb":[[3.4,0],[3.15,0],[3.65,0]],"id":43167133},{"atl":[[32,0],[10.5,0],[21,0],[55,0],[15.5,0]],"id":43167133},{"atb":[[1.2,606.29],[1.25,242.51],[1.15,808.38]],"id":42154339},{"atl":[[3.6,18.65],[3.1,11.54],[2.44,8.42],[2.64,7.39],[2.84,13.18]],"id":42154339},{"spn":1.84,"spf":"NaN","id":42154339},{"atb":[[2.8,67.36],[2.9,31.9],[2.7,71.32]],"id":42688787},{"atl":[[19.5,1.31],[9.8,1.37],[7.8,1.78],[14.5,1.79],[29,1.73]],"id":42688787},{"spn":5.35,"spf":"NaN","id":42688787}],"con":true,"img":false}]}
{"op":"mcm","clk":"5352602393","pt":1646194751778,"mc":[{"id":"1.195453767","rc":[{"atb":[[4.3,18.37],[3.9,41.81],[3.65,45.75]],"id":42162698},{"atl":[[32,0.78],[21,0.6],[55,0.44],[110,0.44],[15.5,0.83]],"id":42162698},{"atb":[[1.6,202.09],[1.7,86.61],[1.65,186.55]],"id":39637621},{"atl":[[3.2,5.51],[3.7,4.48],[6.8,8.36],[4.4,7.13],[5.4,5.51]],"id":39637621},{"atb":[[2,121.25],[2.2,50.52],[2.1,110.23]],"id":41818763},{"atl":[[17.5,2.93],[9,3.03],[5.5,2.69],[12.5,2.1],[7,2.02]],"id":41818763},{"atb":[[3.4,50.52],[3.15,56.4],[3.65,22.88]],"id":43167133},{"atl":[[32,0.78],[10.5,1.27],[21,1.21],[55,0.89],[15.5,0.83]],"id":43167133}],"con":true,"img":false}]}
{"op":"mcm","clk":"5352603663","pt":1646194791993,"mc":[{"id":"1.195453767","rc":[{"atb":[[4.3,0],[3.9,0],[3.65,0]],"id":42162698},{"atl":[[32,0],[21,0],[55,0],[110,0],[15.5,0]],"id":42162698}],"con":true,"img":false}]}
{"op":"mcm","clk":"5352603860","pt":1646194797989,"mc":[{"id":"1.195453767","rc":[{"atb":[[4,40.41],[4.5,34.64],[5,15.15]],"id":42162698},{"atl":[[17,0.75],[70,0.34],[140,0.34],[38,0.65],[24,0.52]],"id":42162698},{"spn":11.0,"spf":"NaN","id":42162698},{"spn":2.45,"spf":"NaN","id":39637621},{"spn":3.85,"spf":"NaN","id":41818763},{"spn":7.07,"spf":"NaN","id":43167133}],"con":true,"img":false}]}
{"op":"mcm","clk":"5352822392","pt":1646201802670,"mc":[{"id":"1.195453767","marketDefinition":{"bspMarket":true,"turnInPlayEnabled":false,"persistenceEnabled":false,"marketBaseRate":7.0,"eventId":"31272499","eventTypeId":"4339","numberOfWinners":2,"bettingType":"ODDS","marketType":"PLACE","marketTime":"2022-03-02T09:08:00.000Z","suspendTime":"2022-03-02T09:08:00.000Z","bspReconciled":false,"complete":true,"inPlay":false,"crossMatching":false,"runnersVoidable":false,"numberOfActiveRunners":7,"betDelay":0,"status":"OPEN","runners":[{"status":"ACTIVE","sortPriority":1,"id":43167133,"name":"1. Sunset Sienna"},{"status":"ACTIVE","sortPriority":2,"id":42154339,"name":"3. Foxy One"},{"status":"ACTIVE","sortPriority":3,"id":42688787,"name":"4. Double Espresso"},{"status":"ACTIVE","sortPriority":4,"id":41818763,"name":"5. Dr Kammi"},{"status":"ACTIVE","sortPriority":5,"id":39637621,"name":"6. Katara Love"},{"status":"ACTIVE","sortPriority":6,"id":42162698,"name":"7. Black Petunia"},{"status":"ACTIVE","sortPriority":7,"id":41910350,"name":"8. Big Time Money"}],"regulators":["MR_INT"],"venue":"Rockhampton","countryCode":"AU","discountAllowed":true,"timezone":"Australia/Queensland","openDate":"2022-03-02T08:28:00.000Z","version":4382601692,"name":"To Be Placed","eventName":"Rockhampton (AUS) 2nd Mar"},"rc":[{"atb":[[4,40.4],[4.5,34.63],[5,15.15]],"id":42162698},{"atl":[[17,0.75],[70,0.34],[140,0.34],[38,0.65],[24,0.52]],"id":42162698},{"spn":11.0,"spf":"NaN","id":42162698},{"atb":[[1.6,202.02],[1.7,86.57],[1.65,186.48]],"id":39637621},{"atl":[[3.2,5.5],[3.7,4.48],[6.8,8.35],[4.4,7.13],[5.4,5.5]],"id":39637621},{"spn":2.45,"spf":"NaN","id":39637621},{"atb":[[2,121.21],[2.2,50.5],[2.1,110.19]],"id":41818763},{"atl":[[17.5,2.93],[9,3.03],[5.5,2.69],[12.5,2.1],[7,2.02]],"id":41818763},{"spn":3.85,"spf":"NaN","id":41818763},{"atb":[[4.1,19.55],[3.8,43.29],[3.55,47.53]],"id":41910350},{"atl":[[19.5,0.65],[95,0.51],[48,0.51],[14.5,0.89],[29,0.86]],"id":41910350},{"spn":9.3,"spf":"NaN","id":41910350},{"atb":[[3.4,50.5],[3.15,56.38],[3.65,22.87]],"id":43167133},{"atl":[[32,0.78],[10.5,1.27],[21,1.21],[55,0.89],[15.5,0.83]],"id":43167133},{"spn":7.07,"spf":"NaN","id":43167133},{"atb":[[1.2,606.06],[1.25,242.42],[1.15,808.08]],"id":42154339},{"atl":[[3.6,18.64],[3.1,11.54],[2.44,8.41],[2.64,7.39],[2.84,13.17]],"id":42154339},{"spn":1.84,"spf":"NaN","id":42154339},{"atb":[[2.8,67.33],[2.9,31.89],[2.7,71.3]],"id":42688787},{"atl":[[19.5,1.31],[9.8,1.37],[7.8,1.77],[14.5,1.79],[29,1.73]],"id":42688787},{"spn":5.35,"spf":"NaN","id":42688787}],"con":true,"img":true}]}
{"op":"mcm","clk":"5352931513","pt":1646204992250,"mc":[{"id":"1.195453767","rc":[{"atb":[[4,40.39],[4.5,34.62],[5,15.14]],"id":42162698},{"atl":[[17,0.75],[70,0.34],[140,0.34],[38,0.65],[24,0.52]],"id":42162698},{"atb":[[1.6,0],[1.7,0],[1.65,0]],"id":39637621},{"atl":[[3.2,0],[3.7,0],[6.8,0],[4.4,0],[5.4,0]],"id":39637621},{"spn":"NaN","spf":"NaN","id":39637621},{"atb":[[2,121.17],[2.2,50.49],[2.1,110.16]],"id":41818763},{"atl":[[17.5,2.93],[9,3.02],[5.5,2.69],[12.5,2.1],[7,2.01]],"id":41818763},{"atb":[[4.1,19.54],[3.8,43.28],[3.55,47.52]],"id":41910350},{"atl":[[19.5,0.65],[95,0.51],[48,0.51],[14.5,0.89],[29,0.86]],"id":41910350},{"atb":[[3.4,50.49],[3.15,56.36],[3.65,22.86]],"id":43167133},{"atl":[[32,0.78],[10.5,1.27],[21,1.21],[55,0.89],[15.5,0.83]],"id":43167133},{"atb":[[1.2,605.89],[1.25,242.35],[1.15,807.86]],"id":42154339},{"atl":[[3.6,18.64],[3.1,11.53],[2.44,8.41],[2.64,7.39],[2.84,13.17]],"id":42154339},{"atb":[[2.8,0],[2.9,0],[2.7,0]],"id":42688787},{"atl":[[19.5,0],[9.8,0],[7.8,0],[14.5,0],[29,0]],"id":42688787},{"spn":"NaN","spf":"NaN","id":42688787}],"con":true,"img":false}]}
{"op":"mcm","clk":"5352931827","pt":1646204998938,"mc":[{"id":"1.195453767","rc":[{"atb":[[1.6,201.96],[1.7,86.55],[1.65,186.43]],"id":39637621},{"atl":[[3.2,5.5],[3.7,4.48],[6.8,8.35],[4.4,7.12],[5.4,5.5]],"id":39637621},{"atb":[[2.8,67.31],[2.9,31.88],[2.7,71.28]],"id":42688787},{"atl":[[19.5,1.31],[9.8,1.37],[7.8,1.77],[14.5,1.79],[29,1.73]],"id":42688787}],"con":true,"img":false}]}
{"op":"mcm","clk":"5353001245","pt":1646206751291,"mc":[{"id":"1.195453767","rc":[{"atb":[[4.6,15.96],[5.2,10.39]],"id":42162698},{"atl":[[32,2.72],[29,2.72]],"id":42162698},{"spn":11.1,"spf":"NaN","id":42162698},{"atb":[[1.49,129.91],[1.71,61.5]],"id":39637621},{"atl":[[5.2,15.28],[4.7,11.8]],"id":39637621},{"spn":2.45,"spf":"NaN","id":39637621},{"atb":[[2.02,60.2],[2.12,38.99]],"id":41818763},{"atl":[[8.2,7.87],[7.4,6.82]],"id":41818763},{"atb":[[5.1,10.64],[4.4,19.65]],"id":41910350},{"atl":[[32,2.72],[29,3.59]],"id":41910350},{"spn":9.8,"spf":"NaN","id":41910350},{"atb":[[3.45,17.82],[2.78,30.05]],"id":43167133},{"atl":[[16,3.56],[14.5,3.23]],"id":43167133},{"atb":[[1.21,305.67],[1.26,108.64]],"id":42154339},{"atl":[[2.44,38.74],[2.62,39.84]],"id":42154339},{"spn":1.85,"spf":"NaN","id":42154339},{"atb":[[2.82,23.99],[2.34,40.22]],"id":42688787},{"atl":[[11.5,4.15],[12.5,4.68]],"id":42688787},{"spn":5.35,"spf":"NaN","id":42688787}],"con":true,"img":false}]}
{"op":"mcm","clk":"5353004680","pt":1646206835651,"mc":[{"id":"1.195453767","rc":[{"atb":[[2.12,0]],"id":41818763},{"atb":[[2.82,0]],"id":42688787}],"con":true,"img":false}]}
{"op":"mcm","clk":"5353004688","pt":1646206835753,"mc":[{"id":"1.195453767","rc":[{"atb":[[2.22,38.99]],"id":41818763},{"atb":[[2.92,23.99]],"id":42688787}],"con":true,"img":false}]}
{"op":"mcm","clk":"5353027767","pt":1646207202702,"mc":[{"id":"1.195453767","marketDefinition":{"bspMarket":true,"turnInPlayEnabled":false,"persistenceEnabled":false,"marketBaseRate":7.0,"eventId":"31272499","eventTypeId":"4339","numberOfWinners":2,"bettingType":"ODDS","marketType":"PLACE","marketTime":"2022-03-02T09:08:00.000Z","suspendTime":"2022-03-02T09:08:00.000Z","bspReconciled":false,"complete":true,"inPlay":false,"crossMatching":false,"runnersVoidable":false,"numberOfActiveRunners":7,"betDelay":0,"status":"OPEN","runners":[{"status":"ACTIVE","sortPriority":1,"id":43167133,"name":"1. Sunset Sienna"},{"status":"ACTIVE","sortPriority":2,"id":42154339,"name":"3. Foxy One"},{"status":"ACTIVE","sortPriority":3,"id":42688787,"name":"4. Double Espresso"},{"status":"ACTIVE","sortPriority":4,"id":41818763,"name":"5. Dr Kammi"},{"status":"ACTIVE","sortPriority":5,"id":39637621,"name":"6. Katara Love"},{"status":"ACTIVE","sortPriority":6,"id":42162698,"name":"7. Black Petunia"},{"status":"ACTIVE","sortPriority":7,"id":41910350,"name":"8. Big Time Money"}],"regulators":["MR_INT"],"venue":"Rockhampton","countryCode":"AU","discountAllowed":true,"timezone":"Australia/Queensland","openDate":"2022-03-02T08:28:00.000Z","version":4382601692,"name":"To Be Placed","eventName":"Rockhampton (AUS) 2nd Mar"},"rc":[{"atb":[[4,40.39],[4.5,34.62],[5,15.14],[4.6,15.96],[5.2,10.39]],"id":42162698},{"atl":[[32,2.72],[17,0.75],[70,0.34],[140,0.34],[38,0.65],[24,0.52],[29,2.72]],"id":42162698},{"spn":11.1,"spf":"NaN","id":42162698},{"atb":[[1.6,201.96],[1.7,86.55],[1.49,129.91],[1.65,186.43],[1.71,61.5]],"id":39637621},{"atl":[[3.2,5.5],[3.7,4.48],[6.8,8.35],[5.2,15.28],[4.4,7.12],[4.7,11.8],[5.4,5.5]],"id":39637621},{"spn":2.45,"spf":"NaN","id":39637621},{"atb":[[2,121.17],[2.02,60.2],[2.22,38.99],[2.2,50.49],[2.1,110.16]],"id":41818763},{"atl":[[17.5,2.93],[9,3.02],[5.5,2.69],[8.2,7.87],[7.4,6.82],[12.5,2.1],[7,2.01]],"id":41818763},{"spn":3.86,"spf":"NaN","id":41818763},{"atb":[[5.1,10.64],[4.1,19.54],[3.8,43.28],[3.55,47.52],[4.4,19.65]],"id":41910350},{"atl":[[32,2.72],[19.5,0.65],[95,0.51],[48,0.51],[14.5,0.89],[29,3.59]],"id":41910350},{"spn":9.8,"spf":"NaN","id":41910350},{"atb":[[3.45,17.82],[3.4,50.49],[3.15,56.36],[2.78,30.05],[3.65,22.86]],"id":43167133},{"atl":[[16,3.56],[32,0.78],[10.5,1.27],[21,1.21],[55,0.89],[14.5,3.23],[15.5,0.83]],"id":43167133},{"spn":7.07,"spf":"NaN","id":43167133},{"atb":[[1.2,605.89],[1.25,242.35],[1.15,807.86],[1.21,305.67],[1.26,108.64]],"id":42154339},{"atl":[[3.6,18.64],[3.1,11.53],[2.44,38.74],[2.64,7.39],[2.84,13.17],[2.62,39.84]],"id":42154339},{"spn":1.85,"spf":"NaN","id":42154339},{"atb":[[2.8,67.31],[2.92,23.99],[2.9,31.88],[2.34,40.22],[2.7,71.28]],"id":42688787},{"atl":[[19.5,1.31],[11.5,4.15],[9.8,1.37],[12.5,4.68],[7.8,1.77],[14.5,1.79],[29,1.73]],"id":42688787},{"spn":5.36,"spf":"NaN","id":42688787}],"con":true,"img":true}]}
{"op":"mcm","clk":"5353084864","pt":1646208495034,"mc":[{"id":"1.195453767","rc":[{"atb":[[1.71,148.06]],"id":39637621},{"atl":[[5.3,14.26]],"id":39637621},{"atb":[[1.94,106.38]],"id":41818763},{"atl":[[5.5,5.38]],"id":41818763},{"spn":3.86,"spf":"NaN","id":41818763},{"atb":[[2.54,60.1]],"id":43167133},{"atl":[[15.5,5.35]],"id":43167133},{"atb":[[1.17,588.24]],"id":42154339},{"atl":[[2.74,57.47]],"id":42154339},{"spn":5.36,"spf":"NaN","id":42688787}],"con":true,"img":false}]}
{"op":"mcm","clk":"5353085097","pt":1646208501140,"mc":[{"id":"1.195453767","rc":[{"atb":[[3.85,31.92]],"id":42162698},{"atl":[[70,2.34]],"id":42162698},{"atb":[[3.5,39.3]],"id":41910350},{"atl":[[42,2.44]],"id":41910350},{"atb":[[1.87,80.44]],"id":42688787},{"atl":[[7.8,3.77]],"id":42688787}],"con":true,"img":false}]}
{"op":"mcm","clk":"5353086807","pt":1646208542802,"mc":[{"id":"1.195453767","rc":[{"atb":[[1.72,85.28],[2.02,0]],"id":41818763},{"atl":[[16,0]],"id":43167133}],"con":true,"img":false}]}
{"op":"mcm","clk":"5353086810","pt":1646208542906,"mc":[{"id":"1.195453767","rc":[{"atl":[[15,3.56]],"id":43167133}],"con":true,"img":false}]}
{"op":"mcm","clk":"5353087166","pt":1646208551588,"mc":[{"id":"1.195453767","rc":[{"atb":[[2.22,0]],"id":41818763}],"con":true,"img":false}]}
{"op":"mcm","clk":"5353087169","pt":1646208551687,"mc":[{"id":"1.195453767","rc":[{"atb":[[1.95,38.99]],"id":41818763}],"con":true,"img":false}]}
{"op":"mcm","clk":"5353088144","pt":1646208573442,"mc":[{"id":"1.195453767","rc":[{"atb":[[5.2,0]],"id":42162698},{"spn":11.0,"spf":"NaN","id":42162698},{"spn":3.85,"spf":"NaN","id":41818763},{"atb":[[5.1,0]],"id":41910350},{"spn":9.45,"spf":"NaN","id":41910350}],"con":true,"img":false}]}
{"op":"mcm","clk":"5353088149","pt":1646208573541,"mc":[{"id":"1.195453767","rc":[{"atb":[[5.4,10.39]],"id":42162698},{"atb":[[5.2,10.64]],"id":41910350}],"con":true,"img":false}]}
{"op":"mcm","clk":"5353089992","pt":1646208613797,"mc":[{"id":"1.195453767","rc":[{"atb":[[1.95,0]],"id":41818763}],"con":true,"img":false}]}
{"op":"mcm","clk":"5353089997","pt":1646208613899,"mc":[{"id":"1.195453767","rc":[{"atb":[[2.22,38.99]],"id":41818763}],"con":true,"img":false}]}
{"op":"mcm","clk":"5353091553","pt":1646208646821,"mc":[{"id":"1.195453767","rc":[{"spn":11.2,"spf":"NaN","id":42162698},{"atb":[[2.22,0]],"id":41818763},{"spn":9.85,"spf":"NaN","id":41910350}],"con":true,"img":false}]}
{"op":"mcm","clk":"5353091558","pt":1646208646925,"mc":[{"id":"1.195453767","rc":[{"atb":[[1.95,38.99]],"id":41818763}],"con":true,"img":false}]}
{"op":"mcm","clk":"5353101217","pt":1646208852282,"mc":[{"id":"1.195453767","rc":[{"atb":[[1.95,0]],"id":41818763}],"con":true,"img":false}]}
{"op":"mcm","clk":"5353101224","pt":1646208852379,"mc":[{"id":"1.195453767","rc":[{"atb":[[2.22,38.99]],"id":41818763}],"con":true,"img":false}]}
{"op":"mcm","clk":"5353102909","pt":1646208888531,"mc":[{"id":"1.195453767","rc":[{"atb":[[1.72,0],[2.02,60.2]],"id":41818763}],"con":true,"img":false}]}
{"op":"mcm","clk":"5353114299","pt":1646209154588,"mc":[{"id":"1.195453767","rc":[{"atb":[[3.85,0],[2.44,47.88]],"id":42162698},{"atb":[[1.86,116.28],[1.94,0]],"id":41818763},{"atl":[[5.8,10.76],[5.5,2.69]],"id":41818763},{"spn":3.86,"spf":"NaN","id":41818763},{"atb":[[2.46,58.95],[3.5,0]],"id":41910350},{"atb":[[2.54,0],[2.3,76.92]],"id":43167133},{"atl":[[2.74,0],[2.42,38.74]],"id":42154339},{"spn":1.84,"spf":"NaN","id":42154339},{"atb":[[1.81,107.54],[1.87,0]],"id":42688787}],"con":true,"img":false}]}
{"op":"mcm","clk":"5353114304","pt":1646209154689,"mc":[{"id":"1.195453767","rc":[{"atb":[[4.3,30.3],[2.44,0]],"id":42162698},{"atb":[[1.86,0],[2.1,201.07]],"id":41818763},{"atb":[[2.46,0],[3.9,34.48]],"id":41910350},{"atb":[[2.3,0],[2.78,86.23]],"id":43167133},{"atb":[[2.02,80.44],[1.81,0]],"id":42688787}],"con":true,"img":false}]}
{"op":"mcm","clk":"5353115614","pt":1646209186832,"mc":[{"id":"1.195453767","rc":[{"atl":[[2.44,8.41]],"id":42154339}],"con":true,"img":false}]}
{"op":"mcm","clk":"5353115617","pt":1646209186934,"mc":[{"id":"1.195453767","rc":[{"atl":[[2.4,30.32]],"id":42154339}],"con":true,"img":false}]}
{"op":"mcm","clk":"5353115620","pt":1646209187041,"mc":[{"id":"1.195453767","rc":[{"atl":[[2.38,30.33]],"id":42154339}],"con":true,"img":false}]}
{"op":"mcm","clk":"5353115630","pt":1646209187234,"mc":[{"id":"1.195453767","rc":[{"atl":[[2.42,0]],"id":42154339}],"con":true,"img":false}]}
{"op":"mcm","clk":"5353116103","pt":1646209198640,"mc":[{"id":"1.195453767","rc":[{"atl":[[7.4,0]],"id":41818763}],"con":true,"img":false}]}
{"op":"mcm","clk":"5353116107","pt":1646209198748,"mc":[{"id":"1.195453767","rc":[{"atl":[[5.7,6.82]],"id":41818763}],"con":true,"img":false}]}
{"op":"mcm","clk":"5353116713","pt":1646209210454,"mc":[{"id":"1.195453767","rc":[{"atl":[[5.8,0],[5.7,13.64]],"id":41818763}],"con":true,"img":false}]}
{"op":"mcm","clk":"5353116961","pt":1646209215673,"mc":[{"id":"1.195453767","rc":[{"atl":[[5.7,6.82]],"id":41818763},{"spn":1.82,"spf":"NaN","id":42154339}],"con":true,"img":false}]}
{"op":"mcm","clk":"5353116969","pt":1646209215778,"mc":[{"id":"1.195453767","rc":[{"atl":[[7.4,6.82]],"id":41818763}],"con":true,"img":false}]}
{"op":"mcm","clk":"5353117222","pt":1646209220998,"mc":[{"id":"1.195453767","rc":[{"atl":[[2.4,0]],"id":42154339}],"con":true,"img":false}]}
{"op":"mcm","clk":"5353117227","pt":1646209221062,"mc":[{"id":"1.195453767","rc":[{"atl":[[2.36,30.32],[2.42,60.66]],"id":42154339}],"con":true,"img":false}]}
{"op":"mcm","clk":"5353117233","pt":1646209221166,"mc":[{"id":"1.195453767","rc":[{"atl":[[2.42,0],[2.38,0],[2.34,30.33]],"id":42154339}],"con":true,"img":false}]}
{"op":"mcm","clk":"5353117736","pt":1646209233300,"mc":[{"id":"1.195453767","rc":[{"atb":[[2.02,158.24],[2.1,110.16]],"id":41818763},{"atl":[[5.8,9.51],[5.7,0]],"id":41818763}],"con":true,"img":false}]}
{"op":"mcm","clk":"5353118672","pt":1646209255046,"mc":[{"id":"1.195453767","rc":[{"atl":[[2.36,0]],"id":42154339}],"con":true,"img":false}]}
{"op":"mcm","clk":"5353118679","pt":1646209255150,"mc":[{"id":"1.195453767","rc":[{"atl":[[2.32,30.32]],"id":42154339}],"con":true,"img":false}]}
{"op":"mcm","clk":"5353118684","pt":1646209255247,"mc":[{"id":"1.195453767","rc":[{"atl":[[2.42,60.66],[2.34,0]],"id":42154339}],"con":true,"img":false}]}
{"op":"mcm","clk":"5353119042","pt":1646209262934,"mc":[{"id":"1.195453767","rc":[{"atb":[[2.02,60.2],[2.1,201.07]],"id":41818763}],"con":true,"img":false}]}
{"op":"mcm","clk":"5353119460","pt":1646209272588,"mc":[{"id":"1.195453767","rc":[{"atl":[[7.4,0]],"id":41818763}],"con":true,"img":false}]}
{"op":"mcm","clk":"5353119464","pt":1646209272650,"mc":[{"id":"1.195453767","rc":[{"atl":[[5.7,6.82]],"id":41818763}],"con":true,"img":false}]}
{"op":"mcm","clk":"5353119967","pt":1646209284580,"mc":[{"id":"1.195453767","rc":[{"atl":[[2.3,30.33],[2.42,0]],"id":42154339},{"spn":1.78,"spf":"NaN","id":42154339}],"con":true,"img":false}]}
{"op":"mcm","clk":"5353121245","pt":1646209312094,"mc":[{"id":"1.195453767","rc":[{"atl":[[2.32,0]],"id":42154339}],"con":true,"img":false}]}
{"op":"mcm","clk":"5353121257","pt":1646209312206,"mc":[{"id":"1.195453767","rc":[{"atl":[[2.3,0],[2.42,60.66],[2.28,30.32]],"id":42154339}],"con":true,"img":false}]}
{"op":"mcm","clk":"5353121731","pt":1646209322943,"mc":[{"id":"1.195453767","rc":[{"atl":[[2.28,0]],"id":42154339}],"con":true,"img":false}]}
{"op":"mcm","clk":"5353121736","pt":1646209323046,"mc":[{"id":"1.195453767","rc":[{"atl":[[2.4,30.32]],"id":42154339}],"con":true,"img":false}]}
{"op":"mcm","clk":"5353122542","pt":1646209341039,"mc":[{"id":"1.195453767","rc":[{"atl":[[2.42,0],[2.38,30.33]],"id":42154339}],"con":true,"img":false}]}
{"op":"mcm","clk":"5353123194","pt":1646209353251,"mc":[{"id":"1.195453767","rc":[{"atl":[[5.3,0],[5.9,14.26]],"id":39637621},{"atb":[[2.02,158.24],[2.1,110.16]],"id":41818763},{"atl":[[5.8,0],[6.2,13.64]],"id":41818763},{"atb":[[2.64,60.98],[2.78,30.05]],"id":43167133},{"spn":1.82,"spf":"NaN","id":42154339},{"atb":[[2.02,0],[1.95,105.26]],"id":42688787}],"con":true,"img":false}]}
{"op":"mcm","clk":"5353123361","pt":1646209356753,"mc":[{"id":"1.195453767","rc":[{"atb":[[2.02,98.04]],"id":41818763}],"con":true,"img":false}]}
{"op":"mcm","clk":"5353123593","pt":1646209362181,"mc":[{"id":"1.195453767","rc":[{"atl":[[5.7,0]],"id":41818763}],"con":true,"img":false}]}
{"op":"mcm","clk":"5353123599","pt":1646209362282,"mc":[{"id":"1.195453767","rc":[{"atl":[[6,6.82]],"id":41818763}],"con":true,"img":false}]}
{"op":"mcm","clk":"5353124238","pt":1646209375705,"mc":[{"id":"1.195453767","rc":[{"atl":[[2.4,0]],"id":42154339}],"con":true,"img":false}]}
{"op":"mcm","clk":"5353124243","pt":1646209375806,"mc":[{"id":"1.195453767","rc":[{"atl":[[2.36,30.32],[2.42,60.66]],"id":42154339}],"con":true,"img":false}]}
{"op":"mcm","clk":"5353124249","pt":1646209375911,"mc":[{"id":"1.195453767","rc":[{"atl":[[2.38,0]],"id":42154339}],"con":true,"img":false}]}
{"op":"mcm","clk":"5353124252","pt":1646209376013,"mc":[{"id":"1.195453767","rc":[{"atl":[[2.42,0],[2.34,30.33]],"id":42154339}],"con":true,"img":false}]}
{"op":"mcm","clk":"5353124671","pt":1646209384804,"mc":[{"id":"1.195453767","rc":[{"atb":[[1.83,73.98]],"id":41818763}],"con":true,"img":false}]}
{"op":"mcm","clk":"5353124983","pt":1646209391443,"mc":[{"id":"1.195453767","rc":[{"atb":[[5.5,1.67]],"id":42162698},{"atb":[[2.24,1.67]],"id":41818763},{"atb":[[5.3,1.67]],"id":41910350},{"atb":[[3.7,1.67]],"id":43167133},{"atb":[[2.94,1.67]],"id":42688787}],"con":true,"img":false}]}
{"op":"mcm","clk":"5353125979","pt":1646209410436,"mc":[{"id":"1.195453767","rc":[{"atl":[[2.36,0]],"id":42154339}],"con":true,"img":false}]}
{"op":"mcm","clk":"5353125986","pt":1646209410539,"mc":[{"id":"1.195453767","rc":[{"atl":[[2.32,30.32],[2.42,60.66],[2.34,0]],"id":42154339}],"con":true,"img":false}]}
{"op":"mcm","clk":"5353125989","pt":1646209410642,"mc":[{"id":"1.195453767","rc":[{"atl":[[2.3,30.33]],"id":42154339}],"con":true,"img":false}]}
{"op":"mcm","clk":"5353125995","pt":1646209410743,"mc":[{"id":"1.195453767","rc":[{"atl":[[2.42,0]],"id":42154339}],"con":true,"img":false}]}
{"op":"mcm","clk":"5353126081","pt":1646209412632,"mc":[{"id":"1.195453767","marketDefinition":{"bspMarket":true,"turnInPlayEnabled":false,"persistenceEnabled":false,"marketBaseRate":7.0,"eventId":"31272499","eventTypeId":"4339","numberOfWinners":2,"bettingType":"ODDS","marketType":"PLACE","marketTime":"2022-03-02T09:08:00.000Z","suspendTime":"2022-03-02T09:08:00.000Z","bspReconciled":false,"complete":true,"inPlay":false,"crossMatching":true,"runnersVoidable":false,"numberOfActiveRunners":7,"betDelay":0,"status":"OPEN","runners":[{"status":"ACTIVE","sortPriority":1,"id":43167133,"name":"1. Sunset Sienna"},{"status":"ACTIVE","sortPriority":2,"id":42154339,"name":"3. Foxy One"},{"status":"ACTIVE","sortPriority":3,"id":42688787,"name":"4. Double Espresso"},{"status":"ACTIVE","sortPriority":4,"id":41818763,"name":"5. Dr Kammi"},{"status":"ACTIVE","sortPriority":5,"id":39637621,"name":"6. Katara Love"},{"status":"ACTIVE","sortPriority":6,"id":42162698,"name":"7. Black Petunia"},{"status":"ACTIVE","sortPriority":7,"id":41910350,"name":"8. Big Time Money"}],"regulators":["MR_INT"],"venue":"Rockhampton","countryCode":"AU","discountAllowed":true,"timezone":"Australia/Queensland","openDate":"2022-03-02T08:28:00.000Z","version":4382601692,"name":"To Be Placed","eventName":"Rockhampton (AUS) 2nd Mar"},"rc":[],"con":true,"img":false}]}
{"op":"mcm","clk":"5353127694","pt":1646209445190,"mc":[{"id":"1.195453767","rc":[{"spn":11.25,"spf":"NaN","id":42162698},{"spn":9.9,"spf":"NaN","id":41910350},{"spn":3.87,"spf":"NaN","id":41818763},{"spn":7.1,"spf":"NaN","id":43167133},{"atl":[[2.32,0]],"id":42154339},{"spn":1.78,"spf":"NaN","id":42154339},{"spn":5.37,"spf":"NaN","id":42688787}],"con":true,"img":false}]}
{"op":"mcm","clk":"5353127699","pt":1646209445296,"mc":[{"id":"1.195453767","rc":[{"atl":[[2.3,0],[2.42,60.66],[2.28,30.32]],"id":42154339}],"con":true,"img":false}]}
{"op":"mcm","clk":"5353128546","pt":1646209460210,"mc":[{"id":"1.195453767","rc":[{"atl":[[2.28,0]],"id":42154339}],"con":true,"img":false}]}
{"op":"mcm","clk":"5353128551","pt":1646209460312,"mc":[{"id":"1.195453767","rc":[{"atl":[[2.4,30.32]],"id":42154339}],"con":true,"img":false}]}
{"op":"mcm","clk":"5353129245","pt":1646209472807,"mc":[{"id":"1.195453767","rc":[{"atl":[[2.42,0],[2.38,30.33]],"id":42154339}],"con":true,"img":false}]}
{"op":"mcm","clk":"5353131019","pt":1646209502870,"mc":[{"id":"1.195453767","rc":[{"atl":[[2.4,0]],"id":42154339}],"con":true,"img":false}]}
{"op":"mcm","clk":"5353131022","pt":1646209502974,"mc":[{"id":"1.195453767","rc":[{"atl":[[2.36,30.32],[2.42,60.66],[2.38,0]],"id":42154339}],"con":true,"img":false}]}
{"op":"mcm","clk":"5353131842","pt":1646209515981,"mc":[{"id":"1.195453767","rc":[{"atb":[[4.3,0],[3.25,31.92]],"id":42162698},{"atl":[[4.8,14.26],[5.9,0]],"id":39637621},{"atb":[[3.15,39.3],[3.9,0]],"id":41910350},{"atb":[[2.02,0],[2.18,84.75]],"id":41818763},{"atb":[[2.64,0],[2.48,60.1]],"id":43167133},{"spn":1.81,"spf":"NaN","id":42154339},{"atb":[[1.95,0],[2.08,92.59]],"id":42688787}],"con":true,"img":false}]}
{"op":"mcm","clk":"5353131851","pt":1646209516190,"mc":[{"id":"1.195453767","rc":[{"atb":[[4,33.33],[3.15,0]],"id":41910350}],"con":true,"img":false}]}
{"op":"mcm","clk":"5353132697","pt":1646209529877,"mc":[{"id":"1.195453767","rc":[{"atl":[[2.42,0],[2.34,30.33]],"id":42154339}],"con":true,"img":false}]}
{"op":"mcm","clk":"5353132768","pt":1646209531022,"mc":[{"id":"1.195453767","rc":[{"atb":[[2.12,89.29],[2.18,0]],"id":41818763}],"con":true,"img":false}]}
{"op":"mcm","clk":"5353133411","pt":1646209542822,"mc":[{"id":"1.195453767","rc":[{"atb":[[3.25,0],[4.4,29.41]],"id":42162698},{"atl":[[4.8,0],[4.2,11.8]],"id":39637621},{"atb":[[2.8,45.74],[2.48,0]],"id":43167133}],"con":true,"img":false}]}
{"op":"mcm","clk":"5353133722","pt":1646209548238,"mc":[{"id":"1.195453767","rc":[{"atb":[[3.75,3.04]],"id":43167133}],"con":true,"img":false}]}
{"op":"mcm","clk":"5353133728","pt":1646209548341,"mc":[{"id":"1.195453767","rc":[{"atb":[[1.29,28.79]],"id":42154339}],"con":true,"img":false}]}
{"op":"mcm","clk":"5353133752","pt":1646209548805,"mc":[{"id":"1.195453767","rc":[{"atb":[[2.28,6.52]],"id":41818763},{"atb":[[2.96,4.25]],"id":42688787}],"con":true,"img":false}]}
{"op":"mcm","clk":"5353133771","pt":1646209549116,"mc":[{"id":"1.195453767","rc":[{"atb":[[1.75,11.13]],"id":39637621}],"con":true,"img":false}]}
{"op":"mcm","clk":"5353133959","pt":1646209552514,"mc":[{"id":"1.195453767","rc":[{"atb":[[2.24,0]],"id":41818763},{"atb":[[3.7,0]],"id":43167133},{"atb":[[2.94,0]],"id":42688787}],"con":true,"img":false}]}
{"op":"mcm","clk":"5353133974","pt":1646209552730,"mc":[{"id":"1.195453767","rc":[{"atb":[[2.3,1.67]],"id":41818763},{"atb":[[3.8,1.67]],"id":43167133},{"atb":[[2.98,1.67]],"id":42688787}],"con":true,"img":false}]}
{"op":"mcm","clk":"5353134144","pt":1646209556019,"mc":[{"id":"1.195453767","rc":[{"atb":[[1.71,61.5],[1.76,86.56]],"id":39637621}],"con":true,"img":false}]}
{"op":"mcm","clk":"5353134219","pt":1646209557615,"mc":[{"id":"1.195453767","rc":[{"atb":[[2.12,0],[2.2,133.82]],"id":41818763},{"atl":[[2.36,0]],"id":42154339}],"con":true,"img":false}]}
{"op":"mcm","clk":"5353134223","pt":1646209557717,"mc":[{"id":"1.195453767","rc":[{"atl":[[2.32,30.32],[2.42,60.66],[2.34,0]],"id":42154339}],"con":true,"img":false}]}
{"op":"mcm","clk":"5353134855","pt":1646209569325,"mc":[{"id":"1.195453767","rc":[{"atb":[[4.4,0],[4.7,27.03]],"id":42162698}],"con":true,"img":false}]}
{"op":"mcm","clk":"5353135040","pt":1646209572461,"mc":[{"id":"1.195453767","rc":[{"atb":[[1.75,0]],"id":39637621}],"con":true,"img":false}]}
{"op":"mcm","clk":"5353135045","pt":1646209572567,"mc":[{"id":"1.195453767","rc":[{"atb":[[1.72,138.89],[1.76,0]],"id":39637621}],"con":true,"img":false}]}
{"op":"mcm","clk":"5353135115","pt":1646209573757,"mc":[{"id":"1.195453767","rc":[{"atl":[[4.7,0]],"id":39637621}],"con":true,"img":false}]}
{"op":"mcm","clk":"5353135120","pt":1646209573856,"mc":[{"id":"1.195453767","rc":[{"atl":[[4.1,11.8]],"id":39637621}],"con":true,"img":false}]}
{"op":"mcm","clk":"5353135649","pt":1646209584061,"mc":[{"id":"1.195453767","rc":[{"spn":2.46,"spf":"NaN","id":39637621},{"spn":3.9,"spf":"NaN","id":41818763},{"spn":7.15,"spf":"NaN","id":43167133},{"atl":[[2.3,30.33],[2.42,0]],"id":42154339},{"spn":1.79,"spf":"NaN","id":42154339},{"spn":5.39,"spf":"NaN","id":42688787}],"con":true,"img":false}]}
{"op":"mcm","clk":"5353136086","pt":1646209592777,"mc":[{"id":"1.195453767","rc":[{"atb":[[2.78,0]],"id":43167133}],"con":true,"img":false}]}
{"op":"mcm","clk":"5353136093","pt":1646209592879,"mc":[{"id":"1.195453767","rc":[{"atb":[[2.82,30.05]],"id":43167133}],"con":true,"img":false}]}
{"op":"mcm","clk":"5353136328","pt":1646209596801,"mc":[{"id":"1.195453767","rc":[{"atb":[[1.71,0]],"id":39637621}],"con":true,"img":false}]}
{"op":"mcm","clk":"5353136332","pt":1646209596860,"mc":[{"id":"1.195453767","rc":[{"atb":[[1.73,61.5]],"id":39637621}],"con":true,"img":false}]}
{"op":"mcm","clk":"5353136335","pt":1646209596961,"mc":[{"id":"1.195453767","rc":[{"atb":[[1.72,0],[1.71,140.85]],"id":39637621}],"con":true,"img":false}]}
{"op":"mcm","clk":"5353136807","pt":1646209605514,"mc":[{"id":"1.195453767","rc":[{"atb":[[1.83,0],[2.02,60.2]],"id":41818763}],"con":true,"img":false}]}
{"op":"mcm","clk":"5353137048","pt":1646209609699,"mc":[{"id":"1.195453767","rc":[{"atb":[[1.73,0]],"id":39637621}],"con":true,"img":false}]}
{"op":"mcm","clk":"5353137056","pt":1646209609801,"mc":[{"id":"1.195453767","rc":[{"atb":[[1.72,61.5]],"id":39637621}],"con":true,"img":false}]}
{"op":"mcm","clk":"5353137435","pt":1646209616407,"mc":[{"id":"1.195453767","rc":[{"atl":[[2.32,0]],"id":42154339}],"con":true,"img":false}]}
{"op":"mcm","clk":"5353137439","pt":1646209616509,"mc":[{"id":"1.195453767","rc":[{"atl":[[2.3,0],[2.42,60.66],[2.28,30.32]],"id":42154339}],"con":true,"img":false}]}
{"op":"mcm","clk":"5353137450","pt":1646209616716,"mc":[{"id":"1.195453767","rc":[{"atl":[[2.42,0],[2.26,30.33]],"id":42154339}],"con":true,"img":false}]}
{"op":"mcm","clk":"5353137660","pt":1646209620607,"mc":[{"id":"1.195453767","rc":[{"atb":[[4.6,0]],"id":42162698}],"con":true,"img":false}]}
{"op":"mcm","clk":"5353137671","pt":1646209620714,"mc":[{"id":"1.195453767","rc":[{"atb":[[4.8,15.96]],"id":42162698}],"con":true,"img":false}]}
{"op":"mcm","clk":"5353137788","pt":1646209622906,"mc":[{"id":"1.195453767","rc":[{"atb":[[1.73,86.56],[1.71,0]],"id":39637621}],"con":true,"img":false}]}
{"op":"mcm","clk":"5353138686","pt":1646209639863,"mc":[{"id":"1.195453767","rc":[{"atb":[[1.77,10.84]],"id":39637621}],"con":true,"img":false}]}
{"op":"mcm","clk":"5353138716","pt":1646209640069,"mc":[{"id":"1.195453767","rc":[{"atb":[[1.73,0],[1.78,61.51]],"id":39637621}],"con":true,"img":false}]}
{"op":"mcm","clk":"5353139290","pt":1646209648316,"mc":[{"id":"1.195453767","rc":[{"spn":2.49,"spf":"NaN","id":39637621},{"atl":[[2.28,0]],"id":42154339},{"spn":1.77,"spf":"NaN","id":42154339}],"con":true,"img":false}]}
{"op":"mcm","clk":"5353139292","pt":1646209648338,"mc":[{"id":"1.195453767","rc":[{"atl":[[2.24,30.32]],"id":42154339}],"con":true,"img":false}]}
{"op":"mcm","clk":"5353139295","pt":1646209648440,"mc":[{"id":"1.195453767","rc":[{"atl":[[2.42,60.66],[2.26,0]],"id":42154339}],"con":true,"img":false}]}
{"op":"mcm","clk":"5353139298","pt":1646209648534,"mc":[{"id":"1.195453767","rc":[{"atl":[[2.42,0],[2.22,30.33]],"id":42154339}],"con":true,"img":false}]}
{"op":"mcm","clk":"5353139418","pt":1646209651059,"mc":[{"id":"1.195453767","rc":[{"atb":[[2.12,89.29],[2.2,50.49]],"id":41818763},{"atl":[[6.2,0],[6.8,13.64]],"id":41818763},{"atl":[[42,0],[60,2]],"id":41910350},{"atb":[[2.8,0],[2.66,52.92]],"id":43167133}],"con":true,"img":false}]}
{"op":"mcm","clk":"5353139563","pt":1646209653535,"mc":[{"id":"1.195453767","rc":[{"atb":[[1.72,0]],"id":39637621}],"con":true,"img":false}]}
{"op":"mcm","clk":"5353139567","pt":1646209653636,"mc":[{"id":"1.195453767","rc":[{"atb":[[1.71,61.5]],"id":39637621}],"con":true,"img":false}]}
{"op":"mcm","clk":"5353139999","pt":1646209660938,"mc":[{"id":"1.195453767","rc":[{"atb":[[1.82,9.18]],"id":39637621},{"atb":[[2.28,12.4]],"id":41818763},{"atb":[[3.75,5.77]],"id":43167133},{"atb":[[1.29,54.74]],"id":42154339},{"atb":[[2.96,8.09]],"id":42688787}],"con":true,"img":false}]}
{"op":"mcm","clk":"5353140044","pt":1646209661869,"mc":[{"id":"1.195453767","rc":[{"atl":[[6,0]],"id":41818763}],"con":true,"img":false}]}
{"op":"mcm","clk":"5353140054","pt":1646209661978,"mc":[{"id":"1.195453767","rc":[{"atl":[[6.6,6.82]],"id":41818763}],"con":true,"img":false}]}
{"op":"mcm","clk":"5353140238","pt":1646209665267,"mc":[{"id":"1.195453767","rc":[{"atb":[[1.77,0]],"id":39637621}],"con":true,"img":false}]}
{"op":"mcm","clk":"5353140253","pt":1646209665576,"mc":[{"id":"1.195453767","rc":[{"atb":[[1.79,61.51],[1.78,0]],"id":39637621}],"con":true,"img":false}]}
{"op":"mcm","clk":"5353140341","pt":1646209666972,"mc":[{"id":"1.195453767","rc":[{"atb":[[1.82,0]],"id":39637621}],"con":true,"img":false}]}
{"op":"mcm","clk":"5353140539","pt":1646209670786,"mc":[{"id":"1.195453767","rc":[{"atb":[[1.72,123.02],[1.79,0]],"id":39637621}],"con":true,"img":false}]}
{"op":"mcm","clk":"5353140979","pt":1646209678987,"mc":[{"id":"1.195453767","rc":[{"atb":[[1.76,9.9]],"id":39637621}],"con":true,"img":false}]}
{"op":"mcm","clk":"5353141397","pt":1646209686102,"mc":[{"id":"1.195453767","rc":[{"atb":[[1.76,20.89]],"id":39637621}],"con":true,"img":false}]}
{"op":"mcm","clk":"5353141430","pt":1646209686672,"mc":[{"id":"1.195453767","rc":[{"atl":[[2.24,0]],"id":42154339}],"con":true,"img":false}]}
{"op":"mcm","clk":"5353141434","pt":1646209686775,"mc":[{"id":"1.195453767","rc":[{"atl":[[2.22,0],[2.42,60.66],[2.2,30.32]],"id":42154339}],"con":true,"img":false}]}
{"op":"mcm","clk":"5353141667","pt":1646209690196,"mc":[{"id":"1.195453767","rc":[{"atb":[[2.12,0],[2.16,86.21]],"id":41818763}],"con":true,"img":false}]}
{"op":"mcm","clk":"5353141725","pt":1646209690918,"mc":[{"id":"1.195453767","rc":[{"atb":[[1.72,0],[1.77,61.51]],"id":39637621}],"con":true,"img":false}]}
{"op":"mcm","clk":"5353141766","pt":1646209691395,"mc":[{"id":"1.195453767","rc":[{"atb":[[1.26,0]],"id":42154339}],"con":true,"img":false}]}
{"op":"mcm","clk":"5353141773","pt":1646209691497,"mc":[{"id":"1.195453767","rc":[{"atb":[[1.3,108.64]],"id":42154339}],"con":true,"img":false}]}
{"op":"mcm","clk":"5353141943","pt":1646209694081,"mc":[{"id":"1.195453767","rc":[{"atb":[[1.76,10.99]],"id":39637621},{"atb":[[1.29,28.79]],"id":42154339}],"con":true,"img":false}]}
{"op":"mcm","clk":"5353142318","pt":1646209699998,"mc":[{"id":"1.195453767","rc":[{"atb":[[1.81,9.29]],"id":39637621},{"atb":[[1.33,22.8]],"id":42154339},{"atl":[[2.2,0]],"id":42154339}],"con":true,"img":false}]}
{"op":"mcm","clk":"5353142323","pt":1646209700100,"mc":[{"id":"1.195453767","rc":[{"atl":[[2.4,30.32]],"id":42154339}],"con":true,"img":false}]}
{"op":"mcm","clk":"5353142719","pt":1646209707398,"mc":[{"id":"1.195453767","rc":[{"atb":[[1.3,0]],"id":42154339}],"con":true,"img":false}]}
{"op":"mcm","clk":"5353142724","pt":1646209707502,"mc":[{"id":"1.195453767","rc":[{"atb":[[1.26,108.64]],"id":42154339}],"con":true,"img":false}]}
{"op":"mcm","clk":"5353142811","pt":1646209709118,"mc":[{"id":"1.195453767","rc":[{"spn":2.5,"spf":"NaN","id":39637621},{"atb":[[1.33,0]],"id":42154339},{"spn":1.84,"spf":"NaN","id":42154339}],"con":true,"img":false}]}
{"op":"mcm","clk":"5353142860","pt":1646209709900,"mc":[{"id":"1.195453767","rc":[{"atb":[[1.76,0]],"id":39637621}],"con":true,"img":false}]}
{"op":"mcm","clk":"5353142987","pt":1646209711917,"mc":[{"id":"1.195453767","rc":[{"atl":[[2.42,0],[2.38,30.33]],"id":42154339}],"con":true,"img":false}]}
{"op":"mcm","clk":"5353143184","pt":1646209715065,"mc":[{"id":"1.195453767","rc":[{"atb":[[1.29,54.74]],"id":42154339}],"con":true,"img":false}]}
{"op":"mcm","clk":"5353143243","pt":1646209715923,"mc":[{"id":"1.195453767","rc":[{"atb":[[1.79,61.51],[1.77,0]],"id":39637621}],"con":true,"img":false}]}
{"op":"mcm","clk":"5353143337","pt":1646209718190,"mc":[{"id":"1.195453767","rc":[{"atb":[[1.81,0]],"id":39637621}],"con":true,"img":false}]}
{"op":"mcm","clk":"5353143342","pt":1646209718293,"mc":[{"id":"1.195453767","rc":[{"atb":[[1.72,123.02],[1.79,0]],"id":39637621}],"con":true,"img":false}]}
{"op":"mcm","clk":"5353143766","pt":1646209727106,"mc":[{"id":"1.195453767","rc":[{"atb":[[1.76,9.9]],"id":39637621}],"con":true,"img":false}]}
{"op":"mcm","clk":"5353143992","pt":1646209731360,"mc":[{"id":"1.195453767","rc":[{"atb":[[3.7,31.92],[4.7,0]],"id":42162698},{"atl":[[70,0.34],[46,2]],"id":42162698},{"atb":[[1.93,107.53]],"id":41818763},{"atb":[[4,0]],"id":41910350},{"atl":[[60,0]],"id":41910350},{"atb":[[2.66,0]],"id":43167133},{"atb":[[2.08,0]],"id":42688787},{"atl":[[7.8,1.77]],"id":42688787}],"con":true,"img":false}]}
{"op":"mcm","clk":"5353143999","pt":1646209731459,"mc":[{"id":"1.195453767","rc":[{"atb":[[4.6,27.78],[3.7,0]],"id":42162698},{"atb":[[2.24,50.49],[1.93,0],[2.16,0]],"id":41818763},{"atb":[[3.2,39.3]],"id":41910350},{"atl":[[28,2.73]],"id":41910350},{"atb":[[2.52,52.92]],"id":43167133},{"atb":[[1.36,72.11]],"id":42688787},{"atl":[[8.8,7.56]],"id":42688787}],"con":true,"img":false}]}
{"op":"mcm","clk":"5353144082","pt":1646209733159,"mc":[{"id":"1.195453767","rc":[{"atb":[[2.28,6.52]],"id":41818763}],"con":true,"img":false}]}
{"op":"mcm","clk":"5353144114","pt":1646209733827,"mc":[{"id":"1.195453767","rc":[{"atb":[[1.76,20.89]],"id":39637621}],"con":true,"img":false}]}
{"op":"mcm","clk":"5353144396","pt":1646209739144,"mc":[{"id":"1.195453767","rc":[{"atb":[[2.3,7.45]],"id":41818763}],"con":true,"img":false}]}
{"op":"mcm","clk":"5353144461","pt":1646209740545,"mc":[{"id":"1.195453767","rc":[{"atl":[[2.4,0]],"id":42154339}],"con":true,"img":false}]}
{"op":"mcm","clk":"5353144467","pt":1646209740642,"mc":[{"id":"1.195453767","rc":[{"atl":[[2.36,30.32],[2.42,60.66]],"id":42154339}],"con":true,"img":false}]}
{"op":"mcm","clk":"5353144473","pt":1646209740745,"mc":[{"id":"1.195453767","rc":[{"atl":[[2.42,0],[2.38,0],[2.34,30.33]],"id":42154339}],"con":true,"img":false}]}
{"op":"mcm","clk":"5353144625","pt":1646209743074,"mc":[{"id":"1.195453767","rc":[{"atb":[[1.72,0],[1.77,61.51]],"id":39637621}],"con":true,"img":false}]}
{"op":"mcm","clk":"5353144680","pt":1646209744162,"mc":[{"id":"1.195453767","rc":[{"atb":[[1.71,0]],"id":39637621},{"atb":[[1.26,0]],"id":42154339}],"con":true,"img":false}]}
{"op":"mcm","clk":"5353144684","pt":1646209744263,"mc":[{"id":"1.195453767","rc":[{"atb":[[1.73,61.5]],"id":39637621},{"atb":[[1.3,108.64]],"id":42154339}],"con":true,"img":false}]}
{"op":"mcm","clk":"5353144715","pt":1646209745042,"mc":[{"id":"1.195453767","rc":[{"atb":[[2.28,0]],"id":41818763},{"atb":[[1.29,25.94]],"id":42154339}],"con":true,"img":false}]}
{"op":"mcm","clk":"5353144724","pt":1646209745254,"mc":[{"id":"1.195453767","rc":[{"atb":[[1.76,10.99]],"id":39637621},{"atb":[[1.29,0]],"id":42154339}],"con":true,"img":false}]}
{"op":"mcm","clk":"5353145024","pt":1646209751183,"mc":[{"id":"1.195453767","rc":[{"atb":[[1.81,9.29]],"id":39637621},{"atb":[[1.33,22.8]],"id":42154339}],"con":true,"img":false}]}
{"op":"mcm","clk":"5353145036","pt":1646209751343,"mc":[{"id":"1.195453767","rc":[{"atb":[[1.8,61.51],[1.77,0]],"id":39637621}],"con":true,"img":false}]}
{"op":"mcm","clk":"5353145191","pt":1646209754372,"mc":[{"id":"1.195453767","rc":[{"atb":[[1.81,0]],"id":39637621}],"con":true,"img":false}]}
{"op":"mcm","clk":"5353145224","pt":1646209755191,"mc":[{"id":"1.195453767","rc":[{"atb":[[1.76,0]],"id":39637621}],"con":true,"img":false}]}
{"op":"mcm","clk":"5353145231","pt":1646209755293,"mc":[{"id":"1.195453767","rc":[{"atb":[[2.3,13.88]],"id":41818763}],"con":true,"img":false}]}
{"op":"mcm","clk":"5353145259","pt":1646209756066,"mc":[{"id":"1.195453767","rc":[{"atb":[[4,33.33],[3.2,0]],"id":41910350},{"atb":[[2.52,0],[2.94,41.48]],"id":43167133},{"atb":[[1.36,0],[1.71,72.11]],"id":42688787},{"atl":[[8.8,0],[7.8,3.77]],"id":42688787}],"con":true,"img":false}]}
{"op":"mcm","clk":"5353145282","pt":1646209756477,"mc":[{"id":"1.195453767","rc":[{"atb":[[1.74,123.02]],"id":39637621}],"con":true,"img":false}]}
{"op":"mcm","clk":"5353145290","pt":1646209756581,"mc":[{"id":"1.195453767","rc":[{"atb":[[1.8,0]],"id":39637621}],"con":true,"img":false}]}
{"op":"mcm","clk":"5353145400","pt":1646209758898,"mc":[{"id":"1.195453767","rc":[{"atb":[[1.3,0]],"id":42154339}],"con":true,"img":false}]}
{"op":"mcm","clk":"5353145405","pt":1646209759002,"mc":[{"id":"1.195453767","rc":[{"atb":[[1.26,108.64]],"id":42154339}],"con":true,"img":false}]}
{"op":"mcm","clk":"5353145469","pt":1646209760186,"mc":[{"id":"1.195453767","rc":[{"atb":[[1.33,0]],"id":42154339}],"con":true,"img":false}]}
{"op":"mcm","clk":"5353145536","pt":1646209761894,"mc":[{"id":"1.195453767","rc":[{"atl":[[29,0.86]],"id":41910350},{"atb":[[2.22,0]],"id":41818763}],"con":true,"img":false}]}
{"op":"mcm","clk":"5353145541","pt":1646209761986,"mc":[{"id":"1.195453767","rc":[{"atl":[[27,2.72]],"id":41910350},{"atb":[[2.26,38.99]],"id":41818763}],"con":true,"img":false}]}
{"op":"mcm","clk":"5353145604","pt":1646209763300,"mc":[{"id":"1.195453767","rc":[{"atb":[[2.3,8.09]],"id":41818763}],"con":true,"img":false}]}
{"op":"mcm","clk":"5353146053","pt":1646209771908,"mc":[{"id":"1.195453767","rc":[{"atb":[[1.73,0]],"id":39637621},{"spn":2.47,"spf":"NaN","id":39637621},{"atl":[[2.36,0]],"id":42154339},{"spn":1.8,"spf":"NaN","id":42154339}],"con":true,"img":false}]}
{"op":"mcm","clk":"5353146058","pt":1646209772009,"mc":[{"id":"1.195453767","rc":[{"atb":[[1.74,0],[1.75,61.5],[1.71,140.85]],"id":39637621},{"atl":[[2.32,30.32],[2.42,60.66],[2.34,0]],"id":42154339}],"con":true,"img":false}]}
{"op":"mcm","clk":"5353146450","pt":1646209780203,"mc":[{"id":"1.195453767","rc":[{"atb":[[2.3,1.67]],"id":41818763}],"con":true,"img":false}]}
{"op":"mcm","clk":"5353146469","pt":1646209780510,"mc":[{"id":"1.195453767","rc":[{"atb":[[1.29,28.79]],"id":42154339}],"con":true,"img":false}]}
{"op":"mcm","clk":"5353146657","pt":1646209784323,"mc":[{"id":"1.195453767","rc":[{"atb":[[2.3,0]],"id":41818763},{"atl":[[6.4,6.82],[6.8,0]],"id":41818763}],"con":true,"img":false}]}
{"op":"mcm","clk":"5353146662","pt":1646209784426,"mc":[{"id":"1.195453767","rc":[{"atb":[[2.28,1.67]],"id":41818763}],"con":true,"img":false}]}
{"op":"mcm","clk":"5353146704","pt":1646209785308,"mc":[{"id":"1.195453767","rc":[{"atb":[[1.75,0]],"id":39637621},{"atl":[[6.6,0]],"id":41818763}],"con":true,"img":false}]}
{"op":"mcm","clk":"5353146708","pt":1646209785413,"mc":[{"id":"1.195453767","rc":[{"atb":[[1.72,61.5]],"id":39637621},{"atl":[[7.6,6.82]],"id":41818763}],"con":true,"img":false}]}
{"op":"mcm","clk":"5353146796","pt":1646209787351,"mc":[{"id":"1.195453767","rc":[{"atb":[[2.32,6.33]],"id":41818763}],"con":true,"img":false}]}
{"op":"mcm","clk":"5353147034","pt":1646209791427,"mc":[{"id":"1.195453767","rc":[{"atb":[[2.28,0]],"id":41818763}],"con":true,"img":false}]}
{"op":"mcm","clk":"5353147052","pt":1646209791635,"mc":[{"id":"1.195453767","rc":[{"atb":[[2.34,1.67]],"id":41818763}],"con":true,"img":false}]}
{"op":"mcm","clk":"5353147294","pt":1646209796271,"mc":[{"id":"1.195453767","rc":[{"atb":[[1.73,86.56],[1.71,0]],"id":39637621},{"atl":[[2.3,30.33],[2.42,0]],"id":42154339}],"con":true,"img":false}]}
{"op":"mcm","clk":"5353147657","pt":1646209802645,"mc":[{"id":"1.195453767","rc":[{"atb":[[1.77,9.77]],"id":39637621},{"atb":[[2.32,12.03]],"id":41818763},{"atb":[[1.29,54.74]],"id":42154339}],"con":true,"img":false}]}
{"op":"mcm","clk":"5353147664","pt":1646209802750,"mc":[{"id":"1.195453767","rc":[{"atb":[[1.73,0],[1.78,61.51]],"id":39637621}],"con":true,"img":false}]}
{"op":"mcm","clk":"5353147864","pt":1646209805880,"mc":[{"id":"1.195453767","rc":[{"atb":[[1.77,0]],"id":39637621}],"con":true,"img":false}]}
{"op":"mcm","clk":"5353147870","pt":1646209806038,"mc":[{"id":"1.195453767","rc":[{"atb":[[1.73,123.02],[1.78,0]],"id":39637621}],"con":true,"img":false}]}
{"op":"mcm","clk":"5353148104","pt":1646209810748,"mc":[{"id":"1.195453767","rc":[{"atb":[[2.82,0]],"id":43167133}],"con":true,"img":false}]}
{"op":"mcm","clk":"5353148109","pt":1646209810850,"mc":[{"id":"1.195453767","rc":[{"atb":[[2.96,30.05]],"id":43167133}],"con":true,"img":false}]}
{"op":"mcm","clk":"5353148314","pt":1646209814671,"mc":[{"id":"1.195453767","rc":[{"atb":[[1.77,9.77]],"id":39637621}],"con":true,"img":false}]}
{"op":"mcm","clk":"5353148322","pt":1646209814774,"mc":[{"id":"1.195453767","rc":[{"atb":[[1.73,0],[1.78,61.51]],"id":39637621}],"con":true,"img":false}]}
{"op":"mcm","clk":"5353148478","pt":1646209817764,"mc":[{"id":"1.195453767","rc":[{"atb":[[1.77,0]],"id":39637621}],"con":true,"img":false}]}
{"op":"mcm","clk":"5353148576","pt":1646209819980,"mc":[{"id":"1.195453767","rc":[{"atb":[[1.73,123.02],[1.78,0]],"id":39637621}],"con":true,"img":false}]}
{"op":"mcm","clk":"5353148668","pt":1646209821375,"mc":[{"id":"1.195453767","rc":[{"atb":[[1.77,10.84]],"id":39637621}],"con":true,"img":false}]}
{"op":"mcm","clk":"5353148938","pt":1646209826685,"mc":[{"id":"1.195453767","rc":[{"atb":[[1.77,20.62]],"id":39637621}],"con":true,"img":false}]}
{"op":"mcm","clk":"5353148986","pt":1646209827873,"mc":[{"id":"1.195453767","rc":[{"atb":[[1.72,0]],"id":39637621},{"atl":[[2.32,0]],"id":42154339}],"con":true,"img":false}]}
{"op":"mcm","clk":"5353148992","pt":1646209827977,"mc":[{"id":"1.195453767","rc":[{"atb":[[1.74,61.5]],"id":39637621},{"atl":[[2.42,60.66],[2.28,30.32]],"id":42154339}],"con":true,"img":false}]}
{"op":"mcm","clk":"5353148995","pt":1646209828081,"mc":[{"id":"1.195453767","rc":[{"atl":[[2.3,0]],"id":42154339}],"con":true,"img":false}]}
{"op":"mcm","clk":"5353149071","pt":1646209829686,"mc":[{"id":"1.195453767","rc":[{"atb":[[1.77,10.84]],"id":39637621}],"con":true,"img":false}]}
{"op":"mcm","clk":"5353149211","pt":1646209832070,"mc":[{"id":"1.195453767","rc":[{"spn":2.48,"spf":"NaN","id":39637621},{"spn":3.92,"spf":"NaN","id":41818763},{"atb":[[1.26,0]],"id":42154339},{"spn":1.78,"spf":"NaN","id":42154339}],"con":true,"img":false}]}
{"op":"mcm","clk":"5353149218","pt":1646209832170,"mc":[{"id":"1.195453767","rc":[{"atb":[[1.3,108.64]],"id":42154339}],"con":true,"img":false}]}
{"op":"mcm","clk":"5353149252","pt":1646209832685,"mc":[{"id":"1.195453767","rc":[{"atb":[[1.29,28.79]],"id":42154339}],"con":true,"img":false}]}
{"op":"mcm","clk":"5353149386","pt":1646209835608,"mc":[{"id":"1.195453767","rc":[{"atb":[[1.78,9.64]],"id":39637621}],"con":true,"img":false}]}
{"op":"mcm","clk":"5353149548","pt":1646209838610,"mc":[{"id":"1.195453767","rc":[{"atb":[[1.73,0],[1.79,10.85]],"id":39637621}],"con":true,"img":false}]}
{"op":"mcm","clk":"5353149555","pt":1646209838712,"mc":[{"id":"1.195453767","rc":[{"atb":[[1.33,22.8]],"id":42154339}],"con":true,"img":false}]}
{"op":"mcm","clk":"5353149644","pt":1646209840122,"mc":[{"id":"1.195453767","rc":[{"atl":[[2.28,0]],"id":42154339}],"con":true,"img":false}]}
{"op":"mcm","clk":"5353149650","pt":1646209840224,"mc":[{"id":"1.195453767","rc":[{"atl":[[2.4,30.32]],"id":42154339}],"con":true,"img":false}]}
{"op":"mcm","clk":"5353149884","pt":1646209844623,"mc":[{"id":"1.195453767","rc":[{"atb":[[1.77,0]],"id":39637621}],"con":true,"img":false}]}
{"op":"mcm","clk":"5353150309","pt":1646209851614,"mc":[{"id":"1.195453767","rc":[{"atl":[[2.42,0],[2.38,30.33]],"id":42154339}],"con":true,"img":false}]}
{"op":"mcm","clk":"5353150545","pt":1646209857041,"mc":[{"id":"1.195453767","rc":[{"atb":[[1.29,0]],"id":42154339}],"con":true,"img":false}]}
{"op":"mcm","clk":"5353150550","pt":1646209857143,"mc":[{"id":"1.195453767","rc":[{"atb":[[1.78,20.35]],"id":39637621}],"con":true,"img":false}]}
{"op":"mcm","clk":"5353151156","pt":1646209868446,"mc":[{"id":"1.195453767","rc":[{"atb":[[1.33,48.1]],"id":42154339}],"con":true,"img":false}]}
{"op":"mcm","clk":"5353151741","pt":1646209878164,"mc":[{"id":"1.195453767","rc":[{"atb":[[1.74,0]],"id":39637621},{"atb":[[1.3,0]],"id":42154339}],"con":true,"img":false}]}
{"op":"mcm","clk":"5353151746","pt":1646209878267,"mc":[{"id":"1.195453767","rc":[{"atb":[[1.71,61.5]],"id":39637621},{"atb":[[1.26,108.64]],"id":42154339}],"con":true,"img":false}]}
{"op":"mcm","clk":"5353151892","pt":1646209880851,"mc":[{"id":"1.195453767","rc":[{"atb":[[1.78,10.7]],"id":39637621},{"atb":[[1.33,25.3]],"id":42154339}],"con":true,"img":false}]}
{"op":"mcm","clk":"5353152208","pt":1646209886963,"mc":[{"id":"1.195453767","rc":[{"atb":[[1.75,10.03]],"id":39637621},{"atb":[[1.29,25.94]],"id":42154339}],"con":true,"img":false}]}
{"op":"mcm","clk":"5353152456","pt":1646209891281,"mc":[{"id":"1.195453767","rc":[{"atb":[[4.8,0]],"id":42162698}],"con":true,"img":false}]}
{"op":"mcm","clk":"5353152467","pt":1646209891386,"mc":[{"id":"1.195453767","rc":[{"atb":[[5.1,15.96]],"id":42162698}],"con":true,"img":false}]}
{"op":"mcm","clk":"5353152826","pt":1646209898376,"mc":[{"id":"1.195453767","rc":[{"atb":[[1.78,0]],"id":39637621},{"spn":2.49,"spf":"NaN","id":39637621},{"atb":[[1.33,0]],"id":42154339},{"spn":1.83,"spf":"NaN","id":42154339}],"con":true,"img":false}]}
{"op":"mcm","clk":"5353152829","pt":1646209898478,"mc":[{"id":"1.195453767","rc":[{"atb":[[1.79,0],[1.76,61.51]],"id":39637621}],"con":true,"img":false}]}
{"op":"mcm","clk":"5353152852","pt":1646209899094,"mc":[{"id":"1.195453767","rc":[{"atb":[[1.75,0]],"id":39637621}],"con":true,"img":false}]}
{"op":"mcm","clk":"5353153057","pt":1646209903609,"mc":[{"id":"1.195453767","rc":[{"atb":[[1.72,123.02],[1.76,0]],"id":39637621}],"con":true,"img":false}]}
{"op":"mcm","clk":"5353153097","pt":1646209904382,"mc":[{"id":"1.195453767","rc":[{"atb":[[2.24,0],[2.16,86.21]],"id":41818763},{"atl":[[6.4,0],[7,11.52]],"id":41818763},{"atb":[[4,0],[3.7,37.04]],"id":41910350},{"atb":[[2.78,52.92],[2.94,0]],"id":43167133},{"atb":[[1.57,72.11],[1.71,0]],"id":42688787},{"atl":[[8,7.56],[7.8,1.77]],"id":42688787}],"con":true,"img":false}]}
{"op":"mcm","clk":"5353153119","pt":1646209904895,"mc":[{"id":"1.195453767","rc":[{"atb":[[5.1,0]],"id":42162698},{"atb":[[2.96,0]],"id":43167133},{"atl":[[2.4,0]],"id":42154339}],"con":true,"img":false}]}
{"op":"mcm","clk":"5353153127","pt":1646209904997,"mc":[{"id":"1.195453767","rc":[{"atb":[[4.7,15.96]],"id":42162698},{"atb":[[2.8,30.05]],"id":43167133},{"atl":[[2.36,30.32],[2.42,60.66]],"id":42154339}],"con":true,"img":false}]}
{"op":"mcm","clk":"5353153137","pt":1646209905099,"mc":[{"id":"1.195453767","rc":[{"atl":[[2.38,0]],"id":42154339}],"con":true,"img":false}]}
{"op":"mcm","clk":"5353153250","pt":1646209907481,"mc":[{"id":"1.195453767","rc":[{"atb":[[1.29,54.74]],"id":42154339}],"con":true,"img":false}]}
{"op":"mcm","clk":"5353153270","pt":1646209907993,"mc":[{"id":"1.195453767","rc":[{"atb":[[2.26,0]],"id":41818763}],"con":true,"img":false}]}
{"op":"mcm","clk":"5353153279","pt":1646209908099,"mc":[{"id":"1.195453767","rc":[{"atb":[[2.22,38.99]],"id":41818763}],"con":true,"img":false}]}
{"op":"mcm","clk":"5353153338","pt":1646209909489,"mc":[{"id":"1.195453767","rc":[{"atl":[[9.6,9.34]],"id":42688787}],"con":true,"img":false}]}
{"op":"mcm","clk":"5353153344","pt":1646209909596,"mc":[{"id":"1.195453767","rc":[{"atl":[[8,0]],"id":42688787}],"con":true,"img":false}]}
{"op":"mcm","clk":"5353153431","pt":1646209911191,"mc":[{"id":"1.195453767","rc":[{"atb":[[1.76,9.9]],"id":39637621}],"con":true,"img":false}]}
{"op":"mcm","clk":"5353153434","pt":1646209911289,"mc":[{"id":"1.195453767","rc":[{"atb":[[2.32,6.33]],"id":41818763}],"con":true,"img":false}]}
{"op":"mcm","clk":"5353153667","pt":1646209917088,"mc":[{"id":"1.195453767","rc":[{"atb":[[2.28,5.87]],"id":41818763}],"con":true,"img":false}]}
{"op":"mcm","clk":"5353153751","pt":1646209918928,"mc":[{"id":"1.195453767","rc":[{"atb":[[1.76,20.89]],"id":39637621}],"con":true,"img":false}]}
{"op":"mcm","clk":"5353154130","pt":1646209926507,"mc":[{"id":"1.195453767","rc":[{"atb":[[1.72,0],[1.77,61.51]],"id":39637621}],"con":true,"img":false}]}
{"op":"mcm","clk":"5353154196","pt":1646209927833,"mc":[{"id":"1.195453767","rc":[{"atl":[[2.42,0],[2.34,30.33]],"id":42154339}],"con":true,"img":false}]}
{"op":"mcm","clk":"5353154268","pt":1646209929224,"mc":[{"id":"1.195453767","rc":[{"atb":[[1.76,10.99]],"id":39637621}],"con":true,"img":false}]}
{"op":"mcm","clk":"5353154437","pt":1646209932329,"mc":[{"id":"1.195453767","rc":[{"atl":[[8,4.16]],"id":42688787}],"con":true,"img":false}]}
{"op":"mcm","clk":"5353154443","pt":1646209932425,"mc":[{"id":"1.195453767","rc":[{"atl":[[9.6,0]],"id":42688787}],"con":true,"img":false}]}
{"op":"mcm","clk":"5353154521","pt":1646209934119,"mc":[{"id":"1.195453767","rc":[{"atb":[[1.71,0]],"id":39637621}],"con":true,"img":false}]}
{"op":"mcm","clk":"5353154527","pt":1646209934220,"mc":[{"id":"1.195453767","rc":[{"atb":[[1.73,61.5]],"id":39637621}],"con":true,"img":false}]}
{"op":"mcm","clk":"5353154580","pt":1646209935305,"mc":[{"id":"1.195453767","rc":[{"atb":[[1.81,9.29]],"id":39637621}],"con":true,"img":false}]}
{"op":"mcm","clk":"5353154849","pt":1646209940141,"mc":[{"id":"1.195453767","rc":[{"atb":[[1.76,0]],"id":39637621},{"atb":[[2.32,0]],"id":41818763}],"con":true,"img":false}]}
{"op":"mcm","clk":"5353155122","pt":1646209945465,"mc":[{"id":"1.195453767","rc":[{"atb":[[1.73,0]],"id":39637621},{"atb":[[2.34,0]],"id":41818763},{"atl":[[7.6,0]],"id":41818763},{"atb":[[1.26,0]],"id":42154339}],"con":true,"img":false}]}
{"op":"mcm","clk":"5353155126","pt":1646209945527,"mc":[{"id":"1.195453767","rc":[{"atb":[[1.71,61.5]],"id":39637621},{"atb":[[2.3,1.67]],"id":41818763},{"atl":[[6.8,6.82]],"id":41818763},{"atb":[[1.3,108.64]],"id":42154339}],"con":true,"img":false}]}
{"op":"mcm","clk":"5353155208","pt":1646209947264,"mc":[{"id":"1.195453767","rc":[{"atb":[[1.29,28.79]],"id":42154339}],"con":true,"img":false}]}
{"op":"mcm","clk":"5353155295","pt":1646209949168,"mc":[{"id":"1.195453767","rc":[{"atb":[[1.8,61.51],[1.77,0]],"id":39637621}],"con":true,"img":false}]}
{"op":"mcm","clk":"5353155368","pt":1646209950457,"mc":[{"id":"1.195453767","rc":[{"atb":[[1.81,0]],"id":39637621}],"con":true,"img":false}]}
{"op":"mcm","clk":"5353155475","pt":1646209952369,"mc":[{"id":"1.195453767","rc":[{"atb":[[2.28,12.4]],"id":41818763}],"con":true,"img":false}]}
{"op":"mcm","clk":"5353155537","pt":1646209953247,"mc":[{"id":"1.195453767","rc":[{"atb":[[1.33,22.8]],"id":42154339}],"con":true,"img":false}]}
{"op":"mcm","clk":"5353155595","pt":1646209954271,"mc":[{"id":"1.195453767","rc":[{"atb":[[1.72,123.02]],"id":39637621}],"con":true,"img":false}]}
{"op":"mcm","clk":"5353155600","pt":1646209954370,"mc":[{"id":"1.195453767","rc":[{"atb":[[1.8,0]],"id":39637621}],"con":true,"img":false}]}
{"op":"mcm","clk":"5353155994","pt":1646209962496,"mc":[{"id":"1.195453767","rc":[{"atb":[[1.76,9.9]],"id":39637621},{"spn":2.48,"spf":"NaN","id":39637621},{"spn":3.9,"spf":"NaN","id":41818763}],"con":true,"img":false}]}
{"op":"mcm","clk":"5353156004","pt":1646209962654,"mc":[{"id":"1.195453767","rc":[{"atb":[[1.3,0]],"id":42154339},{"atl":[[2.36,0]],"id":42154339}],"con":true,"img":false}]}
{"op":"mcm","clk":"5353156015","pt":1646209962761,"mc":[{"id":"1.195453767","rc":[{"atb":[[1.26,108.64]],"id":42154339},{"atl":[[2.32,30.32],[2.42,60.66],[2.34,0]],"id":42154339}],"con":true,"img":false}]}
{"op":"mcm","clk":"5353156030","pt":1646209962968,"mc":[{"id":"1.195453767","rc":[{"atl":[[2.3,30.33],[2.42,0]],"id":42154339}],"con":true,"img":false}]}
{"op":"mcm","clk":"5353156152","pt":1646209965279,"mc":[{"id":"1.195453767","rc":[{"atb":[[1.33,0]],"id":42154339}],"con":true,"img":false}]}
{"op":"mcm","clk":"5353156472","pt":1646209971301,"mc":[{"id":"1.195453767","rc":[{"atb":[[1.29,54.74]],"id":42154339}],"con":true,"img":false}]}
{"op":"mcm","clk":"5353156500","pt":1646209971672,"mc":[{"id":"1.195453767","rc":[{"atb":[[1.72,0],[1.77,61.51]],"id":39637621}],"con":true,"img":false}]}
{"op":"mcm","clk":"5353156643","pt":1646209974406,"mc":[{"id":"1.195453767","rc":[{"atb":[[1.76,0]],"id":39637621}],"con":true,"img":false}]}
{"op":"mcm","clk":"5353156761","pt":1646209976881,"mc":[{"id":"1.195453767","rc":[{"atb":[[1.72,123.02],[1.77,0]],"id":39637621}],"con":true,"img":false}]}
{"op":"mcm","clk":"5353157235","pt":1646209984992,"mc":[{"id":"1.195453767","rc":[{"atb":[[1.71,0]],"id":39637621}],"con":true,"img":false}]}
{"op":"mcm","clk":"5353157243","pt":1646209985095,"mc":[{"id":"1.195453767","rc":[{"atb":[[1.73,61.5],[1.72,0],[1.71,140.85]],"id":39637621}],"con":true,"img":false}]}
{"op":"mcm","clk":"5353157565","pt":1646209991400,"mc":[{"id":"1.195453767","rc":[{"atb":[[1.77,9.77]],"id":39637621}],"con":true,"img":false}]}
{"op":"mcm","clk":"5353157713","pt":1646209993611,"mc":[{"id":"1.195453767","rc":[{"atb":[[2.24,50.49],[2.16,0]],"id":41818763},{"atl":[[7,2.01],[6.6,7.87]],"id":41818763},{"atb":[[4,33.33],[3.7,0]],"id":41910350},{"atb":[[2.94,41.48]],"id":43167133},{"atb":[[1.57,0],[1.71,72.11]],"id":42688787}],"con":true,"img":false}]}
{"op":"mcm","clk":"5353157721","pt":1646209993712,"mc":[{"id":"1.195453767","rc":[{"atb":[[2.78,0]],"id":43167133}],"con":true,"img":false}]}
{"op":"mcm","clk":"5353157766","pt":1646209994484,"mc":[{"id":"1.195453767","rc":[{"atb":[[2.28,6.52]],"id":41818763}],"con":true,"img":false}]}
{"op":"mcm","clk":"5353157951","pt":1646209998046,"mc":[{"id":"1.195453767","rc":[{"atb":[[1.73,0]],"id":39637621},{"atl":[[2.32,0]],"id":42154339}],"con":true,"img":false}]}
{"op":"mcm","clk":"5353157957","pt":1646209998099,"mc":[{"id":"1.195453767","rc":[{"atb":[[1.72,61.5]],"id":39637621},{"atl":[[2.28,30.32]],"id":42154339}],"con":true,"img":false}]}
{"op":"mcm","clk":"5353157964","pt":1646209998203,"mc":[{"id":"1.195453767","rc":[{"atl":[[2.3,0],[2.42,60.66]],"id":42154339}],"con":true,"img":false}]}
{"op":"mcm","clk":"5353157975","pt":1646209998304,"mc":[{"id":"1.195453767","rc":[{"atl":[[2.26,30.33]],"id":42154339}],"con":true,"img":false}]}
{"op":"mcm","clk":"5353157981","pt":1646209998411,"mc":[{"id":"1.195453767","rc":[{"atl":[[2.42,0]],"id":42154339}],"con":true,"img":false}]}
{"op":"mcm","clk":"5353158077","pt":1646210000317,"mc":[{"id":"1.195453767","rc":[{"atb":[[2.3,7.45]],"id":41818763}],"con":true,"img":false}]}
{"op":"mcm","clk":"5353158081","pt":1646210000420,"mc":[{"id":"1.195453767","rc":[{"atb":[[1.77,0]],"id":39637621}],"con":true,"img":false}]}
{"op":"mcm","clk":"5353158427","pt":1646210006403,"mc":[{"id":"1.195453767","rc":[{"atb":[[1.76,9.9]],"id":39637621}],"con":true,"img":false}]}
{"op":"mcm","clk":"5353158467","pt":1646210007228,"mc":[{"id":"1.195453767","rc":[{"atb":[[1.77,61.51],[1.71,0]],"id":39637621}],"con":true,"img":false}]}
{"op":"mcm","clk":"5353158565","pt":1646210009446,"mc":[{"id":"1.195453767","rc":[{"atb":[[1.76,0]],"id":39637621}],"con":true,"img":false}]}
{"op":"mcm","clk":"5353158574","pt":1646210009603,"mc":[{"id":"1.195453767","rc":[{"atb":[[1.73,123.02],[1.77,0]],"id":39637621}],"con":true,"img":false}]}
{"op":"mcm","clk":"5353158603","pt":1646210010348,"mc":[{"id":"1.195453767","rc":[{"atb":[[1.26,0]],"id":42154339}],"con":true,"img":false}]}
{"op":"mcm","clk":"5353158605","pt":1646210010401,"mc":[{"id":"1.195453767","rc":[{"atb":[[1.3,108.64]],"id":42154339}],"con":true,"img":false}]}
{"op":"mcm","clk":"5353158734","pt":1646210012418,"mc":[{"id":"1.195453767","rc":[{"atb":[[1.29,28.79]],"id":42154339}],"con":true,"img":false}]}
{"op":"mcm","clk":"5353158868","pt":1646210014424,"mc":[{"id":"1.195453767","rc":[{"atb":[[2.28,0]],"id":41818763},{"atb":[[1.29,0]],"id":42154339}],"con":true,"img":false}]}
{"op":"mcm","clk":"5353159090","pt":1646210018535,"mc":[{"id":"1.195453767","rc":[{"atb":[[1.77,9.77]],"id":39637621},{"atb":[[1.33,22.8]],"id":42154339}],"con":true,"img":false}]}
{"op":"mcm","clk":"5353159096","pt":1646210018638,"mc":[{"id":"1.195453767","rc":[{"atb":[[1.78,61.51]],"id":39637621}],"con":true,"img":false}]}
{"op":"mcm","clk":"5353159101","pt":1646210018740,"mc":[{"id":"1.195453767","rc":[{"atb":[[1.73,0]],"id":39637621}],"con":true,"img":false}]}
{"op":"mcm","clk":"5353159218","pt":1646210021111,"mc":[{"id":"1.195453767","rc":[{"atb":[[1.3,0]],"id":42154339}],"con":true,"img":false}]}
{"op":"mcm","clk":"5353159223","pt":1646210021214,"mc":[{"id":"1.195453767","rc":[{"atb":[[1.26,108.64]],"id":42154339}],"con":true,"img":false}]}
{"op":"mcm","clk":"5353159289","pt":1646210022552,"mc":[{"id":"1.195453767","rc":[{"atb":[[1.77,0]],"id":39637621},{"spn":2.49,"spf":"NaN","id":39637621},{"atb":[[1.33,0]],"id":42154339},{"spn":1.76,"spf":"NaN","id":42154339}],"con":true,"img":false}]}
{"op":"mcm","clk":"5353159298","pt":1646210022755,"mc":[{"id":"1.195453767","rc":[{"atb":[[1.73,123.02]],"id":39637621}],"con":true,"img":false}]}
{"op":"mcm","clk":"5353159301","pt":1646210022859,"mc":[{"id":"1.195453767","rc":[{"atb":[[1.78,0]],"id":39637621}],"con":true,"img":false}]}
{"op":"mcm","clk":"5353159478","pt":1646210026827,"mc":[{"id":"1.195453767","rc":[{"atb":[[2.22,0]],"id":41818763},{"atl":[[6.8,0]],"id":41818763}],"con":true,"img":false}]}
{"op":"mcm","clk":"5353159483","pt":1646210026930,"mc":[{"id":"1.195453767","rc":[{"atb":[[2.26,38.99]],"id":41818763},{"atl":[[6.4,6.82]],"id":41818763}],"con":true,"img":false}]}
{"op":"mcm","clk":"5353159514","pt":1646210027438,"mc":[{"id":"1.195453767","rc":[{"atb":[[2.3,1.67]],"id":41818763}],"con":true,"img":false}]}
{"op":"mcm","clk":"5353159640","pt":1646210029457,"mc":[{"id":"1.195453767","rc":[{"atb":[[1.77,10.84]],"id":39637621},{"atb":[[2.3,0]],"id":41818763}],"con":true,"img":false}]}
{"op":"mcm","clk":"5353159649","pt":1646210029662,"mc":[{"id":"1.195453767","rc":[{"atb":[[2.28,1.67]],"id":41818763}],"con":true,"img":false}]}
{"op":"mcm","clk":"5353159700","pt":1646210030436,"mc":[{"id":"1.195453767","rc":[{"atb":[[1.77,20.62]],"id":39637621},{"atb":[[1.29,25.94]],"id":42154339}],"con":true,"img":false}]}
{"op":"mcm","clk":"5353159769","pt":1646210031568,"mc":[{"id":"1.195453767","rc":[{"atl":[[2.28,0]],"id":42154339}],"con":true,"img":false}]}
{"op":"mcm","clk":"5353159776","pt":1646210031622,"mc":[{"id":"1.195453767","rc":[{"atl":[[2.24,30.32]],"id":42154339}],"con":true,"img":false}]}
{"op":"mcm","clk":"5353159785","pt":1646210031724,"mc":[{"id":"1.195453767","rc":[{"atl":[[2.42,60.66],[2.26,0]],"id":42154339}],"con":true,"img":false}]}
{"op":"mcm","clk":"5353159893","pt":1646210033430,"mc":[{"id":"1.195453767","rc":[{"atb":[[2.32,5.7]],"id":41818763}],"con":true,"img":false}]}
{"op":"mcm","clk":"5353160029","pt":1646210036061,"mc":[{"id":"1.195453767","rc":[{"atl":[[6.4,0]],"id":41818763}],"con":true,"img":false}]}
{"op":"mcm","clk":"5353160036","pt":1646210036162,"mc":[{"id":"1.195453767","rc":[{"atl":[[7.6,6.82]],"id":41818763}],"con":true,"img":false}]}
{"op":"mcm","clk":"5353160045","pt":1646210036367,"mc":[{"id":"1.195453767","rc":[{"atb":[[2.28,0]],"id":41818763}],"con":true,"img":false}]}
{"op":"mcm","clk":"5353160058","pt":1646210036573,"mc":[{"id":"1.195453767","rc":[{"atb":[[2.34,1.67]],"id":41818763}],"con":true,"img":false}]}
{"op":"mcm","clk":"5353160293","pt":1646210041072,"mc":[{"id":"1.195453767","rc":[{"atb":[[1.72,0]],"id":39637621}],"con":true,"img":false}]}
{"op":"mcm","clk":"5353160299","pt":1646210041174,"mc":[{"id":"1.195453767","rc":[{"atb":[[1.74,61.5]],"id":39637621}],"con":true,"img":false}]}
{"op":"mcm","clk":"5353160371","pt":1646210042469,"mc":[{"id":"1.195453767","rc":[{"atb":[[1.77,10.84]],"id":39637621}],"con":true,"img":false}]}
{"op":"mcm","clk":"5353160488","pt":1646210044477,"mc":[{"id":"1.195453767","rc":[{"atb":[[1.73,0],[1.78,61.51]],"id":39637621}],"con":true,"img":false}]}
{"op":"mcm","clk":"5353160547","pt":1646210045760,"mc":[{"id":"1.195453767","rc":[{"atl":[[2.24,0]],"id":42154339}],"con":true,"img":false}]}
{"op":"mcm","clk":"5353160552","pt":1646210045867,"mc":[{"id":"1.195453767","rc":[{"atl":[[2.4,30.32]],"id":42154339}],"con":true,"img":false}]}
{"op":"mcm","clk":"5353160671","pt":1646210048179,"mc":[{"id":"1.195453767","rc":[{"atb":[[2.32,12.03]],"id":41818763},{"atb":[[1.29,54.74]],"id":42154339}],"con":true,"img":false}]}
{"op":"mcm","clk":"5353160780","pt":1646210050182,"mc":[{"id":"1.195453767","rc":[{"atb":[[2.8,0]],"id":43167133}],"con":true,"img":false}]}
{"op":"mcm","clk":"5353160785","pt":1646210050237,"mc":[{"id":"1.195453767","rc":[{"atb":[[2.96,30.05]],"id":43167133}],"con":true,"img":false}]}
{"op":"mcm","clk":"5353160839","pt":1646210051574,"mc":[{"id":"1.195453767","rc":[{"atb":[[1.82,9.18]],"id":39637621}],"con":true,"img":false}]}
{"op":"mcm","clk":"5353160946","pt":1646210053375,"mc":[{"id":"1.195453767","rc":[{"atl":[[2.42,0],[2.38,30.33]],"id":42154339}],"con":true,"img":false}]}
{"op":"mcm","clk":"5353161210","pt":1646210057956,"mc":[{"id":"1.195453767","rc":[{"atb":[[1.74,0]],"id":39637621},{"atb":[[1.83,73.98],[2.02,0]],"id":41818763},{"atl":[[2.62,0]],"id":42154339}],"con":true,"img":false}]}
{"op":"mcm","clk":"5353161216","pt":1646210058059,"mc":[{"id":"1.195453767","rc":[{"atb":[[1.71,61.5]],"id":39637621},{"atl":[[2.8,39.84]],"id":42154339}],"con":true,"img":false}]}
{"op":"mcm","clk":"5353161622","pt":1646210065980,"mc":[{"id":"1.195453767","rc":[{"atb":[[1.8,61.51],[1.78,0]],"id":39637621}],"con":true,"img":false}]}
{"op":"mcm","clk":"5353161699","pt":1646210067572,"mc":[{"id":"1.195453767","rc":[{"atb":[[5.4,0]],"id":42162698},{"atb":[[1.82,0]],"id":39637621},{"atb":[[2.26,0]],"id":41818763}],"con":true,"img":false}]}
{"op":"mcm","clk":"5353161706","pt":1646210067677,"mc":[{"id":"1.195453767","rc":[{"atb":[[5.1,10.39]],"id":42162698},{"atb":[[2.12,38.99]],"id":41818763}],"con":true,"img":false}]}
{"op":"mcm","clk":"5353161762","pt":1646210068666,"mc":[{"id":"1.195453767","rc":[{"atb":[[1.77,0]],"id":39637621}],"con":true,"img":false}]}
{"op":"mcm","clk":"5353161809","pt":1646210069604,"mc":[{"id":"1.195453767","rc":[{"atb":[[2.32,6.33]],"id":41818763}],"con":true,"img":false}]}
{"op":"mcm","clk":"5353161896","pt":1646210071194,"mc":[{"id":"1.195453767","rc":[{"atb":[[1.8,0],[1.72,123.02]],"id":39637621}],"con":true,"img":false}]}
{"op":"mcm","clk":"5353161906","pt":1646210071397,"mc":[{"id":"1.195453767","rc":[{"atb":[[5.5,0]],"id":42162698}],"con":true,"img":false}]}
{"op":"mcm","clk":"5353161911","pt":1646210071499,"mc":[{"id":"1.195453767","rc":[{"atb":[[5.2,1.67]],"id":42162698}],"con":true,"img":false}]}
{"op":"mcm","clk":"5353162101","pt":1646210075605,"mc":[{"id":"1.195453767","rc":[{"atb":[[2.3,5.78]],"id":41818763}],"con":true,"img":false}]}
{"op":"mcm","clk":"5353162281","pt":1646210078586,"mc":[{"id":"1.195453767","rc":[{"atb":[[1.76,9.9]],"id":39637621}],"con":true,"img":false}]}
{"op":"mcm","clk":"5353162442","pt":1646210081506,"mc":[{"id":"1.195453767","rc":[{"atb":[[2.32,0]],"id":41818763}],"con":true,"img":false}]}
{"op":"mcm","clk":"5353162524","pt":1646210083220,"mc":[{"id":"1.195453767","rc":[{"spn":11.1,"spf":"NaN","id":42162698},{"spn":2.48,"spf":"NaN","id":39637621},{"atl":[[7.6,0]],"id":41818763},{"spn":3.92,"spf":"NaN","id":41818763},{"atl":[[2.4,0]],"id":42154339},{"spn":1.83,"spf":"NaN","id":42154339}],"con":true,"img":false}]}
{"op":"mcm","clk":"5353162528","pt":1646210083276,"mc":[{"id":"1.195453767","rc":[{"atl":[[6.4,6.82]],"id":41818763},{"atl":[[2.36,30.32]],"id":42154339}],"con":true,"img":false}]}
{"op":"mcm","clk":"5353162532","pt":1646210083379,"mc":[{"id":"1.195453767","rc":[{"atl":[[2.42,60.66],[2.38,0]],"id":42154339}],"con":true,"img":false}]}
{"op":"mcm","clk":"5353162637","pt":1646210085389,"mc":[{"id":"1.195453767","rc":[{"atb":[[2.34,0]],"id":41818763}],"con":true,"img":false}]}
{"op":"mcm","clk":"5353162645","pt":1646210085591,"mc":[{"id":"1.195453767","rc":[{"atb":[[2.32,1.67]],"id":41818763}],"con":true,"img":false}]}
{"op":"mcm","clk":"5353162734","pt":1646210087288,"mc":[{"id":"1.195453767","rc":[{"atb":[[1.72,0],[1.77,61.51]],"id":39637621}],"con":true,"img":false}]}
{"op":"mcm","clk":"5353162911","pt":1646210090678,"mc":[{"id":"1.195453767","rc":[{"atb":[[1.76,0]],"id":39637621}],"con":true,"img":false}]}
{"op":"mcm","clk":"5353162918","pt":1646210090784,"mc":[{"id":"1.195453767","rc":[{"atb":[[1.72,123.02],[1.77,0]],"id":39637621}],"con":true,"img":false}]}
{"op":"mcm","clk":"5353163116","pt":1646210094520,"mc":[{"id":"1.195453767","rc":[{"atb":[[1.71,0]],"id":39637621}],"con":true,"img":false}]}
{"op":"mcm","clk":"5353163124","pt":1646210094623,"mc":[{"id":"1.195453767","rc":[{"atb":[[1.73,61.5]],"id":39637621}],"con":true,"img":false}]}
{"op":"mcm","clk":"5353163142","pt":1646210094888,"mc":[{"id":"1.195453767","rc":[{"atb":[[2.3,12.2]],"id":41818763}],"con":true,"img":false}]}
{"op":"mcm","clk":"5353163153","pt":1646210095093,"mc":[{"id":"1.195453767","rc":[{"atb":[[1.76,10.99]],"id":39637621}],"con":true,"img":false}]}
{"op":"mcm","clk":"5353163526","pt":1646210102730,"mc":[{"id":"1.195453767","rc":[{"atb":[[1.77,9.77]],"id":39637621}],"con":true,"img":false}]}
{"op":"mcm","clk":"5353163629","pt":1646210104529,"mc":[{"id":"1.195453767","rc":[{"atl":[[2.42,0],[2.34,30.33]],"id":42154339}],"con":true,"img":false}]}
{"op":"mcm","clk":"5353163665","pt":1646210105141,"mc":[{"id":"1.195453767","rc":[{"atb":[[1.26,0]],"id":42154339}],"con":true,"img":false}]}
{"op":"mcm","clk":"5353163671","pt":1646210105197,"mc":[{"id":"1.195453767","rc":[{"atb":[[1.3,108.64]],"id":42154339}],"con":true,"img":false}]}
{"op":"mcm","clk":"5353163709","pt":1646210105917,"mc":[{"id":"1.195453767","rc":[{"atb":[[1.29,28.79]],"id":42154339}],"con":true,"img":false}]}
{"op":"mcm","clk":"5353163989","pt":1646210111633,"mc":[{"id":"1.195453767","rc":[{"atb":[[1.33,22.8]],"id":42154339}],"con":true,"img":false}]}
{"op":"mcm","clk":"5353164003","pt":1646210111839,"mc":[{"id":"1.195453767","rc":[{"atb":[[1.72,0],[1.78,10.99]],"id":39637621}],"con":true,"img":false}]}
{"op":"mcm","clk":"5353164119","pt":1646210113636,"mc":[{"id":"1.195453767","rc":[{"atb":[[4.6,0]],"id":42162698},{"atb":[[2.24,0],[2.16,86.21]],"id":41818763},{"atb":[[4,0],[3.65,37.74]],"id":41910350},{"atb":[[2.78,52.92],[2.94,0]],"id":43167133},{"atb":[[1.57,72.11],[1.71,0]],"id":42688787}],"con":true,"img":false}]}
{"op":"mcm","clk":"5353164124","pt":1646210113737,"mc":[{"id":"1.195453767","rc":[{"atb":[[4.2,31.25]],"id":42162698}],"con":true,"img":false}]}
{"op":"mcm","clk":"5353164169","pt":1646210114610,"mc":[{"id":"1.195453767","rc":[{"atb":[[2.3,6.42]],"id":41818763}],"con":true,"img":false}]}
{"op":"mcm","clk":"5353164216","pt":1646210115328,"mc":[{"id":"1.195453767","rc":[{"atb":[[2.96,0]],"id":43167133}],"con":true,"img":false}]}
{"op":"mcm","clk":"5353164222","pt":1646210115433,"mc":[{"id":"1.195453767","rc":[{"atb":[[2.8,30.05]],"id":43167133}],"con":true,"img":false}]}
{"op":"mcm","clk":"5353164320","pt":1646210117233,"mc":[{"id":"1.195453767","rc":[{"atb":[[1.76,0]],"id":39637621}],"con":true,"img":false}]}
{"op":"mcm","clk":"5353164391","pt":1646210118521,"mc":[{"id":"1.195453767","rc":[{"atb":[[1.3,0]],"id":42154339}],"con":true,"img":false}]}
{"op":"mcm","clk":"5353164395","pt":1646210118622,"mc":[{"id":"1.195453767","rc":[{"atb":[[1.26,108.64]],"id":42154339}],"con":true,"img":false}]}
{"op":"mcm","clk":"5353164490","pt":1646210120730,"mc":[{"id":"1.195453767","rc":[{"atb":[[2.26,5.97]],"id":41818763},{"atb":[[1.33,0]],"id":42154339}],"con":true,"img":false}]}
{"op":"mcm","clk":"5353164727","pt":1646210125144,"mc":[{"id":"1.195453767","rc":[{"atb":[[1.73,0]],"id":39637621}],"con":true,"img":false}]}
{"op":"mcm","clk":"5353164734","pt":1646210125249,"mc":[{"id":"1.195453767","rc":[{"atb":[[1.71,61.5]],"id":39637621}],"con":true,"img":false}]}
{"op":"mcm","clk":"5353164811","pt":1646210126638,"mc":[{"id":"1.195453767","rc":[{"atb":[[1.77,0]],"id":39637621},{"atb":[[1.29,54.74]],"id":42154339}],"con":true,"img":false}]}
{"op":"mcm","clk":"5353164818","pt":1646210126742,"mc":[{"id":"1.195453767","rc":[{"atb":[[1.72,86.56],[1.78,0]],"id":39637621}],"con":true,"img":false}]}
{"op":"mcm","clk":"5353164958","pt":1646210129767,"mc":[{"id":"1.195453767","rc":[{"atb":[[2.3,0]],"id":41818763}],"con":true,"img":false}]}
{"op":"mcm","clk":"5353165203","pt":1646210134342,"mc":[{"id":"1.195453767","rc":[{"atb":[[2.32,0]],"id":41818763}],"con":true,"img":false}]}
{"op":"mcm","clk":"5353165208","pt":1646210134444,"mc":[{"id":"1.195453767","rc":[{"atb":[[2.28,1.67]],"id":41818763},{"atl":[[2.36,0]],"id":42154339}],"con":true,"img":false}]}
{"op":"mcm","clk":"5353165213","pt":1646210134548,"mc":[{"id":"1.195453767","rc":[{"atl":[[2.32,30.32],[2.42,60.66],[2.34,0]],"id":42154339}],"con":true,"img":false}]}
{"op":"mcm","clk":"5353165272","pt":1646210135675,"mc":[{"id":"1.195453767","rc":[{"atb":[[1.76,9.9]],"id":39637621}],"con":true,"img":false}]}
{"op":"mcm","clk":"5353165524","pt":1646210140567,"mc":[{"id":"1.195453767","rc":[{"atb":[[2.12,0]],"id":41818763}],"con":true,"img":false}]}
{"op":"mcm","clk":"5353165530","pt":1646210140671,"mc":[{"id":"1.195453767","rc":[{"atb":[[2.18,38.99]],"id":41818763}],"con":true,"img":false}]}
{"op":"mcm","clk":"5353165621","pt":1646210142167,"mc":[{"id":"1.195453767","rc":[{"atb":[[2.26,12.6]],"id":41818763}],"con":true,"img":false}]}
{"op":"mcm","clk":"5353165628","pt":1646210142271,"mc":[{"id":"1.195453767","rc":[{"atb":[[1.76,20.89]],"id":39637621}],"con":true,"img":false}]}
{"op":"mcm","clk":"5353165876","pt":1646210146550,"mc":[{"id":"1.195453767","rc":[{"spn":3.89,"spf":"NaN","id":41818763},{"atl":[[2.32,0]],"id":42154339},{"spn":1.85,"spf":"NaN","id":42154339}],"con":true,"img":false}]}
{"op":"mcm","clk":"5353165882","pt":1646210146654,"mc":[{"id":"1.195453767","rc":[{"atl":[[2.4,30.32]],"id":42154339}],"con":true,"img":false}]}
{"op":"mcm","clk":"5353165925","pt":1646210147481,"mc":[{"id":"1.195453767","rc":[{"atb":[[1.77,61.51]],"id":39637621}],"con":true,"img":false}]}
{"op":"mcm","clk":"5353165932","pt":1646210147585,"mc":[{"id":"1.195453767","rc":[{"atb":[[1.72,0]],"id":39637621}],"con":true,"img":false}]}
{"op":"mcm","clk":"5353166105","pt":1646210150884,"mc":[{"id":"1.195453767","rc":[{"atb":[[1.76,10.99]],"id":39637621}],"con":true,"img":false}]}
{"op":"mcm","clk":"5353166359","pt":1646210155185,"mc":[{"id":"1.195453767","rc":[{"atl":[[2.38,30.33]],"id":42154339}],"con":true,"img":false}]}
{"op":"mcm","clk":"5353166368","pt":1646210155289,"mc":[{"id":"1.195453767","rc":[{"atl":[[2.42,0]],"id":42154339}],"con":true,"img":false}]}
{"op":"mcm","clk":"5353166375","pt":1646210155386,"mc":[{"id":"1.195453767","rc":[{"atl":[[6.4,0]],"id":41818763},{"atb":[[1.26,0]],"id":42154339}],"con":true,"img":false}]}
{"op":"mcm","clk":"5353166381","pt":1646210155489,"mc":[{"id":"1.195453767","rc":[{"atl":[[7.6,6.82]],"id":41818763},{"atb":[[1.3,108.64]],"id":42154339}],"con":true,"img":false}]}
{"op":"mcm","clk":"5353166446","pt":1646210156780,"mc":[{"id":"1.195453767","rc":[{"atb":[[1.81,9.29]],"id":39637621}],"con":true,"img":false}]}
{"op":"mcm","clk":"5353166451","pt":1646210156883,"mc":[{"id":"1.195453767","rc":[{"atb":[[1.29,28.79]],"id":42154339}],"con":true,"img":false}]}
{"op":"mcm","clk":"5353166759","pt":1646210162808,"mc":[{"id":"1.195453767","rc":[{"atb":[[1.33,22.8]],"id":42154339}],"con":true,"img":false}]}
{"op":"mcm","clk":"5353166862","pt":1646210164713,"mc":[{"id":"1.195453767","rc":[{"atb":[[1.76,0]],"id":39637621},{"atb":[[1.29,0]],"id":42154339}],"con":true,"img":false}]}
{"op":"mcm","clk":"5353166963","pt":1646210166618,"mc":[{"id":"1.195453767","rc":[{"atb":[[1.3,0]],"id":42154339}],"con":true,"img":false}]}
{"op":"mcm","clk":"5353166967","pt":1646210166674,"mc":[{"id":"1.195453767","rc":[{"atb":[[1.26,108.64]],"id":42154339}],"con":true,"img":false}]}
{"op":"mcm","clk":"5353167032","pt":1646210167931,"mc":[{"id":"1.195453767","rc":[{"atb":[[1.8,61.51],[1.77,0]],"id":39637621}],"con":true,"img":false}]}
{"op":"mcm","clk":"5353167085","pt":1646210168808,"mc":[{"id":"1.195453767","rc":[{"atb":[[1.81,0]],"id":39637621},{"atb":[[1.33,0]],"id":42154339}],"con":true,"img":false}]}
{"op":"mcm","clk":"5353167302","pt":1646210173091,"mc":[{"id":"1.195453767","rc":[{"atb":[[1.8,0],[1.72,123.02]],"id":39637621}],"con":true,"img":false}]}
{"op":"mcm","clk":"5353167411","pt":1646210174699,"mc":[{"id":"1.195453767","rc":[{"atb":[[1.29,25.94]],"id":42154339}],"con":true,"img":false}]}
{"op":"mcm","clk":"5353167725","pt":1646210180709,"mc":[{"id":"1.195453767","rc":[{"atb":[[1.76,9.9]],"id":39637621}],"con":true,"img":false}]}
{"op":"mcm","clk":"5353167830","pt":1646210182724,"mc":[{"id":"1.195453767","rc":[{"atl":[[2.4,0]],"id":42154339}],"con":true,"img":false}]}
{"op":"mcm","clk":"5353167836","pt":1646210182782,"mc":[{"id":"1.195453767","rc":[{"atl":[[2.36,30.32]],"id":42154339}],"con":true,"img":false}]}
{"op":"mcm","clk":"5353167839","pt":1646210182883,"mc":[{"id":"1.195453767","rc":[{"atl":[[2.42,60.66],[2.38,0]],"id":42154339}],"con":true,"img":false}]}
{"op":"mcm","clk":"5353167844","pt":1646210182988,"mc":[{"id":"1.195453767","rc":[{"atl":[[2.42,0],[2.34,30.33]],"id":42154339}],"con":true,"img":false}]}
{"op":"mcm","clk":"5353168175","pt":1646210189229,"mc":[{"id":"1.195453767","rc":[{"atb":[[1.29,54.74]],"id":42154339}],"con":true,"img":false}]}
{"op":"mcm","clk":"5353168192","pt":1646210189536,"mc":[{"id":"1.195453767","rc":[{"atb":[[1.76,20.89]],"id":39637621}],"con":true,"img":false}]}
{"op":"mcm","clk":"5353168358","pt":1646210193293,"mc":[{"id":"1.195453767","rc":[{"atb":[[1.72,0],[1.77,61.51]],"id":39637621}],"con":true,"img":false}]}
{"op":"mcm","clk":"5353168481","pt":1646210195707,"mc":[{"id":"1.195453767","rc":[{"atl":[[7.6,0]],"id":41818763}],"con":true,"img":false}]}
{"op":"mcm","clk":"5353168489","pt":1646210195810,"mc":[{"id":"1.195453767","rc":[{"atb":[[1.76,10.99]],"id":39637621},{"atl":[[6.4,6.82]],"id":41818763}],"con":true,"img":false}]}
{"op":"mcm","clk":"5353168893","pt":1646210201844,"mc":[{"id":"1.195453767","rc":[{"atb":[[1.81,9.29]],"id":39637621}],"con":true,"img":false}]}
{"op":"mcm","clk":"5353168901","pt":1646210202003,"mc":[{"id":"1.195453767","rc":[{"atb":[[1.8,61.51],[1.77,0]],"id":39637621}],"con":true,"img":false}]}
{"op":"mcm","clk":"5353169035","pt":1646210205033,"mc":[{"id":"1.195453767","rc":[{"atb":[[1.81,0]],"id":39637621}],"con":true,"img":false}]}
{"op":"mcm","clk":"5353169143","pt":1646210207249,"mc":[{"id":"1.195453767","rc":[{"atb":[[1.77,123.02]],"id":39637621},{"spn":2.5,"spf":"NaN","id":39637621},{"spn":1.81,"spf":"NaN","id":42154339}],"con":true,"img":false}]}
{"op":"mcm","clk":"5353169148","pt":1646210207352,"mc":[{"id":"1.195453767","rc":[{"atb":[[1.8,0]],"id":39637621}],"con":true,"img":false}]}
{"op":"mcm","clk":"5353169425","pt":1646210213032,"mc":[{"id":"1.195453767","rc":[{"atl":[[2.36,0]],"id":42154339}],"con":true,"img":false}]}
{"op":"mcm","clk":"5353169435","pt":1646210213136,"mc":[{"id":"1.195453767","rc":[{"atl":[[2.32,30.32],[2.42,60.66],[2.34,0]],"id":42154339}],"con":true,"img":false}]}
{"op":"mcm","clk":"5353169444","pt":1646210213342,"mc":[{"id":"1.195453767","rc":[{"atl":[[2.3,30.33],[2.42,0]],"id":42154339}],"con":true,"img":false}]}
{"op":"mcm","clk":"5353169469","pt":1646210213655,"mc":[{"id":"1.195453767","rc":[{"atb":[[1.76,0]],"id":39637621}],"con":true,"img":false}]}
{"op":"mcm","clk":"5353169482","pt":1646210213860,"mc":[{"id":"1.195453767","rc":[{"atb":[[1.72,138.89],[1.81,9.29],[1.77,0]],"id":39637621}],"con":true,"img":false}]}
{"op":"mcm","clk":"5353169658","pt":1646210216845,"mc":[{"id":"1.195453767","rc":[{"atb":[[1.81,0]],"id":39637621}],"con":true,"img":false}]}
{"op":"mcm","clk":"5353169702","pt":1646210217618,"mc":[{"id":"1.195453767","rc":[{"atb":[[1.26,0]],"id":42154339}],"con":true,"img":false}]}
{"op":"mcm","clk":"5353169706","pt":1646210217719,"mc":[{"id":"1.195453767","rc":[{"atb":[[1.3,108.64]],"id":42154339}],"con":true,"img":false}]}
{"op":"mcm","clk":"5353169811","pt":1646210219935,"mc":[{"id":"1.195453767","rc":[{"atb":[[1.29,28.79]],"id":42154339}],"con":true,"img":false}]}
{"op":"mcm","clk":"5353169969","pt":1646210223074,"mc":[{"id":"1.195453767","rc":[{"atb":[[1.76,9.9]],"id":39637621}],"con":true,"img":false}]}
{"op":"mcm","clk":"5353170154","pt":1646210226937,"mc":[{"id":"1.195453767","rc":[{"atb":[[1.33,22.8]],"id":42154339}],"con":true,"img":false}]}
{"op":"mcm","clk":"5353170268","pt":1646210229050,"mc":[{"id":"1.195453767","rc":[{"atb":[[1.3,0]],"id":42154339}],"con":true,"img":false}]}
{"op":"mcm","clk":"5353170273","pt":1646210229157,"mc":[{"id":"1.195453767","rc":[{"atb":[[1.26,108.64]],"id":42154339}],"con":true,"img":false}]}
{"op":"mcm","clk":"5353170416","pt":1646210231880,"mc":[{"id":"1.195453767","rc":[{"atb":[[1.33,0]],"id":42154339}],"con":true,"img":false}]}
{"op":"mcm","clk":"5353170517","pt":1646210233680,"mc":[{"id":"1.195453767","rc":[{"atb":[[1.72,0],[1.77,61.51]],"id":39637621}],"con":true,"img":false}]}
{"op":"mcm","clk":"5353170568","pt":1646210234870,"mc":[{"id":"1.195453767","rc":[{"atb":[[1.76,0]],"id":39637621}],"con":true,"img":false}]}
{"op":"mcm","clk":"5353170765","pt":1646210237951,"mc":[{"id":"1.195453767","rc":[{"atb":[[1.29,54.74]],"id":42154339}],"con":true,"img":false}]}
{"op":"mcm","clk":"5353170813","pt":1646210238878,"mc":[{"id":"1.195453767","rc":[{"atb":[[1.72,123.02],[1.77,0]],"id":39637621}],"con":true,"img":false}]}
{"op":"mcm","clk":"5353170908","pt":1646210240575,"mc":[{"id":"1.195453767","rc":[{"atb":[[1.71,0]],"id":39637621}],"con":true,"img":false}]}
{"op":"mcm","clk":"5353170913","pt":1646210240676,"mc":[{"id":"1.195453767","rc":[{"atb":[[1.73,61.5]],"id":39637621}],"con":true,"img":false}]}
{"op":"mcm","clk":"5353171234","pt":1646210246999,"mc":[{"id":"1.195453767","rc":[{"atl":[[2.32,0]],"id":42154339}],"con":true,"img":false}]}
{"op":"mcm","clk":"5353171238","pt":1646210247102,"mc":[{"id":"1.195453767","rc":[{"atl":[[2.28,30.32]],"id":42154339}],"con":true,"img":false}]}
{"op":"mcm","clk":"5353171246","pt":1646210247202,"mc":[{"id":"1.195453767","rc":[{"atl":[[2.3,0],[2.42,60.66]],"id":42154339}],"con":true,"img":false}]}
{"op":"mcm","clk":"5353171359","pt":1646210249579,"mc":[{"id":"1.195453767","rc":[{"atl":[[6.4,0]],"id":41818763}],"con":true,"img":false}]}
{"op":"mcm","clk":"5353171367","pt":1646210249681,"mc":[{"id":"1.195453767","rc":[{"atl":[[7.6,6.82]],"id":41818763}],"con":true,"img":false}]}
{"op":"mcm","clk":"5353171378","pt":1646210249888,"mc":[{"id":"1.195453767","rc":[{"atb":[[1.77,9.77]],"id":39637621}],"con":true,"img":false}]}
{"op":"mcm","clk":"5353171765","pt":1646210257710,"mc":[{"id":"1.195453767","rc":[{"atl":[[2.28,0]],"id":42154339}],"con":true,"img":false}]}
{"op":"mcm","clk":"5353171773","pt":1646210257812,"mc":[{"id":"1.195453767","rc":[{"atl":[[2.4,30.32]],"id":42154339}],"con":true,"img":false}]}
{"op":"mcm","clk":"5353171817","pt":1646210258379,"mc":[{"id":"1.195453767","rc":[{"atb":[[1.72,0],[1.78,61.51]],"id":39637621}],"con":true,"img":false}]}
{"op":"mcm","clk":"5353171851","pt":1646210258894,"mc":[{"id":"1.195453767","rc":[{"atb":[[1.77,0]],"id":39637621}],"con":true,"img":false}]}
{"op":"mcm","clk":"5353171977","pt":1646210260697,"mc":[{"id":"1.195453767","rc":[{"atb":[[4.2,0],[4.7,42.99]],"id":42162698},{"atb":[[2.24,50.49],[2.16,0]],"id":41818763},{"atb":[[4,33.33]],"id":41910350},{"atb":[[1.79,72.11]],"id":42688787}],"con":true,"img":false}]}
{"op":"mcm","clk":"5353171982","pt":1646210260798,"mc":[{"id":"1.195453767","rc":[{"atb":[[3.65,0]],"id":41910350},{"atb":[[1.57,0]],"id":42688787}],"con":true,"img":false}]}
{"op":"mcm","clk":"5353172094","pt":1646210263112,"mc":[{"id":"1.195453767","rc":[{"atb":[[2.26,6.63]],"id":41818763}],"con":true,"img":false}]}
{"op":"mcm","clk":"5353172110","pt":1646210263519,"mc":[{"id":"1.195453767","rc":[{"atb":[[1.74,123.02]],"id":39637621}],"con":true,"img":false}]}
{"op":"mcm","clk":"5353172116","pt":1646210263578,"mc":[{"id":"1.195453767","rc":[{"atb":[[1.78,0]],"id":39637621}],"con":true,"img":false}]}
{"op":"mcm","clk":"5353172245","pt":1646210265993,"mc":[{"id":"1.195453767","rc":[{"atb":[[2.88,41.48],[2.78,0]],"id":43167133}],"con":true,"img":false}]}
{"op":"mcm","clk":"5353172283","pt":1646210266713,"mc":[{"id":"1.195453767","rc":[{"atl":[[2.42,0],[2.38,30.33]],"id":42154339}],"con":true,"img":false}]}
{"op":"mcm","clk":"5353172333","pt":1646210267998,"mc":[{"id":"1.195453767","rc":[{"spn":2.47,"spf":"NaN","id":39637621},{"atb":[[2.3,5.78]],"id":41818763},{"spn":3.9,"spf":"NaN","id":41818763},{"spn":1.83,"spf":"NaN","id":42154339}],"con":true,"img":false}]}
{"op":"mcm","clk":"5353172453","pt":1646210270229,"mc":[{"id":"1.195453767","rc":[{"atb":[[2.18,0]],"id":41818763}],"con":true,"img":false}]}
{"op":"mcm","clk":"5353172462","pt":1646210270281,"mc":[{"id":"1.195453767","rc":[{"atb":[[2.12,38.99]],"id":41818763}],"con":true,"img":false}]}
{"op":"mcm","clk":"5353172491","pt":1646210270899,"mc":[{"id":"1.195453767","rc":[{"atb":[[1.78,9.64]],"id":39637621}],"con":true,"img":false}]}
{"op":"mcm","clk":"5353172563","pt":1646210272498,"mc":[{"id":"1.195453767","rc":[{"atb":[[2.28,0]],"id":41818763}],"con":true,"img":false}]}
{"op":"mcm","clk":"5353172570","pt":1646210272600,"mc":[{"id":"1.195453767","rc":[{"atb":[[2.32,1.67]],"id":41818763}],"con":true,"img":false}]}
{"op":"mcm","clk":"5353172669","pt":1646210274310,"mc":[{"id":"1.195453767","rc":[{"atb":[[1.73,0]],"id":39637621}],"con":true,"img":false}]}
{"op":"mcm","clk":"5353172675","pt":1646210274414,"mc":[{"id":"1.195453767","rc":[{"atb":[[1.71,61.5]],"id":39637621}],"con":true,"img":false}]}
{"op":"mcm","clk":"5353172900","pt":1646210278610,"mc":[{"id":"1.195453767","rc":[{"atb":[[2.26,0]],"id":41818763}],"con":true,"img":false}]}
{"op":"mcm","clk":"5353173165","pt":1646210282849,"mc":[{"id":"1.195453767","rc":[{"atb":[[1.79,61.51],[1.74,0]],"id":39637621}],"con":true,"img":false}]}
{"op":"mcm","clk":"5353173176","pt":1646210283053,"mc":[{"id":"1.195453767","rc":[{"atb":[[5.1,22.59],[5.3,4.65],[4.9,19.23],[4.7,76.77]],"id":42162698},{"atl":[[21,1],[23,2.27],[25,3.12],[27,4.81]],"id":42162698},{"atb":[[1.72,173.61],[1.74,101.35],[1.78,35.28],[1.76,65.79]],"id":39637621},{"atl":[[3.2,14.59],[3.4,31.25],[3.3,21.74],[3.5,50]],"id":39637621},{"atb":[[2.22,40.98],[2.18,63.56],[2.26,15.87],[2.14,109.65]],"id":41818763},{"atl":[[4.8,19.74],[4.6,13.89],[5,31.25],[4.4,5.88]],"id":41818763},{"atb":[[4.5,14.29],[4.3,22.73],[4.1,59.86],[4.7,5.41]],"id":41910350},{"atl":[[16,8.33],[13,1.67],[14,3.85],[15,5.36]],"id":41910350},{"atb":[[3.2,56.82],[3.4,71.32],[3.5,8],[3.3,32.61]],"id":43167133},{"atl":[[16,1.33],[17,3.12],[18,4.41],[19,6.94]],"id":43167133},{"atb":[[1.2,855.89],[1.26,185.56],[1.22,250],[1.24,208.33]],"id":42154339},{"atl":[[1.73,102.74],[1.75,166.67],[1.71,70.42],[1.69,28.99]],"id":42154339},{"atb":[[2.12,66.96],[2.2,16.67],[2.16,43.1],[2.08,115.74]],"id":42688787},{"atl":[[5.1,4.88],[5.3,11.63],[5.5,16.67],[5.7,26.6]],"id":42688787}],"con":true,"img":false}]}
{"op":"mcm","clk":"5353173184","pt":1646210283112,"mc":[{"id":"1.195453767","rc":[{"atl":[[7,2]],"id":42688787}],"con":true,"img":false}]}
{"op":"mcm","clk":"5353173192","pt":1646210283212,"mc":[{"id":"1.195453767","rc":[{"atl":[[8,0]],"id":42688787}],"con":true,"img":false}]}
{"op":"mcm","clk":"5353173216","pt":1646210283624,"mc":[{"id":"1.195453767","rc":[{"atb":[[4.7,49.74]],"id":42162698},{"atb":[[1.79,0]],"id":42688787}],"con":true,"img":false}]}
{"op":"mcm","clk":"5353173221","pt":1646210283727,"mc":[{"id":"1.195453767","rc":[{"atb":[[4.9,44.87]],"id":42162698},{"atl":[[21,0],[22,1]],"id":42162698},{"atb":[[2.24,0],[2.32,7.46]],"id":41818763},{"atb":[[4,0],[4.9,5.13],[4.4,42.38],[4.7,0]],"id":41910350},{"atl":[[16,0],[10.5,4.51],[8.2,2.78],[15.5,0.83]],"id":43167133},{"atb":[[1.22,643.89],[1.17,0]],"id":42154339},{"atb":[[2.3,15.38],[2.04,80.44],[2.2,0]],"id":42688787}],"con":true,"img":false}]}
{"op":"mcm","clk":"5353173231","pt":1646210283935,"mc":[{"id":"1.195453767","rc":[{"atl":[[15,0]],"id":43167133}],"con":true,"img":false}]}
{"op":"mcm","clk":"5353173235","pt":1646210284037,"mc":[{"id":"1.195453767","rc":[{"atl":[[16.5,3.56]],"id":43167133}],"con":true,"img":false}]}
{"op":"mcm","clk":"5353173263","pt":1646210284549,"mc":[{"id":"1.195453767","rc":[{"atb":[[5.2,0]],"id":42162698}],"con":true,"img":false}]}
{"op":"mcm","clk":"5353173274","pt":1646210284711,"mc":[{"id":"1.195453767","rc":[{"atb":[[5.4,1.67]],"id":42162698}],"con":true,"img":false}]}
{"op":"mcm","clk":"5353173357","pt":1646210286050,"mc":[{"id":"1.195453767","rc":[{"atb":[[5.2,0]],"id":41910350},{"atl":[[1.95,105.26],[2.38,0]],"id":42154339},{"atb":[[2.34,0]],"id":42688787}],"con":true,"img":false}]}
{"op":"mcm","clk":"5353173365","pt":1646210286153,"mc":[{"id":"1.195453767","rc":[{"atb":[[4.5,24.93]],"id":41910350},{"atb":[[2.18,40.22]],"id":42688787}],"con":true,"img":false}]}
{"op":"mcm","clk":"5353173411","pt":1646210287030,"mc":[{"id":"1.195453767","rc":[{"atb":[[1.78,25.64]],"id":39637621},{"atb":[[2.3,0]],"id":41818763}],"con":true,"img":false}]}
{"op":"mcm","clk":"5353173465","pt":1646210287958,"mc":[{"id":"1.195453767","rc":[{"atb":[[1.76,167.14]],"id":39637621}],"con":true,"img":false}]}
{"op":"mcm","clk":"5353173473","pt":1646210288060,"mc":[{"id":"1.195453767","rc":[{"atb":[[1.79,0]],"id":39637621}],"con":true,"img":false}]}
{"op":"mcm","clk":"5353173592","pt":1646210290536,"mc":[{"id":"1.195453767","rc":[{"atb":[[5.3,0]],"id":41910350}],"con":true,"img":false}]}
{"op":"mcm","clk":"5353173597","pt":1646210290639,"mc":[{"id":"1.195453767","rc":[{"atb":[[5,1.67]],"id":41910350}],"con":true,"img":false}]}
{"op":"mcm","clk":"5353173666","pt":1646210291924,"mc":[{"id":"1.195453767","rc":[{"atl":[[1.7,43.66],[2.4,0]],"id":42154339}],"con":true,"img":false}]}
{"op":"mcm","clk":"5353173725","pt":1646210293048,"mc":[{"id":"1.195453767","rc":[{"atb":[[1.74,236.49]],"id":39637621}],"con":true,"img":false}]}
{"op":"mcm","clk":"5353173731","pt":1646210293154,"mc":[{"id":"1.195453767","rc":[{"atb":[[1.76,65.79]],"id":39637621}],"con":true,"img":false}]}
{"op":"mcm","clk":"5353173749","pt":1646210293621,"mc":[{"id":"1.195453767","rc":[{"atb":[[4.7,13.51]],"id":41910350},{"atl":[[8.6,6.58]],"id":43167133},{"atb":[[2.26,39.68]],"id":42688787}],"con":true,"img":false}]}
{"op":"mcm","clk":"5353173756","pt":1646210293722,"mc":[{"id":"1.195453767","rc":[{"atl":[[24,2.69]],"id":42162698}],"con":true,"img":false}]}
{"op":"mcm","clk":"5353173819","pt":1646210295064,"mc":[{"id":"1.195453767","rc":[{"atb":[[1.8,9.4]],"id":39637621},{"atb":[[2.28,5.87]],"id":41818763}],"con":true,"img":false}]}
{"op":"mcm","clk":"5353173863","pt":1646210295939,"mc":[{"id":"1.195453767","rc":[{"atl":[[7.6,0],[4.7,11.8]],"id":41818763}],"con":true,"img":false}]}
{"op":"mcm","clk":"5353174204","pt":1646210302060,"mc":[{"id":"1.195453767","rc":[{"atb":[[1.71,0]],"id":39637621}],"con":true,"img":false}]}
{"op":"mcm","clk":"5353174210","pt":1646210302164,"mc":[{"id":"1.195453767","rc":[{"atb":[[1.73,61.5]],"id":39637621}],"con":true,"img":false}]}
{"op":"mcm","clk":"5353174228","pt":1646210302469,"mc":[{"id":"1.195453767","rc":[{"atb":[[2.28,12.4]],"id":41818763}],"con":true,"img":false}]}
{"op":"mcm","clk":"5353174275","pt":1646210303247,"mc":[{"id":"1.195453767","rc":[{"atb":[[1.8,19.84]],"id":39637621}],"con":true,"img":false}]}
{"op":"mcm","clk":"5353174303","pt":1646210303769,"mc":[{"id":"1.195453767","rc":[{"atl":[[23,0],[25,0],[26,3],[27,0]],"id":42162698},{"atb":[[4.5,32.07],[4.1,19.54]],"id":41910350},{"atl":[[9,9.38],[17,0],[18,0],[19,0]],"id":43167133},{"atb":[[2.22,61.48],[2.12,0],[2.08,0],[2.16,0]],"id":42688787}],"con":true,"img":false}]}
{"op":"mcm","clk":"5353174325","pt":1646210304076,"mc":[{"id":"1.195453767","rc":[{"atb":[[2.12,0]],"id":41818763}],"con":true,"img":false}]}
{"op":"mcm","clk":"5353174330","pt":1646210304177,"mc":[{"id":"1.195453767","rc":[{"atb":[[2.2,89.48]],"id":41818763}],"con":true,"img":false}]}
{"op":"mcm","clk":"5353174445","pt":1646210305940,"mc":[{"id":"1.195453767","rc":[{"atl":[[29,0]],"id":42162698},{"atl":[[27,0]],"id":41910350}],"con":true,"img":false}]}
{"op":"mcm","clk":"5353174450","pt":1646210306038,"mc":[{"id":"1.195453767","rc":[{"atl":[[23,2.72]],"id":42162698},{"atl":[[15.5,2.72]],"id":41910350}],"con":true,"img":false}]}
{"op":"mcm","clk":"5353174558","pt":1646210307944,"mc":[{"id":"1.195453767","rc":[{"atl":[[4.1,0],[3.35,18.58]],"id":39637621},{"atl":[[11.5,0],[5.6,9.49]],"id":42688787}],"con":true,"img":false}]}
{"op":"mcm","clk":"5353174566","pt":1646210308047,"mc":[{"id":"1.195453767","rc":[{"atb":[[2.8,0]],"id":43167133}],"con":true,"img":false}]}
{"op":"mcm","clk":"5353174570","pt":1646210308149,"mc":[{"id":"1.195453767","rc":[{"atb":[[2.9,30.05]],"id":43167133}],"con":true,"img":false}]}
{"op":"mcm","clk":"5353174783","pt":1646210312067,"mc":[{"id":"1.195453767","rc":[{"atb":[[1.81,25.64],[1.74,101.35]],"id":39637621},{"atl":[[1.7,0]],"id":42154339}],"con":true,"img":false}]}
{"op":"mcm","clk":"5353174792","pt":1646210312170,"mc":[{"id":"1.195453767","rc":[{"atl":[[1.72,43.66]],"id":42154339}],"con":true,"img":false}]}
{"op":"mcm","clk":"5353174895","pt":1646210313771,"mc":[{"id":"1.195453767","rc":[{"atl":[[28,4.63]],"id":42162698},{"atb":[[4.3,37.88]],"id":41910350},{"atl":[[9.4,14.88]],"id":43167133},{"atb":[[2.18,146.15]],"id":42688787}],"con":true,"img":false}]}
{"op":"mcm","clk":"5353175337","pt":1646210321958,"mc":[{"id":"1.195453767","rc":[{"atb":[[1.21,0]],"id":42154339}],"con":true,"img":false}]}
{"op":"mcm","clk":"5353175339","pt":1646210322056,"mc":[{"id":"1.195453767","rc":[{"atb":[[1.23,305.67]],"id":42154339}],"con":true,"img":false}]}
{"op":"mcm","clk":"5353175505","pt":1646210325976,"mc":[{"id":"1.195453767","rc":[{"atb":[[4.7,33.78]],"id":42162698},{"atl":[[32,0]],"id":42162698},{"atb":[[1.49,0],[1.61,104.25]],"id":39637621},{"atl":[[4.3,19.1],[5.2,0]],"id":39637621},{"atb":[[4.5,21.43]],"id":41910350},{"atl":[[32,0]],"id":41910350},{"atl":[[8.2,0],[6.2,10.58]],"id":41818763},{"atl":[[8.8,5.6],[14.5,0]],"id":43167133},{"atl":[[2.8,0],[2.2,53.49]],"id":42154339},{"atl":[[12.5,0],[8.6,7.09]],"id":42688787}],"con":true,"img":false}]}
{"op":"mcm","clk":"5353175511","pt":1646210326075,"mc":[{"id":"1.195453767","rc":[{"atb":[[5.1,38.55]],"id":42162698},{"atl":[[25,2.72]],"id":42162698},{"atb":[[4.7,24.15]],"id":41910350},{"atl":[[20,2.72]],"id":41910350}],"con":true,"img":false}]}
{"op":"mcm","clk":"5353175615","pt":1646210327993,"mc":[{"id":"1.195453767","rc":[{"atb":[[1.83,0],[2.02,60.2]],"id":41818763}],"con":true,"img":false}]}
{"op":"mcm","clk":"5353175897","pt":1646210333961,"mc":[{"id":"1.195453767","rc":[{"spn":11.2,"spf":"NaN","id":42162698},{"spn":2.5,"spf":"NaN","id":39637621},{"spn":3.36,"spf":"NaN","id":41818763},{"spn":9.0,"spf":"NaN","id":41910350},{"spn":6.0,"spf":"NaN","id":43167133},{"spn":1.49,"spf":"NaN","id":42154339},{"atb":[[2.18,105.93]],"id":42688787},{"atl":[[5.6,0]],"id":42688787},{"spn":4.04,"spf":"NaN","id":42688787}],"con":true,"img":false}]}
{"op":"mcm","clk":"5353175901","pt":1646210334064,"mc":[{"id":"1.195453767","rc":[{"atb":[[2.28,40.22]],"id":42688787},{"atl":[[5.4,9.49]],"id":42688787}],"con":true,"img":false}]}
{"op":"mcm","clk":"5353176520","pt":1646210345971,"mc":[{"id":"1.195453767","rc":[{"atl":[[16.5,0],[12.5,4.65]],"id":43167133}],"con":true,"img":false}]}
{"op":"mcm","clk":"5353176527","pt":1646210346074,"mc":[{"id":"1.195453767","rc":[{"atb":[[4.4,22.73]],"id":41910350}],"con":true,"img":false}]}
{"op":"mcm","clk":"5353176533","pt":1646210346176,"mc":[{"id":"1.195453767","rc":[{"atb":[[4.6,19.65]],"id":41910350}],"con":true,"img":false}]}
{"op":"mcm","clk":"5353176730","pt":1646210349993,"mc":[{"id":"1.195453767","rc":[{"atl":[[15.5,0]],"id":41910350}],"con":true,"img":false}]}
{"op":"mcm","clk":"5353176736","pt":1646210350092,"mc":[{"id":"1.195453767","rc":[{"atl":[[14.5,3.62]],"id":41910350}],"con":true,"img":false}]}
{"op":"mcm","clk":"5353176916","pt":1646210353594,"mc":[{"id":"1.195453767","rc":[{"atl":[[1.69,0]],"id":42154339},{"trd":[[1.69,57.98]],"ltp":1.69,"tv":57.98,"id":42154339}],"con":true,"img":false}]}
{"op":"mcm","clk":"5353176922","pt":1646210353800,"mc":[{"id":"1.195453767","rc":[{"atb":[[1.3,37.69]],"id":42154339},{"atl":[[1.73,0],[1.72,67.91],[1.75,0],[1.71,0]],"id":42154339}],"con":true,"img":false}]}
{"op":"mcm","clk":"5353176927","pt":1646210354004,"mc":[{"id":"1.195453767","rc":[{"atb":[[4.6,0]],"id":41910350},{"atl":[[2.46,43.66]],"id":42154339}],"con":true,"img":false}]}
{"op":"mcm","clk":"5353176931","pt":1646210354108,"mc":[{"id":"1.195453767","rc":[{"atb":[[4.5,41.08]],"id":41910350},{"atl":[[2.2,0]],"id":42154339}],"con":true,"img":false}]}
{"op":"mcm","clk":"5353177223","pt":1646210359998,"mc":[{"id":"1.195453767","rc":[{"atl":[[1.72,24.25]],"id":42154339}],"con":true,"img":false}]}
{"op":"mcm","clk":"5353177231","pt":1646210360094,"mc":[{"id":"1.195453767","rc":[{"atl":[[2.42,70.42],[1.94,43.66]],"id":42154339}],"con":true,"img":false}]}
{"op":"mcm","clk":"5353177236","pt":1646210360198,"mc":[{"id":"1.195453767","rc":[{"atl":[[1.95,0]],"id":42154339}],"con":true,"img":false}]}
{"op":"mcm","clk":"5353177340","pt":1646210362000,"mc":[{"id":"1.195453767","rc":[{"atb":[[4.5,21.43]],"id":41910350},{"atb":[[1.83,73.98],[2.02,0]],"id":41818763},{"atl":[[6.2,0]],"id":41818763}],"con":true,"img":false}]}
{"op":"mcm","clk":"5353177343","pt":1646210362103,"mc":[{"id":"1.195453767","rc":[{"atl":[[6.6,18.45]],"id":41818763},{"atb":[[4.4,42.38]],"id":41910350}],"con":true,"img":false}]}
{"op":"mcm","clk":"5353177434","pt":1646210363803,"mc":[{"id":"1.195453767","rc":[{"atl":[[1.74,58.99]],"id":42154339}],"con":true,"img":false}]}
{"op":"mcm","clk":"5353177667","pt":1646210368027,"mc":[{"id":"1.195453767","rc":[{"atl":[[1.94,0]],"id":42154339}],"con":true,"img":false}]}
{"op":"mcm","clk":"5353177669","pt":1646210368129,"mc":[{"id":"1.195453767","rc":[{"atl":[[2.04,43.66]],"id":42154339}],"con":true,"img":false}]}
{"op":"mcm","clk":"5353177950","pt":1646210373852,"mc":[{"id":"1.195453767","rc":[{"atl":[[1.76,86.15]],"id":42154339}],"con":true,"img":false}]}
{"op":"mcm","clk":"5353177962","pt":1646210374009,"mc":[{"id":"1.195453767","rc":[{"atl":[[3.35,0]],"id":39637621}],"con":true,"img":false}]}
{"op":"mcm","clk":"5353177968","pt":1646210374112,"mc":[{"id":"1.195453767","rc":[{"atl":[[3.25,18.58]],"id":39637621}],"con":true,"img":false}]}
{"op":"mcm","clk":"5353178001","pt":1646210375038,"mc":[{"id":"1.195453767","rc":[{"atl":[[1.72,11.89]],"id":42154339},{"trd":[[1.72,24.71]],"ltp":1.72,"tv":24.71,"id":42154339}],"con":true,"img":false}]}
{"op":"mcm","clk":"5353178009","pt":1646210375242,"mc":[{"id":"1.195453767","rc":[{"atl":[[1.72,0],[1.74,0],[1.75,21.81],[1.76,0]],"id":42154339}],"con":true,"img":false}]}
{"op":"mcm","clk":"5353178039","pt":1646210376016,"mc":[{"id":"1.195453767","rc":[{"atb":[[1.26,76.92]],"id":42154339}],"con":true,"img":false}]}
{"op":"mcm","clk":"5353178044","pt":1646210376118,"mc":[{"id":"1.195453767","rc":[{"atb":[[1.3,146.33]],"id":42154339}],"con":true,"img":false}]}
{"op":"mcm","clk":"5353178139","pt":1646210377928,"mc":[{"id":"1.195453767","rc":[{"atl":[[2.36,31.18],[2.04,0]],"id":42154339}],"con":true,"img":false}]}
{"op":"mcm","clk":"5353178185","pt":1646210378954,"mc":[{"id":"1.195453767","rc":[{"atb":[[5.3,6.27]],"id":42162698},{"atb":[[1.82,1.61]],"id":39637621},{"atb":[[2.34,1.57]],"id":41818763},{"atb":[[4.9,6.54]],"id":41910350},{"atb":[[3.8,3.12]],"id":43167133},{"atb":[[2.98,3.14]],"id":42688787}],"con":true,"img":false}]}
{"op":"mcm","clk":"5353178201","pt":1646210379214,"mc":[{"id":"1.195453767","rc":[{"atb":[[1.29,28.79]],"id":42154339}],"con":true,"img":false}]}
{"op":"mcm","clk":"5353178482","pt":1646210385042,"mc":[{"id":"1.195453767","rc":[{"atb":[[1.33,22.8],[1.29,0]],"id":42154339}],"con":true,"img":false}]}
{"op":"mcm","clk":"5353178486","pt":1646210385162,"mc":[{"id":"1.195453767","rc":[{"atl":[[1.77,53.11]],"id":42154339}],"con":true,"img":false}]}
{"op":"mcm","clk":"5353178494","pt":1646210385257,"mc":[{"id":"1.195453767","rc":[{"atb":[[1.3,108.64]],"id":42154339}],"con":true,"img":false}]}
{"op":"mcm","clk":"5353178792","pt":1646210391239,"mc":[{"id":"1.195453767","rc":[{"atb":[[1.34,37.43]],"id":42154339}],"con":true,"img":false}]}
{"op":"mcm","clk":"5353178817","pt":1646210392066,"mc":[{"id":"1.195453767","rc":[{"atb":[[1.23,0]],"id":42154339}],"con":true,"img":false}]}
{"op":"mcm","clk":"5353178823","pt":1646210392167,"mc":[{"id":"1.195453767","rc":[{"atb":[[1.25,548.03]],"id":42154339}],"con":true,"img":false}]}
{"op":"mcm","clk":"5353178950","pt":1646210395157,"mc":[{"id":"1.195453767","rc":[{"spn":2.51,"spf":"NaN","id":39637621},{"spn":3.37,"spf":"NaN","id":41818763},{"atl":[[1.79,77.65]],"id":42154339},{"spn":1.54,"spf":"NaN","id":42154339}],"con":true,"img":false}]}
{"op":"mcm","clk":"5353178956","pt":1646210395261,"mc":[{"id":"1.195453767","rc":[{"atl":[[2.42,0],[1.95,74.92]],"id":42154339}],"con":true,"img":false}]}
{"op":"mcm","clk":"5353178990","pt":1646210395773,"mc":[{"id":"1.195453767","rc":[{"atb":[[1.33,48.1]],"id":42154339}],"con":true,"img":false}]}
{"op":"mcm","clk":"5353179008","pt":1646210396081,"mc":[{"id":"1.195453767","rc":[{"atl":[[22,2.4]],"id":42162698},{"atl":[[3.15,1.27]],"id":39637621},{"atl":[[13,3.05]],"id":41910350},{"atl":[[4.3,1.36]],"id":41818763},{"atl":[[8.2,4.07]],"id":43167133},{"atl":[[1.74,1.42]],"id":42154339},{"atl":[[5,1.29]],"id":42688787}],"con":true,"img":false}]}
{"op":"mcm","clk":"5353179495","pt":1646210405144,"mc":[{"id":"1.195453767","rc":[{"atl":[[1.81,126.21]],"id":42154339}],"con":true,"img":false}]}
{"op":"mcm","clk":"5353179544","pt":1646210406074,"mc":[{"id":"1.195453767","rc":[{"atb":[[1.3,0]],"id":42154339}],"con":true,"img":false}]}
{"op":"mcm","clk":"5353179551","pt":1646210406179,"mc":[{"id":"1.195453767","rc":[{"atb":[[1.34,146.07]],"id":42154339}],"con":true,"img":false}]}
{"op":"mcm","clk":"5353179639","pt":1646210407987,"mc":[{"id":"1.195453767","rc":[{"atl":[[1.76,43.66],[2.36,0]],"id":42154339}],"con":true,"img":false}]}
{"op":"mcm","clk":"5353179691","pt":1646210409173,"mc":[{"id":"1.195453767","rc":[{"atb":[[1.33,25.3]],"id":42154339}],"con":true,"img":false}]}
{"op":"mcm","clk":"5353180008","pt":1646210415192,"mc":[{"id":"1.195453767","rc":[{"atb":[[1.37,20.34]],"id":42154339}],"con":true,"img":false}]}
{"op":"mcm","clk":"5353180020","pt":1646210415400,"mc":[{"id":"1.195453767","rc":[{"atb":[[1.34,108.64]],"id":42154339}],"con":true,"img":false}]}
{"op":"mcm","clk":"5353180053","pt":1646210415969,"mc":[{"id":"1.195453767","rc":[{"atl":[[1.74,0]],"id":42154339}],"con":true,"img":false}]}
{"op":"mcm","clk":"5353180059","pt":1646210416075,"mc":[{"id":"1.195453767","rc":[{"atl":[[1000,1.42]],"id":42154339}],"con":true,"img":false}]}
{"op":"mcm","clk":"5353180167","pt":1646210418197,"mc":[{"id":"1.195453767","rc":[{"atl":[[34,3.03],[46,0]],"id":42162698},{"atl":[[4.2,0],[3.65,37.74]],"id":39637621},{"atl":[[22,4.76],[28,0]],"id":41910350},{"atl":[[5.5,24.91],[6.6,10.58]],"id":41818763},{"atl":[[10.5,1.27],[8.8,16.25]],"id":43167133},{"atl":[[1.95,0],[1.79,164.99]],"id":42154339},{"atl":[[5.8,20.83],[7,0]],"id":42688787}],"con":true,"img":false}]}
{"op":"mcm","clk":"5353180379","pt":1646210422067,"mc":[{"id":"1.195453767","rc":[{"atb":[[1.34,0]],"id":42154339}],"con":true,"img":false}]}
{"op":"mcm","clk":"5353180383","pt":1646210422170,"mc":[{"id":"1.195453767","rc":[{"atb":[[1.27,108.64]],"id":42154339}],"con":true,"img":false}]}
{"op":"mcm","clk":"5353180490","pt":1646210424289,"mc":[{"id":"1.195453767","rc":[{"atb":[[1.37,0]],"id":42154339}],"con":true,"img":false}]}
{"op":"mcm","clk":"5353180518","pt":1646210425006,"mc":[{"id":"1.195453767","rc":[{"atl":[[1000,0]],"id":42154339}],"con":true,"img":false}]}
{"op":"mcm","clk":"5353180521","pt":1646210425110,"mc":[{"id":"1.195453767","rc":[{"atl":[[1.74,1.42]],"id":42154339}],"con":true,"img":false}]}
{"op":"mcm","clk":"5353180564","pt":1646210425988,"mc":[{"id":"1.195453767","rc":[{"atl":[[3.25,0]],"id":39637621},{"atl":[[14.5,0.89]],"id":41910350}],"con":true,"img":false}]}
{"op":"mcm","clk":"5353180568","pt":1646210426092,"mc":[{"id":"1.195453767","rc":[{"atl":[[3.35,18.58]],"id":39637621},{"atl":[[15.5,2.72]],"id":41910350}],"con":true,"img":false}]}
{"op":"mcm","clk":"5353180649","pt":1646210428102,"mc":[{"id":"1.195453767","rc":[{"atb":[[4.4,22.73]],"id":41910350},{"atb":[[1.34,34.49]],"id":42154339}],"con":true,"img":false}]}
{"op":"mcm","clk":"5353180653","pt":1646210428204,"mc":[{"id":"1.195453767","rc":[{"atb":[[4.6,19.65]],"id":41910350}],"con":true,"img":false}]}
{"op":"mcm","clk":"5353180748","pt":1646210430010,"mc":[{"id":"1.195453767","rc":[{"atb":[[1.83,0],[2.02,60.2]],"id":41818763}],"con":true,"img":false}]}
{"op":"mcm","clk":"5353180765","pt":1646210430218,"mc":[{"id":"1.195453767","rc":[{"atb":[[1.3,25.08]],"id":42154339}],"con":true,"img":false}]}
{"op":"mcm","clk":"5353180939","pt":1646210433412,"mc":[{"id":"1.195453767","rc":[{"atb":[[1.33,0]],"id":42154339}],"con":true,"img":false}]}
{"op":"mcm","clk":"5353180949","pt":1646210433618,"mc":[{"id":"1.195453767","rc":[{"atb":[[1.34,0]],"id":42154339}],"con":true,"img":false}]}
{"op":"mcm","clk":"5353181015","pt":1646210434909,"mc":[{"id":"1.195453767","rc":[{"atl":[[4.1,32.26],[3.65,0]],"id":39637621},{"atl":[[6.4,18.52],[5.5,2.69]],"id":41818763},{"atl":[[10,11.11],[8.8,5.6]],"id":43167133},{"atl":[[1.95,96.78],[1.79,77.65]],"id":42154339}],"con":true,"img":false}]}
{"op":"mcm","clk":"5353181070","pt":1646210435997,"mc":[{"id":"1.195453767","rc":[{"atl":[[25,0]],"id":42162698}],"con":true,"img":false}]}
{"op":"mcm","clk":"5353181077","pt":1646210436100,"mc":[{"id":"1.195453767","rc":[{"atl":[[23,5.45]],"id":42162698}],"con":true,"img":false}]}
{"op":"mcm","clk":"5353181207","pt":1646210438997,"mc":[{"id":"1.195453767","rc":[{"atb":[[5.3,7.85]],"id":42162698},{"atb":[[1.82,3.23]],"id":39637621},{"atb":[[2.32,8.96]],"id":41818763},{"atb":[[4.9,8.14]],"id":41910350},{"atb":[[3.75,7.29]],"id":43167133},{"atb":[[1.31,1.58]],"id":42154339},{"atb":[[2.98,4.7]],"id":42688787}],"con":true,"img":false}]}
{"op":"mcm","clk":"5353181211","pt":1646210439101,"mc":[{"id":"1.195453767","rc":[{"atb":[[1.83,19.85],[1.81,0]],"id":39637621}],"con":true,"img":false}]}
{"op":"mcm","clk":"5353181228","pt":1646210439513,"mc":[{"id":"1.195453767","rc":[{"atb":[[1.82,1.62]],"id":39637621}],"con":true,"img":false}]}
{"op":"mcm","clk":"5353181234","pt":1646210439618,"mc":[{"id":"1.195453767","rc":[{"atb":[[1.84,1.61]],"id":39637621}],"con":true,"img":false}]}
{"op":"mcm","clk":"5353181249","pt":1646210439927,"mc":[{"id":"1.195453767","rc":[{"atb":[[1.82,0]],"id":39637621}],"con":true,"img":false}]}
{"op":"mcm","clk":"5353181255","pt":1646210440031,"mc":[{"id":"1.195453767","rc":[{"atb":[[1.84,3.23]],"id":39637621}],"con":true,"img":false}]}
{"op":"mcm","clk":"5353181292","pt":1646210440501,"mc":[{"id":"1.195453767","rc":[{"atb":[[1.3,52.92]],"id":42154339}],"con":true,"img":false}]}
{"op":"mcm","clk":"5353181729","pt":1646210448034,"mc":[{"id":"1.195453767","rc":[{"atl":[[2.46,0]],"id":42154339}],"con":true,"img":false}]}
{"op":"mcm","clk":"5353181733","pt":1646210448137,"mc":[{"id":"1.195453767","rc":[{"atl":[[2.26,43.66]],"id":42154339}],"con":true,"img":false}]}
{"op":"mcm","clk":"5353181942","pt":1646210451939,"mc":[{"id":"1.195453767","rc":[{"atl":[[15.5,0]],"id":41910350}],"con":true,"img":false}]}
{"op":"mcm","clk":"5353181948","pt":1646210452042,"mc":[{"id":"1.195453767","rc":[{"atl":[[14.5,3.62]],"id":41910350}],"con":true,"img":false}]}
{"op":"mcm","clk":"5353182185","pt":1646210456016,"mc":[{"id":"1.195453767","rc":[{"atl":[[3.35,0]],"id":39637621},{"spn":2.49,"spf":"NaN","id":39637621},{"spn":3.32,"spf":"NaN","id":41818763},{"spn":1.52,"spf":"NaN","id":42154339},{"spn":3.99,"spf":"NaN","id":42688787}],"con":true,"img":false}]}
{"op":"mcm","clk":"5353182192","pt":1646210456118,"mc":[{"id":"1.195453767","rc":[{"atl":[[3.25,18.58]],"id":39637621}],"con":true,"img":false}]}
{"op":"mcm","clk":"5353182224","pt":1646210456733,"mc":[{"id":"1.195453767","rc":[{"atb":[[1.83,0],[1.85,19.85]],"id":39637621}],"con":true,"img":false}]}
{"op":"mcm","clk":"5353182264","pt":1646210457453,"mc":[{"id":"1.195453767","rc":[{"atb":[[1.84,0]],"id":39637621}],"con":true,"img":false}]}
{"op":"mcm","clk":"5353182267","pt":1646210457556,"mc":[{"id":"1.195453767","rc":[{"atb":[[1.86,3.23]],"id":39637621}],"con":true,"img":false}]}
{"op":"mcm","clk":"5353182271","pt":1646210457609,"mc":[{"id":"1.195453767","rc":[{"atb":[[1.85,0],[1.81,39.7]],"id":39637621}],"con":true,"img":false}]}
{"op":"mcm","clk":"5353182291","pt":1646210458020,"mc":[{"id":"1.195453767","rc":[{"atl":[[6.6,0]],"id":41818763}],"con":true,"img":false}]}
{"op":"mcm","clk":"5353182296","pt":1646210458123,"mc":[{"id":"1.195453767","rc":[{"atl":[[6.2,10.58]],"id":41818763}],"con":true,"img":false}]}
{"op":"mcm","clk":"5353182301","pt":1646210458226,"mc":[{"id":"1.195453767","rc":[{"atb":[[1.86,1.62]],"id":39637621}],"con":true,"img":false}]}
{"op":"mcm","clk":"5353182307","pt":1646210458328,"mc":[{"id":"1.195453767","rc":[{"atb":[[1.82,1.61]],"id":39637621}],"con":true,"img":false}]}
{"op":"mcm","clk":"5353182311","pt":1646210458430,"mc":[{"id":"1.195453767","rc":[{"atb":[[1.86,0]],"id":39637621}],"con":true,"img":false}]}
{"op":"mcm","clk":"5353182315","pt":1646210458533,"mc":[{"id":"1.195453767","rc":[{"atb":[[1.82,3.23]],"id":39637621}],"con":true,"img":false}]}
{"op":"mcm","clk":"5353182400","pt":1646210460230,"mc":[{"id":"1.195453767","rc":[{"atb":[[1.8,10.44]],"id":39637621}],"con":true,"img":false}]}
{"op":"mcm","clk":"5353182491","pt":1646210462039,"mc":[{"id":"1.195453767","rc":[{"atb":[[1.27,0]],"id":42154339}],"con":true,"img":false}]}
{"op":"mcm","clk":"5353182496","pt":1646210462141,"mc":[{"id":"1.195453767","rc":[{"atb":[[1.31,110.22]],"id":42154339}],"con":true,"img":false}]}
{"op":"mcm","clk":"5353182569","pt":1646210463333,"mc":[{"id":"1.195453767","rc":[{"atb":[[1.3,27.83]],"id":42154339}],"con":true,"img":false}]}
{"op":"mcm","clk":"5353182632","pt":1646210464157,"mc":[{"id":"1.195453767","rc":[{"atb":[[1.32,43.67]],"id":42154339}],"con":true,"img":false}]}
{"op":"mcm","clk":"5353182646","pt":1646210464465,"mc":[{"id":"1.195453767","rc":[{"atb":[[1.31,108.64]],"id":42154339}],"con":true,"img":false}]}
{"op":"mcm","clk":"5353182649","pt":1646210464567,"mc":[{"id":"1.195453767","rc":[{"atb":[[1.33,1.58]],"id":42154339}],"con":true,"img":false}]}
{"op":"mcm","clk":"5353182659","pt":1646210464724,"mc":[{"id":"1.195453767","rc":[{"atb":[[1.32,0]],"id":42154339}],"con":true,"img":false}]}
{"op":"mcm","clk":"5353182695","pt":1646210465339,"mc":[{"id":"1.195453767","rc":[{"atb":[[1.33,0]],"id":42154339}],"con":true,"img":false}]}
{"op":"mcm","clk":"5353182699","pt":1646210465443,"mc":[{"id":"1.195453767","rc":[{"atb":[[1.32,1.58]],"id":42154339}],"con":true,"img":false}]}
{"op":"mcm","clk":"5353182754","pt":1646210466372,"mc":[{"id":"1.195453767","rc":[{"atb":[[1.85,8.85]],"id":39637621}],"con":true,"img":false}]}
{"op":"mcm","clk":"5353182801","pt":1646210467144,"mc":[{"id":"1.195453767","rc":[{"atb":[[1.82,0]],"id":39637621}],"con":true,"img":false}]}
{"op":"mcm","clk":"5353182809","pt":1646210467246,"mc":[{"id":"1.195453767","rc":[{"atb":[[1.86,3.23]],"id":39637621}],"con":true,"img":false}]}
{"op":"mcm","clk":"5353182968","pt":1646210470073,"mc":[{"id":"1.195453767","rc":[{"atb":[[1.31,0]],"id":42154339}],"con":true,"img":false}]}
{"op":"mcm","clk":"5353182974","pt":1646210470176,"mc":[{"id":"1.195453767","rc":[{"atb":[[1.27,108.64]],"id":42154339}],"con":true,"img":false}]}
{"op":"mcm","clk":"5353182977","pt":1646210470278,"mc":[{"id":"1.195453767","rc":[{"atb":[[1.34,22.13]],"id":42154339}],"con":true,"img":false}]}
{"op":"mcm","clk":"5353182988","pt":1646210470434,"mc":[{"id":"1.195453767","rc":[{"atb":[[1.32,0]],"id":42154339}],"con":true,"img":false}]}
{"op":"mcm","clk":"5353182992","pt":1646210470537,"mc":[{"id":"1.195453767","rc":[{"atb":[[1.31,1.58]],"id":42154339}],"con":true,"img":false}]}
{"op":"mcm","clk":"5353183021","pt":1646210470947,"mc":[{"id":"1.195453767","rc":[{"atl":[[4.1,0],[3.65,37.74]],"id":39637621},{"atl":[[6.4,0],[5.5,24.91]],"id":41818763},{"atl":[[10,0],[8.8,16.25]],"id":43167133},{"atl":[[1.95,0],[1.79,174.43]],"id":42154339}],"con":true,"img":false}]}
{"op":"mcm","clk":"5353183026","pt":1646210471051,"mc":[{"id":"1.195453767","rc":[{"atb":[[1.31,0]],"id":42154339}],"con":true,"img":false}]}
{"op":"mcm","clk":"5353183032","pt":1646210471153,"mc":[{"id":"1.195453767","rc":[{"atb":[[1.35,1.58]],"id":42154339}],"con":true,"img":false}]}
{"op":"mcm","clk":"5353183095","pt":1646210472239,"mc":[{"id":"1.195453767","rc":[{"atb":[[1.34,0]],"id":42154339}],"con":true,"img":false}]}
{"op":"mcm","clk":"5353183135","pt":1646210473162,"mc":[{"id":"1.195453767","rc":[{"atb":[[1.35,0]],"id":42154339}],"con":true,"img":false}]}
{"op":"mcm","clk":"5353183140","pt":1646210473264,"mc":[{"id":"1.195453767","rc":[{"atb":[[1.31,1.58]],"id":42154339}],"con":true,"img":false}]}
{"op":"mcm","clk":"5353183198","pt":1646210474347,"mc":[{"id":"1.195453767","rc":[{"atl":[[3.65,0]],"id":39637621},{"atl":[[5.5,2.69]],"id":41818763},{"atl":[[1.79,77.65]],"id":42154339}],"con":true,"img":false}]}
{"op":"mcm","clk":"5353183202","pt":1646210474449,"mc":[{"id":"1.195453767","rc":[{"atl":[[4.1,32.26]],"id":39637621},{"atl":[[6.4,18.52]],"id":41818763},{"atl":[[1.95,96.78]],"id":42154339}],"con":true,"img":false}]}
{"op":"mcm","clk":"5353183220","pt":1646210474759,"mc":[{"id":"1.195453767","rc":[{"atl":[[1.69,23.71],[1.75,0]],"id":42154339}],"con":true,"img":false}]}
{"op":"mcm","clk":"5353183232","pt":1646210474960,"mc":[{"id":"1.195453767","rc":[{"atb":[[1.87,8.85],[1.81,0]],"id":39637621}],"con":true,"img":false}]}
{"op":"mcm","clk":"5353183248","pt":1646210475269,"mc":[{"id":"1.195453767","rc":[{"atb":[[1.85,0],[1.86,0]],"id":39637621}],"con":true,"img":false}]}
{"op":"mcm","clk":"5353183252","pt":1646210475371,"mc":[{"id":"1.195453767","rc":[{"atb":[[1.87,0],[1.81,25.64],[1.88,3.23]],"id":39637621},{"atl":[[1.74,0]],"id":42154339}],"con":true,"img":false}]}
{"op":"mcm","clk":"5353183257","pt":1646210475475,"mc":[{"id":"1.195453767","rc":[{"atb":[[1.89,10.44],[1.81,0]],"id":39637621},{"atl":[[1.68,1.42]],"id":42154339}],"con":true,"img":false}]}
{"op":"mcm","clk":"5353183284","pt":1646210476041,"mc":[{"id":"1.195453767","rc":[{"atl":[[10,11.11]],"id":43167133}],"con":true,"img":false}]}
{"op":"mcm","clk":"5353183291","pt":1646210476145,"mc":[{"id":"1.195453767","rc":[{"atl":[[8.8,5.6]],"id":43167133}],"con":true,"img":false}]}
{"op":"mcm","clk":"5353183316","pt":1646210476759,"mc":[{"id":"1.195453767","rc":[{"atb":[[1.88,1.61]],"id":39637621}],"con":true,"img":false}]}
{"op":"mcm","clk":"5353183322","pt":1646210476863,"mc":[{"id":"1.195453767","rc":[{"atb":[[1.88,22.49],[1.9,1.62]],"id":39637621}],"con":true,"img":false}]}
{"op":"mcm","clk":"5353183326","pt":1646210476965,"mc":[{"id":"1.195453767","rc":[{"atb":[[1.89,0],[1.81,25.64],[1.88,1.61]],"id":39637621}],"con":true,"img":false}]}
{"op":"mcm","clk":"5353183330","pt":1646210477068,"mc":[{"id":"1.195453767","rc":[{"atb":[[1.89,10.44]],"id":39637621}],"con":true,"img":false}]}
{"op":"mcm","clk":"5353183335","pt":1646210477170,"mc":[{"id":"1.195453767","rc":[{"atb":[[1.81,0]],"id":39637621}],"con":true,"img":false}]}
{"op":"mcm","clk":"5353183380","pt":1646210477949,"mc":[{"id":"1.195453767","rc":[{"atl":[[14.5,0.89]],"id":41910350}],"con":true,"img":false}]}
{"op":"mcm","clk":"5353183389","pt":1646210478054,"mc":[{"id":"1.195453767","rc":[{"atl":[[15.5,2.72]],"id":41910350}],"con":true,"img":false}]}
{"op":"mcm","clk":"5353183397","pt":1646210478256,"mc":[{"id":"1.195453767","rc":[{"atb":[[1.3,52.92]],"id":42154339}],"con":true,"img":false}]}
{"op":"mcm","clk":"5353183546","pt":1646210481554,"mc":[{"id":"1.195453767","rc":[{"atb":[[1.8,19.84]],"id":39637621}],"con":true,"img":false}]}
{"op":"mcm","clk":"5353183581","pt":1646210482373,"mc":[{"id":"1.195453767","rc":[{"atb":[[5.2,23.81]],"id":42162698},{"atb":[[4.6,41.08]],"id":41910350},{"atb":[[2.04,0]],"id":42688787}],"con":true,"img":false}]}
{"op":"mcm","clk":"5353183585","pt":1646210482476,"mc":[{"id":"1.195453767","rc":[{"atb":[[4.9,19.23]],"id":42162698},{"atb":[[4.4,0]],"id":41910350},{"atb":[[2.88,0],[3.05,45.74]],"id":43167133},{"atb":[[2.14,80.44]],"id":42688787}],"con":true,"img":false}]}
{"op":"mcm","clk":"5353183718","pt":1646210484798,"mc":[{"id":"1.195453767","rc":[{"atl":[[1.71,57.6]],"id":42154339}],"con":true,"img":false}]}
{"op":"mcm","clk":"5353183851","pt":1646210488090,"mc":[{"id":"1.195453767","rc":[{"atb":[[1.25,242.35]],"id":42154339}],"con":true,"img":false}]}
{"op":"mcm","clk":"5353183855","pt":1646210488195,"mc":[{"id":"1.195453767","rc":[{"atb":[[1.23,305.67]],"id":42154339}],"con":true,"img":false}]}
{"op":"mcm","clk":"5353184209","pt":1646210493973,"mc":[{"id":"1.195453767","rc":[{"atl":[[5.4,0]],"id":42688787}],"con":true,"img":false}]}
{"op":"mcm","clk":"5353184216","pt":1646210494076,"mc":[{"id":"1.195453767","rc":[{"atl":[[5.6,9.49]],"id":42688787}],"con":true,"img":false}]}
{"op":"mcm","clk":"5353184266","pt":1646210494692,"mc":[{"id":"1.195453767","rc":[{"atl":[[1.73,84.03],[1.81,0]],"id":42154339}],"con":true,"img":false}]}
{"op":"mcm","clk":"5353184429","pt":1646210497581,"mc":[{"id":"1.195453767","rc":[{"atl":[[1.68,0],[1.69,22.42]],"id":42154339},{"trd":[[1.69,60.56],[1.68,2.85]],"ltp":1.69,"tv":63.41,"id":42154339}],"con":true,"img":false}]}
{"op":"mcm","clk":"5353184438","pt":1646210497787,"mc":[{"id":"1.195453767","rc":[{"atl":[[1.73,0],[1.71,0],[1.69,0],[1.72,22.56],[1.79,0],[1.77,0]],"id":42154339}],"con":true,"img":false}]}
{"op":"mcm","clk":"5353184454","pt":1646210498093,"mc":[{"id":"1.195453767","rc":[{"atb":[[1.88,0]],"id":39637621},{"atb":[[4.6,21.43]],"id":41910350},{"atl":[[15.5,0]],"id":41910350},{"atl":[[2.26,0]],"id":42154339}],"con":true,"img":false}]}
{"op":"mcm","clk":"5353184458","pt":1646210498197,"mc":[{"id":"1.195453767","rc":[{"atb":[[1.9,3.23]],"id":39637621},{"atb":[[4.4,19.65]],"id":41910350},{"atl":[[14.5,3.62]],"id":41910350},{"atl":[[2.42,43.66]],"id":42154339}],"con":true,"img":false}]}
{"op":"mcm","clk":"5353184517","pt":1646210499484,"mc":[{"id":"1.195453767","rc":[{"atb":[[1.32,43.67]],"id":42154339}],"con":true,"img":false}]}
{"op":"mcm","clk":"5353184543","pt":1646210500002,"mc":[{"id":"1.195453767","rc":[{"atb":[[4.7,13.51]],"id":41910350},{"atb":[[1.27,0]],"id":42154339}],"con":true,"img":false}]}
{"op":"mcm","clk":"5353184549","pt":1646210500106,"mc":[{"id":"1.195453767","rc":[{"atb":[[4.8,10.64]],"id":41910350},{"atb":[[1.31,110.22]],"id":42154339}],"con":true,"img":false}]}
{"op":"mcm","clk":"5353184566","pt":1646210500417,"mc":[{"id":"1.195453767","rc":[{"atb":[[1.31,108.64]],"id":42154339}],"con":true,"img":false}]}
{"op":"mcm","clk":"5353184573","pt":1646210500520,"mc":[{"id":"1.195453767","rc":[{"atb":[[1.33,1.58]],"id":42154339}],"con":true,"img":false}]}
{"op":"mcm","clk":"5353184675","pt":1646210502019,"mc":[{"id":"1.195453767","rc":[{"atl":[[1.76,0]],"id":42154339}],"con":true,"img":false}]}
{"op":"mcm","clk":"5353184681","pt":1646210502122,"mc":[{"id":"1.195453767","rc":[{"atl":[[1.94,43.66]],"id":42154339}],"con":true,"img":false}]}
{"op":"mcm","clk":"5353184686","pt":1646210502223,"mc":[{"id":"1.195453767","rc":[{"atl":[[2.4,71.43],[1.95,0]],"id":42154339}],"con":true,"img":false}]}
{"op":"mcm","clk":"5353184700","pt":1646210502380,"mc":[{"id":"1.195453767","rc":[{"atb":[[1.32,45.54],[1.3,27.83]],"id":42154339}],"con":true,"img":false}]}
{"op":"mcm","clk":"5353184819","pt":1646210504133,"mc":[{"id":"1.195453767","rc":[{"atl":[[1.94,0]],"id":42154339}],"con":true,"img":false}]}
{"op":"mcm","clk":"5353184827","pt":1646210504184,"mc":[{"id":"1.195453767","rc":[{"atl":[[2.2,43.66]],"id":42154339}],"con":true,"img":false}]}
{"op":"mcm","clk":"5353184867","pt":1646210505005,"mc":[{"id":"1.195453767","rc":[{"atb":[[5.2,0],[4.9,44.87]],"id":42162698},{"atl":[[3.65,37.74]],"id":39637621},{"atb":[[4.6,0],[4.4,43.81]],"id":41910350},{"atl":[[5.5,24.91]],"id":41818763},{"atl":[[10,0],[8.8,16.25]],"id":43167133}],"con":true,"img":false}]}
{"op":"mcm","clk":"5353184871","pt":1646210505107,"mc":[{"id":"1.195453767","rc":[{"atl":[[4.1,0]],"id":39637621},{"atl":[[6.4,0]],"id":41818763}],"con":true,"img":false}]}
{"op":"mcm","clk":"5353185053","pt":1646210507789,"mc":[{"id":"1.195453767","rc":[{"atb":[[1.32,1.87]],"id":42154339},{"atl":[[1.74,54.88]],"id":42154339}],"con":true,"img":false}]}
{"op":"mcm","clk":"5353185086","pt":1646210508300,"mc":[{"id":"1.195453767","rc":[{"atb":[[1.34,22.13]],"id":42154339}],"con":true,"img":false}]}
{"op":"mcm","clk":"5353185100","pt":1646210508507,"mc":[{"id":"1.195453767","rc":[{"atb":[[1.33,0]],"id":42154339}],"con":true,"img":false}]}
{"op":"mcm","clk":"5353185106","pt":1646210508610,"mc":[{"id":"1.195453767","rc":[{"atb":[[1.35,1.58]],"id":42154339}],"con":true,"img":false}]}
{"op":"mcm","clk":"5353185130","pt":1646210508918,"mc":[{"id":"1.195453767","rc":[{"atb":[[1.32,0]],"id":42154339}],"con":true,"img":false}]}
{"op":"mcm","clk":"5353185139","pt":1646210509022,"mc":[{"id":"1.195453767","rc":[{"atb":[[1.35,3.46]],"id":42154339}],"con":true,"img":false}]}
{"op":"mcm","clk":"5353185197","pt":1646210509898,"mc":[{"id":"1.195453767","rc":[{"atb":[[1.31,0]],"id":42154339}],"con":true,"img":false}]}
{"op":"mcm","clk":"5353185203","pt":1646210510001,"mc":[{"id":"1.195453767","rc":[{"atb":[[1.27,108.64]],"id":42154339}],"con":true,"img":false}]}
{"op":"mcm","clk":"5353185281","pt":1646210511390,"mc":[{"id":"1.195453767","rc":[{"atb":[[1.34,0]],"id":42154339}],"con":true,"img":false}]}
{"op":"mcm","clk":"5353185304","pt":1646210511901,"mc":[{"id":"1.195453767","rc":[{"atb":[[1.35,1.58]],"id":42154339}],"con":true,"img":false}]}
{"op":"mcm","clk":"5353185311","pt":1646210512005,"mc":[{"id":"1.195453767","rc":[{"atb":[[1.31,1.87]],"id":42154339}],"con":true,"img":false}]}
{"op":"mcm","clk":"5353185314","pt":1646210512109,"mc":[{"id":"1.195453767","rc":[{"atb":[[1.35,0]],"id":42154339}],"con":true,"img":false}]}
{"op":"mcm","clk":"5353185319","pt":1646210512213,"mc":[{"id":"1.195453767","rc":[{"atb":[[1.31,3.46]],"id":42154339}],"con":true,"img":false}]}
{"op":"mcm","clk":"5353185623","pt":1646210517419,"mc":[{"id":"1.195453767","rc":[{"spn":2.52,"spf":"NaN","id":39637621},{"atb":[[1.3,52.92]],"id":42154339},{"spn":1.51,"spf":"NaN","id":42154339}],"con":true,"img":false}]}
{"op":"mcm","clk":"5353185632","pt":1646210517521,"mc":[{"id":"1.195453767","rc":[{"atl":[[4.1,32.26],[3.65,0]],"id":39637621},{"atl":[[6.4,18.52],[5.5,2.69]],"id":41818763},{"atl":[[10,11.11],[8.8,5.6]],"id":43167133}],"con":true,"img":false}]}
{"op":"mcm","clk":"5353185654","pt":1646210517831,"mc":[{"id":"1.195453767","rc":[{"atl":[[1.76,80.15]],"id":42154339}],"con":true,"img":false}]}
{"op":"mcm","clk":"5353185734","pt":1646210519117,"mc":[{"id":"1.195453767","rc":[{"atl":[[2.4,0],[1.95,105.26]],"id":42154339}],"con":true,"img":false}]}
{"op":"mcm","clk":"5353186018","pt":1646210524013,"mc":[{"id":"1.195453767","rc":[{"atb":[[2.9,0]],"id":43167133}],"con":true,"img":false}]}
{"op":"mcm","clk":"5353186021","pt":1646210524117,"mc":[{"id":"1.195453767","rc":[{"atb":[[3.1,30.05]],"id":43167133}],"con":true,"img":false}]}
{"op":"mcm","clk":"5353186215","pt":1646210527718,"mc":[{"id":"1.195453767","rc":[{"atl":[[1.78,130.16]],"id":42154339}],"con":true,"img":false}]}
{"op":"mcm","clk":"5353186321","pt":1646210529935,"mc":[{"id":"1.195453767","rc":[{"atl":[[2.2,0]],"id":42154339}],"con":true,"img":false}]}
{"op":"mcm","clk":"5353186328","pt":1646210530035,"mc":[{"id":"1.195453767","rc":[{"atl":[[1.73,43.66]],"id":42154339}],"con":true,"img":false}]}
{"op":"mcm","clk":"5353186579","pt":1646210534056,"mc":[{"id":"1.195453767","rc":[{"atb":[[1.32,43.67]],"id":42154339}],"con":true,"img":false}]}
{"op":"mcm","clk":"5353186616","pt":1646210534625,"mc":[{"id":"1.195453767","rc":[{"atb":[[1.31,1.87]],"id":42154339}],"con":true,"img":false}]}
{"op":"mcm","clk":"5353186621","pt":1646210534728,"mc":[{"id":"1.195453767","rc":[{"atb":[[1.33,1.58]],"id":42154339}],"con":true,"img":false}]}
{"op":"mcm","clk":"5353186628","pt":1646210534833,"mc":[{"id":"1.195453767","rc":[{"atb":[[1.31,0]],"id":42154339}],"con":true,"img":false}]}
{"op":"mcm","clk":"5353186633","pt":1646210534934,"mc":[{"id":"1.195453767","rc":[{"atb":[[1.33,3.46]],"id":42154339}],"con":true,"img":false}]}
{"op":"mcm","clk":"5353186684","pt":1646210535969,"mc":[{"id":"1.195453767","rc":[{"atb":[[1.23,0]],"id":42154339},{"atl":[[5.6,0]],"id":42688787}],"con":true,"img":false}]}
{"op":"mcm","clk":"5353186691","pt":1646210536021,"mc":[{"id":"1.195453767","rc":[{"atb":[[1.25,548.03]],"id":42154339},{"atl":[[5.4,9.49]],"id":42688787}],"con":true,"img":false}]}
{"op":"mcm","clk":"5353186911","pt":1646210539469,"mc":[{"id":"1.195453767","rc":[{"atl":[[4.1,0],[3.65,37.74]],"id":39637621},{"atl":[[5.5,24.91]],"id":41818763},{"atl":[[10,0],[8.8,16.25]],"id":43167133},{"atb":[[1.32,0]],"id":42154339},{"atl":[[1.95,0],[1.79,109.76]],"id":42154339}],"con":true,"img":false}]}
{"op":"mcm","clk":"5353186917","pt":1646210539525,"mc":[{"id":"1.195453767","rc":[{"atl":[[6.4,0]],"id":41818763}],"con":true,"img":false}]}
{"op":"mcm","clk":"5353186926","pt":1646210539730,"mc":[{"id":"1.195453767","rc":[{"atb":[[1.33,1.87]],"id":42154339}],"con":true,"img":false}]}
{"op":"mcm","clk":"5353186930","pt":1646210539832,"mc":[{"id":"1.195453767","rc":[{"atb":[[1.31,1.58]],"id":42154339}],"con":true,"img":false}]}
{"op":"mcm","clk":"5353186934","pt":1646210539934,"mc":[{"id":"1.195453767","rc":[{"atb":[[1.27,0]],"id":42154339}],"con":true,"img":false}]}
{"op":"mcm","clk":"5353186942","pt":1646210540039,"mc":[{"id":"1.195453767","rc":[{"atb":[[1.31,110.22]],"id":42154339}],"con":true,"img":false}]}
{"op":"mcm","clk":"5353186953","pt":1646210540246,"mc":[{"id":"1.195453767","rc":[{"atb":[[1.33,0]],"id":42154339}],"con":true,"img":false}]}
{"op":"mcm","clk":"5353186958","pt":1646210540347,"mc":[{"id":"1.195453767","rc":[{"atb":[[1.31,112.1]],"id":42154339}],"con":true,"img":false}]}
{"op":"mcm","clk":"5353187008","pt":1646210541429,"mc":[{"id":"1.195453767","rc":[{"atb":[[1.3,27.83]],"id":42154339}],"con":true,"img":false}]}
{"op":"mcm","clk":"5353187146","pt":1646210543948,"mc":[{"id":"1.195453767","rc":[{"atl":[[2.42,0]],"id":42154339}],"con":true,"img":false}]}
{"op":"mcm","clk":"5353187154","pt":1646210544053,"mc":[{"id":"1.195453767","rc":[{"atl":[[2.22,43.66]],"id":42154339}],"con":true,"img":false}]}
{"op":"mcm","clk":"5353187268","pt":1646210546064,"mc":[{"id":"1.195453767","rc":[{"atl":[[3.25,0]],"id":39637621},{"atl":[[14.5,0.89]],"id":41910350}],"con":true,"img":false}]}
{"op":"mcm","clk":"5353187275","pt":1646210546165,"mc":[{"id":"1.195453767","rc":[{"atl":[[3.35,18.58]],"id":39637621},{"atl":[[15.5,2.72]],"id":41910350}],"con":true,"img":false}]}
{"op":"mcm","clk":"5353187352","pt":1646210547658,"mc":[{"id":"1.195453767","rc":[{"atb":[[1.34,22.13]],"id":42154339}],"con":true,"img":false}]}
{"op":"mcm","clk":"5353187370","pt":1646210547966,"mc":[{"id":"1.195453767","rc":[{"atb":[[1.31,3.46]],"id":42154339},{"atl":[[5.4,0]],"id":42688787}],"con":true,"img":false}]}
{"op":"mcm","clk":"5353187379","pt":1646210548075,"mc":[{"id":"1.195453767","rc":[{"atb":[[1.27,108.64],[1.31,1.58]],"id":42154339},{"atl":[[5.6,9.49]],"id":42688787}],"con":true,"img":false}]}
{"op":"mcm","clk":"5353187382","pt":1646210548176,"mc":[{"id":"1.195453767","rc":[{"atb":[[1.35,1.87]],"id":42154339}],"con":true,"img":false}]}
{"op":"mcm","clk":"5353187388","pt":1646210548276,"mc":[{"id":"1.195453767","rc":[{"atb":[[1.31,0]],"id":42154339}],"con":true,"img":false}]}
{"op":"mcm","clk":"5353187393","pt":1646210548379,"mc":[{"id":"1.195453767","rc":[{"atb":[[1.35,3.46]],"id":42154339}],"con":true,"img":false}]}
{"op":"mcm","clk":"5353187485","pt":1646210549973,"mc":[{"id":"1.195453767","rc":[{"atb":[[4.4,24.16]],"id":41910350}],"con":true,"img":false}]}
{"op":"mcm","clk":"5353187492","pt":1646210550076,"mc":[{"id":"1.195453767","rc":[{"atb":[[4.6,19.65]],"id":41910350}],"con":true,"img":false}]}
{"op":"mcm","clk":"5353187522","pt":1646210550542,"mc":[{"id":"1.195453767","rc":[{"atb":[[1.34,0]],"id":42154339}],"con":true,"img":false}]}
{"op":"mcm","clk":"5353187599","pt":1646210551881,"mc":[{"id":"1.195453767","rc":[{"atb":[[1.35,1.87]],"id":42154339}],"con":true,"img":false}]}
{"op":"mcm","clk":"5353187604","pt":1646210551933,"mc":[{"id":"1.195453767","rc":[{"atb":[[1.31,1.58]],"id":42154339}],"con":true,"img":false}]}
{"op":"mcm","clk":"5353187837","pt":1646210556559,"mc":[{"id":"1.195453767","rc":[{"atb":[[1.3,52.92]],"id":42154339}],"con":true,"img":false}]}
{"op":"mcm","clk":"5353188439","pt":1646210567999,"mc":[{"id":"1.195453767","rc":[{"atb":[[1.36,26.04]],"id":42154339}],"con":true,"img":false}]}
{"op":"mcm","clk":"5353188470","pt":1646210568669,"mc":[{"id":"1.195453767","rc":[{"atb":[[1.31,0]],"id":42154339}],"con":true,"img":false}]}
{"op":"mcm","clk":"5353188474","pt":1646210568773,"mc":[{"id":"1.195453767","rc":[{"atb":[[1.37,1.58]],"id":42154339}],"con":true,"img":false}]}
{"op":"mcm","clk":"5353188920","pt":1646210577992,"mc":[{"id":"1.195453767","rc":[{"atb":[[1.27,0]],"id":42154339},{"atl":[[1.73,0]],"id":42154339},{"spn":1.54,"spf":"NaN","id":42154339}],"con":true,"img":false}]}
{"op":"mcm","clk":"5353188922","pt":1646210578093,"mc":[{"id":"1.195453767","rc":[{"atb":[[1.36,0],[1.31,108.64]],"id":42154339},{"atl":[[1.75,43.66]],"id":42154339}],"con":true,"img":false}]}
{"op":"mcm","clk":"5353188927","pt":1646210578300,"mc":[{"id":"1.195453767","rc":[{"atb":[[1.37,0]],"id":42154339}],"con":true,"img":false}]}
{"op":"mcm","clk":"5353188933","pt":1646210578405,"mc":[{"id":"1.195453767","rc":[{"atb":[[1.32,1.58]],"id":42154339}],"con":true,"img":false}]}
{"op":"mcm","clk":"5353188945","pt":1646210578712,"mc":[{"id":"1.195453767","rc":[{"atb":[[1.35,0]],"id":42154339}],"con":true,"img":false}]}
{"op":"mcm","clk":"5353188952","pt":1646210578818,"mc":[{"id":"1.195453767","rc":[{"atb":[[1.32,3.46]],"id":42154339}],"con":true,"img":false}]}
{"op":"mcm","clk":"5353189022","pt":1646210580005,"mc":[{"id":"1.195453767","rc":[{"atl":[[5.4,13.95],[6.2,0]],"id":41818763}],"con":true,"img":false}]}
{"op":"mcm","clk":"5353189052","pt":1646210580624,"mc":[{"id":"1.195453767","rc":[{"atb":[[1.3,27.83]],"id":42154339}],"con":true,"img":false}]}
{"op":"mcm","clk":"5353189153","pt":1646210582696,"mc":[{"id":"1.195453767","rc":[{"atb":[[1.3,0]],"id":42154339}],"con":true,"img":false}]}
{"op":"mcm","clk":"5353189263","pt":1646210584827,"mc":[{"id":"1.195453767","rc":[{"atb":[[4.5,63.19],[4.9,19.23]],"id":42162698},{"atb":[[2.32,3.17],[2.16,86.21]],"id":41818763},{"atb":[[4,33.33],[4.4,0]],"id":41910350},{"atb":[[2.78,56.18],[3.05,0]],"id":43167133},{"atl":[[8.8,5.6],[9.4,26.78]],"id":43167133},{"atl":[[1.87,114.94],[1.79,0]],"id":42154339},{"atb":[[1.89,79.9],[2.14,0]],"id":42688787}],"con":true,"img":false}]}
{"op":"mcm","clk":"5353189307","pt":1646210585707,"mc":[{"id":"1.195453767","rc":[{"atb":[[2.32,1.67]],"id":41818763}],"con":true,"img":false}]}
{"op":"mcm","clk":"5353189311","pt":1646210585806,"mc":[{"id":"1.195453767","rc":[{"atb":[[2.3,1.5]],"id":41818763}],"con":true,"img":false}]}
{"op":"mcm","clk":"5353189322","pt":1646210586015,"mc":[{"id":"1.195453767","rc":[{"atb":[[3.1,0]],"id":43167133}],"con":true,"img":false}]}
{"op":"mcm","clk":"5353189326","pt":1646210586119,"mc":[{"id":"1.195453767","rc":[{"atb":[[2.8,30.05]],"id":43167133}],"con":true,"img":false}]}
{"op":"mcm","clk":"5353189352","pt":1646210586629,"mc":[{"id":"1.195453767","rc":[{"atb":[[2.34,0]],"id":41818763},{"atb":[[1.34,22.13]],"id":42154339}],"con":true,"img":false}]}
{"op":"mcm","clk":"5353189360","pt":1646210586731,"mc":[{"id":"1.195453767","rc":[{"atb":[[2.32,0],[2.3,3.08]],"id":41818763}],"con":true,"img":false}]}
{"op":"mcm","clk":"5353189366","pt":1646210586793,"mc":[{"id":"1.195453767","rc":[{"atb":[[2.3,4.75]],"id":41818763}],"con":true,"img":false}]}
{"op":"mcm","clk":"5353189382","pt":1646210587100,"mc":[{"id":"1.195453767","rc":[{"atb":[[1.32,1.58]],"id":42154339}],"con":true,"img":false}]}
{"op":"mcm","clk":"5353189388","pt":1646210587204,"mc":[{"id":"1.195453767","rc":[{"atb":[[1.35,1.87]],"id":42154339}],"con":true,"img":false}]}
{"op":"mcm","clk":"5353189440","pt":1646210588023,"mc":[{"id":"1.195453767","rc":[{"atb":[[1.31,0]],"id":42154339}],"con":true,"img":false}]}
{"op":"mcm","clk":"5353189447","pt":1646210588125,"mc":[{"id":"1.195453767","rc":[{"atb":[[1.27,108.64],[1.32,0]],"id":42154339}],"con":true,"img":false}]}
{"op":"mcm","clk":"5353189455","pt":1646210588230,"mc":[{"id":"1.195453767","rc":[{"atb":[[1.35,3.46]],"id":42154339}],"con":true,"img":false}]}
{"op":"mcm","clk":"5353189560","pt":1646210589826,"mc":[{"id":"1.195453767","rc":[{"atb":[[1.34,0]],"id":42154339}],"con":true,"img":false}]}
{"op":"mcm","clk":"5353189631","pt":1646210590816,"mc":[{"id":"1.195453767","rc":[{"atb":[[1.35,1.87]],"id":42154339}],"con":true,"img":false}]}
{"op":"mcm","clk":"5353189635","pt":1646210590916,"mc":[{"id":"1.195453767","rc":[{"atb":[[1.28,1.58]],"id":42154339}],"con":true,"img":false}]}
{"op":"mcm","clk":"5353189945","pt":1646210595620,"mc":[{"id":"1.195453767","rc":[{"atb":[[1.3,25.08]],"id":42154339}],"con":true,"img":false}]}
{"op":"mcm","clk":"5353189962","pt":1646210595825,"mc":[{"id":"1.195453767","rc":[{"atb":[[1.28,0]],"id":42154339}],"con":true,"img":false}]}
{"op":"mcm","clk":"5353189966","pt":1646210595930,"mc":[{"id":"1.195453767","rc":[{"atb":[[1.31,1.58]],"id":42154339}],"con":true,"img":false}]}
{"op":"mcm","clk":"5353190076","pt":1646210597943,"mc":[{"id":"1.195453767","rc":[{"atl":[[1.75,0]],"id":42154339}],"con":true,"img":false}]}
{"op":"mcm","clk":"5353190080","pt":1646210598039,"mc":[{"id":"1.195453767","rc":[{"atl":[[1.73,43.66]],"id":42154339}],"con":true,"img":false}]}
{"op":"mcm","clk":"5353190239","pt":1646210601209,"mc":[{"id":"1.195453767","rc":[{"atb":[[1.36,16.75]],"id":42154339}],"con":true,"img":false}]}
{"op":"mcm","clk":"5353190261","pt":1646210601829,"mc":[{"id":"1.195453767","rc":[{"atb":[[1.31,0]],"id":42154339}],"con":true,"img":false}]}
{"op":"mcm","clk":"5353190265","pt":1646210601926,"mc":[{"id":"1.195453767","rc":[{"atb":[[1.37,1.58]],"id":42154339}],"con":true,"img":false}]}
{"op":"mcm","clk":"5353190384","pt":1646210604045,"mc":[{"id":"1.195453767","rc":[{"atl":[[5.6,0]],"id":42688787}],"con":true,"img":false}]}
{"op":"mcm","clk":"5353190387","pt":1646210604148,"mc":[{"id":"1.195453767","rc":[{"atl":[[5.4,9.49]],"id":42688787}],"con":true,"img":false}]}
{"op":"mcm","clk":"5353190661","pt":1646210610253,"mc":[{"id":"1.195453767","rc":[{"atb":[[1.3,52.92]],"id":42154339}],"con":true,"img":false}]}
{"op":"mcm","clk":"5353190668","pt":1646210610450,"mc":[{"id":"1.195453767","rc":[{"atb":[[1.36,0]],"id":42154339}],"con":true,"img":false}]}
{"op":"mcm","clk":"5353190701","pt":1646210611127,"mc":[{"id":"1.195453767","rc":[{"atb":[[1.35,0]],"id":42154339}],"con":true,"img":false}]}
{"op":"mcm","clk":"5353190707","pt":1646210611231,"mc":[{"id":"1.195453767","rc":[{"atb":[[1.31,1.87]],"id":42154339}],"con":true,"img":false}]}
{"op":"mcm","clk":"5353190726","pt":1646210611640,"mc":[{"id":"1.195453767","rc":[{"atb":[[1.37,0]],"id":42154339}],"con":true,"img":false}]}
{"op":"mcm","clk":"5353190730","pt":1646210611744,"mc":[{"id":"1.195453767","rc":[{"atb":[[1.31,3.46]],"id":42154339}],"con":true,"img":false}]}
{"op":"mcm","clk":"5353191189","pt":1646210621883,"mc":[{"id":"1.195453767","rc":[{"atl":[[4.3,49.4],[3.65,0]],"id":39637621},{"atl":[[6.8,17.24],[5.5,2.69]],"id":41818763},{"atl":[[10.5,11.8],[9.4,14.88]],"id":43167133},{"atl":[[1.87,0],[2.02,98.04]],"id":42154339},{"atl":[[7,16.67]],"id":42688787}],"con":true,"img":false}]}
{"op":"mcm","clk":"5353191194","pt":1646210621939,"mc":[{"id":"1.195453767","rc":[{"atb":[[1.27,0]],"id":42154339},{"atl":[[5.8,0]],"id":42688787}],"con":true,"img":false}]}
{"op":"mcm","clk":"5353191199","pt":1646210622046,"mc":[{"id":"1.195453767","rc":[{"atb":[[1.31,112.1]],"id":42154339}],"con":true,"img":false}]}
{"op":"mcm","clk":"5353191240","pt":1646210623064,"mc":[{"id":"1.195453767","rc":[{"atb":[[1.3,27.83]],"id":42154339}],"con":true,"img":false}]}
{"op":"mcm","clk":"5353191273","pt":1646210623946,"mc":[{"id":"1.195453767","rc":[{"atl":[[5.4,0],[6.2,10.96]],"id":41818763}],"con":true,"img":false}]}
{"op":"mcm","clk":"5353191473","pt":1646210629185,"mc":[{"id":"1.195453767","rc":[{"atb":[[1.34,22.13]],"id":42154339}],"con":true,"img":false}]}
{"op":"mcm","clk":"5353191495","pt":1646210629757,"mc":[{"id":"1.195453767","rc":[{"atb":[[1.31,110.22]],"id":42154339}],"con":true,"img":false}]}
{"op":"mcm","clk":"5353191499","pt":1646210629862,"mc":[{"id":"1.195453767","rc":[{"atb":[[1.31,108.64],[1.35,1.87]],"id":42154339}],"con":true,"img":false}]}
{"op":"mcm","clk":"5353191504","pt":1646210629962,"mc":[{"id":"1.195453767","rc":[{"atb":[[1.31,0],[1.35,3.46]],"id":42154339}],"con":true,"img":false}]}
{"op":"mcm","clk":"5353191513","pt":1646210630065,"mc":[{"id":"1.195453767","rc":[{"atb":[[1.27,108.64]],"id":42154339}],"con":true,"img":false}]}
{"op":"mcm","clk":"5353191619","pt":1646210632075,"mc":[{"id":"1.195453767","rc":[{"atb":[[1.34,0]],"id":42154339}],"con":true,"img":false}]}
{"op":"mcm","clk":"5353191647","pt":1646210632548,"mc":[{"id":"1.195453767","rc":[{"atb":[[1.35,1.87]],"id":42154339}],"con":true,"img":false}]}
{"op":"mcm","clk":"5353191653","pt":1646210632653,"mc":[{"id":"1.195453767","rc":[{"atb":[[1.31,1.58]],"id":42154339}],"con":true,"img":false}]}
{"op":"mcm","clk":"5353191700","pt":1646210633892,"mc":[{"id":"1.195453767","rc":[{"atb":[[1.36,18.13]],"id":42154339}],"con":true,"img":false}]}
{"op":"mcm","clk":"5353191727","pt":1646210634365,"mc":[{"id":"1.195453767","rc":[{"atb":[[1.31,0]],"id":42154339}],"con":true,"img":false}]}
{"op":"mcm","clk":"5353191733","pt":1646210634467,"mc":[{"id":"1.195453767","rc":[{"atb":[[1.37,1.58]],"id":42154339}],"con":true,"img":false}]}
{"op":"mcm","clk":"5353191858","pt":1646210637599,"mc":[{"id":"1.195453767","rc":[{"atl":[[4.3,19.1],[3.85,35.09]],"id":39637621},{"atl":[[6.8,0],[5.9,20.41]],"id":41818763},{"atl":[[10.5,1.27],[9.4,26.78]],"id":43167133},{"atl":[[1.87,109.76],[2.02,0]],"id":42154339},{"atl":[[6.2,19.23],[7,0]],"id":42688787}],"con":true,"img":false}]}
{"op":"mcm","clk":"5353191884","pt":1646210638178,"mc":[{"id":"1.195453767","rc":[{"spn":3.3,"spf":"NaN","id":41818763},{"atb":[[1.3,52.92]],"id":42154339}],"con":true,"img":false}]}
{"op":"mcm","clk":"5353192122","pt":1646210643283,"mc":[{"id":"1.195453767","rc":[{"atb":[[1.36,0]],"id":42154339}],"con":true,"img":false}]}
{"op":"mcm","clk":"5353192166","pt":1646210644108,"mc":[{"id":"1.195453767","rc":[{"atb":[[1.37,0]],"id":42154339}],"con":true,"img":false}]}
{"op":"mcm","clk":"5353192171","pt":1646210644214,"mc":[{"id":"1.195453767","rc":[{"atb":[[1.31,1.58]],"id":42154339}],"con":true,"img":false}]}
{"op":"mcm","clk":"5353192245","pt":1646210646089,"mc":[{"id":"1.195453767","rc":[{"atl":[[15.5,0]],"id":41910350}],"con":true,"img":false}]}
{"op":"mcm","clk":"5353192249","pt":1646210646190,"mc":[{"id":"1.195453767","rc":[{"atl":[[14.5,3.62]],"id":41910350}],"con":true,"img":false}]}
{"op":"mcm","clk":"5353192602","pt":1646210653984,"mc":[{"id":"1.195453767","rc":[{"atl":[[14.5,0.89]],"id":41910350}],"con":true,"img":false}]}
{"op":"mcm","clk":"5353192608","pt":1646210654090,"mc":[{"id":"1.195453767","rc":[{"atl":[[15.5,2.72]],"id":41910350}],"con":true,"img":false}]}
{"op":"mcm","clk":"5353192649","pt":1646210654811,"mc":[{"id":"1.195453767","rc":[{"atb":[[4.5,34.62],[4.9,44.87]],"id":42162698},{"atl":[[3.6,38.46],[3.85,0]],"id":39637621},{"atb":[[4,0],[4.2,31.25]],"id":41910350},{"atb":[[2.3,17.15],[2.16,0]],"id":41818763},{"atl":[[4.4,0],[4.5,5.71]],"id":41818763},{"atb":[[2.98,45.74],[2.78,0]],"id":43167133},{"atl":[[8.8,16.25],[9.4,14.88]],"id":43167133},{"atl":[[1.7,23.21],[1.87,0],[1.72,0],[1.81,109.76]],"id":42154339},{"atb":[[1.89,0],[2.02,79.9]],"id":42688787},{"atl":[[5.8,20.83],[6.2,0]],"id":42688787}],"con":true,"img":false}]}
{"op":"mcm","clk":"5353192714","pt":1646210656008,"mc":[{"id":"1.195453767","rc":[{"atb":[[1.27,0]],"id":42154339}],"con":true,"img":false}]}
{"op":"mcm","clk":"5353192725","pt":1646210656104,"mc":[{"id":"1.195453767","rc":[{"atb":[[1.31,110.22]],"id":42154339}],"con":true,"img":false}]}
{"op":"mcm","clk":"5353192732","pt":1646210656207,"mc":[{"id":"1.195453767","rc":[{"atl":[[4.3,0]],"id":41818763}],"con":true,"img":false}]}
{"op":"mcm","clk":"5353192737","pt":1646210656310,"mc":[{"id":"1.195453767","rc":[{"atl":[[4.4,1.36],[5.9,0],[5.6,21.74]],"id":41818763}],"con":true,"img":false}]}
{"op":"mcm","clk":"5353192763","pt":1646210656826,"mc":[{"id":"1.195453767","rc":[{"atb":[[1.35,0]],"id":42154339}],"con":true,"img":false}]}
{"op":"mcm","clk":"5353192770","pt":1646210656929,"mc":[{"id":"1.195453767","rc":[{"atb":[[1.32,1.87]],"id":42154339}],"con":true,"img":false}]}
{"op":"mcm","clk":"5353192801","pt":1646210657710,"mc":[{"id":"1.195453767","rc":[{"atb":[[1.3,25.08]],"id":42154339}],"con":true,"img":false}]}
{"op":"mcm","clk":"5353192878","pt":1646210659106,"mc":[{"id":"1.195453767","rc":[{"atb":[[1.3,0]],"id":42154339}],"con":true,"img":false}]}
{"op":"mcm","clk":"5353192933","pt":1646210659925,"mc":[{"id":"1.195453767","rc":[{"atl":[[9,21.88],[8.8,5.6]],"id":43167133}],"con":true,"img":false}]}
{"op":"mcm","clk":"5353193079","pt":1646210662719,"mc":[{"id":"1.195453767","rc":[{"atl":[[3.6,0],[4,33.33]],"id":39637621},{"atl":[[6.4,18.52],[5.6,0]],"id":41818763},{"atl":[[1.7,0],[1.96,104.17],[1.69,23.54],[1.81,0]],"id":42154339},{"atl":[[5.8,0],[6.8,17.24]],"id":42688787}],"con":true,"img":false}]}
{"op":"mcm","clk":"5353193148","pt":1646210664001,"mc":[{"id":"1.195453767","rc":[{"atb":[[1.31,1.58]],"id":42154339}],"con":true,"img":false}]}
{"op":"mcm","clk":"5353193152","pt":1646210664108,"mc":[{"id":"1.195453767","rc":[{"atb":[[1.27,108.64]],"id":42154339}],"con":true,"img":false}]}
{"op":"mcm","clk":"5353193177","pt":1646210664515,"mc":[{"id":"1.195453767","rc":[{"atb":[[1.31,0]],"id":42154339}],"con":true,"img":false}]}
{"op":"mcm","clk":"5353193185","pt":1646210664616,"mc":[{"id":"1.195453767","rc":[{"atb":[[1.28,1.58],[1.32,0]],"id":42154339}],"con":true,"img":false}]}
{"op":"mcm","clk":"5353193188","pt":1646210664720,"mc":[{"id":"1.195453767","rc":[{"atb":[[1.28,3.46]],"id":42154339}],"con":true,"img":false}]}
{"op":"mcm","clk":"5353193193","pt":1646210664823,"mc":[{"id":"1.195453767","rc":[{"atl":[[4.7,25.31]],"id":41818763}],"con":true,"img":false}]}
{"op":"mcm","clk":"5353193205","pt":1646210665029,"mc":[{"id":"1.195453767","rc":[{"atl":[[9,9.38],[10,11.11]],"id":43167133}],"con":true,"img":false}]}
{"op":"mcm","clk":"5353193240","pt":1646210665810,"mc":[{"id":"1.195453767","rc":[{"atb":[[1.29,43.67]],"id":42154339}],"con":true,"img":false}]}
{"op":"mcm","clk":"5353193261","pt":1646210666419,"mc":[{"id":"1.195453767","rc":[{"atb":[[1.28,0]],"id":42154339}],"con":true,"img":false}]}
{"op":"mcm","clk":"5353193265","pt":1646210666522,"mc":[{"id":"1.195453767","rc":[{"atb":[[1.3,3.46]],"id":42154339}],"con":true,"img":false}]}
{"op":"mcm","clk":"5353193560","pt":1646210672250,"mc":[{"id":"1.195453767","rc":[{"atb":[[1.3,28.54]],"id":42154339}],"con":true,"img":false}]}
{"op":"mcm","clk":"5353193572","pt":1646210672456,"mc":[{"id":"1.195453767","rc":[{"atb":[[1.29,0]],"id":42154339}],"con":true,"img":false}]}
{"op":"mcm","clk":"5353193590","pt":1646210672722,"mc":[{"id":"1.195453767","rc":[{"atl":[[1.71,57.2]],"id":42154339}],"con":true,"img":false}]}
{"op":"mcm","clk":"5353193602","pt":1646210672925,"mc":[{"id":"1.195453767","rc":[{"atl":[[4.8,0],[4.6,0],[5,0]],"id":41818763},{"atl":[[1.7,23.21],[1.71,0],[1.69,0]],"id":42154339}],"con":true,"img":false}]}
{"op":"mcm","clk":"5353193613","pt":1646210673136,"mc":[{"id":"1.195453767","rc":[{"atl":[[4.4,7.24]],"id":41818763},{"atb":[[4.4,29.41],[4.2,0]],"id":41910350},{"atl":[[1.7,0],[1.69,23.54]],"id":42154339}],"con":true,"img":false}]}
{"op":"mcm","clk":"5353193646","pt":1646210673963,"mc":[{"id":"1.195453767","rc":[{"atl":[[4.7,13.51]],"id":41818763}],"con":true,"img":false}]}
{"op":"mcm","clk":"5353193654","pt":1646210674030,"mc":[{"id":"1.195453767","rc":[{"atl":[[5.5,14.49]],"id":41818763}],"con":true,"img":false}]}
{"op":"mcm","clk":"5353194111","pt":1646210683142,"mc":[{"id":"1.195453767","rc":[{"atl":[[4.6,13.89]],"id":41818763},{"atl":[[1.71,57.2]],"id":42154339}],"con":true,"img":false}]}
{"op":"mcm","clk":"5353194156","pt":1646210683972,"mc":[{"id":"1.195453767","rc":[{"atl":[[3.35,0]],"id":39637621}],"con":true,"img":false}]}
{"op":"mcm","clk":"5353194163","pt":1646210684075,"mc":[{"id":"1.195453767","rc":[{"atl":[[3.25,18.58]],"id":39637621}],"con":true,"img":false}]}
{"op":"mcm","clk":"5353194287","pt":1646210686048,"mc":[{"id":"1.195453767","rc":[{"atl":[[15.5,0]],"id":41910350},{"atb":[[1.25,242.35]],"id":42154339}],"con":true,"img":false}]}
{"op":"mcm","clk":"5353194289","pt":1646210686151,"mc":[{"id":"1.195453767","rc":[{"atl":[[14.5,3.62]],"id":41910350},{"atb":[[1.23,305.67]],"id":42154339}],"con":true,"img":false}]}
{"op":"mcm","clk":"5353194501","pt":1646210691144,"mc":[{"id":"1.195453767","rc":[{"atb":[[1.3,56.38]],"id":42154339}],"con":true,"img":false}]}
{"op":"mcm","clk":"5353194575","pt":1646210693157,"mc":[{"id":"1.195453767","rc":[{"atl":[[4.8,19.74]],"id":41818763},{"atl":[[1.73,127.11],[1.78,0],[1.76,0],[1.74,0]],"id":42154339}],"con":true,"img":false}]}
{"op":"mcm","clk":"5353194704","pt":1646210695961,"mc":[{"id":"1.195453767","rc":[{"atb":[[2.8,0]],"id":43167133},{"atl":[[5.4,0]],"id":42688787}],"con":true,"img":false}]}
{"op":"mcm","clk":"5353194712","pt":1646210696062,"mc":[{"id":"1.195453767","rc":[{"atb":[[3,30.05]],"id":43167133},{"atl":[[5.6,9.49]],"id":42688787}],"con":true,"img":false}]}
{"op":"mcm","clk":"5353194761","pt":1646210697047,"mc":[{"id":"1.195453767","rc":[{"atb":[[1.31,50.03]],"id":42154339}],"con":true,"img":false}]}
{"op":"mcm","clk":"5353194773","pt":1646210697357,"mc":[{"id":"1.195453767","rc":[{"atb":[[1.3,54.79]],"id":42154339}],"con":true,"img":false}]}
{"op":"mcm","clk":"5353194779","pt":1646210697460,"mc":[{"id":"1.195453767","rc":[{"atb":[[1.32,1.58]],"id":42154339}],"con":true,"img":false}]}
{"op":"mcm","clk":"5353194788","pt":1646210697667,"mc":[{"id":"1.195453767","rc":[{"atb":[[1.3,52.92]],"id":42154339}],"con":true,"img":false}]}
{"op":"mcm","clk":"5353194792","pt":1646210697772,"mc":[{"id":"1.195453767","rc":[{"atb":[[1.32,3.46]],"id":42154339}],"con":true,"img":false}]}
{"op":"mcm","clk":"5353194863","pt":1646210699272,"mc":[{"id":"1.195453767","rc":[{"atl":[[4.5,0],[4.7,0]],"id":41818763},{"spn":3.35,"spf":"NaN","id":41818763},{"spn":1.5,"spf":"NaN","id":42154339}],"con":true,"img":false}]}
{"op":"mcm","clk":"5353195085","pt":1646210703172,"mc":[{"id":"1.195453767","rc":[{"atl":[[5,31.25]],"id":41818763},{"atb":[[1.31,0]],"id":42154339},{"atl":[[1.75,135.37]],"id":42154339}],"con":true,"img":false}]}
{"op":"mcm","clk":"5353195109","pt":1646210703688,"mc":[{"id":"1.195453767","rc":[{"atb":[[1.32,1.58]],"id":42154339}],"con":true,"img":false}]}
{"op":"mcm","clk":"5353195113","pt":1646210703792,"mc":[{"id":"1.195453767","rc":[{"atb":[[1.31,1.87]],"id":42154339}],"con":true,"img":false}]}
{"op":"mcm","clk":"5353195118","pt":1646210703894,"mc":[{"id":"1.195453767","rc":[{"atb":[[1.32,0]],"id":42154339}],"con":true,"img":false}]}
{"op":"mcm","clk":"5353195125","pt":1646210704000,"mc":[{"id":"1.195453767","rc":[{"atl":[[4.3,0]],"id":39637621},{"atb":[[1.31,3.46]],"id":42154339}],"con":true,"img":false}]}
{"op":"mcm","clk":"5353195131","pt":1646210704103,"mc":[{"id":"1.195453767","rc":[{"atl":[[3.95,19.1]],"id":39637621}],"con":true,"img":false}]}
{"op":"mcm","clk":"5353195428","pt":1646210709996,"mc":[{"id":"1.195453767","rc":[{"atl":[[3.25,0]],"id":39637621},{"atl":[[14.5,0.89]],"id":41910350}],"con":true,"img":false}]}
{"op":"mcm","clk":"5353195434","pt":1646210710099,"mc":[{"id":"1.195453767","rc":[{"atl":[[3.35,18.58]],"id":39637621},{"atl":[[15.5,2.72]],"id":41910350}],"con":true,"img":false}]}
{"op":"mcm","clk":"5353195536","pt":1646210712010,"mc":[{"id":"1.195453767","rc":[{"atb":[[1.27,0]],"id":42154339}],"con":true,"img":false}]}
{"op":"mcm","clk":"5353195539","pt":1646210712113,"mc":[{"id":"1.195453767","rc":[{"atb":[[1.31,112.1]],"id":42154339}],"con":true,"img":false}]}
{"op":"mcm","clk":"5353195608","pt":1646210713401,"mc":[{"id":"1.195453767","rc":[{"atb":[[1.3,27.83]],"id":42154339}],"con":true,"img":false}]}
{"op":"mcm","clk":"5353195822","pt":1646210717997,"mc":[{"id":"1.195453767","rc":[{"atl":[[5.5,2.69]],"id":41818763}],"con":true,"img":false}]}
{"op":"mcm","clk":"5353195827","pt":1646210718100,"mc":[{"id":"1.195453767","rc":[{"atl":[[4.7,11.8]],"id":41818763}],"con":true,"img":false}]}
{"op":"mcm","clk":"5353195877","pt":1646210719287,"mc":[{"id":"1.195453767","rc":[{"atb":[[1.34,22.13]],"id":42154339}],"con":true,"img":false}]}
{"op":"mcm","clk":"5353195885","pt":1646210719493,"mc":[{"id":"1.195453767","rc":[{"atb":[[1.31,110.52]],"id":42154339}],"con":true,"img":false}]}
{"op":"mcm","clk":"5353195888","pt":1646210719598,"mc":[{"id":"1.195453767","rc":[{"atb":[[1.35,1.58]],"id":42154339}],"con":true,"img":false}]}
{"op":"mcm","clk":"5353195901","pt":1646210719907,"mc":[{"id":"1.195453767","rc":[{"atb":[[1.31,108.64]],"id":42154339}],"con":true,"img":false}]}
{"op":"mcm","clk":"5353195906","pt":1646210720012,"mc":[{"id":"1.195453767","rc":[{"atb":[[1.31,0],[1.35,3.46]],"id":42154339}],"con":true,"img":false}]}
{"op":"mcm","clk":"5353195910","pt":1646210720115,"mc":[{"id":"1.195453767","rc":[{"atb":[[1.27,108.64]],"id":42154339}],"con":true,"img":false}]}
{"op":"mcm","clk":"5353196001","pt":1646210722439,"mc":[{"id":"1.195453767","rc":[{"atb":[[1.34,0]],"id":42154339}],"con":true,"img":false}]}
{"op":"mcm","clk":"5353196033","pt":1646210723116,"mc":[{"id":"1.195453767","rc":[{"atb":[[1.35,1.87]],"id":42154339}],"con":true,"img":false}]}
{"op":"mcm","clk":"5353196036","pt":1646210723219,"mc":[{"id":"1.195453767","rc":[{"atb":[[1.31,1.58]],"id":42154339}],"con":true,"img":false}]}
{"op":"mcm","clk":"5353196218","pt":1646210726936,"mc":[{"id":"1.195453767","rc":[{"atl":[[4,0],[3.65,37.74]],"id":39637621},{"atl":[[6.4,0],[5.5,24.91]],"id":41818763},{"atl":[[10,0],[8.8,16.25]],"id":43167133},{"atl":[[1.79,126.58],[1.96,0]],"id":42154339},{"atl":[[5.8,20.83],[6.8,0]],"id":42688787}],"con":true,"img":false}]}
{"op":"mcm","clk":"5353196251","pt":1646210727813,"mc":[{"id":"1.195453767","rc":[{"atb":[[1.36,18.13]],"id":42154339}],"con":true,"img":false}]}
{"op":"mcm","clk":"5353196259","pt":1646210728018,"mc":[{"id":"1.195453767","rc":[{"atl":[[3.95,0]],"id":39637621}],"con":true,"img":false}]}
{"op":"mcm","clk":"5353196262","pt":1646210728121,"mc":[{"id":"1.195453767","rc":[{"atl":[[4.3,19.1]],"id":39637621}],"con":true,"img":false}]}
{"op":"mcm","clk":"5353196269","pt":1646210728326,"mc":[{"id":"1.195453767","rc":[{"atb":[[1.3,52.92]],"id":42154339}],"con":true,"img":false}]}
{"op":"mcm","clk":"5353196277","pt":1646210728532,"mc":[{"id":"1.195453767","rc":[{"atb":[[1.31,0]],"id":42154339}],"con":true,"img":false}]}
{"op":"mcm","clk":"5353196281","pt":1646210728634,"mc":[{"id":"1.195453767","rc":[{"atb":[[1.37,1.58]],"id":42154339}],"con":true,"img":false}]}
{"op":"mcm","clk":"5353196963","pt":1646210744715,"mc":[{"id":"1.195453767","rc":[{"atb":[[1.36,0]],"id":42154339}],"con":true,"img":false}]}
{"op":"mcm","clk":"5353196986","pt":1646210745230,"mc":[{"id":"1.195453767","rc":[{"atb":[[1.35,0]],"id":42154339}],"con":true,"img":false}]}
{"op":"mcm","clk":"5353196991","pt":1646210745332,"mc":[{"id":"1.195453767","rc":[{"atb":[[1.37,0],[1.31,1.87]],"id":42154339}],"con":true,"img":false}]}
{"op":"mcm","clk":"5353196994","pt":1646210745435,"mc":[{"id":"1.195453767","rc":[{"atb":[[1.31,3.46]],"id":42154339}],"con":true,"img":false}]}
{"op":"mcm","clk":"5353197211","pt":1646210749973,"mc":[{"id":"1.195453767","rc":[{"atb":[[1.27,0]],"id":42154339}],"con":true,"img":false}]}
{"op":"mcm","clk":"5353197219","pt":1646210750026,"mc":[{"id":"1.195453767","rc":[{"atb":[[1.31,112.1]],"id":42154339}],"con":true,"img":false}]}
{"op":"mcm","clk":"5353197233","pt":1646210750335,"mc":[{"id":"1.195453767","rc":[{"atl":[[4.1,32.26],[3.65,0]],"id":39637621},{"atl":[[6.4,18.52],[5.5,2.69]],"id":41818763},{"atl":[[10,11.11],[8.8,5.6]],"id":43167133},{"atl":[[1.79,0],[1.95,105.26]],"id":42154339}],"con":true,"img":false}]}
{"op":"mcm","clk":"5353197338","pt":1646210752339,"mc":[{"id":"1.195453767","rc":[{"atb":[[1.3,27.83]],"id":42154339}],"con":true,"img":false}]}
{"op":"mcm","clk":"5353197595","pt":1646210757841,"mc":[{"id":"1.195453767","rc":[{"atb":[[1.32,43.67]],"id":42154339}],"con":true,"img":false}]}
{"op":"mcm","clk":"5353197606","pt":1646210758047,"mc":[{"id":"1.195453767","rc":[{"atb":[[1.31,110.22]],"id":42154339}],"con":true,"img":false}]}
{"op":"mcm","clk":"5353197612","pt":1646210758150,"mc":[{"id":"1.195453767","rc":[{"atb":[[1.33,1.87]],"id":42154339}],"con":true,"img":false}]}
{"op":"mcm","clk":"5353197629","pt":1646210758357,"mc":[{"id":"1.195453767","rc":[{"atb":[[1.34,22.13]],"id":42154339}],"con":true,"img":false}]}
{"op":"mcm","clk":"5353197641","pt":1646210758563,"mc":[{"id":"1.195453767","rc":[{"atb":[[1.31,108.64]],"id":42154339}],"con":true,"img":false}]}
{"op":"mcm","clk":"5353197645","pt":1646210758664,"mc":[{"id":"1.195453767","rc":[{"atb":[[1.33,0],[1.35,1.58]],"id":42154339}],"con":true,"img":false}]}
{"op":"mcm","clk":"5353197649","pt":1646210758770,"mc":[{"id":"1.195453767","rc":[{"atb":[[1.35,3.46]],"id":42154339}],"con":true,"img":false}]}
{"op":"mcm","clk":"5353197708","pt":1646210759957,"mc":[{"id":"1.195453767","rc":[{"atb":[[1.31,0]],"id":42154339},{"spn":1.52,"spf":"NaN","id":42154339}],"con":true,"img":false}]}
{"op":"mcm","clk":"5353197712","pt":1646210760060,"mc":[{"id":"1.195453767","rc":[{"atb":[[1.27,108.64]],"id":42154339}],"con":true,"img":false}]}
{"op":"mcm","clk":"5353197810","pt":1646210761369,"mc":[{"id":"1.195453767","rc":[{"atb":[[1.34,0]],"id":42154339}],"con":true,"img":false}]}
{"op":"mcm","clk":"5353197826","pt":1646210761578,"mc":[{"id":"1.195453767","rc":[{"atb":[[1.35,1.87]],"id":42154339}],"con":true,"img":false}]}
{"op":"mcm","clk":"5353197833","pt":1646210761681,"mc":[{"id":"1.195453767","rc":[{"atb":[[1.33,1.58]],"id":42154339}],"con":true,"img":false}]}
{"op":"mcm","clk":"5353197908","pt":1646210762866,"mc":[{"id":"1.195453767","rc":[{"atl":[[1.79,126.58],[1.95,0]],"id":42154339}],"con":true,"img":false}]}
{"op":"mcm","clk":"5353197930","pt":1646210763176,"mc":[{"id":"1.195453767","rc":[{"atb":[[1.32,0]],"id":42154339}],"con":true,"img":false}]}
{"op":"mcm","clk":"5353197948","pt":1646210763381,"mc":[{"id":"1.195453767","rc":[{"atb":[[1.33,0]],"id":42154339}],"con":true,"img":false}]}
{"op":"mcm","clk":"5353197951","pt":1646210763486,"mc":[{"id":"1.195453767","rc":[{"atb":[[1.31,1.58]],"id":42154339}],"con":true,"img":false}]}
{"op":"mcm","clk":"5353198023","pt":1646210764778,"mc":[{"id":"1.195453767","rc":[{"atl":[[4.1,0],[3.65,37.74]],"id":39637621},{"atl":[[6.4,0],[5.5,24.91]],"id":41818763},{"atl":[[8.8,16.25]],"id":43167133}],"con":true,"img":false}]}
{"op":"mcm","clk":"5353198026","pt":1646210764881,"mc":[{"id":"1.195453767","rc":[{"atl":[[10,0]],"id":43167133}],"con":true,"img":false}]}
{"op":"mcm","clk":"5353198113","pt":1646210767400,"mc":[{"id":"1.195453767","rc":[{"atb":[[1.3,52.92]],"id":42154339}],"con":true,"img":false}]}
{"op":"mcm","clk":"5353199157","pt":1646210787299,"mc":[{"id":"1.195453767","rc":[{"atb":[[1.36,26.04]],"id":42154339}],"con":true,"img":false}]}
{"op":"mcm","clk":"5353199170","pt":1646210787507,"mc":[{"id":"1.195453767","rc":[{"atb":[[1.31,0]],"id":42154339}],"con":true,"img":false}]}
{"op":"mcm","clk":"5353199175","pt":1646210787608,"mc":[{"id":"1.195453767","rc":[{"atb":[[1.37,1.58]],"id":42154339}],"con":true,"img":false}]}
{"op":"mcm","clk":"5353199187","pt":1646210788021,"mc":[{"id":"1.195453767","rc":[{"atb":[[1.27,0]],"id":42154339}],"con":true,"img":false}]}
{"op":"mcm","clk":"5353199194","pt":1646210788124,"mc":[{"id":"1.195453767","rc":[{"atb":[[1.31,108.64]],"id":42154339}],"con":true,"img":false}]}
{"op":"mcm","clk":"5353199201","pt":1646210788279,"mc":[{"id":"1.195453767","rc":[{"atb":[[1.36,0]],"id":42154339}],"con":true,"img":false}]}
{"op":"mcm","clk":"5353199210","pt":1646210788486,"mc":[{"id":"1.195453767","rc":[{"atb":[[1.3,27.83]],"id":42154339}],"con":true,"img":false}]}
{"op":"mcm","clk":"5353199219","pt":1646210788690,"mc":[{"id":"1.195453767","rc":[{"atb":[[1.37,0],[1.35,0]],"id":42154339}],"con":true,"img":false}]}
{"op":"mcm","clk":"5353199224","pt":1646210788792,"mc":[{"id":"1.195453767","rc":[{"atb":[[1.32,3.46]],"id":42154339}],"con":true,"img":false}]}
{"op":"mcm","clk":"5353199488","pt":1646210794621,"mc":[{"id":"1.195453767","rc":[{"atb":[[1.34,22.13]],"id":42154339}],"con":true,"img":false}]}
{"op":"mcm","clk":"5353199524","pt":1646210795291,"mc":[{"id":"1.195453767","rc":[{"atb":[[1.32,0]],"id":42154339}],"con":true,"img":false}]}
{"op":"mcm","clk":"5353199528","pt":1646210795394,"mc":[{"id":"1.195453767","rc":[{"atb":[[1.35,3.46]],"id":42154339}],"con":true,"img":false}]}
{"op":"mcm","clk":"5353199551","pt":1646210795910,"mc":[{"id":"1.195453767","rc":[{"atb":[[1.31,0]],"id":42154339}],"con":true,"img":false}]}
{"op":"mcm","clk":"5353199556","pt":1646210796013,"mc":[{"id":"1.195453767","rc":[{"atb":[[1.27,108.64]],"id":42154339}],"con":true,"img":false}]}
{"op":"mcm","clk":"5353199607","pt":1646210797507,"mc":[{"id":"1.195453767","rc":[{"atb":[[1.34,0]],"id":42154339}],"con":true,"img":false}]}
{"op":"mcm","clk":"5353199616","pt":1646210797713,"mc":[{"id":"1.195453767","rc":[{"atb":[[1.35,1.87]],"id":42154339}],"con":true,"img":false}]}
{"op":"mcm","clk":"5353199622","pt":1646210797817,"mc":[{"id":"1.195453767","rc":[{"atb":[[1.31,1.58]],"id":42154339}],"con":true,"img":false}]}
{"op":"mcm","clk":"5353199886","pt":1646210803505,"mc":[{"id":"1.195453767","rc":[{"atb":[[1.3,52.92]],"id":42154339}],"con":true,"img":false}]}
{"op":"mcm","clk":"5353200015","pt":1646210805945,"mc":[{"id":"1.195453767","rc":[{"atl":[[5.4,13.95]],"id":41818763}],"con":true,"img":false}]}
{"op":"mcm","clk":"5353200024","pt":1646210806047,"mc":[{"id":"1.195453767","rc":[{"atl":[[6.2,0]],"id":41818763}],"con":true,"img":false}]}
{"op":"mcm","clk":"5353200504","pt":1646210816125,"mc":[{"id":"1.195453767","rc":[{"atb":[[1.36,26.04]],"id":42154339}],"con":true,"img":false}]}
{"op":"mcm","clk":"5353200512","pt":1646210816334,"mc":[{"id":"1.195453767","rc":[{"atb":[[1.31,0]],"id":42154339}],"con":true,"img":false}]}
{"op":"mcm","clk":"5353200515","pt":1646210816429,"mc":[{"id":"1.195453767","rc":[{"atb":[[1.37,1.58]],"id":42154339}],"con":true,"img":false}]}
{"op":"mcm","clk":"5353200874","pt":1646210823972,"mc":[{"id":"1.195453767","rc":[{"atb":[[1.27,0]],"id":42154339},{"spn":1.53,"spf":"NaN","id":42154339}],"con":true,"img":false}]}
{"op":"mcm","clk":"5353200879","pt":1646210824074,"mc":[{"id":"1.195453767","rc":[{"atb":[[1.31,108.64]],"id":42154339}],"con":true,"img":false}]}
{"op":"mcm","clk":"5353200884","pt":1646210824177,"mc":[{"id":"1.195453767","rc":[{"atb":[[1.36,0]],"id":42154339}],"con":true,"img":false}]}
{"op":"mcm","clk":"5353200912","pt":1646210824740,"mc":[{"id":"1.195453767","rc":[{"atb":[[1.37,0]],"id":42154339}],"con":true,"img":false}]}
{"op":"mcm","clk":"5353200916","pt":1646210824843,"mc":[{"id":"1.195453767","rc":[{"atb":[[1.3,27.83],[1.32,1.58]],"id":42154339}],"con":true,"img":false}]}
{"op":"mcm","clk":"5353201173","pt":1646210830460,"mc":[{"id":"1.195453767","rc":[{"atb":[[1.34,22.13]],"id":42154339}],"con":true,"img":false}]}
{"op":"mcm","clk":"5353201178","pt":1646210830664,"mc":[{"id":"1.195453767","rc":[{"atb":[[1.3,0]],"id":42154339}],"con":true,"img":false}]}
{"op":"mcm","clk":"5353201182","pt":1646210830769,"mc":[{"id":"1.195453767","rc":[{"atb":[[1.32,0]],"id":42154339}],"con":true,"img":false}]}
{"op":"mcm","clk":"5353201186","pt":1646210830871,"mc":[{"id":"1.195453767","rc":[{"atb":[[1.35,3.46]],"id":42154339}],"con":true,"img":false}]}
{"op":"mcm","clk":"5353201236","pt":1646210831951,"mc":[{"id":"1.195453767","rc":[{"atb":[[1.31,0]],"id":42154339}],"con":true,"img":false}]}
{"op":"mcm","clk":"5353201240","pt":1646210832055,"mc":[{"id":"1.195453767","rc":[{"atb":[[1.27,108.64]],"id":42154339}],"con":true,"img":false}]}
{"op":"mcm","clk":"5353201312","pt":1646210833546,"mc":[{"id":"1.195453767","rc":[{"atb":[[1.34,0]],"id":42154339}],"con":true,"img":false}]}
{"op":"mcm","clk":"5353201320","pt":1646210833752,"mc":[{"id":"1.195453767","rc":[{"atb":[[1.35,1.87]],"id":42154339}],"con":true,"img":false}]}
{"op":"mcm","clk":"5353201323","pt":1646210833854,"mc":[{"id":"1.195453767","rc":[{"atb":[[1.28,1.58],[1.35,0]],"id":42154339}],"con":true,"img":false}]}
{"op":"mcm","clk":"5353201326","pt":1646210833956,"mc":[{"id":"1.195453767","rc":[{"atb":[[1.28,3.46]],"id":42154339}],"con":true,"img":false}]}
{"op":"mcm","clk":"5353201601","pt":1646210839566,"mc":[{"id":"1.195453767","rc":[{"atb":[[1.3,25.08]],"id":42154339}],"con":true,"img":false}]}
{"op":"mcm","clk":"5353201608","pt":1646210839769,"mc":[{"id":"1.195453767","rc":[{"atb":[[1.28,1.87]],"id":42154339}],"con":true,"img":false}]}
{"op":"mcm","clk":"5353201615","pt":1646210839872,"mc":[{"id":"1.195453767","rc":[{"atb":[[1.31,1.58]],"id":42154339}],"con":true,"img":false}]}
{"op":"mcm","clk":"5353201758","pt":1646210842860,"mc":[{"id":"1.195453767","rc":[{"atb":[[1.28,0]],"id":42154339}],"con":true,"img":false}]}
{"op":"mcm","clk":"5353201762","pt":1646210842963,"mc":[{"id":"1.195453767","rc":[{"atb":[[1.31,3.46]],"id":42154339}],"con":true,"img":false}]}
{"op":"mcm","clk":"5353201842","pt":1646210844505,"mc":[{"id":"1.195453767","rc":[{"atb":[[1.32,34.38]],"id":42154339}],"con":true,"img":false}]}
{"op":"mcm","clk":"5353201878","pt":1646210845177,"mc":[{"id":"1.195453767","rc":[{"atl":[[4.1,32.26],[3.65,0]],"id":39637621},{"atl":[[6.4,18.52],[5.5,2.69]],"id":41818763},{"atl":[[10,11.11],[8.8,5.6]],"id":43167133},{"atb":[[1.31,1.87]],"id":42154339},{"atl":[[1.79,0],[1.94,106.38]],"id":42154339}],"con":true,"img":false}]}
{"op":"mcm","clk":"5353201884","pt":1646210845280,"mc":[{"id":"1.195453767","rc":[{"atb":[[1.33,1.58],[1.31,0]],"id":42154339}],"con":true,"img":false}]}
{"op":"mcm","clk":"5353201892","pt":1646210845439,"mc":[{"id":"1.195453767","rc":[{"atb":[[1.33,3.46]],"id":42154339}],"con":true,"img":false}]}
{"op":"mcm","clk":"5353201923","pt":1646210846004,"mc":[{"id":"1.195453767","rc":[{"atl":[[5.4,0]],"id":41818763}],"con":true,"img":false}]}
{"op":"mcm","clk":"5353201930","pt":1646210846109,"mc":[{"id":"1.195453767","rc":[{"atl":[[6.2,13.95]],"id":41818763}],"con":true,"img":false}]}
{"op":"mcm","clk":"5353202532","pt":1646210858714,"mc":[{"id":"1.195453767","rc":[{"atl":[[4.1,0],[3.65,37.74]],"id":39637621},{"atl":[[6.4,0],[5.5,24.91]],"id":41818763},{"atl":[[10,0],[8.8,16.25]],"id":43167133},{"atb":[[1.32,0]],"id":42154339},{"atl":[[1.79,126.58],[1.94,0]],"id":42154339}],"con":true,"img":false}]}
{"op":"mcm","clk":"5353202551","pt":1646210859125,"mc":[{"id":"1.195453767","rc":[{"atb":[[1.33,1.87]],"id":42154339}],"con":true,"img":false}]}
{"op":"mcm","clk":"5353202554","pt":1646210859227,"mc":[{"id":"1.195453767","rc":[{"atb":[[1.31,1.58]],"id":42154339}],"con":true,"img":false}]}
{"op":"mcm","clk":"5353203094","pt":1646210869450,"mc":[{"id":"1.195453767","rc":[{"atb":[[5,40.14],[4.9,19.23]],"id":42162698},{"atl":[[1.68,23.89],[1.69,0]],"id":42154339}],"con":true,"img":false}]}
{"op":"mcm","clk":"5353203127","pt":1646210870120,"mc":[{"id":"1.195453767","rc":[{"atb":[[1.33,0]],"id":42154339}],"con":true,"img":false}]}
{"op":"mcm","clk":"5353203131","pt":1646210870224,"mc":[{"id":"1.195453767","rc":[{"atb":[[1.31,3.46]],"id":42154339}],"con":true,"img":false}]}
{"op":"mcm","clk":"5353203141","pt":1646210870430,"mc":[{"id":"1.195453767","rc":[{"atb":[[1.3,52.92]],"id":42154339}],"con":true,"img":false}]}
{"op":"mcm","clk":"5353203208","pt":1646210872211,"mc":[{"id":"1.195453767","rc":[{"atl":[[22,1.4],[23,6.45]],"id":42162698},{"atl":[[4.1,32.26],[3.65,0]],"id":39637621},{"atl":[[6.4,18.52],[5.5,2.69]],"id":41818763},{"atb":[[5.1,4.88],[4.9,3.01]],"id":41910350},{"atl":[[10,11.11],[8.2,1.29],[8.4,2.7],[8.8,5.6]],"id":43167133},{"atb":[[1.32,43.67]],"id":42154339},{"atl":[[1.79,0],[1.94,106.38]],"id":42154339},{"atb":[[2,20],[2.3,0],[2.22,0],[2.26,0],[1.87,79.9],[2.02,0],[2.18,0]],"id":42688787},{"atl":[[5.8,0],[7.2,16.13]],"id":42688787}],"con":true,"img":false}]}
{"op":"mcm","clk":"5353203220","pt":1646210872520,"mc":[{"id":"1.195453767","rc":[{"atb":[[1.31,1.58]],"id":42154339}],"con":true,"img":false}]}
{"op":"mcm","clk":"5353203226","pt":1646210872622,"mc":[{"id":"1.195453767","rc":[{"atb":[[1.33,1.87]],"id":42154339}],"con":true,"img":false}]}
{"op":"mcm","clk":"5353203240","pt":1646210872930,"mc":[{"id":"1.195453767","rc":[{"atb":[[1.31,0]],"id":42154339}],"con":true,"img":false}]}
{"op":"mcm","clk":"5353203241","pt":1646210873033,"mc":[{"id":"1.195453767","rc":[{"atb":[[1.33,3.46]],"id":42154339}],"con":true,"img":false}]}
{"op":"mcm","clk":"5353203253","pt":1646210873243,"mc":[{"id":"1.195453767","rc":[{"atb":[[5,15.14],[4.9,44.87]],"id":42162698},{"atl":[[3.25,8.89],[3.2,5.5]],"id":39637621},{"atb":[[1.32,0]],"id":42154339},{"atl":[[1.68,0],[1.69,23.54]],"id":42154339}],"con":true,"img":false}]}
{"op":"mcm","clk":"5353203262","pt":1646210873453,"mc":[{"id":"1.195453767","rc":[{"atb":[[1.33,1.87]],"id":42154339}],"con":true,"img":false}]}
{"op":"mcm","clk":"5353203267","pt":1646210873556,"mc":[{"id":"1.195453767","rc":[{"atb":[[1.31,1.58]],"id":42154339}],"con":true,"img":false}]}
{"op":"mcm","clk":"5353203461","pt":1646210878052,"mc":[{"id":"1.195453767","rc":[{"atb":[[5,0]],"id":41910350}],"con":true,"img":false}]}
{"op":"mcm","clk":"5353203464","pt":1646210878155,"mc":[{"id":"1.195453767","rc":[{"atb":[[5.2,1.67]],"id":41910350}],"con":true,"img":false}]}
{"op":"mcm","clk":"5353203679","pt":1646210882258,"mc":[{"id":"1.195453767","rc":[{"atl":[[25,2.08]],"id":42162698},{"atb":[[4.9,15.83]],"id":41910350},{"atl":[[8.8,12.01]],"id":43167133},{"atb":[[1.98,51.02]],"id":42688787}],"con":true,"img":false}]}
{"op":"mcm","clk":"5353203697","pt":1646210882566,"mc":[{"id":"1.195453767","rc":[{"atb":[[4.9,14.23]],"id":41910350}],"con":true,"img":false}]}
{"op":"mcm","clk":"5353203700","pt":1646210882670,"mc":[{"id":"1.195453767","rc":[{"atb":[[5.1,6.47]],"id":41910350}],"con":true,"img":false}]}
{"op":"mcm","clk":"5353203715","pt":1646210882928,"mc":[{"id":"1.195453767","rc":[{"atb":[[4.9,12.82]],"id":41910350}],"con":true,"img":false}]}
{"op":"mcm","clk":"5353203719","pt":1646210883031,"mc":[{"id":"1.195453767","rc":[{"atb":[[5.2,3.09]],"id":41910350}],"con":true,"img":false}]}
{"op":"mcm","clk":"5353203731","pt":1646210883342,"mc":[{"id":"1.195453767","rc":[{"atl":[[3.35,39.86]],"id":39637621}],"con":true,"img":false}]}
{"op":"mcm","clk":"5353203743","pt":1646210883652,"mc":[{"id":"1.195453767","rc":[{"atl":[[24,0.52],[26,0],[28,0]],"id":42162698},{"atl":[[3.3,0],[3.5,0],[3.4,0]],"id":39637621},{"atb":[[4.3,0]],"id":41910350},{"atl":[[9,0],[9.4,0],[8.6,0]],"id":43167133}],"con":true,"img":false}]}
{"op":"mcm","clk":"5353203762","pt":1646210884016,"mc":[{"id":"1.195453767","rc":[{"atl":[[23,3.72]],"id":42162698},{"spn":9.1,"spf":"NaN","id":41910350},{"spn":1.51,"spf":"NaN","id":42154339}],"con":true,"img":false}]}
{"op":"mcm","clk":"5353203766","pt":1646210884117,"mc":[{"id":"1.195453767","rc":[{"atl":[[24,3.25]],"id":42162698}],"con":true,"img":false}]}
{"op":"mcm","clk":"5353203828","pt":1646210885419,"mc":[{"id":"1.195453767","rc":[{"atl":[[6.4,0],[5.5,24.91]],"id":41818763},{"atl":[[10,0],[8.8,23.12]],"id":43167133},{"atl":[[1.8,125],[1.94,0]],"id":42154339},{"atl":[[7.2,0],[6.2,19.23]],"id":42688787}],"con":true,"img":false}]}
{"op":"mcm","clk":"5353203833","pt":1646210885522,"mc":[{"id":"1.195453767","rc":[{"atl":[[4.1,0],[3.7,23.58]],"id":39637621}],"con":true,"img":false}]}
{"op":"mcm","clk":"5353204112","pt":1646210891936,"mc":[{"id":"1.195453767","rc":[{"atb":[[1.27,0]],"id":42154339}],"con":true,"img":false}]}
{"op":"mcm","clk":"5353204116","pt":1646210892038,"mc":[{"id":"1.195453767","rc":[{"atb":[[1.31,110.22]],"id":42154339}],"con":true,"img":false}]}
{"op":"mcm","clk":"5353204125","pt":1646210892245,"mc":[{"id":"1.195453767","rc":[{"atl":[[27,2.88]],"id":42162698},{"atb":[[4.7,20.27]],"id":41910350},{"atl":[[9.2,9.15]],"id":43167133},{"atb":[[1.96,78.12]],"id":42688787}],"con":true,"img":false}]}
{"op":"mcm","clk":"5353204168","pt":1646210893227,"mc":[{"id":"1.195453767","rc":[{"atl":[[3.45,30.61]],"id":39637621}],"con":true,"img":false}]}
{"op":"mcm","clk":"5353204177","pt":1646210893537,"mc":[{"id":"1.195453767","rc":[{"atb":[[1.3,27.83]],"id":42154339}],"con":true,"img":false}]}
{"op":"mcm","clk":"5353204284","pt":1646210895915,"mc":[{"id":"1.195453767","rc":[{"atl":[[15.5,0]],"id":41910350}],"con":true,"img":false}]}
{"op":"mcm","clk":"5353204289","pt":1646210896018,"mc":[{"id":"1.195453767","rc":[{"atl":[[14.5,3.62]],"id":41910350}],"con":true,"img":false}]}
{"op":"mcm","clk":"5353204439","pt":1646210899318,"mc":[{"id":"1.195453767","rc":[{"atb":[[1.34,35.76]],"id":42154339}],"con":true,"img":false}]}
{"op":"mcm","clk":"5353204442","pt":1646210899421,"mc":[{"id":"1.195453767","rc":[{"atb":[[1.34,57.89]],"id":42154339}],"con":true,"img":false}]}
{"op":"mcm","clk":"5353204445","pt":1646210899524,"mc":[{"id":"1.195453767","rc":[{"atb":[[1.33,0]],"id":42154339}],"con":true,"img":false}]}
{"op":"mcm","clk":"5353204448","pt":1646210899627,"mc":[{"id":"1.195453767","rc":[{"atb":[[1.35,1.87]],"id":42154339}],"con":true,"img":false}]}
{"op":"mcm","clk":"5353204463","pt":1646210899942,"mc":[{"id":"1.195453767","rc":[{"atl":[[3.35,21.28]],"id":39637621},{"atb":[[1.31,1.58]],"id":42154339}],"con":true,"img":false}]}
{"op":"mcm","clk":"5353204466","pt":1646210900042,"mc":[{"id":"1.195453767","rc":[{"atl":[[3.4,18.58]],"id":39637621},{"atb":[[1.27,108.64]],"id":42154339}],"con":true,"img":false}]}
{"op":"mcm","clk":"5353204475","pt":1646210900248,"mc":[{"id":"1.195453767","rc":[{"atb":[[1.31,0]],"id":42154339}],"con":true,"img":false}]}
{"op":"mcm","clk":"5353204481","pt":1646210900351,"mc":[{"id":"1.195453767","rc":[{"atb":[[1.35,3.46]],"id":42154339}],"con":true,"img":false}]}
{"op":"mcm","clk":"5353204564","pt":1646210902255,"mc":[{"id":"1.195453767","rc":[{"atl":[[29,4.46]],"id":42162698},{"atb":[[4.5,35.71]],"id":41910350},{"atl":[[9.6,14.53]],"id":43167133},{"atb":[[1.94,132.98]],"id":42688787}],"con":true,"img":false}]}
{"op":"mcm","clk":"5353204581","pt":1646210902669,"mc":[{"id":"1.195453767","rc":[{"atb":[[1.34,35.76]],"id":42154339}],"con":true,"img":false}]}
{"op":"mcm","clk":"5353204604","pt":1646210903236,"mc":[{"id":"1.195453767","rc":[{"atl":[[3.55,49.02]],"id":39637621}],"con":true,"img":false}]}
{"op":"mcm","clk":"5353204629","pt":1646210903953,"mc":[{"id":"1.195453767","rc":[{"atl":[[14.5,0.89]],"id":41910350}],"con":true,"img":false}]}
{"op":"mcm","clk":"5353204633","pt":1646210904056,"mc":[{"id":"1.195453767","rc":[{"atl":[[15.5,2.72]],"id":41910350}],"con":true,"img":false}]}
{"op":"mcm","clk":"5353204825","pt":1646210907989,"mc":[{"id":"1.195453767","rc":[{"atb":[[4.8,0]],"id":41910350}],"con":true,"img":false}]}
{"op":"mcm","clk":"5353204830","pt":1646210908042,"mc":[{"id":"1.195453767","rc":[{"atb":[[5,10.64]],"id":41910350}],"con":true,"img":false}]}
{"op":"mcm","clk":"5353204852","pt":1646210908558,"mc":[{"id":"1.195453767","rc":[{"atb":[[1.3,52.92]],"id":42154339}],"con":true,"img":false}]}
{"op":"mcm","clk":"5353204857","pt":1646210908661,"mc":[{"id":"1.195453767","rc":[{"atb":[[1.34,0]],"id":42154339}],"con":true,"img":false}]}
{"op":"mcm","clk":"5353204882","pt":1646210909177,"mc":[{"id":"1.195453767","rc":[{"atb":[[1.35,1.87]],"id":42154339}],"con":true,"img":false}]}
{"op":"mcm","clk":"5353204886","pt":1646210909280,"mc":[{"id":"1.195453767","rc":[{"atb":[[1.31,1.58]],"id":42154339}],"con":true,"img":false}]}
{"op":"mcm","clk":"5353205110","pt":1646210913975,"mc":[{"id":"1.195453767","rc":[{"atb":[[1.81,5.5]],"id":39637621},{"atb":[[2.32,12]],"id":41818763},{"atb":[[1.28,3.81]],"id":42154339}],"con":true,"img":false}]}
{"op":"mcm","clk":"5353205116","pt":1646210914184,"mc":[{"id":"1.195453767","rc":[{"atb":[[2.32,24.4],[2.3,4.75]],"id":41818763}],"con":true,"img":false}]}
{"op":"mcm","clk":"5353205134","pt":1646210914545,"mc":[{"id":"1.195453767","rc":[{"atb":[[2.3,3.24]],"id":41818763}],"con":true,"img":false}]}
{"op":"mcm","clk":"5353205138","pt":1646210914649,"mc":[{"id":"1.195453767","rc":[{"atb":[[2.34,1.5]],"id":41818763}],"con":true,"img":false}]}
{"op":"mcm","clk":"5353205141","pt":1646210914753,"mc":[{"id":"1.195453767","rc":[{"atb":[[2.3,1.67]],"id":41818763}],"con":true,"img":false}]}
{"op":"mcm","clk":"5353205146","pt":1646210914858,"mc":[{"id":"1.195453767","rc":[{"atb":[[2.34,3.08]],"id":41818763}],"con":true,"img":false}]}
{"op":"mcm","clk":"5353205209","pt":1646210916352,"mc":[{"id":"1.195453767","rc":[{"atb":[[1.35,0]],"id":42154339}],"con":true,"img":false}]}
{"op":"mcm","clk":"5353205214","pt":1646210916454,"mc":[{"id":"1.195453767","rc":[{"atb":[[1.31,3.46]],"id":42154339}],"con":true,"img":false}]}
{"op":"mcm","clk":"5353205284","pt":1646210918153,"mc":[{"id":"1.195453767","rc":[{"atb":[[2.3,0]],"id":41818763}],"con":true,"img":false}]}
{"op":"mcm","clk":"5353205291","pt":1646210918359,"mc":[{"id":"1.195453767","rc":[{"atb":[[2.36,1.67]],"id":41818763}],"con":true,"img":false}]}
{"op":"mcm","clk":"5353205301","pt":1646210918667,"mc":[{"id":"1.195453767","rc":[{"atb":[[2.32,12.4]],"id":41818763}],"con":true,"img":false}]}
{"op":"mcm","clk":"5353205343","pt":1646210920052,"mc":[{"id":"1.195453767","rc":[{"atb":[[1.27,0]],"id":42154339}],"con":true,"img":false}]}
{"op":"mcm","clk":"5353205347","pt":1646210920155,"mc":[{"id":"1.195453767","rc":[{"atb":[[1.31,112.1]],"id":42154339}],"con":true,"img":false}]}
{"op":"mcm","clk":"5353205360","pt":1646210920566,"mc":[{"id":"1.195453767","rc":[{"atb":[[1.3,27.83]],"id":42154339}],"con":true,"img":false}]}
{"op":"mcm","clk":"5353205476","pt":1646210923494,"mc":[{"id":"1.195453767","rc":[{"atb":[[2.36,4.99]],"id":41818763}],"con":true,"img":false}]}
{"op":"mcm","clk":"5353205503","pt":1646210924159,"mc":[{"id":"1.195453767","rc":[{"atb":[[2.34,1.5]],"id":41818763}],"con":true,"img":false}]}
{"op":"mcm","clk":"5353205505","pt":1646210924261,"mc":[{"id":"1.195453767","rc":[{"atb":[[2.36,6.57],[2.34,0]],"id":41818763}],"con":true,"img":false}]}
{"op":"mcm","clk":"5353205508","pt":1646210924364,"mc":[{"id":"1.195453767","rc":[{"atb":[[2.36,8.07]],"id":41818763}],"con":true,"img":false}]}
{"op":"mcm","clk":"5353205563","pt":1646210926005,"mc":[{"id":"1.195453767","rc":[{"atl":[[6.2,0]],"id":41818763},{"atb":[[1.32,35.76]],"id":42154339}],"con":true,"img":false}]}
{"op":"mcm","clk":"5353205566","pt":1646210926055,"mc":[{"id":"1.195453767","rc":[{"atl":[[5.4,13.95]],"id":41818763}],"con":true,"img":false}]}
{"op":"mcm","clk":"5353205575","pt":1646210926467,"mc":[{"id":"1.195453767","rc":[{"atb":[[1.34,22.13]],"id":42154339}],"con":true,"img":false}]}
{"op":"mcm","clk":"5353205581","pt":1646210926672,"mc":[{"id":"1.195453767","rc":[{"atb":[[1.31,110.52]],"id":42154339}],"con":true,"img":false}]}
{"op":"mcm","clk":"5353205585","pt":1646210926775,"mc":[{"id":"1.195453767","rc":[{"atb":[[1.33,1.58],[1.31,108.64]],"id":42154339}],"con":true,"img":false}]}
{"op":"mcm","clk":"5353205588","pt":1646210926876,"mc":[{"id":"1.195453767","rc":[{"atb":[[1.35,1.87]],"id":42154339}],"con":true,"img":false}]}
{"op":"mcm","clk":"5353205606","pt":1646210927392,"mc":[{"id":"1.195453767","rc":[{"atb":[[1.33,0]],"id":42154339}],"con":true,"img":false}]}
{"op":"mcm","clk":"5353205612","pt":1646210927494,"mc":[{"id":"1.195453767","rc":[{"atb":[[1.35,3.46]],"id":42154339}],"con":true,"img":false}]}
{"op":"mcm","clk":"5353205640","pt":1646210928110,"mc":[{"id":"1.195453767","rc":[{"atb":[[1.31,0]],"id":42154339}],"con":true,"img":false}]}
{"op":"mcm","clk":"5353205644","pt":1646210928161,"mc":[{"id":"1.195453767","rc":[{"atb":[[1.27,108.64]],"id":42154339}],"con":true,"img":false}]}
{"op":"mcm","clk":"5353205653","pt":1646210928468,"mc":[{"id":"1.195453767","rc":[{"atb":[[1.28,0]],"id":42154339}],"con":true,"img":false}]}
{"op":"mcm","clk":"5353205706","pt":1646210929596,"mc":[{"id":"1.195453767","rc":[{"atb":[[1.34,0]],"id":42154339}],"con":true,"img":false}]}
{"op":"mcm","clk":"5353205738","pt":1646210930315,"mc":[{"id":"1.195453767","rc":[{"atb":[[1.35,1.87]],"id":42154339}],"con":true,"img":false}]}
{"op":"mcm","clk":"5353205743","pt":1646210930368,"mc":[{"id":"1.195453767","rc":[{"atb":[[1.33,1.58]],"id":42154339}],"con":true,"img":false}]}
{"op":"mcm","clk":"5353205853","pt":1646210933514,"mc":[{"id":"1.195453767","rc":[{"atb":[[1.34,2.43]],"id":42154339}],"con":true,"img":false}]}
{"op":"mcm","clk":"5353205861","pt":1646210933718,"mc":[{"id":"1.195453767","rc":[{"atb":[[1.32,0]],"id":42154339}],"con":true,"img":false}]}
{"op":"mcm","clk":"5353205893","pt":1646210934591,"mc":[{"id":"1.195453767","rc":[{"atb":[[1.33,0]],"id":42154339}],"con":true,"img":false}]}
{"op":"mcm","clk":"5353205897","pt":1646210934694,"mc":[{"id":"1.195453767","rc":[{"atb":[[1.31,1.58]],"id":42154339}],"con":true,"img":false}]}
{"op":"mcm","clk":"5353205946","pt":1646210936079,"mc":[{"id":"1.195453767","rc":[{"atb":[[1.3,52.92]],"id":42154339}],"con":true,"img":false}]}
{"op":"mcm","clk":"5353206481","pt":1646210952144,"mc":[{"id":"1.195453767","rc":[{"spn":3.38,"spf":"NaN","id":41818763},{"atb":[[1.36,5.42]],"id":42154339},{"spn":1.52,"spf":"NaN","id":42154339}],"con":true,"img":false}]}
{"op":"mcm","clk":"5353206585","pt":1646210955224,"mc":[{"id":"1.195453767","rc":[{"atb":[[1.34,0]],"id":42154339}],"con":true,"img":false}]}
{"op":"mcm","clk":"5353206658","pt":1646210957951,"mc":[{"id":"1.195453767","rc":[{"atb":[[1.27,0]],"id":42154339}],"con":true,"img":false}]}
{"op":"mcm","clk":"5353206661","pt":1646210958052,"mc":[{"id":"1.195453767","rc":[{"atb":[[1.31,110.22]],"id":42154339}],"con":true,"img":false}]}
{"op":"mcm","clk":"5353206724","pt":1646210959853,"mc":[{"id":"1.195453767","rc":[{"atb":[[1.32,6.5]],"id":42154339}],"con":true,"img":false}]}
{"op":"mcm","clk":"5353206729","pt":1646210960008,"mc":[{"id":"1.195453767","rc":[{"atb":[[1.3,27.83]],"id":42154339}],"con":true,"img":false}]}
{"op":"mcm","clk":"5353206926","pt":1646210965922,"mc":[{"id":"1.195453767","rc":[{"atb":[[1.34,22.13]],"id":42154339}],"con":true,"img":false}]}
{"op":"mcm","clk":"5353206931","pt":1646210966128,"mc":[{"id":"1.195453767","rc":[{"atb":[[1.31,108.64]],"id":42154339}],"con":true,"img":false}]}
{"op":"mcm","clk":"5353206936","pt":1646210966232,"mc":[{"id":"1.195453767","rc":[{"atb":[[1.36,7]],"id":42154339}],"con":true,"img":false}]}
{"op":"mcm","clk":"5353207003","pt":1646210968336,"mc":[{"id":"1.195453767","rc":[{"atb":[[1.3,0]],"id":42154339}],"con":true,"img":false}]}
{"op":"mcm","clk":"5353207026","pt":1646210968952,"mc":[{"id":"1.195453767","rc":[{"atb":[[1.32,0]],"id":42154339}],"con":true,"img":false}]}
{"op":"mcm","clk":"5353207211","pt":1646210973783,"mc":[{"id":"1.195453767","rc":[{"atb":[[1.32,8.4]],"id":42154339}],"con":true,"img":false}]}
{"op":"mcm","clk":"5353207276","pt":1646210975947,"mc":[{"id":"1.195453767","rc":[{"atb":[[1.31,0]],"id":42154339}],"con":true,"img":false}]}
{"op":"mcm","clk":"5353207280","pt":1646210976049,"mc":[{"id":"1.195453767","rc":[{"atb":[[1.27,108.64]],"id":42154339}],"con":true,"img":false}]}
{"op":"mcm","clk":"5353207363","pt":1646210978262,"mc":[{"id":"1.195453767","rc":[{"atb":[[1.34,0]],"id":42154339}],"con":true,"img":false}]}
{"op":"mcm","clk":"5353207400","pt":1646210979288,"mc":[{"id":"1.195453767","rc":[{"atb":[[1.36,5.42]],"id":42154339}],"con":true,"img":false}]}
{"op":"mcm","clk":"5353207404","pt":1646210979340,"mc":[{"id":"1.195453767","rc":[{"atb":[[1.01,1.58]],"id":42154339}],"con":true,"img":false}]}
{"op":"mcm","clk":"5353207526","pt":1646210982847,"mc":[{"id":"1.195453767","rc":[{"atb":[[1.32,0]],"id":42154339}],"con":true,"img":false}]}
{"op":"mcm","clk":"5353207601","pt":1646210985070,"mc":[{"id":"1.195453767","rc":[{"atb":[[1.3,25.08]],"id":42154339}],"con":true,"img":false}]}
{"op":"mcm","clk":"5353207678","pt":1646210987594,"mc":[{"id":"1.195453767","rc":[{"atb":[[1.28,8.66]],"id":42154339}],"con":true,"img":false}]}
{"op":"mcm","clk":"5353207779","pt":1646210990476,"mc":[{"id":"1.195453767","rc":[{"atl":[[1.68,23.89],[1.69,0]],"id":42154339}],"con":true,"img":false}]}
{"op":"mcm","clk":"5353207855","pt":1646210992171,"mc":[{"id":"1.195453767","rc":[{"atb":[[1.28,0]],"id":42154339}],"con":true,"img":false}]}
{"op":"mcm","clk":"5353208045","pt":1646210997583,"mc":[{"id":"1.195453767","rc":[{"atb":[[1.28,8.66]],"id":42154339}],"con":true,"img":false}]}
{"op":"mcm","clk":"5353208191","pt":1646211001814,"mc":[{"id":"1.195453767","rc":[{"atb":[[1.92,2.17]],"id":39637621},{"atb":[[2.38,2.17]],"id":41818763},{"atb":[[1.33,2.17]],"id":42154339}],"con":true,"img":false}]}
{"op":"mcm","clk":"5353208205","pt":1646211002177,"mc":[{"id":"1.195453767","rc":[{"atb":[[2.36,6.4]],"id":41818763}],"con":true,"img":false}]}
