{"op":"mcm","clk":"5346195405","pt":1646178339834,"mc":[{"id":"1.195453723","marketDefinition":{"bspMarket":false,"turnInPlayEnabled":false,"persistenceEnabled":false,"marketBaseRate":7.0,"eventId":"31272494","eventTypeId":"4339","numberOfWinners":1,"bettingType":"ODDS","marketType":"EXACTA","marketTime":"2022-03-02T10:11:00.000Z","suspendTime":"2022-03-02T10:11:00.000Z","bspReconciled":false,"complete":true,"inPlay":false,"crossMatching":false,"runnersVoidable":false,"numberOfActiveRunners":56,"betDelay":0,"status":"OPEN","runners":[{"status":"ACTIVE","sortPriority":1,"id":41419585,"name":"1 - 2"},{"status":"ACTIVE","sortPriority":2,"id":41419586,"name":"1 - 3"},{"status":"ACTIVE","sortPriority":3,"id":41419587,"name":"1 - 4"},{"status":"ACTIVE","sortPriority":4,"id":41419588,"name":"1 - 5"},{"status":"ACTIVE","sortPriority":5,"id":41419589,"name":"1 - 6"},{"status":"ACTIVE","sortPriority":6,"id":41419591,"name":"1 - 8"},{"status":"ACTIVE","sortPriority":7,"id":28546943,"name":"1 - 9"},{"status":"ACTIVE","sortPriority":8,"id":41419592,"name":"2 - 1"},{"status":"ACTIVE","sortPriority":9,"id":41419593,"name":"2 - 3"},{"status":"ACTIVE","sortPriority":10,"id":41419594,"name":"2 - 4"},{"status":"ACTIVE","sortPriority":11,"id":41419595,"name":"2 - 5"},{"status":"ACTIVE","sortPriority":12,"id":41419596,"name":"2 - 6"},{"status":"ACTIVE","sortPriority":13,"id":41419598,"name":"2 - 8"},{"status":"ACTIVE","sortPriority":14,"id":41419651,"name":"2 - 9"},{"status":"ACTIVE","sortPriority":15,"id":41419599,"name":"3 - 1"},{"status":"ACTIVE","sortPriority":16,"id":41419600,"name":"3 - 2"},{"status":"ACTIVE","sortPriority":17,"id":41419601,"name":"3 - 4"},{"status":"ACTIVE","sortPriority":18,"id":41419602,"name":"3 - 5"},{"status":"ACTIVE","sortPriority":19,"id":41419603,"name":"3 - 6"},{"status":"ACTIVE","sortPriority":20,"id":41419605,"name":"3 - 8"},{"status":"ACTIVE","sortPriority":21,"id":41419652,"name":"3 - 9"},{"status":"ACTIVE","sortPriority":22,"id":41419606,"name":"4 - 1"},{"status":"ACTIVE","sortPriority":23,"id":41419607,"name":"4 - 2"},{"status":"ACTIVE","sortPriority":24,"id":41419608,"name":"4 - 3"},{"status":"ACTIVE","sortPriority":25,"id":41419609,"name":"4 - 5"},{"status":"ACTIVE","sortPriority":26,"id":41419610,"name":"4 - 6"},{"status":"ACTIVE","sortPriority":27,"id":41419612,"name":"4 - 8"},{"status":"ACTIVE","sortPriority":28,"id":41435525,"name":"4 - 9"},{"status":"ACTIVE","sortPriority":29,"id":41419613,"name":"5 - 1"},{"status":"ACTIVE","sortPriority":30,"id":41419614,"name":"5 - 2"},{"status":"ACTIVE","sortPriority":31,"id":41419615,"name":"5 - 3"},{"status":"ACTIVE","sortPriority":32,"id":41419616,"name":"5 - 4"},{"status":"ACTIVE","sortPriority":33,"id":41419617,"name":"5 - 6"},{"status":"ACTIVE","sortPriority":34,"id":41419619,"name":"5 - 8"},{"status":"ACTIVE","sortPriority":35,"id":41419653,"name":"5 - 9"},{"status":"ACTIVE","sortPriority":36,"id":41419620,"name":"6 - 1"},{"status":"ACTIVE","sortPriority":37,"id":41419621,"name":"6 - 2"},{"status":"ACTIVE","sortPriority":38,"id":41419622,"name":"6 - 3"},{"status":"ACTIVE","sortPriority":39,"id":41419623,"name":"6 - 4"},{"status":"ACTIVE","sortPriority":40,"id":41419624,"name":"6 - 5"},{"status":"ACTIVE","sortPriority":41,"id":41419626,"name":"6 - 8"},{"status":"ACTIVE","sortPriority":42,"id":41435526,"name":"6 - 9"},{"status":"ACTIVE","sortPriority":43,"id":41419634,"name":"8 - 1"},{"status":"ACTIVE","sortPriority":44,"id":41419635,"name":"8 - 2"},{"status":"ACTIVE","sortPriority":45,"id":41419636,"name":"8 - 3"},{"status":"ACTIVE","sortPriority":46,"id":41419637,"name":"8 - 4"},{"status":"ACTIVE","sortPriority":47,"id":41419638,"name":"8 - 5"},{"status":"ACTIVE","sortPriority":48,"id":41419639,"name":"8 - 6"},{"status":"ACTIVE","sortPriority":49,"id":41419655,"name":"8 - 9"},{"status":"ACTIVE","sortPriority":50,"id":28546950,"name":"9 - 1"},{"status":"ACTIVE","sortPriority":51,"id":41419656,"name":"9 - 2"},{"status":"ACTIVE","sortPriority":52,"id":41419657,"name":"9 - 3"},{"status":"ACTIVE","sortPriority":53,"id":41435527,"name":"9 - 4"},{"status":"ACTIVE","sortPriority":54,"id":41419658,"name":"9 - 5"},{"status":"ACTIVE","sortPriority":55,"id":41435528,"name":"9 - 6"},{"status":"ACTIVE","sortPriority":56,"id":41419660,"name":"9 - 8"}],"regulators":["MR_INT"],"venue":"Traralgon","countryCode":"AU","discountAllowed":true,"timezone":"Australia/Sydney","openDate":"2022-03-02T08:31:00.000Z","version":4382480625,"name":"Exacta","eventName":"Traralgon (AUS) 2nd Mar"},"rc":[],"con":true,"img":false}]}
{"op":"mcm","clk":"5346203715","pt":1646178502896,"mc":[{"id":"1.195453723","rc":[{"atb":[[300,0.66],[150,1.33],[75,3.59]],"id":41419609},{"atb":[[85,2.37],[44,6.18],[220,0.9]],"id":41419638},{"atb":[[17.5,12.09],[12.5,23.13],[30,6.88]],"id":41419605},{"atb":[[85,2.37],[44,6.18],[220,0.9]],"id":41419634},{"atb":[[150,1.33],[50,4.07],[30,9.17]],"id":41419617},{"atb":[[600,0.44],[700,0.28],[850,0.23]],"id":41419613},{"atb":[[6.8,34.4],[9.8,22.67],[5.4,60.47]],"id":41419593},{"atb":[[130,1.54],[46,4.43],[28,9.85]],"id":41419655},{"atb":[[24,8.67],[9.8,30.23],[14.5,14.78]],"id":41419622},{"atb":[[150,1.33],[50,4.07],[30,9.17]],"id":41419589},{"atb":[[90,2.24],[46,5.91],[230,0.87]],"id":41435527},{"atb":[[17,12.47],[12,24.19],[29,7.12]],"id":41419651},{"atb":[[36,5.69],[19,11.08],[14,20.46]],"id":41419601},{"atb":[[600,0.44],[700,0.28],[850,0.23]],"id":28546943},{"atb":[[8,38.01],[17.5,12.09],[10,22.17]],"id":41419626},{"atb":[[18,11.73],[10.5,21],[8.2,36.95]],"id":41419639},{"atb":[[300,0.66],[150,1.33],[75,3.59]],"id":41419606},{"atb":[[5.1,64.89],[9.2,24.33],[6.2,38.37]],"id":41419635},{"atb":[[320,0.62],[220,1.21],[470,0.42]],"id":41419602},{"atb":[[17.5,16.12],[50,4.07],[25,8.31]],"id":41419585},{"atb":[[17.5,16.12],[50,4.07],[25,8.31]],"id":41419614},{"atb":[[9,33.26],[20,10.5],[12.5,17.35]],"id":41419610},{"atb":[[16,17.74],[44,4.64],[22,9.5]],"id":41419656},{"atb":[[8.6,35.01],[19,11.08],[11.5,19]],"id":41419623},{"atb":[[330,0.6],[180,1.11],[90,2.98]],"id":41419652},{"atb":[[36,5.69],[90,2.24],[23,12.09]],"id":41435528},{"atb":[[270,0.74],[120,1.67],[60,4.5]],"id":41419619},{"atb":[[520,0.38],[270,0.99],[370,0.53]],"id":41419586},{"atb":[[7.4,31.18],[5.2,47.51],[4.2,83.15]],"id":41419598},{"atb":[[34,8.06],[170,1.18],[60,3.38]],"id":41419660},{"atb":[[5.6,43.38],[4.6,73.91],[8.2,27.71]],"id":41419594},{"atb":[[5.8,55.43],[11.5,19],[7.6,30.23]],"id":41419607},{"atb":[[600,0.44],[700,0.28],[850,0.23]],"id":28546950},{"atb":[[17,12.47],[12,24.19],[29,7.12]],"id":41419636},{"atb":[[10.5,28],[26,7.98],[15.5,13.76]],"id":41419603},{"atb":[[520,0.38],[270,0.99],[370,0.53]],"id":41419615},{"atb":[[360,0.55],[210,0.95],[110,2.43]],"id":41419657},{"atb":[[40,5.11],[100,2.01],[25,11.08]],"id":41419624},{"atb":[[270,0.74],[120,1.67],[60,4.5]],"id":41419591},{"atb":[[75,2.69],[40,6.82],[200,1]],"id":41435525},{"atb":[[600,0.44],[700,0.28],[850,0.23]],"id":41419653},{"atb":[[40,5.11],[100,2.01],[25,11.08]],"id":41419620},{"atb":[[350,0.57],[200,1],[100,2.68]],"id":41419587},{"atb":[[320,0.62],[220,1.21],[470,0.42]],"id":41419599},{"atb":[[36,5.69],[19,11.08],[14,20.46]],"id":41419595},{"atb":[[36,5.69],[19,11.08],[14,20.46]],"id":41419608},{"atb":[[10.5,28],[26,7.98],[15.5,13.76]],"id":41419637},{"atb":[[350,0.57],[200,1],[100,2.68]],"id":41419616},{"atb":[[10.5,28],[26,7.98],[15.5,13.76]],"id":41419612},{"atb":[[36,5.69],[19,11.08],[14,20.46]],"id":41419592},{"atb":[[70,2.89],[19.5,14.38],[29,7.12]],"id":41435526},{"atb":[[7.2,32.18],[5.1,48.67],[4.1,85.83]],"id":41419621},{"atb":[[600,0.44],[700,0.28],[850,0.23]],"id":41419588},{"atb":[[7.2,42.91],[9.2,24.33],[15.5,13.76]],"id":41419600},{"atb":[[5.3,46.41],[3.4,110.87],[3.9,68.81]],"id":41419596},{"atb":[[600,0.44],[700,0.28],[850,0.23]],"id":41419658}],"con":true,"img":false}]}
{"op":"mcm","clk":"5346401444","pt":1646182002781,"mc":[{"id":"1.195453723","marketDefinition":{"bspMarket":false,"turnInPlayEnabled":false,"persistenceEnabled":false,"marketBaseRate":7.0,"eventId":"31272494","eventTypeId":"4339","numberOfWinners":1,"bettingType":"ODDS","marketType":"EXACTA","marketTime":"2022-03-02T10:11:00.000Z","suspendTime":"2022-03-02T10:11:00.000Z","bspReconciled":false,"complete":true,"inPlay":false,"crossMatching":false,"runnersVoidable":false,"numberOfActiveRunners":56,"betDelay":0,"status":"OPEN","runners":[{"status":"ACTIVE","sortPriority":1,"id":41419585,"name":"1 - 2"},{"status":"ACTIVE","sortPriority":2,"id":41419586,"name":"1 - 3"},{"status":"ACTIVE","sortPriority":3,"id":41419587,"name":"1 - 4"},{"status":"ACTIVE","sortPriority":4,"id":41419588,"name":"1 - 5"},{"status":"ACTIVE","sortPriority":5,"id":41419589,"name":"1 - 6"},{"status":"ACTIVE","sortPriority":6,"id":41419591,"name":"1 - 8"},{"status":"ACTIVE","sortPriority":7,"id":28546943,"name":"1 - 9"},{"status":"ACTIVE","sortPriority":8,"id":41419592,"name":"2 - 1"},{"status":"ACTIVE","sortPriority":9,"id":41419593,"name":"2 - 3"},{"status":"ACTIVE","sortPriority":10,"id":41419594,"name":"2 - 4"},{"status":"ACTIVE","sortPriority":11,"id":41419595,"name":"2 - 5"},{"status":"ACTIVE","sortPriority":12,"id":41419596,"name":"2 - 6"},{"status":"ACTIVE","sortPriority":13,"id":41419598,"name":"2 - 8"},{"status":"ACTIVE","sortPriority":14,"id":41419651,"name":"2 - 9"},{"status":"ACTIVE","sortPriority":15,"id":41419599,"name":"3 - 1"},{"status":"ACTIVE","sortPriority":16,"id":41419600,"name":"3 - 2"},{"status":"ACTIVE","sortPriority":17,"id":41419601,"name":"3 - 4"},{"status":"ACTIVE","sortPriority":18,"id":41419602,"name":"3 - 5"},{"status":"ACTIVE","sortPriority":19,"id":41419603,"name":"3 - 6"},{"status":"ACTIVE","sortPriority":20,"id":41419605,"name":"3 - 8"},{"status":"ACTIVE","sortPriority":21,"id":41419652,"name":"3 - 9"},{"status":"ACTIVE","sortPriority":22,"id":41419606,"name":"4 - 1"},{"status":"ACTIVE","sortPriority":23,"id":41419607,"name":"4 - 2"},{"status":"ACTIVE","sortPriority":24,"id":41419608,"name":"4 - 3"},{"status":"ACTIVE","sortPriority":25,"id":41419609,"name":"4 - 5"},{"status":"ACTIVE","sortPriority":26,"id":41419610,"name":"4 - 6"},{"status":"ACTIVE","sortPriority":27,"id":41419612,"name":"4 - 8"},{"status":"ACTIVE","sortPriority":28,"id":41435525,"name":"4 - 9"},{"status":"ACTIVE","sortPriority":29,"id":41419613,"name":"5 - 1"},{"status":"ACTIVE","sortPriority":30,"id":41419614,"name":"5 - 2"},{"status":"ACTIVE","sortPriority":31,"id":41419615,"name":"5 - 3"},{"status":"ACTIVE","sortPriority":32,"id":41419616,"name":"5 - 4"},{"status":"ACTIVE","sortPriority":33,"id":41419617,"name":"5 - 6"},{"status":"ACTIVE","sortPriority":34,"id":41419619,"name":"5 - 8"},{"status":"ACTIVE","sortPriority":35,"id":41419653,"name":"5 - 9"},{"status":"ACTIVE","sortPriority":36,"id":41419620,"name":"6 - 1"},{"status":"ACTIVE","sortPriority":37,"id":41419621,"name":"6 - 2"},{"status":"ACTIVE","sortPriority":38,"id":41419622,"name":"6 - 3"},{"status":"ACTIVE","sortPriority":39,"id":41419623,"name":"6 - 4"},{"status":"ACTIVE","sortPriority":40,"id":41419624,"name":"6 - 5"},{"status":"ACTIVE","sortPriority":41,"id":41419626,"name":"6 - 8"},{"status":"ACTIVE","sortPriority":42,"id":41435526,"name":"6 - 9"},{"status":"ACTIVE","sortPriority":43,"id":41419634,"name":"8 - 1"},{"status":"ACTIVE","sortPriority":44,"id":41419635,"name":"8 - 2"},{"status":"ACTIVE","sortPriority":45,"id":41419636,"name":"8 - 3"},{"status":"ACTIVE","sortPriority":46,"id":41419637,"name":"8 - 4"},{"status":"ACTIVE","sortPriority":47,"id":41419638,"name":"8 - 5"},{"status":"ACTIVE","sortPriority":48,"id":41419639,"name":"8 - 6"},{"status":"ACTIVE","sortPriority":49,"id":41419655,"name":"8 - 9"},{"status":"ACTIVE","sortPriority":50,"id":28546950,"name":"9 - 1"},{"status":"ACTIVE","sortPriority":51,"id":41419656,"name":"9 - 2"},{"status":"ACTIVE","sortPriority":52,"id":41419657,"name":"9 - 3"},{"status":"ACTIVE","sortPriority":53,"id":41435527,"name":"9 - 4"},{"status":"ACTIVE","sortPriority":54,"id":41419658,"name":"9 - 5"},{"status":"ACTIVE","sortPriority":55,"id":41435528,"name":"9 - 6"},{"status":"ACTIVE","sortPriority":56,"id":41419660,"name":"9 - 8"}],"regulators":["MR_INT"],"venue":"Traralgon","countryCode":"AU","discountAllowed":true,"timezone":"Australia/Sydney","openDate":"2022-03-02T08:31:00.000Z","version":4382480625,"name":"Exacta","eventName":"Traralgon (AUS) 2nd Mar"},"rc":[{"atb":[[300,0.66],[150,1.33],[75,3.59]],"id":41419609},{"atb":[[85,2.37],[44,6.19],[220,0.9]],"id":41419638},{"atb":[[17.5,12.09],[12.5,23.13],[30,6.88]],"id":41419605},{"atb":[[85,2.37],[44,6.19],[220,0.9]],"id":41419634},{"atb":[[150,1.33],[50,4.07],[30,9.17]],"id":41419617},{"atb":[[600,0.44],[700,0.28],[850,0.23]],"id":41419613},{"atb":[[6.8,34.41],[9.8,22.68],[5.4,60.48]],"id":41419593},{"atb":[[130,1.54],[46,4.43],[28,9.85]],"id":41419655},{"atb":[[24,8.67],[9.8,30.24],[14.5,14.78]],"id":41419622},{"atb":[[150,1.33],[50,4.07],[30,9.17]],"id":41419589},{"atb":[[90,2.24],[46,5.91],[230,0.87]],"id":41435527},{"atb":[[17,12.47],[12,24.19],[29,7.12]],"id":41419651},{"atb":[[36,5.7],[19,11.08],[14,20.47]],"id":41419601},{"atb":[[600,0.44],[700,0.28],[850,0.23]],"id":28546943},{"atb":[[8,38.01],[17.5,12.09],[10,22.17]],"id":41419626},{"atb":[[18,11.73],[10.5,21],[8.2,36.96]],"id":41419639},{"atb":[[300,0.66],[150,1.33],[75,3.59]],"id":41419606},{"atb":[[5.1,64.9],[9.2,24.34],[6.2,38.38]],"id":41419635},{"atb":[[320,0.62],[220,1.21],[470,0.42]],"id":41419602},{"atb":[[17.5,16.12],[50,4.07],[25,8.31]],"id":41419585},{"atb":[[17.5,16.12],[50,4.07],[25,8.31]],"id":41419614},{"atb":[[9,33.26],[20,10.5],[12.5,17.35]],"id":41419610},{"atb":[[16,17.74],[44,4.64],[22,9.5]],"id":41419656},{"atb":[[8.6,35.01],[19,11.08],[11.5,19]],"id":41419623},{"atb":[[330,0.6],[180,1.11],[90,2.98]],"id":41419652},{"atb":[[36,5.7],[90,2.24],[23,12.09]],"id":41435528},{"atb":[[270,0.74],[120,1.67],[60,4.5]],"id":41419619},{"atb":[[520,0.38],[270,0.99],[370,0.53]],"id":41419586},{"atb":[[7.4,31.18],[5.2,47.52],[4.2,83.16]],"id":41419598},{"atb":[[34,8.06],[170,1.18],[60,3.38]],"id":41419660},{"atb":[[5.6,43.39],[4.6,73.92],[8.2,27.72]],"id":41419594},{"atb":[[5.8,55.43],[11.5,19],[7.6,30.24]],"id":41419607},{"atb":[[600,0.44],[700,0.28],[850,0.23]],"id":28546950},{"atb":[[17,12.47],[12,24.19],[29,7.12]],"id":41419636},{"atb":[[10.5,28.01],[26,7.98],[15.5,13.76]],"id":41419603},{"atb":[[520,0.38],[270,0.99],[370,0.53]],"id":41419615},{"atb":[[360,0.55],[210,0.95],[110,2.43]],"id":41419657},{"atb":[[40,5.11],[100,2.01],[25,11.08]],"id":41419624},{"atb":[[270,0.74],[120,1.67],[60,4.5]],"id":41419591},{"atb":[[75,2.69],[40,6.82],[200,1]],"id":41435525},{"atb":[[600,0.44],[700,0.28],[850,0.23]],"id":41419653},{"atb":[[40,5.11],[100,2.01],[25,11.08]],"id":41419620},{"atb":[[350,0.57],[200,1],[100,2.68]],"id":41419587},{"atb":[[320,0.62],[220,1.21],[470,0.42]],"id":41419599},{"atb":[[36,5.7],[19,11.08],[14,20.47]],"id":41419595},{"atb":[[36,5.7],[19,11.08],[14,20.47]],"id":41419608},{"atb":[[10.5,28.01],[26,7.98],[15.5,13.76]],"id":41419637},{"atb":[[350,0.57],[200,1],[100,2.68]],"id":41419616},{"atb":[[10.5,28.01],[26,7.98],[15.5,13.76]],"id":41419612},{"atb":[[36,5.7],[19,11.08],[14,20.47]],"id":41419592},{"atb":[[70,2.89],[19.5,14.38],[29,7.12]],"id":41435526},{"atb":[[7.2,32.19],[5.1,48.67],[4.1,85.84]],"id":41419621},{"atb":[[600,0.44],[700,0.28],[850,0.23]],"id":41419588},{"atb":[[7.2,42.92],[9.2,24.34],[15.5,13.76]],"id":41419600},{"atb":[[5.3,46.41],[3.4,110.88],[3.9,68.82]],"id":41419596},{"atb":[[600,0.44],[700,0.28],[850,0.23]],"id":41419658}],"con":true,"img":true}]}
{"op":"mcm","clk":"5346767801","pt":1646187402726,"mc":[{"id":"1.195453723","marketDefinition":{"bspMarket":false,"turnInPlayEnabled":false,"persistenceEnabled":false,"marketBaseRate":7.0,"eventId":"31272494","eventTypeId":"4339","numberOfWinners":1,"bettingType":"ODDS","marketType":"EXACTA","marketTime":"2022-03-02T10:11:00.000Z","suspendTime":"2022-03-02T10:11:00.000Z","bspReconciled":false,"complete":true,"inPlay":false,"crossMatching":false,"runnersVoidable":false,"numberOfActiveRunners":56,"betDelay":0,"status":"OPEN","runners":[{"status":"ACTIVE","sortPriority":1,"id":41419585,"name":"1 - 2"},{"status":"ACTIVE","sortPriority":2,"id":41419586,"name":"1 - 3"},{"status":"ACTIVE","sortPriority":3,"id":41419587,"name":"1 - 4"},{"status":"ACTIVE","sortPriority":4,"id":41419588,"name":"1 - 5"},{"status":"ACTIVE","sortPriority":5,"id":41419589,"name":"1 - 6"},{"status":"ACTIVE","sortPriority":6,"id":41419591,"name":"1 - 8"},{"status":"ACTIVE","sortPriority":7,"id":28546943,"name":"1 - 9"},{"status":"ACTIVE","sortPriority":8,"id":41419592,"name":"2 - 1"},{"status":"ACTIVE","sortPriority":9,"id":41419593,"name":"2 - 3"},{"status":"ACTIVE","sortPriority":10,"id":41419594,"name":"2 - 4"},{"status":"ACTIVE","sortPriority":11,"id":41419595,"name":"2 - 5"},{"status":"ACTIVE","sortPriority":12,"id":41419596,"name":"2 - 6"},{"status":"ACTIVE","sortPriority":13,"id":41419598,"name":"2 - 8"},{"status":"ACTIVE","sortPriority":14,"id":41419651,"name":"2 - 9"},{"status":"ACTIVE","sortPriority":15,"id":41419599,"name":"3 - 1"},{"status":"ACTIVE","sortPriority":16,"id":41419600,"name":"3 - 2"},{"status":"ACTIVE","sortPriority":17,"id":41419601,"name":"3 - 4"},{"status":"ACTIVE","sortPriority":18,"id":41419602,"name":"3 - 5"},{"status":"ACTIVE","sortPriority":19,"id":41419603,"name":"3 - 6"},{"status":"ACTIVE","sortPriority":20,"id":41419605,"name":"3 - 8"},{"status":"ACTIVE","sortPriority":21,"id":41419652,"name":"3 - 9"},{"status":"ACTIVE","sortPriority":22,"id":41419606,"name":"4 - 1"},{"status":"ACTIVE","sortPriority":23,"id":41419607,"name":"4 - 2"},{"status":"ACTIVE","sortPriority":24,"id":41419608,"name":"4 - 3"},{"status":"ACTIVE","sortPriority":25,"id":41419609,"name":"4 - 5"},{"status":"ACTIVE","sortPriority":26,"id":41419610,"name":"4 - 6"},{"status":"ACTIVE","sortPriority":27,"id":41419612,"name":"4 - 8"},{"status":"ACTIVE","sortPriority":28,"id":41435525,"name":"4 - 9"},{"status":"ACTIVE","sortPriority":29,"id":41419613,"name":"5 - 1"},{"status":"ACTIVE","sortPriority":30,"id":41419614,"name":"5 - 2"},{"status":"ACTIVE","sortPriority":31,"id":41419615,"name":"5 - 3"},{"status":"ACTIVE","sortPriority":32,"id":41419616,"name":"5 - 4"},{"status":"ACTIVE","sortPriority":33,"id":41419617,"name":"5 - 6"},{"status":"ACTIVE","sortPriority":34,"id":41419619,"name":"5 - 8"},{"status":"ACTIVE","sortPriority":35,"id":41419653,"name":"5 - 9"},{"status":"ACTIVE","sortPriority":36,"id":41419620,"name":"6 - 1"},{"status":"ACTIVE","sortPriority":37,"id":41419621,"name":"6 - 2"},{"status":"ACTIVE","sortPriority":38,"id":41419622,"name":"6 - 3"},{"status":"ACTIVE","sortPriority":39,"id":41419623,"name":"6 - 4"},{"status":"ACTIVE","sortPriority":40,"id":41419624,"name":"6 - 5"},{"status":"ACTIVE","sortPriority":41,"id":41419626,"name":"6 - 8"},{"status":"ACTIVE","sortPriority":42,"id":41435526,"name":"6 - 9"},{"status":"ACTIVE","sortPriority":43,"id":41419634,"name":"8 - 1"},{"status":"ACTIVE","sortPriority":44,"id":41419635,"name":"8 - 2"},{"status":"ACTIVE","sortPriority":45,"id":41419636,"name":"8 - 3"},{"status":"ACTIVE","sortPriority":46,"id":41419637,"name":"8 - 4"},{"status":"ACTIVE","sortPriority":47,"id":41419638,"name":"8 - 5"},{"status":"ACTIVE","sortPriority":48,"id":41419639,"name":"8 - 6"},{"status":"ACTIVE","sortPriority":49,"id":41419655,"name":"8 - 9"},{"status":"ACTIVE","sortPriority":50,"id":28546950,"name":"9 - 1"},{"status":"ACTIVE","sortPriority":51,"id":41419656,"name":"9 - 2"},{"status":"ACTIVE","sortPriority":52,"id":41419657,"name":"9 - 3"},{"status":"ACTIVE","sortPriority":53,"id":41435527,"name":"9 - 4"},{"status":"ACTIVE","sortPriority":54,"id":41419658,"name":"9 - 5"},{"status":"ACTIVE","sortPriority":55,"id":41435528,"name":"9 - 6"},{"status":"ACTIVE","sortPriority":56,"id":41419660,"name":"9 - 8"}],"regulators":["MR_INT"],"venue":"Traralgon","countryCode":"AU","discountAllowed":true,"timezone":"Australia/Sydney","openDate":"2022-03-02T08:31:00.000Z","version":4382480625,"name":"Exacta","eventName":"Traralgon (AUS) 2nd Mar"},"rc":[{"atb":[[300,0.67],[150,1.34],[75,3.6]],"id":41419609},{"atb":[[85,2.37],[44,6.19],[220,0.91]],"id":41419638},{"atb":[[17.5,12.11],[12.5,23.17],[30,6.89]],"id":41419605},{"atb":[[85,2.37],[44,6.19],[220,0.91]],"id":41419634},{"atb":[[150,1.34],[50,4.07],[30,9.19]],"id":41419617},{"atb":[[600,0.44],[700,0.28],[850,0.23]],"id":41419613},{"atb":[[6.8,34.46],[9.8,22.71],[5.4,60.57]],"id":41419593},{"atb":[[130,1.54],[46,4.44],[28,9.86]],"id":41419655},{"atb":[[24,8.69],[9.8,30.29],[14.5,14.8]],"id":41419622},{"atb":[[150,1.34],[50,4.07],[30,9.19]],"id":41419589},{"atb":[[90,2.24],[46,5.92],[230,0.87]],"id":41435527},{"atb":[[17,12.49],[12,24.23],[29,7.13]],"id":41419651},{"atb":[[36,5.7],[19,11.1],[14,20.5]],"id":41419601},{"atb":[[600,0.44],[700,0.28],[850,0.23]],"id":28546943},{"atb":[[8,38.07],[17.5,12.11],[10,22.2]],"id":41419626},{"atb":[[18,11.75],[10.5,21.04],[8.2,37.01]],"id":41419639},{"atb":[[300,0.67],[150,1.34],[75,3.6]],"id":41419606},{"atb":[[5.1,65],[9.2,24.37],[6.2,38.44]],"id":41419635},{"atb":[[320,0.62],[220,1.21],[470,0.42]],"id":41419602},{"atb":[[17.5,16.15],[50,4.07],[25,8.32]],"id":41419585},{"atb":[[17.5,16.15],[50,4.07],[25,8.32]],"id":41419614},{"atb":[[9,33.31],[20,10.51],[12.5,17.38]],"id":41419610},{"atb":[[16,17.77],[44,4.65],[22,9.52]],"id":41419656},{"atb":[[8.6,35.07],[19,11.1],[11.5,19.03]],"id":41419623},{"atb":[[330,0.6],[180,1.11],[90,2.99]],"id":41419652},{"atb":[[36,5.7],[90,2.24],[23,12.11]],"id":41435528},{"atb":[[270,0.74],[120,1.67],[60,4.51]],"id":41419619},{"atb":[[520,0.38],[270,0.99],[370,0.53]],"id":41419586},{"atb":[[7.4,31.23],[5.2,47.59],[4.2,83.29]],"id":41419598},{"atb":[[34,8.07],[170,1.18],[60,3.38]],"id":41419660},{"atb":[[5.6,43.45],[4.6,74.03],[8.2,27.76]],"id":41419594},{"atb":[[5.8,55.52],[11.5,19.03],[7.6,30.29]],"id":41419607},{"atb":[[600,0.44],[700,0.28],[850,0.23]],"id":28546950},{"atb":[[17,12.49],[12,24.23],[29,7.13]],"id":41419636},{"atb":[[10.5,28.05],[26,7.99],[15.5,13.78]],"id":41419603},{"atb":[[520,0.38],[270,0.99],[370,0.53]],"id":41419615},{"atb":[[360,0.55],[210,0.95],[110,2.44]],"id":41419657},{"atb":[[40,5.12],[100,2.01],[25,11.1]],"id":41419624},{"atb":[[270,0.74],[120,1.67],[60,4.51]],"id":41419591},{"atb":[[75,2.69],[40,6.83],[200,1]],"id":41435525},{"atb":[[600,0.44],[700,0.28],[850,0.23]],"id":41419653},{"atb":[[40,5.12],[100,2.01],[25,11.1]],"id":41419620},{"atb":[[350,0.57],[200,1],[100,2.69]],"id":41419587},{"atb":[[320,0.62],[220,1.21],[470,0.42]],"id":41419599},{"atb":[[36,5.7],[19,11.1],[14,20.5]],"id":41419595},{"atb":[[36,5.7],[19,11.1],[14,20.5]],"id":41419608},{"atb":[[10.5,28.05],[26,7.99],[15.5,13.78]],"id":41419637},{"atb":[[350,0.57],[200,1],[100,2.69]],"id":41419616},{"atb":[[10.5,28.05],[26,7.99],[15.5,13.78]],"id":41419612},{"atb":[[36,5.7],[19,11.1],[14,20.5]],"id":41419592},{"atb":[[70,2.89],[19.5,14.4],[29,7.13]],"id":41435526},{"atb":[[7.2,32.24],[5.1,48.75],[4.1,85.98]],"id":41419621},{"atb":[[600,0.44],[700,0.28],[850,0.23]],"id":41419588},{"atb":[[7.2,42.99],[9.2,24.37],[15.5,13.78]],"id":41419600},{"atb":[[5.3,46.49],[3.4,111.05],[3.9,68.92]],"id":41419596},{"atb":[[600,0.44],[700,0.28],[850,0.23]],"id":41419658}],"con":true,"img":true}]}
{"op":"mcm","clk":"5347092355","pt":1646192802706,"mc":[{"id":"1.195453723","marketDefinition":{"bspMarket":false,"turnInPlayEnabled":false,"persistenceEnabled":false,"marketBaseRate":7.0,"eventId":"31272494","eventTypeId":"4339","numberOfWinners":1,"bettingType":"ODDS","marketType":"EXACTA","marketTime":"2022-03-02T10:11:00.000Z","suspendTime":"2022-03-02T10:11:00.000Z","bspReconciled":false,"complete":true,"inPlay":false,"crossMatching":false,"runnersVoidable":false,"numberOfActiveRunners":56,"betDelay":0,"status":"OPEN","runners":[{"status":"ACTIVE","sortPriority":1,"id":41419585,"name":"1 - 2"},{"status":"ACTIVE","sortPriority":2,"id":41419586,"name":"1 - 3"},{"status":"ACTIVE","sortPriority":3,"id":41419587,"name":"1 - 4"},{"status":"ACTIVE","sortPriority":4,"id":41419588,"name":"1 - 5"},{"status":"ACTIVE","sortPriority":5,"id":41419589,"name":"1 - 6"},{"status":"ACTIVE","sortPriority":6,"id":41419591,"name":"1 - 8"},{"status":"ACTIVE","sortPriority":7,"id":28546943,"name":"1 - 9"},{"status":"ACTIVE","sortPriority":8,"id":41419592,"name":"2 - 1"},{"status":"ACTIVE","sortPriority":9,"id":41419593,"name":"2 - 3"},{"status":"ACTIVE","sortPriority":10,"id":41419594,"name":"2 - 4"},{"status":"ACTIVE","sortPriority":11,"id":41419595,"name":"2 - 5"},{"status":"ACTIVE","sortPriority":12,"id":41419596,"name":"2 - 6"},{"status":"ACTIVE","sortPriority":13,"id":41419598,"name":"2 - 8"},{"status":"ACTIVE","sortPriority":14,"id":41419651,"name":"2 - 9"},{"status":"ACTIVE","sortPriority":15,"id":41419599,"name":"3 - 1"},{"status":"ACTIVE","sortPriority":16,"id":41419600,"name":"3 - 2"},{"status":"ACTIVE","sortPriority":17,"id":41419601,"name":"3 - 4"},{"status":"ACTIVE","sortPriority":18,"id":41419602,"name":"3 - 5"},{"status":"ACTIVE","sortPriority":19,"id":41419603,"name":"3 - 6"},{"status":"ACTIVE","sortPriority":20,"id":41419605,"name":"3 - 8"},{"status":"ACTIVE","sortPriority":21,"id":41419652,"name":"3 - 9"},{"status":"ACTIVE","sortPriority":22,"id":41419606,"name":"4 - 1"},{"status":"ACTIVE","sortPriority":23,"id":41419607,"name":"4 - 2"},{"status":"ACTIVE","sortPriority":24,"id":41419608,"name":"4 - 3"},{"status":"ACTIVE","sortPriority":25,"id":41419609,"name":"4 - 5"},{"status":"ACTIVE","sortPriority":26,"id":41419610,"name":"4 - 6"},{"status":"ACTIVE","sortPriority":27,"id":41419612,"name":"4 - 8"},{"status":"ACTIVE","sortPriority":28,"id":41435525,"name":"4 - 9"},{"status":"ACTIVE","sortPriority":29,"id":41419613,"name":"5 - 1"},{"status":"ACTIVE","sortPriority":30,"id":41419614,"name":"5 - 2"},{"status":"ACTIVE","sortPriority":31,"id":41419615,"name":"5 - 3"},{"status":"ACTIVE","sortPriority":32,"id":41419616,"name":"5 - 4"},{"status":"ACTIVE","sortPriority":33,"id":41419617,"name":"5 - 6"},{"status":"ACTIVE","sortPriority":34,"id":41419619,"name":"5 - 8"},{"status":"ACTIVE","sortPriority":35,"id":41419653,"name":"5 - 9"},{"status":"ACTIVE","sortPriority":36,"id":41419620,"name":"6 - 1"},{"status":"ACTIVE","sortPriority":37,"id":41419621,"name":"6 - 2"},{"status":"ACTIVE","sortPriority":38,"id":41419622,"name":"6 - 3"},{"status":"ACTIVE","sortPriority":39,"id":41419623,"name":"6 - 4"},{"status":"ACTIVE","sortPriority":40,"id":41419624,"name":"6 - 5"},{"status":"ACTIVE","sortPriority":41,"id":41419626,"name":"6 - 8"},{"status":"ACTIVE","sortPriority":42,"id":41435526,"name":"6 - 9"},{"status":"ACTIVE","sortPriority":43,"id":41419634,"name":"8 - 1"},{"status":"ACTIVE","sortPriority":44,"id":41419635,"name":"8 - 2"},{"status":"ACTIVE","sortPriority":45,"id":41419636,"name":"8 - 3"},{"status":"ACTIVE","sortPriority":46,"id":41419637,"name":"8 - 4"},{"status":"ACTIVE","sortPriority":47,"id":41419638,"name":"8 - 5"},{"status":"ACTIVE","sortPriority":48,"id":41419639,"name":"8 - 6"},{"status":"ACTIVE","sortPriority":49,"id":41419655,"name":"8 - 9"},{"status":"ACTIVE","sortPriority":50,"id":28546950,"name":"9 - 1"},{"status":"ACTIVE","sortPriority":51,"id":41419656,"name":"9 - 2"},{"status":"ACTIVE","sortPriority":52,"id":41419657,"name":"9 - 3"},{"status":"ACTIVE","sortPriority":53,"id":41435527,"name":"9 - 4"},{"status":"ACTIVE","sortPriority":54,"id":41419658,"name":"9 - 5"},{"status":"ACTIVE","sortPriority":55,"id":41435528,"name":"9 - 6"},{"status":"ACTIVE","sortPriority":56,"id":41419660,"name":"9 - 8"}],"regulators":["MR_INT"],"venue":"Traralgon","countryCode":"AU","discountAllowed":true,"timezone":"Australia/Sydney","openDate":"2022-03-02T08:31:00.000Z","version":4382480625,"name":"Exacta","eventName":"Traralgon (AUS) 2nd Mar"},"rc":[{"atb":[[300,0.67],[150,1.34],[75,3.61]],"id":41419609},{"atb":[[85,2.38],[44,6.21],[220,0.91]],"id":41419638},{"atb":[[17.5,12.13],[12.5,23.21],[30,6.9]],"id":41419605},{"atb":[[85,2.38],[44,6.21],[220,0.91]],"id":41419634},{"atb":[[150,1.34],[50,4.08],[30,9.2]],"id":41419617},{"atb":[[600,0.44],[700,0.28],[850,0.23]],"id":41419613},{"atb":[[6.8,34.52],[9.8,22.75],[5.4,60.67]],"id":41419593},{"atb":[[130,1.55],[46,4.45],[28,9.88]],"id":41419655},{"atb":[[24,8.7],[9.8,30.34],[14.5,14.83]],"id":41419622},{"atb":[[150,1.34],[50,4.08],[30,9.2]],"id":41419589},{"atb":[[90,2.25],[46,5.93],[230,0.87]],"id":41435527},{"atb":[[17,12.51],[12,24.27],[29,7.14]],"id":41419651},{"atb":[[36,5.71],[19,11.12],[14,20.53]],"id":41419601},{"atb":[[600,0.44],[700,0.28],[850,0.23]],"id":28546943},{"atb":[[8,38.14],[17.5,12.13],[10,22.24]],"id":41419626},{"atb":[[18,11.77],[10.5,21.07],[8.2,37.08]],"id":41419639},{"atb":[[300,0.67],[150,1.34],[75,3.61]],"id":41419606},{"atb":[[5.1,65.11],[9.2,24.42],[6.2,38.5]],"id":41419635},{"atb":[[320,0.62],[220,1.21],[470,0.42]],"id":41419602},{"atb":[[17.5,16.17],[50,4.08],[25,8.34]],"id":41419585},{"atb":[[17.5,16.17],[50,4.08],[25,8.34]],"id":41419614},{"atb":[[9,33.37],[20,10.53],[12.5,17.41]],"id":41419610},{"atb":[[16,17.8],[44,4.65],[22,9.53]],"id":41419656},{"atb":[[8.6,35.13],[19,11.12],[11.5,19.06]],"id":41419623},{"atb":[[330,0.6],[180,1.11],[90,2.99]],"id":41419652},{"atb":[[36,5.71],[90,2.25],[23,12.13]],"id":41435528},{"atb":[[270,0.74],[120,1.68],[60,4.52]],"id":41419619},{"atb":[[520,0.38],[270,0.99],[370,0.54]],"id":41419586},{"atb":[[7.4,31.28],[5.2,47.67],[4.2,83.43]],"id":41419598},{"atb":[[34,8.08],[170,1.18],[60,3.39]],"id":41419660},{"atb":[[5.6,43.53],[4.6,74.16],[8.2,27.81]],"id":41419594},{"atb":[[5.8,55.62],[11.5,19.06],[7.6,30.34]],"id":41419607},{"atb":[[600,0.44],[700,0.28],[850,0.23]],"id":28546950},{"atb":[[17,12.51],[12,24.27],[29,7.14]],"id":41419636},{"atb":[[10.5,28.1],[26,8],[15.5,13.8]],"id":41419603},{"atb":[[520,0.38],[270,0.99],[370,0.54]],"id":41419615},{"atb":[[360,0.55],[210,0.95],[110,2.44]],"id":41419657},{"atb":[[40,5.13],[100,2.02],[25,11.12]],"id":41419624},{"atb":[[270,0.74],[120,1.68],[60,4.52]],"id":41419591},{"atb":[[75,2.7],[40,6.84],[200,1]],"id":41435525},{"atb":[[600,0.44],[700,0.28],[850,0.23]],"id":41419653},{"atb":[[40,5.13],[100,2.02],[25,11.12]],"id":41419620},{"atb":[[350,0.57],[200,1],[100,2.69]],"id":41419587},{"atb":[[320,0.62],[220,1.21],[470,0.42]],"id":41419599},{"atb":[[36,5.71],[19,11.12],[14,20.53]],"id":41419595},{"atb":[[36,5.71],[19,11.12],[14,20.53]],"id":41419608},{"atb":[[10.5,28.1],[26,8],[15.5,13.8]],"id":41419637},{"atb":[[350,0.57],[200,1],[100,2.69]],"id":41419616},{"atb":[[10.5,28.1],[26,8],[15.5,13.8]],"id":41419612},{"atb":[[36,5.71],[19,11.12],[14,20.53]],"id":41419592},{"atb":[[70,2.9],[19.5,14.43],[29,7.14]],"id":41435526},{"atb":[[7.2,32.29],[5.1,48.83],[4.1,86.12]],"id":41419621},{"atb":[[600,0.44],[700,0.28],[850,0.23]],"id":41419588},{"atb":[[7.2,43.06],[9.2,24.42],[15.5,13.8]],"id":41419600},{"atb":[[5.3,46.56],[3.4,111.24],[3.9,69.04]],"id":41419596},{"atb":[[600,0.44],[700,0.28],[850,0.23]],"id":41419658}],"con":true,"img":true}]}
{"op":"mcm","clk":"5347381217","pt":1646198202724,"mc":[{"id":"1.195453723","marketDefinition":{"bspMarket":false,"turnInPlayEnabled":false,"persistenceEnabled":false,"marketBaseRate":7.0,"eventId":"31272494","eventTypeId":"4339","numberOfWinners":1,"bettingType":"ODDS","marketType":"EXACTA","marketTime":"2022-03-02T10:11:00.000Z","suspendTime":"2022-03-02T10:11:00.000Z","bspReconciled":false,"complete":true,"inPlay":false,"crossMatching":false,"runnersVoidable":false,"numberOfActiveRunners":56,"betDelay":0,"status":"OPEN","runners":[{"status":"ACTIVE","sortPriority":1,"id":41419585,"name":"1 - 2"},{"status":"ACTIVE","sortPriority":2,"id":41419586,"name":"1 - 3"},{"status":"ACTIVE","sortPriority":3,"id":41419587,"name":"1 - 4"},{"status":"ACTIVE","sortPriority":4,"id":41419588,"name":"1 - 5"},{"status":"ACTIVE","sortPriority":5,"id":41419589,"name":"1 - 6"},{"status":"ACTIVE","sortPriority":6,"id":41419591,"name":"1 - 8"},{"status":"ACTIVE","sortPriority":7,"id":28546943,"name":"1 - 9"},{"status":"ACTIVE","sortPriority":8,"id":41419592,"name":"2 - 1"},{"status":"ACTIVE","sortPriority":9,"id":41419593,"name":"2 - 3"},{"status":"ACTIVE","sortPriority":10,"id":41419594,"name":"2 - 4"},{"status":"ACTIVE","sortPriority":11,"id":41419595,"name":"2 - 5"},{"status":"ACTIVE","sortPriority":12,"id":41419596,"name":"2 - 6"},{"status":"ACTIVE","sortPriority":13,"id":41419598,"name":"2 - 8"},{"status":"ACTIVE","sortPriority":14,"id":41419651,"name":"2 - 9"},{"status":"ACTIVE","sortPriority":15,"id":41419599,"name":"3 - 1"},{"status":"ACTIVE","sortPriority":16,"id":41419600,"name":"3 - 2"},{"status":"ACTIVE","sortPriority":17,"id":41419601,"name":"3 - 4"},{"status":"ACTIVE","sortPriority":18,"id":41419602,"name":"3 - 5"},{"status":"ACTIVE","sortPriority":19,"id":41419603,"name":"3 - 6"},{"status":"ACTIVE","sortPriority":20,"id":41419605,"name":"3 - 8"},{"status":"ACTIVE","sortPriority":21,"id":41419652,"name":"3 - 9"},{"status":"ACTIVE","sortPriority":22,"id":41419606,"name":"4 - 1"},{"status":"ACTIVE","sortPriority":23,"id":41419607,"name":"4 - 2"},{"status":"ACTIVE","sortPriority":24,"id":41419608,"name":"4 - 3"},{"status":"ACTIVE","sortPriority":25,"id":41419609,"name":"4 - 5"},{"status":"ACTIVE","sortPriority":26,"id":41419610,"name":"4 - 6"},{"status":"ACTIVE","sortPriority":27,"id":41419612,"name":"4 - 8"},{"status":"ACTIVE","sortPriority":28,"id":41435525,"name":"4 - 9"},{"status":"ACTIVE","sortPriority":29,"id":41419613,"name":"5 - 1"},{"status":"ACTIVE","sortPriority":30,"id":41419614,"name":"5 - 2"},{"status":"ACTIVE","sortPriority":31,"id":41419615,"name":"5 - 3"},{"status":"ACTIVE","sortPriority":32,"id":41419616,"name":"5 - 4"},{"status":"ACTIVE","sortPriority":33,"id":41419617,"name":"5 - 6"},{"status":"ACTIVE","sortPriority":34,"id":41419619,"name":"5 - 8"},{"status":"ACTIVE","sortPriority":35,"id":41419653,"name":"5 - 9"},{"status":"ACTIVE","sortPriority":36,"id":41419620,"name":"6 - 1"},{"status":"ACTIVE","sortPriority":37,"id":41419621,"name":"6 - 2"},{"status":"ACTIVE","sortPriority":38,"id":41419622,"name":"6 - 3"},{"status":"ACTIVE","sortPriority":39,"id":41419623,"name":"6 - 4"},{"status":"ACTIVE","sortPriority":40,"id":41419624,"name":"6 - 5"},{"status":"ACTIVE","sortPriority":41,"id":41419626,"name":"6 - 8"},{"status":"ACTIVE","sortPriority":42,"id":41435526,"name":"6 - 9"},{"status":"ACTIVE","sortPriority":43,"id":41419634,"name":"8 - 1"},{"status":"ACTIVE","sortPriority":44,"id":41419635,"name":"8 - 2"},{"status":"ACTIVE","sortPriority":45,"id":41419636,"name":"8 - 3"},{"status":"ACTIVE","sortPriority":46,"id":41419637,"name":"8 - 4"},{"status":"ACTIVE","sortPriority":47,"id":41419638,"name":"8 - 5"},{"status":"ACTIVE","sortPriority":48,"id":41419639,"name":"8 - 6"},{"status":"ACTIVE","sortPriority":49,"id":41419655,"name":"8 - 9"},{"status":"ACTIVE","sortPriority":50,"id":28546950,"name":"9 - 1"},{"status":"ACTIVE","sortPriority":51,"id":41419656,"name":"9 - 2"},{"status":"ACTIVE","sortPriority":52,"id":41419657,"name":"9 - 3"},{"status":"ACTIVE","sortPriority":53,"id":41435527,"name":"9 - 4"},{"status":"ACTIVE","sortPriority":54,"id":41419658,"name":"9 - 5"},{"status":"ACTIVE","sortPriority":55,"id":41435528,"name":"9 - 6"},{"status":"ACTIVE","sortPriority":56,"id":41419660,"name":"9 - 8"}],"regulators":["MR_INT"],"venue":"Traralgon","countryCode":"AU","discountAllowed":true,"timezone":"Australia/Sydney","openDate":"2022-03-02T08:31:00.000Z","version":4382480625,"name":"Exacta","eventName":"Traralgon (AUS) 2nd Mar"},"rc":[{"atb":[[300,0.67],[150,1.34],[75,3.6]],"id":41419609},{"atb":[[85,2.38],[44,6.2],[220,0.91]],"id":41419638},{"atb":[[17.5,12.13],[12.5,23.2],[30,6.9]],"id":41419605},{"atb":[[85,2.38],[44,6.2],[220,0.91]],"id":41419634},{"atb":[[150,1.34],[50,4.08],[30,9.2]],"id":41419617},{"atb":[[600,0.44],[700,0.28],[850,0.23]],"id":41419613},{"atb":[[6.8,34.51],[9.8,22.74],[5.4,60.65]],"id":41419593},{"atb":[[130,1.55],[46,4.44],[28,9.88]],"id":41419655},{"atb":[[24,8.7],[9.8,30.33],[14.5,14.82]],"id":41419622},{"atb":[[150,1.34],[50,4.08],[30,9.2]],"id":41419589},{"atb":[[90,2.24],[46,5.92],[230,0.87]],"id":41435527},{"atb":[[17,12.5],[12,24.26],[29,7.14]],"id":41419651},{"atb":[[36,5.71],[19,11.12],[14,20.52]],"id":41419601},{"atb":[[600,0.44],[700,0.28],[850,0.23]],"id":28546943},{"atb":[[8,38.12],[17.5,12.13],[10,22.23]],"id":41419626},{"atb":[[18,11.77],[10.5,21.07],[8.2,37.06]],"id":41419639},{"atb":[[300,0.67],[150,1.34],[75,3.6]],"id":41419606},{"atb":[[5.1,65.09],[9.2,24.41],[6.2,38.49]],"id":41419635},{"atb":[[320,0.62],[220,1.21],[470,0.42]],"id":41419602},{"atb":[[17.5,16.17],[50,4.08],[25,8.33]],"id":41419585},{"atb":[[17.5,16.17],[50,4.08],[25,8.33]],"id":41419614},{"atb":[[9,33.36],[20,10.53],[12.5,17.4]],"id":41419610},{"atb":[[16,17.79],[44,4.65],[22,9.53]],"id":41419656},{"atb":[[8.6,35.11],[19,11.12],[11.5,19.06]],"id":41419623},{"atb":[[330,0.6],[180,1.11],[90,2.99]],"id":41419652},{"atb":[[36,5.71],[90,2.24],[23,12.13]],"id":41435528},{"atb":[[270,0.74],[120,1.68],[60,4.52]],"id":41419619},{"atb":[[520,0.38],[270,0.99],[370,0.54]],"id":41419586},{"atb":[[7.4,31.27],[5.2,47.66],[4.2,83.4]],"id":41419598},{"atb":[[34,8.08],[170,1.18],[60,3.39]],"id":41419660},{"atb":[[5.6,43.51],[4.6,74.13],[8.2,27.8]],"id":41419594},{"atb":[[5.8,55.59],[11.5,19.06],[7.6,30.33]],"id":41419607},{"atb":[[600,0.44],[700,0.28],[850,0.23]],"id":28546950},{"atb":[[17,12.5],[12,24.26],[29,7.14]],"id":41419636},{"atb":[[10.5,28.09],[26,8],[15.5,13.8]],"id":41419603},{"atb":[[520,0.38],[270,0.99],[370,0.54]],"id":41419615},{"atb":[[360,0.55],[210,0.95],[110,2.44]],"id":41419657},{"atb":[[40,5.13],[100,2.02],[25,11.12]],"id":41419624},{"atb":[[270,0.74],[120,1.68],[60,4.52]],"id":41419591},{"atb":[[75,2.7],[40,6.84],[200,1]],"id":41435525},{"atb":[[600,0.44],[700,0.28],[850,0.23]],"id":41419653},{"atb":[[40,5.13],[100,2.02],[25,11.12]],"id":41419620},{"atb":[[350,0.57],[200,1],[100,2.69]],"id":41419587},{"atb":[[320,0.62],[220,1.21],[470,0.42]],"id":41419599},{"atb":[[36,5.71],[19,11.12],[14,20.52]],"id":41419595},{"atb":[[36,5.71],[19,11.12],[14,20.52]],"id":41419608},{"atb":[[10.5,28.09],[26,8],[15.5,13.8]],"id":41419637},{"atb":[[350,0.57],[200,1],[100,2.69]],"id":41419616},{"atb":[[10.5,28.09],[26,8],[15.5,13.8]],"id":41419612},{"atb":[[36,5.71],[19,11.12],[14,20.52]],"id":41419592},{"atb":[[70,2.89],[19.5,14.42],[29,7.14]],"id":41435526},{"atb":[[7.2,32.28],[5.1,48.81],[4.1,86.09]],"id":41419621},{"atb":[[600,0.44],[700,0.28],[850,0.23]],"id":41419588},{"atb":[[7.2,43.04],[9.2,24.41],[15.5,13.8]],"id":41419600},{"atb":[[5.3,46.55],[3.4,111.2],[3.9,69.01]],"id":41419596},{"atb":[[600,0.44],[700,0.28],[850,0.23]],"id":41419658}],"con":true,"img":true}]}
{"op":"mcm","clk":"5347412425","pt":1646198874699,"mc":[{"id":"1.195453723","rc":[{"atb":[[300,0.67],[150,1.34],[75,3.6]],"id":41419609},{"atb":[[85,2.38],[44,6.2],[220,0.91]],"id":41419638},{"atb":[[17.5,0],[12.5,0],[30,0]],"id":41419605},{"atb":[[85,2.38],[44,6.2],[220,0.91]],"id":41419634},{"atb":[[150,1.34],[50,4.08],[30,9.2]],"id":41419617},{"atb":[[600,0.44],[700,0.28],[850,0.23]],"id":41419613},{"atb":[[6.8,0],[9.8,0],[5.4,0]],"id":41419593},{"atb":[[130,1.55],[46,4.44],[28,9.88]],"id":41419655},{"atb":[[24,8.7],[9.8,30.33],[14.5,14.82]],"id":41419622},{"atb":[[150,0],[50,0],[30,0]],"id":41419589},{"atb":[[90,2.24],[46,5.92],[230,0.87]],"id":41435527},{"atb":[[17,12.5],[12,24.26],[29,7.14]],"id":41419651},{"atb":[[36,0],[19,0],[14,0]],"id":41419601},{"atb":[[600,0],[700,0],[850,0]],"id":28546943},{"atb":[[8,38.12],[17.5,12.13],[10,22.23]],"id":41419626},{"atb":[[18,11.77],[10.5,21.07],[8.2,37.06]],"id":41419639},{"atb":[[300,0.67],[150,1.34],[75,3.6]],"id":41419606},{"atb":[[5.1,65.09],[9.2,24.41],[6.2,38.49]],"id":41419635},{"atb":[[320,0],[220,0],[470,0]],"id":41419602},{"atb":[[17.5,0],[50,0],[25,0]],"id":41419585},{"atb":[[17.5,16.17],[50,4.08],[25,8.33]],"id":41419614},{"atb":[[9,33.36],[20,10.53],[12.5,17.4]],"id":41419610},{"atb":[[16,17.79],[44,4.65],[22,9.53]],"id":41419656},{"atb":[[8.6,35.11],[19,11.12],[11.5,19.06]],"id":41419623},{"atb":[[330,0.6],[180,1.11],[90,2.99]],"id":41419652},{"atb":[[36,5.71],[90,2.24],[23,12.13]],"id":41435528},{"atb":[[270,0.74],[120,1.68],[60,4.52]],"id":41419619},{"atb":[[520,0],[270,0],[370,0]],"id":41419586},{"atb":[[7.4,0],[5.2,0],[4.2,0]],"id":41419598},{"atb":[[34,8.08],[170,1.18],[60,3.39]],"id":41419660},{"atb":[[5.6,0],[4.6,0],[8.2,0]],"id":41419594},{"atb":[[5.8,55.59],[11.5,19.06],[7.6,30.33]],"id":41419607},{"atb":[[600,0],[700,0],[850,0]],"id":28546950},{"atb":[[17,12.5],[12,24.26],[29,7.14]],"id":41419636},{"atb":[[10.5,0],[26,0],[15.5,0]],"id":41419603},{"atb":[[520,0.38],[270,0.99],[370,0.54]],"id":41419615},{"atb":[[360,0.55],[210,0.95],[110,2.44]],"id":41419657},{"atb":[[40,5.13],[100,2.02],[25,11.12]],"id":41419624},{"atb":[[270,0],[120,0],[60,0]],"id":41419591},{"atb":[[75,2.7],[40,6.84],[200,1]],"id":41435525},{"atb":[[600,0.44],[700,0.28],[850,0.23]],"id":41419653},{"atb":[[40,5.13],[100,2.02],[25,11.12]],"id":41419620},{"atb":[[350,0],[200,0],[100,0]],"id":41419587},{"atb":[[320,0],[220,0],[470,0]],"id":41419599},{"atb":[[36,0],[19,0],[14,0]],"id":41419595},{"atb":[[36,5.71],[19,11.12],[14,20.52]],"id":41419608},{"atb":[[10.5,28.09],[26,8],[15.5,13.8]],"id":41419637},{"atb":[[350,0.57],[200,1],[100,2.69]],"id":41419616},{"atb":[[10.5,28.09],[26,8],[15.5,13.8]],"id":41419612},{"atb":[[36,0],[19,0],[14,0]],"id":41419592},{"atb":[[70,2.89],[19.5,14.42],[29,7.14]],"id":41435526},{"atb":[[7.2,32.28],[5.1,48.81],[4.1,86.09]],"id":41419621},{"atb":[[600,0],[700,0],[850,0]],"id":41419588},{"atb":[[7.2,0],[9.2,0],[15.5,0]],"id":41419600},{"atb":[[5.3,0],[3.4,0],[3.9,0]],"id":41419596},{"atb":[[600,0.44],[700,0.28],[850,0.23]],"id":41419658}],"con":true,"img":false}]}
{"op":"mcm","clk":"5347412431","pt":1646198874753,"mc":[{"id":"1.195453723","rc":[{"atb":[[300,0],[150,0],[75,0]],"id":41419609},{"atb":[[85,0],[44,0],[220,0]],"id":41419634},{"atb":[[150,0],[50,0],[30,0]],"id":41419617},{"atb":[[600,0],[700,0],[850,0]],"id":41419613},{"atb":[[24,0],[9.8,0],[14.5,0]],"id":41419622},{"atb":[[8,0],[17.5,0],[10,0]],"id":41419626},{"atb":[[300,0],[150,0],[75,0]],"id":41419606},{"atb":[[5.1,0],[9.2,0],[6.2,0]],"id":41419635},{"atb":[[17.5,0],[50,0],[25,0]],"id":41419614},{"atb":[[9,0],[20,0],[12.5,0]],"id":41419610},{"atb":[[8.6,0],[19,0],[11.5,0]],"id":41419623},{"atb":[[270,0],[120,0],[60,0]],"id":41419619},{"atb":[[5.8,0],[11.5,0],[7.6,0]],"id":41419607},{"atb":[[520,0],[270,0],[370,0]],"id":41419615},{"atb":[[40,0],[100,0],[25,0]],"id":41419624},{"atb":[[40,0],[100,0],[25,0]],"id":41419620},{"atb":[[36,0],[19,0],[14,0]],"id":41419608},{"atb":[[350,0],[200,0],[100,0]],"id":41419616},{"atb":[[10.5,0],[26,0],[15.5,0]],"id":41419612},{"atb":[[7.2,0],[5.1,0],[4.1,0]],"id":41419621}],"con":true,"img":false}]}
{"op":"mcm","clk":"5347412434","pt":1646198874857,"mc":[{"id":"1.195453723","rc":[{"atb":[[85,0],[44,0],[220,0]],"id":41419638},{"atb":[[130,0],[46,0],[28,0]],"id":41419655},{"atb":[[90,0],[46,0],[230,0]],"id":41435527},{"atb":[[17,0],[12,0],[29,0]],"id":41419651},{"atb":[[18,0],[10.5,0],[8.2,0]],"id":41419639},{"atb":[[16,0],[44,0],[22,0]],"id":41419656},{"atb":[[330,0],[180,0],[90,0]],"id":41419652},{"atb":[[36,0],[90,0],[23,0]],"id":41435528},{"atb":[[34,0],[170,0],[60,0]],"id":41419660},{"atb":[[17,0],[12,0],[29,0]],"id":41419636},{"atb":[[360,0],[210,0],[110,0]],"id":41419657},{"atb":[[75,0],[40,0],[200,0]],"id":41435525},{"atb":[[600,0],[700,0],[850,0]],"id":41419653},{"atb":[[10.5,0],[26,0],[15.5,0]],"id":41419637},{"atb":[[70,0],[19.5,0],[29,0]],"id":41435526},{"atb":[[600,0],[700,0],[850,0]],"id":41419658}],"con":true,"img":false}]}
{"op":"mcm","clk":"5347413179","pt":1646198892203,"mc":[{"id":"1.195453723","rc":[{"atb":[[360,0.55],[210,0.95],[110,2.44]],"id":41419609},{"atb":[[75,2.7],[40,6.84],[200,1]],"id":41419638},{"atb":[[36,5.71],[19,11.12],[14,20.52]],"id":41419605},{"atb":[[75,2.7],[40,6.84],[200,1]],"id":41419634},{"atb":[[140,1.44],[48,4.25],[29,9.53]],"id":41419617},{"atb":[[600,0.44],[700,0.28],[850,0.23]],"id":41419613},{"atb":[[6.8,34.51],[9.8,22.74],[5.4,60.65]],"id":41419593},{"atb":[[44,4.65],[27,10.26],[120,1.68]],"id":41419655},{"atb":[[10.5,28.09],[26,8],[15.5,13.8]],"id":41419622},{"atb":[[140,1.44],[48,4.25],[29,9.53]],"id":41419589},{"atb":[[270,0.74],[120,1.68],[60,4.52]],"id":41435527},{"atb":[[16,13.34],[11,26.68],[27,7.69]],"id":41419651},{"atb":[[16,17.79],[44,4.65],[22,9.53]],"id":41419601},{"atb":[[600,0.44],[700,0.28],[850,0.23]],"id":28546943},{"atb":[[18,11.77],[10.5,21.07],[8.2,37.06]],"id":41419626},{"atb":[[18.5,11.43],[11,20.01],[8.4,36.06]],"id":41419639},{"atb":[[360,0.55],[210,0.95],[110,2.44]],"id":41419606},{"atb":[[9,25.01],[5,66.72],[6,40.03]],"id":41419635},{"atb":[[260,1.03],[360,0.55],[510,0.39]],"id":41419602},{"atb":[[16.5,17.22],[46,4.44],[23,9.09]],"id":41419585},{"atb":[[16.5,17.22],[46,4.44],[23,9.09]],"id":41419614},{"atb":[[24,8.7],[9.8,30.33],[14.5,14.82]],"id":41419610},{"atb":[[40,5.13],[20,10.53],[15,19.06]],"id":41419656},{"atb":[[9.2,32.54],[21,10],[13,16.68]],"id":41419623},{"atb":[[350,0.57],[200,1],[100,2.69]],"id":41419652},{"atb":[[34,6.06],[85,2.38],[22,12.71]],"id":41435528},{"atb":[[100,2.02],[50,5.44],[250,0.8]],"id":41419619},{"atb":[[550,0.36],[300,0.88],[400,0.5]],"id":41419586},{"atb":[[4.8,52.67],[6.6,35.74],[3.9,92.02]],"id":41419598},{"atb":[[32,8.61],[160,1.26],[55,3.7]],"id":41419660},{"atb":[[5.7,42.58],[8.4,27.04],[4.7,72.13]],"id":41419594},{"atb":[[6.4,49.42],[13.5,16.01],[8.4,27.04]],"id":41419607},{"atb":[[600,0.44],[700,0.28],[850,0.23]],"id":28546950},{"atb":[[32,6.45],[18,11.77],[13,22.23]],"id":41419636},{"atb":[[16.5,12.91],[11.5,25.41],[28,7.41]],"id":41419603},{"atb":[[550,0.36],[300,0.88],[400,0.5]],"id":41419615},{"atb":[[130,2.06],[380,0.52],[230,0.87]],"id":41419657},{"atb":[[38,5.41],[95,2.12],[24,11.6]],"id":41419624},{"atb":[[100,2.02],[50,5.44],[250,0.8]],"id":41419591},{"atb":[[95,2.12],[48,5.67],[240,0.83]],"id":41435525},{"atb":[[600,0.44],[700,0.28],[850,0.23]],"id":41419653},{"atb":[[38,5.41],[95,2.12],[24,11.6]],"id":41419620},{"atb":[[150,1.79],[400,0.5],[250,0.8]],"id":41419587},{"atb":[[260,1.03],[360,0.55],[510,0.39]],"id":41419599},{"atb":[[17.5,12.13],[12.5,23.2],[30,6.9]],"id":41419595},{"atb":[[16,17.79],[44,4.65],[22,9.53]],"id":41419608},{"atb":[[16.5,12.91],[11.5,25.41],[28,7.41]],"id":41419637},{"atb":[[150,1.79],[400,0.5],[250,0.8]],"id":41419616},{"atb":[[17,12.5],[12,24.26],[29,7.14]],"id":41419612},{"atb":[[17.5,12.13],[12.5,23.2],[30,6.9]],"id":41419592},{"atb":[[65,3.12],[19,14.82],[28,7.41]],"id":41435526},{"atb":[[3.95,90.46],[6.8,34.51],[4.9,51.32]],"id":41419621},{"atb":[[600,0.44],[700,0.28],[850,0.23]],"id":41419588},{"atb":[[16.5,12.91],[9.6,23.27],[7.6,40.43]],"id":41419600},{"atb":[[5,50.04],[3.25,118.61],[3.75,72.78]],"id":41419596},{"atb":[[600,0.44],[700,0.28],[850,0.23]],"id":41419658}],"con":true,"img":false}]}
{"op":"mcm","clk":"5347825026","pt":1646208660453,"mc":[{"id":"1.195453723","rc":[{"atb":[[85,2.72],[360,0.55],[210,0.95],[110,2.44],[60,3.27]],"id":41419609},{"atb":[[65,2.72],[75,2.7],[40,6.83],[46,3.27],[200,1]],"id":41419638},{"atb":[[36,5.71],[19,11.11],[40,2.72],[14,20.52],[30,3.27]],"id":41419605},{"atb":[[75,2.7],[40,6.83],[44,3.27],[200,1],[60,2.72]],"id":41419634},{"atb":[[140,1.44],[80,3.27],[48,4.25],[110,2.72],[29,9.53]],"id":41419617},{"atb":[[600,0.44],[290,2.72],[240,3.27]],"id":41419613},{"atb":[[6.8,34.5],[9.8,22.74],[8.8,2.72],[7.8,3.27],[5.4,60.63]],"id":41419593},{"atb":[[70,2.72],[44,4.65],[48,3.27],[27,10.26],[120,1.68]],"id":41419655},{"atb":[[10.5,28.08],[23,3.27],[26,8],[28,2.72],[15.5,13.79]],"id":41419622},{"atb":[[140,1.44],[75,3.27],[48,4.25],[100,2.72],[29,9.53]],"id":41419589},{"atb":[[270,0.74],[170,2.72],[120,4.95],[60,4.51]],"id":41435527},{"atb":[[16,13.34],[11,26.68],[24,3.27],[27,7.69],[29,2.72]],"id":41419651},{"atb":[[16,17.78],[38,3.27],[44,4.65],[22,9.53],[48,2.72]],"id":41419601},{"atb":[[600,0.44],[300,2.72],[250,3.27]],"id":28546943},{"atb":[[17,3.27],[18,11.76],[19.5,2.72],[10.5,21.06],[8.2,37.05]],"id":41419626},{"atb":[[18.5,14.71],[11,20.01],[22,2.72],[8.4,36.05]],"id":41419639},{"atb":[[75,2.72],[360,0.55],[50,3.27],[210,0.95],[110,2.44]],"id":41419606},{"atb":[[9,25.01],[5,66.7],[10.5,3.27],[6,40.02],[13,2.72]],"id":41419635},{"atb":[[260,1.03],[80,3.27],[360,0.55],[110,2.72],[510,0.39]],"id":41419602},{"atb":[[16.5,17.21],[70,2.72],[46,4.44],[23,9.09],[48,3.27]],"id":41419585},{"atb":[[16.5,17.21],[80,2.72],[46,4.44],[23,9.09],[55,3.27]],"id":41419614},{"atb":[[24,11.97],[9.8,30.32],[14.5,14.82],[29,2.72]],"id":41419610},{"atb":[[65,3.27],[40,5.13],[20,10.52],[90,2.72],[15,19.05]],"id":41419656},{"atb":[[19.5,3.27],[9.2,32.53],[21,10],[24,2.72],[13,16.67]],"id":41419623},{"atb":[[350,0.57],[85,3.27],[200,1],[100,2.69],[120,2.72]],"id":41419652},{"atb":[[130,2.72],[34,6.06],[85,2.37],[22,12.7],[90,3.27]],"id":41435528},{"atb":[[85,3.27],[100,2.01],[50,5.44],[120,2.72],[250,0.8]],"id":41419619},{"atb":[[140,2.72],[300,0.88],[95,3.27],[400,0.5]],"id":41419586},{"atb":[[4.8,52.65],[6,3.27],[6.6,35.73],[3.9,92],[7,2.72]],"id":41419598},{"atb":[[32,8.6],[140,2.72],[160,1.26],[95,3.27],[55,3.7]],"id":41419660},{"atb":[[5.7,42.57],[8.8,2.72],[7.8,3.27],[8.4,27.04],[4.7,72.11]],"id":41419594},{"atb":[[16,3.27],[18.5,2.72],[6.4,49.41],[13.5,16],[8.4,27.04]],"id":41419607},{"atb":[[280,3.27],[600,0.44],[330,2.72]],"id":28546950},{"atb":[[32,9.18],[18,11.76],[13,22.23],[26,3.27]],"id":41419636},{"atb":[[16.5,12.9],[38,2.72],[11.5,25.4],[28,7.41],[29,3.27]],"id":41419603},{"atb":[[300,0.88],[160,2.72],[400,0.5],[110,3.27]],"id":41419615},{"atb":[[130,2.06],[380,0.52],[230,0.87]],"id":41419657},{"atb":[[38,5.4],[42,3.27],[95,2.12],[24,11.59],[55,2.72]],"id":41419624},{"atb":[[80,3.27],[100,2.01],[50,5.44],[110,2.72],[250,0.8]],"id":41419591},{"atb":[[65,3.27],[90,2.72],[95,2.12],[48,5.67],[240,0.83]],"id":41435525},{"atb":[[600,0.44],[290,3.27],[340,2.72]],"id":41419653},{"atb":[[38,5.4],[40,3.27],[95,2.12],[24,11.59],[50,2.72]],"id":41419620},{"atb":[[130,2.72],[150,1.79],[90,3.27],[400,0.5],[250,0.8]],"id":41419587},{"atb":[[260,1.03],[70,3.27],[360,0.55],[95,2.72],[510,0.39]],"id":41419599},{"atb":[[17.5,12.12],[21,3.27],[12.5,23.19],[26,2.72],[30,6.89]],"id":41419595},{"atb":[[16,17.78],[32,3.27],[42,2.72],[44,4.65],[22,9.53]],"id":41419608},{"atb":[[16.5,12.9],[11.5,25.4],[23,3.27],[28,10.14]],"id":41419637},{"atb":[[140,2.72],[150,1.79],[95,3.27],[400,0.5],[250,0.8]],"id":41419616},{"atb":[[32,2.72],[17,12.5],[12,24.25],[26,3.27],[29,7.14]],"id":41419612},{"atb":[[17.5,12.12],[12.5,23.19],[30,6.89]],"id":41419592},{"atb":[[65,3.12],[19,14.82],[44,3.27],[28,7.41],[60,2.72]],"id":41435526},{"atb":[[9.2,3.27],[3.95,90.44],[10.5,2.72],[6.8,34.5],[4.9,51.31]],"id":41419621},{"atb":[[600,0.44]],"id":41419588},{"atb":[[16.5,12.9],[9.6,23.26],[21,3.27],[7.6,40.42],[26,2.72]],"id":41419600},{"atb":[[5.6,3.27],[5,50.02],[6.2,2.72],[3.25,118.58],[3.75,72.76]],"id":41419596},{"atb":[[600,0.44],[310,3.27],[360,2.72]],"id":41419658}],"con":true,"img":false}]}
{"op":"mcm","clk":"5347825030","pt":1646208660512,"mc":[{"id":"1.195453723","rc":[{"atb":[[140,3.27],[190,2.72]],"id":41419657},{"atb":[[19.5,3.27],[24,2.72]],"id":41419592},{"atb":[[270,2.72],[220,3.27]],"id":41419588}],"con":true,"img":false}]}
{"op":"mcm","clk":"5347827793","pt":1646208723703,"mc":[{"id":"1.195453723","rc":[{"atb":[[8.8,0],[7.8,0]],"id":41419593}],"con":true,"img":false}]}
{"op":"mcm","clk":"5347827854","pt":1646208724623,"mc":[{"id":"1.195453723","rc":[{"atb":[[8.6,2.72],[7.6,3.27]],"id":41419593}],"con":true,"img":false}]}
{"op":"mcm","clk":"5347828707","pt":1646208742631,"mc":[{"id":"1.195453723","rc":[{"atb":[[36,0],[19,0],[14,0]],"id":41419605},{"atb":[[6.8,0],[9.8,0],[5.4,0]],"id":41419593},{"atb":[[140,0],[48,0],[29,0]],"id":41419589},{"atb":[[16,0],[44,0],[22,0]],"id":41419601},{"atb":[[600,0],[700,0],[850,0]],"id":28546943},{"atb":[[260,0],[360,0],[510,0]],"id":41419602},{"atb":[[16.5,0],[46,0],[23,0]],"id":41419585},{"atb":[[550,0],[300,0],[400,0]],"id":41419586},{"atb":[[4.8,0],[6.6,0],[3.9,0]],"id":41419598},{"atb":[[5.7,0],[8.4,0],[4.7,0]],"id":41419594},{"atb":[[600,0],[700,0],[850,0]],"id":28546950},{"atb":[[16.5,0],[11.5,0],[28,0]],"id":41419603},{"atb":[[100,0],[50,0],[250,0]],"id":41419591},{"atb":[[150,0],[400,0],[250,0]],"id":41419587},{"atb":[[260,0],[360,0],[510,0]],"id":41419599},{"atb":[[17.5,0],[12.5,0],[30,0]],"id":41419595},{"atb":[[17.5,0],[12.5,0],[30,0]],"id":41419592},{"atb":[[600,0],[700,0],[850,0]],"id":41419588},{"atb":[[16.5,0],[9.6,0],[7.6,0]],"id":41419600},{"atb":[[5,0],[3.25,0],[3.75,0]],"id":41419596}],"con":true,"img":false}]}
{"op":"mcm","clk":"5347828718","pt":1646208742843,"mc":[{"id":"1.195453723","rc":[{"atb":[[360,0],[210,0],[110,0]],"id":41419609},{"atb":[[75,0],[40,0],[200,0]],"id":41419634},{"atb":[[140,0],[48,0],[29,0]],"id":41419617},{"atb":[[600,0],[700,0],[850,0]],"id":41419613},{"atb":[[10.5,0],[26,0],[15.5,0]],"id":41419622},{"atb":[[18,0],[10.5,0],[8.2,0]],"id":41419626},{"atb":[[360,0],[210,0],[110,0]],"id":41419606},{"atb":[[9,0],[5,0],[6,0]],"id":41419635},{"atb":[[16.5,0],[46,0],[23,0]],"id":41419614},{"atb":[[24,3.27],[9.8,0],[14.5,0]],"id":41419610},{"atb":[[9.2,0],[21,0],[13,0]],"id":41419623},{"atb":[[100,0],[50,0],[250,0]],"id":41419619},{"atb":[[6.4,0],[13.5,0],[8.4,0]],"id":41419607},{"atb":[[550,0],[300,0],[400,0]],"id":41419615},{"atb":[[38,0],[95,0],[24,0]],"id":41419624},{"atb":[[38,0],[95,0],[24,0]],"id":41419620},{"atb":[[16,0],[44,0],[22,0]],"id":41419608},{"atb":[[150,0],[400,0],[250,0]],"id":41419616},{"atb":[[17,0],[12,0],[29,0]],"id":41419612},{"atb":[[3.95,0],[6.8,0],[4.9,0]],"id":41419621}],"con":true,"img":false}]}
{"op":"mcm","clk":"5347828722","pt":1646208742941,"mc":[{"id":"1.195453723","rc":[{"atb":[[75,0],[40,0],[200,0]],"id":41419638},{"atb":[[44,0],[27,0],[120,0]],"id":41419655},{"atb":[[270,0],[120,3.27],[60,0]],"id":41435527},{"atb":[[16,0],[11,0],[27,0]],"id":41419651},{"atb":[[18.5,3.27],[11,0],[8.4,0]],"id":41419639},{"atb":[[40,0],[20,0],[15,0]],"id":41419656},{"atb":[[350,0],[200,0],[100,0]],"id":41419652},{"atb":[[34,0],[85,0],[22,0]],"id":41435528},{"atb":[[32,0],[160,0],[55,0]],"id":41419660},{"atb":[[32,2.72],[18,0],[13,0]],"id":41419636},{"atb":[[130,0],[380,0],[230,0]],"id":41419657},{"atb":[[95,0],[48,0],[240,0]],"id":41435525},{"atb":[[600,0],[700,0],[850,0]],"id":41419653},{"atb":[[16.5,0],[11.5,0],[28,2.72]],"id":41419637},{"atb":[[65,0],[19,0],[28,0]],"id":41435526},{"atb":[[600,0],[700,0],[850,0]],"id":41419658}],"con":true,"img":false}]}
{"op":"mcm","clk":"5347829392","pt":1646208757342,"mc":[{"id":"1.195453723","rc":[{"atb":[[360,0.55],[210,0.95],[110,2.44]],"id":41419609},{"atb":[[80,2.53],[42,6.5],[210,0.95]],"id":41419638},{"atb":[[36,5.71],[19,11.11],[14,20.52]],"id":41419605},{"atb":[[80,2.53],[42,6.5],[210,0.95]],"id":41419634},{"atb":[[130,1.55],[46,4.44],[28,9.87]],"id":41419617},{"atb":[[600,0.44],[700,0.28],[850,0.23]],"id":41419613},{"atb":[[6.8,34.5],[9.8,22.74],[5.4,60.63]],"id":41419593},{"atb":[[44,4.65],[27,10.26],[120,1.68]],"id":41419655},{"atb":[[10.5,28.08],[26,8],[15.5,13.79]],"id":41419622},{"atb":[[130,1.55],[46,4.44],[28,9.87]],"id":41419589},{"atb":[[130,1.55],[65,4.17],[280,0.71]],"id":41435527},{"atb":[[16,13.34],[11,26.68],[27,7.69]],"id":41419651},{"atb":[[16,17.78],[44,4.65],[22,9.53]],"id":41419601},{"atb":[[600,0.44],[700,0.28],[850,0.23]],"id":28546943},{"atb":[[8,38.11],[17.5,12.12],[10,22.23]],"id":41419626},{"atb":[[18,11.76],[10.5,21.06],[8.2,37.05]],"id":41419639},{"atb":[[360,0.55],[210,0.95],[110,2.44]],"id":41419606},{"atb":[[9,25.01],[5,66.7],[6,40.02]],"id":41419635},{"atb":[[260,1.03],[360,0.55],[510,0.39]],"id":41419602},{"atb":[[16.5,17.21],[46,4.44],[23,9.09]],"id":41419585},{"atb":[[16.5,17.21],[46,4.44],[23,9.09]],"id":41419614},{"atb":[[24,11.97],[9.8,30.32],[14.5,14.82]],"id":41419610},{"atb":[[40,5.13],[20,10.52],[15,19.05]],"id":41419656},{"atb":[[9.2,32.53],[21,10],[13,16.67]],"id":41419623},{"atb":[[360,0.55],[210,0.95],[110,2.44]],"id":41419652},{"atb":[[34,6.06],[85,2.37],[22,12.7]],"id":41435528},{"atb":[[260,0.77],[110,1.83],[55,4.93]],"id":41419619},{"atb":[[560,0.36],[310,0.86],[410,0.49]],"id":41419586},{"atb":[[3.95,90.44],[6.8,34.5],[4.9,51.31]],"id":41419598},{"atb":[[32,8.6],[160,1.26],[55,3.7]],"id":41419660},{"atb":[[5.7,42.57],[8.4,27.04],[4.7,72.11]],"id":41419594},{"atb":[[6.4,49.41],[13.5,16],[8.4,27.04]],"id":41419607},{"atb":[[600,0.44],[700,0.28],[850,0.23]],"id":28546950},{"atb":[[34,6.06],[18.5,11.43],[13.5,21.34]],"id":41419636},{"atb":[[16,13.34],[11,26.68],[27,7.69]],"id":41419603},{"atb":[[560,0.36],[310,0.86],[410,0.49]],"id":41419615},{"atb":[[140,5.19],[390,0.51],[240,0.83]],"id":41419657},{"atb":[[36,5.71],[90,2.24],[23,12.12]],"id":41419624},{"atb":[[260,0.77],[110,4.56],[55,4.93]],"id":41419591},{"atb":[[95,2.12],[48,5.67],[240,0.83]],"id":41435525},{"atb":[[600,0.44],[700,0.28],[850,0.23]],"id":41419653},{"atb":[[36,5.71],[90,2.24],[23,12.12]],"id":41419620},{"atb":[[260,0.77],[160,1.67],[410,0.49]],"id":41419587},{"atb":[[260,1.03],[360,0.55],[510,0.39]],"id":41419599},{"atb":[[17.5,12.12],[12.5,23.19],[30,6.89]],"id":41419595},{"atb":[[16,17.78],[44,4.65],[22,9.53]],"id":41419608},{"atb":[[16.5,12.9],[11.5,25.4],[28,10.14]],"id":41419637},{"atb":[[260,0.77],[160,1.67],[410,0.49]],"id":41419616},{"atb":[[17,12.5],[12,24.25],[29,7.14]],"id":41419612},{"atb":[[17.5,12.12],[12.5,23.19],[30,6.89]],"id":41419592},{"atb":[[65,3.12],[19,14.82],[28,7.41]],"id":41435526},{"atb":[[4.8,52.65],[6.6,35.73],[3.9,92]],"id":41419621},{"atb":[[600,0.44],[700,0.28],[850,0.23]],"id":41419588},{"atb":[[16.5,12.9],[9.6,23.26],[7.6,40.42]],"id":41419600},{"atb":[[3.2,121.27],[3.7,74.11],[4.9,51.31]],"id":41419596},{"atb":[[600,0.44],[700,0.28],[850,0.23]],"id":41419658}],"con":true,"img":false}]}
{"op":"mcm","clk":"5347903377","pt":1646210055173,"mc":[{"id":"1.195453723","rc":[{"atb":[[8.6,0],[7.6,0]],"id":41419593}],"con":true,"img":false}]}
{"op":"mcm","clk":"5347903413","pt":1646210055849,"mc":[{"id":"1.195453723","rc":[{"atb":[[8.8,2.72],[7.8,3.27]],"id":41419593}],"con":true,"img":false}]}
{"op":"mcm","clk":"5347904114","pt":1646210073499,"mc":[{"id":"1.195453723","rc":[{"atb":[[8.8,0],[7.8,0]],"id":41419593}],"con":true,"img":false}]}
{"op":"mcm","clk":"5347904137","pt":1646210074167,"mc":[{"id":"1.195453723","rc":[{"atb":[[8.6,2.72],[7.6,3.27]],"id":41419593}],"con":true,"img":false}]}
{"op":"mcm","clk":"5347922516","pt":1646210541995,"mc":[{"id":"1.195453723","rc":[{"atb":[[9.2,0],[10.5,0]],"id":41419621}],"con":true,"img":false}]}
{"op":"mcm","clk":"5347922546","pt":1646210542713,"mc":[{"id":"1.195453723","rc":[{"atb":[[9,3.27],[10,2.72]],"id":41419621}],"con":true,"img":false}]}
{"op":"mcm","clk":"5347956434","pt":1646211255200,"mc":[{"id":"1.195453723","rc":[{"atb":[[8.6,0],[7.6,0]],"id":41419593}],"con":true,"img":false}]}
{"op":"mcm","clk":"5347956473","pt":1646211255870,"mc":[{"id":"1.195453723","rc":[{"atb":[[8.8,2.72],[7.8,3.27]],"id":41419593}],"con":true,"img":false}]}
{"op":"mcm","clk":"5347957451","pt":1646211273397,"mc":[{"id":"1.195453723","rc":[{"atb":[[8.8,0],[7.8,0]],"id":41419593}],"con":true,"img":false}]}
{"op":"mcm","clk":"5347957481","pt":1646211274117,"mc":[{"id":"1.195453723","rc":[{"atb":[[8.6,2.72],[7.6,3.27]],"id":41419593}],"con":true,"img":false}]}
{"op":"mcm","clk":"5347979117","pt":1646211738453,"mc":[{"id":"1.195453723","rc":[{"atb":[[85,2.72],[360,0.55],[210,0.95],[110,2.44],[60,3.26]],"id":41419609},{"atb":[[65,2.72],[80,2.52],[42,6.49],[46,3.26],[210,0.95]],"id":41419638},{"atb":[[36,5.7],[19,11.1],[40,2.72],[14,20.49],[30,3.26]],"id":41419605},{"atb":[[80,2.52],[42,6.49],[44,3.26],[210,0.95],[60,2.72]],"id":41419634},{"atb":[[130,1.54],[80,3.26],[46,4.44],[110,2.72],[28,9.86]],"id":41419617},{"atb":[[600,0.44],[290,2.72],[700,0.28],[850,0.23],[240,3.26]],"id":41419613},{"atb":[[8.6,2.72],[7.6,0],[6.8,34.44],[9.8,22.7],[5.4,60.54]],"id":41419593},{"atb":[[70,2.72],[44,4.64],[48,3.26],[27,10.24],[120,1.67]],"id":41419655},{"atb":[[10.5,28.03],[23,3.26],[26,7.98],[28,2.72],[15.5,13.77]],"id":41419622},{"atb":[[130,1.54],[75,3.26],[46,4.44],[100,2.72],[28,9.86]],"id":41419589},{"atb":[[130,1.54],[65,4.16],[280,0.71],[170,2.72],[120,3.26]],"id":41435527},{"atb":[[16,13.31],[11,26.63],[24,3.26],[27,7.68],[29,2.72]],"id":41419651},{"atb":[[16,17.76],[38,3.26],[44,4.64],[22,9.51],[48,2.72]],"id":41419601},{"atb":[[600,0.44],[300,2.72],[700,0.28],[850,0.23],[250,3.26]],"id":28546943},{"atb":[[8,38.05],[17.5,12.1],[17,3.26],[19.5,2.72],[10,22.19]],"id":41419626},{"atb":[[18.5,3.26],[18,11.74],[10.5,21.03],[22,2.72],[8.2,36.99]],"id":41419639},{"atb":[[75,2.72],[360,0.55],[50,3.26],[210,0.95],[110,2.44]],"id":41419606},{"atb":[[9,24.97],[5,66.59],[10.5,3.26],[6,39.95],[13,2.72]],"id":41419635},{"atb":[[260,1.03],[80,3.26],[360,0.55],[110,2.72],[510,0.39]],"id":41419602},{"atb":[[16.5,17.18],[70,2.72],[46,4.44],[23,9.07],[48,3.26]],"id":41419585},{"atb":[[16.5,17.18],[80,2.72],[46,4.44],[23,9.07],[55,3.26]],"id":41419614},{"atb":[[24,11.95],[9.8,30.27],[29,2.72],[14.5,14.8]],"id":41419610},{"atb":[[65,3.26],[40,5.12],[20,10.51],[90,2.72],[15,19.02]],"id":41419656},{"atb":[[19.5,3.26],[9.2,32.48],[21,9.98],[24,2.72],[13,16.64]],"id":41419623},{"atb":[[85,3.26],[360,0.55],[210,0.95],[110,2.44],[120,2.72]],"id":41419652},{"atb":[[130,2.72],[34,6.05],[85,2.37],[90,3.26],[22,12.68]],"id":41435528},{"atb":[[260,0.77],[85,3.26],[110,1.83],[55,4.93],[120,2.72]],"id":41419619},{"atb":[[560,0.35],[140,2.72],[310,0.86],[95,3.26],[410,0.49]],"id":41419586},{"atb":[[3.95,90.29],[6.8,34.44],[6,3.26],[4.9,51.22],[7,2.72]],"id":41419598},{"atb":[[32,8.59],[140,2.72],[160,1.25],[95,3.26],[55,3.7]],"id":41419660},{"atb":[[8.8,2.72],[5.7,42.5],[7.8,3.26],[8.4,26.99],[4.7,71.99]],"id":41419594},{"atb":[[16,3.26],[18.5,2.72],[6.4,49.33],[13.5,15.98],[8.4,26.99]],"id":41419607},{"atb":[[280,3.26],[600,0.44],[330,2.72],[700,0.28],[850,0.23]],"id":28546950},{"atb":[[32,2.72],[34,6.05],[18.5,11.41],[26,3.26],[13.5,21.3]],"id":41419636},{"atb":[[16,13.31],[38,2.72],[11,26.63],[27,7.68],[29,3.26]],"id":41419603},{"atb":[[560,0.35],[310,0.86],[160,2.72],[410,0.49],[110,3.26]],"id":41419615},{"atb":[[140,5.18],[190,2.72],[390,0.51],[240,0.83]],"id":41419657},{"atb":[[36,5.7],[42,3.26],[90,2.24],[23,12.1],[55,2.72]],"id":41419624},{"atb":[[260,0.77],[80,3.26],[110,4.55],[55,4.93]],"id":41419591},{"atb":[[65,3.26],[90,2.72],[95,2.12],[48,5.66],[240,0.83]],"id":41435525},{"atb":[[600,0.44],[290,3.26],[700,0.28],[340,2.72],[850,0.23]],"id":41419653},{"atb":[[36,5.7],[40,3.26],[90,2.24],[23,12.1],[50,2.72]],"id":41419620},{"atb":[[260,0.77],[130,2.72],[160,1.67],[90,3.26],[410,0.49]],"id":41419587},{"atb":[[260,1.03],[70,3.26],[360,0.55],[95,2.72],[510,0.39]],"id":41419599},{"atb":[[17.5,12.1],[21,3.26],[12.5,23.16],[26,2.72],[30,6.88]],"id":41419595},{"atb":[[32,3.26],[16,17.76],[42,2.72],[44,4.64],[22,9.51]],"id":41419608},{"atb":[[16.5,12.88],[23,3.26],[11.5,25.36],[28,10.12]],"id":41419637},{"atb":[[260,0.77],[140,2.72],[160,1.67],[95,3.26],[410,0.49]],"id":41419616},{"atb":[[32,2.72],[17,12.48],[12,24.21],[26,3.26],[29,7.13]],"id":41419612},{"atb":[[17.5,12.1],[19.5,3.26],[24,2.72],[12.5,23.16],[30,6.88]],"id":41419592},{"atb":[[65,3.12],[19,14.8],[44,3.26],[28,7.4],[60,2.72]],"id":41435526},{"atb":[[4.8,52.57],[9,3.26],[10,2.72],[6.6,35.67],[3.9,91.85]],"id":41419621},{"atb":[[270,2.72],[600,0.44],[700,0.28],[850,0.23],[220,3.26]],"id":41419588},{"atb":[[16.5,12.88],[9.6,23.23],[21,3.26],[7.6,40.36],[26,2.72]],"id":41419600},{"atb":[[5.6,3.26],[3.2,121.08],[6.2,2.72],[3.7,73.99],[4.9,51.22]],"id":41419596},{"atb":[[600,0.44],[310,3.26],[700,0.28],[360,2.72],[850,0.23]],"id":41419658}],"con":true,"img":false}]}
{"op":"mcm","clk":"5347979122","pt":1646211738553,"mc":[{"id":"1.195453723","rc":[{"atb":[[8.6,0]],"id":41419593}],"con":true,"img":false}]}
{"op":"mcm","clk":"5347979145","pt":1646211739226,"mc":[{"id":"1.195453723","rc":[{"atb":[[8.8,2.72],[7.8,3.26]],"id":41419593}],"con":true,"img":false}]}
{"op":"mcm","clk":"5348005517","pt":1646212271991,"mc":[{"id":"1.195453723","rc":[{"atb":[[24,4.35]],"id":41419609},{"atb":[[18.5,5.44]],"id":41419638},{"atl":[[1000,2]],"id":41419638},{"atb":[[8.8,11.42]],"id":41419605},{"atl":[[870,2]],"id":41419605},{"atb":[[24,4.35]],"id":41419634},{"atb":[[26,4]],"id":41419617},{"atb":[[27,2]],"id":41419613},{"atb":[[2.94,45.4]],"id":41419593},{"atl":[[430,2]],"id":41419593},{"atb":[[23,4.55]],"id":41419655},{"atl":[[1000,2]],"id":41419655},{"atb":[[5.7,15.98]],"id":41419622},{"atl":[[620,2]],"id":41419622},{"atb":[[26,4]],"id":41419589},{"atb":[[26,4]],"id":41435527},{"atb":[[5.9,15.36]],"id":41419651},{"atl":[[650,2]],"id":41419651},{"atb":[[10,9.3]],"id":41419601},{"atl":[[910,2]],"id":41419601},{"atb":[[27,2]],"id":28546943},{"atb":[[6,20]],"id":41419626},{"atl":[[610,2]],"id":41419626},{"atb":[[5.4,22.73]],"id":41419639},{"atl":[[590,2]],"id":41419639},{"atb":[[25,4.17]],"id":41419606},{"atb":[[3.65,37.74]],"id":41419635},{"atl":[[490,2]],"id":41419635},{"atb":[[24,2.06]],"id":41419602},{"atb":[[25,4.17]],"id":41419585},{"atb":[[25,4.17]],"id":41419614},{"atb":[[7,16.67]],"id":41419610},{"atl":[[730,2]],"id":41419610},{"atb":[[25,4.17]],"id":41419656},{"atb":[[6.2,19.23]],"id":41419623},{"atl":[[720,2]],"id":41419623},{"atb":[[25,4.17]],"id":41419652},{"atb":[[26,4]],"id":41435528},{"atb":[[26,4]],"id":41419619},{"atb":[[26,2]],"id":41419586},{"atb":[[3.05,48.78]],"id":41419598},{"atl":[[340,2]],"id":41419598},{"atb":[[26,4]],"id":41419660},{"atb":[[3.25,44.44]],"id":41419594},{"atl":[[400,2]],"id":41419594},{"atb":[[4.6,27.78]],"id":41419607},{"atl":[[550,2]],"id":41419607},{"atb":[[27,2]],"id":28546950},{"atb":[[6.2,12.1]],"id":41419636},{"atl":[[630,2]],"id":41419636},{"atb":[[6.8,15.36]],"id":41419603},{"atl":[[820,2]],"id":41419603},{"atb":[[26,2]],"id":41419615},{"atb":[[26,3.55]],"id":41419657},{"atb":[[15.5,6.54]],"id":41419624},{"atl":[[1000,2]],"id":41419624},{"atb":[[26,4]],"id":41419591},{"atb":[[24,4.35]],"id":41435525},{"atb":[[27,2]],"id":41419653},{"atb":[[24,4.35]],"id":41419620},{"atb":[[26,3.34]],"id":41419587},{"atb":[[25,2.06]],"id":41419599},{"atb":[[5.1,13.78]],"id":41419595},{"atl":[[570,2]],"id":41419595},{"atb":[[7,9.3]],"id":41419608},{"atl":[[740,2]],"id":41419608},{"atb":[[7,16.67]],"id":41419637},{"atl":[[740,2]],"id":41419637},{"atb":[[26,3.34]],"id":41419616},{"atb":[[7.8,14.26]],"id":41419612},{"atl":[[830,2]],"id":41419612},{"atb":[[6,13.78]],"id":41419592},{"atl":[[680,2]],"id":41419592},{"atb":[[23,4.55]],"id":41435526},{"atl":[[1000,2]],"id":41435526},{"atb":[[2.52,65.79]],"id":41419621},{"atl":[[460,2]],"id":41419621},{"atb":[[27,2]],"id":41419588},{"atb":[[5.2,23.81]],"id":41419600},{"atl":[[550,2]],"id":41419600},{"atb":[[2.52,65.79]],"id":41419596},{"atl":[[260,2]],"id":41419596},{"atb":[[27,2]],"id":41419658}],"con":true,"img":false}]}
{"op":"mcm","clk":"5348006675","pt":1646212293930,"mc":[{"id":"1.195453723","rc":[{"atb":[[6,0],[7,0]],"id":41419598},{"atb":[[16,0],[18.5,0]],"id":41419607}],"con":true,"img":false}]}
{"op":"mcm","clk":"5348006722","pt":1646212294708,"mc":[{"id":"1.195453723","rc":[{"atb":[[7.2,2.72],[6.2,3.26]],"id":41419598},{"atb":[[16.5,3.26],[19,2.72]],"id":41419607}],"con":true,"img":false}]}
{"op":"mcm","clk":"5348008630","pt":1646212339312,"mc":[{"id":"1.195453723","rc":[{"atb":[[23,0],[28,0]],"id":41419622},{"atb":[[9,0],[10,0]],"id":41419621}],"con":true,"img":false}]}
{"op":"mcm","clk":"5348008637","pt":1646212339415,"mc":[{"id":"1.195453723","rc":[{"atb":[[17,0],[19.5,0]],"id":41419626},{"atb":[[19.5,0],[24,0]],"id":41419623}],"con":true,"img":false}]}
{"op":"mcm","clk":"5348008669","pt":1646212339982,"mc":[{"id":"1.195453723","rc":[{"atb":[[22,3.26],[27,2.72]],"id":41419622}],"con":true,"img":false}]}
{"op":"mcm","clk":"5348008674","pt":1646212340085,"mc":[{"id":"1.195453723","rc":[{"atb":[[16.5,3.26],[19,2.72]],"id":41419626},{"atb":[[19,3.26],[23,2.72]],"id":41419623},{"atb":[[9.8,2.72],[8.8,3.26]],"id":41419621}],"con":true,"img":false}]}
{"op":"mcm","clk":"5348030693","pt":1646212754828,"mc":[{"id":"1.195453723","rc":[{"atb":[[18.5,0],[23,4.55]],"id":41419638},{"atl":[[830,2],[870,0]],"id":41419605},{"atl":[[590,2],[620,0]],"id":41419622},{"atl":[[650,0],[640,2]],"id":41419651},{"atl":[[870,2],[910,0]],"id":41419601},{"atl":[[580,2],[610,0]],"id":41419626},{"atl":[[570,2],[590,0]],"id":41419639},{"atl":[[490,0],[480,2]],"id":41419635},{"atl":[[690,2],[730,0]],"id":41419610},{"atl":[[680,2],[720,0]],"id":41419623},{"atl":[[380,2],[400,0]],"id":41419594},{"atl":[[540,2],[550,0]],"id":41419607},{"atl":[[630,0],[610,2]],"id":41419636},{"atl":[[780,2],[820,0]],"id":41419603},{"atb":[[5.1,0],[5.7,13.78]],"id":41419595},{"atl":[[720,2],[740,0]],"id":41419608},{"atl":[[720,2],[740,0]],"id":41419637},{"atl":[[830,0],[800,2]],"id":41419612},{"atl":[[660,2],[680,0]],"id":41419592},{"atl":[[440,2],[460,0]],"id":41419621},{"atl":[[540,2],[550,0]],"id":41419600},{"atl":[[260,0],[230,2]],"id":41419596}],"con":true,"img":false}]}
{"op":"mcm","clk":"5348030704","pt":1646212755088,"mc":[{"id":"1.195453723","rc":[{"atb":[[8.8,0],[7.8,0]],"id":41419593}],"con":true,"img":false}]}
{"op":"mcm","clk":"5348030729","pt":1646212755814,"mc":[{"id":"1.195453723","rc":[{"atb":[[8,3.26],[9,2.72]],"id":41419593}],"con":true,"img":false}]}
{"op":"mcm","clk":"5348032787","pt":1646212793967,"mc":[{"id":"1.195453723","rc":[{"atb":[[21,0],[26,0]],"id":41419595},{"atb":[[19.5,0],[24,0]],"id":41419592}],"con":true,"img":false}]}
{"op":"mcm","clk":"5348032816","pt":1646212794686,"mc":[{"id":"1.195453723","rc":[{"atb":[[9.8,11.36]],"id":41419605},{"atl":[[590,0]],"id":41419622},{"atl":[[580,0]],"id":41419626},{"atb":[[3.9,34.48]],"id":41419635},{"atl":[[680,0]],"id":41419623},{"atb":[[5.1,24.39],[4.6,0]],"id":41419607},{"atl":[[760,2]],"id":41419603},{"atb":[[7.8,0]],"id":41419612},{"atl":[[230,0]],"id":41419596}],"con":true,"img":false}]}
{"op":"mcm","clk":"5348032819","pt":1646212794748,"mc":[{"id":"1.195453723","rc":[{"atb":[[8.8,0]],"id":41419605},{"atl":[[580,2]],"id":41419622},{"atl":[[570,2]],"id":41419626},{"atl":[[660,2]],"id":41419623},{"atl":[[780,0]],"id":41419603},{"atb":[[9.2,12.2]],"id":41419612},{"atl":[[420,2],[440,0]],"id":41419621},{"atl":[[220,2]],"id":41419596}],"con":true,"img":false}]}
{"op":"mcm","clk":"5348032822","pt":1646212794845,"mc":[{"id":"1.195453723","rc":[{"atb":[[3.65,0]],"id":41419635},{"atb":[[22,3.26],[27,2.72]],"id":41419595},{"atb":[[20,3.26],[25,2.72]],"id":41419592}],"con":true,"img":false}]}
{"op":"mcm","clk":"5348032833","pt":1646212795063,"mc":[{"id":"1.195453723","rc":[{"atb":[[8,0],[9,0]],"id":41419593},{"atb":[[5.6,0],[6.2,0]],"id":41419596}],"con":true,"img":false}]}
{"op":"mcm","clk":"5348032890","pt":1646212796042,"mc":[{"id":"1.195453723","rc":[{"atb":[[8.8,2.72],[7.8,3.26]],"id":41419593},{"atb":[[5.5,3.26],[6,2.72]],"id":41419596}],"con":true,"img":false}]}
{"op":"mcm","clk":"5348036124","pt":1646212852041,"mc":[{"id":"1.195453723","rc":[{"atb":[[40,0],[30,0]],"id":41419605},{"atb":[[10.5,0],[13,0]],"id":41419635},{"atb":[[7.2,0],[6.2,0]],"id":41419598},{"atb":[[32,0],[26,0]],"id":41419636},{"atb":[[23,0],[28,7.4]],"id":41419637}],"con":true,"img":false}]}
{"op":"mcm","clk":"5348036162","pt":1646212852756,"mc":[{"id":"1.195453723","rc":[{"atb":[[32,3.26],[42,2.72]],"id":41419605},{"atb":[[11,3.26],[13.5,2.72]],"id":41419635},{"atb":[[6.4,3.26],[7.4,2.72]],"id":41419598},{"atb":[[34,8.77],[27,3.26]],"id":41419636},{"atb":[[24,3.26],[29,2.72]],"id":41419637}],"con":true,"img":false}]}
{"op":"mcm","clk":"5348036287","pt":1646212855041,"mc":[{"id":"1.195453723","rc":[{"atb":[[16.5,0],[19,0]],"id":41419626},{"atb":[[9.8,0],[8.8,0]],"id":41419621}],"con":true,"img":false}]}
{"op":"mcm","clk":"5348036321","pt":1646212855758,"mc":[{"id":"1.195453723","rc":[{"atb":[[16,3.26],[18.5,2.72]],"id":41419626},{"atb":[[8.4,3.26],[9.4,2.72]],"id":41419621}],"con":true,"img":false}]}
{"op":"mcm","clk":"5348038460","pt":1646212893211,"mc":[{"id":"1.195453723","rc":[{"atl":[[630,2],[640,0]],"id":41419651},{"atl":[[760,0],[780,2]],"id":41419603},{"atl":[[570,0],[560,2]],"id":41419595},{"atl":[[720,0],[710,2]],"id":41419608},{"atl":[[720,0],[710,2]],"id":41419637}],"con":true,"img":false}]}
{"op":"mcm","clk":"5348038491","pt":1646212893682,"mc":[{"id":"1.195453723","rc":[{"atb":[[22,0],[27,0]],"id":41419595}],"con":true,"img":false}]}
{"op":"mcm","clk":"5348038544","pt":1646212894557,"mc":[{"id":"1.195453723","rc":[{"atb":[[21,3.26],[26,2.72]],"id":41419595}],"con":true,"img":false}]}
{"op":"mcm","clk":"5348039693","pt":1646212916386,"mc":[{"id":"1.195453723","rc":[{"atb":[[8.8,0],[7.8,0]],"id":41419593}],"con":true,"img":false}]}
{"op":"mcm","clk":"5348039767","pt":1646212917423,"mc":[{"id":"1.195453723","rc":[{"atb":[[8.6,2.72],[7.6,3.26]],"id":41419593}],"con":true,"img":false}]}
{"op":"mcm","clk":"5348040103","pt":1646212924050,"mc":[{"id":"1.195453723","rc":[{"atl":[[780,0],[770,2]],"id":41419603}],"con":true,"img":false}]}
{"op":"mcm","clk":"5348041085","pt":1646212942873,"mc":[{"id":"1.195453723","rc":[{"atb":[[70,0],[48,0]],"id":41419655},{"atb":[[24,0],[29,0]],"id":41419651},{"atb":[[300,0],[250,0]],"id":28546943},{"atb":[[65,0],[90,0]],"id":41419656},{"atb":[[85,0],[120,0]],"id":41419619},{"atb":[[140,0],[95,0]],"id":41419586},{"atb":[[140,0],[95,0]],"id":41419660},{"atb":[[8.8,0],[7.8,0]],"id":41419594},{"atb":[[280,0],[330,0]],"id":28546950},{"atb":[[160,0],[110,0]],"id":41419615},{"atb":[[290,0],[340,0]],"id":41419653},{"atb":[[70,0],[95,0]],"id":41419599},{"atb":[[140,0],[95,0]],"id":41419616},{"atb":[[270,0],[220,0]],"id":41419588},{"atb":[[310,0],[360,0]],"id":41419658}],"con":true,"img":false}]}
{"op":"mcm","clk":"5348041097","pt":1646212943029,"mc":[{"id":"1.195453723","rc":[{"atb":[[25,0],[28,3.7]],"id":41419656}],"con":true,"img":false}]}
{"op":"mcm","clk":"5348041124","pt":1646212943545,"mc":[{"id":"1.195453723","rc":[{"atb":[[75,2.72],[50,3.26]],"id":41419655},{"atb":[[25,3.26],[30,2.72]],"id":41419651},{"atb":[[70,3.26],[95,2.72]],"id":41419656},{"atb":[[130,2.72],[90,3.26]],"id":41419619},{"atb":[[150,2.72],[100,3.26]],"id":41419586},{"atb":[[150,2.72],[100,3.26]],"id":41419660},{"atb":[[9.2,2.72],[8.2,3.26]],"id":41419594},{"atb":[[170,2.72],[120,3.26]],"id":41419615},{"atb":[[300,3.26],[350,2.72]],"id":41419653},{"atb":[[75,3.26],[100,2.72]],"id":41419599},{"atb":[[150,2.72],[100,3.26]],"id":41419616},{"atb":[[280,2.72],[230,3.26]],"id":41419588},{"atb":[[320,3.26],[370,2.72]],"id":41419658}],"con":true,"img":false}]}
{"op":"mcm","clk":"5348041136","pt":1646212943749,"mc":[{"id":"1.195453723","rc":[{"atb":[[260,3.26],[310,2.72]],"id":28546943},{"atb":[[290,3.26],[340,2.72]],"id":28546950}],"con":true,"img":false}]}
{"op":"mcm","clk":"5348042751","pt":1646212973394,"mc":[{"id":"1.195453723","rc":[{"atb":[[36,0],[19,0],[14,0]],"id":41419605},{"atb":[[6.8,0],[9.8,0],[5.4,0]],"id":41419593},{"atb":[[130,0],[46,0],[28,0]],"id":41419589},{"atb":[[16,0],[44,0],[22,0]],"id":41419601},{"atb":[[600,0],[700,0],[850,0]],"id":28546943},{"atb":[[260,0],[360,0],[510,0]],"id":41419602},{"atb":[[16.5,0],[46,0],[23,0]],"id":41419585},{"atb":[[560,0],[310,0],[410,0]],"id":41419586},{"atb":[[3.95,0],[6.8,0],[4.9,0]],"id":41419598},{"atb":[[5.7,0],[8.4,0],[4.7,0]],"id":41419594},{"atb":[[600,0],[700,0],[850,0]],"id":28546950},{"atb":[[16,0],[11,0],[27,0]],"id":41419603},{"atb":[[260,0],[110,2.72],[55,0]],"id":41419591},{"atb":[[260,0],[160,0],[410,0]],"id":41419587},{"atb":[[260,0],[360,0],[510,0]],"id":41419599},{"atb":[[17.5,0],[12.5,0],[30,0]],"id":41419595},{"atb":[[17.5,0],[12.5,0],[30,0]],"id":41419592},{"atb":[[600,0],[700,0],[850,0]],"id":41419588},{"atb":[[16.5,0],[9.6,0],[7.6,0]],"id":41419600},{"atb":[[3.2,0],[3.7,0],[4.9,0]],"id":41419596}],"con":true,"img":false}]}
{"op":"mcm","clk":"5348042758","pt":1646212973496,"mc":[{"id":"1.195453723","rc":[{"atb":[[360,0],[210,0],[110,0]],"id":41419609},{"atb":[[80,0],[42,0],[210,0]],"id":41419634},{"atb":[[130,0],[46,0],[28,0]],"id":41419617},{"atb":[[600,0],[700,0],[850,0]],"id":41419613},{"atb":[[10.5,0],[26,0],[15.5,0]],"id":41419622},{"atb":[[8,0],[17.5,0],[10,0]],"id":41419626},{"atb":[[360,0],[210,0],[110,0]],"id":41419606},{"atb":[[9,0],[5,0],[6,0]],"id":41419635},{"atb":[[16.5,0],[46,0],[23,0]],"id":41419614},{"atb":[[24,3.26],[9.8,0],[14.5,0]],"id":41419610},{"atb":[[9.2,0],[21,0],[13,0]],"id":41419623},{"atb":[[260,0],[110,0],[55,0]],"id":41419619},{"atb":[[6.4,0],[13.5,0],[8.4,0]],"id":41419607},{"atb":[[560,0],[310,0],[410,0]],"id":41419615},{"atb":[[36,0],[90,0],[23,0]],"id":41419624},{"atb":[[36,0],[90,0],[23,0]],"id":41419620},{"atb":[[16,0],[44,0],[22,0]],"id":41419608},{"atb":[[260,0],[160,0],[410,0]],"id":41419616},{"atb":[[17,0],[12,0],[29,0]],"id":41419612},{"atb":[[4.8,0],[6.6,0],[3.9,0]],"id":41419621}],"con":true,"img":false}]}
{"op":"mcm","clk":"5348042764","pt":1646212973601,"mc":[{"id":"1.195453723","rc":[{"atb":[[80,0],[42,0],[210,0]],"id":41419638},{"atb":[[44,0],[27,0],[120,0]],"id":41419655},{"atb":[[130,0],[65,0],[280,0]],"id":41435527},{"atb":[[16,0],[11,0],[27,0]],"id":41419651},{"atb":[[18,0],[10.5,0],[8.2,0]],"id":41419639},{"atb":[[40,0],[20,0],[15,0]],"id":41419656},{"atb":[[360,0],[210,0],[110,0]],"id":41419652},{"atb":[[34,0],[85,0],[22,0]],"id":41435528},{"atb":[[32,0],[160,0],[55,0]],"id":41419660},{"atb":[[34,2.72],[18.5,0],[13.5,0]],"id":41419636},{"atb":[[140,3.26],[390,0],[240,0]],"id":41419657},{"atb":[[95,0],[48,0],[240,0]],"id":41435525},{"atb":[[600,0],[700,0],[850,0]],"id":41419653},{"atb":[[16.5,0],[11.5,0],[28,0]],"id":41419637},{"atb":[[65,0],[19,0],[28,0]],"id":41435526},{"atb":[[600,0],[700,0],[850,0]],"id":41419658}],"con":true,"img":false}]}
{"op":"mcm","clk":"5348043367","pt":1646212985357,"mc":[{"id":"1.195453723","rc":[{"atb":[[260,0.77],[160,1.67],[410,0.49]],"id":41419609},{"atb":[[95,2.12],[48,5.66],[240,0.83]],"id":41419638},{"atb":[[38,5.4],[19.5,10.8],[14.5,19.73]],"id":41419605},{"atb":[[360,0.55],[210,0.95],[110,2.44]],"id":41419634},{"atb":[[150,1.34],[50,4.07],[30,9.18]],"id":41419617},{"atb":[[600,0.44],[700,0.28],[850,0.23]],"id":41419613},{"atb":[[5.1,64.97],[9.2,24.36],[6.2,38.42]],"id":41419593},{"atb":[[340,0.58],[490,0.4],[240,1.11]],"id":41419655},{"atb":[[16,13.31],[11,26.63],[27,10.4]],"id":41419622},{"atb":[[100,4.74],[50,5.43],[250,0.8]],"id":41419589},{"atb":[[600,0.44],[700,0.28],[850,0.23]],"id":41435527},{"atb":[[16,17.76],[44,4.64],[22,9.51]],"id":41419651},{"atb":[[16.5,17.18],[46,4.44],[23,9.07]],"id":41419601},{"atb":[[600,0.44],[700,0.28],[850,0.23]],"id":28546943},{"atb":[[18.5,14.14],[11,19.97],[8.4,35.99]],"id":41419626},{"atb":[[8.6,35.05],[19,11.1],[11.5,19.02]],"id":41419639},{"atb":[[580,0.34],[330,0.81],[430,0.46]],"id":41419606},{"atb":[[4.9,68.3],[8.8,25.61],[5.9,40.77]],"id":41419635},{"atb":[[570,0.34],[320,0.83],[420,0.47]],"id":41419602},{"atb":[[18.5,15.22],[27,7.68],[60,3.38]],"id":41419585},{"atb":[[16.5,17.18],[46,4.44],[23,9.07]],"id":41419614},{"atb":[[10,29.59],[25,8.32],[15,14.27]],"id":41419610},{"atb":[[32,6.44],[80,2.52],[21,13.31]],"id":41419656},{"atb":[[9.6,30.97],[23,11.8],[14,15.36]],"id":41419623},{"atb":[[600,0.44],[700,0.28],[850,0.23]],"id":41419652},{"atb":[[360,0.55],[210,0.95],[110,2.44]],"id":41435528},{"atb":[[140,1.43],[70,3.85],[290,0.69]],"id":41419619},{"atb":[[600,0.44],[700,0.28],[850,0.23]],"id":41419586},{"atb":[[3.7,98.66],[4.4,58.76],[5.9,40.77]],"id":41419598},{"atb":[[580,0.34],[330,0.81],[430,0.46]],"id":41419660},{"atb":[[4.4,78.34],[7.8,29.38],[5.4,45.4]],"id":41419594},{"atb":[[6.2,51.22],[8.2,27.75],[13,16.64]],"id":41419607},{"atb":[[600,0.44],[700,0.28],[850,0.23]],"id":28546950},{"atb":[[36,5.7],[19,11.1],[14,20.49]],"id":41419636},{"atb":[[16.5,12.88],[11.5,25.36],[28,7.4]],"id":41419603},{"atb":[[610,0.32],[360,0.74],[460,0.43]],"id":41419615},{"atb":[[600,0.44],[700,0.28],[850,0.23]],"id":41419657},{"atb":[[40,5.12],[100,2.01],[25,11.1]],"id":41419624},{"atb":[[280,0.71],[180,1.48],[430,0.46]],"id":41419591},{"atb":[[520,0.51],[620,0.32],[770,0.26]],"id":41435525},{"atb":[[600,0.44],[700,0.28],[850,0.23]],"id":41419653},{"atb":[[65,3.12],[36,7.61],[180,1.11]],"id":41419620},{"atb":[[640,0.31],[390,0.68],[490,0.4]],"id":41419587},{"atb":[[540,0.49],[640,0.31],[790,0.25]],"id":41419599},{"atb":[[17,12.48],[12,24.21],[29,7.13]],"id":41419595},{"atb":[[16.5,17.18],[46,4.44],[23,9.07]],"id":41419608},{"atb":[[17,12.48],[12,24.21],[29,9.85]],"id":41419637},{"atb":[[300,0.67],[200,1.34],[450,0.44]],"id":41419616},{"atb":[[17.5,12.1],[12.5,23.16],[30,6.88]],"id":41419612},{"atb":[[36,5.7],[19,11.1],[14,20.49]],"id":41419592},{"atb":[[270,0.74],[60,7.23],[120,1.67]],"id":41435526},{"atb":[[4.6,55.49],[6.2,38.42],[3.8,95.13]],"id":41419621},{"atb":[[600,0.44],[700,0.28],[850,0.23]],"id":41419588},{"atb":[[16,13.31],[7.4,41.62],[9.4,23.78]],"id":41419600},{"atb":[[4.5,57.08],[3,133.19],[3.5,79.91]],"id":41419596},{"atb":[[600,0.44],[700,0.28],[850,0.23]],"id":41419658}],"con":true,"img":false}]}
{"op":"mcm","clk":"5348045685","pt":1646213026652,"mc":[{"id":"1.195453723","rc":[{"atb":[[290,0],[240,0]],"id":41419613},{"atb":[[16,0],[18.5,11.41]],"id":41419626}],"con":true,"img":false}]}
{"op":"mcm","clk":"5348045733","pt":1646213027575,"mc":[{"id":"1.195453723","rc":[{"atb":[[300,2.72],[250,3.26]],"id":41419613},{"atb":[[16.5,3.26],[19,2.72]],"id":41419626}],"con":true,"img":false}]}
{"op":"mcm","clk":"5348048285","pt":1646213073222,"mc":[{"id":"1.195453723","rc":[{"atb":[[18.5,5.71],[23,0]],"id":41419638},{"atb":[[5.1,19.62],[5.7,0]],"id":41419595},{"atb":[[9.2,0],[7.8,14.71]],"id":41419612}],"con":true,"img":false}]}
{"op":"mcm","clk":"5348048570","pt":1646213077724,"mc":[{"id":"1.195453723","rc":[{"atl":[[380,0],[370,2]],"id":41419594}],"con":true,"img":false}]}
{"op":"mcm","clk":"5348049927","pt":1646213102252,"mc":[{"id":"1.195453723","rc":[{"atb":[[18.5,0],[23,4.55]],"id":41419638}],"con":true,"img":false}]}
{"op":"mcm","clk":"5348050217","pt":1646213108179,"mc":[{"id":"1.195453723","rc":[{"atb":[[5.5,0],[6,0]],"id":41419596}],"con":true,"img":false}]}
{"op":"mcm","clk":"5348050266","pt":1646213108959,"mc":[{"id":"1.195453723","rc":[{"atb":[[5.6,3.26],[6.2,2.72]],"id":41419596}],"con":true,"img":false}]}
{"op":"mcm","clk":"5348053332","pt":1646213162063,"mc":[{"id":"1.195453723","rc":[{"atb":[[8.4,0],[9.4,0]],"id":41419621}],"con":true,"img":false}]}
{"op":"mcm","clk":"5348053378","pt":1646213162838,"mc":[{"id":"1.195453723","rc":[{"atb":[[9.6,2.72],[8.6,3.26]],"id":41419621}],"con":true,"img":false}]}
{"op":"mcm","clk":"5348056927","pt":1646213227994,"mc":[{"id":"1.195453723","rc":[{"atb":[[24,0]],"id":41419609},{"atb":[[24,0]],"id":41419602},{"atb":[[7,0]],"id":41419610},{"atl":[[690,0]],"id":41419610},{"atb":[[26,0]],"id":41435528},{"atb":[[3.05,0]],"id":41419598},{"atl":[[340,0]],"id":41419598},{"atb":[[2.52,0]],"id":41419621},{"atl":[[420,0]],"id":41419621}],"con":true,"img":false}]}
{"op":"mcm","clk":"5348056934","pt":1646213228105,"mc":[{"id":"1.195453723","rc":[{"atb":[[26,0]],"id":41419617},{"atb":[[27,0]],"id":28546943},{"atb":[[27,0]],"id":28546950},{"atb":[[6.8,0]],"id":41419603},{"atl":[[770,0]],"id":41419603}],"con":true,"img":false}]}
{"op":"mcm","clk":"5348056937","pt":1646213228204,"mc":[{"id":"1.195453723","rc":[{"atb":[[85,0],[60,0]],"id":41419609},{"atb":[[9.8,0]],"id":41419605},{"atl":[[830,0]],"id":41419605},{"atb":[[5.9,0]],"id":41419651},{"atl":[[630,0]],"id":41419651},{"atb":[[10,0]],"id":41419601},{"atl":[[870,0]],"id":41419601},{"atb":[[5.1,0]],"id":41419595},{"atl":[[560,0]],"id":41419595}],"con":true,"img":false}]}
{"op":"mcm","clk":"5348056947","pt":1646213228308,"mc":[{"id":"1.195453723","rc":[{"atb":[[24,0]],"id":41419634},{"atb":[[24,0],[29,0]],"id":41419610},{"atb":[[130,0],[90,0]],"id":41435528},{"atb":[[6.4,0],[7.4,0]],"id":41419598},{"atb":[[5.1,0]],"id":41419607},{"atl":[[540,0]],"id":41419607},{"atb":[[24,0]],"id":41419620},{"atb":[[7.8,0]],"id":41419612},{"atl":[[800,0]],"id":41419612},{"atb":[[9.6,0],[8.6,0]],"id":41419621}],"con":true,"img":false}]}
{"op":"mcm","clk":"5348056949","pt":1646213228418,"mc":[{"id":"1.195453723","rc":[{"atb":[[80,0],[110,0]],"id":41419617},{"atb":[[2.94,0]],"id":41419593},{"atl":[[430,0]],"id":41419593},{"atb":[[23,0]],"id":41419655},{"atl":[[1000,0]],"id":41419655},{"atb":[[260,0],[300,2.72],[310,0],[250,3.26]],"id":28546943},{"atb":[[6,0]],"id":41419626},{"atl":[[570,0]],"id":41419626},{"atb":[[5.4,0]],"id":41419639},{"atl":[[570,0]],"id":41419639},{"atb":[[25,0]],"id":41419606},{"atb":[[80,0],[110,0]],"id":41419602},{"atb":[[25,0]],"id":41419585},{"atb":[[23,3.26],[28,2.72]],"id":41419610},{"atb":[[28,0]],"id":41419656},{"atb":[[26,0]],"id":41419586},{"atb":[[36,2.72],[38,0],[28,10.67],[29,0]],"id":41419603},{"atb":[[15.5,0]],"id":41419624},{"atl":[[1000,0]],"id":41419624},{"atb":[[26,0]],"id":41419591},{"atb":[[24,0]],"id":41435525},{"atb":[[26,0]],"id":41419587}],"con":true,"img":false}]}
{"op":"mcm","clk":"5348056954","pt":1646213228520,"mc":[{"id":"1.195453723","rc":[{"atb":[[25,0],[30,0]],"id":41419651},{"atb":[[38,0],[48,0]],"id":41419601},{"atb":[[21,0],[22,3.26],[26,0],[27,2.72]],"id":41419595}],"con":true,"img":false}]}
{"op":"mcm","clk":"5348056960","pt":1646213228624,"mc":[{"id":"1.195453723","rc":[{"atb":[[5.7,0]],"id":41419622},{"atl":[[580,0]],"id":41419622},{"atb":[[18.5,0],[22,0]],"id":41419639},{"atb":[[65,3.26],[90,2.72]],"id":41419656},{"atb":[[26,0]],"id":41419660},{"atb":[[26,0]],"id":41419657},{"atb":[[38,3.26],[40,0],[48,2.72],[50,0]],"id":41419620},{"atb":[[130,0],[90,0]],"id":41419587},{"atb":[[7,0]],"id":41419608},{"atl":[[710,0]],"id":41419608},{"atb":[[7,0]],"id":41419637},{"atl":[[710,0]],"id":41419637},{"atb":[[6,0]],"id":41419592},{"atl":[[660,0]],"id":41419592},{"atb":[[23,0]],"id":41435526},{"atl":[[1000,0]],"id":41435526},{"atb":[[27,0]],"id":41419588}],"con":true,"img":false}]}
{"op":"mcm","clk":"5348056965","pt":1646213228729,"mc":[{"id":"1.195453723","rc":[{"atb":[[23,0]],"id":41419638},{"atl":[[1000,0]],"id":41419638},{"atb":[[27,0]],"id":41419613},{"atb":[[8.6,0],[7.6,0]],"id":41419593},{"atb":[[26,0]],"id":41419589},{"atb":[[26,0]],"id":41435527},{"atb":[[16.5,0],[19,0]],"id":41419626},{"atb":[[3.9,0]],"id":41419635},{"atl":[[480,0]],"id":41419635},{"atb":[[70,0],[48,0]],"id":41419585},{"atb":[[25,0]],"id":41419614},{"atb":[[70,0],[95,0]],"id":41419656},{"atb":[[25,0]],"id":41419652},{"atb":[[26,0]],"id":41419619},{"atb":[[150,0],[100,0]],"id":41419586},{"atb":[[3.25,0]],"id":41419594},{"atl":[[370,0]],"id":41419594},{"atb":[[6.2,0]],"id":41419636},{"atl":[[610,0]],"id":41419636},{"atb":[[42,0],[55,0]],"id":41419624},{"atb":[[27,0]],"id":41419653},{"atb":[[5.2,0]],"id":41419600},{"atl":[[540,0]],"id":41419600},{"atb":[[2.52,0]],"id":41419596},{"atl":[[220,0]],"id":41419596},{"atb":[[27,0]],"id":41419658}],"con":true,"img":false}]}
{"op":"mcm","clk":"5348056968","pt":1646213228834,"mc":[{"id":"1.195453723","rc":[{"atb":[[8.8,2.72],[7.8,3.26]],"id":41419593},{"atb":[[6.2,0]],"id":41419623},{"atl":[[660,0]],"id":41419623},{"atb":[[150,0],[100,0]],"id":41419660},{"atb":[[26,0]],"id":41419615},{"atb":[[140,0],[190,0]],"id":41419657},{"atb":[[80,0],[110,0]],"id":41419591},{"atb":[[25,0]],"id":41419599},{"atb":[[32,0],[42,0]],"id":41419608},{"atb":[[26,0]],"id":41419616}],"con":true,"img":false}]}
{"op":"mcm","clk":"5348056973","pt":1646213228889,"mc":[{"id":"1.195453723","rc":[{"atb":[[65,0],[46,0]],"id":41419638},{"atb":[[290,2.72],[240,3.26]],"id":41419613},{"atb":[[22,0],[27,7.68]],"id":41419622},{"atb":[[70,3.26],[75,0],[95,2.72],[100,2.01]],"id":41419589},{"atb":[[85,0],[120,0]],"id":41419652},{"atb":[[34,0],[27,0]],"id":41419636},{"atb":[[20,0],[25,0]],"id":41419592},{"atb":[[5.6,0],[6.2,0]],"id":41419596},{"atb":[[320,0],[370,0]],"id":41419658}],"con":true,"img":false}]}
{"op":"mcm","clk":"5348056976","pt":1646213228995,"mc":[{"id":"1.195453723","rc":[{"atb":[[85,2.72],[60,3.26]],"id":41419609},{"atb":[[300,0],[250,0]],"id":41419613},{"atb":[[170,0],[120,0]],"id":41435527},{"atb":[[11,0],[13.5,0]],"id":41419635},{"atb":[[80,0],[55,0]],"id":41419614},{"atb":[[19,0],[23,9.07]],"id":41419623},{"atb":[[130,2.72],[90,3.26]],"id":41435528},{"atb":[[130,0],[90,0]],"id":41419619},{"atb":[[6.4,3.26],[7.4,2.72]],"id":41419598},{"atb":[[8,3.26],[9,2.72],[9.2,0],[8.2,0]],"id":41419594},{"atb":[[170,0],[120,0]],"id":41419615},{"atb":[[300,0],[350,0]],"id":41419653},{"atb":[[75,0],[100,0]],"id":41419599},{"atb":[[140,2.72],[150,0],[95,3.26],[100,0]],"id":41419616},{"atb":[[9.6,2.72],[8.6,3.26]],"id":41419621},{"atb":[[21,0],[26,0]],"id":41419600}],"con":true,"img":false}]}
{"op":"mcm","clk":"5348056984","pt":1646213229198,"mc":[{"id":"1.195453723","rc":[{"atb":[[80,3.26],[110,2.72]],"id":41419617},{"atb":[[80,3.26],[110,2.72]],"id":41419602}],"con":true,"img":false}]}
{"op":"mcm","clk":"5348056987","pt":1646213229303,"mc":[{"id":"1.195453723","rc":[{"atb":[[25,3.26],[30,2.72]],"id":41419651},{"atb":[[38,3.26],[48,2.72]],"id":41419601},{"atb":[[18.5,3.26],[22,2.72]],"id":41419639},{"atb":[[130,2.72],[90,3.26]],"id":41419587}],"con":true,"img":false}]}
{"op":"mcm","clk":"5348056991","pt":1646213229407,"mc":[{"id":"1.195453723","rc":[{"atb":[[16.5,3.26],[19,2.72]],"id":41419626},{"atb":[[150,2.72],[100,3.26]],"id":41419586}],"con":true,"img":false}]}
{"op":"mcm","clk":"5348056994","pt":1646213229511,"mc":[{"id":"1.195453723","rc":[{"atb":[[70,2.72],[48,3.26]],"id":41419585},{"atb":[[150,2.72],[100,3.26]],"id":41419660},{"atb":[[140,3.26],[190,2.72]],"id":41419657},{"atb":[[42,3.26],[55,2.72]],"id":41419624},{"atb":[[80,3.26],[110,2.72]],"id":41419591},{"atb":[[32,3.26],[42,2.72]],"id":41419608}],"con":true,"img":false}]}
{"op":"mcm","clk":"5348057000","pt":1646213229614,"mc":[{"id":"1.195453723","rc":[{"atb":[[65,2.72],[46,3.26]],"id":41419638},{"atb":[[22,3.26],[27,10.4]],"id":41419622},{"atb":[[85,3.26],[120,2.72]],"id":41419652},{"atb":[[34,2.72],[27,3.26]],"id":41419636},{"atb":[[20,3.26],[25,2.72]],"id":41419592},{"atb":[[5.6,3.26],[6.2,2.72]],"id":41419596},{"atb":[[320,3.26],[370,2.72]],"id":41419658}],"con":true,"img":false}]}
{"op":"mcm","clk":"5348057006","pt":1646213229722,"mc":[{"id":"1.195453723","rc":[{"atb":[[170,2.72],[120,3.26]],"id":41435527},{"atb":[[11,3.26],[13.5,2.72]],"id":41419635},{"atb":[[80,2.72],[55,3.26]],"id":41419614},{"atb":[[19,3.26],[23,11.8]],"id":41419623},{"atb":[[130,2.72],[90,3.26]],"id":41419619},{"atb":[[170,2.72],[120,3.26]],"id":41419615},{"atb":[[300,3.26],[350,2.72]],"id":41419653},{"atb":[[75,3.26],[100,2.72]],"id":41419599},{"atb":[[21,3.26],[26,2.72]],"id":41419600}],"con":true,"img":false}]}
{"op":"mcm","clk":"5348060179","pt":1646213294310,"mc":[{"id":"1.195453723","rc":[{"atb":[[44,0],[60,0]],"id":41419634},{"atb":[[75,0],[50,0]],"id":41419606},{"atb":[[70,0],[48,0]],"id":41419585},{"atb":[[290,0],[340,0]],"id":28546950},{"atb":[[80,0],[110,0]],"id":41419591},{"atb":[[20,0],[25,0]],"id":41419592},{"atb":[[280,0],[230,0]],"id":41419588}],"con":true,"img":false}]}
{"op":"mcm","clk":"5348060185","pt":1646213294464,"mc":[{"id":"1.195453723","rc":[{"atb":[[22,0],[27,0]],"id":41419595}],"con":true,"img":false}]}
{"op":"mcm","clk":"5348060207","pt":1646213294983,"mc":[{"id":"1.195453723","rc":[{"atb":[[65,2.72],[46,3.26]],"id":41419634},{"atb":[[80,2.72],[55,3.26]],"id":41419606},{"atb":[[80,2.72],[55,3.26]],"id":41419585},{"atb":[[310,3.26],[360,2.72]],"id":28546950},{"atb":[[130,2.72],[90,3.26]],"id":41419591},{"atb":[[21,3.26],[26,2.72]],"id":41419592},{"atb":[[260,3.26],[310,2.72]],"id":41419588}],"con":true,"img":false}]}
{"op":"mcm","clk":"5348060215","pt":1646213295191,"mc":[{"id":"1.195453723","rc":[{"atb":[[21,3.26],[26,2.72]],"id":41419595}],"con":true,"img":false}]}
{"op":"mcm","clk":"5348062699","pt":1646213341688,"mc":[{"id":"1.195453723","rc":[{"atb":[[8.8,0],[7.8,0]],"id":41419593},{"atb":[[22,0],[27,7.68]],"id":41419622},{"atb":[[5.6,0],[6.2,0]],"id":41419596}],"con":true,"img":false}]}
{"op":"mcm","clk":"5348062747","pt":1646213342371,"mc":[{"id":"1.195453723","rc":[{"atb":[[7.4,3.26],[8.4,2.72]],"id":41419593},{"atb":[[21,3.26],[26,2.72]],"id":41419622},{"atb":[[5.5,3.26],[6,2.72]],"id":41419596}],"con":true,"img":false}]}
{"op":"mcm","clk":"5348062910","pt":1646213345279,"mc":[{"id":"1.195453723","rc":[{"atb":[[26,3.34]],"id":41419609},{"atb":[[25,4.17]],"id":41419638},{"atl":[[1000,2]],"id":41419638},{"atb":[[10.5,10.53]],"id":41419605},{"atl":[[830,2]],"id":41419605},{"atb":[[27,3.85]],"id":41419634},{"atb":[[28,3.7]],"id":41419617},{"atb":[[30,2]],"id":41419613},{"atb":[[3,48.74]],"id":41419593},{"atl":[[430,2]],"id":41419593},{"atb":[[26,2.24]],"id":41419655},{"atb":[[5.5,15.36]],"id":41419622},{"atl":[[570,2]],"id":41419622},{"atb":[[29,3.57]],"id":41419589},{"atb":[[29,2]],"id":41435527},{"atb":[[6.6,9.3]],"id":41419651},{"atl":[[670,2]],"id":41419651},{"atb":[[11.5,8.88]],"id":41419601},{"atl":[[880,2]],"id":41419601},{"atb":[[30,2]],"id":28546943},{"atb":[[6.2,19.23]],"id":41419626},{"atl":[[570,2]],"id":41419626},{"atb":[[5.9,20.41]],"id":41419639},{"atl":[[590,2]],"id":41419639},{"atb":[[28,2]],"id":41419606},{"atb":[[4.1,32.26]],"id":41419635},{"atl":[[510,2]],"id":41419635},{"atb":[[27,2]],"id":41419602},{"atb":[[28,3.7]],"id":41419585},{"atb":[[27,3.85]],"id":41419614},{"atb":[[7.4,15.62]],"id":41419610},{"atl":[[690,2]],"id":41419610},{"atb":[[28,3.7]],"id":41419656},{"atb":[[6.4,18.52]],"id":41419623},{"atl":[[650,2]],"id":41419623},{"atb":[[27,2]],"id":41419652},{"atb":[[29,3.57]],"id":41435528},{"atb":[[29,3.57]],"id":41419619},{"atb":[[29,2]],"id":41419586},{"atb":[[3.25,44.44]],"id":41419598},{"atl":[[340,2]],"id":41419598},{"atb":[[29,2]],"id":41419660},{"atb":[[3.4,41.67]],"id":41419594},{"atl":[[380,2]],"id":41419594},{"atb":[[5.1,24.39]],"id":41419607},{"atl":[[550,2]],"id":41419607},{"atb":[[30,2]],"id":28546950},{"atb":[[7.2,11.42]],"id":41419636},{"atl":[[650,2]],"id":41419636},{"atb":[[7,16.67]],"id":41419603},{"atl":[[750,2]],"id":41419603},{"atb":[[29,2]],"id":41419615},{"atb":[[29,2]],"id":41419657},{"atb":[[15.5,6.54]],"id":41419624},{"atl":[[1000,2]],"id":41419624},{"atb":[[29,2.98]],"id":41419591},{"atb":[[27,2]],"id":41435525},{"atb":[[29,2]],"id":41419653},{"atb":[[26,4]],"id":41419620},{"atb":[[29,2]],"id":41419587},{"atb":[[27,2]],"id":41419599},{"atb":[[5.7,14.26]],"id":41419595},{"atl":[[570,2]],"id":41419595},{"atb":[[7.8,8.88]],"id":41419608},{"atl":[[740,2]],"id":41419608},{"atb":[[8.2,13.89]],"id":41419637},{"atl":[[790,2]],"id":41419637},{"atb":[[29,2.68]],"id":41419616},{"atb":[[10,11.11]],"id":41419612},{"atl":[[840,2]],"id":41419612},{"atb":[[6.8,11.42]],"id":41419592},{"atl":[[720,2]],"id":41419592},{"atb":[[25,4.17]],"id":41435526},{"atl":[[1000,2]],"id":41435526},{"atb":[[2.52,65.79]],"id":41419621},{"atl":[[420,2]],"id":41419621},{"atb":[[29,2]],"id":41419588},{"atb":[[5.6,21.74]],"id":41419600},{"atl":[[540,2]],"id":41419600},{"atb":[[2.52,65.79]],"id":41419596},{"atl":[[200,2]],"id":41419596},{"atb":[[29,2]],"id":41419658}],"con":true,"img":false}]}
{"op":"mcm","clk":"5348063859","pt":1646213363124,"mc":[{"id":"1.195453723","rc":[{"atb":[[38,0],[19.5,0],[14.5,0]],"id":41419605},{"atb":[[5.1,0],[9.2,0],[6.2,0]],"id":41419593},{"atb":[[100,0],[50,0],[250,0]],"id":41419589},{"atb":[[16.5,0],[46,0],[23,0]],"id":41419601},{"atb":[[600,0],[700,0],[850,0]],"id":28546943},{"atb":[[570,0],[320,0],[420,0]],"id":41419602},{"atb":[[18.5,0],[27,0],[60,0]],"id":41419585},{"atb":[[600,0],[700,0],[850,0]],"id":41419586},{"atb":[[3.7,0],[4.4,0],[5.9,0]],"id":41419598},{"atb":[[4.4,0],[7.8,0],[5.4,0]],"id":41419594},{"atb":[[600,0],[700,0],[850,0]],"id":28546950},{"atb":[[16.5,0],[11.5,0],[28,3.26]],"id":41419603},{"atb":[[280,0],[180,0],[430,0]],"id":41419591},{"atb":[[640,0],[390,0],[490,0]],"id":41419587},{"atb":[[540,0],[640,0],[790,0]],"id":41419599},{"atb":[[17,0],[12,0],[29,0]],"id":41419595},{"atb":[[36,0],[19,0],[14,0]],"id":41419592},{"atb":[[600,0],[700,0],[850,0]],"id":41419588},{"atb":[[16,0],[7.4,0],[9.4,0]],"id":41419600},{"atb":[[4.5,0],[3,0],[3.5,0]],"id":41419596}],"con":true,"img":false}]}
{"op":"mcm","clk":"5348063861","pt":1646213363182,"mc":[{"id":"1.195453723","rc":[{"atb":[[260,0],[160,0],[410,0]],"id":41419609},{"atb":[[360,0],[210,0],[110,0]],"id":41419634},{"atb":[[150,0],[50,0],[30,0]],"id":41419617},{"atb":[[600,0],[700,0],[850,0]],"id":41419613},{"atb":[[16,0],[11,0],[27,0]],"id":41419622},{"atb":[[18.5,0],[11,0],[8.4,0]],"id":41419626},{"atb":[[580,0],[330,0],[430,0]],"id":41419606},{"atb":[[4.9,0],[8.8,0],[5.9,0]],"id":41419635},{"atb":[[16.5,0],[46,0],[23,0]],"id":41419614},{"atb":[[10,0],[25,0],[15,0]],"id":41419610},{"atb":[[9.6,0],[23,2.72],[14,0]],"id":41419623},{"atb":[[140,0],[70,0],[290,0]],"id":41419619},{"atb":[[6.2,0],[8.2,0],[13,0]],"id":41419607},{"atb":[[610,0],[360,0],[460,0]],"id":41419615},{"atb":[[40,0],[100,0],[25,0]],"id":41419624},{"atb":[[65,0],[36,0],[180,0]],"id":41419620},{"atb":[[16.5,0],[46,0],[23,0]],"id":41419608},{"atb":[[300,0],[200,0],[450,0]],"id":41419616},{"atb":[[17.5,0],[12.5,0],[30,0]],"id":41419612},{"atb":[[4.6,0],[6.2,0],[3.8,0]],"id":41419621}],"con":true,"img":false}]}
{"op":"mcm","clk":"5348063866","pt":1646213363289,"mc":[{"id":"1.195453723","rc":[{"atb":[[95,0],[48,0],[240,0]],"id":41419638},{"atb":[[340,0],[490,0],[240,0]],"id":41419655},{"atb":[[600,0],[700,0],[850,0]],"id":41435527},{"atb":[[16,0],[44,0],[22,0]],"id":41419651},{"atb":[[8.6,0],[19,0],[11.5,0]],"id":41419639},{"atb":[[32,0],[80,0],[21,0]],"id":41419656},{"atb":[[600,0],[700,0],[850,0]],"id":41419652},{"atb":[[360,0],[210,0],[110,0]],"id":41435528},{"atb":[[580,0],[330,0],[430,0]],"id":41419660},{"atb":[[36,0],[19,0],[14,0]],"id":41419636},{"atb":[[600,0],[700,0],[850,0]],"id":41419657},{"atb":[[520,0],[620,0],[770,0]],"id":41435525},{"atb":[[600,0],[700,0],[850,0]],"id":41419653},{"atb":[[17,0],[12,0],[29,2.72]],"id":41419637},{"atb":[[270,0],[120,0],[60,2.72]],"id":41435526},{"atb":[[600,0],[700,0],[850,0]],"id":41419658}],"con":true,"img":false}]}
{"op":"mcm","clk":"5348064442","pt":1646213373318,"mc":[{"id":"1.195453723","rc":[{"atl":[[1000,2]],"id":41419655},{"atl":[[670,0],[650,2]],"id":41419651},{"atl":[[880,0],[870,2]],"id":41419601},{"atl":[[590,0],[580,2]],"id":41419639},{"atl":[[480,2],[510,0]],"id":41419635},{"atl":[[380,0],[370,2]],"id":41419594},{"atl":[[540,2],[550,0]],"id":41419607},{"atl":[[620,2],[650,0]],"id":41419636},{"atl":[[710,2],[740,0]],"id":41419608},{"atl":[[720,2],[790,0]],"id":41419637},{"atb":[[8.6,6.54],[10,0]],"id":41419612},{"atl":[[800,2],[840,0]],"id":41419612},{"atl":[[670,2],[720,0]],"id":41419592}],"con":true,"img":false}]}
{"op":"mcm","clk":"5348064705","pt":1646213378233,"mc":[{"id":"1.195453723","rc":[{"atb":[[65,6.88],[130,1.54],[280,0.71]],"id":41419638},{"atb":[[260,0.77],[160,1.67],[410,0.49]],"id":41419634},{"atb":[[130,1.54],[46,4.44],[28,13.56]],"id":41419617},{"atb":[[600,0.44],[700,0.28],[850,0.23]],"id":41419613},{"atb":[[620,0.32],[370,0.71],[470,0.42]],"id":41419655},{"atb":[[10.5,28.03],[26,10.71],[15.5,13.77]],"id":41419622},{"atb":[[600,0.44],[700,0.28],[850,0.23]],"id":41435527},{"atb":[[18.5,11.41],[11,19.97],[8.4,35.99]],"id":41419626},{"atb":[[8.6,35.05],[19,11.1],[11.5,19.02]],"id":41419639},{"atb":[[6.4,36.99],[5.2,63.42],[9.4,23.78]],"id":41419635},{"atb":[[16.5,17.18],[46,4.44],[23,9.07]],"id":41419614},{"atb":[[36,5.7],[90,4.97],[23,12.1]],"id":41419656},{"atb":[[9.2,32.48],[21,9.98],[13,16.64]],"id":41419623},{"atb":[[360,0.55],[210,0.95],[110,2.44]],"id":41435528},{"atb":[[330,0.6],[90,6.26],[180,1.11]],"id":41419619},{"atb":[[560,0.35],[710,0.28],[460,0.57]],"id":41419660},{"atb":[[600,0.44],[700,0.28],[850,0.23]],"id":28546950},{"atb":[[40,5.12],[20,10.51],[15,19.02]],"id":41419636},{"atb":[[620,0.32],[370,0.71],[470,0.42]],"id":41419615},{"atb":[[600,0.44],[700,0.28],[850,0.23]],"id":41419657},{"atb":[[36,5.7],[90,2.24],[23,12.1]],"id":41419624},{"atb":[[600,0.44],[700,0.28],[850,0.23]],"id":41419653},{"atb":[[150,1.34],[50,4.07],[30,9.18]],"id":41419620},{"atb":[[32,6.44],[18,11.74],[13,22.19]],"id":41419637},{"atb":[[310,0.64],[210,1.27],[460,0.43]],"id":41419616},{"atb":[[260,0.77],[110,1.83],[55,4.93]],"id":41435526},{"atb":[[3.6,102.45],[5.7,42.5],[4.2,62.43]],"id":41419621},{"atb":[[600,0.44],[700,0.28],[850,0.23]],"id":41419658}],"con":true,"img":false}]}
{"op":"mcm","clk":"5348064709","pt":1646213378336,"mc":[{"id":"1.195453723","rc":[{"atb":[[260,0.77],[160,1.67],[410,0.49]],"id":41419609},{"atb":[[42,7.59],[21,9.98],[15.5,18.37]],"id":41419605},{"atb":[[5.1,64.97],[9.2,24.36],[6.2,38.42]],"id":41419593},{"atb":[[85,2.37],[44,6.19],[220,0.91]],"id":41419589},{"atb":[[16.5,17.18],[46,4.44],[23,9.07]],"id":41419651},{"atb":[[17,16.64],[48,6.97],[24,8.68]],"id":41419601},{"atb":[[600,0.44],[700,0.28],[850,0.23]],"id":28546943},{"atb":[[580,0.34],[330,0.81],[430,0.46]],"id":41419606},{"atb":[[570,0.34],[320,0.83],[420,0.47]],"id":41419602},{"atb":[[18.5,15.22],[27,7.68],[60,3.38]],"id":41419585},{"atb":[[24,8.68],[9.8,30.27],[14.5,14.8]],"id":41419610},{"atb":[[600,0.44],[700,0.28],[850,0.23]],"id":41419652},{"atb":[[600,0.44],[700,0.28],[850,0.23]],"id":41419586},{"atb":[[3.95,90.29],[6.8,34.44],[4.9,51.22]],"id":41419598},{"atb":[[8,31.81],[4.5,76.11],[5.5,44.4]],"id":41419594},{"atb":[[6.2,51.22],[8.2,27.75],[13,16.64]],"id":41419607},{"atb":[[16,13.31],[11,26.63],[27,7.68]],"id":41419603},{"atb":[[330,0.6],[230,1.16],[480,0.41]],"id":41419591},{"atb":[[600,0.44],[700,0.28],[850,0.23]],"id":41435525},{"atb":[[650,0.3],[400,0.67],[500,0.39]],"id":41419587},{"atb":[[550,0.48],[650,0.3],[800,0.25]],"id":41419599},{"atb":[[17,12.48],[12,24.21],[29,7.13]],"id":41419595},{"atb":[[16.5,17.18],[46,4.44],[23,9.07]],"id":41419608},{"atb":[[32,9.17],[18,11.74],[13,22.19]],"id":41419612},{"atb":[[36,5.7],[19,11.1],[14,20.49]],"id":41419592},{"atb":[[600,0.44],[700,0.28],[850,0.23]],"id":41419588},{"atb":[[16,13.31],[7.4,41.62],[9.4,23.78]],"id":41419600},{"atb":[[3.35,85.01],[4.2,62.43],[2.94,137.31]],"id":41419596}],"con":true,"img":false}]}
{"op":"mcm","clk":"5348064722","pt":1646213378500,"mc":[{"id":"1.195453723","rc":[{"atb":[[5.5,0],[6,20]],"id":41419622}],"con":true,"img":false}]}
{"op":"mcm","clk":"5348067401","pt":1646213423982,"mc":[{"id":"1.195453723","rc":[{"atb":[[42,2.72],[21,0],[15.5,0]],"id":41419605},{"atb":[[5.1,0],[9.2,0],[6.2,0]],"id":41419593},{"atb":[[85,0],[44,0],[220,0]],"id":41419589},{"atb":[[17,0],[48,2.72],[24,0]],"id":41419601},{"atb":[[600,0],[700,0],[850,0]],"id":28546943},{"atb":[[570,0],[320,0],[420,0]],"id":41419602},{"atb":[[18.5,0],[27,0],[60,0]],"id":41419585},{"atb":[[600,0],[700,0],[850,0]],"id":41419586},{"atb":[[3.95,0],[6.8,0],[4.9,0]],"id":41419598},{"atb":[[8,3.26],[4.5,0],[5.5,0]],"id":41419594},{"atb":[[600,0],[700,0],[850,0]],"id":28546950},{"atb":[[16,0],[11,0],[27,0]],"id":41419603},{"atb":[[330,0],[230,0],[480,0]],"id":41419591},{"atb":[[650,0],[400,0],[500,0]],"id":41419587},{"atb":[[550,0],[650,0],[800,0]],"id":41419599},{"atb":[[17,0],[12,0],[29,0]],"id":41419595},{"atb":[[36,0],[19,0],[14,0]],"id":41419592},{"atb":[[600,0],[700,0],[850,0]],"id":41419588},{"atb":[[16,0],[7.4,0],[9.4,0]],"id":41419600},{"atb":[[3.35,0],[4.2,0],[2.94,0]],"id":41419596}],"con":true,"img":false}]}
{"op":"mcm","clk":"5348067410","pt":1646213424190,"mc":[{"id":"1.195453723","rc":[{"atb":[[260,0],[160,0],[410,0]],"id":41419609},{"atb":[[260,0],[160,0],[410,0]],"id":41419634},{"atb":[[130,0],[46,0],[28,3.7]],"id":41419617},{"atb":[[600,0],[700,0],[850,0]],"id":41419613},{"atb":[[10.5,0],[26,2.72],[15.5,0]],"id":41419622},{"atb":[[18.5,0],[11,0],[8.4,0]],"id":41419626},{"atb":[[580,0],[330,0],[430,0]],"id":41419606},{"atb":[[6.4,0],[5.2,0],[9.4,0]],"id":41419635},{"atb":[[16.5,0],[46,0],[23,0]],"id":41419614},{"atb":[[24,0],[9.8,0],[14.5,0]],"id":41419610},{"atb":[[9.2,0],[21,0],[13,0]],"id":41419623},{"atb":[[330,0],[180,0],[90,3.26]],"id":41419619},{"atb":[[6.2,0],[8.2,0],[13,0]],"id":41419607},{"atb":[[620,0],[370,0],[470,0]],"id":41419615},{"atb":[[36,0],[90,0],[23,0]],"id":41419624},{"atb":[[150,0],[50,0],[30,0]],"id":41419620},{"atb":[[16.5,0],[46,0],[23,0]],"id":41419608},{"atb":[[310,0],[210,0],[460,0]],"id":41419616},{"atb":[[32,2.72],[18,0],[13,0]],"id":41419612},{"atb":[[3.6,0],[5.7,0],[4.2,0]],"id":41419621}],"con":true,"img":false}]}
{"op":"mcm","clk":"5348067413","pt":1646213424293,"mc":[{"id":"1.195453723","rc":[{"atb":[[130,0],[65,2.72],[280,0]],"id":41419638},{"atb":[[620,0],[370,0],[470,0]],"id":41419655},{"atb":[[600,0],[700,0],[850,0]],"id":41435527},{"atb":[[16.5,0],[46,0],[23,0]],"id":41419651},{"atb":[[8.6,0],[19,0],[11.5,0]],"id":41419639},{"atb":[[36,0],[90,2.72],[23,0]],"id":41419656},{"atb":[[600,0],[700,0],[850,0]],"id":41419652},{"atb":[[360,0],[210,0],[110,0]],"id":41435528},{"atb":[[560,0],[710,0],[460,0]],"id":41419660},{"atb":[[40,0],[20,0],[15,0]],"id":41419636},{"atb":[[600,0],[700,0],[850,0]],"id":41419657},{"atb":[[600,0],[700,0],[850,0]],"id":41435525},{"atb":[[600,0],[700,0],[850,0]],"id":41419653},{"atb":[[32,0],[18,0],[13,0]],"id":41419637},{"atb":[[260,0],[110,0],[55,0]],"id":41435526},{"atb":[[600,0],[700,0],[850,0]],"id":41419658}],"con":true,"img":false}]}
{"op":"mcm","clk":"5348067859","pt":1646213433485,"mc":[{"id":"1.195453723","rc":[{"atb":[[9.6,0],[8.6,0]],"id":41419621}],"con":true,"img":false}]}
{"op":"mcm","clk":"5348067863","pt":1646213433587,"mc":[{"id":"1.195453723","rc":[{"atb":[[21,0],[26,0]],"id":41419622},{"atb":[[16.5,0],[19,0]],"id":41419626},{"atb":[[19,0],[23,0]],"id":41419623},{"atb":[[5.5,0],[6,0]],"id":41419596}],"con":true,"img":false}]}
{"op":"mcm","clk":"5348067896","pt":1646213434206,"mc":[{"id":"1.195453723","rc":[{"atb":[[8.8,2.72],[7.8,3.26]],"id":41419621}],"con":true,"img":false}]}
{"op":"mcm","clk":"5348067901","pt":1646213434310,"mc":[{"id":"1.195453723","rc":[{"atb":[[20,3.26],[25,2.72]],"id":41419622},{"atb":[[17.5,2.72],[15,3.26]],"id":41419626},{"atb":[[18,3.26],[21,2.72]],"id":41419623},{"atb":[[5.8,2.72],[5.3,3.26]],"id":41419596}],"con":true,"img":false}]}
{"op":"mcm","clk":"5348068380","pt":1646213442982,"mc":[{"id":"1.195453723","rc":[{"atb":[[310,0.64],[210,1.27],[460,0.43]],"id":41419609},{"atb":[[260,0.77],[110,1.83],[55,4.93]],"id":41419638},{"atb":[[40,5.12],[20,10.51],[15,19.02]],"id":41419605},{"atb":[[130,2.06],[380,0.52],[230,0.87]],"id":41419634},{"atb":[[44,4.64],[27,10.24],[120,1.67]],"id":41419617},{"atb":[[600,0.44],[700,0.28],[850,0.23]],"id":41419613},{"atb":[[5.1,64.97],[9.2,24.36],[6.2,38.42]],"id":41419593},{"atb":[[580,0.34],[330,0.81],[430,0.46]],"id":41419655},{"atb":[[10,29.59],[25,11.04],[15,14.27]],"id":41419622},{"atb":[[75,2.69],[40,6.82],[200,1]],"id":41419589},{"atb":[[600,0.44],[700,0.28],[850,0.23]],"id":41435527},{"atb":[[16,17.76],[44,4.64],[22,9.51]],"id":41419651},{"atb":[[17,16.64],[48,6.97],[24,8.68]],"id":41419601},{"atb":[[600,0.44],[700,0.28],[850,0.23]],"id":28546943},{"atb":[[18,11.74],[10.5,21.03],[8.2,36.99]],"id":41419626},{"atb":[[18.5,14.68],[11,19.97],[8.4,35.99]],"id":41419639},{"atb":[[650,0.3],[400,0.67],[500,0.39]],"id":41419606},{"atb":[[5.1,64.97],[9.2,24.36],[6.2,38.42]],"id":41419635},{"atb":[[540,0.37],[290,0.92],[390,0.51]],"id":41419602},{"atb":[[18,15.66],[26,7.98],[55,6.97]],"id":41419585},{"atb":[[16.5,17.18],[46,4.44],[23,9.07]],"id":41419614},{"atb":[[10.5,28.03],[26,7.98],[15.5,13.77]],"id":41419610},{"atb":[[34,6.05],[85,2.37],[22,12.68]],"id":41419656},{"atb":[[22,9.51],[13.5,15.98],[9.4,31.71]],"id":41419623},{"atb":[[600,0.44],[700,0.28],[850,0.23]],"id":41419652},{"atb":[[330,0.6],[90,6.26],[180,1.11]],"id":41435528},{"atb":[[310,0.64],[160,1.25],[80,3.37]],"id":41419619},{"atb":[[560,0.47],[660,0.3],[810,0.24]],"id":41419586},{"atb":[[4.8,52.57],[6.6,35.67],[3.9,91.85]],"id":41419598},{"atb":[[520,0.38],[670,0.29],[420,0.63]],"id":41419660},{"atb":[[4.8,70.1],[8.6,26.29],[5.8,41.62]],"id":41419594},{"atb":[[6.8,45.93],[8.8,25.61],[14.5,14.8]],"id":41419607},{"atb":[[600,0.44],[700,0.28],[850,0.23]],"id":28546950},{"atb":[[38,5.4],[19.5,10.8],[14.5,19.73]],"id":41419636},{"atb":[[16,13.31],[11,26.63],[27,7.68]],"id":41419603},{"atb":[[580,0.34],[330,0.81],[430,0.46]],"id":41419615},{"atb":[[600,0.44],[700,0.28],[850,0.23]],"id":41419657},{"atb":[[34,6.05],[85,2.37],[22,12.68]],"id":41419624},{"atb":[[300,0.67],[200,1.34],[450,0.44]],"id":41419591},{"atb":[[600,0.44],[700,0.28],[850,0.23]],"id":41435525},{"atb":[[600,0.44],[700,0.28],[850,0.23]],"id":41419653},{"atb":[[130,1.54],[46,4.44],[28,9.86]],"id":41419620},{"atb":[[560,0.35],[710,0.28],[460,0.57]],"id":41419587},{"atb":[[600,0.33],[750,0.26],[500,0.53]],"id":41419599},{"atb":[[17,12.48],[12,24.21],[29,7.13]],"id":41419595},{"atb":[[17,16.64],[48,4.25],[24,8.68]],"id":41419608},{"atb":[[34,6.05],[18.5,11.41],[13.5,21.3]],"id":41419637},{"atb":[[350,0.57],[500,0.39],[250,1.06]],"id":41419616},{"atb":[[36,5.7],[19,11.1],[14,20.49]],"id":41419612},{"atb":[[36,5.7],[19,11.1],[14,20.49]],"id":41419592},{"atb":[[90,2.24],[46,5.91],[230,0.87]],"id":41435526},{"atb":[[5.6,43.43],[4.1,64.45],[3.55,104.46]],"id":41419621},{"atb":[[600,0.44],[700,0.28],[850,0.23]],"id":41419588},{"atb":[[7.2,42.96],[9.2,24.36],[15.5,13.77]],"id":41419600},{"atb":[[2.92,138.74],[4.1,64.45],[3.3,86.86]],"id":41419596},{"atb":[[600,0.44],[700,0.28],[850,0.23]],"id":41419658}],"con":true,"img":false}]}
{"op":"mcm","clk":"5348069529","pt":1646213462529,"mc":[{"id":"1.195453723","rc":[{"atl":[[1000,0]],"id":41419655},{"atb":[[8.6,0],[10,11.11]],"id":41419612}],"con":true,"img":false}]}
{"op":"mcm","clk":"5348071344","pt":1646213497296,"mc":[{"id":"1.195453723","rc":[{"atb":[[250,0]],"id":28546943}],"con":true,"img":false}]}
{"op":"mcm","clk":"5348071348","pt":1646213497399,"mc":[{"id":"1.195453723","rc":[{"atb":[[300,0]],"id":28546943}],"con":true,"img":false}]}
{"op":"mcm","clk":"5348071367","pt":1646213497810,"mc":[{"id":"1.195453723","rc":[{"atb":[[290,0],[240,0]],"id":41419613},{"atb":[[70,0],[95,0]],"id":41419589}],"con":true,"img":false}]}
{"op":"mcm","clk":"5348071377","pt":1646213498016,"mc":[{"id":"1.195453723","rc":[{"atb":[[280,3.26]],"id":28546943}],"con":true,"img":false}]}
{"op":"mcm","clk":"5348071381","pt":1646213498118,"mc":[{"id":"1.195453723","rc":[{"atb":[[130,0],[90,0]],"id":41419587}],"con":true,"img":false}]}
{"op":"mcm","clk":"5348071384","pt":1646213498223,"mc":[{"id":"1.195453723","rc":[{"atb":[[330,2.72]],"id":28546943},{"atb":[[150,0],[100,0]],"id":41419586}],"con":true,"img":false}]}
{"op":"mcm","clk":"5348071394","pt":1646213498584,"mc":[{"id":"1.195453723","rc":[{"atb":[[300,2.72],[250,3.26]],"id":41419613},{"atb":[[80,3.26],[110,2.72]],"id":41419589}],"con":true,"img":false}]}
{"op":"mcm","clk":"5348071402","pt":1646213498789,"mc":[{"id":"1.195453723","rc":[{"atb":[[140,2.72],[95,3.26]],"id":41419587},{"atb":[[75,0],[100,0]],"id":41419599}],"con":true,"img":false}]}
{"op":"mcm","clk":"5348071410","pt":1646213498895,"mc":[{"id":"1.195453723","rc":[{"atb":[[160,2.72],[110,3.26]],"id":41419586}],"con":true,"img":false}]}
{"op":"mcm","clk":"5348071447","pt":1646213499616,"mc":[{"id":"1.195453723","rc":[{"atb":[[80,3.26],[110,2.72]],"id":41419599}],"con":true,"img":false}]}
{"op":"mcm","clk":"5348071863","pt":1646213507434,"mc":[{"id":"1.195453723","rc":[{"atb":[[38,0],[48,0]],"id":41419620}],"con":true,"img":false}]}
{"op":"mcm","clk":"5348071894","pt":1646213508107,"mc":[{"id":"1.195453723","rc":[{"atb":[[40,3.26],[50,2.72]],"id":41419620}],"con":true,"img":false}]}
{"op":"mcm","clk":"5348072213","pt":1646213514654,"mc":[{"id":"1.195453723","rc":[{"atb":[[40,0],[20,0],[15,0]],"id":41419605},{"atb":[[5.1,0],[9.2,0],[6.2,0]],"id":41419593},{"atb":[[75,0],[40,0],[200,0]],"id":41419589},{"atb":[[17,0],[48,2.72],[24,0]],"id":41419601},{"atb":[[600,0],[700,0],[850,0]],"id":28546943},{"atb":[[540,0],[290,0],[390,0]],"id":41419602},{"atb":[[18,0],[26,0],[55,3.26]],"id":41419585},{"atb":[[560,0],[660,0],[810,0]],"id":41419586},{"atb":[[4.8,0],[6.6,0],[3.9,0]],"id":41419598},{"atb":[[4.8,0],[8.6,0],[5.8,0]],"id":41419594},{"atb":[[600,0],[700,0],[850,0]],"id":28546950},{"atb":[[16,0],[11,0],[27,0]],"id":41419603},{"atb":[[300,0],[200,0],[450,0]],"id":41419591},{"atb":[[560,0],[710,0],[460,0]],"id":41419587},{"atb":[[600,0],[750,0],[500,0]],"id":41419599},{"atb":[[17,0],[12,0],[29,0]],"id":41419595},{"atb":[[36,0],[19,0],[14,0]],"id":41419592},{"atb":[[600,0],[700,0],[850,0]],"id":41419588},{"atb":[[7.2,0],[9.2,0],[15.5,0]],"id":41419600},{"atb":[[2.92,0],[4.1,0],[3.3,0]],"id":41419596}],"con":true,"img":false}]}
{"op":"mcm","clk":"5348072217","pt":1646213514706,"mc":[{"id":"1.195453723","rc":[{"atb":[[310,0],[210,0],[460,0]],"id":41419609},{"atb":[[130,0],[380,0],[230,0]],"id":41419634},{"atb":[[44,0],[27,0],[120,0]],"id":41419617},{"atb":[[600,0],[700,0],[850,0]],"id":41419613},{"atb":[[10,0],[25,2.72],[15,0]],"id":41419622},{"atb":[[18,0],[10.5,0],[8.2,0]],"id":41419626},{"atb":[[650,0],[400,0],[500,0]],"id":41419606},{"atb":[[5.1,0],[9.2,0],[6.2,0]],"id":41419635},{"atb":[[16.5,0],[46,0],[23,0]],"id":41419614},{"atb":[[10.5,0],[26,0],[15.5,0]],"id":41419610},{"atb":[[22,0],[13.5,0],[9.4,0]],"id":41419623},{"atb":[[310,0],[160,0],[80,0]],"id":41419619},{"atb":[[6.8,0],[8.8,0],[14.5,0]],"id":41419607},{"atb":[[580,0],[330,0],[430,0]],"id":41419615},{"atb":[[34,0],[85,0],[22,0]],"id":41419624},{"atb":[[130,0],[46,0],[28,0]],"id":41419620},{"atb":[[17,0],[48,0],[24,0]],"id":41419608},{"atb":[[350,0],[500,0],[250,0]],"id":41419616},{"atb":[[36,0],[19,0],[14,0]],"id":41419612},{"atb":[[5.6,0],[4.1,0],[3.55,0]],"id":41419621}],"con":true,"img":false}]}
{"op":"mcm","clk":"5348072220","pt":1646213514813,"mc":[{"id":"1.195453723","rc":[{"atb":[[260,0],[110,0],[55,0]],"id":41419638},{"atb":[[580,0],[330,0],[430,0]],"id":41419655},{"atb":[[600,0],[700,0],[850,0]],"id":41435527},{"atb":[[16,0],[44,0],[22,0]],"id":41419651},{"atb":[[18.5,3.26],[11,0],[8.4,0]],"id":41419639},{"atb":[[34,0],[85,0],[22,0]],"id":41419656},{"atb":[[600,0],[700,0],[850,0]],"id":41419652},{"atb":[[330,0],[180,0],[90,3.26]],"id":41435528},{"atb":[[520,0],[670,0],[420,0]],"id":41419660},{"atb":[[38,0],[19.5,0],[14.5,0]],"id":41419636},{"atb":[[600,0],[700,0],[850,0]],"id":41419657},{"atb":[[600,0],[700,0],[850,0]],"id":41435525},{"atb":[[600,0],[700,0],[850,0]],"id":41419653},{"atb":[[34,0],[18.5,0],[13.5,0]],"id":41419637},{"atb":[[90,0],[46,0],[230,0]],"id":41435526},{"atb":[[600,0],[700,0],[850,0]],"id":41419658}],"con":true,"img":false}]}
{"op":"mcm","clk":"5348072662","pt":1646213523732,"mc":[{"id":"1.195453723","rc":[{"atb":[[85,0],[60,0]],"id":41419609},{"atb":[[32,0],[42,0]],"id":41419605},{"atb":[[80,0],[110,0]],"id":41419617},{"atb":[[75,0],[50,0]],"id":41419655},{"atb":[[170,0],[120,0]],"id":41435527},{"atb":[[25,0],[30,0]],"id":41419651},{"atb":[[38,0],[48,0]],"id":41419601},{"atb":[[80,0],[110,0]],"id":41419602},{"atb":[[80,0],[55,0]],"id":41419614},{"atb":[[65,0],[90,0]],"id":41419656},{"atb":[[85,0],[120,0]],"id":41419652},{"atb":[[130,0],[90,0]],"id":41435528},{"atb":[[130,0],[90,0]],"id":41419619},{"atb":[[150,0],[100,0]],"id":41419660},{"atb":[[8,0],[9,0]],"id":41419594},{"atb":[[170,0],[120,0]],"id":41419615},{"atb":[[140,0],[190,0]],"id":41419657},{"atb":[[65,0],[90,0]],"id":41435525},{"atb":[[300,0],[350,0]],"id":41419653},{"atb":[[32,0],[42,0]],"id":41419608},{"atb":[[24,0],[29,0]],"id":41419637},{"atb":[[140,0],[95,0]],"id":41419616},{"atb":[[32,0],[26,0]],"id":41419612},{"atb":[[5.8,0],[5.3,0]],"id":41419596},{"atb":[[320,0],[370,0]],"id":41419658}],"con":true,"img":false}]}
{"op":"mcm","clk":"5348072663","pt":1646213523833,"mc":[{"id":"1.195453723","rc":[{"atb":[[65,0],[46,0]],"id":41419638},{"atb":[[23,0],[28,0]],"id":41419610},{"atb":[[16.5,0],[19,0]],"id":41419607},{"atb":[[44,0],[60,0]],"id":41435526}],"con":true,"img":false}]}
{"op":"mcm","clk":"5348072665","pt":1646213523938,"mc":[{"id":"1.195453723","rc":[{"atb":[[6.4,18.52],[6.6,0]],"id":41419651},{"atb":[[28,3.7],[29,0]],"id":41435528},{"atb":[[22,4.76],[25,0]],"id":41435526}],"con":true,"img":false}]}
{"op":"mcm","clk":"5348072686","pt":1646213524457,"mc":[{"id":"1.195453723","rc":[{"atb":[[75,3.26],[100,2.72]],"id":41419609},{"atb":[[34,3.26],[44,2.72]],"id":41419605},{"atb":[[130,2.72],[90,3.26]],"id":41419617},{"atb":[[85,2.72],[60,3.26]],"id":41419655},{"atb":[[170,3.26],[220,2.72]],"id":41435527},{"atb":[[32,2.72],[26,3.26]],"id":41419651},{"atb":[[42,3.26],[55,2.72]],"id":41419601},{"atb":[[85,3.26],[120,2.72]],"id":41419602},{"atb":[[65,3.26],[90,2.72]],"id":41419614},{"atb":[[80,3.26],[110,2.72]],"id":41419656},{"atb":[[140,2.72],[95,3.26]],"id":41419652},{"atb":[[160,2.72],[110,3.26]],"id":41435528},{"atb":[[150,2.72],[100,3.26]],"id":41419619},{"atb":[[130,3.26],[180,2.72]],"id":41419660},{"atb":[[9.2,2.72],[8.2,3.26]],"id":41419594},{"atb":[[150,3.26],[200,2.72]],"id":41419615},{"atb":[[190,3.26],[240,2.72]],"id":41419657},{"atb":[[85,3.26],[120,2.72]],"id":41435525},{"atb":[[420,3.26],[470,2.72]],"id":41419653},{"atb":[[38,3.26],[48,2.72]],"id":41419608},{"atb":[[32,2.72],[26,3.26]],"id":41419637},{"atb":[[130,3.26],[180,2.72]],"id":41419616},{"atb":[[36,2.72],[28,3.26]],"id":41419612},{"atb":[[5.2,3.26],[5.7,2.72]],"id":41419596},{"atb":[[460,3.26],[510,2.72]],"id":41419658}],"con":true,"img":false}]}
{"op":"mcm","clk":"5348072689","pt":1646213524557,"mc":[{"id":"1.195453723","rc":[{"atb":[[75,2.72],[50,3.26]],"id":41419638},{"atb":[[18,3.26],[21,2.72]],"id":41419607},{"atb":[[65,2.72],[46,3.26]],"id":41435526}],"con":true,"img":false}]}
{"op":"mcm","clk":"5348072736","pt":1646213525333,"mc":[{"id":"1.195453723","rc":[{"atb":[[25,3.26],[30,2.72]],"id":41419610}],"con":true,"img":false}]}
{"op":"mcm","clk":"5348072994","pt":1646213528869,"mc":[{"id":"1.195453723","rc":[{"atb":[[310,0.64],[210,1.27],[460,0.43]],"id":41419609},{"atb":[[260,0.77],[110,1.83],[55,4.93]],"id":41419638},{"atb":[[40,5.12],[20,10.51],[15,19.02]],"id":41419605},{"atb":[[130,2.06],[380,0.52],[230,0.87]],"id":41419634},{"atb":[[44,4.64],[27,10.24],[120,1.67]],"id":41419617},{"atb":[[600,0.44],[700,0.28],[850,0.23]],"id":41419613},{"atb":[[5.1,64.97],[9.2,24.36],[6.2,38.42]],"id":41419593},{"atb":[[580,0.34],[330,0.81],[430,0.46]],"id":41419655},{"atb":[[10,29.59],[25,11.04],[15,14.27]],"id":41419622},{"atb":[[75,2.69],[40,6.82],[200,1]],"id":41419589},{"atb":[[600,0.44],[700,0.28],[850,0.23]],"id":41435527},{"atb":[[16,17.76],[44,4.64],[22,9.51]],"id":41419651},{"atb":[[17,16.64],[48,4.25],[24,8.68]],"id":41419601},{"atb":[[600,0.44],[700,0.28],[850,0.23]],"id":28546943},{"atb":[[18,11.74],[10.5,21.03],[8.2,36.99]],"id":41419626},{"atb":[[18.5,14.68],[11,19.97],[8.4,35.99]],"id":41419639},{"atb":[[650,0.3],[400,0.67],[500,0.39]],"id":41419606},{"atb":[[5.1,64.97],[9.2,24.36],[6.2,38.42]],"id":41419635},{"atb":[[540,0.37],[290,0.92],[390,0.51]],"id":41419602},{"atb":[[18,15.66],[26,7.98],[55,6.97]],"id":41419585},{"atb":[[16.5,17.18],[46,4.44],[23,9.07]],"id":41419614},{"atb":[[10.5,28.03],[26,7.98],[15.5,13.77]],"id":41419610},{"atb":[[34,6.05],[85,2.37],[22,12.68]],"id":41419656},{"atb":[[22,9.51],[13.5,15.98],[9.4,31.71]],"id":41419623},{"atb":[[600,0.44],[700,0.28],[850,0.23]],"id":41419652},{"atb":[[330,0.6],[180,1.11],[90,2.99]],"id":41435528},{"atb":[[310,0.64],[160,1.25],[80,3.37]],"id":41419619},{"atb":[[560,0.47],[660,0.3],[810,0.24]],"id":41419586},{"atb":[[4.8,52.57],[6.6,35.67],[3.9,91.85]],"id":41419598},{"atb":[[520,0.38],[670,0.29],[420,0.63]],"id":41419660},{"atb":[[4.8,70.1],[8.6,26.29],[5.8,41.62]],"id":41419594},{"atb":[[6.8,45.93],[8.8,25.61],[14.5,14.8]],"id":41419607},{"atb":[[600,0.44],[700,0.28],[850,0.23]],"id":28546950},{"atb":[[38,5.4],[19.5,10.8],[14.5,19.73]],"id":41419636},{"atb":[[16,13.31],[11,26.63],[27,7.68]],"id":41419603},{"atb":[[580,0.34],[330,0.81],[430,0.46]],"id":41419615},{"atb":[[600,0.44],[700,0.28],[850,0.23]],"id":41419657},{"atb":[[34,6.05],[85,2.37],[22,12.68]],"id":41419624},{"atb":[[300,0.67],[200,1.34],[450,0.44]],"id":41419591},{"atb":[[600,0.44],[700,0.28],[850,0.23]],"id":41435525},{"atb":[[600,0.44],[700,0.28],[850,0.23]],"id":41419653},{"atb":[[130,1.54],[46,4.44],[28,9.86]],"id":41419620},{"atb":[[560,0.35],[710,0.28],[460,0.57]],"id":41419587},{"atb":[[600,0.33],[750,0.26],[500,0.53]],"id":41419599},{"atb":[[17,12.48],[12,24.21],[29,7.13]],"id":41419595},{"atb":[[17,16.64],[48,6.97],[24,8.68]],"id":41419608},{"atb":[[34,6.05],[18.5,11.41],[13.5,21.3]],"id":41419637},{"atb":[[350,0.57],[500,0.39],[250,1.06]],"id":41419616},{"atb":[[36,8.43],[19,11.1],[14,20.49]],"id":41419612},{"atb":[[36,5.7],[19,11.1],[14,20.49]],"id":41419592},{"atb":[[90,2.24],[46,9.18],[230,0.87]],"id":41435526},{"atb":[[5.6,43.43],[4.1,64.45],[3.55,104.46]],"id":41419621},{"atb":[[600,0.44],[700,0.28],[850,0.23]],"id":41419588},{"atb":[[7.2,42.96],[9.2,24.36],[15.5,13.77]],"id":41419600},{"atb":[[2.92,138.74],[4.1,64.45],[3.3,86.86]],"id":41419596},{"atb":[[600,0.44],[700,0.28],[850,0.23]],"id":41419658}],"con":true,"img":false}]}
{"op":"mcm","clk":"5348074534","pt":1646213557179,"mc":[{"id":"1.195453723","rc":[{"atb":[[65,0],[46,0]],"id":41419634},{"atb":[[80,0],[55,0]],"id":41419606},{"atb":[[310,0],[360,0]],"id":28546950}],"con":true,"img":false}]}
{"op":"mcm","clk":"5348074545","pt":1646213557384,"mc":[{"id":"1.195453723","rc":[{"atb":[[21,0],[26,0]],"id":41419595},{"atb":[[260,0],[310,0]],"id":41419588}],"con":true,"img":false}]}
{"op":"mcm","clk":"5348074576","pt":1646213557900,"mc":[{"id":"1.195453723","rc":[{"atb":[[70,2.72]],"id":41419634},{"atb":[[90,2.72]],"id":41419606},{"atb":[[410,3.26],[460,2.72]],"id":28546950}],"con":true,"img":false}]}
{"op":"mcm","clk":"5348074581","pt":1646213558004,"mc":[{"id":"1.195453723","rc":[{"atb":[[48,3.26]],"id":41419634},{"atb":[[65,3.26]],"id":41419606}],"con":true,"img":false}]}
{"op":"mcm","clk":"5348074598","pt":1646213558163,"mc":[{"id":"1.195453723","rc":[{"atb":[[23,3.26],[28,2.72]],"id":41419595},{"atb":[[310,3.26],[360,2.72]],"id":41419588}],"con":true,"img":false}]}
{"op":"mcm","clk":"5348075283","pt":1646213568751,"mc":[{"id":"1.195453723","rc":[{"atb":[[34,0],[27,0]],"id":41419636}],"con":true,"img":false}]}
{"op":"mcm","clk":"5348075338","pt":1646213569434,"mc":[{"id":"1.195453723","rc":[{"atb":[[36,2.72],[28,3.26]],"id":41419636}],"con":true,"img":false}]}
{"op":"mcm","clk":"5348076129","pt":1646213582564,"mc":[{"id":"1.195453723","rc":[{"atb":[[6,0],[5.2,23.81]],"id":41419622}],"con":true,"img":false}]}
{"op":"mcm","clk":"5348077443","pt":1646213599888,"mc":[{"id":"1.195453723","rc":[{"atb":[[7.4,0],[8.4,0]],"id":41419593}],"con":true,"img":false}]}
{"op":"mcm","clk":"5348077506","pt":1646213600713,"mc":[{"id":"1.195453723","rc":[{"atb":[[8.6,2.72],[7.6,3.26]],"id":41419593}],"con":true,"img":false}]}
{"op":"mcm","clk":"5348078312","pt":1646213613218,"mc":[{"id":"1.195453723","rc":[{"atl":[[1000,2]],"id":41419655},{"atb":[[6,20],[5.2,0]],"id":41419622},{"atb":[[8.6,13.16],[10,0]],"id":41419612}],"con":true,"img":false}]}
{"op":"mcm","clk":"5348078407","pt":1646213614722,"mc":[{"id":"1.195453723","rc":[{"atl":[[1000,0]],"id":41419655}],"con":true,"img":false}]}
{"op":"mcm","clk":"5348078429","pt":1646213615125,"mc":[{"id":"1.195453723","rc":[{"atb":[[8.6,0],[7.6,0]],"id":41419593}],"con":true,"img":false}]}
{"op":"mcm","clk":"5348078479","pt":1646213615914,"mc":[{"id":"1.195453723","rc":[{"atb":[[7.4,3.26],[8.4,2.72]],"id":41419593}],"con":true,"img":false}]}
{"op":"mcm","clk":"5348080641","pt":1646213648356,"mc":[{"id":"1.195453723","rc":[{"atl":[[330,2],[430,0]],"id":41419593},{"atl":[[330,2],[340,0]],"id":41419598},{"atb":[[18.5,5.71],[15.5,0]],"id":41419624},{"atl":[[670,0],[660,2]],"id":41419592},{"atb":[[2.88,53.19]],"id":41419621},{"atb":[[2.52,0],[2.7,58.82]],"id":41419596}],"con":true,"img":false}]}
{"op":"mcm","clk":"5348080649","pt":1646213648457,"mc":[{"id":"1.195453723","rc":[{"atb":[[2.52,0]],"id":41419621}],"con":true,"img":false}]}
{"op":"mcm","clk":"5348082711","pt":1646213682630,"mc":[{"id":"1.195453723","rc":[{"atb":[[20,0],[25,8.32]],"id":41419622},{"atb":[[17.5,0],[15,0]],"id":41419626},{"atb":[[18,0],[21,0]],"id":41419623},{"atb":[[8.8,0],[7.8,0]],"id":41419621}],"con":true,"img":false}]}
{"op":"mcm","clk":"5348082753","pt":1646213683300,"mc":[{"id":"1.195453723","rc":[{"atb":[[21,3.26],[26,2.72]],"id":41419622},{"atb":[[16,3.26],[18.5,2.72]],"id":41419626},{"atb":[[19,3.26],[23,2.72]],"id":41419623},{"atb":[[8,3.26],[9,2.72]],"id":41419621}],"con":true,"img":false}]}
{"op":"mcm","clk":"5348082790","pt":1646213683920,"mc":[{"id":"1.195453723","rc":[{"atb":[[25,0],[30,0]],"id":41419610},{"atb":[[36,0],[28,0]],"id":41419603}],"con":true,"img":false}]}
{"op":"mcm","clk":"5348082830","pt":1646213684643,"mc":[{"id":"1.195453723","rc":[{"atb":[[38,2.72],[29,3.26]],"id":41419603}],"con":true,"img":false}]}
{"op":"mcm","clk":"5348082856","pt":1646213684913,"mc":[{"id":"1.195453723","rc":[{"atb":[[32,2.72],[26,11.25]],"id":41419610}],"con":true,"img":false}]}
{"op":"mcm","clk":"5348083887","pt":1646213703067,"mc":[{"id":"1.195453723","rc":[{"atl":[[330,0],[320,2]],"id":41419598}],"con":true,"img":false}]}
{"op":"mcm","clk":"5348083895","pt":1646213703170,"mc":[{"id":"1.195453723","rc":[{"atl":[[1000,2]],"id":41419655},{"atl":[[660,0],[650,2]],"id":41419592}],"con":true,"img":false}]}
{"op":"mcm","clk":"5348086104","pt":1646213739942,"mc":[{"id":"1.195453723","rc":[{"atb":[[280,0]],"id":28546943}],"con":true,"img":false}]}
{"op":"mcm","clk":"5348086127","pt":1646213740205,"mc":[{"id":"1.195453723","rc":[{"atb":[[330,0]],"id":28546943}],"con":true,"img":false}]}
{"op":"mcm","clk":"5348086154","pt":1646213740615,"mc":[{"id":"1.195453723","rc":[{"atb":[[300,0],[250,0]],"id":41419613}],"con":true,"img":false}]}
{"op":"mcm","clk":"5348086159","pt":1646213740720,"mc":[{"id":"1.195453723","rc":[{"atb":[[360,3.26]],"id":28546943},{"atb":[[110,0]],"id":41419586}],"con":true,"img":false}]}
{"op":"mcm","clk":"5348086164","pt":1646213740821,"mc":[{"id":"1.195453723","rc":[{"atb":[[140,0],[95,0]],"id":41419587}],"con":true,"img":false}]}
{"op":"mcm","clk":"5348086168","pt":1646213740924,"mc":[{"id":"1.195453723","rc":[{"atb":[[410,2.72]],"id":28546943},{"atb":[[160,0]],"id":41419586}],"con":true,"img":false}]}
{"op":"mcm","clk":"5348086195","pt":1646213741340,"mc":[{"id":"1.195453723","rc":[{"atb":[[330,3.26],[380,2.72]],"id":41419613}],"con":true,"img":false}]}
{"op":"mcm","clk":"5348086211","pt":1646213741639,"mc":[{"id":"1.195453723","rc":[{"atb":[[170,2.72],[120,3.26]],"id":41419586},{"atb":[[160,2.72],[110,3.26]],"id":41419587}],"con":true,"img":false}]}
{"op":"mcm","clk":"5348087517","pt":1646213763789,"mc":[{"id":"1.195453723","rc":[{"atb":[[130,0],[180,0]],"id":41419660},{"atb":[[190,0],[240,0]],"id":41419657},{"atb":[[5.2,0],[5.7,0]],"id":41419596}],"con":true,"img":false}]}
{"op":"mcm","clk":"5348087523","pt":1646213763839,"mc":[{"id":"1.195453723","rc":[{"atb":[[420,0],[470,0]],"id":41419653}],"con":true,"img":false}]}
{"op":"mcm","clk":"5348087561","pt":1646213764559,"mc":[{"id":"1.195453723","rc":[{"atb":[[140,3.26],[190,2.72]],"id":41419660},{"atb":[[200,3.26],[250,2.72]],"id":41419657},{"atb":[[5.8,2.72],[5.3,3.26]],"id":41419596}],"con":true,"img":false}]}
{"op":"mcm","clk":"5348087575","pt":1646213764766,"mc":[{"id":"1.195453723","rc":[{"atb":[[430,3.26],[480,2.72]],"id":41419653}],"con":true,"img":false}]}
{"op":"mcm","clk":"5348089683","pt":1646213799107,"mc":[{"id":"1.195453723","rc":[{"atb":[[410,0],[460,0]],"id":28546950}],"con":true,"img":false}]}
{"op":"mcm","clk":"5348089709","pt":1646213799524,"mc":[{"id":"1.195453723","rc":[{"atb":[[65,0],[90,0]],"id":41419606}],"con":true,"img":false}]}
{"op":"mcm","clk":"5348089755","pt":1646213800095,"mc":[{"id":"1.195453723","rc":[{"atb":[[420,3.26],[470,2.72]],"id":28546950}],"con":true,"img":false}]}
{"op":"mcm","clk":"5348089781","pt":1646213800503,"mc":[{"id":"1.195453723","rc":[{"atb":[[70,3.26],[95,2.72]],"id":41419606}],"con":true,"img":false}]}
{"op":"mcm","clk":"5348091028","pt":1646213823154,"mc":[{"id":"1.195453723","rc":[{"atb":[[9,12.5],[10.5,0]],"id":41419605},{"atb":[[4.1,0],[3.65,37.74]],"id":41419635},{"atb":[[7.2,0],[5.9,16.2]],"id":41419636},{"atb":[[8.2,0],[7,16.67]],"id":41419637}],"con":true,"img":false}]}
{"op":"mcm","clk":"5348092269","pt":1646213844602,"mc":[{"id":"1.195453723","rc":[{"atb":[[18.5,11.41],[22,0]],"id":41419639},{"atb":[[11,0],[13.5,0]],"id":41419635},{"atb":[[130,0],[90,0]],"id":41419591}],"con":true,"img":false}]}
{"op":"mcm","clk":"5348092273","pt":1646213844703,"mc":[{"id":"1.195453723","rc":[{"atb":[[75,0],[100,0]],"id":41419609},{"atb":[[75,0],[50,0]],"id":41419638},{"atb":[[85,0],[60,0]],"id":41419655},{"atb":[[410,0]],"id":28546943},{"atb":[[85,0],[120,0]],"id":41419602},{"atb":[[150,0],[100,0]],"id":41419619},{"atb":[[32,0],[26,0]],"id":41419637},{"atb":[[36,5.7],[28,0]],"id":41419612},{"atb":[[310,0],[360,0]],"id":41419588},{"atb":[[5.8,0],[5.3,0]],"id":41419596},{"atb":[[460,0],[510,0]],"id":41419658}],"con":true,"img":false}]}
{"op":"mcm","clk":"5348092307","pt":1646213845272,"mc":[{"id":"1.195453723","rc":[{"atb":[[19,3.26],[23,2.72]],"id":41419639}],"con":true,"img":false}]}
{"op":"mcm","clk":"5348092312","pt":1646213845376,"mc":[{"id":"1.195453723","rc":[{"atb":[[80,3.26],[110,2.72]],"id":41419609},{"atb":[[80,2.72],[55,8.2]],"id":41419638},{"atb":[[65,3.26],[90,2.72]],"id":41419655},{"atb":[[420,2.72]],"id":28546943},{"atb":[[12,3.26],[14.5,2.72]],"id":41419635},{"atb":[[130,2.72],[90,3.26]],"id":41419602},{"atb":[[160,3.98],[110,3.26]],"id":41419619},{"atb":[[140,2.72],[95,3.26]],"id":41419591},{"atb":[[34,8.77],[27,3.26]],"id":41419637},{"atb":[[38,2.72],[29,3.26]],"id":41419612},{"atb":[[320,3.26],[370,2.72]],"id":41419588},{"atb":[[5.2,3.26],[5.7,2.72]],"id":41419596},{"atb":[[530,2.72],[480,3.26]],"id":41419658}],"con":true,"img":false}]}
{"op":"mcm","clk":"5348092375","pt":1646213846305,"mc":[{"id":"1.195453723","rc":[{"atb":[[7.4,0]],"id":41419593}],"con":true,"img":false}]}
{"op":"mcm","clk":"5348092379","pt":1646213846358,"mc":[{"id":"1.195453723","rc":[{"atb":[[8.4,0]],"id":41419593}],"con":true,"img":false}]}
{"op":"mcm","clk":"5348092426","pt":1646213847085,"mc":[{"id":"1.195453723","rc":[{"atb":[[8.8,2.72],[7.8,3.26]],"id":41419593}],"con":true,"img":false}]}
{"op":"mcm","clk":"5348095748","pt":1646213906699,"mc":[{"id":"1.195453723","rc":[{"atb":[[18.5,0]],"id":41419626}],"con":true,"img":false}]}
{"op":"mcm","clk":"5348095770","pt":1646213907062,"mc":[{"id":"1.195453723","rc":[{"atb":[[16,0]],"id":41419626},{"atb":[[19,0],[23,0]],"id":41419623}],"con":true,"img":false}]}
{"op":"mcm","clk":"5348095802","pt":1646213907684,"mc":[{"id":"1.195453723","rc":[{"atb":[[19,2.72]],"id":41419626}],"con":true,"img":false}]}
{"op":"mcm","clk":"5348095825","pt":1646213908091,"mc":[{"id":"1.195453723","rc":[{"atb":[[16.5,3.26]],"id":41419626},{"atb":[[19.5,3.26],[24,2.72]],"id":41419623}],"con":true,"img":false}]}
{"op":"mcm","clk":"5348098607","pt":1646213954893,"mc":[{"id":"1.195453723","rc":[{"atb":[[9,0],[10,11.11]],"id":41419605},{"atl":[[1000,0]],"id":41419655},{"atb":[[4.1,32.26],[3.65,0]],"id":41419635},{"atb":[[7.2,16.13],[5.9,0]],"id":41419636},{"atb":[[8,14.29],[7,0]],"id":41419637}],"con":true,"img":false}]}
{"op":"mcm","clk":"5348098625","pt":1646213955151,"mc":[{"id":"1.195453723","rc":[{"atb":[[8.8,0],[7.8,0]],"id":41419593}],"con":true,"img":false}]}
{"op":"mcm","clk":"5348098691","pt":1646213955975,"mc":[{"id":"1.195453723","rc":[{"atb":[[7.4,3.26],[8.4,2.72]],"id":41419593}],"con":true,"img":false}]}
{"op":"mcm","clk":"5348098839","pt":1646213958564,"mc":[{"id":"1.195453723","rc":[{"atb":[[360,0]],"id":28546943}],"con":true,"img":false}]}
{"op":"mcm","clk":"5348098871","pt":1646213959087,"mc":[{"id":"1.195453723","rc":[{"atb":[[330,0],[380,0]],"id":41419613},{"atb":[[170,0],[120,0]],"id":41419586}],"con":true,"img":false}]}
{"op":"mcm","clk":"5348098887","pt":1646213959385,"mc":[{"id":"1.195453723","rc":[{"atb":[[370,3.26]],"id":28546943}],"con":true,"img":false}]}
{"op":"mcm","clk":"5348098918","pt":1646213959914,"mc":[{"id":"1.195453723","rc":[{"atb":[[340,3.26],[390,2.72]],"id":41419613},{"atb":[[130,3.26],[180,2.72]],"id":41419586}],"con":true,"img":false}]}
{"op":"mcm","clk":"5348100028","pt":1646213980024,"mc":[{"id":"1.195453723","rc":[{"atb":[[430,0],[480,0]],"id":41419653}],"con":true,"img":false}]}
{"op":"mcm","clk":"5348100073","pt":1646213980907,"mc":[{"id":"1.195453723","rc":[{"atb":[[440,3.26],[490,2.72]],"id":41419653}],"con":true,"img":false}]}
{"op":"mcm","clk":"5348102036","pt":1646214011863,"mc":[{"id":"1.195453723","rc":[{"atb":[[420,0],[470,0]],"id":28546950}],"con":true,"img":false}]}
{"op":"mcm","clk":"5348102089","pt":1646214012694,"mc":[{"id":"1.195453723","rc":[{"atb":[[430,3.26],[480,2.72]],"id":28546950}],"con":true,"img":false}]}
{"op":"mcm","clk":"5348104871","pt":1646214062290,"mc":[{"id":"1.195453723","rc":[{"atb":[[34,0],[44,0]],"id":41419605},{"atb":[[70,0],[48,0]],"id":41419634},{"atb":[[170,0],[220,0]],"id":41435527},{"atb":[[19,0],[23,0]],"id":41419639},{"atb":[[12,0],[14.5,0]],"id":41419635},{"atb":[[65,0],[90,0]],"id":41419614},{"atb":[[80,0],[110,0]],"id":41419656},{"atb":[[6.4,0],[7.4,0]],"id":41419598},{"atb":[[140,0],[190,0]],"id":41419660},{"atb":[[36,0],[28,0]],"id":41419636},{"atb":[[150,0],[200,0]],"id":41419615},{"atb":[[130,0],[180,0]],"id":41419616}],"con":true,"img":false}]}
{"op":"mcm","clk":"5348104917","pt":1646214062961,"mc":[{"id":"1.195453723","rc":[{"atb":[[36,3.26],[46,2.72]],"id":41419605},{"atb":[[75,2.72],[50,3.26]],"id":41419634},{"atb":[[180,3.26],[230,2.72]],"id":41435527},{"atb":[[19.5,3.26],[24,2.72]],"id":41419639},{"atb":[[12.5,3.26],[15,2.72]],"id":41419635},{"atb":[[70,3.26],[95,2.72]],"id":41419614},{"atb":[[85,5.64],[120,2.72]],"id":41419656},{"atb":[[7.6,2.72],[6.6,38.94]],"id":41419598},{"atb":[[150,3.26],[200,2.72]],"id":41419660},{"atb":[[38,8.12],[29,3.26]],"id":41419636},{"atb":[[160,3.26],[210,2.72]],"id":41419615},{"atb":[[140,3.26],[190,2.72]],"id":41419616}],"con":true,"img":false}]}
{"op":"mcm","clk":"5348105682","pt":1646214074887,"mc":[{"id":"1.195453723","rc":[{"atb":[[2.88,53.19],[3,0]],"id":41419593},{"atb":[[6,0],[5.4,22.59]],"id":41419622}],"con":true,"img":false}]}
{"op":"mcm","clk":"5348105696","pt":1646214075093,"mc":[{"id":"1.195453723","rc":[{"atl":[[860,2],[870,0]],"id":41419601},{"atl":[[650,0],[640,2]],"id":41419623},{"atl":[[700,2],[710,0]],"id":41419608}],"con":true,"img":false}]}
{"op":"mcm","clk":"5348105719","pt":1646214075400,"mc":[{"id":"1.195453723","rc":[{"atb":[[7.4,0],[8.4,0]],"id":41419593}],"con":true,"img":false}]}
{"op":"mcm","clk":"5348105766","pt":1646214076177,"mc":[{"id":"1.195453723","rc":[{"atb":[[8.6,2.72],[7.6,3.26]],"id":41419593}],"con":true,"img":false}]}
{"op":"mcm","clk":"5348106976","pt":1646214093235,"mc":[{"id":"1.195453723","rc":[{"atl":[[860,0],[850,2]],"id":41419601},{"atl":[[690,0],[680,2]],"id":41419610},{"atl":[[540,0],[530,2]],"id":41419607},{"atl":[[700,0],[680,2]],"id":41419608},{"atl":[[790,2],[800,0]],"id":41419612}],"con":true,"img":false}]}
{"op":"mcm","clk":"5348107013","pt":1646214093909,"mc":[{"id":"1.195453723","rc":[{"atb":[[2.88,0],[3.05,48.78]],"id":41419593}],"con":true,"img":false}]}
{"op":"mcm","clk":"5348107542","pt":1646214103343,"mc":[{"id":"1.195453723","rc":[{"atb":[[130,0],[90,0]],"id":41419617},{"atb":[[21,0],[26,0]],"id":41419622},{"atb":[[160,0],[110,0]],"id":41435528},{"atb":[[430,0],[480,0]],"id":28546950},{"atb":[[200,0],[250,0]],"id":41419657},{"atb":[[40,0],[50,0]],"id":41419620},{"atb":[[8,0],[9,0]],"id":41419621}],"con":true,"img":false}]}
{"op":"mcm","clk":"5348107548","pt":1646214103446,"mc":[{"id":"1.195453723","rc":[{"atb":[[80,0],[110,0]],"id":41419589},{"atb":[[370,0],[420,0]],"id":28546943},{"atb":[[42,0],[55,0]],"id":41419624},{"atb":[[80,0],[110,0]],"id":41419599},{"atb":[[320,0],[370,0]],"id":41419588},{"atb":[[5.2,0],[5.7,0]],"id":41419596},{"atb":[[530,0],[480,0]],"id":41419658}],"con":true,"img":false}]}
{"op":"mcm","clk":"5348107584","pt":1646214104071,"mc":[{"id":"1.195453723","rc":[{"atb":[[140,2.72],[95,3.26]],"id":41419617},{"atb":[[22,3.26],[27,2.72]],"id":41419622},{"atb":[[170,2.72],[120,3.26]],"id":41435528},{"atb":[[260,2.72],[210,3.26]],"id":41419657},{"atb":[[42,3.26],[55,2.72]],"id":41419620},{"atb":[[8.4,3.26],[9.4,2.72]],"id":41419621}],"con":true,"img":false}]}
{"op":"mcm","clk":"5348107593","pt":1646214104127,"mc":[{"id":"1.195453723","rc":[{"atb":[[85,3.26],[120,2.72]],"id":41419589},{"atb":[[380,3.26],[430,2.72]],"id":28546943},{"atb":[[440,3.26],[490,2.72]],"id":28546950},{"atb":[[44,3.26],[60,2.72]],"id":41419624},{"atb":[[85,3.26],[120,2.72]],"id":41419599},{"atb":[[330,3.26],[380,2.72]],"id":41419588},{"atb":[[5.8,2.72],[5.3,3.26]],"id":41419596},{"atb":[[550,2.72],[500,3.26]],"id":41419658}],"con":true,"img":false}]}
{"op":"mcm","clk":"5348107808","pt":1646214108670,"mc":[{"id":"1.195453723","rc":[{"atb":[[19,0]],"id":41419626}],"con":true,"img":false}]}
{"op":"mcm","clk":"5348107829","pt":1646214109034,"mc":[{"id":"1.195453723","rc":[{"atb":[[16.5,0]],"id":41419626}],"con":true,"img":false}]}
{"op":"mcm","clk":"5348107842","pt":1646214109340,"mc":[{"id":"1.195453723","rc":[{"atb":[[21,2.72]],"id":41419626}],"con":true,"img":false}]}
{"op":"mcm","clk":"5348107863","pt":1646214109752,"mc":[{"id":"1.195453723","rc":[{"atb":[[18,15.01]],"id":41419626}],"con":true,"img":false}]}
{"op":"mcm","clk":"5348108582","pt":1646214124357,"mc":[{"id":"1.195453723","rc":[{"atl":[[1000,2]],"id":41419609},{"atl":[[770,2],[830,0]],"id":41419605},{"atl":[[1000,2]],"id":41419655},{"atl":[[570,0],[550,2]],"id":41419622},{"atl":[[620,2],[650,0]],"id":41419651},{"atl":[[770,2],[850,0]],"id":41419601},{"atl":[[570,0],[560,2]],"id":41419626},{"atl":[[570,2],[580,0]],"id":41419639},{"atl":[[630,2],[680,0]],"id":41419610},{"atl":[[610,2],[640,0]],"id":41419623},{"atl":[[310,2],[320,0]],"id":41419598},{"atl":[[530,0],[510,2]],"id":41419607},{"atl":[[600,2],[620,0]],"id":41419636},{"atl":[[700,2],[750,0]],"id":41419603},{"atl":[[900,2],[1000,0]],"id":41419624},{"atl":[[570,0],[550,2]],"id":41419595},{"atl":[[640,2],[680,0]],"id":41419608},{"atl":[[690,2],[720,0]],"id":41419637},{"atl":[[730,2],[790,0]],"id":41419612},{"atl":[[650,0],[640,2]],"id":41419592},{"atl":[[410,2],[420,0]],"id":41419621},{"atl":[[540,0],[520,2]],"id":41419600},{"atl":[[180,2],[200,0]],"id":41419596}],"con":true,"img":false}]}
{"op":"mcm","clk":"5348110394","pt":1646214155600,"mc":[{"id":"1.195453723","rc":[{"atb":[[340,0],[390,0]],"id":41419613}],"con":true,"img":false}]}
{"op":"mcm","clk":"5348110437","pt":1646214156327,"mc":[{"id":"1.195453723","rc":[{"atb":[[350,3.26],[400,2.72]],"id":41419613}],"con":true,"img":false}]}
{"op":"mcm","clk":"5348111453","pt":1646214174572,"mc":[{"id":"1.195453723","rc":[{"atb":[[440,0],[490,0]],"id":41419653}],"con":true,"img":false}]}
{"op":"mcm","clk":"5348111498","pt":1646214175302,"mc":[{"id":"1.195453723","rc":[{"atb":[[460,3.26],[510,2.72]],"id":41419653}],"con":true,"img":false}]}
{"op":"mcm","clk":"5348113862","pt":1646214213212,"mc":[{"id":"1.195453723","rc":[{"atl":[[770,0],[810,2]],"id":41419605},{"atb":[[2.9,52.63],[3.05,0]],"id":41419593},{"atl":[[1000,0]],"id":41419655},{"atl":[[570,2]],"id":41419622},{"atl":[[620,0],[640,2]],"id":41419651},{"atl":[[770,0],[810,2]],"id":41419601},{"atl":[[560,0],[570,2]],"id":41419626},{"atl":[[570,0],[580,2]],"id":41419639},{"atb":[[6.2,19.23],[7.4,0]],"id":41419610},{"atl":[[630,0],[660,2]],"id":41419610},{"atl":[[610,0],[630,2]],"id":41419623},{"atl":[[310,0],[320,2]],"id":41419598},{"atb":[[5.1,0],[4.4,29.41]],"id":41419607},{"atl":[[520,2],[510,0]],"id":41419607},{"atl":[[600,0],[620,2]],"id":41419636},{"atl":[[700,0],[730,2]],"id":41419603},{"atl":[[900,0],[950,2]],"id":41419624},{"atl":[[550,0],[560,2]],"id":41419595},{"atl":[[640,0],[660,2]],"id":41419608},{"atl":[[690,0],[720,2]],"id":41419637},{"atl":[[730,0],[760,2]],"id":41419612},{"atl":[[640,0],[650,2]],"id":41419592},{"atl":[[410,0],[420,2]],"id":41419621},{"atl":[[520,0],[530,2]],"id":41419600},{"atl":[[180,0],[200,2]],"id":41419596}],"con":true,"img":false}]}
{"op":"mcm","clk":"5348113867","pt":1646214213316,"mc":[{"id":"1.195453723","rc":[{"atl":[[550,0]],"id":41419622}],"con":true,"img":false}]}
{"op":"mcm","clk":"5348113879","pt":1646214213520,"mc":[{"id":"1.195453723","rc":[{"atb":[[7.6,0],[6.6,35.67]],"id":41419598}],"con":true,"img":false}]}
{"op":"mcm","clk":"5348113891","pt":1646214213726,"mc":[{"id":"1.195453723","rc":[{"atb":[[9.2,0],[8.2,0]],"id":41419594}],"con":true,"img":false}]}
{"op":"mcm","clk":"5348113939","pt":1646214214240,"mc":[{"id":"1.195453723","rc":[{"atb":[[6.4,3.26],[7.4,2.72]],"id":41419598}],"con":true,"img":false}]}
{"op":"mcm","clk":"5348113962","pt":1646214214500,"mc":[{"id":"1.195453723","rc":[{"atb":[[8,3.26],[9,2.72]],"id":41419594}],"con":true,"img":false}]}
{"op":"mcm","clk":"5348114734","pt":1646214226353,"mc":[{"id":"1.195453723","rc":[{"atl":[[1000,0]],"id":41419609}],"con":true,"img":false}]}
{"op":"mcm","clk":"5348116449","pt":1646214255416,"mc":[{"id":"1.195453723","rc":[{"atb":[[2.9,0],[3,50]],"id":41419593},{"atb":[[5.9,20.41],[5.4,0]],"id":41419622}],"con":true,"img":false}]}
{"op":"mcm","clk":"5348137399","pt":1646214435849,"mc":[{"id":"1.195453723","rc":[{"atb":[[8.6,0],[7.6,0]],"id":41419593}],"con":true,"img":false}]}
{"op":"mcm","clk":"5348137441","pt":1646214436532,"mc":[{"id":"1.195453723","rc":[{"atb":[[7.4,3.26],[8.4,2.72]],"id":41419593}],"con":true,"img":false}]}
{"op":"mcm","clk":"5348152374","pt":1646214641840,"mc":[{"id":"1.195453723","rc":[{"atl":[[1000,2]],"id":41419609},{"atb":[[25,0]],"id":41419638},{"atl":[[1000,0]],"id":41419638},{"atb":[[10,0],[13.5,8]],"id":41419605},{"atb":[[28,0]],"id":41419617},{"atb":[[3,0],[3.3,43.48]],"id":41419593},{"atb":[[6.4,0],[7.8,14.71]],"id":41419651},{"atb":[[21,5],[11.5,0]],"id":41419601},{"atb":[[6.2,0],[5.2,23.81]],"id":41419626},{"atl":[[530,2],[570,0]],"id":41419626},{"atb":[[3.75,36.36]],"id":41419635},{"atl":[[450,2]],"id":41419635},{"atb":[[8.6,13.16],[6.2,0]],"id":41419610},{"atb":[[2.82,54.95],[3.25,0]],"id":41419598},{"atl":[[280,2],[320,0]],"id":41419598},{"atb":[[5.5,22.22],[4.4,0]],"id":41419607},{"atb":[[7,0],[14.5,7.41]],"id":41419603},{"atb":[[18.5,0],[11.5,8.98]],"id":41419624},{"atl":[[880,2],[950,0]],"id":41419624},{"atb":[[27,0]],"id":41435525},{"atb":[[4.5,19.62],[5.7,0]],"id":41419595},{"atl":[[520,2],[560,0]],"id":41419595},{"atb":[[11,10],[7.8,0]],"id":41419608},{"atb":[[8,0],[6.4,18.52]],"id":41419637},{"atl":[[650,2],[720,0]],"id":41419637},{"atl":[[1000,0]],"id":41435526},{"atb":[[5.6,0],[7.2,59.09]],"id":41419600}],"con":true,"img":false}]}
{"op":"mcm","clk":"5348152383","pt":1646214641941,"mc":[{"id":"1.195453723","rc":[{"atb":[[34,3.03],[26,0]],"id":41419609},{"atb":[[11,5.44]],"id":41419638},{"atl":[[940,2]],"id":41419638},{"atl":[[790,2],[810,0]],"id":41419605},{"atb":[[34,3.03],[27,0]],"id":41419634},{"atb":[[38,2.7]],"id":41419617},{"atb":[[40,2],[30,0]],"id":41419613},{"atb":[[34,2.24],[26,0]],"id":41419655},{"atb":[[8,14.29],[5.9,0]],"id":41419622},{"atb":[[40,9.38],[29,0]],"id":41419589},{"atb":[[40,2],[29,0]],"id":41435527},{"atb":[[42,2],[30,0]],"id":28546943},{"atb":[[7.2,16.13],[5.9,0]],"id":41419639},{"atl":[[540,2],[580,0]],"id":41419639},{"atb":[[38,2],[28,0]],"id":41419606},{"atb":[[4.1,0]],"id":41419635},{"atl":[[480,0]],"id":41419635},{"atb":[[36,2.86],[27,0]],"id":41419614},{"atb":[[36,2.86],[28,0]],"id":41419656},{"atb":[[6.4,0],[8.2,13.89]],"id":41419623},{"atl":[[580,2],[630,0]],"id":41419623},{"atb":[[40,2],[27,0]],"id":41419652},{"atb":[[40,2.56],[28,0]],"id":41435528},{"atb":[[38,2.7],[29,0]],"id":41419619},{"atb":[[40,2],[29,0]],"id":41419586},{"atb":[[40,2],[29,0]],"id":41419660},{"atb":[[4,33.33],[3.4,0]],"id":41419594},{"atb":[[42,2],[30,0]],"id":28546950},{"atb":[[7.2,0],[8.2,13.89]],"id":41419636},{"atl":[[580,2],[620,0]],"id":41419636},{"atb":[[38,2],[29,0]],"id":41419615},{"atb":[[40,2],[29,0]],"id":41419657},{"atb":[[38,2]],"id":41435525},{"atb":[[40,2],[29,0]],"id":41419653},{"atb":[[34,3.03],[26,0]],"id":41419620},{"atl":[[1000,2]],"id":41419620},{"atb":[[40,2],[29,0]],"id":41419587},{"atb":[[38,2],[27,0]],"id":41419599},{"atb":[[40,2.56],[29,0]],"id":41419616},{"atb":[[8.6,0],[10.5,10.53]],"id":41419612},{"atl":[[670,2],[760,0]],"id":41419612},{"atb":[[10,11.11],[6.8,0]],"id":41419592},{"atl":[[630,2],[650,0]],"id":41419592},{"atb":[[34,3.03],[22,0]],"id":41435526},{"atl":[[370,2],[420,0]],"id":41419621},{"atb":[[40,2],[29,0]],"id":41419588},{"atb":[[40,2],[29,0]],"id":41419658}],"con":true,"img":false}]}
{"op":"mcm","clk":"5348152395","pt":1646214642102,"mc":[{"id":"1.195453723","rc":[{"atb":[[11,0],[15,5.44]],"id":41419638},{"atl":[[810,2],[940,0]],"id":41419638}],"con":true,"img":false}]}
{"op":"mcm","clk":"5348152403","pt":1646214642206,"mc":[{"id":"1.195453723","rc":[{"atb":[[7.4,0],[8.4,0]],"id":41419593},{"atb":[[6.4,0],[7.4,0]],"id":41419598},{"atb":[[23,0],[28,0]],"id":41419595}],"con":true,"img":false}]}
{"op":"mcm","clk":"5348152459","pt":1646214642875,"mc":[{"id":"1.195453723","rc":[{"atb":[[9.2,27.63],[10.5,2.72]],"id":41419593}],"con":true,"img":false}]}
{"op":"mcm","clk":"5348152477","pt":1646214643186,"mc":[{"id":"1.195453723","rc":[{"atb":[[7.2,2.72],[6.2,3.26]],"id":41419598},{"atb":[[19.5,3.26],[24,2.72]],"id":41419595}],"con":true,"img":false}]}
{"op":"mcm","clk":"5348152744","pt":1646214647316,"mc":[{"id":"1.195453723","rc":[{"atl":[[730,2],[810,0]],"id":41419638},{"atl":[[1000,2]],"id":41419634},{"atl":[[1000,2]],"id":41419655},{"atl":[[530,2],[570,0]],"id":41419622},{"atl":[[600,2],[640,0]],"id":41419651},{"atl":[[540,0],[510,2]],"id":41419639},{"atl":[[1000,2]],"id":41419614},{"atl":[[620,2],[660,0]],"id":41419610},{"atl":[[540,2],[580,0]],"id":41419623},{"atl":[[520,0],[500,2]],"id":41419607},{"atl":[[580,0]],"id":41419636},{"atl":[[600,2],[670,0]],"id":41419612},{"atl":[[570,2],[630,0]],"id":41419592},{"atl":[[1000,2]],"id":41435526},{"atl":[[140,2],[200,0]],"id":41419596}],"con":true,"img":false}]}
{"op":"mcm","clk":"5348152758","pt":1646214647419,"mc":[{"id":"1.195453723","rc":[{"atl":[[550,2]],"id":41419636}],"con":true,"img":false}]}
{"op":"mcm","clk":"5348153249","pt":1646214655143,"mc":[{"id":"1.195453723","rc":[{"atb":[[18.5,5.71],[13.5,0]],"id":41419605},{"atb":[[3.95,33.9]],"id":41419593},{"atb":[[10.5,10.53],[7.8,0]],"id":41419651},{"atb":[[21,0],[28,3.7]],"id":41419601},{"atb":[[6.8,17.24],[5.2,0]],"id":41419626},{"atl":[[450,2]],"id":41419626},{"atb":[[4.5,28.57],[3.75,0]],"id":41419635},{"atl":[[360,2]],"id":41419635},{"atb":[[8.6,0],[11.5,9.52]],"id":41419610},{"atb":[[2.82,0]],"id":41419598},{"atb":[[5.5,0],[7,16.67]],"id":41419607},{"atb":[[15.5,6.9]],"id":41419624},{"atl":[[670,2],[880,0]],"id":41419624},{"atb":[[4.5,0],[5.7,19.62]],"id":41419595},{"atl":[[520,0],[450,2]],"id":41419595},{"atb":[[11,0],[15,7.14]],"id":41419608},{"atb":[[8.4,13.51]],"id":41419637},{"atb":[[7.2,42.96],[9.8,11.36]],"id":41419600}],"con":true,"img":false}]}
{"op":"mcm","clk":"5348153254","pt":1646214655244,"mc":[{"id":"1.195453723","rc":[{"atb":[[3.3,0]],"id":41419593},{"atl":[[530,0]],"id":41419626},{"atl":[[450,0]],"id":41419635},{"atb":[[3.3,43.48]],"id":41419598},{"atb":[[11.5,0]],"id":41419624},{"atb":[[6.4,0]],"id":41419637},{"atl":[[550,2],[650,0]],"id":41419637}],"con":true,"img":false}]}
{"op":"mcm","clk":"5348153261","pt":1646214655300,"mc":[{"id":"1.195453723","rc":[{"atl":[[700,2],[790,0]],"id":41419605},{"atl":[[340,2]],"id":41419621}],"con":true,"img":false}]}
{"op":"mcm","clk":"5348153268","pt":1646214655403,"mc":[{"id":"1.195453723","rc":[{"atl":[[370,0]],"id":41419621}],"con":true,"img":false}]}
{"op":"mcm","clk":"5348153578","pt":1646214660654,"mc":[{"id":"1.195453723","rc":[{"atl":[[730,0],[720,2]],"id":41419638},{"atl":[[540,0],[530,2]],"id":41419623}],"con":true,"img":false}]}
{"op":"mcm","clk":"5348153664","pt":1646214661844,"mc":[{"id":"1.195453723","rc":[{"atl":[[280,2],[330,0]],"id":41419593},{"atl":[[530,0],[520,2]],"id":41419622},{"atb":[[21,5],[28,0]],"id":41419585},{"atl":[[280,0],[230,2]],"id":41419598},{"atl":[[470,2],[500,0]],"id":41419607},{"atb":[[9.2,12.2],[8.2,0]],"id":41419636},{"atl":[[530,2],[550,0]],"id":41419636},{"atb":[[8.4,0],[9.4,11.9]],"id":41419637},{"atl":[[540,2],[550,0]],"id":41419637},{"atb":[[2.88,0],[4.4,29.41]],"id":41419621},{"atb":[[3.55,39.22],[2.7,0]],"id":41419596}],"con":true,"img":false}]}
{"op":"mcm","clk":"5348154528","pt":1646214673741,"mc":[{"id":"1.195453723","rc":[{"atl":[[680,2],[720,0]],"id":41419638}],"con":true,"img":false}]}
{"op":"mcm","clk":"5348160047","pt":1646214758604,"mc":[{"id":"1.195453723","rc":[{"atl":[[540,0],[530,2]],"id":41419637},{"atb":[[8.6,13.16],[9.8,0]],"id":41419600}],"con":true,"img":false}]}
{"op":"mcm","clk":"5348160862","pt":1646214770504,"mc":[{"id":"1.195453723","rc":[{"atb":[[6.2,0]],"id":41419598}],"con":true,"img":false}]}
{"op":"mcm","clk":"5348160889","pt":1646214770914,"mc":[{"id":"1.195453723","rc":[{"atb":[[7.2,0]],"id":41419598}],"con":true,"img":false}]}
{"op":"mcm","clk":"5348160913","pt":1646214771221,"mc":[{"id":"1.195453723","rc":[{"atb":[[6.4,3.26]],"id":41419598}],"con":true,"img":false}]}
{"op":"mcm","clk":"5348160937","pt":1646214771623,"mc":[{"id":"1.195453723","rc":[{"atb":[[7.4,2.72]],"id":41419598}],"con":true,"img":false}]}
{"op":"mcm","clk":"5348163693","pt":1646214813178,"mc":[{"id":"1.195453723","rc":[{"atb":[[10,0],[8.8,12.82]],"id":41419592}],"con":true,"img":false}]}
{"op":"mcm","clk":"5348172435","pt":1646214941967,"mc":[{"id":"1.195453723","rc":[{"atl":[[990,2],[1000,0]],"id":41419609},{"atb":[[18.5,0],[15.5,6.9]],"id":41419605},{"atl":[[520,0],[510,2]],"id":41419622},{"atl":[[530,0],[520,2]],"id":41419636},{"atb":[[12,9.09],[15,0]],"id":41419608}],"con":true,"img":false}]}
{"op":"mcm","clk":"5348172472","pt":1646214942589,"mc":[{"id":"1.195453723","rc":[{"atb":[[9.2,24.36],[10.5,0]],"id":41419593},{"atb":[[19.5,0],[24,0]],"id":41419595}],"con":true,"img":false}]}
{"op":"mcm","clk":"5348172507","pt":1646214943057,"mc":[{"id":"1.195453723","rc":[{"atl":[[1000,0]],"id":41419655},{"atl":[[1000,0]],"id":41419614}],"con":true,"img":false}]}
{"op":"mcm","clk":"5348172517","pt":1646214943263,"mc":[{"id":"1.195453723","rc":[{"atb":[[20,3.26],[25,2.72]],"id":41419595}],"con":true,"img":false}]}
{"op":"mcm","clk":"5348172544","pt":1646214943677,"mc":[{"id":"1.195453723","rc":[{"atb":[[9,3.26],[10,2.72]],"id":41419593}],"con":true,"img":false}]}
{"op":"mcm","clk":"5348172614","pt":1646214944663,"mc":[{"id":"1.195453723","rc":[{"atl":[[1000,2]],"id":41419655},{"atl":[[1000,2]],"id":41419614}],"con":true,"img":false}]}
{"op":"mcm","clk":"5348173684","pt":1646214963011,"mc":[{"id":"1.195453723","rc":[{"atb":[[20,0],[25,0]],"id":41419595}],"con":true,"img":false}]}
{"op":"mcm","clk":"5348173739","pt":1646214963992,"mc":[{"id":"1.195453723","rc":[{"atb":[[19.5,3.26],[24,2.72]],"id":41419595}],"con":true,"img":false}]}
{"op":"mcm","clk":"5348174872","pt":1646214981923,"mc":[{"id":"1.195453723","rc":[{"atb":[[7.4,0],[6.6,29.13]],"id":41419598},{"trd":[[6.6,13.07],[7.4,5.44]],"ltp":6.6,"tv":18.51,"id":41419598}],"con":true,"img":false}]}
{"op":"mcm","clk":"5348174905","pt":1646214982439,"mc":[{"id":"1.195453723","rc":[{"atb":[[6.4,0]],"id":41419598}],"con":true,"img":false}]}
{"op":"mcm","clk":"5348174944","pt":1646214983109,"mc":[{"id":"1.195453723","rc":[{"atb":[[3.65,3.26]],"id":41419598}],"con":true,"img":false}]}
{"op":"mcm","clk":"5348174976","pt":1646214983833,"mc":[{"id":"1.195453723","rc":[{"atl":[[1000,0]],"id":41419634},{"atl":[[1000,0]],"id":41419655},{"atl":[[1000,0]],"id":41419614}],"con":true,"img":false}]}
{"op":"mcm","clk":"5348175728","pt":1646214996130,"mc":[{"id":"1.195453723","rc":[{"atb":[[38,0]],"id":41419612},{"trd":[[38,5.44]],"ltp":38.0,"tv":5.44,"id":41419612}],"con":true,"img":false}]}
{"op":"mcm","clk":"5348175751","pt":1646214996545,"mc":[{"id":"1.195453723","rc":[{"atb":[[3.9,94.58]],"id":41419598}],"con":true,"img":false}]}
{"op":"mcm","clk":"5348175768","pt":1646214996961,"mc":[{"id":"1.195453723","rc":[{"atb":[[29,0]],"id":41419612}],"con":true,"img":false}]}
{"op":"mcm","clk":"5348177139","pt":1646215015993,"mc":[{"id":"1.195453723","rc":[{"atb":[[21,0]],"id":41419626},{"trd":[[21,5.44]],"ltp":21.0,"tv":5.44,"id":41419626}],"con":true,"img":false}]}
{"op":"mcm","clk":"5348177228","pt":1646215017445,"mc":[{"id":"1.195453723","rc":[{"atb":[[310,0],[210,0],[460,0]],"id":41419609},{"atb":[[260,0],[110,0],[55,3.26]],"id":41419638},{"atb":[[40,0],[20,0],[15,0]],"id":41419605},{"atb":[[130,0],[380,0],[230,0]],"id":41419634},{"atb":[[44,0],[27,0],[120,0]],"id":41419617},{"atb":[[600,0],[700,0],[850,0]],"id":41419613},{"atb":[[5.1,0],[9.2,0],[6.2,0]],"id":41419593},{"atb":[[580,0],[330,0],[430,0]],"id":41419655},{"atb":[[10,0],[25,0],[15,0]],"id":41419622},{"atb":[[75,0],[40,2.56],[200,0]],"id":41419589},{"atb":[[600,0],[700,0],[850,0]],"id":41435527},{"atb":[[16,0],[44,0],[22,0]],"id":41419651},{"atb":[[17,0],[48,0],[24,0]],"id":41419601},{"atb":[[600,0],[700,0],[850,0]],"id":28546943},{"atb":[[18,3.26],[10.5,0],[8.2,0]],"id":41419626},{"atb":[[18.5,0],[11,0],[8.4,0]],"id":41419639},{"atb":[[650,0],[400,0],[500,0]],"id":41419606},{"atb":[[5.1,0],[9.2,0],[6.2,0]],"id":41419635},{"atb":[[540,0],[290,0],[390,0]],"id":41419602},{"atb":[[18,0],[26,0],[55,3.26]],"id":41419585},{"atb":[[16.5,0],[46,0],[23,0]],"id":41419614},{"atb":[[10.5,0],[26,3.26],[15.5,0]],"id":41419610},{"atb":[[34,0],[85,3.26],[22,0]],"id":41419656},{"atb":[[22,0],[13.5,0],[9.4,0]],"id":41419623},{"atb":[[600,0],[700,0],[850,0]],"id":41419652},{"atb":[[330,0],[180,0],[90,0]],"id":41435528},{"atb":[[310,0],[160,2.72],[80,0]],"id":41419619},{"atb":[[560,0],[660,0],[810,0]],"id":41419586},{"atb":[[4.8,0],[6.6,0],[3.9,2.72]],"id":41419598},{"atb":[[520,0],[670,0],[420,0]],"id":41419660},{"atb":[[4.8,0],[8.6,0],[5.8,0]],"id":41419594},{"atb":[[6.8,0],[8.8,0],[14.5,0]],"id":41419607},{"atb":[[600,0],[700,0],[850,0]],"id":28546950},{"atb":[[38,2.72],[19.5,0],[14.5,0]],"id":41419636},{"atb":[[16,0],[11,0],[27,0]],"id":41419603},{"atb":[[580,0],[330,0],[430,0]],"id":41419615},{"atb":[[600,0],[700,0],[850,0]],"id":41419657},{"atb":[[34,0],[85,0],[22,0]],"id":41419624},{"atb":[[300,0],[200,0],[450,0]],"id":41419591},{"atb":[[600,0],[700,0],[850,0]],"id":41435525},{"atb":[[600,0],[700,0],[850,0]],"id":41419653},{"atb":[[130,0],[46,0],[28,0]],"id":41419620},{"atb":[[560,0],[710,0],[460,0]],"id":41419587},{"atb":[[600,0],[750,0],[500,0]],"id":41419599},{"atb":[[17,0],[12,0],[29,0]],"id":41419595},{"atb":[[17,0],[48,2.72],[24,0]],"id":41419608},{"atb":[[34,2.72],[18.5,0],[13.5,0]],"id":41419637},{"atb":[[350,0],[500,0],[250,0]],"id":41419616},{"atb":[[36,0],[19,0],[14,0]],"id":41419612},{"atb":[[36,0],[19,0],[14,0]],"id":41419592},{"atb":[[90,0],[46,3.26],[230,0]],"id":41435526},{"atb":[[5.6,0],[4.1,0],[3.55,0]],"id":41419621},{"atb":[[600,0],[700,0],[850,0]],"id":41419588},{"atb":[[7.2,0],[9.2,0],[15.5,0]],"id":41419600},{"atb":[[2.92,0],[4.1,0],[3.3,0]],"id":41419596},{"atb":[[600,0],[700,0],[850,0]],"id":41419658}],"con":true,"img":false}]}
{"op":"mcm","clk":"5348177471","pt":1646215021125,"mc":[{"id":"1.195453723","rc":[{"atb":[[310,0.43],[110,5.19],[55,4.98]],"id":41419609},{"atb":[[32,8.67],[21,13.45],[110,1.23]],"id":41419638},{"atb":[[8,38.42],[20,7.07],[10,29.88]],"id":41419605},{"atb":[[65,4.2],[36,7.68],[230,0.58]],"id":41419634},{"atb":[[18.5,15.37],[44,3.12],[13.5,21.52]],"id":41419617},{"atb":[[700,0.19],[400,3.4],[500,0.53]],"id":41419613},{"atb":[[6.2,25.86],[4.1,86.77],[3.55,105.49]],"id":41419593},{"atb":[[130,2.08],[430,0.31],[230,1.17]],"id":41419655},{"atb":[[8,52.71],[6,53.8],[15,9.6]],"id":41419622},{"atb":[[17.5,16.3],[75,1.82],[25,11.21]],"id":41419589},{"atb":[[700,0.19],[400,0.67],[500,0.53]],"id":41435527},{"atb":[[22,6.4],[11,26.9],[8.4,36.35]],"id":41419651},{"atb":[[24,5.84],[12,24.45],[8.8,34.48]],"id":41419601},{"atb":[[700,0.19],[400,0.67],[500,0.53]],"id":28546943},{"atb":[[5.1,65.61],[10.5,14.15],[6.2,51.73]],"id":41419626},{"atb":[[6.4,49.81],[11,13.45],[5.2,64.04]],"id":41419639},{"atb":[[300,0.89],[200,1.35],[500,0.26]],"id":41419606},{"atb":[[6.2,25.86],[4.1,86.77],[3.55,105.49]],"id":41419635},{"atb":[[190,1.42],[95,2.86],[390,0.34]],"id":41419602},{"atb":[[9.2,32.8],[26,5.37],[13,22.41]],"id":41419585},{"atb":[[8.6,35.39],[23,6.11],[11.5,25.61]],"id":41419614},{"atb":[[6.2,51.73],[8.2,37.36],[15.5,9.27]],"id":41419610},{"atb":[[16,17.93],[34,4.07],[11,26.9]],"id":41419656},{"atb":[[7.4,42.03],[13.5,10.75],[5.7,57.23]],"id":41419623},{"atb":[[700,0.19],[400,0.67],[500,0.53]],"id":41419652},{"atb":[[180,0.75],[46,5.97],[28,9.96]],"id":41435528},{"atb":[[160,3.56],[42,6.56],[26,10.75]],"id":41419619},{"atb":[[660,0.2],[360,0.74],[460,0.58]],"id":41419586},{"atb":[[4.8,33.12],[3.4,104.89],[2.96,128.43]],"id":41419598},{"atb":[[520,0.26],[320,0.84],[220,1.22]],"id":41419660},{"atb":[[5.8,28.02],[3.4,112.08],[3.9,92.76]],"id":41419594},{"atb":[[8.8,17.24],[4.4,79.12],[5.4,61.13]],"id":41419607},{"atb":[[700,0.19],[400,0.67],[500,0.53]],"id":28546950},{"atb":[[19.5,7.27],[9.8,30.56],[7.8,39.56]],"id":41419636},{"atb":[[16,8.96],[6.4,49.81],[8.4,36.35]],"id":41419603},{"atb":[[130,2.08],[430,0.31],[230,1.17]],"id":41419615},{"atb":[[700,0.19],[400,0.67],[500,0.53]],"id":41419657},{"atb":[[16,17.93],[34,4.07],[11,26.9]],"id":41419624},{"atb":[[300,0.45],[100,2.71],[50,5.48]],"id":41419591},{"atb":[[700,0.19],[400,0.67],[500,0.53]],"id":41435525},{"atb":[[700,0.19],[400,0.67],[500,0.53]],"id":41419653},{"atb":[[19,14.94],[46,2.98],[14,20.69]],"id":41419620},{"atb":[[260,1.04],[560,0.23],[360,0.74]],"id":41419587},{"atb":[[600,0.22],[300,0.89],[400,0.67]],"id":41419599},{"atb":[[17,8.4],[6.8,46.37],[8.8,34.48]],"id":41419595},{"atb":[[12,33.54],[24,5.84],[8.8,34.48]],"id":41419608},{"atb":[[18.5,7.68],[7.4,42.03],[9.4,43.92]],"id":41419637},{"atb":[[150,1.8],[75,3.63],[350,0.38]],"id":41419616},{"atb":[[9.6,31.28],[19,7.47],[7.6,40.75]],"id":41419612},{"atb":[[9.6,31.28],[19,7.47],[7.6,40.75]],"id":41419592},{"atb":[[19,14.94],[90,1.5],[28,9.96]],"id":41435526},{"atb":[[2.82,147.8],[4.1,43.38],[3.05,131.22]],"id":41419621},{"atb":[[700,0.19],[400,0.67],[500,0.53]],"id":41419588},{"atb":[[5.6,58.47],[9.2,16.4],[4.6,74.72]],"id":41419600},{"atb":[[2.72,156.4],[2.52,176.97],[3.3,58.47]],"id":41419596},{"atb":[[700,0.19],[400,0.67],[500,3.8]],"id":41419658}],"con":true,"img":false}]}
{"op":"mcm","clk":"5348177897","pt":1646215026704,"mc":[{"id":"1.195453723","rc":[{"atl":[[1000,2]],"id":41419634}],"con":true,"img":false}]}
{"op":"mcm","clk":"5348178104","pt":1646215030115,"mc":[{"id":"1.195453723","rc":[{"atb":[[17.5,2.72]],"id":41419626}],"con":true,"img":false}]}
{"op":"mcm","clk":"5348178421","pt":1646215034818,"mc":[{"id":"1.195453723","rc":[{"atl":[[1000,0]],"id":41419634}],"con":true,"img":false}]}
{"op":"mcm","clk":"5348178708","pt":1646215039839,"mc":[{"id":"1.195453723","rc":[{"atl":[[1000,2]],"id":41419634}],"con":true,"img":false}]}
{"op":"mcm","clk":"5348179019","pt":1646215045057,"mc":[{"id":"1.195453723","rc":[{"atl":[[1000,0]],"id":41419634}],"con":true,"img":false}]}
{"op":"mcm","clk":"5348183298","pt":1646215118255,"mc":[{"id":"1.195453723","rc":[{"atb":[[20,5.26],[15,0]],"id":41419638}],"con":true,"img":false}]}
{"op":"mcm","clk":"5348183309","pt":1646215118463,"mc":[{"id":"1.195453723","rc":[{"atb":[[80,0],[55,0]],"id":41419638},{"atb":[[65,0],[90,0]],"id":41419655},{"atb":[[12.5,0],[15,0]],"id":41419635},{"atb":[[8,0],[9,0]],"id":41419594},{"atb":[[38,0],[29,0]],"id":41419636},{"atb":[[34,0],[27,0]],"id":41419637}],"con":true,"img":false}]}
{"op":"mcm","clk":"5348183315","pt":1646215118574,"mc":[{"id":"1.195453723","rc":[{"atb":[[18,0]],"id":41419626},{"atb":[[3.9,0],[3.65,0]],"id":41419598},{"atb":[[8,14.29],[7,0]],"id":41419607},{"atb":[[19.5,0],[24,0]],"id":41419595}],"con":true,"img":false}]}
{"op":"mcm","clk":"5348183355","pt":1646215119135,"mc":[{"id":"1.195453723","rc":[{"atb":[[85,2.72],[60,3.26]],"id":41419638},{"atb":[[70,3.26],[95,2.72]],"id":41419655},{"atb":[[16.5,2.72],[14,3.26]],"id":41419635},{"atb":[[9.2,2.72],[8.2,3.26]],"id":41419594},{"atb":[[40,2.72],[30,3.26]],"id":41419636},{"atb":[[36,2.72],[28,3.26]],"id":41419637}],"con":true,"img":false}]}
{"op":"mcm","clk":"5348183373","pt":1646215119445,"mc":[{"id":"1.195453723","rc":[{"atb":[[14,3.26]],"id":41419626},{"atb":[[3.95,2.72],[3.7,3.26]],"id":41419598},{"atb":[[21,3.26],[26,2.72]],"id":41419595}],"con":true,"img":false}]}
{"op":"mcm","clk":"5348183449","pt":1646215120741,"mc":[{"id":"1.195453723","rc":[{"atb":[[75,0],[50,0]],"id":41419634},{"atb":[[160,0.84],[110,0]],"id":41419619},{"atb":[[9.2,0],[8.2,0]],"id":41419594}],"con":true,"img":false}]}
{"op":"mcm","clk":"5348183455","pt":1646215120844,"mc":[{"id":"1.195453723","rc":[{"atb":[[10,11.11],[8.8,0]],"id":41419592}],"con":true,"img":false}]}
{"op":"mcm","clk":"5348183462","pt":1646215120951,"mc":[{"id":"1.195453723","rc":[{"atb":[[34,0],[15,6.54]],"id":41419609},{"atl":[[270,2],[280,0]],"id":41419593},{"atb":[[21,0],[27,3.85]],"id":41419585},{"atb":[[40,0],[21,5]],"id":41419616}],"con":true,"img":false}]}
{"op":"mcm","clk":"5348183501","pt":1646215121467,"mc":[{"id":"1.195453723","rc":[{"atb":[[80,2.72],[55,3.26]],"id":41419634}],"con":true,"img":false}]}
{"op":"mcm","clk":"5348183510","pt":1646215121569,"mc":[{"id":"1.195453723","rc":[{"atb":[[170,2.72],[120,3.26]],"id":41419619},{"atb":[[8.4,3.26],[9.4,2.72]],"id":41419594}],"con":true,"img":false}]}
{"op":"mcm","clk":"5348183641","pt":1646215123889,"mc":[{"id":"1.195453723","rc":[{"atl":[[990,0],[1000,2]],"id":41419609}],"con":true,"img":false}]}
{"op":"mcm","clk":"5348183655","pt":1646215124048,"mc":[{"id":"1.195453723","rc":[{"atl":[[280,2]],"id":41419593}],"con":true,"img":false}]}
{"op":"mcm","clk":"5348183660","pt":1646215124151,"mc":[{"id":"1.195453723","rc":[{"atl":[[270,0]],"id":41419593}],"con":true,"img":false}]}
{"op":"mcm","clk":"5348183699","pt":1646215124981,"mc":[{"id":"1.195453723","rc":[{"atb":[[16.5,0],[14,0]],"id":41419635}],"con":true,"img":false}]}
{"op":"mcm","clk":"5348183747","pt":1646215125652,"mc":[{"id":"1.195453723","rc":[{"atb":[[13.5,3.26]],"id":41419635}],"con":true,"img":false}]}
{"op":"mcm","clk":"5348183775","pt":1646215125960,"mc":[{"id":"1.195453723","rc":[{"atb":[[16,2.72]],"id":41419635}],"con":true,"img":false}]}
{"op":"mcm","clk":"5348184386","pt":1646215134801,"mc":[{"id":"1.195453723","rc":[{"atb":[[8,0],[20,0],[10,0]],"id":41419605},{"atb":[[6.2,0],[4.1,0],[3.55,0]],"id":41419593},{"atb":[[17.5,0],[75,0],[25,0]],"id":41419589},{"atb":[[24,0],[12,0],[8.8,0]],"id":41419601},{"atb":[[700,0],[400,0],[500,0]],"id":28546943},{"atb":[[190,0],[95,0],[390,0]],"id":41419602},{"atb":[[9.2,0],[26,0],[13,0]],"id":41419585},{"atb":[[660,0],[360,0],[460,0]],"id":41419586},{"atb":[[4.8,0],[3.4,0],[2.96,0]],"id":41419598},{"atb":[[5.8,0],[3.4,0],[3.9,0]],"id":41419594},{"atb":[[700,0],[400,0],[500,0]],"id":28546950},{"atb":[[16,0],[6.4,0],[8.4,0]],"id":41419603},{"atb":[[300,0],[100,0],[50,0]],"id":41419591},{"atb":[[260,0],[560,0],[360,0]],"id":41419587},{"atb":[[600,0],[300,0],[400,0]],"id":41419599},{"atb":[[17,0],[6.8,0],[8.8,0]],"id":41419595},{"atb":[[9.6,0],[19,0],[7.6,0]],"id":41419592},{"atb":[[700,0],[400,0],[500,0]],"id":41419588},{"atb":[[5.6,0],[9.2,0],[4.6,0]],"id":41419600},{"atb":[[2.72,0],[2.52,0],[3.3,0]],"id":41419596}],"con":true,"img":false}]}
{"op":"mcm","clk":"5348184393","pt":1646215134906,"mc":[{"id":"1.195453723","rc":[{"atb":[[310,0],[110,2.72],[55,0]],"id":41419609},{"atb":[[65,0],[36,0],[230,0]],"id":41419634},{"atb":[[18.5,0],[44,0],[13.5,0]],"id":41419617},{"atb":[[700,0],[400,2.72],[500,0]],"id":41419613},{"atb":[[8,14.29],[6,0],[15,0]],"id":41419622},{"atb":[[5.1,0],[10.5,0],[6.2,0]],"id":41419626},{"atb":[[300,0],[200,0],[500,0]],"id":41419606},{"atb":[[6.2,0],[4.1,0],[3.55,0]],"id":41419635},{"atb":[[8.6,0],[23,0],[11.5,0]],"id":41419614},{"atb":[[6.2,0],[8.2,0],[15.5,0]],"id":41419610},{"atb":[[7.4,0],[13.5,0],[5.7,0]],"id":41419623},{"atb":[[160,0],[42,0],[26,0]],"id":41419619},{"atb":[[8.8,0],[4.4,0],[5.4,0]],"id":41419607},{"atb":[[130,0],[430,0],[230,0]],"id":41419615},{"atb":[[16,0],[34,0],[11,0]],"id":41419624},{"atb":[[19,0],[46,0],[14,0]],"id":41419620},{"atb":[[24,0],[12,9.09],[8.8,0]],"id":41419608},{"atb":[[150,0],[75,0],[350,0]],"id":41419616},{"atb":[[9.6,0],[19,0],[7.6,0]],"id":41419612},{"atb":[[2.82,0],[4.1,0],[3.05,0]],"id":41419621}],"con":true,"img":false}]}
{"op":"mcm","clk":"5348184405","pt":1646215134964,"mc":[{"id":"1.195453723","rc":[{"atb":[[32,0],[21,0],[110,0]],"id":41419638},{"atb":[[130,0],[430,0],[230,0]],"id":41419655},{"atb":[[700,0],[400,0],[500,0]],"id":41435527},{"atb":[[22,0],[11,0],[8.4,0]],"id":41419651},{"atb":[[6.4,0],[11,0],[5.2,0]],"id":41419639},{"atb":[[16,0],[34,0],[11,0]],"id":41419656},{"atb":[[700,0],[400,0],[500,0]],"id":41419652},{"atb":[[180,0],[46,0],[28,0]],"id":41435528},{"atb":[[520,0],[320,0],[220,0]],"id":41419660},{"atb":[[19.5,0],[9.8,0],[7.8,0]],"id":41419636},{"atb":[[700,0],[400,0],[500,0]],"id":41419657},{"atb":[[700,0],[400,0],[500,0]],"id":41435525},{"atb":[[700,0],[400,0],[500,0]],"id":41419653},{"atb":[[18.5,0],[7.4,0],[9.4,11.9]],"id":41419637},{"atb":[[19,0],[90,0],[28,0]],"id":41435526},{"atb":[[700,0],[400,0],[500,3.26]],"id":41419658}],"con":true,"img":false}]}
{"op":"mcm","clk":"5348184411","pt":1646215135068,"mc":[{"id":"1.195453723","rc":[{"atb":[[10,11.11],[10.5,0]],"id":41419612}],"con":true,"img":false}]}
{"op":"mcm","clk":"5348184554","pt":1646215137694,"mc":[{"id":"1.195453723","rc":[{"atb":[[350,0],[400,0]],"id":41419613},{"atb":[[380,0],[430,0]],"id":28546943},{"atb":[[70,0],[95,0]],"id":41419606},{"atb":[[80,0],[55,0]],"id":41419585},{"atb":[[130,0],[180,0]],"id":41419586},{"atb":[[8.4,0],[9.4,0]],"id":41419594},{"atb":[[440,0],[490,0]],"id":28546950},{"atb":[[140,0],[95,0]],"id":41419591},{"atb":[[160,0],[110,0]],"id":41419587},{"atb":[[21,0],[26,0]],"id":41419592},{"atb":[[330,0],[380,0]],"id":41419588}],"con":true,"img":false}]}
{"op":"mcm","clk":"5348184566","pt":1646215137900,"mc":[{"id":"1.195453723","rc":[{"atb":[[36,2.86],[38,0]],"id":41419606},{"atb":[[27,3.85],[29,0]],"id":41419591},{"atb":[[10,0],[9.8,11.36]],"id":41419592}],"con":true,"img":false}]}
{"op":"mcm","clk":"5348184598","pt":1646215138371,"mc":[{"id":"1.195453723","rc":[{"atb":[[370,3.26],[420,2.72]],"id":41419613},{"atb":[[75,3.26],[100,2.72]],"id":41419606},{"atb":[[150,3.26],[200,2.72]],"id":41419586},{"atb":[[9.2,2.72],[8.2,3.26]],"id":41419594},{"atb":[[520,2.72],[470,3.26]],"id":28546950},{"atb":[[160,2.72],[110,3.26]],"id":41419591},{"atb":[[130,3.26],[180,2.72]],"id":41419587},{"atb":[[23,3.26],[28,2.72]],"id":41419592},{"atb":[[370,3.26],[420,2.72]],"id":41419588}],"con":true,"img":false}]}
{"op":"mcm","clk":"5348184615","pt":1646215138679,"mc":[{"id":"1.195453723","rc":[{"atb":[[430,3.26],[480,2.72]],"id":28546943},{"atb":[[65,3.26],[90,2.72]],"id":41419585}],"con":true,"img":false}]}
{"op":"mcm","clk":"5348184969","pt":1646215144082,"mc":[{"id":"1.195453723","rc":[{"atb":[[9.2,0]],"id":41419594}],"con":true,"img":false}]}
{"op":"mcm","clk":"5348184984","pt":1646215144393,"mc":[{"id":"1.195453723","rc":[{"atb":[[8.2,0]],"id":41419594}],"con":true,"img":false}]}
{"op":"mcm","clk":"5348185012","pt":1646215144797,"mc":[{"id":"1.195453723","rc":[{"atb":[[9,2.72]],"id":41419594}],"con":true,"img":false}]}
{"op":"mcm","clk":"5348185033","pt":1646215145210,"mc":[{"id":"1.195453723","rc":[{"atb":[[8,3.26]],"id":41419594}],"con":true,"img":false}]}
{"op":"mcm","clk":"5348185080","pt":1646215145897,"mc":[{"id":"1.195453723","rc":[{"atb":[[700,0.19],[400,0.67],[500,0.53]],"id":41419609},{"atb":[[540,0.25],[340,0.79],[240,1.12]],"id":41419638},{"atb":[[22,6.4],[11,26.9],[8.4,36.35]],"id":41419605},{"atb":[[310,0.43],[55,8.25],[110,2.46]],"id":41419634},{"atb":[[140,3.69],[38,9.97],[24,11.69]],"id":41419617},{"atb":[[700,0.19],[400,0.67],[500,0.53]],"id":41419613},{"atb":[[3.6,103.46],[6.4,24.9],[4.2,84.06]],"id":41419593},{"atb":[[540,0.25],[340,0.79],[240,1.12]],"id":41419655},{"atb":[[7.4,42.03],[13.5,10.75],[5.7,57.23]],"id":41419622},{"atb":[[16,17.93],[22,12.8],[60,2.27]],"id":41419589},{"atb":[[700,0.19],[400,0.67],[500,0.53]],"id":41435527},{"atb":[[8.6,35.39],[23,6.11],[11.5,25.61]],"id":41419651},{"atb":[[24,5.84],[12,24.45],[8.8,34.48]],"id":41419601},{"atb":[[700,0.19],[400,0.67],[500,0.53]],"id":28546943},{"atb":[[10,14.94],[5,67.25],[6,53.8]],"id":41419626},{"atb":[[5.3,62.55],[11.5,12.8],[6.6,48.03]],"id":41419639},{"atb":[[260,1.04],[160,1.68],[460,0.29]],"id":41419606},{"atb":[[7.2,21.69],[4.6,74.72],[3.8,96.07]],"id":41419635},{"atb":[[700,0.19],[400,0.67],[500,0.53]],"id":41419602},{"atb":[[27,9.02],[13.5,21.52],[9.4,32.02]],"id":41419585},{"atb":[[16.5,17.35],[36,6.7],[11.5,25.61]],"id":41419614},{"atb":[[7.4,42.03],[13.5,10.75],[5.7,57.23]],"id":41419610},{"atb":[[16.5,17.35],[36,6.7],[11.5,25.61]],"id":41419656},{"atb":[[5.3,62.55],[11.5,12.8],[6.6,48.03]],"id":41419623},{"atb":[[700,0.19],[400,0.67],[500,0.53]],"id":41419652},{"atb":[[140,0.97],[38,7.27],[24,11.69]],"id":41435528},{"atb":[[630,0.21],[330,0.81],[430,0.62]],"id":41419619},{"atb":[[690,0.19],[390,0.69],[490,0.55]],"id":41419586},{"atb":[[3.6,96.82],[3.1,119.87],[5.2,29.96]],"id":41419598},{"atb":[[630,0.21],[330,0.81],[430,0.62]],"id":41419660},{"atb":[[3.85,94.38],[3.35,114.46],[5.7,28.61]],"id":41419594},{"atb":[[5.2,64.04],[8.4,18.17],[4.2,84.06]],"id":41419607},{"atb":[[700,0.19],[400,0.67],[500,0.53]],"id":28546950},{"atb":[[21,6.72],[10.5,28.31],[8.2,37.36]],"id":41419636},{"atb":[[6.2,51.73],[8.2,37.36],[15.5,9.27]],"id":41419603},{"atb":[[700,0.19],[400,0.67],[500,0.53]],"id":41419615},{"atb":[[700,0.19],[400,0.67],[500,0.53]],"id":41419657},{"atb":[[70,1.95],[17,16.81],[24,11.69]],"id":41419624},{"atb":[[180,1.5],[90,3.02],[380,0.35]],"id":41419591},{"atb":[[700,0.19],[400,0.67],[500,0.53]],"id":41435525},{"atb":[[700,0.19],[400,0.67],[500,0.53]],"id":41419653},{"atb":[[17.5,16.3],[40,3.44],[12.5,23.39]],"id":41419620},{"atb":[[520,0.26],[320,0.84],[220,1.22]],"id":41419587},{"atb":[[620,0.21],[320,0.84],[420,0.64]],"id":41419599},{"atb":[[8.6,35.39],[23,6.11],[11.5,25.61]],"id":41419595},{"atb":[[12,33.54],[24,5.84],[8.8,34.48]],"id":41419608},{"atb":[[9.6,31.28],[19,7.47],[7.6,40.75]],"id":41419637},{"atb":[[700,0.19],[400,0.67],[500,0.53]],"id":41419616},{"atb":[[19.5,7.27],[9.8,30.56],[7.8,39.56]],"id":41419612},{"atb":[[19.5,7.27],[9.8,41.92],[7.8,39.56]],"id":41419592},{"atb":[[70,1.95],[17,16.81],[24,11.69]],"id":41435526},{"atb":[[2.92,140.1],[2.72,156.4],[3.8,48.03]],"id":41419621},{"atb":[[700,0.19],[400,0.67],[500,0.53]],"id":41419588},{"atb":[[5.7,57.23],[9.4,16.01],[4.7,72.7]],"id":41419600},{"atb":[[2.42,189.44],[2.62,166.05],[3.05,65.61]],"id":41419596},{"atb":[[700,0.19],[400,0.67],[500,3.8]],"id":41419658}],"con":true,"img":false}]}
{"op":"mcm","clk":"5348185098","pt":1646215146104,"mc":[{"id":"1.195453723","rc":[{"atb":[[9.6,11.63],[8.6,0]],"id":41419600}],"con":true,"img":false}]}
{"op":"mcm","clk":"5348185584","pt":1646215154333,"mc":[{"id":"1.195453723","rc":[{"atb":[[36,2.72],[28,3.26]],"id":41419612}],"con":true,"img":false}]}
{"op":"mcm","clk":"5348186442","pt":1646215165753,"mc":[{"id":"1.195453723","rc":[{"atb":[[16,0],[13.5,0]],"id":41419635},{"atb":[[40,0],[30,0]],"id":41419636}],"con":true,"img":false}]}
{"op":"mcm","clk":"5348186500","pt":1646215166526,"mc":[{"id":"1.195453723","rc":[{"atb":[[12.5,3.26],[15,2.72]],"id":41419635},{"atb":[[38,2.72],[29,3.26]],"id":41419636}],"con":true,"img":false}]}
{"op":"mcm","clk":"5348187400","pt":1646215179855,"mc":[{"id":"1.195453723","rc":[{"atb":[[38,0],[29,0]],"id":41419636}],"con":true,"img":false}]}
{"op":"mcm","clk":"5348187460","pt":1646215180745,"mc":[{"id":"1.195453723","rc":[{"atb":[[36,2.72],[28,3.26]],"id":41419636}],"con":true,"img":false}]}
{"op":"mcm","clk":"5348188186","pt":1646215193389,"mc":[{"id":"1.195453723","rc":[{"atb":[[22,0],[11,0],[8.4,0]],"id":41419605},{"atb":[[3.6,0],[6.4,0],[4.2,0]],"id":41419593},{"atb":[[16,0],[22,0],[60,0]],"id":41419589},{"atb":[[24,0],[12,0],[8.8,0]],"id":41419601},{"atb":[[700,0],[400,0],[500,0]],"id":28546943},{"atb":[[700,0],[400,0],[500,0]],"id":41419602},{"atb":[[27,3.85],[13.5,0],[9.4,0]],"id":41419585},{"atb":[[690,0],[390,0],[490,0]],"id":41419586},{"atb":[[3.6,0],[3.1,0],[5.2,0]],"id":41419598},{"atb":[[3.85,0],[3.35,0],[5.7,0]],"id":41419594},{"atb":[[700,0],[400,0],[500,0]],"id":28546950},{"atb":[[6.2,0],[8.2,0],[15.5,0]],"id":41419603},{"atb":[[180,0],[90,0],[380,0]],"id":41419591},{"atb":[[520,0],[320,0],[220,0]],"id":41419587},{"atb":[[620,0],[320,0],[420,0]],"id":41419599},{"atb":[[8.6,0],[23,0],[11.5,0]],"id":41419595},{"atb":[[19.5,0],[9.8,11.36],[7.8,0]],"id":41419592},{"atb":[[700,0],[400,0],[500,0]],"id":41419588},{"atb":[[5.7,0],[9.4,0],[4.7,0]],"id":41419600},{"atb":[[2.42,0],[2.62,0],[3.05,0]],"id":41419596}],"con":true,"img":false}]}
{"op":"mcm","clk":"5348188193","pt":1646215193503,"mc":[{"id":"1.195453723","rc":[{"atb":[[700,0],[400,0],[500,0]],"id":41419609},{"atb":[[310,0],[110,0],[55,3.26]],"id":41419634},{"atb":[[140,2.72],[38,2.7],[24,0]],"id":41419617},{"atb":[[700,0],[400,0],[500,0]],"id":41419613},{"atb":[[7.4,0],[13.5,0],[5.7,0]],"id":41419622},{"atb":[[10,0],[5,0],[6,0]],"id":41419626},{"atb":[[260,0],[160,0],[460,0]],"id":41419606},{"atb":[[7.2,0],[4.6,0],[3.8,0]],"id":41419635},{"atb":[[16.5,0],[36,2.86],[11.5,0]],"id":41419614},{"atb":[[7.4,0],[13.5,0],[5.7,0]],"id":41419610},{"atb":[[5.3,0],[11.5,0],[6.6,0]],"id":41419623},{"atb":[[630,0],[330,0],[430,0]],"id":41419619},{"atb":[[5.2,0],[8.4,0],[4.2,0]],"id":41419607},{"atb":[[700,0],[400,0],[500,0]],"id":41419615},{"atb":[[70,0],[17,0],[24,0]],"id":41419624},{"atb":[[17.5,0],[40,0],[12.5,0]],"id":41419620},{"atb":[[24,0],[12,9.09],[8.8,0]],"id":41419608},{"atb":[[700,0],[400,0],[500,0]],"id":41419616},{"atb":[[19.5,0],[9.8,0],[7.8,0]],"id":41419612},{"atb":[[2.92,0],[2.72,0],[3.8,0]],"id":41419621}],"con":true,"img":false}]}
{"op":"mcm","clk":"5348188209","pt":1646215193695,"mc":[{"id":"1.195453723","rc":[{"atb":[[540,0],[340,0],[240,0]],"id":41419638},{"atb":[[540,0],[340,0],[240,0]],"id":41419655},{"atb":[[700,0],[400,0],[500,0]],"id":41435527},{"atb":[[8.6,0],[23,0],[11.5,0]],"id":41419651},{"atb":[[5.3,0],[11.5,0],[6.6,0]],"id":41419639},{"atb":[[16.5,0],[36,2.86],[11.5,0]],"id":41419656},{"atb":[[700,0],[400,0],[500,0]],"id":41419652},{"atb":[[140,0],[38,0],[24,0]],"id":41435528},{"atb":[[630,0],[330,0],[430,0]],"id":41419660},{"atb":[[21,0],[10.5,0],[8.2,0]],"id":41419636},{"atb":[[700,0],[400,0],[500,0]],"id":41419657},{"atb":[[700,0],[400,0],[500,0]],"id":41435525},{"atb":[[700,0],[400,0],[500,0]],"id":41419653},{"atb":[[9.6,0],[19,0],[7.6,0]],"id":41419637},{"atb":[[70,0],[17,0],[24,0]],"id":41435526},{"atb":[[700,0],[400,0],[500,3.26]],"id":41419658}],"con":true,"img":false}]}
{"op":"mcm","clk":"5348188600","pt":1646215199267,"mc":[{"id":"1.195453723","rc":[{"atb":[[21,0],[26,0]],"id":41419595}],"con":true,"img":false}]}
{"op":"mcm","clk":"5348188656","pt":1646215199995,"mc":[{"id":"1.195453723","rc":[{"atb":[[22,3.26],[27,2.72]],"id":41419595}],"con":true,"img":false}]}
{"op":"mcm","clk":"5348188754","pt":1646215200798,"mc":[{"id":"1.195453723","rc":[{"atb":[[3.95,3.55]],"id":41419598}],"con":true,"img":false}]}
{"op":"mcm","clk":"5348188846","pt":1646215201455,"mc":[{"id":"1.195453723","rc":[{"atb":[[3.95,3.49]],"id":41419598}],"con":true,"img":false}]}
{"op":"mcm","clk":"5348189264","pt":1646215205293,"mc":[{"id":"1.195453723","rc":[{"atb":[[400,0.33],[200,1.35],[100,2.71]],"id":41419638},{"atb":[[400,0.33],[200,1.35],[100,2.71]],"id":41419634},{"atb":[[19.5,14.54],[95,4.7],[29,9.6]],"id":41419617},{"atb":[[700,0.19],[400,0.67],[500,0.53]],"id":41419613},{"atb":[[610,0.22],[310,0.87],[410,0.65]],"id":41419655},{"atb":[[5.8,56.04],[7.6,40.75],[14,10.34]],"id":41419622},{"atb":[[700,0.19],[400,0.67],[500,0.53]],"id":41435527},{"atb":[[5.1,65.61],[10.5,14.15],[6.2,51.73]],"id":41419626},{"atb":[[5.3,62.55],[11.5,12.8],[6.6,48.03]],"id":41419639},{"atb":[[4.5,105.42],[7,22.41],[3.75,97.82]],"id":41419635},{"atb":[[9.8,30.56],[29,4.8],[14.5,19.92]],"id":41419614},{"atb":[[17.5,16.3],[40,3.44],[12.5,23.39]],"id":41419656},{"atb":[[12,12.22],[6.8,46.37],[5.4,61.13]],"id":41419623},{"atb":[[32,8.67],[210,0.64],[55,4.98]],"id":41435528},{"atb":[[280,0.96],[180,1.5],[480,0.28]],"id":41419619},{"atb":[[700,0.19],[400,0.67],[500,0.53]],"id":41419660},{"atb":[[700,0.19],[400,0.67],[500,0.53]],"id":28546950},{"atb":[[21,6.72],[10.5,28.31],[8.2,37.36]],"id":41419636},{"atb":[[700,0.19],[400,0.67],[500,0.53]],"id":41419615},{"atb":[[700,0.19],[400,0.67],[500,0.53]],"id":41419657},{"atb":[[21,13.45],[55,2.49],[15.5,25.45]],"id":41419624},{"atb":[[700,0.19],[400,0.67],[500,0.53]],"id":41419653},{"atb":[[21,13.45],[55,5.21],[15.5,18.55]],"id":41419620},{"atb":[[9.6,31.28],[19,7.47],[7.6,40.75]],"id":41419637},{"atb":[[640,0.21],[340,0.79],[440,0.61]],"id":41419616},{"atb":[[20,14.15],[100,1.35],[30,9.27]],"id":41435526},{"atb":[[3.9,46.37],[2.96,137.24],[2.76,152.84]],"id":41419621},{"atb":[[700,0.19],[400,0.67],[500,3.8]],"id":41419658}],"con":true,"img":false}]}
{"op":"mcm","clk":"5348189274","pt":1646215205392,"mc":[{"id":"1.195453723","rc":[{"atb":[[270,0.99],[570,0.23],[370,0.73]],"id":41419609},{"atb":[[21,6.72],[10.5,28.31],[8.2,37.36]],"id":41419605},{"atb":[[6.2,25.86],[4.1,86.77],[3.55,105.49]],"id":41419593},{"atb":[[19.5,14.54],[95,1.43],[29,9.6]],"id":41419589},{"atb":[[24,5.84],[12,24.45],[8.8,34.48]],"id":41419651},{"atb":[[8.6,35.39],[23,6.11],[11.5,25.61]],"id":41419601},{"atb":[[700,0.19],[400,0.67],[500,0.53]],"id":28546943},{"atb":[[270,0.99],[570,0.23],[370,0.73]],"id":41419606},{"atb":[[700,0.19],[400,0.67],[500,0.53]],"id":41419602},{"atb":[[9.8,30.56],[29,4.8],[14.5,19.92]],"id":41419585},{"atb":[[7.4,42.03],[13.5,10.75],[5.7,57.23]],"id":41419610},{"atb":[[700,0.19],[400,0.67],[500,0.53]],"id":41419652},{"atb":[[700,0.19],[400,0.67],[500,0.53]],"id":41419586},{"atb":[[5.1,30.69],[3.55,98.72],[3.05,122.8]],"id":41419598},{"atb":[[5.6,29.23],[3.8,96.07],[3.3,116.96]],"id":41419594},{"atb":[[5.2,64.04],[8.4,18.17],[4.2,84.06]],"id":41419607},{"atb":[[6.2,51.73],[8.2,37.36],[15.5,9.27]],"id":41419603},{"atb":[[280,0.96],[180,1.5],[480,0.28]],"id":41419591},{"atb":[[700,0.19],[400,0.67],[500,0.53]],"id":41435525},{"atb":[[640,0.21],[340,0.79],[440,0.61]],"id":41419587},{"atb":[[700,0.19],[400,0.67],[500,0.53]],"id":41419599},{"atb":[[21,6.72],[10.5,28.31],[8.2,37.36]],"id":41419595},{"atb":[[8.6,35.39],[23,6.11],[11.5,25.61]],"id":41419608},{"atb":[[9.6,31.28],[19,7.47],[7.6,40.75]],"id":41419612},{"atb":[[21,6.72],[10.5,28.31],[8.2,37.36]],"id":41419592},{"atb":[[700,0.19],[400,0.67],[500,0.53]],"id":41419588},{"atb":[[5.6,58.47],[9.2,16.4],[4.6,74.72]],"id":41419600},{"atb":[[3.1,64.04],[2.64,164.03],[2.44,186.81]],"id":41419596}],"con":true,"img":false}]}
{"op":"mcm","clk":"5348189314","pt":1646215205862,"mc":[{"id":"1.195453723","rc":[{"atb":[[3.95,2.72]],"id":41419598}],"con":true,"img":false}]}
{"op":"mcm","clk":"5348189324","pt":1646215205967,"mc":[{"id":"1.195453723","rc":[{"atb":[[5.2,0.76]],"id":41419598}],"con":true,"img":false}]}
{"op":"mcm","clk":"5348189713","pt":1646215210889,"mc":[{"id":"1.195453723","rc":[{"atl":[[1000,0]],"id":41419620}],"con":true,"img":false}]}
{"op":"mcm","clk":"5348189751","pt":1646215211409,"mc":[{"id":"1.195453723","rc":[{"atb":[[3.95,0],[3.7,0]],"id":41419598}],"con":true,"img":false}]}
{"op":"mcm","clk":"5348189819","pt":1646215212189,"mc":[{"id":"1.195453723","rc":[{"atb":[[4,2.72],[3.75,3.26]],"id":41419598}],"con":true,"img":false}]}
{"op":"mcm","clk":"5348190158","pt":1646215216313,"mc":[{"id":"1.195453723","rc":[{"atb":[[370,0],[420,0]],"id":41419613}],"con":true,"img":false}]}
{"op":"mcm","clk":"5348190216","pt":1646215216828,"mc":[{"id":"1.195453723","rc":[{"atb":[[1.02,0.83]],"id":41419613}],"con":true,"img":false}]}
{"op":"mcm","clk":"5348190235","pt":1646215216989,"mc":[{"id":"1.195453723","rc":[{"atb":[[440,2.72]],"id":41419613}],"con":true,"img":false}]}
{"op":"mcm","clk":"5348190271","pt":1646215217303,"mc":[{"id":"1.195453723","rc":[{"atb":[[390,3.26]],"id":41419613}],"con":true,"img":false}]}
{"op":"mcm","clk":"5348190415","pt":1646215219243,"mc":[{"id":"1.195453723","rc":[{"atb":[[70,0],[95,0]],"id":41419614},{"atb":[[160,0],[210,0]],"id":41419615},{"atb":[[460,0],[510,0]],"id":41419653},{"atb":[[140,0],[190,0]],"id":41419616},{"atb":[[370,0],[420,0]],"id":41419588}],"con":true,"img":false}]}
{"op":"mcm","clk":"5348190438","pt":1646215219425,"mc":[{"id":"1.195453723","rc":[{"atb":[[12.5,0],[15,0]],"id":41419635}],"con":true,"img":false}]}
{"op":"mcm","clk":"5348190475","pt":1646215219993,"mc":[{"id":"1.195453723","rc":[{"atb":[[75,3.26],[100,2.72]],"id":41419614},{"atb":[[170,3.26],[220,2.72]],"id":41419615},{"atb":[[520,2.72],[470,3.26]],"id":41419653},{"atb":[[150,3.26],[200,2.72]],"id":41419616},{"atb":[[380,3.26],[430,2.72]],"id":41419588}],"con":true,"img":false}]}
{"op":"mcm","clk":"5348190487","pt":1646215220202,"mc":[{"id":"1.195453723","rc":[{"atb":[[12,3.26],[14.5,2.72]],"id":41419635}],"con":true,"img":false}]}
{"op":"mcm","clk":"5348190984","pt":1646215226128,"mc":[{"id":"1.195453723","rc":[{"atl":[[1000,2]],"id":41419620}],"con":true,"img":false}]}
{"op":"mcm","clk":"5348191298","pt":1646215230312,"mc":[{"id":"1.195453723","marketDefinition":{"bspMarket":false,"turnInPlayEnabled":false,"persistenceEnabled":false,"marketBaseRate":7.0,"eventId":"31272494","eventTypeId":"4339","numberOfWinners":1,"bettingType":"ODDS","marketType":"EXACTA","marketTime":"2022-03-02T10:11:00.000Z","suspendTime":"2022-03-02T10:11:00.000Z","bspReconciled":false,"complete":true,"inPlay":false,"crossMatching":true,"runnersVoidable":false,"numberOfActiveRunners":56,"betDelay":0,"status":"OPEN","runners":[{"status":"ACTIVE","sortPriority":1,"id":41419585,"name":"1 - 2"},{"status":"ACTIVE","sortPriority":2,"id":41419586,"name":"1 - 3"},{"status":"ACTIVE","sortPriority":3,"id":41419587,"name":"1 - 4"},{"status":"ACTIVE","sortPriority":4,"id":41419588,"name":"1 - 5"},{"status":"ACTIVE","sortPriority":5,"id":41419589,"name":"1 - 6"},{"status":"ACTIVE","sortPriority":6,"id":41419591,"name":"1 - 8"},{"status":"ACTIVE","sortPriority":7,"id":28546943,"name":"1 - 9"},{"status":"ACTIVE","sortPriority":8,"id":41419592,"name":"2 - 1"},{"status":"ACTIVE","sortPriority":9,"id":41419593,"name":"2 - 3"},{"status":"ACTIVE","sortPriority":10,"id":41419594,"name":"2 - 4"},{"status":"ACTIVE","sortPriority":11,"id":41419595,"name":"2 - 5"},{"status":"ACTIVE","sortPriority":12,"id":41419596,"name":"2 - 6"},{"status":"ACTIVE","sortPriority":13,"id":41419598,"name":"2 - 8"},{"status":"ACTIVE","sortPriority":14,"id":41419651,"name":"2 - 9"},{"status":"ACTIVE","sortPriority":15,"id":41419599,"name":"3 - 1"},{"status":"ACTIVE","sortPriority":16,"id":41419600,"name":"3 - 2"},{"status":"ACTIVE","sortPriority":17,"id":41419601,"name":"3 - 4"},{"status":"ACTIVE","sortPriority":18,"id":41419602,"name":"3 - 5"},{"status":"ACTIVE","sortPriority":19,"id":41419603,"name":"3 - 6"},{"status":"ACTIVE","sortPriority":20,"id":41419605,"name":"3 - 8"},{"status":"ACTIVE","sortPriority":21,"id":41419652,"name":"3 - 9"},{"status":"ACTIVE","sortPriority":22,"id":41419606,"name":"4 - 1"},{"status":"ACTIVE","sortPriority":23,"id":41419607,"name":"4 - 2"},{"status":"ACTIVE","sortPriority":24,"id":41419608,"name":"4 - 3"},{"status":"ACTIVE","sortPriority":25,"id":41419609,"name":"4 - 5"},{"status":"ACTIVE","sortPriority":26,"id":41419610,"name":"4 - 6"},{"status":"ACTIVE","sortPriority":27,"id":41419612,"name":"4 - 8"},{"status":"ACTIVE","sortPriority":28,"id":41435525,"name":"4 - 9"},{"status":"ACTIVE","sortPriority":29,"id":41419613,"name":"5 - 1"},{"status":"ACTIVE","sortPriority":30,"id":41419614,"name":"5 - 2"},{"status":"ACTIVE","sortPriority":31,"id":41419615,"name":"5 - 3"},{"status":"ACTIVE","sortPriority":32,"id":41419616,"name":"5 - 4"},{"status":"ACTIVE","sortPriority":33,"id":41419617,"name":"5 - 6"},{"status":"ACTIVE","sortPriority":34,"id":41419619,"name":"5 - 8"},{"status":"ACTIVE","sortPriority":35,"id":41419653,"name":"5 - 9"},{"status":"ACTIVE","sortPriority":36,"id":41419620,"name":"6 - 1"},{"status":"ACTIVE","sortPriority":37,"id":41419621,"name":"6 - 2"},{"status":"ACTIVE","sortPriority":38,"id":41419622,"name":"6 - 3"},{"status":"ACTIVE","sortPriority":39,"id":41419623,"name":"6 - 4"},{"status":"ACTIVE","sortPriority":40,"id":41419624,"name":"6 - 5"},{"status":"ACTIVE","sortPriority":41,"id":41419626,"name":"6 - 8"},{"status":"ACTIVE","sortPriority":42,"id":41435526,"name":"6 - 9"},{"status":"ACTIVE","sortPriority":43,"id":41419634,"name":"8 - 1"},{"status":"ACTIVE","sortPriority":44,"id":41419635,"name":"8 - 2"},{"status":"ACTIVE","sortPriority":45,"id":41419636,"name":"8 - 3"},{"status":"ACTIVE","sortPriority":46,"id":41419637,"name":"8 - 4"},{"status":"ACTIVE","sortPriority":47,"id":41419638,"name":"8 - 5"},{"status":"ACTIVE","sortPriority":48,"id":41419639,"name":"8 - 6"},{"status":"ACTIVE","sortPriority":49,"id":41419655,"name":"8 - 9"},{"status":"ACTIVE","sortPriority":50,"id":28546950,"name":"9 - 1"},{"status":"ACTIVE","sortPriority":51,"id":41419656,"name":"9 - 2"},{"status":"ACTIVE","sortPriority":52,"id":41419657,"name":"9 - 3"},{"status":"ACTIVE","sortPriority":53,"id":41435527,"name":"9 - 4"},{"status":"ACTIVE","sortPriority":54,"id":41419658,"name":"9 - 5"},{"status":"ACTIVE","sortPriority":55,"id":41435528,"name":"9 - 6"},{"status":"ACTIVE","sortPriority":56,"id":41419660,"name":"9 - 8"}],"regulators":["MR_INT"],"venue":"Traralgon","countryCode":"AU","discountAllowed":true,"timezone":"Australia/Sydney","openDate":"2022-03-02T08:31:00.000Z","version":4382480625,"name":"Exacta","eventName":"Traralgon (AUS) 2nd Mar"},"rc":[],"con":true,"img":false}]}
{"op":"mcm","clk":"5348192331","pt":1646215242564,"mc":[{"id":"1.195453723","rc":[{"atl":[[1000,0]],"id":41419620}],"con":true,"img":false}]}
{"op":"mcm","clk":"5348193202","pt":1646215254472,"mc":[{"id":"1.195453723","rc":[{"atb":[[36,0],[28,0]],"id":41419636}],"con":true,"img":false}]}
{"op":"mcm","clk":"5348193265","pt":1646215255150,"mc":[{"id":"1.195453723","rc":[{"atb":[[38,2.72],[29,3.26]],"id":41419636}],"con":true,"img":false}]}
{"op":"mcm","clk":"5348193609","pt":1646215260564,"mc":[{"id":"1.195453723","rc":[{"atl":[[1000,2]],"id":41419620}],"con":true,"img":false}]}
{"op":"mcm","clk":"5348193630","pt":1646215260878,"mc":[{"id":"1.195453723","rc":[{"atb":[[110,7.67]],"id":41419609},{"atl":[[990,0.15]],"id":41419609},{"atl":[[700,1.74]],"id":41419638},{"atb":[[42,9.9],[48,3.37],[50,4.95]],"id":41419605},{"atl":[[160,4.95],[690,0.22]],"id":41419605},{"atb":[[150,4.95],[110,9.9]],"id":41419634},{"atl":[[1000,0.15]],"id":41419634},{"atb":[[150,1.06],[38,10.78],[160,4.95],[120,9.9]],"id":41419617},{"atl":[[1000,0.15]],"id":41419617},{"atb":[[7.8,4.95],[7,9.9]],"id":41419593},{"atl":[[16.5,4.95],[270,0.58],[18.5,9.9]],"id":41419593},{"atb":[[150,4.95],[110,9.9]],"id":41419655},{"atb":[[19,9.9],[22,8.22],[14,19.24]],"id":41419622},{"atl":[[530,2.31],[75,9.9],[55,4.95],[500,0.31]],"id":41419622},{"atb":[[130,1.23],[85,11.35]],"id":41419589},{"atb":[[34,14.71],[42,4.95],[24,14.75]],"id":41419651},{"atl":[[590,0.26],[620,1.97],[85,4.95],[110,9.9]],"id":41419651},{"atb":[[28,12.6],[60,2.68]],"id":41419601},{"atl":[[800,0.19],[830,1.47]],"id":41419601},{"atb":[[16,4.95],[14,13.17]],"id":41419626},{"atl":[[32,4.95],[40,9.9]],"id":41419626},{"atb":[[19.5,13.17],[23,4.95],[24,9.61]],"id":41419639},{"atl":[[42,4.95],[50,9.9],[500,0.31]],"id":41419639},{"atl":[[1000,0.15]],"id":41419606},{"atb":[[7,31.32]],"id":41419635},{"atl":[[380,3.23]],"id":41419635},{"atb":[[160,4.95],[29,14.52],[120,9.9]],"id":41419585},{"atb":[[130,4.95],[36,11.36],[95,9.9],[110,1.45]],"id":41419614},{"atl":[[1000,0.15]],"id":41419614},{"atb":[[34,4.8],[36,4.95],[13.5,19.66],[29,9.9]],"id":41419610},{"atl":[[610,0.26],[80,4.95],[640,1.91],[100,9.9]],"id":41419610},{"atb":[[130,1.23],[160,4.95],[120,12.63]],"id":41419656},{"atl":[[1000,0.15]],"id":41419656},{"atb":[[19,9.9],[22,4.95]],"id":41419623},{"atl":[[46,4.95],[60,9.9]],"id":41419623},{"atb":[[160,4.95]],"id":41419652},{"atb":[[160,4.95],[220,0.72],[120,21.26]],"id":41435528},{"atb":[[6.2,4.95],[5.2,7.78],[5.7,9.9],[3.75,12.17]],"id":41419598},{"atl":[[9.2,4.95],[10,9.9],[220,0.72],[250,4.97]],"id":41419598},{"atb":[[16.5,9.9],[18.5,4.95],[21,10.65],[8.4,27.08]],"id":41419607},{"atl":[[38,4.95],[46,9.9],[460,0.34],[490,2.5]],"id":41419607},{"atb":[[24,9.9],[28,4.95]],"id":41419636},{"atl":[[95,4.95]],"id":41419636},{"atb":[[40,4.06],[15.5,18.18]],"id":41419603},{"atl":[[720,0.21],[750,1.63]],"id":41419603},{"atb":[[44,11.01]],"id":41419624},{"atl":[[660,0.23],[690,1.77]],"id":41419624},{"atb":[[160,7.67],[180,4.35]],"id":41419591},{"atb":[[160,4.95],[120,12.63]],"id":41435525},{"atl":[[1000,0.15]],"id":41435525},{"atb":[[34,12.75],[85,9.9],[110,4.95],[60,2.68]],"id":41419620},{"atl":[[1000,2.15]],"id":41419620},{"atb":[[17,9.9],[19,4.95]],"id":41419595},{"atl":[[75,9.9],[55,4.95],[470,2.61]],"id":41419595},{"atb":[[40,9.9],[23,15.01],[48,11.05]],"id":41419608},{"atl":[[140,4.95],[650,0.24],[680,1.8]],"id":41419608},{"atb":[[19,16.37]],"id":41419637},{"atl":[[520,0.3],[550,2.22]],"id":41419637},{"atb":[[36,7.67],[19,16.37],[29,9.9]],"id":41419612},{"atl":[[620,2.09],[80,4.95],[100,9.9]],"id":41419612},{"atb":[[46,10.28],[110,1.45]],"id":41435526},{"atl":[[990,0.15]],"id":41435526},{"atb":[[10,4.95],[9.2,9.9],[4.4,38.31],[9.4,11.63]],"id":41419621},{"atl":[[16,4.95],[18,9.9],[330,0.47],[360,3.41]],"id":41419621},{"atb":[[22,9.9],[26,7.67]],"id":41419600},{"atl":[[65,4.95],[85,9.9]],"id":41419600},{"atl":[[130,1.23]],"id":41419596}],"con":true,"img":false}]}
{"op":"mcm","clk":"5348193637","pt":1646215260984,"mc":[{"id":"1.195453723","rc":[{"atl":[[670,0.23]],"id":41419638},{"atb":[[21,15.63]],"id":41419605},{"atl":[[720,1.7]],"id":41419605},{"atb":[[100,6.73]],"id":41419634},{"atb":[[6.2,34.77]],"id":41419593},{"atl":[[300,4.09]],"id":41419593},{"atl":[[1000,0.15]],"id":41419655},{"atb":[[160,4.95],[120,12.63]],"id":41419589},{"atb":[[70,9.9],[90,4.95]],"id":41419601},{"atl":[[200,4.95]],"id":41419601},{"atb":[[17.5,11.63],[10.5,23.06]],"id":41419626},{"atl":[[440,0.35],[470,2.69]],"id":41419626},{"atb":[[11.5,21.71]],"id":41419639},{"atl":[[530,2.31]],"id":41419639},{"atb":[[160,4.95],[120,9.9]],"id":41419606},{"atl":[[1000,0.15]],"id":41419602},{"atb":[[95,1.68]],"id":41419585},{"atl":[[1000,0.15]],"id":41419585},{"atb":[[40,13.17]],"id":41419656},{"atb":[[24,9.61]],"id":41419623},{"atl":[[520,0.3]],"id":41419623},{"atb":[[180,4.35]],"id":41419619},{"atb":[[5.6,38.14],[9,11.63],[8.2,4.95],[7.4,9.9]],"id":41419594},{"atl":[[360,0.44],[390,3.15],[13.5,4.95],[15.5,9.9]],"id":41419594},{"atb":[[21,15.63]],"id":41419636},{"atl":[[540,2.27],[510,0.31]],"id":41419636},{"atb":[[46,9.9],[60,4.95]],"id":41419603},{"atl":[[130,4.95]],"id":41419603},{"atb":[[38,9.9],[46,4.95]],"id":41419624},{"atl":[[170,4.95]],"id":41419624},{"atb":[[160,4.95],[120,12.63]],"id":41419599},{"atl":[[440,0.35]],"id":41419595},{"atb":[[22,9.9],[26,4.95]],"id":41419637},{"atl":[[80,9.9],[60,4.95]],"id":41419637},{"atb":[[36,12.2]],"id":41419612},{"atl":[[590,0.26]],"id":41419612},{"atb":[[34,4.95],[21,15.63],[28,12.63],[29,5.66]],"id":41419592},{"atl":[[560,0.28],[590,2.08],[80,4.95],[100,9.9]],"id":41419592},{"atb":[[130,4.95],[95,9.9]],"id":41435526},{"atb":[[9.6,20.53],[26,14.02]],"id":41419600},{"atl":[[520,0.3],[550,2.22]],"id":41419600},{"atb":[[5.3,13.17],[3.55,48.12],[5.7,4.95]],"id":41419596},{"atl":[[9.6,4.95],[160,7.69],[11,9.9]],"id":41419596}],"con":true,"img":false}]}
{"op":"mcm","clk":"5348193646","pt":1646215261091,"mc":[{"id":"1.195453723","rc":[{"atl":[[680,0],[700,3.74]],"id":41419638},{"atl":[[700,0],[440,2]],"id":41419605},{"atl":[[280,0],[28,3.7]],"id":41419593},{"atl":[[140,2],[510,0]],"id":41419622},{"atl":[[600,0],[300,2]],"id":41419651},{"atl":[[810,0],[820,2]],"id":41419601},{"atl":[[90,2],[450,0]],"id":41419626},{"atl":[[140,2],[510,0]],"id":41419639},{"atl":[[360,0],[370,2]],"id":41419635},{"atl":[[620,0],[310,2]],"id":41419610},{"atl":[[530,0],[130,2]],"id":41419623},{"atl":[[26,4],[230,0]],"id":41419598},{"atl":[[110,2],[470,0]],"id":41419607},{"atl":[[520,0],[170,2]],"id":41419636},{"atb":[[17.5,6.06],[14.5,0]],"id":41419603},{"atl":[[730,0],[740,2]],"id":41419603},{"atl":[[670,0],[680,2]],"id":41419624},{"atl":[[110,2],[450,0]],"id":41419595},{"atl":[[660,0],[380,2]],"id":41419608},{"atl":[[530,0],[540,2]],"id":41419637},{"atl":[[600,0],[310,2]],"id":41419612},{"atl":[[340,0],[55,2]],"id":41419621},{"atl":[[530,0],[190,2]],"id":41419600}],"con":true,"img":false}]}
{"op":"mcm","clk":"5348193654","pt":1646215261191,"mc":[{"id":"1.195453723","rc":[{"atl":[[65,2],[370,0]],"id":41419594},{"atl":[[570,0],[320,2]],"id":41419592},{"atl":[[140,0],[19.5,5.41]],"id":41419596}],"con":true,"img":false}]}
{"op":"mcm","clk":"5348193666","pt":1646215261296,"mc":[{"id":"1.195453723","rc":[{"atl":[[680,0],[360,2]],"id":41419624}],"con":true,"img":false}]}
{"op":"mcm","clk":"5348193699","pt":1646215261676,"mc":[{"id":"1.195453723","rc":[{"atb":[[10,9.9],[12,8.22]],"id":41419635},{"atl":[[19.5,4.95],[350,0.45],[23,9.9]],"id":41419635},{"atb":[[140,4.95]],"id":41419602},{"atb":[[12,21.13]],"id":41419623},{"atl":[[550,2.22]],"id":41419623},{"atb":[[5.8,17.43]],"id":41419596}],"con":true,"img":false}]}
{"op":"mcm","clk":"5348193709","pt":1646215261876,"mc":[{"id":"1.195453723","rc":[{"atl":[[1000,0]],"id":41419602}],"con":true,"img":false}]}
{"op":"mcm","clk":"5348193762","pt":1646215262608,"mc":[{"id":"1.195453723","rc":[{"atl":[[1000,0.15]],"id":41419602}],"con":true,"img":false}]}
{"op":"mcm","clk":"5348194012","pt":1646215266290,"mc":[{"id":"1.195453723","rc":[{"atl":[[690,2.22],[440,0]],"id":41419605},{"atl":[[170,0],[510,2.31]],"id":41419636},{"atl":[[650,2.24],[380,0]],"id":41419608}],"con":true,"img":false}]}
{"op":"mcm","clk":"5348194021","pt":1646215266391,"mc":[{"id":"1.195453723","rc":[{"atl":[[660,2.23]],"id":41419624}],"con":true,"img":false}]}
{"op":"mcm","clk":"5348194029","pt":1646215266497,"mc":[{"id":"1.195453723","rc":[{"atl":[[360,0]],"id":41419624}],"con":true,"img":false}]}
{"op":"mcm","clk":"5348194097","pt":1646215267115,"mc":[{"id":"1.195453723","rc":[{"atb":[[20,0],[29,3.57]],"id":41419638},{"atb":[[50,2.04]],"id":41419617},{"atb":[[40,0]],"id":41419613},{"atb":[[50,2.04]],"id":41419655},{"atb":[[17.5,6.06],[10.5,0]],"id":41419651},{"atb":[[28,8.9]],"id":41419601},{"atb":[[42,0],[60,2]],"id":28546943},{"atb":[[7.2,0],[9.8,11.36]],"id":41419639},{"atb":[[5.9,20.41]],"id":41419635},{"atb":[[36,8.5],[50,2.04]],"id":41419614},{"atb":[[8.2,0],[12,30.22]],"id":41419623},{"atb":[[40,0],[50,2.04]],"id":41419652},{"atb":[[40,0]],"id":41435528},{"atb":[[40,0]],"id":41419586},{"atb":[[4.1,17.69],[3.3,0]],"id":41419598},{"atb":[[40,0],[55,2]],"id":41419660},{"atb":[[4,0]],"id":41419594},{"atb":[[8,0],[10.5,10.53]],"id":41419607},{"atb":[[60,2]],"id":28546950},{"atb":[[38,0],[48,2]],"id":41419615},{"atb":[[50,2]],"id":41419657},{"atb":[[15.5,18.55]],"id":41419624},{"atb":[[40,0],[60,2]],"id":41419653},{"atb":[[34,9.72],[48,2.13]],"id":41419620},{"atb":[[40,0]],"id":41419587},{"atb":[[38,0]],"id":41419599},{"atb":[[5.7,0]],"id":41419595},{"atb":[[12,0]],"id":41419608},{"atb":[[10,0],[13,8.33]],"id":41419612},{"atb":[[13.5,8]],"id":41419592},{"atb":[[34,0]],"id":41435526},{"atb":[[5.3,23.26],[4.4,8.9]],"id":41419621},{"atb":[[9.6,8.9],[14,7.69]],"id":41419600},{"atb":[[3.55,8.9],[4.2,31.25]],"id":41419596}],"con":true,"img":false}]}
{"op":"mcm","clk":"5348194106","pt":1646215267173,"mc":[{"id":"1.195453723","rc":[{"atb":[[20,5.26],[15.5,0]],"id":41419605},{"atb":[[38,8.08]],"id":41419617},{"atb":[[60,2]],"id":41419613},{"atb":[[4.8,26.32],[3.95,0]],"id":41419593},{"atb":[[34,0]],"id":41419655},{"atb":[[8,0],[10,11.11]],"id":41419622},{"atb":[[40,0],[60,2]],"id":41419589},{"atb":[[40,0],[60,2]],"id":41435527},{"atb":[[38,2.7]],"id":41419601},{"atb":[[9,12.5],[6.8,0]],"id":41419626},{"atb":[[4.5,76.85]],"id":41419635},{"atb":[[36,0],[55,2]],"id":41419656},{"atb":[[60,2]],"id":41435528},{"atb":[[38,0],[55,2]],"id":41419619},{"atb":[[50,2]],"id":41419586},{"atb":[[5,25]],"id":41419594},{"atb":[[42,0]],"id":28546950},{"atb":[[9.2,0],[13,8.33]],"id":41419636},{"atb":[[40,0]],"id":41419657},{"atb":[[23,4.55]],"id":41419624},{"atb":[[38,0],[55,2]],"id":41435525},{"atb":[[55,2]],"id":41419587},{"atb":[[50,2.04]],"id":41419599},{"atb":[[8,14.29]],"id":41419595},{"atb":[[17.5,6.06]],"id":41419608},{"atb":[[13.5,8],[9.4,0]],"id":41419637},{"atb":[[9.8,0]],"id":41419592},{"atb":[[48,2.13]],"id":41435526},{"atb":[[40,0],[60,2]],"id":41419588},{"atb":[[40,0],[60,2]],"id":41419658}],"con":true,"img":false}]}
{"op":"mcm","clk":"5348194178","pt":1646215268261,"mc":[{"id":"1.195453723","rc":[{"atb":[[17.5,0],[20,5.26]],"id":41419603}],"con":true,"img":false}]}
{"op":"mcm","clk":"5348194582","pt":1646215273412,"mc":[{"id":"1.195453723","rc":[{"atb":[[5.8,2.72]],"id":41419596}],"con":true,"img":false}]}
{"op":"mcm","clk":"5348194648","pt":1646215274196,"mc":[{"id":"1.195453723","rc":[{"atb":[[5.7,20.34]],"id":41419596}],"con":true,"img":false}]}
{"op":"mcm","clk":"5348194725","pt":1646215275188,"mc":[{"id":"1.195453723","rc":[{"atl":[[1000,0.15]],"id":41419619}],"con":true,"img":false}]}
