{"op":"mcm","clk":"5317728517","pt":1646251399899,"mc":[{"id":"1.195532879","marketDefinition":{"bspMarket":true,"turnInPlayEnabled":false,"persistenceEnabled":false,"marketBaseRate":5.0,"eventId":"31275720","eventTypeId":"4339","numberOfWinners":2,"bettingType":"ODDS","marketType":"PLACE","marketTime":"2022-03-03T18:02:00.000Z","suspendTime":"2022-03-03T18:02:00.000Z","bspReconciled":false,"complete":true,"inPlay":false,"crossMatching":false,"runnersVoidable":false,"numberOfActiveRunners":6,"betDelay":0,"status":"OPEN","runners":[{"status":"ACTIVE","sortPriority":1,"id":39632625,"name":"1. Knockane Harbour"},{"status":"ACTIVE","sortPriority":2,"id":38251452,"name":"2. Speak Out Aida"},{"status":"ACTIVE","sortPriority":3,"id":28753299,"name":"3. Huwearsdtrousers"},{"status":"ACTIVE","sortPriority":4,"id":40452329,"name":"4. Im Alright Botch"},{"status":"ACTIVE","sortPriority":5,"id":41555107,"name":"5. Theresas Pet"},{"status":"ACTIVE","sortPriority":6,"id":39059999,"name":"6. Conors Pickens"}],"regulators":["MR_INT"],"venue":"Romford","countryCode":"GB","discountAllowed":false,"timezone":"Europe/London","openDate":"2022-03-03T13:57:00.000Z","version":4384107328,"name":"To Be Placed","eventName":"Romford 3rd Mar"},"rc":[],"con":true,"img":false}]}
{"op":"mcm","clk":"5317728869","pt":1646251401774,"mc":[{"id":"1.195532879","marketDefinition":{"bspMarket":true,"turnInPlayEnabled":false,"persistenceEnabled":false,"marketBaseRate":5.0,"eventId":"31275720","eventTypeId":"4339","numberOfWinners":2,"bettingType":"ODDS","marketType":"PLACE","marketTime":"2022-03-03T18:02:00.000Z","suspendTime":"2022-03-03T18:02:00.000Z","bspReconciled":false,"complete":true,"inPlay":false,"crossMatching":false,"runnersVoidable":false,"numberOfActiveRunners":6,"betDelay":0,"status":"OPEN","runners":[{"status":"ACTIVE","sortPriority":1,"id":39632625,"name":"1. Knockane Harbour"},{"status":"ACTIVE","sortPriority":2,"id":38251452,"name":"2. Speak Out Aida"},{"status":"ACTIVE","sortPriority":3,"id":28753299,"name":"3. Huwearsdtrousers"},{"status":"ACTIVE","sortPriority":4,"id":40452329,"name":"4. Im Alright Botch"},{"status":"ACTIVE","sortPriority":5,"id":41555107,"name":"5. Theresas Pet"},{"status":"ACTIVE","sortPriority":6,"id":39059999,"name":"6. Conors Pickens"}],"regulators":["MR_INT"],"venue":"Romford","countryCode":"GB","discountAllowed":true,"timezone":"Europe/London","openDate":"2022-03-03T13:57:00.000Z","version":4384107328,"name":"To Be Placed","eventName":"Romford 3rd Mar"},"rc":[],"con":true,"img":false}]}
{"op":"mcm","clk":"5322076426","pt":1646316128226,"mc":[{"id":"1.195532879","rc":[{"atb":[[1.01,102.04]],"id":39632625},{"spn":"Infinity","spf":"NaN","id":39632625}],"con":true,"img":false}]}
{"op":"mcm","clk":"5322076490","pt":1646316128351,"mc":[{"id":"1.195532879","rc":[{"atb":[[1.01,102.04]],"id":38251452}],"con":true,"img":false}]}
{"op":"mcm","clk":"5322076500","pt":1646316128417,"mc":[{"id":"1.195532879","rc":[{"atb":[[1.01,102.04]],"id":28753299}],"con":true,"img":false}]}
{"op":"mcm","clk":"5322076508","pt":1646316128528,"mc":[{"id":"1.195532879","rc":[{"atb":[[1.01,102.04]],"id":40452329}],"con":true,"img":false}]}
{"op":"mcm","clk":"5322076515","pt":1646316128615,"mc":[{"id":"1.195532879","rc":[{"atb":[[1.01,102.04]],"id":41555107}],"con":true,"img":false}]}
{"op":"mcm","clk":"5322076525","pt":1646316128719,"mc":[{"id":"1.195532879","rc":[{"atb":[[1.01,102.04]],"id":39059999}],"con":true,"img":false}]}
{"op":"mcm","clk":"5322254852","pt":1646318127565,"mc":[{"id":"1.195532879","rc":[{"atl":[[1000,5]],"id":41555107},{"spn":500.5,"spf":"NaN","id":41555107},{"atl":[[1000,5]],"id":40452329},{"spn":500.5,"spf":"NaN","id":40452329},{"atl":[[1000,5]],"id":38251452},{"spn":500.5,"spf":"NaN","id":38251452},{"atl":[[1000,5]],"id":39632625},{"spn":500.5,"spf":"NaN","id":39632625},{"atl":[[1000,5]],"id":39059999},{"spn":500.5,"spf":"NaN","id":39059999},{"atl":[[1000,5]],"id":28753299},{"spn":500.5,"spf":"NaN","id":28753299}],"con":true,"img":false}]}
{"op":"mcm","clk":"5322254895","pt":1646318128036,"mc":[{"id":"1.195532879","rc":[{"atb":[[1.01,4802.04]],"id":41555107},{"atb":[[1.01,4802.04]],"id":40452329},{"atb":[[1.01,4802.04]],"id":38251452},{"atb":[[1.01,4802.04]],"id":39632625},{"atb":[[1.01,4802.04]],"id":39059999},{"atb":[[1.01,4802.04]],"id":28753299}],"con":true,"img":false}]}
{"op":"mcm","clk":"5322538954","pt":1646321484959,"mc":[{"id":"1.195532879","rc":[{"spl":[[1.01,8.24]],"id":39632625},{"spn":1.01,"spf":1.0,"id":39632625}],"con":true,"img":false}]}
{"op":"mcm","clk":"5322622396","pt":1646322479181,"mc":[{"id":"1.195532879","rc":[{"spl":[[1.01,1]],"id":40452329},{"spn":1.01,"spf":1.0,"id":40452329}],"con":true,"img":false}]}
{"op":"mcm","clk":"5322799442","pt":1646324202566,"mc":[{"id":"1.195532879","marketDefinition":{"bspMarket":true,"turnInPlayEnabled":false,"persistenceEnabled":false,"marketBaseRate":5.0,"eventId":"31275720","eventTypeId":"4339","numberOfWinners":2,"bettingType":"ODDS","marketType":"PLACE","marketTime":"2022-03-03T18:02:00.000Z","suspendTime":"2022-03-03T18:02:00.000Z","bspReconciled":false,"complete":true,"inPlay":false,"crossMatching":false,"runnersVoidable":false,"numberOfActiveRunners":6,"betDelay":0,"status":"OPEN","runners":[{"status":"ACTIVE","sortPriority":1,"id":39632625,"name":"1. Knockane Harbour"},{"status":"ACTIVE","sortPriority":2,"id":38251452,"name":"2. Speak Out Aida"},{"status":"ACTIVE","sortPriority":3,"id":28753299,"name":"3. Huwearsdtrousers"},{"status":"ACTIVE","sortPriority":4,"id":40452329,"name":"4. Im Alright Botch"},{"status":"ACTIVE","sortPriority":5,"id":41555107,"name":"5. Theresas Pet"},{"status":"ACTIVE","sortPriority":6,"id":39059999,"name":"6. Conors Pickens"}],"regulators":["MR_INT"],"venue":"Romford","countryCode":"GB","discountAllowed":true,"timezone":"Europe/London","openDate":"2022-03-03T13:57:00.000Z","version":4384107328,"name":"To Be Placed","eventName":"Romford 3rd Mar"},"rc":[{"atb":[[1.01,4802.04]],"id":41555107},{"atl":[[1000,5]],"id":41555107},{"spn":500.5,"spf":"NaN","id":41555107},{"atb":[[1.01,4802.04]],"id":40452329},{"spl":[[1.01,1]],"id":40452329},{"atl":[[1000,5]],"id":40452329},{"spn":1.01,"spf":1.0,"id":40452329},{"atb":[[1.01,4802.04]],"id":38251452},{"atl":[[1000,5]],"id":38251452},{"spn":500.5,"spf":"NaN","id":38251452},{"atb":[[1.01,4802.04]],"id":39632625},{"spl":[[1.01,8.22]],"id":39632625},{"atl":[[1000,5]],"id":39632625},{"spn":1.01,"spf":1.0,"id":39632625},{"atb":[[1.01,4802.04]],"id":39059999},{"atl":[[1000,5]],"id":39059999},{"spn":500.5,"spf":"NaN","id":39059999},{"atb":[[1.01,4802.04]],"id":28753299},{"atl":[[1000,5]],"id":28753299},{"spn":500.5,"spf":"NaN","id":28753299}],"con":true,"img":true}]}
{"op":"mcm","clk":"5323146328","pt":1646327976830,"mc":[{"id":"1.195532879","rc":[{"atl":[[46,2.74]],"id":41555107},{"spn":23.5,"spf":"NaN","id":41555107},{"atl":[[46,2.74]],"id":40452329},{"atl":[[46,2.74]],"id":38251452},{"spn":23.5,"spf":"NaN","id":38251452},{"spl":[[1.01,8.22]],"id":39632625},{"atl":[[46,2.74]],"id":39632625},{"atl":[[46,2.74]],"id":39059999},{"spn":23.5,"spf":"NaN","id":39059999},{"atl":[[46,2.74]],"id":28753299},{"spn":23.5,"spf":"NaN","id":28753299}],"con":true,"img":false}]}
{"op":"mcm","clk":"5323217855","pt":1646328723390,"mc":[{"id":"1.195532879","rc":[{"atb":[[1.01,5052.04]],"id":41555107},{"atl":[[70,2.17],[80,3.16],[50,1],[60,1.69]],"id":41555107},{"atb":[[1.01,5052.04]],"id":40452329},{"atl":[[70,2.17],[80,3.16],[50,1],[60,1.69]],"id":40452329},{"atb":[[1.01,5052.04]],"id":38251452},{"atl":[[70,2.17],[80,3.16],[50,1],[60,1.69]],"id":38251452},{"atb":[[1.01,5052.04]],"id":39632625},{"atl":[[70,2.17],[80,3.16],[50,1],[60,1.69]],"id":39632625},{"atb":[[1.01,5052.04]],"id":39059999},{"atl":[[70,2.17],[80,3.16],[50,1],[60,1.69]],"id":39059999},{"atb":[[1.01,5052.04]],"id":28753299},{"atl":[[70,2.17],[80,3.16],[50,1],[60,1.69]],"id":28753299}],"con":true,"img":false}]}
{"op":"mcm","clk":"5323221119","pt":1646328750766,"mc":[{"id":"1.195532879","marketDefinition":{"bspMarket":true,"turnInPlayEnabled":false,"persistenceEnabled":false,"marketBaseRate":5.0,"eventId":"31275720","eventTypeId":"4339","numberOfWinners":2,"bettingType":"ODDS","marketType":"PLACE","marketTime":"2022-03-03T18:02:00.000Z","suspendTime":"2022-03-03T18:02:00.000Z","bspReconciled":false,"complete":true,"inPlay":false,"crossMatching":true,"runnersVoidable":false,"numberOfActiveRunners":6,"betDelay":0,"status":"OPEN","runners":[{"status":"ACTIVE","sortPriority":1,"id":39632625,"name":"1. Knockane Harbour"},{"status":"ACTIVE","sortPriority":2,"id":38251452,"name":"2. Speak Out Aida"},{"status":"ACTIVE","sortPriority":3,"id":28753299,"name":"3. Huwearsdtrousers"},{"status":"ACTIVE","sortPriority":4,"id":40452329,"name":"4. Im Alright Botch"},{"status":"ACTIVE","sortPriority":5,"id":41555107,"name":"5. Theresas Pet"},{"status":"ACTIVE","sortPriority":6,"id":39059999,"name":"6. Conors Pickens"}],"regulators":["MR_INT"],"venue":"Romford","countryCode":"GB","discountAllowed":true,"timezone":"Europe/London","openDate":"2022-03-03T13:57:00.000Z","version":4384107328,"name":"To Be Placed","eventName":"Romford 3rd Mar"},"rc":[],"con":true,"img":false}]}
{"op":"mcm","clk":"5323333981","pt":1646329687059,"mc":[{"id":"1.195532879","rc":[{"atb":[[1.01,5054.04]],"id":39632625}],"con":true,"img":false}]}
{"op":"mcm","clk":"5323333993","pt":1646329687163,"mc":[{"id":"1.195532879","rc":[{"atb":[[1.53,188.68]],"id":39632625},{"atl":[[9.8,2]],"id":39632625}],"con":true,"img":false}]}
{"op":"mcm","clk":"5323334005","pt":1646329687269,"mc":[{"id":"1.195532879","rc":[{"atb":[[1.01,5056.03]],"id":39632625}],"con":true,"img":false}]}
{"op":"mcm","clk":"5323334014","pt":1646329687373,"mc":[{"id":"1.195532879","rc":[{"atb":[[1.59,169.49]],"id":41555107},{"atl":[[11,2]],"id":41555107},{"atb":[[1.3,333.33]],"id":40452329},{"atl":[[8,2]],"id":40452329},{"atb":[[1.56,178.57]],"id":38251452},{"atl":[[10.5,2]],"id":38251452},{"atb":[[1.51,78.43]],"id":39632625},{"atl":[[10.5,4.21],[50,0]],"id":39632625},{"atb":[[2.12,89.29]],"id":39059999},{"atl":[[46,4.74]],"id":39059999},{"atb":[[1.72,138.89]],"id":28753299},{"atl":[[17.5,2]],"id":28753299}],"con":true,"img":false}]}
{"op":"mcm","clk":"5323334032","pt":1646329687526,"mc":[{"id":"1.195532879","rc":[{"atb":[[1.28,142.86]],"id":40452329},{"atl":[[50,0],[8.4,5.41]],"id":40452329},{"atb":[[1.01,5054.04]],"id":39632625},{"atb":[[2.08,37.04]],"id":39059999},{"atb":[[1.7,57.14]],"id":28753299},{"atl":[[18.5,2.29],[50,0]],"id":28753299}],"con":true,"img":false}]}
{"op":"mcm","clk":"5323334045","pt":1646329687634,"mc":[{"id":"1.195532879","rc":[{"atb":[[1.57,70.18]],"id":41555107},{"atl":[[12,3.64],[50,0]],"id":41555107},{"atb":[[1.54,74.07]],"id":38251452},{"atl":[[11.5,3.81],[50,0]],"id":38251452},{"atb":[[1.02,1.99]],"id":39632625}],"con":true,"img":false}]}
{"op":"mcm","clk":"5323334071","pt":1646329687836,"mc":[{"id":"1.195532879","rc":[{"atb":[[1.01,5054.04]],"id":38251452}],"con":true,"img":false}]}
{"op":"mcm","clk":"5323334091","pt":1646329688044,"mc":[{"id":"1.195532879","rc":[{"atb":[[1.01,5056.03]],"id":38251452}],"con":true,"img":false}]}
{"op":"mcm","clk":"5323334108","pt":1646329688247,"mc":[{"id":"1.195532879","rc":[{"atb":[[1.01,5054.04]],"id":38251452}],"con":true,"img":false}]}
{"op":"mcm","clk":"5323334117","pt":1646329688350,"mc":[{"id":"1.195532879","rc":[{"atb":[[1.02,1.99]],"id":38251452}],"con":true,"img":false}]}
{"op":"mcm","clk":"5323334149","pt":1646329688663,"mc":[{"id":"1.195532879","rc":[{"atb":[[1.01,5054.04]],"id":28753299}],"con":true,"img":false}]}
{"op":"mcm","clk":"5323334179","pt":1646329688974,"mc":[{"id":"1.195532879","rc":[{"atb":[[1.01,5056.03]],"id":28753299}],"con":true,"img":false}]}
{"op":"mcm","clk":"5323334216","pt":1646329689337,"mc":[{"id":"1.195532879","rc":[{"atb":[[1.01,5054.04]],"id":28753299}],"con":true,"img":false}]}
{"op":"mcm","clk":"5323334227","pt":1646329689448,"mc":[{"id":"1.195532879","rc":[{"atb":[[1.02,1.99]],"id":28753299}],"con":true,"img":false}]}
{"op":"mcm","clk":"5323334256","pt":1646329689754,"mc":[{"id":"1.195532879","rc":[{"atb":[[1.01,5054.04]],"id":40452329}],"con":true,"img":false}]}
{"op":"mcm","clk":"5323334276","pt":1646329689961,"mc":[{"id":"1.195532879","rc":[{"atb":[[1.01,5056.03]],"id":40452329}],"con":true,"img":false}]}
{"op":"mcm","clk":"5323334296","pt":1646329690167,"mc":[{"id":"1.195532879","rc":[{"atb":[[1.01,5054.04]],"id":40452329}],"con":true,"img":false}]}
{"op":"mcm","clk":"5323334303","pt":1646329690271,"mc":[{"id":"1.195532879","rc":[{"atb":[[1.02,1.99]],"id":40452329}],"con":true,"img":false}]}
{"op":"mcm","clk":"5323334325","pt":1646329690429,"mc":[{"id":"1.195532879","rc":[{"atb":[[1.01,5054.04]],"id":41555107}],"con":true,"img":false}]}
{"op":"mcm","clk":"5323334355","pt":1646329690739,"mc":[{"id":"1.195532879","rc":[{"atb":[[1.01,5056.03]],"id":41555107}],"con":true,"img":false}]}
{"op":"mcm","clk":"5323334376","pt":1646329690950,"mc":[{"id":"1.195532879","rc":[{"atb":[[1.01,5054.04]],"id":41555107}],"con":true,"img":false}]}
{"op":"mcm","clk":"5323334387","pt":1646329691052,"mc":[{"id":"1.195532879","rc":[{"atb":[[1.02,1.99]],"id":41555107}],"con":true,"img":false}]}
{"op":"mcm","clk":"5323334424","pt":1646329691469,"mc":[{"id":"1.195532879","rc":[{"atb":[[1.01,5054.04]],"id":39059999}],"con":true,"img":false}]}
{"op":"mcm","clk":"5323334447","pt":1646329691675,"mc":[{"id":"1.195532879","rc":[{"atb":[[1.01,5056.03]],"id":39059999}],"con":true,"img":false}]}
{"op":"mcm","clk":"5323334469","pt":1646329691882,"mc":[{"id":"1.195532879","rc":[{"atb":[[1.01,5054.04]],"id":39059999}],"con":true,"img":false}]}
{"op":"mcm","clk":"5323334477","pt":1646329691934,"mc":[{"id":"1.195532879","rc":[{"atb":[[1.02,1.99]],"id":39059999}],"con":true,"img":false}]}
{"op":"mcm","clk":"5323334581","pt":1646329693030,"mc":[{"id":"1.195532879","rc":[{"atb":[[1.02,1201.99]],"id":40452329},{"atb":[[1.02,1109.12]],"id":38251452},{"atb":[[1.02,1115.21]],"id":39632625}],"con":true,"img":false}]}
{"op":"mcm","clk":"5323334613","pt":1646329693342,"mc":[{"id":"1.195532879","rc":[{"atb":[[1.02,1113.22]],"id":39632625}],"con":true,"img":false}]}
{"op":"mcm","clk":"5323334624","pt":1646329693444,"mc":[{"id":"1.195532879","rc":[{"atb":[[1.54,1.99]],"id":39632625}],"con":true,"img":false}]}
{"op":"mcm","clk":"5323334668","pt":1646329693860,"mc":[{"id":"1.195532879","rc":[{"atb":[[1.02,1107.13]],"id":38251452}],"con":true,"img":false}]}
{"op":"mcm","clk":"5323334678","pt":1646329693969,"mc":[{"id":"1.195532879","rc":[{"atb":[[1.57,1.99]],"id":38251452}],"con":true,"img":false}]}
{"op":"mcm","clk":"5323334697","pt":1646329694175,"mc":[{"id":"1.195532879","rc":[{"atb":[[1.02,0]],"id":28753299}],"con":true,"img":false}]}
{"op":"mcm","clk":"5323334707","pt":1646329694278,"mc":[{"id":"1.195532879","rc":[{"atb":[[1.73,1.99]],"id":28753299}],"con":true,"img":false}]}
{"op":"mcm","clk":"5323334737","pt":1646329694539,"mc":[{"id":"1.195532879","rc":[{"atb":[[1.02,1200]],"id":40452329}],"con":true,"img":false}]}
{"op":"mcm","clk":"5323334748","pt":1646329694644,"mc":[{"id":"1.195532879","rc":[{"atb":[[1.31,1.99]],"id":40452329}],"con":true,"img":false}]}
{"op":"mcm","clk":"5323334771","pt":1646329694953,"mc":[{"id":"1.195532879","rc":[{"atb":[[1.02,0]],"id":41555107}],"con":true,"img":false}]}
{"op":"mcm","clk":"5323334780","pt":1646329695058,"mc":[{"id":"1.195532879","rc":[{"atb":[[1.6,1.99]],"id":41555107}],"con":true,"img":false}]}
{"op":"mcm","clk":"5323334798","pt":1646329695266,"mc":[{"id":"1.195532879","rc":[{"atb":[[1.02,0]],"id":39059999}],"con":true,"img":false}]}
{"op":"mcm","clk":"5323334809","pt":1646329695370,"mc":[{"id":"1.195532879","rc":[{"atb":[[2.14,1.99]],"id":39059999}],"con":true,"img":false}]}
{"op":"mcm","clk":"5323334855","pt":1646329695787,"mc":[{"id":"1.195532879","rc":[{"atb":[[1.58,68.97]],"id":41555107},{"atb":[[1.29,137.93]],"id":40452329},{"atb":[[1.55,72.73]],"id":38251452},{"atb":[[1.52,76.92]],"id":39632625},{"atb":[[2.1,36.36]],"id":39059999},{"atb":[[1.71,56.34]],"id":28753299}],"con":true,"img":false}]}
{"op":"mcm","clk":"5323334886","pt":1646329696051,"mc":[{"id":"1.195532879","rc":[{"atb":[[1.62,2.15]],"id":41555107},{"atb":[[1.33,2.15]],"id":40452329},{"atb":[[1.59,2.15]],"id":38251452},{"atb":[[1.56,2.15]],"id":39632625},{"atb":[[2.18,2.15],[2.16,1.65]],"id":39059999},{"atb":[[1.75,2.15]],"id":28753299}],"con":true,"img":false}]}
{"op":"mcm","clk":"5323334928","pt":1646329696461,"mc":[{"id":"1.195532879","rc":[{"atb":[[1.54,0]],"id":39632625}],"con":true,"img":false}]}
{"op":"mcm","clk":"5323334941","pt":1646329696566,"mc":[{"id":"1.195532879","rc":[{"atb":[[1.57,1.99]],"id":39632625}],"con":true,"img":false}]}
{"op":"mcm","clk":"5323334954","pt":1646329696666,"mc":[{"id":"1.195532879","rc":[{"atb":[[1.56,79.07],[1.53,0]],"id":39632625}],"con":true,"img":false}]}
{"op":"mcm","clk":"5323334969","pt":1646329696874,"mc":[{"id":"1.195532879","rc":[{"atb":[[1.59,0],[1.62,4.31]],"id":41555107},{"atb":[[1.33,4.31],[1.3,0]],"id":40452329},{"atb":[[1.56,0],[1.59,4.31],[1.57,0]],"id":38251452},{"atb":[[2.12,0],[2.18,4.15]],"id":39059999},{"atb":[[1.72,0],[1.75,4.31]],"id":28753299}],"con":true,"img":false}]}
{"op":"mcm","clk":"5323334980","pt":1646329696977,"mc":[{"id":"1.195532879","rc":[{"atb":[[1.62,2.15]],"id":41555107},{"atb":[[1.6,1.99],[1.57,72.73]],"id":38251452},{"atb":[[1.73,58.33]],"id":28753299}],"con":true,"img":false}]}
{"op":"mcm","clk":"5323334990","pt":1646329697083,"mc":[{"id":"1.195532879","rc":[{"atb":[[1.6,70.96]],"id":41555107},{"atb":[[1.33,2.15],[1.31,139.92]],"id":40452329},{"atb":[[1.59,2.15]],"id":38251452},{"atb":[[2.18,2.15],[2.16,5.97]],"id":39059999},{"atb":[[1.75,2.15]],"id":28753299}],"con":true,"img":false}]}
{"op":"mcm","clk":"5323335000","pt":1646329697137,"mc":[{"id":"1.195532879","rc":[{"atb":[[1.6,6.31],[1.57,0]],"id":38251452},{"atb":[[1.73,56.34]],"id":28753299}],"con":true,"img":false}]}
{"op":"mcm","clk":"5323335010","pt":1646329697242,"mc":[{"id":"1.195532879","rc":[{"atb":[[1.6,1.99],[1.62,4.31]],"id":41555107},{"atb":[[1.33,6.47],[1.31,1.99]],"id":40452329},{"atb":[[1.73,0],[1.75,58.49],[1.76,1.99]],"id":28753299}],"con":true,"img":false}]}
{"op":"mcm","clk":"5323335038","pt":1646329697552,"mc":[{"id":"1.195532879","rc":[{"atb":[[1.31,0]],"id":40452329}],"con":true,"img":false}]}
{"op":"mcm","clk":"5323335046","pt":1646329697655,"mc":[{"id":"1.195532879","rc":[{"atb":[[1.34,1.99]],"id":40452329}],"con":true,"img":false}]}
{"op":"mcm","clk":"5323335063","pt":1646329697864,"mc":[{"id":"1.195532879","rc":[{"atb":[[1.6,0]],"id":41555107}],"con":true,"img":false}]}
{"op":"mcm","clk":"5323335072","pt":1646329697966,"mc":[{"id":"1.195532879","rc":[{"atb":[[1.63,1.99]],"id":41555107}],"con":true,"img":false}]}
{"op":"mcm","clk":"5323335098","pt":1646329698277,"mc":[{"id":"1.195532879","rc":[{"atb":[[2.14,0]],"id":39059999}],"con":true,"img":false}]}
{"op":"mcm","clk":"5323335107","pt":1646329698378,"mc":[{"id":"1.195532879","rc":[{"atb":[[2.2,1.99]],"id":39059999}],"con":true,"img":false}]}
{"op":"mcm","clk":"5323335129","pt":1646329698536,"mc":[{"id":"1.195532879","rc":[{"atb":[[2.2,4.15],[2.16,1.65]],"id":39059999}],"con":true,"img":false}]}
{"op":"mcm","clk":"5323335171","pt":1646329699049,"mc":[{"id":"1.195532879","rc":[{"atb":[[1.61,65.57]],"id":41555107},{"atb":[[1.32,125]],"id":40452329},{"atb":[[1.58,68.97]],"id":38251452},{"atb":[[1.55,72.73]],"id":39632625},{"atb":[[2.16,36.13]],"id":39059999},{"atb":[[1.74,54.05]],"id":28753299}],"con":true,"img":false}]}
{"op":"mcm","clk":"5323335244","pt":1646329699876,"mc":[{"id":"1.195532879","rc":[{"atb":[[1.02,0]],"id":40452329},{"atb":[[1.02,0]],"id":38251452},{"atb":[[1.02,0]],"id":39632625}],"con":true,"img":false}]}
{"op":"mcm","clk":"5323335827","pt":1646329705476,"mc":[{"id":"1.195532879","rc":[{"atb":[[1.3,9.3]],"id":40452329},{"atb":[[1.56,7.57]],"id":38251452},{"atb":[[1.53,69.03]],"id":39632625}],"con":true,"img":false}]}
{"op":"mcm","clk":"5323335972","pt":1646329707077,"mc":[{"id":"1.195532879","rc":[{"atb":[[2.16,34.48]],"id":39059999}],"con":true,"img":false}]}
{"op":"mcm","clk":"5323335991","pt":1646329707281,"mc":[{"id":"1.195532879","rc":[{"atb":[[2.22,1.65]],"id":39059999}],"con":true,"img":false}]}
{"op":"mcm","clk":"5323336018","pt":1646329707593,"mc":[{"id":"1.195532879","rc":[{"atb":[[1.67,4.32],[1.62,2.15]],"id":41555107},{"atl":[[9.2,2.74],[11,0]],"id":41555107},{"atb":[[1.33,2.15],[1.42,6.48]],"id":40452329},{"atl":[[8,0],[7.6,2.74]],"id":40452329},{"atb":[[1.65,6.31]],"id":38251452},{"atl":[[10.5,0],[9.8,2.74]],"id":38251452},{"atb":[[1.56,2.15],[1.64,72.73]],"id":39632625},{"atl":[[9.4,2.74]],"id":39632625},{"atb":[[2.32,2.16],[2.18,36.05],[2.2,1.99],[2.16,0]],"id":39059999},{"atl":[[38,2],[46,2.74]],"id":39059999},{"atb":[[1.83,54.05],[1.75,2.15]],"id":28753299},{"atl":[[16.5,2.29],[17.5,0]],"id":28753299}],"con":true,"img":false}]}
{"op":"mcm","clk":"5323336032","pt":1646329707647,"mc":[{"id":"1.195532879","rc":[{"atb":[[1.6,1.99]],"id":38251452},{"atl":[[9.8,0]],"id":39632625}],"con":true,"img":false}]}
{"op":"mcm","clk":"5323336164","pt":1646329708999,"mc":[{"id":"1.195532879","rc":[{"atb":[[1.57,0],[1.55,0],[1.62,64.52]],"id":39632625},{"atl":[[10.5,0],[9.8,4.55]],"id":39632625}],"con":true,"img":false}]}
{"op":"mcm","clk":"5323336174","pt":1646329709047,"mc":[{"id":"1.195532879","rc":[{"atb":[[1.65,61.54],[1.61,0]],"id":41555107},{"atl":[[9.6,4.65],[12,0]],"id":41555107},{"atb":[[1.4,100],[1.32,0]],"id":40452329},{"atl":[[8,5.71],[8.4,0]],"id":40452329},{"atb":[[1.63,63.49],[1.58,0]],"id":38251452},{"atl":[[10.5,4.21],[11.5,0]],"id":38251452},{"atb":[[1.65,1.99]],"id":39632625},{"atb":[[1.81,49.38],[1.74,0]],"id":28753299},{"atl":[[17.5,2.42],[18.5,0]],"id":28753299}],"con":true,"img":false}]}
{"op":"mcm","clk":"5323336198","pt":1646329709356,"mc":[{"id":"1.195532879","rc":[{"atb":[[1.6,0]],"id":38251452}],"con":true,"img":false}]}
{"op":"mcm","clk":"5323336207","pt":1646329709513,"mc":[{"id":"1.195532879","rc":[{"atb":[[1.66,1.99]],"id":38251452}],"con":true,"img":false}]}
{"op":"mcm","clk":"5323336230","pt":1646329709774,"mc":[{"id":"1.195532879","rc":[{"atb":[[1.62,0],[1.68,2.15]],"id":41555107}],"con":true,"img":false}]}
{"op":"mcm","clk":"5323336237","pt":1646329709877,"mc":[{"id":"1.195532879","rc":[{"atb":[[1.76,0]],"id":28753299}],"con":true,"img":false}]}
{"op":"mcm","clk":"5323336243","pt":1646329709983,"mc":[{"id":"1.195532879","rc":[{"atb":[[1.84,1.99]],"id":28753299}],"con":true,"img":false}]}
{"op":"mcm","clk":"5323336275","pt":1646329710249,"mc":[{"id":"1.195532879","rc":[{"atb":[[1.34,0]],"id":40452329}],"con":true,"img":false}]}
{"op":"mcm","clk":"5323336284","pt":1646329710347,"mc":[{"id":"1.195532879","rc":[{"atb":[[1.43,1.99]],"id":40452329}],"con":true,"img":false}]}
{"op":"mcm","clk":"5323336311","pt":1646329710655,"mc":[{"id":"1.195532879","rc":[{"atb":[[1.63,0]],"id":41555107}],"con":true,"img":false}]}
{"op":"mcm","clk":"5323336323","pt":1646329710760,"mc":[{"id":"1.195532879","rc":[{"atb":[[1.68,4.14]],"id":41555107}],"con":true,"img":false}]}
{"op":"mcm","clk":"5323336340","pt":1646329710965,"mc":[{"id":"1.195532879","rc":[{"atb":[[2.2,0]],"id":39059999}],"con":true,"img":false}]}
{"op":"mcm","clk":"5323336355","pt":1646329711068,"mc":[{"id":"1.195532879","rc":[{"atb":[[2.34,1.99]],"id":39059999}],"con":true,"img":false}]}
{"op":"mcm","clk":"5323336521","pt":1646329712890,"mc":[{"id":"1.195532879","rc":[{"atb":[[1.3,0]],"id":40452329},{"atb":[[1.56,0]],"id":38251452},{"atb":[[1.53,0]],"id":39632625}],"con":true,"img":false}]}
{"op":"mcm","clk":"5323336590","pt":1646329713718,"mc":[{"id":"1.195532879","rc":[{"atb":[[1.65,0],[1.66,60.61]],"id":41555107},{"atb":[[1.4,0],[1.41,97.56]],"id":40452329},{"atb":[[1.64,62.5],[1.63,0]],"id":38251452},{"atb":[[1.63,63.49],[1.62,0]],"id":39632625},{"atb":[[2.3,30.77],[2.18,2.15]],"id":39059999},{"atl":[[42,1],[50,0]],"id":39059999},{"atb":[[1.82,48.78],[1.81,0]],"id":28753299}],"con":true,"img":false}]}
{"op":"mcm","clk":"5323336861","pt":1646329716769,"mc":[{"id":"1.195532879","rc":[{"atb":[[1.55,6.48]],"id":40452329},{"atb":[[1.7,63.49]],"id":39632625},{"atb":[[1.83,0],[1.93,48.78]],"id":28753299},{"atl":[[16.5,0]],"id":28753299}],"con":true,"img":false}]}
{"op":"mcm","clk":"5323336869","pt":1646329716874,"mc":[{"id":"1.195532879","rc":[{"atb":[[1.67,0],[1.69,4.32]],"id":41555107},{"atl":[[9.2,0],[8.8,2.74]],"id":41555107},{"atb":[[1.42,0]],"id":40452329},{"atl":[[7.2,2.74],[7.6,0]],"id":40452329},{"atb":[[1.72,6.31],[1.65,0]],"id":38251452},{"atl":[[9.6,2.74],[9.8,0]],"id":38251452},{"atb":[[1.64,0]],"id":39632625},{"atl":[[9,2.74],[9.4,0]],"id":39632625},{"atb":[[2.32,0],[2.42,2.16]],"id":39059999},{"atl":[[36,2],[38,0]],"id":39059999},{"atl":[[15.5,2.42]],"id":28753299}],"con":true,"img":false}]}
{"op":"mcm","clk":"5323336895","pt":1646329717183,"mc":[{"id":"1.195532879","rc":[{"atb":[[1.65,0]],"id":39632625}],"con":true,"img":false}]}
{"op":"mcm","clk":"5323336908","pt":1646329717288,"mc":[{"id":"1.195532879","rc":[{"atb":[[1.71,1.99]],"id":39632625}],"con":true,"img":false}]}
{"op":"mcm","clk":"5323336926","pt":1646329717496,"mc":[{"id":"1.195532879","rc":[{"atb":[[1.67,59.7],[1.66,0]],"id":41555107},{"atl":[[9.6,0],[9.2,4.88]],"id":41555107},{"atb":[[1.41,0],[1.53,75.47]],"id":40452329},{"atl":[[8,0],[7.6,6.06]],"id":40452329},{"atb":[[1.64,0],[1.7,57.14],[1.66,0]],"id":38251452},{"atl":[[10,4.44],[10.5,0]],"id":38251452},{"atb":[[1.63,0],[1.69,57.97]],"id":39632625},{"atl":[[9.8,0],[9.4,4.76]],"id":39632625},{"atb":[[2.3,0],[2.38,28.99]],"id":39059999},{"atl":[[40,1.03],[42,0]],"id":39059999},{"atb":[[1.82,0],[1.91,43.96]],"id":28753299},{"atl":[[16.5,2.58],[17.5,0]],"id":28753299}],"con":true,"img":false}]}
{"op":"mcm","clk":"5323336938","pt":1646329717599,"mc":[{"id":"1.195532879","rc":[{"atb":[[1.73,1.99]],"id":38251452}],"con":true,"img":false}]}
{"op":"mcm","clk":"5323336979","pt":1646329717909,"mc":[{"id":"1.195532879","rc":[{"atb":[[1.84,0]],"id":28753299}],"con":true,"img":false}]}
{"op":"mcm","clk":"5323336991","pt":1646329717960,"mc":[{"id":"1.195532879","rc":[{"atb":[[1.94,1.99]],"id":28753299}],"con":true,"img":false}]}
{"op":"mcm","clk":"5323337013","pt":1646329718166,"mc":[{"id":"1.195532879","rc":[{"atb":[[2.22,0]],"id":39059999}],"con":true,"img":false}]}
{"op":"mcm","clk":"5323337034","pt":1646329718375,"mc":[{"id":"1.195532879","rc":[{"atb":[[1.43,0]],"id":40452329},{"atb":[[2.44,1.65]],"id":39059999}],"con":true,"img":false}]}
{"op":"mcm","clk":"5323337046","pt":1646329718477,"mc":[{"id":"1.195532879","rc":[{"atb":[[1.56,1.99]],"id":40452329}],"con":true,"img":false}]}
{"op":"mcm","clk":"5323337064","pt":1646329718684,"mc":[{"id":"1.195532879","rc":[{"atb":[[1.3,16.94]],"id":40452329},{"atb":[[1.56,14.1]],"id":38251452},{"atb":[[1.53,69.03]],"id":39632625}],"con":true,"img":false}]}
{"op":"mcm","clk":"5323337074","pt":1646329718787,"mc":[{"id":"1.195532879","rc":[{"atb":[[1.68,2.15]],"id":41555107}],"con":true,"img":false}]}
{"op":"mcm","clk":"5323337086","pt":1646329718891,"mc":[{"id":"1.195532879","rc":[{"atb":[[1.7,1.99]],"id":41555107}],"con":true,"img":false}]}
{"op":"mcm","clk":"5323337130","pt":1646329719406,"mc":[{"id":"1.195532879","rc":[{"atb":[[2.34,0]],"id":39059999}],"con":true,"img":false}]}
{"op":"mcm","clk":"5323337138","pt":1646329719507,"mc":[{"id":"1.195532879","rc":[{"atb":[[2.44,3.64]],"id":39059999}],"con":true,"img":false}]}
{"op":"mcm","clk":"5323337729","pt":1646329726021,"mc":[{"id":"1.195532879","rc":[{"atb":[[2.42,0],[2.46,3.65]],"id":39059999}],"con":true,"img":false}]}
{"op":"mcm","clk":"5323337786","pt":1646329726642,"mc":[{"id":"1.195532879","rc":[{"atb":[[2.44,1.65]],"id":39059999}],"con":true,"img":false}]}
{"op":"mcm","clk":"5323337796","pt":1646329726745,"mc":[{"id":"1.195532879","rc":[{"atb":[[2.48,1.99]],"id":39059999}],"con":true,"img":false}]}
{"op":"mcm","clk":"5323337874","pt":1646329727526,"mc":[{"id":"1.195532879","rc":[{"atb":[[1.67,0],[1.68,60.97]],"id":41555107},{"atl":[[9.6,11.63]],"id":41555107},{"atb":[[1.54,74.07],[1.53,0]],"id":40452329},{"atl":[[8,14.29]],"id":40452329},{"atb":[[1.7,0],[1.71,56.34]],"id":38251452},{"atl":[[11,10]],"id":38251452},{"atb":[[1.67,149.25]],"id":39632625},{"atl":[[9.8,11.36]],"id":39632625},{"atb":[[2.38,0],[2.44,29.43]],"id":39059999},{"atl":[[44,2.33]],"id":39059999},{"atb":[[1.92,43.48],[1.91,0]],"id":28753299},{"atl":[[17.5,6.06]],"id":28753299}],"con":true,"img":false}]}
{"op":"mcm","clk":"5323337981","pt":1646329728652,"mc":[{"id":"1.195532879","rc":[{"atb":[[1.56,0],[1.73,2.15]],"id":39632625}],"con":true,"img":false}]}
{"op":"mcm","clk":"5323338004","pt":1646329728862,"mc":[{"id":"1.195532879","rc":[{"atb":[[1.73,4.31],[1.7,0]],"id":39632625}],"con":true,"img":false}]}
{"op":"mcm","clk":"5323338026","pt":1646329729018,"mc":[{"id":"1.195532879","rc":[{"atl":[[80,0]],"id":40452329},{"atb":[[1.71,58.33],[1.69,0]],"id":39632625},{"atl":[[70,0],[80,0],[60,0]],"id":39632625},{"atl":[[70,0],[80,0],[60,0]],"id":39059999}],"con":true,"img":false}]}
{"op":"mcm","clk":"5323338038","pt":1646329729125,"mc":[{"id":"1.195532879","rc":[{"atl":[[80,0]],"id":41555107},{"atl":[[80,0]],"id":38251452},{"atl":[[70,0],[80,0],[60,0]],"id":28753299}],"con":true,"img":false}]}
{"op":"mcm","clk":"5323338047","pt":1646329729228,"mc":[{"id":"1.195532879","rc":[{"atb":[[2.44,27.78]],"id":39059999}],"con":true,"img":false}]}
{"op":"mcm","clk":"5323338071","pt":1646329729435,"mc":[{"id":"1.195532879","rc":[{"atb":[[2.5,1.65]],"id":39059999}],"con":true,"img":false}]}
{"op":"mcm","clk":"5323338128","pt":1646329729952,"mc":[{"id":"1.195532879","rc":[{"atb":[[1.3,0]],"id":40452329},{"atb":[[1.56,0]],"id":38251452},{"atb":[[1.53,0]],"id":39632625}],"con":true,"img":false}]}
{"op":"mcm","clk":"5323338204","pt":1646329730630,"mc":[{"id":"1.195532879","rc":[{"atb":[[1.71,56.34]],"id":39632625}],"con":true,"img":false}]}
{"op":"mcm","clk":"5323338221","pt":1646329730739,"mc":[{"id":"1.195532879","rc":[{"atb":[[1.74,1.99]],"id":39632625}],"con":true,"img":false}]}
{"op":"mcm","clk":"5323338637","pt":1646329734617,"mc":[{"id":"1.195532879","rc":[{"atl":[[9.6,0],[9.4,4.44]],"id":38251452},{"atb":[[1.72,55.56],[1.71,0]],"id":39632625},{"atb":[[2.46,31.05],[2.44,0]],"id":39059999},{"atl":[[15.5,0]],"id":28753299}],"con":true,"img":false}]}
{"op":"mcm","clk":"5323338649","pt":1646329734718,"mc":[{"id":"1.195532879","rc":[{"atl":[[16,4.84]],"id":28753299}],"con":true,"img":false}]}
{"op":"mcm","clk":"5323338689","pt":1646329735135,"mc":[{"id":"1.195532879","rc":[{"atb":[[2.5,3.65],[2.46,27.4]],"id":39059999}],"con":true,"img":false}]}
{"op":"mcm","clk":"5323338719","pt":1646329735449,"mc":[{"id":"1.195532879","rc":[{"atb":[[1.59,11.36]],"id":41555107},{"atb":[[1.3,27.95]],"id":40452329},{"atb":[[1.56,19.91]],"id":38251452}],"con":true,"img":false}]}
{"op":"mcm","clk":"5323338760","pt":1646329735814,"mc":[{"id":"1.195532879","rc":[{"atb":[[2.48,0]],"id":39059999}],"con":true,"img":false}]}
{"op":"mcm","clk":"5323338771","pt":1646329735920,"mc":[{"id":"1.195532879","rc":[{"atb":[[2.52,1.99]],"id":39059999}],"con":true,"img":false}]}
{"op":"mcm","clk":"5323338840","pt":1646329736651,"mc":[{"id":"1.195532879","rc":[{"atl":[[10,0],[9.8,4.55]],"id":38251452},{"atb":[[1.01,4804.04],[1.67,0],[1.51,0]],"id":39632625},{"atb":[[2.46,0],[2.48,27.03]],"id":39059999},{"atl":[[16.5,0],[17,2.5]],"id":28753299}],"con":true,"img":false}]}
{"op":"mcm","clk":"5323338940","pt":1646329737528,"mc":[{"id":"1.195532879","rc":[{"atb":[[1.66,151.52]],"id":41555107},{"atl":[[10,16.67]],"id":41555107},{"atb":[[1.52,192.31]],"id":40452329},{"atl":[[8.4,20.27]],"id":40452329}],"con":true,"img":false}]}
{"op":"mcm","clk":"5323339003","pt":1646329738161,"mc":[{"id":"1.195532879","rc":[{"atb":[[1.01,4804.04],[1.57,0]],"id":41555107},{"atl":[[70,0]],"id":41555107},{"atb":[[1.01,4804.04],[1.29,0]],"id":40452329},{"atl":[[70,0]],"id":40452329}],"con":true,"img":false}]}
{"op":"mcm","clk":"5323339229","pt":1646329740147,"mc":[{"id":"1.195532879","rc":[{"atb":[[2.5,2]],"id":39059999}],"con":true,"img":false}]}
{"op":"mcm","clk":"5323339257","pt":1646329740353,"mc":[{"id":"1.195532879","rc":[{"atb":[[2.54,1.65]],"id":39059999}],"con":true,"img":false}]}
{"op":"mcm","clk":"5323339283","pt":1646329740556,"mc":[{"id":"1.195532879","rc":[{"atb":[[1.59,0]],"id":41555107},{"atb":[[1.3,0]],"id":40452329},{"atb":[[1.56,0]],"id":38251452}],"con":true,"img":false}]}
{"op":"mcm","clk":"5323339663","pt":1646329743927,"mc":[{"id":"1.195532879","rc":[{"atb":[[2.5,28.67],[2.48,0]],"id":39059999}],"con":true,"img":false}]}
{"op":"mcm","clk":"5323339691","pt":1646329744189,"mc":[{"id":"1.195532879","rc":[{"atb":[[2.54,3.65],[2.5,26.67]],"id":39059999}],"con":true,"img":false}]}
{"op":"mcm","clk":"5323339714","pt":1646329744343,"mc":[{"id":"1.195532879","rc":[{"atb":[[2.54,1.65],[2.52,5.31]],"id":39059999}],"con":true,"img":false}]}
{"op":"mcm","clk":"5323339762","pt":1646329744660,"mc":[{"id":"1.195532879","rc":[{"atb":[[1.7,142.86]],"id":39632625},{"atl":[[10.5,15.79]],"id":39632625}],"con":true,"img":false}]}
{"op":"mcm","clk":"5323340002","pt":1646329746270,"mc":[{"id":"1.195532879","rc":[{"atb":[[1.7,6.4]],"id":41555107},{"atb":[[1.56,7.91]],"id":40452329},{"atb":[[1.56,19.91]],"id":38251452}],"con":true,"img":false}]}
{"op":"mcm","clk":"5323340033","pt":1646329746479,"mc":[{"id":"1.195532879","rc":[{"atb":[[1.71,6.4],[1.69,0]],"id":41555107},{"atb":[[1.55,0],[1.57,7.92]],"id":40452329}],"con":true,"img":false}]}
{"op":"mcm","clk":"5323340050","pt":1646329746636,"mc":[{"id":"1.195532879","rc":[{"atb":[[1.69,144.93]],"id":38251452},{"atb":[[1.9,111.11]],"id":28753299},{"atl":[[18,5.88]],"id":28753299}],"con":true,"img":false}]}
{"op":"mcm","clk":"5323340073","pt":1646329746845,"mc":[{"id":"1.195532879","rc":[{"atb":[[1.73,2.15],[1.68,58.82]],"id":41555107},{"atb":[[1.59,2.15],[1.33,0]],"id":40452329}],"con":true,"img":false}]}
{"op":"mcm","clk":"5323340083","pt":1646329746950,"mc":[{"id":"1.195532879","rc":[{"atb":[[1.59,10.07],[1.57,0]],"id":40452329}],"con":true,"img":false}]}
{"op":"mcm","clk":"5323340145","pt":1646329747263,"mc":[{"id":"1.195532879","rc":[{"atb":[[1.71,62.74]],"id":41555107},{"spn":5.26,"spf":"NaN","id":41555107},{"atb":[[1.57,70.18]],"id":40452329},{"spn":1.59,"spf":1.0,"id":40452329},{"atb":[[1.54,0]],"id":38251452},{"spn":5.56,"spf":"NaN","id":38251452},{"spn":1.73,"spf":1.0,"id":39632625},{"spn":19.27,"spf":"NaN","id":39059999},{"atb":[[1.01,4804.04],[1.71,0]],"id":28753299},{"spn":8.97,"spf":"NaN","id":28753299}],"con":true,"img":false}]}
{"op":"mcm","clk":"5323340155","pt":1646329747366,"mc":[{"id":"1.195532879","rc":[{"atb":[[1.56,5.92]],"id":40452329}],"con":true,"img":false}]}
{"op":"mcm","clk":"5323340165","pt":1646329747419,"mc":[{"id":"1.195532879","rc":[{"atb":[[1.6,1.99]],"id":40452329}],"con":true,"img":false}]}
{"op":"mcm","clk":"5323340199","pt":1646329747733,"mc":[{"id":"1.195532879","rc":[{"atb":[[1.7,4.41]],"id":41555107}],"con":true,"img":false}]}
{"op":"mcm","clk":"5323340213","pt":1646329747832,"mc":[{"id":"1.195532879","rc":[{"atb":[[1.74,1.99]],"id":41555107}],"con":true,"img":false}]}
{"op":"mcm","clk":"5323340329","pt":1646329748871,"mc":[{"id":"1.195532879","rc":[{"atb":[[1.72,55.56],[1.7,11.45],[1.71,6.4]],"id":41555107},{"atb":[[1.56,14.69],[1.57,0],[1.58,68.97]],"id":40452329}],"con":true,"img":false}]}
{"op":"mcm","clk":"5323340347","pt":1646329749027,"mc":[{"id":"1.195532879","rc":[{"atb":[[1.7,4.41]],"id":41555107},{"atb":[[1.56,5.92]],"id":40452329}],"con":true,"img":false}]}
{"op":"mcm","clk":"5323340549","pt":1646329750846,"mc":[{"id":"1.195532879","rc":[{"atb":[[1.7,0]],"id":41555107},{"atb":[[1.56,0]],"id":40452329},{"atb":[[1.56,0]],"id":38251452}],"con":true,"img":false}]}
{"op":"mcm","clk":"5323340635","pt":1646329751673,"mc":[{"id":"1.195532879","rc":[{"atb":[[1.83,9.09]],"id":38251452},{"atl":[[9.2,4.55],[9.4,0]],"id":38251452},{"atl":[[9,0],[9.2,3.12],[8.8,4.76]],"id":39632625},{"atb":[[2.24,7.04]],"id":28753299},{"atl":[[16,0],[17,8.75]],"id":28753299}],"con":true,"img":false}]}
{"op":"mcm","clk":"5323340645","pt":1646329751723,"mc":[{"id":"1.195532879","rc":[{"atb":[[2.08,13.62]],"id":28753299}],"con":true,"img":false}]}
{"op":"mcm","clk":"5323340654","pt":1646329751835,"mc":[{"id":"1.195532879","rc":[{"atl":[[11.5,5]],"id":38251452},{"atb":[[1.93,0],[2.1,14.08]],"id":28753299}],"con":true,"img":false}]}
{"op":"mcm","clk":"5323340666","pt":1646329751934,"mc":[{"id":"1.195532879","rc":[{"atb":[[1.83,0]],"id":38251452},{"atb":[[2.24,0]],"id":28753299}],"con":true,"img":false}]}
{"op":"mcm","clk":"5323340674","pt":1646329752035,"mc":[{"id":"1.195532879","rc":[{"atl":[[11.5,0]],"id":38251452},{"atb":[[2.1,0],[2.08,41.78]],"id":28753299}],"con":true,"img":false}]}
{"op":"mcm","clk":"5323340685","pt":1646329752142,"mc":[{"id":"1.195532879","rc":[{"atb":[[1.94,85.55],[2.08,13.62]],"id":28753299}],"con":true,"img":false}]}
{"op":"mcm","clk":"5323340711","pt":1646329752349,"mc":[{"id":"1.195532879","rc":[{"atl":[[9.6,4.65],[9.8,0]],"id":38251452},{"atl":[[9.2,8]],"id":39632625},{"atb":[[2.04,38.46],[1.94,83.56]],"id":28753299},{"atl":[[17,6.25],[18,2.35]],"id":28753299}],"con":true,"img":false}]}
{"op":"mcm","clk":"5323340726","pt":1646329752449,"mc":[{"id":"1.195532879","rc":[{"atb":[[2.1,1.99]],"id":28753299}],"con":true,"img":false}]}
{"op":"mcm","clk":"5323340758","pt":1646329752758,"mc":[{"id":"1.195532879","rc":[{"atl":[[9.2,4.88]],"id":39632625},{"atb":[[2.08,0]],"id":28753299}],"con":true,"img":false}]}
{"op":"mcm","clk":"5323340894","pt":1646329753949,"mc":[{"id":"1.195532879","rc":[{"atb":[[2.46,68.49]],"id":39059999},{"atl":[[48,3.19]],"id":39059999}],"con":true,"img":false}]}
{"op":"mcm","clk":"5323340902","pt":1646329754053,"mc":[{"id":"1.195532879","rc":[{"atb":[[2.06,37.74],[2.04,0]],"id":28753299},{"atl":[[17.5,0]],"id":28753299}],"con":true,"img":false}]}
{"op":"mcm","clk":"5323340962","pt":1646329754671,"mc":[{"id":"1.195532879","rc":[{"atb":[[2.1,0]],"id":28753299}],"con":true,"img":false}]}
{"op":"mcm","clk":"5323340974","pt":1646329754773,"mc":[{"id":"1.195532879","rc":[{"atb":[[2.08,1.99]],"id":28753299}],"con":true,"img":false}]}
{"op":"mcm","clk":"5323341017","pt":1646329755349,"mc":[{"id":"1.195532879","rc":[{"atb":[[1.74,4.15],[1.71,0]],"id":41555107}],"con":true,"img":false}]}
{"op":"mcm","clk":"5323341121","pt":1646329756332,"mc":[{"id":"1.195532879","rc":[{"atb":[[1.55,14.48]],"id":40452329},{"atb":[[1.73,7.79]],"id":38251452},{"atb":[[1.74,6.4]],"id":39632625}],"con":true,"img":false}]}
{"op":"mcm","clk":"5323341133","pt":1646329756436,"mc":[{"id":"1.195532879","rc":[{"atb":[[1.72,0],[1.74,7.8]],"id":38251452},{"atb":[[1.73,2.15],[1.75,6.4]],"id":39632625}],"con":true,"img":false}]}
{"op":"mcm","clk":"5323341191","pt":1646329756955,"mc":[{"id":"1.195532879","rc":[{"atb":[[1.74,4.41]],"id":39632625}],"con":true,"img":false}]}
{"op":"mcm","clk":"5323341203","pt":1646329757058,"mc":[{"id":"1.195532879","rc":[{"atb":[[1.76,1.99]],"id":39632625}],"con":true,"img":false}]}
{"op":"mcm","clk":"5323341225","pt":1646329757263,"mc":[{"id":"1.195532879","rc":[{"atb":[[1.72,55.56],[1.71,0]],"id":38251452},{"atb":[[1.8,9.62],[1.74,58.46]],"id":39632625},{"atb":[[2.08,0]],"id":39059999},{"atb":[[2.06,0],[2.04,38.46]],"id":28753299},{"atl":[[17,0],[17.5,6.06]],"id":28753299}],"con":true,"img":false}]}
{"op":"mcm","clk":"5323341235","pt":1646329757366,"mc":[{"id":"1.195532879","rc":[{"atb":[[1.73,7.62]],"id":39632625}],"con":true,"img":false}]}
{"op":"mcm","clk":"5323341246","pt":1646329757469,"mc":[{"id":"1.195532879","rc":[{"atb":[[1.73,5.8]],"id":38251452}],"con":true,"img":false}]}
{"op":"mcm","clk":"5323341256","pt":1646329757572,"mc":[{"id":"1.195532879","rc":[{"atb":[[1.59,0],[1.75,1.99],[1.76,2.15]],"id":38251452},{"atb":[[1.73,5.47],[1.8,0],[1.79,2.15]],"id":39632625}],"con":true,"img":false}]}
{"op":"mcm","clk":"5323341303","pt":1646329757935,"mc":[{"id":"1.195532879","rc":[{"atb":[[1.72,0],[1.74,61.85]],"id":38251452},{"atb":[[1.74,4.41],[1.77,51.95]],"id":39632625},{"atl":[[18,0],[18.5,2.29]],"id":28753299}],"con":true,"img":false}]}
{"op":"mcm","clk":"5323341363","pt":1646329758554,"mc":[{"id":"1.195532879","rc":[{"atb":[[1.76,0]],"id":39632625}],"con":true,"img":false}]}
{"op":"mcm","clk":"5323341372","pt":1646329758660,"mc":[{"id":"1.195532879","rc":[{"atb":[[1.8,1.99]],"id":39632625}],"con":true,"img":false}]}
{"op":"mcm","clk":"5323341382","pt":1646329758764,"mc":[{"id":"1.195532879","rc":[{"atb":[[1.73,0]],"id":39632625}],"con":true,"img":false}]}
{"op":"mcm","clk":"5323341397","pt":1646329758866,"mc":[{"id":"1.195532879","rc":[{"atb":[[1.7,142.86]],"id":41555107},{"atl":[[11,25]],"id":41555107},{"atb":[[1.56,178.57]],"id":40452329},{"atl":[[8.8,32.05]],"id":40452329}],"con":true,"img":false}]}
{"op":"mcm","clk":"5323341407","pt":1646329758969,"mc":[{"id":"1.195532879","rc":[{"atb":[[1.75,0]],"id":38251452}],"con":true,"img":false}]}
{"op":"mcm","clk":"5323341415","pt":1646329759073,"mc":[{"id":"1.195532879","rc":[{"atb":[[1.77,1.99]],"id":38251452}],"con":true,"img":false}]}
{"op":"mcm","clk":"5323341439","pt":1646329759279,"mc":[{"id":"1.195532879","rc":[{"atb":[[1.58,0]],"id":41555107},{"atl":[[60,0]],"id":41555107},{"atb":[[1.28,0]],"id":40452329},{"atl":[[60,0]],"id":40452329},{"atb":[[1.78,51.28],[1.77,0]],"id":39632625}],"con":true,"img":false}]}
{"op":"mcm","clk":"5323341451","pt":1646329759332,"mc":[{"id":"1.195532879","rc":[{"atb":[[2.08,0]],"id":28753299}],"con":true,"img":false}]}
{"op":"mcm","clk":"5323341462","pt":1646329759436,"mc":[{"id":"1.195532879","rc":[{"atb":[[2.06,1.99]],"id":28753299}],"con":true,"img":false}]}
{"op":"mcm","clk":"5323341612","pt":1646329760936,"mc":[{"id":"1.195532879","rc":[{"atb":[[2.06,40.45],[1.94,0]],"id":28753299}],"con":true,"img":false}]}
{"op":"mcm","clk":"5323341633","pt":1646329761149,"mc":[{"id":"1.195532879","rc":[{"atb":[[1.73,0]],"id":38251452},{"atb":[[1.74,0]],"id":39632625}],"con":true,"img":false}]}
{"op":"mcm","clk":"5323341726","pt":1646329762078,"mc":[{"id":"1.195532879","rc":[{"atb":[[2.08,1.65]],"id":28753299}],"con":true,"img":false}]}
{"op":"mcm","clk":"5323341765","pt":1646329762442,"mc":[{"id":"1.195532879","rc":[{"atb":[[1.74,7.8],[1.75,53.33]],"id":38251452},{"atl":[[9,4.65],[9.2,0]],"id":38251452},{"atl":[[8.8,0]],"id":39632625},{"atb":[[2.7,4.46]],"id":39059999}],"con":true,"img":false}]}
{"op":"mcm","clk":"5323341777","pt":1646329762547,"mc":[{"id":"1.195532879","rc":[{"atl":[[9,9.52]],"id":39632625},{"atb":[[2.72,4.46],[2.52,1.99]],"id":39059999}],"con":true,"img":false}]}
{"op":"mcm","clk":"5323341790","pt":1646329762650,"mc":[{"id":"1.195532879","rc":[{"atb":[[2.7,0]],"id":39059999}],"con":true,"img":false}]}
{"op":"mcm","clk":"5323341807","pt":1646329762861,"mc":[{"id":"1.195532879","rc":[{"atb":[[2.52,0]],"id":39059999}],"con":true,"img":false}]}
{"op":"mcm","clk":"5323341817","pt":1646329762964,"mc":[{"id":"1.195532879","rc":[{"atb":[[2.72,6.45]],"id":39059999}],"con":true,"img":false}]}
{"op":"mcm","clk":"5323341858","pt":1646329763379,"mc":[{"id":"1.195532879","rc":[{"atb":[[1.55,0]],"id":40452329}],"con":true,"img":false}]}
{"op":"mcm","clk":"5323341902","pt":1646329763748,"mc":[{"id":"1.195532879","rc":[{"atl":[[9.6,0]],"id":38251452},{"atb":[[2.5,0],[2.68,23.81]],"id":39059999}],"con":true,"img":false}]}
{"op":"mcm","clk":"5323341913","pt":1646329763850,"mc":[{"id":"1.195532879","rc":[{"atl":[[9.4,4.76]],"id":38251452},{"atl":[[9.2,0]],"id":39632625}],"con":true,"img":false}]}
{"op":"mcm","clk":"5323342052","pt":1646329765252,"mc":[{"id":"1.195532879","rc":[{"atb":[[1.74,0],[1.77,4.15]],"id":38251452},{"atb":[[1.8,4.15],[1.75,0]],"id":39632625}],"con":true,"img":false}]}
{"op":"mcm","clk":"5323342165","pt":1646329766343,"mc":[{"id":"1.195532879","rc":[{"atb":[[1.75,2.9]],"id":41555107},{"atb":[[1.77,7.05]],"id":38251452}],"con":true,"img":false}]}
{"op":"mcm","clk":"5323342258","pt":1646329767171,"mc":[{"id":"1.195532879","rc":[{"atb":[[1.74,2.16]],"id":41555107}],"con":true,"img":false}]}
{"op":"mcm","clk":"5323342267","pt":1646329767277,"mc":[{"id":"1.195532879","rc":[{"atb":[[1.76,1.99]],"id":41555107}],"con":true,"img":false}]}
{"op":"mcm","clk":"5323342277","pt":1646329767380,"mc":[{"id":"1.195532879","rc":[{"atb":[[1.76,4.15]],"id":41555107}],"con":true,"img":false}]}
{"op":"mcm","clk":"5323342287","pt":1646329767484,"mc":[{"id":"1.195532879","rc":[{"atb":[[1.74,0]],"id":41555107}],"con":true,"img":false}]}
{"op":"mcm","clk":"5323342343","pt":1646329767967,"mc":[{"id":"1.195532879","rc":[{"atb":[[2,100]],"id":28753299},{"atl":[[19.5,5.41]],"id":28753299}],"con":true,"img":false}]}
{"op":"mcm","clk":"5323342363","pt":1646329768161,"mc":[{"id":"1.195532879","rc":[{"atb":[[1.72,0],[1.74,54.05]],"id":41555107},{"atl":[[8.6,4.88],[8.8,0]],"id":41555107},{"atl":[[9,0],[9.2,9.3]],"id":38251452},{"atl":[[9,0],[9.2,12.2]],"id":39632625},{"atl":[[36,0],[38,2.7]],"id":39059999},{"atb":[[1.7,0]],"id":28753299},{"atl":[[17.5,0],[18,5.88]],"id":28753299}],"con":true,"img":false}]}
{"op":"mcm","clk":"5323342384","pt":1646329768267,"mc":[{"id":"1.195532879","rc":[{"atl":[[9,3.2]],"id":41555107}],"con":true,"img":false}]}
{"op":"mcm","clk":"5323342406","pt":1646329768473,"mc":[{"id":"1.195532879","rc":[{"atl":[[9,0]],"id":41555107}],"con":true,"img":false}]}
{"op":"mcm","clk":"5323342464","pt":1646329768888,"mc":[{"id":"1.195532879","rc":[{"atb":[[1.54,250]],"id":40452329}],"con":true,"img":false}]}
{"op":"mcm","clk":"5323342477","pt":1646329768996,"mc":[{"id":"1.195532879","rc":[{"atl":[[18,10.42]],"id":28753299}],"con":true,"img":false}]}
{"op":"mcm","clk":"5323342492","pt":1646329769146,"mc":[{"id":"1.195532879","rc":[{"atb":[[1.73,0],[1.77,2.15]],"id":41555107},{"atb":[[2.12,2.15],[1.75,0]],"id":28753299},{"atl":[[18,5.88]],"id":28753299}],"con":true,"img":false}]}
{"op":"mcm","clk":"5323342502","pt":1646329769253,"mc":[{"id":"1.195532879","rc":[{"atb":[[1.6,10.43]],"id":40452329},{"atb":[[1.76,131.58]],"id":39632625},{"atl":[[9.6,4.65],[9.4,0]],"id":39632625}],"con":true,"img":false}]}
{"op":"mcm","clk":"5323342511","pt":1646329769354,"mc":[{"id":"1.195532879","rc":[{"atb":[[1.59,2.15],[1.61,10.44]],"id":40452329}],"con":true,"img":false}]}
{"op":"mcm","clk":"5323342531","pt":1646329769562,"mc":[{"id":"1.195532879","rc":[{"atb":[[2.06,38.46]],"id":28753299}],"con":true,"img":false}]}
{"op":"mcm","clk":"5323342542","pt":1646329769667,"mc":[{"id":"1.195532879","rc":[{"atb":[[2.06,0],[2.12,4.31],[2.14,1.99]],"id":28753299}],"con":true,"img":false}]}
{"op":"mcm","clk":"5323342550","pt":1646329769772,"mc":[{"id":"1.195532879","rc":[{"atb":[[1.74,0],[1.75,56.23]],"id":41555107},{"atl":[[9,5],[9.2,0]],"id":41555107},{"atb":[[1.59,69.95],[1.58,0]],"id":40452329},{"atl":[[9.6,4.65],[9.4,0]],"id":38251452},{"atb":[[1.52,0]],"id":39632625},{"atl":[[40,0],[42,1]],"id":39059999},{"atb":[[2.04,0],[2.08,38.69]],"id":28753299},{"atl":[[18.5,0],[19,2.22]],"id":28753299}],"con":true,"img":false}]}
{"op":"mcm","clk":"5323342572","pt":1646329769984,"mc":[{"id":"1.195532879","rc":[{"atb":[[1.76,2.16]],"id":41555107}],"con":true,"img":false}]}
{"op":"mcm","clk":"5323342585","pt":1646329770087,"mc":[{"id":"1.195532879","rc":[{"atb":[[1.78,1.99]],"id":41555107}],"con":true,"img":false}]}
{"op":"mcm","clk":"5323342763","pt":1646329771459,"mc":[{"id":"1.195532879","rc":[{"atb":[[1.75,53.33]],"id":41555107},{"atb":[[1.6,8.44]],"id":40452329},{"atb":[[1.77,4.15]],"id":38251452}],"con":true,"img":false}]}
{"op":"mcm","clk":"5323342774","pt":1646329771564,"mc":[{"id":"1.195532879","rc":[{"atb":[[1.62,1.99]],"id":40452329}],"con":true,"img":false}]}
{"op":"mcm","clk":"5323342956","pt":1646329773177,"mc":[{"id":"1.195532879","rc":[{"atb":[[2.54,0]],"id":39059999},{"atb":[[2.08,37.04]],"id":28753299}],"con":true,"img":false}]}
{"op":"mcm","clk":"5323342977","pt":1646329773385,"mc":[{"id":"1.195532879","rc":[{"atb":[[1.75,0],[1.76,54.79]],"id":41555107},{"atb":[[1.59,2.15],[1.6,75.11]],"id":40452329},{"atl":[[10.5,10.53]],"id":38251452},{"atb":[[2.74,1.65]],"id":39059999},{"atb":[[2.16,1.65],[2.1,36.36],[2.08,0]],"id":28753299}],"con":true,"img":false}]}
{"op":"mcm","clk":"5323342986","pt":1646329773490,"mc":[{"id":"1.195532879","rc":[{"atl":[[9.2,0]],"id":38251452}],"con":true,"img":false}]}
{"op":"mcm","clk":"5323343000","pt":1646329773593,"mc":[{"id":"1.195532879","rc":[{"atb":[[2.12,2.15],[2.16,3.65]],"id":28753299}],"con":true,"img":false}]}
{"op":"mcm","clk":"5323343022","pt":1646329773748,"mc":[{"id":"1.195532879","rc":[{"atb":[[1.6,66.67]],"id":40452329}],"con":true,"img":false}]}
{"op":"mcm","clk":"5323343084","pt":1646329774373,"mc":[{"id":"1.195532879","rc":[{"atb":[[2.14,0]],"id":28753299}],"con":true,"img":false}]}
{"op":"mcm","clk":"5323343094","pt":1646329774475,"mc":[{"id":"1.195532879","rc":[{"atb":[[2.18,1.99]],"id":28753299}],"con":true,"img":false}]}
{"op":"mcm","clk":"5323343182","pt":1646329775263,"mc":[{"id":"1.195532879","rc":[{"atl":[[9.6,0],[10,4.44]],"id":38251452},{"atb":[[2.68,0],[2.7,23.53]],"id":39059999},{"atb":[[2.14,35.09]],"id":28753299}],"con":true,"img":false}]}
{"op":"mcm","clk":"5323343202","pt":1646329775471,"mc":[{"id":"1.195532879","rc":[{"atb":[[2.1,0]],"id":28753299}],"con":true,"img":false}]}
{"op":"mcm","clk":"5323343255","pt":1646329776092,"mc":[{"id":"1.195532879","rc":[{"atb":[[1.78,4.15],[1.76,52.63]],"id":41555107}],"con":true,"img":false}]}
{"op":"mcm","clk":"5323343330","pt":1646329776871,"mc":[{"id":"1.195532879","rc":[{"atl":[[9.2,0],[8.8,11.36]],"id":39632625},{"atl":[[36,2.33],[38,0]],"id":39059999},{"atl":[[17.5,5.41],[18,0]],"id":28753299}],"con":true,"img":false}]}
{"op":"mcm","clk":"5323343351","pt":1646329777081,"mc":[{"id":"1.195532879","rc":[{"atb":[[1.71,5.8]],"id":41555107},{"atb":[[1.7,6.22]],"id":38251452}],"con":true,"img":false}]}
{"op":"mcm","clk":"5323343498","pt":1646329778380,"mc":[{"id":"1.195532879","rc":[{"atl":[[10,0],[11,4]],"id":38251452},{"atl":[[9.2,4.88]],"id":39632625},{"atl":[[40,1.03]],"id":39059999},{"atl":[[18.5,2.29]],"id":28753299}],"con":true,"img":false}]}
{"op":"mcm","clk":"5323343620","pt":1646329779674,"mc":[{"id":"1.195532879","rc":[{"atb":[[1.57,14.91]],"id":40452329}],"con":true,"img":false}]}
{"op":"mcm","clk":"5323343643","pt":1646329779889,"mc":[{"id":"1.195532879","rc":[{"atb":[[1.64,2.15],[1.59,0]],"id":40452329}],"con":true,"img":false}]}
{"op":"mcm","clk":"5323343662","pt":1646329780085,"mc":[{"id":"1.195532879","rc":[{"atb":[[1.64,4.31],[1.61,0]],"id":40452329}],"con":true,"img":false}]}
{"op":"mcm","clk":"5323343671","pt":1646329780192,"mc":[{"id":"1.195532879","rc":[{"atb":[[1.6,0],[1.62,66.51]],"id":40452329}],"con":true,"img":false}]}
{"op":"mcm","clk":"5323343704","pt":1646329780502,"mc":[{"id":"1.195532879","rc":[{"atb":[[1.62,64.52]],"id":40452329}],"con":true,"img":false}]}
{"op":"mcm","clk":"5323343715","pt":1646329780605,"mc":[{"id":"1.195532879","rc":[{"atb":[[1.65,1.99]],"id":40452329}],"con":true,"img":false}]}
{"op":"mcm","clk":"5323343859","pt":1646329782016,"mc":[{"id":"1.195532879","rc":[{"atl":[[10,4],[10.5,0]],"id":38251452},{"atl":[[9,12.5],[8.8,0]],"id":39632625}],"con":true,"img":false}]}
{"op":"mcm","clk":"5323343999","pt":1646329783372,"mc":[{"id":"1.195532879","rc":[{"atb":[[1.74,135.14]],"id":41555107}],"con":true,"img":false}]}
{"op":"mcm","clk":"5323344069","pt":1646329784094,"mc":[{"id":"1.195532879","rc":[{"atb":[[2.16,2]],"id":28753299}],"con":true,"img":false}]}
{"op":"mcm","clk":"5323344095","pt":1646329784307,"mc":[{"id":"1.195532879","rc":[{"atb":[[2.2,1.65]],"id":28753299}],"con":true,"img":false}]}
{"op":"mcm","clk":"5323344121","pt":1646329784506,"mc":[{"id":"1.195532879","rc":[{"atb":[[2.2,3.65],[2.16,0]],"id":28753299}],"con":true,"img":false}]}
{"op":"mcm","clk":"5323344175","pt":1646329784974,"mc":[{"id":"1.195532879","rc":[{"atb":[[2.18,0]],"id":28753299}],"con":true,"img":false}]}
{"op":"mcm","clk":"5323344188","pt":1646329785076,"mc":[{"id":"1.195532879","rc":[{"atb":[[2.22,1.99]],"id":28753299}],"con":true,"img":false}]}
{"op":"mcm","clk":"5323344280","pt":1646329786009,"mc":[{"id":"1.195532879","rc":[{"atb":[[1.66,0]],"id":41555107},{"atb":[[1.63,63.49],[1.62,0]],"id":40452329},{"atl":[[9.2,0],[9.4,4.76]],"id":39632625},{"atl":[[36,0],[38,2.7]],"id":39059999},{"atb":[[2.18,33.9],[2.14,0]],"id":28753299}],"con":true,"img":false}]}
{"op":"mcm","clk":"5323344380","pt":1646329786892,"mc":[{"id":"1.195532879","rc":[{"atb":[[1.71,0]],"id":41555107},{"atb":[[1.7,0]],"id":38251452}],"con":true,"img":false}]}
{"op":"mcm","clk":"5323344518","pt":1646329788397,"mc":[{"id":"1.195532879","rc":[{"atb":[[1.73,136.99]],"id":38251452},{"atl":[[12,9.09]],"id":38251452},{"atb":[[2.66,60.24]],"id":39059999},{"atl":[[40,0],[46,4.96]],"id":39059999}],"con":true,"img":false}]}
{"op":"mcm","clk":"5323344674","pt":1646329789302,"mc":[{"id":"1.195532879","rc":[{"atb":[[1.57,0]],"id":40452329}],"con":true,"img":false}]}
{"op":"mcm","clk":"5323344688","pt":1646329789399,"mc":[{"id":"1.195532879","rc":[{"atb":[[1.01,4804.04]],"id":38251452},{"atb":[[1.01,4804.04]],"id":39059999}],"con":true,"img":false}]}
{"op":"mcm","clk":"5323344778","pt":1646329790282,"mc":[{"id":"1.195532879","rc":[{"atb":[[1.8,10.19]],"id":38251452}],"con":true,"img":false}]}
{"op":"mcm","clk":"5323344787","pt":1646329790386,"mc":[{"id":"1.195532879","rc":[{"atb":[[1.81,4.15],[1.77,1.99]],"id":38251452}],"con":true,"img":false}]}
{"op":"mcm","clk":"5323344801","pt":1646329790488,"mc":[{"id":"1.195532879","rc":[{"atb":[[1.81,0],[1.77,16.33]],"id":38251452},{"atl":[[10,0],[9.8,4]],"id":38251452}],"con":true,"img":false}]}
{"op":"mcm","clk":"5323344820","pt":1646329790693,"mc":[{"id":"1.195532879","rc":[{"atl":[[12.5,4.53]],"id":38251452}],"con":true,"img":false}]}
{"op":"mcm","clk":"5323344826","pt":1646329790797,"mc":[{"id":"1.195532879","rc":[{"atb":[[1.77,14.34]],"id":38251452}],"con":true,"img":false}]}
{"op":"mcm","clk":"5323344837","pt":1646329790911,"mc":[{"id":"1.195532879","rc":[{"atb":[[1.8,0],[1.81,1.99]],"id":38251452},{"atl":[[12.5,0]],"id":38251452}],"con":true,"img":false}]}
{"op":"mcm","clk":"5323344893","pt":1646329791481,"mc":[{"id":"1.195532879","rc":[{"atb":[[1.8,2.15],[1.81,0],[1.76,0]],"id":38251452}],"con":true,"img":false}]}
{"op":"mcm","clk":"5323344908","pt":1646329791589,"mc":[{"id":"1.195532879","rc":[{"atb":[[1.78,1.99]],"id":38251452}],"con":true,"img":false}]}
{"op":"mcm","clk":"5323344922","pt":1646329791698,"mc":[{"id":"1.195532879","rc":[{"atb":[[1.78,53.27],[1.75,0]],"id":38251452},{"atl":[[10.5,4.21],[11,0]],"id":38251452},{"atl":[[17.5,0],[18,5.88]],"id":28753299}],"con":true,"img":false}]}
{"op":"mcm","clk":"5323344942","pt":1646329791896,"mc":[{"id":"1.195532879","rc":[{"atb":[[1.78,51.28]],"id":38251452}],"con":true,"img":false}]}
{"op":"mcm","clk":"5323344953","pt":1646329792009,"mc":[{"id":"1.195532879","rc":[{"atb":[[1.81,1.99]],"id":38251452}],"con":true,"img":false}]}
{"op":"mcm","clk":"5323344976","pt":1646329792214,"mc":[{"id":"1.195532879","rc":[{"atb":[[1.79,2.9]],"id":41555107},{"atb":[[1.78,54.18]],"id":38251452}],"con":true,"img":false}]}
{"op":"mcm","clk":"5323345030","pt":1646329792782,"mc":[{"id":"1.195532879","rc":[{"atb":[[1.78,2.16]],"id":41555107}],"con":true,"img":false}]}
{"op":"mcm","clk":"5323345045","pt":1646329792894,"mc":[{"id":"1.195532879","rc":[{"atb":[[1.8,1.99],[1.77,54.1],[1.76,0]],"id":41555107},{"atb":[[1.79,50.63],[1.78,2.9]],"id":38251452},{"atl":[[18.5,0]],"id":28753299}],"con":true,"img":false}]}
{"op":"mcm","clk":"5323345055","pt":1646329792993,"mc":[{"id":"1.195532879","rc":[{"atb":[[1.8,4.15],[1.78,0],[1.75,6.58]],"id":41555107}],"con":true,"img":false}]}
{"op":"mcm","clk":"5323345067","pt":1646329793105,"mc":[{"id":"1.195532879","rc":[{"atb":[[1.75,0]],"id":41555107}],"con":true,"img":false}]}
{"op":"mcm","clk":"5323345119","pt":1646329793620,"mc":[{"id":"1.195532879","rc":[{"atb":[[1.78,51.28],[1.77,2.15]],"id":41555107}],"con":true,"img":false}]}
{"op":"mcm","clk":"5323345259","pt":1646329795126,"mc":[{"id":"1.195532879","rc":[{"atb":[[2.2,2]],"id":28753299}],"con":true,"img":false}]}
{"op":"mcm","clk":"5323345280","pt":1646329795331,"mc":[{"id":"1.195532879","rc":[{"atb":[[2.24,1.65]],"id":28753299}],"con":true,"img":false}]}
{"op":"mcm","clk":"5323345300","pt":1646329795542,"mc":[{"id":"1.195532879","rc":[{"atb":[[1.57,9.45]],"id":40452329},{"atb":[[1.78,0]],"id":38251452},{"atb":[[2.24,3.65],[2.2,0],[2.16,5.28]],"id":28753299}],"con":true,"img":false}]}
{"op":"mcm","clk":"5323345318","pt":1646329795740,"mc":[{"id":"1.195532879","rc":[{"atb":[[2.16,0]],"id":28753299}],"con":true,"img":false}]}
{"op":"mcm","clk":"5323345349","pt":1646329796006,"mc":[{"id":"1.195532879","rc":[{"atb":[[1.61,163.93]],"id":40452329},{"atb":[[1.74,202.7]],"id":39632625},{"atl":[[11.5,23.81]],"id":39632625},{"atb":[[2.18,4.17],[2.2,33.33]],"id":28753299},{"atl":[[20,5.26]],"id":28753299}],"con":true,"img":false}]}
{"op":"mcm","clk":"5323345366","pt":1646329796211,"mc":[{"id":"1.195532879","rc":[{"atb":[[2.22,0]],"id":28753299}],"con":true,"img":false}]}
{"op":"mcm","clk":"5323345378","pt":1646329796327,"mc":[{"id":"1.195532879","rc":[{"atb":[[2.26,1.99]],"id":28753299}],"con":true,"img":false}]}
{"op":"mcm","clk":"5323345395","pt":1646329796432,"mc":[{"id":"1.195532879","rc":[{"atb":[[2.18,0]],"id":28753299}],"con":true,"img":false}]}
{"op":"mcm","clk":"5323345474","pt":1646329797160,"mc":[{"id":"1.195532879","rc":[{"atb":[[1.56,0],[1.55,12.97],[1.54,0],[1.52,0]],"id":40452329},{"atb":[[1.7,0]],"id":39632625},{"atl":[[9.6,0]],"id":39632625},{"atl":[[17.5,5.41],[18,0]],"id":28753299}],"con":true,"img":false}]}
{"op":"mcm","clk":"5323345498","pt":1646329797365,"mc":[{"id":"1.195532879","rc":[{"atl":[[9.8,16.01]],"id":39632625}],"con":true,"img":false}]}
{"op":"mcm","clk":"5323345510","pt":1646329797408,"mc":[{"id":"1.195532879","rc":[{"atb":[[1.55,0]],"id":40452329}],"con":true,"img":false}]}
{"op":"mcm","clk":"5323345519","pt":1646329797520,"mc":[{"id":"1.195532879","rc":[{"atl":[[9.8,11.36]],"id":39632625}],"con":true,"img":false}]}
{"op":"mcm","clk":"5323345538","pt":1646329797723,"mc":[{"id":"1.195532879","rc":[{"atb":[[1.79,0]],"id":41555107}],"con":true,"img":false}]}
{"op":"mcm","clk":"5323345565","pt":1646329798042,"mc":[{"id":"1.195532879","rc":[{"atl":[[18.5,2.29]],"id":28753299}],"con":true,"img":false}]}
{"op":"mcm","clk":"5323345611","pt":1646329798446,"mc":[{"id":"1.195532879","rc":[{"atb":[[2.62,92.59]],"id":39059999},{"atl":[[50,3.06]],"id":39059999}],"con":true,"img":false}]}
{"op":"mcm","clk":"5323345674","pt":1646329798981,"mc":[{"id":"1.195532879","rc":[{"atb":[[1.81,4.15],[1.77,0]],"id":38251452},{"atl":[[9.6,4.21],[9.8,0]],"id":38251452}],"con":true,"img":false}]}
{"op":"mcm","clk":"5323345688","pt":1646329799156,"mc":[{"id":"1.195532879","rc":[{"atb":[[1.8,16.49],[1.81,1.99]],"id":38251452}],"con":true,"img":false}]}
{"op":"mcm","clk":"5323345791","pt":1646329800248,"mc":[{"id":"1.195532879","rc":[{"atb":[[2.12,11.77],[2.28,4.46]],"id":28753299},{"atl":[[17,4.46],[19,14.06]],"id":28753299}],"con":true,"img":false}]}
{"op":"mcm","clk":"5323345810","pt":1646329800447,"mc":[{"id":"1.195532879","rc":[{"atb":[[1.92,7.41],[1.89,5],[1.85,10],[1.77,14.5],[1.93,2.5]],"id":41555107},{"atl":[[9.6,31.39],[4.8,5],[7.6,7.41],[5.2,10],[4.4,2.5]],"id":41555107},{"atb":[[2,2.5],[1.92,10],[1.81,7.78],[1.96,5],[1.61,189.68]],"id":40452329},{"atl":[[8,42.43],[4.6,2.5],[5,5],[6.8,7.78],[5.4,10]],"id":40452329},{"atb":[[1.73,171.46],[2,9.98],[1.99,10],[2.06,5],[2.14,2.5]],"id":38251452},{"atl":[[8,9.98],[5.1,5],[5.5,10],[12,27.85],[4.7,2.5]],"id":38251452},{"atb":[[1.83,12.09],[2.06,10],[2.22,2.5],[1.78,71.43],[2.14,5]],"id":39632625},{"atl":[[5.1,2.5],[5.5,5],[9.8,34.33],[7.8,11.76],[5.9,10]],"id":39632625},{"atb":[[3.1,3.77],[3,10],[3.2,5],[3.4,2.5],[2.66,73.75],[2.7,29.82]],"id":39059999},{"atl":[[44,7.44],[11,2.5],[13,5],[28,2.96],[15,10]],"id":39059999},{"atb":[[2.3,5],[2.22,10],[2.38,2.5]],"id":28753299},{"atl":[[8,10],[7.2,5],[6.4,2.5]],"id":28753299}],"con":true,"img":false}]}
{"op":"mcm","clk":"5323345818","pt":1646329800544,"mc":[{"id":"1.195532879","rc":[{"atb":[[1.82,12.35]],"id":41555107},{"atl":[[7.4,4.03]],"id":40452329},{"atb":[[1.9,16.62]],"id":38251452},{"atb":[[1.8,11.09]],"id":39632625},{"atb":[[2.84,6.29]],"id":39059999}],"con":true,"img":false}]}
{"op":"mcm","clk":"5323345830","pt":1646329800645,"mc":[{"id":"1.195532879","rc":[{"atl":[[8.6,0],[4.4,7.5]],"id":41555107},{"atb":[[1.64,2.15],[1.95,7.78]],"id":40452329},{"atl":[[7.2,0],[4.6,7.5]],"id":40452329},{"atb":[[1.8,2.15],[2.14,7.5]],"id":38251452},{"atl":[[9.6,0],[4.7,7.5]],"id":38251452},{"atb":[[1.8,8.93],[2.2,10],[1.77,12.5]],"id":39632625},{"atl":[[5.1,7.5],[9,0]],"id":39632625},{"atb":[[2.72,1.99],[3.4,6.27]],"id":39059999},{"atl":[[38,0],[11,7.5]],"id":39059999}],"con":true,"img":false}]}
{"op":"mcm","clk":"5323345850","pt":1646329800849,"mc":[{"id":"1.195532879","rc":[{"atb":[[1.57,0]],"id":40452329},{"atl":[[7.4,0]],"id":40452329},{"atb":[[1.81,2.9]],"id":39632625}],"con":true,"img":false}]}
{"op":"mcm","clk":"5323345860","pt":1646329800907,"mc":[{"id":"1.195532879","rc":[{"atb":[[1.8,1.99]],"id":39632625},{"atb":[[2.7,23.53]],"id":39059999}],"con":true,"img":false}]}
{"op":"mcm","clk":"5323345890","pt":1646329801228,"mc":[{"id":"1.195532879","rc":[{"atb":[[1.8,0]],"id":39632625}],"con":true,"img":false}]}
{"op":"mcm","clk":"5323345900","pt":1646329801330,"mc":[{"id":"1.195532879","rc":[{"atb":[[2.24,1.99]],"id":39632625}],"con":true,"img":false}]}
{"op":"mcm","clk":"5323345912","pt":1646329801429,"mc":[{"id":"1.195532879","rc":[{"atb":[[1.8,1.99],[1.89,15]],"id":41555107}],"con":true,"img":false}]}
{"op":"mcm","clk":"5323345923","pt":1646329801539,"mc":[{"id":"1.195532879","rc":[{"atb":[[1.82,0]],"id":41555107},{"atb":[[1.9,0]],"id":38251452},{"atb":[[1.77,0]],"id":39632625},{"atb":[[2.84,0]],"id":39059999}],"con":true,"img":false}]}
{"op":"mcm","clk":"5323345937","pt":1646329801681,"mc":[{"id":"1.195532879","rc":[{"atb":[[1.81,0]],"id":38251452}],"con":true,"img":false}]}
{"op":"mcm","clk":"5323345945","pt":1646329801756,"mc":[{"id":"1.195532879","rc":[{"atb":[[2.16,1.99]],"id":38251452}],"con":true,"img":false}]}
{"op":"mcm","clk":"5323345966","pt":1646329801946,"mc":[{"id":"1.195532879","rc":[{"atb":[[2.26,0]],"id":28753299}],"con":true,"img":false}]}
{"op":"mcm","clk":"5323345976","pt":1646329802045,"mc":[{"id":"1.195532879","rc":[{"atb":[[2.4,1.99]],"id":28753299}],"con":true,"img":false}]}
{"op":"mcm","clk":"5323345986","pt":1646329802151,"mc":[{"id":"1.195532879","rc":[{"atb":[[1.92,9.56],[1.77,12.35]],"id":41555107},{"atb":[[1.8,0],[2.12,2.15]],"id":38251452},{"atb":[[2.12,9.62],[2.34,2.15]],"id":28753299}],"con":true,"img":false}]}
{"op":"mcm","clk":"5323345998","pt":1646329802214,"mc":[{"id":"1.195532879","rc":[{"atb":[[1.65,0]],"id":40452329}],"con":true,"img":false}]}
{"op":"mcm","clk":"5323346009","pt":1646329802362,"mc":[{"id":"1.195532879","rc":[{"atb":[[1.92,19.56],[1.89,5]],"id":41555107},{"atb":[[2.02,1.99]],"id":40452329}],"con":true,"img":false}]}
{"op":"mcm","clk":"5323346028","pt":1646329802526,"mc":[{"id":"1.195532879","rc":[{"atb":[[1.8,0]],"id":41555107}],"con":true,"img":false}]}
{"op":"mcm","clk":"5323346040","pt":1646329802644,"mc":[{"id":"1.195532879","rc":[{"atb":[[1.94,1.99]],"id":41555107}],"con":true,"img":false}]}
{"op":"mcm","clk":"5323346066","pt":1646329802955,"mc":[{"id":"1.195532879","rc":[{"atb":[[1.79,0],[1.93,43.01]],"id":38251452},{"atl":[[10.5,0],[4.9,10.26]],"id":38251452}],"con":true,"img":false}]}
{"op":"mcm","clk":"5323346075","pt":1646329803052,"mc":[{"id":"1.195532879","rc":[{"atb":[[2.72,0]],"id":39059999}],"con":true,"img":false}]}
{"op":"mcm","clk":"5323346084","pt":1646329803148,"mc":[{"id":"1.195532879","rc":[{"atb":[[1.85,57.06],[1.78,0]],"id":41555107},{"atl":[[9,0],[4.6,11.11]],"id":41555107},{"atb":[[1.76,52.63]],"id":40452329},{"atl":[[4.8,10.53],[7.6,0]],"id":40452329},{"atb":[[1.85,47.06],[1.78,20.15]],"id":39632625},{"atl":[[5.3,9.3],[9.4,0]],"id":39632625},{"atb":[[3,30],[3.45,1.99],[2.7,0]],"id":39059999},{"atl":[[42,0],[44,5.11],[48,0],[12,3.64]],"id":39059999},{"atl":[[18.5,0],[6.8,6.9]],"id":28753299}],"con":true,"img":false}]}
{"op":"mcm","clk":"5323346119","pt":1646329803414,"mc":[{"id":"1.195532879","rc":[{"atb":[[2.46,0],[2.66,13.51],[2.62,0],[2.1,0]],"id":39059999}],"con":true,"img":false}]}
{"op":"mcm","clk":"5323346165","pt":1646329803948,"mc":[{"id":"1.195532879","rc":[{"atb":[[2.4,4.15],[2.24,1.65]],"id":28753299}],"con":true,"img":false}]}
{"op":"mcm","clk":"5323346208","pt":1646329804312,"mc":[{"id":"1.195532879","rc":[{"atb":[[1.9,2.75]],"id":41555107},{"atb":[[1.97,2.75]],"id":40452329},{"atb":[[1.81,0]],"id":39632625}],"con":true,"img":false}]}
{"op":"mcm","clk":"5323346342","pt":1646329805515,"mc":[{"id":"1.195532879","rc":[{"atl":[[7.2,14.4],[17.5,0]],"id":28753299}],"con":true,"img":false}]}
{"op":"mcm","clk":"5323346371","pt":1646329805721,"mc":[{"id":"1.195532879","rc":[{"atl":[[4.8,23.61],[4.4,2.5]],"id":41555107},{"atl":[[4.6,2.5],[5,23.03]],"id":40452329},{"atl":[[5.1,22.76],[4.7,2.5]],"id":38251452},{"atl":[[5.5,21.8]],"id":39632625},{"atl":[[13,13.33]],"id":39059999}],"con":true,"img":false}]}
{"op":"mcm","clk":"5323346384","pt":1646329805827,"mc":[{"id":"1.195532879","rc":[{"atl":[[5.1,2.5]],"id":39632625},{"atl":[[11,2.5]],"id":39059999}],"con":true,"img":false}]}
{"op":"mcm","clk":"5323346420","pt":1646329806243,"mc":[{"id":"1.195532879","rc":[{"atb":[[2.74,0]],"id":39059999},{"atb":[[2.24,0]],"id":28753299}],"con":true,"img":false}]}
{"op":"mcm","clk":"5323346447","pt":1646329806447,"mc":[{"id":"1.195532879","rc":[{"atb":[[2.04,1.65]],"id":40452329},{"atb":[[2.18,1.65]],"id":38251452},{"atb":[[2.26,1.65]],"id":39632625},{"atb":[[3.5,1.65]],"id":39059999},{"atb":[[2.42,1.65]],"id":28753299}],"con":true,"img":false}]}
{"op":"mcm","clk":"5323346753","pt":1646329808957,"mc":[{"id":"1.195532879","rc":[{"spn":3.17,"spf":"NaN","id":41555107},{"spn":2.04,"spf":1.0,"id":40452329},{"atb":[[2.18,3.65],[2.14,2.5]],"id":38251452},{"spn":3.44,"spf":"NaN","id":38251452},{"spn":2.22,"spf":1.0,"id":39632625},{"atb":[[3.5,3.65]],"id":39059999},{"spn":7.25,"spf":"NaN","id":39059999},{"spn":4.41,"spf":"NaN","id":28753299}],"con":true,"img":false}]}
{"op":"mcm","clk":"5323346763","pt":1646329809052,"mc":[{"id":"1.195532879","rc":[{"atb":[[3.4,2.5]],"id":39059999}],"con":true,"img":false}]}
{"op":"mcm","clk":"5323346841","pt":1646329809856,"mc":[{"id":"1.195532879","rc":[{"atb":[[1.97,0]],"id":40452329},{"atb":[[2.08,4.37]],"id":38251452}],"con":true,"img":false}]}
{"op":"mcm","clk":"5323346895","pt":1646329810417,"mc":[{"id":"1.195532879","rc":[{"atb":[[2.16,0]],"id":38251452}],"con":true,"img":false}]}
{"op":"mcm","clk":"5323346908","pt":1646329810518,"mc":[{"id":"1.195532879","rc":[{"atb":[[2.2,1.99]],"id":38251452}],"con":true,"img":false}]}
{"op":"mcm","clk":"5323346919","pt":1646329810620,"mc":[{"id":"1.195532879","rc":[{"atb":[[1.92,9.56],[1.94,4.49]],"id":41555107}],"con":true,"img":false}]}
{"op":"mcm","clk":"5323346952","pt":1646329810988,"mc":[{"id":"1.195532879","rc":[{"atb":[[3.45,0]],"id":39059999}],"con":true,"img":false}]}
{"op":"mcm","clk":"5323346967","pt":1646329811151,"mc":[{"id":"1.195532879","rc":[{"atb":[[3.55,1.99]],"id":39059999}],"con":true,"img":false}]}
{"op":"mcm","clk":"5323347211","pt":1646329812955,"mc":[{"id":"1.195532879","rc":[{"atb":[[1.91,109.89]],"id":38251452},{"atl":[[5.1,47.15]],"id":38251452}],"con":true,"img":false}]}
{"op":"mcm","clk":"5323347237","pt":1646329813153,"mc":[{"id":"1.195532879","rc":[{"atb":[[1.83,120.48]],"id":41555107},{"atl":[[4.8,49.93]],"id":41555107},{"atb":[[1.74,135.14]],"id":40452329},{"atl":[[5,48.03]],"id":40452329},{"atb":[[1.83,132.57]],"id":39632625},{"atl":[[5.5,44.02]],"id":39632625},{"atb":[[2.96,51.02]],"id":39059999},{"atl":[[13,21.66]],"id":39059999},{"atb":[[2.16,86.21]],"id":28753299},{"atl":[[7.2,30.53]],"id":28753299}],"con":true,"img":false}]}
{"op":"mcm","clk":"5323347260","pt":1646329813367,"mc":[{"id":"1.195532879","rc":[{"atb":[[1.74,0],[1.7,0],[1.68,0]],"id":41555107},{"atl":[[11,0]],"id":41555107},{"atb":[[1.97,4.37]],"id":40452329},{"atl":[[8.8,0]],"id":40452329},{"atb":[[1.55,0]],"id":38251452},{"atl":[[70,0],[12,18.76],[60,0]],"id":38251452},{"atb":[[2.22,7.5],[1.76,0],[1.72,0],[1.74,0],[2.2,0]],"id":39632625},{"atl":[[11.5,0]],"id":39632625},{"atb":[[1.9,0]],"id":28753299},{"atl":[[19.5,0]],"id":28753299}],"con":true,"img":false}]}
{"op":"mcm","clk":"5323347292","pt":1646329813632,"mc":[{"id":"1.195532879","rc":[{"atb":[[2,4.65]],"id":40452329}],"con":true,"img":false}]}
{"op":"mcm","clk":"5323347304","pt":1646329813728,"mc":[{"id":"1.195532879","rc":[{"atb":[[1.64,0]],"id":40452329}],"con":true,"img":false}]}
{"op":"mcm","clk":"5323347527","pt":1646329815835,"mc":[{"id":"1.195532879","rc":[{"atb":[[1.9,0]],"id":41555107}],"con":true,"img":false}]}
{"op":"mcm","clk":"5323347637","pt":1646329817144,"mc":[{"id":"1.195532879","rc":[{"atb":[[2.18,2]],"id":38251452},{"atb":[[3.5,2]],"id":39059999}],"con":true,"img":false}]}
{"op":"mcm","clk":"5323347648","pt":1646329817259,"mc":[{"id":"1.195532879","rc":[{"atb":[[2.22,1.65]],"id":38251452},{"atb":[[3.6,1.65]],"id":39059999}],"con":true,"img":false}]}
{"op":"mcm","clk":"5323347667","pt":1646329817464,"mc":[{"id":"1.195532879","rc":[{"atb":[[3.55,5.31],[3.5,0]],"id":39059999}],"con":true,"img":false}]}
{"op":"mcm","clk":"5323347696","pt":1646329817767,"mc":[{"id":"1.195532879","rc":[{"atb":[[2.12,0],[2.34,12.54],[2.4,9.14]],"id":28753299},{"atl":[[7.2,47.15],[19,2.22],[6.2,4.99]],"id":28753299}],"con":true,"img":false}]}
{"op":"mcm","clk":"5323347718","pt":1646329817932,"mc":[{"id":"1.195532879","rc":[{"atb":[[1.73,136.99],[2.14,10.19]],"id":38251452},{"atl":[[5.1,59.45],[12,0]],"id":38251452},{"atb":[[2.28,0]],"id":28753299},{"atl":[[7.2,37.75],[17,0],[6.8,16.9]],"id":28753299}],"con":true,"img":false}]}
{"op":"mcm","clk":"5323347729","pt":1646329818035,"mc":[{"id":"1.195532879","rc":[{"atb":[[1.92,27.14],[1.94,15.03],[1.77,0]],"id":41555107},{"atl":[[4.8,78.05],[9.6,11.62],[4.2,10.54]],"id":41555107},{"atb":[[2.02,7.36],[1.97,15.67],[1.61,163.93]],"id":40452329},{"atl":[[8,14.29],[4.5,5.37],[5,66.11]],"id":40452329},{"atb":[[2.2,5.37]],"id":38251452},{"atl":[[4.6,3.38]],"id":38251452},{"atb":[[2.24,9.49],[1.78,0],[2.14,20.62]],"id":39632625},{"atl":[[5,7.5],[5.5,69.02],[9.8,11.36]],"id":39632625},{"atb":[[3.2,15.8],[2.66,0],[3.55,9.92]],"id":39059999},{"atl":[[10.5,4.61],[44,0],[13,38.94]],"id":39059999}],"con":true,"img":false}]}
{"op":"mcm","clk":"5323347737","pt":1646329818143,"mc":[{"id":"1.195532879","rc":[{"atl":[[8,0]],"id":38251452}],"con":true,"img":false}]}
{"op":"mcm","clk":"5323347750","pt":1646329818248,"mc":[{"id":"1.195532879","rc":[{"atb":[[1.92,29.3],[1.94,12.53]],"id":41555107},{"atl":[[4.8,59.44],[4.6,22.22],[7.6,0]],"id":41555107},{"atb":[[1.81,0]],"id":40452329},{"atl":[[4.8,21.06],[5,48.08],[6.8,0]],"id":40452329},{"atb":[[2,0]],"id":38251452},{"atl":[[5.1,41.69],[4.9,20.52]],"id":38251452},{"atb":[[1.83,120.48]],"id":39632625},{"atl":[[5.3,19.3],[5.5,52.22],[7.8,0]],"id":39632625},{"atb":[[3.1,0]],"id":39059999},{"atl":[[10,3.64],[13,30.61],[28,0]],"id":39059999}],"con":true,"img":false}]}
{"op":"mcm","clk":"5323347788","pt":1646329818565,"mc":[{"id":"1.195532879","rc":[{"atl":[[4.6,11.11],[4.4,14.26]],"id":41555107},{"atl":[[4.8,10.53],[4.7,10.81]],"id":40452329},{"atb":[[2.22,3.65],[2.18,0]],"id":38251452},{"atl":[[4.8,10.53]],"id":38251452},{"atb":[[2.22,2.5],[2.2,20.62]],"id":39632625},{"atl":[[5.3,9.99],[5.2,9.52]],"id":39632625},{"atl":[[11,6.5],[12,0]],"id":39059999},{"atl":[[6.8,10],[6.6,7.14]],"id":28753299}],"con":true,"img":false}]}
{"op":"mcm","clk":"5323347798","pt":1646329818658,"mc":[{"id":"1.195532879","rc":[{"atl":[[4.7,5.55]],"id":41555107},{"atb":[[2.2,10.74]],"id":38251452}],"con":true,"img":false}]}
{"op":"mcm","clk":"5323347811","pt":1646329818764,"mc":[{"id":"1.195532879","rc":[{"atb":[[2.22,1.65]],"id":38251452}],"con":true,"img":false}]}
{"op":"mcm","clk":"5323347922","pt":1646329819853,"mc":[{"id":"1.195532879","rc":[{"atl":[[4.7,0]],"id":41555107}],"con":true,"img":false}]}
{"op":"mcm","clk":"5323348038","pt":1646329820954,"mc":[{"id":"1.195532879","rc":[{"atb":[[1.95,3.14]],"id":41555107}],"con":true,"img":false}]}
{"op":"mcm","clk":"5323348049","pt":1646329821051,"mc":[{"id":"1.195532879","rc":[{"atb":[[2.08,0]],"id":38251452}],"con":true,"img":false}]}
{"op":"mcm","clk":"5323348149","pt":1646329821933,"mc":[{"id":"1.195532879","rc":[{"atb":[[1.94,10.54]],"id":41555107}],"con":true,"img":false}]}
{"op":"mcm","clk":"5323348158","pt":1646329822037,"mc":[{"id":"1.195532879","rc":[{"atb":[[1.96,1.99]],"id":41555107}],"con":true,"img":false}]}
{"op":"mcm","clk":"5323348277","pt":1646329823251,"mc":[{"id":"1.195532879","rc":[{"atb":[[1.97,11.3]],"id":40452329}],"con":true,"img":false}]}
{"op":"mcm","clk":"5323348289","pt":1646329823345,"mc":[{"id":"1.195532879","rc":[{"atl":[[10,0],[11,16.5]],"id":39059999}],"con":true,"img":false}]}
{"op":"mcm","clk":"5323348398","pt":1646329824178,"mc":[{"id":"1.195532879","rc":[{"atb":[[1.97,2.15]],"id":41555107},{"atb":[[2.3,2.15]],"id":39632625},{"atb":[[2.46,2.15]],"id":28753299}],"con":true,"img":false}]}
{"op":"mcm","clk":"5323348409","pt":1646329824278,"mc":[{"id":"1.195532879","rc":[{"atb":[[1.92,27.15]],"id":41555107},{"atb":[[1.79,0]],"id":39632625},{"atb":[[2.34,10.39]],"id":28753299}],"con":true,"img":false}]}
{"op":"mcm","clk":"5323348424","pt":1646329824341,"mc":[{"id":"1.195532879","rc":[{"atb":[[2.4,6.98],[2.46,4.31]],"id":28753299}],"con":true,"img":false}]}
{"op":"mcm","clk":"5323348451","pt":1646329824541,"mc":[{"id":"1.195532879","rc":[{"atb":[[2.24,7.5]],"id":39632625}],"con":true,"img":false}]}
{"op":"mcm","clk":"5323348460","pt":1646329824649,"mc":[{"id":"1.195532879","rc":[{"atb":[[2.32,1.99]],"id":39632625}],"con":true,"img":false}]}
{"op":"mcm","clk":"5323348472","pt":1646329824748,"mc":[{"id":"1.195532879","rc":[{"atb":[[2.4,4.99]],"id":28753299}],"con":true,"img":false}]}
{"op":"mcm","clk":"5323348484","pt":1646329824863,"mc":[{"id":"1.195532879","rc":[{"atb":[[2.48,1.99]],"id":28753299}],"con":true,"img":false}]}
{"op":"mcm","clk":"5323348502","pt":1646329825072,"mc":[{"id":"1.195532879","rc":[{"atb":[[1.96,0]],"id":41555107}],"con":true,"img":false}]}
{"op":"mcm","clk":"5323348524","pt":1646329825269,"mc":[{"id":"1.195532879","rc":[{"atb":[[1.98,1.99]],"id":41555107}],"con":true,"img":false}]}
{"op":"mcm","clk":"5323348573","pt":1646329825738,"mc":[{"id":"1.195532879","rc":[{"atl":[[11,12.5],[11.5,3.81]],"id":39059999}],"con":true,"img":false}]}
{"op":"mcm","clk":"5323348597","pt":1646329825971,"mc":[{"id":"1.195532879","rc":[{"atb":[[2.08,17.36]],"id":38251452}],"con":true,"img":false}]}
{"op":"mcm","clk":"5323348620","pt":1646329826180,"mc":[{"id":"1.195532879","rc":[{"atb":[[2.12,19.11],[2.14,2.5]],"id":38251452}],"con":true,"img":false}]}
{"op":"mcm","clk":"5323348642","pt":1646329826384,"mc":[{"id":"1.195532879","rc":[{"atb":[[1.98,4.15]],"id":41555107}],"con":true,"img":false}]}
{"op":"mcm","clk":"5323348652","pt":1646329826447,"mc":[{"id":"1.195532879","rc":[{"atb":[[1.92,17.58]],"id":41555107}],"con":true,"img":false}]}
{"op":"mcm","clk":"5323348803","pt":1646329828151,"mc":[{"id":"1.195532879","rc":[{"atb":[[2.26,0]],"id":39632625},{"atb":[[2.42,0]],"id":28753299}],"con":true,"img":false}]}
{"op":"mcm","clk":"5323348824","pt":1646329828364,"mc":[{"id":"1.195532879","rc":[{"atb":[[2.34,1.65]],"id":39632625},{"atb":[[2.5,1.65]],"id":28753299}],"con":true,"img":false}]}
{"op":"mcm","clk":"5323348841","pt":1646329828567,"mc":[{"id":"1.195532879","rc":[{"atb":[[1.81,185.19]],"id":41555107},{"atl":[[4.6,38.89]],"id":41555107},{"atb":[[1.72,208.33]],"id":40452329},{"atb":[[1.89,168.54]],"id":38251452},{"atl":[[5,25]],"id":38251452},{"atb":[[1.81,185.19]],"id":39632625},{"atl":[[11,2.5],[11.5,13.33]],"id":39059999},{"atb":[[2.12,133.93]],"id":28753299}],"con":true,"img":false}]}
{"op":"mcm","clk":"5323348872","pt":1646329828876,"mc":[{"id":"1.195532879","rc":[{"atb":[[1.95,0]],"id":41555107},{"atb":[[1.98,9.91]],"id":40452329}],"con":true,"img":false}]}
{"op":"mcm","clk":"5323348904","pt":1646329829249,"mc":[{"id":"1.195532879","rc":[{"atl":[[10,0]],"id":41555107},{"atb":[[1.63,0],[1.61,0]],"id":40452329},{"atb":[[1.69,0]],"id":38251452},{"atl":[[5,30.13]],"id":38251452},{"atb":[[1.92,0]],"id":28753299}],"con":true,"img":false}]}
{"op":"mcm","clk":"5323348974","pt":1646329829975,"mc":[{"id":"1.195532879","rc":[{"atl":[[5,25]],"id":38251452}],"con":true,"img":false}]}
{"op":"mcm","clk":"5323349112","pt":1646329831277,"mc":[{"id":"1.195532879","rc":[{"atb":[[2.08,0]],"id":38251452}],"con":true,"img":false}]}
{"op":"mcm","clk":"5323349242","pt":1646329832463,"mc":[{"id":"1.195532879","rc":[{"atb":[[2.5,3.65],[2.46,2.15]],"id":28753299}],"con":true,"img":false}]}
{"op":"mcm","clk":"5323349250","pt":1646329832570,"mc":[{"id":"1.195532879","rc":[{"atb":[[2.5,1.65],[2.48,6.31]],"id":28753299}],"con":true,"img":false}]}
{"op":"mcm","clk":"5323349386","pt":1646329834179,"mc":[{"id":"1.195532879","rc":[{"atb":[[1.95,4.56]],"id":41555107}],"con":true,"img":false}]}
{"op":"mcm","clk":"5323349440","pt":1646329834750,"mc":[{"id":"1.195532879","rc":[{"atb":[[2.12,16.96],[2.26,2.15]],"id":38251452},{"atb":[[2.36,4.13]],"id":28753299}],"con":true,"img":false}]}
{"op":"mcm","clk":"5323349451","pt":1646329834860,"mc":[{"id":"1.195532879","rc":[{"atb":[[2.24,4.32]],"id":38251452}],"con":true,"img":false}]}
{"op":"mcm","clk":"5323349463","pt":1646329834958,"mc":[{"id":"1.195532879","rc":[{"atb":[[1.86,9.73]],"id":41555107},{"atb":[[2.2,5.37]],"id":38251452},{"atb":[[2.48,11.93],[2.34,0],[2.4,17.47]],"id":28753299},{"atl":[[7.2,21.13],[6.6,27.1]],"id":28753299}],"con":true,"img":false}]}
{"op":"mcm","clk":"5323349473","pt":1646329835062,"mc":[{"id":"1.195532879","rc":[{"atb":[[2.2,3.38]],"id":38251452},{"atl":[[5.4,3.32]],"id":39632625},{"atb":[[2.4,12.48]],"id":28753299},{"atl":[[6.4,12.5]],"id":28753299}],"con":true,"img":false}]}
{"op":"mcm","clk":"5323349489","pt":1646329835164,"mc":[{"id":"1.195532879","rc":[{"atb":[[1.86,0]],"id":41555107},{"atb":[[2.12,0],[1.02,1.99],[2.2,13]],"id":38251452},{"atl":[[4.8,25.93]],"id":38251452},{"atb":[[2.36,0]],"id":28753299},{"atl":[[6.8,0]],"id":28753299}],"con":true,"img":false}]}
{"op":"mcm","clk":"5323349501","pt":1646329835273,"mc":[{"id":"1.195532879","rc":[{"atb":[[1.92,0],[1.98,15.47],[1.95,23.43]],"id":41555107},{"atl":[[4.8,31.32],[4.6,69.09],[4.1,11.32]],"id":41555107},{"atb":[[1.98,27.9],[1.97,0]],"id":40452329},{"atl":[[5,30],[4.4,7.52],[4.7,39.59]],"id":40452329},{"atb":[[2.26,6.56]],"id":38251452},{"atl":[[4.9,10.26],[4.7,23.02]],"id":38251452},{"atb":[[2.24,21.44],[2.32,5.49],[2.14,5]],"id":39632625},{"atl":[[4.8,3.5],[5.5,27.22],[5.2,31.82]],"id":39632625},{"atl":[[11.5,35.07],[13,13.33]],"id":39059999}],"con":true,"img":false}]}
{"op":"mcm","clk":"5323349511","pt":1646329835376,"mc":[{"id":"1.195532879","rc":[{"atl":[[5.1,29.39]],"id":38251452},{"atl":[[7,4.23]],"id":28753299}],"con":true,"img":false}]}
{"op":"mcm","clk":"5323349524","pt":1646329835483,"mc":[{"id":"1.195532879","rc":[{"atb":[[1.98,13.31],[1.97,10.45],[1.94,0]],"id":41555107},{"atl":[[4.6,57.98],[4.4,43.67],[4.2,0]],"id":41555107},{"atl":[[4.8,0],[4.5,0],[4.6,13.24]],"id":40452329},{"atb":[[2.2,9.62]],"id":38251452},{"atl":[[4.8,50.93],[4.7,2.5]],"id":38251452},{"atb":[[2.24,13.94]],"id":39632625},{"atl":[[5.1,17.5],[5,0],[5.3,0]],"id":39632625}],"con":true,"img":false}]}
{"op":"mcm","clk":"5323349553","pt":1646329835789,"mc":[{"id":"1.195532879","rc":[{"atl":[[5.4,0]],"id":39632625},{"atb":[[2.92,78.12]],"id":39059999}],"con":true,"img":false}]}
{"op":"mcm","clk":"5323349571","pt":1646329835957,"mc":[{"id":"1.195532879","rc":[{"atl":[[7,0]],"id":28753299}],"con":true,"img":false}]}
{"op":"mcm","clk":"5323349590","pt":1646329836178,"mc":[{"id":"1.195532879","rc":[{"atl":[[4.3,12.12],[4.4,31.91]],"id":41555107},{"atl":[[4.6,24.35],[4.7,28.78]],"id":40452329},{"atb":[[2.22,10.15],[2.2,0]],"id":39632625},{"atl":[[5,10],[5.2,22.3]],"id":39632625}],"con":true,"img":false}]}
{"op":"mcm","clk":"5323349632","pt":1646329836553,"mc":[{"id":"1.195532879","rc":[{"atl":[[4.8,5.41]],"id":40452329},{"atb":[[2.16,4.83]],"id":38251452}],"con":true,"img":false}]}
{"op":"mcm","clk":"5323349662","pt":1646329836967,"mc":[{"id":"1.195532879","rc":[{"atb":[[2.22,10.33]],"id":38251452}],"con":true,"img":false}]}
{"op":"mcm","clk":"5323349791","pt":1646329838055,"mc":[{"id":"1.195532879","rc":[{"atb":[[2.16,0]],"id":38251452}],"con":true,"img":false}]}
{"op":"mcm","clk":"5323349798","pt":1646329838155,"mc":[{"id":"1.195532879","rc":[{"atl":[[4.8,0]],"id":40452329}],"con":true,"img":false}]}
{"op":"mcm","clk":"5323349840","pt":1646329838574,"mc":[{"id":"1.195532879","rc":[{"atb":[[1.87,250]],"id":38251452},{"atl":[[5.2,35.71]],"id":38251452},{"atb":[[2.08,231.48]],"id":28753299}],"con":true,"img":false}]}
{"op":"mcm","clk":"5323349902","pt":1646329839185,"mc":[{"id":"1.195532879","rc":[{"atb":[[2.22,8.68]],"id":38251452}],"con":true,"img":false}]}
{"op":"mcm","clk":"5323349913","pt":1646329839289,"mc":[{"id":"1.195532879","rc":[{"atb":[[1.95,33.81]],"id":41555107},{"atb":[[2.04,15.18]],"id":40452329},{"atb":[[2.22,27.27]],"id":38251452},{"atb":[[2.26,9.12]],"id":39632625},{"atb":[[3.45,19.3]],"id":39059999},{"atb":[[2.42,19.92]],"id":28753299}],"con":true,"img":false}]}
{"op":"mcm","clk":"5323349923","pt":1646329839345,"mc":[{"id":"1.195532879","rc":[{"atb":[[2.28,1.65]],"id":38251452}],"con":true,"img":false}]}
{"op":"mcm","clk":"5323349935","pt":1646329839459,"mc":[{"id":"1.195532879","rc":[{"atb":[[1.95,29.25]],"id":41555107},{"atb":[[1.98,17.99],[2.06,17.03]],"id":40452329},{"atb":[[3.2,5],[3.4,22.74],[3.05,3.12]],"id":39059999}],"con":true,"img":false}]}
{"op":"mcm","clk":"5323349945","pt":1646329839553,"mc":[{"id":"1.195532879","rc":[{"atb":[[2.02,1.99]],"id":40452329}],"con":true,"img":false}]}
{"op":"mcm","clk":"5323349962","pt":1646329839761,"mc":[{"id":"1.195532879","rc":[{"atb":[[2.02,0]],"id":40452329},{"atb":[[3.05,0]],"id":39059999}],"con":true,"img":false}]}
{"op":"mcm","clk":"5323349971","pt":1646329839874,"mc":[{"id":"1.195532879","rc":[{"atb":[[2.06,19.02]],"id":40452329}],"con":true,"img":false}]}
{"op":"mcm","clk":"5323350008","pt":1646329840280,"mc":[{"id":"1.195532879","rc":[{"atl":[[6.4,2.5],[6.6,44.96]],"id":28753299}],"con":true,"img":false}]}
{"op":"mcm","clk":"5323350050","pt":1646329840691,"mc":[{"id":"1.195532879","rc":[{"atl":[[4.6,13.61],[4.7,55.81]],"id":40452329}],"con":true,"img":false}]}
{"op":"mcm","clk":"5323350154","pt":1646329841688,"mc":[{"id":"1.195532879","rc":[{"atb":[[2.22,18.59]],"id":38251452}],"con":true,"img":false}]}
{"op":"mcm","clk":"5323350301","pt":1646329843091,"mc":[{"id":"1.195532879","rc":[{"atb":[[1.73,0]],"id":38251452},{"atl":[[5.1,5],[4.9,0]],"id":38251452},{"atb":[[2,0]],"id":28753299}],"con":true,"img":false}]}
{"op":"mcm","clk":"5323350311","pt":1646329843183,"mc":[{"id":"1.195532879","rc":[{"atb":[[2.22,34.28],[2.2,0]],"id":38251452}],"con":true,"img":false}]}
{"op":"mcm","clk":"5323350454","pt":1646329844693,"mc":[{"id":"1.195532879","rc":[{"atb":[[1.99,9.31]],"id":41555107},{"atb":[[2.08,13.31]],"id":40452329}],"con":true,"img":false}]}
{"op":"mcm","clk":"5323350477","pt":1646329844891,"mc":[{"id":"1.195532879","rc":[{"atb":[[2,10.46],[1.97,2.15]],"id":41555107}],"con":true,"img":false}]}
{"op":"mcm","clk":"5323350489","pt":1646329844997,"mc":[{"id":"1.195532879","rc":[{"atb":[[1.93,7.14]],"id":41555107}],"con":true,"img":false}]}
{"op":"mcm","clk":"5323350529","pt":1646329845369,"mc":[{"id":"1.195532879","rc":[{"atb":[[2.06,2.15],[1.97,0]],"id":41555107},{"atb":[[2,2.5],[2.14,2.15]],"id":40452329},{"atb":[[2.54,2.15],[2.46,0]],"id":28753299}],"con":true,"img":false}]}
{"op":"mcm","clk":"5323350550","pt":1646329845462,"mc":[{"id":"1.195532879","rc":[{"atb":[[2.06,17.03]],"id":40452329},{"atb":[[2.54,4.31],[2.48,7.61]],"id":28753299}],"con":true,"img":false}]}
{"op":"mcm","clk":"5323350560","pt":1646329845573,"mc":[{"id":"1.195532879","rc":[{"atb":[[2.1,1.99]],"id":40452329},{"atb":[[2.54,2.15],[2.5,13.58]],"id":28753299}],"con":true,"img":false}]}
{"op":"mcm","clk":"5323350577","pt":1646329845780,"mc":[{"id":"1.195532879","rc":[{"atb":[[1.98,11.32]],"id":41555107},{"atb":[[2.88,132.98]],"id":39059999}],"con":true,"img":false}]}
{"op":"mcm","clk":"5323350591","pt":1646329845886,"mc":[{"id":"1.195532879","rc":[{"atb":[[2.02,1.99]],"id":41555107}],"con":true,"img":false}]}
{"op":"mcm","clk":"5323350620","pt":1646329846190,"mc":[{"id":"1.195532879","rc":[{"atb":[[1.93,2.5],[1.79,250]],"id":41555107},{"atb":[[1.7,250]],"id":40452329},{"atl":[[4.8,26.32]],"id":40452329},{"atb":[[1.79,250]],"id":39632625},{"atl":[[5.2,46.11]],"id":39632625}],"con":true,"img":false}]}
{"op":"mcm","clk":"5323350666","pt":1646329846667,"mc":[{"id":"1.195532879","rc":[{"atb":[[2.48,5.62]],"id":28753299}],"con":true,"img":false}]}
{"op":"mcm","clk":"5323350677","pt":1646329846775,"mc":[{"id":"1.195532879","rc":[{"atb":[[2.56,1.99]],"id":28753299}],"con":true,"img":false}]}
{"op":"mcm","clk":"5323350686","pt":1646329846875,"mc":[{"id":"1.195532879","rc":[{"atb":[[1.95,18.87]],"id":41555107},{"atb":[[2.04,1.65]],"id":40452329},{"atb":[[2.22,15.69]],"id":38251452}],"con":true,"img":false}]}
{"op":"mcm","clk":"5323350698","pt":1646329846984,"mc":[{"id":"1.195532879","rc":[{"atb":[[2.1,0]],"id":40452329},{"atb":[[2.44,3.27]],"id":28753299}],"con":true,"img":false}]}
{"op":"mcm","clk":"5323350707","pt":1646329847078,"mc":[{"id":"1.195532879","rc":[{"atb":[[2.16,1.99]],"id":40452329}],"con":true,"img":false}]}
{"op":"mcm","clk":"5323350729","pt":1646329847286,"mc":[{"id":"1.195532879","rc":[{"atb":[[2.02,0]],"id":41555107},{"atb":[[2.28,7.41]],"id":38251452}],"con":true,"img":false}]}
{"op":"mcm","clk":"5323350741","pt":1646329847389,"mc":[{"id":"1.195532879","rc":[{"atb":[[2.08,1.99]],"id":41555107}],"con":true,"img":false}]}
{"op":"mcm","clk":"5323350852","pt":1646329848274,"mc":[{"id":"1.195532879","rc":[{"atb":[[2.44,0]],"id":28753299}],"con":true,"img":false}]}
{"op":"mcm","clk":"5323350891","pt":1646329848585,"mc":[{"id":"1.195532879","rc":[{"atl":[[5.4,56.82]],"id":38251452}],"con":true,"img":false}]}
{"op":"mcm","clk":"5323350930","pt":1646329848911,"mc":[{"id":"1.195532879","rc":[{"atl":[[8.4,0]],"id":40452329},{"atl":[[10.5,0],[5.5,5],[9.8,0]],"id":39632625}],"con":true,"img":false}]}
{"op":"mcm","clk":"5323350997","pt":1646329849579,"mc":[{"id":"1.195532879","rc":[{"atb":[[2.42,0]],"id":28753299}],"con":true,"img":false}]}
{"op":"mcm","clk":"5323351034","pt":1646329849989,"mc":[{"id":"1.195532879","rc":[{"atb":[[1.99,0]],"id":41555107},{"atb":[[2.08,0]],"id":40452329}],"con":true,"img":false}]}
{"op":"mcm","clk":"5323351048","pt":1646329850092,"mc":[{"id":"1.195532879","rc":[{"atb":[[2.04,0]],"id":40452329},{"atb":[[2.5,11.93]],"id":28753299}],"con":true,"img":false}]}
{"op":"mcm","clk":"5323351060","pt":1646329850196,"mc":[{"id":"1.195532879","rc":[{"atb":[[2.1,1.65]],"id":41555107},{"atb":[[2.18,1.65]],"id":40452329},{"atb":[[2.58,1.65]],"id":28753299}],"con":true,"img":false}]}
{"op":"mcm","clk":"5323351203","pt":1646329851801,"mc":[{"id":"1.195532879","rc":[{"atb":[[2.5,22.73],[2.56,5.49]],"id":28753299}],"con":true,"img":false}]}
{"op":"mcm","clk":"5323351214","pt":1646329851903,"mc":[{"id":"1.195532879","rc":[{"atb":[[2.4,0]],"id":28753299}],"con":true,"img":false}]}
{"op":"mcm","clk":"5323351224","pt":1646329852006,"mc":[{"id":"1.195532879","rc":[{"atb":[[2.24,17.93]],"id":38251452},{"atb":[[2.48,0]],"id":28753299}],"con":true,"img":false}]}
{"op":"mcm","clk":"5323351234","pt":1646329852112,"mc":[{"id":"1.195532879","rc":[{"atb":[[2,37.68],[1.95,0],[2.08,12.1]],"id":41555107},{"atl":[[4.6,27.78],[4.4,75.47]],"id":41555107},{"atb":[[1.98,0],[2.06,43.44]],"id":40452329},{"atb":[[2.22,0]],"id":38251452},{"atb":[[2.26,29.47]],"id":39632625},{"atl":[[5.1,50.06],[5.2,23.81]],"id":39632625}],"con":true,"img":false}]}
{"op":"mcm","clk":"5323351246","pt":1646329852173,"mc":[{"id":"1.195532879","rc":[{"atb":[[2.28,15.58]],"id":38251452},{"atb":[[2.24,0]],"id":39632625}],"con":true,"img":false}]}
{"op":"mcm","clk":"5323351259","pt":1646329852381,"mc":[{"id":"1.195532879","rc":[{"atb":[[1.98,0]],"id":41555107},{"atb":[[2.26,2.15]],"id":38251452}],"con":true,"img":false}]}
{"op":"mcm","clk":"5323351301","pt":1646329852798,"mc":[{"id":"1.195532879","rc":[{"atb":[[2,27.22],[2.04,5]],"id":41555107}],"con":true,"img":false}]}
{"op":"mcm","clk":"5323351378","pt":1646329853518,"mc":[{"id":"1.195532879","rc":[{"atb":[[2.5,10.8],[2.58,3.81]],"id":28753299}],"con":true,"img":false}]}
{"op":"mcm","clk":"5323351390","pt":1646329853574,"mc":[{"id":"1.195532879","rc":[{"atb":[[2.56,10.98],[2.58,1.65]],"id":28753299}],"con":true,"img":false}]}
{"op":"mcm","clk":"5323351430","pt":1646329853988,"mc":[{"id":"1.195532879","rc":[{"atb":[[2.08,18.32]],"id":41555107},{"atb":[[2.16,8.21]],"id":40452329},{"atb":[[2.3,11.12]],"id":38251452}],"con":true,"img":false}]}
{"op":"mcm","clk":"5323351578","pt":1646329855229,"mc":[{"id":"1.195532879","rc":[{"atb":[[2.02,4.01]],"id":41555107},{"atb":[[2.02,5.47]],"id":40452329}],"con":true,"img":false}]}
{"op":"mcm","clk":"5323351648","pt":1646329855959,"mc":[{"id":"1.195532879","rc":[{"atb":[[2.14,2.15],[2.06,0]],"id":41555107},{"atb":[[2.26,0],[2.36,2.15]],"id":38251452}],"con":true,"img":false}]}
{"op":"mcm","clk":"5323351672","pt":1646329856166,"mc":[{"id":"1.195532879","rc":[{"atl":[[5,42.5]],"id":40452329},{"atl":[[5.4,34.09]],"id":39632625}],"con":true,"img":false}]}
{"op":"mcm","clk":"5323351769","pt":1646329857047,"mc":[{"id":"1.195532879","rc":[{"atb":[[2.26,20.35]],"id":39632625},{"atb":[[2.4,33.78]],"id":28753299}],"con":true,"img":false}]}
{"op":"mcm","clk":"5323351818","pt":1646329857566,"mc":[{"id":"1.195532879","rc":[{"atb":[[2.28,9.82]],"id":38251452}],"con":true,"img":false}]}
{"op":"mcm","clk":"5323351830","pt":1646329857674,"mc":[{"id":"1.195532879","rc":[{"atb":[[2.08,16.33]],"id":41555107}],"con":true,"img":false}]}
{"op":"mcm","clk":"5323351843","pt":1646329857769,"mc":[{"id":"1.195532879","rc":[{"atb":[[1.02,1.99]],"id":41555107}],"con":true,"img":false}]}
{"op":"mcm","clk":"5323352057","pt":1646329859864,"mc":[{"id":"1.195532879","rc":[{"atb":[[2.24,4.32],[2.28,26.33]],"id":38251452}],"con":true,"img":false}]}
{"op":"mcm","clk":"5323352082","pt":1646329860071,"mc":[{"id":"1.195532879","rc":[{"atb":[[2.02,0]],"id":41555107}],"con":true,"img":false}]}
{"op":"mcm","clk":"5323352091","pt":1646329860170,"mc":[{"id":"1.195532879","rc":[{"atb":[[2.08,10.11]],"id":41555107}],"con":true,"img":false}]}
{"op":"mcm","clk":"5323352209","pt":1646329861263,"mc":[{"id":"1.195532879","rc":[{"atb":[[2.1,0]],"id":41555107},{"atb":[[2.28,24.68]],"id":38251452}],"con":true,"img":false}]}
{"op":"mcm","clk":"5323352233","pt":1646329861471,"mc":[{"id":"1.195532879","rc":[{"atb":[[2.16,1.65]],"id":41555107},{"atb":[[2.38,1.65]],"id":38251452}],"con":true,"img":false}]}
{"op":"mcm","clk":"5323352346","pt":1646329862568,"mc":[{"id":"1.195532879","rc":[{"atb":[[2.32,9.29]],"id":38251452}],"con":true,"img":false}]}
{"op":"mcm","clk":"5323352469","pt":1646329863559,"mc":[{"id":"1.195532879","rc":[{"atb":[[2.28,16.09]],"id":39632625}],"con":true,"img":false}]}
{"op":"mcm","clk":"5323352684","pt":1646329865478,"mc":[{"id":"1.195532879","rc":[{"atb":[[2.1,3.81]],"id":41555107}],"con":true,"img":false}]}
{"op":"mcm","clk":"5323352762","pt":1646329866151,"mc":[{"id":"1.195532879","rc":[{"atl":[[5.2,59.52]],"id":40452329},{"atl":[[5.6,54.35]],"id":39632625}],"con":true,"img":false}]}
{"op":"mcm","clk":"5323352790","pt":1646329866362,"mc":[{"id":"1.195532879","rc":[{"atl":[[4.3,14.62]],"id":41555107},{"atl":[[8,0]],"id":40452329}],"con":true,"img":false}]}
{"op":"mcm","clk":"5323352801","pt":1646329866463,"mc":[{"id":"1.195532879","rc":[{"atl":[[4.8,26.32],[5.2,0],[4.4,72.97]],"id":41555107},{"atb":[[2.14,0],[1.99,0],[2.06,0]],"id":38251452},{"atb":[[2.54,0],[2.62,2.15]],"id":28753299}],"con":true,"img":false}]}
{"op":"mcm","clk":"5323352826","pt":1646329866673,"mc":[{"id":"1.195532879","rc":[{"atb":[[2.58,12.45],[2.56,5.49]],"id":28753299}],"con":true,"img":false}]}
{"op":"mcm","clk":"5323352846","pt":1646329866883,"mc":[{"id":"1.195532879","rc":[{"atb":[[2.1,12.39]],"id":41555107},{"atb":[[2.3,0]],"id":38251452},{"atl":[[5.1,54.74]],"id":39632625}],"con":true,"img":false}]}
{"op":"mcm","clk":"5323352867","pt":1646329867091,"mc":[{"id":"1.195532879","rc":[{"atl":[[5.1,53.24]],"id":39632625},{"atb":[[2.56,3.5]],"id":28753299}],"con":true,"img":false}]}
{"op":"mcm","clk":"5323352879","pt":1646329867143,"mc":[{"id":"1.195532879","rc":[{"atb":[[2.64,1.99]],"id":28753299}],"con":true,"img":false}]}
{"op":"mcm","clk":"5323352900","pt":1646329867352,"mc":[{"id":"1.195532879","rc":[{"atl":[[5.1,50.06]],"id":39632625}],"con":true,"img":false}]}
{"op":"mcm","clk":"5323352970","pt":1646329867974,"mc":[{"id":"1.195532879","rc":[{"atb":[[2.32,0]],"id":38251452}],"con":true,"img":false}]}
{"op":"mcm","clk":"5323352986","pt":1646329868183,"mc":[{"id":"1.195532879","rc":[{"atb":[[2.24,14.5],[2.28,8.16]],"id":38251452}],"con":true,"img":false}]}
{"op":"mcm","clk":"5323352999","pt":1646329868235,"mc":[{"id":"1.195532879","rc":[{"atb":[[2.5,0],[2.62,7.77],[2.56,14.92]],"id":28753299}],"con":true,"img":false}]}
{"op":"mcm","clk":"5323353021","pt":1646329868442,"mc":[{"id":"1.195532879","rc":[{"atb":[[2.56,11.42]],"id":28753299}],"con":true,"img":false}]}
{"op":"mcm","clk":"5323353031","pt":1646329868544,"mc":[{"id":"1.195532879","rc":[{"atb":[[2,0],[2.14,19.94],[2.08,39.76]],"id":41555107},{"atb":[[2.26,0],[2.28,37.53]],"id":39632625}],"con":true,"img":false}]}
{"op":"mcm","clk":"5323353043","pt":1646329868649,"mc":[{"id":"1.195532879","rc":[{"atb":[[2.08,29.65]],"id":41555107},{"atb":[[2.36,6.56]],"id":38251452}],"con":true,"img":false}]}
{"op":"mcm","clk":"5323353067","pt":1646329868856,"mc":[{"id":"1.195532879","rc":[{"atb":[[2.28,0]],"id":38251452}],"con":true,"img":false}]}
{"op":"mcm","clk":"5323353078","pt":1646329868961,"mc":[{"id":"1.195532879","rc":[{"spn":3.13,"spf":"NaN","id":41555107},{"spn":2.18,"spf":1.0,"id":40452329},{"atb":[[2,10],[2.16,2.5],[2.08,5]],"id":38251452},{"spn":3.49,"spf":"NaN","id":38251452},{"spn":2.32,"spf":1.0,"id":39632625},{"spn":7.05,"spf":"NaN","id":39059999},{"spn":4.42,"spf":"NaN","id":28753299}],"con":true,"img":false}]}
{"op":"mcm","clk":"5323353167","pt":1646329869845,"mc":[{"id":"1.195532879","rc":[{"atb":[[2.4,0]],"id":28753299}],"con":true,"img":false}]}
{"op":"mcm","clk":"5323353293","pt":1646329871141,"mc":[{"id":"1.195532879","rc":[{"atb":[[2.58,10.8]],"id":28753299}],"con":true,"img":false}]}
{"op":"mcm","clk":"5323353302","pt":1646329871247,"mc":[{"id":"1.195532879","rc":[{"atb":[[2.66,1.65]],"id":28753299}],"con":true,"img":false}]}
{"op":"mcm","clk":"5323353357","pt":1646329871895,"mc":[{"id":"1.195532879","rc":[{"atl":[[5.1,47.56],[5,12.5],[5.5,0],[5.9,0]],"id":39632625}],"con":true,"img":false}]}
{"op":"mcm","clk":"5323353493","pt":1646329873251,"mc":[{"id":"1.195532879","rc":[{"atb":[[2.18,32.89]],"id":38251452},{"atb":[[2.28,21.44]],"id":39632625}],"con":true,"img":false}]}
{"op":"mcm","clk":"5323353502","pt":1646329873363,"mc":[{"id":"1.195532879","rc":[{"atb":[[2.24,8.58]],"id":39632625}],"con":true,"img":false}]}
{"op":"mcm","clk":"5323353744","pt":1646329875855,"mc":[{"id":"1.195532879","rc":[{"atb":[[2.24,4.32],[2.18,61.3]],"id":38251452}],"con":true,"img":false}]}
{"op":"mcm","clk":"5323353838","pt":1646329876579,"mc":[{"id":"1.195532879","rc":[{"atb":[[2.66,7.13]],"id":28753299}],"con":true,"img":false}]}
{"op":"mcm","clk":"5323353883","pt":1646329877065,"mc":[{"id":"1.195532879","rc":[{"atb":[[2.64,0]],"id":28753299},{"atl":[[8,0],[7.2,16.13],[6.4,0],[6.2,7.49],[7,5]],"id":28753299}],"con":true,"img":false}]}
{"op":"mcm","clk":"5323353896","pt":1646329877152,"mc":[{"id":"1.195532879","rc":[{"atb":[[2.36,12.18]],"id":38251452},{"atb":[[2.68,1.99]],"id":28753299},{"atl":[[6.6,25],[7,35.54]],"id":28753299}],"con":true,"img":false}]}
{"op":"mcm","clk":"5323353909","pt":1646329877266,"mc":[{"id":"1.195532879","rc":[{"atl":[[6.6,10.89],[7,52.21]],"id":28753299}],"con":true,"img":false}]}
{"op":"mcm","clk":"5323353958","pt":1646329877678,"mc":[{"id":"1.195532879","rc":[{"atb":[[2.36,6.56]],"id":38251452},{"atl":[[6.6,7.14]],"id":28753299}],"con":true,"img":false}]}
{"op":"mcm","clk":"5323353979","pt":1646329877883,"mc":[{"id":"1.195532879","rc":[{"atb":[[1.93,8.38]],"id":41555107},{"atb":[[2.14,3.1]],"id":38251452}],"con":true,"img":false}]}
{"op":"mcm","clk":"5323353989","pt":1646329877987,"mc":[{"id":"1.195532879","rc":[{"atb":[[1.93,2.5]],"id":41555107}],"con":true,"img":false}]}
{"op":"mcm","clk":"5323354040","pt":1646329878465,"mc":[{"id":"1.195532879","rc":[{"atb":[[2.14,0]],"id":38251452}],"con":true,"img":false}]}
{"op":"mcm","clk":"5323354182","pt":1646329879964,"mc":[{"id":"1.195532879","rc":[{"atb":[[2.34,12.38]],"id":39632625}],"con":true,"img":false}]}
{"op":"mcm","clk":"5323354196","pt":1646329880071,"mc":[{"id":"1.195532879","rc":[{"atb":[[2.36,13.4]],"id":39632625}],"con":true,"img":false}]}
{"op":"mcm","clk":"5323354205","pt":1646329880184,"mc":[{"id":"1.195532879","rc":[{"atb":[[2.3,0],[2.4,2.15]],"id":39632625}],"con":true,"img":false}]}
{"op":"mcm","clk":"5323354215","pt":1646329880277,"mc":[{"id":"1.195532879","rc":[{"atb":[[2.32,1.99]],"id":39632625}],"con":true,"img":false}]}
{"op":"mcm","clk":"5323354227","pt":1646329880381,"mc":[{"id":"1.195532879","rc":[{"atb":[[2.32,0],[2.28,25.03]],"id":39632625}],"con":true,"img":false}]}
{"op":"mcm","clk":"5323354236","pt":1646329880483,"mc":[{"id":"1.195532879","rc":[{"atb":[[2.36,15.39]],"id":39632625}],"con":true,"img":false}]}
{"op":"mcm","clk":"5323354278","pt":1646329880953,"mc":[{"id":"1.195532879","rc":[{"atb":[[2.28,21.44]],"id":39632625}],"con":true,"img":false}]}
{"op":"mcm","clk":"5323354315","pt":1646329881373,"mc":[{"id":"1.195532879","rc":[{"atb":[[2.36,13.4]],"id":39632625}],"con":true,"img":false}]}
{"op":"mcm","clk":"5323354327","pt":1646329881466,"mc":[{"id":"1.195532879","rc":[{"atb":[[2.42,1.99]],"id":39632625}],"con":true,"img":false}]}
{"op":"mcm","clk":"5323354391","pt":1646329882192,"mc":[{"id":"1.195532879","rc":[{"atb":[[2.34,10.72]],"id":39632625},{"atb":[[2.66,5.47]],"id":28753299}],"con":true,"img":false}]}
{"op":"mcm","clk":"5323354411","pt":1646329882397,"mc":[{"id":"1.195532879","rc":[{"atb":[[2.7,1.65]],"id":28753299}],"con":true,"img":false}]}
{"op":"mcm","clk":"5323354430","pt":1646329882553,"mc":[{"id":"1.195532879","rc":[{"atb":[[2.24,0]],"id":39632625}],"con":true,"img":false}]}
{"op":"mcm","clk":"5323354591","pt":1646329884162,"mc":[{"id":"1.195532879","rc":[{"atb":[[2.62,13.65]],"id":28753299}],"con":true,"img":false}]}
{"op":"mcm","clk":"5323354609","pt":1646329884372,"mc":[{"id":"1.195532879","rc":[{"atb":[[2.56,0],[2.68,11.45]],"id":28753299}],"con":true,"img":false}]}
{"op":"mcm","clk":"5323354619","pt":1646329884472,"mc":[{"id":"1.195532879","rc":[{"atb":[[2.62,26.32]],"id":28753299}],"con":true,"img":false}]}
{"op":"mcm","clk":"5323354641","pt":1646329884691,"mc":[{"id":"1.195532879","rc":[{"atb":[[2.28,0]],"id":39632625},{"atb":[[2.62,20.44]],"id":28753299}],"con":true,"img":false}]}
{"op":"mcm","clk":"5323354652","pt":1646329884789,"mc":[{"id":"1.195532879","rc":[{"atb":[[2.12,4.31]],"id":41555107},{"atb":[[2.34,39.76]],"id":39632625}],"con":true,"img":false}]}
{"op":"mcm","clk":"5323354673","pt":1646329884996,"mc":[{"id":"1.195532879","rc":[{"atb":[[2.1,46.17],[2.08,0]],"id":41555107}],"con":true,"img":false}]}
{"op":"mcm","clk":"5323354697","pt":1646329885205,"mc":[{"id":"1.195532879","rc":[{"atb":[[2.12,0]],"id":41555107}],"con":true,"img":false}]}
{"op":"mcm","clk":"5323354745","pt":1646329885567,"mc":[{"id":"1.195532879","rc":[{"atb":[[2.34,29.04]],"id":39632625},{"atb":[[2.66,0]],"id":28753299}],"con":true,"img":false}]}
{"op":"mcm","clk":"5323354934","pt":1646329887487,"mc":[{"id":"1.195532879","rc":[{"atb":[[2.2,13.15]],"id":38251452}],"con":true,"img":false}]}
{"op":"mcm","clk":"5323354948","pt":1646329887592,"mc":[{"id":"1.195532879","rc":[{"atb":[[2.2,28.84]],"id":38251452}],"con":true,"img":false}]}
{"op":"mcm","clk":"5323354959","pt":1646329887695,"mc":[{"id":"1.195532879","rc":[{"atb":[[2.18,32.89]],"id":38251452}],"con":true,"img":false}]}
{"op":"mcm","clk":"5323355026","pt":1646329888470,"mc":[{"id":"1.195532879","rc":[{"atb":[[2.1,37.59]],"id":41555107}],"con":true,"img":false}]}
{"op":"mcm","clk":"5323355179","pt":1646329889977,"mc":[{"id":"1.195532879","rc":[{"atb":[[2.1,33.78]],"id":41555107}],"con":true,"img":false}]}
{"op":"mcm","clk":"5323355385","pt":1646329892010,"mc":[{"id":"1.195532879","rc":[{"atb":[[2.58,40.69],[2.62,2.15]],"id":28753299}],"con":true,"img":false}]}
{"op":"mcm","clk":"5323355411","pt":1646329892272,"mc":[{"id":"1.195532879","rc":[{"atb":[[2.18,0]],"id":38251452}],"con":true,"img":false}]}
{"op":"mcm","clk":"5323355420","pt":1646329892373,"mc":[{"id":"1.195532879","rc":[{"atb":[[2.42,8.21]],"id":39632625},{"atb":[[2.64,28.84]],"id":28753299}],"con":true,"img":false}]}
{"op":"mcm","clk":"5323355429","pt":1646329892484,"mc":[{"id":"1.195532879","rc":[{"atb":[[2.04,50.29],[2.1,0]],"id":41555107}],"con":true,"img":false}]}
{"op":"mcm","clk":"5323355661","pt":1646329894790,"mc":[{"id":"1.195532879","rc":[{"atb":[[2.06,25.92]],"id":41555107}],"con":true,"img":false}]}
{"op":"mcm","clk":"5323355737","pt":1646329895375,"mc":[{"id":"1.195532879","rc":[{"atb":[[2.06,70.54]],"id":41555107}],"con":true,"img":false}]}
{"op":"mcm","clk":"5323356125","pt":1646329898989,"mc":[{"id":"1.195532879","rc":[{"atb":[[2.26,24.66]],"id":38251452}],"con":true,"img":false}]}
{"op":"mcm","clk":"5323356139","pt":1646329899096,"mc":[{"id":"1.195532879","rc":[{"atb":[[2.24,20.01]],"id":38251452}],"con":true,"img":false}]}
{"op":"mcm","clk":"5323356154","pt":1646329899201,"mc":[{"id":"1.195532879","rc":[{"atb":[[2.2,13.15]],"id":38251452}],"con":true,"img":false}]}
{"op":"mcm","clk":"5323356282","pt":1646329900400,"mc":[{"id":"1.195532879","rc":[{"atb":[[2.62,27.9]],"id":28753299}],"con":true,"img":false}]}
{"op":"mcm","clk":"5323356293","pt":1646329900504,"mc":[{"id":"1.195532879","rc":[{"atb":[[2.58,10.8]],"id":28753299}],"con":true,"img":false}]}
{"op":"mcm","clk":"5323356309","pt":1646329900609,"mc":[{"id":"1.195532879","rc":[{"atb":[[2.36,39.29],[2.34,0]],"id":39632625}],"con":true,"img":false}]}
{"op":"mcm","clk":"5323356412","pt":1646329901710,"mc":[{"id":"1.195532879","rc":[{"atb":[[2.2,0]],"id":38251452}],"con":true,"img":false}]}
{"op":"mcm","clk":"5323356719","pt":1646329904623,"mc":[{"id":"1.195532879","rc":[{"atb":[[2.42,1.99]],"id":39632625}],"con":true,"img":false}]}
{"op":"mcm","clk":"5323356787","pt":1646329905197,"mc":[{"id":"1.195532879","rc":[{"atb":[[2.28,9.86]],"id":38251452}],"con":true,"img":false}]}
{"op":"mcm","clk":"5323356801","pt":1646329905304,"mc":[{"id":"1.195532879","rc":[{"atb":[[2.26,47.27]],"id":38251452}],"con":true,"img":false}]}
{"op":"mcm","clk":"5323356812","pt":1646329905407,"mc":[{"id":"1.195532879","rc":[{"atb":[[2.24,4.32]],"id":38251452}],"con":true,"img":false}]}
{"op":"mcm","clk":"5323357065","pt":1646329907915,"mc":[{"id":"1.195532879","rc":[{"atb":[[2.36,13.4],[2.22,38.46]],"id":39632625}],"con":true,"img":false}]}
{"op":"mcm","clk":"5323357332","pt":1646329910686,"mc":[{"id":"1.195532879","rc":[{"atb":[[2.26,22.61]],"id":38251452},{"atb":[[2.24,15.54]],"id":39632625}],"con":true,"img":false}]}
{"op":"mcm","clk":"5323357437","pt":1646329911725,"mc":[{"id":"1.195532879","rc":[{"atb":[[2.44,3.39]],"id":28753299}],"con":true,"img":false}]}
{"op":"mcm","clk":"5323357481","pt":1646329912092,"mc":[{"id":"1.195532879","rc":[{"atb":[[2.44,0]],"id":28753299}],"con":true,"img":false}]}
{"op":"mcm","clk":"5323357856","pt":1646329916100,"mc":[{"id":"1.195532879","rc":[{"atb":[[2.24,47.92],[2.22,10.15]],"id":39632625}],"con":true,"img":false}]}
{"op":"mcm","clk":"5323357900","pt":1646329916619,"mc":[{"id":"1.195532879","rc":[{"atb":[[2.3,20.55]],"id":38251452}],"con":true,"img":false}]}
{"op":"mcm","clk":"5323357918","pt":1646329916830,"mc":[{"id":"1.195532879","rc":[{"atb":[[2.26,0],[2.28,32.47]],"id":38251452}],"con":true,"img":false}]}
{"op":"mcm","clk":"5323357937","pt":1646329916988,"mc":[{"id":"1.195532879","rc":[{"atb":[[2.26,12.44]],"id":38251452}],"con":true,"img":false}]}
{"op":"mcm","clk":"5323357991","pt":1646329917502,"mc":[{"id":"1.195532879","rc":[{"atb":[[2.26,0],[2.24,7.77]],"id":38251452}],"con":true,"img":false}]}
{"op":"mcm","clk":"5323358008","pt":1646329917711,"mc":[{"id":"1.195532879","rc":[{"atb":[[2.24,4.32]],"id":38251452}],"con":true,"img":false}]}
{"op":"mcm","clk":"5323358277","pt":1646329920587,"mc":[{"id":"1.195532879","rc":[{"atl":[[4.1,5.97]],"id":40452329},{"atl":[[5,15.1]],"id":39632625}],"con":true,"img":false}]}
{"op":"mcm","clk":"5323358291","pt":1646329920692,"mc":[{"id":"1.195532879","rc":[{"atl":[[4,17.64],[4.6,48.39],[4.7,0]],"id":40452329},{"atb":[[3.35,10.81]],"id":39059999}],"con":true,"img":false}]}
{"op":"mcm","clk":"5323358304","pt":1646329920797,"mc":[{"id":"1.195532879","rc":[{"atl":[[4.8,35.78]],"id":40452329}],"con":true,"img":false}]}
{"op":"mcm","clk":"5323358316","pt":1646329920904,"mc":[{"id":"1.195532879","rc":[{"atl":[[4.4,0]],"id":40452329}],"con":true,"img":false}]}
{"op":"mcm","clk":"5323358327","pt":1646329921004,"mc":[{"id":"1.195532879","rc":[{"atl":[[4.6,37.28],[4.2,12.5]],"id":40452329}],"con":true,"img":false}]}
{"op":"mcm","clk":"5323358344","pt":1646329921211,"mc":[{"id":"1.195532879","rc":[{"atl":[[4.8,26.32]],"id":40452329},{"atb":[[2.28,22.61]],"id":38251452},{"atl":[[5,12.5]],"id":39632625},{"atb":[[3.35,0]],"id":39059999}],"con":true,"img":false}]}
{"op":"mcm","clk":"5323358363","pt":1646329921418,"mc":[{"id":"1.195532879","rc":[{"atl":[[4.1,0]],"id":40452329}],"con":true,"img":false}]}
{"op":"mcm","clk":"5323358397","pt":1646329921730,"mc":[{"id":"1.195532879","rc":[{"atl":[[3.95,1.69]],"id":40452329}],"con":true,"img":false}]}
{"op":"mcm","clk":"5323358454","pt":1646329922253,"mc":[{"id":"1.195532879","rc":[{"atl":[[4.1,12.9],[4.2,0]],"id":40452329}],"con":true,"img":false}]}
{"op":"mcm","clk":"5323358595","pt":1646329923617,"mc":[{"id":"1.195532879","rc":[{"atb":[[2.02,0]],"id":40452329}],"con":true,"img":false}]}
{"op":"mcm","clk":"5323358681","pt":1646329924348,"mc":[{"id":"1.195532879","rc":[{"atb":[[2.04,56.23]],"id":41555107}],"con":true,"img":false}]}
{"op":"mcm","clk":"5323358706","pt":1646329924507,"mc":[{"id":"1.195532879","rc":[{"atb":[[2.04,50.29]],"id":41555107}],"con":true,"img":false}]}
{"op":"mcm","clk":"5323358774","pt":1646329925139,"mc":[{"id":"1.195532879","rc":[{"atb":[[2.16,1.99]],"id":40452329}],"con":true,"img":false}]}
{"op":"mcm","clk":"5323358929","pt":1646329926506,"mc":[{"id":"1.195532879","rc":[{"atb":[[2.38,7.41]],"id":38251452}],"con":true,"img":false}]}
{"op":"mcm","clk":"5323358940","pt":1646329926609,"mc":[{"id":"1.195532879","rc":[{"atb":[[2.3,38.04],[2.4,10.49],[2.28,0]],"id":38251452}],"con":true,"img":false}]}
{"op":"mcm","clk":"5323358960","pt":1646329926816,"mc":[{"id":"1.195532879","rc":[{"atb":[[2.36,2.15]],"id":38251452}],"con":true,"img":false}]}
{"op":"mcm","clk":"5323359026","pt":1646329927337,"mc":[{"id":"1.195532879","rc":[{"atb":[[2.4,0]],"id":38251452},{"atl":[[4.3,6.85]],"id":38251452},{"atb":[[3.45,21.8],[3.2,0],[3.4,20.24],[3,20]],"id":39059999}],"con":true,"img":false}]}
{"op":"mcm","clk":"5323359037","pt":1646329927445,"mc":[{"id":"1.195532879","rc":[{"atb":[[2.38,15.51]],"id":38251452},{"atl":[[4.8,10.53],[4.2,11.05],[4.7,22.96]],"id":38251452}],"con":true,"img":false}]}
{"op":"mcm","clk":"5323359050","pt":1646329927550,"mc":[{"id":"1.195532879","rc":[{"atl":[[4.9,5.26],[4.6,0]],"id":38251452}],"con":true,"img":false}]}
{"op":"mcm","clk":"5323359065","pt":1646329927653,"mc":[{"id":"1.195532879","rc":[{"atl":[[4.3,0]],"id":38251452}],"con":true,"img":false}]}
{"op":"mcm","clk":"5323359076","pt":1646329927755,"mc":[{"id":"1.195532879","rc":[{"atl":[[4.9,0]],"id":38251452}],"con":true,"img":false}]}
{"op":"mcm","clk":"5323359174","pt":1646329928642,"mc":[{"id":"1.195532879","rc":[{"atl":[[4.2,15.33]],"id":38251452}],"con":true,"img":false}]}
{"op":"mcm","clk":"5323359256","pt":1646329929422,"mc":[{"id":"1.195532879","rc":[{"atb":[[2.02,5.47]],"id":40452329},{"spn":3.29,"spf":"NaN","id":38251452},{"spn":2.38,"spf":1.0,"id":39632625},{"spn":4.45,"spf":"NaN","id":28753299}],"con":true,"img":false}]}
{"op":"mcm","clk":"5323359288","pt":1646329929735,"mc":[{"id":"1.195532879","rc":[{"atb":[[2.22,13.26]],"id":39632625}],"con":true,"img":false}]}
{"op":"mcm","clk":"5323359362","pt":1646329930258,"mc":[{"id":"1.195532879","rc":[{"atb":[[2.22,10.15]],"id":39632625}],"con":true,"img":false}]}
{"op":"mcm","clk":"5323359506","pt":1646329931539,"mc":[{"id":"1.195532879","rc":[{"atb":[[2,0],[2.08,0],[2.16,0]],"id":38251452}],"con":true,"img":false}]}
{"op":"mcm","clk":"5323359557","pt":1646329932053,"mc":[{"id":"1.195532879","rc":[{"atb":[[2.02,18.25]],"id":40452329},{"atb":[[2.3,17.49]],"id":38251452}],"con":true,"img":false}]}
{"op":"mcm","clk":"5323359592","pt":1646329932363,"mc":[{"id":"1.195532879","rc":[{"atl":[[4.8,0],[4.4,11.76]],"id":38251452}],"con":true,"img":false}]}
{"op":"mcm","clk":"5323359630","pt":1646329932829,"mc":[{"id":"1.195532879","rc":[{"atb":[[1.08,50]],"id":41555107},{"atb":[[1.08,50]],"id":40452329},{"atb":[[1.08,50]],"id":38251452},{"atb":[[1.08,50]],"id":39632625},{"atb":[[1.08,50]],"id":39059999},{"atb":[[1.08,50]],"id":28753299}],"con":true,"img":false}]}
{"op":"mcm","clk":"5323359676","pt":1646329933246,"mc":[{"id":"1.195532879","rc":[{"atl":[[4.3,30.3]],"id":40452329}],"con":true,"img":false}]}
{"op":"mcm","clk":"5323359914","pt":1646329935842,"mc":[{"id":"1.195532879","rc":[{"atl":[[4.3,94.76],[4.6,2.5],[3.95,4.8]],"id":40452329}],"con":true,"img":false}]}
{"op":"mcm","clk":"5323359928","pt":1646329935958,"mc":[{"id":"1.195532879","rc":[{"atl":[[4,0],[4.1,43.2]],"id":40452329}],"con":true,"img":false}]}
{"op":"mcm","clk":"5323359993","pt":1646329936578,"mc":[{"id":"1.195532879","rc":[{"atb":[[2.38,9.75]],"id":38251452}],"con":true,"img":false}]}
{"op":"mcm","clk":"5323360222","pt":1646329939184,"mc":[{"id":"1.195532879","rc":[{"atb":[[2.02,12.78]],"id":40452329},{"atb":[[2.26,37.53]],"id":38251452}],"con":true,"img":false}]}
{"op":"mcm","clk":"5323360244","pt":1646329939400,"mc":[{"id":"1.195532879","rc":[{"atl":[[4.8,0],[5,5],[5.2,0]],"id":40452329}],"con":true,"img":false}]}
{"op":"mcm","clk":"5323360499","pt":1646329941934,"mc":[{"id":"1.195532879","rc":[{"atb":[[2.02,0]],"id":40452329}],"con":true,"img":false}]}
{"op":"mcm","clk":"5323360511","pt":1646329942038,"mc":[{"id":"1.195532879","rc":[{"atb":[[2.26,51.2]],"id":38251452},{"atl":[[4.2,11.05]],"id":38251452}],"con":true,"img":false}]}
{"op":"mcm","clk":"5323360518","pt":1646329942140,"mc":[{"id":"1.195532879","rc":[{"atl":[[4.2,7.67],[4.7,45.92]],"id":38251452},{"atb":[[2.3,0],[2.22,0],[2.38,0]],"id":28753299}],"con":true,"img":false}]}
{"op":"mcm","clk":"5323360534","pt":1646329942346,"mc":[{"id":"1.195532879","rc":[{"atl":[[4.2,0]],"id":38251452}],"con":true,"img":false}]}
{"op":"mcm","clk":"5323360540","pt":1646329942453,"mc":[{"id":"1.195532879","rc":[{"atl":[[4.3,16.14],[5,83.5],[4.7,25.46]],"id":38251452}],"con":true,"img":false}]}
{"op":"mcm","clk":"5323360587","pt":1646329942972,"mc":[{"id":"1.195532879","rc":[{"atl":[[3.95,38.7],[4.1,12.9]],"id":40452329}],"con":true,"img":false}]}
{"op":"mcm","clk":"5323360596","pt":1646329943072,"mc":[{"id":"1.195532879","rc":[{"atl":[[4.3,125.06]],"id":40452329}],"con":true,"img":false}]}
{"op":"mcm","clk":"5323360604","pt":1646329943128,"mc":[{"id":"1.195532879","rc":[{"atl":[[3.95,4.8]],"id":40452329},{"atl":[[4.5,11.43],[4.4,0]],"id":38251452}],"con":true,"img":false}]}
{"op":"mcm","clk":"5323360611","pt":1646329943228,"mc":[{"id":"1.195532879","rc":[{"atl":[[4.3,94.76],[3.95,38.7]],"id":40452329},{"atl":[[4.3,0]],"id":38251452}],"con":true,"img":false}]}
{"op":"mcm","clk":"5323360622","pt":1646329943332,"mc":[{"id":"1.195532879","rc":[{"atl":[[4.3,20.68]],"id":38251452}],"con":true,"img":false}]}
{"op":"mcm","clk":"5323360632","pt":1646329943436,"mc":[{"id":"1.195532879","rc":[{"atl":[[4.5,0],[4.7,36.27]],"id":38251452}],"con":true,"img":false}]}
{"op":"mcm","clk":"5323360686","pt":1646329943851,"mc":[{"id":"1.195532879","rc":[{"atl":[[4.3,0]],"id":38251452}],"con":true,"img":false}]}
{"op":"mcm","clk":"5323360694","pt":1646329943955,"mc":[{"id":"1.195532879","rc":[{"atl":[[4.5,20.44]],"id":38251452}],"con":true,"img":false}]}
{"op":"mcm","clk":"5323360702","pt":1646329944059,"mc":[{"id":"1.195532879","rc":[{"atl":[[4.5,42.86]],"id":40452329}],"con":true,"img":false}]}
{"op":"mcm","clk":"5323360727","pt":1646329944369,"mc":[{"id":"1.195532879","rc":[{"atl":[[5.2,36.64]],"id":39632625}],"con":true,"img":false}]}
{"op":"mcm","clk":"5323360789","pt":1646329944836,"mc":[{"id":"1.195532879","rc":[{"atb":[[2.08,4.37]],"id":40452329},{"atl":[[5.2,23.81]],"id":39632625}],"con":true,"img":false}]}
{"op":"mcm","clk":"5323360797","pt":1646329944938,"mc":[{"id":"1.195532879","rc":[{"atb":[[2.08,25.97],[2.06,17.03]],"id":40452329}],"con":true,"img":false}]}
{"op":"mcm","clk":"5323361037","pt":1646329947260,"mc":[{"id":"1.195532879","rc":[{"atl":[[5,108.5],[4.7,13.31]],"id":38251452}],"con":true,"img":false}]}
{"op":"mcm","clk":"5323361148","pt":1646329948657,"mc":[{"id":"1.195532879","rc":[{"atb":[[2,0],[1.96,0],[1.92,0]],"id":40452329}],"con":true,"img":false}]}
{"op":"mcm","clk":"5323361186","pt":1646329949071,"mc":[{"id":"1.195532879","rc":[{"atb":[[2.02,12.78]],"id":40452329},{"atb":[[2.26,13.66]],"id":38251452}],"con":true,"img":false}]}
{"op":"mcm","clk":"5323361267","pt":1646329950051,"mc":[{"id":"1.195532879","rc":[{"atl":[[4.5,0]],"id":38251452}],"con":true,"img":false}]}
{"op":"mcm","clk":"5323361277","pt":1646329950155,"mc":[{"id":"1.195532879","rc":[{"atl":[[5.1,51.14],[5,50],[4.6,22.22]],"id":38251452}],"con":true,"img":false}]}
{"op":"mcm","clk":"5323361301","pt":1646329950364,"mc":[{"id":"1.195532879","rc":[{"atb":[[2.22,9.38]],"id":38251452}],"con":true,"img":false}]}
{"op":"mcm","clk":"5323361310","pt":1646329950468,"mc":[{"id":"1.195532879","rc":[{"atb":[[2.22,0]],"id":38251452}],"con":true,"img":false}]}
{"op":"mcm","clk":"5323361377","pt":1646329951144,"mc":[{"id":"1.195532879","rc":[{"atb":[[2.22,3.4]],"id":38251452}],"con":true,"img":false}]}
{"op":"mcm","clk":"5323361414","pt":1646329951455,"mc":[{"id":"1.195532879","rc":[{"atb":[[2.22,0]],"id":38251452}],"con":true,"img":false}]}
{"op":"mcm","clk":"5323361686","pt":1646329954061,"mc":[{"id":"1.195532879","rc":[{"atl":[[4.8,10.53],[4.7,2.5]],"id":38251452}],"con":true,"img":false}]}
{"op":"mcm","clk":"5323361696","pt":1646329954168,"mc":[{"id":"1.195532879","rc":[{"atl":[[4.8,36.85],[5,25]],"id":38251452}],"con":true,"img":false}]}
{"op":"mcm","clk":"5323361730","pt":1646329954476,"mc":[{"id":"1.195532879","rc":[{"atb":[[2.26,0]],"id":38251452}],"con":true,"img":false}]}
{"op":"mcm","clk":"5323361738","pt":1646329954579,"mc":[{"id":"1.195532879","rc":[{"atl":[[4.7,67.57]],"id":40452329}],"con":true,"img":false}]}
{"op":"mcm","clk":"5323361820","pt":1646329955360,"mc":[{"id":"1.195532879","rc":[{"atb":[[3.4,23.42]],"id":39059999}],"con":true,"img":false}]}
{"op":"mcm","clk":"5323361830","pt":1646329955463,"mc":[{"id":"1.195532879","rc":[{"atb":[[3.4,20.24]],"id":39059999}],"con":true,"img":false}]}
{"op":"mcm","clk":"5323361839","pt":1646329955570,"mc":[{"id":"1.195532879","rc":[{"atl":[[4.2,5.72]],"id":40452329}],"con":true,"img":false}]}
{"op":"mcm","clk":"5323361855","pt":1646329955671,"mc":[{"id":"1.195532879","rc":[{"atl":[[4.3,30.3],[4.2,42.96]],"id":40452329}],"con":true,"img":false}]}
{"op":"mcm","clk":"5323361870","pt":1646329955776,"mc":[{"id":"1.195532879","rc":[{"atb":[[2.02,0]],"id":40452329},{"atl":[[4.4,9.85]],"id":40452329},{"atb":[[2.32,24.39]],"id":38251452}],"con":true,"img":false}]}
{"op":"mcm","clk":"5323361892","pt":1646329955982,"mc":[{"id":"1.195532879","rc":[{"atl":[[4.4,0],[4.2,37.24]],"id":40452329},{"atb":[[2.32,64.36],[2.3,0]],"id":38251452}],"con":true,"img":false}]}
{"op":"mcm","clk":"5323362025","pt":1646329957162,"mc":[{"id":"1.195532879","rc":[{"atl":[[4.8,100.81],[5.1,5],[4.5,4.38]],"id":38251452}],"con":true,"img":false}]}
{"op":"mcm","clk":"5323362037","pt":1646329957268,"mc":[{"id":"1.195532879","rc":[{"atl":[[4.5,13.58]],"id":38251452}],"con":true,"img":false}]}
{"op":"mcm","clk":"5323362051","pt":1646329957371,"mc":[{"id":"1.195532879","rc":[{"atl":[[4.6,0]],"id":38251452}],"con":true,"img":false}]}
{"op":"mcm","clk":"5323362065","pt":1646329957476,"mc":[{"id":"1.195532879","rc":[{"atl":[[4.5,9.2]],"id":38251452}],"con":true,"img":false}]}
{"op":"mcm","clk":"5323362092","pt":1646329957683,"mc":[{"id":"1.195532879","rc":[{"atl":[[4.5,0]],"id":38251452}],"con":true,"img":false}]}
{"op":"mcm","clk":"5323362104","pt":1646329957788,"mc":[{"id":"1.195532879","rc":[{"atl":[[4.6,14.22]],"id":38251452}],"con":true,"img":false}]}
{"op":"mcm","clk":"5323362118","pt":1646329957894,"mc":[{"id":"1.195532879","rc":[{"atl":[[4.8,74.49],[5,50]],"id":38251452}],"con":true,"img":false}]}
{"op":"mcm","clk":"5323362169","pt":1646329958258,"mc":[{"id":"1.195532879","rc":[{"atb":[[1.89,0],[1.85,47.06],[1.93,0]],"id":41555107},{"atl":[[10.5,7.11],[12.5,5]],"id":39059999}],"con":true,"img":false}]}
{"op":"mcm","clk":"5323362179","pt":1646329958362,"mc":[{"id":"1.195532879","rc":[{"atl":[[11,0],[13,8.33],[15,0]],"id":39059999}],"con":true,"img":false}]}
{"op":"mcm","clk":"5323362191","pt":1646329958470,"mc":[{"id":"1.195532879","rc":[{"atl":[[4.8,7.83]],"id":39632625},{"atl":[[11.5,3.81]],"id":39059999}],"con":true,"img":false}]}
{"op":"mcm","clk":"5323362207","pt":1646329958572,"mc":[{"id":"1.195532879","rc":[{"atb":[[2.4,14.15]],"id":39632625},{"atl":[[5.1,32.56]],"id":39632625},{"atl":[[11.5,10.06],[12.5,40.74]],"id":39059999}],"con":true,"img":false}]}
{"op":"mcm","clk":"5323362220","pt":1646329958678,"mc":[{"id":"1.195532879","rc":[{"atb":[[2.36,0]],"id":39632625},{"atl":[[4.7,12.5]],"id":39632625}],"con":true,"img":false}]}
{"op":"mcm","clk":"5323362229","pt":1646329958783,"mc":[{"id":"1.195532879","rc":[{"atb":[[2.06,120.83],[2.04,45.29]],"id":41555107},{"atb":[[2.4,2.15]],"id":39632625},{"atl":[[4.7,27.75]],"id":39632625},{"atb":[[3.55,6.6],[3.5,20.24]],"id":39059999}],"con":true,"img":false}]}
{"op":"mcm","clk":"5323362241","pt":1646329958885,"mc":[{"id":"1.195532879","rc":[{"atb":[[2.22,41.4],[2.34,3.32],[2.24,15.54]],"id":39632625},{"atl":[[5.1,0],[5,62.5]],"id":39632625}],"con":true,"img":false}]}
{"op":"mcm","clk":"5323362251","pt":1646329958995,"mc":[{"id":"1.195532879","rc":[{"atb":[[2.02,3.86]],"id":41555107},{"atl":[[4.8,4.33],[5,52.5],[5.2,29.91],[4.9,10.26]],"id":39632625},{"atb":[[3.45,59.68],[3.4,0]],"id":39059999}],"con":true,"img":false}]}
{"op":"mcm","clk":"5323362264","pt":1646329959045,"mc":[{"id":"1.195532879","rc":[{"atb":[[2.34,0]],"id":39632625},{"atl":[[11.5,3.81]],"id":39059999}],"con":true,"img":false}]}
{"op":"mcm","clk":"5323362273","pt":1646329959152,"mc":[{"id":"1.195532879","rc":[{"atb":[[2.02,0]],"id":41555107}],"con":true,"img":false}]}
{"op":"mcm","clk":"5323362285","pt":1646329959253,"mc":[{"id":"1.195532879","rc":[{"atb":[[2.22,47.77]],"id":39632625}],"con":true,"img":false}]}
{"op":"mcm","clk":"5323362308","pt":1646329959459,"mc":[{"id":"1.195532879","rc":[{"atb":[[2.26,13.66]],"id":38251452},{"atb":[[2.22,41.4]],"id":39632625},{"atl":[[5.2,23.81]],"id":39632625}],"con":true,"img":false}]}
{"op":"mcm","clk":"5323362319","pt":1646329959562,"mc":[{"id":"1.195532879","rc":[{"atl":[[4.8,0]],"id":39632625}],"con":true,"img":false}]}
{"op":"mcm","clk":"5323362332","pt":1646329959668,"mc":[{"id":"1.195532879","rc":[{"atl":[[5,77.5]],"id":39632625}],"con":true,"img":false}]}
{"op":"mcm","clk":"5323362342","pt":1646329959769,"mc":[{"id":"1.195532879","rc":[{"atl":[[4.7,15.25]],"id":39632625}],"con":true,"img":false}]}
{"op":"mcm","clk":"5323362353","pt":1646329959874,"mc":[{"id":"1.195532879","rc":[{"atl":[[4.7,17.85]],"id":39632625}],"con":true,"img":false}]}
{"op":"mcm","clk":"5323362365","pt":1646329959978,"mc":[{"id":"1.195532879","rc":[{"atl":[[4.7,2.6]],"id":39632625}],"con":true,"img":false}]}
{"op":"mcm","clk":"5323362383","pt":1646329960187,"mc":[{"id":"1.195532879","rc":[{"atl":[[4.8,9.64]],"id":39632625}],"con":true,"img":false}]}
{"op":"mcm","clk":"5323362390","pt":1646329960288,"mc":[{"id":"1.195532879","rc":[{"atl":[[4.7,0]],"id":39632625}],"con":true,"img":false}]}
{"op":"mcm","clk":"5323362439","pt":1646329960657,"mc":[{"id":"1.195532879","rc":[{"atl":[[5,87.5],[4.9,0]],"id":39632625}],"con":true,"img":false}]}
{"op":"mcm","clk":"5323362577","pt":1646329962052,"mc":[{"id":"1.195532879","rc":[{"atb":[[2.1,9.12]],"id":40452329}],"con":true,"img":false}]}
{"op":"mcm","clk":"5323362587","pt":1646329962154,"mc":[{"id":"1.195532879","rc":[{"atb":[[2.1,36.66],[2.08,4.37]],"id":40452329}],"con":true,"img":false}]}
{"op":"mcm","clk":"5323362615","pt":1646329962362,"mc":[{"id":"1.195532879","rc":[{"atl":[[4.6,4.55]],"id":39632625}],"con":true,"img":false}]}
{"op":"mcm","clk":"5323362641","pt":1646329962573,"mc":[{"id":"1.195532879","rc":[{"atl":[[4.8,20.17],[5,77.5]],"id":39632625}],"con":true,"img":false}]}
{"op":"mcm","clk":"5323362777","pt":1646329963867,"mc":[{"id":"1.195532879","rc":[{"atb":[[2.06,70.54],[2.1,47.06]],"id":41555107},{"atb":[[2.4,17.23]],"id":39632625},{"atb":[[3.55,26.84],[3.5,0]],"id":39059999},{"atb":[[2.6,39.36],[2.58,0]],"id":28753299}],"con":true,"img":false}]}
{"op":"mcm","clk":"5323362787","pt":1646329963969,"mc":[{"id":"1.195532879","rc":[{"atb":[[2.06,156.38],[2.04,0]],"id":41555107},{"atb":[[3.6,9.84]],"id":39059999}],"con":true,"img":false}]}
{"op":"mcm","clk":"5323362798","pt":1646329964080,"mc":[{"id":"1.195532879","rc":[{"atb":[[3.55,22.23]],"id":39059999}],"con":true,"img":false}]}
{"op":"mcm","clk":"5323362828","pt":1646329964385,"mc":[{"id":"1.195532879","rc":[{"atb":[[2.08,8.75]],"id":41555107}],"con":true,"img":false}]}
{"op":"mcm","clk":"5323362835","pt":1646329964492,"mc":[{"id":"1.195532879","rc":[{"atb":[[2.08,0]],"id":41555107},{"atl":[[7,62.51]],"id":28753299}],"con":true,"img":false}]}
{"op":"mcm","clk":"5323362859","pt":1646329964696,"mc":[{"id":"1.195532879","rc":[{"atl":[[4.8,100.81],[5,25]],"id":38251452},{"atb":[[3.55,20.24]],"id":39059999}],"con":true,"img":false}]}
{"op":"mcm","clk":"5323362870","pt":1646329964800,"mc":[{"id":"1.195532879","rc":[{"atb":[[3.65,1.99]],"id":39059999}],"con":true,"img":false}]}
{"op":"mcm","clk":"5323362887","pt":1646329964955,"mc":[{"id":"1.195532879","rc":[{"atb":[[2.32,39.97]],"id":38251452},{"atl":[[5.1,11.25]],"id":38251452},{"atb":[[3.45,40.38]],"id":39059999},{"atl":[[7,52.21]],"id":28753299}],"con":true,"img":false}]}
{"op":"mcm","clk":"5323362905","pt":1646329965163,"mc":[{"id":"1.195532879","rc":[{"atl":[[5.1,5]],"id":38251452}],"con":true,"img":false}]}
{"op":"mcm","clk":"5323363036","pt":1646329966463,"mc":[{"id":"1.195532879","rc":[{"atl":[[4.5,20.17],[5,52.5]],"id":39632625}],"con":true,"img":false}]}
{"op":"mcm","clk":"5323363093","pt":1646329967083,"mc":[{"id":"1.195532879","rc":[{"atb":[[2.06,130.46]],"id":41555107},{"atb":[[2.08,0]],"id":40452329}],"con":true,"img":false}]}
{"op":"mcm","clk":"5323363151","pt":1646329967759,"mc":[{"id":"1.195532879","rc":[{"atl":[[4.8,9.64],[4.7,10.81]],"id":39632625}],"con":true,"img":false}]}
{"op":"mcm","clk":"5323363186","pt":1646329968180,"mc":[{"id":"1.195532879","rc":[{"atb":[[2.06,85.84]],"id":41555107}],"con":true,"img":false}]}
{"op":"mcm","clk":"5323363220","pt":1646329968593,"mc":[{"id":"1.195532879","rc":[{"atl":[[4.6,0]],"id":39632625}],"con":true,"img":false}]}
{"op":"mcm","clk":"5323363244","pt":1646329968852,"mc":[{"id":"1.195532879","rc":[{"atb":[[2.14,67],[2.1,0]],"id":41555107},{"atb":[[2.4,2.15]],"id":39632625},{"atb":[[2.62,61.23]],"id":28753299}],"con":true,"img":false}]}
{"op":"mcm","clk":"5323363253","pt":1646329969013,"mc":[{"id":"1.195532879","rc":[{"atb":[[1.98,5],[2.04,2.5],[1.94,10],[2.16,21.1]],"id":41555107},{"atb":[[2.6,0]],"id":28753299}],"con":true,"img":false}]}
{"op":"mcm","clk":"5323363261","pt":1646329969060,"mc":[{"id":"1.195532879","rc":[{"atb":[[2.26,15.34]],"id":39632625}],"con":true,"img":false}]}
{"op":"mcm","clk":"5323363273","pt":1646329969163,"mc":[{"id":"1.195532879","rc":[{"atb":[[2.14,49.21]],"id":41555107}],"con":true,"img":false}]}
{"op":"mcm","clk":"5323363281","pt":1646329969271,"mc":[{"id":"1.195532879","rc":[{"atl":[[5,50],[4.9,2.5]],"id":39632625}],"con":true,"img":false}]}
{"op":"mcm","clk":"5323363292","pt":1646329969372,"mc":[{"id":"1.195532879","rc":[{"atl":[[4.5,22.29]],"id":38251452}],"con":true,"img":false}]}
{"op":"mcm","clk":"5323363313","pt":1646329969589,"mc":[{"id":"1.195532879","rc":[{"atl":[[4.8,10.53],[4.4,32.2],[4.7,50.46]],"id":38251452}],"con":true,"img":false}]}
{"op":"mcm","clk":"5323363336","pt":1646329969798,"mc":[{"id":"1.195532879","rc":[{"atl":[[4.5,0],[4.6,0]],"id":38251452}],"con":true,"img":false}]}
{"op":"mcm","clk":"5323363348","pt":1646329969849,"mc":[{"id":"1.195532879","rc":[{"atb":[[2.22,2.15],[2.14,47.06]],"id":41555107},{"atb":[[2.32,2.15],[2.4,0]],"id":39632625}],"con":true,"img":false}]}
{"op":"mcm","clk":"5323363379","pt":1646329970162,"mc":[{"id":"1.195532879","rc":[{"atb":[[2.16,19.45]],"id":41555107},{"atb":[[3.6,8.19]],"id":39059999}],"con":true,"img":false}]}
{"op":"mcm","clk":"5323363396","pt":1646329970369,"mc":[{"id":"1.195532879","rc":[{"atb":[[2.24,1.65]],"id":41555107},{"atb":[[2.44,1.65]],"id":39632625},{"atb":[[3.7,1.65]],"id":39059999}],"con":true,"img":false}]}
{"op":"mcm","clk":"5323363412","pt":1646329970577,"mc":[{"id":"1.195532879","rc":[{"atb":[[2.42,0]],"id":39632625},{"atl":[[4.4,4.79]],"id":39632625}],"con":true,"img":false}]}
{"op":"mcm","clk":"5323363423","pt":1646329970681,"mc":[{"id":"1.195532879","rc":[{"atb":[[2.34,1.99]],"id":39632625}],"con":true,"img":false}]}
{"op":"mcm","clk":"5323363462","pt":1646329971097,"mc":[{"id":"1.195532879","rc":[{"atl":[[4.8,0],[4.6,11.11]],"id":38251452},{"atl":[[4.6,11.11],[4.7,0]],"id":39632625}],"con":true,"img":false}]}
{"op":"mcm","clk":"5323363471","pt":1646329971203,"mc":[{"id":"1.195532879","rc":[{"atl":[[4.3,2.52]],"id":38251452}],"con":true,"img":false}]}
{"op":"mcm","clk":"5323363490","pt":1646329971359,"mc":[{"id":"1.195532879","rc":[{"atl":[[4.5,11.43],[4.6,0]],"id":38251452}],"con":true,"img":false}]}
{"op":"mcm","clk":"5323363510","pt":1646329971567,"mc":[{"id":"1.195532879","rc":[{"atl":[[4.3,0],[4.5,53.81],[4.7,2.5]],"id":38251452}],"con":true,"img":false}]}
{"op":"mcm","clk":"5323363522","pt":1646329971671,"mc":[{"id":"1.195532879","rc":[{"atl":[[4.2,15.89]],"id":38251452}],"con":true,"img":false}]}
{"op":"mcm","clk":"5323363533","pt":1646329971775,"mc":[{"id":"1.195532879","rc":[{"atl":[[4.5,42.38],[4.6,11.11],[4.4,14.22],[4.2,0]],"id":38251452}],"con":true,"img":false}]}
{"op":"mcm","clk":"5323363546","pt":1646329971879,"mc":[{"id":"1.195532879","rc":[{"atl":[[4.3,24.24],[4.4,25.98]],"id":38251452}],"con":true,"img":false}]}
{"op":"mcm","clk":"5323363599","pt":1646329972608,"mc":[{"id":"1.195532879","rc":[{"atb":[[2.1,27.54]],"id":40452329},{"atb":[[2.28,29.27]],"id":38251452},{"atb":[[3.65,19.73]],"id":39059999}],"con":true,"img":false}]}
{"op":"mcm","clk":"5323363627","pt":1646329972870,"mc":[{"id":"1.195532879","rc":[{"atb":[[2.08,25.32]],"id":41555107},{"atb":[[2.12,3.65]],"id":40452329}],"con":true,"img":false}]}
{"op":"mcm","clk":"5323363638","pt":1646329972971,"mc":[{"id":"1.195532879","rc":[{"atb":[[2.34,7.2]],"id":39632625}],"con":true,"img":false}]}
{"op":"mcm","clk":"5323363650","pt":1646329973074,"mc":[{"id":"1.195532879","rc":[{"atb":[[2.1,0]],"id":40452329},{"atb":[[2.26,0]],"id":39632625},{"atl":[[4.5,0],[4.3,11.11]],"id":39632625}],"con":true,"img":false}]}
{"op":"mcm","clk":"5323363659","pt":1646329973178,"mc":[{"id":"1.195532879","rc":[{"atl":[[4.3,20.1]],"id":39632625}],"con":true,"img":false}]}
{"op":"mcm","clk":"5323363669","pt":1646329973281,"mc":[{"id":"1.195532879","rc":[{"atb":[[2.22,10.15],[2.24,40.5]],"id":39632625},{"atl":[[4.8,0],[4.6,51.05],[5,0],[4.7,4.93]],"id":39632625}],"con":true,"img":false}]}
{"op":"mcm","clk":"5323363685","pt":1646329973385,"mc":[{"id":"1.195532879","rc":[{"atl":[[4.7,0]],"id":39632625},{"atb":[[3.45,2.5]],"id":39059999}],"con":true,"img":false}]}
{"op":"mcm","clk":"5323363706","pt":1646329973592,"mc":[{"id":"1.195532879","rc":[{"atb":[[3.55,55.78]],"id":39059999}],"con":true,"img":false}]}
{"op":"mcm","clk":"5323363775","pt":1646329974272,"mc":[{"id":"1.195532879","rc":[{"atl":[[4.5,53.81],[4.6,0],[5,0],[5.2,0],[4.4,14.22],[5.4,0]],"id":38251452},{"atl":[[4.5,11.43],[4.6,39.94]],"id":39632625},{"atb":[[3.6,29.59],[3.55,35.54]],"id":39059999},{"atb":[[2.6,62.5],[2.62,27.9]],"id":28753299}],"con":true,"img":false}]}
{"op":"mcm","clk":"5323363824","pt":1646329974690,"mc":[{"id":"1.195532879","rc":[{"atl":[[4.5,82.38]],"id":38251452}],"con":true,"img":false}]}
{"op":"mcm","clk":"5323363834","pt":1646329974793,"mc":[{"id":"1.195532879","rc":[{"atl":[[4.4,0]],"id":38251452}],"con":true,"img":false}]}
{"op":"mcm","clk":"5323363852","pt":1646329975000,"mc":[{"id":"1.195532879","rc":[{"atl":[[4.3,0],[4.5,53.81],[4.7,29.53]],"id":38251452}],"con":true,"img":false}]}
{"op":"mcm","clk":"5323363860","pt":1646329975102,"mc":[{"id":"1.195532879","rc":[{"atb":[[2.26,0]],"id":38251452},{"atl":[[4.4,23.53]],"id":38251452}],"con":true,"img":false}]}
{"op":"mcm","clk":"5323363935","pt":1646329975881,"mc":[{"id":"1.195532879","rc":[{"atb":[[2.24,7.38]],"id":41555107},{"atb":[[2.24,24.96]],"id":39632625}],"con":true,"img":false}]}
{"op":"mcm","clk":"5323363966","pt":1646329976195,"mc":[{"id":"1.195532879","rc":[{"atl":[[4.5,11.43],[4.7,104.16]],"id":38251452}],"con":true,"img":false}]}
{"op":"mcm","clk":"5323364041","pt":1646329977034,"mc":[{"id":"1.195532879","rc":[{"atl":[[4.5,0],[4.6,11.11]],"id":38251452}],"con":true,"img":false}]}
{"op":"mcm","clk":"5323364096","pt":1646329977502,"mc":[{"id":"1.195532879","rc":[{"atb":[[2.08,0]],"id":41555107}],"con":true,"img":false}]}
{"op":"mcm","clk":"5323364105","pt":1646329977603,"mc":[{"id":"1.195532879","rc":[{"atl":[[4.4,0]],"id":39632625}],"con":true,"img":false}]}
{"op":"mcm","clk":"5323364124","pt":1646329977812,"mc":[{"id":"1.195532879","rc":[{"atl":[[4.3,8.99],[4.6,67.72]],"id":39632625}],"con":true,"img":false}]}
{"op":"mcm","clk":"5323364147","pt":1646329977965,"mc":[{"id":"1.195532879","rc":[{"atl":[[4.3,0]],"id":39632625}],"con":true,"img":false}]}
{"op":"mcm","clk":"5323364159","pt":1646329978069,"mc":[{"id":"1.195532879","rc":[{"atl":[[4.4,7.02]],"id":39632625}],"con":true,"img":false}]}
{"op":"mcm","clk":"5323364164","pt":1646329978172,"mc":[{"id":"1.195532879","rc":[{"atb":[[2.16,51.87]],"id":41555107},{"atb":[[3.7,21.79]],"id":39059999}],"con":true,"img":false}]}
{"op":"mcm","clk":"5323364176","pt":1646329978276,"mc":[{"id":"1.195532879","rc":[{"atb":[[2.06,0]],"id":41555107}],"con":true,"img":false}]}
{"op":"mcm","clk":"5323364187","pt":1646329978378,"mc":[{"id":"1.195532879","rc":[{"atl":[[4.5,0],[4.6,78.83]],"id":39632625},{"atb":[[3.6,21.4]],"id":39059999}],"con":true,"img":false}]}
{"op":"mcm","clk":"5323364205","pt":1646329978585,"mc":[{"id":"1.195532879","rc":[{"atb":[[3.65,17.74]],"id":39059999}],"con":true,"img":false}]}
{"op":"mcm","clk":"5323364213","pt":1646329978686,"mc":[{"id":"1.195532879","rc":[{"atb":[[3.75,1.99]],"id":39059999}],"con":true,"img":false}]}
{"op":"mcm","clk":"5323364272","pt":1646329979310,"mc":[{"id":"1.195532879","rc":[{"atb":[[2.14,0],[2.16,98.93]],"id":41555107},{"atb":[[3.6,0],[3.55,74.69]],"id":39059999},{"atb":[[2.6,0],[2.62,61.23]],"id":28753299}],"con":true,"img":false}]}
{"op":"mcm","clk":"5323364286","pt":1646329979519,"mc":[{"id":"1.195532879","rc":[{"atl":[[4.2,5.07]],"id":39632625}],"con":true,"img":false}]}
{"op":"mcm","clk":"5323364309","pt":1646329979683,"mc":[{"id":"1.195532879","rc":[{"atl":[[4.6,67.72],[4.4,18.78]],"id":39632625}],"con":true,"img":false}]}
{"op":"mcm","clk":"5323364359","pt":1646329980095,"mc":[{"id":"1.195532879","rc":[{"atb":[[2.08,10.03]],"id":40452329}],"con":true,"img":false}]}
{"op":"mcm","clk":"5323364386","pt":1646329980406,"mc":[{"id":"1.195532879","rc":[{"atb":[[2.26,10.62]],"id":39632625}],"con":true,"img":false}]}
{"op":"mcm","clk":"5323364468","pt":1646329981183,"mc":[{"id":"1.195532879","rc":[{"atb":[[2.44,0]],"id":39632625},{"atb":[[3.7,20.14]],"id":39059999}],"con":true,"img":false}]}
{"op":"mcm","clk":"5323364485","pt":1646329981391,"mc":[{"id":"1.195532879","rc":[{"atb":[[2.36,1.65]],"id":39632625},{"atb":[[3.8,1.65]],"id":39059999}],"con":true,"img":false}]}
{"op":"mcm","clk":"5323364667","pt":1646329983206,"mc":[{"id":"1.195532879","rc":[{"atb":[[2.24,26.83],[2.06,12.55]],"id":41555107},{"atb":[[2.12,0]],"id":40452329}],"con":true,"img":false}]}
{"op":"mcm","clk":"5323364679","pt":1646329983416,"mc":[{"id":"1.195532879","rc":[{"atb":[[2.16,79.48]],"id":41555107},{"atb":[[2.08,38.7]],"id":40452329}],"con":true,"img":false}]}
{"op":"mcm","clk":"5323364689","pt":1646329983514,"mc":[{"id":"1.195532879","rc":[{"atb":[[2.3,2.15],[2.22,0]],"id":41555107}],"con":true,"img":false}]}
{"op":"mcm","clk":"5323364731","pt":1646329983875,"mc":[{"id":"1.195532879","rc":[{"atb":[[2.28,0]],"id":38251452},{"atb":[[2.26,34.99]],"id":39632625},{"atb":[[3.65,0]],"id":39059999}],"con":true,"img":false}]}
{"op":"mcm","clk":"5323364777","pt":1646329984393,"mc":[{"id":"1.195532879","rc":[{"atl":[[4.6,39.94],[4.1,18.78]],"id":39632625}],"con":true,"img":false}]}
{"op":"mcm","clk":"5323364789","pt":1646329984498,"mc":[{"id":"1.195532879","rc":[{"atl":[[4.4,7.58]],"id":40452329},{"atb":[[2.24,2.5],[2.18,84.75]],"id":38251452},{"atb":[[2.22,2.5],[2.16,17.35]],"id":39632625},{"atb":[[3.55,35.54],[3.5,22.13]],"id":39059999},{"atl":[[6.2,4.99],[6,2.5],[6.8,5],[7,47.21]],"id":28753299}],"con":true,"img":false}]}
{"op":"mcm","clk":"5323364801","pt":1646329984604,"mc":[{"id":"1.195532879","rc":[{"atl":[[4.4,0]],"id":40452329},{"atl":[[6,13.47],[6.6,23.27]],"id":28753299}],"con":true,"img":false}]}
{"op":"mcm","clk":"5323364813","pt":1646329984706,"mc":[{"id":"1.195532879","rc":[{"atl":[[6.2,0],[6.6,63.77],[7,0]],"id":28753299}],"con":true,"img":false}]}
{"op":"mcm","clk":"5323364820","pt":1646329984809,"mc":[{"id":"1.195532879","rc":[{"atl":[[4.3,12.12],[4.4,7.02]],"id":39632625},{"atl":[[6.4,7.41],[6.6,56.63]],"id":28753299}],"con":true,"img":false}]}
{"op":"mcm","clk":"5323364833","pt":1646329984918,"mc":[{"id":"1.195532879","rc":[{"atl":[[4.6,17.56]],"id":38251452}],"con":true,"img":false}]}
{"op":"mcm","clk":"5323364853","pt":1646329985128,"mc":[{"id":"1.195532879","rc":[{"atl":[[4.5,28.57],[4.7,77.13]],"id":38251452}],"con":true,"img":false}]}
{"op":"mcm","clk":"5323364876","pt":1646329985286,"mc":[{"id":"1.195532879","rc":[{"atl":[[4.6,88.77],[4.7,2.5]],"id":38251452}],"con":true,"img":false}]}
{"op":"mcm","clk":"5323364911","pt":1646329985596,"mc":[{"id":"1.195532879","rc":[{"atl":[[4.6,93.15]],"id":38251452}],"con":true,"img":false}]}
{"op":"mcm","clk":"5323364922","pt":1646329985696,"mc":[{"id":"1.195532879","rc":[{"atl":[[4.6,88.77],[4.4,30.7]],"id":38251452}],"con":true,"img":false}]}
{"op":"mcm","clk":"5323364943","pt":1646329985898,"mc":[{"id":"1.195532879","rc":[{"atb":[[2.64,62.17],[2.62,27.9]],"id":28753299}],"con":true,"img":false}]}
{"op":"mcm","clk":"5323364967","pt":1646329986111,"mc":[{"id":"1.195532879","rc":[{"atl":[[4.2,0]],"id":39632625}],"con":true,"img":false}]}
{"op":"mcm","clk":"5323364990","pt":1646329986315,"mc":[{"id":"1.195532879","rc":[{"atl":[[4.4,23.53]],"id":38251452}],"con":true,"img":false}]}
{"op":"mcm","clk":"5323365011","pt":1646329986477,"mc":[{"id":"1.195532879","rc":[{"atb":[[2.1,4.01]],"id":40452329}],"con":true,"img":false}]}
{"op":"mcm","clk":"5323365021","pt":1646329986576,"mc":[{"id":"1.195532879","rc":[{"atl":[[4.2,3.93]],"id":38251452}],"con":true,"img":false}]}
{"op":"mcm","clk":"5323365028","pt":1646329986684,"mc":[{"id":"1.195532879","rc":[{"atl":[[4.5,95.15],[4.6,11.11],[4.1,24.97]],"id":38251452}],"con":true,"img":false}]}
{"op":"mcm","clk":"5323365053","pt":1646329986889,"mc":[{"id":"1.195532879","rc":[{"atl":[[4.4,0]],"id":38251452}],"con":true,"img":false}]}
{"op":"mcm","clk":"5323365060","pt":1646329986990,"mc":[{"id":"1.195532879","rc":[{"atl":[[4.2,0]],"id":38251452}],"con":true,"img":false}]}
{"op":"mcm","clk":"5323365073","pt":1646329987093,"mc":[{"id":"1.195532879","rc":[{"atl":[[4.2,43.69]],"id":40452329},{"atl":[[4.3,12.12]],"id":38251452}],"con":true,"img":false}]}
{"op":"mcm","clk":"5323365086","pt":1646329987197,"mc":[{"id":"1.195532879","rc":[{"atb":[[2.24,21.1]],"id":41555107},{"atl":[[4.1,0]],"id":38251452}],"con":true,"img":false}]}
{"op":"mcm","clk":"5323365098","pt":1646329987306,"mc":[{"id":"1.195532879","rc":[{"atl":[[4.2,37.24]],"id":40452329},{"atl":[[4.1,1.57],[4.2,25]],"id":38251452},{"atl":[[4,10.66]],"id":39632625}],"con":true,"img":false}]}
{"op":"mcm","clk":"5323365107","pt":1646329987407,"mc":[{"id":"1.195532879","rc":[{"atb":[[2.26,61.21],[2.24,0]],"id":39632625},{"atl":[[4.6,0],[4.4,41.96]],"id":39632625}],"con":true,"img":false}]}
{"op":"mcm","clk":"5323365119","pt":1646329987518,"mc":[{"id":"1.195532879","rc":[{"atl":[[4.3,0],[4.2,12.5]],"id":39632625}],"con":true,"img":false}]}
{"op":"mcm","clk":"5323365139","pt":1646329987724,"mc":[{"id":"1.195532879","rc":[{"atl":[[3.95,5.39]],"id":39632625}],"con":true,"img":false}]}
{"op":"mcm","clk":"5323365171","pt":1646329988028,"mc":[{"id":"1.195532879","rc":[{"atl":[[4.1,0]],"id":38251452}],"con":true,"img":false}]}
{"op":"mcm","clk":"5323365196","pt":1646329988184,"mc":[{"id":"1.195532879","rc":[{"atl":[[4.3,0],[4.4,11.76]],"id":38251452},{"atl":[[4.1,31.68],[4.2,0]],"id":39632625}],"con":true,"img":false}]}
{"op":"mcm","clk":"5323365238","pt":1646329988605,"mc":[{"id":"1.195532879","rc":[{"atl":[[4.1,4.09]],"id":38251452},{"atl":[[5.1,4.04]],"id":39632625}],"con":true,"img":false}]}
{"op":"mcm","clk":"5323365257","pt":1646329988802,"mc":[{"id":"1.195532879","rc":[{"atl":[[5.1,0]],"id":39632625}],"con":true,"img":false}]}
{"op":"mcm","clk":"5323365288","pt":1646329989119,"mc":[{"id":"1.195532879","rc":[{"atl":[[4,16.14]],"id":38251452}],"con":true,"img":false}]}
{"op":"mcm","clk":"5323365314","pt":1646329989275,"mc":[{"id":"1.195532879","rc":[{"atl":[[4.2,0]],"id":38251452}],"con":true,"img":false}]}
{"op":"mcm","clk":"5323365362","pt":1646329989713,"mc":[{"id":"1.195532879","rc":[{"spn":3.2,"spf":"NaN","id":41555107},{"atl":[[4.2,12.5]],"id":38251452},{"spn":3.19,"spf":"NaN","id":38251452},{"atb":[[2.3,15.74],[2.34,1.99]],"id":39632625},{"spn":2.32,"spf":1.0,"id":39632625},{"spn":7.15,"spf":"NaN","id":39059999},{"spn":4.35,"spf":"NaN","id":28753299}],"con":true,"img":false}]}
{"op":"mcm","clk":"5323365381","pt":1646329989919,"mc":[{"id":"1.195532879","rc":[{"atb":[[2.3,0]],"id":39632625}],"con":true,"img":false}]}
{"op":"mcm","clk":"5323365423","pt":1646329990288,"mc":[{"id":"1.195532879","rc":[{"atl":[[4.5,28.57],[4.2,57.02]],"id":38251452}],"con":true,"img":false}]}
{"op":"mcm","clk":"5323365490","pt":1646329990908,"mc":[{"id":"1.195532879","rc":[{"atl":[[4.1,12.9],[3.9,10.66]],"id":39632625}],"con":true,"img":false}]}
{"op":"mcm","clk":"5323365497","pt":1646329991012,"mc":[{"id":"1.195532879","rc":[{"atb":[[3.55,57.67],[3.5,0]],"id":39059999}],"con":true,"img":false}]}
{"op":"mcm","clk":"5323365517","pt":1646329991218,"mc":[{"id":"1.195532879","rc":[{"atb":[[2.24,19.45]],"id":41555107}],"con":true,"img":false}]}
{"op":"mcm","clk":"5323365527","pt":1646329991279,"mc":[{"id":"1.195532879","rc":[{"atb":[[2.26,50.58]],"id":39632625}],"con":true,"img":false}]}
{"op":"mcm","clk":"5323365536","pt":1646329991386,"mc":[{"id":"1.195532879","rc":[{"atb":[[2.32,1.65]],"id":41555107},{"atl":[[4,23.99],[4.1,0]],"id":39632625}],"con":true,"img":false}]}
{"op":"mcm","clk":"5323365554","pt":1646329991591,"mc":[{"id":"1.195532879","rc":[{"atl":[[4.5,0]],"id":38251452}],"con":true,"img":false}]}
{"op":"mcm","clk":"5323365586","pt":1646329991896,"mc":[{"id":"1.195532879","rc":[{"atl":[[4,32.28]],"id":38251452}],"con":true,"img":false}]}
{"op":"mcm","clk":"5323365608","pt":1646329992102,"mc":[{"id":"1.195532879","rc":[{"atl":[[3.85,5.66]],"id":39632625}],"con":true,"img":false}]}
{"op":"mcm","clk":"5323365615","pt":1646329992203,"mc":[{"id":"1.195532879","rc":[{"atb":[[3.8,9.84]],"id":39059999}],"con":true,"img":false}]}
{"op":"mcm","clk":"5323365625","pt":1646329992311,"mc":[{"id":"1.195532879","rc":[{"atb":[[2.08,28.67]],"id":40452329},{"atb":[[2.26,31.71]],"id":38251452},{"atl":[[4,13.33],[3.8,5.66],[3.9,0]],"id":39632625},{"atb":[[3.7,0],[3.8,15.32]],"id":39059999}],"con":true,"img":false}]}
{"op":"mcm","clk":"5323365644","pt":1646329992521,"mc":[{"id":"1.195532879","rc":[{"atb":[[3.45,30.54],[3.55,22.13]],"id":39059999}],"con":true,"img":false}]}
{"op":"mcm","clk":"5323365727","pt":1646329993398,"mc":[{"id":"1.195532879","rc":[{"atb":[[3.75,0]],"id":39059999}],"con":true,"img":false}]}
{"op":"mcm","clk":"5323365736","pt":1646329993497,"mc":[{"id":"1.195532879","rc":[{"atb":[[3.85,1.99],[3.35,5.6]],"id":39059999}],"con":true,"img":false}]}
{"op":"mcm","clk":"5323365748","pt":1646329993618,"mc":[{"id":"1.195532879","rc":[{"atb":[[3.7,5.59]],"id":39059999}],"con":true,"img":false}]}
{"op":"mcm","clk":"5323365756","pt":1646329993713,"mc":[{"id":"1.195532879","rc":[{"atb":[[3.35,0]],"id":39059999}],"con":true,"img":false}]}
{"op":"mcm","clk":"5323365797","pt":1646329994122,"mc":[{"id":"1.195532879","rc":[{"atb":[[3.7,0]],"id":39059999}],"con":true,"img":false}]}
{"op":"mcm","clk":"5323365855","pt":1646329994597,"mc":[{"id":"1.195532879","rc":[{"atl":[[4,0],[3.9,13.79]],"id":39632625}],"con":true,"img":false}]}
{"op":"mcm","clk":"5323365863","pt":1646329994693,"mc":[{"id":"1.195532879","rc":[{"atl":[[6.8,22.24]],"id":28753299}],"con":true,"img":false}]}
{"op":"mcm","clk":"5323365962","pt":1646329995681,"mc":[{"id":"1.195532879","rc":[{"atb":[[2.26,26.22]],"id":39632625}],"con":true,"img":false}]}
{"op":"mcm","clk":"5323365974","pt":1646329995797,"mc":[{"id":"1.195532879","rc":[{"atb":[[2.18,12.39]],"id":41555107}],"con":true,"img":false}]}
{"op":"mcm","clk":"5323365986","pt":1646329995898,"mc":[{"id":"1.195532879","rc":[{"atb":[[2.18,46.17]],"id":41555107},{"atl":[[3.95,0]],"id":39632625}],"con":true,"img":false}]}
{"op":"mcm","clk":"5323365994","pt":1646329995990,"mc":[{"id":"1.195532879","rc":[{"atb":[[2.16,47.06]],"id":41555107}],"con":true,"img":false}]}
{"op":"mcm","clk":"5323366018","pt":1646329996197,"mc":[{"id":"1.195532879","rc":[{"atl":[[3.9,15.92]],"id":39632625},{"atl":[[20,0]],"id":28753299}],"con":true,"img":false}]}
{"op":"mcm","clk":"5323366052","pt":1646329996510,"mc":[{"id":"1.195532879","rc":[{"atl":[[3.9,13.79]],"id":39632625}],"con":true,"img":false}]}
{"op":"mcm","clk":"5323366088","pt":1646329996821,"mc":[{"id":"1.195532879","rc":[{"atb":[[2.06,0]],"id":41555107},{"atb":[[2.28,4.01]],"id":39632625}],"con":true,"img":false}]}
{"op":"mcm","clk":"5323366124","pt":1646329997074,"mc":[{"id":"1.195532879","rc":[{"atb":[[2.3,21.6]],"id":41555107}],"con":true,"img":false}]}
{"op":"mcm","clk":"5323366151","pt":1646329997290,"mc":[{"id":"1.195532879","rc":[{"atb":[[2.24,0]],"id":41555107},{"atb":[[2.1,25.16]],"id":40452329}],"con":true,"img":false}]}
{"op":"mcm","clk":"5323366161","pt":1646329997388,"mc":[{"id":"1.195532879","rc":[{"atb":[[2.08,0]],"id":40452329},{"atl":[[3.9,27.58]],"id":39632625}],"con":true,"img":false}]}
{"op":"mcm","clk":"5323366182","pt":1646329997595,"mc":[{"id":"1.195532879","rc":[{"atl":[[3.8,0]],"id":39632625}],"con":true,"img":false}]}
{"op":"mcm","clk":"5323366204","pt":1646329997802,"mc":[{"id":"1.195532879","rc":[{"atb":[[2.04,5.74],[2.16,52.94]],"id":41555107}],"con":true,"img":false}]}
{"op":"mcm","clk":"5323366223","pt":1646329998009,"mc":[{"id":"1.195532879","rc":[{"atb":[[2.16,47.06]],"id":41555107}],"con":true,"img":false}]}
{"op":"mcm","clk":"5323366242","pt":1646329998214,"mc":[{"id":"1.195532879","rc":[{"atb":[[2.04,2.5]],"id":41555107}],"con":true,"img":false}]}
{"op":"mcm","clk":"5323366325","pt":1646329999004,"mc":[{"id":"1.195532879","rc":[{"atl":[[3.95,13.56],[3.9,13.79]],"id":39632625}],"con":true,"img":false}]}
{"op":"mcm","clk":"5323366351","pt":1646329999311,"mc":[{"id":"1.195532879","rc":[{"atl":[[3.8,4.67]],"id":39632625}],"con":true,"img":false}]}
{"op":"mcm","clk":"5323366368","pt":1646329999524,"mc":[{"id":"1.195532879","rc":[{"atb":[[2.18,7.13]],"id":40452329},{"atl":[[4.1,0],[4.4,29.41],[4.7,5.62]],"id":38251452}],"con":true,"img":false}]}
{"op":"mcm","clk":"5323366390","pt":1646329999736,"mc":[{"id":"1.195532879","rc":[{"atl":[[4,16.14],[4.4,142.34],[4.2,12.5],[4.7,2.5]],"id":38251452},{"atl":[[3.95,0],[3.9,27.58]],"id":39632625}],"con":true,"img":false}]}
{"op":"mcm","clk":"5323366399","pt":1646329999814,"mc":[{"id":"1.195532879","rc":[{"atb":[[2.22,81.97],[2.18,0]],"id":38251452},{"atl":[[3.8,0]],"id":39632625},{"atb":[[3.55,0],[3.65,22.13]],"id":39059999},{"atb":[[2.64,28.84],[2.62,76.05]],"id":28753299}],"con":true,"img":false}]}
{"op":"mcm","clk":"5323366408","pt":1646329999889,"mc":[{"id":"1.195532879","rc":[{"atl":[[4,0]],"id":38251452},{"atb":[[2.62,61.23]],"id":28753299}],"con":true,"img":false}]}
{"op":"mcm","clk":"5323366415","pt":1646329999992,"mc":[{"id":"1.195532879","rc":[{"atl":[[4.6,38.89],[4.1,21.48],[4.4,112.93]],"id":38251452}],"con":true,"img":false}]}
{"op":"mcm","clk":"5323366478","pt":1646330000619,"mc":[{"id":"1.195532879","rc":[{"atl":[[3.8,4.67]],"id":39632625}],"con":true,"img":false}]}
{"op":"mcm","clk":"5323366510","pt":1646330000928,"mc":[{"id":"1.195532879","rc":[{"atl":[[4.5,8.54]],"id":39632625}],"con":true,"img":false}]}
{"op":"mcm","clk":"5323366520","pt":1646330001034,"mc":[{"id":"1.195532879","rc":[{"atl":[[3.8,0]],"id":39632625}],"con":true,"img":false}]}
{"op":"mcm","clk":"5323366527","pt":1646330001132,"mc":[{"id":"1.195532879","rc":[{"atl":[[4.5,0],[3.75,5.12]],"id":39632625},{"atb":[[3.8,13.66]],"id":39059999}],"con":true,"img":false}]}
{"op":"mcm","clk":"5323366535","pt":1646330001187,"mc":[{"id":"1.195532879","rc":[{"atb":[[2.26,0],[2.28,16.11]],"id":39632625}],"con":true,"img":false}]}
{"op":"mcm","clk":"5323366544","pt":1646330001298,"mc":[{"id":"1.195532879","rc":[{"atl":[[3.85,0],[4.4,0],[3.9,45.86],[3.75,0]],"id":39632625},{"atb":[[3.9,1.65]],"id":39059999}],"con":true,"img":false}]}
{"op":"mcm","clk":"5323366553","pt":1646330001397,"mc":[{"id":"1.195532879","rc":[{"atb":[[2.16,0]],"id":40452329},{"atl":[[3.85,5.46]],"id":39632625}],"con":true,"img":false}]}
{"op":"mcm","clk":"5323366564","pt":1646330001498,"mc":[{"id":"1.195532879","rc":[{"atb":[[2.2,1.99]],"id":40452329}],"con":true,"img":false}]}
{"op":"mcm","clk":"5323366607","pt":1646330002025,"mc":[{"id":"1.195532879","rc":[{"atb":[[2.16,3.25]],"id":40452329}],"con":true,"img":false}]}
{"op":"mcm","clk":"5323366620","pt":1646330002229,"mc":[{"id":"1.195532879","rc":[{"atb":[[2.2,30.24]],"id":41555107},{"atb":[[2.1,0],[2.16,0]],"id":40452329}],"con":true,"img":false}]}
{"op":"mcm","clk":"5323366629","pt":1646330002336,"mc":[{"id":"1.195532879","rc":[{"atb":[[2.18,12.39],[2.16,133.87]],"id":41555107},{"atl":[[4.3,12.12],[4.2,0]],"id":38251452},{"atl":[[3.95,13.56],[3.9,32.07]],"id":39632625}],"con":true,"img":false}]}
{"op":"mcm","clk":"5323366637","pt":1646330002384,"mc":[{"id":"1.195532879","rc":[{"atb":[[2.22,2.15],[2.14,0]],"id":40452329}],"con":true,"img":false}]}
{"op":"mcm","clk":"5323366646","pt":1646330002538,"mc":[{"id":"1.195532879","rc":[{"atb":[[2.16,47.06]],"id":41555107},{"atl":[[3.95,47.46],[3.9,18.28]],"id":39632625}],"con":true,"img":false}]}
{"op":"mcm","clk":"5323366660","pt":1646330002697,"mc":[{"id":"1.195532879","rc":[{"atb":[[2.2,0]],"id":40452329}],"con":true,"img":false}]}
{"op":"mcm","clk":"5323366674","pt":1646330002804,"mc":[{"id":"1.195532879","rc":[{"atb":[[2.24,1.99]],"id":40452329}],"con":true,"img":false}]}
{"op":"mcm","clk":"5323366684","pt":1646330002903,"mc":[{"id":"1.195532879","rc":[{"atb":[[1.98,5],[2.04,2.5]],"id":40452329}],"con":true,"img":false}]}
{"op":"mcm","clk":"5323366705","pt":1646330003115,"mc":[{"id":"1.195532879","rc":[{"atb":[[2.36,7.13]],"id":39632625}],"con":true,"img":false}]}
{"op":"mcm","clk":"5323366764","pt":1646330003686,"mc":[{"id":"1.195532879","rc":[{"atb":[[2.34,0]],"id":39632625}],"con":true,"img":false}]}
{"op":"mcm","clk":"5323366778","pt":1646330003840,"mc":[{"id":"1.195532879","rc":[{"atb":[[2.38,1.99]],"id":39632625}],"con":true,"img":false}]}
{"op":"mcm","clk":"5323366855","pt":1646330004515,"mc":[{"id":"1.195532879","rc":[{"atl":[[7.2,24.19]],"id":28753299}],"con":true,"img":false}]}
{"op":"mcm","clk":"5323366868","pt":1646330004624,"mc":[{"id":"1.195532879","rc":[{"atb":[[2.28,12.1]],"id":39632625}],"con":true,"img":false}]}
{"op":"mcm","clk":"5323367002","pt":1646330005921,"mc":[{"id":"1.195532879","rc":[{"atb":[[3.9,9.84]],"id":39059999}],"con":true,"img":false}]}
{"op":"mcm","clk":"5323367020","pt":1646330006124,"mc":[{"id":"1.195532879","rc":[{"atb":[[3.8,5.47]],"id":39059999}],"con":true,"img":false}]}
{"op":"mcm","clk":"5323367032","pt":1646330006234,"mc":[{"id":"1.195532879","rc":[{"atb":[[3.45,2.5],[3.65,54.01]],"id":39059999}],"con":true,"img":false}]}
{"op":"mcm","clk":"5323367044","pt":1646330006338,"mc":[{"id":"1.195532879","rc":[{"atb":[[2.18,0]],"id":41555107},{"atb":[[2.18,1.65]],"id":40452329},{"atb":[[2.26,0]],"id":38251452},{"atl":[[4.6,11.11],[4.4,142.34]],"id":38251452},{"atb":[[3.8,0]],"id":39059999}],"con":true,"img":false}]}
{"op":"mcm","clk":"5323367196","pt":1646330007636,"mc":[{"id":"1.195532879","rc":[{"atb":[[2.08,6.22]],"id":40452329},{"atl":[[3.95,89.9],[3.9,0]],"id":39632625}],"con":true,"img":false}]}
{"op":"mcm","clk":"5323367222","pt":1646330007855,"mc":[{"id":"1.195532879","rc":[{"atl":[[3.95,56],[4.9,28.14]],"id":39632625}],"con":true,"img":false}]}
{"op":"mcm","clk":"5323367236","pt":1646330007896,"mc":[{"id":"1.195532879","rc":[{"atb":[[3.85,0]],"id":39059999}],"con":true,"img":false}]}
{"op":"mcm","clk":"5323367247","pt":1646330008001,"mc":[{"id":"1.195532879","rc":[{"atb":[[2,3.34]],"id":40452329},{"atb":[[3.95,1.99]],"id":39059999}],"con":true,"img":false}]}
{"op":"mcm","clk":"5323367273","pt":1646330008209,"mc":[{"id":"1.195532879","rc":[{"atb":[[2,0]],"id":40452329}],"con":true,"img":false}]}
{"op":"mcm","clk":"5323367291","pt":1646330008415,"mc":[{"id":"1.195532879","rc":[{"atl":[[3.95,37.01]],"id":40452329}],"con":true,"img":false}]}
{"op":"mcm","clk":"5323367301","pt":1646330008519,"mc":[{"id":"1.195532879","rc":[{"atl":[[4.2,68.49]],"id":40452329}],"con":true,"img":false}]}
{"op":"mcm","clk":"5323367313","pt":1646330008624,"mc":[{"id":"1.195532879","rc":[{"atl":[[3.95,3.11]],"id":40452329}],"con":true,"img":false}]}
{"op":"mcm","clk":"5323367413","pt":1646330009515,"mc":[{"id":"1.195532879","rc":[{"atb":[[2.16,113.96]],"id":41555107}],"con":true,"img":false}]}
{"op":"mcm","clk":"5323367433","pt":1646330009716,"mc":[{"id":"1.195532879","rc":[{"atl":[[3.85,5.54]],"id":40452329}],"con":true,"img":false}]}
{"op":"mcm","clk":"5323367458","pt":1646330009924,"mc":[{"id":"1.195532879","rc":[{"atl":[[3.8,3.95],[4.1,39.74],[4.2,31.25]],"id":40452329}],"con":true,"img":false}]}
{"op":"mcm","clk":"5323367471","pt":1646330010038,"mc":[{"id":"1.195532879","rc":[{"atl":[[3.95,13.56],[4.1,26.84]],"id":40452329}],"con":true,"img":false}]}
{"op":"mcm","clk":"5323367513","pt":1646330010456,"mc":[{"id":"1.195532879","rc":[{"atl":[[3.95,0],[3.9,13.79]],"id":40452329}],"con":true,"img":false}]}
{"op":"mcm","clk":"5323367524","pt":1646330010550,"mc":[{"id":"1.195532879","rc":[{"atb":[[2.2,0]],"id":41555107}],"con":true,"img":false}]}
{"op":"mcm","clk":"5323367535","pt":1646330010659,"mc":[{"id":"1.195532879","rc":[{"atb":[[2.24,12.77]],"id":39632625}],"con":true,"img":false}]}
{"op":"mcm","clk":"5323367567","pt":1646330010925,"mc":[{"id":"1.195532879","rc":[{"atb":[[2.06,33.8]],"id":40452329}],"con":true,"img":false}]}
{"op":"mcm","clk":"5323367598","pt":1646330011235,"mc":[{"id":"1.195532879","rc":[{"atb":[[2.18,0]],"id":40452329},{"atb":[[2.36,5.47]],"id":39632625},{"atb":[[3.9,8.19]],"id":39059999}],"con":true,"img":false}]}
{"op":"mcm","clk":"5323367620","pt":1646330011450,"mc":[{"id":"1.195532879","rc":[{"atb":[[2.26,1.65]],"id":40452329},{"atb":[[4,1.65]],"id":39059999}],"con":true,"img":false}]}
{"op":"mcm","clk":"5323367680","pt":1646330011921,"mc":[{"id":"1.195532879","rc":[{"atl":[[4.5,28.57]],"id":38251452},{"atl":[[4.1,32.26]],"id":39632625}],"con":true,"img":false}]}
{"op":"mcm","clk":"5323367693","pt":1646330012026,"mc":[{"id":"1.195532879","rc":[{"atl":[[4.1,64.52],[4.9,2.5]],"id":39632625}],"con":true,"img":false}]}
{"op":"mcm","clk":"5323367719","pt":1646330012241,"mc":[{"id":"1.195532879","rc":[{"atl":[[5.6,0],[5.2,0],[5.4,0]],"id":39632625}],"con":true,"img":false}]}
{"op":"mcm","clk":"5323367878","pt":1646330013593,"mc":[{"id":"1.195532879","rc":[{"atb":[[2.06,34.51]],"id":41555107}],"con":true,"img":false}]}
{"op":"mcm","clk":"5323367927","pt":1646330013953,"mc":[{"id":"1.195532879","rc":[{"atl":[[3.95,13.56],[4.1,103.64]],"id":39632625}],"con":true,"img":false}]}
{"op":"mcm","clk":"5323367948","pt":1646330014161,"mc":[{"id":"1.195532879","rc":[{"atl":[[7.6,37.88]],"id":28753299}],"con":true,"img":false}]}
{"op":"mcm","clk":"5323367965","pt":1646330014369,"mc":[{"id":"1.195532879","rc":[{"atl":[[19,0]],"id":28753299}],"con":true,"img":false}]}
{"op":"mcm","clk":"5323367987","pt":1646330014516,"mc":[{"id":"1.195532879","rc":[{"atb":[[2.36,0]],"id":39632625}],"con":true,"img":false}]}
{"op":"mcm","clk":"5323367999","pt":1646330014636,"mc":[{"id":"1.195532879","rc":[{"atb":[[2.22,38.76]],"id":41555107},{"atb":[[2.1,13.46]],"id":40452329},{"atb":[[2.26,31.71]],"id":38251452},{"atb":[[3.7,17.51]],"id":39059999}],"con":true,"img":false}]}
{"op":"mcm","clk":"5323368013","pt":1646330014730,"mc":[{"id":"1.195532879","rc":[{"atb":[[2.24,43.86],[2.28,0]],"id":39632625}],"con":true,"img":false}]}
{"op":"mcm","clk":"5323368031","pt":1646330014849,"mc":[{"id":"1.195532879","rc":[{"atl":[[3.8,9.49],[4.2,0]],"id":40452329}],"con":true,"img":false}]}
{"op":"mcm","clk":"5323368043","pt":1646330014939,"mc":[{"id":"1.195532879","rc":[{"atb":[[2.38,0]],"id":39632625}],"con":true,"img":false}]}
{"op":"mcm","clk":"5323368057","pt":1646330015058,"mc":[{"id":"1.195532879","rc":[{"atb":[[2.34,1.99]],"id":39632625}],"con":true,"img":false}]}
{"op":"mcm","clk":"5323368383","pt":1646330017823,"mc":[{"id":"1.195532879","rc":[{"atl":[[4.2,3.73]],"id":40452329}],"con":true,"img":false}]}
{"op":"mcm","clk":"5323368420","pt":1646330018131,"mc":[{"id":"1.195532879","rc":[{"atb":[[2.06,0]],"id":41555107},{"atb":[[2.08,0]],"id":40452329}],"con":true,"img":false}]}
{"op":"mcm","clk":"5323368445","pt":1646330018335,"mc":[{"id":"1.195532879","rc":[{"atl":[[4.2,0]],"id":40452329}],"con":true,"img":false}]}
{"op":"mcm","clk":"5323368505","pt":1646330018803,"mc":[{"id":"1.195532879","rc":[{"atl":[[3.85,0]],"id":40452329}],"con":true,"img":false}]}
{"op":"mcm","clk":"5323368513","pt":1646330018910,"mc":[{"id":"1.195532879","rc":[{"atl":[[4.1,57.14],[3.8,3.95]],"id":40452329}],"con":true,"img":false}]}
{"op":"mcm","clk":"5323368528","pt":1646330019121,"mc":[{"id":"1.195532879","rc":[{"atl":[[3.8,0]],"id":40452329}],"con":true,"img":false}]}
{"op":"mcm","clk":"5323368538","pt":1646330019227,"mc":[{"id":"1.195532879","rc":[{"atl":[[4.3,60.6],[3.85,4.58],[4.1,0]],"id":40452329}],"con":true,"img":false}]}
{"op":"mcm","clk":"5323368553","pt":1646330019330,"mc":[{"id":"1.195532879","rc":[{"atl":[[4.3,115.12]],"id":40452329},{"atb":[[4,9.84]],"id":39059999}],"con":true,"img":false}]}
{"op":"mcm","clk":"5323368578","pt":1646330019549,"mc":[{"id":"1.195532879","rc":[{"atb":[[3.9,0]],"id":39059999}],"con":true,"img":false}]}
{"op":"mcm","clk":"5323368590","pt":1646330019645,"mc":[{"id":"1.195532879","rc":[{"atb":[[3.7,42.55],[3.65,22.13]],"id":39059999}],"con":true,"img":false}]}
{"op":"mcm","clk":"5323368612","pt":1646330019855,"mc":[{"id":"1.195532879","rc":[{"atl":[[4,7.97]],"id":40452329},{"atb":[[3.95,0],[3.4,6.22]],"id":39059999}],"con":true,"img":false}]}
{"op":"mcm","clk":"5323368624","pt":1646330019908,"mc":[{"id":"1.195532879","rc":[{"atl":[[3.75,5.74],[3.95,13.56],[3.9,0]],"id":40452329},{"atb":[[4.1,1.99]],"id":39059999}],"con":true,"img":false}]}
{"op":"mcm","clk":"5323368633","pt":1646330020011,"mc":[{"id":"1.195532879","rc":[{"atl":[[4,0]],"id":40452329},{"atb":[[2.26,10.35]],"id":39632625}],"con":true,"img":false}]}
{"op":"mcm","clk":"5323368669","pt":1646330020328,"mc":[{"id":"1.195532879","rc":[{"atb":[[3.4,0]],"id":39059999}],"con":true,"img":false}]}
{"op":"mcm","clk":"5323368685","pt":1646330020535,"mc":[{"id":"1.195532879","rc":[{"atb":[[3.85,5.08]],"id":39059999}],"con":true,"img":false}]}
{"op":"mcm","clk":"5323368694","pt":1646330020640,"mc":[{"id":"1.195532879","rc":[{"atl":[[3.85,18.62],[3.95,0]],"id":40452329},{"atb":[[2.6,62.5],[2.62,27.9]],"id":28753299}],"con":true,"img":false}]}
{"op":"mcm","clk":"5323368703","pt":1646330020737,"mc":[{"id":"1.195532879","rc":[{"atb":[[3.85,0]],"id":39059999}],"con":true,"img":false}]}
{"op":"mcm","clk":"5323368750","pt":1646330021102,"mc":[{"id":"1.195532879","rc":[{"atb":[[4,8.19]],"id":39059999}],"con":true,"img":false}]}
{"op":"mcm","clk":"5323368770","pt":1646330021310,"mc":[{"id":"1.195532879","rc":[{"atb":[[2.36,1.65]],"id":39632625},{"atb":[[4.2,1.65]],"id":39059999}],"con":true,"img":false}]}
{"op":"mcm","clk":"5323368777","pt":1646330021415,"mc":[{"id":"1.195532879","rc":[{"atl":[[4.7,43.04]],"id":38251452},{"atl":[[4.3,45.45]],"id":39632625}],"con":true,"img":false}]}
{"op":"mcm","clk":"5323368970","pt":1646330023337,"mc":[{"id":"1.195532879","rc":[{"atl":[[3.7,5.93]],"id":40452329}],"con":true,"img":false}]}
{"op":"mcm","clk":"5323369000","pt":1646330023540,"mc":[{"id":"1.195532879","rc":[{"atl":[[4.3,60.6],[3.85,37.38]],"id":40452329}],"con":true,"img":false}]}
{"op":"mcm","clk":"5323369016","pt":1646330023663,"mc":[{"id":"1.195532879","rc":[{"atb":[[2.24,31.09]],"id":39632625}],"con":true,"img":false}]}
{"op":"mcm","clk":"5323369027","pt":1646330023750,"mc":[{"id":"1.195532879","rc":[{"atb":[[2.18,31]],"id":41555107},{"atb":[[2.12,5.11]],"id":40452329}],"con":true,"img":false}]}
{"op":"mcm","clk":"5323369051","pt":1646330023910,"mc":[{"id":"1.195532879","rc":[{"atb":[[2.18,98.85],[2.16,47.05]],"id":41555107}],"con":true,"img":false}]}
{"op":"mcm","clk":"5323369062","pt":1646330024013,"mc":[{"id":"1.195532879","rc":[{"atl":[[3.85,23.34],[3.8,14.29]],"id":40452329}],"con":true,"img":false}]}
{"op":"mcm","clk":"5323369084","pt":1646330024232,"mc":[{"id":"1.195532879","rc":[{"atb":[[2.12,18.67],[2.06,17.03]],"id":40452329}],"con":true,"img":false}]}
{"op":"mcm","clk":"5323369211","pt":1646330025315,"mc":[{"id":"1.195532879","rc":[{"atl":[[4.3,30.3],[3.7,11.86]],"id":40452329}],"con":true,"img":false}]}
{"op":"mcm","clk":"5323369220","pt":1646330025419,"mc":[{"id":"1.195532879","rc":[{"atl":[[4.6,0],[4.4,112.93]],"id":38251452}],"con":true,"img":false}]}
{"op":"mcm","clk":"5323369248","pt":1646330025736,"mc":[{"id":"1.195532879","rc":[{"atb":[[2.12,5.11]],"id":40452329}],"con":true,"img":false}]}
{"op":"mcm","clk":"5323369310","pt":1646330026250,"mc":[{"id":"1.195532879","rc":[{"atb":[[3.7,25.04]],"id":39059999}],"con":true,"img":false}]}
{"op":"mcm","clk":"5323369335","pt":1646330026411,"mc":[{"id":"1.195532879","rc":[{"atb":[[2.28,4.01]],"id":39632625}],"con":true,"img":false}]}
{"op":"mcm","clk":"5323369345","pt":1646330026519,"mc":[{"id":"1.195532879","rc":[{"atb":[[1.98,0],[2.04,0],[1.94,0]],"id":41555107}],"con":true,"img":false}]}
{"op":"mcm","clk":"5323369364","pt":1646330026723,"mc":[{"id":"1.195532879","rc":[{"atb":[[2.6,0],[2.62,61.23]],"id":28753299}],"con":true,"img":false}]}
{"op":"mcm","clk":"5323369375","pt":1646330026831,"mc":[{"id":"1.195532879","rc":[{"atl":[[4.9,0]],"id":39632625}],"con":true,"img":false}]}
{"op":"mcm","clk":"5323369504","pt":1646330028028,"mc":[{"id":"1.195532879","rc":[{"atb":[[2.24,0],[2.28,15.86]],"id":39632625}],"con":true,"img":false}]}
{"op":"mcm","clk":"5323369577","pt":1646330028856,"mc":[{"id":"1.195532879","rc":[{"atl":[[4,2.11]],"id":41555107},{"atl":[[3.65,2.63]],"id":40452329},{"atl":[[4,2.11]],"id":38251452},{"atl":[[3.8,2.39]],"id":39632625},{"atl":[[10,1.13]],"id":39059999},{"atl":[[5.9,1.76]],"id":28753299}],"con":true,"img":false}]}
{"op":"mcm","clk":"5323369592","pt":1646330029013,"mc":[{"id":"1.195532879","rc":[{"atl":[[4,13.43],[4.3,90.4],[3.95,19.45],[4.4,0]],"id":41555107},{"atl":[[3.75,0]],"id":40452329},{"atl":[[4,14.23],[4.3,55.88],[3.95,16.41],[4.4,0]],"id":38251452},{"atl":[[3.95,31.78],[4.1,32.26],[3.8,7.85],[3.75,3.41]],"id":39632625},{"atl":[[10,4.94],[11.5,25.65],[12.5,5],[9.8,4.35]],"id":39059999},{"atl":[[6.6,40.5],[5.9,23.31]],"id":28753299}],"con":true,"img":false}]}
{"op":"mcm","clk":"5323369601","pt":1646330029119,"mc":[{"id":"1.195532879","rc":[{"atl":[[4.1,0],[3.9,2.25]],"id":41555107},{"atl":[[4.1,0],[3.9,2.25]],"id":38251452},{"atl":[[3.85,0],[3.7,2.54]],"id":39632625},{"atl":[[9.6,1.24],[10.5,2.49]],"id":39059999},{"atl":[[6.4,68.12],[6,2.5],[6.6,0]],"id":28753299}],"con":true,"img":false}]}
{"op":"mcm","clk":"5323369610","pt":1646330029221,"mc":[{"id":"1.195532879","rc":[{"atb":[[2.22,0]],"id":41555107},{"atl":[[4.3,94.15]],"id":41555107},{"atb":[[2.1,0]],"id":40452329},{"atl":[[4.3,61.57]],"id":38251452},{"atl":[[3.95,38.56],[4.2,3.42]],"id":39632625},{"atl":[[12,4.93]],"id":39059999},{"atl":[[6.8,25.83]],"id":28753299}],"con":true,"img":false}]}
{"op":"mcm","clk":"5323369617","pt":1646330029325,"mc":[{"id":"1.195532879","rc":[{"atl":[[4.3,90.4],[4.5,4.79]],"id":41555107},{"atl":[[3.8,0],[3.75,14.55]],"id":40452329},{"atl":[[4,27.56]],"id":38251452},{"atl":[[3.95,31.78],[3.8,22.14],[4.2,0]],"id":39632625},{"atl":[[10,9.38],[11.5,21.84]],"id":39059999},{"atl":[[6.4,60.71],[6.2,7.69],[6.6,3.45]],"id":28753299}],"con":true,"img":false}]}
{"op":"mcm","clk":"5323369628","pt":1646330029431,"mc":[{"id":"1.195532879","rc":[{"atl":[[4,26.76],[4.3,78.28]],"id":41555107}],"con":true,"img":false}]}
{"op":"mcm","clk":"5323369638","pt":1646330029532,"mc":[{"id":"1.195532879","rc":[{"atl":[[4.5,0]],"id":41555107}],"con":true,"img":false}]}
{"op":"mcm","clk":"5323369646","pt":1646330029638,"mc":[{"id":"1.195532879","rc":[{"atb":[[2.2,6.32]],"id":41555107},{"atl":[[4.3,55.88]],"id":38251452},{"atl":[[12,0]],"id":39059999},{"atl":[[6.8,22.24]],"id":28753299}],"con":true,"img":false}]}
{"op":"mcm","clk":"5323369655","pt":1646330029743,"mc":[{"id":"1.195532879","rc":[{"atb":[[2.04,3.76]],"id":41555107}],"con":true,"img":false}]}
{"op":"mcm","clk":"5323369664","pt":1646330029843,"mc":[{"id":"1.195532879","rc":[{"atb":[[2.2,0]],"id":41555107}],"con":true,"img":false}]}
{"op":"mcm","clk":"5323369675","pt":1646330029949,"mc":[{"id":"1.195532879","rc":[{"atb":[[2.04,0]],"id":41555107},{"atl":[[6.6,0]],"id":28753299}],"con":true,"img":false}]}
{"op":"mcm","clk":"5323369685","pt":1646330030052,"mc":[{"id":"1.195532879","rc":[{"atb":[[2.18,31],[2.16,109.6]],"id":41555107}],"con":true,"img":false}]}
{"op":"mcm","clk":"5323369761","pt":1646330030733,"mc":[{"id":"1.195532879","rc":[{"atb":[[2.24,47.06],[2.16,62.54]],"id":41555107},{"atl":[[4.6,0],[5,0],[5.4,0]],"id":40452329},{"atb":[[2.22,0],[2.26,63.42]],"id":38251452},{"atl":[[5.1,0],[5.5,0],[4.7,40.54]],"id":38251452},{"atb":[[2.34,5.52],[2.16,0]],"id":39632625},{"atb":[[3.45,0],[3.7,27.54]],"id":39059999}],"con":true,"img":false}]}
{"op":"mcm","clk":"5323369773","pt":1646330030836,"mc":[{"id":"1.195532879","rc":[{"atb":[[2.22,7.5]],"id":39632625}],"con":true,"img":false}]}
{"op":"mcm","clk":"5323369927","pt":1646330032395,"mc":[{"id":"1.195532879","rc":[{"atl":[[3.6,3.59]],"id":40452329}],"con":true,"img":false}]}
{"op":"mcm","clk":"5323369938","pt":1646330032501,"mc":[{"id":"1.195532879","rc":[{"atl":[[3.85,0],[3.75,32.07]],"id":40452329},{"atb":[[4.2,6.41]],"id":39059999}],"con":true,"img":false}]}
{"op":"mcm","clk":"5323369947","pt":1646330032610,"mc":[{"id":"1.195532879","rc":[{"atl":[[3.7,5.93]],"id":40452329}],"con":true,"img":false}]}
{"op":"mcm","clk":"5323369960","pt":1646330032711,"mc":[{"id":"1.195532879","rc":[{"atb":[[4,0]],"id":39059999}],"con":true,"img":false}]}
{"op":"mcm","clk":"5323369971","pt":1646330032814,"mc":[{"id":"1.195532879","rc":[{"atb":[[2.64,62.17],[2.62,27.9]],"id":28753299}],"con":true,"img":false}]}
{"op":"mcm","clk":"5323369983","pt":1646330032914,"mc":[{"id":"1.195532879","rc":[{"atl":[[3.7,20.74],[3.75,17.52]],"id":40452329},{"atb":[[3.7,2.5],[3.65,41.88]],"id":39059999}],"con":true,"img":false}]}
{"op":"mcm","clk":"5323369994","pt":1646330032972,"mc":[{"id":"1.195532879","rc":[{"atb":[[2.26,31.71]],"id":38251452},{"atb":[[2.26,0]],"id":39632625},{"atb":[[4.2,11.89]],"id":39059999}],"con":true,"img":false}]}
{"op":"mcm","clk":"5323370008","pt":1646330033078,"mc":[{"id":"1.195532879","rc":[{"atl":[[3.6,7.74]],"id":40452329}],"con":true,"img":false}]}
{"op":"mcm","clk":"5323370016","pt":1646330033180,"mc":[{"id":"1.195532879","rc":[{"atl":[[3.55,7.74]],"id":40452329},{"atb":[[4.1,0]],"id":39059999}],"con":true,"img":false}]}
{"op":"mcm","clk":"5323370026","pt":1646330033285,"mc":[{"id":"1.195532879","rc":[{"atl":[[3.7,14.81]],"id":40452329},{"atb":[[4.3,1.99]],"id":39059999}],"con":true,"img":false}]}
{"op":"mcm","clk":"5323370038","pt":1646330033390,"mc":[{"id":"1.195532879","rc":[{"atl":[[3.7,0],[3.65,17.72]],"id":40452329}],"con":true,"img":false}]}
{"op":"mcm","clk":"5323370049","pt":1646330033491,"mc":[{"id":"1.195532879","rc":[{"atb":[[2.18,0]],"id":41555107},{"atb":[[2.12,0]],"id":40452329},{"atl":[[3.6,3.58]],"id":40452329}],"con":true,"img":false}]}
{"op":"mcm","clk":"5323370076","pt":1646330033802,"mc":[{"id":"1.195532879","rc":[{"atl":[[3.55,11.99]],"id":40452329}],"con":true,"img":false}]}
{"op":"mcm","clk":"5323370194","pt":1646330035104,"mc":[{"id":"1.195532879","rc":[{"atl":[[4,15.44],[3.9,21.7]],"id":41555107},{"atl":[[4,15.44],[3.9,18.66]],"id":38251452},{"atl":[[3.7,5.95],[3.8,16.68]],"id":39632625},{"atl":[[9.6,5.59],[10,5.57]],"id":39059999}],"con":true,"img":false}]}
{"op":"mcm","clk":"5323370265","pt":1646330035776,"mc":[{"id":"1.195532879","rc":[{"atl":[[3.5,2.9]],"id":40452329}],"con":true,"img":false}]}
{"op":"mcm","clk":"5323370282","pt":1646330035886,"mc":[{"id":"1.195532879","rc":[{"atb":[[2.2,62.54]],"id":41555107},{"atb":[[2,7.78],[1.95,0]],"id":40452329}],"con":true,"img":false}]}
{"op":"mcm","clk":"5323370290","pt":1646330035985,"mc":[{"id":"1.195532879","rc":[{"atb":[[2.24,0]],"id":41555107}],"con":true,"img":false}]}
{"op":"mcm","clk":"5323370300","pt":1646330036096,"mc":[{"id":"1.195532879","rc":[{"atb":[[2.28,11.85]],"id":39632625}],"con":true,"img":false}]}
{"op":"mcm","clk":"5323370313","pt":1646330036194,"mc":[{"id":"1.195532879","rc":[{"atl":[[3.55,7.74]],"id":40452329}],"con":true,"img":false}]}
{"op":"mcm","clk":"5323370322","pt":1646330036307,"mc":[{"id":"1.195532879","rc":[{"atl":[[3.6,18.97],[3.65,2.63]],"id":40452329}],"con":true,"img":false}]}
{"op":"mcm","clk":"5323370330","pt":1646330036405,"mc":[{"id":"1.195532879","rc":[{"atl":[[3.45,3.8]],"id":40452329}],"con":true,"img":false}]}
{"op":"mcm","clk":"5323370339","pt":1646330036510,"mc":[{"id":"1.195532879","rc":[{"atl":[[3.6,15.38]],"id":40452329}],"con":true,"img":false}]}
{"op":"mcm","clk":"5323370349","pt":1646330036613,"mc":[{"id":"1.195532879","rc":[{"atl":[[3.4,5.45],[3.55,22.64],[3.75,0]],"id":40452329}],"con":true,"img":false}]}
{"op":"mcm","clk":"5323370362","pt":1646330036720,"mc":[{"id":"1.195532879","rc":[{"atb":[[1.98,11.33]],"id":40452329}],"con":true,"img":false}]}
{"op":"mcm","clk":"5323370385","pt":1646330036874,"mc":[{"id":"1.195532879","rc":[{"atb":[[1.98,5]],"id":40452329}],"con":true,"img":false}]}
{"op":"mcm","clk":"5323370425","pt":1646330037318,"mc":[{"id":"1.195532879","rc":[{"atb":[[2.2,101.95]],"id":41555107},{"atb":[[2.08,13.68],[2.06,26.34]],"id":40452329}],"con":true,"img":false}]}
{"op":"mcm","clk":"5323370527","pt":1646330038491,"mc":[{"id":"1.195532879","rc":[{"atb":[[2.22,0],[2.14,2.15]],"id":40452329},{"atl":[[11,10]],"id":39059999}],"con":true,"img":false}]}
{"op":"mcm","clk":"5323370537","pt":1646330038601,"mc":[{"id":"1.195532879","rc":[{"atl":[[4.2,31.25]],"id":41555107}],"con":true,"img":false}]}
{"op":"mcm","clk":"5323370545","pt":1646330038698,"mc":[{"id":"1.195532879","rc":[{"atb":[[2.2,3.3]],"id":40452329}],"con":true,"img":false}]}
{"op":"mcm","clk":"5323370561","pt":1646330038907,"mc":[{"id":"1.195532879","rc":[{"atb":[[2.06,17.03],[2.2,0]],"id":40452329}],"con":true,"img":false}]}
{"op":"mcm","clk":"5323370593","pt":1646330039219,"mc":[{"id":"1.195532879","rc":[{"atb":[[2.22,27.92]],"id":41555107},{"atb":[[2.08,19.52]],"id":40452329},{"atl":[[3.35,3.8],[3.55,14.9]],"id":40452329}],"con":true,"img":false}]}
{"op":"mcm","clk":"5323370611","pt":1646330039391,"mc":[{"id":"1.195532879","rc":[{"atb":[[2.2,158.16],[2.16,0]],"id":41555107},{"atb":[[2.24,0]],"id":40452329},{"atl":[[3.3,3.35]],"id":40452329}],"con":true,"img":false}]}
{"op":"mcm","clk":"5323370621","pt":1646330039488,"mc":[{"id":"1.195532879","rc":[{"atb":[[2.16,1.99]],"id":40452329}],"con":true,"img":false}]}
{"op":"mcm","clk":"5323370659","pt":1646330039900,"mc":[{"id":"1.195532879","rc":[{"atl":[[9.6,0]],"id":41555107},{"atl":[[3.6,0],[3.4,22.12]],"id":40452329},{"atl":[[50,0]],"id":39059999}],"con":true,"img":false}]}
{"op":"mcm","clk":"5323370764","pt":1646330040986,"mc":[{"id":"1.195532879","rc":[{"atb":[[2.38,1.65]],"id":38251452},{"atl":[[4.3,58.38]],"id":38251452},{"atb":[[4.2,7.13]],"id":39059999}],"con":true,"img":false}]}
{"op":"mcm","clk":"5323370773","pt":1646330041091,"mc":[{"id":"1.195532879","rc":[{"atb":[[2.36,7.91]],"id":38251452}],"con":true,"img":false}]}
{"op":"mcm","clk":"5323370784","pt":1646330041193,"mc":[{"id":"1.195532879","rc":[{"atb":[[2.26,0]],"id":40452329},{"atb":[[2.32,23.23],[2.26,80.3]],"id":38251452},{"atb":[[4.2,5.47]],"id":39059999}],"con":true,"img":false}]}
{"op":"mcm","clk":"5323370790","pt":1646330041301,"mc":[{"id":"1.195532879","rc":[{"atb":[[2.28,29.27]],"id":38251452},{"atb":[[2.24,21.54]],"id":39632625}],"con":true,"img":false}]}
{"op":"mcm","clk":"5323370802","pt":1646330041400,"mc":[{"id":"1.195532879","rc":[{"atb":[[2.18,1.65]],"id":40452329}],"con":true,"img":false}]}
{"op":"mcm","clk":"5323370813","pt":1646330041499,"mc":[{"id":"1.195532879","rc":[{"atb":[[2.26,75.55],[2.36,2.15]],"id":38251452}],"con":true,"img":false}]}
{"op":"mcm","clk":"5323370862","pt":1646330041914,"mc":[{"id":"1.195532879","rc":[{"atb":[[2.24,30.87]],"id":39632625}],"con":true,"img":false}]}
{"op":"mcm","clk":"5323370875","pt":1646330042018,"mc":[{"id":"1.195532879","rc":[{"atl":[[4,105.38],[4.3,2.5],[3.85,28.07]],"id":41555107},{"atl":[[4.3,14.62],[3.85,23.89]],"id":38251452},{"atl":[[3.95,13.56],[3.8,42.94],[3.65,6.7]],"id":39632625},{"atl":[[10,27.89],[11.5,0],[9.4,7.36]],"id":39059999}],"con":true,"img":false}]}
{"op":"mcm","clk":"5323370884","pt":1646330042071,"mc":[{"id":"1.195532879","rc":[{"atl":[[4,85.58]],"id":38251452},{"atl":[[6.4,0],[6.2,71.85]],"id":28753299}],"con":true,"img":false}]}
{"op":"mcm","clk":"5323370899","pt":1646330042179,"mc":[{"id":"1.195532879","rc":[{"atl":[[3.95,0],[3.8,2.39]],"id":41555107},{"atl":[[3.95,0],[3.8,2.39]],"id":38251452},{"atl":[[3.6,2.71],[3.75,0]],"id":39632625},{"atl":[[9.2,1.36],[9.8,0]],"id":39059999}],"con":true,"img":false}]}
{"op":"mcm","clk":"5323370911","pt":1646330042284,"mc":[{"id":"1.195532879","rc":[{"atl":[[3.8,24.09],[3.9,2.25]],"id":41555107},{"atl":[[3.6,8.66]],"id":39632625},{"atl":[[9.6,1.24],[9.2,6.95],[11,14.53]],"id":39059999}],"con":true,"img":false}]}
{"op":"mcm","clk":"5323370922","pt":1646330042392,"mc":[{"id":"1.195532879","rc":[{"atl":[[3.8,21.05],[3.9,2.25]],"id":38251452},{"atl":[[3.7,2.54]],"id":39632625}],"con":true,"img":false}]}
{"op":"mcm","clk":"5323370937","pt":1646330042494,"mc":[{"id":"1.195532879","rc":[{"atl":[[4.5,31.9]],"id":38251452},{"atl":[[11,10]],"id":39059999}],"con":true,"img":false}]}
{"op":"mcm","clk":"5323370946","pt":1646330042592,"mc":[{"id":"1.195532879","rc":[{"atl":[[4,92.05],[3.9,16.04]],"id":41555107},{"atl":[[4,72.25],[3.9,16.04]],"id":38251452},{"atl":[[3.7,17.35],[3.8,28.65]],"id":39632625},{"atl":[[9.6,5.89],[10,23.45]],"id":39059999}],"con":true,"img":false}]}
{"op":"mcm","clk":"5323370958","pt":1646330042703,"mc":[{"id":"1.195532879","rc":[{"atl":[[3.4,19.78]],"id":40452329}],"con":true,"img":false}]}
{"op":"mcm","clk":"5323370990","pt":1646330043017,"mc":[{"id":"1.195532879","rc":[{"atl":[[3.35,6.1]],"id":40452329},{"atl":[[4.5,28.57]],"id":38251452}],"con":true,"img":false}]}
{"op":"mcm","clk":"5323371060","pt":1646330043637,"mc":[{"id":"1.195532879","rc":[{"atl":[[3.35,3.8]],"id":40452329}],"con":true,"img":false}]}
{"op":"mcm","clk":"5323371224","pt":1646330045212,"mc":[{"id":"1.195532879","rc":[{"atl":[[3.35,0],[3.25,3.8]],"id":40452329}],"con":true,"img":false}]}
{"op":"mcm","clk":"5323371236","pt":1646330045306,"mc":[{"id":"1.195532879","rc":[{"atl":[[3.3,7.48]],"id":40452329}],"con":true,"img":false}]}
{"op":"mcm","clk":"5323371246","pt":1646330045409,"mc":[{"id":"1.195532879","rc":[{"atl":[[3.55,0],[3.45,0],[3.2,3.03],[3.4,34.68]],"id":40452329}],"con":true,"img":false}]}
{"op":"mcm","clk":"5323371286","pt":1646330045721,"mc":[{"id":"1.195532879","rc":[{"atl":[[3.45,4.23],[3.7,3.79]],"id":40452329}],"con":true,"img":false}]}
{"op":"mcm","clk":"5323371313","pt":1646330045881,"mc":[{"id":"1.195532879","rc":[{"atl":[[3.45,0]],"id":40452329}],"con":true,"img":false}]}
{"op":"mcm","clk":"5323371329","pt":1646330045990,"mc":[{"id":"1.195532879","rc":[{"atl":[[3.7,0]],"id":40452329}],"con":true,"img":false}]}
{"op":"mcm","clk":"5323371356","pt":1646330046202,"mc":[{"id":"1.195532879","rc":[{"atb":[[2.22,74.98],[2.2,95.62]],"id":41555107},{"atl":[[3.4,18],[3.3,28.36]],"id":40452329},{"atb":[[2.26,43.84],[2.2,83.33]],"id":38251452},{"atb":[[2.22,2.5],[2.24,38.55]],"id":39632625},{"atb":[[2.64,28.84],[2.62,76.05]],"id":28753299}],"con":true,"img":false}]}
{"op":"mcm","clk":"5323371389","pt":1646330046514,"mc":[{"id":"1.195532879","rc":[{"atb":[[2.18,4]],"id":39632625}],"con":true,"img":false}]}
{"op":"mcm","clk":"5323371409","pt":1646330046714,"mc":[{"id":"1.195532879","rc":[{"atb":[[2.6,3.7],[2.62,61.23]],"id":28753299}],"con":true,"img":false}]}
{"op":"mcm","clk":"5323371440","pt":1646330047032,"mc":[{"id":"1.195532879","rc":[{"atb":[[2.18,0]],"id":39632625},{"atb":[[2.6,0]],"id":28753299}],"con":true,"img":false}]}
{"op":"mcm","clk":"5323371512","pt":1646330047709,"mc":[{"id":"1.195532879","rc":[{"atb":[[2.2,56.21]],"id":41555107},{"atb":[[4.2,0]],"id":39059999}],"con":true,"img":false}]}
{"op":"mcm","clk":"5323371532","pt":1646330047922,"mc":[{"id":"1.195532879","rc":[{"atb":[[3,37.89],[3.65,22.13],[3.75,9.63]],"id":39059999}],"con":true,"img":false}]}
{"op":"mcm","clk":"5323371554","pt":1646330048123,"mc":[{"id":"1.195532879","rc":[{"atb":[[3.4,4.44]],"id":39059999}],"con":true,"img":false}]}
{"op":"mcm","clk":"5323371573","pt":1646330048332,"mc":[{"id":"1.195532879","rc":[{"atb":[[3.95,9.8]],"id":39059999}],"con":true,"img":false}]}
{"op":"mcm","clk":"5323371606","pt":1646330048668,"mc":[{"id":"1.195532879","rc":[{"atb":[[4.3,0],[3.95,0],[3.4,0]],"id":39059999}],"con":true,"img":false}]}
{"op":"mcm","clk":"5323371623","pt":1646330048848,"mc":[{"id":"1.195532879","rc":[{"atb":[[3.6,38.46],[3.8,1.99],[3.65,0]],"id":39059999}],"con":true,"img":false}]}
{"op":"mcm","clk":"5323371649","pt":1646330049176,"mc":[{"id":"1.195532879","rc":[{"atl":[[3.3,24.87]],"id":40452329}],"con":true,"img":false}]}
{"op":"mcm","clk":"5323371658","pt":1646330049229,"mc":[{"id":"1.195532879","rc":[{"atl":[[3.2,6.92]],"id":40452329}],"con":true,"img":false}]}
{"op":"mcm","clk":"5323371673","pt":1646330049388,"mc":[{"id":"1.195532879","rc":[{"atl":[[3.4,3.1],[3.3,42.18]],"id":40452329}],"con":true,"img":false}]}
{"op":"mcm","clk":"5323371679","pt":1646330049490,"mc":[{"id":"1.195532879","rc":[{"atl":[[3.1,2.25]],"id":40452329}],"con":true,"img":false}]}
{"op":"mcm","clk":"5323371690","pt":1646330049595,"mc":[{"id":"1.195532879","rc":[{"atl":[[3.05,2.86]],"id":40452329}],"con":true,"img":false}]}
{"op":"mcm","clk":"5323371711","pt":1646330049908,"mc":[{"id":"1.195532879","rc":[{"spn":3.06,"spf":"NaN","id":41555107},{"atl":[[3.1,0]],"id":40452329},{"spn":3.09,"spf":"NaN","id":38251452},{"spn":2.34,"spf":1.0,"id":39632625},{"spn":6.5,"spf":"NaN","id":39059999},{"spn":4.3,"spf":"NaN","id":28753299}],"con":true,"img":false}]}
{"op":"mcm","clk":"5323371729","pt":1646330050114,"mc":[{"id":"1.195532879","rc":[{"atb":[[2.08,28.83]],"id":40452329}],"con":true,"img":false}]}
{"op":"mcm","clk":"5323371784","pt":1646330050685,"mc":[{"id":"1.195532879","rc":[{"atl":[[3.2,28.41],[3.3,24.79]],"id":40452329}],"con":true,"img":false}]}
{"op":"mcm","clk":"5323371824","pt":1646330051110,"mc":[{"id":"1.195532879","rc":[{"atl":[[3.25,0],[3.05,6.66]],"id":40452329},{"atb":[[3.85,1.65]],"id":39059999}],"con":true,"img":false}]}
{"op":"mcm","clk":"5323371844","pt":1646330051319,"mc":[{"id":"1.195532879","rc":[{"atl":[[3.15,24.79],[3.05,2.86]],"id":40452329}],"con":true,"img":false}]}
{"op":"mcm","clk":"5323371860","pt":1646330051521,"mc":[{"id":"1.195532879","rc":[{"atl":[[4,125.38]],"id":41555107},{"atl":[[3.15,0],[3.05,27.65]],"id":40452329},{"atl":[[4,105.58]],"id":38251452},{"atl":[[3.8,64.36]],"id":39632625},{"atl":[[10,34.56]],"id":39059999}],"con":true,"img":false}]}
{"op":"mcm","clk":"5323371921","pt":1646330052085,"mc":[{"id":"1.195532879","rc":[{"atl":[[4.8,0]],"id":41555107},{"atl":[[4.3,2.5],[4.5,0],[4.7,0]],"id":38251452},{"atb":[[2.24,30.87],[2.28,23.7]],"id":39632625},{"atl":[[4.3,0],[3.95,0],[4.1,0]],"id":39632625},{"atl":[[46,2.74]],"id":39059999}],"con":true,"img":false}]}
{"op":"mcm","clk":"5323372100","pt":1646330053901,"mc":[{"id":"1.195532879","rc":[{"atb":[[2.26,0],[2.28,84.62]],"id":38251452}],"con":true,"img":false}]}
{"op":"mcm","clk":"5323372113","pt":1646330054004,"mc":[{"id":"1.195532879","rc":[{"atb":[[3.6,0],[3.55,39.22]],"id":39059999}],"con":true,"img":false}]}
{"op":"mcm","clk":"5323372183","pt":1646330054734,"mc":[{"id":"1.195532879","rc":[{"atl":[[4,35.44],[3.9,120.35],[3.75,29.09]],"id":41555107},{"atl":[[3.75,27.82]],"id":38251452},{"atl":[[3.6,17.82],[3.7,49.03],[3.8,38.1]],"id":39632625},{"atl":[[9.6,31.57],[9,9.63],[10,12.24]],"id":39059999}],"con":true,"img":false}]}
{"op":"mcm","clk":"5323372194","pt":1646330054787,"mc":[{"id":"1.195532879","rc":[{"atl":[[4,35.44],[3.9,104.6]],"id":38251452},{"atl":[[3.6,11.87],[3.65,17.35]],"id":39632625},{"atl":[[9.4,0]],"id":39059999}],"con":true,"img":false}]}
{"op":"mcm","clk":"5323372203","pt":1646330054891,"mc":[{"id":"1.195532879","rc":[{"atb":[[2.24,38.14]],"id":41555107},{"atl":[[4.3,10.31],[3.85,0],[3.7,2.54],[3.9,127.37]],"id":41555107},{"atl":[[3.85,0],[3.7,2.54]],"id":38251452},{"atl":[[3.7,56.58]],"id":39632625},{"atb":[[3.8,18.88]],"id":39059999},{"atl":[[8.8,1.5]],"id":39059999}],"con":true,"img":false}]}
{"op":"mcm","clk":"5323372213","pt":1646330054996,"mc":[{"id":"1.195532879","rc":[{"atl":[[3.9,111.62]],"id":38251452},{"atl":[[9.6,35.36]],"id":39059999}],"con":true,"img":false}]}
{"op":"mcm","clk":"5323372224","pt":1646330055101,"mc":[{"id":"1.195532879","rc":[{"atb":[[2.22,141.45],[2.2,13.96]],"id":41555107},{"atl":[[4.3,2.5],[3.7,26.63],[3.8,2.39],[3.9,120.35]],"id":41555107},{"atl":[[3.7,23.59],[3.8,2.39]],"id":38251452},{"atl":[[3.7,49.03]],"id":39632625},{"atl":[[9.2,1.36],[8.8,8.45]],"id":39059999}],"con":true,"img":false}]}
{"op":"mcm","clk":"5323372243","pt":1646330055309,"mc":[{"id":"1.195532879","rc":[{"atl":[[3.9,104.6]],"id":38251452},{"atl":[[9.6,31.57]],"id":39059999}],"con":true,"img":false}]}
{"op":"mcm","clk":"5323372257","pt":1646330055410,"mc":[{"id":"1.195532879","rc":[{"atb":[[2.2,9.21]],"id":41555107}],"con":true,"img":false}]}
{"op":"mcm","clk":"5323372267","pt":1646330055513,"mc":[{"id":"1.195532879","rc":[{"atl":[[3.8,16.68]],"id":41555107},{"atl":[[3.8,16.68]],"id":38251452},{"atl":[[9.6,26.92],[9.2,6.24]],"id":39059999}],"con":true,"img":false}]}
{"op":"mcm","clk":"5323372279","pt":1646330055617,"mc":[{"id":"1.195532879","rc":[{"atl":[[3.9,106.56]],"id":41555107}],"con":true,"img":false}]}
{"op":"mcm","clk":"5323372289","pt":1646330055732,"mc":[{"id":"1.195532879","rc":[{"atb":[[2.2,0]],"id":41555107}],"con":true,"img":false}]}
{"op":"mcm","clk":"5323372333","pt":1646330056088,"mc":[{"id":"1.195532879","rc":[{"atb":[[2.3,2.5],[2.06,0]],"id":39632625},{"atb":[[2.64,62.17],[2.62,27.9]],"id":28753299}],"con":true,"img":false}]}
{"op":"mcm","clk":"5323372346","pt":1646330056193,"mc":[{"id":"1.195532879","rc":[{"atb":[[2.32,0]],"id":38251452},{"atb":[[2.3,26.31],[2.28,11.85]],"id":39632625}],"con":true,"img":false}]}
{"op":"mcm","clk":"5323372441","pt":1646330057231,"mc":[{"id":"1.195532879","rc":[{"atb":[[2.22,19.87]],"id":39632625}],"con":true,"img":false}]}
{"op":"mcm","clk":"5323372452","pt":1646330057280,"mc":[{"id":"1.195532879","rc":[{"atb":[[2.28,0]],"id":39632625}],"con":true,"img":false}]}
{"op":"mcm","clk":"5323372483","pt":1646330057597,"mc":[{"id":"1.195532879","rc":[{"atb":[[2.28,55.35]],"id":38251452}],"con":true,"img":false}]}
{"op":"mcm","clk":"5323372515","pt":1646330057906,"mc":[{"id":"1.195532879","rc":[{"atl":[[3.05,47.86]],"id":40452329}],"con":true,"img":false}]}
{"op":"mcm","clk":"5323372525","pt":1646330058008,"mc":[{"id":"1.195532879","rc":[{"atl":[[3.15,46.51]],"id":40452329}],"con":true,"img":false}]}
{"op":"mcm","clk":"5323372534","pt":1646330058111,"mc":[{"id":"1.195532879","rc":[{"atl":[[3.2,139.02],[3.05,23.07]],"id":40452329}],"con":true,"img":false}]}
{"op":"mcm","clk":"5323372542","pt":1646330058216,"mc":[{"id":"1.195532879","rc":[{"atl":[[3.3,3.35]],"id":40452329}],"con":true,"img":false}]}
{"op":"mcm","clk":"5323372593","pt":1646330058784,"mc":[{"id":"1.195532879","rc":[{"atb":[[2.22,113.53]],"id":41555107},{"atb":[[2.24,21.54]],"id":39632625}],"con":true,"img":false}]}
{"op":"mcm","clk":"5323372649","pt":1646330059507,"mc":[{"id":"1.195532879","rc":[{"atl":[[3.3,46.83]],"id":40452329}],"con":true,"img":false}]}
{"op":"mcm","clk":"5323372666","pt":1646330059713,"mc":[{"id":"1.195532879","rc":[{"atl":[[4.3,0],[4.5,0],[4.7,0]],"id":40452329},{"atb":[[2.24,52.84],[2.28,0]],"id":38251452}],"con":true,"img":false}]}
{"op":"mcm","clk":"5323372677","pt":1646330059817,"mc":[{"id":"1.195532879","rc":[{"atb":[[3.65,37.74]],"id":39059999}],"con":true,"img":false}]}
{"op":"mcm","clk":"5323372687","pt":1646330059923,"mc":[{"id":"1.195532879","rc":[{"atb":[[3.55,0]],"id":39059999}],"con":true,"img":false}]}
{"op":"mcm","clk":"5323372693","pt":1646330060024,"mc":[{"id":"1.195532879","rc":[{"atl":[[3.2,135.71]],"id":40452329}],"con":true,"img":false}]}
{"op":"mcm","clk":"5323372724","pt":1646330060285,"mc":[{"id":"1.195532879","rc":[{"atl":[[3.15,48.82]],"id":40452329},{"atl":[[3.9,51.72]],"id":39632625}],"con":true,"img":false}]}
{"op":"mcm","clk":"5323372735","pt":1646330060390,"mc":[{"id":"1.195532879","rc":[{"atl":[[3.95,4.31]],"id":39632625}],"con":true,"img":false}]}
{"op":"mcm","clk":"5323372743","pt":1646330060492,"mc":[{"id":"1.195532879","rc":[{"atb":[[3.85,15.21],[3.7,25.1]],"id":39059999}],"con":true,"img":false}]}
{"op":"mcm","clk":"5323372755","pt":1646330060596,"mc":[{"id":"1.195532879","rc":[{"atl":[[3.95,0]],"id":39632625},{"atb":[[3,20]],"id":39059999}],"con":true,"img":false}]}
{"op":"mcm","clk":"5323372770","pt":1646330060699,"mc":[{"id":"1.195532879","rc":[{"atb":[[3.8,16.89],[3.75,0]],"id":39059999}],"con":true,"img":false}]}
{"op":"mcm","clk":"5323372780","pt":1646330060803,"mc":[{"id":"1.195532879","rc":[{"atb":[[3.9,1.99]],"id":39059999}],"con":true,"img":false}]}
{"op":"mcm","clk":"5323372809","pt":1646330061218,"mc":[{"id":"1.195532879","rc":[{"atb":[[2.24,85.2],[2.22,66.47]],"id":41555107},{"atb":[[2,0],[1.98,0],[2.04,0],[2.08,19.52],[1.92,108.7]],"id":40452329},{"atb":[[2.24,50.34],[2.06,94.34],[2.2,0]],"id":38251452},{"atb":[[3.85,13.56]],"id":39059999}],"con":true,"img":false}]}
{"op":"mcm","clk":"5323372817","pt":1646330061320,"mc":[{"id":"1.195532879","rc":[{"atb":[[2.62,61.23]],"id":28753299}],"con":true,"img":false}]}
{"op":"mcm","clk":"5323372828","pt":1646330061427,"mc":[{"id":"1.195532879","rc":[{"atb":[[3.95,1.65]],"id":39059999},{"atb":[[2.64,28.84]],"id":28753299}],"con":true,"img":false}]}
{"op":"mcm","clk":"5323372840","pt":1646330061530,"mc":[{"id":"1.195532879","rc":[{"atb":[[2,3.98]],"id":40452329},{"atb":[[2.24,0]],"id":39632625}],"con":true,"img":false}]}
{"op":"mcm","clk":"5323372894","pt":1646330062102,"mc":[{"id":"1.195532879","rc":[{"atb":[[2,0]],"id":40452329}],"con":true,"img":false}]}
{"op":"mcm","clk":"5323373045","pt":1646330063712,"mc":[{"id":"1.195532879","rc":[{"atl":[[3.15,2.31],[3.05,71.85]],"id":40452329}],"con":true,"img":false}]}
{"op":"mcm","clk":"5323373054","pt":1646330063817,"mc":[{"id":"1.195532879","rc":[{"atl":[[3.15,48.82],[3.05,23.07]],"id":40452329}],"con":true,"img":false}]}
{"op":"mcm","clk":"5323373066","pt":1646330063919,"mc":[{"id":"1.195532879","rc":[{"atl":[[3.05,71.85]],"id":40452329}],"con":true,"img":false}]}
{"op":"mcm","clk":"5323373076","pt":1646330064020,"mc":[{"id":"1.195532879","rc":[{"atl":[[3.15,2.31]],"id":40452329}],"con":true,"img":false}]}
{"op":"mcm","clk":"5323373085","pt":1646330064228,"mc":[{"id":"1.195532879","rc":[{"atl":[[3.9,141.04]],"id":41555107},{"atl":[[3.9,125.29]],"id":38251452},{"atl":[[9.6,38.55]],"id":39059999}],"con":true,"img":false}]}
{"op":"mcm","clk":"5323373095","pt":1646330064279,"mc":[{"id":"1.195532879","rc":[{"atb":[[2.32,17.94]],"id":41555107},{"atb":[[2.26,8.62]],"id":39632625}],"con":true,"img":false}]}
{"op":"mcm","clk":"5323373100","pt":1646330064384,"mc":[{"id":"1.195532879","rc":[{"atb":[[2.34,24.72]],"id":41555107}],"con":true,"img":false}]}
{"op":"mcm","clk":"5323373114","pt":1646330064589,"mc":[{"id":"1.195532879","rc":[{"atb":[[2.3,2.15],[2.08,7.15]],"id":41555107}],"con":true,"img":false}]}
{"op":"mcm","clk":"5323373136","pt":1646330064900,"mc":[{"id":"1.195532879","rc":[{"atb":[[2.3,0],[2.4,2.15]],"id":41555107}],"con":true,"img":false}]}
{"op":"mcm","clk":"5323373152","pt":1646330065111,"mc":[{"id":"1.195532879","rc":[{"atb":[[2.08,0]],"id":41555107}],"con":true,"img":false}]}
{"op":"mcm","clk":"5323373175","pt":1646330065418,"mc":[{"id":"1.195532879","rc":[{"atb":[[2.06,158.6]],"id":38251452}],"con":true,"img":false}]}
{"op":"mcm","clk":"5323373183","pt":1646330065522,"mc":[{"id":"1.195532879","rc":[{"atb":[[2.24,0],[2.08,20.02]],"id":38251452},{"atb":[[3.8,0]],"id":39059999}],"con":true,"img":false}]}
{"op":"mcm","clk":"5323373215","pt":1646330065885,"mc":[{"id":"1.195532879","rc":[{"atb":[[2.04,4.38]],"id":38251452}],"con":true,"img":false}]}
{"op":"mcm","clk":"5323373230","pt":1646330066090,"mc":[{"id":"1.195532879","rc":[{"atb":[[2.04,0]],"id":38251452}],"con":true,"img":false}]}
{"op":"mcm","clk":"5323373249","pt":1646330066296,"mc":[{"id":"1.195532879","rc":[{"atl":[[4.6,0]],"id":41555107},{"atb":[[2.06,168.85]],"id":38251452},{"atl":[[13,0]],"id":39059999}],"con":true,"img":false}]}
{"op":"mcm","clk":"5323373273","pt":1646330066608,"mc":[{"id":"1.195532879","rc":[{"atb":[[2.06,158.6]],"id":38251452}],"con":true,"img":false}]}
{"op":"mcm","clk":"5323373305","pt":1646330067018,"mc":[{"id":"1.195532879","rc":[{"atl":[[3.15,0]],"id":40452329}],"con":true,"img":false}]}
{"op":"mcm","clk":"5323373312","pt":1646330067121,"mc":[{"id":"1.195532879","rc":[{"atl":[[3.8,102.02],[3.65,30.19]],"id":41555107},{"atl":[[3.2,21.21],[3.3,172.8]],"id":40452329},{"atl":[[3.65,27.53]],"id":38251452},{"atl":[[8.6,10.53],[9.2,42.4]],"id":39059999}],"con":true,"img":false}]}
{"op":"mcm","clk":"5323373318","pt":1646330067224,"mc":[{"id":"1.195532879","rc":[{"atl":[[3.6,2.71],[3.9,36.73],[3.75,0]],"id":41555107},{"atl":[[3.6,2.71],[3.8,103.92],[3.9,36.73],[3.75,0]],"id":38251452},{"atl":[[9.6,12.87],[9,0],[8.4,1.65]],"id":39059999}],"con":true,"img":false}]}
{"op":"mcm","clk":"5323373325","pt":1646330067328,"mc":[{"id":"1.195532879","rc":[{"atl":[[3.7,2.54],[3.65,34.26]],"id":41555107},{"atl":[[3.15,3.16]],"id":40452329},{"atl":[[8.4,10.1]],"id":39059999}],"con":true,"img":false}]}
{"op":"mcm","clk":"5323373335","pt":1646330067432,"mc":[{"id":"1.195532879","rc":[{"atl":[[3.6,29.34],[3.7,17.35],[3.8,87.73]],"id":41555107},{"atl":[[4,42.35],[3.6,26.3],[3.7,17.35]],"id":38251452},{"atl":[[9.2,37.52],[8.8,6.63]],"id":39059999}],"con":true,"img":false}]}
{"op":"mcm","clk":"5323373352","pt":1646330067639,"mc":[{"id":"1.195532879","rc":[{"atb":[[2.32,71.28],[2.22,0]],"id":41555107},{"atl":[[4,35.44]],"id":38251452}],"con":true,"img":false}]}
{"op":"mcm","clk":"5323373365","pt":1646330067689,"mc":[{"id":"1.195532879","rc":[{"atl":[[3.15,0]],"id":40452329}],"con":true,"img":false}]}
{"op":"mcm","clk":"5323373379","pt":1646330067897,"mc":[{"id":"1.195532879","rc":[{"atl":[[3.6,9.16],[3.7,46.49]],"id":39632625}],"con":true,"img":false}]}
{"op":"mcm","clk":"5323373393","pt":1646330068000,"mc":[{"id":"1.195532879","rc":[{"atl":[[3.1,1.62]],"id":40452329},{"atl":[[3.7,83.53],[3.65,0]],"id":39632625}],"con":true,"img":false}]}
{"op":"mcm","clk":"5323373403","pt":1646330068107,"mc":[{"id":"1.195532879","rc":[{"atl":[[3.6,0],[3.7,51.85],[3.8,109.04]],"id":39632625}],"con":true,"img":false}]}
{"op":"mcm","clk":"5323373412","pt":1646330068208,"mc":[{"id":"1.195532879","rc":[{"atl":[[3.4,65.61]],"id":40452329},{"atl":[[6,2.5],[6.8,5],[7.6,10],[3.65,11.01]],"id":39632625}],"con":true,"img":false}]}
{"op":"mcm","clk":"5323373460","pt":1646330068832,"mc":[{"id":"1.195532879","rc":[{"atb":[[2.32,54.99]],"id":41555107},{"atl":[[3.7,37.04],[3.75,14.55]],"id":39632625}],"con":true,"img":false}]}
{"op":"mcm","clk":"5323373477","pt":1646330068988,"mc":[{"id":"1.195532879","rc":[{"atb":[[2.24,47.06]],"id":41555107},{"atb":[[2.36,12.42]],"id":39632625}],"con":true,"img":false}]}
{"op":"mcm","clk":"5323373485","pt":1646330069092,"mc":[{"id":"1.195532879","rc":[{"atb":[[2.32,31.45],[2.38,17.58]],"id":39632625}],"con":true,"img":false}]}
{"op":"mcm","clk":"5323373493","pt":1646330069195,"mc":[{"id":"1.195532879","rc":[{"atb":[[2.3,2.5]],"id":39632625}],"con":true,"img":false}]}
{"op":"mcm","clk":"5323373503","pt":1646330069302,"mc":[{"id":"1.195532879","rc":[{"atb":[[2.34,0]],"id":39632625}],"con":true,"img":false}]}
{"op":"mcm","clk":"5323373512","pt":1646330069401,"mc":[{"id":"1.195532879","rc":[{"atb":[[2.34,3.12],[2.4,1.99]],"id":39632625}],"con":true,"img":false}]}
{"op":"mcm","clk":"5323373531","pt":1646330069610,"mc":[{"id":"1.195532879","rc":[{"atb":[[2.34,0]],"id":39632625}],"con":true,"img":false}]}
{"op":"mcm","clk":"5323373607","pt":1646330070435,"mc":[{"id":"1.195532879","rc":[{"atl":[[3.1,0]],"id":40452329}],"con":true,"img":false}]}
{"op":"mcm","clk":"5323373632","pt":1646330070746,"mc":[{"id":"1.195532879","rc":[{"atl":[[3.05,75.12]],"id":40452329}],"con":true,"img":false}]}
{"op":"mcm","clk":"5323373649","pt":1646330070902,"mc":[{"id":"1.195532879","rc":[{"atl":[[3.65,30.19]],"id":41555107}],"con":true,"img":false}]}
{"op":"mcm","clk":"5323373671","pt":1646330071107,"mc":[{"id":"1.195532879","rc":[{"atb":[[2.32,53.34]],"id":41555107},{"atb":[[2.26,0],[2.36,10.77]],"id":39632625}],"con":true,"img":false}]}
{"op":"mcm","clk":"5323373696","pt":1646330071315,"mc":[{"id":"1.195532879","rc":[{"atb":[[2.24,0],[2.42,1.65],[2.28,49.44]],"id":41555107},{"atb":[[1.85,117.65],[1.92,0],[2.06,0]],"id":40452329},{"atb":[[2.42,1.65]],"id":39632625},{"atb":[[2.6,62.5],[2.62,27.9]],"id":28753299}],"con":true,"img":false}]}
{"op":"mcm","clk":"5323373788","pt":1646330072294,"mc":[{"id":"1.195532879","rc":[{"atl":[[3.05,71.85]],"id":40452329}],"con":true,"img":false}]}
{"op":"mcm","clk":"5323373811","pt":1646330072501,"mc":[{"id":"1.195532879","rc":[{"atb":[[3.95,7.13]],"id":39059999}],"con":true,"img":false}]}
{"op":"mcm","clk":"5323373820","pt":1646330072606,"mc":[{"id":"1.195532879","rc":[{"atl":[[2.96,3.11]],"id":40452329}],"con":true,"img":false}]}
{"op":"mcm","clk":"5323373833","pt":1646330072710,"mc":[{"id":"1.195532879","rc":[{"atl":[[3.2,67.57],[2.96,7.06],[3.3,46.83],[2.94,22.98]],"id":40452329}],"con":true,"img":false}]}
{"op":"mcm","clk":"5323373844","pt":1646330072813,"mc":[{"id":"1.195532879","rc":[{"atl":[[3.05,23.07]],"id":40452329},{"atb":[[4,12.92]],"id":39059999}],"con":true,"img":false}]}
{"op":"mcm","clk":"5323373851","pt":1646330072915,"mc":[{"id":"1.195532879","rc":[{"atl":[[3.1,11.3],[3.05,2.86]],"id":40452329},{"atb":[[3.85,0],[3.7,2.5]],"id":39059999}],"con":true,"img":false}]}
{"op":"mcm","clk":"5323373861","pt":1646330073019,"mc":[{"id":"1.195532879","rc":[{"atb":[[3.85,25.79],[3.5,4.16]],"id":39059999}],"con":true,"img":false}]}
{"op":"mcm","clk":"5323373870","pt":1646330073120,"mc":[{"id":"1.195532879","rc":[{"atl":[[3.1,0]],"id":40452329},{"atl":[[3.75,50.91]],"id":39632625},{"atb":[[3.9,0]],"id":39059999}],"con":true,"img":false}]}
{"op":"mcm","clk":"5323373882","pt":1646330073223,"mc":[{"id":"1.195532879","rc":[{"atl":[[3.7,0]],"id":39632625},{"atb":[[3.5,0],[4.1,1.99]],"id":39059999}],"con":true,"img":false}]}
{"op":"mcm","clk":"5323373896","pt":1646330073432,"mc":[{"id":"1.195532879","rc":[{"atb":[[3.9,3.62]],"id":39059999}],"con":true,"img":false}]}
{"op":"mcm","clk":"5323373906","pt":1646330073533,"mc":[{"id":"1.195532879","rc":[{"atl":[[3.35,5.62]],"id":40452329}],"con":true,"img":false}]}
{"op":"mcm","clk":"5323373914","pt":1646330073637,"mc":[{"id":"1.195532879","rc":[{"atb":[[3.9,0]],"id":39059999}],"con":true,"img":false}]}
{"op":"mcm","clk":"5323373923","pt":1646330073740,"mc":[{"id":"1.195532879","rc":[{"atl":[[3.35,0]],"id":40452329}],"con":true,"img":false}]}
{"op":"mcm","clk":"5323373941","pt":1646330073895,"mc":[{"id":"1.195532879","rc":[{"atb":[[2.26,29.03]],"id":41555107}],"con":true,"img":false}]}
{"op":"mcm","clk":"5323374015","pt":1646330074616,"mc":[{"id":"1.195532879","rc":[{"atl":[[2.94,33.98]],"id":40452329}],"con":true,"img":false}]}
{"op":"mcm","clk":"5323374104","pt":1646330075543,"mc":[{"id":"1.195532879","rc":[{"atb":[[2.44,2.15]],"id":39632625}],"con":true,"img":false}]}
{"op":"mcm","clk":"5323374110","pt":1646330075653,"mc":[{"id":"1.195532879","rc":[{"atb":[[2.32,29.3]],"id":39632625}],"con":true,"img":false}]}
{"op":"mcm","clk":"5323374119","pt":1646330075700,"mc":[{"id":"1.195532879","rc":[{"atl":[[2.96,3.95]],"id":40452329}],"con":true,"img":false}]}
{"op":"mcm","clk":"5323374140","pt":1646330075909,"mc":[{"id":"1.195532879","rc":[{"atl":[[3.8,123.44]],"id":41555107},{"atl":[[3.8,125.34]],"id":38251452},{"atb":[[2.4,0]],"id":39632625},{"atl":[[9.2,49.72]],"id":39059999}],"con":true,"img":false}]}
{"op":"mcm","clk":"5323374150","pt":1646330076009,"mc":[{"id":"1.195532879","rc":[{"atl":[[2.96,11.22]],"id":40452329},{"atb":[[2.46,1.99]],"id":39632625}],"con":true,"img":false}]}
{"op":"mcm","clk":"5323374179","pt":1646330076320,"mc":[{"id":"1.195532879","rc":[{"atb":[[2.08,5.83]],"id":40452329},{"atb":[[2.36,0]],"id":39632625}],"con":true,"img":false}]}
{"op":"mcm","clk":"5323374188","pt":1646330076423,"mc":[{"id":"1.195532879","rc":[{"atb":[[2.42,7.38]],"id":41555107},{"atl":[[4.2,0]],"id":41555107},{"atl":[[11,0]],"id":39059999},{"atb":[[2.6,0],[2.58,63.29]],"id":28753299}],"con":true,"img":false}]}
{"op":"mcm","clk":"5323374211","pt":1646330076631,"mc":[{"id":"1.195532879","rc":[{"atb":[[2.08,0]],"id":40452329},{"atl":[[2.96,3.95]],"id":40452329},{"atb":[[2.1,8.01]],"id":38251452}],"con":true,"img":false}]}
{"op":"mcm","clk":"5323374223","pt":1646330076732,"mc":[{"id":"1.195532879","rc":[{"atb":[[2.44,21.96]],"id":41555107},{"atb":[[1.85,127.15]],"id":40452329},{"atl":[[3.5,102.9]],"id":40452329},{"atb":[[2.08,66.74]],"id":38251452}],"con":true,"img":false}]}
{"op":"mcm","clk":"5323374230","pt":1646330076835,"mc":[{"id":"1.195532879","rc":[{"atb":[[2.34,0]],"id":41555107},{"atb":[[2.06,94.34]],"id":38251452},{"atb":[[4.1,12.99]],"id":39059999}],"con":true,"img":false}]}
{"op":"mcm","clk":"5323374241","pt":1646330076937,"mc":[{"id":"1.195532879","rc":[{"atl":[[2.88,1.66]],"id":40452329}],"con":true,"img":false}]}
{"op":"mcm","clk":"5323374251","pt":1646330077040,"mc":[{"id":"1.195532879","rc":[{"atl":[[2.86,1.9]],"id":40452329}],"con":true,"img":false}]}
{"op":"mcm","clk":"5323374276","pt":1646330077308,"mc":[{"id":"1.195532879","rc":[{"atl":[[3.85,35.09]],"id":39632625}],"con":true,"img":false}]}
{"op":"mcm","clk":"5323374367","pt":1646330078333,"mc":[{"id":"1.195532879","rc":[{"atl":[[2.86,3.9],[2.94,12.77]],"id":40452329}],"con":true,"img":false}]}
{"op":"mcm","clk":"5323374411","pt":1646330078957,"mc":[{"id":"1.195532879","rc":[{"atb":[[2.26,0]],"id":41555107}],"con":true,"img":false}]}
{"op":"mcm","clk":"5323374439","pt":1646330079214,"mc":[{"id":"1.195532879","rc":[{"atl":[[9.4,9.67]],"id":39059999}],"con":true,"img":false}]}
{"op":"mcm","clk":"5323374449","pt":1646330079323,"mc":[{"id":"1.195532879","rc":[{"atl":[[3.6,58.82],[3.7,103.52],[3.8,38.1]],"id":41555107},{"atl":[[3.2,21.21],[2.96,19.65]],"id":40452329},{"atl":[[3.55,19.02]],"id":38251452},{"atl":[[9.2,13.56],[8.2,11.11],[8.8,47.89]],"id":39059999}],"con":true,"img":false}]}
{"op":"mcm","clk":"5323374459","pt":1646330079425,"mc":[{"id":"1.195532879","rc":[{"atl":[[3.6,2.71],[3.7,112.04],[3.8,38.1],[3.5,29.2]],"id":38251452},{"atl":[[8,12.37]],"id":39059999}],"con":true,"img":false}]}
{"op":"mcm","clk":"5323374470","pt":1646330079525,"mc":[{"id":"1.195532879","rc":[{"atl":[[3.65,0]],"id":41555107},{"atl":[[2.88,0]],"id":40452329},{"atl":[[3.65,0]],"id":38251452},{"atl":[[8.4,1.65],[8.6,0]],"id":39059999}],"con":true,"img":false}]}
{"op":"mcm","clk":"5323374479","pt":1646330079633,"mc":[{"id":"1.195532879","rc":[{"atl":[[3.7,95.97]],"id":41555107},{"atl":[[3.7,104.65]],"id":38251452},{"atl":[[9.4,0]],"id":39059999}],"con":true,"img":false}]}
{"op":"mcm","clk":"5323374501","pt":1646330079842,"mc":[{"id":"1.195532879","rc":[{"atb":[[2.4,77.23],[2.32,0]],"id":41555107},{"atl":[[2.84,3.51]],"id":40452329}],"con":true,"img":false}]}
{"op":"mcm","clk":"5323374513","pt":1646330079940,"mc":[{"id":"1.195532879","rc":[{"atl":[[3.95,3.57]],"id":41555107}],"con":true,"img":false}]}
{"op":"mcm","clk":"5323374520","pt":1646330080041,"mc":[{"id":"1.195532879","rc":[{"atl":[[2.82,1.94]],"id":40452329}],"con":true,"img":false}]}
{"op":"mcm","clk":"5323374542","pt":1646330080255,"mc":[{"id":"1.195532879","rc":[{"atl":[[3.95,0]],"id":41555107}],"con":true,"img":false}]}
{"op":"mcm","clk":"5323374588","pt":1646330080718,"mc":[{"id":"1.195532879","rc":[{"atb":[[1.86,26.46]],"id":40452329},{"atb":[[2.34,12.43]],"id":39632625},{"atb":[[3.95,1.65]],"id":39059999}],"con":true,"img":false}]}
{"op":"mcm","clk":"5323374618","pt":1646330081131,"mc":[{"id":"1.195532879","rc":[{"atb":[[2.42,5.72]],"id":41555107},{"atb":[[2.42,0]],"id":39632625},{"atb":[[3.95,0]],"id":39059999}],"con":true,"img":false}]}
{"op":"mcm","clk":"5323374627","pt":1646330081236,"mc":[{"id":"1.195532879","rc":[{"atb":[[2.46,1.65]],"id":41555107},{"atb":[[2.32,0],[2.34,52.03],[2.48,1.65]],"id":39632625},{"atb":[[4.2,1.65]],"id":39059999}],"con":true,"img":false}]}
