{"op":"mcm","clk":"5352092075","pt":1646182318990,"mc":[{"id":"1.195503865","marketDefinition":{"bspMarket":false,"turnInPlayEnabled":false,"persistenceEnabled":false,"marketBaseRate":7.0,"eventId":"31272499","eventTypeId":"4339","numberOfWinners":1,"bettingType":"ODDS","marketType":"EXACTA","marketTime":"2022-03-02T10:15:00.000Z","suspendTime":"2022-03-02T10:15:00.000Z","bspReconciled":false,"complete":true,"inPlay":false,"crossMatching":false,"runnersVoidable":false,"numberOfActiveRunners":56,"betDelay":0,"status":"OPEN","runners":[{"status":"ACTIVE","sortPriority":1,"id":41419585,"name":"1 - 2"},{"status":"ACTIVE","sortPriority":2,"id":41419586,"name":"1 - 3"},{"status":"ACTIVE","sortPriority":3,"id":41419587,"name":"1 - 4"},{"status":"ACTIVE","sortPriority":4,"id":41419588,"name":"1 - 5"},{"status":"ACTIVE","sortPriority":5,"id":41419590,"name":"1 - 7"},{"status":"ACTIVE","sortPriority":6,"id":41419591,"name":"1 - 8"},{"status":"ACTIVE","sortPriority":7,"id":28546943,"name":"1 - 9"},{"status":"ACTIVE","sortPriority":8,"id":41419592,"name":"2 - 1"},{"status":"ACTIVE","sortPriority":9,"id":41419593,"name":"2 - 3"},{"status":"ACTIVE","sortPriority":10,"id":41419594,"name":"2 - 4"},{"status":"ACTIVE","sortPriority":11,"id":41419595,"name":"2 - 5"},{"status":"ACTIVE","sortPriority":12,"id":41419597,"name":"2 - 7"},{"status":"ACTIVE","sortPriority":13,"id":41419598,"name":"2 - 8"},{"status":"ACTIVE","sortPriority":14,"id":41419651,"name":"2 - 9"},{"status":"ACTIVE","sortPriority":15,"id":41419599,"name":"3 - 1"},{"status":"ACTIVE","sortPriority":16,"id":41419600,"name":"3 - 2"},{"status":"ACTIVE","sortPriority":17,"id":41419601,"name":"3 - 4"},{"status":"ACTIVE","sortPriority":18,"id":41419602,"name":"3 - 5"},{"status":"ACTIVE","sortPriority":19,"id":41419604,"name":"3 - 7"},{"status":"ACTIVE","sortPriority":20,"id":41419605,"name":"3 - 8"},{"status":"ACTIVE","sortPriority":21,"id":41419652,"name":"3 - 9"},{"status":"ACTIVE","sortPriority":22,"id":41419606,"name":"4 - 1"},{"status":"ACTIVE","sortPriority":23,"id":41419607,"name":"4 - 2"},{"status":"ACTIVE","sortPriority":24,"id":41419608,"name":"4 - 3"},{"status":"ACTIVE","sortPriority":25,"id":41419609,"name":"4 - 5"},{"status":"ACTIVE","sortPriority":26,"id":41419611,"name":"4 - 7"},{"status":"ACTIVE","sortPriority":27,"id":41419612,"name":"4 - 8"},{"status":"ACTIVE","sortPriority":28,"id":41435525,"name":"4 - 9"},{"status":"ACTIVE","sortPriority":29,"id":41419613,"name":"5 - 1"},{"status":"ACTIVE","sortPriority":30,"id":41419614,"name":"5 - 2"},{"status":"ACTIVE","sortPriority":31,"id":41419615,"name":"5 - 3"},{"status":"ACTIVE","sortPriority":32,"id":41419616,"name":"5 - 4"},{"status":"ACTIVE","sortPriority":33,"id":41419618,"name":"5 - 7"},{"status":"ACTIVE","sortPriority":34,"id":41419619,"name":"5 - 8"},{"status":"ACTIVE","sortPriority":35,"id":41419653,"name":"5 - 9"},{"status":"ACTIVE","sortPriority":36,"id":41419627,"name":"7 - 1"},{"status":"ACTIVE","sortPriority":37,"id":41419628,"name":"7 - 2"},{"status":"ACTIVE","sortPriority":38,"id":41419629,"name":"7 - 3"},{"status":"ACTIVE","sortPriority":39,"id":41419630,"name":"7 - 4"},{"status":"ACTIVE","sortPriority":40,"id":41419631,"name":"7 - 5"},{"status":"ACTIVE","sortPriority":41,"id":41419633,"name":"7 - 8"},{"status":"ACTIVE","sortPriority":42,"id":41419654,"name":"7 - 9"},{"status":"ACTIVE","sortPriority":43,"id":41419634,"name":"8 - 1"},{"status":"ACTIVE","sortPriority":44,"id":41419635,"name":"8 - 2"},{"status":"ACTIVE","sortPriority":45,"id":41419636,"name":"8 - 3"},{"status":"ACTIVE","sortPriority":46,"id":41419637,"name":"8 - 4"},{"status":"ACTIVE","sortPriority":47,"id":41419638,"name":"8 - 5"},{"status":"ACTIVE","sortPriority":48,"id":41419640,"name":"8 - 7"},{"status":"ACTIVE","sortPriority":49,"id":41419655,"name":"8 - 9"},{"status":"ACTIVE","sortPriority":50,"id":28546950,"name":"9 - 1"},{"status":"ACTIVE","sortPriority":51,"id":41419656,"name":"9 - 2"},{"status":"ACTIVE","sortPriority":52,"id":41419657,"name":"9 - 3"},{"status":"ACTIVE","sortPriority":53,"id":41435527,"name":"9 - 4"},{"status":"ACTIVE","sortPriority":54,"id":41419658,"name":"9 - 5"},{"status":"ACTIVE","sortPriority":55,"id":41419659,"name":"9 - 7"},{"status":"ACTIVE","sortPriority":56,"id":41419660,"name":"9 - 8"}],"regulators":["MR_INT"],"venue":"Rockhampton","countryCode":"AU","discountAllowed":true,"timezone":"Australia/Queensland","openDate":"2022-03-02T08:34:00.000Z","version":4382565129,"name":"Exacta","eventName":"Rockhampton (AUS) 2nd Mar"},"rc":[],"con":true,"img":false}]}
{"op":"mcm","clk":"5352095598","pt":1646182411275,"mc":[{"id":"1.195503865","rc":[{"atb":[[17,16.63],[48,4.24],[24,8.67]],"id":41419609},{"atb":[[9,33.26],[20,10.5],[12.5,17.35]],"id":41419638},{"atb":[[4.8,70.02],[8.6,26.26],[5.8,41.58]],"id":41419605},{"atb":[[8,28.51],[4.5,76.03],[5.5,44.35]],"id":41419634},{"atb":[[18.5,15.2],[27,7.67],[60,3.38]],"id":41419613},{"atb":[[16.5,12.87],[11.5,25.34],[28,7.39]],"id":41419593},{"atb":[[32,6.44],[18,11.73],[13,22.17]],"id":41419655},{"atb":[[150,1.33],[50,4.07],[30,9.17]],"id":41435527},{"atb":[[330,0.6],[180,1.11],[90,2.98]],"id":41419651},{"atb":[[600,0.44],[700,0.28],[850,0.23]],"id":41419618},{"atb":[[8.6,35.01],[19,11.08],[11.5,19]],"id":41419601},{"atb":[[150,1.33],[50,4.07],[30,9.17]],"id":41419630},{"atb":[[330,0.6],[180,1.11],[90,2.98]],"id":41419597},{"atb":[[140,1.43],[48,4.24],[29,9.5]],"id":28546943},{"atb":[[600,0.44],[700,0.28],[850,0.23]],"id":41419659},{"atb":[[9.2,32.45],[21,9.97],[13,16.63]],"id":41419606},{"atb":[[5.8,55.43],[11.5,19],[7.6,30.24]],"id":41419635},{"atb":[[16.5,17.17],[46,4.43],[23,9.07]],"id":41419602},{"atb":[[17.5,12.09],[12.5,23.13],[30,6.88]],"id":41419585},{"atb":[[44,4.64],[27,10.23],[120,1.67]],"id":41419614},{"atb":[[360,0.55],[210,0.95],[110,2.43]],"id":41419656},{"atb":[[140,1.43],[48,4.24],[29,9.5]],"id":41419590},{"atb":[[38,5.39],[95,2.12],[24,11.56]],"id":41419652},{"atb":[[16.5,12.87],[11.5,25.34],[28,7.39]],"id":41419619},{"atb":[[9,33.26],[20,10.5],[12.5,17.35]],"id":41419586},{"atb":[[600,0.44],[700,0.28],[850,0.23]],"id":41419631},{"atb":[[16.5,12.87],[9.6,23.2],[7.6,40.32]],"id":41419598},{"atb":[[16,17.74],[44,4.64],[22,9.5]],"id":41419660},{"atb":[[65,3.11],[36,7.6],[180,1.11]],"id":41419627},{"atb":[[17,12.47],[12,24.19],[29,7.12]],"id":41419594},{"atb":[[32,6.44],[18,11.73],[13,22.17]],"id":41419640},{"atb":[[16.5,12.87],[11.5,25.34],[28,7.39]],"id":41419607},{"atb":[[65,3.11],[36,7.6],[180,1.11]],"id":28546950},{"atb":[[7.2,32.19],[5.1,48.67],[4.1,85.84]],"id":41419636},{"atb":[[17.5,16.12],[50,4.07],[25,8.31]],"id":41419615},{"atb":[[42,4.86],[26,10.64],[110,1.82]],"id":41419611},{"atb":[[130,1.54],[46,4.43],[28,9.85]],"id":41419657},{"atb":[[6.8,34.41],[9.8,22.68],[5.4,60.48]],"id":41419591},{"atb":[[42,4.86],[26,10.64],[110,1.82]],"id":41435525},{"atb":[[600,0.44],[700,0.28],[850,0.23]],"id":41419653},{"atb":[[9.2,32.45],[21,9.97],[13,16.63]],"id":41419587},{"atb":[[19.5,10.79],[12,18.14],[8.8,34.11]],"id":41419599},{"atb":[[360,0.55],[210,0.95],[110,2.43]],"id":41419628},{"atb":[[40,5.11],[100,2.01],[25,11.08]],"id":41419595},{"atb":[[8.6,35.01],[19,11.08],[11.5,19]],"id":41419608},{"atb":[[4.3,80.64],[5.3,46.41],[7.6,30.24]],"id":41419637},{"atb":[[38,5.39],[95,2.12],[24,11.56]],"id":41419604},{"atb":[[18,15.65],[26,7.98],[55,3.69]],"id":41419616},{"atb":[[5.1,64.9],[9.2,24.34],[6.2,38.38]],"id":41419612},{"atb":[[32,6.44],[18,11.73],[13,22.17]],"id":41419592},{"atb":[[600,0.44],[700,0.28],[850,0.23]],"id":41419654},{"atb":[[18,15.65],[26,7.98],[55,3.69]],"id":41419588},{"atb":[[16,17.74],[44,4.64],[22,9.5]],"id":41419633},{"atb":[[16,13.3],[11,26.61],[27,7.67]],"id":41419600},{"atb":[[130,1.54],[46,4.43],[28,9.85]],"id":41419629},{"atb":[[600,0.44],[700,0.28],[850,0.23]],"id":41419658}],"con":true,"img":false}]}
{"op":"mcm","clk":"5352146187","pt":1646183572645,"mc":[{"id":"1.195503865","marketDefinition":{"bspMarket":false,"turnInPlayEnabled":false,"persistenceEnabled":false,"marketBaseRate":7.0,"eventId":"31272499","eventTypeId":"4339","numberOfWinners":1,"bettingType":"ODDS","marketType":"EXACTA","marketTime":"2022-03-02T10:15:00.000Z","suspendTime":"2022-03-02T10:15:00.000Z","bspReconciled":false,"complete":true,"inPlay":false,"crossMatching":false,"runnersVoidable":false,"numberOfActiveRunners":56,"betDelay":0,"status":"OPEN","runners":[{"status":"ACTIVE","sortPriority":1,"id":41419585,"name":"1 - 2"},{"status":"ACTIVE","sortPriority":2,"id":41419586,"name":"1 - 3"},{"status":"ACTIVE","sortPriority":3,"id":41419587,"name":"1 - 4"},{"status":"ACTIVE","sortPriority":4,"id":41419588,"name":"1 - 5"},{"status":"ACTIVE","sortPriority":5,"id":41419590,"name":"1 - 7"},{"status":"ACTIVE","sortPriority":6,"id":41419591,"name":"1 - 8"},{"status":"ACTIVE","sortPriority":7,"id":28546943,"name":"1 - 9"},{"status":"ACTIVE","sortPriority":8,"id":41419592,"name":"2 - 1"},{"status":"ACTIVE","sortPriority":9,"id":41419593,"name":"2 - 3"},{"status":"ACTIVE","sortPriority":10,"id":41419594,"name":"2 - 4"},{"status":"ACTIVE","sortPriority":11,"id":41419595,"name":"2 - 5"},{"status":"ACTIVE","sortPriority":12,"id":41419597,"name":"2 - 7"},{"status":"ACTIVE","sortPriority":13,"id":41419598,"name":"2 - 8"},{"status":"ACTIVE","sortPriority":14,"id":41419651,"name":"2 - 9"},{"status":"ACTIVE","sortPriority":15,"id":41419599,"name":"3 - 1"},{"status":"ACTIVE","sortPriority":16,"id":41419600,"name":"3 - 2"},{"status":"ACTIVE","sortPriority":17,"id":41419601,"name":"3 - 4"},{"status":"ACTIVE","sortPriority":18,"id":41419602,"name":"3 - 5"},{"status":"ACTIVE","sortPriority":19,"id":41419604,"name":"3 - 7"},{"status":"ACTIVE","sortPriority":20,"id":41419605,"name":"3 - 8"},{"status":"ACTIVE","sortPriority":21,"id":41419652,"name":"3 - 9"},{"status":"ACTIVE","sortPriority":22,"id":41419606,"name":"4 - 1"},{"status":"ACTIVE","sortPriority":23,"id":41419607,"name":"4 - 2"},{"status":"ACTIVE","sortPriority":24,"id":41419608,"name":"4 - 3"},{"status":"ACTIVE","sortPriority":25,"id":41419609,"name":"4 - 5"},{"status":"ACTIVE","sortPriority":26,"id":41419611,"name":"4 - 7"},{"status":"ACTIVE","sortPriority":27,"id":41419612,"name":"4 - 8"},{"status":"ACTIVE","sortPriority":28,"id":41435525,"name":"4 - 9"},{"status":"ACTIVE","sortPriority":29,"id":41419613,"name":"5 - 1"},{"status":"ACTIVE","sortPriority":30,"id":41419614,"name":"5 - 2"},{"status":"ACTIVE","sortPriority":31,"id":41419615,"name":"5 - 3"},{"status":"ACTIVE","sortPriority":32,"id":41419616,"name":"5 - 4"},{"status":"ACTIVE","sortPriority":33,"id":41419618,"name":"5 - 7"},{"status":"ACTIVE","sortPriority":34,"id":41419619,"name":"5 - 8"},{"status":"ACTIVE","sortPriority":35,"id":41419653,"name":"5 - 9"},{"status":"ACTIVE","sortPriority":36,"id":41419627,"name":"7 - 1"},{"status":"ACTIVE","sortPriority":37,"id":41419628,"name":"7 - 2"},{"status":"ACTIVE","sortPriority":38,"id":41419629,"name":"7 - 3"},{"status":"ACTIVE","sortPriority":39,"id":41419630,"name":"7 - 4"},{"status":"ACTIVE","sortPriority":40,"id":41419631,"name":"7 - 5"},{"status":"ACTIVE","sortPriority":41,"id":41419633,"name":"7 - 8"},{"status":"ACTIVE","sortPriority":42,"id":41419654,"name":"7 - 9"},{"status":"ACTIVE","sortPriority":43,"id":41419634,"name":"8 - 1"},{"status":"ACTIVE","sortPriority":44,"id":41419635,"name":"8 - 2"},{"status":"ACTIVE","sortPriority":45,"id":41419636,"name":"8 - 3"},{"status":"ACTIVE","sortPriority":46,"id":41419637,"name":"8 - 4"},{"status":"ACTIVE","sortPriority":47,"id":41419638,"name":"8 - 5"},{"status":"ACTIVE","sortPriority":48,"id":41419640,"name":"8 - 7"},{"status":"ACTIVE","sortPriority":49,"id":41419655,"name":"8 - 9"},{"status":"ACTIVE","sortPriority":50,"id":28546950,"name":"9 - 1"},{"status":"ACTIVE","sortPriority":51,"id":41419656,"name":"9 - 2"},{"status":"ACTIVE","sortPriority":52,"id":41419657,"name":"9 - 3"},{"status":"ACTIVE","sortPriority":53,"id":41435527,"name":"9 - 4"},{"status":"ACTIVE","sortPriority":54,"id":41419658,"name":"9 - 5"},{"status":"ACTIVE","sortPriority":55,"id":41419659,"name":"9 - 7"},{"status":"ACTIVE","sortPriority":56,"id":41419660,"name":"9 - 8"}],"regulators":["MR_INT"],"venue":"Rockhampton","countryCode":"AU","discountAllowed":true,"timezone":"Australia/Queensland","openDate":"2022-03-02T08:28:00.000Z","version":4382597898,"name":"Exacta","eventName":"Rockhampton (AUS) 2nd Mar"},"rc":[],"con":true,"img":false}]}
{"op":"mcm","clk":"5352158677","pt":1646183904344,"mc":[{"id":"1.195503865","marketDefinition":{"bspMarket":false,"turnInPlayEnabled":false,"persistenceEnabled":false,"marketBaseRate":7.0,"eventId":"31272499","eventTypeId":"4339","numberOfWinners":1,"bettingType":"ODDS","marketType":"EXACTA","marketTime":"2022-03-02T10:08:00.000Z","suspendTime":"2022-03-02T10:08:00.000Z","bspReconciled":false,"complete":true,"inPlay":false,"crossMatching":false,"runnersVoidable":false,"numberOfActiveRunners":56,"betDelay":0,"status":"OPEN","runners":[{"status":"ACTIVE","sortPriority":1,"id":41419585,"name":"1 - 2"},{"status":"ACTIVE","sortPriority":2,"id":41419586,"name":"1 - 3"},{"status":"ACTIVE","sortPriority":3,"id":41419587,"name":"1 - 4"},{"status":"ACTIVE","sortPriority":4,"id":41419588,"name":"1 - 5"},{"status":"ACTIVE","sortPriority":5,"id":41419590,"name":"1 - 7"},{"status":"ACTIVE","sortPriority":6,"id":41419591,"name":"1 - 8"},{"status":"ACTIVE","sortPriority":7,"id":28546943,"name":"1 - 9"},{"status":"ACTIVE","sortPriority":8,"id":41419592,"name":"2 - 1"},{"status":"ACTIVE","sortPriority":9,"id":41419593,"name":"2 - 3"},{"status":"ACTIVE","sortPriority":10,"id":41419594,"name":"2 - 4"},{"status":"ACTIVE","sortPriority":11,"id":41419595,"name":"2 - 5"},{"status":"ACTIVE","sortPriority":12,"id":41419597,"name":"2 - 7"},{"status":"ACTIVE","sortPriority":13,"id":41419598,"name":"2 - 8"},{"status":"ACTIVE","sortPriority":14,"id":41419651,"name":"2 - 9"},{"status":"ACTIVE","sortPriority":15,"id":41419599,"name":"3 - 1"},{"status":"ACTIVE","sortPriority":16,"id":41419600,"name":"3 - 2"},{"status":"ACTIVE","sortPriority":17,"id":41419601,"name":"3 - 4"},{"status":"ACTIVE","sortPriority":18,"id":41419602,"name":"3 - 5"},{"status":"ACTIVE","sortPriority":19,"id":41419604,"name":"3 - 7"},{"status":"ACTIVE","sortPriority":20,"id":41419605,"name":"3 - 8"},{"status":"ACTIVE","sortPriority":21,"id":41419652,"name":"3 - 9"},{"status":"ACTIVE","sortPriority":22,"id":41419606,"name":"4 - 1"},{"status":"ACTIVE","sortPriority":23,"id":41419607,"name":"4 - 2"},{"status":"ACTIVE","sortPriority":24,"id":41419608,"name":"4 - 3"},{"status":"ACTIVE","sortPriority":25,"id":41419609,"name":"4 - 5"},{"status":"ACTIVE","sortPriority":26,"id":41419611,"name":"4 - 7"},{"status":"ACTIVE","sortPriority":27,"id":41419612,"name":"4 - 8"},{"status":"ACTIVE","sortPriority":28,"id":41435525,"name":"4 - 9"},{"status":"ACTIVE","sortPriority":29,"id":41419613,"name":"5 - 1"},{"status":"ACTIVE","sortPriority":30,"id":41419614,"name":"5 - 2"},{"status":"ACTIVE","sortPriority":31,"id":41419615,"name":"5 - 3"},{"status":"ACTIVE","sortPriority":32,"id":41419616,"name":"5 - 4"},{"status":"ACTIVE","sortPriority":33,"id":41419618,"name":"5 - 7"},{"status":"ACTIVE","sortPriority":34,"id":41419619,"name":"5 - 8"},{"status":"ACTIVE","sortPriority":35,"id":41419653,"name":"5 - 9"},{"status":"ACTIVE","sortPriority":36,"id":41419627,"name":"7 - 1"},{"status":"ACTIVE","sortPriority":37,"id":41419628,"name":"7 - 2"},{"status":"ACTIVE","sortPriority":38,"id":41419629,"name":"7 - 3"},{"status":"ACTIVE","sortPriority":39,"id":41419630,"name":"7 - 4"},{"status":"ACTIVE","sortPriority":40,"id":41419631,"name":"7 - 5"},{"status":"ACTIVE","sortPriority":41,"id":41419633,"name":"7 - 8"},{"status":"ACTIVE","sortPriority":42,"id":41419654,"name":"7 - 9"},{"status":"ACTIVE","sortPriority":43,"id":41419634,"name":"8 - 1"},{"status":"ACTIVE","sortPriority":44,"id":41419635,"name":"8 - 2"},{"status":"ACTIVE","sortPriority":45,"id":41419636,"name":"8 - 3"},{"status":"ACTIVE","sortPriority":46,"id":41419637,"name":"8 - 4"},{"status":"ACTIVE","sortPriority":47,"id":41419638,"name":"8 - 5"},{"status":"ACTIVE","sortPriority":48,"id":41419640,"name":"8 - 7"},{"status":"ACTIVE","sortPriority":49,"id":41419655,"name":"8 - 9"},{"status":"ACTIVE","sortPriority":50,"id":28546950,"name":"9 - 1"},{"status":"ACTIVE","sortPriority":51,"id":41419656,"name":"9 - 2"},{"status":"ACTIVE","sortPriority":52,"id":41419657,"name":"9 - 3"},{"status":"ACTIVE","sortPriority":53,"id":41435527,"name":"9 - 4"},{"status":"ACTIVE","sortPriority":54,"id":41419658,"name":"9 - 5"},{"status":"ACTIVE","sortPriority":55,"id":41419659,"name":"9 - 7"},{"status":"ACTIVE","sortPriority":56,"id":41419660,"name":"9 - 8"}],"regulators":["MR_INT"],"venue":"Rockhampton","countryCode":"AU","discountAllowed":true,"timezone":"Australia/Queensland","openDate":"2022-03-02T08:28:00.000Z","version":4382602304,"name":"Exacta","eventName":"Rockhampton (AUS) 2nd Mar"},"rc":[],"con":true,"img":false}]}
{"op":"mcm","clk":"5352239428","pt":1646185602748,"mc":[{"id":"1.195503865","marketDefinition":{"bspMarket":false,"turnInPlayEnabled":false,"persistenceEnabled":false,"marketBaseRate":7.0,"eventId":"31272499","eventTypeId":"4339","numberOfWinners":1,"bettingType":"ODDS","marketType":"EXACTA","marketTime":"2022-03-02T10:08:00.000Z","suspendTime":"2022-03-02T10:08:00.000Z","bspReconciled":false,"complete":true,"inPlay":false,"crossMatching":false,"runnersVoidable":false,"numberOfActiveRunners":56,"betDelay":0,"status":"OPEN","runners":[{"status":"ACTIVE","sortPriority":1,"id":41419585,"name":"1 - 2"},{"status":"ACTIVE","sortPriority":2,"id":41419586,"name":"1 - 3"},{"status":"ACTIVE","sortPriority":3,"id":41419587,"name":"1 - 4"},{"status":"ACTIVE","sortPriority":4,"id":41419588,"name":"1 - 5"},{"status":"ACTIVE","sortPriority":5,"id":41419590,"name":"1 - 7"},{"status":"ACTIVE","sortPriority":6,"id":41419591,"name":"1 - 8"},{"status":"ACTIVE","sortPriority":7,"id":28546943,"name":"1 - 9"},{"status":"ACTIVE","sortPriority":8,"id":41419592,"name":"2 - 1"},{"status":"ACTIVE","sortPriority":9,"id":41419593,"name":"2 - 3"},{"status":"ACTIVE","sortPriority":10,"id":41419594,"name":"2 - 4"},{"status":"ACTIVE","sortPriority":11,"id":41419595,"name":"2 - 5"},{"status":"ACTIVE","sortPriority":12,"id":41419597,"name":"2 - 7"},{"status":"ACTIVE","sortPriority":13,"id":41419598,"name":"2 - 8"},{"status":"ACTIVE","sortPriority":14,"id":41419651,"name":"2 - 9"},{"status":"ACTIVE","sortPriority":15,"id":41419599,"name":"3 - 1"},{"status":"ACTIVE","sortPriority":16,"id":41419600,"name":"3 - 2"},{"status":"ACTIVE","sortPriority":17,"id":41419601,"name":"3 - 4"},{"status":"ACTIVE","sortPriority":18,"id":41419602,"name":"3 - 5"},{"status":"ACTIVE","sortPriority":19,"id":41419604,"name":"3 - 7"},{"status":"ACTIVE","sortPriority":20,"id":41419605,"name":"3 - 8"},{"status":"ACTIVE","sortPriority":21,"id":41419652,"name":"3 - 9"},{"status":"ACTIVE","sortPriority":22,"id":41419606,"name":"4 - 1"},{"status":"ACTIVE","sortPriority":23,"id":41419607,"name":"4 - 2"},{"status":"ACTIVE","sortPriority":24,"id":41419608,"name":"4 - 3"},{"status":"ACTIVE","sortPriority":25,"id":41419609,"name":"4 - 5"},{"status":"ACTIVE","sortPriority":26,"id":41419611,"name":"4 - 7"},{"status":"ACTIVE","sortPriority":27,"id":41419612,"name":"4 - 8"},{"status":"ACTIVE","sortPriority":28,"id":41435525,"name":"4 - 9"},{"status":"ACTIVE","sortPriority":29,"id":41419613,"name":"5 - 1"},{"status":"ACTIVE","sortPriority":30,"id":41419614,"name":"5 - 2"},{"status":"ACTIVE","sortPriority":31,"id":41419615,"name":"5 - 3"},{"status":"ACTIVE","sortPriority":32,"id":41419616,"name":"5 - 4"},{"status":"ACTIVE","sortPriority":33,"id":41419618,"name":"5 - 7"},{"status":"ACTIVE","sortPriority":34,"id":41419619,"name":"5 - 8"},{"status":"ACTIVE","sortPriority":35,"id":41419653,"name":"5 - 9"},{"status":"ACTIVE","sortPriority":36,"id":41419627,"name":"7 - 1"},{"status":"ACTIVE","sortPriority":37,"id":41419628,"name":"7 - 2"},{"status":"ACTIVE","sortPriority":38,"id":41419629,"name":"7 - 3"},{"status":"ACTIVE","sortPriority":39,"id":41419630,"name":"7 - 4"},{"status":"ACTIVE","sortPriority":40,"id":41419631,"name":"7 - 5"},{"status":"ACTIVE","sortPriority":41,"id":41419633,"name":"7 - 8"},{"status":"ACTIVE","sortPriority":42,"id":41419654,"name":"7 - 9"},{"status":"ACTIVE","sortPriority":43,"id":41419634,"name":"8 - 1"},{"status":"ACTIVE","sortPriority":44,"id":41419635,"name":"8 - 2"},{"status":"ACTIVE","sortPriority":45,"id":41419636,"name":"8 - 3"},{"status":"ACTIVE","sortPriority":46,"id":41419637,"name":"8 - 4"},{"status":"ACTIVE","sortPriority":47,"id":41419638,"name":"8 - 5"},{"status":"ACTIVE","sortPriority":48,"id":41419640,"name":"8 - 7"},{"status":"ACTIVE","sortPriority":49,"id":41419655,"name":"8 - 9"},{"status":"ACTIVE","sortPriority":50,"id":28546950,"name":"9 - 1"},{"status":"ACTIVE","sortPriority":51,"id":41419656,"name":"9 - 2"},{"status":"ACTIVE","sortPriority":52,"id":41419657,"name":"9 - 3"},{"status":"ACTIVE","sortPriority":53,"id":41435527,"name":"9 - 4"},{"status":"ACTIVE","sortPriority":54,"id":41419658,"name":"9 - 5"},{"status":"ACTIVE","sortPriority":55,"id":41419659,"name":"9 - 7"},{"status":"ACTIVE","sortPriority":56,"id":41419660,"name":"9 - 8"}],"regulators":["MR_INT"],"venue":"Rockhampton","countryCode":"AU","discountAllowed":true,"timezone":"Australia/Queensland","openDate":"2022-03-02T08:28:00.000Z","version":4382602304,"name":"Exacta","eventName":"Rockhampton (AUS) 2nd Mar"},"rc":[{"atb":[[17,16.65],[48,4.25],[24,8.69]],"id":41419609},{"atb":[[9,33.31],[20,10.51],[12.5,17.38]],"id":41419638},{"atb":[[4.8,70.14],[8.6,26.3],[5.8,41.64]],"id":41419605},{"atb":[[8,28.55],[4.5,76.15],[5.5,44.42]],"id":41419634},{"atb":[[18.5,15.22],[27,7.68],[60,3.38]],"id":41419613},{"atb":[[16.5,12.89],[11.5,25.38],[28,7.4]],"id":41419593},{"atb":[[32,6.45],[18,11.75],[13,22.2]],"id":41419655},{"atb":[[150,1.34],[50,4.07],[30,9.19]],"id":41435527},{"atb":[[330,0.6],[180,1.11],[90,2.99]],"id":41419651},{"atb":[[600,0.44],[700,0.28],[850,0.23]],"id":41419618},{"atb":[[8.6,35.07],[19,11.1],[11.5,19.03]],"id":41419601},{"atb":[[150,1.34],[50,4.07],[30,9.19]],"id":41419630},{"atb":[[330,0.6],[180,1.11],[90,2.99]],"id":41419597},{"atb":[[140,1.43],[48,4.25],[29,9.52]],"id":28546943},{"atb":[[600,0.44],[700,0.28],[850,0.23]],"id":41419659},{"atb":[[9.2,32.5],[21,9.99],[13,16.65]],"id":41419606},{"atb":[[5.8,55.52],[11.5,19.03],[7.6,30.29]],"id":41419635},{"atb":[[16.5,17.19],[46,4.44],[23,9.08]],"id":41419602},{"atb":[[17.5,12.11],[12.5,23.17],[30,6.89]],"id":41419585},{"atb":[[44,4.65],[27,10.25],[120,1.67]],"id":41419614},{"atb":[[360,0.55],[210,0.95],[110,2.44]],"id":41419656},{"atb":[[140,1.43],[48,4.25],[29,9.52]],"id":41419590},{"atb":[[38,5.4],[95,2.12],[24,11.58]],"id":41419652},{"atb":[[16.5,12.89],[11.5,25.38],[28,7.4]],"id":41419619},{"atb":[[9,33.31],[20,10.51],[12.5,17.38]],"id":41419586},{"atb":[[600,0.44],[700,0.28],[850,0.23]],"id":41419631},{"atb":[[16.5,12.89],[9.6,23.24],[7.6,40.38]],"id":41419598},{"atb":[[16,17.77],[44,4.65],[22,9.52]],"id":41419660},{"atb":[[65,3.12],[36,7.61],[180,1.11]],"id":41419627},{"atb":[[17,12.49],[12,24.23],[29,7.13]],"id":41419594},{"atb":[[32,6.45],[18,11.75],[13,22.2]],"id":41419640},{"atb":[[16.5,12.89],[11.5,25.38],[28,7.4]],"id":41419607},{"atb":[[65,3.12],[36,7.61],[180,1.11]],"id":28546950},{"atb":[[7.2,32.24],[5.1,48.75],[4.1,85.98]],"id":41419636},{"atb":[[17.5,16.15],[50,4.07],[25,8.32]],"id":41419615},{"atb":[[42,4.87],[26,10.66],[110,1.83]],"id":41419611},{"atb":[[130,1.54],[46,4.44],[28,9.86]],"id":41419657},{"atb":[[6.8,34.46],[9.8,22.71],[5.4,60.57]],"id":41419591},{"atb":[[42,4.87],[26,10.66],[110,1.83]],"id":41435525},{"atb":[[600,0.44],[700,0.28],[850,0.23]],"id":41419653},{"atb":[[9.2,32.5],[21,9.99],[13,16.65]],"id":41419587},{"atb":[[19.5,10.8],[12,18.17],[8.8,34.17]],"id":41419599},{"atb":[[360,0.55],[210,0.95],[110,2.44]],"id":41419628},{"atb":[[40,5.12],[100,2.01],[25,11.1]],"id":41419595},{"atb":[[8.6,35.07],[19,11.1],[11.5,19.03]],"id":41419608},{"atb":[[4.3,80.76],[5.3,46.49],[7.6,30.29]],"id":41419637},{"atb":[[38,5.4],[95,2.12],[24,11.58]],"id":41419604},{"atb":[[18,15.67],[26,7.99],[55,3.7]],"id":41419616},{"atb":[[5.1,65],[9.2,24.37],[6.2,38.44]],"id":41419612},{"atb":[[32,6.45],[18,11.75],[13,22.2]],"id":41419592},{"atb":[[600,0.44],[700,0.28],[850,0.23]],"id":41419654},{"atb":[[18,15.67],[26,7.99],[55,3.7]],"id":41419588},{"atb":[[16,17.77],[44,4.65],[22,9.52]],"id":41419633},{"atb":[[16,13.32],[11,26.65],[27,7.68]],"id":41419600},{"atb":[[130,1.54],[46,4.44],[28,9.86]],"id":41419629},{"atb":[[600,0.44],[700,0.28],[850,0.23]],"id":41419658}],"con":true,"img":true}]}
{"op":"mcm","clk":"5352466716","pt":1646191002691,"mc":[{"id":"1.195503865","marketDefinition":{"bspMarket":false,"turnInPlayEnabled":false,"persistenceEnabled":false,"marketBaseRate":7.0,"eventId":"31272499","eventTypeId":"4339","numberOfWinners":1,"bettingType":"ODDS","marketType":"EXACTA","marketTime":"2022-03-02T10:08:00.000Z","suspendTime":"2022-03-02T10:08:00.000Z","bspReconciled":false,"complete":true,"inPlay":false,"crossMatching":false,"runnersVoidable":false,"numberOfActiveRunners":56,"betDelay":0,"status":"OPEN","runners":[{"status":"ACTIVE","sortPriority":1,"id":41419585,"name":"1 - 2"},{"status":"ACTIVE","sortPriority":2,"id":41419586,"name":"1 - 3"},{"status":"ACTIVE","sortPriority":3,"id":41419587,"name":"1 - 4"},{"status":"ACTIVE","sortPriority":4,"id":41419588,"name":"1 - 5"},{"status":"ACTIVE","sortPriority":5,"id":41419590,"name":"1 - 7"},{"status":"ACTIVE","sortPriority":6,"id":41419591,"name":"1 - 8"},{"status":"ACTIVE","sortPriority":7,"id":28546943,"name":"1 - 9"},{"status":"ACTIVE","sortPriority":8,"id":41419592,"name":"2 - 1"},{"status":"ACTIVE","sortPriority":9,"id":41419593,"name":"2 - 3"},{"status":"ACTIVE","sortPriority":10,"id":41419594,"name":"2 - 4"},{"status":"ACTIVE","sortPriority":11,"id":41419595,"name":"2 - 5"},{"status":"ACTIVE","sortPriority":12,"id":41419597,"name":"2 - 7"},{"status":"ACTIVE","sortPriority":13,"id":41419598,"name":"2 - 8"},{"status":"ACTIVE","sortPriority":14,"id":41419651,"name":"2 - 9"},{"status":"ACTIVE","sortPriority":15,"id":41419599,"name":"3 - 1"},{"status":"ACTIVE","sortPriority":16,"id":41419600,"name":"3 - 2"},{"status":"ACTIVE","sortPriority":17,"id":41419601,"name":"3 - 4"},{"status":"ACTIVE","sortPriority":18,"id":41419602,"name":"3 - 5"},{"status":"ACTIVE","sortPriority":19,"id":41419604,"name":"3 - 7"},{"status":"ACTIVE","sortPriority":20,"id":41419605,"name":"3 - 8"},{"status":"ACTIVE","sortPriority":21,"id":41419652,"name":"3 - 9"},{"status":"ACTIVE","sortPriority":22,"id":41419606,"name":"4 - 1"},{"status":"ACTIVE","sortPriority":23,"id":41419607,"name":"4 - 2"},{"status":"ACTIVE","sortPriority":24,"id":41419608,"name":"4 - 3"},{"status":"ACTIVE","sortPriority":25,"id":41419609,"name":"4 - 5"},{"status":"ACTIVE","sortPriority":26,"id":41419611,"name":"4 - 7"},{"status":"ACTIVE","sortPriority":27,"id":41419612,"name":"4 - 8"},{"status":"ACTIVE","sortPriority":28,"id":41435525,"name":"4 - 9"},{"status":"ACTIVE","sortPriority":29,"id":41419613,"name":"5 - 1"},{"status":"ACTIVE","sortPriority":30,"id":41419614,"name":"5 - 2"},{"status":"ACTIVE","sortPriority":31,"id":41419615,"name":"5 - 3"},{"status":"ACTIVE","sortPriority":32,"id":41419616,"name":"5 - 4"},{"status":"ACTIVE","sortPriority":33,"id":41419618,"name":"5 - 7"},{"status":"ACTIVE","sortPriority":34,"id":41419619,"name":"5 - 8"},{"status":"ACTIVE","sortPriority":35,"id":41419653,"name":"5 - 9"},{"status":"ACTIVE","sortPriority":36,"id":41419627,"name":"7 - 1"},{"status":"ACTIVE","sortPriority":37,"id":41419628,"name":"7 - 2"},{"status":"ACTIVE","sortPriority":38,"id":41419629,"name":"7 - 3"},{"status":"ACTIVE","sortPriority":39,"id":41419630,"name":"7 - 4"},{"status":"ACTIVE","sortPriority":40,"id":41419631,"name":"7 - 5"},{"status":"ACTIVE","sortPriority":41,"id":41419633,"name":"7 - 8"},{"status":"ACTIVE","sortPriority":42,"id":41419654,"name":"7 - 9"},{"status":"ACTIVE","sortPriority":43,"id":41419634,"name":"8 - 1"},{"status":"ACTIVE","sortPriority":44,"id":41419635,"name":"8 - 2"},{"status":"ACTIVE","sortPriority":45,"id":41419636,"name":"8 - 3"},{"status":"ACTIVE","sortPriority":46,"id":41419637,"name":"8 - 4"},{"status":"ACTIVE","sortPriority":47,"id":41419638,"name":"8 - 5"},{"status":"ACTIVE","sortPriority":48,"id":41419640,"name":"8 - 7"},{"status":"ACTIVE","sortPriority":49,"id":41419655,"name":"8 - 9"},{"status":"ACTIVE","sortPriority":50,"id":28546950,"name":"9 - 1"},{"status":"ACTIVE","sortPriority":51,"id":41419656,"name":"9 - 2"},{"status":"ACTIVE","sortPriority":52,"id":41419657,"name":"9 - 3"},{"status":"ACTIVE","sortPriority":53,"id":41435527,"name":"9 - 4"},{"status":"ACTIVE","sortPriority":54,"id":41419658,"name":"9 - 5"},{"status":"ACTIVE","sortPriority":55,"id":41419659,"name":"9 - 7"},{"status":"ACTIVE","sortPriority":56,"id":41419660,"name":"9 - 8"}],"regulators":["MR_INT"],"venue":"Rockhampton","countryCode":"AU","discountAllowed":true,"timezone":"Australia/Queensland","openDate":"2022-03-02T08:28:00.000Z","version":4382602304,"name":"Exacta","eventName":"Rockhampton (AUS) 2nd Mar"},"rc":[{"atb":[[17,16.68],[48,4.26],[24,8.7]],"id":41419609},{"atb":[[9,33.37],[20,10.53],[12.5,17.41]],"id":41419638},{"atb":[[4.8,70.25],[8.6,26.34],[5.8,41.71]],"id":41419605},{"atb":[[8,28.6],[4.5,76.28],[5.5,44.49]],"id":41419634},{"atb":[[18.5,15.25],[27,7.7],[60,3.39]],"id":41419613},{"atb":[[16.5,12.91],[11.5,25.42],[28,7.41]],"id":41419593},{"atb":[[32,6.46],[18,11.77],[13,22.24]],"id":41419655},{"atb":[[150,1.34],[50,4.08],[30,9.2]],"id":41435527},{"atb":[[330,0.6],[180,1.11],[90,2.99]],"id":41419651},{"atb":[[600,0.44],[700,0.28],[850,0.23]],"id":41419618},{"atb":[[8.6,35.13],[19,11.12],[11.5,19.06]],"id":41419601},{"atb":[[150,1.34],[50,4.08],[30,9.2]],"id":41419630},{"atb":[[330,0.6],[180,1.11],[90,2.99]],"id":41419597},{"atb":[[140,1.44],[48,4.26],[29,9.53]],"id":28546943},{"atb":[[600,0.44],[700,0.28],[850,0.23]],"id":41419659},{"atb":[[9.2,32.55],[21,10.01],[13,16.68]],"id":41419606},{"atb":[[5.8,55.62],[11.5,19.06],[7.6,30.34]],"id":41419635},{"atb":[[16.5,17.22],[46,4.45],[23,9.09]],"id":41419602},{"atb":[[17.5,12.13],[12.5,23.21],[30,6.9]],"id":41419585},{"atb":[[44,4.65],[27,10.26],[120,1.68]],"id":41419614},{"atb":[[360,0.55],[210,0.95],[110,2.44]],"id":41419656},{"atb":[[140,1.44],[48,4.26],[29,9.53]],"id":41419590},{"atb":[[38,5.41],[95,2.13],[24,11.6]],"id":41419652},{"atb":[[16.5,12.91],[11.5,25.42],[28,7.41]],"id":41419619},{"atb":[[9,33.37],[20,10.53],[12.5,17.41]],"id":41419586},{"atb":[[600,0.44],[700,0.28],[850,0.23]],"id":41419631},{"atb":[[16.5,12.91],[9.6,23.28],[7.6,40.45]],"id":41419598},{"atb":[[16,17.8],[44,4.65],[22,9.53]],"id":41419660},{"atb":[[65,3.12],[36,7.63],[180,1.11]],"id":41419627},{"atb":[[17,12.51],[12,24.27],[29,7.14]],"id":41419594},{"atb":[[32,6.46],[18,11.77],[13,22.24]],"id":41419640},{"atb":[[16.5,12.91],[11.5,25.42],[28,7.41]],"id":41419607},{"atb":[[65,3.12],[36,7.63],[180,1.11]],"id":28546950},{"atb":[[7.2,32.29],[5.1,48.83],[4.1,86.12]],"id":41419636},{"atb":[[17.5,16.17],[50,4.08],[25,8.34]],"id":41419615},{"atb":[[42,4.88],[26,10.67],[110,1.83]],"id":41419611},{"atb":[[130,1.55],[46,4.45],[28,9.88]],"id":41419657},{"atb":[[6.8,34.52],[9.8,22.75],[5.4,60.67]],"id":41419591},{"atb":[[42,4.88],[26,10.67],[110,1.83]],"id":41435525},{"atb":[[600,0.44],[700,0.28],[850,0.23]],"id":41419653},{"atb":[[9.2,32.55],[21,10.01],[13,16.68]],"id":41419587},{"atb":[[19.5,10.82],[12,18.2],[8.8,34.23]],"id":41419599},{"atb":[[360,0.55],[210,0.95],[110,2.44]],"id":41419628},{"atb":[[40,5.13],[100,2.02],[25,11.12]],"id":41419595},{"atb":[[8.6,35.13],[19,11.12],[11.5,19.06]],"id":41419608},{"atb":[[4.3,80.9],[5.3,46.56],[7.6,30.34]],"id":41419637},{"atb":[[38,5.41],[95,2.13],[24,11.6]],"id":41419604},{"atb":[[18,15.7],[26,8],[55,3.7]],"id":41419616},{"atb":[[5.1,65.11],[9.2,24.42],[6.2,38.5]],"id":41419612},{"atb":[[32,6.46],[18,11.77],[13,22.24]],"id":41419592},{"atb":[[600,0.44],[700,0.28],[850,0.23]],"id":41419654},{"atb":[[18,15.7],[26,8],[55,3.7]],"id":41419588},{"atb":[[16,17.8],[44,4.65],[22,9.53]],"id":41419633},{"atb":[[16,13.34],[11,26.69],[27,7.7]],"id":41419600},{"atb":[[130,1.55],[46,4.45],[28,9.88]],"id":41419629},{"atb":[[600,0.44],[700,0.28],[850,0.23]],"id":41419658}],"con":true,"img":true}]}
{"op":"mcm","clk":"5352823522","pt":1646201802742,"mc":[{"id":"1.195503865","marketDefinition":{"bspMarket":false,"turnInPlayEnabled":false,"persistenceEnabled":false,"marketBaseRate":7.0,"eventId":"31272499","eventTypeId":"4339","numberOfWinners":1,"bettingType":"ODDS","marketType":"EXACTA","marketTime":"2022-03-02T10:08:00.000Z","suspendTime":"2022-03-02T10:08:00.000Z","bspReconciled":false,"complete":true,"inPlay":false,"crossMatching":false,"runnersVoidable":false,"numberOfActiveRunners":56,"betDelay":0,"status":"OPEN","runners":[{"status":"ACTIVE","sortPriority":1,"id":41419585,"name":"1 - 2"},{"status":"ACTIVE","sortPriority":2,"id":41419586,"name":"1 - 3"},{"status":"ACTIVE","sortPriority":3,"id":41419587,"name":"1 - 4"},{"status":"ACTIVE","sortPriority":4,"id":41419588,"name":"1 - 5"},{"status":"ACTIVE","sortPriority":5,"id":41419590,"name":"1 - 7"},{"status":"ACTIVE","sortPriority":6,"id":41419591,"name":"1 - 8"},{"status":"ACTIVE","sortPriority":7,"id":28546943,"name":"1 - 9"},{"status":"ACTIVE","sortPriority":8,"id":41419592,"name":"2 - 1"},{"status":"ACTIVE","sortPriority":9,"id":41419593,"name":"2 - 3"},{"status":"ACTIVE","sortPriority":10,"id":41419594,"name":"2 - 4"},{"status":"ACTIVE","sortPriority":11,"id":41419595,"name":"2 - 5"},{"status":"ACTIVE","sortPriority":12,"id":41419597,"name":"2 - 7"},{"status":"ACTIVE","sortPriority":13,"id":41419598,"name":"2 - 8"},{"status":"ACTIVE","sortPriority":14,"id":41419651,"name":"2 - 9"},{"status":"ACTIVE","sortPriority":15,"id":41419599,"name":"3 - 1"},{"status":"ACTIVE","sortPriority":16,"id":41419600,"name":"3 - 2"},{"status":"ACTIVE","sortPriority":17,"id":41419601,"name":"3 - 4"},{"status":"ACTIVE","sortPriority":18,"id":41419602,"name":"3 - 5"},{"status":"ACTIVE","sortPriority":19,"id":41419604,"name":"3 - 7"},{"status":"ACTIVE","sortPriority":20,"id":41419605,"name":"3 - 8"},{"status":"ACTIVE","sortPriority":21,"id":41419652,"name":"3 - 9"},{"status":"ACTIVE","sortPriority":22,"id":41419606,"name":"4 - 1"},{"status":"ACTIVE","sortPriority":23,"id":41419607,"name":"4 - 2"},{"status":"ACTIVE","sortPriority":24,"id":41419608,"name":"4 - 3"},{"status":"ACTIVE","sortPriority":25,"id":41419609,"name":"4 - 5"},{"status":"ACTIVE","sortPriority":26,"id":41419611,"name":"4 - 7"},{"status":"ACTIVE","sortPriority":27,"id":41419612,"name":"4 - 8"},{"status":"ACTIVE","sortPriority":28,"id":41435525,"name":"4 - 9"},{"status":"ACTIVE","sortPriority":29,"id":41419613,"name":"5 - 1"},{"status":"ACTIVE","sortPriority":30,"id":41419614,"name":"5 - 2"},{"status":"ACTIVE","sortPriority":31,"id":41419615,"name":"5 - 3"},{"status":"ACTIVE","sortPriority":32,"id":41419616,"name":"5 - 4"},{"status":"ACTIVE","sortPriority":33,"id":41419618,"name":"5 - 7"},{"status":"ACTIVE","sortPriority":34,"id":41419619,"name":"5 - 8"},{"status":"ACTIVE","sortPriority":35,"id":41419653,"name":"5 - 9"},{"status":"ACTIVE","sortPriority":36,"id":41419627,"name":"7 - 1"},{"status":"ACTIVE","sortPriority":37,"id":41419628,"name":"7 - 2"},{"status":"ACTIVE","sortPriority":38,"id":41419629,"name":"7 - 3"},{"status":"ACTIVE","sortPriority":39,"id":41419630,"name":"7 - 4"},{"status":"ACTIVE","sortPriority":40,"id":41419631,"name":"7 - 5"},{"status":"ACTIVE","sortPriority":41,"id":41419633,"name":"7 - 8"},{"status":"ACTIVE","sortPriority":42,"id":41419654,"name":"7 - 9"},{"status":"ACTIVE","sortPriority":43,"id":41419634,"name":"8 - 1"},{"status":"ACTIVE","sortPriority":44,"id":41419635,"name":"8 - 2"},{"status":"ACTIVE","sortPriority":45,"id":41419636,"name":"8 - 3"},{"status":"ACTIVE","sortPriority":46,"id":41419637,"name":"8 - 4"},{"status":"ACTIVE","sortPriority":47,"id":41419638,"name":"8 - 5"},{"status":"ACTIVE","sortPriority":48,"id":41419640,"name":"8 - 7"},{"status":"ACTIVE","sortPriority":49,"id":41419655,"name":"8 - 9"},{"status":"ACTIVE","sortPriority":50,"id":28546950,"name":"9 - 1"},{"status":"ACTIVE","sortPriority":51,"id":41419656,"name":"9 - 2"},{"status":"ACTIVE","sortPriority":52,"id":41419657,"name":"9 - 3"},{"status":"ACTIVE","sortPriority":53,"id":41435527,"name":"9 - 4"},{"status":"ACTIVE","sortPriority":54,"id":41419658,"name":"9 - 5"},{"status":"ACTIVE","sortPriority":55,"id":41419659,"name":"9 - 7"},{"status":"ACTIVE","sortPriority":56,"id":41419660,"name":"9 - 8"}],"regulators":["MR_INT"],"venue":"Rockhampton","countryCode":"AU","discountAllowed":true,"timezone":"Australia/Queensland","openDate":"2022-03-02T08:28:00.000Z","version":4382602304,"name":"Exacta","eventName":"Rockhampton (AUS) 2nd Mar"},"rc":[{"atb":[[17,16.68],[48,4.25],[24,8.7]],"id":41419609},{"atb":[[9,33.36],[20,10.53],[12.5,17.4]],"id":41419638},{"atb":[[4.8,70.23],[8.6,26.33],[5.8,41.7]],"id":41419605},{"atb":[[8,28.59],[4.5,76.25],[5.5,44.48]],"id":41419634},{"atb":[[18.5,15.24],[27,7.69],[60,3.39]],"id":41419613},{"atb":[[16.5,12.91],[11.5,25.41],[28,7.41]],"id":41419593},{"atb":[[32,6.45],[18,11.77],[13,22.23]],"id":41419655},{"atb":[[150,1.34],[50,4.08],[30,9.2]],"id":41435527},{"atb":[[330,0.6],[180,1.11],[90,2.99]],"id":41419651},{"atb":[[600,0.44],[700,0.28],[850,0.23]],"id":41419618},{"atb":[[8.6,35.11],[19,11.12],[11.5,19.06]],"id":41419601},{"atb":[[150,1.34],[50,4.08],[30,9.2]],"id":41419630},{"atb":[[330,0.6],[180,1.11],[90,2.99]],"id":41419597},{"atb":[[140,1.44],[48,4.25],[29,9.53]],"id":28546943},{"atb":[[600,0.44],[700,0.28],[850,0.23]],"id":41419659},{"atb":[[9.2,32.54],[21,10],[13,16.68]],"id":41419606},{"atb":[[5.8,55.59],[11.5,19.06],[7.6,30.33]],"id":41419635},{"atb":[[16.5,17.22],[46,4.44],[23,9.09]],"id":41419602},{"atb":[[17.5,12.13],[12.5,23.2],[30,6.9]],"id":41419585},{"atb":[[44,4.65],[27,10.26],[120,1.68]],"id":41419614},{"atb":[[360,0.55],[210,0.95],[110,2.44]],"id":41419656},{"atb":[[140,1.44],[48,4.25],[29,9.53]],"id":41419590},{"atb":[[38,5.41],[95,2.12],[24,11.6]],"id":41419652},{"atb":[[16.5,12.91],[11.5,25.41],[28,7.41]],"id":41419619},{"atb":[[9,33.36],[20,10.53],[12.5,17.4]],"id":41419586},{"atb":[[600,0.44],[700,0.28],[850,0.23]],"id":41419631},{"atb":[[16.5,12.91],[9.6,23.27],[7.6,40.43]],"id":41419598},{"atb":[[16,17.79],[44,4.65],[22,9.53]],"id":41419660},{"atb":[[65,3.12],[36,7.62],[180,1.11]],"id":41419627},{"atb":[[17,12.5],[12,24.26],[29,7.14]],"id":41419594},{"atb":[[32,6.45],[18,11.77],[13,22.23]],"id":41419640},{"atb":[[16.5,12.91],[11.5,25.41],[28,7.41]],"id":41419607},{"atb":[[65,3.12],[36,7.62],[180,1.11]],"id":28546950},{"atb":[[7.2,32.28],[5.1,48.81],[4.1,86.09]],"id":41419636},{"atb":[[17.5,16.17],[50,4.08],[25,8.33]],"id":41419615},{"atb":[[42,4.88],[26,10.67],[110,1.83]],"id":41419611},{"atb":[[130,1.55],[46,4.44],[28,9.88]],"id":41419657},{"atb":[[6.8,34.51],[9.8,22.74],[5.4,60.65]],"id":41419591},{"atb":[[42,4.88],[26,10.67],[110,1.83]],"id":41435525},{"atb":[[600,0.44],[700,0.28],[850,0.23]],"id":41419653},{"atb":[[9.2,32.54],[21,10],[13,16.68]],"id":41419587},{"atb":[[19.5,10.82],[12,18.19],[8.8,34.21]],"id":41419599},{"atb":[[360,0.55],[210,0.95],[110,2.44]],"id":41419628},{"atb":[[40,5.13],[100,2.02],[25,11.12]],"id":41419595},{"atb":[[8.6,35.11],[19,11.12],[11.5,19.06]],"id":41419608},{"atb":[[4.3,80.87],[5.3,46.55],[7.6,30.33]],"id":41419637},{"atb":[[38,5.41],[95,2.12],[24,11.6]],"id":41419604},{"atb":[[18,15.69],[26,8],[55,3.7]],"id":41419616},{"atb":[[5.1,65.09],[9.2,24.41],[6.2,38.49]],"id":41419612},{"atb":[[32,6.45],[18,11.77],[13,22.23]],"id":41419592},{"atb":[[600,0.44],[700,0.28],[850,0.23]],"id":41419654},{"atb":[[18,15.69],[26,8],[55,3.7]],"id":41419588},{"atb":[[16,17.79],[44,4.65],[22,9.53]],"id":41419633},{"atb":[[16,13.34],[11,26.68],[27,7.69]],"id":41419600},{"atb":[[130,1.55],[46,4.44],[28,9.88]],"id":41419629},{"atb":[[600,0.44],[700,0.28],[850,0.23]],"id":41419658}],"con":true,"img":true}]}
{"op":"mcm","clk":"5353028892","pt":1646207202759,"mc":[{"id":"1.195503865","marketDefinition":{"bspMarket":false,"turnInPlayEnabled":false,"persistenceEnabled":false,"marketBaseRate":7.0,"eventId":"31272499","eventTypeId":"4339","numberOfWinners":1,"bettingType":"ODDS","marketType":"EXACTA","marketTime":"2022-03-02T10:08:00.000Z","suspendTime":"2022-03-02T10:08:00.000Z","bspReconciled":false,"complete":true,"inPlay":false,"crossMatching":false,"runnersVoidable":false,"numberOfActiveRunners":56,"betDelay":0,"status":"OPEN","runners":[{"status":"ACTIVE","sortPriority":1,"id":41419585,"name":"1 - 2"},{"status":"ACTIVE","sortPriority":2,"id":41419586,"name":"1 - 3"},{"status":"ACTIVE","sortPriority":3,"id":41419587,"name":"1 - 4"},{"status":"ACTIVE","sortPriority":4,"id":41419588,"name":"1 - 5"},{"status":"ACTIVE","sortPriority":5,"id":41419590,"name":"1 - 7"},{"status":"ACTIVE","sortPriority":6,"id":41419591,"name":"1 - 8"},{"status":"ACTIVE","sortPriority":7,"id":28546943,"name":"1 - 9"},{"status":"ACTIVE","sortPriority":8,"id":41419592,"name":"2 - 1"},{"status":"ACTIVE","sortPriority":9,"id":41419593,"name":"2 - 3"},{"status":"ACTIVE","sortPriority":10,"id":41419594,"name":"2 - 4"},{"status":"ACTIVE","sortPriority":11,"id":41419595,"name":"2 - 5"},{"status":"ACTIVE","sortPriority":12,"id":41419597,"name":"2 - 7"},{"status":"ACTIVE","sortPriority":13,"id":41419598,"name":"2 - 8"},{"status":"ACTIVE","sortPriority":14,"id":41419651,"name":"2 - 9"},{"status":"ACTIVE","sortPriority":15,"id":41419599,"name":"3 - 1"},{"status":"ACTIVE","sortPriority":16,"id":41419600,"name":"3 - 2"},{"status":"ACTIVE","sortPriority":17,"id":41419601,"name":"3 - 4"},{"status":"ACTIVE","sortPriority":18,"id":41419602,"name":"3 - 5"},{"status":"ACTIVE","sortPriority":19,"id":41419604,"name":"3 - 7"},{"status":"ACTIVE","sortPriority":20,"id":41419605,"name":"3 - 8"},{"status":"ACTIVE","sortPriority":21,"id":41419652,"name":"3 - 9"},{"status":"ACTIVE","sortPriority":22,"id":41419606,"name":"4 - 1"},{"status":"ACTIVE","sortPriority":23,"id":41419607,"name":"4 - 2"},{"status":"ACTIVE","sortPriority":24,"id":41419608,"name":"4 - 3"},{"status":"ACTIVE","sortPriority":25,"id":41419609,"name":"4 - 5"},{"status":"ACTIVE","sortPriority":26,"id":41419611,"name":"4 - 7"},{"status":"ACTIVE","sortPriority":27,"id":41419612,"name":"4 - 8"},{"status":"ACTIVE","sortPriority":28,"id":41435525,"name":"4 - 9"},{"status":"ACTIVE","sortPriority":29,"id":41419613,"name":"5 - 1"},{"status":"ACTIVE","sortPriority":30,"id":41419614,"name":"5 - 2"},{"status":"ACTIVE","sortPriority":31,"id":41419615,"name":"5 - 3"},{"status":"ACTIVE","sortPriority":32,"id":41419616,"name":"5 - 4"},{"status":"ACTIVE","sortPriority":33,"id":41419618,"name":"5 - 7"},{"status":"ACTIVE","sortPriority":34,"id":41419619,"name":"5 - 8"},{"status":"ACTIVE","sortPriority":35,"id":41419653,"name":"5 - 9"},{"status":"ACTIVE","sortPriority":36,"id":41419627,"name":"7 - 1"},{"status":"ACTIVE","sortPriority":37,"id":41419628,"name":"7 - 2"},{"status":"ACTIVE","sortPriority":38,"id":41419629,"name":"7 - 3"},{"status":"ACTIVE","sortPriority":39,"id":41419630,"name":"7 - 4"},{"status":"ACTIVE","sortPriority":40,"id":41419631,"name":"7 - 5"},{"status":"ACTIVE","sortPriority":41,"id":41419633,"name":"7 - 8"},{"status":"ACTIVE","sortPriority":42,"id":41419654,"name":"7 - 9"},{"status":"ACTIVE","sortPriority":43,"id":41419634,"name":"8 - 1"},{"status":"ACTIVE","sortPriority":44,"id":41419635,"name":"8 - 2"},{"status":"ACTIVE","sortPriority":45,"id":41419636,"name":"8 - 3"},{"status":"ACTIVE","sortPriority":46,"id":41419637,"name":"8 - 4"},{"status":"ACTIVE","sortPriority":47,"id":41419638,"name":"8 - 5"},{"status":"ACTIVE","sortPriority":48,"id":41419640,"name":"8 - 7"},{"status":"ACTIVE","sortPriority":49,"id":41419655,"name":"8 - 9"},{"status":"ACTIVE","sortPriority":50,"id":28546950,"name":"9 - 1"},{"status":"ACTIVE","sortPriority":51,"id":41419656,"name":"9 - 2"},{"status":"ACTIVE","sortPriority":52,"id":41419657,"name":"9 - 3"},{"status":"ACTIVE","sortPriority":53,"id":41435527,"name":"9 - 4"},{"status":"ACTIVE","sortPriority":54,"id":41419658,"name":"9 - 5"},{"status":"ACTIVE","sortPriority":55,"id":41419659,"name":"9 - 7"},{"status":"ACTIVE","sortPriority":56,"id":41419660,"name":"9 - 8"}],"regulators":["MR_INT"],"venue":"Rockhampton","countryCode":"AU","discountAllowed":true,"timezone":"Australia/Queensland","openDate":"2022-03-02T08:28:00.000Z","version":4382602304,"name":"Exacta","eventName":"Rockhampton (AUS) 2nd Mar"},"rc":[{"atb":[[17,16.67],[48,4.25],[24,8.7]],"id":41419609},{"atb":[[9,33.35],[20,10.52],[12.5,17.4]],"id":41419638},{"atb":[[4.8,70.21],[8.6,26.33],[5.8,41.69]],"id":41419605},{"atb":[[8,28.58],[4.5,76.23],[5.5,44.47]],"id":41419634},{"atb":[[18.5,15.24],[27,7.69],[60,3.38]],"id":41419613},{"atb":[[16.5,12.9],[11.5,25.4],[28,7.41]],"id":41419593},{"atb":[[32,6.45],[18,11.76],[13,22.23]],"id":41419655},{"atb":[[150,1.34],[50,4.08],[30,9.2]],"id":41435527},{"atb":[[330,0.6],[180,1.11],[90,2.99]],"id":41419651},{"atb":[[600,0.44],[700,0.28],[850,0.23]],"id":41419618},{"atb":[[8.6,35.1],[19,11.11],[11.5,19.05]],"id":41419601},{"atb":[[150,1.34],[50,4.08],[30,9.2]],"id":41419630},{"atb":[[330,0.6],[180,1.11],[90,2.99]],"id":41419597},{"atb":[[140,1.44],[48,4.25],[29,9.53]],"id":28546943},{"atb":[[600,0.44],[700,0.28],[850,0.23]],"id":41419659},{"atb":[[9.2,32.53],[21,10],[13,16.67]],"id":41419606},{"atb":[[5.8,55.58],[11.5,19.05],[7.6,30.32]],"id":41419635},{"atb":[[16.5,17.21],[46,4.44],[23,9.09]],"id":41419602},{"atb":[[17.5,12.12],[12.5,23.19],[30,6.89]],"id":41419585},{"atb":[[44,4.65],[27,10.26],[120,1.68]],"id":41419614},{"atb":[[360,0.55],[210,0.95],[110,2.44]],"id":41419656},{"atb":[[140,1.44],[48,4.25],[29,9.53]],"id":41419590},{"atb":[[38,5.4],[95,2.12],[24,11.59]],"id":41419652},{"atb":[[16.5,12.9],[11.5,25.4],[28,7.41]],"id":41419619},{"atb":[[9,33.35],[20,10.52],[12.5,17.4]],"id":41419586},{"atb":[[600,0.44],[700,0.28],[850,0.23]],"id":41419631},{"atb":[[16.5,12.9],[9.6,23.26],[7.6,40.42]],"id":41419598},{"atb":[[16,17.78],[44,4.65],[22,9.53]],"id":41419660},{"atb":[[65,3.12],[36,7.62],[180,1.11]],"id":41419627},{"atb":[[17,12.5],[12,24.25],[29,7.14]],"id":41419594},{"atb":[[32,6.45],[18,11.76],[13,22.23]],"id":41419640},{"atb":[[16.5,12.9],[11.5,25.4],[28,7.41]],"id":41419607},{"atb":[[65,3.12],[36,7.62],[180,1.11]],"id":28546950},{"atb":[[7.2,32.27],[5.1,48.8],[4.1,86.06]],"id":41419636},{"atb":[[17.5,16.16],[50,4.08],[25,8.33]],"id":41419615},{"atb":[[42,4.87],[26,10.67],[110,1.83]],"id":41419611},{"atb":[[130,1.55],[46,4.44],[28,9.87]],"id":41419657},{"atb":[[6.8,34.5],[9.8,22.74],[5.4,60.63]],"id":41419591},{"atb":[[42,4.87],[26,10.67],[110,1.83]],"id":41435525},{"atb":[[600,0.44],[700,0.28],[850,0.23]],"id":41419653},{"atb":[[9.2,32.53],[21,10],[13,16.67]],"id":41419587},{"atb":[[19.5,10.81],[12,18.19],[8.8,34.2]],"id":41419599},{"atb":[[360,0.55],[210,0.95],[110,2.44]],"id":41419628},{"atb":[[40,5.13],[100,2.01],[25,11.11]],"id":41419595},{"atb":[[8.6,35.1],[19,11.11],[11.5,19.05]],"id":41419608},{"atb":[[4.3,80.85],[5.3,46.53],[7.6,30.32]],"id":41419637},{"atb":[[38,5.4],[95,2.12],[24,11.59]],"id":41419604},{"atb":[[18,15.69],[26,8],[55,3.7]],"id":41419616},{"atb":[[5.1,65.07],[9.2,24.4],[6.2,38.48]],"id":41419612},{"atb":[[32,6.45],[18,11.76],[13,22.23]],"id":41419592},{"atb":[[600,0.44],[700,0.28],[850,0.23]],"id":41419654},{"atb":[[18,15.69],[26,8],[55,3.7]],"id":41419588},{"atb":[[16,17.78],[44,4.65],[22,9.53]],"id":41419633},{"atb":[[16,13.34],[11,26.68],[27,7.69]],"id":41419600},{"atb":[[130,1.55],[46,4.44],[28,9.87]],"id":41419629},{"atb":[[600,0.44],[700,0.28],[850,0.23]],"id":41419658}],"con":true,"img":true}]}
{"op":"mcm","clk":"5353084233","pt":1646208480433,"mc":[{"id":"1.195503865","rc":[{"atb":[[32,3.27],[17,16.67],[42,2.72],[48,4.25],[24,8.7]],"id":41419609},{"atb":[[16.5,3.27],[9,33.35],[19,2.72],[20,10.52],[12.5,17.4]],"id":41419638},{"atb":[[4.8,70.21],[8.6,26.33],[5.8,41.69]],"id":41419605},{"atb":[[8,28.58],[4.5,76.23],[5.5,44.47],[8.4,3.27],[9.4,2.72]],"id":41419634},{"atb":[[70,2.72],[18.5,15.24],[48,3.27],[27,7.69],[60,3.38]],"id":41419613},{"atb":[[16.5,12.9],[11.5,25.4],[28,7.41]],"id":41419593},{"atb":[[32,6.45],[18,11.76],[24,3.27],[13,22.23],[29,2.72]],"id":41419655},{"atb":[[150,1.34],[50,4.08],[30,9.2]],"id":41435527},{"atb":[[70,3.27],[330,0.6],[180,1.11],[90,2.99],[95,2.72]],"id":41419651},{"atb":[[600,0.44],[150,2.72],[700,0.28],[100,3.27],[850,0.23]],"id":41419618},{"atb":[[8.6,35.1],[19,11.11],[20,3.27],[11.5,19.05],[25,2.72]],"id":41419601},{"atb":[[150,1.34],[80,3.27],[50,4.08],[110,2.72],[30,9.2]],"id":41419630},{"atb":[[70,3.27],[330,0.6],[180,1.11],[90,2.99],[95,2.72]],"id":41419597},{"atb":[[140,1.44],[48,4.25],[29,9.53]],"id":28546943},{"atb":[[600,0.44],[700,0.28],[200,3.27],[850,0.23],[250,2.72]],"id":41419659},{"atb":[[9.2,32.53],[20,3.27],[21,10],[25,2.72],[13,16.67]],"id":41419606},{"atb":[[5.8,55.58],[10,3.27],[11.5,19.05],[7.6,30.32],[12.5,2.72]],"id":41419635},{"atb":[[16.5,17.21],[34,3.27],[44,2.72],[46,4.44],[23,9.09]],"id":41419602},{"atb":[[17.5,12.12],[12.5,23.19],[30,6.89]],"id":41419585},{"atb":[[44,4.65],[27,10.26],[120,1.68]],"id":41419614},{"atb":[[360,0.55],[210,0.95],[110,2.44]],"id":41419656},{"atb":[[65,2.72],[140,1.44],[46,3.27],[48,4.25],[29,9.53]],"id":41419590},{"atb":[[38,5.4],[44,3.27],[95,2.12],[24,11.59],[60,2.72]],"id":41419652},{"atb":[[16.5,12.9],[34,3.27],[44,2.72],[11.5,25.4],[28,7.41]],"id":41419619},{"atb":[[9,33.35],[20,10.52],[23,3.27],[12.5,17.4],[28,2.72]],"id":41419586},{"atb":[[130,3.27],[600,0.44],[700,0.28],[180,2.72],[850,0.23]],"id":41419631},{"atb":[[16.5,12.9],[9.6,23.26],[22,3.27],[7.6,40.42],[27,2.72]],"id":41419598},{"atb":[[16,17.78],[75,2.72],[44,4.65],[22,9.53],[50,3.27]],"id":41419660},{"atb":[[65,3.12],[36,7.62],[180,1.11]],"id":41419627},{"atb":[[17,12.5],[40,2.72],[12,24.25],[29,7.14],[30,3.27]],"id":41419594},{"atb":[[32,6.45],[18,11.76],[24,3.27],[13,22.23],[29,2.72]],"id":41419640},{"atb":[[16.5,12.9],[11.5,25.4],[28,7.41]],"id":41419607},{"atb":[[65,3.12],[36,7.62],[180,1.11]],"id":28546950},{"atb":[[7.2,32.27],[5.1,48.8],[4.1,86.06]],"id":41419636},{"atb":[[65,2.72],[17.5,16.16],[46,3.27],[50,4.08],[25,8.33]],"id":41419615},{"atb":[[42,4.87],[44,3.27],[26,10.67],[110,1.83],[60,2.72]],"id":41419611},{"atb":[[130,1.55],[46,4.44],[28,9.87]],"id":41419657},{"atb":[[16,2.72],[6.8,34.5],[9.8,22.74],[13.5,3.27],[5.4,60.63]],"id":41419591},{"atb":[[42,4.87],[44,3.27],[26,10.67],[110,1.83],[60,2.72]],"id":41435525},{"atb":[[600,0.44],[700,0.28],[850,0.23]],"id":41419653},{"atb":[[9.2,32.53],[21,10],[13,16.67]],"id":41419587},{"atb":[[19.5,10.81],[22,3.27],[12,18.19],[8.8,34.2],[27,2.72]],"id":41419599},{"atb":[[140,2.72],[360,0.55],[95,3.27],[210,0.95],[110,2.44]],"id":41419628},{"atb":[[40,5.13],[100,2.01],[25,11.11]],"id":41419595},{"atb":[[8.6,35.1],[19,11.11],[19.5,3.27],[11.5,19.05],[24,2.72]],"id":41419608},{"atb":[[4.3,80.85],[8.6,2.72],[5.3,46.53],[7.6,33.59]],"id":41419637},{"atb":[[38,5.4],[44,3.27],[95,2.12],[24,11.59],[60,2.72]],"id":41419604},{"atb":[[65,2.72],[18,15.69],[46,3.27],[26,8],[55,3.7]],"id":41419616},{"atb":[[5.1,65.07],[9.2,24.4],[6.2,38.48],[11,3.27],[13.5,2.72]],"id":41419612},{"atb":[[32,9.73],[18,11.76],[42,2.72],[13,22.23]],"id":41419592},{"atb":[[600,0.44],[700,0.28],[200,3.27],[850,0.23],[250,2.72]],"id":41419654},{"atb":[[18,15.69],[26,8],[55,3.7]],"id":41419588},{"atb":[[16,17.78],[75,2.72],[44,4.65],[22,9.53],[50,3.27]],"id":41419633},{"atb":[[16,13.34],[11,26.68],[27,7.69]],"id":41419600},{"atb":[[130,1.55],[80,3.27],[46,4.44],[110,2.72],[28,9.87]],"id":41419629},{"atb":[[130,3.27],[600,0.44],[700,0.28],[180,2.72],[850,0.23]],"id":41419658}],"con":true,"img":false}]}
{"op":"mcm","clk":"5353084239","pt":1646208480537,"mc":[{"id":"1.195503865","rc":[{"atb":[[12,3.27],[14.5,2.72]],"id":41419605},{"atb":[[40,2.72],[30,3.27]],"id":41419593},{"atb":[[80,3.27],[110,2.72]],"id":41435527},{"atb":[[65,2.72],[46,3.27]],"id":28546943},{"atb":[[36,2.72],[28,3.27]],"id":41419585},{"atb":[[85,2.72],[60,3.27]],"id":41419614},{"atb":[[140,2.72],[95,3.27]],"id":41419656},{"atb":[[80,3.27],[110,2.72]],"id":41419627},{"atb":[[32,2.72],[26,3.27]],"id":41419607},{"atb":[[80,3.27],[110,2.72]],"id":28546950},{"atb":[[7.6,2.72],[6.6,3.27]],"id":41419636},{"atb":[[80,3.27],[110,2.72]],"id":41419657},{"atb":[[150,2.72],[100,3.27]],"id":41419653},{"atb":[[22,3.27],[27,2.72]],"id":41419587},{"atb":[[70,2.72],[48,3.27]],"id":41419595},{"atb":[[38,3.27],[48,2.72]],"id":41419588},{"atb":[[34,2.72],[27,10.97]],"id":41419600}],"con":true,"img":false}]}
{"op":"mcm","clk":"5353090494","pt":1646208623775,"mc":[{"id":"1.195503865","rc":[{"atb":[[8.6,0],[7.6,30.32]],"id":41419637}],"con":true,"img":false}]}
{"op":"mcm","clk":"5353090526","pt":1646208624488,"mc":[{"id":"1.195503865","rc":[{"atb":[[7.4,3.27],[8.4,2.72]],"id":41419637}],"con":true,"img":false}]}
{"op":"mcm","clk":"5353103455","pt":1646208900069,"mc":[{"id":"1.195503865","rc":[{"atb":[[8.4,0],[9.4,0]],"id":41419634}],"con":true,"img":false}]}
{"op":"mcm","clk":"5353103508","pt":1646208901057,"mc":[{"id":"1.195503865","rc":[{"atb":[[9.2,2.72],[8.2,3.27]],"id":41419634}],"con":true,"img":false}]}
{"op":"mcm","clk":"5353110499","pt":1646209062165,"mc":[{"id":"1.195503865","rc":[{"atb":[[7.6,0],[6.6,0]],"id":41419636}],"con":true,"img":false}]}
{"op":"mcm","clk":"5353110532","pt":1646209062950,"mc":[{"id":"1.195503865","rc":[{"atb":[[6.4,3.27],[7.4,2.72]],"id":41419636}],"con":true,"img":false}]}
{"op":"mcm","clk":"5353116504","pt":1646209206158,"mc":[{"id":"1.195503865","rc":[{"atb":[[24,0],[29,0]],"id":41419655},{"atb":[[65,0]],"id":28546943},{"atb":[[200,0],[250,0]],"id":41419659},{"atb":[[20,0],[25,0]],"id":41419606},{"atb":[[140,0],[95,0]],"id":41419656},{"atb":[[44,0],[60,0]],"id":41419652},{"atb":[[75,0],[50,0]],"id":41419660},{"atb":[[80,0],[110,0]],"id":28546950},{"atb":[[80,0],[110,0]],"id":41419657},{"atb":[[150,0],[100,0]],"id":41419653},{"atb":[[130,0],[180,0]],"id":41419658}],"con":true,"img":false}]}
{"op":"mcm","clk":"5353116508","pt":1646209206258,"mc":[{"id":"1.195503865","rc":[{"atb":[[46,0]],"id":28546943}],"con":true,"img":false}]}
{"op":"mcm","clk":"5353116530","pt":1646209206872,"mc":[{"id":"1.195503865","rc":[{"atb":[[25,3.27],[30,2.72]],"id":41419655},{"atb":[[210,3.27]],"id":41419659},{"atb":[[21,13.28],[26,2.72]],"id":41419606},{"atb":[[150,2.72]],"id":41419656},{"atb":[[65,2.72],[46,3.27]],"id":41419652},{"atb":[[80,2.72],[55,3.27]],"id":41419660},{"atb":[[85,3.27],[120,2.72]],"id":28546950},{"atb":[[160,2.72],[110,3.27]],"id":41419653}],"con":true,"img":false}]}
{"op":"mcm","clk":"5353116537","pt":1646209206975,"mc":[{"id":"1.195503865","rc":[{"atb":[[70,2.72],[48,7.53]],"id":28546943},{"atb":[[260,2.72]],"id":41419659},{"atb":[[100,3.27]],"id":41419656},{"atb":[[85,3.27],[120,2.72]],"id":41419657},{"atb":[[140,3.27],[190,2.72]],"id":41419658}],"con":true,"img":false}]}
{"op":"mcm","clk":"5353143957","pt":1646209730430,"mc":[{"id":"1.195503865","rc":[{"atb":[[6.4,0],[7.4,0]],"id":41419636}],"con":true,"img":false}]}
{"op":"mcm","clk":"5353143983","pt":1646209731149,"mc":[{"id":"1.195503865","rc":[{"atb":[[7.6,2.72],[6.6,3.27]],"id":41419636}],"con":true,"img":false}]}
{"op":"mcm","clk":"5353174438","pt":1646210305882,"mc":[{"id":"1.195503865","rc":[{"atb":[[7.6,0],[6.6,0]],"id":41419636}],"con":true,"img":false}]}
{"op":"mcm","clk":"5353174487","pt":1646210306764,"mc":[{"id":"1.195503865","rc":[{"atb":[[6.4,3.27],[7.4,2.72]],"id":41419636}],"con":true,"img":false}]}
{"op":"mcm","clk":"5353202116","pt":1646210849878,"mc":[{"id":"1.195503865","rc":[{"atb":[[6.4,0],[7.4,0]],"id":41419636}],"con":true,"img":false}]}
{"op":"mcm","clk":"5353202150","pt":1646210850704,"mc":[{"id":"1.195503865","rc":[{"atb":[[7.6,2.72],[6.6,3.27]],"id":41419636}],"con":true,"img":false}]}
{"op":"mcm","clk":"5353224204","pt":1646211395746,"mc":[{"id":"1.195503865","rc":[{"atb":[[32,0],[26,0]],"id":41419607},{"atb":[[7.6,0],[6.6,0]],"id":41419636},{"atb":[[19.5,0],[24,0]],"id":41419608}],"con":true,"img":false}]}
{"op":"mcm","clk":"5353224232","pt":1646211396465,"mc":[{"id":"1.195503865","rc":[{"atb":[[25,3.27],[30,2.72]],"id":41419607},{"atb":[[8.8,2.72],[7.8,3.27]],"id":41419636},{"atb":[[19,14.39],[23,2.72]],"id":41419608}],"con":true,"img":false}]}
{"op":"mcm","clk":"5353263587","pt":1646212088347,"mc":[{"id":"1.195503865","rc":[{"atb":[[32,3.26],[17,16.64],[42,2.72],[48,4.25],[24,8.68],[7,8.52]],"id":41419609},{"atl":[[860,2]],"id":41419609},{"atb":[[16.5,3.26],[9,33.29],[19,2.72],[20,10.51],[12.5,17.37]],"id":41419638},{"atb":[[4.8,70.1],[8.6,26.29],[5.8,41.62],[12,3.26],[14.5,2.72]],"id":41419605},{"atb":[[8,28.54],[4.5,76.11],[9.2,2.72],[8.2,3.26],[5.5,44.4]],"id":41419634},{"atb":[[70,2.72],[18.5,15.22],[23,4.55],[48,3.26],[27,7.68],[60,3.38]],"id":41419613},{"atl":[[1000,2]],"id":41419613},{"atb":[[16.5,12.88],[40,2.72],[11.5,25.36],[28,7.4],[30,3.26]],"id":41419593},{"atb":[[32,6.44],[18,11.74],[9.2,12.2],[25,3.26],[13,22.19],[30,2.72]],"id":41419655},{"atl":[[950,2]],"id":41419655},{"atb":[[150,1.34],[80,3.26],[50,4.07],[110,2.72],[30,9.18]],"id":41435527},{"atb":[[70,3.26],[330,0.6],[180,1.11],[90,2.99],[95,2.72]],"id":41419651},{"atb":[[600,0.44],[150,2.72],[700,0.28],[100,3.26],[850,0.23]],"id":41419618},{"atb":[[8.6,35.05],[19,11.1],[20,3.26],[11.5,19.02],[25,2.72]],"id":41419601},{"atb":[[150,1.34],[80,3.26],[50,4.07],[26,4],[110,2.72],[30,9.18]],"id":41419630},{"atb":[[70,3.26],[330,0.6],[180,1.11],[90,2.99],[95,2.72]],"id":41419597},{"atb":[[140,1.43],[70,2.72],[48,7.52],[29,9.51]],"id":28546943},{"atb":[[260,2.72],[600,0.44],[700,0.28],[850,0.23],[210,3.26],[2.16,2]],"id":41419659},{"atb":[[9.2,32.48],[21,13.25],[26,2.72],[13,16.64]],"id":41419606},{"atb":[[10,3.26],[5.8,55.49],[11.5,19.02],[3.35,38.12],[7.6,30.27],[12.5,2.72]],"id":41419635},{"atl":[[420,2]],"id":41419635},{"atb":[[16.5,17.18],[34,3.26],[44,2.72],[46,4.44],[23,9.07]],"id":41419602},{"atb":[[17.5,12.1],[36,2.72],[12.5,23.16],[28,3.26],[30,6.88]],"id":41419585},{"atl":[[830,2]],"id":41419585},{"atb":[[85,2.72],[21,5],[44,4.64],[27,10.24],[120,1.67],[60,3.26]],"id":41419614},{"atl":[[1000,2]],"id":41419614},{"atb":[[150,2.72],[360,0.55],[100,3.26],[210,0.95],[110,2.44],[2.16,4.9]],"id":41419656},{"atb":[[65,2.72],[140,1.43],[46,3.26],[48,4.25],[26,4],[29,9.51]],"id":41419590},{"atb":[[65,2.72],[38,5.4],[95,2.12],[46,3.26],[24,11.58]],"id":41419652},{"atb":[[16.5,12.88],[34,3.26],[44,2.72],[11.5,25.36],[28,7.4]],"id":41419619},{"atb":[[9,33.29],[20,10.51],[23,3.26],[12.5,17.37],[28,2.72]],"id":41419586},{"atb":[[130,3.26],[600,0.44],[700,0.28],[180,2.72],[850,0.23]],"id":41419631},{"atb":[[16.5,12.88],[9.6,23.23],[22,3.26],[7.6,40.36],[27,2.72]],"id":41419598},{"atb":[[16,17.76],[80,2.72],[44,4.64],[22,9.51],[55,3.26],[2.16,9.32]],"id":41419660},{"atb":[[65,3.12],[36,7.61],[80,3.26],[180,1.11],[110,2.72]],"id":41419627},{"atb":[[17,12.48],[40,2.72],[12,24.21],[29,7.13],[30,3.26]],"id":41419594},{"atb":[[32,6.44],[18,11.74],[24,3.26],[13,22.19],[29,2.72]],"id":41419640},{"atb":[[16.5,12.88],[11.5,25.36],[25,3.26],[28,7.4],[30,2.72]],"id":41419607},{"atb":[[65,3.12],[36,7.61],[85,3.26],[180,1.11],[120,2.72]],"id":28546950},{"atb":[[7.2,32.22],[5.1,48.72],[4.1,85.93],[8.8,2.72],[7.8,3.26]],"id":41419636},{"atb":[[65,2.72],[17.5,16.14],[46,3.26],[50,4.07],[25,8.32]],"id":41419615},{"atb":[[42,4.87],[44,3.26],[26,10.65],[110,1.83],[60,2.72]],"id":41419611},{"atb":[[130,1.54],[85,3.26],[46,4.44],[28,9.86],[2.16,6.56],[120,2.72]],"id":41419657},{"atb":[[16,2.72],[6.8,34.44],[9.8,22.7],[13.5,3.26],[5.4,60.54]],"id":41419591},{"atb":[[42,4.87],[44,3.26],[26,10.65],[110,1.83],[60,2.72]],"id":41435525},{"atb":[[600,0.44],[160,2.72],[700,0.28],[850,0.23],[26,2],[110,3.26]],"id":41419653},{"atb":[[9.2,32.48],[21,9.98],[22,3.26],[13,16.64],[27,2.72],[7,16.67]],"id":41419587},{"atl":[[850,2]],"id":41419587},{"atb":[[19.5,10.8],[22,3.26],[12,18.16],[27,2.72],[8.8,34.15]],"id":41419599},{"atb":[[140,2.72],[360,0.55],[95,3.26],[210,0.95],[110,2.44]],"id":41419628},{"atb":[[70,2.72],[40,5.12],[48,3.26],[100,2.01],[25,11.1]],"id":41419595},{"atb":[[8.6,35.05],[19,14.37],[23,2.72],[11.5,19.02]],"id":41419608},{"atb":[[4.3,80.72],[5.3,46.46],[7.4,3.26],[7.6,30.27],[8.4,2.72]],"id":41419637},{"atb":[[38,5.4],[44,3.26],[95,2.12],[24,11.58],[60,2.72]],"id":41419604},{"atb":[[65,2.72],[18,15.66],[22,4.76],[46,3.26],[26,7.98],[55,3.7]],"id":41419616},{"atl":[[1000,2]],"id":41419616},{"atb":[[5.1,64.97],[9.2,24.36],[6.2,38.42],[11,3.26],[13.5,2.72]],"id":41419612},{"atb":[[32,9.71],[18,11.74],[42,2.72],[13,22.19]],"id":41419592},{"atb":[[600,0.44],[700,0.28],[200,3.26],[850,0.23],[27,2],[250,2.72]],"id":41419654},{"atb":[[18,15.66],[38,3.26],[21,5],[48,2.72],[26,7.98],[55,3.7]],"id":41419588},{"atl":[[1000,2]],"id":41419588},{"atb":[[16,17.76],[75,2.72],[44,4.64],[22,9.51],[50,3.26]],"id":41419633},{"atb":[[16,13.31],[34,2.72],[11,26.63],[27,10.95]],"id":41419600},{"atb":[[130,1.54],[80,3.26],[46,4.44],[110,2.72],[28,9.86]],"id":41419629},{"atb":[[140,3.26],[600,0.44],[700,0.28],[190,2.72],[850,0.23],[2.16,2]],"id":41419658}],"con":true,"img":false}]}
{"op":"mcm","clk":"5353263593","pt":1646212088455,"mc":[{"id":"1.195503865","rc":[{"atb":[[4.5,21.06]],"id":41419638},{"atl":[[550,2]],"id":41419638},{"atb":[[3.6,38.46]],"id":41419605},{"atl":[[480,2]],"id":41419605},{"atb":[[3.35,42.55]],"id":41419634},{"atl":[[420,2]],"id":41419634},{"atb":[[6.2,14.82]],"id":41419593},{"atl":[[700,2]],"id":41419593},{"atb":[[2.16,6.56]],"id":41435527},{"atb":[[26,4]],"id":41419651},{"atb":[[26,2]],"id":41419618},{"atb":[[5.4,22.24]],"id":41419601},{"atl":[[600,2]],"id":41419601},{"atb":[[26,4]],"id":41419597},{"atb":[[26,4]],"id":28546943},{"atb":[[5.1,24.39]],"id":41419606},{"atl":[[580,2]],"id":41419606},{"atb":[[8,8.9]],"id":41419602},{"atl":[[900,2]],"id":41419602},{"atb":[[24,15.93]],"id":41419652},{"atb":[[8.2,13.89]],"id":41419619},{"atl":[[910,2]],"id":41419619},{"atb":[[6.2,19.23]],"id":41419586},{"atl":[[710,2]],"id":41419586},{"atb":[[27,2]],"id":41419631},{"atb":[[5.5,22.22]],"id":41419598},{"atl":[[610,2]],"id":41419598},{"atb":[[26,4]],"id":41419627},{"atb":[[7.2,14.3]],"id":41419594},{"atl":[[860,2]],"id":41419594},{"atb":[[8.8,12.82]],"id":41419640},{"atl":[[930,2]],"id":41419640},{"atb":[[5.1,14.82]],"id":41419607},{"atl":[[580,2]],"id":41419607},{"atb":[[2.16,6.26]],"id":28546950},{"atb":[[3,50]],"id":41419636},{"atl":[[320,2]],"id":41419636},{"atb":[[13.5,8]],"id":41419615},{"atl":[[1000,2]],"id":41419615},{"atb":[[24,4.35]],"id":41419611},{"atb":[[5.5,22.22]],"id":41419591},{"atl":[[600,2]],"id":41419591},{"atb":[[24,4.35]],"id":41435525},{"atb":[[5.5,21.64]],"id":41419599},{"atl":[[600,2]],"id":41419599},{"atb":[[26,4]],"id":41419628},{"atb":[[19.5,5.41]],"id":41419595},{"atl":[[1000,2]],"id":41419595},{"atb":[[4.1,32.26]],"id":41419608},{"atl":[[520,2]],"id":41419608},{"atb":[[3.25,44.44]],"id":41419637},{"atl":[[390,2]],"id":41419637},{"atb":[[24,15.93]],"id":41419604},{"atb":[[3.45,40.82]],"id":41419612},{"atl":[[440,2]],"id":41419612},{"atb":[[6.8,17.24]],"id":41419592},{"atl":[[850,2]],"id":41419592},{"atb":[[25,4.17]],"id":41419633},{"atb":[[5.4,22.73]],"id":41419600},{"atl":[[590,2]],"id":41419600},{"atb":[[26,4]],"id":41419629}],"con":true,"img":false}]}
{"op":"mcm","clk":"5353267096","pt":1646212146867,"mc":[{"id":"1.195503865","rc":[{"atb":[[10,0],[12.5,0]],"id":41419635},{"atb":[[8.8,0],[7.8,0]],"id":41419636},{"atb":[[200,0],[250,0]],"id":41419654}],"con":true,"img":false}]}
{"op":"mcm","clk":"5353267101","pt":1646212146965,"mc":[{"id":"1.195503865","rc":[{"atb":[[80,0],[110,0]],"id":41435527},{"atb":[[7.4,0],[8.4,0]],"id":41419637},{"atb":[[11,0],[13.5,0]],"id":41419612}],"con":true,"img":false}]}
{"op":"mcm","clk":"5353267144","pt":1646212147542,"mc":[{"id":"1.195503865","rc":[{"atb":[[10.5,3.26],[13,2.72]],"id":41419635},{"atb":[[260,2.72],[210,3.26]],"id":41419654}],"con":true,"img":false}]}
{"op":"mcm","clk":"5353267154","pt":1646212147643,"mc":[{"id":"1.195503865","rc":[{"atb":[[85,3.26],[120,2.72]],"id":41435527},{"atb":[[8,3.26],[9,2.72]],"id":41419636}],"con":true,"img":false}]}
{"op":"mcm","clk":"5353267159","pt":1646212147744,"mc":[{"id":"1.195503865","rc":[{"atb":[[8.6,2.72],[7.6,33.54]],"id":41419637}],"con":true,"img":false}]}
{"op":"mcm","clk":"5353267171","pt":1646212147852,"mc":[{"id":"1.195503865","rc":[{"atb":[[11.5,3.26],[14,2.72]],"id":41419612}],"con":true,"img":false}]}
{"op":"mcm","clk":"5353309859","pt":1646212754933,"mc":[{"id":"1.195503865","rc":[{"atl":[[300,2]],"id":41419636}],"con":true,"img":false}]}
{"op":"mcm","clk":"5353309867","pt":1646212754986,"mc":[{"id":"1.195503865","rc":[{"atl":[[830,2],[860,0]],"id":41419609},{"atl":[[540,2],[550,0]],"id":41419638},{"atl":[[460,2],[480,0]],"id":41419605},{"atl":[[410,2],[420,0]],"id":41419634},{"atl":[[700,0],[680,2]],"id":41419593},{"atl":[[900,2],[950,0]],"id":41419655},{"atl":[[600,0],[580,2]],"id":41419601},{"atb":[[5.6,21.74],[5.1,0]],"id":41419606},{"atl":[[570,2],[580,0]],"id":41419606},{"atl":[[410,2],[420,0]],"id":41419635},{"atl":[[860,2],[900,0]],"id":41419602},{"atl":[[830,0],[820,2]],"id":41419585},{"atl":[[880,2],[910,0]],"id":41419619},{"atl":[[690,2],[710,0]],"id":41419586},{"atb":[[5.5,0],[6,20]],"id":41419598},{"atl":[[590,2],[610,0]],"id":41419598},{"atl":[[860,0],[840,2]],"id":41419594},{"atl":[[890,2],[930,0]],"id":41419640},{"atl":[[570,2],[580,0]],"id":41419607},{"atl":[[320,0]],"id":41419636},{"atl":[[600,0],[590,2]],"id":41419591},{"atl":[[830,2],[850,0]],"id":41419587},{"atl":[[600,0],[590,2]],"id":41419599},{"atl":[[370,2],[390,0]],"id":41419637},{"atl":[[430,2],[440,0]],"id":41419612},{"atl":[[820,2],[850,0]],"id":41419592},{"atl":[[590,0],[580,2]],"id":41419600}],"con":true,"img":false}]}
{"op":"mcm","clk":"5353309889","pt":1646212755401,"mc":[{"id":"1.195503865","rc":[{"atb":[[25,0],[30,0]],"id":41419607}],"con":true,"img":false}]}
{"op":"mcm","clk":"5353309927","pt":1646212756124,"mc":[{"id":"1.195503865","rc":[{"atb":[[32,2.72],[26,3.26]],"id":41419607}],"con":true,"img":false}]}
{"op":"mcm","clk":"5353310802","pt":1646212773021,"mc":[{"id":"1.195503865","rc":[{"atl":[[830,0],[820,2]],"id":41419609},{"atb":[[3.6,0],[3.85,35.09]],"id":41419605},{"atl":[[460,0],[470,2]],"id":41419605},{"atl":[[900,0],[910,2]],"id":41419655},{"atl":[[570,0],[560,2]],"id":41419606},{"atl":[[820,0],[800,2]],"id":41419585},{"atl":[[880,0],[870,2]],"id":41419619},{"atl":[[830,2],[840,0]],"id":41419594},{"atl":[[570,0],[560,2]],"id":41419607},{"atl":[[300,0],[310,2]],"id":41419636},{"atl":[[590,0],[580,2]],"id":41419591},{"atl":[[830,0],[820,2]],"id":41419587},{"atl":[[820,0],[810,2]],"id":41419592}],"con":true,"img":false}]}
{"op":"mcm","clk":"5353310817","pt":1646212773334,"mc":[{"id":"1.195503865","rc":[{"atb":[[32,0],[26,0]],"id":41419607}],"con":true,"img":false}]}
{"op":"mcm","clk":"5353310849","pt":1646212774243,"mc":[{"id":"1.195503865","rc":[{"atb":[[25,3.26],[30,2.72]],"id":41419607}],"con":true,"img":false}]}
{"op":"mcm","clk":"5353311402","pt":1646212785432,"mc":[{"id":"1.195503865","rc":[{"atl":[[690,0],[680,2]],"id":41419586}],"con":true,"img":false}]}
{"op":"mcm","clk":"5353317916","pt":1646212896478,"mc":[{"id":"1.195503865","rc":[{"atb":[[9.2,0]],"id":41419655},{"atl":[[800,0]],"id":41419585},{"atb":[[18,21.54]],"id":41419616}],"con":true,"img":false}]}
{"op":"mcm","clk":"5353317921","pt":1646212896577,"mc":[{"id":"1.195503865","rc":[{"atl":[[770,2],[820,0]],"id":41419609},{"atl":[[540,0],[530,2]],"id":41419638},{"atl":[[410,0],[400,2]],"id":41419634},{"atb":[[17,6.25],[23,0]],"id":41419613},{"atb":[[11.5,9.52]],"id":41419655},{"atb":[[5.9,20.41],[5.4,0]],"id":41419601},{"atb":[[5.6,0],[5,25]],"id":41419606},{"atl":[[560,0],[550,2]],"id":41419606},{"atb":[[3.6,38.12]],"id":41419635},{"atl":[[860,0],[840,2]],"id":41419602},{"atl":[[730,2]],"id":41419585},{"atl":[[820,2],[870,0]],"id":41419619},{"atl":[[630,2],[680,0]],"id":41419586},{"atb":[[7.2,0],[8.2,13.89]],"id":41419594},{"atb":[[10.5,10.53],[8.8,0]],"id":41419640},{"atb":[[3,0],[3.25,44.44]],"id":41419636},{"atl":[[960,2],[1000,0]],"id":41419615},{"atl":[[560,2],[580,0]],"id":41419591},{"atl":[[730,2],[820,0]],"id":41419587},{"atl":[[590,0],[580,2]],"id":41419599},{"atb":[[22,0]],"id":41419616},{"atl":[[790,2],[810,0]],"id":41419592},{"atb":[[21,0],[14.5,7.41]],"id":41419588},{"atb":[[6,20],[5.4,0]],"id":41419600}],"con":true,"img":false}]}
{"op":"mcm","clk":"5353317924","pt":1646212896683,"mc":[{"id":"1.195503865","rc":[{"atb":[[3.35,0]],"id":41419635}],"con":true,"img":false}]}
{"op":"mcm","clk":"5353318738","pt":1646212911014,"mc":[{"id":"1.195503865","rc":[{"atb":[[12,0],[14.5,0]],"id":41419605},{"atb":[[260,0],[210,0]],"id":41419659},{"atb":[[80,0],[110,0]],"id":41419627},{"atb":[[8.6,0],[7.6,30.27]],"id":41419637}],"con":true,"img":false}]}
{"op":"mcm","clk":"5353318751","pt":1646212911219,"mc":[{"id":"1.195503865","rc":[{"atb":[[25,0],[30,0]],"id":41419655}],"con":true,"img":false}]}
{"op":"mcm","clk":"5353318774","pt":1646212911713,"mc":[{"id":"1.195503865","rc":[{"atb":[[270,2.72],[220,3.26]],"id":41419659}],"con":true,"img":false}]}
{"op":"mcm","clk":"5353318789","pt":1646212912010,"mc":[{"id":"1.195503865","rc":[{"atb":[[12.5,3.26],[15,2.72]],"id":41419605},{"atb":[[32,9.17],[26,3.26]],"id":41419655},{"atb":[[85,3.26],[120,2.72]],"id":41419627},{"atb":[[8.8,2.72],[7.8,3.26]],"id":41419637}],"con":true,"img":false}]}
{"op":"mcm","clk":"5353324907","pt":1646213016545,"mc":[{"id":"1.195503865","rc":[{"atb":[[17,6.25],[21,0]],"id":41419614},{"atb":[[8.2,0],[7,16.67]],"id":41419619},{"atb":[[5.5,0],[4.9,25.64]],"id":41419591},{"atl":[[730,0],[760,2]],"id":41419587}],"con":true,"img":false}]}
{"op":"mcm","clk":"5353328287","pt":1646213070622,"mc":[{"id":"1.195503865","rc":[{"atb":[[25,0],[30,0]],"id":41419607}],"con":true,"img":false}]}
{"op":"mcm","clk":"5353328342","pt":1646213071516,"mc":[{"id":"1.195503865","rc":[{"atb":[[32,2.72]],"id":41419607}],"con":true,"img":false}]}
{"op":"mcm","clk":"5353328348","pt":1646213071623,"mc":[{"id":"1.195503865","rc":[{"atb":[[26,3.26]],"id":41419607}],"con":true,"img":false}]}
{"op":"mcm","clk":"5353337437","pt":1646213229095,"mc":[{"id":"1.195503865","rc":[{"atb":[[24,11.58]],"id":41419652},{"atb":[[6.2,0]],"id":41419586},{"atl":[[630,0]],"id":41419586},{"atb":[[10.5,0]],"id":41419640},{"atl":[[890,0]],"id":41419640},{"atb":[[5.1,0]],"id":41419607},{"atl":[[560,0]],"id":41419607},{"atb":[[25,0]],"id":41419633},{"atb":[[26,0]],"id":41419629}],"con":true,"img":false}]}
{"op":"mcm","clk":"5353337441","pt":1646213229197,"mc":[{"id":"1.195503865","rc":[{"atb":[[26,0]],"id":41419618},{"atb":[[5,0]],"id":41419606},{"atl":[[550,0]],"id":41419606},{"atb":[[4.9,0]],"id":41419591},{"atl":[[560,0]],"id":41419591},{"atb":[[5.5,0]],"id":41419599},{"atl":[[580,0]],"id":41419599},{"atb":[[26,0]],"id":41419628}],"con":true,"img":false}]}
{"op":"mcm","clk":"5353337446","pt":1646213229301,"mc":[{"id":"1.195503865","rc":[{"atb":[[7.2,8.52],[7,0]],"id":41419609},{"atl":[[770,0]],"id":41419609},{"atb":[[3.85,0],[3.9,34.48]],"id":41419605},{"atl":[[470,0]],"id":41419605},{"atb":[[6.2,0]],"id":41419593},{"atl":[[680,0]],"id":41419593},{"atb":[[2.16,0]],"id":41435527},{"atb":[[26,0]],"id":41419630},{"atb":[[26,0]],"id":41419597},{"atb":[[17,0]],"id":41419614},{"atl":[[1000,0]],"id":41419614},{"atb":[[8.2,0]],"id":41419594},{"atl":[[830,0]],"id":41419594},{"atb":[[13.5,0]],"id":41419615},{"atl":[[960,0]],"id":41419615},{"atb":[[2.16,0]],"id":41419657},{"atb":[[26,0]],"id":41419653},{"atb":[[7,0]],"id":41419587},{"atl":[[730,2],[760,0]],"id":41419587},{"atb":[[24,11.58],[27,3.85]],"id":41419604},{"atb":[[3.45,0]],"id":41419612},{"atl":[[430,0]],"id":41419612},{"atb":[[14.5,0]],"id":41419588},{"atl":[[1000,0]],"id":41419588},{"atb":[[6,0]],"id":41419600},{"atl":[[580,0]],"id":41419600}],"con":true,"img":false}]}
{"op":"mcm","clk":"5353337449","pt":1646213229406,"mc":[{"id":"1.195503865","rc":[{"atl":[[770,2]],"id":41419609},{"atl":[[470,2]],"id":41419605},{"atb":[[17,0]],"id":41419613},{"atl":[[1000,0]],"id":41419613},{"atb":[[40,0],[6.8,14.82],[30,0]],"id":41419593},{"atl":[[680,2]],"id":41419593},{"atb":[[11.5,0]],"id":41419655},{"atl":[[910,0]],"id":41419655},{"atb":[[2.16,6.56]],"id":41435527},{"atb":[[26,0]],"id":41419651},{"atb":[[150,0],[100,0],[29,2]],"id":41419618},{"atb":[[29,3.57]],"id":41419630},{"atb":[[28,3.7]],"id":41419597},{"atb":[[5,25],[21,9.98],[26,0]],"id":41419606},{"atl":[[550,2]],"id":41419606},{"atb":[[3.6,0]],"id":41419635},{"atl":[[410,0]],"id":41419635},{"atb":[[18.5,5.71]],"id":41419614},{"atl":[[1000,2]],"id":41419614},{"atb":[[65,0],[46,0],[27,3.85]],"id":41419652},{"atb":[[6.2,19.23],[23,0],[28,0]],"id":41419586},{"atl":[[630,2]],"id":41419586},{"atb":[[27,0]],"id":41419631},{"atb":[[26,0]],"id":41419627},{"atb":[[8.2,13.89]],"id":41419594},{"atl":[[830,2]],"id":41419594},{"atb":[[10.5,10.53],[24,0],[29,0]],"id":41419640},{"atl":[[930,2]],"id":41419640},{"atb":[[32,0],[5.5,14.8],[26,0]],"id":41419607},{"atl":[[570,2]],"id":41419607},{"atb":[[3.25,0]],"id":41419636},{"atl":[[310,0]],"id":41419636},{"atb":[[12,9.09]],"id":41419615},{"atl":[[960,2]],"id":41419615},{"atb":[[2.16,6.56]],"id":41419657},{"atb":[[16,0],[5.3,23.26],[13.5,0]],"id":41419591},{"atl":[[560,2]],"id":41419591},{"atb":[[24,0]],"id":41435525},{"atb":[[29,2]],"id":41419653},{"atb":[[7,16.67]],"id":41419587},{"atb":[[22,0],[27,0],[5.7,21.28]],"id":41419599},{"atl":[[580,2]],"id":41419599},{"atb":[[140,0],[95,0],[29,3.57]],"id":41419628},{"atb":[[19.5,0]],"id":41419595},{"atl":[[1000,0]],"id":41419595},{"atb":[[4.1,0]],"id":41419608},{"atl":[[520,0]],"id":41419608},{"atb":[[3.25,0]],"id":41419637},{"atl":[[370,0]],"id":41419637},{"atb":[[3.65,37.74]],"id":41419612},{"atl":[[430,2]],"id":41419612},{"atb":[[6.8,0]],"id":41419592},{"atl":[[790,0]],"id":41419592},{"atb":[[27,0]],"id":41419654},{"atb":[[14.5,7.41]],"id":41419588},{"atl":[[1000,2]],"id":41419588},{"atb":[[75,0],[50,0],[28,3.7]],"id":41419633},{"atb":[[6,20]],"id":41419600},{"atl":[[580,2]],"id":41419600},{"atb":[[80,0],[110,0],[28,13.56]],"id":41419629},{"atb":[[2.16,0]],"id":41419658}],"con":true,"img":false}]}
{"op":"mcm","clk":"5353337452","pt":1646213229509,"mc":[{"id":"1.195503865","rc":[{"atb":[[32,0],[42,0]],"id":41419609},{"atb":[[4.5,0]],"id":41419638},{"atl":[[530,0]],"id":41419638},{"atb":[[12.5,0],[15,0]],"id":41419605},{"atb":[[85,0],[120,0]],"id":41435527},{"atb":[[5.9,0]],"id":41419601},{"atl":[[580,0]],"id":41419601},{"atb":[[2.16,0]],"id":41419659},{"atb":[[8,0]],"id":41419602},{"atl":[[840,0]],"id":41419602},{"atb":[[7,0]],"id":41419619},{"atl":[[820,0]],"id":41419619},{"atb":[[6,0]],"id":41419598},{"atl":[[590,0]],"id":41419598},{"atb":[[40,0],[30,0]],"id":41419594},{"atb":[[65,0],[46,0]],"id":41419615},{"atb":[[44,0],[60,0]],"id":41419604},{"atb":[[18,15.66]],"id":41419616},{"atl":[[1000,0]],"id":41419616},{"atb":[[11.5,0],[14,0]],"id":41419612},{"atb":[[34,0],[27,7.68]],"id":41419600}],"con":true,"img":false}]}
{"op":"mcm","clk":"5353337455","pt":1646213229566,"mc":[{"id":"1.195503865","rc":[{"atb":[[3.35,0]],"id":41419634},{"atl":[[400,0]],"id":41419634},{"atb":[[65,2.72],[46,3.26]],"id":41419613},{"atb":[[80,0],[110,0]],"id":41419630},{"atb":[[70,0],[95,0]],"id":41419597},{"atb":[[26,0]],"id":28546943},{"atl":[[730,0]],"id":41419585},{"atb":[[80,2.72],[85,0],[55,3.26],[60,0]],"id":41419614},{"atb":[[2.16,0]],"id":41419656},{"atb":[[26,0]],"id":41419590},{"atb":[[2.16,0]],"id":41419660},{"atb":[[2.16,0]],"id":28546950},{"atb":[[24,0]],"id":41419611},{"atb":[[85,0],[120,0]],"id":41419657},{"atb":[[160,0],[110,0]],"id":41419653},{"atb":[[22,0],[27,0]],"id":41419587},{"atb":[[36,3.26],[38,0],[46,2.72],[48,0]],"id":41419588}],"con":true,"img":false}]}
{"op":"mcm","clk":"5353337459","pt":1646213229668,"mc":[{"id":"1.195503865","rc":[{"atb":[[16.5,0],[16,3.26],[18.5,2.72],[19,0]],"id":41419638},{"atb":[[70,0],[48,0]],"id":41419613},{"atb":[[70,0],[95,0]],"id":41419651},{"atb":[[20,0],[25,0]],"id":41419601},{"atb":[[34,0],[44,0]],"id":41419602},{"atb":[[34,0],[44,0]],"id":41419619},{"atb":[[130,0],[180,0]],"id":41419631},{"atb":[[85,0],[120,0]],"id":41419627},{"atb":[[8,0],[9,0]],"id":41419636},{"atb":[[44,0],[60,0]],"id":41435525},{"atb":[[150,2.72],[100,3.26]],"id":41419653},{"atb":[[8.8,0],[7.8,0]],"id":41419637},{"atb":[[65,0],[46,0]],"id":41419616},{"atb":[[32,6.44],[42,0]],"id":41419592}],"con":true,"img":false}]}
{"op":"mcm","clk":"5353337465","pt":1646213229772,"mc":[{"id":"1.195503865","rc":[{"atb":[[9.2,0],[8.2,0]],"id":41419634},{"atb":[[70,0],[48,4.25]],"id":28546943},{"atb":[[270,0],[220,0]],"id":41419659},{"atb":[[65,0],[46,0]],"id":41419590},{"atb":[[32,3.26],[42,2.72]],"id":41419619},{"atb":[[22,0],[27,0]],"id":41419598},{"atb":[[80,0],[55,0]],"id":41419660},{"atb":[[85,0],[120,0]],"id":28546950},{"atb":[[44,0],[60,0]],"id":41419611},{"atb":[[44,3.26],[60,2.72]],"id":41419616}],"con":true,"img":false}]}
{"op":"mcm","clk":"5353337469","pt":1646213229876,"mc":[{"id":"1.195503865","rc":[{"atb":[[9.6,2.72],[8.6,3.26]],"id":41419634},{"atb":[[36,0],[28,0]],"id":41419585}],"con":true,"img":false}]}
{"op":"mcm","clk":"5353337474","pt":1646213229980,"mc":[{"id":"1.195503865","rc":[{"atb":[[150,0],[100,0]],"id":41419656}],"con":true,"img":false}]}
{"op":"mcm","clk":"5353337478","pt":1646213230083,"mc":[{"id":"1.195503865","rc":[{"atb":[[40,2.72],[30,3.26]],"id":41419593},{"atb":[[150,2.72],[100,3.26]],"id":41419618},{"atb":[[21,13.25],[26,2.72]],"id":41419606},{"atb":[[23,3.26],[28,2.72]],"id":41419586},{"atb":[[24,3.26],[29,2.72]],"id":41419640},{"atb":[[32,2.72],[26,3.26]],"id":41419607},{"atb":[[16,2.72],[13.5,3.26]],"id":41419591},{"atb":[[22,3.26],[27,2.72]],"id":41419599},{"atb":[[140,2.72],[95,3.26]],"id":41419628},{"atb":[[80,3.26],[110,2.72]],"id":41419629}],"con":true,"img":false}]}
{"op":"mcm","clk":"5353337481","pt":1646213230186,"mc":[{"id":"1.195503865","rc":[{"atb":[[12.5,3.26],[15,2.72]],"id":41419605},{"atb":[[85,3.26],[120,2.72]],"id":41435527},{"atb":[[65,2.72],[46,3.26]],"id":41419652},{"atb":[[40,2.72],[30,3.26]],"id":41419594},{"atb":[[65,2.72],[46,3.26]],"id":41419615},{"atb":[[44,3.26],[60,2.72]],"id":41419604},{"atb":[[11.5,3.26],[14,2.72]],"id":41419612},{"atb":[[75,2.72],[50,3.26]],"id":41419633},{"atb":[[34,2.72],[27,10.95]],"id":41419600}],"con":true,"img":false}]}
{"op":"mcm","clk":"5353337485","pt":1646213230288,"mc":[{"id":"1.195503865","rc":[{"atb":[[32,3.26],[42,2.72]],"id":41419609}],"con":true,"img":false}]}
{"op":"mcm","clk":"5353337490","pt":1646213230393,"mc":[{"id":"1.195503865","rc":[{"atb":[[80,3.26],[110,2.72]],"id":41419630},{"atb":[[70,3.26],[95,2.72]],"id":41419597},{"atb":[[85,3.26],[120,2.72]],"id":41419657},{"atb":[[22,3.26],[27,2.72]],"id":41419587}],"con":true,"img":false}]}
{"op":"mcm","clk":"5353337503","pt":1646213230705,"mc":[{"id":"1.195503865","rc":[{"atb":[[20,3.26],[25,2.72]],"id":41419601},{"atb":[[270,2.72],[220,3.26]],"id":41419659},{"atb":[[130,3.26],[180,2.72]],"id":41419631},{"atb":[[85,3.26],[120,2.72]],"id":41419627},{"atb":[[8,3.26],[9,2.72]],"id":41419636},{"atb":[[44,3.26],[60,2.72]],"id":41435525},{"atb":[[32,9.71],[42,2.72]],"id":41419592}],"con":true,"img":false}]}
{"op":"mcm","clk":"5353337510","pt":1646213230809,"mc":[{"id":"1.195503865","rc":[{"atb":[[70,3.26],[95,2.72]],"id":41419651},{"atb":[[70,2.72],[48,7.52]],"id":28546943},{"atb":[[34,3.26],[44,2.72]],"id":41419602},{"atb":[[36,2.72],[28,3.26]],"id":41419585},{"atb":[[150,2.72],[100,3.26]],"id":41419656},{"atb":[[65,2.72],[46,3.26]],"id":41419590},{"atb":[[22,3.26],[27,2.72]],"id":41419598},{"atb":[[80,2.72],[55,3.26]],"id":41419660},{"atb":[[85,3.26],[120,2.72]],"id":28546950},{"atb":[[44,3.26],[60,2.72]],"id":41419611},{"atb":[[8.8,2.72],[7.8,3.26]],"id":41419637}],"con":true,"img":false}]}
{"op":"mcm","clk":"5353339874","pt":1646213272127,"mc":[{"id":"1.195503865","rc":[{"atb":[[3.5,40]],"id":41419634},{"atl":[[400,2]],"id":41419634},{"atb":[[17,6.25]],"id":41419613},{"atl":[[1000,2]],"id":41419613},{"atb":[[28,3.7]],"id":41419651},{"atb":[[28,3.7]],"id":28546943},{"atb":[[2.16,2]],"id":41419659},{"atb":[[2.16,4.88]],"id":41419656},{"atb":[[2.16,9.3]],"id":41419660},{"atb":[[2.16,6.24]],"id":28546950},{"atb":[[30,2]],"id":41419654}],"con":true,"img":false}]}
{"op":"mcm","clk":"5353339879","pt":1646213272233,"mc":[{"id":"1.195503865","rc":[{"atb":[[4.7,21.02]],"id":41419638},{"atl":[[530,2]],"id":41419638},{"atb":[[11.5,9.52]],"id":41419655},{"atl":[[950,2]],"id":41419655},{"atb":[[5.9,20.41]],"id":41419601},{"atl":[[590,2]],"id":41419601},{"atb":[[3.6,38.06]],"id":41419635},{"atl":[[420,2]],"id":41419635},{"atb":[[8,8.88]],"id":41419602},{"atl":[[840,2]],"id":41419602},{"atl":[[730,2]],"id":41419585},{"atb":[[28,3.7]],"id":41419590},{"atb":[[7.6,14.8]],"id":41419619},{"atl":[[820,2]],"id":41419619},{"atb":[[29,2]],"id":41419631},{"atb":[[6,20]],"id":41419598},{"atl":[[610,2]],"id":41419598},{"atb":[[29,3.57]],"id":41419627},{"atb":[[3.25,44.44]],"id":41419636},{"atl":[[330,2]],"id":41419636},{"atb":[[26,14.65]],"id":41419611},{"atb":[[26,14.65]],"id":41435525},{"atb":[[20,5.26]],"id":41419595},{"atl":[[1000,2]],"id":41419595},{"atb":[[4.3,30.3]],"id":41419608},{"atl":[[520,2]],"id":41419608},{"atb":[[3.45,40.82]],"id":41419637},{"atl":[[390,2]],"id":41419637},{"atb":[[18,21.54]],"id":41419616},{"atl":[[1000,2]],"id":41419616},{"atb":[[7.2,16.13]],"id":41419592},{"atl":[[790,2]],"id":41419592},{"atb":[[2.16,2]],"id":41419658}],"con":true,"img":false}]}
{"op":"mcm","clk":"5353348921","pt":1646213454750,"mc":[{"id":"1.195503865","rc":[{"atb":[[23,0],[28,0]],"id":41419586},{"atb":[[8.8,0],[7.8,0]],"id":41419637}],"con":true,"img":false}]}
{"op":"mcm","clk":"5353348929","pt":1646213454855,"mc":[{"id":"1.195503865","rc":[{"atb":[[12.5,0],[15,0]],"id":41419605},{"atb":[[40,0],[30,0]],"id":41419593},{"atb":[[21,9.98],[26,0]],"id":41419606},{"atb":[[16,0],[13.5,0]],"id":41419591},{"atb":[[22,0],[27,0]],"id":41419599},{"atb":[[140,0],[95,0]],"id":41419628},{"atb":[[260,0],[210,0]],"id":41419654},{"atb":[[140,0],[190,0]],"id":41419658}],"con":true,"img":false}]}
{"op":"mcm","clk":"5353348970","pt":1646213455574,"mc":[{"id":"1.195503865","rc":[{"atb":[[12,3.26],[14.5,2.72]],"id":41419605},{"atb":[[32,3.26],[42,2.72]],"id":41419593},{"atb":[[22,3.26],[27,2.72]],"id":41419606},{"atb":[[25,3.26],[30,2.72]],"id":41419586},{"atb":[[23,3.26],[28,2.72]],"id":41419599},{"atb":[[8.6,2.72],[7.6,33.54]],"id":41419637},{"atb":[[270,2.72],[220,3.26]],"id":41419654},{"atb":[[150,3.26],[200,2.72]],"id":41419658}],"con":true,"img":false}]}
{"op":"mcm","clk":"5353348975","pt":1646213455677,"mc":[{"id":"1.195503865","rc":[{"atb":[[17.5,2.72],[15,3.26]],"id":41419591},{"atb":[[150,2.72],[100,3.26]],"id":41419628}],"con":true,"img":false}]}
{"op":"mcm","clk":"5353349018","pt":1646213456564,"mc":[{"id":"1.195503865","rc":[{"atb":[[3.6,6.56],[2.16,0]],"id":41435527},{"atb":[[3.6,2],[2.16,0]],"id":41419659},{"atb":[[1.71,13.78]],"id":41419585},{"atb":[[3.6,4.88],[2.16,0]],"id":41419656},{"atb":[[3.6,9.3],[2.16,0]],"id":41419660},{"atb":[[3.6,6.24],[2.16,0]],"id":28546950},{"atb":[[3.6,6.56],[2.16,0]],"id":41419657},{"atb":[[3.45,0],[1.71,81.64]],"id":41419637},{"atb":[[3.6,2],[2.16,0]],"id":41419658}],"con":true,"img":false}]}
{"op":"mcm","clk":"5353350190","pt":1646213480278,"mc":[{"id":"1.195503865","rc":[{"atb":[[80,0],[55,0]],"id":41419614},{"atb":[[36,0],[46,0]],"id":41419588}],"con":true,"img":false}]}
{"op":"mcm","clk":"5353350200","pt":1646213480487,"mc":[{"id":"1.195503865","rc":[{"atb":[[65,0],[46,0]],"id":41419613}],"con":true,"img":false}]}
{"op":"mcm","clk":"5353350222","pt":1646213480803,"mc":[{"id":"1.195503865","rc":[{"atb":[[9.6,0],[8.6,0]],"id":41419634},{"atb":[[44,0]],"id":41419604},{"atb":[[44,0],[60,0]],"id":41419616}],"con":true,"img":false}]}
{"op":"mcm","clk":"5353350226","pt":1646213480899,"mc":[{"id":"1.195503865","rc":[{"atb":[[60,0]],"id":41419604}],"con":true,"img":false}]}
{"op":"mcm","clk":"5353350230","pt":1646213481002,"mc":[{"id":"1.195503865","rc":[{"atb":[[85,2.72],[60,3.26]],"id":41419614},{"atb":[[22,0],[27,0]],"id":41419587},{"atb":[[40,3.26],[50,2.72]],"id":41419588}],"con":true,"img":false}]}
{"op":"mcm","clk":"5353350247","pt":1646213481307,"mc":[{"id":"1.195503865","rc":[{"atb":[[70,2.72],[48,3.26]],"id":41419613}],"con":true,"img":false}]}
{"op":"mcm","clk":"5353350253","pt":1646213481410,"mc":[{"id":"1.195503865","rc":[{"atb":[[48,4.25]],"id":28546943},{"atb":[[100,0]],"id":41419656},{"atb":[[65,0]],"id":41419590},{"atb":[[27,0]],"id":41419598},{"atb":[[85,0],[120,0]],"id":28546950},{"atb":[[32,6.44],[42,0]],"id":41419592}],"con":true,"img":false}]}
{"op":"mcm","clk":"5353350259","pt":1646213481513,"mc":[{"id":"1.195503865","rc":[{"atb":[[9,3.26]],"id":41419634},{"atb":[[70,0],[95,0]],"id":41419651},{"atb":[[70,0]],"id":28546943},{"atb":[[36,0],[28,0]],"id":41419585},{"atb":[[150,0]],"id":41419656},{"atb":[[46,0]],"id":41419590},{"atb":[[22,0]],"id":41419598},{"atb":[[46,3.26]],"id":41419604},{"atb":[[46,3.26]],"id":41419616}],"con":true,"img":false}]}
{"op":"mcm","clk":"5353350262","pt":1646213481617,"mc":[{"id":"1.195503865","rc":[{"atb":[[10,2.72]],"id":41419634},{"atb":[[65,2.72]],"id":41419604},{"atb":[[65,2.72]],"id":41419616}],"con":true,"img":false}]}
{"op":"mcm","clk":"5353350266","pt":1646213481721,"mc":[{"id":"1.195503865","rc":[{"atb":[[24,3.26],[29,2.72]],"id":41419587}],"con":true,"img":false}]}
{"op":"mcm","clk":"5353350280","pt":1646213482083,"mc":[{"id":"1.195503865","rc":[{"atb":[[50,3.26]],"id":28546943},{"atb":[[110,5.71]],"id":41419656},{"atb":[[28,2.72]],"id":41419598},{"atb":[[130,2.72],[90,3.26]],"id":28546950},{"atb":[[36,3.26],[46,2.72]],"id":41419592}],"con":true,"img":false}]}
{"op":"mcm","clk":"5353350284","pt":1646213482186,"mc":[{"id":"1.195503865","rc":[{"atb":[[75,3.26],[100,2.72]],"id":41419651},{"atb":[[75,2.72]],"id":28546943},{"atb":[[40,2.72],[30,10.15]],"id":41419585},{"atb":[[160,2.72]],"id":41419656},{"atb":[[70,2.72],[48,7.52]],"id":41419590},{"atb":[[23,3.26]],"id":41419598}],"con":true,"img":false}]}
{"op":"mcm","clk":"5353371896","pt":1646213862076,"mc":[{"id":"1.195503865","rc":[{"atb":[[11.5,0],[14,0]],"id":41419612}],"con":true,"img":false}]}
{"op":"mcm","clk":"5353371936","pt":1646213862747,"mc":[{"id":"1.195503865","rc":[{"atb":[[11,3.26],[13.5,2.72]],"id":41419612}],"con":true,"img":false}]}
{"op":"mcm","clk":"5353373923","pt":1646213894736,"mc":[{"id":"1.195503865","rc":[{"atl":[[650,2],[680,0]],"id":41419593},{"atl":[[950,0],[930,2]],"id":41419655},{"atl":[[590,0],[580,2]],"id":41419601},{"atl":[[830,2],[840,0]],"id":41419602},{"atl":[[730,0],[710,2]],"id":41419585},{"atl":[[630,0],[620,2]],"id":41419586},{"atl":[[590,2],[610,0]],"id":41419598},{"atl":[[830,0],[810,2]],"id":41419594},{"atl":[[920,2],[930,0]],"id":41419640},{"atl":[[570,0],[560,2]],"id":41419607},{"atl":[[560,2],[580,0]],"id":41419599},{"atl":[[740,2],[790,0]],"id":41419592},{"atl":[[570,2],[580,0]],"id":41419600}],"con":true,"img":false}]}
{"op":"mcm","clk":"5353373936","pt":1646213894903,"mc":[{"id":"1.195503865","rc":[{"atb":[[32,0],[26,0]],"id":41419607},{"atb":[[34,0],[27,7.68]],"id":41419600}],"con":true,"img":false}]}
{"op":"mcm","clk":"5353373984","pt":1646213895623,"mc":[{"id":"1.195503865","rc":[{"atb":[[25,3.26],[30,2.72]],"id":41419607},{"atb":[[32,2.72],[26,3.26]],"id":41419600}],"con":true,"img":false}]}
{"op":"mcm","clk":"5353377688","pt":1646213955000,"mc":[{"id":"1.195503865","rc":[{"atl":[[910,2]],"id":41419640}],"con":true,"img":false}]}
{"op":"mcm","clk":"5353377697","pt":1646213955106,"mc":[{"id":"1.195503865","rc":[{"atl":[[920,0]],"id":41419640},{"atb":[[18,15.66],[21,5]],"id":41419616}],"con":true,"img":false}]}
{"op":"mcm","clk":"5353378802","pt":1646213972946,"mc":[{"id":"1.195503865","rc":[{"atl":[[910,0],[920,2]],"id":41419640}],"con":true,"img":false}]}
{"op":"mcm","clk":"5353385573","pt":1646214074829,"mc":[{"id":"1.195503865","rc":[{"atl":[[470,0]],"id":41419605},{"atl":[[830,0],[820,2]],"id":41419602}],"con":true,"img":false}]}
{"op":"mcm","clk":"5353385580","pt":1646214074934,"mc":[{"id":"1.195503865","rc":[{"atl":[[460,2]],"id":41419605},{"atb":[[17,0],[19.5,5.41]],"id":41419613},{"atl":[[570,2],[580,0]],"id":41419601},{"atl":[[920,0],[910,2]],"id":41419640},{"atb":[[6,0],[5.4,21]],"id":41419600},{"atl":[[570,0],[560,2]],"id":41419600}],"con":true,"img":false}]}
{"op":"mcm","clk":"5353385608","pt":1646214075301,"mc":[{"id":"1.195503865","rc":[{"atb":[[32,0],[26,0]],"id":41419600}],"con":true,"img":false}]}
{"op":"mcm","clk":"5353385664","pt":1646214076123,"mc":[{"id":"1.195503865","rc":[{"atb":[[25,3.26],[30,2.72]],"id":41419600}],"con":true,"img":false}]}
{"op":"mcm","clk":"5353385977","pt":1646214079800,"mc":[{"id":"1.195503865","rc":[{"atb":[[25,0],[30,0]],"id":41419607}],"con":true,"img":false}]}
{"op":"mcm","clk":"5353386046","pt":1646214080729,"mc":[{"id":"1.195503865","rc":[{"atb":[[32,2.72],[26,3.26]],"id":41419607}],"con":true,"img":false}]}
{"op":"mcm","clk":"5353393768","pt":1646214194902,"mc":[{"id":"1.195503865","rc":[{"atb":[[3.6,38.46],[3.9,0]],"id":41419605},{"atb":[[5.3,23.26],[5.9,0]],"id":41419601},{"atb":[[5,25],[5.7,0]],"id":41419599},{"atb":[[17,6.25],[20,0]],"id":41419595}],"con":true,"img":false}]}
{"op":"mcm","clk":"5353397816","pt":1646214254125,"mc":[{"id":"1.195503865","rc":[{"atb":[[5.2,21.02],[4.7,0]],"id":41419638},{"atb":[[3.6,0],[3.85,35.09]],"id":41419605},{"atb":[[5.9,20.41]],"id":41419601},{"atl":[[710,0]],"id":41419585},{"atb":[[7.6,0]],"id":41419619},{"atl":[[590,2],[620,0]],"id":41419586},{"atl":[[1000,2]],"id":41419611},{"atl":[[560,0]],"id":41419591},{"atl":[[730,0],[710,2]],"id":41419587},{"atl":[[1000,2]],"id":41419604},{"atl":[[740,0]],"id":41419592},{"atl":[[990,2],[1000,0]],"id":41419588}],"con":true,"img":false}]}
{"op":"mcm","clk":"5353397822","pt":1646214254225,"mc":[{"id":"1.195503865","rc":[{"atb":[[5.3,0]],"id":41419601},{"atl":[[670,2]],"id":41419585},{"atb":[[8.6,13.16]],"id":41419619},{"atb":[[8.6,13.16],[10.5,0]],"id":41419640},{"atl":[[860,2],[910,0]],"id":41419640},{"atl":[[550,2]],"id":41419591},{"atl":[[560,0],[550,2]],"id":41419599},{"atl":[[720,2]],"id":41419592}],"con":true,"img":false}]}
{"op":"mcm","clk":"5353397835","pt":1646214254437,"mc":[{"id":"1.195503865","rc":[{"atb":[[19,11.1],[23,0]],"id":41419608},{"atb":[[25,0],[30,0]],"id":41419600}],"con":true,"img":false}]}
{"op":"mcm","clk":"5353397893","pt":1646214255101,"mc":[{"id":"1.195503865","rc":[{"atb":[[19.5,3.26],[24,2.72]],"id":41419608},{"atb":[[32,2.72],[26,3.26]],"id":41419600}],"con":true,"img":false}]}
{"op":"mcm","clk":"5353398933","pt":1646214270333,"mc":[{"id":"1.195503865","rc":[{"atl":[[860,0],[870,2]],"id":41419640},{"atl":[[990,0],[1000,2]],"id":41419588}],"con":true,"img":false}]}
{"op":"mcm","clk":"5353400132","pt":1646214289361,"mc":[{"id":"1.195503865","rc":[{"atl":[[670,0],[660,2]],"id":41419585},{"atl":[[540,2],[550,0]],"id":41419591},{"atl":[[700,2],[710,0]],"id":41419587},{"atl":[[720,0],[710,2]],"id":41419592}],"con":true,"img":false}]}
{"op":"mcm","clk":"5353400159","pt":1646214289776,"mc":[{"id":"1.195503865","rc":[{"atb":[[32,0],[26,0]],"id":41419600}],"con":true,"img":false}]}
{"op":"mcm","clk":"5353400197","pt":1646214290497,"mc":[{"id":"1.195503865","rc":[{"atb":[[25,3.26],[30,2.72]],"id":41419600}],"con":true,"img":false}]}
{"op":"mcm","clk":"5353402059","pt":1646214316916,"mc":[{"id":"1.195503865","rc":[{"atb":[[19.5,0],[24,0]],"id":41419608}],"con":true,"img":false}]}
{"op":"mcm","clk":"5353402120","pt":1646214317593,"mc":[{"id":"1.195503865","rc":[{"atb":[[19,14.37],[23,2.72]],"id":41419608}],"con":true,"img":false}]}
{"op":"mcm","clk":"5353407568","pt":1646214393179,"mc":[{"id":"1.195503865","rc":[{"atl":[[700,0],[690,2]],"id":41419587}],"con":true,"img":false}]}
{"op":"mcm","clk":"5353408845","pt":1646214410318,"mc":[{"id":"1.195503865","rc":[{"atl":[[990,2],[1000,0]],"id":41419588}],"con":true,"img":false}]}
{"op":"mcm","clk":"5353409782","pt":1646214424334,"mc":[{"id":"1.195503865","rc":[{"atl":[[540,2],[550,0]],"id":41419606},{"atl":[[660,0],[650,2]],"id":41419585},{"atl":[[580,2]],"id":41419586}],"con":true,"img":false}]}
{"op":"mcm","clk":"5353409790","pt":1646214424440,"mc":[{"id":"1.195503865","rc":[{"atl":[[590,0]],"id":41419586}],"con":true,"img":false}]}
{"op":"mcm","clk":"5353410562","pt":1646214435163,"mc":[{"id":"1.195503865","rc":[{"atb":[[25,0],[30,0]],"id":41419600}],"con":true,"img":false}]}
{"op":"mcm","clk":"5353410620","pt":1646214435855,"mc":[{"id":"1.195503865","rc":[{"atb":[[32,2.72]],"id":41419600}],"con":true,"img":false}]}
{"op":"mcm","clk":"5353410627","pt":1646214435945,"mc":[{"id":"1.195503865","rc":[{"atb":[[26,3.26]],"id":41419600}],"con":true,"img":false}]}
{"op":"mcm","clk":"5353410856","pt":1646214439542,"mc":[{"id":"1.195503865","rc":[{"atb":[[9.6,11.63],[8.6,0]],"id":41419640},{"atl":[[1000,2]],"id":41435525},{"atl":[[690,0],[680,2]],"id":41419587},{"atl":[[700,2],[710,0]],"id":41419592},{"atl":[[990,0],[980,2]],"id":41419588}],"con":true,"img":false}]}
{"op":"mcm","clk":"5353411010","pt":1646214441664,"mc":[{"id":"1.195503865","rc":[{"atb":[[32,0],[26,0]],"id":41419600}],"con":true,"img":false}]}
{"op":"mcm","clk":"5353411055","pt":1646214442444,"mc":[{"id":"1.195503865","rc":[{"atb":[[25,3.26],[30,2.72]],"id":41419600}],"con":true,"img":false}]}
{"op":"mcm","clk":"5353412138","pt":1646214460615,"mc":[{"id":"1.195503865","rc":[{"atb":[[3.85,0],[5.3,23.26]],"id":41419605},{"atl":[[350,2],[400,0]],"id":41419634},{"atb":[[12,8.79]],"id":41419613},{"atl":[[960,2]],"id":41419613},{"atl":[[540,0]],"id":41419606},{"atb":[[8,0],[10.5,8.88]],"id":41419602},{"atl":[[570,2],[650,0]],"id":41419585},{"atb":[[13.5,7.92]],"id":41419614},{"atb":[[8.6,0]],"id":41419619},{"atb":[[6.2,0]],"id":41419586},{"atl":[[580,0]],"id":41419586},{"atl":[[780,2],[810,0]],"id":41419594},{"atb":[[3.25,0]],"id":41419636},{"atb":[[12,0],[15,7.14]],"id":41419615},{"atl":[[1000,0]],"id":41419611},{"atl":[[680,0]],"id":41419587},{"atl":[[540,2]],"id":41419599},{"atb":[[5,25]],"id":41419608},{"atb":[[15.5,6.9]],"id":41419616},{"atb":[[4.8,26.32],[3.65,0]],"id":41419612},{"atb":[[30,0]],"id":41419654},{"atb":[[10,11.11]],"id":41419588},{"atl":[[900,2]],"id":41419588},{"atb":[[6,20],[5.4,0]],"id":41419600}],"con":true,"img":false}]}
{"op":"mcm","clk":"5353412147","pt":1646214460781,"mc":[{"id":"1.195503865","rc":[{"atb":[[7.2,0],[10,8.52]],"id":41419609},{"atl":[[720,2],[770,0]],"id":41419609},{"atb":[[5.2,0],[6.6,17.86]],"id":41419638},{"atl":[[530,0],[520,2]],"id":41419638},{"atb":[[4,33.33],[3.5,0]],"id":41419634},{"atb":[[19.5,0]],"id":41419613},{"atl":[[1000,0]],"id":41419613},{"atb":[[6.8,0],[8.4,13.51]],"id":41419593},{"atl":[[600,2],[650,0]],"id":41419593},{"atb":[[11.5,0],[7.6,15.15]],"id":41419655},{"atl":[[820,2],[930,0]],"id":41419655},{"atb":[[40,2],[29,0]],"id":41419618},{"atb":[[7.8,14.71],[5.9,0]],"id":41419601},{"atl":[[570,0],[560,2]],"id":41419601},{"atb":[[38,2.7],[29,0]],"id":41419630},{"atb":[[36,2.86],[28,0]],"id":41419597},{"atl":[[1000,2]],"id":28546943},{"atb":[[5,0],[6,20]],"id":41419606},{"atl":[[530,2]],"id":41419606},{"atb":[[3.6,0],[4.4,29.41]],"id":41419635},{"atl":[[390,2],[420,0]],"id":41419635},{"atl":[[820,0],[800,2]],"id":41419602},{"atb":[[18.5,0]],"id":41419614},{"atl":[[860,2],[1000,0]],"id":41419614},{"atl":[[1000,2]],"id":41419590},{"atb":[[34,3.03],[27,0]],"id":41419652},{"atl":[[1000,2]],"id":41419652},{"atb":[[9.8,11.36]],"id":41419619},{"atl":[[780,2],[820,0]],"id":41419619},{"atb":[[5.1,24.39]],"id":41419586},{"atl":[[550,2]],"id":41419586},{"atb":[[40,2],[29,0]],"id":41419631},{"atb":[[8,14.29],[6,0]],"id":41419598},{"atl":[[590,0],[580,2]],"id":41419598},{"atl":[[1000,2]],"id":41419660},{"atb":[[8.2,0],[9.4,11.9]],"id":41419594},{"atb":[[9.6,0],[14,7.69]],"id":41419640},{"atl":[[800,2],[870,0]],"id":41419640},{"atb":[[5.5,0],[7.4,14.8]],"id":41419607},{"atl":[[540,2],[560,0]],"id":41419607},{"atl":[[1000,2]],"id":28546950},{"atb":[[3.5,40]],"id":41419636},{"atl":[[870,2],[960,0]],"id":41419615},{"atb":[[34,3.03],[26,10.65]],"id":41419611},{"atb":[[6.2,19.23],[5.3,0]],"id":41419591},{"atl":[[540,0],[510,2]],"id":41419591},{"atb":[[34,3.03],[26,10.65]],"id":41435525},{"atb":[[38,2],[29,0]],"id":41419653},{"atl":[[610,2]],"id":41419587},{"atb":[[5,0],[6,20]],"id":41419599},{"atl":[[550,0]],"id":41419599},{"atb":[[38,2.7],[29,0]],"id":41419628},{"atb":[[17,0],[14,7.69]],"id":41419595},{"atl":[[860,2],[1000,0]],"id":41419595},{"atb":[[4.3,0]],"id":41419608},{"atl":[[520,0],[510,2]],"id":41419608},{"atb":[[34,3.03],[27,0]],"id":41419604},{"atl":[[1000,0]],"id":41419604},{"atb":[[21,0]],"id":41419616},{"atl":[[880,2],[1000,0]],"id":41419616},{"atb":[[7.2,0],[6,18.2]],"id":41419592},{"atl":[[590,2],[700,0]],"id":41419592},{"atb":[[40,2]],"id":41419654},{"atb":[[14.5,0]],"id":41419588},{"atl":[[980,0]],"id":41419588},{"atb":[[36,2.86],[28,0]],"id":41419633},{"atl":[[560,0],[550,2]],"id":41419600},{"atb":[[36,2.86],[28,9.86]],"id":41419629}],"con":true,"img":false}]}
{"op":"mcm","clk":"5353412153","pt":1646214460874,"mc":[{"id":"1.195503865","rc":[{"atl":[[1000,2]],"id":41419611}],"con":true,"img":false}]}
{"op":"mcm","clk":"5353412161","pt":1646214460918,"mc":[{"id":"1.195503865","rc":[{"atb":[[40,0],[30,6.88]],"id":41419585},{"atb":[[25,0],[30,0]],"id":41419586},{"atb":[[19,11.1],[23,0]],"id":41419608},{"atb":[[36,0],[46,0]],"id":41419592}],"con":true,"img":false}]}
{"op":"mcm","clk":"5353412165","pt":1646214461069,"mc":[{"id":"1.195503865","rc":[{"atb":[[22,0],[27,0]],"id":41419606},{"atb":[[32,0],[26,0]],"id":41419607},{"atb":[[23,0],[28,0]],"id":41419599}],"con":true,"img":false}]}
{"op":"mcm","clk":"5353412200","pt":1646214461588,"mc":[{"id":"1.195503865","rc":[{"atb":[[32,2.72],[26,3.26]],"id":41419585},{"atb":[[24,3.26],[29,2.72]],"id":41419586},{"atb":[[19.5,3.26],[24,2.72]],"id":41419608},{"atb":[[36,2.72],[28,3.26]],"id":41419592}],"con":true,"img":false}]}
{"op":"mcm","clk":"5353412204","pt":1646214461695,"mc":[{"id":"1.195503865","rc":[{"atb":[[21,13.25],[26,2.72]],"id":41419606},{"atb":[[34,2.72],[27,3.26]],"id":41419607}],"con":true,"img":false}]}
{"op":"mcm","clk":"5353412217","pt":1646214461901,"mc":[{"id":"1.195503865","rc":[{"atb":[[22,3.26],[27,2.72]],"id":41419599}],"con":true,"img":false}]}
{"op":"mcm","clk":"5353412654","pt":1646214469207,"mc":[{"id":"1.195503865","rc":[{"atl":[[520,0],[530,2]],"id":41419638},{"atl":[[1000,2]],"id":41419651},{"atl":[[560,0],[570,2]],"id":41419601},{"atl":[[390,0],[400,2]],"id":41419635},{"atl":[[860,0],[870,2]],"id":41419614},{"atl":[[780,0],[790,2]],"id":41419619},{"atl":[[800,0],[810,2]],"id":41419640},{"atl":[[870,0],[880,2]],"id":41419615},{"atl":[[880,0],[890,2]],"id":41419616}],"con":true,"img":false}]}
{"op":"mcm","clk":"5353412659","pt":1646214469311,"mc":[{"id":"1.195503865","rc":[{"atl":[[810,2]],"id":41419602}],"con":true,"img":false}]}
{"op":"mcm","clk":"5353412665","pt":1646214469415,"mc":[{"id":"1.195503865","rc":[{"atl":[[800,0]],"id":41419602}],"con":true,"img":false}]}
{"op":"mcm","clk":"5353412669","pt":1646214469518,"mc":[{"id":"1.195503865","rc":[{"atb":[[32,0],[26,0]],"id":41419585},{"atb":[[24,0],[29,0]],"id":41419586},{"atb":[[36,0],[28,0]],"id":41419592}],"con":true,"img":false}]}
{"op":"mcm","clk":"5353412704","pt":1646214470199,"mc":[{"id":"1.195503865","rc":[{"atb":[[25,3.26],[30,9.61]],"id":41419585},{"atb":[[23,3.26],[28,2.72]],"id":41419586},{"atb":[[34,2.72],[27,3.26]],"id":41419592}],"con":true,"img":false}]}
{"op":"mcm","clk":"5353412888","pt":1646214473918,"mc":[{"id":"1.195503865","rc":[{"atb":[[6.8,17.24]],"id":41419605}],"con":true,"img":false}]}
{"op":"mcm","clk":"5353412893","pt":1646214474035,"mc":[{"id":"1.195503865","rc":[{"atb":[[5.3,0]],"id":41419605},{"atl":[[320,2],[350,0]],"id":41419634},{"atb":[[16.5,6.45],[12,0]],"id":41419613},{"atl":[[840,2],[960,0]],"id":41419613},{"atb":[[10.5,0],[14.5,7.41]],"id":41419602},{"atl":[[530,2],[570,0]],"id":41419585},{"atb":[[19,5.56],[13.5,0]],"id":41419614},{"atl":[[660,2],[780,0]],"id":41419594},{"atb":[[20,5.26],[15,0]],"id":41419615},{"atl":[[540,0],[510,2]],"id":41419599},{"atb":[[5,0],[6.2,19.23]],"id":41419608},{"atb":[[21,5],[15.5,0]],"id":41419616},{"atb":[[4.8,0],[6,20]],"id":41419612},{"atb":[[10,0],[12.5,8.7]],"id":41419588},{"atl":[[780,2],[900,0]],"id":41419588},{"atb":[[6,0],[7.6,15.15]],"id":41419600}],"con":true,"img":false}]}
{"op":"mcm","clk":"5353412908","pt":1646214474237,"mc":[{"id":"1.195503865","rc":[{"atl":[[600,0],[580,2]],"id":41419593},{"atl":[[500,2]],"id":41419606},{"atb":[[4.3,30.3]],"id":41419636},{"atl":[[560,2],[610,0]],"id":41419587},{"atb":[[16.5,6.45],[14,0]],"id":41419595},{"atl":[[860,0],[840,2]],"id":41419595}],"con":true,"img":false}]}
{"op":"mcm","clk":"5353412914","pt":1646214474338,"mc":[{"id":"1.195503865","rc":[{"atb":[[10,11.11],[7.6,0]],"id":41419655},{"atl":[[730,2],[820,0]],"id":41419655},{"atl":[[950,2],[1000,0]],"id":28546943},{"atl":[[530,0]],"id":41419606},{"atb":[[9.8,0],[13,8.33]],"id":41419619},{"atb":[[5.1,0],[6.4,18.52]],"id":41419586},{"atl":[[550,0],[510,2]],"id":41419586},{"atl":[[560,2],[580,0]],"id":41419598},{"atb":[[3.5,0]],"id":41419636},{"atb":[[7.2,16.13],[6,0]],"id":41419592},{"atl":[[540,2],[590,0]],"id":41419592}],"con":true,"img":false}]}
{"op":"mcm","clk":"5353413233","pt":1646214479940,"mc":[{"id":"1.195503865","rc":[{"atb":[[21,9.98],[26,0]],"id":41419606}],"con":true,"img":false}]}
{"op":"mcm","clk":"5353413275","pt":1646214480617,"mc":[{"id":"1.195503865","rc":[{"atb":[[20,3.26],[25,2.72]],"id":41419606}],"con":true,"img":false}]}
{"op":"mcm","clk":"5353418138","pt":1646214571948,"mc":[{"id":"1.195503865","rc":[{"atb":[[25,0],[30,0]],"id":41419600}],"con":true,"img":false}]}
{"op":"mcm","clk":"5353418180","pt":1646214572674,"mc":[{"id":"1.195503865","rc":[{"atb":[[27,10.95]],"id":41419600}],"con":true,"img":false}]}
{"op":"mcm","clk":"5353418187","pt":1646214572777,"mc":[{"id":"1.195503865","rc":[{"atb":[[34,2.72]],"id":41419600}],"con":true,"img":false}]}
{"op":"mcm","clk":"5353418313","pt":1646214575313,"mc":[{"id":"1.195503865","rc":[{"atl":[[670,2],[720,0]],"id":41419609},{"atl":[[530,0]],"id":41419638},{"atl":[[830,2],[840,0]],"id":41419613},{"atl":[[570,0],[560,2]],"id":41419601},{"atl":[[480,2],[500,0]],"id":41419606},{"atl":[[1000,0]],"id":41419652},{"atl":[[790,0],[780,2]],"id":41419619},{"atl":[[560,0],[550,2]],"id":41419598},{"atl":[[620,2],[660,0]],"id":41419594},{"atl":[[770,2],[810,0]],"id":41419640},{"atl":[[540,0],[530,2]],"id":41419607},{"atl":[[560,0],[550,2]],"id":41419587},{"atl":[[820,2],[840,0]],"id":41419595},{"atl":[[1000,2]],"id":41419604},{"atl":[[860,2],[890,0]],"id":41419616},{"atl":[[540,0],[530,2]],"id":41419592},{"atl":[[780,0],[770,2]],"id":41419588}],"con":true,"img":false}]}
{"op":"mcm","clk":"5353418319","pt":1646214575361,"mc":[{"id":"1.195503865","rc":[{"atl":[[520,2]],"id":41419638}],"con":true,"img":false}]}
{"op":"mcm","clk":"5353418332","pt":1646214575568,"mc":[{"id":"1.195503865","rc":[{"atb":[[20,0],[25,0]],"id":41419606},{"atb":[[34,0],[27,0]],"id":41419607},{"atb":[[34,0],[27,0]],"id":41419592}],"con":true,"img":false}]}
{"op":"mcm","clk":"5353418391","pt":1646214576401,"mc":[{"id":"1.195503865","rc":[{"atb":[[19,3.26],[23,2.72]],"id":41419606},{"atb":[[32,2.72],[26,3.26]],"id":41419607},{"atb":[[32,9.17],[26,3.26]],"id":41419592}],"con":true,"img":false}]}
{"op":"mcm","clk":"5353418541","pt":1646214579305,"mc":[{"id":"1.195503865","rc":[{"atl":[[950,0],[940,2]],"id":28546943},{"atb":[[11.5,9.52],[14.5,0]],"id":41419602},{"atl":[[760,2],[810,0]],"id":41419602},{"atl":[[530,0],[520,2]],"id":41419585},{"atl":[[840,2],[870,0]],"id":41419614},{"atl":[[1000,2]],"id":41419652},{"atl":[[850,2],[880,0]],"id":41419615},{"atl":[[510,0],[500,2]],"id":41419591},{"atb":[[16.5,0],[13.5,8]],"id":41419595},{"atl":[[1000,0]],"id":41419604},{"atb":[[9.6,11.63],[12.5,0]],"id":41419588}],"con":true,"img":false}]}
{"op":"mcm","clk":"5353418560","pt":1646214579667,"mc":[{"id":"1.195503865","rc":[{"atb":[[23,0],[28,0]],"id":41419586}],"con":true,"img":false}]}
{"op":"mcm","clk":"5353418593","pt":1646214580500,"mc":[{"id":"1.195503865","rc":[{"atb":[[22,3.26],[27,2.72]],"id":41419586}],"con":true,"img":false}]}
{"op":"mcm","clk":"5353418989","pt":1646214587493,"mc":[{"id":"1.195503865","rc":[{"atl":[[670,0],[660,2]],"id":41419609},{"atl":[[830,0],[800,2]],"id":41419613},{"atl":[[780,0],[770,2]],"id":41419619},{"atl":[[790,2]],"id":41419595},{"atl":[[710,2]],"id":41419588}],"con":true,"img":false}]}
{"op":"mcm","clk":"5353418995","pt":1646214587597,"mc":[{"id":"1.195503865","rc":[{"atl":[[520,0],[500,2]],"id":41419638},{"atl":[[820,0]],"id":41419595},{"atl":[[770,0]],"id":41419588}],"con":true,"img":false}]}
{"op":"mcm","clk":"5353420207","pt":1646214611951,"mc":[{"id":"1.195503865","rc":[{"atb":[[22,0],[27,0]],"id":41419599}],"con":true,"img":false}]}
{"op":"mcm","clk":"5353420245","pt":1646214612625,"mc":[{"id":"1.195503865","rc":[{"atb":[[23,3.26],[28,2.72]],"id":41419599}],"con":true,"img":false}]}
{"op":"mcm","clk":"5353420550","pt":1646214618344,"mc":[{"id":"1.195503865","rc":[{"atb":[[23,0],[28,0]],"id":41419599}],"con":true,"img":false}]}
{"op":"mcm","clk":"5353420579","pt":1646214619064,"mc":[{"id":"1.195503865","rc":[{"atb":[[22,3.26],[27,2.72]],"id":41419599}],"con":true,"img":false}]}
{"op":"mcm","clk":"5353422612","pt":1646214661639,"mc":[{"id":"1.195503865","rc":[{"atl":[[500,0],[510,2]],"id":41419638}],"con":true,"img":false}]}
{"op":"mcm","clk":"5353422945","pt":1646214669145,"mc":[{"id":"1.195503865","rc":[{"atl":[[800,0],[810,2]],"id":41419613},{"atl":[[760,0],[750,2]],"id":41419602},{"atb":[[16.5,6.45],[14,0]],"id":41419640}],"con":true,"img":false}]}
{"op":"mcm","clk":"5353423946","pt":1646214692503,"mc":[{"id":"1.195503865","rc":[{"atb":[[26,0]],"id":41419607}],"con":true,"img":false}]}
{"op":"mcm","clk":"5353423963","pt":1646214692864,"mc":[{"id":"1.195503865","rc":[{"atb":[[32,0]],"id":41419607},{"atb":[[32,6.44],[26,0]],"id":41419592}],"con":true,"img":false}]}
{"op":"mcm","clk":"5353423979","pt":1646214693175,"mc":[{"id":"1.195503865","rc":[{"atb":[[27,3.26]],"id":41419607}],"con":true,"img":false}]}
{"op":"mcm","clk":"5353424015","pt":1646214693890,"mc":[{"id":"1.195503865","rc":[{"atb":[[34,2.72]],"id":41419607},{"atb":[[34,2.72],[27,3.26]],"id":41419592}],"con":true,"img":false}]}
{"op":"mcm","clk":"5353427469","pt":1646214759816,"mc":[{"id":"1.195503865","rc":[{"atl":[[660,0],[670,2]],"id":41419609},{"atl":[[310,2],[320,0]],"id":41419634},{"atl":[[770,0],[780,2]],"id":41419619},{"atl":[[490,2],[500,0]],"id":41419591},{"atl":[[790,0],[800,2]],"id":41419595}],"con":true,"img":false}]}
{"op":"mcm","clk":"5353428064","pt":1646214770236,"mc":[{"id":"1.195503865","rc":[{"atl":[[670,0],[660,2]],"id":41419609},{"atl":[[490,0],[480,2]],"id":41419591}],"con":true,"img":false}]}
{"op":"mcm","clk":"5353428737","pt":1646214784143,"mc":[{"id":"1.195503865","rc":[{"atb":[[8,14.29],[7,0]],"id":41419587}],"con":true,"img":false}]}
{"op":"mcm","clk":"5353429083","pt":1646214790955,"mc":[{"id":"1.195503865","rc":[{"atb":[[22,0],[27,0]],"id":41419599}],"con":true,"img":false}]}
{"op":"mcm","clk":"5353429114","pt":1646214791622,"mc":[{"id":"1.195503865","rc":[{"atb":[[23,3.26],[28,2.72]],"id":41419599}],"con":true,"img":false}]}
{"op":"mcm","clk":"5353430618","pt":1646214819822,"mc":[{"id":"1.195503865","rc":[{"atb":[[17,0],[48,0],[24,0]],"id":41419609},{"atb":[[9,0],[20,0],[12.5,0]],"id":41419638},{"atb":[[4.8,0],[8.6,0],[5.8,0]],"id":41419605},{"atb":[[8,0],[4.5,0],[5.5,0]],"id":41419634},{"atb":[[18.5,0],[27,0],[60,0]],"id":41419613},{"atb":[[16.5,0],[11.5,0],[28,0]],"id":41419593},{"atb":[[32,2.72],[18,0],[13,0]],"id":41419655},{"atb":[[150,0],[50,0],[30,0]],"id":41435527},{"atb":[[330,0],[180,0],[90,0]],"id":41419651},{"atb":[[600,0],[700,0],[850,0]],"id":41419618},{"atb":[[8.6,0],[19,0],[11.5,0]],"id":41419601},{"atb":[[150,0],[50,0],[30,0]],"id":41419630},{"atb":[[330,0],[180,0],[90,0]],"id":41419597},{"atb":[[140,0],[48,0],[29,0]],"id":28546943},{"atb":[[600,0],[700,0],[850,0]],"id":41419659},{"atb":[[9.2,0],[21,0],[13,0]],"id":41419606},{"atb":[[5.8,0],[11.5,0],[7.6,0]],"id":41419635},{"atb":[[16.5,0],[46,0],[23,0]],"id":41419602},{"atb":[[17.5,0],[12.5,0],[30,2.72]],"id":41419585},{"atb":[[44,0],[27,0],[120,0]],"id":41419614},{"atb":[[360,0],[210,0],[110,3.26]],"id":41419656},{"atb":[[140,0],[48,3.26],[29,0]],"id":41419590},{"atb":[[38,0],[95,0],[24,0]],"id":41419652},{"atb":[[16.5,0],[11.5,0],[28,0]],"id":41419619},{"atb":[[9,0],[20,0],[12.5,0]],"id":41419586},{"atb":[[600,0],[700,0],[850,0]],"id":41419631},{"atb":[[16.5,0],[9.6,0],[7.6,0]],"id":41419598},{"atb":[[16,0],[44,0],[22,0]],"id":41419660},{"atb":[[65,0],[36,0],[180,0]],"id":41419627},{"atb":[[17,0],[12,0],[29,0]],"id":41419594},{"atb":[[32,0],[18,0],[13,0]],"id":41419640},{"atb":[[16.5,0],[11.5,0],[28,0]],"id":41419607},{"atb":[[65,0],[36,0],[180,0]],"id":28546950},{"atb":[[7.2,0],[5.1,0],[4.1,0]],"id":41419636},{"atb":[[17.5,0],[50,0],[25,0]],"id":41419615},{"atb":[[42,0],[26,0],[110,0]],"id":41419611},{"atb":[[130,0],[46,0],[28,0]],"id":41419657},{"atb":[[6.8,0],[9.8,0],[5.4,0]],"id":41419591},{"atb":[[42,0],[26,0],[110,0]],"id":41435525},{"atb":[[600,0],[700,0],[850,0]],"id":41419653},{"atb":[[9.2,0],[21,0],[13,0]],"id":41419587},{"atb":[[19.5,0],[12,0],[8.8,0]],"id":41419599},{"atb":[[360,0],[210,0],[110,0]],"id":41419628},{"atb":[[40,0],[100,0],[25,0]],"id":41419595},{"atb":[[8.6,0],[19,0],[11.5,0]],"id":41419608},{"atb":[[4.3,0],[5.3,0],[7.6,3.26]],"id":41419637},{"atb":[[38,0],[95,0],[24,0]],"id":41419604},{"atb":[[18,0],[26,0],[55,0]],"id":41419616},{"atb":[[5.1,0],[9.2,0],[6.2,0]],"id":41419612},{"atb":[[32,0],[18,0],[13,0]],"id":41419592},{"atb":[[600,0],[700,0],[850,0]],"id":41419654},{"atb":[[18,0],[26,0],[55,0]],"id":41419588},{"atb":[[16,0],[44,0],[22,0]],"id":41419633},{"atb":[[16,0],[11,0],[27,3.26]],"id":41419600},{"atb":[[130,0],[46,0],[28,0]],"id":41419629},{"atb":[[600,0],[700,0],[850,0]],"id":41419658}],"con":true,"img":false}]}
{"op":"mcm","clk":"5353430892","pt":1646214825707,"mc":[{"id":"1.195503865","rc":[{"atb":[[24,5.79],[12,24.21],[8.8,34.15]],"id":41419609},{"atb":[[5.8,27.75],[3.4,110.99],[3.9,91.85]],"id":41419605},{"atb":[[16.5,8.59],[8.6,35.05],[6.6,47.57]],"id":41419593},{"atb":[[180,0.74],[46,5.91],[28,13.56]],"id":41419651},{"atb":[[5.3,61.94],[11.5,12.68],[6.6,47.57]],"id":41419601},{"atb":[[180,0.74],[46,5.91],[28,9.86]],"id":41419597},{"atb":[[19.5,14.39],[48,2.83],[14.5,19.73]],"id":28546943},{"atb":[[5.6,57.91],[7.2,42.96],[13,11.1]],"id":41419606},{"atb":[[8.6,35.05],[11.5,34.88],[23,6.05]],"id":41419602},{"atb":[[17.5,8.07],[9,33.29],[7,44.4]],"id":41419585},{"atb":[[19.5,14.39],[48,6.1],[14.5,19.73]],"id":41419590},{"atb":[[17,16.64],[38,3.6],[12,24.21]],"id":41419652},{"atb":[[5.5,59.19],[12.5,11.58],[7,44.4]],"id":41419586},{"atb":[[9.6,15.48],[4.8,70.1],[5.8,55.49]],"id":41419598},{"atb":[[17,8.32],[6.8,45.93],[8.8,34.15]],"id":41419594},{"atb":[[16.5,8.59],[8.6,35.05],[6.6,47.57]],"id":41419607},{"atb":[[18,15.66],[42,3.24],[13,22.19]],"id":41419611},{"atb":[[3.7,98.66],[6.8,22.96],[4.4,78.34]],"id":41419591},{"atb":[[18,15.66],[42,3.24],[13,22.19]],"id":41435525},{"atb":[[5.6,57.91],[7.2,42.96],[13,11.1]],"id":41419587},{"atb":[[12,12.1],[6.8,45.93],[5.4,60.54]],"id":41419599},{"atb":[[17.5,16.14],[40,3.41],[12.5,23.16]],"id":41419595},{"atb":[[5.3,61.94],[11.5,12.68],[6.6,47.57]],"id":41419608},{"atb":[[17,16.64],[38,3.6],[12,24.21]],"id":41419604},{"atb":[[6.2,25.61],[4.1,85.93],[3.55,104.46]],"id":41419612},{"atb":[[7.2,59.09],[18,7.83],[9.2,32.48]],"id":41419592},{"atb":[[9.2,32.48],[26,5.32],[13,22.19]],"id":41419588},{"atb":[[16,8.87],[6.4,49.33],[8.4,35.99]],"id":41419600}],"con":true,"img":false}]}
{"op":"mcm","clk":"5353430894","pt":1646214825808,"mc":[{"id":"1.195503865","rc":[{"atb":[[5.5,59.19],[12.5,11.58],[7,44.4]],"id":41419638},{"atb":[[5.5,29.59],[3.25,118.39],[3.75,96.87]],"id":41419634},{"atb":[[27,5.12],[13.5,21.3],[9.4,31.71]],"id":41419613},{"atb":[[7.2,42.96],[18,7.83],[9.2,32.48]],"id":41419655},{"atb":[[20,14.02],[50,2.71],[15,19.02]],"id":41435527},{"atb":[[700,0.19],[400,0.67],[500,0.53]],"id":41419618},{"atb":[[20,14.02],[50,2.71],[15,19.02]],"id":41419630},{"atb":[[700,0.19],[400,0.67],[500,0.53]],"id":41419659},{"atb":[[4.8,70.1],[7.6,20.18],[3.9,91.85]],"id":41419635},{"atb":[[18.5,15.22],[44,3.09],[13.5,21.3]],"id":41419614},{"atb":[[32,8.59],[210,0.63],[55,4.93]],"id":41419656},{"atb":[[16.5,8.59],[8.6,35.05],[6.6,47.57]],"id":41419619},{"atb":[[700,0.19],[400,0.67],[500,0.53]],"id":41419631},{"atb":[[22,6.34],[11,26.63],[8.4,35.99]],"id":41419660},{"atb":[[65,2.08],[16.5,17.18],[23,12.1]],"id":41419627},{"atb":[[7.2,42.96],[18,7.83],[9.2,32.48]],"id":41419640},{"atb":[[65,2.08],[16.5,17.18],[23,12.1]],"id":28546950},{"atb":[[5.1,32.48],[3.55,104.46],[3.05,129.94]],"id":41419636},{"atb":[[9,33.29],[25,5.54],[12.5,23.16]],"id":41419615},{"atb":[[19,14.8],[46,2.95],[14,20.49]],"id":41419657},{"atb":[[700,0.19],[400,0.67],[500,0.53]],"id":41419653},{"atb":[[32,8.59],[210,0.63],[55,4.93]],"id":41419628},{"atb":[[5.3,30.97],[3.15,123.9],[3.65,100.52]],"id":41419637},{"atb":[[9.2,32.48],[26,5.32],[13,22.19]],"id":41419616},{"atb":[[700,0.19],[400,0.67],[500,0.53]],"id":41419654},{"atb":[[22,6.34],[11,26.63],[8.4,35.99]],"id":41419633},{"atb":[[19,14.8],[46,2.95],[14,20.49]],"id":41419629},{"atb":[[700,0.19],[400,0.67],[500,0.53]],"id":41419658}],"con":true,"img":false}]}
{"op":"mcm","clk":"5353433796","pt":1646214879854,"mc":[{"id":"1.195503865","rc":[{"atb":[[70,0],[95,0]],"id":41419597},{"atb":[[10.5,0],[13,0]],"id":41419635},{"atb":[[150,0],[100,0]],"id":41419653},{"atb":[[70,0],[48,0]],"id":41419595},{"atb":[[40,0],[50,0]],"id":41419588},{"atb":[[150,0],[200,0]],"id":41419658}],"con":true,"img":false}]}
{"op":"mcm","clk":"5353433803","pt":1646214879956,"mc":[{"id":"1.195503865","rc":[{"atb":[[16,0],[18.5,0]],"id":41419638},{"atb":[[9,0],[10,0]],"id":41419634},{"atb":[[75,0],[100,0]],"id":41419651},{"atb":[[270,0],[220,0]],"id":41419659},{"atb":[[32,0],[42,0]],"id":41419619},{"atb":[[130,0],[180,0]],"id":41419631},{"atb":[[23,0],[28,0]],"id":41419598},{"atb":[[80,0],[55,0]],"id":41419660},{"atb":[[40,0],[30,0]],"id":41419594},{"atb":[[8,0],[9,0]],"id":41419636},{"atb":[[44,0],[60,0]],"id":41435525},{"atb":[[8.6,0],[7.6,0]],"id":41419637},{"atb":[[11,0],[13.5,0]],"id":41419612},{"atb":[[270,0],[220,0]],"id":41419654},{"atb":[[80,0],[110,0]],"id":41419629}],"con":true,"img":false}]}
{"op":"mcm","clk":"5353433807","pt":1646214880063,"mc":[{"id":"1.195503865","rc":[{"atb":[[6,0],[5.9,20.41]],"id":41419612},{"atb":[[36,0],[38,2.7]],"id":41419629}],"con":true,"img":false}]}
{"op":"mcm","clk":"5353433815","pt":1646214880161,"mc":[{"id":"1.195503865","rc":[{"atb":[[150,0],[100,0]],"id":41419618},{"atb":[[24,0],[29,0]],"id":41419640},{"atb":[[17.5,0],[15,0]],"id":41419591}],"con":true,"img":false}]}
{"op":"mcm","clk":"5353433827","pt":1646214880373,"mc":[{"id":"1.195503865","rc":[{"atb":[[16.5,0],[17,6.25]],"id":41419640},{"atb":[[5.7,21.28]],"id":41419591}],"con":true,"img":false}]}
{"op":"mcm","clk":"5353433833","pt":1646214880471,"mc":[{"id":"1.195503865","rc":[{"atb":[[6.2,0]],"id":41419591}],"con":true,"img":false}]}
{"op":"mcm","clk":"5353433836","pt":1646214880573,"mc":[{"id":"1.195503865","rc":[{"atb":[[75,3.26],[100,2.72]],"id":41419597},{"atb":[[11,3.26],[13.5,2.72]],"id":41419635},{"atb":[[160,2.72],[110,3.26]],"id":41419653},{"atb":[[75,2.72],[50,3.26]],"id":41419595},{"atb":[[42,3.26],[55,2.72]],"id":41419588},{"atb":[[160,3.26],[210,2.72]],"id":41419658}],"con":true,"img":false}]}
{"op":"mcm","clk":"5353433840","pt":1646214880678,"mc":[{"id":"1.195503865","rc":[{"atb":[[17,3.26],[19.5,2.72]],"id":41419638},{"atb":[[9.2,3.26],[10.5,2.72]],"id":41419634},{"atb":[[80,3.26],[110,2.72]],"id":41419651},{"atb":[[280,2.72],[230,3.26]],"id":41419659},{"atb":[[34,3.26],[44,2.72]],"id":41419619},{"atb":[[140,3.26],[190,2.72]],"id":41419631},{"atb":[[24,3.26],[29,2.72]],"id":41419598},{"atb":[[85,2.72],[60,3.26]],"id":41419660},{"atb":[[32,3.26],[42,2.72]],"id":41419594},{"atb":[[9.2,2.72],[8.2,3.26]],"id":41419636},{"atb":[[65,2.72],[46,3.26]],"id":41435525},{"atb":[[8.8,2.72],[7.8,3.26]],"id":41419637},{"atb":[[11.5,3.26],[14,2.72]],"id":41419612},{"atb":[[280,2.72],[230,3.26]],"id":41419654},{"atb":[[85,3.26],[120,2.72]],"id":41419629}],"con":true,"img":false}]}
{"op":"mcm","clk":"5353433861","pt":1646214880995,"mc":[{"id":"1.195503865","rc":[{"atb":[[160,2.72],[110,3.26]],"id":41419618},{"atb":[[25,3.26],[30,2.72]],"id":41419640},{"atb":[[18,2.72],[15.5,3.26]],"id":41419591}],"con":true,"img":false}]}
{"op":"mcm","clk":"5353434071","pt":1646214884976,"mc":[{"id":"1.195503865","rc":[{"atl":[[1000,0]],"id":41419651}],"con":true,"img":false}]}
{"op":"mcm","clk":"5353435093","pt":1646214905418,"mc":[{"id":"1.195503865","rc":[{"atl":[[1000,2]],"id":41419651}],"con":true,"img":false}]}
{"op":"mcm","clk":"5353435459","pt":1646214911926,"mc":[{"id":"1.195503865","rc":[{"atl":[[1000,0]],"id":41419651}],"con":true,"img":false}]}
{"op":"mcm","clk":"5353436550","pt":1646214932362,"mc":[{"id":"1.195503865","rc":[{"atl":[[1000,2]],"id":41419651}],"con":true,"img":false}]}
{"op":"mcm","clk":"5353436660","pt":1646214934737,"mc":[{"id":"1.195503865","rc":[{"atb":[[32,0],[42,0]],"id":41419609}],"con":true,"img":false}]}
{"op":"mcm","clk":"5353436676","pt":1646214935051,"mc":[{"id":"1.195503865","rc":[{"atb":[[85,0],[120,0]],"id":41419627},{"atb":[[24,0],[29,0]],"id":41419587},{"atb":[[75,0],[50,0]],"id":41419633}],"con":true,"img":false}]}
{"op":"mcm","clk":"5353436683","pt":1646214935154,"mc":[{"id":"1.195503865","rc":[{"atb":[[36,2.86],[29,0]],"id":41419627}],"con":true,"img":false}]}
{"op":"mcm","clk":"5353436704","pt":1646214935464,"mc":[{"id":"1.195503865","rc":[{"atb":[[34,3.26],[44,2.72]],"id":41419609}],"con":true,"img":false}]}
{"op":"mcm","clk":"5353436785","pt":1646214935773,"mc":[{"id":"1.195503865","rc":[{"atb":[[130,2.72],[90,3.26]],"id":41419627},{"atb":[[25,3.26],[30,2.72]],"id":41419587},{"atb":[[80,2.72],[55,3.26]],"id":41419633}],"con":true,"img":false}]}
{"op":"mcm","clk":"5353437155","pt":1646214940259,"mc":[{"id":"1.195503865","rc":[{"atl":[[280,2],[310,0]],"id":41419634},{"atb":[[3.6,0],[14,6.56]],"id":41435527},{"atb":[[3.6,0],[14,2]],"id":41419659},{"atb":[[6.8,16.14],[1.71,0]],"id":41419585},{"atb":[[3.6,0],[14,6.54]],"id":41419656},{"atb":[[7.6,12.2],[28,0]],"id":41419590},{"atb":[[3.6,0],[14,7.69]],"id":41419660},{"atb":[[36,0],[7.6,6.13]],"id":41419627},{"atb":[[17,0],[7.6,15.15]],"id":41419640},{"atb":[[3.6,0],[14,6.54]],"id":28546950},{"atb":[[3.6,0],[14,28.18]],"id":41419657},{"atb":[[4.8,26.32],[1.71,0]],"id":41419637},{"atb":[[36,0],[7.6,9.61]],"id":41419633},{"atb":[[3.6,0],[14,2]],"id":41419658}],"con":true,"img":false}]}
{"op":"mcm","clk":"5353437297","pt":1646214942590,"mc":[{"id":"1.195503865","rc":[{"atl":[[1000,0]],"id":41419651}],"con":true,"img":false}]}
{"op":"mcm","clk":"5353437555","pt":1646214947505,"mc":[{"id":"1.195503865","rc":[{"atl":[[660,0],[650,2]],"id":41419609},{"atl":[[280,0],[290,2]],"id":41419634},{"atl":[[1000,2]],"id":41419651},{"atl":[[1000,0]],"id":41419590},{"atl":[[780,0],[770,2]],"id":41419619}],"con":true,"img":false}]}
{"op":"mcm","clk":"5353437558","pt":1646214947560,"mc":[{"id":"1.195503865","rc":[{"atl":[[510,0],[500,2]],"id":41419638}],"con":true,"img":false}]}
{"op":"mcm","clk":"5353437576","pt":1646214947870,"mc":[{"id":"1.195503865","rc":[{"atb":[[34,0],[27,0]],"id":41419592}],"con":true,"img":false}]}
{"op":"mcm","clk":"5353437595","pt":1646214948180,"mc":[{"id":"1.195503865","rc":[{"atb":[[34,0],[27,0]],"id":41419607}],"con":true,"img":false}]}
{"op":"mcm","clk":"5353437626","pt":1646214948797,"mc":[{"id":"1.195503865","rc":[{"atb":[[36,2.72],[28,3.26]],"id":41419592}],"con":true,"img":false}]}
{"op":"mcm","clk":"5353437649","pt":1646214949164,"mc":[{"id":"1.195503865","rc":[{"atb":[[34,2.72],[27,3.26]],"id":41419607}],"con":true,"img":false}]}
{"op":"mcm","clk":"5353437694","pt":1646214949994,"mc":[{"id":"1.195503865","rc":[{"atb":[[12,0],[14.5,0]],"id":41419605},{"atb":[[32,0],[42,0]],"id":41419593},{"atb":[[20,0],[25,0]],"id":41419601},{"atb":[[34,0],[44,0]],"id":41419602},{"atb":[[85,0],[60,0]],"id":41419614},{"atb":[[70,0],[48,2.83]],"id":41419590},{"atb":[[65,0],[46,0]],"id":41419652},{"atb":[[65,0],[46,0]],"id":41419615},{"atb":[[85,0],[120,0]],"id":41419657},{"atb":[[34,0],[27,0]],"id":41419600}],"con":true,"img":false}]}
{"op":"mcm","clk":"5353437699","pt":1646214950089,"mc":[{"id":"1.195503865","rc":[{"atb":[[19.5,0],[24,0]],"id":41419608}],"con":true,"img":false}]}
{"op":"mcm","clk":"5353437705","pt":1646214950193,"mc":[{"id":"1.195503865","rc":[{"atb":[[18,5.88],[20,0]],"id":41419615}],"con":true,"img":false}]}
{"op":"mcm","clk":"5353437726","pt":1646214950704,"mc":[{"id":"1.195503865","rc":[{"atb":[[12.5,3.26],[15,2.72]],"id":41419605},{"atb":[[34,3.26],[44,2.72]],"id":41419593},{"atb":[[75,2.72],[50,3.26]],"id":41419590},{"atb":[[70,2.72],[48,3.26]],"id":41419652},{"atb":[[70,2.72],[48,3.26]],"id":41419615},{"atb":[[36,2.72],[28,3.26]],"id":41419600}],"con":true,"img":false}]}
{"op":"mcm","clk":"5353437730","pt":1646214950808,"mc":[{"id":"1.195503865","rc":[{"atb":[[21,3.26],[26,2.72]],"id":41419601},{"atb":[[36,3.26],[46,2.72]],"id":41419602},{"atb":[[65,3.26],[90,2.72]],"id":41419614},{"atb":[[130,2.72],[90,3.26]],"id":41419657},{"atb":[[20,3.26],[25,2.72]],"id":41419608}],"con":true,"img":false}]}
{"op":"mcm","clk":"5353437781","pt":1646214951583,"mc":[{"id":"1.195503865","rc":[{"atb":[[65,0],[90,0]],"id":41419614}],"con":true,"img":false}]}
{"op":"mcm","clk":"5353437813","pt":1646214952308,"mc":[{"id":"1.195503865","rc":[{"atb":[[85,2.72],[60,3.26]],"id":41419614}],"con":true,"img":false}]}
{"op":"mcm","clk":"5353437859","pt":1646214953189,"mc":[{"id":"1.195503865","rc":[{"atb":[[34,0],[27,0]],"id":41419607}],"con":true,"img":false}]}
{"op":"mcm","clk":"5353437894","pt":1646214953861,"mc":[{"id":"1.195503865","rc":[{"atb":[[32,2.72],[26,3.26]],"id":41419607}],"con":true,"img":false}]}
{"op":"mcm","clk":"5353438019","pt":1646214956386,"mc":[{"id":"1.195503865","rc":[{"atb":[[34,0]],"id":41419593}],"con":true,"img":false}]}
{"op":"mcm","clk":"5353438038","pt":1646214956797,"mc":[{"id":"1.195503865","rc":[{"atb":[[44,0]],"id":41419593},{"atb":[[20,0],[25,0]],"id":41419608},{"atb":[[36,0],[28,0]],"id":41419600}],"con":true,"img":false}]}
{"op":"mcm","clk":"5353438058","pt":1646214957116,"mc":[{"id":"1.195503865","rc":[{"atb":[[32,3.26]],"id":41419593}],"con":true,"img":false}]}
{"op":"mcm","clk":"5353438083","pt":1646214957471,"mc":[{"id":"1.195503865","rc":[{"atb":[[20,3.26]],"id":41419608}],"con":true,"img":false}]}
{"op":"mcm","clk":"5353438098","pt":1646214957779,"mc":[{"id":"1.195503865","rc":[{"atb":[[25,2.72]],"id":41419608},{"atb":[[36,2.72],[28,3.26]],"id":41419600}],"con":true,"img":false}]}
{"op":"mcm","clk":"5353438102","pt":1646214957883,"mc":[{"id":"1.195503865","rc":[{"atb":[[44,2.72]],"id":41419593}],"con":true,"img":false}]}
{"op":"mcm","clk":"5353438304","pt":1646214961407,"mc":[{"id":"1.195503865","rc":[{"atl":[[280,2],[290,0]],"id":41419634},{"atl":[[730,0],[720,2]],"id":41419655},{"atl":[[1000,0]],"id":41419651},{"atl":[[1000,2]],"id":41419590}],"con":true,"img":false}]}
{"op":"mcm","clk":"5353438329","pt":1646214961769,"mc":[{"id":"1.195503865","rc":[{"atb":[[32,0],[26,0]],"id":41419607}],"con":true,"img":false}]}
{"op":"mcm","clk":"5353438375","pt":1646214962598,"mc":[{"id":"1.195503865","rc":[{"atb":[[34,2.72],[27,3.26]],"id":41419607}],"con":true,"img":false}]}
{"op":"mcm","clk":"5353438418","pt":1646214963370,"mc":[{"id":"1.195503865","rc":[{"atb":[[20,0]],"id":41419608}],"con":true,"img":false}]}
{"op":"mcm","clk":"5353438440","pt":1646214963684,"mc":[{"id":"1.195503865","rc":[{"atb":[[44,0]],"id":41419593},{"atb":[[25,0]],"id":41419608},{"atb":[[36,0],[28,0]],"id":41419600}],"con":true,"img":false}]}
{"op":"mcm","clk":"5353438473","pt":1646214964300,"mc":[{"id":"1.195503865","rc":[{"atb":[[19.5,3.26]],"id":41419608}],"con":true,"img":false}]}
{"op":"mcm","clk":"5353438492","pt":1646214964714,"mc":[{"id":"1.195503865","rc":[{"atb":[[42,2.72]],"id":41419593},{"atb":[[24,2.72]],"id":41419608},{"atb":[[34,2.72],[27,3.26]],"id":41419600}],"con":true,"img":false}]}
{"op":"mcm","clk":"5353438597","pt":1646214966673,"mc":[{"id":"1.195503865","rc":[{"atb":[[280,0],[230,0]],"id":41419659},{"atb":[[8.8,0],[7.8,0]],"id":41419637}],"con":true,"img":false}]}
{"op":"mcm","clk":"5353438621","pt":1646214967296,"mc":[{"id":"1.195503865","rc":[{"atl":[[1000,0]],"id":41419590}],"con":true,"img":false}]}
{"op":"mcm","clk":"5353438641","pt":1646214967710,"mc":[{"id":"1.195503865","rc":[{"atb":[[290,2.72],[240,3.26]],"id":41419659},{"atb":[[8,3.26],[9,2.72]],"id":41419637}],"con":true,"img":false}]}
{"op":"mcm","clk":"5353438874","pt":1646214973231,"mc":[{"id":"1.195503865","rc":[{"atl":[[650,0],[640,2]],"id":41419609},{"atl":[[1000,2]],"id":41419590}],"con":true,"img":false}]}
{"op":"mcm","clk":"5353441668","pt":1646215027679,"mc":[{"id":"1.195503865","rc":[{"atb":[[36,0]],"id":41419592}],"con":true,"img":false}]}
{"op":"mcm","clk":"5353441682","pt":1646215027990,"mc":[{"id":"1.195503865","rc":[{"atb":[[28,0]],"id":41419592}],"con":true,"img":false}]}
{"op":"mcm","clk":"5353441703","pt":1646215028353,"mc":[{"id":"1.195503865","rc":[{"atb":[[38,2.72]],"id":41419592}],"con":true,"img":false}]}
{"op":"mcm","clk":"5353441719","pt":1646215028661,"mc":[{"id":"1.195503865","rc":[{"atb":[[29,3.26]],"id":41419592}],"con":true,"img":false}]}
{"op":"mcm","clk":"5353444311","pt":1646215077685,"mc":[{"id":"1.195503865","rc":[{"atb":[[24,0],[12,0],[8.8,0]],"id":41419609},{"atb":[[5.5,0],[12.5,0],[7,0]],"id":41419638},{"atb":[[5.8,0],[3.4,0],[3.9,0]],"id":41419605},{"atb":[[5.5,0],[3.25,0],[3.75,0]],"id":41419634},{"atb":[[27,0],[13.5,0],[9.4,0]],"id":41419613},{"atb":[[16.5,0],[8.6,0],[6.6,0]],"id":41419593},{"atb":[[7.2,0],[18,0],[9.2,0]],"id":41419655},{"atb":[[20,0],[50,0],[15,0]],"id":41435527},{"atb":[[180,0],[46,0],[28,3.7]],"id":41419651},{"atb":[[700,0],[400,0],[500,0]],"id":41419618},{"atb":[[5.3,0],[11.5,0],[6.6,0]],"id":41419601},{"atb":[[20,0],[50,0],[15,0]],"id":41419630},{"atb":[[180,0],[46,0],[28,0]],"id":41419597},{"atb":[[19.5,0],[48,0],[14.5,0]],"id":28546943},{"atb":[[700,0],[400,0],[500,0]],"id":41419659},{"atb":[[5.6,0],[7.2,0],[13,0]],"id":41419606},{"atb":[[4.8,0],[7.6,0],[3.9,0]],"id":41419635},{"atb":[[8.6,0],[23,0],[11.5,9.52]],"id":41419602},{"atb":[[17.5,0],[9,0],[7,0]],"id":41419585},{"atb":[[18.5,0],[44,0],[13.5,0]],"id":41419614},{"atb":[[32,0],[210,0],[55,0]],"id":41419656},{"atb":[[19.5,0],[48,0],[14.5,0]],"id":41419590},{"atb":[[17,0],[38,0],[12,0]],"id":41419652},{"atb":[[16.5,0],[8.6,0],[6.6,0]],"id":41419619},{"atb":[[5.5,0],[12.5,0],[7,0]],"id":41419586},{"atb":[[700,0],[400,0],[500,0]],"id":41419631},{"atb":[[9.6,0],[4.8,0],[5.8,0]],"id":41419598},{"atb":[[22,0],[11,0],[8.4,0]],"id":41419660},{"atb":[[65,0],[16.5,0],[23,0]],"id":41419627},{"atb":[[17,0],[6.8,0],[8.8,0]],"id":41419594},{"atb":[[7.2,0],[18,0],[9.2,0]],"id":41419640},{"atb":[[16.5,0],[8.6,0],[6.6,0]],"id":41419607},{"atb":[[65,0],[16.5,0],[23,0]],"id":28546950},{"atb":[[5.1,0],[3.55,0],[3.05,0]],"id":41419636},{"atb":[[9,0],[25,0],[12.5,0]],"id":41419615},{"atb":[[18,0],[42,0],[13,0]],"id":41419611},{"atb":[[19,0],[46,0],[14,7.69]],"id":41419657},{"atb":[[3.7,0],[6.8,0],[4.4,0]],"id":41419591},{"atb":[[18,0],[42,0],[13,0]],"id":41435525},{"atb":[[700,0],[400,0],[500,0]],"id":41419653},{"atb":[[5.6,0],[7.2,0],[13,0]],"id":41419587},{"atb":[[12,0],[6.8,0],[5.4,0]],"id":41419599},{"atb":[[32,0],[210,0],[55,0]],"id":41419628},{"atb":[[17.5,0],[40,0],[12.5,0]],"id":41419595},{"atb":[[5.3,0],[11.5,0],[6.6,0]],"id":41419608},{"atb":[[5.3,0],[3.15,0],[3.65,0]],"id":41419637},{"atb":[[17,0],[38,0],[12,0]],"id":41419604},{"atb":[[9.2,0],[26,0],[13,0]],"id":41419616},{"atb":[[6.2,0],[4.1,0],[3.55,0]],"id":41419612},{"atb":[[7.2,16.13],[18,0],[9.2,0]],"id":41419592},{"atb":[[700,0],[400,0],[500,0]],"id":41419654},{"atb":[[9.2,0],[26,0],[13,0]],"id":41419588},{"atb":[[22,0],[11,0],[8.4,0]],"id":41419633},{"atb":[[16,0],[6.4,0],[8.4,0]],"id":41419600},{"atb":[[19,0],[46,0],[14,0]],"id":41419629},{"atb":[[700,0],[400,0],[500,0]],"id":41419658}],"con":true,"img":false}]}
{"op":"mcm","clk":"5353444493","pt":1646215081140,"mc":[{"id":"1.195503865","rc":[{"atl":[[510,0.31]],"id":41419585},{"atb":[[14,16.26]],"id":41419656},{"atb":[[8,23.19]],"id":41419598},{"atl":[[570,2.15]],"id":41419598},{"atb":[[9.2,8.9]],"id":41419637},{"atl":[[380,0.41]],"id":41419637},{"atb":[[38,10.78]],"id":41419629}],"con":true,"img":false}]}
{"op":"mcm","clk":"5353444503","pt":1646215081291,"mc":[{"id":"1.195503865","rc":[{"atb":[[10,17.42],[26,9.9],[30,4.95]],"id":41419609},{"atl":[[630,0.25],[660,1.85],[95,4.95]],"id":41419609},{"atb":[[16,4.95],[6.6,26.76],[14,9.9]],"id":41419638},{"atl":[[520,2.36],[34,4.95],[42,9.9],[490,0.32]],"id":41419638},{"atb":[[17.5,4.95],[6.8,26.14],[15.5,9.9]],"id":41419605},{"atl":[[38,4.95],[46,9.9],[480,2.56]],"id":41419605},{"atb":[[4,42.23],[8,9.9],[8.8,4.95]],"id":41419634},{"atl":[[270,0.58],[300,4.1],[13,4.95],[15,9.9]],"id":41419634},{"atb":[[16.5,15.35],[44,9.9],[55,4.95]],"id":41419613},{"atl":[[200,4.95],[800,0.19],[830,1.47]],"id":41419613},{"atb":[[21,9.9],[25,4.95],[8.4,22.41]],"id":41419593},{"atl":[[570,0.27],[75,4.95],[600,2.04],[95,9.9]],"id":41419593},{"atb":[[32,12.63],[34,4.8],[10,20.01],[40,4.95]],"id":41419655},{"atl":[[80,4.95],[710,0.22],[740,1.65],[100,9.9]],"id":41419655},{"atb":[[160,4.95],[14,16.28],[120,12.63]],"id":41435527},{"atb":[[85,9.9],[110,7.67],[28,13.42],[120,1.32]],"id":41419651},{"atl":[[1000,0.15]],"id":41419651},{"atb":[[160,7.67],[40,10.08],[170,0.93],[120,9.9]],"id":41419618},{"atl":[[1000,0.15]],"id":41419618},{"atb":[[21,13.17],[25,4.95],[26,9.06],[7.8,23.61]],"id":41419601},{"atl":[[70,9.9],[550,0.28],[580,2.12],[50,4.95]],"id":41419601},{"atb":[[38,10.78],[160,4.95],[120,11.23]],"id":41419630},{"atl":[[1000,0.15]],"id":41419630},{"atb":[[36,11.36],[150,4.95],[110,11.36]],"id":41419597},{"atl":[[1000,0.15]],"id":41419597},{"atb":[[80,2],[85,9.9],[110,4.95],[28,12.6]],"id":28546943},{"atl":[[930,0.16],[960,1.27]],"id":28546943},{"atb":[[300,0.52],[160,4.95],[14,10.08],[120,9.9]],"id":41419659},{"atb":[[17.5,4.95],[6,28.9],[15.5,9.9]],"id":41419606},{"atl":[[46,4.95],[470,0.33],[60,9.9],[500,2.45]],"id":41419606},{"atb":[[9.6,9.9],[11,8.22],[4.4,38.31]],"id":41419635},{"atl":[[19.5,4.95],[23,9.9],[390,0.4],[420,2.92]],"id":41419635},{"atb":[[38,9.9],[46,11.19],[11.5,18.42]],"id":41419602},{"atl":[[95,4.95],[740,0.21],[770,1.59]],"id":41419602},{"atb":[[18,9.9],[20,4.95],[6.8,25.04]],"id":41419585},{"atl":[[540,2.27],[75,4.95],[95,9.9]],"id":41419585},{"atb":[[65,4.95],[19,14.46],[48,9.9]],"id":41419614},{"atl":[[830,0.19],[860,1.42]],"id":41419614},{"atb":[[130,4.95],[160,3.72],[95,9.9]],"id":41419656},{"atl":[[1000,0.15]],"id":41419656},{"atb":[[80,2],[7.6,21.1]],"id":41419590},{"atl":[[990,0.15]],"id":41419590},{"atb":[[34,11.57],[75,2.14],[90,9.9],[120,4.95]],"id":41419652},{"atl":[[990,0.15]],"id":41419652},{"atb":[[40,9.9],[44,6.41],[48,4.95],[13,17.23]],"id":41419619},{"atl":[[95,4.95],[760,0.2],[790,1.55]],"id":41419619},{"atb":[[16.5,9.9],[18.5,4.95],[6.4,27.42]],"id":41419586},{"atl":[[530,2.31],[70,9.9],[50,4.95],[500,0.31]],"id":41419586},{"atb":[[40,10.08],[160,4.95],[200,0.79],[120,9.9]],"id":41419631},{"atl":[[1000,0.15]],"id":41419631},{"atb":[[20,9.9],[24,8.22]],"id":41419598},{"atl":[[65,9.9],[540,0.29],[570,4.15],[48,4.95]],"id":41419598},{"atb":[[90,11.69],[14,16.59],[120,4.95]],"id":41419660},{"atl":[[990,0.15]],"id":41419660},{"atb":[[140,1.13],[160,4.95],[7.6,15.85],[120,9.9]],"id":41419627},{"atl":[[1000,0.15]],"id":41419627},{"atb":[[34,4.95],[28,9.9],[9.4,20.8]],"id":41419594},{"atl":[[610,0.26],[640,1.91],[85,4.95],[110,9.9]],"id":41419594},{"atb":[[32,5.11],[38,4.95],[7.6,24.05],[30,12.63]],"id":41419640},{"atl":[[760,0.2],[790,1.55],[120,4.95]],"id":41419640},{"atb":[[18.5,9.9],[21,4.95],[7.4,23.7]],"id":41419607},{"atl":[[520,0.3],[550,2.23],[80,9.9],[60,4.95]],"id":41419607},{"atb":[[130,3.95],[85,9.9],[110,4.95],[14,15.44]],"id":28546950},{"atl":[[990,0.15]],"id":28546950},{"atb":[[4.3,39.2],[9.2,21.53],[10,4.95]],"id":41419636},{"atl":[[17.5,4.95],[19.5,9.9],[320,0.49],[350,3.51]],"id":41419636},{"atb":[[65,4.95],[70,5.02],[18,14.78],[48,13.17]],"id":41419615},{"atl":[[170,4.95],[840,0.19],[870,1.4]],"id":41419615},{"atb":[[34,11.57],[90,9.9],[120,4.95]],"id":41419611},{"atb":[[140,1.13],[150,4.95],[110,9.9],[14,17.41]],"id":41419657},{"atl":[[1000,0.15]],"id":41419657},{"atb":[[17.5,4.95],[18,11.63],[5.7,30.18],[15.5,13.17]],"id":41419591},{"atl":[[34,4.95],[42,9.9],[470,0.33],[500,2.45]],"id":41419591},{"atb":[[34,11.57],[70,2.29],[90,9.9],[120,4.95]],"id":41435525},{"atl":[[220,4.95],[990,0.15]],"id":41435525},{"atb":[[38,10.08],[160,7.67],[170,0.93],[120,9.9]],"id":41419653},{"atl":[[1000,0.15]],"id":41419653},{"atb":[[8,23.19],[20,9.9],[24,4.95]],"id":41419587},{"atl":[[540,0.29],[70,9.9],[570,2.15],[50,4.95]],"id":41419587},{"atb":[[18,9.9],[20,4.95],[6,28.9]],"id":41419599},{"atl":[[530,2.31],[44,4.95],[55,9.9],[500,0.31]],"id":41419599},{"atb":[[38,10.78],[160,5.95],[120,9.9]],"id":41419628},{"atl":[[1000,0.15]],"id":41419628},{"atb":[[42,9.9],[50,8.22],[13.5,16.9]],"id":41419595},{"atl":[[180,4.95],[790,0.2],[820,1.49]],"id":41419595},{"atb":[[17,4.95],[6.2,28.13],[15,9.9]],"id":41419608},{"atl":[[530,2.31],[38,4.95],[46,9.9],[500,0.31]],"id":41419608},{"atb":[[4.8,35.22],[9.2,18.81],[10,4.95]],"id":41419637},{"atl":[[23,4.95],[410,2.99],[27,9.9]],"id":41419637},{"atb":[[130,4.95],[34,12.03],[70,2.29],[95,9.9]],"id":41419604},{"atl":[[1000,0.15]],"id":41419604},{"atb":[[21,13.9]],"id":41419616},{"atl":[[880,1.38]],"id":41419616},{"atb":[[13.5,9.9],[14,11.63],[5.9,29.31],[15.5,4.95]],"id":41419612},{"atl":[[32,4.95],[40,9.9],[420,0.37],[450,2.73]],"id":41419612},{"atb":[[7.2,25.03],[19,9.9],[22,4.95]],"id":41419592},{"atl":[[520,0.3],[550,2.23],[85,4.95],[110,9.9]],"id":41419592},{"atb":[[290,0.55],[40,10.08],[160,4.95],[120,9.9]],"id":41419654},{"atb":[[9.6,20.53],[36,4.95],[29,9.9]],"id":41419588},{"atl":[[700,0.22],[730,1.67],[120,4.95]],"id":41419588},{"atb":[[160,4.95],[85,1.88],[7.6,19.33],[120,9.9]],"id":41419633},{"atl":[[1000,0.15]],"id":41419633},{"atb":[[19,9.9],[22,4.95],[7.6,24.05]],"id":41419600},{"atl":[[540,0.29],[570,2.15],[75,9.9],[55,4.95]],"id":41419600},{"atb":[[130,1.23],[150,4.95],[110,9.9]],"id":41419629},{"atl":[[1000,0.15]],"id":41419629},{"atb":[[160,8.22],[210,3.48],[14,10.08],[120,9.9]],"id":41419658}],"con":true,"img":false}]}
{"op":"mcm","clk":"5353444509","pt":1646215081342,"mc":[{"id":"1.195503865","rc":[{"atl":[[550,0]],"id":41419598},{"atb":[[70,4.95],[50,9.9]],"id":41419616},{"atl":[[180,4.95]],"id":41419616}],"con":true,"img":false}]}
{"op":"mcm","clk":"5353444512","pt":1646215081447,"mc":[{"id":"1.195503865","rc":[{"atl":[[640,0],[240,2]],"id":41419609},{"atl":[[100,2],[500,0]],"id":41419638},{"atl":[[460,0],[120,2]],"id":41419605},{"atl":[[280,0],[29,3.57]],"id":41419634},{"atl":[[810,0],[410,2]],"id":41419613},{"atl":[[580,0],[200,2]],"id":41419593},{"atl":[[320,2],[720,0]],"id":41419655},{"atl":[[560,0],[180,2]],"id":41419601},{"atl":[[940,0],[950,2]],"id":28546943},{"atl":[[95,2],[480,0]],"id":41419606},{"atl":[[400,0],[55,2]],"id":41419635},{"atl":[[360,2],[750,0]],"id":41419602},{"atl":[[520,0],[130,2]],"id":41419585},{"atl":[[840,0],[850,2]],"id":41419614},{"atl":[[370,2],[770,0]],"id":41419619},{"atl":[[120,2],[510,0]],"id":41419586},{"atl":[[620,0],[310,2]],"id":41419594},{"atl":[[770,0],[440,2]],"id":41419640},{"atl":[[530,0],[140,2]],"id":41419607},{"atl":[[330,0],[44,2.33]],"id":41419636},{"atl":[[850,0],[460,2]],"id":41419615},{"atl":[[100,2],[480,0]],"id":41419591},{"atl":[[680,2],[1000,0]],"id":41435525},{"atl":[[550,0],[180,2]],"id":41419587},{"atl":[[110,2],[510,0]],"id":41419599},{"atl":[[800,0],[410,2]],"id":41419595},{"atl":[[110,2],[510,0]],"id":41419608},{"atl":[[70,2],[390,0]],"id":41419637},{"atb":[[65,5.2]],"id":41419616},{"atl":[[860,0],[850,0.18],[880,3.38]],"id":41419616},{"atl":[[95,2],[430,0]],"id":41419612},{"atl":[[530,0],[160,2]],"id":41419592},{"atl":[[330,2],[710,0]],"id":41419588},{"atl":[[550,0],[160,2]],"id":41419600}],"con":true,"img":false}]}
{"op":"mcm","clk":"5353444526","pt":1646215081653,"mc":[{"id":"1.195503865","rc":[{"atl":[[840,2.19]],"id":41419615},{"atl":[[880,1.38],[490,2]],"id":41419616}],"con":true,"img":false}]}
{"op":"mcm","clk":"5353444533","pt":1646215081757,"mc":[{"id":"1.195503865","rc":[{"atl":[[630,2.25],[240,0]],"id":41419609},{"atl":[[410,0],[800,2.19]],"id":41419613},{"atl":[[360,0],[740,2.21]],"id":41419602},{"atl":[[370,0],[760,2.2]],"id":41419619},{"atl":[[760,2.2]],"id":41419640},{"atl":[[460,0]],"id":41419615},{"atl":[[680,0],[990,2.15]],"id":41435525},{"atl":[[790,2.2],[410,0]],"id":41419595},{"atl":[[330,0],[700,2.22]],"id":41419588}],"con":true,"img":false}]}
{"op":"mcm","clk":"5353444540","pt":1646215081860,"mc":[{"id":"1.195503865","rc":[{"atl":[[440,0]],"id":41419640},{"atl":[[1000,1.22]],"id":41435525}],"con":true,"img":false}]}
{"op":"mcm","clk":"5353444552","pt":1646215082068,"mc":[{"id":"1.195503865","rc":[{"atb":[[15.5,18.81]],"id":41419605},{"atl":[[450,0.35]],"id":41419605},{"atb":[[130,1.23]],"id":41435527},{"atl":[[1000,0.15]],"id":41435527},{"atb":[[85,9.9],[110,4.95]],"id":41419590},{"atb":[[65,2.47]],"id":41419611},{"atl":[[990,0.15]],"id":41419611}],"con":true,"img":false}]}
{"op":"mcm","clk":"5353444559","pt":1646215082174,"mc":[{"id":"1.195503865","rc":[{"atb":[[5.5,59.19],[12.5,11.58],[7,44.4]],"id":41419638},{"atb":[[5.5,29.59],[3.25,118.39],[3.75,96.87]],"id":41419634},{"atb":[[27,5.12],[13.5,21.3],[9.4,31.71]],"id":41419613},{"atb":[[7.2,42.96],[18,7.83],[9.2,32.48]],"id":41419655},{"atb":[[20,14.02],[50,2.71],[15,19.02]],"id":41435527},{"atb":[[700,0.19],[400,0.67],[500,0.53]],"id":41419618},{"atb":[[20,14.02],[50,2.71],[15,19.02]],"id":41419630},{"atb":[[700,0.19],[400,0.67],[500,0.53]],"id":41419659},{"atb":[[4.8,70.1],[7.6,20.18],[3.9,91.85]],"id":41419635},{"atb":[[18.5,15.22],[44,3.09],[13.5,21.3]],"id":41419614},{"atb":[[32,8.59],[210,0.63],[55,4.93]],"id":41419656},{"atb":[[16.5,8.59],[8.6,35.05],[6.6,47.57]],"id":41419619},{"atb":[[700,0.19],[400,0.67],[500,0.53]],"id":41419631},{"atb":[[22,6.34],[11,26.63],[8.4,35.99]],"id":41419660},{"atb":[[65,2.08],[16.5,17.18],[23,12.1]],"id":41419627},{"atb":[[7.2,42.96],[18,7.83],[9.2,32.48]],"id":41419640},{"atb":[[65,2.08],[16.5,17.18],[23,12.1]],"id":28546950},{"atb":[[5.1,32.48],[3.55,104.46],[3.05,129.94]],"id":41419636},{"atb":[[9,33.29],[25,5.54],[12.5,23.16]],"id":41419615},{"atb":[[19,14.8],[46,2.95],[14,37.9]],"id":41419657},{"atb":[[700,0.19],[400,0.67],[500,0.53]],"id":41419653},{"atb":[[32,8.59],[210,0.63],[55,4.93]],"id":41419628},{"atb":[[5.3,30.97],[3.15,123.9],[3.65,100.52]],"id":41419637},{"atb":[[9.2,32.48],[26,5.32],[13,22.19]],"id":41419616},{"atb":[[700,0.19],[400,0.67],[500,0.53]],"id":41419654},{"atb":[[22,6.34],[11,26.63],[8.4,35.99]],"id":41419633},{"atb":[[19,14.8],[46,2.95],[14,20.49]],"id":41419629},{"atb":[[700,0.19],[400,0.67],[500,0.53]],"id":41419658}],"con":true,"img":false}]}
{"op":"mcm","clk":"5353444565","pt":1646215082278,"mc":[{"id":"1.195503865","rc":[{"atb":[[24,5.79],[12,24.21],[8.8,34.15]],"id":41419609},{"atb":[[5.8,27.75],[3.4,110.99],[3.9,91.85]],"id":41419605},{"atb":[[16.5,8.59],[8.6,35.05],[6.6,47.57]],"id":41419593},{"atb":[[180,0.74],[46,5.91],[28,23.28]],"id":41419651},{"atb":[[5.3,61.94],[11.5,12.68],[6.6,47.57]],"id":41419601},{"atb":[[180,0.74],[46,5.91],[28,9.86]],"id":41419597},{"atb":[[19.5,14.39],[48,2.83],[14.5,19.73]],"id":28546943},{"atb":[[5.6,57.91],[7.2,42.96],[13,11.1]],"id":41419606},{"atb":[[8.6,35.05],[11.5,43.79],[23,6.05]],"id":41419602},{"atb":[[17.5,8.07],[9,33.29],[7,44.4]],"id":41419585},{"atb":[[19.5,14.39],[48,2.83],[14.5,19.73]],"id":41419590},{"atb":[[17,16.64],[38,3.6],[12,24.21]],"id":41419652},{"atb":[[5.5,59.19],[12.5,11.58],[7,44.4]],"id":41419586},{"atb":[[9.6,15.48],[4.8,70.1],[5.8,55.49]],"id":41419598},{"atb":[[17,8.32],[6.8,45.93],[8.8,34.15]],"id":41419594},{"atb":[[16.5,8.59],[8.6,35.05],[6.6,47.57]],"id":41419607},{"atb":[[18,15.66],[42,3.24],[13,22.19]],"id":41419611},{"atb":[[3.7,98.66],[6.8,22.96],[4.4,78.34]],"id":41419591},{"atb":[[18,15.66],[42,3.24],[13,22.19]],"id":41435525},{"atb":[[5.6,57.91],[7.2,42.96],[13,11.1]],"id":41419587},{"atb":[[12,12.1],[6.8,45.93],[5.4,60.54]],"id":41419599},{"atb":[[17.5,16.14],[40,3.41],[12.5,23.16]],"id":41419595},{"atb":[[5.3,61.94],[11.5,12.68],[6.6,47.57]],"id":41419608},{"atb":[[17,16.64],[38,3.6],[12,24.21]],"id":41419604},{"atb":[[6.2,25.61],[4.1,85.93],[3.55,104.46]],"id":41419612},{"atb":[[7.2,68],[18,7.83],[9.2,32.48]],"id":41419592},{"atb":[[9.2,32.48],[26,5.32],[13,22.19]],"id":41419588},{"atb":[[16,8.87],[6.4,49.33],[8.4,35.99]],"id":41419600}],"con":true,"img":false}]}
{"op":"mcm","clk":"5353444572","pt":1646215082338,"mc":[{"id":"1.195503865","rc":[{"atl":[[850,0],[860,3.42]],"id":41419614}],"con":true,"img":false}]}
{"op":"mcm","clk":"5353444581","pt":1646215082441,"mc":[{"id":"1.195503865","rc":[{"atl":[[950,0],[960,3.27]],"id":28546943}],"con":true,"img":false}]}
{"op":"mcm","clk":"5353444600","pt":1646215082644,"mc":[{"id":"1.195503865","rc":[{"atb":[[14,2]],"id":41419658}],"con":true,"img":false}]}
{"op":"mcm","clk":"5353444620","pt":1646215082847,"mc":[{"id":"1.195503865","rc":[{"atb":[[40,2]],"id":41419618},{"atl":[[1000,0]],"id":41419618},{"atl":[[250,4.95]],"id":28546943},{"atb":[[40,2]],"id":41419654}],"con":true,"img":false}]}
{"op":"mcm","clk":"5353444625","pt":1646215082953,"mc":[{"id":"1.195503865","rc":[{"atb":[[8,14.29]],"id":41419638},{"atb":[[4,8.9],[5.5,51.81]],"id":41419634},{"atb":[[16.5,8.9],[21,5]],"id":41419613},{"atb":[[11.5,9.52],[8.4,8.9]],"id":41419593},{"atb":[[10,8.9],[14,7.69]],"id":41419655},{"atb":[[50,2.04],[28,19.58]],"id":41419651},{"atb":[[40,0],[55,2]],"id":41419618},{"atb":[[11,10],[7.8,8.9]],"id":41419601},{"atb":[[38,8.08],[55,2]],"id":41419630},{"atb":[[36,8.5],[50,2.04]],"id":41419597},{"atb":[[44,2.33],[28,8.9]],"id":28546943},{"atl":[[560,2]],"id":28546943},{"atb":[[14,2]],"id":41419659},{"atb":[[6,8.9],[7.6,15.15]],"id":41419606},{"atb":[[5.8,20.83],[4.4,8.9]],"id":41419635},{"atb":[[16,6.67],[11.5,34.27]],"id":41419602},{"atb":[[19,8.9],[25,4.17]],"id":41419614},{"atl":[[1000,0]],"id":41419590},{"atb":[[34,8.54],[48,5.39]],"id":41419652},{"atb":[[17,6.25],[13,8.9]],"id":41419619},{"atb":[[8.6,13.16],[6.4,8.9]],"id":41419586},{"atb":[[40,0],[55,2]],"id":41419631},{"atl":[[1000,0]],"id":41419631},{"atb":[[8,8.9],[10.5,10.53]],"id":41419598},{"atb":[[13,8.33],[9.4,8.9]],"id":41419594},{"atb":[[9.6,11.63],[7.4,8.9]],"id":41419607},{"atb":[[4.3,8.9],[5.5,22.22]],"id":41419636},{"atb":[[18,8.9],[25,9.71]],"id":41419615},{"atb":[[34,8.54],[48,2.13]],"id":41419611},{"atb":[[7.6,15.15],[5.7,8.9]],"id":41419591},{"atb":[[34,8.54],[46,5.48]],"id":41435525},{"atb":[[38,0],[55,2]],"id":41419653},{"atb":[[8,8.9],[11,10]],"id":41419587},{"atb":[[6,8.9],[8.4,13.51]],"id":41419599},{"atb":[[38,8.08],[55,6.93]],"id":41419628},{"atb":[[20,5.26],[13.5,8.9]],"id":41419595},{"atb":[[8,14.29],[6.2,8.9]],"id":41419608},{"atb":[[4.8,8.9],[6.2,19.23]],"id":41419637},{"atb":[[34,9],[50,2.04]],"id":41419604},{"atb":[[21,8.9],[29,3.57]],"id":41419616},{"atb":[[7.6,15.15],[5.9,8.9]],"id":41419612},{"atb":[[7.2,51.87],[10,11.11]],"id":41419592},{"atb":[[40,0],[60,2]],"id":41419654},{"atb":[[9.6,8.9],[14,7.69]],"id":41419588},{"atb":[[10.5,10.53],[7.6,8.9]],"id":41419600},{"atb":[[38,8.08],[55,2]],"id":41419629}],"con":true,"img":false}]}
{"op":"mcm","clk":"5353444628","pt":1646215083055,"mc":[{"id":"1.195503865","rc":[{"atb":[[6.6,8.9]],"id":41419638},{"atl":[[960,1.27]],"id":28546943}],"con":true,"img":false}]}
{"op":"mcm","clk":"5353444634","pt":1646215083157,"mc":[{"id":"1.195503865","rc":[{"atl":[[250,4.95]],"id":41419614},{"atl":[[250,4.95]],"id":41419652},{"atl":[[85,0],[90,4.95],[110,0],[120,9.9]],"id":41419592}],"con":true,"img":false}]}
{"op":"mcm","clk":"5353444641","pt":1646215083260,"mc":[{"id":"1.195503865","rc":[{"atl":[[560,0],[930,2.16]],"id":28546943},{"atl":[[460,2]],"id":41419614},{"atl":[[850,2]],"id":41419652}],"con":true,"img":false}]}
{"op":"mcm","clk":"5353444646","pt":1646215083363,"mc":[{"id":"1.195503865","rc":[{"atl":[[860,1.42]],"id":41419614},{"atl":[[1000,0]],"id":41419652}],"con":true,"img":false}]}
{"op":"mcm","clk":"5353444657","pt":1646215083569,"mc":[{"id":"1.195503865","rc":[{"atl":[[830,2.19]],"id":41419614},{"atl":[[990,2.15],[1000,1.23]],"id":41419652}],"con":true,"img":false}]}
{"op":"mcm","clk":"5353444667","pt":1646215083674,"mc":[{"id":"1.195503865","rc":[{"atl":[[460,0]],"id":41419614},{"atl":[[850,0]],"id":41419652}],"con":true,"img":false}]}
{"op":"mcm","clk":"5353444704","pt":1646215084340,"mc":[{"id":"1.195503865","rc":[{"atb":[[130,0],[95,0]],"id":41419604}],"con":true,"img":false}]}
{"op":"mcm","clk":"5353444722","pt":1646215084549,"mc":[{"id":"1.195503865","rc":[{"atb":[[90,9.9],[120,4.95]],"id":41419604}],"con":true,"img":false}]}
{"op":"mcm","clk":"5353444752","pt":1646215085165,"mc":[{"id":"1.195503865","rc":[{"atl":[[120,0]],"id":41419588}],"con":true,"img":false}]}
{"op":"mcm","clk":"5353444772","pt":1646215085577,"mc":[{"id":"1.195503865","rc":[{"atl":[[75,9.9],[55,4.95]],"id":41419587},{"atl":[[130,4.95]],"id":41419588}],"con":true,"img":false}]}
{"op":"mcm","clk":"5353444778","pt":1646215085679,"mc":[{"id":"1.195503865","rc":[{"atl":[[70,0],[50,0]],"id":41419587}],"con":true,"img":false}]}
{"op":"mcm","clk":"5353444840","pt":1646215086761,"mc":[{"id":"1.195503865","rc":[{"atl":[[850,2.18],[490,0]],"id":41419616}],"con":true,"img":false}]}
{"op":"mcm","clk":"5353444916","pt":1646215088362,"mc":[{"id":"1.195503865","rc":[{"atb":[[34,0],[27,0]],"id":41419607}],"con":true,"img":false}]}
{"op":"mcm","clk":"5353444931","pt":1646215088774,"mc":[{"id":"1.195503865","rc":[{"atb":[[21,12.88]],"id":41419607}],"con":true,"img":false}]}
{"op":"mcm","clk":"5353444942","pt":1646215089186,"mc":[{"id":"1.195503865","rc":[{"atb":[[32,2.72],[26,3.26]],"id":41419607}],"con":true,"img":false}]}
{"op":"mcm","clk":"5353445316","pt":1646215096870,"mc":[{"id":"1.195503865","rc":[{"atl":[[75,7.09]],"id":41419585},{"atb":[[14,6.54]],"id":41419656},{"atb":[[8,0],[20,29.48]],"id":41419598},{"atl":[[540,2.64],[570,2]],"id":41419598},{"atl":[[23,12.15]],"id":41419637},{"atb":[[38,0],[120,8.59]],"id":41419629}],"con":true,"img":false}]}
{"op":"mcm","clk":"5353445320","pt":1646215096974,"mc":[{"id":"1.195503865","rc":[{"atb":[[10,8.52]],"id":41419609},{"atl":[[90,1.78]],"id":41419609},{"atb":[[16,17.17],[6.6,0]],"id":41419638},{"atl":[[34,9.76],[100,14.21]],"id":41419638},{"atb":[[6.8,17.24],[15,17.43]],"id":41419605},{"atl":[[120,12.64],[480,0]],"id":41419605},{"atb":[[4,0],[8.8,17.61]],"id":41419634},{"atl":[[300,0],[29,16.23]],"id":41419634},{"atb":[[16.5,0],[48,12.17]],"id":41419613},{"atl":[[200,5.74]],"id":41419613},{"atb":[[25,17.17],[8.4,0]],"id":41419593},{"atl":[[75,7.09],[600,0],[200,8.38]],"id":41419593},{"atb":[[32,27.34]],"id":41419655},{"atl":[[80,6.95],[320,5.98],[740,0]],"id":41419655},{"atb":[[14,6.56]],"id":41435527},{"atb":[[21,34.01],[7.8,0]],"id":41419601},{"atl":[[580,0]],"id":41419601},{"atb":[[38,0],[170,0.93],[110,14.12]],"id":41419630},{"atb":[[180,1.63],[110,19.83]],"id":41419597},{"atb":[[80,12.58]],"id":28546943},{"atl":[[250,5.59]],"id":28546943},{"atb":[[6,0]],"id":41419606},{"atl":[[95,14.21],[500,0]],"id":41419606},{"atb":[[9.6,29.48],[4.4,0]],"id":41419635},{"atb":[[36,15.48],[11.5,25.36]],"id":41419602},{"atl":[[95,6.63]],"id":41419602},{"atl":[[130,11.82]],"id":41419585},{"atb":[[60,12.17]],"id":41419614},{"atb":[[130,11.43]],"id":41419656},{"atb":[[80,7.97],[7.6,12.2],[120,1.32]],"id":41419590},{"atb":[[34,0],[75,12.7],[120,6.28]],"id":41419652},{"atl":[[250,5.59]],"id":41419652},{"atb":[[48,8.32],[13,0]],"id":41419619},{"atl":[[95,6.63]],"id":41419619},{"atb":[[18.5,17.17],[6.4,0]],"id":41419586},{"atl":[[530,0]],"id":41419586},{"atb":[[14,7.69],[120,6.28]],"id":41419660},{"atb":[[7.6,6.13]],"id":41419627},{"atb":[[32,15.48],[9.4,0]],"id":41419594},{"atl":[[640,0]],"id":41419594},{"atb":[[38,9.23],[7.6,15.15],[30,27.34]],"id":41419640},{"atl":[[550,0],[55,2.93]],"id":41419607},{"atb":[[90,12.99],[14,6.54]],"id":28546950},{"atb":[[4.3,0],[10,19.66]],"id":41419636},{"atl":[[44,17.04]],"id":41419636},{"atb":[[18,0],[48,27.89]],"id":41419615},{"atl":[[170,5.89]],"id":41419615},{"atb":[[34,0]],"id":41419611},{"atb":[[130,8.46],[14,28.18]],"id":41419657},{"atb":[[5.7,0],[15.5,35.26]],"id":41419591},{"atl":[[100,14.77],[500,0]],"id":41419591},{"atb":[[120,6.28]],"id":41435525},{"atl":[[220,5.67]],"id":41435525},{"atb":[[8,0],[24,17.17]],"id":41419587},{"atl":[[570,0],[170,0.93],[180,9.09]],"id":41419587},{"atb":[[20,17.17],[6,0]],"id":41419599},{"atl":[[530,0],[44,8.64]],"id":41419599},{"atb":[[150,7.71],[38,0]],"id":41419628},{"atb":[[42,21.3],[13.5,0]],"id":41419595},{"atl":[[180,5.84]],"id":41419595},{"atb":[[17,17.17]],"id":41419608},{"atl":[[530,0],[38,9.23]],"id":41419608},{"atb":[[4.8,0],[9,17.43],[10,19.66]],"id":41419637},{"atl":[[70,16.71],[410,0]],"id":41419637},{"atb":[[50,24.62]],"id":41419616},{"atb":[[13.5,31.99],[5.9,0]],"id":41419612},{"atl":[[95,15.44]],"id":41419612},{"atb":[[7.2,42.96],[22,17.17]],"id":41419592},{"atl":[[550,0],[160,9.97]],"id":41419592},{"atl":[[120,1.32]],"id":41419588},{"atb":[[160,5.95],[85,12.04]],"id":41419633},{"atb":[[22,17.17]],"id":41419600},{"atl":[[55,7.89]],"id":41419600},{"atb":[[160,0.99]],"id":41419629}],"con":true,"img":false}]}
{"op":"mcm","clk":"5353445331","pt":1646215097077,"mc":[{"id":"1.195503865","rc":[{"atb":[[30,13.85]],"id":41419609},{"atl":[[630,0.25],[240,2]],"id":41419609},{"atl":[[520,0]],"id":41419638},{"atb":[[40,9.01],[10,0]],"id":41419655},{"atb":[[120,21.81]],"id":41435527},{"atb":[[110,10.76],[28,9.86]],"id":41419651},{"atl":[[180,9.09],[50,8.19]],"id":41419601},{"atb":[[36,0]],"id":41419597},{"atb":[[110,6.4],[28,0]],"id":28546943},{"atb":[[17.5,17.17]],"id":41419606},{"atl":[[44,3.68]],"id":41419606},{"atl":[[420,0],[55,21.57]],"id":41419635},{"atb":[[20,17.17],[6.8,16.14]],"id":41419585},{"atl":[[540,0]],"id":41419585},{"atb":[[19,0]],"id":41419614},{"atl":[[250,5.59]],"id":41419614},{"atb":[[40,24.62]],"id":41419619},{"atl":[[50,8.19],[120,12.64]],"id":41419586},{"atb":[[85,10.81]],"id":41419660},{"atb":[[130,8.46],[170,0.93]],"id":41419627},{"atl":[[310,6.11]],"id":41419594},{"atl":[[120,6.28]],"id":41419640},{"atb":[[21,25.1],[7.4,0]],"id":41419607},{"atl":[[140,11.12]],"id":41419607},{"atb":[[8.2,17.98]],"id":41419636},{"atl":[[17.5,14.56],[350,0]],"id":41419636},{"atb":[[65,9.85]],"id":41419611},{"atb":[[150,6.01]],"id":41419657},{"atl":[[34,9.76]],"id":41419591},{"atb":[[70,13.07],[34,0]],"id":41435525},{"atl":[[110,13.61]],"id":41419599},{"atb":[[210,1.39]],"id":41419628},{"atb":[[6.2,0]],"id":41419608},{"atl":[[110,13.61]],"id":41419608},{"atb":[[70,13.07],[34,0],[75,0.23]],"id":41419604},{"atb":[[21,0]],"id":41419616},{"atb":[[15.5,15.88]],"id":41419612},{"atl":[[32,10.06],[450,0]],"id":41419612},{"atl":[[150,1.06]],"id":41419592},{"atb":[[9.6,0],[36,13.85]],"id":41419588},{"atl":[[330,2],[700,0.22]],"id":41419588},{"atb":[[7.6,9.61]],"id":41419633},{"atb":[[7.6,0]],"id":41419600},{"atl":[[570,0],[160,9.97]],"id":41419600}],"con":true,"img":false}]}
{"op":"mcm","clk":"5353445340","pt":1646215097283,"mc":[{"id":"1.195503865","rc":[{"atb":[[70,7.25]],"id":41419616},{"atl":[[170,0.93]],"id":41419616}],"con":true,"img":false}]}
{"op":"mcm","clk":"5353445358","pt":1646215097594,"mc":[{"id":"1.195503865","rc":[{"atl":[[630,2.27],[660,0]],"id":41419609},{"atl":[[510,0]],"id":41419585},{"atl":[[380,0]],"id":41419637},{"atl":[[700,2.04],[730,0]],"id":41419588}],"con":true,"img":false}]}
{"op":"mcm","clk":"5353445362","pt":1646215097698,"mc":[{"id":"1.195503865","rc":[{"atl":[[630,2.02]],"id":41419609},{"atl":[[490,0]],"id":41419638},{"atl":[[800,2]],"id":41419613},{"atl":[[570,0]],"id":41419593},{"atl":[[710,0]],"id":41419655},{"atb":[[120,9.9]],"id":41419630},{"atb":[[180,0.74],[110,18.38]],"id":41419597},{"atl":[[930,2]],"id":28546943},{"atl":[[740,2]],"id":41419602},{"atb":[[80,5.97]],"id":41419590},{"atb":[[75,10.56]],"id":41419652},{"atl":[[990,2]],"id":41419652},{"atb":[[44,2.72]],"id":41419619},{"atl":[[760,2]],"id":41419619},{"atb":[[90,9.9]],"id":41419660},{"atb":[[32,0]],"id":41419640},{"atb":[[9.2,12.63]],"id":41419636},{"atl":[[840,2]],"id":41419615},{"atb":[[70,10.77]],"id":41435525},{"atl":[[540,0]],"id":41419587},{"atl":[[500,0]],"id":41419599},{"atl":[[790,2]],"id":41419595},{"atb":[[9.2,9.9]],"id":41419637},{"atl":[[850,3.68],[880,0]],"id":41419616},{"atl":[[700,1.82]],"id":41419588},{"atb":[[85,10.16]],"id":41419633},{"atl":[[540,0]],"id":41419600},{"atb":[[130,0]],"id":41419629}],"con":true,"img":false}]}
{"op":"mcm","clk":"5353445367","pt":1646215097800,"mc":[{"id":"1.195503865","rc":[{"atb":[[17.5,14.56]],"id":41419605},{"atl":[[38,9.23]],"id":41419605},{"atb":[[170,0.93]],"id":41435527},{"atb":[[80,10.58]],"id":28546943},{"atb":[[140,0]],"id":41419627},{"atl":[[760,2]],"id":41419640},{"atl":[[520,0]],"id":41419607},{"atb":[[120,6.28]],"id":41419611},{"atl":[[470,0]],"id":41419591},{"atl":[[990,2]],"id":41435525},{"atl":[[500,0]],"id":41419608},{"atb":[[14,2.72]],"id":41419612}],"con":true,"img":false}]}
{"op":"mcm","clk":"5353445373","pt":1646215097853,"mc":[{"id":"1.195503865","rc":[{"atl":[[470,0]],"id":41419606},{"atl":[[830,2]],"id":41419614},{"atl":[[320,0]],"id":41419636},{"atb":[[160,4.95],[210,0.63]],"id":41419628},{"atl":[[520,0]],"id":41419592}],"con":true,"img":false}]}
{"op":"mcm","clk":"5353445379","pt":1646215097956,"mc":[{"id":"1.195503865","rc":[{"atb":[[34,0]],"id":41419655},{"atl":[[550,0]],"id":41419601},{"atb":[[140,0]],"id":41419657},{"atb":[[70,10.77]],"id":41419604}],"con":true,"img":false}]}
{"op":"mcm","clk":"5353445386","pt":1646215098058,"mc":[{"id":"1.195503865","rc":[{"atl":[[500,0]],"id":41419586},{"atb":[[65,2.72]],"id":41419616},{"atl":[[850,3.49]],"id":41419616},{"atl":[[420,0]],"id":41419612}],"con":true,"img":false}]}
{"op":"mcm","clk":"5353445422","pt":1646215098580,"mc":[{"id":"1.195503865","rc":[{"atb":[[15.5,9.9]],"id":41419605},{"atl":[[450,0]],"id":41419605},{"atb":[[130,0]],"id":41435527},{"atb":[[160,0.99]],"id":41419597},{"atb":[[65,7.37]],"id":41419611},{"atb":[[170,0.93]],"id":41419628}],"con":true,"img":false}]}
{"op":"mcm","clk":"5353445601","pt":1646215102082,"mc":[{"id":"1.195503865","rc":[{"atl":[[44,0]],"id":41419606}],"con":true,"img":false}]}
{"op":"mcm","clk":"5353445631","pt":1646215102756,"mc":[{"id":"1.195503865","rc":[{"atl":[[55,2.93]],"id":41419606}],"con":true,"img":false}]}
{"op":"mcm","clk":"5353445721","pt":1646215104559,"mc":[{"id":"1.195503865","rc":[{"atb":[[30,12.63]],"id":41419640}],"con":true,"img":false}]}
{"op":"mcm","clk":"5353445738","pt":1646215104868,"mc":[{"id":"1.195503865","rc":[{"atb":[[32,12.63],[26,27.02]],"id":41419655},{"atb":[[25,17.46]],"id":41419640},{"atb":[[130,2.72],[110,21.71]],"id":41419657}],"con":true,"img":false}]}
{"op":"mcm","clk":"5353445789","pt":1646215106003,"mc":[{"id":"1.195503865","rc":[{"atl":[[90,0]],"id":41419609},{"atl":[[200,0],[210,4.95]],"id":41419613},{"atl":[[260,4.95],[250,0]],"id":28546943},{"atl":[[170,0],[180,4.95]],"id":41419615},{"atl":[[44,0],[55,0]],"id":41419599},{"atl":[[38,0],[40,4.95],[46,0],[48,9.9]],"id":41419608},{"atl":[[120,0]],"id":41419588}],"con":true,"img":false}]}
{"op":"mcm","clk":"5353445798","pt":1646215106107,"mc":[{"id":"1.195503865","rc":[{"atl":[[65,9.9],[46,0],[48,4.95],[60,0]],"id":41419606},{"atl":[[70,0],[75,9.9],[50,0],[55,4.95]],"id":41419586},{"atl":[[46,4.95],[60,9.9]],"id":41419599},{"atl":[[170,0]],"id":41419616}],"con":true,"img":false}]}
{"op":"mcm","clk":"5353445802","pt":1646215106160,"mc":[{"id":"1.195503865","rc":[{"atl":[[800,0],[410,2]],"id":41419613},{"atl":[[570,2],[930,0]],"id":28546943},{"atl":[[840,0],[460,2]],"id":41419615}],"con":true,"img":false}]}
{"op":"mcm","clk":"5353445819","pt":1646215106470,"mc":[{"id":"1.195503865","rc":[{"atl":[[130,10.02],[110,2]],"id":41419599}],"con":true,"img":false}]}
{"op":"mcm","clk":"5353445836","pt":1646215106676,"mc":[{"id":"1.195503865","rc":[{"atl":[[95,6.63]],"id":41419609},{"atl":[[400,0.39]],"id":41419613},{"atl":[[260,0],[560,0.28]],"id":28546943},{"atl":[[55,2.93]],"id":41419599},{"atl":[[46,3.52]],"id":41419608},{"atl":[[130,6.18]],"id":41419588}],"con":true,"img":false}]}
{"op":"mcm","clk":"5353445843","pt":1646215106779,"mc":[{"id":"1.195503865","rc":[{"atl":[[630,4.02],[240,0]],"id":41419609},{"atl":[[450,0.35]],"id":41419615},{"atl":[[180,5.84]],"id":41419616},{"atl":[[330,0],[700,3.82]],"id":41419588}],"con":true,"img":false}]}
{"op":"mcm","clk":"5353445849","pt":1646215106883,"mc":[{"id":"1.195503865","rc":[{"atl":[[70,2.29]],"id":41419586}],"con":true,"img":false}]}
{"op":"mcm","clk":"5353445868","pt":1646215107190,"mc":[{"id":"1.195503865","rc":[{"atl":[[410,5.17]],"id":41419613}],"con":true,"img":false}]}
{"op":"mcm","clk":"5353445871","pt":1646215107294,"mc":[{"id":"1.195503865","rc":[{"atl":[[830,0]],"id":41419613}],"con":true,"img":false}]}
{"op":"mcm","clk":"5353445881","pt":1646215107501,"mc":[{"id":"1.195503865","rc":[{"atl":[[460,4.83]],"id":41419615}],"con":true,"img":false}]}
{"op":"mcm","clk":"5353445887","pt":1646215107603,"mc":[{"id":"1.195503865","rc":[{"atl":[[870,0]],"id":41419615}],"con":true,"img":false}]}
{"op":"mcm","clk":"5353446168","pt":1646215112298,"mc":[{"id":"1.195503865","rc":[{"atb":[[110,9.9]],"id":41419597},{"atl":[[150,9.86]],"id":41419592}],"con":true,"img":false}]}
{"op":"mcm","clk":"5353446173","pt":1646215112403,"mc":[{"id":"1.195503865","rc":[{"atl":[[210,5.71]],"id":41419613},{"atb":[[110,2.72],[120,18.66]],"id":41419630},{"atb":[[150,7.55],[180,1.63]],"id":41419597},{"atl":[[65,22.12],[95,2]],"id":41419606},{"atb":[[80,0],[85,19.24]],"id":41419590},{"atl":[[75,22.12],[120,2]],"id":41419586},{"atl":[[170,8.7],[180,2]],"id":41419587},{"atl":[[46,8.47],[60,22.12]],"id":41419599},{"atb":[[150,2.72],[160,7.3]],"id":41419628},{"atl":[[160,2],[85,1.88]],"id":41419592}],"con":true,"img":false}]}
{"op":"mcm","clk":"5353446181","pt":1646215112506,"mc":[{"id":"1.195503865","rc":[{"atl":[[50,3.23]],"id":41419606},{"atl":[[55,7.89]],"id":41419586},{"atl":[[140,2],[80,22.12]],"id":41419607},{"atl":[[180,5.84]],"id":41419615},{"atl":[[130,0]],"id":41419599},{"atb":[[210,1.39]],"id":41419628},{"atl":[[40,9.01],[48,22.49],[110,2]],"id":41419608},{"atb":[[70,0],[75,7.95]],"id":41419604}],"con":true,"img":false}]}
{"op":"mcm","clk":"5353446195","pt":1646215112714,"mc":[{"id":"1.195503865","rc":[{"atb":[[130,1.23]],"id":41419604}],"con":true,"img":false}]}
{"op":"mcm","clk":"5353446214","pt":1646215112979,"mc":[{"id":"1.195503865","rc":[{"atl":[[630,2],[110,11.95]],"id":41419609},{"atl":[[150,8.81],[700,2]],"id":41419588}],"con":true,"img":false}]}
{"op":"mcm","clk":"5353446223","pt":1646215113183,"mc":[{"id":"1.195503865","rc":[{"atl":[[400,0]],"id":41419613},{"atb":[[160,0],[180,0.74]],"id":41419597},{"atl":[[450,0]],"id":41419615},{"atl":[[55,0]],"id":41419599},{"atl":[[200,6.61],[850,2]],"id":41419616},{"atl":[[150,8.8]],"id":41419592}],"con":true,"img":false}]}
{"op":"mcm","clk":"5353446233","pt":1646215113290,"mc":[{"id":"1.195503865","rc":[{"atl":[[55,0]],"id":41419606},{"atl":[[70,0]],"id":41419586},{"atl":[[46,0]],"id":41419608},{"atl":[[850,0],[490,2]],"id":41419616}],"con":true,"img":false}]}
{"op":"mcm","clk":"5353446238","pt":1646215113392,"mc":[{"id":"1.195503865","rc":[{"atb":[[170,0],[210,0.63]],"id":41419628}],"con":true,"img":false}]}
{"op":"mcm","clk":"5353446245","pt":1646215113494,"mc":[{"id":"1.195503865","rc":[{"atb":[[75,7.71]],"id":41419604}],"con":true,"img":false}]}
{"op":"mcm","clk":"5353446267","pt":1646215113807,"mc":[{"id":"1.195503865","rc":[{"atl":[[110,0]],"id":41419609}],"con":true,"img":false}]}
{"op":"mcm","clk":"5353446293","pt":1646215114216,"mc":[{"id":"1.195503865","rc":[{"atb":[[160,0.99]],"id":41419597},{"atl":[[110,14.04]],"id":41419599},{"atb":[[170,0.93]],"id":41419628}],"con":true,"img":false}]}
{"op":"mcm","clk":"5353446299","pt":1646215114321,"mc":[{"id":"1.195503865","rc":[{"atl":[[60,9.9]],"id":41419599}],"con":true,"img":false}]}
{"op":"mcm","clk":"5353446408","pt":1646215116499,"mc":[{"id":"1.195503865","rc":[{"atl":[[1000,2.15]],"id":41419651}],"con":true,"img":false}]}
{"op":"mcm","clk":"5353446423","pt":1646215116705,"mc":[{"id":"1.195503865","rc":[{"atl":[[95,1.68]],"id":41419609}],"con":true,"img":false}]}
{"op":"mcm","clk":"5353446452","pt":1646215117114,"mc":[{"id":"1.195503865","rc":[{"atl":[[95,0],[100,4.95]],"id":41419609},{"atl":[[210,0],[220,4.95]],"id":41419613},{"atb":[[38,0],[29,0]],"id":41419592}],"con":true,"img":false}]}
{"op":"mcm","clk":"5353446470","pt":1646215117320,"mc":[{"id":"1.195503865","rc":[{"atl":[[630,0],[250,2]],"id":41419609}],"con":true,"img":false}]}
{"op":"mcm","clk":"5353446490","pt":1646215117578,"mc":[{"id":"1.195503865","rc":[{"atb":[[22,4.95]],"id":41419592}],"con":true,"img":false}]}
{"op":"mcm","clk":"5353446508","pt":1646215117885,"mc":[{"id":"1.195503865","rc":[{"atl":[[100,6.55]],"id":41419609},{"atl":[[220,5.67]],"id":41419613},{"atb":[[18,34.21],[36,2.72],[22,12.5],[28,3.26]],"id":41419592}],"con":true,"img":false}]}
{"op":"mcm","clk":"5353446523","pt":1646215118090,"mc":[{"id":"1.195503865","rc":[{"atl":[[48,8.32]],"id":41419606}],"con":true,"img":false}]}
{"op":"mcm","clk":"5353446542","pt":1646215118404,"mc":[{"id":"1.195503865","rc":[{"atl":[[270,4.95]],"id":28546943},{"atl":[[270,4.95]],"id":41419611}],"con":true,"img":false}]}
{"op":"mcm","clk":"5353446550","pt":1646215118510,"mc":[{"id":"1.195503865","rc":[{"atl":[[910,2]],"id":41419611}],"con":true,"img":false}]}
{"op":"mcm","clk":"5353446560","pt":1646215118611,"mc":[{"id":"1.195503865","rc":[{"atl":[[1000,0]],"id":41419611}],"con":true,"img":false}]}
{"op":"mcm","clk":"5353446572","pt":1646215118818,"mc":[{"id":"1.195503865","rc":[{"atl":[[570,4.34],[960,0]],"id":28546943},{"atl":[[50,0]],"id":41419606},{"atl":[[910,0],[990,2.15],[1000,1.32]],"id":41419611}],"con":true,"img":false}]}
{"op":"mcm","clk":"5353446582","pt":1646215118922,"mc":[{"id":"1.195503865","rc":[{"atl":[[260,0.61]],"id":41419611}],"con":true,"img":false}]}
{"op":"mcm","clk":"5353446599","pt":1646215119183,"mc":[{"id":"1.195503865","rc":[{"atl":[[270,0]],"id":28546943}],"con":true,"img":false}]}
{"op":"mcm","clk":"5353446612","pt":1646215119388,"mc":[{"id":"1.195503865","rc":[{"atb":[[10,0],[12.5,8.7]],"id":41419609},{"atb":[[46,3.26]],"id":41435525},{"atl":[[930,2],[990,0]],"id":41435525}],"con":true,"img":false}]}
{"op":"mcm","clk":"5353446617","pt":1646215119490,"mc":[{"id":"1.195503865","rc":[{"atb":[[36,2.86]],"id":41435525}],"con":true,"img":false}]}
{"op":"mcm","clk":"5353446623","pt":1646215119593,"mc":[{"id":"1.195503865","rc":[{"atb":[[32,2.72],[40,4.06]],"id":41419655},{"atl":[[550,0.28]],"id":28546943},{"atb":[[120,4.95]],"id":41435525}],"con":true,"img":false}]}
{"op":"mcm","clk":"5353446630","pt":1646215119696,"mc":[{"id":"1.195503865","rc":[{"atb":[[19.5,11.29]],"id":41419638},{"atl":[[13,0],[13.5,4.95],[15,0],[15.5,9.9]],"id":41419634},{"atb":[[38,4.95],[30,9.9]],"id":41419655},{"atb":[[80,20.49],[85,0],[100,4.95],[110,0]],"id":28546943},{"atb":[[90,0],[120,1.32]],"id":41419652},{"atl":[[990,2]],"id":41419611},{"atb":[[130,7.67],[150,1.06],[95,9.9],[110,11.8]],"id":41419657},{"atb":[[75,9.9],[90,0],[95,4.95],[120,0]],"id":41435525},{"atb":[[36,0],[28,0]],"id":41419592}],"con":true,"img":false}]}
{"op":"mcm","clk":"5353446634","pt":1646215119800,"mc":[{"id":"1.195503865","rc":[{"atl":[[65,9.9],[95,16.12]],"id":41419606},{"atb":[[80,9.9],[100,4.95],[120,0]],"id":41419652},{"atl":[[75,9.9],[120,13.18]],"id":41419586}],"con":true,"img":false}]}
{"op":"mcm","clk":"5353446646","pt":1646215120010,"mc":[{"id":"1.195503865","rc":[{"atl":[[48,9.9],[110,14.2]],"id":41419608}],"con":true,"img":false}]}
{"op":"mcm","clk":"5353446652","pt":1646215120110,"mc":[{"id":"1.195503865","rc":[{"atb":[[32,18.97]],"id":41419655},{"atb":[[75,13.21]],"id":28546943},{"atb":[[70,9.73]],"id":41419652}],"con":true,"img":false}]}
{"op":"mcm","clk":"5353446661","pt":1646215120217,"mc":[{"id":"1.195503865","rc":[{"atl":[[13.5,13.85]],"id":41419634},{"atb":[[26,3.26]],"id":41419655},{"atb":[[80,9.9]],"id":28546943},{"atb":[[75,0]],"id":41419652}],"con":true,"img":false}]}
{"op":"mcm","clk":"5353446676","pt":1646215120423,"mc":[{"id":"1.195503865","rc":[{"atb":[[80,10.75]],"id":28546943},{"atl":[[270,4.95],[560,0]],"id":28546943},{"atb":[[95,6.63]],"id":41435525},{"atb":[[38,2.72],[29,3.26]],"id":41419592},{"atl":[[700,3.91]],"id":41419588}],"con":true,"img":false}]}
{"op":"mcm","clk":"5353446681","pt":1646215120528,"mc":[{"id":"1.195503865","rc":[{"atl":[[150,0]],"id":41419588}],"con":true,"img":false}]}
{"op":"mcm","clk":"5353446688","pt":1646215120583,"mc":[{"id":"1.195503865","rc":[{"atb":[[17.5,0],[17,4.95],[15,27.34],[15.5,0]],"id":41419605},{"atb":[[80,11.91]],"id":41419652},{"atl":[[200,0],[490,4.73]],"id":41419616}],"con":true,"img":false}]}
{"op":"mcm","clk":"5353446693","pt":1646215120685,"mc":[{"id":"1.195503865","rc":[{"atb":[[32,0],[42,0]],"id":41419593},{"atb":[[85,0],[60,8.9]],"id":41419614},{"atb":[[140,0],[190,0]],"id":41419631},{"atl":[[55,0]],"id":41419607},{"atb":[[9,9.9],[10,0],[9.2,2.72],[9.8,4.95]],"id":41419636},{"atb":[[19.5,0],[24,0]],"id":41419608},{"atb":[[130,0]],"id":41419604},{"atl":[[85,0]],"id":41419592},{"atb":[[34,0],[27,0]],"id":41419600}],"con":true,"img":false}]}
{"op":"mcm","clk":"5353446697","pt":1646215120789,"mc":[{"id":"1.195503865","rc":[{"atb":[[70,20.68],[90,4.95]],"id":41435525}],"con":true,"img":false}]}
{"op":"mcm","clk":"5353446702","pt":1646215120895,"mc":[{"id":"1.195503865","rc":[{"atb":[[19.5,2.72]],"id":41419638},{"atl":[[34,4.95]],"id":41419638},{"atl":[[270,0]],"id":41419634},{"atb":[[40,0]],"id":41419655},{"atl":[[80,4.95]],"id":41419655},{"atl":[[95,1.68],[110,4.95]],"id":41419619},{"atb":[[75,0],[95,1.68]],"id":41435525},{"atb":[[23,0],[28,0]],"id":41419599}],"con":true,"img":false}]}
{"op":"mcm","clk":"5353446707","pt":1646215120997,"mc":[{"id":"1.195503865","rc":[{"atl":[[760,0],[390,2]],"id":41419619},{"atl":[[220,4.95]],"id":41435525},{"atl":[[40,0],[42,4.95],[48,0],[50,9.9]],"id":41419608},{"atl":[[180,0],[200,4.95]],"id":41419616}],"con":true,"img":false}]}
{"op":"mcm","clk":"5353446715","pt":1646215121102,"mc":[{"id":"1.195503865","rc":[{"atl":[[100,0],[110,4.95]],"id":41419609},{"atb":[[12.5,31.73],[15,12.63]],"id":41419605},{"atb":[[16.5,36.08],[25,11.55]],"id":41419593},{"atb":[[65,7.43],[48,25.57]],"id":41419614},{"atl":[[140,11.6],[80,9.9]],"id":41419607},{"atb":[[9,39.36],[8.2,3.26]],"id":41419636},{"atb":[[17,14.86],[11.5,46.28]],"id":41419608},{"atb":[[16,38.33],[22,12.5]],"id":41419600}],"con":true,"img":false}]}
{"op":"mcm","clk":"5353446722","pt":1646215121204,"mc":[{"id":"1.195503865","rc":[{"atb":[[60,0]],"id":41419614},{"atb":[[70,9.9],[75,15.79]],"id":41435525},{"atl":[[700,2]],"id":41419588}],"con":true,"img":false}]}
{"op":"mcm","clk":"5353446727","pt":1646215121306,"mc":[{"id":"1.195503865","rc":[{"atb":[[17,0],[15,2.72],[15.5,10.93]],"id":41419605},{"atl":[[760,1.76],[790,0]],"id":41419619},{"atb":[[20,13.29],[12,44.83]],"id":41419599},{"atl":[[490,2]],"id":41419616}],"con":true,"img":false}]}
{"op":"mcm","clk":"5353446734","pt":1646215121412,"mc":[{"id":"1.195503865","rc":[{"atb":[[32,3.26],[42,2.72]],"id":41419593},{"atb":[[9,29.45],[9.8,0]],"id":41419636},{"atb":[[19.5,3.26],[24,2.72]],"id":41419608},{"atb":[[130,1.23]],"id":41419604},{"atb":[[34,2.72],[27,3.26]],"id":41419600}],"con":true,"img":false}]}
{"op":"mcm","clk":"5353446737","pt":1646215121513,"mc":[{"id":"1.195503865","rc":[{"atb":[[85,2.72],[60,3.26]],"id":41419614},{"atb":[[140,3.26],[190,2.72]],"id":41419631},{"atl":[[75,2.14]],"id":41419607},{"atb":[[9,49.27]],"id":41419636},{"atl":[[85,1.88]],"id":41419592}],"con":true,"img":false}]}
{"op":"mcm","clk":"5353446741","pt":1646215121616,"mc":[{"id":"1.195503865","rc":[{"atl":[[220,0],[230,4.95]],"id":41435525}],"con":true,"img":false}]}
{"op":"mcm","clk":"5353446746","pt":1646215121720,"mc":[{"id":"1.195503865","rc":[{"atb":[[17,13.17]],"id":41419638},{"atl":[[40,4.06]],"id":41419638},{"atb":[[32,24.08]],"id":41419655},{"atb":[[23,3.26],[28,2.72]],"id":41419599},{"atl":[[48,3.37]],"id":41419608},{"atl":[[200,5.74]],"id":41419616}],"con":true,"img":false}]}
{"op":"mcm","clk":"5353446757","pt":1646215121926,"mc":[{"id":"1.195503865","rc":[{"atl":[[110,6.4]],"id":41419609},{"atl":[[260,0.61]],"id":28546943},{"atl":[[95,1.68],[100,4.95]],"id":41419602},{"atl":[[210,0.75]],"id":41435525}],"con":true,"img":false}]}
{"op":"mcm","clk":"5353446763","pt":1646215122030,"mc":[{"id":"1.195503865","rc":[{"atb":[[17,9.9],[19,4.95]],"id":41419605},{"atl":[[55,7.89]],"id":41419587}],"con":true,"img":false}]}
{"op":"mcm","clk":"5353446770","pt":1646215122082,"mc":[{"id":"1.195503865","rc":[{"atl":[[42,31.99]],"id":41419638},{"atl":[[360,2],[740,0]],"id":41419602},{"atb":[[9.2,12.63],[10,4.95]],"id":41419636}],"con":true,"img":false}]}
{"op":"mcm","clk":"5353446777","pt":1646215122187,"mc":[{"id":"1.195503865","rc":[{"atl":[[100,2]],"id":41419638},{"atl":[[80,6.95]],"id":41419655},{"atl":[[75,0],[80,9.9],[55,0],[60,4.95]],"id":41419600}],"con":true,"img":false}]}
{"op":"mcm","clk":"5353446780","pt":1646215122287,"mc":[{"id":"1.195503865","rc":[{"atl":[[410,2],[240,5.61]],"id":41419613},{"atl":[[75,4.95]],"id":41419593},{"atl":[[770,0]],"id":41419602},{"atl":[[80,0],[60,0]],"id":41419607},{"atl":[[930,3.44],[1000,0]],"id":41435525}],"con":true,"img":false}]}
{"op":"mcm","clk":"5353446785","pt":1646215122392,"mc":[{"id":"1.195503865","rc":[{"atl":[[75,0],[80,4.95],[95,0],[100,9.9]],"id":41419593},{"atl":[[740,1.81]],"id":41419602},{"atl":[[65,4.95],[85,9.9]],"id":41419607}],"con":true,"img":false}]}
{"op":"mcm","clk":"5353446801","pt":1646215122702,"mc":[{"id":"1.195503865","rc":[{"atl":[[550,0]],"id":28546943},{"atl":[[100,0]],"id":41419602},{"atl":[[200,6.74],[460,2]],"id":41419615}],"con":true,"img":false}]}
{"op":"mcm","clk":"5353446808","pt":1646215122806,"mc":[{"id":"1.195503865","rc":[{"atl":[[170,7.76]],"id":41419587}],"con":true,"img":false}]}
{"op":"mcm","clk":"5353446818","pt":1646215123010,"mc":[{"id":"1.195503865","rc":[{"atl":[[80,6.95]],"id":41419593},{"atl":[[150,1.06]],"id":41419600}],"con":true,"img":false}]}
{"op":"mcm","clk":"5353446821","pt":1646215123112,"mc":[{"id":"1.195503865","rc":[{"atl":[[260,4.95],[250,0]],"id":41419614},{"atl":[[180,0],[190,4.95]],"id":41419595}],"con":true,"img":false}]}
{"op":"mcm","clk":"5353446827","pt":1646215123215,"mc":[{"id":"1.195503865","rc":[{"atl":[[830,0],[480,2]],"id":41419614},{"atl":[[790,0],[410,2]],"id":41419595}],"con":true,"img":false}]}
{"op":"mcm","clk":"5353446844","pt":1646215123524,"mc":[{"id":"1.195503865","rc":[{"atl":[[100,4.95]],"id":41419602},{"atl":[[150,10.07],[160,2]],"id":41419600}],"con":true,"img":false}]}
{"op":"mcm","clk":"5353446862","pt":1646215123834,"mc":[{"id":"1.195503865","rc":[{"atl":[[260,5.56]],"id":41419614},{"atl":[[400,0.39]],"id":41419595}],"con":true,"img":false}]}
{"op":"mcm","clk":"5353446890","pt":1646215124299,"mc":[{"id":"1.195503865","rc":[{"atl":[[820,0]],"id":41419595}],"con":true,"img":false}]}
{"op":"mcm","clk":"5353446904","pt":1646215124608,"mc":[{"id":"1.195503865","rc":[{"atl":[[410,5.29]],"id":41419595}],"con":true,"img":false}]}
{"op":"mcm","clk":"5353447013","pt":1646215126726,"mc":[{"id":"1.195503865","rc":[{"atl":[[260,0.61]],"id":41419614}],"con":true,"img":false}]}
{"op":"mcm","clk":"5353447030","pt":1646215126994,"mc":[{"id":"1.195503865","rc":[{"atl":[[260,0],[270,4.95]],"id":41419614},{"atl":[[180,0.88],[190,4.95]],"id":41419615}],"con":true,"img":false}]}
{"op":"mcm","clk":"5353447035","pt":1646215127104,"mc":[{"id":"1.195503865","rc":[{"atl":[[180,0]],"id":41419615}],"con":true,"img":false}]}
{"op":"mcm","clk":"5353447046","pt":1646215127306,"mc":[{"id":"1.195503865","rc":[{"atb":[[29,8.38]],"id":41419598},{"atl":[[70,9.9],[48,8.27],[50,4.95]],"id":41419598}],"con":true,"img":false}]}
{"op":"mcm","clk":"5353447051","pt":1646215127410,"mc":[{"id":"1.195503865","rc":[{"atl":[[65,0],[570,0],[180,2],[48,3.31]],"id":41419598}],"con":true,"img":false}]}
{"op":"mcm","clk":"5353447054","pt":1646215127512,"mc":[{"id":"1.195503865","rc":[{"atb":[[32,7.83],[30,34.98]],"id":41419655},{"atb":[[190,0.83]],"id":41419597},{"atl":[[140,2],[85,22.12]],"id":41419607},{"atb":[[220,0.72]],"id":41419628},{"atl":[[190,0],[200,4.95]],"id":41419595},{"atl":[[40,4.06],[50,22.27],[110,2]],"id":41419608},{"atb":[[75,0]],"id":41419604},{"atl":[[150,0],[120,21.27]],"id":41419592},{"atl":[[80,0],[60,0]],"id":41419600}],"con":true,"img":false}]}
{"op":"mcm","clk":"5353447063","pt":1646215127618,"mc":[{"id":"1.195503865","rc":[{"atb":[[90,19.09]],"id":41419604}],"con":true,"img":false}]}
{"op":"mcm","clk":"5353447069","pt":1646215127721,"mc":[{"id":"1.195503865","rc":[{"atl":[[65,4.95],[85,9.9]],"id":41419600}],"con":true,"img":false}]}
{"op":"mcm","clk":"5353447080","pt":1646215127824,"mc":[{"id":"1.195503865","rc":[{"atl":[[270,5.54]],"id":41419614},{"atl":[[540,0.29],[65,20.99]],"id":41419598},{"atl":[[190,5.79]],"id":41419615}],"con":true,"img":false}]}
{"op":"mcm","clk":"5353447095","pt":1646215128031,"mc":[{"id":"1.195503865","rc":[{"atb":[[150,4.95],[160,3.36]],"id":41419597},{"atb":[[160,4.95],[170,2.95]],"id":41419628}],"con":true,"img":false}]}
{"op":"mcm","clk":"5353447100","pt":1646215128136,"mc":[{"id":"1.195503865","rc":[{"atl":[[130,9.72]],"id":41419609},{"atl":[[540,0]],"id":41419598},{"atl":[[150,9.1]],"id":41419588}],"con":true,"img":false}]}
{"op":"mcm","clk":"5353447109","pt":1646215128343,"mc":[{"id":"1.195503865","rc":[{"atl":[[860,3.42],[480,0]],"id":41419614},{"atl":[[220,6.2]],"id":41419616},{"atl":[[330,2],[700,0]],"id":41419588}],"con":true,"img":false}]}
{"op":"mcm","clk":"5353447112","pt":1646215128397,"mc":[{"id":"1.195503865","rc":[{"atb":[[160,2.36]],"id":41419597},{"atb":[[170,2.02]],"id":41419628},{"atl":[[48,0]],"id":41419608}],"con":true,"img":false}]}
{"op":"mcm","clk":"5353447137","pt":1646215128812,"mc":[{"id":"1.195503865","rc":[{"atl":[[860,2]],"id":41419614}],"con":true,"img":false}]}
{"op":"mcm","clk":"5353447210","pt":1646215129120,"mc":[{"id":"1.195503865","rc":[{"atl":[[290,4.7]],"id":41419614}],"con":true,"img":false}]}
{"op":"mcm","clk":"5353447234","pt":1646215129639,"mc":[{"id":"1.195503865","rc":[{"atl":[[240,0]],"id":41419613}],"con":true,"img":false}]}
{"op":"mcm","clk":"5353447244","pt":1646215129898,"mc":[{"id":"1.195503865","rc":[{"atl":[[410,5.33]],"id":41419613}],"con":true,"img":false}]}
{"op":"mcm","clk":"5353447251","pt":1646215130103,"mc":[{"id":"1.195503865","rc":[{"atb":[[85,0],[60,0]],"id":41419614},{"atl":[[460,4.97]],"id":41419615},{"atb":[[23,0],[28,0]],"id":41419599}],"con":true,"img":false}]}
{"op":"mcm","clk":"5353447258","pt":1646215130207,"mc":[{"id":"1.195503865","rc":[{"atl":[[200,0]],"id":41419615},{"atb":[[34,0],[27,0]],"id":41419600}],"con":true,"img":false}]}
{"op":"mcm","clk":"5353447273","pt":1646215130515,"mc":[{"id":"1.195503865","rc":[{"atb":[[48,9.9]],"id":41419614}],"con":true,"img":false}]}
{"op":"mcm","clk":"5353447293","pt":1646215130829,"mc":[{"id":"1.195503865","rc":[{"atb":[[65,10.7],[44,18.32],[90,2.72]],"id":41419614},{"atb":[[24,3.26],[29,2.72]],"id":41419599}],"con":true,"img":false}]}
{"op":"mcm","clk":"5353447383","pt":1646215131238,"mc":[{"id":"1.195503865","rc":[{"atb":[[36,2.72],[28,3.26]],"id":41419600}],"con":true,"img":false}]}
{"op":"mcm","clk":"5353447478","pt":1646215132942,"mc":[{"id":"1.195503865","rc":[{"atb":[[17,0],[19,0]],"id":41419605}],"con":true,"img":false}]}
{"op":"mcm","clk":"5353447494","pt":1646215133201,"mc":[{"id":"1.195503865","rc":[{"atb":[[16.5,9.9],[18.5,4.95]],"id":41419605},{"atb":[[18,7.83],[22,24.72]],"id":41419592}],"con":true,"img":false}]}
{"op":"mcm","clk":"5353447520","pt":1646215133717,"mc":[{"id":"1.195503865","rc":[{"atl":[[1000,0]],"id":41419611}],"con":true,"img":false}]}
{"op":"mcm","clk":"5353447534","pt":1646215134026,"mc":[{"id":"1.195503865","rc":[{"atl":[[990,3.38]],"id":41419611}],"con":true,"img":false}]}
{"op":"mcm","clk":"5353447575","pt":1646215134749,"mc":[{"id":"1.195503865","rc":[{"atb":[[19.5,11.29]],"id":41419638},{"atb":[[12.5,28.46],[15,0]],"id":41419605},{"atb":[[11,4.95],[13.5,0]],"id":41419635},{"atb":[[11.5,0],[14,0]],"id":41419612}],"con":true,"img":false}]}
{"op":"mcm","clk":"5353447581","pt":1646215134885,"mc":[{"id":"1.195503865","rc":[{"atb":[[32,0],[42,0]],"id":41419593},{"atb":[[9.2,9.9],[8.2,0]],"id":41419636}],"con":true,"img":false}]}
{"op":"mcm","clk":"5353447602","pt":1646215135218,"mc":[{"id":"1.195503865","rc":[{"atb":[[13.5,9.9]],"id":41419612}],"con":true,"img":false}]}
{"op":"mcm","clk":"5353447609","pt":1646215135321,"mc":[{"id":"1.195503865","rc":[{"atl":[[130,0],[250,7.53]],"id":41419609},{"atb":[[100,6.55]],"id":28546943},{"atb":[[9.6,9.9],[11,20.8],[7.6,64.9]],"id":41419635},{"atb":[[7.6,60.61]],"id":41419612},{"atl":[[150,0]],"id":41419588}],"con":true,"img":false}]}
{"op":"mcm","clk":"5353447611","pt":1646215135423,"mc":[{"id":"1.195503865","rc":[{"atb":[[13,3.26],[15.5,13.65]],"id":41419605},{"atl":[[330,6.19]],"id":41419588}],"con":true,"img":false}]}
{"op":"mcm","clk":"5353447619","pt":1646215135527,"mc":[{"id":"1.195503865","rc":[{"atb":[[17,3.26]],"id":41419638},{"atb":[[10,3.26],[12.5,2.72]],"id":41419635},{"atl":[[280,4.95]],"id":41419590},{"atb":[[100,6.55]],"id":41419652},{"atb":[[12,3.26],[14.5,2.72]],"id":41419612}],"con":true,"img":false}]}
{"op":"mcm","clk":"5353447626","pt":1646215135631,"mc":[{"id":"1.195503865","rc":[{"atb":[[38,2.72],[29,3.26]],"id":41419593},{"atb":[[8.4,3.26],[9.4,2.72]],"id":41419636},{"atl":[[220,0],[490,4.82]],"id":41419616}],"con":true,"img":false}]}
{"op":"mcm","clk":"5353447637","pt":1646215135837,"mc":[{"id":"1.195503865","rc":[{"atl":[[19.5,13.52]],"id":41419635}],"con":true,"img":false}]}
{"op":"mcm","clk":"5353447647","pt":1646215136043,"mc":[{"id":"1.195503865","rc":[{"atb":[[12.5,0],[15.5,43.11]],"id":41419605},{"atb":[[44,3.09],[48,25.14]],"id":41419614},{"atl":[[270,0.58]],"id":41419590},{"atb":[[17,28.26],[11.5,12.68]],"id":41419608},{"atb":[[16,8.87],[22,34.59]],"id":41419600}],"con":true,"img":false}]}
{"op":"mcm","clk":"5353447653","pt":1646215136145,"mc":[{"id":"1.195503865","rc":[{"atb":[[25,34.36]],"id":41419593},{"atb":[[80,9.9]],"id":28546943},{"atb":[[9,19.81],[9.2,39.36]],"id":41419636}],"con":true,"img":false}]}
{"op":"mcm","clk":"5353447657","pt":1646215136250,"mc":[{"id":"1.195503865","rc":[{"atb":[[16.5,8.59]],"id":41419593}],"con":true,"img":false}]}
{"op":"mcm","clk":"5353447661","pt":1646215136300,"mc":[{"id":"1.195503865","rc":[{"atb":[[18.5,14.01]],"id":41419605},{"atl":[[290,0],[860,3.6]],"id":41419614},{"atb":[[80,9.9]],"id":41419652},{"atl":[[760,0],[390,5.55]],"id":41419619},{"atb":[[20,40.61],[12,12.1]],"id":41419599}],"con":true,"img":false}]}
{"op":"mcm","clk":"5353447664","pt":1646215136403,"mc":[{"id":"1.195503865","rc":[{"atl":[[60,2.68]],"id":41419607},{"atb":[[10,22.56]],"id":41419636}],"con":true,"img":false}]}
{"op":"mcm","clk":"5353447668","pt":1646215136506,"mc":[{"id":"1.195503865","rc":[{"atl":[[990,1.55]],"id":41419590}],"con":true,"img":false}]}
{"op":"mcm","clk":"5353447674","pt":1646215136608,"mc":[{"id":"1.195503865","rc":[{"atl":[[34,9.76]],"id":41419638},{"atb":[[38,9.23]],"id":41419655},{"atl":[[390,0]],"id":41419635}],"con":true,"img":false}]}
{"op":"mcm","clk":"5353447691","pt":1646215136917,"mc":[{"id":"1.195503865","rc":[{"atl":[[990,1.39]],"id":41419590}],"con":true,"img":false}]}
{"op":"mcm","clk":"5353447695","pt":1646215137020,"mc":[{"id":"1.195503865","rc":[{"atl":[[75,11.04],[85,9.9]],"id":41419607},{"atb":[[36,0],[28,0]],"id":41419600}],"con":true,"img":false}]}
{"op":"mcm","clk":"5353447698","pt":1646215137123,"mc":[{"id":"1.195503865","rc":[{"atb":[[15.5,32.18]],"id":41419605},{"atl":[[410,2],[240,5.79]],"id":41419613},{"atl":[[75,8.9]],"id":41419607},{"atb":[[9,0]],"id":41419636}],"con":true,"img":false}]}
{"op":"mcm","clk":"5353447709","pt":1646215137329,"mc":[{"id":"1.195503865","rc":[{"atl":[[40,0]],"id":41419638},{"atb":[[32,2.72]],"id":41419655},{"atl":[[360,5.85],[740,0]],"id":41419602}],"con":true,"img":false}]}
{"op":"mcm","clk":"5353447725","pt":1646215137640,"mc":[{"id":"1.195503865","rc":[{"atl":[[210,6.62],[460,2]],"id":41419615}],"con":true,"img":false}]}
{"op":"mcm","clk":"5353447746","pt":1646215137950,"mc":[{"id":"1.195503865","rc":[{"atl":[[42,9.9],[100,15.92]],"id":41419638},{"atb":[[34,2.72],[27,3.26]],"id":41419600},{"atl":[[60,2.68]],"id":41419600}],"con":true,"img":false}]}
{"op":"mcm","clk":"5353447765","pt":1646215138418,"mc":[{"id":"1.195503865","rc":[{"atl":[[210,0]],"id":41419615},{"atl":[[150,1.06],[85,22.12]],"id":41419600}],"con":true,"img":false}]}
{"op":"mcm","clk":"5353447785","pt":1646215138725,"mc":[{"id":"1.195503865","rc":[{"atl":[[390,0.4]],"id":41419595},{"atl":[[150,0]],"id":41419600}],"con":true,"img":false}]}
{"op":"mcm","clk":"5353447814","pt":1646215139241,"mc":[{"id":"1.195503865","rc":[{"atb":[[65,7.43],[90,0]],"id":41419614}],"con":true,"img":false}]}
{"op":"mcm","clk":"5353447833","pt":1646215139552,"mc":[{"id":"1.195503865","rc":[{"atb":[[75,0],[50,4.95]],"id":41419595},{"atl":[[400,3.48],[410,2]],"id":41419595}],"con":true,"img":false}]}
{"op":"mcm","clk":"5353447853","pt":1646215139810,"mc":[{"id":"1.195503865","rc":[{"atb":[[44,19.56],[48,9.9]],"id":41419614}],"con":true,"img":false}]}
{"op":"mcm","clk":"5353447871","pt":1646215140118,"mc":[{"id":"1.195503865","rc":[{"atb":[[40,15.96]],"id":41419595}],"con":true,"img":false}]}
{"op":"mcm","clk":"5353447877","pt":1646215140222,"mc":[{"id":"1.195503865","rc":[{"atb":[[80,2.72],[50,3.23],[55,3.26]],"id":41419614},{"atb":[[42,9.9],[50,8.19]],"id":41419595}],"con":true,"img":false}]}
{"op":"mcm","clk":"5353447890","pt":1646215140535,"mc":[{"id":"1.195503865","rc":[{"atb":[[65,2.72],[46,3.26]],"id":41419595}],"con":true,"img":false}]}
{"op":"mcm","clk":"5353447937","pt":1646215141162,"mc":[{"id":"1.195503865","rc":[{"atl":[[90,4.95],[120,9.9]],"id":41419609},{"atb":[[16.5,4.95],[14.5,9.9]],"id":41419638},{"atb":[[16.5,0],[17,9.9],[18.5,9.05],[19,4.95]],"id":41419605},{"atb":[[8,0],[9,4.95],[8.2,9.9],[8.8,12.66]],"id":41419634},{"atb":[[44,0],[55,0]],"id":41419613},{"atl":[[230,4.95]],"id":28546943},{"atl":[[65,0],[48,3.37]],"id":41419606},{"atl":[[100,0]],"id":41419602},{"atb":[[18,0],[18.5,9.9],[20,12.21],[21,4.95]],"id":41419585},{"atb":[[65,2.47],[70,4.95],[48,0],[50,9.9]],"id":41419614},{"atl":[[200,4.95]],"id":41419652},{"atl":[[65,9.9],[75,0],[48,4.95],[55,2.93]],"id":41419586},{"atl":[[80,4.95],[100,9.9]],"id":41419594},{"atl":[[65,0],[85,0]],"id":41419607},{"atl":[[16.5,4.95],[17.5,9.6],[18.5,9.9],[19.5,0]],"id":41419636},{"atb":[[65,0],[70,9.97],[48,17.98],[50,9.9]],"id":41419615},{"atb":[[16,9.9],[17.5,0],[18,16.58],[15.5,25.35]],"id":41419591},{"atl":[[180,4.95]],"id":41435525},{"atl":[[75,0],[55,2.93]],"id":41419587},{"atl":[[44,4.95],[55,9.9]],"id":41419599},{"atb":[[42,0],[44,9.9],[50,3.23],[55,4.95]],"id":41419595},{"atl":[[42,0],[50,12.36]],"id":41419608},{"atl":[[23,7.2],[27,0]],"id":41419637},{"atb":[[140,4.95],[90,9.18],[100,9.9],[120,0]],"id":41419604},{"atb":[[75,4.95],[55,9.9]],"id":41419616},{"atl":[[32,5.11],[40,0]],"id":41419612},{"atb":[[19.5,9.9],[23,4.95]],"id":41419592},{"atb":[[36,8.9],[38,4.95],[29,0],[30,9.9]],"id":41419588},{"atl":[[65,0],[80,9.9],[85,12.21],[60,7.64]],"id":41419600}],"con":true,"img":false}]}
{"op":"mcm","clk":"5353447946","pt":1646215141218,"mc":[{"id":"1.195503865","rc":[{"atl":[[110,1.45]],"id":41419609},{"atb":[[46,9.9],[60,4.95]],"id":41419613},{"atl":[[75,4.95],[80,2],[95,9.9],[100,0]],"id":41419655},{"atl":[[42,4.95],[50,9.9]],"id":41419606},{"atl":[[130,9.9],[95,6.63]],"id":41419602},{"atb":[[85,9.33],[90,9.9],[110,0],[120,6.28]],"id":41419590},{"atl":[[250,0.63]],"id":41419652},{"atb":[[40,14.71],[42,9.9],[48,3.37],[50,4.95]],"id":41419619},{"atl":[[85,0],[110,0]],"id":41419594},{"atb":[[32,9.9],[38,4.28],[40,4.95],[30,2.72]],"id":41419640},{"atl":[[75,18.81],[55,4.95]],"id":41419607},{"atl":[[230,0]],"id":41435525},{"atl":[[70,9.9],[50,4.95]],"id":41419587},{"atl":[[46,3.52],[60,0]],"id":41419599},{"atl":[[38,4.95],[46,9.9]],"id":41419608},{"atl":[[22,4.95],[26,9.9]],"id":41419637},{"atb":[[70,2.29],[50,14.71]],"id":41419616},{"atl":[[38,9.9],[30,4.95]],"id":41419612},{"atb":[[19,0],[22,19.76]],"id":41419592}],"con":true,"img":false}]}
{"op":"mcm","clk":"5353447955","pt":1646215141318,"mc":[{"id":"1.195503865","rc":[{"atb":[[16,12.21],[14,0]],"id":41419638},{"atl":[[610,2],[990,0]],"id":41419652},{"atl":[[520,2],[930,1.44]],"id":41435525}],"con":true,"img":false}]}
{"op":"mcm","clk":"5353447978","pt":1646215141531,"mc":[{"id":"1.195503865","rc":[{"atb":[[16,0]],"id":41419638},{"atb":[[27,21.17]],"id":41419613},{"atl":[[55,10.01]],"id":41419606},{"atb":[[21,22.86]],"id":41419585},{"atl":[[120,2]],"id":41419586},{"atl":[[44,2.33]],"id":41419636},{"atl":[[170,0]],"id":41419587},{"atl":[[55,29.85]],"id":41419599},{"atl":[[70,2]],"id":41419637},{"atl":[[95,2]],"id":41419612}],"con":true,"img":false}]}
{"op":"mcm","clk":"5353447991","pt":1646215141636,"mc":[{"id":"1.195503865","rc":[{"atl":[[90,6.73]],"id":41419609},{"atb":[[16.5,34.19]],"id":41419638},{"atb":[[9,27.04],[8.8,0]],"id":41419634},{"atb":[[48,3.26]],"id":41419613},{"atl":[[70,2.41],[320,2],[95,24.68]],"id":41419655},{"atl":[[270,10.14],[570,2],[230,5.64]],"id":28546943},{"atl":[[42,8.82],[95,2]],"id":41419606},{"atb":[[20,0]],"id":41419585},{"atl":[[190,0.83],[990,1.41],[1000,0]],"id":41419652},{"atb":[[40,0],[44,15.09],[55,2.93]],"id":41419619},{"atl":[[65,22.12],[48,8.32]],"id":41419586},{"atl":[[310,2],[100,23.94]],"id":41419594},{"atb":[[32,23.62],[40,9.01],[25,3.26]],"id":41419640},{"atl":[[16.5,15.18],[18.5,38.92]],"id":41419636},{"atl":[[180,5.84],[230,6.09],[930,0]],"id":41435525},{"atl":[[180,9.79]],"id":41419587},{"atl":[[110,2]],"id":41419599},{"atl":[[38,9.23],[50,0],[110,12.91]],"id":41419608},{"atl":[[25,49.67]],"id":41419637},{"atb":[[140,6.09]],"id":41419604},{"atb":[[65,17.43],[80,2],[50,0]],"id":41419616},{"atl":[[36,29.45],[29,5.66]],"id":41419612},{"atb":[[36,0],[38,19.66]],"id":41419588}],"con":true,"img":false}]}
{"op":"mcm","clk":"5353448004","pt":1646215141742,"mc":[{"id":"1.195503865","rc":[{"atl":[[44,8.64]],"id":41419599}],"con":true,"img":false}]}
{"op":"mcm","clk":"5353448013","pt":1646215141845,"mc":[{"id":"1.195503865","rc":[{"atl":[[70,4.95],[75,2.14],[90,9.9],[95,0]],"id":41419585},{"atl":[[270,0.58],[250,4.95]],"id":41419614},{"atl":[[180,4.95],[190,0.83]],"id":41419615},{"atl":[[180,4.95],[200,0]],"id":41419595},{"atl":[[21,7.92]],"id":41419637},{"atl":[[170,4.95],[200,0.79]],"id":41419616},{"atl":[[85,6.83],[90,0],[110,9.9],[120,11.36]],"id":41419592},{"atl":[[130,1.23],[110,4.95]],"id":41419588}],"con":true,"img":false}]}
{"op":"mcm","clk":"5353448020","pt":1646215141951,"mc":[{"id":"1.195503865","rc":[{"atl":[[190,4.95],[220,0.72]],"id":41419613},{"atl":[[860,1.6],[480,2]],"id":41419614}],"con":true,"img":false}]}
{"op":"mcm","clk":"5353448047","pt":1646215142211,"mc":[{"id":"1.195503865","rc":[{"atl":[[130,2],[70,7.25],[90,22.12]],"id":41419585},{"atl":[[250,5.59]],"id":41419614},{"atl":[[170,5.89]],"id":41419616},{"atl":[[110,6.4]],"id":41419588}],"con":true,"img":false}]}
{"op":"mcm","clk":"5353448053","pt":1646215142316,"mc":[{"id":"1.195503865","rc":[{"atl":[[110,0]],"id":41419609},{"atb":[[27,5.12]],"id":41419613},{"atl":[[190,5.79]],"id":41419613},{"atl":[[95,9.9]],"id":41419655},{"atl":[[260,0]],"id":28546943},{"atl":[[48,0]],"id":41419606},{"atb":[[48,0]],"id":41419619},{"atl":[[55,0]],"id":41419586},{"atb":[[38,0]],"id":41419640},{"atl":[[17.5,0]],"id":41419636},{"atl":[[210,0]],"id":41435525},{"atl":[[40,0]],"id":41419608},{"atb":[[130,0],[90,0],[100,20.78]],"id":41419604},{"atl":[[32,0]],"id":41419612}],"con":true,"img":false}]}
{"op":"mcm","clk":"5353448060","pt":1646215142418,"mc":[{"id":"1.195503865","rc":[{"atl":[[250,0]],"id":41419652}],"con":true,"img":false}]}
{"op":"mcm","clk":"5353448078","pt":1646215142625,"mc":[{"id":"1.195503865","rc":[{"atl":[[80,0]],"id":41419655},{"atl":[[180,5.84]],"id":41419615},{"atl":[[46,0]],"id":41419599},{"atl":[[23,0]],"id":41419637},{"atb":[[70,0]],"id":41419616}],"con":true,"img":false}]}
{"op":"mcm","clk":"5353448100","pt":1646215142935,"mc":[{"id":"1.195503865","rc":[{"atl":[[120,21.63],[250,2]],"id":41419609},{"atl":[[75,0]],"id":41419585},{"atl":[[270,0]],"id":41419614}],"con":true,"img":false}]}
{"op":"mcm","clk":"5353448104","pt":1646215143039,"mc":[{"id":"1.195503865","rc":[{"atl":[[200,0]],"id":41419616},{"atl":[[130,0]],"id":41419588}],"con":true,"img":false}]}
{"op":"mcm","clk":"5353448117","pt":1646215143351,"mc":[{"id":"1.195503865","rc":[{"atl":[[220,0]],"id":41419613}],"con":true,"img":false}]}
{"op":"mcm","clk":"5353448134","pt":1646215143657,"mc":[{"id":"1.195503865","rc":[{"atl":[[190,0]],"id":41419615},{"atl":[[190,7.41]],"id":41419616},{"atl":[[130,10.83]],"id":41419588}],"con":true,"img":false}]}
{"op":"mcm","clk":"5353448142","pt":1646215143760,"mc":[{"id":"1.195503865","rc":[{"atl":[[490,2]],"id":41419616},{"atl":[[330,2]],"id":41419588}],"con":true,"img":false}]}
{"op":"mcm","clk":"5353448194","pt":1646215144333,"mc":[{"id":"1.195503865","rc":[{"atl":[[410,5.43],[240,0]],"id":41419613},{"atl":[[270,5.19],[210,4.95],[230,0.69]],"id":28546943},{"atl":[[130,0],[140,9.9],[95,1.68],[100,4.95]],"id":41419602},{"atl":[[250,4.95]],"id":41419614},{"atl":[[190,0],[200,0],[210,4.95]],"id":41419652},{"atl":[[180,0],[190,4.95]],"id":41435525},{"atl":[[180,0],[190,4.95]],"id":41419595},{"atl":[[170,0],[180,4.95],[190,0]],"id":41419616},{"atl":[[130,0]],"id":41419588}],"con":true,"img":false}]}
{"op":"mcm","clk":"5353448202","pt":1646215144438,"mc":[{"id":"1.195503865","rc":[{"atl":[[260,4.95],[860,3.6],[480,0],[250,0]],"id":41419614}],"con":true,"img":false}]}
{"op":"mcm","clk":"5353448243","pt":1646215145057,"mc":[{"id":"1.195503865","rc":[{"atl":[[410,2]],"id":41419613},{"atl":[[260,5.56],[280,5.04],[860,2]],"id":41419614},{"atl":[[600,0.26]],"id":41419652},{"atl":[[200,7.05]],"id":41419615},{"atl":[[220,0.72]],"id":41435525}],"con":true,"img":false}]}
{"op":"mcm","clk":"5353448266","pt":1646215145519,"mc":[{"id":"1.195503865","rc":[{"atb":[[44,3.09]],"id":41419614}],"con":true,"img":false}]}
{"op":"mcm","clk":"5353448276","pt":1646215145728,"mc":[{"id":"1.195503865","rc":[{"atl":[[1000,0.15]],"id":41419616}],"con":true,"img":false}]}
{"op":"mcm","clk":"5353448282","pt":1646215145845,"mc":[{"id":"1.195503865","rc":[{"atb":[[65,13.88]],"id":41419614},{"atl":[[900,2],[490,0]],"id":41419616}],"con":true,"img":false}]}
{"op":"mcm","clk":"5353448391","pt":1646215147958,"mc":[{"id":"1.195503865","rc":[{"atb":[[22,7.54]],"id":41419592}],"con":true,"img":false}]}
{"op":"mcm","clk":"5353448396","pt":1646215148061,"mc":[{"id":"1.195503865","rc":[{"atl":[[180,0],[190,4.95]],"id":41419615},{"atl":[[38,0],[40,4.95],[46,0],[48,9.9]],"id":41419608},{"atb":[[23,22.47]],"id":41419592}],"con":true,"img":false}]}
{"op":"mcm","clk":"5353448439","pt":1646215148735,"mc":[{"id":"1.195503865","rc":[{"atl":[[65,9.9],[120,13.86]],"id":41419586},{"atb":[[32,9.9],[30,16.1]],"id":41419640},{"atl":[[180,0.88],[190,0]],"id":41419615},{"atl":[[55,9.9],[110,14.94]],"id":41419599},{"atl":[[100,1.6]],"id":41419608}],"con":true,"img":false}]}
{"op":"mcm","clk":"5353448446","pt":1646215148940,"mc":[{"id":"1.195503865","rc":[{"atl":[[310,6.58],[100,9.9]],"id":41419594},{"atl":[[18.5,9.9],[44,34.7]],"id":41419636}],"con":true,"img":false}]}
{"op":"mcm","clk":"5353448454","pt":1646215149043,"mc":[{"id":"1.195503865","rc":[{"atb":[[9.2,0],[10.5,0]],"id":41419634}],"con":true,"img":false}]}
{"op":"mcm","clk":"5353448467","pt":1646215149352,"mc":[{"id":"1.195503865","rc":[{"atl":[[130,12.96],[90,9.9]],"id":41419585}],"con":true,"img":false}]}
{"op":"mcm","clk":"5353448472","pt":1646215149454,"mc":[{"id":"1.195503865","rc":[{"atb":[[9,24.76],[5.5,96.55]],"id":41419634},{"atl":[[180,0],[190,4.95]],"id":41419615},{"atb":[[65,15.82],[100,9.9]],"id":41419604},{"atl":[[60,4.95]],"id":41419600}],"con":true,"img":false}]}
{"op":"mcm","clk":"5353448490","pt":1646215149763,"mc":[{"id":"1.195503865","rc":[{"atb":[[9,28.03],[10,2.72]],"id":41419634},{"atl":[[65,4.95],[80,0],[85,22.12],[60,0]],"id":41419600}],"con":true,"img":false}]}
{"op":"mcm","clk":"5353448500","pt":1646215149916,"mc":[{"id":"1.195503865","rc":[{"atb":[[10,38.09],[12.5,16.51]],"id":41419635},{"atb":[[7.6,15.15]],"id":41419612}],"con":true,"img":false}]}
{"op":"mcm","clk":"5353448506","pt":1646215150020,"mc":[{"id":"1.195503865","rc":[{"atl":[[250,7.7]],"id":41419609},{"atb":[[13.5,33.04]],"id":41419612},{"atl":[[130,9.72]],"id":41419588}],"con":true,"img":false}]}
{"op":"mcm","clk":"5353448512","pt":1646215150122,"mc":[{"id":"1.195503865","rc":[{"atl":[[120,9.9]],"id":41419609},{"atb":[[7.6,20.18]],"id":41419635}],"con":true,"img":false}]}
{"op":"mcm","clk":"5353448518","pt":1646215150227,"mc":[{"id":"1.195503865","rc":[{"atl":[[210,0],[220,4.95]],"id":41419652},{"atl":[[65,7.43],[85,9.9]],"id":41419600}],"con":true,"img":false}]}
{"op":"mcm","clk":"5353448526","pt":1646215150328,"mc":[{"id":"1.195503865","rc":[{"atl":[[190,5.79]],"id":41419615},{"atl":[[1000,1.57]],"id":41419616},{"atl":[[160,10.92]],"id":41419600}],"con":true,"img":false}]}
{"op":"mcm","clk":"5353448541","pt":1646215150638,"mc":[{"id":"1.195503865","rc":[{"atb":[[17,38.37],[15.5,2.72]],"id":41419605}],"con":true,"img":false}]}
{"op":"mcm","clk":"5353448567","pt":1646215150948,"mc":[{"id":"1.195503865","rc":[{"atl":[[110,4.95]],"id":41419602},{"atl":[[55,7.89]],"id":41419607}],"con":true,"img":false}]}
{"op":"mcm","clk":"5353448571","pt":1646215151053,"mc":[{"id":"1.195503865","rc":[{"atb":[[19,13.76]],"id":41419605},{"atb":[[11,4.95]],"id":41419635},{"atl":[[140,0],[95,0],[100,0]],"id":41419602}],"con":true,"img":false}]}
{"op":"mcm","clk":"5353448603","pt":1646215151724,"mc":[{"id":"1.195503865","rc":[{"atl":[[60,0]],"id":41419607}],"con":true,"img":false}]}
{"op":"mcm","clk":"5353448613","pt":1646215151931,"mc":[{"id":"1.195503865","rc":[{"atb":[[18.5,0]],"id":41419605},{"atl":[[210,6.81]],"id":41419613},{"atl":[[130,11.01],[360,2],[1000,0.15]],"id":41419602}],"con":true,"img":false}]}
{"op":"mcm","clk":"5353448638","pt":1646215152351,"mc":[{"id":"1.195503865","rc":[{"atl":[[280,0],[860,3.65]],"id":41419614},{"atl":[[140,12.23],[75,9.9]],"id":41419607},{"atl":[[200,0],[460,5.1]],"id":41419615}],"con":true,"img":false}]}
{"op":"mcm","clk":"5353448708","pt":1646215153235,"mc":[{"id":"1.195503865","rc":[{"atl":[[190,0],[200,4.95]],"id":41419613},{"atl":[[210,0],[230,0],[240,4.95]],"id":28546943},{"atl":[[130,15.97],[110,0]],"id":41419602},{"atl":[[260,0],[860,2]],"id":41419614},{"atl":[[1000,0]],"id":41419656},{"atl":[[280,4.95],[220,0]],"id":41419652},{"atl":[[95,0]],"id":41419619},{"atl":[[190,0],[220,4.95],[460,2]],"id":41419615},{"atl":[[1000,0]],"id":41419653},{"atl":[[70,9.9],[44,0],[50,4.95],[55,0]],"id":41419599},{"atl":[[190,0],[210,4.95]],"id":41419595},{"atb":[[9,22.39],[10,0],[9.2,0],[8.2,9.9]],"id":41419637},{"atb":[[12,13.17],[13.5,23.14],[14,4.95],[15.5,0]],"id":41419612},{"atl":[[65,0],[75,4.95],[85,0],[95,9.9]],"id":41419600}],"con":true,"img":false}]}
{"op":"mcm","clk":"5353448728","pt":1646215153542,"mc":[{"id":"1.195503865","rc":[{"atl":[[130,9.9],[80,0],[95,4.95],[100,0]],"id":41419593},{"atl":[[250,4.95]],"id":41419614},{"atl":[[380,0.41]],"id":41419595}],"con":true,"img":false}]}
{"op":"mcm","clk":"5353448732","pt":1646215153645,"mc":[{"id":"1.195503865","rc":[{"atl":[[860,0],[480,2]],"id":41419614}],"con":true,"img":false}]}
{"op":"mcm","clk":"5353448745","pt":1646215153961,"mc":[{"id":"1.195503865","rc":[{"atl":[[190,0.83],[200,0]],"id":41419613},{"atl":[[270,0],[570,4.51],[230,5.64],[240,0]],"id":28546943},{"atl":[[850,0.18],[860,2],[480,0]],"id":41419614},{"atl":[[1000,0.15]],"id":41419656},{"atl":[[280,0],[200,4.95]],"id":41419652},{"atl":[[130,11.05],[390,2],[110,6.4]],"id":41419619},{"atb":[[32,0],[26,0]],"id":41419607},{"atl":[[210,0.75]],"id":41419615},{"atl":[[1000,0.15]],"id":41419653},{"atl":[[65,2.47]],"id":41419599},{"atb":[[8,29.78],[9,2.72],[10,4.95],[9.2,9.9],[8.2,0],[8.4,19.14]],"id":41419637},{"atb":[[12,3.26],[14,12.19]],"id":41419612},{"atl":[[150,1.06]],"id":41419600}],"con":true,"img":false}]}
{"op":"mcm","clk":"5353448758","pt":1646215154170,"mc":[{"id":"1.195503865","rc":[{"atl":[[290,4.95]],"id":41419660},{"atl":[[390,4.09],[400,0]],"id":41419595},{"atb":[[13.5,33.04],[15.5,4.95]],"id":41419612}],"con":true,"img":false}]}
{"op":"mcm","clk":"5353448771","pt":1646215154336,"mc":[{"id":"1.195503865","rc":[{"atl":[[130,0],[80,4.95],[90,1.78],[95,0],[100,9.9]],"id":41419593},{"atl":[[880,2],[1000,0]],"id":41419660},{"atb":[[16.5,38.05]],"id":41419607},{"atl":[[260,5.56],[270,0]],"id":41419611},{"atl":[[390,3.68]],"id":41419595},{"atb":[[19.5,9.9],[23,4.95]],"id":41419600}],"con":true,"img":false}]}
{"op":"mcm","clk":"5353448779","pt":1646215154430,"mc":[{"id":"1.195503865","rc":[{"atb":[[21,12.88]],"id":41419607},{"atl":[[900,2]],"id":41419611},{"atb":[[95,0]],"id":41435525},{"atb":[[19,0],[22,29.63]],"id":41419600},{"atl":[[160,2]],"id":41419600}],"con":true,"img":false}]}
{"op":"mcm","clk":"5353448784","pt":1646215154532,"mc":[{"id":"1.195503865","rc":[{"atl":[[260,4.95],[250,0]],"id":41419614},{"atl":[[880,0],[990,2.15]],"id":41419660},{"atl":[[990,1.38]],"id":41419611},{"atl":[[150,10.65]],"id":41419600}],"con":true,"img":false}]}
{"op":"mcm","clk":"5353448790","pt":1646215154636,"mc":[{"id":"1.195503865","rc":[{"atl":[[190,5.79]],"id":41419613},{"atl":[[200,0],[210,4.95]],"id":41419652},{"atl":[[130,0]],"id":41419619},{"atl":[[1000,1.43]],"id":41419660},{"atb":[[32,2.72],[26,3.26]],"id":41419607},{"atb":[[40,3.41],[50,14.13]],"id":41419595},{"atb":[[9,12.63],[9.8,4.95]],"id":41419637}],"con":true,"img":false}]}
{"op":"mcm","clk":"5353448797","pt":1646215154739,"mc":[{"id":"1.195503865","rc":[{"atb":[[10,0],[9.2,0]],"id":41419637}],"con":true,"img":false}]}
{"op":"mcm","clk":"5353448806","pt":1646215154842,"mc":[{"id":"1.195503865","rc":[{"atl":[[100,22.12],[200,2]],"id":41419593},{"atl":[[290,0]],"id":41419660},{"atl":[[280,5.13],[990,0]],"id":41419611},{"atb":[[22,7.54],[23,17.17]],"id":41419600}],"con":true,"img":false}]}
{"op":"mcm","clk":"5353448812","pt":1646215154944,"mc":[{"id":"1.195503865","rc":[{"atb":[[70,26.33]],"id":41435525}],"con":true,"img":false}]}
{"op":"mcm","clk":"5353448820","pt":1646215155049,"mc":[{"id":"1.195503865","rc":[{"atl":[[990,0.15],[1000,3.43]],"id":41419660},{"atb":[[75,0]],"id":41435525}],"con":true,"img":false}]}
{"op":"mcm","clk":"5353448827","pt":1646215155151,"mc":[{"id":"1.195503865","rc":[{"atl":[[80,0],[85,4.95],[100,12.21],[110,9.9]],"id":41419593},{"atb":[[90,6.73]],"id":41435525}],"con":true,"img":false}]}
