{"op":"mcm","clk":"5317728515","pt":1646251399897,"mc":[{"id":"1.195532868","marketDefinition":{"bspMarket":true,"turnInPlayEnabled":false,"persistenceEnabled":false,"marketBaseRate":5.0,"eventId":"31275720","eventTypeId":"4339","numberOfWinners":1,"bettingType":"ODDS","marketType":"WIN","marketTime":"2022-03-03T16:28:00.000Z","suspendTime":"2022-03-03T16:28:00.000Z","bspReconciled":false,"complete":true,"inPlay":false,"crossMatching":false,"runnersVoidable":false,"numberOfActiveRunners":6,"betDelay":0,"status":"OPEN","runners":[{"status":"ACTIVE","sortPriority":1,"id":42142047,"name":"1. Underground Girl"},{"status":"ACTIVE","sortPriority":2,"id":36909993,"name":"2. Brosna Misty"},{"status":"ACTIVE","sortPriority":3,"id":42609835,"name":"3. Slaneyside Nally"},{"status":"ACTIVE","sortPriority":4,"id":2441997,"name":"4. Fine Line"},{"status":"ACTIVE","sortPriority":5,"id":40302111,"name":"5. Urry Up Alex"},{"status":"ACTIVE","sortPriority":6,"id":40133336,"name":"6. Mayses Stan"}],"regulators":["MR_INT"],"venue":"Romford","countryCode":"GB","discountAllowed":false,"timezone":"Europe/London","openDate":"2022-03-03T13:57:00.000Z","version":4384107320,"name":"A5 400m","eventName":"Romford 3rd Mar"},"rc":[],"con":true,"img":false}]}
{"op":"mcm","clk":"5317728865","pt":1646251401771,"mc":[{"id":"1.195532868","marketDefinition":{"bspMarket":true,"turnInPlayEnabled":false,"persistenceEnabled":false,"marketBaseRate":5.0,"eventId":"31275720","eventTypeId":"4339","numberOfWinners":1,"bettingType":"ODDS","marketType":"WIN","marketTime":"2022-03-03T16:28:00.000Z","suspendTime":"2022-03-03T16:28:00.000Z","bspReconciled":false,"complete":true,"inPlay":false,"crossMatching":false,"runnersVoidable":false,"numberOfActiveRunners":6,"betDelay":0,"status":"OPEN","runners":[{"status":"ACTIVE","sortPriority":1,"id":42142047,"name":"1. Underground Girl"},{"status":"ACTIVE","sortPriority":2,"id":36909993,"name":"2. Brosna Misty"},{"status":"ACTIVE","sortPriority":3,"id":42609835,"name":"3. Slaneyside Nally"},{"status":"ACTIVE","sortPriority":4,"id":2441997,"name":"4. Fine Line"},{"status":"ACTIVE","sortPriority":5,"id":40302111,"name":"5. Urry Up Alex"},{"status":"ACTIVE","sortPriority":6,"id":40133336,"name":"6. Mayses Stan"}],"regulators":["MR_INT"],"venue":"Romford","countryCode":"GB","discountAllowed":true,"timezone":"Europe/London","openDate":"2022-03-03T13:57:00.000Z","version":4384107320,"name":"A5 400m","eventName":"Romford 3rd Mar"},"rc":[],"con":true,"img":false}]}
{"op":"mcm","clk":"5318486304","pt":1646259100274,"mc":[{"id":"1.195532868","rc":[{"atl":[[560,3]],"id":40302111},{"spn":1.0,"spf":"NaN","id":40302111},{"atb":[[1.12,30]],"id":2441997},{"atl":[[270,3]],"id":2441997},{"spn":135.56,"spf":"NaN","id":2441997},{"atb":[[1.12,30]],"id":36909993},{"atl":[[390,3]],"id":36909993},{"spn":195.56,"spf":"NaN","id":36909993},{"atb":[[1.12,30]],"id":42142047},{"atl":[[370,3]],"id":42142047},{"spn":185.56,"spf":"NaN","id":42142047},{"atb":[[1.12,30]],"id":42609835},{"atl":[[550,3]],"id":42609835},{"spn":275.56,"spf":"NaN","id":42609835},{"atl":[[500,3]],"id":40133336},{"spn":1.0,"spf":"NaN","id":40133336}],"con":true,"img":false}]}
{"op":"mcm","clk":"5318486312","pt":1646259100431,"mc":[{"id":"1.195532868","rc":[{"atb":[[1.12,30]],"id":40302111},{"atb":[[1.14,30]],"id":40133336}],"con":true,"img":false}]}
{"op":"mcm","clk":"5318509026","pt":1646259402463,"mc":[{"id":"1.195532868","marketDefinition":{"bspMarket":true,"turnInPlayEnabled":false,"persistenceEnabled":false,"marketBaseRate":5.0,"eventId":"31275720","eventTypeId":"4339","numberOfWinners":1,"bettingType":"ODDS","marketType":"WIN","marketTime":"2022-03-03T16:28:00.000Z","suspendTime":"2022-03-03T16:28:00.000Z","bspReconciled":false,"complete":true,"inPlay":false,"crossMatching":false,"runnersVoidable":false,"numberOfActiveRunners":6,"betDelay":0,"status":"OPEN","runners":[{"status":"ACTIVE","sortPriority":1,"id":42142047,"name":"1. Underground Girl"},{"status":"ACTIVE","sortPriority":2,"id":36909993,"name":"2. Brosna Misty"},{"status":"ACTIVE","sortPriority":3,"id":42609835,"name":"3. Slaneyside Nally"},{"status":"ACTIVE","sortPriority":4,"id":2441997,"name":"4. Fine Line"},{"status":"ACTIVE","sortPriority":5,"id":40302111,"name":"5. Urry Up Alex"},{"status":"ACTIVE","sortPriority":6,"id":40133336,"name":"6. Mayses Stan"}],"regulators":["MR_INT"],"venue":"Romford","countryCode":"GB","discountAllowed":true,"timezone":"Europe/London","openDate":"2022-03-03T13:57:00.000Z","version":4384107320,"name":"A5 400m","eventName":"Romford 3rd Mar"},"rc":[{"atb":[[1.12,30]],"id":40302111},{"atl":[[560,3]],"id":40302111},{"spn":280.56,"spf":"NaN","id":40302111},{"atb":[[1.12,30]],"id":2441997},{"atl":[[270,3]],"id":2441997},{"spn":135.56,"spf":"NaN","id":2441997},{"atb":[[1.12,30]],"id":36909993},{"atl":[[390,3]],"id":36909993},{"spn":195.56,"spf":"NaN","id":36909993},{"atb":[[1.12,30]],"id":42142047},{"atl":[[370,3]],"id":42142047},{"spn":185.56,"spf":"NaN","id":42142047},{"atb":[[1.12,30]],"id":42609835},{"atl":[[550,3]],"id":42609835},{"spn":275.56,"spf":"NaN","id":42609835},{"atb":[[1.14,30]],"id":40133336},{"atl":[[500,3]],"id":40133336},{"spn":250.57,"spf":"NaN","id":40133336}],"con":true,"img":true}]}
{"op":"mcm","clk":"5320139882","pt":1646287411052,"mc":[{"id":"1.195532868","rc":[{"atb":[[2,10.03]],"id":40302111},{"spn":281.0,"spf":"NaN","id":40302111},{"atb":[[2.02,9.29]],"id":2441997},{"spn":136.01,"spf":"NaN","id":2441997},{"atb":[[2.04,12.79]],"id":36909993},{"spn":196.02,"spf":"NaN","id":36909993},{"atb":[[2.04,9.38]],"id":42142047},{"spn":186.02,"spf":"NaN","id":42142047},{"atb":[[2.06,10.33]],"id":42609835},{"spn":276.03,"spf":"NaN","id":42609835},{"atb":[[2.04,11.94]],"id":40133336},{"spn":251.02,"spf":"NaN","id":40133336}],"con":true,"img":false}]}
{"op":"mcm","clk":"5320524486","pt":1646296955753,"mc":[{"id":"1.195532868","rc":[{"atb":[[2,10.04]],"id":40302111},{"spl":[[6.6,10]],"id":40302111},{"spn":4.3,"spf":1.0,"id":40302111},{"atb":[[2.02,9.29]],"id":2441997},{"spl":[[10,10]],"id":2441997},{"spn":6.01,"spf":1.0,"id":2441997},{"atb":[[2.04,12.8]],"id":36909993},{"spl":[[6.6,10]],"id":36909993},{"spn":4.32,"spf":1.0,"id":36909993},{"atb":[[2.04,9.38]],"id":42142047},{"spl":[[18.5,10]],"id":42142047},{"spn":10.27,"spf":1.0,"id":42142047},{"atb":[[2.06,10.33]],"id":42609835},{"spl":[[10,10]],"id":42609835},{"spn":6.03,"spf":1.0,"id":42609835},{"atb":[[2.04,11.94]],"id":40133336},{"spl":[[36,10]],"id":40133336},{"spn":19.02,"spf":1.0,"id":40133336}],"con":true,"img":false}]}
{"op":"mcm","clk":"5320534926","pt":1646297165642,"mc":[{"id":"1.195532868","rc":[{"spb":[[1000,10]],"id":36909993},{"spn":6.6,"spf":6.6,"id":36909993}],"con":true,"img":false}]}
{"op":"mcm","clk":"5320684919","pt":1646299896570,"mc":[{"id":"1.195532868","rc":[{"spl":[[21,1]],"id":40302111},{"spl":[[21,1]],"id":2441997},{"spl":[[21,1]],"id":36909993},{"spl":[[21,1]],"id":42142047},{"spl":[[21,1]],"id":42609835},{"spl":[[21,1]],"id":40133336},{"spn":11.52,"spf":1.0,"id":40133336}],"con":true,"img":false}]}
{"op":"mcm","clk":"5320830254","pt":1646302602577,"mc":[{"id":"1.195532868","marketDefinition":{"bspMarket":true,"turnInPlayEnabled":false,"persistenceEnabled":false,"marketBaseRate":5.0,"eventId":"31275720","eventTypeId":"4339","numberOfWinners":1,"bettingType":"ODDS","marketType":"WIN","marketTime":"2022-03-03T16:28:00.000Z","suspendTime":"2022-03-03T16:28:00.000Z","bspReconciled":false,"complete":true,"inPlay":false,"crossMatching":false,"runnersVoidable":false,"numberOfActiveRunners":6,"betDelay":0,"status":"OPEN","runners":[{"status":"ACTIVE","sortPriority":1,"id":42142047,"name":"1. Underground Girl"},{"status":"ACTIVE","sortPriority":2,"id":36909993,"name":"2. Brosna Misty"},{"status":"ACTIVE","sortPriority":3,"id":42609835,"name":"3. Slaneyside Nally"},{"status":"ACTIVE","sortPriority":4,"id":2441997,"name":"4. Fine Line"},{"status":"ACTIVE","sortPriority":5,"id":40302111,"name":"5. Urry Up Alex"},{"status":"ACTIVE","sortPriority":6,"id":40133336,"name":"6. Mayses Stan"}],"regulators":["MR_INT"],"venue":"Romford","countryCode":"GB","discountAllowed":true,"timezone":"Europe/London","openDate":"2022-03-03T13:57:00.000Z","version":4384107320,"name":"A5 400m","eventName":"Romford 3rd Mar"},"rc":[{"atb":[[2,10.03],[1.12,30]],"id":40302111},{"spl":[[21,1],[6.6,10]],"id":40302111},{"atl":[[560,3]],"id":40302111},{"spn":4.3,"spf":1.0,"id":40302111},{"atb":[[1.12,30],[2.02,9.29]],"id":2441997},{"spl":[[10,10],[21,1]],"id":2441997},{"atl":[[270,3]],"id":2441997},{"spn":6.01,"spf":1.0,"id":2441997},{"atb":[[1.12,30],[2.04,12.79]],"id":36909993},{"spl":[[21,1],[6.6,10]],"id":36909993},{"atl":[[390,3]],"id":36909993},{"spb":[[1000,10]],"id":36909993},{"spn":6.6,"spf":6.6,"id":36909993},{"atb":[[1.12,30],[2.04,9.38]],"id":42142047},{"spl":[[18.5,10],[21,1]],"id":42142047},{"atl":[[370,3]],"id":42142047},{"spn":10.27,"spf":1.0,"id":42142047},{"atb":[[1.12,30],[2.06,10.33]],"id":42609835},{"spl":[[10,10],[21,1]],"id":42609835},{"atl":[[550,3]],"id":42609835},{"spn":6.03,"spf":1.0,"id":42609835},{"atb":[[2.04,11.94],[1.14,30]],"id":40133336},{"spl":[[36,10],[21,1]],"id":40133336},{"atl":[[500,3]],"id":40133336},{"spn":11.52,"spf":1.0,"id":40133336}],"con":true,"img":true}]}
{"op":"mcm","clk":"5321026669","pt":1646305302074,"mc":[{"id":"1.195532868","rc":[{"atb":[[2,10.04],[10,2]],"id":40302111},{"spn":6.6,"spf":1.0,"id":40302111},{"atb":[[2.02,9.29],[3.9,2]],"id":2441997},{"spn":6.95,"spf":1.0,"id":2441997},{"atb":[[2.04,12.79],[3.3,2]],"id":36909993},{"atb":[[2.04,9.38],[7.8,2]],"id":42142047},{"spn":13.15,"spf":1.0,"id":42142047},{"atb":[[2.06,10.33],[6.8,2]],"id":42609835},{"spn":8.4,"spf":1.0,"id":42609835},{"atb":[[5,2],[2.04,11.94]],"id":40133336},{"spn":13.0,"spf":1.0,"id":40133336}],"con":true,"img":false}]}
{"op":"mcm","clk":"5321028073","pt":1646305320234,"mc":[{"id":"1.195532868","marketDefinition":{"bspMarket":true,"turnInPlayEnabled":false,"persistenceEnabled":false,"marketBaseRate":5.0,"eventId":"31275720","eventTypeId":"4339","numberOfWinners":1,"bettingType":"ODDS","marketType":"WIN","marketTime":"2022-03-03T16:28:00.000Z","suspendTime":"2022-03-03T16:28:00.000Z","bspReconciled":false,"complete":true,"inPlay":false,"crossMatching":true,"runnersVoidable":false,"numberOfActiveRunners":6,"betDelay":0,"status":"OPEN","runners":[{"status":"ACTIVE","sortPriority":1,"id":42142047,"name":"1. Underground Girl"},{"status":"ACTIVE","sortPriority":2,"id":36909993,"name":"2. Brosna Misty"},{"status":"ACTIVE","sortPriority":3,"id":42609835,"name":"3. Slaneyside Nally"},{"status":"ACTIVE","sortPriority":4,"id":2441997,"name":"4. Fine Line"},{"status":"ACTIVE","sortPriority":5,"id":40302111,"name":"5. Urry Up Alex"},{"status":"ACTIVE","sortPriority":6,"id":40133336,"name":"6. Mayses Stan"}],"regulators":["MR_INT"],"venue":"Romford","countryCode":"GB","discountAllowed":true,"timezone":"Europe/London","openDate":"2022-03-03T13:57:00.000Z","version":4384107320,"name":"A5 400m","eventName":"Romford 3rd Mar"},"rc":[],"con":true,"img":false}]}
{"op":"mcm","clk":"5321084611","pt":1646305982794,"mc":[{"id":"1.195532868","rc":[{"atb":[[9.6,1.17]],"id":40302111},{"atl":[[29,0.37]],"id":40302111},{"atb":[[3.55,2]],"id":2441997},{"atl":[[6.2,1.93]],"id":2441997},{"spn":5.05,"spf":1.0,"id":2441997},{"atb":[[3.05,2]],"id":36909993},{"atl":[[5,2]],"id":36909993},{"spn":5.98,"spf":6.6,"id":36909993},{"atb":[[6.2,1.93]],"id":42142047},{"atl":[[13.5,0.81]],"id":42142047},{"spn":10.65,"spf":1.0,"id":42142047},{"atb":[[5.6,2]],"id":42609835},{"atl":[[12,0.92]],"id":42609835},{"atb":[[4.3,2]],"id":40133336},{"atl":[[8.4,1.36]],"id":40133336},{"spn":6.7,"spf":1.0,"id":40133336}],"con":true,"img":false}]}
{"op":"mcm","clk":"5321275589","pt":1646307938517,"mc":[{"id":"1.195532868","rc":[{"atl":[[29,0]],"id":40302111},{"atl":[[13.5,0]],"id":42142047},{"spn":13.15,"spf":1.0,"id":42142047},{"atl":[[12,0]],"id":42609835},{"atl":[[8.4,0]],"id":40133336},{"spn":13.0,"spf":1.0,"id":40133336}],"con":true,"img":false}]}
{"op":"mcm","clk":"5321275598","pt":1646307938617,"mc":[{"id":"1.195532868","rc":[{"atl":[[28,0.38]],"id":40302111},{"atl":[[13,0.84]],"id":42142047},{"atl":[[11.5,0.96]],"id":42609835},{"atl":[[8.2,1.4]],"id":40133336}],"con":true,"img":false}]}
{"op":"mcm","clk":"5321282928","pt":1646308002551,"mc":[{"id":"1.195532868","marketDefinition":{"bspMarket":true,"turnInPlayEnabled":false,"persistenceEnabled":false,"marketBaseRate":5.0,"eventId":"31275720","eventTypeId":"4339","numberOfWinners":1,"bettingType":"ODDS","marketType":"WIN","marketTime":"2022-03-03T16:28:00.000Z","suspendTime":"2022-03-03T16:28:00.000Z","bspReconciled":false,"complete":true,"inPlay":false,"crossMatching":true,"runnersVoidable":false,"numberOfActiveRunners":6,"betDelay":0,"status":"OPEN","runners":[{"status":"ACTIVE","sortPriority":1,"id":42142047,"name":"1. Underground Girl"},{"status":"ACTIVE","sortPriority":2,"id":36909993,"name":"2. Brosna Misty"},{"status":"ACTIVE","sortPriority":3,"id":42609835,"name":"3. Slaneyside Nally"},{"status":"ACTIVE","sortPriority":4,"id":2441997,"name":"4. Fine Line"},{"status":"ACTIVE","sortPriority":5,"id":40302111,"name":"5. Urry Up Alex"},{"status":"ACTIVE","sortPriority":6,"id":40133336,"name":"6. Mayses Stan"}],"regulators":["MR_INT"],"venue":"Romford","countryCode":"GB","discountAllowed":true,"timezone":"Europe/London","openDate":"2022-03-03T13:57:00.000Z","version":4384107320,"name":"A5 400m","eventName":"Romford 3rd Mar"},"rc":[{"atb":[[9.6,1.17],[2,10.04],[1.12,30],[10,2]],"id":40302111},{"spl":[[21,1],[6.6,10]],"id":40302111},{"atl":[[560,3],[28,0.38]],"id":40302111},{"spn":6.6,"spf":1.0,"id":40302111},{"atb":[[1.12,30],[2.02,9.29],[3.55,2],[3.9,2]],"id":2441997},{"spl":[[10,10],[21,1]],"id":2441997},{"atl":[[270,3],[6.2,1.93]],"id":2441997},{"spn":5.05,"spf":1.0,"id":2441997},{"atb":[[1.12,30],[2.04,12.79],[3.3,2],[3.05,2]],"id":36909993},{"spl":[[21,1],[6.6,10]],"id":36909993},{"atl":[[5,2],[390,3]],"id":36909993},{"spb":[[1000,10]],"id":36909993},{"spn":5.98,"spf":6.6,"id":36909993},{"atb":[[1.12,30],[6.2,1.93],[2.04,9.38],[7.8,2]],"id":42142047},{"spl":[[18.5,10],[21,1]],"id":42142047},{"atl":[[370,3],[13,0.84]],"id":42142047},{"spn":10.4,"spf":1.0,"id":42142047},{"atb":[[5.6,2],[1.12,30],[2.06,10.33],[6.8,2]],"id":42609835},{"spl":[[10,10],[21,1]],"id":42609835},{"atl":[[550,3],[11.5,0.96]],"id":42609835},{"spn":8.4,"spf":1.0,"id":42609835},{"atb":[[4.3,2],[5,2],[2.04,11.94],[1.14,30]],"id":40133336},{"spl":[[36,10],[21,1]],"id":40133336},{"atl":[[8.2,1.4],[500,3]],"id":40133336},{"spn":6.6,"spf":1.0,"id":40133336}],"con":true,"img":true}]}
{"op":"mcm","clk":"5321611528","pt":1646311529037,"mc":[{"id":"1.195532868","rc":[{"atl":[[1000,10]],"id":40302111},{"atl":[[1000,10]],"id":2441997},{"atl":[[1000,10]],"id":36909993},{"atl":[[1000,10]],"id":42142047},{"spn":10.4,"spf":1.0,"id":42142047},{"atl":[[1000,10]],"id":42609835},{"atl":[[1000,10]],"id":40133336},{"spn":6.6,"spf":1.0,"id":40133336}],"con":true,"img":false}]}
{"op":"mcm","clk":"5321611561","pt":1646311529356,"mc":[{"id":"1.195532868","rc":[{"atb":[[1.01,1000]],"id":40302111},{"atb":[[1.01,1000]],"id":2441997},{"atb":[[1.01,1000]],"id":36909993},{"atb":[[1.01,1000]],"id":42142047},{"atb":[[1.01,1000]],"id":42609835},{"atb":[[1.01,1000]],"id":40133336}],"con":true,"img":false}]}
{"op":"mcm","clk":"5321611610","pt":1646311529863,"mc":[{"id":"1.195532868","rc":[{"atb":[[1.01,11000]],"id":40302111},{"atb":[[1.01,11000]],"id":2441997},{"atb":[[1.01,11000]],"id":36909993},{"atb":[[1.01,11000]],"id":42142047},{"atb":[[1.01,11000]],"id":42609835},{"atb":[[1.01,11000]],"id":40133336}],"con":true,"img":false}]}
{"op":"mcm","clk":"5321684433","pt":1646312216445,"mc":[{"id":"1.195532868","rc":[{"atl":[[1000,12]],"id":42142047}],"con":true,"img":false}]}
{"op":"mcm","clk":"5321684536","pt":1646312217793,"mc":[{"id":"1.195532868","rc":[{"atl":[[1000,12.2]],"id":42142047}],"con":true,"img":false}]}
{"op":"mcm","clk":"5321684624","pt":1646312219098,"mc":[{"id":"1.195532868","rc":[{"atl":[[1000,12]],"id":42142047}],"con":true,"img":false}]}
{"op":"mcm","clk":"5321684639","pt":1646312219153,"mc":[{"id":"1.195532868","rc":[{"atl":[[16.5,0.2]],"id":42142047}],"con":true,"img":false}]}
{"op":"mcm","clk":"5321685094","pt":1646312224670,"mc":[{"id":"1.195532868","rc":[{"atl":[[1000,12]],"id":36909993}],"con":true,"img":false}]}
{"op":"mcm","clk":"5321685207","pt":1646312225968,"mc":[{"id":"1.195532868","rc":[{"atl":[[1000,12.2]],"id":36909993}],"con":true,"img":false}]}
{"op":"mcm","clk":"5321685314","pt":1646312227310,"mc":[{"id":"1.195532868","rc":[{"atl":[[1000,12]],"id":36909993}],"con":true,"img":false}]}
{"op":"mcm","clk":"5321685323","pt":1646312227375,"mc":[{"id":"1.195532868","rc":[{"atl":[[8,0.2]],"id":36909993}],"con":true,"img":false}]}
{"op":"mcm","clk":"5321685428","pt":1646312228709,"mc":[{"id":"1.195532868","rc":[{"atl":[[1000,12]],"id":42609835}],"con":true,"img":false}]}
{"op":"mcm","clk":"5321685552","pt":1646312230009,"mc":[{"id":"1.195532868","rc":[{"atl":[[1000,12.2]],"id":42609835}],"con":true,"img":false}]}
{"op":"mcm","clk":"5321685674","pt":1646312231306,"mc":[{"id":"1.195532868","rc":[{"atl":[[1000,12]],"id":42609835}],"con":true,"img":false}]}
{"op":"mcm","clk":"5321685682","pt":1646312231411,"mc":[{"id":"1.195532868","rc":[{"atl":[[15,0.2]],"id":42609835}],"con":true,"img":false}]}
{"op":"mcm","clk":"5321685819","pt":1646312232806,"mc":[{"id":"1.195532868","rc":[{"atl":[[1000,12]],"id":2441997}],"con":true,"img":false}]}
{"op":"mcm","clk":"5321685932","pt":1646312234099,"mc":[{"id":"1.195532868","rc":[{"atl":[[1000,12.2]],"id":2441997}],"con":true,"img":false}]}
{"op":"mcm","clk":"5321686037","pt":1646312235491,"mc":[{"id":"1.195532868","rc":[{"atl":[[1000,12]],"id":2441997}],"con":true,"img":false}]}
{"op":"mcm","clk":"5321686044","pt":1646312235592,"mc":[{"id":"1.195532868","rc":[{"atl":[[10.5,0.2]],"id":2441997}],"con":true,"img":false}]}
{"op":"mcm","clk":"5321686254","pt":1646312238295,"mc":[{"id":"1.195532868","rc":[{"atl":[[1000,12]],"id":40302111}],"con":true,"img":false}]}
{"op":"mcm","clk":"5321686353","pt":1646312239633,"mc":[{"id":"1.195532868","rc":[{"atl":[[1000,12.2]],"id":40302111}],"con":true,"img":false}]}
{"op":"mcm","clk":"5321686475","pt":1646312241037,"mc":[{"id":"1.195532868","rc":[{"atl":[[1000,12]],"id":40302111}],"con":true,"img":false}]}
{"op":"mcm","clk":"5321686486","pt":1646312241140,"mc":[{"id":"1.195532868","rc":[{"atl":[[27,0.2]],"id":40302111}],"con":true,"img":false}]}
{"op":"mcm","clk":"5321686670","pt":1646312243318,"mc":[{"id":"1.195532868","rc":[{"atl":[[1000,12]],"id":40133336}],"con":true,"img":false}]}
{"op":"mcm","clk":"5321686805","pt":1646312244628,"mc":[{"id":"1.195532868","rc":[{"atl":[[1000,12.2]],"id":40133336}],"con":true,"img":false}]}
{"op":"mcm","clk":"5321686912","pt":1646312245915,"mc":[{"id":"1.195532868","rc":[{"atl":[[1000,12]],"id":40133336}],"con":true,"img":false}]}
{"op":"mcm","clk":"5321686922","pt":1646312246018,"mc":[{"id":"1.195532868","rc":[{"atl":[[11,0.2]],"id":40133336}],"con":true,"img":false}]}
{"op":"mcm","clk":"5321759552","pt":1646312966592,"mc":[{"id":"1.195532868","rc":[{"atb":[[2,10.03]],"id":40302111},{"spb":[[1000,29.45]],"id":40302111},{"spn":6.93,"spf":6.6,"id":40302111},{"atb":[[2.02,9.28]],"id":2441997},{"atb":[[2.04,12.79]],"id":36909993},{"spn":5.54,"spf":6.6,"id":36909993},{"atb":[[2.04,9.38]],"id":42142047},{"atb":[[2.06,10.33]],"id":42609835},{"atb":[[2.04,11.93]],"id":40133336}],"con":true,"img":false}]}
{"op":"mcm","clk":"5321806420","pt":1646313394309,"mc":[{"id":"1.195532868","rc":[{"atb":[[1.03,2.99]],"id":40302111}],"con":true,"img":false}]}
{"op":"mcm","clk":"5321806471","pt":1646313394829,"mc":[{"id":"1.195532868","rc":[{"atb":[[1.03,0.56]],"id":40302111}],"con":true,"img":false}]}
{"op":"mcm","clk":"5321806526","pt":1646313395404,"mc":[{"id":"1.195532868","rc":[{"atb":[[1.03,0]],"id":40302111}],"con":true,"img":false}]}
{"op":"mcm","clk":"5321806534","pt":1646313395508,"mc":[{"id":"1.195532868","rc":[{"atb":[[3.8,0.56]],"id":40302111}],"con":true,"img":false}]}
{"op":"mcm","clk":"5321865622","pt":1646313910583,"mc":[{"id":"1.195532868","rc":[{"spn":7.04,"spf":6.6,"id":40302111},{"atl":[[1000,12.2]],"id":36909993}],"con":true,"img":false}]}
{"op":"mcm","clk":"5321865643","pt":1646313910890,"mc":[{"id":"1.195532868","rc":[{"atl":[[1000,12]],"id":36909993}],"con":true,"img":false}]}
{"op":"mcm","clk":"5321865652","pt":1646313910994,"mc":[{"id":"1.195532868","rc":[{"atb":[[3.3,1.8]],"id":36909993},{"trd":[[3.3,0.4]],"ltp":3.3,"tv":0.4,"id":36909993}],"con":true,"img":false}]}
{"op":"mcm","clk":"5321865670","pt":1646313911200,"mc":[{"id":"1.195532868","rc":[{"atb":[[3.05,0]],"id":36909993}],"con":true,"img":false}]}
{"op":"mcm","clk":"5321865679","pt":1646313911303,"mc":[{"id":"1.195532868","rc":[{"atb":[[2.08,2]],"id":36909993}],"con":true,"img":false}]}
{"op":"mcm","clk":"5321865788","pt":1646313912601,"mc":[{"id":"1.195532868","rc":[{"atb":[[3.3,2]],"id":36909993}],"con":true,"img":false}]}
{"op":"mcm","clk":"5322216944","pt":1646317681325,"mc":[{"id":"1.195532868","rc":[{"atb":[[4.6,25.56],[3.7,37.78],[2.62,64.81]],"id":40302111},{"spn":7.6,"spf":6.6,"id":40302111},{"atl":[[17,9.5]],"id":2441997},{"atl":[[34,15.5]],"id":36909993},{"spn":5.5,"spf":6.6,"id":36909993},{"atb":[[2.62,64.81]],"id":42142047},{"atb":[[2.62,64.81]],"id":42609835},{"atl":[[34,15.5]],"id":40133336}],"con":true,"img":false}]}
{"op":"mcm","clk":"5322216959","pt":1646317681429,"mc":[{"id":"1.195532868","rc":[{"atl":[[34,15.5]],"id":2441997},{"atl":[[17,9.5]],"id":36909993}],"con":true,"img":false}]}
{"op":"mcm","clk":"5322218778","pt":1646317700777,"mc":[{"id":"1.195532868","rc":[{"atb":[[10.5,1.65]],"id":40302111},{"atb":[[3.95,1.65]],"id":2441997},{"atl":[[14.5,1.65]],"id":42609835}],"con":true,"img":false}]}
{"op":"mcm","clk":"5322220456","pt":1646317718808,"mc":[{"id":"1.195532868","rc":[{"atb":[[1.88,115.91],[2.18,77.97]],"id":2441997},{"atl":[[27,9.2]],"id":42609835}],"con":true,"img":false}]}
{"op":"mcm","clk":"5322220465","pt":1646317718905,"mc":[{"id":"1.195532868","rc":[{"atl":[[36,15.2]],"id":42609835}],"con":true,"img":false}]}
{"op":"mcm","clk":"5322244303","pt":1646317994367,"mc":[{"id":"1.195532868","rc":[{"spn":8.83,"spf":6.6,"id":40302111},{"atb":[[2.02,0]],"id":2441997},{"spn":5.07,"spf":1.0,"id":2441997},{"spn":5.46,"spf":6.6,"id":36909993}],"con":true,"img":false}]}
{"op":"mcm","clk":"5322244309","pt":1646317994469,"mc":[{"id":"1.195532868","rc":[{"atb":[[2.2,9.28]],"id":2441997}],"con":true,"img":false}]}
{"op":"mcm","clk":"5322386724","pt":1646319609129,"mc":[{"id":"1.195532868","rc":[{"atb":[[2,10.04],[2.06,165.09],[10.5,1.65],[3.8,0.56]],"id":40302111},{"atl":[[150,5]],"id":40302111},{"spb":[[1000,29.64]],"id":40302111},{"spn":8.84,"spf":6.6,"id":40302111},{"atb":[[2.06,165.09],[3.95,1.65],[2.2,9.3]],"id":2441997},{"atl":[[150,5]],"id":2441997},{"atb":[[2.04,12.8]],"id":36909993},{"atl":[[150,5]],"id":36909993},{"atb":[[2.06,165.09],[2.04,9.39]],"id":42142047},{"atl":[[150,5]],"id":42142047},{"atb":[[2.06,175.43]],"id":42609835},{"atl":[[150,5],[14.5,1.65]],"id":42609835},{"atb":[[2.06,165.09],[2.04,11.95]],"id":40133336},{"atl":[[150,5]],"id":40133336}],"con":true,"img":false}]}
{"op":"mcm","clk":"5322401674","pt":1646319795217,"mc":[{"id":"1.195532868","rc":[{"atb":[[2,0]],"id":40302111},{"atb":[[2.04,0]],"id":42142047},{"atb":[[2.04,0]],"id":40133336}],"con":true,"img":false}]}
{"op":"mcm","clk":"5322401681","pt":1646319795308,"mc":[{"id":"1.195532868","rc":[{"atb":[[2.08,10.04]],"id":40302111},{"atb":[[2.08,9.39]],"id":42142047},{"atb":[[2.08,11.95]],"id":40133336}],"con":true,"img":false}]}
{"op":"mcm","clk":"5322539356","pt":1646321490313,"mc":[{"id":"1.195532868","rc":[{"atb":[[1.02,2.24]],"id":40302111}],"con":true,"img":false}]}
{"op":"mcm","clk":"5322539388","pt":1646321490625,"mc":[{"id":"1.195532868","rc":[{"atb":[[1.02,0.33]],"id":40302111}],"con":true,"img":false}]}
{"op":"mcm","clk":"5322539410","pt":1646321490843,"mc":[{"id":"1.195532868","rc":[{"atb":[[1.02,0]],"id":40302111}],"con":true,"img":false}]}
{"op":"mcm","clk":"5322539420","pt":1646321490945,"mc":[{"id":"1.195532868","rc":[{"atb":[[11,0.33]],"id":40302111}],"con":true,"img":false}]}
{"op":"mcm","clk":"5322608489","pt":1646322324826,"mc":[{"id":"1.195532868","rc":[{"spn":9.1,"spf":6.6,"id":40302111},{"atb":[[2.08,0]],"id":36909993},{"atl":[[13,0]],"id":42142047},{"spn":12.15,"spf":1.0,"id":42142047},{"atl":[[8.2,0]],"id":40133336},{"spn":8.0,"spf":1.0,"id":40133336}],"con":true,"img":false}]}
{"op":"mcm","clk":"5322608510","pt":1646322324991,"mc":[{"id":"1.195532868","rc":[{"atb":[[2.1,2]],"id":36909993},{"atl":[[12.5,0.88]],"id":42142047},{"atl":[[8,1.44]],"id":40133336}],"con":true,"img":false}]}
{"op":"mcm","clk":"5322664717","pt":1646322850774,"mc":[{"id":"1.195532868","rc":[{"atb":[[15,67.88]],"id":40302111},{"spn":15.0,"spf":6.6,"id":40302111},{"spn":10.15,"spf":1.0,"id":42142047},{"spn":6.5,"spf":1.0,"id":40133336}],"con":true,"img":false}]}
{"op":"mcm","clk":"5322665136","pt":1646322855087,"mc":[{"id":"1.195532868","rc":[{"atb":[[10,0]],"id":40302111}],"con":true,"img":false}]}
{"op":"mcm","clk":"5322666123","pt":1646322865479,"mc":[{"id":"1.195532868","rc":[{"atb":[[10.5,0]],"id":40302111}],"con":true,"img":false}]}
{"op":"mcm","clk":"5322684157","pt":1646323085457,"mc":[{"id":"1.195532868","rc":[{"atb":[[8,5.71],[6.8,43.1],[7.2,24.19],[7.6,15.15]],"id":40302111},{"atl":[[32,3.23],[36,4.29],[40,6.41],[29,1.43]],"id":40302111},{"atb":[[3.1,71.43],[3,125],[3.3,17.39],[3.2,45.45]],"id":2441997},{"atl":[[7.4,23.44],[6.6,7.14],[7,16.67],[7.8,36.76]],"id":2441997},{"atb":[[2.82,54.95],[2.86,21.51],[2.74,143.68],[2.78,84.27]],"id":36909993},{"atl":[[5.6,32.61],[5.8,52.08],[5.2,9.52],[5.4,22.73]],"id":36909993},{"spn":5.03,"spf":6.6,"id":36909993},{"atb":[[5.1,9.76],[4.5,71.43],[4.9,25.64],[4.7,40.54]],"id":42142047},{"atl":[[16.5,16.33],[13.5,3.2],[14.5,7.41],[15.5,10.34]],"id":42142047},{"atb":[[5.1,9.76],[4.5,71.43],[4.9,25.64],[4.7,40.54]],"id":42609835},{"atl":[[12.5,3.48],[13.5,8],[14.5,12.76],[15.5,17.24]],"id":42609835},{"atb":[[3.45,102.04],[3.55,58.82],[3.75,14.55],[3.65,37.74]],"id":40133336},{"atl":[[9.6,29.07],[9.2,18.29],[8.8,12.82],[8.4,5.41]],"id":40133336}],"con":true,"img":false}]}
{"op":"mcm","clk":"5322684251","pt":1646323086448,"mc":[{"id":"1.195532868","rc":[{"atb":[[1.07,2.81]],"id":40302111},{"atb":[[1.02,3.05]],"id":2441997},{"atb":[[1.03,3.1]],"id":36909993},{"atb":[[1.03,2.95]],"id":42142047},{"atb":[[1.03,2.95]],"id":42609835},{"atb":[[1.02,3.02]],"id":40133336}],"con":true,"img":false}]}
{"op":"mcm","clk":"5322684291","pt":1646323086867,"mc":[{"id":"1.195532868","rc":[{"atb":[[1.07,0.06]],"id":40302111},{"atb":[[1.02,0.3]],"id":2441997},{"atb":[[1.03,0.35]],"id":36909993},{"atb":[[1.03,0.2]],"id":42142047},{"atb":[[1.03,0.2]],"id":42609835},{"atb":[[1.02,0.27]],"id":40133336}],"con":true,"img":false}]}
{"op":"mcm","clk":"5322684328","pt":1646323087236,"mc":[{"id":"1.195532868","rc":[{"atb":[[1.07,0]],"id":40302111},{"atb":[[1.03,0]],"id":36909993},{"atb":[[1.02,0]],"id":40133336}],"con":true,"img":false}]}
{"op":"mcm","clk":"5322684339","pt":1646323087337,"mc":[{"id":"1.195532868","rc":[{"atb":[[17,0.06]],"id":40302111},{"atb":[[1.02,0]],"id":2441997},{"atb":[[3.1,0.35]],"id":36909993},{"atb":[[1.03,0]],"id":42142047},{"atb":[[1.03,0]],"id":42609835},{"atb":[[4,0.27]],"id":40133336}],"con":true,"img":false}]}
{"op":"mcm","clk":"5322684349","pt":1646323087442,"mc":[{"id":"1.195532868","rc":[{"atb":[[3.6,0.3]],"id":2441997},{"atb":[[5.4,0.2]],"id":42142047},{"atb":[[5.4,0.2]],"id":42609835}],"con":true,"img":false}]}
{"op":"mcm","clk":"5322684898","pt":1646323093545,"mc":[{"id":"1.195532868","rc":[{"atl":[[11,9.2],[14,15.2]],"id":2441997},{"atl":[[11,15.2],[8.6,9.2]],"id":36909993},{"atl":[[18.5,15.2],[14.5,9.2]],"id":40133336}],"con":true,"img":false}]}
{"op":"mcm","clk":"5322685078","pt":1646323096050,"mc":[{"id":"1.195532868","rc":[{"atb":[[6.8,0]],"id":42609835},{"atl":[[6.8,8]],"id":42609835},{"trd":[[6.8,4]],"ltp":6.8,"tv":4.0,"id":42609835}],"con":true,"img":false}]}
{"op":"mcm","clk":"5322685327","pt":1646323099456,"mc":[{"id":"1.195532868","rc":[{"atb":[[2.26,8.9]],"id":36909993},{"atb":[[2.66,6.76]],"id":42609835}],"con":true,"img":false}]}
{"op":"mcm","clk":"5322685344","pt":1646323099551,"mc":[{"id":"1.195532868","rc":[{"atb":[[2.46,7.68]],"id":2441997},{"atb":[[2.7,6.6]],"id":40133336}],"con":true,"img":false}]}
{"op":"mcm","clk":"5322685349","pt":1646323099657,"mc":[{"id":"1.195532868","rc":[{"atb":[[5.6,0]],"id":42609835},{"atl":[[10.5,4.21],[12.5,0]],"id":42609835}],"con":true,"img":false}]}
{"op":"mcm","clk":"5322685370","pt":1646323099864,"mc":[{"id":"1.195532868","rc":[{"atb":[[3.15,2]],"id":42609835}],"con":true,"img":false}]}
{"op":"mcm","clk":"5322685616","pt":1646323103364,"mc":[{"id":"1.195532868","rc":[{"atb":[[2.3,9.56]],"id":36909993}],"con":true,"img":false}]}
{"op":"mcm","clk":"5322685637","pt":1646323103784,"mc":[{"id":"1.195532868","rc":[{"atb":[[2.5,8.29]],"id":2441997},{"atb":[[2.74,7.14]],"id":40133336}],"con":true,"img":false}]}
{"op":"mcm","clk":"5322685657","pt":1646323104078,"mc":[{"id":"1.195532868","rc":[{"atb":[[3.25,5.53]],"id":42609835}],"con":true,"img":false}]}
{"op":"mcm","clk":"5322686046","pt":1646323109090,"mc":[{"id":"1.195532868","rc":[{"atb":[[6.2,1.03]],"id":2441997},{"atl":[[6.2,0]],"id":2441997},{"trd":[[6.2,3.86]],"ltp":6.2,"tv":3.86,"id":2441997}],"con":true,"img":false}]}
{"op":"mcm","clk":"5322686060","pt":1646323109296,"mc":[{"id":"1.195532868","rc":[{"atb":[[3.55,0]],"id":2441997}],"con":true,"img":false}]}
{"op":"mcm","clk":"5322686094","pt":1646323109660,"mc":[{"id":"1.195532868","rc":[{"atl":[[6.6,0],[7,6.56]],"id":2441997},{"atl":[[11.5,10.48]],"id":42609835}],"con":true,"img":false}]}
{"op":"mcm","clk":"5322686812","pt":1646323119687,"mc":[{"id":"1.195532868","rc":[{"atl":[[7.4,6.15],[7,0]],"id":2441997},{"atl":[[12.5,13.04],[15.5,0]],"id":42609835}],"con":true,"img":false}]}
{"op":"mcm","clk":"5322687004","pt":1646323122381,"mc":[{"id":"1.195532868","rc":[{"atb":[[3.95,0]],"id":2441997},{"atl":[[14.5,11.11]],"id":42609835}],"con":true,"img":false}]}
{"op":"mcm","clk":"5322687580","pt":1646323129716,"mc":[{"id":"1.195532868","rc":[{"atl":[[7.4,0],[7.8,5.79]],"id":2441997},{"atl":[[13.5,20],[14.5,0]],"id":42609835}],"con":true,"img":false}]}
{"op":"mcm","clk":"5322687773","pt":1646323131912,"mc":[{"id":"1.195532868","rc":[{"atl":[[11,10.2]],"id":2441997}],"con":true,"img":false}]}
{"op":"mcm","clk":"5322688317","pt":1646323138792,"mc":[{"id":"1.195532868","rc":[{"atb":[[15,62.8],[17,0]],"id":40302111},{"trd":[[15,10.15],[17,0.13]],"ltp":15.0,"tv":10.28,"id":40302111},{"atb":[[7.8,0]],"id":42142047},{"trd":[[7.8,4]],"ltp":7.8,"tv":4.0,"id":42142047}],"con":true,"img":false}]}
{"op":"mcm","clk":"5322688378","pt":1646323139677,"mc":[{"id":"1.195532868","rc":[{"atl":[[8.2,5.47],[7.8,0]],"id":2441997}],"con":true,"img":false}]}
{"op":"mcm","clk":"5322688471","pt":1646323140876,"mc":[{"id":"1.195532868","rc":[{"atl":[[11,1.01]],"id":2441997}],"con":true,"img":false}]}
{"op":"mcm","clk":"5322689231","pt":1646323149737,"mc":[{"id":"1.195532868","rc":[{"atl":[[8.6,5.18],[8.2,0]],"id":2441997},{"spn":7.4,"spf":1.0,"id":2441997},{"spn":9.35,"spf":1.0,"id":42142047},{"spn":6.1,"spf":1.0,"id":42609835}],"con":true,"img":false}]}
{"op":"mcm","clk":"5322690281","pt":1646323159732,"mc":[{"id":"1.195532868","rc":[{"atl":[[8.6,0],[9,4.92]],"id":2441997}],"con":true,"img":false}]}
{"op":"mcm","clk":"5322691201","pt":1646323169774,"mc":[{"id":"1.195532868","rc":[{"atl":[[9,0],[9.4,4.69]],"id":2441997}],"con":true,"img":false}]}
{"op":"mcm","clk":"5322691444","pt":1646323172449,"mc":[{"id":"1.195532868","rc":[{"atb":[[3.7,0]],"id":40302111}],"con":true,"img":false}]}
{"op":"mcm","clk":"5322692099","pt":1646323179778,"mc":[{"id":"1.195532868","rc":[{"atl":[[9.8,4.47],[9.4,0]],"id":2441997}],"con":true,"img":false}]}
{"op":"mcm","clk":"5322692540","pt":1646323185460,"mc":[{"id":"1.195532868","rc":[{"atl":[[9.6,1.65]],"id":2441997}],"con":true,"img":false}]}
{"op":"mcm","clk":"5322692893","pt":1646323189777,"mc":[{"id":"1.195532868","rc":[{"atl":[[10,4.38],[9.8,0]],"id":2441997}],"con":true,"img":false}]}
{"op":"mcm","clk":"5322693596","pt":1646323199793,"mc":[{"id":"1.195532868","rc":[{"atl":[[11,10.85]],"id":2441997}],"con":true,"img":false}]}
{"op":"mcm","clk":"5322694508","pt":1646323209822,"mc":[{"id":"1.195532868","rc":[{"atb":[[11,0.33],[3.8,0.56],[15,62.9],[2.08,10.04]],"id":40302111},{"spb":[[1000,29.74]],"id":40302111},{"trd":[[15,10.15],[17,0.13]],"ltp":15.0,"tv":10.28,"id":40302111},{"atb":[[3.6,0.3],[2.5,8.29],[6.2,1.03],[2.46,7.69],[2.2,9.3]],"id":2441997},{"atl":[[9.6,1.65],[12,13.42]],"id":2441997},{"trd":[[6.2,3.86]],"ltp":6.2,"tv":3.86,"id":2441997},{"spn":7.9,"spf":1.0,"id":2441997},{"atb":[[2.3,9.56],[3.1,0.35],[2.04,12.81],[2.26,8.91]],"id":36909993},{"atb":[[2.08,9.39],[5.4,0.2]],"id":42142047},{"trd":[[7.8,3.99]],"ltp":7.8,"tv":3.99,"id":42142047},{"atb":[[2.06,175.43],[2.66,6.77],[3.25,5.53],[5.4,0.2]],"id":42609835},{"atb":[[2.08,11.95],[4,0.27],[2.74,7.14],[2.7,6.61]],"id":40133336}],"con":true,"img":false}]}
{"op":"mcm","clk":"5322695438","pt":1646323219793,"mc":[{"id":"1.195532868","rc":[{"atl":[[13,20.51]],"id":2441997}],"con":true,"img":false}]}
{"op":"mcm","clk":"5322696031","pt":1646323226427,"mc":[{"id":"1.195532868","rc":[{"spl":[[10,5]],"id":40302111},{"spl":[[10,15]],"id":2441997},{"spl":[[10,5]],"id":36909993},{"spl":[[10,5]],"id":42142047},{"spl":[[10,15]],"id":42609835},{"spl":[[10,5]],"id":40133336}],"con":true,"img":false}]}
{"op":"mcm","clk":"5322705757","pt":1646323334319,"mc":[{"id":"1.195532868","rc":[{"spn":8.1,"spf":1.0,"id":42142047},{"atb":[[2.66,0]],"id":42609835}],"con":true,"img":false}]}
{"op":"mcm","clk":"5322705972","pt":1646323337292,"mc":[{"id":"1.195532868","rc":[{"atb":[[2.46,0]],"id":2441997},{"atb":[[2.26,0]],"id":36909993},{"atb":[[2.7,0]],"id":40133336}],"con":true,"img":false}]}
{"op":"mcm","clk":"5322706844","pt":1646323347827,"mc":[{"id":"1.195532868","rc":[{"atb":[[2.5,0]],"id":2441997}],"con":true,"img":false}]}
{"op":"mcm","clk":"5322710327","pt":1646323391446,"mc":[{"id":"1.195532868","rc":[{"atb":[[2.04,0]],"id":36909993}],"con":true,"img":false}]}
{"op":"mcm","clk":"5322710335","pt":1646323391549,"mc":[{"id":"1.195532868","rc":[{"atb":[[2.32,12.81]],"id":36909993}],"con":true,"img":false}]}
{"op":"mcm","clk":"5322713013","pt":1646323423480,"mc":[{"id":"1.195532868","rc":[{"atl":[[34,15.2],[25,9.2]],"id":42142047},{"atb":[[2.22,83.61],[2.64,56.1]],"id":42609835}],"con":true,"img":false}]}
{"op":"mcm","clk":"5322715956","pt":1646323453527,"mc":[{"id":"1.195532868","rc":[{"atb":[[1.01,11002]],"id":42142047}],"con":true,"img":false}]}
{"op":"mcm","clk":"5322715963","pt":1646323453631,"mc":[{"id":"1.195532868","rc":[{"atb":[[1.01,11003.99]],"id":42142047}],"con":true,"img":false}]}
{"op":"mcm","clk":"5322715972","pt":1646323453736,"mc":[{"id":"1.195532868","rc":[{"atb":[[1.01,11002]],"id":42142047}],"con":true,"img":false}]}
{"op":"mcm","clk":"5322715983","pt":1646323453843,"mc":[{"id":"1.195532868","rc":[{"atb":[[5.5,1.99]],"id":42142047}],"con":true,"img":false}]}
{"op":"mcm","clk":"5322716002","pt":1646323454004,"mc":[{"id":"1.195532868","rc":[{"atb":[[1.88,0],[2.18,0]],"id":2441997},{"atb":[[1.01,11002]],"id":36909993}],"con":true,"img":false}]}
{"op":"mcm","clk":"5322716020","pt":1646323454213,"mc":[{"id":"1.195532868","rc":[{"atb":[[1.01,11003.99]],"id":36909993}],"con":true,"img":false}]}
{"op":"mcm","clk":"5322716028","pt":1646323454311,"mc":[{"id":"1.195532868","rc":[{"atb":[[1.01,11002]],"id":36909993}],"con":true,"img":false}]}
{"op":"mcm","clk":"5322716039","pt":1646323454434,"mc":[{"id":"1.195532868","rc":[{"atb":[[1.02,1.99]],"id":36909993}],"con":true,"img":false}]}
{"op":"mcm","clk":"5322716046","pt":1646323454531,"mc":[{"id":"1.195532868","rc":[{"atb":[[1.01,11002]],"id":42609835}],"con":true,"img":false}]}
{"op":"mcm","clk":"5322716055","pt":1646323454637,"mc":[{"id":"1.195532868","rc":[{"atb":[[1.01,11003.99]],"id":42609835}],"con":true,"img":false}]}
{"op":"mcm","clk":"5322716066","pt":1646323454841,"mc":[{"id":"1.195532868","rc":[{"atb":[[1.01,11002]],"id":42609835}],"con":true,"img":false}]}
{"op":"mcm","clk":"5322716073","pt":1646323454939,"mc":[{"id":"1.195532868","rc":[{"atb":[[5.2,1.99]],"id":42609835}],"con":true,"img":false}]}
{"op":"mcm","clk":"5322716092","pt":1646323455106,"mc":[{"id":"1.195532868","rc":[{"atb":[[1.01,11002]],"id":2441997}],"con":true,"img":false}]}
{"op":"mcm","clk":"5322716106","pt":1646323455314,"mc":[{"id":"1.195532868","rc":[{"atb":[[1.01,11003.99]],"id":2441997}],"con":true,"img":false}]}
{"op":"mcm","clk":"5322716121","pt":1646323455525,"mc":[{"id":"1.195532868","rc":[{"atb":[[1.01,11002]],"id":2441997}],"con":true,"img":false}]}
{"op":"mcm","clk":"5322716128","pt":1646323455627,"mc":[{"id":"1.195532868","rc":[{"atb":[[3.95,1.99]],"id":2441997}],"con":true,"img":false}]}
{"op":"mcm","clk":"5322716139","pt":1646323455730,"mc":[{"id":"1.195532868","rc":[{"atb":[[1.01,11002]],"id":40133336}],"con":true,"img":false}]}
{"op":"mcm","clk":"5322716152","pt":1646323455838,"mc":[{"id":"1.195532868","rc":[{"atb":[[1.01,11003.99]],"id":40133336}],"con":true,"img":false}]}
{"op":"mcm","clk":"5322716170","pt":1646323456044,"mc":[{"id":"1.195532868","rc":[{"atb":[[1.01,11002]],"id":40133336}],"con":true,"img":false}]}
{"op":"mcm","clk":"5322716184","pt":1646323456252,"mc":[{"id":"1.195532868","rc":[{"atb":[[5.1,1.99]],"id":40133336}],"con":true,"img":false}]}
{"op":"mcm","clk":"5322716399","pt":1646323458556,"mc":[{"id":"1.195532868","rc":[{"atb":[[5.5,0]],"id":42142047}],"con":true,"img":false}]}
{"op":"mcm","clk":"5322716408","pt":1646323458657,"mc":[{"id":"1.195532868","rc":[{"atb":[[5.2,1.99]],"id":42142047}],"con":true,"img":false}]}
{"op":"mcm","clk":"5322716666","pt":1646323461332,"mc":[{"id":"1.195532868","rc":[{"atb":[[5.2,0]],"id":42142047}],"con":true,"img":false}]}
{"op":"mcm","clk":"5322716677","pt":1646323461460,"mc":[{"id":"1.195532868","rc":[{"atb":[[5.5,1.99]],"id":42142047}],"con":true,"img":false}]}
{"op":"mcm","clk":"5322716789","pt":1646323462892,"mc":[{"id":"1.195532868","rc":[{"atb":[[5.5,0]],"id":42142047}],"con":true,"img":false}]}
{"op":"mcm","clk":"5322716796","pt":1646323462962,"mc":[{"id":"1.195532868","rc":[{"atb":[[5.2,1.99]],"id":42142047}],"con":true,"img":false}]}
{"op":"mcm","clk":"5322716926","pt":1646323464518,"mc":[{"id":"1.195532868","rc":[{"atb":[[5.2,0]],"id":42142047}],"con":true,"img":false}]}
{"op":"mcm","clk":"5322716936","pt":1646323464619,"mc":[{"id":"1.195532868","rc":[{"atb":[[5.5,1.99]],"id":42142047}],"con":true,"img":false}]}
{"op":"mcm","clk":"5322717004","pt":1646323465347,"mc":[{"id":"1.195532868","rc":[{"atb":[[5.5,0]],"id":42142047}],"con":true,"img":false}]}
{"op":"mcm","clk":"5322717012","pt":1646323465446,"mc":[{"id":"1.195532868","rc":[{"atb":[[5.2,1.99]],"id":42142047}],"con":true,"img":false}]}
{"op":"mcm","clk":"5322717169","pt":1646323467223,"mc":[{"id":"1.195532868","rc":[{"atb":[[5.2,0]],"id":42142047}],"con":true,"img":false}]}
{"op":"mcm","clk":"5322717177","pt":1646323467324,"mc":[{"id":"1.195532868","rc":[{"atb":[[5.5,1.99]],"id":42142047}],"con":true,"img":false}]}
{"op":"mcm","clk":"5322717323","pt":1646323469047,"mc":[{"id":"1.195532868","rc":[{"atb":[[2.64,56.1]],"id":40133336}],"con":true,"img":false}]}
{"op":"mcm","clk":"5322717333","pt":1646323469145,"mc":[{"id":"1.195532868","rc":[{"atb":[[2.22,83.61]],"id":40133336}],"con":true,"img":false}]}
{"op":"mcm","clk":"5322717456","pt":1646323470543,"mc":[{"id":"1.195532868","rc":[{"atb":[[5.5,0]],"id":42142047}],"con":true,"img":false}]}
{"op":"mcm","clk":"5322717463","pt":1646323470651,"mc":[{"id":"1.195532868","rc":[{"atb":[[5.2,1.99]],"id":42142047}],"con":true,"img":false}]}
{"op":"mcm","clk":"5322717528","pt":1646323471644,"mc":[{"id":"1.195532868","rc":[{"atb":[[5.2,0]],"id":42142047}],"con":true,"img":false}]}
{"op":"mcm","clk":"5322717533","pt":1646323471746,"mc":[{"id":"1.195532868","rc":[{"atb":[[5.5,1.99]],"id":42142047}],"con":true,"img":false}]}
{"op":"mcm","clk":"5322717614","pt":1646323472827,"mc":[{"id":"1.195532868","rc":[{"atb":[[5.5,0]],"id":42142047}],"con":true,"img":false}]}
{"op":"mcm","clk":"5322717622","pt":1646323472930,"mc":[{"id":"1.195532868","rc":[{"atb":[[5.2,1.99]],"id":42142047}],"con":true,"img":false}]}
{"op":"mcm","clk":"5322717715","pt":1646323473965,"mc":[{"id":"1.195532868","rc":[{"atb":[[5.2,0]],"id":42142047}],"con":true,"img":false}]}
{"op":"mcm","clk":"5322717725","pt":1646323474069,"mc":[{"id":"1.195532868","rc":[{"atb":[[5.5,1.99]],"id":42142047}],"con":true,"img":false}]}
{"op":"mcm","clk":"5322717928","pt":1646323476466,"mc":[{"id":"1.195532868","rc":[{"atb":[[5.5,0]],"id":42142047}],"con":true,"img":false}]}
{"op":"mcm","clk":"5322717937","pt":1646323476528,"mc":[{"id":"1.195532868","rc":[{"atb":[[5.2,1.99]],"id":42142047}],"con":true,"img":false}]}
{"op":"mcm","clk":"5322718021","pt":1646323477458,"mc":[{"id":"1.195532868","rc":[{"atb":[[5.2,0]],"id":42142047}],"con":true,"img":false}]}
{"op":"mcm","clk":"5322718031","pt":1646323477561,"mc":[{"id":"1.195532868","rc":[{"atb":[[5.5,1.99]],"id":42142047}],"con":true,"img":false}]}
{"op":"mcm","clk":"5322718232","pt":1646323479847,"mc":[{"id":"1.195532868","rc":[{"atb":[[5.5,0]],"id":42142047}],"con":true,"img":false}]}
{"op":"mcm","clk":"5322718240","pt":1646323479959,"mc":[{"id":"1.195532868","rc":[{"atb":[[5.2,1.99]],"id":42142047}],"con":true,"img":false}]}
{"op":"mcm","clk":"5322718395","pt":1646323481877,"mc":[{"id":"1.195532868","rc":[{"atb":[[5.2,0]],"id":42142047}],"con":true,"img":false}]}
{"op":"mcm","clk":"5322718422","pt":1646323482174,"mc":[{"id":"1.195532868","rc":[{"atb":[[5.5,1.99]],"id":42142047}],"con":true,"img":false}]}
{"op":"mcm","clk":"5322718509","pt":1646323483482,"mc":[{"id":"1.195532868","rc":[{"atb":[[5.5,0]],"id":42142047},{"spn":6.55,"spf":1.0,"id":40133336}],"con":true,"img":false}]}
{"op":"mcm","clk":"5322718517","pt":1646323483544,"mc":[{"id":"1.195532868","rc":[{"atb":[[5.2,1.99]],"id":42142047}],"con":true,"img":false}]}
{"op":"mcm","clk":"5322718897","pt":1646323488367,"mc":[{"id":"1.195532868","rc":[{"atb":[[5.2,0]],"id":42142047}],"con":true,"img":false}]}
{"op":"mcm","clk":"5322718910","pt":1646323488474,"mc":[{"id":"1.195532868","rc":[{"atb":[[5.5,1.99]],"id":42142047}],"con":true,"img":false}]}
{"op":"mcm","clk":"5322719282","pt":1646323492268,"mc":[{"id":"1.195532868","rc":[{"atb":[[5.5,0]],"id":42142047}],"con":true,"img":false}]}
{"op":"mcm","clk":"5322719291","pt":1646323492373,"mc":[{"id":"1.195532868","rc":[{"atb":[[5.2,1.99]],"id":42142047}],"con":true,"img":false}]}
{"op":"mcm","clk":"5322719558","pt":1646323495172,"mc":[{"id":"1.195532868","rc":[{"atb":[[5.2,0]],"id":42142047}],"con":true,"img":false}]}
{"op":"mcm","clk":"5322719566","pt":1646323495277,"mc":[{"id":"1.195532868","rc":[{"atb":[[5.5,1.99]],"id":42142047}],"con":true,"img":false}]}
{"op":"mcm","clk":"5322719657","pt":1646323496174,"mc":[{"id":"1.195532868","rc":[{"atb":[[5.5,0]],"id":42142047}],"con":true,"img":false}]}
{"op":"mcm","clk":"5322719669","pt":1646323496275,"mc":[{"id":"1.195532868","rc":[{"atb":[[5.2,1.99]],"id":42142047}],"con":true,"img":false}]}
{"op":"mcm","clk":"5322719772","pt":1646323497377,"mc":[{"id":"1.195532868","rc":[{"atb":[[5.2,0]],"id":42142047}],"con":true,"img":false}]}
{"op":"mcm","clk":"5322719786","pt":1646323497478,"mc":[{"id":"1.195532868","rc":[{"atb":[[5.5,1.99]],"id":42142047}],"con":true,"img":false}]}
{"op":"mcm","clk":"5322719893","pt":1646323498567,"mc":[{"id":"1.195532868","rc":[{"atb":[[5.5,0]],"id":42142047}],"con":true,"img":false}]}
{"op":"mcm","clk":"5322719902","pt":1646323498680,"mc":[{"id":"1.195532868","rc":[{"atb":[[5.2,1.99]],"id":42142047}],"con":true,"img":false}]}
{"op":"mcm","clk":"5322720110","pt":1646323500703,"mc":[{"id":"1.195532868","rc":[{"atb":[[5.2,0]],"id":42142047}],"con":true,"img":false}]}
{"op":"mcm","clk":"5322720119","pt":1646323500796,"mc":[{"id":"1.195532868","rc":[{"atb":[[5.5,1.99]],"id":42142047}],"con":true,"img":false}]}
{"op":"mcm","clk":"5322720251","pt":1646323502171,"mc":[{"id":"1.195532868","rc":[{"atb":[[5.5,0]],"id":42142047}],"con":true,"img":false}]}
{"op":"mcm","clk":"5322720266","pt":1646323502318,"mc":[{"id":"1.195532868","rc":[{"atb":[[5.2,1.99]],"id":42142047}],"con":true,"img":false}]}
{"op":"mcm","clk":"5322720305","pt":1646323502693,"mc":[{"id":"1.195532868","rc":[{"atb":[[5.2,0]],"id":42142047}],"con":true,"img":false}]}
{"op":"mcm","clk":"5322720316","pt":1646323502798,"mc":[{"id":"1.195532868","rc":[{"atb":[[5.5,1.99]],"id":42142047}],"con":true,"img":false}]}
{"op":"mcm","clk":"5322720353","pt":1646323503206,"mc":[{"id":"1.195532868","rc":[{"atb":[[5.5,0]],"id":42142047}],"con":true,"img":false}]}
{"op":"mcm","clk":"5322720364","pt":1646323503309,"mc":[{"id":"1.195532868","rc":[{"atb":[[5.2,1.99]],"id":42142047}],"con":true,"img":false}]}
{"op":"mcm","clk":"5322720581","pt":1646323505615,"mc":[{"id":"1.195532868","rc":[{"atb":[[5.2,0]],"id":42142047}],"con":true,"img":false}]}
{"op":"mcm","clk":"5322720597","pt":1646323505677,"mc":[{"id":"1.195532868","rc":[{"atb":[[5.5,1.99]],"id":42142047}],"con":true,"img":false}]}
{"op":"mcm","clk":"5322720693","pt":1646323506609,"mc":[{"id":"1.195532868","rc":[{"atb":[[5.5,0]],"id":42142047}],"con":true,"img":false}]}
{"op":"mcm","clk":"5322720706","pt":1646323506716,"mc":[{"id":"1.195532868","rc":[{"atb":[[5.2,1.99]],"id":42142047}],"con":true,"img":false}]}
{"op":"mcm","clk":"5322721018","pt":1646323509593,"mc":[{"id":"1.195532868","rc":[{"atb":[[5.2,0]],"id":42142047}],"con":true,"img":false}]}
{"op":"mcm","clk":"5322721025","pt":1646323509699,"mc":[{"id":"1.195532868","rc":[{"atb":[[5.5,1.99]],"id":42142047}],"con":true,"img":false}]}
{"op":"mcm","clk":"5322721097","pt":1646323510419,"mc":[{"id":"1.195532868","rc":[{"atb":[[5.5,0]],"id":42142047}],"con":true,"img":false}]}
{"op":"mcm","clk":"5322721111","pt":1646323510523,"mc":[{"id":"1.195532868","rc":[{"atb":[[5.2,1.99]],"id":42142047}],"con":true,"img":false}]}
{"op":"mcm","clk":"5322721338","pt":1646323512708,"mc":[{"id":"1.195532868","rc":[{"atb":[[5.2,0]],"id":42142047}],"con":true,"img":false}]}
{"op":"mcm","clk":"5322721353","pt":1646323512824,"mc":[{"id":"1.195532868","rc":[{"atb":[[5.5,1.99]],"id":42142047}],"con":true,"img":false}]}
{"op":"mcm","clk":"5322721514","pt":1646323514535,"mc":[{"id":"1.195532868","rc":[{"atb":[[5.5,0]],"id":42142047}],"con":true,"img":false}]}
{"op":"mcm","clk":"5322721526","pt":1646323514631,"mc":[{"id":"1.195532868","rc":[{"atb":[[5.2,1.99]],"id":42142047}],"con":true,"img":false}]}
{"op":"mcm","clk":"5322721588","pt":1646323515225,"mc":[{"id":"1.195532868","rc":[{"atb":[[5.2,0]],"id":42142047}],"con":true,"img":false}]}
{"op":"mcm","clk":"5322721602","pt":1646323515325,"mc":[{"id":"1.195532868","rc":[{"atb":[[5.5,1.99]],"id":42142047}],"con":true,"img":false}]}
{"op":"mcm","clk":"5322721749","pt":1646323516830,"mc":[{"id":"1.195532868","rc":[{"atb":[[5.5,0]],"id":42142047}],"con":true,"img":false}]}
{"op":"mcm","clk":"5322721764","pt":1646323516938,"mc":[{"id":"1.195532868","rc":[{"atb":[[5.2,1.99]],"id":42142047}],"con":true,"img":false}]}
{"op":"mcm","clk":"5322721842","pt":1646323517820,"mc":[{"id":"1.195532868","rc":[{"atb":[[5.2,0]],"id":42142047}],"con":true,"img":false}]}
{"op":"mcm","clk":"5322721853","pt":1646323517936,"mc":[{"id":"1.195532868","rc":[{"atb":[[5.5,1.99]],"id":42142047}],"con":true,"img":false}]}
{"op":"mcm","clk":"5322721907","pt":1646323518515,"mc":[{"id":"1.195532868","rc":[{"atb":[[5.5,0]],"id":42142047}],"con":true,"img":false}]}
{"op":"mcm","clk":"5322721920","pt":1646323518628,"mc":[{"id":"1.195532868","rc":[{"atb":[[5.2,1.99]],"id":42142047}],"con":true,"img":false}]}
{"op":"mcm","clk":"5322722097","pt":1646323520335,"mc":[{"id":"1.195532868","rc":[{"atb":[[5.2,0]],"id":42142047}],"con":true,"img":false}]}
{"op":"mcm","clk":"5322722107","pt":1646323520437,"mc":[{"id":"1.195532868","rc":[{"atb":[[5.5,1.99]],"id":42142047}],"con":true,"img":false}]}
{"op":"mcm","clk":"5322722331","pt":1646323522726,"mc":[{"id":"1.195532868","rc":[{"atb":[[5.5,0]],"id":42142047}],"con":true,"img":false}]}
{"op":"mcm","clk":"5322722341","pt":1646323522835,"mc":[{"id":"1.195532868","rc":[{"atb":[[5.2,1.99]],"id":42142047}],"con":true,"img":false}]}
{"op":"mcm","clk":"5322722458","pt":1646323523920,"mc":[{"id":"1.195532868","rc":[{"atb":[[5.2,0]],"id":42142047}],"con":true,"img":false}]}
{"op":"mcm","clk":"5322722470","pt":1646323524026,"mc":[{"id":"1.195532868","rc":[{"atb":[[5.5,1.99]],"id":42142047}],"con":true,"img":false}]}
{"op":"mcm","clk":"5322722509","pt":1646323524543,"mc":[{"id":"1.195532868","rc":[{"atb":[[5.5,0]],"id":42142047}],"con":true,"img":false}]}
{"op":"mcm","clk":"5322722524","pt":1646323524646,"mc":[{"id":"1.195532868","rc":[{"atb":[[5.2,1.99]],"id":42142047}],"con":true,"img":false}]}
{"op":"mcm","clk":"5322722627","pt":1646323525744,"mc":[{"id":"1.195532868","rc":[{"atb":[[5.2,0]],"id":42142047}],"con":true,"img":false}]}
{"op":"mcm","clk":"5322722641","pt":1646323525845,"mc":[{"id":"1.195532868","rc":[{"atb":[[5.5,1.99]],"id":42142047}],"con":true,"img":false}]}
{"op":"mcm","clk":"5322722749","pt":1646323526741,"mc":[{"id":"1.195532868","rc":[{"atb":[[5.5,0]],"id":42142047}],"con":true,"img":false}]}
{"op":"mcm","clk":"5322722766","pt":1646323526845,"mc":[{"id":"1.195532868","rc":[{"atb":[[5.2,1.99]],"id":42142047}],"con":true,"img":false}]}
{"op":"mcm","clk":"5322722903","pt":1646323528161,"mc":[{"id":"1.195532868","rc":[{"atb":[[5.2,0]],"id":42142047}],"con":true,"img":false}]}
{"op":"mcm","clk":"5322722913","pt":1646323528209,"mc":[{"id":"1.195532868","rc":[{"atb":[[5.5,1.99]],"id":42142047}],"con":true,"img":false}]}
{"op":"mcm","clk":"5322723097","pt":1646323529833,"mc":[{"id":"1.195532868","rc":[{"atb":[[5.5,0]],"id":42142047}],"con":true,"img":false}]}
{"op":"mcm","clk":"5322723106","pt":1646323529937,"mc":[{"id":"1.195532868","rc":[{"atb":[[5.2,1.99]],"id":42142047}],"con":true,"img":false}]}
{"op":"mcm","clk":"5322723183","pt":1646323530827,"mc":[{"id":"1.195532868","rc":[{"atb":[[5.2,0]],"id":42142047}],"con":true,"img":false}]}
{"op":"mcm","clk":"5322723195","pt":1646323530929,"mc":[{"id":"1.195532868","rc":[{"atb":[[5.5,1.99]],"id":42142047}],"con":true,"img":false}]}
{"op":"mcm","clk":"5322723299","pt":1646323531918,"mc":[{"id":"1.195532868","rc":[{"atb":[[5.5,0]],"id":42142047}],"con":true,"img":false}]}
{"op":"mcm","clk":"5322723306","pt":1646323532020,"mc":[{"id":"1.195532868","rc":[{"atb":[[5.2,1.99]],"id":42142047}],"con":true,"img":false}]}
{"op":"mcm","clk":"5322723486","pt":1646323534153,"mc":[{"id":"1.195532868","rc":[{"atb":[[5.2,0]],"id":42142047}],"con":true,"img":false}]}
{"op":"mcm","clk":"5322723495","pt":1646323534209,"mc":[{"id":"1.195532868","rc":[{"atb":[[5.5,1.99]],"id":42142047}],"con":true,"img":false}]}
{"op":"mcm","clk":"5322723603","pt":1646323535347,"mc":[{"id":"1.195532868","rc":[{"atb":[[5.5,0]],"id":42142047}],"con":true,"img":false}]}
{"op":"mcm","clk":"5322723611","pt":1646323535456,"mc":[{"id":"1.195532868","rc":[{"atb":[[5.2,1.99]],"id":42142047}],"con":true,"img":false}]}
{"op":"mcm","clk":"5322723760","pt":1646323536662,"mc":[{"id":"1.195532868","rc":[{"atb":[[5.2,0]],"id":42142047}],"con":true,"img":false}]}
{"op":"mcm","clk":"5322723770","pt":1646323536765,"mc":[{"id":"1.195532868","rc":[{"atb":[[5.5,1.99]],"id":42142047}],"con":true,"img":false}]}
{"op":"mcm","clk":"5322723893","pt":1646323537853,"mc":[{"id":"1.195532868","rc":[{"atb":[[5.5,0]],"id":42142047}],"con":true,"img":false}]}
{"op":"mcm","clk":"5322723906","pt":1646323537964,"mc":[{"id":"1.195532868","rc":[{"atb":[[5.2,1.99]],"id":42142047}],"con":true,"img":false}]}
{"op":"mcm","clk":"5322724041","pt":1646323539061,"mc":[{"id":"1.195532868","rc":[{"atb":[[5.2,0]],"id":42142047}],"con":true,"img":false}]}
{"op":"mcm","clk":"5322724056","pt":1646323539153,"mc":[{"id":"1.195532868","rc":[{"atb":[[5.5,1.99]],"id":42142047}],"con":true,"img":false}]}
{"op":"mcm","clk":"5322724148","pt":1646323540147,"mc":[{"id":"1.195532868","rc":[{"atb":[[5.5,0]],"id":42142047}],"con":true,"img":false}]}
{"op":"mcm","clk":"5322724154","pt":1646323540246,"mc":[{"id":"1.195532868","rc":[{"atb":[[5.2,1.99]],"id":42142047}],"con":true,"img":false}]}
{"op":"mcm","clk":"5322724346","pt":1646323542129,"mc":[{"id":"1.195532868","rc":[{"atb":[[5.2,0]],"id":42142047}],"con":true,"img":false}]}
{"op":"mcm","clk":"5322724359","pt":1646323542238,"mc":[{"id":"1.195532868","rc":[{"atb":[[5.5,1.99]],"id":42142047}],"con":true,"img":false}]}
{"op":"mcm","clk":"5322724516","pt":1646323543528,"mc":[{"id":"1.195532868","rc":[{"atb":[[5.5,0]],"id":42142047}],"con":true,"img":false}]}
{"op":"mcm","clk":"5322724527","pt":1646323543632,"mc":[{"id":"1.195532868","rc":[{"atb":[[5.2,1.99]],"id":42142047}],"con":true,"img":false}]}
{"op":"mcm","clk":"5322724697","pt":1646323545049,"mc":[{"id":"1.195532868","rc":[{"atb":[[5.2,0]],"id":42142047}],"con":true,"img":false}]}
{"op":"mcm","clk":"5322724712","pt":1646323545156,"mc":[{"id":"1.195532868","rc":[{"atb":[[5.5,1.99]],"id":42142047}],"con":true,"img":false}]}
{"op":"mcm","clk":"5322724797","pt":1646323546043,"mc":[{"id":"1.195532868","rc":[{"atb":[[5.5,0]],"id":42142047}],"con":true,"img":false}]}
{"op":"mcm","clk":"5322724806","pt":1646323546145,"mc":[{"id":"1.195532868","rc":[{"atb":[[5.2,1.99]],"id":42142047}],"con":true,"img":false}]}
{"op":"mcm","clk":"5322724948","pt":1646323547759,"mc":[{"id":"1.195532868","rc":[{"atb":[[5.2,0]],"id":42142047}],"con":true,"img":false}]}
{"op":"mcm","clk":"5322724958","pt":1646323547867,"mc":[{"id":"1.195532868","rc":[{"atb":[[5.5,1.99]],"id":42142047}],"con":true,"img":false}]}
{"op":"mcm","clk":"5322725099","pt":1646323549534,"mc":[{"id":"1.195532868","rc":[{"atb":[[5.5,0]],"id":42142047}],"con":true,"img":false}]}
{"op":"mcm","clk":"5322725106","pt":1646323549640,"mc":[{"id":"1.195532868","rc":[{"atb":[[5.2,1.99]],"id":42142047}],"con":true,"img":false}]}
{"op":"mcm","clk":"5322725399","pt":1646323552356,"mc":[{"id":"1.195532868","rc":[{"atb":[[5.2,0]],"id":42142047}],"con":true,"img":false}]}
{"op":"mcm","clk":"5322725409","pt":1646323552458,"mc":[{"id":"1.195532868","rc":[{"atb":[[5.5,1.99]],"id":42142047}],"con":true,"img":false}]}
{"op":"mcm","clk":"5322725514","pt":1646323553449,"mc":[{"id":"1.195532868","rc":[{"atb":[[5.5,0]],"id":42142047}],"con":true,"img":false}]}
{"op":"mcm","clk":"5322725523","pt":1646323553556,"mc":[{"id":"1.195532868","rc":[{"atb":[[5.2,1.99]],"id":42142047}],"con":true,"img":false}]}
{"op":"mcm","clk":"5322725570","pt":1646323554079,"mc":[{"id":"1.195532868","rc":[{"atb":[[5.2,0]],"id":42142047}],"con":true,"img":false}]}
{"op":"mcm","clk":"5322725582","pt":1646323554135,"mc":[{"id":"1.195532868","rc":[{"atb":[[5.5,1.99]],"id":42142047}],"con":true,"img":false}]}
{"op":"mcm","clk":"5322725728","pt":1646323555565,"mc":[{"id":"1.195532868","rc":[{"atb":[[5.5,0]],"id":42142047}],"con":true,"img":false}]}
{"op":"mcm","clk":"5322725739","pt":1646323555665,"mc":[{"id":"1.195532868","rc":[{"atb":[[5.2,1.99]],"id":42142047}],"con":true,"img":false}]}
{"op":"mcm","clk":"5322725846","pt":1646323556733,"mc":[{"id":"1.195532868","rc":[{"atb":[[5.2,0]],"id":42142047}],"con":true,"img":false}]}
{"op":"mcm","clk":"5322725855","pt":1646323556840,"mc":[{"id":"1.195532868","rc":[{"atb":[[5.5,1.99]],"id":42142047}],"con":true,"img":false}]}
{"op":"mcm","clk":"5322725931","pt":1646323557878,"mc":[{"id":"1.195532868","rc":[{"atb":[[5.5,0]],"id":42142047}],"con":true,"img":false}]}
{"op":"mcm","clk":"5322725941","pt":1646323557937,"mc":[{"id":"1.195532868","rc":[{"atb":[[5.2,1.99]],"id":42142047}],"con":true,"img":false}]}
{"op":"mcm","clk":"5322726013","pt":1646323558982,"mc":[{"id":"1.195532868","rc":[{"atb":[[5.2,0]],"id":42142047}],"con":true,"img":false}]}
{"op":"mcm","clk":"5322726020","pt":1646323559039,"mc":[{"id":"1.195532868","rc":[{"atb":[[5.5,1.99]],"id":42142047}],"con":true,"img":false}]}
{"op":"mcm","clk":"5322726566","pt":1646323564947,"mc":[{"id":"1.195532868","rc":[{"atb":[[5.5,0]],"id":42142047}],"con":true,"img":false}]}
{"op":"mcm","clk":"5322726578","pt":1646323565050,"mc":[{"id":"1.195532868","rc":[{"atb":[[5.2,1.99]],"id":42142047}],"con":true,"img":false}]}
{"op":"mcm","clk":"5322726648","pt":1646323565886,"mc":[{"id":"1.195532868","rc":[{"atb":[[5.2,0]],"id":42142047}],"con":true,"img":false}]}
{"op":"mcm","clk":"5322726658","pt":1646323565988,"mc":[{"id":"1.195532868","rc":[{"atb":[[5.5,1.99]],"id":42142047}],"con":true,"img":false}]}
{"op":"mcm","clk":"5322726839","pt":1646323567958,"mc":[{"id":"1.195532868","rc":[{"atb":[[5.5,0]],"id":42142047}],"con":true,"img":false}]}
{"op":"mcm","clk":"5322726848","pt":1646323568067,"mc":[{"id":"1.195532868","rc":[{"atb":[[5.2,1.99]],"id":42142047}],"con":true,"img":false}]}
{"op":"mcm","clk":"5322726960","pt":1646323569294,"mc":[{"id":"1.195532868","rc":[{"atb":[[5.2,0]],"id":42142047}],"con":true,"img":false}]}
{"op":"mcm","clk":"5322726968","pt":1646323569390,"mc":[{"id":"1.195532868","rc":[{"atb":[[5.5,1.99]],"id":42142047}],"con":true,"img":false}]}
{"op":"mcm","clk":"5322727467","pt":1646323574983,"mc":[{"id":"1.195532868","rc":[{"atb":[[5.5,0]],"id":42142047}],"con":true,"img":false}]}
{"op":"mcm","clk":"5322727477","pt":1646323575096,"mc":[{"id":"1.195532868","rc":[{"atb":[[5.2,1.99]],"id":42142047}],"con":true,"img":false}]}
{"op":"mcm","clk":"5322728857","pt":1646323589456,"mc":[{"id":"1.195532868","rc":[{"atb":[[2.3,0]],"id":36909993},{"atb":[[2.74,0]],"id":40133336}],"con":true,"img":false}]}
{"op":"mcm","clk":"5322729037","pt":1646323591545,"mc":[{"id":"1.195532868","rc":[{"atb":[[5.2,0]],"id":42142047}],"con":true,"img":false}]}
{"op":"mcm","clk":"5322729047","pt":1646323591648,"mc":[{"id":"1.195532868","rc":[{"atb":[[5.5,1.99]],"id":42142047}],"con":true,"img":false}]}
{"op":"mcm","clk":"5322729718","pt":1646323598042,"mc":[{"id":"1.195532868","rc":[{"atb":[[5.5,0]],"id":42142047}],"con":true,"img":false}]}
{"op":"mcm","clk":"5322729723","pt":1646323598141,"mc":[{"id":"1.195532868","rc":[{"atb":[[5.2,1.99]],"id":42142047}],"con":true,"img":false}]}
{"op":"mcm","clk":"5322729780","pt":1646323598817,"mc":[{"id":"1.195532868","rc":[{"atb":[[5.2,0]],"id":42142047}],"con":true,"img":false}]}
{"op":"mcm","clk":"5322729789","pt":1646323598978,"mc":[{"id":"1.195532868","rc":[{"atb":[[5.5,1.99]],"id":42142047}],"con":true,"img":false}]}
{"op":"mcm","clk":"5322730758","pt":1646323609445,"mc":[{"id":"1.195532868","rc":[{"atb":[[5.5,0]],"id":42142047}],"con":true,"img":false}]}
{"op":"mcm","clk":"5322730770","pt":1646323609548,"mc":[{"id":"1.195532868","rc":[{"atb":[[5.2,1.99]],"id":42142047}],"con":true,"img":false}]}
{"op":"mcm","clk":"5322730945","pt":1646323611375,"mc":[{"id":"1.195532868","rc":[{"atb":[[5.2,0]],"id":42142047}],"con":true,"img":false}]}
{"op":"mcm","clk":"5322730956","pt":1646323611490,"mc":[{"id":"1.195532868","rc":[{"atb":[[5.5,1.99]],"id":42142047}],"con":true,"img":false}]}
{"op":"mcm","clk":"5322731079","pt":1646323612748,"mc":[{"id":"1.195532868","rc":[{"atb":[[5.5,0]],"id":42142047}],"con":true,"img":false}]}
{"op":"mcm","clk":"5322731091","pt":1646323612857,"mc":[{"id":"1.195532868","rc":[{"atb":[[5.2,1.99]],"id":42142047}],"con":true,"img":false}]}
{"op":"mcm","clk":"5322731661","pt":1646323618540,"mc":[{"id":"1.195532868","rc":[{"atb":[[5.2,0]],"id":42142047}],"con":true,"img":false}]}
{"op":"mcm","clk":"5322731674","pt":1646323618642,"mc":[{"id":"1.195532868","rc":[{"atb":[[5.5,1.99]],"id":42142047}],"con":true,"img":false}]}
{"op":"mcm","clk":"5322731781","pt":1646323619599,"mc":[{"id":"1.195532868","rc":[{"atb":[[5.5,0]],"id":42142047}],"con":true,"img":false}]}
{"op":"mcm","clk":"5322731793","pt":1646323619692,"mc":[{"id":"1.195532868","rc":[{"atb":[[5.2,1.99]],"id":42142047}],"con":true,"img":false}]}
{"op":"mcm","clk":"5322731936","pt":1646323621070,"mc":[{"id":"1.195532868","rc":[{"atb":[[5.2,0]],"id":42142047}],"con":true,"img":false}]}
{"op":"mcm","clk":"5322731946","pt":1646323621180,"mc":[{"id":"1.195532868","rc":[{"atb":[[5.5,1.99]],"id":42142047}],"con":true,"img":false}]}
{"op":"mcm","clk":"5322732058","pt":1646323622081,"mc":[{"id":"1.195532868","rc":[{"atb":[[5.5,0]],"id":42142047}],"con":true,"img":false}]}
{"op":"mcm","clk":"5322732073","pt":1646323622185,"mc":[{"id":"1.195532868","rc":[{"atb":[[5.2,1.99]],"id":42142047}],"con":true,"img":false}]}
{"op":"mcm","clk":"5322732759","pt":1646323628384,"mc":[{"id":"1.195532868","rc":[{"atb":[[5.2,0]],"id":42142047}],"con":true,"img":false}]}
{"op":"mcm","clk":"5322732766","pt":1646323628481,"mc":[{"id":"1.195532868","rc":[{"atb":[[5.5,1.99]],"id":42142047}],"con":true,"img":false}]}
{"op":"mcm","clk":"5322732973","pt":1646323630377,"mc":[{"id":"1.195532868","rc":[{"atb":[[5.5,0]],"id":42142047}],"con":true,"img":false}]}
{"op":"mcm","clk":"5322732985","pt":1646323630488,"mc":[{"id":"1.195532868","rc":[{"atb":[[5.2,1.99]],"id":42142047}],"con":true,"img":false}]}
{"op":"mcm","clk":"5322733686","pt":1646323636316,"mc":[{"id":"1.195532868","rc":[{"atb":[[5.2,0]],"id":42142047}],"con":true,"img":false}]}
{"op":"mcm","clk":"5322733725","pt":1646323636557,"mc":[{"id":"1.195532868","rc":[{"atb":[[5.5,1.99]],"id":42142047}],"con":true,"img":false}]}
{"op":"mcm","clk":"5322734196","pt":1646323638106,"mc":[{"id":"1.195532868","rc":[{"atb":[[5.5,0]],"id":42142047}],"con":true,"img":false}]}
{"op":"mcm","clk":"5322734213","pt":1646323638217,"mc":[{"id":"1.195532868","rc":[{"atb":[[5.2,1.99]],"id":42142047}],"con":true,"img":false}]}
{"op":"mcm","clk":"5322734365","pt":1646323639634,"mc":[{"id":"1.195532868","rc":[{"atb":[[5.2,0]],"id":42142047}],"con":true,"img":false}]}
{"op":"mcm","clk":"5322734375","pt":1646323639737,"mc":[{"id":"1.195532868","rc":[{"atb":[[5.5,1.99]],"id":42142047}],"con":true,"img":false}]}
{"op":"mcm","clk":"5322734465","pt":1646323640562,"mc":[{"id":"1.195532868","rc":[{"atb":[[5.5,0]],"id":42142047}],"con":true,"img":false}]}
{"op":"mcm","clk":"5322734473","pt":1646323640645,"mc":[{"id":"1.195532868","rc":[{"atb":[[5.2,1.99]],"id":42142047}],"con":true,"img":false}]}
{"op":"mcm","clk":"5322734648","pt":1646323642529,"mc":[{"id":"1.195532868","rc":[{"atb":[[5.2,0]],"id":42142047}],"con":true,"img":false}]}
{"op":"mcm","clk":"5322734661","pt":1646323642640,"mc":[{"id":"1.195532868","rc":[{"atb":[[5.5,1.99]],"id":42142047}],"con":true,"img":false}]}
{"op":"mcm","clk":"5322734748","pt":1646323643533,"mc":[{"id":"1.195532868","rc":[{"atb":[[5.5,0]],"id":42142047}],"con":true,"img":false}]}
{"op":"mcm","clk":"5322734768","pt":1646323643735,"mc":[{"id":"1.195532868","rc":[{"atb":[[5.2,1.99]],"id":42142047}],"con":true,"img":false}]}
{"op":"mcm","clk":"5322734909","pt":1646323645148,"mc":[{"id":"1.195532868","rc":[{"atb":[[5.2,0]],"id":42142047}],"con":true,"img":false}]}
{"op":"mcm","clk":"5322734919","pt":1646323645255,"mc":[{"id":"1.195532868","rc":[{"atb":[[5.5,1.99]],"id":42142047}],"con":true,"img":false}]}
{"op":"mcm","clk":"5322735065","pt":1646323646830,"mc":[{"id":"1.195532868","rc":[{"atb":[[5.5,0]],"id":42142047}],"con":true,"img":false}]}
{"op":"mcm","clk":"5322735075","pt":1646323646938,"mc":[{"id":"1.195532868","rc":[{"atb":[[5.2,1.99]],"id":42142047}],"con":true,"img":false}]}
{"op":"mcm","clk":"5322735244","pt":1646323648725,"mc":[{"id":"1.195532868","rc":[{"atb":[[5.2,0]],"id":42142047}],"con":true,"img":false}]}
{"op":"mcm","clk":"5322735254","pt":1646323648831,"mc":[{"id":"1.195532868","rc":[{"atb":[[5.5,1.99]],"id":42142047}],"con":true,"img":false}]}
{"op":"mcm","clk":"5322735880","pt":1646323655070,"mc":[{"id":"1.195532868","rc":[{"atb":[[5.5,0]],"id":42142047}],"con":true,"img":false}]}
{"op":"mcm","clk":"5322735892","pt":1646323655131,"mc":[{"id":"1.195532868","rc":[{"atb":[[5.2,1.99]],"id":42142047}],"con":true,"img":false}]}
{"op":"mcm","clk":"5322736028","pt":1646323656443,"mc":[{"id":"1.195532868","rc":[{"atb":[[5.2,0]],"id":42142047}],"con":true,"img":false}]}
{"op":"mcm","clk":"5322736039","pt":1646323656553,"mc":[{"id":"1.195532868","rc":[{"atb":[[5.5,1.99]],"id":42142047}],"con":true,"img":false}]}
{"op":"mcm","clk":"5322736147","pt":1646323657749,"mc":[{"id":"1.195532868","rc":[{"atb":[[5.5,0]],"id":42142047}],"con":true,"img":false}]}
{"op":"mcm","clk":"5322736161","pt":1646323657856,"mc":[{"id":"1.195532868","rc":[{"atb":[[5.2,1.99]],"id":42142047}],"con":true,"img":false}]}
{"op":"mcm","clk":"5322736346","pt":1646323659605,"mc":[{"id":"1.195532868","rc":[{"atb":[[5.2,0]],"id":42142047}],"con":true,"img":false}]}
{"op":"mcm","clk":"5322736357","pt":1646323659669,"mc":[{"id":"1.195532868","rc":[{"atb":[[5.5,1.99]],"id":42142047}],"con":true,"img":false}]}
{"op":"mcm","clk":"5322736518","pt":1646323661244,"mc":[{"id":"1.195532868","rc":[{"atb":[[5.5,0]],"id":42142047}],"con":true,"img":false}]}
{"op":"mcm","clk":"5322736530","pt":1646323661351,"mc":[{"id":"1.195532868","rc":[{"atb":[[5.2,1.99]],"id":42142047}],"con":true,"img":false}]}
{"op":"mcm","clk":"5322736623","pt":1646323662354,"mc":[{"id":"1.195532868","rc":[{"atb":[[5.2,0]],"id":42142047}],"con":true,"img":false}]}
{"op":"mcm","clk":"5322736634","pt":1646323662453,"mc":[{"id":"1.195532868","rc":[{"atb":[[5.5,1.99]],"id":42142047}],"con":true,"img":false}]}
{"op":"mcm","clk":"5322736795","pt":1646323664275,"mc":[{"id":"1.195532868","rc":[{"atb":[[5.5,0]],"id":42142047}],"con":true,"img":false}]}
{"op":"mcm","clk":"5322736805","pt":1646323664379,"mc":[{"id":"1.195532868","rc":[{"atb":[[5.2,1.99]],"id":42142047}],"con":true,"img":false}]}
{"op":"mcm","clk":"5322736871","pt":1646323665071,"mc":[{"id":"1.195532868","rc":[{"atb":[[5.2,0]],"id":42142047}],"con":true,"img":false}]}
{"op":"mcm","clk":"5322736881","pt":1646323665171,"mc":[{"id":"1.195532868","rc":[{"atb":[[5.5,1.99]],"id":42142047}],"con":true,"img":false}]}
{"op":"mcm","clk":"5322737044","pt":1646323666894,"mc":[{"id":"1.195532868","rc":[{"atb":[[5.5,0]],"id":42142047}],"con":true,"img":false}]}
{"op":"mcm","clk":"5322737051","pt":1646323666950,"mc":[{"id":"1.195532868","rc":[{"atb":[[5.2,1.99]],"id":42142047}],"con":true,"img":false}]}
{"op":"mcm","clk":"5322737137","pt":1646323667993,"mc":[{"id":"1.195532868","rc":[{"atb":[[5.2,0]],"id":42142047}],"con":true,"img":false}]}
{"op":"mcm","clk":"5322737150","pt":1646323668053,"mc":[{"id":"1.195532868","rc":[{"atb":[[5.5,1.99]],"id":42142047}],"con":true,"img":false}]}
{"op":"mcm","clk":"5322737230","pt":1646323668892,"mc":[{"id":"1.195532868","rc":[{"atb":[[5.5,0]],"id":42142047}],"con":true,"img":false}]}
{"op":"mcm","clk":"5322737245","pt":1646323668986,"mc":[{"id":"1.195532868","rc":[{"atb":[[5.2,1.99]],"id":42142047}],"con":true,"img":false}]}
{"op":"mcm","clk":"5322737399","pt":1646323670355,"mc":[{"id":"1.195532868","rc":[{"atb":[[5.2,0]],"id":42142047}],"con":true,"img":false}]}
{"op":"mcm","clk":"5322737408","pt":1646323670459,"mc":[{"id":"1.195532868","rc":[{"atb":[[5.5,1.99]],"id":42142047}],"con":true,"img":false}]}
{"op":"mcm","clk":"5322737459","pt":1646323671084,"mc":[{"id":"1.195532868","rc":[{"atb":[[5.5,0]],"id":42142047}],"con":true,"img":false}]}
{"op":"mcm","clk":"5322737470","pt":1646323671188,"mc":[{"id":"1.195532868","rc":[{"atb":[[5.2,1.99]],"id":42142047}],"con":true,"img":false}]}
{"op":"mcm","clk":"5322737515","pt":1646323671558,"mc":[{"id":"1.195532868","rc":[{"atb":[[5.2,0]],"id":42142047}],"con":true,"img":false}]}
{"op":"mcm","clk":"5322737530","pt":1646323671775,"mc":[{"id":"1.195532868","rc":[{"atb":[[5.5,1.99]],"id":42142047}],"con":true,"img":false}]}
{"op":"mcm","clk":"5322737684","pt":1646323673713,"mc":[{"id":"1.195532868","rc":[{"atb":[[5.5,0]],"id":42142047}],"con":true,"img":false}]}
{"op":"mcm","clk":"5322737693","pt":1646323673776,"mc":[{"id":"1.195532868","rc":[{"atb":[[5.2,1.99]],"id":42142047}],"con":true,"img":false}]}
{"op":"mcm","clk":"5322737831","pt":1646323675180,"mc":[{"id":"1.195532868","rc":[{"atb":[[5.2,0]],"id":42142047}],"con":true,"img":false}]}
{"op":"mcm","clk":"5322737841","pt":1646323675291,"mc":[{"id":"1.195532868","rc":[{"atb":[[5.5,1.99]],"id":42142047}],"con":true,"img":false}]}
{"op":"mcm","clk":"5322737901","pt":1646323675972,"mc":[{"id":"1.195532868","rc":[{"atb":[[5.5,0]],"id":42142047}],"con":true,"img":false}]}
{"op":"mcm","clk":"5322737906","pt":1646323676075,"mc":[{"id":"1.195532868","rc":[{"atb":[[5.2,1.99]],"id":42142047}],"con":true,"img":false}]}
{"op":"mcm","clk":"5322737976","pt":1646323676796,"mc":[{"id":"1.195532868","rc":[{"atb":[[5.2,0]],"id":42142047}],"con":true,"img":false}]}
{"op":"mcm","clk":"5322737983","pt":1646323676907,"mc":[{"id":"1.195532868","rc":[{"atb":[[5.5,1.99]],"id":42142047}],"con":true,"img":false}]}
{"op":"mcm","clk":"5322738078","pt":1646323678004,"mc":[{"id":"1.195532868","rc":[{"atb":[[5.5,0]],"id":42142047}],"con":true,"img":false}]}
{"op":"mcm","clk":"5322738086","pt":1646323678109,"mc":[{"id":"1.195532868","rc":[{"atb":[[5.2,1.99]],"id":42142047}],"con":true,"img":false}]}
{"op":"mcm","clk":"5322738148","pt":1646323678783,"mc":[{"id":"1.195532868","rc":[{"atb":[[5.2,0]],"id":42142047}],"con":true,"img":false}]}
{"op":"mcm","clk":"5322738160","pt":1646323678885,"mc":[{"id":"1.195532868","rc":[{"atb":[[5.5,1.99]],"id":42142047}],"con":true,"img":false}]}
{"op":"mcm","clk":"5322738235","pt":1646323679670,"mc":[{"id":"1.195532868","rc":[{"atb":[[5.5,0]],"id":42142047}],"con":true,"img":false}]}
{"op":"mcm","clk":"5322738245","pt":1646323679772,"mc":[{"id":"1.195532868","rc":[{"atb":[[5.2,1.99]],"id":42142047}],"con":true,"img":false}]}
{"op":"mcm","clk":"5322738343","pt":1646323680675,"mc":[{"id":"1.195532868","rc":[{"atb":[[5.2,0]],"id":42142047}],"con":true,"img":false}]}
{"op":"mcm","clk":"5322738353","pt":1646323680781,"mc":[{"id":"1.195532868","rc":[{"atb":[[5.5,1.99]],"id":42142047}],"con":true,"img":false}]}
{"op":"mcm","clk":"5322738481","pt":1646323682194,"mc":[{"id":"1.195532868","rc":[{"atb":[[5.5,0]],"id":42142047}],"con":true,"img":false}]}
{"op":"mcm","clk":"5322738491","pt":1646323682307,"mc":[{"id":"1.195532868","rc":[{"atb":[[5.2,1.99]],"id":42142047}],"con":true,"img":false}]}
{"op":"mcm","clk":"5322738543","pt":1646323682669,"mc":[{"id":"1.195532868","rc":[{"atb":[[5.2,0]],"id":42142047}],"con":true,"img":false}]}
{"op":"mcm","clk":"5322738553","pt":1646323682783,"mc":[{"id":"1.195532868","rc":[{"atb":[[5.5,1.99]],"id":42142047}],"con":true,"img":false}]}
{"op":"mcm","clk":"5322738634","pt":1646323683580,"mc":[{"id":"1.195532868","rc":[{"atb":[[5.5,0]],"id":42142047}],"con":true,"img":false}]}
{"op":"mcm","clk":"5322738643","pt":1646323683680,"mc":[{"id":"1.195532868","rc":[{"atb":[[5.2,1.99]],"id":42142047}],"con":true,"img":false}]}
{"op":"mcm","clk":"5322739121","pt":1646323687994,"mc":[{"id":"1.195532868","rc":[{"atl":[[1000,14.52]],"id":2441997}],"con":true,"img":false}]}
{"op":"mcm","clk":"5322739136","pt":1646323688201,"mc":[{"id":"1.195532868","rc":[{"atl":[[1000,14.1]],"id":2441997}],"con":true,"img":false}]}
{"op":"mcm","clk":"5322739146","pt":1646323688308,"mc":[{"id":"1.195532868","rc":[{"atb":[[5.2,0]],"id":42142047}],"con":true,"img":false}]}
{"op":"mcm","clk":"5322739169","pt":1646323688511,"mc":[{"id":"1.195532868","rc":[{"atl":[[1000,12]],"id":2441997},{"atb":[[5.5,1.99]],"id":42142047}],"con":true,"img":false}]}
{"op":"mcm","clk":"5322739182","pt":1646323688616,"mc":[{"id":"1.195532868","rc":[{"atl":[[9.4,2.1]],"id":2441997}],"con":true,"img":false}]}
{"op":"mcm","clk":"5322739237","pt":1646323689096,"mc":[{"id":"1.195532868","rc":[{"atl":[[9.4,0]],"id":2441997}],"con":true,"img":false}]}
{"op":"mcm","clk":"5322739262","pt":1646323689410,"mc":[{"id":"1.195532868","rc":[{"atb":[[5.5,0]],"id":42142047}],"con":true,"img":false}]}
{"op":"mcm","clk":"5322739276","pt":1646323689509,"mc":[{"id":"1.195532868","rc":[{"atb":[[5.2,1.99]],"id":42142047}],"con":true,"img":false}]}
{"op":"mcm","clk":"5322739379","pt":1646323690710,"mc":[{"id":"1.195532868","rc":[{"atb":[[5.2,0]],"id":42142047}],"con":true,"img":false}]}
{"op":"mcm","clk":"5322739390","pt":1646323690814,"mc":[{"id":"1.195532868","rc":[{"atb":[[5.5,1.99]],"id":42142047}],"con":true,"img":false}]}
{"op":"mcm","clk":"5322739442","pt":1646323691295,"mc":[{"id":"1.195532868","rc":[{"atb":[[2.06,165.09]],"id":42609835},{"atb":[[2.08,0]],"id":40133336}],"con":true,"img":false}]}
{"op":"mcm","clk":"5322739456","pt":1646323691399,"mc":[{"id":"1.195532868","rc":[{"atb":[[2.24,10.34]],"id":42609835},{"atb":[[2.24,11.95]],"id":40133336}],"con":true,"img":false}]}
{"op":"mcm","clk":"5322739609","pt":1646323692916,"mc":[{"id":"1.195532868","rc":[{"atb":[[5.5,0]],"id":42142047}],"con":true,"img":false}]}
{"op":"mcm","clk":"5322739617","pt":1646323693020,"mc":[{"id":"1.195532868","rc":[{"atb":[[5.2,1.99]],"id":42142047}],"con":true,"img":false}]}
{"op":"mcm","clk":"5322739651","pt":1646323693399,"mc":[{"id":"1.195532868","rc":[{"atb":[[5.2,0]],"id":42142047}],"con":true,"img":false}]}
{"op":"mcm","clk":"5322739662","pt":1646323693508,"mc":[{"id":"1.195532868","rc":[{"atb":[[5.5,1.99]],"id":42142047}],"con":true,"img":false}]}
{"op":"mcm","clk":"5322739759","pt":1646323694557,"mc":[{"id":"1.195532868","rc":[{"atl":[[1000,14.52]],"id":2441997}],"con":true,"img":false}]}
{"op":"mcm","clk":"5322739769","pt":1646323694626,"mc":[{"id":"1.195532868","rc":[{"atb":[[5.5,0]],"id":42142047}],"con":true,"img":false}]}
{"op":"mcm","clk":"5322739782","pt":1646323694706,"mc":[{"id":"1.195532868","rc":[{"atl":[[1000,14.1]],"id":2441997}],"con":true,"img":false}]}
{"op":"mcm","clk":"5322739790","pt":1646323694863,"mc":[{"id":"1.195532868","rc":[{"atb":[[5.2,1.99]],"id":42142047}],"con":true,"img":false}]}
{"op":"mcm","clk":"5322739799","pt":1646323694909,"mc":[{"id":"1.195532868","rc":[{"atl":[[1000,12]],"id":2441997}],"con":true,"img":false}]}
{"op":"mcm","clk":"5322739806","pt":1646323695015,"mc":[{"id":"1.195532868","rc":[{"atl":[[9.4,2.1]],"id":2441997}],"con":true,"img":false}]}
{"op":"mcm","clk":"5322739837","pt":1646323695387,"mc":[{"id":"1.195532868","rc":[{"atl":[[9.4,0]],"id":2441997}],"con":true,"img":false}]}
{"op":"mcm","clk":"5322739902","pt":1646323696377,"mc":[{"id":"1.195532868","rc":[{"atb":[[5.2,0]],"id":42142047}],"con":true,"img":false}]}
{"op":"mcm","clk":"5322739912","pt":1646323696534,"mc":[{"id":"1.195532868","rc":[{"atb":[[5.5,1.99]],"id":42142047}],"con":true,"img":false}]}
{"op":"mcm","clk":"5322739994","pt":1646323697717,"mc":[{"id":"1.195532868","rc":[{"atb":[[5.5,0]],"id":42142047}],"con":true,"img":false}]}
{"op":"mcm","clk":"5322740002","pt":1646323697821,"mc":[{"id":"1.195532868","rc":[{"atb":[[5.2,1.99]],"id":42142047}],"con":true,"img":false}]}
{"op":"mcm","clk":"5322740131","pt":1646323699130,"mc":[{"id":"1.195532868","rc":[{"atb":[[5.2,0]],"id":42142047}],"con":true,"img":false}]}
{"op":"mcm","clk":"5322740142","pt":1646323699189,"mc":[{"id":"1.195532868","rc":[{"atb":[[5.5,1.99]],"id":42142047}],"con":true,"img":false}]}
{"op":"mcm","clk":"5322740236","pt":1646323700291,"mc":[{"id":"1.195532868","rc":[{"atb":[[5.5,0]],"id":42142047}],"con":true,"img":false}]}
{"op":"mcm","clk":"5322740247","pt":1646323700388,"mc":[{"id":"1.195532868","rc":[{"atb":[[5.2,1.99]],"id":42142047}],"con":true,"img":false}]}
{"op":"mcm","clk":"5322740276","pt":1646323700702,"mc":[{"id":"1.195532868","rc":[{"atl":[[1000,14.52]],"id":2441997},{"atb":[[1.01,11004.52]],"id":42142047}],"con":true,"img":false}]}
{"op":"mcm","clk":"5322740284","pt":1646323700807,"mc":[{"id":"1.195532868","rc":[{"atb":[[1.01,11003.68]],"id":42142047}],"con":true,"img":false}]}
{"op":"mcm","clk":"5322740296","pt":1646323700912,"mc":[{"id":"1.195532868","rc":[{"atl":[[1000,14.1]],"id":2441997}],"con":true,"img":false}]}
{"op":"mcm","clk":"5322740305","pt":1646323701016,"mc":[{"id":"1.195532868","rc":[{"atb":[[1.01,11002]],"id":42142047}],"con":true,"img":false}]}
{"op":"mcm","clk":"5322740315","pt":1646323701068,"mc":[{"id":"1.195532868","rc":[{"atb":[[6.4,1.68]],"id":42142047}],"con":true,"img":false}]}
{"op":"mcm","clk":"5322740325","pt":1646323701172,"mc":[{"id":"1.195532868","rc":[{"atl":[[1000,12]],"id":2441997}],"con":true,"img":false}]}
{"op":"mcm","clk":"5322740332","pt":1646323701278,"mc":[{"id":"1.195532868","rc":[{"atl":[[9.4,2.1]],"id":2441997}],"con":true,"img":false}]}
{"op":"mcm","clk":"5322740374","pt":1646323701800,"mc":[{"id":"1.195532868","rc":[{"atl":[[9.4,0]],"id":2441997}],"con":true,"img":false}]}
{"op":"mcm","clk":"5322740401","pt":1646323702114,"mc":[{"id":"1.195532868","rc":[{"atb":[[5.2,0]],"id":42142047}],"con":true,"img":false}]}
{"op":"mcm","clk":"5322740409","pt":1646323702218,"mc":[{"id":"1.195532868","rc":[{"atb":[[6.4,3.67]],"id":42142047}],"con":true,"img":false}]}
{"op":"mcm","clk":"5322740876","pt":1646323707500,"mc":[{"id":"1.195532868","rc":[{"atl":[[1000,14.52]],"id":2441997}],"con":true,"img":false}]}
{"op":"mcm","clk":"5322740894","pt":1646323707708,"mc":[{"id":"1.195532868","rc":[{"atl":[[1000,14.1]],"id":2441997}],"con":true,"img":false}]}
{"op":"mcm","clk":"5322740908","pt":1646323707922,"mc":[{"id":"1.195532868","rc":[{"atl":[[1000,12]],"id":2441997}],"con":true,"img":false}]}
{"op":"mcm","clk":"5322740921","pt":1646323708020,"mc":[{"id":"1.195532868","rc":[{"atl":[[9.4,2.1]],"id":2441997}],"con":true,"img":false}]}
{"op":"mcm","clk":"5322740943","pt":1646323708334,"mc":[{"id":"1.195532868","rc":[{"atb":[[6.4,1.68]],"id":42142047}],"con":true,"img":false}]}
{"op":"mcm","clk":"5322740954","pt":1646323708389,"mc":[{"id":"1.195532868","rc":[{"atl":[[9.4,0]],"id":2441997},{"atb":[[5.5,1.99]],"id":42142047}],"con":true,"img":false}]}
{"op":"mcm","clk":"5322741125","pt":1646323710422,"mc":[{"id":"1.195532868","rc":[{"atb":[[8.2,13.13]],"id":40302111},{"atb":[[3.35,12.11]],"id":2441997},{"atb":[[2.88,17.89]],"id":36909993}],"con":true,"img":false}]}
{"op":"mcm","clk":"5322741141","pt":1646323710632,"mc":[{"id":"1.195532868","rc":[{"atb":[[2.84,10.8]],"id":36909993}],"con":true,"img":false}]}
{"op":"mcm","clk":"5322741201","pt":1646323711415,"mc":[{"id":"1.195532868","rc":[{"atb":[[5.5,0]],"id":42142047}],"con":true,"img":false}]}
{"op":"mcm","clk":"5322741215","pt":1646323711519,"mc":[{"id":"1.195532868","rc":[{"atb":[[6.4,3.67]],"id":42142047}],"con":true,"img":false}]}
{"op":"mcm","clk":"5322741225","pt":1646323711622,"mc":[{"id":"1.195532868","rc":[{"atb":[[2.84,0]],"id":36909993}],"con":true,"img":false}]}
{"op":"mcm","clk":"5322741327","pt":1646323712838,"mc":[{"id":"1.195532868","rc":[{"atb":[[6.4,1.68]],"id":42142047}],"con":true,"img":false}]}
{"op":"mcm","clk":"5322741334","pt":1646323712890,"mc":[{"id":"1.195532868","rc":[{"atb":[[5.5,1.99]],"id":42142047}],"con":true,"img":false}]}
{"op":"mcm","clk":"5322741407","pt":1646323713725,"mc":[{"id":"1.195532868","rc":[{"atl":[[1000,14.52]],"id":2441997}],"con":true,"img":false}]}
{"op":"mcm","clk":"5322741417","pt":1646323713827,"mc":[{"id":"1.195532868","rc":[{"atb":[[5.5,0]],"id":42142047}],"con":true,"img":false}]}
{"op":"mcm","clk":"5322741425","pt":1646323713931,"mc":[{"id":"1.195532868","rc":[{"atl":[[1000,14.1]],"id":2441997},{"atb":[[6.4,3.67]],"id":42142047}],"con":true,"img":false}]}
{"op":"mcm","clk":"5322741439","pt":1646323714086,"mc":[{"id":"1.195532868","rc":[{"atl":[[1000,12]],"id":2441997}],"con":true,"img":false}]}
{"op":"mcm","clk":"5322741447","pt":1646323714190,"mc":[{"id":"1.195532868","rc":[{"atl":[[9.4,2.1]],"id":2441997}],"con":true,"img":false}]}
{"op":"mcm","clk":"5322741483","pt":1646323714604,"mc":[{"id":"1.195532868","rc":[{"atl":[[9.4,0]],"id":2441997}],"con":true,"img":false}]}
{"op":"mcm","clk":"5322741932","pt":1646323720009,"mc":[{"id":"1.195532868","rc":[{"atl":[[1000,14.52]],"id":2441997}],"con":true,"img":false}]}
{"op":"mcm","clk":"5322741954","pt":1646323720224,"mc":[{"id":"1.195532868","rc":[{"atl":[[1000,14.1]],"id":2441997}],"con":true,"img":false}]}
{"op":"mcm","clk":"5322741962","pt":1646323720324,"mc":[{"id":"1.195532868","rc":[{"atb":[[6.4,1.68]],"id":42142047}],"con":true,"img":false}]}
{"op":"mcm","clk":"5322741973","pt":1646323720428,"mc":[{"id":"1.195532868","rc":[{"atl":[[1000,12]],"id":2441997},{"atb":[[5.5,1.99]],"id":42142047}],"con":true,"img":false}]}
{"op":"mcm","clk":"5322741982","pt":1646323720531,"mc":[{"id":"1.195532868","rc":[{"atl":[[9.4,2.1]],"id":2441997}],"con":true,"img":false}]}
{"op":"mcm","clk":"5322742027","pt":1646323721009,"mc":[{"id":"1.195532868","rc":[{"atl":[[9.4,0]],"id":2441997}],"con":true,"img":false}]}
{"op":"mcm","clk":"5322742082","pt":1646323721727,"mc":[{"id":"1.195532868","rc":[{"atb":[[5.5,0]],"id":42142047}],"con":true,"img":false}]}
{"op":"mcm","clk":"5322742091","pt":1646323721832,"mc":[{"id":"1.195532868","rc":[{"atb":[[6.4,3.67]],"id":42142047}],"con":true,"img":false}]}
{"op":"mcm","clk":"5322742229","pt":1646323723236,"mc":[{"id":"1.195532868","rc":[{"atb":[[6.4,1.68]],"id":42142047}],"con":true,"img":false}]}
{"op":"mcm","clk":"5322742239","pt":1646323723340,"mc":[{"id":"1.195532868","rc":[{"atb":[[5.5,1.99]],"id":42142047}],"con":true,"img":false}]}
{"op":"mcm","clk":"5322742516","pt":1646323726518,"mc":[{"id":"1.195532868","rc":[{"atl":[[1000,14.52]],"id":2441997}],"con":true,"img":false}]}
{"op":"mcm","clk":"5322742530","pt":1646323726726,"mc":[{"id":"1.195532868","rc":[{"atl":[[1000,14.1]],"id":2441997}],"con":true,"img":false}]}
{"op":"mcm","clk":"5322742554","pt":1646323727038,"mc":[{"id":"1.195532868","rc":[{"atl":[[1000,12]],"id":2441997}],"con":true,"img":false}]}
{"op":"mcm","clk":"5322742562","pt":1646323727140,"mc":[{"id":"1.195532868","rc":[{"atl":[[9.4,2.1]],"id":2441997}],"con":true,"img":false}]}
{"op":"mcm","clk":"5322742585","pt":1646323727402,"mc":[{"id":"1.195532868","rc":[{"atl":[[9.4,0]],"id":2441997}],"con":true,"img":false}]}
{"op":"mcm","clk":"5322742754","pt":1646323729325,"mc":[{"id":"1.195532868","rc":[{"atb":[[5.5,0]],"id":42142047}],"con":true,"img":false}]}
{"op":"mcm","clk":"5322742766","pt":1646323729426,"mc":[{"id":"1.195532868","rc":[{"atb":[[6.4,3.67]],"id":42142047}],"con":true,"img":false}]}
{"op":"mcm","clk":"5322742867","pt":1646323730527,"mc":[{"id":"1.195532868","rc":[{"atb":[[6.4,1.68]],"id":42142047},{"spn":8.2,"spf":1.0,"id":42142047}],"con":true,"img":false}]}
{"op":"mcm","clk":"5322742877","pt":1646323730625,"mc":[{"id":"1.195532868","rc":[{"atb":[[5.5,1.99]],"id":42142047}],"con":true,"img":false}]}
{"op":"mcm","clk":"5322743074","pt":1646323732941,"mc":[{"id":"1.195532868","rc":[{"atl":[[1000,14.52]],"id":2441997}],"con":true,"img":false}]}
{"op":"mcm","clk":"5322743092","pt":1646323733120,"mc":[{"id":"1.195532868","rc":[{"atl":[[1000,14.1]],"id":2441997}],"con":true,"img":false}]}
{"op":"mcm","clk":"5322743120","pt":1646323733433,"mc":[{"id":"1.195532868","rc":[{"atl":[[1000,12]],"id":2441997}],"con":true,"img":false}]}
{"op":"mcm","clk":"5322743133","pt":1646323733535,"mc":[{"id":"1.195532868","rc":[{"atl":[[9.4,2.1]],"id":2441997}],"con":true,"img":false}]}
{"op":"mcm","clk":"5322743152","pt":1646323733744,"mc":[{"id":"1.195532868","rc":[{"atl":[[9.4,0]],"id":2441997}],"con":true,"img":false}]}
{"op":"mcm","clk":"5322743576","pt":1646323738957,"mc":[{"id":"1.195532868","rc":[{"atl":[[1000,14.52]],"id":2441997}],"con":true,"img":false}]}
{"op":"mcm","clk":"5322743598","pt":1646323739221,"mc":[{"id":"1.195532868","rc":[{"atl":[[1000,14.1]],"id":2441997}],"con":true,"img":false}]}
{"op":"mcm","clk":"5322743618","pt":1646323739531,"mc":[{"id":"1.195532868","rc":[{"atl":[[1000,12]],"id":2441997}],"con":true,"img":false}]}
{"op":"mcm","clk":"5322743625","pt":1646323739633,"mc":[{"id":"1.195532868","rc":[{"atl":[[9.4,2.1]],"id":2441997}],"con":true,"img":false}]}
{"op":"mcm","clk":"5322743638","pt":1646323739837,"mc":[{"id":"1.195532868","rc":[{"atl":[[9.4,0]],"id":2441997}],"con":true,"img":false}]}
{"op":"mcm","clk":"5322743781","pt":1646323741563,"mc":[{"id":"1.195532868","rc":[{"atb":[[5.5,0]],"id":42142047}],"con":true,"img":false}]}
{"op":"mcm","clk":"5322743793","pt":1646323741667,"mc":[{"id":"1.195532868","rc":[{"atb":[[6.4,3.67]],"id":42142047}],"con":true,"img":false}]}
{"op":"mcm","clk":"5322744151","pt":1646323745836,"mc":[{"id":"1.195532868","rc":[{"atl":[[1000,14.52]],"id":2441997}],"con":true,"img":false}]}
{"op":"mcm","clk":"5322744177","pt":1646323746145,"mc":[{"id":"1.195532868","rc":[{"atl":[[1000,14.1]],"id":2441997}],"con":true,"img":false}]}
{"op":"mcm","clk":"5322744199","pt":1646323746459,"mc":[{"id":"1.195532868","rc":[{"atl":[[1000,12]],"id":2441997}],"con":true,"img":false}]}
{"op":"mcm","clk":"5322744210","pt":1646323746563,"mc":[{"id":"1.195532868","rc":[{"atl":[[9.4,2.1]],"id":2441997}],"con":true,"img":false}]}
{"op":"mcm","clk":"5322744259","pt":1646323747037,"mc":[{"id":"1.195532868","rc":[{"atl":[[9.4,0]],"id":2441997}],"con":true,"img":false}]}
{"op":"mcm","clk":"5322744405","pt":1646323748541,"mc":[{"id":"1.195532868","rc":[{"atb":[[6.4,1.68]],"id":42142047}],"con":true,"img":false}]}
{"op":"mcm","clk":"5322744417","pt":1646323748647,"mc":[{"id":"1.195532868","rc":[{"atb":[[5.5,1.99]],"id":42142047}],"con":true,"img":false}]}
{"op":"mcm","clk":"5322744744","pt":1646323752435,"mc":[{"id":"1.195532868","rc":[{"atl":[[1000,14.52]],"id":2441997}],"con":true,"img":false}]}
{"op":"mcm","clk":"5322744764","pt":1646323752645,"mc":[{"id":"1.195532868","rc":[{"atl":[[1000,14.1]],"id":2441997}],"con":true,"img":false}]}
{"op":"mcm","clk":"5322744776","pt":1646323752754,"mc":[{"id":"1.195532868","rc":[{"atl":[[1000,12]],"id":2441997}],"con":true,"img":false}]}
{"op":"mcm","clk":"5322744786","pt":1646323752853,"mc":[{"id":"1.195532868","rc":[{"atl":[[9.4,2.1]],"id":2441997}],"con":true,"img":false}]}
{"op":"mcm","clk":"5322744826","pt":1646323753369,"mc":[{"id":"1.195532868","rc":[{"atl":[[9.4,0]],"id":2441997}],"con":true,"img":false}]}
{"op":"mcm","clk":"5322745381","pt":1646323758887,"mc":[{"id":"1.195532868","rc":[{"atl":[[1000,14.52]],"id":2441997}],"con":true,"img":false}]}
{"op":"mcm","clk":"5322745407","pt":1646323759050,"mc":[{"id":"1.195532868","rc":[{"atl":[[1000,14.1]],"id":2441997}],"con":true,"img":false}]}
{"op":"mcm","clk":"5322745428","pt":1646323759258,"mc":[{"id":"1.195532868","rc":[{"atl":[[1000,12]],"id":2441997}],"con":true,"img":false}]}
{"op":"mcm","clk":"5322745443","pt":1646323759358,"mc":[{"id":"1.195532868","rc":[{"atl":[[9.4,2.1]],"id":2441997}],"con":true,"img":false}]}
{"op":"mcm","clk":"5322745466","pt":1646323759576,"mc":[{"id":"1.195532868","rc":[{"atl":[[9.4,0]],"id":2441997}],"con":true,"img":false}]}
{"op":"mcm","clk":"5322745567","pt":1646323760357,"mc":[{"id":"1.195532868","rc":[{"atb":[[5.5,0]],"id":42142047}],"con":true,"img":false}]}
{"op":"mcm","clk":"5322745578","pt":1646323760467,"mc":[{"id":"1.195532868","rc":[{"atb":[[6.4,3.67]],"id":42142047}],"con":true,"img":false}]}
{"op":"mcm","clk":"5322746146","pt":1646323765375,"mc":[{"id":"1.195532868","rc":[{"atl":[[1000,14.52]],"id":2441997}],"con":true,"img":false}]}
{"op":"mcm","clk":"5322746157","pt":1646323765484,"mc":[{"id":"1.195532868","rc":[{"atl":[[1000,14.1]],"id":2441997}],"con":true,"img":false}]}
{"op":"mcm","clk":"5322746182","pt":1646323765687,"mc":[{"id":"1.195532868","rc":[{"atl":[[1000,12]],"id":2441997}],"con":true,"img":false}]}
{"op":"mcm","clk":"5322746191","pt":1646323765793,"mc":[{"id":"1.195532868","rc":[{"atl":[[9.4,2.1]],"id":2441997}],"con":true,"img":false}]}
{"op":"mcm","clk":"5322746221","pt":1646323766005,"mc":[{"id":"1.195532868","rc":[{"atl":[[9.4,0]],"id":2441997}],"con":true,"img":false}]}
{"op":"mcm","clk":"5322746389","pt":1646323767376,"mc":[{"id":"1.195532868","rc":[{"atb":[[6.4,1.68]],"id":42142047}],"con":true,"img":false}]}
{"op":"mcm","clk":"5322746401","pt":1646323767472,"mc":[{"id":"1.195532868","rc":[{"atb":[[5.5,1.99]],"id":42142047}],"con":true,"img":false}]}
{"op":"mcm","clk":"5322746915","pt":1646323771264,"mc":[{"id":"1.195532868","rc":[{"atl":[[1000,14.52]],"id":2441997}],"con":true,"img":false}]}
{"op":"mcm","clk":"5322746943","pt":1646323771580,"mc":[{"id":"1.195532868","rc":[{"atl":[[1000,14.1]],"id":2441997}],"con":true,"img":false}]}
{"op":"mcm","clk":"5322746967","pt":1646323771785,"mc":[{"id":"1.195532868","rc":[{"atl":[[1000,12]],"id":2441997}],"con":true,"img":false}]}
{"op":"mcm","clk":"5322746978","pt":1646323771890,"mc":[{"id":"1.195532868","rc":[{"atl":[[9.4,2.1]],"id":2441997}],"con":true,"img":false}]}
{"op":"mcm","clk":"5322747022","pt":1646323772259,"mc":[{"id":"1.195532868","rc":[{"atl":[[9.4,0]],"id":2441997}],"con":true,"img":false}]}
{"op":"mcm","clk":"5322747162","pt":1646323773570,"mc":[{"id":"1.195532868","rc":[{"atb":[[5.5,0]],"id":42142047}],"con":true,"img":false}]}
{"op":"mcm","clk":"5322747179","pt":1646323773670,"mc":[{"id":"1.195532868","rc":[{"atb":[[6.4,3.67]],"id":42142047}],"con":true,"img":false}]}
{"op":"mcm","clk":"5322747276","pt":1646323774503,"mc":[{"id":"1.195532868","rc":[{"atb":[[6.4,1.68]],"id":42142047}],"con":true,"img":false}]}
{"op":"mcm","clk":"5322747292","pt":1646323774607,"mc":[{"id":"1.195532868","rc":[{"atb":[[5.5,1.99]],"id":42142047}],"con":true,"img":false}]}
{"op":"mcm","clk":"5322747623","pt":1646323777695,"mc":[{"id":"1.195532868","rc":[{"atl":[[1000,14.52]],"id":2441997}],"con":true,"img":false}]}
{"op":"mcm","clk":"5322747650","pt":1646323777906,"mc":[{"id":"1.195532868","rc":[{"atl":[[1000,14.1]],"id":2441997}],"con":true,"img":false}]}
{"op":"mcm","clk":"5322747664","pt":1646323778008,"mc":[{"id":"1.195532868","rc":[{"atl":[[1000,12]],"id":2441997}],"con":true,"img":false}]}
{"op":"mcm","clk":"5322747675","pt":1646323778115,"mc":[{"id":"1.195532868","rc":[{"atl":[[9.4,2.1]],"id":2441997}],"con":true,"img":false}]}
{"op":"mcm","clk":"5322747749","pt":1646323778698,"mc":[{"id":"1.195532868","rc":[{"atl":[[9.4,0]],"id":2441997}],"con":true,"img":false}]}
{"op":"mcm","clk":"5322747934","pt":1646323780341,"mc":[{"id":"1.195532868","rc":[{"atb":[[5.5,0]],"id":42142047}],"con":true,"img":false}]}
{"op":"mcm","clk":"5322747948","pt":1646323780421,"mc":[{"id":"1.195532868","rc":[{"atb":[[6.4,3.67]],"id":42142047}],"con":true,"img":false}]}
{"op":"mcm","clk":"5322748149","pt":1646323781936,"mc":[{"id":"1.195532868","rc":[{"atb":[[6.4,1.68]],"id":42142047}],"con":true,"img":false}]}
{"op":"mcm","clk":"5322748168","pt":1646323782041,"mc":[{"id":"1.195532868","rc":[{"atb":[[5.5,1.99]],"id":42142047}],"con":true,"img":false}]}
{"op":"mcm","clk":"5322748255","pt":1646323782721,"mc":[{"id":"1.195532868","rc":[{"atb":[[5.5,0]],"id":42142047}],"con":true,"img":false}]}
{"op":"mcm","clk":"5322748268","pt":1646323782819,"mc":[{"id":"1.195532868","rc":[{"atb":[[6.4,3.67]],"id":42142047}],"con":true,"img":false}]}
{"op":"mcm","clk":"5322748461","pt":1646323784337,"mc":[{"id":"1.195532868","rc":[{"atl":[[1000,14.52]],"id":2441997}],"con":true,"img":false}]}
{"op":"mcm","clk":"5322748472","pt":1646323784441,"mc":[{"id":"1.195532868","rc":[{"atl":[[1000,14.1]],"id":2441997}],"con":true,"img":false}]}
{"op":"mcm","clk":"5322748496","pt":1646323784642,"mc":[{"id":"1.195532868","rc":[{"atl":[[1000,12]],"id":2441997}],"con":true,"img":false}]}
{"op":"mcm","clk":"5322748511","pt":1646323784743,"mc":[{"id":"1.195532868","rc":[{"atl":[[9.4,2.1]],"id":2441997}],"con":true,"img":false}]}
{"op":"mcm","clk":"5322748585","pt":1646323785328,"mc":[{"id":"1.195532868","rc":[{"atl":[[9.4,0]],"id":2441997}],"con":true,"img":false}]}
{"op":"mcm","clk":"5322748950","pt":1646323788880,"mc":[{"id":"1.195532868","rc":[{"atb":[[6.4,1.68]],"id":42142047}],"con":true,"img":false}]}
{"op":"mcm","clk":"5322748969","pt":1646323789037,"mc":[{"id":"1.195532868","rc":[{"atb":[[5.5,1.99]],"id":42142047}],"con":true,"img":false}]}
{"op":"mcm","clk":"5322749141","pt":1646323790451,"mc":[{"id":"1.195532868","rc":[{"atl":[[1000,14.52]],"id":2441997}],"con":true,"img":false}]}
{"op":"mcm","clk":"5322749163","pt":1646323790608,"mc":[{"id":"1.195532868","rc":[{"atl":[[1000,14.1]],"id":2441997},{"atb":[[5.5,0]],"id":42142047}],"con":true,"img":false}]}
{"op":"mcm","clk":"5322749190","pt":1646323790720,"mc":[{"id":"1.195532868","rc":[{"atl":[[1000,12]],"id":2441997},{"atb":[[6.4,3.67]],"id":42142047}],"con":true,"img":false}]}
{"op":"mcm","clk":"5322749213","pt":1646323790819,"mc":[{"id":"1.195532868","rc":[{"atl":[[9.4,2.1]],"id":2441997}],"con":true,"img":false}]}
{"op":"mcm","clk":"5322749234","pt":1646323791027,"mc":[{"id":"1.195532868","rc":[{"atl":[[9.4,0]],"id":2441997}],"con":true,"img":false}]}
{"op":"mcm","clk":"5322749887","pt":1646323797033,"mc":[{"id":"1.195532868","rc":[{"atl":[[1000,14.52]],"id":2441997},{"atb":[[6.4,1.68]],"id":42142047}],"con":true,"img":false}]}
{"op":"mcm","clk":"5322749897","pt":1646323797130,"mc":[{"id":"1.195532868","rc":[{"atb":[[5.5,1.99]],"id":42142047}],"con":true,"img":false}]}
{"op":"mcm","clk":"5322749913","pt":1646323797348,"mc":[{"id":"1.195532868","rc":[{"atl":[[1000,14.1]],"id":2441997}],"con":true,"img":false}]}
{"op":"mcm","clk":"5322749925","pt":1646323797448,"mc":[{"id":"1.195532868","rc":[{"atl":[[1000,12]],"id":2441997}],"con":true,"img":false}]}
{"op":"mcm","clk":"5322749935","pt":1646323797546,"mc":[{"id":"1.195532868","rc":[{"atl":[[9.4,2.1]],"id":2441997}],"con":true,"img":false}]}
{"op":"mcm","clk":"5322749986","pt":1646323798020,"mc":[{"id":"1.195532868","rc":[{"atl":[[9.4,0]],"id":2441997}],"con":true,"img":false}]}
{"op":"mcm","clk":"5322750586","pt":1646323803138,"mc":[{"id":"1.195532868","rc":[{"atb":[[5.5,0]],"id":42142047}],"con":true,"img":false}]}
{"op":"mcm","clk":"5322750598","pt":1646323803245,"mc":[{"id":"1.195532868","rc":[{"atb":[[6.4,3.67]],"id":42142047}],"con":true,"img":false}]}
{"op":"mcm","clk":"5322750643","pt":1646323803558,"mc":[{"id":"1.195532868","rc":[{"atl":[[1000,14.52]],"id":2441997}],"con":true,"img":false}]}
{"op":"mcm","clk":"5322750671","pt":1646323803719,"mc":[{"id":"1.195532868","rc":[{"atl":[[1000,14.1]],"id":2441997}],"con":true,"img":false}]}
{"op":"mcm","clk":"5322750689","pt":1646323803824,"mc":[{"id":"1.195532868","rc":[{"atl":[[1000,12]],"id":2441997}],"con":true,"img":false}]}
{"op":"mcm","clk":"5322750705","pt":1646323803926,"mc":[{"id":"1.195532868","rc":[{"atl":[[9.4,2.1]],"id":2441997}],"con":true,"img":false}]}
{"op":"mcm","clk":"5322750735","pt":1646323804140,"mc":[{"id":"1.195532868","rc":[{"atl":[[9.4,0]],"id":2441997}],"con":true,"img":false}]}
{"op":"mcm","clk":"5322750792","pt":1646323804537,"mc":[{"id":"1.195532868","rc":[{"atb":[[6.4,1.68]],"id":42142047}],"con":true,"img":false}]}
{"op":"mcm","clk":"5322750828","pt":1646323804844,"mc":[{"id":"1.195532868","rc":[{"atb":[[5.5,1.99]],"id":42142047}],"con":true,"img":false}]}
{"op":"mcm","clk":"5322751020","pt":1646323806161,"mc":[{"id":"1.195532868","rc":[{"atb":[[5.5,0]],"id":42142047}],"con":true,"img":false}]}
{"op":"mcm","clk":"5322751039","pt":1646323806273,"mc":[{"id":"1.195532868","rc":[{"atb":[[6.4,3.67]],"id":42142047}],"con":true,"img":false}]}
{"op":"mcm","clk":"5322751593","pt":1646323809924,"mc":[{"id":"1.195532868","rc":[{"atl":[[1000,14.52]],"id":2441997}],"con":true,"img":false}]}
{"op":"mcm","clk":"5322751618","pt":1646323810136,"mc":[{"id":"1.195532868","rc":[{"atl":[[1000,14.1]],"id":2441997}],"con":true,"img":false}]}
{"op":"mcm","clk":"5322751630","pt":1646323810241,"mc":[{"id":"1.195532868","rc":[{"atl":[[1000,12]],"id":2441997}],"con":true,"img":false}]}
{"op":"mcm","clk":"5322751646","pt":1646323810348,"mc":[{"id":"1.195532868","rc":[{"atl":[[9.4,2.1]],"id":2441997}],"con":true,"img":false}]}
{"op":"mcm","clk":"5322751689","pt":1646323810660,"mc":[{"id":"1.195532868","rc":[{"atl":[[9.4,0]],"id":2441997}],"con":true,"img":false}]}
{"op":"mcm","clk":"5322752005","pt":1646323812553,"mc":[{"id":"1.195532868","rc":[{"atb":[[6.4,1.68]],"id":42142047}],"con":true,"img":false}]}
{"op":"mcm","clk":"5322752025","pt":1646323812657,"mc":[{"id":"1.195532868","rc":[{"atb":[[5.5,1.99]],"id":42142047}],"con":true,"img":false}]}
{"op":"mcm","clk":"5322752148","pt":1646323813656,"mc":[{"id":"1.195532868","rc":[{"atb":[[5.5,0]],"id":42142047}],"con":true,"img":false}]}
{"op":"mcm","clk":"5322752164","pt":1646323813768,"mc":[{"id":"1.195532868","rc":[{"atb":[[6.4,3.67]],"id":42142047}],"con":true,"img":false}]}
{"op":"mcm","clk":"5322752511","pt":1646323816246,"mc":[{"id":"1.195532868","rc":[{"atl":[[1000,14.52]],"id":2441997}],"con":true,"img":false}]}
{"op":"mcm","clk":"5322752534","pt":1646323816455,"mc":[{"id":"1.195532868","rc":[{"atl":[[1000,14.1]],"id":2441997}],"con":true,"img":false}]}
{"op":"mcm","clk":"5322752563","pt":1646323816663,"mc":[{"id":"1.195532868","rc":[{"atl":[[1000,12]],"id":2441997}],"con":true,"img":false}]}
{"op":"mcm","clk":"5322752579","pt":1646323816766,"mc":[{"id":"1.195532868","rc":[{"atl":[[9.4,2.1]],"id":2441997}],"con":true,"img":false}]}
{"op":"mcm","clk":"5322752638","pt":1646323817242,"mc":[{"id":"1.195532868","rc":[{"atl":[[9.4,0]],"id":2441997}],"con":true,"img":false}]}
{"op":"mcm","clk":"5322752932","pt":1646323819462,"mc":[{"id":"1.195532868","rc":[{"atb":[[6.4,1.68]],"id":42142047}],"con":true,"img":false}]}
{"op":"mcm","clk":"5322752948","pt":1646323819565,"mc":[{"id":"1.195532868","rc":[{"atb":[[5.5,1.99]],"id":42142047}],"con":true,"img":false}]}
{"op":"mcm","clk":"5322753208","pt":1646323821359,"mc":[{"id":"1.195532868","rc":[{"atb":[[5.5,0]],"id":42142047}],"con":true,"img":false}]}
{"op":"mcm","clk":"5322753222","pt":1646323821464,"mc":[{"id":"1.195532868","rc":[{"atb":[[6.4,3.67]],"id":42142047}],"con":true,"img":false}]}
{"op":"mcm","clk":"5322753347","pt":1646323822564,"mc":[{"id":"1.195532868","rc":[{"atl":[[1000,14.52]],"id":2441997}],"con":true,"img":false}]}
{"op":"mcm","clk":"5322753368","pt":1646323822775,"mc":[{"id":"1.195532868","rc":[{"atl":[[1000,14.1]],"id":2441997}],"con":true,"img":false}]}
{"op":"mcm","clk":"5322753391","pt":1646323822879,"mc":[{"id":"1.195532868","rc":[{"atl":[[1000,12]],"id":2441997}],"con":true,"img":false}]}
{"op":"mcm","clk":"5322753403","pt":1646323822933,"mc":[{"id":"1.195532868","rc":[{"atl":[[9.4,2.1]],"id":2441997}],"con":true,"img":false}]}
{"op":"mcm","clk":"5322753452","pt":1646323823353,"mc":[{"id":"1.195532868","rc":[{"atl":[[9.4,0]],"id":2441997}],"con":true,"img":false}]}
{"op":"mcm","clk":"5322753938","pt":1646323827478,"mc":[{"id":"1.195532868","rc":[{"atb":[[6.4,1.68]],"id":42142047}],"con":true,"img":false}]}
{"op":"mcm","clk":"5322753955","pt":1646323827583,"mc":[{"id":"1.195532868","rc":[{"atb":[[5.5,1.99]],"id":42142047}],"con":true,"img":false}]}
{"op":"mcm","clk":"5322754132","pt":1646323828949,"mc":[{"id":"1.195532868","rc":[{"atl":[[1000,14.52]],"id":2441997}],"con":true,"img":false}]}
{"op":"mcm","clk":"5322754145","pt":1646323829084,"mc":[{"id":"1.195532868","rc":[{"atl":[[1000,14.1]],"id":2441997}],"con":true,"img":false}]}
{"op":"mcm","clk":"5322754175","pt":1646323829292,"mc":[{"id":"1.195532868","rc":[{"atl":[[1000,12]],"id":2441997}],"con":true,"img":false}]}
{"op":"mcm","clk":"5322754185","pt":1646323829344,"mc":[{"id":"1.195532868","rc":[{"atl":[[9.4,2.1]],"id":2441997}],"con":true,"img":false}]}
{"op":"mcm","clk":"5322754223","pt":1646323829661,"mc":[{"id":"1.195532868","rc":[{"atl":[[9.4,0]],"id":2441997}],"con":true,"img":false}]}
{"op":"mcm","clk":"5322754844","pt":1646323834583,"mc":[{"id":"1.195532868","rc":[{"atl":[[1000,14.52]],"id":2441997}],"con":true,"img":false}]}
{"op":"mcm","clk":"5322754853","pt":1646323834690,"mc":[{"id":"1.195532868","rc":[{"atl":[[1000,14.1]],"id":2441997}],"con":true,"img":false}]}
{"op":"mcm","clk":"5322754879","pt":1646323834851,"mc":[{"id":"1.195532868","rc":[{"atl":[[1000,12]],"id":2441997}],"con":true,"img":false}]}
{"op":"mcm","clk":"5322754893","pt":1646323834954,"mc":[{"id":"1.195532868","rc":[{"atl":[[9.4,2.1]],"id":2441997}],"con":true,"img":false}]}
{"op":"mcm","clk":"5322754923","pt":1646323835162,"mc":[{"id":"1.195532868","rc":[{"atl":[[9.4,0]],"id":2441997}],"con":true,"img":false}]}
{"op":"mcm","clk":"5322755721","pt":1646323841196,"mc":[{"id":"1.195532868","rc":[{"atl":[[1000,14.52]],"id":2441997}],"con":true,"img":false}]}
{"op":"mcm","clk":"5322755746","pt":1646323841394,"mc":[{"id":"1.195532868","rc":[{"atl":[[1000,14.1]],"id":2441997}],"con":true,"img":false}]}
{"op":"mcm","clk":"5322755776","pt":1646323841604,"mc":[{"id":"1.195532868","rc":[{"atl":[[1000,12]],"id":2441997}],"con":true,"img":false}]}
{"op":"mcm","clk":"5322755789","pt":1646323841663,"mc":[{"id":"1.195532868","rc":[{"atl":[[9.4,2.1]],"id":2441997}],"con":true,"img":false}]}
{"op":"mcm","clk":"5322755837","pt":1646323842080,"mc":[{"id":"1.195532868","rc":[{"atl":[[9.4,0]],"id":2441997}],"con":true,"img":false}]}
{"op":"mcm","clk":"5322756431","pt":1646323847724,"mc":[{"id":"1.195532868","rc":[{"atl":[[1000,14.52]],"id":2441997}],"con":true,"img":false}]}
{"op":"mcm","clk":"5322756456","pt":1646323847923,"mc":[{"id":"1.195532868","rc":[{"atl":[[1000,14.1]],"id":2441997}],"con":true,"img":false}]}
{"op":"mcm","clk":"5322756477","pt":1646323848084,"mc":[{"id":"1.195532868","rc":[{"atl":[[1000,12]],"id":2441997}],"con":true,"img":false}]}
{"op":"mcm","clk":"5322756491","pt":1646323848196,"mc":[{"id":"1.195532868","rc":[{"atl":[[9.4,2.1]],"id":2441997}],"con":true,"img":false}]}
{"op":"mcm","clk":"5322756539","pt":1646323848606,"mc":[{"id":"1.195532868","rc":[{"atl":[[9.4,0]],"id":2441997}],"con":true,"img":false}]}
{"op":"mcm","clk":"5322756640","pt":1646323849403,"mc":[{"id":"1.195532868","rc":[{"atb":[[5.5,0]],"id":42142047}],"con":true,"img":false}]}
{"op":"mcm","clk":"5322756656","pt":1646323849497,"mc":[{"id":"1.195532868","rc":[{"atb":[[6.4,3.67]],"id":42142047}],"con":true,"img":false}]}
{"op":"mcm","clk":"5322756801","pt":1646323850813,"mc":[{"id":"1.195532868","rc":[{"atb":[[6.4,1.68]],"id":42142047}],"con":true,"img":false}]}
{"op":"mcm","clk":"5322756814","pt":1646323850907,"mc":[{"id":"1.195532868","rc":[{"atb":[[5.5,1.99]],"id":42142047}],"con":true,"img":false}]}
{"op":"mcm","clk":"5322757031","pt":1646323852430,"mc":[{"id":"1.195532868","rc":[{"atb":[[5.5,0]],"id":42142047}],"con":true,"img":false}]}
{"op":"mcm","clk":"5322757059","pt":1646323852593,"mc":[{"id":"1.195532868","rc":[{"atb":[[6.4,3.67]],"id":42142047}],"con":true,"img":false}]}
{"op":"mcm","clk":"5322757183","pt":1646323853835,"mc":[{"id":"1.195532868","rc":[{"atb":[[6.4,1.68]],"id":42142047}],"con":true,"img":false}]}
{"op":"mcm","clk":"5322757197","pt":1646323853889,"mc":[{"id":"1.195532868","rc":[{"atb":[[5.5,1.99]],"id":42142047}],"con":true,"img":false}]}
{"op":"mcm","clk":"5322757214","pt":1646323853998,"mc":[{"id":"1.195532868","rc":[{"atl":[[1000,14.52]],"id":2441997}],"con":true,"img":false}]}
{"op":"mcm","clk":"5322757232","pt":1646323854206,"mc":[{"id":"1.195532868","rc":[{"atl":[[1000,14.1]],"id":2441997}],"con":true,"img":false}]}
{"op":"mcm","clk":"5322757259","pt":1646323854413,"mc":[{"id":"1.195532868","rc":[{"atl":[[1000,12]],"id":2441997}],"con":true,"img":false}]}
{"op":"mcm","clk":"5322757277","pt":1646323854526,"mc":[{"id":"1.195532868","rc":[{"atl":[[9.4,2.1]],"id":2441997}],"con":true,"img":false}]}
{"op":"mcm","clk":"5322757316","pt":1646323854832,"mc":[{"id":"1.195532868","rc":[{"atb":[[5.5,0]],"id":42142047}],"con":true,"img":false}]}
{"op":"mcm","clk":"5322757336","pt":1646323854935,"mc":[{"id":"1.195532868","rc":[{"atb":[[6.4,3.67]],"id":42142047}],"con":true,"img":false}]}
{"op":"mcm","clk":"5322757350","pt":1646323855031,"mc":[{"id":"1.195532868","rc":[{"atl":[[9.4,0]],"id":2441997}],"con":true,"img":false}]}
{"op":"mcm","clk":"5322757532","pt":1646323856241,"mc":[{"id":"1.195532868","rc":[{"atb":[[6.4,1.68]],"id":42142047}],"con":true,"img":false}]}
{"op":"mcm","clk":"5322757547","pt":1646323856351,"mc":[{"id":"1.195532868","rc":[{"atb":[[5.5,1.99]],"id":42142047}],"con":true,"img":false}]}
{"op":"mcm","clk":"5322757845","pt":1646323858820,"mc":[{"id":"1.195532868","rc":[{"atb":[[5.5,0]],"id":42142047}],"con":true,"img":false}]}
{"op":"mcm","clk":"5322757895","pt":1646323858925,"mc":[{"id":"1.195532868","rc":[{"atb":[[6.4,3.67]],"id":42142047}],"con":true,"img":false}]}
{"op":"mcm","clk":"5322758002","pt":1646323859815,"mc":[{"id":"1.195532868","rc":[{"atb":[[6.4,1.68]],"id":42142047}],"con":true,"img":false}]}
{"op":"mcm","clk":"5322758017","pt":1646323859918,"mc":[{"id":"1.195532868","rc":[{"atb":[[5.5,1.99]],"id":42142047}],"con":true,"img":false}]}
{"op":"mcm","clk":"5322758086","pt":1646323860503,"mc":[{"id":"1.195532868","rc":[{"atl":[[1000,14.52]],"id":2441997}],"con":true,"img":false}]}
{"op":"mcm","clk":"5322758100","pt":1646323860603,"mc":[{"id":"1.195532868","rc":[{"atl":[[1000,14.1]],"id":2441997}],"con":true,"img":false}]}
{"op":"mcm","clk":"5322758112","pt":1646323860711,"mc":[{"id":"1.195532868","rc":[{"atl":[[1000,12]],"id":2441997}],"con":true,"img":false}]}
{"op":"mcm","clk":"5322758126","pt":1646323860813,"mc":[{"id":"1.195532868","rc":[{"atl":[[9.4,2.1]],"id":2441997}],"con":true,"img":false}]}
{"op":"mcm","clk":"5322758161","pt":1646323861131,"mc":[{"id":"1.195532868","rc":[{"atl":[[9.4,0]],"id":2441997}],"con":true,"img":false}]}
{"op":"mcm","clk":"5322758208","pt":1646323861599,"mc":[{"id":"1.195532868","rc":[{"atb":[[5.5,0]],"id":42142047}],"con":true,"img":false}]}
{"op":"mcm","clk":"5322758221","pt":1646323861701,"mc":[{"id":"1.195532868","rc":[{"atb":[[6.4,3.67]],"id":42142047}],"con":true,"img":false}]}
{"op":"mcm","clk":"5322758267","pt":1646323862138,"mc":[{"id":"1.195532868","rc":[{"atb":[[6.4,1.68]],"id":42142047}],"con":true,"img":false}]}
{"op":"mcm","clk":"5322758277","pt":1646323862228,"mc":[{"id":"1.195532868","rc":[{"atb":[[5.5,1.99]],"id":42142047}],"con":true,"img":false}]}
{"op":"mcm","clk":"5322758359","pt":1646323862919,"mc":[{"id":"1.195532868","rc":[{"atb":[[5.5,0]],"id":42142047}],"con":true,"img":false}]}
{"op":"mcm","clk":"5322758376","pt":1646323863029,"mc":[{"id":"1.195532868","rc":[{"atb":[[6.4,3.67]],"id":42142047}],"con":true,"img":false}]}
{"op":"mcm","clk":"5322758912","pt":1646323867235,"mc":[{"id":"1.195532868","rc":[{"atl":[[1000,14.52]],"id":2441997}],"con":true,"img":false}]}
{"op":"mcm","clk":"5322758942","pt":1646323867444,"mc":[{"id":"1.195532868","rc":[{"atl":[[1000,14.1]],"id":2441997}],"con":true,"img":false}]}
{"op":"mcm","clk":"5322758975","pt":1646323867654,"mc":[{"id":"1.195532868","rc":[{"atl":[[1000,12]],"id":2441997}],"con":true,"img":false}]}
{"op":"mcm","clk":"5322758987","pt":1646323867709,"mc":[{"id":"1.195532868","rc":[{"atl":[[9.4,2.1]],"id":2441997}],"con":true,"img":false}]}
{"op":"mcm","clk":"5322759034","pt":1646323868030,"mc":[{"id":"1.195532868","rc":[{"atl":[[9.4,0]],"id":2441997}],"con":true,"img":false}]}
{"op":"mcm","clk":"5322759255","pt":1646323869613,"mc":[{"id":"1.195532868","rc":[{"atb":[[6.4,1.68]],"id":42142047}],"con":true,"img":false}]}
{"op":"mcm","clk":"5322759265","pt":1646323869722,"mc":[{"id":"1.195532868","rc":[{"atb":[[5.5,1.99]],"id":42142047}],"con":true,"img":false}]}
{"op":"mcm","clk":"5322759424","pt":1646323871235,"mc":[{"id":"1.195532868","rc":[{"atb":[[5.5,0]],"id":42142047}],"con":true,"img":false}]}
{"op":"mcm","clk":"5322759438","pt":1646323871338,"mc":[{"id":"1.195532868","rc":[{"atb":[[6.4,3.67]],"id":42142047}],"con":true,"img":false}]}
{"op":"mcm","clk":"5322759521","pt":1646323872029,"mc":[{"id":"1.195532868","rc":[{"atb":[[6.4,1.68]],"id":42142047}],"con":true,"img":false}]}
{"op":"mcm","clk":"5322759537","pt":1646323872140,"mc":[{"id":"1.195532868","rc":[{"atb":[[5.5,1.99]],"id":42142047}],"con":true,"img":false}]}
{"op":"mcm","clk":"5322759669","pt":1646323873445,"mc":[{"id":"1.195532868","rc":[{"atl":[[1000,14.52]],"id":2441997}],"con":true,"img":false}]}
{"op":"mcm","clk":"5322759682","pt":1646323873549,"mc":[{"id":"1.195532868","rc":[{"atl":[[1000,14.1]],"id":2441997}],"con":true,"img":false}]}
{"op":"mcm","clk":"5322759704","pt":1646323873710,"mc":[{"id":"1.195532868","rc":[{"atl":[[1000,12]],"id":2441997}],"con":true,"img":false}]}
{"op":"mcm","clk":"5322759717","pt":1646323873815,"mc":[{"id":"1.195532868","rc":[{"atl":[[9.4,2.1]],"id":2441997}],"con":true,"img":false}]}
{"op":"mcm","clk":"5322759749","pt":1646323874127,"mc":[{"id":"1.195532868","rc":[{"atl":[[9.4,0]],"id":2441997}],"con":true,"img":false}]}
{"op":"mcm","clk":"5322760230","pt":1646323878158,"mc":[{"id":"1.195532868","rc":[{"atb":[[5.5,0]],"id":42142047}],"con":true,"img":false}]}
{"op":"mcm","clk":"5322760243","pt":1646323878264,"mc":[{"id":"1.195532868","rc":[{"atb":[[6.4,3.67]],"id":42142047}],"con":true,"img":false}]}
{"op":"mcm","clk":"5322760459","pt":1646323879948,"mc":[{"id":"1.195532868","rc":[{"atl":[[1000,14.52]],"id":2441997}],"con":true,"img":false}]}
{"op":"mcm","clk":"5322760480","pt":1646323880157,"mc":[{"id":"1.195532868","rc":[{"atl":[[1000,14.1]],"id":2441997}],"con":true,"img":false}]}
{"op":"mcm","clk":"5322760506","pt":1646323880325,"mc":[{"id":"1.195532868","rc":[{"atl":[[1000,12]],"id":2441997}],"con":true,"img":false}]}
{"op":"mcm","clk":"5322760523","pt":1646323880427,"mc":[{"id":"1.195532868","rc":[{"atl":[[9.4,2.1]],"id":2441997}],"con":true,"img":false}]}
{"op":"mcm","clk":"5322760560","pt":1646323880734,"mc":[{"id":"1.195532868","rc":[{"atl":[[9.4,0]],"id":2441997}],"con":true,"img":false}]}
{"op":"mcm","clk":"5322760660","pt":1646323881526,"mc":[{"id":"1.195532868","rc":[{"atb":[[6.4,1.68]],"id":42142047}],"con":true,"img":false}]}
{"op":"mcm","clk":"5322760674","pt":1646323881631,"mc":[{"id":"1.195532868","rc":[{"atb":[[5.5,1.99]],"id":42142047}],"con":true,"img":false}]}
{"op":"mcm","clk":"5322760846","pt":1646323883164,"mc":[{"id":"1.195532868","rc":[{"atb":[[5.5,0]],"id":42142047}],"con":true,"img":false}]}
{"op":"mcm","clk":"5322760856","pt":1646323883226,"mc":[{"id":"1.195532868","rc":[{"atb":[[6.4,3.67]],"id":42142047}],"con":true,"img":false}]}
{"op":"mcm","clk":"5322760905","pt":1646323883737,"mc":[{"id":"1.195532868","rc":[{"atb":[[15,57.9]],"id":40302111},{"trd":[[15,20.15]],"ltp":15.0,"tv":20.15,"id":40302111}],"con":true,"img":false}]}
{"op":"mcm","clk":"5322760936","pt":1646323884049,"mc":[{"id":"1.195532868","rc":[{"atb":[[6.4,1.68]],"id":42142047}],"con":true,"img":false}]}
{"op":"mcm","clk":"5322760950","pt":1646323884154,"mc":[{"id":"1.195532868","rc":[{"atb":[[5.5,1.99]],"id":42142047}],"con":true,"img":false}]}
{"op":"mcm","clk":"5322761118","pt":1646323885465,"mc":[{"id":"1.195532868","rc":[{"atb":[[5.5,0]],"id":42142047}],"con":true,"img":false}]}
{"op":"mcm","clk":"5322761132","pt":1646323885568,"mc":[{"id":"1.195532868","rc":[{"atb":[[6.4,3.67]],"id":42142047}],"con":true,"img":false}]}
{"op":"mcm","clk":"5322761218","pt":1646323886262,"mc":[{"id":"1.195532868","rc":[{"atl":[[1000,14.52]],"id":2441997}],"con":true,"img":false}]}
{"op":"mcm","clk":"5322761247","pt":1646323886473,"mc":[{"id":"1.195532868","rc":[{"atl":[[1000,14.1]],"id":2441997}],"con":true,"img":false}]}
{"op":"mcm","clk":"5322761277","pt":1646323886637,"mc":[{"id":"1.195532868","rc":[{"atl":[[1000,12]],"id":2441997}],"con":true,"img":false}]}
{"op":"mcm","clk":"5322761292","pt":1646323886770,"mc":[{"id":"1.195532868","rc":[{"atl":[[9.4,2.1]],"id":2441997}],"con":true,"img":false}]}
{"op":"mcm","clk":"5322761325","pt":1646323887052,"mc":[{"id":"1.195532868","rc":[{"atl":[[9.4,0]],"id":2441997}],"con":true,"img":false}]}
{"op":"mcm","clk":"5322761338","pt":1646323887157,"mc":[{"id":"1.195532868","rc":[{"atb":[[6.4,1.68]],"id":42142047}],"con":true,"img":false}]}
{"op":"mcm","clk":"5322761352","pt":1646323887262,"mc":[{"id":"1.195532868","rc":[{"atb":[[5.5,1.99]],"id":42142047}],"con":true,"img":false}]}
{"op":"mcm","clk":"5322761431","pt":1646323887941,"mc":[{"id":"1.195532868","rc":[{"atb":[[5.5,0]],"id":42142047}],"con":true,"img":false}]}
{"op":"mcm","clk":"5322761444","pt":1646323888044,"mc":[{"id":"1.195532868","rc":[{"atb":[[6.4,3.67]],"id":42142047}],"con":true,"img":false}]}
{"op":"mcm","clk":"5322761497","pt":1646323888566,"mc":[{"id":"1.195532868","rc":[{"atb":[[6.4,1.68]],"id":42142047}],"con":true,"img":false}]}
{"op":"mcm","clk":"5322761509","pt":1646323888625,"mc":[{"id":"1.195532868","rc":[{"atb":[[5.5,1.99]],"id":42142047}],"con":true,"img":false}]}
{"op":"mcm","clk":"5322761935","pt":1646323892363,"mc":[{"id":"1.195532868","rc":[{"atl":[[1000,14.52]],"id":2441997}],"con":true,"img":false}]}
{"op":"mcm","clk":"5322761947","pt":1646323892457,"mc":[{"id":"1.195532868","rc":[{"atl":[[1000,14.1]],"id":2441997}],"con":true,"img":false}]}
{"op":"mcm","clk":"5322761972","pt":1646323892670,"mc":[{"id":"1.195532868","rc":[{"atl":[[1000,12]],"id":2441997}],"con":true,"img":false}]}
{"op":"mcm","clk":"5322761987","pt":1646323892776,"mc":[{"id":"1.195532868","rc":[{"atl":[[9.4,2.1]],"id":2441997}],"con":true,"img":false}]}
{"op":"mcm","clk":"5322762010","pt":1646323892945,"mc":[{"id":"1.195532868","rc":[{"atl":[[9.4,0]],"id":2441997}],"con":true,"img":false}]}
{"op":"mcm","clk":"5322762124","pt":1646323893937,"mc":[{"id":"1.195532868","rc":[{"atb":[[15.5,1.74]],"id":40302111},{"atb":[[3.4,1.69]],"id":2441997},{"atb":[[2.9,1.74]],"id":36909993},{"atb":[[5.2,1.71]],"id":42142047},{"atb":[[5.2,3.57]],"id":42609835},{"atb":[[3.8,1.6]],"id":40133336}],"con":true,"img":false}]}
{"op":"mcm","clk":"5322762145","pt":1646323894149,"mc":[{"id":"1.195532868","rc":[{"atb":[[2.86,26.51]],"id":36909993}],"con":true,"img":false}]}
{"op":"mcm","clk":"5322762190","pt":1646323894676,"mc":[{"id":"1.195532868","rc":[{"atl":[[9.8,0.82]],"id":2441997},{"atl":[[5.1,0.82]],"id":36909993},{"atb":[[5.5,0]],"id":42142047},{"atl":[[13,0.82]],"id":42142047},{"atl":[[8.2,0.82]],"id":40133336}],"con":true,"img":false}]}
{"op":"mcm","clk":"5322762203","pt":1646323894783,"mc":[{"id":"1.195532868","rc":[{"atb":[[6.4,3.67]],"id":42142047}],"con":true,"img":false}]}
{"op":"mcm","clk":"5322762290","pt":1646323895538,"mc":[{"id":"1.195532868","rc":[{"atl":[[9.8,0.48]],"id":2441997},{"atl":[[5.1,0.44]],"id":36909993},{"atl":[[13,0.46]],"id":42142047},{"atl":[[8.2,0.48]],"id":40133336}],"con":true,"img":false}]}
{"op":"mcm","clk":"5322762324","pt":1646323895850,"mc":[{"id":"1.195532868","rc":[{"atb":[[2.86,21.51]],"id":36909993}],"con":true,"img":false}]}
{"op":"mcm","clk":"5322762370","pt":1646323896269,"mc":[{"id":"1.195532868","rc":[{"atb":[[3.35,0]],"id":2441997},{"atb":[[2.88,0]],"id":36909993},{"atb":[[6.4,1.68]],"id":42142047}],"con":true,"img":false}]}
{"op":"mcm","clk":"5322762382","pt":1646323896372,"mc":[{"id":"1.195532868","rc":[{"atb":[[5.5,1.99]],"id":42142047}],"con":true,"img":false}]}
{"op":"mcm","clk":"5322762446","pt":1646323896950,"mc":[{"id":"1.195532868","rc":[{"atb":[[3.4,0]],"id":2441997},{"atb":[[2.9,0]],"id":36909993}],"con":true,"img":false}]}
{"op":"mcm","clk":"5322762458","pt":1646323897060,"mc":[{"id":"1.195532868","rc":[{"atb":[[3.35,1.69]],"id":2441997},{"atb":[[2.88,1.74]],"id":36909993}],"con":true,"img":false}]}
{"op":"mcm","clk":"5322762471","pt":1646323897159,"mc":[{"id":"1.195532868","rc":[{"atb":[[5.5,0]],"id":42142047}],"con":true,"img":false}]}
{"op":"mcm","clk":"5322762484","pt":1646323897261,"mc":[{"id":"1.195532868","rc":[{"atb":[[6.4,3.67]],"id":42142047}],"con":true,"img":false}]}
{"op":"mcm","clk":"5322762629","pt":1646323898473,"mc":[{"id":"1.195532868","rc":[{"atl":[[1000,14.52]],"id":2441997}],"con":true,"img":false}]}
{"op":"mcm","clk":"5322762662","pt":1646323898686,"mc":[{"id":"1.195532868","rc":[{"atl":[[1000,14.1]],"id":2441997}],"con":true,"img":false}]}
{"op":"mcm","clk":"5322762681","pt":1646323898746,"mc":[{"id":"1.195532868","rc":[{"atb":[[6.4,1.68]],"id":42142047}],"con":true,"img":false}]}
{"op":"mcm","clk":"5322762701","pt":1646323898902,"mc":[{"id":"1.195532868","rc":[{"atl":[[1000,12]],"id":2441997},{"atb":[[5.5,1.99]],"id":42142047}],"con":true,"img":false}]}
{"op":"mcm","clk":"5322762711","pt":1646323898958,"mc":[{"id":"1.195532868","rc":[{"atl":[[9.4,2.1]],"id":2441997}],"con":true,"img":false}]}
{"op":"mcm","clk":"5322762746","pt":1646323899266,"mc":[{"id":"1.195532868","rc":[{"atl":[[9.4,0]],"id":2441997}],"con":true,"img":false}]}
{"op":"mcm","clk":"5322762859","pt":1646323900266,"mc":[{"id":"1.195532868","rc":[{"atb":[[3.4,11.35]],"id":2441997}],"con":true,"img":false}]}
{"op":"mcm","clk":"5322762946","pt":1646323900958,"mc":[{"id":"1.195532868","rc":[{"atb":[[3.35,0]],"id":2441997}],"con":true,"img":false}]}
{"op":"mcm","clk":"5322762956","pt":1646323901062,"mc":[{"id":"1.195532868","rc":[{"atb":[[3.45,1.69]],"id":2441997}],"con":true,"img":false}]}
{"op":"mcm","clk":"5322763266","pt":1646323903797,"mc":[{"id":"1.195532868","rc":[{"atb":[[3.4,0]],"id":2441997}],"con":true,"img":false}]}
{"op":"mcm","clk":"5322763346","pt":1646323904579,"mc":[{"id":"1.195532868","rc":[{"atl":[[1000,14.52]],"id":2441997}],"con":true,"img":false}]}
{"op":"mcm","clk":"5322763368","pt":1646323904791,"mc":[{"id":"1.195532868","rc":[{"atl":[[1000,14.1]],"id":2441997}],"con":true,"img":false}]}
{"op":"mcm","clk":"5322763382","pt":1646323904901,"mc":[{"id":"1.195532868","rc":[{"atl":[[1000,12]],"id":2441997},{"atb":[[5.5,0]],"id":42142047}],"con":true,"img":false}]}
{"op":"mcm","clk":"5322763395","pt":1646323904998,"mc":[{"id":"1.195532868","rc":[{"atb":[[3.45,0]],"id":2441997},{"atl":[[9.4,2.1]],"id":2441997},{"atb":[[6.4,3.67]],"id":42142047}],"con":true,"img":false}]}
{"op":"mcm","clk":"5322763409","pt":1646323905103,"mc":[{"id":"1.195532868","rc":[{"atb":[[3.35,1.69]],"id":2441997}],"con":true,"img":false}]}
{"op":"mcm","clk":"5322763423","pt":1646323905203,"mc":[{"id":"1.195532868","rc":[{"atl":[[9.4,0]],"id":2441997}],"con":true,"img":false}]}
{"op":"mcm","clk":"5322763506","pt":1646323905794,"mc":[{"id":"1.195532868","rc":[{"atb":[[6.4,1.68]],"id":42142047}],"con":true,"img":false}]}
{"op":"mcm","clk":"5322763519","pt":1646323905896,"mc":[{"id":"1.195532868","rc":[{"atb":[[5.5,1.99]],"id":42142047}],"con":true,"img":false}]}
{"op":"mcm","clk":"5322763685","pt":1646323907104,"mc":[{"id":"1.195532868","rc":[{"atb":[[5.5,0]],"id":42142047}],"con":true,"img":false}]}
{"op":"mcm","clk":"5322763698","pt":1646323907205,"mc":[{"id":"1.195532868","rc":[{"atb":[[6.4,3.67]],"id":42142047}],"con":true,"img":false}]}
{"op":"mcm","clk":"5322763720","pt":1646323907409,"mc":[{"id":"1.195532868","rc":[{"atb":[[3.4,11.35]],"id":2441997}],"con":true,"img":false}]}
{"op":"mcm","clk":"5322763841","pt":1646323908411,"mc":[{"id":"1.195532868","rc":[{"atb":[[6.4,1.68]],"id":42142047}],"con":true,"img":false}]}
{"op":"mcm","clk":"5322763848","pt":1646323908517,"mc":[{"id":"1.195532868","rc":[{"atb":[[5.5,1.99]],"id":42142047}],"con":true,"img":false}]}
{"op":"mcm","clk":"5322763979","pt":1646323909617,"mc":[{"id":"1.195532868","rc":[{"atb":[[5.5,0]],"id":42142047}],"con":true,"img":false}]}
{"op":"mcm","clk":"5322763998","pt":1646323909688,"mc":[{"id":"1.195532868","rc":[{"atb":[[6.4,3.67]],"id":42142047}],"con":true,"img":false}]}
{"op":"mcm","clk":"5322764063","pt":1646323910103,"mc":[{"id":"1.195532868","rc":[{"atb":[[15.5,1.37]],"id":40302111},{"trd":[[15.5,0.72]],"ltp":15.5,"tv":0.72,"id":40302111}],"con":true,"img":false}]}
{"op":"mcm","clk":"5322764118","pt":1646323910494,"mc":[{"id":"1.195532868","rc":[{"atl":[[1000,14.52]],"id":2441997}],"con":true,"img":false}]}
{"op":"mcm","clk":"5322764155","pt":1646323910706,"mc":[{"id":"1.195532868","rc":[{"atl":[[1000,14.1]],"id":2441997}],"con":true,"img":false}]}
{"op":"mcm","clk":"5322764186","pt":1646323910900,"mc":[{"id":"1.195532868","rc":[{"spn":15.05,"spf":6.6,"id":40302111},{"atl":[[1000,12]],"id":2441997},{"spn":5.02,"spf":6.6,"id":36909993}],"con":true,"img":false}]}
{"op":"mcm","clk":"5322764209","pt":1646323910998,"mc":[{"id":"1.195532868","rc":[{"atl":[[9.4,2.1]],"id":2441997}],"con":true,"img":false}]}
{"op":"mcm","clk":"5322764238","pt":1646323911215,"mc":[{"id":"1.195532868","rc":[{"atb":[[6.4,1.68]],"id":42142047}],"con":true,"img":false}]}
{"op":"mcm","clk":"5322764249","pt":1646323911316,"mc":[{"id":"1.195532868","rc":[{"atb":[[5.5,1.99]],"id":42142047}],"con":true,"img":false}]}
{"op":"mcm","clk":"5322764282","pt":1646323911521,"mc":[{"id":"1.195532868","rc":[{"atl":[[9.4,0]],"id":2441997}],"con":true,"img":false}]}
{"op":"mcm","clk":"5322764442","pt":1646323912718,"mc":[{"id":"1.195532868","rc":[{"atb":[[5.5,0]],"id":42142047}],"con":true,"img":false}]}
{"op":"mcm","clk":"5322764459","pt":1646323912790,"mc":[{"id":"1.195532868","rc":[{"atb":[[6.4,3.67]],"id":42142047}],"con":true,"img":false}]}
{"op":"mcm","clk":"5322764554","pt":1646323913582,"mc":[{"id":"1.195532868","rc":[{"atb":[[6.4,1.68]],"id":42142047}],"con":true,"img":false}]}
{"op":"mcm","clk":"5322764564","pt":1646323913687,"mc":[{"id":"1.195532868","rc":[{"atb":[[5.5,1.99]],"id":42142047}],"con":true,"img":false}]}
{"op":"mcm","clk":"5322764887","pt":1646323916413,"mc":[{"id":"1.195532868","rc":[{"atl":[[1000,14.52]],"id":2441997}],"con":true,"img":false}]}
{"op":"mcm","clk":"5322764917","pt":1646323916615,"mc":[{"id":"1.195532868","rc":[{"atl":[[1000,14.1]],"id":2441997}],"con":true,"img":false}]}
{"op":"mcm","clk":"5322764936","pt":1646323916821,"mc":[{"id":"1.195532868","rc":[{"atl":[[1000,12]],"id":2441997}],"con":true,"img":false}]}
{"op":"mcm","clk":"5322764949","pt":1646323916924,"mc":[{"id":"1.195532868","rc":[{"atl":[[9.4,2.1]],"id":2441997}],"con":true,"img":false}]}
{"op":"mcm","clk":"5322764973","pt":1646323917090,"mc":[{"id":"1.195532868","rc":[{"atl":[[9.4,0]],"id":2441997}],"con":true,"img":false}]}
{"op":"mcm","clk":"5322765288","pt":1646323919708,"mc":[{"id":"1.195532868","rc":[{"atb":[[5.5,0]],"id":42142047}],"con":true,"img":false}]}
{"op":"mcm","clk":"5322765306","pt":1646323919836,"mc":[{"id":"1.195532868","rc":[{"atb":[[6.4,3.67]],"id":42142047}],"con":true,"img":false}]}
{"op":"mcm","clk":"5322765480","pt":1646323921149,"mc":[{"id":"1.195532868","rc":[{"atb":[[6.4,1.68]],"id":42142047}],"con":true,"img":false}]}
{"op":"mcm","clk":"5322765495","pt":1646323921206,"mc":[{"id":"1.195532868","rc":[{"atb":[[5.5,1.99]],"id":42142047}],"con":true,"img":false}]}
{"op":"mcm","clk":"5322765608","pt":1646323922132,"mc":[{"id":"1.195532868","rc":[{"atl":[[1000,14.52]],"id":2441997}],"con":true,"img":false}]}
{"op":"mcm","clk":"5322765638","pt":1646323922309,"mc":[{"id":"1.195532868","rc":[{"atl":[[1000,14.1]],"id":2441997}],"con":true,"img":false}]}
{"op":"mcm","clk":"5322765660","pt":1646323922554,"mc":[{"id":"1.195532868","rc":[{"atl":[[1000,12]],"id":2441997}],"con":true,"img":false}]}
{"op":"mcm","clk":"5322765689","pt":1646323922719,"mc":[{"id":"1.195532868","rc":[{"atl":[[9.4,2.1]],"id":2441997}],"con":true,"img":false}]}
{"op":"mcm","clk":"5322765726","pt":1646323923029,"mc":[{"id":"1.195532868","rc":[{"atl":[[9.4,0]],"id":2441997}],"con":true,"img":false}]}
{"op":"mcm","clk":"5322765821","pt":1646323923835,"mc":[{"id":"1.195532868","rc":[{"atb":[[5.5,0]],"id":42142047}],"con":true,"img":false}]}
{"op":"mcm","clk":"5322765831","pt":1646323923931,"mc":[{"id":"1.195532868","rc":[{"atb":[[6.4,3.67]],"id":42142047}],"con":true,"img":false}]}
{"op":"mcm","clk":"5322765990","pt":1646323925242,"mc":[{"id":"1.195532868","rc":[{"atb":[[6.4,1.68]],"id":42142047}],"con":true,"img":false}]}
{"op":"mcm","clk":"5322766002","pt":1646323925311,"mc":[{"id":"1.195532868","rc":[{"atb":[[5.5,1.99]],"id":42142047}],"con":true,"img":false}]}
{"op":"mcm","clk":"5322766147","pt":1646323926519,"mc":[{"id":"1.195532868","rc":[{"atb":[[5.5,0]],"id":42142047}],"con":true,"img":false}]}
{"op":"mcm","clk":"5322766160","pt":1646323926616,"mc":[{"id":"1.195532868","rc":[{"atb":[[6.4,3.67]],"id":42142047}],"con":true,"img":false}]}
{"op":"mcm","clk":"5322766237","pt":1646323927227,"mc":[{"id":"1.195532868","rc":[{"atl":[[1000,14.52]],"id":2441997},{"atb":[[6.4,1.68]],"id":42142047}],"con":true,"img":false}]}
{"op":"mcm","clk":"5322766249","pt":1646323927328,"mc":[{"id":"1.195532868","rc":[{"atb":[[5.5,1.99]],"id":42142047}],"con":true,"img":false}]}
{"op":"mcm","clk":"5322766263","pt":1646323927438,"mc":[{"id":"1.195532868","rc":[{"atl":[[1000,14.1]],"id":2441997}],"con":true,"img":false}]}
{"op":"mcm","clk":"5322766288","pt":1646323927633,"mc":[{"id":"1.195532868","rc":[{"atl":[[1000,12]],"id":2441997}],"con":true,"img":false}]}
{"op":"mcm","clk":"5322766302","pt":1646323927745,"mc":[{"id":"1.195532868","rc":[{"atl":[[9.4,2.1]],"id":2441997},{"atb":[[5.5,0]],"id":42142047}],"con":true,"img":false}]}
{"op":"mcm","clk":"5322766315","pt":1646323927805,"mc":[{"id":"1.195532868","rc":[{"atb":[[6.4,3.67]],"id":42142047}],"con":true,"img":false}]}
{"op":"mcm","clk":"5322766340","pt":1646323928025,"mc":[{"id":"1.195532868","rc":[{"atl":[[9.4,0]],"id":2441997}],"con":true,"img":false}]}
{"op":"mcm","clk":"5322766471","pt":1646323929230,"mc":[{"id":"1.195532868","rc":[{"atb":[[6.4,1.68]],"id":42142047}],"con":true,"img":false}]}
{"op":"mcm","clk":"5322766490","pt":1646323929333,"mc":[{"id":"1.195532868","rc":[{"atb":[[5.5,1.99]],"id":42142047}],"con":true,"img":false}]}
{"op":"mcm","clk":"5322766789","pt":1646323931743,"mc":[{"id":"1.195532868","rc":[{"atb":[[5.5,0]],"id":42142047}],"con":true,"img":false}]}
{"op":"mcm","clk":"5322766797","pt":1646323931845,"mc":[{"id":"1.195532868","rc":[{"atb":[[6.4,3.67]],"id":42142047}],"con":true,"img":false}]}
{"op":"mcm","clk":"5322766910","pt":1646323932839,"mc":[{"id":"1.195532868","rc":[{"atl":[[1000,14.52]],"id":2441997}],"con":true,"img":false}]}
{"op":"mcm","clk":"5322766920","pt":1646323932937,"mc":[{"id":"1.195532868","rc":[{"atb":[[6.4,1.68]],"id":42142047}],"con":true,"img":false}]}
{"op":"mcm","clk":"5322766932","pt":1646323933041,"mc":[{"id":"1.195532868","rc":[{"atl":[[1000,14.1]],"id":2441997},{"atb":[[5.5,1.99]],"id":42142047}],"con":true,"img":false}]}
{"op":"mcm","clk":"5322766956","pt":1646323933212,"mc":[{"id":"1.195532868","rc":[{"atl":[[1000,12]],"id":2441997}],"con":true,"img":false}]}
{"op":"mcm","clk":"5322766969","pt":1646323933321,"mc":[{"id":"1.195532868","rc":[{"atl":[[9.4,2.1]],"id":2441997}],"con":true,"img":false}]}
{"op":"mcm","clk":"5322767016","pt":1646323933739,"mc":[{"id":"1.195532868","rc":[{"atl":[[9.4,0]],"id":2441997}],"con":true,"img":false}]}
{"op":"mcm","clk":"5322767182","pt":1646323935238,"mc":[{"id":"1.195532868","rc":[{"atb":[[5.5,0]],"id":42142047}],"con":true,"img":false}]}
{"op":"mcm","clk":"5322767191","pt":1646323935345,"mc":[{"id":"1.195532868","rc":[{"atb":[[6.4,3.67]],"id":42142047}],"con":true,"img":false}]}
{"op":"mcm","clk":"5322767284","pt":1646323936244,"mc":[{"id":"1.195532868","rc":[{"atb":[[6.4,1.68]],"id":42142047}],"con":true,"img":false}]}
{"op":"mcm","clk":"5322767293","pt":1646323936349,"mc":[{"id":"1.195532868","rc":[{"atb":[[5.5,1.99]],"id":42142047}],"con":true,"img":false}]}
{"op":"mcm","clk":"5322767334","pt":1646323936752,"mc":[{"id":"1.195532868","rc":[{"atb":[[5.5,0]],"id":42142047}],"con":true,"img":false}]}
{"op":"mcm","clk":"5322767347","pt":1646323936822,"mc":[{"id":"1.195532868","rc":[{"atb":[[6.4,3.67]],"id":42142047}],"con":true,"img":false}]}
{"op":"mcm","clk":"5322767429","pt":1646323937642,"mc":[{"id":"1.195532868","rc":[{"atb":[[6.4,1.68]],"id":42142047}],"con":true,"img":false}]}
{"op":"mcm","clk":"5322767438","pt":1646323937746,"mc":[{"id":"1.195532868","rc":[{"atb":[[5.5,1.99]],"id":42142047}],"con":true,"img":false}]}
{"op":"mcm","clk":"5322767493","pt":1646323938229,"mc":[{"id":"1.195532868","rc":[{"atl":[[1000,14.52]],"id":2441997}],"con":true,"img":false}]}
{"op":"mcm","clk":"5322767509","pt":1646323938437,"mc":[{"id":"1.195532868","rc":[{"atl":[[1000,14.1]],"id":2441997}],"con":true,"img":false}]}
{"op":"mcm","clk":"5322767533","pt":1646323938653,"mc":[{"id":"1.195532868","rc":[{"atl":[[1000,12]],"id":2441997}],"con":true,"img":false}]}
{"op":"mcm","clk":"5322767545","pt":1646323938748,"mc":[{"id":"1.195532868","rc":[{"atl":[[9.4,2.1]],"id":2441997}],"con":true,"img":false}]}
{"op":"mcm","clk":"5322767607","pt":1646323939258,"mc":[{"id":"1.195532868","rc":[{"atl":[[9.4,0]],"id":2441997},{"atb":[[5.5,0]],"id":42142047}],"con":true,"img":false}]}
{"op":"mcm","clk":"5322767619","pt":1646323939323,"mc":[{"id":"1.195532868","rc":[{"atb":[[6.4,3.67]],"id":42142047}],"con":true,"img":false}]}
{"op":"mcm","clk":"5322767750","pt":1646323940444,"mc":[{"id":"1.195532868","rc":[{"atb":[[6.4,1.68]],"id":42142047}],"con":true,"img":false}]}
{"op":"mcm","clk":"5322767764","pt":1646323940547,"mc":[{"id":"1.195532868","rc":[{"atb":[[5.5,1.99]],"id":42142047}],"con":true,"img":false}]}
{"op":"mcm","clk":"5322767827","pt":1646323941032,"mc":[{"id":"1.195532868","rc":[{"atb":[[5.5,0]],"id":42142047}],"con":true,"img":false}]}
{"op":"mcm","clk":"5322767839","pt":1646323941134,"mc":[{"id":"1.195532868","rc":[{"atb":[[6.4,3.67]],"id":42142047}],"con":true,"img":false}]}
{"op":"mcm","clk":"5322767967","pt":1646323942334,"mc":[{"id":"1.195532868","rc":[{"atb":[[6.4,1.68]],"id":42142047}],"con":true,"img":false}]}
{"op":"mcm","clk":"5322767979","pt":1646323942442,"mc":[{"id":"1.195532868","rc":[{"atb":[[5.5,1.99]],"id":42142047}],"con":true,"img":false}]}
{"op":"mcm","clk":"5322768109","pt":1646323943432,"mc":[{"id":"1.195532868","rc":[{"atl":[[1000,14.52]],"id":2441997}],"con":true,"img":false}]}
{"op":"mcm","clk":"5322768137","pt":1646323943748,"mc":[{"id":"1.195532868","rc":[{"atl":[[1000,14.1]],"id":2441997},{"atb":[[5.5,0]],"id":42142047}],"con":true,"img":false}]}
{"op":"mcm","clk":"5322768150","pt":1646323943857,"mc":[{"id":"1.195532868","rc":[{"atl":[[1000,12]],"id":2441997},{"atb":[[6.4,3.67]],"id":42142047}],"con":true,"img":false}]}
{"op":"mcm","clk":"5322768160","pt":1646323943961,"mc":[{"id":"1.195532868","rc":[{"atl":[[9.4,2.1]],"id":2441997}],"con":true,"img":false}]}
{"op":"mcm","clk":"5322768205","pt":1646323944330,"mc":[{"id":"1.195532868","rc":[{"atl":[[9.4,0]],"id":2441997}],"con":true,"img":false}]}
{"op":"mcm","clk":"5322768253","pt":1646323944729,"mc":[{"id":"1.195532868","rc":[{"atb":[[6.4,1.68]],"id":42142047}],"con":true,"img":false}]}
{"op":"mcm","clk":"5322768262","pt":1646323944830,"mc":[{"id":"1.195532868","rc":[{"atb":[[5.5,1.99]],"id":42142047}],"con":true,"img":false}]}
{"op":"mcm","clk":"5322768377","pt":1646323945958,"mc":[{"id":"1.195532868","rc":[{"atb":[[5.5,0]],"id":42142047}],"con":true,"img":false}]}
{"op":"mcm","clk":"5322768393","pt":1646323946025,"mc":[{"id":"1.195532868","rc":[{"atb":[[6.4,3.67]],"id":42142047}],"con":true,"img":false}]}
{"op":"mcm","clk":"5322768469","pt":1646323946658,"mc":[{"id":"1.195532868","rc":[{"atb":[[6.4,1.68]],"id":42142047}],"con":true,"img":false}]}
{"op":"mcm","clk":"5322768481","pt":1646323946763,"mc":[{"id":"1.195532868","rc":[{"atb":[[5.5,1.99]],"id":42142047}],"con":true,"img":false}]}
{"op":"mcm","clk":"5322768547","pt":1646323947271,"mc":[{"id":"1.195532868","rc":[{"atb":[[5.5,0]],"id":42142047}],"con":true,"img":false}]}
{"op":"mcm","clk":"5322768558","pt":1646323947339,"mc":[{"id":"1.195532868","rc":[{"atb":[[6.4,3.67]],"id":42142047}],"con":true,"img":false}]}
{"op":"mcm","clk":"5322768700","pt":1646323948643,"mc":[{"id":"1.195532868","rc":[{"atl":[[1000,14.52]],"id":2441997},{"atb":[[6.4,1.68]],"id":42142047}],"con":true,"img":false}]}
{"op":"mcm","clk":"5322768709","pt":1646323948749,"mc":[{"id":"1.195532868","rc":[{"atb":[[5.5,1.99]],"id":42142047}],"con":true,"img":false}]}
{"op":"mcm","clk":"5322768721","pt":1646323948849,"mc":[{"id":"1.195532868","rc":[{"atl":[[1000,14.1]],"id":2441997}],"con":true,"img":false}]}
{"op":"mcm","clk":"5322768748","pt":1646323949195,"mc":[{"id":"1.195532868","rc":[{"atl":[[1000,12]],"id":2441997}],"con":true,"img":false}]}
{"op":"mcm","clk":"5322768756","pt":1646323949258,"mc":[{"id":"1.195532868","rc":[{"atl":[[9.4,2.1]],"id":2441997},{"atb":[[5.5,0]],"id":42142047}],"con":true,"img":false}]}
{"op":"mcm","clk":"5322768765","pt":1646323949361,"mc":[{"id":"1.195532868","rc":[{"atb":[[6.4,3.67]],"id":42142047}],"con":true,"img":false}]}
{"op":"mcm","clk":"5322768774","pt":1646323949464,"mc":[{"id":"1.195532868","rc":[{"atl":[[9.4,0]],"id":2441997}],"con":true,"img":false}]}
{"op":"mcm","clk":"5322768841","pt":1646323950159,"mc":[{"id":"1.195532868","rc":[{"atb":[[6.4,1.68]],"id":42142047}],"con":true,"img":false}]}
{"op":"mcm","clk":"5322768854","pt":1646323950271,"mc":[{"id":"1.195532868","rc":[{"atb":[[5.5,1.99]],"id":42142047}],"con":true,"img":false}]}
{"op":"mcm","clk":"5322768972","pt":1646323951264,"mc":[{"id":"1.195532868","rc":[{"atb":[[5.5,0]],"id":42142047}],"con":true,"img":false}]}
{"op":"mcm","clk":"5322768983","pt":1646323951369,"mc":[{"id":"1.195532868","rc":[{"atb":[[6.4,3.67]],"id":42142047}],"con":true,"img":false}]}
{"op":"mcm","clk":"5322769100","pt":1646323952375,"mc":[{"id":"1.195532868","rc":[{"atb":[[6.4,1.68]],"id":42142047}],"con":true,"img":false}]}
{"op":"mcm","clk":"5322769129","pt":1646323952551,"mc":[{"id":"1.195532868","rc":[{"atb":[[5.5,1.99]],"id":42142047}],"con":true,"img":false}]}
{"op":"mcm","clk":"5322769268","pt":1646323953742,"mc":[{"id":"1.195532868","rc":[{"atb":[[5.5,0]],"id":42142047}],"con":true,"img":false}]}
{"op":"mcm","clk":"5322769282","pt":1646323953857,"mc":[{"id":"1.195532868","rc":[{"atb":[[6.4,3.67]],"id":42142047}],"con":true,"img":false}]}
{"op":"mcm","clk":"5322769311","pt":1646323954062,"mc":[{"id":"1.195532868","rc":[{"atl":[[1000,14.52]],"id":2441997}],"con":true,"img":false}]}
{"op":"mcm","clk":"5322769336","pt":1646323954268,"mc":[{"id":"1.195532868","rc":[{"atl":[[1000,14.1]],"id":2441997}],"con":true,"img":false}]}
{"op":"mcm","clk":"5322769359","pt":1646323954471,"mc":[{"id":"1.195532868","rc":[{"atl":[[1000,12]],"id":2441997}],"con":true,"img":false}]}
{"op":"mcm","clk":"5322769370","pt":1646323954578,"mc":[{"id":"1.195532868","rc":[{"atl":[[9.4,2.1]],"id":2441997}],"con":true,"img":false}]}
{"op":"mcm","clk":"5322769439","pt":1646323955168,"mc":[{"id":"1.195532868","rc":[{"atl":[[9.4,0]],"id":2441997}],"con":true,"img":false}]}
{"op":"mcm","clk":"5322769621","pt":1646323956876,"mc":[{"id":"1.195532868","rc":[{"atb":[[3.4,0]],"id":2441997}],"con":true,"img":false}]}
{"op":"mcm","clk":"5322769890","pt":1646323959452,"mc":[{"id":"1.195532868","rc":[{"atl":[[1000,14.52]],"id":2441997}],"con":true,"img":false}]}
{"op":"mcm","clk":"5322769902","pt":1646323959555,"mc":[{"id":"1.195532868","rc":[{"atl":[[1000,14.1]],"id":2441997}],"con":true,"img":false}]}
{"op":"mcm","clk":"5322769929","pt":1646323959767,"mc":[{"id":"1.195532868","rc":[{"atl":[[1000,12]],"id":2441997}],"con":true,"img":false}]}
{"op":"mcm","clk":"5322769941","pt":1646323959872,"mc":[{"id":"1.195532868","rc":[{"atl":[[9.4,2.1]],"id":2441997}],"con":true,"img":false}]}
{"op":"mcm","clk":"5322769972","pt":1646323960177,"mc":[{"id":"1.195532868","rc":[{"atl":[[9.4,0]],"id":2441997}],"con":true,"img":false}]}
{"op":"mcm","clk":"5322770012","pt":1646323960484,"mc":[{"id":"1.195532868","rc":[{"atb":[[3.4,11.35]],"id":2441997}],"con":true,"img":false}]}
{"op":"mcm","clk":"5322770599","pt":1646323965286,"mc":[{"id":"1.195532868","rc":[{"atb":[[6.4,1.68]],"id":42142047}],"con":true,"img":false}]}
{"op":"mcm","clk":"5322770612","pt":1646323965340,"mc":[{"id":"1.195532868","rc":[{"atb":[[5.5,1.99]],"id":42142047}],"con":true,"img":false}]}
{"op":"mcm","clk":"5322770627","pt":1646323965445,"mc":[{"id":"1.195532868","rc":[{"atl":[[1000,14.52]],"id":2441997}],"con":true,"img":false}]}
{"op":"mcm","clk":"5322770647","pt":1646323965655,"mc":[{"id":"1.195532868","rc":[{"atl":[[1000,14.1]],"id":2441997}],"con":true,"img":false}]}
{"op":"mcm","clk":"5322770670","pt":1646323965863,"mc":[{"id":"1.195532868","rc":[{"atl":[[1000,12]],"id":2441997}],"con":true,"img":false}]}
{"op":"mcm","clk":"5322770685","pt":1646323965967,"mc":[{"id":"1.195532868","rc":[{"atl":[[9.4,2.1]],"id":2441997}],"con":true,"img":false}]}
{"op":"mcm","clk":"5322770750","pt":1646323966441,"mc":[{"id":"1.195532868","rc":[{"atl":[[9.4,0]],"id":2441997}],"con":true,"img":false}]}
{"op":"mcm","clk":"5322770776","pt":1646323966651,"mc":[{"id":"1.195532868","rc":[{"atb":[[5.5,0]],"id":42142047}],"con":true,"img":false}]}
{"op":"mcm","clk":"5322770790","pt":1646323966765,"mc":[{"id":"1.195532868","rc":[{"atb":[[6.4,3.67]],"id":42142047}],"con":true,"img":false}]}
{"op":"mcm","clk":"5322770941","pt":1646323968077,"mc":[{"id":"1.195532868","rc":[{"atb":[[6.4,1.68]],"id":42142047}],"con":true,"img":false}]}
{"op":"mcm","clk":"5322770952","pt":1646323968180,"mc":[{"id":"1.195532868","rc":[{"atb":[[5.5,1.99]],"id":42142047}],"con":true,"img":false}]}
{"op":"mcm","clk":"5322771108","pt":1646323969492,"mc":[{"id":"1.195532868","rc":[{"atb":[[9.6,1.76]],"id":2441997},{"atl":[[9.6,0]],"id":2441997},{"trd":[[9.6,3.31]],"ltp":9.6,"tv":3.31,"id":2441997}],"con":true,"img":false}]}
{"op":"mcm","clk":"5322771120","pt":1646323969544,"mc":[{"id":"1.195532868","rc":[{"atb":[[9.6,0],[6.2,0]],"id":2441997},{"trd":[[6.2,5.94],[9.6,6.83]],"ltp":6.2,"tv":12.77,"id":2441997}],"con":true,"img":false}]}
{"op":"mcm","clk":"5322771131","pt":1646323969649,"mc":[{"id":"1.195532868","rc":[{"atb":[[5.5,0]],"id":42142047}],"con":true,"img":false}]}
{"op":"mcm","clk":"5322771144","pt":1646323969755,"mc":[{"id":"1.195532868","rc":[{"atl":[[11,9.84]],"id":2441997},{"atb":[[6.4,3.67]],"id":42142047}],"con":true,"img":false}]}
{"op":"mcm","clk":"5322771160","pt":1646323969873,"mc":[{"id":"1.195532868","rc":[{"atl":[[8,1.44]],"id":2441997}],"con":true,"img":false}]}
{"op":"mcm","clk":"5322771302","pt":1646323971077,"mc":[{"id":"1.195532868","rc":[{"spn":5.97,"spf":1.0,"id":2441997},{"atb":[[2.36,8.26]],"id":36909993},{"atb":[[6.4,1.68],[2.76,6.38]],"id":42142047}],"con":true,"img":false}]}
{"op":"mcm","clk":"5322771314","pt":1646323971180,"mc":[{"id":"1.195532868","rc":[{"atb":[[5.5,1.99]],"id":42142047}],"con":true,"img":false}]}
{"op":"mcm","clk":"5322771325","pt":1646323971286,"mc":[{"id":"1.195532868","rc":[{"atb":[[2.46,7.69]],"id":2441997},{"atb":[[3.35,4.78]],"id":42609835}],"con":true,"img":false}]}
{"op":"mcm","clk":"5322771338","pt":1646323971390,"mc":[{"id":"1.195532868","rc":[{"atb":[[3.55,63.22]],"id":40133336}],"con":true,"img":false}]}
{"op":"mcm","clk":"5322771456","pt":1646323972494,"mc":[{"id":"1.195532868","rc":[{"atb":[[5.5,0]],"id":42142047}],"con":true,"img":false}]}
{"op":"mcm","clk":"5322771473","pt":1646323972544,"mc":[{"id":"1.195532868","rc":[{"atb":[[6.4,3.67]],"id":42142047}],"con":true,"img":false}]}
{"op":"mcm","clk":"5322771498","pt":1646323972757,"mc":[{"id":"1.195532868","rc":[{"atb":[[3.4,0]],"id":2441997},{"atb":[[2.9,3.07]],"id":36909993}],"con":true,"img":false}]}
{"op":"mcm","clk":"5322771592","pt":1646323973601,"mc":[{"id":"1.195532868","rc":[{"atb":[[6.4,1.68]],"id":42142047}],"con":true,"img":false}]}
{"op":"mcm","clk":"5322771600","pt":1646323973698,"mc":[{"id":"1.195532868","rc":[{"atb":[[5.5,1.99]],"id":42142047}],"con":true,"img":false}]}
{"op":"mcm","clk":"5322771708","pt":1646323974593,"mc":[{"id":"1.195532868","rc":[{"atl":[[4.9,2.52]],"id":36909993}],"con":true,"img":false}]}
{"op":"mcm","clk":"5322771728","pt":1646323974750,"mc":[{"id":"1.195532868","rc":[{"atl":[[5.3,4.78]],"id":36909993}],"con":true,"img":false}]}
{"op":"mcm","clk":"5322771750","pt":1646323974958,"mc":[{"id":"1.195532868","rc":[{"atl":[[5.3,0]],"id":36909993}],"con":true,"img":false}]}
{"op":"mcm","clk":"5322771824","pt":1646323975699,"mc":[{"id":"1.195532868","rc":[{"atb":[[2.88,0]],"id":36909993},{"atb":[[5.5,0]],"id":42142047}],"con":true,"img":false}]}
{"op":"mcm","clk":"5322771833","pt":1646323975795,"mc":[{"id":"1.195532868","rc":[{"atb":[[2.92,1.74]],"id":36909993},{"atb":[[6.4,3.67]],"id":42142047}],"con":true,"img":false}]}
{"op":"mcm","clk":"5322771953","pt":1646323976786,"mc":[{"id":"1.195532868","rc":[{"atb":[[3.35,16.64]],"id":2441997}],"con":true,"img":false}]}
{"op":"mcm","clk":"5322772127","pt":1646323978261,"mc":[{"id":"1.195532868","rc":[{"atb":[[2.8,6.9]],"id":42142047}],"con":true,"img":false}]}
{"op":"mcm","clk":"5322772141","pt":1646323978366,"mc":[{"id":"1.195532868","rc":[{"atb":[[2.5,8.29]],"id":2441997}],"con":true,"img":false}]}
{"op":"mcm","clk":"5322772165","pt":1646323978583,"mc":[{"id":"1.195532868","rc":[{"atb":[[2.4,8.88],[2.9,0]],"id":36909993}],"con":true,"img":false}]}
{"op":"mcm","clk":"5322772188","pt":1646323978784,"mc":[{"id":"1.195532868","rc":[{"atb":[[3.55,68.1]],"id":40133336}],"con":true,"img":false}]}
{"op":"mcm","clk":"5322772307","pt":1646323979788,"mc":[{"id":"1.195532868","rc":[{"atb":[[2.92,0]],"id":36909993}],"con":true,"img":false}]}
{"op":"mcm","clk":"5322772318","pt":1646323979886,"mc":[{"id":"1.195532868","rc":[{"atb":[[2.88,1.74]],"id":36909993}],"con":true,"img":false}]}
{"op":"mcm","clk":"5322772432","pt":1646323980882,"mc":[{"id":"1.195532868","rc":[{"atb":[[2.54,43.02]],"id":36909993},{"atl":[[4.9,4.52]],"id":36909993}],"con":true,"img":false}]}
{"op":"mcm","clk":"5322772489","pt":1646323981301,"mc":[{"id":"1.195532868","rc":[{"atl":[[5.1,0]],"id":36909993}],"con":true,"img":false}]}
{"op":"mcm","clk":"5322772503","pt":1646323981406,"mc":[{"id":"1.195532868","rc":[{"atl":[[4.8,0.44]],"id":36909993}],"con":true,"img":false}]}
{"op":"mcm","clk":"5322772525","pt":1646323981566,"mc":[{"id":"1.195532868","rc":[{"atb":[[1.94,106.38]],"id":40302111},{"atl":[[36,7.15]],"id":40302111},{"atb":[[3.1,119.05]],"id":2441997},{"atl":[[10,8.76]],"id":2441997},{"atb":[[4.1,13.43]],"id":42142047},{"atl":[[14.5,14.82]],"id":42142047},{"atb":[[4,33.33]],"id":42609835},{"atl":[[11.5,20]],"id":42609835},{"atb":[[3.85,14.55]],"id":40133336},{"atl":[[9,12.5]],"id":40133336}],"con":true,"img":false}]}
{"op":"mcm","clk":"5322772540","pt":1646323981672,"mc":[{"id":"1.195532868","rc":[{"atb":[[6.4,1.68]],"id":42142047}],"con":true,"img":false}]}
{"op":"mcm","clk":"5322772549","pt":1646323981774,"mc":[{"id":"1.195532868","rc":[{"atb":[[5.5,1.99]],"id":42142047}],"con":true,"img":false}]}
{"op":"mcm","clk":"5322772580","pt":1646323982089,"mc":[{"id":"1.195532868","rc":[{"atl":[[32,4.05]],"id":40302111}],"con":true,"img":false}]}
{"op":"mcm","clk":"5322772674","pt":1646323982874,"mc":[{"id":"1.195532868","rc":[{"atl":[[32,3.69]],"id":40302111}],"con":true,"img":false}]}
{"op":"mcm","clk":"5322772687","pt":1646323982978,"mc":[{"id":"1.195532868","rc":[{"atb":[[3.8,0]],"id":40133336}],"con":true,"img":false}]}
{"op":"mcm","clk":"5322772701","pt":1646323983087,"mc":[{"id":"1.195532868","rc":[{"atb":[[3.9,1.6]],"id":40133336}],"con":true,"img":false}]}
{"op":"mcm","clk":"5322772745","pt":1646323983515,"mc":[{"id":"1.195532868","rc":[{"atb":[[5.5,0]],"id":42142047}],"con":true,"img":false}]}
{"op":"mcm","clk":"5322772756","pt":1646323983560,"mc":[{"id":"1.195532868","rc":[{"atb":[[6.4,3.67]],"id":42142047}],"con":true,"img":false}]}
{"op":"mcm","clk":"5322772885","pt":1646323984710,"mc":[{"id":"1.195532868","rc":[{"atb":[[6.4,1.68]],"id":42142047}],"con":true,"img":false}]}
{"op":"mcm","clk":"5322772897","pt":1646323984765,"mc":[{"id":"1.195532868","rc":[{"atb":[[5.5,1.99]],"id":42142047}],"con":true,"img":false}]}
{"op":"mcm","clk":"5322773063","pt":1646323986293,"mc":[{"id":"1.195532868","rc":[{"atb":[[5.5,0]],"id":42142047}],"con":true,"img":false}]}
{"op":"mcm","clk":"5322773078","pt":1646323986398,"mc":[{"id":"1.195532868","rc":[{"atb":[[6.4,3.67]],"id":42142047}],"con":true,"img":false}]}
{"op":"mcm","clk":"5322773238","pt":1646323987723,"mc":[{"id":"1.195532868","rc":[{"atb":[[6.4,1.68]],"id":42142047}],"con":true,"img":false}]}
{"op":"mcm","clk":"5322773245","pt":1646323987772,"mc":[{"id":"1.195532868","rc":[{"atb":[[5.5,1.99]],"id":42142047}],"con":true,"img":false}]}
{"op":"mcm","clk":"5322773396","pt":1646323989086,"mc":[{"id":"1.195532868","rc":[{"atb":[[5.5,0]],"id":42142047}],"con":true,"img":false}]}
{"op":"mcm","clk":"5322773408","pt":1646323989186,"mc":[{"id":"1.195532868","rc":[{"atb":[[6.4,3.67]],"id":42142047}],"con":true,"img":false}]}
{"op":"mcm","clk":"5322773553","pt":1646323990707,"mc":[{"id":"1.195532868","rc":[{"atb":[[6.4,1.68]],"id":42142047}],"con":true,"img":false}]}
{"op":"mcm","clk":"5322773563","pt":1646323990811,"mc":[{"id":"1.195532868","rc":[{"atb":[[5.5,1.99]],"id":42142047}],"con":true,"img":false}]}
{"op":"mcm","clk":"5322774232","pt":1646323997302,"mc":[{"id":"1.195532868","rc":[{"atb":[[5.5,0]],"id":42142047}],"con":true,"img":false}]}
{"op":"mcm","clk":"5322774240","pt":1646323997408,"mc":[{"id":"1.195532868","rc":[{"atb":[[6.4,3.67]],"id":42142047}],"con":true,"img":false}]}
{"op":"mcm","clk":"5322774294","pt":1646323997884,"mc":[{"id":"1.195532868","rc":[{"atb":[[6.4,1.68]],"id":42142047}],"con":true,"img":false}]}
{"op":"mcm","clk":"5322774305","pt":1646323997985,"mc":[{"id":"1.195532868","rc":[{"atb":[[5.5,1.99]],"id":42142047}],"con":true,"img":false}]}
{"op":"mcm","clk":"5322774395","pt":1646323998777,"mc":[{"id":"1.195532868","rc":[{"atb":[[5.5,0]],"id":42142047}],"con":true,"img":false}]}
{"op":"mcm","clk":"5322774407","pt":1646323998882,"mc":[{"id":"1.195532868","rc":[{"atb":[[6.4,3.67]],"id":42142047}],"con":true,"img":false}]}
{"op":"mcm","clk":"5322774524","pt":1646323999990,"mc":[{"id":"1.195532868","rc":[{"atb":[[6.4,1.68]],"id":42142047}],"con":true,"img":false}]}
{"op":"mcm","clk":"5322774538","pt":1646324000113,"mc":[{"id":"1.195532868","rc":[{"atb":[[5.5,1.99]],"id":42142047}],"con":true,"img":false}]}
{"op":"mcm","clk":"5322774698","pt":1646324001411,"mc":[{"id":"1.195532868","rc":[{"atb":[[5.5,0]],"id":42142047}],"con":true,"img":false}]}
{"op":"mcm","clk":"5322774714","pt":1646324001517,"mc":[{"id":"1.195532868","rc":[{"atb":[[6.4,3.67]],"id":42142047}],"con":true,"img":false}]}
{"op":"mcm","clk":"5322774856","pt":1646324002783,"mc":[{"id":"1.195532868","rc":[{"atb":[[6.4,1.68]],"id":42142047}],"con":true,"img":false}]}
{"op":"mcm","clk":"5322774870","pt":1646324002883,"mc":[{"id":"1.195532868","rc":[{"atb":[[5.5,1.99]],"id":42142047}],"con":true,"img":false}]}
{"op":"mcm","clk":"5322774961","pt":1646324003716,"mc":[{"id":"1.195532868","rc":[{"atb":[[5.5,0]],"id":42142047}],"con":true,"img":false}]}
{"op":"mcm","clk":"5322774973","pt":1646324003821,"mc":[{"id":"1.195532868","rc":[{"atb":[[6.4,3.67]],"id":42142047}],"con":true,"img":false}]}
{"op":"mcm","clk":"5322775568","pt":1646324009497,"mc":[{"id":"1.195532868","rc":[{"atb":[[6.4,1.68]],"id":42142047}],"con":true,"img":false}]}
{"op":"mcm","clk":"5322775582","pt":1646324009602,"mc":[{"id":"1.195532868","rc":[{"atb":[[5.5,1.99]],"id":42142047}],"con":true,"img":false}]}
{"op":"mcm","clk":"5322775798","pt":1646324011695,"mc":[{"id":"1.195532868","rc":[{"atb":[[5.5,0]],"id":42142047}],"con":true,"img":false}]}
{"op":"mcm","clk":"5322775811","pt":1646324011803,"mc":[{"id":"1.195532868","rc":[{"atb":[[6.4,3.67]],"id":42142047}],"con":true,"img":false}]}
{"op":"mcm","clk":"5322775861","pt":1646324012425,"mc":[{"id":"1.195532868","rc":[{"atb":[[6.4,1.68]],"id":42142047}],"con":true,"img":false}]}
{"op":"mcm","clk":"5322775876","pt":1646324012530,"mc":[{"id":"1.195532868","rc":[{"atb":[[5.5,1.99]],"id":42142047}],"con":true,"img":false}]}
{"op":"mcm","clk":"5322775926","pt":1646324012904,"mc":[{"id":"1.195532868","rc":[{"atb":[[5.5,0]],"id":42142047}],"con":true,"img":false}]}
{"op":"mcm","clk":"5322775934","pt":1646324013012,"mc":[{"id":"1.195532868","rc":[{"atb":[[6.4,3.67]],"id":42142047}],"con":true,"img":false}]}
{"op":"mcm","clk":"5322776053","pt":1646324014220,"mc":[{"id":"1.195532868","rc":[{"atb":[[6.4,1.68]],"id":42142047}],"con":true,"img":false}]}
{"op":"mcm","clk":"5322776061","pt":1646324014316,"mc":[{"id":"1.195532868","rc":[{"atb":[[5.5,1.99]],"id":42142047}],"con":true,"img":false}]}
{"op":"mcm","clk":"5322776206","pt":1646324015829,"mc":[{"id":"1.195532868","rc":[{"atb":[[5.5,0]],"id":42142047}],"con":true,"img":false}]}
{"op":"mcm","clk":"5322776218","pt":1646324015935,"mc":[{"id":"1.195532868","rc":[{"atb":[[6.4,3.67]],"id":42142047}],"con":true,"img":false}]}
{"op":"mcm","clk":"5322776314","pt":1646324016721,"mc":[{"id":"1.195532868","rc":[{"atb":[[6.4,1.68]],"id":42142047}],"con":true,"img":false}]}
{"op":"mcm","clk":"5322776325","pt":1646324016823,"mc":[{"id":"1.195532868","rc":[{"atb":[[5.5,1.99]],"id":42142047}],"con":true,"img":false}]}
{"op":"mcm","clk":"5322776447","pt":1646324018029,"mc":[{"id":"1.195532868","rc":[{"atb":[[5.5,0]],"id":42142047}],"con":true,"img":false}]}
{"op":"mcm","clk":"5322776457","pt":1646324018130,"mc":[{"id":"1.195532868","rc":[{"atb":[[6.4,3.67]],"id":42142047}],"con":true,"img":false}]}
{"op":"mcm","clk":"5322776553","pt":1646324019123,"mc":[{"id":"1.195532868","rc":[{"atb":[[6.4,1.68]],"id":42142047}],"con":true,"img":false}]}
{"op":"mcm","clk":"5322776566","pt":1646324019228,"mc":[{"id":"1.195532868","rc":[{"atb":[[5.5,1.99]],"id":42142047}],"con":true,"img":false}]}
{"op":"mcm","clk":"5322776630","pt":1646324019802,"mc":[{"id":"1.195532868","rc":[{"atb":[[5.1,0]],"id":40133336},{"atl":[[5.1,5.17]],"id":40133336},{"trd":[[5.1,3.98]],"ltp":5.1,"tv":3.98,"id":40133336}],"con":true,"img":false}]}
{"op":"mcm","clk":"5322776745","pt":1646324021006,"mc":[{"id":"1.195532868","rc":[{"atb":[[5.5,0]],"id":42142047}],"con":true,"img":false}]}
{"op":"mcm","clk":"5322776757","pt":1646324021107,"mc":[{"id":"1.195532868","rc":[{"atb":[[6.4,3.67]],"id":42142047}],"con":true,"img":false}]}
{"op":"mcm","clk":"5322776775","pt":1646324021319,"mc":[{"id":"1.195532868","rc":[{"atb":[[4.6,51.82]],"id":40302111},{"atl":[[29,5]],"id":40302111},{"atl":[[10,4.38]],"id":2441997},{"atb":[[2.76,43.02]],"id":36909993},{"atb":[[4.1,0],[5.2,11.47]],"id":42142047},{"atl":[[13.5,11.2],[14.5,7.41]],"id":42142047},{"atb":[[4,0]],"id":42609835},{"atl":[[8.4,0]],"id":40133336}],"con":true,"img":false}]}
{"op":"mcm","clk":"5322776787","pt":1646324021420,"mc":[{"id":"1.195532868","rc":[{"atb":[[1.94,0]],"id":40302111},{"atl":[[36,4.29]],"id":40302111},{"atl":[[8.4,5.32]],"id":2441997},{"atb":[[2.54,0]],"id":36909993},{"atl":[[5,12],[5.2,0]],"id":36909993},{"atb":[[4.6,27.78]],"id":42609835},{"atb":[[4.3,0]],"id":40133336},{"atl":[[9,0],[6.8,6.9],[8.6,4.3],[7.6,10.34]],"id":40133336}],"con":true,"img":false}]}
{"op":"mcm","clk":"5322776797","pt":1646324021525,"mc":[{"id":"1.195532868","rc":[{"atb":[[6.4,1.68]],"id":42142047}],"con":true,"img":false}]}
{"op":"mcm","clk":"5322776806","pt":1646324021630,"mc":[{"id":"1.195532868","rc":[{"atb":[[5.5,1.99]],"id":42142047},{"atl":[[8.6,0]],"id":40133336}],"con":true,"img":false}]}
{"op":"mcm","clk":"5322776854","pt":1646324022106,"mc":[{"id":"1.195532868","rc":[{"atb":[[5.5,0]],"id":42142047}],"con":true,"img":false}]}
{"op":"mcm","clk":"5322776865","pt":1646324022211,"mc":[{"id":"1.195532868","rc":[{"atb":[[6.4,3.67]],"id":42142047}],"con":true,"img":false}]}
{"op":"mcm","clk":"5322776909","pt":1646324022624,"mc":[{"id":"1.195532868","rc":[{"atb":[[6.4,1.68]],"id":42142047}],"con":true,"img":false}]}
{"op":"mcm","clk":"5322776929","pt":1646324022739,"mc":[{"id":"1.195532868","rc":[{"atb":[[5.5,1.99]],"id":42142047}],"con":true,"img":false}]}
{"op":"mcm","clk":"5322777019","pt":1646324023521,"mc":[{"id":"1.195532868","rc":[{"atl":[[5.1,0]],"id":40133336}],"con":true,"img":false}]}
{"op":"mcm","clk":"5322777027","pt":1646324023627,"mc":[{"id":"1.195532868","rc":[{"atb":[[5,0]],"id":40133336},{"atl":[[5,3.17]],"id":40133336},{"trd":[[5,4]],"ltp":5.0,"tv":4.0,"id":40133336}],"con":true,"img":false}]}
{"op":"mcm","clk":"5322777056","pt":1646324023840,"mc":[{"id":"1.195532868","rc":[{"atb":[[3.6,2]],"id":40133336}],"con":true,"img":false}]}
{"op":"mcm","clk":"5322777089","pt":1646324024107,"mc":[{"id":"1.195532868","rc":[{"atb":[[3.9,0]],"id":40133336}],"con":true,"img":false}]}
{"op":"mcm","clk":"5322777106","pt":1646324024218,"mc":[{"id":"1.195532868","rc":[{"atb":[[3.85,0],[1.01,11003.6]],"id":40133336}],"con":true,"img":false}]}
{"op":"mcm","clk":"5322777121","pt":1646324024321,"mc":[{"id":"1.195532868","rc":[{"atb":[[3.75,29.37]],"id":40133336}],"con":true,"img":false}]}
{"op":"mcm","clk":"5322777186","pt":1646324024904,"mc":[{"id":"1.195532868","rc":[{"atb":[[3.8,2.52]],"id":40133336}],"con":true,"img":false}]}
{"op":"mcm","clk":"5322777196","pt":1646324025041,"mc":[{"id":"1.195532868","rc":[{"atb":[[3.8,5.38]],"id":40133336}],"con":true,"img":false}]}
{"op":"mcm","clk":"5322777206","pt":1646324025112,"mc":[{"id":"1.195532868","rc":[{"atb":[[1.01,11002]],"id":40133336}],"con":true,"img":false}]}
{"op":"mcm","clk":"5322777215","pt":1646324025218,"mc":[{"id":"1.195532868","rc":[{"atb":[[3.85,29.37],[3.8,6.98],[3.75,14.55]],"id":40133336}],"con":true,"img":false}]}
{"op":"mcm","clk":"5322777243","pt":1646324025531,"mc":[{"id":"1.195532868","rc":[{"atb":[[4,2.48]],"id":2441997},{"atb":[[6.6,2.48]],"id":42142047},{"atb":[[4.5,2]],"id":40133336}],"con":true,"img":false}]}
{"op":"mcm","clk":"5322777270","pt":1646324025748,"mc":[{"id":"1.195532868","rc":[{"atb":[[3.15,0]],"id":42609835}],"con":true,"img":false}]}
{"op":"mcm","clk":"5322777315","pt":1646324026119,"mc":[{"id":"1.195532868","rc":[{"atb":[[5.5,0]],"id":42142047}],"con":true,"img":false}]}
{"op":"mcm","clk":"5322777329","pt":1646324026220,"mc":[{"id":"1.195532868","rc":[{"atb":[[6.8,1.99]],"id":42142047}],"con":true,"img":false}]}
{"op":"mcm","clk":"5322777354","pt":1646324026533,"mc":[{"id":"1.195532868","rc":[{"atb":[[3.95,0]],"id":2441997},{"atb":[[6.4,0]],"id":42142047}],"con":true,"img":false}]}
{"op":"mcm","clk":"5322777368","pt":1646324026637,"mc":[{"id":"1.195532868","rc":[{"atb":[[4.1,1.99]],"id":2441997}],"con":true,"img":false}]}
{"op":"mcm","clk":"5322777388","pt":1646324026842,"mc":[{"id":"1.195532868","rc":[{"atl":[[1000,14.52]],"id":42142047}],"con":true,"img":false}]}
{"op":"mcm","clk":"5322777408","pt":1646324027011,"mc":[{"id":"1.195532868","rc":[{"atl":[[1000,13.68]],"id":42142047}],"con":true,"img":false}]}
{"op":"mcm","clk":"5322777440","pt":1646324027319,"mc":[{"id":"1.195532868","rc":[{"atl":[[1000,12]],"id":42142047}],"con":true,"img":false}]}
{"op":"mcm","clk":"5322777452","pt":1646324027423,"mc":[{"id":"1.195532868","rc":[{"atl":[[12.5,2.56]],"id":42142047}],"con":true,"img":false}]}
{"op":"mcm","clk":"5322777463","pt":1646324027530,"mc":[{"id":"1.195532868","rc":[{"atl":[[12.5,5.12]],"id":42142047}],"con":true,"img":false}]}
{"op":"mcm","clk":"5322777473","pt":1646324027635,"mc":[{"id":"1.195532868","rc":[{"atl":[[13.5,3.2]],"id":42142047}],"con":true,"img":false}]}
{"op":"mcm","clk":"5322777498","pt":1646324027996,"mc":[{"id":"1.195532868","rc":[{"atb":[[4,0]],"id":2441997},{"atb":[[6.6,0]],"id":42142047}],"con":true,"img":false}]}
{"op":"mcm","clk":"5322777511","pt":1646324028209,"mc":[{"id":"1.195532868","rc":[{"atl":[[13,0]],"id":42142047}],"con":true,"img":false}]}
{"op":"mcm","clk":"5322777520","pt":1646324028264,"mc":[{"id":"1.195532868","rc":[{"atl":[[12,0.46]],"id":42142047}],"con":true,"img":false}]}
{"op":"mcm","clk":"5322777610","pt":1646324029203,"mc":[{"id":"1.195532868","rc":[{"atb":[[6.8,0]],"id":42142047}],"con":true,"img":false}]}
{"op":"mcm","clk":"5322777621","pt":1646324029308,"mc":[{"id":"1.195532868","rc":[{"atb":[[6.4,1.99]],"id":42142047}],"con":true,"img":false}]}
{"op":"mcm","clk":"5322777642","pt":1646324029514,"mc":[{"id":"1.195532868","rc":[{"atb":[[4.1,0]],"id":2441997}],"con":true,"img":false}]}
{"op":"mcm","clk":"5322777653","pt":1646324029569,"mc":[{"id":"1.195532868","rc":[{"atb":[[3.95,1.99]],"id":2441997}],"con":true,"img":false}]}
{"op":"mcm","clk":"5322777847","pt":1646324031404,"mc":[{"id":"1.195532868","rc":[{"atl":[[8.8,12.62]],"id":2441997},{"atl":[[5.2,23.81]],"id":36909993},{"spn":4.88,"spf":6.6,"id":36909993},{"atl":[[13,3.33]],"id":42142047},{"atl":[[7.2,16.13]],"id":40133336},{"spn":4.75,"spf":1.0,"id":40133336}],"con":true,"img":false}]}
{"op":"mcm","clk":"5322777861","pt":1646324031508,"mc":[{"id":"1.195532868","rc":[{"atl":[[8.8,19.38]],"id":2441997},{"atl":[[13.5,0]],"id":42142047}],"con":true,"img":false}]}
{"op":"mcm","clk":"5322777872","pt":1646324031564,"mc":[{"id":"1.195532868","rc":[{"atl":[[10,0]],"id":2441997},{"atl":[[14,3.21]],"id":42142047}],"con":true,"img":false}]}
{"op":"mcm","clk":"5322777884","pt":1646324031719,"mc":[{"id":"1.195532868","rc":[{"atb":[[5.3,23.26],[4.6,25.56]],"id":40302111},{"atl":[[13,0]],"id":2441997},{"atb":[[2.76,0],[2.86,75.27]],"id":36909993},{"atl":[[5.8,0],[5.9,4.68]],"id":36909993},{"atb":[[5.2,1.71]],"id":42142047},{"atb":[[4.9,51.28],[4.6,0]],"id":42609835},{"atl":[[9.6,0]],"id":40133336}],"con":true,"img":false}]}
{"op":"mcm","clk":"5322777896","pt":1646324031773,"mc":[{"id":"1.195532868","rc":[{"atb":[[5.6,9.76]],"id":42142047}],"con":true,"img":false}]}
{"op":"mcm","clk":"5322777916","pt":1646324031983,"mc":[{"id":"1.195532868","rc":[{"atl":[[5.9,0]],"id":36909993},{"atb":[[3.8,4.46]],"id":40133336}],"con":true,"img":false}]}
{"op":"mcm","clk":"5322777933","pt":1646324032192,"mc":[{"id":"1.195532868","rc":[{"atl":[[9.8,0]],"id":2441997},{"atb":[[5.2,0]],"id":42142047}],"con":true,"img":false}]}
{"op":"mcm","clk":"5322777944","pt":1646324032303,"mc":[{"id":"1.195532868","rc":[{"atl":[[8.2,0.48]],"id":2441997},{"atb":[[5.7,1.71]],"id":42142047}],"con":true,"img":false}]}
{"op":"mcm","clk":"5322777962","pt":1646324032510,"mc":[{"id":"1.195532868","rc":[{"atl":[[5,0]],"id":40133336}],"con":true,"img":false}]}
{"op":"mcm","clk":"5322777980","pt":1646324032621,"mc":[{"id":"1.195532868","rc":[{"atb":[[4.5,0]],"id":40133336},{"atl":[[4.5,1.17]],"id":40133336},{"trd":[[4.5,4]],"ltp":4.5,"tv":4.0,"id":40133336}],"con":true,"img":false}]}
{"op":"mcm","clk":"5322778023","pt":1646324032982,"mc":[{"id":"1.195532868","rc":[{"atl":[[8.2,0]],"id":40133336}],"con":true,"img":false}]}
{"op":"mcm","clk":"5322778039","pt":1646324033090,"mc":[{"id":"1.195532868","rc":[{"atl":[[6.6,0.48]],"id":40133336}],"con":true,"img":false}]}
{"op":"mcm","clk":"5322778087","pt":1646324033615,"mc":[{"id":"1.195532868","rc":[{"atl":[[14,0]],"id":42142047}],"con":true,"img":false}]}
{"op":"mcm","clk":"5322778119","pt":1646324033923,"mc":[{"id":"1.195532868","rc":[{"atb":[[3.9,2.52]],"id":40133336}],"con":true,"img":false}]}
{"op":"mcm","clk":"5322778159","pt":1646324034400,"mc":[{"id":"1.195532868","rc":[{"atb":[[4,2.48]],"id":2441997},{"atb":[[6.6,2.48]],"id":42142047}],"con":true,"img":false}]}
{"op":"mcm","clk":"5322778194","pt":1646324034712,"mc":[{"id":"1.195532868","rc":[{"atb":[[6.4,0]],"id":42142047}],"con":true,"img":false}]}
{"op":"mcm","clk":"5322778204","pt":1646324034817,"mc":[{"id":"1.195532868","rc":[{"atb":[[6.8,1.99]],"id":42142047}],"con":true,"img":false}]}
{"op":"mcm","clk":"5322778232","pt":1646324034985,"mc":[{"id":"1.195532868","rc":[{"atb":[[3.95,0]],"id":2441997}],"con":true,"img":false}]}
{"op":"mcm","clk":"5322778241","pt":1646324035091,"mc":[{"id":"1.195532868","rc":[{"atb":[[4.1,1.99]],"id":2441997}],"con":true,"img":false}]}
{"op":"mcm","clk":"5322778340","pt":1646324035976,"mc":[{"id":"1.195532868","rc":[{"atl":[[1000,14.52]],"id":2441997}],"con":true,"img":false}]}
{"op":"mcm","clk":"5322778354","pt":1646324036087,"mc":[{"id":"1.195532868","rc":[{"atl":[[1000,14.1]],"id":2441997}],"con":true,"img":false}]}
{"op":"mcm","clk":"5322778361","pt":1646324036187,"mc":[{"id":"1.195532868","rc":[{"atl":[[1000,12]],"id":2441997}],"con":true,"img":false}]}
{"op":"mcm","clk":"5322778372","pt":1646324036288,"mc":[{"id":"1.195532868","rc":[{"atl":[[7.8,2.1]],"id":2441997}],"con":true,"img":false}]}
{"op":"mcm","clk":"5322778419","pt":1646324036747,"mc":[{"id":"1.195532868","rc":[{"atb":[[4,0]],"id":2441997},{"atb":[[6.6,0]],"id":42142047}],"con":true,"img":false}]}
{"op":"mcm","clk":"5322778467","pt":1646324037095,"mc":[{"id":"1.195532868","rc":[{"atb":[[3.8,1.6]],"id":40133336}],"con":true,"img":false}]}
{"op":"mcm","clk":"5322778485","pt":1646324037302,"mc":[{"id":"1.195532868","rc":[{"atl":[[8.2,5.95],[8.4,0]],"id":2441997},{"atb":[[6.8,0]],"id":42142047},{"atb":[[3.85,0],[3.7,37.04]],"id":40133336}],"con":true,"img":false}]}
{"op":"mcm","clk":"5322778497","pt":1646324037404,"mc":[{"id":"1.195532868","rc":[{"atb":[[6.4,1.99]],"id":42142047}],"con":true,"img":false}]}
{"op":"mcm","clk":"5322778509","pt":1646324037511,"mc":[{"id":"1.195532868","rc":[{"atb":[[5.6,0],[5.5,9.76]],"id":42142047}],"con":true,"img":false}]}
{"op":"mcm","clk":"5322778520","pt":1646324037617,"mc":[{"id":"1.195532868","rc":[{"atb":[[4.1,0]],"id":2441997}],"con":true,"img":false}]}
{"op":"mcm","clk":"5322778532","pt":1646324037721,"mc":[{"id":"1.195532868","rc":[{"atb":[[3.95,1.99]],"id":2441997}],"con":true,"img":false}]}
{"op":"mcm","clk":"5322778643","pt":1646324038824,"mc":[{"id":"1.195532868","rc":[{"atb":[[8.4,3.29]],"id":40302111},{"atb":[[3.65,6.7]],"id":2441997},{"atb":[[2.88,5.5]],"id":36909993}],"con":true,"img":false}]}
{"op":"mcm","clk":"5322778661","pt":1646324039021,"mc":[{"id":"1.195532868","rc":[{"atb":[[4,2.48]],"id":2441997},{"atb":[[6.6,2.48]],"id":42142047}],"con":true,"img":false}]}
{"op":"mcm","clk":"5322778739","pt":1646324039815,"mc":[{"id":"1.195532868","rc":[{"atb":[[6.4,0]],"id":42142047}],"con":true,"img":false}]}
{"op":"mcm","clk":"5322778750","pt":1646324039916,"mc":[{"id":"1.195532868","rc":[{"atb":[[1.03,2.89]],"id":2441997},{"atb":[[1.03,2.91]],"id":36909993},{"atb":[[6.8,1.99]],"id":42142047},{"atb":[[1.05,2.84]],"id":42609835},{"atb":[[1.04,2.87]],"id":40133336}],"con":true,"img":false}]}
{"op":"mcm","clk":"5322778772","pt":1646324040124,"mc":[{"id":"1.195532868","rc":[{"atb":[[3.95,0]],"id":2441997}],"con":true,"img":false}]}
{"op":"mcm","clk":"5322778780","pt":1646324040223,"mc":[{"id":"1.195532868","rc":[{"atb":[[4.1,1.99]],"id":2441997}],"con":true,"img":false}]}
{"op":"mcm","clk":"5322778791","pt":1646324040330,"mc":[{"id":"1.195532868","rc":[{"atb":[[1.03,0.14]],"id":2441997},{"atb":[[1.03,0.17]],"id":36909993},{"atb":[[1.05,0.09]],"id":42609835},{"atb":[[1.04,0.13]],"id":40133336}],"con":true,"img":false}]}
{"op":"mcm","clk":"5322778844","pt":1646324040715,"mc":[{"id":"1.195532868","rc":[{"atb":[[1.03,0]],"id":2441997},{"atb":[[1.03,0]],"id":36909993},{"atb":[[1.05,0]],"id":42609835},{"atb":[[1.04,0]],"id":40133336}],"con":true,"img":false}]}
{"op":"mcm","clk":"5322778857","pt":1646324040811,"mc":[{"id":"1.195532868","rc":[{"atb":[[3.7,0.14]],"id":2441997},{"atb":[[3.15,0.17]],"id":36909993},{"atb":[[5.4,0.3]],"id":42609835},{"atb":[[4.1,0.13]],"id":40133336}],"con":true,"img":false}]}
{"op":"mcm","clk":"5322778889","pt":1646324041119,"mc":[{"id":"1.195532868","rc":[{"atl":[[7.8,4.2],[8.8,12.62]],"id":2441997}],"con":true,"img":false}]}
{"op":"mcm","clk":"5322778911","pt":1646324041326,"mc":[{"id":"1.195532868","rc":[{"atb":[[8.2,0]],"id":40302111},{"atb":[[3.35,1.69]],"id":2441997},{"atl":[[8.2,11.9],[7.8,2.1]],"id":2441997},{"atb":[[5,25]],"id":42609835}],"con":true,"img":false}]}
{"op":"mcm","clk":"5322778926","pt":1646324041390,"mc":[{"id":"1.195532868","rc":[{"atl":[[5.4,34.09]],"id":36909993},{"atb":[[4.8,5.19],[4.9,25.64]],"id":42609835},{"atl":[[7.6,33.07]],"id":40133336}],"con":true,"img":false}]}
{"op":"mcm","clk":"5322778937","pt":1646324041492,"mc":[{"id":"1.195532868","rc":[{"atl":[[8.2,5.95],[7.8,6.3]],"id":2441997}],"con":true,"img":false}]}
{"op":"mcm","clk":"5322778950","pt":1646324041600,"mc":[{"id":"1.195532868","rc":[{"atl":[[8.2,17.85]],"id":2441997}],"con":true,"img":false}]}
{"op":"mcm","clk":"5322778962","pt":1646324041702,"mc":[{"id":"1.195532868","rc":[{"atl":[[7.8,2.1]],"id":2441997},{"atb":[[4.8,0]],"id":42609835}],"con":true,"img":false}]}
{"op":"mcm","clk":"5322778975","pt":1646324041807,"mc":[{"id":"1.195532868","rc":[{"atb":[[4,0]],"id":2441997},{"atl":[[8.2,17.37]],"id":2441997},{"atb":[[6.6,0]],"id":42142047}],"con":true,"img":false}]}
{"op":"mcm","clk":"5322778986","pt":1646324041904,"mc":[{"id":"1.195532868","rc":[{"atl":[[8.2,5.47],[7.8,8.4],[7.6,0.48]],"id":2441997},{"atb":[[3.9,0]],"id":40133336}],"con":true,"img":false}]}
{"op":"mcm","clk":"5322779093","pt":1646324042804,"mc":[{"id":"1.195532868","rc":[{"atb":[[6.8,0]],"id":42142047}],"con":true,"img":false}]}
{"op":"mcm","clk":"5322779109","pt":1646324042908,"mc":[{"id":"1.195532868","rc":[{"atb":[[4.2,2.48]],"id":2441997},{"atb":[[6.4,1.99]],"id":42142047}],"con":true,"img":false}]}
{"op":"mcm","clk":"5322779141","pt":1646324043223,"mc":[{"id":"1.195532868","rc":[{"atb":[[4.1,0]],"id":2441997},{"atl":[[8,7.07],[8.2,0]],"id":2441997},{"atb":[[3.75,50.91],[3.7,0]],"id":40133336},{"atl":[[9.2,0]],"id":40133336}],"con":true,"img":false}]}
{"op":"mcm","clk":"5322779152","pt":1646324043331,"mc":[{"id":"1.195532868","rc":[{"atb":[[3.95,1.99]],"id":2441997}],"con":true,"img":false}]}
{"op":"mcm","clk":"5322779228","pt":1646324043999,"mc":[{"id":"1.195532868","rc":[{"atb":[[3.85,2.52]],"id":40133336}],"con":true,"img":false}]}
{"op":"mcm","clk":"5322779262","pt":1646324044323,"mc":[{"id":"1.195532868","rc":[{"atb":[[5.7,0]],"id":42142047}],"con":true,"img":false}]}
{"op":"mcm","clk":"5322779272","pt":1646324044431,"mc":[{"id":"1.195532868","rc":[{"atb":[[5.6,1.71]],"id":42142047}],"con":true,"img":false}]}
{"op":"mcm","clk":"5322779341","pt":1646324045107,"mc":[{"id":"1.195532868","rc":[{"atb":[[8.4,0]],"id":40302111},{"atb":[[3.35,0],[3.65,0]],"id":2441997}],"con":true,"img":false}]}
{"op":"mcm","clk":"5322779349","pt":1646324045214,"mc":[{"id":"1.195532868","rc":[{"atb":[[3.7,1.83]],"id":2441997},{"atb":[[6.6,2.48]],"id":42142047}],"con":true,"img":false}]}
{"op":"mcm","clk":"5322779450","pt":1646324046096,"mc":[{"id":"1.195532868","rc":[{"atb":[[3.7,0.14]],"id":2441997}],"con":true,"img":false}]}
{"op":"mcm","clk":"5322779459","pt":1646324046199,"mc":[{"id":"1.195532868","rc":[{"atb":[[3.35,1.69]],"id":2441997}],"con":true,"img":false}]}
{"op":"mcm","clk":"5322779592","pt":1646324047613,"mc":[{"id":"1.195532868","rc":[{"atl":[[4.5,0]],"id":40133336}],"con":true,"img":false}]}
{"op":"mcm","clk":"5322779603","pt":1646324047714,"mc":[{"id":"1.195532868","rc":[{"atb":[[3.85,1.75],[4,0],[4.1,0]],"id":40133336},{"trd":[[3.85,1.53],[4,0.54],[4.1,0.26]],"ltp":3.85,"tv":2.33,"id":40133336}],"con":true,"img":false}]}
{"op":"mcm","clk":"5322779613","pt":1646324047820,"mc":[{"id":"1.195532868","rc":[{"atl":[[7.4,13.8],[7.6,22.73]],"id":40133336}],"con":true,"img":false}]}
{"op":"mcm","clk":"5322779796","pt":1646324049533,"mc":[{"id":"1.195532868","rc":[{"atb":[[3.95,0]],"id":2441997}],"con":true,"img":false}]}
{"op":"mcm","clk":"5322779805","pt":1646324049594,"mc":[{"id":"1.195532868","rc":[{"atb":[[4.3,1.99]],"id":2441997}],"con":true,"img":false}]}
{"op":"mcm","clk":"5322779826","pt":1646324049809,"mc":[{"id":"1.195532868","rc":[{"atb":[[4.3,30.3],[5.3,0],[8.2,3.38]],"id":40302111},{"atb":[[3.95,2.73]],"id":2441997},{"atb":[[5,0],[4.7,67.57]],"id":42609835},{"atb":[[3.55,107.32],[3.75,14.55]],"id":40133336},{"atl":[[6.8,0],[7,6.67]],"id":40133336}],"con":true,"img":false}]}
{"op":"mcm","clk":"5322779884","pt":1646324050431,"mc":[{"id":"1.195532868","rc":[{"atb":[[8.2,16.52]],"id":40302111},{"atb":[[3.4,16.78],[4.2,0]],"id":2441997}],"con":true,"img":false}]}
{"op":"mcm","clk":"5322779901","pt":1646324050639,"mc":[{"id":"1.195532868","rc":[{"atl":[[6.6,0]],"id":40133336}],"con":true,"img":false}]}
{"op":"mcm","clk":"5322779910","pt":1646324050734,"mc":[{"id":"1.195532868","rc":[{"atb":[[6.4,0]],"id":42142047},{"atl":[[6.8,0.48]],"id":40133336}],"con":true,"img":false}]}
{"op":"mcm","clk":"5322779924","pt":1646324050837,"mc":[{"id":"1.195532868","rc":[{"atb":[[6.8,1.99]],"id":42142047}],"con":true,"img":false}]}
{"op":"mcm","clk":"5322779944","pt":1646324051005,"mc":[{"id":"1.195532868","rc":[{"atb":[[4.3,0]],"id":2441997}],"con":true,"img":false}]}
{"op":"mcm","clk":"5322779958","pt":1646324051107,"mc":[{"id":"1.195532868","rc":[{"atb":[[4,1.99]],"id":2441997}],"con":true,"img":false}]}
{"op":"mcm","clk":"5322779993","pt":1646324051420,"mc":[{"id":"1.195532868","rc":[{"atl":[[5.6,54.35]],"id":36909993}],"con":true,"img":false}]}
{"op":"mcm","clk":"5322780016","pt":1646324051631,"mc":[{"id":"1.195532868","rc":[{"atb":[[4.1,1.65]],"id":2441997}],"con":true,"img":false}]}
{"op":"mcm","clk":"5322780037","pt":1646324051840,"mc":[{"id":"1.195532868","rc":[{"atb":[[6.6,0]],"id":42142047}],"con":true,"img":false}]}
{"op":"mcm","clk":"5322780128","pt":1646324052731,"mc":[{"id":"1.195532868","rc":[{"atb":[[6.8,0]],"id":42142047}],"con":true,"img":false}]}
{"op":"mcm","clk":"5322780137","pt":1646324052828,"mc":[{"id":"1.195532868","rc":[{"atb":[[6.4,1.99]],"id":42142047}],"con":true,"img":false}]}
{"op":"mcm","clk":"5322780148","pt":1646324052941,"mc":[{"id":"1.195532868","rc":[{"atb":[[5.1,34.15],[5.5,0]],"id":42142047}],"con":true,"img":false}]}
{"op":"mcm","clk":"5322780170","pt":1646324053135,"mc":[{"id":"1.195532868","rc":[{"atb":[[3.85,0]],"id":40133336},{"atl":[[3.85,8.25]],"id":40133336},{"trd":[[3.85,5.04]],"ltp":3.85,"tv":5.04,"id":40133336}],"con":true,"img":false}]}
{"op":"mcm","clk":"5322780181","pt":1646324053240,"mc":[{"id":"1.195532868","rc":[{"atl":[[8.4,13.3]],"id":2441997},{"atl":[[3.85,0]],"id":40133336},{"trd":[[3.85,21.54]],"ltp":3.85,"tv":21.54,"id":40133336}],"con":true,"img":false}]}
{"op":"mcm","clk":"5322780218","pt":1646324053620,"mc":[{"id":"1.195532868","rc":[{"atl":[[1000,14.52]],"id":40133336}],"con":true,"img":false}]}
{"op":"mcm","clk":"5322780231","pt":1646324053722,"mc":[{"id":"1.195532868","rc":[{"atl":[[1000,14.1]],"id":40133336}],"con":true,"img":false}]}
{"op":"mcm","clk":"5322780243","pt":1646324053827,"mc":[{"id":"1.195532868","rc":[{"atb":[[5.4,3.4]],"id":42142047},{"atl":[[1000,12]],"id":40133336}],"con":true,"img":false}]}
{"op":"mcm","clk":"5322780251","pt":1646324053927,"mc":[{"id":"1.195532868","rc":[{"atb":[[3.4,0]],"id":2441997},{"atl":[[6.8,2.58]],"id":40133336}],"con":true,"img":false}]}
{"op":"mcm","clk":"5322780271","pt":1646324054240,"mc":[{"id":"1.195532868","rc":[{"atb":[[5.6,0]],"id":42142047}],"con":true,"img":false}]}
{"op":"mcm","clk":"5322780280","pt":1646324054337,"mc":[{"id":"1.195532868","rc":[{"atb":[[1.01,11003.71]],"id":42142047}],"con":true,"img":false}]}
{"op":"mcm","clk":"5322780367","pt":1646324055644,"mc":[{"id":"1.195532868","rc":[{"atb":[[3.95,4.73],[3.9,0]],"id":2441997},{"atb":[[3.35,2],[3.3,0]],"id":36909993}],"con":true,"img":false}]}
{"op":"mcm","clk":"5322780381","pt":1646324055845,"mc":[{"id":"1.195532868","rc":[{"atb":[[5.4,0.2]],"id":42142047}],"con":true,"img":false}]}
{"op":"mcm","clk":"5322780403","pt":1646324056013,"mc":[{"id":"1.195532868","rc":[{"atl":[[12,0]],"id":2441997},{"atb":[[2.86,21.51],[2.74,154.68]],"id":36909993},{"atb":[[3.6,40.46],[3.55,68.1],[3.75,0],[3.7,14.81]],"id":40133336},{"atl":[[7.4,0],[7.2,6.45],[7.6,37.88],[7,0]],"id":40133336}],"con":true,"img":false}]}
{"op":"mcm","clk":"5322780409","pt":1646324056106,"mc":[{"id":"1.195532868","rc":[{"atb":[[1.01,11002]],"id":42142047}],"con":true,"img":false}]}
{"op":"mcm","clk":"5322780424","pt":1646324056221,"mc":[{"id":"1.195532868","rc":[{"atb":[[5.2,1.71]],"id":42142047}],"con":true,"img":false}]}
{"op":"mcm","clk":"5322780450","pt":1646324056430,"mc":[{"id":"1.195532868","rc":[{"atl":[[6.8,2.1]],"id":40133336}],"con":true,"img":false}]}
{"op":"mcm","clk":"5322780459","pt":1646324056533,"mc":[{"id":"1.195532868","rc":[{"atl":[[7,0.48]],"id":40133336}],"con":true,"img":false}]}
{"op":"mcm","clk":"5322780512","pt":1646324057117,"mc":[{"id":"1.195532868","rc":[{"atb":[[3.8,0]],"id":40133336}],"con":true,"img":false}]}
{"op":"mcm","clk":"5322780521","pt":1646324057228,"mc":[{"id":"1.195532868","rc":[{"atb":[[3.75,1.6]],"id":40133336}],"con":true,"img":false}]}
{"op":"mcm","clk":"5322780541","pt":1646324057432,"mc":[{"id":"1.195532868","rc":[{"atb":[[1.01,11003.65]],"id":2441997},{"atl":[[1000,13.65]],"id":42142047}],"con":true,"img":false}]}
{"op":"mcm","clk":"5322780549","pt":1646324057520,"mc":[{"id":"1.195532868","rc":[{"atl":[[1000,13.65]],"id":40302111}],"con":true,"img":false}]}
{"op":"mcm","clk":"5322780561","pt":1646324057633,"mc":[{"id":"1.195532868","rc":[{"atl":[[1000,12.35]],"id":42142047}],"con":true,"img":false}]}
{"op":"mcm","clk":"5322780570","pt":1646324057744,"mc":[{"id":"1.195532868","rc":[{"atl":[[1000,12.15]],"id":40302111}],"con":true,"img":false}]}
{"op":"mcm","clk":"5322780581","pt":1646324057846,"mc":[{"id":"1.195532868","rc":[{"atb":[[1.01,11002.98]],"id":2441997}],"con":true,"img":false}]}
{"op":"mcm","clk":"5322780601","pt":1646324058050,"mc":[{"id":"1.195532868","rc":[{"atl":[[1000,12]],"id":42142047}],"con":true,"img":false}]}
{"op":"mcm","clk":"5322780613","pt":1646324058111,"mc":[{"id":"1.195532868","rc":[{"atb":[[3.95,2]],"id":2441997},{"atl":[[11.5,0.35]],"id":42142047}],"con":true,"img":false}]}
{"op":"mcm","clk":"5322780623","pt":1646324058219,"mc":[{"id":"1.195532868","rc":[{"atb":[[8,0],[3.55,39.22],[7.6,6.06]],"id":40302111},{"atl":[[1000,12]],"id":40302111},{"atb":[[3.7,0],[3.65,15.09]],"id":40133336}],"con":true,"img":false}]}
{"op":"mcm","clk":"5322780636","pt":1646324058320,"mc":[{"id":"1.195532868","rc":[{"atb":[[4.3,0],[9.6,0]],"id":40302111},{"atl":[[26,0.15]],"id":40302111},{"atb":[[2.1,0]],"id":36909993}],"con":true,"img":false}]}
{"op":"mcm","clk":"5322780656","pt":1646324058528,"mc":[{"id":"1.195532868","rc":[{"atb":[[1.01,11002]],"id":2441997}],"con":true,"img":false}]}
{"op":"mcm","clk":"5322780665","pt":1646324058627,"mc":[{"id":"1.195532868","rc":[{"atb":[[4.2,0.98]],"id":2441997}],"con":true,"img":false}]}
{"op":"mcm","clk":"5322780703","pt":1646324059041,"mc":[{"id":"1.195532868","rc":[{"atb":[[4,0]],"id":2441997}],"con":true,"img":false}]}
{"op":"mcm","clk":"5322780713","pt":1646324059148,"mc":[{"id":"1.195532868","rc":[{"atb":[[4.2,2.97]],"id":2441997},{"atb":[[3.75,0]],"id":40133336}],"con":true,"img":false}]}
{"op":"mcm","clk":"5322780722","pt":1646324059243,"mc":[{"id":"1.195532868","rc":[{"atb":[[3.7,1.6]],"id":40133336}],"con":true,"img":false}]}
{"op":"mcm","clk":"5322780786","pt":1646324059928,"mc":[{"id":"1.195532868","rc":[{"atb":[[4.2,0.98]],"id":2441997}],"con":true,"img":false}]}
{"op":"mcm","clk":"5322780795","pt":1646324060034,"mc":[{"id":"1.195532868","rc":[{"atb":[[4,1.99]],"id":2441997}],"con":true,"img":false}]}
{"op":"mcm","clk":"5322780817","pt":1646324060346,"mc":[{"id":"1.195532868","rc":[{"atl":[[6.6,3.84]],"id":40133336}],"con":true,"img":false}]}
{"op":"mcm","clk":"5322780852","pt":1646324060707,"mc":[{"id":"1.195532868","rc":[{"atl":[[6.8,0]],"id":40133336}],"con":true,"img":false}]}
{"op":"mcm","clk":"5322780863","pt":1646324060822,"mc":[{"id":"1.195532868","rc":[{"atb":[[8.2,3.38]],"id":40302111},{"atb":[[3.4,18.52]],"id":2441997}],"con":true,"img":false}]}
{"op":"mcm","clk":"5322780883","pt":1646324061032,"mc":[{"id":"1.195532868","rc":[{"atl":[[28,1.86],[29,3.57]],"id":40302111},{"atb":[[4,0]],"id":2441997},{"atl":[[12.5,8.6],[13,0]],"id":42142047},{"atb":[[3.6,55.84],[3.65,0]],"id":40133336},{"atl":[[7,7.15]],"id":40133336}],"con":true,"img":false}]}
{"op":"mcm","clk":"5322780892","pt":1646324061128,"mc":[{"id":"1.195532868","rc":[{"atb":[[3.35,0],[4.2,2.97]],"id":2441997},{"atb":[[3.6,17.38],[3.55,107.32]],"id":40133336}],"con":true,"img":false}]}
{"op":"mcm","clk":"5322780903","pt":1646324061234,"mc":[{"id":"1.195532868","rc":[{"atb":[[3.45,1.69]],"id":2441997},{"atl":[[7,6.67]],"id":40133336}],"con":true,"img":false}]}
{"op":"mcm","clk":"5322780916","pt":1646324061339,"mc":[{"id":"1.195532868","rc":[{"atl":[[6.4,0.48]],"id":40133336}],"con":true,"img":false}]}
{"op":"mcm","clk":"5322780945","pt":1646324061703,"mc":[{"id":"1.195532868","rc":[{"atb":[[4.2,0.98]],"id":2441997}],"con":true,"img":false}]}
{"op":"mcm","clk":"5322780959","pt":1646324061814,"mc":[{"id":"1.195532868","rc":[{"atb":[[4,1.99]],"id":2441997}],"con":true,"img":false}]}
{"op":"mcm","clk":"5322780987","pt":1646324062124,"mc":[{"id":"1.195532868","rc":[{"atb":[[3.7,0]],"id":40133336}],"con":true,"img":false}]}
{"op":"mcm","clk":"5322780997","pt":1646324062227,"mc":[{"id":"1.195532868","rc":[{"atb":[[3.65,1.6]],"id":40133336}],"con":true,"img":false}]}
{"op":"mcm","clk":"5322781038","pt":1646324062751,"mc":[{"id":"1.195532868","rc":[{"atb":[[8.2,0]],"id":40302111},{"atb":[[3.7,9.02]],"id":40133336}],"con":true,"img":false}]}
{"op":"mcm","clk":"5322781049","pt":1646324062848,"mc":[{"id":"1.195532868","rc":[{"atb":[[4,0]],"id":2441997}],"con":true,"img":false}]}
{"op":"mcm","clk":"5322781062","pt":1646324062916,"mc":[{"id":"1.195532868","rc":[{"atb":[[4.2,2.97]],"id":2441997}],"con":true,"img":false}]}
{"op":"mcm","clk":"5322781080","pt":1646324063125,"mc":[{"id":"1.195532868","rc":[{"atl":[[12.5,6.92]],"id":42142047}],"con":true,"img":false}]}
{"op":"mcm","clk":"5322781089","pt":1646324063226,"mc":[{"id":"1.195532868","rc":[{"atl":[[8.8,18.93]],"id":2441997}],"con":true,"img":false}]}
{"op":"mcm","clk":"5322781094","pt":1646324063328,"mc":[{"id":"1.195532868","rc":[{"atl":[[1000,14.52]],"id":42142047}],"con":true,"img":false}]}
{"op":"mcm","clk":"5322781119","pt":1646324063646,"mc":[{"id":"1.195532868","rc":[{"atl":[[1000,13.68]],"id":42142047}],"con":true,"img":false}]}
{"op":"mcm","clk":"5322781139","pt":1646324063846,"mc":[{"id":"1.195532868","rc":[{"atl":[[1000,12]],"id":42142047}],"con":true,"img":false}]}
{"op":"mcm","clk":"5322781143","pt":1646324063949,"mc":[{"id":"1.195532868","rc":[{"atl":[[12,2.14]],"id":42142047}],"con":true,"img":false}]}
{"op":"mcm","clk":"5322781170","pt":1646324064224,"mc":[{"id":"1.195532868","rc":[{"atb":[[3.4,0]],"id":2441997}],"con":true,"img":false}]}
{"op":"mcm","clk":"5322781198","pt":1646324064534,"mc":[{"id":"1.195532868","rc":[{"atb":[[3.5,13.14]],"id":40133336}],"con":true,"img":false}]}
{"op":"mcm","clk":"5322781251","pt":1646324065117,"mc":[{"id":"1.195532868","rc":[{"atb":[[3.45,0]],"id":2441997}],"con":true,"img":false}]}
{"op":"mcm","clk":"5322781259","pt":1646324065223,"mc":[{"id":"1.195532868","rc":[{"atb":[[1.01,11003.69]],"id":2441997}],"con":true,"img":false}]}
{"op":"mcm","clk":"5322781329","pt":1646324066053,"mc":[{"id":"1.195532868","rc":[{"atb":[[7.8,13.9]],"id":40302111},{"atb":[[3.5,0]],"id":40133336}],"con":true,"img":false}]}
{"op":"mcm","clk":"5322781354","pt":1646324066226,"mc":[{"id":"1.195532868","rc":[{"atl":[[7,0]],"id":40133336}],"con":true,"img":false}]}
{"op":"mcm","clk":"5322781370","pt":1646324066340,"mc":[{"id":"1.195532868","rc":[{"atl":[[6.8,6.9]],"id":40133336}],"con":true,"img":false}]}
{"op":"mcm","clk":"5322781474","pt":1646324067432,"mc":[{"id":"1.195532868","rc":[{"atb":[[5.2,7.51]],"id":42142047}],"con":true,"img":false}]}
{"op":"mcm","clk":"5322781539","pt":1646324068055,"mc":[{"id":"1.195532868","rc":[{"atb":[[4.1,0]],"id":2441997}],"con":true,"img":false}]}
{"op":"mcm","clk":"5322781553","pt":1646324068161,"mc":[{"id":"1.195532868","rc":[{"atb":[[3.35,20.84]],"id":2441997}],"con":true,"img":false}]}
{"op":"mcm","clk":"5322781609","pt":1646324068640,"mc":[{"id":"1.195532868","rc":[{"atb":[[4.2,0.98]],"id":2441997}],"con":true,"img":false}]}
{"op":"mcm","clk":"5322781622","pt":1646324068743,"mc":[{"id":"1.195532868","rc":[{"atb":[[4,1.99]],"id":2441997}],"con":true,"img":false}]}
{"op":"mcm","clk":"5322781843","pt":1646324071032,"mc":[{"id":"1.195532868","rc":[{"atb":[[7.2,40.32]],"id":40302111},{"atl":[[13.5,8]],"id":42142047}],"con":true,"img":false}]}
{"op":"mcm","clk":"5322781852","pt":1646324071134,"mc":[{"id":"1.195532868","rc":[{"atb":[[7.2,16.13]],"id":40302111}],"con":true,"img":false}]}
{"op":"mcm","clk":"5322781983","pt":1646324072653,"mc":[{"id":"1.195532868","rc":[{"atl":[[6.6,0]],"id":40133336}],"con":true,"img":false}]}
{"op":"mcm","clk":"5322782040","pt":1646324073228,"mc":[{"id":"1.195532868","rc":[{"atb":[[4.1,1.65]],"id":2441997},{"atl":[[9.2,30.01]],"id":2441997}],"con":true,"img":false}]}
{"op":"mcm","clk":"5322782213","pt":1646324074127,"mc":[{"id":"1.195532868","rc":[{"atb":[[1.01,11002]],"id":2441997}],"con":true,"img":false}]}
{"op":"mcm","clk":"5322782231","pt":1646324074230,"mc":[{"id":"1.195532868","rc":[{"atb":[[3.4,1.69]],"id":2441997}],"con":true,"img":false}]}
{"op":"mcm","clk":"5322782316","pt":1646324074954,"mc":[{"id":"1.195532868","rc":[{"atl":[[6.4,0]],"id":40133336}],"con":true,"img":false}]}
{"op":"mcm","clk":"5322782326","pt":1646324075064,"mc":[{"id":"1.195532868","rc":[{"atl":[[6.6,0.48]],"id":40133336}],"con":true,"img":false}]}
{"op":"mcm","clk":"5322782377","pt":1646324075542,"mc":[{"id":"1.195532868","rc":[{"atb":[[3.55,0],[6.6,17.86]],"id":40302111},{"atb":[[3.1,71.43],[3.5,17.39]],"id":2441997},{"atl":[[11,0]],"id":2441997},{"atb":[[5.3,23.26],[5.1,9.76]],"id":42142047},{"atl":[[12.5,4.36],[13,8],[16.5,0.2]],"id":42142047},{"atb":[[5.3,9.76],[4.7,40.54]],"id":42609835},{"atl":[[11.5,10.48]],"id":42609835},{"atb":[[3.55,68.1],[3.75,9.02]],"id":40133336},{"atl":[[6.8,0],[8.4,12.9],[7.6,22.73],[7,6.67]],"id":40133336}],"con":true,"img":false}]}
{"op":"mcm","clk":"5322782396","pt":1646324075729,"mc":[{"id":"1.195532868","rc":[{"atl":[[13.5,28]],"id":42609835}],"con":true,"img":false}]}
{"op":"mcm","clk":"5322782401","pt":1646324075833,"mc":[{"id":"1.195532868","rc":[{"atl":[[7,13.07]],"id":40133336}],"con":true,"img":false}]}
{"op":"mcm","clk":"5322782444","pt":1646324076139,"mc":[{"id":"1.195532868","rc":[{"atb":[[5.2,5.8]],"id":42142047},{"atl":[[7,6.67]],"id":40133336}],"con":true,"img":false}]}
{"op":"mcm","clk":"5322782454","pt":1646324076241,"mc":[{"id":"1.195532868","rc":[{"atb":[[5.4,1.91]],"id":42142047}],"con":true,"img":false}]}
{"op":"mcm","clk":"5322782465","pt":1646324076345,"mc":[{"id":"1.195532868","rc":[{"atb":[[6.6,0]],"id":40302111},{"atl":[[32,6.92],[29,0]],"id":40302111},{"atb":[[3,129.56],[3.5,0]],"id":2441997},{"atl":[[8.2,13.89],[7.8,2.1]],"id":2441997},{"atb":[[5.3,0]],"id":42609835},{"atb":[[3.75,0],[3.4,10.2],[3.65,16.69]],"id":40133336}],"con":true,"img":false}]}
{"op":"mcm","clk":"5322782476","pt":1646324076446,"mc":[{"id":"1.195532868","rc":[{"atb":[[3.65,37.74]],"id":40302111},{"atb":[[3.05,8.29]],"id":2441997},{"atb":[[4.7,67.57]],"id":42609835},{"atb":[[3.55,107.32]],"id":40133336}],"con":true,"img":false}]}
{"op":"mcm","clk":"5322782485","pt":1646324076551,"mc":[{"id":"1.195532868","rc":[{"atb":[[3.35,0]],"id":2441997},{"atb":[[3.55,64.19],[3.65,1.6]],"id":40133336},{"atl":[[6.6,0]],"id":40133336}],"con":true,"img":false}]}
{"op":"mcm","clk":"5322782494","pt":1646324076654,"mc":[{"id":"1.195532868","rc":[{"atl":[[6.8,0.48]],"id":40133336}],"con":true,"img":false}]}
{"op":"mcm","clk":"5322782502","pt":1646324076759,"mc":[{"id":"1.195532868","rc":[{"atl":[[6.8,4.32]],"id":40133336}],"con":true,"img":false}]}
{"op":"mcm","clk":"5322782511","pt":1646324076863,"mc":[{"id":"1.195532868","rc":[{"atb":[[3,125]],"id":2441997},{"atb":[[3.4,0]],"id":40133336}],"con":true,"img":false}]}
{"op":"mcm","clk":"5322782544","pt":1646324077143,"mc":[{"id":"1.195532868","rc":[{"atb":[[3.4,0]],"id":2441997}],"con":true,"img":false}]}
{"op":"mcm","clk":"5322782556","pt":1646324077241,"mc":[{"id":"1.195532868","rc":[{"atb":[[3.35,1.69]],"id":2441997}],"con":true,"img":false}]}
{"op":"mcm","clk":"5322782575","pt":1646324077445,"mc":[{"id":"1.195532868","rc":[{"atl":[[7.6,0]],"id":2441997}],"con":true,"img":false}]}
{"op":"mcm","clk":"5322782584","pt":1646324077556,"mc":[{"id":"1.195532868","rc":[{"atl":[[7.8,2.58]],"id":2441997}],"con":true,"img":false}]}
{"op":"mcm","clk":"5322782646","pt":1646324078247,"mc":[{"id":"1.195532868","rc":[{"atb":[[5.2,0]],"id":42142047},{"atb":[[3.7,0]],"id":40133336}],"con":true,"img":false}]}
{"op":"mcm","clk":"5322782830","pt":1646324080275,"mc":[{"id":"1.195532868","rc":[{"atb":[[3.4,18.52]],"id":2441997}],"con":true,"img":false}]}
{"op":"mcm","clk":"5322782914","pt":1646324081075,"mc":[{"id":"1.195532868","rc":[{"atb":[[6.8,25.86]],"id":40302111},{"atl":[[14.5,11.11]],"id":42142047}],"con":true,"img":false}]}
{"op":"mcm","clk":"5322783121","pt":1646324082958,"mc":[{"id":"1.195532868","rc":[{"atb":[[5.4,7.45]],"id":42142047},{"atb":[[3.65,10.79]],"id":40133336}],"con":true,"img":false}]}
{"op":"mcm","clk":"5322783140","pt":1646324083163,"mc":[{"id":"1.195532868","rc":[{"atl":[[8,1.44],[8.2,19.36]],"id":2441997},{"atb":[[3.6,2]],"id":40133336},{"atl":[[7,0]],"id":40133336}],"con":true,"img":false}]}
{"op":"mcm","clk":"5322783165","pt":1646324083371,"mc":[{"id":"1.195532868","rc":[{"atl":[[8.2,23.92]],"id":2441997}],"con":true,"img":false}]}
{"op":"mcm","clk":"5322783224","pt":1646324083851,"mc":[{"id":"1.195532868","rc":[{"atl":[[7.8,2.1]],"id":2441997}],"con":true,"img":false}]}
{"op":"mcm","clk":"5322783232","pt":1646324083944,"mc":[{"id":"1.195532868","rc":[{"atl":[[8,1.92]],"id":2441997}],"con":true,"img":false}]}
{"op":"mcm","clk":"5322783267","pt":1646324084264,"mc":[{"id":"1.195532868","rc":[{"atl":[[8.2,19.36]],"id":2441997}],"con":true,"img":false}]}
{"op":"mcm","clk":"5322783320","pt":1646324084772,"mc":[{"id":"1.195532868","rc":[{"atl":[[12.5,12.36],[13,0]],"id":42142047},{"atl":[[7.4,12.9],[8.4,0]],"id":40133336}],"con":true,"img":false}]}
{"op":"mcm","clk":"5322783397","pt":1646324085461,"mc":[{"id":"1.195532868","rc":[{"atb":[[4.4,7.14]],"id":42609835}],"con":true,"img":false}]}
{"op":"mcm","clk":"5322783411","pt":1646324085559,"mc":[{"id":"1.195532868","rc":[{"atl":[[32,3.69],[29,3.57]],"id":40302111},{"atl":[[8,15.22]],"id":2441997}],"con":true,"img":false}]}
{"op":"mcm","clk":"5322783426","pt":1646324085657,"mc":[{"id":"1.195532868","rc":[{"atl":[[8.2,5.47]],"id":2441997}],"con":true,"img":false}]}
{"op":"mcm","clk":"5322783454","pt":1646324085871,"mc":[{"id":"1.195532868","rc":[{"atb":[[4.4,0]],"id":42609835}],"con":true,"img":false}]}
{"op":"mcm","clk":"5322783518","pt":1646324086558,"mc":[{"id":"1.195532868","rc":[{"atb":[[3.45,142.86]],"id":40133336},{"atl":[[7.6,37.88]],"id":40133336}],"con":true,"img":false}]}
{"op":"mcm","clk":"5322783530","pt":1646324086661,"mc":[{"id":"1.195532868","rc":[{"atb":[[3.45,40.82]],"id":40133336},{"atl":[[7.6,15.15]],"id":40133336}],"con":true,"img":false}]}
{"op":"mcm","clk":"5322783617","pt":1646324087458,"mc":[{"id":"1.195532868","rc":[{"atl":[[1000,13.65]],"id":40133336}],"con":true,"img":false}]}
{"op":"mcm","clk":"5322783630","pt":1646324087568,"mc":[{"id":"1.195532868","rc":[{"atl":[[1000,12.63]],"id":40133336}],"con":true,"img":false}]}
{"op":"mcm","clk":"5322783655","pt":1646324087772,"mc":[{"id":"1.195532868","rc":[{"atl":[[1000,12]],"id":40133336}],"con":true,"img":false}]}
{"op":"mcm","clk":"5322783671","pt":1646324087878,"mc":[{"id":"1.195532868","rc":[{"atl":[[6.6,0.63]],"id":40133336}],"con":true,"img":false}]}
{"op":"mcm","clk":"5322783803","pt":1646324089081,"mc":[{"id":"1.195532868","rc":[{"atl":[[6.8,0.48]],"id":40133336}],"con":true,"img":false}]}
{"op":"mcm","clk":"5322783821","pt":1646324089283,"mc":[{"id":"1.195532868","rc":[{"atl":[[1000,13.65],[6.6,0],[7,6.67]],"id":40133336}],"con":true,"img":false}]}
{"op":"mcm","clk":"5322783845","pt":1646324089492,"mc":[{"id":"1.195532868","rc":[{"atl":[[6.8,0],[1000,12.63]],"id":40133336}],"con":true,"img":false}]}
{"op":"mcm","clk":"5322783859","pt":1646324089595,"mc":[{"id":"1.195532868","rc":[{"atl":[[7,7.15]],"id":40133336}],"con":true,"img":false}]}
{"op":"mcm","clk":"5322783870","pt":1646324089690,"mc":[{"id":"1.195532868","rc":[{"atl":[[1000,12]],"id":40133336}],"con":true,"img":false}]}
{"op":"mcm","clk":"5322783885","pt":1646324089756,"mc":[{"id":"1.195532868","rc":[{"atl":[[7,7.78]],"id":40133336}],"con":true,"img":false}]}
{"op":"mcm","clk":"5322784027","pt":1646324091093,"mc":[{"id":"1.195532868","rc":[{"atb":[[6.4,46.3]],"id":40302111},{"atl":[[15.5,17.24]],"id":42142047}],"con":true,"img":false}]}
{"op":"mcm","clk":"5322784112","pt":1646324092082,"mc":[{"id":"1.195532868","rc":[{"spn":6.0,"spf":1.0,"id":2441997},{"atb":[[3.65,1.6]],"id":40133336},{"spn":5.32,"spf":1.0,"id":40133336}],"con":true,"img":false}]}
{"op":"mcm","clk":"5322784154","pt":1646324092390,"mc":[{"id":"1.195532868","rc":[{"atb":[[3.65,0]],"id":40133336}],"con":true,"img":false}]}
{"op":"mcm","clk":"5322784165","pt":1646324092495,"mc":[{"id":"1.195532868","rc":[{"atb":[[3.6,3.6]],"id":40133336}],"con":true,"img":false}]}
{"op":"mcm","clk":"5322784193","pt":1646324092763,"mc":[{"id":"1.195532868","rc":[{"atl":[[6.8,3.84]],"id":40133336}],"con":true,"img":false}]}
{"op":"mcm","clk":"5322784216","pt":1646324092974,"mc":[{"id":"1.195532868","rc":[{"atl":[[1000,13.65],[7,7.15]],"id":40133336}],"con":true,"img":false}]}
{"op":"mcm","clk":"5322784234","pt":1646324093172,"mc":[{"id":"1.195532868","rc":[{"atl":[[8.6,12.95]],"id":2441997},{"atl":[[1000,12.63]],"id":40133336}],"con":true,"img":false}]}
{"op":"mcm","clk":"5322784250","pt":1646324093285,"mc":[{"id":"1.195532868","rc":[{"atl":[[1000,12]],"id":40133336}],"con":true,"img":false}]}
{"op":"mcm","clk":"5322784262","pt":1646324093382,"mc":[{"id":"1.195532868","rc":[{"atl":[[6.6,0.63]],"id":40133336}],"con":true,"img":false}]}
{"op":"mcm","clk":"5322784367","pt":1646324094169,"mc":[{"id":"1.195532868","rc":[{"atb":[[3.6,6.53]],"id":40133336}],"con":true,"img":false}]}
{"op":"mcm","clk":"5322784391","pt":1646324094805,"mc":[{"id":"1.195532868","rc":[{"atl":[[9.2,0],[8.4,0],[8.8,0]],"id":2441997},{"atb":[[1.01,11004.52],[3.55,48.5],[3.5,16]],"id":40133336}],"con":true,"img":false}]}
{"op":"mcm","clk":"5322784406","pt":1646324094819,"mc":[{"id":"1.195532868","rc":[{"atb":[[1.01,11004.1]],"id":40133336}],"con":true,"img":false}]}
{"op":"mcm","clk":"5322784436","pt":1646324094868,"mc":[{"id":"1.195532868","rc":[{"atb":[[1.01,11002]],"id":40133336}],"con":true,"img":false}]}
{"op":"mcm","clk":"5322784453","pt":1646324094897,"mc":[{"id":"1.195532868","rc":[{"atb":[[3.65,2.1]],"id":40133336}],"con":true,"img":false}]}
{"op":"mcm","clk":"5322784497","pt":1646324095270,"mc":[{"id":"1.195532868","rc":[{"atb":[[4,0]],"id":2441997}],"con":true,"img":false}]}
{"op":"mcm","clk":"5322784506","pt":1646324095367,"mc":[{"id":"1.195532868","rc":[{"atb":[[4.2,2.97]],"id":2441997}],"con":true,"img":false}]}
{"op":"mcm","clk":"5322784522","pt":1646324095477,"mc":[{"id":"1.195532868","rc":[{"atb":[[1.01,11003.65],[4.2,1.99]],"id":2441997}],"con":true,"img":false}]}
{"op":"mcm","clk":"5322784545","pt":1646324095686,"mc":[{"id":"1.195532868","rc":[{"atb":[[1.01,11002.98]],"id":2441997}],"con":true,"img":false}]}
{"op":"mcm","clk":"5322784577","pt":1646324095998,"mc":[{"id":"1.195532868","rc":[{"atb":[[1.01,11002]],"id":2441997}],"con":true,"img":false}]}
{"op":"mcm","clk":"5322784586","pt":1646324096096,"mc":[{"id":"1.195532868","rc":[{"atb":[[4,0.98]],"id":2441997}],"con":true,"img":false}]}
{"op":"mcm","clk":"5322784605","pt":1646324096261,"mc":[{"id":"1.195532868","rc":[{"atb":[[1.01,11003.65],[4,0]],"id":2441997}],"con":true,"img":false}]}
{"op":"mcm","clk":"5322784625","pt":1646324096464,"mc":[{"id":"1.195532868","rc":[{"atb":[[1.01,11002.96]],"id":2441997}],"con":true,"img":false}]}
{"op":"mcm","clk":"5322784638","pt":1646324096580,"mc":[{"id":"1.195532868","rc":[{"atb":[[1.01,11002]],"id":2441997}],"con":true,"img":false}]}
{"op":"mcm","clk":"5322784646","pt":1646324096676,"mc":[{"id":"1.195532868","rc":[{"atb":[[4.3,0.96]],"id":2441997},{"atb":[[3.65,4.61]],"id":40133336}],"con":true,"img":false}]}
{"op":"mcm","clk":"5322784770","pt":1646324098086,"mc":[{"id":"1.195532868","rc":[{"atb":[[3.55,64.19]],"id":40133336},{"atl":[[7.4,0]],"id":40133336}],"con":true,"img":false}]}
{"op":"mcm","clk":"5322784786","pt":1646324098181,"mc":[{"id":"1.195532868","rc":[{"atl":[[7.2,19.35]],"id":40133336}],"con":true,"img":false}]}
{"op":"mcm","clk":"5322784801","pt":1646324098294,"mc":[{"id":"1.195532868","rc":[{"atl":[[7.4,3.97]],"id":40133336}],"con":true,"img":false}]}
{"op":"mcm","clk":"5322784831","pt":1646324098602,"mc":[{"id":"1.195532868","rc":[{"atl":[[7.4,0]],"id":40133336}],"con":true,"img":false}]}
{"op":"mcm","clk":"5322784844","pt":1646324098699,"mc":[{"id":"1.195532868","rc":[{"atb":[[3.4,0]],"id":2441997}],"con":true,"img":false}]}
{"op":"mcm","clk":"5322785200","pt":1646324101874,"mc":[{"id":"1.195532868","rc":[{"atb":[[4.2,0]],"id":2441997}],"con":true,"img":false}]}
{"op":"mcm","clk":"5322785216","pt":1646324101988,"mc":[{"id":"1.195532868","rc":[{"atb":[[4,1.99]],"id":2441997}],"con":true,"img":false}]}
{"op":"mcm","clk":"5322785240","pt":1646324102195,"mc":[{"id":"1.195532868","rc":[{"atb":[[2.8,3.06]],"id":36909993}],"con":true,"img":false}]}
{"op":"mcm","clk":"5322785262","pt":1646324102396,"mc":[{"id":"1.195532868","rc":[{"atb":[[3.4,19.59]],"id":2441997}],"con":true,"img":false}]}
{"op":"mcm","clk":"5322785290","pt":1646324102620,"mc":[{"id":"1.195532868","rc":[{"atb":[[2.8,0]],"id":36909993}],"con":true,"img":false}]}
{"op":"mcm","clk":"5322785386","pt":1646324103189,"mc":[{"id":"1.195532868","rc":[{"atl":[[9,18.46]],"id":2441997}],"con":true,"img":false}]}
{"op":"mcm","clk":"5322785394","pt":1646324103288,"mc":[{"id":"1.195532868","rc":[{"atl":[[8.6,16.88]],"id":2441997}],"con":true,"img":false}]}
{"op":"mcm","clk":"5322785406","pt":1646324103399,"mc":[{"id":"1.195532868","rc":[{"atb":[[28,14.14]],"id":40302111},{"atl":[[26,0],[27,0],[28,0]],"id":40302111},{"trd":[[28,3.72],[26,0.31],[27,0.39]],"ltp":28.0,"tv":4.42,"id":40302111}],"con":true,"img":false}]}
{"op":"mcm","clk":"5322785418","pt":1646324103498,"mc":[{"id":"1.195532868","rc":[{"atl":[[8.6,12.95]],"id":2441997}],"con":true,"img":false}]}
{"op":"mcm","clk":"5322785427","pt":1646324103556,"mc":[{"id":"1.195532868","rc":[{"atb":[[28,13.42]],"id":40302111},{"atl":[[32,1.66],[36,2.86],[40,0],[29,0]],"id":40302111},{"trd":[[28,5.16]],"ltp":28.0,"tv":5.16,"id":40302111}],"con":true,"img":false}]}
{"op":"mcm","clk":"5322785442","pt":1646324103658,"mc":[{"id":"1.195532868","rc":[{"atl":[[60,0.18]],"id":40302111}],"con":true,"img":false}]}
{"op":"mcm","clk":"5322785478","pt":1646324103984,"mc":[{"id":"1.195532868","rc":[{"atb":[[4,0]],"id":2441997}],"con":true,"img":false}]}
{"op":"mcm","clk":"5322785493","pt":1646324104077,"mc":[{"id":"1.195532868","rc":[{"atb":[[4.2,1.99]],"id":2441997}],"con":true,"img":false}]}
{"op":"mcm","clk":"5322785520","pt":1646324104293,"mc":[{"id":"1.195532868","rc":[{"atb":[[3.6,4.93]],"id":40133336}],"con":true,"img":false}]}
{"op":"mcm","clk":"5322785537","pt":1646324104400,"mc":[{"id":"1.195532868","rc":[{"atb":[[3.7,1.6]],"id":40133336}],"con":true,"img":false}]}
{"op":"mcm","clk":"5322785631","pt":1646324105084,"mc":[{"id":"1.195532868","rc":[{"atl":[[6.8,0]],"id":40133336}],"con":true,"img":false}]}
{"op":"mcm","clk":"5322785661","pt":1646324105390,"mc":[{"id":"1.195532868","rc":[{"atb":[[3.5,27.94]],"id":40133336}],"con":true,"img":false}]}
{"op":"mcm","clk":"5322785688","pt":1646324105600,"mc":[{"id":"1.195532868","rc":[{"atl":[[1000,13.65],[6.6,0]],"id":40133336}],"con":true,"img":false}]}
{"op":"mcm","clk":"5322785697","pt":1646324105699,"mc":[{"id":"1.195532868","rc":[{"atl":[[32,1.2]],"id":40302111},{"atb":[[4.2,0]],"id":2441997}],"con":true,"img":false}]}
{"op":"mcm","clk":"5322785727","pt":1646324105820,"mc":[{"id":"1.195532868","rc":[{"atb":[[7.8,0]],"id":40302111},{"atl":[[1000,12.46]],"id":40302111},{"atb":[[4,1.99]],"id":2441997},{"atl":[[7.2,6.45],[7.6,30.3],[1000,12.63]],"id":40133336}],"con":true,"img":false}]}
{"op":"mcm","clk":"5322785751","pt":1646324105975,"mc":[{"id":"1.195532868","rc":[{"atl":[[1000,12]],"id":40133336}],"con":true,"img":false}]}
{"op":"mcm","clk":"5322785764","pt":1646324106078,"mc":[{"id":"1.195532868","rc":[{"atl":[[6.8,0.63]],"id":40133336}],"con":true,"img":false}]}
{"op":"mcm","clk":"5322785800","pt":1646324106491,"mc":[{"id":"1.195532868","rc":[{"atb":[[3.5,16]],"id":40133336}],"con":true,"img":false}]}
{"op":"mcm","clk":"5322785811","pt":1646324106597,"mc":[{"id":"1.195532868","rc":[{"atb":[[4,0]],"id":2441997},{"atb":[[3.6,2],[3.65,2.51]],"id":40133336}],"con":true,"img":false}]}
{"op":"mcm","clk":"5322785822","pt":1646324106701,"mc":[{"id":"1.195532868","rc":[{"atb":[[4.2,1.99]],"id":2441997}],"con":true,"img":false}]}
{"op":"mcm","clk":"5322785860","pt":1646324106968,"mc":[{"id":"1.195532868","rc":[{"atl":[[1000,14.52]],"id":40133336}],"con":true,"img":false}]}
{"op":"mcm","clk":"5322785879","pt":1646324107176,"mc":[{"id":"1.195532868","rc":[{"atl":[[1000,14.1]],"id":40133336}],"con":true,"img":false}]}
{"op":"mcm","clk":"5322785899","pt":1646324107390,"mc":[{"id":"1.195532868","rc":[{"atl":[[1000,12]],"id":40133336}],"con":true,"img":false}]}
{"op":"mcm","clk":"5322785917","pt":1646324107498,"mc":[{"id":"1.195532868","rc":[{"atl":[[6.8,2.73]],"id":40133336}],"con":true,"img":false}]}
{"op":"mcm","clk":"5322785927","pt":1646324107596,"mc":[{"id":"1.195532868","rc":[{"atb":[[3.4,0]],"id":2441997},{"atb":[[3.7,0]],"id":40133336}],"con":true,"img":false}]}
{"op":"mcm","clk":"5322785940","pt":1646324107705,"mc":[{"id":"1.195532868","rc":[{"atb":[[4.2,0]],"id":2441997},{"atb":[[3.6,3.6]],"id":40133336}],"con":true,"img":false}]}
{"op":"mcm","clk":"5322785953","pt":1646324107810,"mc":[{"id":"1.195532868","rc":[{"atb":[[4,1.99]],"id":2441997}],"con":true,"img":false}]}
{"op":"mcm","clk":"5322785985","pt":1646324108074,"mc":[{"id":"1.195532868","rc":[{"atb":[[3.35,63.83]],"id":40133336},{"atl":[[8,22.87]],"id":40133336}],"con":true,"img":false}]}
{"op":"mcm","clk":"5322785999","pt":1646324108178,"mc":[{"id":"1.195532868","rc":[{"atl":[[7,0.48]],"id":40133336}],"con":true,"img":false}]}
{"op":"mcm","clk":"5322786061","pt":1646324108807,"mc":[{"id":"1.195532868","rc":[{"atl":[[36,0],[60,2.18]],"id":40302111}],"con":true,"img":false}]}
{"op":"mcm","clk":"5322786087","pt":1646324108970,"mc":[{"id":"1.195532868","rc":[{"atb":[[4,0]],"id":2441997}],"con":true,"img":false}]}
{"op":"mcm","clk":"5322786103","pt":1646324109078,"mc":[{"id":"1.195532868","rc":[{"atb":[[4.2,1.99]],"id":2441997}],"con":true,"img":false}]}
{"op":"mcm","clk":"5322786165","pt":1646324109602,"mc":[{"id":"1.195532868","rc":[{"atb":[[15.5,7.89]],"id":40302111}],"con":true,"img":false}]}
{"op":"mcm","clk":"5322786216","pt":1646324109984,"mc":[{"id":"1.195532868","rc":[{"atb":[[4.2,0]],"id":2441997}],"con":true,"img":false}]}
{"op":"mcm","clk":"5322786232","pt":1646324110080,"mc":[{"id":"1.195532868","rc":[{"atb":[[4,1.99]],"id":2441997}],"con":true,"img":false}]}
{"op":"mcm","clk":"5322786256","pt":1646324110295,"mc":[{"id":"1.195532868","rc":[{"atl":[[6.6,3.84]],"id":40133336}],"con":true,"img":false}]}
{"op":"mcm","clk":"5322786280","pt":1646324110511,"mc":[{"id":"1.195532868","rc":[{"atl":[[6.8,2.1],[1000,13.65]],"id":40133336}],"con":true,"img":false}]}
{"op":"mcm","clk":"5322786303","pt":1646324110676,"mc":[{"id":"1.195532868","rc":[{"atl":[[1000,12.64]],"id":40133336}],"con":true,"img":false}]}
{"op":"mcm","clk":"5322786322","pt":1646324110885,"mc":[{"id":"1.195532868","rc":[{"atl":[[6.8,0],[1000,12]],"id":40133336}],"con":true,"img":false}]}
{"op":"mcm","clk":"5322786333","pt":1646324110984,"mc":[{"id":"1.195532868","rc":[{"atb":[[28,2.12]],"id":40302111},{"trd":[[28,27.75]],"ltp":28.0,"tv":27.75,"id":40302111},{"atl":[[6.4,0.64]],"id":40133336}],"con":true,"img":false}]}
{"op":"mcm","clk":"5322786404","pt":1646324111610,"mc":[{"id":"1.195532868","rc":[{"atb":[[3.4,19.59]],"id":2441997}],"con":true,"img":false}]}
{"op":"mcm","clk":"5322786448","pt":1646324111874,"mc":[{"id":"1.195532868","rc":[{"atb":[[4,0]],"id":2441997}],"con":true,"img":false}]}
{"op":"mcm","clk":"5322786459","pt":1646324111979,"mc":[{"id":"1.195532868","rc":[{"atb":[[4.2,1.99]],"id":2441997},{"atl":[[7.8,3.28]],"id":2441997},{"atb":[[3.7,2.96]],"id":40133336},{"atl":[[6.8,1.38]],"id":40133336}],"con":true,"img":false}]}
{"op":"mcm","clk":"5322786631","pt":1646324113189,"mc":[{"id":"1.195532868","rc":[{"atl":[[9.4,29.3]],"id":2441997}],"con":true,"img":false}]}
{"op":"mcm","clk":"5322786656","pt":1646324113398,"mc":[{"id":"1.195532868","rc":[{"atb":[[4.2,4.49]],"id":2441997}],"con":true,"img":false}]}
